File: Data/compression 32/AutoNoHeating-15-32-reverse-1-1_11142024_163353.csv
Time (sec),S:Load (lbs),S:HL1 (DIM),S:LVDT (in),S:Position (in),Ch:Position (mm),Ch:Load (N),Ch:Stress (MPa),Ch:Strain (mm/mm),Ch:HL1 (DIM),Set Point (),Cycles ()
0.110000,-0.056602,-280.541351,-0.012085,-0.007062,-0.179386,-0.251780,-0.012826,-1.793859,-280.541351,-0.179248,0.000000
0.560000,-0.042450,-280.541351,-0.012081,-0.006967,-0.176957,-0.188827,-0.009619,-1.769575,-280.541351,-0.176299,0.000000
1.010000,-0.056602,-280.496887,-0.011891,-0.006694,-0.170037,-0.251780,-0.012826,-1.700372,-280.496887,-0.168806,0.000000
1.460000,-0.062187,-280.585846,-0.011568,-0.006389,-0.162275,-0.276622,-0.014092,-1.622751,-280.585846,-0.161314,0.000000
1.910000,-0.056976,-280.719269,-0.011292,-0.006100,-0.154948,-0.253443,-0.012911,-1.549475,-280.719269,-0.153803,0.000000
2.360000,-0.004471,-280.674805,-0.010977,-0.005809,-0.147550,-0.019887,-0.001013,-1.475503,-280.674805,-0.146310,0.000000
2.810000,-0.055855,-280.630310,-0.010680,-0.005504,-0.139814,-0.248455,-0.012657,-1.398140,-280.630310,-0.138818,0.000000
3.260000,-0.087883,-280.719269,-0.010382,-0.005212,-0.132391,-0.390923,-0.019915,-1.323911,-280.719269,-0.131324,0.000000
3.710000,-0.010429,-280.674805,-0.010089,-0.004922,-0.125020,-0.046392,-0.002363,-1.250196,-280.674805,-0.123815,0.000000
4.160000,0.002975,-280.763763,-0.009791,-0.004621,-0.117362,0.013236,0.000674,-1.173620,-280.763763,-0.116322,0.000000
4.610000,-0.021599,-280.763763,-0.009490,-0.004329,-0.109956,-0.096076,-0.004894,-1.099557,-280.763763,-0.108829,0.000000
5.060000,-0.013031,-280.808258,-0.009192,-0.004032,-0.102412,-0.057965,-0.002953,-1.024117,-280.808258,-0.101335,0.000000
5.510000,-0.059952,-280.808258,-0.008882,-0.003734,-0.094849,-0.266679,-0.013585,-0.948495,-280.808258,-0.093826,0.000000
5.960001,-0.041710,-280.808258,-0.008593,-0.003444,-0.087469,-0.185535,-0.009452,-0.874689,-280.808258,-0.086333,0.000000
6.410000,0.009308,-280.897217,-0.008265,-0.003149,-0.079985,0.041403,0.002109,-0.799854,-280.897217,-0.078839,0.000000
6.860000,-0.023460,-280.852722,-0.008002,-0.002856,-0.072552,-0.104357,-0.005316,-0.725519,-280.852722,-0.071347,0.000000
7.310000,-0.091606,-280.897217,-0.007679,-0.002559,-0.064990,-0.407484,-0.020758,-0.649897,-280.897217,-0.063854,0.000000
7.760000,-0.032768,-280.897217,-0.007368,-0.002258,-0.057350,-0.145760,-0.007425,-0.573502,-280.897217,-0.056343,0.000000
8.210000,-0.002235,-280.986176,-0.007088,-0.001977,-0.050213,-0.009944,-0.000507,-0.502134,-280.986176,-0.048851,0.000000
8.660001,-0.029419,-280.986176,-0.006752,-0.001673,-0.042503,-0.130862,-0.006666,-0.425029,-280.986176,-0.041358,0.000000
9.110001,-0.026070,-280.941681,-0.006463,-0.001376,-0.034941,-0.115964,-0.005907,-0.349406,-280.941681,-0.033866,0.000000
9.560000,-0.056229,-280.941681,-0.006153,-0.001084,-0.027534,-0.250117,-0.012742,-0.275344,-280.941681,-0.026355,0.000000
10.010000,-0.084526,-281.075134,-0.005838,-0.000787,-0.019990,-0.375991,-0.019154,-0.199903,-281.075134,-0.018862,0.000000
10.460000,-0.008194,-281.030640,-0.005545,-0.000490,-0.012445,-0.036449,-0.001857,-0.124447,-281.030640,-0.011370,0.000000
10.910001,0.009682,-281.075134,-0.005247,-0.000207,-0.005256,0.043066,0.002194,-0.052565,-281.075134,-0.003877,0.000000
11.360001,-0.049896,-281.119598,-0.004928,0.000101,0.002566,-0.221950,-0.011307,0.025662,-281.119598,0.003633,0.000000
11.810000,0.091606,-281.075134,-0.004635,0.000007,0.000173,0.407484,0.020758,0.001726,-281.075134,0.001170,0.000000
12.260000,0.105751,-281.164093,-0.004605,0.000003,0.000077,0.470404,0.023964,0.000772,-281.164093,0.000303,0.000000
12.710001,0.131073,-281.208588,-0.004605,0.000003,0.000077,0.583042,0.029702,0.000772,-281.208588,0.000893,0.000000
13.160001,0.246513,-281.164093,-0.004596,0.000027,0.000693,1.096546,0.055861,0.006934,-281.164093,0.001638,0.000000
13.610001,0.501587,-281.253052,-0.004570,0.000063,0.001603,2.231170,0.113661,0.016033,-281.253052,0.002394,0.000000
14.060000,0.726868,-281.297546,-0.004544,0.000088,0.002229,3.233269,0.164711,0.022285,-281.297546,0.003138,0.000000
14.510000,1.026627,-281.342010,-0.004518,0.000113,0.002878,4.566663,0.232637,0.028780,-281.342010,0.003894,0.000000
14.960001,1.508850,-281.342010,-0.004484,0.000142,0.003615,6.711700,0.341910,0.036153,-281.342010,0.004639,0.000000
15.410001,2.090126,-281.342010,-0.004462,0.000179,0.004534,9.297345,0.473629,0.045343,-281.342010,0.005394,0.000000
15.860001,2.441643,-281.386505,-0.004432,0.000208,0.005272,10.860970,0.553284,0.052716,-281.386505,0.006139,0.000000
16.310001,2.780502,-281.475464,-0.004411,0.000233,0.005923,12.368292,0.630071,0.059226,-281.475464,0.006895,0.000000
16.760000,3.339806,-281.430969,-0.004381,0.000263,0.006677,14.856197,0.756811,0.066766,-281.430969,0.007639,0.000000
17.210001,3.582970,-281.430969,-0.004359,0.000283,0.007181,15.937845,0.811913,0.071807,-281.430969,0.008395,0.000000
17.660002,4.223076,-281.475464,-0.004320,0.000321,0.008142,18.785179,0.956963,0.081421,-281.475464,0.009140,0.000000
18.110001,4.623375,-281.564423,-0.004307,0.000350,0.008898,20.565800,1.047672,0.088975,-281.564423,0.009886,0.000000
18.560001,5.142838,-281.519928,-0.004294,0.000383,0.009721,22.876484,1.165384,0.097211,-281.519928,0.010640,0.000000
19.010000,5.435150,-281.564423,-0.004255,0.000405,0.010277,24.176756,1.231623,0.102767,-281.564423,0.011386,0.000000
19.460001,5.933380,-281.564423,-0.004212,0.000436,0.011082,26.392992,1.344523,0.110822,-281.564423,0.012140,0.000000
19.910002,6.317673,-281.653381,-0.004204,0.000469,0.011915,28.102411,1.431605,0.119148,-281.653381,0.012887,0.000000
20.360001,6.828194,-281.653381,-0.004152,0.000501,0.012713,30.373322,1.547291,0.127127,-281.653381,0.013641,0.000000
20.810001,7.137634,-281.697876,-0.004135,0.000526,0.013355,31.749783,1.617411,0.133546,-281.697876,0.014387,0.000000
21.260000,7.750191,-281.742340,-0.004113,0.000561,0.014257,34.474571,1.756218,0.142569,-281.742340,0.015141,0.000000
21.710001,7.996696,-281.831299,-0.004079,0.000590,0.014985,35.571083,1.812077,0.149852,-281.831299,0.015887,0.000000
22.160002,8.296829,-281.786835,-0.004044,0.000619,0.015722,36.906139,1.880088,0.157225,-281.786835,0.016641,0.000000
22.610001,8.711655,-281.786835,-0.004027,0.000646,0.016399,38.751377,1.974089,0.163992,-281.786835,0.017388,0.000000
23.060001,8.802139,-281.920258,-0.004001,0.000667,0.016937,39.153870,1.994593,0.169366,-281.920258,0.018142,0.000000
23.510000,9.724876,-281.920258,-0.003958,0.000707,0.017960,43.258411,2.203688,0.179601,-281.920258,0.018888,0.000000
23.960001,9.767700,-281.920258,-0.003928,0.000732,0.018593,43.448902,2.213392,0.185929,-281.920258,0.019642,0.000000
24.410002,10.309502,-281.964752,-0.003902,0.000768,0.019495,45.858955,2.336167,0.194952,-281.964752,0.020388,0.000000
24.860001,10.422333,-281.920258,-0.003885,0.000787,0.019980,46.360851,2.361734,0.199797,-281.920258,0.021142,0.000000
25.310001,11.387520,-282.053711,-0.003850,0.000827,0.021012,50.654217,2.580449,0.210122,-282.053711,0.021889,0.000000
25.760002,11.346191,-281.964752,-0.003829,0.000854,0.021689,50.470379,2.571084,0.216890,-281.964752,0.022643,0.000000
26.210001,11.786331,-282.053711,-0.003794,0.000882,0.022408,52.428219,2.670821,0.224081,-282.053711,0.023389,0.000000
26.660002,11.771065,-282.053711,-0.003773,0.000903,0.022946,52.360310,2.667361,0.229455,-282.053711,0.024143,0.000000
27.110001,12.677422,-282.098206,-0.003738,0.000943,0.023943,56.391987,2.872745,0.239432,-282.098206,0.024889,0.000000
27.560001,12.849457,-282.098206,-0.003699,0.000973,0.024715,57.157238,2.911729,0.247154,-282.098206,0.025643,0.000000
28.010002,12.862862,-282.142670,-0.003669,0.000997,0.025322,57.216866,2.914766,0.253225,-282.142670,0.026390,0.000000
28.460001,13.344711,-282.142670,-0.003639,0.001029,0.026137,59.360241,3.023955,0.261370,-282.142670,0.027144,0.000000
28.910002,13.032288,-282.187164,-0.003600,0.001044,0.026528,57.970512,2.953159,0.265276,-282.187164,0.027890,0.000000
29.360001,14.260002,-282.187164,-0.003566,0.001095,0.027820,63.431656,3.231363,0.278205,-282.187164,0.028644,0.000000
29.810001,14.239525,-282.276123,-0.003531,0.001119,0.028428,63.340569,3.226722,0.284276,-282.276123,0.029390,0.000000
30.260002,14.468903,-282.231628,-0.003510,0.001146,0.029121,64.360893,3.278700,0.291210,-282.231628,0.030144,0.000000
30.710001,14.515823,-282.365082,-0.003479,0.001171,0.029754,64.569611,3.289333,0.297538,-282.365082,0.030891,0.000000
31.160002,15.177528,-282.320587,-0.003449,0.001210,0.030733,67.513016,3.439277,0.307333,-282.320587,0.031645,0.000000
31.610001,15.133957,-282.320587,-0.003415,0.001236,0.031384,67.319206,3.429404,0.313843,-282.320587,0.032390,0.000000
32.060001,15.749123,-282.365082,-0.003393,0.001268,0.032217,70.055595,3.568802,0.322170,-282.365082,0.033145,0.000000
32.510002,15.960999,-282.365082,-0.003359,0.001295,0.032901,70.998070,3.616814,0.329013,-282.365082,0.033890,0.000000
32.960003,16.084999,-282.498535,-0.003320,0.001326,0.033673,71.549652,3.644913,0.336735,-282.498535,0.034645,0.000000
33.410000,16.356834,-282.409546,-0.003298,0.001354,0.034402,72.758835,3.706512,0.344017,-282.409546,0.035390,0.000000
33.860001,16.744469,-282.454041,-0.003247,0.001386,0.035209,74.483116,3.794351,0.352086,-282.454041,0.036146,0.000000
34.310001,16.687500,-282.498535,-0.003216,0.001410,0.035825,74.229706,3.781442,0.358248,-282.498535,0.036891,0.000000
34.760002,17.095993,-282.498535,-0.003199,0.001442,0.036623,76.046776,3.874007,0.366226,-282.498535,0.037646,0.000000
35.210003,17.745407,-282.542999,-0.003152,0.001478,0.037542,78.935516,4.021167,0.375416,-282.542999,0.038391,0.000000
35.660000,17.584915,-282.542999,-0.003109,0.001502,0.038149,78.221611,3.984799,0.381487,-282.542999,0.039146,0.000000
36.110001,17.968460,-282.631958,-0.003087,0.001533,0.038937,79.927704,4.071711,0.389375,-282.631958,0.039891,0.000000
36.560001,17.895477,-282.676453,-0.003061,0.001553,0.039458,79.603058,4.055173,0.394583,-282.676453,0.040647,0.000000
37.010002,18.806671,-282.676453,-0.003014,0.001595,0.040507,83.656250,4.261652,0.405075,-282.676453,0.041392,0.000000
37.460003,18.614525,-282.720917,-0.002984,0.001620,0.041140,82.801544,4.218112,0.411403,-282.720917,0.042147,0.000000
37.910004,19.181274,-282.676453,-0.002953,0.001653,0.041999,85.322571,4.346539,0.419987,-282.676453,0.042892,0.000000
38.360001,19.052063,-282.765411,-0.002923,0.001676,0.042571,84.747810,4.317259,0.425710,-282.765411,0.043638,0.000000
38.810001,19.702972,-282.765411,-0.002880,0.001710,0.043438,87.643196,4.464757,0.434385,-282.765411,0.044392,0.000000
39.260002,19.772232,-282.854370,-0.002850,0.001739,0.044159,87.951279,4.480452,0.441591,-282.854370,0.045139,0.000000
39.710003,20.373238,-282.854370,-0.002807,0.001772,0.044999,90.624687,4.616642,0.449994,-282.854370,0.045893,0.000000
40.160004,20.258179,-282.765411,-0.002772,0.001798,0.045667,90.112877,4.590569,0.456670,-282.765411,0.046639,0.000000
40.610001,20.836845,-282.854370,-0.002759,0.001830,0.046492,92.686920,4.721697,0.464921,-282.854370,0.047393,0.000000
41.060001,20.892700,-282.898834,-0.002712,0.001857,0.047160,92.935371,4.734354,0.471598,-282.898834,0.048139,0.000000
41.510002,21.084846,-282.898834,-0.002677,0.001886,0.047905,93.790085,4.777894,0.479047,-282.898834,0.048893,0.000000
41.960003,21.242355,-282.943329,-0.002634,0.001915,0.048633,94.490715,4.813586,0.486329,-282.943329,0.049640,0.000000
42.410004,21.813950,-282.943329,-0.002596,0.001949,0.049500,97.033295,4.943111,0.495004,-282.943329,0.050394,0.000000
42.860001,22.251488,-282.943329,-0.002535,0.001979,0.050272,98.979561,5.042259,0.502725,-282.943329,0.051140,0.000000
43.310001,21.944283,-283.032288,-0.002535,0.002002,0.050845,97.613045,4.972645,0.508448,-283.032288,0.051894,0.000000
43.760002,22.736320,-282.987823,-0.002479,0.002038,0.051756,101.136208,5.152124,0.517562,-282.987823,0.052640,0.000000
44.210003,22.506187,-283.032288,-0.002466,0.002059,0.052294,100.112518,5.099975,0.522936,-283.032288,0.053394,0.000000
44.660004,23.425949,-283.076782,-0.002419,0.002095,0.053222,104.203827,5.308396,0.532217,-283.076782,0.054141,0.000000
45.110001,23.308655,-283.076782,-0.002393,0.002123,0.053915,103.682076,5.281817,0.539151,-283.076782,0.054895,0.000000
45.560001,23.788643,-283.076782,-0.002354,0.002154,0.054713,105.817169,5.390584,0.547129,-283.076782,0.055641,0.000000
46.010002,23.724220,-283.165741,-0.002311,0.002180,0.055362,105.530602,5.375985,0.553624,-283.165741,0.056395,0.000000
46.460003,23.389084,-283.165741,-0.002212,0.002209,0.056109,104.039841,5.300042,0.561088,-283.165741,0.057141,0.000000
46.910004,24.643982,-283.254700,-0.002203,0.002242,0.056951,109.621910,5.584406,0.569506,-283.254700,0.057895,0.000000
47.360001,24.428001,-283.254700,-0.002207,0.002268,0.057618,108.661179,5.535464,0.576182,-283.254700,0.058642,0.000000
47.810001,25.068489,-283.254700,-0.002190,0.002299,0.058390,111.510208,5.680601,0.583903,-283.254700,0.059396,0.000000
48.260002,24.517372,-283.299164,-0.002151,0.002316,0.058832,109.058716,5.555716,0.588324,-283.299164,0.060142,0.000000
48.710003,25.987877,-283.299164,-0.002001,0.002361,0.059959,115.599854,5.888937,0.599588,-283.299164,0.060896,0.000000
49.160004,25.626671,-283.343658,-0.002005,0.002386,0.060593,113.993126,5.807086,0.605931,-283.343658,0.061642,0.000000
49.610001,26.358009,-283.299164,-0.002009,0.002418,0.061424,117.246284,5.972810,0.614243,-283.299164,0.062396,0.000000
50.060001,26.129745,-283.343658,-0.002005,0.002441,0.061989,116.230911,5.921085,0.619890,-283.343658,0.063143,0.000000
50.510002,27.219681,-283.388153,-0.001975,0.002477,0.062925,121.079185,6.168068,0.629246,-283.388153,0.063897,0.000000
50.960003,26.970566,-283.388153,-0.001932,0.002507,0.063671,119.971069,6.111618,0.636710,-283.388153,0.064643,0.000000
51.410004,26.931839,-283.477112,-0.001789,0.002535,0.064392,119.798805,6.102842,0.643917,-283.477112,0.065397,0.000000
51.860001,27.670250,-283.477112,-0.001789,0.002566,0.065180,123.083420,6.270168,0.651804,-283.477112,0.066143,0.000000
52.310001,27.960327,-283.521576,-0.001802,0.002598,0.065978,124.373749,6.335901,0.659783,-283.521576,0.066897,0.000000
52.760002,27.989746,-283.566071,-0.001772,0.002627,0.066716,124.504608,6.342567,0.667156,-283.566071,0.067644,0.000000
53.210003,27.869469,-283.566071,-0.001750,0.002652,0.067358,123.969589,6.315312,0.673575,-283.566071,0.068398,0.000000
53.660004,28.084328,-283.610535,-0.001703,0.002681,0.068102,124.925331,6.363999,0.681024,-283.610535,0.069144,0.000000
54.110004,28.859238,-283.566071,-0.001582,0.002715,0.068970,128.372299,6.539597,0.689699,-283.566071,0.069898,0.000000
54.560001,28.994034,-283.566071,-0.001574,0.002745,0.069733,128.971909,6.570142,0.697329,-283.566071,0.070644,0.000000
55.010002,29.324699,-283.655029,-0.001565,0.002777,0.070531,130.442780,6.645072,0.705308,-283.655029,0.071398,0.000000
55.460003,29.067764,-283.655029,-0.001544,0.002801,0.071147,129.299866,6.586850,0.711469,-283.655029,0.072145,0.000000
55.910004,28.760933,-283.699493,-0.001522,0.002825,0.071745,127.935020,6.517321,0.717450,-283.699493,0.072899,0.000000
56.360004,29.940979,-283.743988,-0.001483,0.002863,0.072724,133.184128,6.784723,0.727245,-283.743988,0.073645,0.000000
56.810001,29.629677,-283.743988,-0.001358,0.002892,0.073454,131.799377,6.714180,0.734542,-283.743988,0.074399,0.000000
57.260002,29.468811,-283.788483,-0.001358,0.002918,0.074122,131.083817,6.677728,0.741219,-283.788483,0.075145,0.000000
57.710003,29.860916,-283.832947,-0.001345,0.002947,0.074850,132.827988,6.766580,0.748501,-283.832947,0.075890,0.000000
58.160004,30.897606,-283.788483,-0.001345,0.002986,0.075846,137.439423,7.001498,0.758463,-283.788483,0.076644,0.000000
58.610004,30.411285,-283.877441,-0.001302,0.003009,0.076428,135.276154,6.891296,0.764276,-283.877441,0.077390,0.000000
59.060001,30.318565,-283.921906,-0.001259,0.003038,0.077156,134.863708,6.870285,0.771558,-283.921906,0.078144,0.000000
59.510002,30.437721,-283.966400,-0.001237,0.003064,0.077816,135.393753,6.897286,0.778159,-283.966400,0.078891,0.000000
59.960003,30.708443,-283.966400,-0.001194,0.003095,0.078605,136.597977,6.958632,0.786047,-283.966400,0.079645,0.000000
60.410004,31.419670,-283.966400,-0.001168,0.003125,0.079386,139.761673,7.119799,0.793859,-283.966400,0.080391,0.000000
60.860004,31.452065,-283.921906,-0.001091,0.003156,0.080166,139.905777,7.127140,0.801656,-283.921906,0.081145,0.000000
61.310001,31.892952,-283.966400,-0.001095,0.003183,0.080842,141.866928,7.227046,0.808423,-283.966400,0.081891,0.000000
61.760002,31.465843,-284.055359,-0.001056,0.003203,0.081354,139.967056,7.130262,0.813540,-284.055359,0.082645,0.000000
62.210003,33.099068,-284.010864,-0.001005,0.003246,0.082447,147.232010,7.500356,0.824471,-284.010864,0.083392,0.000000
62.660004,33.327705,-284.055359,-0.000996,0.003272,0.083106,148.249039,7.552166,0.831057,-284.055359,0.084146,0.000000
63.110004,34.028885,-284.144318,-0.000970,0.003303,0.083887,151.368042,7.711056,0.838869,-284.144318,0.084892,0.000000
63.560001,34.585205,-284.144318,-0.000936,0.003329,0.084562,153.842682,7.837120,0.845621,-284.144318,0.085646,0.000000
64.010002,35.750359,-284.144318,-0.000931,0.003364,0.085439,159.025543,8.101147,0.854387,-284.144318,0.086392,0.000000
64.460007,36.187157,-284.188782,-0.000888,0.003392,0.086150,160.968506,8.200128,0.861503,-284.188782,0.087146,0.000000
64.910004,36.873062,-284.188782,-0.000867,0.003422,0.086913,164.019577,8.355556,0.869133,-284.188782,0.087893,0.000000
65.360001,37.399971,-284.188782,-0.000836,0.003445,0.087493,166.363373,8.474955,0.874931,-284.188782,0.088647,0.000000
65.810005,38.278023,-284.233276,-0.000828,0.003482,0.088439,170.269150,8.673923,0.884394,-284.233276,0.089393,0.000000
66.260002,40.153297,-284.322235,-0.000802,0.003513,0.089237,178.610794,9.098867,0.892372,-284.322235,0.090147,0.000000
66.710007,41.339302,-284.277771,-0.000767,0.003544,0.090017,183.886398,9.367620,0.900169,-284.277771,0.090893,0.000000
67.160004,41.982391,-284.322235,-0.000737,0.003568,0.090624,186.747009,9.513346,0.906240,-284.322235,0.091647,0.000000
67.610001,41.961159,-284.322235,-0.000724,0.003587,0.091101,186.652557,9.508534,0.911009,-284.322235,0.092394,0.000000
68.060005,44.686928,-284.366730,-0.000698,0.003631,0.092238,198.777390,10.126203,0.922379,-284.366730,0.093148,0.000000
68.510002,45.366135,-284.366730,-0.000686,0.003656,0.092862,201.798645,10.280113,0.928616,-284.366730,0.093894,0.000000
68.960007,46.801262,-284.366730,-0.000655,0.003686,0.093634,208.182404,10.605318,0.936338,-284.366730,0.094648,0.000000
69.410004,47.833107,-284.455688,-0.000634,0.003713,0.094301,212.772293,10.839137,0.943014,-284.455688,0.095394,0.000000
69.860001,49.786194,-284.455688,-0.000617,0.003748,0.095204,221.460052,11.281713,0.952037,-284.455688,0.096148,0.000000
70.310005,50.745804,-284.455688,-0.000591,0.003773,0.095837,225.728607,11.499164,0.958366,-284.455688,0.096895,0.000000
70.760002,52.026764,-284.544647,-0.000599,0.003803,0.096609,231.426605,11.789433,0.966087,-284.544647,0.097649,0.000000
71.210007,53.985817,-284.544647,-0.000565,0.003836,0.097441,240.140915,12.233361,0.974414,-284.544647,0.098395,0.000000
71.660004,53.918411,-284.544647,-0.000569,0.003859,0.098030,239.841064,12.218086,0.980303,-284.544647,0.099149,0.000000
72.110001,57.436218,-284.633606,-0.000552,0.003895,0.098933,255.489059,13.015233,0.989326,-284.633606,0.099895,0.000000
72.560005,58.729836,-284.633606,-0.000513,0.003924,0.099679,261.243347,13.308371,0.996790,-284.633606,0.100649,0.000000
73.010002,60.593193,-284.722565,-0.000496,0.003953,0.100415,269.531982,13.730614,1.004148,-284.722565,0.101396,0.000000
73.460007,61.515182,-284.678101,-0.000492,0.003974,0.100936,273.633209,13.939539,1.009356,-284.678101,0.102150,0.000000
73.910004,64.363464,-284.767059,-0.000479,0.004015,0.101977,286.302979,14.584970,1.019772,-284.767059,0.102896,0.000000
74.360001,66.115479,-284.767059,-0.000466,0.004043,0.102696,294.096344,14.981981,1.026963,-284.767059,0.103650,0.000000
74.810005,65.237045,-284.767059,-0.000440,0.004036,0.102506,290.188873,14.782926,1.025056,-284.767059,0.018005,0.000000
75.260002,65.573669,-284.767059,-0.000431,0.004047,0.102792,291.686249,14.859206,1.027917,-284.767059,294.500458,0.000000
75.710007,65.150650,-284.856018,-0.000427,0.004063,0.103191,289.804565,14.763348,1.031914,-284.856018,294.500458,0.000000
76.160004,65.144699,-284.856018,-0.000427,0.004071,0.103399,289.778107,14.762000,1.033988,-284.856018,294.500458,0.000000
76.610001,65.078415,-284.944977,-0.000414,0.004078,0.103573,289.483246,14.746980,1.035729,-284.944977,294.500458,0.000000
77.060005,65.762833,-284.989441,-0.000423,0.004089,0.103859,292.527679,14.902071,1.038590,-284.989441,294.500458,0.000000
77.510002,65.193115,-284.944977,-0.000392,0.004090,0.103894,289.993469,14.772971,1.038939,-284.944977,294.500458,0.000000
77.960007,65.031494,-284.944977,-0.000397,0.004095,0.104006,289.274536,14.736347,1.040059,-284.944977,294.500458,0.000000
78.410004,66.037277,-285.033936,-0.000401,0.004102,0.104197,293.748474,14.964260,1.041966,-285.033936,294.500458,0.000000
78.860001,65.492874,-284.989441,-0.000379,0.004103,0.104206,291.326843,14.840898,1.042057,-284.989441,294.500458,0.000000
79.310005,65.433655,-285.078430,-0.000384,0.004111,0.104431,291.063446,14.827478,1.044313,-285.078430,294.500458,0.000000
79.760002,65.125702,-285.078430,-0.000379,0.004113,0.104474,289.693604,14.757695,1.044737,-285.078430,294.500458,0.000000
80.210007,65.080276,-285.078430,-0.000388,0.004116,0.104552,289.491516,14.747402,1.045524,-285.078430,294.500458,0.000000
80.660004,65.114532,-285.122894,-0.000375,0.004120,0.104648,289.643921,14.755164,1.046478,-285.122894,294.500458,0.000000
81.110001,65.132782,-285.167389,-0.000392,0.004125,0.104769,289.725098,14.759299,1.047689,-285.167389,294.500458,0.000000
81.560005,65.180450,-285.122894,-0.000375,0.004126,0.104804,289.937134,14.770102,1.048037,-285.122894,294.500458,0.000000
82.010002,64.936539,-285.211853,-0.000384,0.004129,0.104873,288.852142,14.714830,1.048734,-285.211853,294.500458,0.000000
82.460007,65.728210,-285.211853,-0.000366,0.004136,0.105064,292.373688,14.894225,1.050641,-285.211853,294.500458,0.000000
82.910004,65.504410,-285.256348,-0.000366,0.004136,0.105064,291.378174,14.843512,1.050641,-285.256348,294.500458,0.000000
83.360001,65.281738,-285.300812,-0.000358,0.004136,0.105064,290.387665,14.793054,1.050641,-285.300812,294.500458,0.000000
83.810005,65.145065,-285.256348,-0.000366,0.004138,0.105107,289.779724,14.762082,1.051065,-285.256348,294.500458,0.000000
84.260002,65.017349,-285.300812,-0.000362,0.004138,0.105116,289.211609,14.733142,1.051156,-285.300812,294.500458,0.000000
84.710007,64.906006,-285.389771,-0.000358,0.004141,0.105185,288.716339,14.707911,1.051853,-285.389771,294.500458,0.000000
85.160004,65.046387,-285.434265,-0.000358,0.004144,0.105255,289.340790,14.739721,1.052549,-285.434265,294.500458,0.000000
85.610001,64.926483,-285.389771,-0.000354,0.004144,0.105264,288.807434,14.712552,1.052640,-285.389771,294.500458,0.000000
86.060005,65.660431,-285.478729,-0.000354,0.004152,0.105471,292.072174,14.878866,1.054714,-285.478729,294.500458,0.000000
86.510002,65.563614,-285.478729,-0.000362,0.004152,0.105471,291.641510,14.856928,1.054714,-285.478729,294.500458,0.000000
86.960007,65.412430,-285.523224,-0.000358,0.004152,0.105471,290.969025,14.822668,1.054714,-285.523224,294.500458,0.000000
87.410004,65.273163,-285.523224,-0.000345,0.004152,0.105471,290.349518,14.791110,1.054714,-285.523224,294.500458,0.000000
87.860001,65.116776,-285.523224,-0.000341,0.004152,0.105471,289.653870,14.755672,1.054714,-285.523224,294.500458,0.000000
88.310005,64.987183,-285.523224,-0.000345,0.004152,0.105471,289.077423,14.726306,1.054714,-285.523224,294.500458,0.000000
88.760002,65.879761,-285.612183,-0.000358,0.004163,0.105748,293.047821,14.928567,1.057485,-285.612183,294.500458,0.000000
89.210007,65.788528,-285.656677,-0.000341,0.004163,0.105748,292.641998,14.907893,1.057485,-285.656677,294.500458,0.000000
89.660004,65.679794,-285.656677,-0.000336,0.004163,0.105748,292.158325,14.883254,1.057485,-285.656677,294.500458,0.000000
90.110001,65.580750,-285.701141,-0.000354,0.004163,0.105748,291.717743,14.860810,1.057485,-285.701141,294.500458,0.000000
90.560005,65.464188,-285.701141,-0.000362,0.004163,0.105748,291.199249,14.834396,1.057485,-285.701141,294.500458,0.000000
91.010002,65.267960,-285.790100,-0.000349,0.004163,0.105748,290.326385,14.789931,1.057485,-285.790100,294.500458,0.000000
91.460007,65.249329,-285.790100,-0.000345,0.004165,0.105783,290.243500,14.785709,1.057833,-285.790100,294.500458,0.000000
91.910004,65.213593,-285.834595,-0.000349,0.004166,0.105827,290.084534,14.777611,1.058272,-285.834595,294.500458,0.000000
92.360001,65.273911,-285.834595,-0.000349,0.004168,0.105871,290.352844,14.791280,1.058711,-285.834595,294.500458,0.000000
92.810005,65.277267,-285.834595,-0.000341,0.004169,0.105897,290.367798,14.792040,1.058968,-285.834595,294.500458,0.000000
93.260002,65.282852,-285.834595,-0.000345,0.004170,0.105913,290.392639,14.793305,1.059135,-285.834595,294.500458,0.000000
93.710007,65.278015,-285.923553,-0.000336,0.004171,0.105939,290.371124,14.792210,1.059392,-285.923553,294.500458,0.000000
94.160004,65.267578,-285.923553,-0.000332,0.004171,0.105948,290.324677,14.789845,1.059483,-285.923553,294.500458,0.000000
94.610008,65.299606,-285.968048,-0.000345,0.004174,0.106009,290.467163,14.797102,1.060089,-285.968048,294.500458,0.000000
95.060005,65.286942,-285.968048,-0.000341,0.004174,0.106009,290.410828,14.794232,1.060089,-285.968048,294.500458,0.000000
95.510002,65.292526,-286.012512,-0.000341,0.004175,0.106035,290.435669,14.795499,1.060346,-286.012512,294.500458,0.000000
95.960007,65.265350,-286.057007,-0.000323,0.004175,0.106044,290.314789,14.789339,1.060437,-286.057007,294.500458,0.000000
96.410004,65.264969,-286.057007,-0.000341,0.004176,0.106069,290.313080,14.789253,1.060694,-286.057007,294.500458,0.000000
96.860008,65.265717,-286.190430,-0.000328,0.004177,0.106095,290.316406,14.789423,1.060951,-286.190430,294.500458,0.000000
97.310005,65.263855,-286.101471,-0.000345,0.004178,0.106122,290.308136,14.789001,1.061224,-286.101471,294.500458,0.000000
97.760002,65.259018,-286.234924,-0.000336,0.004178,0.106122,290.286621,14.787905,1.061224,-286.234924,294.500458,0.000000
98.210007,65.238907,-286.190430,-0.000336,0.004179,0.106139,290.197144,14.783348,1.061391,-286.190430,294.500458,0.000000
98.660004,65.228485,-286.190430,-0.000328,0.004180,0.106165,290.150787,14.780987,1.061648,-286.190430,294.500458,0.000000
99.110008,65.232574,-286.279388,-0.000349,0.004180,0.106165,290.168976,14.781913,1.061648,-286.279388,294.500458,0.000000
99.560005,65.177475,-286.234924,-0.000319,0.004180,0.106183,289.923889,14.769426,1.061830,-286.234924,294.500458,0.000000
100.010002,65.149536,-286.279388,-0.000328,0.004181,0.106191,289.799622,14.763096,1.061905,-286.279388,294.500458,0.000000
100.460007,65.176346,-286.368378,-0.000328,0.004182,0.106234,289.918854,14.769171,1.062344,-286.368378,294.500458,0.000000
100.910004,65.182678,-286.368378,-0.000341,0.004183,0.106244,289.947021,14.770606,1.062435,-286.368378,294.500458,0.000000
101.360008,65.170013,-286.368378,-0.000328,0.004184,0.106286,289.890686,14.767735,1.062859,-286.368378,294.500458,0.000000
101.810005,65.354340,-286.457336,-0.000336,0.004186,0.106313,290.710632,14.809505,1.063132,-286.457336,294.500458,0.000000
102.260002,65.296997,-286.412842,-0.000332,0.004186,0.106313,290.455536,14.796512,1.063132,-286.412842,294.500458,0.000000
102.710007,65.299240,-286.412842,-0.000336,0.004186,0.106313,290.465515,14.797020,1.063132,-286.412842,294.500458,0.000000
103.160004,65.256409,-286.457336,-0.000336,0.004186,0.106313,290.274994,14.787313,1.063132,-286.457336,294.500458,0.000000
103.610008,65.253799,-286.501801,-0.000328,0.004186,0.106330,290.263397,14.786722,1.063298,-286.501801,294.500458,0.000000
104.060005,65.276154,-286.546295,-0.000328,0.004188,0.106365,290.362823,14.791788,1.063646,-286.546295,294.500458,0.000000
104.510002,65.276886,-286.590759,-0.000336,0.004188,0.106365,290.366089,14.791954,1.063646,-286.590759,294.500458,0.000000
104.960007,65.243378,-286.501801,-0.000332,0.004188,0.106365,290.217041,14.784361,1.063646,-286.501801,294.500458,0.000000
105.410004,65.217682,-286.635254,-0.000323,0.004188,0.106365,290.102753,14.778538,1.063646,-286.635254,294.500458,0.000000
105.860008,65.164429,-286.590759,-0.000328,0.004188,0.106374,289.865845,14.766471,1.063737,-286.590759,294.500458,0.000000
106.310005,65.109329,-286.724213,-0.000336,0.004188,0.106381,289.620758,14.753985,1.063813,-286.724213,294.500458,0.000000
106.760002,65.121979,-286.679718,-0.000332,0.004189,0.106409,289.677032,14.756851,1.064085,-286.679718,294.500458,0.000000
107.210007,65.180069,-286.724213,-0.000328,0.004190,0.106434,289.935425,14.770015,1.064343,-286.724213,294.500458,0.000000
107.660004,65.174866,-286.724213,-0.000315,0.004190,0.106434,289.912292,14.768836,1.064343,-286.724213,294.500458,0.000000
108.110008,65.138748,-286.679718,-0.000319,0.004190,0.106434,289.751617,14.760652,1.064343,-286.679718,294.500458,0.000000
108.560005,65.317474,-286.813171,-0.000319,0.004194,0.106539,290.546631,14.801151,1.065387,-286.813171,294.500458,0.000000
109.010002,65.371841,-286.768677,-0.000332,0.004194,0.106539,290.788483,14.813471,1.065387,-286.768677,294.500458,0.000000
109.460007,65.366638,-286.813171,-0.000315,0.004194,0.106539,290.765320,14.812292,1.065387,-286.813171,294.500458,0.000000
109.910004,65.342056,-286.857666,-0.000323,0.004194,0.106539,290.655975,14.806722,1.065387,-286.857666,294.500458,0.000000
110.360008,65.320084,-286.857666,-0.000319,0.004194,0.106539,290.558258,14.801743,1.065387,-286.857666,294.500458,0.000000
110.810005,65.292908,-286.902130,-0.000328,0.004194,0.106539,290.437347,14.795585,1.065387,-286.902130,294.500458,0.000000
111.260002,65.261993,-286.902130,-0.000319,0.004194,0.106539,290.299835,14.788579,1.065387,-286.902130,294.500458,0.000000
111.710007,65.230347,-286.946625,-0.000319,0.004194,0.106539,290.159088,14.781407,1.065387,-286.946625,294.500458,0.000000
112.160004,65.209488,-286.991089,-0.000302,0.004194,0.106539,290.066284,14.776682,1.065387,-286.991089,294.500458,0.000000
112.610008,65.155502,-286.946625,-0.000315,0.004194,0.106539,289.826141,14.764448,1.065387,-286.946625,294.500458,0.000000
113.060005,65.101883,-287.035583,-0.000319,0.004195,0.106546,289.587646,14.752297,1.065463,-287.035583,294.500458,0.000000
113.510002,65.519302,-287.035583,-0.000323,0.004199,0.106660,291.444427,14.846886,1.066599,-287.035583,294.500458,0.000000
113.960007,65.499573,-287.080048,-0.000323,0.004199,0.106660,291.356659,14.842416,1.066599,-287.080048,294.500458,0.000000
114.410004,65.486542,-287.035583,-0.000310,0.004199,0.106660,291.298676,14.839462,1.066599,-287.035583,294.500458,0.000000
114.860008,65.450790,-287.213501,-0.000310,0.004199,0.106660,291.139648,14.831361,1.066599,-287.213501,294.500458,0.000000
115.310005,65.409836,-287.124542,-0.000310,0.004199,0.106660,290.957489,14.822081,1.066599,-287.124542,294.500458,0.000000
115.760002,65.383759,-287.213501,-0.000315,0.004199,0.106660,290.841492,14.816172,1.066599,-287.213501,294.500458,0.000000
116.210007,65.348389,-287.169006,-0.000306,0.004199,0.106660,290.684143,14.808156,1.066599,-287.169006,294.500458,0.000000
116.660004,65.327911,-287.257996,-0.000319,0.004199,0.106660,290.593048,14.803516,1.066599,-287.257996,294.500458,0.000000
117.110008,65.300720,-287.257996,-0.000336,0.004199,0.106660,290.472107,14.797355,1.066599,-287.257996,294.500458,0.000000
117.560005,65.276886,-287.302460,-0.000323,0.004199,0.106660,290.366089,14.791954,1.066599,-287.302460,294.500458,0.000000
118.010002,65.259384,-287.302460,-0.000323,0.004199,0.106660,290.288239,14.787988,1.066599,-287.302460,294.500458,0.000000
118.460007,65.212097,-287.302460,-0.000319,0.004199,0.106660,290.077881,14.777272,1.066599,-287.302460,294.500458,0.000000
118.910004,65.184540,-287.391418,-0.000306,0.004199,0.106660,289.955322,14.771028,1.066599,-287.391418,294.500458,0.000000
119.360008,65.133530,-287.435913,-0.000328,0.004199,0.106660,289.728424,14.759469,1.066599,-287.435913,294.500458,0.000000
119.810005,65.103745,-287.435913,-0.000319,0.004199,0.106660,289.595917,14.752720,1.066599,-287.435913,294.500458,0.000000
120.260002,65.076553,-287.391418,-0.000302,0.004199,0.106660,289.474976,14.746557,1.066599,-287.391418,294.500458,0.000000
120.710007,65.043411,-287.480377,-0.000319,0.004199,0.106660,289.327545,14.739048,1.066599,-287.480377,294.500458,0.000000
121.160004,65.008041,-287.480377,-0.000310,0.004199,0.106660,289.170197,14.731032,1.066599,-287.480377,294.500458,0.000000
121.610008,64.982346,-287.524872,-0.000315,0.004199,0.106660,289.055908,14.725209,1.066599,-287.524872,294.500458,0.000000
122.060005,64.963348,-287.613831,-0.000310,0.004200,0.106669,288.971405,14.720905,1.066689,-287.613831,294.500458,0.000000
122.510002,64.916809,-287.613831,-0.000315,0.004200,0.106669,288.764374,14.710359,1.066689,-287.613831,294.500458,0.000000
122.960007,64.901535,-287.613831,-0.000315,0.004200,0.106669,288.696442,14.706899,1.066689,-287.613831,294.500458,0.000000
123.410004,64.860947,-287.613831,-0.000315,0.004200,0.106669,288.515900,14.697701,1.066689,-287.613831,294.500458,0.000000
123.860008,64.831528,-287.658325,-0.000328,0.004200,0.106669,288.385040,14.691034,1.066689,-287.658325,294.500458,0.000000
124.310005,64.802490,-287.658325,-0.000315,0.004200,0.106669,288.255859,14.684454,1.066689,-287.658325,294.500458,0.000000
124.760002,66.201492,-287.702789,-0.000306,0.004212,0.106988,294.478943,15.001472,1.069884,-287.702789,294.500458,0.000000
125.210007,66.127396,-287.702789,-0.000310,0.004205,0.106798,294.149353,14.984682,1.067976,-287.702789,294.500458,0.000000
125.660004,66.086060,-287.791748,-0.000310,0.004205,0.106798,293.965485,14.975315,1.067976,-287.791748,294.500458,0.000000
126.110008,66.013077,-287.747284,-0.000306,0.004204,0.106790,293.640839,14.958777,1.067901,-287.747284,294.500458,0.000000
126.560005,65.992966,-287.791748,-0.000306,0.004204,0.106790,293.551361,14.954220,1.067901,-287.791748,294.500458,0.000000
127.010010,65.917007,-287.880707,-0.000310,0.004204,0.106790,293.213501,14.937007,1.067901,-287.880707,294.500458,0.000000
127.460007,65.873428,-287.836243,-0.000315,0.004204,0.106790,293.019653,14.927133,1.067901,-287.836243,294.500458,0.000000
127.910004,65.890930,-287.880707,-0.000302,0.004204,0.106790,293.097504,14.931098,1.067901,-287.880707,294.500458,0.000000
128.360001,65.819061,-287.880707,-0.000310,0.004204,0.106790,292.777802,14.914812,1.067901,-287.880707,294.500458,0.000000
128.810013,65.847733,-287.925201,-0.000310,0.004204,0.106790,292.905334,14.921309,1.067901,-287.925201,294.500458,0.000000
129.260010,65.793365,-287.925201,-0.000310,0.004204,0.106790,292.663513,14.908989,1.067901,-287.925201,294.500458,0.000000
129.710007,65.754639,-287.969666,-0.000319,0.004204,0.106790,292.491241,14.900214,1.067901,-287.969666,294.500458,0.000000
130.160004,65.752777,-287.969666,-0.000315,0.004204,0.106790,292.482971,14.899792,1.067901,-287.969666,294.500458,0.000000
130.610001,65.671600,-288.014160,-0.000310,0.004204,0.106790,292.121857,14.881397,1.067901,-288.014160,294.500458,0.000000
131.060013,65.648514,-288.058624,-0.000306,0.004204,0.106790,292.019165,14.876165,1.067901,-288.058624,294.500458,0.000000
131.510010,65.615753,-288.103119,-0.000302,0.004204,0.106790,291.873444,14.868742,1.067901,-288.103119,294.500458,0.000000
131.960007,65.580002,-288.103119,-0.000315,0.004204,0.106790,291.714417,14.860641,1.067901,-288.103119,294.500458,0.000000
132.410004,65.565475,-288.103119,-0.000319,0.004204,0.106790,291.649811,14.857348,1.067901,-288.103119,294.500458,0.000000
132.860001,65.540909,-288.192078,-0.000310,0.004204,0.106790,291.540527,14.851783,1.067901,-288.192078,294.500458,0.000000
133.310013,65.507767,-288.192078,-0.000319,0.004204,0.106790,291.393097,14.844272,1.067901,-288.192078,294.500458,0.000000
133.760010,65.487289,-288.192078,-0.000297,0.004204,0.106790,291.302002,14.839632,1.067901,-288.192078,294.500458,0.000000
134.210007,65.451904,-288.147614,-0.000302,0.004204,0.106790,291.144623,14.831614,1.067901,-288.147614,294.500458,0.000000
134.660004,65.396423,-288.192078,-0.000310,0.004204,0.106790,290.897827,14.819041,1.067901,-288.192078,294.500458,0.000000
135.110001,65.380035,-288.281036,-0.000302,0.004204,0.106790,290.824921,14.815328,1.067901,-288.281036,1681.640747,0.000000
135.560013,65.273911,-288.325531,-0.000302,0.004198,0.106625,290.352844,14.791280,1.066250,-288.325531,0.106409,0.000000
136.010010,65.307419,-288.325531,-0.000306,0.004177,0.106095,290.501923,14.798873,1.060951,-288.325531,0.105662,0.000000
136.460007,65.244125,-288.325531,-0.000302,0.004151,0.105437,290.220367,14.784530,1.054366,-288.325531,0.104908,0.000000
136.910004,65.186401,-288.369995,-0.000306,0.004120,0.104648,289.963593,14.771450,1.046478,-288.369995,0.104162,0.000000
137.360001,65.166290,-288.369995,-0.000297,0.004097,0.104076,289.874146,14.766892,1.040755,-288.369995,0.103408,0.000000
137.810013,65.109329,-288.414490,-0.000293,0.004063,0.103191,289.620758,14.753985,1.031914,-288.414490,0.102661,0.000000
138.260010,65.077301,-288.414490,-0.000289,0.004039,0.102592,289.478302,14.746727,1.025918,-288.414490,0.101908,0.000000
138.710007,65.050858,-288.414490,-0.000297,0.004006,0.101752,289.360657,14.740735,1.017516,-288.414490,0.101161,0.000000
139.160004,65.019958,-288.458954,-0.000302,0.003979,0.101057,289.223206,14.733733,1.010567,-288.458954,0.100407,0.000000
139.610001,64.666199,-288.547943,-0.000293,0.003947,0.100259,287.649628,14.653570,1.002588,-288.547943,0.099661,0.000000
140.060013,64.029816,-288.503448,-0.000280,0.003924,0.099679,284.818848,14.509364,0.996790,-288.503448,0.098907,0.000000
140.510010,63.095535,-288.547943,-0.000276,0.003902,0.099123,280.662964,14.297652,0.991234,-288.547943,0.098160,0.000000
140.960007,61.569550,-288.547943,-0.000237,0.003872,0.098351,273.875031,13.951859,0.983513,-288.547943,0.097407,0.000000
141.410004,59.408676,-288.636902,-0.000237,0.003836,0.097423,264.263000,13.462198,0.974232,-288.636902,0.096660,0.000000
141.860001,56.601730,-288.636902,-0.000237,0.003809,0.096756,251.777069,12.826136,0.967555,-288.636902,0.095915,0.000000
142.310013,54.189499,-288.725861,-0.000237,0.003783,0.096088,241.046936,12.279516,0.960879,-288.725861,0.095160,0.000000
142.760010,51.723648,-288.725861,-0.000259,0.003762,0.095550,230.078278,11.720746,0.955504,-288.725861,0.094415,0.000000
143.210007,48.531677,-288.725861,-0.000241,0.003731,0.094762,215.879684,10.997436,0.947617,-288.725861,0.093659,0.000000
143.660004,44.444885,-288.725861,-0.000241,0.003694,0.093825,197.700729,10.071355,0.938245,-288.725861,0.092915,0.000000
144.110001,41.022781,-288.770325,-0.000229,0.003664,0.093061,182.478439,9.295895,0.930615,-288.770325,0.092159,0.000000
144.560013,38.163338,-288.814819,-0.000241,0.003636,0.092359,169.759003,8.647936,0.923590,-288.814819,0.091414,0.000000
145.010010,35.357140,-288.770325,-0.000237,0.003610,0.091682,157.276413,8.012042,0.916823,-288.770325,0.090659,0.000000
145.460007,32.826492,-288.859283,-0.000246,0.003587,0.091110,146.019531,7.438589,0.911100,-288.859283,0.089914,0.000000
145.910004,28.191574,-288.903778,-0.000246,0.003546,0.090061,125.402382,6.388302,0.900608,-288.903778,0.089158,0.000000
146.360001,25.121735,-288.948273,-0.000229,0.003520,0.089419,111.747055,5.692666,0.894189,-288.948273,0.088414,0.000000
146.810013,22.550873,-288.903778,-0.000237,0.003496,0.088795,100.311295,5.110101,0.887951,-288.903778,0.087658,0.000000
147.260010,18.955994,-288.948273,-0.000241,0.003461,0.087902,84.320473,4.295489,0.879019,-288.948273,0.086913,0.000000
147.710007,14.995438,-288.948273,-0.000246,0.003427,0.087034,66.703041,3.398015,0.870344,-288.948273,0.086158,0.000000
148.160004,12.552673,-288.948273,-0.000237,0.003402,0.086402,55.837078,2.844476,0.864016,-288.948273,0.085413,0.000000
148.610001,9.057213,-289.037231,-0.000250,0.003375,0.085716,40.288494,2.052394,0.857158,-289.037231,0.084657,0.000000
149.060013,6.355278,-289.037231,-0.000241,0.003348,0.085039,28.269688,1.440127,0.850390,-289.037231,0.083913,0.000000
149.510010,2.135185,-289.126190,-0.000233,0.003308,0.084016,9.497778,0.483840,0.840156,-289.126190,0.083157,0.000000
149.960007,0.276299,-289.126190,-0.000237,0.003289,0.083539,1.229037,0.062610,0.835387,-289.126190,0.082412,0.000000
150.410004,-3.346886,-289.126190,-0.000254,0.003252,0.082594,-14.887691,-0.758415,0.825940,-289.126190,0.081657,0.000000
150.860001,-0.208160,-289.215149,-0.000254,0.003224,0.081882,-0.925944,-0.047170,0.818824,-289.215149,0.080912,0.000000
151.310013,-0.082664,-289.215149,-0.000237,0.003188,0.080982,-0.367710,-0.018732,0.809816,-289.215149,0.080157,0.000000
151.760010,-0.041336,-289.259613,-0.000246,0.003165,0.080400,-0.183872,-0.009367,0.804003,-289.259613,0.079412,0.000000
152.210007,-0.072983,-289.215149,-0.000237,0.003140,0.079749,-0.324644,-0.016538,0.797493,-289.215149,0.078656,0.000000
152.660004,-0.058090,-289.304108,-0.000250,0.003104,0.078847,-0.258398,-0.013163,0.788469,-289.304108,0.077911,0.000000
153.110001,-0.048782,-289.215149,-0.000259,0.003082,0.078284,-0.216995,-0.011054,0.782837,-289.215149,0.077156,0.000000
153.560013,-0.073357,-289.304108,-0.000272,0.003047,0.077381,-0.326307,-0.016623,0.773814,-289.304108,0.076411,0.000000
154.010010,-0.086021,-289.348572,-0.000293,0.003021,0.076732,-0.382642,-0.019493,0.767319,-289.348572,0.075656,0.000000
154.460007,-0.061073,-289.348572,-0.000358,0.002993,0.076011,-0.271668,-0.013839,0.760113,-289.348572,0.074911,0.000000
154.910004,-0.065910,-289.393066,-0.000461,0.002963,0.075266,-0.293184,-0.014935,0.752664,-289.393066,0.074155,0.000000
155.360001,-0.017128,-289.348572,-0.000535,0.002928,0.074373,-0.076189,-0.003881,0.743732,-289.348572,0.073410,0.000000
155.810013,-0.024574,-289.437561,-0.000595,0.002904,0.073766,-0.109312,-0.005569,0.737661,-289.437561,0.072656,0.000000
156.260010,-0.031281,-289.482025,-0.000660,0.002867,0.072812,-0.139143,-0.007088,0.728123,-289.482025,0.071910,0.000000
156.710007,-0.046547,-289.482025,-0.000737,0.002839,0.072110,-0.207051,-0.010548,0.721098,-289.482025,0.071156,0.000000
157.160004,-0.011917,-289.526520,-0.000785,0.002809,0.071347,-0.053010,-0.002700,0.713468,-289.526520,0.070410,0.000000
157.610001,-0.020485,-289.570984,-0.000815,0.002782,0.070661,-0.091121,-0.004642,0.706610,-289.570984,0.069656,0.000000
158.060013,-0.035004,-289.570984,-0.000875,0.002750,0.069854,-0.155704,-0.007932,0.698540,-289.570984,0.068909,0.000000
158.510010,-0.072243,-289.570984,-0.000923,0.002721,0.069117,-0.321352,-0.016370,0.691167,-289.570984,0.068155,0.000000
158.960007,-0.038353,-289.570984,-0.000966,0.002700,0.068579,-0.170603,-0.008691,0.685793,-289.570984,0.067409,0.000000
159.410004,-0.044312,-289.615479,-0.001035,0.002660,0.067556,-0.197107,-0.010041,0.675558,-289.615479,0.066655,0.000000
159.860001,-0.062187,-289.704437,-0.001078,0.002636,0.066958,-0.276622,-0.014092,0.669578,-289.704437,0.065909,0.000000
160.310013,-0.071495,-289.704437,-0.001117,0.002602,0.066099,-0.318026,-0.016201,0.660994,-289.704437,0.065155,0.000000
160.760010,-0.068520,-289.704437,-0.001155,0.002578,0.065492,-0.304790,-0.015527,0.654923,-289.704437,0.064408,0.000000
161.210007,-0.089371,-289.659943,-0.001181,0.002546,0.064660,-0.397541,-0.020252,0.646596,-289.659943,0.063662,0.000000
161.660004,-0.090485,-289.748901,-0.001212,0.002516,0.063897,-0.402496,-0.020504,0.638966,-289.748901,0.062908,0.000000
162.110001,-0.054367,-289.793396,-0.001263,0.002483,0.063073,-0.241837,-0.012320,0.630730,-289.793396,0.062162,0.000000
162.560013,-0.075218,-289.882355,-0.001281,0.002458,0.062422,-0.334587,-0.017045,0.624220,-289.882355,0.061408,0.000000
163.010010,-0.081177,-289.882355,-0.001337,0.002418,0.061408,-0.361092,-0.018395,0.614076,-289.882355,0.060661,0.000000
163.460007,-0.051018,-289.882355,-0.001358,0.002395,0.060835,-0.226938,-0.011561,0.608354,-289.882355,0.059907,0.000000
163.910004,-0.079315,-289.837891,-0.001414,0.002369,0.060184,-0.352812,-0.017973,0.601844,-289.837891,0.059161,0.000000
164.360001,-0.112083,-289.971313,-0.001427,0.002338,0.059387,-0.498572,-0.025398,0.593865,-289.971313,0.058407,0.000000
164.810013,-0.110222,-290.015808,-0.001457,0.002309,0.058658,-0.490291,-0.024977,0.586583,-290.015808,0.057661,0.000000
165.260010,-0.095703,-290.015808,-0.001496,0.002274,0.057748,-0.425709,-0.021687,0.577484,-290.015808,0.056907,0.000000
165.710007,-0.108360,-290.015808,-0.001531,0.002248,0.057097,-0.482011,-0.024555,0.570974,-290.015808,0.056160,0.000000
166.160004,-0.116180,-290.060272,-0.001548,0.002223,0.056455,-0.516796,-0.026327,0.564555,-290.060272,0.055406,0.000000
166.610001,-0.133682,-290.104767,-0.001595,0.002195,0.055753,-0.594648,-0.030293,0.557530,-290.104767,0.054661,0.000000
167.060013,-0.112083,-290.060272,-0.001643,0.002154,0.054713,-0.498572,-0.025398,0.547129,-290.060272,0.053906,0.000000
167.510010,-0.112831,-290.104767,-0.001656,0.002130,0.054106,-0.501898,-0.025568,0.541058,-290.104767,0.053161,0.000000
167.960007,-0.110970,-290.149231,-0.001694,0.002102,0.053385,-0.493617,-0.025146,0.533852,-290.149231,0.052406,0.000000
168.410004,-0.147461,-290.193726,-0.001729,0.002075,0.052701,-0.655939,-0.033415,0.527009,-290.193726,0.051661,0.000000
168.860001,-0.085274,-290.238220,-0.001750,0.002039,0.051782,-0.379317,-0.019323,0.517819,-290.238220,0.050905,0.000000
169.310013,-0.102402,-290.282684,-0.001789,0.002014,0.051149,-0.455506,-0.023205,0.511491,-290.282684,0.050160,0.000000
169.760010,-0.100540,-290.282684,-0.001815,0.001978,0.050229,-0.447225,-0.022783,0.502286,-290.282684,0.049405,0.000000
170.210007,-0.102776,-290.282684,-0.001858,0.001953,0.049605,-0.457169,-0.023289,0.496048,-290.282684,0.048660,0.000000
170.660004,-0.086761,-290.371643,-0.001914,0.001916,0.048668,-0.385934,-0.019660,0.486677,-290.371643,0.047905,0.000000
171.110001,-0.087883,-290.327179,-0.001944,0.001895,0.048130,-0.390923,-0.019915,0.481302,-290.327179,0.047160,0.000000
171.560013,-0.093468,-290.371643,-0.001970,0.001862,0.047290,-0.415765,-0.021180,0.472900,-290.371643,0.046404,0.000000
172.010010,-0.054741,-290.416138,-0.002001,0.001831,0.046500,-0.243500,-0.012404,0.464997,-290.416138,0.045659,0.000000
172.460007,-0.079315,-290.460602,-0.002022,0.001811,0.045997,-0.352812,-0.017973,0.459971,-290.460602,0.044904,0.000000
172.910004,-0.100540,-290.460602,-0.002070,0.001774,0.045052,-0.447225,-0.022783,0.450524,-290.460602,0.044159,0.000000
173.360001,-0.118790,-290.460602,-0.002070,0.001749,0.044418,-0.528403,-0.026918,0.444180,-290.460602,0.043404,0.000000
173.810013,-0.105751,-290.549561,-0.002117,0.001718,0.043629,-0.470404,-0.023964,0.436292,-290.549561,0.042659,0.000000
174.260010,-0.120277,-290.594055,-0.002169,0.001690,0.042936,-0.535021,-0.027255,0.429358,-290.594055,0.041903,0.000000
174.710007,-0.071495,-290.549561,-0.002190,0.001655,0.042034,-0.318026,-0.016201,0.420335,-290.549561,0.041158,0.000000
175.160004,-0.085274,-290.594055,-0.002229,0.001630,0.041392,-0.379317,-0.019323,0.413916,-290.594055,0.040403,0.000000
175.610016,-0.066284,-290.594055,-0.002255,0.001598,0.040594,-0.294847,-0.015020,0.405938,-290.594055,0.039658,0.000000
176.060013,-0.076706,-290.683014,-0.002298,0.001573,0.039952,-0.341205,-0.017382,0.399518,-290.683014,0.038903,0.000000
176.510010,-0.056602,-290.638519,-0.002320,0.001543,0.039189,-0.251780,-0.012826,0.391888,-290.638519,0.038158,0.000000
176.960007,-0.047295,-290.727509,-0.002350,0.001511,0.038383,-0.210377,-0.010717,0.383834,-290.727509,0.037402,0.000000
177.410004,-0.037239,-290.727509,-0.002376,0.001481,0.037611,-0.165648,-0.008438,0.376113,-290.727509,0.036657,0.000000
177.860016,-0.061073,-290.727509,-0.002419,0.001450,0.036822,-0.271668,-0.013839,0.368225,-290.727509,0.035902,0.000000
178.310013,-0.032028,-290.727509,-0.002432,0.001427,0.036241,-0.142469,-0.007258,0.362411,-290.727509,0.035157,0.000000
178.760010,-0.015266,-290.771973,-0.002479,0.001393,0.035383,-0.067908,-0.003459,0.353827,-290.771973,0.034402,0.000000
179.210007,-0.024948,-290.771973,-0.002505,0.001360,0.034541,-0.110975,-0.005653,0.345410,-290.771973,0.033657,0.000000
179.660004,-0.052879,-290.905426,-0.002527,0.001335,0.033908,-0.235219,-0.011983,0.339081,-290.905426,0.032901,0.000000
180.110016,-0.084526,-290.905426,-0.002570,0.001307,0.033197,-0.375991,-0.019154,0.331966,-290.905426,0.032156,0.000000
180.560013,-0.052132,-290.949890,-0.002587,0.001276,0.032399,-0.231893,-0.011813,0.323987,-290.949890,0.031401,0.000000
181.010010,-0.062561,-290.905426,-0.002621,0.001257,0.031931,-0.278285,-0.014177,0.319309,-290.905426,0.030656,0.000000
181.460007,-0.067024,-290.949890,-0.002665,0.001217,0.030907,-0.298139,-0.015188,0.309075,-290.949890,0.029910,0.000000
181.910004,-0.080803,-290.949890,-0.002703,0.001186,0.030135,-0.359429,-0.018310,0.301353,-290.949890,0.029156,0.000000
182.360016,-0.067398,-290.994385,-0.002729,0.001154,0.029303,-0.299802,-0.015273,0.293027,-290.994385,0.028409,0.000000
182.810013,-0.086388,-291.038849,-0.002764,0.001125,0.028565,-0.384271,-0.019576,0.285654,-291.038849,0.027655,0.000000
183.260010,-0.070007,-291.038849,-0.002807,0.001095,0.027811,-0.311408,-0.015864,0.278114,-291.038849,0.026909,0.000000
183.710007,-0.072983,-291.038849,-0.002833,0.001071,0.027204,-0.324644,-0.016538,0.272043,-291.038849,0.026155,0.000000
184.160004,-0.070755,-291.083344,-0.002880,0.001030,0.026172,-0.314734,-0.016033,0.261718,-291.083344,0.025409,0.000000
184.610016,-0.051392,-291.083344,-0.002902,0.001007,0.025583,-0.228601,-0.011646,0.255829,-291.083344,0.024655,0.000000
185.060013,-0.075218,-291.172302,-0.002928,0.000980,0.024889,-0.334587,-0.017045,0.248895,-291.172302,0.023908,0.000000
185.510010,-0.109848,-291.083344,-0.002958,0.000951,0.024143,-0.488628,-0.024892,0.241431,-291.083344,0.023154,0.000000
185.900009,-0.054367,-291.172302,-0.002992,0.000930,0.023631,-0.241837,-0.012320,0.236314,-291.172302,0.023485,0.000000