File: Data/compression 32/AutoNoHeating-15-32-reverse-1-0_11142024_175040.csv
Time (sec),S:Load (lbs),S:HL1 (DIM),S:LVDT (in),S:Position (in),Ch:Position (mm),Ch:Load (N),Ch:Stress (MPa),Ch:Strain (mm/mm),Ch:HL1 (DIM),Set Point (),Cycles ()
0.110000,-0.023460,-277.027374,-0.013292,-0.008366,-0.212496,-0.104357,-0.005316,-2.124963,-277.027374,-0.212349,0.000000
0.490000,-0.019737,-276.982880,-0.013258,-0.008284,-0.210415,-0.087796,-0.004473,-2.104150,-276.982880,-0.209765,0.000000
0.870000,-0.035378,-277.160797,-0.013111,-0.008048,-0.204414,-0.157367,-0.008017,-2.044138,-277.160797,-0.203434,0.000000
1.250000,-0.030533,-277.160797,-0.012866,-0.007801,-0.198152,-0.135817,-0.006919,-1.981524,-277.160797,-0.197103,0.000000
1.630000,-0.009682,-277.071838,-0.012577,-0.007553,-0.191856,-0.043066,-0.002194,-1.918563,-277.071838,-0.190772,0.000000
2.010000,-0.040588,-277.116333,-0.012335,-0.007303,-0.185508,-0.180546,-0.009197,-1.855083,-277.116333,-0.184442,0.000000
2.390000,-0.100540,-277.160797,-0.012068,-0.007055,-0.179186,-0.447225,-0.022783,-1.791862,-277.160797,-0.178111,0.000000
2.770000,-0.096443,-277.116333,-0.011814,-0.006809,-0.172942,-0.429001,-0.021854,-1.729421,-277.116333,-0.171780,0.000000
3.150000,-0.043938,-277.294250,-0.011559,-0.006556,-0.166525,-0.195445,-0.009956,-1.665247,-277.294250,-0.165449,0.000000
3.530000,-0.045433,-277.205292,-0.011296,-0.006308,-0.160220,-0.202096,-0.010295,-1.602200,-277.205292,-0.159119,0.000000
3.910000,-0.043938,-277.116333,-0.011050,-0.006059,-0.153889,-0.195445,-0.009956,-1.538892,-277.116333,-0.152788,0.000000
4.290000,-0.084526,-277.205292,-0.010770,-0.005807,-0.147506,-0.375991,-0.019154,-1.475064,-277.205292,-0.146457,0.000000
4.670000,-0.072983,-277.338715,-0.010529,-0.005556,-0.141115,-0.324644,-0.016538,-1.411150,-277.338715,-0.140126,0.000000
5.050000,-0.010056,-277.294250,-0.010287,-0.005311,-0.134888,-0.044729,-0.002279,-1.348883,-277.294250,-0.133796,0.000000
5.430000,0.001862,-277.249756,-0.010020,-0.005059,-0.128506,0.008281,0.000422,-1.285055,-277.249756,-0.127465,0.000000
5.810000,0.005585,-277.249756,-0.009770,-0.004817,-0.122357,0.024842,0.001266,-1.223569,-277.249756,-0.121134,0.000000
6.190000,-0.036865,-277.249756,-0.009511,-0.004566,-0.115965,-0.163985,-0.008354,-1.159654,-277.249756,-0.114803,0.000000
6.570000,-0.050270,-277.294250,-0.009257,-0.004316,-0.109617,-0.223612,-0.011391,-1.096173,-277.294250,-0.108473,0.000000
6.950000,-0.030159,-277.338715,-0.009024,-0.004074,-0.103486,-0.134154,-0.006834,-1.034860,-277.338715,-0.102142,0.000000
7.330000,0.011543,-277.383209,-0.008748,-0.003820,-0.097025,0.051347,0.002616,-0.970252,-277.383209,-0.095811,0.000000
7.710001,0.039841,-277.338715,-0.008494,-0.003572,-0.090720,0.177220,0.009028,-0.907205,-277.338715,-0.089480,0.000000
8.090000,0.014893,-277.338715,-0.008235,-0.003320,-0.084329,0.066245,0.003375,-0.843290,-277.338715,-0.083150,0.000000
8.470000,0.000374,-277.427704,-0.007968,-0.003065,-0.077860,0.001663,0.000085,-0.778595,-277.427704,-0.076819,0.000000
8.850000,-0.017128,-277.472168,-0.007718,-0.002822,-0.071668,-0.076189,-0.003881,-0.716675,-277.472168,-0.070488,0.000000
9.230000,-0.000748,-277.383209,-0.007463,-0.002570,-0.065285,-0.003326,-0.000169,-0.652848,-277.383209,-0.064157,0.000000
9.610001,0.000748,-277.383209,-0.007205,-0.002322,-0.058971,0.003326,0.000169,-0.589713,-277.383209,-0.057827,0.000000
9.990001,0.005211,-277.427704,-0.006937,-0.002070,-0.052571,0.023179,0.001181,-0.525712,-277.427704,-0.051496,0.000000
10.370001,-0.027184,-277.472168,-0.006674,-0.001825,-0.046362,-0.120918,-0.006160,-0.463619,-277.472168,-0.045165,0.000000
10.750001,-0.037979,-277.561127,-0.006416,-0.001575,-0.039996,-0.168940,-0.008606,-0.399965,-277.561127,-0.038834,0.000000
11.130000,-0.082298,-277.561127,-0.006170,-0.001326,-0.033692,-0.366081,-0.018649,-0.336917,-277.561127,-0.032504,0.000000
11.510000,-0.004471,-277.472168,-0.005924,-0.001076,-0.027326,-0.019887,-0.001013,-0.273263,-277.472168,-0.026173,0.000000
11.890000,-0.004845,-277.605621,-0.005665,-0.000827,-0.021013,-0.021550,-0.001098,-0.210129,-277.605621,-0.019842,0.000000
12.270000,0.010429,-277.605621,-0.005407,-0.000579,-0.014708,0.046392,0.002363,-0.147081,-277.605621,-0.013511,0.000000
12.650001,-0.030159,-277.650085,-0.005131,-0.000327,-0.008308,-0.134154,-0.006834,-0.083080,-277.650085,-0.007181,0.000000
13.030001,0.140015,-277.605621,-0.004941,-0.000002,-0.000061,0.622816,0.031728,-0.000607,-277.605621,0.000156,0.000000
13.410001,0.134796,-277.605621,-0.004954,-0.000002,-0.000061,0.599603,0.030545,-0.000607,-277.605621,0.000156,0.000000
13.790001,0.105011,-277.561127,-0.004958,-0.000002,-0.000061,0.467112,0.023796,-0.000607,-277.561127,0.000711,0.000000
14.170001,0.180969,-277.650085,-0.004932,0.000020,0.000503,0.804991,0.041008,0.005030,-277.650085,0.001344,0.000000
14.550001,0.263641,-277.694580,-0.004919,0.000043,0.001101,1.172735,0.059742,0.011014,-277.694580,0.001977,0.000000
14.930000,0.388008,-277.694580,-0.004898,0.000069,0.001760,1.725946,0.087924,0.017605,-277.694580,0.002610,0.000000
15.310000,0.512383,-277.694580,-0.004876,0.000095,0.002411,2.279191,0.116108,0.024109,-277.694580,0.003243,0.000000
15.690001,0.698944,-277.694580,-0.004859,0.000117,0.002966,3.109059,0.158383,0.029659,-277.694580,0.003877,0.000000
16.070002,0.876190,-277.828033,-0.004842,0.000136,0.003460,3.897489,0.198548,0.034602,-277.828033,0.004510,0.000000
16.450001,1.021790,-277.783539,-0.004820,0.000154,0.003911,4.545147,0.231541,0.039112,-277.783539,0.005143,0.000000
16.830000,1.434006,-277.872498,-0.004794,0.000193,0.004909,6.378776,0.324950,0.049085,-277.872498,0.005776,0.000000
17.210001,1.683121,-277.828033,-0.004764,0.000216,0.005498,7.486895,0.381401,0.054982,-277.828033,0.006417,0.000000
17.590000,1.971336,-277.783539,-0.004747,0.000240,0.006097,8.768942,0.446711,0.060966,-277.783539,0.007051,0.000000
17.970001,2.308708,-277.828033,-0.004721,0.000261,0.006634,10.269647,0.523161,0.066343,-277.828033,0.007684,0.000000
18.350000,2.639374,-277.872498,-0.004717,0.000280,0.007103,11.740520,0.598091,0.071026,-277.872498,0.008317,0.000000
18.730001,3.212456,-277.916992,-0.004661,0.000318,0.008083,14.289717,0.727953,0.080825,-277.916992,0.008950,0.000000
19.110001,3.456360,-277.828033,-0.004669,0.000339,0.008603,15.374657,0.783222,0.086029,-277.828033,0.009583,0.000000
19.490002,3.983269,-277.872498,-0.004622,0.000367,0.009314,17.718464,0.902622,0.093140,-277.872498,0.010216,0.000000
19.870001,4.385429,-277.961456,-0.004618,0.000387,0.009834,19.507364,0.993752,0.098343,-277.961456,0.010849,0.000000
20.250002,4.802116,-278.005951,-0.004592,0.000409,0.010398,21.360880,1.088175,0.103980,-278.005951,0.011482,0.000000
20.630001,5.348755,-277.916992,-0.004566,0.000440,0.011170,23.792450,1.212045,0.111699,-277.916992,0.012115,0.000000
21.010000,5.702515,-277.961456,-0.004549,0.000465,0.011820,25.366053,1.292208,0.118203,-277.961456,0.012748,0.000000
21.390001,6.142281,-277.961456,-0.004506,0.000491,0.012471,27.322229,1.391861,0.124707,-277.961456,0.013381,0.000000
21.770000,6.459915,-278.050415,-0.004493,0.000512,0.013008,28.735138,1.463838,0.130084,-278.050415,0.014014,0.000000
22.150002,6.889259,-278.050415,-0.004480,0.000534,0.013572,30.644957,1.561128,0.135721,-278.050415,0.014647,0.000000
22.530001,7.456383,-278.139374,-0.004458,0.000564,0.014335,33.167648,1.689641,0.143352,-278.139374,0.015281,0.000000
22.910002,7.827644,-278.005951,-0.004406,0.000591,0.015003,34.819099,1.773770,0.150030,-278.005951,0.015914,0.000000
23.290001,8.216400,-278.050415,-0.004406,0.000617,0.015679,36.548374,1.861863,0.156794,-278.050415,0.016547,0.000000
23.670002,8.435722,-278.139374,-0.004381,0.000636,0.016165,37.523968,1.911562,0.161651,-278.139374,0.017180,0.000000
24.050001,8.890762,-278.139374,-0.004355,0.000661,0.016789,39.548084,2.014675,0.167895,-278.139374,0.017813,0.000000
24.430000,9.310425,-278.139374,-0.004329,0.000690,0.017527,41.414837,2.109772,0.175266,-278.139374,0.018446,0.000000
24.810001,9.601997,-278.139374,-0.004303,0.000716,0.018186,42.711819,2.175844,0.181857,-278.139374,0.019079,0.000000
25.190001,10.021286,-278.183868,-0.004273,0.000739,0.018758,44.576908,2.270856,0.187581,-278.183868,0.019712,0.000000
25.570002,10.337059,-278.228363,-0.004243,0.000763,0.019374,45.981537,2.342411,0.193738,-278.228363,0.020345,0.000000
25.950001,10.565697,-278.228363,-0.004238,0.000783,0.019885,46.998566,2.394221,0.198855,-278.228363,0.020978,0.000000
26.330002,11.284378,-278.228363,-0.004204,0.000816,0.020735,50.195419,2.557077,0.207354,-278.228363,0.021611,0.000000
26.710001,11.477264,-278.228363,-0.004174,0.000840,0.021334,51.053421,2.600785,0.213338,-278.228363,0.022244,0.000000
27.090002,11.642967,-278.228363,-0.004143,0.000864,0.021941,51.790504,2.638334,0.219408,-278.228363,0.022877,0.000000
27.470001,12.042152,-278.272827,-0.004130,0.000888,0.022548,53.566170,2.728791,0.225479,-278.272827,0.023510,0.000000
27.850000,12.285683,-278.272827,-0.004092,0.000909,0.023094,54.649445,2.783976,0.230942,-278.272827,0.024144,0.000000
28.230001,13.070648,-278.317322,-0.004074,0.000941,0.023909,58.141148,2.961851,0.239094,-278.317322,0.024785,0.000000
28.610001,13.055748,-278.317322,-0.004036,0.000965,0.024508,58.074867,2.958475,0.245078,-278.317322,0.025418,0.000000
28.990002,13.164108,-278.361786,-0.004027,0.000986,0.025054,58.556877,2.983030,0.250542,-278.361786,0.026051,0.000000
29.370001,13.754692,-278.406281,-0.004001,0.001018,0.025861,61.183926,3.116858,0.258607,-278.406281,0.026685,0.000000
29.750002,13.553238,-278.406281,-0.003971,0.001038,0.026355,60.287815,3.071208,0.263550,-278.406281,0.027318,0.000000
30.130001,14.197441,-278.406281,-0.003932,0.001061,0.026945,63.153374,3.217186,0.269447,-278.406281,0.027951,0.000000
30.510002,14.433159,-278.361786,-0.003898,0.001085,0.027569,64.201897,3.270601,0.275691,-278.361786,0.028584,0.000000
30.890001,14.658066,-278.450745,-0.003880,0.001112,0.028254,65.202332,3.321565,0.282542,-278.450745,0.029217,0.000000
31.270002,15.046829,-278.495239,-0.003850,0.001140,0.028957,66.931641,3.409660,0.289567,-278.495239,0.029850,0.000000
31.650002,15.068794,-278.495239,-0.003824,0.001163,0.029538,67.029343,3.414638,0.295377,-278.495239,0.030483,0.000000
32.030003,15.308228,-278.450745,-0.003820,0.001186,0.030136,68.094398,3.468894,0.301361,-278.450745,0.031116,0.000000
32.410000,15.613205,-278.450745,-0.003773,0.001213,0.030813,69.451004,3.538003,0.308125,-278.450745,0.031749,0.000000
32.790001,15.892113,-278.539703,-0.003721,0.001240,0.031498,70.691650,3.601204,0.314976,-278.539703,0.032382,0.000000
33.170002,16.120750,-278.539703,-0.003721,0.001265,0.032139,71.708679,3.653014,0.321394,-278.539703,0.033015,0.000000
33.550003,16.329651,-278.495239,-0.003673,0.001291,0.032790,72.637917,3.700352,0.327898,-278.495239,0.033648,0.000000
33.930000,16.621964,-278.584198,-0.003643,0.001318,0.033484,73.938187,3.766591,0.334836,-278.584198,0.034281,0.000000
34.310001,16.621964,-278.628693,-0.003600,0.001340,0.034039,73.938187,3.766591,0.340386,-278.628693,0.034915,0.000000
34.690002,16.802193,-278.628693,-0.003574,0.001365,0.034672,74.739883,3.807431,0.346717,-278.628693,0.035548,0.000000
35.070004,16.998055,-278.628693,-0.003570,0.001389,0.035270,75.611122,3.851814,0.352701,-278.628693,0.036181,0.000000
35.450001,16.888954,-278.673157,-0.003523,0.001407,0.035730,75.125824,3.827092,0.357297,-278.673157,0.036814,0.000000
35.830002,17.486237,-278.584198,-0.003510,0.001439,0.036562,77.782661,3.962438,0.365622,-278.584198,0.037447,0.000000
36.210003,17.610985,-278.628693,-0.003471,0.001463,0.037152,78.337570,3.990706,0.371520,-278.628693,0.038080,0.000000
36.590000,17.658272,-278.717651,-0.003441,0.001487,0.037776,78.547913,4.001421,0.377764,-278.717651,0.038713,0.000000
36.970001,17.819511,-278.806610,-0.003419,0.001511,0.038375,79.265144,4.037959,0.383747,-278.806610,0.039346,0.000000
37.350002,17.975166,-278.717651,-0.003397,0.001534,0.038956,79.957535,4.073231,0.389558,-278.717651,0.039979,0.000000
37.730003,17.839249,-278.717651,-0.003367,0.001550,0.039381,79.352943,4.042431,0.393807,-278.717651,0.040612,0.000000
38.110001,18.833855,-278.806610,-0.003316,0.001589,0.040369,83.777168,4.267813,0.403694,-278.806610,0.041245,0.000000
38.490002,18.672241,-278.806610,-0.003294,0.001612,0.040950,83.058281,4.231190,0.409504,-278.806610,0.041878,0.000000
38.870003,18.802948,-278.851074,-0.003255,0.001637,0.041575,83.639687,4.260809,0.415748,-278.851074,0.042511,0.000000
39.250000,18.912422,-278.806610,-0.003221,0.001660,0.042156,84.126656,4.285616,0.421558,-278.806610,0.043153,0.000000
39.630001,18.902000,-278.806610,-0.003195,0.001678,0.042624,84.080299,4.283255,0.426241,-278.806610,0.043786,0.000000
40.010002,19.830322,-278.851074,-0.003156,0.001715,0.043561,88.209679,4.493615,0.435607,-278.851074,0.044419,0.000000
40.390003,19.414009,-278.895569,-0.003122,0.001735,0.044072,86.357826,4.399278,0.440724,-278.895569,0.045052,0.000000
40.770000,19.647858,-278.940033,-0.003117,0.001760,0.044705,87.398033,4.452268,0.447055,-278.940033,0.045685,0.000000
41.150002,19.832932,-278.940033,-0.003074,0.001784,0.045321,88.221283,4.494206,0.453212,-278.940033,0.046319,0.000000
41.530003,19.993423,-278.895569,-0.003040,0.001807,0.045894,88.935188,4.530574,0.458936,-278.895569,0.046952,0.000000
41.910004,20.428352,-278.940033,-0.003018,0.001836,0.046622,90.869850,4.629131,0.466221,-278.940033,0.047585,0.000000
42.290001,20.601135,-278.984528,-0.002979,0.001860,0.047238,91.638428,4.668284,0.472378,-278.984528,0.048218,0.000000
42.670002,20.822693,-278.984528,-0.002945,0.001885,0.047871,92.623962,4.718490,0.478709,-278.984528,0.048851,0.000000
43.050003,20.924355,-278.984528,-0.002902,0.001909,0.048495,93.076180,4.741526,0.484953,-278.984528,0.049484,0.000000
43.430000,20.858818,-279.028992,-0.002880,0.001932,0.049085,92.784660,4.726676,0.490850,-279.028992,0.050117,0.000000
43.810001,21.436363,-278.984528,-0.002859,0.001962,0.049822,95.353706,4.857550,0.498221,-278.984528,0.050750,0.000000
44.190002,21.688835,-279.117981,-0.002828,0.001987,0.050464,96.476761,4.914760,0.504639,-279.117981,0.051383,0.000000
44.570004,21.682129,-279.117981,-0.002790,0.002010,0.051054,96.446930,4.913240,0.510536,-279.117981,0.052016,0.000000
44.950001,21.574890,-279.028992,-0.002764,0.002033,0.051635,95.969902,4.888940,0.516346,-279.028992,0.052649,0.000000
45.330002,21.899597,-279.117981,-0.002729,0.002057,0.052242,97.414276,4.962520,0.522417,-279.117981,0.053282,0.000000
45.710003,22.372139,-279.117981,-0.002690,0.002086,0.052987,99.516243,5.069599,0.529875,-279.117981,0.053915,0.000000
46.090004,22.400436,-279.162445,-0.002660,0.002112,0.053638,99.642120,5.076012,0.536379,-279.162445,0.054548,0.000000
46.470001,22.521828,-279.162445,-0.002626,0.002137,0.054280,100.182091,5.103519,0.542797,-279.162445,0.055182,0.000000
46.850002,22.736687,-279.206940,-0.002604,0.002161,0.054895,101.137833,5.152207,0.548954,-279.206940,0.055815,0.000000
47.230003,22.654396,-279.206940,-0.002557,0.002181,0.055407,100.771790,5.133559,0.554071,-279.206940,0.056448,0.000000
47.610001,23.310890,-279.295898,-0.002535,0.002211,0.056170,103.692017,5.282323,0.561702,-279.295898,0.057081,0.000000
47.990002,23.161194,-279.251404,-0.002496,0.002237,0.056812,103.026138,5.248401,0.568120,-279.251404,0.057714,0.000000
48.370003,22.830154,-279.251404,-0.002479,0.002254,0.057246,101.553596,5.173387,0.572456,-279.251404,0.058347,0.000000
48.750004,23.384987,-279.206940,-0.002436,0.002284,0.058026,104.021614,5.299114,0.580261,-279.206940,0.058980,0.000000
49.130001,23.494843,-279.206940,-0.002393,0.002308,0.058616,104.510277,5.324007,0.586158,-279.206940,0.059613,0.000000
49.510002,24.069038,-279.295898,-0.002384,0.002336,0.059344,107.064430,5.454122,0.593443,-279.295898,0.060246,0.000000
49.890003,23.875404,-279.384857,-0.002337,0.002357,0.059865,106.203102,5.410244,0.598646,-279.384857,0.060888,0.000000
50.270004,23.830719,-279.295898,-0.002324,0.002382,0.060506,106.004333,5.400118,0.605063,-279.295898,0.061521,0.000000
50.650002,24.387413,-279.384857,-0.002276,0.002412,0.061252,108.480629,5.526267,0.612521,-279.384857,0.062154,0.000000
51.030003,23.732788,-279.340363,-0.002242,0.002431,0.061755,105.568710,5.377927,0.617551,-279.340363,0.062787,0.000000
51.410004,24.081696,-279.429321,-0.002220,0.002457,0.062406,107.120735,5.456990,0.624056,-279.429321,0.063420,0.000000
51.790001,24.565041,-279.429321,-0.002190,0.002484,0.063091,109.270760,5.566517,0.630907,-279.429321,0.064053,0.000000
52.170002,24.627594,-279.429321,-0.002147,0.002507,0.063680,109.549011,5.580693,0.636804,-279.429321,0.064686,0.000000
52.550003,24.837242,-279.429321,-0.002113,0.002535,0.064392,110.481567,5.628200,0.643915,-279.429321,0.065319,0.000000
52.930004,24.325974,-279.473816,-0.002061,0.002556,0.064912,108.207336,5.512344,0.649118,-279.473816,0.065953,0.000000
53.310001,24.064194,-279.518311,-0.002052,0.002578,0.065476,107.042877,5.453024,0.654755,-279.518311,0.066586,0.000000
53.690002,25.192116,-279.518311,-0.002005,0.002609,0.066273,112.060127,5.708615,0.662734,-279.518311,0.067219,0.000000
54.070004,24.950813,-279.518311,-0.001975,0.002635,0.066932,110.986763,5.653935,0.669325,-279.518311,0.067852,0.000000
54.450001,25.040558,-279.562775,-0.001944,0.002659,0.067540,111.385963,5.674272,0.675395,-279.562775,0.068485,0.000000
54.830002,25.359680,-279.562775,-0.001897,0.002688,0.068277,112.805489,5.746586,0.682767,-279.562775,0.069118,0.000000
55.210003,25.326164,-279.562775,-0.001876,0.002714,0.068927,112.656403,5.738991,0.689271,-279.562775,0.069751,0.000000
55.590004,25.297493,-279.562775,-0.001832,0.002737,0.069525,112.528870,5.732494,0.695255,-279.562775,0.070384,0.000000
55.970001,25.232330,-279.607269,-0.001807,0.002762,0.070150,112.239014,5.717728,0.701499,-279.607269,0.071017,0.000000
56.350002,24.929962,-279.607269,-0.001772,0.002783,0.070688,110.894012,5.649210,0.706876,-279.607269,0.071650,0.000000
56.730003,25.010399,-279.607269,-0.001729,0.002805,0.071243,111.251808,5.667437,0.712426,-279.607269,0.072283,0.000000
57.110004,25.261749,-279.740692,-0.001720,0.002833,0.071962,112.369873,5.724394,0.719624,-279.740692,0.072916,0.000000
57.490002,25.806900,-279.740692,-0.001673,0.002860,0.072647,114.794823,5.847927,0.726475,-279.740692,0.073549,0.000000
57.870003,25.635612,-279.740692,-0.001634,0.002884,0.073255,114.032898,5.809113,0.732546,-279.740692,0.074182,0.000000
58.250004,25.645660,-279.696228,-0.001604,0.002907,0.073836,114.077599,5.811389,0.738356,-279.696228,0.074816,0.000000
58.630001,25.838928,-279.740692,-0.001569,0.002931,0.074451,114.937294,5.855185,0.744513,-279.740692,0.075449,0.000000
59.010002,25.477722,-279.785187,-0.001556,0.002949,0.074894,113.330566,5.773335,0.748936,-279.785187,0.076082,0.000000
59.390003,27.105362,-279.829651,-0.001505,0.002986,0.075848,120.570671,6.142163,0.758476,-279.829651,0.076715,0.000000
59.770004,26.533775,-279.785187,-0.001492,0.003007,0.076368,118.028130,6.012640,0.763679,-279.785187,0.077348,0.000000
60.150002,26.934441,-279.740692,-0.001470,0.003031,0.076992,119.810379,6.103431,0.769923,-279.740692,0.077981,0.000000
60.530003,27.232712,-279.829651,-0.001444,0.003056,0.077625,121.137154,6.171021,0.776254,-279.829651,0.078614,0.000000
60.910004,27.081161,-279.874146,-0.001418,0.003076,0.078120,120.463020,6.136679,0.781197,-279.874146,0.079256,0.000000
61.290005,28.723320,-279.874146,-0.001375,0.003112,0.079048,127.767708,6.508797,0.790476,-279.874146,0.079889,0.000000
61.670002,28.342010,-279.829651,-0.001345,0.003132,0.079551,126.071556,6.422391,0.795506,-279.829651,0.080522,0.000000
62.050003,28.472717,-279.874146,-0.001337,0.003155,0.080140,126.652969,6.452010,0.801403,-279.874146,0.081155,0.000000
62.430004,29.077446,-279.963104,-0.001293,0.003180,0.080773,129.342941,6.589043,0.807734,-279.963104,0.081788,0.000000
62.810001,29.239059,-279.918640,-0.001281,0.003200,0.081285,130.061829,6.625666,0.812851,-279.918640,0.082421,0.000000
63.190002,30.200897,-280.007599,-0.001255,0.003231,0.082074,134.340302,6.843621,0.820742,-280.007599,0.083054,0.000000
63.570004,30.756851,-279.918640,-0.001229,0.003257,0.082716,136.813309,6.969602,0.827160,-279.918640,0.083687,0.000000
63.950005,30.909889,-280.007599,-0.001194,0.003282,0.083358,137.494049,7.004281,0.833577,-280.007599,0.084320,0.000000
64.330002,31.895935,-280.007599,-0.001173,0.003307,0.084008,141.880203,7.227722,0.840082,-280.007599,0.084953,0.000000
64.710007,32.064247,-280.007599,-0.001151,0.003325,0.084459,142.628891,7.265862,0.844591,-280.007599,0.085587,0.000000
65.090004,33.135567,-280.141022,-0.001121,0.003355,0.085205,147.394363,7.508627,0.852049,-280.141022,0.086220,0.000000
65.470001,33.853500,-280.052063,-0.001099,0.003384,0.085942,150.587891,7.671313,0.859421,-280.052063,0.086853,0.000000
65.850006,34.102989,-280.052063,-0.001082,0.003405,0.086488,151.697678,7.727848,0.864884,-280.052063,0.087486,0.000000
66.230003,34.921089,-280.141022,-0.001065,0.003430,0.087113,155.336761,7.913232,0.871128,-280.141022,0.088119,0.000000
66.610001,35.614449,-280.141022,-0.001043,0.003453,0.087703,158.420975,8.070350,0.877025,-280.141022,0.088752,0.000000
66.990005,36.809761,-280.096558,-0.001022,0.003481,0.088414,163.737991,8.341211,0.884137,-280.096558,0.089385,0.000000
67.370003,37.586533,-280.141022,-0.001009,0.003508,0.089099,167.193253,8.517230,0.890988,-280.141022,0.090018,0.000000
67.750000,38.142113,-280.185516,-0.000979,0.003530,0.089662,169.664597,8.643126,0.896625,-280.185516,0.090651,0.000000
68.130005,39.290504,-280.185516,-0.000957,0.003558,0.090374,174.772888,8.903356,0.903736,-280.185516,0.091284,0.000000
68.510002,39.364235,-280.141022,-0.000927,0.003577,0.090851,175.100861,8.920063,0.908506,-280.141022,0.091917,0.000000
68.890007,41.133377,-280.185516,-0.000914,0.003607,0.091614,182.970398,9.320957,0.916137,-280.185516,0.092550,0.000000
69.270004,41.818916,-280.185516,-0.000897,0.003628,0.092151,186.019836,9.476302,0.921514,-280.185516,0.093183,0.000000
69.650002,42.529030,-280.229980,-0.000901,0.003650,0.092715,189.178574,9.637216,0.927151,-280.229980,0.093816,0.000000
70.030006,43.957825,-280.229980,-0.000862,0.003680,0.093470,195.534164,9.960986,0.934696,-280.229980,0.094450,0.000000
70.410004,44.680595,-280.274475,-0.000849,0.003701,0.094016,198.749222,10.124767,0.940159,-280.274475,0.095083,0.000000
70.790001,45.630524,-280.318939,-0.000841,0.003730,0.094744,202.974701,10.340025,0.947444,-280.318939,0.095716,0.000000
71.170006,47.186668,-280.318939,-0.000811,0.003755,0.095377,209.896790,10.692653,0.953775,-280.318939,0.096349,0.000000
71.550003,48.171219,-280.318939,-0.000811,0.003778,0.095967,214.276291,10.915754,0.959672,-280.318939,0.096982,0.000000
71.930000,49.608200,-280.318939,-0.000793,0.003808,0.096713,220.668289,11.241379,0.967130,-280.318939,0.097624,0.000000
72.310005,49.991371,-280.407928,-0.000785,0.003822,0.097077,222.372726,11.328207,0.970772,-280.407928,0.098257,0.000000
72.690002,50.381996,-280.407928,-0.000772,0.003838,0.097494,224.110306,11.416723,0.974935,-280.407928,0.098890,0.000000
73.070000,52.655327,-280.318939,-0.000750,0.003874,0.098395,234.222595,11.931868,0.983954,-280.318939,0.099523,0.000000
73.450005,54.099388,-280.407928,-0.000729,0.003902,0.099115,240.646103,12.259097,0.991152,-280.407928,0.100156,0.000000
73.830002,55.271988,-280.541351,-0.000720,0.003926,0.099722,245.862076,12.524811,0.997223,-280.541351,0.100789,0.000000
74.210007,56.739136,-280.496887,-0.000716,0.003948,0.100286,252.388275,12.857272,1.002860,-280.496887,0.101422,0.000000
74.590004,57.237000,-280.452393,-0.000690,0.003964,0.100694,254.602890,12.970089,1.006936,-280.452393,0.102055,0.000000
74.970001,59.749023,-280.496887,-0.000698,0.004002,0.101656,265.776917,13.539322,1.016562,-280.496887,0.102688,0.000000
75.350006,61.081001,-280.496887,-0.000673,0.004025,0.102246,271.701874,13.841153,1.022459,-280.496887,0.103321,0.000000
75.730003,62.571236,-280.585846,-0.000664,0.004051,0.102888,278.330750,14.178844,1.028877,-280.585846,0.103954,0.000000
76.110001,64.424896,-280.541351,-0.000655,0.004080,0.103625,286.576263,14.598890,1.036248,-280.541351,0.104587,0.000000
76.490005,65.354721,-280.541351,-0.000625,0.004098,0.104084,290.712311,14.809591,1.040844,-280.541351,0.105220,0.000000
76.870003,65.360306,-280.541351,-0.000625,0.004101,0.104171,290.737152,14.810857,1.041712,-280.541351,0.018283,0.000000
77.250000,65.453400,-280.585846,-0.000608,0.004116,0.104553,291.151276,14.831953,1.045527,-280.585846,294.500458,0.000000
77.630005,65.295517,-280.719269,-0.000621,0.004122,0.104700,290.448975,14.796175,1.047001,-280.719269,294.500458,0.000000
78.010002,65.195709,-280.674805,-0.000604,0.004130,0.104900,290.005005,14.773559,1.048996,-280.674805,294.500458,0.000000
78.390007,65.291794,-280.674805,-0.000604,0.004135,0.105021,290.432404,14.795332,1.050210,-280.674805,294.500458,0.000000
78.770004,65.416901,-280.630310,-0.000595,0.004143,0.105220,290.988922,14.823681,1.052205,-280.630310,294.500458,0.000000
79.150002,65.168900,-280.674805,-0.000599,0.004144,0.105247,289.885742,14.767485,1.052465,-280.674805,294.500458,0.000000
79.530006,65.240768,-280.763763,-0.000586,0.004148,0.105368,290.205444,14.783769,1.053679,-280.763763,294.500458,0.000000
79.910004,65.590424,-280.808258,-0.000586,0.004156,0.105567,291.760773,14.863003,1.055674,-280.808258,294.500458,0.000000
80.290001,65.316360,-280.674805,-0.000578,0.004157,0.105585,290.541687,14.800900,1.055847,-280.674805,294.500458,0.000000
80.670006,65.277267,-280.808258,-0.000578,0.004160,0.105671,290.367798,14.792040,1.056715,-280.808258,294.500458,0.000000
81.050003,65.213211,-280.763763,-0.000569,0.004163,0.105732,290.082855,14.777525,1.057322,-280.763763,294.500458,0.000000
81.430000,65.158112,-280.808258,-0.000569,0.004165,0.105802,289.837769,14.765039,1.058015,-280.808258,294.500458,0.000000
81.810005,65.147308,-280.808258,-0.000565,0.004167,0.105854,289.789703,14.762590,1.058536,-280.808258,294.500458,0.000000
82.190002,65.218063,-280.719269,-0.000560,0.004171,0.105932,290.104431,14.778625,1.059316,-280.719269,294.500458,0.000000
82.570007,65.169281,-280.763763,-0.000560,0.004172,0.105975,289.887451,14.767570,1.059750,-280.763763,294.500458,0.000000
82.950005,65.258270,-280.897217,-0.000552,0.004176,0.106062,290.283295,14.787735,1.060617,-280.897217,294.500458,0.000000
83.330002,65.310028,-280.897217,-0.000586,0.004178,0.106131,290.513519,14.799464,1.061311,-280.897217,294.500458,0.000000
83.710007,65.245605,-280.897217,-0.000560,0.004179,0.106140,290.226959,14.784865,1.061398,-280.897217,294.500458,0.000000
84.090004,65.396057,-280.897217,-0.000543,0.004183,0.106244,290.896179,14.818958,1.062438,-280.897217,294.500458,0.000000
84.470001,65.294769,-280.941681,-0.000548,0.004183,0.106244,290.445648,14.796006,1.062438,-280.941681,294.500458,0.000000
84.850006,65.269073,-280.986176,-0.000556,0.004184,0.106279,290.331329,14.790184,1.062785,-280.986176,294.500458,0.000000
85.230003,65.220657,-280.986176,-0.000548,0.004186,0.106322,290.115967,14.779213,1.063219,-280.986176,294.500458,0.000000
85.610001,65.221786,-281.030640,-0.000552,0.004188,0.106374,290.121002,14.779469,1.063739,-281.030640,294.500458,0.000000
85.990005,65.245605,-280.941681,-0.000556,0.004188,0.106383,290.226959,14.784865,1.063826,-280.941681,294.500458,0.000000
86.370003,65.217316,-281.030640,-0.000556,0.004190,0.106435,290.101105,14.778456,1.064346,-281.030640,294.500458,0.000000
86.750008,65.307434,-281.030640,-0.000569,0.004192,0.106478,290.501984,14.798876,1.064780,-281.030640,294.500458,0.000000
87.130005,65.259384,-281.030640,-0.000548,0.004193,0.106513,290.288239,14.787988,1.065127,-281.030640,294.500458,0.000000
87.510002,65.267212,-281.030640,-0.000548,0.004194,0.106530,290.323059,14.789762,1.065300,-281.030640,294.500458,0.000000
87.890007,65.287689,-281.030640,-0.000539,0.004195,0.106565,290.414154,14.794401,1.065647,-281.030640,294.500458,0.000000
88.270004,65.285828,-281.030640,-0.000539,0.004197,0.106599,290.405853,14.793981,1.065994,-281.030640,294.500458,0.000000
88.650002,65.264603,-281.164093,-0.000539,0.004197,0.106599,290.311462,14.789170,1.065994,-281.164093,294.500458,0.000000
89.030006,65.248215,-281.075134,-0.000543,0.004198,0.106634,290.238556,14.785457,1.066341,-281.075134,294.500458,0.000000
89.410004,65.252319,-281.119598,-0.000552,0.004199,0.106660,290.256805,14.786387,1.066601,-281.119598,294.500458,0.000000
89.790001,65.199066,-281.164093,-0.000543,0.004199,0.106660,290.019928,14.774320,1.066601,-281.164093,294.500458,0.000000
90.170006,65.206512,-281.075134,-0.000539,0.004201,0.106695,290.053040,14.776007,1.066948,-281.075134,294.500458,0.000000
90.550003,65.164810,-281.208588,-0.000543,0.004201,0.106695,289.867554,14.766557,1.066948,-281.208588,294.500458,0.000000
90.930008,65.159592,-281.208588,-0.000560,0.004202,0.106729,289.844330,14.765374,1.067295,-281.208588,294.500458,0.000000
91.310005,65.116776,-281.208588,-0.000539,0.004202,0.106729,289.653870,14.755672,1.067295,-281.208588,294.500458,0.000000
91.690002,65.559143,-281.208588,-0.000530,0.004207,0.106868,291.621643,14.855914,1.068682,-281.208588,294.500458,0.000000
92.070007,65.503296,-281.253052,-0.000539,0.004207,0.106868,291.373199,14.843259,1.068682,-281.253052,294.500458,0.000000
92.450005,65.471649,-281.342010,-0.000530,0.004207,0.106868,291.232452,14.836088,1.068682,-281.342010,294.500458,0.000000
92.830002,65.389725,-281.297546,-0.000539,0.004207,0.106868,290.868011,14.817523,1.068682,-281.297546,294.500458,0.000000
93.210007,65.339081,-281.253052,-0.000548,0.004207,0.106868,290.642761,14.806047,1.068682,-281.253052,294.500458,0.000000
93.590004,65.282471,-281.297546,-0.000539,0.004207,0.106868,290.390930,14.793220,1.068682,-281.297546,294.500458,0.000000
93.970001,65.230347,-281.386505,-0.000522,0.004207,0.106868,290.159088,14.781407,1.068682,-281.386505,294.500458,0.000000
94.350006,65.146561,-281.386505,-0.000543,0.004207,0.106868,289.786377,14.762422,1.068682,-281.386505,294.500458,0.000000
94.730003,65.071335,-281.386505,-0.000539,0.004207,0.106868,289.451752,14.745376,1.068682,-281.386505,294.500458,0.000000
95.110008,65.640335,-281.297546,-0.000535,0.004216,0.107085,291.982788,14.874312,1.070850,-281.297546,294.500458,0.000000
95.490005,65.662674,-281.386505,-0.000530,0.004216,0.107085,292.082153,14.879375,1.070850,-281.386505,294.500458,0.000000
95.870003,65.656342,-281.430969,-0.000535,0.004216,0.107085,292.053986,14.877939,1.070850,-281.430969,294.500458,0.000000
96.250008,65.613892,-281.519928,-0.000530,0.004216,0.107085,291.865173,14.868320,1.070850,-281.519928,294.500458,0.000000
96.630005,65.582977,-281.519928,-0.000522,0.004216,0.107085,291.727661,14.861315,1.070850,-281.519928,294.500458,0.000000
97.010002,65.569580,-281.475464,-0.000530,0.004216,0.107085,291.668060,14.858279,1.070850,-281.475464,294.500458,0.000000
97.390007,65.507385,-281.475464,-0.000522,0.004216,0.107085,291.391388,14.844186,1.070850,-281.475464,294.500458,0.000000
97.770004,65.482819,-281.564423,-0.000530,0.004216,0.107085,291.282135,14.838619,1.070850,-281.564423,294.500458,0.000000
98.150002,65.388977,-281.519928,-0.000552,0.004216,0.107085,290.864685,14.817353,1.070850,-281.519928,294.500458,0.000000
98.530006,65.352112,-281.608887,-0.000530,0.004216,0.107085,290.700714,14.809001,1.070850,-281.608887,294.500458,0.000000
98.910004,65.318970,-281.519928,-0.000526,0.004216,0.107085,290.553284,14.801490,1.070850,-281.519928,294.500458,0.000000
99.290001,65.261627,-281.564423,-0.000522,0.004216,0.107085,290.298218,14.788496,1.070850,-281.564423,294.500458,0.000000
99.670006,65.222153,-281.608887,-0.000530,0.004216,0.107085,290.122620,14.779552,1.070850,-281.608887,294.500458,0.000000
100.050003,65.183792,-281.653381,-0.000543,0.004216,0.107085,289.951996,14.770859,1.070850,-281.653381,294.500458,0.000000
100.430008,65.140228,-281.697876,-0.000530,0.004216,0.107085,289.758209,14.760986,1.070850,-281.697876,294.500458,0.000000
100.810005,65.083252,-281.653381,-0.000535,0.004216,0.107085,289.504761,14.748075,1.070850,-281.653381,294.500458,0.000000
101.190002,65.048630,-281.653381,-0.000535,0.004216,0.107085,289.350769,14.740230,1.070850,-281.653381,294.500458,0.000000
101.570007,65.012512,-281.697876,-0.000526,0.004216,0.107085,289.190094,14.732045,1.070850,-281.697876,294.500458,0.000000
101.950005,64.976395,-281.697876,-0.000530,0.004220,0.107180,289.029449,14.723862,1.071804,-281.697876,294.500458,0.000000
102.330002,65.142838,-281.697876,-0.000530,0.004220,0.107180,289.769806,14.761578,1.071804,-281.697876,294.500458,0.000000
102.710007,65.143585,-281.742340,-0.000526,0.004220,0.107180,289.773132,14.761747,1.071804,-281.742340,294.500458,0.000000
103.090004,65.133530,-281.697876,-0.000517,0.004220,0.107180,289.728424,14.759469,1.071804,-281.697876,294.500458,0.000000
103.470001,65.092941,-281.831299,-0.000535,0.004220,0.107180,289.547852,14.750272,1.071804,-281.831299,294.500458,0.000000
103.850006,65.075439,-281.831299,-0.000535,0.004220,0.107180,289.470001,14.746305,1.071804,-281.831299,294.500458,0.000000
104.230003,65.046768,-281.786835,-0.000522,0.004221,0.107215,289.342468,14.739808,1.072151,-281.786835,294.500458,0.000000
104.610008,65.050858,-281.831299,-0.000526,0.004221,0.107215,289.360657,14.740735,1.072151,-281.831299,294.500458,0.000000
104.990005,65.032242,-281.786835,-0.000517,0.004221,0.107215,289.277863,14.736517,1.072151,-281.786835,294.500458,0.000000
105.370003,65.575912,-281.875793,-0.000530,0.004229,0.107415,291.696228,14.859715,1.074146,-281.875793,294.500458,0.000000
105.750008,65.611282,-281.875793,-0.000522,0.004228,0.107380,291.853546,14.867729,1.073799,-281.875793,294.500458,0.000000
106.130005,65.584839,-281.875793,-0.000535,0.004228,0.107380,291.735931,14.861737,1.073799,-281.875793,294.500458,0.000000
106.510002,65.580002,-281.831299,-0.000522,0.004228,0.107380,291.714417,14.860641,1.073799,-281.831299,294.500458,0.000000
106.890007,65.550583,-281.920258,-0.000530,0.004228,0.107380,291.583557,14.853974,1.073799,-281.920258,294.500458,0.000000
107.270004,65.536438,-281.920258,-0.000517,0.004228,0.107380,291.520630,14.850769,1.073799,-281.920258,294.500458,0.000000
107.650002,65.507019,-281.964752,-0.000526,0.004228,0.107380,291.389771,14.844102,1.073799,-281.964752,294.500458,0.000000
108.030006,65.477234,-282.009216,-0.000513,0.004228,0.107380,291.257294,14.837354,1.073799,-282.009216,294.500458,0.000000
108.410004,65.457489,-282.009216,-0.000509,0.004228,0.107380,291.169464,14.832879,1.073799,-282.009216,294.500458,0.000000
108.790009,65.403122,-282.053711,-0.000539,0.004228,0.107380,290.927612,14.820560,1.073799,-282.053711,294.500458,0.000000
109.170006,65.394562,-282.098206,-0.000535,0.004228,0.107380,290.889526,14.818619,1.073799,-282.098206,294.500458,0.000000
109.550003,65.352478,-281.964752,-0.000517,0.004228,0.107380,290.702332,14.809083,1.073799,-281.964752,294.500458,0.000000
109.930008,65.329391,-282.053711,-0.000522,0.004228,0.107380,290.599640,14.803851,1.073799,-282.053711,294.500458,0.000000
110.310005,65.310776,-282.098206,-0.000526,0.004228,0.107380,290.516846,14.799634,1.073799,-282.098206,294.500458,0.000000
110.690002,65.276154,-282.187164,-0.000513,0.004228,0.107380,290.362823,14.791788,1.073799,-282.187164,294.500458,0.000000
111.070007,65.253433,-282.187164,-0.000522,0.004228,0.107380,290.261780,14.786639,1.073799,-282.187164,294.500458,0.000000
111.450005,65.214706,-282.142670,-0.000513,0.004228,0.107380,290.089508,14.777864,1.073799,-282.142670,294.500458,0.000000
111.830002,65.204285,-282.142670,-0.000530,0.004228,0.107380,290.043152,14.775502,1.073799,-282.142670,294.500458,0.000000
112.210007,65.158112,-282.231628,-0.000517,0.004228,0.107380,289.837769,14.765039,1.073799,-282.231628,294.500458,0.000000
112.590004,65.138000,-282.276123,-0.000513,0.004228,0.107380,289.748291,14.760482,1.073799,-282.276123,294.500458,0.000000
112.970009,65.101501,-282.231628,-0.000526,0.004228,0.107380,289.585937,14.752212,1.073799,-282.231628,294.500458,0.000000
113.350006,65.071335,-282.231628,-0.000530,0.004228,0.107380,289.451752,14.745376,1.073799,-282.231628,294.500458,0.000000
113.730003,65.055328,-282.276123,-0.000513,0.004228,0.107380,289.380554,14.741748,1.073799,-282.276123,294.500458,0.000000
114.110008,65.011383,-282.276123,-0.000517,0.004228,0.107380,289.185089,14.731790,1.073799,-282.276123,294.500458,0.000000
114.490005,64.995010,-282.276123,-0.000517,0.004228,0.107380,289.112244,14.728080,1.073799,-282.276123,294.500458,0.000000
114.870003,64.968933,-282.320587,-0.000530,0.004228,0.107380,288.996246,14.722170,1.073799,-282.320587,294.500458,0.000000
115.250008,64.957031,-282.320587,-0.000530,0.004228,0.107380,288.943298,14.719474,1.073799,-282.320587,294.500458,0.000000
115.630005,64.914566,-282.320587,-0.000513,0.004228,0.107380,288.754425,14.709851,1.073799,-282.320587,294.500458,0.000000
116.010002,64.893341,-282.409546,-0.000522,0.004228,0.107380,288.660004,14.705041,1.073799,-282.409546,294.500458,0.000000
116.390007,64.857605,-282.409546,-0.000530,0.004228,0.107380,288.501038,14.696943,1.073799,-282.409546,294.500458,0.000000
116.770004,64.828934,-282.454041,-0.000517,0.004228,0.107380,288.373505,14.690447,1.073799,-282.454041,294.500458,0.000000
117.150009,64.815155,-282.365082,-0.000530,0.004228,0.107380,288.312195,14.687325,1.073799,-282.365082,294.500458,0.000000
117.530006,64.773437,-282.409546,-0.000509,0.004228,0.107380,288.126648,14.677870,1.073799,-282.409546,294.500458,0.000000
117.910004,64.760040,-282.454041,-0.000513,0.004228,0.107380,288.067047,14.674835,1.073799,-282.454041,294.500458,0.000000
118.290009,64.736954,-282.498535,-0.000513,0.004228,0.107380,287.964355,14.669603,1.073799,-282.498535,294.500458,0.000000
118.670006,64.702698,-282.498535,-0.000517,0.004228,0.107380,287.811981,14.661841,1.073799,-282.498535,294.500458,0.000000
119.050003,64.677750,-282.542999,-0.000535,0.004228,0.107380,287.700989,14.656187,1.073799,-282.542999,294.500458,0.000000
119.430008,64.648697,-282.542999,-0.000509,0.004228,0.107380,287.571777,14.649604,1.073799,-282.542999,294.500458,0.000000
119.810005,64.632309,-282.542999,-0.000517,0.004228,0.107380,287.498871,14.645890,1.073799,-282.542999,294.500458,0.000000
120.190002,64.589859,-282.498535,-0.000513,0.004228,0.107380,287.310028,14.636271,1.073799,-282.498535,294.500458,0.000000
120.570007,64.569016,-282.587494,-0.000513,0.004228,0.107380,287.217316,14.631549,1.073799,-282.587494,294.500458,0.000000
120.950005,64.536240,-282.587494,-0.000517,0.004228,0.107380,287.071533,14.624121,1.073799,-282.587494,294.500458,0.000000
121.330009,64.525818,-282.631958,-0.000500,0.004228,0.107380,287.025177,14.621759,1.073799,-282.631958,294.500458,0.000000
121.710007,64.503479,-282.676453,-0.000530,0.004228,0.107380,286.925812,14.616697,1.073799,-282.676453,294.500458,0.000000
122.090004,64.461761,-282.631958,-0.000522,0.004228,0.107380,286.740234,14.607244,1.073799,-282.631958,294.500458,0.000000
122.470009,66.948837,-282.676453,-0.000517,0.004112,0.104449,297.803314,15.170823,1.044487,-282.676453,294.500458,0.000000
122.850006,66.688187,-282.676453,-0.000509,0.004061,0.103139,296.643860,15.111759,1.031392,-282.676453,294.500458,0.000000
123.230003,66.685944,-282.676453,-0.000504,0.004061,0.103139,296.633881,15.111251,1.031392,-282.676453,294.500458,0.000000
123.610008,66.671051,-282.720917,-0.000487,0.004061,0.103139,296.567657,15.107877,1.031392,-282.720917,294.500458,0.000000
123.990005,66.654663,-282.720917,-0.000513,0.004061,0.103139,296.494751,15.104162,1.031392,-282.720917,294.500458,0.000000
124.370003,66.589508,-282.765411,-0.000500,0.004061,0.103139,296.204926,15.089398,1.031392,-282.765411,294.500458,0.000000
124.750008,66.584671,-282.809875,-0.000509,0.004061,0.103139,296.183411,15.088303,1.031392,-282.809875,294.500458,0.000000
125.130005,66.477417,-282.809875,-0.000496,0.004061,0.103139,295.706329,15.063998,1.031392,-282.809875,294.500458,0.000000
125.510010,66.486359,-282.854370,-0.000504,0.004061,0.103139,295.746094,15.066024,1.031392,-282.854370,294.500458,0.000000
125.890007,66.478165,-282.898834,-0.000500,0.004061,0.103148,295.709656,15.064168,1.031478,-282.898834,294.500458,0.000000
126.270004,66.418961,-282.854370,-0.000500,0.004061,0.103148,295.446289,15.050752,1.031478,-282.854370,294.500458,0.000000
126.650009,66.431625,-282.854370,-0.000483,0.004061,0.103156,295.502625,15.053622,1.031565,-282.854370,294.500458,0.000000
127.030006,66.412994,-282.898834,-0.000500,0.004061,0.103156,295.419739,15.049399,1.031565,-282.898834,294.500458,0.000000
127.410004,66.385071,-282.943329,-0.000496,0.004061,0.103156,295.295532,15.043072,1.031565,-282.943329,294.500458,0.000000
127.790009,66.361237,-282.898834,-0.000500,0.004061,0.103156,295.189514,15.037671,1.031565,-282.898834,294.500458,0.000000
128.170013,66.342987,-282.898834,-0.000496,0.004061,0.103156,295.108337,15.033536,1.031565,-282.898834,294.500458,0.000000
128.550003,66.305756,-282.898834,-0.000496,0.004061,0.103156,294.942719,15.025099,1.031565,-282.898834,294.500458,0.000000
128.930008,66.284164,-282.987823,-0.000479,0.004061,0.103156,294.846680,15.020206,1.031565,-282.987823,294.500458,0.000000
129.310013,66.264053,-282.987823,-0.000500,0.004061,0.103156,294.757233,15.015649,1.031565,-282.987823,294.500458,0.000000
129.690002,66.214157,-283.121246,-0.000492,0.004061,0.103156,294.535278,15.004342,1.031565,-283.121246,294.500458,0.000000
130.070007,66.206329,-282.943329,-0.000496,0.004061,0.103156,294.500458,15.002569,1.031565,-282.943329,294.500458,0.000000
130.450012,66.175049,-282.987823,-0.000517,0.004061,0.103156,294.361328,14.995481,1.031565,-282.987823,294.500458,0.000000
130.830002,66.167984,-283.032288,-0.000500,0.004061,0.103156,294.329895,14.993879,1.031565,-283.032288,294.500458,0.000000
131.210007,66.132980,-283.076782,-0.000504,0.004061,0.103156,294.174194,14.985948,1.031565,-283.076782,294.500458,0.000000
131.590012,66.117706,-283.076782,-0.000487,0.004061,0.103156,294.106232,14.982487,1.031565,-283.076782,294.500458,0.000000
131.970001,66.096115,-283.076782,-0.000496,0.004061,0.103156,294.010193,14.977594,1.031565,-283.076782,294.500458,0.000000
132.350006,66.073395,-283.076782,-0.000492,0.004061,0.103156,293.909149,14.972445,1.031565,-283.076782,294.500458,0.000000
132.730011,66.049561,-283.121246,-0.000487,0.004061,0.103156,293.803131,14.967044,1.031565,-283.121246,294.500458,0.000000
133.110001,66.021271,-283.165741,-0.000496,0.004061,0.103156,293.677277,14.960633,1.031565,-283.165741,294.500458,0.000000
133.490005,66.011581,-283.165741,-0.000487,0.004061,0.103156,293.634186,14.958439,1.031565,-283.165741,294.500458,0.000000
133.870010,65.983276,-283.165741,-0.000504,0.004061,0.103156,293.508270,14.952024,1.031565,-283.165741,294.500458,0.000000
134.250000,65.947159,-283.165741,-0.000500,0.004064,0.103217,293.347626,14.943840,1.032172,-283.165741,294.500458,0.000000
134.630005,65.941956,-283.165741,-0.000483,0.004075,0.103495,293.324463,14.942661,1.034947,-283.165741,294.500458,0.000000
135.010010,65.867477,-283.254700,-0.000492,0.004088,0.103833,292.993164,14.925783,1.038329,-283.254700,294.500458,0.000000
135.389999,65.895035,-283.254700,-0.000496,0.004089,0.103859,293.115753,14.932029,1.038589,-283.254700,294.500458,0.000000
135.770004,65.842148,-283.254700,-0.000500,0.004089,0.103868,292.880493,14.920044,1.038676,-283.254700,294.500458,0.000000
136.150009,65.867844,-283.210205,-0.000487,0.004090,0.103885,292.994812,14.925867,1.038850,-283.210205,294.500458,0.000000
136.530014,65.854813,-283.343658,-0.000479,0.004090,0.103894,292.936829,14.922914,1.038936,-283.343658,294.500458,0.000000
136.910004,65.856308,-283.343658,-0.000500,0.004090,0.103894,292.943481,14.923252,1.038936,-283.343658,294.500458,0.000000
137.290009,65.811996,-283.343658,-0.000492,0.004089,0.103868,292.746368,14.913212,1.038676,-283.343658,0.103894,0.000000
137.670013,65.784439,-283.343658,-0.000487,0.004089,0.103859,292.623810,14.906966,1.038589,-283.343658,0.103321,0.000000
138.050003,65.774384,-283.343658,-0.000496,0.004064,0.103226,292.579071,14.904688,1.032259,-283.343658,0.102688,0.000000
138.430008,65.746460,-283.343658,-0.000487,0.004051,0.102905,292.454865,14.898361,1.029050,-283.343658,0.102055,0.000000
138.810013,65.631393,-283.432617,-0.000496,0.004022,0.102159,291.943024,14.872286,1.021592,-283.432617,0.101422,0.000000
139.190002,65.314880,-283.477112,-0.000492,0.003995,0.101483,290.535095,14.800563,1.014828,-283.477112,0.100789,0.000000
139.570007,64.687805,-283.432617,-0.000500,0.003973,0.100919,287.745728,14.658465,1.009191,-283.432617,0.100156,0.000000
139.950012,63.592651,-283.521576,-0.000492,0.003945,0.100199,282.874237,14.410301,1.001992,-283.521576,0.099523,0.000000
140.330002,62.481117,-283.477112,-0.000461,0.003924,0.099670,277.929901,14.158423,0.996703,-283.477112,0.098890,0.000000
140.710007,61.431030,-283.477112,-0.000453,0.003907,0.099228,273.258881,13.920470,0.992280,-283.477112,0.098257,0.000000
141.090012,59.756470,-283.566071,-0.000448,0.003885,0.098682,265.810059,13.541010,0.986816,-283.566071,0.097615,0.000000
141.470001,57.575111,-283.566071,-0.000448,0.003856,0.097936,256.106873,13.046706,0.979358,-283.566071,0.096982,0.000000
141.850006,55.960503,-283.477112,-0.000453,0.003839,0.097520,248.924744,12.680831,0.975195,-283.477112,0.096349,0.000000
142.230011,53.061211,-283.566071,-0.000448,0.003810,0.096765,236.028046,12.023843,0.967650,-283.566071,0.095716,0.000000
142.610001,50.306404,-283.610535,-0.000453,0.003783,0.096089,223.774063,11.399593,0.960886,-283.610535,0.095083,0.000000
142.990005,47.488663,-283.655029,-0.000448,0.003756,0.095403,211.240128,10.761085,0.954035,-283.655029,0.094450,0.000000
143.370010,44.902534,-283.610535,-0.000457,0.003734,0.094840,199.736450,10.175060,0.948398,-283.610535,0.093816,0.000000
143.750000,42.848900,-283.655029,-0.000461,0.003714,0.094345,190.601425,9.709700,0.943455,-283.655029,0.093183,0.000000
144.130005,38.884995,-283.610535,-0.000461,0.003676,0.093366,172.969101,8.811465,0.933655,-283.610535,0.092550,0.000000
144.510010,37.186974,-283.610535,-0.000435,0.003661,0.093001,165.415924,8.426689,0.930013,-283.610535,0.091917,0.000000
144.889999,34.469398,-283.743988,-0.000457,0.003634,0.092316,153.327545,7.810877,0.923162,-283.743988,0.091284,0.000000
145.270004,31.887001,-283.788483,-0.000448,0.003605,0.091579,141.840469,7.225698,0.915790,-283.788483,0.090651,0.000000
145.650009,29.151924,-283.699493,-0.000453,0.003583,0.090998,129.674240,6.605920,0.909980,-283.699493,0.090018,0.000000
146.030014,26.104424,-283.743988,-0.000431,0.003557,0.090348,116.118279,5.915347,0.903476,-283.743988,0.089385,0.000000
146.410004,24.072762,-283.788483,-0.000444,0.003537,0.089845,107.080994,5.454966,0.898446,-283.788483,0.088752,0.000000
146.790009,20.980583,-283.832947,-0.000448,0.003508,0.089099,93.326294,4.754268,0.890988,-283.832947,0.088119,0.000000
147.170013,18.471535,-283.788483,-0.000457,0.003483,0.088457,82.165489,4.185709,0.884570,-283.788483,0.087486,0.000000
147.550003,15.745399,-283.832947,-0.000435,0.003461,0.087911,70.039032,3.567959,0.879107,-283.832947,0.086853,0.000000
147.930008,12.172485,-283.832947,-0.000448,0.003430,0.087130,54.145920,2.758325,0.871302,-283.832947,0.086220,0.000000
148.310013,10.346367,-283.832947,-0.000453,0.003414,0.086723,46.022938,2.344520,0.867226,-283.832947,0.085587,0.000000
148.690002,6.335915,-283.832947,-0.000435,0.003375,0.085734,28.183556,1.435739,0.857339,-283.832947,0.084953,0.000000
149.070007,4.046944,-283.877441,-0.000453,0.003351,0.085118,18.001705,0.917051,0.851182,-283.877441,0.084320,0.000000
149.450012,2.145981,-283.877441,-0.000457,0.003334,0.084676,9.545799,0.486286,0.846759,-283.877441,0.083687,0.000000
149.830002,-0.634148,-283.966400,-0.000444,0.003305,0.083939,-2.820830,-0.143700,0.839388,-283.966400,0.083054,0.000000
150.210007,-1.863354,-283.966400,-0.000440,0.003289,0.083549,-8.288611,-0.422242,0.835485,-283.966400,0.082421,0.000000
150.590012,-0.355988,-283.966400,-0.000448,0.003265,0.082924,-1.583512,-0.080668,0.829241,-283.966400,0.081788,0.000000
150.970001,-0.090485,-284.010864,-0.000457,0.003227,0.081970,-0.402496,-0.020504,0.819702,-284.010864,0.081155,0.000000
151.350006,-0.053993,-283.966400,-0.000457,0.003206,0.081441,-0.240174,-0.012235,0.814412,-283.966400,0.080522,0.000000
151.730011,-0.004471,-284.010864,-0.000461,0.003177,0.080704,-0.019887,-0.001013,0.807040,-284.010864,0.079889,0.000000
152.110001,-0.016014,-284.010864,-0.000461,0.003160,0.080262,-0.071234,-0.003629,0.802617,-284.010864,0.079247,0.000000
152.490005,-0.027557,-284.010864,-0.000470,0.003126,0.079403,-0.122581,-0.006245,0.794032,-284.010864,0.078614,0.000000
152.870010,0.028671,-284.099823,-0.000517,0.003116,0.079143,0.127536,0.006497,0.791430,-284.099823,0.077981,0.000000
153.250000,-0.024574,-284.055359,-0.000591,0.003085,0.078354,-0.109312,-0.005569,0.783538,-284.055359,0.077348,0.000000
153.630005,0.022713,-284.099823,-0.000647,0.003054,0.077573,0.101031,0.005147,0.775733,-284.099823,0.076715,0.000000
154.010010,0.045425,-284.099823,-0.000673,0.003032,0.077010,0.202062,0.010294,0.770096,-284.099823,0.076082,0.000000
154.390015,0.016014,-284.144318,-0.000711,0.003009,0.076420,0.071234,0.003629,0.764199,-284.144318,0.075449,0.000000
154.770004,0.009308,-284.188782,-0.000785,0.002983,0.075770,0.041403,0.002109,0.757695,-284.188782,0.074816,0.000000
154.900009,0.026062,-284.188782,-0.000802,0.002981,0.075726,0.115930,0.005906,0.757262,-284.188782,0.075579,0.000000