File: Data/compression 32/AutoNoHeating-12-32-reverse-1-1_11142024_180359.csv
Time (sec),S:Load (lbs),S:HL1 (DIM),S:LVDT (in),S:Position (in),Ch:Position (mm),Ch:Load (N),Ch:Stress (MPa),Ch:Strain (mm/mm),Ch:HL1 (DIM),Set Point (),Cycles ()
0.110000,-0.099800,-68.411705,-0.009127,-0.009057,-0.230049,-0.443933,-0.022615,-2.300490,-68.411705,-0.229754,0.000000
0.480000,0.003349,-68.411705,-0.009136,-0.009008,-0.228791,0.014898,0.000759,-2.287915,-68.411705,-0.228106,0.000000
0.850000,-0.080063,-68.322739,-0.009007,-0.008794,-0.223363,-0.356137,-0.018143,-2.233626,-68.322739,-0.221949,0.000000
1.220000,-0.003357,-68.500664,-0.008783,-0.008545,-0.217032,-0.014932,-0.000761,-2.170319,-68.500664,-0.215774,0.000000
1.590000,0.002228,-68.456184,-0.008532,-0.008300,-0.210823,0.009910,0.000505,-2.108226,-68.456184,-0.209617,0.000000
1.960000,0.008560,-68.500664,-0.008274,-0.008058,-0.204683,0.038078,0.001940,-2.046826,-68.500664,-0.203442,0.000000
2.330000,0.007812,-68.545143,-0.008032,-0.007817,-0.198543,0.034752,0.001770,-1.985427,-68.545143,-0.197285,0.000000
2.700000,-0.013412,-68.500664,-0.007769,-0.007577,-0.192455,-0.059662,-0.003039,-1.924547,-68.500664,-0.191128,0.000000
3.070000,-0.009682,-68.589630,-0.007528,-0.007332,-0.186245,-0.043066,-0.002194,-1.862454,-68.589630,-0.184953,0.000000
3.440000,0.030159,-68.678589,-0.007269,-0.007087,-0.180019,0.134154,0.006834,-1.800187,-68.678589,-0.178796,0.000000
3.810000,0.056221,-68.678589,-0.007015,-0.006846,-0.173896,0.250084,0.012740,-1.738961,-68.678589,-0.172639,0.000000
4.180000,0.027550,-68.678589,-0.006756,-0.006604,-0.167730,0.122547,0.006243,-1.677301,-68.678589,-0.166464,0.000000
4.550000,0.005585,-68.678589,-0.006532,-0.006367,-0.161729,0.024842,0.001266,-1.617289,-68.678589,-0.160307,0.000000
4.920000,-0.030167,-68.767548,-0.006278,-0.006124,-0.155537,-0.134188,-0.006836,-1.555369,-68.767548,-0.154132,0.000000
5.290000,-0.045433,-68.856514,-0.006015,-0.005880,-0.149345,-0.202096,-0.010295,-1.493449,-68.856514,-0.147975,0.000000
5.660000,0.007812,-68.767548,-0.005769,-0.005633,-0.143084,0.034752,0.001770,-1.430836,-68.767548,-0.141817,0.000000
6.030000,0.029045,-68.767548,-0.005493,-0.005385,-0.136788,0.129199,0.006582,-1.367875,-68.767548,-0.135643,0.000000
6.400000,0.029045,-68.812035,-0.005273,-0.005148,-0.130760,0.129199,0.006582,-1.307603,-68.812035,-0.129485,0.000000
6.770000,0.020103,-68.900993,-0.005010,-0.004906,-0.124620,0.089425,0.004556,-1.246203,-68.900993,-0.123311,0.000000
7.140000,0.156769,-68.945473,-0.004885,-0.000000,-0.000000,0.697342,0.035524,-0.000000,-68.945473,0.000173,0.000000
7.510000,0.097183,-69.034439,-0.004876,-0.000000,-0.000009,0.432293,0.022022,-0.000087,-69.034439,0.000243,0.000000
7.880001,0.133675,-68.945473,-0.004881,-0.000000,-0.000009,0.594614,0.030291,-0.000087,-68.945473,0.000859,0.000000
8.250000,0.150063,-68.900993,-0.004876,-0.000000,-0.000000,0.667512,0.034005,-0.000000,-68.900993,0.001474,0.000000
8.620001,0.202568,-69.034439,-0.004859,0.000038,0.000971,0.901068,0.045903,0.009713,-69.034439,0.002090,0.000000
8.990001,0.326942,-69.078918,-0.004838,0.000064,0.001622,1.454313,0.074086,0.016217,-69.078918,0.002706,0.000000
9.360001,0.571213,-69.078918,-0.004799,0.000095,0.002402,2.540881,0.129439,0.024022,-69.078918,0.003321,0.000000
9.730000,0.653885,-69.167877,-0.004781,0.000113,0.002862,2.908625,0.148172,0.028618,-69.167877,0.003937,0.000000
10.100000,0.891457,-69.123398,-0.004756,0.000140,0.003564,3.965397,0.202007,0.035643,-69.123398,0.004562,0.000000
10.470000,0.970772,-69.212357,-0.004743,0.000162,0.004119,4.318209,0.219980,0.041193,-69.212357,0.005177,0.000000
10.840000,1.241486,-69.123398,-0.004700,0.000181,0.004588,5.522404,0.281325,0.045876,-69.123398,0.005793,0.000000
11.210001,1.551300,-69.212357,-0.004682,0.000205,0.005212,6.900527,0.351530,0.052120,-69.212357,0.006409,0.000000
11.580001,1.835793,-69.212357,-0.004656,0.000231,0.005880,8.166013,0.415997,0.058798,-69.212357,0.007025,0.000000
11.950001,2.148216,-69.345802,-0.004639,0.000264,0.006695,9.555743,0.486793,0.066950,-69.345802,0.007640,0.000000
12.320001,2.452072,-69.345802,-0.004605,0.000287,0.007285,10.907362,0.555647,0.072847,-69.345802,0.008256,0.000000
12.690001,2.675491,-69.345802,-0.004592,0.000305,0.007753,11.901180,0.606275,0.077530,-69.345802,0.008872,0.000000
13.060000,3.036697,-69.301323,-0.004566,0.000327,0.008308,13.507905,0.688125,0.083080,-69.301323,0.009487,0.000000
13.430000,3.523758,-69.390282,-0.004557,0.000360,0.009149,15.674459,0.798495,0.091492,-69.390282,0.010112,0.000000
13.800000,3.632118,-69.434761,-0.004540,0.000375,0.009531,16.156469,0.823050,0.095308,-69.434761,0.010728,0.000000
14.170001,4.136307,-69.479248,-0.004497,0.000406,0.010303,18.399212,0.937301,0.103026,-69.479248,0.011343,0.000000
14.540001,4.240944,-69.479248,-0.004475,0.000422,0.010728,18.864660,0.961012,0.107276,-69.479248,0.011959,0.000000
14.910001,4.592468,-69.523727,-0.004467,0.000451,0.011447,20.428320,1.040668,0.114474,-69.523727,0.012575,0.000000
15.280001,5.124588,-69.612686,-0.004432,0.000478,0.012150,22.795305,1.161248,0.121498,-69.612686,0.013191,0.000000
15.650001,5.327904,-69.612686,-0.004419,0.000504,0.012800,23.699699,1.207320,0.128003,-69.612686,0.013806,0.000000
16.020000,5.665268,-69.612686,-0.004402,0.000526,0.013355,25.200371,1.283768,0.133553,-69.612686,0.014422,0.000000
16.390001,5.980667,-69.612686,-0.004359,0.000551,0.013988,26.603336,1.355239,0.139884,-69.612686,0.015038,0.000000
16.760000,6.355652,-69.657173,-0.004333,0.000574,0.014587,28.271351,1.440211,0.145867,-69.657173,0.015662,0.000000
17.130001,5.935242,-69.701653,-0.004333,0.000574,0.014587,26.401274,1.344945,0.145867,-69.701653,0.016278,0.000000
17.500000,7.184547,-69.746132,-0.004290,0.000631,0.016026,31.958464,1.628042,0.160263,-69.746132,0.016894,0.000000
17.870001,7.242638,-69.746132,-0.004255,0.000651,0.016529,32.216862,1.641205,0.165293,-69.746132,0.017509,0.000000
18.240002,7.516708,-69.790611,-0.004230,0.000677,0.017206,33.435989,1.703310,0.172058,-69.790611,0.018125,0.000000
18.610001,7.802315,-69.790611,-0.004208,0.000702,0.017821,34.706429,1.768030,0.178215,-69.790611,0.018741,0.000000
18.980001,7.996696,-69.835091,-0.004195,0.000722,0.018342,35.571083,1.812077,0.183418,-69.835091,0.019356,0.000000
19.350000,8.222351,-69.924057,-0.004165,0.000742,0.018836,36.574844,1.863211,0.188361,-69.924057,0.019972,0.000000
19.720001,8.516525,-69.879578,-0.004130,0.000765,0.019435,37.883396,1.929872,0.194345,-69.879578,0.020588,0.000000
20.090000,8.860229,-69.924057,-0.004109,0.000797,0.020250,39.412270,2.007757,0.202497,-69.924057,0.021212,0.000000
20.460001,9.002098,-69.968536,-0.004087,0.000819,0.020805,40.043331,2.039905,0.208047,-69.968536,0.021828,0.000000
20.830002,9.157379,-70.013016,-0.004066,0.000838,0.021273,40.734058,2.075092,0.212730,-70.013016,0.022444,0.000000
21.200001,9.596779,-70.013016,-0.004027,0.000866,0.021984,42.688606,2.174661,0.219842,-70.013016,0.023060,0.000000
21.570002,9.878662,-70.057495,-0.003992,0.000891,0.022635,43.942482,2.238537,0.226346,-70.057495,0.023675,0.000000
21.940001,10.140442,-70.146461,-0.003980,0.000917,0.023302,45.106937,2.297857,0.233024,-70.146461,0.024291,0.000000
22.310001,10.143791,-70.146461,-0.003958,0.000937,0.023788,45.121838,2.298616,0.237880,-70.146461,0.024907,0.000000
22.680000,10.477440,-70.146461,-0.003898,0.000963,0.024456,46.605980,2.374222,0.244558,-70.146461,0.025522,0.000000
23.050001,10.840134,-70.146461,-0.003876,0.000990,0.025150,48.219322,2.456409,0.251495,-70.146461,0.026147,0.000000
23.420002,10.648735,-70.235420,-0.003863,0.001006,0.025548,47.367939,2.413038,0.255485,-70.235420,0.026763,0.000000
23.790001,11.226654,-70.190941,-0.003816,0.001040,0.026407,49.938652,2.543996,0.264070,-70.190941,0.027378,0.000000
24.160002,11.062813,-70.279900,-0.003790,0.001063,0.026997,49.209850,2.506869,0.269967,-70.279900,0.027994,0.000000
24.530001,11.076584,-70.279900,-0.003777,0.001081,0.027465,49.271107,2.509990,0.274650,-70.279900,0.028610,0.000000
24.900002,11.630676,-70.368866,-0.003738,0.001111,0.028211,51.735832,2.635549,0.282109,-70.368866,0.029226,0.000000
25.270000,11.616898,-70.279900,-0.003708,0.001132,0.028757,51.674541,2.632427,0.287572,-70.279900,0.029841,0.000000
25.640001,11.929695,-70.324387,-0.003682,0.001160,0.029460,53.065933,2.703307,0.294597,-70.324387,0.030457,0.000000
26.010002,11.864159,-70.324387,-0.003635,0.001182,0.030015,52.774414,2.688457,0.300147,-70.324387,0.031073,0.000000
26.380001,11.595299,-70.457825,-0.003622,0.001194,0.030336,51.578465,2.627532,0.303356,-70.457825,0.031697,0.000000
26.750002,11.924110,-70.457825,-0.003574,0.001226,0.031133,53.041092,2.702042,0.311334,-70.457825,0.032313,0.000000
27.120001,12.413780,-70.457825,-0.003531,0.001257,0.031940,55.219254,2.813003,0.319399,-70.457825,0.032929,0.000000
27.490002,12.363136,-70.457825,-0.003501,0.001276,0.032408,54.993977,2.801527,0.324082,-70.457825,0.033544,0.000000
27.860001,12.530701,-70.502304,-0.003479,0.001304,0.033128,55.739342,2.839497,0.331280,-70.502304,0.034160,0.000000
28.230001,12.283073,-70.591270,-0.003449,0.001316,0.033414,54.637840,2.783384,0.334142,-70.591270,0.034776,0.000000
28.600002,13.090378,-70.546791,-0.003402,0.001353,0.034359,58.228909,2.966322,0.343595,-70.546791,0.035391,0.000000
28.970001,12.979042,-70.502304,-0.003380,0.001375,0.034932,57.733662,2.941093,0.349319,-70.502304,0.036007,0.000000
29.340002,12.970848,-70.591270,-0.003363,0.001396,0.035452,57.697212,2.939236,0.354522,-70.591270,0.036623,0.000000
29.710001,13.114578,-70.724709,-0.003307,0.001422,0.036111,58.336559,2.971806,0.361113,-70.724709,0.037247,0.000000
30.080002,13.187943,-70.724709,-0.003281,0.001446,0.036736,58.662899,2.988431,0.367357,-70.724709,0.037863,0.000000
30.450001,13.530525,-70.724709,-0.003260,0.001473,0.037412,60.186783,3.066061,0.374121,-70.724709,0.038479,0.000000
30.820002,13.692505,-70.769196,-0.003212,0.001501,0.038115,60.907303,3.102766,0.381146,-70.769196,0.039095,0.000000
31.190001,13.539085,-70.769196,-0.003195,0.001521,0.038626,60.224861,3.068001,0.386262,-70.769196,0.039710,0.000000
31.560001,14.057426,-70.813675,-0.003152,0.001550,0.039381,62.530556,3.185458,0.393807,-70.813675,0.040326,0.000000
31.930002,13.687294,-70.858154,-0.003130,0.001566,0.039771,60.884125,3.101585,0.397710,-70.858154,0.040942,0.000000
32.300003,13.419182,-70.769196,-0.003096,0.001579,0.040109,59.691502,3.040830,0.401092,-70.769196,0.041557,0.000000
32.670002,14.385864,-70.902634,-0.003057,0.001617,0.041080,63.991520,3.259883,0.410805,-70.902634,0.042173,0.000000
33.040001,14.323677,-70.902634,-0.003031,0.001641,0.041679,63.714897,3.245792,0.416789,-70.902634,0.042798,0.000000
33.410000,14.733284,-70.991600,-0.002992,0.001673,0.042503,65.536919,3.338610,0.425027,-70.991600,0.043413,0.000000
33.780003,14.183662,-71.036079,-0.002953,0.001691,0.042962,63.092083,3.214064,0.429624,-71.036079,0.044029,0.000000
34.150002,14.445068,-71.036079,-0.002932,0.001714,0.043543,64.254875,3.273299,0.435434,-71.036079,0.044645,0.000000
34.520000,14.861008,-70.991600,-0.002915,0.001739,0.044159,66.105064,3.367553,0.441591,-70.991600,0.045261,0.000000
34.890003,15.270988,-71.036079,-0.002863,0.001768,0.044914,67.928749,3.460455,0.449136,-71.036079,0.045876,0.000000
35.260002,14.887077,-71.125038,-0.002841,0.001784,0.045313,66.221024,3.373460,0.453125,-71.125038,0.046492,0.000000
35.630001,15.371902,-71.125038,-0.002785,0.001813,0.046058,68.377640,3.483323,0.460584,-71.125038,0.047108,0.000000
36.000000,15.523460,-71.125038,-0.002768,0.001840,0.046743,69.051804,3.517666,0.467435,-71.125038,0.047723,0.000000
36.370003,15.022247,-71.214005,-0.002755,0.001851,0.047012,66.822296,3.404090,0.470123,-71.214005,0.048348,0.000000
36.740002,15.763641,-71.214005,-0.002725,0.001887,0.047940,70.120178,3.572092,0.479402,-71.214005,0.048964,0.000000
37.110001,15.834015,-71.302963,-0.002682,0.001912,0.048556,70.433212,3.588039,0.485560,-71.302963,0.049579,0.000000
37.480003,15.869766,-71.302963,-0.002639,0.001935,0.049137,70.592247,3.596140,0.491370,-71.302963,0.050195,0.000000
37.850002,15.577080,-71.214005,-0.002617,0.001951,0.049545,69.290314,3.529817,0.495446,-71.214005,0.050811,0.000000
38.220001,15.689911,-71.258484,-0.002591,0.001972,0.050091,69.792206,3.555385,0.500910,-71.258484,0.051426,0.000000
38.590000,16.749680,-71.391930,-0.002544,0.002008,0.051002,74.506294,3.795532,0.510015,-71.391930,0.052042,0.000000
38.960003,16.590309,-71.436409,-0.002514,0.002036,0.051713,73.797379,3.759418,0.517127,-71.436409,0.052658,0.000000
39.330002,16.261871,-71.347443,-0.002492,0.002057,0.052250,72.336418,3.684993,0.522503,-71.347443,0.053274,0.000000
39.700001,16.284958,-71.391930,-0.002458,0.002082,0.052892,72.439110,3.690224,0.528921,-71.391930,0.053898,0.000000
40.070004,16.496841,-71.480888,-0.002427,0.002106,0.053482,73.381615,3.738238,0.534818,-71.480888,0.054514,0.000000
40.440002,16.537430,-71.569847,-0.002397,0.002130,0.054098,73.562164,3.747435,0.540975,-71.569847,0.055130,0.000000
40.810001,16.569824,-71.480888,-0.002350,0.002148,0.054557,73.706261,3.754776,0.545572,-71.480888,0.055745,0.000000
41.180000,17.383461,-71.569847,-0.002328,0.002185,0.055511,77.325493,3.939149,0.555111,-71.569847,0.056361,0.000000
41.550003,16.790268,-71.569847,-0.002289,0.002203,0.055962,74.686844,3.804729,0.559621,-71.569847,0.056977,0.000000
41.920002,17.029709,-71.614334,-0.002264,0.002227,0.056578,75.751930,3.858987,0.565778,-71.614334,0.057592,0.000000
42.290001,16.935867,-71.703293,-0.002229,0.002247,0.057081,75.334503,3.837722,0.570808,-71.703293,0.058208,0.000000
42.660004,16.947037,-71.747772,-0.002190,0.002272,0.057697,75.384186,3.840253,0.576965,-71.747772,0.058824,0.000000
43.030003,17.332817,-71.703293,-0.002169,0.002297,0.058338,77.100220,3.927672,0.583383,-71.703293,0.059448,0.000000
43.400002,17.383461,-71.747772,-0.002139,0.002322,0.058980,77.325493,3.939149,0.589800,-71.747772,0.060064,0.000000
43.770000,17.169716,-71.792252,-0.002108,0.002343,0.059518,76.374710,3.890713,0.595177,-71.792252,0.060680,0.000000
44.140003,17.011086,-71.792252,-0.002078,0.002362,0.059986,75.669090,3.854767,0.599860,-71.792252,0.061296,0.000000
44.510002,17.559219,-71.792252,-0.002026,0.002394,0.060801,78.107307,3.978976,0.608012,-71.792252,0.061911,0.000000
44.880001,17.620285,-71.836739,-0.002001,0.002418,0.061426,78.378944,3.992814,0.614256,-71.836739,0.062527,0.000000
45.250004,17.998245,-71.881218,-0.001962,0.002448,0.062171,80.060196,4.078461,0.621714,-71.881218,0.063143,0.000000
45.620003,17.439316,-71.881218,-0.001923,0.002467,0.062666,77.573952,3.951806,0.626657,-71.881218,0.063758,0.000000
45.990002,17.338776,-71.970177,-0.001893,0.002484,0.063091,77.126724,3.929023,0.630907,-71.970177,0.064383,0.000000
46.360001,18.287582,-71.970177,-0.001876,0.002518,0.063949,81.347229,4.144025,0.639492,-71.970177,0.064999,0.000000
46.730003,17.998619,-71.970177,-0.001828,0.002542,0.064556,80.061859,4.078545,0.645563,-71.970177,0.065614,0.000000
47.100002,18.056335,-71.970177,-0.001807,0.002568,0.065233,80.318588,4.091624,0.652327,-71.970177,0.066230,0.000000
47.470001,17.727531,-72.103622,-0.001763,0.002588,0.065744,78.855995,4.017116,0.657444,-72.103622,0.066846,0.000000
47.840004,17.655663,-72.059143,-0.001733,0.002610,0.066282,78.536308,4.000830,0.662821,-72.059143,0.067461,0.000000
48.210003,18.834595,-72.059143,-0.001703,0.002643,0.067141,83.780464,4.267980,0.671406,-72.059143,0.068077,0.000000
48.580002,17.907387,-72.103622,-0.001651,0.002662,0.067618,79.656036,4.057872,0.676176,-72.103622,0.068693,0.000000
48.950001,18.455147,-72.192581,-0.001630,0.002692,0.068372,82.092590,4.181996,0.683721,-72.192581,0.069309,0.000000
49.320004,17.666832,-72.281548,-0.001595,0.002705,0.068702,78.585991,4.003361,0.687016,-72.281548,0.069933,0.000000
49.690002,17.606514,-72.281548,-0.001552,0.002725,0.069205,78.317688,3.989693,0.692046,-72.281548,0.070549,0.000000
50.060001,18.561646,-72.281548,-0.001535,0.002759,0.070081,82.566322,4.206129,0.700805,-72.281548,0.071165,0.000000
50.430004,18.373596,-72.281548,-0.001513,0.002782,0.070653,81.729836,4.163516,0.706529,-72.281548,0.071780,0.000000
50.800003,18.710968,-72.281548,-0.001462,0.002807,0.071286,83.230545,4.239966,0.712860,-72.281548,0.072396,0.000000
51.170002,18.190392,-72.370506,-0.001423,0.002828,0.071841,80.914902,4.122002,0.718410,-72.370506,0.073012,0.000000
51.540001,18.147568,-72.326027,-0.001401,0.002850,0.072379,80.724411,4.112298,0.723787,-72.326027,0.073627,0.000000
51.910004,18.779114,-72.370506,-0.001375,0.002882,0.073194,83.533669,4.255408,0.731938,-72.370506,0.074243,0.000000
52.280003,18.507652,-72.459473,-0.001328,0.002905,0.073784,82.326149,4.193894,0.737836,-72.459473,0.074859,0.000000
52.650002,17.969948,-72.459473,-0.001302,0.002921,0.074182,79.934319,4.072048,0.741825,-72.459473,0.075483,0.000000
53.020004,18.614151,-72.503952,-0.001255,0.002953,0.075006,82.799881,4.218027,0.750064,-72.503952,0.076099,0.000000
53.390003,18.063416,-72.459473,-0.001233,0.002969,0.075405,80.350082,4.093228,0.754053,-72.459473,0.076715,0.000000
53.760002,18.716179,-72.548431,-0.001216,0.002996,0.076108,83.253723,4.241147,0.761077,-72.548431,0.077331,0.000000
54.130001,18.419029,-72.592911,-0.001164,0.003015,0.076585,81.931931,4.173811,0.765847,-72.592911,0.077946,0.000000
54.500004,19.052437,-72.637390,-0.001130,0.003051,0.077504,84.749474,4.317344,0.775040,-72.637390,0.078562,0.000000
54.870003,19.100471,-72.637390,-0.001078,0.003082,0.078276,84.963142,4.328228,0.782758,-72.637390,0.079178,0.000000
55.240002,18.335617,-72.637390,-0.001056,0.003097,0.078675,81.560898,4.154910,0.786747,-72.637390,0.079793,0.000000
55.610004,18.129318,-72.726357,-0.001035,0.003113,0.079082,80.643234,4.108162,0.790823,-72.726357,0.080409,0.000000
55.980003,19.270645,-72.726357,-0.000992,0.003151,0.080028,85.720108,4.366790,0.800276,-72.726357,0.081034,0.000000
56.350002,19.050201,-72.815315,-0.000970,0.003172,0.080574,84.739525,4.316837,0.805739,-72.815315,0.081649,0.000000
56.720001,19.088181,-72.815315,-0.000931,0.003197,0.081207,84.908470,4.325444,0.812070,-72.815315,0.082265,0.000000
57.090004,19.298203,-72.770836,-0.000884,0.003219,0.081771,85.842690,4.373035,0.817707,-72.770836,0.082881,0.000000
57.460003,19.382355,-72.859795,-0.000880,0.003243,0.082378,86.217018,4.392104,0.823778,-72.859795,0.083496,0.000000
57.830002,20.085770,-72.904282,-0.000858,0.003272,0.083106,89.345963,4.551500,0.831062,-72.904282,0.084112,0.000000
58.200005,20.066406,-72.904282,-0.000815,0.003296,0.083722,89.259834,4.547112,0.837220,-72.904282,0.084728,0.000000
58.570004,20.168808,-72.904282,-0.000780,0.003318,0.084286,89.715340,4.570317,0.842857,-72.904282,0.085344,0.000000
58.940002,20.525169,-72.948761,-0.000750,0.003340,0.084841,91.300514,4.651070,0.848407,-72.948761,0.085959,0.000000
59.310001,20.521812,-72.993240,-0.000720,0.003367,0.085526,91.285583,4.650310,0.855258,-72.993240,0.086584,0.000000
59.680004,20.531494,-72.993240,-0.000694,0.003375,0.085725,91.328644,4.652503,0.857253,-72.993240,0.087200,0.000000
60.050003,20.148697,-72.948761,-0.000698,0.003403,0.086445,89.625877,4.565760,0.864451,-72.948761,0.087815,0.000000
60.420002,23.073685,-72.948761,-0.000651,0.003445,0.087494,102.636879,5.228572,0.874944,-72.948761,0.088431,0.000000
60.790005,23.221146,-73.082199,-0.000617,0.003469,0.088101,103.292816,5.261987,0.881015,-73.082199,0.089047,0.000000
61.160004,23.713051,-73.126686,-0.000612,0.003492,0.088700,105.480919,5.373454,0.886998,-73.126686,0.089662,0.000000
61.530003,23.834068,-73.126686,-0.000569,0.003515,0.089272,106.019234,5.400877,0.892722,-73.126686,0.090278,0.000000
61.900002,24.432472,-73.126686,-0.000548,0.003535,0.089793,108.681061,5.536477,0.897925,-73.126686,0.090894,0.000000
62.270004,25.344780,-73.171165,-0.000522,0.003562,0.090469,112.739212,5.743209,0.904690,-73.171165,0.091510,0.000000
62.640003,26.533020,-73.215645,-0.000509,0.003592,0.091241,118.024765,6.012468,0.912408,-73.215645,0.092134,0.000000
63.010002,26.665215,-73.304604,-0.000483,0.003612,0.091744,118.612801,6.042424,0.917438,-73.304604,0.092750,0.000000
63.380005,27.094933,-73.304604,-0.000461,0.003634,0.092299,120.524277,6.139800,0.922988,-73.304604,0.093366,0.000000
63.750004,28.182259,-73.304604,-0.000427,0.003658,0.092915,125.360947,6.386191,0.929146,-73.304604,0.093981,0.000000
64.120003,29.131439,-73.349091,-0.000423,0.003687,0.093643,129.583115,6.601278,0.936430,-73.349091,0.094597,0.000000
64.490005,29.383904,-73.393570,-0.000414,0.003702,0.094025,130.706131,6.658488,0.940246,-73.393570,0.095213,0.000000
64.860001,30.452248,-73.393570,-0.000405,0.003729,0.094727,135.458359,6.900578,0.947271,-73.393570,0.095828,0.000000
65.230003,31.412590,-73.393570,-0.000362,0.003756,0.095395,139.730179,7.118195,0.953948,-73.393570,0.096444,0.000000
65.600006,32.561737,-73.438049,-0.000349,0.003783,0.096097,144.841843,7.378595,0.960973,-73.438049,0.097060,0.000000
65.970001,33.178383,-73.393570,-0.000332,0.003803,0.096592,147.584824,7.518329,0.965916,-73.393570,0.097684,0.000000
66.340004,33.437180,-73.571495,-0.000302,0.003819,0.096991,148.736008,7.576973,0.969905,-73.571495,0.098300,0.000000
66.710007,35.244675,-73.571495,-0.000267,0.003855,0.097910,156.776138,7.986557,0.979098,-73.571495,0.098916,0.000000
67.080002,35.577576,-73.571495,-0.000280,0.003873,0.098369,158.256958,8.061994,0.983694,-73.571495,0.099532,0.000000
67.450005,34.999283,-73.571495,-0.000267,0.003875,0.098430,155.684586,7.930951,0.984301,-73.571495,0.100147,0.000000
67.820000,38.078056,-73.660454,-0.000246,0.003921,0.099592,169.379654,8.628611,0.995922,-73.660454,0.100763,0.000000
68.190002,39.200760,-73.704933,-0.000211,0.003944,0.100173,174.373688,8.883018,1.001732,-73.704933,0.101379,0.000000
68.560005,40.612427,-73.749420,-0.000207,0.003974,0.100936,180.653091,9.202908,1.009364,-73.749420,0.101994,0.000000
68.930000,40.902130,-73.704933,-0.000181,0.003988,0.101283,181.941757,9.268556,1.012833,-73.704933,0.102619,0.000000
69.300003,42.763252,-73.749420,-0.000172,0.004020,0.102098,190.220444,9.690291,1.020985,-73.749420,0.103235,0.000000
69.670006,44.560692,-73.793900,-0.000155,0.004049,0.102853,198.215851,10.097597,1.028530,-73.793900,0.103850,0.000000
70.040001,44.923386,-73.838379,-0.000134,0.004069,0.103347,199.829193,10.179785,1.033473,-73.838379,0.104466,0.000000
70.410004,46.530540,-73.882858,-0.000108,0.004090,0.103894,206.978180,10.543972,1.038936,-73.882858,0.105082,0.000000
70.780006,47.101013,-73.793900,-0.000108,0.004107,0.104319,209.515778,10.673242,1.043186,-73.793900,0.105697,0.000000
71.150002,48.817284,-73.838379,-0.000095,0.004136,0.105047,217.150116,11.062155,1.050470,-73.838379,0.106313,0.000000
71.520004,50.908524,-73.927338,-0.000091,0.004166,0.105819,226.452423,11.536036,1.058189,-73.927338,0.106929,0.000000
71.890007,51.840942,-73.927338,-0.000060,0.004185,0.106305,230.600021,11.747325,1.063045,-73.927338,0.107545,0.000000
72.260002,53.665947,-73.927338,-0.000056,0.004217,0.107120,238.718048,12.160877,1.071197,-73.927338,0.108169,0.000000
72.630005,54.858650,-73.927338,-0.000043,0.004235,0.107562,244.023468,12.431148,1.075620,-73.927338,0.108785,0.000000
73.000000,56.430809,-74.016304,-0.000026,0.004260,0.108195,251.016769,12.787404,1.081951,-74.016304,0.109401,0.000000
73.370003,58.796120,-74.105263,-0.000034,0.004292,0.109019,261.538208,13.323391,1.090189,-74.105263,0.110016,0.000000
73.740005,59.779556,-74.105263,-0.000004,0.004309,0.109453,265.912750,13.546241,1.094526,-74.105263,0.110632,0.000000
74.110001,61.525612,-74.105263,0.000004,0.004335,0.110112,273.679596,13.941903,1.101117,-74.105263,0.111248,0.000000
74.480003,62.661720,-74.105263,0.000013,0.004354,0.110580,278.733246,14.199348,1.105800,-74.105263,0.111863,0.000000
74.850006,64.113968,-74.149742,0.000030,0.004376,0.111152,285.193176,14.528432,1.111523,-74.149742,0.112479,0.000000
75.220001,65.494354,-74.194229,0.000030,0.004395,0.111638,291.333435,14.841232,1.116380,-74.194229,0.113095,0.000000
75.590004,66.099457,-74.238708,0.000047,0.004401,0.111794,294.025055,14.978352,1.117941,-74.238708,0.019625,0.000000
75.960007,65.330887,-74.194229,0.000043,0.004400,0.111768,290.606293,14.804191,1.117680,-74.194229,294.500458,0.000000
76.330002,65.615753,-74.238708,0.000056,0.004414,0.112106,291.873444,14.868742,1.121063,-74.238708,294.500458,0.000000
76.700005,65.207626,-74.327667,0.000065,0.004414,0.112106,290.058014,14.776259,1.121063,-74.327667,294.500458,0.000000
77.070007,64.822220,-74.372147,0.000069,0.004414,0.112115,288.343628,14.688925,1.121149,-74.372147,294.500458,0.000000
77.440002,65.647034,-74.372147,0.000082,0.004426,0.112418,292.012604,14.875831,1.124185,-74.372147,294.500458,0.000000
77.810005,65.383011,-74.327667,0.000069,0.004426,0.112418,290.838165,14.816002,1.124185,-74.327667,294.500458,0.000000
78.180000,65.157364,-74.416634,0.000073,0.004426,0.112427,289.834442,14.764870,1.124271,-74.416634,294.500458,0.000000
78.550003,64.981964,-74.505592,0.000065,0.004427,0.112453,289.054199,14.725123,1.124532,-74.505592,294.500458,0.000000
78.920006,65.519669,-74.505592,0.000082,0.004435,0.112661,291.446045,14.846970,1.126613,-74.505592,294.500458,0.000000
79.290001,65.370361,-74.461113,0.000065,0.004435,0.112661,290.781891,14.813136,1.126613,-74.461113,294.500458,0.000000
79.660004,65.243744,-74.461113,0.000086,0.004436,0.112679,290.218658,14.784444,1.126786,-74.461113,294.500458,0.000000
80.030006,65.177094,-74.594559,0.000086,0.004438,0.112713,289.922180,14.769341,1.127133,-74.594559,294.500458,0.000000
80.400002,65.046387,-74.594559,0.000091,0.004437,0.112705,289.340790,14.739721,1.127046,-74.594559,294.500458,0.000000
80.770004,64.917923,-74.639038,0.000073,0.004437,0.112705,288.769348,14.710611,1.127046,-74.639038,294.500458,0.000000
81.140007,64.751465,-74.594559,0.000095,0.004438,0.112713,288.028900,14.672892,1.127133,-74.594559,294.500458,0.000000
81.510002,64.637894,-74.683517,0.000086,0.004438,0.112713,287.523712,14.647156,1.127133,-74.683517,294.500458,0.000000
81.880005,66.414856,-74.683517,0.000099,0.004432,0.112566,295.428040,15.049822,1.125659,-74.683517,294.500458,0.000000
82.250008,66.265167,-74.772476,0.000091,0.004432,0.112566,294.762177,15.015902,1.125659,-74.772476,294.500458,0.000000
82.620003,66.114731,-74.772476,0.000108,0.004432,0.112566,294.093018,14.981812,1.125659,-74.772476,294.500458,0.000000
82.990005,65.981049,-74.816963,0.000095,0.004432,0.112566,293.498352,14.951519,1.125659,-74.816963,294.500458,0.000000
83.360001,65.863373,-74.816963,0.000103,0.004432,0.112566,292.974915,14.924854,1.125659,-74.816963,294.500458,0.000000
83.730003,65.766937,-74.861443,0.000099,0.004432,0.112575,292.545959,14.903001,1.125746,-74.861443,294.500458,0.000000
84.100006,65.612396,-74.861443,0.000112,0.004432,0.112575,291.858521,14.867981,1.125746,-74.861443,294.500458,0.000000
84.470001,65.517807,-74.861443,0.000108,0.004432,0.112583,291.437775,14.846547,1.125832,-74.861443,294.500458,0.000000
84.840004,65.452652,-74.861443,0.000103,0.004433,0.112601,291.147949,14.831783,1.126006,-74.861443,294.500458,0.000000
85.210007,65.305557,-74.950401,0.000121,0.004438,0.112722,290.493622,14.798450,1.127220,-74.950401,294.500458,0.000000
85.580002,65.235931,-74.994881,0.000108,0.004438,0.112731,290.183929,14.782673,1.127307,-74.994881,294.500458,0.000000
85.950005,65.197571,-74.994881,0.000095,0.004447,0.112956,290.013275,14.773981,1.129561,-74.994881,294.500458,0.000000
86.320007,65.097412,-74.950401,0.000103,0.004447,0.112956,289.567749,14.751285,1.129561,-74.950401,294.500458,0.000000
86.690002,65.006180,-74.994881,0.000099,0.004447,0.112956,289.161926,14.730611,1.129561,-74.994881,294.500458,0.000000
87.060005,64.929092,-75.128326,0.000108,0.004447,0.112965,288.819031,14.713142,1.129648,-75.128326,294.500458,0.000000
87.430008,65.789642,-75.128326,0.000103,0.004461,0.113312,292.646942,14.908146,1.133117,-75.128326,294.500458,0.000000
87.800003,65.785919,-75.128326,0.000103,0.004461,0.113312,292.630371,14.907303,1.133117,-75.128326,294.500458,0.000000
88.170006,65.769165,-75.172806,0.000108,0.004461,0.113312,292.555847,14.903506,1.133117,-75.172806,294.500458,0.000000
88.540001,65.755020,-75.172806,0.000125,0.004461,0.113312,292.492950,14.900300,1.133117,-75.172806,294.500458,0.000000
88.910004,65.650757,-75.217285,0.000121,0.004461,0.113312,292.029144,14.876674,1.133117,-75.217285,294.500458,0.000000
89.280006,65.585220,-75.261772,0.000125,0.004461,0.113312,291.737640,14.861823,1.133117,-75.261772,294.500458,0.000000
89.650002,65.562500,-75.261772,0.000134,0.004461,0.113312,291.636566,14.856675,1.133117,-75.261772,294.500458,0.000000
90.020004,65.524887,-75.306252,0.000125,0.004461,0.113312,291.469269,14.848151,1.133117,-75.306252,294.500458,0.000000
90.390007,65.468292,-75.306252,0.000134,0.004461,0.113312,291.217499,14.835327,1.133117,-75.306252,294.500458,0.000000
90.760002,65.407227,-75.395210,0.000116,0.004461,0.113312,290.945862,14.821489,1.133117,-75.395210,294.500458,0.000000
91.130005,65.338333,-75.439690,0.000121,0.004461,0.113312,290.639435,14.805878,1.133117,-75.439690,294.500458,0.000000
91.500008,65.310776,-75.395210,0.000134,0.004461,0.113312,290.516846,14.799634,1.133117,-75.395210,294.500458,0.000000
91.870003,65.265717,-75.439690,0.000116,0.004461,0.113312,290.316406,14.789423,1.133117,-75.439690,294.500458,0.000000
92.240005,65.234436,-75.484177,0.000134,0.004461,0.113312,290.177277,14.782334,1.133117,-75.484177,294.500458,0.000000
92.610001,65.175980,-75.528656,0.000116,0.004461,0.113312,289.917236,14.769088,1.133117,-75.528656,294.500458,0.000000
92.980003,65.112305,-75.528656,0.000134,0.004461,0.113312,289.634003,14.754659,1.133117,-75.528656,294.500458,0.000000
93.350006,65.090332,-75.528656,0.000121,0.004461,0.113312,289.536255,14.749681,1.133117,-75.528656,294.500458,0.000000
93.720001,65.030746,-75.573135,0.000112,0.004461,0.113312,289.271210,14.736178,1.133117,-75.573135,294.500458,0.000000
94.090004,64.995743,-75.617615,0.000134,0.004461,0.113312,289.115509,14.728246,1.133117,-75.617615,294.500458,0.000000
94.460007,64.965958,-75.662094,0.000125,0.004461,0.113312,288.983002,14.721497,1.133117,-75.662094,294.500458,0.000000
94.830002,64.927597,-75.662094,0.000129,0.004461,0.113320,288.812378,14.712804,1.133204,-75.662094,294.500458,0.000000
95.200005,64.890732,-75.706581,0.000125,0.004461,0.113320,288.648376,14.704450,1.133204,-75.706581,294.500458,0.000000
95.570007,64.846054,-75.751060,0.000116,0.004461,0.113320,288.449646,14.694325,1.133204,-75.751060,294.500458,0.000000
95.940002,64.799515,-75.795540,0.000112,0.004461,0.113320,288.242645,14.683780,1.133204,-75.795540,294.500458,0.000000
96.310005,64.762650,-75.795540,0.000116,0.004461,0.113320,288.078644,14.675426,1.133204,-75.795540,294.500458,0.000000
96.680008,64.754822,-75.840019,0.000125,0.004461,0.113320,288.043823,14.673653,1.133204,-75.840019,294.500458,0.000000
97.050003,64.704178,-75.884506,0.000125,0.004461,0.113320,287.818573,14.662176,1.133204,-75.884506,294.500458,0.000000
97.420006,64.672531,-75.884506,0.000121,0.004461,0.113320,287.677795,14.655005,1.133204,-75.884506,294.500458,0.000000
97.790001,64.631195,-75.928986,0.000129,0.004461,0.113320,287.493927,14.645638,1.133204,-75.928986,294.500458,0.000000
98.160004,66.676636,-75.884506,0.000134,0.004441,0.112791,296.592499,15.109142,1.127914,-75.884506,294.500458,0.000000
98.530006,66.657272,-75.973465,0.000134,0.004439,0.112748,296.506348,15.104753,1.127480,-75.973465,294.500458,0.000000
98.900002,66.550781,-75.884506,0.000125,0.004439,0.112748,296.032654,15.080623,1.127480,-75.884506,294.500458,0.000000
99.270004,66.531036,-76.017944,0.000116,0.004439,0.112748,295.944824,15.076148,1.127480,-76.017944,294.500458,0.000000
99.640007,66.408905,-76.062424,0.000134,0.004439,0.112748,295.401550,15.048472,1.127480,-76.062424,294.500458,0.000000
100.010002,66.378738,-76.062424,0.000138,0.004439,0.112748,295.267365,15.041636,1.127480,-76.062424,294.500458,0.000000
100.380005,66.401459,-76.062424,0.000121,0.004439,0.112748,295.368439,15.046786,1.127480,-76.062424,294.500458,0.000000
100.750008,66.371658,-76.062424,0.000134,0.004439,0.112748,295.235870,15.040032,1.127480,-76.062424,294.500458,0.000000
101.120003,66.329956,-76.151390,0.000129,0.004439,0.112748,295.050385,15.030583,1.127480,-76.151390,294.500458,0.000000
101.490005,66.295334,-76.195869,0.000125,0.004439,0.112748,294.896362,15.022738,1.127480,-76.195869,294.500458,0.000000
101.860008,66.240967,-76.151390,0.000125,0.004439,0.112748,294.654541,15.010418,1.127480,-76.151390,294.500458,0.000000
102.230003,66.218994,-76.106911,0.000138,0.004439,0.112748,294.556793,15.005439,1.127480,-76.106911,294.500458,0.000000
102.600006,66.184738,-76.240349,0.000129,0.004439,0.112748,294.404419,14.997676,1.127480,-76.240349,294.500458,0.000000
102.970001,66.147491,-76.240349,0.000116,0.004439,0.112748,294.238739,14.989236,1.127480,-76.240349,294.500458,0.000000
103.340004,66.112869,-76.284828,0.000142,0.004439,0.112748,294.084717,14.981391,1.127480,-76.284828,294.500458,0.000000
103.710007,66.079346,-76.373795,0.000138,0.004439,0.112748,293.935608,14.973794,1.127480,-76.373795,294.500458,0.000000
104.080002,66.054031,-76.329315,0.000129,0.004439,0.112748,293.822998,14.968057,1.127480,-76.329315,294.500458,0.000000
104.450005,66.009338,-76.418274,0.000134,0.004439,0.112748,293.624207,14.957931,1.127480,-76.418274,294.500458,0.000000
104.820007,65.992218,-76.418274,0.000142,0.004439,0.112748,293.548035,14.954050,1.127480,-76.418274,294.500458,0.000000
105.190002,65.969131,-76.507233,0.000142,0.004439,0.112748,293.445343,14.948819,1.127480,-76.507233,294.500458,0.000000
105.560005,65.864120,-76.462753,0.000129,0.004439,0.112757,292.978241,14.925023,1.127567,-76.462753,294.500458,0.000000
105.930008,65.888702,-76.507233,0.000125,0.004440,0.112765,293.087585,14.930593,1.127654,-76.507233,294.500458,0.000000
106.300003,65.875671,-76.462753,0.000121,0.004440,0.112765,293.029633,14.927641,1.127654,-76.462753,294.500458,0.000000
106.670006,65.841782,-76.596199,0.000138,0.004440,0.112765,292.878876,14.919961,1.127654,-76.596199,294.500458,0.000000
107.040009,65.848480,-76.551720,0.000147,0.004440,0.112765,292.908661,14.921478,1.127654,-76.551720,294.500458,0.000000
107.410004,65.804169,-76.596199,0.000138,0.004440,0.112765,292.711548,14.911438,1.127654,-76.596199,294.500458,0.000000
107.780006,65.771774,-76.685158,0.000129,0.004440,0.112765,292.567474,14.904097,1.127654,-76.685158,294.500458,0.000000
108.150002,65.774002,-76.729637,0.000121,0.004440,0.112765,292.577362,14.904602,1.127654,-76.729637,294.500458,0.000000
108.520004,65.755386,-76.685158,0.000138,0.004440,0.112765,292.494568,14.900384,1.127654,-76.685158,294.500458,0.000000
108.890007,65.704376,-76.685158,0.000138,0.004440,0.112774,292.267670,14.888824,1.127740,-76.685158,294.500458,0.000000
109.260002,65.662292,-76.685158,0.000138,0.004442,0.112817,292.080475,14.879289,1.128174,-76.685158,294.500458,0.000000
109.630005,65.628784,-76.729637,0.000138,0.004442,0.112817,291.931427,14.871696,1.128174,-76.729637,294.500458,0.000000
110.000008,65.610535,-76.863083,0.000138,0.004442,0.112817,291.850220,14.867560,1.128174,-76.863083,294.500458,0.000000
110.370003,65.585220,-76.863083,0.000121,0.004442,0.112817,291.737640,14.861823,1.128174,-76.863083,294.500458,0.000000
110.740005,65.577393,-76.818604,0.000138,0.004442,0.112817,291.702820,14.860049,1.128174,-76.818604,294.500458,0.000000
111.110008,65.569199,-76.863083,0.000142,0.004442,0.112817,291.666351,14.858193,1.128174,-76.863083,294.500458,0.000000
111.480003,65.554306,-76.952042,0.000138,0.004442,0.112817,291.600128,14.854818,1.128174,-76.952042,294.500458,0.000000
111.850006,65.523026,-76.952042,0.000142,0.004442,0.112826,291.460968,14.847730,1.128261,-76.952042,294.500458,0.000000
112.220009,65.486160,-76.952042,0.000134,0.004442,0.112826,291.296997,14.839376,1.128261,-76.952042,294.500458,0.000000
112.590004,65.488770,-76.996529,0.000138,0.004442,0.112835,291.308594,14.839967,1.128347,-76.996529,294.500458,0.000000
112.960007,65.460846,-76.996529,0.000129,0.004442,0.112835,291.184387,14.833639,1.128347,-76.996529,294.500458,0.000000
113.330002,65.436630,-77.129967,0.000138,0.004445,0.112904,291.076660,14.828153,1.129041,-77.129967,294.500458,0.000000
113.700005,65.393066,-77.129967,0.000125,0.004445,0.112904,290.882874,14.818280,1.129041,-77.129967,294.500458,0.000000
114.070007,65.391953,-77.085487,0.000138,0.004445,0.112904,290.877930,14.818028,1.129041,-77.085487,294.500458,0.000000
114.440002,65.367752,-77.129967,0.000138,0.004445,0.112904,290.770294,14.812545,1.129041,-77.129967,294.500458,0.000000
114.810005,65.333496,-77.129967,0.000129,0.004445,0.112904,290.617920,14.804782,1.129041,-77.129967,294.500458,0.000000
115.180008,65.326035,-77.218933,0.000138,0.004448,0.112973,290.584717,14.803091,1.129735,-77.218933,294.500458,0.000000
115.550003,65.308914,-77.218933,0.000121,0.004448,0.112973,290.508545,14.799212,1.129735,-77.218933,294.500458,0.000000
115.920006,65.299225,-77.218933,0.000138,0.004448,0.112973,290.465454,14.797015,1.129735,-77.218933,294.500458,0.000000
116.290009,65.289917,-77.263412,0.000142,0.004448,0.112973,290.424042,14.794907,1.129735,-77.263412,294.500458,0.000000
116.660004,65.277267,-77.352371,0.000134,0.004448,0.112973,290.367798,14.792040,1.129735,-77.352371,294.500458,0.000000
117.030006,65.270935,-77.352371,0.000129,0.004448,0.112982,290.339630,14.790605,1.129822,-77.352371,294.500458,0.000000
117.400009,65.256042,-77.396858,0.000125,0.004448,0.112982,290.273376,14.787230,1.129822,-77.396858,294.500458,0.000000
117.770004,65.237793,-77.441338,0.000134,0.004448,0.112982,290.192200,14.783095,1.129822,-77.441338,294.500458,0.000000
118.140007,65.213593,-77.307892,0.000129,0.004448,0.112982,290.084534,14.777611,1.129822,-77.307892,294.500458,0.000000
118.510002,65.270187,-77.485817,0.000125,0.004469,0.113520,290.336304,14.790436,1.135198,-77.485817,294.500458,0.000000
118.880005,65.298492,-77.485817,0.000129,0.004472,0.113589,290.462189,14.796850,1.135892,-77.485817,294.500458,0.000000
119.250008,65.301468,-77.485817,0.000138,0.004472,0.113598,290.475433,14.797524,1.135979,-77.485817,294.500458,0.000000
119.620003,65.296997,-77.485817,0.000138,0.004472,0.113598,290.455536,14.796512,1.135979,-77.485817,294.500458,0.000000
119.990005,65.303696,-77.574776,0.000138,0.004472,0.113598,290.485352,14.798029,1.135979,-77.574776,294.500458,0.000000
120.360008,65.308548,-77.619263,0.000129,0.004474,0.113633,290.506927,14.799129,1.136326,-77.619263,294.500458,0.000000
120.730003,65.315247,-77.619263,0.000129,0.004474,0.113633,290.536713,14.800647,1.136326,-77.619263,294.500458,0.000000
121.100006,65.307053,-77.619263,0.000142,0.004474,0.113633,290.500275,14.798789,1.136326,-77.619263,294.500458,0.000000
121.470009,65.368866,-77.663742,0.000116,0.004476,0.113693,290.775238,14.812798,1.136933,-77.663742,294.500458,0.000000
121.840004,65.411316,-77.619263,0.000142,0.004476,0.113693,290.964050,14.822415,1.136933,-77.619263,294.500458,0.000000
122.210007,65.391586,-77.752701,0.000121,0.004476,0.113693,290.876312,14.817945,1.136933,-77.752701,294.500458,0.000000
122.580009,65.406845,-77.752701,0.000121,0.004476,0.113693,290.944183,14.821403,1.136933,-77.752701,294.500458,0.000000
122.950005,65.394180,-77.708221,0.000134,0.004476,0.113693,290.887848,14.818533,1.136933,-77.708221,294.500458,0.000000
123.320007,65.392700,-77.797180,0.000129,0.004476,0.113693,290.881256,14.818198,1.136933,-77.797180,294.500458,0.000000
123.690002,65.369232,-77.752701,0.000138,0.004476,0.113693,290.776855,14.812880,1.136933,-77.752701,294.500458,0.000000
124.060005,65.360306,-77.930626,0.000125,0.004476,0.113693,290.737152,14.810857,1.136933,-77.930626,294.500458,0.000000
124.430008,65.352478,-77.841667,0.000138,0.004476,0.113693,290.702332,14.809083,1.136933,-77.841667,294.500458,0.000000
124.800003,65.333115,-77.841667,0.000134,0.004476,0.113702,290.616211,14.804696,1.137020,-77.841667,294.500458,0.000000
125.170006,65.338333,-77.886147,0.000138,0.004476,0.113702,290.639435,14.805878,1.137020,-77.886147,294.500458,0.000000
125.540009,65.325668,-77.930626,0.000125,0.004476,0.113702,290.583099,14.803008,1.137020,-77.930626,294.500458,0.000000
125.910004,65.321579,-77.975105,0.000142,0.004476,0.113702,290.564880,14.802081,1.137020,-77.975105,294.500458,0.000000
126.280006,65.313385,-77.975105,0.000134,0.004476,0.113702,290.528442,14.800224,1.137020,-77.975105,294.500458,0.000000
126.650009,65.309662,-77.975105,0.000134,0.004476,0.113702,290.511871,14.799381,1.137020,-77.975105,294.500458,0.000000
127.020004,65.307053,-78.064072,0.000142,0.004476,0.113702,290.500275,14.798789,1.137020,-78.064072,294.500458,0.000000
127.390007,65.296997,-78.108551,0.000138,0.004476,0.113702,290.455536,14.796512,1.137020,-78.108551,294.500458,0.000000
127.760010,65.302948,-78.108551,0.000129,0.004479,0.113754,290.482025,14.797860,1.137540,-78.108551,294.500458,0.000000
128.130005,65.341675,-78.108551,0.000147,0.004479,0.113763,290.654297,14.806635,1.137627,-78.108551,294.500458,0.000000
128.500000,65.371475,-78.108551,0.000134,0.004479,0.113763,290.786835,14.813388,1.137627,-78.108551,294.500458,0.000000
128.870010,65.368118,-78.153030,0.000134,0.004479,0.113763,290.771912,14.812628,1.137627,-78.153030,294.500458,0.000000
129.240005,65.376312,-78.197510,0.000138,0.004479,0.113763,290.808350,14.814484,1.137627,-78.197510,294.500458,0.000000
129.610001,65.376312,-78.330956,0.000125,0.004479,0.113763,290.808350,14.814484,1.137627,-78.330956,294.500458,0.000000
129.980011,65.372223,-78.197510,0.000142,0.004479,0.113763,290.790161,14.813558,1.137627,-78.197510,294.500458,0.000000
130.350006,65.356949,-78.241989,0.000134,0.004479,0.113763,290.722229,14.810097,1.137627,-78.241989,294.500458,0.000000
130.720001,65.350998,-78.286476,0.000138,0.004479,0.113763,290.695770,14.808748,1.137627,-78.286476,294.500458,0.000000
131.090012,65.335724,-78.330956,0.000134,0.004479,0.113763,290.627808,14.805286,1.137627,-78.330956,294.500458,0.000000
131.460007,65.349136,-78.375435,0.000129,0.004479,0.113763,290.687469,14.808326,1.137627,-78.375435,294.500458,0.000000
131.830002,65.348007,-78.375435,0.000142,0.004479,0.113763,290.682465,14.808070,1.137627,-78.375435,294.500458,0.000000
132.200012,65.317474,-78.375435,0.000142,0.004479,0.113763,290.546631,14.801151,1.137627,-78.375435,294.500458,0.000000
132.570007,65.338699,-78.419914,0.000134,0.004481,0.113806,290.641052,14.805962,1.138060,-78.419914,294.500458,0.000000
132.940002,65.342804,-78.508881,0.000134,0.004481,0.113806,290.659302,14.806890,1.138060,-78.508881,294.500458,0.000000
133.310013,65.348389,-78.508881,0.000134,0.004481,0.113806,290.684143,14.808156,1.138060,-78.508881,294.500458,0.000000
133.680008,65.342804,-78.508881,0.000134,0.004481,0.113806,290.659302,14.806890,1.138060,-78.508881,294.500458,0.000000
134.050003,65.335724,-78.553360,0.000134,0.004481,0.113806,290.627808,14.805286,1.138060,-78.553360,294.500458,0.000000
134.420013,65.343170,-78.597839,0.000134,0.004481,0.113806,290.660950,14.806974,1.138060,-78.597839,294.500458,0.000000
134.790009,65.328278,-78.642319,0.000138,0.004481,0.113806,290.594696,14.803599,1.138060,-78.642319,294.500458,0.000000
135.160004,65.324173,-78.686806,0.000121,0.004481,0.113806,290.576447,14.802670,1.138060,-78.686806,294.500458,0.000000
135.530014,65.314865,-78.642319,0.000134,0.004481,0.113806,290.535034,14.800560,1.138060,-78.642319,294.500458,0.000000
135.900009,65.324921,-78.642319,0.000142,0.004481,0.113806,290.579773,14.802838,1.138060,-78.642319,1681.640747,0.000000
136.270004,65.307053,-78.775764,0.000142,0.004474,0.113641,290.500275,14.798789,1.136413,-78.775764,0.113442,0.000000
136.639999,65.331635,-78.731285,0.000147,0.004457,0.113208,290.609619,14.804359,1.132077,-78.731285,0.112826,0.000000
137.010010,65.239273,-78.864723,0.000155,0.004438,0.112713,290.198792,14.783430,1.127133,-78.864723,0.112210,0.000000
137.380005,65.209869,-78.775764,0.000151,0.004414,0.112124,290.067993,14.776768,1.121236,-78.775764,0.111595,0.000000
137.750000,65.194962,-78.820244,0.000147,0.004391,0.111534,290.001678,14.773390,1.115339,-78.820244,0.110979,0.000000
138.120010,65.153641,-78.864723,0.000142,0.004365,0.110875,289.817871,14.764026,1.108748,-78.864723,0.110363,0.000000
138.490005,65.165924,-78.909210,0.000151,0.004349,0.110467,289.872498,14.766809,1.104672,-78.909210,0.109747,0.000000
138.860001,65.142838,-78.909210,0.000134,0.004318,0.109678,289.769806,14.761578,1.096780,-78.909210,0.109123,0.000000
139.230011,65.126083,-78.909210,0.000147,0.004296,0.109123,289.695282,14.757781,1.091230,-78.909210,0.108507,0.000000
139.600006,65.084366,-78.998169,0.000142,0.004270,0.108455,289.509705,14.748328,1.084552,-78.998169,0.107892,0.000000
139.970001,64.949951,-79.042648,0.000151,0.004247,0.107866,288.911804,14.717870,1.078655,-79.042648,0.107276,0.000000
140.340012,64.589859,-79.131615,0.000151,0.004229,0.107423,287.310028,14.636271,1.074232,-79.131615,0.106660,0.000000
140.710007,63.762817,-79.087128,0.000142,0.004205,0.106816,283.631165,14.448861,1.068162,-79.087128,0.106044,0.000000
141.080002,62.811783,-79.087128,0.000151,0.004182,0.106218,279.400757,14.233353,1.062178,-79.087128,0.105429,0.000000
141.450012,61.523003,-79.176094,0.000142,0.004160,0.105663,273.667969,13.941312,1.056628,-79.176094,0.104813,0.000000
141.820007,59.848816,-79.220573,0.000168,0.004135,0.105038,266.220825,13.561935,1.050384,-79.220573,0.104197,0.000000
142.190002,58.182449,-79.176094,0.000142,0.004113,0.104475,258.808472,13.184332,1.044747,-79.176094,0.103573,0.000000
142.560013,56.603592,-79.176094,0.000151,0.004093,0.103963,251.785355,12.826558,1.039630,-79.176094,0.102957,0.000000
142.930008,54.341423,-79.265053,0.000147,0.004071,0.103399,241.722717,12.313943,1.033993,-79.265053,0.102341,0.000000
143.300003,52.341789,-79.354019,0.000147,0.004051,0.102896,232.827911,11.860819,1.028963,-79.354019,0.101726,0.000000
143.670013,49.501701,-79.354019,0.000151,0.004022,0.102168,220.194565,11.217246,1.021679,-79.354019,0.101110,0.000000
144.040009,46.626984,-79.309532,0.000172,0.003994,0.101457,207.407181,10.565825,1.014567,-79.309532,0.100494,0.000000
144.410004,44.172676,-79.309532,0.000160,0.003972,0.100893,196.489883,10.009671,1.008930,-79.309532,0.099878,0.000000
144.780014,42.747986,-79.309532,0.000155,0.003961,0.100607,190.152542,9.686832,1.006069,-79.309532,0.099263,0.000000
145.150009,38.964310,-79.398499,0.000168,0.003925,0.099688,173.321899,8.829439,0.996876,-79.398499,0.098647,0.000000
145.520004,36.760605,-79.442978,0.000155,0.003908,0.099254,163.519333,8.330071,0.992540,-79.442978,0.098023,0.000000
145.889999,34.144691,-79.442978,0.000172,0.003882,0.098595,151.883179,7.737298,0.985949,-79.442978,0.097407,0.000000
146.260010,31.234222,-79.487457,0.000155,0.003856,0.097944,138.936768,7.077776,0.979445,-79.487457,0.096791,0.000000
146.630005,28.555008,-79.531944,0.000151,0.003833,0.097346,127.019020,6.470657,0.973461,-79.531944,0.096175,0.000000
147.000000,25.300468,-79.531944,0.000147,0.003801,0.096540,112.542107,5.733168,0.965396,-79.531944,0.095560,0.000000
147.370010,22.808556,-79.576424,0.000138,0.003776,0.095915,101.457520,5.168493,0.959152,-79.576424,0.094944,0.000000
147.740005,20.977600,-79.576424,0.000142,0.003766,0.095655,93.313026,4.753592,0.956550,-79.576424,0.094328,0.000000
148.110001,17.173813,-79.665382,0.000134,0.003730,0.094753,76.392937,3.891642,0.947531,-79.665382,0.093712,0.000000
148.480011,16.049622,-79.665382,0.000138,0.003715,0.094354,71.392281,3.636896,0.943542,-79.665382,0.093097,0.000000
148.850006,11.389755,-79.754349,0.000125,0.003679,0.093444,50.664162,2.580956,0.934436,-79.754349,0.092472,0.000000
149.220001,9.686897,-79.665382,0.000134,0.003664,0.093053,43.089470,2.195082,0.930533,-79.665382,0.091857,0.000000
149.590012,6.496780,-79.665382,0.000129,0.003635,0.092325,28.899122,1.472191,0.923248,-79.665382,0.091241,0.000000
149.960007,4.382072,-79.709862,0.000129,0.003616,0.091839,19.492432,0.992992,0.918392,-79.709862,0.090625,0.000000
150.330002,1.696526,-79.887787,0.000116,0.003589,0.091171,7.546523,0.384438,0.911714,-79.887787,0.090009,0.000000
150.700012,-1.298096,-79.843307,0.000112,0.003557,0.090348,-5.774218,-0.294153,0.903476,-79.843307,0.089394,0.000000
151.070007,-0.090866,-79.843307,0.000095,0.003540,0.089923,-0.404193,-0.020591,0.899226,-79.843307,0.088778,0.000000
151.440002,-0.246513,-79.887787,0.000052,0.003510,0.089159,-1.096546,-0.055861,0.891595,-79.887787,0.088162,0.000000
151.810013,0.048035,-79.887787,-0.000026,0.003486,0.088535,0.213669,0.010885,0.885351,-79.887787,0.087546,0.000000
152.180008,0.185814,-79.932266,-0.000043,0.003468,0.088075,0.826542,0.042106,0.880754,-79.932266,0.086922,0.000000
152.550003,0.128090,-79.976753,-0.000095,0.003434,0.087234,0.569772,0.029026,0.872342,-79.976753,0.086306,0.000000
152.920013,0.121391,-79.976753,-0.000160,0.003412,0.086662,0.539975,0.027508,0.866619,-79.976753,0.085691,0.000000
153.290009,0.142990,-79.976753,-0.000220,0.003388,0.086046,0.636052,0.032402,0.860461,-79.976753,0.085075,0.000000
153.660004,0.122505,-80.065712,-0.000267,0.003364,0.085439,0.544930,0.027760,0.854391,-80.065712,0.084459,0.000000
154.030014,0.097183,-80.065712,-0.000323,0.003341,0.084849,0.432293,0.022022,0.848494,-80.065712,0.083843,0.000000
154.400009,0.114311,-80.110191,-0.000379,0.003311,0.084095,0.508482,0.025903,0.840949,-80.110191,0.083228,0.000000
154.770004,0.128090,-80.154671,-0.000444,0.003289,0.083540,0.569772,0.029026,0.835399,-80.154671,0.082612,0.000000
155.140015,0.068138,-80.110191,-0.000487,0.003268,0.083020,0.303093,0.015440,0.830195,-80.110191,0.081996,0.000000
155.500000,0.137032,-80.154671,-0.000543,0.003259,0.082777,0.609547,0.031052,0.827767,-80.154671,0.082638,0.000000