File: Data/compression 32/AutoNoHeating-17-32-reverse-1-1_11142024_160512.csv
Time (sec),S:Load (lbs),S:HL1 (DIM),S:LVDT (in),S:Position (in),Ch:Position (mm),Ch:Load (N),Ch:Stress (MPa),Ch:Strain (mm/mm),Ch:HL1 (DIM),Set Point (),Cycles ()
0.110000,-0.008194,-163.467499,-0.005941,-0.006058,-0.153880,-0.036449,-0.001857,-1.538802,-163.467499,-0.153697,0.000000
0.490000,-0.024208,-163.467499,-0.005941,-0.005998,-0.152362,-0.107683,-0.005486,-1.523617,-163.467499,-0.151824,0.000000
0.870000,0.041336,-163.600937,-0.005894,-0.005782,-0.146872,0.183872,0.009367,-1.468721,-163.600937,-0.145494,0.000000
1.250000,0.046173,-163.600937,-0.005648,-0.005529,-0.140438,0.205388,0.010463,-1.404378,-163.600937,-0.139163,0.000000
1.630000,0.068146,-163.600937,-0.005385,-0.005276,-0.134003,0.303127,0.015442,-1.340034,-163.600937,-0.132832,0.000000
2.010000,0.106125,-163.645416,-0.005333,-0.000007,-0.000182,0.472067,0.024048,-0.001817,-163.645416,-0.000017,0.000000
2.390000,0.101288,-163.689896,-0.005320,-0.000007,-0.000182,0.450551,0.022952,-0.001817,-163.689896,0.000216,0.000000
2.770000,0.118790,-163.689896,-0.005312,0.000005,0.000139,0.528403,0.026918,0.001393,-163.689896,0.000849,0.000000
3.150000,0.186928,-163.778854,-0.005312,0.000025,0.000642,0.831496,0.042358,0.006419,-163.778854,0.001484,0.000000
3.530000,0.335136,-163.778854,-0.005295,0.000053,0.001353,1.490761,0.075943,0.013535,-163.778854,0.002117,0.000000
3.910000,0.480362,-163.734375,-0.005269,0.000071,0.001796,2.136757,0.108852,0.017956,-163.734375,0.002749,0.000000
4.290000,0.582764,-163.823349,-0.005251,0.000086,0.002194,2.592262,0.132056,0.021937,-163.823349,0.003382,0.000000
4.670000,0.934280,-163.867828,-0.005208,0.000127,0.003235,4.155887,0.211711,0.032353,-163.867828,0.004015,0.000000
5.050000,1.101479,-163.956787,-0.005204,0.000145,0.003677,4.899621,0.249599,0.036774,-163.956787,0.004648,0.000000
5.430000,1.383362,-163.956787,-0.005182,0.000168,0.004266,6.153501,0.313474,0.042663,-163.956787,0.005282,0.000000
5.810000,1.823883,-163.956787,-0.005157,0.000201,0.005108,8.113037,0.413298,0.051081,-163.956787,0.005915,0.000000
6.190000,1.970970,-163.956787,-0.005139,0.000214,0.005446,8.767313,0.446628,0.054457,-163.956787,0.006548,0.000000
6.570000,2.547028,-164.001266,-0.005109,0.000250,0.006348,11.329744,0.577165,0.063480,-164.001266,0.007181,0.000000
6.950000,2.859818,-164.090225,-0.005101,0.000272,0.006911,12.721104,0.648044,0.069112,-164.090225,0.007814,0.000000
7.330000,3.174103,-164.179184,-0.005088,0.000293,0.007450,14.119114,0.719262,0.074502,-164.179184,0.008455,0.000000
7.710001,3.687233,-164.090225,-0.005040,0.000321,0.008160,16.401632,0.835539,0.081602,-164.090225,0.009088,0.000000
8.090000,3.906929,-164.090225,-0.005027,0.000340,0.008637,17.378889,0.885323,0.086371,-164.090225,0.009721,0.000000
8.470000,4.623001,-164.179184,-0.004997,0.000377,0.009565,20.564137,1.047587,0.095652,-164.179184,0.010355,0.000000
8.850000,4.791687,-164.223679,-0.004971,0.000396,0.010060,21.314487,1.085812,0.100603,-164.223679,0.010988,0.000000
9.230000,5.103363,-164.223679,-0.004958,0.000417,0.010589,22.700893,1.156439,0.105886,-164.223679,0.011621,0.000000
9.610001,5.725227,-164.223679,-0.004919,0.000448,0.011379,25.467083,1.297355,0.113789,-164.223679,0.012254,0.000000
9.990001,5.829865,-164.268158,-0.004902,0.000464,0.011794,25.932533,1.321066,0.117937,-164.268158,0.012887,0.000000
10.370001,6.464386,-164.401596,-0.004859,0.000499,0.012670,28.755026,1.464851,0.126703,-164.401596,0.013520,0.000000
10.750001,6.625992,-164.401596,-0.004842,0.000522,0.013268,29.473885,1.501471,0.132683,-164.401596,0.014154,0.000000
11.130000,6.983841,-164.401596,-0.004816,0.000550,0.013971,31.065676,1.582561,0.139708,-164.401596,0.014787,0.000000
11.510000,7.236687,-164.446075,-0.004803,0.000570,0.014466,32.190392,1.639857,0.144659,-164.446075,0.015420,0.000000
11.890000,7.478729,-164.401596,-0.004773,0.000591,0.015003,33.267048,1.694704,0.150033,-164.401596,0.016052,0.000000
12.270000,8.010849,-164.535034,-0.004743,0.000623,0.015836,35.634037,1.815284,0.158360,-164.535034,0.016685,0.000000
12.650001,8.024254,-164.490555,-0.004704,0.000648,0.016460,35.693665,1.818322,0.164598,-164.490555,0.017318,0.000000
13.030001,7.921104,-164.579514,-0.004700,0.000664,0.016867,35.234833,1.794948,0.168670,-164.579514,0.017951,0.000000
13.410001,8.530304,-164.535034,-0.004674,0.000695,0.017657,37.944687,1.932994,0.176573,-164.535034,0.018585,0.000000
13.790001,8.562706,-164.623993,-0.004644,0.000716,0.018177,38.088818,1.940337,0.181766,-164.623993,0.019218,0.000000
14.170001,8.475945,-164.668488,-0.004622,0.000728,0.018481,37.702885,1.920676,0.184809,-164.668488,0.019851,0.000000
14.550001,9.135414,-164.712967,-0.004570,0.000775,0.019686,40.636353,2.070115,0.196860,-164.712967,0.020484,0.000000
14.930000,8.969337,-164.668488,-0.004562,0.000791,0.020093,39.897606,2.032481,0.200933,-164.668488,0.021117,0.000000
15.310000,9.385651,-164.712967,-0.004523,0.000820,0.020840,41.749458,2.126819,0.208396,-164.712967,0.021750,0.000000
15.690001,9.224037,-164.668488,-0.004501,0.000833,0.021161,41.030567,2.090197,0.211606,-164.668488,0.022384,0.000000
16.070002,9.309685,-164.846405,-0.004475,0.000853,0.021672,41.411545,2.109605,0.216723,-164.846405,0.023017,0.000000
16.450001,10.030220,-164.846405,-0.004432,0.000897,0.022773,44.616646,2.272880,0.227730,-164.846405,0.023650,0.000000
16.830000,9.842545,-164.801926,-0.004398,0.000917,0.023285,43.781826,2.230352,0.232847,-164.801926,0.024282,0.000000
17.210001,10.193695,-164.801926,-0.004381,0.000948,0.024092,45.343819,2.309924,0.240916,-164.801926,0.024915,0.000000
17.590000,9.920746,-164.890884,-0.004346,0.000963,0.024464,44.129681,2.248073,0.244640,-164.890884,0.025548,0.000000
17.970001,9.727486,-164.979843,-0.004324,0.000973,0.024715,43.270016,2.204280,0.247154,-164.979843,0.026182,0.000000
18.350000,10.558250,-164.979843,-0.004286,0.001022,0.025957,46.965443,2.392534,0.259568,-164.979843,0.026823,0.000000
18.730001,10.425308,-165.024323,-0.004251,0.001043,0.026485,46.374088,2.362409,0.264852,-165.024323,0.027457,0.000000
19.110001,10.597717,-164.979843,-0.004230,0.001069,0.027162,47.141003,2.401477,0.271619,-164.979843,0.028090,0.000000
19.490002,10.470741,-164.979843,-0.004199,0.001086,0.027595,46.576183,2.372704,0.275949,-164.979843,0.028723,0.000000
19.870001,11.151436,-165.113297,-0.004152,0.001124,0.028541,49.604065,2.526951,0.285411,-165.113297,0.029356,0.000000
20.250002,11.045311,-165.202255,-0.004135,0.001149,0.029174,49.131996,2.502903,0.291740,-165.202255,0.029988,0.000000
20.630001,10.876251,-165.113297,-0.004113,0.001168,0.029677,48.379982,2.464594,0.296766,-165.113297,0.030621,0.000000
21.010000,11.115692,-165.157776,-0.004079,0.001198,0.030423,49.445068,2.518852,0.304230,-165.157776,0.031256,0.000000
21.390001,10.974190,-165.202255,-0.004044,0.001214,0.030839,48.815636,2.486787,0.308393,-165.202255,0.031888,0.000000
21.770000,10.932480,-165.335693,-0.004023,0.001229,0.031221,48.630100,2.477335,0.312208,-165.335693,0.032521,0.000000
22.150002,11.302246,-165.335693,-0.003992,0.001265,0.032122,50.274902,2.561126,0.321216,-165.335693,0.033154,0.000000
22.530001,11.517853,-165.291214,-0.003954,0.001293,0.032851,51.233967,2.609983,0.328514,-165.291214,0.033787,0.000000
22.910002,11.557693,-165.335693,-0.003941,0.001314,0.033371,51.411190,2.619011,0.333707,-165.335693,0.034420,0.000000
23.290001,11.686913,-165.424652,-0.003915,0.001340,0.034038,51.985985,2.648292,0.340383,-165.424652,0.035053,0.000000
23.670002,11.624725,-165.424652,-0.003885,0.001357,0.034480,51.709362,2.634200,0.344804,-165.424652,0.035687,0.000000
24.050001,12.239883,-165.469131,-0.003829,0.001397,0.035487,54.445721,2.773597,0.354872,-165.469131,0.036320,0.000000
24.430000,12.058533,-165.513626,-0.003811,0.001417,0.035981,53.639034,2.732503,0.359807,-165.513626,0.036953,0.000000
24.810001,12.319199,-165.513626,-0.003773,0.001446,0.036736,54.798531,2.791570,0.367362,-165.513626,0.037586,0.000000
25.190001,12.366119,-165.513626,-0.003747,0.001468,0.037299,55.007248,2.802203,0.372994,-165.513626,0.038218,0.000000
25.570002,12.172485,-165.602585,-0.003738,0.001483,0.037672,54.145920,2.758325,0.376718,-165.602585,0.038851,0.000000
25.950001,12.805885,-165.691544,-0.003699,0.001519,0.038574,56.963425,2.901855,0.385741,-165.691544,0.039486,0.000000
26.330002,12.767906,-165.647064,-0.003669,0.001542,0.039165,56.794483,2.893249,0.391646,-165.647064,0.040118,0.000000
26.710001,12.834190,-165.647064,-0.003639,0.001565,0.039754,57.089329,2.908269,0.397535,-165.647064,0.040751,0.000000
27.090002,13.142509,-165.736023,-0.003604,0.001594,0.040482,58.460800,2.978135,0.404817,-165.736023,0.041384,0.000000
27.470001,12.962288,-165.736023,-0.003574,0.001611,0.040916,57.659138,2.937296,0.409162,-165.736023,0.042017,0.000000
27.850000,13.483978,-165.824982,-0.003548,0.001642,0.041714,59.979733,3.055513,0.417141,-165.824982,0.042650,0.000000
28.230001,13.490311,-165.824982,-0.003518,0.001666,0.042312,60.007900,3.056948,0.423121,-165.824982,0.043284,0.000000
28.610001,13.550636,-165.736023,-0.003501,0.001689,0.042903,60.276241,3.070618,0.429025,-165.736023,0.043917,0.000000
28.990002,13.980721,-165.869461,-0.003458,0.001719,0.043673,62.189350,3.168077,0.436731,-165.869461,0.044550,0.000000
29.370001,13.740913,-165.913940,-0.003428,0.001737,0.044108,61.122635,3.113735,0.441077,-165.913940,0.045192,0.000000
29.750002,14.211967,-165.958435,-0.003415,0.001769,0.044922,63.217987,3.220478,0.449222,-165.958435,0.045824,0.000000
30.130001,14.189621,-166.002914,-0.003389,0.001791,0.045504,63.118587,3.215414,0.455035,-166.002914,0.046457,0.000000
30.510002,14.152016,-166.002914,-0.003359,0.001812,0.046024,62.951309,3.206893,0.460243,-166.002914,0.047090,0.000000
30.890001,14.539658,-166.047394,-0.003333,0.001841,0.046753,64.675629,3.294734,0.467525,-166.047394,0.047723,0.000000
31.270002,14.623810,-166.136353,-0.003320,0.001862,0.047290,65.049957,3.313802,0.472900,-166.136353,0.048357,0.000000
31.650002,15.170822,-166.180832,-0.003272,0.001894,0.048114,67.483185,3.437757,0.481136,-166.180832,0.048990,0.000000
32.030003,15.087418,-166.136353,-0.003251,0.001920,0.048774,67.112183,3.418858,0.487737,-166.136353,0.049623,0.000000
32.410000,15.221092,-166.180832,-0.003212,0.001943,0.049346,67.706802,3.449149,0.493459,-166.180832,0.050256,0.000000
32.790001,15.259819,-166.180832,-0.003182,0.001963,0.049858,67.879066,3.457925,0.498577,-166.180832,0.050889,0.000000
33.170002,15.571869,-166.269791,-0.003178,0.001988,0.050507,69.267136,3.528636,0.505072,-166.269791,0.051522,0.000000
33.550003,15.497025,-166.358749,-0.003156,0.002011,0.051070,68.934212,3.511676,0.510703,-166.358749,0.052156,0.000000
33.930000,15.985573,-166.269791,-0.003117,0.002041,0.051842,71.107376,3.622383,0.518425,-166.269791,0.052789,0.000000
34.310001,15.798645,-166.314270,-0.003083,0.002061,0.052354,70.275887,3.580024,0.523542,-166.314270,0.053422,0.000000
34.690002,16.196709,-166.358749,-0.003070,0.002088,0.053031,72.046562,3.670227,0.530309,-166.358749,0.054054,0.000000
35.070004,16.325554,-166.403244,-0.003027,0.002112,0.053647,72.619690,3.699423,0.536471,-166.403244,0.054687,0.000000
35.450001,16.047020,-166.492203,-0.003018,0.002126,0.053994,71.380707,3.636307,0.539938,-166.492203,0.055320,0.000000
35.830002,17.271004,-166.403244,-0.002945,0.002172,0.055164,76.825264,3.913665,0.551641,-166.403244,0.055953,0.000000
36.210003,16.936615,-166.492203,-0.002953,0.002189,0.055590,75.337830,3.837892,0.555895,-166.492203,0.056587,0.000000
36.590000,17.249039,-166.536682,-0.002932,0.002216,0.056274,76.727554,3.908688,0.562738,-166.536682,0.057220,0.000000
36.970001,17.130997,-166.581161,-0.002897,0.002232,0.056683,76.202477,3.881939,0.566826,-166.581161,0.057853,0.000000
37.350002,17.449745,-166.625641,-0.002889,0.002262,0.057446,77.620346,3.954169,0.574456,-166.625641,0.058486,0.000000
37.730003,18.123741,-166.670120,-0.002859,0.002291,0.058183,80.618423,4.106898,0.581829,-166.670120,0.059119,0.000000
38.110001,18.306946,-166.625641,-0.002815,0.002314,0.058781,81.433365,4.148413,0.587809,-166.625641,0.059751,0.000000
38.490002,18.695328,-166.714600,-0.002798,0.002344,0.059526,83.160973,4.236422,0.595258,-166.714600,0.060386,0.000000
38.870003,18.295029,-166.803574,-0.002759,0.002360,0.059942,81.380356,4.145713,0.599421,-166.803574,0.061019,0.000000
39.250000,18.658096,-166.759079,-0.002759,0.002386,0.060602,82.995354,4.227985,0.606022,-166.759079,0.061651,0.000000
39.630001,19.183510,-166.759079,-0.002712,0.002409,0.061200,85.332512,4.347045,0.612002,-166.759079,0.062284,0.000000
40.010002,19.551414,-166.759079,-0.002699,0.002439,0.061947,86.969032,4.430414,0.619466,-166.759079,0.062926,0.000000
40.390003,19.910011,-166.848053,-0.002669,0.002465,0.062614,88.564156,4.511673,0.626143,-166.848053,0.063559,0.000000
40.770000,19.816544,-166.937012,-0.002643,0.002484,0.063099,88.148392,4.490493,0.630987,-166.937012,0.064192,0.000000
41.150002,20.668533,-166.892532,-0.002617,0.002518,0.063959,91.938225,4.683557,0.639587,-166.892532,0.064825,0.000000
41.530003,21.091545,-166.937012,-0.002583,0.002545,0.064634,93.819878,4.779412,0.646339,-166.937012,0.065459,0.000000
41.910004,20.855835,-166.981491,-0.002578,0.002564,0.065120,92.771385,4.725999,0.651199,-166.981491,0.066092,0.000000
42.290001,21.299332,-166.981491,-0.002544,0.002591,0.065822,94.744156,4.826498,0.658224,-166.981491,0.066725,0.000000
42.670002,21.371941,-167.070450,-0.002505,0.002611,0.066325,95.067139,4.842951,0.663250,-167.070450,0.067358,0.000000
43.050003,21.338806,-167.114929,-0.002514,0.002627,0.066734,94.919754,4.835443,0.667338,-167.114929,0.067990,0.000000
43.430000,22.533371,-167.114929,-0.002483,0.002667,0.067748,100.233437,5.106135,0.677481,-167.114929,0.068623,0.000000
43.810001,22.612320,-167.114929,-0.002436,0.002690,0.068337,100.584625,5.124025,0.683370,-167.114929,0.069258,0.000000
44.190002,23.171249,-167.159409,-0.002432,0.002717,0.069023,103.070862,5.250680,0.690229,-167.159409,0.069890,0.000000
44.570004,23.170128,-167.248383,-0.002393,0.002737,0.069525,103.065880,5.250426,0.695255,-167.248383,0.070523,0.000000
44.950001,23.156357,-167.203888,-0.002393,0.002753,0.069925,103.004616,5.247305,0.699252,-167.203888,0.071156,0.000000
45.330002,24.518494,-167.292862,-0.002367,0.002791,0.070887,109.063705,5.555970,0.708865,-167.292862,0.071789,0.000000
45.710003,24.550888,-167.292862,-0.002337,0.002813,0.071459,109.207802,5.563311,0.714588,-167.292862,0.072422,0.000000
46.090004,25.037949,-167.292862,-0.002307,0.002840,0.072145,111.374359,5.673680,0.721446,-167.292862,0.073055,0.000000
46.470001,25.452400,-167.426300,-0.002276,0.002865,0.072761,113.217934,5.767596,0.727608,-167.426300,0.073689,0.000000
46.850002,25.292282,-167.381821,-0.002276,0.002881,0.073177,112.505692,5.731313,0.731772,-167.381821,0.074322,0.000000
47.230003,26.430252,-167.381821,-0.002255,0.002913,0.073983,117.567635,5.989181,0.739826,-167.381821,0.074955,0.000000
47.610001,26.955299,-167.470779,-0.002225,0.002940,0.074685,119.903160,6.108158,0.746851,-167.470779,0.075587,0.000000
47.990002,27.005196,-167.470779,-0.002203,0.002962,0.075241,120.125107,6.119464,0.752407,-167.470779,0.076220,0.000000
48.370003,27.594658,-167.604218,-0.002190,0.002985,0.075813,122.747169,6.253039,0.758130,-167.604218,0.076853,0.000000
48.750004,27.962189,-167.604218,-0.002164,0.003008,0.076403,124.382027,6.336322,0.764034,-167.604218,0.077487,0.000000
49.130001,28.601555,-167.559738,-0.002143,0.003035,0.077079,127.226067,6.481205,0.770786,-167.559738,0.078120,0.000000
49.510002,29.090851,-167.604218,-0.002113,0.003062,0.077781,129.402573,6.592081,0.777811,-167.604218,0.078753,0.000000
49.890003,29.658722,-167.648712,-0.002091,0.003084,0.078328,131.928589,6.720762,0.783276,-167.648712,0.079386,0.000000
50.270004,30.731529,-167.737671,-0.002065,0.003114,0.079091,136.700668,6.963864,0.790907,-167.737671,0.080019,0.000000
50.650002,30.942291,-167.737671,-0.002057,0.003134,0.079595,137.638184,7.011623,0.795948,-167.737671,0.080652,0.000000
51.030003,31.829651,-167.693192,-0.002044,0.003164,0.080358,141.585358,7.212702,0.803579,-167.693192,0.081293,0.000000
51.410004,32.148407,-167.782150,-0.002009,0.003187,0.080947,143.003250,7.284933,0.809468,-167.782150,0.081926,0.000000
51.790001,32.695419,-167.826630,-0.001983,0.003210,0.081528,145.436493,7.408888,0.815282,-167.826630,0.082561,0.000000
52.170002,33.340370,-167.826630,-0.001970,0.003233,0.082126,148.305374,7.555036,0.821262,-167.826630,0.083194,0.000000
52.550003,33.467346,-167.960068,-0.001944,0.003255,0.082682,148.870193,7.583809,0.826818,-167.960068,0.083826,0.000000
52.930004,35.080467,-167.915588,-0.001944,0.003287,0.083489,156.045715,7.949347,0.834887,-167.915588,0.084459,0.000000
53.310001,35.749619,-167.915588,-0.001906,0.003312,0.084122,159.022247,8.100980,0.841216,-167.915588,0.085092,0.000000
53.690002,36.368126,-168.004547,-0.001893,0.003338,0.084780,161.773499,8.241135,0.847801,-168.004547,0.085725,0.000000
54.070004,36.750183,-168.004547,-0.001858,0.003359,0.085308,163.472977,8.327710,0.853085,-168.004547,0.086359,0.000000
54.450001,37.248413,-168.049026,-0.001867,0.003381,0.085873,165.689209,8.440612,0.858732,-168.049026,0.086992,0.000000
54.830002,37.327728,-168.049026,-0.001837,0.003398,0.086297,166.042023,8.458584,0.862971,-168.049026,0.087625,0.000000
55.210003,39.808479,-168.049026,-0.001811,0.003438,0.087313,177.076965,9.020730,0.873130,-168.049026,0.088258,0.000000
55.590004,40.022217,-168.138000,-0.001794,0.003458,0.087841,178.027710,9.069164,0.878414,-168.138000,0.088891,0.000000
55.970001,40.585617,-168.226959,-0.001772,0.003481,0.088423,180.533844,9.196833,0.884227,-168.226959,0.089523,0.000000
56.350002,41.509850,-168.226959,-0.001768,0.003503,0.088969,184.645035,9.406266,0.889693,-168.226959,0.090156,0.000000
56.730003,41.845726,-168.182480,-0.001759,0.003520,0.089411,186.139084,9.482377,0.894113,-168.182480,0.090791,0.000000
57.110004,44.736084,-168.315918,-0.001712,0.003566,0.090582,198.996033,10.137341,0.905816,-168.315918,0.091423,0.000000
57.490002,44.888008,-168.271439,-0.001703,0.003585,0.091068,199.671829,10.171768,0.910676,-168.271439,0.092056,0.000000
57.870003,45.471519,-168.315918,-0.001677,0.003608,0.091640,202.267426,10.303993,0.916399,-168.315918,0.092689,0.000000
58.250004,46.322388,-168.360397,-0.001673,0.003629,0.092177,206.052277,10.496802,0.921773,-168.360397,0.093322,0.000000
58.630001,46.825089,-168.404877,-0.001673,0.003650,0.092698,208.288391,10.610717,0.926981,-168.404877,0.093955,0.000000
59.010002,48.591629,-168.360397,-0.001643,0.003681,0.093505,216.146362,11.011021,0.935051,-168.360397,0.094589,0.000000
59.390003,50.023773,-168.404877,-0.001634,0.003712,0.094276,222.516861,11.335549,0.942757,-168.404877,0.095222,0.000000
59.770004,50.353691,-168.493835,-0.001613,0.003726,0.094650,223.984406,11.410310,0.946496,-168.493835,0.095855,0.000000
60.150002,51.802223,-168.627289,-0.001600,0.003756,0.095404,230.427795,11.738552,0.954036,-168.627289,0.096488,0.000000
60.530003,51.910583,-168.538330,-0.001574,0.003770,0.095759,230.909805,11.763106,0.957594,-168.538330,0.097120,0.000000
60.910004,54.393188,-168.582809,-0.001574,0.003812,0.096825,241.952988,12.325672,0.968252,-168.582809,0.097753,0.000000
61.290005,55.540466,-168.582809,-0.001539,0.003836,0.097432,247.056335,12.585649,0.974323,-168.582809,0.098388,0.000000
61.670002,56.980431,-168.716248,-0.001522,0.003862,0.098092,253.461609,12.911950,0.980924,-168.716248,0.099020,0.000000
62.050003,57.547928,-168.716248,-0.001526,0.003881,0.098586,255.985962,13.040546,0.985859,-168.716248,0.099662,0.000000
62.430004,58.426353,-168.760727,-0.001518,0.003905,0.099176,259.893402,13.239601,0.991764,-168.760727,0.100295,0.000000
62.810001,60.925346,-168.805206,-0.001492,0.003939,0.100051,271.009491,13.805881,1.000514,-168.805206,0.100928,0.000000
63.190002,61.686104,-168.805206,-0.001483,0.003960,0.100572,274.393494,13.978271,1.005722,-168.805206,0.101561,0.000000
63.570004,62.183968,-168.849686,-0.001466,0.003983,0.101163,276.608093,14.091089,1.011627,-168.849686,0.102194,0.000000
63.950005,64.252121,-168.894165,-0.001444,0.004008,0.101803,285.807709,14.559738,1.018031,-168.894165,0.102827,0.000000
64.330002,64.887756,-168.894165,-0.001440,0.004025,0.102238,288.635162,14.703775,1.022376,-168.894165,0.103461,0.000000
64.710007,65.892792,-168.938660,-0.001414,0.004040,0.102628,293.105774,14.931520,1.026282,-168.938660,0.018014,0.000000
65.090004,65.783691,-168.938660,-0.001418,0.004054,0.102966,292.620483,14.906797,1.029658,-168.938660,294.500458,0.000000
65.470001,64.922760,-168.983139,-0.001406,0.004054,0.102966,288.790863,14.711707,1.029658,-168.983139,294.500458,0.000000
65.850006,65.731934,-169.027618,-0.001401,0.004061,0.103147,292.390259,14.895069,1.031475,-169.027618,294.500458,0.000000
66.230003,64.853134,-169.072098,-0.001393,0.004062,0.103175,288.481140,14.695930,1.031747,-169.072098,294.500458,0.000000
66.610001,65.750916,-169.116577,-0.001388,0.004073,0.103461,292.474670,14.899371,1.034609,-169.116577,294.500458,0.000000
66.990005,64.982712,-169.161057,-0.001371,0.004073,0.103461,289.057526,14.725293,1.034609,-169.161057,294.500458,0.000000
67.370003,65.985138,-169.116577,-0.001362,0.004089,0.103859,293.516541,14.952446,1.038590,-169.116577,294.500458,0.000000
67.750000,65.329391,-169.161057,-0.001362,0.004089,0.103859,290.599640,14.803851,1.038590,-169.161057,294.500458,0.000000
68.130005,65.762100,-169.250015,-0.001362,0.004107,0.104327,292.524445,14.901905,1.043268,-169.250015,294.500458,0.000000
68.510002,65.327911,-169.250015,-0.001367,0.004107,0.104327,290.593048,14.803516,1.043268,-169.250015,294.500458,0.000000
68.890007,64.947708,-169.250015,-0.001362,0.004107,0.104327,288.901825,14.717361,1.043268,-169.250015,294.500458,0.000000
69.270004,66.670685,-169.294495,-0.001354,0.004081,0.103659,296.566010,15.107793,1.036592,-169.294495,294.500458,0.000000
69.650002,66.121811,-169.383469,-0.001345,0.004072,0.103417,294.124512,14.983417,1.034170,-169.383469,294.500458,0.000000
70.030006,65.782578,-169.427948,-0.001341,0.004079,0.103617,292.615509,14.906546,1.036168,-169.427948,294.500458,0.000000
70.410004,65.358063,-169.427948,-0.001332,0.004093,0.103973,290.727173,14.810349,1.039726,-169.427948,294.500458,0.000000
70.790001,65.265350,-169.427948,-0.001332,0.004123,0.104717,290.314789,14.789339,1.047174,-169.427948,294.500458,0.000000
71.170006,65.270187,-169.472427,-0.001324,0.004128,0.104848,290.336304,14.790436,1.048476,-169.472427,294.500458,0.000000
71.550003,65.209122,-169.516907,-0.001319,0.004131,0.104926,290.064667,14.776598,1.049264,-169.516907,294.500458,0.000000
71.930000,65.288055,-169.561386,-0.001328,0.004135,0.105022,290.415771,14.794485,1.050218,-169.561386,294.500458,0.000000
72.310005,65.055710,-169.605865,-0.001337,0.004135,0.105029,289.382263,14.741835,1.050293,-169.605865,294.500458,0.000000
72.690002,65.036346,-169.561386,-0.001332,0.004137,0.105090,289.296112,14.737447,1.050899,-169.561386,294.500458,0.000000
73.070000,64.932816,-169.650345,-0.001328,0.004139,0.105134,288.835602,14.713986,1.051338,-169.650345,294.500458,0.000000
73.450005,65.623566,-169.650345,-0.001319,0.004149,0.105376,291.908203,14.870512,1.053760,-169.650345,294.500458,0.000000
73.830002,65.477966,-169.739304,-0.001337,0.004149,0.105376,291.260529,14.837520,1.053760,-169.739304,294.500458,0.000000
74.210007,65.281357,-169.694824,-0.001337,0.004149,0.105376,290.385986,14.792967,1.053760,-169.694824,294.500458,0.000000
74.590004,65.089218,-169.739304,-0.001319,0.004149,0.105376,289.531311,14.749428,1.053760,-169.739304,294.500458,0.000000
74.970001,64.908981,-169.828278,-0.001311,0.004150,0.105411,288.729584,14.708586,1.054108,-169.828278,294.500458,0.000000
75.350006,65.003204,-169.872757,-0.001332,0.004153,0.105480,289.148682,14.729937,1.054805,-169.872757,294.500458,0.000000
75.730003,64.930588,-169.961716,-0.001315,0.004155,0.105541,288.825684,14.713481,1.055410,-169.961716,294.500458,0.000000
76.110001,65.040436,-169.917236,-0.001328,0.004157,0.105576,289.314301,14.738373,1.055759,-169.917236,294.500458,0.000000
76.490005,64.940643,-169.872757,-0.001319,0.004159,0.105636,288.870422,14.715760,1.056364,-169.872757,294.500458,0.000000
76.870003,64.968933,-169.961716,-0.001306,0.004159,0.105636,288.996246,14.722170,1.056364,-169.961716,294.500458,0.000000
77.250000,66.206329,-170.006195,-0.001315,0.004173,0.106001,294.500458,15.002569,1.060013,-170.006195,294.500458,0.000000
77.630005,65.968384,-170.006195,-0.001302,0.004167,0.105854,293.442017,14.948649,1.058544,-170.006195,294.500458,0.000000
78.010002,65.828369,-170.050674,-0.001311,0.004167,0.105854,292.819214,14.916922,1.058544,-170.050674,294.500458,0.000000
78.390007,65.626556,-170.095154,-0.001302,0.004167,0.105854,291.921509,14.871190,1.058544,-170.095154,294.500458,0.000000
78.770004,65.498459,-170.095154,-0.001298,0.004167,0.105854,291.351685,14.842163,1.058544,-170.095154,294.500458,0.000000
79.150002,65.332748,-170.139633,-0.001285,0.004167,0.105854,290.614594,14.804612,1.058544,-170.139633,294.500458,0.000000
79.530006,65.197205,-170.273087,-0.001306,0.004167,0.105854,290.011658,14.773898,1.058544,-170.273087,294.500458,0.000000
79.910004,65.749435,-170.273087,-0.001306,0.004178,0.106122,292.468109,14.899035,1.061224,-170.273087,294.500458,0.000000
80.290001,65.679794,-170.273087,-0.001293,0.004178,0.106122,292.158325,14.883254,1.061224,-170.273087,294.500458,0.000000
80.670006,65.606445,-170.228607,-0.001302,0.004178,0.106122,291.832031,14.866633,1.061224,-170.228607,294.500458,0.000000
81.050003,65.534195,-170.317566,-0.001302,0.004178,0.106122,291.510651,14.850261,1.061224,-170.317566,294.500458,0.000000
81.430000,65.414291,-170.362045,-0.001293,0.004178,0.106122,290.977295,14.823091,1.061224,-170.362045,294.500458,0.000000
81.810005,65.318604,-170.406525,-0.001302,0.004179,0.106141,290.551666,14.801407,1.061406,-170.406525,294.500458,0.000000
82.190002,65.358810,-170.451004,-0.001306,0.004183,0.106236,290.730499,14.810518,1.062359,-170.451004,294.500458,0.000000
82.570007,65.398285,-170.451004,-0.001298,0.004183,0.106236,290.906097,14.819464,1.062359,-170.451004,294.500458,0.000000
82.950005,65.337585,-170.495483,-0.001298,0.004183,0.106236,290.636108,14.805709,1.062359,-170.495483,294.500458,0.000000
83.330002,65.329773,-170.495483,-0.001306,0.004184,0.106269,290.601349,14.803939,1.062693,-170.495483,294.500458,0.000000
83.710007,65.284714,-170.584442,-0.001293,0.004184,0.106269,290.400909,14.793728,1.062693,-170.584442,294.500458,0.000000
84.090004,65.378922,-170.584442,-0.001293,0.004187,0.106348,290.819977,14.815075,1.063480,-170.584442,294.500458,0.000000
84.470001,65.351364,-170.628922,-0.001289,0.004187,0.106348,290.697388,14.808831,1.063480,-170.628922,294.500458,0.000000
84.850006,65.304825,-170.628922,-0.001289,0.004187,0.106348,290.490356,14.798285,1.063480,-170.628922,294.500458,0.000000
85.230003,65.313019,-170.673416,-0.001293,0.004189,0.106399,290.526825,14.800141,1.063995,-170.673416,294.500458,0.000000
85.610001,65.293274,-170.762375,-0.001293,0.004189,0.106399,290.438995,14.795667,1.063995,-170.762375,294.500458,0.000000
85.990005,65.234436,-170.762375,-0.001306,0.004189,0.106399,290.177277,14.782334,1.063995,-170.762375,294.500458,0.000000
86.370003,65.273163,-170.717896,-0.001285,0.004191,0.106452,290.349518,14.791110,1.064524,-170.717896,294.500458,0.000000
86.750008,65.270187,-170.806854,-0.001293,0.004192,0.106469,290.336304,14.790436,1.064691,-170.806854,294.500458,0.000000
87.130005,65.228485,-170.940292,-0.001293,0.004192,0.106469,290.150787,14.780987,1.064691,-170.940292,294.500458,0.000000
87.510002,65.187897,-170.984772,-0.001293,0.004193,0.106504,289.970245,14.771788,1.065039,-170.984772,294.500458,0.000000
87.890007,65.679047,-170.984772,-0.001293,0.004199,0.106643,292.154999,14.883085,1.066432,-170.984772,294.500458,0.000000
88.270004,65.665283,-170.984772,-0.001293,0.004199,0.106643,292.093781,14.879966,1.066432,-170.984772,294.500458,0.000000
88.650002,65.627670,-170.895813,-0.001289,0.004199,0.106643,291.926453,14.871443,1.066432,-170.895813,294.500458,0.000000
89.030006,65.586700,-171.029251,-0.001281,0.004199,0.106643,291.744202,14.862159,1.066432,-171.029251,294.500458,0.000000
89.410004,65.545746,-171.073730,-0.001281,0.004199,0.106652,291.562042,14.852879,1.066523,-171.073730,294.500458,0.000000
89.790001,65.468292,-171.118225,-0.001293,0.004199,0.106652,291.217499,14.835327,1.066523,-171.118225,294.500458,0.000000
90.170006,65.378922,-171.118225,-0.001281,0.004199,0.106652,290.819977,14.815075,1.066523,-171.118225,294.500458,0.000000
90.550003,65.383759,-171.118225,-0.001276,0.004200,0.106678,290.841492,14.816172,1.066780,-171.118225,294.500458,0.000000
90.930008,65.332001,-171.162704,-0.001285,0.004200,0.106686,290.611267,14.804443,1.066856,-171.162704,294.500458,0.000000
91.310005,65.296249,-171.251663,-0.001298,0.004200,0.106686,290.452209,14.796342,1.066856,-171.251663,294.500458,0.000000
91.690002,65.243744,-171.296143,-0.001289,0.004202,0.106720,290.218658,14.784444,1.067204,-171.296143,294.500458,0.000000
92.070007,65.561752,-171.251663,-0.001293,0.004205,0.106816,291.633240,14.856505,1.068158,-171.251663,294.500458,0.000000
92.450005,65.557281,-171.296143,-0.001276,0.004205,0.106816,291.613342,14.855493,1.068158,-171.296143,294.500458,0.000000
92.830002,65.515579,-171.385101,-0.001272,0.004205,0.106816,291.427856,14.846043,1.068158,-171.385101,294.500458,0.000000
93.210007,65.494354,-171.429581,-0.001281,0.004205,0.106816,291.333435,14.841232,1.068158,-171.429581,294.500458,0.000000
93.590004,65.394928,-171.429581,-0.001281,0.004205,0.106816,290.891174,14.818703,1.068158,-171.429581,294.500458,0.000000
93.970001,65.371109,-171.429581,-0.001276,0.004205,0.106816,290.785217,14.813306,1.068158,-171.429581,294.500458,0.000000
94.350006,65.319336,-171.474060,-0.001289,0.004205,0.106816,290.554932,14.801573,1.068158,-171.474060,294.500458,0.000000
94.730003,65.283600,-171.518555,-0.001285,0.004206,0.106834,290.395966,14.793475,1.068340,-171.518555,294.500458,0.000000
95.110008,65.280991,-171.563034,-0.001289,0.004207,0.106860,290.384338,14.792884,1.068597,-171.563034,294.500458,0.000000
95.490005,65.265717,-171.607513,-0.001281,0.004207,0.106860,290.316406,14.789423,1.068597,-171.607513,294.500458,0.000000
95.870003,65.252319,-171.607513,-0.001281,0.004207,0.106869,290.256805,14.786387,1.068688,-171.607513,294.500458,0.000000
96.250008,65.251572,-171.607513,-0.001285,0.004209,0.106904,290.253479,14.786218,1.069036,-171.607513,294.500458,0.000000
96.630005,65.257904,-171.696472,-0.001268,0.004209,0.106911,290.281647,14.787653,1.069112,-171.696472,294.500458,0.000000
97.010002,65.230713,-171.740952,-0.001263,0.004209,0.106911,290.160706,14.781491,1.069112,-171.740952,294.500458,0.000000
97.390007,65.238907,-171.740952,-0.001281,0.004210,0.106946,290.197144,14.783348,1.069460,-171.740952,294.500458,0.000000
97.770004,65.246353,-171.829910,-0.001289,0.004211,0.106955,290.230286,14.785034,1.069551,-171.829910,294.500458,0.000000
98.150002,65.240768,-171.829910,-0.001285,0.004211,0.106955,290.205444,14.783769,1.069551,-171.829910,294.500458,0.000000
98.530006,65.239655,-171.785431,-0.001263,0.004211,0.106964,290.200470,14.783518,1.069642,-171.785431,294.500458,0.000000
98.910004,65.260513,-171.874390,-0.001281,0.004213,0.106999,290.293274,14.788243,1.069990,-171.874390,294.500458,0.000000
99.290001,65.255661,-171.918869,-0.001272,0.004213,0.106999,290.271667,14.787145,1.069990,-171.918869,294.500458,0.000000
99.670006,65.247101,-171.918869,-0.001272,0.004213,0.107016,290.233612,14.785204,1.070156,-171.918869,294.500458,0.000000
100.050003,65.227737,-171.963364,-0.001285,0.004213,0.107016,290.147461,14.780817,1.070156,-171.963364,294.500458,0.000000
100.430008,65.186783,-172.007843,-0.001285,0.004213,0.107016,289.965302,14.771536,1.070156,-172.007843,294.500458,0.000000
100.810005,65.350616,-172.007843,-0.001263,0.004217,0.107111,290.694061,14.808661,1.071110,-172.007843,294.500458,0.000000
101.190002,65.385620,-172.052322,-0.001268,0.004217,0.107111,290.849762,14.816593,1.071110,-172.052322,294.500458,0.000000
101.570007,65.362534,-172.096802,-0.001272,0.004217,0.107111,290.747070,14.811362,1.071110,-172.096802,294.500458,0.000000
101.950005,65.343170,-172.096802,-0.001285,0.004217,0.107111,290.660950,14.806974,1.071110,-172.096802,294.500458,0.000000
102.330002,65.323059,-172.141281,-0.001281,0.004217,0.107111,290.571472,14.802417,1.071110,-172.141281,294.500458,0.000000
102.710007,65.302582,-172.141281,-0.001276,0.004217,0.107111,290.480377,14.797776,1.071110,-172.141281,294.500458,0.000000
103.090004,65.273163,-172.274719,-0.001272,0.004217,0.107111,290.349518,14.791110,1.071110,-172.274719,294.500458,0.000000
103.470001,65.240021,-172.274719,-0.001285,0.004218,0.107129,290.202118,14.783600,1.071292,-172.274719,294.500458,0.000000
103.850006,65.225876,-172.274719,-0.001272,0.004218,0.107129,290.139191,14.780395,1.071292,-172.274719,294.500458,0.000000
104.230003,65.206146,-172.230240,-0.001259,0.004218,0.107146,290.051422,14.775925,1.071458,-172.230240,294.500458,0.000000
104.610008,65.187149,-172.319199,-0.001259,0.004218,0.107146,289.966919,14.771620,1.071458,-172.319199,294.500458,0.000000
104.990005,65.156616,-172.319199,-0.001263,0.004218,0.107146,289.831116,14.764701,1.071458,-172.319199,294.500458,0.000000
105.370003,65.257904,-172.408173,-0.001272,0.004221,0.107225,290.281647,14.787653,1.072246,-172.408173,294.500458,0.000000
105.750008,65.307053,-172.452652,-0.001272,0.004221,0.107225,290.500275,14.798789,1.072246,-172.452652,294.500458,0.000000
106.130005,65.293655,-172.452652,-0.001285,0.004221,0.107225,290.440674,14.795754,1.072246,-172.452652,294.500458,0.000000
106.510002,65.274658,-172.497131,-0.001268,0.004221,0.107225,290.356171,14.791450,1.072246,-172.497131,294.500458,0.000000
106.890007,65.260880,-172.541611,-0.001263,0.004221,0.107225,290.294891,14.788326,1.072246,-172.541611,294.500458,0.000000
107.270004,65.233704,-172.541611,-0.001255,0.004222,0.107232,290.174011,14.782168,1.072321,-172.541611,294.500458,0.000000
107.650002,65.220657,-172.630569,-0.001268,0.004222,0.107241,290.115967,14.779213,1.072412,-172.630569,294.500458,0.000000
108.030006,65.200180,-172.630569,-0.001272,0.004222,0.107241,290.024872,14.774571,1.072412,-172.630569,294.500458,0.000000
108.410004,65.181198,-172.630569,-0.001263,0.004222,0.107241,289.940460,14.770271,1.072412,-172.630569,294.500458,0.000000
108.790009,65.163315,-172.675049,-0.001263,0.004223,0.107276,289.860901,14.766218,1.072760,-172.675049,294.500458,0.000000
109.170006,65.175613,-172.764008,-0.001272,0.004223,0.107276,289.915619,14.769006,1.072760,-172.764008,294.500458,0.000000
109.550003,65.148788,-172.764008,-0.001281,0.004223,0.107276,289.796295,14.762927,1.072760,-172.764008,294.500458,0.000000
109.930008,65.133530,-172.764008,-0.001272,0.004223,0.107276,289.728424,14.759469,1.072760,-172.764008,294.500458,0.000000
110.310005,65.112305,-172.808502,-0.001272,0.004224,0.107285,289.634003,14.754659,1.072851,-172.808502,294.500458,0.000000
110.690002,65.098892,-172.852982,-0.001259,0.004224,0.107285,289.574341,14.751619,1.072851,-172.852982,294.500458,0.000000
111.070007,65.085861,-172.941940,-0.001272,0.004225,0.107311,289.516357,14.748668,1.073109,-172.941940,294.500458,0.000000
111.450005,65.496597,-172.897461,-0.001263,0.004230,0.107450,291.343414,14.841741,1.074501,-172.897461,294.500458,0.000000
111.830002,65.542023,-172.852982,-0.001259,0.004230,0.107441,291.545471,14.852035,1.074411,-172.852982,294.500458,0.000000
112.210007,65.553192,-172.941940,-0.001285,0.004230,0.107441,291.595154,14.854566,1.074411,-172.941940,294.500458,0.000000
112.590004,65.556915,-172.986420,-0.001272,0.004230,0.107441,291.611725,14.855410,1.074411,-172.986420,294.500458,0.000000
112.970009,65.553940,-173.075378,-0.001272,0.004230,0.107441,291.598480,14.854734,1.074411,-173.075378,294.500458,0.000000
113.350006,65.526016,-173.075378,-0.001276,0.004230,0.107441,291.474274,14.848407,1.074411,-173.075378,294.500458,0.000000
113.730003,65.505524,-173.119858,-0.001255,0.004230,0.107441,291.383118,14.843763,1.074411,-173.119858,294.500458,0.000000
114.110008,65.498459,-173.119858,-0.001268,0.004230,0.107441,291.351685,14.842163,1.074411,-173.119858,294.500458,0.000000
114.490005,65.457870,-173.164337,-0.001272,0.004230,0.107441,291.171143,14.832966,1.074411,-173.164337,294.500458,0.000000
114.870003,65.430313,-173.164337,-0.001255,0.004230,0.107441,291.048584,14.826720,1.074411,-173.164337,294.500458,0.000000
115.250008,65.385620,-173.253311,-0.001285,0.004230,0.107450,290.849762,14.816593,1.074501,-173.253311,294.500458,0.000000
115.630005,65.364777,-173.253311,-0.001272,0.004230,0.107450,290.757050,14.811871,1.074501,-173.253311,294.500458,0.000000
116.010002,65.367371,-173.253311,-0.001268,0.004231,0.107458,290.768585,14.812458,1.074577,-173.253311,294.500458,0.000000
116.390007,65.333496,-173.342270,-0.001259,0.004231,0.107458,290.617920,14.804782,1.074577,-173.342270,294.500458,0.000000
116.770004,65.304825,-173.342270,-0.001268,0.004231,0.107458,290.490356,14.798285,1.074577,-173.342270,294.500458,0.000000
117.150009,65.287323,-173.431229,-0.001250,0.004231,0.107458,290.412506,14.794319,1.074577,-173.431229,294.500458,0.000000
117.530006,65.277267,-173.475708,-0.001272,0.004231,0.107458,290.367798,14.792040,1.074577,-173.475708,294.500458,0.000000
117.910004,65.258652,-173.431229,-0.001276,0.004231,0.107467,290.284973,14.787822,1.074668,-173.431229,294.500458,0.000000
118.290009,65.264969,-173.475708,-0.001268,0.004232,0.107493,290.313080,14.789253,1.074925,-173.475708,294.500458,0.000000
118.670006,65.274292,-173.520187,-0.001263,0.004232,0.107493,290.354553,14.791366,1.074925,-173.520187,294.500458,0.000000
119.050003,65.253067,-173.609146,-0.001268,0.004232,0.107493,290.260132,14.786556,1.074925,-173.609146,294.500458,0.000000
119.430008,65.224014,-173.564667,-0.001259,0.004232,0.107493,290.130920,14.779973,1.074925,-173.564667,294.500458,0.000000
119.810005,65.219177,-173.609146,-0.001255,0.004232,0.107493,290.109375,14.778876,1.074925,-173.609146,294.500458,0.000000
120.190002,65.193481,-173.653625,-0.001272,0.004232,0.107493,289.995087,14.773054,1.074925,-173.653625,294.500458,0.000000
120.570007,65.471649,-173.742599,-0.001255,0.004237,0.107632,291.232452,14.836088,1.076318,-173.742599,294.500458,0.000000
120.950005,65.528992,-173.787079,-0.001272,0.004237,0.107623,291.487518,14.849082,1.076227,-173.787079,294.500458,0.000000
121.330009,65.536804,-173.831558,-0.001268,0.004237,0.107623,291.522278,14.850852,1.076227,-173.831558,294.500458,0.000000
121.710007,65.534943,-173.787079,-0.001259,0.004237,0.107623,291.513977,14.850430,1.076227,-173.787079,294.500458,0.000000
122.090004,65.515213,-173.787079,-0.001272,0.004237,0.107623,291.426208,14.845960,1.076227,-173.787079,294.500458,0.000000
122.470009,65.516693,-173.876038,-0.001250,0.004237,0.107623,291.432800,14.846294,1.076227,-173.876038,294.500458,0.000000
122.850006,65.500687,-173.920517,-0.001255,0.004237,0.107623,291.361603,14.842668,1.076227,-173.920517,294.500458,0.000000
123.230003,65.488022,-173.920517,-0.001250,0.004237,0.107623,291.305267,14.839798,1.076227,-173.920517,294.500458,0.000000
123.610008,65.470154,-173.964996,-0.001272,0.004237,0.107623,291.225800,14.835750,1.076227,-173.964996,294.500458,0.000000
123.990005,65.418015,-174.009476,-0.001268,0.004237,0.107623,290.993866,14.823934,1.076227,-174.009476,294.500458,0.000000
124.370003,65.402008,-174.009476,-0.001263,0.004237,0.107623,290.922668,14.820307,1.076227,-174.009476,294.500458,0.000000
124.750008,65.370361,-174.098450,-0.001250,0.004237,0.107623,290.781891,14.813136,1.076227,-174.098450,294.500458,0.000000
125.130005,65.349884,-174.142929,-0.001263,0.004237,0.107623,290.690796,14.808496,1.076227,-174.142929,1681.640747,0.000000
125.510010,65.322693,-174.053955,-0.001259,0.004229,0.107423,290.569855,14.802334,1.074229,-174.053955,0.107388,0.000000
125.890007,65.244492,-174.142929,-0.001255,0.004217,0.107111,290.221985,14.784614,1.071110,-174.142929,0.106755,0.000000
126.270004,65.142471,-174.142929,-0.001259,0.004195,0.106557,289.768188,14.761495,1.065569,-174.142929,0.106122,0.000000
126.650009,65.061295,-174.187408,-0.001259,0.004175,0.106036,289.407104,14.743100,1.060361,-174.187408,0.105480,0.000000
127.030006,65.040802,-174.276367,-0.001246,0.004156,0.105568,289.315948,14.738456,1.055683,-174.276367,0.104848,0.000000
127.410004,65.027023,-174.320847,-0.001263,0.004119,0.104631,289.254639,14.735333,1.046311,-174.320847,0.104215,0.000000
127.790009,64.964844,-174.276367,-0.001255,0.004098,0.104101,288.978058,14.721244,1.041013,-174.276367,0.103582,0.000000
128.170013,64.895950,-174.365326,-0.001250,0.004073,0.103443,288.671600,14.705633,1.034427,-174.365326,0.102949,0.000000
128.550003,64.880692,-174.365326,-0.001237,0.004049,0.102854,288.603729,14.702175,1.028538,-174.365326,0.102315,0.000000
128.930008,64.814026,-174.409805,-0.001233,0.004031,0.102384,288.307190,14.687069,1.023844,-174.409805,0.101682,0.000000
129.310013,64.648331,-174.498764,-0.001250,0.003999,0.101587,287.570129,14.649521,1.015866,-174.498764,0.101049,0.000000
129.690002,64.358994,-174.454285,-0.001237,0.003979,0.101075,286.283112,14.583957,1.010749,-174.454285,0.100416,0.000000
130.070007,63.865234,-174.498764,-0.001237,0.003961,0.100598,284.086761,14.472069,1.005980,-174.498764,0.099783,0.000000
130.450012,62.825562,-174.498764,-0.001212,0.003940,0.100079,279.462067,14.236476,1.000787,-174.498764,0.099151,0.000000
130.830002,61.430283,-174.632217,-0.001194,0.003915,0.099444,273.255554,13.920301,0.994443,-174.632217,0.098516,0.000000
131.210007,59.326378,-174.632217,-0.001203,0.003884,0.098665,263.896912,13.443549,0.986646,-174.632217,0.097883,0.000000
131.590012,57.607880,-174.632217,-0.001194,0.003864,0.098144,256.252655,13.054132,0.981438,-174.632217,0.097251,0.000000
131.970001,55.940399,-174.587738,-0.001190,0.003843,0.097615,248.835327,12.676275,0.976155,-174.587738,0.096618,0.000000
132.350006,52.934608,-174.632217,-0.001199,0.003814,0.096887,235.464905,11.995153,0.968873,-174.632217,0.095985,0.000000
132.730011,50.658669,-174.721176,-0.001194,0.003792,0.096323,225.341019,11.479419,0.963225,-174.721176,0.095352,0.000000
133.110001,47.883743,-174.810135,-0.001199,0.003763,0.095569,212.997528,10.850612,0.955686,-174.810135,0.094719,0.000000
133.490005,45.054085,-174.810135,-0.001203,0.003741,0.095013,200.410583,10.209401,0.950130,-174.810135,0.094085,0.000000
133.870010,42.731232,-174.810135,-0.001203,0.003718,0.094432,190.078018,9.683036,0.944316,-174.810135,0.093452,0.000000
134.250000,39.445412,-174.810135,-0.001181,0.003687,0.093661,175.461960,8.938457,0.936610,-174.810135,0.092819,0.000000
134.630005,37.043236,-174.899094,-0.001199,0.003666,0.093124,164.776535,8.394117,0.931236,-174.899094,0.092186,0.000000
135.010010,35.002640,-174.943573,-0.001199,0.003646,0.092619,155.699524,7.931711,0.926194,-174.943573,0.091554,0.000000
135.389999,31.926842,-174.899094,-0.001181,0.003615,0.091814,142.017685,7.234726,0.918140,-174.899094,0.090921,0.000000
135.770004,29.416306,-174.899094,-0.001199,0.003595,0.091319,130.850266,6.665830,0.913189,-174.899094,0.090286,0.000000
136.150009,26.365456,-174.988068,-0.001186,0.003566,0.090565,117.279404,5.974497,0.905650,-174.988068,0.089654,0.000000
136.530014,23.936104,-175.077026,-0.001203,0.003541,0.089940,106.473106,5.423999,0.899397,-175.077026,0.089021,0.000000
136.910004,22.051895,-175.077026,-0.001186,0.003525,0.089532,98.091728,4.997031,0.895324,-175.077026,0.088388,0.000000
137.290009,18.707993,-175.121506,-0.001207,0.003494,0.088753,83.217308,4.239292,0.887528,-175.121506,0.087755,0.000000
137.670013,16.152397,-175.077026,-0.001203,0.003472,0.088179,71.849449,3.660186,0.881790,-175.077026,0.087113,0.000000
138.050003,15.192421,-175.121506,-0.001186,0.003463,0.087972,67.579262,3.442652,0.879716,-175.121506,0.086480,0.000000
138.430008,10.796570,-175.210464,-0.001207,0.003420,0.086871,48.025539,2.446538,0.868709,-175.210464,0.085847,0.000000
138.810013,8.302040,-175.210464,-0.001186,0.003397,0.086280,36.929317,1.881269,0.862805,-175.210464,0.085213,0.000000
139.190002,5.416901,-175.254944,-0.001207,0.003369,0.085569,24.095577,1.227487,0.855689,-175.254944,0.084580,0.000000
139.570007,3.296616,-175.299423,-0.001190,0.003348,0.085050,14.664079,0.747024,0.850496,-175.299423,0.083947,0.000000
139.950012,0.094955,-175.299423,-0.001186,0.003315,0.084208,0.422383,0.021517,0.842079,-175.299423,0.083315,0.000000
140.330002,-1.610512,-175.432877,-0.001203,0.003297,0.083740,-7.163914,-0.364947,0.837400,-175.432877,0.082682,0.000000
140.710007,-0.275558,-175.432877,-0.001194,0.003273,0.083124,-1.225745,-0.062442,0.831239,-175.432877,0.082049,0.000000
141.090012,-0.004845,-175.432877,-0.001194,0.003241,0.082326,-0.021550,-0.001098,0.823260,-175.432877,0.081415,0.000000
141.470001,-0.001488,-175.432877,-0.001212,0.003220,0.081789,-0.006618,-0.000337,0.817886,-175.432877,0.080782,0.000000
141.850006,-0.022713,-175.521835,-0.001203,0.003191,0.081051,-0.101031,-0.005147,0.810513,-175.521835,0.080149,0.000000
142.230011,-0.049156,-175.521835,-0.001203,0.003170,0.080514,-0.218658,-0.011139,0.805138,-175.521835,0.079516,0.000000
142.610001,-0.072983,-175.566315,-0.001203,0.003141,0.079793,-0.324644,-0.016538,0.797932,-175.566315,0.078883,0.000000
142.990005,-0.074478,-175.655273,-0.001216,0.003116,0.079151,-0.331295,-0.016877,0.791512,-175.655273,0.078250,0.000000
143.370010,-0.095329,-175.610794,-0.001224,0.003093,0.078562,-0.424046,-0.021602,0.785623,-175.610794,0.077618,0.000000
143.750000,-0.112457,-175.610794,-0.001237,0.003065,0.077851,-0.500235,-0.025483,0.778507,-175.610794,0.076983,0.000000
144.130005,-0.108734,-175.610794,-0.001242,0.003049,0.077453,-0.483674,-0.024640,0.774526,-175.610794,0.076350,0.000000
144.510010,-0.098679,-175.699753,-0.001285,0.003025,0.076827,-0.438944,-0.022361,0.768273,-175.699753,0.075718,0.000000
144.889999,-0.126236,-175.744232,-0.001362,0.002986,0.075839,-0.561526,-0.028605,0.758387,-175.744232,0.075085,0.000000
145.270004,-0.105011,-175.788712,-0.001384,0.002966,0.075345,-0.467112,-0.023796,0.753451,-175.788712,0.074452,0.000000
145.650009,-0.122513,-175.788712,-0.001401,0.002947,0.074850,-0.544964,-0.027762,0.748501,-175.788712,0.073819,0.000000
146.030014,-0.111343,-175.833206,-0.001431,0.002925,0.074296,-0.495280,-0.025231,0.742960,-175.833206,0.073185,0.000000
146.410004,-0.151558,-175.922165,-0.001470,0.002899,0.073636,-0.674163,-0.034344,0.736359,-175.922165,0.072552,0.000000
146.790009,-0.154533,-175.966644,-0.001522,0.002864,0.072743,-0.687399,-0.035018,0.727427,-175.966644,0.071919,0.000000
147.170013,-0.144112,-175.966644,-0.001544,0.002841,0.072154,-0.641041,-0.032656,0.721537,-175.966644,0.071286,0.000000
147.550003,-0.166451,-175.922165,-0.001561,0.002823,0.071693,-0.740409,-0.037718,0.716935,-175.922165,0.070653,0.000000
147.930008,-0.155281,-175.922165,-0.001582,0.002795,0.070982,-0.690725,-0.035187,0.709819,-175.922165,0.070021,0.000000
148.310013,-0.186188,-176.100082,-0.001638,0.002773,0.070428,-0.828204,-0.042191,0.704278,-176.100082,0.069379,0.000000
148.690002,-0.190285,-176.100082,-0.001651,0.002753,0.069933,-0.846429,-0.043119,0.699327,-176.100082,0.068746,0.000000
149.070007,-0.148949,-176.100082,-0.001694,0.002714,0.068944,-0.662557,-0.033752,0.689441,-176.100082,0.068111,0.000000
149.450012,-0.152672,-176.100082,-0.001707,0.002694,0.068432,-0.679118,-0.034596,0.684324,-176.100082,0.067479,0.000000
149.830002,-0.191399,-176.189041,-0.001746,0.002671,0.067843,-0.851384,-0.043372,0.678435,-176.189041,0.066846,0.000000
150.210007,-0.188423,-176.189041,-0.001750,0.002646,0.067202,-0.838148,-0.042697,0.672016,-176.189041,0.066213,0.000000
150.590012,-0.150436,-176.233521,-0.001802,0.002614,0.066386,-0.669175,-0.034089,0.663855,-176.233521,0.065580,0.000000
150.970001,-0.141502,-176.233521,-0.001837,0.002591,0.065822,-0.629434,-0.032065,0.658224,-176.233521,0.064947,0.000000
151.350006,-0.151932,-176.233521,-0.001832,0.002570,0.065276,-0.675826,-0.034428,0.652758,-176.233521,0.064313,0.000000
151.730011,-0.150810,-176.278015,-0.001858,0.002544,0.064617,-0.670837,-0.034174,0.646172,-176.278015,0.063680,0.000000
152.110001,-0.163101,-176.322495,-0.001897,0.002521,0.064045,-0.725510,-0.036959,0.640450,-176.322495,0.063047,0.000000
152.490005,-0.169060,-176.455933,-0.001910,0.002494,0.063359,-0.752015,-0.038309,0.633591,-176.455933,0.062414,0.000000
152.870010,-0.144112,-176.411453,-0.001949,0.002466,0.062649,-0.641041,-0.032656,0.626491,-176.411453,0.061782,0.000000
153.250000,-0.156395,-176.411453,-0.001983,0.002449,0.062198,-0.695680,-0.035440,0.621979,-176.411453,0.061149,0.000000
153.630005,-0.147087,-176.411453,-0.002005,0.002416,0.061374,-0.654276,-0.033330,0.613743,-176.411453,0.060514,0.000000
154.010010,-0.130333,-176.500412,-0.002035,0.002394,0.060802,-0.579750,-0.029534,0.608021,-176.500412,0.059882,0.000000
154.390015,-0.175758,-176.455933,-0.002048,0.002374,0.060290,-0.781812,-0.039827,0.602903,-176.455933,0.059249,0.000000
154.770004,-0.158630,-176.544891,-0.002095,0.002342,0.059474,-0.705623,-0.035946,0.594743,-176.544891,0.058616,0.000000
155.150009,-0.175392,-176.544891,-0.002108,0.002324,0.059023,-0.780183,-0.039744,0.590232,-176.544891,0.057983,0.000000
155.530014,-0.142990,-176.544891,-0.002126,0.002293,0.058251,-0.636052,-0.032402,0.582510,-176.544891,0.057350,0.000000
155.910004,-0.132935,-176.633850,-0.002156,0.002268,0.057618,-0.591322,-0.030123,0.576182,-176.633850,0.056717,0.000000
156.290009,-0.145599,-176.722824,-0.002177,0.002248,0.057099,-0.647658,-0.032993,0.570989,-176.722824,0.056083,0.000000
156.670013,-0.138153,-176.722824,-0.002225,0.002215,0.056257,-0.614536,-0.031306,0.562572,-176.722824,0.055450,0.000000
157.050003,-0.126236,-176.678345,-0.002255,0.002196,0.055780,-0.561526,-0.028605,0.557803,-176.678345,0.054817,0.000000
157.200012,-0.110596,-176.811783,-0.002246,0.002197,0.055797,-0.491954,-0.025061,0.557969,-176.811783,0.055736,0.000000