File: Data/compression 32/AutoNoHeating-10-32-reverse-1-1_11142024_181717.csv
Time (sec),S:Load (lbs),S:HL1 (DIM),S:LVDT (in),S:Position (in),Ch:Position (mm),Ch:Load (N),Ch:Stress (MPa),Ch:Strain (mm/mm),Ch:HL1 (DIM),Set Point (),Cycles ()
0.110000,-0.078575,-121.255074,-0.011839,-0.006878,-0.174711,-0.349520,-0.017805,-1.747113,-121.255074,-0.174486,0.000000
0.450000,0.002602,-121.299553,-0.011852,-0.006859,-0.174208,0.011573,0.000590,-1.742083,-121.299553,-0.173549,0.000000
0.790000,-0.072617,-121.299553,-0.011792,-0.006662,-0.169204,-0.323015,-0.016455,-1.692044,-121.299553,-0.167895,0.000000
1.130000,-0.010429,-121.299553,-0.011563,-0.006430,-0.163333,-0.046392,-0.002363,-1.633333,-121.299553,-0.162223,0.000000
1.470000,0.029411,-121.344032,-0.011339,-0.006215,-0.157870,0.130828,0.006665,-1.578698,-121.344032,-0.156569,0.000000
1.810000,0.013031,-121.344032,-0.011111,-0.005988,-0.152085,0.057965,0.002953,-1.520854,-121.344032,-0.150897,0.000000
2.150000,-0.039848,-121.388512,-0.010895,-0.005773,-0.146631,-0.177254,-0.009030,-1.466305,-121.388512,-0.145243,0.000000
2.490000,-0.046921,-121.432999,-0.010675,-0.005547,-0.140898,-0.208714,-0.010632,-1.408982,-121.432999,-0.139571,0.000000
2.830000,-0.033142,-121.388512,-0.010438,-0.005322,-0.135183,-0.147423,-0.007510,-1.351831,-121.388512,-0.133900,0.000000
3.170000,0.010796,-121.432999,-0.010210,-0.005098,-0.129494,0.048021,0.002446,-1.294942,-121.432999,-0.128245,0.000000
3.510000,-0.005592,-121.432999,-0.009968,-0.004871,-0.123727,-0.024876,-0.001267,-1.237271,-121.432999,-0.122574,0.000000
3.850000,0.005585,-121.432999,-0.009735,-0.004648,-0.118047,0.024842,0.001266,-1.180468,-121.432999,-0.116919,0.000000
4.190000,-0.018250,-121.477478,-0.009511,-0.004430,-0.112514,-0.081178,-0.004135,-1.125139,-121.477478,-0.111248,0.000000
4.530000,-0.013039,-121.521957,-0.009274,-0.004208,-0.106894,-0.057999,-0.002955,-1.068942,-121.521957,-0.105593,0.000000
4.870000,-0.093468,-121.566437,-0.009071,-0.003988,-0.101283,-0.415765,-0.021180,-1.012833,-121.566437,-0.099922,0.000000
5.210000,-0.008194,-121.610924,-0.008808,-0.003757,-0.095421,-0.036449,-0.001857,-0.954208,-121.610924,-0.094250,0.000000
5.550000,0.046539,-121.521957,-0.008571,-0.003532,-0.089706,0.207017,0.010546,-0.897058,-121.521957,-0.088596,0.000000
5.890000,0.029785,-121.610924,-0.008364,-0.003314,-0.084182,0.132491,0.006749,-0.841816,-121.610924,-0.082924,0.000000
6.230000,-0.024208,-121.610924,-0.008140,-0.003095,-0.078605,-0.107683,-0.005486,-0.786053,-121.610924,-0.077270,0.000000
6.570000,-0.042458,-121.610924,-0.007899,-0.002868,-0.072847,-0.188861,-0.009621,-0.728470,-121.610924,-0.071598,0.000000
6.910000,-0.031654,-121.655403,-0.007675,-0.002649,-0.067288,-0.140806,-0.007173,-0.672880,-121.655403,-0.065944,0.000000
7.250000,0.017128,-121.655403,-0.007446,-0.002424,-0.061564,0.076189,0.003881,-0.615644,-121.655403,-0.060272,0.000000
7.590000,0.004463,-121.744362,-0.007200,-0.002195,-0.055754,0.019853,0.001011,-0.557539,-121.744362,-0.054601,0.000000
7.930000,-0.008194,-121.699883,-0.006976,-0.001972,-0.050100,-0.036449,-0.001857,-0.500996,-121.699883,-0.048946,0.000000
8.270000,0.014519,-121.744362,-0.006743,-0.001753,-0.044515,0.064583,0.003290,-0.445147,-121.744362,-0.043275,0.000000
8.610001,0.011909,-121.744362,-0.006510,-0.001529,-0.038826,0.052976,0.002699,-0.388257,-121.744362,-0.037620,0.000000
8.950001,-0.046921,-121.788841,-0.006269,-0.001309,-0.033258,-0.208714,-0.010632,-0.332581,-121.788841,-0.031949,0.000000
9.290001,-0.037239,-121.833328,-0.006058,-0.001082,-0.027474,-0.165648,-0.008438,-0.274737,-121.833328,-0.026277,0.000000
9.630000,0.029785,-121.788841,-0.005829,-0.000858,-0.021785,0.132491,0.006749,-0.217847,-121.788841,-0.020623,0.000000
9.970000,0.052498,-121.833328,-0.005596,-0.000639,-0.016226,0.233522,0.011896,-0.162258,-121.833328,-0.014951,0.000000
10.310000,0.029045,-121.877808,-0.005359,-0.000419,-0.010641,0.129199,0.006582,-0.106409,-121.877808,-0.009297,0.000000
10.650001,-0.004471,-121.833328,-0.005131,-0.000189,-0.004804,-0.019887,-0.001013,-0.048044,-121.833328,-0.003625,0.000000
10.990001,-0.023834,-121.877808,-0.004889,0.000029,0.000737,-0.106020,-0.005401,0.007371,-121.877808,0.002029,0.000000
11.330001,0.021591,-121.877808,-0.004665,0.000252,0.006391,0.096042,0.004893,0.063915,-121.877808,0.007701,0.000000
11.670001,0.011909,-121.877808,-0.004458,0.000480,0.012193,0.052976,0.002699,0.121932,-121.877808,0.013373,0.000000
12.010000,0.001488,-121.922287,-0.004199,0.000705,0.017900,0.006618,0.000337,0.178995,-121.922287,0.019027,0.000000
12.350000,0.037979,-121.966766,-0.003971,0.000926,0.023528,0.168940,0.008606,0.235278,-121.966766,0.024699,0.000000
12.690001,0.016380,-121.966766,-0.003777,0.001146,0.029104,0.072863,0.003712,0.291041,-121.966766,0.030353,0.000000
13.030001,-0.033890,-122.011246,-0.003540,0.001361,0.034576,-0.150749,-0.007680,0.345763,-122.011246,0.036025,0.000000
13.370001,-0.067406,-122.055733,-0.003316,0.001592,0.040447,-0.299836,-0.015274,0.404474,-122.055733,0.041679,0.000000
13.710001,0.032394,-122.055733,-0.003070,0.001816,0.046119,0.144098,0.007341,0.461191,-122.055733,0.047351,0.000000
14.050000,0.065163,-122.055733,-0.002854,0.002040,0.051808,0.289858,0.014766,0.518081,-122.055733,0.053022,0.000000
14.390000,0.069260,-122.100212,-0.002708,-0.000000,-0.000009,0.308082,0.015694,-0.000087,-122.100212,0.000208,0.000000
14.730000,0.067024,-122.100212,-0.002699,-0.000000,-0.000009,0.298139,0.015188,-0.000087,-122.100212,0.000208,0.000000
15.070001,0.114311,-122.144691,-0.002708,-0.000000,-0.000000,0.508482,0.025903,-0.000000,-122.144691,0.000650,0.000000
15.410001,0.102402,-122.144691,-0.002708,0.000006,0.000147,0.455506,0.023205,0.001474,-122.144691,0.001214,0.000000
15.750001,0.156395,-122.144691,-0.002690,0.000021,0.000529,0.695680,0.035440,0.005290,-122.144691,0.001778,0.000000
16.090000,0.218582,-122.233650,-0.002652,0.000058,0.001466,0.972302,0.049531,0.014656,-122.233650,0.002350,0.000000
16.430000,0.318375,-122.233650,-0.002634,0.000078,0.001986,1.416201,0.072145,0.019859,-122.233650,0.002914,0.000000
16.770000,0.405510,-122.189171,-0.002621,0.000099,0.002524,1.803798,0.091890,0.025236,-122.189171,0.003478,0.000000
17.110001,0.506424,-122.322617,-0.002600,0.000118,0.003001,2.252686,0.114757,0.030006,-122.322617,0.004050,0.000000
17.450001,0.733566,-122.278137,-0.002578,0.000149,0.003772,3.263066,0.166229,0.037724,-122.278137,0.004614,0.000000
17.790001,0.773788,-122.367096,-0.002557,0.000165,0.004197,3.441983,0.175343,0.041974,-122.367096,0.005177,0.000000
18.130001,0.954018,-122.322617,-0.002531,0.000188,0.004770,4.243682,0.216183,0.047697,-122.322617,0.005750,0.000000
18.470001,1.044876,-122.278137,-0.002522,0.000199,0.005065,4.647841,0.236772,0.050646,-122.278137,0.006313,0.000000
18.810001,1.320053,-122.367096,-0.002483,0.000232,0.005897,5.871890,0.299128,0.058971,-122.367096,0.006877,0.000000
19.150002,1.521507,-122.278137,-0.002462,0.000255,0.006478,6.768003,0.344778,0.064782,-122.278137,0.007449,0.000000
19.490002,1.592262,-122.500542,-0.002466,0.000269,0.006842,7.082736,0.360812,0.068424,-122.500542,0.008013,0.000000
19.830002,1.909149,-122.411575,-0.002432,0.000302,0.007666,8.492320,0.432619,0.076663,-122.411575,0.008586,0.000000
20.170000,2.007454,-122.411575,-0.002419,0.000322,0.008187,8.929601,0.454896,0.081866,-122.411575,0.009149,0.000000
20.510000,2.013786,-122.500542,-0.002406,0.000331,0.008412,8.957768,0.456331,0.084121,-122.500542,0.009713,0.000000
20.850000,2.301262,-122.456055,-0.002376,0.000357,0.009071,10.236525,0.521473,0.090712,-122.456055,0.010285,0.000000
21.190001,2.547768,-122.500542,-0.002350,0.000382,0.009696,11.333036,0.577332,0.096956,-122.500542,0.010849,0.000000
21.530001,2.782738,-122.500542,-0.002328,0.000409,0.010398,12.378236,0.630577,0.103980,-122.500542,0.011413,0.000000
21.870001,3.074303,-122.633980,-0.002315,0.000436,0.011074,13.675181,0.696647,0.110745,-122.633980,0.011985,0.000000
22.210001,3.044884,-122.633980,-0.002289,0.000451,0.011447,13.544319,0.689981,0.114474,-122.633980,0.012549,0.000000
22.550001,3.322678,-122.500542,-0.002259,0.000468,0.011898,14.780008,0.752930,0.118983,-122.500542,0.013112,0.000000
22.890001,3.782555,-122.678467,-0.002255,0.000503,0.012774,16.825644,0.857139,0.127742,-122.678467,0.013685,0.000000
23.230001,3.698029,-122.633980,-0.002212,0.000520,0.013217,16.449652,0.837985,0.132165,-122.633980,0.014249,0.000000
23.570002,3.867081,-122.633980,-0.002195,0.000537,0.013633,17.201633,0.876293,0.136328,-122.633980,0.014812,0.000000
23.910002,3.561363,-122.678467,-0.002186,0.000537,0.013641,15.841735,0.807016,0.136415,-122.678467,0.015385,0.000000
24.250002,4.460648,-122.678467,-0.002143,0.000586,0.014873,19.841951,1.010797,0.148729,-122.678467,0.015948,0.000000
24.590002,4.510170,-122.678467,-0.002126,0.000606,0.015393,20.062239,1.022019,0.153933,-122.678467,0.016512,0.000000
24.930000,4.788704,-122.722946,-0.002100,0.000634,0.016096,21.301218,1.085136,0.160957,-122.722946,0.017084,0.000000
25.270000,4.712746,-122.767426,-0.002091,0.000651,0.016529,20.963339,1.067923,0.165293,-122.767426,0.017648,0.000000
25.610001,4.660606,-122.767426,-0.002065,0.000669,0.016980,20.731413,1.056108,0.169803,-122.767426,0.018212,0.000000
25.950001,4.951431,-122.722946,-0.002039,0.000693,0.017605,22.025066,1.122010,0.176047,-122.722946,0.018784,0.000000
26.290001,5.110809,-122.811905,-0.002009,0.000717,0.018203,22.734015,1.158126,0.182031,-122.811905,0.019348,0.000000
26.630001,5.387856,-122.811905,-0.001975,0.000743,0.018880,23.966379,1.220906,0.188795,-122.811905,0.019911,0.000000
26.970001,5.489510,-122.900871,-0.001975,0.000765,0.019435,24.418558,1.243941,0.194345,-122.900871,0.020484,0.000000
27.310001,5.539406,-122.856384,-0.001962,0.000783,0.019894,24.640509,1.255247,0.198942,-122.856384,0.021048,0.000000
27.650002,5.821297,-122.856384,-0.001923,0.000813,0.020649,25.894421,1.319125,0.206486,-122.856384,0.021620,0.000000
27.990002,5.655960,-122.945351,-0.001897,0.000825,0.020961,25.158966,1.281659,0.209608,-122.945351,0.022184,0.000000
28.330002,5.919975,-122.945351,-0.001884,0.000848,0.021533,26.333364,1.341486,0.215332,-122.945351,0.022747,0.000000
28.670002,6.268143,-122.900871,-0.001845,0.000874,0.022201,27.882092,1.420381,0.222010,-122.900871,0.023320,0.000000
29.010002,6.364212,-122.989830,-0.001837,0.000899,0.022843,28.309429,1.442151,0.228427,-122.989830,0.023883,0.000000
29.350002,6.539604,-122.989830,-0.001811,0.000925,0.023502,29.089613,1.481895,0.235018,-122.989830,0.024447,0.000000
29.690001,6.584290,-122.989830,-0.001776,0.000948,0.024083,29.288383,1.492021,0.240829,-122.989830,0.025019,0.000000
30.030001,6.296814,-123.034309,-0.001750,0.000962,0.024438,28.009628,1.426878,0.244384,-123.034309,0.025583,0.000000
30.370001,6.430870,-123.034309,-0.001742,0.000980,0.024898,28.605938,1.457256,0.248981,-123.034309,0.026147,0.000000
30.710001,7.099274,-123.078789,-0.001712,0.001015,0.025774,31.579147,1.608718,0.257739,-123.078789,0.026719,0.000000
31.050001,6.901550,-123.034309,-0.001673,0.001036,0.026320,30.699629,1.563914,0.263203,-123.034309,0.027283,0.000000
31.390001,6.608116,-123.078789,-0.001673,0.001047,0.026598,29.394369,1.497421,0.265978,-123.078789,0.027847,0.000000
31.730001,7.184547,-123.123276,-0.001613,0.001083,0.027500,31.958464,1.628042,0.274997,-123.123276,0.028419,0.000000
32.070000,7.040070,-123.167755,-0.001625,0.001104,0.028037,31.315794,1.595302,0.280374,-123.167755,0.028983,0.000000
32.410000,7.139496,-123.256714,-0.001604,0.001123,0.028532,31.758064,1.617833,0.285317,-123.256714,0.029546,0.000000
32.750000,7.253815,-123.167755,-0.001561,0.001145,0.029095,32.266579,1.643738,0.290954,-123.167755,0.030119,0.000000
33.090000,7.168541,-123.212234,-0.001531,0.001164,0.029572,31.887262,1.624415,0.295724,-123.212234,0.030682,0.000000
33.430000,7.514847,-123.212234,-0.001509,0.001195,0.030344,33.427708,1.702889,0.303442,-123.212234,0.031246,0.000000
33.770000,7.362915,-123.167755,-0.001492,0.001213,0.030821,32.751881,1.668460,0.308212,-123.167755,0.031819,0.000000
34.110001,7.469788,-123.345680,-0.001466,0.001236,0.031394,33.227276,1.692678,0.313936,-123.345680,0.032382,0.000000
34.450001,7.178223,-123.256714,-0.001449,0.001246,0.031654,31.930328,1.626608,0.316537,-123.256714,0.032946,0.000000
34.790001,7.910675,-123.301193,-0.001423,0.001282,0.032573,35.188438,1.792585,0.325730,-123.301193,0.033518,0.000000
35.130001,7.762474,-123.345680,-0.001401,0.001307,0.033189,34.529209,1.759002,0.331887,-123.345680,0.034082,0.000000
35.470001,7.750183,-123.345680,-0.001367,0.001330,0.033770,34.474537,1.756217,0.337698,-123.345680,0.034646,0.000000
35.810001,7.839180,-123.345680,-0.001345,0.001351,0.034316,34.870415,1.776384,0.343161,-123.345680,0.035218,0.000000
36.150002,7.843651,-123.390160,-0.001319,0.001370,0.034810,34.890301,1.777397,0.348104,-123.390160,0.035782,0.000000
36.490002,7.740128,-123.345680,-0.001298,0.001385,0.035183,34.429806,1.753938,0.351833,-123.345680,0.036354,0.000000
36.830002,7.769920,-123.434639,-0.001281,0.001408,0.035756,34.562332,1.760689,0.357557,-123.434639,0.036918,0.000000
37.170002,8.383591,-123.390160,-0.001259,0.001434,0.036423,37.292072,1.899749,0.364235,-123.390160,0.037481,0.000000
37.510002,8.340019,-123.479118,-0.001229,0.001462,0.037143,37.098259,1.889875,0.371433,-123.479118,0.038054,0.000000
37.850002,8.073776,-123.479118,-0.001190,0.001480,0.037603,35.913952,1.829544,0.376029,-123.479118,0.038618,0.000000
38.190002,8.170219,-123.479118,-0.001190,0.001502,0.038158,36.342953,1.851398,0.381579,-123.479118,0.039181,0.000000
38.530003,8.341881,-123.568085,-0.001177,0.001525,0.038748,37.106541,1.890297,0.387476,-123.568085,0.039754,0.000000
38.870003,8.627869,-123.523598,-0.001134,0.001552,0.039433,38.378677,1.955103,0.394328,-123.523598,0.040317,0.000000
39.210003,8.486740,-123.657043,-0.001121,0.001572,0.039918,37.750904,1.923123,0.399184,-123.657043,0.040881,0.000000
39.550003,8.518013,-123.568085,-0.001095,0.001592,0.040430,37.890015,1.930209,0.404301,-123.568085,0.041453,0.000000
39.890003,8.066330,-123.568085,-0.001078,0.001605,0.040777,35.880829,1.827856,0.407770,-123.568085,0.042017,0.000000
40.230003,9.007317,-123.701523,-0.001043,0.001636,0.041566,40.066544,2.041087,0.415661,-123.701523,0.042581,0.000000
40.570004,8.924278,-123.568085,-0.001030,0.001659,0.042130,39.697174,2.022270,0.421298,-123.568085,0.043153,0.000000
40.910004,9.351761,-123.657043,-0.001009,0.001682,0.042728,41.598709,2.119139,0.427282,-123.657043,0.043717,0.000000
41.250004,9.521561,-123.657043,-0.000970,0.001707,0.043370,42.354015,2.157616,0.433700,-123.657043,0.044281,0.000000
41.590000,9.375221,-123.701523,-0.000953,0.001725,0.043821,41.703068,2.124455,0.438209,-123.701523,0.044853,0.000000
41.930000,9.298882,-123.746002,-0.000940,0.001739,0.044176,41.363491,2.107157,0.441765,-123.746002,0.045417,0.000000
42.270000,9.719292,-123.701523,-0.000918,0.001762,0.044749,43.233570,2.202423,0.447488,-123.701523,0.045980,0.000000
42.610001,10.066338,-123.746002,-0.000888,0.001787,0.045391,44.777306,2.281065,0.453906,-123.746002,0.046553,0.000000
42.950001,10.694534,-123.834969,-0.000867,0.001814,0.046084,47.571663,2.423416,0.460844,-123.834969,0.047116,0.000000
43.290001,10.965622,-123.746002,-0.000849,0.001840,0.046735,48.777523,2.484845,0.467348,-123.746002,0.047680,0.000000
43.630001,10.720230,-123.879448,-0.000828,0.001855,0.047116,47.685966,2.429239,0.471164,-123.879448,0.048252,0.000000
43.970001,11.239685,-123.790489,-0.000824,0.001873,0.047567,49.996616,2.546949,0.475673,-123.790489,0.048816,0.000000
44.310001,12.284561,-123.879448,-0.000789,0.001906,0.048417,54.644459,2.783721,0.484172,-123.879448,0.049389,0.000000
44.650002,11.693977,-123.834969,-0.000750,0.001922,0.048816,52.017410,2.649893,0.488161,-123.834969,0.049952,0.000000
44.990002,11.884262,-123.879448,-0.000755,0.001937,0.049189,52.863838,2.693012,0.491890,-123.879448,0.050516,0.000000
45.330002,12.579109,-123.923927,-0.000746,0.001962,0.049839,55.954674,2.850467,0.498395,-123.923927,0.051088,0.000000
45.670002,13.140648,-123.923927,-0.000711,0.001987,0.050473,58.452522,2.977713,0.504725,-123.923927,0.051652,0.000000
46.010002,13.492165,-124.012894,-0.000711,0.002005,0.050915,60.016144,3.057368,0.509148,-124.012894,0.052216,0.000000
46.350002,14.650993,-123.923927,-0.000677,0.002037,0.051747,65.170876,3.319963,0.517474,-123.923927,0.052788,0.000000
46.690002,14.495712,-124.012894,-0.000660,0.002051,0.052086,64.480148,3.284775,0.520856,-124.012894,0.053352,0.000000
47.030003,15.223701,-124.057373,-0.000642,0.002079,0.052797,67.718407,3.449740,0.527967,-124.057373,0.053915,0.000000
47.370003,16.087234,-124.101852,-0.000621,0.002103,0.053412,71.559593,3.645420,0.534124,-124.101852,0.054488,0.000000
47.710003,17.069550,-124.057373,-0.000608,0.002127,0.054037,75.929146,3.868015,0.540368,-124.057373,0.055051,0.000000
48.050003,17.695877,-124.101852,-0.000595,0.002150,0.054609,78.715195,4.009943,0.546092,-124.101852,0.055615,0.000000
48.390003,18.096924,-124.057373,-0.000578,0.002168,0.055069,80.499138,4.100821,0.550688,-124.057373,0.056188,0.000000
48.730003,18.418282,-124.146332,-0.000573,0.002186,0.055520,81.928612,4.173642,0.555198,-124.146332,0.056751,0.000000
49.070004,19.917824,-124.146332,-0.000560,0.002211,0.056170,88.598907,4.513443,0.561702,-124.146332,0.057315,0.000000
49.410004,20.626076,-124.190819,-0.000517,0.002234,0.056734,91.749367,4.673935,0.567339,-124.190819,0.057887,0.000000
49.750004,21.843735,-124.146332,-0.000522,0.002259,0.057376,97.165787,4.949861,0.573756,-124.146332,0.058451,0.000000
50.090004,23.100121,-124.190819,-0.000509,0.002281,0.057948,102.754471,5.234562,0.579480,-124.190819,0.059015,0.000000
50.430004,24.179260,-124.235298,-0.000509,0.002302,0.058468,107.554718,5.479099,0.584684,-124.235298,0.059587,0.000000
50.770004,25.596138,-124.190819,-0.000470,0.002328,0.059136,113.857307,5.800168,0.591361,-124.190819,0.060151,0.000000
51.110001,26.685699,-124.146332,-0.000470,0.002352,0.059743,118.703918,6.047066,0.597432,-124.146332,0.060714,0.000000
51.450001,27.431931,-124.279778,-0.000448,0.002368,0.060159,122.023323,6.216164,0.601594,-124.279778,0.061287,0.000000
51.790001,28.850296,-124.279778,-0.000435,0.002391,0.060740,128.332520,6.537570,0.607405,-124.279778,0.061851,0.000000
52.130001,30.573265,-124.324257,-0.000431,0.002414,0.061313,135.996674,6.928001,0.613129,-124.324257,0.062414,0.000000
52.470001,31.788315,-124.279778,-0.000418,0.002435,0.061842,141.401489,7.203335,0.618419,-124.279778,0.062987,0.000000
52.810001,33.467712,-124.279778,-0.000410,0.002463,0.062562,148.871826,7.583892,0.625617,-124.279778,0.063550,0.000000
53.150002,34.932259,-124.368736,-0.000392,0.002485,0.063117,155.386444,7.915763,0.631167,-124.368736,0.064123,0.000000
53.490002,36.485046,-124.413223,-0.000388,0.002507,0.063672,162.293594,8.267630,0.636717,-124.413223,0.064686,0.000000
53.830002,37.815536,-124.502182,-0.000375,0.002527,0.064192,168.211914,8.569122,0.641920,-124.502182,0.065250,0.000000
54.170002,39.589149,-124.413223,-0.000362,0.002549,0.064756,176.101334,8.971029,0.647557,-124.413223,0.065822,0.000000
54.510002,41.431274,-124.413223,-0.000354,0.002574,0.065389,184.295517,9.388461,0.653888,-124.413223,0.066386,0.000000
54.850002,43.100990,-124.502182,-0.000349,0.002598,0.065979,191.722778,9.766824,0.659785,-124.502182,0.066950,0.000000
55.190002,44.370033,-124.502182,-0.000354,0.002614,0.066403,197.367767,10.054394,0.664035,-124.502182,0.067522,0.000000
55.530003,46.130241,-124.502182,-0.000345,0.002635,0.066941,205.197556,10.453261,0.669411,-124.502182,0.068086,0.000000
55.870003,47.798096,-124.502182,-0.000336,0.002659,0.067531,212.616547,10.831203,0.675309,-124.502182,0.068650,0.000000
56.210003,50.304535,-124.502182,-0.000336,0.002688,0.068268,223.765747,11.399171,0.682680,-124.502182,0.069222,0.000000
56.550003,52.378281,-124.546661,-0.000315,0.002710,0.068840,232.990234,11.869088,0.688404,-124.546661,0.069786,0.000000
56.890003,54.084862,-124.591141,-0.000310,0.002731,0.069378,240.581482,12.255805,0.693781,-124.591141,0.070349,0.000000
57.230003,55.741920,-124.635628,-0.000315,0.002752,0.069907,247.952438,12.631300,0.699071,-124.635628,0.070922,0.000000
57.570004,57.752731,-124.591141,-0.000297,0.002772,0.070419,256.896973,13.086956,0.704187,-124.591141,0.071485,0.000000
57.910004,59.212807,-124.591141,-0.000315,0.002789,0.070852,263.391724,13.417813,0.708523,-124.591141,0.072049,0.000000
58.250004,61.159195,-124.724586,-0.000285,0.002812,0.071433,272.049683,13.858871,0.714334,-124.724586,0.072621,0.000000
58.590004,63.461197,-124.680107,-0.000302,0.002840,0.072136,282.289490,14.380512,0.721358,-124.680107,0.073185,0.000000
58.930004,65.927795,-124.724586,-0.000297,0.002863,0.072708,293.261475,14.939452,0.727082,-124.724586,0.073749,0.000000
59.270004,65.981049,-124.680107,-0.000293,0.002857,0.072569,293.498352,14.951519,0.725694,-124.680107,0.012757,0.000000
59.610004,65.635849,-124.724586,-0.000280,0.002857,0.072561,291.962830,14.873296,0.725608,-124.724586,294.500458,0.000000
59.950005,65.295883,-124.813545,-0.000276,0.002857,0.072561,290.450592,14.796259,0.725608,-124.813545,294.500458,0.000000
60.290005,65.026657,-124.724586,-0.000272,0.002857,0.072561,289.253021,14.735251,0.725608,-124.724586,294.500458,0.000000
60.630001,64.793915,-124.813545,-0.000272,0.002857,0.072561,288.217712,14.682511,0.725608,-124.813545,294.500458,0.000000
60.970001,66.197769,-124.813545,-0.000267,0.002866,0.072786,294.462372,15.000628,0.727862,-124.813545,294.500458,0.000000
61.310001,66.010086,-124.858032,-0.000267,0.002866,0.072786,293.627533,14.958099,0.727862,-124.858032,294.500458,0.000000
61.650002,65.878265,-124.902512,-0.000272,0.002865,0.072778,293.041168,14.928228,0.727776,-124.902512,294.500458,0.000000
61.990002,65.747940,-124.902512,-0.000280,0.002865,0.072778,292.461456,14.898696,0.727776,-124.902512,294.500458,0.000000
62.330002,65.580002,-124.946991,-0.000272,0.002866,0.072786,291.714417,14.860641,0.727862,-124.946991,294.500458,0.000000
62.670002,65.485046,-124.991470,-0.000263,0.002866,0.072786,291.292023,14.839124,0.727862,-124.991470,294.500458,0.000000
63.010002,65.334610,-124.946991,-0.000267,0.002866,0.072804,290.622864,14.805035,0.728036,-124.946991,294.500458,0.000000
63.350002,65.254547,-124.991470,-0.000259,0.002867,0.072812,290.266724,14.786892,0.728123,-124.991470,294.500458,0.000000
63.690002,65.198685,-125.035950,-0.000272,0.002872,0.072951,290.018219,14.774233,0.729510,-125.035950,294.500458,0.000000
64.030006,65.139114,-125.080437,-0.000272,0.002874,0.072994,289.753265,14.760735,0.729944,-125.080437,294.500458,0.000000
64.370003,65.114914,-125.080437,-0.000267,0.002874,0.073012,289.645599,14.755250,0.730117,-125.080437,294.500458,0.000000
64.710007,65.426208,-125.035950,-0.000272,0.002881,0.073177,291.030304,14.825791,0.731765,-125.035950,294.500458,0.000000
65.050003,65.489136,-125.080437,-0.000259,0.002880,0.073142,291.310211,14.840051,0.731418,-125.080437,294.500458,0.000000
65.389999,65.445206,-125.080437,-0.000254,0.002880,0.073142,291.114807,14.830095,0.731418,-125.080437,294.500458,0.000000
65.730003,65.389343,-125.169395,-0.000246,0.002880,0.073142,290.866333,14.817437,0.731418,-125.169395,294.500458,0.000000
66.070000,65.348389,-125.080437,-0.000259,0.002880,0.073142,290.684143,14.808156,0.731418,-125.080437,294.500458,0.000000
66.410004,65.314133,-125.124916,-0.000272,0.002880,0.073142,290.531769,14.800394,0.731418,-125.124916,294.500458,0.000000
66.750000,65.288803,-125.258362,-0.000254,0.002880,0.073150,290.419098,14.794654,0.731505,-125.258362,294.500458,0.000000
67.090004,65.256409,-125.213875,-0.000250,0.002880,0.073150,290.274994,14.787313,0.731505,-125.213875,294.500458,0.000000
67.430000,65.232574,-125.258362,-0.000259,0.002880,0.073150,290.168976,14.781913,0.731505,-125.258362,294.500458,0.000000
67.770004,65.201294,-125.213875,-0.000259,0.002880,0.073150,290.029846,14.774824,0.731505,-125.213875,294.500458,0.000000
68.110001,65.156616,-125.347321,-0.000263,0.002880,0.073150,289.831116,14.764701,0.731505,-125.347321,294.500458,0.000000
68.450005,65.102997,-125.258362,-0.000263,0.002880,0.073150,289.592590,14.752550,0.731505,-125.258362,294.500458,0.000000
68.790001,65.070969,-125.213875,-0.000259,0.002880,0.073150,289.450134,14.745292,0.731505,-125.213875,294.500458,0.000000
69.130005,65.048996,-125.347321,-0.000285,0.002880,0.073150,289.352386,14.740314,0.731505,-125.347321,294.500458,0.000000
69.470001,65.022186,-125.347321,-0.000272,0.002880,0.073150,289.233124,14.734238,0.731505,-125.347321,294.500458,0.000000
69.810005,65.002075,-125.391800,-0.000272,0.002880,0.073150,289.143677,14.729681,0.731505,-125.391800,294.500458,0.000000
70.150002,64.973038,-125.436279,-0.000259,0.002880,0.073150,289.014496,14.723101,0.731505,-125.436279,294.500458,0.000000
70.490005,64.959625,-125.347321,-0.000276,0.002880,0.073150,288.954834,14.720061,0.731505,-125.347321,294.500458,0.000000
70.830002,64.929840,-125.436279,-0.000263,0.002880,0.073150,288.822357,14.713312,0.731505,-125.436279,294.500458,0.000000
71.170006,64.891479,-125.391800,-0.000254,0.002880,0.073150,288.651703,14.704619,0.731505,-125.391800,294.500458,0.000000
71.510002,64.856110,-125.436279,-0.000250,0.002880,0.073150,288.494385,14.696605,0.731505,-125.436279,294.500458,0.000000
71.850006,64.837494,-125.436279,-0.000254,0.002880,0.073150,288.411591,14.692387,0.731505,-125.436279,294.500458,0.000000
72.190002,64.805832,-125.525246,-0.000263,0.002880,0.073150,288.270752,14.685211,0.731505,-125.525246,294.500458,0.000000
72.530006,64.789825,-125.569725,-0.000259,0.002880,0.073150,288.199524,14.681584,0.731505,-125.569725,294.500458,0.000000
72.870003,64.774933,-125.525246,-0.000267,0.002880,0.073150,288.133301,14.678209,0.731505,-125.525246,294.500458,0.000000
73.210007,64.746628,-125.614204,-0.000272,0.002880,0.073150,288.007385,14.671796,0.731505,-125.614204,294.500458,0.000000
73.550003,64.730621,-125.614204,-0.000259,0.002880,0.073150,287.936188,14.668168,0.731505,-125.614204,294.500458,0.000000
73.890007,64.702698,-125.569725,-0.000254,0.002880,0.073150,287.811981,14.661841,0.731505,-125.569725,294.500458,0.000000
74.230003,64.698227,-125.658684,-0.000259,0.002880,0.073150,287.792084,14.660829,0.731505,-125.658684,294.500458,0.000000
74.570007,64.686310,-125.614204,-0.000272,0.002880,0.073150,287.739075,14.658128,0.731505,-125.614204,294.500458,0.000000
74.910004,64.667694,-125.703171,-0.000250,0.002880,0.073150,287.656281,14.653909,0.731505,-125.703171,294.500458,0.000000
75.250000,64.639008,-125.614204,-0.000254,0.002880,0.073150,287.528656,14.647408,0.731505,-125.614204,294.500458,0.000000
75.590004,64.618912,-125.658684,-0.000263,0.002880,0.073150,287.439270,14.642855,0.731505,-125.658684,294.500458,0.000000
75.930000,64.600662,-125.747650,-0.000263,0.002880,0.073150,287.358093,14.638720,0.731505,-125.747650,294.500458,0.000000
76.270004,64.579056,-125.703171,-0.000259,0.002880,0.073150,287.261993,14.633822,0.731505,-125.703171,294.500458,0.000000
76.610001,64.563797,-125.747650,-0.000272,0.002880,0.073150,287.194122,14.630365,0.731505,-125.747650,294.500458,0.000000
76.950005,64.544067,-125.703171,-0.000250,0.002880,0.073159,287.106354,14.625895,0.731592,-125.703171,294.500458,0.000000
77.290001,64.539215,-125.792130,-0.000263,0.002880,0.073159,287.084778,14.624795,0.731592,-125.792130,294.500458,0.000000
77.630005,64.515762,-125.836609,-0.000263,0.002880,0.073159,286.980438,14.619480,0.731592,-125.836609,294.500458,0.000000
77.970001,64.505341,-125.792130,-0.000263,0.002880,0.073159,286.934082,14.617119,0.731592,-125.792130,294.500458,0.000000
78.310005,66.701965,-125.881088,-0.000259,0.002854,0.072500,296.705170,15.114882,0.725001,-125.881088,294.500458,0.000000
78.650002,66.683716,-125.881088,-0.000254,0.002854,0.072500,296.623993,15.110746,0.725001,-125.881088,294.500458,0.000000
78.990005,66.663605,-125.881088,-0.000267,0.002854,0.072500,296.534515,15.106189,0.725001,-125.881088,294.500458,0.000000
79.330002,66.667328,-125.925575,-0.000267,0.002854,0.072500,296.551086,15.107032,0.725001,-125.925575,294.500458,0.000000
79.670006,66.624878,-125.881088,-0.000259,0.002854,0.072500,296.362244,15.097413,0.725001,-125.881088,294.500458,0.000000
80.010002,66.596954,-126.014534,-0.000267,0.002854,0.072500,296.238037,15.091085,0.725001,-126.014534,294.500458,0.000000
80.350006,66.583542,-125.925575,-0.000263,0.002854,0.072500,296.178375,15.088047,0.725001,-125.925575,294.500458,0.000000
80.690002,66.591370,-125.970055,-0.000267,0.002854,0.072500,296.213196,15.089820,0.725001,-125.970055,294.500458,0.000000
81.030006,66.563812,-126.059013,-0.000263,0.002854,0.072500,296.090637,15.083575,0.725001,-126.059013,294.500458,0.000000
81.370003,66.486725,-125.970055,-0.000259,0.002854,0.072500,295.747711,15.066107,0.725001,-125.970055,294.500458,0.000000
81.710007,66.491943,-126.059013,-0.000263,0.002854,0.072500,295.770935,15.067289,0.725001,-126.059013,294.500458,0.000000
82.050003,66.416718,-126.059013,-0.000250,0.002854,0.072500,295.436310,15.050243,0.725001,-126.059013,294.500458,0.000000
82.390007,66.430878,-126.059013,-0.000254,0.002854,0.072500,295.499298,15.053452,0.725001,-126.059013,294.500458,0.000000
82.730003,66.390289,-126.147980,-0.000254,0.002854,0.072500,295.318756,15.044255,0.725001,-126.147980,294.500458,0.000000
83.070007,66.394745,-126.103493,-0.000254,0.002854,0.072500,295.338562,15.045264,0.725001,-126.103493,294.500458,0.000000
83.410004,66.418213,-126.236938,-0.000272,0.002854,0.072500,295.442963,15.050583,0.725001,-126.236938,294.500458,0.000000
83.750008,66.395493,-126.147980,-0.000241,0.002854,0.072500,295.341888,15.045433,0.725001,-126.147980,294.500458,0.000000
84.090004,66.389160,-126.147980,-0.000267,0.002854,0.072500,295.313721,15.043999,0.725001,-126.147980,294.500458,0.000000
84.430000,66.382095,-126.236938,-0.000250,0.002854,0.072500,295.282318,15.042397,0.725001,-126.236938,294.500458,0.000000
84.770004,66.357880,-126.192459,-0.000259,0.002854,0.072500,295.174591,15.036911,0.725001,-126.192459,294.500458,0.000000
85.110001,66.347092,-126.281418,-0.000254,0.002854,0.072500,295.126617,15.034466,0.725001,-126.281418,294.500458,0.000000
85.450005,66.323257,-126.236938,-0.000246,0.002854,0.072500,295.020569,15.029065,0.725001,-126.236938,294.500458,0.000000
85.790001,66.312088,-126.236938,-0.000263,0.002854,0.072500,294.970886,15.026534,0.725001,-126.236938,294.500458,0.000000
86.130005,66.299789,-126.281418,-0.000263,0.002854,0.072500,294.916199,15.023746,0.725001,-126.281418,294.500458,0.000000
86.470001,66.282669,-126.325897,-0.000259,0.002854,0.072500,294.840027,15.019868,0.725001,-126.325897,294.500458,0.000000
86.810005,66.261444,-126.459343,-0.000272,0.002854,0.072500,294.745636,15.015058,0.725001,-126.459343,294.500458,0.000000
87.150002,66.247665,-126.325897,-0.000246,0.002854,0.072500,294.684326,15.011936,0.725001,-126.325897,294.500458,0.000000
87.490005,66.230911,-126.370384,-0.000259,0.002854,0.072500,294.609802,15.008140,0.725001,-126.370384,294.500458,0.000000
87.830002,66.231277,-126.414864,-0.000276,0.002854,0.072500,294.611450,15.008222,0.725001,-126.414864,294.500458,0.000000
88.170006,66.198135,-126.459343,-0.000259,0.002854,0.072500,294.464020,15.000712,0.725001,-126.459343,294.500458,0.000000
88.510002,66.195908,-126.459343,-0.000254,0.002854,0.072500,294.454102,15.000207,0.725001,-126.459343,294.500458,0.000000
88.850006,66.183609,-126.414864,-0.000259,0.002854,0.072500,294.399384,14.997420,0.725001,-126.414864,294.500458,0.000000
89.190002,66.177292,-126.503822,-0.000250,0.002854,0.072500,294.371307,14.995989,0.725001,-126.503822,294.500458,0.000000
89.530006,66.149353,-126.548309,-0.000267,0.002854,0.072500,294.247009,14.989657,0.725001,-126.548309,294.500458,0.000000
89.870003,66.147125,-126.503822,-0.000259,0.002854,0.072500,294.237122,14.989153,0.725001,-126.503822,294.500458,0.000000
90.210007,66.135208,-126.592789,-0.000272,0.002854,0.072500,294.184113,14.986453,0.725001,-126.592789,294.500458,0.000000
90.550003,66.135208,-126.548309,-0.000250,0.002854,0.072500,294.184113,14.986453,0.725001,-126.548309,294.500458,0.000000
90.890007,66.118073,-126.592789,-0.000246,0.002854,0.072500,294.107880,14.982569,0.725001,-126.592789,294.500458,0.000000
91.230003,66.099091,-126.637268,-0.000254,0.002854,0.072500,294.023437,14.978268,0.725001,-126.637268,294.500458,0.000000
91.570007,66.099457,-126.592789,-0.000259,0.002854,0.072500,294.025055,14.978352,0.725001,-126.592789,294.500458,0.000000
91.910004,66.092010,-126.637268,-0.000263,0.002854,0.072500,293.991943,14.976664,0.725001,-126.637268,294.500458,0.000000
92.250008,66.062592,-126.681747,-0.000250,0.002854,0.072500,293.861084,14.969997,0.725001,-126.681747,294.500458,0.000000
92.590004,66.062973,-126.681747,-0.000250,0.002854,0.072500,293.862793,14.970083,0.725001,-126.681747,294.500458,0.000000
92.930008,66.051056,-126.726227,-0.000272,0.002854,0.072500,293.809784,14.967383,0.725001,-126.726227,294.500458,0.000000
93.270004,66.033920,-126.770714,-0.000250,0.002854,0.072500,293.733551,14.963500,0.725001,-126.770714,294.500458,0.000000
93.610008,66.027588,-126.770714,-0.000259,0.002854,0.072500,293.705383,14.962066,0.725001,-126.770714,294.500458,0.000000
93.950005,66.013077,-126.681747,-0.000250,0.002854,0.072500,293.640839,14.958777,0.725001,-126.681747,294.500458,0.000000
94.290001,66.013077,-126.770714,-0.000259,0.002854,0.072500,293.640839,14.958777,0.725001,-126.770714,294.500458,0.000000
94.630005,66.003754,-126.859673,-0.000254,0.002854,0.072500,293.599365,14.956665,0.725001,-126.859673,294.500458,0.000000
94.970001,65.977325,-126.815193,-0.000246,0.002854,0.072500,293.481812,14.950676,0.725001,-126.815193,294.500458,0.000000
95.310005,65.962051,-126.859673,-0.000254,0.002854,0.072500,293.413849,14.947214,0.725001,-126.859673,294.500458,0.000000
95.650002,66.016418,-126.770714,-0.000254,0.002855,0.072509,293.655701,14.959535,0.725087,-126.770714,294.500458,0.000000
95.990005,66.022751,-126.904152,-0.000259,0.002855,0.072509,293.683868,14.960970,0.725087,-126.904152,294.500458,0.000000
96.330002,65.934494,-126.904152,-0.000263,0.002855,0.072509,293.291290,14.940970,0.725087,-126.904152,294.500458,0.000000
96.670006,65.909546,-126.948631,-0.000254,0.002855,0.072509,293.180298,14.935317,0.725087,-126.948631,294.500458,0.000000
97.010002,65.909927,-126.948631,-0.000263,0.002855,0.072509,293.182007,14.935403,0.725087,-126.948631,294.500458,0.000000
97.350006,65.912903,-126.948631,-0.000263,0.002855,0.072509,293.195221,14.936077,0.725087,-126.948631,294.500458,0.000000
97.690002,65.916626,-126.993118,-0.000259,0.002855,0.072509,293.211792,14.936921,0.725087,-126.993118,294.500458,0.000000
98.030006,65.890182,-127.037598,-0.000246,0.002855,0.072509,293.094177,14.930928,0.725087,-127.037598,294.500458,0.000000
98.370003,65.947525,-127.037598,-0.000263,0.002855,0.072509,293.349243,14.943923,0.725087,-127.037598,294.500458,0.000000
98.710007,65.946793,-127.082077,-0.000267,0.002855,0.072509,293.345978,14.943757,0.725087,-127.082077,294.500458,0.000000
99.050003,65.842148,-127.082077,-0.000246,0.002855,0.072509,292.880493,14.920044,0.725087,-127.082077,294.500458,0.000000
99.390007,65.921097,-127.126556,-0.000263,0.002855,0.072509,293.231689,14.937934,0.725087,-127.126556,294.500458,0.000000
99.730003,65.875671,-127.037598,-0.000250,0.002855,0.072509,293.029633,14.927641,0.725087,-127.037598,294.500458,0.000000
100.070007,65.871933,-127.037598,-0.000254,0.002855,0.072509,293.013000,14.926793,0.725087,-127.037598,294.500458,0.000000
100.410004,65.826141,-127.171036,-0.000246,0.002855,0.072509,292.809296,14.916417,0.725087,-127.171036,294.500458,0.000000
100.750008,65.903595,-127.126556,-0.000229,0.002855,0.072509,293.153839,14.933968,0.725087,-127.126556,294.500458,0.000000
101.090004,65.887955,-127.126556,-0.000254,0.002855,0.072509,293.084259,14.930425,0.725087,-127.126556,294.500458,0.000000
101.430008,65.893158,-127.171036,-0.000246,0.002855,0.072509,293.107391,14.931602,0.725087,-127.171036,294.500458,0.000000
101.770004,65.902481,-127.171036,-0.000250,0.002855,0.072509,293.148865,14.933715,0.725087,-127.171036,294.500458,0.000000
102.110008,65.870071,-127.260002,-0.000250,0.002855,0.072509,293.004700,14.926372,0.725087,-127.260002,294.500458,0.000000
102.450005,65.905823,-127.215523,-0.000263,0.002855,0.072509,293.163727,14.934472,0.725087,-127.215523,294.500458,0.000000
102.790009,65.873795,-127.304482,-0.000259,0.002855,0.072509,293.021271,14.927216,0.725087,-127.304482,294.500458,0.000000
103.130005,65.801941,-127.260002,-0.000263,0.002855,0.072509,292.701660,14.910933,0.725087,-127.260002,294.500458,0.000000
103.470001,65.804169,-127.215523,-0.000263,0.002855,0.072509,292.711548,14.911438,0.725087,-127.215523,294.500458,0.000000
103.810005,65.801941,-127.348961,-0.000259,0.002855,0.072509,292.701660,14.910933,0.725087,-127.348961,294.500458,0.000000
104.150002,65.775497,-127.348961,-0.000267,0.002855,0.072509,292.584015,14.904941,0.725087,-127.348961,294.500458,0.000000
104.490005,65.811981,-127.393440,-0.000259,0.002855,0.072509,292.746307,14.913208,0.725087,-127.393440,294.500458,0.000000
104.830002,65.815338,-127.393440,-0.000254,0.002855,0.072509,292.761230,14.913969,0.725087,-127.393440,294.500458,0.000000
105.170006,65.795227,-127.348961,-0.000254,0.002855,0.072509,292.671783,14.909411,0.725087,-127.348961,294.500458,0.000000
105.510002,65.788895,-127.482407,-0.000250,0.002855,0.072509,292.643616,14.907976,0.725087,-127.482407,294.500458,0.000000
105.850006,65.785172,-127.437927,-0.000246,0.002855,0.072509,292.627045,14.907133,0.725087,-127.437927,294.500458,0.000000
106.190002,65.749435,-127.482407,-0.000246,0.002855,0.072509,292.468109,14.899035,0.725087,-127.482407,294.500458,0.000000
106.530006,65.778107,-127.437927,-0.000254,0.002855,0.072509,292.595642,14.905532,0.725087,-127.437927,294.500458,0.000000
106.870003,65.769913,-127.437927,-0.000259,0.002855,0.072509,292.559174,14.903675,0.725087,-127.437927,294.500458,0.000000
107.210007,65.787415,-127.571365,-0.000250,0.002855,0.072509,292.637024,14.907641,0.725087,-127.571365,294.500458,0.000000
107.550003,65.737137,-127.482407,-0.000250,0.002855,0.072509,292.413391,14.896248,0.725087,-127.482407,294.500458,0.000000
107.890007,65.685760,-127.526886,-0.000254,0.002855,0.072509,292.184845,14.884606,0.725087,-127.526886,294.500458,0.000000
108.230003,65.690964,-127.571365,-0.000250,0.002855,0.072509,292.208008,14.885785,0.725087,-127.571365,294.500458,0.000000
108.570007,65.694687,-127.526886,-0.000250,0.002855,0.072509,292.224548,14.886628,0.725087,-127.526886,294.500458,0.000000
108.910004,65.689850,-127.615852,-0.000259,0.002855,0.072509,292.203033,14.885532,0.725087,-127.615852,294.500458,0.000000
109.250008,65.674957,-127.615852,-0.000250,0.002855,0.072509,292.136810,14.882158,0.725087,-127.615852,294.500458,0.000000
109.590004,65.654099,-127.660332,-0.000259,0.002855,0.072509,292.044006,14.877431,0.725087,-127.660332,294.500458,0.000000
109.930008,65.615372,-127.704811,-0.000259,0.002855,0.072509,291.871765,14.868656,0.725087,-127.704811,294.500458,0.000000
110.270004,65.625061,-127.660332,-0.000263,0.002855,0.072509,291.914856,14.870852,0.725087,-127.660332,294.500458,0.000000
110.610008,65.610901,-127.704811,-0.000259,0.002855,0.072509,291.851868,14.867642,0.725087,-127.704811,294.500458,0.000000
110.950005,65.614258,-127.704811,-0.000254,0.002855,0.072509,291.866791,14.868403,0.725087,-127.704811,294.500458,0.000000
111.290009,65.602722,-127.660332,-0.000246,0.002855,0.072509,291.815491,14.865789,0.725087,-127.660332,294.500458,0.000000
111.630005,65.603836,-127.793770,-0.000254,0.002855,0.072509,291.820435,14.866042,0.725087,-127.793770,294.500458,0.000000
111.970009,65.593781,-127.838257,-0.000263,0.002855,0.072509,291.775696,14.863764,0.725087,-127.838257,294.500458,0.000000
112.310005,65.581497,-127.793770,-0.000250,0.002855,0.072517,291.721069,14.860980,0.725174,-127.793770,294.500458,0.000000
112.650009,65.577393,-127.793770,-0.000259,0.002855,0.072517,291.702820,14.860049,0.725174,-127.793770,294.500458,0.000000
112.990005,65.571808,-127.793770,-0.000246,0.002855,0.072517,291.677979,14.858784,0.725174,-127.793770,294.500458,0.000000
113.330002,65.565475,-127.838257,-0.000254,0.002855,0.072517,291.649811,14.857348,0.725174,-127.838257,294.500458,0.000000
113.670006,65.556915,-127.882736,-0.000259,0.002855,0.072517,291.611725,14.855410,0.725174,-127.882736,294.500458,0.000000
114.010002,65.555420,-127.882736,-0.000276,0.002855,0.072517,291.605072,14.855071,0.725174,-127.882736,294.500458,0.000000
114.350006,65.559891,-127.927216,-0.000250,0.002855,0.072517,291.624969,14.856084,0.725174,-127.927216,294.500458,0.000000
114.690002,65.544250,-127.882736,-0.000267,0.002855,0.072517,291.555389,14.852540,0.725174,-127.882736,294.500458,0.000000
115.030006,65.526749,-127.971695,-0.000250,0.002855,0.072517,291.477539,14.848574,0.725174,-127.971695,294.500458,0.000000
115.370003,65.529724,-127.971695,-0.000250,0.002855,0.072517,291.490784,14.849248,0.725174,-127.971695,294.500458,0.000000
115.710007,65.517807,-128.016174,-0.000246,0.002855,0.072517,291.437775,14.846547,0.725174,-128.016174,294.500458,0.000000
116.050003,65.518188,-127.971695,-0.000250,0.002855,0.072517,291.439453,14.846633,0.725174,-127.971695,294.500458,0.000000
116.390007,65.509628,-127.971695,-0.000254,0.002855,0.072517,291.401367,14.844694,0.725174,-127.971695,294.500458,0.000000
116.730003,65.505524,-128.060654,-0.000250,0.002855,0.072517,291.383118,14.843763,0.725174,-128.060654,294.500458,0.000000
117.070007,65.506271,-128.105133,-0.000263,0.002855,0.072517,291.386444,14.843933,0.725174,-128.105133,294.500458,0.000000
117.410004,65.508881,-128.105133,-0.000254,0.002855,0.072517,291.398041,14.844524,0.725174,-128.105133,294.500458,0.000000
117.750008,65.496216,-128.060654,-0.000254,0.002855,0.072517,291.341705,14.841655,0.725174,-128.060654,294.500458,0.000000
118.090004,65.486160,-128.105133,-0.000263,0.002855,0.072517,291.296997,14.839376,0.725174,-128.105133,294.500458,0.000000
118.430008,65.489517,-128.149612,-0.000246,0.002855,0.072517,291.311920,14.840137,0.725174,-128.149612,294.500458,0.000000
118.770004,65.467545,-128.149612,-0.000263,0.002855,0.072517,291.214172,14.835157,0.725174,-128.149612,294.500458,0.000000
119.110008,65.454514,-128.194107,-0.000259,0.002855,0.072517,291.156219,14.832205,0.725174,-128.194107,294.500458,0.000000
119.450005,65.453018,-128.194107,-0.000250,0.002855,0.072517,291.149567,14.831865,0.725174,-128.194107,294.500458,0.000000
119.790009,65.440735,-128.194107,-0.000250,0.002855,0.072509,291.094940,14.829082,0.725087,-128.194107,0.072517,0.000000
120.130005,65.398651,-128.283066,-0.000246,0.002854,0.072500,290.907715,14.819546,0.725001,-128.283066,0.071971,0.000000
120.470009,65.413177,-128.238586,-0.000267,0.002835,0.072006,290.972351,14.822838,0.720057,-128.238586,0.071407,0.000000
120.810005,65.346146,-128.283066,-0.000259,0.002810,0.071364,290.674164,14.807648,0.713640,-128.283066,0.070844,0.000000
121.150009,65.368866,-128.283066,-0.000250,0.002791,0.070887,290.775238,14.812798,0.708870,-128.283066,0.070271,0.000000
121.490005,65.367752,-128.327545,-0.000263,0.002776,0.070523,290.770294,14.812545,0.705228,-128.327545,0.069708,0.000000
121.830009,65.345779,-128.372025,-0.000250,0.002746,0.069742,290.672546,14.807566,0.697423,-128.372025,0.069135,0.000000
122.170006,65.340561,-128.372025,-0.000259,0.002730,0.069335,290.649323,14.806382,0.693347,-128.372025,0.068572,0.000000
122.510002,65.274277,-128.416504,-0.000250,0.002699,0.068546,290.354492,14.791362,0.685455,-128.416504,0.068008,0.000000
122.850006,65.085495,-128.372025,-0.000259,0.002679,0.068043,289.514740,14.748584,0.680425,-128.372025,0.067435,0.000000
123.190002,65.010269,-128.505463,-0.000259,0.002663,0.067644,289.180115,14.731537,0.676436,-128.505463,0.066872,0.000000
123.530006,64.486343,-128.416504,-0.000254,0.002639,0.067019,286.849579,14.612814,0.670192,-128.416504,0.066308,0.000000
123.870003,63.762451,-128.505463,-0.000272,0.002618,0.066490,283.629547,14.448778,0.664902,-128.505463,0.065736,0.000000
124.210007,63.177078,-128.505463,-0.000254,0.002600,0.066048,281.025665,14.316131,0.660479,-128.505463,0.065172,0.000000
124.550003,61.584816,-128.460983,-0.000250,0.002571,0.065311,273.942932,13.955318,0.653108,-128.460983,0.064608,0.000000
124.890007,60.217094,-128.505463,-0.000224,0.002553,0.064834,267.859009,13.645389,0.648338,-128.505463,0.064036,0.000000
125.230003,59.037041,-128.460983,-0.000207,0.002537,0.064452,262.609863,13.377985,0.644522,-128.460983,0.063472,0.000000
125.570007,58.006317,-128.505463,-0.000198,0.002528,0.064209,258.024994,13.144420,0.642094,-128.505463,0.062909,0.000000
125.910004,54.918976,-128.638916,-0.000194,0.002492,0.063290,244.291809,12.444818,0.632901,-128.638916,0.062336,0.000000
126.250008,52.932373,-128.549942,-0.000198,0.002472,0.062787,235.454956,11.994647,0.627871,-128.549942,0.061772,0.000000
126.590004,50.368584,-128.594437,-0.000203,0.002447,0.062154,224.050644,11.413685,0.621541,-128.594437,0.061209,0.000000
126.930008,48.157440,-128.638916,-0.000198,0.002428,0.061660,214.214996,10.912632,0.616597,-128.638916,0.060636,0.000000
127.270004,46.235626,-128.683395,-0.000207,0.002407,0.061148,205.666336,10.477142,0.611481,-128.683395,0.060073,0.000000
127.610008,43.125938,-128.683395,-0.000194,0.002382,0.060515,191.833755,9.772477,0.605150,-128.683395,0.059509,0.000000
127.950005,40.760262,-128.638916,-0.000203,0.002363,0.060029,181.310699,9.236406,0.600294,-128.638916,0.058937,0.000000
128.290009,39.344872,-128.727875,-0.000203,0.002350,0.059682,175.014725,8.915676,0.596825,-128.727875,0.058373,0.000000
128.630005,35.744400,-128.683395,-0.000190,0.002316,0.058833,158.999039,8.099796,0.588326,-128.683395,0.057809,0.000000
128.970001,33.191040,-128.727875,-0.000207,0.002295,0.058304,147.641113,7.521197,0.583036,-128.727875,0.057237,0.000000
129.310013,30.791100,-128.772354,-0.000185,0.002273,0.057723,136.965652,6.977363,0.577225,-128.772354,0.056673,0.000000
129.650009,28.724434,-128.727875,-0.000194,0.002254,0.057246,127.772667,6.509050,0.572456,-128.727875,0.056101,0.000000
129.990005,25.547729,-128.816833,-0.000198,0.002226,0.056552,113.641975,5.789198,0.565518,-128.816833,0.055537,0.000000
130.330002,23.686234,-128.861313,-0.000190,0.002209,0.056109,105.361626,5.367377,0.561095,-128.861313,0.054973,0.000000
130.670013,20.219078,-128.861313,-0.000194,0.002182,0.055424,89.938950,4.581709,0.554244,-128.861313,0.054401,0.000000
131.010010,18.113686,-128.905792,-0.000181,0.002162,0.054904,80.573700,4.104620,0.549041,-128.905792,0.053837,0.000000
131.350006,15.456436,-128.861313,-0.000190,0.002140,0.054349,68.753662,3.502479,0.543490,-128.861313,0.053274,0.000000
131.690002,12.856903,-128.950272,-0.000185,0.002119,0.053811,57.190361,2.913416,0.538114,-128.950272,0.052701,0.000000
132.029999,9.918510,-128.861313,-0.000194,0.002090,0.053083,44.119740,2.247567,0.530829,-128.861313,0.052138,0.000000
132.370010,7.592300,-128.905792,-0.000198,0.002068,0.052528,33.772240,1.720440,0.525279,-128.905792,0.051574,0.000000
132.710007,4.864670,-128.950272,-0.000190,0.002046,0.051973,21.639132,1.102350,0.519728,-128.950272,0.051002,0.000000
133.050003,2.324348,-128.950272,-0.000194,0.002024,0.051409,10.339218,0.526705,0.514091,-128.950272,0.050438,0.000000
133.389999,0.654625,-128.994751,-0.000203,0.002008,0.050993,2.911917,0.148340,0.509929,-128.994751,0.049874,0.000000
133.730011,-0.699318,-129.039246,-0.000198,0.001985,0.050429,-3.110722,-0.158468,0.504292,-129.039246,0.049302,0.000000
134.070007,0.105751,-129.039246,-0.000190,0.001959,0.049753,0.470404,0.023964,0.497527,-129.039246,0.048738,0.000000
134.410004,0.093834,-128.994751,-0.000172,0.001935,0.049137,0.417394,0.021263,0.491370,-128.994751,0.048174,0.000000
134.750000,0.102028,-129.039246,-0.000198,0.001913,0.048591,0.453843,0.023120,0.485907,-129.039246,0.047602,0.000000
135.090012,0.068886,-129.128204,-0.000190,0.001890,0.048018,0.306419,0.015610,0.480183,-129.128204,0.047038,0.000000
135.430008,0.052132,-129.039246,-0.000177,0.001871,0.047533,0.231893,0.011813,0.475326,-129.039246,0.046475,0.000000
135.770004,0.028671,-129.172684,-0.000185,0.001849,0.046960,0.127536,0.006497,0.469603,-129.172684,0.045902,0.000000
136.110001,0.030907,-129.172684,-0.000172,0.001831,0.046501,0.137480,0.007004,0.465006,-129.172684,0.045339,0.000000
136.450012,0.030907,-129.128204,-0.000229,0.001800,0.045720,0.137480,0.007004,0.457201,-129.128204,0.044775,0.000000
136.790009,0.023453,-129.172684,-0.000272,0.001783,0.045278,0.104323,0.005314,0.452779,-129.172684,0.044202,0.000000
137.130005,-0.004471,-129.172684,-0.000302,0.001757,0.044636,-0.019887,-0.001013,0.446361,-129.172684,0.043639,0.000000
137.470001,-0.012665,-129.261642,-0.000358,0.001734,0.044038,-0.056336,-0.002870,0.440377,-129.261642,0.043075,0.000000
137.810013,0.001862,-129.217163,-0.000371,0.001717,0.043621,0.008281,0.000422,0.436215,-129.217163,0.042503,0.000000
138.150009,0.003349,-129.217163,-0.000414,0.001696,0.043075,0.014898,0.000759,0.430751,-129.217163,0.041939,0.000000
138.490005,-0.044319,-129.306122,-0.000453,0.001668,0.042373,-0.197141,-0.010043,0.423726,-129.306122,0.041367,0.000000
138.830002,-0.072243,-129.261642,-0.000470,0.001645,0.041792,-0.321352,-0.016370,0.417916,-129.261642,0.040803,0.000000
139.170013,-0.000748,-129.350601,-0.000483,0.001634,0.041514,-0.003326,-0.000169,0.415141,-129.350601,0.041427,0.000000
139.300003,0.008186,-129.350601,-0.000504,0.001635,0.041523,0.036415,0.001855,0.415228,-129.350601,0.041427,0.000000