File: Data/compression 32/AutoNoHeating-12-32-reverse-1-3_11142024_181110.csv
Time (sec),S:Load (lbs),S:HL1 (DIM),S:LVDT (in),S:Position (in),Ch:Position (mm),Ch:Load (N),Ch:Stress (MPa),Ch:Strain (mm/mm),Ch:HL1 (DIM),Set Point (),Cycles ()
0.110000,-0.059959,-98.836670,-0.010710,-0.005827,-0.148009,-0.266713,-0.013587,-1.480094,-98.836670,-0.147793,0.000000
0.490000,-0.027557,-98.881157,-0.010705,-0.005777,-0.146735,-0.122581,-0.006245,-1.467346,-98.881157,-0.145937,0.000000
0.870000,-0.081551,-98.881157,-0.010602,-0.005546,-0.140872,-0.362755,-0.018480,-1.408721,-98.881157,-0.139606,0.000000
1.250000,-0.061447,-98.925636,-0.010348,-0.005291,-0.134394,-0.273331,-0.013924,-1.343940,-98.925636,-0.133275,0.000000
1.630000,-0.014153,-98.925636,-0.010106,-0.005045,-0.128150,-0.062954,-0.003207,-1.281499,-98.925636,-0.126944,0.000000
2.010000,-0.014153,-98.970116,-0.009856,-0.004794,-0.121758,-0.062954,-0.003207,-1.217585,-98.970116,-0.120614,0.000000
2.390000,-0.004471,-98.970116,-0.009585,-0.004548,-0.115514,-0.019887,-0.001013,-1.155145,-98.970116,-0.114283,0.000000
2.770000,-0.018997,-99.014595,-0.009347,-0.004302,-0.109270,-0.084504,-0.004305,-1.092704,-99.014595,-0.107952,0.000000
3.150000,-0.032402,-99.059074,-0.009089,-0.004046,-0.102766,-0.144131,-0.007342,-1.027663,-99.059074,-0.101622,0.000000
3.530000,0.019363,-99.014595,-0.008826,-0.003800,-0.096522,0.086133,0.004388,-0.965222,-99.014595,-0.095291,0.000000
3.910000,0.038727,-99.103561,-0.008550,-0.003546,-0.090079,0.172265,0.008776,-0.900787,-99.103561,-0.088960,0.000000
4.290000,0.033508,-99.059074,-0.008291,-0.003299,-0.083783,0.149052,0.007593,-0.837827,-99.059074,-0.082629,0.000000
4.670000,-0.005219,-99.192520,-0.008067,-0.003058,-0.077669,-0.023213,-0.001183,-0.776687,-99.192520,-0.076299,0.000000
5.050000,-0.009682,-99.148041,-0.007787,-0.002804,-0.071217,-0.043066,-0.002194,-0.712166,-99.148041,-0.069968,0.000000
5.430000,-0.011551,-99.192520,-0.007528,-0.002555,-0.064886,-0.051381,-0.002617,-0.648858,-99.192520,-0.063637,0.000000
5.810000,0.024200,-99.148041,-0.007274,-0.002305,-0.058555,0.107649,0.005484,-0.585551,-99.148041,-0.057306,0.000000
6.190000,0.058456,-99.237000,-0.007023,-0.002056,-0.052224,0.260027,0.013246,-0.522243,-99.237000,-0.050976,0.000000
6.570000,0.029045,-99.192520,-0.006756,-0.001804,-0.045833,0.129199,0.006582,-0.458329,-99.192520,-0.044645,0.000000
6.950000,0.011169,-99.325966,-0.006506,-0.001559,-0.039589,0.049684,0.002531,-0.395889,-99.325966,-0.038314,0.000000
7.330000,-0.010803,-99.281487,-0.006260,-0.001308,-0.033232,-0.048055,-0.002448,-0.332321,-99.281487,-0.031983,0.000000
7.710001,0.020851,-99.281487,-0.005997,-0.001061,-0.026962,0.092750,0.004725,-0.269620,-99.281487,-0.025653,0.000000
8.090000,0.036118,-99.325966,-0.005743,-0.000809,-0.020553,0.160659,0.008184,-0.205533,-99.325966,-0.019322,0.000000
8.470000,0.033508,-99.325966,-0.005484,-0.000560,-0.014222,0.149052,0.007593,-0.142225,-99.325966,-0.012991,0.000000
8.850000,-0.000000,-99.370445,-0.005234,-0.000317,-0.008048,-0.000000,-0.000000,-0.080479,-99.370445,-0.006660,0.000000
9.230000,0.016754,-99.370445,-0.004975,-0.000069,-0.001760,0.074526,0.003797,-0.017605,-99.370445,-0.000330,0.000000
9.610001,0.085266,-99.370445,-0.004919,-0.000010,-0.000251,0.379283,0.019322,-0.002515,-99.370445,-0.000026,0.000000
9.990001,0.107986,-99.459404,-0.004907,-0.000010,-0.000251,0.480348,0.024470,-0.002515,-99.459404,0.000286,0.000000
10.370001,0.122131,-99.459404,-0.004915,-0.000002,-0.000043,0.543267,0.027675,-0.000434,-99.459404,0.000919,0.000000
10.750001,0.133675,-99.592850,-0.004907,0.000022,0.000546,0.594614,0.030291,0.005464,-99.592850,0.001552,0.000000
11.130000,0.201447,-99.592850,-0.004876,0.000050,0.001257,0.896079,0.045648,0.012575,-99.592850,0.002185,0.000000
11.510000,0.280022,-99.503891,-0.004855,0.000071,0.001813,1.245599,0.063454,0.018125,-99.503891,0.002818,0.000000
11.890000,0.468071,-99.548370,-0.004829,0.000096,0.002437,2.082084,0.106066,0.024369,-99.548370,0.003452,0.000000
12.270000,0.692978,-99.548370,-0.004812,0.000121,0.003079,3.082520,0.157031,0.030787,-99.548370,0.004085,0.000000
12.650001,0.863159,-99.637329,-0.004786,0.000147,0.003746,3.839524,0.195595,0.037464,-99.637329,0.004718,0.000000
13.030001,1.072426,-99.681808,-0.004751,0.000176,0.004466,4.770389,0.243015,0.044662,-99.681808,0.005351,0.000000
13.410001,1.200897,-99.681808,-0.004747,0.000190,0.004830,5.341857,0.272127,0.048304,-99.681808,0.005984,0.000000
13.790001,1.380005,-99.681808,-0.004730,0.000208,0.005281,6.138568,0.312714,0.052814,-99.681808,0.006617,0.000000
14.170001,1.841003,-99.681808,-0.004687,0.000239,0.006079,8.189192,0.417177,0.060793,-99.681808,0.007259,0.000000
14.550001,2.290459,-99.770775,-0.004665,0.000275,0.006981,10.188469,0.519025,0.069812,-99.770775,0.007892,0.000000
14.930000,2.568993,-99.859734,-0.004661,0.000302,0.007675,11.427450,0.582142,0.076749,-99.859734,0.008525,0.000000
15.310000,2.755554,-99.770775,-0.004631,0.000321,0.008152,12.257318,0.624417,0.081519,-99.770775,0.009158,0.000000
15.690001,3.075790,-99.815254,-0.004600,0.000340,0.008646,13.681799,0.696984,0.086462,-99.815254,0.009791,0.000000
16.070002,3.452263,-99.815254,-0.004587,0.000364,0.009236,15.356432,0.782294,0.092360,-99.815254,0.010424,0.000000
16.450001,3.902458,-99.904213,-0.004557,0.000395,0.010034,17.359001,0.884310,0.100338,-99.904213,0.011057,0.000000
16.830000,3.988853,-99.904213,-0.004544,0.000408,0.010372,17.743307,0.903887,0.103720,-99.904213,0.011690,0.000000
17.210001,4.560066,-99.904213,-0.004506,0.000445,0.011309,20.284187,1.033326,0.113086,-99.904213,0.012323,0.000000
17.590000,4.943611,-99.948700,-0.004488,0.000469,0.011916,21.990280,1.120238,0.119157,-99.948700,0.012956,0.000000
17.970001,5.261246,-99.948700,-0.004467,0.000493,0.012531,23.403191,1.192215,0.125314,-99.948700,0.013589,0.000000
18.350000,5.495842,-100.037659,-0.004441,0.000511,0.012991,24.446726,1.245376,0.129910,-100.037659,0.014223,0.000000
18.730001,6.160896,-100.037659,-0.004406,0.000548,0.013919,27.405035,1.396079,0.139190,-100.037659,0.014856,0.000000
19.110001,6.295326,-99.993179,-0.004393,0.000569,0.014457,28.003010,1.426541,0.144567,-99.993179,0.015489,0.000000
19.490002,6.780525,-100.037659,-0.004368,0.000596,0.015142,30.161282,1.536489,0.151418,-100.037659,0.016122,0.000000
19.870001,7.087730,-100.037659,-0.004342,0.000618,0.015705,31.527800,1.606103,0.157055,-100.037659,0.016755,0.000000
20.250002,7.496223,-100.171104,-0.004324,0.000647,0.016425,33.344868,1.698669,0.164253,-100.171104,0.017388,0.000000
20.630001,7.949028,-100.171104,-0.004307,0.000677,0.017188,35.359043,1.801275,0.171884,-100.171104,0.018021,0.000000
21.010000,8.007492,-100.215584,-0.004268,0.000698,0.017735,35.619102,1.814524,0.177348,-100.215584,0.018654,0.000000
21.390001,8.307625,-100.171104,-0.004251,0.000720,0.018298,36.954163,1.882535,0.182985,-100.171104,0.019287,0.000000
21.770000,8.700851,-100.215584,-0.004208,0.000744,0.018897,38.703320,1.971641,0.188968,-100.215584,0.019920,0.000000
22.150002,8.891502,-100.260063,-0.004195,0.000766,0.019461,39.551376,2.014843,0.194605,-100.260063,0.020553,0.000000
22.530001,9.338722,-100.304543,-0.004186,0.000793,0.020154,41.540710,2.116185,0.201543,-100.304543,0.021186,0.000000
22.910002,9.643326,-100.304543,-0.004161,0.000820,0.020831,42.895657,2.185209,0.208308,-100.304543,0.021819,0.000000
23.290001,9.801208,-100.260063,-0.004122,0.000841,0.021368,43.597954,2.220986,0.213684,-100.260063,0.022452,0.000000
23.670002,10.039154,-100.304543,-0.004109,0.000867,0.022010,44.656387,2.274905,0.220102,-100.304543,0.023086,0.000000
24.050001,10.454353,-100.349022,-0.004066,0.000892,0.022669,46.503284,2.368990,0.226693,-100.349022,0.023719,0.000000
24.430000,10.760818,-100.437988,-0.004044,0.000916,0.023259,47.866512,2.438437,0.232590,-100.437988,0.024352,0.000000
24.810001,11.139145,-100.393509,-0.004023,0.000945,0.024005,49.549393,2.524166,0.240048,-100.393509,0.024985,0.000000
25.190001,11.005089,-100.437988,-0.003997,0.000959,0.024369,48.953079,2.493789,0.243690,-100.437988,0.025627,0.000000
25.570002,11.656746,-100.437988,-0.003971,0.000993,0.025228,51.851795,2.641456,0.252276,-100.437988,0.026260,0.000000
25.950001,11.801971,-100.482468,-0.003941,0.001016,0.025809,52.497791,2.674365,0.258086,-100.482468,0.026893,0.000000
26.330002,12.169128,-100.526947,-0.003928,0.001043,0.026485,54.130985,2.757564,0.264851,-100.526947,0.027526,0.000000
26.710001,12.468140,-100.571434,-0.003915,0.001071,0.027196,55.461056,2.825321,0.271962,-100.571434,0.028159,0.000000
27.090002,12.324409,-100.571434,-0.003867,0.001091,0.027699,54.821712,2.792751,0.276992,-100.571434,0.028792,0.000000
27.470001,12.774231,-100.615913,-0.003859,0.001113,0.028263,56.822617,2.894682,0.282629,-100.615913,0.029425,0.000000
27.850000,13.190170,-100.615913,-0.003824,0.001140,0.028957,58.672810,2.988935,0.289567,-100.615913,0.030058,0.000000
28.230001,13.241562,-100.615913,-0.003807,0.001164,0.029555,58.901409,3.000581,0.295551,-100.615913,0.030691,0.000000
28.610001,13.506317,-100.660393,-0.003786,0.001185,0.030110,60.079098,3.060575,0.301101,-100.660393,0.031324,0.000000
28.990002,13.711121,-100.660393,-0.003747,0.001212,0.030787,60.990112,3.106984,0.307865,-100.660393,0.031957,0.000000
29.370001,13.572975,-100.704872,-0.003747,0.001226,0.031142,60.375610,3.075680,0.311421,-100.704872,0.032590,0.000000
29.750002,14.563858,-100.749352,-0.003686,0.001269,0.032226,64.783279,3.300217,0.322261,-100.749352,0.033223,0.000000
30.130001,14.245102,-100.793839,-0.003673,0.001286,0.032677,63.365379,3.227986,0.326771,-100.793839,0.033856,0.000000
30.510002,14.604446,-100.793839,-0.003652,0.001317,0.033440,64.963821,3.309415,0.334402,-100.793839,0.034490,0.000000
30.890001,14.752274,-100.793839,-0.003617,0.001337,0.033961,65.621391,3.342913,0.339606,-100.793839,0.035123,0.000000
31.270002,14.548958,-100.793839,-0.003591,0.001354,0.034385,64.716995,3.296841,0.343855,-100.793839,0.035756,0.000000
31.650002,15.679855,-100.793839,-0.003566,0.001394,0.035409,69.747482,3.553106,0.354088,-100.793839,0.036389,0.000000
32.030003,15.341370,-100.927277,-0.003535,0.001410,0.035816,68.241821,3.476404,0.358164,-100.927277,0.037022,0.000000
32.410000,15.959137,-100.927277,-0.003501,0.001446,0.036727,70.989784,3.616392,0.367270,-100.927277,0.037655,0.000000
32.790001,15.634796,-100.927277,-0.003466,0.001464,0.037195,69.547050,3.542896,0.371953,-100.927277,0.038288,0.000000
33.170002,16.153885,-100.927277,-0.003458,0.001491,0.037872,71.856071,3.660523,0.378717,-100.927277,0.038921,0.000000
33.550003,16.484924,-100.971756,-0.003410,0.001519,0.038583,73.328606,3.735537,0.385829,-100.971756,0.039554,0.000000
33.930000,16.567963,-101.016243,-0.003397,0.001544,0.039225,73.697975,3.754354,0.392246,-101.016243,0.040187,0.000000
34.310001,16.822670,-101.060722,-0.003372,0.001572,0.039927,74.830971,3.812072,0.399271,-101.060722,0.040820,0.000000
34.690002,16.405235,-101.016243,-0.003333,0.001589,0.040352,72.974129,3.717479,0.403520,-101.016243,0.041453,0.000000
35.070004,16.315125,-101.016243,-0.003316,0.001606,0.040803,72.573296,3.697060,0.408030,-101.016243,0.042086,0.000000
35.450001,17.170837,-101.105202,-0.003303,0.001642,0.041714,76.379700,3.890967,0.417136,-101.105202,0.042720,0.000000
35.830002,17.441551,-101.194160,-0.003255,0.001669,0.042381,77.583893,3.952312,0.423813,-101.194160,0.043353,0.000000
36.210003,17.724556,-101.149681,-0.003234,0.001698,0.043127,78.842766,4.016442,0.431271,-101.149681,0.043994,0.000000
36.590000,17.238609,-101.149681,-0.003199,0.001718,0.043639,76.681168,3.906325,0.436388,-101.149681,0.044627,0.000000
36.970001,17.256851,-101.149681,-0.003178,0.001742,0.044237,76.762306,3.910458,0.442372,-101.149681,0.045261,0.000000
37.350002,17.374153,-101.194160,-0.003152,0.001761,0.044732,77.284096,3.937039,0.447315,-101.194160,0.045894,0.000000
37.730003,17.865685,-101.238647,-0.003126,0.001793,0.045538,79.470535,4.048422,0.455380,-101.238647,0.046527,0.000000
38.110001,18.029152,-101.372086,-0.003091,0.001819,0.046197,80.197670,4.085464,0.461971,-101.372086,0.047160,0.000000
38.490002,17.946487,-101.283127,-0.003070,0.001842,0.046795,79.829964,4.066732,0.467955,-101.283127,0.047793,0.000000
38.870003,17.950211,-101.283127,-0.003027,0.001865,0.047359,79.846527,4.067576,0.473592,-101.283127,0.048426,0.000000
39.250000,17.998619,-101.327606,-0.003005,0.001888,0.047966,80.061859,4.078545,0.479663,-101.327606,0.049059,0.000000
39.630001,18.318863,-101.327606,-0.002971,0.001916,0.048669,81.486374,4.151114,0.486687,-101.327606,0.049692,0.000000
40.010002,18.514725,-101.372086,-0.002932,0.001945,0.049415,82.357613,4.195497,0.494145,-101.372086,0.050325,0.000000
40.390003,18.339340,-101.505531,-0.002923,0.001967,0.049952,81.577461,4.155754,0.499522,-101.505531,0.050958,0.000000
40.770000,18.703148,-101.416565,-0.002893,0.001993,0.050629,83.195755,4.238194,0.506286,-101.416565,0.051591,0.000000
41.150002,18.602982,-101.416565,-0.002859,0.002016,0.051201,82.750198,4.215496,0.512010,-101.416565,0.052224,0.000000
41.530003,18.933647,-101.505531,-0.002833,0.002043,0.051886,84.221069,4.290426,0.518861,-101.505531,0.052857,0.000000
41.910004,19.072540,-101.550011,-0.002798,0.002071,0.052606,84.838898,4.321899,0.526059,-101.550011,0.053490,0.000000
42.290001,18.981308,-101.550011,-0.002768,0.002093,0.053161,84.433075,4.301226,0.531609,-101.550011,0.054124,0.000000
42.670002,19.068817,-101.550011,-0.002751,0.002117,0.053759,84.822334,4.321056,0.537593,-101.550011,0.054757,0.000000
43.050003,19.260963,-101.594490,-0.002725,0.002140,0.054349,85.677048,4.364597,0.543490,-101.594490,0.055390,0.000000
43.430000,19.351448,-101.550011,-0.002677,0.002162,0.054913,86.079536,4.385101,0.549127,-101.550011,0.056023,0.000000
43.810001,19.542847,-101.638969,-0.002673,0.002189,0.055589,86.930923,4.428473,0.555892,-101.638969,0.056656,0.000000
44.190002,19.975174,-101.683456,-0.002634,0.002217,0.056318,88.854012,4.526439,0.563176,-101.683456,0.057289,0.000000
44.570004,19.907776,-101.727936,-0.002600,0.002239,0.056881,88.554207,4.511167,0.568813,-101.727936,0.057922,0.000000
44.950001,19.888412,-101.683456,-0.002574,0.002262,0.057462,88.468079,4.506779,0.574624,-101.683456,0.058555,0.000000
45.330002,20.051140,-101.683456,-0.002539,0.002287,0.058078,89.191925,4.543653,0.580781,-101.683456,0.059188,0.000000
45.710003,20.495750,-101.772415,-0.002527,0.002314,0.058781,91.169655,4.644403,0.587806,-101.772415,0.059821,0.000000
46.090004,20.619003,-101.816895,-0.002501,0.002342,0.059492,91.717911,4.672333,0.594917,-101.816895,0.060454,0.000000
46.470001,20.136780,-101.816895,-0.002475,0.002357,0.059873,89.572868,4.563059,0.598733,-101.816895,0.061087,0.000000
46.850002,20.823067,-101.772415,-0.002432,0.002389,0.060680,92.625626,4.718575,0.606798,-101.772415,0.061720,0.000000
47.230003,20.804817,-101.816895,-0.002419,0.002413,0.061278,92.544449,4.714439,0.612782,-101.816895,0.062362,0.000000
47.610001,20.934029,-101.861382,-0.002367,0.002440,0.061972,93.119209,4.743719,0.619720,-101.861382,0.062995,0.000000
47.990002,21.163414,-101.950340,-0.002363,0.002467,0.062666,94.139565,4.795698,0.626657,-101.950340,0.063628,0.000000
48.370003,20.659218,-101.950340,-0.002328,0.002486,0.063143,91.896790,4.681446,0.631427,-101.950340,0.064261,0.000000
48.750004,20.384041,-101.994820,-0.002298,0.002503,0.063568,90.672745,4.619090,0.635676,-101.994820,0.064894,0.000000
49.130001,21.392052,-101.994820,-0.002276,0.002538,0.064461,95.156601,4.847508,0.644609,-101.994820,0.065528,0.000000
49.510002,20.944832,-101.950340,-0.002246,0.002560,0.065016,93.167267,4.746167,0.650159,-101.950340,0.066161,0.000000
49.890003,21.180542,-102.039299,-0.002216,0.002584,0.065623,94.215759,4.799579,0.656230,-102.039299,0.066794,0.000000
50.270004,21.008133,-102.039299,-0.002182,0.002608,0.066247,93.448845,4.760511,0.662474,-102.039299,0.067427,0.000000
50.650002,20.659218,-102.083786,-0.002147,0.002632,0.066863,91.896790,4.681446,0.668631,-102.083786,0.068060,0.000000
51.030003,21.816185,-102.083786,-0.002117,0.002666,0.067713,97.043236,4.943618,0.677130,-102.083786,0.068693,0.000000
51.410004,21.053566,-102.039299,-0.002095,0.002686,0.068233,93.650940,4.770806,0.682333,-102.039299,0.069326,0.000000
51.790001,21.444183,-102.128265,-0.002065,0.002713,0.068910,95.388489,4.859322,0.689098,-102.128265,0.069959,0.000000
52.170002,21.097504,-102.172745,-0.002031,0.002733,0.069413,93.846382,4.780763,0.694128,-102.172745,0.070592,0.000000
52.550003,20.995842,-102.172745,-0.002022,0.002754,0.069942,93.394173,4.757726,0.699418,-102.172745,0.071225,0.000000
52.930004,21.921188,-102.217224,-0.001966,0.002790,0.070861,97.510315,4.967412,0.708610,-102.217224,0.071858,0.000000
53.310001,21.260971,-102.217224,-0.001966,0.002810,0.071364,94.573524,4.817805,0.713640,-102.217224,0.072491,0.000000
53.690002,21.949120,-102.217224,-0.001927,0.002842,0.072179,97.634560,4.973742,0.721792,-102.217224,0.073124,0.000000
54.070004,21.303429,-102.350670,-0.001893,0.002860,0.072656,94.762383,4.827426,0.726562,-102.350670,0.073758,0.000000
54.450001,21.585312,-102.261703,-0.001871,0.002887,0.073324,96.016266,4.891302,0.733239,-102.261703,0.074391,0.000000
54.830002,21.924545,-102.306190,-0.001841,0.002915,0.074035,97.525246,4.968173,0.740351,-102.306190,0.075024,0.000000
55.210003,21.903320,-102.306190,-0.001815,0.002939,0.074659,97.430832,4.963363,0.746595,-102.306190,0.075657,0.000000
55.590004,22.104401,-102.439629,-0.001768,0.002967,0.075371,98.325287,5.008929,0.753706,-102.439629,0.076290,0.000000
55.970001,21.672073,-102.439629,-0.001746,0.002987,0.075865,96.402199,4.910962,0.758649,-102.439629,0.076923,0.000000
56.350002,21.383484,-102.395149,-0.001729,0.003006,0.076342,95.118484,4.845567,0.763419,-102.395149,0.077556,0.000000
56.730003,20.634644,-102.395149,-0.001716,0.003014,0.076559,91.787476,4.675877,0.765587,-102.395149,0.078189,0.000000
57.110004,23.039429,-102.439629,-0.001660,0.003065,0.077851,102.484497,5.220809,0.778509,-102.439629,0.078822,0.000000
57.490002,22.891968,-102.484108,-0.001630,0.003094,0.078579,101.828560,5.187394,0.785793,-102.484108,0.079455,0.000000
57.870003,22.076469,-102.573074,-0.001608,0.003114,0.079100,98.201042,5.002599,0.790997,-102.573074,0.080097,0.000000
58.250004,22.077957,-102.528595,-0.001582,0.003137,0.079689,98.207657,5.002937,0.796894,-102.528595,0.080730,0.000000
58.630001,22.184830,-102.484108,-0.001556,0.003160,0.080253,98.683052,5.027154,0.802531,-102.484108,0.081363,0.000000
59.010002,22.830521,-102.573074,-0.001518,0.003191,0.081051,101.555229,5.173470,0.810509,-102.573074,0.081996,0.000000
59.390003,21.879486,-102.617554,-0.001509,0.003202,0.081337,97.324814,4.957963,0.813371,-102.617554,0.082629,0.000000
59.770004,22.721794,-102.706512,-0.001479,0.003239,0.082265,101.071587,5.148832,0.822650,-102.706512,0.083262,0.000000
60.150002,22.739662,-102.617554,-0.001444,0.003263,0.082881,101.151070,5.152881,0.828808,-102.617554,0.083895,0.000000
60.530003,22.534859,-102.662033,-0.001406,0.003287,0.083479,100.240059,5.106472,0.834791,-102.662033,0.084528,0.000000
60.910004,22.652161,-102.662033,-0.001380,0.003308,0.084034,100.761841,5.133053,0.840342,-102.662033,0.085162,0.000000
61.290005,23.302322,-102.750999,-0.001354,0.003342,0.084875,103.653908,5.280382,0.848754,-102.750999,0.085795,0.000000
61.670002,22.919891,-102.750999,-0.001324,0.003362,0.085396,101.952766,5.193722,0.853957,-102.750999,0.086428,0.000000
62.050003,23.473984,-102.795479,-0.001306,0.003391,0.086124,104.417496,5.319281,0.861242,-102.795479,0.087061,0.000000
62.430004,23.422966,-102.839958,-0.001298,0.003410,0.086610,104.190559,5.307720,0.866098,-102.839958,0.087694,0.000000
62.810001,24.175537,-102.839958,-0.001259,0.003438,0.087330,107.538162,5.478255,0.873296,-102.839958,0.088327,0.000000
63.190002,24.258202,-102.839958,-0.001229,0.003462,0.087928,107.905869,5.496987,0.879280,-102.839958,0.088960,0.000000
63.570004,24.835007,-102.928925,-0.001207,0.003490,0.088656,110.471626,5.627693,0.886565,-102.928925,0.089593,0.000000
63.950005,25.085243,-102.928925,-0.001186,0.003514,0.089255,111.584732,5.684398,0.892549,-102.928925,0.090226,0.000000
64.330002,25.557411,-102.884438,-0.001160,0.003537,0.089836,113.685043,5.791392,0.898359,-102.884438,0.090859,0.000000
64.710007,26.149483,-102.973404,-0.001125,0.003560,0.090417,116.318710,5.925558,0.904170,-102.973404,0.091492,0.000000
65.090004,26.290611,-102.928925,-0.001134,0.003580,0.090920,116.946480,5.957538,0.909199,-102.928925,0.092125,0.000000
65.470001,27.916016,-103.017883,-0.001095,0.003614,0.091796,124.176636,6.325860,0.917958,-103.017883,0.092758,0.000000
65.850006,28.198273,-103.017883,-0.001082,0.003638,0.092403,125.432182,6.389820,0.924029,-103.017883,0.093392,0.000000
66.230003,28.886787,-103.017883,-0.001065,0.003661,0.092984,128.494843,6.545840,0.929839,-103.017883,0.094025,0.000000
66.610001,29.625946,-103.106842,-0.001043,0.003684,0.093574,131.782791,6.713336,0.935736,-103.106842,0.094658,0.000000
66.990005,30.706947,-103.062363,-0.001022,0.003713,0.094302,136.591324,6.958293,0.943021,-103.062363,0.095291,0.000000
67.370003,31.319130,-103.151329,-0.000992,0.003736,0.094892,139.314453,7.097016,0.948918,-103.151329,0.095924,0.000000
67.750000,31.593193,-103.195808,-0.000983,0.003755,0.095386,140.533539,7.159120,0.953862,-103.195808,0.096557,0.000000
68.130005,33.020866,-103.062363,-0.000961,0.003786,0.096175,146.884155,7.482635,0.961753,-103.062363,0.097190,0.000000
68.510002,34.007286,-103.151329,-0.000927,0.003811,0.096800,151.271957,7.706161,0.967997,-103.151329,0.097823,0.000000
68.890007,34.819427,-103.240288,-0.000910,0.003837,0.097450,154.884552,7.890195,0.974501,-103.240288,0.098465,0.000000
69.270004,35.903778,-103.240288,-0.000905,0.003864,0.098135,159.707977,8.135912,0.981353,-103.240288,0.099098,0.000000
69.650002,36.256416,-103.284767,-0.000892,0.003883,0.098630,161.276596,8.215821,0.986296,-103.284767,0.099731,0.000000
70.030006,36.593040,-103.284767,-0.000867,0.003904,0.099159,162.773972,8.292101,0.991586,-103.284767,0.100364,0.000000
70.410004,38.769928,-103.284767,-0.000854,0.003936,0.099965,172.457260,8.785392,0.999651,-103.284767,0.100997,0.000000
70.790001,39.586540,-103.373734,-0.000811,0.003956,0.100485,176.089722,8.970438,1.004854,-103.373734,0.101630,0.000000
71.170006,40.864151,-103.373734,-0.000819,0.003982,0.101153,181.772827,9.259949,1.011532,-103.373734,0.102263,0.000000
71.550003,41.885193,-103.418213,-0.000798,0.004007,0.101769,186.314636,9.491321,1.017689,-103.418213,0.102896,0.000000
71.930000,42.317520,-103.373734,-0.000772,0.004023,0.102185,188.237732,9.589288,1.021852,-103.373734,0.103529,0.000000
72.310005,45.100632,-103.373734,-0.000763,0.004063,0.103209,200.617630,10.219950,1.032085,-103.373734,0.104162,0.000000
72.690002,45.403000,-103.418213,-0.000737,0.004078,0.103590,201.962631,10.288466,1.035901,-103.418213,0.104796,0.000000
73.070000,46.881317,-103.551651,-0.000733,0.004105,0.104267,208.538513,10.623459,1.042665,-103.551651,0.105429,0.000000
73.450005,47.814484,-103.507172,-0.000724,0.004126,0.104804,212.689453,10.834916,1.048042,-103.507172,0.106062,0.000000
73.830002,48.741692,-103.551651,-0.000703,0.004147,0.105333,216.813873,11.045026,1.053332,-103.551651,0.106695,0.000000
74.210007,51.374367,-103.507172,-0.000690,0.004185,0.106296,228.524597,11.641598,1.062958,-103.507172,0.107328,0.000000
74.590004,52.312744,-103.551651,-0.000673,0.004203,0.106755,232.698715,11.854237,1.067555,-103.551651,0.107961,0.000000
74.970001,54.587936,-103.596138,-0.000668,0.004237,0.107623,242.819275,12.369802,1.076227,-103.596138,0.108594,0.000000
75.350006,55.388168,-103.596138,-0.000664,0.004257,0.108134,246.378876,12.551139,1.081344,-103.596138,0.109227,0.000000
75.730003,56.927925,-103.596138,-0.000642,0.004282,0.108767,253.228058,12.900052,1.087674,-103.596138,0.109860,0.000000
76.110001,58.771912,-103.640617,-0.000617,0.004308,0.109427,261.430511,13.317906,1.094265,-103.640617,0.110493,0.000000
76.490005,60.315025,-103.729576,-0.000612,0.004334,0.110094,268.294647,13.667580,1.100943,-103.729576,0.111126,0.000000
76.870003,62.382439,-103.685097,-0.000608,0.004362,0.110797,277.490936,14.136063,1.107968,-103.685097,0.111759,0.000000
77.250000,63.788895,-103.774055,-0.000595,0.004385,0.111369,283.747162,14.454770,1.113691,-103.774055,0.112392,0.000000
77.630005,64.906006,-103.729576,-0.000573,0.004402,0.111820,288.716339,14.707911,1.118201,-103.729576,0.113026,0.000000
78.010002,66.730637,-103.774055,-0.000565,0.004418,0.112219,296.832703,15.121379,1.122190,-103.774055,0.112497,0.000000
78.390007,65.824646,-103.818542,-0.000552,0.004417,0.112202,292.802643,14.916078,1.122017,-103.818542,294.500458,0.000000
78.770004,65.050858,-103.951981,-0.000569,0.004417,0.112202,289.360657,14.740735,1.122017,-103.951981,294.500458,0.000000
79.150002,64.458038,-103.863022,-0.000556,0.004432,0.112575,286.723663,14.606400,1.125746,-103.863022,294.500458,0.000000
79.530006,66.200378,-103.907501,-0.000539,0.004386,0.111404,294.473999,15.001221,1.114038,-103.907501,294.500458,0.000000
79.910004,65.692078,-103.863022,-0.000543,0.004387,0.111439,292.212952,14.886038,1.114385,-103.863022,294.500458,0.000000
80.290001,65.274277,-103.951981,-0.000522,0.004402,0.111820,290.354492,14.791362,1.118201,-103.951981,294.500458,0.000000
80.670006,65.139481,-103.996460,-0.000522,0.004432,0.112566,289.754883,14.760817,1.125659,-103.996460,294.500458,0.000000
81.050003,64.857605,-103.996460,-0.000530,0.004432,0.112566,288.501038,14.696943,1.125659,-103.996460,294.500458,0.000000
81.430000,65.788895,-104.040947,-0.000530,0.004448,0.112973,292.643616,14.907976,1.129735,-104.040947,294.500458,0.000000
81.810005,65.574783,-103.996460,-0.000517,0.004448,0.112973,291.691193,14.859459,1.129735,-103.996460,294.500458,0.000000
82.190002,65.382263,-104.085426,-0.000509,0.004448,0.112973,290.834839,14.815832,1.129735,-104.085426,294.500458,0.000000
82.570007,65.196091,-104.129906,-0.000526,0.004448,0.112973,290.006683,14.773645,1.129735,-104.129906,294.500458,0.000000
82.950005,65.013245,-104.085426,-0.000517,0.004448,0.112973,289.193359,14.732212,1.129735,-104.085426,294.500458,0.000000
83.330002,65.775864,-104.129906,-0.000517,0.004459,0.113251,292.585663,14.905024,1.132510,-104.129906,294.500458,0.000000
83.710007,65.687988,-104.174385,-0.000504,0.004459,0.113251,292.194763,14.885112,1.132510,-104.174385,294.500458,0.000000
84.090004,65.561386,-104.174385,-0.000517,0.004459,0.113260,291.631622,14.856422,1.132597,-104.174385,294.500458,0.000000
84.470001,65.455627,-104.263351,-0.000526,0.004459,0.113260,291.161163,14.832458,1.132597,-104.263351,294.500458,0.000000
84.850006,65.315613,-104.174385,-0.000504,0.004459,0.113260,290.538361,14.800730,1.132597,-104.174385,294.500458,0.000000
85.230003,65.189011,-104.218872,-0.000509,0.004459,0.113268,289.975189,14.772040,1.132684,-104.218872,294.500458,0.000000
85.610001,65.092941,-104.218872,-0.000509,0.004460,0.113277,289.547852,14.750272,1.132770,-104.218872,294.500458,0.000000
85.990005,65.233322,-104.307831,-0.000509,0.004465,0.113398,290.172302,14.782083,1.133984,-104.307831,294.500458,0.000000
86.370003,65.245987,-104.352310,-0.000509,0.004464,0.113381,290.228638,14.784952,1.133811,-104.352310,294.500458,0.000000
86.750008,65.103363,-104.396790,-0.000513,0.004464,0.113381,289.594208,14.752633,1.133811,-104.396790,294.500458,0.000000
87.130005,65.050858,-104.352310,-0.000513,0.004464,0.113381,289.360657,14.740735,1.133811,-104.352310,294.500458,0.000000
87.510002,64.971542,-104.352310,-0.000492,0.004464,0.113381,289.007843,14.722762,1.133811,-104.352310,294.500458,0.000000
87.890007,64.914948,-104.441277,-0.000496,0.004464,0.113381,288.756104,14.709937,1.133811,-104.441277,294.500458,0.000000
88.270004,64.796158,-104.530235,-0.000500,0.004464,0.113381,288.227692,14.683020,1.133811,-104.530235,294.500458,0.000000
88.650002,64.728012,-104.485756,-0.000509,0.004464,0.113381,287.924591,14.667577,1.133811,-104.485756,294.500458,0.000000
89.030006,64.666199,-104.441277,-0.000500,0.004464,0.113381,287.649628,14.653570,1.133811,-104.441277,294.500458,0.000000
89.410004,64.551880,-104.485756,-0.000496,0.004464,0.113381,287.141113,14.627665,1.133811,-104.485756,294.500458,0.000000
89.790001,64.505341,-104.574715,-0.000500,0.004464,0.113381,286.934082,14.617119,1.133811,-104.574715,294.500458,0.000000
90.170006,64.432724,-104.574715,-0.000517,0.004464,0.113381,286.611084,14.600664,1.133811,-104.574715,294.500458,0.000000
90.550003,64.383194,-104.574715,-0.000500,0.004464,0.113390,286.390747,14.589440,1.133898,-104.574715,294.500458,0.000000
90.930008,66.762283,-104.574715,-0.000487,0.004274,0.108568,296.973480,15.128550,1.085680,-104.574715,294.500458,0.000000
91.310005,66.439438,-104.663681,-0.000479,0.004273,0.108542,295.537384,15.055391,1.085420,-104.663681,294.500458,0.000000
91.690002,66.408157,-104.708160,-0.000466,0.004274,0.108559,295.398224,15.048304,1.085593,-104.708160,294.500458,0.000000
92.070007,66.318420,-104.708160,-0.000496,0.004274,0.108559,294.999054,15.027969,1.085593,-104.708160,294.500458,0.000000
92.450005,66.245056,-104.708160,-0.000487,0.004274,0.108559,294.672729,15.011344,1.085593,-104.708160,294.500458,0.000000
92.830002,66.173187,-104.663681,-0.000492,0.004274,0.108559,294.353027,14.995058,1.085593,-104.663681,294.500458,0.000000
93.210007,66.114349,-104.752640,-0.000496,0.004274,0.108559,294.091309,14.981726,1.085593,-104.752640,294.500458,0.000000
93.590004,66.029831,-104.797119,-0.000500,0.004274,0.108559,293.715363,14.962574,1.085593,-104.797119,294.500458,0.000000
93.970001,65.932632,-104.752640,-0.000487,0.004275,0.108577,293.282990,14.940548,1.085767,-104.752640,294.500458,0.000000
94.350006,65.930771,-104.841599,-0.000483,0.004277,0.108637,293.274719,14.940126,1.086374,-104.841599,294.500458,0.000000
94.730003,65.860031,-104.841599,-0.000492,0.004280,0.108715,292.960052,14.924097,1.087154,-104.841599,294.500458,0.000000
95.110008,65.774002,-104.841599,-0.000483,0.004282,0.108767,292.577362,14.904602,1.087674,-104.841599,294.500458,0.000000
95.490005,65.740494,-104.886086,-0.000474,0.004296,0.109114,292.428314,14.897009,1.091143,-104.886086,294.500458,0.000000
95.870003,65.673462,-104.930565,-0.000474,0.004331,0.110008,292.130157,14.881820,1.100076,-104.930565,294.500458,0.000000
96.250008,65.601974,-104.930565,-0.000487,0.004342,0.110285,291.812164,14.865620,1.102851,-104.930565,294.500458,0.000000
96.630005,65.558395,-104.886086,-0.000474,0.004342,0.110285,291.618317,14.855744,1.102851,-104.886086,294.500458,0.000000
97.010002,65.508881,-104.930565,-0.000470,0.004390,0.111508,291.398041,14.844524,1.115079,-104.930565,294.500458,0.000000
97.390007,65.464188,-105.019524,-0.000492,0.004402,0.111820,291.199249,14.834396,1.118201,-105.019524,294.500458,0.000000
97.770004,65.383759,-105.064003,-0.000487,0.004402,0.111820,290.841492,14.816172,1.118201,-105.064003,294.500458,0.000000
98.150002,65.320450,-105.108490,-0.000483,0.004402,0.111820,290.559875,14.801826,1.118201,-105.108490,294.500458,0.000000
98.530006,65.327911,-105.108490,-0.000492,0.004420,0.112280,290.593048,14.803516,1.122797,-105.108490,294.500458,0.000000
98.910004,65.360672,-105.064003,-0.000474,0.004443,0.112861,290.738800,14.810940,1.128608,-105.064003,294.500458,0.000000
99.290001,65.318222,-105.152969,-0.000479,0.004444,0.112869,290.549957,14.801320,1.128694,-105.152969,294.500458,0.000000
99.670006,65.314499,-105.241928,-0.000487,0.004448,0.112973,290.533386,14.800477,1.129735,-105.241928,294.500458,0.000000
100.050003,65.257904,-105.197449,-0.000487,0.004448,0.112973,290.281647,14.787653,1.129735,-105.197449,294.500458,0.000000
100.430008,65.230347,-105.197449,-0.000474,0.004449,0.113000,290.159088,14.781407,1.129995,-105.197449,294.500458,0.000000
100.810005,65.181564,-105.197449,-0.000479,0.004449,0.113000,289.942078,14.770354,1.129995,-105.197449,294.500458,0.000000
101.190002,65.249710,-105.241928,-0.000483,0.004466,0.113424,290.245209,14.785795,1.134245,-105.241928,294.500458,0.000000
101.570007,65.206512,-105.375374,-0.000470,0.004466,0.113424,290.053040,14.776007,1.134245,-105.375374,294.500458,0.000000
101.950005,65.152145,-105.330894,-0.000483,0.004466,0.113424,289.811218,14.763687,1.134245,-105.330894,294.500458,0.000000
102.330002,65.104858,-105.330894,-0.000487,0.004466,0.113424,289.600861,14.752973,1.134245,-105.330894,294.500458,0.000000
102.710007,65.520798,-105.330894,-0.000483,0.004482,0.113841,291.451050,14.847225,1.138407,-105.330894,294.500458,0.000000
103.090004,65.526001,-105.419853,-0.000483,0.004482,0.113841,291.474213,14.848404,1.138407,-105.419853,294.500458,0.000000
103.470001,65.495102,-105.464333,-0.000487,0.004482,0.113841,291.336761,14.841402,1.138407,-105.464333,294.500458,0.000000
103.850006,65.491379,-105.464333,-0.000492,0.004482,0.113841,291.320190,14.840559,1.138407,-105.464333,294.500458,0.000000
104.230003,65.436264,-105.508820,-0.000483,0.004482,0.113841,291.075043,14.828069,1.138407,-105.508820,294.500458,0.000000
104.610008,65.397537,-105.508820,-0.000470,0.004482,0.113841,290.902771,14.819294,1.138407,-105.508820,294.500458,0.000000
104.990005,65.374817,-105.597778,-0.000466,0.004482,0.113849,290.801697,14.814145,1.138494,-105.597778,294.500458,0.000000
105.370003,65.336472,-105.597778,-0.000496,0.004482,0.113849,290.631134,14.805456,1.138494,-105.597778,294.500458,0.000000
105.750008,65.318222,-105.553299,-0.000492,0.004482,0.113849,290.549957,14.801320,1.138494,-105.553299,294.500458,0.000000
106.130005,65.289917,-105.597778,-0.000483,0.004482,0.113849,290.424042,14.794907,1.138494,-105.597778,294.500458,0.000000
106.510002,65.272415,-105.597778,-0.000479,0.004483,0.113858,290.346191,14.790941,1.138581,-105.597778,294.500458,0.000000
106.890007,65.242630,-105.642258,-0.000479,0.004483,0.113858,290.213715,14.784191,1.138581,-105.642258,294.500458,0.000000
107.270004,65.239655,-105.686737,-0.000479,0.004483,0.113867,290.200470,14.783518,1.138667,-105.686737,294.500458,0.000000
107.650002,65.343536,-105.731224,-0.000474,0.004486,0.113945,290.662567,14.807057,1.139448,-105.731224,294.500458,0.000000
108.030006,65.380035,-105.686737,-0.000466,0.004487,0.113971,290.824921,14.815328,1.139708,-105.686737,294.500458,0.000000
108.410004,65.399399,-105.731224,-0.000474,0.004487,0.113971,290.911041,14.819715,1.139708,-105.731224,294.500458,0.000000
108.790009,65.381531,-105.731224,-0.000479,0.004487,0.113971,290.831573,14.815667,1.139708,-105.731224,294.500458,0.000000
109.170006,65.382263,-105.820183,-0.000470,0.004487,0.113971,290.834839,14.815832,1.139708,-105.820183,294.500458,0.000000
109.550003,65.366638,-105.820183,-0.000496,0.004487,0.113979,290.765320,14.812292,1.139795,-105.820183,294.500458,0.000000
109.930008,65.361420,-105.820183,-0.000483,0.004487,0.113979,290.742126,14.811110,1.139795,-105.820183,294.500458,0.000000
110.310005,65.356201,-105.864662,-0.000496,0.004488,0.113988,290.718903,14.809927,1.139881,-105.864662,294.500458,0.000000
110.690002,65.379288,-105.820183,-0.000479,0.004489,0.114014,290.821594,14.815159,1.140142,-105.820183,294.500458,0.000000
111.070007,65.401260,-105.909142,-0.000483,0.004489,0.114014,290.919342,14.820137,1.140142,-105.909142,294.500458,0.000000
111.450005,65.382645,-105.909142,-0.000474,0.004489,0.114014,290.836517,14.815919,1.140142,-105.909142,294.500458,0.000000
111.830002,65.383392,-105.864662,-0.000492,0.004489,0.114014,290.839844,14.816088,1.140142,-105.864662,294.500458,0.000000
112.210007,65.378540,-105.909142,-0.000474,0.004489,0.114023,290.818268,14.814989,1.140228,-105.909142,294.500458,0.000000
112.590004,65.358810,-105.998108,-0.000470,0.004489,0.114023,290.730499,14.810518,1.140228,-105.998108,294.500458,0.000000
112.970009,65.359924,-106.042587,-0.000492,0.004490,0.114040,290.735474,14.810771,1.140402,-106.042587,294.500458,0.000000
113.350006,65.369614,-106.087067,-0.000483,0.004490,0.114049,290.778564,14.812966,1.140489,-106.087067,294.500458,0.000000
113.730003,65.371841,-106.087067,-0.000487,0.004490,0.114049,290.788483,14.813471,1.140489,-106.087067,294.500458,0.000000
114.110008,65.352478,-106.042587,-0.000492,0.004490,0.114049,290.702332,14.809083,1.140489,-106.042587,294.500458,0.000000
114.490005,65.356201,-106.131546,-0.000479,0.004491,0.114066,290.718903,14.809927,1.140662,-106.131546,294.500458,0.000000
114.870003,65.374084,-106.131546,-0.000483,0.004491,0.114084,290.798462,14.813979,1.140836,-106.131546,294.500458,0.000000
115.250008,65.392319,-106.220512,-0.000483,0.004491,0.114084,290.879547,14.818110,1.140836,-106.220512,294.500458,0.000000
115.630005,65.387482,-106.176033,-0.000479,0.004491,0.114084,290.858032,14.817015,1.140836,-106.176033,294.500458,0.000000
116.010002,65.367004,-106.220512,-0.000487,0.004491,0.114084,290.766968,14.812375,1.140836,-106.220512,294.500458,0.000000
116.390007,65.369980,-106.220512,-0.000474,0.004492,0.114101,290.780182,14.813048,1.141009,-106.220512,294.500458,0.000000
116.770004,65.357697,-106.309471,-0.000474,0.004492,0.114101,290.725555,14.810266,1.141009,-106.309471,294.500458,0.000000
117.150009,65.347275,-106.309471,-0.000483,0.004492,0.114101,290.679199,14.807904,1.141009,-106.309471,294.500458,0.000000
117.530006,65.328644,-106.309471,-0.000492,0.004492,0.114101,290.596313,14.803682,1.141009,-106.309471,294.500458,0.000000
117.910004,65.314133,-106.353951,-0.000483,0.004492,0.114101,290.531769,14.800394,1.141009,-106.353951,294.500458,0.000000
118.290009,65.341309,-106.398437,-0.000470,0.004494,0.114144,290.652649,14.806552,1.141442,-106.398437,294.500458,0.000000
118.670006,65.358063,-106.442917,-0.000483,0.004494,0.114144,290.727173,14.810349,1.141442,-106.442917,294.500458,0.000000
119.050003,65.369980,-106.398437,-0.000479,0.004494,0.114144,290.780182,14.813048,1.141442,-106.398437,294.500458,0.000000
119.430008,65.363647,-106.398437,-0.000479,0.004494,0.114144,290.752014,14.811614,1.141442,-106.398437,294.500458,0.000000
119.810005,65.352859,-106.353951,-0.000474,0.004494,0.114144,290.704041,14.809170,1.141442,-106.353951,294.500458,0.000000
120.190002,65.386734,-106.442917,-0.000470,0.004495,0.114170,290.854706,14.816845,1.141703,-106.442917,294.500458,0.000000
120.570007,65.385620,-106.531876,-0.000466,0.004495,0.114170,290.849762,14.816593,1.141703,-106.531876,294.500458,0.000000
120.950005,65.397171,-106.620842,-0.000487,0.004495,0.114170,290.901154,14.819211,1.141703,-106.620842,294.500458,0.000000
121.330009,65.386368,-106.531876,-0.000466,0.004495,0.114170,290.853088,14.816763,1.141703,-106.531876,294.500458,0.000000
121.710007,65.380035,-106.531876,-0.000470,0.004495,0.114170,290.824921,14.815328,1.141703,-106.531876,294.500458,0.000000
122.090004,65.373337,-106.576355,-0.000466,0.004495,0.114179,290.795135,14.813809,1.141789,-106.576355,294.500458,0.000000
122.470009,65.396042,-106.576355,-0.000453,0.004496,0.114205,290.896118,14.818955,1.142050,-106.576355,294.500458,0.000000
122.850006,65.428070,-106.665321,-0.000461,0.004497,0.114214,291.038605,14.826213,1.142136,-106.665321,294.500458,0.000000
123.230003,65.421371,-106.709801,-0.000470,0.004497,0.114214,291.008789,14.824695,1.142136,-106.709801,294.500458,0.000000
123.610008,65.433655,-106.620842,-0.000470,0.004497,0.114214,291.063446,14.827478,1.142136,-106.620842,294.500458,0.000000
123.990005,65.427322,-106.709801,-0.000453,0.004497,0.114214,291.035278,14.826044,1.142136,-106.709801,294.500458,0.000000
124.370003,65.410202,-106.798767,-0.000466,0.004497,0.114214,290.959106,14.822164,1.142136,-106.798767,294.500458,0.000000
124.750008,65.400146,-106.798767,-0.000470,0.004497,0.114214,290.914368,14.819884,1.142136,-106.798767,294.500458,0.000000
125.130005,65.390457,-106.843246,-0.000457,0.004497,0.114214,290.871277,14.817690,1.142136,-106.843246,294.500458,0.000000
125.510010,65.430313,-106.754280,-0.000470,0.004497,0.114231,291.048584,14.826720,1.142310,-106.754280,294.500458,0.000000
125.890007,65.430679,-106.798767,-0.000466,0.004497,0.114231,291.050201,14.826804,1.142310,-106.798767,294.500458,0.000000
126.270004,65.422485,-106.887726,-0.000470,0.004497,0.114231,291.013763,14.824946,1.142310,-106.887726,294.500458,0.000000
126.650009,65.417267,-106.932205,-0.000474,0.004498,0.114240,290.990540,14.823765,1.142396,-106.932205,294.500458,0.000000
127.030006,65.404984,-106.932205,-0.000470,0.004498,0.114240,290.935883,14.820981,1.142396,-106.932205,294.500458,0.000000
127.410004,65.407593,-106.932205,-0.000461,0.004498,0.114240,290.947510,14.821572,1.142396,-106.932205,294.500458,0.000000
127.790009,65.386002,-106.932205,-0.000461,0.004498,0.114240,290.851471,14.816680,1.142396,-106.932205,294.500458,0.000000
128.170013,65.375565,-106.976685,-0.000474,0.004498,0.114257,290.805023,14.814314,1.142570,-106.976685,294.500458,0.000000
128.550003,65.401260,-107.021172,-0.000461,0.004499,0.114266,290.919342,14.820137,1.142657,-107.021172,294.500458,0.000000
128.930008,65.395309,-107.065651,-0.000474,0.004499,0.114266,290.892853,14.818789,1.142657,-107.065651,294.500458,0.000000
129.310013,65.421371,-107.065651,-0.000474,0.004499,0.114266,291.008789,14.824695,1.142657,-107.065651,294.500458,0.000000
129.690002,65.412064,-107.021172,-0.000483,0.004499,0.114266,290.967377,14.822585,1.142657,-107.021172,294.500458,0.000000
130.070007,65.407593,-107.154610,-0.000474,0.004499,0.114266,290.947510,14.821572,1.142657,-107.154610,294.500458,0.000000
130.450012,65.398285,-107.154610,-0.000474,0.004499,0.114266,290.906097,14.819464,1.142657,-107.154610,294.500458,0.000000
130.830002,65.387482,-107.199089,-0.000479,0.004499,0.114274,290.858032,14.817015,1.142743,-107.199089,294.500458,0.000000
131.210007,65.394180,-107.154610,-0.000457,0.004499,0.114274,290.887848,14.818533,1.142743,-107.154610,294.500458,0.000000
131.590012,65.377060,-107.199089,-0.000474,0.004499,0.114274,290.811676,14.814653,1.142743,-107.199089,294.500458,0.000000
131.970001,65.384872,-107.199089,-0.000461,0.004499,0.114274,290.846436,14.816424,1.142743,-107.199089,294.500458,0.000000
132.350006,65.375565,-107.243576,-0.000461,0.004499,0.114274,290.805023,14.814314,1.142743,-107.243576,294.500458,0.000000
132.730011,65.371094,-107.288055,-0.000466,0.004499,0.114274,290.785156,14.813301,1.142743,-107.288055,294.500458,0.000000
133.110001,65.348389,-107.288055,-0.000470,0.004499,0.114274,290.684143,14.808156,1.142743,-107.288055,294.500458,0.000000
133.490005,65.393066,-107.332535,-0.000461,0.004501,0.114326,290.882874,14.818280,1.143264,-107.332535,294.500458,0.000000
133.870010,65.450790,-107.332535,-0.000466,0.004501,0.114326,291.139648,14.831361,1.143264,-107.332535,294.500458,0.000000
134.250000,65.465683,-107.421494,-0.000457,0.004501,0.114326,291.205902,14.834736,1.143264,-107.421494,294.500458,0.000000
134.630005,65.470520,-107.421494,-0.000470,0.004501,0.114326,291.227417,14.835832,1.143264,-107.421494,294.500458,0.000000
135.010010,65.467178,-107.421494,-0.000474,0.004501,0.114326,291.212555,14.835074,1.143264,-107.421494,294.500458,0.000000
135.389999,65.482437,-107.421494,-0.000457,0.004501,0.114326,291.280426,14.838532,1.143264,-107.421494,294.500458,0.000000
135.770004,65.496964,-107.421494,-0.000461,0.004501,0.114326,291.345032,14.841825,1.143264,-107.421494,294.500458,0.000000
136.150009,65.455261,-107.465981,-0.000479,0.004501,0.114326,291.159546,14.832374,1.143264,-107.465981,294.500458,0.000000
136.530014,65.466049,-107.554939,-0.000479,0.004501,0.114326,291.207520,14.834819,1.143264,-107.554939,294.500458,0.000000
136.910004,65.432175,-107.554939,-0.000474,0.004501,0.114326,291.056854,14.827143,1.143264,-107.554939,294.500458,0.000000
137.290009,65.432175,-107.465981,-0.000466,0.004501,0.114326,291.056854,14.827143,1.143264,-107.465981,294.500458,0.000000
137.670013,65.422852,-107.599419,-0.000474,0.004501,0.114326,291.015381,14.825030,1.143264,-107.599419,294.500458,0.000000
138.050003,65.398651,-107.599419,-0.000466,0.004501,0.114326,290.907715,14.819546,1.143264,-107.599419,294.500458,0.000000
138.430008,65.415039,-107.688385,-0.000457,0.004501,0.114326,290.980621,14.823260,1.143264,-107.688385,294.500458,0.000000
138.810013,65.461578,-107.643898,-0.000470,0.004496,0.114196,291.187653,14.833806,1.141963,-107.643898,0.114248,0.000000
139.190002,65.364395,-107.688385,-0.000474,0.004484,0.113893,290.755341,14.811783,1.138928,-107.688385,0.113615,0.000000
139.570007,65.379669,-107.643898,-0.000461,0.004465,0.113416,290.823303,14.815245,1.134158,-107.643898,0.112982,0.000000
139.950012,65.305557,-107.688385,-0.000448,0.004444,0.112878,290.493622,14.798450,1.128781,-107.688385,0.112349,0.000000
140.330002,65.321945,-107.732864,-0.000461,0.004421,0.112306,290.566528,14.802165,1.123057,-107.732864,0.111716,0.000000
140.710007,65.259018,-107.777344,-0.000470,0.004395,0.111638,290.286621,14.787905,1.116380,-107.777344,0.111083,0.000000
141.090012,65.265717,-107.821823,-0.000466,0.004373,0.111083,290.316406,14.789423,1.110829,-107.821823,0.110450,0.000000
141.470001,65.206879,-107.732864,-0.000453,0.004344,0.110328,290.054687,14.776090,1.103285,-107.732864,0.109817,0.000000
141.850006,65.209122,-107.777344,-0.000444,0.004322,0.109773,290.064667,14.776598,1.097734,-107.777344,0.109184,0.000000
142.230011,65.199814,-107.866310,-0.000448,0.004302,0.109279,290.023254,14.774489,1.092791,-107.866310,0.108551,0.000000
142.610001,65.091446,-107.866310,-0.000470,0.004276,0.108611,289.541199,14.749933,1.086113,-107.866310,0.107918,0.000000
142.990005,64.773437,-107.910789,-0.000461,0.004251,0.107987,288.126648,14.677870,1.079869,-107.910789,0.107284,0.000000
143.370010,64.123276,-107.866310,-0.000453,0.004232,0.107484,285.234589,14.530542,1.074840,-107.866310,0.106651,0.000000
143.750000,62.943230,-107.955269,-0.000448,0.004205,0.106799,279.985474,14.263140,1.067988,-107.955269,0.106018,0.000000
144.130005,61.671577,-107.955269,-0.000453,0.004180,0.106174,274.328888,13.974979,1.061744,-107.955269,0.105385,0.000000
144.510010,60.208153,-107.955269,-0.000457,0.004163,0.105732,267.819244,13.643362,1.057322,-107.955269,0.104752,0.000000
144.889999,58.090469,-108.044228,-0.000453,0.004134,0.105004,258.399323,13.163488,1.050037,-108.044228,0.104119,0.000000
145.270004,56.118019,-108.088715,-0.000457,0.004111,0.104414,249.625412,12.716524,1.044140,-108.088715,0.103486,0.000000
145.650009,54.118752,-108.044228,-0.000440,0.004087,0.103816,240.732224,12.263485,1.038156,-108.044228,0.102853,0.000000
146.030014,51.619385,-108.133194,-0.000440,0.004065,0.103252,229.614487,11.697120,1.032519,-108.133194,0.102220,0.000000
146.410004,48.841484,-108.133194,-0.000457,0.004039,0.102601,217.257767,11.067639,1.026015,-108.133194,0.101587,0.000000
146.790009,46.317543,-108.133194,-0.000466,0.004013,0.101925,206.030716,10.495706,1.019250,-108.133194,0.100954,0.000000
147.170013,43.696419,-108.133194,-0.000453,0.003990,0.101335,194.371384,9.901750,1.013353,-108.133194,0.100321,0.000000
147.550003,40.997833,-108.222153,-0.000448,0.003966,0.100728,182.367477,9.290242,1.007283,-108.222153,0.099679,0.000000
147.930008,38.179718,-108.177673,-0.000457,0.003940,0.100087,169.831863,8.651649,1.000865,-108.177673,0.099046,0.000000
148.310013,35.836746,-108.266632,-0.000466,0.003914,0.099427,159.409805,8.120723,0.994274,-108.266632,0.098413,0.000000
148.690002,32.614983,-108.266632,-0.000466,0.003889,0.098777,145.078690,7.390661,0.987770,-108.266632,0.097780,0.000000
149.070007,30.845100,-108.222153,-0.000461,0.003875,0.098413,137.205856,6.989600,0.984128,-108.222153,0.097147,0.000000
149.450012,27.532845,-108.266632,-0.000448,0.003840,0.097546,122.472206,6.239032,0.975455,-108.266632,0.096514,0.000000
149.830002,24.549393,-108.355598,-0.000457,0.003816,0.096938,109.201149,5.562972,0.969385,-108.355598,0.095880,0.000000
150.210007,21.739471,-108.400078,-0.000461,0.003791,0.096297,96.701996,4.926234,0.962967,-108.400078,0.095247,0.000000
150.590012,18.877792,-108.355598,-0.000470,0.003765,0.095620,83.972618,4.277769,0.956203,-108.355598,0.094614,0.000000
150.970001,17.180145,-108.400078,-0.000483,0.003752,0.095299,76.421104,3.893077,0.952994,-108.400078,0.093981,0.000000
151.350006,14.419006,-108.400078,-0.000479,0.003717,0.094424,64.138947,3.267394,0.944235,-108.400078,0.093348,0.000000
151.730011,10.569786,-108.489037,-0.000487,0.003690,0.093738,47.016758,2.395148,0.937384,-108.489037,0.092715,0.000000
152.110001,8.189957,-108.489037,-0.000487,0.003666,0.093123,36.430748,1.855871,0.931227,-108.489037,0.092082,0.000000
152.490005,5.417641,-108.489037,-0.000500,0.003644,0.092568,24.098869,1.227655,0.925677,-108.489037,0.091449,0.000000
152.870010,2.757042,-108.489037,-0.000492,0.003615,0.091831,12.263935,0.624755,0.918305,-108.489037,0.090816,0.000000
153.250000,0.452805,-108.489037,-0.000509,0.003594,0.091284,2.014175,0.102607,0.912842,-108.489037,0.090183,0.000000
153.630005,-0.681442,-108.578003,-0.000509,0.003565,0.090556,-3.031207,-0.154417,0.905557,-108.578003,0.089550,0.000000
154.010010,0.293053,-108.666962,-0.000543,0.003549,0.090157,1.303563,0.066407,0.901568,-108.666962,0.088917,0.000000
154.390015,0.279274,-108.578003,-0.000629,0.003516,0.089307,1.242273,0.063284,0.893069,-108.578003,0.088284,0.000000
154.770004,0.312416,-108.622482,-0.000660,0.003498,0.088847,1.389696,0.070794,0.888473,-108.622482,0.087651,0.000000
155.150009,0.225281,-108.622482,-0.000703,0.003467,0.088049,1.002099,0.051049,0.880494,-108.622482,0.087017,0.000000
155.530014,0.208900,-108.666962,-0.000746,0.003437,0.087312,0.929236,0.047338,0.873123,-108.666962,0.086384,0.000000
155.910004,0.191025,-108.755928,-0.000785,0.003421,0.086896,0.849721,0.043287,0.868960,-108.755928,0.085751,0.000000
156.290009,0.198097,-108.711441,-0.000802,0.003409,0.086601,0.881180,0.044889,0.866012,-108.711441,0.085118,0.000000
156.670013,0.091225,-108.711441,-0.000875,0.003368,0.085552,0.405788,0.020672,0.855518,-108.711441,0.084485,0.000000
157.050003,0.061066,-108.755928,-0.000901,0.003345,0.084953,0.271634,0.013838,0.849534,-108.755928,0.083852,0.000000
157.430008,0.061813,-108.800407,-0.000961,0.003312,0.084121,0.274960,0.014007,0.841209,-108.800407,0.083219,0.000000
157.810013,0.014145,-108.800407,-0.000983,0.003293,0.083635,0.062920,0.003205,0.836352,-108.800407,0.082586,0.000000
158.190002,0.068138,-108.844887,-0.001022,0.003277,0.083228,0.303093,0.015440,0.832277,-108.844887,0.083089,0.000000
158.200012,0.068886,-108.800407,-0.001026,0.003277,0.083228,0.306419,0.015610,0.832277,-108.800407,0.083089,0.000000