File: Data/compression 32/AutoNoHeating-12-32-reverse-1-2_11142024_180722.csv
Time (sec),S:Load (lbs),S:HL1 (DIM),S:LVDT (in),S:Position (in),Ch:Position (mm),Ch:Load (N),Ch:Stress (MPa),Ch:Strain (mm/mm),Ch:HL1 (DIM),Set Point (),Cycles ()
0.110000,0.008934,-83.535225,-0.011102,-0.006212,-0.157774,0.039741,0.002024,-1.577744,-83.535225,-0.157558,0.000000
0.510000,0.008560,-83.624191,-0.011111,-0.006146,-0.156118,0.038078,0.001940,-1.561180,-83.624191,-0.155355,0.000000
0.910000,-0.025322,-83.624191,-0.010969,-0.005911,-0.150134,-0.112638,-0.005738,-1.501341,-83.624191,-0.148695,0.000000
1.310000,-0.026070,-83.668671,-0.010718,-0.005646,-0.143404,-0.115964,-0.005907,-1.434044,-83.668671,-0.142034,0.000000
1.710000,-0.037987,-83.668671,-0.010430,-0.005379,-0.136631,-0.168974,-0.008608,-1.366314,-83.668671,-0.135357,0.000000
2.110000,0.004089,-83.668671,-0.010154,-0.005119,-0.130023,0.018190,0.000927,-1.300231,-83.668671,-0.128696,0.000000
2.510000,0.040215,-83.713150,-0.009895,-0.004856,-0.123354,0.178883,0.009113,-1.233542,-83.713150,-0.122036,0.000000
2.910000,0.019363,-83.713150,-0.009615,-0.004590,-0.116590,0.086133,0.004388,-1.165898,-83.713150,-0.115376,0.000000
3.310000,0.007446,-83.757629,-0.009334,-0.004328,-0.109938,0.033123,0.001687,-1.099382,-83.757629,-0.108698,0.000000
3.710000,-0.031281,-83.802109,-0.009080,-0.004069,-0.103365,-0.139143,-0.007088,-1.033646,-83.802109,-0.102038,0.000000
4.110000,0.027550,-83.846596,-0.008817,-0.003807,-0.096687,0.122547,0.006243,-0.966870,-83.846596,-0.095377,0.000000
4.510000,0.035370,-83.846596,-0.008554,-0.003535,-0.089801,0.157333,0.008015,-0.898012,-83.846596,-0.088717,0.000000
4.910000,0.032768,-83.846596,-0.008278,-0.003279,-0.083297,0.145760,0.007425,-0.832970,-83.846596,-0.082057,0.000000
5.310000,-0.033142,-83.891075,-0.008019,-0.003016,-0.076611,-0.147423,-0.007510,-0.766107,-83.891075,-0.075379,0.000000
5.710000,-0.063683,-83.935555,-0.007731,-0.002756,-0.069994,-0.283274,-0.014431,-0.699938,-83.935555,-0.068719,0.000000
6.110000,-0.035751,-84.024513,-0.007455,-0.002491,-0.063264,-0.159030,-0.008101,-0.632641,-84.024513,-0.062059,0.000000
6.510000,-0.007454,-83.980034,-0.007200,-0.002231,-0.056665,-0.033157,-0.001689,-0.566645,-83.980034,-0.055398,0.000000
6.910000,0.022713,-84.024513,-0.006916,-0.001966,-0.049935,0.101031,0.005147,-0.499349,-84.024513,-0.048738,0.000000
7.310000,-0.004471,-84.024513,-0.006644,-0.001713,-0.043509,-0.019887,-0.001013,-0.435087,-84.024513,-0.042060,0.000000
7.710001,-0.007820,-84.113480,-0.006394,-0.001448,-0.036788,-0.034786,-0.001772,-0.367877,-84.113480,-0.035400,0.000000
8.110001,-0.021973,-84.069000,-0.006109,-0.001181,-0.029989,-0.097739,-0.004979,-0.299887,-84.069000,-0.028740,0.000000
8.510000,0.025314,-84.069000,-0.005833,-0.000919,-0.023354,0.112604,0.005736,-0.233544,-84.069000,-0.022080,0.000000
8.910001,0.058083,-84.113480,-0.005566,-0.000657,-0.016694,0.258364,0.013162,-0.166941,-84.113480,-0.015419,0.000000
9.310000,0.036118,-84.157959,-0.005307,-0.000392,-0.009964,0.160659,0.008184,-0.099644,-84.157959,-0.008742,0.000000
9.710000,0.033134,-84.157959,-0.005019,-0.000132,-0.003356,0.147389,0.007508,-0.033562,-84.157959,-0.002081,0.000000
10.110001,0.130325,-84.202438,-0.004885,-0.000000,-0.000000,0.579716,0.029532,-0.000000,-84.202438,0.000165,0.000000
10.510000,0.062180,-84.202438,-0.004876,-0.000000,-0.000009,0.276589,0.014090,-0.000087,-84.202438,0.000234,0.000000
10.910001,0.134048,-84.246918,-0.004863,-0.000000,-0.000000,0.596277,0.030376,-0.000000,-84.246918,0.000902,0.000000
11.310000,0.100166,-84.291405,-0.004885,0.000000,0.000009,0.445562,0.022698,0.000087,-84.291405,0.001561,0.000000
11.710001,0.129211,-84.246918,-0.004838,0.000040,0.001006,0.574761,0.029280,0.010060,-84.246918,0.002229,0.000000
12.110001,0.219322,-84.291405,-0.004825,0.000068,0.001717,0.975594,0.049699,0.017171,-84.291405,0.002897,0.000000
12.510000,0.393967,-84.335884,-0.004781,0.000104,0.002636,1.752451,0.089274,0.026364,-84.335884,0.003564,0.000000
12.910001,0.451683,-84.380363,-0.004773,0.000125,0.003174,2.009187,0.102353,0.031740,-84.380363,0.004232,0.000000
13.310000,0.532486,-84.424843,-0.004725,0.000152,0.003859,2.368616,0.120663,0.038592,-84.424843,0.004900,0.000000
13.710001,0.655746,-84.469330,-0.004717,0.000171,0.004353,2.916906,0.148594,0.043535,-84.469330,0.005568,0.000000
14.110001,0.859802,-84.469330,-0.004687,0.000196,0.004987,3.824591,0.194834,0.049865,-84.469330,0.006235,0.000000
14.510000,1.190102,-84.558289,-0.004661,0.000230,0.005845,5.293837,0.269681,0.058451,-84.558289,0.006894,0.000000
14.910001,1.477196,-84.513809,-0.004639,0.000258,0.006556,6.570895,0.334737,0.065562,-84.513809,0.007562,0.000000
15.310000,1.740089,-84.602768,-0.004605,0.000289,0.007328,7.740304,0.394310,0.073281,-84.602768,0.008230,0.000000
15.710001,1.923302,-84.602768,-0.004613,0.000305,0.007744,8.555273,0.435826,0.077443,-84.602768,0.008898,0.000000
16.110001,2.153801,-84.647247,-0.004570,0.000326,0.008273,9.580585,0.488058,0.082733,-84.647247,0.009565,0.000000
16.510000,2.780128,-84.691734,-0.004536,0.000366,0.009288,12.366629,0.629986,0.092880,-84.691734,0.010233,0.000000
16.910002,2.943970,-84.691734,-0.004510,0.000382,0.009713,13.095431,0.667113,0.097129,-84.691734,0.010901,0.000000
17.310001,3.361404,-84.647247,-0.004484,0.000415,0.010537,14.952273,0.761705,0.105368,-84.647247,0.011569,0.000000
17.710001,3.796333,-84.691734,-0.004471,0.000445,0.011291,16.886934,0.860261,0.112913,-84.691734,0.012228,0.000000
18.110001,4.027206,-84.780693,-0.004441,0.000465,0.011812,17.913908,0.912578,0.118116,-84.780693,0.012896,0.000000
18.510000,4.593208,-84.825172,-0.004415,0.000497,0.012618,20.431610,1.040836,0.126181,-84.825172,0.013563,0.000000
18.910002,4.946220,-84.825172,-0.004398,0.000522,0.013260,22.001886,1.120830,0.132599,-84.825172,0.014231,0.000000
19.310001,5.143951,-84.869652,-0.004372,0.000547,0.013893,22.881439,1.165636,0.138930,-84.869652,0.014899,0.000000
19.710001,5.556541,-84.869652,-0.004337,0.000570,0.014483,24.716730,1.259130,0.144827,-84.869652,0.015567,0.000000
20.110001,6.124031,-85.003098,-0.004312,0.000597,0.015159,27.241051,1.387725,0.151591,-85.003098,0.016234,0.000000
20.510000,6.445023,-84.914139,-0.004286,0.000631,0.016018,28.668892,1.460463,0.160177,-84.914139,0.016902,0.000000
20.910002,6.747383,-85.003098,-0.004260,0.000656,0.016668,30.013859,1.528979,0.166681,-85.003098,0.017570,0.000000
21.310001,6.960381,-85.047577,-0.004234,0.000679,0.017249,30.961319,1.577245,0.172491,-85.047577,0.018229,0.000000
21.710001,7.402390,-85.047577,-0.004208,0.000705,0.017917,32.927475,1.677405,0.179169,-85.047577,0.018897,0.000000
22.110001,7.670494,-85.092056,-0.004204,0.000731,0.018559,34.120060,1.738159,0.185586,-85.092056,0.019565,0.000000
22.510000,8.002655,-85.136543,-0.004182,0.000753,0.019114,35.597588,1.813428,0.191137,-85.136543,0.020232,0.000000
22.910002,8.525093,-85.225502,-0.004130,0.000782,0.019868,37.921509,1.931814,0.198681,-85.225502,0.020900,0.000000
23.310001,8.703461,-85.181023,-0.004100,0.000810,0.020579,38.714928,1.972232,0.205793,-85.181023,0.021568,0.000000
23.710001,8.961510,-85.269981,-0.004083,0.000835,0.021221,39.862785,2.030707,0.212210,-85.269981,0.022236,0.000000
24.110001,9.171906,-85.225502,-0.004061,0.000861,0.021871,40.798672,2.078383,0.218714,-85.225502,0.022903,0.000000
24.510000,9.800095,-85.269981,-0.004018,0.000889,0.022591,43.592999,2.220733,0.225912,-85.269981,0.023563,0.000000
24.910002,10.036179,-85.269981,-0.004005,0.000916,0.023268,44.643150,2.274231,0.232677,-85.269981,0.024230,0.000000
25.310001,10.125923,-85.314461,-0.003984,0.000937,0.023788,45.042355,2.294567,0.237880,-85.314461,0.024898,0.000000
25.710001,10.482651,-85.358948,-0.003945,0.000963,0.024464,46.629158,2.375403,0.244644,-85.358948,0.025566,0.000000
26.110001,10.909019,-85.403427,-0.003919,0.000993,0.025210,48.525742,2.472019,0.252103,-85.403427,0.026234,0.000000
26.510002,11.051270,-85.403427,-0.003880,0.001019,0.025887,49.158501,2.504254,0.258867,-85.403427,0.026901,0.000000
26.910002,11.432945,-85.447906,-0.003859,0.001049,0.026633,50.856281,2.590743,0.266325,-85.447906,0.027569,0.000000
27.310001,11.326080,-85.492386,-0.003833,0.001068,0.027135,50.380920,2.566526,0.271355,-85.492386,0.028237,0.000000
27.710001,11.123131,-85.492386,-0.003807,0.001079,0.027396,49.478157,2.520537,0.273957,-85.492386,0.028896,0.000000
28.110001,12.127426,-85.536865,-0.003768,0.001120,0.028445,53.945484,2.748114,0.284450,-85.536865,0.029564,0.000000
28.510002,12.107315,-85.492386,-0.003742,0.001141,0.028983,53.856026,2.743557,0.289827,-85.492386,0.030231,0.000000
28.910002,12.680397,-85.625832,-0.003708,0.001178,0.029919,56.405224,2.873419,0.299193,-85.625832,0.030899,0.000000
29.310001,12.254028,-85.625832,-0.003682,0.001190,0.030223,54.508640,2.776803,0.302228,-85.625832,0.031567,0.000000
29.710001,13.135063,-85.670311,-0.003652,0.001227,0.031177,58.427681,2.976448,0.311768,-85.670311,0.032235,0.000000
30.110001,13.303375,-85.670311,-0.003613,0.001256,0.031914,59.176369,3.014588,0.319139,-85.670311,0.032903,0.000000
30.510002,13.241188,-85.625832,-0.003587,0.001276,0.032400,58.899746,3.000496,0.323996,-85.625832,0.033570,0.000000
30.910002,13.358856,-85.759277,-0.003561,0.001306,0.033180,59.423161,3.027160,0.331801,-85.759277,0.034229,0.000000
31.310001,13.643723,-85.803757,-0.003523,0.001326,0.033683,60.690308,3.091712,0.336830,-85.803757,0.034897,0.000000
31.710001,14.169144,-85.848236,-0.003479,0.001359,0.034516,63.027500,3.210774,0.345156,-85.848236,0.035565,0.000000
32.110001,14.156853,-85.848236,-0.003432,0.001383,0.035131,62.972824,3.207989,0.351313,-85.848236,0.036233,0.000000
32.510002,14.297607,-85.803757,-0.003423,0.001409,0.035782,63.598934,3.239884,0.357817,-85.803757,0.036900,0.000000
32.910000,14.218292,-85.848236,-0.003397,0.001434,0.036415,63.246124,3.221911,0.364148,-85.848236,0.037568,0.000000
33.310001,14.605934,-85.892715,-0.003346,0.001461,0.037117,64.970444,3.309752,0.371173,-85.892715,0.038236,0.000000
33.710003,15.135818,-85.892715,-0.003307,0.001495,0.037967,67.327484,3.429826,0.379671,-85.892715,0.038904,0.000000
34.110001,14.739616,-85.937195,-0.003290,0.001512,0.038409,65.565086,3.340045,0.384094,-85.937195,0.039572,0.000000
34.510002,15.298920,-85.981682,-0.003234,0.001547,0.039294,68.052994,3.466785,0.392940,-85.981682,0.040231,0.000000
34.910000,14.958946,-85.937195,-0.003212,0.001569,0.039849,66.540718,3.389746,0.398490,-85.937195,0.040898,0.000000
35.310001,15.266151,-85.981682,-0.003199,0.001594,0.040499,67.907234,3.459359,0.404994,-85.981682,0.041566,0.000000
35.710003,15.308228,-86.026161,-0.003147,0.001616,0.041054,68.094398,3.468894,0.410545,-86.026161,0.042234,0.000000
36.110001,15.871628,-86.070641,-0.003109,0.001652,0.041956,70.600525,3.596562,0.419564,-86.070641,0.042902,0.000000
36.510002,15.879074,-86.070641,-0.003074,0.001681,0.042702,70.633652,3.598249,0.427022,-86.070641,0.043569,0.000000
36.910000,15.445633,-86.115120,-0.003053,0.001702,0.043231,68.705605,3.500030,0.432312,-86.115120,0.044237,0.000000
37.310001,15.661980,-86.115120,-0.003018,0.001724,0.043795,69.667969,3.549055,0.437949,-86.115120,0.044905,0.000000
37.710003,16.157608,-86.115120,-0.002984,0.001757,0.044619,71.872627,3.661366,0.446188,-86.115120,0.045564,0.000000
38.110001,16.193359,-86.204086,-0.002953,0.001781,0.045234,72.031662,3.669467,0.452345,-86.204086,0.046232,0.000000
38.510002,16.337837,-86.204086,-0.002919,0.001808,0.045920,72.674332,3.702207,0.459196,-86.204086,0.046900,0.000000
38.910004,16.344543,-86.248566,-0.002876,0.001832,0.046544,72.704163,3.703727,0.465440,-86.248566,0.047567,0.000000
39.310001,15.881310,-86.248566,-0.002846,0.001847,0.046926,70.643593,3.598756,0.469256,-86.248566,0.048235,0.000000
39.710003,16.723618,-86.293045,-0.002828,0.001885,0.047880,74.390366,3.789626,0.478795,-86.293045,0.048903,0.000000
40.110001,16.535942,-86.337524,-0.002785,0.001906,0.048409,73.555542,3.747098,0.484085,-86.337524,0.049571,0.000000
40.510002,16.812614,-86.337524,-0.002742,0.001938,0.049215,74.786247,3.809793,0.492151,-86.337524,0.050238,0.000000
40.910004,16.935493,-86.382004,-0.002721,0.001965,0.049918,75.332840,3.837638,0.499175,-86.382004,0.050897,0.000000
41.310001,16.254799,-86.426491,-0.002686,0.001977,0.050212,72.304955,3.683390,0.502124,-86.426491,0.051565,0.000000
41.710003,17.482880,-86.470970,-0.002647,0.002013,0.051140,77.767731,3.961677,0.511403,-86.470970,0.052233,0.000000
42.110001,17.936806,-86.470970,-0.002617,0.002049,0.052042,79.786896,4.064538,0.520422,-86.470970,0.052901,0.000000
42.510002,17.672424,-86.515450,-0.002578,0.002073,0.052649,78.610870,4.004629,0.526493,-86.515450,0.053569,0.000000
42.910004,17.616562,-86.559929,-0.002531,0.002095,0.053204,78.362381,3.991970,0.532043,-86.559929,0.054236,0.000000
43.310001,17.726418,-86.559929,-0.002509,0.002118,0.053803,78.851044,4.016863,0.538027,-86.559929,0.054904,0.000000
43.710003,17.912971,-86.559929,-0.002492,0.002145,0.054488,79.680878,4.059137,0.544878,-86.559929,0.055572,0.000000
44.110001,17.654922,-86.604408,-0.002458,0.002159,0.054835,78.533020,4.000663,0.548347,-86.604408,0.056231,0.000000
44.510002,18.703896,-86.604408,-0.002414,0.002202,0.055936,83.199081,4.238363,0.559361,-86.604408,0.056899,0.000000
44.910004,18.501694,-86.693375,-0.002380,0.002225,0.056517,82.299644,4.192544,0.565171,-86.693375,0.057566,0.000000
45.310001,18.421265,-86.693375,-0.002358,0.002247,0.057081,81.941879,4.174318,0.570808,-86.693375,0.058234,0.000000
45.710003,18.805176,-86.693375,-0.002320,0.002277,0.057835,83.649597,4.261314,0.578353,-86.693375,0.058902,0.000000
46.110001,18.920242,-86.737854,-0.002289,0.002304,0.058529,84.161438,4.287388,0.585291,-86.737854,0.059570,0.000000
46.510002,19.025253,-86.782333,-0.002251,0.002330,0.059171,84.628555,4.311184,0.591708,-86.782333,0.060237,0.000000
46.910004,19.329475,-86.826813,-0.002220,0.002357,0.059873,85.981804,4.380122,0.598733,-86.826813,0.060905,0.000000
47.310001,19.745415,-86.826813,-0.002177,0.002387,0.060636,87.831993,4.474375,0.606364,-86.826813,0.061573,0.000000
47.710003,19.134354,-86.915779,-0.002151,0.002405,0.061079,85.113853,4.335907,0.610787,-86.915779,0.062232,0.000000
48.110001,19.644508,-86.915779,-0.002117,0.002439,0.061946,87.383141,4.451509,0.619459,-86.915779,0.062900,0.000000
48.510002,19.289261,-86.915779,-0.002091,0.002461,0.062501,85.802917,4.371009,0.625010,-86.915779,0.063568,0.000000
48.910004,19.033813,-86.915779,-0.002052,0.002478,0.062943,84.666634,4.313124,0.629432,-86.915779,0.064235,0.000000
49.310001,20.170670,-86.960258,-0.002031,0.002515,0.063889,89.723618,4.570739,0.638885,-86.960258,0.064903,0.000000
49.710003,19.462044,-87.049225,-0.002001,0.002532,0.064305,86.571495,4.410162,0.643048,-87.049225,0.065571,0.000000
50.110001,19.873512,-87.004738,-0.001940,0.002562,0.065085,88.401794,4.503402,0.650853,-87.004738,0.066239,0.000000
50.510002,19.517525,-87.049225,-0.001914,0.002589,0.065762,86.818283,4.422734,0.657617,-87.049225,0.066906,0.000000
50.910004,19.067329,-87.093704,-0.001897,0.002603,0.066109,84.815720,4.320718,0.661086,-87.093704,0.067566,0.000000
51.310001,20.337494,-87.138184,-0.001854,0.002648,0.067271,90.465691,4.608542,0.672707,-87.138184,0.068233,0.000000
51.710003,19.787498,-87.138184,-0.001832,0.002672,0.067878,88.019188,4.483911,0.678778,-87.138184,0.068901,0.000000
52.110001,19.663498,-87.182663,-0.001789,0.002692,0.068389,87.467606,4.455812,0.683894,-87.182663,0.069569,0.000000
52.510002,19.476196,-87.227142,-0.001750,0.002716,0.068996,86.634445,4.413369,0.689965,-87.227142,0.070237,0.000000
52.910004,20.263390,-87.271629,-0.001733,0.002751,0.069872,90.136055,4.591750,0.698724,-87.271629,0.070904,0.000000
53.310001,20.132683,-87.271629,-0.001677,0.002775,0.070479,89.554649,4.562131,0.704794,-87.271629,0.071572,0.000000
53.710003,20.325577,-87.316109,-0.001643,0.002802,0.071182,90.412682,4.605841,0.711819,-87.316109,0.072240,0.000000
54.110004,20.042946,-87.316109,-0.001608,0.002826,0.071789,89.155479,4.541796,0.717889,-87.316109,0.072899,0.000000
54.510002,19.924904,-87.360588,-0.001587,0.002850,0.072379,88.630402,4.515048,0.723787,-87.360588,0.073567,0.000000
54.910004,19.995651,-87.360588,-0.001569,0.002876,0.073055,88.945099,4.531079,0.730551,-87.360588,0.074235,0.000000
55.310001,20.295784,-87.405067,-0.001513,0.002907,0.073844,90.280159,4.599090,0.738443,-87.405067,0.074902,0.000000
55.710003,20.712471,-87.449547,-0.001475,0.002937,0.074590,92.133675,4.693513,0.745901,-87.449547,0.075570,0.000000
56.110004,20.340096,-87.449547,-0.001444,0.002962,0.075232,90.477264,4.609131,0.752318,-87.449547,0.076238,0.000000
56.510002,20.114067,-87.449547,-0.001418,0.002982,0.075743,89.471840,4.557913,0.757435,-87.449547,0.076906,0.000000
56.910004,20.684166,-87.582993,-0.001380,0.003010,0.076455,92.007767,4.687099,0.764546,-87.582993,0.077573,0.000000
57.310001,20.642090,-87.582993,-0.001337,0.003039,0.077200,91.820602,4.677565,0.772004,-87.582993,0.078232,0.000000
57.710003,21.040901,-87.582993,-0.001306,0.003071,0.078007,93.594604,4.767937,0.780070,-87.582993,0.078900,0.000000
58.110004,20.358345,-87.627472,-0.001259,0.003091,0.078510,90.558441,4.613267,0.785099,-87.627472,0.079568,0.000000
58.510002,20.324089,-87.582993,-0.001237,0.003115,0.079126,90.406067,4.605505,0.791257,-87.582993,0.080236,0.000000
58.910004,20.494629,-87.716438,-0.001220,0.003139,0.079733,91.164665,4.644149,0.797327,-87.716438,0.080903,0.000000
59.310001,20.885620,-87.716438,-0.001155,0.003171,0.080539,92.903877,4.732749,0.805393,-87.716438,0.081571,0.000000
59.710003,19.909264,-87.760918,-0.001134,0.003183,0.080843,88.560829,4.511504,0.808428,-87.760918,0.082239,0.000000
60.110004,20.947807,-87.760918,-0.001091,0.003224,0.081883,93.180504,4.746841,0.818835,-87.760918,0.082907,0.000000
60.510002,20.763115,-87.760918,-0.001069,0.003246,0.082438,92.358948,4.704989,0.824385,-87.760918,0.083575,0.000000
60.910004,21.196930,-87.805397,-0.001039,0.003275,0.083193,94.288651,4.803293,0.831930,-87.805397,0.084234,0.000000
61.310001,21.196556,-87.849876,-0.000996,0.003300,0.083826,94.286987,4.803208,0.838260,-87.849876,0.084901,0.000000
61.710003,21.242729,-87.894356,-0.000966,0.003326,0.084468,94.492378,4.813671,0.844678,-87.894356,0.085569,0.000000
62.110004,21.488495,-87.894356,-0.000940,0.003354,0.085188,95.585602,4.869363,0.851876,-87.894356,0.086237,0.000000
62.510002,20.989517,-87.894356,-0.000905,0.003365,0.085482,93.366035,4.756292,0.854824,-87.894356,0.086905,0.000000
62.910004,22.989159,-87.894356,-0.000892,0.003408,0.086575,102.260887,5.209418,0.865751,-87.894356,0.087572,0.000000
63.310001,23.378281,-87.983322,-0.000854,0.003438,0.087321,103.991783,5.297594,0.873210,-87.983322,0.088240,0.000000
63.710003,23.382751,-87.983322,-0.000824,0.003462,0.087945,104.011673,5.298607,0.879454,-87.983322,0.088908,0.000000
64.110001,23.797203,-88.027802,-0.000793,0.003487,0.088578,105.855247,5.392523,0.885784,-88.027802,0.089567,0.000000
64.510002,24.131218,-88.072281,-0.000772,0.003512,0.089203,107.341019,5.468212,0.892028,-88.072281,0.090235,0.000000
64.910004,24.732605,-88.116760,-0.000746,0.003536,0.089810,110.016121,5.604488,0.898099,-88.116760,0.090903,0.000000
65.310005,25.428192,-88.116760,-0.000724,0.003561,0.090443,113.110245,5.762111,0.904430,-88.116760,0.091570,0.000000
65.710007,26.817513,-88.161247,-0.000698,0.003594,0.091275,119.290253,6.076935,0.912755,-88.161247,0.092238,0.000000
66.110001,27.119881,-88.161247,-0.000673,0.003617,0.091865,120.635254,6.145452,0.918652,-88.161247,0.092906,0.000000
66.510002,27.551834,-88.161247,-0.000642,0.003642,0.092507,122.556679,6.243335,0.925070,-88.161247,0.093574,0.000000
66.910004,28.465263,-88.205727,-0.000634,0.003669,0.093183,126.619812,6.450321,0.931834,-88.205727,0.094241,0.000000
67.310005,28.734116,-88.250206,-0.000599,0.003687,0.093643,127.815727,6.511244,0.936430,-88.250206,0.094901,0.000000
67.710007,30.171478,-88.339172,-0.000573,0.003721,0.094519,134.209442,6.836955,0.945189,-88.339172,0.095568,0.000000
68.110001,30.909889,-88.339172,-0.000565,0.003746,0.095161,137.494049,7.004281,0.951607,-88.339172,0.096236,0.000000
68.510002,30.937820,-88.339172,-0.000543,0.003765,0.095620,137.618301,7.010610,0.956203,-88.339172,0.096904,0.000000
68.910004,32.896500,-88.383652,-0.000526,0.003802,0.096574,146.330933,7.454453,0.965743,-88.383652,0.097572,0.000000
69.310005,33.822212,-88.339172,-0.000500,0.003826,0.097173,150.448715,7.664223,0.971726,-88.339172,0.098239,0.000000
69.710007,34.798203,-88.472610,-0.000466,0.003854,0.097901,154.790131,7.885385,0.979011,-88.472610,0.098907,0.000000
70.110001,35.053650,-88.472610,-0.000457,0.003869,0.098283,155.926422,7.943271,0.982827,-88.472610,0.099575,0.000000
70.510002,36.708099,-88.472610,-0.000431,0.003901,0.099098,163.285782,8.318174,0.990979,-88.472610,0.100234,0.000000
70.910004,37.396248,-88.517090,-0.000427,0.003924,0.099662,166.346817,8.474111,0.996616,-88.517090,0.100902,0.000000
71.310005,38.994095,-88.472610,-0.000410,0.003957,0.100520,173.454391,8.836187,1.005201,-88.472610,0.101569,0.000000
71.710007,40.646683,-88.517090,-0.000379,0.003983,0.101171,180.805481,9.210670,1.011706,-88.517090,0.102237,0.000000
72.110001,41.189980,-88.517090,-0.000375,0.004002,0.101639,183.222183,9.333783,1.016389,-88.517090,0.102905,0.000000
72.510002,43.874413,-88.561577,-0.000345,0.004041,0.102636,195.163132,9.942083,1.026362,-88.561577,0.103573,0.000000
72.910004,44.033783,-88.561577,-0.000310,0.004057,0.103052,195.872055,9.978198,1.030524,-88.561577,0.104241,0.000000
73.310005,45.952621,-88.650536,-0.000310,0.004090,0.103894,204.407471,10.413013,1.038936,-88.650536,0.104908,0.000000
73.710007,46.583794,-88.650536,-0.000280,0.004106,0.104293,207.215057,10.556039,1.042926,-88.650536,0.105576,0.000000
74.110001,48.253883,-88.650536,-0.000289,0.004136,0.105047,214.643997,10.934486,1.050470,-88.650536,0.106235,0.000000
74.510002,50.310867,-88.695015,-0.000272,0.004168,0.105862,223.793915,11.400605,1.058622,-88.695015,0.106903,0.000000
74.910004,51.188919,-88.783981,-0.000246,0.004192,0.106469,227.699692,11.599575,1.064693,-88.783981,0.107571,0.000000
75.310005,53.432091,-88.828461,-0.000241,0.004221,0.107224,237.677811,12.107885,1.072238,-88.828461,0.108238,0.000000
75.710007,54.436378,-88.783981,-0.000216,0.004242,0.107753,242.145111,12.335460,1.077528,-88.783981,0.108906,0.000000
76.110001,56.136261,-88.828461,-0.000203,0.004270,0.108464,249.706558,12.720659,1.084639,-88.828461,0.109574,0.000000
76.510002,58.371613,-88.828461,-0.000194,0.004300,0.109218,259.649902,13.227196,1.092184,-88.828461,0.110242,0.000000
76.910004,59.664116,-88.872940,-0.000181,0.004321,0.109756,265.399231,13.520082,1.097561,-88.872940,0.110909,0.000000
77.310005,61.535294,-88.917419,-0.000168,0.004351,0.110528,273.722656,13.944097,1.105279,-88.917419,0.111569,0.000000
77.710007,62.650917,-88.917419,-0.000147,0.004370,0.110988,278.685211,14.196900,1.109876,-88.917419,0.112236,0.000000
78.110001,64.726151,-88.961899,-0.000142,0.004396,0.111664,287.916290,14.667155,1.116640,-88.961899,0.112904,0.000000
78.510002,65.930771,-89.006386,-0.000129,0.004407,0.111933,293.274719,14.940126,1.119328,-89.006386,0.019653,0.000000
78.910004,65.060165,-89.050865,-0.000112,0.004406,0.111915,289.402069,14.742845,1.119155,-89.050865,294.500458,0.000000
79.310005,66.539230,-89.006386,-0.000112,0.004396,0.111655,295.981293,15.078005,1.116553,-89.006386,294.500458,0.000000
79.710007,65.828003,-89.095345,-0.000099,0.004395,0.111638,292.817596,14.916839,1.116380,-89.095345,294.500458,0.000000
80.110001,65.260880,-89.050865,-0.000103,0.004396,0.111655,290.294891,14.788326,1.116553,-89.050865,294.500458,0.000000
80.510002,64.968933,-89.095345,-0.000091,0.004422,0.112314,288.996246,14.722170,1.123144,-89.095345,294.500458,0.000000
80.910004,65.763214,-89.095345,-0.000091,0.004438,0.112731,292.529388,14.902158,1.127307,-89.095345,294.500458,0.000000
81.310005,65.503662,-89.139824,-0.000082,0.004438,0.112731,291.374847,14.843342,1.127307,-89.139824,294.500458,0.000000
81.710007,65.248962,-89.184303,-0.000073,0.004438,0.112731,290.241882,14.785626,1.127307,-89.184303,294.500458,0.000000
82.110001,64.980850,-89.228790,-0.000082,0.004438,0.112731,289.049255,14.724871,1.127307,-89.228790,294.500458,0.000000
82.510002,65.249329,-89.228790,-0.000082,0.004456,0.113173,290.243500,14.785709,1.131729,-89.228790,294.500458,0.000000
82.910004,65.816086,-89.317749,-0.000091,0.004449,0.113008,292.764557,14.914139,1.130082,-89.317749,294.500458,0.000000
83.310005,65.565475,-89.362228,-0.000082,0.004449,0.113008,291.649811,14.857348,1.130082,-89.362228,294.500458,0.000000
83.710007,65.376678,-89.362228,-0.000073,0.004449,0.113017,290.809998,14.814567,1.130168,-89.362228,294.500458,0.000000
84.110001,65.203537,-89.362228,-0.000082,0.004449,0.113017,290.039825,14.775332,1.130168,-89.362228,294.500458,0.000000
84.510002,65.030380,-89.406715,-0.000078,0.004449,0.113017,289.269592,14.736094,1.130168,-89.406715,294.500458,0.000000
84.910004,64.856110,-89.451195,-0.000065,0.004449,0.113017,288.494385,14.696605,1.130168,-89.451195,294.500458,0.000000
85.310005,64.709763,-89.451195,-0.000073,0.004450,0.113026,287.843414,14.663442,1.130255,-89.451195,294.500458,0.000000
85.710007,64.562302,-89.495674,-0.000060,0.004450,0.113026,287.187469,14.630027,1.130255,-89.495674,294.500458,0.000000
86.110001,64.446121,-89.540154,-0.000082,0.004450,0.113026,286.670654,14.603700,1.130255,-89.540154,294.500458,0.000000
86.510002,66.863937,-89.540154,-0.000056,0.004282,0.108759,297.425659,15.151585,1.087588,-89.540154,294.500458,0.000000
86.910004,66.687805,-89.584633,-0.000056,0.004282,0.108759,296.642181,15.111672,1.087588,-89.584633,294.500458,0.000000
87.310005,66.583923,-89.629120,-0.000052,0.004282,0.108759,296.180084,15.088133,1.087588,-89.629120,294.500458,0.000000
87.710007,66.416718,-89.584633,-0.000043,0.004282,0.108767,295.436310,15.050243,1.087674,-89.584633,294.500458,0.000000
88.110001,66.296448,-89.673599,-0.000056,0.004282,0.108767,294.901337,15.022989,1.087674,-89.673599,294.500458,0.000000
88.510002,66.175049,-89.673599,-0.000065,0.004282,0.108767,294.361328,14.995481,1.087674,-89.673599,294.500458,0.000000
88.910004,66.077866,-89.718079,-0.000043,0.004282,0.108767,293.929016,14.973458,1.087674,-89.718079,294.500458,0.000000
89.310005,65.969498,-89.807037,-0.000065,0.004282,0.108767,293.446991,14.948902,1.087674,-89.807037,294.500458,0.000000
89.710007,65.878265,-89.718079,-0.000052,0.004299,0.109201,293.041168,14.928228,1.092011,-89.718079,294.500458,0.000000
90.110001,65.801559,-89.807037,-0.000043,0.004303,0.109305,292.699951,14.910847,1.093051,-89.807037,294.500458,0.000000
90.510002,65.682037,-89.851524,-0.000052,0.004317,0.109661,292.168304,14.883762,1.096607,-89.851524,294.500458,0.000000
90.910004,65.579254,-89.896004,-0.000060,0.004318,0.109678,291.711090,14.860472,1.096780,-89.896004,294.500458,0.000000
91.310005,65.503296,-89.851524,-0.000052,0.004369,0.110970,291.373199,14.843259,1.109702,-89.851524,294.500458,0.000000
91.710007,65.481323,-89.940483,-0.000056,0.004420,0.112280,291.275482,14.838281,1.122797,-89.940483,294.500458,0.000000
92.110001,65.401260,-89.940483,-0.000056,0.004425,0.112384,290.919342,14.820137,1.123838,-89.940483,294.500458,0.000000
92.510002,65.334610,-89.940483,-0.000047,0.004435,0.112644,290.622864,14.805035,1.126439,-89.940483,294.500458,0.000000
92.910004,65.299973,-89.984962,-0.000039,0.004438,0.112731,290.468781,14.797185,1.127307,-89.984962,294.500458,0.000000
93.310005,65.283966,-90.029442,-0.000056,0.004444,0.112878,290.397583,14.793558,1.128781,-90.029442,294.500458,0.000000
93.710007,65.213211,-89.984962,-0.000052,0.004444,0.112878,290.082855,14.777525,1.128781,-89.984962,294.500458,0.000000
94.110008,65.134644,-90.073929,-0.000043,0.004444,0.112878,289.733368,14.759721,1.128781,-90.073929,294.500458,0.000000
94.510002,65.073578,-90.073929,-0.000052,0.004444,0.112878,289.461731,14.745884,1.128781,-90.073929,294.500458,0.000000
94.910004,65.386368,-90.118408,-0.000043,0.004470,0.113529,290.853088,14.816763,1.135285,-90.118408,294.500458,0.000000
95.310005,65.377060,-90.162888,-0.000052,0.004470,0.113537,290.811676,14.814653,1.135372,-90.162888,294.500458,0.000000
95.710007,65.341309,-90.162888,-0.000060,0.004471,0.113555,290.652649,14.806552,1.135545,-90.162888,294.500458,0.000000
96.110008,65.316727,-90.207367,-0.000047,0.004471,0.113555,290.543304,14.800982,1.135545,-90.207367,294.500458,0.000000
96.510002,65.293640,-90.251846,-0.000047,0.004472,0.113581,290.440613,14.795751,1.135806,-90.251846,294.500458,0.000000
96.910004,65.346146,-90.251846,-0.000047,0.004473,0.113615,290.674164,14.807648,1.136152,-90.251846,294.500458,0.000000
97.310005,65.355087,-90.296333,-0.000039,0.004473,0.113624,290.713959,14.809674,1.136239,-90.296333,294.500458,0.000000
97.710007,65.353973,-90.340813,-0.000060,0.004474,0.113633,290.708984,14.809422,1.136326,-90.340813,294.500458,0.000000
98.110008,65.372589,-90.385292,-0.000047,0.004475,0.113659,290.791809,14.813641,1.136586,-90.385292,294.500458,0.000000
98.510002,65.402008,-90.340813,-0.000052,0.004475,0.113667,290.922668,14.820307,1.136673,-90.340813,294.500458,0.000000
98.910004,65.362534,-90.385292,-0.000056,0.004475,0.113676,290.747070,14.811362,1.136759,-90.385292,294.500458,0.000000
99.310005,65.395309,-90.429771,-0.000047,0.004476,0.113685,290.892853,14.818789,1.136846,-90.429771,294.500458,0.000000
99.710007,65.394562,-90.429771,-0.000047,0.004476,0.113693,290.889526,14.818619,1.136933,-90.429771,294.500458,0.000000
100.110008,65.372223,-90.474251,-0.000052,0.004476,0.113693,290.790161,14.813558,1.136933,-90.474251,294.500458,0.000000
100.510002,65.361038,-90.518738,-0.000034,0.004476,0.113702,290.740417,14.811023,1.137020,-90.518738,294.500458,0.000000
100.910004,65.367752,-90.563217,-0.000047,0.004477,0.113719,290.770294,14.812545,1.137193,-90.563217,294.500458,0.000000
101.310005,65.357697,-90.563217,-0.000043,0.004477,0.113728,290.725555,14.810266,1.137280,-90.563217,294.500458,0.000000
101.710007,65.343918,-90.607697,-0.000052,0.004477,0.113728,290.664276,14.807143,1.137280,-90.607697,294.500458,0.000000
102.110008,65.320831,-90.652176,-0.000052,0.004478,0.113745,290.561584,14.801912,1.137453,-90.652176,294.500458,0.000000
102.510002,65.383759,-90.696663,-0.000056,0.004480,0.113780,290.841492,14.816172,1.137800,-90.696663,294.500458,0.000000
102.910004,65.398651,-90.696663,-0.000034,0.004480,0.113780,290.907715,14.819546,1.137800,-90.696663,294.500458,0.000000
103.310005,65.386002,-90.696663,-0.000052,0.004480,0.113780,290.851471,14.816680,1.137800,-90.696663,294.500458,0.000000
103.710007,65.361786,-90.696663,-0.000056,0.004480,0.113780,290.743744,14.811193,1.137800,-90.696663,294.500458,0.000000
104.110008,65.345398,-90.785622,-0.000043,0.004480,0.113780,290.670837,14.807479,1.137800,-90.785622,294.500458,0.000000
104.510002,65.353592,-90.785622,-0.000034,0.004481,0.113806,290.707306,14.809336,1.138060,-90.785622,294.500458,0.000000
104.910004,65.370361,-90.874580,-0.000043,0.004481,0.113806,290.781891,14.813136,1.138060,-90.874580,294.500458,0.000000
105.310005,65.336090,-90.874580,-0.000056,0.004481,0.113806,290.629456,14.805369,1.138060,-90.874580,294.500458,0.000000
105.710007,65.340942,-90.874580,-0.000039,0.004481,0.113806,290.651031,14.806470,1.138060,-90.874580,294.500458,0.000000
106.110008,65.357697,-90.919067,-0.000034,0.004482,0.113832,290.725555,14.810266,1.138320,-90.919067,294.500458,0.000000
106.510002,65.352859,-90.874580,-0.000052,0.004482,0.113832,290.704041,14.809170,1.138320,-90.874580,294.500458,0.000000
106.910004,65.341309,-90.963547,-0.000030,0.004482,0.113841,290.652649,14.806552,1.138407,-90.963547,294.500458,0.000000
107.310005,65.339081,-91.008026,-0.000034,0.004482,0.113841,290.642761,14.806047,1.138407,-91.008026,294.500458,0.000000
107.710007,65.320831,-91.008026,-0.000039,0.004483,0.113858,290.561584,14.801912,1.138581,-91.008026,294.500458,0.000000
108.110008,65.341309,-91.052505,-0.000039,0.004483,0.113867,290.652649,14.806552,1.138667,-91.052505,294.500458,0.000000
108.510002,65.336090,-91.008026,-0.000039,0.004483,0.113867,290.629456,14.805369,1.138667,-91.008026,294.500458,0.000000
108.910004,65.327911,-91.141472,-0.000043,0.004483,0.113867,290.593048,14.803516,1.138667,-91.141472,294.500458,0.000000
109.310005,65.323059,-91.141472,-0.000047,0.004483,0.113867,290.571472,14.802417,1.138667,-91.141472,294.500458,0.000000
109.710007,65.309280,-91.141472,-0.000017,0.004484,0.113884,290.510193,14.799294,1.138841,-91.141472,294.500458,0.000000
110.110008,65.327530,-91.096985,-0.000034,0.004484,0.113893,290.591370,14.803431,1.138928,-91.096985,294.500458,0.000000
110.510002,65.328278,-91.141472,-0.000034,0.004484,0.113901,290.594696,14.803599,1.139014,-91.141472,294.500458,0.000000
110.910004,65.325668,-91.230431,-0.000052,0.004484,0.113901,290.583099,14.803008,1.139014,-91.230431,294.500458,0.000000
111.310005,65.310410,-91.230431,-0.000047,0.004484,0.113901,290.515198,14.799551,1.139014,-91.230431,294.500458,0.000000
111.710007,65.321198,-91.230431,-0.000026,0.004485,0.113927,290.563202,14.801995,1.139274,-91.230431,294.500458,0.000000
112.110008,65.337219,-91.363876,-0.000043,0.004485,0.113927,290.634460,14.805625,1.139274,-91.363876,294.500458,0.000000
112.510002,65.321945,-91.274910,-0.000039,0.004485,0.113927,290.566528,14.802165,1.139274,-91.274910,294.500458,0.000000
112.910004,65.321945,-91.319389,-0.000039,0.004486,0.113936,290.566528,14.802165,1.139361,-91.319389,294.500458,0.000000
113.310005,65.329773,-91.363876,-0.000039,0.004486,0.113936,290.601349,14.803939,1.139361,-91.363876,294.500458,0.000000
113.710007,65.311523,-91.408356,-0.000047,0.004486,0.113945,290.520172,14.799802,1.139448,-91.408356,294.500458,0.000000
114.110008,65.310776,-91.452835,-0.000034,0.004486,0.113953,290.516846,14.799634,1.139535,-91.452835,294.500458,0.000000
114.510002,65.355835,-91.452835,-0.000034,0.004487,0.113971,290.717285,14.809844,1.139708,-91.452835,294.500458,0.000000
114.910004,65.359924,-91.452835,-0.000026,0.004487,0.113979,290.735474,14.810771,1.139795,-91.452835,294.500458,0.000000
115.310005,65.363281,-91.497314,-0.000047,0.004487,0.113979,290.750397,14.811532,1.139795,-91.497314,294.500458,0.000000
115.710007,65.355453,-91.541794,-0.000030,0.004487,0.113979,290.715576,14.809758,1.139795,-91.541794,294.500458,0.000000
116.110008,65.346146,-91.630760,-0.000052,0.004487,0.113979,290.674164,14.807648,1.139795,-91.630760,294.500458,0.000000
116.510002,65.337585,-91.586281,-0.000030,0.004487,0.113979,290.636108,14.805709,1.139795,-91.586281,294.500458,0.000000
116.910004,65.319336,-91.586281,-0.000026,0.004487,0.113979,290.554932,14.801573,1.139795,-91.586281,294.500458,0.000000
117.310005,65.326782,-91.630760,-0.000017,0.004487,0.113979,290.588043,14.803261,1.139795,-91.630760,294.500458,0.000000
117.710007,65.308167,-91.719719,-0.000039,0.004487,0.113979,290.505219,14.799042,1.139795,-91.719719,294.500458,0.000000
118.110008,65.314133,-91.719719,-0.000026,0.004487,0.113979,290.531769,14.800394,1.139795,-91.719719,294.500458,0.000000
118.510002,65.289917,-91.719719,-0.000039,0.004488,0.113988,290.424042,14.794907,1.139881,-91.719719,294.500458,0.000000
118.910004,65.291046,-91.764198,-0.000043,0.004488,0.113997,290.429077,14.795162,1.139968,-91.764198,294.500458,0.000000
119.310005,65.278381,-91.764198,-0.000034,0.004488,0.113997,290.372742,14.792293,1.139968,-91.764198,294.500458,0.000000
119.710007,65.286942,-91.764198,-0.000039,0.004488,0.113997,290.410828,14.794232,1.139968,-91.764198,294.500458,0.000000
120.110008,65.281723,-91.808685,-0.000039,0.004489,0.114014,290.387604,14.793050,1.140142,-91.808685,294.500458,0.000000
120.510002,65.293640,-91.853165,-0.000022,0.004489,0.114014,290.440613,14.795751,1.140142,-91.853165,294.500458,0.000000
120.910004,65.281357,-91.897644,-0.000030,0.004489,0.114014,290.385986,14.792967,1.140142,-91.897644,294.500458,0.000000
121.310005,65.271301,-91.897644,-0.000022,0.004489,0.114014,290.341248,14.790689,1.140142,-91.897644,294.500458,0.000000
121.710007,65.250076,-91.897644,-0.000026,0.004489,0.114023,290.246826,14.785879,1.140228,-91.897644,294.500458,0.000000
122.110008,65.247467,-92.031090,-0.000034,0.004489,0.114023,290.235229,14.785287,1.140228,-92.031090,294.500458,0.000000
122.510002,65.246353,-91.986610,-0.000022,0.004489,0.114023,290.230286,14.785034,1.140228,-91.986610,294.500458,0.000000
122.910004,65.253052,-91.942123,-0.000030,0.004489,0.114023,290.260071,14.786552,1.140228,-91.942123,294.500458,0.000000
123.310005,65.219543,-91.986610,-0.000022,0.004489,0.114023,290.111023,14.778960,1.140228,-91.986610,294.500458,0.000000
123.710007,65.224762,-92.075569,-0.000034,0.004489,0.114023,290.134216,14.780142,1.140228,-92.075569,294.500458,0.000000
124.110008,65.190125,-92.075569,-0.000034,0.004489,0.114023,289.980164,14.772293,1.140228,-92.075569,294.500458,0.000000
124.510002,65.183044,-92.120049,-0.000022,0.004489,0.114023,289.948669,14.770689,1.140228,-92.120049,294.500458,0.000000
124.910004,65.200180,-92.120049,-0.000026,0.004489,0.114032,290.024872,14.774571,1.140315,-92.120049,294.500458,0.000000
125.310005,65.206879,-92.209015,-0.000026,0.004489,0.114032,290.054687,14.776090,1.140315,-92.209015,294.500458,0.000000
125.710007,65.194229,-92.164528,-0.000034,0.004489,0.114032,289.998413,14.773223,1.140315,-92.164528,294.500458,0.000000
126.110008,65.159958,-92.209015,-0.000022,0.004489,0.114032,289.845978,14.765458,1.140315,-92.209015,294.500458,0.000000
126.510010,65.143204,-92.209015,-0.000026,0.004489,0.114032,289.771454,14.761662,1.140315,-92.209015,294.500458,0.000000
126.910004,65.125702,-92.253494,-0.000017,0.004489,0.114032,289.693604,14.757695,1.140315,-92.253494,294.500458,0.000000
127.310005,65.140976,-92.253494,-0.000039,0.004489,0.114032,289.761536,14.761156,1.140315,-92.253494,294.500458,0.000000
127.710007,65.114532,-92.297974,-0.000030,0.004491,0.114075,289.643921,14.755164,1.140749,-92.297974,294.500458,0.000000
128.110001,65.332748,-92.342453,-0.000034,0.004494,0.114136,290.614594,14.804612,1.141356,-92.342453,294.500458,0.000000
128.510010,65.352478,-92.297974,-0.000039,0.004494,0.114136,290.702332,14.809083,1.141356,-92.297974,294.500458,0.000000
128.910004,65.350250,-92.431419,-0.000026,0.004494,0.114136,290.692444,14.808578,1.141356,-92.431419,294.500458,0.000000
129.310013,65.357315,-92.386932,-0.000030,0.004494,0.114136,290.723846,14.810179,1.141356,-92.386932,294.500458,0.000000
129.710007,65.372589,-92.475899,-0.000026,0.004494,0.114136,290.791809,14.813641,1.141356,-92.475899,294.500458,0.000000
130.110001,65.371841,-92.475899,-0.000026,0.004494,0.114136,290.788483,14.813471,1.141356,-92.475899,294.500458,0.000000
130.510010,65.369980,-92.475899,-0.000013,0.004494,0.114136,290.780182,14.813048,1.141356,-92.475899,294.500458,0.000000
130.910004,65.358444,-92.520378,-0.000034,0.004494,0.114136,290.728882,14.810435,1.141356,-92.520378,294.500458,0.000000
131.310013,65.343170,-92.520378,-0.000026,0.004494,0.114136,290.660950,14.806974,1.141356,-92.520378,294.500458,0.000000
131.710007,65.327911,-92.564857,-0.000034,0.004494,0.114136,290.593048,14.803516,1.141356,-92.564857,294.500458,0.000000
132.110001,65.317108,-92.609337,-0.000030,0.004494,0.114136,290.545013,14.801068,1.141356,-92.609337,294.500458,0.000000
132.510010,65.329025,-92.609337,-0.000034,0.004494,0.114136,290.598022,14.803769,1.141356,-92.609337,294.500458,0.000000
132.910004,65.319336,-92.653824,-0.000039,0.004494,0.114136,290.554932,14.801573,1.141356,-92.653824,294.500458,0.000000
133.310013,65.323807,-92.653824,-0.000030,0.004494,0.114136,290.574799,14.802586,1.141356,-92.653824,294.500458,0.000000
133.710007,65.304810,-92.653824,-0.000034,0.004494,0.114136,290.490295,14.798281,1.141356,-92.653824,294.500458,0.000000
134.110001,65.286194,-92.698303,-0.000030,0.004494,0.114136,290.407501,14.794064,1.141356,-92.698303,294.500458,0.000000
134.510010,65.270554,-92.742783,-0.000034,0.004494,0.114136,290.337921,14.790519,1.141356,-92.742783,294.500458,0.000000
134.910004,65.268692,-92.698303,-0.000013,0.004494,0.114136,290.329651,14.790096,1.141356,-92.698303,294.500458,0.000000
135.310013,65.253433,-92.787262,-0.000026,0.004494,0.114136,290.261780,14.786639,1.141356,-92.787262,294.500458,0.000000
135.710007,65.244125,-92.831741,-0.000022,0.004494,0.114136,290.220367,14.784530,1.141356,-92.831741,294.500458,0.000000
136.110001,65.249710,-92.787262,-0.000022,0.004494,0.114136,290.245209,14.785795,1.141356,-92.787262,294.500458,0.000000
136.510010,65.235184,-92.876228,-0.000017,0.004494,0.114136,290.180603,14.782503,1.141356,-92.876228,294.500458,0.000000
136.910004,65.218430,-92.920708,-0.000026,0.004494,0.114153,290.106049,14.778708,1.141529,-92.920708,294.500458,0.000000
137.310013,65.214706,-92.965187,-0.000030,0.004494,0.114153,290.089508,14.777864,1.141529,-92.965187,294.500458,0.000000
137.710007,65.225128,-92.965187,-0.000030,0.004494,0.114153,290.135864,14.780226,1.141529,-92.965187,294.500458,0.000000
138.110001,65.194595,-93.009666,-0.000013,0.004495,0.114162,290.000031,14.773306,1.141616,-93.009666,294.500458,0.000000
138.510010,65.225494,-93.009666,-0.000022,0.004495,0.114170,290.137482,14.780309,1.141703,-93.009666,294.500458,0.000000
138.910004,65.216934,-92.965187,-0.000017,0.004495,0.114170,290.099426,14.778368,1.141703,-92.965187,1681.640747,0.000000
139.310013,65.225494,-93.098633,-0.000026,0.004486,0.113953,290.137482,14.780309,1.139535,-93.098633,0.113806,0.000000
139.710007,65.174866,-93.054146,-0.000022,0.004472,0.113581,289.912292,14.768836,1.135806,-93.054146,0.113138,0.000000
140.110001,65.067612,-93.143112,0.000000,0.004447,0.112947,289.435181,14.744532,1.129475,-93.143112,0.112479,0.000000
140.510010,65.076920,-93.098633,-0.000017,0.004424,0.112358,289.476593,14.746641,1.123578,-93.098633,0.111811,0.000000
140.910004,65.073578,-93.187592,0.000000,0.004399,0.111733,289.461731,14.745884,1.117334,-93.187592,0.111144,0.000000
141.310013,65.020691,-93.187592,-0.000017,0.004372,0.111040,289.226471,14.733899,1.110396,-93.187592,0.110476,0.000000
141.710007,64.993134,-93.187592,-0.000017,0.004351,0.110528,289.103882,14.727654,1.105279,-93.187592,0.109808,0.000000
142.110001,64.930206,-93.232071,-0.000017,0.004318,0.109669,288.823975,14.713395,1.096694,-93.232071,0.109140,0.000000
142.510010,64.952927,-93.276558,-0.000004,0.004298,0.109158,288.925049,14.718543,1.091577,-93.276558,0.108473,0.000000
142.910004,64.847168,-93.232071,-0.000004,0.004270,0.108447,288.454620,14.694578,1.084466,-93.232071,0.107805,0.000000
143.310013,64.564911,-93.321037,0.000000,0.004245,0.107813,287.199066,14.630618,1.078135,-93.321037,0.107146,0.000000
143.710007,63.938950,-93.409996,-0.000009,0.004225,0.107310,284.414642,14.488773,1.073105,-93.409996,0.106478,0.000000
144.110001,62.714592,-93.454475,0.000000,0.004196,0.106591,278.968445,14.211329,1.065907,-93.454475,0.105810,0.000000
144.510010,61.619820,-93.409996,0.000009,0.004176,0.106079,274.098633,13.963250,1.060791,-93.409996,0.105142,0.000000
144.910004,59.596344,-93.409996,0.000004,0.004147,0.105333,265.097778,13.504725,1.053332,-93.409996,0.104475,0.000000
145.310013,57.521484,-93.409996,-0.000004,0.004122,0.104709,255.868347,13.034555,1.047088,-93.409996,0.103807,0.000000
145.710007,55.858101,-93.454475,0.000000,0.004102,0.104188,248.469238,12.657626,1.041885,-93.454475,0.103139,0.000000
146.110001,53.328201,-93.543442,-0.000004,0.004074,0.103469,237.215683,12.084343,1.034687,-93.543442,0.102471,0.000000
146.510010,50.653824,-93.587921,-0.000009,0.004049,0.102844,225.319458,11.478321,1.028443,-93.587921,0.101812,0.000000
146.910004,47.808151,-93.498962,0.000009,0.004022,0.102168,212.661285,10.833482,1.021679,-93.498962,0.101145,0.000000
147.310013,44.815025,-93.587921,0.000000,0.003997,0.101526,199.347183,10.155231,1.015261,-93.587921,0.100477,0.000000
147.710007,42.073990,-93.587921,0.000000,0.003970,0.100832,187.154449,9.534102,1.008323,-93.587921,0.099809,0.000000
148.110001,39.366470,-93.632401,0.000000,0.003944,0.100182,175.110809,8.920569,1.001819,-93.632401,0.099141,0.000000
148.510010,36.437759,-93.676880,-0.000004,0.003919,0.099540,162.083252,8.256914,0.995402,-93.676880,0.098473,0.000000
148.910004,33.992386,-93.676880,-0.000009,0.003890,0.098803,151.205688,7.702785,0.988030,-93.676880,0.097806,0.000000
149.310013,30.500648,-93.765846,0.000000,0.003862,0.098083,135.673660,6.911546,0.980832,-93.765846,0.097138,0.000000
149.710007,28.707680,-93.765846,-0.000022,0.003848,0.097736,127.698135,6.505253,0.977363,-93.765846,0.096479,0.000000
150.110001,24.950066,-93.810326,-0.000026,0.003812,0.096817,110.983437,5.653766,0.968171,-93.810326,0.095811,0.000000
150.510010,22.554596,-93.810326,0.000000,0.003792,0.096323,100.327850,5.110944,0.963228,-93.810326,0.095143,0.000000
150.910004,19.341766,-93.810326,-0.000017,0.003759,0.095490,86.036476,4.382907,0.954902,-93.810326,0.094476,0.000000
151.310013,17.047951,-93.854805,-0.000022,0.003742,0.095057,75.833069,3.863121,0.950566,-93.854805,0.093808,0.000000
151.710007,13.797882,-93.899284,-0.000043,0.003713,0.094319,61.376045,3.126645,0.943195,-93.899284,0.093140,0.000000
152.110001,10.004898,-93.988251,-0.000034,0.003679,0.093444,44.504009,2.267142,0.934436,-93.988251,0.092472,0.000000
152.510010,7.725235,-93.943771,-0.000043,0.003657,0.092880,34.363560,1.750563,0.928799,-93.943771,0.091805,0.000000
152.910004,4.714233,-94.032730,-0.000043,0.003632,0.092247,20.969957,1.068261,0.922468,-94.032730,0.091145,0.000000
153.310013,2.073364,-93.988251,-0.000052,0.003603,0.091518,9.222785,0.469831,0.915183,-93.988251,0.090478,0.000000
153.710007,-0.227898,-94.077209,-0.000060,0.003580,0.090929,-1.013739,-0.051642,0.909286,-94.077209,0.089810,0.000000
154.110001,-0.116928,-94.077209,-0.000116,0.003547,0.090096,-0.520122,-0.026496,0.900961,-94.077209,0.089142,0.000000
154.510010,0.230865,-94.077209,-0.000160,0.003528,0.089602,1.026941,0.052315,0.896018,-94.077209,0.088474,0.000000
154.910004,0.166451,-94.121689,-0.000194,0.003505,0.089021,0.740409,0.037718,0.890207,-94.121689,0.087807,0.000000
155.310013,0.216721,-94.121689,-0.000254,0.003476,0.088301,0.964021,0.049110,0.883009,-94.121689,0.087139,0.000000
155.710007,0.208900,-94.121689,-0.000302,0.003456,0.087789,0.929236,0.047338,0.877893,-94.121689,0.086471,0.000000
156.110001,0.165703,-94.166176,-0.000384,0.003416,0.086775,0.737083,0.037549,0.867746,-94.166176,0.085803,0.000000
156.510010,0.164955,-94.210655,-0.000423,0.003401,0.086376,0.733757,0.037379,0.863757,-94.210655,0.085144,0.000000
156.910004,0.152672,-94.210655,-0.000461,0.003388,0.086046,0.679118,0.034596,0.860461,-94.210655,0.084476,0.000000
157.310013,0.054733,-94.255135,-0.000535,0.003341,0.084867,0.243466,0.012403,0.848667,-94.255135,0.083809,0.000000
157.710007,0.076332,-94.344101,-0.000608,0.003308,0.084025,0.339542,0.017297,0.840255,-94.344101,0.083141,0.000000
158.110001,0.045799,-94.344101,-0.000668,0.003287,0.083479,0.203725,0.010378,0.834791,-94.344101,0.082473,0.000000
158.510010,0.082664,-94.433060,-0.000716,0.003265,0.082941,0.367710,0.018732,0.829415,-94.433060,0.081805,0.000000
158.910004,0.034630,-94.388580,-0.000776,0.003247,0.082464,0.154041,0.007847,0.824645,-94.388580,0.081138,0.000000
159.310013,0.018990,-94.477539,-0.000828,0.003219,0.081762,0.084470,0.004303,0.817620,-94.477539,0.080470,0.000000
159.710007,0.010422,-94.433060,-0.000905,0.003176,0.080669,0.046358,0.002362,0.806693,-94.433060,0.079811,0.000000
160.110001,-0.005592,-94.477539,-0.000936,0.003157,0.080184,-0.024876,-0.001267,0.801837,-94.477539,0.079143,0.000000
160.510010,0.024200,-94.566505,-0.000987,0.003135,0.079620,0.107649,0.005484,0.796200,-94.566505,0.078475,0.000000
160.910004,0.014893,-94.477539,-0.001039,0.003101,0.078770,0.066245,0.003375,0.787701,-94.477539,0.077807,0.000000
161.310013,0.003349,-94.566505,-0.001087,0.003075,0.078102,0.014898,0.000759,0.781024,-94.566505,0.077140,0.000000
161.710007,-0.006706,-94.566505,-0.001130,0.003048,0.077417,-0.029831,-0.001520,0.774172,-94.566505,0.076472,0.000000
162.110001,0.022713,-94.610985,-0.001147,0.003027,0.076880,0.101031,0.005147,0.768796,-94.610985,0.075804,0.000000
162.510010,0.030907,-94.699944,-0.001194,0.003002,0.076255,0.137480,0.007004,0.762552,-94.699944,0.075136,0.000000
162.910004,0.011169,-94.655464,-0.001250,0.002974,0.075535,0.049684,0.002531,0.755354,-94.655464,0.074477,0.000000
163.310013,0.030533,-94.655464,-0.001281,0.002952,0.074980,0.135817,0.006919,0.749803,-94.655464,0.073810,0.000000
163.710007,-0.027184,-94.699944,-0.001319,0.002918,0.074113,-0.120918,-0.006160,0.741131,-94.699944,0.073142,0.000000
164.110001,0.033882,-94.699944,-0.001345,0.002895,0.073523,0.150715,0.007678,0.735234,-94.699944,0.072474,0.000000
164.510010,0.037979,-94.788910,-0.001380,0.002867,0.072812,0.168940,0.008606,0.728123,-94.788910,0.071806,0.000000
164.910004,0.018990,-94.833389,-0.001423,0.002841,0.072162,0.084470,0.004303,0.721618,-94.833389,0.071139,0.000000
165.310013,0.013031,-94.833389,-0.001449,0.002818,0.071572,0.057965,0.002953,0.715721,-94.833389,0.070471,0.000000
165.710007,-0.022346,-94.833389,-0.001492,0.002787,0.070792,-0.099402,-0.005064,0.707916,-94.833389,0.069803,0.000000
166.110001,0.006325,-94.877869,-0.001522,0.002765,0.070219,0.028134,0.001433,0.702193,-94.877869,0.070141,0.000000
166.200012,-0.001495,-94.877869,-0.001522,0.002765,0.070228,-0.006652,-0.000339,0.702279,-94.877869,0.070141,0.000000