File: Data/compression 32/AutoNoHeating-17-32-reverse-1-2_11142024_160930.csv
Time (sec),S:Load (lbs),S:HL1 (DIM),S:LVDT (in),S:Position (in),Ch:Position (mm),Ch:Load (N),Ch:Stress (MPa),Ch:Strain (mm/mm),Ch:HL1 (DIM),Set Point (),Cycles ()
0.110000,-0.080437,-184.418030,-0.014573,-0.009130,-0.231905,-0.357800,-0.018227,-2.319051,-184.418030,-0.231689,0.000000
0.510000,-0.019737,-184.462509,-0.014577,-0.009064,-0.230222,-0.087796,-0.004473,-2.302215,-184.462509,-0.229398,0.000000
0.910000,0.017876,-184.506989,-0.014426,-0.008816,-0.223936,0.079515,0.004051,-2.239356,-184.506989,-0.222721,0.000000
1.310000,0.029419,-184.551468,-0.014150,-0.008556,-0.217335,0.130862,0.006666,-2.173347,-184.551468,-0.216060,0.000000
1.710000,-0.001122,-184.551468,-0.013879,-0.008303,-0.210884,-0.004989,-0.000254,-2.108838,-184.551468,-0.209400,0.000000
2.110000,-0.034256,-184.551468,-0.013607,-0.008023,-0.203789,-0.152378,-0.007763,-2.037894,-184.551468,-0.202740,0.000000
2.510000,-0.061440,-184.640427,-0.013323,-0.007757,-0.197016,-0.273297,-0.013922,-1.970159,-184.640427,-0.196062,0.000000
2.910000,-0.000374,-184.684906,-0.013073,-0.007500,-0.190512,-0.001663,-0.000085,-1.905119,-184.684906,-0.189402,0.000000
3.310000,-0.004471,-184.684906,-0.012788,-0.007236,-0.183782,-0.019887,-0.001013,-1.837824,-184.684906,-0.182742,0.000000
3.710000,-0.009682,-184.773865,-0.012512,-0.006977,-0.177209,-0.043066,-0.002194,-1.772088,-184.773865,-0.176081,0.000000
4.110000,-0.043198,-184.818344,-0.012245,-0.006714,-0.170531,-0.192153,-0.009789,-1.705307,-184.818344,-0.169421,0.000000
4.510000,-0.077827,-184.773865,-0.011977,-0.006450,-0.163827,-0.346194,-0.017636,-1.638269,-184.773865,-0.162743,0.000000
4.910000,-0.064423,-184.862839,-0.011701,-0.006191,-0.157246,-0.286566,-0.014598,-1.572457,-184.862839,-0.156083,0.000000
5.310000,-0.015266,-184.862839,-0.011438,-0.005928,-0.150559,-0.067908,-0.003459,-1.505586,-184.862839,-0.149423,0.000000
5.710000,-0.009682,-184.951797,-0.011163,-0.005662,-0.143820,-0.043066,-0.002194,-1.438200,-184.951797,-0.142763,0.000000
6.110000,-0.032028,-184.951797,-0.010891,-0.005401,-0.137178,-0.142469,-0.007258,-1.371782,-184.951797,-0.136102,0.000000
6.510000,-0.021599,-184.951797,-0.010632,-0.005136,-0.130465,-0.096076,-0.004894,-1.304653,-184.951797,-0.129425,0.000000
6.910000,0.007072,-184.996277,-0.010382,-0.004880,-0.123952,0.031460,0.001603,-1.239523,-184.996277,-0.122764,0.000000
7.310000,0.026436,-185.040756,-0.010119,-0.004619,-0.117318,0.117593,0.005990,-1.173181,-185.040756,-0.116104,0.000000
7.710001,0.040215,-185.040756,-0.009852,-0.004359,-0.110719,0.178883,0.009113,-1.107188,-185.040756,-0.109444,0.000000
8.110001,0.020477,-185.040756,-0.009589,-0.004107,-0.104318,0.091088,0.004640,-1.043178,-185.040756,-0.102784,0.000000
8.510000,-0.024948,-185.085236,-0.009326,-0.003829,-0.097260,-0.110975,-0.005653,-0.972597,-185.085236,-0.096106,0.000000
8.910001,-0.029419,-185.129715,-0.009054,-0.003561,-0.090461,-0.130862,-0.006666,-0.904605,-185.129715,-0.089446,0.000000
9.310000,0.030533,-185.263168,-0.008791,-0.003304,-0.083929,0.135817,0.006919,-0.839293,-185.263168,-0.082785,0.000000
9.710000,-0.000374,-185.218674,-0.008511,-0.003038,-0.077157,-0.001663,-0.000085,-0.771574,-185.218674,-0.076125,0.000000
10.110001,0.019737,-185.263168,-0.008244,-0.002778,-0.070566,0.087796,0.004473,-0.705656,-185.263168,-0.069465,0.000000
10.510000,-0.011917,-185.307648,-0.007976,-0.002515,-0.063889,-0.053010,-0.002700,-0.638890,-185.307648,-0.062787,0.000000
10.910001,-0.064049,-185.307648,-0.007700,-0.002251,-0.057185,-0.284903,-0.014514,-0.571852,-185.307648,-0.056127,0.000000
11.310000,-0.046173,-185.352127,-0.007433,-0.001994,-0.050654,-0.205388,-0.010463,-0.506540,-185.352127,-0.049467,0.000000
11.710001,0.001862,-185.352127,-0.007157,-0.001730,-0.043943,0.008281,0.000422,-0.439426,-185.352127,-0.042806,0.000000
12.110001,0.021225,-185.441086,-0.006890,-0.001464,-0.037186,0.094413,0.004810,-0.371858,-185.441086,-0.036129,0.000000
12.510000,-0.002235,-185.396606,-0.006622,-0.001202,-0.030526,-0.009944,-0.000507,-0.305259,-185.396606,-0.029468,0.000000
12.910001,0.001862,-185.441086,-0.006342,-0.000939,-0.023848,0.008281,0.000422,-0.238479,-185.441086,-0.022808,0.000000
13.310000,0.030907,-185.485565,-0.006084,-0.000682,-0.017327,0.137480,0.007004,-0.173272,-185.485565,-0.016148,0.000000
13.710001,0.048409,-185.530045,-0.005812,-0.000421,-0.010701,0.215332,0.010970,-0.107007,-185.530045,-0.009488,0.000000
14.110001,0.065163,-185.619003,-0.005553,-0.000163,-0.004136,0.289858,0.014766,-0.041361,-185.619003,-0.002810,0.000000
14.510000,0.219330,-185.663483,-0.005346,-0.000008,-0.000191,0.975628,0.049701,-0.001908,-185.663483,0.000070,0.000000
14.910001,0.045425,-185.663483,-0.005338,-0.000008,-0.000191,0.202062,0.010294,-0.001908,-185.663483,0.000104,0.000000
15.310000,0.118042,-185.663483,-0.005359,-0.000005,-0.000138,0.525077,0.026749,-0.001378,-185.663483,0.000772,0.000000
15.710001,0.184326,-185.707977,-0.005342,0.000019,0.000486,0.819924,0.041769,0.004860,-185.707977,0.001440,0.000000
16.110001,0.333275,-185.707977,-0.005303,0.000050,0.001275,1.482481,0.075521,0.012748,-185.707977,0.002107,0.000000
16.510000,0.427856,-185.752457,-0.005295,0.000063,0.001605,1.903201,0.096954,0.016048,-185.752457,0.002768,0.000000
16.910002,0.686653,-185.796936,-0.005273,0.000099,0.002507,3.054386,0.155598,0.025071,-185.796936,0.003435,0.000000
17.310001,0.926086,-185.796936,-0.005234,0.000125,0.003175,4.119438,0.209854,0.031748,-185.796936,0.004103,0.000000
17.710001,1.165527,-185.796936,-0.005221,0.000149,0.003791,5.184525,0.264112,0.037910,-185.796936,0.004770,0.000000
18.110001,1.600830,-185.885895,-0.005200,0.000177,0.004484,7.120848,0.362753,0.044843,-185.885895,0.005438,0.000000
18.510000,1.820526,-185.930374,-0.005178,0.000193,0.004892,8.098104,0.412537,0.048916,-185.930374,0.006106,0.000000
18.910002,2.339615,-185.930374,-0.005148,0.000225,0.005715,10.407126,0.530164,0.057152,-185.930374,0.006773,0.000000
19.310001,2.806946,-185.974854,-0.005122,0.000256,0.006504,12.485918,0.636063,0.065040,-185.974854,0.007441,0.000000
19.710001,3.284698,-186.019333,-0.005113,0.000282,0.007164,14.611069,0.744323,0.071640,-186.019333,0.008100,0.000000
20.110001,3.890175,-186.019333,-0.005062,0.000313,0.007962,17.304361,0.881526,0.079619,-186.019333,0.008769,0.000000
20.510000,4.338135,-186.063812,-0.005066,0.000336,0.008543,19.296988,0.983035,0.085433,-186.063812,0.009437,0.000000
20.910002,4.870628,-186.152786,-0.005057,0.000365,0.009271,21.665636,1.103700,0.092715,-186.152786,0.010104,0.000000
21.310001,5.215073,-186.152786,-0.005010,0.000390,0.009913,23.197802,1.181752,0.099134,-186.152786,0.010772,0.000000
21.710001,5.712936,-186.152786,-0.004980,0.000415,0.010537,25.412411,1.294570,0.105371,-186.152786,0.011439,0.000000
22.110001,6.172073,-186.197266,-0.004971,0.000444,0.011274,27.454754,1.398612,0.112744,-186.197266,0.012107,0.000000
22.510000,6.636795,-186.241745,-0.004932,0.000467,0.011865,29.521938,1.503919,0.118649,-186.241745,0.012775,0.000000
22.910002,7.011024,-186.286224,-0.004924,0.000494,0.012540,31.186594,1.588721,0.125401,-186.286224,0.013433,0.000000
23.310001,7.469421,-186.241745,-0.004881,0.000523,0.013277,33.225647,1.692595,0.132774,-186.241745,0.014101,0.000000
23.710001,7.855568,-186.330704,-0.004850,0.000547,0.013894,34.943310,1.780097,0.138936,-186.330704,0.014769,0.000000
24.110001,8.216766,-186.330704,-0.004829,0.000572,0.014517,36.550003,1.861946,0.145173,-186.330704,0.015438,0.000000
24.510000,8.722450,-186.375183,-0.004807,0.000602,0.015289,38.799397,1.976535,0.152895,-186.375183,0.016105,0.000000
24.910002,8.893745,-186.375183,-0.004764,0.000628,0.015940,39.561356,2.015352,0.159405,-186.375183,0.016773,0.000000
25.310001,8.936195,-186.464142,-0.004751,0.000645,0.016392,39.750183,2.024971,0.163916,-186.464142,0.017441,0.000000
25.710001,9.232605,-186.508621,-0.004738,0.000669,0.016981,41.068680,2.092138,0.169806,-186.508621,0.018108,0.000000
26.110001,9.752060,-186.464142,-0.004704,0.000698,0.017727,43.379330,2.209848,0.177269,-186.464142,0.018776,0.000000
26.510002,10.473351,-186.553116,-0.004682,0.000736,0.018690,46.587791,2.373295,0.186898,-186.553116,0.019435,0.000000
26.910002,10.316582,-186.464142,-0.004639,0.000757,0.019227,45.890446,2.337771,0.192273,-186.464142,0.020102,0.000000
27.310001,10.397011,-186.597595,-0.004622,0.000778,0.019765,46.248215,2.355996,0.197647,-186.597595,0.020770,0.000000
27.710001,10.906044,-186.642075,-0.004609,0.000807,0.020502,48.512508,2.471345,0.205020,-186.642075,0.021438,0.000000
28.110001,10.951843,-186.642075,-0.004566,0.000826,0.020970,48.716232,2.481723,0.209698,-186.642075,0.022107,0.000000
28.510002,11.386032,-186.775513,-0.004531,0.000856,0.021733,50.647602,2.580112,0.217329,-186.775513,0.022774,0.000000
28.910002,11.608711,-186.775513,-0.004506,0.000885,0.022479,51.638126,2.630571,0.224792,-186.775513,0.023442,0.000000
29.310001,11.547272,-186.731033,-0.004475,0.000911,0.023147,51.364830,2.616649,0.231469,-186.731033,0.024110,0.000000
29.710001,11.835114,-186.731033,-0.004454,0.000935,0.023754,52.645214,2.681875,0.237540,-186.731033,0.024768,0.000000
30.110001,11.791176,-186.819992,-0.004424,0.000954,0.024231,52.449768,2.671919,0.242309,-186.819992,0.025436,0.000000
30.510002,12.317337,-186.864471,-0.004381,0.000988,0.025106,54.790253,2.791148,0.251060,-186.864471,0.026104,0.000000
30.910002,12.475220,-186.908951,-0.004346,0.001016,0.025801,55.492550,2.826925,0.258009,-186.908951,0.026771,0.000000
31.310001,12.775726,-186.908951,-0.004316,0.001045,0.026555,56.829269,2.895021,0.265548,-186.908951,0.027439,0.000000
31.710001,12.648376,-186.953430,-0.004303,0.001066,0.027085,56.262787,2.866163,0.270847,-186.953430,0.028107,0.000000
32.110001,13.266144,-186.997925,-0.004255,0.001101,0.027978,59.010754,3.006151,0.279779,-186.997925,0.028776,0.000000
32.510002,13.242310,-187.042404,-0.004230,0.001126,0.028593,58.904736,3.000750,0.285926,-187.042404,0.029443,0.000000
32.910000,13.027824,-187.086884,-0.004191,0.001149,0.029183,57.950657,2.952147,0.291831,-187.086884,0.030102,0.000000
33.310001,13.526054,-187.086884,-0.004152,0.001180,0.029963,60.166893,3.065048,0.299627,-187.086884,0.030770,0.000000
33.710003,13.178635,-187.131363,-0.004122,0.001195,0.030353,58.621494,2.986321,0.303533,-187.131363,0.031437,0.000000
34.110001,13.721176,-187.175842,-0.004109,0.001230,0.031237,61.034840,3.109263,0.312375,-187.175842,0.032105,0.000000
34.510002,13.816132,-187.175842,-0.004053,0.001254,0.031854,61.457222,3.130780,0.318537,-187.175842,0.032773,0.000000
34.910000,13.710754,-187.264801,-0.004018,0.001278,0.032452,60.988483,3.106901,0.324517,-187.264801,0.033440,0.000000
35.310001,13.901039,-187.264801,-0.003988,0.001307,0.033189,61.834911,3.150020,0.331890,-187.264801,0.034108,0.000000
35.710003,14.043282,-187.264801,-0.003945,0.001333,0.033866,62.467636,3.182253,0.338657,-187.264801,0.034776,0.000000
36.110001,14.142334,-187.264801,-0.003919,0.001356,0.034438,62.908245,3.204699,0.344380,-187.264801,0.035436,0.000000
36.510002,14.207497,-187.353760,-0.003893,0.001383,0.035140,63.198101,3.219465,0.351405,-187.353760,0.036103,0.000000
36.910000,14.213829,-187.353760,-0.003854,0.001408,0.035764,63.226269,3.220900,0.357642,-187.353760,0.036771,0.000000
37.310001,14.433525,-187.442734,-0.003829,0.001436,0.036476,64.203529,3.270684,0.364758,-187.442734,0.037439,0.000000
37.710003,14.509491,-187.442734,-0.003790,0.001461,0.037101,64.541443,3.287898,0.371011,-187.442734,0.038106,0.000000
38.110001,14.875908,-187.442734,-0.003768,0.001490,0.037846,66.171341,3.370929,0.378459,-187.442734,0.038774,0.000000
38.510002,14.691956,-187.487213,-0.003717,0.001513,0.038427,65.353081,3.329245,0.384273,-187.487213,0.039442,0.000000
38.910004,14.737381,-187.576172,-0.003699,0.001540,0.039113,65.555145,3.339538,0.391131,-187.576172,0.040109,0.000000
39.310001,15.163002,-187.531693,-0.003652,0.001571,0.039911,67.448402,3.435985,0.399110,-187.531693,0.040777,0.000000
39.710003,14.872185,-187.620651,-0.003639,0.001589,0.040353,66.154785,3.370085,0.403530,-187.620651,0.041437,0.000000
40.110001,15.380096,-187.620651,-0.003587,0.001622,0.041211,68.414085,3.485180,0.412115,-187.620651,0.042105,0.000000
40.510002,15.368179,-187.620651,-0.003548,0.001646,0.041809,68.361076,3.482479,0.418095,-187.620651,0.042772,0.000000
40.910004,15.294456,-187.754089,-0.003518,0.001670,0.042426,68.033142,3.465773,0.424256,-187.754089,0.043440,0.000000
41.310001,15.747627,-187.754089,-0.003484,0.001703,0.043249,70.048943,3.568463,0.432492,-187.754089,0.044108,0.000000
41.710003,15.380844,-187.754089,-0.003466,0.001718,0.043640,68.417412,3.485349,0.436398,-187.754089,0.044775,0.000000
42.110001,16.002708,-187.798569,-0.003423,0.001754,0.044541,71.183601,3.626266,0.445406,-187.798569,0.045443,0.000000
42.510002,15.905891,-187.843063,-0.003402,0.001777,0.045131,70.752937,3.604326,0.451311,-187.843063,0.046111,0.000000
42.910004,15.901421,-187.887543,-0.003385,0.001798,0.045678,70.733055,3.603313,0.456776,-187.887543,0.046771,0.000000
43.310001,16.391090,-187.887543,-0.003350,0.001830,0.046475,72.911209,3.714274,0.464755,-187.887543,0.047438,0.000000
43.710003,16.169159,-187.932022,-0.003303,0.001852,0.047030,71.924011,3.663984,0.470296,-187.932022,0.048106,0.000000
44.110001,16.721008,-188.020981,-0.003272,0.001885,0.047888,74.378761,3.789035,0.478880,-188.020981,0.048774,0.000000
44.510002,16.784317,-187.932022,-0.003242,0.001910,0.048513,74.660370,3.803381,0.485133,-187.932022,0.049441,0.000000
44.910004,17.067688,-188.020981,-0.003221,0.001937,0.049207,75.920868,3.867593,0.492067,-188.020981,0.050109,0.000000
45.310001,16.941826,-188.065460,-0.003191,0.001958,0.049727,75.361008,3.839072,0.497275,-188.065460,0.050777,0.000000
45.710003,16.838684,-188.109940,-0.003169,0.001981,0.050309,74.902206,3.815700,0.503088,-188.109940,0.051444,0.000000
46.110001,17.497406,-188.065460,-0.003104,0.002013,0.051123,77.832352,3.964969,0.511233,-188.065460,0.052103,0.000000
46.510002,17.623268,-188.198898,-0.003096,0.002041,0.051835,78.392212,3.993490,0.518349,-188.198898,0.052771,0.000000
46.910004,17.809830,-188.154419,-0.003053,0.002066,0.052484,79.222076,4.035765,0.524844,-188.154419,0.053440,0.000000
47.310001,17.809082,-188.198898,-0.003040,0.002089,0.053066,79.218750,4.035596,0.530657,-188.198898,0.054107,0.000000
47.710003,17.997505,-188.243378,-0.003009,0.002118,0.053803,80.056900,4.078293,0.538030,-188.243378,0.054775,0.000000
48.110001,18.617134,-188.243378,-0.002971,0.002148,0.054566,82.813148,4.218703,0.545661,-188.243378,0.055443,0.000000
48.510002,18.401901,-188.332352,-0.002945,0.002169,0.055096,81.855743,4.169930,0.550960,-188.332352,0.056110,0.000000
48.910004,18.514732,-188.376831,-0.002919,0.002193,0.055703,82.357643,4.195498,0.557031,-188.376831,0.056778,0.000000
49.310001,18.922104,-188.376831,-0.002876,0.002222,0.056448,84.169724,4.287810,0.564479,-188.376831,0.057437,0.000000
49.710003,19.357407,-188.465790,-0.002859,0.002248,0.057090,86.106049,4.386451,0.570898,-188.465790,0.058104,0.000000
50.110001,19.660149,-188.465790,-0.002833,0.002275,0.057783,87.452705,4.455053,0.577832,-188.465790,0.058772,0.000000
50.510002,19.657913,-188.465790,-0.002802,0.002302,0.058460,87.442764,4.454547,0.584600,-188.465790,0.059440,0.000000
50.910004,20.177376,-188.465790,-0.002768,0.002331,0.059197,89.753448,4.572259,0.591973,-188.465790,0.060109,0.000000
51.310001,20.076836,-188.599228,-0.002746,0.002350,0.059700,89.306229,4.549476,0.596999,-188.599228,0.060776,0.000000
51.710003,20.527405,-188.599228,-0.002708,0.002380,0.060446,91.310455,4.651577,0.604463,-188.599228,0.061444,0.000000
52.110001,20.743004,-188.599228,-0.002686,0.002409,0.061200,92.269493,4.700432,0.612002,-188.599228,0.062112,0.000000
52.510002,20.993988,-188.599228,-0.002665,0.002434,0.061816,93.385925,4.757306,0.618164,-188.599228,0.062779,0.000000
52.910004,21.193581,-188.643707,-0.002630,0.002459,0.062458,94.273758,4.802534,0.624583,-188.643707,0.063438,0.000000
53.310001,21.301567,-188.688202,-0.002591,0.002479,0.062979,94.754105,4.827004,0.629791,-188.688202,0.064106,0.000000
53.710003,21.821770,-188.732681,-0.002574,0.002511,0.063768,97.068077,4.944884,0.637679,-188.732681,0.064773,0.000000
54.110004,22.180740,-188.732681,-0.002535,0.002540,0.064513,98.664864,5.026227,0.645128,-188.732681,0.065441,0.000000
54.510002,22.602264,-188.821640,-0.002505,0.002567,0.065199,100.539894,5.121746,0.651986,-188.821640,0.066108,0.000000
54.910004,22.385170,-188.910599,-0.002492,0.002586,0.065692,99.574211,5.072552,0.656922,-188.910599,0.066776,0.000000
55.310001,22.575821,-188.821640,-0.002471,0.002608,0.066231,100.422264,5.115754,0.662311,-188.821640,0.067445,0.000000
55.710003,23.519417,-188.866119,-0.002427,0.002642,0.067115,104.619591,5.329576,0.671153,-188.866119,0.068113,0.000000
56.110004,23.831833,-188.955078,-0.002397,0.002672,0.067878,106.009285,5.400371,0.678783,-188.955078,0.068772,0.000000
56.510002,24.279427,-188.999557,-0.002384,0.002699,0.068546,108.000282,5.501797,0.685460,-188.999557,0.069439,0.000000
56.910004,24.048561,-188.999557,-0.002341,0.002717,0.069014,106.973343,5.449482,0.690138,-188.999557,0.070107,0.000000
57.310001,24.924004,-189.044037,-0.002345,0.002747,0.069786,110.867508,5.647860,0.697859,-189.044037,0.070775,0.000000
57.710003,25.391335,-189.044037,-0.002311,0.002774,0.070454,112.946297,5.753758,0.704535,-189.044037,0.071442,0.000000
58.110004,25.684021,-189.133011,-0.002281,0.002800,0.071121,114.248230,5.820082,0.711212,-189.133011,0.072110,0.000000
58.510002,26.254494,-189.088516,-0.002264,0.002828,0.071833,116.785820,5.949353,0.718328,-189.088516,0.072777,0.000000
58.910004,26.220978,-189.177490,-0.002233,0.002849,0.072354,116.636734,5.941758,0.723536,-189.177490,0.073445,0.000000
59.310001,25.866478,-189.221970,-0.002199,0.002864,0.072735,115.059837,5.861428,0.727351,-189.221970,0.074105,0.000000
59.710003,27.748451,-189.221970,-0.002186,0.002908,0.073854,123.431274,6.287889,0.738539,-189.221970,0.074773,0.000000
60.110004,27.763718,-189.266449,-0.002164,0.002929,0.074408,123.499184,6.291348,0.744080,-189.266449,0.075441,0.000000
60.510002,28.619431,-189.310928,-0.002139,0.002961,0.075206,127.305588,6.485256,0.752059,-189.310928,0.076108,0.000000
60.910004,28.945259,-189.355408,-0.002104,0.002987,0.075866,128.754944,6.559089,0.758659,-189.355408,0.076776,0.000000
61.310001,29.529877,-189.355408,-0.002100,0.003013,0.076525,131.355453,6.691566,0.765245,-189.355408,0.077443,0.000000
61.710003,29.949913,-189.399887,-0.002065,0.003038,0.077157,133.223862,6.786747,0.771574,-189.399887,0.078111,0.000000
62.110004,30.620934,-189.444366,-0.002035,0.003066,0.077869,136.208710,6.938803,0.778689,-189.444366,0.078779,0.000000
62.510002,31.322853,-189.399887,-0.002013,0.003094,0.078580,139.331009,7.097860,0.785805,-189.399887,0.079439,0.000000
62.910004,31.388763,-189.444366,-0.001983,0.003114,0.079092,139.624191,7.112795,0.790922,-189.444366,0.080107,0.000000
63.310001,32.438484,-189.577820,-0.001970,0.003145,0.079881,144.293579,7.350666,0.798810,-189.577820,0.080774,0.000000
63.710003,32.559502,-189.533325,-0.001932,0.003170,0.080530,144.831894,7.378088,0.805305,-189.533325,0.081442,0.000000
64.110001,33.204079,-189.577820,-0.001914,0.003194,0.081130,147.699112,7.524152,0.811300,-189.577820,0.082110,0.000000
64.510002,34.116020,-189.622299,-0.001901,0.003224,0.081884,151.755630,7.730801,0.818839,-189.622299,0.082777,0.000000
64.910004,34.370720,-189.666779,-0.001863,0.003242,0.082352,152.888596,7.788516,0.823517,-189.666779,0.083445,0.000000
65.310005,35.641632,-189.666779,-0.001863,0.003275,0.083184,158.541901,8.076509,0.831844,-189.666779,0.084112,0.000000
65.710007,36.241150,-189.711258,-0.001837,0.003302,0.083861,161.208679,8.212362,0.838612,-189.711258,0.084780,0.000000
66.110001,36.811623,-189.711258,-0.001798,0.003327,0.084494,163.746277,8.341633,0.844940,-189.711258,0.085440,0.000000
66.510002,37.679626,-189.844696,-0.001794,0.003352,0.085136,167.607346,8.538325,0.851359,-189.844696,0.086108,0.000000
66.910004,37.912354,-189.755737,-0.001763,0.003371,0.085622,168.642578,8.591063,0.856219,-189.755737,0.086776,0.000000
67.310005,39.676659,-189.844696,-0.001750,0.003407,0.086550,176.490585,8.990859,0.865499,-189.844696,0.087443,0.000000
67.710007,40.181969,-189.889175,-0.001725,0.003433,0.087192,178.738327,9.105365,0.871919,-189.889175,0.088111,0.000000
68.110001,40.769569,-189.889175,-0.001699,0.003454,0.087729,181.352097,9.238517,0.877293,-189.889175,0.088778,0.000000
68.510002,41.724335,-189.933655,-0.001690,0.003481,0.088406,185.599106,9.454869,0.884061,-189.933655,0.089446,0.000000
68.910004,41.787262,-189.978149,-0.001669,0.003495,0.088769,185.879028,9.469130,0.887694,-189.978149,0.090114,0.000000
69.310005,44.367432,-190.022629,-0.001634,0.003539,0.089879,197.356186,10.053803,0.898791,-190.022629,0.090772,0.000000
69.710007,44.765503,-190.111588,-0.001617,0.003563,0.090495,199.126907,10.144009,0.904953,-190.111588,0.091440,0.000000
70.110001,45.252190,-190.022629,-0.001630,0.003585,0.091051,201.291794,10.254293,0.910509,-190.022629,0.092109,0.000000
70.510002,46.536873,-190.067108,-0.001600,0.003610,0.091700,207.006348,10.545406,0.917004,-190.067108,0.092777,0.000000
70.910004,46.904037,-190.111588,-0.001587,0.003632,0.092265,208.639572,10.628607,0.922651,-190.111588,0.093445,0.000000
71.310005,48.571892,-190.200546,-0.001561,0.003661,0.092993,216.058563,11.006548,0.929934,-190.200546,0.094112,0.000000
71.710007,50.028984,-190.200546,-0.001535,0.003692,0.093765,222.540039,11.336730,0.937655,-190.200546,0.094780,0.000000
72.110001,51.153175,-190.200546,-0.001513,0.003719,0.094459,227.540695,11.591475,0.944589,-190.200546,0.095447,0.000000
72.510002,52.111664,-190.289505,-0.001500,0.003745,0.095127,231.804260,11.808672,0.951265,-190.289505,0.096106,0.000000
72.910004,53.750847,-190.333984,-0.001487,0.003775,0.095873,239.095703,12.180116,0.958729,-190.333984,0.096774,0.000000
73.310005,54.474365,-190.289505,-0.001466,0.003796,0.096427,242.314072,12.344068,0.964270,-190.289505,0.097441,0.000000
73.710007,55.520737,-190.333984,-0.001462,0.003824,0.097120,246.968567,12.581179,0.971204,-190.333984,0.098109,0.000000
74.110001,56.834091,-190.422958,-0.001440,0.003849,0.097762,252.810669,12.878789,0.977623,-190.422958,0.098778,0.000000
74.510002,57.279823,-190.467438,-0.001427,0.003865,0.098171,254.793381,12.979793,0.981711,-190.467438,0.099446,0.000000
74.910004,60.017876,-190.422958,-0.001410,0.003906,0.099202,266.972839,13.600245,0.992021,-190.422958,0.100113,0.000000
75.310005,61.238884,-190.467438,-0.001401,0.003931,0.099844,272.404175,13.876929,0.998440,-190.467438,0.100781,0.000000
75.710007,62.020493,-190.467438,-0.001380,0.003954,0.100425,275.880920,14.054045,1.004254,-190.467438,0.101440,0.000000
76.110001,64.003006,-190.511917,-0.001371,0.003983,0.101179,284.699585,14.503288,1.011793,-190.511917,0.102107,0.000000
76.510002,64.745148,-190.600876,-0.001354,0.004004,0.101700,288.000793,14.671460,1.017001,-190.600876,0.102775,0.000000
76.910004,65.877533,-190.600876,-0.001337,0.004020,0.102107,293.037903,14.928062,1.021074,-190.600876,0.017921,0.000000
77.310005,65.743103,-190.645355,-0.001324,0.004033,0.102447,292.439941,14.897600,1.024465,-190.645355,294.500458,0.000000
77.710007,65.442230,-190.734314,-0.001315,0.004042,0.102672,291.101593,14.829421,1.026721,-190.734314,294.500458,0.000000
78.110001,65.398285,-190.778793,-0.001298,0.004051,0.102905,290.906097,14.819464,1.029052,-190.778793,294.500458,0.000000
78.510002,65.278381,-190.734314,-0.001298,0.004058,0.103079,290.372742,14.792293,1.030793,-190.734314,294.500458,0.000000
78.910004,65.159973,-190.778793,-0.001293,0.004066,0.103270,289.846039,14.765461,1.032701,-190.778793,294.500458,0.000000
79.310005,65.101135,-190.912247,-0.001289,0.004071,0.103408,289.584320,14.752128,1.034079,-190.912247,294.500458,0.000000
79.710007,64.892227,-190.867767,-0.001285,0.004077,0.103547,288.655029,14.704788,1.035472,-190.867767,294.500458,0.000000
80.110001,65.781082,-190.912247,-0.001276,0.004079,0.103599,292.608856,14.906206,1.035986,-190.912247,294.500458,0.000000
80.510002,65.589310,-190.956726,-0.001268,0.004093,0.103963,291.755829,14.862750,1.039635,-190.956726,294.500458,0.000000
80.910004,65.457870,-190.912247,-0.001272,0.004096,0.104033,291.171143,14.832966,1.040331,-190.912247,294.500458,0.000000
81.310005,65.299606,-191.001205,-0.001259,0.004101,0.104171,290.467163,14.797102,1.041709,-191.001205,294.500458,0.000000
81.710007,65.221405,-191.045685,-0.001259,0.004103,0.104224,290.119293,14.779382,1.042239,-191.045685,294.500458,0.000000
82.110001,65.526749,-191.045685,-0.001259,0.004110,0.104396,291.477539,14.848574,1.043965,-191.045685,294.500458,0.000000
82.510002,65.291046,-191.090164,-0.001250,0.004111,0.104415,290.429077,14.795162,1.044147,-191.090164,294.500458,0.000000
82.910004,65.037827,-191.134644,-0.001250,0.004111,0.104424,289.302704,14.737782,1.044237,-191.134644,294.500458,0.000000
83.310005,65.256790,-191.134644,-0.001255,0.004117,0.104580,290.276703,14.787400,1.045797,-191.134644,294.500458,0.000000
83.710007,65.050491,-191.134644,-0.001255,0.004118,0.104587,289.359039,14.740652,1.045872,-191.134644,294.500458,0.000000
84.110001,64.855743,-191.223602,-0.001246,0.004119,0.104631,288.492767,14.696522,1.046311,-191.223602,294.500458,0.000000
84.510002,65.832840,-191.268097,-0.001237,0.004131,0.104935,292.839111,14.917934,1.049355,-191.268097,294.500458,0.000000
84.910004,65.651871,-191.268097,-0.001229,0.004131,0.104935,292.034119,14.876926,1.049355,-191.268097,294.500458,0.000000
85.310005,65.437759,-191.312576,-0.001246,0.004131,0.104935,291.081696,14.828408,1.049355,-191.312576,294.500458,0.000000
85.710007,65.183060,-191.357056,-0.001246,0.004132,0.104943,289.948730,14.770692,1.049430,-191.357056,294.500458,0.000000
86.110001,64.949203,-191.357056,-0.001233,0.004132,0.104952,288.908478,14.717700,1.049521,-191.357056,294.500458,0.000000
86.510002,65.819443,-191.401535,-0.001220,0.004144,0.105264,292.779510,14.914899,1.052640,-191.401535,294.500458,0.000000
86.910004,65.698410,-191.490494,-0.001220,0.004144,0.105264,292.241119,14.887473,1.052640,-191.490494,294.500458,0.000000
87.310005,65.555054,-191.490494,-0.001233,0.004144,0.105264,291.603455,14.854987,1.052640,-191.490494,294.500458,0.000000
87.710007,65.339828,-191.446014,-0.001229,0.004144,0.105264,290.646088,14.806217,1.052640,-191.446014,294.500458,0.000000
88.110001,65.177841,-191.490494,-0.001224,0.004144,0.105264,289.925507,14.769509,1.052640,-191.490494,294.500458,0.000000
88.510002,65.652618,-191.579453,-0.001229,0.004152,0.105473,292.037445,14.877096,1.054729,-191.579453,294.500458,0.000000
88.910004,65.561386,-191.623932,-0.001220,0.004152,0.105473,291.631622,14.856422,1.054729,-191.623932,294.500458,0.000000
89.310005,65.425842,-191.623932,-0.001220,0.004152,0.105473,291.028687,14.825707,1.054729,-191.623932,294.500458,0.000000
89.710007,65.289932,-191.712906,-0.001212,0.004152,0.105473,290.424133,14.794909,1.054729,-191.712906,294.500458,0.000000
90.110001,65.128693,-191.712906,-0.001216,0.004152,0.105473,289.706879,14.758373,1.054729,-191.712906,294.500458,0.000000
90.510002,64.997620,-191.757385,-0.001237,0.004152,0.105473,289.123840,14.728671,1.054729,-191.757385,294.500458,0.000000
90.910004,65.831726,-191.757385,-0.001203,0.004164,0.105767,292.834137,14.917682,1.057666,-191.757385,294.500458,0.000000
91.310005,65.831726,-191.846344,-0.001207,0.004164,0.105767,292.834137,14.917682,1.057666,-191.846344,294.500458,0.000000
91.710007,65.691345,-191.801865,-0.001207,0.004164,0.105767,292.209686,14.885872,1.057666,-191.801865,294.500458,0.000000
92.110001,65.594147,-191.890823,-0.001220,0.004164,0.105767,291.777344,14.863846,1.057666,-191.890823,294.500458,0.000000
92.510002,65.469788,-191.935303,-0.001207,0.004164,0.105767,291.224152,14.835666,1.057666,-191.935303,294.500458,0.000000
92.910004,65.348007,-191.890823,-0.001203,0.004164,0.105767,290.682465,14.808070,1.057666,-191.890823,294.500458,0.000000
93.310005,65.293655,-191.979782,-0.001220,0.004166,0.105829,290.440674,14.795754,1.058287,-191.979782,294.500458,0.000000
93.710007,65.261627,-191.935303,-0.001203,0.004166,0.105829,290.298218,14.788496,1.058287,-191.935303,294.500458,0.000000
94.110008,65.152893,-192.024261,-0.001224,0.004166,0.105829,289.814545,14.763856,1.058287,-192.024261,294.500458,0.000000
94.510002,65.265350,-192.068741,-0.001203,0.004170,0.105924,290.314789,14.789339,1.059241,-192.068741,294.500458,0.000000
94.910004,65.215820,-192.068741,-0.001199,0.004170,0.105924,290.094452,14.778116,1.059241,-192.068741,294.500458,0.000000
95.310005,65.138748,-192.113220,-0.001212,0.004170,0.105924,289.751617,14.760652,1.059241,-192.113220,294.500458,0.000000
95.710007,65.098160,-192.113220,-0.001212,0.004171,0.105941,289.571075,14.751454,1.059407,-192.113220,294.500458,0.000000
96.110008,65.349136,-192.157715,-0.001203,0.004175,0.106054,290.687469,14.808326,1.060543,-192.157715,294.500458,0.000000
96.510002,65.305939,-192.246674,-0.001212,0.004175,0.106054,290.495331,14.798536,1.060543,-192.246674,294.500458,0.000000
96.910004,65.256409,-192.202194,-0.001190,0.004175,0.106054,290.274994,14.787313,1.060543,-192.202194,294.500458,0.000000
97.310005,65.154388,-192.246674,-0.001203,0.004176,0.106071,289.821198,14.764195,1.060709,-192.246674,294.500458,0.000000
97.710007,65.289185,-192.291153,-0.001207,0.004179,0.106141,290.420807,14.794741,1.061406,-192.291153,294.500458,0.000000
98.110008,65.254929,-192.335632,-0.001194,0.004179,0.106141,290.268433,14.786978,1.061406,-192.335632,294.500458,0.000000
98.510002,65.222153,-192.380112,-0.001199,0.004179,0.106141,290.122620,14.779552,1.061406,-192.380112,294.500458,0.000000
98.910004,65.260132,-192.335632,-0.001207,0.004182,0.106218,290.291565,14.788157,1.062178,-192.335632,294.500458,0.000000
99.310005,65.289185,-192.424591,-0.001194,0.004182,0.106227,290.420807,14.794741,1.062269,-192.424591,294.500458,0.000000
99.710007,65.256409,-192.380112,-0.001212,0.004182,0.106227,290.274994,14.787313,1.062269,-192.380112,294.500458,0.000000
100.110008,65.239288,-192.469070,-0.001194,0.004184,0.106262,290.198853,14.783434,1.062617,-192.469070,294.500458,0.000000
100.510002,65.236298,-192.513550,-0.001181,0.004185,0.106287,290.185547,14.782756,1.062874,-192.513550,294.500458,0.000000
100.910004,65.258270,-192.513550,-0.001199,0.004185,0.106297,290.283295,14.787735,1.062965,-192.513550,294.500458,0.000000
101.310005,65.238541,-192.558044,-0.001190,0.004186,0.106322,290.195526,14.783265,1.063222,-192.558044,294.500458,0.000000
101.710007,65.258270,-192.558044,-0.001181,0.004188,0.106366,290.283295,14.787735,1.063661,-192.558044,294.500458,0.000000
102.110008,65.289551,-192.647003,-0.001199,0.004188,0.106374,290.422424,14.794824,1.063737,-192.647003,294.500458,0.000000
102.510002,65.262375,-192.691483,-0.001190,0.004188,0.106374,290.301544,14.788666,1.063737,-192.691483,294.500458,0.000000
102.910004,65.262375,-192.691483,-0.001203,0.004189,0.106401,290.301544,14.788666,1.064010,-192.691483,294.500458,0.000000
103.310005,65.237427,-192.691483,-0.001203,0.004189,0.106401,290.190582,14.783012,1.064010,-192.691483,294.500458,0.000000
103.710007,65.223267,-192.735962,-0.001194,0.004191,0.106443,290.127594,14.779803,1.064434,-192.735962,294.500458,0.000000
104.110008,65.241882,-192.780441,-0.001194,0.004191,0.106452,290.210388,14.784021,1.064524,-192.780441,294.500458,0.000000
104.510002,65.215073,-192.824921,-0.001203,0.004191,0.106462,290.091125,14.777947,1.064615,-192.824921,294.500458,0.000000
104.910004,65.275772,-192.913879,-0.001194,0.004193,0.106504,290.361145,14.791701,1.065039,-192.913879,294.500458,0.000000
105.310005,65.274292,-192.869400,-0.001194,0.004193,0.106504,290.354553,14.791366,1.065039,-192.869400,294.500458,0.000000
105.710007,65.225876,-192.913879,-0.001186,0.004193,0.106513,290.139191,14.780395,1.065130,-192.913879,294.500458,0.000000
106.110008,65.189011,-192.958359,-0.001199,0.004193,0.106513,289.975189,14.772040,1.065130,-192.958359,294.500458,0.000000
106.510002,65.395676,-193.002853,-0.001194,0.004198,0.106634,290.894501,14.818871,1.066341,-193.002853,294.500458,0.000000
106.910004,65.486542,-193.047333,-0.001181,0.004198,0.106634,291.298676,14.839462,1.066341,-193.047333,294.500458,0.000000
107.310005,65.439621,-193.091812,-0.001194,0.004198,0.106634,291.089966,14.828831,1.066341,-193.091812,294.500458,0.000000
107.710007,65.401642,-193.047333,-0.001177,0.004198,0.106634,290.921021,14.820224,1.066341,-193.047333,294.500458,0.000000
108.110008,65.349884,-193.136292,-0.001186,0.004198,0.106634,290.690796,14.808496,1.066341,-193.136292,294.500458,0.000000
108.510002,65.313385,-193.136292,-0.001190,0.004198,0.106634,290.528442,14.800224,1.066341,-193.136292,294.500458,0.000000
108.910004,65.280243,-193.225250,-0.001203,0.004198,0.106634,290.381012,14.792715,1.066341,-193.225250,294.500458,0.000000
109.310005,65.235565,-193.269730,-0.001186,0.004198,0.106634,290.182281,14.782591,1.066341,-193.269730,294.500458,0.000000
109.710007,65.194595,-193.269730,-0.001190,0.004199,0.106643,290.000031,14.773306,1.066432,-193.269730,294.500458,0.000000
110.110008,65.156616,-193.269730,-0.001186,0.004199,0.106643,289.831116,14.764701,1.066432,-193.269730,294.500458,0.000000
110.510002,65.119751,-193.314209,-0.001199,0.004199,0.106643,289.667114,14.756347,1.066432,-193.314209,294.500458,0.000000
110.910004,65.505157,-193.269730,-0.001186,0.004205,0.106799,291.381500,14.843681,1.067991,-193.269730,294.500458,0.000000
111.310005,65.513718,-193.403168,-0.001181,0.004204,0.106790,291.419556,14.845620,1.067901,-193.403168,294.500458,0.000000
111.710007,65.512238,-193.358688,-0.001186,0.004204,0.106790,291.412994,14.845285,1.067901,-193.358688,294.500458,0.000000
112.110008,65.479462,-193.403168,-0.001190,0.004204,0.106790,291.267181,14.837858,1.067901,-193.403168,294.500458,0.000000
112.510002,65.432922,-193.403168,-0.001181,0.004204,0.106790,291.060181,14.827312,1.067901,-193.403168,294.500458,0.000000
112.910004,65.405365,-193.447662,-0.001177,0.004205,0.106799,290.937592,14.821068,1.067991,-193.447662,294.500458,0.000000
113.310005,65.351364,-193.536621,-0.001173,0.004205,0.106799,290.697388,14.808831,1.067991,-193.536621,294.500458,0.000000
113.710007,65.318604,-193.536621,-0.001190,0.004205,0.106799,290.551666,14.801407,1.067991,-193.536621,294.500458,0.000000
114.110008,65.296997,-193.581100,-0.001168,0.004205,0.106799,290.455536,14.796512,1.067991,-193.581100,294.500458,0.000000
114.510002,65.259018,-193.581100,-0.001186,0.004205,0.106799,290.286621,14.787905,1.067991,-193.581100,294.500458,0.000000
114.910004,65.219177,-193.581100,-0.001177,0.004205,0.106799,290.109375,14.778876,1.067991,-193.581100,294.500458,0.000000
115.310005,65.186035,-193.670059,-0.001181,0.004205,0.106808,289.961975,14.771367,1.068082,-193.670059,294.500458,0.000000
115.710007,65.125336,-193.625580,-0.001173,0.004205,0.106808,289.691956,14.757612,1.068082,-193.625580,294.500458,0.000000
116.110008,65.082886,-193.759018,-0.001177,0.004205,0.106817,289.503143,14.747993,1.068173,-193.759018,294.500458,0.000000
116.510002,65.078796,-193.759018,-0.001190,0.004206,0.106843,289.484955,14.747066,1.068430,-193.759018,294.500458,0.000000
116.910004,65.600113,-193.759018,-0.001181,0.004213,0.107008,291.803864,14.865198,1.070081,-193.759018,294.500458,0.000000
117.310005,65.613144,-193.803497,-0.001177,0.004213,0.107008,291.861847,14.868151,1.070081,-193.803497,294.500458,0.000000
117.710007,65.617233,-193.803497,-0.001168,0.004213,0.107008,291.880035,14.869078,1.070081,-193.803497,294.500458,0.000000
118.110008,65.592285,-193.892471,-0.001173,0.004213,0.107008,291.769043,14.863424,1.070081,-193.892471,294.500458,0.000000
118.510002,65.577393,-193.892471,-0.001177,0.004213,0.107008,291.702820,14.860049,1.070081,-193.892471,294.500458,0.000000
118.910004,65.567337,-193.936951,-0.001186,0.004213,0.107008,291.658081,14.857771,1.070081,-193.936951,294.500458,0.000000
119.310005,65.542023,-193.936951,-0.001168,0.004213,0.107008,291.545471,14.852035,1.070081,-193.936951,294.500458,0.000000
119.710007,65.504791,-193.981430,-0.001173,0.004213,0.107008,291.379852,14.843598,1.070081,-193.981430,294.500458,0.000000
120.110008,65.483185,-194.025909,-0.001177,0.004213,0.107008,291.283752,14.838701,1.070081,-194.025909,294.500458,0.000000
120.510002,65.441483,-194.025909,-0.001173,0.004213,0.107008,291.098267,14.829251,1.070081,-194.025909,294.500458,0.000000
120.910004,65.410950,-194.114868,-0.001177,0.004213,0.107008,290.962433,14.822333,1.070081,-194.114868,294.500458,0.000000
121.310005,65.369980,-194.114868,-0.001173,0.004213,0.107008,290.780182,14.813048,1.070081,-194.114868,294.500458,0.000000
121.710007,65.333115,-194.114868,-0.001177,0.004213,0.107008,290.616211,14.804696,1.070081,-194.114868,294.500458,0.000000
122.110008,65.305557,-194.159348,-0.001164,0.004213,0.107008,290.493622,14.798450,1.070081,-194.159348,294.500458,0.000000
122.510002,65.288055,-194.248306,-0.001181,0.004213,0.107016,290.415771,14.794485,1.070156,-194.248306,294.500458,0.000000
122.910004,65.256409,-194.248306,-0.001177,0.004213,0.107016,290.274994,14.787313,1.070156,-194.248306,294.500458,0.000000
123.310005,65.233704,-194.248306,-0.001160,0.004213,0.107016,290.174011,14.782168,1.070156,-194.248306,294.500458,0.000000
123.710007,65.202423,-194.248306,-0.001177,0.004213,0.107016,290.034851,14.775080,1.070156,-194.248306,294.500458,0.000000
124.110008,65.158112,-194.292801,-0.001173,0.004214,0.107025,289.837769,14.765039,1.070247,-194.292801,294.500458,0.000000
124.510002,65.158112,-194.381760,-0.001177,0.004214,0.107043,289.837769,14.765039,1.070429,-194.381760,294.500458,0.000000
124.910004,65.128311,-194.426239,-0.001173,0.004214,0.107043,289.705200,14.758286,1.070429,-194.426239,294.500458,0.000000
125.310005,65.098892,-194.426239,-0.001181,0.004214,0.107043,289.574341,14.751619,1.070429,-194.426239,294.500458,0.000000
125.710007,65.068359,-194.515198,-0.001177,0.004215,0.107050,289.438507,14.744701,1.070505,-194.515198,294.500458,0.000000
126.110008,65.775131,-194.470718,-0.001173,0.004223,0.107276,292.582397,14.904858,1.072760,-194.470718,294.500458,0.000000
126.510010,65.792999,-194.470718,-0.001168,0.004223,0.107276,292.661865,14.908907,1.072760,-194.470718,294.500458,0.000000
126.910004,65.781464,-194.559677,-0.001173,0.004223,0.107276,292.610565,14.906293,1.072760,-194.559677,294.500458,0.000000
127.310005,65.801941,-194.559677,-0.001164,0.004223,0.107276,292.701660,14.910933,1.072760,-194.559677,294.500458,0.000000
127.710007,65.801941,-194.515198,-0.001168,0.004223,0.107276,292.701660,14.910933,1.072760,-194.515198,294.500458,0.000000
128.110001,65.795975,-194.604156,-0.001173,0.004223,0.107276,292.675110,14.909581,1.072760,-194.604156,294.500458,0.000000
128.510010,65.765442,-194.648636,-0.001173,0.004223,0.107276,292.539307,14.902661,1.072760,-194.648636,294.500458,0.000000
128.910004,65.779221,-194.648636,-0.001160,0.004223,0.107276,292.600586,14.905785,1.072760,-194.648636,294.500458,0.000000
129.310013,65.751663,-194.737610,-0.001160,0.004223,0.107276,292.477997,14.899540,1.072760,-194.737610,294.500458,0.000000
129.710007,65.671600,-194.693115,-0.001164,0.004223,0.107276,292.121857,14.881397,1.072760,-194.693115,294.500458,0.000000
130.110001,65.663788,-194.782089,-0.001168,0.004223,0.107276,292.087128,14.879627,1.072760,-194.782089,294.500458,0.000000
130.510010,65.630280,-194.782089,-0.001173,0.004223,0.107276,291.938049,14.872034,1.072760,-194.782089,294.500458,0.000000
130.910004,65.605331,-194.782089,-0.001168,0.004223,0.107276,291.827087,14.866381,1.072760,-194.782089,294.500458,0.000000
131.310013,65.586334,-194.871048,-0.001160,0.004223,0.107276,291.742584,14.862076,1.072760,-194.871048,294.500458,0.000000
131.710007,65.566971,-194.915527,-0.001160,0.004223,0.107276,291.656464,14.857688,1.072760,-194.915527,294.500458,0.000000
132.110001,65.538300,-195.004486,-0.001168,0.004223,0.107276,291.528931,14.851191,1.072760,-195.004486,294.500458,0.000000
132.510010,65.503662,-194.915527,-0.001168,0.004223,0.107276,291.374847,14.843342,1.072760,-194.915527,294.500458,0.000000
132.910004,65.469788,-194.960007,-0.001151,0.004223,0.107276,291.224152,14.835666,1.072760,-194.960007,294.500458,0.000000
133.310013,65.439987,-195.004486,-0.001160,0.004223,0.107276,291.091614,14.828914,1.072760,-195.004486,294.500458,0.000000
133.710007,65.396790,-195.004486,-0.001160,0.004223,0.107276,290.899445,14.819124,1.072760,-195.004486,294.500458,0.000000
134.110001,65.380417,-195.048965,-0.001151,0.004223,0.107276,290.826630,14.815414,1.072760,-195.048965,294.500458,0.000000
134.510010,65.334610,-195.093445,-0.001173,0.004223,0.107276,290.622864,14.805035,1.072760,-195.093445,294.500458,0.000000
134.910004,65.323059,-195.093445,-0.001151,0.004223,0.107276,290.571472,14.802417,1.072760,-195.093445,294.500458,0.000000
135.310013,65.278015,-195.137939,-0.001164,0.004223,0.107276,290.371124,14.792210,1.072760,-195.137939,294.500458,0.000000
135.710007,65.273911,-195.137939,-0.001168,0.004223,0.107276,290.352844,14.791280,1.072760,-195.137939,294.500458,0.000000
136.110001,65.243378,-195.182419,-0.001160,0.004223,0.107276,290.217041,14.784361,1.072760,-195.182419,294.500458,0.000000
136.510010,65.226624,-195.271378,-0.001160,0.004223,0.107276,290.142517,14.780564,1.072760,-195.271378,294.500458,0.000000
136.910004,65.187149,-195.271378,-0.001168,0.004223,0.107276,289.966919,14.771620,1.072760,-195.271378,294.500458,0.000000
137.310013,65.150650,-195.315857,-0.001164,0.004223,0.107276,289.804565,14.763348,1.072760,-195.315857,1681.640747,0.000000
137.710007,65.096664,-195.271378,-0.001168,0.004219,0.107172,289.564423,14.751115,1.071716,-195.271378,0.107008,0.000000
138.110001,65.018463,-195.315857,-0.001155,0.004202,0.106722,289.216583,14.733395,1.067219,-195.315857,0.106340,0.000000
138.510010,64.956284,-195.404816,-0.001164,0.004179,0.106141,288.939972,14.719304,1.061406,-195.404816,0.105671,0.000000
138.910004,64.868027,-195.404816,-0.001143,0.004153,0.105480,288.547394,14.699306,1.054805,-195.404816,0.105004,0.000000
139.310013,64.863937,-195.449295,-0.001134,0.004134,0.105004,288.529205,14.698379,1.050036,-195.449295,0.104336,0.000000
139.710007,64.794662,-195.449295,-0.001121,0.004099,0.104110,288.221039,14.682680,1.041103,-195.449295,0.103677,0.000000
140.110001,64.754456,-195.449295,-0.001143,0.004076,0.103531,288.042206,14.673570,1.035305,-195.449295,0.103010,0.000000
140.510010,64.714981,-195.538254,-0.001138,0.004051,0.102905,287.866608,14.664624,1.029052,-195.538254,0.102342,0.000000
140.910004,64.683701,-195.582748,-0.001134,0.004026,0.102256,287.727478,14.657537,1.022557,-195.582748,0.101674,0.000000
141.310013,64.549652,-195.582748,-0.001143,0.003999,0.101579,287.131195,14.627160,1.015790,-195.582748,0.101007,0.000000
141.710007,64.350052,-195.627228,-0.001134,0.003971,0.100851,286.243317,14.581930,1.008508,-195.627228,0.100339,0.000000
142.110001,63.934860,-195.582748,-0.001121,0.003950,0.100330,284.396454,14.487846,1.003300,-195.582748,0.099671,0.000000
142.510010,63.260498,-195.716187,-0.001130,0.003929,0.099800,281.396759,14.335033,0.998001,-195.716187,0.099002,0.000000
142.910004,61.981026,-195.716187,-0.001099,0.003902,0.099099,275.705383,14.045101,0.990991,-195.716187,0.098344,0.000000
143.310013,60.243530,-195.760666,-0.001082,0.003876,0.098448,267.976593,13.651379,0.984481,-195.760666,0.097676,0.000000
143.710007,58.141121,-195.760666,-0.001091,0.003849,0.097762,258.624634,13.174966,0.977623,-195.760666,0.097008,0.000000
144.110001,56.612160,-195.805145,-0.001087,0.003832,0.097329,251.823471,12.828499,0.973293,-195.805145,0.096341,0.000000
144.510010,54.019325,-195.894104,-0.001108,0.003800,0.096522,240.289963,12.240953,0.965224,-195.894104,0.095673,0.000000
144.910004,51.593697,-195.894104,-0.001087,0.003776,0.095915,229.500229,11.691298,0.959153,-195.894104,0.095005,0.000000
145.310013,49.119278,-195.938583,-0.001099,0.003757,0.095429,218.493454,11.130588,0.954293,-195.938583,0.094338,0.000000
145.710007,45.464813,-195.983063,-0.001099,0.003722,0.094529,202.237595,10.302474,0.945285,-195.983063,0.093670,0.000000
146.110001,42.860443,-195.938583,-0.001095,0.003698,0.093938,190.652771,9.712316,0.939381,-195.938583,0.093010,0.000000
146.510010,39.569412,-195.983063,-0.001099,0.003666,0.093124,176.013535,8.966558,0.931236,-195.983063,0.092342,0.000000
146.910004,37.381729,-196.027557,-0.001095,0.003648,0.092663,166.282242,8.470820,0.926633,-196.027557,0.091675,0.000000
147.310013,35.178772,-196.027557,-0.001108,0.003627,0.092117,156.482986,7.971624,0.921168,-196.027557,0.091007,0.000000
147.710007,31.265511,-196.072037,-0.001087,0.003590,0.091198,139.075943,7.084866,0.911978,-196.072037,0.090339,0.000000
148.110001,29.527275,-196.072037,-0.001082,0.003575,0.090800,131.343872,6.690976,0.907996,-196.072037,0.089672,0.000000
148.510010,26.232147,-196.160995,-0.001095,0.003545,0.090037,116.686417,5.944289,0.900366,-196.160995,0.089004,0.000000
148.910004,23.682518,-196.205475,-0.001095,0.003519,0.089395,105.345100,5.366535,0.893947,-196.205475,0.088336,0.000000
149.310013,21.561485,-196.249954,-0.001099,0.003499,0.088865,95.910278,4.885902,0.888648,-196.249954,0.087676,0.000000
149.710007,18.199699,-196.294434,-0.001095,0.003466,0.088032,80.956306,4.124111,0.880321,-196.294434,0.087009,0.000000
150.110001,15.661987,-196.249954,-0.001104,0.003444,0.087469,69.667999,3.549057,0.874689,-196.249954,0.086341,0.000000
150.510010,12.252541,-196.294434,-0.001082,0.003412,0.086654,54.502022,2.776465,0.866544,-196.294434,0.085673,0.000000
150.910004,9.568481,-196.338913,-0.001087,0.003385,0.085985,42.562733,2.168249,0.859852,-196.338913,0.085006,0.000000
151.310013,6.465874,-196.383392,-0.001095,0.003355,0.085206,28.761642,1.465188,0.852056,-196.383392,0.084338,0.000000
151.710007,4.757805,-196.427887,-0.001091,0.003340,0.084824,21.163773,1.078134,0.848240,-196.427887,0.083670,0.000000
152.110001,1.512573,-196.427887,-0.001099,0.003304,0.083913,6.728262,0.342754,0.839126,-196.427887,0.083003,0.000000
152.510010,-0.784218,-196.516846,-0.001087,0.003280,0.083324,-3.488375,-0.177706,0.833237,-196.516846,0.082335,0.000000
152.910004,-0.867256,-196.516846,-0.001112,0.003257,0.082717,-3.857748,-0.196523,0.827166,-196.516846,0.081677,0.000000
153.310013,-0.119904,-196.605804,-0.001099,0.003228,0.081979,-0.533358,-0.027171,0.819793,-196.605804,0.081007,0.000000
153.710007,0.001862,-196.605804,-0.001087,0.003203,0.081356,0.008281,0.000422,0.813556,-196.605804,0.080340,0.000000
154.110001,-0.028671,-196.605804,-0.001108,0.003175,0.080653,-0.127536,-0.006497,0.806531,-196.605804,0.079672,0.000000
154.510010,-0.043571,-196.650284,-0.001121,0.003150,0.080019,-0.193816,-0.009873,0.800187,-196.650284,0.079004,0.000000
154.910004,-0.067024,-196.694763,-0.001117,0.003125,0.079386,-0.298139,-0.015188,0.793859,-196.694763,0.078337,0.000000
155.310013,-0.067398,-196.739243,-0.001173,0.003094,0.078588,-0.299802,-0.015273,0.785880,-196.739243,0.077669,0.000000
155.710007,-0.042450,-196.739243,-0.001177,0.003090,0.078493,-0.188827,-0.009619,0.784927,-196.739243,0.077001,0.000000
156.110001,-0.079689,-196.739243,-0.001229,0.003040,0.077227,-0.354474,-0.018058,0.772270,-196.739243,0.076343,0.000000
156.510010,-0.062561,-196.828201,-0.001259,0.003017,0.076629,-0.278285,-0.014177,0.766290,-196.828201,0.075675,0.000000
156.910004,-0.068146,-196.828201,-0.001285,0.002998,0.076160,-0.303127,-0.015442,0.761597,-196.828201,0.075008,0.000000
157.310013,-0.097939,-196.917175,-0.001345,0.002959,0.075154,-0.435652,-0.022193,0.751544,-196.917175,0.074338,0.000000
157.710007,-0.095703,-197.006134,-0.001362,0.002942,0.074738,-0.425709,-0.021687,0.747380,-197.006134,0.073671,0.000000
158.110001,-0.079315,-196.917175,-0.001418,0.002922,0.074210,-0.352812,-0.017973,0.742097,-196.917175,0.073003,0.000000
158.510010,-0.128471,-196.961655,-0.001449,0.002889,0.073385,-0.571469,-0.029112,0.733846,-196.961655,0.072335,0.000000
158.910004,-0.106499,-196.961655,-0.001462,0.002868,0.072840,-0.473730,-0.024133,0.728395,-196.961655,0.071668,0.000000
159.310013,-0.118416,-197.050613,-0.001518,0.002829,0.071849,-0.526740,-0.026833,0.718494,-197.050613,0.071009,0.000000
159.710007,-0.124374,-197.050613,-0.001526,0.002810,0.071382,-0.553245,-0.028184,0.713816,-197.050613,0.070342,0.000000
160.110001,-0.112083,-197.050613,-0.001565,0.002786,0.070765,-0.498572,-0.025398,0.707654,-197.050613,0.069674,0.000000
160.510010,-0.149323,-197.095093,-0.001600,0.002756,0.069995,-0.664220,-0.033837,0.699948,-197.095093,0.069006,0.000000
160.910004,-0.145599,-197.184052,-0.001625,0.002735,0.069457,-0.647658,-0.032993,0.694574,-197.184052,0.068339,0.000000
161.310013,-0.112831,-197.184052,-0.001681,0.002698,0.068529,-0.501898,-0.025568,0.685293,-197.184052,0.067669,0.000000
161.710007,-0.119164,-197.273026,-0.001703,0.002678,0.068025,-0.530066,-0.027003,0.680252,-197.273026,0.067002,0.000000
162.110001,-0.150810,-197.228531,-0.001742,0.002650,0.067323,-0.670837,-0.034174,0.673227,-197.228531,0.066334,0.000000
162.510010,-0.151558,-197.273026,-0.001763,0.002625,0.066681,-0.674163,-0.034344,0.666808,-197.273026,0.065675,0.000000
162.910004,-0.130707,-197.273026,-0.001789,0.002591,0.065815,-0.581413,-0.029619,0.658148,-197.273026,0.065008,0.000000
163.310013,-0.101288,-197.317505,-0.001824,0.002568,0.065233,-0.450551,-0.022952,0.652334,-197.317505,0.064340,0.000000
163.710007,-0.139267,-197.361984,-0.001854,0.002546,0.064670,-0.619490,-0.031558,0.646702,-197.361984,0.063673,0.000000
164.110001,-0.141502,-197.406464,-0.001858,0.002522,0.064054,-0.629434,-0.032065,0.640540,-197.406464,0.063005,0.000000
164.400009,-0.083412,-197.406464,-0.001906,0.002506,0.063663,-0.371036,-0.018901,0.636634,-197.406464,0.063517,0.000000