File: Data/compression 32/AutoNoHeating-15-32-reverse-1-2_11142024_174331.csv
Time (sec),S:Load (lbs),S:HL1 (DIM),S:LVDT (in),S:Position (in),Ch:Position (mm),Ch:Load (N),Ch:Stress (MPa),Ch:Strain (mm/mm),Ch:HL1 (DIM),Set Point (),Cycles ()
0.110000,-0.007072,-256.699554,-0.008959,-0.008729,-0.221724,-0.031460,-0.001603,-2.217236,-256.699554,-0.221541,0.000000
0.460000,-0.027931,-256.655090,-0.008990,-0.008660,-0.219954,-0.124244,-0.006329,-2.199545,-256.655090,-0.219477,0.000000
0.810000,0.027924,-256.744049,-0.008864,-0.008456,-0.214777,0.124210,0.006328,-2.147771,-256.744049,-0.213632,0.000000
1.160000,0.006699,-256.744049,-0.008623,-0.008224,-0.208880,0.029797,0.001518,-2.088800,-256.744049,-0.207805,0.000000
1.510000,-0.013779,-256.833008,-0.008403,-0.007999,-0.203182,-0.061291,-0.003122,-2.031823,-256.833008,-0.201977,0.000000
1.860000,0.019363,-256.833008,-0.008170,-0.007766,-0.197259,0.086133,0.004388,-1.972592,-256.833008,-0.196149,0.000000
2.210000,-0.013031,-256.788544,-0.007942,-0.007539,-0.191492,-0.057965,-0.002953,-1.914921,-256.788544,-0.190321,0.000000
2.560000,0.004471,-256.833008,-0.007679,-0.007309,-0.185647,0.019887,0.001013,-1.856470,-256.833008,-0.184494,0.000000
2.910000,-0.013031,-256.833008,-0.007450,-0.007076,-0.179724,-0.057965,-0.002953,-1.797239,-256.833008,-0.178648,0.000000
3.260000,-0.006706,-256.877502,-0.007205,-0.006849,-0.173965,-0.029831,-0.001520,-1.739655,-256.877502,-0.172821,0.000000
3.610000,-0.013779,-256.877502,-0.006967,-0.006615,-0.168034,-0.061291,-0.003122,-1.680336,-256.877502,-0.166993,0.000000
3.960000,0.010056,-256.921967,-0.006765,-0.006399,-0.162544,0.044729,0.002279,-1.625441,-256.921967,-0.161165,0.000000
4.310000,0.021225,-256.877502,-0.006485,-0.006161,-0.156491,0.094413,0.004810,-1.564909,-256.877502,-0.155337,0.000000
4.660000,-0.013031,-256.921967,-0.006269,-0.005930,-0.150628,-0.057965,-0.002953,-1.506284,-256.921967,-0.149492,0.000000
5.010000,-0.045433,-256.921967,-0.006058,-0.005702,-0.144835,-0.202096,-0.010295,-1.448354,-256.921967,-0.143665,0.000000
5.360000,-0.001122,-256.921967,-0.005795,-0.005472,-0.138982,-0.004989,-0.000254,-1.389816,-256.921967,-0.137837,0.000000
5.710000,0.047287,-256.966461,-0.005562,-0.005243,-0.133180,0.210343,0.010715,-1.331799,-256.966461,-0.132009,0.000000
6.060000,0.033142,-257.010925,-0.005320,-0.005018,-0.127447,0.147423,0.007510,-1.274475,-257.010925,-0.126181,0.000000
6.410000,0.023460,-257.010925,-0.005088,-0.004781,-0.121446,0.104357,0.005316,-1.214463,-257.010925,-0.120354,0.000000
6.760000,0.015266,-256.921967,-0.004859,-0.004552,-0.115627,0.067908,0.003459,-1.156272,-256.921967,-0.114508,0.000000
7.110000,0.184326,-257.010925,-0.004695,-0.000003,-0.000069,0.819924,0.041769,-0.000694,-257.010925,0.000113,0.000000
7.460001,0.176506,-257.010925,-0.004717,-0.000003,-0.000078,0.785138,0.039997,-0.000781,-257.010925,0.000113,0.000000
7.810000,0.114693,-257.010925,-0.004700,-0.000001,-0.000035,0.510179,0.025990,-0.000347,-257.010925,0.000642,0.000000
8.160001,0.179855,-257.099884,-0.004691,0.000016,0.000399,0.800037,0.040756,0.003989,-257.099884,0.001223,0.000000
8.510000,0.319122,-257.055420,-0.004687,0.000033,0.000833,1.419527,0.072314,0.008325,-257.055420,0.001804,0.000000
8.860001,0.498978,-257.099884,-0.004652,0.000062,0.001570,2.219563,0.113070,0.015697,-257.099884,0.002385,0.000000
9.210000,0.702667,-257.144379,-0.004639,0.000082,0.002081,3.125620,0.159227,0.020813,-257.144379,0.002975,0.000000
9.560000,0.945824,-257.188873,-0.004609,0.000107,0.002706,4.207234,0.214327,0.027057,-257.188873,0.003556,0.000000
9.910001,1.270905,-257.188873,-0.004609,0.000127,0.003217,5.653266,0.287991,0.032174,-257.188873,0.004137,0.000000
10.260000,1.572159,-257.233337,-0.004570,0.000147,0.003729,6.993312,0.356256,0.037291,-257.233337,0.004726,0.000000
10.610001,1.853668,-257.188873,-0.004557,0.000167,0.004232,8.245528,0.420047,0.042321,-257.188873,0.005307,0.000000
10.960001,2.332169,-257.144379,-0.004527,0.000195,0.004961,10.374004,0.528477,0.049605,-257.144379,0.005888,0.000000
11.310000,2.751831,-257.277832,-0.004510,0.000219,0.005550,12.240756,0.623574,0.055502,-257.277832,0.006470,0.000000
11.660001,3.082123,-257.233337,-0.004493,0.000242,0.006157,13.709967,0.698419,0.061573,-257.233337,0.007059,0.000000
12.010000,3.577011,-257.277832,-0.004467,0.000265,0.006721,15.911340,0.810562,0.067210,-257.277832,0.007640,0.000000
12.360001,3.683136,-257.322296,-0.004467,0.000280,0.007120,16.383408,0.834611,0.071199,-257.322296,0.008221,0.000000
12.710001,4.560814,-257.277832,-0.004437,0.000312,0.007935,20.287514,1.033495,0.079351,-257.277832,0.008802,0.000000
13.060000,4.813286,-257.322296,-0.004419,0.000332,0.008429,21.410564,1.090706,0.084294,-257.322296,0.009392,0.000000
13.410001,5.188263,-257.366791,-0.004398,0.000355,0.009010,23.078547,1.175677,0.090105,-257.366791,0.009973,0.000000
13.760000,5.708466,-257.366791,-0.004363,0.000380,0.009661,25.392523,1.293557,0.096609,-257.366791,0.010554,0.000000
14.110001,5.973595,-257.411255,-0.004368,0.000399,0.010138,26.571877,1.353636,0.101379,-257.411255,0.011135,0.000000
14.460001,6.407043,-257.411255,-0.004337,0.000421,0.010684,28.499952,1.451857,0.106842,-257.411255,0.011725,0.000000
14.810000,6.912720,-257.411255,-0.004320,0.000450,0.011439,30.749313,1.566445,0.114387,-257.411255,0.012306,0.000000
15.160001,7.244881,-257.455750,-0.004294,0.000473,0.012002,32.226837,1.641713,0.120024,-257.455750,0.012887,0.000000
15.510001,7.540169,-257.455750,-0.004277,0.000491,0.012479,33.540344,1.708627,0.124794,-257.455750,0.013477,0.000000
15.860001,8.199638,-257.500214,-0.004243,0.000521,0.013225,36.473812,1.858065,0.132252,-257.500214,0.014058,0.000000
16.210001,8.150864,-257.544708,-0.004230,0.000530,0.013468,36.256851,1.847012,0.134680,-257.544708,0.014639,0.000000
16.560001,8.678139,-257.544708,-0.004217,0.000560,0.014214,38.602287,1.966494,0.142138,-257.544708,0.015220,0.000000
16.910002,9.337242,-257.455750,-0.004178,0.000588,0.014925,41.534126,2.115849,0.149250,-257.455750,0.015810,0.000000
17.260000,9.648918,-257.544708,-0.004165,0.000609,0.015480,42.920532,2.186476,0.154800,-257.544708,0.016391,0.000000
17.610001,10.195930,-257.544708,-0.004152,0.000635,0.016139,45.353764,2.310431,0.161391,-257.544708,0.016972,0.000000
17.960001,10.292747,-257.544708,-0.004143,0.000650,0.016521,45.784428,2.332370,0.165206,-257.544708,0.017553,0.000000
18.310001,10.593254,-257.633667,-0.004118,0.000668,0.016963,47.121147,2.400466,0.169629,-257.633667,0.018142,0.000000
18.660002,11.529022,-257.633667,-0.004070,0.000701,0.017813,51.283653,2.612514,0.178128,-257.633667,0.018723,0.000000
19.010000,11.594185,-257.633667,-0.004074,0.000723,0.018359,51.573509,2.627280,0.183592,-257.633667,0.019304,0.000000
19.360001,11.888359,-257.633667,-0.004036,0.000743,0.018880,52.882061,2.693941,0.188795,-257.633667,0.019894,0.000000
19.710001,12.524750,-257.678162,-0.004023,0.000771,0.019582,55.712868,2.838149,0.195820,-257.678162,0.020475,0.000000
20.060001,12.394791,-257.722626,-0.003997,0.000784,0.019903,55.134781,2.808700,0.199028,-257.722626,0.021056,0.000000
20.410002,12.578743,-257.678162,-0.003992,0.000799,0.020302,55.953045,2.850384,0.203018,-257.678162,0.021637,0.000000
20.760000,13.527550,-257.678162,-0.003954,0.000835,0.021204,60.173546,3.065387,0.212037,-257.678162,0.022227,0.000000
21.110001,13.770332,-257.722626,-0.003936,0.000859,0.021811,61.253498,3.120402,0.218107,-257.722626,0.022808,0.000000
21.460001,14.125946,-257.722626,-0.003906,0.000882,0.022400,62.835346,3.200985,0.224004,-257.722626,0.023389,0.000000
21.810001,14.593277,-257.722626,-0.003902,0.000906,0.023025,64.914139,3.306884,0.230248,-257.722626,0.023970,0.000000
22.160002,14.674080,-257.811584,-0.003863,0.000923,0.023441,65.273567,3.325194,0.234411,-257.811584,0.024560,0.000000
22.510000,15.313446,-257.722626,-0.003854,0.000952,0.024170,68.117607,3.470077,0.241696,-257.722626,0.025141,0.000000
22.860001,15.484360,-257.856079,-0.003820,0.000975,0.024759,68.877869,3.508806,0.247593,-257.856079,0.025722,0.000000
23.210001,16.012390,-257.811584,-0.003807,0.001000,0.025392,71.226669,3.628459,0.253924,-257.811584,0.026303,0.000000
23.560001,16.300980,-257.856079,-0.003777,0.001023,0.025991,72.510376,3.693855,0.259908,-257.856079,0.026893,0.000000
23.910002,16.179955,-257.900543,-0.003751,0.001039,0.026390,71.972031,3.666430,0.263897,-257.900543,0.027474,0.000000
24.260000,17.021515,-257.856079,-0.003734,0.001072,0.027222,75.715477,3.857130,0.272222,-257.856079,0.028055,0.000000
24.610001,17.282547,-257.856079,-0.003725,0.001095,0.027803,76.876610,3.916281,0.278033,-257.856079,0.028644,0.000000
24.960001,17.348831,-257.900543,-0.003678,0.001114,0.028289,77.171455,3.931301,0.282889,-257.900543,0.029226,0.000000
25.310001,17.773338,-257.900543,-0.003673,0.001138,0.028905,79.059761,4.027496,0.289046,-257.900543,0.029807,0.000000
25.660002,17.994530,-257.900543,-0.003639,0.001159,0.029442,80.043663,4.077619,0.294423,-257.900543,0.030388,0.000000
26.010002,18.308807,-257.989502,-0.003609,0.001179,0.029954,81.441643,4.148835,0.299540,-257.989502,0.030977,0.000000
26.360001,19.086693,-257.989502,-0.003591,0.001210,0.030743,84.901848,4.325107,0.307431,-257.989502,0.031558,0.000000
26.710001,18.806671,-258.033997,-0.003570,0.001227,0.031159,83.656250,4.261652,0.311594,-258.033997,0.032139,0.000000
27.060001,18.968651,-258.078491,-0.003553,0.001250,0.031758,84.376770,4.298358,0.317578,-258.078491,0.032720,0.000000
27.410002,19.535774,-258.033997,-0.003523,0.001275,0.032374,86.899467,4.426869,0.323735,-258.033997,0.033310,0.000000
27.760002,19.601311,-257.989502,-0.003514,0.001292,0.032816,87.190987,4.441720,0.328158,-257.989502,0.033891,0.000000
28.110001,19.653076,-258.078491,-0.003484,0.001309,0.033258,87.421249,4.453451,0.332581,-258.078491,0.034472,0.000000
28.460001,20.842804,-258.078491,-0.003471,0.001346,0.034177,92.713425,4.723047,0.341774,-258.078491,0.035062,0.000000
28.810001,20.677467,-258.167450,-0.003441,0.001365,0.034680,91.977966,4.685581,0.346804,-258.167450,0.035643,0.000000
29.160002,20.826050,-258.122955,-0.003410,0.001390,0.035296,92.638893,4.719250,0.352961,-258.122955,0.036224,0.000000
29.510002,21.297844,-258.167450,-0.003389,0.001412,0.035860,94.737541,4.826160,0.358598,-258.167450,0.036805,0.000000
29.860001,21.422585,-258.122955,-0.003359,0.001431,0.036337,95.292412,4.854427,0.363368,-258.122955,0.037395,0.000000
30.210001,22.374741,-258.167450,-0.003350,0.001461,0.037100,99.527817,5.070189,0.370999,-258.167450,0.037976,0.000000
30.560001,22.275322,-258.211914,-0.003316,0.001482,0.037638,99.085579,5.047660,0.376376,-258.211914,0.038557,0.000000
30.910002,22.452568,-258.256409,-0.003290,0.001504,0.038210,99.874008,5.087825,0.382100,-258.256409,0.039138,0.000000
31.260002,22.689026,-258.256409,-0.003264,0.001526,0.038756,100.925827,5.141407,0.387563,-258.256409,0.039728,0.000000
31.610001,22.770950,-258.211914,-0.003251,0.001545,0.039233,101.290245,5.159971,0.392333,-258.211914,0.040309,0.000000
31.960001,23.221146,-258.300873,-0.003238,0.001568,0.039823,103.292816,5.261987,0.398230,-258.300873,0.040890,0.000000
32.310001,23.782684,-258.256409,-0.003195,0.001594,0.040491,105.790665,5.389234,0.404908,-258.256409,0.041471,0.000000
32.660000,24.131966,-258.300873,-0.003186,0.001618,0.041089,107.344345,5.468381,0.410892,-258.300873,0.042060,0.000000
33.010002,24.485352,-258.345367,-0.003143,0.001642,0.041714,108.916283,5.548460,0.417136,-258.345367,0.042641,0.000000
33.360001,24.772453,-258.345367,-0.003109,0.001665,0.042295,110.193375,5.613518,0.422946,-258.345367,0.043223,0.000000
33.710003,24.858093,-258.345367,-0.003104,0.001685,0.042789,110.574318,5.632925,0.427889,-258.345367,0.043812,0.000000
34.060001,25.509377,-258.345367,-0.003074,0.001712,0.043483,113.471375,5.780508,0.434827,-258.345367,0.044393,0.000000
34.410000,25.620712,-258.389832,-0.003061,0.001732,0.044003,113.966621,5.805737,0.440030,-258.389832,0.044974,0.000000
34.760002,25.786789,-258.389832,-0.003018,0.001754,0.044541,114.705368,5.843370,0.445407,-258.389832,0.045555,0.000000
35.110001,26.437325,-258.389832,-0.003005,0.001781,0.045243,117.599091,5.990783,0.452432,-258.389832,0.046145,0.000000
35.460003,26.294334,-258.434326,-0.002975,0.001798,0.045677,116.963043,5.958381,0.456768,-258.434326,0.046726,0.000000
35.810001,26.765388,-258.389832,-0.002966,0.001823,0.046310,119.058395,6.065124,0.463099,-258.389832,0.047307,0.000000
36.160000,27.554443,-258.523285,-0.002932,0.001851,0.047004,122.568283,6.243926,0.470036,-258.523285,0.047888,0.000000
36.510002,27.652382,-258.523285,-0.002915,0.001873,0.047576,123.003937,6.266119,0.475760,-258.523285,0.048478,0.000000
36.860001,27.631157,-258.434326,-0.002863,0.001890,0.048018,122.909523,6.261310,0.480183,-258.434326,0.049059,0.000000
37.210003,28.534157,-258.478821,-0.002854,0.001919,0.048747,126.926270,6.465932,0.487468,-258.478821,0.049640,0.000000
37.560001,27.871704,-258.567780,-0.002837,0.001929,0.048990,123.979530,6.315818,0.489896,-258.567780,0.050230,0.000000
37.910004,29.539192,-258.567780,-0.002815,0.001967,0.049952,131.396896,6.693676,0.499522,-258.567780,0.050811,0.000000
38.260002,29.755165,-258.567780,-0.002781,0.001990,0.050551,132.357590,6.742617,0.505506,-258.567780,0.051392,0.000000
38.610001,29.796127,-258.612244,-0.002759,0.002008,0.051010,132.539795,6.751899,0.510102,-258.612244,0.051973,0.000000
38.960003,30.433632,-258.656738,-0.002742,0.002035,0.051695,135.375549,6.896360,0.516953,-258.656738,0.052563,0.000000
39.310001,30.234406,-258.612244,-0.002708,0.002051,0.052103,134.489349,6.851214,0.521029,-258.612244,0.053144,0.000000
39.660004,30.239250,-258.656738,-0.002677,0.002067,0.052511,134.510910,6.852312,0.525105,-258.656738,0.053725,0.000000
40.010002,31.872101,-258.656738,-0.002673,0.002103,0.053412,141.774185,7.222321,0.534124,-258.656738,0.054306,0.000000
40.360001,31.812523,-258.701202,-0.002660,0.002122,0.053907,141.509171,7.208820,0.539067,-258.701202,0.054895,0.000000
40.710003,31.978600,-258.656738,-0.002630,0.002141,0.054392,142.247910,7.246454,0.543924,-258.656738,0.055476,0.000000
41.060001,32.973206,-258.701202,-0.002591,0.002171,0.055147,146.672150,7.471836,0.551469,-258.701202,0.056057,0.000000
41.410004,32.394913,-258.701202,-0.002578,0.002182,0.055433,144.099762,7.340792,0.554331,-258.701202,0.056639,0.000000
41.760002,32.886818,-258.745697,-0.002544,0.002211,0.056153,146.287872,7.452260,0.561529,-258.745697,0.057228,0.000000
42.110001,33.947334,-258.745697,-0.002527,0.002234,0.056743,151.005280,7.692576,0.567426,-258.745697,0.057809,0.000000
42.460003,34.418388,-258.745697,-0.002496,0.002260,0.057410,153.100632,7.799318,0.574103,-258.745697,0.058390,0.000000
42.810001,34.658195,-258.834656,-0.002479,0.002281,0.057931,154.167358,7.853659,0.579307,-258.834656,0.058980,0.000000
43.160004,35.485977,-258.879150,-0.002440,0.002305,0.058555,157.849503,8.041237,0.585551,-258.879150,0.059561,0.000000
43.510002,35.363098,-258.790161,-0.002427,0.002322,0.058989,157.302917,8.013392,0.589887,-258.790161,0.060142,0.000000
43.860001,36.501808,-258.790161,-0.002393,0.002353,0.059769,162.368149,8.271428,0.597692,-258.790161,0.060723,0.000000
44.210003,37.020523,-258.879150,-0.002367,0.002377,0.060385,164.675507,8.388970,0.603849,-258.879150,0.061313,0.000000
44.560001,37.491203,-258.923615,-0.002341,0.002399,0.060940,166.769196,8.495628,0.609399,-258.923615,0.061894,0.000000
44.910004,38.171532,-258.879150,-0.002324,0.002425,0.061590,169.795456,8.649793,0.615904,-258.879150,0.062475,0.000000
45.260002,38.206161,-258.968109,-0.002302,0.002445,0.062093,169.949493,8.657640,0.620934,-258.968109,0.063056,0.000000
45.610001,39.112144,-258.879150,-0.002272,0.002472,0.062778,173.979507,8.862939,0.627785,-258.879150,0.063646,0.000000
45.960003,39.777199,-258.923615,-0.002229,0.002495,0.063368,176.937820,9.013641,0.633682,-258.923615,0.064227,0.000000
46.310001,39.751877,-258.923615,-0.002207,0.002514,0.063854,176.825180,9.007904,0.638538,-258.923615,0.064808,0.000000
46.660004,40.443001,-258.968109,-0.002195,0.002539,0.064487,179.899460,9.164515,0.644869,-258.968109,0.065397,0.000000
47.010002,40.654510,-258.968109,-0.002164,0.002558,0.064973,180.840302,9.212443,0.649725,-258.968109,0.065979,0.000000
47.360001,41.059273,-259.012573,-0.002130,0.002578,0.065484,182.640762,9.304165,0.654842,-259.012573,0.066560,0.000000
47.710003,42.427742,-259.012573,-0.002104,0.002610,0.066291,188.728027,9.614264,0.662907,-259.012573,0.067141,0.000000
48.060001,42.183098,-259.012573,-0.002078,0.002627,0.066733,187.639786,9.558826,0.667330,-259.012573,0.067730,0.000000
48.410004,42.742401,-259.057068,-0.002065,0.002651,0.067331,190.127701,9.685567,0.673314,-259.057068,0.068311,0.000000
48.760002,43.400757,-259.057068,-0.002022,0.002674,0.067930,193.056213,9.834752,0.679298,-259.057068,0.068892,0.000000
49.110001,43.502411,-259.101532,-0.002001,0.002690,0.068329,193.508392,9.857787,0.683287,-259.101532,0.069473,0.000000
49.460003,43.640564,-259.101532,-0.001983,0.002708,0.068788,194.122925,9.889092,0.687883,-259.101532,0.070063,0.000000
49.810001,45.762344,-259.146027,-0.001957,0.002746,0.069742,203.561081,10.369896,0.697423,-259.146027,0.070644,0.000000
50.160004,45.719887,-259.101532,-0.001919,0.002765,0.070237,203.372208,10.360274,0.702366,-259.101532,0.071225,0.000000
50.510002,46.052788,-259.146027,-0.001897,0.002788,0.070826,204.853027,10.435711,0.708263,-259.146027,0.071806,0.000000
50.860001,46.987076,-259.279449,-0.001871,0.002812,0.071416,209.008957,10.647424,0.714160,-259.279449,0.072396,0.000000
51.210003,47.213852,-259.234985,-0.001845,0.002830,0.071884,210.017700,10.698812,0.718843,-259.234985,0.072977,0.000000
51.560001,48.573753,-259.323944,-0.001824,0.002862,0.072691,216.066849,11.006969,0.726909,-259.323944,0.073558,0.000000
51.910004,48.752861,-259.279449,-0.001772,0.002883,0.073220,216.863556,11.047557,0.732199,-259.279449,0.074148,0.000000
52.260002,49.071617,-259.234985,-0.001759,0.002902,0.073723,218.281448,11.119787,0.737229,-259.234985,0.074729,0.000000
52.610001,49.518089,-259.279449,-0.001729,0.002924,0.074278,220.267456,11.220960,0.742779,-259.279449,0.075310,0.000000
52.960003,49.823807,-259.368439,-0.001707,0.002943,0.074764,221.627365,11.290236,0.747635,-259.368439,0.075891,0.000000
53.310001,50.332466,-259.323944,-0.001651,0.002969,0.075423,223.889984,11.405500,0.754226,-259.323944,0.076481,0.000000
53.660004,51.239197,-259.368439,-0.001638,0.002993,0.076012,227.923325,11.610969,0.760123,-259.368439,0.077062,0.000000
54.010002,51.794403,-259.412903,-0.001621,0.003017,0.076619,230.393005,11.736779,0.766194,-259.412903,0.077643,0.000000
54.360004,52.410309,-259.412903,-0.001591,0.003041,0.077235,233.132690,11.876346,0.772351,-259.412903,0.078224,0.000000
54.710003,53.035522,-259.368439,-0.001569,0.003065,0.077851,235.913788,12.018022,0.778508,-259.368439,0.078813,0.000000
55.060001,53.156540,-259.412903,-0.001535,0.003083,0.078302,236.452103,12.045444,0.783018,-259.412903,0.079395,0.000000
55.410004,54.079651,-259.412903,-0.001500,0.003110,0.079004,240.558304,12.254624,0.790043,-259.412903,0.079976,0.000000
55.760002,54.347389,-259.457397,-0.001475,0.003131,0.079525,241.749268,12.315294,0.795246,-259.457397,0.080557,0.000000
56.110004,54.652733,-259.501862,-0.001457,0.003152,0.080071,243.107498,12.384486,0.800709,-259.501862,0.081146,0.000000
56.460003,55.558716,-259.501862,-0.001418,0.003180,0.080765,247.137512,12.589786,0.807647,-259.501862,0.081727,0.000000
56.810001,55.500626,-259.501862,-0.001393,0.003197,0.081198,246.879120,12.576622,0.811983,-259.501862,0.082308,0.000000
57.160004,56.163452,-259.501862,-0.001362,0.003223,0.081857,249.827515,12.726820,0.818574,-259.501862,0.082898,0.000000
57.510002,57.181885,-259.546356,-0.001324,0.003249,0.082534,254.357727,12.957600,0.825339,-259.546356,0.083479,0.000000
57.860004,57.421326,-259.501862,-0.001302,0.003272,0.083106,255.422806,13.011858,0.831062,-259.501862,0.084060,0.000000
58.210003,57.625755,-259.546356,-0.001276,0.003294,0.083661,256.332153,13.058183,0.836613,-259.546356,0.084641,0.000000
58.560001,58.598389,-259.590820,-0.001242,0.003318,0.084268,260.658661,13.278584,0.842683,-259.590820,0.085231,0.000000
58.910004,57.773956,-259.590820,-0.001207,0.003327,0.084511,256.991394,13.091765,0.845111,-259.590820,0.085812,0.000000
59.260002,59.088058,-259.635315,-0.001181,0.003365,0.085465,262.836823,13.389545,0.854651,-259.635315,0.086393,0.000000
59.610004,60.189171,-259.679779,-0.001134,0.003390,0.086098,267.734802,13.639061,0.860982,-259.679779,0.086974,0.000000
59.960003,60.289337,-259.679779,-0.001117,0.003407,0.086549,268.180359,13.661758,0.865491,-259.679779,0.087564,0.000000
60.310001,61.174835,-259.724274,-0.001091,0.003434,0.087217,272.119263,13.862415,0.872169,-259.724274,0.088145,0.000000
60.660004,60.964821,-259.724274,-0.001056,0.003450,0.087624,271.185059,13.814825,0.876245,-259.724274,0.088726,0.000000
61.010002,60.868004,-259.768768,-0.001039,0.003467,0.088049,270.754395,13.792887,0.880494,-259.768768,0.089316,0.000000
61.360004,62.570114,-259.724274,-0.001005,0.003502,0.088951,278.325775,14.178590,0.889513,-259.724274,0.089897,0.000000
61.710003,62.764122,-259.768768,-0.000979,0.003522,0.089463,279.188751,14.222553,0.894630,-259.768768,0.090478,0.000000
62.060001,63.211716,-259.724274,-0.000949,0.003547,0.090096,281.179749,14.323979,0.900961,-259.724274,0.091059,0.000000
62.410004,64.198868,-259.768768,-0.000923,0.003572,0.090720,285.570831,14.547671,0.907205,-259.768768,0.091648,0.000000
62.760002,63.614624,-259.768768,-0.000892,0.003581,0.090955,282.971985,14.415279,0.909546,-259.768768,0.092229,0.000000
63.110004,63.892044,-259.813232,-0.000897,0.003607,0.091622,284.205994,14.478144,0.916224,-259.813232,0.092810,0.000000
63.460003,65.425476,-259.857727,-0.000828,0.003632,0.092264,291.027039,14.825624,0.922641,-259.857727,0.093392,0.000000
63.810001,66.044724,-259.857727,-0.000815,0.003658,0.092915,293.781616,14.965948,0.929146,-259.857727,0.093981,0.000000
64.160004,64.582794,-259.902191,-0.000789,0.003650,0.092698,287.278625,14.634670,0.926978,-259.902191,0.016286,0.000000
64.510002,65.276886,-259.902191,-0.000759,0.003485,0.088526,290.366089,14.791954,0.885264,-259.902191,294.500458,0.000000
64.860001,65.134277,-259.857727,-0.000742,0.003678,0.093418,289.731750,14.759639,0.934175,-259.857727,294.500458,0.000000
65.210007,65.572556,-259.946686,-0.000729,0.003703,0.094068,291.681305,14.858953,0.940680,-259.946686,294.500458,0.000000
65.560005,65.417282,-259.991150,-0.000707,0.003717,0.094406,290.990601,14.823769,0.944062,-259.991150,294.500458,0.000000
65.910004,64.863190,-259.902191,-0.000690,0.003727,0.094666,288.525879,14.698209,0.946664,-259.902191,294.500458,0.000000
66.260002,65.330521,-259.991150,-0.000686,0.003739,0.094961,290.604675,14.804107,0.949612,-259.991150,294.500458,0.000000
66.610001,65.722244,-260.035645,-0.000673,0.003749,0.095221,292.347137,14.892874,0.952214,-260.035645,294.500458,0.000000
66.960007,66.008606,-260.035645,-0.000647,0.003760,0.095516,293.620941,14.957764,0.955162,-260.035645,294.500458,0.000000
67.310005,64.894470,-260.035645,-0.000642,0.003765,0.095638,288.665009,14.705297,0.956376,-260.035645,294.500458,0.000000
67.660004,65.136505,-260.080109,-0.000625,0.003779,0.095976,289.741638,14.760143,0.959759,-260.080109,294.500458,0.000000
68.010002,65.394928,-260.080109,-0.000617,0.003791,0.096288,290.891174,14.818703,0.962881,-260.080109,294.500458,0.000000
68.360001,65.170395,-260.035645,-0.000599,0.003797,0.096435,289.892395,14.767822,0.964355,-260.035645,294.500458,0.000000
68.710007,65.132034,-260.080109,-0.000591,0.003804,0.096609,289.721771,14.759130,0.966089,-260.080109,294.500458,0.000000
69.060005,65.262375,-260.124603,-0.000586,0.003814,0.096886,290.301544,14.788666,0.968865,-260.124603,294.500458,0.000000
69.410004,65.269073,-260.169098,-0.000573,0.003819,0.097008,290.331329,14.790184,0.970079,-260.169098,294.500458,0.000000
69.760002,65.202423,-260.169098,-0.000556,0.003825,0.097164,290.034851,14.775080,0.971640,-260.169098,294.500458,0.000000
70.110001,65.199066,-260.213562,-0.000560,0.003831,0.097320,290.019928,14.774320,0.973201,-260.213562,294.500458,0.000000
70.460007,65.298859,-260.213562,-0.000560,0.003839,0.097511,290.463837,14.796933,0.975109,-260.213562,294.500458,0.000000
70.810005,65.208374,-260.213562,-0.000543,0.003844,0.097650,290.061340,14.776429,0.976496,-260.213562,294.500458,0.000000
71.160004,65.037827,-260.258057,-0.000543,0.003847,0.097719,289.302704,14.737782,0.977190,-260.258057,294.500458,0.000000
71.510002,65.361786,-260.258057,-0.000535,0.003857,0.097962,290.743744,14.811193,0.979618,-260.258057,294.500458,0.000000
71.860001,65.196457,-260.258057,-0.000530,0.003859,0.098031,290.008331,14.773728,0.980312,-260.258057,294.500458,0.000000
72.210007,65.280243,-260.302521,-0.000526,0.003864,0.098153,290.381012,14.792715,0.981526,-260.302521,294.500458,0.000000
72.560005,65.209122,-260.302521,-0.000509,0.003868,0.098257,290.064667,14.776598,0.982567,-260.302521,294.500458,0.000000
72.910004,65.302963,-260.347015,-0.000522,0.003874,0.098404,290.482086,14.797863,0.984041,-260.347015,294.500458,0.000000
73.260002,65.289932,-260.347015,-0.000504,0.003878,0.098508,290.424133,14.794909,0.985082,-260.347015,294.500458,0.000000
73.610001,65.272797,-260.347015,-0.000504,0.003882,0.098595,290.347900,14.791027,0.985949,-260.347015,294.500458,0.000000
73.960007,65.249344,-260.347015,-0.000492,0.003885,0.098673,290.243591,14.785712,0.986729,-260.347015,294.500458,0.000000
74.310005,65.376694,-260.391479,-0.000483,0.003890,0.098803,290.810059,14.814571,0.988030,-260.391479,294.500458,0.000000
74.660004,65.282852,-260.435974,-0.000492,0.003893,0.098872,290.392639,14.793305,0.988724,-260.435974,294.500458,0.000000
75.010002,65.175613,-260.391479,-0.000496,0.003895,0.098933,289.915619,14.769006,0.989331,-260.391479,294.500458,0.000000
75.360001,65.208374,-260.435974,-0.000474,0.003899,0.099028,290.061340,14.776429,0.990285,-260.435974,294.500458,0.000000
75.710007,65.199814,-260.391479,-0.000487,0.003901,0.099098,290.023254,14.774489,0.990979,-260.391479,294.500458,0.000000
76.060005,65.158112,-260.480438,-0.000487,0.003904,0.099167,289.837769,14.765039,0.991673,-260.480438,294.500458,0.000000
76.410004,65.130173,-260.524933,-0.000466,0.003910,0.099306,289.713470,14.758708,0.993060,-260.524933,294.500458,0.000000
76.760002,65.209869,-260.480438,-0.000470,0.003910,0.099323,290.067993,14.776768,0.993234,-260.480438,294.500458,0.000000
77.110001,65.214340,-260.524933,-0.000461,0.003913,0.099401,290.087860,14.777781,0.994014,-260.524933,294.500458,0.000000
77.460007,65.222519,-260.524933,-0.000466,0.003917,0.099479,290.124268,14.779634,0.994795,-260.524933,294.500458,0.000000
77.810005,65.238159,-260.524933,-0.000457,0.003919,0.099540,290.193817,14.783178,0.995402,-260.524933,294.500458,0.000000
78.160004,65.218796,-260.569397,-0.000453,0.003921,0.099592,290.107697,14.778790,0.995922,-260.569397,294.500458,0.000000
78.510002,65.192368,-260.569397,-0.000461,0.003923,0.099644,289.990143,14.772801,0.996442,-260.569397,294.500458,0.000000
78.860001,65.212479,-260.569397,-0.000448,0.003925,0.099705,290.079590,14.777359,0.997049,-260.569397,294.500458,0.000000
79.210007,65.061661,-260.613892,-0.000448,0.003926,0.099714,289.408722,14.743183,0.997136,-260.613892,294.500458,0.000000
79.560005,65.516693,-260.702850,-0.000431,0.003932,0.099870,291.432800,14.846294,0.998697,-260.702850,294.500458,0.000000
79.910004,65.330521,-260.658386,-0.000444,0.003932,0.099870,290.604675,14.804107,0.998697,-260.658386,294.500458,0.000000
80.260002,65.201294,-260.658386,-0.000440,0.003932,0.099870,290.029846,14.774824,0.998697,-260.658386,294.500458,0.000000
80.610001,65.011383,-260.747345,-0.000448,0.003932,0.099870,289.185089,14.731790,0.998697,-260.747345,294.500458,0.000000
80.960007,64.835632,-260.658386,-0.000435,0.003939,0.100043,288.403290,14.691964,1.000432,-260.658386,294.500458,0.000000
81.310005,65.870819,-260.702850,-0.000444,0.003937,0.099991,293.008026,14.926540,0.999911,-260.702850,294.500458,0.000000
81.660004,65.739014,-260.747345,-0.000435,0.003937,0.099991,292.421722,14.896673,0.999911,-260.747345,294.500458,0.000000
82.010002,65.505524,-260.791809,-0.000435,0.003937,0.099991,291.383118,14.843763,0.999911,-260.791809,294.500458,0.000000
82.360001,65.290298,-260.791809,-0.000418,0.003937,0.099991,290.425751,14.794993,0.999911,-260.791809,294.500458,0.000000
82.710007,65.088837,-260.791809,-0.000410,0.003937,0.099991,289.529602,14.749341,0.999911,-260.791809,294.500458,0.000000
83.060005,65.216202,-260.836304,-0.000414,0.003945,0.100199,290.096161,14.778203,1.001992,-260.836304,294.500458,0.000000
83.410004,65.231461,-260.880768,-0.000414,0.003948,0.100269,290.164032,14.781660,1.002686,-260.880768,294.500458,0.000000
83.760002,65.157364,-260.880768,-0.000423,0.003948,0.100269,289.834442,14.764870,1.002686,-260.880768,294.500458,0.000000
84.110001,65.149536,-260.880768,-0.000423,0.003950,0.100329,289.799622,14.763096,1.003293,-260.880768,294.500458,0.000000
84.460007,65.150665,-260.880768,-0.000414,0.003953,0.100407,289.804626,14.763351,1.004074,-260.880768,294.500458,0.000000
84.810005,65.247849,-260.836304,-0.000410,0.003953,0.100416,290.236938,14.785374,1.004161,-260.836304,294.500458,0.000000
85.160004,65.145447,-260.880768,-0.000405,0.003954,0.100425,289.781433,14.762170,1.004247,-260.880768,294.500458,0.000000
85.510002,65.223267,-260.969727,-0.000410,0.003956,0.100477,290.127594,14.779803,1.004768,-260.969727,294.500458,0.000000
85.860001,65.140610,-260.969727,-0.000414,0.003956,0.100494,289.759918,14.761073,1.004941,-260.969727,294.500458,0.000000
86.210007,65.108948,-260.969727,-0.000414,0.003957,0.100511,289.619049,14.753899,1.005115,-260.969727,294.500458,0.000000
86.560005,65.082886,-261.014221,-0.000401,0.003959,0.100555,289.503143,14.747993,1.005548,-261.014221,294.500458,0.000000
86.910004,65.141724,-260.925262,-0.000414,0.003960,0.100590,289.764862,14.761325,1.005895,-260.925262,294.500458,0.000000
87.260002,65.080276,-261.014221,-0.000401,0.003960,0.100590,289.491516,14.747402,1.005895,-261.014221,294.500458,0.000000
87.610001,65.552826,-260.969727,-0.000392,0.003969,0.100806,291.593536,14.854483,1.008063,-260.969727,294.500458,0.000000
87.960007,65.568085,-261.058716,-0.000405,0.003967,0.100754,291.661407,14.857941,1.007543,-261.058716,294.500458,0.000000
88.310005,65.489151,-261.058716,-0.000397,0.003967,0.100754,291.310303,14.840055,1.007543,-261.058716,294.500458,0.000000
88.660004,65.367386,-261.014221,-0.000388,0.003967,0.100754,290.768646,14.812461,1.007543,-261.014221,294.500458,0.000000
89.010002,65.279877,-261.103180,-0.000401,0.003967,0.100754,290.379395,14.792631,1.007543,-261.103180,294.500458,0.000000
89.360001,65.194595,-261.103180,-0.000405,0.003967,0.100763,290.000031,14.773306,1.007630,-261.103180,294.500458,0.000000
89.710007,65.532715,-261.147675,-0.000392,0.003974,0.100928,291.504089,14.849925,1.009277,-261.147675,294.500458,0.000000
90.060005,65.539780,-261.103180,-0.000397,0.003973,0.100919,291.535492,14.851526,1.009191,-261.103180,294.500458,0.000000
90.410004,65.499939,-261.147675,-0.000392,0.003973,0.100919,291.358276,14.842498,1.009191,-261.147675,294.500458,0.000000
90.760002,65.430679,-261.192139,-0.000397,0.003973,0.100919,291.050201,14.826804,1.009191,-261.192139,294.500458,0.000000
91.110001,65.379288,-261.147675,-0.000397,0.003974,0.100928,290.821594,14.815159,1.009277,-261.147675,294.500458,0.000000
91.460007,65.303329,-261.192139,-0.000397,0.003974,0.100928,290.483704,14.797946,1.009277,-261.192139,294.500458,0.000000
91.810005,65.244125,-261.236633,-0.000401,0.003974,0.100928,290.220367,14.784530,1.009277,-261.236633,294.500458,0.000000
92.160004,65.167786,-261.192139,-0.000388,0.003975,0.100954,289.880798,14.767232,1.009537,-261.192139,294.500458,0.000000
92.510002,65.235565,-261.236633,-0.000397,0.003976,0.100997,290.182281,14.782591,1.009971,-261.236633,294.500458,0.000000
92.860001,65.183426,-261.281097,-0.000392,0.003976,0.100997,289.950348,14.770775,1.009971,-261.281097,294.500458,0.000000
93.210007,65.129425,-261.281097,-0.000397,0.003976,0.100997,289.710144,14.758538,1.009971,-261.281097,294.500458,0.000000
93.560005,65.099274,-261.281097,-0.000397,0.003978,0.101032,289.576019,14.751707,1.010318,-261.281097,294.500458,0.000000
93.910004,65.074326,-261.281097,-0.000397,0.003978,0.101032,289.465057,14.746053,1.010318,-261.281097,294.500458,0.000000
94.260002,65.017715,-261.325592,-0.000392,0.003978,0.101049,289.213257,14.733225,1.010491,-261.325592,294.500458,0.000000
94.610008,65.040436,-261.370056,-0.000379,0.003979,0.101066,289.314301,14.738373,1.010665,-261.370056,294.500458,0.000000
94.960007,65.249710,-261.414551,-0.000397,0.003986,0.101240,290.245209,14.785795,1.012399,-261.414551,294.500458,0.000000
95.310005,65.513718,-261.414551,-0.000371,0.003986,0.101240,291.419556,14.845620,1.012399,-261.414551,294.500458,0.000000
95.660004,65.501434,-261.370056,-0.000384,0.003986,0.101240,291.364929,14.842837,1.012399,-261.370056,294.500458,0.000000
96.010002,65.473129,-261.370056,-0.000392,0.003986,0.101240,291.239014,14.836423,1.012399,-261.370056,294.500458,0.000000
96.360008,65.405365,-261.370056,-0.000401,0.003986,0.101240,290.937592,14.821068,1.012399,-261.370056,294.500458,0.000000
96.710007,65.346527,-261.414551,-0.000375,0.003986,0.101240,290.675873,14.807735,1.012399,-261.414551,294.500458,0.000000
97.060005,65.298111,-261.503510,-0.000392,0.003986,0.101240,290.460510,14.796764,1.012399,-261.503510,294.500458,0.000000
97.410004,65.244492,-261.459045,-0.000379,0.003986,0.101249,290.221985,14.784614,1.012486,-261.459045,294.500458,0.000000
97.760002,65.184174,-261.503510,-0.000362,0.003987,0.101257,289.953674,14.770945,1.012573,-261.503510,294.500458,0.000000
98.110008,65.200180,-261.459045,-0.000379,0.003988,0.101292,290.024872,14.774571,1.012920,-261.459045,294.500458,0.000000
98.460007,65.213211,-261.459045,-0.000371,0.003988,0.101301,290.082855,14.777525,1.013006,-261.459045,294.500458,0.000000
98.810005,65.168900,-261.548004,-0.000366,0.003988,0.101301,289.885742,14.767485,1.013006,-261.548004,294.500458,0.000000
99.160004,65.160706,-261.548004,-0.000358,0.003989,0.101309,289.849304,14.765627,1.013093,-261.548004,294.500458,0.000000
99.510002,65.250458,-261.548004,-0.000371,0.003992,0.101387,290.248535,14.785965,1.013874,-261.548004,294.500458,0.000000
99.860008,65.264969,-261.592468,-0.000362,0.003992,0.101387,290.313080,14.789253,1.013874,-261.592468,294.500458,0.000000
100.210007,65.251938,-261.548004,-0.000375,0.003992,0.101387,290.255127,14.786300,1.013874,-261.548004,294.500458,0.000000
100.560005,65.217682,-261.592468,-0.000371,0.003992,0.101396,290.102753,14.778538,1.013960,-261.592468,294.500458,0.000000
100.910004,65.187149,-261.636963,-0.000371,0.003992,0.101396,289.966919,14.771620,1.013960,-261.636963,294.500458,0.000000
101.260002,65.141342,-261.636963,-0.000358,0.003992,0.101396,289.763153,14.761239,1.013960,-261.636963,294.500458,0.000000
101.610008,65.115280,-261.636963,-0.000375,0.003992,0.101405,289.647247,14.755334,1.014047,-261.636963,294.500458,0.000000
101.960007,65.074326,-261.681427,-0.000362,0.003992,0.101405,289.465057,14.746053,1.014047,-261.681427,294.500458,0.000000
102.310005,65.245605,-261.770386,-0.000379,0.003995,0.101483,290.226959,14.784865,1.014828,-261.770386,294.500458,0.000000
102.660004,65.243744,-261.725922,-0.000362,0.003996,0.101491,290.218658,14.784444,1.014914,-261.725922,294.500458,0.000000
103.010002,65.285080,-261.725922,-0.000371,0.003997,0.101526,290.402527,14.793811,1.015261,-261.725922,294.500458,0.000000
103.360008,65.299240,-261.770386,-0.000362,0.003997,0.101535,290.465515,14.797020,1.015348,-261.770386,294.500458,0.000000
103.710007,65.288803,-261.814880,-0.000366,0.003997,0.101535,290.419098,14.794654,1.015348,-261.814880,294.500458,0.000000
104.060005,65.281357,-261.814880,-0.000362,0.003998,0.101543,290.385986,14.792967,1.015435,-261.814880,294.500458,0.000000
104.410004,65.283966,-261.814880,-0.000345,0.003998,0.101552,290.397583,14.793558,1.015521,-261.814880,294.500458,0.000000
104.760002,65.264969,-261.814880,-0.000362,0.003998,0.101552,290.313080,14.789253,1.015521,-261.814880,294.500458,0.000000
105.110008,65.239655,-261.859344,-0.000362,0.003998,0.101561,290.200470,14.783518,1.015608,-261.859344,294.500458,0.000000
105.460007,65.239655,-261.814880,-0.000354,0.003999,0.101587,290.200470,14.783518,1.015868,-261.814880,294.500458,0.000000
105.810005,65.252319,-261.859344,-0.000362,0.003999,0.101587,290.256805,14.786387,1.015868,-261.859344,294.500458,0.000000
106.160004,65.220657,-261.859344,-0.000354,0.004000,0.101595,290.115967,14.779213,1.015955,-261.859344,294.500458,0.000000
106.510002,65.201294,-261.948334,-0.000362,0.004000,0.101595,290.029846,14.774824,1.015955,-261.948334,294.500458,0.000000
106.860008,65.186783,-261.948334,-0.000362,0.004001,0.101613,289.965302,14.771536,1.016128,-261.948334,294.500458,0.000000
107.210007,65.208008,-261.948334,-0.000358,0.004002,0.101648,290.059692,14.776345,1.016475,-261.948334,294.500458,0.000000
107.560005,65.238907,-261.992798,-0.000358,0.004002,0.101656,290.197144,14.783348,1.016562,-261.992798,294.500458,0.000000
107.910004,65.238159,-261.948334,-0.000358,0.004002,0.101656,290.193817,14.783178,1.016562,-261.948334,294.500458,0.000000
108.260002,65.229599,-262.037292,-0.000362,0.004002,0.101656,290.155762,14.781239,1.016562,-262.037292,294.500458,0.000000
108.610008,65.188644,-262.037292,-0.000371,0.004002,0.101656,289.973572,14.771957,1.016562,-262.037292,294.500458,0.000000
108.960007,65.171890,-262.037292,-0.000358,0.004003,0.101682,289.899048,14.768161,1.016822,-262.037292,294.500458,0.000000
109.310005,65.210617,-262.037292,-0.000366,0.004004,0.101708,290.071320,14.776937,1.017082,-262.037292,294.500458,0.000000
109.660004,65.199814,-262.037292,-0.000349,0.004004,0.101708,290.023254,14.774489,1.017082,-262.037292,294.500458,0.000000
110.010002,65.183426,-262.081757,-0.000341,0.004004,0.101708,289.950348,14.770775,1.017082,-262.081757,294.500458,0.000000
110.360008,65.200180,-262.081757,-0.000358,0.004006,0.101743,290.024872,14.774571,1.017429,-262.081757,294.500458,0.000000
110.710007,65.272797,-262.126251,-0.000371,0.004007,0.101778,290.347900,14.791027,1.017776,-262.126251,294.500458,0.000000
111.060005,65.282852,-262.126251,-0.000341,0.004007,0.101778,290.392639,14.793305,1.017776,-262.126251,294.500458,0.000000
111.410004,65.281357,-262.215210,-0.000354,0.004007,0.101778,290.385986,14.792967,1.017776,-262.215210,294.500458,0.000000
111.760002,65.267212,-262.215210,-0.000358,0.004007,0.101778,290.323059,14.789762,1.017776,-262.215210,294.500458,0.000000
112.110008,65.246735,-262.259674,-0.000362,0.004007,0.101778,290.231964,14.785122,1.017776,-262.259674,294.500458,0.000000
112.460007,65.215073,-262.259674,-0.000341,0.004007,0.101778,290.091125,14.777947,1.017776,-262.259674,294.500458,0.000000
112.810005,65.225128,-262.259674,-0.000345,0.004007,0.101786,290.135864,14.780226,1.017863,-262.259674,294.500458,0.000000
113.160004,65.217316,-262.304169,-0.000366,0.004008,0.101795,290.101105,14.778456,1.017949,-262.304169,294.500458,0.000000
113.510002,65.165176,-262.348663,-0.000354,0.004009,0.101821,289.869171,14.766640,1.018210,-262.348663,294.500458,0.000000
113.860008,65.197952,-262.259674,-0.000354,0.004009,0.101821,290.014984,14.774067,1.018210,-262.259674,294.500458,0.000000
114.210007,65.218796,-262.348663,-0.000345,0.004009,0.101830,290.107697,14.778790,1.018296,-262.348663,294.500458,0.000000
114.560005,65.209869,-262.304169,-0.000341,0.004009,0.101830,290.067993,14.776768,1.018296,-262.304169,294.500458,0.000000
114.910004,65.177094,-262.348663,-0.000345,0.004009,0.101830,289.922180,14.769341,1.018296,-262.348663,294.500458,0.000000
115.260002,65.210617,-262.393127,-0.000345,0.004010,0.101864,290.071320,14.776937,1.018643,-262.393127,294.500458,0.000000
115.610008,65.195709,-262.437622,-0.000354,0.004011,0.101873,290.005005,14.773559,1.018730,-262.437622,294.500458,0.000000
115.960007,65.198700,-262.393127,-0.000336,0.004011,0.101890,290.018311,14.774237,1.018903,-262.393127,294.500458,0.000000
116.310005,65.210236,-262.437622,-0.000354,0.004011,0.101890,290.069611,14.776851,1.018903,-262.437622,294.500458,0.000000
116.660004,65.199066,-262.437622,-0.000345,0.004011,0.101890,290.019928,14.774320,1.018903,-262.437622,294.500458,0.000000
117.010002,65.192734,-262.482086,-0.000354,0.004011,0.101890,289.991760,14.772885,1.018903,-262.482086,294.500458,0.000000
117.360008,65.170761,-262.482086,-0.000336,0.004011,0.101890,289.894012,14.767905,1.018903,-262.482086,294.500458,0.000000
117.710007,65.223267,-262.571045,-0.000345,0.004013,0.101925,290.127594,14.779803,1.019250,-262.571045,294.500458,0.000000
118.060005,65.209122,-262.571045,-0.000349,0.004013,0.101925,290.064667,14.776598,1.019250,-262.571045,294.500458,0.000000
118.410004,65.199432,-262.571045,-0.000349,0.004013,0.101925,290.021545,14.774403,1.019250,-262.571045,294.500458,0.000000
118.760002,65.187897,-262.615540,-0.000336,0.004013,0.101925,289.970245,14.771788,1.019250,-262.615540,294.500458,0.000000
119.110008,65.156250,-262.615540,-0.000349,0.004013,0.101925,289.829468,14.764617,1.019250,-262.615540,294.500458,0.000000
119.460007,65.175613,-262.571045,-0.000341,0.004013,0.101934,289.915619,14.769006,1.019337,-262.571045,294.500458,0.000000
119.810005,65.136505,-262.660004,-0.000341,0.004013,0.101934,289.741638,14.760143,1.019337,-262.660004,294.500458,0.000000
120.160004,65.284332,-262.704498,-0.000345,0.004016,0.102003,290.399200,14.793641,1.020031,-262.704498,294.500458,0.000000
120.510002,65.299973,-262.704498,-0.000336,0.004016,0.102003,290.468781,14.797185,1.020031,-262.704498,294.500458,0.000000
120.860008,65.300720,-262.704498,-0.000345,0.004016,0.102003,290.472107,14.797355,1.020031,-262.704498,294.500458,0.000000
121.210007,65.286194,-262.704498,-0.000332,0.004016,0.102003,290.407501,14.794064,1.020031,-262.704498,294.500458,0.000000
121.560005,65.278015,-262.704498,-0.000341,0.004016,0.102003,290.371124,14.792210,1.020031,-262.704498,294.500458,0.000000
121.910004,65.254929,-262.748993,-0.000366,0.004016,0.102003,290.268433,14.786978,1.020031,-262.748993,294.500458,0.000000
122.260002,65.222153,-262.793457,-0.000336,0.004016,0.102012,290.122620,14.779552,1.020118,-262.793457,294.500458,0.000000
122.610008,65.213593,-262.793457,-0.000354,0.004016,0.102012,290.084534,14.777611,1.020118,-262.793457,294.500458,0.000000
122.960007,65.186401,-262.837952,-0.000358,0.004016,0.102012,289.963593,14.771450,1.020118,-262.837952,294.500458,0.000000
123.310005,65.170761,-262.837952,-0.000341,0.004016,0.102012,289.894012,14.767905,1.020118,-262.837952,294.500458,0.000000
123.660004,65.162201,-262.837952,-0.000358,0.004016,0.102012,289.855957,14.765966,1.020118,-262.837952,294.500458,0.000000
124.010002,65.125702,-262.882416,-0.000349,0.004017,0.102020,289.693604,14.757695,1.020204,-262.882416,294.500458,0.000000
124.360008,65.126083,-262.926910,-0.000345,0.004017,0.102029,289.695282,14.757781,1.020291,-262.926910,294.500458,0.000000
124.710007,65.108948,-262.882416,-0.000336,0.004010,0.101856,289.619049,14.753899,1.018557,-262.882416,0.102029,0.000000
125.060005,64.941757,-262.926910,-0.000341,0.004005,0.101717,288.875366,14.716012,1.017169,-262.926910,0.101509,0.000000
125.410004,65.035599,-262.882416,-0.000332,0.003986,0.101249,289.292786,14.737277,1.012486,-262.882416,0.100928,0.000000
125.760010,64.883301,-262.926910,-0.000328,0.003967,0.100763,288.615326,14.702765,1.007630,-262.926910,0.100338,0.000000
126.110008,64.824829,-262.971375,-0.000341,0.003945,0.100199,288.355255,14.689516,1.001992,-262.971375,0.099757,0.000000
126.460007,64.812164,-262.971375,-0.000328,0.003930,0.099818,288.298920,14.686646,0.998177,-262.971375,0.099176,0.000000
126.810005,64.730621,-263.015869,-0.000349,0.003899,0.099037,287.936188,14.668168,0.990372,-263.015869,0.098595,0.000000
127.160004,64.731735,-263.015869,-0.000336,0.003881,0.098578,287.941132,14.668421,0.985775,-263.015869,0.098005,0.000000
127.510010,64.694870,-263.015869,-0.000332,0.003854,0.097901,287.777161,14.660068,0.979011,-263.015869,0.097424,0.000000
127.860008,64.635300,-263.060333,-0.000341,0.003836,0.097433,287.512177,14.646568,0.974328,-263.060333,0.096843,0.000000
128.210007,64.606995,-263.015869,-0.000345,0.003816,0.096930,287.386261,14.640154,0.969298,-263.015869,0.096253,0.000000
128.560013,64.551880,-263.015869,-0.000323,0.003797,0.096444,287.141113,14.627665,0.964442,-263.015869,0.095672,0.000000
128.910004,64.351547,-263.060333,-0.000341,0.003774,0.095863,286.249969,14.582269,0.958631,-263.060333,0.095091,0.000000
129.260010,63.761337,-263.104828,-0.000323,0.003745,0.095135,283.624603,14.448525,0.951347,-263.104828,0.094510,0.000000
129.610001,62.921638,-263.149292,-0.000332,0.003725,0.094614,279.889435,14.258246,0.946143,-263.149292,0.093921,0.000000
129.960007,61.854416,-263.104828,-0.000310,0.003702,0.094033,275.142181,14.016411,0.940333,-263.104828,0.093340,0.000000
130.310013,60.754059,-263.193787,-0.000315,0.003685,0.093591,270.247559,13.767067,0.935910,-263.193787,0.092758,0.000000
130.660004,59.631355,-263.149292,-0.000315,0.003668,0.093166,265.253510,13.512659,0.931661,-263.149292,0.092177,0.000000
131.010010,58.562271,-263.193787,-0.000302,0.003654,0.092819,260.497986,13.270400,0.928192,-263.193787,0.091588,0.000000
131.360001,56.058815,-263.149292,-0.000302,0.003623,0.092013,249.362061,12.703110,0.920126,-263.149292,0.091007,0.000000
131.710007,54.264725,-263.193787,-0.000310,0.003602,0.091492,241.381546,12.296562,0.914923,-263.193787,0.090426,0.000000
132.060013,51.407509,-263.149292,-0.000315,0.003572,0.090729,228.672028,11.649109,0.907291,-263.149292,0.089836,0.000000
132.410004,49.275299,-263.193787,-0.000315,0.003554,0.090261,219.187485,11.165943,0.902609,-263.193787,0.089255,0.000000
132.760010,47.319229,-263.193787,-0.000306,0.003536,0.089819,210.486450,10.722691,0.898186,-263.193787,0.088674,0.000000
133.110001,44.595695,-263.193787,-0.000302,0.003511,0.089185,198.371567,10.105529,0.891855,-263.193787,0.088093,0.000000
133.460007,41.831947,-263.238281,-0.000315,0.003486,0.088535,186.077789,9.479255,0.885351,-263.238281,0.087503,0.000000
133.810013,40.215111,-263.282745,-0.000302,0.003470,0.088127,178.885742,9.112874,0.881275,-263.282745,0.086922,0.000000
134.160004,36.130554,-263.282745,-0.000306,0.003431,0.087156,160.716736,8.187301,0.871562,-263.282745,0.086341,0.000000
134.510010,34.801933,-263.282745,-0.000319,0.003419,0.086835,154.806732,7.886231,0.868353,-263.282745,0.085760,0.000000
134.860001,31.856834,-263.282745,-0.000328,0.003391,0.086124,141.706284,7.218862,0.861242,-263.282745,0.085170,0.000000
135.210007,29.455032,-263.327240,-0.000315,0.003366,0.085500,131.022522,6.674606,0.854998,-263.327240,0.084589,0.000000
135.560013,27.401024,-263.327240,-0.000323,0.003351,0.085118,121.885841,6.209161,0.851182,-263.327240,0.084008,0.000000
135.910004,23.998657,-263.416199,-0.000328,0.003319,0.084312,106.751358,5.438173,0.843117,-263.416199,0.083427,0.000000
136.260010,22.146111,-263.371704,-0.000345,0.003302,0.083869,98.510818,5.018380,0.838694,-263.371704,0.082837,0.000000
136.610001,20.177376,-263.371704,-0.000341,0.003284,0.083401,89.753448,4.572259,0.834011,-263.371704,0.082256,0.000000
136.960007,17.523849,-263.416199,-0.000349,0.003259,0.082777,77.949974,3.970961,0.827767,-263.416199,0.081675,0.000000
137.310013,14.440231,-263.416199,-0.000349,0.003231,0.082066,64.233360,3.272203,0.820656,-263.416199,0.081086,0.000000
137.660004,11.295174,-263.460663,-0.000341,0.003197,0.081198,50.243443,2.559523,0.811983,-263.460663,0.080505,0.000000
138.010010,9.380806,-263.505157,-0.000362,0.003181,0.080799,41.727909,2.125721,0.807994,-263.505157,0.079924,0.000000
138.360001,8.004143,-263.460663,-0.000375,0.003170,0.080522,35.604206,1.813765,0.805219,-263.460663,0.079342,0.000000
138.710007,3.772507,-263.460663,-0.000366,0.003131,0.079516,16.780949,0.854862,0.795159,-263.460663,0.078753,0.000000
139.060013,2.002243,-263.549622,-0.000379,0.003111,0.079030,8.906422,0.453715,0.790303,-263.549622,0.078172,0.000000
139.410004,0.120277,-263.549622,-0.000379,0.003092,0.078536,0.535021,0.027255,0.785360,-263.549622,0.077591,0.000000
139.760010,-2.476276,-263.549622,-0.000379,0.003063,0.077799,-11.015028,-0.561132,0.777988,-263.549622,0.077010,0.000000
140.110001,-2.704914,-263.549622,-0.000401,0.003051,0.077495,-12.032059,-0.612942,0.774953,-263.549622,0.076420,0.000000
140.460007,-0.757408,-263.638611,-0.000427,0.003029,0.076949,-3.369120,-0.171631,0.769489,-263.638611,0.075839,0.000000
140.810013,-0.152672,-263.638611,-0.000496,0.002997,0.076134,-0.679118,-0.034596,0.761337,-263.638611,0.075258,0.000000
141.160004,-0.088997,-263.638611,-0.000526,0.002978,0.075631,-0.395878,-0.020167,0.756308,-263.638611,0.074668,0.000000
141.510010,-0.111343,-263.638611,-0.000582,0.002948,0.074868,-0.495280,-0.025231,0.748676,-263.638611,0.074087,0.000000
141.860001,-0.016754,-263.727570,-0.000625,0.002929,0.074399,-0.074526,-0.003797,0.743993,-263.727570,0.073506,0.000000
142.210007,-0.005211,-263.594116,-0.000647,0.002921,0.074182,-0.023179,-0.001181,0.741825,-263.594116,0.072925,0.000000
142.560013,-0.030159,-263.683075,-0.000690,0.002878,0.073090,-0.134154,-0.006834,0.730898,-263.683075,0.072335,0.000000
142.910004,-0.021599,-263.727570,-0.000729,0.002860,0.072639,-0.096076,-0.004894,0.726388,-263.727570,0.071754,0.000000
143.260010,-0.022713,-263.727570,-0.000755,0.002843,0.072223,-0.101031,-0.005147,0.722226,-263.727570,0.071173,0.000000
143.610001,-0.010056,-263.727570,-0.000819,0.002812,0.071425,-0.044729,-0.002279,0.714247,-263.727570,0.070592,0.000000
143.960007,0.022339,-263.772034,-0.000845,0.002796,0.071008,0.099368,0.005062,0.710084,-263.772034,0.070002,0.000000
144.310013,0.002609,-263.816528,-0.000888,0.002773,0.070445,0.011607,0.000591,0.704447,-263.816528,0.069421,0.000000
144.660004,0.026062,-263.816528,-0.000931,0.002747,0.069786,0.115930,0.005906,0.697856,-263.816528,0.068840,0.000000
145.010010,0.011917,-263.860992,-0.000992,0.002726,0.069239,0.053010,0.002700,0.692393,-263.860992,0.069049,0.000000
145.100006,0.023087,-263.860992,-0.000996,0.002726,0.069239,0.102694,0.005231,0.692393,-263.860992,0.069049,0.000000