File: Data/compression 32/AutoNoHeating-15-32-reverse-1-4ring_11142024_175357.csv
Time (sec),S:Load (lbs),S:HL1 (DIM),S:LVDT (in),S:Position (in),Ch:Position (mm),Ch:Load (N),Ch:Stress (MPa),Ch:Strain (mm/mm),Ch:HL1 (DIM),Set Point (),Cycles ()
0.110000,-0.043198,-286.145966,-0.012128,-0.007170,-0.182109,-0.192153,-0.009789,-1.821087,-286.145966,-0.181970,0.000000
0.480000,-0.041710,-286.190430,-0.012128,-0.007096,-0.180227,-0.185535,-0.009452,-1.802269,-286.190430,-0.179663,0.000000
0.850000,-0.070755,-286.190430,-0.012021,-0.006873,-0.174564,-0.314734,-0.016033,-1.745639,-286.190430,-0.173506,0.000000
1.220000,-0.080063,-286.057007,-0.011753,-0.006631,-0.168433,-0.356137,-0.018143,-1.684326,-286.057007,-0.167331,0.000000
1.590000,-0.041710,-286.190430,-0.011520,-0.006389,-0.162293,-0.185535,-0.009452,-1.622926,-286.190430,-0.161174,0.000000
1.960000,-0.045433,-286.234924,-0.011266,-0.006145,-0.156075,-0.202096,-0.010295,-1.560746,-286.234924,-0.155017,0.000000
2.330000,-0.020851,-286.234924,-0.011029,-0.005902,-0.149909,-0.092750,-0.004725,-1.499086,-286.234924,-0.148842,0.000000
2.700000,-0.044312,-286.234924,-0.010774,-0.005656,-0.143665,-0.197107,-0.010041,-1.436646,-286.234924,-0.142685,0.000000
3.070000,-0.068520,-286.279388,-0.010533,-0.005424,-0.137759,-0.304790,-0.015527,-1.377588,-286.279388,-0.136527,0.000000
3.440000,0.005959,-286.190430,-0.010300,-0.005182,-0.131628,0.026505,0.001350,-1.316275,-286.190430,-0.130353,0.000000
3.810000,0.023087,-286.190430,-0.010054,-0.004939,-0.125453,0.102694,0.005231,-1.254529,-286.190430,-0.124195,0.000000
4.180000,-0.012665,-286.279388,-0.009783,-0.004694,-0.119226,-0.056336,-0.002870,-1.192262,-286.279388,-0.118021,0.000000
4.550000,-0.036118,-286.279388,-0.009533,-0.004448,-0.112991,-0.160659,-0.008184,-1.129908,-286.279388,-0.111863,0.000000
4.920000,-0.054741,-286.323883,-0.009291,-0.004210,-0.106929,-0.243500,-0.012404,-1.069289,-286.323883,-0.105706,0.000000
5.290000,-0.106125,-286.234924,-0.009041,-0.003968,-0.100789,-0.472067,-0.024048,-1.007890,-286.234924,-0.099532,0.000000
5.660000,-0.024208,-286.368378,-0.008800,-0.003721,-0.094502,-0.107683,-0.005486,-0.945016,-286.368378,-0.093374,0.000000
6.030000,-0.025696,-286.412842,-0.008550,-0.003476,-0.088301,-0.114301,-0.005823,-0.883009,-286.412842,-0.087200,0.000000
6.400000,0.010796,-286.368378,-0.008291,-0.003231,-0.082057,0.048021,0.002446,-0.820569,-286.368378,-0.081042,0.000000
6.770000,-0.024208,-286.412842,-0.008045,-0.002994,-0.076056,-0.107683,-0.005486,-0.760557,-286.412842,-0.074885,0.000000
7.140000,-0.043198,-286.368378,-0.007808,-0.002751,-0.069864,-0.192153,-0.009789,-0.698637,-286.368378,-0.068710,0.000000
7.510000,-0.010056,-286.412842,-0.007567,-0.002515,-0.063880,-0.044729,-0.002279,-0.638798,-286.412842,-0.062553,0.000000
7.880001,0.018616,-286.457336,-0.007308,-0.002268,-0.057601,0.082807,0.004218,-0.576011,-286.457336,-0.056378,0.000000
8.250000,0.006332,-286.501801,-0.007045,-0.002023,-0.051392,0.028168,0.001435,-0.513918,-286.501801,-0.050221,0.000000
8.620001,0.008934,-286.412842,-0.006786,-0.001779,-0.045182,0.039741,0.002024,-0.451825,-286.412842,-0.044064,0.000000
8.990001,-0.008194,-286.457336,-0.006545,-0.001537,-0.039042,-0.036449,-0.001857,-0.390425,-286.457336,-0.037889,0.000000
9.360001,-0.070007,-286.501801,-0.006303,-0.001294,-0.032868,-0.311408,-0.015864,-0.328679,-286.501801,-0.031732,0.000000
9.730000,-0.065536,-286.546295,-0.006058,-0.001052,-0.026719,-0.291521,-0.014851,-0.267192,-286.546295,-0.025557,0.000000
10.100000,-0.028297,-286.590759,-0.005808,-0.000808,-0.020527,-0.125873,-0.006412,-0.205272,-286.590759,-0.019400,0.000000
10.470000,0.045059,-286.501801,-0.005536,-0.000565,-0.014344,0.200433,0.010211,-0.143439,-286.501801,-0.013243,0.000000
10.840000,0.003723,-286.590759,-0.005290,-0.000326,-0.008282,0.016561,0.000844,-0.082820,-286.590759,-0.007068,0.000000
11.210001,-0.010796,-286.590759,-0.005053,-0.000082,-0.002081,-0.048021,-0.002446,-0.020813,-286.590759,-0.000911,0.000000
11.580001,0.040215,-286.635254,-0.004816,0.000155,0.003937,0.178883,0.009113,0.039372,-286.635254,0.005264,0.000000
11.950001,0.235710,-286.635254,-0.004721,-0.000005,-0.000139,1.048491,0.053413,-0.001388,-286.635254,0.000121,0.000000
12.320001,0.164589,-286.679718,-0.004712,-0.000005,-0.000139,0.732128,0.037296,-0.001388,-286.679718,0.000260,0.000000
12.690001,0.105011,-286.635254,-0.004730,-0.000001,-0.000035,0.467112,0.023796,-0.000347,-286.635254,0.000876,0.000000
13.060000,0.290825,-286.679718,-0.004708,0.000025,0.000642,1.293654,0.065902,0.006417,-286.679718,0.001492,0.000000
13.430000,0.452805,-286.724213,-0.004704,0.000041,0.001041,2.014175,0.102607,0.010407,-286.724213,0.002116,0.000000
13.800000,0.641228,-286.679718,-0.004678,0.000060,0.001526,2.852323,0.145304,0.015263,-286.679718,0.002732,0.000000
14.170001,1.027000,-286.679718,-0.004626,0.000100,0.002532,4.568326,0.232722,0.025323,-286.679718,0.003347,0.000000
14.540001,1.244843,-286.724213,-0.004635,0.000118,0.003001,5.537336,0.282085,0.030006,-286.724213,0.003963,0.000000
14.910001,1.486511,-286.768677,-0.004613,0.000139,0.003538,6.612332,0.336848,0.035383,-286.768677,0.004579,0.000000
15.280001,1.981766,-286.768677,-0.004600,0.000167,0.004241,8.815334,0.449075,0.042407,-286.768677,0.005195,0.000000
15.650001,2.325462,-286.813171,-0.004579,0.000188,0.004778,10.344173,0.526957,0.047784,-286.813171,0.005810,0.000000
16.020000,2.811783,-286.768677,-0.004557,0.000216,0.005481,12.507435,0.637159,0.054809,-286.768677,0.006426,0.000000
16.390001,3.210220,-286.768677,-0.004531,0.000240,0.006105,14.279774,0.727446,0.061053,-286.768677,0.007042,0.000000
16.760000,3.588554,-286.768677,-0.004510,0.000265,0.006738,15.962687,0.813178,0.067383,-286.768677,0.007666,0.000000
17.130001,4.010826,-286.857666,-0.004493,0.000290,0.007354,17.841045,0.908866,0.073541,-286.857666,0.008282,0.000000
17.500000,4.411125,-286.857666,-0.004475,0.000308,0.007814,19.621664,0.999575,0.078137,-286.857666,0.008898,0.000000
17.870001,5.085121,-286.857666,-0.004449,0.000337,0.008560,22.619749,1.152305,0.085595,-286.857666,0.009513,0.000000
18.240002,5.358070,-286.902130,-0.004428,0.000363,0.009210,23.833887,1.214156,0.092099,-286.902130,0.010129,0.000000
18.610001,5.752785,-286.902130,-0.004411,0.000383,0.009722,25.589664,1.303600,0.097216,-286.902130,0.010745,0.000000
18.980001,6.259956,-286.946625,-0.004389,0.000410,0.010424,27.845676,1.418526,0.104240,-286.946625,0.011361,0.000000
19.350000,6.449493,-286.991089,-0.004363,0.000423,0.010754,28.688780,1.461476,0.107536,-286.991089,0.011976,0.000000
19.720001,7.445587,-286.991089,-0.004342,0.000462,0.011742,33.119625,1.687194,0.117422,-286.991089,0.012592,0.000000
20.090000,7.698059,-286.902130,-0.004329,0.000486,0.012332,34.242676,1.744405,0.123320,-286.902130,0.013217,0.000000
20.460001,8.021278,-286.991089,-0.004312,0.000506,0.012861,35.680428,1.817648,0.128610,-286.991089,0.013832,0.000000
20.830002,8.696754,-286.991089,-0.004273,0.000536,0.013615,38.685097,1.970713,0.136154,-286.991089,0.014448,0.000000
21.200001,8.697502,-287.035583,-0.004251,0.000550,0.013980,38.688423,1.970882,0.139797,-287.035583,0.015064,0.000000
21.570002,9.142113,-286.991089,-0.004260,0.000570,0.014483,40.666149,2.071632,0.144827,-286.991089,0.015679,0.000000
21.940001,9.918884,-286.991089,-0.004217,0.000606,0.015402,44.121403,2.247651,0.154019,-286.991089,0.016295,0.000000
22.310001,10.088318,-287.035583,-0.004199,0.000626,0.015905,44.875080,2.286045,0.159049,-287.035583,0.016911,0.000000
22.680000,10.740341,-287.124542,-0.004191,0.000655,0.016642,47.775425,2.433796,0.166421,-287.124542,0.017527,0.000000
23.050001,10.905670,-287.124542,-0.004161,0.000674,0.017128,48.510845,2.471260,0.171277,-287.124542,0.018142,0.000000
23.420002,11.053131,-287.080048,-0.004135,0.000691,0.017553,49.166782,2.504675,0.175526,-287.080048,0.018767,0.000000
23.790001,12.127800,-287.124542,-0.004122,0.000728,0.018498,53.947147,2.748199,0.184979,-287.124542,0.019382,0.000000
24.160002,12.049225,-287.124542,-0.004092,0.000748,0.018992,53.597630,2.730393,0.189922,-287.124542,0.019998,0.000000
24.530001,12.543365,-287.213501,-0.004066,0.000774,0.019660,55.795677,2.842367,0.196600,-287.213501,0.020614,0.000000
24.900002,13.043465,-287.213501,-0.004049,0.000802,0.020380,58.020229,2.955691,0.203798,-287.213501,0.021230,0.000000
25.270000,13.067291,-287.213501,-0.004049,0.000818,0.020770,58.126213,2.961090,0.207701,-287.213501,0.021845,0.000000
25.640001,13.669792,-287.213501,-0.004014,0.000846,0.021499,60.806271,3.097619,0.214985,-287.213501,0.022461,0.000000
26.010002,13.896568,-287.257996,-0.004010,0.000871,0.022123,61.815022,3.149007,0.221229,-287.257996,0.023077,0.000000
26.380001,14.112167,-287.257996,-0.003992,0.000892,0.022669,62.774055,3.197863,0.226693,-287.257996,0.023701,0.000000
26.750002,14.738129,-287.302460,-0.003949,0.000922,0.023424,65.558472,3.339708,0.234238,-287.302460,0.024317,0.000000
27.120001,14.809250,-287.213501,-0.003932,0.000943,0.023961,65.874832,3.355824,0.239614,-287.213501,0.024933,0.000000
27.490002,15.173431,-287.346954,-0.003915,0.000966,0.024542,67.494797,3.438349,0.245425,-287.346954,0.025548,0.000000
27.860001,15.606133,-287.346954,-0.003911,0.000993,0.025219,69.419548,3.536400,0.252189,-287.346954,0.026164,0.000000
28.230001,15.654167,-287.346954,-0.003911,0.001017,0.025835,69.633217,3.547285,0.258347,-287.346954,0.026780,0.000000
28.600002,16.135269,-287.435913,-0.003872,0.001044,0.026520,71.773262,3.656304,0.265198,-287.435913,0.027396,0.000000
28.970001,15.958023,-287.391418,-0.003850,0.001060,0.026919,70.984833,3.616140,0.269187,-287.391418,0.028011,0.000000
29.340002,16.568710,-287.391418,-0.003833,0.001091,0.027708,73.701302,3.754524,0.277079,-287.391418,0.028627,0.000000
29.710001,16.821182,-287.391418,-0.003803,0.001116,0.028350,74.824356,3.811734,0.283496,-287.391418,0.029252,0.000000
30.080002,16.831238,-287.435913,-0.003811,0.001139,0.028931,74.869087,3.814013,0.289306,-287.435913,0.029867,0.000000
30.450001,17.058754,-287.435913,-0.003786,0.001161,0.029494,75.881126,3.865569,0.294943,-287.435913,0.030483,0.000000
30.820002,17.354042,-287.480377,-0.003760,0.001184,0.030067,77.194633,3.932482,0.300667,-287.480377,0.031099,0.000000
31.190001,17.433731,-287.435913,-0.003747,0.001202,0.030535,77.549110,3.950540,0.305350,-287.435913,0.031714,0.000000
31.560001,18.164330,-287.435913,-0.003734,0.001236,0.031394,80.798973,4.116096,0.313936,-287.435913,0.032330,0.000000
31.930002,18.114059,-287.524872,-0.003725,0.001259,0.031983,80.575363,4.104704,0.319833,-287.524872,0.032946,0.000000
32.300003,18.150177,-287.524872,-0.003717,0.001280,0.032504,80.736023,4.112889,0.325036,-287.524872,0.033562,0.000000
32.670002,18.635750,-287.524872,-0.003686,0.001309,0.033249,82.895958,4.222921,0.332494,-287.524872,0.034177,0.000000
33.040001,18.560158,-287.524872,-0.003691,0.001327,0.033718,82.559708,4.205792,0.337177,-287.524872,0.034802,0.000000
33.410000,19.354431,-287.569336,-0.003660,0.001360,0.034533,86.092812,4.385777,0.345329,-287.569336,0.035417,0.000000
33.780003,19.287033,-287.613831,-0.003630,0.001382,0.035114,85.793007,4.370504,0.351140,-287.613831,0.036033,0.000000
34.150002,19.078499,-287.613831,-0.003626,0.001400,0.035565,84.865402,4.323249,0.355649,-287.613831,0.036649,0.000000
34.520000,19.097862,-287.613831,-0.003600,0.001429,0.036285,84.951530,4.327638,0.362847,-287.613831,0.037265,0.000000
34.890003,19.476196,-287.569336,-0.003591,0.001450,0.036831,86.634445,4.413369,0.368311,-287.569336,0.037880,0.000000
35.260002,20.225784,-287.613831,-0.003579,0.001481,0.037620,89.968781,4.583228,0.376202,-287.613831,0.038496,0.000000
35.630001,20.397072,-287.702789,-0.003557,0.001506,0.038253,90.730705,4.622043,0.382533,-287.702789,0.039112,0.000000
36.000000,20.086884,-287.747284,-0.003544,0.001522,0.038670,89.350922,4.551753,0.386696,-287.747284,0.039728,0.000000
36.370003,20.550491,-287.702789,-0.003523,0.001551,0.039398,91.413155,4.656808,0.393981,-287.702789,0.040352,0.000000
36.740002,20.408615,-287.702789,-0.003514,0.001568,0.039823,90.782051,4.624658,0.398230,-287.702789,0.040968,0.000000
37.110001,21.088570,-287.747284,-0.003492,0.001598,0.040577,93.806641,4.778738,0.405775,-287.747284,0.041583,0.000000
37.480003,21.148148,-287.791748,-0.003475,0.001621,0.041185,94.071655,4.792239,0.411845,-287.791748,0.042199,0.000000
37.850002,21.447906,-287.836243,-0.003449,0.001648,0.041852,95.405052,4.860165,0.418523,-287.836243,0.042815,0.000000
38.220001,21.975929,-287.791748,-0.003441,0.001675,0.042546,97.753815,4.979816,0.425461,-287.791748,0.043431,0.000000
38.590000,21.683990,-287.791748,-0.003419,0.001695,0.043040,96.455208,4.913662,0.430404,-287.791748,0.044046,0.000000
38.960003,21.693298,-287.836243,-0.003406,0.001713,0.043509,96.496613,4.915771,0.435087,-287.836243,0.044662,0.000000
39.330002,22.371765,-287.925201,-0.003385,0.001743,0.044281,99.514580,5.069514,0.442805,-287.925201,0.045278,0.000000
39.700001,22.652534,-287.880707,-0.003380,0.001770,0.044948,100.763504,5.133138,0.449483,-287.880707,0.045902,0.000000
40.070004,23.112785,-287.836243,-0.003363,0.001799,0.045703,102.810806,5.237432,0.457028,-287.836243,0.046518,0.000000
40.440002,22.770203,-287.880707,-0.003350,0.001816,0.046128,101.286919,5.159801,0.461277,-287.880707,0.047134,0.000000
40.810001,23.093422,-287.925201,-0.003341,0.001840,0.046726,102.724670,5.233044,0.467261,-287.925201,0.047749,0.000000
41.180000,23.613251,-288.014160,-0.003311,0.001868,0.047455,105.036987,5.350839,0.474546,-288.014160,0.048365,0.000000
41.550003,23.663155,-287.969666,-0.003303,0.001892,0.048053,105.258972,5.362147,0.480530,-287.969666,0.048981,0.000000
41.920002,23.899979,-287.969666,-0.003277,0.001916,0.048677,106.312416,5.415812,0.486774,-287.969666,0.049597,0.000000
42.290001,24.045578,-288.014160,-0.003285,0.001938,0.049215,106.960075,5.448806,0.492151,-288.014160,0.050212,0.000000
42.660004,24.136436,-287.969666,-0.003268,0.001961,0.049805,107.364235,5.469395,0.498048,-287.969666,0.050828,0.000000
43.030003,25.045769,-288.058624,-0.003251,0.001991,0.050559,111.409142,5.675452,0.505593,-288.058624,0.051452,0.000000
43.400002,24.887138,-288.103119,-0.003234,0.002015,0.051175,110.703522,5.639506,0.511750,-288.103119,0.052068,0.000000
43.770000,24.659248,-288.014160,-0.003225,0.002032,0.051617,109.689812,5.587865,0.516173,-288.014160,0.052684,0.000000
44.140003,25.204399,-288.103119,-0.003212,0.002061,0.052346,112.114769,5.711399,0.523457,-288.103119,0.053300,0.000000
44.510002,24.802238,-288.103119,-0.003203,0.002080,0.052840,110.325867,5.620268,0.528401,-288.103119,0.053915,0.000000
44.880001,24.897568,-288.147614,-0.003178,0.002097,0.053256,110.749916,5.641869,0.532563,-288.147614,0.054531,0.000000
45.250004,26.309975,-288.147614,-0.003169,0.002137,0.054280,117.032616,5.961926,0.542797,-288.147614,0.055147,0.000000
45.620003,25.726837,-288.147614,-0.003147,0.002153,0.054679,114.438690,5.829785,0.546786,-288.147614,0.055763,0.000000
45.990002,26.222839,-288.103119,-0.003139,0.002180,0.055364,116.645012,5.942181,0.553637,-288.103119,0.056378,0.000000
46.360001,26.371788,-288.236572,-0.003139,0.002203,0.055953,117.307571,5.975933,0.559534,-288.236572,0.057003,0.000000
46.730003,25.997925,-288.236572,-0.003113,0.002223,0.056474,115.644547,5.891214,0.564737,-288.236572,0.057618,0.000000
47.100002,26.955673,-288.281036,-0.003087,0.002254,0.057254,119.904823,6.108243,0.572542,-288.281036,0.058234,0.000000
47.470001,27.103874,-288.236572,-0.003083,0.002277,0.057827,120.564056,6.141826,0.578266,-288.236572,0.058850,0.000000
47.840004,26.891251,-288.236572,-0.003065,0.002296,0.058312,119.618256,6.093645,0.583123,-288.236572,0.059466,0.000000
48.210003,27.698181,-288.325531,-0.003057,0.002328,0.059136,123.207664,6.276497,0.591361,-288.325531,0.060081,0.000000
48.580002,27.244629,-288.325531,-0.003044,0.002344,0.059535,121.190163,6.173721,0.595350,-288.325531,0.060697,0.000000
48.950001,27.679932,-288.281036,-0.003035,0.002372,0.060246,123.126488,6.272362,0.602462,-288.281036,0.061313,0.000000
49.320004,28.219505,-288.236572,-0.003027,0.002399,0.060940,125.526627,6.394631,0.609399,-288.236572,0.061937,0.000000
49.690002,28.208328,-288.281036,-0.003027,0.002423,0.061538,125.476913,6.392098,0.615383,-288.281036,0.062553,0.000000
50.060001,28.536018,-288.414490,-0.003009,0.002449,0.062197,126.934547,6.466354,0.621974,-288.414490,0.063169,0.000000
50.430004,28.495804,-288.414490,-0.002988,0.002471,0.062761,126.755669,6.457242,0.627611,-288.414490,0.063784,0.000000
50.800003,29.027550,-288.458954,-0.002975,0.002501,0.063516,129.120987,6.577737,0.635156,-288.458954,0.064400,0.000000
51.170002,28.782158,-288.414490,-0.002966,0.002523,0.064097,128.029434,6.522130,0.640967,-288.414490,0.065016,0.000000
51.540001,28.722580,-288.503448,-0.002953,0.002545,0.064634,127.764420,6.508630,0.646343,-288.503448,0.065632,0.000000
51.910004,28.983986,-288.414490,-0.002953,0.002570,0.065267,128.927216,6.567865,0.652674,-288.414490,0.066247,0.000000
52.280003,28.415741,-288.414490,-0.002932,0.002585,0.065658,126.399529,6.439099,0.656577,-288.414490,0.066863,0.000000
52.650002,29.357475,-288.458954,-0.002923,0.002618,0.066508,130.588577,6.652499,0.665075,-288.458954,0.067488,0.000000
53.020004,29.706757,-288.503448,-0.002923,0.002646,0.067201,132.142258,6.731647,0.672013,-288.503448,0.068103,0.000000
53.390003,29.187294,-288.503448,-0.002910,0.002665,0.067696,129.831573,6.613935,0.676956,-288.503448,0.068719,0.000000
53.760002,29.324699,-288.592407,-0.002902,0.002689,0.068311,130.442780,6.645072,0.683114,-288.592407,0.069335,0.000000
54.130001,29.265495,-288.547943,-0.002897,0.002712,0.068875,130.179428,6.631656,0.688751,-288.547943,0.069950,0.000000
54.500004,28.648849,-288.547943,-0.002871,0.002727,0.069265,127.436447,6.491922,0.692653,-288.547943,0.070566,0.000000
54.870003,30.045990,-288.547943,-0.002854,0.002766,0.070263,133.651245,6.808519,0.702626,-288.547943,0.071182,0.000000
55.240002,29.345558,-288.636902,-0.002837,0.002785,0.070740,130.535568,6.649799,0.707396,-288.636902,0.071798,0.000000
55.610004,28.984726,-288.636902,-0.002837,0.002803,0.071199,128.930496,6.568033,0.711992,-288.636902,0.072413,0.000000
55.980003,29.723145,-288.636902,-0.002815,0.002835,0.071997,132.215149,6.735361,0.719971,-288.636902,0.073038,0.000000
56.350002,29.370880,-288.636902,-0.002820,0.002851,0.072413,130.648193,6.655537,0.724133,-288.636902,0.073653,0.000000
56.720001,31.010063,-288.681366,-0.002802,0.002890,0.073411,137.939651,7.026981,0.734107,-288.681366,0.074269,0.000000
57.090004,30.335320,-288.725861,-0.002785,0.002910,0.073905,134.938248,6.874082,0.739050,-288.725861,0.074885,0.000000
57.460003,30.032211,-288.725861,-0.002768,0.002931,0.074460,133.589951,6.805397,0.744600,-288.725861,0.075501,0.000000
57.830002,30.636200,-288.636902,-0.002759,0.002959,0.075154,136.276627,6.942262,0.751538,-288.636902,0.076116,0.000000
58.200005,29.944702,-288.770325,-0.002734,0.002977,0.075622,133.200684,6.785566,0.756221,-288.770325,0.076732,0.000000
58.570004,31.231247,-288.814819,-0.002751,0.003006,0.076359,138.923523,7.077102,0.763592,-288.814819,0.077348,0.000000
58.940002,31.449463,-288.770325,-0.002729,0.003029,0.076940,139.894196,7.126550,0.769403,-288.770325,0.077964,0.000000
59.310001,31.553352,-288.859283,-0.002712,0.003053,0.077539,140.356323,7.150092,0.775386,-288.859283,0.078588,0.000000
59.680004,32.571419,-288.770325,-0.002695,0.003083,0.078302,144.884903,7.380789,0.783018,-288.770325,0.079204,0.000000
60.050003,32.537529,-288.814819,-0.002695,0.003104,0.078831,144.734161,7.373109,0.788308,-288.814819,0.079819,0.000000
60.420002,33.475540,-288.903778,-0.002699,0.003131,0.079516,148.906647,7.585666,0.795159,-288.903778,0.080435,0.000000
60.790005,33.522461,-288.903778,-0.002660,0.003152,0.080071,149.115356,7.596298,0.800709,-288.903778,0.081051,0.000000
61.160004,34.036705,-288.903778,-0.002630,0.003174,0.080617,151.402832,7.712828,0.806173,-288.903778,0.081667,0.000000
61.530003,34.815338,-288.903778,-0.002634,0.003201,0.081311,154.866364,7.889268,0.813111,-288.903778,0.082282,0.000000
61.900002,34.872307,-288.903778,-0.002630,0.003220,0.081779,155.119766,7.902177,0.817794,-288.903778,0.082898,0.000000
62.270004,35.385063,-288.948273,-0.002626,0.003240,0.082291,157.400620,8.018370,0.822910,-288.948273,0.083514,0.000000
62.640003,37.653557,-288.948273,-0.002587,0.003279,0.083280,167.491379,8.532417,0.832797,-288.948273,0.084138,0.000000
63.010002,37.590256,-288.992737,-0.002583,0.003298,0.083757,167.209808,8.518074,0.837567,-288.992737,0.084754,0.000000
63.380005,38.307076,-288.992737,-0.002578,0.003322,0.084381,170.398376,8.680508,0.843811,-288.992737,0.085370,0.000000
63.750004,38.785194,-289.037231,-0.002548,0.003345,0.084962,172.525162,8.788850,0.849621,-289.037231,0.085985,0.000000
64.120003,39.004150,-289.037231,-0.002539,0.003364,0.085448,173.499130,8.838467,0.854477,-289.037231,0.086601,0.000000
64.490005,40.830643,-289.081696,-0.002535,0.003397,0.086280,181.623764,9.252356,0.862803,-289.081696,0.087217,0.000000
64.860001,41.582832,-289.037231,-0.002509,0.003421,0.086887,184.969681,9.422805,0.868873,-289.037231,0.087833,0.000000
65.230003,42.386040,-289.081696,-0.002492,0.003446,0.087529,188.542526,9.604815,0.875291,-289.081696,0.088448,0.000000
65.600006,42.823578,-289.081696,-0.002492,0.003465,0.088015,190.488785,9.703961,0.880147,-289.081696,0.089064,0.000000
65.970001,43.551193,-289.170654,-0.002483,0.003487,0.088561,193.725388,9.868842,0.885611,-289.170654,0.089688,0.000000
66.340004,45.125214,-289.215149,-0.002466,0.003519,0.089376,200.726974,10.225520,0.893763,-289.215149,0.090304,0.000000
66.710007,45.894905,-289.170654,-0.002432,0.003541,0.089940,204.150726,10.399935,0.899400,-289.170654,0.090920,0.000000
67.080002,46.580818,-289.170654,-0.002445,0.003561,0.090460,207.201828,10.555364,0.904603,-289.170654,0.091536,0.000000
67.450005,47.920609,-289.215149,-0.002423,0.003590,0.091197,213.161514,10.858965,0.911975,-289.215149,0.092151,0.000000
67.820000,48.303780,-289.215149,-0.002406,0.003611,0.091726,214.865936,10.945793,0.917265,-289.215149,0.092767,0.000000
68.190002,49.681564,-289.215149,-0.002397,0.003634,0.092299,220.994629,11.258003,0.922988,-289.215149,0.093383,0.000000
68.560005,51.185204,-289.215149,-0.002389,0.003663,0.093036,227.683151,11.598733,0.930360,-289.215149,0.093999,0.000000
68.930000,52.137360,-289.215149,-0.002376,0.003684,0.093565,231.918564,11.814494,0.935650,-289.215149,0.094614,0.000000
69.300003,53.093613,-289.304108,-0.002354,0.003706,0.094137,236.172180,12.031184,0.941374,-289.304108,0.095239,0.000000
69.670006,54.410316,-289.348572,-0.002358,0.003728,0.094692,242.029175,12.329554,0.946924,-289.348572,0.095854,0.000000
70.040001,54.860893,-289.304108,-0.002341,0.003744,0.095091,244.033447,12.431656,0.950913,-289.304108,0.096470,0.000000
70.410004,57.453346,-289.304108,-0.002320,0.003784,0.096123,255.565247,13.019114,0.961233,-289.304108,0.097086,0.000000
70.780006,58.540672,-289.348572,-0.002302,0.003805,0.096644,260.401917,13.265506,0.966436,-289.348572,0.097702,0.000000
71.150002,59.772110,-289.393066,-0.002294,0.003828,0.097225,265.879639,13.544554,0.972247,-289.393066,0.098317,0.000000
71.520004,61.345009,-289.437561,-0.002289,0.003854,0.097884,272.876221,13.900978,0.978838,-289.437561,0.098933,0.000000
71.890007,62.360840,-289.437561,-0.002264,0.003874,0.098395,277.394867,14.131168,0.983954,-289.437561,0.099549,0.000000
72.260002,64.524323,-289.348572,-0.002268,0.003904,0.099167,287.018524,14.621421,0.991673,-289.348572,0.100165,0.000000
72.630005,65.717041,-289.348572,-0.002246,0.003927,0.099740,292.324005,14.891694,0.997396,-289.348572,0.100789,0.000000
73.000000,65.572922,-289.482025,-0.002255,0.003926,0.099731,291.682922,14.859036,0.997310,-289.482025,0.017508,0.000000
73.370003,65.721878,-289.482025,-0.002246,0.003940,0.100078,292.345520,14.892791,1.000779,-289.482025,294.500458,0.000000
73.740005,65.091827,-289.526520,-0.002220,0.003945,0.100208,289.542908,14.750019,1.002079,-289.526520,294.500458,0.000000
74.110001,65.146927,-289.482025,-0.002233,0.003952,0.100381,289.787994,14.762505,1.003814,-289.482025,294.500458,0.000000
74.480003,65.188644,-289.526520,-0.002229,0.003960,0.100581,289.973572,14.771957,1.005808,-289.526520,294.500458,0.000000
74.850006,65.288803,-289.526520,-0.002212,0.003966,0.100746,290.419098,14.794654,1.007456,-289.526520,294.500458,0.000000
75.220001,65.131668,-289.615479,-0.002229,0.003969,0.100815,289.720123,14.759047,1.008150,-289.615479,294.500458,0.000000
75.590004,65.240021,-289.615479,-0.002207,0.003976,0.100988,290.202118,14.783600,1.009884,-289.615479,294.500458,0.000000
75.960007,65.172256,-289.526520,-0.002199,0.003977,0.101014,289.900665,14.768245,1.010144,-289.526520,294.500458,0.000000
76.330002,65.082886,-289.615479,-0.002199,0.003980,0.101092,289.503143,14.747993,1.010925,-289.615479,294.500458,0.000000
76.700005,64.984573,-289.615479,-0.002203,0.003982,0.101145,289.065826,14.725715,1.011445,-289.615479,294.500458,0.000000
77.070007,64.796158,-289.659943,-0.002203,0.003984,0.101188,288.227692,14.683020,1.011879,-289.659943,294.500458,0.000000
77.440002,65.761353,-289.704437,-0.002203,0.003994,0.101448,292.521118,14.901735,1.014481,-289.704437,294.500458,0.000000
77.810005,65.508514,-289.704437,-0.002195,0.003994,0.101448,291.396423,14.844441,1.014481,-289.704437,294.500458,0.000000
78.180000,65.253433,-289.615479,-0.002190,0.003994,0.101448,290.261780,14.786639,1.014481,-289.615479,294.500458,0.000000
78.550003,65.046768,-289.748901,-0.002182,0.003995,0.101474,289.342468,14.739808,1.014741,-289.748901,294.500458,0.000000
78.920006,64.873611,-289.748901,-0.002195,0.003996,0.101509,288.572235,14.700571,1.015088,-289.748901,294.500458,0.000000
79.290001,65.117523,-289.704437,-0.002177,0.004001,0.101613,289.657196,14.755842,1.016128,-289.704437,294.500458,0.000000
79.660004,64.968933,-289.748901,-0.002173,0.004001,0.101622,288.996246,14.722170,1.016215,-289.748901,294.500458,0.000000
80.030006,65.491379,-289.704437,-0.002177,0.004007,0.101786,291.320190,14.840559,1.017863,-289.704437,294.500458,0.000000
80.400002,65.312637,-289.837891,-0.002173,0.004007,0.101786,290.525116,14.800055,1.017863,-289.837891,294.500458,0.000000
80.770004,65.184921,-289.837891,-0.002186,0.004008,0.101795,289.957001,14.771114,1.017949,-289.837891,294.500458,0.000000
81.140007,65.046021,-289.837891,-0.002182,0.004008,0.101795,289.339142,14.739638,1.017949,-289.837891,294.500458,0.000000
81.510002,64.925003,-289.748901,-0.002186,0.004008,0.101795,288.800842,14.712215,1.017949,-289.748901,294.500458,0.000000
81.880005,64.774185,-289.793396,-0.002186,0.004008,0.101795,288.129974,14.678040,1.017949,-289.793396,294.500458,0.000000
82.250008,64.641251,-289.882355,-0.002182,0.004008,0.101795,287.538635,14.647917,1.017949,-289.882355,294.500458,0.000000
82.620003,64.519119,-289.926849,-0.002169,0.004008,0.101795,286.995361,14.620241,1.017949,-289.926849,294.500458,0.000000
82.990005,64.392883,-289.926849,-0.002177,0.004008,0.101795,286.433838,14.591636,1.017949,-289.926849,294.500458,0.000000
83.360001,66.686691,-289.882355,-0.002164,0.003829,0.097259,296.637207,15.111420,0.972594,-289.882355,294.500458,0.000000
83.730003,66.541473,-289.882355,-0.002164,0.003829,0.097259,295.991241,15.078513,0.972594,-289.882355,294.500458,0.000000
84.100006,66.394379,-289.971313,-0.002156,0.003829,0.097268,295.336945,15.045181,0.972680,-289.971313,294.500458,0.000000
84.470001,66.252136,-290.060272,-0.002151,0.003829,0.097268,294.704224,15.012949,0.972680,-290.060272,294.500458,0.000000
84.840004,66.102814,-290.015808,-0.002151,0.003829,0.097268,294.040009,14.979112,0.972680,-290.015808,294.500458,0.000000
85.210007,65.992218,-290.015808,-0.002134,0.003829,0.097268,293.548035,14.954050,0.972680,-290.015808,294.500458,0.000000
85.580002,65.834335,-289.971313,-0.002139,0.003842,0.097580,292.845764,14.918274,0.975802,-289.971313,294.500458,0.000000
85.950005,65.771774,-290.060272,-0.002147,0.003848,0.097745,292.567474,14.904097,0.977450,-290.060272,294.500458,0.000000
86.320007,65.623566,-290.104767,-0.002147,0.003900,0.099055,291.908203,14.870512,0.990545,-290.104767,294.500458,0.000000
86.690002,65.553558,-290.015808,-0.002156,0.003952,0.100381,291.596802,14.854649,1.003814,-290.015808,294.500458,0.000000
87.060005,65.507385,-290.015808,-0.002156,0.003968,0.100789,291.391388,14.844186,1.007890,-290.015808,294.500458,0.000000
87.430008,65.414673,-290.104767,-0.002156,0.003980,0.101092,290.979004,14.823176,1.010925,-290.104767,294.500458,0.000000
87.800003,65.317474,-290.149231,-0.002164,0.003983,0.101162,290.546631,14.801151,1.011619,-290.149231,294.500458,0.000000
88.170006,65.242264,-290.104767,-0.002151,0.003983,0.101179,290.212097,14.784108,1.011792,-290.104767,294.500458,0.000000
88.540001,65.206512,-290.149231,-0.002169,0.003991,0.101361,290.053040,14.776007,1.013613,-290.149231,294.500458,0.000000
88.910004,65.136139,-290.149231,-0.002147,0.003998,0.101561,289.740021,14.760059,1.015608,-290.149231,294.500458,0.000000
89.280006,65.059799,-290.149231,-0.002160,0.003999,0.101578,289.400452,14.742761,1.015782,-290.149231,294.500458,0.000000
89.650002,65.082886,-290.193726,-0.002147,0.004016,0.102012,289.503143,14.747993,1.020118,-290.193726,294.500458,0.000000
90.020004,65.188263,-290.238220,-0.002151,0.004019,0.102081,289.971863,14.771872,1.020811,-290.238220,294.500458,0.000000
90.390007,65.214706,-290.193726,-0.002164,0.004022,0.102168,290.089508,14.777864,1.021679,-290.193726,294.500458,0.000000
90.760002,65.229233,-290.238220,-0.002147,0.004023,0.102185,290.154114,14.781156,1.021852,-290.238220,294.500458,0.000000
91.130005,65.215073,-290.193726,-0.002151,0.004024,0.102203,290.091125,14.777947,1.022025,-290.193726,294.500458,0.000000
91.500008,65.193115,-290.282684,-0.002143,0.004024,0.102211,289.993469,14.772971,1.022112,-290.282684,294.500458,0.000000
91.870003,65.152527,-290.327179,-0.002151,0.004024,0.102220,289.812927,14.763774,1.022199,-290.327179,294.500458,0.000000
92.240005,65.386368,-290.282684,-0.002143,0.004029,0.102333,290.853088,14.816763,1.023326,-290.282684,294.500458,0.000000
92.610001,65.395309,-290.282684,-0.002147,0.004029,0.102333,290.892853,14.818789,1.023326,-290.282684,294.500458,0.000000
92.980003,65.352112,-290.238220,-0.002147,0.004029,0.102333,290.700714,14.809001,1.023326,-290.238220,294.500458,0.000000
93.350006,65.320465,-290.327179,-0.002164,0.004029,0.102333,290.559937,14.801828,1.023326,-290.327179,294.500458,0.000000
93.720001,65.295135,-290.371643,-0.002143,0.004029,0.102341,290.447266,14.796089,1.023413,-290.371643,294.500458,0.000000
94.090004,65.279129,-290.460602,-0.002151,0.004030,0.102350,290.376068,14.792462,1.023500,-290.460602,294.500458,0.000000
94.460007,65.288437,-290.460602,-0.002134,0.004031,0.102385,290.417480,14.794571,1.023847,-290.460602,294.500458,0.000000
94.830002,65.278015,-290.371643,-0.002151,0.004031,0.102385,290.371124,14.792210,1.023847,-290.371643,294.500458,0.000000
95.200005,65.260132,-290.371643,-0.002156,0.004031,0.102385,290.291565,14.788157,1.023847,-290.371643,294.500458,0.000000
95.570007,65.255661,-290.460602,-0.002143,0.004032,0.102419,290.271667,14.787145,1.024194,-290.460602,294.500458,0.000000
95.940002,65.257523,-290.460602,-0.002143,0.004032,0.102419,290.279968,14.787565,1.024194,-290.460602,294.500458,0.000000
96.310005,65.232956,-290.505096,-0.002139,0.004032,0.102419,290.170685,14.782000,1.024194,-290.505096,294.500458,0.000000
96.680008,65.216568,-290.505096,-0.002156,0.004034,0.102454,290.097778,14.778286,1.024540,-290.505096,294.500458,0.000000
97.050003,65.272049,-290.505096,-0.002134,0.004035,0.102480,290.344574,14.790857,1.024801,-290.505096,294.500458,0.000000
97.420006,65.287689,-290.549561,-0.002151,0.004035,0.102489,290.414154,14.794401,1.024887,-290.549561,294.500458,0.000000
97.790001,65.286194,-290.638519,-0.002147,0.004035,0.102489,290.407501,14.794064,1.024887,-290.638519,294.500458,0.000000
98.160004,65.266098,-290.594055,-0.002151,0.004036,0.102506,290.318115,14.789509,1.025061,-290.594055,294.500458,0.000000
98.530006,65.264969,-290.549561,-0.002130,0.004036,0.102515,290.313080,14.789253,1.025148,-290.549561,294.500458,0.000000
98.900002,65.366638,-290.549561,-0.002143,0.004038,0.102558,290.765320,14.812292,1.025581,-290.549561,294.500458,0.000000
99.270004,65.349884,-290.638519,-0.002147,0.004038,0.102558,290.690796,14.808496,1.025581,-290.638519,294.500458,0.000000
99.640007,65.336838,-290.683014,-0.002147,0.004038,0.102558,290.632782,14.805539,1.025581,-290.683014,294.500458,0.000000
100.010002,65.301834,-290.638519,-0.002151,0.004038,0.102558,290.477051,14.797607,1.025581,-290.638519,294.500458,0.000000
100.380005,65.295135,-290.594055,-0.002143,0.004038,0.102558,290.447266,14.796089,1.025581,-290.594055,294.500458,0.000000
100.750008,65.247467,-290.638519,-0.002147,0.004038,0.102575,290.235229,14.785287,1.025755,-290.638519,294.500458,0.000000
101.120003,65.222519,-290.771973,-0.002156,0.004038,0.102575,290.124268,14.779634,1.025755,-290.771973,294.500458,0.000000
101.490005,65.212845,-290.727509,-0.002134,0.004039,0.102584,290.081207,14.777442,1.025841,-290.727509,294.500458,0.000000
101.860008,65.528244,-290.771973,-0.002134,0.004043,0.102697,291.484192,14.848912,1.026969,-290.771973,294.500458,0.000000
102.230003,65.554687,-290.727509,-0.002134,0.004043,0.102697,291.601807,14.854904,1.026969,-290.727509,294.500458,0.000000
102.600006,65.544632,-290.771973,-0.002143,0.004043,0.102697,291.557098,14.852626,1.026969,-290.771973,294.500458,0.000000
102.970001,65.525269,-290.816467,-0.002147,0.004043,0.102697,291.470947,14.848238,1.026969,-290.816467,294.500458,0.000000
103.340004,65.508514,-290.816467,-0.002134,0.004043,0.102697,291.396423,14.844441,1.026969,-290.816467,294.500458,0.000000
103.710007,65.500687,-290.771973,-0.002160,0.004043,0.102697,291.361603,14.842668,1.026969,-290.771973,294.500458,0.000000
104.080002,65.464935,-290.816467,-0.002156,0.004043,0.102697,291.202576,14.834566,1.026969,-290.816467,294.500458,0.000000
104.450005,65.431427,-290.816467,-0.002143,0.004043,0.102697,291.053528,14.826973,1.026969,-290.816467,294.500458,0.000000
104.820007,65.398285,-290.860931,-0.002151,0.004043,0.102697,290.906097,14.819464,1.026969,-290.860931,294.500458,0.000000
105.190002,65.358444,-290.949890,-0.002151,0.004043,0.102697,290.728882,14.810435,1.026969,-290.949890,294.500458,0.000000
105.560005,65.349884,-290.860931,-0.002139,0.004044,0.102723,290.690796,14.808496,1.027229,-290.860931,294.500458,0.000000
105.930008,65.314499,-290.905426,-0.002143,0.004044,0.102723,290.533386,14.800477,1.027229,-290.905426,294.500458,0.000000
106.300003,65.315247,-290.905426,-0.002147,0.004044,0.102723,290.536713,14.800647,1.027229,-290.905426,294.500458,0.000000
106.670006,65.280991,-290.949890,-0.002147,0.004044,0.102723,290.384338,14.792884,1.027229,-290.949890,294.500458,0.000000
107.040009,65.257523,-290.994385,-0.002164,0.004044,0.102723,290.279968,14.787565,1.027229,-290.994385,294.500458,0.000000
107.410004,65.236298,-290.949890,-0.002151,0.004044,0.102723,290.185547,14.782756,1.027229,-290.949890,294.500458,0.000000
107.780006,65.217316,-290.949890,-0.002143,0.004044,0.102723,290.101105,14.778456,1.027229,-290.949890,294.500458,0.000000
108.150002,65.210617,-290.994385,-0.002143,0.004044,0.102723,290.071320,14.776937,1.027229,-290.994385,294.500458,0.000000
108.520004,65.195343,-291.038849,-0.002147,0.004045,0.102732,290.003357,14.773476,1.027316,-291.038849,294.500458,0.000000
108.890007,65.174866,-291.038849,-0.002147,0.004045,0.102732,289.912292,14.768836,1.027316,-291.038849,294.500458,0.000000
109.260002,65.529358,-291.083344,-0.002143,0.004051,0.102905,291.489136,14.849164,1.029050,-291.083344,294.500458,0.000000
109.630005,65.592667,-291.038849,-0.002143,0.004051,0.102896,291.770752,14.863511,1.028963,-291.038849,294.500458,0.000000
110.000008,65.594894,-291.083344,-0.002143,0.004051,0.102896,291.780670,14.864016,1.028963,-291.083344,294.500458,0.000000
110.370003,65.590057,-291.172302,-0.002139,0.004051,0.102896,291.759155,14.862919,1.028963,-291.172302,294.500458,0.000000
110.740005,65.594894,-291.127838,-0.002134,0.004051,0.102896,291.780670,14.864016,1.028963,-291.127838,294.500458,0.000000
111.110008,65.585968,-291.127838,-0.002143,0.004051,0.102896,291.740967,14.861993,1.028963,-291.127838,294.500458,0.000000
111.480003,65.589310,-291.172302,-0.002147,0.004051,0.102896,291.755829,14.862750,1.028963,-291.172302,294.500458,0.000000
111.850006,65.561752,-291.172302,-0.002151,0.004051,0.102896,291.633240,14.856505,1.028963,-291.172302,294.500458,0.000000
112.220009,65.555054,-291.216797,-0.002156,0.004051,0.102896,291.603455,14.854987,1.028963,-291.216797,294.500458,0.000000
112.590004,65.531601,-291.216797,-0.002143,0.004051,0.102896,291.499115,14.849672,1.028963,-291.216797,294.500458,0.000000
112.960007,65.513351,-291.216797,-0.002126,0.004051,0.102896,291.417938,14.845537,1.028963,-291.216797,294.500458,0.000000
113.330002,65.503662,-291.172302,-0.002156,0.004051,0.102896,291.374847,14.843342,1.028963,-291.172302,294.500458,0.000000
113.700005,65.460464,-291.216797,-0.002143,0.004051,0.102896,291.182678,14.833553,1.028963,-291.216797,294.500458,0.000000
114.070007,65.445953,-291.261261,-0.002156,0.004051,0.102896,291.118134,14.830265,1.028963,-291.261261,294.500458,0.000000
114.440002,65.407227,-291.350220,-0.002151,0.004051,0.102896,290.945862,14.821489,1.028963,-291.350220,294.500458,0.000000
114.810005,65.384506,-291.305756,-0.002151,0.004051,0.102905,290.844818,14.816340,1.029050,-291.305756,294.500458,0.000000
115.180008,65.365143,-291.261261,-0.002156,0.004051,0.102905,290.758667,14.811953,1.029050,-291.261261,294.500458,0.000000
115.550003,65.337585,-291.305756,-0.002143,0.004051,0.102905,290.636108,14.805709,1.029050,-291.305756,294.500458,0.000000
115.920006,65.325302,-291.350220,-0.002147,0.004051,0.102905,290.581451,14.802925,1.029050,-291.350220,294.500458,0.000000
116.290009,65.304443,-291.350220,-0.002121,0.004052,0.102931,290.488678,14.798199,1.029310,-291.350220,294.500458,0.000000
116.660004,65.328659,-291.394714,-0.002139,0.004053,0.102940,290.596375,14.803686,1.029397,-291.394714,294.500458,0.000000
117.030006,65.314499,-291.350220,-0.002143,0.004053,0.102940,290.533386,14.800477,1.029397,-291.350220,294.500458,0.000000
117.400009,65.315994,-291.350220,-0.002151,0.004053,0.102948,290.540039,14.800816,1.029484,-291.350220,294.500458,0.000000
117.770004,65.314133,-291.439178,-0.002134,0.004053,0.102948,290.531769,14.800394,1.029484,-291.439178,294.500458,0.000000
118.140007,65.307053,-291.439178,-0.002139,0.004053,0.102948,290.500275,14.798789,1.029484,-291.439178,294.500458,0.000000
118.510002,65.294388,-291.483673,-0.002139,0.004053,0.102948,290.443939,14.795919,1.029484,-291.483673,294.500458,0.000000
118.880005,65.271683,-291.439178,-0.002134,0.004053,0.102948,290.342957,14.790774,1.029484,-291.439178,294.500458,0.000000
119.250008,65.269821,-291.483673,-0.002147,0.004053,0.102957,290.334656,14.790353,1.029570,-291.483673,294.500458,0.000000
119.620003,65.255661,-291.483673,-0.002134,0.004054,0.102966,290.271667,14.787145,1.029657,-291.483673,294.500458,0.000000
119.990005,65.243378,-291.617126,-0.002151,0.004054,0.102966,290.217041,14.784361,1.029657,-291.617126,294.500458,0.000000
120.360008,65.243378,-291.483673,-0.002143,0.004054,0.102974,290.217041,14.784361,1.029744,-291.483673,294.500458,0.000000
120.730003,65.245605,-291.572632,-0.002134,0.004054,0.102983,290.226959,14.784865,1.029831,-291.572632,294.500458,0.000000
121.100006,65.248962,-291.572632,-0.002134,0.004055,0.102992,290.241882,14.785626,1.029917,-291.572632,294.500458,0.000000
121.470009,65.277634,-291.617126,-0.002147,0.004056,0.103018,290.369415,14.792123,1.030177,-291.617126,294.500458,0.000000
121.840004,65.286575,-291.572632,-0.002156,0.004056,0.103018,290.409180,14.794149,1.030177,-291.572632,294.500458,0.000000
122.210007,65.296997,-291.661591,-0.002139,0.004056,0.103018,290.455536,14.796512,1.030177,-291.661591,294.500458,0.000000
122.580009,65.287689,-291.617126,-0.002143,0.004056,0.103018,290.414154,14.794401,1.030177,-291.617126,294.500458,0.000000
122.950005,65.273544,-291.617126,-0.002139,0.004056,0.103018,290.351227,14.791197,1.030177,-291.617126,294.500458,0.000000
123.320007,65.257904,-291.661591,-0.002143,0.004056,0.103018,290.281647,14.787653,1.030177,-291.661591,294.500458,0.000000
123.690002,65.269440,-291.706085,-0.002147,0.004056,0.103018,290.332977,14.790266,1.030177,-291.706085,294.500458,0.000000
124.060005,65.244492,-291.706085,-0.002130,0.004056,0.103026,290.221985,14.784614,1.030264,-291.706085,294.500458,0.000000
124.430008,65.253067,-291.706085,-0.002134,0.004056,0.103026,290.260132,14.786556,1.030264,-291.706085,294.500458,0.000000
124.800003,65.233322,-291.706085,-0.002134,0.004056,0.103035,290.172302,14.782083,1.030351,-291.706085,294.500458,0.000000
125.170006,65.235931,-291.750549,-0.002130,0.004056,0.103035,290.183929,14.782673,1.030351,-291.750549,294.500458,0.000000
125.540009,65.228104,-291.795044,-0.002143,0.004056,0.103035,290.149109,14.780899,1.030351,-291.795044,294.500458,0.000000
125.910004,65.203156,-291.795044,-0.002130,0.004057,0.103044,290.038116,14.775247,1.030438,-291.795044,294.500458,0.000000
126.280006,65.210983,-291.839508,-0.002147,0.004057,0.103044,290.072937,14.777020,1.030438,-291.839508,294.500458,0.000000
126.650009,65.199814,-291.795044,-0.002130,0.004057,0.103052,290.023254,14.774489,1.030524,-291.795044,294.500458,0.000000
127.020004,65.210617,-291.839508,-0.002126,0.004058,0.103061,290.071320,14.776937,1.030611,-291.839508,294.500458,0.000000
127.390007,65.212479,-291.839508,-0.002147,0.004058,0.103078,290.079590,14.777359,1.030784,-291.839508,294.500458,0.000000
127.760010,65.243378,-291.795044,-0.002139,0.004059,0.103087,290.217041,14.784361,1.030871,-291.795044,294.500458,0.000000
128.130005,65.251938,-291.839508,-0.002134,0.004059,0.103087,290.255127,14.786300,1.030871,-291.839508,294.500458,0.000000
128.500000,65.251205,-291.884003,-0.002139,0.004059,0.103087,290.251862,14.786135,1.030871,-291.884003,294.500458,0.000000
128.870010,65.260880,-291.884003,-0.002147,0.004059,0.103087,290.294891,14.788326,1.030871,-291.884003,294.500458,0.000000
129.240005,65.232574,-291.972961,-0.002143,0.004059,0.103087,290.168976,14.781913,1.030871,-291.972961,294.500458,0.000000
129.610001,65.226242,-291.972961,-0.002134,0.004059,0.103087,290.140808,14.780478,1.030871,-291.972961,294.500458,0.000000
129.980011,65.213211,-292.017456,-0.002126,0.004059,0.103087,290.082855,14.777525,1.030871,-292.017456,294.500458,0.000000
130.350006,65.192368,-292.017456,-0.002139,0.004059,0.103087,289.990143,14.772801,1.030871,-292.017456,294.500458,0.000000
130.720001,65.180817,-291.972961,-0.002143,0.004059,0.103096,289.938751,14.770185,1.030958,-291.972961,294.500458,0.000000
131.090012,65.220291,-292.061920,-0.002121,0.004061,0.103139,290.114349,14.779129,1.031392,-292.061920,294.500458,0.000000
131.460007,65.251205,-292.106415,-0.002130,0.004061,0.103139,290.251862,14.786135,1.031392,-292.106415,294.500458,0.000000
131.830002,65.250076,-292.017456,-0.002139,0.004061,0.103139,290.246826,14.785879,1.031392,-292.017456,294.500458,0.000000
132.200012,65.270187,-292.017456,-0.002134,0.004061,0.103139,290.336304,14.790436,1.031392,-292.017456,294.500458,0.000000
132.570007,65.241882,-292.061920,-0.002143,0.004061,0.103139,290.210388,14.784021,1.031392,-292.061920,294.500458,0.000000
132.940002,65.245239,-292.106415,-0.002143,0.004061,0.103139,290.225311,14.784782,1.031392,-292.106415,294.500458,0.000000
133.310013,65.251205,-292.150879,-0.002147,0.004061,0.103139,290.251862,14.786135,1.031392,-292.150879,1681.640747,0.000000
133.680008,65.281357,-292.150879,-0.002130,0.004053,0.102948,290.385986,14.792967,1.029484,-292.150879,0.102914,0.000000
134.050003,65.206512,-292.150879,-0.002139,0.004040,0.102610,290.053040,14.776007,1.026101,-292.150879,0.102298,0.000000
134.420013,65.149170,-292.106415,-0.002130,0.004018,0.102064,289.797974,14.763013,1.020638,-292.106415,0.101682,0.000000
134.790009,65.082520,-292.195374,-0.002139,0.004002,0.101656,289.501495,14.747910,1.016562,-292.195374,0.101066,0.000000
135.160004,65.008408,-292.239838,-0.002130,0.003975,0.100954,289.171844,14.731116,1.009537,-292.239838,0.100451,0.000000
135.530014,65.025543,-292.195374,-0.002126,0.003953,0.100407,289.248077,14.734999,1.004074,-292.195374,0.099835,0.000000
135.900009,65.008789,-292.195374,-0.002126,0.003929,0.099800,289.173523,14.731202,0.998003,-292.195374,0.099219,0.000000
136.270004,64.992020,-292.239838,-0.002143,0.003905,0.099193,289.098938,14.727402,0.991933,-292.239838,0.098604,0.000000
136.639999,64.943253,-292.284332,-0.002130,0.003880,0.098552,288.882019,14.716352,0.985515,-292.284332,0.097979,0.000000
137.010010,64.850525,-292.284332,-0.002130,0.003855,0.097918,288.469543,14.695339,0.979185,-292.284332,0.097363,0.000000
137.380005,64.808441,-292.239838,-0.002134,0.003837,0.097459,288.282349,14.685803,0.974588,-292.239838,0.096748,0.000000
137.750000,64.535873,-292.284332,-0.002113,0.003814,0.096878,287.069916,14.624038,0.968778,-292.284332,0.096132,0.000000
138.120010,64.118073,-292.284332,-0.002121,0.003798,0.096479,285.211426,14.529363,0.964789,-292.284332,0.095516,0.000000
138.490005,62.858704,-292.373291,-0.002108,0.003764,0.095603,279.609467,14.243985,0.956030,-292.373291,0.094901,0.000000
138.860001,61.510345,-292.373291,-0.002104,0.003741,0.095013,273.611694,13.938443,0.950132,-292.373291,0.094285,0.000000
139.230011,59.674179,-292.373291,-0.002095,0.003719,0.094458,265.444000,13.522363,0.944582,-292.373291,0.093669,0.000000
139.600006,58.425240,-292.373291,-0.002087,0.003703,0.094059,259.888458,13.239348,0.940593,-292.373291,0.093053,0.000000
139.970001,57.141296,-292.417786,-0.002104,0.003688,0.093669,254.177185,12.948402,0.936690,-292.417786,0.092429,0.000000
140.340012,54.584961,-292.506744,-0.002095,0.003655,0.092845,242.806030,12.369129,0.928452,-292.506744,0.091813,0.000000
140.710007,52.001068,-292.462250,-0.002095,0.003632,0.092247,231.312302,11.783610,0.922468,-292.462250,0.091197,0.000000
141.080002,48.974800,-292.462250,-0.002108,0.003602,0.091492,217.850784,11.097848,0.914923,-292.462250,0.090582,0.000000
141.450012,46.589378,-292.417786,-0.002091,0.003581,0.090963,207.239899,10.557304,0.909633,-292.417786,0.089966,0.000000
141.820007,44.154434,-292.506744,-0.002113,0.003556,0.090330,196.408737,10.005538,0.903302,-292.506744,0.089350,0.000000
142.190002,41.594376,-292.506744,-0.002087,0.003533,0.089749,185.021027,9.425420,0.897492,-292.506744,0.088735,0.000000
142.560013,39.017555,-292.506744,-0.002095,0.003509,0.089116,173.558746,8.841504,0.891161,-292.506744,0.088119,0.000000
142.930008,37.317680,-292.506744,-0.002104,0.003494,0.088752,165.997330,8.456307,0.887519,-292.506744,0.087503,0.000000
143.300003,33.517990,-292.551208,-0.002095,0.003456,0.087772,149.095459,7.595285,0.877719,-292.551208,0.086879,0.000000
143.670013,31.444992,-292.506744,-0.002091,0.003437,0.087312,139.874313,7.125537,0.873123,-292.506744,0.086263,0.000000
144.040009,28.701355,-292.595703,-0.002082,0.003412,0.086662,127.670006,6.503820,0.866619,-292.595703,0.085647,0.000000
144.410004,26.167358,-292.595703,-0.002095,0.003386,0.085994,116.398224,5.929608,0.859941,-292.595703,0.085031,0.000000
144.780014,23.478081,-292.640167,-0.002095,0.003363,0.085430,104.435722,5.320209,0.854304,-292.640167,0.084416,0.000000
145.150009,20.438034,-292.551208,-0.002095,0.003336,0.084737,90.912918,4.631325,0.847366,-292.551208,0.083800,0.000000
145.520004,18.473022,-292.640167,-0.002104,0.003320,0.084329,82.172112,4.186047,0.843290,-292.640167,0.083184,0.000000
145.889999,15.686935,-292.729126,-0.002117,0.003292,0.083627,69.778976,3.554710,0.836266,-292.729126,0.082569,0.000000
146.260010,12.727318,-292.684662,-0.002117,0.003263,0.082881,56.613937,2.884051,0.828808,-292.684662,0.081944,0.000000
146.630005,10.322906,-292.684662,-0.002108,0.003244,0.082395,45.918583,2.339204,0.823951,-292.684662,0.081328,0.000000
147.000000,6.739571,-292.595703,-0.002108,0.003212,0.081597,29.979107,1.527209,0.815973,-292.595703,0.080713,0.000000
147.370010,4.954414,-292.729126,-0.002121,0.003194,0.081120,22.038336,1.122686,0.811203,-292.729126,0.080097,0.000000
147.740005,1.698761,-292.729126,-0.002126,0.003161,0.080296,7.556466,0.384945,0.802964,-292.729126,0.079481,0.000000
148.110001,0.135918,-292.729126,-0.002121,0.003146,0.079906,0.604592,0.030799,0.799062,-292.729126,0.078865,0.000000
148.480011,-2.126247,-292.773621,-0.002113,0.003120,0.079238,-9.458021,-0.481815,0.792384,-292.773621,0.078250,0.000000
148.850006,-0.439026,-292.818115,-0.002126,0.003089,0.078467,-1.952885,-0.099485,0.784666,-292.818115,0.077634,0.000000
149.220001,-0.086021,-292.818115,-0.002126,0.003075,0.078102,-0.382642,-0.019493,0.781024,-292.818115,0.077018,0.000000
149.590012,-0.152672,-292.818115,-0.002117,0.003051,0.077504,-0.679118,-0.034596,0.775040,-292.818115,0.076394,0.000000
149.960007,-0.101662,-292.862579,-0.002117,0.003022,0.076749,-0.452214,-0.023037,0.767495,-292.862579,0.075778,0.000000
150.330002,-0.040215,-292.907074,-0.002117,0.002999,0.076168,-0.178883,-0.009113,0.761684,-292.907074,0.075162,0.000000
150.700012,-0.047661,-292.818115,-0.002121,0.002975,0.075553,-0.212006,-0.010800,0.755527,-292.818115,0.074547,0.000000
151.070007,-0.030907,-292.907074,-0.002121,0.002950,0.074928,-0.137480,-0.007004,0.749283,-292.907074,0.073931,0.000000
151.440002,0.009308,-292.951538,-0.002108,0.002932,0.074469,0.041403,0.002109,0.744687,-292.951538,0.074391,0.000000
151.600006,0.027557,-292.907074,-0.002126,0.002932,0.074469,0.122581,0.006245,0.744687,-292.907074,0.074391,0.000000