File: Data/compression 32/AutoNoHeating-15-32-reverse-1-3_11142024_174638.csv
Time (sec),S:Load (lbs),S:HL1 (DIM),S:LVDT (in),S:Position (in),Ch:Position (mm),Ch:Load (N),Ch:Stress (MPa),Ch:Strain (mm/mm),Ch:HL1 (DIM),Set Point (),Cycles ()
0.110000,-0.011169,-265.818176,-0.010559,-0.005845,-0.148452,-0.049684,-0.002531,-1.484517,-265.818176,-0.148278,0.000000
0.450000,-0.030907,-265.862640,-0.010559,-0.005780,-0.146804,-0.137480,-0.007004,-1.468040,-265.862640,-0.146353,0.000000
0.790000,-0.046547,-265.862640,-0.010468,-0.005580,-0.141731,-0.207051,-0.010548,-1.417307,-265.862640,-0.140681,0.000000
1.130000,-0.020111,-265.862640,-0.010240,-0.005360,-0.136154,-0.089459,-0.004557,-1.361544,-265.862640,-0.135010,0.000000
1.470000,0.028297,-265.907135,-0.010011,-0.005135,-0.130422,0.125873,0.006412,-1.304221,-265.907135,-0.129355,0.000000
1.810000,0.010796,-265.951599,-0.009770,-0.004920,-0.124959,0.048021,0.002446,-1.249585,-265.951599,-0.123684,0.000000
2.150000,-0.015266,-265.907135,-0.009550,-0.004689,-0.119096,-0.067908,-0.003459,-1.190961,-265.907135,-0.118029,0.000000
2.490000,-0.070755,-265.996094,-0.009326,-0.004469,-0.113511,-0.314734,-0.016033,-1.135112,-265.996094,-0.112358,0.000000
2.830000,-0.039474,-265.907135,-0.009089,-0.004241,-0.107709,-0.175591,-0.008945,-1.077094,-265.907135,-0.106686,0.000000
3.170000,0.022713,-265.951599,-0.008873,-0.004026,-0.102263,0.101031,0.005147,-1.022632,-265.951599,-0.101032,0.000000
3.510000,0.022713,-266.085052,-0.008645,-0.003798,-0.096479,0.101031,0.005147,-0.964789,-266.085052,-0.095360,0.000000
3.850000,-0.014526,-265.996094,-0.008425,-0.003579,-0.090894,-0.064617,-0.003292,-0.908939,-265.996094,-0.089706,0.000000
4.190000,0.022713,-266.085052,-0.008179,-0.003354,-0.085196,0.101031,0.005147,-0.851963,-266.085052,-0.084034,0.000000
4.530000,-0.002609,-266.040558,-0.007933,-0.003132,-0.079559,-0.011607,-0.000591,-0.795593,-266.040558,-0.078380,0.000000
4.870000,-0.021973,-266.040558,-0.007722,-0.002907,-0.073844,-0.097739,-0.004979,-0.738443,-266.040558,-0.072708,0.000000
5.210000,-0.049156,-266.129517,-0.007493,-0.002685,-0.068207,-0.218658,-0.011139,-0.682073,-266.129517,-0.067037,0.000000
5.550000,0.028297,-266.129517,-0.007256,-0.002460,-0.062492,0.125873,0.006412,-0.624923,-266.129517,-0.061382,0.000000
5.890000,0.047661,-266.174011,-0.007023,-0.002245,-0.057011,0.212006,0.010800,-0.570114,-266.174011,-0.055711,0.000000
6.230000,0.011169,-266.085052,-0.006773,-0.002013,-0.051123,0.049684,0.002531,-0.511230,-266.085052,-0.050056,0.000000
6.570000,-0.017876,-266.129517,-0.006558,-0.001793,-0.045538,-0.079515,-0.004051,-0.455380,-266.129517,-0.044385,0.000000
6.910000,-0.038727,-266.174011,-0.006325,-0.001566,-0.039771,-0.172265,-0.008776,-0.397710,-266.174011,-0.038730,0.000000
7.250000,-0.014153,-266.129517,-0.006118,-0.001355,-0.034429,-0.062954,-0.003207,-0.344289,-266.129517,-0.033059,0.000000
7.590000,0.003349,-266.307465,-0.005877,-0.001122,-0.028488,0.014898,0.000759,-0.284884,-266.307465,-0.027387,0.000000
7.930000,-0.001862,-266.174011,-0.005657,-0.000901,-0.022877,-0.008281,-0.000422,-0.228774,-266.174011,-0.021733,0.000000
8.270000,0.027924,-266.218506,-0.005407,-0.000676,-0.017162,0.124210,0.006328,-0.171624,-266.218506,-0.016061,0.000000
8.610001,-0.007820,-266.218506,-0.005182,-0.000460,-0.011682,-0.034786,-0.001772,-0.116815,-266.218506,-0.010407,0.000000
8.950001,0.020477,-266.262970,-0.004963,-0.000232,-0.005888,0.091088,0.004640,-0.058885,-266.262970,-0.004735,0.000000
9.290001,0.192886,-266.262970,-0.004760,0.000030,0.000754,0.858001,0.043709,0.007545,-266.262970,0.000928,0.000000
9.630000,0.173523,-266.262970,-0.004747,0.000029,0.000746,0.771869,0.039321,0.007458,-266.262970,0.000928,0.000000
9.970000,0.135544,-266.307465,-0.004751,0.000029,0.000746,0.602929,0.030715,0.007458,-266.307465,0.001310,0.000000
10.310000,0.084152,-266.307465,-0.004743,0.000033,0.000833,0.374328,0.019069,0.008325,-266.307465,0.001873,0.000000
10.650001,0.218208,-266.307465,-0.004730,0.000057,0.001448,0.970639,0.049447,0.014483,-266.307465,0.002446,0.000000
10.990001,0.450569,-266.396423,-0.004721,0.000083,0.002116,2.004232,0.102100,0.021160,-266.396423,0.003009,0.000000
11.330001,0.605850,-266.351929,-0.004691,0.000097,0.002454,2.694956,0.137288,0.024543,-266.351929,0.003573,0.000000
11.670001,0.845657,-266.440887,-0.004691,0.000115,0.002931,3.761672,0.191629,0.029312,-266.440887,0.004145,0.000000
12.010000,1.318199,-266.396423,-0.004644,0.000152,0.003868,5.863643,0.298708,0.038678,-266.396423,0.004709,0.000000
12.350000,1.595985,-266.396423,-0.004635,0.000171,0.004336,7.099298,0.361655,0.043361,-266.396423,0.005273,0.000000
12.690001,1.959053,-266.485382,-0.004618,0.000194,0.004926,8.714303,0.443928,0.049258,-266.485382,0.005845,0.000000
13.030001,2.385414,-266.440887,-0.004592,0.000217,0.005524,10.610852,0.540543,0.055242,-266.440887,0.006409,0.000000
13.370001,2.499367,-266.396423,-0.004583,0.000227,0.005758,11.117739,0.566365,0.057584,-266.396423,0.006972,0.000000
13.710001,3.148033,-266.485382,-0.004549,0.000261,0.006617,14.003151,0.713354,0.066169,-266.485382,0.007545,0.000000
14.050000,3.499557,-266.440887,-0.004536,0.000281,0.007129,15.566810,0.793011,0.071286,-266.440887,0.008109,0.000000
14.390000,3.891289,-266.529846,-0.004514,0.000305,0.007753,17.309317,0.881779,0.077530,-266.529846,0.008672,0.000000
14.730000,4.390274,-266.485382,-0.004488,0.000329,0.008351,19.528913,0.994850,0.083514,-266.485382,0.009245,0.000000
15.070001,4.623375,-266.529846,-0.004475,0.000347,0.008802,20.565800,1.047672,0.088023,-266.529846,0.009808,0.000000
15.410001,5.099640,-266.574341,-0.004449,0.000369,0.009375,22.684332,1.155595,0.093747,-266.574341,0.010372,0.000000
15.750001,5.610535,-266.574341,-0.004449,0.000393,0.009982,24.956905,1.271365,0.099818,-266.574341,0.010944,0.000000
16.090000,5.997055,-266.574341,-0.004424,0.000418,0.010624,26.676233,1.358952,0.106235,-266.574341,0.011508,0.000000
16.430000,6.344856,-266.574341,-0.004398,0.000438,0.011118,28.223330,1.437765,0.111178,-266.574341,0.012080,0.000000
16.770000,6.789093,-266.618835,-0.004389,0.000460,0.011682,30.199394,1.538430,0.116815,-266.618835,0.012644,0.000000
17.110001,7.036346,-266.574341,-0.004355,0.000478,0.012141,31.299232,1.594459,0.121412,-266.574341,0.013208,0.000000
17.450001,7.711464,-266.574341,-0.004355,0.000507,0.012870,34.302303,1.747443,0.128696,-266.574341,0.013780,0.000000
17.790001,8.111015,-266.663300,-0.004324,0.000531,0.013477,36.079597,1.837982,0.134767,-266.663300,0.014344,0.000000
18.130001,8.394394,-266.618835,-0.004299,0.000552,0.014032,37.340130,1.902197,0.140317,-266.618835,0.014908,0.000000
18.470001,8.802513,-266.707794,-0.004299,0.000574,0.014578,39.155533,1.994678,0.145781,-266.707794,0.015480,0.000000
18.810001,9.358467,-266.707794,-0.004260,0.000598,0.015185,41.628540,2.120659,0.151851,-266.707794,0.016044,0.000000
19.150002,9.413574,-266.707794,-0.004243,0.000615,0.015619,41.873669,2.133147,0.156187,-266.707794,0.016607,0.000000
19.490002,9.614281,-266.752258,-0.004243,0.000626,0.015905,42.766457,2.178627,0.159049,-266.752258,0.017180,0.000000
19.830002,10.559738,-266.707794,-0.004199,0.000665,0.016894,46.972061,2.392871,0.168936,-266.707794,0.017743,0.000000
20.170000,10.754120,-266.752258,-0.004191,0.000686,0.017414,47.836716,2.436918,0.174139,-266.752258,0.018307,0.000000
20.510000,11.193146,-266.796753,-0.004156,0.000705,0.017917,49.789600,2.536403,0.179169,-266.796753,0.018880,0.000000
20.850000,11.414703,-266.841217,-0.004148,0.000728,0.018481,50.775135,2.586609,0.184806,-266.841217,0.019443,0.000000
21.190001,11.802719,-266.841217,-0.004130,0.000745,0.018914,52.501118,2.674534,0.189142,-266.841217,0.020007,0.000000
21.530001,12.744072,-266.885712,-0.004118,0.000777,0.019729,56.688465,2.887848,0.197294,-266.885712,0.020579,0.000000
21.870001,12.678909,-266.841217,-0.004092,0.000795,0.020180,56.398605,2.873082,0.201803,-266.841217,0.021143,0.000000
22.210001,13.041969,-266.885712,-0.004070,0.000816,0.020727,58.013577,2.955352,0.207267,-266.885712,0.021707,0.000000
22.550001,13.601646,-266.885712,-0.004044,0.000841,0.021368,60.503143,3.082177,0.213684,-266.885712,0.022279,0.000000
22.890001,13.694366,-266.930176,-0.004049,0.000859,0.021819,60.915585,3.103188,0.218194,-266.930176,0.022843,0.000000
23.230001,13.816505,-266.930176,-0.004010,0.000874,0.022210,61.458885,3.130865,0.222096,-266.930176,0.023406,0.000000
23.570002,14.645409,-266.974670,-0.004001,0.000905,0.022990,65.146034,3.318697,0.229902,-266.974670,0.023979,0.000000
23.910002,14.887825,-267.019135,-0.003980,0.000927,0.023554,66.224350,3.373629,0.235538,-267.019135,0.024542,0.000000
24.250002,15.098213,-266.930176,-0.003949,0.000947,0.024057,67.160210,3.421304,0.240568,-266.930176,0.025115,0.000000
24.590002,15.769600,-267.019135,-0.003932,0.000975,0.024768,70.146683,3.573442,0.247680,-267.019135,0.025679,0.000000
24.930000,15.878708,-266.974670,-0.003911,0.000997,0.025323,70.632019,3.598166,0.253230,-266.974670,0.026242,0.000000
25.270000,15.510803,-267.063629,-0.003902,0.001003,0.025479,68.995499,3.514798,0.254791,-267.063629,0.026815,0.000000
25.610001,16.734047,-267.019135,-0.003863,0.001041,0.026442,74.436760,3.791989,0.264417,-267.019135,0.027378,0.000000
25.950001,16.636482,-267.019135,-0.003867,0.001060,0.026927,74.002769,3.769881,0.269274,-267.019135,0.027942,0.000000
26.290001,17.010345,-267.063629,-0.003833,0.001083,0.027500,75.665794,3.854599,0.274997,-267.063629,0.028514,0.000000
26.630001,17.510811,-267.063629,-0.003798,0.001110,0.028185,77.891975,3.968006,0.281848,-267.063629,0.029078,0.000000
26.970001,17.602043,-267.108124,-0.003781,0.001128,0.028644,78.297798,3.988680,0.286445,-267.108124,0.029642,0.000000
27.310001,18.309181,-267.152588,-0.003768,0.001158,0.029408,81.443306,4.148920,0.294076,-267.152588,0.030214,0.000000
27.650002,18.304710,-267.063629,-0.003751,0.001176,0.029859,81.423416,4.147907,0.298586,-267.063629,0.030778,0.000000
27.990002,18.598511,-267.108124,-0.003734,0.001199,0.030466,82.730309,4.214483,0.304656,-267.108124,0.031342,0.000000
28.330002,18.795876,-267.152588,-0.003699,0.001219,0.030969,83.608231,4.259206,0.309686,-267.152588,0.031914,0.000000
28.670002,19.175690,-267.108124,-0.003695,0.001240,0.031498,85.297729,4.345273,0.314976,-267.108124,0.032478,0.000000
29.010002,19.269531,-267.197083,-0.003673,0.001259,0.031966,85.715157,4.366538,0.319659,-267.197083,0.033041,0.000000
29.350002,20.097687,-267.197083,-0.003639,0.001292,0.032824,89.398979,4.554201,0.328245,-267.197083,0.033614,0.000000
29.690001,19.721214,-267.152588,-0.003630,0.001306,0.033171,87.724342,4.468891,0.331714,-267.152588,0.034177,0.000000
30.030001,20.333023,-267.197083,-0.003617,0.001332,0.033822,90.445801,4.607529,0.338218,-267.197083,0.034741,0.000000
30.370001,20.413086,-267.197083,-0.003591,0.001350,0.034281,90.801941,4.625671,0.342814,-267.197083,0.035313,0.000000
30.710001,20.763489,-267.286041,-0.003579,0.001369,0.034776,92.360611,4.705074,0.347757,-267.286041,0.035877,0.000000
31.050001,20.861046,-267.241547,-0.003561,0.001388,0.035244,92.794563,4.727181,0.352441,-267.241547,0.036441,0.000000
31.390001,22.058228,-267.286041,-0.003523,0.001424,0.036172,98.119896,4.998466,0.361720,-267.286041,0.037013,0.000000
31.730001,21.786766,-267.330505,-0.003514,0.001442,0.036614,96.912376,4.936952,0.366143,-267.330505,0.037577,0.000000
32.070000,21.756233,-267.286041,-0.003484,0.001460,0.037083,96.776558,4.930033,0.370826,-267.286041,0.038141,0.000000
32.410000,22.442146,-267.330505,-0.003475,0.001487,0.037759,99.827652,5.085463,0.377590,-267.330505,0.038713,0.000000
32.750000,22.019127,-267.330505,-0.003445,0.001495,0.037967,97.945969,4.989605,0.379671,-267.330505,0.039277,0.000000
33.090000,22.361336,-267.375000,-0.003454,0.001519,0.038592,99.468185,5.067151,0.385915,-267.375000,0.039849,0.000000
33.430000,23.745445,-267.463959,-0.003419,0.001557,0.039554,105.625015,5.380795,0.395542,-267.463959,0.040413,0.000000
33.770000,23.473244,-267.375000,-0.003397,0.001576,0.040031,104.414200,5.319113,0.400311,-267.375000,0.040976,0.000000
34.110001,24.039619,-267.463959,-0.003372,0.001602,0.040690,106.933571,5.447455,0.406902,-267.463959,0.041549,0.000000
34.450001,24.091377,-267.419464,-0.003354,0.001620,0.041159,107.163795,5.459184,0.411585,-267.419464,0.042112,0.000000
34.790001,24.189690,-267.419464,-0.003341,0.001636,0.041566,107.601112,5.481462,0.415661,-267.419464,0.042676,0.000000
35.130001,24.852135,-267.508453,-0.003328,0.001664,0.042260,110.547813,5.631575,0.422599,-267.508453,0.043249,0.000000
35.470001,25.182808,-267.463959,-0.003303,0.001686,0.042832,112.018723,5.706506,0.428323,-267.463959,0.043812,0.000000
35.810001,25.332870,-267.463959,-0.003285,0.001707,0.043361,112.686234,5.740510,0.433613,-267.463959,0.044376,0.000000
36.150002,25.992714,-267.508453,-0.003264,0.001734,0.044055,115.621368,5.890033,0.440551,-267.508453,0.044948,0.000000
36.490002,25.873924,-267.508453,-0.003251,0.001750,0.044454,115.092964,5.863115,0.444540,-267.508453,0.045512,0.000000
36.830002,26.006119,-267.597412,-0.003221,0.001770,0.044957,115.680992,5.893071,0.449570,-267.597412,0.046076,0.000000
37.170002,26.927368,-267.597412,-0.003199,0.001798,0.045677,119.778915,6.101829,0.456768,-267.597412,0.046648,0.000000
37.510002,27.324318,-267.552917,-0.003186,0.001823,0.046301,121.544640,6.191779,0.463012,-267.552917,0.047212,0.000000
37.850002,27.328041,-267.597412,-0.003173,0.001844,0.046839,121.561195,6.192623,0.468389,-267.597412,0.047775,0.000000
38.190002,27.901497,-267.597412,-0.003152,0.001867,0.047411,124.112061,6.322569,0.474112,-267.597412,0.048348,0.000000
38.530003,27.450928,-267.641876,-0.003117,0.001880,0.047749,122.107826,6.220469,0.477494,-267.641876,0.048912,0.000000
38.870003,29.056969,-267.641876,-0.003100,0.001913,0.048599,129.251846,6.584403,0.485993,-267.641876,0.049475,0.000000
39.210003,29.343323,-267.686371,-0.003091,0.001936,0.049163,130.525620,6.649292,0.491630,-267.686371,0.050048,0.000000
39.550003,29.214851,-267.686371,-0.003065,0.001954,0.049631,129.954147,6.620180,0.496313,-267.686371,0.050611,0.000000
39.890003,29.416679,-267.641876,-0.003040,0.001978,0.050247,130.851929,6.665915,0.502471,-267.641876,0.051175,0.000000
40.230003,29.892197,-267.686371,-0.003018,0.001999,0.050776,132.967133,6.773669,0.507761,-267.686371,0.051747,0.000000
40.570004,30.102592,-267.730835,-0.003009,0.002016,0.051218,133.903015,6.821345,0.512183,-267.730835,0.052311,0.000000
40.910004,31.281151,-267.775330,-0.002979,0.002048,0.052016,139.145508,7.088410,0.520162,-267.775330,0.052883,0.000000
41.250004,31.599899,-267.775330,-0.002971,0.002069,0.052563,140.563370,7.160640,0.525626,-267.775330,0.053447,0.000000
41.590000,31.495262,-267.730835,-0.002945,0.002086,0.052996,140.097916,7.136929,0.529962,-267.730835,0.054011,0.000000
41.930000,32.185272,-267.775330,-0.002940,0.002112,0.053655,143.167236,7.293287,0.536552,-267.775330,0.054583,0.000000
42.270000,32.089569,-267.775330,-0.002923,0.002128,0.054054,142.741531,7.271601,0.540542,-267.775330,0.055147,0.000000
42.610001,32.165161,-267.819794,-0.002893,0.002146,0.054496,143.077789,7.288730,0.544965,-267.819794,0.055711,0.000000
42.950001,33.761894,-267.819794,-0.002880,0.002181,0.055398,150.180405,7.650555,0.553984,-267.819794,0.056283,0.000000
43.290001,33.961113,-267.819794,-0.002867,0.002200,0.055875,151.066574,7.695698,0.558753,-267.819794,0.056847,0.000000
43.630001,34.048622,-267.953247,-0.002850,0.002218,0.056326,151.455841,7.715528,0.563263,-267.953247,0.057410,0.000000
43.970001,34.683144,-267.819794,-0.002833,0.002243,0.056968,154.278336,7.859313,0.569681,-267.819794,0.057983,0.000000
44.310001,34.810493,-267.908783,-0.002828,0.002259,0.057384,154.844803,7.888170,0.573843,-267.908783,0.058546,0.000000
44.650002,34.778473,-267.908783,-0.002794,0.002278,0.057861,154.702377,7.880915,0.578613,-267.908783,0.059110,0.000000
44.990002,36.234077,-267.908783,-0.002781,0.002309,0.058642,161.177231,8.210759,0.586418,-267.908783,0.059682,0.000000
45.330002,36.962433,-268.042206,-0.002759,0.002332,0.059232,164.417114,8.375807,0.592315,-268.042206,0.060246,0.000000
45.670002,37.034676,-267.997742,-0.002746,0.002351,0.059717,164.738464,8.392177,0.597172,-267.997742,0.060810,0.000000
46.010002,38.231110,-267.953247,-0.002738,0.002381,0.060480,170.060471,8.663293,0.604803,-267.953247,0.061382,0.000000
46.350002,38.372238,-268.042206,-0.002708,0.002398,0.060897,170.688248,8.695273,0.608966,-268.042206,0.061946,0.000000
46.690002,38.857437,-267.997742,-0.002699,0.002421,0.061495,172.846512,8.805222,0.614950,-267.997742,0.062510,0.000000
47.030003,39.672188,-268.086700,-0.002686,0.002445,0.062102,176.470703,8.989846,0.621020,-268.086700,0.063082,0.000000
47.370003,39.910133,-267.997742,-0.002660,0.002466,0.062640,177.529144,9.043766,0.626397,-267.997742,0.063646,0.000000
47.710003,40.663445,-268.086700,-0.002647,0.002491,0.063273,180.880035,9.214468,0.632728,-268.086700,0.064209,0.000000
48.050003,41.420479,-268.042206,-0.002634,0.002515,0.063871,184.247498,9.386015,0.638712,-268.042206,0.064782,0.000000
48.390003,41.269669,-268.086700,-0.002608,0.002528,0.064209,183.576660,9.351841,0.642094,-268.086700,0.065345,0.000000
48.730003,42.773682,-268.220123,-0.002596,0.002562,0.065077,190.266846,9.692656,0.650766,-268.220123,0.065909,0.000000
49.070004,42.930450,-268.175659,-0.002578,0.002581,0.065545,190.964188,9.728179,0.655449,-268.175659,0.066482,0.000000
49.410004,43.362404,-268.175659,-0.002565,0.002602,0.066083,192.885605,9.826061,0.660826,-268.175659,0.067045,0.000000
49.750004,43.817810,-268.175659,-0.002531,0.002624,0.066638,194.911346,9.929257,0.666376,-268.175659,0.067618,0.000000
50.090004,44.503349,-268.131165,-0.002539,0.002649,0.067279,197.960785,10.084603,0.672794,-268.131165,0.068181,0.000000
50.430004,45.106224,-268.220123,-0.002505,0.002671,0.067843,200.642502,10.221216,0.678431,-268.220123,0.068745,0.000000
50.770004,46.212166,-268.220123,-0.002514,0.002695,0.068450,205.561981,10.471827,0.684501,-268.220123,0.069317,0.000000
51.110001,46.245308,-268.264618,-0.002488,0.002712,0.068892,205.709396,10.479337,0.688924,-268.264618,0.069881,0.000000
51.450001,46.872757,-268.220123,-0.002475,0.002734,0.069447,208.500443,10.621518,0.694474,-268.220123,0.070445,0.000000
51.790001,47.254440,-268.264618,-0.002462,0.002754,0.069959,210.198242,10.708010,0.699591,-268.264618,0.071017,0.000000
52.130001,48.267288,-268.309082,-0.002432,0.002778,0.070566,214.703629,10.937524,0.705662,-268.309082,0.071581,0.000000
52.470001,47.683037,-268.309082,-0.002436,0.002786,0.070774,212.104736,10.805130,0.707743,-268.309082,0.072145,0.000000
52.810001,50.026009,-268.353577,-0.002427,0.002825,0.071763,222.526794,11.336056,0.717629,-268.353577,0.072717,0.000000
53.150002,50.346245,-268.353577,-0.002402,0.002845,0.072275,223.951279,11.408622,0.722746,-268.353577,0.073281,0.000000
53.490002,50.209213,-268.353577,-0.002402,0.002859,0.072621,223.341736,11.377570,0.726215,-268.353577,0.073844,0.000000
53.830002,51.625343,-268.398071,-0.002380,0.002887,0.073341,229.640991,11.698469,0.733413,-268.398071,0.074417,0.000000
54.170002,52.118736,-268.398071,-0.002358,0.002906,0.073818,231.835724,11.810275,0.738182,-268.398071,0.074980,0.000000
54.510002,53.868515,-268.398071,-0.002363,0.002940,0.074685,239.619125,12.206779,0.746855,-268.398071,0.075544,0.000000
54.850002,54.182426,-268.487030,-0.002320,0.002959,0.075162,241.015472,12.277914,0.751624,-268.487030,0.076116,0.000000
55.190002,54.649384,-268.398071,-0.002320,0.002979,0.075657,243.092606,12.383727,0.756568,-268.398071,0.076680,0.000000
55.530003,55.545311,-268.487030,-0.002302,0.003004,0.076299,247.077881,12.586748,0.762985,-268.487030,0.077244,0.000000
55.870003,55.851028,-268.442535,-0.002307,0.003020,0.076715,248.437790,12.656024,0.767148,-268.442535,0.077816,0.000000
56.210003,56.301598,-268.487030,-0.002276,0.003042,0.077278,250.442017,12.758124,0.772785,-268.487030,0.078380,0.000000
56.550003,57.184120,-268.531494,-0.002268,0.003065,0.077851,254.367676,12.958107,0.778508,-268.531494,0.078944,0.000000
56.890003,58.373482,-268.487030,-0.002255,0.003092,0.078545,259.658203,13.227620,0.785446,-268.487030,0.079516,0.000000
57.230003,58.665047,-268.575989,-0.002229,0.003111,0.079013,260.955170,13.293689,0.790129,-268.575989,0.080080,0.000000
57.570004,60.131821,-268.531494,-0.002229,0.003138,0.079715,267.479706,13.626065,0.797154,-268.531494,0.080643,0.000000
57.910004,59.811584,-268.620453,-0.002229,0.003154,0.080106,266.055206,13.553499,0.801056,-268.620453,0.081216,0.000000
58.250004,60.236084,-268.620453,-0.002199,0.003172,0.080574,267.943481,13.649692,0.805739,-268.620453,0.081779,0.000000
58.590004,62.026077,-268.575989,-0.002199,0.003205,0.081406,275.905762,14.055310,0.814065,-268.575989,0.082352,0.000000
58.930004,62.828171,-268.664948,-0.002169,0.003228,0.081988,279.473663,14.237067,0.819875,-268.664948,0.082915,0.000000
59.270004,63.502914,-268.575989,-0.002160,0.003252,0.082603,282.475067,14.389966,0.826032,-268.575989,0.083479,0.000000
59.610004,63.832092,-268.664948,-0.002151,0.003266,0.082967,283.939331,14.464560,0.829675,-268.664948,0.084052,0.000000
59.950005,64.213776,-268.664948,-0.002139,0.003288,0.083514,285.637146,14.551049,0.835138,-268.664948,0.084615,0.000000
60.290005,65.584106,-268.664948,-0.002134,0.003312,0.084121,291.732666,14.861570,0.841209,-268.664948,0.085179,0.000000
60.630001,65.318604,-268.709412,-0.002108,0.003320,0.084320,290.551666,14.801407,0.843203,-268.709412,0.014802,0.000000
60.970001,66.735474,-268.664948,-0.002074,0.003091,0.078519,296.854218,15.122475,0.785186,-268.664948,294.500458,0.000000
61.310001,65.833588,-268.798401,-0.002061,0.003316,0.084234,292.842438,14.918104,0.842336,-268.798401,294.500458,0.000000
61.650002,65.336838,-268.798401,-0.002048,0.003360,0.085335,290.632782,14.805539,0.853350,-268.798401,294.500458,0.000000
61.990002,65.217682,-268.753906,-0.002057,0.003381,0.085873,290.102753,14.778538,0.858727,-268.753906,294.500458,0.000000
62.330002,65.333115,-268.842865,-0.002048,0.003391,0.086133,290.616211,14.804696,0.861329,-268.842865,294.500458,0.000000
62.670002,64.968201,-268.798401,-0.002044,0.003402,0.086402,288.992981,14.722005,0.864017,-268.798401,294.500458,0.000000
63.010002,65.329391,-268.887360,-0.002057,0.003416,0.086766,290.599640,14.803851,0.867659,-268.887360,294.500458,0.000000
63.350002,67.282486,-268.798401,-0.002031,0.003395,0.086237,299.287445,15.246429,0.862369,-268.798401,294.500458,0.000000
63.690002,65.688736,-268.887360,-0.002035,0.003352,0.085153,292.198090,14.885280,0.851529,-268.887360,294.500458,0.000000
64.030006,65.984772,-268.887360,-0.002026,0.003449,0.087616,293.514923,14.952363,0.876158,-268.887360,294.500458,0.000000
64.370003,66.092758,-268.842865,-0.002009,0.003473,0.088214,293.995270,14.976833,0.882142,-268.842865,294.500458,0.000000
64.710007,65.005798,-268.931824,-0.002018,0.003462,0.087928,289.160248,14.730524,0.879280,-268.931824,294.500458,0.000000
65.050003,65.253799,-268.931824,-0.001992,0.003473,0.088206,290.263397,14.786722,0.882055,-268.931824,294.500458,0.000000
65.389999,65.256790,-268.976318,-0.002009,0.003491,0.088674,290.276703,14.787400,0.886738,-268.976318,294.500458,0.000000
65.730003,65.298111,-268.976318,-0.001988,0.003504,0.089012,290.460510,14.796764,0.890121,-268.976318,294.500458,0.000000
66.070000,65.296249,-268.976318,-0.002013,0.003515,0.089272,290.452209,14.796342,0.892722,-268.976318,294.500458,0.000000
66.410004,65.340942,-269.020782,-0.001992,0.003526,0.089567,290.651031,14.806470,0.895671,-269.020782,294.500458,0.000000
66.750000,65.513351,-268.931824,-0.001970,0.003537,0.089845,291.417938,14.845537,0.898446,-268.931824,294.500458,0.000000
67.090004,65.114914,-268.976318,-0.001975,0.003542,0.089957,289.645599,14.755250,0.899573,-268.976318,294.500458,0.000000
67.430000,65.106339,-269.065277,-0.001966,0.003550,0.090174,289.607452,14.753307,0.901741,-269.065277,294.500458,0.000000
67.770004,66.363480,-269.020782,-0.001970,0.003543,0.090001,295.199493,15.038179,0.900007,-269.020782,294.500458,0.000000
68.110001,65.313751,-269.109741,-0.001957,0.003547,0.090087,290.530090,14.800307,0.900874,-269.109741,294.500458,0.000000
68.450005,65.549469,-269.154236,-0.001953,0.003577,0.090859,291.578613,14.853722,0.908592,-269.154236,294.500458,0.000000
68.790001,66.118088,-269.109741,-0.001944,0.003594,0.091275,294.107941,14.982573,0.912755,-269.109741,294.500458,0.000000
69.130005,65.176346,-269.109741,-0.001949,0.003586,0.091076,289.918854,14.769171,0.910760,-269.109741,294.500458,0.000000
69.470001,65.168533,-269.198730,-0.001957,0.003603,0.091510,289.884125,14.767401,0.915097,-269.198730,294.500458,0.000000
69.810005,65.391953,-269.154236,-0.001949,0.003611,0.091709,290.877930,14.818028,0.917091,-269.154236,294.500458,0.000000
70.150002,65.121979,-269.198730,-0.001923,0.003615,0.091831,289.677032,14.756851,0.918305,-269.198730,294.500458,0.000000
70.490005,65.392700,-269.198730,-0.001932,0.003625,0.092065,290.881256,14.818198,0.920647,-269.198730,294.500458,0.000000
70.830002,64.696732,-269.243195,-0.001927,0.003625,0.092065,287.785431,14.660489,0.920647,-269.243195,294.500458,0.000000
71.170006,68.601059,-269.154236,-0.001923,0.003612,0.091744,305.152740,15.545221,0.917438,-269.154236,294.500458,0.000000
71.510002,65.482071,-269.287689,-0.001893,0.003630,0.092212,291.278809,14.838449,0.922121,-269.287689,294.500458,0.000000
71.850006,65.212845,-269.243195,-0.001893,0.003642,0.092498,290.081207,14.777442,0.924983,-269.243195,294.500458,0.000000
72.190002,65.176346,-269.198730,-0.001888,0.003652,0.092750,289.918854,14.769171,0.927498,-269.198730,294.500458,0.000000
72.530006,65.000214,-269.243195,-0.001888,0.003658,0.092915,289.135376,14.729259,0.929146,-269.243195,294.500458,0.000000
72.870003,65.381531,-269.287689,-0.001871,0.003669,0.093183,290.831573,14.815667,0.931834,-269.287689,294.500458,0.000000
73.210007,64.794662,-269.376648,-0.001876,0.003670,0.093227,288.221039,14.682680,0.932268,-269.376648,294.500458,0.000000
73.550003,65.694687,-269.332153,-0.001880,0.003686,0.093617,292.224548,14.886628,0.936170,-269.332153,294.500458,0.000000
73.890007,65.261993,-269.376648,-0.001897,0.003686,0.093626,290.299835,14.788579,0.936257,-269.376648,294.500458,0.000000
74.230003,65.199066,-269.421112,-0.001876,0.003692,0.093782,290.019928,14.774320,0.937818,-269.421112,294.500458,0.000000
74.570007,65.491745,-269.421112,-0.001876,0.003702,0.094033,291.321838,14.840642,0.940333,-269.421112,294.500458,0.000000
74.910004,65.077301,-269.465607,-0.001888,0.003702,0.094033,289.478302,14.746727,0.940333,-269.465607,294.500458,0.000000
75.250000,65.176346,-269.421112,-0.001876,0.003709,0.094207,289.918854,14.769171,0.942067,-269.421112,294.500458,0.000000
75.590004,65.512238,-269.421112,-0.001893,0.003718,0.094432,291.412994,14.845285,0.944322,-269.421112,294.500458,0.000000
75.930000,65.046021,-269.421112,-0.001867,0.003719,0.094458,289.339142,14.739638,0.944582,-269.421112,294.500458,0.000000
76.270004,65.433655,-269.421112,-0.001884,0.003727,0.094666,291.063446,14.827478,0.946664,-269.421112,294.500458,0.000000
76.610001,65.082138,-269.510071,-0.001871,0.003729,0.094718,289.499817,14.747823,0.947184,-269.510071,294.500458,0.000000
76.950005,65.296997,-269.510071,-0.001867,0.003737,0.094909,290.455536,14.796512,0.949092,-269.510071,294.500458,0.000000
77.290001,65.215073,-269.554565,-0.001871,0.003741,0.095013,290.091125,14.777947,0.950132,-269.554565,294.500458,0.000000
77.630005,65.130173,-269.554565,-0.001863,0.003744,0.095091,289.713470,14.758708,0.950913,-269.554565,294.500458,0.000000
77.970001,65.161453,-269.510071,-0.001858,0.003750,0.095239,289.852631,14.765797,0.952387,-269.510071,294.500458,0.000000
78.310005,65.053848,-269.599030,-0.001858,0.003753,0.095317,289.373962,14.741412,0.953168,-269.599030,294.500458,0.000000
78.650002,65.065384,-269.599030,-0.001850,0.003756,0.095412,289.425293,14.744026,0.954122,-269.599030,294.500458,0.000000
78.990005,65.226242,-269.643524,-0.001854,0.003762,0.095551,290.140808,14.780478,0.955509,-269.643524,294.500458,0.000000
79.330002,65.543884,-269.599030,-0.001841,0.003768,0.095716,291.553772,14.852456,0.957157,-269.599030,294.500458,0.000000
79.670006,65.168900,-269.643524,-0.001867,0.003768,0.095716,289.885742,14.767485,0.957157,-269.643524,294.500458,0.000000
80.010002,64.760788,-269.643524,-0.001850,0.003768,0.095716,288.070374,14.675004,0.957157,-269.643524,294.500458,0.000000
80.350006,66.376877,-269.688019,-0.001837,0.003751,0.095282,295.259094,15.041216,0.952821,-269.688019,294.500458,0.000000
80.690002,65.845505,-269.732483,-0.001841,0.003751,0.095282,292.895447,14.920805,0.952821,-269.732483,294.500458,0.000000
81.030006,65.486908,-269.732483,-0.001845,0.003751,0.095282,291.300323,14.839546,0.952821,-269.732483,294.500458,0.000000
81.370003,65.195343,-269.732483,-0.001845,0.003780,0.096019,290.003357,14.773476,0.960192,-269.732483,294.500458,0.000000
81.710007,65.377060,-269.776978,-0.001832,0.003792,0.096314,290.811676,14.814653,0.963141,-269.776978,294.500458,0.000000
82.050003,65.176346,-269.776978,-0.001832,0.003792,0.096305,289.918854,14.769171,0.963054,-269.776978,294.500458,0.000000
82.390007,65.176346,-269.821442,-0.001832,0.003796,0.096418,289.918854,14.769171,0.964182,-269.821442,294.500458,0.000000
82.730003,64.956650,-269.776978,-0.001832,0.003797,0.096453,288.941620,14.719388,0.964528,-269.776978,294.500458,0.000000
83.070007,64.793549,-269.821442,-0.001832,0.003800,0.096514,288.216095,14.682427,0.965135,-269.821442,294.500458,0.000000
83.410004,65.774384,-269.865936,-0.001824,0.003813,0.096860,292.579071,14.904688,0.968604,-269.865936,294.500458,0.000000
83.750008,65.563614,-269.821442,-0.001828,0.003813,0.096860,291.641510,14.856928,0.968604,-269.821442,294.500458,0.000000
84.090004,65.278381,-269.910400,-0.001832,0.003813,0.096860,290.372742,14.792293,0.968604,-269.910400,294.500458,0.000000
84.430000,64.980484,-269.821442,-0.001807,0.003814,0.096869,289.047638,14.724789,0.968691,-269.821442,294.500458,0.000000
84.770004,65.095917,-269.865936,-0.001819,0.003819,0.096999,289.561096,14.750946,0.969992,-269.865936,294.500458,0.000000
85.110001,65.066132,-269.954895,-0.001828,0.003822,0.097077,289.428619,14.744196,0.970772,-269.954895,294.500458,0.000000
85.450005,65.050858,-269.821442,-0.001824,0.003825,0.097155,289.360657,14.740735,0.971553,-269.821442,294.500458,0.000000
85.790001,65.305939,-269.954895,-0.001828,0.003830,0.097285,290.495331,14.798536,0.972854,-269.954895,294.500458,0.000000
86.130005,65.174866,-269.954895,-0.001815,0.003831,0.097311,289.912292,14.768836,0.973114,-269.954895,294.500458,0.000000
86.470001,65.531967,-269.954895,-0.001802,0.003838,0.097485,291.500763,14.849756,0.974848,-269.954895,294.500458,0.000000
86.810005,65.342804,-270.043854,-0.001819,0.003838,0.097485,290.659302,14.806890,0.974848,-270.043854,294.500458,0.000000
87.150002,65.129059,-269.999359,-0.001811,0.003839,0.097520,289.708527,14.758455,0.975195,-269.999359,294.500458,0.000000
87.490005,65.298859,-270.043854,-0.001824,0.003844,0.097641,290.463837,14.796933,0.976409,-270.043854,294.500458,0.000000
87.830002,65.200928,-270.043854,-0.001815,0.003844,0.097641,290.028198,14.774741,0.976409,-270.043854,294.500458,0.000000
88.170006,65.588562,-269.999359,-0.001807,0.003852,0.097832,291.752502,14.862580,0.978317,-269.999359,294.500458,0.000000
88.510002,65.477966,-270.088348,-0.001794,0.003852,0.097832,291.260529,14.837520,0.978317,-270.088348,294.500458,0.000000
88.850006,65.264969,-269.999359,-0.001802,0.003852,0.097840,290.313080,14.789253,0.978404,-269.999359,294.500458,0.000000
89.190002,65.119385,-270.088348,-0.001802,0.003854,0.097901,289.665497,14.756263,0.979011,-270.088348,294.500458,0.000000
89.530006,65.216934,-270.132812,-0.001794,0.003857,0.097970,290.099426,14.778368,0.979705,-270.132812,294.500458,0.000000
89.870003,65.142838,-270.132812,-0.001815,0.003859,0.098014,289.769806,14.761578,0.980138,-270.132812,294.500458,0.000000
90.210007,65.069473,-270.177307,-0.001789,0.003860,0.098049,289.443481,14.744953,0.980485,-270.177307,294.500458,0.000000
90.550003,65.168533,-270.132812,-0.001785,0.003864,0.098135,289.884125,14.767401,0.981353,-270.132812,294.500458,0.000000
90.890007,65.207626,-270.177307,-0.001794,0.003866,0.098187,290.058014,14.776259,0.981873,-270.177307,294.500458,0.000000
91.230003,65.216202,-270.221771,-0.001785,0.003868,0.098248,290.096161,14.778203,0.982480,-270.221771,294.500458,0.000000
91.570007,65.215073,-270.221771,-0.001798,0.003870,0.098300,290.091125,14.777947,0.983000,-270.221771,294.500458,0.000000
91.910004,65.236298,-270.177307,-0.001794,0.003873,0.098378,290.185547,14.782756,0.983781,-270.177307,294.500458,0.000000
92.250008,65.232956,-270.221771,-0.001794,0.003873,0.098378,290.170685,14.782000,0.983781,-270.221771,294.500458,0.000000
92.590004,65.095917,-270.310730,-0.001798,0.003876,0.098439,289.561096,14.750946,0.984388,-270.310730,294.500458,0.000000
92.930008,65.098160,-270.266266,-0.001785,0.003876,0.098447,289.571075,14.751454,0.984475,-270.266266,294.500458,0.000000
93.270004,65.251205,-270.266266,-0.001794,0.003881,0.098569,290.251862,14.786135,0.985689,-270.266266,294.500458,0.000000
93.610008,65.213211,-270.310730,-0.001781,0.003881,0.098569,290.082855,14.777525,0.985689,-270.310730,294.500458,0.000000
93.950005,65.120499,-270.310730,-0.001785,0.003883,0.098621,289.670441,14.756516,0.986209,-270.310730,294.500458,0.000000
94.290001,65.072083,-270.355225,-0.001785,0.003883,0.098621,289.455078,14.745544,0.986209,-270.355225,294.500458,0.000000
94.630005,65.267578,-270.399689,-0.001768,0.003886,0.098716,290.324677,14.789845,0.987163,-270.399689,294.500458,0.000000
94.970001,65.153259,-270.355225,-0.001776,0.003887,0.098725,289.816162,14.763940,0.987250,-270.355225,294.500458,0.000000
95.310005,65.209488,-270.444183,-0.001785,0.003889,0.098786,290.066284,14.776682,0.987857,-270.444183,294.500458,0.000000
95.650002,65.088104,-270.355225,-0.001776,0.003890,0.098794,289.526337,14.749176,0.987944,-270.355225,294.500458,0.000000
95.990005,65.324554,-270.399689,-0.001772,0.003894,0.098898,290.578125,14.802755,0.988984,-270.399689,294.500458,0.000000
96.330002,65.248215,-270.399689,-0.001763,0.003894,0.098898,290.238556,14.785457,0.988984,-270.399689,294.500458,0.000000
96.670006,65.247849,-270.488678,-0.001785,0.003896,0.098959,290.236938,14.785374,0.989591,-270.488678,294.500458,0.000000
97.010002,65.166672,-270.444183,-0.001768,0.003896,0.098959,289.875824,14.766979,0.989591,-270.444183,294.500458,0.000000
97.350006,65.335724,-270.488678,-0.001763,0.003900,0.099063,290.627808,14.805286,0.990632,-270.488678,294.500458,0.000000
97.690002,65.273544,-270.533142,-0.001781,0.003900,0.099063,290.351227,14.791197,0.990632,-270.533142,294.500458,0.000000
98.030006,65.176346,-270.533142,-0.001781,0.003900,0.099063,289.918854,14.769171,0.990632,-270.533142,294.500458,0.000000
98.370003,65.176727,-270.533142,-0.001798,0.003902,0.099115,289.920563,14.769257,0.991152,-270.533142,294.500458,0.000000
98.710007,65.165176,-270.533142,-0.001772,0.003904,0.099150,289.869171,14.766640,0.991499,-270.533142,294.500458,0.000000
99.050003,65.313385,-270.533142,-0.001759,0.003907,0.099245,290.528442,14.800224,0.992453,-270.533142,294.500458,0.000000
99.390007,65.288437,-270.622101,-0.001763,0.003907,0.099245,290.417480,14.794571,0.992453,-270.622101,294.500458,0.000000
99.730003,65.241516,-270.533142,-0.001768,0.003909,0.099280,290.208771,14.783938,0.992800,-270.533142,294.500458,0.000000
100.070007,65.210236,-270.666595,-0.001781,0.003910,0.099306,290.069611,14.776851,0.993060,-270.666595,294.500458,0.000000
100.410004,65.193481,-270.622101,-0.001759,0.003910,0.099323,289.995087,14.773054,0.993234,-270.622101,294.500458,0.000000
100.750008,65.268326,-270.577637,-0.001763,0.003913,0.099384,290.328003,14.790014,0.993841,-270.577637,294.500458,0.000000
101.090004,65.381531,-270.622101,-0.001768,0.003916,0.099471,290.831573,14.815667,0.994708,-270.622101,294.500458,0.000000
101.430008,65.399033,-270.711060,-0.001763,0.003916,0.099471,290.909424,14.819633,0.994708,-270.711060,294.500458,0.000000
101.770004,65.356949,-270.666595,-0.001768,0.003917,0.099497,290.722229,14.810097,0.994968,-270.666595,294.500458,0.000000
102.110008,65.354721,-270.755554,-0.001772,0.003918,0.099523,290.712311,14.809591,0.995228,-270.755554,294.500458,0.000000
102.450005,65.333862,-270.666595,-0.001772,0.003919,0.099549,290.619537,14.804865,0.995488,-270.666595,294.500458,0.000000
102.790009,65.296249,-270.800018,-0.001763,0.003920,0.099566,290.452209,14.796342,0.995662,-270.800018,294.500458,0.000000
103.130005,65.314499,-270.711060,-0.001759,0.003922,0.099610,290.533386,14.800477,0.996095,-270.711060,294.500458,0.000000
103.470001,65.322693,-270.711060,-0.001759,0.003923,0.099636,290.569855,14.802334,0.996356,-270.711060,294.500458,0.000000
103.810005,65.263489,-270.800018,-0.001746,0.003923,0.099636,290.306488,14.788918,0.996356,-270.800018,294.500458,0.000000
104.150002,65.186035,-270.844513,-0.001759,0.003923,0.099636,289.961975,14.771367,0.996356,-270.844513,294.500458,0.000000
104.490005,65.132782,-270.800018,-0.001763,0.003924,0.099662,289.725098,14.759299,0.996616,-270.800018,294.500458,0.000000
104.830002,65.094055,-270.800018,-0.001738,0.003924,0.099679,289.552826,14.750524,0.996789,-270.800018,294.500458,0.000000
105.170006,65.095169,-270.844513,-0.001759,0.003926,0.099722,289.557770,14.750776,0.997223,-270.844513,294.500458,0.000000
105.510002,65.053101,-270.888977,-0.001759,0.003926,0.099722,289.370636,14.741242,0.997223,-270.888977,294.500458,0.000000
105.850006,65.008041,-270.888977,-0.001742,0.003926,0.099731,289.170197,14.731032,0.997310,-270.888977,294.500458,0.000000
106.190002,65.247849,-270.933472,-0.001750,0.003931,0.099852,290.236938,14.785374,0.998524,-270.933472,294.500458,0.000000
106.530006,65.230713,-270.888977,-0.001755,0.003931,0.099852,290.160706,14.781491,0.998524,-270.888977,294.500458,0.000000
106.870003,65.164429,-270.933472,-0.001768,0.003931,0.099852,289.865845,14.766471,0.998524,-270.933472,294.500458,0.000000
107.210007,65.085114,-270.933472,-0.001738,0.003931,0.099852,289.513031,14.748498,0.998524,-270.933472,294.500458,0.000000
107.550003,65.053101,-271.022430,-0.001763,0.003932,0.099870,289.370636,14.741242,0.998697,-271.022430,294.500458,0.000000
107.890007,65.258652,-270.977966,-0.001763,0.003941,0.100095,290.284973,14.787822,1.000952,-270.977966,294.500458,0.000000
108.230003,65.564362,-270.888977,-0.001763,0.003939,0.100052,291.644836,14.857098,1.000518,-270.888977,294.500458,0.000000
108.570007,65.520050,-271.022430,-0.001755,0.003939,0.100052,291.447723,14.847055,1.000518,-271.022430,294.500458,0.000000
108.910004,65.440369,-270.977966,-0.001759,0.003939,0.100052,291.093292,14.829000,1.000518,-270.977966,294.500458,0.000000
109.250008,65.367386,-270.977966,-0.001746,0.003939,0.100052,290.768646,14.812461,1.000518,-270.977966,294.500458,0.000000
109.590004,65.292160,-271.066925,-0.001750,0.003939,0.100052,290.434021,14.795415,1.000518,-271.066925,294.500458,0.000000
109.930008,65.242630,-271.066925,-0.001738,0.003939,0.100052,290.213715,14.784191,1.000518,-271.066925,294.500458,0.000000
110.270004,65.149918,-271.066925,-0.001768,0.003939,0.100052,289.801300,14.763183,1.000518,-271.066925,294.500458,0.000000
110.610008,65.168900,-271.066925,-0.001742,0.003941,0.100113,289.885742,14.767485,1.001125,-271.066925,294.500458,0.000000
110.950005,65.102249,-271.111389,-0.001759,0.003942,0.100130,289.589264,14.752380,1.001299,-271.111389,294.500458,0.000000
111.290009,65.236298,-271.155884,-0.001750,0.003944,0.100182,290.185547,14.782756,1.001819,-271.155884,294.500458,0.000000
111.630005,65.209122,-271.200348,-0.001759,0.003944,0.100182,290.064667,14.776598,1.001819,-271.200348,294.500458,0.000000
111.970009,65.145813,-271.200348,-0.001750,0.003945,0.100199,289.783051,14.762252,1.001992,-271.200348,294.500458,0.000000
112.310005,65.142090,-271.200348,-0.001746,0.003945,0.100208,289.766479,14.761409,1.002079,-271.200348,294.500458,0.000000
112.650009,65.104111,-271.200348,-0.001738,0.003946,0.100234,289.597534,14.752803,1.002339,-271.200348,294.500458,0.000000
112.990005,65.368118,-271.244843,-0.001759,0.003950,0.100338,290.771912,14.812628,1.003380,-271.244843,294.500458,0.000000
113.330002,65.371475,-271.244843,-0.001738,0.003950,0.100338,290.786835,14.813388,1.003380,-271.244843,294.500458,0.000000
113.670006,65.334610,-271.244843,-0.001746,0.003950,0.100338,290.622864,14.805035,1.003380,-271.244843,294.500458,0.000000
114.010002,65.291046,-271.289307,-0.001755,0.003950,0.100338,290.429077,14.795162,1.003380,-271.289307,294.500458,0.000000
114.350006,65.235184,-271.200348,-0.001746,0.003950,0.100338,290.180603,14.782503,1.003380,-271.200348,294.500458,0.000000
114.690002,65.194595,-271.422760,-0.001742,0.003951,0.100355,290.000031,14.773306,1.003554,-271.422760,294.500458,0.000000
115.030006,65.283600,-271.289307,-0.001733,0.003954,0.100425,290.395966,14.793475,1.004247,-271.289307,294.500458,0.000000
115.370003,65.285828,-271.289307,-0.001755,0.003954,0.100425,290.405853,14.793981,1.004247,-271.289307,294.500458,0.000000
115.710007,65.254547,-271.378296,-0.001742,0.003954,0.100425,290.266724,14.786892,1.004247,-271.378296,294.500458,0.000000
116.050003,65.335358,-271.378296,-0.001733,0.003957,0.100511,290.626190,14.805204,1.005115,-271.378296,294.500458,0.000000
116.390007,65.399033,-271.378296,-0.001750,0.003957,0.100520,290.909424,14.819633,1.005201,-271.378296,294.500458,0.000000
116.730003,65.368866,-271.422760,-0.001733,0.003957,0.100520,290.775238,14.812798,1.005201,-271.422760,294.500458,0.000000
117.070007,65.338333,-271.378296,-0.001750,0.003958,0.100529,290.639435,14.805878,1.005288,-271.378296,294.500458,0.000000
117.410004,65.292526,-271.467255,-0.001746,0.003959,0.100546,290.435669,14.795499,1.005461,-271.467255,294.500458,0.000000
117.750008,65.313019,-271.422760,-0.001729,0.003959,0.100555,290.526825,14.800141,1.005548,-271.422760,294.500458,0.000000
118.090004,65.348022,-271.467255,-0.001759,0.003961,0.100598,290.682526,14.808074,1.005982,-271.467255,294.500458,0.000000
118.430008,65.337967,-271.467255,-0.001742,0.003961,0.100598,290.637787,14.805795,1.005982,-271.467255,294.500458,0.000000
118.770004,65.307434,-271.467255,-0.001750,0.003961,0.100598,290.501984,14.798876,1.005982,-271.467255,294.500458,0.000000
119.110008,65.278748,-271.467255,-0.001729,0.003961,0.100598,290.374359,14.792376,1.005982,-271.467255,294.500458,0.000000
119.450005,65.225876,-271.511719,-0.001733,0.003961,0.100616,290.139191,14.780395,1.006155,-271.511719,294.500458,0.000000
119.790009,65.190506,-271.556213,-0.001729,0.003962,0.100624,289.981842,14.772380,1.006242,-271.556213,294.500458,0.000000
120.130005,65.162567,-271.556213,-0.001729,0.003962,0.100633,289.857574,14.766049,1.006329,-271.556213,294.500458,0.000000
120.470009,65.306305,-271.600677,-0.001738,0.003965,0.100720,290.496948,14.798620,1.007196,-271.600677,294.500458,0.000000
120.810005,65.319717,-271.689636,-0.001750,0.003965,0.100720,290.556610,14.801660,1.007196,-271.689636,294.500458,0.000000
121.150009,65.291412,-271.556213,-0.001733,0.003965,0.100720,290.430695,14.795246,1.007196,-271.556213,1681.640747,0.000000
121.490005,65.203903,-271.600677,-0.001742,0.003957,0.100503,290.041443,14.775416,1.005028,-271.600677,0.100303,0.000000
121.830009,65.051971,-271.645172,-0.001725,0.003938,0.100026,289.365631,14.740987,1.000258,-271.645172,0.099731,0.000000
122.170006,64.977127,-271.645172,-0.001738,0.003918,0.099505,289.032684,14.724028,0.995055,-271.645172,0.099167,0.000000
122.510002,64.837860,-271.645172,-0.001729,0.003901,0.099098,288.413208,14.692470,0.990979,-271.645172,0.098604,0.000000
122.850006,64.766373,-271.645172,-0.001720,0.003883,0.098630,288.095215,14.676270,0.986296,-271.645172,0.098031,0.000000
123.190002,64.698975,-271.734131,-0.001729,0.003866,0.098205,287.795410,14.660997,0.982046,-271.734131,0.097467,0.000000
123.530006,64.676620,-271.778625,-0.001716,0.003840,0.097546,287.695984,14.655931,0.975455,-271.778625,0.096904,0.000000
123.870003,64.604385,-271.689636,-0.001729,0.003820,0.097034,287.374664,14.639563,0.970339,-271.689636,0.096331,0.000000
124.210007,64.483734,-271.734131,-0.001725,0.003797,0.096435,286.837982,14.612224,0.964355,-271.734131,0.095768,0.000000
124.550003,64.377609,-271.734131,-0.001725,0.003769,0.095742,286.365906,14.588175,0.957417,-271.734131,0.095204,0.000000
124.890007,64.346710,-271.823090,-0.001729,0.003751,0.095282,286.228455,14.581173,0.952821,-271.823090,0.094632,0.000000
125.230003,64.145248,-271.823090,-0.001707,0.003736,0.094901,285.332306,14.535521,0.949005,-271.823090,0.094068,0.000000
125.570007,63.845490,-271.823090,-0.001725,0.003717,0.094415,283.998932,14.467595,0.944149,-271.823090,0.093504,0.000000
125.910004,62.907112,-271.823090,-0.001707,0.003689,0.093704,279.824799,14.254955,0.937037,-271.823090,0.092932,0.000000
126.250008,62.295303,-271.867584,-0.001699,0.003672,0.093279,277.103363,14.116318,0.932788,-271.867584,0.092368,0.000000
126.590004,61.048233,-271.823090,-0.001699,0.003649,0.092689,271.556091,13.833728,0.926891,-271.823090,0.091805,0.000000
126.930008,59.878983,-271.867584,-0.001703,0.003630,0.092203,266.355011,13.568771,0.922034,-271.867584,0.091232,0.000000
127.270004,58.535088,-271.867584,-0.001703,0.003613,0.091770,260.377075,13.264240,0.917698,-271.867584,0.090668,0.000000
127.610008,56.593536,-271.912048,-0.001686,0.003588,0.091137,251.740616,12.824279,0.911367,-271.912048,0.090105,0.000000
127.950005,54.514580,-271.912048,-0.001694,0.003564,0.090521,242.492966,12.353180,0.905210,-271.912048,0.089532,0.000000
128.290009,53.202713,-271.912048,-0.001694,0.003550,0.090165,236.657486,12.055906,0.901655,-271.912048,0.088969,0.000000
128.630005,49.322968,-271.912048,-0.001703,0.003509,0.089133,219.399521,11.176744,0.891335,-271.912048,0.088396,0.000000
128.970001,48.011101,-271.956543,-0.001694,0.003499,0.088873,213.564041,10.879471,0.888733,-271.956543,0.087833,0.000000
129.310013,46.330956,-272.001007,-0.001699,0.003481,0.088414,206.090378,10.498745,0.884137,-272.001007,0.087269,0.000000
129.650009,43.502411,-272.001007,-0.001694,0.003457,0.087798,193.508392,9.857787,0.877979,-272.001007,0.086697,0.000000
129.990005,40.689514,-272.001007,-0.001694,0.003429,0.087104,180.996002,9.220376,0.871041,-272.001007,0.086133,0.000000
130.330002,37.606636,-272.001007,-0.001686,0.003399,0.086324,167.282669,8.521785,0.863236,-272.001007,0.085569,0.000000
130.670013,35.846809,-271.956543,-0.001681,0.003382,0.085907,159.454575,8.123003,0.859074,-271.956543,0.084997,0.000000
131.010010,34.514084,-272.089966,-0.001686,0.003367,0.085526,153.526306,7.821003,0.855258,-272.089966,0.084433,0.000000
131.350006,31.807686,-272.089966,-0.001690,0.003339,0.084815,141.487656,7.207725,0.848147,-272.089966,0.083869,0.000000
131.690002,30.378891,-272.089966,-0.001703,0.003331,0.084598,135.132050,6.883955,0.845979,-272.089966,0.083297,0.000000
132.029999,27.308304,-272.178925,-0.001694,0.003298,0.083774,121.473404,6.188150,0.837740,-272.178925,0.082733,0.000000
132.370010,23.781570,-272.089966,-0.001686,0.003267,0.082985,105.785706,5.388981,0.829848,-272.089966,0.082170,0.000000
132.710007,22.165100,-272.178925,-0.001707,0.003251,0.082577,98.595291,5.022684,0.825772,-272.178925,0.081597,0.000000
133.050003,19.603546,-272.178925,-0.001690,0.003224,0.081892,87.200928,4.442227,0.818921,-272.178925,0.081034,0.000000
133.389999,17.132484,-272.134460,-0.001694,0.003204,0.081380,76.209099,3.882277,0.813805,-272.134460,0.080470,0.000000
133.730011,14.780579,-272.223419,-0.001703,0.003182,0.080834,65.747299,3.349327,0.808341,-272.223419,0.079898,0.000000
134.070007,13.323112,-272.134460,-0.001699,0.003168,0.080479,59.264164,3.019060,0.804785,-272.134460,0.079334,0.000000
134.410004,10.414886,-272.223419,-0.001703,0.003140,0.079759,46.327728,2.360047,0.797588,-272.223419,0.078770,0.000000
134.750000,9.007690,-272.178925,-0.001690,0.003128,0.079455,40.068207,2.041172,0.794552,-272.178925,0.078198,0.000000
135.090012,6.454704,-272.267914,-0.001694,0.003102,0.078787,28.711958,1.462657,0.787875,-272.267914,0.077634,0.000000
135.430008,3.406837,-272.267914,-0.001699,0.003069,0.077964,15.154370,0.772000,0.779636,-272.267914,0.077070,0.000000
135.770004,1.631737,-272.267914,-0.001699,0.003051,0.077504,7.258327,0.369757,0.775040,-272.267914,0.076498,0.000000
136.110001,-0.899281,-272.312378,-0.001720,0.003021,0.076732,-4.000200,-0.203780,0.767321,-272.312378,0.075934,0.000000
136.450012,-2.638634,-272.312378,-0.001703,0.003004,0.076307,-11.737229,-0.597923,0.763072,-272.312378,0.075362,0.000000
136.790009,-0.610321,-272.312378,-0.001725,0.002988,0.075891,-2.714844,-0.138301,0.758909,-272.312378,0.074798,0.000000
137.130005,-0.215607,-272.356873,-0.001759,0.002955,0.075050,-0.959066,-0.048857,0.750497,-272.356873,0.074235,0.000000
137.470001,-0.211136,-272.356873,-0.001746,0.002937,0.074590,-0.939179,-0.047844,0.745901,-272.356873,0.073662,0.000000
137.810013,-0.116554,-272.445831,-0.001781,0.002919,0.074148,-0.518459,-0.026412,0.741478,-272.445831,0.073098,0.000000
138.150009,-0.013779,-272.445831,-0.001785,0.002890,0.073402,-0.061291,-0.003122,0.734020,-272.445831,0.072535,0.000000
138.490005,-0.027931,-272.356873,-0.001794,0.002870,0.072890,-0.124244,-0.006329,0.728903,-272.356873,0.071962,0.000000
138.830002,-0.041336,-272.445831,-0.001798,0.002851,0.072405,-0.183872,-0.009367,0.724047,-272.445831,0.071399,0.000000
139.170013,-0.051758,-272.401337,-0.001837,0.002826,0.071789,-0.230230,-0.011728,0.717889,-272.401337,0.070835,0.000000
139.510010,-0.067398,-272.445831,-0.001837,0.002802,0.071182,-0.299802,-0.015273,0.711819,-272.445831,0.070263,0.000000
139.850006,-0.033142,-272.401337,-0.001850,0.002786,0.070766,-0.147423,-0.007510,0.707656,-272.401337,0.069699,0.000000
140.190002,-0.002983,-272.445831,-0.001876,0.002758,0.070046,-0.013269,-0.000676,0.700458,-272.445831,0.069135,0.000000
140.530014,-0.031654,-272.579254,-0.001897,0.002740,0.069595,-0.140806,-0.007173,0.695949,-272.579254,0.069508,0.000000
140.700012,-0.016014,-272.534790,-0.001901,0.002741,0.069612,-0.071234,-0.003629,0.696122,-272.534790,0.069508,0.000000