File: Data/compression 33/AutoNoHeating-15-33-reverse-1-1_11152024_180532.csv
Time (sec),S:Load (lbs),S:HL1 (DIM),S:LVDT (in),S:Position (in),Ch:Position (mm),Ch:Load (N),Ch:Stress (MPa),Ch:Strain (mm/mm),Ch:HL1 (DIM),Set Point (),Cycles ()
0.110000,-0.072617,-692.123596,-0.007390,-0.007247,-0.184077,-0.323015,-0.016455,-1.840773,-692.123596,-0.183800,0.000000
0.470000,-0.052132,-692.212585,-0.007399,-0.007191,-0.182664,-0.231893,-0.011813,-1.826638,-692.212585,-0.181892,0.000000
0.830000,-0.032028,-692.168091,-0.007269,-0.006976,-0.177183,-0.142469,-0.007258,-1.771829,-692.168091,-0.175908,0.000000
1.190000,-0.057343,-692.123596,-0.007028,-0.006741,-0.171234,-0.255072,-0.012994,-1.712337,-692.123596,-0.169907,0.000000
1.550000,-0.081551,-692.168091,-0.006786,-0.006507,-0.165276,-0.362755,-0.018480,-1.652759,-692.168091,-0.163906,0.000000
1.910000,-0.117302,-692.168091,-0.006566,-0.006271,-0.159275,-0.521785,-0.026581,-1.592747,-692.168091,-0.157904,0.000000
2.270000,-0.158630,-692.212585,-0.006321,-0.006034,-0.153256,-0.705623,-0.035946,-1.532561,-692.212585,-0.151903,0.000000
2.630000,-0.050644,-692.168091,-0.006079,-0.005803,-0.147402,-0.225275,-0.011476,-1.474024,-692.168091,-0.145919,0.000000
2.990000,-0.022346,-692.257019,-0.005816,-0.005556,-0.141132,-0.099402,-0.005064,-1.411323,-692.257019,-0.139918,0.000000
3.350000,-0.032028,-692.123596,-0.005579,-0.005323,-0.135209,-0.142469,-0.007258,-1.352092,-692.123596,-0.133917,0.000000
3.710000,-0.069260,-692.168091,-0.005333,-0.005093,-0.129355,-0.308082,-0.015694,-1.293554,-692.168091,-0.127916,0.000000
4.070000,-0.080437,-692.212585,-0.005122,-0.004856,-0.123354,-0.357800,-0.018227,-1.233542,-692.212585,-0.121932,0.000000
4.430000,-0.007072,-692.212585,-0.004868,-0.004616,-0.117258,-0.031460,-0.001603,-1.172576,-692.212585,-0.115931,0.000000
4.790000,0.126976,-692.257019,-0.004829,-0.000000,-0.000009,0.564817,0.028773,-0.000087,-692.257019,0.000182,0.000000
5.150000,0.096443,-692.257019,-0.004842,-0.000000,-0.000009,0.429001,0.021854,-0.000087,-692.257019,0.000399,0.000000
5.510000,0.071495,-692.257019,-0.004838,-0.000000,-0.000009,0.318026,0.016201,-0.000087,-692.257019,0.000997,0.000000
5.870000,0.188423,-692.301514,-0.004838,0.000022,0.000564,0.838148,0.042697,0.005637,-692.301514,0.001596,0.000000
6.230000,0.248001,-692.212585,-0.004790,0.000044,0.001119,1.103164,0.056198,0.011187,-692.212585,0.002194,0.000000
6.590000,0.418915,-692.257019,-0.004764,0.000073,0.001847,1.863426,0.094927,0.018472,-692.257019,0.002792,0.000000
6.950000,0.540688,-692.212585,-0.004747,0.000090,0.002298,2.405098,0.122522,0.022982,-692.212585,0.003391,0.000000
7.310000,0.694847,-692.301514,-0.004730,0.000108,0.002732,3.090834,0.157455,0.027318,-692.301514,0.003998,0.000000
7.670001,1.087326,-692.301514,-0.004708,0.000138,0.003495,4.836668,0.246392,0.034949,-692.301514,0.004596,0.000000
8.030001,1.456718,-692.346008,-0.004682,0.000162,0.004111,6.479807,0.330097,0.041107,-692.346008,0.005195,0.000000
8.390000,1.651474,-692.346008,-0.004656,0.000181,0.004596,7.346123,0.374229,0.045963,-692.346008,0.005793,0.000000
8.750000,2.040970,-692.257019,-0.004648,0.000203,0.005151,9.078688,0.462490,0.051513,-692.257019,0.006391,0.000000
9.110001,2.445000,-692.257019,-0.004626,0.000228,0.005793,10.875902,0.554045,0.057931,-692.257019,0.006999,0.000000
9.470000,2.598045,-692.390503,-0.004592,0.000241,0.006114,11.556683,0.588725,0.061139,-692.390503,0.007597,0.000000
9.830001,3.203148,-692.346008,-0.004566,0.000277,0.007025,14.248313,0.725844,0.070245,-692.346008,0.008195,0.000000
10.190001,3.866341,-692.434937,-0.004557,0.000307,0.007805,17.198341,0.876125,0.078050,-692.434937,0.008794,0.000000
10.550000,4.182861,-692.346008,-0.004544,0.000325,0.008256,18.606297,0.947850,0.082560,-692.346008,0.009392,0.000000
10.910001,4.663216,-692.301514,-0.004493,0.000353,0.008976,20.743019,1.056700,0.089758,-692.301514,0.009999,0.000000
11.270000,4.994629,-692.390503,-0.004488,0.000372,0.009461,22.217218,1.131799,0.094614,-692.390503,0.010598,0.000000
11.630000,5.438126,-692.346008,-0.004471,0.000397,0.010095,24.189991,1.232297,0.100945,-692.346008,0.011196,0.000000
11.990001,5.945671,-692.434937,-0.004441,0.000423,0.010754,26.447666,1.347308,0.107536,-692.434937,0.011794,0.000000
12.350000,6.199257,-692.390503,-0.004441,0.000439,0.011144,27.575672,1.404772,0.111439,-692.390503,0.012393,0.000000
12.710001,6.891869,-692.434937,-0.004398,0.000477,0.012115,30.656563,1.561720,0.121151,-692.434937,0.013000,0.000000
13.070001,7.237427,-692.434937,-0.004393,0.000498,0.012662,32.193684,1.640024,0.126615,-692.434937,0.013598,0.000000
13.430000,7.677574,-692.390503,-0.004359,0.000522,0.013251,34.151554,1.739763,0.132512,-692.390503,0.014196,0.000000
13.790001,8.048454,-692.390503,-0.004320,0.000544,0.013806,35.801311,1.823806,0.138062,-692.390503,0.014795,0.000000
14.150001,8.282310,-692.434937,-0.004307,0.000562,0.014266,36.841557,1.876798,0.142659,-692.434937,0.015393,0.000000
14.510000,8.529190,-692.479431,-0.004303,0.000579,0.014717,37.939732,1.932742,0.147168,-692.479431,0.015992,0.000000
14.870001,9.014023,-692.479431,-0.004277,0.000607,0.015428,40.096375,2.042607,0.154280,-692.479431,0.016599,0.000000
15.230000,9.492516,-692.479431,-0.004243,0.000633,0.016070,42.224819,2.151035,0.160697,-692.479431,0.017197,0.000000
15.590001,9.550606,-692.434937,-0.004234,0.000648,0.016469,42.483215,2.164198,0.164686,-692.434937,0.017795,0.000000
15.950001,10.101349,-692.523926,-0.004212,0.000676,0.017162,44.933044,2.288998,0.171624,-692.523926,0.018394,0.000000
16.310001,10.611496,-692.612915,-0.004178,0.000701,0.017804,47.202293,2.404599,0.178041,-692.612915,0.018992,0.000000
16.670000,11.043076,-692.523926,-0.004178,0.000726,0.018437,49.122055,2.502397,0.184372,-692.523926,0.019599,0.000000
17.030001,11.453430,-692.523926,-0.004139,0.000752,0.019096,50.947403,2.595385,0.190963,-692.523926,0.020198,0.000000
17.390001,11.727501,-692.479431,-0.004105,0.000779,0.019799,52.166531,2.657490,0.197988,-692.479431,0.020796,0.000000
17.750000,11.989273,-692.612915,-0.004087,0.000798,0.020258,53.330952,2.716808,0.202584,-692.612915,0.021394,0.000000
18.110001,12.098381,-692.612915,-0.004061,0.000820,0.020822,53.816288,2.741532,0.208221,-692.612915,0.021993,0.000000
18.470001,12.959679,-692.657349,-0.004044,0.000850,0.021603,57.647530,2.936705,0.216026,-692.657349,0.022600,0.000000
18.830002,13.057236,-692.568420,-0.004031,0.000869,0.022080,58.081486,2.958812,0.220796,-692.568420,0.023198,0.000000
19.190001,13.179008,-692.568420,-0.004001,0.000891,0.022626,58.623158,2.986406,0.226259,-692.568420,0.023797,0.000000
19.550001,13.698837,-692.657349,-0.003980,0.000915,0.023242,60.935471,3.104201,0.232417,-692.657349,0.024395,0.000000
19.910002,14.260376,-692.568420,-0.003949,0.000944,0.023979,63.433319,3.231447,0.239788,-692.568420,0.024993,0.000000
20.270000,13.915932,-692.657349,-0.003919,0.000956,0.024282,61.901157,3.153395,0.242823,-692.657349,0.025601,0.000000
20.630001,14.574654,-692.612915,-0.003911,0.000987,0.025080,64.831299,3.302664,0.250802,-692.612915,0.026199,0.000000
20.990002,14.750420,-692.657349,-0.003863,0.001008,0.025609,65.613144,3.342493,0.256092,-692.657349,0.026797,0.000000
21.350000,15.120186,-692.701843,-0.003859,0.001030,0.026164,67.257942,3.426283,0.261642,-692.701843,0.027396,0.000000
21.710001,15.571129,-692.657349,-0.003824,0.001061,0.026953,69.263840,3.528468,0.269534,-692.657349,0.027994,0.000000
22.070002,15.828438,-692.657349,-0.003790,0.001084,0.027534,70.408409,3.586775,0.275344,-692.657349,0.028592,0.000000
22.430000,16.026909,-692.657349,-0.003773,0.001108,0.028150,71.291252,3.631749,0.281501,-692.657349,0.029199,0.000000
22.790001,15.917801,-692.701843,-0.003751,0.001127,0.028636,70.805916,3.607025,0.286358,-692.701843,0.029798,0.000000
23.150002,15.742043,-692.746338,-0.003747,0.001136,0.028861,70.024101,3.567198,0.288613,-692.746338,0.030396,0.000000
23.510000,16.894913,-692.701843,-0.003682,0.001177,0.029893,75.152328,3.828442,0.298933,-692.701843,0.030995,0.000000
23.870001,17.336174,-692.701843,-0.003665,0.001207,0.030648,77.115150,3.928433,0.306478,-692.701843,0.031593,0.000000
24.230001,16.988373,-692.701843,-0.003626,0.001225,0.031125,75.568054,3.849620,0.311247,-692.701843,0.032200,0.000000
24.590002,17.167488,-692.746338,-0.003604,0.001250,0.031758,76.364799,3.890208,0.317578,-692.746338,0.032798,0.000000
24.950001,17.667580,-692.790833,-0.003561,0.001277,0.032443,78.589317,4.003531,0.324429,-692.790833,0.033397,0.000000
25.310001,17.651573,-692.746338,-0.003544,0.001298,0.032972,78.518120,3.999904,0.329719,-692.746338,0.033995,0.000000
25.670002,17.744667,-692.835266,-0.003518,0.001314,0.033388,78.932220,4.020999,0.333882,-692.835266,0.034594,0.000000
26.030001,18.490150,-692.835266,-0.003492,0.001346,0.034195,82.248299,4.189928,0.341947,-692.835266,0.035201,0.000000
26.390001,18.361313,-692.746338,-0.003466,0.001364,0.034646,81.675201,4.160733,0.346457,-692.746338,0.035799,0.000000
26.750002,18.842415,-692.879761,-0.003449,0.001393,0.035374,83.815247,4.269752,0.353741,-692.879761,0.036397,0.000000
27.110001,18.443977,-692.790833,-0.003419,0.001411,0.035842,82.042908,4.179465,0.358424,-692.790833,0.036996,0.000000
27.470001,18.955246,-692.835266,-0.003393,0.001431,0.036345,84.317146,4.295320,0.363454,-692.835266,0.037594,0.000000
27.830002,19.498535,-692.835266,-0.003372,0.001462,0.037126,86.733818,4.418431,0.371259,-692.835266,0.038201,0.000000
28.190001,19.323151,-692.835266,-0.003328,0.001486,0.037742,85.953667,4.378689,0.377417,-692.835266,0.038800,0.000000
28.550001,19.668709,-692.924255,-0.003303,0.001509,0.038340,87.490784,4.456993,0.383401,-692.924255,0.039398,0.000000
28.910002,19.446777,-692.835266,-0.003264,0.001522,0.038652,86.503586,4.406703,0.386523,-692.835266,0.039996,0.000000
29.270000,20.424255,-692.879761,-0.003238,0.001557,0.039537,90.851624,4.628202,0.395368,-692.879761,0.040595,0.000000
29.630001,20.236206,-692.790833,-0.003216,0.001577,0.040066,90.015137,4.585590,0.400658,-692.790833,0.041202,0.000000
29.990002,20.085022,-692.835266,-0.003195,0.001591,0.040421,89.342636,4.551331,0.404214,-692.835266,0.041800,0.000000
30.350002,20.690872,-692.879761,-0.003173,0.001620,0.041150,92.037598,4.688619,0.411499,-692.879761,0.042399,0.000000
30.710001,20.548256,-692.835266,-0.003134,0.001639,0.041627,91.403206,4.656301,0.416268,-692.835266,0.042997,0.000000
31.070002,21.415512,-692.879761,-0.003096,0.001672,0.042459,95.260956,4.852825,0.424594,-692.879761,0.043595,0.000000
31.430002,21.164902,-692.879761,-0.003065,0.001696,0.043075,94.146187,4.796035,0.430751,-692.879761,0.044194,0.000000
31.790001,20.949677,-692.835266,-0.003040,0.001716,0.043587,93.188812,4.747264,0.435868,-692.835266,0.044801,0.000000
32.150002,21.860870,-692.924255,-0.003009,0.001748,0.044411,97.242004,4.953744,0.444106,-692.924255,0.045399,0.000000
32.510002,21.636703,-692.924255,-0.002988,0.001768,0.044914,96.244865,4.902947,0.449136,-692.924255,0.045998,0.000000
32.870003,22.037003,-692.968750,-0.002958,0.001792,0.045512,98.025482,4.993656,0.455120,-692.968750,0.046596,0.000000
33.230003,22.214996,-692.924255,-0.002910,0.001815,0.046093,98.817238,5.033990,0.460931,-692.924255,0.047194,0.000000
33.590000,22.239944,-692.968750,-0.002884,0.001836,0.046639,98.928215,5.039643,0.466394,-692.968750,0.047801,0.000000
33.950001,22.776161,-693.057678,-0.002850,0.001870,0.047507,101.313423,5.161152,0.475066,-693.057678,0.048400,0.000000
34.310001,22.530396,-692.924255,-0.002815,0.001891,0.048027,100.220207,5.105461,0.480270,-692.924255,0.048998,0.000000
34.670002,22.742645,-693.057678,-0.002794,0.001915,0.048634,101.164337,5.153557,0.486340,-693.057678,0.049597,0.000000
35.030003,22.978355,-692.924255,-0.002768,0.001937,0.049198,102.212830,5.206970,0.491977,-692.924255,0.050195,0.000000
35.390003,23.170128,-693.013245,-0.002729,0.001958,0.049744,103.065880,5.250426,0.497441,-693.013245,0.050802,0.000000
35.750000,23.279236,-693.013245,-0.002716,0.001978,0.050238,103.551216,5.275150,0.502384,-693.013245,0.051400,0.000000
36.110001,23.533569,-693.057678,-0.002673,0.002004,0.050897,104.682541,5.332783,0.508975,-693.057678,0.051999,0.000000
36.470001,24.143143,-693.057678,-0.002639,0.002031,0.051591,107.394066,5.470914,0.515913,-693.057678,0.052597,0.000000
36.830002,23.951370,-693.013245,-0.002634,0.002051,0.052086,106.541016,5.427458,0.520856,-693.013245,0.053196,0.000000
37.190002,24.267143,-693.057678,-0.002587,0.002073,0.052649,107.945641,5.499013,0.526493,-693.057678,0.053803,0.000000
37.550003,24.429123,-693.013245,-0.002565,0.002097,0.053274,108.666168,5.535718,0.532737,-693.013245,0.054401,0.000000
37.910004,24.445137,-693.102173,-0.002531,0.002122,0.053889,108.737404,5.539347,0.538894,-693.102173,0.054999,0.000000
38.270000,24.282036,-693.146667,-0.002505,0.002135,0.054236,108.011887,5.502388,0.542363,-693.146667,0.055598,0.000000
38.630001,25.339203,-693.102173,-0.002471,0.002172,0.055173,112.714401,5.741946,0.551729,-693.102173,0.056196,0.000000
38.990002,25.345528,-693.102173,-0.002432,0.002195,0.055763,112.742538,5.743379,0.557626,-693.102173,0.056795,0.000000
39.350002,25.088593,-693.146667,-0.002402,0.002216,0.056283,111.599632,5.685156,0.562829,-693.146667,0.057402,0.000000
39.710003,25.689232,-693.102173,-0.002371,0.002243,0.056968,114.271408,5.821263,0.569681,-693.102173,0.058000,0.000000
40.070004,25.676567,-693.057678,-0.002328,0.002265,0.057523,114.215073,5.818393,0.575231,-693.057678,0.058598,0.000000
40.430000,25.648270,-693.057678,-0.002302,0.002284,0.058026,114.089203,5.811981,0.580261,-693.057678,0.059197,0.000000
40.790001,25.960320,-693.146667,-0.002276,0.002309,0.058642,115.477272,5.882692,0.586418,-693.146667,0.059795,0.000000
41.150002,26.085434,-693.146667,-0.002255,0.002333,0.059266,116.033806,5.911044,0.592662,-693.146667,0.060402,0.000000
41.510002,26.121552,-693.102173,-0.002229,0.002354,0.059787,116.194466,5.919228,0.597865,-693.102173,0.061001,0.000000
41.870003,26.642128,-693.191162,-0.002173,0.002382,0.060506,118.510101,6.037192,0.605063,-693.191162,0.061599,0.000000
42.230003,26.694633,-693.191162,-0.002164,0.002404,0.061070,118.743660,6.049091,0.610700,-693.191162,0.062197,0.000000
42.590000,25.969627,-693.146667,-0.002113,0.002416,0.061374,115.518669,5.884802,0.613736,-693.146667,0.062796,0.000000
42.950001,27.180206,-693.280090,-0.002095,0.002452,0.062293,120.903595,6.159123,0.622928,-693.280090,0.063403,0.000000
43.310001,26.195656,-693.191162,-0.002057,0.002471,0.062761,116.524094,5.936020,0.627611,-693.191162,0.064001,0.000000
43.670002,27.183563,-693.280090,-0.002022,0.002501,0.063516,120.918526,6.159883,0.635156,-693.280090,0.064600,0.000000
44.030003,26.947479,-693.235596,-0.001988,0.002519,0.063993,119.868378,6.106386,0.639926,-693.235596,0.065198,0.000000
44.390003,26.886032,-693.191162,-0.001962,0.002544,0.064608,119.595047,6.092462,0.646083,-693.191162,0.065796,0.000000
44.750004,27.245377,-693.280090,-0.001936,0.002565,0.065163,121.193489,6.173891,0.651633,-693.280090,0.066403,0.000000
45.110001,27.638229,-693.324585,-0.001884,0.002595,0.065900,122.940987,6.262912,0.659005,-693.324585,0.067002,0.000000
45.470001,28.103691,-693.280090,-0.001837,0.002622,0.066594,125.011459,6.368388,0.665943,-693.280090,0.067600,0.000000
45.830002,27.952141,-693.280090,-0.001824,0.002647,0.067227,124.337334,6.334045,0.672273,-693.280090,0.068199,0.000000
46.190002,27.663551,-693.235596,-0.001772,0.002669,0.067800,123.053619,6.268650,0.677997,-693.235596,0.068797,0.000000
46.550003,27.512367,-693.280090,-0.001738,0.002689,0.068294,122.381119,6.234391,0.682940,-693.280090,0.069395,0.000000
46.910004,27.590195,-693.280090,-0.001716,0.002712,0.068875,122.727318,6.252028,0.688751,-693.280090,0.070002,0.000000
47.270000,27.930916,-693.324585,-0.001673,0.002734,0.069447,124.242920,6.329236,0.694474,-693.324585,0.070601,0.000000
47.630001,28.243332,-693.280090,-0.001656,0.002761,0.070133,125.632614,6.400030,0.701325,-693.280090,0.071199,0.000000
47.990002,28.494682,-693.280090,-0.001621,0.002787,0.070783,126.750679,6.456987,0.707830,-693.280090,0.071798,0.000000
48.350002,27.975967,-693.369080,-0.001582,0.002800,0.071130,124.443321,6.339445,0.711299,-693.369080,0.072396,0.000000
48.710003,28.002777,-693.280090,-0.001544,0.002819,0.071598,124.562576,6.345520,0.715982,-693.280090,0.073003,0.000000
49.070004,29.269966,-693.369080,-0.001526,0.002857,0.072578,130.199310,6.632669,0.725781,-693.369080,0.073601,0.000000
49.430004,29.286720,-693.369080,-0.001492,0.002878,0.073107,130.273834,6.636466,0.731071,-693.369080,0.074200,0.000000
49.790001,29.227142,-693.369080,-0.001457,0.002900,0.073653,130.008820,6.622965,0.736535,-693.369080,0.074798,0.000000
50.150002,29.051010,-693.324585,-0.001427,0.002918,0.074122,129.225342,6.583053,0.741218,-693.324585,0.075397,0.000000
50.510002,29.143356,-693.369080,-0.001397,0.002938,0.074616,129.636124,6.603979,0.746161,-693.369080,0.076004,0.000000
50.870003,30.205734,-693.369080,-0.001362,0.002973,0.075518,134.361816,6.844717,0.755180,-693.369080,0.076602,0.000000
51.230003,30.012848,-693.413574,-0.001341,0.002988,0.075891,133.503815,6.801009,0.758909,-693.413574,0.077200,0.000000
51.590004,30.857018,-693.369080,-0.001328,0.003017,0.076619,137.258865,6.992300,0.766194,-693.369080,0.077799,0.000000
51.950001,30.626892,-693.413574,-0.001289,0.003034,0.077062,136.235214,6.940153,0.770617,-693.413574,0.078397,0.000000
52.310001,31.662460,-693.413574,-0.001263,0.003066,0.077886,140.841660,7.174816,0.778855,-693.413574,0.079004,0.000000
52.670002,31.904503,-693.458008,-0.001237,0.003085,0.078371,141.918320,7.229664,0.783712,-693.458008,0.079603,0.000000
53.030003,32.270172,-693.458008,-0.001203,0.003109,0.078961,143.544891,7.312525,0.789609,-693.458008,0.080201,0.000000
53.390003,33.339996,-693.413574,-0.001181,0.003142,0.079802,148.303711,7.554951,0.798021,-693.413574,0.080799,0.000000
53.750004,33.460274,-693.502502,-0.001151,0.003162,0.080305,148.838730,7.582207,0.803051,-693.502502,0.081398,0.000000
54.110004,33.797638,-693.458008,-0.001121,0.003182,0.080834,150.339401,7.658654,0.808341,-693.458008,0.081996,0.000000
54.470001,34.614624,-693.458008,-0.001099,0.003210,0.081537,153.973541,7.843786,0.815366,-693.458008,0.082603,0.000000
54.830002,35.547043,-693.546997,-0.001065,0.003235,0.082178,158.121140,8.055075,0.821783,-693.546997,0.083202,0.000000
55.190002,36.510002,-693.458008,-0.001052,0.003264,0.082907,162.404602,8.273284,0.829068,-693.458008,0.083800,0.000000
55.550003,36.648521,-693.546997,-0.001022,0.003283,0.083384,163.020767,8.304674,0.833838,-693.546997,0.084398,0.000000
55.910004,36.859657,-693.458008,-0.001009,0.003301,0.083852,163.959946,8.352518,0.838521,-693.458008,0.084997,0.000000
56.270004,37.719841,-693.635925,-0.000983,0.003328,0.084528,167.786240,8.547438,0.845285,-693.635925,0.085604,0.000000
56.630001,38.072479,-693.546997,-0.000961,0.003346,0.084997,169.354843,8.627347,0.849968,-693.546997,0.086202,0.000000
56.990002,38.462349,-693.546997,-0.000936,0.003368,0.085552,171.089066,8.715693,0.855518,-693.546997,0.086801,0.000000
57.350002,40.170052,-693.546997,-0.000910,0.003400,0.086358,178.685318,9.102664,0.863583,-693.546997,0.087399,0.000000
57.710003,40.587479,-693.546997,-0.000905,0.003418,0.086809,180.542130,9.197254,0.868093,-693.546997,0.087997,0.000000
58.070004,41.071564,-693.546997,-0.000875,0.003436,0.087269,182.695435,9.306950,0.872689,-693.546997,0.088604,0.000000
58.430004,42.675743,-693.591492,-0.000854,0.003467,0.088058,189.831192,9.670461,0.880581,-693.591492,0.089203,0.000000
58.790001,43.464806,-693.502502,-0.000845,0.003491,0.088674,193.341110,9.849266,0.886738,-693.502502,0.089801,0.000000
59.150002,44.084801,-693.546997,-0.000815,0.003509,0.089116,196.098984,9.989758,0.891161,-693.546997,0.090400,0.000000
59.510002,45.025040,-693.591492,-0.000811,0.003532,0.089714,200.281372,10.202820,0.897145,-693.591492,0.090998,0.000000
59.870003,46.202110,-693.546997,-0.000772,0.003560,0.090417,205.517258,10.469547,0.904170,-693.546997,0.091605,0.000000
60.230003,47.699425,-693.591492,-0.000767,0.003589,0.091163,212.177643,10.808845,0.911628,-693.591492,0.092203,0.000000
60.590004,48.472839,-693.591492,-0.000742,0.003611,0.091709,215.617966,10.984102,0.917091,-693.591492,0.092802,0.000000
60.950005,48.655678,-693.680420,-0.000729,0.003628,0.092151,216.431259,11.025534,0.921514,-693.680420,0.093400,0.000000
61.310001,50.090797,-693.591492,-0.000711,0.003651,0.092724,222.815002,11.350738,0.927238,-693.591492,0.093999,0.000000
61.670002,51.274940,-693.635925,-0.000681,0.003677,0.093400,228.082321,11.619068,0.934002,-693.635925,0.094597,0.000000
62.030003,51.669281,-693.724915,-0.000686,0.003691,0.093747,229.836441,11.708426,0.937471,-693.724915,0.095204,0.000000
62.390003,54.030502,-693.635925,-0.000660,0.003725,0.094606,240.339676,12.243486,0.946057,-693.635925,0.095802,0.000000
62.750004,55.496155,-693.724915,-0.000638,0.003751,0.095273,246.859222,12.575608,0.952734,-693.724915,0.096401,0.000000
63.110004,56.673225,-693.680420,-0.000634,0.003774,0.095863,252.095093,12.842337,0.958631,-693.680420,0.096999,0.000000
63.470001,57.800026,-693.635925,-0.000608,0.003797,0.096435,257.107361,13.097673,0.964355,-693.635925,0.097598,0.000000
63.830002,58.916023,-693.724915,-0.000591,0.003820,0.097017,262.071564,13.350562,0.970165,-693.724915,0.098205,0.000000
64.190002,60.719421,-693.635925,-0.000595,0.003847,0.097702,270.093475,13.759217,0.977017,-693.635925,0.098803,0.000000
64.550003,61.462677,-693.680420,-0.000569,0.003862,0.098083,273.399628,13.927642,0.980832,-693.680420,0.099401,0.000000
64.910004,63.327148,-693.724915,-0.000565,0.003891,0.098820,281.693237,14.350137,0.988204,-693.724915,0.100000,0.000000
65.270004,64.636414,-693.635925,-0.000539,0.003915,0.099436,287.517120,14.646821,0.994361,-693.635925,0.100598,0.000000
65.630005,65.784058,-693.769409,-0.000535,0.003934,0.099930,292.622101,14.906880,0.999304,-693.769409,0.101205,0.000000
65.990005,66.112869,-693.724915,-0.000522,0.003939,0.100052,294.084717,14.981391,1.000518,-693.724915,0.017567,0.000000
66.350006,65.047516,-693.724915,-0.000500,0.003939,0.100061,289.345795,14.739977,1.000605,-693.724915,294.500458,0.000000
66.710007,65.478714,-693.769409,-0.000504,0.003955,0.100451,291.263855,14.837688,1.004508,-693.769409,294.500458,0.000000
67.070000,64.836746,-693.769409,-0.000513,0.003955,0.100451,288.408264,14.692217,1.004508,-693.769409,294.500458,0.000000
67.430000,64.299042,-693.769409,-0.000500,0.003955,0.100451,286.016418,14.570371,1.004508,-693.769409,294.500458,0.000000
67.790001,66.555252,-693.769409,-0.000483,0.003848,0.097728,296.052551,15.081636,0.977277,-693.769409,294.500458,0.000000
68.150002,65.903229,-693.769409,-0.000466,0.003849,0.097762,293.152191,14.933885,0.977624,-693.769409,294.500458,0.000000
68.510002,65.441483,-693.813904,-0.000466,0.003913,0.099393,291.098267,14.829251,0.993927,-693.813904,294.500458,0.000000
68.870003,65.156250,-693.813904,-0.000470,0.003968,0.100780,289.829468,14.764617,1.007803,-693.813904,294.500458,0.000000
69.230003,64.921280,-693.813904,-0.000466,0.003974,0.100936,288.784271,14.711372,1.009364,-693.813904,294.500458,0.000000
69.590004,65.701019,-693.769409,-0.000461,0.003988,0.101292,292.252716,14.888063,1.012920,-693.769409,294.500458,0.000000
69.950005,65.437378,-693.813904,-0.000457,0.003988,0.101292,291.079987,14.828321,1.012920,-693.813904,294.500458,0.000000
70.310005,65.175613,-693.858337,-0.000466,0.003988,0.101292,289.915619,14.769006,1.012920,-693.858337,294.500458,0.000000
70.670006,64.898193,-693.769409,-0.000448,0.003991,0.101361,288.681580,14.706141,1.013613,-693.769409,294.500458,0.000000
71.030006,65.760605,-693.858337,-0.000453,0.004000,0.101604,292.517792,14.901566,1.016042,-693.858337,294.500458,0.000000
71.390007,65.571060,-693.813904,-0.000444,0.004000,0.101604,291.674652,14.858614,1.016042,-693.813904,294.500458,0.000000
71.750000,65.353226,-693.858337,-0.000453,0.004000,0.101604,290.705658,14.809253,1.016042,-693.858337,294.500458,0.000000
72.110001,65.183426,-693.858337,-0.000448,0.004000,0.101604,289.950348,14.770775,1.016042,-693.858337,294.500458,0.000000
72.470001,64.996124,-693.813904,-0.000440,0.004001,0.101613,289.117187,14.728333,1.016128,-693.813904,294.500458,0.000000
72.830002,64.800262,-693.902832,-0.000431,0.004001,0.101613,288.245972,14.683949,1.016128,-693.902832,294.500458,0.000000
73.190002,64.654663,-693.858337,-0.000440,0.004001,0.101613,287.598297,14.650956,1.016128,-693.858337,294.500458,0.000000
73.550003,64.476288,-693.947327,-0.000431,0.004001,0.101613,286.804840,14.610536,1.016128,-693.947327,294.500458,0.000000
73.910004,67.290680,-693.991821,-0.000423,0.003888,0.098751,299.323883,15.248286,0.987510,-693.991821,294.500458,0.000000
74.270004,66.582428,-693.947327,-0.000410,0.003835,0.097415,296.173431,15.087794,0.974155,-693.947327,294.500458,0.000000
74.630005,66.370178,-693.902832,-0.000423,0.003835,0.097415,295.229309,15.039698,0.974155,-693.902832,294.500458,0.000000
74.990005,66.192932,-693.902832,-0.000405,0.003835,0.097415,294.440857,14.999533,0.974155,-693.902832,294.500458,0.000000
75.350006,66.053284,-693.947327,-0.000427,0.003835,0.097415,293.819672,14.967888,0.974155,-693.947327,294.500458,0.000000
75.710007,65.899872,-693.947327,-0.000414,0.003838,0.097494,293.137268,14.933125,0.974935,-693.947327,294.500458,0.000000
76.070007,65.768051,-693.991821,-0.000418,0.003844,0.097650,292.550903,14.903254,0.976496,-693.991821,294.500458,0.000000
76.430000,65.617615,-693.947327,-0.000401,0.003868,0.098239,291.881714,14.869164,0.982393,-693.947327,294.500458,0.000000
76.790001,65.480957,-693.991821,-0.000423,0.003915,0.099445,291.273834,14.838197,0.994448,-693.991821,294.500458,0.000000
77.150002,65.364395,-693.991821,-0.000414,0.003968,0.100789,290.755341,14.811783,1.007890,-693.991821,294.500458,0.000000
77.510002,65.278015,-693.947327,-0.000418,0.003986,0.101240,290.371124,14.792210,1.012399,-693.947327,294.500458,0.000000
77.870003,65.203903,-694.036255,-0.000414,0.003990,0.101353,290.041443,14.775416,1.013527,-694.036255,294.500458,0.000000
78.230003,65.330521,-694.125244,-0.000414,0.004017,0.102020,290.604675,14.804107,1.020204,-694.125244,294.500458,0.000000
78.590004,65.306686,-693.991821,-0.000414,0.004020,0.102098,290.498657,14.798706,1.020985,-693.991821,294.500458,0.000000
78.950005,65.232574,-694.036255,-0.000410,0.004020,0.102107,290.168976,14.781913,1.021072,-694.036255,294.500458,0.000000
79.310005,65.183060,-694.080750,-0.000431,0.004020,0.102116,289.948730,14.770692,1.021158,-694.080750,294.500458,0.000000
79.670006,65.089966,-694.036255,-0.000414,0.004020,0.102116,289.534637,14.749597,1.021158,-694.036255,294.500458,0.000000
80.030006,65.761353,-694.080750,-0.000410,0.004031,0.102376,292.521118,14.901735,1.023760,-694.080750,294.500458,0.000000
80.390007,65.685760,-694.080750,-0.000414,0.004030,0.102367,292.184845,14.884606,1.023673,-694.080750,294.500458,0.000000
80.750008,65.604950,-694.036255,-0.000401,0.004030,0.102367,291.825378,14.866295,1.023673,-694.036255,294.500458,0.000000
81.110001,65.566971,-694.169739,-0.000427,0.004031,0.102376,291.656464,14.857688,1.023760,-694.169739,294.500458,0.000000
81.470001,65.517441,-694.080750,-0.000405,0.004031,0.102376,291.436127,14.846464,1.023760,-694.080750,294.500458,0.000000
81.830002,65.409088,-694.169739,-0.000397,0.004031,0.102385,290.954163,14.821911,1.023847,-694.169739,294.500458,0.000000
82.190002,65.353226,-694.125244,-0.000410,0.004031,0.102385,290.705658,14.809253,1.023847,-694.125244,294.500458,0.000000
82.550003,65.326416,-694.080750,-0.000414,0.004032,0.102411,290.586426,14.803178,1.024107,-694.080750,294.500458,0.000000
82.910004,65.282852,-694.169739,-0.000410,0.004032,0.102411,290.392639,14.793305,1.024107,-694.169739,294.500458,0.000000
83.270004,65.252686,-694.125244,-0.000414,0.004032,0.102411,290.258453,14.786469,1.024107,-694.125244,294.500458,0.000000
83.630005,65.207626,-694.214233,-0.000414,0.004033,0.102428,290.058014,14.776259,1.024280,-694.214233,294.500458,0.000000
83.990005,65.349884,-694.169739,-0.000423,0.004036,0.102506,290.690796,14.808496,1.025061,-694.169739,294.500458,0.000000
84.350006,65.338333,-694.214233,-0.000405,0.004036,0.102506,290.639435,14.805878,1.025061,-694.214233,294.500458,0.000000
84.710007,65.309296,-694.214233,-0.000414,0.004036,0.102506,290.510254,14.799298,1.025061,-694.214233,294.500458,0.000000
85.070007,65.295883,-694.169739,-0.000414,0.004036,0.102523,290.450592,14.796259,1.025234,-694.169739,294.500458,0.000000
85.430000,65.280243,-694.214233,-0.000418,0.004037,0.102532,290.381012,14.792715,1.025321,-694.214233,294.500458,0.000000
85.790001,65.262741,-694.258667,-0.000410,0.004037,0.102549,290.303162,14.788749,1.025494,-694.258667,294.500458,0.000000
86.150002,65.318222,-694.214233,-0.000410,0.004039,0.102593,290.549957,14.801320,1.025928,-694.214233,294.500458,0.000000
86.510002,65.319336,-694.258667,-0.000414,0.004039,0.102593,290.554932,14.801573,1.025928,-694.258667,294.500458,0.000000
86.870003,65.304077,-694.169739,-0.000414,0.004039,0.102601,290.487030,14.798116,1.026015,-694.169739,294.500458,0.000000
87.230003,65.292526,-694.258667,-0.000410,0.004040,0.102610,290.435669,14.795499,1.026101,-694.258667,294.500458,0.000000
87.590004,65.273163,-694.258667,-0.000423,0.004040,0.102610,290.349518,14.791110,1.026101,-694.258667,294.500458,0.000000
87.950005,65.247467,-694.258667,-0.000392,0.004040,0.102610,290.235229,14.785287,1.026101,-694.258667,294.500458,0.000000
88.310005,65.214340,-694.347656,-0.000410,0.004040,0.102619,290.087860,14.777781,1.026188,-694.347656,294.500458,0.000000
88.670006,65.174484,-694.303162,-0.000418,0.004043,0.102680,289.910583,14.768749,1.026795,-694.303162,294.500458,0.000000
89.030006,65.457489,-694.303162,-0.000414,0.004045,0.102732,291.169464,14.832879,1.027316,-694.303162,294.500458,0.000000
89.390007,65.462708,-694.303162,-0.000405,0.004045,0.102732,291.192657,14.834062,1.027316,-694.303162,294.500458,0.000000
89.750008,65.428818,-694.303162,-0.000397,0.004045,0.102732,291.041931,14.826382,1.027316,-694.303162,294.500458,0.000000
90.110001,65.390839,-694.347656,-0.000397,0.004045,0.102732,290.872986,14.817776,1.027316,-694.347656,294.500458,0.000000
90.470001,65.362167,-694.258667,-0.000401,0.004045,0.102732,290.745453,14.811279,1.027316,-694.258667,294.500458,0.000000
90.830002,65.337219,-694.303162,-0.000392,0.004045,0.102732,290.634460,14.805625,1.027316,-694.303162,294.500458,0.000000
91.190002,65.298492,-694.258667,-0.000410,0.004045,0.102732,290.462189,14.796850,1.027316,-694.258667,294.500458,0.000000
91.550003,65.286575,-694.347656,-0.000397,0.004045,0.102740,290.409180,14.794149,1.027402,-694.347656,294.500458,0.000000
91.910004,65.263489,-694.347656,-0.000397,0.004045,0.102740,290.306488,14.788918,1.027402,-694.347656,294.500458,0.000000
92.270004,65.238159,-694.303162,-0.000397,0.004045,0.102740,290.193817,14.783178,1.027402,-694.303162,294.500458,0.000000
92.630005,65.202789,-694.347656,-0.000397,0.004045,0.102740,290.036499,14.775164,1.027402,-694.347656,294.500458,0.000000
92.990005,65.181931,-694.347656,-0.000405,0.004046,0.102758,289.943695,14.770436,1.027576,-694.347656,294.500458,0.000000
93.350006,65.165176,-694.347656,-0.000392,0.004046,0.102766,289.869171,14.766640,1.027663,-694.347656,294.500458,0.000000
93.710007,65.165924,-694.481079,-0.000401,0.004047,0.102784,289.872498,14.766809,1.027836,-694.481079,294.500458,0.000000
94.070007,65.157730,-694.347656,-0.000405,0.004047,0.102801,289.836060,14.764953,1.028009,-694.347656,294.500458,0.000000
94.430008,65.174118,-694.481079,-0.000401,0.004048,0.102810,289.908966,14.768666,1.028096,-694.481079,294.500458,0.000000
94.790001,65.208740,-694.392151,-0.000397,0.004048,0.102827,290.062958,14.776512,1.028270,-694.392151,294.500458,0.000000
95.150002,65.210236,-694.436584,-0.000397,0.004048,0.102827,290.069611,14.776851,1.028270,-694.436584,294.500458,0.000000
95.510002,65.248962,-694.436584,-0.000405,0.004050,0.102862,290.241882,14.785626,1.028616,-694.436584,294.500458,0.000000
95.870003,65.254181,-694.436584,-0.000397,0.004050,0.102862,290.265106,14.786808,1.028616,-694.436584,294.500458,0.000000
96.230003,65.264969,-694.436584,-0.000379,0.004050,0.102879,290.313080,14.789253,1.028790,-694.436584,294.500458,0.000000
96.590004,65.278381,-694.481079,-0.000392,0.004050,0.102879,290.372742,14.792293,1.028790,-694.481079,294.500458,0.000000
96.950005,65.255295,-694.436584,-0.000392,0.004050,0.102879,290.270050,14.787061,1.028790,-694.436584,294.500458,0.000000
97.310005,65.248596,-694.570068,-0.000397,0.004050,0.102879,290.240265,14.785542,1.028790,-694.570068,294.500458,0.000000
97.670006,65.238159,-694.525574,-0.000392,0.004050,0.102879,290.193817,14.783178,1.028790,-694.525574,294.500458,0.000000
98.030006,65.214706,-694.525574,-0.000401,0.004050,0.102879,290.089508,14.777864,1.028790,-694.525574,294.500458,0.000000
98.390007,65.191238,-694.570068,-0.000384,0.004051,0.102888,289.985107,14.772546,1.028877,-694.570068,294.500458,0.000000
98.750008,65.164429,-694.525574,-0.000388,0.004051,0.102896,289.865845,14.766471,1.028963,-694.525574,294.500458,0.000000
99.110008,65.250824,-694.481079,-0.000397,0.004052,0.102931,290.250153,14.786048,1.029310,-694.481079,294.500458,0.000000
99.470001,65.245239,-694.570068,-0.000392,0.004052,0.102931,290.225311,14.784782,1.029310,-694.570068,294.500458,0.000000
99.830002,65.246735,-694.570068,-0.000388,0.004052,0.102931,290.231964,14.785122,1.029310,-694.570068,294.500458,0.000000
100.190002,65.227371,-694.614502,-0.000397,0.004053,0.102940,290.145844,14.780734,1.029397,-694.614502,294.500458,0.000000
100.550003,65.220291,-694.614502,-0.000392,0.004053,0.102940,290.114349,14.779129,1.029397,-694.614502,294.500458,0.000000
100.910004,65.222900,-694.658997,-0.000384,0.004053,0.102948,290.125946,14.779721,1.029484,-694.658997,294.500458,0.000000
101.270004,65.188263,-694.570068,-0.000392,0.004053,0.102948,289.971863,14.771872,1.029484,-694.570068,294.500458,0.000000
101.630005,65.173370,-694.525574,-0.000397,0.004053,0.102948,289.905640,14.768497,1.029484,-694.525574,294.500458,0.000000
101.990005,65.139481,-694.703491,-0.000397,0.004053,0.102948,289.754883,14.760817,1.029484,-694.703491,294.500458,0.000000
102.350006,65.253067,-694.570068,-0.000392,0.004056,0.103018,290.260132,14.786556,1.030177,-694.570068,294.500458,0.000000
102.710007,65.285080,-694.703491,-0.000397,0.004056,0.103018,290.402527,14.793811,1.030177,-694.703491,294.500458,0.000000
103.070007,65.285461,-694.614502,-0.000405,0.004056,0.103018,290.404236,14.793897,1.030177,-694.614502,294.500458,0.000000
103.430008,65.285080,-694.614502,-0.000371,0.004056,0.103018,290.402527,14.793811,1.030177,-694.614502,294.500458,0.000000
103.790009,65.270569,-694.747986,-0.000392,0.004056,0.103018,290.337982,14.790523,1.030177,-694.747986,294.500458,0.000000
104.150002,65.271683,-694.658997,-0.000388,0.004056,0.103018,290.342957,14.790774,1.030177,-694.658997,294.500458,0.000000
104.510002,65.250076,-694.658997,-0.000379,0.004056,0.103018,290.246826,14.785879,1.030177,-694.658997,294.500458,0.000000
104.870003,65.235931,-694.747986,-0.000392,0.004056,0.103018,290.183929,14.782673,1.030177,-694.747986,294.500458,0.000000
105.230003,65.238907,-694.658997,-0.000379,0.004056,0.103035,290.197144,14.783348,1.030351,-694.658997,294.500458,0.000000
105.590004,65.218063,-694.792480,-0.000401,0.004056,0.103035,290.104431,14.778625,1.030351,-694.792480,294.500458,0.000000
105.950005,65.220291,-694.614502,-0.000397,0.004056,0.103035,290.114349,14.779129,1.030351,-694.614502,294.500458,0.000000
106.310005,65.217316,-694.703491,-0.000388,0.004057,0.103052,290.101105,14.778456,1.030524,-694.703491,294.500458,0.000000
106.670006,65.311890,-694.703491,-0.000384,0.004059,0.103096,290.521790,14.799886,1.030958,-694.703491,294.500458,0.000000
107.030006,65.310776,-694.703491,-0.000388,0.004059,0.103096,290.516846,14.799634,1.030958,-694.703491,294.500458,0.000000
107.390007,65.331253,-694.836914,-0.000388,0.004059,0.103096,290.607941,14.804274,1.030958,-694.836914,294.500458,0.000000
107.750008,65.324554,-694.792480,-0.000392,0.004059,0.103096,290.578125,14.802755,1.030958,-694.792480,294.500458,0.000000
108.110008,65.328278,-694.703491,-0.000388,0.004059,0.103096,290.594696,14.803599,1.030958,-694.703491,294.500458,0.000000
108.470009,65.315613,-694.703491,-0.000392,0.004059,0.103096,290.538361,14.800730,1.030958,-694.703491,294.500458,0.000000
108.830002,65.299973,-694.703491,-0.000401,0.004059,0.103096,290.468781,14.797185,1.030958,-694.703491,294.500458,0.000000
109.190002,65.294022,-694.881409,-0.000375,0.004059,0.103096,290.442322,14.795836,1.030958,-694.881409,294.500458,0.000000
109.550003,65.253433,-694.836914,-0.000388,0.004059,0.103104,290.261780,14.786639,1.031045,-694.836914,294.500458,0.000000
109.910004,65.271683,-694.792480,-0.000384,0.004059,0.103104,290.342957,14.790774,1.031045,-694.792480,294.500458,0.000000
110.270004,65.252319,-694.836914,-0.000388,0.004059,0.103104,290.256805,14.786387,1.031045,-694.836914,294.500458,0.000000
110.630005,65.215073,-694.792480,-0.000388,0.004060,0.103130,290.091125,14.777947,1.031305,-694.792480,294.500458,0.000000
110.990005,65.262741,-694.881409,-0.000371,0.004060,0.103130,290.303162,14.788749,1.031305,-694.881409,294.500458,0.000000
111.350006,65.261993,-694.836914,-0.000379,0.004060,0.103130,290.299835,14.788579,1.031305,-694.836914,294.500458,0.000000
111.710007,65.251938,-694.792480,-0.000384,0.004060,0.103130,290.255127,14.786300,1.031305,-694.792480,294.500458,0.000000
112.070007,65.242630,-694.881409,-0.000392,0.004060,0.103130,290.213715,14.784191,1.031305,-694.881409,294.500458,0.000000
112.430008,65.235565,-694.836914,-0.000388,0.004060,0.103130,290.182281,14.782591,1.031305,-694.836914,294.500458,0.000000
112.790009,65.218063,-694.881409,-0.000375,0.004061,0.103139,290.104431,14.778625,1.031392,-694.881409,294.500458,0.000000
113.150009,65.288055,-694.836914,-0.000392,0.004063,0.103200,290.415771,14.794485,1.031999,-694.836914,294.500458,0.000000
113.510002,65.319336,-694.881409,-0.000384,0.004063,0.103200,290.554932,14.801573,1.031999,-694.881409,294.500458,0.000000
113.870003,65.305939,-694.881409,-0.000379,0.004063,0.103200,290.495331,14.798536,1.031999,-694.881409,294.500458,0.000000
114.230003,65.318604,-694.836914,-0.000375,0.004063,0.103200,290.551666,14.801407,1.031999,-694.836914,294.500458,0.000000
114.590004,65.308914,-694.881409,-0.000379,0.004063,0.103200,290.508545,14.799212,1.031999,-694.881409,294.500458,0.000000
114.950005,65.300720,-694.925903,-0.000392,0.004063,0.103200,290.472107,14.797355,1.031999,-694.925903,294.500458,0.000000
115.310005,65.294022,-694.925903,-0.000371,0.004063,0.103200,290.442322,14.795836,1.031999,-694.925903,294.500458,0.000000
115.670006,65.295883,-694.970398,-0.000379,0.004063,0.103200,290.450592,14.796259,1.031999,-694.970398,294.500458,0.000000
116.030006,65.271301,-694.925903,-0.000388,0.004063,0.103200,290.341248,14.790689,1.031999,-694.925903,294.500458,0.000000
116.390007,65.260880,-694.925903,-0.000379,0.004063,0.103200,290.294891,14.788326,1.031999,-694.925903,294.500458,0.000000
116.750008,65.248962,-694.970398,-0.000392,0.004063,0.103200,290.241882,14.785626,1.031999,-694.970398,294.500458,0.000000
117.110008,65.235184,-694.970398,-0.000371,0.004063,0.103200,290.180603,14.782503,1.031999,-694.970398,294.500458,0.000000
117.470009,65.228485,-695.103821,-0.000388,0.004063,0.103200,290.150787,14.780987,1.031999,-695.103821,294.500458,0.000000
117.830002,65.215073,-695.014832,-0.000397,0.004063,0.103200,290.091125,14.777947,1.031999,-695.014832,294.500458,0.000000
118.190002,65.200562,-694.970398,-0.000384,0.004063,0.103200,290.026581,14.774658,1.031999,-694.970398,294.500458,0.000000
118.550003,65.195343,-695.059326,-0.000388,0.004063,0.103200,290.003357,14.773476,1.031999,-695.059326,294.500458,0.000000
118.910004,65.330139,-694.970398,-0.000392,0.004067,0.103304,290.602966,14.804021,1.033039,-694.970398,294.500458,0.000000
119.270004,65.397537,-695.014832,-0.000379,0.004067,0.103304,290.902771,14.819294,1.033039,-695.014832,294.500458,0.000000
119.630005,65.406845,-695.059326,-0.000379,0.004067,0.103304,290.944183,14.821403,1.033039,-695.059326,294.500458,0.000000
119.990005,65.402374,-694.970398,-0.000392,0.004067,0.103304,290.924286,14.820390,1.033039,-694.970398,294.500458,0.000000
120.350006,65.403870,-695.148315,-0.000379,0.004067,0.103304,290.930939,14.820729,1.033039,-695.148315,294.500458,0.000000
120.710007,65.405365,-695.014832,-0.000371,0.004067,0.103304,290.937592,14.821068,1.033039,-695.014832,294.500458,0.000000
121.070007,65.399399,-695.014832,-0.000375,0.004067,0.103304,290.911041,14.819715,1.033039,-695.014832,294.500458,0.000000
121.430008,65.396790,-695.148315,-0.000392,0.004067,0.103304,290.899445,14.819124,1.033039,-695.148315,294.500458,0.000000
121.790009,65.379288,-695.059326,-0.000366,0.004067,0.103304,290.821594,14.815159,1.033039,-695.059326,294.500458,0.000000
122.150009,65.366257,-695.103821,-0.000379,0.004067,0.103304,290.763641,14.812205,1.033039,-695.103821,294.500458,0.000000
122.510002,65.349884,-695.103821,-0.000384,0.004067,0.103304,290.690796,14.808496,1.033039,-695.103821,294.500458,0.000000
122.870003,65.343170,-695.059326,-0.000388,0.004067,0.103304,290.660950,14.806974,1.033039,-695.059326,294.500458,0.000000
123.230003,65.323059,-695.148315,-0.000384,0.004067,0.103304,290.571472,14.802417,1.033039,-695.148315,294.500458,0.000000
123.590004,65.314133,-695.059326,-0.000379,0.004067,0.103304,290.531769,14.800394,1.033039,-695.059326,294.500458,0.000000
123.950005,65.300354,-695.192810,-0.000375,0.004067,0.103304,290.470490,14.797272,1.033039,-695.192810,294.500458,0.000000
124.310005,65.292908,-695.148315,-0.000388,0.004067,0.103304,290.437347,14.795585,1.033039,-695.148315,294.500458,0.000000
124.670006,65.282852,-695.148315,-0.000366,0.004067,0.103304,290.392639,14.793305,1.033039,-695.148315,294.500458,0.000000
125.030006,65.268692,-695.237244,-0.000375,0.004067,0.103304,290.329651,14.790096,1.033039,-695.237244,294.500458,0.000000
125.390007,65.254181,-695.192810,-0.000392,0.004067,0.103304,290.265106,14.786808,1.033039,-695.192810,294.500458,0.000000
125.750008,65.244492,-695.192810,-0.000366,0.004067,0.103304,290.221985,14.784614,1.033039,-695.192810,294.500458,0.000000
126.110008,65.280991,-695.192810,-0.000388,0.004069,0.103347,290.384338,14.792884,1.033473,-695.192810,294.500458,0.000000
126.470009,65.310776,-695.103821,-0.000379,0.004064,0.103235,290.516846,14.799634,1.032346,-695.103821,0.103347,0.000000
126.830009,65.191986,-695.281738,-0.000371,0.004055,0.103000,289.988434,14.772716,1.030004,-695.281738,0.102801,0.000000
127.190002,65.210602,-695.237244,-0.000362,0.004038,0.102575,290.071259,14.776934,1.025755,-695.237244,0.102203,0.000000
127.550003,65.189011,-695.281738,-0.000366,0.004026,0.102255,289.975189,14.772040,1.022546,-695.281738,0.101604,0.000000
127.910004,65.114532,-695.326233,-0.000379,0.003999,0.101578,289.643921,14.755164,1.015782,-695.326233,0.101006,0.000000
128.270004,65.089966,-695.237244,-0.000371,0.003974,0.100936,289.534637,14.749597,1.009364,-695.237244,0.100399,0.000000
128.630005,65.067993,-695.281738,-0.000362,0.003951,0.100347,289.436890,14.744618,1.003467,-695.281738,0.099800,0.000000
128.990005,65.027405,-695.370728,-0.000371,0.003927,0.099757,289.256348,14.735421,0.997570,-695.370728,0.099202,0.000000
129.350006,65.048996,-695.281738,-0.000349,0.003907,0.099228,289.352386,14.740314,0.992280,-695.281738,0.098604,0.000000
129.710007,65.008408,-695.326233,-0.000366,0.003883,0.098621,289.171844,14.731116,0.986209,-695.326233,0.098005,0.000000
130.070007,64.871002,-695.326233,-0.000362,0.003856,0.097936,288.560638,14.699979,0.979358,-695.326233,0.097407,0.000000
130.430008,64.822601,-695.326233,-0.000358,0.003837,0.097467,288.345337,14.689012,0.974675,-695.326233,0.096800,0.000000
130.790009,64.476288,-695.326233,-0.000375,0.003818,0.096982,286.804840,14.610536,0.969819,-695.326233,0.096201,0.000000
131.150009,63.645905,-695.281738,-0.000349,0.003793,0.096349,283.111115,14.422368,0.963488,-695.281738,0.095603,0.000000
131.510010,62.868759,-695.326233,-0.000354,0.003777,0.095941,279.654205,14.246264,0.959412,-695.326233,0.095005,0.000000
131.870010,61.337936,-695.326233,-0.000358,0.003746,0.095161,272.844757,13.899376,0.951607,-695.326233,0.094406,0.000000
132.230011,60.188423,-695.370728,-0.000354,0.003729,0.094727,267.731476,13.638891,0.947271,-695.370728,0.093799,0.000000
132.590012,59.049332,-695.415161,-0.000362,0.003713,0.094311,262.664551,13.380771,0.943108,-695.415161,0.093201,0.000000
132.950012,56.428574,-695.370728,-0.000349,0.003681,0.093504,251.006836,12.786898,0.935043,-695.370728,0.092602,0.000000
133.310013,54.832588,-695.459656,-0.000354,0.003663,0.093045,243.907532,12.425241,0.930446,-695.459656,0.092004,0.000000
133.670013,53.636528,-695.415161,-0.000354,0.003654,0.092810,238.587189,12.154211,0.928105,-695.415161,0.091406,0.000000
134.029999,49.770561,-695.326233,-0.000341,0.003612,0.091752,221.390518,11.278171,0.917525,-695.326233,0.090799,0.000000
134.389999,47.317368,-695.415161,-0.000345,0.003588,0.091145,210.478165,10.722269,0.911454,-695.415161,0.090200,0.000000
134.750000,44.769966,-695.370728,-0.000375,0.003567,0.090608,199.146759,10.145020,0.906077,-695.370728,0.089602,0.000000
135.110001,42.384926,-695.415161,-0.000358,0.003546,0.090070,188.537567,9.604562,0.900701,-695.415161,0.089003,0.000000
135.470001,40.411346,-695.370728,-0.000362,0.003526,0.089567,179.758652,9.157342,0.895671,-695.370728,0.088405,0.000000
135.830002,37.078613,-695.370728,-0.000345,0.003496,0.088795,164.933914,8.402133,0.887952,-695.370728,0.087798,0.000000
136.190002,34.921463,-695.504150,-0.000349,0.003476,0.088292,155.338425,7.913317,0.882922,-695.504150,0.087200,0.000000
136.550003,32.443695,-695.504150,-0.000358,0.003449,0.087598,144.316757,7.351846,0.875985,-695.504150,0.086601,0.000000
136.910004,29.727982,-695.415161,-0.000358,0.003430,0.087121,132.236664,6.736457,0.871215,-695.415161,0.086003,0.000000
137.270004,27.638603,-695.459656,-0.000362,0.003411,0.086627,122.942650,6.262997,0.866272,-695.459656,0.085404,0.000000
137.630005,24.406036,-695.415161,-0.000362,0.003380,0.085847,108.563469,5.530487,0.858467,-695.415161,0.084806,0.000000
137.990005,21.640800,-695.504150,-0.000366,0.003355,0.085205,96.263092,4.903876,0.852049,-695.504150,0.084199,0.000000
138.350006,19.241974,-695.415161,-0.000371,0.003329,0.084563,85.592575,4.360293,0.845632,-695.415161,0.083601,0.000000
138.710007,17.320160,-695.504150,-0.000384,0.003317,0.084242,77.043922,3.924804,0.842423,-695.504150,0.083002,0.000000
139.070007,14.854309,-695.459656,-0.000375,0.003293,0.083644,66.075264,3.366035,0.836439,-695.459656,0.082404,0.000000
139.430008,11.432205,-695.548645,-0.000397,0.003260,0.082811,50.852989,2.590575,0.828114,-695.548645,0.081805,0.000000
139.790009,8.423065,-695.548645,-0.000392,0.003231,0.082074,37.467667,1.908694,0.820742,-695.548645,0.081198,0.000000
140.150009,6.634186,-695.504150,-0.000401,0.003215,0.081649,29.510332,1.503328,0.816493,-695.504150,0.080600,0.000000
140.510010,3.981033,-695.504150,-0.000401,0.003190,0.081025,17.708521,0.902115,0.810249,-695.504150,0.080002,0.000000
140.870010,1.824997,-695.548645,-0.000418,0.003166,0.080418,8.117991,0.413550,0.804178,-695.548645,0.079403,0.000000
141.230011,-0.837097,-695.548645,-0.000414,0.003140,0.079767,-3.723594,-0.189689,0.797674,-695.548645,0.078805,0.000000
141.590012,-1.433262,-695.593140,-0.000435,0.003113,0.079074,-6.375467,-0.324782,0.790736,-695.593140,0.078198,0.000000
141.950012,-0.307579,-695.548645,-0.000483,0.003096,0.078640,-1.368180,-0.069698,0.786400,-695.548645,0.077599,0.000000
142.310013,-0.183205,-695.593140,-0.000517,0.003073,0.078050,-0.814935,-0.041515,0.780503,-695.593140,0.077001,0.000000
142.670013,-0.029793,-695.593140,-0.000556,0.003053,0.077547,-0.132525,-0.006751,0.775473,-695.593140,0.076403,0.000000
143.030014,-0.018990,-695.593140,-0.000591,0.003031,0.076975,-0.084470,-0.004303,0.769750,-695.593140,0.075804,0.000000
143.389999,-0.069633,-695.593140,-0.000638,0.002993,0.076021,-0.309745,-0.015779,0.760210,-695.593140,0.075197,0.000000
143.750000,-0.029793,-695.593140,-0.000686,0.002972,0.075492,-0.132525,-0.006751,0.754920,-695.593140,0.074599,0.000000
144.110001,-0.053993,-695.637573,-0.000707,0.002948,0.074885,-0.240174,-0.012235,0.748849,-695.637573,0.074000,0.000000
144.470001,-0.027557,-695.637573,-0.000776,0.002928,0.074373,-0.122581,-0.006245,0.743733,-695.637573,0.073402,0.000000
144.830002,-0.021973,-695.593140,-0.000811,0.002905,0.073792,-0.097739,-0.004979,0.737922,-695.593140,0.072804,0.000000
145.190002,-0.031654,-695.682068,-0.000854,0.002881,0.073177,-0.140806,-0.007173,0.731765,-695.682068,0.072205,0.000000
145.550003,-0.028305,-695.637573,-0.000927,0.002858,0.072587,-0.125907,-0.006414,0.725868,-695.637573,0.071598,0.000000
145.910004,-0.008194,-695.637573,-0.000970,0.002839,0.072101,-0.036449,-0.001857,0.721011,-695.637573,0.071000,0.000000
146.270004,0.019737,-695.682068,-0.001030,0.002813,0.071459,0.087796,0.004473,0.714594,-695.682068,0.070401,0.000000
146.500000,0.023460,-695.682068,-0.001069,0.002806,0.071260,0.104357,0.005316,0.712599,-695.682068,0.071130,0.000000