File: Data/compression 33/AutoNoHeating-17-33-reverse-1-1_11152024_182528.csv
Time (sec),S:Load (lbs),S:HL1 (DIM),S:LVDT (in),S:Position (in),Ch:Position (mm),Ch:Load (N),Ch:Stress (MPa),Ch:Strain (mm/mm),Ch:HL1 (DIM),Set Point (),Cycles ()
0.110000,-0.075226,-104.797119,-0.013663,-0.008790,-0.223276,-0.334621,-0.017046,-2.232759,-104.797119,-0.223259,0.000000
0.480000,-0.088997,-104.797119,-0.013672,-0.008719,-0.221455,-0.395878,-0.020167,-2.214547,-104.797119,-0.220692,0.000000
0.850000,-0.093094,-104.841599,-0.013525,-0.008495,-0.215783,-0.414102,-0.021095,-2.157831,-104.841599,-0.214517,0.000000
1.220000,-0.074478,-104.886086,-0.013297,-0.008255,-0.209678,-0.331295,-0.016877,-2.096778,-104.886086,-0.208360,0.000000
1.590000,-0.077454,-104.797119,-0.013029,-0.008010,-0.203451,-0.344531,-0.017551,-2.034511,-104.797119,-0.202202,0.000000
1.960000,-0.065170,-104.886086,-0.012775,-0.007766,-0.197268,-0.289892,-0.014768,-1.972678,-104.886086,-0.196028,0.000000
2.330000,-0.114693,-104.930565,-0.012525,-0.007530,-0.191258,-0.510179,-0.025990,-1.912580,-104.930565,-0.189870,0.000000
2.700000,-0.133682,-104.975044,-0.012275,-0.007287,-0.185092,-0.594648,-0.030293,-1.850920,-104.975044,-0.183696,0.000000
3.070000,-0.180603,-104.930565,-0.012025,-0.007042,-0.178857,-0.803362,-0.040925,-1.788566,-104.930565,-0.177538,0.000000
3.440000,-0.053627,-104.975044,-0.011792,-0.006806,-0.172873,-0.238545,-0.012152,-1.728728,-104.975044,-0.171381,0.000000
3.810000,-0.054741,-105.108490,-0.011520,-0.006552,-0.166429,-0.243500,-0.012404,-1.664293,-105.108490,-0.165206,0.000000
4.180000,-0.048782,-105.108490,-0.011279,-0.006317,-0.160463,-0.216995,-0.011054,-1.604628,-105.108490,-0.159049,0.000000
4.550000,-0.077087,-105.152969,-0.011016,-0.006070,-0.154184,-0.342902,-0.017468,-1.541841,-105.152969,-0.152875,0.000000
4.920000,-0.064423,-105.152969,-0.010779,-0.005827,-0.148009,-0.286566,-0.014598,-1.480094,-105.152969,-0.146717,0.000000
5.290000,-0.098679,-105.152969,-0.010555,-0.005588,-0.141939,-0.438944,-0.022361,-1.419388,-105.152969,-0.140560,0.000000
5.660000,-0.069267,-105.241928,-0.010287,-0.005346,-0.135782,-0.308116,-0.015696,-1.357815,-105.241928,-0.134385,0.000000
6.030000,-0.050270,-105.286407,-0.010016,-0.005092,-0.129347,-0.223612,-0.011391,-1.293467,-105.286407,-0.128228,0.000000
6.400000,-0.055115,-105.197449,-0.009787,-0.004861,-0.123476,-0.245163,-0.012489,-1.234756,-105.197449,-0.122053,0.000000
6.770000,-0.100914,-105.241928,-0.009533,-0.004616,-0.117258,-0.448888,-0.022867,-1.172576,-105.241928,-0.115896,0.000000
7.140000,-0.138901,-105.330894,-0.009287,-0.004365,-0.110875,-0.617861,-0.031475,-1.108748,-105.330894,-0.109739,0.000000
7.510000,-0.097939,-105.375374,-0.009037,-0.004124,-0.104744,-0.435652,-0.022193,-1.047435,-105.375374,-0.103564,0.000000
7.880001,-0.059586,-105.419853,-0.008787,-0.003884,-0.098656,-0.265050,-0.013502,-0.986556,-105.419853,-0.097407,0.000000
8.250000,-0.019363,-105.375374,-0.008537,-0.003641,-0.092481,-0.086133,-0.004388,-0.924810,-105.375374,-0.091249,0.000000
8.620001,-0.069633,-105.464333,-0.008278,-0.003401,-0.086376,-0.309745,-0.015779,-0.863757,-105.464333,-0.085075,0.000000
8.990001,-0.050644,-105.464333,-0.008054,-0.003159,-0.080227,-0.225275,-0.011476,-0.802270,-105.464333,-0.078918,0.000000
9.360001,-0.050644,-105.553299,-0.007774,-0.002911,-0.073940,-0.225275,-0.011476,-0.739397,-105.553299,-0.072743,0.000000
9.730000,-0.097939,-105.553299,-0.007524,-0.002676,-0.067982,-0.435652,-0.022193,-0.679818,-105.553299,-0.066586,0.000000
10.100000,-0.075592,-105.553299,-0.007286,-0.002430,-0.061729,-0.336250,-0.017129,-0.617291,-105.553299,-0.060428,0.000000
10.470000,-0.060699,-105.597778,-0.007028,-0.002184,-0.055468,-0.270005,-0.013755,-0.554678,-105.597778,-0.054254,0.000000
10.840000,-0.105759,-105.642258,-0.006782,-0.001945,-0.049397,-0.470438,-0.023965,-0.493972,-105.642258,-0.048096,0.000000
11.210001,-0.117302,-105.686737,-0.006541,-0.001702,-0.043240,-0.521785,-0.026581,-0.432399,-105.686737,-0.041922,0.000000
11.580001,-0.090858,-105.731224,-0.006286,-0.001461,-0.037109,-0.404159,-0.020589,-0.371086,-105.731224,-0.035764,0.000000
11.950001,-0.034264,-105.775703,-0.006053,-0.001218,-0.030934,-0.152412,-0.007764,-0.309339,-105.775703,-0.029607,0.000000
12.320001,-0.030540,-105.731224,-0.005786,-0.000970,-0.024629,-0.135851,-0.006921,-0.246292,-105.731224,-0.023432,0.000000
12.690001,-0.027557,-105.820183,-0.005540,-0.000732,-0.018602,-0.122581,-0.006245,-0.186020,-105.820183,-0.017275,0.000000
13.060000,-0.034637,-105.864662,-0.005303,-0.000492,-0.012497,-0.154075,-0.007849,-0.124967,-105.864662,-0.011100,0.000000
13.430000,-0.026070,-105.864662,-0.005049,-0.000249,-0.006322,-0.115964,-0.005907,-0.063221,-105.864662,-0.004943,0.000000
13.800000,0.080429,-105.864662,-0.004919,-0.000009,-0.000234,0.357766,0.018225,-0.002341,-105.864662,-0.000000,0.000000
14.170001,0.079315,-105.864662,-0.004928,-0.000009,-0.000234,0.352812,0.017973,-0.002341,-105.864662,0.000078,0.000000
14.540001,0.163467,-105.953629,-0.004932,-0.000009,-0.000234,0.727139,0.037042,-0.002341,-105.953629,0.000694,0.000000
14.910001,0.107613,-106.087067,-0.004945,-0.000009,-0.000225,0.478685,0.024385,-0.002255,-106.087067,0.001310,0.000000
15.280001,0.367157,-106.042587,-0.004889,0.000034,0.000876,1.633196,0.083199,0.008759,-106.042587,0.001925,0.000000
15.650001,0.551849,-105.998108,-0.004868,0.000057,0.001457,2.454749,0.125051,0.014569,-105.998108,0.002541,0.000000
16.020000,0.721283,-106.042587,-0.004850,0.000076,0.001934,3.208427,0.163445,0.019339,-106.042587,0.003157,0.000000
16.390001,1.020668,-106.131546,-0.004842,0.000094,0.002376,4.540158,0.231287,0.023762,-106.131546,0.003772,0.000000
16.760000,1.566566,-106.176033,-0.004807,0.000123,0.003113,6.968436,0.354989,0.031134,-106.176033,0.004397,0.000000
17.130001,2.154915,-106.131546,-0.004790,0.000154,0.003920,9.585540,0.488311,0.039199,-106.131546,0.005013,0.000000
17.500000,2.809547,-106.087067,-0.004773,0.000183,0.004657,12.497491,0.636653,0.046570,-106.087067,0.005628,0.000000
17.870001,3.036324,-106.176033,-0.004743,0.000198,0.005030,13.506242,0.688041,0.050299,-106.176033,0.006244,0.000000
18.240002,3.687973,-106.309471,-0.004725,0.000224,0.005698,16.404922,0.835707,0.056977,-106.309471,0.006860,0.000000
18.610001,3.760956,-106.353951,-0.004717,0.000238,0.006053,16.729567,0.852245,0.060533,-106.353951,0.007475,0.000000
18.980001,4.918289,-106.309471,-0.004669,0.000276,0.006999,21.877644,1.114500,0.069985,-106.309471,0.008091,0.000000
19.350000,5.517067,-106.309471,-0.004652,0.000300,0.007632,24.541140,1.250185,0.076316,-106.309471,0.008707,0.000000
19.720001,5.663780,-106.442917,-0.004656,0.000311,0.007892,25.193752,1.283431,0.078918,-106.442917,0.009323,0.000000
20.090000,6.371666,-106.353951,-0.004626,0.000339,0.008612,28.342587,1.443840,0.086116,-106.353951,0.009947,0.000000
20.460001,7.253815,-106.442917,-0.004587,0.000372,0.009461,32.266579,1.643738,0.094614,-106.442917,0.010563,0.000000
20.830002,7.655602,-106.487396,-0.004579,0.000396,0.010069,34.053818,1.734784,0.100685,-106.487396,0.011179,0.000000
21.200001,8.127396,-106.442917,-0.004549,0.000422,0.010728,36.152462,1.841694,0.107276,-106.442917,0.011794,0.000000
21.570002,8.965233,-106.531876,-0.004531,0.000450,0.011430,39.879349,2.031551,0.114301,-106.531876,0.012410,0.000000
21.940001,9.181953,-106.620842,-0.004514,0.000469,0.011916,40.843369,2.080660,0.119157,-106.620842,0.013026,0.000000
22.310001,9.036362,-106.620842,-0.004501,0.000476,0.012089,40.195744,2.047669,0.120891,-106.620842,0.013641,0.000000
22.680000,10.299072,-106.620842,-0.004449,0.000520,0.013217,45.812561,2.333803,0.132165,-106.620842,0.014257,0.000000
23.050001,10.779434,-106.665321,-0.004437,0.000546,0.013858,47.949318,2.442655,0.138583,-106.665321,0.014873,0.000000
23.420002,11.120155,-106.665321,-0.004415,0.000566,0.014379,49.464920,2.519863,0.143786,-106.665321,0.015497,0.000000
23.790001,11.602005,-106.754280,-0.004393,0.000596,0.015142,51.608295,2.629052,0.151418,-106.754280,0.016113,0.000000
24.160002,12.131523,-106.754280,-0.004368,0.000622,0.015810,53.963711,2.749043,0.158095,-106.754280,0.016729,0.000000
24.530001,12.255150,-106.709801,-0.004346,0.000642,0.016304,54.513630,2.777057,0.163039,-106.709801,0.017345,0.000000
24.900002,12.834557,-106.798767,-0.004329,0.000667,0.016946,57.090958,2.908352,0.169456,-106.798767,0.017960,0.000000
25.270000,12.847221,-106.798767,-0.004312,0.000678,0.017214,57.147293,2.911222,0.172144,-106.798767,0.018576,0.000000
25.640001,13.844429,-106.843246,-0.004268,0.000717,0.018212,61.583096,3.137192,0.182118,-106.843246,0.019192,0.000000
26.010002,14.197815,-106.932205,-0.004247,0.000739,0.018775,63.155037,3.217271,0.187754,-106.932205,0.019807,0.000000
26.380001,14.184784,-106.887726,-0.004238,0.000755,0.019174,63.097069,3.214318,0.191744,-106.887726,0.020423,0.000000
26.750002,14.808876,-106.887726,-0.004212,0.000784,0.019912,65.873169,3.355739,0.199115,-106.887726,0.021048,0.000000
27.120001,15.094116,-106.976685,-0.004208,0.000803,0.020406,67.141983,3.420376,0.204058,-106.976685,0.021663,0.000000
27.490002,15.847794,-106.976685,-0.004165,0.000833,0.021152,70.494507,3.591161,0.211516,-106.976685,0.022279,0.000000
27.860001,15.937538,-107.065651,-0.004135,0.000854,0.021681,70.893707,3.611498,0.216807,-107.065651,0.022895,0.000000
28.230001,16.464447,-106.932205,-0.004122,0.000877,0.022288,73.237518,3.730897,0.222877,-106.932205,0.023510,0.000000
28.600002,16.966774,-107.065651,-0.004079,0.000906,0.023016,75.471977,3.844726,0.230162,-107.065651,0.024126,0.000000
28.970001,17.134712,-107.065651,-0.004070,0.000930,0.023623,76.219009,3.882781,0.236232,-107.065651,0.024742,0.000000
29.340002,17.717476,-107.154610,-0.004036,0.000959,0.024360,78.811272,4.014837,0.243604,-107.154610,0.025358,0.000000
29.710001,17.561829,-107.154610,-0.004014,0.000973,0.024725,78.118912,3.979567,0.247246,-107.154610,0.025973,0.000000
30.080002,17.851532,-107.199089,-0.003988,0.000996,0.025288,79.407578,4.045215,0.252883,-107.199089,0.026598,0.000000
30.450001,18.828262,-107.243576,-0.003967,0.001030,0.026156,83.752296,4.266545,0.261555,-107.243576,0.027214,0.000000
30.820002,19.081848,-107.243576,-0.003941,0.001054,0.026771,84.880302,4.324008,0.267713,-107.243576,0.027829,0.000000
31.190001,19.282562,-107.332535,-0.003923,0.001078,0.027387,85.773117,4.369491,0.273870,-107.332535,0.028445,0.000000
31.560001,19.450874,-107.332535,-0.003880,0.001099,0.027925,86.521812,4.407631,0.279247,-107.332535,0.029061,0.000000
31.930002,19.779305,-107.332535,-0.003859,0.001123,0.028532,87.982742,4.482055,0.285317,-107.332535,0.029676,0.000000
32.300003,20.205673,-107.288055,-0.003833,0.001152,0.029252,89.879326,4.578671,0.292515,-107.288055,0.030292,0.000000
32.670002,20.104012,-107.377014,-0.003798,0.001172,0.029772,89.427109,4.555634,0.297719,-107.377014,0.030908,0.000000
33.040001,20.462982,-107.465981,-0.003773,0.001195,0.030362,91.023888,4.636978,0.303616,-107.465981,0.031524,0.000000
33.410000,20.449203,-107.465981,-0.003738,0.001216,0.030891,90.962601,4.633855,0.308906,-107.465981,0.032148,0.000000
33.780003,20.731087,-107.510460,-0.003708,0.001240,0.031506,92.216476,4.697731,0.315063,-107.510460,0.032764,0.000000
34.150002,20.734070,-107.554939,-0.003691,0.001267,0.032183,92.229752,4.698408,0.321828,-107.554939,0.033380,0.000000
34.520000,21.314972,-107.554939,-0.003656,0.001293,0.032851,94.813728,4.830042,0.328505,-107.554939,0.033995,0.000000
34.890003,22.039230,-107.643898,-0.003630,0.001328,0.033735,98.035393,4.994161,0.337351,-107.643898,0.034611,0.000000
35.260002,21.618828,-107.599419,-0.003587,0.001349,0.034264,96.165352,4.898897,0.342641,-107.599419,0.035227,0.000000
35.630001,21.717133,-107.643898,-0.003557,0.001373,0.034871,96.602631,4.921173,0.348712,-107.643898,0.035842,0.000000
36.000000,21.981514,-107.688385,-0.003544,0.001396,0.035461,97.778656,4.981082,0.354609,-107.688385,0.036458,0.000000
36.370003,22.007584,-107.688385,-0.003514,0.001417,0.035999,97.894623,4.986990,0.359985,-107.688385,0.037083,0.000000
36.740002,22.260796,-107.732864,-0.003484,0.001440,0.036588,99.020966,5.044368,0.365883,-107.732864,0.037698,0.000000
37.110001,22.322235,-107.777344,-0.003454,0.001466,0.037230,99.294258,5.058291,0.372300,-107.777344,0.038314,0.000000
37.480003,22.784721,-107.732864,-0.003432,0.001488,0.037802,101.351501,5.163092,0.378024,-107.732864,0.038930,0.000000
37.850002,22.376602,-107.866310,-0.003406,0.001503,0.038175,99.536095,5.070611,0.381753,-107.866310,0.039546,0.000000
38.220001,23.294502,-107.866310,-0.003376,0.001537,0.039051,103.619118,5.278610,0.390512,-107.866310,0.040161,0.000000
38.590000,23.644905,-107.910789,-0.003346,0.001564,0.039736,105.177788,5.358012,0.397363,-107.910789,0.040777,0.000000
38.960003,23.693314,-107.866310,-0.003294,0.001592,0.040439,105.393120,5.368982,0.404387,-107.866310,0.041393,0.000000
39.330002,23.343651,-107.910789,-0.003264,0.001612,0.040933,103.837746,5.289747,0.409331,-107.910789,0.042008,0.000000
39.700001,23.215187,-107.955269,-0.003242,0.001628,0.041349,103.266312,5.260636,0.413493,-107.955269,0.042633,0.000000
40.070004,24.015045,-108.044228,-0.003208,0.001661,0.042182,106.824257,5.441887,0.421819,-108.044228,0.043249,0.000000
40.440002,23.859390,-108.088715,-0.003186,0.001684,0.042763,106.131866,5.406615,0.427629,-108.088715,0.043864,0.000000
40.810001,23.869820,-108.044228,-0.003134,0.001704,0.043275,106.178261,5.408978,0.432746,-108.044228,0.044480,0.000000
41.180000,23.812096,-108.088715,-0.003117,0.001723,0.043769,105.921494,5.395898,0.437689,-108.088715,0.045096,0.000000
41.550003,23.587555,-108.044228,-0.003087,0.001740,0.044194,104.922684,5.345016,0.441938,-108.044228,0.045711,0.000000
41.920002,25.126572,-108.133194,-0.003065,0.001780,0.045200,111.768570,5.693762,0.451998,-108.133194,0.046327,0.000000
42.290001,24.653290,-108.177673,-0.003035,0.001807,0.045902,109.663307,5.586515,0.459023,-108.177673,0.046943,0.000000
42.660004,24.489441,-108.222153,-0.002997,0.001824,0.046327,108.934471,5.549387,0.463272,-108.222153,0.047559,0.000000
43.030003,25.192482,-108.222153,-0.002949,0.001857,0.047177,112.061760,5.708698,0.471771,-108.222153,0.048183,0.000000
43.400002,24.757179,-108.222153,-0.002949,0.001877,0.047680,110.125435,5.610057,0.476801,-108.222153,0.048799,0.000000
43.770000,24.786972,-108.266632,-0.002893,0.001897,0.048174,110.257957,5.616808,0.481744,-108.266632,0.049415,0.000000
44.140003,25.138863,-108.355598,-0.002876,0.001929,0.049007,111.823242,5.696548,0.490069,-108.355598,0.050030,0.000000
44.510002,25.482193,-108.311119,-0.002820,0.001953,0.049597,113.350456,5.774347,0.495966,-108.311119,0.050646,0.000000
44.880001,25.773384,-108.311119,-0.002807,0.001979,0.050256,114.645737,5.840332,0.502557,-108.311119,0.051262,0.000000
45.250004,25.857910,-108.311119,-0.002768,0.002005,0.050924,115.021729,5.859486,0.509235,-108.311119,0.051877,0.000000
45.620003,25.787163,-108.489037,-0.002742,0.002026,0.051461,114.707031,5.843454,0.514612,-108.489037,0.052493,0.000000
45.990002,25.851952,-108.489037,-0.002712,0.002050,0.052060,114.995224,5.858136,0.520596,-108.489037,0.053109,0.000000
46.360001,26.345352,-108.489037,-0.002669,0.002076,0.052727,117.189980,5.969942,0.527273,-108.489037,0.053733,0.000000
46.730003,26.316307,-108.533524,-0.002647,0.002101,0.053360,117.060783,5.963360,0.533604,-108.533524,0.054349,0.000000
47.100002,26.253746,-108.533524,-0.002630,0.002118,0.053794,116.782494,5.949184,0.537940,-108.533524,0.054965,0.000000
47.470001,26.478287,-108.578003,-0.002613,0.002144,0.054453,117.781303,6.000065,0.544531,-108.578003,0.055580,0.000000
47.840004,26.399345,-108.622482,-0.002565,0.002163,0.054930,117.430153,5.982177,0.549301,-108.622482,0.056196,0.000000
48.210003,26.791451,-108.666962,-0.002544,0.002188,0.055572,119.174324,6.071030,0.555718,-108.666962,0.056812,0.000000
48.580002,26.746391,-108.666962,-0.002509,0.002207,0.056049,118.973892,6.060819,0.560488,-108.666962,0.057428,0.000000
48.950001,27.543640,-108.711441,-0.002488,0.002237,0.056821,122.520233,6.241478,0.568206,-108.711441,0.058043,0.000000
49.320004,28.264557,-108.666962,-0.002445,0.002266,0.057566,125.727028,6.404840,0.575665,-108.666962,0.058659,0.000000
49.690002,28.131248,-108.755928,-0.002414,0.002290,0.058165,125.134041,6.374632,0.581648,-108.755928,0.059284,0.000000
50.060001,28.014320,-108.800407,-0.002384,0.002314,0.058772,124.613922,6.348136,0.587719,-108.800407,0.059899,0.000000
50.430004,27.977829,-108.800407,-0.002354,0.002333,0.059258,124.451599,6.339867,0.592575,-108.800407,0.060515,0.000000
50.800003,28.752365,-108.800407,-0.002333,0.002364,0.060047,127.896904,6.515379,0.600467,-108.800407,0.061131,0.000000
51.170002,28.650703,-108.889366,-0.002302,0.002385,0.060567,127.444695,6.492342,0.605671,-108.889366,0.061746,0.000000
51.540001,28.204605,-108.978333,-0.002276,0.002398,0.060905,125.460350,6.391255,0.609053,-108.978333,0.062362,0.000000
51.910004,29.506042,-108.933846,-0.002255,0.002433,0.061790,131.249435,6.686165,0.617898,-108.933846,0.062978,0.000000
52.280003,29.416679,-108.933846,-0.002216,0.002457,0.062406,130.851929,6.665915,0.624056,-108.933846,0.063594,0.000000
52.650002,30.138710,-108.978333,-0.002186,0.002483,0.063056,134.063675,6.829529,0.630560,-108.978333,0.064209,0.000000
53.020004,29.955498,-108.978333,-0.002164,0.002502,0.063559,133.248703,6.788013,0.635590,-108.978333,0.064834,0.000000
53.390003,30.261215,-109.022812,-0.002143,0.002528,0.064218,134.608612,6.857289,0.642181,-109.022812,0.065450,0.000000
53.760002,31.189911,-109.156258,-0.002117,0.002558,0.064981,138.739655,7.067735,0.649812,-109.156258,0.066065,0.000000
54.130001,31.129219,-109.111771,-0.002074,0.002576,0.065424,138.469681,7.053982,0.654235,-109.111771,0.066681,0.000000
54.500004,31.955513,-109.111771,-0.002048,0.002606,0.066195,142.145218,7.241223,0.661954,-109.111771,0.067297,0.000000
54.870003,31.445358,-109.156258,-0.002022,0.002621,0.066577,139.875946,7.125620,0.665769,-109.156258,0.067912,0.000000
55.240002,31.675491,-109.200737,-0.002001,0.002641,0.067080,140.899628,7.177769,0.670799,-109.200737,0.068528,0.000000
55.610004,33.348930,-109.245216,-0.001983,0.002680,0.068060,148.343445,7.556975,0.680599,-109.245216,0.069144,0.000000
55.980003,33.236847,-109.200737,-0.001953,0.002698,0.068520,147.844879,7.531577,0.685195,-109.200737,0.069760,0.000000
56.350002,34.336090,-109.245216,-0.001914,0.002733,0.069430,152.734558,7.780669,0.694301,-109.245216,0.070384,0.000000
56.720001,34.296616,-109.289696,-0.001901,0.002754,0.069959,152.558960,7.771724,0.699591,-109.289696,0.071000,0.000000
57.090004,34.797089,-109.334175,-0.001871,0.002781,0.070636,154.785187,7.885133,0.706356,-109.334175,0.071616,0.000000
57.460003,34.823524,-109.423141,-0.001845,0.002801,0.071147,154.902771,7.891123,0.711472,-109.423141,0.072231,0.000000
57.830002,35.224571,-109.423141,-0.001811,0.002823,0.071711,156.686722,7.982002,0.717109,-109.423141,0.072847,0.000000
58.200005,35.232765,-109.378662,-0.001789,0.002839,0.072110,156.723160,7.983859,0.721098,-109.378662,0.073463,0.000000
58.570004,36.365891,-109.423141,-0.001768,0.002870,0.072908,161.763565,8.240628,0.729077,-109.423141,0.074078,0.000000
58.940002,36.367012,-109.467621,-0.001750,0.002885,0.073289,161.768555,8.240883,0.732893,-109.467621,0.074694,0.000000
59.310001,37.999489,-109.601067,-0.001742,0.002919,0.074148,169.030167,8.610807,0.741478,-109.601067,0.075310,0.000000
59.680004,38.281746,-109.556580,-0.001699,0.002938,0.074616,170.285706,8.674767,0.746161,-109.556580,0.075934,0.000000
60.050003,39.041389,-109.556580,-0.001669,0.002970,0.075440,173.664780,8.846906,0.754400,-109.556580,0.076550,0.000000
60.420002,39.929871,-109.556580,-0.001656,0.002995,0.076073,177.616928,9.048238,0.760731,-109.556580,0.077166,0.000000
60.790005,39.734749,-109.645546,-0.001634,0.003014,0.076559,176.748993,9.004023,0.765587,-109.645546,0.077781,0.000000
61.160004,41.100609,-109.690025,-0.001595,0.003043,0.077296,182.824646,9.313531,0.772958,-109.690025,0.078397,0.000000
61.530003,41.824501,-109.690025,-0.001582,0.003068,0.077920,186.044678,9.477568,0.779202,-109.690025,0.079013,0.000000
61.900002,42.782242,-109.734505,-0.001556,0.003094,0.078588,190.304916,9.694594,0.785880,-109.734505,0.079629,0.000000
62.270004,42.009567,-109.734505,-0.001544,0.003103,0.078805,186.867889,9.519504,0.788048,-109.734505,0.080244,0.000000
62.640003,43.292023,-109.778984,-0.001518,0.003132,0.079559,192.572540,9.810113,0.795593,-109.778984,0.080869,0.000000
63.010002,43.644287,-109.778984,-0.001492,0.003161,0.080288,194.139481,9.889937,0.802878,-109.778984,0.081485,0.000000
63.380005,45.721375,-109.823471,-0.001453,0.003190,0.081016,203.378830,10.360611,0.810162,-109.823471,0.082100,0.000000
63.750004,46.581932,-109.823471,-0.001444,0.003215,0.081667,207.206787,10.555616,0.816667,-109.823471,0.082716,0.000000
64.120003,47.278267,-109.823471,-0.001423,0.003238,0.082256,210.304230,10.713408,0.822564,-109.823471,0.083332,0.000000
64.490005,47.661812,-109.956909,-0.001406,0.003260,0.082794,212.010330,10.800322,0.827941,-109.956909,0.083947,0.000000
64.860001,48.993790,-110.045876,-0.001388,0.003289,0.083540,217.935257,11.102151,0.835399,-110.045876,0.084563,0.000000
65.230003,49.581390,-110.001389,-0.001362,0.003310,0.084069,220.549042,11.235304,0.840689,-110.001389,0.085179,0.000000
65.600006,51.085030,-110.045876,-0.001341,0.003340,0.084832,227.237564,11.576034,0.848320,-110.045876,0.085795,0.000000
65.970001,50.988586,-110.045876,-0.001324,0.003351,0.085118,226.808563,11.554179,0.851182,-110.045876,0.086419,0.000000
66.340004,52.717880,-110.045876,-0.001324,0.003385,0.085977,234.500839,11.946042,0.859768,-110.045876,0.087035,0.000000
66.710007,53.807076,-110.090355,-0.001285,0.003411,0.086645,239.345825,12.192857,0.866445,-110.090355,0.087651,0.000000
67.080002,54.389091,-110.090355,-0.001272,0.003431,0.087156,241.934769,12.324744,0.871562,-110.090355,0.088266,0.000000
67.450005,55.337151,-110.134834,-0.001263,0.003453,0.087694,246.151947,12.539577,0.876939,-110.134834,0.088882,0.000000
67.820000,56.549599,-110.179314,-0.001229,0.003476,0.088301,251.545181,12.814322,0.883009,-110.179314,0.089498,0.000000
68.190002,57.561333,-110.268280,-0.001229,0.003506,0.089047,256.045593,13.043585,0.890468,-110.268280,0.090113,0.000000
68.560005,59.242966,-110.268280,-0.001207,0.003534,0.089758,263.525879,13.424648,0.897579,-110.268280,0.090729,0.000000
68.930000,60.087883,-110.312759,-0.001181,0.003551,0.090183,267.284241,13.616109,0.901828,-110.312759,0.091345,0.000000
69.300003,61.131264,-110.268280,-0.001155,0.003577,0.090859,271.925446,13.852543,0.908592,-110.268280,0.091969,0.000000
69.670006,62.048050,-110.268280,-0.001168,0.003592,0.091241,276.003510,14.060289,0.912408,-110.268280,0.092585,0.000000
70.040001,63.246712,-110.312759,-0.001143,0.003616,0.091848,281.335419,14.331910,0.918479,-110.312759,0.093201,0.000000
70.410004,64.206322,-110.401718,-0.001121,0.003636,0.092342,285.603973,14.549360,0.923422,-110.401718,0.093816,0.000000
70.780006,65.730064,-110.446205,-0.001112,0.003656,0.092863,292.381927,14.894646,0.928625,-110.446205,0.093097,0.000000
71.150002,64.551140,-110.446205,-0.001095,0.003656,0.092854,287.137817,14.627498,0.928539,-110.446205,294.500488,0.000000
71.520004,66.047707,-110.490685,-0.001074,0.003467,0.088049,293.794861,14.966624,0.880494,-110.490685,294.500488,0.000000
71.890007,65.050865,-110.535164,-0.001065,0.003628,0.092151,289.360687,14.740736,0.921514,-110.535164,294.500488,0.000000
72.260002,64.755562,-110.535164,-0.001069,0.003675,0.093357,288.047119,14.673820,0.933568,-110.535164,294.500488,0.000000
72.630005,65.498817,-110.535164,-0.001074,0.003686,0.093626,291.353302,14.842244,0.936257,-110.535164,294.500488,0.000000
73.000000,64.730614,-110.579643,-0.001061,0.003687,0.093643,287.936157,14.668166,0.936430,-110.579643,294.500488,0.000000
73.370003,65.547600,-110.579643,-0.001039,0.003704,0.094077,291.570282,14.853299,0.940767,-110.579643,294.500488,0.000000
73.740005,64.940636,-110.624123,-0.001043,0.003706,0.094120,288.870361,14.715758,0.941200,-110.624123,294.500488,0.000000
74.110001,65.529732,-110.713089,-0.001035,0.003720,0.094476,291.490814,14.849250,0.944756,-110.713089,294.500488,0.000000
74.480003,65.105965,-110.668610,-0.001026,0.003720,0.094476,289.605804,14.753222,0.944756,-110.668610,294.500488,0.000000
74.850006,64.685188,-110.668610,-0.001043,0.003720,0.094484,287.734100,14.657873,0.944843,-110.668610,294.500488,0.000000
75.220001,66.313942,-110.757568,-0.001022,0.003734,0.094831,294.979156,15.026955,0.948311,-110.757568,294.500488,0.000000
75.590004,65.845879,-110.757568,-0.001022,0.003733,0.094822,292.897095,14.920889,0.948225,-110.757568,294.500488,0.000000
75.960007,65.375938,-110.891014,-0.001013,0.003733,0.094822,290.806702,14.814400,0.948225,-110.891014,294.500488,0.000000
76.330002,65.016228,-110.757568,-0.001000,0.003734,0.094831,289.206635,14.732888,0.948311,-110.757568,294.500488,0.000000
76.700005,64.674385,-110.891014,-0.001005,0.003734,0.094831,287.686035,14.655425,0.948311,-110.891014,294.500488,0.000000
77.070007,65.996315,-110.891014,-0.001022,0.003746,0.095161,293.566284,14.954979,0.951607,-110.891014,294.500488,0.000000
77.440002,65.665276,-110.935493,-0.001005,0.003746,0.095161,292.093719,14.879964,0.951607,-110.935493,294.500488,0.000000
77.810005,65.359550,-110.935493,-0.000992,0.003746,0.095161,290.733795,14.810686,0.951607,-110.935493,294.500488,0.000000
78.180000,65.071342,-110.979973,-0.000996,0.003747,0.095169,289.451782,14.745378,0.951694,-110.979973,294.500488,0.000000
78.550003,65.065758,-111.024452,-0.001000,0.003767,0.095672,289.426941,14.744112,0.956724,-111.024452,294.500488,0.000000
78.920006,65.764320,-111.024452,-0.001000,0.003756,0.095412,292.534302,14.902408,0.954122,-111.024452,294.500488,0.000000
79.290001,65.451530,-111.113419,-0.000987,0.003756,0.095412,291.142944,14.831529,0.954122,-111.113419,294.500488,0.000000
79.660004,65.206886,-111.068932,-0.000983,0.003757,0.095438,290.054718,14.776092,0.954382,-111.068932,294.500488,0.000000
80.030006,65.068733,-111.157898,-0.000992,0.003765,0.095620,289.440186,14.744785,0.956203,-111.157898,294.500488,0.000000
80.400002,64.989052,-111.113419,-0.000983,0.003767,0.095672,289.085754,14.726729,0.956724,-111.113419,294.500488,0.000000
80.770004,65.080650,-111.157898,-0.000979,0.003768,0.095716,289.493195,14.747486,0.957157,-111.157898,294.500488,0.000000
81.140007,64.995369,-111.246857,-0.000979,0.003770,0.095750,289.113831,14.728161,0.957504,-111.246857,294.500488,0.000000
81.510002,64.914192,-111.291336,-0.000983,0.003770,0.095759,288.752747,14.709766,0.957591,-111.291336,294.500488,0.000000
81.880005,65.482811,-111.291336,-0.000983,0.003779,0.095976,291.282104,14.838617,0.959759,-111.291336,294.500488,0.000000
82.250008,65.385628,-111.291336,-0.000992,0.003778,0.095959,290.849792,14.816595,0.959585,-111.291336,294.500488,0.000000
82.620003,65.261253,-111.335823,-0.000974,0.003778,0.095959,290.296539,14.788412,0.959585,-111.335823,294.500488,0.000000
82.990005,65.130547,-111.380302,-0.000961,0.003778,0.095967,289.715149,14.758793,0.959672,-111.380302,294.500488,0.000000
83.360001,65.004311,-111.424782,-0.000970,0.003779,0.095976,289.153625,14.730187,0.959759,-111.424782,294.500488,0.000000
83.730003,64.898552,-111.380302,-0.000966,0.003779,0.095985,288.683167,14.706223,0.959846,-111.380302,294.500488,0.000000
84.100006,65.574791,-111.513741,-0.000961,0.003788,0.096210,291.691223,14.859460,0.962100,-111.513741,294.500488,0.000000
84.470001,65.523033,-111.380302,-0.000979,0.003787,0.096201,291.460999,14.847732,0.962014,-111.380302,294.500488,0.000000
84.840004,65.407585,-111.513741,-0.000961,0.003787,0.096201,290.947479,14.821570,0.962014,-111.513741,294.500488,0.000000
85.210007,65.290672,-111.558228,-0.000957,0.003787,0.096201,290.427429,14.795078,0.962014,-111.558228,294.500488,0.000000
85.580002,65.179695,-111.558228,-0.000949,0.003787,0.096201,289.933777,14.769930,0.962014,-111.558228,294.500488,0.000000
85.950005,65.071342,-111.602707,-0.000961,0.003788,0.096210,289.451782,14.745378,0.962100,-111.602707,294.500488,0.000000
86.320007,64.994255,-111.602707,-0.000953,0.003788,0.096219,289.108887,14.727909,0.962187,-111.602707,294.500488,0.000000
86.690002,65.153267,-111.691666,-0.000970,0.003793,0.096331,289.816193,14.763942,0.963314,-111.691666,294.500488,0.000000
87.060005,65.161461,-111.691666,-0.000961,0.003793,0.096331,289.852661,14.765799,0.963314,-111.691666,294.500488,0.000000
87.430008,65.072090,-111.691666,-0.000953,0.003793,0.096331,289.455109,14.745546,0.963314,-111.691666,294.500488,0.000000
87.800003,65.005058,-111.736153,-0.000957,0.003793,0.096331,289.156952,14.730357,0.963314,-111.736153,294.500488,0.000000
88.170006,64.943993,-111.780632,-0.000957,0.003793,0.096331,288.885315,14.716518,0.963314,-111.780632,294.500488,0.000000
88.540001,64.842705,-111.869591,-0.000966,0.003793,0.096331,288.434753,14.693566,0.963314,-111.869591,294.500488,0.000000
88.910004,64.759285,-111.825111,-0.000961,0.003793,0.096331,288.063690,14.674664,0.963314,-111.825111,294.500488,0.000000
89.280006,64.674019,-111.914070,-0.000949,0.003793,0.096331,287.684418,14.655342,0.963314,-111.914070,294.500488,0.000000
89.650002,64.604759,-111.869591,-0.000970,0.003793,0.096331,287.376312,14.639647,0.963314,-111.869591,294.500488,0.000000
90.020004,65.651863,-111.958557,-0.000944,0.003805,0.096644,292.034058,14.876925,0.966437,-111.958557,294.500488,0.000000
90.390007,65.626549,-112.047516,-0.000957,0.003805,0.096644,291.921478,14.871188,0.966437,-112.047516,294.500488,0.000000
90.760002,65.582603,-112.047516,-0.000940,0.003805,0.096644,291.725983,14.861231,0.966437,-112.047516,294.500488,0.000000
91.130005,65.528236,-111.958557,-0.000936,0.003805,0.096644,291.484161,14.848910,0.966437,-111.958557,294.500488,0.000000
91.500008,65.479088,-112.003036,-0.000953,0.003805,0.096644,291.265533,14.837773,0.966437,-112.003036,294.500488,0.000000
91.870003,65.368858,-112.091995,-0.000944,0.003805,0.096644,290.775208,14.812795,0.966437,-112.091995,294.500488,0.000000
92.240005,65.312645,-112.136475,-0.000949,0.003805,0.096644,290.525146,14.800056,0.966437,-112.136475,294.500488,0.000000
92.610001,65.253059,-112.091995,-0.000944,0.003805,0.096644,290.260101,14.786554,0.966437,-112.091995,294.500488,0.000000
92.980003,65.199440,-112.091995,-0.000953,0.003805,0.096644,290.021606,14.774405,0.966437,-112.091995,294.500488,0.000000
93.350006,65.105598,-112.180962,-0.000944,0.003805,0.096644,289.604156,14.753139,0.966437,-112.180962,294.500488,0.000000
93.720001,65.052727,-112.225441,-0.000949,0.003805,0.096644,289.368988,14.741158,0.966437,-112.225441,294.500488,0.000000
94.090004,64.996864,-112.314400,-0.000940,0.003805,0.096644,289.120483,14.728499,0.966437,-112.314400,294.500488,0.000000
94.460007,64.928352,-112.314400,-0.000936,0.003805,0.096644,288.815735,14.712975,0.966437,-112.314400,294.500488,0.000000
94.830002,64.844933,-112.314400,-0.000949,0.003805,0.096644,288.444672,14.694072,0.966437,-112.314400,294.500488,0.000000
95.200005,64.789085,-112.358879,-0.000940,0.003805,0.096644,288.196259,14.681417,0.966437,-112.358879,294.500488,0.000000
95.570007,64.741051,-112.358879,-0.000949,0.003805,0.096644,287.982574,14.670532,0.966437,-112.358879,294.500488,0.000000
95.940002,64.704185,-112.447845,-0.000953,0.003805,0.096652,287.818604,14.662178,0.966523,-112.447845,294.500488,0.000000
96.310005,65.842155,-112.403366,-0.000940,0.003816,0.096921,292.880524,14.920046,0.969212,-112.403366,294.500488,0.000000
96.680008,65.749809,-112.403366,-0.000940,0.003816,0.096921,292.469757,14.899120,0.969212,-112.403366,294.500488,0.000000
97.050003,65.653358,-112.447845,-0.000931,0.003816,0.096921,292.040710,14.877264,0.969212,-112.447845,294.500488,0.000000
97.420006,65.586708,-112.536804,-0.000931,0.003816,0.096921,291.744263,14.862160,0.969212,-112.536804,294.500488,0.000000
97.790001,65.563240,-112.625771,-0.000944,0.003816,0.096921,291.639862,14.856842,0.969212,-112.625771,294.500488,0.000000
98.160004,65.516701,-112.536804,-0.000918,0.003816,0.096921,291.432831,14.846296,0.969212,-112.536804,294.500488,0.000000
98.530006,65.454506,-112.581284,-0.000931,0.003816,0.096921,291.156189,14.832203,0.969212,-112.581284,294.500488,0.000000
98.900002,65.386742,-112.536804,-0.000936,0.003816,0.096921,290.854767,14.816847,0.969212,-112.536804,294.500488,0.000000
99.270004,65.339821,-112.670250,-0.000940,0.003816,0.096921,290.646027,14.806215,0.969212,-112.670250,294.500488,0.000000
99.640007,65.286201,-112.670250,-0.000936,0.003816,0.096921,290.407532,14.794065,0.969212,-112.670250,294.500488,0.000000
100.010002,65.249336,-112.714729,-0.000940,0.003816,0.096921,290.243530,14.785711,0.969212,-112.714729,294.500488,0.000000
100.380005,65.205391,-112.714729,-0.000927,0.003816,0.096921,290.048065,14.775753,0.969212,-112.714729,294.500488,0.000000
100.750008,65.145821,-112.759209,-0.000927,0.003816,0.096921,289.783081,14.762254,0.969212,-112.759209,294.500488,0.000000
101.120003,65.078041,-112.803696,-0.000944,0.003816,0.096921,289.481598,14.746895,0.969212,-112.803696,294.500488,0.000000
101.490005,65.038567,-112.848175,-0.000944,0.003816,0.096921,289.306000,14.737949,0.969212,-112.848175,294.500488,0.000000
101.860008,64.994637,-112.848175,-0.000936,0.003816,0.096921,289.110596,14.727995,0.969212,-112.848175,294.500488,0.000000
102.230003,64.963722,-112.892654,-0.000914,0.003816,0.096921,288.973083,14.720990,0.969212,-112.892654,294.500488,0.000000
102.600006,64.901161,-112.892654,-0.000931,0.003816,0.096921,288.694794,14.706813,0.969212,-112.892654,294.500488,0.000000
102.970001,64.847176,-112.981613,-0.000927,0.003816,0.096921,288.454651,14.694580,0.969212,-112.981613,294.500488,0.000000
103.340004,64.776054,-112.981613,-0.000940,0.003816,0.096921,288.138275,14.678464,0.969212,-112.981613,294.500488,0.000000
103.710007,64.748116,-113.026100,-0.000944,0.003816,0.096921,288.014008,14.672132,0.969212,-113.026100,294.500488,0.000000
104.080002,64.708275,-113.026100,-0.000927,0.003816,0.096921,287.836792,14.663104,0.969212,-113.026100,294.500488,0.000000
104.450005,64.674019,-113.026100,-0.000931,0.003816,0.096921,287.684418,14.655342,0.969212,-113.026100,294.500488,0.000000
104.820007,64.647575,-113.115059,-0.000944,0.003816,0.096930,287.566772,14.649349,0.969298,-113.115059,294.500488,0.000000
105.190002,64.590614,-113.204018,-0.000940,0.003816,0.096930,287.313416,14.636442,0.969298,-113.204018,294.500488,0.000000
105.560005,66.012321,-113.159538,-0.000927,0.003826,0.097173,293.637482,14.958606,0.971727,-113.159538,294.500488,0.000000
105.930008,65.926308,-113.204018,-0.000923,0.003824,0.097129,293.254852,14.939116,0.971293,-113.204018,294.500488,0.000000
106.300003,65.867104,-113.204018,-0.000918,0.003824,0.097129,292.991516,14.925699,0.971293,-113.204018,294.500488,0.000000
106.670006,65.839546,-113.248505,-0.000931,0.003824,0.097129,292.868927,14.919454,0.971293,-113.248505,294.500488,0.000000
107.040009,65.768425,-113.292984,-0.000914,0.003824,0.097129,292.552551,14.903338,0.971293,-113.292984,294.500488,0.000000
107.410004,65.749428,-113.292984,-0.000931,0.003824,0.097129,292.468048,14.899034,0.971293,-113.292984,294.500488,0.000000
107.780006,65.652992,-113.337463,-0.000927,0.003824,0.097129,292.039093,14.877180,0.971293,-113.337463,294.500488,0.000000
108.150002,65.614265,-113.292984,-0.000918,0.003824,0.097129,291.866821,14.868405,0.971293,-113.292984,294.500488,0.000000
108.520004,65.584465,-113.426422,-0.000918,0.003824,0.097129,291.734283,14.861651,0.971293,-113.426422,294.500488,0.000000
108.890007,65.555794,-113.426422,-0.000923,0.003824,0.097129,291.606720,14.855155,0.971293,-113.426422,294.500488,0.000000
109.260002,65.517815,-113.426422,-0.000918,0.003824,0.097129,291.437805,14.846549,0.971293,-113.426422,294.500488,0.000000
109.630005,65.480949,-113.426422,-0.000905,0.003824,0.097129,291.273804,14.838195,0.971293,-113.426422,294.500488,0.000000
110.000008,65.418388,-113.470909,-0.000927,0.003824,0.097129,290.995514,14.824019,0.971293,-113.470909,294.500488,0.000000
110.370003,65.364403,-113.470909,-0.000923,0.003824,0.097129,290.755371,14.811786,0.971293,-113.470909,294.500488,0.000000
110.740005,65.339821,-113.604347,-0.000918,0.003824,0.097129,290.646027,14.806215,0.971293,-113.604347,294.500488,0.000000
111.110008,65.301842,-113.515388,-0.000901,0.003824,0.097129,290.477112,14.797609,0.971293,-113.515388,294.500488,0.000000
111.480003,65.266457,-113.515388,-0.000914,0.003824,0.097129,290.319702,14.789590,0.971293,-113.515388,294.500488,0.000000
111.850006,65.241890,-113.604347,-0.000923,0.003824,0.097129,290.210419,14.784024,0.971293,-113.604347,294.500488,0.000000
112.220009,65.208366,-113.693314,-0.000918,0.003824,0.097138,290.061310,14.776427,0.971380,-113.693314,294.500488,0.000000
112.590004,65.156990,-113.648827,-0.000923,0.003826,0.097190,289.832764,14.764785,0.971900,-113.648827,294.500488,0.000000
112.960007,65.111931,-113.693314,-0.000918,0.003826,0.097190,289.632324,14.754575,0.971900,-113.693314,294.500488,0.000000
113.330002,65.079155,-113.693314,-0.000927,0.003826,0.097190,289.486542,14.747148,0.971900,-113.693314,294.500488,0.000000
113.700005,65.094795,-113.782272,-0.000914,0.003829,0.097251,289.556122,14.750691,0.972507,-113.782272,294.500488,0.000000
114.070007,65.078041,-113.782272,-0.000914,0.003829,0.097251,289.481598,14.746895,0.972507,-113.782272,294.500488,0.000000
114.440002,65.058678,-113.782272,-0.000918,0.003829,0.097251,289.395447,14.742507,0.972507,-113.782272,294.500488,0.000000
114.810005,65.038948,-113.826752,-0.000918,0.003829,0.097251,289.307678,14.738036,0.972507,-113.826752,294.500488,0.000000
115.180008,65.037086,-113.915718,-0.000910,0.003831,0.097311,289.299408,14.737615,0.973114,-113.915718,294.500488,0.000000
115.550003,65.086601,-113.915718,-0.000923,0.003831,0.097311,289.519653,14.748835,0.973114,-113.915718,294.500488,0.000000
115.920006,65.087349,-113.915718,-0.000918,0.003831,0.097311,289.522980,14.749004,0.973114,-113.915718,294.500488,0.000000
116.290009,65.067986,-113.960197,-0.000910,0.003831,0.097311,289.436859,14.744617,0.973114,-113.960197,294.500488,0.000000
116.660004,65.057564,-113.960197,-0.000923,0.003831,0.097311,289.390503,14.742254,0.973114,-113.960197,294.500488,0.000000
117.030006,65.024422,-114.004677,-0.000910,0.003831,0.097311,289.243073,14.734745,0.973114,-114.004677,294.500488,0.000000
117.400009,65.009148,-114.049156,-0.000918,0.003831,0.097311,289.175140,14.731283,0.973114,-114.049156,294.500488,0.000000
117.770004,64.982338,-114.049156,-0.000905,0.003831,0.097311,289.055878,14.725208,0.973114,-114.049156,294.500488,0.000000
118.140007,64.978615,-114.093643,-0.000923,0.003831,0.097311,289.039307,14.724364,0.973114,-114.093643,294.500488,0.000000
118.510002,64.955528,-114.093643,-0.000914,0.003831,0.097311,288.936615,14.719133,0.973114,-114.093643,294.500488,0.000000
118.880005,64.937660,-114.093643,-0.000914,0.003831,0.097311,288.857147,14.715084,0.973114,-114.093643,294.500488,0.000000
119.250008,64.906013,-114.138123,-0.000927,0.003831,0.097311,288.716370,14.707913,0.973114,-114.138123,294.500488,0.000000
119.620003,64.881432,-114.227081,-0.000914,0.003831,0.097311,288.607025,14.702343,0.973114,-114.227081,294.500488,0.000000
119.990005,64.851646,-114.227081,-0.000910,0.003831,0.097311,288.474518,14.695593,0.973114,-114.227081,294.500488,0.000000
120.360008,64.822975,-114.227081,-0.000914,0.003831,0.097311,288.346985,14.689096,0.973114,-114.227081,294.500488,0.000000
120.730003,64.802864,-114.271561,-0.000927,0.003831,0.097311,288.257538,14.684539,0.973114,-114.271561,294.500488,0.000000
121.100006,64.788338,-114.316048,-0.000918,0.003831,0.097311,288.192932,14.681248,0.973114,-114.316048,294.500488,0.000000
121.470009,65.829124,-114.405006,-0.000918,0.003845,0.097658,292.822571,14.917092,0.976583,-114.405006,294.500488,0.000000
121.840004,65.882362,-114.405006,-0.000901,0.003845,0.097658,293.059387,14.929157,0.976583,-114.405006,294.500488,0.000000
122.210007,65.848106,-114.405006,-0.000901,0.003844,0.097650,292.907013,14.921394,0.976496,-114.405006,294.500488,0.000000
122.580009,65.892052,-114.405006,-0.000905,0.003844,0.097650,293.102478,14.931353,0.976496,-114.405006,294.500488,0.000000
122.950005,65.853325,-114.449486,-0.000914,0.003844,0.097650,292.930206,14.922577,0.976496,-114.449486,294.500488,0.000000
123.320007,65.841026,-114.493965,-0.000910,0.003844,0.097650,292.875519,14.919790,0.976496,-114.493965,294.500488,0.000000
123.690002,65.844383,-114.538452,-0.000910,0.003844,0.097650,292.890442,14.920550,0.976496,-114.538452,294.500488,0.000000
124.060005,65.857414,-114.538452,-0.000905,0.003844,0.097650,292.948395,14.923503,0.976496,-114.538452,294.500488,0.000000
124.430008,65.846626,-114.582932,-0.000901,0.003844,0.097650,292.900421,14.921059,0.976496,-114.582932,294.500488,0.000000
124.800003,65.827995,-114.582932,-0.000923,0.003844,0.097650,292.817535,14.916837,0.976496,-114.582932,294.500488,0.000000
125.170006,65.784431,-114.716370,-0.000914,0.003844,0.097650,292.623779,14.906965,0.976496,-114.716370,294.500488,0.000000
125.540009,65.776237,-114.671890,-0.000910,0.003844,0.097650,292.587311,14.905108,0.976496,-114.671890,294.500488,0.000000
125.910004,65.768425,-114.627411,-0.000910,0.003844,0.097650,292.552551,14.903338,0.976496,-114.627411,294.500488,0.000000
126.280006,65.759850,-114.671890,-0.000918,0.003844,0.097650,292.514435,14.901395,0.976496,-114.671890,294.500488,0.000000
126.650009,65.681664,-114.671890,-0.000910,0.003844,0.097650,292.166626,14.883677,0.976496,-114.671890,294.500488,0.000000
127.020004,65.667885,-114.805336,-0.000905,0.003844,0.097650,292.105347,14.880556,0.976496,-114.805336,294.500488,0.000000
127.390007,65.658577,-114.760857,-0.000910,0.003844,0.097650,292.063934,14.878446,0.976496,-114.760857,294.500488,0.000000
127.760010,65.626915,-114.805336,-0.000897,0.003844,0.097650,291.923096,14.871271,0.976496,-114.805336,294.500488,0.000000
128.130005,65.596764,-114.849815,-0.000914,0.003844,0.097650,291.788971,14.864439,0.976496,-114.849815,294.500488,0.000000
128.500000,65.597496,-114.849815,-0.000901,0.003844,0.097650,291.792236,14.864605,0.976496,-114.849815,294.500488,0.000000
128.870010,65.564735,-114.938774,-0.000905,0.003844,0.097650,291.646515,14.857182,0.976496,-114.938774,294.500488,0.000000
129.240005,65.558769,-114.938774,-0.000918,0.003844,0.097650,291.619965,14.855830,0.976496,-114.938774,294.500488,0.000000
129.610001,65.542397,-114.983261,-0.000901,0.003844,0.097650,291.547150,14.852119,0.976496,-114.983261,294.500488,0.000000
129.980011,65.522652,-114.938774,-0.000901,0.003844,0.097650,291.459320,14.847645,0.976496,-114.938774,294.500488,0.000000
130.350006,65.491753,-114.983261,-0.000914,0.003844,0.097650,291.321869,14.840643,0.976496,-114.983261,294.500488,0.000000
130.720001,65.484306,-115.116699,-0.000905,0.003844,0.097650,291.288757,14.838956,0.976496,-115.116699,294.500488,0.000000
131.090012,65.471275,-115.072220,-0.000892,0.003845,0.097658,291.230774,14.836003,0.976583,-115.072220,294.500488,0.000000
131.460007,65.425835,-115.116699,-0.000892,0.003843,0.097624,291.028656,14.825706,0.976236,-115.116699,0.097554,0.000000
131.830002,65.318596,-115.116699,-0.000901,0.003828,0.097233,290.551636,14.801406,0.972334,-115.116699,0.096938,0.000000
132.200012,65.295509,-115.072220,-0.000910,0.003809,0.096748,290.448944,14.796174,0.967477,-115.072220,0.096323,0.000000
132.570007,65.218056,-115.205666,-0.000905,0.003789,0.096245,290.104401,14.778623,0.962447,-115.205666,0.095707,0.000000
132.940002,65.196083,-115.205666,-0.000888,0.003768,0.095698,290.006653,14.773643,0.956984,-115.205666,0.095091,0.000000
133.310013,65.156990,-115.205666,-0.000884,0.003741,0.095013,289.832764,14.764785,0.950133,-115.205666,0.094467,0.000000
133.680008,65.100761,-115.205666,-0.000914,0.003716,0.094398,289.582642,14.752044,0.943975,-115.205666,0.093851,0.000000
134.050003,65.062782,-115.250145,-0.000897,0.003693,0.093799,289.413696,14.743437,0.937991,-115.250145,0.093235,0.000000
134.420013,65.045280,-115.339104,-0.000901,0.003670,0.093218,289.335846,14.739471,0.932181,-115.339104,0.092620,0.000000
134.790009,65.005806,-115.383591,-0.000892,0.003646,0.092620,289.160278,14.730526,0.926197,-115.383591,0.092004,0.000000
135.160004,64.948830,-115.339104,-0.000892,0.003630,0.092212,288.906830,14.717615,0.922121,-115.339104,0.091388,0.000000
135.530014,64.494164,-115.428070,-0.000901,0.003599,0.091414,286.884369,14.614587,0.914143,-115.428070,0.090773,0.000000
135.900009,63.802299,-115.428070,-0.000897,0.003579,0.090894,283.806793,14.457808,0.908939,-115.428070,0.090157,0.000000
136.270004,62.807312,-115.472549,-0.000892,0.003553,0.090252,279.380890,14.232340,0.902522,-115.472549,0.089541,0.000000
136.639999,61.927399,-115.472549,-0.000892,0.003536,0.089810,275.466827,14.032948,0.898099,-115.472549,0.088917,0.000000
137.010010,60.766342,-115.561508,-0.000884,0.003516,0.089316,270.302185,13.769850,0.893156,-115.561508,0.088301,0.000000
137.380005,59.176682,-115.517029,-0.000892,0.003496,0.088787,263.231018,13.409628,0.887866,-115.517029,0.087685,0.000000
137.750000,56.921967,-115.517029,-0.000884,0.003465,0.088006,253.201553,12.898702,0.880061,-115.517029,0.087069,0.000000
138.120010,55.000900,-115.650475,-0.000888,0.003443,0.087451,244.656219,12.463382,0.874510,-115.650475,0.086454,0.000000
138.490005,53.417572,-115.605995,-0.000892,0.003427,0.087052,237.613220,12.104595,0.870521,-115.605995,0.085838,0.000000
138.860001,50.893631,-115.605995,-0.000892,0.003401,0.086376,226.386185,11.532661,0.863757,-115.605995,0.085222,0.000000
139.230011,48.906654,-115.694954,-0.000888,0.003382,0.085907,217.547668,11.082407,0.859074,-115.694954,0.084607,0.000000
139.600006,44.722305,-115.694954,-0.000892,0.003341,0.084867,198.934753,10.134219,0.848667,-115.694954,0.083991,0.000000
139.970001,42.677231,-115.783913,-0.000897,0.003321,0.084364,189.837799,9.670799,0.843637,-115.783913,0.083366,0.000000
140.340012,39.979767,-115.783913,-0.000901,0.003296,0.083731,177.838882,9.059545,0.837306,-115.783913,0.082751,0.000000
140.710007,38.391602,-115.783913,-0.000897,0.003285,0.083427,170.774368,8.699661,0.834271,-115.783913,0.082135,0.000000
141.080002,35.026840,-115.828400,-0.000901,0.003247,0.082473,155.807159,7.937195,0.824732,-115.828400,0.081519,0.000000
141.450012,31.906731,-115.828400,-0.000901,0.003221,0.081814,141.928223,7.230168,0.818141,-115.828400,0.080904,0.000000
141.820007,30.034439,-115.917358,-0.000905,0.003204,0.081380,133.599854,6.805901,0.813805,-115.917358,0.080288,0.000000
142.190002,28.216148,-116.006317,-0.000901,0.003189,0.080999,125.511696,6.393870,0.809989,-116.006317,0.079672,0.000000
142.560013,24.874847,-115.961838,-0.000897,0.003156,0.080175,110.648849,5.636721,0.801750,-115.961838,0.079056,0.000000
142.930008,22.546776,-116.050804,-0.000914,0.003137,0.079681,100.293068,5.109173,0.796807,-116.050804,0.078441,0.000000
143.300003,18.675591,-115.961838,-0.000918,0.003099,0.078709,83.073174,4.231949,0.787094,-115.961838,0.077816,0.000000
143.670013,16.297623,-116.095284,-0.000918,0.003078,0.078172,72.495445,3.693094,0.781717,-116.095284,0.077200,0.000000
144.040009,13.698090,-116.139763,-0.000918,0.003050,0.077478,60.932144,3.104031,0.774780,-116.139763,0.076585,0.000000
144.410004,11.632172,-116.050804,-0.000927,0.003032,0.077018,51.742485,2.635888,0.770183,-116.050804,0.075969,0.000000
144.780014,9.019974,-116.139763,-0.000931,0.003007,0.076385,40.122849,2.043955,0.763853,-116.139763,0.075353,0.000000
145.150009,6.642746,-116.050804,-0.000936,0.002984,0.075787,29.548410,1.505268,0.757869,-116.050804,0.074738,0.000000
145.520004,4.069283,-116.184242,-0.000961,0.002959,0.075162,18.101072,0.922113,0.751625,-116.184242,0.074122,0.000000
145.889999,2.093102,-116.228722,-0.000940,0.002939,0.074642,9.310580,0.474304,0.746421,-116.228722,0.073506,0.000000
146.260010,-0.822945,-116.273209,-0.000949,0.002909,0.073896,-3.660640,-0.186482,0.738963,-116.273209,0.072890,0.000000
146.630005,-1.907295,-116.228722,-0.000970,0.002888,0.073367,-8.484073,-0.432199,0.733673,-116.228722,0.072266,0.000000
147.000000,-0.370514,-116.228722,-0.001013,0.002862,0.072691,-1.648128,-0.083960,0.726909,-116.228722,0.071650,0.000000
147.370010,-0.132568,-116.317688,-0.001061,0.002838,0.072084,-0.589693,-0.030040,0.720838,-116.317688,0.071034,0.000000
147.740005,-0.042084,-116.362167,-0.001095,0.002815,0.071511,-0.187198,-0.009536,0.715115,-116.362167,0.070419,0.000000
148.110001,-0.052505,-116.362167,-0.001121,0.002789,0.070844,-0.233556,-0.011898,0.708437,-116.362167,0.069803,0.000000
148.480011,-0.023834,-116.406647,-0.001147,0.002766,0.070254,-0.106020,-0.005401,0.702540,-116.406647,0.069187,0.000000
148.850006,-0.001862,-116.406647,-0.001212,0.002737,0.069517,-0.008281,-0.000422,0.695168,-116.406647,0.068572,0.000000
149.220001,-0.049530,-116.451126,-0.001233,0.002720,0.069092,-0.220321,-0.011224,0.690919,-116.451126,0.067956,0.000000
149.590012,-0.042084,-116.540092,-0.001259,0.002696,0.068485,-0.187198,-0.009536,0.684848,-116.540092,0.067340,0.000000
149.960007,-0.020111,-116.540092,-0.001332,0.002668,0.067765,-0.089459,-0.004557,0.677650,-116.540092,0.067670,0.000000
150.100006,-0.013779,-116.540092,-0.001315,0.002668,0.067774,-0.061291,-0.003122,0.677737,-116.540092,0.067670,0.000000