File: Data/compression 33/AutoNoHeating-15-33-reverse-1-4_11152024_182106.csv
Time (sec),S:Load (lbs),S:HL1 (DIM),S:LVDT (in),S:Position (in),Ch:Position (mm),Ch:Load (N),Ch:Stress (MPa),Ch:Strain (mm/mm),Ch:HL1 (DIM),Set Point (),Cycles ()
0.210000,-0.035751,-81.667023,-0.014017,-0.009024,-0.229216,-0.159030,-0.008101,-2.292164,-81.667023,-0.228956,0.000000
0.580000,-0.070755,-81.711510,-0.014012,-0.008937,-0.227005,-0.314734,-0.016033,-2.270050,-81.711510,-0.226181,0.000000
0.950000,-0.087135,-81.667023,-0.013887,-0.008717,-0.221411,-0.387597,-0.019745,-2.214114,-81.667023,-0.220024,0.000000
1.320000,-0.102402,-81.711510,-0.013629,-0.008464,-0.214985,-0.455506,-0.023205,-2.149853,-81.711510,-0.213849,0.000000
1.690000,-0.108360,-81.800468,-0.013392,-0.008227,-0.208967,-0.482011,-0.024555,-2.089667,-81.800468,-0.207692,0.000000
2.060000,-0.056229,-81.800468,-0.013116,-0.007981,-0.202723,-0.250117,-0.012742,-2.027227,-81.800468,-0.201517,0.000000
2.430000,-0.033516,-81.889427,-0.012883,-0.007741,-0.196626,-0.149086,-0.007595,-1.966261,-81.889427,-0.195360,0.000000
2.800000,-0.068520,-81.889427,-0.012633,-0.007500,-0.190495,-0.304790,-0.015527,-1.904948,-81.889427,-0.189203,0.000000
3.170000,-0.076714,-81.933914,-0.012361,-0.007260,-0.184416,-0.341239,-0.017384,-1.844155,-81.933914,-0.183028,0.000000
3.540000,-0.124374,-82.022873,-0.012128,-0.007010,-0.178059,-0.553245,-0.028184,-1.780588,-82.022873,-0.176871,0.000000
3.910000,-0.132195,-81.978394,-0.011861,-0.006773,-0.172040,-0.588031,-0.029956,-1.720402,-81.978394,-0.170713,0.000000
4.280000,-0.078949,-82.022873,-0.011602,-0.006526,-0.165753,-0.351183,-0.017890,-1.657528,-82.022873,-0.164539,0.000000
4.650000,-0.072243,-82.022873,-0.011365,-0.006283,-0.159578,-0.321352,-0.016370,-1.595782,-82.022873,-0.158381,0.000000
5.020000,-0.056976,-82.067352,-0.011137,-0.006045,-0.153551,-0.253443,-0.012911,-1.535510,-82.067352,-0.152207,0.000000
5.390000,-0.092720,-82.156319,-0.010878,-0.005802,-0.147376,-0.412439,-0.021011,-1.473763,-82.156319,-0.146049,0.000000
5.760000,-0.102402,-82.156319,-0.010624,-0.005560,-0.141219,-0.455506,-0.023205,-1.412190,-82.156319,-0.139892,0.000000
6.130000,-0.043945,-82.200798,-0.010374,-0.005313,-0.134958,-0.195479,-0.009958,-1.349577,-82.200798,-0.133718,0.000000
6.500000,-0.027557,-82.200798,-0.010123,-0.005072,-0.128826,-0.122581,-0.006245,-1.288264,-82.200798,-0.127560,0.000000
6.870000,-0.053253,-82.200798,-0.009869,-0.004833,-0.122756,-0.236882,-0.012067,-1.227558,-82.200798,-0.121386,0.000000
7.240000,-0.095329,-82.289757,-0.009641,-0.004596,-0.116729,-0.424046,-0.021602,-1.167286,-82.289757,-0.115228,0.000000
7.610000,-0.106133,-82.334244,-0.009382,-0.004351,-0.110519,-0.472101,-0.024050,-1.105192,-82.334244,-0.109071,0.000000
7.980000,-0.162361,-82.378723,-0.009145,-0.004108,-0.104353,-0.722218,-0.036792,-1.043533,-82.378723,-0.102896,0.000000
8.350000,-0.065170,-82.423203,-0.008873,-0.003863,-0.098127,-0.289892,-0.014768,-0.981266,-82.423203,-0.096739,0.000000
8.720000,-0.080063,-82.467682,-0.008623,-0.003617,-0.091883,-0.356137,-0.018143,-0.918826,-82.467682,-0.090564,0.000000
9.090000,-0.024582,-82.512161,-0.008390,-0.003377,-0.085777,-0.109346,-0.005570,-0.857773,-82.512161,-0.084407,0.000000
9.460000,-0.067772,-82.601128,-0.008136,-0.003134,-0.079611,-0.301465,-0.015357,-0.796113,-82.601128,-0.078250,0.000000
9.830001,-0.093468,-82.556648,-0.007864,-0.002887,-0.073341,-0.415765,-0.021180,-0.733413,-82.556648,-0.072075,0.000000
10.200001,-0.077827,-82.601128,-0.007618,-0.002646,-0.067210,-0.346194,-0.017636,-0.672100,-82.601128,-0.065918,0.000000
10.570001,-0.026443,-82.601128,-0.007381,-0.002402,-0.061001,-0.117626,-0.005992,-0.610006,-82.601128,-0.059743,0.000000
10.940001,-0.019363,-82.734566,-0.007127,-0.002159,-0.054826,-0.086133,-0.004388,-0.548260,-82.734566,-0.053586,0.000000
11.310000,-0.038361,-82.734566,-0.006885,-0.001919,-0.048747,-0.170636,-0.008693,-0.487467,-82.734566,-0.047429,0.000000
11.680000,-0.061073,-82.690086,-0.006618,-0.001679,-0.042650,-0.271668,-0.013839,-0.426501,-82.690086,-0.041254,0.000000
12.050000,-0.108360,-82.734566,-0.006377,-0.001430,-0.036328,-0.482011,-0.024555,-0.363281,-82.734566,-0.035097,0.000000
12.420001,-0.114693,-82.779053,-0.006127,-0.001189,-0.030205,-0.510179,-0.025990,-0.302055,-82.779053,-0.028922,0.000000
12.790001,-0.061813,-82.912491,-0.005877,-0.000943,-0.023961,-0.274960,-0.014007,-0.239614,-82.912491,-0.022765,0.000000
13.160001,-0.004471,-82.912491,-0.005622,-0.000705,-0.017908,-0.019887,-0.001013,-0.179082,-82.912491,-0.016607,0.000000
13.530001,-0.022720,-82.956970,-0.005385,-0.000465,-0.011812,-0.101065,-0.005149,-0.118116,-82.956970,-0.010433,0.000000
13.900001,-0.051765,-83.001457,-0.005118,-0.000221,-0.005620,-0.230264,-0.011730,-0.056196,-83.001457,-0.004275,0.000000
14.270000,-0.046547,-82.956970,-0.004868,0.000022,0.000564,-0.207051,-0.010548,0.005637,-82.956970,0.001899,0.000000
14.640000,0.101654,-83.001457,-0.004751,-0.000000,-0.000000,0.452180,0.023035,-0.000000,-83.001457,0.000225,0.000000
15.010001,0.132935,-83.090416,-0.004734,-0.000000,-0.000000,0.591322,0.030123,-0.000000,-83.090416,0.000286,0.000000
15.380001,0.164215,-83.090416,-0.004743,-0.000000,-0.000000,0.730465,0.037212,-0.000000,-83.090416,0.000902,0.000000
15.750001,0.195122,-83.090416,-0.004734,0.000015,0.000390,0.867945,0.044215,0.003902,-83.090416,0.001526,0.000000
16.120001,0.294540,-83.134895,-0.004717,0.000046,0.001162,1.310181,0.066744,0.011621,-83.134895,0.002142,0.000000
16.490002,0.378700,-83.223862,-0.004695,0.000068,0.001734,1.684543,0.085815,0.017345,-83.223862,0.002758,0.000000
16.860001,0.538078,-83.312820,-0.004678,0.000086,0.002177,2.393492,0.121930,0.021767,-83.312820,0.003374,0.000000
17.230001,0.745483,-83.268341,-0.004665,0.000112,0.002853,3.316076,0.168929,0.028532,-83.268341,0.003989,0.000000
17.600000,1.157700,-83.268341,-0.004631,0.000141,0.003573,5.149705,0.262338,0.035730,-83.268341,0.004605,0.000000
17.970001,1.386337,-83.312820,-0.004613,0.000158,0.004015,6.166736,0.314149,0.040153,-83.312820,0.005221,0.000000
18.340000,1.711792,-83.401787,-0.004592,0.000182,0.004631,7.614431,0.387898,0.046310,-83.401787,0.005836,0.000000
18.710001,2.088631,-83.446266,-0.004549,0.000208,0.005290,9.290693,0.473290,0.052901,-83.446266,0.006452,0.000000
19.080002,2.289719,-83.446266,-0.004562,0.000221,0.005602,10.185177,0.518858,0.056023,-83.446266,0.007077,0.000000
19.450001,3.051964,-83.446266,-0.004527,0.000262,0.006652,13.575813,0.691585,0.066516,-83.446266,0.007692,0.000000
19.820002,3.530457,-83.579704,-0.004510,0.000289,0.007337,15.704255,0.800013,0.073367,-83.579704,0.008308,0.000000
20.190001,3.924805,-83.579704,-0.004480,0.000309,0.007857,17.458403,0.889373,0.078571,-83.579704,0.008924,0.000000
20.560001,4.356384,-83.624191,-0.004449,0.000334,0.008490,19.378164,0.987171,0.084901,-83.624191,0.009539,0.000000
20.930000,4.760406,-83.624191,-0.004432,0.000352,0.008950,21.175346,1.078724,0.089498,-83.624191,0.010155,0.000000
21.300001,5.301834,-83.624191,-0.004411,0.000383,0.009722,23.583736,1.201413,0.097216,-83.624191,0.010771,0.000000
21.670000,5.850342,-83.624191,-0.004385,0.000408,0.010372,26.023621,1.325706,0.103720,-83.624191,0.011387,0.000000
22.040001,5.872314,-83.802109,-0.004381,0.000424,0.010780,26.121359,1.330685,0.107796,-83.802109,0.012002,0.000000
22.410002,6.769356,-83.757629,-0.004342,0.000455,0.011560,30.111599,1.533958,0.115601,-83.757629,0.012627,0.000000
22.780001,7.223274,-83.802109,-0.004320,0.000484,0.012297,32.130730,1.636817,0.122973,-83.802109,0.013243,0.000000
23.150002,7.638100,-83.846596,-0.004299,0.000506,0.012844,33.975964,1.730818,0.128436,-83.846596,0.013858,0.000000
23.520000,7.976959,-83.846596,-0.004294,0.000528,0.013399,35.483288,1.807605,0.133986,-83.846596,0.014474,0.000000
23.890001,8.480408,-83.891075,-0.004264,0.000550,0.013980,37.722736,1.921688,0.139797,-83.891075,0.015090,0.000000
24.260000,9.103386,-83.935555,-0.004234,0.000580,0.014734,40.493881,2.062857,0.147342,-83.935555,0.015705,0.000000
24.630001,9.327553,-83.891075,-0.004221,0.000601,0.015272,41.491028,2.113654,0.152718,-83.891075,0.016321,0.000000
25.000002,9.539436,-83.980034,-0.004195,0.000618,0.015705,42.433533,2.161667,0.157055,-83.980034,0.016937,0.000000
25.370001,10.323654,-84.024513,-0.004182,0.000648,0.016460,45.921906,2.339373,0.164599,-84.024513,0.017553,0.000000
25.740002,10.437225,-84.069000,-0.004169,0.000664,0.016876,46.427097,2.365109,0.168762,-84.069000,0.018177,0.000000
26.110001,11.049774,-84.157959,-0.004135,0.000691,0.017553,49.151852,2.503915,0.175526,-84.157959,0.018793,0.000000
26.480001,11.474281,-84.157959,-0.004113,0.000716,0.018186,51.040154,2.600109,0.181857,-84.157959,0.019409,0.000000
26.850000,11.908470,-84.157959,-0.004100,0.000740,0.018801,52.971519,2.698498,0.188015,-84.157959,0.020024,0.000000
27.220001,12.582832,-84.202438,-0.004066,0.000773,0.019643,55.971233,2.851311,0.196427,-84.202438,0.020640,0.000000
27.590002,12.667732,-84.335884,-0.004053,0.000791,0.020102,56.348888,2.870549,0.201023,-84.335884,0.021256,0.000000
27.960001,13.164856,-84.335884,-0.004027,0.000820,0.020839,58.560204,2.983199,0.208394,-84.335884,0.021871,0.000000
28.330002,13.462379,-84.335884,-0.004005,0.000843,0.021420,59.883656,3.050619,0.214205,-84.335884,0.022487,0.000000
28.700001,13.723412,-84.424843,-0.004010,0.000864,0.021941,61.044785,3.109769,0.219408,-84.424843,0.023112,0.000000
29.070002,14.387726,-84.380363,-0.003988,0.000888,0.022557,63.999802,3.260305,0.225565,-84.380363,0.023727,0.000000
29.440001,14.588806,-84.469330,-0.003954,0.000914,0.023216,64.894249,3.305871,0.232156,-84.469330,0.024343,0.000000
29.810001,14.789513,-84.469330,-0.003932,0.000933,0.023710,65.787041,3.351351,0.237100,-84.469330,0.024959,0.000000
30.180002,15.144386,-84.513809,-0.003902,0.000957,0.024308,67.365593,3.431767,0.243083,-84.513809,0.025574,0.000000
30.550001,15.565163,-84.558289,-0.003889,0.000984,0.024993,69.237305,3.527116,0.249934,-84.558289,0.026190,0.000000
30.920002,15.615807,-84.558289,-0.003876,0.001007,0.025583,69.462578,3.538592,0.255832,-84.558289,0.026806,0.000000
31.290001,16.414177,-84.602768,-0.003842,0.001037,0.026329,73.013908,3.719506,0.263290,-84.602768,0.027422,0.000000
31.660002,16.267464,-84.602768,-0.003829,0.001050,0.026676,72.361290,3.686260,0.266759,-84.602768,0.028037,0.000000
32.030003,16.936615,-84.691734,-0.003803,0.001081,0.027448,75.337830,3.837892,0.274477,-84.691734,0.028662,0.000000
32.400002,17.142166,-84.736214,-0.003794,0.001103,0.028020,76.252167,3.884470,0.280201,-84.736214,0.029278,0.000000
32.770000,17.462029,-84.736214,-0.003751,0.001124,0.028558,77.674980,3.956952,0.285577,-84.736214,0.029893,0.000000
33.140003,18.127464,-84.780693,-0.003747,0.001156,0.029373,80.634987,4.107742,0.293729,-84.780693,0.030509,0.000000
33.510002,18.721024,-84.825172,-0.003729,0.001188,0.030171,83.275269,4.242245,0.301708,-84.825172,0.031125,0.000000
33.880001,18.713951,-84.825172,-0.003686,0.001213,0.030821,83.243813,4.240642,0.308212,-84.825172,0.031740,0.000000
34.250000,18.564629,-84.780693,-0.003686,0.001234,0.031333,82.579590,4.206805,0.313329,-84.780693,0.032356,0.000000
34.620003,19.298943,-84.958618,-0.003656,0.001262,0.032044,85.845985,4.373203,0.320440,-84.958618,0.032972,0.000000
34.990002,19.097122,-85.003098,-0.003652,0.001281,0.032538,84.948242,4.327470,0.325383,-85.003098,0.033588,0.000000
35.360001,19.767387,-84.958618,-0.003630,0.001305,0.033145,87.929733,4.479354,0.331454,-84.958618,0.034212,0.000000
35.730003,19.805374,-85.003098,-0.003596,0.001322,0.033588,88.098701,4.487962,0.335877,-85.003098,0.034828,0.000000
36.100002,20.145721,-85.003098,-0.003604,0.001346,0.034186,89.612648,4.565085,0.341860,-85.003098,0.035444,0.000000
36.470001,20.257431,-85.092056,-0.003587,0.001366,0.034689,90.109550,4.590399,0.346890,-85.092056,0.036059,0.000000
36.840000,20.995476,-85.181023,-0.003561,0.001394,0.035400,93.392540,4.757643,0.354001,-85.181023,0.036675,0.000000
37.210003,21.468758,-85.136543,-0.003518,0.001424,0.036172,95.497803,4.864890,0.361720,-85.136543,0.037291,0.000000
37.580002,21.892891,-85.225502,-0.003505,0.001454,0.036944,97.384445,4.961000,0.369438,-85.225502,0.037906,0.000000
37.950001,21.679146,-85.225502,-0.003484,0.001476,0.037490,96.433655,4.912565,0.374902,-85.225502,0.038522,0.000000
38.320004,21.675056,-85.314461,-0.003471,0.001494,0.037950,96.415466,4.911638,0.379498,-85.314461,0.039138,0.000000
38.690002,22.297287,-85.314461,-0.003458,0.001521,0.038644,99.183289,5.052637,0.386436,-85.314461,0.039762,0.000000
39.060001,22.731102,-85.358948,-0.003436,0.001547,0.039285,101.112991,5.150941,0.392853,-85.358948,0.040378,0.000000
39.430000,22.505074,-85.403427,-0.003406,0.001562,0.039684,100.107567,5.099722,0.396842,-85.403427,0.040994,0.000000
39.800003,22.852119,-85.403427,-0.003406,0.001589,0.040369,101.651306,5.178364,0.403694,-85.403427,0.041609,0.000000
40.170002,23.075172,-85.403427,-0.003393,0.001607,0.040820,102.643494,5.228909,0.408203,-85.403427,0.042225,0.000000
40.540001,23.659424,-85.581352,-0.003380,0.001633,0.041488,105.242371,5.361302,0.414881,-85.581352,0.042841,0.000000
40.910004,24.383316,-85.536865,-0.003341,0.001669,0.042381,108.462410,5.525339,0.423813,-85.536865,0.043457,0.000000
41.280003,24.327835,-85.536865,-0.003303,0.001690,0.042919,108.215614,5.512766,0.429190,-85.536865,0.044072,0.000000
41.650002,24.675629,-85.581352,-0.003307,0.001718,0.043647,109.762680,5.591577,0.436475,-85.581352,0.044688,0.000000
42.020000,24.252991,-85.625832,-0.003281,0.001733,0.044012,107.882690,5.495806,0.440117,-85.625832,0.045313,0.000000
42.390003,25.186897,-85.714790,-0.003260,0.001764,0.044801,112.036911,5.707432,0.448009,-85.714790,0.045928,0.000000
42.760002,25.611031,-85.714790,-0.003238,0.001792,0.045512,113.923553,5.803542,0.455120,-85.714790,0.046544,0.000000
43.130001,25.962547,-85.714790,-0.003216,0.001816,0.046136,115.487175,5.883197,0.461364,-85.714790,0.047160,0.000000
43.500004,26.092133,-85.759277,-0.003203,0.001837,0.046657,116.063599,5.912562,0.466568,-85.759277,0.047775,0.000000
43.870003,26.599678,-85.803757,-0.003199,0.001866,0.047394,118.321274,6.027573,0.473939,-85.803757,0.048391,0.000000
44.240002,26.889755,-85.892715,-0.003173,0.001890,0.048001,119.611603,6.093306,0.480009,-85.892715,0.049007,0.000000
44.610001,26.763893,-85.937195,-0.003143,0.001911,0.048539,119.051743,6.064785,0.485386,-85.937195,0.049623,0.000000
44.980003,27.023437,-85.892715,-0.003134,0.001938,0.049224,120.206253,6.123599,0.492237,-85.892715,0.050238,0.000000
45.350002,26.843956,-85.892715,-0.003113,0.001951,0.049545,119.407883,6.082927,0.495446,-85.892715,0.050863,0.000000
45.720001,27.651634,-85.981682,-0.003104,0.001984,0.050394,123.000610,6.265950,0.503945,-85.981682,0.051479,0.000000
46.090004,28.313713,-86.070641,-0.003083,0.002011,0.051071,125.945686,6.415979,0.510709,-86.070641,0.052094,0.000000
46.460003,28.253387,-86.070641,-0.003061,0.002031,0.051591,125.677345,6.402309,0.515913,-86.070641,0.052710,0.000000
46.830002,28.404938,-86.070641,-0.003053,0.002053,0.052146,126.351471,6.436651,0.521463,-86.070641,0.053326,0.000000
47.200001,28.797050,-86.115120,-0.003035,0.002075,0.052701,128.095673,6.525505,0.527013,-86.115120,0.053941,0.000000
47.570004,29.484451,-86.159599,-0.003027,0.002104,0.053430,131.153397,6.681272,0.534298,-86.159599,0.054557,0.000000
47.940002,29.753304,-86.159599,-0.003014,0.002124,0.053950,132.349304,6.742195,0.539501,-86.159599,0.055173,0.000000
48.310001,30.302551,-86.204086,-0.002979,0.002149,0.054583,134.792480,6.866656,0.545832,-86.204086,0.055789,0.000000
48.680004,30.775093,-86.248566,-0.002971,0.002178,0.055312,136.894455,6.973735,0.553117,-86.248566,0.056413,0.000000
49.050003,30.790733,-86.293045,-0.002953,0.002199,0.055849,136.964020,6.977280,0.558493,-86.293045,0.057029,0.000000
49.420002,31.156403,-86.337524,-0.002945,0.002227,0.056560,138.590607,7.060142,0.565605,-86.337524,0.057644,0.000000
49.790001,31.201454,-86.382004,-0.002928,0.002247,0.057063,138.791000,7.070350,0.570634,-86.382004,0.058260,0.000000
50.160004,31.517227,-86.382004,-0.002902,0.002267,0.057575,140.195633,7.141906,0.575751,-86.382004,0.058876,0.000000
50.530003,32.851067,-86.470970,-0.002884,0.002300,0.058416,146.128845,7.444158,0.584163,-86.470970,0.059492,0.000000
50.900002,32.920700,-86.426491,-0.002871,0.002323,0.059015,146.438583,7.459937,0.590147,-86.426491,0.060107,0.000000
51.270004,33.439041,-86.515450,-0.002854,0.002348,0.059648,148.744278,7.577395,0.596478,-86.515450,0.060723,0.000000
51.640003,33.293449,-86.559929,-0.002850,0.002368,0.060159,148.096664,7.544404,0.601594,-86.559929,0.061348,0.000000
52.010002,33.738808,-86.559929,-0.002828,0.002392,0.060749,150.077713,7.645323,0.607492,-86.559929,0.061963,0.000000
52.380001,34.324921,-86.515450,-0.002798,0.002420,0.061460,152.684875,7.778138,0.614603,-86.515450,0.062579,0.000000
52.750004,34.571426,-86.648895,-0.002794,0.002442,0.062024,153.781387,7.833997,0.620240,-86.648895,0.063195,0.000000
53.120003,34.675323,-86.693375,-0.002781,0.002462,0.062544,154.243546,7.857541,0.625443,-86.693375,0.063810,0.000000
53.490002,35.275581,-86.737854,-0.002768,0.002490,0.063255,156.913620,7.993561,0.632554,-86.737854,0.064426,0.000000
53.860004,35.364586,-86.737854,-0.002751,0.002510,0.063758,157.309540,8.013730,0.637584,-86.737854,0.065042,0.000000
54.230003,36.252693,-86.693375,-0.002742,0.002542,0.064574,161.260040,8.214977,0.645736,-86.693375,0.065658,0.000000
54.600002,36.483559,-86.782333,-0.002738,0.002563,0.065111,162.286972,8.267293,0.651113,-86.782333,0.066273,0.000000
54.970001,37.292725,-86.826813,-0.002725,0.002590,0.065796,165.886322,8.450652,0.657964,-86.826813,0.066898,0.000000
55.340004,37.687073,-86.871300,-0.002686,0.002618,0.066499,167.640472,8.540012,0.664989,-86.871300,0.067514,0.000000
55.710003,37.294960,-86.871300,-0.002677,0.002639,0.067019,165.896271,8.451159,0.670192,-86.871300,0.068129,0.000000
56.080002,38.296646,-86.915779,-0.002669,0.002666,0.067704,170.351990,8.678144,0.677043,-86.915779,0.068745,0.000000
56.450005,38.113434,-86.960258,-0.002656,0.002687,0.068242,169.537018,8.636628,0.682420,-86.960258,0.069361,0.000000
56.820004,38.566612,-87.004738,-0.002647,0.002712,0.068875,171.552856,8.739319,0.688751,-87.004738,0.069976,0.000000
57.190002,38.671623,-87.093704,-0.002630,0.002732,0.069404,172.019974,8.763115,0.694041,-87.093704,0.070592,0.000000
57.560001,38.772537,-87.093704,-0.002630,0.002757,0.070020,172.468857,8.785982,0.700198,-87.093704,0.071208,0.000000
57.930004,38.237061,-87.093704,-0.002613,0.002766,0.070245,170.086945,8.664642,0.702453,-87.093704,0.071824,0.000000
58.300003,40.383415,-87.138184,-0.002591,0.002807,0.071295,179.634399,9.151012,0.712946,-87.138184,0.072448,0.000000
58.670002,40.636261,-87.182663,-0.002587,0.002832,0.071936,180.759109,9.208308,0.719364,-87.182663,0.073064,0.000000
59.040001,41.545593,-87.227142,-0.002578,0.002862,0.072700,184.804031,9.414367,0.726995,-87.227142,0.073679,0.000000
59.410004,41.243599,-87.227142,-0.002552,0.002879,0.073133,183.460693,9.345933,0.731331,-87.227142,0.074295,0.000000
59.780003,41.109917,-87.271629,-0.002539,0.002899,0.073645,182.866043,9.315640,0.736448,-87.271629,0.074911,0.000000
60.150002,42.227036,-87.316109,-0.002531,0.002931,0.074451,187.835236,9.568783,0.744513,-87.316109,0.075527,0.000000
60.520004,41.925781,-87.360588,-0.002531,0.002954,0.075024,186.495193,9.500518,0.750237,-87.360588,0.076142,0.000000
60.890003,41.957809,-87.405067,-0.002514,0.002976,0.075579,186.637665,9.507775,0.755787,-87.405067,0.076758,0.000000
61.260002,42.213257,-87.449547,-0.002505,0.002995,0.076073,187.773941,9.565660,0.760730,-87.449547,0.077374,0.000000
61.630001,41.732521,-87.449547,-0.002505,0.003011,0.076489,185.635529,9.456724,0.764893,-87.449547,0.077998,0.000000
62.000004,43.614868,-87.538513,-0.002470,0.003052,0.077513,194.008621,9.883270,0.775126,-87.538513,0.078614,0.000000
62.370003,43.960800,-87.449547,-0.002475,0.003081,0.078250,195.547409,9.961659,0.782498,-87.449547,0.079230,0.000000
62.740002,43.748924,-87.582993,-0.002449,0.003102,0.078779,194.604935,9.913649,0.787788,-87.582993,0.079845,0.000000
63.110004,43.990593,-87.582993,-0.002436,0.003126,0.079412,195.679932,9.968411,0.794119,-87.582993,0.080461,0.000000
63.480003,43.614494,-87.582993,-0.002427,0.003148,0.079958,194.006958,9.883185,0.799582,-87.582993,0.081077,0.000000
63.850002,44.110863,-87.582993,-0.002419,0.003170,0.080513,196.214920,9.995665,0.805132,-87.582993,0.081693,0.000000
64.220001,44.282158,-87.716438,-0.002406,0.003192,0.081086,196.976883,10.034480,0.810856,-87.716438,0.082308,0.000000
64.590004,44.412117,-87.805397,-0.002406,0.003215,0.081658,197.554962,10.063930,0.816580,-87.805397,0.082924,0.000000
64.960007,44.702194,-87.760918,-0.002393,0.003242,0.082334,198.845291,10.129662,0.823344,-87.760918,0.083549,0.000000
65.330002,45.868835,-87.760918,-0.002367,0.003274,0.083167,204.034775,10.394027,0.831669,-87.760918,0.084164,0.000000
65.700005,45.903839,-87.805397,-0.002363,0.003298,0.083757,204.190475,10.401958,0.837566,-87.805397,0.084780,0.000000
66.070000,46.229668,-87.894356,-0.002345,0.003320,0.084329,205.639832,10.475793,0.843290,-87.894356,0.085396,0.000000
66.440002,46.842964,-87.938843,-0.002350,0.003344,0.084945,208.367905,10.614768,0.849448,-87.938843,0.086011,0.000000
66.810005,47.136765,-87.938843,-0.002337,0.003370,0.085595,209.674805,10.681343,0.855952,-87.938843,0.086627,0.000000
67.180000,47.407104,-87.983322,-0.002307,0.003389,0.086089,210.877335,10.742603,0.860895,-87.983322,0.087243,0.000000
67.550003,47.973488,-88.027802,-0.002302,0.003413,0.086697,213.396729,10.870948,0.866965,-88.027802,0.087859,0.000000
67.920006,48.221855,-88.027802,-0.002294,0.003434,0.087217,214.501526,10.927229,0.872169,-88.027802,0.088474,0.000000
68.290001,49.029533,-88.072281,-0.002276,0.003460,0.087893,218.094254,11.110251,0.878933,-88.072281,0.089099,0.000000
68.660004,48.837387,-88.116760,-0.002268,0.003475,0.088258,217.239548,11.066710,0.882576,-88.116760,0.089714,0.000000
69.030006,50.523865,-88.072281,-0.002264,0.003512,0.089194,224.741379,11.448872,0.891942,-88.072281,0.090330,0.000000
69.400002,50.508224,-88.116760,-0.002255,0.003523,0.089472,224.671799,11.445327,0.894717,-88.116760,0.090946,0.000000
69.770004,52.623672,-88.250206,-0.002238,0.003560,0.090417,234.081787,11.924695,0.904170,-88.250206,0.091562,0.000000
70.140007,52.874649,-88.250206,-0.002220,0.003581,0.090955,235.198181,11.981566,0.909546,-88.250206,0.092177,0.000000
70.510002,53.677490,-88.339172,-0.002199,0.003605,0.091570,238.769409,12.163493,0.915704,-88.339172,0.092793,0.000000
70.880005,55.315926,-88.339172,-0.002203,0.003634,0.092308,246.057526,12.534767,0.923075,-88.339172,0.093409,0.000000
71.250000,55.385185,-88.339172,-0.002195,0.003648,0.092654,246.365616,12.550463,0.926544,-88.339172,0.094025,0.000000
71.620003,55.659256,-88.428131,-0.002173,0.003664,0.093062,247.584732,12.612568,0.930620,-88.428131,0.094649,0.000000
71.990005,58.442368,-88.428131,-0.002147,0.003704,0.094077,259.964630,13.243230,0.940766,-88.428131,0.095265,0.000000
72.360001,59.012466,-88.472610,-0.002130,0.003722,0.094545,262.500549,13.372416,0.945449,-88.472610,0.095880,0.000000
72.730003,60.486687,-88.428131,-0.002139,0.003751,0.095265,269.058228,13.706479,0.952647,-88.428131,0.096496,0.000000
73.100006,61.532310,-88.472610,-0.002130,0.003777,0.095924,273.709381,13.943421,0.959238,-88.472610,0.097112,0.000000
73.470001,62.732841,-88.561577,-0.002108,0.003799,0.096488,279.049622,14.215465,0.964875,-88.561577,0.097728,0.000000
73.840004,64.424156,-88.606056,-0.002108,0.003827,0.097199,286.572968,14.598722,0.971987,-88.606056,0.098343,0.000000
74.210007,65.296257,-88.606056,-0.002087,0.003847,0.097719,290.452271,14.796344,0.977190,-88.606056,0.098959,0.000000
74.580002,65.896141,-88.561577,-0.002070,0.003859,0.098014,293.120667,14.932280,0.980139,-88.561577,0.098231,0.000000
74.950005,65.701027,-88.695015,-0.002065,0.003876,0.098456,292.252777,14.888065,0.984561,-88.695015,294.500488,0.000000
75.320007,64.921272,-88.739494,-0.002070,0.003877,0.098473,288.784241,14.711370,0.984735,-88.739494,294.500488,0.000000
75.690002,65.690224,-88.783981,-0.002044,0.003883,0.098630,292.204712,14.885618,0.986296,-88.783981,294.500488,0.000000
76.060005,65.032234,-88.783981,-0.002026,0.003898,0.099002,289.277832,14.736515,0.990025,-88.783981,294.500488,0.000000
76.430000,64.809196,-88.828461,-0.002031,0.003900,0.099072,288.285706,14.685973,0.990719,-88.828461,294.500488,0.000000
76.800003,65.384132,-88.828461,-0.002022,0.003912,0.099375,290.843140,14.816257,0.993754,-88.828461,294.500488,0.000000
77.170006,64.799141,-88.917419,-0.002018,0.003913,0.099384,288.240967,14.683695,0.993841,-88.917419,294.500488,0.000000
77.540001,65.830986,-88.961899,-0.002031,0.003924,0.099662,292.830841,14.917515,0.996616,-88.961899,294.500488,0.000000
77.910004,65.205391,-88.917419,-0.002031,0.003924,0.099670,290.048065,14.775753,0.996702,-88.917419,294.500488,0.000000
78.280006,64.689293,-89.006386,-0.002001,0.003934,0.099913,287.752350,14.658804,0.999131,-89.006386,294.500488,0.000000
78.650002,65.572929,-89.050865,-0.001996,0.003932,0.099870,291.682953,14.859038,0.998697,-89.050865,294.500488,0.000000
79.020004,65.049004,-89.139824,-0.002001,0.003933,0.099887,289.352417,14.740315,0.998871,-89.139824,294.500488,0.000000
79.390007,66.140053,-89.095345,-0.001996,0.003949,0.100312,294.205658,14.987550,1.003120,-89.095345,294.500488,0.000000
79.760002,65.623192,-89.095345,-0.001996,0.003943,0.100165,291.906525,14.870428,1.001646,-89.095345,294.500488,0.000000
80.130005,65.226997,-89.095345,-0.001992,0.003943,0.100165,290.144165,14.780648,1.001646,-89.095345,294.500488,0.000000
80.500008,64.840843,-89.228790,-0.001996,0.003943,0.100165,288.426483,14.693146,1.001646,-89.228790,294.500488,0.000000
80.870003,65.582237,-89.317749,-0.001979,0.003962,0.100624,291.724365,14.861147,1.006242,-89.317749,294.500488,0.000000
81.240005,65.361046,-89.273270,-0.001988,0.003962,0.100633,290.740448,14.811025,1.006329,-89.273270,294.500488,0.000000
81.610001,65.116768,-89.273270,-0.001979,0.003962,0.100633,289.653839,14.755671,1.006329,-89.273270,294.500488,0.000000
81.980003,64.937660,-89.273270,-0.001988,0.003963,0.100668,288.857147,14.715084,1.006676,-89.273270,294.500488,0.000000
82.350006,65.601219,-89.406715,-0.001996,0.003974,0.100928,291.808807,14.865449,1.009277,-89.406715,294.500488,0.000000
82.720001,65.466057,-89.495674,-0.001979,0.003974,0.100928,291.207550,14.834821,1.009277,-89.495674,294.500488,0.000000
83.090004,65.254555,-89.495674,-0.001988,0.003974,0.100928,290.266754,14.786894,1.009277,-89.495674,294.500488,0.000000
83.460007,65.106712,-89.495674,-0.001975,0.003974,0.100936,289.609131,14.753392,1.009364,-89.495674,294.500488,0.000000
83.830002,64.916054,-89.451195,-0.001970,0.003974,0.100936,288.761017,14.710188,1.009364,-89.451195,294.500488,0.000000
84.200005,66.200005,-89.540154,-0.001970,0.003984,0.101205,294.472321,15.001135,1.012053,-89.540154,294.500488,0.000000
84.570007,65.902855,-89.629120,-0.001962,0.003984,0.101197,293.150543,14.933801,1.011966,-89.629120,294.500488,0.000000
84.940002,65.766563,-89.673599,-0.001979,0.003984,0.101197,292.544281,14.902917,1.011966,-89.673599,294.500488,0.000000
85.310005,65.529732,-89.584633,-0.001979,0.003984,0.101205,291.490814,14.849250,1.012053,-89.584633,294.500488,0.000000
85.680000,65.340569,-89.718079,-0.001966,0.003984,0.101205,290.649353,14.806384,1.012053,-89.718079,294.500488,0.000000
86.050003,65.161079,-89.762558,-0.001975,0.003984,0.101205,289.850952,14.765712,1.012053,-89.762558,294.500488,0.000000
86.420006,65.012138,-89.762558,-0.001966,0.003984,0.101205,289.188446,14.731961,1.012053,-89.762558,294.500488,0.000000
86.790001,64.855370,-89.807037,-0.001966,0.003984,0.101205,288.491089,14.696436,1.012053,-89.807037,294.500488,0.000000
87.160004,64.685936,-89.718079,-0.001975,0.003984,0.101205,287.737427,14.658043,1.012053,-89.718079,294.500488,0.000000
87.530006,66.407036,-89.851524,-0.001953,0.003975,0.100971,295.393250,15.048050,1.009711,-89.851524,294.500488,0.000000
87.900002,66.259956,-89.940483,-0.001962,0.003975,0.100971,294.739014,15.014721,1.009711,-89.940483,294.500488,0.000000
88.270004,66.093498,-89.940483,-0.001962,0.003975,0.100971,293.998566,14.977000,1.009711,-89.940483,294.500488,0.000000
88.640007,65.909172,-89.940483,-0.001944,0.003976,0.100980,293.178650,14.935231,1.009798,-89.940483,294.500488,0.000000
89.010002,65.846626,-89.984962,-0.001949,0.003976,0.100980,292.900421,14.921059,1.009798,-89.984962,294.500488,0.000000
89.380005,65.671227,-90.029442,-0.001962,0.003976,0.100988,292.120209,14.881313,1.009884,-90.029442,294.500488,0.000000
89.750008,65.539040,-90.118408,-0.001953,0.003976,0.100997,291.532196,14.851358,1.009971,-90.118408,294.500488,0.000000
90.120003,65.407967,-90.162888,-0.001944,0.003977,0.101006,290.949158,14.821657,1.010058,-90.162888,294.500488,0.000000
90.490005,65.334236,-90.207367,-0.001932,0.003991,0.101379,290.621185,14.804950,1.013787,-90.207367,294.500488,0.000000
90.860001,65.294395,-90.207367,-0.001944,0.003996,0.101500,290.443970,14.795921,1.015001,-90.207367,294.500488,0.000000
91.230003,65.286568,-90.207367,-0.001949,0.004000,0.101595,290.409149,14.794147,1.015955,-90.207367,294.500488,0.000000
91.600006,65.203163,-90.207367,-0.001949,0.004000,0.101595,290.038147,14.775248,1.015955,-90.207367,294.500488,0.000000
91.970001,65.246361,-90.296333,-0.001940,0.004002,0.101656,290.230316,14.785036,1.016562,-90.296333,294.500488,0.000000
92.340004,65.260139,-90.296333,-0.001953,0.004003,0.101674,290.291595,14.788159,1.016735,-90.296333,294.500488,0.000000
92.710007,65.292152,-90.296333,-0.001940,0.004005,0.101734,290.433990,14.795413,1.017342,-90.296333,294.500488,0.000000
93.080002,65.253426,-90.385292,-0.001949,0.004005,0.101734,290.261719,14.786638,1.017342,-90.385292,294.500488,0.000000
93.450005,65.226616,-90.385292,-0.001944,0.004006,0.101752,290.142487,14.780562,1.017516,-90.385292,294.500488,0.000000
93.820007,65.296257,-90.429771,-0.001949,0.004008,0.101812,290.452271,14.796344,1.018123,-90.429771,294.500488,0.000000
94.190002,65.295143,-90.385292,-0.001936,0.004009,0.101821,290.447296,14.796091,1.018210,-90.385292,294.500488,0.000000
94.560005,65.329018,-90.474251,-0.001944,0.004011,0.101882,290.597992,14.803767,1.018817,-90.474251,294.500488,0.000000
94.930008,65.354347,-90.518738,-0.001936,0.004011,0.101882,290.710663,14.809507,1.018817,-90.518738,294.500488,0.000000
95.300003,65.317101,-90.652176,-0.001932,0.004011,0.101890,290.544983,14.801066,1.018903,-90.652176,294.500488,0.000000
95.670006,65.278374,-90.607697,-0.001940,0.004011,0.101890,290.372711,14.792291,1.018903,-90.607697,294.500488,0.000000
96.040001,65.248955,-90.563217,-0.001949,0.004011,0.101890,290.241852,14.785625,1.018903,-90.563217,294.500488,0.000000
96.410004,65.205025,-90.652176,-0.001944,0.004015,0.101977,290.046448,14.775670,1.019771,-90.652176,294.500488,0.000000
96.780006,65.337212,-90.785622,-0.001936,0.004015,0.101986,290.634430,14.805623,1.019857,-90.785622,294.500488,0.000000
97.150002,65.319710,-90.741142,-0.001936,0.004015,0.101986,290.556580,14.801658,1.019857,-90.741142,294.500488,0.000000
97.520004,65.296257,-90.785622,-0.001936,0.004015,0.101986,290.452271,14.796344,1.019857,-90.785622,294.500488,0.000000
97.890007,65.251945,-90.785622,-0.001940,0.004016,0.101994,290.255157,14.786302,1.019944,-90.785622,294.500488,0.000000
98.260002,65.235558,-90.830101,-0.001949,0.004016,0.102012,290.182251,14.782589,1.020118,-90.830101,294.500488,0.000000
98.630005,65.289543,-90.919067,-0.001936,0.004019,0.102072,290.422394,14.794822,1.020725,-90.919067,294.500488,0.000000
99.000008,65.326042,-90.963547,-0.001927,0.004019,0.102081,290.584747,14.803092,1.020811,-90.963547,294.500488,0.000000
99.370003,65.308540,-90.963547,-0.001923,0.004019,0.102081,290.506897,14.799127,1.020811,-90.963547,294.500488,0.000000
99.740005,65.280235,-90.919067,-0.001932,0.004019,0.102081,290.380981,14.792713,1.020811,-90.919067,294.500488,0.000000
100.110008,65.248955,-90.963547,-0.001940,0.004019,0.102090,290.241852,14.785625,1.020898,-90.963547,294.500488,0.000000
100.480003,65.220665,-91.096985,-0.001940,0.004020,0.102107,290.115997,14.779214,1.021071,-91.096985,294.500488,0.000000
100.850006,65.255669,-91.096985,-0.001932,0.004022,0.102151,290.271698,14.787147,1.021505,-91.096985,294.500488,0.000000
101.220001,65.291405,-91.096985,-0.001923,0.004022,0.102151,290.430664,14.795244,1.021505,-91.096985,294.500488,0.000000
101.590004,65.243370,-91.141472,-0.001923,0.004022,0.102151,290.217010,14.784359,1.021505,-91.141472,294.500488,0.000000
101.960007,65.260139,-91.141472,-0.001932,0.004023,0.102177,290.291595,14.788159,1.021765,-91.141472,294.500488,0.000000
102.330002,65.230721,-91.230431,-0.001940,0.004023,0.102177,290.160736,14.781493,1.021765,-91.230431,294.500488,0.000000
102.700005,65.271675,-91.274910,-0.001923,0.004024,0.102211,290.342926,14.790773,1.022112,-91.274910,294.500488,0.000000
103.070007,65.278008,-91.319389,-0.001932,0.004024,0.102211,290.371094,14.792209,1.022112,-91.319389,294.500488,0.000000
103.440002,65.243370,-91.319389,-0.001940,0.004024,0.102211,290.217010,14.784359,1.022112,-91.319389,294.500488,0.000000
103.810005,65.201302,-91.319389,-0.001949,0.004024,0.102211,290.029877,14.774826,1.022112,-91.319389,294.500488,0.000000
104.180008,65.181190,-91.497314,-0.001936,0.004024,0.102220,289.940430,14.770268,1.022199,-91.497314,294.500488,0.000000
104.550003,65.127571,-91.408356,-0.001940,0.004024,0.102220,289.701904,14.758119,1.022199,-91.408356,294.500488,0.000000
104.920006,65.122734,-91.408356,-0.001944,0.004025,0.102246,289.680389,14.757022,1.022459,-91.408356,294.500488,0.000000
105.290009,65.121986,-91.408356,-0.001927,0.004026,0.102255,289.677063,14.756853,1.022546,-91.408356,294.500488,0.000000
105.660004,65.093315,-91.541794,-0.001927,0.004026,0.102272,289.549530,14.750356,1.022719,-91.541794,294.500488,0.000000
106.030006,65.104103,-91.541794,-0.001936,0.004027,0.102281,289.597504,14.752801,1.022806,-91.541794,294.500488,0.000000
106.400002,65.320091,-91.630760,-0.001927,0.004030,0.102367,290.558289,14.801744,1.023673,-91.630760,294.500488,0.000000
106.770004,65.335732,-91.541794,-0.001914,0.004030,0.102367,290.627838,14.805288,1.023673,-91.541794,294.500488,0.000000
107.140007,65.348015,-91.630760,-0.001910,0.004030,0.102367,290.682495,14.808072,1.023673,-91.630760,294.500488,0.000000
107.510002,65.332741,-91.675240,-0.001927,0.004030,0.102367,290.614532,14.804610,1.023673,-91.675240,294.500488,0.000000
107.880005,65.309654,-91.675240,-0.001919,0.004030,0.102367,290.511841,14.799379,1.023673,-91.675240,294.500488,0.000000
108.250008,65.292534,-91.764198,-0.001914,0.004030,0.102367,290.435699,14.795500,1.023673,-91.764198,294.500488,0.000000
108.620003,65.269814,-91.808685,-0.001927,0.004030,0.102367,290.334625,14.790351,1.023673,-91.808685,294.500488,0.000000
108.990005,65.247841,-91.808685,-0.001932,0.004030,0.102367,290.236877,14.785373,1.023673,-91.808685,294.500488,0.000000
109.360008,65.222893,-91.808685,-0.001936,0.004030,0.102367,290.125916,14.779719,1.023673,-91.808685,294.500488,0.000000
109.730003,65.163689,-91.853165,-0.001919,0.004030,0.102367,289.862549,14.766303,1.023673,-91.853165,294.500488,0.000000
110.100006,65.196083,-91.853165,-0.001923,0.004032,0.102411,290.006653,14.773643,1.024107,-91.853165,294.500488,0.000000
110.470009,65.206139,-91.897644,-0.001919,0.004032,0.102411,290.051392,14.775923,1.024107,-91.897644,294.500488,0.000000
110.840004,65.207253,-91.986610,-0.001944,0.004032,0.102411,290.056335,14.776175,1.024107,-91.986610,294.500488,0.000000
111.210007,65.164055,-91.986610,-0.001919,0.004032,0.102411,289.864197,14.766386,1.024107,-91.986610,294.500488,0.000000
111.580002,65.134636,-92.031090,-0.001927,0.004032,0.102411,289.733337,14.759720,1.024107,-92.031090,294.500488,0.000000
111.950005,65.107826,-92.075569,-0.001932,0.004032,0.102419,289.614075,14.753644,1.024194,-92.075569,294.500488,0.000000
112.320007,65.094795,-92.075569,-0.001919,0.004032,0.102419,289.556122,14.750691,1.024194,-92.075569,294.500488,0.000000
112.690002,65.077675,-92.120049,-0.001927,0.004032,0.102419,289.479950,14.746812,1.024194,-92.120049,294.500488,0.000000
113.060005,65.060921,-92.164528,-0.001927,0.004033,0.102428,289.405426,14.743015,1.024280,-92.164528,294.500488,0.000000
113.430008,65.041924,-92.209015,-0.001932,0.004033,0.102428,289.320923,14.738711,1.024280,-92.209015,294.500488,0.000000
113.800003,65.024055,-92.253494,-0.001932,0.004033,0.102428,289.241455,14.734662,1.024280,-92.253494,294.500488,0.000000
114.170006,64.997978,-92.253494,-0.001923,0.004033,0.102428,289.125458,14.728752,1.024280,-92.253494,294.500488,0.000000
114.540009,64.978996,-92.253494,-0.001923,0.004033,0.102428,289.041016,14.724450,1.024280,-92.253494,294.500488,0.000000
114.910004,65.610909,-92.297974,-0.001906,0.004041,0.102645,291.851898,14.867644,1.026448,-92.297974,294.500488,0.000000
115.280006,65.666771,-92.342453,-0.001932,0.004041,0.102645,292.100372,14.880303,1.026448,-92.342453,294.500488,0.000000
115.650009,65.672722,-92.386932,-0.001927,0.004041,0.102645,292.126862,14.881652,1.026448,-92.386932,294.500488,0.000000
116.020004,65.667885,-92.431419,-0.001932,0.004041,0.102645,292.105347,14.880556,1.026448,-92.431419,294.500488,0.000000
116.390007,65.650383,-92.475899,-0.001910,0.004041,0.102645,292.027496,14.876590,1.026448,-92.475899,294.500488,0.000000
116.760002,65.610542,-92.520378,-0.001923,0.004041,0.102645,291.850281,14.867561,1.026448,-92.520378,294.500488,0.000000
117.130005,65.598991,-92.653824,-0.001923,0.004041,0.102645,291.798889,14.864944,1.026448,-92.653824,294.500488,0.000000
117.500008,65.602348,-92.609337,-0.001919,0.004041,0.102645,291.813812,14.865705,1.026448,-92.609337,294.500488,0.000000
117.870003,65.587074,-92.520378,-0.001923,0.004041,0.102645,291.745880,14.862244,1.026448,-92.520378,294.500488,0.000000
118.240005,65.555046,-92.609337,-0.001919,0.004041,0.102645,291.603394,14.854985,1.026448,-92.609337,294.500488,0.000000
118.610008,65.538292,-92.609337,-0.001927,0.004041,0.102645,291.528870,14.851189,1.026448,-92.609337,294.500488,0.000000
118.980003,65.520042,-92.742783,-0.001932,0.004041,0.102645,291.447693,14.847054,1.026448,-92.742783,294.500488,0.000000
119.350006,65.495842,-92.698303,-0.001923,0.004041,0.102645,291.340057,14.841571,1.026448,-92.698303,294.500488,0.000000
119.720009,65.465675,-92.742783,-0.001914,0.004041,0.102645,291.205872,14.834734,1.026448,-92.742783,294.500488,0.000000
120.090004,65.445198,-92.742783,-0.001919,0.004041,0.102645,291.114777,14.830093,1.026448,-92.742783,294.500488,0.000000
120.460007,65.404991,-92.787262,-0.001919,0.004041,0.102645,290.935944,14.820983,1.026448,-92.787262,294.500488,0.000000
120.830009,65.378914,-92.876228,-0.001923,0.004041,0.102645,290.819946,14.815073,1.026448,-92.876228,294.500488,0.000000
121.200005,65.343178,-92.920708,-0.001923,0.004041,0.102645,290.660980,14.806976,1.026448,-92.920708,294.500488,0.000000
121.570007,65.319710,-92.965187,-0.001906,0.004042,0.102662,290.556580,14.801658,1.026622,-92.965187,294.500488,0.000000
121.940002,65.325294,-92.920708,-0.001919,0.004042,0.102671,290.581421,14.802923,1.026709,-92.920708,294.500488,0.000000
122.310005,65.317848,-92.965187,-0.001914,0.004042,0.102671,290.548309,14.801236,1.026709,-92.965187,294.500488,0.000000
122.680008,65.291039,-93.009666,-0.001927,0.004042,0.102671,290.429047,14.795160,1.026709,-93.009666,294.500488,0.000000
123.050003,65.274651,-93.054146,-0.001906,0.004042,0.102671,290.356140,14.791448,1.026709,-93.054146,294.500488,0.000000
123.420006,65.276146,-93.054146,-0.001914,0.004042,0.102671,290.362793,14.791786,1.026709,-93.054146,294.500488,0.000000
123.790009,65.242638,-93.054146,-0.001932,0.004042,0.102671,290.213745,14.784193,1.026709,-93.054146,294.500488,0.000000
124.160004,65.234444,-93.098633,-0.001923,0.004042,0.102671,290.177307,14.782336,1.026709,-93.098633,294.500488,0.000000
124.530006,65.237419,-93.232071,-0.001906,0.004042,0.102671,290.190521,14.783010,1.026709,-93.232071,294.500488,0.000000
124.900009,65.198326,-93.187592,-0.001919,0.004042,0.102671,290.016632,14.774152,1.026709,-93.187592,294.500488,0.000000
125.270004,65.187141,-93.232071,-0.001906,0.004042,0.102671,289.966888,14.771618,1.026709,-93.232071,294.500488,0.000000
125.640007,65.158852,-93.187592,-0.001923,0.004042,0.102671,289.841034,14.765207,1.026709,-93.187592,294.500488,0.000000
126.010010,65.126457,-93.321037,-0.001927,0.004042,0.102671,289.696960,14.757866,1.026709,-93.321037,294.500488,0.000000
126.380005,65.114159,-93.365517,-0.001923,0.004042,0.102671,289.642242,14.755079,1.026709,-93.365517,294.500488,0.000000
126.750008,65.096657,-93.365517,-0.001914,0.004042,0.102671,289.564392,14.751113,1.026709,-93.365517,294.500488,0.000000
127.120003,65.055702,-93.321037,-0.001914,0.004042,0.102671,289.382202,14.741833,1.026709,-93.321037,294.500488,0.000000
127.490005,65.042671,-93.454475,-0.001919,0.004042,0.102671,289.324249,14.738880,1.026709,-93.454475,294.500488,0.000000
127.860008,65.026283,-93.454475,-0.001944,0.004042,0.102671,289.251343,14.735167,1.026709,-93.454475,294.500488,0.000000
128.230011,65.018456,-93.543442,-0.001914,0.004042,0.102671,289.216522,14.733393,1.026709,-93.543442,294.500488,0.000000
128.600006,65.005424,-93.543442,-0.001910,0.004042,0.102671,289.158569,14.730440,1.026709,-93.543442,294.500488,0.000000
128.970001,64.973412,-93.543442,-0.001914,0.004042,0.102671,289.016174,14.723186,1.026709,-93.543442,294.500488,0.000000
129.340012,64.956642,-93.587921,-0.001914,0.004042,0.102671,288.941589,14.719386,1.026709,-93.587921,294.500488,0.000000
129.710007,64.958885,-93.632401,-0.001910,0.004042,0.102671,288.951538,14.719894,1.026709,-93.632401,294.500488,0.000000
130.080002,64.925377,-93.632401,-0.001919,0.004042,0.102671,288.802490,14.712301,1.026709,-93.632401,294.500488,0.000000
130.450012,65.917747,-93.676880,-0.001923,0.004054,0.102974,293.216797,14.937175,1.029744,-93.676880,294.500488,0.000000
130.820007,65.919975,-93.721367,-0.001897,0.004054,0.102974,293.226685,14.937680,1.029744,-93.721367,294.500488,0.000000
131.190002,65.945671,-93.721367,-0.001910,0.004052,0.102931,293.341003,14.943502,1.029310,-93.721367,294.500488,0.000000
131.560013,65.919228,-93.765846,-0.001923,0.004052,0.102931,293.223358,14.937510,1.029310,-93.765846,294.500488,0.000000
131.930008,65.854805,-93.854805,-0.001923,0.004052,0.102931,292.936798,14.922912,1.029310,-93.854805,294.500488,0.000000
132.300003,65.878639,-93.765846,-0.001910,0.004052,0.102931,293.042816,14.928313,1.029310,-93.765846,294.500488,0.000000
132.670013,65.868584,-93.899284,-0.001910,0.004052,0.102931,292.998108,14.926034,1.029310,-93.899284,294.500488,0.000000
133.040009,65.860023,-93.899284,-0.001910,0.004052,0.102931,292.960022,14.924095,1.029310,-93.899284,294.500488,0.000000
133.410004,65.817940,-93.943771,-0.001910,0.004052,0.102931,292.772827,14.914558,1.029310,-93.943771,294.500488,0.000000
133.779999,65.803795,-93.988251,-0.001906,0.004052,0.102931,292.709900,14.911353,1.029310,-93.988251,294.500488,0.000000
134.150009,65.801567,-94.032730,-0.001910,0.004052,0.102931,292.699982,14.910849,1.029310,-94.032730,294.500488,0.000000
134.520004,65.807518,-94.032730,-0.001923,0.004052,0.102931,292.726471,14.912197,1.029310,-94.032730,294.500488,0.000000
134.889999,65.783684,-94.032730,-0.001914,0.004052,0.102931,292.620453,14.906796,1.029310,-94.032730,294.500488,0.000000
135.260010,65.740486,-94.077209,-0.001914,0.004050,0.102879,292.428284,14.897007,1.028790,-94.077209,0.102801,0.000000
135.630005,65.618721,-94.210655,-0.001906,0.004034,0.102454,291.886658,14.869415,1.024541,-94.210655,0.102185,0.000000
136.000000,65.602348,-94.210655,-0.001910,0.004017,0.102029,291.813812,14.865705,1.020291,-94.210655,0.101569,0.000000
136.370010,65.532341,-94.166176,-0.001888,0.003996,0.101500,291.502411,14.849841,1.015001,-94.166176,0.100954,0.000000
136.740005,65.485420,-94.255135,-0.001897,0.003971,0.100858,291.293701,14.839208,1.008583,-94.255135,0.100338,0.000000
137.110001,65.490639,-94.255135,-0.001910,0.003949,0.100303,291.316925,14.840391,1.003033,-94.255135,0.099722,0.000000
137.480011,65.476479,-94.344101,-0.001906,0.003925,0.099688,291.253937,14.837182,0.996876,-94.344101,0.099107,0.000000
137.850006,65.445946,-94.344101,-0.001901,0.003900,0.099072,291.118103,14.830263,0.990719,-94.344101,0.098491,0.000000
138.220001,65.414299,-94.433060,-0.001897,0.003877,0.098482,290.977325,14.823092,0.984822,-94.433060,0.097866,0.000000
138.590012,65.375191,-94.388580,-0.001888,0.003855,0.097918,290.803375,14.814230,0.979185,-94.388580,0.097251,0.000000
138.960007,65.267586,-94.433060,-0.001901,0.003832,0.097337,290.324707,14.789846,0.973374,-94.433060,0.096635,0.000000
139.330002,65.008415,-94.477539,-0.001910,0.003809,0.096748,289.171875,14.731118,0.967477,-94.477539,0.096019,0.000000
139.700012,64.375008,-94.566505,-0.001897,0.003786,0.096167,286.354340,14.587585,0.961667,-94.566505,0.095403,0.000000
140.070007,63.546852,-94.522018,-0.001884,0.003764,0.095612,282.670502,14.399922,0.956116,-94.522018,0.094788,0.000000
140.440002,62.313179,-94.522018,-0.001880,0.003738,0.094953,277.182861,14.120369,0.949525,-94.522018,0.094172,0.000000
140.810013,61.009132,-94.655464,-0.001876,0.003716,0.094398,271.382172,13.824867,0.943975,-94.655464,0.093556,0.000000
141.180008,59.511444,-94.610985,-0.001880,0.003695,0.093842,264.720123,13.485486,0.938425,-94.610985,0.092941,0.000000
141.550003,57.630592,-94.744423,-0.001888,0.003670,0.093209,256.353668,13.059279,0.932094,-94.744423,0.092316,0.000000
141.920013,55.682343,-94.699944,-0.001893,0.003648,0.092654,247.687424,12.617800,0.926544,-94.699944,0.091700,0.000000
142.290009,54.154121,-94.699944,-0.001884,0.003634,0.092299,240.889557,12.271499,0.922988,-94.699944,0.091085,0.000000
142.660004,51.053749,-94.744423,-0.001901,0.003601,0.091458,227.098419,11.568945,0.914576,-94.744423,0.090469,0.000000
143.030014,48.811699,-94.877869,-0.001897,0.003580,0.090937,217.125275,11.060889,0.909373,-94.877869,0.089853,0.000000
143.400009,45.996185,-94.877869,-0.001893,0.003551,0.090183,204.601257,10.422885,0.901828,-94.877869,0.089238,0.000000
143.770004,43.417511,-94.877869,-0.001901,0.003529,0.089636,193.130737,9.838549,0.896365,-94.877869,0.088622,0.000000
144.139999,41.315842,-94.877869,-0.001906,0.003511,0.089177,183.782043,9.362304,0.891768,-94.877869,0.088006,0.000000
144.510010,38.309677,-94.922348,-0.001914,0.003480,0.088396,170.409958,8.681097,0.883963,-94.922348,0.087390,0.000000
144.880005,35.634178,-95.011314,-0.001927,0.003458,0.087824,158.508743,8.074821,0.878239,-95.011314,0.086766,0.000000
145.250000,32.486885,-95.100273,-0.001919,0.003427,0.087052,144.508881,7.361633,0.870521,-95.100273,0.086150,0.000000
145.620010,30.439583,-95.011314,-0.001919,0.003409,0.086584,135.402023,6.897708,0.865838,-95.011314,0.085534,0.000000
145.990005,28.424301,-95.011314,-0.001932,0.003392,0.086150,126.437607,6.441039,0.861502,-95.011314,0.084919,0.000000
146.360001,25.650871,-95.011314,-0.001932,0.003364,0.085448,114.100777,5.812571,0.854477,-95.011314,0.084303,0.000000
146.730011,22.401924,-95.144753,-0.001927,0.003336,0.084737,99.648735,5.076349,0.847366,-95.144753,0.083687,0.000000
147.100006,20.048904,-95.144753,-0.001949,0.003312,0.084121,89.181984,4.543147,0.841209,-95.144753,0.083072,0.000000
147.470001,17.393143,-95.189232,-0.001949,0.003289,0.083540,77.368561,3.941342,0.835398,-95.189232,0.082456,0.000000
147.840012,14.807762,-95.144753,-0.001953,0.003265,0.082924,65.868217,3.355487,0.829241,-95.144753,0.081840,0.000000
148.210007,12.186630,-95.233719,-0.001953,0.003236,0.082196,54.208839,2.761530,0.821957,-95.233719,0.081216,0.000000
148.580002,8.685211,-95.233719,-0.001992,0.003208,0.081476,38.633747,1.968097,0.814758,-95.233719,0.080600,0.000000
148.950012,6.295326,-95.278198,-0.001975,0.003183,0.080843,28.003010,1.426541,0.808428,-95.278198,0.079984,0.000000
149.320007,4.499748,-95.322678,-0.001988,0.003169,0.080505,20.015881,1.019657,0.805046,-95.322678,0.079368,0.000000
149.690002,2.124382,-95.322678,-0.001979,0.003146,0.079906,9.449723,0.481392,0.799062,-95.322678,0.078753,0.000000
150.060013,-0.748840,-95.367157,-0.001988,0.003116,0.079152,-3.331008,-0.169690,0.791517,-95.367157,0.078137,0.000000
150.430008,-2.285625,-95.500603,-0.002009,0.003090,0.078484,-10.166970,-0.517930,0.784839,-95.500603,0.077521,0.000000
150.800003,-0.605850,-95.456123,-0.002013,0.003073,0.078042,-2.694956,-0.137288,0.780416,-95.456123,0.076906,0.000000
151.170013,-0.306465,-95.500603,-0.002026,0.003046,0.077357,-1.363225,-0.069446,0.773565,-95.500603,0.076290,0.000000
151.540009,-0.103149,-95.456123,-0.002044,0.003024,0.076819,-0.458832,-0.023374,0.768188,-95.456123,0.075665,0.000000
151.910004,-0.166084,-95.545082,-0.002078,0.002995,0.076073,-0.738780,-0.037635,0.760730,-95.545082,0.075050,0.000000
152.280014,-0.108360,-95.589561,-0.002100,0.002964,0.075293,-0.482011,-0.024555,0.752925,-95.589561,0.074434,0.000000
152.650009,-0.105011,-95.678528,-0.002108,0.002946,0.074824,-0.467112,-0.023796,0.748242,-95.678528,0.073818,0.000000
153.020004,-0.048042,-95.634048,-0.002104,0.002922,0.074208,-0.213703,-0.010887,0.742085,-95.634048,0.073203,0.000000
153.390015,0.011543,-95.723007,-0.002121,0.002906,0.073801,0.051347,0.002616,0.738009,-95.723007,0.073653,0.000000
153.400009,0.011909,-95.678528,-0.002121,0.002906,0.073801,0.052976,0.002699,0.738009,-95.678528,0.073653,0.000000