File: Data/compression 33/AutoNoHeating-12-33-reverse-1-1re_11152024_180004.csv
Time (sec),S:Load (lbs),S:HL1 (DIM),S:LVDT (in),S:Position (in),Ch:Position (mm),Ch:Load (N),Ch:Stress (MPa),Ch:Strain (mm/mm),Ch:HL1 (DIM),Set Point (),Cycles ()
0.110000,-0.078941,-684.383911,-0.014198,-0.008834,-0.224377,-0.351149,-0.017888,-2.243773,-684.383911,-0.224169,0.000000
0.510000,-0.075218,-684.339417,-0.014194,-0.008764,-0.222608,-0.334587,-0.017045,-2.226081,-684.339417,-0.221810,0.000000
0.910000,-0.087135,-684.428406,-0.014034,-0.008521,-0.216425,-0.387597,-0.019745,-2.164249,-684.428406,-0.215150,0.000000
1.310000,-0.138527,-684.383911,-0.013793,-0.008264,-0.209895,-0.616198,-0.031391,-2.098946,-684.383911,-0.208490,0.000000
1.710000,-0.154907,-684.428406,-0.013504,-0.008001,-0.203226,-0.689062,-0.035102,-2.032257,-684.428406,-0.201812,0.000000
2.110000,-0.097565,-684.383911,-0.013241,-0.007742,-0.196635,-0.433989,-0.022108,-1.966348,-684.383911,-0.195152,0.000000
2.510000,-0.048035,-684.428406,-0.012952,-0.007468,-0.189697,-0.213669,-0.010885,-1.896969,-684.428406,-0.188492,0.000000
2.910000,-0.063301,-684.383911,-0.012689,-0.007208,-0.183071,-0.281577,-0.014344,-1.830714,-684.383911,-0.181831,0.000000
3.310000,-0.071495,-684.472900,-0.012404,-0.006947,-0.176446,-0.318026,-0.016201,-1.764457,-684.472900,-0.175171,0.000000
3.710000,-0.075218,-684.383911,-0.012141,-0.006683,-0.169742,-0.334587,-0.017045,-1.697421,-684.383911,-0.168493,0.000000
4.110000,-0.042824,-684.472900,-0.011870,-0.006420,-0.163073,-0.190490,-0.009704,-1.630731,-684.472900,-0.161833,0.000000
4.510000,-0.051392,-684.472900,-0.011598,-0.006158,-0.156413,-0.228601,-0.011646,-1.564128,-684.472900,-0.155173,0.000000
4.910000,-0.048782,-684.428406,-0.011326,-0.005898,-0.149813,-0.216995,-0.011054,-1.498132,-684.428406,-0.148512,0.000000
5.310000,-0.077827,-684.517334,-0.011063,-0.005638,-0.143205,-0.346194,-0.017636,-1.432050,-684.517334,-0.141852,0.000000
5.710000,-0.084526,-684.517334,-0.010779,-0.005367,-0.136319,-0.375991,-0.019154,-1.363192,-684.517334,-0.135174,0.000000
6.110000,-0.106499,-684.472900,-0.010499,-0.005107,-0.129720,-0.473730,-0.024133,-1.297196,-684.472900,-0.128514,0.000000
6.510000,-0.076340,-684.472900,-0.010253,-0.004844,-0.123033,-0.339576,-0.017299,-1.230333,-684.472900,-0.121854,0.000000
6.910000,-0.080063,-684.517334,-0.009981,-0.004587,-0.116512,-0.356137,-0.018143,-1.165118,-684.517334,-0.115194,0.000000
7.310000,-0.089745,-684.472900,-0.009701,-0.004325,-0.109843,-0.399204,-0.020336,-1.098428,-684.472900,-0.108533,0.000000
7.710001,-0.119904,-684.561829,-0.009464,-0.004066,-0.103287,-0.533358,-0.027171,-1.032866,-684.561829,-0.101856,0.000000
8.110001,-0.148209,-684.517334,-0.009184,-0.003804,-0.096609,-0.659265,-0.033585,-0.966089,-684.517334,-0.095195,0.000000
8.510000,-0.076340,-684.606323,-0.008921,-0.003545,-0.090035,-0.339576,-0.017299,-0.900354,-684.606323,-0.088535,0.000000
8.910001,-0.038727,-684.517334,-0.008619,-0.003270,-0.083063,-0.172265,-0.008776,-0.830629,-684.517334,-0.081875,0.000000
9.310000,-0.054367,-684.606323,-0.008364,-0.003009,-0.076429,-0.241837,-0.012320,-0.764286,-684.606323,-0.075197,0.000000
9.710000,-0.048782,-684.561829,-0.008093,-0.002751,-0.069872,-0.216995,-0.011054,-0.698724,-684.561829,-0.068537,0.000000
10.110001,-0.072983,-684.650818,-0.007830,-0.002486,-0.063151,-0.324644,-0.016538,-0.631514,-684.650818,-0.061877,0.000000
10.510000,-0.043198,-684.606323,-0.007545,-0.002223,-0.056465,-0.192153,-0.009789,-0.564650,-684.606323,-0.055216,0.000000
10.910001,-0.039101,-684.695251,-0.007269,-0.001960,-0.049787,-0.173928,-0.008860,-0.497874,-684.695251,-0.048556,0.000000
11.310000,-0.036118,-684.606323,-0.007006,-0.001702,-0.043223,-0.160659,-0.008184,-0.432225,-684.606323,-0.041878,0.000000
11.710001,-0.069633,-684.650818,-0.006748,-0.001441,-0.036606,-0.309745,-0.015779,-0.366056,-684.650818,-0.035218,0.000000
12.110001,-0.102402,-684.606323,-0.006459,-0.001168,-0.029676,-0.455506,-0.023205,-0.296765,-684.606323,-0.028558,0.000000
12.510000,-0.113571,-684.650818,-0.006209,-0.000910,-0.023120,-0.505190,-0.025736,-0.231202,-684.650818,-0.021897,0.000000
12.910001,-0.065163,-684.650818,-0.005920,-0.000646,-0.016417,-0.289858,-0.014766,-0.164166,-684.650818,-0.015237,0.000000
13.310000,-0.057343,-684.695251,-0.005670,-0.000390,-0.009912,-0.255072,-0.012994,-0.099124,-684.695251,-0.008560,0.000000
13.710001,-0.074104,-684.650818,-0.005398,-0.000128,-0.003261,-0.329632,-0.016792,-0.032608,-684.650818,-0.001899,0.000000
14.110001,0.008194,-684.606323,-0.005131,0.000132,0.003356,0.036449,0.001857,0.033562,-684.606323,0.004761,0.000000
14.510000,0.078194,-684.739746,-0.005096,-0.000000,-0.000000,0.347823,0.017719,-0.000000,-684.739746,0.000217,0.000000
14.910001,0.149323,-684.650818,-0.005096,-0.000000,-0.000000,0.664220,0.033837,-0.000000,-684.650818,0.000581,0.000000
15.310000,0.150436,-684.650818,-0.005101,0.000002,0.000061,0.669175,0.034089,0.000607,-684.650818,0.001249,0.000000
15.710001,0.307205,-684.739746,-0.005079,0.000033,0.000841,1.366517,0.069614,0.008412,-684.739746,0.001917,0.000000
16.110001,0.566376,-684.695251,-0.005053,0.000065,0.001648,2.519365,0.128343,0.016477,-684.695251,0.002576,0.000000
16.510000,0.776024,-684.739746,-0.005014,0.000092,0.002342,3.451926,0.175850,0.023415,-684.739746,0.003243,0.000000
16.910002,1.048599,-684.695251,-0.004988,0.000116,0.002949,4.664402,0.237616,0.029486,-684.695251,0.003911,0.000000
17.310001,1.372566,-684.739746,-0.004971,0.000141,0.003590,6.105480,0.311028,0.035903,-684.739746,0.004579,0.000000
17.710001,1.648491,-684.784241,-0.004954,0.000164,0.004163,7.332854,0.373553,0.041627,-684.784241,0.005247,0.000000
18.110001,1.780685,-684.784241,-0.004928,0.000181,0.004596,7.920884,0.403509,0.045963,-684.784241,0.005914,0.000000
18.510000,2.205559,-684.784241,-0.004907,0.000211,0.005368,9.810816,0.499787,0.053681,-684.784241,0.006582,0.000000
18.910002,2.354507,-684.784241,-0.004898,0.000227,0.005776,10.473372,0.533539,0.057757,-684.784241,0.007250,0.000000
19.310001,2.944717,-684.784241,-0.004863,0.000265,0.006730,13.098757,0.667283,0.067297,-684.784241,0.007909,0.000000
19.710001,3.259750,-684.828735,-0.004855,0.000286,0.007276,14.500093,0.738670,0.072760,-684.828735,0.008577,0.000000
20.110001,3.659676,-684.828735,-0.004803,0.000318,0.008083,16.279051,0.829294,0.080825,-684.828735,0.009245,0.000000
20.510000,4.121414,-684.784241,-0.004786,0.000350,0.008880,18.332966,0.933926,0.088804,-684.784241,0.009912,0.000000
20.910002,4.478149,-684.828735,-0.004773,0.000373,0.009470,19.919804,1.014763,0.094701,-684.828735,0.010580,0.000000
21.310001,4.840469,-684.873230,-0.004734,0.000397,0.010095,21.531483,1.096866,0.100945,-684.873230,0.011248,0.000000
21.710001,5.349503,-684.873230,-0.004712,0.000428,0.010866,23.795776,1.212215,0.108663,-684.873230,0.011916,0.000000
22.110001,5.477600,-684.873230,-0.004691,0.000445,0.011300,24.365582,1.241242,0.112999,-684.873230,0.012583,0.000000
22.510000,5.902473,-684.873230,-0.004665,0.000471,0.011959,26.255514,1.337520,0.119590,-684.873230,0.013243,0.000000
22.910002,6.137444,-684.962158,-0.004648,0.000492,0.012488,27.300713,1.390765,0.124880,-684.962158,0.013910,0.000000
23.310001,6.954056,-684.917664,-0.004613,0.000533,0.013546,30.933186,1.575812,0.135461,-684.917664,0.014578,0.000000
23.710001,7.288818,-684.962158,-0.004583,0.000561,0.014240,32.422283,1.651670,0.142398,-684.962158,0.015246,0.000000
24.110001,7.616135,-684.962158,-0.004566,0.000587,0.014908,33.878258,1.725841,0.149076,-684.962158,0.015914,0.000000
24.510000,7.735664,-684.873230,-0.004536,0.000611,0.015515,34.409954,1.752927,0.155147,-684.873230,0.016581,0.000000
24.910002,8.173576,-684.962158,-0.004518,0.000637,0.016182,36.357883,1.852159,0.161824,-684.962158,0.017249,0.000000
25.310001,8.638664,-684.962158,-0.004480,0.000664,0.016859,38.426697,1.957549,0.168589,-684.962158,0.017917,0.000000
25.710001,8.933960,-684.962158,-0.004454,0.000689,0.017509,39.740238,2.024464,0.175093,-684.962158,0.018576,0.000000
26.110001,9.307823,-685.006653,-0.004411,0.000722,0.018333,41.403267,2.109183,0.183331,-685.006653,0.019244,0.000000
26.510002,9.545769,-684.917664,-0.004402,0.000749,0.019018,42.461700,2.163102,0.190183,-684.917664,0.019912,0.000000
26.910002,9.898773,-685.051147,-0.004381,0.000772,0.019599,44.031940,2.243094,0.195993,-685.051147,0.020579,0.000000
27.310001,10.101349,-684.962158,-0.004372,0.000796,0.020206,44.933044,2.288998,0.202064,-684.962158,0.021247,0.000000
27.710001,10.302429,-685.051147,-0.004320,0.000816,0.020727,45.827496,2.334564,0.207267,-685.051147,0.021915,0.000000
28.110001,10.589897,-685.051147,-0.004320,0.000840,0.021325,47.106216,2.399705,0.213251,-685.051147,0.022583,0.000000
28.510002,10.989456,-685.051147,-0.004286,0.000872,0.022140,48.883541,2.490247,0.221403,-685.051147,0.023250,0.000000
28.910002,11.091110,-685.051147,-0.004255,0.000891,0.022626,49.335724,2.513281,0.226259,-685.051147,0.023918,0.000000
29.310001,11.471306,-685.095581,-0.004221,0.000920,0.023363,51.026917,2.599435,0.233631,-685.095581,0.024577,0.000000
29.710001,11.806816,-685.140076,-0.004191,0.000948,0.024074,52.519341,2.675463,0.240742,-685.140076,0.025245,0.000000
30.110001,12.217911,-685.140076,-0.004174,0.000978,0.024837,54.347980,2.768618,0.248373,-685.140076,0.025913,0.000000
30.510002,12.371704,-685.140076,-0.004143,0.001001,0.025418,55.032089,2.803468,0.254184,-685.140076,0.026580,0.000000
30.910002,12.870308,-685.140076,-0.004100,0.001030,0.026173,57.249989,2.916453,0.261729,-685.140076,0.027248,0.000000
31.310001,12.764931,-685.095581,-0.004083,0.001052,0.026711,56.781246,2.892575,0.267105,-685.095581,0.027916,0.000000
31.710001,12.826744,-685.095581,-0.004053,0.001072,0.027240,57.056206,2.906582,0.272396,-685.095581,0.028584,0.000000
32.110001,13.566643,-685.140076,-0.004027,0.001110,0.028194,60.347443,3.074245,0.281935,-685.140076,0.029252,0.000000
32.510002,13.428123,-685.184570,-0.004001,0.001129,0.028670,59.731277,3.042856,0.286705,-685.184570,0.029911,0.000000
32.910000,13.882042,-685.229065,-0.003971,0.001159,0.029451,61.750408,3.145716,0.294510,-685.229065,0.030578,0.000000
33.310001,14.077911,-685.140076,-0.003945,0.001185,0.030101,62.621677,3.190100,0.301014,-685.140076,0.031246,0.000000
33.710003,14.383255,-685.184570,-0.003915,0.001211,0.030769,63.979912,3.259292,0.307692,-685.184570,0.031914,0.000000
34.110001,14.560883,-685.184570,-0.003889,0.001235,0.031376,64.770042,3.299543,0.313762,-685.184570,0.032582,0.000000
34.510002,15.011826,-685.184570,-0.003854,0.001266,0.032148,66.775932,3.401728,0.321481,-685.184570,0.033249,0.000000
34.910000,15.190186,-685.229065,-0.003820,0.001292,0.032807,67.569321,3.442145,0.328072,-685.229065,0.033917,0.000000
35.310001,15.270248,-685.229065,-0.003798,0.001317,0.033449,67.925461,3.460288,0.334489,-685.229065,0.034585,0.000000
35.710003,15.242691,-685.229065,-0.003773,0.001340,0.034039,67.802879,3.454043,0.340386,-685.229065,0.035244,0.000000
36.110001,15.703690,-685.229065,-0.003729,0.001368,0.034758,69.853500,3.558507,0.347584,-685.229065,0.035912,0.000000
36.510002,15.931580,-685.273560,-0.003717,0.001392,0.035357,70.867203,3.610147,0.353568,-685.273560,0.036580,0.000000
36.910000,16.518440,-685.273560,-0.003673,0.001424,0.036181,73.477692,3.743132,0.361807,-685.273560,0.037247,0.000000
37.310001,16.846504,-685.317993,-0.003630,0.001456,0.036970,74.936996,3.817472,0.369698,-685.317993,0.037915,0.000000
37.710003,16.515465,-685.273560,-0.003609,0.001478,0.037551,73.464455,3.742458,0.375509,-685.273560,0.038583,0.000000
38.110001,16.703880,-685.273560,-0.003566,0.001506,0.038245,74.302574,3.785153,0.382446,-685.273560,0.039251,0.000000
38.510002,17.194298,-685.317993,-0.003531,0.001533,0.038930,76.484055,3.896284,0.389298,-685.317993,0.039918,0.000000
38.910004,17.338776,-685.362488,-0.003505,0.001557,0.039537,77.126724,3.929023,0.395368,-685.362488,0.040577,0.000000
39.310001,17.473206,-685.317993,-0.003488,0.001579,0.040109,77.724701,3.959485,0.401092,-685.317993,0.041245,0.000000
39.710003,17.653061,-685.273560,-0.003454,0.001606,0.040794,78.524734,4.000241,0.407943,-685.273560,0.041913,0.000000
40.110001,17.593857,-685.317993,-0.003449,0.001628,0.041341,78.261383,3.986825,0.413406,-685.317993,0.042581,0.000000
40.510002,18.257790,-685.273560,-0.003415,0.001658,0.042121,81.214706,4.137274,0.421212,-685.273560,0.043249,0.000000
40.910004,18.743736,-685.362488,-0.003363,0.001685,0.042798,83.376305,4.247391,0.427976,-685.362488,0.043916,0.000000
41.310001,18.693466,-685.362488,-0.003341,0.001714,0.043526,83.152687,4.236000,0.435261,-685.362488,0.044584,0.000000
41.710003,18.866623,-685.362488,-0.003307,0.001738,0.044133,83.922928,4.275238,0.441331,-685.362488,0.045252,0.000000
42.110001,18.655113,-685.362488,-0.003272,0.001757,0.044619,82.982086,4.227309,0.446188,-685.362488,0.045920,0.000000
42.510002,19.581207,-685.406982,-0.003247,0.001790,0.045469,87.101562,4.437165,0.454686,-685.406982,0.046579,0.000000
42.910004,19.706696,-685.406982,-0.003216,0.001817,0.046154,87.659760,4.465601,0.461538,-685.406982,0.047246,0.000000
43.310001,19.799042,-685.406982,-0.003195,0.001841,0.046752,88.070534,4.486527,0.467521,-685.406982,0.047914,0.000000
43.710003,20.276794,-685.362488,-0.003152,0.001869,0.047481,90.195686,4.594788,0.474806,-685.362488,0.048582,0.000000
44.110001,19.892509,-685.406982,-0.003134,0.001889,0.047984,88.486298,4.507707,0.479836,-685.406982,0.049250,0.000000
44.510002,21.080002,-685.406982,-0.003109,0.001923,0.048851,93.768532,4.776796,0.488508,-685.406982,0.049918,0.000000
44.910004,20.951164,-685.540405,-0.003083,0.001950,0.049527,93.195435,4.747602,0.495273,-685.540405,0.050585,0.000000
45.310001,21.043884,-685.495911,-0.003040,0.001973,0.050108,93.607872,4.768612,0.501083,-685.495911,0.051253,0.000000
45.710003,21.403595,-685.495911,-0.002992,0.002004,0.050897,95.207947,4.850124,0.508975,-685.495911,0.051912,0.000000
46.110001,21.695908,-685.495911,-0.002979,0.002031,0.051591,96.508217,4.916363,0.515913,-685.495911,0.052580,0.000000
46.510002,21.987473,-685.451477,-0.002953,0.002055,0.052198,97.805161,4.982432,0.521983,-685.451477,0.053248,0.000000
46.910004,22.028435,-685.495911,-0.002919,0.002077,0.052762,97.987373,4.991715,0.527620,-685.495911,0.053915,0.000000
47.310001,21.456474,-685.540405,-0.002906,0.002090,0.053092,95.443161,4.862107,0.530915,-685.540405,0.054583,0.000000
47.710003,22.889359,-685.540405,-0.002854,0.002137,0.054288,101.816956,5.186802,0.542883,-685.540405,0.055251,0.000000
48.110001,22.941864,-685.540405,-0.002828,0.002163,0.054947,102.050507,5.198701,0.549474,-685.540405,0.055919,0.000000
48.510002,23.080391,-685.584900,-0.002802,0.002188,0.055580,102.666710,5.230092,0.555805,-685.584900,0.056586,0.000000
48.910004,23.093048,-685.584900,-0.002772,0.002208,0.056083,102.723007,5.232959,0.560835,-685.584900,0.057246,0.000000
49.310001,23.695175,-685.540405,-0.002746,0.002236,0.056795,105.401405,5.369403,0.567946,-685.540405,0.057913,0.000000
49.710003,23.467659,-685.584900,-0.002716,0.002262,0.057462,104.389359,5.317848,0.574624,-685.584900,0.058581,0.000000
50.110001,24.258949,-685.584900,-0.002677,0.002288,0.058113,107.909195,5.497157,0.581128,-685.584900,0.059249,0.000000
50.510002,24.650314,-685.584900,-0.002656,0.002318,0.058876,109.650078,5.585841,0.588759,-685.584900,0.059917,0.000000
50.910004,24.763512,-685.540405,-0.002634,0.002343,0.059518,110.153603,5.611492,0.595177,-685.540405,0.060584,0.000000
51.310001,24.605255,-685.629395,-0.002591,0.002362,0.059986,109.449638,5.575631,0.599860,-685.629395,0.061252,0.000000
51.710003,24.910599,-685.584900,-0.002570,0.002391,0.060740,110.807877,5.644823,0.607405,-685.584900,0.061920,0.000000
52.110001,25.792007,-685.584900,-0.002527,0.002421,0.061495,114.728577,5.844553,0.614950,-685.584900,0.062579,0.000000
52.510002,25.733543,-685.584900,-0.002488,0.002446,0.062128,114.468521,5.831305,0.621280,-685.584900,0.063247,0.000000
52.910004,25.638214,-685.629395,-0.002462,0.002471,0.062761,114.044472,5.809702,0.627611,-685.629395,0.063915,0.000000
53.310001,26.285774,-685.629395,-0.002436,0.002503,0.063568,116.924965,5.956442,0.635676,-685.629395,0.064582,0.000000
53.710003,25.795731,-685.629395,-0.002419,0.002520,0.064001,114.745140,5.845396,0.640013,-685.629395,0.065250,0.000000
54.110004,26.347954,-685.629395,-0.002376,0.002549,0.064756,117.201553,5.970531,0.647557,-685.629395,0.065918,0.000000
54.510002,26.643250,-685.629395,-0.002350,0.002575,0.065397,118.515091,6.037446,0.653975,-685.629395,0.066586,0.000000
54.910004,26.823853,-685.673889,-0.002307,0.002604,0.066143,119.318459,6.078372,0.661433,-685.673889,0.067253,0.000000
55.310001,26.978386,-685.629395,-0.002302,0.002627,0.066724,120.005852,6.113390,0.667243,-685.629395,0.067921,0.000000
55.710003,26.995140,-685.673889,-0.002272,0.002651,0.067323,120.080383,6.117186,0.673227,-685.673889,0.068580,0.000000
56.110004,26.825714,-685.629395,-0.002220,0.002678,0.068017,119.326736,6.078794,0.680165,-685.629395,0.069248,0.000000
56.510002,27.917511,-685.673889,-0.002186,0.002712,0.068875,124.183289,6.326199,0.688751,-685.673889,0.069916,0.000000
56.910004,27.714561,-685.673889,-0.002147,0.002733,0.069430,123.280525,6.280210,0.694301,-685.673889,0.070583,0.000000
57.310001,28.007622,-685.718323,-0.002126,0.002763,0.070185,124.584122,6.346618,0.701846,-685.718323,0.071251,0.000000
57.710003,27.790527,-685.762817,-0.002091,0.002784,0.070714,123.618439,6.297423,0.707136,-685.762817,0.071919,0.000000
58.110004,28.089912,-685.762817,-0.002052,0.002816,0.071537,124.950172,6.365265,0.715374,-685.762817,0.072587,0.000000
58.510002,28.251152,-685.762817,-0.002026,0.002839,0.072110,125.667404,6.401803,0.721098,-685.762817,0.073255,0.000000
58.910004,28.702469,-685.762817,-0.001979,0.002873,0.072968,127.674957,6.504073,0.729684,-685.762817,0.073914,0.000000
59.310001,28.365471,-685.807312,-0.001949,0.002898,0.073601,126.175919,6.427708,0.736014,-685.807312,0.074581,0.000000
59.710003,28.326370,-685.762817,-0.001906,0.002924,0.074278,126.001991,6.418847,0.742779,-685.762817,0.075249,0.000000
60.110004,27.817337,-685.762817,-0.001867,0.002947,0.074859,123.737694,6.303499,0.748589,-685.762817,0.075917,0.000000
60.510002,27.889954,-685.762817,-0.001819,0.002973,0.075509,124.060707,6.319953,0.755093,-685.762817,0.076585,0.000000
60.910004,27.888092,-685.762817,-0.001807,0.002993,0.076030,124.052429,6.319532,0.760297,-685.762817,0.077252,0.000000
61.310001,28.065712,-685.807312,-0.001750,0.003020,0.076715,124.842522,6.359781,0.767148,-685.807312,0.077920,0.000000
61.710003,28.294724,-685.807312,-0.001733,0.003046,0.077357,125.861214,6.411676,0.773565,-685.807312,0.078588,0.000000
62.110004,28.293602,-685.807312,-0.001681,0.003070,0.077990,125.856224,6.411422,0.779896,-685.807312,0.079247,0.000000
62.510002,28.578094,-685.896240,-0.001647,0.003103,0.078813,127.121712,6.475889,0.788135,-685.896240,0.079915,0.000000
62.910004,28.613846,-685.851807,-0.001608,0.003129,0.079481,127.280746,6.483990,0.794812,-685.851807,0.080583,0.000000
63.310001,28.259720,-685.896240,-0.001582,0.003155,0.080140,125.705513,6.403744,0.801403,-685.896240,0.081250,0.000000
63.710003,27.650146,-685.851807,-0.001544,0.003170,0.080513,122.993996,6.265613,0.805132,-685.851807,0.081918,0.000000
64.110001,29.188789,-685.896240,-0.001513,0.003211,0.081554,129.838226,6.614275,0.815539,-685.896240,0.082586,0.000000
64.510002,28.251526,-685.851807,-0.001466,0.003226,0.081944,125.669060,6.401887,0.819442,-685.851807,0.083254,0.000000
64.910004,27.641953,-685.896240,-0.001444,0.003252,0.082603,122.957542,6.263756,0.826033,-685.896240,0.083921,0.000000
65.310005,28.785881,-685.896240,-0.001397,0.003279,0.083288,128.045990,6.522974,0.832884,-685.896240,0.084581,0.000000
65.710007,28.773590,-685.896240,-0.001371,0.003302,0.083861,127.991318,6.520188,0.838607,-685.896240,0.085248,0.000000
66.110001,29.787186,-685.896240,-0.001332,0.003340,0.084823,132.500015,6.749873,0.848233,-685.896240,0.085916,0.000000
66.510002,29.934273,-685.940735,-0.001289,0.003367,0.085517,133.154297,6.783203,0.855171,-685.940735,0.086584,0.000000
66.910004,30.286537,-685.985229,-0.001259,0.003396,0.086263,134.721252,6.863028,0.862629,-685.985229,0.087252,0.000000
67.310005,29.617012,-685.940735,-0.001216,0.003413,0.086688,131.743042,6.711311,0.866879,-685.940735,0.087919,0.000000
67.710007,30.125305,-685.940735,-0.001199,0.003441,0.087408,134.004044,6.826492,0.874077,-685.940735,0.088587,0.000000
68.110001,30.564331,-685.985229,-0.001160,0.003471,0.088162,135.956940,6.925976,0.881622,-685.985229,0.089255,0.000000
68.510002,30.197914,-686.029724,-0.001121,0.003487,0.088561,134.327026,6.842945,0.885611,-686.029724,0.089923,0.000000
68.910004,31.771935,-685.940735,-0.001087,0.003527,0.089593,141.328629,7.199623,0.895931,-685.940735,0.090582,0.000000
69.310005,31.717567,-685.985229,-0.001048,0.003552,0.090226,141.086792,7.187304,0.902262,-685.985229,0.091249,0.000000
69.710007,31.665436,-686.029724,-0.001018,0.003578,0.090877,140.854889,7.175490,0.908766,-686.029724,0.091917,0.000000
70.110001,31.560051,-685.985229,-0.000987,0.003597,0.091362,140.386124,7.151610,0.913622,-685.985229,0.092585,0.000000
70.510002,31.925728,-686.029724,-0.000957,0.003628,0.092160,142.012726,7.234473,0.921601,-686.029724,0.093253,0.000000
70.910004,32.784790,-686.029724,-0.000923,0.003653,0.092784,145.834030,7.429140,0.927845,-686.029724,0.093921,0.000000
71.310005,32.339058,-686.074219,-0.000901,0.003669,0.093192,143.851318,7.328135,0.931921,-686.074219,0.094588,0.000000
71.710007,33.701569,-686.029724,-0.000854,0.003704,0.094094,149.912064,7.636885,0.940940,-686.029724,0.095256,0.000000
72.110001,33.576820,-686.074219,-0.000845,0.003724,0.094597,149.357162,7.608616,0.945970,-686.074219,0.095915,0.000000
72.510002,33.996490,-686.118652,-0.000806,0.003749,0.095230,151.223938,7.703715,0.952300,-686.118652,0.096583,0.000000
72.910004,35.223457,-686.074219,-0.000785,0.003782,0.096063,156.681763,7.981749,0.960626,-686.074219,0.097251,0.000000
73.310005,36.114166,-686.118652,-0.000742,0.003812,0.096817,160.643829,8.183587,0.968171,-686.118652,0.097918,0.000000
73.710007,37.102074,-686.118652,-0.000724,0.003842,0.097598,165.038269,8.407450,0.975976,-686.118652,0.098586,0.000000
74.110001,37.280815,-686.118652,-0.000698,0.003861,0.098057,165.833344,8.447953,0.980572,-686.118652,0.099254,0.000000
74.510002,37.305389,-686.163147,-0.000677,0.003885,0.098682,165.942657,8.453522,0.986816,-686.163147,0.099922,0.000000
74.910004,39.125916,-686.163147,-0.000660,0.003914,0.099427,174.040771,8.866059,0.994274,-686.163147,0.100590,0.000000
75.310005,39.474457,-686.207642,-0.000629,0.003936,0.099965,175.591156,8.945040,0.999651,-686.207642,0.101249,0.000000
75.710007,41.147156,-686.207642,-0.000604,0.003970,0.100850,183.031693,9.324079,1.008497,-686.207642,0.101916,0.000000
76.110001,42.235970,-686.163147,-0.000582,0.003993,0.101422,187.874969,9.570807,1.014220,-686.163147,0.102584,0.000000
76.510002,43.255157,-686.163147,-0.000560,0.004020,0.102098,192.408554,9.801759,1.020985,-686.163147,0.103252,0.000000
76.910004,43.169884,-686.207642,-0.000543,0.004035,0.102480,192.029236,9.782435,1.024801,-686.207642,0.103920,0.000000
77.310005,45.252937,-686.207642,-0.000526,0.004068,0.103330,201.295120,10.254461,1.033299,-686.207642,0.104587,0.000000
77.710007,47.063408,-686.252136,-0.000504,0.004103,0.104206,209.348495,10.664721,1.042058,-686.252136,0.105255,0.000000
78.110001,47.525894,-686.296570,-0.000483,0.004119,0.104613,211.405731,10.769522,1.046134,-686.296570,0.105923,0.000000
78.510002,48.884682,-686.296570,-0.000474,0.004151,0.105429,217.449921,11.077427,1.054286,-686.296570,0.106582,0.000000
78.910004,50.094894,-686.252136,-0.000448,0.004173,0.105984,222.833221,11.351665,1.059837,-686.252136,0.107250,0.000000
79.310005,52.031601,-686.296570,-0.000431,0.004207,0.106868,231.448120,11.790529,1.068682,-686.296570,0.107918,0.000000
79.710007,53.430237,-686.341064,-0.000418,0.004231,0.107467,237.669571,12.107465,1.074666,-686.341064,0.108585,0.000000
80.110001,55.340874,-686.341064,-0.000388,0.004262,0.108264,246.168503,12.540421,1.082645,-686.341064,0.109253,0.000000
80.510002,56.825897,-686.341064,-0.000388,0.004289,0.108950,252.774216,12.876932,1.089496,-686.341064,0.109921,0.000000
80.910004,57.981743,-686.252136,-0.000371,0.004311,0.109496,257.915680,13.138850,1.094959,-686.252136,0.110589,0.000000
81.310005,59.562088,-686.296570,-0.000362,0.004336,0.110129,264.945404,13.496963,1.101290,-686.296570,0.111256,0.000000
81.710007,60.878426,-686.296570,-0.000328,0.004360,0.110745,270.800751,13.795249,1.107447,-686.296570,0.111924,0.000000
82.110001,61.733398,-686.341064,-0.000323,0.004379,0.111230,274.603882,13.988989,1.112304,-686.341064,0.112583,0.000000
82.510002,63.965775,-686.430054,-0.000332,0.004408,0.111959,284.533966,14.494852,1.119588,-686.430054,0.113251,0.000000
82.910004,65.725967,-686.430054,-0.000293,0.004437,0.112705,292.363708,14.893717,1.127046,-686.430054,0.113919,0.000000
83.310005,65.649261,-686.341064,-0.000297,0.004433,0.112592,292.022491,14.876335,1.125919,-686.341064,292.030792,0.000000
83.710007,64.652054,-686.430054,-0.000280,0.004432,0.112566,287.586700,14.650364,1.125659,-686.430054,294.500458,0.000000
84.110001,66.137817,-686.430054,-0.000272,0.004417,0.112202,294.195709,14.987043,1.122017,-686.430054,294.500458,0.000000
84.510002,65.464188,-686.430054,-0.000272,0.004418,0.112210,291.199249,14.834396,1.122103,-686.430054,294.500458,0.000000
84.910004,64.956650,-686.474487,-0.000267,0.004445,0.112895,288.941620,14.719388,1.128954,-686.474487,294.500458,0.000000
85.310005,65.305191,-686.430054,-0.000259,0.004458,0.113225,290.492004,14.798368,1.132250,-686.430054,294.500458,0.000000
85.710007,64.964478,-686.385559,-0.000254,0.004458,0.113234,288.976440,14.721162,1.132336,-686.385559,294.500458,0.000000
86.110001,65.330887,-686.474487,-0.000254,0.004467,0.113450,290.606293,14.804191,1.134505,-686.474487,294.500458,0.000000
86.510002,65.081024,-686.518982,-0.000246,0.004467,0.113450,289.494843,14.747571,1.134505,-686.518982,294.500458,0.000000
86.910004,65.224380,-686.518982,-0.000250,0.004475,0.113676,290.132538,14.780056,1.136759,-686.518982,294.500458,0.000000
87.310005,65.289551,-686.474487,-0.000246,0.004474,0.113641,290.422424,14.794824,1.136413,-686.474487,294.500458,0.000000
87.710007,65.085861,-686.518982,-0.000246,0.004474,0.113641,289.516357,14.748668,1.136413,-686.518982,294.500458,0.000000
88.110001,64.885529,-686.518982,-0.000241,0.004474,0.113641,288.625244,14.703271,1.136413,-686.518982,294.500458,0.000000
88.510002,64.688171,-686.518982,-0.000241,0.004474,0.113641,287.747345,14.658549,1.136413,-686.518982,294.500458,0.000000
88.910004,64.499756,-686.518982,-0.000229,0.004474,0.113641,286.909241,14.615853,1.136413,-686.518982,294.500458,0.000000
89.310005,64.322128,-686.563477,-0.000241,0.004474,0.113641,286.119110,14.575603,1.136413,-686.563477,294.500458,0.000000
89.710007,66.395874,-686.518982,-0.000224,0.004443,0.112861,295.343597,15.045521,1.128607,-686.518982,294.500458,0.000000
90.110001,66.235001,-686.607971,-0.000224,0.004443,0.112861,294.627991,15.009066,1.128607,-686.607971,294.500458,0.000000
90.510002,66.052536,-686.607971,-0.000216,0.004443,0.112861,293.816345,14.967719,1.128607,-686.607971,294.500458,0.000000
90.910004,65.839172,-686.563477,-0.000220,0.004444,0.112869,292.867279,14.919370,1.128694,-686.563477,294.500458,0.000000
91.310005,65.750183,-686.652466,-0.000224,0.004444,0.112887,292.471436,14.899204,1.128868,-686.652466,294.500458,0.000000
91.710007,65.578888,-686.563477,-0.000207,0.004450,0.113026,291.709473,14.860388,1.130255,-686.563477,294.500458,0.000000
92.110001,65.470520,-686.518982,-0.000224,0.004458,0.113234,291.227417,14.835832,1.132336,-686.518982,294.500458,0.000000
92.510002,65.313385,-686.607971,-0.000216,0.004462,0.113346,290.528442,14.800224,1.133464,-686.607971,294.500458,0.000000
92.910004,65.243378,-686.607971,-0.000211,0.004470,0.113546,290.217041,14.784361,1.135459,-686.607971,294.500458,0.000000
93.310005,65.152527,-686.607971,-0.000224,0.004475,0.113659,289.812927,14.763774,1.136586,-686.607971,294.500458,0.000000
93.710007,65.030014,-686.696899,-0.000220,0.004475,0.113659,289.267944,14.736012,1.136586,-686.696899,294.500458,0.000000
94.110008,65.120865,-686.652466,-0.000216,0.004490,0.114058,289.672089,14.756599,1.140575,-686.652466,294.500458,0.000000
94.510002,65.123474,-686.607971,-0.000216,0.004491,0.114075,289.683685,14.757190,1.140749,-686.607971,294.500458,0.000000
94.910004,65.097778,-686.607971,-0.000216,0.004492,0.114092,289.569366,14.751368,1.140922,-686.607971,294.500458,0.000000
95.310005,65.304077,-686.652466,-0.000211,0.004496,0.114196,290.487030,14.798116,1.141963,-686.652466,294.500458,0.000000
95.710007,65.294022,-686.696899,-0.000233,0.004496,0.114196,290.442322,14.795836,1.141963,-686.696899,294.500458,0.000000
96.110008,65.229233,-686.652466,-0.000216,0.004496,0.114196,290.154114,14.781156,1.141963,-686.652466,294.500458,0.000000
96.510002,65.155502,-686.696899,-0.000216,0.004496,0.114196,289.826141,14.764448,1.141963,-686.696899,294.500458,0.000000
96.910004,65.082138,-686.741394,-0.000207,0.004496,0.114196,289.499817,14.747823,1.141963,-686.741394,294.500458,0.000000
97.310005,65.019577,-686.696899,-0.000211,0.004497,0.114214,289.221527,14.733647,1.142136,-686.696899,294.500458,0.000000
97.710007,65.274658,-686.696899,-0.000198,0.004502,0.114344,290.356171,14.791450,1.143437,-686.696899,294.500458,0.000000
98.110008,65.330139,-686.741394,-0.000207,0.004502,0.114344,290.602966,14.804021,1.143437,-686.741394,294.500458,0.000000
98.510002,65.307800,-686.741394,-0.000203,0.004502,0.114344,290.503601,14.798959,1.143437,-686.741394,294.500458,0.000000
98.910004,65.282104,-686.785889,-0.000224,0.004502,0.114344,290.389313,14.793136,1.143437,-686.785889,294.500458,0.000000
99.310005,65.218430,-686.830383,-0.000190,0.004502,0.114344,290.106049,14.778708,1.143437,-686.830383,294.500458,0.000000
99.710007,65.169647,-686.785889,-0.000203,0.004502,0.114344,289.889069,14.767653,1.143437,-686.785889,294.500458,0.000000
100.110008,65.090698,-686.741394,-0.000207,0.004502,0.114344,289.537872,14.749763,1.143437,-686.741394,294.500458,0.000000
100.510002,65.054214,-686.785889,-0.000198,0.004502,0.114344,289.375610,14.741495,1.143437,-686.785889,294.500458,0.000000
100.910004,64.990540,-686.785889,-0.000198,0.004502,0.114344,289.092346,14.727067,1.143437,-686.785889,294.500458,0.000000
101.310005,64.953674,-686.830383,-0.000190,0.004502,0.114344,288.928375,14.718713,1.143437,-686.830383,294.500458,0.000000
101.710007,64.906006,-686.830383,-0.000207,0.004502,0.114344,288.716339,14.707911,1.143437,-686.830383,294.500458,0.000000
102.110008,65.498077,-686.874817,-0.000194,0.004516,0.114708,291.350006,14.842077,1.147079,-686.874817,294.500458,0.000000
102.510002,65.883118,-686.874817,-0.000194,0.004514,0.114656,293.062744,14.929328,1.146559,-686.874817,294.500458,0.000000
102.910004,65.849976,-686.874817,-0.000216,0.004514,0.114656,292.915314,14.921818,1.146559,-686.874817,294.500458,0.000000
103.310005,65.864120,-686.874817,-0.000194,0.004514,0.114656,292.978241,14.925023,1.146559,-686.874817,294.500458,0.000000
103.710007,65.844009,-686.874817,-0.000203,0.004514,0.114656,292.888794,14.920465,1.146559,-686.874817,294.500458,0.000000
104.110008,65.850342,-686.874817,-0.000190,0.004514,0.114656,292.916962,14.921901,1.146559,-686.874817,294.500458,0.000000
104.510002,65.803421,-686.919312,-0.000194,0.004514,0.114656,292.708221,14.911268,1.146559,-686.919312,294.500458,0.000000
104.910004,65.762100,-686.874817,-0.000198,0.004514,0.114656,292.524445,14.901905,1.146559,-686.874817,294.500458,0.000000
105.310005,65.730072,-686.919312,-0.000203,0.004514,0.114656,292.381958,14.894648,1.146559,-686.919312,294.500458,0.000000
105.710007,65.674210,-686.919312,-0.000177,0.004514,0.114656,292.133484,14.881989,1.146559,-686.919312,294.500458,0.000000
106.110008,65.600479,-686.963806,-0.000207,0.004514,0.114656,291.805511,14.865281,1.146559,-686.963806,294.500458,0.000000
106.510002,65.588196,-686.919312,-0.000181,0.004514,0.114656,291.750854,14.862498,1.146559,-686.919312,294.500458,0.000000
106.910004,65.550217,-686.874817,-0.000194,0.004514,0.114656,291.581940,14.853891,1.146559,-686.874817,294.500458,0.000000
107.310005,65.523773,-686.963806,-0.000185,0.004514,0.114656,291.464294,14.847898,1.146559,-686.963806,294.500458,0.000000
107.710007,65.497711,-686.963806,-0.000177,0.004514,0.114656,291.348358,14.841993,1.146559,-686.963806,294.500458,0.000000
108.110008,65.436264,-687.008301,-0.000181,0.004514,0.114656,291.075043,14.828069,1.146559,-687.008301,294.500458,0.000000
108.510002,65.356949,-686.963806,-0.000181,0.004514,0.114665,290.722229,14.810097,1.146646,-686.963806,294.500458,0.000000
108.910004,65.328644,-687.052795,-0.000172,0.004514,0.114665,290.596313,14.803682,1.146646,-687.052795,294.500458,0.000000
109.310005,65.305557,-687.008301,-0.000168,0.004514,0.114665,290.493622,14.798450,1.146646,-687.008301,294.500458,0.000000
109.710007,65.282104,-687.052795,-0.000172,0.004515,0.114673,290.389313,14.793136,1.146733,-687.052795,294.500458,0.000000
110.110008,65.256409,-687.052795,-0.000181,0.004515,0.114673,290.274994,14.787313,1.146733,-687.052795,294.500458,0.000000
110.510002,65.235931,-687.097229,-0.000185,0.004515,0.114673,290.183929,14.782673,1.146733,-687.097229,294.500458,0.000000
110.910004,65.210983,-687.052795,-0.000160,0.004515,0.114673,290.072937,14.777020,1.146733,-687.052795,294.500458,0.000000
111.310005,65.154007,-687.097229,-0.000177,0.004515,0.114673,289.819489,14.764109,1.146733,-687.097229,294.500458,0.000000
111.710007,65.116776,-687.097229,-0.000172,0.004515,0.114673,289.653870,14.755672,1.146733,-687.097229,294.500458,0.000000
112.110008,65.075439,-687.052795,-0.000164,0.004515,0.114673,289.470001,14.746305,1.146733,-687.052795,294.500458,0.000000
112.510002,65.063156,-687.097229,-0.000172,0.004515,0.114673,289.415375,14.743522,1.146733,-687.097229,294.500458,0.000000
112.910004,65.006180,-687.097229,-0.000168,0.004515,0.114673,289.161926,14.730611,1.146733,-687.097229,294.500458,0.000000
113.310005,64.976761,-687.186218,-0.000190,0.004515,0.114673,289.031067,14.723944,1.146733,-687.186218,294.500458,0.000000
113.710007,64.976013,-687.141724,-0.000181,0.004515,0.114673,289.027740,14.723775,1.146733,-687.141724,294.500458,0.000000
114.110008,64.954422,-687.097229,-0.000172,0.004515,0.114673,288.931702,14.718883,1.146733,-687.097229,294.500458,0.000000
114.510002,64.910110,-687.141724,-0.000168,0.004515,0.114673,288.734589,14.708841,1.146733,-687.141724,294.500458,0.000000
114.910004,64.863190,-687.186218,-0.000181,0.004515,0.114673,288.525879,14.698209,1.146733,-687.186218,294.500458,0.000000
115.310005,64.849030,-687.186218,-0.000168,0.004515,0.114673,288.462891,14.695001,1.146733,-687.186218,294.500458,0.000000
115.710007,64.811050,-687.186218,-0.000164,0.004515,0.114673,288.293945,14.686394,1.146733,-687.186218,294.500458,0.000000
116.110008,64.782013,-687.186218,-0.000172,0.004515,0.114673,288.164795,14.679813,1.146733,-687.186218,294.500458,0.000000
116.510002,64.753342,-687.186218,-0.000172,0.004515,0.114673,288.037262,14.673317,1.146733,-687.186218,294.500458,0.000000
116.910004,64.733231,-687.186218,-0.000177,0.004515,0.114673,287.947784,14.668760,1.146733,-687.186218,294.500458,0.000000
117.310005,64.707169,-687.230713,-0.000181,0.004515,0.114673,287.831848,14.662854,1.146733,-687.230713,294.500458,0.000000
117.710007,64.690399,-687.230713,-0.000181,0.004515,0.114673,287.757263,14.659055,1.146733,-687.230713,294.500458,0.000000
118.110008,64.663223,-687.275146,-0.000185,0.004515,0.114673,287.636383,14.652895,1.146733,-687.275146,294.500458,0.000000
118.510002,64.628220,-687.319641,-0.000181,0.004515,0.114673,287.480682,14.644963,1.146733,-687.319641,294.500458,0.000000
118.910004,66.279312,-687.319641,-0.000172,0.004527,0.114985,294.825104,15.019107,1.149855,-687.319641,294.500458,0.000000
119.310005,66.253250,-687.275146,-0.000155,0.004527,0.114977,294.709167,15.013202,1.149768,-687.275146,294.500458,0.000000
119.710007,66.224579,-687.364136,-0.000181,0.004527,0.114977,294.581635,15.006704,1.149768,-687.364136,294.500458,0.000000
120.110008,66.191071,-687.319641,-0.000172,0.004527,0.114977,294.432587,14.999110,1.149768,-687.319641,294.500458,0.000000
120.510002,66.147873,-687.319641,-0.000160,0.004527,0.114977,294.240448,14.989323,1.149768,-687.319641,294.500458,0.000000
120.910004,66.145630,-687.364136,-0.000177,0.004527,0.114977,294.230469,14.988814,1.149768,-687.364136,294.500458,0.000000
121.310005,66.110626,-687.364136,-0.000168,0.004527,0.114977,294.074738,14.980883,1.149768,-687.364136,294.500458,0.000000
121.710007,66.077499,-687.319641,-0.000160,0.004527,0.114977,293.927399,14.973375,1.149768,-687.319641,294.500458,0.000000
122.110008,66.057007,-687.364136,-0.000177,0.004527,0.114977,293.836243,14.968732,1.149768,-687.364136,294.500458,0.000000
122.510002,66.022385,-687.364136,-0.000164,0.004527,0.114977,293.682220,14.960886,1.149768,-687.364136,294.500458,0.000000
122.910004,65.997437,-687.408630,-0.000160,0.004527,0.114977,293.571259,14.955233,1.149768,-687.408630,294.500458,0.000000
123.310005,65.945679,-687.364136,-0.000177,0.004527,0.114977,293.341034,14.943504,1.149768,-687.364136,294.500458,0.000000
123.710007,65.932266,-687.453125,-0.000172,0.004527,0.114977,293.281372,14.940465,1.149768,-687.453125,294.500458,0.000000
124.110008,65.883865,-687.408630,-0.000160,0.004527,0.114977,293.066071,14.929498,1.149768,-687.408630,294.500458,0.000000
124.510002,65.854065,-687.408630,-0.000164,0.004527,0.114977,292.933502,14.922744,1.149768,-687.408630,294.500458,0.000000
124.910004,65.841034,-687.453125,-0.000155,0.004527,0.114977,292.875549,14.919792,1.149768,-687.453125,294.500458,0.000000
125.310005,65.842896,-687.408630,-0.000172,0.004527,0.114977,292.883820,14.920213,1.149768,-687.408630,294.500458,0.000000
125.710007,65.801193,-687.453125,-0.000177,0.004527,0.114977,292.698334,14.910763,1.149768,-687.453125,294.500458,0.000000
126.110008,65.784439,-687.453125,-0.000168,0.004527,0.114977,292.623810,14.906966,1.149768,-687.453125,294.500458,0.000000
126.510010,65.772141,-687.542053,-0.000168,0.004527,0.114977,292.569092,14.904180,1.149768,-687.542053,294.500458,0.000000
126.910004,65.750916,-687.453125,-0.000160,0.004527,0.114977,292.474670,14.899371,1.149768,-687.453125,294.500458,0.000000
127.310005,65.723740,-687.497559,-0.000177,0.004527,0.114977,292.353790,14.893212,1.149768,-687.497559,294.500458,0.000000
127.710007,65.665283,-687.497559,-0.000177,0.004527,0.114977,292.093781,14.879966,1.149768,-687.497559,294.500458,0.000000
128.110001,65.647034,-687.497559,-0.000177,0.004527,0.114977,292.012604,14.875831,1.149768,-687.497559,294.500458,0.000000
128.510010,65.630646,-687.497559,-0.000172,0.004527,0.114977,291.939697,14.872117,1.149768,-687.497559,294.500458,0.000000
128.910004,65.598618,-687.542053,-0.000185,0.004527,0.114977,291.797211,14.864860,1.149768,-687.542053,294.500458,0.000000
129.310013,65.590424,-687.542053,-0.000181,0.004527,0.114977,291.760773,14.863003,1.149768,-687.542053,294.500458,0.000000
129.710007,65.563995,-687.542053,-0.000177,0.004527,0.114977,291.643219,14.857014,1.149768,-687.542053,294.500458,0.000000
130.110001,65.553558,-687.542053,-0.000168,0.004527,0.114977,291.596802,14.854649,1.149768,-687.542053,294.500458,0.000000
130.510010,65.536804,-687.542053,-0.000172,0.004527,0.114977,291.522278,14.850852,1.149768,-687.542053,294.500458,0.000000
130.910004,65.502182,-687.542053,-0.000185,0.004527,0.114977,291.368256,14.843006,1.149768,-687.542053,294.500458,0.000000
131.310013,65.479095,-687.586548,-0.000177,0.004527,0.114977,291.265564,14.837775,1.149768,-687.586548,294.500458,0.000000
131.710007,65.470520,-687.586548,-0.000168,0.004527,0.114977,291.227417,14.835832,1.149768,-687.586548,294.500458,0.000000
132.110001,65.431793,-687.586548,-0.000172,0.004527,0.114977,291.055145,14.827056,1.149768,-687.586548,294.500458,0.000000
132.510010,65.415039,-687.586548,-0.000172,0.004527,0.114985,290.980621,14.823260,1.149855,-687.586548,294.500458,0.000000
132.910004,65.388611,-687.631042,-0.000181,0.004527,0.114985,290.863068,14.817271,1.149855,-687.631042,294.500458,0.000000
133.310013,65.350250,-687.675476,-0.000172,0.004528,0.115003,290.692444,14.808578,1.150028,-687.675476,294.500458,0.000000
133.710007,65.333862,-687.675476,-0.000177,0.004528,0.115003,290.619537,14.804865,1.150028,-687.675476,294.500458,0.000000
134.110001,65.325302,-687.631042,-0.000168,0.004528,0.115003,290.581451,14.802925,1.150028,-687.631042,294.500458,0.000000
134.510010,65.299606,-687.631042,-0.000168,0.004528,0.115003,290.467163,14.797102,1.150028,-687.631042,294.500458,0.000000
134.910004,65.285461,-687.719971,-0.000168,0.004528,0.115003,290.404236,14.793897,1.150028,-687.719971,294.500458,0.000000
135.310013,65.269821,-687.631042,-0.000177,0.004528,0.115003,290.334656,14.790353,1.150028,-687.631042,294.500458,0.000000
135.710007,65.257523,-687.675476,-0.000172,0.004528,0.115003,290.279968,14.787565,1.150028,-687.675476,294.500458,0.000000
136.110001,65.244873,-687.586548,-0.000172,0.004528,0.115003,290.223694,14.784699,1.150028,-687.586548,294.500458,0.000000
136.510010,65.228104,-687.675476,-0.000177,0.004528,0.115003,290.149109,14.780899,1.150028,-687.675476,294.500458,0.000000
136.910004,65.212479,-687.675476,-0.000168,0.004528,0.115003,290.079590,14.777359,1.150028,-687.675476,294.500458,0.000000
137.310013,65.178207,-687.675476,-0.000164,0.004528,0.115011,289.927155,14.769593,1.150115,-687.675476,294.500458,0.000000
137.710007,65.154755,-687.675476,-0.000160,0.004528,0.115011,289.822815,14.764278,1.150115,-687.675476,294.500458,0.000000
138.110001,65.133163,-687.719971,-0.000177,0.004528,0.115011,289.726776,14.759386,1.150115,-687.719971,294.500458,0.000000
138.510010,65.113800,-687.764465,-0.000168,0.004528,0.115011,289.640656,14.754998,1.150115,-687.764465,294.500458,0.000000
138.910004,65.220291,-687.719971,-0.000177,0.004532,0.115107,290.114349,14.779129,1.151069,-687.719971,294.500458,0.000000
139.310013,65.247849,-687.719971,-0.000172,0.004532,0.115107,290.236938,14.785374,1.151069,-687.719971,294.500458,0.000000
139.710007,65.247101,-687.719971,-0.000172,0.004532,0.115107,290.233612,14.785204,1.151069,-687.719971,294.500458,0.000000
140.110001,65.246353,-687.719971,-0.000155,0.004532,0.115107,290.230286,14.785034,1.151069,-687.719971,294.500458,0.000000
140.510010,65.243378,-687.719971,-0.000160,0.004532,0.115107,290.217041,14.784361,1.151069,-687.719971,294.500458,0.000000
140.910004,65.250458,-687.764465,-0.000160,0.004532,0.115107,290.248535,14.785965,1.151069,-687.764465,294.500458,0.000000
141.310013,65.249710,-687.808960,-0.000160,0.004532,0.115107,290.245209,14.785795,1.151069,-687.808960,294.500458,0.000000
141.710007,65.236679,-687.853455,-0.000160,0.004532,0.115107,290.187256,14.782843,1.151069,-687.853455,294.500458,0.000000
142.110001,65.229599,-687.808960,-0.000164,0.004532,0.115107,290.155762,14.781239,1.151069,-687.808960,294.500458,0.000000
142.510010,65.222519,-687.808960,-0.000168,0.004532,0.115107,290.124268,14.779634,1.151069,-687.808960,294.500458,0.000000
142.910004,65.216568,-687.853455,-0.000155,0.004532,0.115107,290.097778,14.778286,1.151069,-687.853455,294.500458,0.000000
143.310013,65.184174,-687.808960,-0.000155,0.004532,0.115107,289.953674,14.770945,1.151069,-687.808960,294.500458,0.000000
143.710007,65.196838,-687.853455,-0.000168,0.004529,0.115037,290.010010,14.773814,1.150375,-687.853455,0.115107,0.000000
144.110001,65.151398,-687.764465,-0.000172,0.004519,0.114777,289.807892,14.763517,1.147773,-687.764465,0.114500,0.000000
144.510010,65.051239,-687.897888,-0.000151,0.004501,0.114318,289.362366,14.740822,1.143177,-687.897888,0.113841,0.000000
144.910004,65.026657,-687.897888,-0.000168,0.004472,0.113581,289.253021,14.735251,1.135805,-687.897888,0.113173,0.000000
145.310013,65.006180,-687.853455,-0.000160,0.004452,0.113069,289.161926,14.730611,1.130689,-687.853455,0.112505,0.000000
145.710007,64.961868,-687.853455,-0.000155,0.004425,0.112401,288.964813,14.720570,1.124011,-687.853455,0.111837,0.000000
146.110001,64.969681,-687.897888,-0.000151,0.004403,0.111837,288.999573,14.722340,1.118374,-687.897888,0.111170,0.000000
146.510010,64.930206,-687.897888,-0.000164,0.004372,0.111040,288.823975,14.713395,1.110396,-687.897888,0.110502,0.000000
146.910004,64.906006,-687.942383,-0.000172,0.004351,0.110519,288.716339,14.707911,1.105192,-687.942383,0.109834,0.000000
147.310013,64.857224,-687.897888,-0.000164,0.004323,0.109799,288.499329,14.696856,1.097994,-687.897888,0.109166,0.000000
147.710007,64.599548,-687.942383,-0.000151,0.004298,0.109166,287.353149,14.638467,1.091664,-687.942383,0.108507,0.000000
148.110001,64.110245,-687.942383,-0.000160,0.004279,0.108698,285.176605,14.527589,1.086981,-687.942383,0.107840,0.000000
148.510010,63.075058,-687.942383,-0.000164,0.004249,0.107926,280.571869,14.293013,1.079262,-687.942383,0.107172,0.000000
148.910004,61.908035,-687.897888,-0.000168,0.004226,0.107328,275.380707,14.028562,1.073279,-687.897888,0.106504,0.000000
149.310013,60.420784,-687.986877,-0.000168,0.004200,0.106686,268.765076,13.691545,1.066861,-687.986877,0.105836,0.000000
149.710007,59.028854,-687.986877,-0.000160,0.004176,0.106070,262.573456,13.376129,1.060704,-687.986877,0.105168,0.000000
150.110001,56.412193,-687.986877,-0.000155,0.004146,0.105316,250.933975,12.783186,1.053159,-687.986877,0.104501,0.000000
150.510010,54.659805,-687.986877,-0.000151,0.004129,0.104865,243.138962,12.386088,1.048649,-687.986877,0.103833,0.000000
150.910004,52.286674,-687.986877,-0.000160,0.004103,0.104206,232.582748,11.848330,1.042058,-687.986877,0.103174,0.000000
151.310013,49.869606,-688.075806,-0.000155,0.004080,0.103642,221.831085,11.300614,1.036421,-688.075806,0.102506,0.000000
151.710007,46.974411,-688.031372,-0.000164,0.004051,0.102888,208.952621,10.644554,1.028877,-688.031372,0.101838,0.000000
152.110001,43.917236,-688.031372,-0.000168,0.004023,0.102185,195.353622,9.951789,1.021852,-688.031372,0.101171,0.000000
152.510010,40.770317,-688.031372,-0.000172,0.003996,0.101491,181.355423,9.238686,1.014914,-688.031372,0.100503,0.000000
152.910004,38.394203,-688.075806,-0.000155,0.003975,0.100954,170.785950,8.700251,1.009537,-688.075806,0.099835,0.000000
153.310013,35.130363,-688.075806,-0.000147,0.003942,0.100130,156.267654,7.960654,1.001299,-688.075806,0.099167,0.000000
153.710007,32.730423,-688.120300,-0.000155,0.003922,0.099618,145.592194,7.416820,0.996182,-688.120300,0.098499,0.000000
154.110001,31.002243,-688.075806,-0.000164,0.003907,0.099245,137.904861,7.025209,0.992453,-688.075806,0.097832,0.000000
154.510010,26.717354,-688.075806,-0.000160,0.003865,0.098161,118.844727,6.054239,0.981613,-688.075806,0.097173,0.000000
154.910004,23.713425,-688.120300,-0.000181,0.003837,0.097459,105.482582,5.373538,0.974588,-688.120300,0.096505,0.000000
155.310013,20.894562,-688.075806,-0.000172,0.003813,0.096860,92.943649,4.734775,0.968604,-688.075806,0.095837,0.000000
155.710007,18.126343,-688.120300,-0.000168,0.003788,0.096210,80.629997,4.107488,0.962100,-688.120300,0.095169,0.000000
156.110001,15.128746,-688.164795,-0.000172,0.003760,0.095508,67.296021,3.428223,0.955076,-688.164795,0.094502,0.000000
156.510010,12.155350,-688.120300,-0.000172,0.003735,0.094857,54.069695,2.754442,0.948571,-688.120300,0.093834,0.000000
156.910004,9.394585,-688.164795,-0.000181,0.003711,0.094250,41.789200,2.128843,0.942501,-688.164795,0.093166,0.000000
157.310013,7.172638,-688.164795,-0.000190,0.003692,0.093764,31.905487,1.625343,0.937644,-688.164795,0.092498,0.000000
157.710007,4.188446,-688.164795,-0.000203,0.003662,0.093027,18.631138,0.949115,0.930273,-688.164795,0.091839,0.000000
158.110001,0.946198,-688.164795,-0.000190,0.003630,0.092212,4.208897,0.214411,0.922121,-688.164795,0.091171,0.000000
158.510010,-1.378525,-688.164795,-0.000216,0.003603,0.091527,-6.131985,-0.312378,0.915270,-688.164795,0.090504,0.000000
158.910004,-0.231987,-688.164795,-0.000280,0.003572,0.090729,-1.031930,-0.052569,0.907291,-688.164795,0.089836,0.000000
159.310013,0.051758,-688.209290,-0.000302,0.003558,0.090374,0.230230,0.011728,0.903736,-688.209290,0.089168,0.000000
159.710007,0.026436,-688.120300,-0.000345,0.003526,0.089567,0.117593,0.005990,0.895671,-688.120300,0.088500,0.000000
160.110001,0.017128,-688.253784,-0.000427,0.003491,0.088674,0.076189,0.003881,0.886738,-688.253784,0.087833,0.000000
160.510010,0.024574,-688.209290,-0.000474,0.003471,0.088153,0.109312,0.005569,0.881535,-688.209290,0.087165,0.000000
160.910004,0.064423,-688.253784,-0.000535,0.003443,0.087460,0.286566,0.014598,0.874597,-688.253784,0.086506,0.000000
161.310013,0.011169,-688.253784,-0.000569,0.003422,0.086913,0.049684,0.002531,0.869134,-688.253784,0.085838,0.000000
161.710007,-0.001488,-688.209290,-0.000642,0.003389,0.086072,-0.006618,-0.000337,0.860721,-688.209290,0.085170,0.000000
162.110001,0.034630,-688.253784,-0.000711,0.003364,0.085439,0.154041,0.007847,0.854391,-688.253784,0.084502,0.000000
162.510010,0.060326,-688.253784,-0.000750,0.003347,0.085023,0.268342,0.013670,0.850228,-688.253784,0.084875,0.000000
162.600006,0.063301,-688.387207,-0.000755,0.003347,0.085023,0.281577,0.014344,0.850228,-688.387207,0.084875,0.000000