File: Data/compression 33/AutoNoHeating-17-33-reverse-1-3re_11152024_183815.csv
Time (sec),S:Load (lbs),S:HL1 (DIM),S:LVDT (in),S:Position (in),Ch:Position (mm),Ch:Load (N),Ch:Stress (MPa),Ch:Strain (mm/mm),Ch:HL1 (DIM),Set Point (),Cycles ()
0.210000,-0.055862,-158.574585,-0.013758,-0.009036,-0.229520,-0.248488,-0.012659,-2.295200,-158.574585,-0.229260,0.000000
0.570000,-0.091980,-158.574585,-0.013749,-0.008957,-0.227517,-0.409147,-0.020843,-2.275167,-158.574585,-0.226658,0.000000
0.930000,-0.156029,-158.663559,-0.013616,-0.008731,-0.221776,-0.694051,-0.035357,-2.217756,-158.663559,-0.220657,0.000000
1.290000,-0.106499,-158.574585,-0.013370,-0.008495,-0.215783,-0.473730,-0.024133,-2.157831,-158.574585,-0.214656,0.000000
1.650000,-0.056602,-158.619064,-0.013120,-0.008262,-0.209843,-0.251780,-0.012826,-2.098426,-158.619064,-0.208672,0.000000
2.010000,-0.045059,-158.619064,-0.012883,-0.008031,-0.203989,-0.200433,-0.010211,-2.039888,-158.619064,-0.202671,0.000000
2.370000,-0.074852,-158.663559,-0.012650,-0.007793,-0.197953,-0.332958,-0.016962,-1.979529,-158.663559,-0.196669,0.000000
2.730000,-0.093842,-158.752518,-0.012396,-0.007561,-0.192047,-0.417428,-0.021265,-1.920471,-158.752518,-0.190668,0.000000
3.090000,-0.140762,-158.663559,-0.012158,-0.007319,-0.185907,-0.626142,-0.031897,-1.859072,-158.663559,-0.184684,0.000000
3.450000,-0.112083,-158.752518,-0.011895,-0.007082,-0.179889,-0.498572,-0.025398,-1.798886,-158.752518,-0.178683,0.000000
3.810000,-0.074478,-158.752518,-0.011654,-0.006847,-0.173922,-0.331295,-0.016877,-1.739221,-158.752518,-0.172682,0.000000
4.170000,-0.044685,-158.708038,-0.011408,-0.006610,-0.167904,-0.198770,-0.010126,-1.679036,-158.708038,-0.166681,0.000000
4.530000,-0.068893,-158.796997,-0.011167,-0.006376,-0.161954,-0.306453,-0.015611,-1.619544,-158.796997,-0.160680,0.000000
4.890000,-0.083038,-158.841476,-0.010930,-0.006147,-0.156144,-0.369373,-0.018817,-1.561440,-158.841476,-0.154696,0.000000
5.250000,-0.096451,-158.841476,-0.010680,-0.005900,-0.149848,-0.429035,-0.021856,-1.498479,-158.841476,-0.148695,0.000000
5.610000,-0.135544,-158.885956,-0.010464,-0.005676,-0.144176,-0.602929,-0.030715,-1.441763,-158.885956,-0.142693,0.000000
5.970000,-0.085274,-158.885956,-0.010188,-0.005428,-0.137872,-0.379317,-0.019323,-1.378715,-158.885956,-0.136692,0.000000
6.330000,-0.037613,-158.974915,-0.009964,-0.005194,-0.131931,-0.167311,-0.008523,-1.319310,-158.974915,-0.130691,0.000000
6.690001,-0.060699,-158.841476,-0.009735,-0.004962,-0.126034,-0.270005,-0.013755,-1.260339,-158.841476,-0.124707,0.000000
7.050000,-0.068520,-159.019394,-0.009481,-0.004724,-0.119981,-0.304790,-0.015527,-1.199807,-159.019394,-0.118706,0.000000
7.410000,-0.066658,-158.974915,-0.009231,-0.004485,-0.113927,-0.296510,-0.015105,-1.139274,-158.974915,-0.112705,0.000000
7.770000,-0.126236,-158.974915,-0.008990,-0.004257,-0.108126,-0.561526,-0.028605,-1.081257,-158.974915,-0.106703,0.000000
8.130000,-0.080063,-159.063889,-0.008739,-0.004014,-0.101960,-0.356137,-0.018143,-1.019597,-159.063889,-0.100720,0.000000
8.490001,-0.079689,-159.019394,-0.008494,-0.003776,-0.095915,-0.354474,-0.018058,-0.959152,-159.019394,-0.094718,0.000000
8.850000,-0.067032,-159.063889,-0.008261,-0.003546,-0.090061,-0.298173,-0.015190,-0.900614,-159.063889,-0.088717,0.000000
9.210000,-0.085274,-159.063889,-0.008015,-0.003309,-0.084052,-0.379317,-0.019323,-0.840515,-159.063889,-0.082716,0.000000
9.570001,-0.088257,-159.108368,-0.007774,-0.003072,-0.078024,-0.392586,-0.019999,-0.780243,-159.108368,-0.076715,0.000000
9.930000,-0.062935,-159.197327,-0.007528,-0.002838,-0.072075,-0.279948,-0.014261,-0.720751,-159.197327,-0.070731,0.000000
10.290001,-0.067772,-159.197327,-0.007295,-0.002596,-0.065944,-0.301465,-0.015357,-0.659438,-159.197327,-0.064730,0.000000
10.650001,-0.077454,-159.197327,-0.007049,-0.002361,-0.059969,-0.344531,-0.017551,-0.599687,-159.197327,-0.058729,0.000000
11.010000,-0.084534,-159.241806,-0.006795,-0.002126,-0.053993,-0.376025,-0.019156,-0.539935,-159.241806,-0.052727,0.000000
11.370001,-0.081924,-159.197327,-0.006549,-0.001889,-0.047984,-0.364418,-0.018564,-0.479836,-159.197327,-0.046726,0.000000
11.730000,-0.100914,-159.286285,-0.006329,-0.001656,-0.042060,-0.448888,-0.022867,-0.420604,-159.286285,-0.040742,0.000000
12.090000,-0.038361,-159.241806,-0.006088,-0.001418,-0.036007,-0.170636,-0.008693,-0.360072,-159.241806,-0.034741,0.000000
12.450001,-0.035004,-159.286285,-0.005829,-0.001182,-0.030032,-0.155704,-0.007932,-0.300320,-159.286285,-0.028740,0.000000
12.810000,-0.055115,-159.330765,-0.005583,-0.000946,-0.024022,-0.245163,-0.012489,-0.240221,-159.330765,-0.022739,0.000000
13.170001,-0.090118,-159.330765,-0.005355,-0.000712,-0.018082,-0.400867,-0.020421,-0.180817,-159.330765,-0.016737,0.000000
13.530001,-0.105385,-159.375244,-0.005079,-0.000474,-0.012037,-0.468775,-0.023881,-0.120371,-159.375244,-0.010754,0.000000
13.890000,-0.057350,-159.330765,-0.004846,-0.000237,-0.006010,-0.255106,-0.012996,-0.060099,-159.330765,-0.004752,0.000000
14.250001,0.058090,-159.419724,-0.004747,0.000003,0.000078,0.258398,0.013163,0.000781,-159.419724,0.000312,0.000000
14.610001,0.078194,-159.375244,-0.004769,0.000003,0.000078,0.347823,0.017719,0.000781,-159.375244,0.000390,0.000000
14.970000,0.134422,-159.419724,-0.004773,0.000003,0.000087,0.597940,0.030461,0.000867,-159.419724,0.000989,0.000000
15.330001,0.186554,-159.508698,-0.004764,0.000017,0.000425,0.829833,0.042274,0.004249,-159.508698,0.001596,0.000000
15.690001,0.381310,-159.464203,-0.004730,0.000048,0.001223,1.696149,0.086406,0.012228,-159.464203,0.002194,0.000000
16.050001,0.567863,-159.464203,-0.004695,0.000069,0.001760,2.525983,0.128680,0.017605,-159.464203,0.002792,0.000000
16.410000,0.748840,-159.597656,-0.004687,0.000081,0.002047,3.331008,0.169690,0.020467,-159.597656,0.003391,0.000000
16.770000,1.035194,-159.597656,-0.004682,0.000103,0.002628,4.604774,0.234578,0.026277,-159.597656,0.003989,0.000000
17.130001,1.798187,-159.642136,-0.004661,0.000138,0.003504,7.998736,0.407475,0.035036,-159.642136,0.004596,0.000000
17.490002,2.093849,-159.642136,-0.004644,0.000155,0.003946,9.313907,0.474473,0.039459,-159.642136,0.005195,0.000000
17.850000,2.526917,-159.642136,-0.004618,0.000176,0.004475,11.240286,0.572607,0.044749,-159.642136,0.005793,0.000000
18.210001,2.940247,-159.686615,-0.004605,0.000199,0.005056,13.078870,0.666269,0.050559,-159.686615,0.006391,0.000000
18.570002,3.170380,-159.642136,-0.004592,0.000211,0.005351,14.102553,0.718418,0.053508,-159.642136,0.006990,0.000000
18.930000,4.233124,-159.731094,-0.004549,0.000257,0.006530,18.829876,0.959240,0.065302,-159.731094,0.007588,0.000000
19.290001,4.957764,-159.686615,-0.004531,0.000285,0.007233,22.053234,1.123445,0.072327,-159.686615,0.008195,0.000000
19.650002,5.180817,-159.731094,-0.004510,0.000306,0.007762,23.045424,1.173990,0.077617,-159.731094,0.008794,0.000000
20.010000,5.948273,-159.731094,-0.004493,0.000329,0.008369,26.459238,1.347898,0.083687,-159.731094,0.009392,0.000000
20.370001,6.443161,-159.775574,-0.004467,0.000350,0.008889,28.660612,1.460041,0.088891,-159.775574,0.009990,0.000000
20.730001,6.960381,-159.864532,-0.004458,0.000374,0.009505,30.961319,1.577245,0.095048,-159.864532,0.010589,0.000000
21.090000,7.689857,-159.775574,-0.004419,0.000398,0.010112,34.206196,1.742547,0.101119,-159.775574,0.011196,0.000000
21.450001,7.913658,-159.864532,-0.004419,0.000414,0.010511,35.201710,1.793261,0.105108,-159.864532,0.011794,0.000000
21.810001,8.842728,-159.864532,-0.004385,0.000452,0.011491,39.334415,2.003791,0.114908,-159.864532,0.012393,0.000000
22.170002,9.311913,-159.909012,-0.004363,0.000475,0.012054,41.421455,2.110110,0.120544,-159.909012,0.012991,0.000000
22.530001,9.795998,-159.953506,-0.004342,0.000496,0.012609,43.574772,2.219805,0.126095,-159.953506,0.013589,0.000000
22.890001,10.248428,-159.909012,-0.004324,0.000519,0.013182,45.587288,2.322327,0.131818,-159.909012,0.014197,0.000000
23.250002,10.932106,-159.953506,-0.004303,0.000543,0.013798,48.628437,2.477251,0.137976,-159.953506,0.014795,0.000000
23.610001,11.107498,-159.997986,-0.004277,0.000566,0.014379,49.408619,2.516995,0.143786,-159.997986,0.015393,0.000000
23.970001,11.631424,-159.997986,-0.004273,0.000588,0.014925,51.739159,2.635718,0.149250,-159.997986,0.015992,0.000000
24.330002,12.073799,-160.042465,-0.004234,0.000609,0.015480,53.706940,2.735962,0.154800,-160.042465,0.016590,0.000000
24.690001,12.472984,-160.086945,-0.004234,0.000633,0.016078,55.482605,2.826419,0.160784,-160.086945,0.017197,0.000000
25.050001,13.121658,-159.997986,-0.004199,0.000658,0.016711,58.368050,2.973410,0.167114,-159.997986,0.017795,0.000000
25.410002,13.079208,-160.175903,-0.004178,0.000670,0.017006,58.179226,2.963791,0.170063,-160.175903,0.018394,0.000000
25.770000,14.007530,-160.131424,-0.004165,0.000705,0.017900,62.308605,3.174152,0.178995,-160.131424,0.018992,0.000000
26.130001,13.975883,-160.131424,-0.004130,0.000726,0.018429,62.167835,3.166980,0.184286,-160.131424,0.019591,0.000000
26.490002,14.759727,-160.131424,-0.004122,0.000749,0.019036,65.654549,3.344602,0.190356,-160.131424,0.020189,0.000000
26.850000,15.183853,-160.175903,-0.004087,0.000774,0.019660,67.541153,3.440710,0.196600,-160.175903,0.020796,0.000000
27.210001,15.373398,-160.175903,-0.004070,0.000792,0.020111,68.384293,3.483662,0.201110,-160.175903,0.021394,0.000000
27.570002,16.150536,-160.220383,-0.004044,0.000822,0.020883,71.841171,3.659764,0.208828,-160.220383,0.021993,0.000000
27.930002,16.371353,-160.309341,-0.004040,0.000844,0.021429,72.823418,3.709802,0.214292,-160.309341,0.022591,0.000000
28.290001,16.834213,-160.309341,-0.004010,0.000865,0.021967,74.882324,3.814687,0.219668,-160.309341,0.023190,0.000000
28.650002,17.068810,-160.309341,-0.004001,0.000885,0.022470,75.925858,3.867847,0.224698,-160.309341,0.023797,0.000000
29.010002,17.510811,-160.353836,-0.003967,0.000914,0.023207,77.891975,3.968006,0.232070,-160.353836,0.024395,0.000000
29.370001,17.954308,-160.309341,-0.003962,0.000933,0.023693,79.864746,4.068504,0.236926,-160.309341,0.024993,0.000000
29.730001,18.524406,-160.398315,-0.003919,0.000962,0.024438,82.400673,4.197690,0.244384,-160.398315,0.025592,0.000000
30.090002,18.865501,-160.353836,-0.003885,0.000985,0.025028,83.917938,4.274984,0.250281,-160.353836,0.026190,0.000000
30.450001,18.504677,-160.398315,-0.003876,0.000995,0.025280,82.312912,4.193220,0.252796,-160.398315,0.026797,0.000000
30.810001,19.761429,-160.487274,-0.003867,0.001037,0.026338,87.903229,4.478004,0.263376,-160.487274,0.027396,0.000000
31.170002,20.051506,-160.487274,-0.003820,0.001060,0.026919,89.193550,4.543736,0.269187,-160.487274,0.027994,0.000000
31.530001,20.222427,-160.531754,-0.003811,0.001084,0.027526,89.953850,4.582468,0.275257,-160.531754,0.028592,0.000000
31.890001,20.557938,-160.442795,-0.003798,0.001106,0.028089,91.446274,4.658495,0.280895,-160.442795,0.029191,0.000000
32.250000,20.686035,-160.442795,-0.003760,0.001123,0.028514,92.016083,4.687522,0.285144,-160.442795,0.029798,0.000000
32.610001,21.338058,-160.531754,-0.003751,0.001152,0.029269,94.916428,4.835273,0.292689,-160.531754,0.030396,0.000000
32.970001,21.804268,-160.576233,-0.003721,0.001182,0.030015,96.990227,4.940918,0.300147,-160.576233,0.030995,0.000000
33.330002,21.629623,-160.576233,-0.003686,0.001206,0.030622,96.213371,4.901343,0.306217,-160.576233,0.031593,0.000000
33.690002,21.665375,-160.576233,-0.003669,0.001225,0.031125,96.372398,4.909444,0.311247,-160.576233,0.032191,0.000000
34.050003,22.301758,-160.620712,-0.003648,0.001254,0.031845,99.203171,5.053650,0.318445,-160.620712,0.032790,0.000000
34.410000,22.219833,-160.665192,-0.003626,0.001275,0.032382,98.838753,5.035087,0.323822,-160.665192,0.033397,0.000000
34.770000,22.344948,-160.620712,-0.003622,0.001292,0.032816,99.395294,5.063437,0.328158,-160.620712,0.033995,0.000000
35.130001,22.493156,-160.709671,-0.003591,0.001319,0.033501,100.054558,5.097022,0.335009,-160.709671,0.034594,0.000000
35.490002,23.036072,-160.709671,-0.003583,0.001339,0.034013,102.469566,5.220049,0.340126,-160.709671,0.035192,0.000000
35.850002,23.014847,-160.709671,-0.003535,0.001360,0.034533,102.375153,5.215239,0.345329,-160.709671,0.035790,0.000000
36.210003,23.894020,-160.709671,-0.003518,0.001390,0.035296,106.285912,5.414463,0.352961,-160.709671,0.036397,0.000000
36.570004,23.825500,-160.754150,-0.003488,0.001408,0.035756,105.981117,5.398936,0.357557,-160.754150,0.036996,0.000000
36.930000,24.598923,-160.798645,-0.003466,0.001440,0.036588,109.421471,5.574196,0.365882,-160.798645,0.037594,0.000000
37.290001,24.299538,-160.798645,-0.003445,0.001464,0.037187,108.089745,5.506354,0.371866,-160.798645,0.038193,0.000000
37.650002,23.795715,-160.798645,-0.003419,0.001479,0.037568,105.848625,5.392186,0.375682,-160.798645,0.038791,0.000000
38.010002,24.019135,-160.932083,-0.003410,0.001506,0.038245,106.842445,5.442814,0.382447,-160.932083,0.039398,0.000000
38.370003,24.734840,-160.843124,-0.003380,0.001530,0.038852,110.026062,5.604995,0.388517,-160.843124,0.039996,0.000000
38.730003,24.705048,-160.932083,-0.003363,0.001551,0.039398,109.893539,5.598244,0.393981,-160.932083,0.040595,0.000000
39.090000,24.945976,-160.932083,-0.003333,0.001574,0.039979,110.965248,5.652839,0.399791,-160.932083,0.041193,0.000000
39.450001,24.970924,-160.976562,-0.003307,0.001592,0.040447,111.076218,5.658493,0.404474,-160.976562,0.041792,0.000000
39.810001,24.743027,-161.021042,-0.003307,0.001609,0.040881,110.062477,5.606850,0.408810,-161.021042,0.042399,0.000000
40.170002,26.192673,-161.021042,-0.003268,0.001649,0.041896,116.510826,5.935345,0.418957,-161.021042,0.042997,0.000000
40.530003,26.461533,-160.976562,-0.003229,0.001679,0.042650,117.706779,5.996269,0.426502,-160.976562,0.043595,0.000000
40.890003,25.570442,-161.065521,-0.003208,0.001692,0.042971,113.743004,5.794345,0.429710,-161.065521,0.044194,0.000000
41.250004,26.128998,-161.065521,-0.003173,0.001725,0.043812,116.227585,5.920916,0.438122,-161.065521,0.044792,0.000000
41.610001,25.696304,-161.198959,-0.003173,0.001744,0.044289,114.302872,5.822865,0.442892,-161.198959,0.045399,0.000000
41.970001,26.105911,-161.065521,-0.003143,0.001767,0.044879,116.124893,5.915684,0.448789,-161.065521,0.045998,0.000000
42.330002,26.273109,-161.154480,-0.003100,0.001791,0.045486,116.868629,5.953572,0.454860,-161.154480,0.046596,0.000000
42.690002,26.617180,-161.198959,-0.003109,0.001819,0.046197,118.399132,6.031539,0.461971,-161.198959,0.047194,0.000000
43.050003,27.090096,-161.198959,-0.003065,0.001845,0.046856,120.502762,6.138704,0.468562,-161.198959,0.047793,0.000000
43.410004,26.771713,-161.198959,-0.003048,0.001865,0.047368,119.086525,6.066557,0.473679,-161.198959,0.048391,0.000000
43.770000,27.167549,-161.198959,-0.003022,0.001892,0.048053,120.847298,6.156254,0.480530,-161.198959,0.048998,0.000000
44.130001,26.938538,-161.287933,-0.002988,0.001909,0.048487,119.828598,6.104360,0.484866,-161.287933,0.049597,0.000000
44.490002,27.428581,-161.287933,-0.002966,0.001936,0.049180,122.008423,6.215405,0.491804,-161.287933,0.050195,0.000000
44.850002,27.422997,-161.243454,-0.002953,0.001958,0.049727,121.983582,6.214140,0.497267,-161.243454,0.050793,0.000000
45.210003,27.819572,-161.376892,-0.002919,0.001984,0.050403,123.747635,6.304005,0.504032,-161.376892,0.051392,0.000000
45.570004,28.049324,-161.332413,-0.002897,0.002008,0.051002,124.769623,6.356068,0.510016,-161.332413,0.051999,0.000000
45.930000,27.821434,-161.376892,-0.002871,0.002026,0.051452,123.755920,6.304427,0.514525,-161.376892,0.052597,0.000000
46.290001,28.195297,-161.421371,-0.002863,0.002050,0.052060,125.418945,6.389146,0.520596,-161.421371,0.053196,0.000000
46.650002,28.143532,-161.287933,-0.002828,0.002068,0.052528,125.188683,6.377416,0.525279,-161.287933,0.053794,0.000000
47.010002,27.999054,-161.465851,-0.002828,0.002085,0.052970,124.546013,6.344676,0.529701,-161.465851,0.054392,0.000000
47.370003,28.383347,-161.421371,-0.002798,0.002111,0.053621,126.255432,6.431758,0.536206,-161.421371,0.054999,0.000000
47.730003,29.523178,-161.465851,-0.002764,0.002148,0.054548,131.325653,6.690048,0.545485,-161.465851,0.055598,0.000000
48.090004,29.673615,-161.599289,-0.002742,0.002171,0.055147,131.994827,6.724137,0.551469,-161.599289,0.056196,0.000000
48.450001,29.430458,-161.510330,-0.002708,0.002190,0.055633,130.913223,6.669037,0.556325,-161.510330,0.056795,0.000000
48.810001,30.080620,-161.554810,-0.002712,0.002219,0.056352,133.805283,6.816366,0.563523,-161.554810,0.057393,0.000000
49.170002,30.058647,-161.510330,-0.002669,0.002240,0.056899,133.707535,6.811387,0.568987,-161.510330,0.058000,0.000000
49.530003,30.479057,-161.599289,-0.002652,0.002263,0.057480,135.577621,6.906653,0.574797,-161.599289,0.058598,0.000000
49.890003,30.408302,-161.599289,-0.002634,0.002283,0.057991,135.262878,6.890620,0.579914,-161.599289,0.059197,0.000000
50.250004,30.369209,-161.643784,-0.002600,0.002301,0.058451,135.088989,6.881761,0.584510,-161.643784,0.059795,0.000000
50.610001,30.954948,-161.688263,-0.002587,0.002331,0.059214,137.694489,7.014492,0.592142,-161.688263,0.060394,0.000000
50.970001,31.559311,-161.599289,-0.002557,0.002358,0.059882,140.382828,7.151442,0.598819,-161.599289,0.060992,0.000000
51.330002,31.435677,-161.777222,-0.002531,0.002377,0.060368,139.832870,7.123426,0.603676,-161.777222,0.061599,0.000000
51.690002,31.406265,-161.732742,-0.002535,0.002398,0.060897,139.702042,7.116761,0.608966,-161.732742,0.062197,0.000000
52.050003,32.435501,-161.777222,-0.002492,0.002428,0.061668,144.280319,7.349989,0.616684,-161.777222,0.062796,0.000000
52.410004,32.051208,-161.777222,-0.002475,0.002445,0.062093,142.570892,7.262908,0.620934,-161.777222,0.063394,0.000000
52.770004,32.404594,-161.732742,-0.002458,0.002475,0.062857,144.142838,7.342986,0.628565,-161.732742,0.063993,0.000000
53.130001,32.049721,-161.866180,-0.002432,0.002492,0.063290,142.564285,7.262571,0.632901,-161.866180,0.064600,0.000000
53.490002,32.514069,-161.821701,-0.002414,0.002510,0.063758,144.629807,7.367793,0.637585,-161.821701,0.065198,0.000000
53.850002,34.002441,-161.866180,-0.002389,0.002547,0.064704,151.250412,7.705063,0.647037,-161.866180,0.065796,0.000000
54.210003,34.008400,-161.955139,-0.002371,0.002566,0.065172,151.276917,7.706413,0.651720,-161.955139,0.066395,0.000000
54.570004,35.061844,-161.866180,-0.002333,0.002597,0.065970,155.962875,7.945127,0.659699,-161.866180,0.066993,0.000000
54.930004,35.274841,-161.999619,-0.002315,0.002622,0.066594,156.910324,7.993393,0.665943,-161.999619,0.067600,0.000000
55.290001,35.617050,-161.955139,-0.002289,0.002647,0.067227,158.432556,8.070939,0.672274,-161.955139,0.068199,0.000000
55.650002,35.563057,-161.955139,-0.002259,0.002665,0.067696,158.192383,8.058703,0.676956,-161.955139,0.068797,0.000000
56.010002,35.759300,-161.999619,-0.002259,0.002687,0.068242,159.065308,8.103173,0.682420,-161.999619,0.069395,0.000000
56.370003,35.510551,-162.044098,-0.002220,0.002699,0.068563,157.958817,8.046806,0.685629,-162.044098,0.069994,0.000000
56.730003,36.539787,-162.088593,-0.002203,0.002728,0.069283,162.537094,8.280034,0.692827,-162.088593,0.070601,0.000000
57.090004,37.345978,-162.088593,-0.002199,0.002755,0.069976,166.123199,8.462719,0.699764,-162.088593,0.071199,0.000000
57.450005,36.352112,-162.044098,-0.002151,0.002761,0.070124,161.702271,8.237507,0.701239,-162.044098,0.071798,0.000000
57.810001,38.716309,-162.088593,-0.002151,0.002801,0.071156,172.218735,8.773241,0.711559,-162.088593,0.072396,0.000000
58.170002,39.004524,-162.133072,-0.002143,0.002825,0.071754,173.500793,8.838552,0.717543,-162.133072,0.072994,0.000000
58.530003,40.684296,-162.177551,-0.002100,0.002861,0.072665,180.972778,9.219193,0.726649,-162.177551,0.073593,0.000000
58.890003,39.721336,-162.133072,-0.002087,0.002871,0.072934,176.689331,9.000984,0.729337,-162.133072,0.074200,0.000000
59.250004,39.786507,-162.222031,-0.002065,0.002898,0.073601,176.979218,9.015752,0.736014,-162.222031,0.074798,0.000000
59.610004,40.793030,-162.266510,-0.002044,0.002913,0.073983,181.456467,9.243833,0.739830,-162.266510,0.075397,0.000000
59.970001,42.063187,-162.222031,-0.002022,0.002945,0.074816,187.106400,9.531654,0.748156,-162.222031,0.075995,0.000000
60.330002,41.764923,-162.355469,-0.002001,0.002957,0.075110,185.779663,9.464067,0.751104,-162.355469,0.076593,0.000000
60.690002,43.367981,-162.310989,-0.002001,0.002991,0.075969,192.910416,9.827325,0.759690,-162.310989,0.077200,0.000000
61.050003,42.944595,-162.310989,-0.001966,0.003001,0.076238,191.027100,9.731384,0.762378,-162.310989,0.077799,0.000000
61.410004,44.077354,-162.399948,-0.001940,0.003028,0.076914,196.065872,9.988071,0.769142,-162.399948,0.078397,0.000000
61.770004,45.981293,-162.355469,-0.001936,0.003066,0.077868,204.535004,10.419510,0.778682,-162.355469,0.078996,0.000000
62.130001,46.670181,-162.399948,-0.001897,0.003090,0.078493,207.599335,10.575614,0.784926,-162.399948,0.079594,0.000000
62.490002,47.551216,-162.399948,-0.001906,0.003117,0.079160,211.518372,10.775260,0.791604,-162.399948,0.080201,0.000000
62.850002,47.878532,-162.444427,-0.001863,0.003137,0.079681,212.974350,10.849430,0.796807,-162.444427,0.080799,0.000000
63.210003,48.599075,-162.488907,-0.001841,0.003160,0.080262,216.179489,11.012708,0.802617,-162.488907,0.081398,0.000000
63.570004,49.401161,-162.488907,-0.001828,0.003183,0.080860,219.747345,11.194464,0.808601,-162.488907,0.081996,0.000000
63.930004,50.632599,-162.488907,-0.001807,0.003211,0.081554,225.225052,11.473511,0.815539,-162.488907,0.082595,0.000000
64.290001,51.694229,-162.533401,-0.001802,0.003236,0.082204,229.947418,11.714080,0.822043,-162.533401,0.083202,0.000000
64.650002,52.233803,-162.533401,-0.001772,0.003258,0.082751,232.347565,11.836349,0.827507,-162.533401,0.083800,0.000000
65.010002,53.224686,-162.533401,-0.001759,0.003285,0.083427,236.755234,12.060886,0.834271,-162.533401,0.084398,0.000000
65.370003,53.635040,-162.577881,-0.001755,0.003303,0.083895,238.580582,12.153873,0.838954,-162.577881,0.084997,0.000000
65.730003,54.326157,-162.711319,-0.001729,0.003322,0.084381,241.654816,12.310483,0.843811,-162.711319,0.085595,0.000000
66.090004,55.655899,-162.622360,-0.001699,0.003348,0.085031,247.569809,12.611807,0.850315,-162.622360,0.086194,0.000000
66.450005,56.915642,-162.622360,-0.001694,0.003376,0.085751,253.173416,12.897268,0.857513,-162.622360,0.086801,0.000000
66.810005,58.022705,-162.711319,-0.001673,0.003400,0.086358,258.097870,13.148133,0.863583,-162.711319,0.087399,0.000000
67.170006,58.689247,-162.711319,-0.001664,0.003419,0.086844,261.062805,13.299173,0.868440,-162.711319,0.087997,0.000000
67.530006,59.957550,-162.755798,-0.001651,0.003445,0.087494,266.704498,13.586576,0.874944,-162.755798,0.088596,0.000000
67.890007,60.994232,-162.711319,-0.001634,0.003467,0.088049,271.315887,13.821491,0.880494,-162.711319,0.089194,0.000000
68.250000,61.798187,-162.800278,-0.001613,0.003485,0.088526,274.892059,14.003669,0.885264,-162.800278,0.089801,0.000000
68.610001,63.054573,-162.844757,-0.001604,0.003510,0.089151,280.480743,14.288371,0.891508,-162.844757,0.090400,0.000000
68.970001,64.645348,-162.800278,-0.001587,0.003538,0.089862,287.556854,14.648846,0.898619,-162.800278,0.090998,0.000000
69.330002,65.734535,-162.889236,-0.001569,0.003563,0.090512,292.401825,14.895658,0.905124,-162.889236,0.091596,0.000000
69.690002,65.086235,-162.889236,-0.001552,0.003557,0.090348,289.518036,14.748752,0.903476,-162.889236,0.015868,0.000000
70.050003,66.954048,-162.889236,-0.001535,0.003488,0.088604,297.826477,15.172004,0.886045,-162.889236,294.500488,0.000000
70.410004,65.776619,-162.889236,-0.001535,0.003469,0.088110,292.589020,14.905194,0.881101,-162.889236,294.500488,0.000000
70.770004,64.960381,-162.889236,-0.001526,0.003584,0.091041,288.958191,14.720233,0.910414,-162.889236,294.500488,0.000000
71.130005,64.776421,-162.978210,-0.001526,0.003589,0.091163,288.139923,14.678547,0.911628,-162.978210,294.500488,0.000000
71.490005,65.238533,-162.933731,-0.001505,0.003602,0.091501,290.195496,14.783262,0.915010,-162.933731,294.500488,0.000000
71.850006,65.688728,-163.022690,-0.001509,0.003616,0.091857,292.198059,14.885279,0.918566,-163.022690,294.500488,0.000000
72.210007,65.245232,-163.067169,-0.001496,0.003616,0.091839,290.225281,14.784781,0.918392,-163.067169,294.500488,0.000000
72.570000,64.672157,-163.067169,-0.001487,0.003616,0.091839,287.676117,14.654920,0.918392,-163.067169,294.500488,0.000000
72.930000,65.989616,-163.067169,-0.001487,0.003618,0.091891,293.536469,14.953461,0.918912,-163.067169,294.500488,0.000000
73.290001,65.389351,-163.111649,-0.001487,0.003618,0.091900,290.866364,14.817439,0.918999,-163.111649,294.500488,0.000000
73.650002,64.837486,-163.111649,-0.001479,0.003618,0.091900,288.411530,14.692384,0.918999,-163.111649,294.500488,0.000000
74.010002,65.572548,-163.111649,-0.001479,0.003636,0.092342,291.681274,14.858952,0.923422,-163.111649,294.500488,0.000000
74.370003,65.092567,-163.156128,-0.001470,0.003636,0.092342,289.546204,14.750187,0.923422,-163.156128,294.500488,0.000000
74.730003,64.668800,-163.200607,-0.001466,0.003636,0.092351,287.661194,14.654160,0.923509,-163.200607,294.500488,0.000000
75.090004,66.638649,-163.200607,-0.001449,0.003615,0.091822,296.423523,15.100534,0.918219,-163.200607,294.500488,0.000000
75.450005,66.121437,-163.245087,-0.001453,0.003615,0.091822,294.122833,14.983332,0.918219,-163.245087,294.500488,0.000000
75.810005,65.797844,-163.245087,-0.001436,0.003618,0.091891,292.683441,14.910005,0.918912,-163.245087,294.500488,0.000000
76.170006,65.385246,-163.200607,-0.001444,0.003635,0.092334,290.848114,14.816508,0.923335,-163.200607,294.500488,0.000000
76.530006,65.057930,-163.334045,-0.001453,0.003639,0.092429,289.392120,14.742338,0.924289,-163.334045,294.500488,0.000000
76.890007,65.613136,-163.334045,-0.001444,0.003668,0.093175,291.861816,14.868150,0.931747,-163.334045,294.500488,0.000000
77.250000,65.420998,-163.334045,-0.001449,0.003668,0.093175,291.007141,14.824610,0.931747,-163.334045,294.500488,0.000000
77.610001,65.183418,-163.378540,-0.001453,0.003668,0.093175,289.950317,14.770773,0.931747,-163.378540,294.500488,0.000000
77.970001,64.958885,-163.334045,-0.001436,0.003668,0.093175,288.951538,14.719894,0.931747,-163.334045,294.500488,0.000000
78.330002,64.719444,-163.467499,-0.001431,0.003668,0.093175,287.886475,14.665635,0.931747,-163.467499,294.500488,0.000000
78.690002,64.493416,-163.378540,-0.001418,0.003668,0.093175,286.881042,14.614417,0.931747,-163.378540,294.500488,0.000000
79.050003,66.310600,-163.378540,-0.001431,0.003673,0.093305,294.964294,15.026197,0.933048,-163.378540,294.500488,0.000000
79.410004,66.038017,-163.467499,-0.001414,0.003673,0.093305,293.751770,14.964429,0.933048,-163.467499,294.500488,0.000000
79.770004,65.827995,-163.511978,-0.001406,0.003673,0.093305,292.817535,14.916837,0.933048,-163.511978,294.500488,0.000000
80.130005,65.583717,-163.511978,-0.001423,0.003673,0.093305,291.730957,14.861483,0.933048,-163.511978,294.500488,0.000000
80.490005,65.356956,-163.511978,-0.001414,0.003673,0.093305,290.722260,14.810098,0.933048,-163.511978,294.500488,0.000000
80.850006,65.206505,-163.556458,-0.001427,0.003673,0.093305,290.053009,14.776005,0.933048,-163.556458,294.500488,0.000000
81.210007,65.011391,-163.556458,-0.001418,0.003684,0.093574,289.185120,14.731791,0.935736,-163.556458,294.500488,0.000000
81.570007,65.253807,-163.556458,-0.001418,0.003691,0.093747,290.263428,14.786724,0.937471,-163.556458,294.500488,0.000000
81.930000,65.144691,-163.600937,-0.001414,0.003691,0.093756,289.778046,14.761998,0.937558,-163.600937,294.500488,0.000000
82.290001,65.135765,-163.600937,-0.001418,0.003693,0.093799,289.738342,14.759975,0.937991,-163.600937,294.500488,0.000000
82.650002,65.048622,-163.689896,-0.001414,0.003693,0.093808,289.350708,14.740228,0.938078,-163.689896,294.500488,0.000000
83.010002,64.927605,-163.689896,-0.001423,0.003693,0.093808,288.812408,14.712806,0.938078,-163.689896,294.500488,0.000000
83.370003,64.798759,-163.734375,-0.001414,0.003693,0.093808,288.239288,14.683609,0.938078,-163.734375,294.500488,0.000000
83.730003,65.598991,-163.734375,-0.001418,0.003705,0.094103,291.798889,14.864944,0.941027,-163.734375,294.500488,0.000000
84.090004,65.577400,-163.689896,-0.001401,0.003705,0.094103,291.702850,14.860051,0.941027,-163.689896,294.500488,0.000000
84.450005,65.517067,-163.734375,-0.001410,0.003705,0.094103,291.434479,14.846379,0.941027,-163.734375,294.500488,0.000000
84.810005,65.403130,-163.823349,-0.001414,0.003705,0.094103,290.927643,14.820561,0.941027,-163.823349,294.500488,0.000000
85.170006,65.303703,-163.734375,-0.001401,0.003705,0.094103,290.485382,14.798031,0.941027,-163.734375,294.500488,0.000000
85.530006,65.212090,-163.867828,-0.001401,0.003705,0.094103,290.077850,14.777270,0.941027,-163.867828,294.500488,0.000000
85.890007,65.097786,-163.823349,-0.001410,0.003705,0.094103,289.569427,14.751369,0.941027,-163.823349,294.500488,0.000000
86.250008,65.010643,-163.867828,-0.001397,0.003705,0.094103,289.181793,14.731623,0.941027,-163.867828,294.500488,0.000000
86.610001,64.911964,-163.867828,-0.001393,0.003705,0.094111,288.742828,14.709262,0.941113,-163.867828,294.500488,0.000000
86.970001,64.813652,-163.912308,-0.001388,0.003705,0.094111,288.305511,14.686983,0.941113,-163.912308,294.500488,0.000000
87.330002,64.735832,-163.956787,-0.001406,0.003705,0.094111,287.959351,14.669350,0.941113,-163.956787,294.500488,0.000000
87.690002,64.635658,-163.912308,-0.001397,0.003705,0.094111,287.513763,14.646649,0.941113,-163.912308,294.500488,0.000000
88.050003,64.547035,-164.001266,-0.001380,0.003705,0.094111,287.119537,14.626567,0.941113,-164.001266,294.500488,0.000000
88.410004,64.461021,-164.045746,-0.001410,0.003706,0.094120,286.736938,14.607076,0.941200,-164.045746,294.500488,0.000000
88.770004,66.345970,-163.956787,-0.001397,0.003714,0.094337,295.121613,15.034211,0.943368,-163.956787,294.500488,0.000000
89.130005,66.206337,-164.134705,-0.001388,0.003714,0.094337,294.500488,15.002570,0.943368,-164.134705,294.500488,0.000000
89.490005,66.093880,-164.001266,-0.001393,0.003714,0.094337,294.000275,14.977087,0.943368,-164.001266,294.500488,0.000000
89.850006,65.991478,-164.090225,-0.001388,0.003714,0.094337,293.544769,14.953883,0.943368,-164.090225,294.500488,0.000000
90.210007,65.855553,-164.134705,-0.001393,0.003714,0.094337,292.940125,14.923081,0.943368,-164.134705,294.500488,0.000000
90.570007,65.795982,-164.134705,-0.001393,0.003714,0.094337,292.675140,14.909583,0.943368,-164.134705,294.500488,0.000000
90.930008,65.687996,-164.179184,-0.001384,0.003714,0.094337,292.194794,14.885113,0.943368,-164.179184,294.500488,0.000000
91.290001,65.604576,-164.134705,-0.001401,0.003714,0.094337,291.823730,14.866209,0.943368,-164.134705,294.500488,0.000000
91.650002,65.542397,-164.223679,-0.001371,0.003714,0.094345,291.547150,14.852119,0.943455,-164.223679,294.500488,0.000000
92.010002,65.438499,-164.268158,-0.001393,0.003714,0.094345,291.084991,14.828575,0.943455,-164.268158,294.500488,0.000000
92.370003,65.356575,-164.223679,-0.001388,0.003714,0.094345,290.720551,14.810012,0.943455,-164.223679,294.500488,0.000000
92.730003,65.272041,-164.312637,-0.001384,0.003714,0.094345,290.344543,14.790855,0.943455,-164.312637,294.500488,0.000000
93.090004,65.230339,-164.268158,-0.001393,0.003715,0.094354,290.159027,14.781406,0.943542,-164.268158,294.500488,0.000000
93.450005,65.130913,-164.312637,-0.001384,0.003715,0.094363,289.716766,14.758876,0.943628,-164.312637,294.500488,0.000000
93.810005,65.046394,-164.357117,-0.001380,0.003716,0.094380,289.340820,14.739723,0.943802,-164.357117,294.500488,0.000000
94.170006,64.986443,-164.268158,-0.001388,0.003716,0.094380,289.074127,14.726138,0.943802,-164.268158,294.500488,0.000000
94.530006,64.921272,-164.401596,-0.001397,0.003716,0.094380,288.784241,14.711370,0.943802,-164.401596,294.500488,0.000000
94.890007,64.841591,-164.312637,-0.001384,0.003716,0.094380,288.429810,14.693315,0.943802,-164.312637,294.500488,0.000000
95.250008,65.678673,-164.401596,-0.001367,0.003733,0.094822,292.153320,14.882999,0.948225,-164.401596,294.500488,0.000000
95.610008,65.725975,-164.446075,-0.001397,0.003733,0.094822,292.363739,14.893719,0.948225,-164.446075,294.500488,0.000000
95.970001,65.680534,-164.401596,-0.001384,0.003733,0.094822,292.161621,14.883422,0.948225,-164.401596,294.500488,0.000000
96.330002,65.658195,-164.579514,-0.001371,0.003733,0.094822,292.062225,14.878360,0.948225,-164.579514,294.500488,0.000000
96.690002,65.606071,-164.490555,-0.001393,0.003733,0.094822,291.830383,14.866549,0.948225,-164.490555,294.500488,0.000000
97.050003,65.563622,-164.490555,-0.001375,0.003733,0.094822,291.641541,14.856929,0.948225,-164.490555,294.500488,0.000000
97.410004,65.524895,-164.535034,-0.001371,0.003733,0.094822,291.469299,14.848153,0.948225,-164.535034,294.500488,0.000000
97.770004,65.475365,-164.579514,-0.001375,0.003733,0.094822,291.248962,14.836929,0.948225,-164.579514,294.500488,0.000000
98.130005,65.403862,-164.623993,-0.001380,0.003733,0.094822,290.930908,14.820727,0.948225,-164.623993,294.500488,0.000000
98.490005,65.346519,-164.579514,-0.001384,0.003733,0.094822,290.675842,14.807734,0.948225,-164.579514,294.500488,0.000000
98.850006,65.302208,-164.623993,-0.001380,0.003733,0.094822,290.478729,14.797691,0.948225,-164.623993,294.500488,0.000000
99.210007,65.271675,-164.623993,-0.001371,0.003733,0.094822,290.342926,14.790773,0.948225,-164.623993,294.500488,0.000000
99.570007,65.207634,-164.668488,-0.001375,0.003733,0.094822,290.058044,14.776261,0.948225,-164.668488,294.500488,0.000000
99.930008,65.188637,-164.712967,-0.001393,0.003734,0.094831,289.973541,14.771956,0.948311,-164.712967,294.500488,0.000000
100.290009,65.118629,-164.757446,-0.001371,0.003734,0.094831,289.662140,14.756093,0.948311,-164.757446,294.500488,0.000000
100.650002,65.065758,-164.668488,-0.001380,0.003734,0.094831,289.426941,14.744112,0.948311,-164.668488,294.500488,0.000000
101.010002,65.023674,-164.757446,-0.001375,0.003734,0.094840,289.239746,14.734575,0.948398,-164.757446,294.500488,0.000000
101.370003,65.499199,-164.668488,-0.001367,0.003741,0.095031,291.354980,14.842331,0.950306,-164.668488,294.500488,0.000000
101.730003,65.537544,-164.846405,-0.001371,0.003741,0.095031,291.525543,14.851020,0.950306,-164.846405,294.500488,0.000000
102.090004,65.530098,-164.801926,-0.001362,0.003741,0.095031,291.492432,14.849333,0.950306,-164.801926,294.500488,0.000000
102.450005,65.527122,-164.801926,-0.001354,0.003741,0.095031,291.479187,14.848658,0.950306,-164.801926,294.500488,0.000000
102.810005,65.486900,-164.890884,-0.001380,0.003741,0.095031,291.300293,14.839544,0.950306,-164.890884,294.500488,0.000000
103.170006,65.448555,-164.801926,-0.001375,0.003741,0.095031,291.129700,14.830854,0.950306,-164.801926,294.500488,0.000000
103.530006,65.390465,-164.979843,-0.001371,0.003741,0.095031,290.871307,14.817692,0.950306,-164.979843,294.500488,0.000000
103.890007,65.356575,-164.890884,-0.001371,0.003741,0.095031,290.720551,14.810012,0.950306,-164.890884,294.500488,0.000000
104.250008,65.317848,-164.979843,-0.001371,0.003741,0.095031,290.548309,14.801236,0.950306,-164.979843,294.500488,0.000000
104.610008,65.283958,-165.024323,-0.001362,0.003741,0.095031,290.397552,14.793556,0.950306,-165.024323,294.500488,0.000000
104.970001,65.256035,-164.979843,-0.001375,0.003741,0.095031,290.273346,14.787229,0.950306,-164.979843,294.500488,0.000000
105.330002,65.220284,-165.024323,-0.001358,0.003741,0.095031,290.114319,14.779127,0.950306,-165.024323,294.500488,0.000000
105.690002,65.174110,-165.024323,-0.001362,0.003741,0.095031,289.908936,14.768664,0.950306,-165.024323,294.500488,0.000000
106.050003,65.145821,-165.068802,-0.001354,0.003741,0.095031,289.783081,14.762254,0.950306,-165.068802,294.500488,0.000000
106.410004,65.114906,-165.157776,-0.001380,0.003742,0.095039,289.645569,14.755248,0.950393,-165.157776,294.500488,0.000000
106.770004,65.060921,-165.068802,-0.001358,0.003742,0.095039,289.405426,14.743015,0.950393,-165.068802,294.500488,0.000000
107.130005,65.027397,-165.113297,-0.001375,0.003742,0.095057,289.256317,14.735419,0.950566,-165.113297,294.500488,0.000000
107.490005,65.042290,-165.113297,-0.001362,0.003743,0.095065,289.322540,14.738793,0.950653,-165.113297,294.500488,0.000000
107.850006,65.383018,-165.113297,-0.001350,0.003748,0.095204,290.838196,14.816004,0.952040,-165.113297,294.500488,0.000000
108.210007,65.444450,-165.246735,-0.001358,0.003748,0.095195,291.111450,14.829925,0.951954,-165.246735,294.500488,0.000000
108.570007,65.424355,-165.202255,-0.001358,0.003748,0.095195,291.022064,14.825371,0.951954,-165.202255,294.500488,0.000000
108.930008,65.413551,-165.246735,-0.001350,0.003748,0.095195,290.973999,14.822923,0.951954,-165.246735,294.500488,0.000000
109.290009,65.386742,-165.246735,-0.001354,0.003748,0.095195,290.854767,14.816847,0.951954,-165.246735,294.500488,0.000000
109.650002,65.365135,-165.291214,-0.001367,0.003748,0.095195,290.758636,14.811952,0.951954,-165.291214,294.500488,0.000000
110.010002,65.340569,-165.335693,-0.001362,0.003748,0.095204,290.649353,14.806384,0.952040,-165.335693,294.500488,0.000000
110.370003,65.299980,-165.335693,-0.001350,0.003748,0.095204,290.468811,14.797187,0.952040,-165.335693,294.500488,0.000000
110.730003,65.269447,-165.424652,-0.001362,0.003748,0.095204,290.333008,14.790268,0.952040,-165.424652,294.500488,0.000000
111.090004,65.246727,-165.335693,-0.001358,0.003748,0.095204,290.231934,14.785120,0.952040,-165.335693,294.500488,0.000000
111.450005,65.238914,-165.424652,-0.001358,0.003748,0.095204,290.197174,14.783349,0.952040,-165.424652,294.500488,0.000000
111.810005,65.191612,-165.424652,-0.001358,0.003748,0.095204,289.986786,14.772631,0.952040,-165.424652,294.500488,0.000000
112.170006,65.171883,-165.380173,-0.001345,0.003749,0.095213,289.899017,14.768160,0.952127,-165.380173,294.500488,0.000000
112.530006,65.152519,-165.424652,-0.001354,0.003749,0.095213,289.812866,14.763772,0.952127,-165.424652,294.500488,0.000000
112.890007,65.107826,-165.469131,-0.001367,0.003749,0.095213,289.614075,14.753644,0.952127,-165.469131,294.500488,0.000000
113.250008,65.077675,-165.469131,-0.001358,0.003749,0.095213,289.479950,14.746812,0.952127,-165.469131,294.500488,0.000000
113.610008,65.044533,-165.558105,-0.001367,0.003749,0.095213,289.332520,14.739302,0.952127,-165.558105,294.500488,0.000000
113.970009,65.022560,-165.469131,-0.001362,0.003749,0.095213,289.234802,14.734323,0.952127,-165.469131,294.500488,0.000000
114.330002,65.001701,-165.602585,-0.001362,0.003749,0.095213,289.141998,14.729596,0.952127,-165.602585,294.500488,0.000000
114.690002,64.983086,-165.558105,-0.001362,0.003749,0.095213,289.059204,14.725378,0.952127,-165.558105,294.500488,0.000000
115.050003,65.401268,-165.647064,-0.001345,0.003755,0.095386,290.919373,14.820139,0.953862,-165.647064,294.500488,0.000000
115.410004,65.482811,-165.602585,-0.001358,0.003755,0.095386,291.282104,14.838617,0.953862,-165.602585,294.500488,0.000000
115.770004,65.484673,-165.647064,-0.001337,0.003755,0.095377,291.290375,14.839039,0.953775,-165.647064,294.500488,0.000000
116.130005,65.451530,-165.647064,-0.001358,0.003755,0.095377,291.142944,14.831529,0.953775,-165.647064,294.500488,0.000000
116.490005,65.419502,-165.691544,-0.001350,0.003755,0.095377,291.000488,14.824271,0.953775,-165.691544,294.500488,0.000000
116.850006,65.403862,-165.691544,-0.001354,0.003755,0.095377,290.930908,14.820727,0.953775,-165.691544,294.500488,0.000000
117.210007,65.363274,-165.736023,-0.001358,0.003755,0.095377,290.750366,14.811529,0.953775,-165.736023,294.500488,0.000000
117.570007,65.352104,-165.691544,-0.001358,0.003755,0.095377,290.700684,14.808999,0.953775,-165.691544,294.500488,0.000000
117.930008,65.334984,-165.780502,-0.001362,0.003755,0.095377,290.624512,14.805119,0.953775,-165.780502,294.500488,0.000000
118.290009,65.306679,-165.780502,-0.001354,0.003755,0.095377,290.498627,14.798705,0.953775,-165.780502,294.500488,0.000000
118.650009,65.283226,-165.824982,-0.001354,0.003755,0.095377,290.394287,14.793390,0.953775,-165.824982,294.500488,0.000000
119.010002,65.279503,-165.824982,-0.001380,0.003755,0.095377,290.377716,14.792547,0.953775,-165.824982,294.500488,0.000000
119.370003,65.248222,-165.869461,-0.001358,0.003755,0.095377,290.238586,14.785459,0.953775,-165.869461,294.500488,0.000000
119.730003,65.222527,-165.913940,-0.001350,0.003755,0.095377,290.124298,14.779635,0.953775,-165.913940,294.500488,0.000000
120.090004,65.196831,-165.958435,-0.001362,0.003755,0.095377,290.009979,14.773812,0.953775,-165.958435,294.500488,0.000000
120.450005,65.179329,-165.913940,-0.001345,0.003755,0.095377,289.932129,14.769847,0.953775,-165.913940,294.500488,0.000000
120.810005,65.144325,-165.913940,-0.001358,0.003755,0.095377,289.776428,14.761915,0.953775,-165.913940,294.500488,0.000000
121.170006,65.129051,-166.002914,-0.001345,0.003755,0.095377,289.708496,14.758454,0.953775,-166.002914,294.500488,0.000000
121.530006,65.082146,-166.091873,-0.001345,0.003756,0.095403,289.499847,14.747825,0.954035,-166.091873,294.500488,0.000000
121.890007,65.086235,-166.002914,-0.001367,0.003756,0.095403,289.518036,14.748752,0.954035,-166.002914,294.500488,0.000000
122.250008,65.092186,-166.136353,-0.001345,0.003756,0.095403,289.544495,14.750100,0.954035,-166.136353,294.500488,0.000000
122.610008,65.056450,-166.091873,-0.001375,0.003756,0.095412,289.385529,14.742002,0.954122,-166.091873,294.500488,0.000000
122.970009,65.041557,-166.047394,-0.001354,0.003756,0.095412,289.319305,14.738627,0.954122,-166.047394,294.500488,0.000000
123.330009,65.023674,-166.180832,-0.001337,0.003756,0.095412,289.239746,14.734575,0.954122,-166.180832,294.500488,0.000000
123.690002,65.009895,-166.136353,-0.001350,0.003756,0.095412,289.178467,14.731453,0.954122,-166.136353,294.500488,0.000000
124.050003,64.999107,-166.180832,-0.001345,0.003756,0.095412,289.130463,14.729008,0.954122,-166.180832,294.500488,0.000000
124.410004,64.977135,-166.225311,-0.001358,0.003756,0.095412,289.032745,14.724030,0.954122,-166.225311,294.500488,0.000000
124.770004,64.971550,-166.225311,-0.001332,0.003757,0.095421,289.007874,14.722764,0.954208,-166.225311,294.500488,0.000000
125.130005,64.960747,-166.314270,-0.001362,0.003757,0.095421,288.959839,14.720315,0.954208,-166.314270,294.500488,0.000000
125.490005,64.941017,-166.225311,-0.001350,0.003757,0.095421,288.872070,14.715845,0.954208,-166.225311,294.500488,0.000000
125.850006,64.928352,-166.314270,-0.001341,0.003757,0.095421,288.815735,14.712975,0.954208,-166.314270,294.500488,0.000000
126.210007,64.907875,-166.358749,-0.001354,0.003757,0.095421,288.724640,14.708335,0.954208,-166.358749,294.500488,0.000000
126.570007,64.865791,-166.314270,-0.001354,0.003757,0.095430,288.537445,14.698799,0.954295,-166.314270,294.500488,0.000000
126.930008,64.857231,-166.358749,-0.001358,0.003757,0.095430,288.499359,14.696858,0.954295,-166.358749,294.500488,0.000000
127.290009,64.844933,-166.447723,-0.001350,0.003757,0.095430,288.444672,14.694072,0.954295,-166.447723,294.500488,0.000000
127.650009,64.833397,-166.447723,-0.001345,0.003757,0.095430,288.393341,14.691458,0.954295,-166.447723,294.500488,0.000000
128.010010,64.825951,-166.447723,-0.001345,0.003757,0.095438,288.360229,14.689770,0.954382,-166.447723,294.500488,0.000000
128.370010,64.901161,-166.403244,-0.001345,0.003760,0.095499,288.694794,14.706813,0.954989,-166.403244,294.500488,0.000000
128.730011,64.926109,-166.536682,-0.001345,0.003760,0.095499,288.805756,14.712466,0.954989,-166.536682,294.500488,0.000000
129.090012,64.929100,-166.492203,-0.001358,0.003760,0.095499,288.819061,14.713144,0.954989,-166.492203,294.500488,0.000000
129.450012,64.941383,-166.581161,-0.001354,0.003760,0.095499,288.873688,14.715928,0.954989,-166.581161,294.500488,0.000000
129.810013,64.926857,-166.581161,-0.001362,0.003760,0.095499,288.809082,14.712636,0.954989,-166.581161,294.500488,0.000000
130.170013,64.935799,-166.536682,-0.001345,0.003755,0.095369,288.848846,14.714663,0.953688,-166.536682,0.095499,0.000000
130.529999,64.876595,-166.625641,-0.001345,0.003748,0.095204,288.585510,14.701246,0.952040,-166.625641,0.094944,0.000000
130.889999,64.889626,-166.581161,-0.001337,0.003730,0.094744,288.643463,14.704200,0.947444,-166.581161,0.094345,0.000000
131.250000,64.711250,-166.670120,-0.001332,0.003712,0.094276,287.850006,14.663779,0.942761,-166.670120,0.093747,0.000000
131.610001,64.711250,-166.625641,-0.001341,0.003693,0.093808,287.850006,14.663779,0.938078,-166.625641,0.093140,0.000000
131.970001,64.691887,-166.625641,-0.001337,0.003667,0.093149,287.763885,14.659391,0.931487,-166.625641,0.092542,0.000000
132.330002,64.660240,-166.670120,-0.001341,0.003643,0.092533,287.623108,14.652220,0.925330,-166.670120,0.091943,0.000000
132.690002,64.637154,-166.625641,-0.001332,0.003630,0.092203,287.520416,14.646988,0.922035,-166.625641,0.091345,0.000000
133.050003,64.543312,-166.714600,-0.001337,0.003594,0.091276,287.102997,14.625724,0.912755,-166.714600,0.090746,0.000000
133.410004,64.503105,-166.759079,-0.001341,0.003571,0.090703,286.924133,14.616612,0.907031,-166.759079,0.090139,0.000000
133.770004,64.452080,-166.759079,-0.001337,0.003553,0.090252,286.697174,14.605050,0.902522,-166.759079,0.089541,0.000000
134.130005,64.310585,-166.848053,-0.001337,0.003528,0.089610,286.067780,14.572988,0.896104,-166.848053,0.088943,0.000000
134.490005,63.925545,-166.759079,-0.001337,0.003511,0.089168,284.355011,14.485736,0.891681,-166.759079,0.088344,0.000000
134.850006,62.938393,-166.848053,-0.001337,0.003483,0.088466,279.963959,14.262044,0.884657,-166.848053,0.087746,0.000000
135.210007,61.953094,-166.848053,-0.001350,0.003461,0.087902,275.581116,14.038772,0.879020,-166.848053,0.087148,0.000000
135.570007,60.752937,-166.848053,-0.001332,0.003439,0.087347,270.242554,13.766812,0.873470,-166.848053,0.086540,0.000000
135.930008,59.114128,-166.981491,-0.001350,0.003416,0.086757,262.952789,13.395452,0.867573,-166.981491,0.085942,0.000000
136.290009,58.214104,-166.937012,-0.001337,0.003405,0.086488,258.949280,13.191504,0.864884,-166.937012,0.085344,0.000000
136.650009,56.593536,-166.892532,-0.001341,0.003386,0.086003,251.740616,12.824279,0.860028,-166.892532,0.084745,0.000000
137.010010,54.604698,-167.025970,-0.001350,0.003356,0.085248,242.893829,12.373601,0.852483,-167.025970,0.084147,0.000000
137.370010,51.854721,-166.981491,-0.001328,0.003332,0.084633,230.661316,11.750448,0.846326,-166.981491,0.083540,0.000000
137.730011,49.489784,-167.070450,-0.001341,0.003306,0.083965,220.141556,11.214546,0.839648,-167.070450,0.082941,0.000000
138.090012,47.041069,-166.981491,-0.001345,0.003282,0.083375,209.249130,10.659658,0.833751,-166.981491,0.082343,0.000000
138.450012,44.679482,-167.070450,-0.001337,0.003261,0.082820,198.744263,10.124516,0.828201,-167.070450,0.081745,0.000000
138.810013,41.743698,-167.070450,-0.001358,0.003233,0.082118,185.685242,9.459257,0.821176,-167.070450,0.081146,0.000000
139.170013,38.762856,-167.070450,-0.001345,0.003206,0.081433,172.425797,8.783789,0.814325,-167.070450,0.080539,0.000000
139.530014,36.320465,-167.114929,-0.001350,0.003183,0.080860,161.561493,8.230335,0.808601,-167.114929,0.079941,0.000000
139.889999,34.234062,-167.114929,-0.001358,0.003165,0.080383,152.280716,7.757549,0.803832,-167.114929,0.079342,0.000000
140.250000,32.530457,-167.159409,-0.001337,0.003150,0.080019,144.702698,7.371507,0.800189,-167.159409,0.078744,0.000000
140.610001,29.870598,-167.203888,-0.001354,0.003120,0.079256,132.871048,6.768774,0.792558,-167.203888,0.078146,0.000000
140.970001,26.597443,-167.159409,-0.001354,0.003089,0.078467,118.311333,6.027066,0.784666,-167.159409,0.077539,0.000000
141.330002,24.660362,-167.203888,-0.001362,0.003076,0.078120,109.694771,5.588118,0.781197,-167.203888,0.076940,0.000000
141.690002,22.081680,-167.159409,-0.001367,0.003050,0.077478,98.224220,5.003780,0.774780,-167.159409,0.076342,0.000000
142.050003,19.394646,-167.337341,-0.001375,0.003024,0.076819,86.271690,4.394889,0.768189,-167.337341,0.075744,0.000000
142.410004,17.144768,-167.292862,-0.001375,0.003006,0.076359,76.263733,3.885060,0.763592,-167.292862,0.075145,0.000000
142.770004,13.537598,-167.248383,-0.001375,0.002970,0.075431,60.218243,3.067663,0.754313,-167.248383,0.074547,0.000000
143.130005,11.101906,-167.337341,-0.001401,0.002948,0.074876,49.383743,2.515728,0.748763,-167.337341,0.073940,0.000000
143.490005,9.321594,-167.337341,-0.001397,0.002926,0.074321,41.464523,2.112303,0.743213,-167.337341,0.073341,0.000000
143.850006,6.512794,-167.381821,-0.001397,0.002904,0.073766,28.970356,1.475820,0.737662,-167.381821,0.072743,0.000000
144.210007,4.118439,-167.381821,-0.001414,0.002881,0.073177,18.319731,0.933252,0.731765,-167.381821,0.072145,0.000000
144.570007,2.630066,-167.337341,-0.001406,0.002867,0.072821,11.699118,0.595981,0.728210,-167.337341,0.071546,0.000000
144.930008,-0.365303,-167.426300,-0.001418,0.002834,0.071988,-1.624949,-0.082779,0.719884,-167.426300,0.070939,0.000000
145.290009,-1.880486,-167.426300,-0.001440,0.002814,0.071477,-8.364818,-0.426124,0.714767,-167.426300,0.070341,0.000000
145.650009,-0.231247,-167.426300,-0.001453,0.002788,0.070826,-1.028638,-0.052401,0.708263,-167.426300,0.069742,0.000000
146.010010,-0.198853,-167.515259,-0.001505,0.002760,0.070098,-0.884540,-0.045061,0.700979,-167.515259,0.069144,0.000000
146.370010,0.043190,-167.470779,-0.001552,0.002738,0.069552,0.192119,0.009787,0.695515,-167.470779,0.068546,0.000000
146.730011,0.008934,-167.515259,-0.001569,0.002715,0.068970,0.039741,0.002024,0.689705,-167.515259,0.067938,0.000000
147.000000,0.077080,-167.515259,-0.001591,0.002709,0.068814,0.342868,0.017467,0.688144,-167.515259,0.068615,0.000000