File: Data/compression 33/AutoNoHeating-10-33-reverse-1-2_11152024_173423.csv
Time (sec),S:Load (lbs),S:HL1 (DIM),S:LVDT (in),S:Position (in),Ch:Position (mm),Ch:Load (N),Ch:Stress (MPa),Ch:Strain (mm/mm),Ch:HL1 (DIM),Set Point (),Cycles ()
0.110000,0.024574,-645.640991,-0.008481,-0.008272,-0.210120,0.109312,0.005569,-2.101201,-645.640991,-0.209860,0.000000
0.520000,-0.014893,-645.640991,-0.008481,-0.008194,-0.208126,-0.066245,-0.003375,-2.081255,-645.640991,-0.207328,0.000000
0.930000,-0.027931,-645.685486,-0.008291,-0.007945,-0.201812,-0.124244,-0.006329,-2.018121,-645.685486,-0.200511,0.000000
1.340000,-0.046547,-645.640991,-0.007998,-0.007673,-0.194892,-0.207051,-0.010548,-1.948916,-645.640991,-0.193677,0.000000
1.750000,-0.086021,-645.729980,-0.007743,-0.007408,-0.188162,-0.382642,-0.019493,-1.881620,-645.729980,-0.186844,0.000000
2.160000,-0.065536,-645.640991,-0.007476,-0.007138,-0.181294,-0.291521,-0.014851,-1.812935,-645.640991,-0.180010,0.000000
2.570000,-0.072617,-645.729980,-0.007183,-0.006867,-0.174416,-0.323015,-0.016455,-1.744164,-645.729980,-0.173176,0.000000
2.980000,-0.028671,-645.774475,-0.006885,-0.006604,-0.167730,-0.127536,-0.006497,-1.677301,-645.774475,-0.166343,0.000000
3.390000,-0.056602,-645.729980,-0.006631,-0.006336,-0.160922,-0.251780,-0.012826,-1.609224,-645.729980,-0.159526,0.000000
3.800000,-0.025696,-645.729980,-0.006359,-0.006059,-0.153898,-0.114301,-0.005823,-1.538979,-645.729980,-0.152692,0.000000
4.210000,-0.009308,-645.774475,-0.006088,-0.005789,-0.147038,-0.041403,-0.002109,-1.470381,-645.774475,-0.145859,0.000000
4.620000,-0.024948,-645.818909,-0.005808,-0.005524,-0.140308,-0.110975,-0.005653,-1.403085,-645.818909,-0.139025,0.000000
5.030000,-0.018250,-645.729980,-0.005527,-0.005259,-0.133587,-0.081178,-0.004135,-1.335875,-645.729980,-0.132191,0.000000
5.440000,-0.061813,-645.818909,-0.005251,-0.004986,-0.126632,-0.274960,-0.014007,-1.266323,-645.818909,-0.125375,0.000000
5.850000,-0.025696,-645.863403,-0.004984,-0.004713,-0.119703,-0.114301,-0.005823,-1.197032,-645.863403,-0.118541,0.000000
6.260000,0.013405,-645.774475,-0.004898,0.000006,0.000156,0.059628,0.003038,0.001561,-645.774475,0.000390,0.000000
6.670001,0.077080,-645.863403,-0.004911,0.000006,0.000156,0.342868,0.017467,0.001561,-645.863403,0.000728,0.000000
7.080000,0.119530,-645.774475,-0.004902,0.000019,0.000486,0.531695,0.027086,0.004856,-645.774475,0.001414,0.000000
7.490000,0.132195,-645.818909,-0.004889,0.000039,0.000997,0.588031,0.029956,0.009973,-645.818909,0.002099,0.000000
7.900001,0.207413,-645.863403,-0.004885,0.000061,0.001561,0.922618,0.047000,0.015610,-645.863403,0.002775,0.000000
8.310000,0.270340,-645.863403,-0.004820,0.000088,0.002237,1.202532,0.061260,0.022374,-645.863403,0.003460,0.000000
8.720000,0.445358,-645.996826,-0.004799,0.000120,0.003044,1.981053,0.100920,0.030440,-645.996826,0.004145,0.000000
9.130000,0.654259,-645.907898,-0.004769,0.000149,0.003781,2.910288,0.148257,0.037811,-645.907898,0.004830,0.000000
9.540001,0.778259,-645.907898,-0.004747,0.000179,0.004544,3.461870,0.176356,0.045443,-645.907898,0.005516,0.000000
9.950001,0.914177,-645.952393,-0.004712,0.000202,0.005134,4.066462,0.207155,0.051340,-645.952393,0.006192,0.000000
10.360001,1.113396,-645.952393,-0.004700,0.000228,0.005802,4.952631,0.252299,0.058017,-645.952393,0.006877,0.000000
10.770000,1.379265,-646.041321,-0.004665,0.000253,0.006435,6.135276,0.312546,0.064348,-646.041321,0.007562,0.000000
11.180000,1.581841,-645.952393,-0.004622,0.000281,0.007146,7.036378,0.358450,0.071459,-645.952393,0.008247,0.000000
11.590000,1.767654,-646.041321,-0.004600,0.000305,0.007744,7.862919,0.400556,0.077443,-646.041321,0.008932,0.000000
12.000001,1.997032,-646.041321,-0.004579,0.000334,0.008481,8.883243,0.452534,0.084815,-646.041321,0.009618,0.000000
12.410001,2.082306,-645.952393,-0.004544,0.000352,0.008941,9.262559,0.471857,0.089411,-645.952393,0.010294,0.000000
12.820001,2.551865,-645.996826,-0.004506,0.000392,0.009964,11.351261,0.578261,0.099644,-645.996826,0.010979,0.000000
13.230000,2.693741,-645.996826,-0.004471,0.000419,0.010641,11.982358,0.610410,0.106409,-645.996826,0.011664,0.000000
13.640000,2.925728,-646.041321,-0.004462,0.000444,0.011283,13.014287,0.662979,0.112826,-646.041321,0.012349,0.000000
14.050000,3.072075,-646.085815,-0.004428,0.000472,0.011976,13.665272,0.696142,0.119764,-646.085815,0.013034,0.000000
14.460001,3.327522,-646.085815,-0.004398,0.000497,0.012635,14.801558,0.754027,0.126355,-646.085815,0.013711,0.000000
14.870001,3.567329,-646.130310,-0.004363,0.000527,0.013390,15.868274,0.808368,0.133900,-646.130310,0.014396,0.000000
15.280001,3.699890,-646.085815,-0.004333,0.000548,0.013928,16.457933,0.838407,0.139276,-646.085815,0.015081,0.000000
15.690001,3.846603,-646.130310,-0.004307,0.000575,0.014613,17.110546,0.871653,0.146128,-646.130310,0.015766,0.000000
16.100000,4.093864,-646.085815,-0.004268,0.000609,0.015471,18.210419,0.927683,0.154713,-646.085815,0.016451,0.000000
16.510000,4.165733,-646.130310,-0.004238,0.000635,0.016139,18.530107,0.943969,0.161391,-646.130310,0.017128,0.000000
16.920000,4.287498,-646.174805,-0.004199,0.000660,0.016763,19.071745,0.971561,0.167635,-646.174805,0.017813,0.000000
17.330000,4.328453,-646.130310,-0.004174,0.000681,0.017292,19.253922,0.980841,0.172925,-646.130310,0.018498,0.000000
17.740002,4.609222,-646.219238,-0.004130,0.000716,0.018177,20.502846,1.044465,0.181771,-646.219238,0.019183,0.000000
18.150002,4.463257,-646.130310,-0.004109,0.000728,0.018498,19.853558,1.011388,0.184979,-646.130310,0.019868,0.000000
18.560001,4.770088,-646.174805,-0.004070,0.000766,0.019452,21.218412,1.080917,0.194519,-646.174805,0.020545,0.000000
18.970001,4.815147,-646.219238,-0.004036,0.000795,0.020189,21.418846,1.091128,0.201890,-646.219238,0.021230,0.000000
19.380001,4.852386,-646.219238,-0.003980,0.000814,0.020683,21.584494,1.099567,0.206833,-646.219238,0.021915,0.000000
19.790001,4.958138,-646.263733,-0.003962,0.000847,0.021525,22.054897,1.123530,0.215245,-646.263733,0.022600,0.000000
20.200001,5.120117,-646.219238,-0.003928,0.000874,0.022210,22.775419,1.160235,0.222097,-646.219238,0.023285,0.000000
20.610001,5.249336,-646.219238,-0.003867,0.000906,0.023025,23.350214,1.189517,0.230248,-646.219238,0.023961,0.000000
21.020000,5.115280,-646.219238,-0.003850,0.000925,0.023502,22.753902,1.159139,0.235018,-646.219238,0.024647,0.000000
21.430000,5.334976,-646.263733,-0.003807,0.000956,0.024291,23.731159,1.208923,0.242910,-646.263733,0.025332,0.000000
21.840000,5.222893,-646.308228,-0.003773,0.000979,0.024855,23.232588,1.183524,0.248547,-646.308228,0.026017,0.000000
22.250002,5.319710,-646.219238,-0.003738,0.001002,0.025462,23.663250,1.205463,0.254617,-646.219238,0.026702,0.000000
22.660002,5.601227,-646.308228,-0.003708,0.001037,0.026338,24.915501,1.269256,0.263376,-646.308228,0.027378,0.000000
23.070002,5.478714,-646.263733,-0.003669,0.001058,0.026867,24.370537,1.241494,0.268667,-646.263733,0.028063,0.000000
23.480001,5.658195,-646.263733,-0.003617,0.001089,0.027673,25.168911,1.282165,0.276732,-646.263733,0.028749,0.000000
23.890001,5.719269,-646.352722,-0.003596,0.001116,0.028358,25.440578,1.296005,0.283583,-646.352722,0.029434,0.000000
24.300001,5.547234,-646.308228,-0.003570,0.001131,0.028731,24.675327,1.257021,0.287312,-646.308228,0.030119,0.000000
24.710001,5.987373,-646.352722,-0.003518,0.001174,0.029824,26.633167,1.356758,0.298239,-646.352722,0.030795,0.000000
25.120001,5.994080,-646.352722,-0.003497,0.001201,0.030500,26.662998,1.358278,0.305003,-646.352722,0.031480,0.000000
25.530001,5.974716,-646.397156,-0.003436,0.001227,0.031177,26.576864,1.353890,0.311768,-646.397156,0.032165,0.000000
25.940001,6.079727,-646.397156,-0.003428,0.001255,0.031871,27.043978,1.377686,0.318705,-646.397156,0.032851,0.000000
26.350000,6.121429,-646.441650,-0.003376,0.001280,0.032512,27.229479,1.387136,0.325123,-646.441650,0.033536,0.000000
26.760002,6.087547,-646.486145,-0.003346,0.001301,0.033041,27.078762,1.379458,0.330413,-646.486145,0.034212,0.000000
27.170002,6.351929,-646.397156,-0.003316,0.001335,0.033909,28.254789,1.439368,0.339085,-646.397156,0.034897,0.000000
27.580002,6.323257,-646.441650,-0.003272,0.001361,0.034568,28.127254,1.432871,0.345676,-646.441650,0.035582,0.000000
27.990002,6.481514,-646.441650,-0.003234,0.001389,0.035279,28.831215,1.468732,0.352787,-646.441650,0.036267,0.000000
28.400002,6.554131,-646.486145,-0.003212,0.001417,0.035981,29.154228,1.485187,0.359812,-646.486145,0.036952,0.000000
28.810001,6.573860,-646.486145,-0.003160,0.001438,0.036528,29.241991,1.489658,0.365275,-646.486145,0.037629,0.000000
29.220001,6.719460,-646.530640,-0.003147,0.001469,0.037308,29.889648,1.522651,0.373081,-646.530640,0.038314,0.000000
29.630001,6.572746,-646.530640,-0.003104,0.001487,0.037768,29.237036,1.489406,0.377677,-646.530640,0.038999,0.000000
30.040001,6.909370,-646.486145,-0.003074,0.001519,0.038592,30.734415,1.565686,0.385915,-646.486145,0.039684,0.000000
30.450001,6.950333,-646.530640,-0.003022,0.001547,0.039303,30.916624,1.574968,0.393027,-646.530640,0.040369,0.000000
30.860001,6.952194,-646.530640,-0.002997,0.001574,0.039970,30.924904,1.575390,0.399704,-646.530640,0.041046,0.000000
31.270002,6.917938,-646.530640,-0.002958,0.001601,0.040656,30.772526,1.567627,0.406555,-646.530640,0.041731,0.000000
31.680002,6.985710,-646.486145,-0.002923,0.001627,0.041323,31.073990,1.582985,0.413233,-646.486145,0.042416,0.000000
32.090000,7.224770,-646.575134,-0.002893,0.001656,0.042060,32.137379,1.637156,0.420604,-646.575134,0.043101,0.000000
32.500000,7.216576,-646.530640,-0.002850,0.001680,0.042676,32.100933,1.635299,0.426762,-646.530640,0.043786,0.000000
32.910000,7.187157,-646.619568,-0.002820,0.001703,0.043266,31.970070,1.628633,0.432659,-646.619568,0.044463,0.000000
33.320000,7.321587,-646.575134,-0.002790,0.001732,0.044003,32.568043,1.659095,0.440030,-646.575134,0.045148,0.000000
33.730003,7.190140,-646.619568,-0.002751,0.001751,0.044471,31.983339,1.629309,0.444713,-646.619568,0.045833,0.000000
34.140003,7.643692,-646.575134,-0.002738,0.001790,0.045469,34.000839,1.732085,0.454686,-646.575134,0.046518,0.000000
34.550003,7.573311,-646.619568,-0.002677,0.001819,0.046197,33.687771,1.716137,0.461971,-646.619568,0.047203,0.000000
34.960003,7.340950,-646.619568,-0.002652,0.001834,0.046596,32.654175,1.663483,0.465960,-646.619568,0.047880,0.000000
35.370003,7.634750,-646.664062,-0.002604,0.001870,0.047507,33.961067,1.730059,0.475066,-646.664062,0.048565,0.000000
35.780003,7.645180,-646.664062,-0.002557,0.001895,0.048131,34.007458,1.732423,0.481310,-646.664062,0.049250,0.000000
36.190002,7.847374,-646.575134,-0.002518,0.001927,0.048938,34.906864,1.778240,0.489375,-646.575134,0.049935,0.000000
36.600002,7.802322,-646.664062,-0.002483,0.001949,0.049510,34.706463,1.768032,0.495099,-646.664062,0.050620,0.000000
37.010002,7.992226,-646.753052,-0.002445,0.001980,0.050290,35.551197,1.811064,0.502904,-646.753052,0.051296,0.000000
37.420002,7.981430,-646.708557,-0.002397,0.002009,0.051028,35.503174,1.808618,0.510276,-646.708557,0.051982,0.000000
37.830002,7.964302,-646.708557,-0.002367,0.002034,0.051661,35.426987,1.804737,0.516606,-646.708557,0.052667,0.000000
38.240002,8.003403,-646.797485,-0.002337,0.002058,0.052285,35.600914,1.813597,0.522850,-646.797485,0.053352,0.000000
38.650002,7.921104,-646.753052,-0.002307,0.002078,0.052771,35.234833,1.794948,0.527707,-646.753052,0.054037,0.000000
39.060001,8.355293,-646.797485,-0.002285,0.002115,0.053725,37.166203,1.893337,0.537246,-646.797485,0.054713,0.000000
39.470001,7.913284,-646.708557,-0.002229,0.002127,0.054019,35.200047,1.793176,0.540195,-646.708557,0.055398,0.000000
39.880001,8.313217,-646.797485,-0.002190,0.002166,0.055008,36.979038,1.883802,0.550081,-646.797485,0.056083,0.000000
40.290001,8.295715,-646.753052,-0.002164,0.002193,0.055711,36.901184,1.879836,0.557106,-646.753052,0.056769,0.000000
40.700001,8.358643,-646.797485,-0.002108,0.002219,0.056361,37.181099,1.894096,0.563610,-646.797485,0.057454,0.000000
41.110001,8.463280,-646.797485,-0.002082,0.002247,0.057072,37.646549,1.917807,0.570721,-646.797485,0.058130,0.000000
41.520000,8.562706,-646.841980,-0.002052,0.002273,0.057731,38.088818,1.940337,0.577312,-646.841980,0.058815,0.000000
41.930000,8.681122,-646.841980,-0.001996,0.002306,0.058581,38.615559,1.967170,0.585811,-646.841980,0.059500,0.000000
42.340000,8.344124,-646.797485,-0.001962,0.002324,0.059023,37.116516,1.890805,0.590234,-646.797485,0.060185,0.000000
42.750004,8.116600,-646.886475,-0.001927,0.002345,0.059552,36.104439,1.839248,0.595524,-646.886475,0.060871,0.000000
43.160004,8.453598,-646.841980,-0.001897,0.002377,0.060376,37.603481,1.915613,0.603763,-646.841980,0.061547,0.000000
43.570004,8.425301,-646.841980,-0.001854,0.002396,0.060871,37.477608,1.909200,0.608706,-646.841980,0.062232,0.000000
43.980003,8.890022,-646.930969,-0.001811,0.002436,0.061868,39.544796,2.014508,0.618679,-646.930969,0.062917,0.000000
44.390003,8.604782,-646.930969,-0.001785,0.002460,0.062492,38.275982,1.949872,0.624923,-646.930969,0.063602,0.000000
44.800003,8.780914,-646.930969,-0.001738,0.002488,0.063203,39.059456,1.989784,0.632034,-646.930969,0.064287,0.000000
45.210003,8.795067,-646.975403,-0.001725,0.002514,0.063854,39.122410,1.992991,0.638538,-646.975403,0.064964,0.000000
45.620003,8.422691,-646.886475,-0.001664,0.002529,0.064235,37.466003,1.908609,0.642354,-646.886475,0.065649,0.000000
46.030003,9.100410,-646.975403,-0.001617,0.002573,0.065345,40.480648,2.062182,0.653455,-646.975403,0.066334,0.000000
46.440002,9.035614,-646.930969,-0.001578,0.002600,0.066048,40.192417,2.047499,0.660479,-646.930969,0.067019,0.000000
46.850002,8.918320,-646.975403,-0.001531,0.002627,0.066716,39.670666,2.020920,0.667157,-646.975403,0.067704,0.000000
47.260002,8.992050,-646.975403,-0.001500,0.002654,0.067409,39.998638,2.037628,0.674094,-646.975403,0.068381,0.000000
47.670002,9.046791,-646.930969,-0.001449,0.002679,0.068043,40.242138,2.050032,0.680425,-646.930969,0.069066,0.000000
48.080002,9.248611,-647.108887,-0.001436,0.002707,0.068754,41.139877,2.095765,0.687537,-647.108887,0.069751,0.000000
48.490002,9.278030,-647.019897,-0.001406,0.002734,0.069447,41.270741,2.102432,0.694474,-647.019897,0.070436,0.000000
48.900002,9.244888,-647.064392,-0.001345,0.002760,0.070098,41.123318,2.094922,0.700979,-647.064392,0.071121,0.000000
49.310001,9.438522,-647.064392,-0.001332,0.002787,0.070800,41.984646,2.138800,0.708003,-647.064392,0.071798,0.000000
49.720001,9.486931,-647.019897,-0.001298,0.002813,0.071451,42.199978,2.149769,0.714507,-647.019897,0.072483,0.000000
50.130001,9.497360,-647.064392,-0.001250,0.002837,0.072049,42.246368,2.152133,0.720491,-647.064392,0.073168,0.000000
50.540001,9.422882,-647.019897,-0.001220,0.002856,0.072543,41.915073,2.135256,0.725434,-647.019897,0.073853,0.000000
50.950001,9.582260,-647.153381,-0.001186,0.002887,0.073341,42.624023,2.171371,0.733413,-647.153381,0.074538,0.000000
51.360001,9.907341,-647.108887,-0.001160,0.002914,0.074018,44.070053,2.245036,0.740177,-647.108887,0.075214,0.000000
51.770004,10.273010,-647.064392,-0.001108,0.002946,0.074824,45.696632,2.327898,0.748242,-647.064392,0.075900,0.000000
52.180004,10.208221,-647.153381,-0.001082,0.002972,0.075492,45.408436,2.313216,0.754920,-647.153381,0.076585,0.000000
52.590004,10.377274,-647.064392,-0.001043,0.003003,0.076273,46.160419,2.351524,0.762725,-647.064392,0.077270,0.000000
53.000004,10.060760,-647.153381,-0.001018,0.003016,0.076611,44.752499,2.279801,0.766107,-647.153381,0.077955,0.000000
53.410004,10.907532,-647.197815,-0.000979,0.003051,0.077487,48.519123,2.471682,0.774866,-647.197815,0.078631,0.000000
53.820004,10.989830,-647.108887,-0.000927,0.003078,0.078189,48.885204,2.490331,0.781891,-647.108887,0.079316,0.000000
54.230003,11.098557,-647.242310,-0.000901,0.003102,0.078787,49.368847,2.514969,0.787875,-647.242310,0.080002,0.000000
54.640003,11.266502,-647.197815,-0.000875,0.003127,0.079429,50.115906,2.553026,0.794292,-647.197815,0.080687,0.000000
55.050003,11.393478,-647.286804,-0.000841,0.003149,0.079993,50.680721,2.581799,0.799929,-647.286804,0.081372,0.000000
55.460003,12.515068,-647.197815,-0.000824,0.003191,0.081060,55.669804,2.835955,0.810596,-647.197815,0.082048,0.000000
55.870003,12.373566,-647.242310,-0.000785,0.003217,0.081719,55.040367,2.803890,0.817187,-647.242310,0.082733,0.000000
56.280003,12.651352,-647.331299,-0.000759,0.003242,0.082352,56.276024,2.866838,0.823518,-647.331299,0.083418,0.000000
56.690002,12.949249,-647.242310,-0.000729,0.003269,0.083037,57.601139,2.934342,0.830369,-647.242310,0.084104,0.000000
57.100002,13.282150,-647.375732,-0.000707,0.003295,0.083696,59.081955,3.009778,0.836959,-647.375732,0.084789,0.000000
57.510002,13.832520,-647.331299,-0.000655,0.003324,0.084442,61.530121,3.134494,0.844418,-647.331299,0.085465,0.000000
57.920002,14.013863,-647.331299,-0.000629,0.003347,0.085014,62.336773,3.175587,0.850141,-647.331299,0.086150,0.000000
58.330002,14.314743,-647.331299,-0.000617,0.003378,0.085795,63.675156,3.243767,0.857946,-647.331299,0.086835,0.000000
58.740002,15.041611,-647.286804,-0.000591,0.003406,0.086514,66.908424,3.408478,0.865144,-647.286804,0.087520,0.000000
59.150002,15.302277,-647.375732,-0.000552,0.003432,0.087174,68.067924,3.467546,0.871735,-647.375732,0.088206,0.000000
59.560001,15.694008,-647.331299,-0.000517,0.003457,0.087815,69.810432,3.556313,0.878153,-647.331299,0.088882,0.000000
59.970001,15.845940,-647.331299,-0.000492,0.003480,0.088388,70.486259,3.590741,0.883876,-647.331299,0.089567,0.000000
60.380001,16.904221,-647.420227,-0.000470,0.003514,0.089246,75.193726,3.830551,0.892462,-647.420227,0.090252,0.000000
60.790005,16.929916,-647.420227,-0.000448,0.003529,0.089645,75.308029,3.836374,0.896451,-647.420227,0.090937,0.000000
61.200005,17.996758,-647.375732,-0.000418,0.003565,0.090556,80.053574,4.078124,0.905557,-647.375732,0.091622,0.000000
61.610004,18.557182,-647.464722,-0.000392,0.003592,0.091232,82.546471,4.205117,0.912322,-647.464722,0.092299,0.000000
62.020004,18.756401,-647.375732,-0.000362,0.003612,0.091735,83.432640,4.250261,0.917351,-647.375732,0.092984,0.000000
62.430004,19.831810,-647.464722,-0.000345,0.003645,0.092594,88.216293,4.493952,0.925937,-647.464722,0.093669,0.000000
62.840004,20.511017,-647.375732,-0.000315,0.003673,0.093296,91.237556,4.647862,0.932961,-647.375732,0.094354,0.000000
63.250004,21.656807,-647.509216,-0.000289,0.003703,0.094068,96.334290,4.907503,0.940680,-647.509216,0.095039,0.000000
63.660004,21.708939,-647.464722,-0.000272,0.003722,0.094536,96.566185,4.919316,0.945363,-647.464722,0.095716,0.000000
64.070000,22.894577,-647.509216,-0.000233,0.003753,0.095334,101.840164,5.187985,0.953341,-647.509216,0.096401,0.000000
64.480003,23.308281,-647.509216,-0.000229,0.003776,0.095898,103.680412,5.281732,0.958978,-647.509216,0.097086,0.000000
64.889999,24.268631,-647.553711,-0.000198,0.003804,0.096626,107.952263,5.499351,0.966263,-647.553711,0.097771,0.000000
65.300003,25.679176,-647.553711,-0.000181,0.003834,0.097389,114.226685,5.818985,0.973894,-647.553711,0.098456,0.000000
65.710007,26.479774,-647.509216,-0.000155,0.003862,0.098083,117.787918,6.000402,0.980832,-647.509216,0.099133,0.000000
66.120003,27.448318,-647.509216,-0.000138,0.003886,0.098716,122.096222,6.219878,0.987163,-647.509216,0.099818,0.000000
66.530006,28.393402,-647.553711,-0.000121,0.003912,0.099375,126.300163,6.434037,0.993754,-647.553711,0.100503,0.000000
66.940002,28.547935,-647.553711,-0.000099,0.003927,0.099757,126.987556,6.469055,0.997570,-647.553711,0.101188,0.000000
67.350006,31.118050,-647.598145,-0.000078,0.003971,0.100858,138.419998,7.051451,1.008583,-647.598145,0.101873,0.000000
67.760002,32.210587,-647.642639,-0.000065,0.003998,0.101561,143.279846,7.299023,1.015608,-647.642639,0.102549,0.000000
68.170006,33.213387,-647.598145,-0.000039,0.004025,0.102229,147.740524,7.526261,1.022286,-647.598145,0.103235,0.000000
68.580002,34.380775,-647.642639,-0.000034,0.004051,0.102905,152.933334,7.790795,1.029050,-647.642639,0.103920,0.000000
68.990005,35.708656,-647.553711,-0.000004,0.004077,0.103564,158.840042,8.091698,1.035641,-647.553711,0.104605,0.000000
69.400002,36.657089,-647.776062,0.000022,0.004098,0.104084,163.058884,8.306615,1.040844,-647.776062,0.105290,0.000000
69.810005,38.589333,-647.642639,0.000022,0.004131,0.104934,171.653931,8.744468,1.049343,-647.642639,0.105966,0.000000
70.220001,40.037117,-647.687134,0.000052,0.004158,0.105611,178.093994,9.072540,1.056108,-647.687134,0.106651,0.000000
70.630005,41.674438,-647.776062,0.000065,0.004186,0.106322,185.377167,9.443563,1.063219,-647.776062,0.107337,0.000000
71.040001,43.206375,-647.687134,0.000065,0.004211,0.106964,192.191559,9.790705,1.069636,-647.687134,0.108022,0.000000
71.450005,44.518616,-647.731628,0.000082,0.004235,0.107571,198.028687,10.088062,1.075707,-647.731628,0.108707,0.000000
71.860001,45.580254,-647.731628,0.000091,0.004254,0.108056,202.751099,10.328633,1.080563,-647.731628,0.109383,0.000000
72.270004,47.535950,-647.731628,0.000095,0.004284,0.108811,211.450470,10.771801,1.088108,-647.731628,0.110068,0.000000
72.680000,48.864578,-647.776062,0.000116,0.004307,0.109409,217.360504,11.072871,1.094092,-647.776062,0.110753,0.000000
73.090004,51.903877,-647.731628,0.000129,0.004344,0.110346,230.879974,11.761586,1.103458,-647.731628,0.111438,0.000000
73.500000,53.658875,-647.820557,0.000147,0.004371,0.111014,238.686600,12.159275,1.110136,-647.820557,0.112124,0.000000
73.910004,55.571373,-647.820557,0.000160,0.004398,0.111699,247.193817,12.592653,1.116987,-647.820557,0.112800,0.000000
74.320007,56.466187,-647.820557,0.000160,0.004416,0.112158,251.174149,12.795421,1.121583,-647.820557,0.113485,0.000000
74.730003,59.209084,-647.865051,0.000181,0.004450,0.113026,263.375153,13.416970,1.130255,-647.865051,0.114170,0.000000
75.140007,61.377777,-647.776062,0.000194,0.004476,0.113702,273.022003,13.908403,1.137020,-647.776062,0.114855,0.000000
75.550003,63.152512,-647.909546,0.000207,0.004506,0.114448,280.916412,14.310564,1.144478,-647.909546,0.115540,0.000000
75.960007,65.031128,-647.820557,0.000198,0.004526,0.114968,289.272919,14.736264,1.149681,-647.820557,0.116217,0.000000
76.370003,66.270386,-647.909546,0.000229,0.004537,0.115228,294.785400,15.017084,1.152283,-647.909546,0.115506,0.000000
76.780006,65.581863,-647.954041,0.000224,0.004536,0.115202,291.722687,14.861063,1.152023,-647.954041,294.500458,0.000000
77.190002,65.002075,-647.909546,0.000229,0.004536,0.115211,289.143677,14.729681,1.152109,-647.909546,294.500458,0.000000
77.600006,65.527496,-647.909546,0.000229,0.004552,0.115610,291.480865,14.848743,1.156098,-647.909546,294.500458,0.000000
78.010002,65.249710,-647.865051,0.000229,0.004552,0.115619,290.245209,14.785795,1.156185,-647.865051,294.500458,0.000000
78.420006,64.986069,-647.954041,0.000241,0.004552,0.115619,289.072479,14.726054,1.156185,-647.954041,294.500458,0.000000
78.830002,64.735458,-647.909546,0.000246,0.004552,0.115619,287.957703,14.669265,1.156185,-647.909546,294.500458,0.000000
79.240005,65.857788,-647.954041,0.000254,0.004566,0.115965,292.950073,14.923589,1.159654,-647.954041,294.500458,0.000000
79.650002,65.778107,-647.998474,0.000263,0.004566,0.115965,292.595642,14.905532,1.159654,-647.998474,294.500458,0.000000
80.060005,65.584106,-647.998474,0.000250,0.004566,0.115965,291.732666,14.861570,1.159654,-647.998474,294.500458,0.000000
80.470001,65.450043,-647.954041,0.000259,0.004566,0.115974,291.136322,14.831192,1.159741,-647.954041,294.500458,0.000000
80.880005,65.295883,-648.042969,0.000263,0.004566,0.115974,290.450592,14.796259,1.159741,-648.042969,294.500458,0.000000
81.290001,65.159225,-647.998474,0.000259,0.004566,0.115974,289.842712,14.765291,1.159741,-647.998474,294.500458,0.000000
81.700005,65.018097,-647.998474,0.000250,0.004566,0.115974,289.214935,14.733311,1.159741,-647.998474,294.500458,0.000000
82.110001,64.898193,-648.042969,0.000254,0.004566,0.115974,288.681580,14.706141,1.159741,-648.042969,294.500458,0.000000
82.520004,64.773437,-648.042969,0.000259,0.004566,0.115974,288.126648,14.677870,1.159741,-648.042969,294.500458,0.000000
82.930000,64.692261,-648.087463,0.000254,0.004566,0.115974,287.765533,14.659475,1.159741,-648.087463,294.500458,0.000000
83.340004,64.562302,-648.042969,0.000263,0.004566,0.115974,287.187469,14.630027,1.159741,-648.042969,294.500458,0.000000
83.750008,64.490814,-648.087463,0.000259,0.004566,0.115974,286.869476,14.613828,1.159741,-648.087463,294.500458,0.000000
84.160004,64.411499,-647.998474,0.000263,0.004566,0.115974,286.516663,14.595854,1.159741,-647.998474,294.500458,0.000000
84.570007,64.312073,-648.042969,0.000272,0.004566,0.115983,286.074402,14.573324,1.159828,-648.042969,294.500458,0.000000
84.980003,64.245041,-648.176392,0.000259,0.004567,0.115991,285.776215,14.558134,1.159914,-648.176392,294.500458,0.000000
85.390007,67.513733,-648.042969,0.000267,0.004572,0.116122,300.316071,15.298831,1.161215,-648.042969,294.500458,0.000000
85.800003,66.679993,-648.131958,0.000285,0.004391,0.111543,296.607422,15.109902,1.115426,-648.131958,294.500458,0.000000
86.210007,66.582062,-648.087463,0.000267,0.004391,0.111543,296.171814,15.087710,1.115426,-648.087463,294.500458,0.000000
86.620003,66.433105,-648.131958,0.000272,0.004391,0.111543,295.509216,15.053957,1.115426,-648.131958,294.500458,0.000000
87.030006,66.376511,-648.176392,0.000276,0.004392,0.111569,295.257477,15.041132,1.115686,-648.176392,294.500458,0.000000
87.440002,66.306503,-648.176392,0.000289,0.004392,0.111569,294.946045,15.025269,1.115686,-648.176392,294.500458,0.000000
87.850006,66.227554,-648.176392,0.000289,0.004392,0.111569,294.594879,15.007379,1.115686,-648.176392,294.500458,0.000000
88.260002,66.162766,-648.131958,0.000280,0.004392,0.111569,294.306671,14.992697,1.115686,-648.131958,294.500458,0.000000
88.670006,66.080475,-648.176392,0.000276,0.004392,0.111569,293.940643,14.974050,1.115686,-648.176392,294.500458,0.000000
89.080002,66.000046,-648.265381,0.000272,0.004392,0.111569,293.582855,14.955824,1.115686,-648.265381,294.500458,0.000000
89.490005,65.982544,-648.220886,0.000276,0.004400,0.111751,293.505005,14.951859,1.117507,-648.220886,294.500458,0.000000
89.900002,65.851837,-648.220886,0.000285,0.004406,0.111907,292.923615,14.922239,1.119068,-648.220886,294.500458,0.000000
90.310005,65.809387,-648.220886,0.000280,0.004408,0.111959,292.734772,14.912621,1.119588,-648.220886,294.500458,0.000000
90.720001,65.797089,-648.265381,0.000276,0.004411,0.112028,292.680054,14.909834,1.120282,-648.265381,294.500458,0.000000
91.130005,65.738998,-648.265381,0.000285,0.004411,0.112028,292.421661,14.896670,1.120282,-648.265381,294.500458,0.000000
91.540001,65.591553,-648.309875,0.000293,0.004430,0.112531,291.765808,14.863258,1.125312,-648.309875,294.500458,0.000000
91.950005,65.571442,-648.309875,0.000276,0.004436,0.112670,291.676331,14.858701,1.126700,-648.309875,294.500458,0.000000
92.360001,65.554306,-648.309875,0.000285,0.004492,0.114092,291.600128,14.854818,1.140922,-648.309875,294.500458,0.000000
92.770004,65.531219,-648.309875,0.000276,0.004492,0.114092,291.497437,14.849586,1.140922,-648.309875,294.500458,0.000000
93.180008,65.493988,-648.354370,0.000272,0.004518,0.114760,291.331818,14.841150,1.147600,-648.354370,294.500458,0.000000
93.590004,65.458984,-648.309875,0.000276,0.004535,0.115185,291.176117,14.833219,1.151849,-648.309875,294.500458,0.000000
94.000008,65.387115,-648.354370,0.000280,0.004535,0.115185,290.856415,14.816933,1.151849,-648.354370,294.500458,0.000000
94.410004,65.340561,-648.354370,0.000280,0.004535,0.115185,290.649323,14.806382,1.151849,-648.354370,294.500458,0.000000
94.820007,65.311890,-648.309875,0.000289,0.004535,0.115185,290.521790,14.799886,1.151849,-648.309875,294.500458,0.000000
95.230003,65.268326,-648.398804,0.000276,0.004535,0.115185,290.328003,14.790014,1.151849,-648.398804,294.500458,0.000000
95.640007,65.240768,-648.354370,0.000280,0.004542,0.115358,290.205444,14.783769,1.153584,-648.354370,294.500458,0.000000
96.050003,65.210602,-648.398804,0.000293,0.004543,0.115402,290.071259,14.776934,1.154017,-648.398804,294.500458,0.000000
96.460007,65.168152,-648.398804,0.000280,0.004543,0.115402,289.882416,14.767315,1.154017,-648.398804,294.500458,0.000000
96.870003,65.111923,-648.398804,0.000280,0.004543,0.115402,289.632294,14.754573,1.154017,-648.398804,294.500458,0.000000
97.280006,65.089584,-648.443298,0.000276,0.004547,0.115497,289.532928,14.749511,1.154971,-648.443298,294.500458,0.000000
97.690002,65.062408,-648.443298,0.000285,0.004547,0.115497,289.412048,14.743353,1.154971,-648.443298,294.500458,0.000000
98.100006,65.027771,-648.487793,0.000280,0.004547,0.115497,289.257965,14.735503,1.154971,-648.487793,294.500458,0.000000
98.510002,64.997986,-648.443298,0.000285,0.004547,0.115497,289.125488,14.728754,1.154971,-648.443298,294.500458,0.000000
98.920006,64.976761,-648.443298,0.000302,0.004548,0.115523,289.031067,14.723944,1.155231,-648.443298,294.500458,0.000000
99.330002,64.943253,-648.532288,0.000272,0.004548,0.115523,288.882019,14.716352,1.155231,-648.532288,294.500458,0.000000
99.740005,64.904144,-648.487793,0.000280,0.004548,0.115523,288.708038,14.707489,1.155231,-648.487793,294.500458,0.000000
100.150002,64.861694,-648.532288,0.000276,0.004548,0.115523,288.519226,14.697870,1.155231,-648.532288,294.500458,0.000000
100.560005,65.206512,-648.487793,0.000280,0.004581,0.116364,290.053040,14.776007,1.163643,-648.487793,294.500458,0.000000
100.970001,65.222900,-648.576721,0.000293,0.004581,0.116364,290.125946,14.779721,1.163643,-648.576721,294.500458,0.000000
101.380005,65.193848,-648.532288,0.000289,0.004582,0.116382,289.996704,14.773137,1.163817,-648.532288,294.500458,0.000000
101.790009,65.181564,-648.532288,0.000289,0.004582,0.116382,289.942078,14.770354,1.163817,-648.532288,294.500458,0.000000
102.200005,65.170013,-648.576721,0.000285,0.004582,0.116382,289.890686,14.767735,1.163817,-648.576721,294.500458,0.000000
102.610008,65.139114,-648.621216,0.000293,0.004582,0.116382,289.753265,14.760735,1.163817,-648.621216,294.500458,0.000000
103.020004,65.119385,-648.532288,0.000289,0.004582,0.116382,289.665497,14.756263,1.163817,-648.532288,294.500458,0.000000
103.430008,65.094803,-648.621216,0.000267,0.004582,0.116382,289.556152,14.750693,1.163817,-648.621216,294.500458,0.000000
103.840004,65.063522,-648.621216,0.000280,0.004582,0.116382,289.416992,14.743606,1.163817,-648.621216,294.500458,0.000000
104.250008,65.384506,-648.621216,0.000280,0.004589,0.116564,290.844818,14.816340,1.165638,-648.621216,294.500458,0.000000
104.660004,65.533081,-648.621216,0.000289,0.004589,0.116555,291.505707,14.850009,1.165551,-648.621216,294.500458,0.000000
105.070007,65.537186,-648.665710,0.000280,0.004589,0.116555,291.523956,14.850938,1.165551,-648.665710,294.500458,0.000000
105.480003,65.556915,-648.665710,0.000285,0.004589,0.116555,291.611725,14.855410,1.165551,-648.665710,294.500458,0.000000
105.890007,65.546112,-648.665710,0.000285,0.004589,0.116555,291.563660,14.852961,1.165551,-648.665710,294.500458,0.000000
106.300003,65.534576,-648.710205,0.000280,0.004589,0.116555,291.512360,14.850348,1.165551,-648.710205,294.500458,0.000000
106.710007,65.523773,-648.710205,0.000289,0.004589,0.116555,291.464294,14.847898,1.165551,-648.710205,294.500458,0.000000
107.120003,65.523407,-648.710205,0.000280,0.004589,0.116555,291.462677,14.847816,1.165551,-648.710205,294.500458,0.000000
107.530006,65.499573,-648.665710,0.000285,0.004589,0.116555,291.356659,14.842416,1.165551,-648.665710,294.500458,0.000000
107.940002,65.484680,-648.710205,0.000285,0.004589,0.116555,291.290405,14.839041,1.165551,-648.710205,294.500458,0.000000
108.350006,65.466797,-648.799133,0.000280,0.004589,0.116555,291.210846,14.834989,1.165551,-648.799133,294.500458,0.000000
108.760002,65.460464,-648.754700,0.000272,0.004589,0.116555,291.182678,14.833553,1.165551,-648.754700,294.500458,0.000000
109.170006,65.443344,-648.754700,0.000293,0.004589,0.116555,291.106537,14.829674,1.165551,-648.754700,294.500458,0.000000
109.580002,65.418762,-648.843628,0.000297,0.004589,0.116555,290.997192,14.824103,1.165551,-648.843628,294.500458,0.000000
109.990005,65.402756,-648.799133,0.000297,0.004589,0.116564,290.925995,14.820477,1.165638,-648.799133,294.500458,0.000000
110.400002,65.367752,-648.799133,0.000306,0.004589,0.116564,290.770294,14.812545,1.165638,-648.799133,294.500458,0.000000
110.810005,65.363281,-648.754700,0.000293,0.004589,0.116564,290.750397,14.811532,1.165638,-648.754700,294.500458,0.000000
111.220009,65.338333,-648.799133,0.000306,0.004589,0.116564,290.639435,14.805878,1.165638,-648.799133,294.500458,0.000000
111.630005,65.333496,-648.843628,0.000293,0.004589,0.116564,290.617920,14.804782,1.165638,-648.843628,294.500458,0.000000
112.040009,65.303696,-648.799133,0.000302,0.004589,0.116564,290.485352,14.798029,1.165638,-648.799133,294.500458,0.000000
112.450005,65.295517,-648.888123,0.000310,0.004589,0.116564,290.448975,14.796175,1.165638,-648.888123,294.500458,0.000000
112.860008,65.293274,-648.843628,0.000293,0.004589,0.116572,290.438995,14.795667,1.165725,-648.843628,294.500458,0.000000
113.270004,65.265350,-648.888123,0.000306,0.004589,0.116572,290.314789,14.789339,1.165725,-648.888123,294.500458,0.000000
113.680008,65.263855,-648.843628,0.000302,0.004589,0.116572,290.308136,14.789001,1.165725,-648.843628,294.500458,0.000000
114.090004,65.239288,-648.888123,0.000297,0.004589,0.116572,290.198853,14.783434,1.165725,-648.888123,294.500458,0.000000
114.500008,65.226624,-648.888123,0.000293,0.004589,0.116572,290.142517,14.780564,1.165725,-648.888123,294.500458,0.000000
114.910004,65.226624,-648.843628,0.000297,0.004590,0.116581,290.142517,14.780564,1.165812,-648.843628,294.500458,0.000000
115.320007,65.242630,-648.888123,0.000310,0.004591,0.116607,290.213715,14.784191,1.166072,-648.888123,294.500458,0.000000
115.730003,65.244492,-648.888123,0.000302,0.004591,0.116607,290.221985,14.784614,1.166072,-648.888123,294.500458,0.000000
116.140007,65.241150,-648.932617,0.000306,0.004591,0.116607,290.207123,14.783856,1.166072,-648.932617,294.500458,0.000000
116.550003,65.223267,-648.977051,0.000293,0.004591,0.116607,290.127594,14.779803,1.166072,-648.977051,294.500458,0.000000
116.960007,65.227371,-648.888123,0.000297,0.004591,0.116607,290.145844,14.780734,1.166072,-648.888123,294.500458,0.000000
117.370003,65.213959,-648.888123,0.000310,0.004591,0.116607,290.086182,14.777695,1.166072,-648.888123,294.500458,0.000000
117.780006,65.203156,-648.932617,0.000297,0.004591,0.116616,290.038116,14.775247,1.166158,-648.932617,294.500458,0.000000
118.190002,65.192734,-648.977051,0.000302,0.004591,0.116616,289.991760,14.772885,1.166158,-648.977051,294.500458,0.000000
118.600006,65.178955,-649.066040,0.000289,0.004591,0.116616,289.930481,14.769762,1.166158,-649.066040,294.500458,0.000000
119.010002,65.248215,-648.932617,0.000302,0.004593,0.116659,290.238556,14.785457,1.166592,-648.932617,294.500458,0.000000
119.420006,65.269821,-648.977051,0.000306,0.004593,0.116659,290.334656,14.790353,1.166592,-648.977051,294.500458,0.000000
119.830009,65.262375,-649.021545,0.000306,0.004593,0.116659,290.301544,14.788666,1.166592,-649.021545,294.500458,0.000000
120.240005,65.270187,-648.977051,0.000302,0.004593,0.116659,290.336304,14.790436,1.166592,-648.977051,294.500458,0.000000
120.650009,65.284714,-649.021545,0.000297,0.004593,0.116659,290.400909,14.793728,1.166592,-649.021545,294.500458,0.000000
121.060005,65.255661,-649.066040,0.000302,0.004593,0.116659,290.271667,14.787145,1.166592,-649.066040,294.500458,0.000000
121.470009,65.264236,-649.066040,0.000293,0.004593,0.116659,290.309814,14.789087,1.166592,-649.066040,294.500458,0.000000
121.880005,65.250458,-649.066040,0.000297,0.004593,0.116659,290.248535,14.785965,1.166592,-649.066040,294.500458,0.000000
122.290009,65.240768,-649.066040,0.000302,0.004593,0.116659,290.205444,14.783769,1.166592,-649.066040,294.500458,0.000000
122.700005,65.242630,-649.155029,0.000297,0.004593,0.116668,290.213715,14.784191,1.166679,-649.155029,294.500458,0.000000
123.110008,65.235184,-649.155029,0.000315,0.004593,0.116668,290.180603,14.782503,1.166679,-649.155029,294.500458,0.000000
123.520004,65.234818,-649.199463,0.000310,0.004594,0.116694,290.178955,14.782421,1.166939,-649.199463,294.500458,0.000000
123.930008,65.245987,-649.155029,0.000293,0.004594,0.116694,290.228638,14.784952,1.166939,-649.155029,294.500458,0.000000
124.340004,65.249710,-649.155029,0.000293,0.004594,0.116694,290.245209,14.785795,1.166939,-649.155029,294.500458,0.000000
124.750008,65.257156,-649.155029,0.000293,0.004594,0.116694,290.278320,14.787483,1.166939,-649.155029,294.500458,0.000000
125.160004,65.246735,-649.155029,0.000310,0.004594,0.116694,290.231964,14.785122,1.166939,-649.155029,294.500458,0.000000
125.570007,65.246353,-649.243958,0.000306,0.004594,0.116694,290.230286,14.785034,1.166939,-649.243958,294.500458,0.000000
125.980003,65.232956,-649.199463,0.000302,0.004594,0.116694,290.170685,14.782000,1.166939,-649.199463,294.500458,0.000000
126.390007,65.217682,-649.243958,0.000319,0.004594,0.116694,290.102753,14.778538,1.166939,-649.243958,294.500458,0.000000
126.800003,65.201294,-649.243958,0.000302,0.004594,0.116694,290.029846,14.774824,1.166939,-649.243958,294.500458,0.000000
127.210007,65.206879,-649.199463,0.000285,0.004594,0.116694,290.054687,14.776090,1.166939,-649.199463,294.500458,0.000000
127.620003,65.198318,-649.288452,0.000306,0.004594,0.116694,290.016602,14.774151,1.166939,-649.288452,294.500458,0.000000
128.029999,65.183060,-649.243958,0.000297,0.004595,0.116720,289.948730,14.770692,1.167199,-649.243958,294.500458,0.000000
128.440002,65.191986,-649.288452,0.000310,0.004595,0.116720,289.988434,14.772716,1.167199,-649.288452,294.500458,0.000000
128.850006,65.195709,-649.377380,0.000293,0.004595,0.116720,290.005005,14.773559,1.167199,-649.377380,294.500458,0.000000
129.260010,65.197571,-649.288452,0.000302,0.004595,0.116720,290.013275,14.773981,1.167199,-649.288452,294.500458,0.000000
129.670013,65.186401,-649.377380,0.000306,0.004595,0.116720,289.963593,14.771450,1.167199,-649.377380,294.500458,0.000000
130.080002,65.173752,-649.288452,0.000297,0.004595,0.116720,289.907318,14.768583,1.167199,-649.288452,294.500458,0.000000
130.490005,65.170013,-649.332947,0.000306,0.004595,0.116720,289.890686,14.767735,1.167199,-649.332947,294.500458,0.000000
130.900009,65.168900,-649.377380,0.000310,0.004595,0.116720,289.885742,14.767485,1.167199,-649.377380,294.500458,0.000000
131.310013,65.156250,-649.421875,0.000302,0.004595,0.116720,289.829468,14.764617,1.167199,-649.421875,294.500458,0.000000
131.720001,65.142090,-649.377380,0.000297,0.004595,0.116720,289.766479,14.761409,1.167199,-649.377380,294.500458,0.000000
132.130005,65.133530,-649.421875,0.000302,0.004595,0.116720,289.728424,14.759469,1.167199,-649.421875,294.500458,0.000000
132.540009,65.113052,-649.466370,0.000302,0.004595,0.116720,289.637329,14.754828,1.167199,-649.466370,294.500458,0.000000
132.950012,65.112671,-649.421875,0.000297,0.004595,0.116720,289.635620,14.754742,1.167199,-649.421875,294.500458,0.000000
133.360001,65.100021,-649.421875,0.000302,0.004595,0.116720,289.579346,14.751876,1.167199,-649.421875,294.500458,0.000000
133.770004,65.075806,-649.510864,0.000293,0.004595,0.116720,289.471649,14.746388,1.167199,-649.510864,294.500458,0.000000
134.180008,65.072830,-649.377380,0.000306,0.004595,0.116720,289.458405,14.745714,1.167199,-649.377380,294.500458,0.000000
134.590012,65.072464,-649.421875,0.000302,0.004595,0.116720,289.456787,14.745631,1.167199,-649.421875,294.500458,0.000000
135.000000,65.057571,-649.510864,0.000293,0.004595,0.116720,289.390533,14.742256,1.167199,-649.510864,294.500458,0.000000
135.410004,65.036713,-649.555298,0.000289,0.004595,0.116720,289.297760,14.737530,1.167199,-649.555298,294.500458,0.000000
135.820007,65.043045,-649.510864,0.000297,0.004595,0.116720,289.325928,14.738965,1.167199,-649.510864,294.500458,0.000000
136.230011,65.038940,-649.510864,0.000293,0.004595,0.116720,289.307648,14.738035,1.167199,-649.510864,294.500458,0.000000
136.639999,65.020706,-649.599792,0.000302,0.004595,0.116720,289.226532,14.733903,1.167199,-649.599792,294.500458,0.000000
137.050003,64.993149,-649.555298,0.000306,0.004590,0.116598,289.103973,14.727658,1.165985,-649.555298,0.116720,0.000000
137.460007,64.947708,-649.510864,0.000310,0.004580,0.116338,288.901825,14.717361,1.163383,-649.510864,0.116087,0.000000
137.870010,64.846436,-649.599792,0.000293,0.004561,0.115853,288.451355,14.694413,1.158527,-649.599792,0.115402,0.000000
138.280014,64.771957,-649.555298,0.000302,0.004536,0.115220,288.120056,14.677535,1.152196,-649.555298,0.114717,0.000000
138.690002,64.786850,-649.688782,0.000315,0.004504,0.114396,288.186310,14.680909,1.143957,-649.688782,0.114032,0.000000
139.100006,64.775299,-649.644287,0.000306,0.004480,0.113797,288.134918,14.678292,1.137974,-649.644287,0.113355,0.000000
139.510010,64.747009,-649.599792,0.000315,0.004454,0.113130,288.009094,14.671882,1.131296,-649.599792,0.112670,0.000000
139.920013,64.699341,-649.688782,0.000285,0.004429,0.112505,287.797028,14.661080,1.125052,-649.688782,0.111985,0.000000
140.330002,64.688171,-649.555298,0.000306,0.004408,0.111959,287.747345,14.658549,1.119588,-649.555298,0.111300,0.000000
140.740005,64.640503,-649.644287,0.000310,0.004379,0.111230,287.535309,14.647747,1.112304,-649.644287,0.110615,0.000000
141.150009,64.357132,-649.688782,0.000302,0.004356,0.110649,286.274811,14.583534,1.106493,-649.688782,0.109938,0.000000
141.560013,63.400131,-649.644287,0.000310,0.004328,0.109921,282.017883,14.366675,1.099209,-649.644287,0.109253,0.000000
141.970001,62.490799,-649.644287,0.000302,0.004304,0.109331,277.972961,14.160618,1.093311,-649.644287,0.108568,0.000000
142.380005,61.010620,-649.644287,0.000319,0.004278,0.108672,271.388794,13.825204,1.086720,-649.644287,0.107883,0.000000
142.790009,59.343506,-649.733276,0.000310,0.004255,0.108065,263.973083,13.447431,1.080650,-649.733276,0.107198,0.000000
143.200012,57.172203,-649.777710,0.000302,0.004228,0.107389,254.314667,12.955407,1.073886,-649.777710,0.106513,0.000000
143.610001,55.060112,-649.733276,0.000319,0.004205,0.106808,244.919617,12.476800,1.068075,-649.733276,0.105836,0.000000
144.020004,52.848961,-649.822205,0.000306,0.004181,0.106209,235.083923,11.975746,1.062091,-649.822205,0.105151,0.000000
144.430008,49.788803,-649.777710,0.000306,0.004151,0.105437,221.471664,11.282304,1.054373,-649.777710,0.104466,0.000000
144.840012,47.379181,-649.777710,0.000310,0.004128,0.104848,210.753128,10.736276,1.048476,-649.777710,0.103781,0.000000
145.250000,44.019264,-649.733276,0.000306,0.004100,0.104145,195.807465,9.974908,1.041451,-649.733276,0.103096,0.000000
145.660004,40.909210,-649.777710,0.000319,0.004070,0.103382,181.973251,9.270160,1.033820,-649.777710,0.102419,0.000000
146.070007,37.970818,-649.822205,0.000302,0.004047,0.102784,168.902634,8.604311,1.027836,-649.822205,0.101734,0.000000
146.480011,35.465866,-649.777710,0.000306,0.004019,0.102081,157.760056,8.036680,1.020811,-649.777710,0.101049,0.000000
146.889999,32.051590,-649.777710,0.000310,0.003990,0.101353,142.572586,7.262994,1.013527,-649.777710,0.100364,0.000000
147.300003,29.311668,-649.777710,0.000289,0.003966,0.100728,130.384811,6.642119,1.007283,-649.777710,0.099679,0.000000
147.710007,26.249649,-649.733276,0.000315,0.003940,0.100087,116.764267,5.948256,1.000865,-649.733276,0.099002,0.000000
148.120010,23.062141,-649.866699,0.000297,0.003912,0.099367,102.585526,5.225956,0.993667,-649.866699,0.098317,0.000000
148.530014,20.415695,-649.866699,0.000302,0.003886,0.098708,90.813545,4.626263,0.987076,-649.866699,0.097632,0.000000
148.940002,16.757507,-649.822205,0.000302,0.003856,0.097953,74.541115,3.797305,0.979531,-649.822205,0.096947,0.000000
149.350006,14.239525,-649.911194,0.000289,0.003835,0.097398,63.340569,3.226722,0.973981,-649.911194,0.096262,0.000000
149.760010,10.770874,-649.866699,0.000297,0.003803,0.096600,47.911240,2.440715,0.966003,-649.866699,0.095586,0.000000
150.170013,8.514671,-649.955627,0.000289,0.003779,0.095985,37.875149,1.929452,0.959845,-649.955627,0.094901,0.000000
150.580002,5.205025,-649.911194,0.000280,0.003752,0.095291,23.153107,1.179475,0.952908,-649.911194,0.094215,0.000000
150.990005,2.024590,-649.866699,0.000297,0.003719,0.094467,9.005824,0.458779,0.944669,-649.866699,0.093530,0.000000
151.400009,-0.366417,-649.955627,0.000285,0.003696,0.093877,-1.629904,-0.083031,0.938772,-649.955627,0.092845,0.000000
151.810013,-0.431953,-649.911194,0.000259,0.003665,0.093097,-1.921425,-0.097882,0.930967,-649.911194,0.092169,0.000000
152.220001,-0.129585,-650.000122,0.000229,0.003644,0.092568,-0.576424,-0.029364,0.925677,-650.000122,0.091484,0.000000
152.630005,-0.074844,-650.000122,0.000160,0.003613,0.091770,-0.332924,-0.016960,0.917698,-650.000122,0.090799,0.000000
153.040009,-0.025696,-650.000122,0.000112,0.003588,0.091145,-0.114301,-0.005823,0.911454,-650.000122,0.090113,0.000000
153.450012,-0.029793,-650.044617,0.000034,0.003556,0.090330,-0.132525,-0.006751,0.903302,-650.044617,0.089428,0.000000
153.860001,0.046547,-650.044617,-0.000009,0.003539,0.089879,0.207051,0.010548,0.898793,-650.044617,0.088752,0.000000
154.270004,-0.000374,-650.000122,-0.000078,0.003505,0.089038,-0.001663,-0.000085,0.890381,-650.000122,0.088067,0.000000
154.680008,-0.002235,-650.044617,-0.000168,0.003479,0.088370,-0.009944,-0.000507,0.883703,-650.044617,0.087382,0.000000
155.090012,0.038727,-650.044617,-0.000250,0.003449,0.087598,0.172265,0.008776,0.875985,-650.044617,0.086697,0.000000
155.500000,0.052879,-650.089111,-0.000341,0.003423,0.086957,0.235219,0.011983,0.869567,-650.089111,0.086011,0.000000
155.910004,0.045059,-650.044617,-0.000418,0.003400,0.086367,0.200433,0.010211,0.863670,-650.044617,0.085335,0.000000
156.320007,0.006699,-650.044617,-0.000492,0.003372,0.085639,0.029797,0.001518,0.856385,-650.044617,0.084650,0.000000
156.730011,-0.000374,-650.089111,-0.000617,0.003338,0.084789,-0.001663,-0.000085,0.847887,-650.089111,0.083965,0.000000
157.140015,-0.017876,-650.089111,-0.000686,0.003310,0.084069,-0.079515,-0.004051,0.840689,-650.089111,0.083280,0.000000
157.550003,-0.038353,-650.133606,-0.000746,0.003294,0.083661,-0.170603,-0.008691,0.836613,-650.133606,0.082595,0.000000
157.960007,-0.024208,-650.133606,-0.000793,0.003274,0.083167,-0.107683,-0.005486,0.831670,-650.133606,0.081918,0.000000
158.370010,-0.043938,-650.089111,-0.000871,0.003238,0.082248,-0.195445,-0.009956,0.822477,-650.089111,0.081233,0.000000
158.780014,-0.038727,-650.089111,-0.000927,0.003210,0.081537,-0.172265,-0.008776,0.815366,-650.089111,0.080548,0.000000
159.190002,-0.061073,-650.133606,-0.000957,0.003184,0.080877,-0.271668,-0.013839,0.808775,-650.133606,0.079863,0.000000
159.600006,-0.049530,-650.133606,-0.001022,0.003163,0.080348,-0.220321,-0.011224,0.803485,-650.133606,0.079178,0.000000
160.010010,-0.080063,-650.133606,-0.001074,0.003130,0.079490,-0.356137,-0.018143,0.794899,-650.133606,0.078501,0.000000
160.420013,-0.075966,-650.178040,-0.001112,0.003095,0.078623,-0.337913,-0.017214,0.786227,-650.178040,0.077816,0.000000
160.830002,-0.039848,-650.178040,-0.001164,0.003074,0.078085,-0.177254,-0.009030,0.780850,-650.178040,0.077131,0.000000
161.240005,-0.021225,-650.178040,-0.001255,0.003046,0.077374,-0.094413,-0.004810,0.773739,-650.178040,0.076446,0.000000
161.650009,-0.048409,-650.178040,-0.001298,0.003018,0.076654,-0.215332,-0.010970,0.766541,-650.178040,0.075761,0.000000
162.060013,-0.043571,-650.178040,-0.001332,0.002993,0.076030,-0.193816,-0.009873,0.760297,-650.178040,0.075084,0.000000
162.470001,-0.050270,-650.222534,-0.001367,0.002967,0.075371,-0.223612,-0.011391,0.753706,-650.222534,0.074399,0.000000
162.880005,0.007446,-650.267029,-0.001406,0.002948,0.074885,0.033123,0.001687,0.748849,-650.267029,0.073714,0.000000
163.290009,-0.002983,-650.267029,-0.001440,0.002913,0.073983,-0.013269,-0.000676,0.739830,-650.267029,0.073029,0.000000
163.700012,-0.024208,-650.178040,-0.001462,0.002890,0.073402,-0.107683,-0.005486,0.734020,-650.178040,0.072344,0.000000
164.110001,-0.017876,-650.222534,-0.001500,0.002866,0.072795,-0.079515,-0.004051,0.727949,-650.222534,0.071668,0.000000
164.520004,-0.035004,-650.178040,-0.001539,0.002831,0.071902,-0.155704,-0.007932,0.719017,-650.178040,0.070982,0.000000
164.930008,-0.026436,-650.267029,-0.001565,0.002806,0.071269,-0.117593,-0.005990,0.712686,-650.267029,0.070297,0.000000
165.340012,0.013779,-650.311523,-0.001608,0.002786,0.070766,0.061291,0.003122,0.707656,-650.311523,0.069612,0.000000
165.750015,-0.018250,-650.222534,-0.001634,0.002751,0.069881,-0.081178,-0.004135,0.698810,-650.222534,0.068927,0.000000
166.160004,-0.023087,-650.355957,-0.001656,0.002728,0.069283,-0.102694,-0.005231,0.692827,-650.355957,0.068251,0.000000
166.570007,-0.060326,-650.267029,-0.001703,0.002702,0.068624,-0.268342,-0.013670,0.686236,-650.267029,0.067566,0.000000
166.980011,-0.028305,-650.311523,-0.001716,0.002670,0.067808,-0.125907,-0.006414,0.678084,-650.311523,0.066880,0.000000
167.390015,-0.026436,-650.311523,-0.001759,0.002645,0.067193,-0.117593,-0.005990,0.671926,-650.311523,0.066195,0.000000
167.800003,-0.052132,-650.355957,-0.001781,0.002618,0.066490,-0.231893,-0.011813,0.664902,-650.355957,0.065510,0.000000
168.210007,-0.046547,-650.355957,-0.001811,0.002591,0.065822,-0.207051,-0.010548,0.658224,-650.355957,0.064834,0.000000
168.620010,-0.053993,-650.267029,-0.001841,0.002567,0.065207,-0.240174,-0.012235,0.652067,-650.267029,0.064149,0.000000
169.030014,-0.059578,-650.400452,-0.001871,0.002538,0.064470,-0.265016,-0.013501,0.644696,-650.400452,0.063464,0.000000
169.440002,-0.027184,-650.400452,-0.001901,0.002519,0.063984,-0.120918,-0.006160,0.639839,-650.400452,0.063880,0.000000
169.500015,-0.026810,-650.355957,-0.001884,0.002519,0.063984,-0.119255,-0.006075,0.639839,-650.355957,0.063880,0.000000