File: Data/compression 33/AutoNoHeating-15-33-reverse-1-3_11152024_181808.csv
Time (sec),S:Load (lbs),S:HL1 (DIM),S:LVDT (in),S:Position (in),Ch:Position (mm),Ch:Load (N),Ch:Stress (MPa),Ch:Strain (mm/mm),Ch:HL1 (DIM),Set Point (),Cycles ()
0.110000,-0.061813,-62.540218,-0.008088,-0.008006,-0.203364,-0.274960,-0.014007,-2.033644,-62.540218,-0.203148,0.000000
0.450000,-0.044312,-62.584698,-0.008080,-0.007942,-0.201725,-0.197107,-0.010041,-2.017253,-62.584698,-0.201049,0.000000
0.790000,-0.065170,-62.629181,-0.007972,-0.007743,-0.196678,-0.289892,-0.014768,-1.966781,-62.629181,-0.195377,0.000000
1.130000,-0.070007,-62.629181,-0.007761,-0.007516,-0.190894,-0.311408,-0.015864,-1.908937,-62.629181,-0.189723,0.000000
1.470000,-0.123634,-62.718140,-0.007545,-0.007298,-0.185378,-0.549953,-0.028016,-1.853782,-62.718140,-0.184051,0.000000
1.810000,-0.045059,-62.762623,-0.007308,-0.007072,-0.179637,-0.200433,-0.010211,-1.796371,-62.762623,-0.178397,0.000000
2.150000,-0.018250,-62.762623,-0.007080,-0.006851,-0.174018,-0.081178,-0.004135,-1.740175,-62.762623,-0.172725,0.000000
2.490000,-0.037239,-62.807102,-0.006860,-0.006630,-0.168407,-0.165648,-0.008438,-1.684065,-62.807102,-0.167054,0.000000
2.830000,-0.087135,-62.807102,-0.006618,-0.006409,-0.162778,-0.387597,-0.019745,-1.627783,-62.807102,-0.161399,0.000000
3.170000,-0.108360,-62.940544,-0.006385,-0.006174,-0.156820,-0.482011,-0.024555,-1.568204,-62.940544,-0.155728,0.000000
3.510000,-0.083786,-62.940544,-0.006157,-0.005959,-0.151366,-0.372699,-0.018986,-1.513656,-62.940544,-0.150073,0.000000
3.850000,-0.053253,-63.029507,-0.005946,-0.005741,-0.145824,-0.236882,-0.012067,-1.458240,-63.029507,-0.144402,0.000000
4.190000,-0.060699,-63.029507,-0.005708,-0.005520,-0.140196,-0.270005,-0.013755,-1.401957,-63.029507,-0.138747,0.000000
4.530000,-0.028305,-62.985027,-0.005467,-0.005297,-0.134550,-0.125907,-0.006414,-1.345501,-62.985027,-0.133076,0.000000
4.870000,-0.048782,-63.162949,-0.005243,-0.005067,-0.128714,-0.216995,-0.011054,-1.287136,-63.162949,-0.127404,0.000000
5.210000,-0.058090,-63.162949,-0.005010,-0.004848,-0.123129,-0.258398,-0.013163,-1.231287,-63.162949,-0.121750,0.000000
5.550000,0.090858,-63.296394,-0.004885,-0.000008,-0.000208,0.404159,0.020589,-0.002081,-63.296394,0.000035,0.000000
5.890000,0.085274,-63.251911,-0.004863,-0.000008,-0.000208,0.379317,0.019323,-0.002081,-63.251911,0.000035,0.000000
6.230000,0.108360,-63.296394,-0.004876,-0.000008,-0.000208,0.482011,0.024555,-0.002081,-63.296394,0.000564,0.000000
6.570000,0.089737,-63.385357,-0.004881,-0.000008,-0.000199,0.399170,0.020335,-0.001995,-63.385357,0.001127,0.000000
6.910000,0.173523,-63.340874,-0.004863,0.000020,0.000512,0.771869,0.039321,0.005117,-63.340874,0.001700,0.000000
7.250000,0.344070,-63.429836,-0.004846,0.000046,0.001179,1.530502,0.077967,0.011794,-63.429836,0.002263,0.000000
7.590000,0.445351,-63.429836,-0.004816,0.000069,0.001752,1.981019,0.100918,0.017518,-63.429836,0.002827,0.000000
7.930000,0.608826,-63.474316,-0.004790,0.000086,0.002185,2.708192,0.137962,0.021854,-63.474316,0.003400,0.000000
8.270000,0.762245,-63.563278,-0.004777,0.000102,0.002584,3.390636,0.172727,0.025843,-63.563278,0.003963,0.000000
8.610001,1.215050,-63.474316,-0.004773,0.000137,0.003478,5.404811,0.275334,0.034776,-63.474316,0.004536,0.000000
8.950001,1.535286,-63.652241,-0.004743,0.000163,0.004137,6.829293,0.347901,0.041367,-63.652241,0.005099,0.000000
9.290001,1.892395,-63.607761,-0.004700,0.000186,0.004726,8.417793,0.428823,0.047264,-63.607761,0.005663,0.000000
9.630000,2.099060,-63.696720,-0.004687,0.000203,0.005160,9.337086,0.475654,0.051600,-63.696720,0.006235,0.000000
9.970000,2.299026,-63.741203,-0.004674,0.000223,0.005672,10.226581,0.520967,0.056717,-63.741203,0.006799,0.000000
10.310000,2.889610,-63.741203,-0.004665,0.000246,0.006253,12.853628,0.654795,0.062527,-63.741203,0.007363,0.000000
10.650001,3.335335,-63.874645,-0.004644,0.000271,0.006877,14.836310,0.755798,0.068771,-63.874645,0.007935,0.000000
10.990001,3.692818,-63.830166,-0.004613,0.000286,0.007276,16.426474,0.836804,0.072760,-63.830166,0.008499,0.000000
11.330001,4.042099,-63.874645,-0.004605,0.000306,0.007770,17.980154,0.915953,0.077703,-63.874645,0.009063,0.000000
11.670001,4.484482,-63.963608,-0.004596,0.000331,0.008403,19.947971,1.016198,0.084034,-63.963608,0.009635,0.000000
12.010000,4.609222,-63.963608,-0.004583,0.000349,0.008863,20.502846,1.044465,0.088631,-63.963608,0.010199,0.000000
12.350000,5.511856,-64.008087,-0.004549,0.000383,0.009730,24.517960,1.249004,0.097303,-64.008087,0.010762,0.000000
12.690001,6.017532,-64.052567,-0.004518,0.000409,0.010381,26.767321,1.363592,0.103807,-64.052567,0.011335,0.000000
13.030001,6.298676,-64.097054,-0.004506,0.000428,0.010866,28.017908,1.427300,0.108663,-64.097054,0.011898,0.000000
13.370001,6.789467,-64.097054,-0.004475,0.000453,0.011508,30.201057,1.538515,0.115081,-64.097054,0.012462,0.000000
13.710001,7.035599,-64.141533,-0.004454,0.000468,0.011890,31.295906,1.594290,0.118897,-64.141533,0.013034,0.000000
14.050000,7.444466,-64.274971,-0.004441,0.000488,0.012401,33.114635,1.686940,0.124013,-64.274971,0.013598,0.000000
14.390000,8.161659,-64.230492,-0.004406,0.000518,0.013165,36.304874,1.849458,0.131645,-64.230492,0.014162,0.000000
14.730000,8.501633,-64.274971,-0.004406,0.000541,0.013737,37.817150,1.926497,0.137369,-64.274971,0.014734,0.000000
15.070001,8.980133,-64.363937,-0.004376,0.000562,0.014266,39.945625,2.034927,0.142659,-64.363937,0.015298,0.000000
15.410001,9.091469,-64.408417,-0.004372,0.000578,0.014682,40.440872,2.060156,0.146821,-64.408417,0.015862,0.000000
15.750001,9.251221,-64.497375,-0.004355,0.000594,0.015098,41.151485,2.096357,0.150984,-64.497375,0.016434,0.000000
16.090000,10.190712,-64.452896,-0.004324,0.000629,0.015974,45.330551,2.309248,0.159743,-64.452896,0.016998,0.000000
16.430000,10.344879,-64.497375,-0.004299,0.000648,0.016469,46.016319,2.344183,0.164686,-64.497375,0.017570,0.000000
16.770000,10.601067,-64.541862,-0.004273,0.000666,0.016928,47.155899,2.402236,0.169282,-64.541862,0.018134,0.000000
17.110001,11.132072,-64.541862,-0.004273,0.000692,0.017570,49.517933,2.522564,0.175700,-64.541862,0.018697,0.000000
17.450001,11.512260,-64.586342,-0.004230,0.000715,0.018151,51.209091,2.608716,0.181510,-64.586342,0.019270,0.000000
17.790001,11.793777,-64.630821,-0.004212,0.000735,0.018663,52.461342,2.672508,0.186627,-64.630821,0.019833,0.000000
18.130001,12.256638,-64.675301,-0.004195,0.000759,0.019270,54.520248,2.777394,0.192698,-64.675301,0.020397,0.000000
18.470001,12.577621,-64.675301,-0.004191,0.000778,0.019764,55.948055,2.850130,0.197641,-64.675301,0.020970,0.000000
18.810001,13.001381,-64.764267,-0.004156,0.000801,0.020354,57.833031,2.946155,0.203538,-64.764267,0.021533,0.000000
19.150002,13.092987,-64.853226,-0.004152,0.000814,0.020675,58.240517,2.966913,0.206747,-64.853226,0.022097,0.000000
19.490002,13.596436,-64.853226,-0.004122,0.000839,0.021308,60.479965,3.080996,0.213078,-64.853226,0.022669,0.000000
19.830002,14.439857,-64.897705,-0.004096,0.000870,0.022106,64.231697,3.272118,0.221056,-64.897705,0.023233,0.000000
20.170000,14.652481,-64.942192,-0.004083,0.000896,0.022765,65.177490,3.320300,0.227647,-64.942192,0.023797,0.000000
20.510000,14.937347,-64.942192,-0.004061,0.000915,0.023242,66.444641,3.384851,0.232416,-64.942192,0.024369,0.000000
20.850000,15.220718,-65.031151,-0.004049,0.000937,0.023805,67.705139,3.449064,0.238054,-65.031151,0.024933,0.000000
21.190001,15.562187,-65.031151,-0.004027,0.000961,0.024421,69.224068,3.526442,0.244211,-65.031151,0.025496,0.000000
21.530001,15.634056,-65.120110,-0.003997,0.000977,0.024811,69.543755,3.542728,0.248113,-65.120110,0.026069,0.000000
21.870001,15.703316,-65.120110,-0.003967,0.000992,0.025184,69.851837,3.558422,0.251842,-65.120110,0.026633,0.000000
22.210001,16.854691,-65.209076,-0.003958,0.001028,0.026103,74.973412,3.819327,0.261035,-65.209076,0.027196,0.000000
22.550001,17.022263,-65.298035,-0.003936,0.001051,0.026685,75.718803,3.857300,0.266845,-65.298035,0.027769,0.000000
22.890001,17.198021,-65.209076,-0.003923,0.001073,0.027257,76.500618,3.897127,0.272569,-65.209076,0.028332,0.000000
23.230001,17.619545,-65.342514,-0.003906,0.001094,0.027795,78.375648,3.992646,0.277946,-65.342514,0.028896,0.000000
23.570002,17.814667,-65.342514,-0.003885,0.001114,0.028289,79.243599,4.036861,0.282889,-65.342514,0.029468,0.000000
23.910002,18.114052,-65.298035,-0.003885,0.001135,0.028827,80.575325,4.104703,0.288266,-65.298035,0.030032,0.000000
24.250002,18.443230,-65.431480,-0.003846,0.001160,0.029468,82.039581,4.179296,0.294683,-65.431480,0.030596,0.000000
24.590002,18.338593,-65.475960,-0.003816,0.001173,0.029789,81.574135,4.155584,0.297892,-65.475960,0.031168,0.000000
24.930000,19.119461,-65.520439,-0.003811,0.001208,0.030682,85.047607,4.332531,0.306825,-65.520439,0.031732,0.000000
25.270000,19.244209,-65.520439,-0.003773,0.001225,0.031125,85.602516,4.360800,0.311247,-65.520439,0.032304,0.000000
25.610001,19.653442,-65.564919,-0.003755,0.001248,0.031688,87.422874,4.453534,0.316884,-65.564919,0.032868,0.000000
25.950001,20.118912,-65.653885,-0.003729,0.001275,0.032382,89.493385,4.559011,0.323822,-65.653885,0.033432,0.000000
26.290001,20.387764,-65.653885,-0.003712,0.001295,0.032885,90.689301,4.619933,0.328852,-65.653885,0.034004,0.000000
26.630001,20.994354,-65.698364,-0.003691,0.001325,0.033666,93.387550,4.757389,0.336657,-65.698364,0.034568,0.000000
26.970001,20.925095,-65.698364,-0.003660,0.001345,0.034169,93.079468,4.741694,0.341687,-65.698364,0.035131,0.000000
27.310001,20.754173,-65.787323,-0.003652,0.001359,0.034507,92.319176,4.702963,0.345069,-65.787323,0.035704,0.000000
27.650002,21.642654,-65.876289,-0.003630,0.001390,0.035305,96.271332,4.904295,0.353048,-65.876289,0.036267,0.000000
27.990002,21.158943,-65.787323,-0.003622,0.001407,0.035730,94.119682,4.794685,0.357297,-65.787323,0.036831,0.000000
28.330002,22.000877,-65.920769,-0.003583,0.001428,0.036267,97.864792,4.985470,0.362674,-65.920769,0.037403,0.000000
28.670002,22.069771,-65.920769,-0.003574,0.001445,0.036710,98.171242,5.001081,0.367097,-65.920769,0.037967,0.000000
29.010002,22.364685,-65.965248,-0.003553,0.001470,0.037334,99.483086,5.067910,0.373341,-65.965248,0.038531,0.000000
29.350002,22.654022,-66.009735,-0.003535,0.001489,0.037828,100.770126,5.133475,0.378284,-66.009735,0.039103,0.000000
29.690001,23.457603,-66.009735,-0.003510,0.001517,0.038522,104.344635,5.315569,0.385222,-66.009735,0.039667,0.000000
30.030001,23.562607,-66.098694,-0.003488,0.001536,0.039016,104.811707,5.339363,0.390165,-66.098694,0.040231,0.000000
30.370001,24.067177,-66.098694,-0.003475,0.001564,0.039728,107.056152,5.453700,0.397276,-66.098694,0.040803,0.000000
30.710001,24.357628,-66.143173,-0.003445,0.001591,0.040413,108.348137,5.519517,0.404127,-66.143173,0.041367,0.000000
31.050001,23.922691,-66.187653,-0.003428,0.001604,0.040734,106.413445,5.420959,0.407336,-66.187653,0.041930,0.000000
31.390001,24.287621,-66.232140,-0.003410,0.001626,0.041297,108.036736,5.503654,0.412973,-66.232140,0.042503,0.000000
31.730001,25.167160,-66.410057,-0.003380,0.001655,0.042026,111.949120,5.702960,0.420258,-66.410057,0.043066,0.000000
32.070000,24.969063,-66.321098,-0.003359,0.001670,0.042407,111.067940,5.658071,0.424073,-66.321098,0.043630,0.000000
32.410000,25.493362,-66.410057,-0.003359,0.001693,0.043014,113.400139,5.776878,0.430144,-66.410057,0.044203,0.000000
32.750000,25.767799,-66.365578,-0.003333,0.001718,0.043639,114.620895,5.839067,0.436388,-66.365578,0.044766,0.000000
33.090000,25.591293,-66.499023,-0.003311,0.001728,0.043890,113.835754,5.799070,0.438903,-66.499023,0.045339,0.000000
33.430000,26.470467,-66.543503,-0.003303,0.001756,0.044601,117.746513,5.998293,0.446014,-66.543503,0.045902,0.000000
33.770000,27.342560,-66.543503,-0.003272,0.001788,0.045408,121.625778,6.195913,0.454080,-66.543503,0.046466,0.000000
34.110001,27.619980,-66.587982,-0.003238,0.001812,0.046032,122.859810,6.258777,0.460323,-66.587982,0.047038,0.000000
34.450001,27.668015,-66.632462,-0.003234,0.001835,0.046605,123.073479,6.269661,0.466047,-66.632462,0.047602,0.000000
34.790001,27.745094,-66.587982,-0.003195,0.001855,0.047116,123.416344,6.287128,0.471164,-66.587982,0.048166,0.000000
35.130001,27.331764,-66.765907,-0.003186,0.001867,0.047411,121.577759,6.193467,0.474112,-66.765907,0.048738,0.000000
35.470001,27.669876,-66.721428,-0.003186,0.001887,0.047923,123.081757,6.270084,0.479229,-66.721428,0.049302,0.000000
35.810001,28.991798,-66.765907,-0.003143,0.001921,0.048790,128.961960,6.569635,0.487901,-66.765907,0.049865,0.000000
36.150002,29.106491,-66.765907,-0.003134,0.001939,0.049258,129.472137,6.595625,0.492584,-66.765907,0.050438,0.000000
36.490002,29.425613,-66.810387,-0.003113,0.001960,0.049787,130.891663,6.667939,0.497874,-66.810387,0.051002,0.000000
36.830002,29.355980,-66.899353,-0.003083,0.001982,0.050334,130.581924,6.652160,0.503338,-66.899353,0.051565,0.000000
37.170002,30.671570,-66.854866,-0.003070,0.002010,0.051045,136.433960,6.950277,0.510449,-66.854866,0.052138,0.000000
37.510002,30.959045,-66.943832,-0.003053,0.002031,0.051583,137.712708,7.015420,0.515826,-66.943832,0.052701,0.000000
37.850002,31.032028,-66.943832,-0.003031,0.002051,0.052086,138.037354,7.031958,0.520856,-66.943832,0.053265,0.000000
38.190002,31.707512,-67.032791,-0.003014,0.002080,0.052831,141.042053,7.185025,0.528314,-67.032791,0.053837,0.000000
38.530003,32.248199,-67.032791,-0.002997,0.002101,0.053378,143.447159,7.307547,0.533778,-67.032791,0.054401,0.000000
38.870003,32.313362,-67.121758,-0.002962,0.002122,0.053889,143.737015,7.322312,0.538894,-67.121758,0.054965,0.000000
39.210003,32.469017,-67.121758,-0.002966,0.002140,0.054358,144.429398,7.357584,0.543577,-67.121758,0.055537,0.000000
39.550003,32.515930,-67.166237,-0.002932,0.002157,0.054800,144.638077,7.368215,0.548000,-67.166237,0.056101,0.000000
39.890003,33.420052,-67.166237,-0.002928,0.002184,0.055485,148.659821,7.573092,0.554851,-67.166237,0.056665,0.000000
40.230003,33.389145,-67.255196,-0.002897,0.002204,0.055988,148.522339,7.566088,0.559881,-67.255196,0.057237,0.000000
40.570004,34.356941,-67.299683,-0.002876,0.002227,0.056569,152.827301,7.785394,0.565691,-67.299683,0.057801,0.000000
40.910004,33.865784,-67.388641,-0.002871,0.002238,0.056838,150.642532,7.674097,0.568380,-67.388641,0.058364,0.000000
41.250004,34.721123,-67.344162,-0.002846,0.002263,0.057471,154.447266,7.867919,0.574710,-67.344162,0.058937,0.000000
41.590000,36.434410,-67.477600,-0.002833,0.002299,0.058399,162.068344,8.256155,0.583990,-67.477600,0.059500,0.000000
41.930000,36.154381,-67.433121,-0.002807,0.002314,0.058763,160.822723,8.192699,0.587632,-67.433121,0.060073,0.000000
42.270000,37.408165,-67.477600,-0.002785,0.002345,0.059561,166.399826,8.476811,0.595611,-67.477600,0.060636,0.000000
42.610001,37.402580,-67.522087,-0.002781,0.002364,0.060055,166.374985,8.475546,0.600554,-67.522087,0.061200,0.000000
42.950001,36.807152,-67.566566,-0.002746,0.002373,0.060272,163.726395,8.340620,0.602722,-67.566566,0.061772,0.000000
43.290001,38.111572,-67.566566,-0.002738,0.002408,0.061157,169.528748,8.636206,0.611568,-67.566566,0.062336,0.000000
43.630001,39.032082,-67.611046,-0.002716,0.002429,0.061686,173.623367,8.844796,0.616858,-67.611046,0.062900,0.000000
43.970001,39.476318,-67.655525,-0.002721,0.002451,0.062249,175.599442,8.945462,0.622495,-67.655525,0.063472,0.000000
44.310001,40.103767,-67.788971,-0.002690,0.002473,0.062822,178.390472,9.087644,0.628218,-67.788971,0.064036,0.000000
44.650002,40.630676,-67.700005,-0.002665,0.002498,0.063455,180.734268,9.207043,0.634549,-67.700005,0.064600,0.000000
44.990002,41.101723,-67.788971,-0.002656,0.002519,0.063993,182.829590,9.313783,0.639926,-67.788971,0.065172,0.000000
45.330002,42.006592,-67.877930,-0.002613,0.002546,0.064660,186.854660,9.518830,0.646604,-67.877930,0.065736,0.000000
45.670002,42.223312,-67.877930,-0.002617,0.002563,0.065103,187.818680,9.567940,0.651026,-67.877930,0.066299,0.000000
46.010002,42.909592,-67.922409,-0.002596,0.002589,0.065762,190.871399,9.723453,0.657617,-67.922409,0.066872,0.000000
46.350002,43.539650,-67.966896,-0.002587,0.002611,0.066308,193.674042,9.866225,0.663081,-67.966896,0.067435,0.000000
46.690002,43.886696,-68.055855,-0.002557,0.002632,0.066846,195.217773,9.944867,0.668458,-68.055855,0.067999,0.000000
47.030003,44.442650,-68.055855,-0.002535,0.002655,0.067435,197.690781,10.070848,0.674355,-68.055855,0.068572,0.000000
47.370003,45.187019,-68.055855,-0.002518,0.002676,0.067982,201.001907,10.239525,0.679818,-68.055855,0.069135,0.000000
47.710003,45.481567,-68.144814,-0.002509,0.002699,0.068563,202.312119,10.306271,0.685629,-68.144814,0.069699,0.000000
48.050003,47.042931,-68.100334,-0.002501,0.002727,0.069274,209.257401,10.660081,0.692740,-68.100334,0.070271,0.000000
48.390003,47.359070,-68.278259,-0.002470,0.002749,0.069829,210.663666,10.731719,0.698290,-68.278259,0.070835,0.000000
48.730003,47.912415,-68.233780,-0.002458,0.002771,0.070393,213.125061,10.857109,0.703927,-68.233780,0.071399,0.000000
49.070004,48.355911,-68.233780,-0.002432,0.002788,0.070826,215.097839,10.957605,0.708263,-68.233780,0.071971,0.000000
49.410004,48.826591,-68.367218,-0.002414,0.002811,0.071407,217.191528,11.064263,0.714074,-68.367218,0.072535,0.000000
49.750004,49.268227,-68.322739,-0.002397,0.002831,0.071919,219.156021,11.164339,0.719190,-68.322739,0.073107,0.000000
50.090004,49.925087,-68.411705,-0.002393,0.002852,0.072448,222.077881,11.313187,0.724480,-68.411705,0.073671,0.000000
50.430004,50.183517,-68.411705,-0.002358,0.002870,0.072899,223.227432,11.371748,0.728990,-68.411705,0.074235,0.000000
50.770004,50.740959,-68.411705,-0.002350,0.002888,0.073367,225.707062,11.498065,0.733673,-68.411705,0.074807,0.000000
51.110001,52.225609,-68.500664,-0.002350,0.002916,0.074078,232.311111,11.834493,0.740784,-68.500664,0.075371,0.000000
51.450001,52.716766,-68.456184,-0.002328,0.002937,0.074590,234.495895,11.945790,0.745901,-68.456184,0.075934,0.000000
51.790001,54.665390,-68.545143,-0.002294,0.002973,0.075518,243.163803,12.387354,0.755180,-68.545143,0.076507,0.000000
52.130001,55.091011,-68.589630,-0.002294,0.002991,0.075960,245.057053,12.483801,0.759603,-68.589630,0.077070,0.000000
52.470001,55.151337,-68.678589,-0.002281,0.003007,0.076377,245.325394,12.497472,0.763766,-68.678589,0.077634,0.000000
52.810001,55.480888,-68.723068,-0.002259,0.003025,0.076845,246.791321,12.572148,0.768449,-68.723068,0.078206,0.000000
53.150002,57.287636,-68.678589,-0.002238,0.003057,0.077651,254.828125,12.981564,0.776514,-68.678589,0.078770,0.000000
53.490002,57.024742,-68.812035,-0.002225,0.003068,0.077938,253.658722,12.921990,0.779376,-68.812035,0.079334,0.000000
53.830002,57.596336,-68.767548,-0.002203,0.003089,0.078449,256.201294,13.051517,0.784492,-68.767548,0.079906,0.000000
54.170002,58.959961,-68.856514,-0.002207,0.003117,0.079169,262.266998,13.360518,0.791691,-68.856514,0.080470,0.000000
54.510002,59.102211,-68.856514,-0.002195,0.003133,0.079585,262.899750,13.392753,0.795853,-68.856514,0.081034,0.000000
54.850002,61.043388,-68.945473,-0.002164,0.003166,0.080409,271.534546,13.832629,0.804092,-68.945473,0.081606,0.000000
55.190002,62.055496,-68.989952,-0.002134,0.003191,0.081051,276.036621,14.061976,0.810509,-68.989952,0.082170,0.000000
55.530003,62.938766,-68.989952,-0.002139,0.003215,0.081649,279.965607,14.262128,0.816493,-68.989952,0.082733,0.000000
55.870003,63.702126,-69.034439,-0.002113,0.003239,0.082274,283.361206,14.435108,0.822737,-69.034439,0.083306,0.000000
56.210003,64.123650,-69.078918,-0.002091,0.003254,0.082664,285.236237,14.530626,0.826640,-69.078918,0.083869,0.000000
56.550003,63.820915,-69.078918,-0.002087,0.003266,0.082959,283.889618,14.462027,0.829588,-69.078918,0.084433,0.000000
56.890003,65.704750,-69.123398,-0.002078,0.003299,0.083791,292.269318,14.888908,0.837914,-69.123398,0.085005,0.000000
57.230003,65.074684,-69.167877,-0.002048,0.003298,0.083765,289.466644,14.746135,0.837653,-69.167877,0.014720,0.000000
57.570004,66.785744,-69.256844,-0.002035,0.003186,0.080912,297.077820,15.133866,0.809122,-69.256844,294.500488,0.000000
57.910004,65.208366,-69.212357,-0.002013,0.003273,0.083124,290.061310,14.776427,0.831236,-69.212357,294.500488,0.000000
58.250004,64.970802,-69.301323,-0.002026,0.003342,0.084884,289.004578,14.722594,0.848841,-69.301323,294.500488,0.000000
58.590004,66.023125,-69.301323,-0.002005,0.003355,0.085222,293.685516,14.961054,0.852223,-69.301323,294.500488,0.000000
58.930004,64.740303,-69.345802,-0.002001,0.003356,0.085231,287.979248,14.670362,0.852309,-69.345802,294.500488,0.000000
59.270004,65.250450,-69.434761,-0.002001,0.003370,0.085587,290.248505,14.785963,0.855865,-69.434761,294.500488,0.000000
59.610004,65.279121,-69.390282,-0.001983,0.003388,0.086046,290.376038,14.792460,0.860461,-69.390282,294.500488,0.000000
59.950005,64.358620,-69.434761,-0.001979,0.003388,0.086063,286.281433,14.583872,0.860635,-69.434761,294.500488,0.000000
60.290005,66.362358,-69.479248,-0.001962,0.003283,0.083392,295.194519,15.037926,0.833924,-69.479248,294.500488,0.000000
60.630001,65.304070,-69.434761,-0.001949,0.003353,0.085170,290.487000,14.798114,0.851702,-69.434761,294.500488,0.000000
60.970001,65.572182,-69.612686,-0.001949,0.003424,0.086965,291.679626,14.858869,0.869654,-69.612686,294.500488,0.000000
61.310001,64.735466,-69.612686,-0.001944,0.003424,0.086974,287.957733,14.669267,0.869741,-69.612686,294.500488,0.000000
61.650002,66.900429,-69.657173,-0.001927,0.003344,0.084945,297.587982,15.159854,0.849448,-69.657173,294.500488,0.000000
61.990002,65.879753,-69.701653,-0.001914,0.003323,0.084407,293.047791,14.928565,0.844071,-69.701653,294.500488,0.000000
62.330002,65.188637,-69.746132,-0.001910,0.003435,0.087252,289.973541,14.771956,0.872516,-69.746132,294.500488,0.000000
62.670002,65.540154,-69.835091,-0.001910,0.003461,0.087919,291.537170,14.851611,0.879193,-69.835091,294.500488,0.000000
63.010002,65.286201,-69.790611,-0.001897,0.003467,0.088058,290.407532,14.794065,0.880581,-69.790611,294.500488,0.000000
63.350002,65.034096,-69.924057,-0.001901,0.003470,0.088145,289.286102,14.736937,0.881448,-69.924057,294.500488,0.000000
63.690002,65.362907,-69.968536,-0.001888,0.003481,0.088405,290.748718,14.811446,0.884050,-69.968536,294.500488,0.000000
64.030006,64.846794,-69.924057,-0.001906,0.003482,0.088431,288.452942,14.694494,0.884310,-69.924057,294.500488,0.000000
64.370003,66.027962,-70.013016,-0.001871,0.003489,0.088630,293.707031,14.962150,0.886305,-70.013016,294.500488,0.000000
64.710007,65.319710,-69.968536,-0.001871,0.003490,0.088639,290.556580,14.801658,0.886391,-69.968536,294.500488,0.000000
65.050003,64.676628,-70.013016,-0.001867,0.003490,0.088656,287.696014,14.655933,0.886565,-70.013016,294.500488,0.000000
65.389999,65.903221,-70.101982,-0.001871,0.003498,0.088856,293.152161,14.933884,0.888559,-70.101982,294.500488,0.000000
65.730003,65.277260,-70.057495,-0.001863,0.003498,0.088856,290.367767,14.792039,0.888559,-70.057495,294.500488,0.000000
66.070000,64.853508,-70.190941,-0.001845,0.003525,0.089541,288.482819,14.696015,0.895411,-70.190941,294.500488,0.000000
66.410004,65.716286,-70.146461,-0.001850,0.003518,0.089368,292.320648,14.891523,0.893676,-70.146461,294.500488,0.000000
66.750000,65.063515,-70.235420,-0.001850,0.003518,0.089368,289.416962,14.743604,0.893676,-70.235420,294.500488,0.000000
67.090004,65.946037,-70.190941,-0.001841,0.003533,0.089741,293.342621,14.943585,0.897405,-70.190941,294.500488,0.000000
67.430000,65.379662,-70.279900,-0.001845,0.003533,0.089741,290.823273,14.815243,0.897405,-70.279900,294.500488,0.000000
67.770004,64.846794,-70.324387,-0.001828,0.003533,0.089749,288.452942,14.694494,0.897492,-70.324387,294.500488,0.000000
68.110001,64.370155,-70.324387,-0.001850,0.003533,0.089749,286.332764,14.586486,0.897492,-70.324387,294.500488,0.000000
68.450005,66.905281,-70.368866,-0.001824,0.003366,0.085500,297.609558,15.160954,0.854998,-70.368866,294.500488,0.000000
68.790001,66.133720,-70.457825,-0.001819,0.003364,0.085456,294.177490,14.986115,0.854564,-70.457825,294.500488,0.000000
69.130005,65.641075,-70.457825,-0.001824,0.003377,0.085769,291.986084,14.874480,0.857686,-70.457825,294.500488,0.000000
69.470001,65.251564,-70.502304,-0.001811,0.003532,0.089714,290.253448,14.786216,0.897145,-70.502304,294.500488,0.000000
69.810005,65.037819,-70.502304,-0.001807,0.003557,0.090339,289.302673,14.737781,0.903389,-70.502304,294.500488,0.000000
70.150002,65.132408,-70.635750,-0.001824,0.003568,0.090616,289.723419,14.759214,0.906164,-70.635750,294.500488,0.000000
70.490005,65.021446,-70.546791,-0.001815,0.003572,0.090738,289.229828,14.734070,0.907378,-70.546791,294.500488,0.000000
70.830002,64.930962,-70.680229,-0.001819,0.003575,0.090816,288.827332,14.713567,0.908159,-70.680229,294.500488,0.000000
71.170006,65.312263,-70.680229,-0.001802,0.003583,0.091007,290.523468,14.799971,0.910067,-70.680229,294.500488,0.000000
71.510002,65.044151,-70.680229,-0.001811,0.003583,0.091015,289.330841,14.739215,0.910153,-70.680229,294.500488,0.000000
71.850006,65.327538,-70.769196,-0.001798,0.003590,0.091189,290.591400,14.803432,0.911888,-70.769196,294.500488,0.000000
72.190002,65.031868,-70.769196,-0.001789,0.003590,0.091189,289.276184,14.736432,0.911888,-70.769196,294.500488,0.000000
72.530006,64.732109,-70.858154,-0.001789,0.003590,0.091189,287.942810,14.668506,0.911888,-70.858154,294.500488,0.000000
72.870003,65.779961,-70.858154,-0.001785,0.003605,0.091570,292.603882,14.905951,0.915704,-70.858154,294.500488,0.000000
73.210007,65.536430,-70.813675,-0.001807,0.003605,0.091570,291.520599,14.850768,0.915704,-70.813675,294.500488,0.000000
73.550003,65.235558,-70.991600,-0.001794,0.003605,0.091570,290.182251,14.782589,0.915704,-70.991600,294.500488,0.000000
73.890007,64.964104,-70.858154,-0.001781,0.003605,0.091570,288.974762,14.721076,0.915704,-70.858154,294.500488,0.000000
74.230003,65.270180,-71.036079,-0.001785,0.003613,0.091770,290.336273,14.790435,0.917698,-71.036079,294.500488,0.000000
74.570007,65.038948,-71.080559,-0.001781,0.003613,0.091770,289.307678,14.738036,0.917698,-71.080559,294.500488,0.000000
74.910004,64.805473,-71.080559,-0.001785,0.003613,0.091778,288.269135,14.685130,0.917785,-71.080559,294.500488,0.000000
75.250000,65.854439,-71.169525,-0.001785,0.003626,0.092108,292.935181,14.922830,0.921080,-71.169525,294.500488,0.000000
75.590004,65.580376,-71.125038,-0.001772,0.003626,0.092108,291.716095,14.860725,0.921080,-71.125038,294.500488,0.000000
75.930000,65.317482,-71.214005,-0.001776,0.003626,0.092108,290.546661,14.801153,0.921080,-71.214005,294.500488,0.000000
76.270004,65.065758,-71.169525,-0.001776,0.003626,0.092108,289.426941,14.744112,0.921080,-71.169525,294.500488,0.000000
76.610001,65.286568,-71.302963,-0.001759,0.003634,0.092316,290.409149,14.794147,0.923162,-71.302963,294.500488,0.000000
76.950005,65.170021,-71.347443,-0.001759,0.003633,0.092290,289.890747,14.767738,0.922902,-71.347443,294.500488,0.000000
77.290001,64.964836,-71.302963,-0.001759,0.003633,0.092290,288.978027,14.721243,0.922902,-71.302963,294.500488,0.000000
77.630005,64.724663,-71.347443,-0.001763,0.003634,0.092299,287.909668,14.666818,0.922988,-71.347443,294.500488,0.000000
77.970001,64.487083,-71.347443,-0.001755,0.003634,0.092299,286.852875,14.612983,0.922988,-71.347443,294.500488,0.000000
78.310005,66.086052,-71.436409,-0.001755,0.003643,0.092542,293.965454,14.975313,0.925417,-71.436409,294.500488,0.000000
78.650002,65.774010,-71.525368,-0.001750,0.003643,0.092542,292.577393,14.904604,0.925417,-71.525368,294.500488,0.000000
78.990005,65.526009,-71.480888,-0.001759,0.003643,0.092542,291.474243,14.848406,0.925417,-71.480888,294.500488,0.000000
79.330002,65.260506,-71.569847,-0.001750,0.003643,0.092542,290.293213,14.788242,0.925417,-71.569847,294.500488,0.000000
79.670006,65.006920,-71.569847,-0.001742,0.003644,0.092550,289.165222,14.730779,0.925503,-71.569847,294.500488,0.000000
80.010002,64.742912,-71.614334,-0.001755,0.003644,0.092550,287.990845,14.670954,0.925503,-71.614334,294.500488,0.000000
80.350006,64.507561,-71.658813,-0.001742,0.003644,0.092559,286.943970,14.617622,0.925590,-71.658813,294.500488,0.000000
80.690002,67.266853,-71.703293,-0.001750,0.003671,0.093235,299.217896,15.242887,0.932354,-71.703293,294.500488,0.000000
81.030006,66.666588,-71.792252,-0.001746,0.003551,0.090183,296.547791,15.106865,0.901828,-71.792252,294.500488,0.000000
81.370003,66.362724,-71.747772,-0.001733,0.003551,0.090191,295.196136,15.038008,0.901915,-71.747772,294.500488,0.000000
81.710007,66.111748,-71.836739,-0.001746,0.003551,0.090191,294.079742,14.981136,0.901915,-71.836739,294.500488,0.000000
82.050003,65.836189,-71.836739,-0.001720,0.003552,0.090217,292.854004,14.918694,0.902175,-71.836739,294.500488,0.000000
82.390007,65.631020,-71.836739,-0.001729,0.003576,0.090833,291.941345,14.872202,0.908332,-71.836739,294.500488,0.000000
82.730003,65.412804,-71.925697,-0.001733,0.003631,0.092229,290.970673,14.822754,0.922295,-71.925697,294.500488,0.000000
83.070007,65.222527,-71.925697,-0.001738,0.003636,0.092351,290.124298,14.779635,0.923509,-71.925697,294.500488,0.000000
83.410004,65.044533,-72.059143,-0.001733,0.003655,0.092845,289.332520,14.739302,0.928452,-72.059143,294.500488,0.000000
83.750008,64.991280,-72.059143,-0.001725,0.003669,0.093183,289.095642,14.727234,0.931834,-72.059143,294.500488,0.000000
84.090004,64.911217,-72.014656,-0.001729,0.003671,0.093235,288.739502,14.709092,0.932354,-72.014656,294.500488,0.000000
84.430000,64.722801,-72.103622,-0.001729,0.003671,0.093235,287.901398,14.666396,0.932354,-72.103622,294.500488,0.000000
84.770004,64.804344,-72.148102,-0.001720,0.003690,0.093721,288.264130,14.684875,0.937211,-72.148102,294.500488,0.000000
85.110001,66.074135,-72.192581,-0.001712,0.003683,0.093548,293.912445,14.972612,0.935477,-72.192581,294.500488,0.000000
85.450005,65.829857,-72.192581,-0.001712,0.003683,0.093539,292.825836,14.917259,0.935390,-72.192581,294.500488,0.000000
85.790001,65.633247,-72.281548,-0.001720,0.003683,0.093539,291.951263,14.872706,0.935390,-72.281548,294.500488,0.000000
86.130005,65.450783,-72.281548,-0.001716,0.003683,0.093539,291.139618,14.831359,0.935390,-72.281548,294.500488,0.000000
86.470001,65.248589,-72.326027,-0.001720,0.003683,0.093548,290.240204,14.785542,0.935477,-72.326027,294.500488,0.000000
86.810005,65.064644,-72.370506,-0.001716,0.003683,0.093556,289.421997,14.743859,0.935563,-72.370506,294.500488,0.000000
87.150002,64.900414,-72.370506,-0.001716,0.003683,0.093556,288.691467,14.706643,0.935563,-72.370506,294.500488,0.000000
87.490005,65.938972,-72.459473,-0.001720,0.003704,0.094077,293.311188,14.941985,0.940766,-72.459473,294.500488,0.000000
87.830002,65.837685,-72.503952,-0.001716,0.003704,0.094077,292.860657,14.919033,0.940766,-72.503952,294.500488,0.000000
88.170006,65.772148,-72.503952,-0.001707,0.003704,0.094077,292.569122,14.904181,0.940766,-72.503952,294.500488,0.000000
88.510002,65.609413,-72.548431,-0.001703,0.003704,0.094077,291.845245,14.867306,0.940766,-72.548431,294.500488,0.000000
88.850006,65.470528,-72.548431,-0.001703,0.003704,0.094077,291.227448,14.835834,0.940766,-72.548431,294.500488,0.000000
89.190002,65.298485,-72.681877,-0.001699,0.003704,0.094077,290.462158,14.796848,0.940766,-72.681877,294.500488,0.000000
89.530006,65.175606,-72.592911,-0.001707,0.003704,0.094094,289.915588,14.769003,0.940940,-72.592911,294.500488,0.000000
89.870003,65.024055,-72.681877,-0.001712,0.003705,0.094103,289.241455,14.734662,0.941027,-72.681877,294.500488,0.000000
90.210007,64.906380,-72.726357,-0.001703,0.003705,0.094103,288.717987,14.707996,0.941027,-72.726357,294.500488,0.000000
90.550003,64.747749,-72.726357,-0.001707,0.003705,0.094103,288.012360,14.672050,0.941027,-72.726357,294.500488,0.000000
90.890007,65.705864,-72.815315,-0.001703,0.003718,0.094432,292.274292,14.889161,0.944322,-72.815315,294.500488,0.000000
91.230003,65.635857,-72.770836,-0.001690,0.003718,0.094432,291.962860,14.873298,0.944322,-72.770836,294.500488,0.000000
91.570007,65.534203,-72.859795,-0.001707,0.003718,0.094432,291.510681,14.850263,0.944322,-72.859795,294.500488,0.000000
91.910004,65.388222,-72.904282,-0.001699,0.003718,0.094432,290.861328,14.817183,0.944322,-72.904282,294.500488,0.000000
92.250008,65.278374,-72.993240,-0.001707,0.003718,0.094432,290.372711,14.792291,0.944322,-72.993240,294.500488,0.000000
92.590004,65.135384,-72.993240,-0.001699,0.003718,0.094432,289.736664,14.759890,0.944322,-72.993240,294.500488,0.000000
92.930008,65.001335,-72.993240,-0.001686,0.003718,0.094432,289.140381,14.729513,0.944322,-72.993240,294.500488,0.000000
93.270004,64.860207,-73.082199,-0.001694,0.003718,0.094441,288.512604,14.697534,0.944409,-73.082199,294.500488,0.000000
93.610008,64.736198,-73.126686,-0.001681,0.003718,0.094441,287.960999,14.669432,0.944409,-73.126686,294.500488,0.000000
93.950005,65.699898,-73.171165,-0.001699,0.003732,0.094796,292.247742,14.887810,0.947965,-73.171165,294.500488,0.000000
94.290001,65.762093,-73.171165,-0.001694,0.003732,0.094796,292.524384,14.901904,0.947965,-73.171165,294.500488,0.000000
94.630005,65.670113,-73.171165,-0.001686,0.003732,0.094796,292.115265,14.881061,0.947965,-73.171165,294.500488,0.000000
94.970001,65.568092,-73.260124,-0.001690,0.003732,0.094796,291.661438,14.857943,0.947965,-73.260124,294.500488,0.000000
95.310005,65.454887,-73.304604,-0.001681,0.003732,0.094796,291.157867,14.832290,0.947965,-73.304604,294.500488,0.000000
95.650002,65.338326,-73.304604,-0.001694,0.003732,0.094796,290.639374,14.805876,0.947965,-73.304604,294.500488,0.000000
95.990005,65.237785,-73.349091,-0.001681,0.003732,0.094805,290.192169,14.783093,0.948051,-73.349091,294.500488,0.000000
96.330002,65.123100,-73.349091,-0.001673,0.003733,0.094814,289.682007,14.757106,0.948138,-73.349091,294.500488,0.000000
96.670006,65.015114,-73.438049,-0.001690,0.003733,0.094822,289.201660,14.732635,0.948225,-73.438049,294.500488,0.000000
97.010002,65.191994,-73.393570,-0.001677,0.003738,0.094944,289.988464,14.772717,0.949439,-73.393570,294.500488,0.000000
97.350006,65.215080,-73.482529,-0.001690,0.003738,0.094944,290.091156,14.777948,0.949439,-73.482529,294.500488,0.000000
97.690002,65.271309,-73.571495,-0.001681,0.003740,0.095005,290.341278,14.790690,0.950046,-73.571495,294.500488,0.000000
98.030006,65.218803,-73.527016,-0.001681,0.003740,0.095005,290.107727,14.778792,0.950046,-73.527016,294.500488,0.000000
98.370003,65.115654,-73.615974,-0.001677,0.003740,0.095005,289.648895,14.755418,0.950046,-73.615974,294.500488,0.000000
98.710007,65.061287,-73.571495,-0.001690,0.003744,0.095091,289.407043,14.743098,0.950913,-73.571495,294.500488,0.000000
99.050003,65.165550,-73.615974,-0.001681,0.003745,0.095117,289.870850,14.766726,0.951173,-73.615974,294.500488,0.000000
99.390007,65.213951,-73.615974,-0.001673,0.003746,0.095143,290.086151,14.777693,0.951433,-73.615974,294.500488,0.000000
99.730003,65.130547,-73.660454,-0.001669,0.003747,0.095169,289.715149,14.758793,0.951694,-73.660454,294.500488,0.000000
100.070007,65.172997,-73.793900,-0.001686,0.003748,0.095187,289.903961,14.768412,0.951867,-73.793900,294.500488,0.000000
100.410004,65.098518,-73.749420,-0.001677,0.003748,0.095195,289.572662,14.751535,0.951954,-73.749420,294.500488,0.000000
100.750008,65.021812,-73.882858,-0.001664,0.003748,0.095195,289.231476,14.734154,0.951954,-73.882858,294.500488,0.000000
101.090004,65.313377,-73.882858,-0.001669,0.003753,0.095325,290.528412,14.800222,0.953255,-73.882858,294.500488,0.000000
101.430008,65.276894,-73.927338,-0.001677,0.003753,0.095325,290.366119,14.791956,0.953255,-73.927338,294.500488,0.000000
101.770004,65.228111,-74.016304,-0.001673,0.003753,0.095325,290.149139,14.780901,0.953255,-74.016304,294.500488,0.000000
102.110008,65.122353,-73.971825,-0.001660,0.003753,0.095334,289.678680,14.756936,0.953341,-73.971825,294.500488,0.000000
102.450005,65.056068,-74.060783,-0.001669,0.003754,0.095343,289.383850,14.741916,0.953428,-74.060783,294.500488,0.000000
102.790009,64.994255,-74.060783,-0.001673,0.003754,0.095351,289.108887,14.727909,0.953515,-74.060783,294.500488,0.000000
103.130005,65.313011,-74.060783,-0.001664,0.003759,0.095482,290.526794,14.800140,0.954815,-74.060783,294.500488,0.000000
103.470001,65.278374,-74.194229,-0.001673,0.003759,0.095482,290.372711,14.792291,0.954815,-74.194229,294.500488,0.000000
103.810005,65.218803,-74.149742,-0.001660,0.003759,0.095482,290.107727,14.778792,0.954815,-74.149742,294.500488,0.000000
104.150002,65.116768,-74.283188,-0.001681,0.003759,0.095482,289.653839,14.755671,0.954815,-74.283188,294.500488,0.000000
104.490005,65.094048,-74.149742,-0.001664,0.003761,0.095525,289.552795,14.750523,0.955249,-74.149742,294.500488,0.000000
104.830002,65.058678,-74.283188,-0.001664,0.003761,0.095525,289.395447,14.742507,0.955249,-74.283188,294.500488,0.000000
105.170006,65.010277,-74.372147,-0.001664,0.003761,0.095534,289.180145,14.731539,0.955336,-74.372147,294.500488,0.000000
105.510002,64.952919,-74.327667,-0.001669,0.003762,0.095542,288.925018,14.718541,0.955423,-74.327667,294.500488,0.000000
105.850006,65.194969,-74.372147,-0.001669,0.003767,0.095672,290.001709,14.773392,0.956724,-74.372147,294.500488,0.000000
106.190002,65.236305,-74.372147,-0.001660,0.003767,0.095672,290.185577,14.782759,0.956724,-74.372147,294.500488,0.000000
106.530006,65.187889,-74.461113,-0.001660,0.003767,0.095672,289.970215,14.771787,0.956724,-74.461113,294.500488,0.000000
106.870003,65.090706,-74.505592,-0.001656,0.003767,0.095672,289.537933,14.749764,0.956724,-74.505592,294.500488,0.000000
107.210007,65.036705,-74.550072,-0.001660,0.003767,0.095672,289.297699,14.737528,0.956724,-74.550072,294.500488,0.000000
107.550003,64.971169,-74.594559,-0.001669,0.003767,0.095672,289.006195,14.722678,0.956724,-74.594559,294.500488,0.000000
107.890007,64.889244,-74.550072,-0.001660,0.003767,0.095672,288.641785,14.704113,0.956724,-74.550072,294.500488,0.000000
108.230003,64.796532,-74.639038,-0.001660,0.003767,0.095672,288.229370,14.683104,0.956724,-74.639038,294.500488,0.000000
108.570007,64.721306,-74.727997,-0.001651,0.003767,0.095672,287.894745,14.666058,0.956724,-74.727997,294.500488,0.000000
108.910004,64.644966,-74.727997,-0.001656,0.003767,0.095681,287.555176,14.648759,0.956810,-74.727997,294.500488,0.000000
109.250008,65.579628,-74.727997,-0.001673,0.003779,0.095985,291.712769,14.860556,0.959846,-74.727997,294.500488,0.000000
109.590004,65.609795,-74.772476,-0.001664,0.003779,0.095985,291.846954,14.867392,0.959846,-74.772476,294.500488,0.000000
109.930008,65.574043,-74.861443,-0.001651,0.003779,0.095985,291.687927,14.859290,0.959846,-74.861443,294.500488,0.000000
110.270004,65.546852,-74.905922,-0.001656,0.003779,0.095985,291.566956,14.853129,0.959846,-74.905922,294.500488,0.000000
110.610008,65.485786,-74.905922,-0.001664,0.003779,0.095985,291.295319,14.839292,0.959846,-74.905922,294.500488,0.000000
110.950005,65.370354,-74.950401,-0.001660,0.003779,0.095985,290.781860,14.813134,0.959846,-74.950401,294.500488,0.000000
111.290009,65.293282,-74.950401,-0.001656,0.003779,0.095985,290.439026,14.795669,0.959846,-74.950401,294.500488,0.000000
111.630005,65.243370,-74.994881,-0.001643,0.003779,0.095985,290.217010,14.784359,0.959846,-74.994881,294.500488,0.000000
111.970009,65.161079,-74.994881,-0.001634,0.003779,0.095993,289.850952,14.765712,0.959932,-74.994881,294.500488,0.000000
112.310005,65.067238,-75.039368,-0.001643,0.003779,0.095993,289.433533,14.744447,0.959932,-75.039368,294.500488,0.000000
112.650009,65.012871,-75.128326,-0.001638,0.003779,0.095993,289.191681,14.732127,0.959932,-75.128326,294.500488,0.000000
112.990005,64.957771,-75.172806,-0.001643,0.003780,0.096002,288.946594,14.719642,0.960019,-75.172806,294.500488,0.000000
113.330002,64.865425,-75.217285,-0.001664,0.003780,0.096002,288.535828,14.698715,0.960019,-75.217285,294.500488,0.000000
113.670006,64.805840,-75.172806,-0.001638,0.003780,0.096002,288.270782,14.685213,0.960019,-75.172806,294.500488,0.000000
114.010002,65.204277,-75.261772,-0.001656,0.003786,0.096175,290.043121,14.775500,0.961753,-75.261772,294.500488,0.000000
114.350006,65.235191,-75.306252,-0.001656,0.003786,0.096175,290.180634,14.782506,0.961753,-75.306252,294.500488,0.000000
114.690002,65.193108,-75.306252,-0.001651,0.003786,0.096175,289.993439,14.772969,0.961753,-75.306252,294.500488,0.000000
115.030006,65.126076,-75.395210,-0.001638,0.003786,0.096175,289.695251,14.757779,0.961753,-75.395210,294.500488,0.000000
115.370003,65.061287,-75.395210,-0.001643,0.003786,0.096175,289.407043,14.743098,0.961753,-75.395210,294.500488,0.000000
115.710007,64.999840,-75.439690,-0.001651,0.003786,0.096175,289.133728,14.729175,0.961753,-75.439690,294.500488,0.000000
116.050003,64.949577,-75.439690,-0.001643,0.003787,0.096184,288.910156,14.717784,0.961840,-75.439690,294.500488,0.000000
116.390007,64.889244,-75.439690,-0.001634,0.003787,0.096184,288.641785,14.704113,0.961840,-75.439690,294.500488,0.000000
116.730003,65.214333,-75.573135,-0.001643,0.003792,0.096305,290.087830,14.777779,0.963054,-75.573135,294.500488,0.000000
117.070007,65.204277,-75.528656,-0.001634,0.003792,0.096305,290.043121,14.775500,0.963054,-75.528656,294.500488,0.000000
117.410004,65.114906,-75.617615,-0.001647,0.003792,0.096305,289.645569,14.755248,0.963054,-75.617615,294.500488,0.000000
117.750008,65.074684,-75.662094,-0.001647,0.003783,0.096089,289.466644,14.746135,0.960886,-75.662094,0.096262,0.000000
118.090004,64.908241,-75.617615,-0.001634,0.003776,0.095898,288.726288,14.708417,0.958978,-75.617615,0.095690,0.000000
118.430008,64.872871,-75.706581,-0.001630,0.003760,0.095516,288.568939,14.700402,0.955162,-75.706581,0.095126,0.000000
118.770004,64.707527,-75.706581,-0.001621,0.003745,0.095126,287.833466,14.662935,0.951260,-75.706581,0.094562,0.000000
119.110008,64.611458,-75.795540,-0.001634,0.003723,0.094554,287.406128,14.641166,0.945536,-75.795540,0.093990,0.000000
119.450005,64.517250,-75.840019,-0.001625,0.003702,0.094025,286.987061,14.619818,0.940246,-75.840019,0.093426,0.000000
119.790009,64.463249,-75.840019,-0.001625,0.003683,0.093548,286.746857,14.607581,0.935477,-75.840019,0.092863,0.000000
120.130005,64.327339,-75.884506,-0.001634,0.003655,0.092845,286.142303,14.576783,0.928452,-75.884506,0.092290,0.000000
120.470009,64.282661,-75.928986,-0.001634,0.003638,0.092412,285.943573,14.566660,0.924116,-75.928986,0.091726,0.000000
120.810005,64.156425,-75.973465,-0.001647,0.003613,0.091778,285.382019,14.538054,0.917785,-75.973465,0.091163,0.000000
121.150009,64.036522,-76.017944,-0.001630,0.003588,0.091128,284.848663,14.510883,0.911281,-76.017944,0.090590,0.000000
121.490005,63.863731,-75.973465,-0.001621,0.003567,0.090590,284.080078,14.471728,0.905904,-75.973465,0.090027,0.000000
121.830009,63.457848,-76.062424,-0.001625,0.003548,0.090122,282.274597,14.379753,0.901221,-76.062424,0.089454,0.000000
122.170006,62.953659,-76.062424,-0.001617,0.003535,0.089784,280.031860,14.265503,0.897839,-76.062424,0.088891,0.000000
122.510002,62.156410,-76.151390,-0.001621,0.003513,0.089238,276.485535,14.084844,0.892375,-76.151390,0.088327,0.000000
122.850006,61.104828,-76.151390,-0.001621,0.003492,0.088691,271.807861,13.846552,0.886912,-76.151390,0.087755,0.000000
123.190002,59.743065,-76.151390,-0.001621,0.003466,0.088032,265.750427,13.537972,0.880321,-76.151390,0.087191,0.000000
123.530006,58.589455,-76.240349,-0.001621,0.003452,0.087677,260.618896,13.276560,0.876765,-76.240349,0.086627,0.000000
123.870003,56.620720,-76.284828,-0.001617,0.003423,0.086939,251.861542,12.830439,0.869394,-76.284828,0.086055,0.000000
124.210007,55.966461,-76.373795,-0.001634,0.003414,0.086705,248.951248,12.682181,0.867052,-76.373795,0.085491,0.000000
124.550003,53.327827,-76.284828,-0.001625,0.003385,0.085968,237.214020,12.084259,0.859681,-76.284828,0.084927,0.000000
124.890007,51.219086,-76.373795,-0.001634,0.003364,0.085456,227.833878,11.606411,0.854564,-76.373795,0.084355,0.000000
125.230003,48.336174,-76.418274,-0.001621,0.003333,0.084650,215.010040,10.953134,0.846499,-76.418274,0.083791,0.000000
125.570007,46.330208,-76.418274,-0.001617,0.003311,0.084095,206.087051,10.498575,0.840949,-76.418274,0.083228,0.000000
125.910004,44.135818,-76.551720,-0.001643,0.003292,0.083627,196.325928,10.001319,0.836266,-76.551720,0.082655,0.000000
126.250008,42.724525,-76.507233,-0.001625,0.003282,0.083358,190.048187,9.681516,0.833577,-76.507233,0.082092,0.000000
126.590004,40.345436,-76.507233,-0.001630,0.003251,0.082577,179.465469,9.142406,0.825772,-76.507233,0.081528,0.000000
126.930008,37.239479,-76.596199,-0.001643,0.003228,0.081979,165.649475,8.438587,0.819789,-76.596199,0.080956,0.000000
127.270004,34.997421,-76.551720,-0.001651,0.003206,0.081441,155.676300,7.930529,0.814412,-76.551720,0.080392,0.000000
127.610008,33.255089,-76.640678,-0.001651,0.003188,0.080964,147.926025,7.535711,0.809642,-76.640678,0.079828,0.000000
127.950005,31.414452,-76.596199,-0.001651,0.003172,0.080565,139.738464,7.118617,0.805653,-76.596199,0.079256,0.000000
128.290009,28.222847,-76.640678,-0.001647,0.003140,0.079750,125.541496,6.395389,0.797501,-76.640678,0.078692,0.000000
128.630005,25.928665,-76.818604,-0.001664,0.003122,0.079290,115.336464,5.875520,0.792904,-76.818604,0.078128,0.000000
128.970001,22.341972,-76.818604,-0.001651,0.003087,0.078406,99.382057,5.062763,0.784059,-76.818604,0.077556,0.000000
129.310013,20.663315,-76.818604,-0.001673,0.003071,0.078007,91.915016,4.682374,0.780070,-76.818604,0.076992,0.000000
129.650009,17.965477,-76.907562,-0.001681,0.003046,0.077357,79.914436,4.071035,0.773565,-76.907562,0.076420,0.000000
129.990005,16.785057,-76.863083,-0.001673,0.003030,0.076966,74.663666,3.803548,0.769663,-76.863083,0.075856,0.000000
130.330002,13.703674,-76.996529,-0.001673,0.003005,0.076316,60.956989,3.105297,0.763159,-76.996529,0.075293,0.000000
130.670013,11.431831,-76.907562,-0.001681,0.002983,0.075761,50.851326,2.590490,0.757608,-76.907562,0.074720,0.000000
131.010010,9.118652,-76.996529,-0.001681,0.002960,0.075180,40.561790,2.066316,0.751798,-76.996529,0.074156,0.000000
131.350006,7.310783,-77.041008,-0.001686,0.002942,0.074720,32.519989,1.656647,0.747202,-77.041008,0.073593,0.000000
131.690002,5.185654,-76.996529,-0.001703,0.002914,0.074009,23.066940,1.175086,0.740091,-76.996529,0.073020,0.000000
132.029999,2.561920,-77.129967,-0.001699,0.002891,0.073428,11.395990,0.580539,0.734280,-77.129967,0.072457,0.000000
132.370010,1.060516,-77.085487,-0.001703,0.002872,0.072960,4.717412,0.240316,0.729597,-77.085487,0.071893,0.000000
132.710007,-1.464172,-77.129967,-0.001712,0.002849,0.072353,-6.512964,-0.331786,0.723526,-77.129967,0.071321,0.000000
133.050003,-3.361408,-77.129967,-0.001716,0.002825,0.071763,-14.952291,-0.761706,0.717629,-77.129967,0.070757,0.000000
133.389999,-0.236084,-77.218933,-0.001759,0.002808,0.071312,-1.050154,-0.053497,0.713120,-77.218933,0.070193,0.000000
133.730011,-0.135918,-77.218933,-0.001785,0.002783,0.070688,-0.604592,-0.030799,0.706876,-77.218933,0.069621,0.000000
134.070007,-0.068146,-77.263412,-0.001807,0.002761,0.070141,-0.303127,-0.015442,0.701412,-77.263412,0.069057,0.000000
134.410004,-0.076340,-77.352371,-0.001832,0.002737,0.069525,-0.339576,-0.017299,0.695255,-77.352371,0.068493,0.000000
134.750000,-0.080063,-77.396858,-0.001828,0.002718,0.069049,-0.356137,-0.018143,0.690485,-77.396858,0.067921,0.000000
135.090012,-0.097565,-77.352371,-0.001854,0.002694,0.068424,-0.433989,-0.022108,0.684241,-77.352371,0.067357,0.000000
135.430008,-0.046547,-77.485817,-0.001871,0.002676,0.067964,-0.207051,-0.010548,0.679645,-77.485817,0.066794,0.000000
135.770004,-0.061073,-77.441338,-0.001901,0.002646,0.067210,-0.271668,-0.013839,0.672100,-77.441338,0.066221,0.000000
136.110001,-0.072990,-77.485817,-0.001923,0.002626,0.066698,-0.324678,-0.016540,0.666983,-77.485817,0.065658,0.000000
136.450012,-0.058090,-77.619263,-0.001949,0.002608,0.066239,-0.258398,-0.013163,0.662387,-77.619263,0.065094,0.000000
136.790009,-0.078201,-77.530296,-0.001975,0.002582,0.065571,-0.347857,-0.017721,0.655709,-77.530296,0.064522,0.000000
137.130005,-0.072990,-77.619263,-0.001988,0.002560,0.065033,-0.324678,-0.016540,0.650333,-77.619263,0.063958,0.000000
137.470001,-0.083038,-77.663742,-0.002013,0.002537,0.064444,-0.369373,-0.018817,0.644435,-77.663742,0.063394,0.000000
137.810013,-0.080437,-77.619263,-0.002031,0.002520,0.064019,-0.357800,-0.018227,0.640186,-77.619263,0.062822,0.000000
138.150009,-0.089745,-77.708221,-0.002035,0.002493,0.063316,-0.399204,-0.020336,0.633162,-77.708221,0.062258,0.000000
138.490005,-0.053627,-77.752701,-0.002065,0.002476,0.062900,-0.238545,-0.012152,0.628999,-77.752701,0.061686,0.000000
138.830002,-0.075226,-77.797180,-0.002087,0.002445,0.062102,-0.334621,-0.017046,0.621020,-77.797180,0.061122,0.000000
139.170013,-0.091232,-77.797180,-0.002104,0.002426,0.061616,-0.405822,-0.020674,0.616164,-77.797180,0.060558,0.000000
139.510010,-0.062561,-77.752701,-0.002139,0.002399,0.060931,-0.278285,-0.014177,0.609313,-77.752701,0.059986,0.000000
139.850006,-0.041710,-77.886147,-0.002134,0.002386,0.060593,-0.185535,-0.009452,0.605931,-77.886147,0.059422,0.000000
140.100006,-0.046547,-77.930626,-0.002156,0.002376,0.060359,-0.207051,-0.010548,0.603589,-77.930626,0.060307,0.000000