File: Data/compression 33/AutoNoHeating-12-33-reverse-1-1_11152024_174935.csv
Time (sec),S:Load (lbs),S:HL1 (DIM),S:LVDT (in),S:Position (in),Ch:Position (mm),Ch:Load (N),Ch:Stress (MPa),Ch:Strain (mm/mm),Ch:HL1 (DIM),Set Point (),Cycles ()
0.110000,-0.067772,-668.993530,-0.009188,-0.008998,-0.228557,-0.301465,-0.015357,-2.285573,-668.993530,-0.228349,0.000000
0.510000,-0.099426,-669.082458,-0.009184,-0.008932,-0.226866,-0.442270,-0.022530,-2.268662,-669.082458,-0.226146,0.000000
0.910000,-0.120277,-669.082458,-0.009024,-0.008691,-0.220761,-0.535021,-0.027255,-2.207609,-669.082458,-0.219486,0.000000
1.310000,-0.074478,-669.082458,-0.008748,-0.008432,-0.214161,-0.331295,-0.016877,-2.141614,-669.082458,-0.212826,0.000000
1.710000,-0.065910,-669.037964,-0.008520,-0.008171,-0.207544,-0.293184,-0.014935,-2.075444,-669.037964,-0.206166,0.000000
2.110000,-0.087135,-669.082458,-0.008218,-0.007907,-0.200849,-0.387597,-0.019745,-2.008495,-669.082458,-0.199488,0.000000
2.510000,-0.105011,-669.082458,-0.007950,-0.007640,-0.194059,-0.467112,-0.023796,-1.940591,-669.082458,-0.192828,0.000000
2.910000,-0.123253,-669.082458,-0.007700,-0.007390,-0.187694,-0.548256,-0.027929,-1.876937,-669.082458,-0.186167,0.000000
3.310000,-0.064796,-669.126953,-0.007424,-0.007126,-0.180999,-0.288229,-0.014683,-1.809987,-669.126953,-0.179507,0.000000
3.710000,-0.037987,-669.126953,-0.007140,-0.006853,-0.174070,-0.168974,-0.008608,-1.740695,-669.126953,-0.172847,0.000000
4.110000,-0.039474,-669.126953,-0.006868,-0.006590,-0.167383,-0.175591,-0.008945,-1.673832,-669.126953,-0.166169,0.000000
4.510000,-0.054367,-669.126953,-0.006605,-0.006327,-0.160714,-0.241837,-0.012320,-1.607143,-669.126953,-0.159509,0.000000
4.910000,-0.095329,-669.215881,-0.006342,-0.006070,-0.154167,-0.424046,-0.021602,-1.541667,-669.215881,-0.152849,0.000000
5.310000,-0.035751,-669.126953,-0.006066,-0.005808,-0.147532,-0.159030,-0.008101,-1.475324,-669.126953,-0.146188,0.000000
5.710000,-0.011543,-669.171448,-0.005808,-0.005544,-0.140811,-0.051347,-0.002616,-1.408114,-669.171448,-0.139528,0.000000
6.110000,-0.007446,-669.171448,-0.005549,-0.005286,-0.134255,-0.033123,-0.001687,-1.342552,-669.171448,-0.132850,0.000000
6.510000,-0.039848,-669.171448,-0.005247,-0.005018,-0.127456,-0.177254,-0.009030,-1.274562,-669.171448,-0.126190,0.000000
6.910000,0.087135,-669.215881,-0.005062,-0.000009,-0.000217,0.387597,0.019745,-0.002168,-669.215881,0.000017,0.000000
7.310000,0.093834,-669.215881,-0.005066,-0.000009,-0.000217,0.417394,0.021263,-0.002168,-669.215881,0.000035,0.000000
7.710001,0.152298,-669.215881,-0.005053,-0.000009,-0.000217,0.677455,0.034511,-0.002168,-669.215881,0.000702,0.000000
8.110001,0.285233,-669.215881,-0.005053,0.000016,0.000416,1.268778,0.064635,0.004163,-669.215881,0.001370,0.000000
8.510000,0.367157,-669.215881,-0.005019,0.000035,0.000885,1.633196,0.083199,0.008846,-669.215881,0.002038,0.000000
8.910001,0.593559,-669.304871,-0.005006,0.000062,0.001587,2.640284,0.134502,0.015870,-669.304871,0.002706,0.000000
9.310000,0.866135,-669.260376,-0.004971,0.000095,0.002411,3.852759,0.196269,0.024109,-669.260376,0.003365,0.000000
9.710000,1.167015,-669.349365,-0.004950,0.000120,0.003053,5.191143,0.264449,0.030526,-669.349365,0.004033,0.000000
10.110001,1.501778,-669.304871,-0.004924,0.000145,0.003677,6.680241,0.340308,0.036770,-669.304871,0.004700,0.000000
10.510000,1.745308,-669.304871,-0.004915,0.000167,0.004232,7.763517,0.395492,0.042321,-669.304871,0.005368,0.000000
10.910001,2.011185,-669.304871,-0.004889,0.000196,0.004987,8.946197,0.455741,0.049866,-669.304871,0.006036,0.000000
11.310000,2.232368,-669.349365,-0.004859,0.000213,0.005420,9.930071,0.505862,0.054202,-669.349365,0.006704,0.000000
11.710001,2.557823,-669.349365,-0.004833,0.000236,0.005984,11.377766,0.579611,0.059839,-669.349365,0.007371,0.000000
12.110001,3.041534,-669.304871,-0.004803,0.000266,0.006764,13.529421,0.689222,0.067644,-669.304871,0.008039,0.000000
12.510000,3.449661,-669.349365,-0.004781,0.000297,0.007545,15.344860,0.781704,0.075449,-669.349365,0.008698,0.000000
12.910001,3.865227,-669.393860,-0.004756,0.000327,0.008308,17.193388,0.875873,0.083080,-669.393860,0.009366,0.000000
13.310000,4.039871,-669.304871,-0.004751,0.000345,0.008759,17.970245,0.915448,0.087590,-669.304871,0.010034,0.000000
13.710001,4.727264,-669.393860,-0.004708,0.000378,0.009600,21.027922,1.071213,0.096002,-669.393860,0.010702,0.000000
14.110001,4.986809,-669.393860,-0.004678,0.000405,0.010277,22.182434,1.130027,0.102766,-669.393860,0.011369,0.000000
14.510000,5.152885,-669.393860,-0.004678,0.000422,0.010728,22.921179,1.167660,0.107276,-669.393860,0.012037,0.000000
14.910001,5.722244,-669.393860,-0.004644,0.000460,0.011673,25.453814,1.296679,0.116729,-669.393860,0.012705,0.000000
15.310000,5.982162,-669.438293,-0.004613,0.000487,0.012367,26.609987,1.355577,0.123666,-669.438293,0.013373,0.000000
15.710001,6.038017,-669.393860,-0.004605,0.000501,0.012731,26.858442,1.368234,0.127309,-669.393860,0.014040,0.000000
16.110001,7.046028,-669.438293,-0.004566,0.000540,0.013728,31.342299,1.596653,0.137282,-669.438293,0.014699,0.000000
16.510000,7.069489,-669.393860,-0.004531,0.000562,0.014283,31.446655,1.601969,0.142832,-669.393860,0.015367,0.000000
16.910002,7.515221,-669.482788,-0.004523,0.000589,0.014968,33.429371,1.702973,0.149683,-669.482788,0.016035,0.000000
17.310001,8.070801,-669.527283,-0.004484,0.000619,0.015731,35.900715,1.828870,0.157315,-669.527283,0.016703,0.000000
17.710001,8.312843,-669.438293,-0.004449,0.000643,0.016330,36.977375,1.883717,0.163299,-669.438293,0.017371,0.000000
18.110001,8.680374,-669.482788,-0.004437,0.000670,0.017015,38.612232,1.967001,0.170150,-669.482788,0.018038,0.000000
18.510000,9.081421,-669.482788,-0.004398,0.000697,0.017700,40.396179,2.057879,0.177001,-669.482788,0.018706,0.000000
18.910002,9.190895,-669.527283,-0.004385,0.000718,0.018246,40.883144,2.082687,0.182464,-669.527283,0.019374,0.000000
19.310001,9.565872,-669.527283,-0.004372,0.000742,0.018853,42.551125,2.167658,0.188535,-669.527283,0.020033,0.000000
19.710001,10.060013,-669.482788,-0.004324,0.000776,0.019712,44.749172,2.279631,0.197120,-669.482788,0.020701,0.000000
20.110001,10.103210,-669.527283,-0.004312,0.000795,0.020189,44.941326,2.289420,0.201890,-669.527283,0.021368,0.000000
20.510000,10.449890,-669.527283,-0.004286,0.000820,0.020831,46.483433,2.367979,0.208308,-669.527283,0.022036,0.000000
20.910002,10.891151,-669.571777,-0.004251,0.000849,0.021577,48.446262,2.467970,0.215766,-669.571777,0.022704,0.000000
21.310001,11.155907,-669.527283,-0.004217,0.000876,0.022253,49.623951,2.527965,0.222530,-669.527283,0.023372,0.000000
21.710001,11.585251,-669.571777,-0.004208,0.000906,0.023025,51.533768,2.625255,0.230248,-669.571777,0.024039,0.000000
22.110001,11.622116,-669.571777,-0.004174,0.000926,0.023519,51.697754,2.633609,0.235192,-669.571777,0.024707,0.000000
22.510000,11.970284,-669.616211,-0.004152,0.000952,0.024187,53.246479,2.712505,0.241869,-669.616211,0.025366,0.000000
22.910002,12.245468,-669.616211,-0.004122,0.000978,0.024829,54.470562,2.774863,0.248287,-669.616211,0.026034,0.000000
23.310001,12.839027,-669.616211,-0.004087,0.001011,0.025670,57.110847,2.909365,0.256699,-669.616211,0.026702,0.000000
23.710001,12.903450,-669.616211,-0.004066,0.001036,0.026312,57.397411,2.923964,0.263116,-669.616211,0.027370,0.000000
24.110001,13.076599,-669.616211,-0.004027,0.001062,0.026971,58.167618,2.963200,0.269707,-669.616211,0.028037,0.000000
24.510000,13.612816,-669.705200,-0.003992,0.001092,0.027725,60.552830,3.084708,0.277252,-669.705200,0.028705,0.000000
24.910002,13.501480,-669.705200,-0.003988,0.001111,0.028211,60.057583,3.059479,0.282109,-669.705200,0.029373,0.000000
25.310001,13.552124,-669.660706,-0.003962,0.001132,0.028757,60.282860,3.070955,0.287572,-669.660706,0.030041,0.000000
25.710001,14.249947,-669.705200,-0.003923,0.001165,0.029590,63.386929,3.229084,0.295897,-669.705200,0.030700,0.000000
26.110001,14.277130,-669.705200,-0.003911,0.001183,0.030049,63.507847,3.235244,0.300494,-669.705200,0.031368,0.000000
26.510002,14.899368,-669.705200,-0.003876,0.001220,0.030977,66.275703,3.376245,0.309773,-669.705200,0.032035,0.000000
26.910002,15.396484,-669.705200,-0.003837,0.001249,0.031732,68.486984,3.488893,0.317318,-669.705200,0.032703,0.000000
27.310001,14.941071,-669.749695,-0.003816,0.001262,0.032053,66.461205,3.385695,0.320527,-669.749695,0.033371,0.000000
27.710001,15.733856,-669.749695,-0.003786,0.001299,0.032998,69.987686,3.565343,0.329979,-669.749695,0.034039,0.000000
28.110001,16.078300,-669.749695,-0.003755,0.001327,0.033709,71.519852,3.643395,0.337091,-669.749695,0.034706,0.000000
28.510002,16.076065,-669.749695,-0.003712,0.001354,0.034385,71.509911,3.642889,0.343855,-669.749695,0.035374,0.000000
28.910002,16.284218,-669.749695,-0.003682,0.001379,0.035027,72.435822,3.690057,0.350273,-669.749695,0.036042,0.000000
29.310001,16.592918,-669.838623,-0.003673,0.001404,0.035660,73.808990,3.760009,0.356603,-669.838623,0.036701,0.000000
29.710001,16.728088,-669.749695,-0.003648,0.001429,0.036293,74.410255,3.790639,0.362934,-669.749695,0.037369,0.000000
30.110001,17.278084,-669.794189,-0.003609,0.001458,0.037022,76.856758,3.915270,0.370219,-669.794189,0.038037,0.000000
30.510002,17.415489,-669.838623,-0.003579,0.001481,0.037620,77.467964,3.946406,0.376202,-669.838623,0.038704,0.000000
30.910002,17.801262,-669.838623,-0.003553,0.001511,0.038392,79.183968,4.033823,0.383921,-669.838623,0.039372,0.000000
31.310001,17.893982,-669.883118,-0.003518,0.001533,0.038947,79.596405,4.054834,0.389471,-669.883118,0.040040,0.000000
31.710001,18.069374,-669.927612,-0.003488,0.001560,0.039624,80.376587,4.094579,0.396235,-669.927612,0.040708,0.000000
32.110001,18.273804,-669.883118,-0.003471,0.001581,0.040153,81.285942,4.140903,0.401526,-669.883118,0.041375,0.000000
32.510002,18.409348,-669.883118,-0.003436,0.001607,0.040820,81.888870,4.171618,0.408203,-669.883118,0.042034,0.000000
32.910000,18.714325,-669.883118,-0.003410,0.001633,0.041479,83.245476,4.240726,0.414794,-669.883118,0.042702,0.000000
33.310001,19.631477,-669.883118,-0.003376,0.001665,0.042286,87.325172,4.448556,0.422859,-669.883118,0.043370,0.000000
33.710003,19.459068,-669.927612,-0.003350,0.001690,0.042928,86.558258,4.409488,0.429277,-669.927612,0.044038,0.000000
34.110001,19.912987,-669.927612,-0.003311,0.001722,0.043734,88.577393,4.512347,0.437342,-669.927612,0.044705,0.000000
34.510002,19.525719,-669.927612,-0.003285,0.001738,0.044142,86.854736,4.424591,0.441418,-669.927612,0.045373,0.000000
34.910000,19.838516,-669.972107,-0.003251,0.001764,0.044818,88.246124,4.495472,0.448182,-669.972107,0.046041,0.000000
35.310001,20.711731,-669.972107,-0.003221,0.001799,0.045703,92.130379,4.693346,0.457028,-669.972107,0.046709,0.000000
35.710003,20.167694,-669.972107,-0.003182,0.001819,0.046206,89.710381,4.570065,0.462058,-669.972107,0.047368,0.000000
36.110001,21.275124,-669.972107,-0.003156,0.001854,0.047099,94.636475,4.821012,0.470990,-669.972107,0.048036,0.000000
36.510002,21.079628,-669.972107,-0.003139,0.001876,0.047663,93.766869,4.776712,0.476627,-669.972107,0.048703,0.000000
36.910000,20.338242,-669.972107,-0.003113,0.001886,0.047914,90.469017,4.608711,0.479142,-669.972107,0.049371,0.000000
37.310001,21.997528,-669.927612,-0.003065,0.001933,0.049094,97.849892,4.984711,0.490936,-669.927612,0.050039,0.000000
37.710003,21.831451,-669.972107,-0.003027,0.001957,0.049718,97.111145,4.947078,0.497180,-669.972107,0.050707,0.000000
38.110001,21.367477,-670.016541,-0.003005,0.001971,0.050065,95.047287,4.841939,0.500649,-670.016541,0.051374,0.000000
38.510002,22.439537,-669.972107,-0.002962,0.002010,0.051045,99.816048,5.084872,0.510449,-669.972107,0.052042,0.000000
38.910004,22.398201,-670.061035,-0.002953,0.002030,0.051565,99.632172,5.075505,0.515652,-670.061035,0.052701,0.000000
39.310001,22.686043,-670.016541,-0.002902,0.002057,0.052250,100.912560,5.140730,0.522503,-670.016541,0.053369,0.000000
39.710003,22.948944,-670.061035,-0.002880,0.002083,0.052918,102.082001,5.200305,0.529181,-670.061035,0.054037,0.000000
40.110001,23.294876,-670.061035,-0.002850,0.002111,0.053612,103.620781,5.278694,0.536119,-670.061035,0.054705,0.000000
40.510002,22.900902,-670.150024,-0.002820,0.002127,0.054028,101.868301,5.189419,0.540282,-670.150024,0.055372,0.000000
40.910004,24.270866,-670.061035,-0.002785,0.002166,0.055017,107.962204,5.499857,0.550168,-670.061035,0.056040,0.000000
41.310001,23.912643,-670.105530,-0.002742,0.002187,0.055554,106.368752,5.418683,0.555545,-670.105530,0.056708,0.000000
41.710003,23.556656,-670.061035,-0.002734,0.002210,0.056144,104.785240,5.338014,0.561442,-670.061035,0.057376,0.000000
42.110001,24.452583,-670.105530,-0.002699,0.002242,0.056959,108.770523,5.541034,0.569594,-670.105530,0.058043,0.000000
42.510002,24.878944,-670.150024,-0.002669,0.002268,0.057618,110.667068,5.637649,0.576185,-670.150024,0.058703,0.000000
42.910004,24.996246,-670.105530,-0.002634,0.002293,0.058243,111.188858,5.664230,0.582429,-670.105530,0.059370,0.000000
43.310001,25.257652,-670.105530,-0.002596,0.002320,0.058919,112.351646,5.723465,0.589193,-670.105530,0.060038,0.000000
43.710003,25.666885,-670.105530,-0.002578,0.002348,0.059648,114.172005,5.816199,0.596478,-670.105530,0.060706,0.000000
44.110001,25.729820,-670.238953,-0.002557,0.002370,0.060194,114.451958,5.830461,0.601941,-670.238953,0.061374,0.000000
44.510002,26.178154,-670.150024,-0.002509,0.002398,0.060914,116.446243,5.932055,0.609139,-670.150024,0.062041,0.000000
44.910004,26.820869,-670.194519,-0.002488,0.002431,0.061746,119.305183,6.077696,0.617465,-670.194519,0.062709,0.000000
45.310001,26.461159,-670.238953,-0.002440,0.002449,0.062215,117.705116,5.996184,0.622148,-670.238953,0.063377,0.000000
45.710003,25.809135,-670.194519,-0.002427,0.002463,0.062570,114.804771,5.848433,0.625703,-670.194519,0.064036,0.000000
46.110001,27.092331,-670.194519,-0.002397,0.002504,0.063611,120.512711,6.139210,0.636110,-670.194519,0.064704,0.000000
46.510002,27.018974,-670.238953,-0.002350,0.002525,0.064140,120.186401,6.122587,0.641400,-670.238953,0.065371,0.000000
46.910004,27.916389,-670.327942,-0.002324,0.002559,0.064990,124.178299,6.325944,0.649899,-670.327942,0.066039,0.000000
47.310001,27.942085,-670.283447,-0.002285,0.002581,0.065562,124.292603,6.331767,0.655623,-670.283447,0.066707,0.000000
47.710003,28.327492,-670.238953,-0.002268,0.002611,0.066308,126.006973,6.419101,0.663081,-670.238953,0.067375,0.000000
48.110001,28.568039,-670.327942,-0.002238,0.002636,0.066958,127.076981,6.473610,0.669585,-670.327942,0.068043,0.000000
48.510002,28.188225,-670.283447,-0.002212,0.002655,0.067444,125.387489,6.387543,0.674441,-670.283447,0.068710,0.000000
48.910004,29.195114,-670.283447,-0.002156,0.002691,0.068346,129.866348,6.615707,0.683461,-670.283447,0.069369,0.000000
49.310001,29.401787,-670.327942,-0.002130,0.002717,0.069005,130.785675,6.662540,0.690051,-670.327942,0.070037,0.000000
49.710003,29.447586,-670.327942,-0.002108,0.002745,0.069734,130.989410,6.672918,0.697336,-670.327942,0.070705,0.000000
50.110001,29.195488,-670.327942,-0.002061,0.002769,0.070323,129.868011,6.615792,0.703233,-670.327942,0.071373,0.000000
50.510002,29.437531,-670.372437,-0.002035,0.002798,0.071069,130.944672,6.670640,0.710692,-670.372437,0.072040,0.000000
50.910004,29.538818,-670.372437,-0.001988,0.002820,0.071624,131.395233,6.693592,0.716242,-670.372437,0.072708,0.000000
51.310001,29.780113,-670.416870,-0.001953,0.002844,0.072240,132.468567,6.748270,0.722399,-670.416870,0.073376,0.000000
51.710003,30.332718,-670.372437,-0.001923,0.002877,0.073072,134.926666,6.873492,0.730724,-670.372437,0.074044,0.000000
52.110001,30.001305,-670.416870,-0.001901,0.002899,0.073645,133.452469,6.798393,0.736448,-670.416870,0.074703,0.000000
52.510002,30.245209,-670.372437,-0.001867,0.002924,0.074261,134.537415,6.853662,0.742605,-670.372437,0.075371,0.000000
52.910004,30.160683,-670.416870,-0.001824,0.002947,0.074859,134.161423,6.834508,0.748589,-670.416870,0.076038,0.000000
53.310001,29.650902,-670.461365,-0.001776,0.002970,0.075440,131.893799,6.718990,0.754400,-670.461365,0.076706,0.000000
53.710003,30.250046,-670.372437,-0.001750,0.002996,0.076108,134.558929,6.854758,0.761077,-670.372437,0.077374,0.000000
54.110004,29.966301,-670.461365,-0.001725,0.003017,0.076628,133.296768,6.790461,0.766281,-670.461365,0.078042,0.000000
54.510002,31.251358,-670.505859,-0.001686,0.003052,0.077521,139.012985,7.081659,0.775213,-670.505859,0.078709,0.000000
54.910004,31.395836,-670.416870,-0.001638,0.003082,0.078276,139.655655,7.114398,0.782758,-670.416870,0.079377,0.000000
55.310001,31.603249,-670.505859,-0.001600,0.003111,0.079013,140.578278,7.161398,0.790129,-670.505859,0.080045,0.000000
55.710003,31.080063,-670.550354,-0.001552,0.003135,0.079629,138.251022,7.042843,0.796287,-670.550354,0.080704,0.000000
56.110004,30.801529,-670.505859,-0.001513,0.003156,0.080158,137.012039,6.979726,0.801577,-670.505859,0.081372,0.000000
56.510002,31.732094,-670.505859,-0.001470,0.003190,0.081034,141.151398,7.190595,0.810336,-670.505859,0.082040,0.000000
56.910004,31.361954,-670.550354,-0.001444,0.003213,0.081606,139.504944,7.106720,0.816059,-670.550354,0.082707,0.000000
57.310001,31.583885,-670.505859,-0.001410,0.003242,0.082343,140.492142,7.157011,0.823431,-670.505859,0.083375,0.000000
57.710003,31.581650,-670.594849,-0.001354,0.003268,0.083011,140.482193,7.156504,0.830108,-670.594849,0.084043,0.000000
58.110004,30.916595,-670.594849,-0.001337,0.003285,0.083436,137.523880,7.005800,0.834358,-670.594849,0.084711,0.000000
58.510002,31.246887,-670.639282,-0.001302,0.003310,0.084086,138.993103,7.080646,0.840862,-670.639282,0.085378,0.000000
58.910004,32.158081,-670.639282,-0.001259,0.003346,0.084997,143.046295,7.287125,0.849968,-670.639282,0.086037,0.000000
59.310001,31.668785,-670.594849,-0.001207,0.003369,0.085569,140.869797,7.176249,0.855692,-670.594849,0.086705,0.000000
59.710003,32.228462,-670.594849,-0.001186,0.003396,0.086254,143.359360,7.303074,0.862543,-670.594849,0.087373,0.000000
60.110004,32.481674,-670.594849,-0.001151,0.003425,0.086991,144.485703,7.360453,0.869914,-670.594849,0.088041,0.000000
60.510002,32.920334,-670.594849,-0.001104,0.003450,0.087642,146.436966,7.459854,0.876418,-670.594849,0.088709,0.000000
60.910004,33.046196,-670.683777,-0.001065,0.003477,0.088310,146.996826,7.488375,0.883096,-670.683777,0.089376,0.000000
61.310001,32.711800,-670.639282,-0.001035,0.003494,0.088752,145.509354,7.412600,0.887519,-670.639282,0.090044,0.000000
61.710003,33.034279,-670.639282,-0.001005,0.003521,0.089446,146.943817,7.485674,0.894457,-670.639282,0.090712,0.000000
62.110004,33.940628,-670.683777,-0.000983,0.003555,0.090287,150.975449,7.691056,0.902869,-670.683777,0.091371,0.000000
62.510002,34.294388,-670.683777,-0.000931,0.003578,0.090885,152.549057,7.771220,0.908853,-670.683777,0.092039,0.000000
62.910004,34.197197,-670.683777,-0.000905,0.003601,0.091458,152.116730,7.749196,0.914576,-670.683777,0.092706,0.000000
63.310001,34.860764,-670.683777,-0.000875,0.003629,0.092186,155.068420,7.899562,0.921861,-670.683777,0.093374,0.000000
63.710003,34.973221,-670.728271,-0.000836,0.003657,0.092889,155.568649,7.925045,0.928886,-670.728271,0.094042,0.000000
64.110001,35.790207,-670.772766,-0.000793,0.003685,0.093591,159.202789,8.110177,0.935910,-670.772766,0.094710,0.000000
64.510002,36.240776,-670.728271,-0.000767,0.003710,0.094241,161.207016,8.212277,0.942414,-670.728271,0.095377,0.000000
64.910004,36.405365,-670.772766,-0.000742,0.003733,0.094814,161.939148,8.249574,0.948138,-670.772766,0.096045,0.000000
65.310005,37.567909,-670.772766,-0.000707,0.003764,0.095594,167.110413,8.513010,0.955943,-670.772766,0.096704,0.000000
65.710007,37.869164,-670.728271,-0.000686,0.003787,0.096184,168.450455,8.581275,0.961840,-670.728271,0.097372,0.000000
66.110001,39.163528,-670.817200,-0.000655,0.003820,0.097025,174.208069,8.874582,0.970252,-670.817200,0.098040,0.000000
66.510002,39.262207,-670.772766,-0.000625,0.003842,0.097589,174.647018,8.896943,0.975889,-670.772766,0.098708,0.000000
66.910004,39.679260,-670.861694,-0.000586,0.003861,0.098075,176.502167,8.991448,0.980746,-670.861694,0.099375,0.000000
67.310005,41.176949,-670.772766,-0.000582,0.003897,0.098994,183.164215,9.330830,0.989938,-670.772766,0.100043,0.000000
67.710007,41.646133,-670.772766,-0.000552,0.003920,0.099566,185.251251,9.437149,0.995662,-670.772766,0.100711,0.000000
68.110001,42.620262,-670.817200,-0.000526,0.003945,0.100191,189.584396,9.657889,1.001906,-670.817200,0.101379,0.000000
68.510002,44.194283,-670.817200,-0.000513,0.003977,0.101014,196.585983,10.014567,1.010144,-670.817200,0.102046,0.000000
68.910004,44.080338,-670.817200,-0.000487,0.003989,0.101327,196.079132,9.988748,1.013267,-670.817200,0.102706,0.000000
69.310005,45.479713,-670.906189,-0.000461,0.004019,0.102072,202.303864,10.305850,1.020725,-670.906189,0.103373,0.000000
69.710007,47.189644,-670.861694,-0.000444,0.004051,0.102905,209.910019,10.693326,1.029050,-670.861694,0.104041,0.000000
70.110001,48.464645,-670.861694,-0.000410,0.004079,0.103616,215.581512,10.982245,1.036161,-670.861694,0.104709,0.000000
70.510002,49.026558,-670.861694,-0.000405,0.004103,0.104223,218.081024,11.109576,1.042232,-670.861694,0.105377,0.000000
70.910004,51.211639,-670.861694,-0.000375,0.004136,0.105064,227.800751,11.604723,1.050644,-670.861694,0.106044,0.000000
71.310005,51.782112,-670.906189,-0.000366,0.004158,0.105602,230.338333,11.733994,1.056021,-670.906189,0.106712,0.000000
71.710007,53.661850,-670.861694,-0.000332,0.004187,0.106357,238.699829,12.159949,1.063566,-670.861694,0.107380,0.000000
72.110001,54.638954,-670.861694,-0.000328,0.004211,0.106955,243.046204,12.381364,1.069549,-670.861694,0.108039,0.000000
72.510002,55.567276,-670.950684,-0.000310,0.004232,0.107501,247.175583,12.591724,1.075013,-670.950684,0.108707,0.000000
72.910004,57.634315,-670.906189,-0.000289,0.004265,0.108343,256.370239,13.060122,1.083425,-670.906189,0.109374,0.000000
73.310005,59.107056,-670.995117,-0.000289,0.004290,0.108976,262.921326,13.393850,1.089756,-670.995117,0.110042,0.000000
73.710007,60.722031,-670.995117,-0.000267,0.004317,0.109661,270.105072,13.759809,1.096607,-670.995117,0.110710,0.000000
74.110001,62.194023,-670.950684,-0.000259,0.004341,0.110268,276.652832,14.093368,1.102678,-670.950684,0.111378,0.000000
74.510002,63.469772,-670.995117,-0.000181,0.004362,0.110797,282.327637,14.382456,1.107968,-670.995117,0.112046,0.000000
74.910004,65.034470,-671.039612,-0.000190,0.004388,0.111447,289.287781,14.737021,1.114472,-671.039612,0.112713,0.000000
75.310005,66.224213,-670.995117,-0.000190,0.004399,0.111725,294.580017,15.006621,1.117247,-670.995117,0.019612,0.000000
75.710007,65.056824,-671.039612,-0.000177,0.004398,0.111716,289.387207,14.742087,1.117160,-671.039612,294.500458,0.000000
76.110001,66.042114,-671.039612,-0.000172,0.004413,0.112089,293.769989,14.965357,1.120889,-671.039612,294.500458,0.000000
76.510002,65.207626,-670.995117,-0.000164,0.004410,0.112011,290.058014,14.776259,1.120109,-670.995117,294.500458,0.000000
76.910004,65.296997,-671.128601,-0.000164,0.004425,0.112401,290.455536,14.796512,1.124011,-671.128601,294.500458,0.000000
77.310005,64.878448,-671.084106,-0.000155,0.004426,0.112410,288.593750,14.701667,1.124098,-671.084106,294.500458,0.000000
77.710007,65.002457,-671.128601,-0.000177,0.004431,0.112557,289.145355,14.729767,1.125572,-671.128601,294.500458,0.000000
78.110001,64.846054,-671.084106,-0.000155,0.004440,0.112783,288.449646,14.694325,1.127827,-671.084106,294.500458,0.000000
78.510002,65.546494,-671.084106,-0.000138,0.004443,0.112843,291.565369,14.853048,1.128434,-671.084106,294.500458,0.000000
78.910004,65.272430,-671.084106,-0.000151,0.004443,0.112843,290.346283,14.790944,1.128434,-671.084106,294.500458,0.000000
79.310005,64.999847,-671.084106,-0.000147,0.004443,0.112843,289.133759,14.729176,1.128434,-671.084106,294.500458,0.000000
79.710007,64.728394,-671.128601,-0.000138,0.004443,0.112852,287.926270,14.667664,1.128521,-671.128601,294.500458,0.000000
80.110001,65.785187,-671.128601,-0.000155,0.004447,0.112965,292.627136,14.907136,1.129648,-671.128601,294.500458,0.000000
80.510002,65.520416,-671.217529,-0.000134,0.004447,0.112965,291.449371,14.847138,1.129648,-671.217529,294.500458,0.000000
80.910004,65.268326,-671.128601,-0.000138,0.004448,0.112973,290.328003,14.790014,1.129735,-671.128601,294.500458,0.000000
81.310005,65.029266,-671.173096,-0.000108,0.004448,0.112973,289.264618,14.735842,1.129735,-671.173096,294.500458,0.000000
81.710007,64.833023,-671.173096,-0.000138,0.004448,0.112991,288.391693,14.691374,1.129908,-671.173096,294.500458,0.000000
82.110001,65.765442,-671.173096,-0.000129,0.004465,0.113398,292.539307,14.902661,1.133984,-671.173096,294.500458,0.000000
82.510002,65.593414,-671.217529,-0.000134,0.004465,0.113398,291.774078,14.863680,1.133984,-671.217529,294.500458,0.000000
82.910004,65.495468,-671.173096,-0.000134,0.004465,0.113398,291.338379,14.841485,1.133984,-671.173096,294.500458,0.000000
83.310005,65.326416,-671.262024,-0.000125,0.004465,0.113398,290.586426,14.803178,1.133984,-671.262024,294.500458,0.000000
83.710007,65.218430,-671.173096,-0.000129,0.004465,0.113398,290.106049,14.778708,1.133984,-671.173096,294.500458,0.000000
84.110001,65.085114,-671.262024,-0.000112,0.004466,0.113424,289.513031,14.748498,1.134245,-671.262024,294.500458,0.000000
84.510002,65.029633,-671.217529,-0.000116,0.004466,0.113433,289.266266,14.735926,1.134331,-671.217529,294.500458,0.000000
84.910004,64.934311,-671.217529,-0.000121,0.004466,0.113442,288.842255,14.714326,1.134418,-671.217529,294.500458,0.000000
85.310005,65.310028,-671.262024,-0.000125,0.004472,0.113589,290.513519,14.799464,1.135892,-671.262024,294.500458,0.000000
85.710007,65.245239,-671.306519,-0.000116,0.004472,0.113589,290.225311,14.784782,1.135892,-671.306519,294.500458,0.000000
86.110001,65.164810,-671.306519,-0.000121,0.004472,0.113589,289.867554,14.766557,1.135892,-671.306519,294.500458,0.000000
86.510002,65.078049,-671.306519,-0.000112,0.004472,0.113598,289.481628,14.746897,1.135979,-671.306519,294.500458,0.000000
86.910004,65.094437,-671.306519,-0.000112,0.004475,0.113659,289.554504,14.750610,1.136586,-671.306519,294.500458,0.000000
87.310005,65.062408,-671.306519,-0.000103,0.004475,0.113659,289.412048,14.743353,1.136586,-671.306519,294.500458,0.000000
87.710007,65.006927,-671.306519,-0.000112,0.004475,0.113659,289.165253,14.730780,1.136586,-671.306519,294.500458,0.000000
88.110001,64.953293,-671.351013,-0.000116,0.004475,0.113659,288.926666,14.718627,1.136586,-671.351013,294.500458,0.000000
88.510002,65.491379,-671.351013,-0.000116,0.004482,0.113841,291.320190,14.840559,1.138407,-671.351013,294.500458,0.000000
88.910004,65.474243,-671.351013,-0.000108,0.004481,0.113823,291.243988,14.836676,1.138234,-671.351013,294.500458,0.000000
89.310005,65.399399,-671.395447,-0.000116,0.004481,0.113823,290.911041,14.819715,1.138234,-671.395447,294.500458,0.000000
89.710007,65.333496,-671.351013,-0.000116,0.004481,0.113823,290.617920,14.804782,1.138234,-671.351013,294.500458,0.000000
90.110001,65.299240,-671.395447,-0.000099,0.004481,0.113823,290.465515,14.797020,1.138234,-671.395447,294.500458,0.000000
90.510002,65.251572,-671.395447,-0.000103,0.004481,0.113823,290.253479,14.786218,1.138234,-671.395447,294.500458,0.000000
90.910004,65.162201,-671.439941,-0.000108,0.004482,0.113832,289.855957,14.765966,1.138320,-671.439941,294.500458,0.000000
91.310005,65.073578,-671.484436,-0.000103,0.004482,0.113832,289.461731,14.745884,1.138320,-671.484436,294.500458,0.000000
91.710007,65.021820,-671.439941,-0.000112,0.004482,0.113832,289.231506,14.734156,1.138320,-671.439941,294.500458,0.000000
92.110001,64.964096,-671.439941,-0.000099,0.004482,0.113832,288.974731,14.721074,1.138320,-671.439941,294.500458,0.000000
92.510002,64.902664,-671.484436,-0.000108,0.004482,0.113832,288.701477,14.707154,1.138320,-671.484436,294.500458,0.000000
92.910004,64.834885,-671.528931,-0.000103,0.004482,0.113832,288.399963,14.691794,1.138320,-671.528931,294.500458,0.000000
93.310005,64.785355,-671.484436,-0.000108,0.004482,0.113841,288.179657,14.680572,1.138407,-671.484436,294.500458,0.000000
93.710007,64.741791,-671.528931,-0.000095,0.004482,0.113841,287.985870,14.670699,1.138407,-671.528931,294.500458,0.000000
94.110008,64.697479,-671.528931,-0.000103,0.004482,0.113841,287.788757,14.660659,1.138407,-671.528931,294.500458,0.000000
94.510002,64.647949,-671.484436,-0.000103,0.004483,0.113858,287.568451,14.649435,1.138581,-671.484436,294.500458,0.000000
94.910004,66.057755,-671.484436,-0.000091,0.004493,0.114127,293.839569,14.968902,1.141269,-671.484436,294.500458,0.000000
95.310005,65.990356,-671.573425,-0.000099,0.004493,0.114118,293.539764,14.953629,1.141182,-671.573425,294.500458,0.000000
95.710007,65.883118,-671.573425,-0.000082,0.004493,0.114118,293.062744,14.929328,1.141182,-671.573425,294.500458,0.000000
96.110008,65.852585,-671.617859,-0.000095,0.004493,0.114118,292.926941,14.922409,1.141182,-671.617859,294.500458,0.000000
96.510002,65.848862,-671.617859,-0.000099,0.004493,0.114118,292.910370,14.921566,1.141182,-671.617859,294.500458,0.000000
96.910004,65.787781,-671.573425,-0.000099,0.004493,0.114118,292.638672,14.907723,1.141182,-671.573425,294.500458,0.000000
97.310005,65.732681,-671.573425,-0.000091,0.004493,0.114118,292.393555,14.895238,1.141182,-671.573425,294.500458,0.000000
97.710007,65.666397,-671.573425,-0.000112,0.004493,0.114118,292.098724,14.880218,1.141182,-671.573425,294.500458,0.000000
98.110008,65.596390,-671.662354,-0.000095,0.004493,0.114118,291.787323,14.864354,1.141182,-671.662354,294.500458,0.000000
98.510002,65.582611,-671.706848,-0.000099,0.004493,0.114127,291.726013,14.861233,1.141269,-671.706848,294.500458,0.000000
98.910004,65.532333,-671.662354,-0.000095,0.004493,0.114127,291.502380,14.849839,1.141269,-671.662354,294.500458,0.000000
99.310005,65.482071,-671.617859,-0.000095,0.004493,0.114127,291.278809,14.838449,1.141269,-671.617859,294.500458,0.000000
99.710007,65.438873,-671.662354,-0.000086,0.004493,0.114127,291.086639,14.828661,1.141269,-671.662354,294.500458,0.000000
100.110008,65.380783,-671.662354,-0.000082,0.004493,0.114127,290.828247,14.815497,1.141269,-671.662354,294.500458,0.000000
100.510002,65.339447,-671.662354,-0.000091,0.004493,0.114127,290.644379,14.806130,1.141269,-671.662354,294.500458,0.000000
100.910004,65.278015,-671.706848,-0.000095,0.004494,0.114136,290.371124,14.792210,1.141356,-671.706848,294.500458,0.000000
101.310005,65.240402,-671.662354,-0.000082,0.004494,0.114136,290.203796,14.783687,1.141356,-671.662354,294.500458,0.000000
101.710007,65.193115,-671.751343,-0.000099,0.004494,0.114144,289.993469,14.772971,1.141442,-671.751343,294.500458,0.000000
102.110008,65.179337,-671.751343,-0.000091,0.004495,0.114179,289.932159,14.769849,1.141789,-671.751343,294.500458,0.000000
102.510002,65.152527,-671.706848,-0.000082,0.004495,0.114179,289.812927,14.763774,1.141789,-671.706848,294.500458,0.000000
102.910004,65.178955,-671.706848,-0.000078,0.004496,0.114196,289.930481,14.769762,1.141963,-671.706848,294.500458,0.000000
103.310005,65.143585,-671.706848,-0.000078,0.004496,0.114196,289.773132,14.761747,1.141963,-671.706848,294.500458,0.000000
103.710007,65.119385,-671.751343,-0.000091,0.004496,0.114196,289.665497,14.756263,1.141963,-671.751343,294.500458,0.000000
104.110008,65.079163,-671.706848,-0.000086,0.004496,0.114196,289.486572,14.747149,1.141963,-671.706848,294.500458,0.000000
104.510002,65.037079,-671.751343,-0.000091,0.004496,0.114196,289.299377,14.737613,1.141963,-671.751343,294.500458,0.000000
104.910004,65.037827,-671.840271,-0.000082,0.004496,0.114196,289.302704,14.737782,1.141963,-671.840271,294.500458,0.000000
105.310005,65.507019,-671.751343,-0.000086,0.004504,0.114404,291.389771,14.844102,1.144044,-671.751343,294.500458,0.000000
105.710007,65.609421,-671.751343,-0.000095,0.004504,0.114396,291.845276,14.867308,1.143957,-671.751343,294.500458,0.000000
106.110008,65.619843,-671.795776,-0.000082,0.004504,0.114396,291.891632,14.869669,1.143957,-671.795776,294.500458,0.000000
106.510002,65.601227,-671.840271,-0.000073,0.004504,0.114396,291.808838,14.865450,1.143957,-671.840271,294.500458,0.000000
106.910004,65.613892,-671.795776,-0.000095,0.004504,0.114396,291.865173,14.868320,1.143957,-671.795776,294.500458,0.000000
107.310005,65.594894,-671.795776,-0.000091,0.004504,0.114396,291.780670,14.864016,1.143957,-671.795776,294.500458,0.000000
107.710007,65.585968,-671.751343,-0.000073,0.004504,0.114396,291.740967,14.861993,1.143957,-671.751343,294.500458,0.000000
108.110008,65.572189,-671.884766,-0.000078,0.004504,0.114396,291.679657,14.858871,1.143957,-671.884766,294.500458,0.000000
108.510002,65.544998,-671.840271,-0.000095,0.004504,0.114396,291.558716,14.852709,1.143957,-671.840271,294.500458,0.000000
108.910004,65.534576,-671.840271,-0.000082,0.004504,0.114396,291.512360,14.850348,1.143957,-671.840271,294.500458,0.000000
109.310005,65.501801,-671.884766,-0.000078,0.004504,0.114396,291.366547,14.842920,1.143957,-671.884766,294.500458,0.000000
109.710007,65.486908,-671.884766,-0.000086,0.004504,0.114396,291.300323,14.839546,1.143957,-671.884766,294.500458,0.000000
110.110008,65.470154,-671.884766,-0.000082,0.004504,0.114396,291.225800,14.835750,1.143957,-671.884766,294.500458,0.000000
110.510002,65.418396,-671.840271,-0.000069,0.004504,0.114396,290.995544,14.824020,1.143957,-671.840271,294.500458,0.000000
110.910004,65.400146,-671.840271,-0.000073,0.004504,0.114396,290.914368,14.819884,1.143957,-671.840271,294.500458,0.000000
111.310005,65.353973,-671.929260,-0.000082,0.004504,0.114396,290.708984,14.809422,1.143957,-671.929260,294.500458,0.000000
111.710007,65.332748,-671.884766,-0.000082,0.004504,0.114396,290.614594,14.804612,1.143957,-671.884766,294.500458,0.000000
112.110008,65.316742,-671.929260,-0.000082,0.004504,0.114396,290.543365,14.800985,1.143957,-671.929260,294.500458,0.000000
112.510002,65.295517,-671.973755,-0.000082,0.004504,0.114396,290.448975,14.796175,1.143957,-671.973755,294.500458,0.000000
112.910004,65.295517,-671.929260,-0.000082,0.004504,0.114404,290.448975,14.796175,1.144044,-671.929260,294.500458,0.000000
113.310005,65.266098,-671.929260,-0.000073,0.004504,0.114404,290.318115,14.789509,1.144044,-671.929260,294.500458,0.000000
113.710007,65.243378,-672.018188,-0.000078,0.004504,0.114404,290.217041,14.784361,1.144044,-672.018188,294.500458,0.000000
114.110008,65.223648,-671.929260,-0.000078,0.004504,0.114404,290.129272,14.779890,1.144044,-671.929260,294.500458,0.000000
114.510002,65.186401,-672.018188,-0.000082,0.004505,0.114430,289.963593,14.771450,1.144304,-672.018188,294.500458,0.000000
114.910004,65.185654,-671.973755,-0.000065,0.004505,0.114430,289.960266,14.771280,1.144304,-671.973755,294.500458,0.000000
115.310005,65.182312,-672.018188,-0.000086,0.004505,0.114430,289.945404,14.770522,1.144304,-672.018188,294.500458,0.000000
115.710007,65.151779,-672.018188,-0.000073,0.004505,0.114430,289.809601,14.763604,1.144304,-672.018188,294.500458,0.000000
116.110008,65.130173,-672.018188,-0.000082,0.004505,0.114439,289.713470,14.758708,1.144391,-672.018188,294.500458,0.000000
116.510002,65.129425,-672.018188,-0.000082,0.004506,0.114448,289.710144,14.758538,1.144478,-672.018188,294.500458,0.000000
116.910004,65.223648,-672.018188,-0.000082,0.004508,0.114500,290.129272,14.779890,1.144998,-672.018188,294.500458,0.000000
117.310005,65.245605,-672.018188,-0.000073,0.004508,0.114500,290.226959,14.784865,1.144998,-672.018188,294.500458,0.000000
117.710007,65.248215,-672.107178,-0.000082,0.004508,0.114500,290.238556,14.785457,1.144998,-672.107178,294.500458,0.000000
118.110008,65.243011,-672.018188,-0.000078,0.004508,0.114500,290.215424,14.784278,1.144998,-672.018188,294.500458,0.000000
118.510002,65.237427,-672.062683,-0.000082,0.004508,0.114500,290.190582,14.783012,1.144998,-672.062683,294.500458,0.000000
118.910004,65.236298,-672.062683,-0.000078,0.004508,0.114500,290.185547,14.782756,1.144998,-672.062683,294.500458,0.000000
119.310005,65.217682,-672.107178,-0.000073,0.004508,0.114500,290.102753,14.778538,1.144998,-672.107178,294.500458,0.000000
119.710007,65.215073,-672.151672,-0.000069,0.004508,0.114508,290.091125,14.777947,1.145085,-672.151672,294.500458,0.000000
120.110008,65.202423,-672.107178,-0.000082,0.004508,0.114508,290.034851,14.775080,1.145085,-672.107178,294.500458,0.000000
120.510002,65.195343,-672.107178,-0.000078,0.004508,0.114508,290.003357,14.773476,1.145085,-672.107178,294.500458,0.000000
120.910004,65.176346,-672.107178,-0.000078,0.004508,0.114508,289.918854,14.769171,1.145085,-672.107178,294.500458,0.000000
121.310005,65.158844,-672.196106,-0.000069,0.004509,0.114526,289.841003,14.765205,1.145258,-672.196106,294.500458,0.000000
121.710007,65.159973,-672.107178,-0.000082,0.004509,0.114526,289.846039,14.765461,1.145258,-672.107178,294.500458,0.000000
122.110008,65.142471,-672.107178,-0.000091,0.004509,0.114526,289.768188,14.761495,1.145258,-672.107178,294.500458,0.000000
122.510002,65.131668,-672.062683,-0.000078,0.004509,0.114526,289.720123,14.759047,1.145258,-672.062683,294.500458,0.000000
122.910004,65.117142,-672.196106,-0.000065,0.004509,0.114534,289.655518,14.755754,1.145345,-672.196106,294.500458,0.000000
123.310005,65.116776,-672.196106,-0.000082,0.004509,0.114534,289.653870,14.755672,1.145345,-672.196106,294.500458,0.000000
123.710007,65.107468,-672.240601,-0.000082,0.004509,0.114534,289.612488,14.753563,1.145345,-672.240601,294.500458,0.000000
124.110008,65.089218,-672.240601,-0.000095,0.004509,0.114534,289.531311,14.749428,1.145345,-672.240601,294.500458,0.000000
124.510002,65.076553,-672.196106,-0.000086,0.004509,0.114534,289.474976,14.746557,1.145345,-672.196106,294.500458,0.000000
124.910004,65.077301,-672.240601,-0.000069,0.004509,0.114534,289.478302,14.746727,1.145345,-672.240601,294.500458,0.000000
125.310005,65.051605,-672.240601,-0.000078,0.004509,0.114534,289.363983,14.740905,1.145345,-672.240601,294.500458,0.000000
125.710007,65.042664,-672.240601,-0.000073,0.004509,0.114534,289.324219,14.738878,1.145345,-672.240601,294.500458,0.000000
126.110008,65.019577,-672.285095,-0.000078,0.004509,0.114534,289.221527,14.733647,1.145345,-672.285095,294.500458,0.000000
126.510010,65.005798,-672.285095,-0.000069,0.004509,0.114534,289.160248,14.730524,1.145345,-672.285095,294.500458,0.000000
126.910004,64.984955,-672.285095,-0.000069,0.004509,0.114534,289.067505,14.725801,1.145345,-672.285095,294.500458,0.000000
127.310005,64.976761,-672.374084,-0.000091,0.004509,0.114534,289.031067,14.723944,1.145345,-672.374084,294.500458,0.000000
127.710007,64.967819,-672.285095,-0.000086,0.004509,0.114534,288.991302,14.721919,1.145345,-672.285095,294.500458,0.000000
128.110001,65.588196,-672.285095,-0.000078,0.004518,0.114751,291.750854,14.862498,1.147513,-672.285095,294.500458,0.000000
128.510010,65.629898,-672.285095,-0.000069,0.004518,0.114751,291.936371,14.871947,1.147513,-672.285095,294.500458,0.000000
128.910004,65.681656,-672.374084,-0.000069,0.004518,0.114751,292.166595,14.883677,1.147513,-672.374084,294.500458,0.000000
129.310013,65.687241,-672.374084,-0.000069,0.004518,0.114751,292.191437,14.884942,1.147513,-672.374084,294.500458,0.000000
129.710007,65.675323,-672.374084,-0.000069,0.004518,0.114751,292.138428,14.882241,1.147513,-672.374084,294.500458,0.000000
130.110001,65.695816,-672.418518,-0.000073,0.004518,0.114751,292.229584,14.886885,1.147513,-672.418518,294.500458,0.000000
130.510010,65.685013,-672.374084,-0.000073,0.004518,0.114751,292.181519,14.884437,1.147513,-672.374084,294.500458,0.000000
130.910004,65.674957,-672.329590,-0.000069,0.004518,0.114751,292.136810,14.882158,1.147513,-672.329590,294.500458,0.000000
131.310013,65.669739,-672.418518,-0.000065,0.004518,0.114751,292.113586,14.880975,1.147513,-672.418518,294.500458,0.000000
131.710007,65.616867,-672.418518,-0.000056,0.004518,0.114751,291.878387,14.868995,1.147513,-672.418518,294.500458,0.000000
132.110001,65.608307,-672.418518,-0.000069,0.004518,0.114751,291.840332,14.867055,1.147513,-672.418518,294.500458,0.000000
132.510010,65.610168,-672.463013,-0.000078,0.004518,0.114751,291.848602,14.867476,1.147513,-672.463013,294.500458,0.000000
132.910004,65.591171,-672.418518,-0.000065,0.004518,0.114751,291.764099,14.863172,1.147513,-672.418518,294.500458,0.000000
133.310013,65.584106,-672.418518,-0.000069,0.004518,0.114751,291.732666,14.861570,1.147513,-672.418518,294.500458,0.000000
133.710007,65.578140,-672.463013,-0.000073,0.004518,0.114751,291.706146,14.860219,1.147513,-672.463013,294.500458,0.000000
134.110001,65.574417,-672.463013,-0.000069,0.004518,0.114751,291.689575,14.859375,1.147513,-672.463013,294.500458,0.000000
134.510010,65.563995,-672.463013,-0.000082,0.004518,0.114751,291.643219,14.857014,1.147513,-672.463013,294.500458,0.000000
134.910004,65.557663,-672.507507,-0.000073,0.004518,0.114751,291.615051,14.855579,1.147513,-672.507507,294.500458,0.000000
135.310013,65.545746,-672.552002,-0.000078,0.004518,0.114751,291.562042,14.852879,1.147513,-672.552002,294.500458,0.000000
135.710007,65.531601,-672.596436,-0.000078,0.004518,0.114751,291.499115,14.849672,1.147513,-672.596436,1681.640747,0.000000
136.110001,65.515579,-672.596436,-0.000073,0.004513,0.114639,291.427856,14.846043,1.146386,-672.596436,0.114517,0.000000
136.510010,65.515961,-672.552002,-0.000065,0.004496,0.114188,291.429535,14.846128,1.141876,-672.552002,0.113849,0.000000
136.910004,65.368500,-672.552002,-0.000078,0.004475,0.113676,290.773621,14.812714,1.136760,-672.552002,0.113182,0.000000
137.310013,65.308548,-672.507507,-0.000065,0.004450,0.113026,290.506927,14.799129,1.130255,-672.507507,0.112514,0.000000
137.710007,65.276886,-672.552002,-0.000060,0.004424,0.112358,290.366089,14.791954,1.123578,-672.552002,0.111846,0.000000
138.110001,65.261993,-672.596436,-0.000073,0.004399,0.111733,290.299835,14.788579,1.117334,-672.596436,0.111178,0.000000
138.510010,65.210983,-672.596436,-0.000060,0.004371,0.111031,290.072937,14.777020,1.110309,-672.596436,0.110519,0.000000
138.910004,65.227371,-672.596436,-0.000060,0.004348,0.110450,290.145844,14.780734,1.104499,-672.596436,0.109851,0.000000
139.310013,65.185654,-672.640930,-0.000056,0.004322,0.109791,289.960266,14.771280,1.097908,-672.640930,0.109184,0.000000
139.710007,65.128693,-672.596436,-0.000060,0.004298,0.109166,289.706879,14.758373,1.091664,-672.596436,0.108516,0.000000
140.110001,64.895203,-672.640930,-0.000065,0.004276,0.108620,288.668274,14.705463,1.086200,-672.640930,0.107848,0.000000
140.510010,64.205582,-672.640930,-0.000056,0.004249,0.107935,285.600677,14.549192,1.079349,-672.640930,0.107180,0.000000
140.910004,63.238525,-672.640930,-0.000052,0.004226,0.107328,281.299011,14.330054,1.073279,-672.640930,0.106513,0.000000
141.310013,61.981766,-672.685425,-0.000052,0.004200,0.106677,275.708649,14.045269,1.066774,-672.685425,0.105845,0.000000
141.710007,60.600639,-672.640930,-0.000052,0.004179,0.106148,269.565094,13.732301,1.061484,-672.640930,0.105186,0.000000
142.110001,58.731331,-672.640930,-0.000056,0.004152,0.105463,261.250000,13.308709,1.054633,-672.640930,0.104518,0.000000
142.510010,56.677322,-672.685425,-0.000052,0.004127,0.104830,252.113327,12.843265,1.048303,-672.685425,0.103850,0.000000
142.910004,54.341805,-672.729919,-0.000056,0.004100,0.104128,241.724426,12.314029,1.041278,-672.729919,0.103183,0.000000
143.310013,51.842438,-672.729919,-0.000060,0.004075,0.103503,230.606674,11.747664,1.035034,-672.729919,0.102515,0.000000
143.710007,49.144974,-672.729919,-0.000060,0.004048,0.102818,218.607758,11.136411,1.028183,-672.729919,0.101847,0.000000
144.110001,46.421440,-672.729919,-0.000052,0.004026,0.102255,206.492874,10.519248,1.022546,-672.729919,0.101179,0.000000
144.510010,43.886703,-672.685425,-0.000060,0.003997,0.101535,195.217804,9.944869,1.015348,-672.685425,0.100511,0.000000
144.910004,40.492897,-672.774414,-0.000052,0.003970,0.100850,180.121399,9.175822,1.008497,-672.774414,0.099852,0.000000
145.310013,38.154770,-672.774414,-0.000065,0.003951,0.100364,169.720886,8.645994,1.003640,-672.774414,0.099185,0.000000
145.710007,34.912895,-672.729919,-0.000043,0.003921,0.099592,155.300308,7.911376,0.995922,-672.729919,0.098517,0.000000
146.110001,32.426941,-672.729919,-0.000052,0.003899,0.099037,144.242233,7.348050,0.990372,-672.729919,0.097849,0.000000
146.510010,28.924774,-672.774414,-0.000069,0.003864,0.098135,128.663818,6.554448,0.981353,-672.774414,0.097181,0.000000
146.910004,26.217255,-672.774414,-0.000073,0.003840,0.097546,116.620171,5.940915,0.975455,-672.774414,0.096514,0.000000
147.310013,23.463188,-672.863342,-0.000060,0.003815,0.096904,104.369476,5.316834,0.969038,-672.863342,0.095846,0.000000
147.710007,20.267860,-672.774414,-0.000060,0.003787,0.096201,90.155945,4.592763,0.962013,-672.774414,0.095178,0.000000
148.110001,18.032135,-672.863342,-0.000069,0.003767,0.095681,80.210945,4.086140,0.956810,-672.863342,0.094519,0.000000
148.510010,14.494972,-672.907837,-0.000065,0.003734,0.094840,64.476860,3.284608,0.948398,-672.907837,0.093851,0.000000
148.910004,12.106941,-672.863342,-0.000069,0.003712,0.094285,53.854362,2.743472,0.942848,-672.863342,0.093183,0.000000
149.310013,8.789108,-672.818848,-0.000078,0.003682,0.093522,39.095905,1.991640,0.935216,-672.818848,0.092516,0.000000
149.710007,7.254929,-672.818848,-0.000099,0.003670,0.093209,32.271534,1.643990,0.932094,-672.818848,0.091848,0.000000
150.110001,3.003181,-672.907837,-0.000086,0.003628,0.092143,13.358818,0.680531,0.921427,-672.907837,0.091180,0.000000
150.510010,1.213562,-672.907837,-0.000099,0.003606,0.091605,5.398193,0.274997,0.916051,-672.907837,0.090512,0.000000
150.910004,-1.872662,-672.907837,-0.000095,0.003573,0.090755,-8.330015,-0.424351,0.907552,-672.907837,0.089845,0.000000
151.310013,-0.293434,-672.952332,-0.000160,0.003552,0.090217,-1.305260,-0.066493,0.902175,-672.952332,0.089177,0.000000
151.710007,-0.091980,-672.907837,-0.000185,0.003531,0.089680,-0.409147,-0.020843,0.896798,-672.907837,0.088518,0.000000
152.110001,-0.117668,-672.996765,-0.000250,0.003494,0.088743,-0.523414,-0.026664,0.887432,-672.996765,0.087850,0.000000
152.510010,-0.100540,-672.952332,-0.000310,0.003465,0.088023,-0.447225,-0.022783,0.880234,-672.952332,0.087182,0.000000
152.910004,-0.102028,-672.996765,-0.000345,0.003436,0.087278,-0.453843,-0.023120,0.872776,-672.996765,0.086514,0.000000
153.310013,-0.049530,-672.952332,-0.000371,0.003430,0.087121,-0.220321,-0.011224,0.871215,-672.952332,0.085847,0.000000
153.710007,-0.088257,-673.041260,-0.000431,0.003396,0.086254,-0.392586,-0.019999,0.862543,-673.041260,0.085179,0.000000
154.110001,-0.051392,-672.952332,-0.000487,0.003369,0.085569,-0.228601,-0.011646,0.855692,-672.952332,0.084511,0.000000
154.510010,-0.044685,-672.996765,-0.000543,0.003342,0.084875,-0.198770,-0.010126,0.848754,-672.996765,0.083843,0.000000
154.910004,-0.028305,-673.041260,-0.000591,0.003321,0.084355,-0.125907,-0.006414,0.843550,-673.041260,0.083184,0.000000
155.310013,-0.038727,-672.996765,-0.000664,0.003292,0.083609,-0.172265,-0.008776,0.836092,-672.996765,0.082517,0.000000
155.710007,-0.018250,-672.996765,-0.000742,0.003268,0.083002,-0.081178,-0.004135,0.830022,-672.996765,0.081849,0.000000
156.110001,-0.051392,-673.041260,-0.000819,0.003229,0.082005,-0.228601,-0.011646,0.820049,-673.041260,0.081181,0.000000
156.510010,-0.036491,-672.996765,-0.000867,0.003206,0.081441,-0.162322,-0.008269,0.814412,-672.996765,0.080513,0.000000
156.910004,-0.008942,-673.130249,-0.000949,0.003180,0.080765,-0.039774,-0.002026,0.807647,-673.130249,0.079845,0.000000
157.310013,-0.064049,-673.085754,-0.001000,0.003154,0.080123,-0.284903,-0.014514,0.801230,-673.085754,0.079178,0.000000
157.710007,-0.047661,-673.085754,-0.001052,0.003134,0.079611,-0.212006,-0.010800,0.796113,-673.085754,0.078510,0.000000
158.110001,-0.070381,-673.085754,-0.001121,0.003105,0.078866,-0.313071,-0.015949,0.788655,-673.085754,0.077851,0.000000
158.510010,-0.066658,-673.085754,-0.001190,0.003079,0.078215,-0.296510,-0.015105,0.782151,-673.085754,0.077183,0.000000
158.910004,-0.005211,-673.130249,-0.001246,0.003051,0.077504,-0.023179,-0.001181,0.775040,-673.130249,0.076515,0.000000
159.310013,-0.014893,-673.174744,-0.001311,0.003024,0.076810,-0.066245,-0.003375,0.768102,-673.174744,0.075848,0.000000
159.710007,-0.046547,-673.130249,-0.001350,0.003000,0.076203,-0.207051,-0.010548,0.762031,-673.130249,0.075180,0.000000
160.110001,-0.060326,-673.130249,-0.001410,0.002971,0.075466,-0.268342,-0.013670,0.754660,-673.130249,0.074512,0.000000
160.510010,-0.073730,-673.174744,-0.001483,0.002949,0.074894,-0.327969,-0.016708,0.748936,-673.174744,0.073844,0.000000
160.910004,0.010422,-673.174744,-0.001526,0.002920,0.074156,0.046358,0.002362,0.741565,-673.174744,0.073177,0.000000
161.310013,-0.003723,-673.219177,-0.001561,0.002892,0.073454,-0.016561,-0.000844,0.734540,-673.219177,0.072517,0.000000
161.710007,-0.002609,-673.219177,-0.001600,0.002868,0.072847,-0.011607,-0.000591,0.728470,-673.219177,0.071850,0.000000
162.110001,-0.068520,-673.219177,-0.001630,0.002842,0.072179,-0.304790,-0.015527,0.721792,-673.219177,0.071182,0.000000
162.510010,-0.061440,-673.219177,-0.001664,0.002818,0.071589,-0.273297,-0.013922,0.715895,-673.219177,0.070514,0.000000
162.910004,-0.031654,-673.174744,-0.001707,0.002791,0.070887,-0.140806,-0.007173,0.708870,-673.174744,0.070766,0.000000
163.100006,-0.032028,-673.219177,-0.001703,0.002791,0.070896,-0.142469,-0.007258,0.708957,-673.219177,0.070766,0.000000