File: Data/compression 33/AutoNoHeating-17-33-reverse-1-2_11152024_182836.csv
Time (sec),S:Load (lbs),S:HL1 (DIM),S:LVDT (in),S:Position (in),Ch:Position (mm),Ch:Load (N),Ch:Stress (MPa),Ch:Strain (mm/mm),Ch:HL1 (DIM),Set Point (),Cycles ()
0.210000,-0.091606,-119.386871,-0.011490,-0.006572,-0.166932,-0.407484,-0.020758,-1.669323,-119.386871,-0.166681,0.000000
0.560000,-0.052132,-119.431351,-0.011490,-0.006497,-0.165024,-0.231893,-0.011813,-1.650244,-119.431351,-0.164166,0.000000
0.910000,-0.098679,-119.520317,-0.011357,-0.006282,-0.159570,-0.438944,-0.022361,-1.595695,-119.520317,-0.158338,0.000000
1.260000,-0.061073,-119.520317,-0.011115,-0.006059,-0.153898,-0.271668,-0.013839,-1.538979,-119.520317,-0.152493,0.000000
1.610000,-0.064049,-119.564796,-0.010869,-0.005826,-0.147975,-0.284903,-0.014514,-1.479747,-119.564796,-0.146665,0.000000
1.960000,-0.088997,-119.564796,-0.010628,-0.005591,-0.142008,-0.395878,-0.020167,-1.420082,-119.564796,-0.140837,0.000000
2.310000,-0.126984,-119.609276,-0.010412,-0.005370,-0.136406,-0.564851,-0.028775,-1.364059,-119.609276,-0.135010,0.000000
2.660000,-0.092354,-119.609276,-0.010162,-0.005136,-0.130448,-0.410810,-0.020928,-1.304481,-119.609276,-0.129182,0.000000
3.010000,-0.031281,-119.653755,-0.009934,-0.004906,-0.124603,-0.139143,-0.007088,-1.246030,-119.653755,-0.123337,0.000000
3.360000,-0.059212,-119.698242,-0.009692,-0.004677,-0.118801,-0.263387,-0.013418,-1.188012,-119.698242,-0.117509,0.000000
3.710000,-0.068893,-119.742722,-0.009459,-0.004453,-0.113104,-0.306453,-0.015611,-1.131036,-119.742722,-0.111681,0.000000
4.060000,-0.133682,-119.742722,-0.009205,-0.004217,-0.107102,-0.594648,-0.030293,-1.071024,-119.742722,-0.105854,0.000000
4.410000,-0.119164,-119.787201,-0.008977,-0.003988,-0.101283,-0.530066,-0.027003,-1.012833,-119.787201,-0.100026,0.000000
4.760000,-0.059212,-119.787201,-0.008739,-0.003758,-0.095456,-0.263387,-0.013418,-0.954555,-119.787201,-0.094198,0.000000
5.110000,-0.026070,-119.787201,-0.008520,-0.003529,-0.089645,-0.115964,-0.005907,-0.896451,-119.787201,-0.088353,0.000000
5.460000,-0.059952,-119.876160,-0.008269,-0.003301,-0.083835,-0.266679,-0.013585,-0.838347,-119.876160,-0.082525,0.000000
5.810000,-0.088997,-119.876160,-0.008028,-0.003071,-0.077998,-0.395878,-0.020167,-0.779983,-119.876160,-0.076697,0.000000
6.160000,-0.127724,-119.831680,-0.007791,-0.002836,-0.072023,-0.568143,-0.028943,-0.720231,-119.831680,-0.070870,0.000000
6.510000,-0.085648,-119.920647,-0.007562,-0.002607,-0.066213,-0.380979,-0.019408,-0.662127,-119.920647,-0.065042,0.000000
6.860000,-0.056602,-119.920647,-0.007330,-0.002379,-0.060437,-0.251780,-0.012826,-0.604370,-119.920647,-0.059197,0.000000
7.210001,-0.021973,-119.965126,-0.007080,-0.002151,-0.054635,-0.097739,-0.004979,-0.546352,-119.965126,-0.053369,0.000000
7.560000,-0.052132,-120.009605,-0.006847,-0.001921,-0.048790,-0.231893,-0.011813,-0.487901,-120.009605,-0.047541,0.000000
7.910000,-0.101662,-120.054085,-0.006631,-0.001692,-0.042971,-0.452214,-0.023037,-0.429710,-120.054085,-0.041714,0.000000
8.260000,-0.090858,-119.965126,-0.006385,-0.001455,-0.036961,-0.404159,-0.020589,-0.369612,-119.965126,-0.035886,0.000000
8.610001,-0.088257,-120.054085,-0.006170,-0.001234,-0.031342,-0.392586,-0.019999,-0.313415,-120.054085,-0.030058,0.000000
8.960000,-0.026817,-120.054085,-0.005907,-0.001003,-0.025470,-0.119289,-0.006077,-0.254704,-120.054085,-0.024213,0.000000
9.310000,-0.032028,-120.143051,-0.005670,-0.000771,-0.019573,-0.142469,-0.007258,-0.195733,-120.143051,-0.018385,0.000000
9.660001,-0.053993,-120.143051,-0.005445,-0.000550,-0.013971,-0.240174,-0.012235,-0.139710,-120.143051,-0.012557,0.000000
10.010000,-0.054367,-120.187531,-0.005200,-0.000316,-0.008022,-0.241837,-0.012320,-0.080218,-120.187531,-0.006730,0.000000
10.360001,-0.074852,-120.232010,-0.004980,-0.000086,-0.002194,-0.332958,-0.016962,-0.021941,-120.232010,-0.000902,0.000000
10.710000,0.243156,-120.232010,-0.004738,-0.000004,-0.000113,1.081614,0.055100,-0.001127,-120.232010,-0.000026,0.000000
11.060000,0.147453,-120.276489,-0.004730,-0.000010,-0.000252,0.655905,0.033413,-0.002515,-120.276489,-0.000026,0.000000
11.410001,0.170914,-120.320976,-0.004743,-0.000010,-0.000252,0.760262,0.038730,-0.002515,-120.320976,0.000321,0.000000
11.760000,0.198471,-120.276489,-0.004747,-0.000010,-0.000243,0.882843,0.044974,-0.002428,-120.276489,0.000911,0.000000
12.110001,0.360825,-120.320976,-0.004743,0.000014,0.000347,1.605028,0.081764,0.003469,-120.320976,0.001492,0.000000
12.460001,0.551483,-120.365456,-0.004721,0.000044,0.001127,2.453120,0.124968,0.011274,-120.365456,0.002073,0.000000
12.810000,0.914169,-120.320976,-0.004674,0.000069,0.001752,4.066428,0.207154,0.017518,-120.320976,0.002662,0.000000
13.160001,1.161430,-120.454414,-0.004678,0.000082,0.002090,5.166300,0.263184,0.020900,-120.454414,0.003243,0.000000
13.510000,1.507736,-120.409935,-0.004656,0.000102,0.002584,6.706746,0.341658,0.025843,-120.409935,0.003824,0.000000
13.860001,1.982880,-120.454414,-0.004622,0.000130,0.003304,8.820290,0.449327,0.033041,-120.454414,0.004405,0.000000
14.210001,2.510902,-120.498894,-0.004613,0.000150,0.003807,11.169052,0.568979,0.038071,-120.498894,0.004995,0.000000
14.560000,3.128296,-120.498894,-0.004592,0.000179,0.004536,13.915355,0.708882,0.045356,-120.498894,0.005576,0.000000
14.910001,3.355446,-120.498894,-0.004587,0.000197,0.005013,14.925769,0.760355,0.050125,-120.498894,0.006157,0.000000
15.260001,3.787025,-120.587860,-0.004557,0.000210,0.005333,16.845531,0.858152,0.053334,-120.587860,0.006738,0.000000
15.610001,4.754448,-120.543381,-0.004518,0.000247,0.006261,21.148840,1.077373,0.062614,-120.543381,0.007328,0.000000
15.960001,5.249329,-120.632339,-0.004518,0.000268,0.006816,23.350180,1.189515,0.068164,-120.632339,0.007909,0.000000
16.310001,5.813103,-120.632339,-0.004488,0.000292,0.007423,25.857973,1.317268,0.074234,-120.632339,0.008490,0.000000
16.660000,6.404434,-120.632339,-0.004475,0.000316,0.008031,28.488346,1.451265,0.080305,-120.632339,0.009071,0.000000
17.010000,6.800636,-120.676819,-0.004432,0.000335,0.008507,30.250742,1.541046,0.085075,-120.676819,0.009661,0.000000
17.360001,7.005814,-120.765785,-0.004441,0.000347,0.008811,31.163416,1.587540,0.088110,-120.765785,0.010242,0.000000
17.710001,8.171341,-120.765785,-0.004402,0.000385,0.009782,36.347939,1.851652,0.097823,-120.765785,0.010823,0.000000
18.060001,8.617813,-120.676819,-0.004398,0.000408,0.010363,38.333946,1.952824,0.103634,-120.676819,0.011413,0.000000
18.410002,8.982735,-120.854744,-0.004368,0.000428,0.010875,39.957199,2.035517,0.108750,-120.854744,0.011994,0.000000
18.760000,9.851112,-120.854744,-0.004363,0.000459,0.011656,43.819935,2.232294,0.116555,-120.854744,0.012575,0.000000
19.110001,10.135231,-120.810265,-0.004337,0.000481,0.012219,45.083759,2.296676,0.122192,-120.810265,0.013156,0.000000
19.460001,10.578728,-120.810265,-0.004312,0.000502,0.012740,47.056530,2.397174,0.127395,-120.810265,0.013746,0.000000
19.810001,11.026688,-120.854744,-0.004290,0.000524,0.013321,49.049156,2.498683,0.133206,-120.854744,0.014327,0.000000
20.160002,11.620995,-120.899223,-0.004273,0.000548,0.013928,51.692764,2.633355,0.139276,-120.899223,0.014908,0.000000
20.510000,11.483963,-120.899223,-0.004243,0.000556,0.014118,51.083218,2.602303,0.141184,-120.899223,0.015489,0.000000
20.860001,12.466286,-120.988190,-0.004221,0.000593,0.015055,55.452808,2.824901,0.150550,-120.988190,0.016078,0.000000
21.210001,12.832321,-120.988190,-0.004204,0.000613,0.015575,57.081017,2.907845,0.155754,-120.988190,0.016659,0.000000
21.560001,13.207306,-120.943703,-0.004191,0.000635,0.016130,58.749031,2.992818,0.161304,-120.943703,0.017240,0.000000
21.910002,13.697716,-121.077148,-0.004161,0.000657,0.016694,60.930481,3.103947,0.166941,-121.077148,0.017821,0.000000
22.260000,13.712982,-121.121628,-0.004156,0.000670,0.017006,60.998390,3.107406,0.170063,-121.121628,0.018411,0.000000
22.610001,14.379532,-121.077148,-0.004139,0.000699,0.017761,63.963352,3.258449,0.177608,-121.077148,0.018992,0.000000
22.960001,14.954102,-121.166107,-0.004109,0.000722,0.018333,66.519165,3.388648,0.183331,-121.166107,0.019573,0.000000
23.310001,15.565163,-121.121628,-0.004079,0.000751,0.019088,69.237305,3.527116,0.190876,-121.121628,0.020163,0.000000
23.660002,16.084999,-121.121628,-0.004049,0.000777,0.019738,71.549652,3.644913,0.197380,-121.121628,0.020744,0.000000
24.010000,16.187775,-121.210594,-0.004049,0.000793,0.020137,72.006821,3.668202,0.201370,-121.210594,0.021325,0.000000
24.360001,16.350502,-121.255074,-0.004036,0.000810,0.020562,72.730667,3.705077,0.205619,-121.255074,0.021906,0.000000
24.710001,17.123917,-121.299553,-0.003997,0.000843,0.021412,76.170982,3.880335,0.214118,-121.299553,0.022496,0.000000
25.060001,17.516022,-121.255074,-0.003975,0.000864,0.021958,77.915154,3.969187,0.219581,-121.255074,0.023077,0.000000
25.410002,17.730141,-121.344032,-0.003980,0.000885,0.022470,78.867607,4.017707,0.224698,-121.344032,0.023658,0.000000
25.760002,18.424988,-121.344032,-0.003928,0.000908,0.023068,81.958443,4.175162,0.230682,-121.344032,0.024239,0.000000
26.110001,18.731445,-121.388512,-0.003923,0.000931,0.023641,83.321632,4.244606,0.236406,-121.388512,0.024829,0.000000
26.460001,19.359642,-121.344032,-0.003889,0.000959,0.024360,86.115990,4.386958,0.243604,-121.344032,0.025410,0.000000
26.810001,19.396133,-121.432999,-0.003880,0.000976,0.024794,86.278313,4.395227,0.247940,-121.432999,0.025991,0.000000
27.160002,19.743187,-121.432999,-0.003854,0.001001,0.025427,87.822083,4.473870,0.254270,-121.432999,0.026580,0.000000
27.510002,20.474152,-121.477478,-0.003829,0.001027,0.026086,91.073578,4.639509,0.260861,-121.477478,0.027161,0.000000
27.860001,20.791039,-121.432999,-0.003798,0.001051,0.026702,92.483162,4.711317,0.267019,-121.432999,0.027743,0.000000
28.210001,20.502449,-121.521957,-0.003790,0.001063,0.027005,91.199448,4.645921,0.270054,-121.521957,0.028324,0.000000
28.560001,21.103462,-121.521957,-0.003760,0.001094,0.027795,93.872887,4.782113,0.277946,-121.521957,0.028913,0.000000
28.910002,21.380508,-121.566437,-0.003747,0.001112,0.028246,95.105255,4.844893,0.282455,-121.566437,0.029494,0.000000
29.260002,21.942413,-121.610924,-0.003729,0.001141,0.028991,97.604729,4.972222,0.289914,-121.610924,0.030075,0.000000
29.610001,22.051147,-121.610924,-0.003686,0.001158,0.029408,98.088402,4.996861,0.294076,-121.610924,0.030656,0.000000
29.960001,22.981339,-121.699883,-0.003673,0.001192,0.030284,102.226097,5.207646,0.302835,-121.699883,0.031246,0.000000
30.310001,23.005539,-121.744362,-0.003648,0.001216,0.030891,102.333748,5.213130,0.308906,-121.744362,0.031827,0.000000
30.660002,22.942238,-121.699883,-0.003622,0.001235,0.031376,102.052170,5.198786,0.313762,-121.699883,0.032408,0.000000
31.010002,23.510849,-121.744362,-0.003596,0.001262,0.032053,104.581482,5.327635,0.320526,-121.744362,0.032989,0.000000
31.360001,23.606552,-121.788841,-0.003570,0.001283,0.032582,105.007187,5.349321,0.325817,-121.788841,0.033579,0.000000
31.710001,23.683632,-121.744362,-0.003548,0.001300,0.033015,105.350060,5.366787,0.330153,-121.744362,0.034160,0.000000
32.060001,24.177025,-121.833328,-0.003518,0.001323,0.033614,107.544777,5.478592,0.336137,-121.833328,0.034741,0.000000
32.410000,24.377357,-121.833328,-0.003488,0.001345,0.034169,108.435905,5.523988,0.341687,-121.833328,0.035331,0.000000
32.760002,24.637650,-121.877808,-0.003484,0.001366,0.034706,109.593742,5.582972,0.347064,-121.877808,0.035912,0.000000
33.110001,25.300102,-121.833328,-0.003458,0.001392,0.035365,112.540474,5.733085,0.353655,-121.833328,0.036493,0.000000
33.460003,25.441231,-121.877808,-0.003423,0.001413,0.035894,113.168243,5.765065,0.358945,-121.877808,0.037074,0.000000
33.810001,26.032181,-121.922287,-0.003402,0.001442,0.036632,115.796921,5.898976,0.366316,-121.922287,0.037664,0.000000
34.160000,26.156181,-121.966766,-0.003372,0.001468,0.037299,116.348503,5.927075,0.372994,-121.966766,0.038245,0.000000
34.510002,25.683640,-122.055733,-0.003354,0.001485,0.037716,114.246536,5.819996,0.377156,-122.055733,0.038826,0.000000
34.860001,26.048943,-122.055733,-0.003346,0.001506,0.038262,115.871483,5.902775,0.382620,-122.055733,0.039407,0.000000
35.210003,26.726288,-122.055733,-0.003316,0.001533,0.038938,118.884468,6.056263,0.389384,-122.055733,0.039996,0.000000
35.560001,26.399345,-122.100212,-0.003290,0.001548,0.039329,117.430153,5.982177,0.393287,-122.100212,0.040577,0.000000
35.910000,27.130684,-122.100212,-0.003272,0.001576,0.040031,120.683311,6.147901,0.400311,-122.100212,0.041159,0.000000
36.260002,26.273849,-122.144691,-0.003247,0.001583,0.040205,116.871918,5.953739,0.402046,-122.144691,0.041748,0.000000
36.610001,27.107971,-122.189171,-0.003225,0.001613,0.040976,120.582275,6.142754,0.409764,-122.189171,0.042329,0.000000
36.960003,28.271629,-122.233650,-0.003186,0.001645,0.041792,125.758492,6.406443,0.417916,-122.233650,0.042910,0.000000
37.310001,27.895905,-122.233650,-0.003165,0.001667,0.042338,124.087181,6.321302,0.423380,-122.233650,0.043491,0.000000
37.660004,28.344246,-122.233650,-0.003143,0.001691,0.042954,126.081505,6.422898,0.429537,-122.233650,0.044081,0.000000
38.010002,28.582191,-122.278137,-0.003117,0.001718,0.043630,127.139938,6.476817,0.436301,-122.278137,0.044662,0.000000
38.360001,28.340149,-122.278137,-0.003096,0.001733,0.044029,126.063278,6.421969,0.440290,-122.278137,0.045243,0.000000
38.710003,28.443298,-122.322617,-0.003061,0.001753,0.044523,126.522110,6.445344,0.445234,-122.322617,0.045824,0.000000
39.060001,29.519081,-122.367096,-0.003027,0.001786,0.045356,131.307434,6.689120,0.453559,-122.367096,0.046414,0.000000
39.410004,29.600258,-122.367096,-0.003009,0.001808,0.045920,131.668518,6.707514,0.459196,-122.367096,0.046995,0.000000
39.760002,29.549240,-122.456055,-0.002984,0.001827,0.046397,131.441589,6.695953,0.463966,-122.456055,0.047576,0.000000
40.110001,30.373299,-122.411575,-0.002966,0.001858,0.047186,135.107178,6.882688,0.471857,-122.411575,0.048157,0.000000
40.460003,30.477570,-122.411575,-0.002945,0.001882,0.047810,135.570999,6.906316,0.478102,-122.411575,0.048747,0.000000
40.810001,30.474213,-122.500542,-0.002897,0.001900,0.048261,135.556061,6.905555,0.482611,-122.500542,0.049328,0.000000
41.160004,30.709923,-122.545021,-0.002884,0.001924,0.048859,136.604553,6.958968,0.488595,-122.545021,0.049909,0.000000
41.510002,31.274818,-122.589500,-0.002863,0.001947,0.049458,139.117340,7.086975,0.494579,-122.589500,0.050499,0.000000
41.860001,30.737854,-122.545021,-0.002837,0.001959,0.049753,136.728806,6.965297,0.497527,-122.545021,0.051080,0.000000
42.210003,31.752945,-122.633980,-0.002811,0.001992,0.050585,141.244156,7.195320,0.505853,-122.633980,0.051661,0.000000
42.560001,32.097755,-122.633980,-0.002798,0.002013,0.051140,142.777954,7.273455,0.511403,-122.633980,0.052242,0.000000
42.910004,32.179306,-122.633980,-0.002768,0.002036,0.051704,143.140701,7.291935,0.517040,-122.633980,0.052831,0.000000
43.260002,32.516304,-122.722946,-0.002742,0.002056,0.052216,144.639740,7.368300,0.522157,-122.722946,0.053412,0.000000
43.610001,32.051956,-122.678467,-0.002721,0.002068,0.052528,142.574219,7.263077,0.525279,-122.678467,0.053993,0.000000
43.960003,33.021988,-122.722946,-0.002703,0.002103,0.053404,146.889145,7.482889,0.534038,-122.722946,0.054574,0.000000
44.310001,33.436066,-122.722946,-0.002665,0.002121,0.053863,148.731049,7.576721,0.538634,-122.722946,0.055164,0.000000
44.660004,34.503288,-122.811905,-0.002656,0.002151,0.054627,153.478287,7.818557,0.546265,-122.811905,0.055745,0.000000
45.010002,34.811981,-122.722946,-0.002626,0.002176,0.055260,154.851425,7.888508,0.552596,-122.722946,0.056326,0.000000
45.360001,34.660057,-122.856384,-0.002587,0.002196,0.055771,154.175629,7.854082,0.557713,-122.856384,0.056916,0.000000
45.710003,34.840279,-122.811905,-0.002570,0.002222,0.056448,154.977295,7.894920,0.564477,-122.811905,0.057497,0.000000
46.060001,35.094612,-122.856384,-0.002539,0.002243,0.056977,156.108627,7.952553,0.569767,-122.856384,0.058078,0.000000
46.410004,35.310959,-122.945351,-0.002518,0.002263,0.057480,157.070984,8.001577,0.574797,-122.945351,0.058659,0.000000
46.760002,35.371658,-122.945351,-0.002483,0.002286,0.058069,157.340988,8.015332,0.580694,-122.945351,0.059249,0.000000
47.110001,35.876221,-122.945351,-0.002453,0.002307,0.058590,159.585403,8.129668,0.585898,-122.945351,0.059830,0.000000
47.460003,36.247849,-122.989830,-0.002436,0.002334,0.059275,161.238480,8.213881,0.592749,-122.989830,0.060411,0.000000
47.810001,36.905830,-123.034309,-0.002410,0.002359,0.059917,164.165329,8.362981,0.599166,-123.034309,0.060992,0.000000
48.160004,36.809013,-122.989830,-0.002380,0.002379,0.060420,163.734665,8.341043,0.604196,-122.989830,0.061582,0.000000
48.510002,36.990730,-123.034309,-0.002367,0.002401,0.060975,164.542984,8.382219,0.609746,-123.034309,0.062163,0.000000
48.860001,37.875114,-123.078789,-0.002341,0.002427,0.061642,168.476929,8.582623,0.616424,-123.078789,0.062744,0.000000
49.210003,38.230736,-123.078789,-0.002311,0.002450,0.062232,170.058807,8.663209,0.622321,-123.078789,0.063325,0.000000
49.560001,38.590820,-123.167755,-0.002281,0.002473,0.062804,171.660538,8.744805,0.628045,-123.167755,0.063915,0.000000
49.910004,38.366280,-123.123276,-0.002246,0.002494,0.063342,170.661728,8.693924,0.633422,-123.123276,0.064496,0.000000
50.260002,38.466820,-123.167755,-0.002225,0.002512,0.063802,171.108963,8.716706,0.638018,-123.167755,0.065077,0.000000
50.610001,39.347847,-123.212234,-0.002203,0.002540,0.064504,175.027969,8.916349,0.645042,-123.212234,0.065666,0.000000
50.960003,39.343758,-123.212234,-0.002182,0.002556,0.064929,175.009781,8.915423,0.649292,-123.212234,0.066247,0.000000
51.310001,40.792282,-123.212234,-0.002143,0.002592,0.065848,181.453140,9.243663,0.658484,-123.212234,0.066828,0.000000
51.660004,41.037674,-123.301193,-0.002121,0.002615,0.066421,182.544693,9.299270,0.664208,-123.301193,0.067409,0.000000
52.010002,40.953522,-123.301193,-0.002100,0.002635,0.066941,182.170364,9.280201,0.669411,-123.301193,0.067999,0.000000
52.360001,41.612617,-123.390160,-0.002070,0.002662,0.067609,185.102173,9.429554,0.676089,-123.390160,0.068580,0.000000
52.710003,41.607033,-123.345680,-0.002044,0.002681,0.068086,185.077332,9.428288,0.680859,-123.345680,0.069161,0.000000
53.060001,41.919083,-123.434639,-0.002013,0.002704,0.068684,186.465393,9.499000,0.686843,-123.434639,0.069742,0.000000
53.410004,42.218094,-123.479118,-0.001988,0.002722,0.069127,187.795456,9.566757,0.691265,-123.479118,0.070332,0.000000
53.760002,42.556953,-123.390160,-0.001966,0.002744,0.069699,189.302780,9.643544,0.696989,-123.390160,0.070913,0.000000
54.110004,42.986671,-123.479118,-0.001940,0.002765,0.070237,191.214264,9.740919,0.702366,-123.479118,0.071494,0.000000
54.460003,43.795837,-123.523598,-0.001923,0.002789,0.070852,194.813614,9.924278,0.708523,-123.523598,0.072084,0.000000
54.810001,43.211586,-123.523598,-0.001906,0.002805,0.071251,192.214737,9.791885,0.712513,-123.523598,0.072665,0.000000
55.160004,45.456993,-123.523598,-0.001876,0.002841,0.072153,202.202805,10.300702,0.721532,-123.523598,0.073246,0.000000
55.510002,46.130615,-123.612564,-0.001854,0.002867,0.072812,205.199219,10.453347,0.728123,-123.612564,0.073827,0.000000
55.860004,45.836815,-123.612564,-0.001837,0.002885,0.073272,203.892334,10.386770,0.732719,-123.612564,0.074417,0.000000
56.210003,46.291481,-123.657043,-0.001811,0.002909,0.073896,205.914795,10.489799,0.738963,-123.657043,0.074998,0.000000
56.560001,47.393700,-123.657043,-0.001781,0.002932,0.074469,210.817703,10.739566,0.744687,-123.657043,0.075579,0.000000
56.910004,47.228745,-123.657043,-0.001755,0.002947,0.074850,210.083954,10.702187,0.748502,-123.657043,0.076160,0.000000
57.260002,48.296333,-123.657043,-0.001738,0.002975,0.075553,214.832825,10.944105,0.755527,-123.657043,0.076749,0.000000
57.610004,48.884308,-123.746002,-0.001720,0.002999,0.076177,217.448257,11.077343,0.761771,-123.746002,0.077331,0.000000
57.960003,48.473579,-123.746002,-0.001712,0.003010,0.076446,215.621246,10.984270,0.764459,-123.746002,0.077912,0.000000
58.310001,50.566689,-123.834969,-0.001673,0.003046,0.077357,224.931870,11.458575,0.773565,-123.834969,0.078493,0.000000
58.660004,50.987473,-123.834969,-0.001647,0.003065,0.077860,226.803604,11.553926,0.778595,-123.834969,0.079082,0.000000
59.010002,52.002930,-123.834969,-0.001625,0.003093,0.078553,231.320587,11.784033,0.785533,-123.834969,0.079663,0.000000
59.360004,52.753258,-123.790489,-0.001600,0.003118,0.079204,234.658203,11.954059,0.792037,-123.790489,0.080244,0.000000
59.710003,52.647133,-123.879448,-0.001582,0.003131,0.079533,234.186142,11.930011,0.795332,-123.879448,0.080834,0.000000
60.060001,54.056564,-123.879448,-0.001565,0.003162,0.080314,240.455612,12.249393,0.803138,-123.879448,0.081415,0.000000
60.410004,54.780457,-123.923927,-0.001548,0.003184,0.080869,243.675644,12.413429,0.808688,-123.923927,0.081996,0.000000
60.760002,55.527061,-123.968414,-0.001518,0.003206,0.081441,246.996704,12.582612,0.814411,-123.968414,0.082577,0.000000
61.110004,56.008911,-124.012894,-0.001496,0.003225,0.081918,249.140076,12.691800,0.819181,-124.012894,0.083167,0.000000
61.460003,57.555748,-124.012894,-0.001466,0.003257,0.082716,256.020752,13.042319,0.827160,-124.012894,0.083748,0.000000
61.810001,58.436035,-124.057373,-0.001466,0.003281,0.083349,259.936462,13.241796,0.833491,-124.057373,0.084329,0.000000
62.160004,58.867989,-124.057373,-0.001444,0.003299,0.083791,261.857880,13.339677,0.837913,-124.057373,0.084910,0.000000
62.510002,59.681618,-124.101852,-0.001423,0.003322,0.084381,265.477081,13.524048,0.843811,-124.101852,0.085500,0.000000
62.860004,60.789429,-124.101852,-0.001401,0.003346,0.084979,270.404877,13.775081,0.849794,-124.101852,0.086081,0.000000
63.210003,61.433632,-124.146332,-0.001388,0.003370,0.085587,273.270447,13.921061,0.855865,-124.146332,0.086662,0.000000
63.560001,62.512398,-124.101852,-0.001393,0.003390,0.086098,278.069031,14.165512,0.860982,-124.101852,0.087243,0.000000
63.910004,63.472374,-124.146332,-0.001358,0.003412,0.086662,282.339233,14.383045,0.866619,-124.146332,0.087833,0.000000
64.260002,63.617592,-124.190819,-0.001350,0.003426,0.087017,282.985168,14.415953,0.870174,-124.190819,0.088414,0.000000
64.610001,65.240395,-124.235298,-0.001332,0.003454,0.087737,290.203766,14.783685,0.877372,-124.235298,0.088995,0.000000
64.960007,65.906578,-124.279778,-0.001311,0.003477,0.088318,293.167114,14.934644,0.883183,-124.279778,0.089584,0.000000
65.310005,64.976006,-124.279778,-0.001285,0.003471,0.088162,289.027710,14.723774,0.881621,-124.279778,0.015478,0.000000
65.660004,64.996117,-124.324257,-0.001285,0.003487,0.088578,289.117157,14.728331,0.885784,-124.324257,294.500488,0.000000
66.010002,65.332375,-124.324257,-0.001259,0.003500,0.088908,290.612915,14.804527,0.889080,-124.324257,294.500488,0.000000
66.360001,64.400703,-124.413223,-0.001259,0.003501,0.088925,286.468628,14.593409,0.889253,-124.413223,294.500488,0.000000
66.710007,66.093498,-124.368736,-0.001233,0.003466,0.088041,293.998566,14.977000,0.880408,-124.368736,294.500488,0.000000
67.060005,65.175972,-124.457703,-0.001233,0.003491,0.088665,289.917206,14.769087,0.886651,-124.457703,294.500488,0.000000
67.410004,65.233696,-124.502182,-0.001216,0.003528,0.089619,290.173981,14.782166,0.896191,-124.502182,294.500488,0.000000
67.760002,64.510551,-124.546661,-0.001212,0.003528,0.089619,286.957275,14.618300,0.896191,-124.546661,294.500488,0.000000
68.110001,66.567162,-124.502182,-0.001203,0.003460,0.087876,296.105530,15.084334,0.878760,-124.502182,294.500488,0.000000
68.460007,65.780708,-124.502182,-0.001203,0.003464,0.087980,292.607208,14.906121,0.879800,-124.502182,294.500488,0.000000
68.810005,65.041557,-124.546661,-0.001194,0.003520,0.089411,289.319305,14.738627,0.894110,-124.546661,294.500488,0.000000
69.160004,65.505531,-124.546661,-0.001181,0.003562,0.090469,291.383148,14.843765,0.904690,-124.546661,294.500488,0.000000
69.510002,65.060539,-124.591141,-0.001186,0.003564,0.090521,289.403748,14.742929,0.905210,-124.591141,294.500488,0.000000
69.860001,65.395302,-124.591141,-0.001173,0.003572,0.090720,290.892822,14.818788,0.907205,-124.591141,294.500488,0.000000
70.210007,65.078423,-124.635628,-0.001168,0.003574,0.090781,289.483276,14.746982,0.907812,-124.635628,294.500488,0.000000
70.560005,65.215446,-124.635628,-0.001160,0.003581,0.090946,290.092804,14.778031,0.909459,-124.635628,294.500488,0.000000
70.910004,65.324547,-124.680107,-0.001155,0.003588,0.091128,290.578094,14.802753,0.911281,-124.680107,294.500488,0.000000
71.260002,65.137993,-124.680107,-0.001151,0.003588,0.091128,289.748260,14.760480,0.911281,-124.680107,294.500488,0.000000
71.610001,65.256035,-124.680107,-0.001160,0.003594,0.091293,290.273346,14.787229,0.912928,-124.680107,294.500488,0.000000
71.960007,64.999840,-124.724586,-0.001151,0.003594,0.091293,289.133728,14.729175,0.912928,-124.724586,294.500488,0.000000
72.310005,65.291405,-124.813545,-0.001138,0.003602,0.091484,290.430664,14.795244,0.914836,-124.813545,294.500488,0.000000
72.660004,65.032982,-124.769066,-0.001147,0.003602,0.091492,289.281158,14.736685,0.914923,-124.769066,294.500488,0.000000
73.010002,65.103371,-124.858032,-0.001138,0.003606,0.091596,289.594269,14.752634,0.915964,-124.858032,294.500488,0.000000
73.360001,64.844566,-124.813545,-0.001138,0.003606,0.091596,288.443024,14.693989,0.915964,-124.813545,294.500488,0.000000
73.710007,65.760597,-124.902512,-0.001121,0.003618,0.091900,292.517731,14.901565,0.918999,-124.902512,294.500488,0.000000
74.060005,65.512230,-124.946991,-0.001121,0.003618,0.091900,291.412964,14.845284,0.918999,-124.946991,294.500488,0.000000
74.410004,65.251945,-124.946991,-0.001117,0.003618,0.091909,290.255157,14.786302,0.919086,-124.946991,294.500488,0.000000
74.760002,64.978249,-124.991470,-0.001121,0.003618,0.091909,289.037689,14.724281,0.919086,-124.991470,294.500488,0.000000
75.110001,64.729134,-124.946991,-0.001125,0.003618,0.091909,287.929565,14.667831,0.919086,-124.946991,294.500488,0.000000
75.460007,64.465858,-124.991470,-0.001112,0.003618,0.091909,286.758453,14.608172,0.919086,-124.991470,294.500488,0.000000
75.810005,66.596947,-125.080437,-0.001091,0.003575,0.090799,296.238007,15.091084,0.907985,-125.080437,294.500488,0.000000
76.160004,66.284157,-125.080437,-0.001112,0.003575,0.090799,294.846649,15.020205,0.907985,-125.080437,294.500488,0.000000
76.510002,66.002647,-125.080437,-0.001095,0.003575,0.090799,293.594452,14.956414,0.907985,-125.080437,294.500488,0.000000
76.860001,65.763954,-125.124916,-0.001099,0.003585,0.091050,292.532684,14.902325,0.910500,-125.124916,294.500488,0.000000
77.210007,65.518562,-125.124916,-0.001082,0.003596,0.091336,291.441132,14.846719,0.913362,-125.124916,294.500488,0.000000
77.560005,65.306313,-125.124916,-0.001078,0.003611,0.091709,290.496979,14.798622,0.917091,-125.124916,294.500488,0.000000
77.910004,65.187141,-125.169395,-0.001099,0.003631,0.092221,289.966888,14.771618,0.922208,-125.169395,294.500488,0.000000
78.260002,65.094048,-125.169395,-0.001091,0.003637,0.092368,289.552795,14.750523,0.923682,-125.169395,294.500488,0.000000
78.610001,65.221779,-125.169395,-0.001091,0.003642,0.092498,290.120972,14.779467,0.924983,-125.169395,294.500488,0.000000
78.960007,65.105965,-125.258362,-0.001091,0.003642,0.092507,289.605804,14.753222,0.925070,-125.258362,294.500488,0.000000
79.310005,64.978249,-125.302841,-0.001095,0.003643,0.092524,289.037689,14.724281,0.925243,-125.302841,294.500488,0.000000
79.660004,65.174492,-125.258362,-0.001087,0.003647,0.092628,289.910614,14.768751,0.926284,-125.258362,294.500488,0.000000
80.010002,65.025536,-125.347321,-0.001087,0.003648,0.092654,289.248016,14.734997,0.926544,-125.347321,294.500488,0.000000
80.360001,65.296623,-125.436279,-0.001078,0.003652,0.092767,290.453888,14.796426,0.927671,-125.436279,294.500488,0.000000
80.710007,65.221031,-125.391800,-0.001099,0.003652,0.092767,290.117645,14.779297,0.927671,-125.391800,294.500488,0.000000
81.060005,65.222145,-125.436279,-0.001082,0.003655,0.092845,290.122589,14.779550,0.928452,-125.436279,294.500488,0.000000
81.410004,65.210228,-125.436279,-0.001082,0.003655,0.092845,290.069580,14.776849,0.928452,-125.436279,294.500488,0.000000
81.760002,65.086983,-125.480766,-0.001078,0.003656,0.092854,289.521362,14.748921,0.928539,-125.480766,294.500488,0.000000
82.110001,65.324928,-125.436279,-0.001074,0.003660,0.092975,290.579803,14.802840,0.929753,-125.436279,294.500488,0.000000
82.460007,65.279503,-125.480766,-0.001082,0.003660,0.092975,290.377716,14.792547,0.929753,-125.480766,294.500488,0.000000
82.810005,65.183800,-125.569725,-0.001078,0.003660,0.092975,289.952026,14.770861,0.929753,-125.569725,294.500488,0.000000
83.160004,65.078041,-125.569725,-0.001074,0.003661,0.092993,289.481598,14.746895,0.929926,-125.569725,294.500488,0.000000
83.510002,65.006554,-125.525246,-0.001074,0.003661,0.092993,289.163605,14.730696,0.929926,-125.525246,294.500488,0.000000
83.860001,65.313011,-125.658684,-0.001074,0.003667,0.093140,290.526794,14.800140,0.931400,-125.658684,294.500488,0.000000
84.210007,65.274284,-125.658684,-0.001078,0.003667,0.093140,290.354523,14.791364,0.931400,-125.658684,294.500488,0.000000
84.560005,65.194588,-125.614204,-0.001061,0.003667,0.093140,290.000000,14.773304,0.931400,-125.614204,294.500488,0.000000
84.910004,65.083626,-125.658684,-0.001082,0.003667,0.093140,289.506439,14.748160,0.931400,-125.658684,294.500488,0.000000
85.260002,65.078789,-125.747650,-0.001065,0.003669,0.093192,289.484924,14.747064,0.931921,-125.747650,294.500488,0.000000
85.610001,65.025917,-125.703171,-0.001074,0.003669,0.093192,289.249725,14.735084,0.931921,-125.703171,294.500488,0.000000
85.960007,64.964470,-125.747650,-0.001074,0.003669,0.093192,288.976410,14.721160,0.931921,-125.747650,294.500488,0.000000
86.310005,64.874352,-125.703171,-0.001074,0.003669,0.093192,288.575531,14.700738,0.931921,-125.703171,294.500488,0.000000
86.660004,64.760033,-125.792130,-0.001061,0.003669,0.093192,288.067017,14.674833,0.931921,-125.792130,294.500488,0.000000
87.010002,64.701576,-125.836609,-0.001065,0.003669,0.093192,287.806976,14.661587,0.931921,-125.836609,294.500488,0.000000
87.360001,64.608482,-125.881088,-0.001061,0.003669,0.093192,287.392883,14.640491,0.931921,-125.881088,294.500488,0.000000
87.710007,65.828377,-125.881088,-0.001061,0.003682,0.093513,292.819244,14.916924,0.935130,-125.881088,294.500488,0.000000
88.060005,65.734169,-125.881088,-0.001065,0.003682,0.093513,292.400177,14.895576,0.935130,-125.881088,294.500488,0.000000
88.410004,65.604210,-125.925575,-0.001048,0.003682,0.093513,291.822113,14.866126,0.935130,-125.925575,294.500488,0.000000
88.760002,65.549095,-125.925575,-0.001061,0.003682,0.093513,291.576935,14.853638,0.935130,-125.925575,294.500488,0.000000
89.110001,65.470528,-125.925575,-0.001061,0.003682,0.093513,291.227448,14.835834,0.935130,-125.925575,294.500488,0.000000
89.460007,65.370720,-126.014534,-0.001052,0.003682,0.093513,290.783478,14.813217,0.935130,-126.014534,294.500488,0.000000
89.810005,65.299599,-126.014534,-0.001043,0.003682,0.093513,290.467133,14.797101,0.935130,-126.014534,294.500488,0.000000
90.160004,65.213951,-126.059013,-0.001039,0.003682,0.093513,290.086151,14.777693,0.935130,-126.059013,294.500488,0.000000
90.510002,65.129433,-126.014534,-0.001043,0.003682,0.093513,289.710175,14.758540,0.935130,-126.014534,294.500488,0.000000
90.860001,65.053841,-126.103493,-0.001052,0.003682,0.093522,289.373932,14.741411,0.935216,-126.103493,294.500488,0.000000
91.210007,65.003563,-126.147980,-0.001048,0.003682,0.093522,289.150299,14.730018,0.935216,-126.147980,294.500488,0.000000
91.560005,64.929832,-126.103493,-0.001052,0.003682,0.093522,288.822327,14.713310,0.935216,-126.103493,294.500488,0.000000
91.910004,64.841209,-126.192459,-0.001052,0.003682,0.093522,288.428101,14.693229,0.935216,-126.192459,294.500488,0.000000
92.260002,64.758171,-126.236938,-0.001039,0.003682,0.093522,288.058746,14.674412,0.935216,-126.236938,294.500488,0.000000
92.610001,64.695992,-126.236938,-0.001052,0.003682,0.093522,287.782135,14.660321,0.935216,-126.236938,294.500488,0.000000
92.960007,64.617424,-126.236938,-0.001043,0.003682,0.093522,287.432648,14.642518,0.935216,-126.236938,294.500488,0.000000
93.310005,66.149361,-126.281418,-0.001030,0.003698,0.093921,294.247040,14.989659,0.939205,-126.281418,294.500488,0.000000
93.660004,65.995934,-126.236938,-0.001030,0.003686,0.093626,293.564575,14.954893,0.936257,-126.236938,294.500488,0.000000
94.010002,65.926674,-126.325897,-0.001052,0.003686,0.093626,293.256500,14.939198,0.936257,-126.325897,294.500488,0.000000
94.360008,65.827263,-126.325897,-0.001026,0.003686,0.093626,292.814301,14.916672,0.936257,-126.325897,294.500488,0.000000
94.710007,65.761711,-126.370384,-0.001056,0.003686,0.093626,292.522705,14.901816,0.936257,-126.370384,294.500488,0.000000
95.060005,65.638466,-126.414864,-0.001043,0.003686,0.093626,291.974487,14.873889,0.936257,-126.414864,294.500488,0.000000
95.410004,65.575905,-126.370384,-0.001030,0.003686,0.093626,291.696198,14.859713,0.936257,-126.370384,294.500488,0.000000
95.760002,65.528618,-126.414864,-0.001026,0.003686,0.093626,291.485840,14.848997,0.936257,-126.414864,294.500488,0.000000
96.110008,65.451530,-126.459343,-0.001035,0.003686,0.093626,291.142944,14.831529,0.936257,-126.459343,294.500488,0.000000
96.460007,65.351738,-126.548309,-0.001039,0.003686,0.093626,290.699036,14.808915,0.936257,-126.548309,294.500488,0.000000
96.810005,65.292900,-126.548309,-0.001030,0.003686,0.093626,290.437317,14.795583,0.936257,-126.548309,294.500488,0.000000
97.160004,65.240028,-126.548309,-0.001035,0.003686,0.093626,290.202148,14.783602,0.936257,-126.548309,294.500488,0.000000
97.510002,65.175606,-126.592789,-0.001035,0.003686,0.093626,289.915588,14.769003,0.936257,-126.592789,294.500488,0.000000
97.860008,65.079536,-126.548309,-0.001030,0.003686,0.093626,289.488251,14.747233,0.936257,-126.548309,294.500488,0.000000
98.210007,65.027031,-126.592789,-0.001026,0.003686,0.093626,289.254669,14.735335,0.936257,-126.592789,294.500488,0.000000
98.560005,64.969688,-126.726227,-0.001035,0.003686,0.093626,288.999603,14.722342,0.936257,-126.726227,294.500488,0.000000
98.910004,64.900795,-126.681747,-0.001026,0.003686,0.093626,288.693146,14.706731,0.936257,-126.681747,294.500488,0.000000
99.260002,64.828560,-126.681747,-0.001022,0.003686,0.093626,288.371826,14.690362,0.936257,-126.681747,294.500488,0.000000
99.610008,64.752586,-126.770714,-0.001030,0.003686,0.093634,288.033875,14.673146,0.936343,-126.770714,294.500488,0.000000
99.960007,65.846626,-126.770714,-0.001043,0.003707,0.094146,292.900421,14.921059,0.941460,-126.770714,294.500488,0.000000
100.310005,65.832848,-126.815193,-0.001022,0.003707,0.094146,292.839142,14.917937,0.941460,-126.815193,294.500488,0.000000
100.660004,65.794121,-126.859673,-0.001030,0.003707,0.094146,292.666870,14.909161,0.941460,-126.859673,294.500488,0.000000
101.010002,65.756874,-126.815193,-0.001035,0.003707,0.094146,292.501190,14.900721,0.941460,-126.815193,294.500488,0.000000
101.360008,65.720757,-126.904152,-0.001018,0.003707,0.094146,292.340515,14.892536,0.941460,-126.904152,294.500488,0.000000
101.710007,65.648888,-126.904152,-0.001026,0.003707,0.094146,292.020844,14.876251,0.941460,-126.904152,294.500488,0.000000
102.060005,65.596764,-126.904152,-0.001035,0.003707,0.094146,291.788971,14.864439,0.941460,-126.904152,294.500488,0.000000
102.410004,65.571068,-126.948631,-0.001026,0.003707,0.094146,291.674683,14.858616,0.941460,-126.948631,294.500488,0.000000
102.760002,65.534950,-126.904152,-0.001030,0.003707,0.094146,291.514008,14.850431,0.941460,-126.904152,294.500488,0.000000
103.110008,65.490257,-126.993118,-0.001035,0.003707,0.094146,291.315216,14.840305,0.941460,-126.993118,294.500488,0.000000
103.460007,65.436638,-127.037598,-0.001026,0.003707,0.094146,291.076691,14.828155,0.941460,-127.037598,294.500488,0.000000
103.810005,65.373329,-126.993118,-0.001022,0.003707,0.094146,290.795105,14.813807,0.941460,-126.993118,294.500488,0.000000
104.160004,65.315620,-127.082077,-0.001018,0.003707,0.094146,290.538391,14.800731,0.941460,-127.082077,294.500488,0.000000
104.510002,65.283226,-127.126556,-0.001018,0.003707,0.094146,290.394287,14.793390,0.941460,-127.126556,294.500488,0.000000
104.860008,65.245979,-127.082077,-0.001022,0.003707,0.094155,290.228607,14.784950,0.941547,-127.082077,294.500488,0.000000
105.210007,65.208366,-127.171036,-0.001022,0.003707,0.094155,290.061310,14.776427,0.941547,-127.171036,294.500488,0.000000
105.560005,65.156609,-127.126556,-0.001018,0.003707,0.094163,289.831085,14.764699,0.941634,-127.126556,294.500488,0.000000
105.910004,65.124596,-127.215523,-0.001013,0.003708,0.094172,289.688660,14.757444,0.941720,-127.215523,294.500488,0.000000
106.260002,65.091454,-127.171036,-0.001009,0.003708,0.094172,289.541260,14.749934,0.941720,-127.171036,294.500488,0.000000
106.610008,65.052345,-127.260002,-0.001009,0.003708,0.094172,289.367279,14.741073,0.941720,-127.260002,294.500488,0.000000
106.960007,65.032616,-127.260002,-0.001013,0.003708,0.094172,289.279510,14.736601,0.941720,-127.260002,294.500488,0.000000
107.310005,64.996117,-127.260002,-0.001013,0.003709,0.094198,289.117157,14.728331,0.941980,-127.260002,294.500488,0.000000
107.660004,64.974525,-127.304482,-0.001026,0.003709,0.094198,289.021118,14.723438,0.941980,-127.304482,294.500488,0.000000
108.010002,64.959251,-127.348961,-0.001026,0.003709,0.094198,288.953186,14.719976,0.941980,-127.348961,294.500488,0.000000
108.360008,64.929100,-127.393440,-0.001009,0.003709,0.094198,288.819061,14.713144,0.941980,-127.393440,294.500488,0.000000
108.710007,64.888512,-127.393440,-0.001009,0.003709,0.094198,288.638519,14.703947,0.941980,-127.393440,294.500488,0.000000
109.060005,64.847542,-127.437927,-0.001018,0.003709,0.094198,288.456268,14.694663,0.941980,-127.437927,294.500488,0.000000
109.410004,64.808067,-127.393440,-0.001022,0.003709,0.094198,288.280670,14.685718,0.941980,-127.393440,294.500488,0.000000
109.760002,64.781639,-127.482407,-0.001009,0.003709,0.094207,288.163116,14.679729,0.942067,-127.482407,294.500488,0.000000
110.110008,65.770287,-127.437927,-0.001009,0.003722,0.094528,292.560852,14.903760,0.945276,-127.437927,294.500488,0.000000
110.460007,65.858528,-127.526886,-0.001000,0.003722,0.094528,292.953369,14.923756,0.945276,-127.526886,294.500488,0.000000
110.810005,65.835823,-127.571365,-0.000996,0.003722,0.094528,292.852356,14.918611,0.945276,-127.571365,294.500488,0.000000
111.160004,65.867851,-127.571365,-0.001013,0.003722,0.094528,292.994843,14.925869,0.945276,-127.571365,294.500488,0.000000
111.510002,65.857414,-127.571365,-0.001013,0.003722,0.094528,292.948395,14.923503,0.945276,-127.571365,294.500488,0.000000
111.860008,65.845879,-127.615852,-0.001005,0.003722,0.094528,292.897095,14.920889,0.945276,-127.615852,294.500488,0.000000
112.210007,65.788902,-127.615852,-0.000996,0.003722,0.094528,292.643646,14.907978,0.945276,-127.615852,294.500488,0.000000
112.560005,65.767311,-127.660332,-0.001009,0.003722,0.094528,292.547607,14.903086,0.945276,-127.660332,294.500488,0.000000
112.910004,65.763206,-127.704811,-0.001018,0.003722,0.094528,292.529358,14.902155,0.945276,-127.704811,294.500488,0.000000
113.260002,65.695061,-127.704811,-0.000996,0.003722,0.094528,292.226227,14.886714,0.945276,-127.704811,294.500488,0.000000
113.610008,65.680916,-127.749290,-0.001009,0.003722,0.094528,292.163300,14.883508,0.945276,-127.749290,294.500488,0.000000
113.960007,65.642189,-127.749290,-0.001005,0.003722,0.094528,291.991028,14.874733,0.945276,-127.749290,294.500488,0.000000
114.310005,65.610909,-127.793770,-0.001009,0.003722,0.094528,291.851898,14.867644,0.945276,-127.793770,294.500488,0.000000
114.660004,65.580376,-127.838257,-0.000996,0.003722,0.094528,291.716095,14.860725,0.945276,-127.838257,294.500488,0.000000
115.010002,65.569954,-127.838257,-0.001000,0.003722,0.094528,291.669708,14.858364,0.945276,-127.838257,294.500488,0.000000
115.360008,65.530479,-127.927216,-0.000996,0.003722,0.094528,291.494141,14.849419,0.945276,-127.927216,294.500488,0.000000
115.710007,65.506645,-127.882736,-0.001018,0.003722,0.094528,291.388123,14.844018,0.945276,-127.882736,294.500488,0.000000
116.060005,65.473503,-127.927216,-0.001000,0.003722,0.094528,291.240692,14.836508,0.945276,-127.927216,294.500488,0.000000
116.410004,65.441856,-127.927216,-0.001005,0.003722,0.094528,291.099915,14.829336,0.945276,-127.927216,294.500488,0.000000
116.760002,65.389351,-127.971695,-0.001005,0.003722,0.094528,290.866364,14.817439,0.945276,-127.971695,294.500488,0.000000
117.110008,65.375572,-128.016174,-0.001000,0.003722,0.094528,290.805084,14.814316,0.945276,-128.016174,294.500488,0.000000
117.460007,65.334984,-128.016174,-0.000996,0.003722,0.094528,290.624512,14.805119,0.945276,-128.016174,294.500488,0.000000
117.810005,65.325676,-128.060654,-0.000987,0.003722,0.094528,290.583130,14.803010,0.945276,-128.060654,294.500488,0.000000
118.160004,65.289177,-128.016174,-0.001000,0.003722,0.094528,290.420776,14.794740,0.945276,-128.016174,294.500488,0.000000
118.510002,65.272789,-128.105133,-0.001000,0.003722,0.094528,290.347870,14.791025,0.945276,-128.105133,294.500488,0.000000
118.860008,65.226250,-128.060654,-0.001018,0.003722,0.094528,290.140839,14.780479,0.945276,-128.060654,294.500488,0.000000
119.210007,65.208000,-128.149612,-0.001005,0.003722,0.094528,290.059662,14.776343,0.945276,-128.149612,294.500488,0.000000
119.560005,65.165550,-128.149612,-0.001000,0.003722,0.094528,289.870850,14.766726,0.945276,-128.149612,294.500488,0.000000
119.910004,65.130913,-128.105133,-0.000992,0.003722,0.094536,289.716766,14.758876,0.945363,-128.105133,294.500488,0.000000
120.260002,65.090706,-128.194107,-0.000996,0.003722,0.094536,289.537933,14.749764,0.945363,-128.194107,294.500488,0.000000
120.610008,65.062782,-128.238586,-0.001013,0.003722,0.094536,289.413696,14.743437,0.945363,-128.238586,294.500488,0.000000
120.960007,65.043785,-128.283066,-0.000996,0.003722,0.094536,289.329193,14.739132,0.945363,-128.283066,294.500488,0.000000
121.310005,65.005806,-128.238586,-0.001009,0.003722,0.094536,289.160278,14.730526,0.945363,-128.238586,294.500488,0.000000
121.660004,64.991646,-128.327545,-0.000992,0.003722,0.094536,289.097290,14.727318,0.945363,-128.327545,294.500488,0.000000
122.010002,64.968941,-128.327545,-0.001009,0.003722,0.094536,288.996277,14.722173,0.945363,-128.327545,294.500488,0.000000
122.360008,64.935051,-128.372025,-0.001005,0.003722,0.094536,288.845520,14.714493,0.945363,-128.372025,294.500488,0.000000
122.710007,64.914940,-128.327545,-0.001013,0.003722,0.094536,288.756073,14.709935,0.945363,-128.327545,294.500488,0.000000
123.060005,64.871010,-128.416504,-0.001005,0.003722,0.094536,288.560669,14.699981,0.945363,-128.416504,294.500488,0.000000
123.410004,64.832649,-128.460983,-0.001000,0.003722,0.094545,288.390015,14.691288,0.945449,-128.460983,294.500488,0.000000
123.760002,64.817375,-128.460983,-0.001013,0.003722,0.094545,288.322083,14.687827,0.945449,-128.460983,294.500488,0.000000
124.110008,64.791695,-128.460983,-0.001000,0.003722,0.094545,288.207855,14.682008,0.945449,-128.460983,294.500488,0.000000
124.460007,64.773811,-128.460983,-0.000996,0.003722,0.094545,288.128296,14.677956,0.945449,-128.460983,294.500488,0.000000
124.810005,64.744392,-128.549942,-0.000992,0.003722,0.094545,287.997437,14.671289,0.945449,-128.549942,294.500488,0.000000
125.160004,64.716103,-128.594437,-0.001000,0.003722,0.094545,287.871613,14.664879,0.945449,-128.594437,294.500488,0.000000
125.510010,64.687050,-128.594437,-0.001005,0.003722,0.094545,287.742371,14.658296,0.945449,-128.594437,1681.640991,0.000000
125.860008,66.065208,-128.638916,-0.001000,0.003734,0.094848,293.872711,14.970590,0.948485,-128.638916,0.094762,0.000000
126.210007,65.919609,-128.638916,-0.001000,0.003720,0.094476,293.225067,14.937597,0.944756,-128.638916,0.094181,0.000000
126.560005,65.872688,-128.638916,-0.001005,0.003703,0.094059,293.016357,14.926965,0.940593,-128.638916,0.093600,0.000000
126.910004,65.779594,-128.727875,-0.001000,0.003682,0.093522,292.602264,14.905869,0.935216,-128.727875,0.093010,0.000000
127.260010,65.745705,-128.683395,-0.000992,0.003662,0.093010,292.451508,14.898190,0.930099,-128.683395,0.092429,0.000000
127.610008,65.698036,-128.772354,-0.000992,0.003640,0.092464,292.239471,14.887387,0.924636,-128.772354,0.091848,0.000000
127.960007,65.674950,-128.772354,-0.000992,0.003616,0.091848,292.136780,14.882156,0.918479,-128.772354,0.091258,0.000000
128.310013,65.584846,-128.816833,-0.000996,0.003592,0.091232,291.735962,14.861739,0.912321,-128.816833,0.090677,0.000000
128.660004,65.583717,-128.772354,-0.000992,0.003574,0.090772,291.730957,14.861483,0.907725,-128.772354,0.090096,0.000000
129.010010,65.418770,-128.772354,-0.000992,0.003547,0.090087,290.997223,14.824105,0.900874,-128.772354,0.089515,0.000000
129.360001,65.364021,-128.816833,-0.000987,0.003529,0.089628,290.753693,14.811699,0.896278,-128.816833,0.088925,0.000000
129.710007,65.245232,-128.905792,-0.000979,0.003512,0.089203,290.225281,14.784781,0.892028,-128.905792,0.088344,0.000000
130.060013,64.582787,-128.950272,-0.000996,0.003484,0.088483,287.278595,14.634668,0.884830,-128.950272,0.087763,0.000000
130.410004,63.803032,-128.950272,-0.000992,0.003461,0.087919,283.810059,14.457974,0.879193,-128.950272,0.087182,0.000000
130.760010,62.850136,-128.994751,-0.000979,0.003441,0.087399,279.571381,14.242044,0.873990,-128.994751,0.086592,0.000000
131.110001,61.798561,-128.950272,-0.000979,0.003421,0.086887,274.893738,14.003755,0.868873,-128.950272,0.086011,0.000000
131.460007,60.711601,-129.039246,-0.000974,0.003400,0.086350,270.058685,13.757445,0.863497,-129.039246,0.085430,0.000000
131.810013,58.803566,-129.039246,-0.000966,0.003377,0.085786,261.571320,13.325079,0.857860,-129.039246,0.084849,0.000000
132.160004,57.190079,-129.128204,-0.000996,0.003358,0.085292,254.394180,12.959457,0.852916,-129.128204,0.084260,0.000000
132.510010,55.387794,-129.039246,-0.000979,0.003336,0.084737,246.377213,12.551053,0.847366,-129.039246,0.083679,0.000000
132.860001,53.457413,-129.128204,-0.000987,0.003316,0.084234,237.790451,12.113623,0.842336,-129.128204,0.083098,0.000000
133.210007,51.099922,-129.172684,-0.000992,0.003290,0.083557,227.303802,11.579408,0.835572,-129.172684,0.082508,0.000000
133.560013,49.230614,-129.172684,-0.000987,0.003274,0.083167,218.988708,11.155817,0.831669,-129.172684,0.081927,0.000000
133.910004,46.141785,-129.217163,-0.000979,0.003244,0.082386,205.248917,10.455878,0.823864,-129.217163,0.081346,0.000000
134.260010,43.162437,-129.261642,-0.000992,0.003214,0.081641,191.996109,9.780748,0.816406,-129.261642,0.080765,0.000000
134.610001,41.116989,-129.261642,-0.000996,0.003195,0.081146,182.897507,9.317243,0.811463,-129.261642,0.080175,0.000000
134.960007,38.674973,-129.306122,-0.000974,0.003175,0.080635,172.034866,8.763874,0.806346,-129.306122,0.079594,0.000000
135.310013,37.261078,-129.350601,-0.000974,0.003162,0.080322,165.745560,8.443481,0.803224,-129.350601,0.079013,0.000000
135.660004,34.374817,-129.306122,-0.001005,0.003131,0.079525,152.906830,7.789445,0.795246,-129.306122,0.078432,0.000000
136.010010,31.616653,-129.306122,-0.000979,0.003106,0.078900,140.637894,7.164436,0.789002,-129.306122,0.077842,0.000000
136.360001,29.469551,-129.439575,-0.000987,0.003084,0.078328,131.087112,6.677896,0.783278,-129.439575,0.077261,0.000000
136.710007,27.217445,-129.350601,-0.000992,0.003064,0.077825,121.069244,6.167561,0.778248,-129.350601,0.076680,0.000000
137.060013,24.906128,-129.484055,-0.000996,0.003042,0.077278,110.787987,5.643809,0.772785,-129.484055,0.076090,0.000000
137.410004,21.686966,-129.395081,-0.001000,0.003013,0.076541,96.468445,4.914337,0.765413,-129.395081,0.075509,0.000000
137.760010,19.568169,-129.484055,-0.000996,0.002991,0.075978,87.043564,4.434210,0.759776,-129.484055,0.074928,0.000000
138.110001,16.138992,-129.528534,-0.001018,0.002962,0.075232,71.789825,3.657148,0.752318,-129.528534,0.074347,0.000000
138.460007,14.250694,-129.573013,-0.001035,0.002945,0.074798,63.390255,3.229254,0.747982,-129.573013,0.073758,0.000000
138.810013,11.691002,-129.528534,-0.001022,0.002918,0.074122,52.004173,2.649219,0.741218,-129.528534,0.073176,0.000000
139.160004,9.581512,-129.573013,-0.001030,0.002896,0.073558,42.620697,2.171202,0.735581,-129.573013,0.072595,0.000000
139.510010,7.219185,-129.617493,-0.001035,0.002876,0.073038,32.112537,1.635891,0.730377,-129.617493,0.072014,0.000000
139.860001,5.030380,-129.617493,-0.001030,0.002855,0.072517,22.376249,1.139900,0.725174,-129.617493,0.071425,0.000000
140.210007,2.663208,-129.661972,-0.001039,0.002831,0.071910,11.846540,0.603492,0.719104,-129.661972,0.070844,0.000000
140.560013,1.271652,-129.706451,-0.001043,0.002813,0.071442,5.656591,0.288161,0.714420,-129.706451,0.070263,0.000000
140.910004,-1.573650,-129.706451,-0.001061,0.002782,0.070670,-6.999947,-0.356594,0.706702,-129.706451,0.069682,0.000000
141.260010,-0.526535,-129.706451,-0.001099,0.002762,0.070159,-2.342145,-0.119315,0.701585,-129.706451,0.069092,0.000000
141.610001,-0.256943,-129.706451,-0.001130,0.002736,0.069499,-1.142938,-0.058224,0.694994,-129.706451,0.068511,0.000000
141.960007,-0.149323,-129.795410,-0.001164,0.002714,0.068944,-0.664220,-0.033837,0.689444,-129.795410,0.067930,0.000000
142.310013,-0.056602,-129.795410,-0.001207,0.002695,0.068441,-0.251780,-0.012826,0.684415,-129.795410,0.067340,0.000000
142.660004,0.020477,-129.839890,-0.001233,0.002671,0.067843,0.091088,0.004640,0.678431,-129.839890,0.066759,0.000000
143.010010,0.003349,-129.884384,-0.001263,0.002654,0.067418,0.014898,0.000759,0.674181,-129.884384,0.066178,0.000000
143.360001,-0.005219,-129.839890,-0.001293,0.002625,0.066681,-0.023213,-0.001183,0.666810,-129.839890,0.065597,0.000000
143.710007,-0.000000,-129.928864,-0.001345,0.002605,0.066178,-0.000000,-0.000000,0.661780,-129.928864,0.065007,0.000000
144.060013,-0.076714,-129.884384,-0.001380,0.002578,0.065476,-0.341239,-0.017384,0.654755,-129.884384,0.064426,0.000000
144.410004,-0.043945,-129.973343,-0.001406,0.002551,0.064799,-0.195479,-0.009958,0.647991,-129.973343,0.063845,0.000000
144.760010,-0.030540,-130.017822,-0.001440,0.002531,0.064296,-0.135851,-0.006921,0.642961,-130.017822,0.063264,0.000000
145.000000,-0.011917,-129.973343,-0.001479,0.002529,0.064235,-0.053010,-0.002700,0.642354,-129.973343,0.064097,0.000000