File: Data/compression 33/AutoNoHeating-12-33-reverse-1-3_11152024_175623.csv
Time (sec),S:Load (lbs),S:HL1 (DIM),S:LVDT (in),S:Position (in),Ch:Position (mm),Ch:Load (N),Ch:Stress (MPa),Ch:Strain (mm/mm),Ch:HL1 (DIM),Set Point (),Cycles ()
0.110000,-0.132935,-679.090698,-0.012322,-0.007176,-0.182265,-0.591322,-0.030123,-1.822648,-679.090698,-0.182022,0.000000
0.500000,-0.058090,-679.046204,-0.012322,-0.007119,-0.180817,-0.258398,-0.013163,-1.808166,-679.046204,-0.180062,0.000000
0.890000,-0.128471,-679.090698,-0.012184,-0.006877,-0.174668,-0.571469,-0.029112,-1.746679,-679.090698,-0.173575,0.000000
1.280000,-0.121025,-679.179626,-0.011921,-0.006626,-0.168294,-0.538346,-0.027425,-1.682938,-679.179626,-0.167071,0.000000
1.670000,-0.084160,-679.179626,-0.011680,-0.006372,-0.161859,-0.374362,-0.019071,-1.618590,-679.179626,-0.160567,0.000000
2.060000,-0.082664,-679.179626,-0.011404,-0.006116,-0.155355,-0.367710,-0.018732,-1.553548,-679.179626,-0.154080,0.000000
2.450000,-0.095703,-679.179626,-0.011141,-0.005858,-0.148799,-0.425709,-0.021687,-1.487986,-679.179626,-0.147576,0.000000
2.840000,-0.124748,-679.135132,-0.010869,-0.005605,-0.142364,-0.554908,-0.028268,-1.423638,-679.135132,-0.141089,0.000000
3.230000,-0.163101,-679.224121,-0.010615,-0.005352,-0.135946,-0.725510,-0.036959,-1.359463,-679.224121,-0.134585,0.000000
3.620000,-0.078201,-679.224121,-0.010352,-0.005096,-0.129442,-0.347857,-0.017721,-1.294421,-679.224121,-0.128081,0.000000
4.010000,-0.084160,-679.179626,-0.010089,-0.004835,-0.122808,-0.374362,-0.019071,-1.228078,-679.179626,-0.121594,0.000000
4.400000,-0.058464,-679.179626,-0.009822,-0.004584,-0.116442,-0.260061,-0.013248,-1.164424,-679.179626,-0.115090,0.000000
4.790000,-0.093094,-679.224121,-0.009559,-0.004328,-0.109930,-0.414102,-0.021095,-1.099295,-679.224121,-0.108603,0.000000
5.180000,-0.143738,-679.313110,-0.009296,-0.004066,-0.103287,-0.639378,-0.032571,-1.032866,-679.313110,-0.102098,0.000000
5.570000,-0.133682,-679.268616,-0.009037,-0.003817,-0.096956,-0.594648,-0.030293,-0.969558,-679.268616,-0.095594,0.000000
5.960001,-0.061440,-679.313110,-0.008778,-0.003558,-0.090374,-0.273297,-0.013922,-0.903736,-679.313110,-0.089107,0.000000
6.350000,-0.112457,-679.224121,-0.008494,-0.003305,-0.083956,-0.500235,-0.025483,-0.839561,-679.224121,-0.082603,0.000000
6.740000,-0.067024,-679.268616,-0.008222,-0.003049,-0.077435,-0.298139,-0.015188,-0.774346,-679.268616,-0.076116,0.000000
7.130000,-0.106499,-679.357544,-0.007998,-0.002803,-0.071191,-0.473730,-0.024133,-0.711906,-679.357544,-0.069612,0.000000
7.520000,-0.152672,-679.268616,-0.007722,-0.002543,-0.064591,-0.679118,-0.034596,-0.645910,-679.268616,-0.063108,0.000000
7.910000,-0.068520,-679.268616,-0.007459,-0.002287,-0.058087,-0.304790,-0.015527,-0.580868,-679.268616,-0.056621,0.000000
8.300000,-0.045059,-679.357544,-0.007179,-0.002018,-0.051262,-0.200433,-0.010211,-0.512617,-679.357544,-0.050117,0.000000
8.690001,-0.071121,-679.313110,-0.006924,-0.001772,-0.045018,-0.316363,-0.016116,-0.450177,-679.313110,-0.043613,0.000000
9.080001,-0.082664,-679.357544,-0.006687,-0.001517,-0.038531,-0.367710,-0.018732,-0.385308,-679.357544,-0.037126,0.000000
9.470000,-0.112831,-679.313110,-0.006407,-0.001252,-0.031792,-0.501898,-0.025568,-0.317925,-679.313110,-0.030622,0.000000
9.860001,-0.106873,-679.357544,-0.006148,-0.001006,-0.025557,-0.475393,-0.024218,-0.255571,-679.357544,-0.024135,0.000000
10.250001,-0.058090,-679.402039,-0.005881,-0.000747,-0.018966,-0.258398,-0.013163,-0.189662,-679.402039,-0.017631,0.000000
10.640000,-0.037613,-679.357544,-0.005635,-0.000492,-0.012497,-0.167311,-0.008523,-0.124967,-679.357544,-0.011127,0.000000
11.030001,-0.055855,-679.446533,-0.005364,-0.000237,-0.006019,-0.248455,-0.012657,-0.060186,-679.446533,-0.004640,0.000000
11.420000,0.080063,-679.357544,-0.005217,0.000007,0.000173,0.356137,0.018143,0.001735,-679.357544,0.000399,0.000000
11.810000,0.056602,-679.446533,-0.005213,0.000007,0.000173,0.251780,0.012826,0.001735,-679.446533,0.000468,0.000000
12.200001,0.131447,-679.402039,-0.005208,0.000007,0.000182,0.584705,0.029786,0.001821,-679.402039,0.001119,0.000000
12.590000,0.191025,-679.402039,-0.005208,0.000027,0.000676,0.849721,0.043287,0.006764,-679.402039,0.001769,0.000000
12.980000,0.409607,-679.491028,-0.005191,0.000056,0.001431,1.822023,0.092818,0.014309,-679.491028,0.002420,0.000000
13.370001,0.486687,-679.446533,-0.005174,0.000070,0.001778,2.164891,0.110285,0.017778,-679.446533,0.003070,0.000000
13.760000,0.745491,-679.446533,-0.005139,0.000104,0.002654,3.316110,0.168931,0.026537,-679.446533,0.003720,0.000000
14.150001,0.890343,-679.446533,-0.005122,0.000125,0.003165,3.960442,0.201755,0.031654,-679.446533,0.004371,0.000000
14.540001,1.343895,-679.446533,-0.005083,0.000155,0.003946,5.977943,0.304531,0.039459,-679.446533,0.005013,0.000000
14.930000,1.532684,-679.535461,-0.005062,0.000179,0.004544,6.817720,0.347311,0.045443,-679.535461,0.005663,0.000000
15.320001,2.020493,-679.446533,-0.005040,0.000213,0.005403,8.987599,0.457850,0.054028,-679.446533,0.006313,0.000000
15.710001,2.340729,-679.535461,-0.005014,0.000238,0.006036,10.412082,0.530417,0.060359,-679.535461,0.006964,0.000000
16.100000,2.712357,-679.535461,-0.004988,0.000263,0.006678,12.065165,0.614629,0.066776,-679.535461,0.007614,0.000000
16.490002,3.028503,-679.491028,-0.004954,0.000286,0.007267,13.471456,0.686269,0.072674,-679.491028,0.008265,0.000000
16.880001,3.346512,-679.579956,-0.004937,0.000306,0.007770,14.886028,0.758330,0.077704,-679.579956,0.008915,0.000000
17.270000,3.461571,-679.535461,-0.004945,0.000323,0.008204,15.397836,0.784403,0.082040,-679.535461,0.009566,0.000000
17.660002,3.994812,-679.535461,-0.004911,0.000354,0.009002,17.769812,0.905237,0.090018,-679.535461,0.010216,0.000000
18.050001,4.296806,-679.535461,-0.004881,0.000379,0.009635,19.113150,0.973670,0.096349,-679.535461,0.010866,0.000000
18.440001,5.063522,-679.579956,-0.004859,0.000410,0.010415,22.523672,1.147411,0.104154,-679.579956,0.011517,0.000000
18.830002,5.287689,-679.579956,-0.004816,0.000436,0.011074,23.520817,1.198207,0.110745,-679.579956,0.012167,0.000000
19.220001,5.586700,-679.535461,-0.004807,0.000465,0.011820,24.850885,1.265964,0.118203,-679.535461,0.012818,0.000000
19.610001,5.914391,-679.668945,-0.004773,0.000483,0.012280,26.308523,1.340220,0.122799,-679.668945,0.013468,0.000000
20.000000,6.336288,-679.579956,-0.004769,0.000509,0.012939,28.185219,1.435823,0.129390,-679.579956,0.014118,0.000000
20.390001,6.919426,-679.624451,-0.004738,0.000537,0.013633,30.779144,1.567964,0.136328,-679.624451,0.014769,0.000000
20.780001,7.173752,-679.579956,-0.004704,0.000563,0.014301,31.910442,1.625595,0.143006,-679.579956,0.015419,0.000000
21.170000,7.504051,-679.624451,-0.004704,0.000586,0.014882,33.379688,1.700442,0.148816,-679.624451,0.016070,0.000000
21.560001,7.658211,-679.624451,-0.004700,0.000612,0.015541,34.065422,1.735375,0.155407,-679.624451,0.016720,0.000000
21.950001,7.944565,-679.624451,-0.004635,0.000629,0.015974,35.339188,1.800264,0.159743,-679.624451,0.017371,0.000000
22.340000,8.831184,-679.713440,-0.004622,0.000667,0.016937,39.283070,2.001175,0.169369,-679.713440,0.018021,0.000000
22.730001,8.947365,-679.624451,-0.004613,0.000689,0.017509,39.799866,2.027502,0.175093,-679.624451,0.018671,0.000000
23.120001,9.148071,-679.713440,-0.004592,0.000712,0.018082,40.692654,2.072983,0.180817,-679.713440,0.019322,0.000000
23.510000,9.655617,-679.713440,-0.004553,0.000747,0.018966,42.950329,2.187994,0.189662,-679.713440,0.019964,0.000000
23.900002,9.820580,-679.668945,-0.004536,0.000766,0.019452,43.684120,2.225375,0.194519,-679.668945,0.020614,0.000000
24.290001,10.502396,-679.757874,-0.004497,0.000797,0.020232,46.716988,2.379877,0.202324,-679.757874,0.021264,0.000000
24.680000,10.570168,-679.713440,-0.004467,0.000817,0.020744,47.018452,2.395234,0.207440,-679.713440,0.021915,0.000000
25.070002,10.465157,-679.713440,-0.004480,0.000832,0.021134,46.551342,2.371438,0.211343,-679.713440,0.022565,0.000000
25.460001,11.381935,-679.846863,-0.004424,0.000874,0.022201,50.629375,2.579183,0.222010,-679.846863,0.023216,0.000000
25.850000,11.468697,-679.713440,-0.004411,0.000897,0.022782,51.015312,2.598844,0.227820,-679.713440,0.023866,0.000000
26.240002,11.901024,-679.757874,-0.004398,0.000925,0.023502,52.938396,2.696810,0.235018,-679.757874,0.024516,0.000000
26.630001,11.940491,-679.713440,-0.004363,0.000947,0.024048,53.113956,2.705754,0.240482,-679.713440,0.025167,0.000000
27.020000,12.528099,-679.757874,-0.004342,0.000973,0.024716,55.727768,2.838908,0.247159,-679.757874,0.025817,0.000000
27.410002,12.784294,-679.802368,-0.004320,0.000998,0.025349,56.867382,2.896962,0.253490,-679.802368,0.026468,0.000000
27.800001,12.744072,-679.713440,-0.004307,0.001015,0.025783,56.688465,2.887848,0.257826,-679.713440,0.027118,0.000000
28.190001,13.577446,-679.846863,-0.004299,0.001050,0.026659,60.395496,3.076693,0.266585,-679.846863,0.027769,0.000000
28.580002,13.512650,-679.802368,-0.004260,0.001069,0.027153,60.107265,3.062010,0.271528,-679.802368,0.028419,0.000000
28.970001,13.767357,-679.846863,-0.004238,0.001095,0.027803,61.240261,3.119728,0.278033,-679.846863,0.029069,0.000000
29.360001,14.331497,-679.846863,-0.004225,0.001127,0.028627,63.749683,3.247564,0.286271,-679.846863,0.029720,0.000000
29.750002,14.585831,-679.846863,-0.004208,0.001153,0.029278,64.881012,3.305197,0.292775,-679.846863,0.030370,0.000000
30.140001,14.892662,-679.846863,-0.004182,0.001180,0.029963,66.245872,3.374726,0.299627,-679.846863,0.031021,0.000000
30.530001,15.021507,-679.846863,-0.004139,0.001205,0.030596,66.819000,3.403922,0.305957,-679.846863,0.031671,0.000000
30.920002,15.063210,-679.891357,-0.004126,0.001226,0.031151,67.004501,3.413372,0.311507,-679.891357,0.032322,0.000000
31.310001,15.729012,-679.891357,-0.004100,0.001258,0.031949,69.966141,3.564245,0.319486,-679.891357,0.032972,0.000000
31.700001,15.806091,-679.891357,-0.004092,0.001279,0.032486,70.309006,3.581712,0.324863,-679.891357,0.033622,0.000000
32.090000,16.145325,-679.935791,-0.004074,0.001304,0.033128,71.817993,3.658583,0.331280,-679.935791,0.034273,0.000000
32.480003,16.275284,-679.935791,-0.004036,0.001331,0.033796,72.396080,3.688032,0.337958,-679.935791,0.034915,0.000000
32.870003,16.353111,-679.891357,-0.004027,0.001349,0.034264,72.742271,3.705668,0.342641,-679.891357,0.035565,0.000000
33.260002,16.833839,-679.935791,-0.004005,0.001377,0.034975,74.880661,3.814603,0.349752,-679.935791,0.036215,0.000000
33.650002,17.374901,-679.891357,-0.003967,0.001409,0.035799,77.287422,3.937209,0.357991,-679.891357,0.036866,0.000000
34.040001,17.372665,-679.980286,-0.003967,0.001432,0.036380,77.277473,3.936702,0.363801,-679.980286,0.037516,0.000000
34.430000,17.678009,-679.935791,-0.003949,0.001457,0.037005,78.635712,4.005894,0.370045,-679.935791,0.038167,0.000000
34.820004,17.745033,-679.935791,-0.003906,0.001478,0.037534,78.933853,4.021082,0.375335,-679.935791,0.038817,0.000000
35.210003,18.031021,-680.024780,-0.003893,0.001504,0.038210,80.205986,4.085888,0.382100,-680.024780,0.039467,0.000000
35.600002,18.276787,-679.935791,-0.003880,0.001528,0.038800,81.299210,4.141579,0.387997,-679.935791,0.040118,0.000000
35.990002,19.158188,-680.069275,-0.003867,0.001563,0.039693,85.219879,4.341307,0.396929,-680.069275,0.040768,0.000000
36.380001,19.159309,-680.024780,-0.003846,0.001589,0.040361,85.224861,4.341561,0.403607,-680.024780,0.041419,0.000000
36.770000,19.510078,-680.024780,-0.003820,0.001617,0.041063,86.785164,4.421047,0.410631,-680.024780,0.042069,0.000000
37.160004,19.516411,-680.024780,-0.003794,0.001642,0.041705,86.813332,4.422482,0.417049,-680.024780,0.042720,0.000000
37.550003,19.873886,-680.024780,-0.003773,0.001669,0.042390,88.403458,4.503487,0.423900,-680.024780,0.043370,0.000000
37.940002,19.940170,-680.069275,-0.003755,0.001694,0.043023,88.698311,4.518507,0.430231,-680.069275,0.044020,0.000000
38.330002,20.195244,-680.069275,-0.003734,0.001717,0.043613,89.832932,4.576307,0.436128,-680.069275,0.044671,0.000000
38.720001,20.394096,-680.069275,-0.003725,0.001736,0.044098,90.717468,4.621368,0.440984,-680.069275,0.045321,0.000000
39.110001,20.594055,-680.113770,-0.003695,0.001760,0.044714,91.606934,4.666679,0.447142,-680.113770,0.045972,0.000000
39.500000,20.537827,-680.069275,-0.003682,0.001779,0.045191,91.356812,4.653938,0.451911,-680.069275,0.046622,0.000000
39.890003,21.431152,-680.113770,-0.003669,0.001812,0.046024,95.330528,4.856369,0.460237,-680.113770,0.047272,0.000000
40.280003,21.807991,-680.069275,-0.003652,0.001841,0.046761,97.006790,4.941761,0.467608,-680.069275,0.047923,0.000000
40.670002,21.948746,-680.158203,-0.003630,0.001868,0.047446,97.632896,4.973657,0.474459,-680.158203,0.048573,0.000000
41.060001,21.969231,-680.158203,-0.003596,0.001894,0.048105,97.724022,4.978299,0.481050,-680.158203,0.049224,0.000000
41.450001,21.523499,-680.069275,-0.003587,0.001908,0.048461,95.741302,4.877295,0.484606,-680.069275,0.049865,0.000000
41.840000,22.770576,-680.202698,-0.003587,0.001950,0.049519,101.288582,5.159886,0.495186,-680.202698,0.050516,0.000000
42.230003,22.742271,-680.202698,-0.003548,0.001970,0.050048,101.162674,5.153472,0.500476,-680.202698,0.051166,0.000000
42.620003,22.739296,-680.202698,-0.003531,0.001993,0.050611,101.149437,5.152798,0.506113,-680.202698,0.051817,0.000000
43.010002,23.261734,-680.247192,-0.003527,0.002020,0.051314,103.473358,5.271184,0.513137,-680.247192,0.052467,0.000000
43.400002,23.051720,-680.202698,-0.003514,0.002039,0.051791,102.539169,5.223594,0.517907,-680.202698,0.053118,0.000000
43.790001,23.614746,-680.291687,-0.003479,0.002068,0.052519,105.043640,5.351178,0.525192,-680.291687,0.053768,0.000000
44.180000,24.222824,-680.202698,-0.003449,0.002100,0.053352,107.748505,5.488970,0.533517,-680.202698,0.054418,0.000000
44.570004,24.205696,-680.202698,-0.003449,0.002127,0.054019,107.672318,5.485089,0.540195,-680.202698,0.055069,0.000000
44.960003,24.120056,-680.291687,-0.003432,0.002151,0.054635,107.291367,5.465683,0.546352,-680.291687,0.055719,0.000000
45.350002,23.552559,-680.202698,-0.003397,0.002164,0.054973,104.767014,5.337086,0.549734,-680.202698,0.056370,0.000000
45.740002,25.001831,-680.247192,-0.003397,0.002205,0.056005,111.213699,5.665496,0.560054,-680.247192,0.057020,0.000000
46.130001,25.173492,-680.291687,-0.003372,0.002230,0.056647,111.977287,5.704395,0.566472,-680.291687,0.057671,0.000000
46.520000,25.091202,-680.247192,-0.003354,0.002251,0.057185,111.611237,5.685748,0.571849,-680.247192,0.058321,0.000000
46.910004,25.368988,-680.380615,-0.003328,0.002281,0.057931,112.846893,5.748695,0.579307,-680.380615,0.058971,0.000000
47.300003,25.234940,-680.291687,-0.003311,0.002306,0.058564,112.250618,5.718319,0.585638,-680.291687,0.059622,0.000000
47.690002,25.420006,-680.291687,-0.003303,0.002333,0.059258,113.073830,5.760255,0.592575,-680.291687,0.060272,0.000000
48.080002,25.176102,-680.336121,-0.003281,0.002352,0.059735,111.988892,5.704986,0.597345,-680.336121,0.060923,0.000000
48.470001,25.672844,-680.291687,-0.003260,0.002381,0.060472,114.198517,5.817550,0.604717,-680.291687,0.061573,0.000000
48.860001,25.107216,-680.380615,-0.003247,0.002403,0.061044,111.682472,5.689377,0.610440,-680.380615,0.062223,0.000000
49.250004,24.724411,-680.291687,-0.003264,0.002424,0.061582,109.979675,5.602632,0.615817,-680.291687,0.062874,0.000000
49.640003,25.587570,-680.380615,-0.003216,0.002448,0.062180,113.819199,5.798226,0.621801,-680.380615,0.063524,0.000000
50.030003,26.292847,-680.336121,-0.003203,0.002480,0.062987,116.956421,5.958044,0.629866,-680.336121,0.064175,0.000000
50.420002,25.484428,-680.380615,-0.003221,0.002494,0.063351,113.360397,5.774854,0.633508,-680.380615,0.064825,0.000000
50.810001,26.235870,-680.336121,-0.003186,0.002531,0.064287,116.702980,5.945133,0.642874,-680.336121,0.065467,0.000000
51.200001,27.225639,-680.380615,-0.003186,0.002563,0.065094,121.105690,6.169418,0.650940,-680.380615,0.066117,0.000000
51.590004,27.192123,-680.425110,-0.003143,0.002588,0.065744,120.956604,6.161823,0.657444,-680.425110,0.066768,0.000000
51.980003,26.400093,-680.380615,-0.003130,0.002605,0.066178,117.433479,5.982347,0.661780,-680.380615,0.067418,0.000000
52.370003,27.132919,-680.469604,-0.003104,0.002639,0.067037,120.693253,6.148407,0.670366,-680.469604,0.068069,0.000000
52.760002,26.670433,-680.425110,-0.003096,0.002661,0.067592,118.636009,6.043606,0.675916,-680.425110,0.068719,0.000000
53.150002,26.259705,-680.469604,-0.003091,0.002682,0.068121,116.808998,5.950534,0.681206,-680.469604,0.069369,0.000000
53.540001,27.406609,-680.425110,-0.003061,0.002715,0.068970,121.910683,6.210426,0.689705,-680.425110,0.070020,0.000000
53.930004,27.366394,-680.469604,-0.003053,0.002738,0.069534,121.731804,6.201313,0.695342,-680.469604,0.070670,0.000000
54.320004,26.584785,-680.514099,-0.003053,0.002753,0.069924,118.255035,6.024199,0.699244,-680.514099,0.071321,0.000000
54.710003,26.830551,-680.469604,-0.003040,0.002780,0.070610,119.348251,6.079890,0.706095,-680.469604,0.071971,0.000000
55.100002,27.511993,-680.425110,-0.003031,0.002812,0.071425,122.379456,6.234307,0.714247,-680.425110,0.072621,0.000000
55.490002,27.916389,-680.514099,-0.002997,0.002844,0.072240,124.178299,6.325944,0.722399,-680.514099,0.073272,0.000000
55.880001,27.755524,-680.558533,-0.002988,0.002867,0.072821,123.462738,6.289492,0.728210,-680.558533,0.073922,0.000000
56.270004,27.481087,-680.603027,-0.002975,0.002887,0.073324,122.241982,6.227304,0.733239,-680.603027,0.074573,0.000000
56.660004,27.601364,-680.558533,-0.002949,0.002913,0.073992,122.777000,6.254559,0.739917,-680.558533,0.075223,0.000000
57.050003,27.921600,-680.514099,-0.002949,0.002939,0.074651,124.201485,6.327125,0.746508,-680.514099,0.075874,0.000000
57.440002,28.421700,-680.558533,-0.002923,0.002969,0.075405,126.426033,6.440449,0.754053,-680.558533,0.076524,0.000000
57.830002,28.879715,-680.558533,-0.002915,0.002999,0.076186,128.463394,6.544237,0.761858,-680.558533,0.077174,0.000000
58.220001,28.665977,-680.603027,-0.002923,0.003027,0.076888,127.512634,6.495803,0.768882,-680.603027,0.077825,0.000000
58.610004,28.410904,-680.514099,-0.002906,0.003048,0.077417,126.378014,6.438003,0.774172,-680.514099,0.078475,0.000000
59.000004,28.736351,-680.558533,-0.002893,0.003078,0.078172,127.825676,6.511750,0.781717,-680.558533,0.079126,0.000000
59.390003,28.431381,-680.647522,-0.002871,0.003097,0.078675,126.469101,6.442643,0.786747,-680.647522,0.079776,0.000000
59.780003,28.382225,-680.558533,-0.002863,0.003118,0.079186,126.250443,6.431504,0.791864,-680.558533,0.080418,0.000000
60.170002,28.696884,-680.647522,-0.002850,0.003147,0.079941,127.650116,6.502807,0.799409,-680.647522,0.081068,0.000000
60.560001,28.695763,-680.603027,-0.002850,0.003169,0.080487,127.645126,6.502553,0.804872,-680.603027,0.081719,0.000000
60.950005,28.832054,-680.647522,-0.002837,0.003188,0.080982,128.251389,6.533437,0.809815,-680.647522,0.082369,0.000000
61.340004,29.014893,-680.647522,-0.002811,0.003218,0.081727,129.064682,6.574869,0.817274,-680.647522,0.083020,0.000000
61.730003,30.334579,-680.647522,-0.002798,0.003253,0.082629,134.934952,6.873914,0.826293,-680.647522,0.083670,0.000000
62.120003,30.151001,-680.736450,-0.002790,0.003280,0.083306,134.118347,6.832314,0.833057,-680.736450,0.084320,0.000000
62.510002,29.389122,-680.647522,-0.002790,0.003298,0.083757,130.729340,6.659670,0.837567,-680.647522,0.084971,0.000000
62.900002,29.741760,-680.647522,-0.002781,0.003326,0.084476,132.297958,6.739579,0.844765,-680.647522,0.085621,0.000000
63.290005,30.335693,-680.647522,-0.002764,0.003355,0.085214,134.939911,6.874166,0.852136,-680.647522,0.086272,0.000000
63.680004,29.823311,-680.647522,-0.002755,0.003374,0.085708,132.660706,6.758059,0.857079,-680.647522,0.086922,0.000000
64.070000,29.588715,-680.736450,-0.002738,0.003401,0.086376,131.617172,6.704899,0.863757,-680.736450,0.087572,0.000000
64.460007,29.830757,-680.692017,-0.002712,0.003424,0.086965,132.693832,6.759746,0.869654,-680.692017,0.088223,0.000000
64.850006,29.662071,-680.736450,-0.002695,0.003446,0.087529,131.943481,6.721521,0.875291,-680.736450,0.088873,0.000000
65.240005,30.706207,-680.692017,-0.002690,0.003481,0.088405,136.588028,6.958126,0.884050,-680.692017,0.089524,0.000000
65.630005,30.759453,-680.780945,-0.002682,0.003509,0.089116,136.824875,6.970192,0.891161,-680.780945,0.090174,0.000000
66.020004,31.128471,-680.780945,-0.002677,0.003537,0.089836,138.466354,7.053813,0.898359,-680.780945,0.090825,0.000000
66.410004,30.590767,-680.780945,-0.002669,0.003558,0.090365,136.074524,6.931967,0.903649,-680.780945,0.091475,0.000000
66.800003,30.976921,-680.825439,-0.002652,0.003582,0.090981,137.792221,7.019471,0.909807,-680.825439,0.092125,0.000000
67.190002,31.303116,-680.736450,-0.002630,0.003607,0.091614,139.243210,7.093387,0.916137,-680.736450,0.092776,0.000000
67.580002,31.200714,-680.780945,-0.002626,0.003629,0.092169,138.787704,7.070183,0.921688,-680.780945,0.093426,0.000000
67.970001,31.463982,-680.780945,-0.002604,0.003654,0.092802,139.958786,7.129840,0.928018,-680.780945,0.094077,0.000000
68.360001,32.686478,-680.780945,-0.002600,0.003694,0.093816,145.396713,7.406862,0.938165,-680.780945,0.094727,0.000000
68.750000,32.501785,-680.825439,-0.002591,0.003713,0.094311,144.575165,7.365010,0.943108,-680.825439,0.095369,0.000000
69.140007,32.693932,-680.825439,-0.002565,0.003737,0.094909,145.429871,7.408551,0.949092,-680.825439,0.096019,0.000000
69.530006,32.902458,-680.780945,-0.002565,0.003757,0.095430,146.357437,7.455804,0.954295,-680.780945,0.096670,0.000000
69.920006,33.724281,-680.780945,-0.002544,0.003790,0.096253,150.013092,7.642032,0.962534,-680.780945,0.097320,0.000000
70.310005,34.048996,-680.914429,-0.002548,0.003812,0.096817,151.457504,7.715613,0.968171,-680.914429,0.097970,0.000000
70.700005,34.441475,-680.869934,-0.002518,0.003831,0.097320,153.203339,7.804550,0.973201,-680.869934,0.098621,0.000000
71.090004,35.662857,-680.869934,-0.002514,0.003864,0.098153,158.636307,8.081319,0.981526,-680.869934,0.099271,0.000000
71.480003,35.399590,-680.869934,-0.002509,0.003881,0.098578,157.465240,8.021662,0.985776,-680.869934,0.099922,0.000000
71.870003,36.812370,-680.914429,-0.002483,0.003913,0.099393,163.749603,8.341803,0.993927,-680.914429,0.100572,0.000000
72.260002,36.852211,-680.914429,-0.002471,0.003932,0.099870,163.926819,8.350830,0.998697,-680.914429,0.101223,0.000000
72.650002,38.210999,-680.914429,-0.002449,0.003967,0.100772,169.971008,8.658735,1.007716,-680.914429,0.101873,0.000000
73.040001,39.039154,-680.914429,-0.002440,0.003992,0.101387,173.654831,8.846399,1.013874,-680.914429,0.102523,0.000000
73.430000,39.574631,-680.958862,-0.002432,0.004015,0.101977,176.036743,8.967739,1.019771,-680.958862,0.103174,0.000000
73.820000,40.823189,-680.914429,-0.002427,0.004044,0.102723,181.590607,9.250668,1.027229,-680.914429,0.103824,0.000000
74.210007,41.267433,-681.003357,-0.002419,0.004067,0.103304,183.566711,9.351334,1.033039,-681.003357,0.104475,0.000000
74.600006,42.288109,-680.958862,-0.002402,0.004092,0.103946,188.106903,9.582622,1.039457,-680.958862,0.105125,0.000000
74.990005,43.496452,-680.958862,-0.002371,0.004117,0.104570,193.481888,9.856437,1.045701,-680.958862,0.105776,0.000000
75.380005,44.634796,-681.003357,-0.002380,0.004145,0.105273,198.545486,10.114389,1.052725,-681.003357,0.106426,0.000000
75.770004,45.085739,-680.958862,-0.002363,0.004162,0.105723,200.551376,10.216575,1.057235,-680.958862,0.107076,0.000000
76.160004,46.539482,-681.003357,-0.002354,0.004191,0.106452,207.017960,10.545998,1.064520,-681.003357,0.107727,0.000000
76.550003,47.011650,-680.914429,-0.002324,0.004210,0.106929,209.118271,10.652992,1.069289,-680.914429,0.108377,0.000000
76.940002,49.798859,-681.047852,-0.002311,0.004252,0.107996,221.516388,11.284583,1.079956,-681.047852,0.109028,0.000000
77.330002,49.648048,-681.047852,-0.002307,0.004263,0.108273,220.845551,11.250408,1.082731,-681.047852,0.109678,0.000000
77.720001,52.089691,-681.047852,-0.002289,0.004300,0.109218,231.706512,11.803693,1.092184,-681.047852,0.110320,0.000000
78.110001,52.444191,-681.092346,-0.002281,0.004321,0.109765,233.283417,11.884024,1.097648,-681.092346,0.110970,0.000000
78.500000,54.715294,-681.047852,-0.002268,0.004350,0.110502,243.385788,12.398663,1.105019,-681.047852,0.111621,0.000000
78.890007,55.958267,-681.092346,-0.002259,0.004374,0.111109,248.914810,12.680325,1.111090,-681.092346,0.112271,0.000000
79.280006,57.863327,-681.136780,-0.002238,0.004407,0.111941,257.388947,13.112018,1.119415,-681.136780,0.112921,0.000000
79.670006,59.308502,-681.047852,-0.002238,0.004433,0.112601,263.817383,13.439499,1.126006,-681.047852,0.113572,0.000000
80.060005,60.788689,-681.092346,-0.002220,0.004458,0.113242,270.401581,13.774914,1.132423,-681.092346,0.114222,0.000000
80.450005,62.098694,-681.003357,-0.002199,0.004481,0.113806,276.228790,14.071765,1.138060,-681.003357,0.114873,0.000000
80.840004,63.335342,-681.136780,-0.002207,0.004502,0.114344,281.729675,14.351994,1.143437,-681.136780,0.115523,0.000000
81.230003,64.342239,-681.136780,-0.002186,0.004526,0.114959,286.208588,14.580160,1.149594,-681.136780,0.116174,0.000000
81.620003,66.303894,-681.136780,-0.002164,0.004541,0.115332,294.934448,15.024677,1.153324,-681.136780,0.115575,0.000000
82.010002,65.285461,-681.181274,-0.002151,0.004540,0.115324,290.404236,14.793897,1.153237,-681.181274,294.500458,0.000000
82.400002,65.110809,-681.092346,-0.002164,0.004555,0.115697,289.627350,14.754320,1.156966,-681.092346,294.500458,0.000000
82.790001,64.932068,-681.225769,-0.002164,0.004555,0.115705,288.832275,14.713818,1.157053,-681.225769,294.500458,0.000000
83.180000,65.240402,-681.225769,-0.002147,0.004564,0.115931,290.203796,14.783687,1.159307,-681.225769,294.500458,0.000000
83.570007,64.976013,-681.181274,-0.002156,0.004567,0.116009,289.027740,14.723775,1.160088,-681.181274,294.500458,0.000000
83.960007,64.723923,-681.225769,-0.002143,0.004573,0.116156,287.906403,14.666650,1.161562,-681.225769,294.500458,0.000000
84.350006,65.145447,-681.181274,-0.002143,0.004575,0.116217,289.781433,14.762170,1.162169,-681.181274,294.500458,0.000000
84.740005,64.849030,-681.225769,-0.002156,0.004576,0.116226,288.462891,14.695001,1.162256,-681.225769,294.500458,0.000000
85.130005,64.577576,-681.181274,-0.002134,0.004576,0.116234,287.255402,14.633488,1.162343,-681.181274,294.500458,0.000000
85.520004,65.625809,-681.225769,-0.002121,0.004589,0.116564,291.918182,14.871020,1.165638,-681.225769,294.500458,0.000000
85.910004,65.486908,-681.181274,-0.002121,0.004589,0.116564,291.300323,14.839546,1.165638,-681.181274,294.500458,0.000000
86.300003,65.229965,-681.225769,-0.002117,0.004589,0.116572,290.157379,14.781322,1.165725,-681.225769,294.500458,0.000000
86.690002,64.997986,-681.314697,-0.002130,0.004589,0.116572,289.125488,14.728754,1.165725,-681.314697,294.500458,0.000000
87.080002,64.792068,-681.270264,-0.002126,0.004589,0.116572,288.209503,14.682093,1.165725,-681.270264,294.500458,0.000000
87.470001,64.596573,-681.314697,-0.002126,0.004589,0.116572,287.339905,14.637793,1.165725,-681.314697,294.500458,0.000000
87.860001,66.042114,-681.270264,-0.002126,0.004597,0.116755,293.769989,14.965357,1.167546,-681.270264,294.500458,0.000000
88.250008,65.842529,-681.270264,-0.002121,0.004596,0.116746,292.882202,14.920131,1.167459,-681.270264,294.500458,0.000000
88.640007,65.601593,-681.359192,-0.002117,0.004596,0.116746,291.810455,14.865534,1.167459,-681.359192,294.500458,0.000000
89.030006,65.447067,-681.270264,-0.002121,0.004596,0.116746,291.123108,14.830518,1.167459,-681.270264,294.500458,0.000000
89.420006,65.275772,-681.359192,-0.002117,0.004597,0.116755,290.361145,14.791701,1.167546,-681.359192,294.500458,0.000000
89.810005,65.089218,-681.314697,-0.002113,0.004597,0.116755,289.531311,14.749428,1.167546,-681.314697,294.500458,0.000000
90.200005,64.978256,-681.314697,-0.002117,0.004597,0.116755,289.037720,14.724283,1.167546,-681.314697,294.500458,0.000000
90.590004,64.811050,-681.359192,-0.002095,0.004597,0.116755,288.293945,14.686394,1.167546,-681.359192,294.500458,0.000000
90.980003,64.698593,-681.314697,-0.002117,0.004597,0.116755,287.793701,14.660911,1.167546,-681.314697,294.500458,0.000000
91.370003,66.089783,-681.403687,-0.002117,0.004607,0.117015,293.982025,14.976159,1.170148,-681.403687,294.500458,0.000000
91.760002,65.955734,-681.359192,-0.002104,0.004607,0.117015,293.385773,14.945783,1.170148,-681.359192,294.500458,0.000000
92.150002,65.851089,-681.403687,-0.002108,0.004607,0.117015,292.920288,14.922071,1.170148,-681.403687,294.500458,0.000000
92.540001,65.733414,-681.448181,-0.002104,0.004607,0.117015,292.396820,14.895405,1.170148,-681.448181,294.500458,0.000000
92.930008,65.575165,-681.359192,-0.002113,0.004607,0.117015,291.692902,14.859545,1.170148,-681.359192,294.500458,0.000000
93.320007,65.496964,-681.448181,-0.002095,0.004607,0.117015,291.345032,14.841825,1.170148,-681.448181,294.500458,0.000000
93.710007,65.352478,-681.403687,-0.002095,0.004607,0.117015,290.702332,14.809083,1.170148,-681.403687,294.500458,0.000000
94.100006,65.272430,-681.448181,-0.002104,0.004607,0.117015,290.346283,14.790944,1.170148,-681.448181,294.500458,0.000000
94.490005,65.177841,-681.448181,-0.002100,0.004607,0.117023,289.925507,14.769509,1.170234,-681.448181,294.500458,0.000000
94.880005,65.063522,-681.448181,-0.002095,0.004607,0.117023,289.416992,14.743606,1.170234,-681.448181,294.500458,0.000000
95.270004,65.000961,-681.492676,-0.002108,0.004607,0.117023,289.138702,14.729428,1.170234,-681.492676,294.500458,0.000000
95.660004,64.911224,-681.492676,-0.002087,0.004607,0.117023,288.739532,14.709093,1.170234,-681.492676,294.500458,0.000000
96.050003,64.819244,-681.448181,-0.002108,0.004608,0.117032,288.330414,14.688251,1.170321,-681.448181,294.500458,0.000000
96.440002,65.774384,-681.492676,-0.002100,0.004625,0.117466,292.579071,14.904688,1.174657,-681.492676,294.500458,0.000000
96.830002,65.768051,-681.448181,-0.002095,0.004625,0.117466,292.550903,14.903254,1.174657,-681.448181,294.500458,0.000000
97.220001,65.751663,-681.581604,-0.002091,0.004625,0.117466,292.477997,14.899540,1.174657,-681.581604,294.500458,0.000000
97.610008,65.666016,-681.492676,-0.002104,0.004625,0.117466,292.097015,14.880132,1.174657,-681.492676,294.500458,0.000000
98.000008,65.601974,-681.537109,-0.002100,0.004625,0.117466,291.812164,14.865620,1.174657,-681.537109,294.500458,0.000000
98.390007,65.558411,-681.492676,-0.002087,0.004625,0.117466,291.618378,14.855748,1.174657,-681.492676,294.500458,0.000000
98.780006,65.521164,-681.581604,-0.002121,0.004625,0.117466,291.452698,14.847308,1.174657,-681.581604,294.500458,0.000000
99.170006,65.455261,-681.581604,-0.002087,0.004625,0.117466,291.159546,14.832374,1.174657,-681.581604,294.500458,0.000000
99.560005,65.383759,-681.581604,-0.002091,0.004625,0.117466,290.841492,14.816172,1.174657,-681.581604,294.500458,0.000000
99.950005,65.326050,-681.626099,-0.002087,0.004625,0.117466,290.584778,14.803094,1.174657,-681.626099,294.500458,0.000000
100.340004,65.299973,-681.626099,-0.002082,0.004625,0.117466,290.468781,14.797185,1.174657,-681.626099,294.500458,0.000000
100.730003,65.257904,-681.492676,-0.002100,0.004625,0.117466,290.281647,14.787653,1.174657,-681.492676,294.500458,0.000000
101.120003,65.201294,-681.670593,-0.002087,0.004625,0.117466,290.029846,14.774824,1.174657,-681.670593,294.500458,0.000000
101.510002,65.140610,-681.537109,-0.002091,0.004625,0.117466,289.759918,14.761073,1.174657,-681.537109,294.500458,0.000000
101.900002,65.092941,-681.626099,-0.002104,0.004627,0.117518,289.547852,14.750272,1.175178,-681.626099,294.500458,0.000000
102.290009,65.149918,-681.581604,-0.002082,0.004627,0.117535,289.801300,14.763183,1.175351,-681.581604,294.500458,0.000000
102.680008,65.145447,-681.626099,-0.002095,0.004627,0.117535,289.781433,14.762170,1.175351,-681.626099,294.500458,0.000000
103.070007,65.122360,-681.626099,-0.002095,0.004627,0.117535,289.678711,14.756938,1.175351,-681.626099,294.500458,0.000000
103.460007,65.077667,-681.626099,-0.002091,0.004628,0.117544,289.479919,14.746810,1.175438,-681.626099,294.500458,0.000000
103.850006,65.051239,-681.715027,-0.002091,0.004628,0.117544,289.362366,14.740822,1.175438,-681.715027,294.500458,0.000000
104.240005,65.010651,-681.670593,-0.002100,0.004628,0.117544,289.181824,14.731625,1.175438,-681.670593,294.500458,0.000000
104.630005,64.977875,-681.670593,-0.002095,0.004628,0.117552,289.036011,14.724196,1.175524,-681.670593,294.500458,0.000000
105.020004,65.088837,-681.670593,-0.002078,0.004630,0.117613,289.529602,14.749341,1.176131,-681.670593,294.500458,0.000000
105.410004,65.082886,-681.670593,-0.002087,0.004630,0.117613,289.503143,14.747993,1.176131,-681.670593,294.500458,0.000000
105.800003,65.068359,-681.715027,-0.002113,0.004630,0.117613,289.438507,14.744701,1.176131,-681.715027,294.500458,0.000000
106.190002,65.040070,-681.715027,-0.002095,0.004630,0.117613,289.312683,14.738291,1.176131,-681.715027,294.500458,0.000000
106.580002,65.024796,-681.670593,-0.002091,0.004631,0.117622,289.244751,14.734829,1.176218,-681.670593,294.500458,0.000000
106.970009,65.174118,-681.715027,-0.002095,0.004634,0.117700,289.908966,14.768666,1.176999,-681.715027,294.500458,0.000000
107.360008,65.237045,-681.759521,-0.002095,0.004634,0.117700,290.188873,14.782926,1.176999,-681.759521,294.500458,0.000000
107.750008,65.240402,-681.759521,-0.002087,0.004634,0.117700,290.203796,14.783687,1.176999,-681.759521,294.500458,0.000000
108.140007,65.230713,-681.715027,-0.002082,0.004634,0.117700,290.160706,14.781491,1.176999,-681.715027,294.500458,0.000000
108.530006,65.195709,-681.759521,-0.002091,0.004634,0.117700,290.005005,14.773559,1.176999,-681.759521,294.500458,0.000000
108.920006,65.178589,-681.804016,-0.002087,0.004634,0.117700,289.928833,14.769679,1.176999,-681.804016,294.500458,0.000000
109.310005,65.148422,-681.804016,-0.002078,0.004634,0.117700,289.794647,14.762843,1.176999,-681.804016,294.500458,0.000000
109.700005,65.111557,-681.848511,-0.002087,0.004634,0.117700,289.630676,14.754489,1.176999,-681.848511,294.500458,0.000000
110.090004,65.085114,-681.804016,-0.002074,0.004634,0.117700,289.513031,14.748498,1.176999,-681.804016,294.500458,0.000000
110.480003,65.052719,-681.848511,-0.002095,0.004634,0.117700,289.368958,14.741157,1.176999,-681.848511,294.500458,0.000000
110.870003,65.260880,-681.848511,-0.002095,0.004638,0.117804,290.294891,14.788326,1.178039,-681.848511,294.500458,0.000000
111.260002,65.273911,-681.804016,-0.002091,0.004638,0.117804,290.352844,14.791280,1.178039,-681.804016,294.500458,0.000000
111.650002,65.293274,-681.848511,-0.002095,0.004638,0.117804,290.438995,14.795667,1.178039,-681.848511,294.500458,0.000000
112.040009,65.270187,-681.848511,-0.002082,0.004638,0.117804,290.336304,14.790436,1.178039,-681.848511,294.500458,0.000000
112.430008,65.272430,-681.848511,-0.002108,0.004638,0.117804,290.346283,14.790944,1.178039,-681.848511,294.500458,0.000000
112.820007,65.253067,-681.893005,-0.002087,0.004638,0.117804,290.260132,14.786556,1.178039,-681.893005,294.500458,0.000000
113.210007,65.234436,-681.893005,-0.002078,0.004638,0.117804,290.177277,14.782334,1.178039,-681.893005,294.500458,0.000000
113.600006,65.223648,-681.937439,-0.002095,0.004638,0.117804,290.129272,14.779890,1.178039,-681.937439,294.500458,0.000000
113.990005,65.181564,-681.893005,-0.002091,0.004638,0.117804,289.942078,14.770354,1.178039,-681.893005,294.500458,0.000000
114.380005,65.142090,-681.937439,-0.002104,0.004638,0.117804,289.766479,14.761409,1.178039,-681.937439,294.500458,0.000000
114.770004,65.117142,-681.893005,-0.002074,0.004638,0.117804,289.655518,14.755754,1.178039,-681.893005,294.500458,0.000000
115.160004,65.095917,-681.937439,-0.002091,0.004638,0.117804,289.561096,14.750946,1.178039,-681.937439,294.500458,0.000000
115.550003,65.056076,-682.026428,-0.002078,0.004638,0.117804,289.383881,14.741918,1.178039,-682.026428,294.500458,0.000000
115.940002,65.037827,-681.848511,-0.002074,0.004638,0.117804,289.302704,14.737782,1.178039,-681.848511,294.500458,0.000000
116.330002,65.017349,-681.981934,-0.002082,0.004638,0.117804,289.211609,14.733142,1.178039,-681.981934,294.500458,0.000000
116.720009,65.004684,-681.937439,-0.002074,0.004638,0.117804,289.155273,14.730271,1.178039,-681.937439,294.500458,0.000000
117.110008,64.989044,-681.981934,-0.002091,0.004638,0.117804,289.085693,14.726727,1.178039,-681.981934,294.500458,0.000000
117.500008,65.757996,-681.937439,-0.002091,0.004648,0.118047,292.506165,14.900975,1.180468,-681.937439,294.500458,0.000000
117.890007,65.762833,-681.937439,-0.002082,0.004646,0.118021,292.527679,14.902071,1.180208,-681.937439,294.500458,0.000000
118.280006,65.760605,-682.026428,-0.002095,0.004646,0.118021,292.517792,14.901566,1.180208,-682.026428,294.500458,0.000000
118.670006,65.759491,-681.937439,-0.002087,0.004646,0.118021,292.512817,14.901314,1.180208,-681.937439,294.500458,0.000000
119.060005,65.754272,-681.981934,-0.002095,0.004646,0.118021,292.489624,14.900131,1.180208,-681.981934,294.500458,0.000000
119.450005,65.696930,-682.026428,-0.002078,0.004646,0.118021,292.234528,14.887137,1.180208,-682.026428,294.500458,0.000000
119.840004,65.686874,-682.026428,-0.002087,0.004646,0.118021,292.189819,14.884859,1.180208,-682.026428,294.500458,0.000000
120.230003,65.674210,-682.070923,-0.002087,0.004646,0.118021,292.133484,14.881989,1.180208,-682.070923,294.500458,0.000000
120.620003,65.667877,-682.026428,-0.002074,0.004646,0.118021,292.105316,14.880554,1.180208,-682.026428,294.500458,0.000000
121.010002,65.649261,-682.070923,-0.002082,0.004646,0.118021,292.022491,14.876335,1.180208,-682.070923,294.500458,0.000000
121.400009,65.619843,-682.115356,-0.002082,0.004646,0.118021,291.891632,14.869669,1.180208,-682.115356,294.500458,0.000000
121.790009,65.597870,-682.026428,-0.002070,0.004646,0.118021,291.793884,14.864690,1.180208,-682.026428,294.500458,0.000000
122.180008,65.591171,-682.115356,-0.002074,0.004646,0.118021,291.764099,14.863172,1.180208,-682.115356,294.500458,0.000000
122.570007,65.583359,-682.070923,-0.002082,0.004646,0.118021,291.729340,14.861402,1.180208,-682.070923,294.500458,0.000000
122.960007,65.575165,-682.070923,-0.002082,0.004646,0.118021,291.692902,14.859545,1.180208,-682.070923,294.500458,0.000000
123.350006,65.563995,-682.115356,-0.002074,0.004646,0.118021,291.643219,14.857014,1.180208,-682.115356,294.500458,0.000000
123.740005,65.535690,-682.070923,-0.002070,0.004646,0.118021,291.517303,14.850599,1.180208,-682.070923,294.500458,0.000000
124.130005,65.538300,-682.159851,-0.002070,0.004646,0.118021,291.528931,14.851191,1.180208,-682.159851,294.500458,0.000000
124.520004,65.510376,-682.026428,-0.002070,0.004646,0.118021,291.404694,14.844864,1.180208,-682.026428,294.500458,0.000000
124.910004,65.474991,-682.159851,-0.002070,0.004646,0.118021,291.247314,14.836845,1.180208,-682.159851,294.500458,0.000000
125.300003,65.434784,-682.159851,-0.002087,0.004647,0.118029,291.068451,14.827734,1.180294,-682.159851,294.500458,0.000000
125.690002,65.427704,-682.159851,-0.002095,0.004647,0.118029,291.036957,14.826130,1.180294,-682.159851,294.500458,0.000000
126.080009,65.396790,-682.159851,-0.002070,0.004647,0.118029,290.899445,14.819124,1.180294,-682.159851,294.500458,0.000000
126.470009,65.384506,-682.159851,-0.002074,0.004647,0.118029,290.844818,14.816340,1.180294,-682.159851,294.500458,0.000000
126.860008,65.355087,-682.159851,-0.002082,0.004647,0.118029,290.713959,14.809674,1.180294,-682.159851,294.500458,0.000000
127.250008,65.332382,-682.204346,-0.002065,0.004647,0.118029,290.612946,14.804529,1.180294,-682.204346,294.500458,0.000000
127.640007,65.332001,-682.204346,-0.002074,0.004647,0.118029,290.611267,14.804443,1.180294,-682.204346,294.500458,0.000000
128.029999,65.307053,-682.204346,-0.002082,0.004647,0.118029,290.500275,14.798789,1.180294,-682.204346,294.500458,0.000000
128.420013,65.297745,-682.159851,-0.002070,0.004647,0.118029,290.458862,14.796680,1.180294,-682.159851,294.500458,0.000000
128.810013,65.276886,-682.204346,-0.002091,0.004647,0.118029,290.366089,14.791954,1.180294,-682.204346,294.500458,0.000000
129.200012,65.264969,-682.204346,-0.002070,0.004647,0.118029,290.313080,14.789253,1.180294,-682.204346,294.500458,0.000000
129.590012,65.255295,-682.248840,-0.002074,0.004647,0.118029,290.270050,14.787061,1.180294,-682.248840,294.500458,0.000000
129.980011,65.229599,-682.248840,-0.002082,0.004647,0.118029,290.155762,14.781239,1.180294,-682.248840,294.500458,0.000000
130.370010,65.209869,-682.248840,-0.002082,0.004647,0.118029,290.067993,14.776768,1.180294,-682.248840,294.500458,0.000000
130.760010,65.203156,-682.293335,-0.002082,0.004647,0.118029,290.038116,14.775247,1.180294,-682.293335,294.500458,0.000000
131.150009,65.177475,-682.293335,-0.002065,0.004647,0.118029,289.923889,14.769426,1.180294,-682.293335,294.500458,0.000000
131.540009,65.147675,-682.248840,-0.002082,0.004647,0.118029,289.791321,14.762674,1.180294,-682.248840,294.500458,0.000000
131.930008,65.130173,-682.337769,-0.002074,0.004647,0.118029,289.713470,14.758708,1.180294,-682.337769,294.500458,0.000000
132.320007,65.115280,-682.337769,-0.002082,0.004647,0.118029,289.647247,14.755334,1.180294,-682.337769,294.500458,0.000000
132.710007,65.086243,-682.337769,-0.002087,0.004647,0.118038,289.518066,14.748754,1.180381,-682.337769,294.500458,0.000000
133.100006,65.063522,-682.337769,-0.002082,0.004647,0.118038,289.416992,14.743606,1.180381,-682.337769,294.500458,0.000000
133.490005,65.058304,-682.293335,-0.002087,0.004647,0.118038,289.393799,14.742422,1.180381,-682.293335,294.500458,0.000000
133.880005,65.047516,-682.382263,-0.002078,0.004647,0.118038,289.345795,14.739977,1.180381,-682.382263,294.500458,0.000000
134.270004,65.032242,-682.382263,-0.002070,0.004647,0.118038,289.277863,14.736517,1.180381,-682.382263,294.500458,0.000000
134.660004,65.010651,-682.382263,-0.002091,0.004647,0.118038,289.181824,14.731625,1.180381,-682.382263,294.500458,0.000000
135.050003,65.007294,-682.382263,-0.002082,0.004647,0.118038,289.166870,14.730864,1.180381,-682.382263,294.500458,0.000000
135.440002,64.982712,-682.337769,-0.002087,0.004647,0.118038,289.057526,14.725293,1.180381,-682.337769,294.500458,0.000000
135.830002,64.980484,-682.426758,-0.002070,0.004647,0.118038,289.047638,14.724789,1.180381,-682.426758,294.500458,0.000000
136.220001,64.970062,-682.426758,-0.002082,0.004647,0.118038,289.001282,14.722427,1.180381,-682.426758,294.500458,0.000000
136.610001,64.947342,-682.471252,-0.002082,0.004647,0.118038,288.900208,14.717278,1.180381,-682.471252,294.500458,0.000000
137.000000,64.921646,-682.426758,-0.002070,0.004647,0.118038,288.785919,14.711455,1.180381,-682.426758,294.500458,0.000000
137.389999,64.917175,-682.426758,-0.002082,0.004647,0.118038,288.766022,14.710442,1.180381,-682.426758,294.500458,0.000000
137.780014,64.902664,-682.426758,-0.002082,0.004647,0.118038,288.701477,14.707154,1.180381,-682.426758,294.500458,0.000000
138.170013,65.782944,-682.382263,-0.002070,0.004658,0.118324,292.617157,14.906628,1.183243,-682.382263,294.500458,0.000000
138.560013,65.841782,-682.471252,-0.002074,0.004658,0.118324,292.878876,14.919961,1.183243,-682.471252,294.500458,0.000000
138.950012,65.894653,-682.382263,-0.002070,0.004658,0.118324,293.114044,14.931941,1.183243,-682.382263,294.500458,0.000000
139.340012,65.888702,-682.471252,-0.002082,0.004658,0.118324,293.087585,14.930593,1.183243,-682.471252,294.500458,0.000000
139.730011,65.911041,-682.604675,-0.002078,0.004658,0.118316,293.186951,14.935656,1.183156,-682.604675,294.500458,0.000000
140.120010,65.897263,-682.471252,-0.002065,0.004658,0.118316,293.125671,14.932533,1.183156,-682.471252,294.500458,0.000000
140.510010,65.908813,-682.649170,-0.002078,0.004658,0.118316,293.177032,14.935150,1.183156,-682.649170,294.500458,0.000000
140.900009,65.852585,-682.560181,-0.002061,0.004658,0.118316,292.926941,14.922409,1.183156,-682.560181,294.500458,0.000000
141.290009,65.845139,-682.515686,-0.002087,0.004658,0.118316,292.893799,14.920721,1.183156,-682.515686,294.500458,0.000000
141.680008,65.828003,-682.560181,-0.002074,0.004658,0.118316,292.817596,14.916839,1.183156,-682.560181,294.500458,0.000000
142.070007,65.910294,-682.515686,-0.002078,0.004658,0.118316,293.183624,14.935486,1.183156,-682.515686,294.500458,0.000000
142.460007,65.848862,-682.560181,-0.002078,0.004655,0.118238,292.910370,14.921566,1.182376,-682.560181,0.118107,0.000000
142.850006,65.883865,-682.560181,-0.002057,0.004638,0.117795,293.066071,14.929498,1.177953,-682.560181,0.117457,0.000000
143.240005,65.765076,-682.604675,-0.002052,0.004612,0.117154,292.537659,14.902579,1.171535,-682.604675,0.116807,0.000000
143.630005,65.644424,-682.604675,-0.002044,0.004594,0.116694,292.000977,14.875239,1.166939,-682.604675,0.116156,0.000000
144.020004,65.634735,-682.604675,-0.002052,0.004568,0.116035,291.957886,14.873043,1.160348,-682.604675,0.115506,0.000000
144.410004,65.631760,-682.649170,-0.002048,0.004546,0.115471,291.944641,14.872369,1.154711,-682.649170,0.114855,0.000000
144.800003,65.620224,-682.604675,-0.002061,0.004519,0.114786,291.893341,14.869755,1.147860,-682.604675,0.114205,0.000000
145.190002,65.633255,-682.604675,-0.002065,0.004494,0.114144,291.951294,14.872708,1.141442,-682.604675,0.113555,0.000000
145.580002,65.580750,-682.649170,-0.002048,0.004469,0.113520,291.717743,14.860810,1.135199,-682.649170,0.112904,0.000000
145.970001,65.511108,-682.649170,-0.002065,0.004443,0.112843,291.407959,14.845029,1.128434,-682.649170,0.112254,0.000000
146.360001,65.399033,-682.693665,-0.002065,0.004422,0.112323,290.909424,14.819633,1.123231,-682.693665,0.111603,0.000000
146.750000,64.808823,-682.604675,-0.002052,0.004395,0.111621,288.284027,14.685889,1.116206,-682.604675,0.110953,0.000000
147.139999,64.050293,-682.604675,-0.002057,0.004373,0.111074,284.909943,14.514004,1.110743,-682.604675,0.110302,0.000000
147.530014,62.796143,-682.693665,-0.002048,0.004346,0.110381,279.331207,14.229810,1.103805,-682.693665,0.109652,0.000000
147.920013,61.527100,-682.693665,-0.002031,0.004325,0.109860,273.686218,13.942240,1.098602,-682.693665,0.109002,0.000000
148.310013,59.829826,-682.738098,-0.002048,0.004297,0.109132,266.136353,13.557632,1.091317,-682.738098,0.108351,0.000000
148.700012,58.116173,-682.693665,-0.002039,0.004276,0.108620,258.513641,13.169313,1.086200,-682.693665,0.107701,0.000000
149.090012,55.817139,-682.693665,-0.002039,0.004251,0.107970,248.287033,12.648345,1.079696,-682.693665,0.107059,0.000000
149.480011,53.568008,-682.738098,-0.002039,0.004227,0.107363,238.282410,12.138684,1.073625,-682.738098,0.106409,0.000000
149.870010,51.651787,-682.693665,-0.002035,0.004210,0.106929,229.758621,11.704462,1.069289,-682.693665,0.105758,0.000000
150.260010,48.819893,-682.738098,-0.002031,0.004183,0.106252,217.161728,11.062745,1.062525,-682.738098,0.105108,0.000000
150.650009,45.607803,-682.738098,-0.002039,0.004151,0.105429,202.873642,10.334876,1.054286,-682.738098,0.104457,0.000000
151.040009,42.792297,-682.782593,-0.002044,0.004125,0.104778,190.349640,9.696873,1.047782,-682.782593,0.103807,0.000000
151.430008,40.698448,-682.738098,-0.002039,0.004109,0.104379,181.035736,9.222400,1.043793,-682.738098,0.103157,0.000000
151.820007,37.094254,-682.693665,-0.002039,0.004076,0.103529,165.003479,8.405678,1.035294,-682.693665,0.102506,0.000000
152.210007,35.042480,-682.782593,-0.002044,0.004053,0.102948,155.876740,7.940740,1.029484,-682.782593,0.101856,0.000000
152.600006,32.082123,-682.782593,-0.002035,0.004024,0.102220,142.708405,7.269913,1.022199,-682.782593,0.101205,0.000000
152.990005,28.733749,-682.738098,-0.002048,0.003998,0.101561,127.814102,6.511161,1.015608,-682.738098,0.100555,0.000000
153.380005,25.914146,-682.871582,-0.002048,0.003974,0.100936,115.271881,5.872230,1.009364,-682.871582,0.099904,0.000000
153.770004,23.531334,-682.738098,-0.002048,0.003952,0.100390,104.672600,5.332276,1.003901,-682.738098,0.099254,0.000000
154.160004,20.576927,-682.871582,-0.002065,0.003925,0.099705,91.530746,4.662798,0.997049,-682.871582,0.098604,0.000000
154.550003,17.637047,-682.827087,-0.002052,0.003897,0.098994,78.453499,3.996612,0.989938,-682.827087,0.097953,0.000000
154.940002,14.669609,-682.871582,-0.002065,0.003871,0.098326,65.253677,3.324181,0.983261,-682.871582,0.097303,0.000000
155.330002,11.951294,-682.871582,-0.002074,0.003844,0.097632,53.162010,2.708202,0.976323,-682.871582,0.096652,0.000000
155.720001,9.540924,-682.827087,-0.002100,0.003825,0.097164,42.440151,2.162004,0.971640,-682.827087,0.096002,0.000000
156.110001,6.900803,-682.916016,-0.002091,0.003796,0.096418,30.696302,1.563744,0.964182,-682.916016,0.095351,0.000000
156.500000,3.356934,-682.871582,-0.002095,0.003765,0.095638,14.932386,0.760692,0.956377,-682.871582,0.094701,0.000000
156.890015,1.017693,-682.871582,-0.002091,0.003742,0.095057,4.526923,0.230612,0.950566,-682.871582,0.094051,0.000000
157.280014,-1.610512,-682.916016,-0.002100,0.003712,0.094276,-7.163914,-0.364947,0.942761,-682.916016,0.093400,0.000000
157.670013,-0.360085,-682.871582,-0.002130,0.003694,0.093825,-1.601736,-0.081596,0.938252,-682.871582,0.092750,0.000000
158.060013,-0.072617,-682.960510,-0.002151,0.003675,0.093357,-0.323015,-0.016455,0.933568,-682.960510,0.092108,0.000000
158.450012,-0.118416,-682.871582,-0.002151,0.003633,0.092290,-0.526740,-0.026833,0.922902,-682.871582,0.091458,0.000000
158.840012,-0.079315,-682.916016,-0.002164,0.003613,0.091770,-0.352812,-0.017973,0.917698,-682.916016,0.090807,0.000000
159.230011,-0.043198,-682.960510,-0.002160,0.003585,0.091059,-0.192153,-0.009789,0.910587,-682.960510,0.090157,0.000000
159.620010,-0.088997,-682.871582,-0.002190,0.003562,0.090486,-0.395878,-0.020167,0.904863,-682.871582,0.089506,0.000000
160.010010,-0.062935,-683.049500,-0.002173,0.003533,0.089749,-0.279948,-0.014261,0.897492,-683.049500,0.088856,0.000000
160.400009,-0.042450,-683.005005,-0.002195,0.003506,0.089064,-0.188827,-0.009619,0.890641,-683.005005,0.088206,0.000000
160.790009,-0.030907,-683.005005,-0.002207,0.003489,0.088630,-0.137480,-0.007004,0.886305,-683.005005,0.087555,0.000000
161.000015,0.030159,-682.960510,-0.002199,0.003484,0.088500,0.134154,0.006834,0.885004,-682.960510,0.088362,0.000000