File: Data/compression 33/AutoNoHeating-15-33-reverse-1-2_11152024_180839.csv
Time (sec),S:Load (lbs),S:HL1 (DIM),S:LVDT (in),S:Position (in),Ch:Position (mm),Ch:Load (N),Ch:Stress (MPa),Ch:Strain (mm/mm),Ch:HL1 (DIM),Set Point (),Cycles ()
0.110000,-0.049896,-696.482727,-0.012947,-0.008079,-0.205212,-0.221950,-0.011307,-2.052116,-696.482727,-0.204995,0.000000
0.490000,-0.080063,-696.571716,-0.012956,-0.008016,-0.203607,-0.356137,-0.018143,-2.036072,-696.571716,-0.202792,0.000000
0.870000,-0.090485,-696.616150,-0.012831,-0.007783,-0.197693,-0.402496,-0.020504,-1.976928,-696.616150,-0.196461,0.000000
1.250000,-0.078201,-696.616150,-0.012572,-0.007535,-0.191397,-0.347857,-0.017721,-1.913967,-696.616150,-0.190131,0.000000
1.630000,-0.103523,-696.616150,-0.012322,-0.007286,-0.185066,-0.460494,-0.023459,-1.850660,-696.616150,-0.183800,0.000000
2.010000,-0.105751,-696.660645,-0.012051,-0.007036,-0.178727,-0.470404,-0.023964,-1.787266,-696.660645,-0.177469,0.000000
2.390000,-0.055855,-696.616150,-0.011805,-0.006793,-0.172552,-0.248455,-0.012657,-1.725519,-696.616150,-0.171138,0.000000
2.770000,-0.049896,-696.660645,-0.011563,-0.006540,-0.166126,-0.221950,-0.011307,-1.661258,-696.660645,-0.164808,0.000000
3.150000,-0.045799,-696.616150,-0.011292,-0.006291,-0.159804,-0.203725,-0.010378,-1.598037,-696.616150,-0.158477,0.000000
3.530000,-0.074478,-696.660645,-0.011037,-0.006041,-0.153438,-0.331295,-0.016877,-1.534382,-696.660645,-0.152146,0.000000
3.910000,-0.101662,-696.705139,-0.010770,-0.005793,-0.147142,-0.452214,-0.023037,-1.471422,-696.705139,-0.145815,0.000000
4.290000,-0.094208,-696.571716,-0.010529,-0.005542,-0.140759,-0.419057,-0.021348,-1.407594,-696.571716,-0.139485,0.000000
4.670000,-0.047661,-696.616150,-0.010261,-0.005293,-0.134446,-0.212006,-0.010800,-1.344460,-696.616150,-0.133154,0.000000
5.050000,-0.038727,-696.749634,-0.010020,-0.005043,-0.128098,-0.172265,-0.008776,-1.280979,-696.749634,-0.126823,0.000000
5.430000,-0.052879,-696.660645,-0.009753,-0.004793,-0.121732,-0.235219,-0.011983,-1.217325,-696.660645,-0.120492,0.000000
5.810000,-0.071869,-696.616150,-0.009507,-0.004548,-0.115514,-0.319689,-0.016286,-1.155144,-696.616150,-0.114162,0.000000
6.190000,-0.058090,-696.705139,-0.009235,-0.004294,-0.109071,-0.258398,-0.013163,-1.090710,-696.705139,-0.107831,0.000000
6.570000,-0.056976,-696.660645,-0.008981,-0.004050,-0.102879,-0.253443,-0.012911,-1.028790,-696.660645,-0.101500,0.000000
6.950000,-0.047661,-696.794128,-0.008731,-0.003799,-0.096496,-0.212006,-0.010800,-0.964962,-696.794128,-0.095169,0.000000
7.330000,-0.049156,-696.749634,-0.008481,-0.003551,-0.090191,-0.218658,-0.011139,-0.901915,-696.749634,-0.088839,0.000000
7.710001,-0.081924,-696.660645,-0.008209,-0.003301,-0.083843,-0.364418,-0.018564,-0.838434,-696.660645,-0.082508,0.000000
8.090000,-0.103149,-696.705139,-0.007968,-0.003054,-0.077573,-0.458832,-0.023374,-0.775733,-696.705139,-0.076177,0.000000
8.470000,-0.159378,-696.749634,-0.007709,-0.002810,-0.071373,-0.708949,-0.036116,-0.713727,-696.749634,-0.069846,0.000000
8.850000,-0.059212,-696.705139,-0.007459,-0.002558,-0.064964,-0.263387,-0.013418,-0.649639,-696.705139,-0.063516,0.000000
9.230000,-0.082664,-696.794128,-0.007187,-0.002307,-0.058598,-0.367710,-0.018732,-0.585984,-696.794128,-0.057185,0.000000
9.610001,-0.057343,-696.749634,-0.006942,-0.002056,-0.052224,-0.255072,-0.012994,-0.522243,-696.749634,-0.050854,0.000000
9.990001,-0.095329,-696.749634,-0.006683,-0.001805,-0.045842,-0.424046,-0.021602,-0.458416,-696.749634,-0.044523,0.000000
10.370001,-0.129585,-696.749634,-0.006411,-0.001547,-0.039294,-0.576424,-0.029364,-0.392940,-696.749634,-0.038193,0.000000
10.750001,-0.104263,-696.838562,-0.006165,-0.001303,-0.033085,-0.463786,-0.023626,-0.330847,-696.838562,-0.031862,0.000000
11.130000,-0.057716,-696.838562,-0.005911,-0.001056,-0.026823,-0.256735,-0.013079,-0.268233,-696.838562,-0.025531,0.000000
11.510000,-0.015640,-696.794128,-0.005652,-0.000806,-0.020484,-0.069571,-0.003544,-0.204839,-696.794128,-0.019200,0.000000
11.890000,-0.033516,-696.794128,-0.005407,-0.000563,-0.014292,-0.149086,-0.007595,-0.142919,-696.794128,-0.012870,0.000000
12.270000,-0.032028,-696.794128,-0.005148,-0.000308,-0.007814,-0.142469,-0.007258,-0.078137,-696.794128,-0.006539,0.000000
12.650001,0.106873,-696.838562,-0.005053,-0.000002,-0.000052,0.475393,0.024218,-0.000520,-696.838562,0.000165,0.000000
13.030001,0.130699,-696.883057,-0.005057,-0.000002,-0.000052,0.581379,0.029617,-0.000520,-696.883057,0.000338,0.000000
13.410001,0.141129,-696.838562,-0.005079,-0.000002,-0.000052,0.627771,0.031980,-0.000520,-696.838562,0.000971,0.000000
13.790001,0.325081,-696.794128,-0.005053,0.000024,0.000598,1.446032,0.073664,0.005984,-696.794128,0.001604,0.000000
14.170001,0.486687,-696.838562,-0.005014,0.000044,0.001127,2.164891,0.110285,0.011274,-696.838562,0.002237,0.000000
14.550001,0.861298,-696.883057,-0.005006,0.000076,0.001934,3.831243,0.195173,0.019339,-696.883057,0.002871,0.000000
14.930000,1.136482,-696.972046,-0.004971,0.000101,0.002567,5.055326,0.257531,0.025670,-696.972046,0.003504,0.000000
15.310000,1.512207,-696.927551,-0.004971,0.000127,0.003226,6.726633,0.342671,0.032261,-696.927551,0.004137,0.000000
15.690001,1.809731,-696.883057,-0.004928,0.000145,0.003677,8.050083,0.410091,0.036770,-696.883057,0.004770,0.000000
16.070002,2.192528,-696.883057,-0.004924,0.000171,0.004345,9.752851,0.496834,0.043448,-696.883057,0.005403,0.000000
16.450001,2.482979,-696.927551,-0.004907,0.000185,0.004709,11.044842,0.562651,0.047090,-696.927551,0.006036,0.000000
16.830000,3.072815,-696.972046,-0.004876,0.000218,0.005533,13.668564,0.696310,0.055329,-696.972046,0.006669,0.000000
17.210001,3.191978,-696.972046,-0.004876,0.000229,0.005828,14.198629,0.723313,0.058278,-696.972046,0.007302,0.000000
17.590000,4.104660,-696.927551,-0.004829,0.000267,0.006782,18.258440,0.930129,0.067817,-696.927551,0.007935,0.000000
17.970001,4.556351,-696.927551,-0.004816,0.000295,0.007501,20.267660,1.032484,0.075015,-696.927551,0.008568,0.000000
18.350000,5.135757,-696.883057,-0.004777,0.000325,0.008256,22.844990,1.163779,0.082560,-696.883057,0.009201,0.000000
18.730001,5.332748,-697.016479,-0.004764,0.000342,0.008698,23.721251,1.208418,0.086983,-697.016479,0.009834,0.000000
19.110001,5.864868,-697.060974,-0.004769,0.000367,0.009331,26.088236,1.328998,0.093314,-697.060974,0.010467,0.000000
19.490002,6.443161,-697.016479,-0.004730,0.000392,0.009947,28.660612,1.460041,0.099471,-697.016479,0.011100,0.000000
19.870001,6.740685,-696.972046,-0.004691,0.000413,0.010502,29.984062,1.527461,0.105021,-696.972046,0.011734,0.000000
20.250002,7.231102,-696.972046,-0.004691,0.000442,0.011231,32.165546,1.638591,0.112306,-696.972046,0.012375,0.000000
20.630001,7.648529,-697.016479,-0.004652,0.000469,0.011907,34.022358,1.733181,0.119070,-697.016479,0.013008,0.000000
21.010000,7.834717,-697.105469,-0.004635,0.000485,0.012323,34.850559,1.775372,0.123233,-697.105469,0.013641,0.000000
21.390001,8.416359,-697.149963,-0.004622,0.000510,0.012956,37.437836,1.907174,0.129563,-697.149963,0.014275,0.000000
21.770000,8.942894,-697.016479,-0.004596,0.000539,0.013685,39.779980,2.026489,0.136848,-697.016479,0.014908,0.000000
22.150002,9.335007,-697.060974,-0.004566,0.000568,0.014422,41.524185,2.115343,0.144220,-697.060974,0.015541,0.000000
22.530001,9.612793,-697.105469,-0.004544,0.000584,0.014838,42.759838,2.178290,0.148382,-697.105469,0.016174,0.000000
22.910002,10.261093,-697.149963,-0.004523,0.000618,0.015697,45.643623,2.325197,0.156968,-697.149963,0.016807,0.000000
23.290001,10.554527,-697.105469,-0.004510,0.000637,0.016174,46.948883,2.391690,0.161738,-697.105469,0.017440,0.000000
23.670002,11.337250,-697.105469,-0.004471,0.000664,0.016876,50.430607,2.569057,0.168762,-697.105469,0.018073,0.000000
24.050001,11.677231,-697.105469,-0.004449,0.000690,0.017518,51.942917,2.646098,0.175180,-697.105469,0.018706,0.000000
24.430000,12.188866,-697.105469,-0.004419,0.000720,0.018298,54.218781,2.762037,0.182985,-697.105469,0.019339,0.000000
24.810001,12.127052,-697.238892,-0.004415,0.000734,0.018654,53.943821,2.748029,0.186540,-697.238892,0.019972,0.000000
25.190001,12.885201,-697.238892,-0.004385,0.000766,0.019461,57.316235,2.919828,0.194605,-697.238892,0.020605,0.000000
25.570002,13.482491,-697.105469,-0.004355,0.000795,0.020189,59.973114,3.055176,0.201890,-697.105469,0.021238,0.000000
25.950001,13.807945,-697.149963,-0.004329,0.000818,0.020787,61.420807,3.128925,0.207874,-697.149963,0.021871,0.000000
26.330002,13.652290,-697.238892,-0.004324,0.000831,0.021108,60.728420,3.093653,0.211083,-697.238892,0.022504,0.000000
26.710001,14.378792,-697.194397,-0.004299,0.000863,0.021923,63.960060,3.258281,0.219235,-697.194397,0.023138,0.000000
27.090002,14.836807,-697.238892,-0.004260,0.000890,0.022600,65.997414,3.362069,0.225999,-697.238892,0.023771,0.000000
27.470001,15.400208,-697.149963,-0.004247,0.000920,0.023380,68.503548,3.489737,0.233804,-697.149963,0.024404,0.000000
27.850000,15.595329,-697.149963,-0.004212,0.000940,0.023866,69.371490,3.533952,0.238660,-697.149963,0.025037,0.000000
28.230001,15.977760,-697.283386,-0.004199,0.000964,0.024482,71.072624,3.620612,0.244818,-697.283386,0.025670,0.000000
28.610001,16.361671,-697.238892,-0.004169,0.000988,0.025089,72.780350,3.707608,0.250888,-697.238892,0.026303,0.000000
28.990002,16.877411,-697.283386,-0.004152,0.001021,0.025930,75.074471,3.824476,0.259300,-697.283386,0.026936,0.000000
29.370001,17.161156,-697.238892,-0.004113,0.001046,0.026572,76.336632,3.888773,0.265718,-697.238892,0.027569,0.000000
29.750002,17.328728,-697.238892,-0.004096,0.001065,0.027057,77.082031,3.926746,0.270574,-697.238892,0.028202,0.000000
30.130001,17.730888,-697.283386,-0.004074,0.001093,0.027769,78.870934,4.017877,0.277686,-697.283386,0.028835,0.000000
30.510002,18.211617,-697.283386,-0.004040,0.001117,0.028384,81.009315,4.126811,0.283843,-697.283386,0.029468,0.000000
30.890001,18.279022,-697.283386,-0.004018,0.001137,0.028879,81.309151,4.142086,0.288786,-697.283386,0.030110,0.000000
31.270002,18.749329,-697.283386,-0.003997,0.001164,0.029564,83.401176,4.248658,0.295637,-697.283386,0.030743,0.000000
31.650002,19.249046,-697.238892,-0.003971,0.001192,0.030275,85.624031,4.361897,0.302748,-697.238892,0.031376,0.000000
32.030003,19.237877,-697.283386,-0.003941,0.001212,0.030778,85.574348,4.359365,0.307778,-697.283386,0.032009,0.000000
32.410000,19.748032,-697.327881,-0.003911,0.001243,0.031584,87.843636,4.474968,0.315844,-697.327881,0.032642,0.000000
32.790001,19.798302,-697.372375,-0.003889,0.001263,0.032087,88.067245,4.486360,0.320873,-697.372375,0.033275,0.000000
33.170002,20.418297,-697.238892,-0.003863,0.001290,0.032764,90.825119,4.626852,0.327638,-697.238892,0.033909,0.000000
33.550003,20.547142,-697.327881,-0.003842,0.001316,0.033423,91.398254,4.656049,0.334229,-697.327881,0.034542,0.000000
33.930000,20.980949,-697.327881,-0.003803,0.001344,0.034143,93.327927,4.754351,0.341427,-697.327881,0.035175,0.000000
34.310001,21.087448,-697.372375,-0.003790,0.001365,0.034672,93.801651,4.778484,0.346717,-697.372375,0.035808,0.000000
34.690002,21.506371,-697.372375,-0.003768,0.001391,0.035331,95.665115,4.873413,0.353308,-697.372375,0.036441,0.000000
35.070004,21.923058,-697.327881,-0.003734,0.001417,0.035999,97.518631,4.967836,0.359985,-697.327881,0.037074,0.000000
35.450001,21.838524,-697.372375,-0.003712,0.001440,0.036588,97.142609,4.948680,0.365882,-697.372375,0.037707,0.000000
35.830002,22.700195,-697.416809,-0.003691,0.001473,0.037412,100.975510,5.143938,0.374121,-697.416809,0.038340,0.000000
36.210003,22.673759,-697.461304,-0.003660,0.001495,0.037984,100.857918,5.137948,0.379845,-697.461304,0.038973,0.000000
36.590000,22.995857,-697.416809,-0.003643,0.001521,0.038635,102.290680,5.210936,0.386349,-697.416809,0.039606,0.000000
36.970001,23.013733,-697.416809,-0.003609,0.001540,0.039121,102.370193,5.214986,0.391205,-697.416809,0.040239,0.000000
37.350002,23.282211,-697.372375,-0.003570,0.001564,0.039736,103.564445,5.275825,0.397363,-697.372375,0.040872,0.000000
37.730003,23.428185,-697.416809,-0.003561,0.001584,0.040231,104.213768,5.308903,0.402306,-697.416809,0.041505,0.000000
38.110001,24.234741,-697.416809,-0.003527,0.001615,0.041028,107.801514,5.491671,0.410285,-697.416809,0.042138,0.000000
38.490002,23.834442,-697.505798,-0.003514,0.001629,0.041367,106.020897,5.400962,0.413667,-697.505798,0.042772,0.000000
38.870003,25.156364,-697.461304,-0.003484,0.001665,0.042295,111.901100,5.700514,0.422946,-697.461304,0.043405,0.000000
39.250000,25.306061,-697.505798,-0.003441,0.001690,0.042936,112.566978,5.734436,0.429363,-697.505798,0.044038,0.000000
39.630001,25.356705,-697.461304,-0.003410,0.001716,0.043587,112.792259,5.745912,0.435868,-697.461304,0.044671,0.000000
40.010002,25.638214,-697.505798,-0.003385,0.001740,0.044202,114.044472,5.809702,0.442025,-697.505798,0.045304,0.000000
40.390003,25.334358,-697.550293,-0.003372,0.001757,0.044619,112.692856,5.740848,0.446188,-697.550293,0.045937,0.000000
40.770000,26.409775,-697.505798,-0.003359,0.001790,0.045477,117.476547,5.984540,0.454773,-697.505798,0.046570,0.000000
41.150002,26.558723,-697.550293,-0.003307,0.001812,0.046015,118.139099,6.018293,0.460150,-697.550293,0.047203,0.000000
41.530003,26.740807,-697.505798,-0.003285,0.001835,0.046613,118.949051,6.059554,0.466134,-697.505798,0.047836,0.000000
41.910004,27.116165,-697.594727,-0.003255,0.001859,0.047229,120.618729,6.144611,0.472291,-697.594727,0.048478,0.000000
42.290001,27.009666,-697.550293,-0.003247,0.001877,0.047671,120.144997,6.120478,0.476714,-697.550293,0.049111,0.000000
42.670002,27.765205,-697.594727,-0.003234,0.001906,0.048417,123.505798,6.291685,0.484172,-697.594727,0.049744,0.000000
43.050003,28.534531,-697.594727,-0.003195,0.001937,0.049206,126.927933,6.466017,0.492064,-697.594727,0.050377,0.000000
43.430000,28.712151,-697.550293,-0.003165,0.001962,0.049822,127.718025,6.506266,0.498221,-697.550293,0.051010,0.000000
43.810001,28.662628,-697.594727,-0.003139,0.001983,0.050360,127.497734,6.495044,0.503598,-697.594727,0.051643,0.000000
44.190002,29.394333,-697.594727,-0.003113,0.002014,0.051158,130.752518,6.660851,0.511576,-697.594727,0.052276,0.000000
44.570004,29.450195,-697.639221,-0.003091,0.002036,0.051704,131.001007,6.673510,0.517040,-697.639221,0.052909,0.000000
44.950001,30.259361,-697.594727,-0.003048,0.002063,0.052398,134.600357,6.856869,0.523978,-697.594727,0.053543,0.000000
45.330002,30.640671,-697.594727,-0.003027,0.002088,0.053040,136.296509,6.943275,0.530395,-697.594727,0.054176,0.000000
45.710003,30.762802,-697.594727,-0.002988,0.002109,0.053577,136.839783,6.970951,0.535772,-697.594727,0.054809,0.000000
46.090004,30.751633,-697.683716,-0.002984,0.002131,0.054124,136.790100,6.968420,0.541236,-697.683716,0.055442,0.000000
46.470001,31.065544,-697.683716,-0.002953,0.002163,0.054930,138.186447,7.039553,0.549301,-697.683716,0.056075,0.000000
46.850002,32.638817,-697.683716,-0.002923,0.002192,0.055685,145.184708,7.396061,0.556846,-697.683716,0.056708,0.000000
47.230003,32.568069,-697.594727,-0.002880,0.002216,0.056283,144.870010,7.380030,0.562829,-697.594727,0.057341,0.000000
47.610001,32.241867,-697.683716,-0.002859,0.002229,0.056621,143.418991,7.306112,0.566212,-697.683716,0.057974,0.000000
47.990002,33.179504,-697.728210,-0.002841,0.002261,0.057436,147.589813,7.518583,0.574364,-697.728210,0.058607,0.000000
48.370003,33.668800,-697.683716,-0.002824,0.002288,0.058121,149.766296,7.629459,0.581215,-697.683716,0.059240,0.000000
48.750004,33.990532,-697.728210,-0.002802,0.002316,0.058815,151.197433,7.702365,0.588152,-697.728210,0.059873,0.000000
49.130001,34.243744,-697.728210,-0.002759,0.002338,0.059379,152.323776,7.759743,0.593789,-697.728210,0.060506,0.000000
49.510002,34.832466,-697.728210,-0.002751,0.002362,0.059986,154.942551,7.893149,0.599860,-697.728210,0.061139,0.000000
49.890003,35.261810,-697.817139,-0.002721,0.002386,0.060610,156.852371,7.990440,0.606104,-697.817139,0.061772,0.000000
50.270004,35.902290,-697.728210,-0.002673,0.002413,0.061296,159.701370,8.135575,0.612955,-697.728210,0.062406,0.000000
50.650002,36.433662,-697.683716,-0.002647,0.002442,0.062015,162.065018,8.255985,0.620153,-697.683716,0.063039,0.000000
51.030003,36.500694,-697.728210,-0.002617,0.002463,0.062570,162.363190,8.271175,0.625703,-697.728210,0.063672,0.000000
51.410004,36.054962,-697.772705,-0.002600,0.002480,0.062995,160.380478,8.170171,0.629953,-697.772705,0.064305,0.000000
51.790001,37.696007,-697.817139,-0.002561,0.002514,0.063862,167.680206,8.542037,0.638625,-697.817139,0.064938,0.000000
52.170002,37.904167,-697.772705,-0.002535,0.002535,0.064400,168.606155,8.589207,0.644002,-697.772705,0.065571,0.000000
52.550003,38.261269,-697.772705,-0.002509,0.002558,0.064981,170.194626,8.670127,0.649812,-697.772705,0.066204,0.000000
52.930004,38.584114,-697.817139,-0.002479,0.002587,0.065701,171.630707,8.743286,0.657010,-697.817139,0.066846,0.000000
53.310001,39.084961,-697.817139,-0.002458,0.002607,0.066221,173.858597,8.856778,0.662214,-697.817139,0.067479,0.000000
53.690002,39.628250,-697.817139,-0.002414,0.002634,0.066898,176.275253,8.979890,0.668978,-697.817139,0.068112,0.000000
54.070004,40.314156,-697.861633,-0.002389,0.002661,0.067592,179.326324,9.135318,0.675916,-697.861633,0.068745,0.000000
54.450001,40.273941,-697.817139,-0.002367,0.002680,0.068060,179.147430,9.126205,0.680599,-697.817139,0.069378,0.000000
54.830002,41.374306,-697.817139,-0.002345,0.002712,0.068875,184.042099,9.375551,0.688751,-697.817139,0.070011,0.000000
55.210003,41.694916,-697.817139,-0.002302,0.002739,0.069578,185.468246,9.448202,0.695775,-697.817139,0.070644,0.000000
55.590004,41.090927,-697.906128,-0.002268,0.002753,0.069924,182.781570,9.311337,0.699244,-697.906128,0.071277,0.000000
55.970001,41.987228,-697.906128,-0.002251,0.002784,0.070714,186.768524,9.514442,0.707136,-697.906128,0.071910,0.000000
56.350002,42.930077,-697.861633,-0.002225,0.002811,0.071399,190.962524,9.728094,0.713987,-697.861633,0.072543,0.000000
56.730003,43.168770,-697.861633,-0.002173,0.002834,0.071980,192.024277,9.782183,0.719797,-697.861633,0.073176,0.000000
57.110004,44.446007,-697.906128,-0.002147,0.002870,0.072899,197.705719,10.071609,0.728990,-697.906128,0.073810,0.000000
57.490002,44.487709,-697.906128,-0.002121,0.002892,0.073463,197.891220,10.081059,0.734627,-697.906128,0.074443,0.000000
57.870003,44.791939,-697.950623,-0.002100,0.002917,0.074087,199.244492,10.149999,0.740871,-697.950623,0.075076,0.000000
58.250004,44.970680,-697.906128,-0.002061,0.002937,0.074607,200.039581,10.190501,0.746074,-697.906128,0.075709,0.000000
58.630001,45.082016,-697.906128,-0.002009,0.002962,0.075223,200.534821,10.215731,0.752232,-697.906128,0.076342,0.000000
59.010002,45.021690,-697.950623,-0.001992,0.002983,0.075761,200.266479,10.202062,0.757608,-697.950623,0.076975,0.000000
59.390003,45.983154,-697.950623,-0.001970,0.003011,0.076489,204.543289,10.419931,0.764893,-697.950623,0.077608,0.000000
59.770004,45.107338,-697.950623,-0.001940,0.003020,0.076715,200.647461,10.221469,0.767148,-697.950623,0.078241,0.000000
60.150002,45.796227,-698.039551,-0.001914,0.003046,0.077365,203.711792,10.377573,0.773652,-698.039551,0.078874,0.000000
60.530003,47.537071,-697.950623,-0.001871,0.003084,0.078328,211.455460,10.772055,0.783278,-697.950623,0.079507,0.000000
60.910004,48.222977,-697.950623,-0.001824,0.003111,0.079030,214.506516,10.927483,0.790303,-697.950623,0.080140,0.000000
61.290005,48.734619,-698.039551,-0.001794,0.003138,0.079715,216.782410,11.043422,0.797154,-698.039551,0.080773,0.000000
61.670002,48.335808,-698.039551,-0.001776,0.003156,0.080158,215.008408,10.953051,0.801577,-698.039551,0.081406,0.000000
62.050003,47.655853,-697.995056,-0.001729,0.003175,0.080643,211.983826,10.798970,0.806433,-697.995056,0.082040,0.000000
62.430004,49.573570,-697.950623,-0.001686,0.003210,0.081537,220.514252,11.233531,0.815366,-697.950623,0.082673,0.000000
62.810001,49.656609,-697.995056,-0.001664,0.003233,0.082109,220.883621,11.252348,0.821089,-697.995056,0.083306,0.000000
63.190002,49.328178,-698.084045,-0.001617,0.003254,0.082647,219.422699,11.177925,0.826466,-698.084045,0.083939,0.000000
63.570004,49.646927,-698.128540,-0.001595,0.003275,0.083193,220.840561,11.250154,0.831930,-698.128540,0.084572,0.000000
63.950005,49.476013,-698.128540,-0.001569,0.003295,0.083705,220.080292,11.211425,0.837046,-698.128540,0.085214,0.000000
64.330002,51.404900,-698.039551,-0.001535,0.003335,0.084719,228.660416,11.648517,0.847193,-698.039551,0.085847,0.000000
64.710007,51.742645,-698.084045,-0.001483,0.003360,0.085344,230.162781,11.725051,0.853437,-698.084045,0.086480,0.000000
65.090004,51.626091,-698.128540,-0.001457,0.003381,0.085881,229.644318,11.698639,0.858814,-698.128540,0.087113,0.000000
65.470001,52.171242,-698.128540,-0.001423,0.003411,0.086627,232.069275,11.822172,0.866272,-698.128540,0.087746,0.000000
65.850006,52.225235,-698.128540,-0.001388,0.003432,0.087174,232.309448,11.834407,0.871735,-698.128540,0.088379,0.000000
66.230003,52.628143,-698.128540,-0.001354,0.003461,0.087911,234.101669,11.925708,0.879107,-698.128540,0.089012,0.000000
66.610001,53.332672,-698.128540,-0.001315,0.003487,0.088561,237.235580,12.085356,0.885611,-698.128540,0.089645,0.000000
66.990005,53.718079,-698.128540,-0.001276,0.003511,0.089177,238.949951,12.172690,0.891768,-698.128540,0.090278,0.000000
67.370003,53.056000,-698.173035,-0.001255,0.003525,0.089532,236.004868,12.022661,0.895324,-698.173035,0.090911,0.000000
67.750000,54.247963,-698.173035,-0.001216,0.003559,0.090408,241.306992,12.292765,0.904083,-698.173035,0.091544,0.000000
68.130005,54.425217,-698.173035,-0.001199,0.003578,0.090885,242.095459,12.332931,0.908853,-698.173035,0.092177,0.000000
68.510002,55.399338,-698.128540,-0.001155,0.003609,0.091657,246.428558,12.553670,0.916571,-698.128540,0.092810,0.000000
68.890007,55.430618,-698.217468,-0.001125,0.003628,0.092143,246.567703,12.560758,0.921427,-698.217468,0.093444,0.000000
69.270004,56.230103,-698.217468,-0.001104,0.003660,0.092975,250.123993,12.741923,0.929753,-698.217468,0.094077,0.000000
69.650002,57.178535,-698.306458,-0.001087,0.003687,0.093643,254.342834,12.956841,0.936430,-698.306458,0.094710,0.000000
70.030006,57.301788,-698.217468,-0.001056,0.003706,0.094120,254.891083,12.984771,0.941200,-698.217468,0.095343,0.000000
70.410004,58.003716,-698.128540,-0.001013,0.003731,0.094770,258.013428,13.143830,0.947704,-698.128540,0.095976,0.000000
70.790001,58.143723,-698.217468,-0.000996,0.003755,0.095386,258.636200,13.175555,0.953862,-698.217468,0.096609,0.000000
71.170006,58.682922,-698.261963,-0.000953,0.003778,0.095967,261.034668,13.297740,0.959672,-698.261963,0.097242,0.000000
71.550003,58.564133,-698.306458,-0.000936,0.003790,0.096271,260.506287,13.270823,0.962707,-698.306458,0.097875,0.000000
71.930000,61.257500,-698.261963,-0.000918,0.003835,0.097407,272.486969,13.881147,0.974068,-698.261963,0.098508,0.000000
72.310005,61.330490,-698.350952,-0.000892,0.003855,0.097918,272.811646,13.897688,0.979185,-698.350952,0.099141,0.000000
72.690002,62.202209,-698.261963,-0.000867,0.003877,0.098482,276.689240,14.095222,0.984821,-698.261963,0.099774,0.000000
73.070000,63.746811,-698.350952,-0.000841,0.003910,0.099323,283.559967,14.445234,0.993234,-698.350952,0.100407,0.000000
73.450005,64.635300,-698.350952,-0.000819,0.003934,0.099922,287.512177,14.646568,0.999217,-698.350952,0.101040,0.000000
73.830002,64.940643,-698.306458,-0.000811,0.003955,0.100451,288.870422,14.715760,1.004508,-698.306458,0.101674,0.000000
74.210007,65.397919,-698.306458,-0.000776,0.003960,0.100581,290.904480,14.819380,1.005808,-698.306458,0.017668,0.000000
74.590004,66.195541,-698.261963,-0.000746,0.003951,0.100347,294.452484,15.000124,1.003467,-698.261963,294.500458,0.000000
74.970001,65.261246,-698.350952,-0.000750,0.003990,0.101344,290.296509,14.788410,1.013440,-698.350952,294.500458,0.000000
75.350006,65.590424,-698.350952,-0.000711,0.004005,0.101734,291.760773,14.863003,1.017342,-698.350952,294.500458,0.000000
75.730003,65.534943,-698.395386,-0.000724,0.004016,0.102003,291.513977,14.850430,1.020031,-698.395386,294.500458,0.000000
76.110001,65.447067,-698.395386,-0.000703,0.004026,0.102263,291.123108,14.830518,1.022632,-698.395386,294.500458,0.000000
76.490005,65.232208,-698.350952,-0.000690,0.004032,0.102419,290.167358,14.781830,1.024194,-698.350952,294.500458,0.000000
76.870003,65.599365,-698.395386,-0.000673,0.004044,0.102723,291.800537,14.865029,1.027229,-698.395386,294.500458,0.000000
77.250000,64.973038,-698.395386,-0.000673,0.004046,0.102775,289.014496,14.723101,1.027749,-698.395386,294.500458,0.000000
77.630005,65.285828,-698.439880,-0.000668,0.004056,0.103018,290.405853,14.793981,1.030177,-698.439880,294.500458,0.000000
78.010002,65.312637,-698.395386,-0.000651,0.004063,0.103209,290.525116,14.800055,1.032085,-698.395386,294.500458,0.000000
78.390007,64.945847,-698.395386,-0.000651,0.004064,0.103235,288.893555,14.716939,1.032346,-698.395386,294.500458,0.000000
78.770004,65.889450,-698.395386,-0.000647,0.004071,0.103399,293.090912,14.930763,1.033993,-698.395386,294.500458,0.000000
79.150002,65.289551,-698.484375,-0.000634,0.004071,0.103399,290.422424,14.794824,1.033993,-698.484375,294.500458,0.000000
79.530006,64.700089,-698.395386,-0.000647,0.004071,0.103399,287.800354,14.661249,1.033993,-698.395386,294.500458,0.000000
79.910004,65.757996,-698.439880,-0.000629,0.004080,0.103633,292.506165,14.900975,1.036335,-698.439880,294.500458,0.000000
80.290001,65.226624,-698.395386,-0.000612,0.004080,0.103642,290.142517,14.780564,1.036421,-698.395386,294.500458,0.000000
80.670006,64.736572,-698.484375,-0.000608,0.004080,0.103642,287.962646,14.669518,1.036421,-698.484375,294.500458,0.000000
81.050003,66.269638,-698.528870,-0.000595,0.004077,0.103547,294.782074,15.016914,1.035468,-698.528870,294.500458,0.000000
81.430000,65.819809,-698.528870,-0.000586,0.004077,0.103547,292.781128,14.914982,1.035468,-698.528870,294.500458,0.000000
81.810005,65.374832,-698.528870,-0.000604,0.004077,0.103555,290.801788,14.814149,1.035554,-698.528870,294.500458,0.000000
82.190002,65.146194,-698.528870,-0.000608,0.004104,0.104249,289.784760,14.762339,1.042492,-698.528870,294.500458,0.000000
82.570007,65.213593,-698.484375,-0.000591,0.004110,0.104388,290.084534,14.777611,1.043880,-698.484375,294.500458,0.000000
82.950005,64.937668,-698.528870,-0.000578,0.004110,0.104397,288.857178,14.715086,1.043966,-698.528870,294.500458,0.000000
83.330002,65.675323,-698.573364,-0.000578,0.004122,0.104700,292.138428,14.882241,1.047001,-698.573364,294.500458,0.000000
83.710007,65.510376,-698.573364,-0.000586,0.004122,0.104700,291.404694,14.844864,1.047001,-698.573364,294.500458,0.000000
84.090004,65.269440,-698.573364,-0.000569,0.004122,0.104709,290.332977,14.790266,1.047088,-698.573364,294.500458,0.000000
84.470001,65.033356,-698.573364,-0.000565,0.004123,0.104717,289.282806,14.736769,1.047175,-698.573364,294.500458,0.000000
84.850006,65.645172,-698.573364,-0.000565,0.004133,0.104978,292.004303,14.875408,1.049777,-698.573364,294.500458,0.000000
85.230003,65.558411,-698.617798,-0.000582,0.004133,0.104978,291.618378,14.855748,1.049777,-698.617798,294.500458,0.000000
85.610001,65.366638,-698.706787,-0.000569,0.004133,0.104978,290.765320,14.812292,1.049777,-698.706787,294.500458,0.000000
85.990005,65.180817,-698.662292,-0.000560,0.004133,0.104978,289.938751,14.770185,1.049777,-698.662292,294.500458,0.000000
86.370003,65.025909,-698.528870,-0.000556,0.004134,0.105004,289.249695,14.735082,1.050037,-698.528870,294.500458,0.000000
86.750008,64.851639,-698.617798,-0.000556,0.004134,0.105004,288.474487,14.695591,1.050037,-698.617798,294.500458,0.000000
87.130005,65.681656,-698.662292,-0.000556,0.004149,0.105377,292.166595,14.883677,1.053766,-698.662292,294.500458,0.000000
87.510002,65.717407,-698.706787,-0.000565,0.004146,0.105316,292.325623,14.891778,1.053159,-698.706787,294.500458,0.000000
87.890007,65.563248,-698.617798,-0.000552,0.004146,0.105316,291.639893,14.856845,1.053159,-698.617798,294.500458,0.000000
88.270004,65.422485,-698.617798,-0.000560,0.004146,0.105316,291.013763,14.824946,1.053159,-698.617798,294.500458,0.000000
88.650002,65.272797,-698.662292,-0.000548,0.004146,0.105316,290.347900,14.791027,1.053159,-698.662292,294.500458,0.000000
89.030006,65.088104,-698.662292,-0.000535,0.004147,0.105325,289.526337,14.749176,1.053246,-698.662292,294.500458,0.000000
89.410004,64.963348,-698.751282,-0.000539,0.004147,0.105325,288.971405,14.720905,1.053246,-698.751282,294.500458,0.000000
89.790001,64.814026,-698.706787,-0.000543,0.004147,0.105325,288.307190,14.687069,1.053246,-698.706787,294.500458,0.000000
90.170006,65.604202,-698.662292,-0.000552,0.004158,0.105619,291.822052,14.866125,1.056194,-698.662292,294.500458,0.000000
90.550003,65.576645,-698.617798,-0.000539,0.004158,0.105619,291.699493,14.859879,1.056194,-698.617798,294.500458,0.000000
90.930008,65.496964,-698.706787,-0.000543,0.004158,0.105619,291.345032,14.841825,1.056194,-698.706787,294.500458,0.000000
91.310005,65.350250,-698.751282,-0.000543,0.004158,0.105619,290.692444,14.808578,1.056194,-698.751282,294.500458,0.000000
91.690002,65.251938,-698.706787,-0.000539,0.004159,0.105628,290.255127,14.786300,1.056281,-698.706787,294.500458,0.000000
92.070007,65.145447,-698.706787,-0.000517,0.004159,0.105628,289.781433,14.762170,1.056281,-698.706787,294.500458,0.000000
92.450005,65.057190,-698.706787,-0.000526,0.004159,0.105637,289.388824,14.742170,1.056368,-698.706787,294.500458,0.000000
92.830002,64.957397,-698.795715,-0.000552,0.004159,0.105637,288.944946,14.719557,1.056368,-698.795715,294.500458,0.000000
93.210007,64.826691,-698.795715,-0.000548,0.004159,0.105637,288.363525,14.689939,1.056368,-698.795715,294.500458,0.000000
93.590004,65.250458,-698.751282,-0.000539,0.004170,0.105914,290.248535,14.785965,1.059143,-698.751282,294.500458,0.000000
93.970001,65.566605,-698.795715,-0.000522,0.004170,0.105906,291.654816,14.857605,1.059056,-698.795715,294.500458,0.000000
94.350006,65.534576,-698.795715,-0.000517,0.004169,0.105897,291.512360,14.850348,1.058969,-698.795715,294.500458,0.000000
94.730003,65.445572,-698.795715,-0.000526,0.004169,0.105897,291.116455,14.830179,1.058969,-698.795715,294.500458,0.000000
95.110008,65.339447,-698.840210,-0.000526,0.004170,0.105906,290.644379,14.806130,1.059056,-698.840210,294.500458,0.000000
95.490005,65.285461,-698.795715,-0.000522,0.004170,0.105906,290.404236,14.793897,1.059056,-698.795715,294.500458,0.000000
95.870003,65.206879,-698.795715,-0.000539,0.004170,0.105906,290.054687,14.776090,1.059056,-698.795715,294.500458,0.000000
96.250008,65.120865,-698.751282,-0.000517,0.004170,0.105914,289.672089,14.756599,1.059143,-698.751282,294.500458,0.000000
96.630005,65.032608,-698.840210,-0.000504,0.004170,0.105914,289.279480,14.736600,1.059143,-698.840210,294.500458,0.000000
97.010002,64.961868,-698.884705,-0.000522,0.004170,0.105914,288.964813,14.720570,1.059143,-698.884705,294.500458,0.000000
97.390007,64.887390,-698.973694,-0.000513,0.004170,0.105923,288.633514,14.703692,1.059229,-698.973694,294.500458,0.000000
97.770004,64.801743,-698.884705,-0.000535,0.004170,0.105923,288.252533,14.684285,1.059229,-698.884705,294.500458,0.000000
98.150002,64.740295,-698.840210,-0.000526,0.004170,0.105923,287.979218,14.670361,1.059229,-698.840210,294.500458,0.000000
98.530006,64.664337,-698.884705,-0.000509,0.004170,0.105923,287.641327,14.653148,1.059229,-698.884705,294.500458,0.000000
98.910004,64.581299,-698.929199,-0.000517,0.004170,0.105923,287.271973,14.634331,1.059229,-698.929199,294.500458,0.000000
99.290001,64.501236,-698.929199,-0.000509,0.004170,0.105923,286.915833,14.616189,1.059229,-698.929199,294.500458,0.000000
99.670006,66.137451,-698.929199,-0.000517,0.004178,0.106131,294.194061,14.986961,1.061311,-698.929199,294.500458,0.000000
100.050003,66.030579,-698.929199,-0.000504,0.004177,0.106096,293.718689,14.962744,1.060964,-698.929199,294.500458,0.000000
100.430008,65.867096,-698.929199,-0.000509,0.004177,0.106096,292.991486,14.925697,1.060964,-698.929199,294.500458,0.000000
100.810005,65.853699,-698.973694,-0.000504,0.004177,0.106096,292.931885,14.922662,1.060964,-698.973694,294.500458,0.000000
101.190002,65.761719,-699.018127,-0.000504,0.004177,0.106096,292.522736,14.901818,1.060964,-699.018127,294.500458,0.000000
101.570007,65.614639,-699.018127,-0.000522,0.004177,0.106096,291.868500,14.868489,1.060964,-699.018127,294.500458,0.000000
101.950005,65.563995,-698.973694,-0.000517,0.004177,0.106096,291.643219,14.857014,1.060964,-698.973694,294.500458,0.000000
102.330002,65.495102,-698.929199,-0.000513,0.004177,0.106096,291.336761,14.841402,1.060964,-698.929199,294.500458,0.000000
102.710007,65.416153,-699.018127,-0.000509,0.004177,0.106105,290.985596,14.823512,1.061051,-699.018127,294.500458,0.000000
103.090004,65.331253,-699.062622,-0.000504,0.004177,0.106105,290.607941,14.804274,1.061051,-699.062622,294.500458,0.000000
103.470001,65.270569,-699.062622,-0.000496,0.004178,0.106114,290.337982,14.790523,1.061137,-699.062622,294.500458,0.000000
103.850006,65.233322,-698.973694,-0.000517,0.004178,0.106114,290.172302,14.782083,1.061137,-698.973694,294.500458,0.000000
104.230003,65.134644,-699.018127,-0.000500,0.004178,0.106122,289.733368,14.759721,1.061224,-699.018127,294.500458,0.000000
104.610008,65.083252,-699.062622,-0.000517,0.004178,0.106122,289.504761,14.748075,1.061224,-699.062622,294.500458,0.000000
104.990005,65.024796,-699.107117,-0.000496,0.004182,0.106218,289.244751,14.734829,1.062178,-699.107117,294.500458,0.000000
105.370003,64.977875,-699.062622,-0.000496,0.004182,0.106226,289.036011,14.724196,1.062265,-699.062622,294.500458,0.000000
105.750008,64.932068,-699.062622,-0.000509,0.004182,0.106226,288.832275,14.713818,1.062265,-699.062622,294.500458,0.000000
106.130005,64.857605,-699.062622,-0.000513,0.004182,0.106226,288.501038,14.696943,1.062265,-699.062622,294.500458,0.000000
106.510002,64.795044,-699.151611,-0.000492,0.004182,0.106226,288.222748,14.682767,1.062265,-699.151611,294.500458,0.000000
106.890007,65.493240,-699.196045,-0.000500,0.004193,0.106513,291.328491,14.840981,1.065127,-699.196045,294.500458,0.000000
107.270004,65.517075,-699.151611,-0.000504,0.004193,0.106513,291.434509,14.846381,1.065127,-699.151611,294.500458,0.000000
107.650002,65.508133,-699.107117,-0.000496,0.004193,0.106513,291.394714,14.844355,1.065127,-699.107117,294.500458,0.000000
108.030006,65.497330,-699.151611,-0.000496,0.004193,0.106513,291.346680,14.841908,1.065127,-699.151611,294.500458,0.000000
108.410004,65.440735,-699.151611,-0.000492,0.004193,0.106513,291.094940,14.829082,1.065127,-699.151611,294.500458,0.000000
108.790009,65.394562,-699.151611,-0.000496,0.004193,0.106513,290.889526,14.818619,1.065127,-699.151611,294.500458,0.000000
109.170006,65.349503,-699.240540,-0.000513,0.004193,0.106513,290.689117,14.808409,1.065127,-699.240540,294.500458,0.000000
109.550003,65.309662,-699.151611,-0.000504,0.004193,0.106513,290.511871,14.799381,1.065127,-699.151611,294.500458,0.000000
109.930008,65.296249,-699.151611,-0.000500,0.004193,0.106513,290.452209,14.796342,1.065127,-699.151611,294.500458,0.000000
110.310005,65.253799,-699.151611,-0.000496,0.004193,0.106513,290.263397,14.786722,1.065127,-699.151611,294.500458,0.000000
110.690002,65.202042,-699.196045,-0.000492,0.004193,0.106513,290.033173,14.774994,1.065127,-699.196045,294.500458,0.000000
111.070007,65.177094,-699.240540,-0.000492,0.004193,0.106513,289.922180,14.769341,1.065127,-699.240540,294.500458,0.000000
111.450005,65.134644,-699.285034,-0.000496,0.004193,0.106513,289.733368,14.759721,1.065127,-699.285034,294.500458,0.000000
111.830002,65.072464,-699.196045,-0.000483,0.004193,0.106513,289.456787,14.745631,1.065127,-699.196045,294.500458,0.000000
112.210007,65.049377,-699.196045,-0.000487,0.004193,0.106513,289.354095,14.740399,1.065127,-699.196045,294.500458,0.000000
112.590004,65.010269,-699.285034,-0.000492,0.004193,0.106513,289.180115,14.731537,1.065127,-699.285034,294.500458,0.000000
112.970009,64.977509,-699.285034,-0.000496,0.004193,0.106513,289.034393,14.724113,1.065127,-699.285034,294.500458,0.000000
113.350006,64.946228,-699.285034,-0.000487,0.004193,0.106513,288.895264,14.717026,1.065127,-699.285034,294.500458,0.000000
113.730003,64.901169,-699.240540,-0.000487,0.004194,0.106521,288.694824,14.706815,1.065213,-699.240540,294.500458,0.000000
114.110008,64.897812,-699.240540,-0.000483,0.004194,0.106521,288.679871,14.706054,1.065213,-699.240540,294.500458,0.000000
114.490005,64.837494,-699.285034,-0.000487,0.004194,0.106521,288.411591,14.692387,1.065213,-699.285034,294.500458,0.000000
114.870003,64.806961,-699.329529,-0.000492,0.004194,0.106521,288.275757,14.685467,1.065213,-699.329529,294.500458,0.000000
115.250008,65.752045,-699.329529,-0.000487,0.004206,0.106825,292.479706,14.899627,1.068249,-699.329529,294.500458,0.000000
115.630005,65.769165,-699.329529,-0.000496,0.004206,0.106825,292.555847,14.903506,1.068249,-699.329529,294.500458,0.000000
116.010002,65.779602,-699.285034,-0.000479,0.004206,0.106825,292.602295,14.905870,1.068249,-699.285034,294.500458,0.000000
116.390007,65.760605,-699.285034,-0.000483,0.004206,0.106825,292.517792,14.901566,1.068249,-699.285034,294.500458,0.000000
116.770004,65.756134,-699.285034,-0.000492,0.004206,0.106825,292.497894,14.900553,1.068249,-699.285034,294.500458,0.000000
117.150009,65.695816,-699.374023,-0.000504,0.004206,0.106825,292.229584,14.886885,1.068249,-699.374023,294.500458,0.000000
117.530006,65.658203,-699.329529,-0.000496,0.004206,0.106825,292.062286,14.878362,1.068249,-699.329529,294.500458,0.000000
117.910004,65.636597,-699.240540,-0.000483,0.004206,0.106825,291.966156,14.873466,1.068249,-699.240540,294.500458,0.000000
118.290009,65.593033,-699.329529,-0.000483,0.004206,0.106825,291.772369,14.863594,1.068249,-699.329529,294.500458,0.000000
118.670006,65.580368,-699.374023,-0.000474,0.004206,0.106825,291.716034,14.860724,1.068249,-699.374023,294.500458,0.000000
119.050003,65.557281,-699.374023,-0.000492,0.004206,0.106825,291.613342,14.855493,1.068249,-699.374023,294.500458,0.000000
119.430008,65.527496,-699.374023,-0.000500,0.004206,0.106825,291.480865,14.848743,1.068249,-699.374023,294.500458,0.000000
119.810005,65.504776,-699.329529,-0.000487,0.004206,0.106825,291.379791,14.843594,1.068249,-699.329529,294.500458,0.000000
120.190002,65.460098,-699.462952,-0.000474,0.004206,0.106825,291.181061,14.833470,1.068249,-699.462952,294.500458,0.000000
120.570007,65.442963,-699.418457,-0.000487,0.004206,0.106825,291.104828,14.829587,1.068249,-699.418457,294.500458,0.000000
120.950005,65.383392,-699.418457,-0.000492,0.004206,0.106825,290.839844,14.816088,1.068249,-699.418457,294.500458,0.000000
121.330009,65.353973,-699.462952,-0.000483,0.004206,0.106825,290.708984,14.809422,1.068249,-699.462952,294.500458,0.000000
121.710007,65.327911,-699.418457,-0.000474,0.004206,0.106825,290.593048,14.803516,1.068249,-699.418457,294.500458,0.000000
122.090004,65.298111,-699.418457,-0.000474,0.004206,0.106825,290.460510,14.796764,1.068249,-699.418457,294.500458,0.000000
122.470009,65.281738,-699.507446,-0.000474,0.004206,0.106825,290.387665,14.793054,1.068249,-699.507446,294.500458,0.000000
122.850006,65.243378,-699.507446,-0.000474,0.004206,0.106825,290.217041,14.784361,1.068249,-699.507446,294.500458,0.000000
123.230003,65.209488,-699.418457,-0.000496,0.004206,0.106825,290.066284,14.776682,1.068249,-699.418457,294.500458,0.000000
123.610008,65.185287,-699.462952,-0.000483,0.004206,0.106825,289.958649,14.771197,1.068249,-699.462952,294.500458,0.000000
123.990005,65.136505,-699.462952,-0.000474,0.004206,0.106825,289.741638,14.760143,1.068249,-699.462952,294.500458,0.000000
124.370003,65.119003,-699.507446,-0.000470,0.004206,0.106825,289.663788,14.756177,1.068249,-699.507446,294.500458,0.000000
124.750008,65.068359,-699.507446,-0.000487,0.004206,0.106825,289.438507,14.744701,1.068249,-699.507446,294.500458,0.000000
125.130005,65.053467,-699.507446,-0.000474,0.004206,0.106825,289.372284,14.741326,1.068249,-699.507446,294.500458,0.000000
125.510010,65.017715,-699.507446,-0.000487,0.004206,0.106825,289.213257,14.733225,1.068249,-699.507446,294.500458,0.000000
125.890007,65.003937,-699.507446,-0.000487,0.004206,0.106825,289.151947,14.730103,1.068249,-699.507446,294.500458,0.000000
126.270004,64.972656,-699.551941,-0.000492,0.004206,0.106825,289.012817,14.723015,1.068249,-699.551941,294.500458,0.000000
126.650009,64.957031,-699.596375,-0.000483,0.004206,0.106825,288.943298,14.719474,1.068249,-699.596375,294.500458,0.000000
127.030006,64.917557,-699.551941,-0.000474,0.004206,0.106825,288.767700,14.710528,1.068249,-699.551941,294.500458,0.000000
127.410004,64.891113,-699.596375,-0.000470,0.004206,0.106825,288.650085,14.704536,1.068249,-699.596375,294.500458,0.000000
127.790009,64.846802,-699.507446,-0.000466,0.004206,0.106825,288.452972,14.694495,1.068249,-699.507446,294.500458,0.000000
128.170013,64.827438,-699.596375,-0.000479,0.004206,0.106825,288.366852,14.690108,1.068249,-699.596375,294.500458,0.000000
128.550003,64.786102,-699.640869,-0.000479,0.004206,0.106825,288.182983,14.680740,1.068249,-699.640869,294.500458,0.000000
128.930008,64.777908,-699.640869,-0.000492,0.004206,0.106825,288.146515,14.678884,1.068249,-699.640869,294.500458,0.000000
129.310013,64.764511,-699.596375,-0.000479,0.004206,0.106825,288.086945,14.675848,1.068249,-699.596375,294.500458,0.000000
129.690002,64.719818,-699.596375,-0.000470,0.004206,0.106825,287.888123,14.665721,1.068249,-699.596375,294.500458,0.000000
130.070007,64.701202,-699.596375,-0.000474,0.004206,0.106825,287.805328,14.661502,1.068249,-699.596375,294.500458,0.000000
130.450012,65.948273,-699.685364,-0.000466,0.004211,0.106955,293.352570,14.944092,1.069549,-699.685364,294.500458,0.000000
130.830002,65.897263,-699.640869,-0.000474,0.004211,0.106955,293.125671,14.932533,1.069549,-699.640869,294.500458,0.000000
131.210007,65.868225,-699.596375,-0.000474,0.004211,0.106955,292.996490,14.925953,1.069549,-699.596375,294.500458,0.000000
131.590012,65.867844,-699.640869,-0.000487,0.004211,0.106955,292.994812,14.925867,1.069549,-699.640869,294.500458,0.000000
131.970001,65.831726,-699.729858,-0.000461,0.004211,0.106955,292.834137,14.917682,1.069549,-699.729858,294.500458,0.000000
132.350006,65.793365,-699.774292,-0.000470,0.004211,0.106955,292.663513,14.908989,1.069549,-699.774292,294.500458,0.000000
132.730011,65.770660,-699.729858,-0.000483,0.004211,0.106955,292.562500,14.903845,1.069549,-699.729858,294.500458,0.000000
133.110001,65.744217,-699.685364,-0.000470,0.004211,0.106955,292.444885,14.897853,1.069549,-699.685364,294.500458,0.000000
133.490005,65.679794,-699.729858,-0.000470,0.004211,0.106955,292.158325,14.883254,1.069549,-699.729858,294.500458,0.000000
133.870010,65.676819,-699.729858,-0.000470,0.004211,0.106955,292.145081,14.882580,1.069549,-699.729858,294.500458,0.000000
134.250000,65.622086,-699.774292,-0.000470,0.004211,0.106955,291.901611,14.870177,1.069549,-699.774292,294.500458,0.000000
134.630005,65.604584,-699.774292,-0.000492,0.004211,0.106955,291.823761,14.866211,1.069549,-699.774292,1681.640747,0.000000
135.010010,65.528992,-699.774292,-0.000479,0.004207,0.106851,291.487518,14.849082,1.068509,-699.774292,0.106634,0.000000
135.389999,65.527496,-699.729858,-0.000470,0.004189,0.106391,291.480865,14.848743,1.063912,-699.729858,0.106001,0.000000
135.770004,65.381149,-699.863281,-0.000466,0.004168,0.105871,290.829865,14.815579,1.058709,-699.863281,0.105368,0.000000
136.150009,65.369247,-699.818787,-0.000461,0.004147,0.105325,290.776947,14.812883,1.053246,-699.818787,0.104735,0.000000
136.530014,65.322327,-699.774292,-0.000470,0.004118,0.104605,290.568207,14.802251,1.046048,-699.774292,0.104102,0.000000
136.910004,65.306305,-699.818787,-0.000466,0.004101,0.104162,290.496948,14.798620,1.041625,-699.818787,0.103469,0.000000
137.290009,65.255661,-699.774292,-0.000470,0.004073,0.103443,290.271667,14.787145,1.034427,-699.774292,0.102836,0.000000
137.670013,65.224014,-699.863281,-0.000470,0.004049,0.102844,290.130920,14.779973,1.028443,-699.863281,0.102203,0.000000
138.050003,65.119751,-699.863281,-0.000479,0.004031,0.102385,289.667114,14.756347,1.023847,-699.863281,0.101569,0.000000
138.430008,65.009521,-699.863281,-0.000466,0.003999,0.101578,289.176788,14.731368,1.015781,-699.863281,0.100936,0.000000
138.810013,64.718704,-699.818787,-0.000457,0.003976,0.100997,287.883179,14.665468,1.009971,-699.818787,0.100303,0.000000
139.190002,63.865967,-699.863281,-0.000461,0.003947,0.100260,284.089996,14.472235,1.002600,-699.863281,0.099670,0.000000
139.570007,63.322311,-699.818787,-0.000457,0.003934,0.099913,281.671722,14.349041,0.999131,-699.818787,0.099037,0.000000
139.950012,62.312805,-699.907776,-0.000453,0.003913,0.099384,277.181213,14.120283,0.993841,-699.907776,0.098404,0.000000
140.330002,61.819412,-699.952271,-0.000466,0.003904,0.099167,274.986481,14.008479,0.991673,-699.952271,0.097771,0.000000
140.710007,58.902992,-699.952271,-0.000457,0.003857,0.097979,262.013580,13.347609,0.979792,-699.952271,0.097138,0.000000
141.090012,56.962189,-699.863281,-0.000466,0.003833,0.097355,253.380463,12.907817,0.973548,-699.863281,0.096505,0.000000
141.470001,55.025108,-699.907776,-0.000457,0.003810,0.096782,244.763901,12.468868,0.967824,-699.907776,0.095872,0.000000
141.850006,53.030304,-699.996704,-0.000457,0.003789,0.096236,235.890579,12.016839,0.962360,-699.996704,0.095239,0.000000
142.230011,50.497429,-699.907776,-0.000466,0.003762,0.095560,224.623779,11.442882,0.955596,-699.907776,0.094606,0.000000
142.610001,47.794380,-699.907776,-0.000457,0.003738,0.094935,212.600021,10.830361,0.949352,-699.907776,0.093973,0.000000
142.990005,45.239899,-699.952271,-0.000444,0.003714,0.094337,201.237122,10.251508,0.943368,-699.952271,0.093331,0.000000
143.370010,42.462006,-699.907776,-0.000457,0.003689,0.093712,188.880432,9.622027,0.937124,-699.907776,0.092698,0.000000
143.750000,40.421028,-699.952271,-0.000457,0.003671,0.093244,179.801712,9.159536,0.932441,-699.952271,0.092065,0.000000
144.130005,37.307625,-699.996704,-0.000461,0.003641,0.092472,165.952606,8.454028,0.924723,-699.996704,0.091432,0.000000
144.510010,34.697296,-699.996704,-0.000461,0.003615,0.091831,154.341278,7.862520,0.918305,-699.996704,0.090799,0.000000
144.889999,31.987907,-699.952271,-0.000457,0.003589,0.091154,142.289322,7.248564,0.911541,-699.952271,0.090165,0.000000
145.270004,29.498230,-699.996704,-0.000461,0.003567,0.090608,131.214676,6.684394,0.906077,-699.996704,0.089532,0.000000
145.650009,27.027534,-699.952271,-0.000461,0.003545,0.090044,120.224480,6.124527,0.900440,-699.952271,0.088899,0.000000
146.030014,23.762199,-700.085693,-0.000470,0.003514,0.089246,105.699539,5.384591,0.892462,-700.085693,0.088266,0.000000
146.410004,20.829025,-700.041199,-0.000487,0.003486,0.088544,92.652130,4.719925,0.885437,-700.041199,0.087633,0.000000
146.790009,18.633148,-699.996704,-0.000487,0.003465,0.088006,82.884384,4.222332,0.880061,-699.996704,0.087000,0.000000
147.170013,15.947220,-699.996704,-0.000487,0.003441,0.087399,70.936775,3.613692,0.873990,-699.996704,0.086367,0.000000
147.550003,13.635536,-700.041199,-0.000479,0.003416,0.086766,60.653893,3.089857,0.867659,-700.041199,0.085734,0.000000
147.930008,10.356049,-700.130188,-0.000500,0.003389,0.086072,46.066006,2.346714,0.860721,-700.130188,0.085101,0.000000
148.310013,7.552460,-700.085693,-0.000500,0.003362,0.085387,33.595020,1.711412,0.853870,-700.085693,0.084468,0.000000
148.690002,5.836189,-700.085693,-0.000500,0.003344,0.084945,25.960667,1.322499,0.849448,-700.085693,0.083835,0.000000
149.070007,3.153992,-700.130188,-0.000504,0.003317,0.084260,14.029655,0.714705,0.842597,-700.130188,0.083202,0.000000
149.450012,1.046738,-700.130188,-0.000513,0.003293,0.083653,4.656122,0.237194,0.836526,-700.130188,0.082569,0.000000
149.830002,-1.434380,-700.130188,-0.000530,0.003268,0.083011,-6.380439,-0.325035,0.830108,-700.130188,0.081935,0.000000
150.210007,-0.505310,-700.130188,-0.000591,0.003234,0.082144,-2.247731,-0.114505,0.821436,-700.130188,0.081302,0.000000
150.590012,-0.223427,-700.130188,-0.000621,0.003215,0.081667,-0.993852,-0.050629,0.816666,-700.130188,0.080669,0.000000
150.970001,-0.131073,-700.085693,-0.000655,0.003187,0.080938,-0.583042,-0.029702,0.809382,-700.085693,0.080036,0.000000
151.350006,-0.065910,-700.219116,-0.000703,0.003164,0.080374,-0.293184,-0.014935,0.803745,-700.219116,0.079403,0.000000
151.730011,-0.076706,-700.174622,-0.000733,0.003143,0.079828,-0.341205,-0.017382,0.798281,-700.174622,0.078770,0.000000
152.110001,-0.075218,-700.219116,-0.000772,0.003117,0.079169,-0.334587,-0.017045,0.791690,-700.219116,0.078137,0.000000
152.490005,-0.053253,-700.174622,-0.000832,0.003093,0.078553,-0.236882,-0.012067,0.785533,-700.174622,0.077504,0.000000
152.870010,0.020477,-700.174622,-0.000901,0.003064,0.077834,0.091088,0.004640,0.778335,-700.174622,0.076871,0.000000
153.250000,0.043198,-700.219116,-0.000953,0.003040,0.077209,0.192153,0.009789,0.772091,-700.219116,0.076238,0.000000
153.630005,0.014153,-700.263611,-0.001022,0.003014,0.076567,0.062954,0.003207,0.765673,-700.263611,0.075605,0.000000
154.010010,0.039101,-700.174622,-0.001104,0.002992,0.075995,0.173928,0.008860,0.759950,-700.174622,0.075830,0.000000
154.200012,0.065163,-700.219116,-0.001104,0.002992,0.076004,0.289858,0.014766,0.760037,-700.219116,0.075830,0.000000