File: Data/compression 33/AutoNoHeating-10-33-reverse-1-3_11152024_173801.csv
Time (sec),S:Load (lbs),S:HL1 (DIM),S:LVDT (in),S:Position (in),Ch:Position (mm),Ch:Load (N),Ch:Stress (MPa),Ch:Strain (mm/mm),Ch:HL1 (DIM),Set Point (),Cycles ()
0.110000,-0.140388,-651.645935,-0.012650,-0.007672,-0.194866,-0.624479,-0.031812,-1.948656,-651.645935,-0.194640,0.000000
0.500000,-0.065163,-651.690430,-0.012659,-0.007604,-0.193140,-0.289858,-0.014766,-1.931398,-651.690430,-0.192437,0.000000
0.890000,-0.075966,-651.690430,-0.012538,-0.007377,-0.187364,-0.337913,-0.017214,-1.873641,-651.690430,-0.185933,0.000000
1.280000,-0.074104,-651.690430,-0.012258,-0.007111,-0.180608,-0.329632,-0.016792,-1.806084,-651.690430,-0.179446,0.000000
1.670000,-0.096069,-651.734924,-0.012021,-0.006863,-0.174321,-0.427338,-0.021770,-1.743210,-651.734924,-0.172942,0.000000
2.060000,-0.053619,-651.690430,-0.011749,-0.006605,-0.167765,-0.238511,-0.012150,-1.677648,-651.690430,-0.166438,0.000000
2.450000,-0.036491,-651.779358,-0.011469,-0.006344,-0.161139,-0.162322,-0.008269,-1.611392,-651.779358,-0.159951,0.000000
2.840000,-0.051392,-651.734924,-0.011219,-0.006092,-0.154739,-0.228601,-0.011646,-1.547391,-651.734924,-0.153447,0.000000
3.230000,-0.062187,-651.690430,-0.010964,-0.005841,-0.148356,-0.276622,-0.014092,-1.483563,-651.690430,-0.146960,0.000000
3.620000,-0.068146,-651.734924,-0.010684,-0.005578,-0.141687,-0.303127,-0.015442,-1.416873,-651.734924,-0.140456,0.000000
4.010000,-0.042076,-651.734924,-0.010434,-0.005323,-0.135209,-0.187164,-0.009535,-1.352092,-651.734924,-0.133952,0.000000
4.400000,-0.027557,-651.823853,-0.010162,-0.005068,-0.128740,-0.122581,-0.006245,-1.287397,-651.823853,-0.127465,0.000000
4.790000,-0.029793,-651.690430,-0.009895,-0.004815,-0.122305,-0.132525,-0.006751,-1.223048,-651.690430,-0.120961,0.000000
5.180000,-0.052505,-651.779358,-0.009645,-0.004560,-0.115827,-0.233556,-0.011898,-1.158267,-651.779358,-0.114474,0.000000
5.570000,-0.056602,-651.779358,-0.009356,-0.004300,-0.109218,-0.251780,-0.012826,-1.092184,-651.779358,-0.107970,0.000000
5.960001,-0.045059,-651.779358,-0.009110,-0.004045,-0.102732,-0.200433,-0.010211,-1.027316,-651.779358,-0.101465,0.000000
6.350000,-0.020485,-651.823853,-0.008843,-0.003787,-0.096193,-0.091121,-0.004642,-0.961927,-651.823853,-0.094979,0.000000
6.740000,-0.006706,-651.823853,-0.008584,-0.003533,-0.089732,-0.029831,-0.001520,-0.897318,-651.823853,-0.088474,0.000000
7.130000,-0.033516,-651.868347,-0.008304,-0.003276,-0.083219,-0.149086,-0.007595,-0.832190,-651.868347,-0.081988,0.000000
7.520000,-0.037239,-651.823853,-0.008050,-0.003021,-0.076723,-0.165648,-0.008438,-0.767235,-651.823853,-0.075483,0.000000
7.910000,-0.062561,-651.868347,-0.007787,-0.002766,-0.070263,-0.278285,-0.014177,-0.702626,-651.868347,-0.068979,0.000000
8.300000,-0.035378,-651.912842,-0.007528,-0.002508,-0.063706,-0.157367,-0.008017,-0.637064,-651.912842,-0.062492,0.000000
8.690001,-0.014893,-651.823853,-0.007256,-0.002255,-0.057280,-0.066245,-0.003375,-0.572802,-651.823853,-0.055988,0.000000
9.080001,-0.014526,-651.912842,-0.006993,-0.001998,-0.050741,-0.064617,-0.003292,-0.507414,-651.912842,-0.049501,0.000000
9.470000,-0.052879,-651.912842,-0.006730,-0.001743,-0.044281,-0.235219,-0.011983,-0.442805,-651.912842,-0.042997,0.000000
9.860001,-0.075966,-651.868347,-0.006480,-0.001487,-0.037768,-0.337913,-0.017214,-0.377677,-651.868347,-0.036493,0.000000
10.250001,-0.068893,-652.046265,-0.006204,-0.001229,-0.031229,-0.306453,-0.015611,-0.312288,-652.046265,-0.030006,0.000000
10.640000,-0.009308,-651.957275,-0.005946,-0.000971,-0.024673,-0.041403,-0.002109,-0.246726,-651.957275,-0.023502,0.000000
11.030001,-0.001488,-652.001770,-0.005687,-0.000722,-0.018350,-0.006618,-0.000337,-0.183505,-652.001770,-0.017015,0.000000
11.420000,-0.029793,-652.001770,-0.005437,-0.000467,-0.011864,-0.132525,-0.006751,-0.118636,-652.001770,-0.010511,0.000000
11.810000,-0.041710,-652.001770,-0.005170,-0.000206,-0.005229,-0.185535,-0.009452,-0.052294,-652.001770,-0.004007,0.000000
12.200001,-0.042824,-651.957275,-0.004911,0.000045,0.001136,-0.190490,-0.009704,0.011361,-651.957275,0.002480,0.000000
12.590000,0.064423,-651.957275,-0.004807,-0.000000,-0.000000,0.286566,0.014598,-0.000000,-651.957275,0.000234,0.000000
12.980000,0.132195,-652.090759,-0.004803,-0.000000,-0.000000,0.588031,0.029956,-0.000000,-652.090759,0.000382,0.000000
13.370001,0.115807,-652.001770,-0.004794,0.000003,0.000078,0.515133,0.026242,0.000781,-652.001770,0.001032,0.000000
13.760000,0.204430,-652.090759,-0.004799,0.000026,0.000650,0.909348,0.046324,0.006504,-652.090759,0.001682,0.000000
14.150001,0.306831,-652.090759,-0.004743,0.000051,0.001301,1.364854,0.069529,0.013008,-652.090759,0.002333,0.000000
14.540001,0.369766,-652.046265,-0.004708,0.000075,0.001908,1.644802,0.083790,0.019079,-652.046265,0.002983,0.000000
14.930000,0.513870,-652.090759,-0.004695,0.000097,0.002463,2.285809,0.116445,0.024629,-652.090759,0.003634,0.000000
15.320001,0.728729,-652.090759,-0.004687,0.000125,0.003183,3.241549,0.165132,0.031827,-652.090759,0.004284,0.000000
15.710001,0.910080,-652.135254,-0.004656,0.000152,0.003859,4.048238,0.206227,0.038592,-652.135254,0.004935,0.000000
16.100000,1.107437,-652.135254,-0.004626,0.000178,0.004510,4.926126,0.250949,0.045096,-652.135254,0.005585,0.000000
16.490002,1.278351,-652.090759,-0.004592,0.000203,0.005160,5.686388,0.289678,0.051600,-652.090759,0.006235,0.000000
16.880001,1.460815,-652.179687,-0.004579,0.000225,0.005724,6.498032,0.331026,0.057237,-652.179687,0.006886,0.000000
17.270000,1.573647,-652.135254,-0.004549,0.000241,0.006131,6.999929,0.356593,0.061313,-652.135254,0.007536,0.000000
17.660002,1.978783,-652.135254,-0.004531,0.000282,0.007172,8.802065,0.448399,0.071720,-652.135254,0.008187,0.000000
18.050001,2.151939,-652.135254,-0.004506,0.000303,0.007701,9.572305,0.487636,0.077010,-652.135254,0.008837,0.000000
18.440001,2.472923,-652.179687,-0.004471,0.000335,0.008507,11.000113,0.560372,0.085075,-652.179687,0.009487,0.000000
18.830002,2.694855,-652.224182,-0.004445,0.000358,0.009106,11.987312,0.610663,0.091059,-652.224182,0.010138,0.000000
19.220001,2.877319,-652.135254,-0.004424,0.000379,0.009635,12.798956,0.652010,0.096349,-652.135254,0.010788,0.000000
19.610001,3.108566,-652.224182,-0.004398,0.000405,0.010294,13.827594,0.704411,0.102940,-652.224182,0.011439,0.000000
20.000000,3.219528,-652.179687,-0.004363,0.000428,0.010884,14.321177,0.729556,0.108837,-652.179687,0.012089,0.000000
20.390001,3.637703,-652.224182,-0.004346,0.000464,0.011794,16.181311,0.824315,0.117943,-652.224182,0.012731,0.000000
20.780001,3.869324,-652.179687,-0.004307,0.000490,0.012445,17.211611,0.876801,0.124447,-652.179687,0.013381,0.000000
21.170000,3.950500,-652.268677,-0.004290,0.000506,0.012844,17.572704,0.895196,0.128436,-652.268677,0.014032,0.000000
21.560001,4.241318,-652.313171,-0.004260,0.000534,0.013572,18.866323,0.961096,0.135721,-652.313171,0.014682,0.000000
21.950001,4.345955,-652.313171,-0.004225,0.000552,0.014032,19.331774,0.984807,0.140317,-652.313171,0.015333,0.000000
22.340000,4.754082,-652.313171,-0.004186,0.000590,0.014986,21.147211,1.077290,0.149857,-652.313171,0.015983,0.000000
22.730001,4.750725,-652.313171,-0.004152,0.000607,0.015411,21.132278,1.076530,0.154106,-652.313171,0.016633,0.000000
23.120001,5.089958,-652.313171,-0.004139,0.000638,0.016200,22.641264,1.153401,0.161998,-652.313171,0.017284,0.000000
23.510000,5.151772,-652.446594,-0.004100,0.000661,0.016789,22.916224,1.167408,0.167895,-652.446594,0.017934,0.000000
23.900002,5.212845,-652.268677,-0.004083,0.000683,0.017336,23.187893,1.181248,0.173358,-652.268677,0.018585,0.000000
24.290001,5.490257,-652.402100,-0.004061,0.000714,0.018142,24.421885,1.244110,0.181424,-652.402100,0.019235,0.000000
24.680000,5.513344,-652.357605,-0.004018,0.000735,0.018663,24.524578,1.249342,0.186627,-652.357605,0.019885,0.000000
25.070002,5.828369,-652.446594,-0.003975,0.000769,0.019539,25.925880,1.320727,0.195386,-652.446594,0.020536,0.000000
25.460001,5.687241,-652.402100,-0.003932,0.000788,0.020007,25.298109,1.288747,0.200069,-652.402100,0.021186,0.000000
25.850000,5.764694,-652.402100,-0.003911,0.000810,0.020571,25.642641,1.306298,0.205706,-652.402100,0.021837,0.000000
26.240002,5.783318,-652.402100,-0.003876,0.000835,0.021212,25.725481,1.310519,0.212123,-652.402100,0.022487,0.000000
26.630001,5.949394,-652.402100,-0.003842,0.000863,0.021915,26.464228,1.348152,0.219148,-652.402100,0.023138,0.000000
27.020000,6.165001,-652.446594,-0.003811,0.000894,0.022695,27.423294,1.397009,0.226953,-652.446594,0.023788,0.000000
27.410002,6.066322,-652.446594,-0.003768,0.000912,0.023164,26.984350,1.374648,0.231636,-652.446594,0.024438,0.000000
27.800001,5.998917,-652.402100,-0.003725,0.000931,0.023649,26.684513,1.359374,0.236492,-652.402100,0.025089,0.000000
28.190001,6.207817,-652.535522,-0.003695,0.000965,0.024499,27.613749,1.406711,0.244991,-652.535522,0.025739,0.000000
28.580002,6.538116,-652.402100,-0.003656,0.001001,0.025427,29.082994,1.481558,0.254271,-652.402100,0.026390,0.000000
28.970001,6.279312,-652.535522,-0.003643,0.001017,0.025843,27.931776,1.422912,0.258433,-652.535522,0.027040,0.000000
29.360001,6.527313,-652.535522,-0.003591,0.001049,0.026633,29.034939,1.479110,0.266325,-652.535522,0.027682,0.000000
29.750002,6.620033,-652.491089,-0.003566,0.001079,0.027413,29.447378,1.500121,0.274130,-652.491089,0.028332,0.000000
30.140001,6.575356,-652.535522,-0.003510,0.001102,0.027994,29.248642,1.489997,0.279941,-652.535522,0.028983,0.000000
30.530001,6.658394,-652.491089,-0.003479,0.001127,0.028627,29.618015,1.508814,0.286271,-652.491089,0.029633,0.000000
30.920002,6.634186,-652.535522,-0.003462,0.001145,0.029095,29.510332,1.503328,0.290954,-652.535522,0.030284,0.000000
31.310001,6.806969,-652.535522,-0.003410,0.001174,0.029815,30.278910,1.542481,0.298152,-652.535522,0.030934,0.000000
31.700001,6.970436,-652.535522,-0.003397,0.001205,0.030604,31.006048,1.579523,0.306044,-652.535522,0.031584,0.000000
32.090000,7.019592,-652.580017,-0.003354,0.001230,0.031237,31.224707,1.590662,0.312375,-652.580017,0.032235,0.000000
32.480003,7.101517,-652.535522,-0.003333,0.001256,0.031897,31.589125,1.609227,0.318966,-652.535522,0.032885,0.000000
32.870003,7.209503,-652.669006,-0.003281,0.001281,0.032530,32.069473,1.633697,0.325296,-652.669006,0.033536,0.000000
33.260002,7.062416,-652.535522,-0.003264,0.001299,0.033007,31.415195,1.600366,0.330066,-652.535522,0.034186,0.000000
33.650002,7.383400,-652.669006,-0.003238,0.001328,0.033744,32.843002,1.673102,0.337438,-652.669006,0.034836,0.000000
34.040001,7.283607,-652.624512,-0.003186,0.001353,0.034377,32.399105,1.650489,0.343768,-652.624512,0.035487,0.000000
34.430000,7.297012,-652.624512,-0.003160,0.001371,0.034819,32.458733,1.653527,0.348191,-652.624512,0.036137,0.000000
34.820004,7.778114,-652.624512,-0.003130,0.001407,0.035747,34.598782,1.762546,0.357470,-652.624512,0.036788,0.000000
35.210003,7.731194,-652.624512,-0.003091,0.001433,0.036406,34.390068,1.751914,0.364061,-652.624512,0.037438,0.000000
35.600002,7.765083,-652.713501,-0.003044,0.001460,0.037083,34.540817,1.759593,0.370826,-652.713501,0.038089,0.000000
35.990002,7.740875,-652.713501,-0.003022,0.001485,0.037716,34.433132,1.754107,0.377156,-652.713501,0.038739,0.000000
36.380001,7.813118,-652.669006,-0.002992,0.001506,0.038253,34.754486,1.770478,0.382533,-652.669006,0.039389,0.000000
36.770000,8.188843,-652.713501,-0.002958,0.001539,0.039086,36.425793,1.855618,0.390859,-652.713501,0.040040,0.000000
37.160004,8.038773,-652.624512,-0.002906,0.001562,0.039667,35.758247,1.821612,0.396669,-652.624512,0.040690,0.000000
37.550003,8.001167,-652.802429,-0.002880,0.001583,0.040196,35.590969,1.813090,0.401959,-652.802429,0.041341,0.000000
37.940002,8.167992,-652.713501,-0.002859,0.001612,0.040950,36.333042,1.850893,0.409504,-652.713501,0.041991,0.000000
38.330002,7.964676,-652.713501,-0.002837,0.001625,0.041280,35.428646,1.804821,0.412799,-652.713501,0.042641,0.000000
38.720001,8.481895,-652.713501,-0.002781,0.001660,0.042156,37.729355,1.922025,0.421558,-652.713501,0.043283,0.000000
39.110001,8.417854,-652.669006,-0.002742,0.001690,0.042936,37.444485,1.907513,0.429363,-652.669006,0.043934,0.000000
39.500000,8.302040,-652.802429,-0.002712,0.001713,0.043509,36.929317,1.881269,0.435087,-652.802429,0.044584,0.000000
39.890003,8.393646,-652.757935,-0.002677,0.001739,0.044176,37.336803,1.902027,0.441765,-652.757935,0.045234,0.000000
40.280003,8.515038,-652.802429,-0.002652,0.001768,0.044896,37.876778,1.929535,0.448963,-652.802429,0.045885,0.000000
40.670002,8.690804,-652.802429,-0.002604,0.001793,0.045538,38.658627,1.969364,0.455380,-652.802429,0.046535,0.000000
41.060001,8.543343,-652.802429,-0.002591,0.001812,0.046024,38.002686,1.935949,0.460237,-652.802429,0.047186,0.000000
41.450001,8.787247,-652.802429,-0.002548,0.001847,0.046908,39.087627,1.991219,0.469082,-652.802429,0.047836,0.000000
41.840000,8.673668,-652.757935,-0.002496,0.001871,0.047515,38.582401,1.965481,0.475153,-652.757935,0.048487,0.000000
42.230003,8.737717,-652.846924,-0.002462,0.001895,0.048140,38.867306,1.979995,0.481397,-652.846924,0.049137,0.000000
42.620003,8.828209,-652.846924,-0.002436,0.001921,0.048790,39.269836,2.000501,0.487901,-652.846924,0.049787,0.000000
43.010002,8.892624,-652.802429,-0.002397,0.001941,0.049302,39.556366,2.015097,0.493018,-652.802429,0.050438,0.000000
43.400002,9.004341,-652.891418,-0.002371,0.001965,0.049918,40.053310,2.040413,0.499175,-652.891418,0.051088,0.000000
43.790001,8.948853,-652.802429,-0.002337,0.001989,0.050516,39.806484,2.027839,0.505159,-652.802429,0.051739,0.000000
44.180000,8.758202,-652.891418,-0.002324,0.002006,0.050941,38.958427,1.984637,0.509408,-652.891418,0.052389,0.000000
44.570004,9.119400,-652.891418,-0.002281,0.002040,0.051817,40.565117,2.066485,0.518167,-652.891418,0.053040,0.000000
44.960003,9.223289,-652.935852,-0.002238,0.002071,0.052606,41.027241,2.090027,0.526059,-652.935852,0.053690,0.000000
45.350002,9.352135,-652.980347,-0.002195,0.002096,0.053239,41.600372,2.119224,0.532390,-652.980347,0.054340,0.000000
45.740002,9.350647,-652.935852,-0.002160,0.002120,0.053846,41.593754,2.118887,0.538460,-652.935852,0.054991,0.000000
46.130001,9.240791,-652.935852,-0.002130,0.002145,0.054488,41.105091,2.093993,0.544878,-652.935852,0.055641,0.000000
46.520000,9.774773,-652.980347,-0.002087,0.002180,0.055364,43.480362,2.214995,0.553637,-652.980347,0.056292,0.000000
46.910004,9.383041,-652.935852,-0.002057,0.002196,0.055771,41.737854,2.126228,0.557713,-652.935852,0.056942,0.000000
47.300003,9.873451,-653.024841,-0.002031,0.002230,0.056630,43.919304,2.237356,0.566298,-653.024841,0.057592,0.000000
47.690002,9.464966,-652.980347,-0.001966,0.002248,0.057107,42.102272,2.144792,0.571068,-652.980347,0.058234,0.000000
48.080002,9.739777,-652.980347,-0.001957,0.002275,0.057783,43.324692,2.207065,0.577832,-652.980347,0.058885,0.000000
48.470001,9.901009,-653.024841,-0.001906,0.002303,0.058503,44.041885,2.243601,0.585030,-653.024841,0.059535,0.000000
48.860001,9.928192,-653.024841,-0.001880,0.002328,0.059119,44.162804,2.249760,0.591188,-653.024841,0.060185,0.000000
49.250004,10.077515,-652.980347,-0.001832,0.002354,0.059804,44.827023,2.283597,0.598039,-652.980347,0.060836,0.000000
49.640003,9.597900,-652.980347,-0.001811,0.002373,0.060281,42.693592,2.174915,0.602809,-652.980347,0.061486,0.000000
50.030003,9.849625,-653.024841,-0.001776,0.002400,0.060966,43.813320,2.231957,0.609660,-653.024841,0.062137,0.000000
50.420002,10.206352,-652.980347,-0.001733,0.002430,0.061712,45.400124,2.312792,0.617118,-652.980347,0.062787,0.000000
50.810001,9.977348,-653.024841,-0.001720,0.002457,0.062406,44.381462,2.260899,0.624056,-653.024841,0.063438,0.000000
51.200001,10.168373,-653.113831,-0.001656,0.002486,0.063143,45.231182,2.304186,0.631427,-653.113831,0.064088,0.000000
51.590004,10.061501,-653.113831,-0.001625,0.002509,0.063741,44.755791,2.279969,0.637411,-653.113831,0.064738,0.000000
51.980003,10.334076,-653.158264,-0.001587,0.002536,0.064426,45.968266,2.341735,0.644262,-653.158264,0.065389,0.000000
52.370003,10.452118,-653.158264,-0.001561,0.002560,0.065016,46.493343,2.368484,0.650159,-653.158264,0.066039,0.000000
52.760002,10.714645,-653.113831,-0.001526,0.002589,0.065753,47.661121,2.427973,0.657531,-653.113831,0.066690,0.000000
53.150002,10.504997,-653.158264,-0.001483,0.002611,0.066308,46.728561,2.380466,0.663081,-653.158264,0.067340,0.000000
53.540001,10.402596,-653.158264,-0.001449,0.002637,0.066976,46.273056,2.357262,0.669758,-653.158264,0.067990,0.000000
53.930004,10.779068,-653.202759,-0.001406,0.002664,0.067670,47.947689,2.442572,0.676696,-653.202759,0.068641,0.000000
54.320004,10.799545,-653.158264,-0.001384,0.002689,0.068294,48.038776,2.447212,0.682940,-653.158264,0.069291,0.000000
54.710003,10.561600,-653.158264,-0.001345,0.002708,0.068780,46.980343,2.393293,0.687797,-653.158264,0.069942,0.000000
55.100002,10.629745,-653.202759,-0.001311,0.002732,0.069404,47.283470,2.408735,0.694041,-653.202759,0.070592,0.000000
55.490002,10.692673,-653.202759,-0.001285,0.002754,0.069959,47.563385,2.422994,0.699591,-653.202759,0.071243,0.000000
55.880001,10.523247,-653.291748,-0.001255,0.002770,0.070367,46.809738,2.384602,0.703667,-653.291748,0.071893,0.000000
56.270004,11.409492,-653.247253,-0.001203,0.002816,0.071520,50.751957,2.585428,0.715201,-653.247253,0.072543,0.000000
56.660004,11.338371,-653.291748,-0.001177,0.002842,0.072188,50.435593,2.569312,0.721879,-653.291748,0.073185,0.000000
57.050003,11.498863,-653.202759,-0.001134,0.002869,0.072882,51.149498,2.605680,0.728817,-653.202759,0.073836,0.000000
57.440002,11.156281,-653.202759,-0.001104,0.002885,0.073281,49.625614,2.528049,0.732806,-653.202759,0.074486,0.000000
57.830002,11.317886,-653.291748,-0.001078,0.002911,0.073948,50.344471,2.564670,0.739483,-653.291748,0.075136,0.000000
58.220001,12.149025,-653.202759,-0.001022,0.002944,0.074790,54.041561,2.753008,0.747895,-653.202759,0.075787,0.000000
58.610004,11.622490,-653.336182,-0.001000,0.002961,0.075197,51.699417,2.633694,0.751971,-653.336182,0.076437,0.000000
59.000004,12.093910,-653.247253,-0.000966,0.002993,0.076021,53.796398,2.740519,0.760210,-653.247253,0.077088,0.000000
59.390003,11.991135,-653.247253,-0.000936,0.003011,0.076472,53.339230,2.717230,0.764720,-653.247253,0.077738,0.000000
59.780003,12.559753,-653.291748,-0.000914,0.003038,0.077166,55.868572,2.846081,0.771657,-653.291748,0.078389,0.000000
60.170002,13.046440,-653.336182,-0.000884,0.003070,0.077972,58.033463,2.956366,0.779723,-653.336182,0.079039,0.000000
60.560001,12.951859,-653.336182,-0.000854,0.003094,0.078588,57.612743,2.934933,0.785880,-653.336182,0.079689,0.000000
60.950005,13.431847,-653.336182,-0.000824,0.003123,0.079334,59.747837,3.043700,0.793338,-653.336182,0.080340,0.000000
61.340004,13.379341,-653.247253,-0.000789,0.003147,0.079932,59.514282,3.031802,0.799322,-653.247253,0.080990,0.000000
61.730003,13.888748,-653.336182,-0.000759,0.003174,0.080617,61.780239,3.147235,0.806173,-653.336182,0.081641,0.000000
62.120003,14.327026,-653.380676,-0.000720,0.003198,0.081242,63.729797,3.246551,0.812417,-653.380676,0.082291,0.000000
62.510002,14.510612,-653.425171,-0.000703,0.003221,0.081805,64.546425,3.288152,0.818054,-653.425171,0.082941,0.000000
62.900002,15.189819,-653.380676,-0.000655,0.003256,0.082690,67.567688,3.442062,0.826900,-653.380676,0.083592,0.000000
63.290005,15.419197,-653.336182,-0.000629,0.003281,0.083340,68.588013,3.494040,0.833404,-653.336182,0.084242,0.000000
63.680004,15.600540,-653.425171,-0.000608,0.003303,0.083887,69.394669,3.535133,0.838867,-653.425171,0.084893,0.000000
64.070000,15.947594,-653.380676,-0.000586,0.003327,0.084502,70.938438,3.613776,0.845025,-653.380676,0.085543,0.000000
64.460007,15.820618,-653.380676,-0.000569,0.003345,0.084971,70.373619,3.585003,0.849708,-653.380676,0.086194,0.000000
64.850006,16.896774,-653.425171,-0.000526,0.003374,0.085691,75.160606,3.828864,0.856906,-653.425171,0.086844,0.000000
65.240005,17.273613,-653.425171,-0.000513,0.003398,0.086306,76.836868,3.914257,0.863063,-653.425171,0.087494,0.000000
65.630005,17.736099,-653.514160,-0.000466,0.003421,0.086905,78.894112,4.019058,0.869047,-653.514160,0.088136,0.000000
66.020004,18.763847,-653.469666,-0.000448,0.003456,0.087772,83.465759,4.251948,0.877719,-653.469666,0.088787,0.000000
66.410004,18.818588,-653.514160,-0.000431,0.003477,0.088318,83.709259,4.264353,0.883183,-653.514160,0.089437,0.000000
66.800003,19.637802,-653.514160,-0.000410,0.003506,0.089064,87.353310,4.449990,0.890641,-653.514160,0.090087,0.000000
67.190002,19.973312,-653.514160,-0.000375,0.003527,0.089576,88.845734,4.526017,0.895757,-653.514160,0.090738,0.000000
67.580002,20.408615,-653.558594,-0.000349,0.003554,0.090270,90.782051,4.624658,0.902695,-653.558594,0.091388,0.000000
67.970001,21.427429,-653.514160,-0.000323,0.003581,0.090963,95.313965,4.855525,0.909633,-653.514160,0.092039,0.000000
68.360001,21.921562,-653.558594,-0.000306,0.003607,0.091614,97.511978,4.967497,0.916137,-653.558594,0.092689,0.000000
68.750000,22.858452,-653.514160,-0.000272,0.003632,0.092255,101.679474,5.179799,0.922555,-653.514160,0.093340,0.000000
69.140007,23.104591,-653.514160,-0.000267,0.003652,0.092767,102.774353,5.235576,0.927671,-653.514160,0.093990,0.000000
69.530006,23.904823,-653.603088,-0.000241,0.003678,0.093426,106.333961,5.416910,0.934262,-653.603088,0.094640,0.000000
69.920006,25.373459,-653.603088,-0.000207,0.003709,0.094207,112.866783,5.749708,0.942067,-653.603088,0.095291,0.000000
70.310005,25.692207,-653.603088,-0.000211,0.003727,0.094666,114.284645,5.821938,0.946664,-653.603088,0.095941,0.000000
70.700005,26.594093,-653.647583,-0.000185,0.003757,0.095421,118.296432,6.026308,0.954208,-653.647583,0.096592,0.000000
71.090004,27.841545,-653.603088,-0.000155,0.003785,0.096149,123.845375,6.308984,0.961493,-653.603088,0.097242,0.000000
71.480003,27.971130,-653.647583,-0.000134,0.003801,0.096557,124.421799,6.338349,0.965569,-653.647583,0.097892,0.000000
71.870003,30.346123,-653.647583,-0.000121,0.003841,0.097563,134.986298,6.876530,0.975629,-653.647583,0.098543,0.000000
72.260002,31.407013,-653.692078,-0.000103,0.003866,0.098205,139.705368,7.116930,0.982046,-653.692078,0.099193,0.000000
72.650002,32.255646,-653.603088,-0.000082,0.003893,0.098872,143.480286,7.309234,0.988724,-653.603088,0.099844,0.000000
73.040001,33.006348,-653.692078,-0.000069,0.003914,0.099410,146.819565,7.479345,0.994101,-653.692078,0.100494,0.000000
73.430000,34.523766,-653.603088,-0.000047,0.003942,0.100130,153.569382,7.823197,1.001299,-653.603088,0.101145,0.000000
73.820000,35.500870,-653.647583,-0.000034,0.003965,0.100711,157.915756,8.044612,1.007109,-653.647583,0.101795,0.000000
74.210007,37.072281,-653.692078,-0.000013,0.003994,0.101439,164.905746,8.400699,1.014394,-653.692078,0.102445,0.000000
74.600006,38.212860,-653.736511,0.000022,0.004022,0.102151,169.979294,8.659158,1.021505,-653.736511,0.103087,0.000000
74.990005,39.218636,-653.736511,0.000009,0.004039,0.102584,174.453201,8.887070,1.025841,-653.736511,0.103738,0.000000
75.380005,41.017197,-653.736511,0.000039,0.004070,0.103382,182.453598,9.294629,1.033820,-653.736511,0.104388,0.000000
75.770004,42.179375,-653.692078,0.000047,0.004092,0.103937,187.623230,9.557983,1.039370,-653.692078,0.105038,0.000000
76.160004,43.613380,-653.736511,0.000056,0.004116,0.104544,194.001999,9.882934,1.045441,-653.736511,0.105689,0.000000
76.550003,45.280487,-653.692078,0.000086,0.004141,0.105177,201.417664,10.260705,1.051771,-653.692078,0.106339,0.000000
76.940002,46.044228,-653.781006,0.000078,0.004162,0.105715,204.814957,10.433771,1.057148,-653.781006,0.106990,0.000000
77.330002,48.591995,-653.781006,0.000108,0.004194,0.106521,216.147995,11.011103,1.065213,-653.781006,0.107640,0.000000
77.720001,50.442688,-653.736511,0.000103,0.004217,0.107120,224.380280,11.430477,1.071197,-653.736511,0.108290,0.000000
78.110001,52.192093,-653.781006,0.000129,0.004244,0.107787,232.162018,11.826898,1.077875,-653.781006,0.108941,0.000000
78.500000,53.994751,-653.781006,0.000151,0.004271,0.108473,240.180649,12.235385,1.084726,-653.781006,0.109591,0.000000
78.890007,55.264168,-653.825500,0.000134,0.004292,0.109028,245.827301,12.523039,1.090276,-653.825500,0.110242,0.000000
79.280006,57.522232,-653.869995,0.000164,0.004321,0.109756,255.871674,13.034724,1.097561,-653.869995,0.110892,0.000000
79.670006,59.609756,-653.781006,0.000172,0.004347,0.110424,265.157440,13.507764,1.104239,-653.781006,0.111543,0.000000
80.060005,61.363258,-653.869995,0.000181,0.004373,0.111083,272.957397,13.905113,1.110829,-653.869995,0.112193,0.000000
80.450005,63.399017,-653.825500,0.000181,0.004399,0.111725,282.012909,14.366423,1.117247,-653.825500,0.112843,0.000000
80.840004,64.153824,-653.825500,0.000185,0.004420,0.112262,285.370453,14.537464,1.122624,-653.825500,0.113494,0.000000
81.230003,66.600296,-653.869995,0.000207,0.004434,0.112635,296.252899,15.091844,1.126353,-653.869995,0.114084,0.000000
81.620003,65.769913,-653.869995,0.000216,0.004434,0.112618,292.559174,14.903675,1.126179,-653.869995,294.500458,0.000000
82.010002,65.238907,-653.914490,0.000216,0.004434,0.112618,290.197144,14.783348,1.126179,-653.914490,294.500458,0.000000
82.400002,64.738815,-653.869995,0.000220,0.004434,0.112627,287.972626,14.670026,1.126266,-653.869995,294.500458,0.000000
82.790001,66.901932,-653.914490,0.000220,0.004443,0.112852,297.594666,15.160194,1.128521,-653.914490,294.500458,0.000000
83.180000,66.277084,-653.914490,0.000229,0.004406,0.111915,294.815186,15.018602,1.119155,-653.914490,294.500458,0.000000
83.570007,65.975082,-653.914490,0.000233,0.004406,0.111915,293.471832,14.950168,1.119155,-653.914490,294.500458,0.000000
83.960007,65.753525,-654.003418,0.000233,0.004406,0.111924,292.486298,14.899961,1.119241,-654.003418,294.500458,0.000000
84.350006,65.442963,-654.003418,0.000233,0.004412,0.112054,291.104828,14.829587,1.120542,-654.003418,294.500458,0.000000
84.740005,65.228485,-653.958923,0.000241,0.004421,0.112288,290.150787,14.780987,1.122884,-653.958923,294.500458,0.000000
85.130005,65.073578,-654.047913,0.000241,0.004437,0.112696,289.461731,14.745884,1.126960,-654.047913,294.500458,0.000000
85.520004,64.972656,-653.914490,0.000224,0.004448,0.112982,289.012817,14.723015,1.129822,-653.914490,294.500458,0.000000
85.910004,65.350616,-654.047913,0.000250,0.004454,0.113121,290.694061,14.808661,1.131209,-654.047913,294.500458,0.000000
86.300003,65.253799,-653.958923,0.000233,0.004454,0.113130,290.263397,14.786722,1.131296,-653.958923,294.500458,0.000000
86.690002,65.156616,-654.003418,0.000229,0.004455,0.113147,289.831116,14.764701,1.131469,-654.003418,294.500458,0.000000
87.080002,65.167419,-654.047913,0.000259,0.004456,0.113182,289.879150,14.767148,1.131816,-654.047913,294.500458,0.000000
87.470001,65.130920,-654.003418,0.000254,0.004457,0.113199,289.716797,14.758878,1.131990,-654.003418,294.500458,0.000000
87.860001,65.035965,-654.092407,0.000241,0.004457,0.113199,289.294434,14.737360,1.131990,-654.092407,294.500458,0.000000
88.250008,65.608673,-654.003418,0.000254,0.004465,0.113398,291.841949,14.867138,1.133984,-654.003418,294.500458,0.000000
88.640007,65.572189,-654.092407,0.000241,0.004465,0.113398,291.679657,14.858871,1.133984,-654.092407,294.500458,0.000000
89.030006,65.525635,-654.092407,0.000250,0.004465,0.113398,291.472595,14.848321,1.133984,-654.092407,294.500458,0.000000
89.420006,65.472763,-654.047913,0.000246,0.004465,0.113398,291.237396,14.836340,1.133984,-654.047913,294.500458,0.000000
89.810005,65.403503,-654.136841,0.000237,0.004465,0.113398,290.929321,14.820645,1.133984,-654.136841,294.500458,0.000000
90.200005,65.329025,-654.047913,0.000250,0.004465,0.113407,290.598022,14.803769,1.134071,-654.047913,294.500458,0.000000
90.590004,65.277267,-654.092407,0.000241,0.004465,0.113407,290.367798,14.792040,1.134071,-654.092407,294.500458,0.000000
90.980003,65.221786,-654.136841,0.000254,0.004465,0.113407,290.121002,14.779469,1.134071,-654.136841,294.500458,0.000000
91.370003,65.251205,-654.136841,0.000241,0.004468,0.113476,290.251862,14.786135,1.134765,-654.136841,294.500458,0.000000
91.760002,65.266464,-654.136841,0.000254,0.004468,0.113476,290.319733,14.789592,1.134765,-654.136841,294.500458,0.000000
92.150002,65.232574,-654.136841,0.000250,0.004468,0.113476,290.168976,14.781913,1.134765,-654.136841,294.500458,0.000000
92.540001,65.206146,-654.225830,0.000246,0.004468,0.113476,290.051422,14.775925,1.134765,-654.225830,294.500458,0.000000
92.930008,65.149170,-654.136841,0.000259,0.004468,0.113476,289.797974,14.763013,1.134765,-654.136841,294.500458,0.000000
93.320007,65.093689,-654.225830,0.000259,0.004468,0.113476,289.551178,14.750442,1.134765,-654.225830,294.500458,0.000000
93.710007,65.226242,-654.270325,0.000246,0.004472,0.113598,290.140808,14.780478,1.135979,-654.270325,294.500458,0.000000
94.100006,65.327530,-654.225830,0.000246,0.004472,0.113598,290.591370,14.803431,1.135979,-654.225830,294.500458,0.000000
94.490005,65.313385,-654.225830,0.000237,0.004472,0.113598,290.528442,14.800224,1.135979,-654.225830,294.500458,0.000000
94.880005,65.294769,-654.136841,0.000254,0.004472,0.113598,290.445648,14.796006,1.135979,-654.136841,294.500458,0.000000
95.270004,65.272430,-654.225830,0.000267,0.004472,0.113598,290.346283,14.790944,1.135979,-654.225830,294.500458,0.000000
95.660004,65.237427,-654.225830,0.000237,0.004472,0.113598,290.190582,14.783012,1.135979,-654.225830,294.500458,0.000000
96.050003,65.202423,-654.225830,0.000267,0.004472,0.113598,290.034851,14.775080,1.135979,-654.225830,294.500458,0.000000
96.440002,65.154755,-654.270325,0.000254,0.004472,0.113598,289.822815,14.764278,1.135979,-654.270325,294.500458,0.000000
96.830002,65.169647,-654.270325,0.000254,0.004473,0.113615,289.889069,14.767653,1.136152,-654.270325,294.500458,0.000000
97.220001,65.134644,-654.225830,0.000254,0.004473,0.113615,289.733368,14.759721,1.136152,-654.225830,294.500458,0.000000
97.610008,65.098892,-654.270325,0.000267,0.004473,0.113615,289.574341,14.751619,1.136152,-654.270325,294.500458,0.000000
98.000008,65.057571,-654.270325,0.000246,0.004473,0.113615,289.390533,14.742256,1.136152,-654.270325,294.500458,0.000000
98.390007,65.034103,-654.359253,0.000254,0.004473,0.113615,289.286133,14.736938,1.136152,-654.359253,294.500458,0.000000
98.780006,65.014740,-654.225830,0.000267,0.004473,0.113615,289.200012,14.732551,1.136152,-654.225830,294.500458,0.000000
99.170006,64.987564,-654.314819,0.000246,0.004473,0.113615,289.079132,14.726393,1.136152,-654.314819,294.500458,0.000000
99.560005,64.955902,-654.448242,0.000263,0.004473,0.113615,288.938293,14.719218,1.136152,-654.448242,294.500458,0.000000
99.950005,64.928345,-654.270325,0.000259,0.004473,0.113615,288.815704,14.712973,1.136152,-654.270325,294.500458,0.000000
100.340004,64.881805,-654.359253,0.000254,0.004473,0.113615,288.608673,14.702427,1.136152,-654.359253,294.500458,0.000000
100.730003,65.851837,-654.314819,0.000259,0.004485,0.113927,292.923615,14.922239,1.139274,-654.314819,294.500458,0.000000
101.120003,65.907318,-654.314819,0.000259,0.004485,0.113919,293.170380,14.934812,1.139188,-654.314819,294.500458,0.000000
101.510002,65.893539,-654.359253,0.000267,0.004485,0.113919,293.109100,14.931690,1.139188,-654.359253,294.500458,0.000000
101.900002,65.904709,-654.314819,0.000254,0.004485,0.113919,293.158783,14.934220,1.139188,-654.314819,294.500458,0.000000
102.290009,65.879395,-654.403748,0.000267,0.004485,0.113919,293.046173,14.928484,1.139188,-654.403748,294.500458,0.000000
102.680008,65.849976,-654.403748,0.000276,0.004485,0.113919,292.915314,14.921818,1.139188,-654.403748,294.500458,0.000000
103.070007,65.843277,-654.492737,0.000259,0.004485,0.113919,292.885529,14.920300,1.139188,-654.492737,294.500458,0.000000
103.460007,65.842529,-654.403748,0.000263,0.004485,0.113919,292.882202,14.920131,1.139188,-654.403748,294.500458,0.000000
103.850006,65.837311,-654.403748,0.000276,0.004485,0.113919,292.858978,14.918947,1.139188,-654.403748,294.500458,0.000000
104.240005,65.857422,-654.492737,0.000267,0.004485,0.113919,292.948456,14.923505,1.139188,-654.492737,294.500458,0.000000
104.630005,65.836945,-654.448242,0.000272,0.004485,0.113919,292.857361,14.918864,1.139188,-654.448242,294.500458,0.000000
105.020004,65.779968,-654.403748,0.000254,0.004485,0.113919,292.603912,14.905953,1.139188,-654.403748,294.500458,0.000000
105.410004,65.769165,-654.448242,0.000267,0.004485,0.113919,292.555847,14.903506,1.139188,-654.448242,294.500458,0.000000
105.800003,65.774002,-654.492737,0.000263,0.004485,0.113919,292.577362,14.904602,1.139188,-654.492737,294.500458,0.000000
106.190002,65.744965,-654.581665,0.000263,0.004485,0.113919,292.448212,14.898022,1.139188,-654.581665,294.500458,0.000000
106.580002,65.682404,-654.448242,0.000263,0.004485,0.113919,292.169922,14.883845,1.139188,-654.448242,294.500458,0.000000
106.970009,65.669373,-654.492737,0.000250,0.004485,0.113919,292.111969,14.880893,1.139188,-654.492737,294.500458,0.000000
107.360008,65.642929,-654.537170,0.000263,0.004485,0.113919,291.994324,14.874900,1.139188,-654.537170,294.500458,0.000000
107.750008,65.613144,-654.537170,0.000259,0.004485,0.113919,291.861847,14.868151,1.139188,-654.537170,294.500458,0.000000
108.140007,65.596756,-654.581665,0.000276,0.004485,0.113919,291.788940,14.864437,1.139188,-654.581665,294.500458,0.000000
108.530006,65.588196,-654.581665,0.000267,0.004485,0.113919,291.750854,14.862498,1.139188,-654.581665,294.500458,0.000000
108.920006,65.569199,-654.670654,0.000246,0.004485,0.113919,291.666351,14.858193,1.139188,-654.670654,294.500458,0.000000
109.310005,65.570328,-654.581665,0.000272,0.004485,0.113919,291.671387,14.858449,1.139188,-654.581665,294.500458,0.000000
109.700005,65.540161,-654.670654,0.000259,0.004485,0.113919,291.537201,14.851613,1.139188,-654.670654,294.500458,0.000000
110.090004,65.520416,-654.670654,0.000263,0.004485,0.113919,291.449371,14.847138,1.139188,-654.670654,294.500458,0.000000
110.480003,65.493607,-654.581665,0.000276,0.004485,0.113919,291.330109,14.841063,1.139188,-654.581665,294.500458,0.000000
110.870003,65.493240,-654.670654,0.000250,0.004485,0.113919,291.328491,14.840981,1.139188,-654.670654,294.500458,0.000000
111.260002,65.464935,-654.715149,0.000263,0.004485,0.113919,291.202576,14.834566,1.139188,-654.715149,294.500458,0.000000
111.650002,65.458984,-654.670654,0.000263,0.004485,0.113919,291.176117,14.833219,1.139188,-654.670654,294.500458,0.000000
112.040009,65.401260,-654.715149,0.000267,0.004485,0.113919,290.919342,14.820137,1.139188,-654.715149,294.500458,0.000000
112.430008,65.397919,-654.715149,0.000276,0.004485,0.113919,290.904480,14.819380,1.139188,-654.715149,294.500458,0.000000
112.820007,65.367752,-654.759583,0.000250,0.004485,0.113919,290.770294,14.812545,1.139188,-654.759583,294.500458,0.000000
113.210007,65.345779,-654.759583,0.000276,0.004485,0.113919,290.672546,14.807566,1.139188,-654.759583,294.500458,0.000000
113.600006,65.332382,-654.759583,0.000272,0.004485,0.113919,290.612946,14.804529,1.139188,-654.759583,294.500458,0.000000
113.990005,65.312637,-654.804077,0.000280,0.004485,0.113919,290.525116,14.800055,1.139188,-654.804077,294.500458,0.000000
114.380005,65.302582,-654.715149,0.000263,0.004485,0.113919,290.480377,14.797776,1.139188,-654.715149,294.500458,0.000000
114.770004,65.286194,-654.804077,0.000259,0.004485,0.113919,290.407501,14.794064,1.139188,-654.804077,294.500458,0.000000
115.160004,65.280609,-654.670654,0.000280,0.004485,0.113919,290.382660,14.792797,1.139188,-654.670654,294.500458,0.000000
115.550003,65.257156,-654.804077,0.000263,0.004485,0.113927,290.278320,14.787483,1.139274,-654.804077,294.500458,0.000000
115.940002,65.239655,-654.848572,0.000276,0.004485,0.113927,290.200470,14.783518,1.139274,-654.848572,294.500458,0.000000
116.330002,65.228851,-654.804077,0.000259,0.004485,0.113927,290.152435,14.781069,1.139274,-654.804077,294.500458,0.000000
116.720009,65.206879,-654.848572,0.000276,0.004485,0.113927,290.054687,14.776090,1.139274,-654.848572,294.500458,0.000000
117.110008,65.189758,-654.804077,0.000272,0.004485,0.113927,289.978516,14.772210,1.139274,-654.804077,294.500458,0.000000
117.500008,65.187515,-654.804077,0.000267,0.004485,0.113927,289.968536,14.771702,1.139274,-654.804077,294.500458,0.000000
117.890007,65.170013,-654.937500,0.000276,0.004485,0.113927,289.890686,14.767735,1.139274,-654.937500,294.500458,0.000000
118.280006,65.142471,-654.848572,0.000276,0.004485,0.113927,289.768188,14.761495,1.139274,-654.848572,294.500458,0.000000
118.670006,65.122726,-654.893066,0.000267,0.004485,0.113927,289.680359,14.757020,1.139274,-654.893066,294.500458,0.000000
119.060005,65.106339,-654.893066,0.000267,0.004486,0.113936,289.607452,14.753307,1.139361,-654.893066,294.500458,0.000000
119.450005,65.088104,-654.937500,0.000276,0.004486,0.113936,289.526337,14.749176,1.139361,-654.937500,294.500458,0.000000
119.840004,65.062408,-654.937500,0.000263,0.004486,0.113936,289.412048,14.743353,1.139361,-654.937500,294.500458,0.000000
120.230003,65.067612,-654.893066,0.000272,0.004486,0.113936,289.435181,14.744532,1.139361,-654.893066,294.500458,0.000000
120.620003,65.049744,-654.981995,0.000272,0.004486,0.113936,289.355713,14.740482,1.139361,-654.981995,294.500458,0.000000
121.010002,65.048996,-654.981995,0.000259,0.004486,0.113936,289.352386,14.740314,1.139361,-654.981995,294.500458,0.000000
121.400009,65.012512,-654.937500,0.000272,0.004486,0.113936,289.190094,14.732045,1.139361,-654.937500,294.500458,0.000000
121.790009,65.015854,-654.981995,0.000263,0.004486,0.113936,289.204956,14.732802,1.139361,-654.981995,294.500458,0.000000
122.180008,64.993149,-654.937500,0.000272,0.004486,0.113936,289.103973,14.727658,1.139361,-654.937500,294.500458,0.000000
122.570007,64.979736,-655.026489,0.000267,0.004486,0.113936,289.044312,14.724619,1.139361,-655.026489,294.500458,0.000000
122.960007,64.967453,-654.937500,0.000267,0.004486,0.113936,288.989655,14.721835,1.139361,-654.937500,294.500458,0.000000
123.350006,64.960007,-655.026489,0.000259,0.004486,0.113936,288.956543,14.720148,1.139361,-655.026489,294.500458,0.000000
123.740005,64.940262,-655.026489,0.000272,0.004486,0.113936,288.868713,14.715673,1.139361,-655.026489,294.500458,0.000000
124.130005,64.934311,-655.026489,0.000263,0.004486,0.113936,288.842255,14.714326,1.139361,-655.026489,294.500458,0.000000
124.520004,64.900803,-655.026489,0.000272,0.004486,0.113936,288.693176,14.706732,1.139361,-655.026489,294.500458,0.000000
124.910004,64.895950,-655.070984,0.000259,0.004486,0.113936,288.671600,14.705633,1.139361,-655.070984,294.500458,0.000000
125.300003,64.862442,-655.070984,0.000259,0.004486,0.113945,288.522552,14.698040,1.139448,-655.070984,294.500458,0.000000
125.690002,64.847168,-655.070984,0.000272,0.004486,0.113945,288.454620,14.694578,1.139448,-655.070984,294.500458,0.000000
126.080009,64.828552,-655.070984,0.000259,0.004486,0.113945,288.371796,14.690360,1.139448,-655.070984,294.500458,0.000000
126.470009,64.830414,-655.115417,0.000267,0.004486,0.113945,288.380096,14.690782,1.139448,-655.115417,294.500458,0.000000
126.860008,64.801376,-655.070984,0.000267,0.004486,0.113945,288.250916,14.684201,1.139448,-655.070984,294.500458,0.000000
127.250008,64.799133,-655.159912,0.000267,0.004486,0.113945,288.240936,14.683693,1.139448,-655.159912,294.500458,0.000000
127.640007,65.970993,-655.115417,0.000272,0.004500,0.114292,293.453644,14.949241,1.142917,-655.115417,294.500458,0.000000
128.029999,65.946793,-655.159912,0.000272,0.004496,0.114188,293.345978,14.943757,1.141876,-655.159912,294.500458,0.000000
128.420013,65.941574,-655.070984,0.000276,0.004496,0.114188,293.322784,14.942574,1.141876,-655.070984,294.500458,0.000000
128.810013,65.934494,-655.159912,0.000267,0.004496,0.114188,293.291290,14.940970,1.141876,-655.159912,294.500458,0.000000
129.200012,65.939713,-655.159912,0.000267,0.004496,0.114188,293.314484,14.942153,1.141876,-655.159912,294.500458,0.000000
129.590012,65.865982,-655.204407,0.000280,0.004496,0.114188,292.986511,14.925445,1.141876,-655.204407,294.500458,0.000000
129.980011,65.868225,-655.204407,0.000263,0.004496,0.114188,292.996490,14.925953,1.141876,-655.204407,294.500458,0.000000
130.370010,65.866730,-655.293396,0.000272,0.004496,0.114188,292.989838,14.925614,1.141876,-655.293396,294.500458,0.000000
130.760010,65.836197,-655.204407,0.000272,0.004496,0.114188,292.854034,14.918696,1.141876,-655.204407,294.500458,0.000000
131.150009,65.842529,-655.293396,0.000267,0.004496,0.114188,292.882202,14.920131,1.141876,-655.293396,294.500458,0.000000
131.540009,65.831360,-655.248901,0.000276,0.004496,0.114188,292.832520,14.917599,1.141876,-655.248901,294.500458,0.000000
131.930008,65.843277,-655.248901,0.000276,0.004496,0.114188,292.885529,14.920300,1.141876,-655.248901,294.500458,0.000000
132.320007,65.842148,-655.293396,0.000280,0.004496,0.114188,292.880493,14.920044,1.141876,-655.293396,294.500458,0.000000
132.710007,65.823532,-655.248901,0.000276,0.004496,0.114188,292.797699,14.915826,1.141876,-655.248901,294.500458,0.000000
133.100006,65.832092,-655.293396,0.000272,0.004496,0.114188,292.835785,14.917766,1.141876,-655.293396,294.500458,0.000000
133.490005,65.785187,-655.248901,0.000280,0.004496,0.114188,292.627136,14.907136,1.141876,-655.248901,294.500458,0.000000
133.880005,65.771027,-655.293396,0.000280,0.004496,0.114188,292.564148,14.903927,1.141876,-655.293396,294.500458,0.000000
134.270004,65.783325,-655.337830,0.000259,0.004496,0.114188,292.618835,14.906714,1.141876,-655.337830,294.500458,0.000000
134.660004,65.756500,-655.337830,0.000280,0.004496,0.114188,292.499512,14.900637,1.141876,-655.337830,294.500458,0.000000
135.050003,65.770279,-655.337830,0.000272,0.004496,0.114188,292.560822,14.903758,1.141876,-655.337830,294.500458,0.000000
135.440002,65.765442,-655.337830,0.000280,0.004496,0.114188,292.539307,14.902661,1.141876,-655.337830,294.500458,0.000000
135.830002,65.729691,-655.293396,0.000276,0.004496,0.114188,292.380280,14.894561,1.141876,-655.293396,294.500458,0.000000
136.220001,65.687622,-655.382324,0.000267,0.004496,0.114188,292.193146,14.885028,1.141876,-655.382324,294.500458,0.000000
136.610001,65.700272,-655.382324,0.000276,0.004496,0.114188,292.249390,14.887894,1.141876,-655.382324,294.500458,0.000000
137.000000,65.673462,-655.382324,0.000272,0.004496,0.114188,292.130157,14.881820,1.141876,-655.382324,294.500458,0.000000
137.389999,65.686874,-655.382324,0.000276,0.004496,0.114188,292.189819,14.884859,1.141876,-655.382324,294.500458,0.000000
137.780014,65.657089,-655.426819,0.000276,0.004496,0.114188,292.057312,14.878109,1.141876,-655.426819,294.500458,0.000000
138.170013,65.664902,-655.426819,0.000280,0.004496,0.114188,292.092072,14.879879,1.141876,-655.426819,294.500458,0.000000
138.560013,65.648514,-655.382324,0.000280,0.004496,0.114188,292.019165,14.876165,1.141876,-655.382324,294.500458,0.000000
138.950012,65.636230,-655.426819,0.000263,0.004496,0.114188,291.964539,14.873382,1.141876,-655.426819,294.500458,0.000000
139.340012,65.634735,-655.426819,0.000272,0.004496,0.114188,291.957886,14.873043,1.141876,-655.426819,294.500458,0.000000
139.730011,65.624695,-655.426819,0.000267,0.004496,0.114188,291.913208,14.870769,1.141876,-655.426819,294.500458,0.000000
140.120010,65.608307,-655.382324,0.000276,0.004496,0.114188,291.840332,14.867055,1.141876,-655.382324,294.500458,0.000000
140.510010,65.591919,-655.471313,0.000272,0.004496,0.114188,291.767426,14.863341,1.141876,-655.471313,294.500458,0.000000
140.900009,65.595276,-655.471313,0.000267,0.004496,0.114188,291.782349,14.864102,1.141876,-655.471313,294.500458,0.000000
141.290009,65.602722,-655.471313,0.000289,0.004496,0.114188,291.815491,14.865789,1.141876,-655.471313,294.500458,0.000000
141.680008,65.574417,-655.560242,0.000267,0.004496,0.114188,291.689575,14.859375,1.141876,-655.560242,294.500458,0.000000
142.070007,65.567337,-655.471313,0.000267,0.004495,0.114179,291.658081,14.857771,1.141789,-655.471313,0.114058,0.000000
142.460007,65.579254,-655.515747,0.000267,0.004479,0.113754,291.711090,14.860472,1.137540,-655.515747,0.113407,0.000000
142.850006,65.458237,-655.515747,0.000280,0.004462,0.113346,291.172791,14.833049,1.133464,-655.515747,0.112757,0.000000
143.240005,65.347641,-655.515747,0.000267,0.004435,0.112644,290.680817,14.807987,1.126439,-655.515747,0.112106,0.000000
143.630005,65.338333,-655.560242,0.000280,0.004410,0.112002,290.639435,14.805878,1.120022,-655.560242,0.111456,0.000000
144.020004,65.382278,-655.515747,0.000285,0.004377,0.111187,290.834900,14.815836,1.111870,-655.515747,0.110805,0.000000
144.410004,65.317474,-655.560242,0.000272,0.004355,0.110615,290.546631,14.801151,1.106146,-655.560242,0.110155,0.000000
144.800003,65.320465,-655.560242,0.000285,0.004331,0.109999,290.559937,14.801828,1.099989,-655.560242,0.109505,0.000000
145.190002,65.242630,-655.515747,0.000289,0.004309,0.109461,290.213715,14.784191,1.094612,-655.515747,0.108854,0.000000
145.580002,65.221039,-655.560242,0.000276,0.004284,0.108811,290.117676,14.779299,1.088108,-655.560242,0.108204,0.000000
145.970001,64.981232,-655.560242,0.000289,0.004260,0.108204,289.050964,14.724958,1.082038,-655.560242,0.107553,0.000000
146.360001,64.441284,-655.604736,0.000285,0.004239,0.107666,286.649139,14.602604,1.076661,-655.604736,0.106903,0.000000
146.750000,63.541641,-655.649231,0.000289,0.004214,0.107042,282.647339,14.398742,1.070417,-655.649231,0.106261,0.000000
147.139999,62.238708,-655.604736,0.000289,0.004187,0.106357,276.851593,14.103493,1.063566,-655.604736,0.105611,0.000000
147.530014,60.822571,-655.649231,0.000285,0.004165,0.105802,270.552307,13.782592,1.058015,-655.649231,0.104960,0.000000
147.920013,59.335686,-655.693726,0.000272,0.004146,0.105299,263.938324,13.445658,1.052985,-655.693726,0.104310,0.000000
148.310013,56.890320,-655.604736,0.000289,0.004115,0.104509,253.060776,12.891531,1.045094,-655.604736,0.103659,0.000000
148.700012,55.053406,-655.693726,0.000285,0.004096,0.104032,244.889786,12.475280,1.040324,-655.693726,0.103009,0.000000
149.090012,52.593513,-655.649231,0.000302,0.004070,0.103382,233.947632,11.917860,1.033820,-655.649231,0.102359,0.000000
149.480011,49.894554,-655.693726,0.000289,0.004045,0.102740,221.942062,11.306268,1.027402,-655.693726,0.101708,0.000000
149.870010,47.053352,-655.693726,0.000289,0.004018,0.102046,209.303772,10.662442,1.020464,-655.693726,0.101058,0.000000
150.260010,44.199867,-655.649231,0.000276,0.003992,0.101387,196.610825,10.015833,1.013874,-655.649231,0.100407,0.000000
150.650009,41.578735,-655.693726,0.000293,0.003969,0.100806,184.951447,9.421876,1.008063,-655.693726,0.099757,0.000000
151.040009,38.479851,-655.738159,0.000293,0.003943,0.100147,171.166931,8.719659,1.001472,-655.738159,0.099107,0.000000
151.430008,36.470901,-655.782654,0.000280,0.003925,0.099705,162.230667,8.264425,0.997049,-655.782654,0.098456,0.000000
151.820007,32.626900,-655.693726,0.000293,0.003889,0.098768,145.131699,7.393361,0.987683,-655.693726,0.097806,0.000000
152.210007,29.902252,-655.782654,0.000280,0.003863,0.098127,133.011856,6.775948,0.981266,-655.782654,0.097155,0.000000
152.600006,27.198456,-655.827148,0.000302,0.003841,0.097563,120.984772,6.163258,0.975629,-655.827148,0.096505,0.000000
152.990005,24.453697,-655.738159,0.000285,0.003818,0.096965,108.775475,5.541287,0.969645,-655.738159,0.095854,0.000000
153.380005,21.625900,-655.782654,0.000297,0.003794,0.096357,96.196808,4.900499,0.963575,-655.782654,0.095204,0.000000
153.770004,19.181274,-655.782654,0.000297,0.003765,0.095629,85.322571,4.346539,0.956290,-655.782654,0.094554,0.000000
154.160004,15.177155,-655.827148,0.000285,0.003734,0.094831,67.511353,3.439192,0.948311,-655.827148,0.093903,0.000000
154.550003,12.811844,-655.827148,0.000285,0.003714,0.094337,56.989929,2.903205,0.943368,-655.827148,0.093253,0.000000
154.940002,9.907341,-655.827148,0.000276,0.003682,0.093522,44.070053,2.245036,0.935216,-655.827148,0.092602,0.000000
155.330002,7.247856,-655.916077,0.000289,0.003659,0.092932,32.240074,1.642388,0.929319,-655.916077,0.091952,0.000000
155.720001,4.850151,-655.782654,0.000280,0.003639,0.092438,21.574549,1.099060,0.924376,-655.782654,0.091310,0.000000
156.110001,1.250801,-655.827148,0.000272,0.003606,0.091588,5.563841,0.283436,0.915877,-655.827148,0.090660,0.000000
156.500000,-0.547760,-655.827148,0.000293,0.003585,0.091067,-2.436558,-0.124124,0.910674,-655.827148,0.090009,0.000000
156.890015,-0.090858,-655.916077,0.000233,0.003564,0.090521,-0.404159,-0.020589,0.905210,-655.916077,0.089359,0.000000
157.280014,-0.000000,-655.871643,0.000185,0.003535,0.089801,-0.000000,-0.000000,0.898012,-655.871643,0.088709,0.000000
157.670013,0.019363,-655.871643,0.000151,0.003514,0.089246,0.086133,0.004388,0.892462,-655.871643,0.088058,0.000000
158.060013,-0.018990,-655.916077,0.000099,0.003479,0.088370,-0.084470,-0.004303,0.883703,-655.916077,0.087408,0.000000
158.450012,-0.007820,-655.871643,0.000043,0.003457,0.087815,-0.034786,-0.001772,0.878153,-655.871643,0.086757,0.000000
158.840012,0.032394,-655.871643,-0.000043,0.003426,0.087026,0.144098,0.007341,0.870261,-655.871643,0.086107,0.000000
159.230011,0.079315,-655.960571,-0.000069,0.003418,0.086827,0.352812,0.017973,0.868266,-655.960571,0.085456,0.000000
159.620010,0.031654,-655.960571,-0.000160,0.003376,0.085760,0.140806,0.007173,0.857599,-655.960571,0.084806,0.000000
160.010010,0.107986,-656.005066,-0.000246,0.003353,0.085170,0.480348,0.024470,0.851702,-656.005066,0.084979,0.000000
160.200012,0.126602,-655.960571,-0.000246,0.003353,0.085170,0.563155,0.028688,0.851702,-655.960571,0.084979,0.000000