File: Data/compression 33/AutoNoHeating-17-33-reverse-1-3_11152024_183159.csv
Time (sec),S:Load (lbs),S:HL1 (DIM),S:LVDT (in),S:Position (in),Ch:Position (mm),Ch:Load (N),Ch:Stress (MPa),Ch:Strain (mm/mm),Ch:HL1 (DIM),Set Point (),Cycles ()
0.210000,-0.121399,-133.976624,-0.011960,-0.007134,-0.181207,-0.540009,-0.027509,-1.812068,-133.976624,-0.180981,0.000000
0.560000,-0.100540,-134.110062,-0.011973,-0.007067,-0.179490,-0.447225,-0.022783,-1.794897,-134.110062,-0.178692,0.000000
0.910000,-0.065544,-134.065582,-0.011839,-0.006856,-0.174139,-0.291555,-0.014853,-1.741389,-134.065582,-0.172864,0.000000
1.260000,-0.094955,-134.110062,-0.011611,-0.006627,-0.168320,-0.422383,-0.021517,-1.683198,-134.110062,-0.167036,0.000000
1.610000,-0.093094,-134.110062,-0.011369,-0.006396,-0.162449,-0.414102,-0.021095,-1.624487,-134.110062,-0.161209,0.000000
1.960000,-0.069633,-134.110062,-0.011137,-0.006171,-0.156734,-0.309745,-0.015779,-1.567337,-134.110062,-0.155381,0.000000
2.310000,-0.091232,-134.243515,-0.010900,-0.005940,-0.150871,-0.405822,-0.020674,-1.508713,-134.243515,-0.149536,0.000000
2.660000,-0.061073,-134.199036,-0.010649,-0.005706,-0.144939,-0.271668,-0.013839,-1.449394,-134.199036,-0.143708,0.000000
3.010000,-0.125122,-134.154541,-0.010434,-0.005484,-0.139294,-0.556571,-0.028353,-1.392938,-134.154541,-0.137880,0.000000
3.360000,-0.087135,-134.243515,-0.010175,-0.005248,-0.133293,-0.387597,-0.019745,-1.332926,-134.243515,-0.132052,0.000000
3.710000,-0.037987,-134.199036,-0.009955,-0.005020,-0.127508,-0.168974,-0.008608,-1.275082,-134.199036,-0.126225,0.000000
4.060000,-0.070381,-134.287994,-0.009718,-0.004791,-0.121680,-0.313071,-0.015949,-1.216805,-134.287994,-0.120380,0.000000
4.410000,-0.056229,-134.243515,-0.009481,-0.004564,-0.115913,-0.250117,-0.012742,-1.159134,-134.243515,-0.114552,0.000000
4.760000,-0.093468,-134.376953,-0.009235,-0.004327,-0.109912,-0.415765,-0.021180,-1.099122,-134.376953,-0.108724,0.000000
5.110000,-0.137039,-134.332474,-0.009011,-0.004105,-0.104267,-0.609581,-0.031054,-1.042666,-134.332474,-0.102896,0.000000
5.460000,-0.073357,-134.376953,-0.008757,-0.003869,-0.098283,-0.326307,-0.016623,-0.982827,-134.376953,-0.097069,0.000000
5.810000,-0.033890,-134.376953,-0.008520,-0.003641,-0.092472,-0.150749,-0.007680,-0.924723,-134.376953,-0.091241,0.000000
6.160000,-0.049156,-134.421432,-0.008274,-0.003411,-0.086645,-0.218658,-0.011139,-0.866445,-134.421432,-0.085396,0.000000
6.510000,-0.082672,-134.421432,-0.008045,-0.003188,-0.080982,-0.367744,-0.018734,-0.809815,-134.421432,-0.079568,0.000000
6.860000,-0.126984,-134.421432,-0.007804,-0.002952,-0.074972,-0.564851,-0.028775,-0.749717,-134.421432,-0.073740,0.000000
7.210001,-0.114693,-134.465912,-0.007571,-0.002722,-0.069127,-0.510179,-0.025990,-0.691266,-134.465912,-0.067912,0.000000
7.560000,-0.045059,-134.554871,-0.007351,-0.002493,-0.063325,-0.200433,-0.010211,-0.633248,-134.554871,-0.062085,0.000000
7.910000,-0.027184,-134.554871,-0.007114,-0.002266,-0.057549,-0.120918,-0.006160,-0.575491,-134.554871,-0.056240,0.000000
8.260000,-0.058090,-134.554871,-0.006864,-0.002037,-0.051747,-0.258398,-0.013163,-0.517474,-134.554871,-0.050412,0.000000
8.610001,-0.083038,-134.510391,-0.006631,-0.001805,-0.045850,-0.369373,-0.018817,-0.458502,-134.510391,-0.044584,0.000000
8.960000,-0.142998,-134.599365,-0.006390,-0.001569,-0.039849,-0.636086,-0.032404,-0.398490,-134.599365,-0.038756,0.000000
9.310000,-0.096451,-134.643845,-0.006161,-0.001348,-0.034229,-0.429035,-0.021856,-0.342294,-134.643845,-0.032929,0.000000
9.660001,-0.052132,-134.688324,-0.005924,-0.001115,-0.028324,-0.231893,-0.011813,-0.283236,-134.688324,-0.027101,0.000000
10.010000,-0.040222,-134.688324,-0.005691,-0.000886,-0.022496,-0.178917,-0.009114,-0.224958,-134.688324,-0.021256,0.000000
10.360001,-0.049156,-134.688324,-0.005445,-0.000665,-0.016885,-0.218658,-0.011139,-0.168849,-134.688324,-0.015428,0.000000
10.710000,-0.098679,-134.688324,-0.005217,-0.000426,-0.010823,-0.438944,-0.022361,-0.108230,-134.688324,-0.009600,0.000000
11.060000,-0.080063,-134.688324,-0.004984,-0.000194,-0.004926,-0.356137,-0.018143,-0.049259,-134.688324,-0.003772,0.000000
11.410001,-0.030167,-134.821762,-0.004747,0.000029,0.000728,-0.134188,-0.006836,0.007285,-134.821762,0.002055,0.000000
11.760000,0.086014,-134.732803,-0.004665,-0.000004,-0.000095,0.382608,0.019491,-0.000954,-134.732803,0.000130,0.000000
12.110001,0.221184,-134.821762,-0.004682,-0.000004,-0.000095,0.983875,0.050121,-0.000954,-134.821762,0.000252,0.000000
12.460001,0.150436,-134.866241,-0.004687,-0.000003,-0.000069,0.669175,0.034089,-0.000694,-134.866241,0.000833,0.000000
12.810000,0.201454,-134.866241,-0.004669,0.000009,0.000225,0.896113,0.045650,0.002255,-134.866241,0.001414,0.000000
13.160001,0.454666,-134.910721,-0.004635,0.000033,0.000841,2.022456,0.103029,0.008412,-134.910721,0.002003,0.000000
13.510000,0.765594,-134.910721,-0.004618,0.000060,0.001526,3.405534,0.173486,0.015263,-134.910721,0.002584,0.000000
13.860001,1.015831,-134.910721,-0.004605,0.000081,0.002064,4.518642,0.230191,0.020640,-134.910721,0.003165,0.000000
14.210001,1.310379,-134.955200,-0.004600,0.000096,0.002446,5.828857,0.296936,0.024456,-134.955200,0.003746,0.000000
14.560000,1.780685,-134.999680,-0.004587,0.000122,0.003096,7.920884,0.403509,0.030960,-134.999680,0.004336,0.000000
14.910001,1.999634,-134.999680,-0.004562,0.000141,0.003590,8.894815,0.453124,0.035903,-134.999680,0.004917,0.000000
15.260001,2.897057,-134.999680,-0.004523,0.000174,0.004432,12.886751,0.656482,0.044315,-134.999680,0.005498,0.000000
15.610001,3.511467,-135.044174,-0.004514,0.000202,0.005125,15.619785,0.795710,0.051253,-135.044174,0.006088,0.000000
15.960001,4.025345,-135.044174,-0.004475,0.000223,0.005654,17.905628,0.912156,0.056543,-135.044174,0.006669,0.000000
16.310001,4.540337,-135.133133,-0.004475,0.000246,0.006244,20.196426,1.028855,0.062440,-135.133133,0.007250,0.000000
16.660000,4.949570,-135.133133,-0.004454,0.000263,0.006686,22.016787,1.121588,0.066863,-135.133133,0.007831,0.000000
17.010000,5.650375,-135.177612,-0.004432,0.000289,0.007345,25.134125,1.280393,0.073454,-135.177612,0.008421,0.000000
17.360001,6.173935,-135.177612,-0.004419,0.000308,0.007831,27.463034,1.399034,0.078311,-135.177612,0.009002,0.000000
17.710001,6.971924,-135.311050,-0.004398,0.000340,0.008629,31.012667,1.579860,0.086289,-135.311050,0.009583,0.000000
18.060001,7.425850,-135.266571,-0.004359,0.000365,0.009262,33.031830,1.682722,0.092620,-135.266571,0.010164,0.000000
18.410002,7.861153,-135.311050,-0.004368,0.000385,0.009791,34.968155,1.781363,0.097910,-135.311050,0.010754,0.000000
18.760000,8.553017,-135.266571,-0.004329,0.000410,0.010407,38.045719,1.938141,0.104067,-135.266571,0.011335,0.000000
19.110001,8.922417,-135.311050,-0.004303,0.000429,0.010892,39.688892,2.021848,0.108924,-135.311050,0.011916,0.000000
19.460001,9.371124,-135.355530,-0.004286,0.000453,0.011499,41.684841,2.123527,0.114994,-135.355530,0.012505,0.000000
19.810001,9.892815,-135.400009,-0.004264,0.000472,0.011985,44.005436,2.241744,0.119851,-135.400009,0.013086,0.000000
20.160002,10.483398,-135.355530,-0.004255,0.000496,0.012609,46.632484,2.375572,0.126095,-135.355530,0.013667,0.000000
20.510000,10.709427,-135.400009,-0.004238,0.000515,0.013086,47.637909,2.426791,0.130864,-135.400009,0.014249,0.000000
20.860001,11.278412,-135.444489,-0.004217,0.000539,0.013693,50.168880,2.555725,0.136935,-135.444489,0.014838,0.000000
21.210001,11.929321,-135.488983,-0.004217,0.000565,0.014344,53.064270,2.703223,0.143439,-135.488983,0.015419,0.000000
21.560001,12.207481,-135.533463,-0.004178,0.000586,0.014873,54.301590,2.766255,0.148729,-135.533463,0.016000,0.000000
21.910002,12.385101,-135.533463,-0.004152,0.000599,0.015211,55.091682,2.806504,0.152111,-135.533463,0.016581,0.000000
22.260000,13.119423,-135.533463,-0.004139,0.000628,0.015948,58.358109,2.972904,0.159483,-135.533463,0.017171,0.000000
22.610001,13.879433,-135.577942,-0.004122,0.000657,0.016677,61.738800,3.145124,0.166768,-135.577942,0.017752,0.000000
22.960001,14.271545,-135.577942,-0.004100,0.000679,0.017240,63.483006,3.233978,0.172405,-135.577942,0.018333,0.000000
23.310001,14.684502,-135.622421,-0.004066,0.000704,0.017882,65.319923,3.327556,0.178822,-135.622421,0.018914,0.000000
23.660002,14.804039,-135.666901,-0.004049,0.000722,0.018333,65.851654,3.354643,0.183332,-135.666901,0.019504,0.000000
24.010000,15.438187,-135.711380,-0.004018,0.000750,0.019044,68.672485,3.498343,0.190443,-135.711380,0.020085,0.000000
24.360001,15.826942,-135.711380,-0.004027,0.000774,0.019651,70.401756,3.586437,0.196513,-135.711380,0.020666,0.000000
24.710001,15.844818,-135.666901,-0.004005,0.000786,0.019955,70.481270,3.590487,0.199549,-135.666901,0.021256,0.000000
25.060001,16.935493,-135.800339,-0.003967,0.000817,0.020753,75.332840,3.837638,0.207527,-135.800339,0.021837,0.000000
25.410002,17.228928,-135.800339,-0.003967,0.000839,0.021308,76.638100,3.904131,0.213078,-135.800339,0.022418,0.000000
25.760002,17.775200,-135.755859,-0.003941,0.000864,0.021941,79.068039,4.027918,0.219408,-135.755859,0.022999,0.000000
26.110001,18.112190,-135.755859,-0.003923,0.000886,0.022496,80.567047,4.104281,0.224958,-135.755859,0.023589,0.000000
26.460001,18.481216,-135.800339,-0.003902,0.000909,0.023077,82.208557,4.187903,0.230769,-135.800339,0.024170,0.000000
26.810001,18.064903,-135.844818,-0.003889,0.000919,0.023354,80.356705,4.093565,0.233544,-135.844818,0.024751,0.000000
27.160002,19.269157,-135.889313,-0.003846,0.000953,0.024196,85.713493,4.366454,0.241956,-135.889313,0.025332,0.000000
27.510002,19.727173,-135.933792,-0.003833,0.000979,0.024872,87.750847,4.470241,0.248720,-135.933792,0.025921,0.000000
27.860001,20.002731,-135.978271,-0.003816,0.001002,0.025444,88.976593,4.532684,0.254444,-135.978271,0.026502,0.000000
28.210001,20.381432,-135.933792,-0.003794,0.001023,0.025991,90.661133,4.618498,0.259908,-135.933792,0.027083,0.000000
28.560001,20.796997,-135.933792,-0.003768,0.001045,0.026546,92.509666,4.712667,0.265458,-135.933792,0.027665,0.000000
28.910002,21.073296,-136.067230,-0.003747,0.001069,0.027162,93.738701,4.775277,0.271615,-136.067230,0.028254,0.000000
29.260002,21.906670,-136.022751,-0.003734,0.001097,0.027864,97.445732,4.964122,0.278640,-136.022751,0.028835,0.000000
29.610001,21.794960,-136.111710,-0.003704,0.001115,0.028332,96.948822,4.938808,0.283323,-136.111710,0.029416,0.000000
29.960001,21.969971,-136.067230,-0.003695,0.001141,0.028983,97.727310,4.978467,0.289827,-136.067230,0.030006,0.000000
30.310001,22.516617,-136.067230,-0.003665,0.001166,0.029607,100.158913,5.102338,0.296071,-136.067230,0.030587,0.000000
30.660002,22.536720,-136.156189,-0.003635,0.001184,0.030067,100.248337,5.106894,0.300667,-136.156189,0.031168,0.000000
31.010002,22.732590,-136.156189,-0.003635,0.001206,0.030630,101.119606,5.151278,0.306304,-136.156189,0.031749,0.000000
31.360001,22.667801,-136.200668,-0.003591,0.001218,0.030934,100.831413,5.136597,0.309339,-136.200668,0.032339,0.000000
31.710001,23.546600,-136.156189,-0.003600,0.001254,0.031862,104.740509,5.335736,0.318619,-136.156189,0.032920,0.000000
32.060001,23.802414,-136.245148,-0.003566,0.001273,0.032322,105.878426,5.393704,0.323215,-136.245148,0.033501,0.000000
32.410000,23.177200,-136.245148,-0.003535,0.001280,0.032512,103.097336,5.252029,0.325123,-136.245148,0.034082,0.000000
32.760002,24.729996,-136.334122,-0.003510,0.001320,0.033527,110.004517,5.603897,0.335270,-136.334122,0.034672,0.000000
33.110001,24.858467,-136.334122,-0.003497,0.001340,0.034047,110.575981,5.633009,0.340473,-136.334122,0.035253,0.000000
33.460003,25.312012,-136.334122,-0.003479,0.001372,0.034845,112.593452,5.735784,0.348451,-136.334122,0.035834,0.000000
33.810001,24.725159,-136.334122,-0.003471,0.001382,0.035114,109.983002,5.602801,0.351140,-136.334122,0.036423,0.000000
34.160000,25.506020,-136.334122,-0.003449,0.001412,0.035868,113.456444,5.779747,0.358685,-136.334122,0.037005,0.000000
34.510002,25.808762,-136.378601,-0.003406,0.001433,0.036406,114.803108,5.848349,0.364061,-136.378601,0.037586,0.000000
34.860001,26.186722,-136.423080,-0.003393,0.001460,0.037074,116.484360,5.933996,0.370739,-136.423080,0.038167,0.000000
35.210003,26.380722,-136.467560,-0.003380,0.001482,0.037655,117.347313,5.977957,0.376550,-136.467560,0.038756,0.000000
35.560001,26.169586,-136.467560,-0.003359,0.001500,0.038089,116.408134,5.930113,0.380886,-136.467560,0.039337,0.000000
35.910000,26.664101,-136.467560,-0.003337,0.001520,0.038618,118.607841,6.042171,0.386176,-136.467560,0.039918,0.000000
36.260002,27.176109,-136.512039,-0.003298,0.001546,0.039259,120.885368,6.158195,0.392593,-136.512039,0.040499,0.000000
36.610001,28.080231,-136.600998,-0.003285,0.001575,0.040014,124.907104,6.363071,0.400138,-136.600998,0.041089,0.000000
36.960003,28.249290,-136.556519,-0.003255,0.001600,0.040647,125.659119,6.401381,0.406469,-136.556519,0.041670,0.000000
37.310001,28.139809,-136.556519,-0.003238,0.001623,0.041219,125.172119,6.376572,0.412193,-136.556519,0.042251,0.000000
37.660004,28.255623,-136.645477,-0.003208,0.001644,0.041766,125.687286,6.402815,0.417656,-136.645477,0.042832,0.000000
38.010002,28.346107,-136.600998,-0.003191,0.001668,0.042373,126.089783,6.423319,0.423727,-136.600998,0.043422,0.000000
38.360001,28.671928,-136.645477,-0.003173,0.001689,0.042910,127.539108,6.497152,0.429103,-136.645477,0.044003,0.000000
38.710003,28.736725,-136.689957,-0.003173,0.001710,0.043439,127.827339,6.511835,0.434393,-136.689957,0.044584,0.000000
39.060001,29.617386,-136.645477,-0.003130,0.001738,0.044150,131.744705,6.711396,0.441505,-136.645477,0.045174,0.000000
39.410004,29.945076,-136.689957,-0.003104,0.001764,0.044810,133.202347,6.785651,0.448096,-136.689957,0.045755,0.000000
39.760002,30.030716,-136.689957,-0.003065,0.001789,0.045434,133.583298,6.805058,0.454340,-136.689957,0.046336,0.000000
40.110001,30.258240,-136.823410,-0.003061,0.001808,0.045920,134.595367,6.856615,0.459196,-136.823410,0.046917,0.000000
40.460003,30.343140,-136.823410,-0.003035,0.001829,0.046466,134.973022,6.875854,0.464659,-136.823410,0.047507,0.000000
40.810001,30.757965,-136.823410,-0.003022,0.001852,0.047038,136.818268,6.969854,0.470383,-136.823410,0.048088,0.000000
41.160004,30.913239,-136.823410,-0.002984,0.001870,0.047507,137.508957,7.005040,0.475066,-136.823410,0.048669,0.000000
41.510002,31.396210,-136.912369,-0.002984,0.001897,0.048192,139.657318,7.114483,0.481917,-136.912369,0.049250,0.000000
41.860001,31.281517,-136.912369,-0.002949,0.001914,0.048608,139.147141,7.088493,0.486080,-136.912369,0.049839,0.000000
42.210003,31.785713,-136.867889,-0.002953,0.001939,0.049241,141.389908,7.202746,0.492411,-136.867889,0.050421,0.000000
42.560001,32.461937,-136.956848,-0.002915,0.001964,0.049874,144.397903,7.355980,0.498742,-136.956848,0.051002,0.000000
42.910004,32.603813,-136.956848,-0.002897,0.001983,0.050368,145.029007,7.388130,0.503685,-136.956848,0.051591,0.000000
43.260002,31.837845,-137.001328,-0.002876,0.002001,0.050837,141.621811,7.214559,0.508368,-137.001328,0.052172,0.000000
43.610001,33.362335,-137.001328,-0.002854,0.002026,0.051470,148.403076,7.560013,0.514699,-137.001328,0.052753,0.000000
43.960003,34.393806,-137.001328,-0.002854,0.002055,0.052207,152.991287,7.793748,0.522070,-137.001328,0.053334,0.000000
44.310001,34.669365,-137.090286,-0.002828,0.002080,0.052831,154.217041,7.856190,0.528314,-137.090286,0.053924,0.000000
44.660004,35.041733,-137.001328,-0.002798,0.002103,0.053412,155.873413,7.940570,0.534124,-137.001328,0.054505,0.000000
45.010002,34.791130,-137.090286,-0.002781,0.002120,0.053837,154.758682,7.883783,0.538374,-137.090286,0.055086,0.000000
45.360001,35.668068,-137.090286,-0.002759,0.002149,0.054592,158.659485,8.082500,0.545919,-137.090286,0.055667,0.000000
45.710003,35.841965,-137.134766,-0.002738,0.002173,0.055182,159.433029,8.121905,0.551816,-137.134766,0.056257,0.000000
46.060001,35.235741,-137.179260,-0.002716,0.002182,0.055424,156.736404,7.984533,0.554244,-137.179260,0.056838,0.000000
46.410004,36.623199,-137.134766,-0.002695,0.002216,0.056274,162.908127,8.298936,0.562743,-137.134766,0.057419,0.000000
46.760002,36.838058,-137.268219,-0.002682,0.002238,0.056847,163.863861,8.347623,0.568467,-137.268219,0.058000,0.000000
47.110001,37.432365,-137.223740,-0.002665,0.002265,0.057532,166.507477,8.482295,0.575318,-137.223740,0.058590,0.000000
47.460003,37.622276,-137.223740,-0.002647,0.002286,0.058061,167.352249,8.525330,0.580608,-137.223740,0.059171,0.000000
47.810001,37.959274,-137.312698,-0.002608,0.002307,0.058598,168.851288,8.601694,0.585985,-137.312698,0.059752,0.000000
48.160004,37.592857,-137.312698,-0.002600,0.002329,0.059145,167.221375,8.518663,0.591448,-137.312698,0.060342,0.000000
48.510002,38.798973,-137.357178,-0.002583,0.002354,0.059795,172.586456,8.791973,0.597952,-137.357178,0.060923,0.000000
48.860001,39.347481,-137.312698,-0.002561,0.002379,0.060437,175.026337,8.916266,0.604370,-137.312698,0.061504,0.000000
49.210003,39.611862,-137.357178,-0.002522,0.002401,0.060992,176.202362,8.976176,0.609920,-137.357178,0.062085,0.000000
49.560001,39.847946,-137.312698,-0.002518,0.002422,0.061512,177.252518,9.029674,0.615123,-137.312698,0.062674,0.000000
49.910004,40.146217,-137.401657,-0.002496,0.002442,0.062024,178.579300,9.097263,0.620240,-137.401657,0.063255,0.000000
50.260002,40.728233,-137.446136,-0.002479,0.002467,0.062657,181.168228,9.229150,0.626571,-137.446136,0.063836,0.000000
50.610001,41.676292,-137.446136,-0.002466,0.002497,0.063420,185.385406,9.443983,0.634202,-137.446136,0.064418,0.000000
50.960003,41.907913,-137.446136,-0.002427,0.002519,0.063993,186.415710,9.496469,0.639926,-137.446136,0.065007,0.000000
51.310001,42.134689,-137.490616,-0.002423,0.002540,0.064504,187.424454,9.547857,0.645043,-137.490616,0.065588,0.000000
51.660004,42.677979,-137.446136,-0.002397,0.002564,0.065120,189.841125,9.670968,0.651200,-137.446136,0.066169,0.000000
52.010002,42.641853,-137.579575,-0.002371,0.002582,0.065580,189.680435,9.662782,0.655796,-137.579575,0.066759,0.000000
52.360001,42.766228,-137.535095,-0.002350,0.002603,0.066109,190.233688,9.690966,0.661086,-137.535095,0.067340,0.000000
52.710003,42.618401,-137.535095,-0.002333,0.002617,0.066482,189.576111,9.657467,0.664815,-137.535095,0.067921,0.000000
53.060001,43.970856,-137.579575,-0.002320,0.002654,0.067401,195.592133,9.963938,0.674008,-137.579575,0.068502,0.000000
53.410004,44.327957,-137.624069,-0.002289,0.002671,0.067852,197.180603,10.044859,0.678517,-137.624069,0.069092,0.000000
53.760002,44.438179,-137.624069,-0.002272,0.002698,0.068520,197.670898,10.069835,0.685195,-137.624069,0.069673,0.000000
54.110004,45.664406,-137.668549,-0.002264,0.002718,0.069040,203.125427,10.347703,0.690398,-137.668549,0.070254,0.000000
54.460003,45.957832,-137.668549,-0.002229,0.002739,0.069569,204.430649,10.414194,0.695689,-137.668549,0.070835,0.000000
54.810001,47.224274,-137.668549,-0.002220,0.002773,0.070427,210.064056,10.701173,0.704274,-137.668549,0.071425,0.000000
55.160004,46.392761,-137.668549,-0.002186,0.002781,0.070636,206.365311,10.512750,0.706355,-137.668549,0.072006,0.000000
55.510002,47.524033,-137.801987,-0.002190,0.002810,0.071381,211.397461,10.769100,0.713813,-137.801987,0.072587,0.000000
55.860004,47.870712,-137.801987,-0.002164,0.002830,0.071884,212.939560,10.847658,0.718844,-137.801987,0.073168,0.000000
56.210003,48.830315,-137.801987,-0.002130,0.002858,0.072604,217.208084,11.065108,0.726041,-137.801987,0.073758,0.000000
56.560001,49.210510,-137.846466,-0.002130,0.002882,0.073211,218.899277,11.151261,0.732112,-137.846466,0.074339,0.000000
56.910004,48.918938,-137.801987,-0.002113,0.002893,0.073471,217.602310,11.085189,0.734714,-137.801987,0.074920,0.000000
57.260002,49.191147,-137.846466,-0.002095,0.002911,0.073948,218.813156,11.146873,0.739483,-137.846466,0.075509,0.000000
57.610004,50.678024,-137.890945,-0.002065,0.002943,0.074746,225.427109,11.483804,0.747462,-137.890945,0.076090,0.000000
57.960003,52.271782,-137.890945,-0.002044,0.002976,0.075579,232.516495,11.844955,0.755787,-137.890945,0.076671,0.000000
58.310001,53.058601,-137.935425,-0.002018,0.003001,0.076220,236.016449,12.023251,0.762205,-137.935425,0.077252,0.000000
58.660004,53.524071,-137.979904,-0.002013,0.003023,0.076793,238.086960,12.128727,0.767928,-137.979904,0.077842,0.000000
59.010002,54.014488,-137.979904,-0.001975,0.003043,0.077305,240.268448,12.239858,0.773045,-137.979904,0.078423,0.000000
59.360004,54.307167,-138.024384,-0.001970,0.003069,0.077955,241.570343,12.306180,0.779549,-138.024384,0.079004,0.000000
59.710003,54.574532,-138.068878,-0.001957,0.003081,0.078250,242.759644,12.366766,0.782498,-138.068878,0.079585,0.000000
60.060001,55.557220,-138.113358,-0.001940,0.003108,0.078944,247.130859,12.589446,0.789436,-138.113358,0.080175,0.000000
60.410004,57.099594,-138.113358,-0.001940,0.003137,0.079672,253.991684,12.938952,0.796720,-138.113358,0.080756,0.000000
60.760002,58.009666,-138.157837,-0.001906,0.003163,0.080331,258.039886,13.145178,0.803311,-138.157837,0.081337,0.000000
61.110004,58.746964,-138.113358,-0.001893,0.003188,0.080964,261.319550,13.312252,0.809642,-138.113358,0.081918,0.000000
61.460003,59.430267,-138.157837,-0.001863,0.003207,0.081450,264.359039,13.467092,0.814498,-138.157837,0.082508,0.000000
61.810001,60.059204,-138.157837,-0.001858,0.003229,0.082014,267.156677,13.609610,0.820135,-138.157837,0.083089,0.000000
62.160004,61.016205,-138.246796,-0.001832,0.003253,0.082629,271.413635,13.826469,0.826293,-138.246796,0.083670,0.000000
62.510002,61.736000,-138.246796,-0.001828,0.003271,0.083080,274.615448,13.989577,0.830802,-138.246796,0.084260,0.000000
62.860004,62.806572,-138.246796,-0.001807,0.003298,0.083774,279.377594,14.232173,0.837740,-138.246796,0.084841,0.000000
63.210003,63.463814,-138.246796,-0.001789,0.003316,0.084225,282.301147,14.381106,0.842250,-138.246796,0.085422,0.000000
63.560001,64.507561,-138.291275,-0.001781,0.003338,0.084780,286.943970,14.617622,0.847800,-138.291275,0.086003,0.000000
63.910004,65.701393,-138.335754,-0.001785,0.003364,0.085439,292.254395,14.888148,0.854391,-138.335754,0.086592,0.000000
64.260002,66.220482,-138.335754,-0.001750,0.003373,0.085682,294.563416,15.005776,0.856819,-138.335754,0.085890,0.000000
64.610001,64.775307,-138.335754,-0.001742,0.003377,0.085777,288.134949,14.678294,0.857773,-138.335754,294.500488,0.000000
64.960007,64.669548,-138.424713,-0.001720,0.003388,0.086063,287.664520,14.654329,0.860635,-138.424713,294.500488,0.000000
65.310005,64.901161,-138.380234,-0.001729,0.003401,0.086376,288.694794,14.706813,0.863757,-138.380234,294.500488,0.000000
65.660004,64.905632,-138.469208,-0.001703,0.003416,0.086757,288.714661,14.707827,0.867573,-138.469208,294.500488,0.000000
66.010002,64.795784,-138.513687,-0.001703,0.003429,0.087087,288.226044,14.682934,0.870868,-138.513687,294.500488,0.000000
66.360001,64.920158,-138.513687,-0.001690,0.003428,0.087069,288.779297,14.711118,0.870695,-138.513687,294.500488,0.000000
66.710007,65.438866,-138.513687,-0.001686,0.003442,0.087416,291.086609,14.828659,0.874164,-138.513687,294.500488,0.000000
67.060005,64.707161,-138.558167,-0.001681,0.003442,0.087416,287.831818,14.662852,0.874164,-138.558167,294.500488,0.000000
67.410004,65.779213,-138.602646,-0.001681,0.003453,0.087711,292.600555,14.905783,0.877112,-138.602646,294.500488,0.000000
67.760002,64.941750,-138.602646,-0.001673,0.003454,0.087720,288.875336,14.716010,0.877199,-138.602646,294.500488,0.000000
68.110001,65.416527,-138.602646,-0.001660,0.003469,0.088101,290.987244,14.823597,0.881015,-138.602646,294.500488,0.000000
68.460007,65.342430,-138.602646,-0.001660,0.003476,0.088284,290.657654,14.806807,0.882836,-138.602646,294.500488,0.000000
68.810005,65.280983,-138.647125,-0.001647,0.003481,0.088405,290.384308,14.792882,0.884050,-138.647125,294.500488,0.000000
69.160004,65.242638,-138.691605,-0.001630,0.003485,0.088526,290.213745,14.784193,0.885264,-138.691605,294.500488,0.000000
69.510002,65.013618,-138.691605,-0.001634,0.003488,0.088587,289.195007,14.732296,0.885871,-138.691605,294.500488,0.000000
69.860001,65.604576,-138.736084,-0.001638,0.003500,0.088891,291.823730,14.866209,0.888906,-138.736084,294.500488,0.000000
70.210007,65.298866,-138.780563,-0.001625,0.003500,0.088891,290.463867,14.796934,0.888906,-138.780563,294.500488,0.000000
70.560005,64.906380,-138.825043,-0.001630,0.003504,0.088995,288.717987,14.707996,0.889947,-138.825043,294.500488,0.000000
70.910004,65.138374,-138.780563,-0.001630,0.003507,0.089081,289.749969,14.760567,0.890814,-138.780563,294.500488,0.000000
71.260002,65.370720,-138.780563,-0.001613,0.003515,0.089290,290.783478,14.813217,0.892896,-138.780563,294.500488,0.000000
71.610001,65.199059,-138.914017,-0.001600,0.003515,0.089290,290.019897,14.774318,0.892896,-138.914017,294.500488,0.000000
71.960007,64.878822,-138.869522,-0.001625,0.003516,0.089298,288.595428,14.701751,0.892982,-138.869522,294.500488,0.000000
72.310005,65.889076,-138.914017,-0.001595,0.003529,0.089645,293.089264,14.930678,0.896451,-138.914017,294.500488,0.000000
72.660004,65.597130,-138.869522,-0.001608,0.003529,0.089645,291.790619,14.864522,0.896451,-138.869522,294.500488,0.000000
73.010002,65.287682,-139.002975,-0.001600,0.003529,0.089645,290.414124,14.794400,0.896451,-139.002975,294.500488,0.000000
73.360001,64.973412,-139.002975,-0.001591,0.003529,0.089645,289.016174,14.723186,0.896451,-139.002975,294.500488,0.000000
73.710007,64.669548,-139.047455,-0.001595,0.003530,0.089654,287.664520,14.654329,0.896538,-139.047455,294.500488,0.000000
74.060005,67.069496,-139.047455,-0.001595,0.003542,0.089966,298.340027,15.198165,0.899660,-139.047455,294.500488,0.000000
74.410004,66.383202,-139.047455,-0.001582,0.003483,0.088466,295.287231,15.042648,0.884657,-139.047455,294.500488,0.000000
74.760002,66.070045,-139.091934,-0.001569,0.003483,0.088466,293.894226,14.971686,0.884657,-139.091934,294.500488,0.000000
75.110001,65.748314,-139.136414,-0.001578,0.003486,0.088544,292.463104,14.898781,0.885438,-139.136414,294.500488,0.000000
75.460007,65.481697,-139.091934,-0.001578,0.003505,0.089021,291.277130,14.838365,0.890207,-139.091934,294.500488,0.000000
75.810005,65.231834,-139.180893,-0.001569,0.003514,0.089264,290.165680,14.781745,0.892636,-139.180893,294.500488,0.000000
76.160004,65.103737,-139.225372,-0.001565,0.003543,0.089992,289.595886,14.752718,0.899920,-139.225372,294.500488,0.000000
76.510002,65.115273,-139.269852,-0.001574,0.003547,0.090105,289.647186,14.755332,0.901047,-139.269852,294.500488,0.000000
76.860001,65.149544,-139.180893,-0.001565,0.003550,0.090174,289.799652,14.763098,0.901741,-139.180893,294.500488,0.000000
77.210007,65.197578,-139.358826,-0.001565,0.003553,0.090244,290.013306,14.773982,0.902435,-139.358826,294.500488,0.000000
77.560005,65.056068,-139.269852,-0.001569,0.003554,0.090270,289.383850,14.741916,0.902695,-139.269852,294.500488,0.000000
77.910004,65.126076,-139.314346,-0.001565,0.003557,0.090348,289.695251,14.757779,0.903476,-139.314346,294.500488,0.000000
78.260002,65.148048,-139.358826,-0.001565,0.003560,0.090417,289.792999,14.762759,0.904170,-139.358826,294.500488,0.000000
78.610001,65.278008,-139.403305,-0.001561,0.003564,0.090521,290.371094,14.792209,0.905210,-139.403305,294.500488,0.000000
78.960007,65.233696,-139.447784,-0.001561,0.003564,0.090521,290.173981,14.782166,0.905210,-139.447784,294.500488,0.000000
79.310005,65.101875,-139.403305,-0.001561,0.003565,0.090538,289.587616,14.752295,0.905384,-139.403305,294.500488,0.000000
79.660004,65.179695,-139.447784,-0.001556,0.003567,0.090608,289.933777,14.769930,0.906078,-139.447784,294.500488,0.000000
80.010002,65.314873,-139.447784,-0.001548,0.003572,0.090738,290.535065,14.800561,0.907378,-139.447784,294.500488,0.000000
80.360001,65.331993,-139.447784,-0.001556,0.003572,0.090738,290.611206,14.804441,0.907378,-139.447784,294.500488,0.000000
80.710007,65.218056,-139.536743,-0.001556,0.003573,0.090746,290.104401,14.778623,0.907465,-139.536743,294.500488,0.000000
81.060005,65.098900,-139.492264,-0.001548,0.003573,0.090746,289.574371,14.751621,0.907465,-139.492264,294.500488,0.000000
81.410004,65.129433,-139.536743,-0.001544,0.003579,0.090911,289.710175,14.758540,0.909113,-139.536743,294.500488,0.000000
81.760002,65.355095,-139.581223,-0.001539,0.003579,0.090903,290.713989,14.809676,0.909026,-139.581223,294.500488,0.000000
82.110001,65.276512,-139.581223,-0.001544,0.003579,0.090903,290.364441,14.791869,0.909026,-139.581223,294.500488,0.000000
82.460007,65.116402,-139.670181,-0.001535,0.003579,0.090903,289.652222,14.755588,0.909026,-139.670181,294.500488,0.000000
82.810005,65.006172,-139.670181,-0.001548,0.003579,0.090911,289.161896,14.730610,0.909113,-139.670181,294.500488,0.000000
83.160004,64.956642,-139.670181,-0.001518,0.003581,0.090955,288.941589,14.719386,0.909546,-139.670181,294.500488,0.000000
83.510002,64.873238,-139.759155,-0.001544,0.003581,0.090955,288.570587,14.700485,0.909546,-139.759155,294.500488,0.000000
83.860001,64.913078,-139.759155,-0.001548,0.003583,0.091007,288.747803,14.709514,0.910067,-139.759155,294.500488,0.000000
84.210007,64.819618,-139.803635,-0.001531,0.003583,0.091007,288.332062,14.688335,0.910067,-139.803635,294.500488,0.000000
84.560005,64.723167,-139.848114,-0.001526,0.003583,0.091007,287.903015,14.666480,0.910067,-139.848114,294.500488,0.000000
84.910004,64.640129,-139.759155,-0.001535,0.003583,0.091015,287.533661,14.647663,0.910153,-139.759155,294.500488,0.000000
85.260002,64.525810,-139.848114,-0.001526,0.003583,0.091015,287.025146,14.621758,0.910153,-139.848114,294.500488,0.000000
85.610001,65.805656,-139.803635,-0.001518,0.003596,0.091328,292.718170,14.911775,0.913276,-139.803635,294.500488,0.000000
85.960007,65.650383,-139.892593,-0.001531,0.003596,0.091328,292.027496,14.876590,0.913276,-139.892593,294.500488,0.000000
86.310005,65.549095,-139.892593,-0.001518,0.003596,0.091328,291.576935,14.853638,0.913276,-139.892593,294.500488,0.000000
86.660004,65.449669,-139.892593,-0.001535,0.003596,0.091328,291.134674,14.831106,0.913276,-139.892593,294.500488,0.000000
87.010002,65.330879,-139.892593,-0.001544,0.003596,0.091328,290.606262,14.804189,0.913276,-139.892593,294.500488,0.000000
87.360001,65.247475,-139.937073,-0.001531,0.003596,0.091328,290.235260,14.785289,0.913276,-139.937073,294.500488,0.000000
87.710007,65.136513,-139.981552,-0.001526,0.003596,0.091328,289.741669,14.760145,0.913276,-139.981552,294.500488,0.000000
88.060005,65.031120,-140.026031,-0.001522,0.003596,0.091328,289.272858,14.736262,0.913276,-140.026031,294.500488,0.000000
88.410004,64.948830,-140.070511,-0.001531,0.003596,0.091328,288.906830,14.717615,0.913276,-140.070511,294.500488,0.000000
88.760002,64.832649,-140.026031,-0.001531,0.003596,0.091328,288.390015,14.691288,0.913276,-140.026031,294.500488,0.000000
89.110001,64.748863,-140.026031,-0.001513,0.003596,0.091328,288.017334,14.672302,0.913276,-140.026031,294.500488,0.000000
89.460007,64.669548,-140.070511,-0.001518,0.003596,0.091328,287.664520,14.654329,0.913276,-140.070511,294.500488,0.000000
89.810005,64.570122,-140.114990,-0.001522,0.003596,0.091336,287.222260,14.631799,0.913362,-140.114990,294.500488,0.000000
90.160004,66.234261,-140.159470,-0.001509,0.003604,0.091544,294.624695,15.008898,0.915444,-140.159470,294.500488,0.000000
90.510002,66.083443,-140.114990,-0.001496,0.003602,0.091492,293.953827,14.974723,0.914923,-140.114990,294.500488,0.000000
90.860001,65.976952,-140.159470,-0.001509,0.003602,0.091484,293.480133,14.950591,0.914837,-140.159470,294.500488,0.000000
91.210007,65.881248,-140.203964,-0.001509,0.003602,0.091484,293.054443,14.928905,0.914837,-140.203964,294.500488,0.000000
91.560005,65.781456,-140.203964,-0.001509,0.003602,0.091484,292.610535,14.906291,0.914837,-140.203964,294.500488,0.000000
91.910004,65.665642,-140.248444,-0.001505,0.003602,0.091484,292.095367,14.880048,0.914837,-140.248444,294.500488,0.000000
92.260002,65.562126,-140.248444,-0.001500,0.003602,0.091484,291.634888,14.856590,0.914837,-140.248444,294.500488,0.000000
92.610001,65.502174,-140.337402,-0.001513,0.003602,0.091484,291.368225,14.843005,0.914837,-140.337402,294.500488,0.000000
92.960007,65.376320,-140.381882,-0.001505,0.003602,0.091484,290.808380,14.814486,0.914837,-140.381882,294.500488,0.000000
93.310005,65.301094,-140.292923,-0.001509,0.003602,0.091484,290.473785,14.797440,0.914837,-140.292923,294.500488,0.000000
93.660004,65.243004,-140.381882,-0.001500,0.003602,0.091484,290.215363,14.784276,0.914837,-140.381882,294.500488,0.000000
94.010002,65.125710,-140.381882,-0.001505,0.003602,0.091484,289.693634,14.757697,0.914837,-140.381882,294.500488,0.000000
94.360008,65.034477,-140.381882,-0.001518,0.003602,0.091484,289.287811,14.737023,0.914837,-140.381882,294.500488,0.000000
94.710007,64.964470,-140.426361,-0.001500,0.003602,0.091484,288.976410,14.721160,0.914837,-140.426361,294.500488,0.000000
95.060005,64.895576,-140.470840,-0.001500,0.003613,0.091778,288.669952,14.705547,0.917785,-140.470840,294.500488,0.000000
95.410004,65.483177,-140.470840,-0.001518,0.003617,0.091883,291.283722,14.838700,0.918826,-140.470840,294.500488,0.000000
95.760002,65.462700,-140.559799,-0.001496,0.003617,0.091883,291.192627,14.834060,0.918826,-140.559799,294.500488,0.000000
96.110008,65.398277,-140.515320,-0.001492,0.003617,0.091883,290.906067,14.819462,0.918826,-140.515320,294.500488,0.000000
96.460007,65.354713,-140.559799,-0.001496,0.003617,0.091883,290.712280,14.809589,0.918826,-140.559799,294.500488,0.000000
96.810005,65.310402,-140.559799,-0.001492,0.003618,0.091891,290.515167,14.799548,0.918912,-140.559799,294.500488,0.000000
97.160004,65.245613,-140.559799,-0.001496,0.003618,0.091891,290.226990,14.784867,0.918912,-140.559799,294.500488,0.000000
97.510002,65.218803,-140.604294,-0.001505,0.003618,0.091891,290.107727,14.778792,0.918912,-140.604294,294.500488,0.000000
97.860008,65.141350,-140.648773,-0.001500,0.003618,0.091891,289.763184,14.761241,0.918912,-140.648773,294.500488,0.000000
98.210007,65.092567,-140.648773,-0.001496,0.003618,0.091900,289.546204,14.750187,0.918999,-140.648773,294.500488,0.000000
98.560005,65.050484,-140.737732,-0.001492,0.003618,0.091909,289.359009,14.740650,0.919086,-140.737732,294.500488,0.000000
98.910004,64.993141,-140.782211,-0.001500,0.003618,0.091909,289.103943,14.727656,0.919086,-140.782211,294.500488,0.000000
99.260002,65.297371,-140.826691,-0.001496,0.003624,0.092047,290.457214,14.796596,0.920473,-140.826691,294.500488,0.000000
99.610008,65.295876,-140.826691,-0.001487,0.003624,0.092047,290.450562,14.796256,0.920473,-140.826691,294.500488,0.000000
99.960007,65.278008,-140.693253,-0.001500,0.003624,0.092047,290.371094,14.792209,0.920473,-140.693253,294.500488,0.000000
100.310005,65.234444,-140.826691,-0.001492,0.003624,0.092047,290.177307,14.782336,0.920473,-140.826691,294.500488,0.000000
100.660004,65.180443,-140.871170,-0.001505,0.003624,0.092047,289.937103,14.770100,0.920473,-140.871170,294.500488,0.000000
101.010002,65.217308,-140.871170,-0.001487,0.003625,0.092082,290.101074,14.778454,0.920820,-140.871170,294.500488,0.000000
101.360008,65.200188,-140.871170,-0.001496,0.003625,0.092082,290.024933,14.774573,0.920820,-140.871170,294.500488,0.000000
101.710007,65.151405,-140.871170,-0.001487,0.003625,0.092082,289.807922,14.763519,0.920820,-140.871170,294.500488,0.000000
102.060005,65.103737,-140.960129,-0.001496,0.003625,0.092082,289.595886,14.752718,0.920820,-140.960129,294.500488,0.000000
102.410004,65.195717,-140.960129,-0.001492,0.003629,0.092186,290.005035,14.773561,0.921861,-140.960129,294.500488,0.000000
102.760002,65.302956,-140.960129,-0.001496,0.003629,0.092186,290.482056,14.797861,0.921861,-140.960129,294.500488,0.000000
103.110008,65.305183,-141.049103,-0.001487,0.003629,0.092186,290.491974,14.798367,0.921861,-141.049103,294.500488,0.000000
103.460007,65.275780,-141.049103,-0.001487,0.003629,0.092186,290.361176,14.791703,0.921861,-141.049103,294.500488,0.000000
103.810005,65.246361,-141.138062,-0.001496,0.003629,0.092186,290.230316,14.785036,0.921861,-141.138062,294.500488,0.000000
104.160004,65.189751,-141.138062,-0.001492,0.003629,0.092186,289.978485,14.772208,0.921861,-141.138062,294.500488,0.000000
104.510002,65.137627,-141.093582,-0.001487,0.003630,0.092195,289.746643,14.760398,0.921948,-141.093582,294.500488,0.000000
104.860008,65.089592,-141.138062,-0.001483,0.003630,0.092195,289.532959,14.749513,0.921948,-141.138062,294.500488,0.000000
105.210007,65.079536,-141.093582,-0.001487,0.003631,0.092229,289.488251,14.747233,0.922295,-141.093582,294.500488,0.000000
105.560005,65.074318,-141.182541,-0.001479,0.003631,0.092229,289.465027,14.746051,0.922295,-141.182541,294.500488,0.000000
105.910004,65.053093,-141.271500,-0.001475,0.003631,0.092229,289.370605,14.741241,0.922295,-141.271500,294.500488,0.000000
106.260002,65.015480,-141.227020,-0.001487,0.003631,0.092229,289.203308,14.732718,0.922295,-141.227020,294.500488,0.000000
106.610008,64.989052,-141.271500,-0.001483,0.003631,0.092229,289.085754,14.726729,0.922295,-141.271500,294.500488,0.000000
106.960007,64.960381,-141.227020,-0.001487,0.003631,0.092229,288.958191,14.720233,0.922295,-141.227020,294.500488,0.000000
107.310005,64.942497,-141.271500,-0.001492,0.003631,0.092238,288.878662,14.716180,0.922381,-141.271500,294.500488,0.000000
107.660004,65.256416,-141.315979,-0.001483,0.003638,0.092394,290.275024,14.787314,0.923942,-141.315979,294.500488,0.000000
108.010002,65.339455,-141.360458,-0.001496,0.003638,0.092394,290.644409,14.806131,0.923942,-141.360458,294.500488,0.000000
108.360008,65.327904,-141.360458,-0.001492,0.003638,0.092394,290.593018,14.803514,0.923942,-141.360458,294.500488,0.000000
108.710007,65.314507,-141.404938,-0.001470,0.003638,0.092394,290.533447,14.800479,0.923942,-141.404938,294.500488,0.000000
109.060005,65.302208,-141.404938,-0.001475,0.003638,0.092394,290.478729,14.797691,0.923942,-141.404938,294.500488,0.000000
109.410004,65.274651,-141.404938,-0.001479,0.003638,0.092394,290.356140,14.791448,0.923942,-141.404938,294.500488,0.000000
109.760002,65.248955,-141.449417,-0.001475,0.003638,0.092394,290.241852,14.785625,0.923942,-141.449417,294.500488,0.000000
110.110008,65.228111,-141.493912,-0.001470,0.003638,0.092394,290.149139,14.780901,0.923942,-141.493912,294.500488,0.000000
110.460007,65.171501,-141.493912,-0.001470,0.003638,0.092394,289.897308,14.768073,0.923942,-141.493912,294.500488,0.000000
110.810005,65.140236,-141.538391,-0.001475,0.003638,0.092394,289.758240,14.760988,0.923942,-141.538391,294.500488,0.000000
111.160004,65.098900,-141.538391,-0.001492,0.003638,0.092403,289.574371,14.751621,0.924029,-141.538391,294.500488,0.000000
111.510002,65.067619,-141.538391,-0.001483,0.003638,0.092403,289.435211,14.744533,0.924029,-141.538391,294.500488,0.000000
111.860008,65.029259,-141.627350,-0.001479,0.003638,0.092403,289.264587,14.735841,0.924029,-141.627350,294.500488,0.000000
112.210007,65.127571,-141.627350,-0.001483,0.003640,0.092464,289.701904,14.758119,0.924636,-141.627350,294.500488,0.000000
112.560005,65.143959,-141.627350,-0.001475,0.003640,0.092464,289.774811,14.761832,0.924636,-141.627350,294.500488,0.000000
112.910004,65.121605,-141.716309,-0.001470,0.003642,0.092498,289.675354,14.756766,0.924983,-141.716309,294.500488,0.000000
113.260002,65.182686,-141.671829,-0.001475,0.003642,0.092498,289.947083,14.770608,0.924983,-141.671829,294.500488,0.000000
113.610008,65.168526,-141.716309,-0.001483,0.003642,0.092498,289.884094,14.767399,0.924983,-141.716309,294.500488,0.000000
113.960007,65.143959,-141.671829,-0.001479,0.003642,0.092498,289.774811,14.761832,0.924983,-141.671829,294.500488,0.000000
114.310005,65.123100,-141.760788,-0.001483,0.003642,0.092498,289.682007,14.757106,0.924983,-141.760788,294.500488,0.000000
114.660004,65.102989,-141.760788,-0.001479,0.003642,0.092498,289.592560,14.752548,0.924983,-141.760788,294.500488,0.000000
115.010002,65.076546,-141.805267,-0.001470,0.003642,0.092507,289.474945,14.746555,0.925070,-141.805267,294.500488,0.000000
115.360008,65.351738,-141.805267,-0.001475,0.003647,0.092628,290.699036,14.808915,0.926284,-141.805267,294.500488,0.000000
115.710007,65.402382,-141.894241,-0.001487,0.003647,0.092628,290.924316,14.820392,0.926284,-141.894241,294.500488,0.000000
116.060005,65.403496,-141.805267,-0.001475,0.003647,0.092628,290.929291,14.820643,0.926284,-141.805267,294.500488,0.000000
116.410004,65.381157,-141.894241,-0.001483,0.003647,0.092628,290.829926,14.815581,0.926284,-141.894241,294.500488,0.000000
116.760002,65.356575,-141.983200,-0.001470,0.003647,0.092628,290.720551,14.810012,0.926284,-141.983200,294.500488,0.000000
117.110008,65.350624,-141.894241,-0.001466,0.003647,0.092628,290.694092,14.808662,0.926284,-141.894241,294.500488,0.000000
117.460007,65.326042,-141.983200,-0.001479,0.003647,0.092628,290.584747,14.803092,0.926284,-141.983200,294.500488,0.000000
117.810005,65.310036,-142.027679,-0.001475,0.003647,0.092628,290.513550,14.799465,0.926284,-142.027679,294.500488,0.000000
118.160004,65.289177,-142.027679,-0.001483,0.003647,0.092628,290.420776,14.794740,0.926284,-142.027679,294.500488,0.000000
118.510002,65.254921,-142.072159,-0.001475,0.003647,0.092628,290.268372,14.786977,0.926284,-142.072159,294.500488,0.000000
118.860008,65.230339,-142.072159,-0.001479,0.003647,0.092628,290.159027,14.781406,0.926284,-142.072159,294.500488,0.000000
119.210007,65.202415,-142.116638,-0.001475,0.003647,0.092628,290.034821,14.775078,0.926284,-142.116638,294.500488,0.000000
119.560005,65.168907,-142.072159,-0.001470,0.003647,0.092628,289.885773,14.767486,0.926284,-142.072159,294.500488,0.000000
119.910004,65.171135,-142.116638,-0.001479,0.003648,0.092663,289.895691,14.767991,0.926631,-142.116638,294.500488,0.000000
120.260002,65.190498,-142.161118,-0.001453,0.003648,0.092663,289.981812,14.772378,0.926631,-142.161118,294.500488,0.000000
120.610008,65.177101,-142.161118,-0.001466,0.003648,0.092663,289.922211,14.769342,0.926631,-142.161118,294.500488,0.000000
120.960007,65.152885,-142.205597,-0.001479,0.003648,0.092663,289.814514,14.763855,0.926631,-142.205597,294.500488,0.000000
121.310005,65.112297,-142.205597,-0.001462,0.003648,0.092663,289.633972,14.754658,0.926631,-142.205597,294.500488,0.000000
121.660004,65.076546,-142.250076,-0.001470,0.003649,0.092680,289.474945,14.746555,0.926804,-142.250076,294.500488,0.000000
122.010002,65.063515,-142.294556,-0.001470,0.003649,0.092680,289.416962,14.743604,0.926804,-142.294556,294.500488,0.000000
122.360008,65.054207,-142.294556,-0.001466,0.003649,0.092680,289.375549,14.741493,0.926804,-142.294556,294.500488,0.000000
122.710007,65.039314,-142.339050,-0.001479,0.003649,0.092680,289.309326,14.738119,0.926804,-142.339050,294.500488,0.000000
123.060005,65.028145,-142.339050,-0.001475,0.003649,0.092680,289.259644,14.735588,0.926804,-142.339050,294.500488,0.000000
123.410004,64.991646,-142.383530,-0.001466,0.003649,0.092680,289.097290,14.727318,0.926804,-142.383530,294.500488,0.000000
123.760002,64.989052,-142.339050,-0.001470,0.003649,0.092680,289.085754,14.726729,0.926804,-142.339050,294.500488,0.000000
124.110008,65.593407,-142.339050,-0.001475,0.003658,0.092906,291.774048,14.863678,0.929059,-142.339050,294.500488,0.000000
124.460007,65.702141,-142.383530,-0.001462,0.003658,0.092906,292.257721,14.888318,0.929059,-142.383530,294.500488,0.000000
124.810005,65.759850,-142.472488,-0.001475,0.003658,0.092906,292.514435,14.901395,0.929059,-142.472488,1681.640991,0.000000
125.160004,65.677559,-142.472488,-0.001466,0.003654,0.092802,292.148376,14.882748,0.928018,-142.472488,0.092602,0.000000
125.510010,65.646660,-142.516968,-0.001462,0.003636,0.092351,292.010925,14.875746,0.923509,-142.516968,0.092013,0.000000
125.860008,65.468285,-142.516968,-0.001462,0.003618,0.091900,291.217468,14.835325,0.918999,-142.516968,0.091432,0.000000
126.210007,65.421364,-142.561447,-0.001457,0.003595,0.091319,291.008759,14.824693,0.913189,-142.561447,0.090851,0.000000
126.560005,65.397545,-142.516968,-0.001453,0.003577,0.090851,290.902802,14.819296,0.908506,-142.516968,0.090270,0.000000
126.910004,65.361046,-142.516968,-0.001457,0.003554,0.090278,290.740448,14.811025,0.902782,-142.516968,0.089680,0.000000
127.260010,65.338707,-142.561447,-0.001449,0.003532,0.089706,290.641083,14.805963,0.897058,-142.561447,0.089099,0.000000
127.610008,65.232201,-142.605927,-0.001457,0.003505,0.089021,290.167328,14.781828,0.890207,-142.605927,0.088518,0.000000
127.960007,65.214699,-142.694885,-0.001462,0.003486,0.088544,290.089478,14.777862,0.885438,-142.694885,0.087937,0.000000
128.310013,65.151772,-142.739365,-0.001466,0.003464,0.087989,289.809540,14.763602,0.879887,-142.739365,0.087347,0.000000
128.660004,65.066872,-142.694885,-0.001466,0.003442,0.087416,289.431915,14.744364,0.874164,-142.694885,0.086766,0.000000
129.010010,64.875099,-142.739365,-0.001462,0.003424,0.086965,288.578857,14.700908,0.869654,-142.739365,0.086185,0.000000
129.360001,64.084175,-142.739365,-0.001449,0.003397,0.086280,285.060638,14.521682,0.862803,-142.739365,0.085604,0.000000
129.710007,63.298851,-142.783859,-0.001444,0.003374,0.085708,281.567352,14.343724,0.857079,-142.783859,0.085014,0.000000
130.060013,62.226044,-142.783859,-0.001444,0.003352,0.085153,276.795258,14.100623,0.851529,-142.783859,0.084433,0.000000
130.410004,61.131264,-142.828339,-0.001457,0.003334,0.084685,271.925446,13.852543,0.846846,-142.828339,0.083852,0.000000
130.760010,59.966858,-142.872818,-0.001453,0.003316,0.084225,266.745911,13.588684,0.842250,-142.872818,0.083262,0.000000
131.110001,58.802818,-142.872818,-0.001449,0.003300,0.083826,261.567993,13.324909,0.838260,-142.872818,0.082681,0.000000
131.460007,56.955482,-142.917297,-0.001453,0.003280,0.083306,253.350632,12.906297,0.833057,-142.917297,0.082100,0.000000
131.810013,54.444946,-142.872818,-0.001453,0.003249,0.082525,242.183212,12.337401,0.825252,-142.872818,0.081519,0.000000
132.160004,52.424454,-142.917297,-0.001453,0.003228,0.081996,233.195618,11.879551,0.819962,-142.917297,0.080929,0.000000
132.510010,50.294853,-142.872818,-0.001453,0.003207,0.081450,223.722687,11.396976,0.814498,-142.872818,0.080348,0.000000
132.860001,47.853584,-143.006256,-0.001457,0.003181,0.080808,212.863373,10.843777,0.808081,-143.006256,0.079767,0.000000
133.210007,45.033234,-142.961777,-0.001453,0.003155,0.080140,200.317825,10.204677,0.801403,-142.961777,0.079186,0.000000
133.560013,42.284378,-143.050735,-0.001457,0.003130,0.079490,188.090302,9.581777,0.794899,-143.050735,0.078597,0.000000
133.910004,40.255325,-143.050735,-0.001466,0.003111,0.079030,179.064636,9.121987,0.790303,-143.050735,0.078016,0.000000
134.260010,37.656906,-143.095215,-0.001470,0.003087,0.078397,167.506287,8.533176,0.783972,-143.095215,0.077435,0.000000
134.610001,36.064644,-143.095215,-0.001466,0.003073,0.078042,160.423553,8.172365,0.780416,-143.095215,0.076845,0.000000
134.960007,34.153999,-143.139694,-0.001479,0.003054,0.077582,151.924576,7.739407,0.775820,-143.139694,0.076264,0.000000
135.310013,31.362694,-143.095215,-0.001479,0.003026,0.076854,139.508224,7.106888,0.768535,-143.095215,0.075683,0.000000
135.660004,28.556122,-143.139694,-0.001475,0.002998,0.076151,127.023972,6.470910,0.761511,-143.139694,0.075102,0.000000
136.010010,26.615692,-143.228668,-0.001492,0.002980,0.075691,118.392509,6.031202,0.756915,-143.228668,0.074512,0.000000
136.360001,24.550888,-143.228668,-0.001496,0.002963,0.075258,109.207802,5.563311,0.752579,-143.228668,0.073931,0.000000
136.710007,21.452003,-143.273148,-0.001496,0.002934,0.074521,95.423279,4.861094,0.745207,-143.273148,0.073350,0.000000
137.060013,18.545265,-143.184189,-0.001492,0.002903,0.073749,82.493462,4.202417,0.737489,-143.184189,0.072769,0.000000
137.410004,15.326103,-143.273148,-0.001509,0.002876,0.073055,68.173912,3.472945,0.730551,-143.273148,0.072179,0.000000
137.760010,13.552864,-143.273148,-0.001513,0.002859,0.072613,60.286152,3.071123,0.726128,-143.273148,0.071598,0.000000
138.110001,10.934341,-143.317627,-0.001526,0.002835,0.072006,48.638378,2.477757,0.720058,-143.317627,0.071017,0.000000
138.460007,8.971939,-143.406586,-0.001531,0.002815,0.071511,39.909180,2.033070,0.715115,-143.406586,0.070436,0.000000
138.810013,6.729515,-143.362106,-0.001539,0.002793,0.070939,29.934378,1.524930,0.709391,-143.362106,0.069846,0.000000
139.160004,4.576454,-143.362106,-0.001531,0.002772,0.070401,20.357084,1.037039,0.704014,-143.362106,0.069265,0.000000
139.510010,2.067406,-143.406586,-0.001526,0.002745,0.069734,9.196280,0.468481,0.697336,-143.406586,0.068684,0.000000
139.860001,0.498978,-143.451065,-0.001539,0.002728,0.069283,2.219563,0.113070,0.692827,-143.451065,0.068095,0.000000
140.210007,-2.025711,-143.495544,-0.001556,0.002698,0.068537,-9.010813,-0.459033,0.685369,-143.495544,0.067514,0.000000
140.560013,-0.400673,-143.451065,-0.001582,0.002677,0.067991,-1.782282,-0.090794,0.679905,-143.451065,0.066932,0.000000
140.910004,-0.155281,-143.495544,-0.001617,0.002653,0.067383,-0.690725,-0.035187,0.673835,-143.495544,0.066351,0.000000
141.260010,-0.071129,-143.584503,-0.001638,0.002632,0.066846,-0.316397,-0.016118,0.668458,-143.584503,0.065762,0.000000
141.610001,-0.050644,-143.584503,-0.001669,0.002608,0.066239,-0.225275,-0.011476,0.662387,-143.584503,0.065181,0.000000
141.960007,0.021225,-143.628998,-0.001690,0.002585,0.065649,0.094413,0.004810,0.656490,-143.628998,0.064600,0.000000
142.310013,-0.000374,-143.628998,-0.001729,0.002560,0.065025,-0.001663,-0.000085,0.650246,-143.628998,0.064019,0.000000
142.660004,0.036865,-143.628998,-0.001729,0.002544,0.064626,0.163985,0.008354,0.646257,-143.628998,0.063429,0.000000
143.010010,0.029785,-143.584503,-0.001785,0.002520,0.064010,0.132491,0.006749,0.640099,-143.584503,0.062848,0.000000
143.360001,-0.073730,-143.628998,-0.001798,0.002492,0.063290,-0.327969,-0.016708,0.632901,-143.628998,0.062267,0.000000
143.710007,-0.052505,-143.673477,-0.001819,0.002473,0.062804,-0.233556,-0.011898,0.628045,-143.673477,0.061677,0.000000
144.060013,-0.052132,-143.717957,-0.001845,0.002443,0.062050,-0.231893,-0.011813,0.620500,-143.717957,0.061096,0.000000
144.410004,-0.033890,-143.717957,-0.001876,0.002428,0.061677,-0.150749,-0.007680,0.616771,-143.717957,0.060515,0.000000
144.760010,-0.074478,-143.762436,-0.001876,0.002400,0.060966,-0.331295,-0.016877,0.609660,-143.762436,0.059934,0.000000
145.000000,-0.040962,-143.762436,-0.001901,0.002396,0.060853,-0.182209,-0.009282,0.608532,-143.762436,0.060680,0.000000