File: Data/compression 33/AutoNoHeating-10-33-reverse-1-1_11152024_172934.csv
Time (sec),S:Load (lbs),S:HL1 (DIM),S:LVDT (in),S:Position (in),Ch:Position (mm),Ch:Load (N),Ch:Stress (MPa),Ch:Strain (mm/mm),Ch:HL1 (DIM),Set Point (),Cycles ()
0.110000,-0.093468,-637.234131,-0.007502,-0.007388,-0.187668,-0.415765,-0.021180,-1.876677,-637.234131,-0.187442,0.000000
0.490000,-0.013031,-637.234131,-0.007515,-0.007320,-0.185925,-0.057965,-0.002953,-1.859245,-637.234131,-0.185291,0.000000
0.870000,-0.015640,-637.278564,-0.007377,-0.007095,-0.180218,-0.069571,-0.003544,-1.802182,-637.278564,-0.178961,0.000000
1.250000,-0.003349,-637.323059,-0.007110,-0.006848,-0.173939,-0.014898,-0.000759,-1.739395,-637.323059,-0.172630,0.000000
1.630000,-0.018623,-637.323059,-0.006842,-0.006595,-0.167513,-0.082841,-0.004220,-1.675133,-637.323059,-0.166299,0.000000
2.010000,-0.025322,-637.323059,-0.006605,-0.006347,-0.161217,-0.112638,-0.005738,-1.612173,-637.323059,-0.159968,0.000000
2.390000,-0.026436,-637.323059,-0.006355,-0.006099,-0.154913,-0.117593,-0.005990,-1.549125,-637.323059,-0.153638,0.000000
2.770000,-0.021973,-637.323059,-0.006105,-0.005850,-0.148590,-0.097739,-0.004979,-1.485905,-637.323059,-0.147307,0.000000
3.150000,-0.017876,-637.412048,-0.005842,-0.005606,-0.142381,-0.079515,-0.004051,-1.423811,-637.412048,-0.140976,0.000000
3.530000,-0.007446,-637.367554,-0.005583,-0.005352,-0.135929,-0.033123,-0.001687,-1.359290,-637.367554,-0.134645,0.000000
3.910000,-0.016754,-637.412048,-0.005342,-0.005112,-0.129850,-0.074526,-0.003797,-1.298497,-637.412048,-0.128315,0.000000
4.290000,0.058464,-637.367554,-0.005195,-0.000003,-0.000078,0.260061,0.013248,-0.000781,-637.367554,0.000147,0.000000
4.670000,0.166824,-637.367554,-0.005200,-0.000003,-0.000078,0.742072,0.037803,-0.000781,-637.367554,0.000278,0.000000
5.050000,0.119530,-637.412048,-0.005191,-0.000003,-0.000069,0.531695,0.027086,-0.000694,-637.412048,0.000911,0.000000
5.430000,0.145599,-637.412048,-0.005182,0.000016,0.000408,0.647658,0.032993,0.004076,-637.412048,0.001544,0.000000
5.810000,0.261406,-637.412048,-0.005157,0.000050,0.001266,1.162792,0.059235,0.012661,-637.412048,0.002177,0.000000
6.190000,0.273689,-637.456482,-0.005139,0.000068,0.001734,1.217431,0.062019,0.017345,-637.456482,0.002810,0.000000
6.570000,0.348167,-637.456482,-0.005113,0.000093,0.002368,1.548726,0.078896,0.023675,-637.456482,0.003443,0.000000
6.950000,0.372742,-637.545471,-0.005066,0.000118,0.002992,1.658038,0.084464,0.029919,-637.545471,0.004076,0.000000
7.330000,0.493393,-637.500977,-0.005053,0.000143,0.003642,2.194721,0.111804,0.036423,-637.500977,0.004709,0.000000
7.710001,0.649788,-637.456482,-0.005027,0.000170,0.004327,2.890401,0.147244,0.043275,-637.456482,0.005342,0.000000
8.090000,0.671387,-637.500977,-0.005027,0.000190,0.004822,2.986477,0.152138,0.048218,-637.500977,0.005975,0.000000
8.470000,0.832993,-637.500977,-0.004984,0.000220,0.005585,3.705336,0.188759,0.055849,-637.500977,0.006608,0.000000
8.850000,0.944710,-637.545471,-0.004945,0.000247,0.006261,4.202279,0.214074,0.062614,-637.545471,0.007241,0.000000
9.230000,1.089561,-637.589966,-0.004915,0.000270,0.006851,4.846611,0.246898,0.068511,-637.589966,0.007874,0.000000
9.610001,1.302933,-637.545471,-0.004911,0.000296,0.007510,5.795734,0.295249,0.075102,-637.545471,0.008507,0.000000
9.990001,1.336075,-637.545471,-0.004876,0.000312,0.007918,5.943158,0.302759,0.079178,-637.545471,0.009141,0.000000
10.370001,1.559494,-637.545471,-0.004846,0.000341,0.008672,6.936976,0.353386,0.086723,-637.545471,0.009774,0.000000
10.750001,1.632477,-637.634460,-0.004820,0.000367,0.009331,7.261620,0.369925,0.093314,-637.634460,0.010407,0.000000
11.130000,1.715889,-637.634460,-0.004799,0.000386,0.009808,7.632655,0.388826,0.098083,-637.634460,0.011040,0.000000
11.510000,1.969101,-637.634460,-0.004777,0.000411,0.010450,8.758999,0.446205,0.104501,-637.634460,0.011673,0.000000
11.890000,2.113586,-637.634460,-0.004738,0.000443,0.011257,9.401702,0.478946,0.112566,-637.634460,0.012306,0.000000
12.270000,2.309456,-637.589966,-0.004695,0.000472,0.011985,10.272973,0.523330,0.119851,-637.589966,0.012939,0.000000
12.650001,2.394730,-637.634460,-0.004669,0.000494,0.012557,10.652289,0.542654,0.125574,-637.634460,0.013572,0.000000
13.030001,2.531761,-637.767883,-0.004635,0.000518,0.013164,11.261836,0.573705,0.131645,-637.767883,0.014205,0.000000
13.410001,2.760025,-637.723389,-0.004618,0.000543,0.013789,12.277205,0.625431,0.137889,-637.723389,0.014838,0.000000
13.790001,2.841949,-637.634460,-0.004596,0.000565,0.014353,12.641623,0.643995,0.143526,-637.634460,0.015471,0.000000
14.170001,2.967064,-637.678894,-0.004575,0.000592,0.015029,13.198159,0.672346,0.150290,-637.678894,0.016104,0.000000
14.550001,3.058670,-637.723389,-0.004527,0.000614,0.015601,13.605644,0.693105,0.156014,-637.723389,0.016737,0.000000
14.930000,3.119362,-637.812378,-0.004510,0.000636,0.016148,13.875614,0.706858,0.161477,-637.812378,0.017379,0.000000
15.310000,3.348000,-637.767883,-0.004484,0.000666,0.016928,14.892646,0.758668,0.169282,-637.767883,0.018012,0.000000
15.690001,3.347626,-637.767883,-0.004432,0.000688,0.017475,14.890983,0.758583,0.174746,-637.767883,0.018645,0.000000
16.070002,3.517059,-637.723389,-0.004402,0.000718,0.018246,15.644661,0.796977,0.182464,-637.723389,0.019278,0.000000
16.450001,3.423592,-637.767883,-0.004372,0.000735,0.018680,15.228896,0.775797,0.186800,-637.767883,0.019912,0.000000
16.830000,3.582596,-637.856812,-0.004342,0.000762,0.019365,15.936182,0.811828,0.193651,-637.856812,0.020545,0.000000
17.210001,3.663025,-637.812378,-0.004307,0.000783,0.019877,16.293949,0.830053,0.198768,-637.812378,0.021178,0.000000
17.590000,3.802666,-637.812378,-0.004264,0.000815,0.020709,16.915102,0.861696,0.207093,-637.812378,0.021811,0.000000
17.970001,3.798569,-637.812378,-0.004255,0.000834,0.021195,16.896877,0.860768,0.211950,-637.812378,0.022444,0.000000
18.350000,3.984009,-637.901306,-0.004191,0.000873,0.022175,17.721756,0.902789,0.221750,-637.901306,0.023077,0.000000
18.730001,3.952736,-637.901306,-0.004156,0.000893,0.022678,17.582647,0.895703,0.226780,-637.901306,0.023710,0.000000
19.110001,4.022736,-637.945801,-0.004148,0.000917,0.023302,17.894022,0.911565,0.233024,-637.945801,0.024343,0.000000
19.490002,4.089020,-637.901306,-0.004109,0.000942,0.023927,18.188868,0.926585,0.239268,-637.901306,0.024976,0.000000
19.870001,4.154182,-637.856812,-0.004083,0.000964,0.024490,18.478725,0.941351,0.244904,-637.856812,0.025609,0.000000
20.250002,4.185097,-637.990295,-0.004044,0.000986,0.025054,18.616240,0.948356,0.250541,-637.990295,0.026242,0.000000
20.630001,4.232384,-637.901306,-0.004001,0.001010,0.025644,18.826584,0.959072,0.256439,-637.901306,0.026875,0.000000
21.010000,4.361229,-638.034790,-0.003980,0.001042,0.026468,19.399715,0.988269,0.264677,-638.034790,0.027508,0.000000
21.390001,4.433464,-637.990295,-0.003945,0.001066,0.027083,19.721033,1.004637,0.270835,-637.990295,0.028141,0.000000
21.770000,4.444267,-637.945801,-0.003919,0.001088,0.027630,19.769089,1.007085,0.276298,-637.945801,0.028775,0.000000
22.150002,4.496765,-637.990295,-0.003867,0.001110,0.028194,20.002611,1.018982,0.281935,-637.990295,0.029408,0.000000
22.530001,4.600288,-638.079224,-0.003842,0.001138,0.028896,20.463104,1.042440,0.288960,-638.079224,0.030041,0.000000
22.910002,4.729500,-638.034790,-0.003803,0.001164,0.029564,21.037867,1.071720,0.295637,-638.034790,0.030674,0.000000
23.290001,4.818497,-638.079224,-0.003773,0.001194,0.030336,21.433744,1.091887,0.303356,-638.079224,0.031307,0.000000
23.670002,4.648323,-637.990295,-0.003742,0.001208,0.030682,20.676773,1.053325,0.306824,-637.990295,0.031940,0.000000
24.050001,4.913826,-638.079224,-0.003708,0.001244,0.031593,21.857790,1.113489,0.315930,-638.079224,0.032573,0.000000
24.430000,4.833023,-638.079224,-0.003669,0.001265,0.032139,21.498360,1.095179,0.321394,-638.079224,0.033206,0.000000
24.810001,4.911964,-638.123718,-0.003660,0.001286,0.032668,21.849508,1.113067,0.326684,-638.123718,0.033839,0.000000
25.190001,5.178581,-638.079224,-0.003617,0.001318,0.033475,23.035480,1.173483,0.334749,-638.079224,0.034472,0.000000
25.570002,5.149162,-638.034790,-0.003583,0.001340,0.034039,22.904617,1.166817,0.340386,-638.034790,0.035105,0.000000
25.950001,5.053467,-638.079224,-0.003553,0.001360,0.034550,22.478943,1.145132,0.345503,-638.079224,0.035747,0.000000
26.330002,5.184166,-638.123718,-0.003514,0.001390,0.035305,23.060322,1.174749,0.353048,-638.123718,0.036380,0.000000
26.710001,5.274658,-638.123718,-0.003475,0.001414,0.035920,23.462851,1.195255,0.359205,-638.123718,0.037013,0.000000
27.090002,5.504784,-638.212708,-0.003458,0.001444,0.036675,24.486500,1.247402,0.366750,-638.212708,0.037646,0.000000
27.470001,5.329391,-638.168213,-0.003436,0.001462,0.037143,23.706318,1.207657,0.371433,-638.168213,0.038279,0.000000
27.850000,5.420250,-638.212708,-0.003376,0.001492,0.037889,24.110476,1.228246,0.378891,-638.212708,0.038912,0.000000
28.230001,5.451904,-638.212708,-0.003341,0.001516,0.038505,24.251282,1.235419,0.385048,-638.212708,0.039545,0.000000
28.610001,5.463821,-638.301636,-0.003320,0.001537,0.039034,24.304291,1.238120,0.390338,-638.301636,0.040179,0.000000
28.990002,5.665276,-638.301636,-0.003281,0.001569,0.039849,25.200405,1.283770,0.398490,-638.301636,0.040812,0.000000
29.370001,5.557655,-638.257141,-0.003260,0.001589,0.040369,24.721685,1.259383,0.403694,-638.257141,0.041445,0.000000
29.750002,5.650749,-638.257141,-0.003229,0.001615,0.041028,25.135788,1.280478,0.410285,-638.257141,0.042078,0.000000
30.130001,5.664154,-638.257141,-0.003191,0.001640,0.041644,25.195415,1.283516,0.416442,-638.257141,0.042711,0.000000
30.510002,5.781456,-638.301636,-0.003152,0.001667,0.042338,25.717201,1.310097,0.423380,-638.301636,0.043344,0.000000
30.890001,5.877899,-638.346130,-0.003122,0.001691,0.042954,26.146202,1.331951,0.429537,-638.346130,0.043977,0.000000
31.270002,5.797096,-638.301636,-0.003100,0.001710,0.043439,25.786772,1.313641,0.434393,-638.301636,0.044610,0.000000
31.650002,5.659317,-638.301636,-0.003070,0.001728,0.043882,25.173899,1.282420,0.438816,-638.301636,0.045243,0.000000
32.030003,5.912903,-638.301636,-0.003035,0.001760,0.044714,26.301905,1.339883,0.447142,-638.301636,0.045876,0.000000
32.410000,5.890556,-638.346130,-0.002984,0.001781,0.045243,26.202503,1.334819,0.452432,-638.346130,0.046509,0.000000
32.790001,6.186592,-638.435120,-0.002949,0.001815,0.046102,27.519337,1.401902,0.461017,-638.435120,0.047142,0.000000
33.170002,6.165741,-638.390625,-0.002923,0.001841,0.046752,27.426586,1.397177,0.467521,-638.390625,0.047775,0.000000
33.550003,6.291977,-638.390625,-0.002889,0.001869,0.047472,27.988111,1.425782,0.474719,-638.390625,0.048409,0.000000
33.930000,6.105789,-638.390625,-0.002854,0.001891,0.048036,27.159906,1.383592,0.480356,-638.390625,0.049042,0.000000
34.310001,6.148239,-638.435120,-0.002815,0.001911,0.048547,27.348734,1.393211,0.485473,-638.435120,0.049675,0.000000
34.690002,6.268143,-638.390625,-0.002785,0.001935,0.049146,27.882092,1.420381,0.491457,-638.390625,0.050308,0.000000
35.070004,6.302773,-638.435120,-0.002768,0.001963,0.049865,28.036133,1.428229,0.498655,-638.435120,0.050941,0.000000
35.450001,6.403313,-638.479553,-0.002738,0.001988,0.050507,28.483356,1.451011,0.505072,-638.479553,0.051574,0.000000
35.830002,6.223091,-638.435120,-0.002699,0.002007,0.050976,27.681692,1.410173,0.509755,-638.435120,0.052207,0.000000
36.210003,6.368317,-638.390625,-0.002643,0.002031,0.051591,28.327686,1.443081,0.515913,-638.390625,0.052840,0.000000
36.590000,6.373154,-638.568542,-0.002626,0.002056,0.052224,28.349203,1.444177,0.522243,-638.568542,0.053473,0.000000
36.970001,6.637169,-638.524048,-0.002591,0.002091,0.053100,29.523602,1.504004,0.531002,-638.524048,0.054115,0.000000
37.350002,6.415977,-638.435120,-0.002552,0.002110,0.053595,28.539694,1.453881,0.535945,-638.435120,0.054748,0.000000
37.730003,6.677010,-638.524048,-0.002501,0.002140,0.054349,29.700823,1.513032,0.543490,-638.524048,0.055381,0.000000
38.110001,6.568649,-638.524048,-0.002466,0.002161,0.054887,29.218811,1.488477,0.548867,-638.524048,0.056014,0.000000
38.490002,6.590622,-638.613037,-0.002440,0.002181,0.055390,29.316551,1.493456,0.553897,-638.613037,0.056647,0.000000
38.870003,6.758186,-638.613037,-0.002419,0.002212,0.056196,30.061914,1.531427,0.561962,-638.613037,0.057280,0.000000
39.250000,6.678497,-638.524048,-0.002363,0.002233,0.056717,29.707439,1.513369,0.567166,-638.524048,0.057913,0.000000
39.630001,6.919426,-638.568542,-0.002333,0.002268,0.057618,30.779144,1.567964,0.576185,-638.568542,0.058546,0.000000
40.010002,6.815163,-638.568542,-0.002294,0.002291,0.058200,30.315357,1.544338,0.581995,-638.568542,0.059179,0.000000
40.390003,6.832664,-638.613037,-0.002251,0.002316,0.058824,30.393209,1.548304,0.588239,-638.613037,0.059813,0.000000
40.770000,6.840851,-638.657471,-0.002233,0.002338,0.059396,30.429625,1.550159,0.593963,-638.657471,0.060446,0.000000
41.150002,6.890007,-638.613037,-0.002195,0.002361,0.059977,30.648281,1.561298,0.599773,-638.613037,0.061079,0.000000
41.530003,6.879951,-638.613037,-0.002156,0.002385,0.060567,30.603552,1.559019,0.605670,-638.613037,0.061712,0.000000
41.910004,6.898201,-638.568542,-0.002126,0.002411,0.061235,30.684731,1.563155,0.612348,-638.568542,0.062345,0.000000
42.290001,7.096298,-638.613037,-0.002091,0.002441,0.061989,31.565910,1.608044,0.619893,-638.613037,0.062978,0.000000
42.670002,7.065392,-638.746460,-0.002044,0.002463,0.062570,31.428431,1.601041,0.625703,-638.746460,0.063611,0.000000
43.050003,7.009537,-638.701965,-0.002031,0.002486,0.063151,31.179977,1.588384,0.631514,-638.701965,0.064244,0.000000
43.430000,7.090340,-638.613037,-0.002005,0.002509,0.063732,31.539406,1.606694,0.637324,-638.613037,0.064877,0.000000
43.810001,7.059067,-638.701965,-0.001957,0.002533,0.064339,31.400297,1.599607,0.643395,-638.701965,0.065510,0.000000
44.190002,7.238174,-638.701965,-0.001927,0.002562,0.065085,32.197006,1.640194,0.650853,-638.701965,0.066143,0.000000
44.570004,7.362923,-638.746460,-0.001897,0.002592,0.065831,32.751915,1.668462,0.658311,-638.746460,0.066776,0.000000
44.950001,6.999855,-638.746460,-0.001858,0.002606,0.066204,31.136909,1.586190,0.662040,-638.746460,0.067409,0.000000
45.330002,7.408722,-638.790955,-0.001841,0.002640,0.067063,32.955643,1.678840,0.670626,-638.790955,0.068043,0.000000
45.710003,7.164444,-638.701965,-0.001785,0.002661,0.067583,31.869038,1.623486,0.675829,-638.701965,0.068676,0.000000
46.090004,7.188652,-638.835449,-0.001759,0.002682,0.068112,31.976721,1.628972,0.681119,-638.835449,0.069309,0.000000
46.470001,7.536446,-638.835449,-0.001720,0.002713,0.068901,33.523785,1.707783,0.689011,-638.835449,0.069942,0.000000
46.850002,7.168167,-638.790955,-0.001690,0.002726,0.069231,31.885599,1.624330,0.692306,-638.790955,0.070575,0.000000
47.230003,7.590439,-638.835449,-0.001664,0.002763,0.070185,33.763958,1.720018,0.701846,-638.835449,0.071208,0.000000
47.610001,7.349144,-638.790955,-0.001617,0.002784,0.070714,32.690624,1.665340,0.707136,-638.790955,0.071841,0.000000
47.990002,7.633263,-638.879883,-0.001578,0.002813,0.071442,33.954449,1.729722,0.714421,-638.879883,0.072483,0.000000
48.370003,7.883865,-638.835449,-0.001561,0.002839,0.072101,35.069183,1.786509,0.721011,-638.835449,0.073116,0.000000
48.750004,7.685768,-638.879883,-0.001500,0.002861,0.072665,34.188004,1.741620,0.726648,-638.879883,0.073749,0.000000
49.130001,7.912910,-638.879883,-0.001487,0.002889,0.073376,35.198383,1.793091,0.733760,-638.879883,0.074382,0.000000
49.510002,7.869720,-638.835449,-0.001440,0.002914,0.074018,35.006264,1.783304,0.740177,-638.835449,0.075015,0.000000
49.890003,7.875679,-638.835449,-0.001418,0.002934,0.074521,35.032768,1.784654,0.745207,-638.835449,0.075648,0.000000
50.270004,8.080856,-638.924377,-0.001393,0.002961,0.075214,35.945446,1.831148,0.752145,-638.924377,0.076281,0.000000
50.650002,8.119949,-638.924377,-0.001375,0.002983,0.075770,36.119339,1.840007,0.757695,-638.924377,0.076914,0.000000
51.030003,8.283798,-638.924377,-0.001350,0.003010,0.076455,36.848175,1.877136,0.764546,-638.924377,0.077547,0.000000
51.410004,8.478920,-638.924377,-0.001289,0.003038,0.077166,37.716118,1.921351,0.771657,-638.924377,0.078180,0.000000
51.790001,8.679626,-638.879883,-0.001250,0.003064,0.077825,38.608906,1.966831,0.778248,-638.879883,0.078813,0.000000
52.170002,8.742935,-638.968872,-0.001229,0.003087,0.078397,38.890518,1.981177,0.783972,-638.968872,0.079447,0.000000
52.550003,8.736977,-638.968872,-0.001212,0.003107,0.078926,38.864014,1.979827,0.789262,-638.968872,0.080080,0.000000
52.930004,8.722076,-639.013367,-0.001194,0.003128,0.079464,38.797733,1.976451,0.794639,-639.013367,0.080713,0.000000
53.310001,9.267609,-638.968872,-0.001155,0.003158,0.080218,41.224380,2.100070,0.802184,-638.968872,0.081346,0.000000
53.690002,9.328674,-638.968872,-0.001121,0.003180,0.080765,41.496017,2.113908,0.807647,-638.968872,0.081979,0.000000
54.070004,9.862282,-639.013367,-0.001087,0.003209,0.081502,43.869621,2.234825,0.815019,-639.013367,0.082612,0.000000
54.450001,9.724136,-639.013367,-0.001052,0.003230,0.082031,43.255119,2.203521,0.820309,-639.013367,0.083245,0.000000
54.830002,10.321793,-639.013367,-0.001039,0.003266,0.082959,45.913628,2.338952,0.829588,-639.013367,0.083878,0.000000
55.210003,10.074905,-638.968872,-0.001005,0.003283,0.083384,44.815418,2.283006,0.833837,-638.968872,0.084511,0.000000
55.590004,10.389191,-639.057800,-0.000983,0.003309,0.084060,46.213428,2.354224,0.840602,-639.057800,0.085144,0.000000
55.970001,10.780556,-639.057800,-0.000940,0.003335,0.084702,47.954308,2.442909,0.847019,-639.057800,0.085777,0.000000
56.350002,11.002113,-639.102295,-0.000923,0.003361,0.085361,48.939846,2.493115,0.853610,-639.102295,0.086410,0.000000
56.730003,10.880722,-639.146790,-0.000888,0.003376,0.085760,48.399868,2.465607,0.857599,-639.146790,0.087043,0.000000
57.110004,11.216606,-639.102295,-0.000871,0.003404,0.086454,49.893955,2.541719,0.864537,-639.102295,0.087677,0.000000
57.490002,11.609825,-639.146790,-0.000841,0.003428,0.087078,51.643082,2.630824,0.870781,-639.146790,0.088310,0.000000
57.870003,12.319939,-639.146790,-0.000806,0.003459,0.087867,54.801823,2.791738,0.878673,-639.146790,0.088943,0.000000
58.250004,12.557884,-639.146790,-0.000780,0.003486,0.088535,55.860260,2.845657,0.885351,-639.146790,0.089576,0.000000
58.630001,12.380638,-639.146790,-0.000755,0.003502,0.088960,55.071831,2.805493,0.889600,-639.146790,0.090217,0.000000
59.010002,12.937332,-639.146790,-0.000733,0.003530,0.089671,57.548126,2.931641,0.896711,-639.146790,0.090851,0.000000
59.390003,13.256462,-639.102295,-0.000694,0.003557,0.090356,58.967690,3.003957,0.903562,-639.102295,0.091484,0.000000
59.770004,13.613937,-639.146790,-0.000677,0.003579,0.090903,60.557819,3.084962,0.909026,-639.146790,0.092117,0.000000
60.150002,14.466293,-639.191284,-0.000647,0.003610,0.091683,64.349289,3.278109,0.916831,-639.191284,0.092750,0.000000
60.530003,14.582474,-639.146790,-0.000625,0.003631,0.092238,64.866081,3.304436,0.922381,-639.146790,0.093383,0.000000
60.910004,15.351425,-639.191284,-0.000608,0.003661,0.093001,68.286552,3.478683,0.930013,-639.191284,0.094016,0.000000
61.290005,15.781891,-639.191284,-0.000565,0.003690,0.093721,70.201355,3.576228,0.937211,-639.191284,0.094649,0.000000
61.670002,15.990044,-639.235718,-0.000548,0.003714,0.094337,71.127266,3.623396,0.943368,-639.235718,0.095282,0.000000
62.050003,16.535568,-639.280212,-0.000513,0.003737,0.094909,73.553879,3.747013,0.949092,-639.280212,0.095915,0.000000
62.430004,16.485672,-639.280212,-0.000500,0.003751,0.095273,73.331932,3.735707,0.952734,-639.280212,0.096548,0.000000
62.810001,17.584175,-639.280212,-0.000483,0.003782,0.096071,78.218315,3.984631,0.960713,-639.280212,0.097181,0.000000
63.190002,17.514908,-639.191284,-0.000466,0.003802,0.096574,77.910202,3.968935,0.965743,-639.191284,0.097814,0.000000
63.570004,18.944077,-639.280212,-0.000431,0.003834,0.097389,84.267464,4.292789,0.973894,-639.280212,0.098447,0.000000
63.950005,19.609131,-639.280212,-0.000410,0.003861,0.098075,87.225769,4.443492,0.980746,-639.280212,0.099081,0.000000
64.330002,20.033638,-639.369202,-0.000401,0.003884,0.098664,89.114075,4.539688,0.986643,-639.369202,0.099714,0.000000
64.710007,20.738541,-639.280212,-0.000371,0.003907,0.099245,92.249634,4.699421,0.992453,-639.280212,0.100347,0.000000
65.090004,21.459076,-639.280212,-0.000354,0.003932,0.099861,95.454735,4.862696,0.998610,-639.280212,0.100980,0.000000
65.470001,22.061577,-639.369202,-0.000319,0.003956,0.100494,98.134796,4.999225,1.004941,-639.369202,0.101613,0.000000
65.850006,23.356316,-639.324707,-0.000319,0.003987,0.101275,103.894081,5.292617,1.012746,-639.324707,0.102246,0.000000
66.230003,23.613251,-639.369202,-0.000285,0.004005,0.101726,105.036987,5.350839,1.017256,-639.369202,0.102879,0.000000
66.610001,23.817314,-639.369202,-0.000280,0.004020,0.102116,105.944702,5.397080,1.021158,-639.369202,0.103512,0.000000
66.990005,25.695930,-639.413696,-0.000237,0.004059,0.103104,114.301208,5.822781,1.031045,-639.413696,0.104145,0.000000
67.370003,25.537300,-639.369202,-0.000237,0.004070,0.103382,113.595581,5.786835,1.033820,-639.369202,0.104778,0.000000
67.750000,27.476250,-639.458130,-0.000224,0.004105,0.104258,122.220459,6.226207,1.042579,-639.458130,0.105411,0.000000
68.130005,28.539368,-639.413696,-0.000203,0.004134,0.104995,126.949448,6.467113,1.049950,-639.413696,0.106044,0.000000
68.510002,29.330292,-639.413696,-0.000177,0.004153,0.105489,130.467651,6.646339,1.054893,-639.413696,0.106677,0.000000
68.890007,30.391922,-639.413696,-0.000151,0.004178,0.106131,135.190018,6.886908,1.061311,-639.413696,0.107310,0.000000
69.270004,31.481857,-639.458130,-0.000142,0.004207,0.106860,140.038300,7.133891,1.068596,-639.458130,0.107944,0.000000
69.650002,31.437172,-639.458130,-0.000138,0.004225,0.107310,139.839523,7.123765,1.073105,-639.458130,0.108585,0.000000
70.030006,34.207626,-639.547119,-0.000121,0.004259,0.108169,152.163116,7.751559,1.081691,-639.547119,0.109218,0.000000
70.410004,35.131104,-639.502625,-0.000099,0.004281,0.108733,156.270950,7.960822,1.087328,-639.502625,0.109851,0.000000
70.790001,36.472763,-639.458130,-0.000069,0.004309,0.109444,162.238953,8.264846,1.094439,-639.458130,0.110485,0.000000
71.170006,37.522110,-639.458130,-0.000065,0.004333,0.110051,166.906677,8.502631,1.100509,-639.458130,0.111118,0.000000
71.550003,39.054054,-639.547119,-0.000052,0.004359,0.110727,173.721115,8.849775,1.107274,-639.547119,0.111751,0.000000
71.930000,40.156647,-639.502625,-0.000043,0.004381,0.111265,178.625687,9.099626,1.112651,-639.502625,0.112384,0.000000
72.310005,41.696777,-639.547119,-0.000034,0.004407,0.111941,185.476532,9.448625,1.119415,-639.547119,0.113017,0.000000
72.690002,43.494217,-639.547119,-0.000013,0.004436,0.112679,193.471939,9.855930,1.126786,-639.547119,0.113650,0.000000
73.070000,44.507446,-639.502625,-0.000004,0.004457,0.113199,197.979004,10.085531,1.131990,-639.502625,0.114283,0.000000
73.450005,46.078857,-639.547119,0.000022,0.004482,0.113849,204.968994,10.441619,1.138494,-639.547119,0.114916,0.000000
73.830002,47.360939,-639.636047,0.000017,0.004503,0.114387,210.671982,10.732142,1.143871,-639.636047,0.115549,0.000000
74.210007,48.358894,-639.591614,0.000030,0.004522,0.114855,215.111099,10.958282,1.148554,-639.591614,0.116182,0.000000
74.590004,50.767029,-639.591614,0.000052,0.004556,0.115731,225.823029,11.503974,1.157313,-639.591614,0.116815,0.000000
74.970001,51.217598,-639.547119,0.000047,0.004573,0.116148,227.827255,11.606074,1.161475,-639.547119,0.117448,0.000000
75.350006,53.434700,-639.591614,0.000073,0.004602,0.116885,237.689423,12.108476,1.168847,-639.591614,0.118081,0.000000
75.730003,55.989922,-639.636047,0.000069,0.004628,0.117552,249.055603,12.687497,1.175524,-639.636047,0.118715,0.000000
76.110001,57.423927,-639.636047,0.000086,0.004655,0.118229,255.434387,13.012448,1.182289,-639.636047,0.119348,0.000000
76.490005,59.671944,-639.636047,0.000108,0.004682,0.118914,265.434052,13.521856,1.189140,-639.636047,0.119981,0.000000
76.870003,61.009132,-639.591614,0.000099,0.004704,0.119478,271.382172,13.824867,1.194777,-639.591614,0.120614,0.000000
77.250000,62.045441,-639.680542,0.000099,0.004720,0.119885,275.991913,14.059697,1.198853,-639.680542,0.121247,0.000000
77.630005,65.232574,-639.725037,0.000112,0.004754,0.120753,290.168976,14.781913,1.207525,-639.725037,0.121880,0.000000
78.010002,65.918488,-639.725037,0.000129,0.004761,0.120926,293.220062,14.937343,1.209260,-639.725037,0.021215,0.000000
78.390007,65.176727,-639.680542,0.000160,0.004761,0.120935,289.920563,14.769257,1.209346,-639.680542,294.500458,0.000000
78.770004,65.350616,-639.725037,0.000134,0.004772,0.121221,290.694061,14.808661,1.212208,-639.725037,294.500458,0.000000
79.150002,65.005798,-639.725037,0.000160,0.004772,0.121221,289.160248,14.730524,1.212208,-639.725037,294.500458,0.000000
79.530006,64.889999,-639.814026,0.000151,0.004776,0.121299,288.645142,14.704284,1.212989,-639.814026,294.500458,0.000000
79.910004,65.545380,-639.769531,0.000160,0.004785,0.121533,291.560425,14.852796,1.215330,-639.769531,294.500458,0.000000
80.290001,65.304443,-639.725037,0.000160,0.004785,0.121533,290.488678,14.798199,1.215330,-639.725037,294.500458,0.000000
80.670006,65.086243,-639.769531,0.000164,0.004785,0.121533,289.518066,14.748754,1.215330,-639.769531,294.500458,0.000000
81.050003,64.882919,-639.858459,0.000164,0.004785,0.121542,288.613647,14.702680,1.215417,-639.858459,294.500458,0.000000
81.430000,64.711258,-639.858459,0.000155,0.004785,0.121542,287.850037,14.663780,1.215417,-639.858459,294.500458,0.000000
81.810005,64.518372,-639.814026,0.000160,0.004785,0.121542,286.992065,14.620072,1.215417,-639.814026,294.500458,0.000000
82.190002,66.368683,-639.814026,0.000177,0.004783,0.121481,295.222656,15.039358,1.214810,-639.814026,294.500458,0.000000
82.570007,66.160156,-639.814026,0.000172,0.004783,0.121481,294.295074,14.992105,1.214810,-639.814026,294.500458,0.000000
82.950005,65.977692,-639.858459,0.000172,0.004783,0.121481,293.483429,14.950758,1.214810,-639.858459,294.500458,0.000000
83.330002,65.837677,-639.947449,0.000177,0.004783,0.121481,292.860626,14.919031,1.214810,-639.947449,294.500458,0.000000
83.710007,65.666397,-639.902954,0.000172,0.004783,0.121481,292.098724,14.880218,1.214810,-639.902954,294.500458,0.000000
84.090004,65.567719,-639.858459,0.000181,0.004783,0.121481,291.659790,14.857858,1.214810,-639.858459,294.500458,0.000000
84.470001,65.417648,-639.947449,0.000181,0.004783,0.121490,290.992218,14.823851,1.214896,-639.947449,294.500458,0.000000
84.850006,65.311157,-639.947449,0.000181,0.004783,0.121490,290.518524,14.799720,1.214896,-639.947449,294.500458,0.000000
85.230003,65.211731,-639.991943,0.000181,0.004790,0.121672,290.076263,14.777190,1.216718,-639.991943,294.500458,0.000000
85.610001,65.099640,-639.902954,0.000172,0.004790,0.121672,289.577667,14.751789,1.216718,-639.902954,294.500458,0.000000
85.990005,65.076553,-639.902954,0.000172,0.004800,0.121932,289.474976,14.746557,1.219319,-639.902954,294.500458,0.000000
86.370003,65.051605,-639.947449,0.000177,0.004800,0.121932,289.363983,14.740905,1.219319,-639.947449,294.500458,0.000000
86.750008,65.018845,-639.991943,0.000194,0.004801,0.121941,289.218262,14.733480,1.219406,-639.991943,294.500458,0.000000
87.130005,65.492126,-640.080872,0.000181,0.004808,0.122123,291.323517,14.840728,1.221227,-640.080872,294.500458,0.000000
87.510002,65.476852,-639.947449,0.000168,0.004808,0.122123,291.255585,14.837267,1.221227,-639.947449,294.500458,0.000000
87.890007,65.408340,-639.991943,0.000177,0.004808,0.122123,290.950836,14.821742,1.221227,-639.991943,294.500458,0.000000
88.270004,65.345032,-640.080872,0.000190,0.004808,0.122123,290.669220,14.807396,1.221227,-640.080872,294.500458,0.000000
88.650002,65.313751,-640.036377,0.000194,0.004808,0.122131,290.530090,14.800307,1.221314,-640.036377,294.500458,0.000000
89.030006,65.278015,-640.080872,0.000177,0.004808,0.122131,290.371124,14.792210,1.221314,-640.080872,294.500458,0.000000
89.410004,65.231094,-640.036377,0.000181,0.004808,0.122131,290.162415,14.781577,1.221314,-640.036377,294.500458,0.000000
89.790001,65.175980,-640.036377,0.000172,0.004808,0.122131,289.917236,14.769088,1.221314,-640.036377,294.500458,0.000000
90.170006,65.097778,-640.125366,0.000194,0.004809,0.122140,289.569366,14.751368,1.221401,-640.125366,294.500458,0.000000
90.550003,65.069107,-640.169861,0.000181,0.004809,0.122140,289.441833,14.744871,1.221401,-640.169861,294.500458,0.000000
90.930008,65.031494,-640.125366,0.000177,0.004809,0.122140,289.274536,14.736347,1.221401,-640.125366,294.500458,0.000000
91.310005,64.985321,-640.080872,0.000190,0.004809,0.122140,289.069153,14.725884,1.221401,-640.080872,294.500458,0.000000
91.690002,64.938400,-640.080872,0.000185,0.004809,0.122140,288.860443,14.715252,1.221401,-640.080872,294.500458,0.000000
92.070007,65.559525,-640.169861,0.000181,0.004817,0.122340,291.623322,14.856000,1.223395,-640.169861,294.500458,0.000000
92.450005,65.558411,-640.169861,0.000198,0.004817,0.122340,291.618378,14.855748,1.223395,-640.169861,294.500458,0.000000
92.830002,65.545380,-640.169861,0.000190,0.004817,0.122340,291.560425,14.852796,1.223395,-640.169861,294.500458,0.000000
93.210007,65.514099,-640.125366,0.000190,0.004817,0.122340,291.421265,14.845707,1.223395,-640.125366,294.500458,0.000000
93.590004,65.497330,-640.125366,0.000194,0.004817,0.122340,291.346680,14.841908,1.223395,-640.125366,294.500458,0.000000
93.970001,65.464569,-640.214355,0.000194,0.004817,0.122340,291.200958,14.834484,1.223395,-640.214355,294.500458,0.000000
94.350006,65.393814,-640.214355,0.000190,0.004817,0.122340,290.886200,14.818450,1.223395,-640.214355,294.500458,0.000000
94.730003,65.366638,-640.214355,0.000181,0.004817,0.122340,290.765320,14.812292,1.223395,-640.214355,294.500458,0.000000
95.110008,65.326416,-640.214355,0.000185,0.004817,0.122340,290.586426,14.803178,1.223395,-640.214355,294.500458,0.000000
95.490005,65.293274,-640.169861,0.000190,0.004817,0.122340,290.438995,14.795667,1.223395,-640.169861,294.500458,0.000000
95.870003,65.272430,-640.214355,0.000190,0.004817,0.122348,290.346283,14.790944,1.223482,-640.214355,294.500458,0.000000
96.250008,65.248962,-640.303284,0.000194,0.004817,0.122348,290.241882,14.785626,1.223482,-640.303284,294.500458,0.000000
96.630005,65.211349,-640.303284,0.000190,0.004817,0.122348,290.074585,14.777102,1.223482,-640.303284,294.500458,0.000000
97.010002,65.168900,-640.258789,0.000194,0.004817,0.122348,289.885742,14.767485,1.223482,-640.258789,294.500458,0.000000
97.390007,65.123108,-640.303284,0.000203,0.004817,0.122348,289.682037,14.757108,1.223482,-640.303284,294.500458,0.000000
97.770004,65.076553,-640.258789,0.000194,0.004817,0.122348,289.474976,14.746557,1.223482,-640.258789,294.500458,0.000000
98.150002,65.058304,-640.347778,0.000194,0.004817,0.122348,289.393799,14.742422,1.223482,-640.347778,294.500458,0.000000
98.530006,65.028519,-640.347778,0.000181,0.004817,0.122348,289.261292,14.735673,1.223482,-640.347778,294.500458,0.000000
98.910004,64.992401,-640.303284,0.000177,0.004817,0.122348,289.100647,14.727489,1.223482,-640.303284,294.500458,0.000000
99.290001,64.982346,-640.303284,0.000207,0.004817,0.122348,289.055908,14.725209,1.223482,-640.303284,294.500458,0.000000
99.670006,64.946228,-640.347778,0.000194,0.004817,0.122348,288.895264,14.717026,1.223482,-640.347778,294.500458,0.000000
100.050003,64.898193,-640.347778,0.000203,0.004817,0.122348,288.681580,14.706141,1.223482,-640.347778,294.500458,0.000000
100.430008,64.842712,-640.347778,0.000185,0.004817,0.122348,288.434784,14.693568,1.223482,-640.347778,294.500458,0.000000
100.810005,64.830048,-640.303284,0.000194,0.004817,0.122348,288.378448,14.690699,1.223482,-640.303284,294.500458,0.000000
101.190002,64.786102,-640.436707,0.000194,0.004817,0.122348,288.182983,14.680740,1.223482,-640.436707,294.500458,0.000000
101.570007,64.758926,-640.392273,0.000198,0.004817,0.122348,288.062103,14.674582,1.223482,-640.392273,294.500458,0.000000
101.950005,64.749985,-640.436707,0.000211,0.004817,0.122348,288.022308,14.672557,1.223482,-640.436707,294.500458,0.000000
102.330002,64.716843,-640.392273,0.000190,0.004817,0.122348,287.874908,14.665046,1.223482,-640.392273,294.500458,0.000000
102.710007,64.677750,-640.481201,0.000198,0.004817,0.122348,287.700989,14.656187,1.223482,-640.481201,294.500458,0.000000
103.090004,64.678116,-640.436707,0.000194,0.004817,0.122348,287.702637,14.656271,1.223482,-640.436707,294.500458,0.000000
103.470001,65.605698,-640.436707,0.000211,0.004829,0.122669,291.828705,14.866464,1.226691,-640.436707,294.500458,0.000000
103.850006,65.779602,-640.481201,0.000203,0.004829,0.122669,292.602295,14.905870,1.226691,-640.481201,294.500458,0.000000
104.230003,65.774002,-640.481201,0.000198,0.004829,0.122669,292.577362,14.904602,1.226691,-640.481201,294.500458,0.000000
104.610008,65.792252,-640.436707,0.000185,0.004829,0.122669,292.658539,14.908737,1.226691,-640.436707,294.500458,0.000000
104.990005,65.795975,-640.436707,0.000216,0.004829,0.122669,292.675110,14.909581,1.226691,-640.436707,294.500458,0.000000
105.370003,65.788910,-640.525696,0.000194,0.004829,0.122669,292.643677,14.907980,1.226691,-640.525696,294.500458,0.000000
105.750008,65.755386,-640.525696,0.000194,0.004829,0.122669,292.494568,14.900384,1.226691,-640.525696,294.500458,0.000000
106.130005,65.785187,-640.570190,0.000181,0.004829,0.122669,292.627136,14.907136,1.226691,-640.570190,294.500458,0.000000
106.510002,65.777725,-640.525696,0.000194,0.004829,0.122669,292.593933,14.905445,1.226691,-640.525696,294.500458,0.000000
106.890007,65.683151,-640.525696,0.000207,0.004829,0.122669,292.173248,14.884014,1.226691,-640.525696,294.500458,0.000000
107.270004,65.676819,-640.570190,0.000190,0.004829,0.122669,292.145081,14.882580,1.226691,-640.570190,294.500458,0.000000
107.650002,65.650375,-640.614685,0.000207,0.004829,0.122669,292.027466,14.876588,1.226691,-640.614685,294.500458,0.000000
108.030006,65.612778,-640.614685,0.000207,0.004829,0.122669,291.860199,14.868069,1.226691,-640.614685,294.500458,0.000000
108.410004,65.595276,-640.659119,0.000190,0.004829,0.122669,291.782349,14.864102,1.226691,-640.659119,294.500458,0.000000
108.790009,65.584473,-640.570190,0.000203,0.004829,0.122669,291.734314,14.861653,1.226691,-640.570190,294.500458,0.000000
109.170006,65.592285,-640.614685,0.000198,0.004829,0.122669,291.769043,14.863424,1.226691,-640.614685,294.500458,0.000000
109.550003,65.575912,-640.614685,0.000203,0.004829,0.122669,291.696228,14.859715,1.226691,-640.614685,294.500458,0.000000
109.930008,65.550583,-640.614685,0.000190,0.004829,0.122669,291.583557,14.853974,1.226691,-640.614685,294.500458,0.000000
110.310005,65.548355,-640.659119,0.000194,0.004829,0.122669,291.573639,14.853469,1.226691,-640.659119,294.500458,0.000000
110.690002,65.515213,-640.614685,0.000207,0.004829,0.122669,291.426208,14.845960,1.226691,-640.614685,294.500458,0.000000
111.070007,65.511856,-640.703613,0.000211,0.004829,0.122669,291.411285,14.845199,1.226691,-640.703613,294.500458,0.000000
111.450005,65.499573,-640.703613,0.000194,0.004829,0.122669,291.356659,14.842416,1.226691,-640.703613,294.500458,0.000000
111.830002,65.477234,-640.792603,0.000207,0.004829,0.122669,291.257294,14.837354,1.226691,-640.792603,294.500458,0.000000
112.210007,65.415421,-640.659119,0.000203,0.004829,0.122669,290.982330,14.823346,1.226691,-640.659119,294.500458,0.000000
112.590004,65.408707,-640.748108,0.000216,0.004829,0.122669,290.952454,14.821825,1.226691,-640.748108,294.500458,0.000000
112.970009,65.394928,-640.748108,0.000216,0.004829,0.122669,290.891174,14.818703,1.226691,-640.748108,294.500458,0.000000
113.350006,65.358063,-640.703613,0.000211,0.004829,0.122669,290.727173,14.810349,1.226691,-640.703613,294.500458,0.000000
113.730003,65.338333,-640.792603,0.000211,0.004829,0.122669,290.639435,14.805878,1.226691,-640.792603,294.500458,0.000000
114.110008,65.347275,-640.748108,0.000216,0.004829,0.122669,290.679199,14.807904,1.226691,-640.748108,294.500458,0.000000
114.490005,65.322327,-640.703613,0.000207,0.004829,0.122669,290.568207,14.802251,1.226691,-640.703613,294.500458,0.000000
114.870003,65.315994,-640.792603,0.000220,0.004829,0.122669,290.540039,14.800816,1.226691,-640.792603,294.500458,0.000000
115.250008,65.293274,-640.792603,0.000220,0.004829,0.122669,290.438995,14.795667,1.226691,-640.792603,294.500458,0.000000
115.630005,65.285828,-640.837036,0.000198,0.004829,0.122669,290.405853,14.793981,1.226691,-640.837036,294.500458,0.000000
116.010002,65.272430,-640.837036,0.000207,0.004830,0.122678,290.346283,14.790944,1.226777,-640.837036,294.500458,0.000000
116.390007,65.271301,-640.792603,0.000203,0.004830,0.122678,290.341248,14.790689,1.226777,-640.792603,294.500458,0.000000
116.770004,65.245239,-640.792603,0.000211,0.004830,0.122678,290.225311,14.784782,1.226777,-640.792603,294.500458,0.000000
117.150009,65.240402,-640.881531,0.000216,0.004830,0.122678,290.203796,14.783687,1.226777,-640.881531,294.500458,0.000000
117.530006,65.225876,-640.926025,0.000211,0.004830,0.122678,290.139191,14.780395,1.226777,-640.926025,294.500458,0.000000
117.910004,65.209869,-640.837036,0.000190,0.004830,0.122678,290.067993,14.776768,1.226777,-640.837036,294.500458,0.000000
118.290009,65.180450,-640.881531,0.000203,0.004830,0.122678,289.937134,14.770102,1.226777,-640.881531,294.500458,0.000000
118.670006,65.159592,-640.926025,0.000211,0.004830,0.122678,289.844330,14.765374,1.226777,-640.926025,294.500458,0.000000
119.050003,65.127563,-640.926025,0.000207,0.004830,0.122678,289.701874,14.758117,1.226777,-640.926025,294.500458,0.000000
119.430008,65.128311,-640.970520,0.000203,0.004830,0.122678,289.705200,14.758286,1.226777,-640.970520,294.500458,0.000000
119.810005,65.105606,-640.926025,0.000207,0.004830,0.122678,289.604187,14.753141,1.226777,-640.926025,294.500458,0.000000
120.190002,65.088837,-640.926025,0.000211,0.004830,0.122678,289.529602,14.749341,1.226777,-640.926025,294.500458,0.000000
120.570007,65.055710,-640.926025,0.000220,0.004830,0.122678,289.382263,14.741835,1.226777,-640.926025,294.500458,0.000000
120.950005,65.057190,-640.970520,0.000220,0.004830,0.122678,289.388824,14.742170,1.226777,-640.970520,294.500458,0.000000
121.330009,65.047134,-641.059448,0.000216,0.004830,0.122678,289.344116,14.739891,1.226777,-641.059448,294.500458,0.000000
121.710007,65.028152,-641.059448,0.000216,0.004830,0.122678,289.259674,14.735590,1.226777,-641.059448,294.500458,0.000000
122.090004,65.030746,-640.970520,0.000216,0.004830,0.122678,289.271210,14.736178,1.226777,-640.970520,294.500458,0.000000
122.470009,65.013245,-640.970520,0.000207,0.004830,0.122678,289.193359,14.732212,1.226777,-640.970520,294.500458,0.000000
122.850006,64.996872,-641.103943,0.000211,0.004830,0.122678,289.120514,14.728501,1.226777,-641.103943,294.500458,0.000000
123.230003,64.978256,-641.148437,0.000220,0.004830,0.122678,289.037720,14.724283,1.226777,-641.148437,294.500458,0.000000
123.610008,64.968567,-641.148437,0.000198,0.004830,0.122678,288.994629,14.722088,1.226777,-641.148437,294.500458,0.000000
123.990005,64.973404,-641.059448,0.000211,0.004830,0.122678,289.016144,14.723184,1.226777,-641.059448,294.500458,0.000000
124.370003,64.955902,-641.103943,0.000207,0.004830,0.122678,288.938293,14.719218,1.226777,-641.103943,294.500458,0.000000
124.750008,64.923889,-641.103943,0.000207,0.004830,0.122678,288.795868,14.711963,1.226777,-641.103943,294.500458,0.000000
125.130005,64.918671,-641.103943,0.000198,0.004830,0.122678,288.772675,14.710781,1.226777,-641.103943,294.500458,0.000000
125.510010,64.900803,-641.103943,0.000216,0.004830,0.122678,288.693176,14.706732,1.226777,-641.103943,294.500458,0.000000
125.890007,64.879196,-641.148437,0.000207,0.004830,0.122678,288.597076,14.701837,1.226777,-641.148437,294.500458,0.000000
126.270004,64.864670,-641.148437,0.000216,0.004830,0.122678,288.532471,14.698545,1.226777,-641.148437,294.500458,0.000000
126.650009,64.844574,-641.192932,0.000207,0.004830,0.122678,288.443085,14.693991,1.226777,-641.192932,294.500458,0.000000
127.030006,64.831528,-641.192932,0.000203,0.004830,0.122678,288.385040,14.691034,1.226777,-641.192932,294.500458,0.000000
127.410004,64.828552,-641.192932,0.000190,0.004830,0.122678,288.371796,14.690360,1.226777,-641.192932,294.500458,0.000000
127.790009,64.810303,-641.148437,0.000216,0.004830,0.122678,288.290619,14.686224,1.226777,-641.148437,294.500458,0.000000
128.170013,64.790939,-641.192932,0.000211,0.004830,0.122678,288.204498,14.681837,1.226777,-641.192932,294.500458,0.000000
128.550003,64.768234,-641.237366,0.000207,0.004830,0.122678,288.103485,14.676692,1.226777,-641.237366,294.500458,0.000000
128.930008,64.761902,-641.281860,0.000198,0.004830,0.122678,288.075317,14.675257,1.226777,-641.281860,294.500458,0.000000
129.310013,64.744766,-641.281860,0.000211,0.004830,0.122678,287.999115,14.671373,1.226777,-641.281860,294.500458,0.000000
129.690002,64.740677,-641.281860,0.000211,0.004830,0.122678,287.980927,14.670446,1.226777,-641.281860,294.500458,0.000000
130.070007,64.733978,-641.237366,0.000216,0.004830,0.122678,287.951111,14.668929,1.226777,-641.237366,294.500458,0.000000
130.450012,64.713867,-641.237366,0.000207,0.004830,0.122678,287.861664,14.664372,1.226777,-641.237366,294.500458,0.000000
130.830002,64.707535,-641.326355,0.000207,0.004830,0.122678,287.833496,14.662937,1.226777,-641.326355,294.500458,0.000000
131.210007,64.689285,-641.326355,0.000203,0.004830,0.122678,287.752319,14.658802,1.226777,-641.326355,294.500458,0.000000
131.590012,64.678864,-641.237366,0.000207,0.004830,0.122678,287.705963,14.656440,1.226777,-641.237366,294.500458,0.000000
131.970001,64.660614,-641.237366,0.000211,0.004830,0.122678,287.624786,14.652305,1.226777,-641.237366,294.500458,0.000000
132.350006,64.653534,-641.370850,0.000216,0.004830,0.122678,287.593292,14.650701,1.226777,-641.370850,294.500458,0.000000
132.730011,64.631943,-641.370850,0.000216,0.004830,0.122686,287.497253,14.645808,1.226864,-641.370850,294.500458,0.000000
133.110001,64.627472,-641.370850,0.000216,0.004830,0.122686,287.477356,14.644794,1.226864,-641.370850,294.500458,0.000000
133.490005,64.606995,-641.370850,0.000203,0.004830,0.122686,287.386261,14.640154,1.226864,-641.370850,294.500458,0.000000
133.870010,64.598053,-641.415344,0.000190,0.004830,0.122686,287.346497,14.638127,1.226864,-641.415344,294.500458,0.000000
134.250000,64.567520,-641.370850,0.000211,0.004830,0.122686,287.210663,14.631209,1.226864,-641.370850,294.500458,0.000000
134.630005,64.554489,-641.415344,0.000224,0.004830,0.122686,287.152710,14.628257,1.226864,-641.415344,294.500458,0.000000
135.010010,64.541824,-641.459778,0.000198,0.004830,0.122686,287.096375,14.625386,1.226864,-641.459778,294.500458,0.000000
135.389999,64.532898,-641.370850,0.000211,0.004830,0.122686,287.056671,14.623363,1.226864,-641.370850,294.500458,0.000000
135.770004,64.513901,-641.415344,0.000220,0.004830,0.122686,286.972168,14.619060,1.226864,-641.415344,294.500458,0.000000
136.150009,64.503098,-641.504272,0.000220,0.004830,0.122686,286.924103,14.616611,1.226864,-641.504272,294.500458,0.000000
136.530014,64.515396,-641.504272,0.000211,0.004830,0.122686,286.978821,14.619398,1.226864,-641.504272,294.500458,0.000000
136.910004,64.501617,-641.548767,0.000211,0.004830,0.122686,286.917511,14.616276,1.226864,-641.548767,294.500458,0.000000
137.290009,64.471451,-641.504272,0.000211,0.004830,0.122686,286.783325,14.609440,1.226864,-641.504272,294.500458,0.000000
137.670013,64.475174,-641.504272,0.000224,0.004830,0.122686,286.799896,14.610283,1.226864,-641.504272,294.500458,0.000000
138.050003,64.469955,-641.504272,0.000203,0.004830,0.122686,286.776672,14.609100,1.226864,-641.504272,294.500458,0.000000
138.430008,64.450974,-641.548767,0.000220,0.004830,0.122686,286.692261,14.604800,1.226864,-641.548767,1681.640747,0.000000
138.810013,64.453949,-641.548767,0.000220,0.004823,0.122496,286.705475,14.605474,1.224956,-641.548767,0.122478,0.000000
139.190002,64.317291,-641.593262,0.000203,0.004809,0.122140,286.097595,14.574507,1.221401,-641.593262,0.121845,0.000000
139.570007,64.240585,-641.548767,0.000220,0.004784,0.121507,285.756409,14.557124,1.215070,-641.548767,0.121212,0.000000
139.950012,64.346329,-641.593262,0.000224,0.004763,0.120978,286.226776,14.581086,1.209780,-641.593262,0.120579,0.000000
140.330002,64.290482,-641.637695,0.000220,0.004738,0.120336,285.978333,14.568432,1.203362,-641.637695,0.119946,0.000000
140.710007,64.212280,-641.593262,0.000207,0.004715,0.119764,285.630493,14.550711,1.197639,-641.593262,0.119313,0.000000
141.090012,64.207062,-641.548767,0.000203,0.004693,0.119209,285.607269,14.549528,1.192088,-641.548767,0.118680,0.000000
141.470001,64.204086,-641.593262,0.000220,0.004670,0.118610,285.594025,14.548854,1.186105,-641.593262,0.118047,0.000000
141.850006,64.201477,-641.593262,0.000220,0.004645,0.117995,285.582428,14.548263,1.179947,-641.593262,0.117414,0.000000
142.230011,64.171310,-641.637695,0.000207,0.004621,0.117370,285.448242,14.541428,1.173703,-641.637695,0.116781,0.000000
142.610001,64.025726,-641.637695,0.000203,0.004596,0.116737,284.800659,14.508437,1.167373,-641.637695,0.116148,0.000000
142.990005,63.614990,-641.682190,0.000220,0.004573,0.116156,282.973602,14.415362,1.161562,-641.682190,0.115514,0.000000
143.370010,62.977119,-641.682190,0.000211,0.004557,0.115740,280.136230,14.270820,1.157399,-641.682190,0.114881,0.000000
143.750000,61.687592,-641.726685,0.000216,0.004527,0.114994,274.400116,13.978608,1.149941,-641.726685,0.114248,0.000000
144.130005,60.511269,-641.726685,0.000229,0.004507,0.114465,269.167572,13.712049,1.144651,-641.726685,0.113615,0.000000
144.510010,59.116737,-641.682190,0.000220,0.004483,0.113858,262.964386,13.396045,1.138581,-641.682190,0.112982,0.000000
144.889999,57.389671,-641.682190,0.000224,0.004466,0.113424,255.282013,13.004685,1.134245,-641.682190,0.112349,0.000000
145.270004,54.972977,-641.726685,0.000224,0.004434,0.112635,244.532013,12.457054,1.126353,-641.726685,0.111716,0.000000
145.650009,53.197502,-641.815613,0.000224,0.004414,0.112124,236.634308,12.054727,1.121236,-641.815613,0.111083,0.000000
146.030014,50.121704,-641.815613,0.000224,0.004386,0.111404,222.952469,11.357740,1.114038,-641.815613,0.110450,0.000000
146.410004,47.906830,-641.771179,0.000207,0.004367,0.110918,213.100220,10.855844,1.109182,-641.771179,0.109817,0.000000
146.790009,44.699959,-641.815613,0.000229,0.004337,0.110164,198.835342,10.129155,1.101637,-641.815613,0.109184,0.000000
147.170013,42.008827,-641.726685,0.000224,0.004313,0.109557,186.864594,9.519337,1.095566,-641.726685,0.108542,0.000000
147.550003,39.551537,-641.815613,0.000211,0.004291,0.108984,175.934021,8.962506,1.089843,-641.815613,0.107909,0.000000
147.930008,36.374084,-641.771179,0.000233,0.004261,0.108238,161.800003,8.242485,1.082384,-641.771179,0.107276,0.000000
148.310013,34.297363,-641.815613,0.000229,0.004240,0.107701,152.562286,7.771894,1.077008,-641.815613,0.106643,0.000000
148.690002,31.213745,-641.815613,0.000220,0.004214,0.107024,138.845673,7.073135,1.070243,-641.815613,0.106010,0.000000
149.070007,28.153221,-641.815613,0.000224,0.004189,0.106400,125.231781,6.379611,1.063999,-641.815613,0.105377,0.000000
149.450012,25.876160,-641.815613,0.000220,0.004168,0.105871,115.102905,5.863621,1.058709,-641.815613,0.104744,0.000000
149.830002,22.493156,-641.904602,0.000216,0.004136,0.105064,100.054558,5.097022,1.050644,-641.904602,0.104110,0.000000
150.210007,20.111465,-641.860107,0.000207,0.004118,0.104587,89.460266,4.557323,1.045874,-641.860107,0.103477,0.000000
150.590012,17.205467,-641.815613,0.000233,0.004093,0.103954,76.533737,3.898815,1.039543,-641.815613,0.102844,0.000000
150.970001,14.304687,-641.860107,0.000220,0.004064,0.103226,63.630428,3.241488,1.032259,-641.860107,0.102211,0.000000
151.350006,12.383987,-641.904602,0.000224,0.004049,0.102844,55.086727,2.806252,1.028443,-641.904602,0.101578,0.000000
151.730011,8.372421,-641.904602,0.000216,0.004010,0.101856,37.242390,1.897218,1.018557,-641.904602,0.100945,0.000000
152.110001,6.115097,-641.949097,0.000216,0.003988,0.101301,27.201311,1.385701,1.013006,-641.949097,0.100312,0.000000
152.490005,3.307037,-641.904602,0.000224,0.003962,0.100642,14.710437,0.749385,1.006415,-641.904602,0.099679,0.000000
152.870010,1.044876,-641.904602,0.000224,0.003938,0.100017,4.647841,0.236772,1.000171,-641.904602,0.099046,0.000000
153.250000,-0.940987,-642.038025,0.000207,0.003914,0.099427,-4.185718,-0.213231,0.994274,-642.038025,0.098413,0.000000
153.630005,-0.153046,-641.993591,0.000164,0.003886,0.098708,-0.680781,-0.034681,0.987076,-641.993591,0.097780,0.000000
154.010010,-0.067772,-641.949097,0.000121,0.003866,0.098196,-0.301465,-0.015357,0.981960,-641.949097,0.097147,0.000000
154.390015,0.009308,-641.993591,0.000065,0.003836,0.097433,0.041403,0.002109,0.974328,-641.993591,0.096514,0.000000
154.770004,-0.008194,-642.038025,0.000026,0.003816,0.096938,-0.036449,-0.001857,0.969385,-642.038025,0.095880,0.000000
155.150009,0.011917,-642.082520,-0.000047,0.003787,0.096184,0.053010,0.002700,0.961840,-642.082520,0.095247,0.000000
155.530014,-0.012291,-642.038025,-0.000086,0.003762,0.095560,-0.054673,-0.002785,0.955596,-642.038025,0.094614,0.000000
155.910004,0.030159,-642.038025,-0.000168,0.003739,0.094970,0.134154,0.006834,0.949699,-642.038025,0.093981,0.000000
156.200012,0.151924,-642.038025,-0.000220,0.003730,0.094744,0.675792,0.034427,0.947444,-642.038025,0.094632,0.000000