File: Data/compression 33/AutoNoHeating-17-33-reverse-1-4_11152024_183506.csv
Time (sec),S:Load (lbs),S:HL1 (DIM),S:LVDT (in),S:Position (in),Ch:Position (mm),Ch:Load (N),Ch:Stress (MPa),Ch:Strain (mm/mm),Ch:HL1 (DIM),Set Point (),Cycles ()
0.210000,-0.164223,-146.609207,-0.012749,-0.007992,-0.203009,-0.730499,-0.037213,-2.030088,-146.609207,-0.202792,0.000000
0.560000,-0.040962,-146.564728,-0.012753,-0.007920,-0.201170,-0.182209,-0.009282,-2.011703,-146.564728,-0.200329,0.000000
0.910000,-0.064049,-146.564728,-0.012615,-0.007707,-0.195750,-0.284903,-0.014514,-1.957502,-146.564728,-0.194501,0.000000
1.260000,-0.094955,-146.653702,-0.012370,-0.007479,-0.189957,-0.422383,-0.021517,-1.899571,-146.653702,-0.188656,0.000000
1.610000,-0.153046,-146.653702,-0.012163,-0.007245,-0.184017,-0.680781,-0.034681,-1.840166,-146.653702,-0.182829,0.000000
1.960000,-0.090118,-146.698181,-0.011921,-0.007014,-0.178154,-0.400867,-0.020421,-1.781542,-146.698181,-0.177001,0.000000
2.310000,-0.047668,-146.698181,-0.011671,-0.006785,-0.172335,-0.212040,-0.010802,-1.723351,-146.698181,-0.171173,0.000000
2.660000,-0.041336,-146.742661,-0.011443,-0.006560,-0.166611,-0.183872,-0.009367,-1.666114,-146.742661,-0.165345,0.000000
3.010000,-0.059212,-146.742661,-0.011206,-0.006333,-0.160862,-0.263387,-0.013418,-1.608617,-146.742661,-0.159517,0.000000
3.360000,-0.090858,-146.831619,-0.010964,-0.006098,-0.154878,-0.404159,-0.020589,-1.548778,-146.831619,-0.153672,0.000000
3.710000,-0.094955,-146.831619,-0.010727,-0.005864,-0.148955,-0.422383,-0.021517,-1.489547,-146.831619,-0.147845,0.000000
4.060000,-0.090492,-146.876099,-0.010490,-0.005642,-0.143309,-0.402530,-0.020506,-1.433090,-146.876099,-0.142017,0.000000
4.410000,-0.048409,-146.831619,-0.010257,-0.005413,-0.137499,-0.215332,-0.010970,-1.374986,-146.831619,-0.136189,0.000000
4.760000,-0.051392,-146.831619,-0.010007,-0.005177,-0.131506,-0.228601,-0.011646,-1.315061,-146.831619,-0.130361,0.000000
5.110000,-0.069633,-146.876099,-0.009787,-0.004957,-0.125904,-0.309745,-0.015779,-1.259038,-146.876099,-0.124516,0.000000
5.460000,-0.071869,-146.920578,-0.009550,-0.004724,-0.119989,-0.319689,-0.016286,-1.199893,-146.920578,-0.118688,0.000000
5.810000,-0.093094,-147.009537,-0.009300,-0.004495,-0.114179,-0.414102,-0.021095,-1.141789,-147.009537,-0.112861,0.000000
6.160000,-0.052132,-147.009537,-0.009071,-0.004263,-0.108273,-0.231893,-0.011813,-1.082731,-147.009537,-0.107033,0.000000
6.510000,-0.069267,-147.009537,-0.008847,-0.004044,-0.102706,-0.308116,-0.015696,-1.027055,-147.009537,-0.101205,0.000000
6.860000,-0.067406,-147.054031,-0.008606,-0.003801,-0.096557,-0.299836,-0.015274,-0.965569,-147.054031,-0.095360,0.000000
7.210001,-0.038361,-146.965057,-0.008373,-0.003577,-0.090859,-0.170636,-0.008693,-0.908592,-146.965057,-0.089532,0.000000
7.560000,-0.065910,-147.098511,-0.008127,-0.003348,-0.085049,-0.293184,-0.014935,-0.850488,-147.098511,-0.083705,0.000000
7.910000,-0.065170,-147.098511,-0.007881,-0.003118,-0.079195,-0.289892,-0.014768,-0.791950,-147.098511,-0.077877,0.000000
8.260000,-0.123634,-147.187469,-0.007653,-0.002892,-0.073463,-0.549953,-0.028016,-0.734627,-147.187469,-0.072049,0.000000
8.610001,-0.058464,-147.187469,-0.007420,-0.002666,-0.067713,-0.260061,-0.013248,-0.677130,-147.187469,-0.066221,0.000000
8.960000,-0.066658,-147.142990,-0.007166,-0.002423,-0.061538,-0.296510,-0.015105,-0.615383,-147.142990,-0.060376,0.000000
9.310000,-0.021225,-147.187469,-0.006959,-0.002203,-0.055953,-0.094413,-0.004810,-0.559534,-147.187469,-0.054548,0.000000
9.660001,-0.046181,-147.187469,-0.006700,-0.001970,-0.050039,-0.205422,-0.010465,-0.500389,-147.187469,-0.048721,0.000000
10.010000,-0.065910,-147.231949,-0.006476,-0.001739,-0.044168,-0.293184,-0.014935,-0.441678,-147.231949,-0.042893,0.000000
10.360001,-0.125862,-147.276428,-0.006256,-0.001517,-0.038522,-0.559863,-0.028521,-0.385222,-147.276428,-0.037065,0.000000
10.710000,-0.054741,-147.320908,-0.006006,-0.001287,-0.032694,-0.243500,-0.012404,-0.326944,-147.320908,-0.031220,0.000000
11.060000,-0.016014,-147.276428,-0.005764,-0.001046,-0.026563,-0.071234,-0.003629,-0.265631,-147.276428,-0.025392,0.000000
11.410001,-0.021599,-147.320908,-0.005523,-0.000822,-0.020874,-0.096076,-0.004894,-0.208741,-147.320908,-0.019565,0.000000
11.760000,-0.056976,-147.409866,-0.005299,-0.000600,-0.015246,-0.253443,-0.012911,-0.152458,-147.409866,-0.013737,0.000000
12.110001,-0.091232,-147.409866,-0.005040,-0.000363,-0.009219,-0.405822,-0.020674,-0.092186,-147.409866,-0.007909,0.000000
12.460001,-0.118790,-147.409866,-0.004807,-0.000130,-0.003313,-0.528403,-0.026918,-0.033128,-147.409866,-0.002081,0.000000
12.810000,0.140007,-147.409866,-0.004583,-0.000003,-0.000069,0.622782,0.031726,-0.000694,-147.409866,0.001362,0.000000
13.160001,0.111336,-147.498840,-0.004562,-0.000007,-0.000182,0.495246,0.025229,-0.001821,-147.498840,-0.000026,0.000000
13.510000,0.173149,-147.454346,-0.004575,-0.000007,-0.000182,0.770206,0.039236,-0.001821,-147.454346,0.000252,0.000000
13.860001,0.125114,-147.543320,-0.004575,-0.000007,-0.000182,0.556537,0.028351,-0.001821,-147.543320,0.000833,0.000000
14.210001,0.209641,-147.454346,-0.004553,0.000011,0.000278,0.932528,0.047505,0.002775,-147.454346,0.001422,0.000000
14.560000,0.284859,-147.587799,-0.004549,0.000030,0.000772,1.267115,0.064550,0.007718,-147.587799,0.002003,0.000000
14.910001,0.459877,-147.587799,-0.004527,0.000043,0.001084,2.045635,0.104210,0.010840,-147.587799,0.002584,0.000000
15.260001,0.997581,-147.632278,-0.004501,0.000082,0.002090,4.437464,0.226055,0.020900,-147.632278,0.003165,0.000000
15.610001,1.543854,-147.632278,-0.004480,0.000111,0.002818,6.867404,0.349842,0.028185,-147.632278,0.003755,0.000000
15.960001,1.839142,-147.676758,-0.004449,0.000125,0.003165,8.180911,0.416755,0.031654,-147.676758,0.004336,0.000000
16.310001,2.437546,-147.676758,-0.004428,0.000155,0.003946,10.842745,0.552356,0.039459,-147.676758,0.004917,0.000000
16.660000,2.811035,-147.676758,-0.004419,0.000171,0.004353,12.504108,0.636990,0.043535,-147.676758,0.005507,0.000000
17.010000,3.416512,-147.765717,-0.004389,0.000199,0.005065,15.197402,0.774193,0.050646,-147.765717,0.006088,0.000000
17.360001,3.988106,-147.721237,-0.004381,0.000218,0.005533,17.739981,0.903718,0.055329,-147.721237,0.006669,0.000000
17.710001,4.684067,-147.810196,-0.004346,0.000245,0.006227,20.835770,1.061425,0.062267,-147.810196,0.007250,0.000000
18.060001,5.296623,-147.810196,-0.004333,0.000271,0.006886,23.560556,1.200232,0.068858,-147.810196,0.007840,0.000000
18.410002,5.683517,-147.765717,-0.004316,0.000293,0.007441,25.281548,1.287903,0.074408,-147.765717,0.008421,0.000000
18.760000,6.253990,-147.854675,-0.004294,0.000314,0.007987,27.819138,1.417174,0.079871,-147.854675,0.009002,0.000000
19.110001,6.764145,-147.810196,-0.004277,0.000336,0.008525,30.088419,1.532777,0.085248,-147.810196,0.009583,0.000000
19.460001,7.257164,-147.854675,-0.004247,0.000356,0.009036,32.281479,1.644497,0.090365,-147.854675,0.010173,0.000000
19.810001,7.859291,-147.943649,-0.004238,0.000378,0.009609,34.959873,1.780941,0.096089,-147.943649,0.010754,0.000000
20.160002,8.160538,-147.943649,-0.004230,0.000396,0.010068,36.299885,1.849204,0.100685,-147.943649,0.011335,0.000000
20.510000,8.934326,-147.899155,-0.004204,0.000428,0.010875,39.741867,2.024547,0.108750,-147.899155,0.011916,0.000000
20.860001,9.336121,-147.988129,-0.004186,0.000448,0.011387,41.529140,2.115595,0.113867,-147.988129,0.012505,0.000000
21.210001,9.561775,-147.943649,-0.004165,0.000463,0.011768,42.532902,2.166729,0.117683,-147.943649,0.013086,0.000000
21.560001,10.355301,-148.032608,-0.004139,0.000495,0.012566,46.062679,2.346545,0.125661,-148.032608,0.013667,0.000000
21.910002,10.962273,-148.077087,-0.004139,0.000518,0.013164,48.762623,2.484087,0.131645,-148.077087,0.014257,0.000000
22.260000,11.110100,-148.077087,-0.004109,0.000538,0.013667,49.420193,2.517585,0.136675,-148.077087,0.014838,0.000000
22.610001,11.215111,-148.077087,-0.004092,0.000548,0.013928,49.887302,2.541380,0.139277,-148.077087,0.015419,0.000000
22.960001,12.456230,-148.077087,-0.004070,0.000589,0.014960,55.408077,2.822622,0.149597,-148.077087,0.016000,0.000000
23.310001,12.570915,-148.166046,-0.004044,0.000607,0.015419,55.918224,2.848610,0.154193,-148.166046,0.016590,0.000000
23.660002,12.683746,-148.166046,-0.004027,0.000623,0.015836,56.420120,2.874178,0.158356,-148.166046,0.017171,0.000000
24.010000,13.798256,-148.166046,-0.004014,0.000659,0.016737,61.377708,3.126729,0.167375,-148.166046,0.017752,0.000000
24.360001,13.931938,-148.166046,-0.003988,0.000680,0.017284,61.972355,3.157022,0.172838,-148.166046,0.018333,0.000000
24.710001,14.276382,-148.255005,-0.003962,0.000698,0.017735,63.504520,3.235075,0.177348,-148.255005,0.018923,0.000000
25.060001,14.607422,-148.210526,-0.003954,0.000716,0.018186,64.977058,3.310089,0.181857,-148.210526,0.019504,0.000000
25.410002,15.514153,-148.299484,-0.003941,0.000749,0.019036,69.010399,3.515557,0.190356,-148.299484,0.020085,0.000000
25.760002,15.620277,-148.299484,-0.003919,0.000764,0.019400,69.482468,3.539605,0.193998,-148.299484,0.020666,0.000000
26.110001,16.385132,-148.299484,-0.003872,0.000797,0.020241,72.884705,3.712924,0.202411,-148.299484,0.021256,0.000000
26.460001,16.663292,-148.299484,-0.003863,0.000818,0.020770,74.122025,3.775956,0.207701,-148.299484,0.021837,0.000000
26.810001,16.320335,-148.343979,-0.003850,0.000825,0.020952,72.596481,3.698241,0.209522,-148.343979,0.022418,0.000000
27.160002,17.548424,-148.388458,-0.003833,0.000863,0.021932,78.059288,3.976530,0.219321,-148.388458,0.023008,0.000000
27.510002,17.476181,-148.388458,-0.003807,0.000878,0.022314,77.737938,3.960159,0.223137,-148.388458,0.023589,0.000000
27.860001,17.820251,-148.388458,-0.003790,0.000900,0.022860,79.268440,4.038126,0.228601,-148.388458,0.024170,0.000000
28.210001,17.947975,-148.477417,-0.003781,0.000918,0.023320,79.836578,4.067070,0.233197,-148.477417,0.024751,0.000000
28.560001,19.137337,-148.477417,-0.003760,0.000954,0.024230,85.127129,4.336583,0.242303,-148.477417,0.025340,0.000000
28.910002,19.349960,-148.521896,-0.003742,0.000979,0.024855,86.072922,4.384764,0.248547,-148.521896,0.025921,0.000000
29.260002,19.615089,-148.477417,-0.003712,0.000999,0.025375,87.252274,4.444843,0.253750,-148.477417,0.026502,0.000000
29.610001,20.360580,-148.521896,-0.003682,0.001030,0.026156,90.568382,4.613774,0.261555,-148.521896,0.027083,0.000000
29.960001,20.397446,-148.521896,-0.003660,0.001052,0.026711,90.732368,4.622127,0.267105,-148.521896,0.027673,0.000000
30.310001,20.653633,-148.566376,-0.003652,0.001075,0.027300,91.871948,4.680180,0.273003,-148.566376,0.028254,0.000000
30.660002,20.930305,-148.566376,-0.003635,0.001096,0.027829,93.102646,4.742875,0.278293,-148.566376,0.028835,0.000000
31.010002,20.968292,-148.566376,-0.003626,0.001115,0.028315,93.271622,4.751483,0.283149,-148.566376,0.029425,0.000000
31.360001,21.239746,-148.610855,-0.003604,0.001133,0.028775,94.479111,4.812995,0.287745,-148.610855,0.030006,0.000000
31.710001,21.912254,-148.610855,-0.003579,0.001161,0.029486,97.470573,4.965388,0.294857,-148.610855,0.030587,0.000000
32.060001,22.199722,-148.655334,-0.003553,0.001186,0.030119,98.749298,5.030529,0.301188,-148.655334,0.031168,0.000000
32.410000,21.512329,-148.655334,-0.003557,0.001191,0.030249,95.691620,4.874763,0.302488,-148.655334,0.031758,0.000000
32.760002,22.676361,-148.699814,-0.003531,0.001227,0.031177,100.869492,5.138537,0.311768,-148.699814,0.032339,0.000000
33.110001,22.728119,-148.699814,-0.003510,0.001247,0.031671,101.099724,5.150265,0.316711,-148.699814,0.032920,0.000000
33.460003,23.621071,-148.744293,-0.003488,0.001281,0.032538,105.071770,5.352611,0.325383,-148.744293,0.033501,0.000000
33.810001,23.411423,-148.788788,-0.003462,0.001302,0.033067,104.139206,5.305104,0.330673,-148.788788,0.034091,0.000000
34.160000,22.905746,-148.833267,-0.003466,0.001312,0.033336,101.889847,5.190516,0.333361,-148.833267,0.034672,0.000000
34.510002,22.972023,-148.877747,-0.003441,0.001336,0.033926,102.184662,5.205534,0.339259,-148.877747,0.035253,0.000000
34.860001,24.324112,-148.833267,-0.003410,0.001368,0.034741,108.199051,5.511923,0.347411,-148.833267,0.035834,0.000000
35.210003,24.063454,-148.877747,-0.003393,0.001383,0.035140,107.039589,5.452857,0.351400,-148.877747,0.036423,0.000000
35.560001,24.353531,-148.922226,-0.003367,0.001408,0.035764,108.329918,5.518589,0.357644,-148.922226,0.037005,0.000000
35.910000,24.502853,-148.922226,-0.003372,0.001426,0.036224,108.994133,5.552426,0.362240,-148.922226,0.037586,0.000000
36.260002,24.306236,-148.966705,-0.003359,0.001441,0.036597,108.119537,5.507872,0.365969,-148.966705,0.038175,0.000000
36.610001,25.821045,-148.966705,-0.003324,0.001482,0.037655,114.857742,5.851132,0.376550,-148.966705,0.038756,0.000000
36.960003,26.104797,-149.011185,-0.003316,0.001510,0.038366,116.119942,5.915431,0.383661,-149.011185,0.039337,0.000000
37.310001,25.401756,-149.011185,-0.003285,0.001524,0.038713,112.992653,5.756120,0.387130,-149.011185,0.039918,0.000000
37.660004,25.979309,-149.055664,-0.003277,0.001556,0.039511,115.561737,5.886995,0.395108,-149.055664,0.040508,0.000000
38.010002,25.706734,-149.011185,-0.003247,0.001575,0.040005,114.349266,5.825229,0.400051,-149.011185,0.041089,0.000000
38.360001,26.182251,-149.055664,-0.003238,0.001598,0.040595,116.464470,5.932983,0.405948,-149.055664,0.041670,0.000000
38.710003,26.479774,-149.100143,-0.003208,0.001621,0.041176,117.787918,6.000402,0.411759,-149.100143,0.042251,0.000000
39.060001,26.721069,-149.100143,-0.003195,0.001643,0.041731,118.861252,6.055081,0.417309,-149.100143,0.042841,0.000000
39.410004,27.550346,-149.144623,-0.003182,0.001674,0.042511,122.550064,6.242998,0.425114,-149.144623,0.043422,0.000000
39.760002,27.346283,-149.189117,-0.003169,0.001693,0.043006,121.642342,6.196756,0.430057,-149.189117,0.044003,0.000000
40.110001,27.458000,-149.189117,-0.003147,0.001718,0.043630,122.139282,6.222072,0.436301,-149.189117,0.044593,0.000000
40.460003,27.392464,-149.189117,-0.003126,0.001736,0.044098,121.847763,6.207221,0.440984,-149.189117,0.045174,0.000000
40.810001,27.403259,-149.278076,-0.003113,0.001754,0.044558,121.895782,6.209667,0.445581,-149.278076,0.045755,0.000000
41.160004,27.794250,-149.322556,-0.003078,0.001783,0.045295,123.635002,6.298267,0.452952,-149.322556,0.046336,0.000000
41.510002,28.370682,-149.278076,-0.003074,0.001807,0.045894,126.199097,6.428888,0.458936,-149.278076,0.046926,0.000000
41.860001,28.346107,-149.322556,-0.003048,0.001827,0.046405,126.089783,6.423319,0.464052,-149.322556,0.047507,0.000000
42.210003,28.432495,-149.367035,-0.003035,0.001851,0.047012,126.474052,6.442895,0.470123,-149.367035,0.048088,0.000000
42.560001,28.064964,-149.411514,-0.003031,0.001868,0.047446,124.839195,6.359612,0.474459,-149.411514,0.048669,0.000000
42.910004,28.703209,-149.367035,-0.003018,0.001889,0.047984,127.678253,6.504240,0.479836,-149.367035,0.049258,0.000000
43.260002,29.422638,-149.455994,-0.003001,0.001917,0.048686,130.878433,6.667265,0.486861,-149.455994,0.049839,0.000000
43.610001,29.656487,-149.411514,-0.002984,0.001941,0.049293,131.918640,6.720256,0.492931,-149.411514,0.050421,0.000000
43.960003,28.594475,-149.455994,-0.002975,0.001947,0.049449,127.194580,6.479601,0.494492,-149.455994,0.051002,0.000000
44.310001,30.334206,-149.411514,-0.002949,0.001988,0.050490,134.933289,6.873829,0.504899,-149.411514,0.051591,0.000000
44.660004,30.001305,-149.455994,-0.002936,0.002008,0.051010,133.452469,6.798393,0.510102,-149.455994,0.052172,0.000000
45.010002,29.570465,-149.500473,-0.002923,0.002022,0.051348,131.535995,6.700763,0.513484,-149.500473,0.052753,0.000000
45.360001,31.096825,-149.544952,-0.002897,0.002059,0.052294,138.325592,7.046641,0.522937,-149.544952,0.053343,0.000000
45.710003,31.002609,-149.544952,-0.002876,0.002081,0.052857,137.906494,7.025291,0.528574,-149.544952,0.053924,0.000000
46.060001,30.662262,-149.544952,-0.002859,0.002096,0.053248,136.392548,6.948168,0.532477,-149.544952,0.054505,0.000000
46.410004,30.636200,-149.589432,-0.002854,0.002114,0.053707,136.276627,6.942262,0.537073,-149.589432,0.055086,0.000000
46.760002,31.801353,-149.722885,-0.002828,0.002148,0.054566,141.459488,7.206289,0.545658,-149.722885,0.055676,0.000000
47.110001,32.181541,-149.589432,-0.002815,0.002173,0.055190,143.150650,7.292441,0.551902,-149.589432,0.056257,0.000000
47.460003,32.425819,-149.678406,-0.002794,0.002197,0.055815,144.237244,7.347795,0.558146,-149.678406,0.056838,0.000000
47.810001,32.259369,-149.767365,-0.002785,0.002219,0.056370,143.496841,7.310078,0.563697,-149.767365,0.057419,0.000000
48.160004,31.195503,-149.767365,-0.002759,0.002224,0.056482,138.764526,7.069002,0.564824,-149.767365,0.058009,0.000000
48.510002,32.884209,-149.722885,-0.002738,0.002264,0.057506,146.276260,7.451668,0.575057,-149.722885,0.058590,0.000000
48.860001,32.278358,-149.811844,-0.002721,0.002276,0.057818,143.581314,7.314381,0.578179,-149.811844,0.059171,0.000000
49.210003,33.107635,-149.856323,-0.002703,0.002308,0.058624,147.270111,7.502297,0.586245,-149.856323,0.059761,0.000000
49.560001,33.261795,-149.856323,-0.002708,0.002333,0.059249,147.955856,7.537230,0.592489,-149.856323,0.060342,0.000000
49.910004,33.599907,-149.856323,-0.002673,0.002352,0.059752,149.459854,7.613848,0.597519,-149.856323,0.060923,0.000000
50.260002,34.029251,-149.900803,-0.002660,0.002378,0.060411,151.369675,7.711138,0.604109,-149.900803,0.061504,0.000000
50.610001,34.120857,-149.900803,-0.002652,0.002398,0.060897,151.777161,7.731897,0.608966,-149.900803,0.062093,0.000000
50.960003,35.119560,-149.989761,-0.002621,0.002429,0.061686,156.219604,7.958206,0.616858,-149.989761,0.062674,0.000000
51.310001,35.090141,-149.989761,-0.002613,0.002450,0.062241,156.088745,7.951540,0.622408,-149.989761,0.063255,0.000000
51.660004,35.391022,-150.034241,-0.002587,0.002474,0.062831,157.427124,8.019720,0.628305,-150.034241,0.063836,0.000000
52.010002,35.442780,-149.989761,-0.002583,0.002493,0.063333,157.657364,8.031448,0.633335,-149.989761,0.064426,0.000000
52.360001,35.433846,-150.078735,-0.002557,0.002513,0.063836,157.617615,8.029424,0.638365,-150.078735,0.065007,0.000000
52.710003,35.598801,-150.078735,-0.002535,0.002531,0.064296,158.351379,8.066804,0.642961,-150.078735,0.065588,0.000000
53.060001,36.584473,-150.034241,-0.002544,0.002559,0.065007,162.735855,8.290160,0.650073,-150.034241,0.066169,0.000000
53.410004,37.105423,-150.034241,-0.002522,0.002585,0.065649,165.053162,8.408209,0.656490,-150.034241,0.066759,0.000000
53.760002,36.082520,-150.078735,-0.002522,0.002592,0.065831,160.503067,8.176415,0.658311,-150.078735,0.067340,0.000000
54.110004,37.885918,-150.123215,-0.002475,0.002626,0.066707,168.524979,8.585072,0.667070,-150.123215,0.067921,0.000000
54.460003,38.012894,-150.123215,-0.002466,0.002645,0.067193,169.089798,8.613845,0.671926,-150.123215,0.068511,0.000000
54.810001,39.598083,-150.167694,-0.002462,0.002681,0.068103,176.141068,8.973054,0.681032,-150.167694,0.069092,0.000000
55.160004,39.588028,-150.212173,-0.002449,0.002700,0.068589,176.096344,8.970776,0.685889,-150.212173,0.069673,0.000000
55.510002,39.407059,-150.212173,-0.002427,0.002718,0.069031,175.291351,8.929767,0.690312,-150.212173,0.070254,0.000000
55.860004,40.095947,-150.256653,-0.002410,0.002744,0.069699,178.355682,9.085872,0.696989,-150.256653,0.070844,0.000000
56.210003,40.917030,-150.167694,-0.002406,0.002766,0.070263,182.008041,9.271932,0.702626,-150.167694,0.071425,0.000000
56.560001,40.724884,-150.301132,-0.002384,0.002782,0.070662,181.153336,9.228391,0.706616,-150.301132,0.072006,0.000000
56.910004,41.344513,-150.256653,-0.002358,0.002807,0.071295,183.909576,9.368801,0.712946,-150.256653,0.072587,0.000000
57.260002,41.742203,-150.345612,-0.002350,0.002825,0.071763,185.678589,9.458918,0.717629,-150.345612,0.073176,0.000000
57.610004,41.675179,-150.345612,-0.002328,0.002840,0.072136,185.380447,9.443730,0.721358,-150.345612,0.073758,0.000000
57.960003,44.037880,-150.390091,-0.002320,0.002883,0.073229,195.890274,9.979126,0.732285,-150.390091,0.074339,0.000000
58.310001,45.169151,-150.390091,-0.002289,0.002911,0.073931,200.922424,10.235476,0.739310,-150.390091,0.074928,0.000000
58.660004,44.735336,-150.434570,-0.002276,0.002927,0.074356,198.992722,10.137173,0.743559,-150.434570,0.075509,0.000000
59.010002,46.082581,-150.434570,-0.002272,0.002956,0.075084,204.985550,10.442462,0.750844,-150.434570,0.076090,0.000000
59.360004,46.424789,-150.434570,-0.002255,0.002977,0.075622,206.507782,10.520007,0.756221,-150.434570,0.076671,0.000000
59.710003,47.011650,-150.479065,-0.002238,0.002997,0.076116,209.118271,10.652992,0.761164,-150.479065,0.077261,0.000000
60.060001,47.416420,-150.523544,-0.002216,0.003015,0.076576,210.918777,10.744714,0.765760,-150.523544,0.077842,0.000000
60.410004,48.659393,-150.568024,-0.002220,0.003042,0.077270,216.447784,11.026376,0.772698,-150.568024,0.078423,0.000000
60.760002,49.835350,-150.568024,-0.002186,0.003071,0.078016,221.678711,11.292851,0.780156,-150.568024,0.079004,0.000000
61.110004,50.432632,-150.479065,-0.002186,0.003092,0.078536,224.335556,11.428198,0.785360,-150.479065,0.079594,0.000000
61.460003,51.383301,-150.523544,-0.002169,0.003118,0.079186,228.564331,11.643622,0.791864,-150.523544,0.080175,0.000000
61.810001,51.764610,-150.656982,-0.002147,0.003136,0.079646,230.260483,11.730028,0.796460,-150.656982,0.080756,0.000000
62.160004,52.271034,-150.612503,-0.002121,0.003153,0.080080,232.513168,11.844786,0.800796,-150.612503,0.081337,0.000000
62.510002,53.910217,-150.568024,-0.002113,0.003183,0.080851,239.804626,12.216229,0.808515,-150.568024,0.081927,0.000000
62.860004,54.743965,-150.656982,-0.002121,0.003206,0.081424,243.513321,12.405160,0.814238,-150.656982,0.082508,0.000000
63.210003,55.466736,-150.701462,-0.002078,0.003225,0.081927,246.728363,12.568942,0.819268,-150.701462,0.083089,0.000000
63.560001,55.873741,-150.745941,-0.002074,0.003242,0.082352,248.538818,12.661171,0.823517,-150.745941,0.083679,0.000000
63.910004,57.609741,-150.745941,-0.002070,0.003274,0.083167,256.260925,13.054554,0.831669,-150.745941,0.084260,0.000000
64.260002,57.985840,-150.745941,-0.002052,0.003290,0.083575,257.933899,13.139779,0.835746,-150.745941,0.084841,0.000000
64.610001,59.490967,-150.790421,-0.002044,0.003315,0.084208,264.629028,13.480846,0.842076,-150.790421,0.085422,0.000000
64.960007,60.695961,-150.879379,-0.002031,0.003340,0.084841,269.989105,13.753901,0.848407,-150.879379,0.086011,0.000000
65.310005,60.147087,-150.879379,-0.002031,0.003346,0.084979,267.547607,13.629525,0.849795,-150.879379,0.086592,0.000000
65.660004,63.105583,-150.834900,-0.002001,0.003387,0.086029,280.707642,14.299930,0.860288,-150.834900,0.087174,0.000000
66.010002,63.811974,-150.834900,-0.001979,0.003406,0.086514,283.849823,14.460000,0.865144,-150.834900,0.087755,0.000000
66.360001,64.277077,-150.879379,-0.001979,0.003420,0.086870,285.918732,14.565394,0.868700,-150.879379,0.088344,0.000000
66.710007,65.616493,-150.968353,-0.001962,0.003439,0.087356,291.876740,14.868910,0.873557,-150.968353,0.015339,0.000000
67.060005,64.478889,-150.923874,-0.001957,0.003449,0.087607,286.816437,14.611125,0.876071,-150.923874,294.500488,0.000000
67.410004,65.730446,-150.968353,-0.001949,0.003413,0.086688,292.383636,14.894732,0.866879,-150.968353,294.500488,0.000000
67.760002,65.140602,-150.879379,-0.001932,0.003462,0.087928,289.759857,14.761071,0.879280,-150.879379,294.500488,0.000000
68.110001,64.859459,-151.012833,-0.001932,0.003472,0.088180,288.509277,14.697364,0.881795,-151.012833,294.500488,0.000000
68.460007,64.993889,-151.012833,-0.001919,0.003477,0.088318,289.107269,14.727826,0.883183,-151.012833,294.500488,0.000000
68.810005,64.294197,-151.057312,-0.001906,0.003477,0.088327,285.994873,14.569273,0.883269,-151.057312,294.500488,0.000000
69.160004,66.427895,-151.101791,-0.001897,0.003390,0.086116,295.486023,15.052776,0.861155,-151.101791,294.500488,0.000000
69.510002,65.740486,-151.012833,-0.001901,0.003401,0.086376,292.428284,14.897007,0.863757,-151.012833,294.500488,0.000000
69.860001,65.180443,-151.146271,-0.001897,0.003491,0.088665,289.937103,14.770100,0.886652,-151.146271,294.500488,0.000000
70.210007,64.681465,-151.146271,-0.001906,0.003496,0.088795,287.717529,14.657030,0.887952,-151.146271,294.500488,0.000000
70.560005,65.505898,-151.190750,-0.001876,0.003513,0.089220,291.384796,14.843848,0.892202,-151.190750,294.500488,0.000000
70.910004,64.992027,-151.235229,-0.001880,0.003513,0.089220,289.098969,14.727404,0.892202,-151.235229,294.500488,0.000000
71.260002,64.529167,-151.235229,-0.001893,0.003513,0.089220,287.040070,14.622519,0.892202,-151.235229,294.500488,0.000000
71.610001,67.068001,-151.235229,-0.001880,0.003530,0.089671,298.333374,15.197826,0.896711,-151.235229,294.500488,0.000000
71.960007,66.300545,-151.279709,-0.001863,0.003472,0.088197,294.919556,15.023918,0.881968,-151.279709,294.500488,0.000000
72.310005,65.849602,-151.279709,-0.001858,0.003473,0.088206,292.913666,14.921733,0.882055,-151.279709,294.500488,0.000000
72.660004,65.497337,-151.324188,-0.001850,0.003496,0.088795,291.346710,14.841908,0.887952,-151.324188,294.500488,0.000000
73.010002,65.181557,-151.279709,-0.001867,0.003516,0.089298,289.942047,14.770352,0.892982,-151.279709,294.500488,0.000000
73.360001,64.978249,-151.324188,-0.001867,0.003534,0.089758,289.037689,14.724281,0.897579,-151.324188,294.500488,0.000000
73.710007,65.554680,-151.368683,-0.001845,0.003546,0.090079,291.601776,14.854903,0.900787,-151.368683,294.500488,0.000000
74.060005,65.385994,-151.413162,-0.001837,0.003545,0.090053,290.851440,14.816678,0.900527,-151.413162,294.500488,0.000000
74.410004,65.165550,-151.457642,-0.001841,0.003545,0.090053,289.870850,14.766726,0.900527,-151.457642,294.500488,0.000000
74.760002,64.938408,-151.502121,-0.001850,0.003545,0.090053,288.860474,14.715253,0.900527,-151.502121,294.500488,0.000000
75.110001,64.696739,-151.457642,-0.001854,0.003545,0.090053,287.785461,14.660490,0.900527,-151.457642,294.500488,0.000000
75.460007,65.756874,-151.502121,-0.001850,0.003560,0.090417,292.501190,14.900721,0.904170,-151.502121,294.500488,0.000000
75.810005,65.573677,-151.502121,-0.001850,0.003560,0.090417,291.686279,14.859208,0.904170,-151.502121,294.500488,0.000000
76.160004,65.382271,-151.502121,-0.001841,0.003560,0.090417,290.834869,14.815834,0.904170,-151.502121,294.500488,0.000000
76.510002,65.225136,-151.546600,-0.001841,0.003560,0.090417,290.135895,14.780228,0.904170,-151.546600,294.500488,0.000000
76.860001,65.024788,-151.591080,-0.001850,0.003560,0.090417,289.244690,14.734827,0.904170,-151.591080,294.500488,0.000000
77.210007,64.850899,-151.591080,-0.001824,0.003560,0.090417,288.471191,14.695423,0.904170,-151.591080,294.500488,0.000000
77.560005,65.897255,-151.591080,-0.001845,0.003570,0.090677,293.125641,14.932531,0.906771,-151.591080,294.500488,0.000000
77.910004,65.717781,-151.591080,-0.001828,0.003570,0.090677,292.327301,14.891862,0.906771,-151.591080,294.500488,0.000000
78.260002,65.524513,-151.635559,-0.001837,0.003570,0.090677,291.467590,14.848067,0.906771,-151.635559,294.500488,0.000000
78.610001,65.330879,-151.680038,-0.001824,0.003570,0.090677,290.606262,14.804189,0.906771,-151.680038,294.500488,0.000000
78.960007,65.172997,-151.680038,-0.001837,0.003570,0.090677,289.903961,14.768412,0.906771,-151.680038,294.500488,0.000000
79.310005,65.000969,-151.769012,-0.001819,0.003570,0.090677,289.138763,14.729430,0.906771,-151.769012,294.500488,0.000000
79.660004,65.069481,-151.813492,-0.001824,0.003581,0.090946,289.443512,14.744955,0.909460,-151.813492,294.500488,0.000000
80.010002,65.541267,-151.769012,-0.001811,0.003580,0.090937,291.542114,14.851864,0.909373,-151.769012,294.500488,0.000000
80.360001,65.456367,-151.813492,-0.001811,0.003580,0.090937,291.164459,14.832624,0.909373,-151.813492,294.500488,0.000000
80.710007,65.310768,-151.813492,-0.001807,0.003581,0.090946,290.516815,14.799632,0.909460,-151.813492,294.500488,0.000000
81.060005,65.210976,-151.813492,-0.001815,0.003581,0.090946,290.072906,14.777019,0.909460,-151.813492,294.500488,0.000000
81.410004,65.135384,-151.902451,-0.001811,0.003582,0.090989,289.736664,14.759890,0.909893,-151.902451,294.500488,0.000000
81.760002,65.120872,-151.902451,-0.001811,0.003583,0.091015,289.672119,14.756600,0.910153,-151.902451,294.500488,0.000000
82.110001,65.196831,-151.902451,-0.001824,0.003585,0.091067,290.009979,14.773812,0.910674,-151.902451,294.500488,0.000000
82.460007,65.113411,-151.902451,-0.001832,0.003585,0.091067,289.638916,14.754910,0.910674,-151.902451,294.500488,0.000000
82.810005,65.199440,-151.991409,-0.001819,0.003588,0.091128,290.021606,14.774405,0.911281,-151.991409,294.500488,0.000000
83.160004,65.151772,-152.035889,-0.001807,0.003588,0.091137,289.809540,14.763602,0.911367,-152.035889,294.500488,0.000000
83.510002,65.141716,-151.991409,-0.001819,0.003589,0.091163,289.764832,14.761324,0.911628,-151.991409,294.500488,0.000000
83.860001,65.151405,-151.991409,-0.001824,0.003590,0.091189,289.807922,14.763519,0.911888,-151.991409,294.500488,0.000000
84.210007,65.124214,-152.035889,-0.001811,0.003591,0.091206,289.686981,14.757359,0.912061,-152.035889,294.500488,0.000000
84.560005,65.152519,-152.080368,-0.001798,0.003594,0.091284,289.812866,14.763772,0.912842,-152.080368,294.500488,0.000000
84.910004,65.241890,-152.035889,-0.001807,0.003594,0.091293,290.210419,14.784024,0.912928,-152.035889,294.500488,0.000000
85.260002,65.208748,-152.035889,-0.001802,0.003594,0.091293,290.062988,14.776513,0.912928,-152.035889,294.500488,0.000000
85.610001,65.164055,-152.124847,-0.001802,0.003595,0.091319,289.864197,14.766386,0.913189,-152.124847,294.500488,0.000000
85.960007,65.156990,-152.124847,-0.001807,0.003596,0.091336,289.832764,14.764785,0.913362,-152.124847,294.500488,0.000000
86.310005,65.113411,-152.124847,-0.001802,0.003596,0.091336,289.638916,14.754910,0.913362,-152.124847,294.500488,0.000000
86.660004,65.171883,-152.169327,-0.001815,0.003598,0.091388,289.899017,14.768160,0.913882,-152.169327,294.500488,0.000000
87.010002,65.114906,-152.258301,-0.001807,0.003598,0.091388,289.645569,14.755248,0.913882,-152.258301,294.500488,0.000000
87.360001,65.069481,-152.213821,-0.001802,0.003598,0.091388,289.443512,14.744955,0.913882,-152.213821,294.500488,0.000000
87.710007,65.005058,-152.302780,-0.001811,0.003598,0.091388,289.156952,14.730357,0.913882,-152.302780,294.500488,0.000000
88.060005,65.065010,-152.302780,-0.001789,0.003601,0.091458,289.423615,14.743942,0.914576,-152.302780,294.500488,0.000000
88.410004,65.109322,-152.258301,-0.001802,0.003601,0.091466,289.620728,14.753983,0.914663,-152.258301,294.500488,0.000000
88.760002,65.075066,-152.302780,-0.001802,0.003601,0.091466,289.468353,14.746221,0.914663,-152.302780,294.500488,0.000000
89.110001,65.027779,-152.391739,-0.001798,0.003601,0.091466,289.257996,14.735505,0.914663,-152.391739,294.500488,0.000000
89.460007,65.208748,-152.391739,-0.001785,0.003604,0.091553,290.062988,14.776513,0.915530,-152.391739,294.500488,0.000000
89.810005,65.193108,-152.347260,-0.001798,0.003604,0.091553,289.993439,14.772969,0.915530,-152.347260,294.500488,0.000000
90.160004,65.143959,-152.436218,-0.001785,0.003604,0.091553,289.774811,14.761832,0.915530,-152.436218,294.500488,0.000000
90.510002,65.084740,-152.347260,-0.001785,0.003604,0.091553,289.511383,14.748413,0.915530,-152.347260,294.500488,0.000000
90.860001,65.101128,-152.436218,-0.001802,0.003606,0.091605,289.584290,14.752126,0.916051,-152.436218,294.500488,0.000000
91.210007,65.111183,-152.436218,-0.001794,0.003606,0.091605,289.628998,14.754405,0.916051,-152.436218,294.500488,0.000000
91.560005,65.073570,-152.525177,-0.001794,0.003607,0.091614,289.461700,14.745882,0.916137,-152.525177,294.500488,0.000000
91.910004,65.043037,-152.569656,-0.001794,0.003607,0.091614,289.325867,14.738962,0.916137,-152.569656,294.500488,0.000000
92.260002,65.364403,-152.569656,-0.001798,0.003613,0.091778,290.755371,14.811786,0.917785,-152.569656,294.500488,0.000000
92.610001,65.522652,-152.480698,-0.001798,0.003613,0.091770,291.459320,14.847645,0.917698,-152.480698,294.500488,0.000000
92.960007,65.507759,-152.525177,-0.001789,0.003613,0.091770,291.393066,14.844271,0.917698,-152.525177,294.500488,0.000000
93.310005,65.480583,-152.569656,-0.001798,0.003613,0.091770,291.272186,14.838112,0.917698,-152.569656,294.500488,0.000000
93.660004,65.384880,-152.569656,-0.001781,0.003613,0.091770,290.846466,14.816426,0.917698,-152.569656,294.500488,0.000000
94.010002,65.340935,-152.614136,-0.001781,0.003613,0.091770,290.651001,14.806468,0.917698,-152.614136,294.500488,0.000000
94.360008,65.304817,-152.703110,-0.001785,0.003613,0.091770,290.490326,14.798283,0.917698,-152.703110,294.500488,0.000000
94.710007,65.270561,-152.658630,-0.001781,0.003613,0.091770,290.337952,14.790521,0.917698,-152.658630,294.500488,0.000000
95.060005,65.233315,-152.747589,-0.001802,0.003613,0.091778,290.172272,14.782081,0.917785,-152.747589,294.500488,0.000000
95.410004,65.171501,-152.703110,-0.001781,0.003613,0.091778,289.897308,14.768073,0.917785,-152.703110,294.500488,0.000000
95.760002,65.115273,-152.792068,-0.001789,0.003613,0.091778,289.647186,14.755332,0.917785,-152.792068,294.500488,0.000000
96.110008,65.069481,-152.747589,-0.001798,0.003613,0.091778,289.443512,14.744955,0.917785,-152.747589,294.500488,0.000000
96.460007,65.042290,-152.747589,-0.001798,0.003613,0.091778,289.322540,14.738793,0.917785,-152.747589,294.500488,0.000000
96.810005,65.382637,-152.792068,-0.001785,0.003619,0.091926,290.836487,14.815918,0.919259,-152.792068,294.500488,0.000000
97.160004,65.401634,-152.792068,-0.001776,0.003619,0.091926,290.920990,14.820223,0.919259,-152.792068,294.500488,0.000000
97.510002,65.380043,-152.836548,-0.001794,0.003619,0.091926,290.824951,14.815329,0.919259,-152.836548,294.500488,0.000000
97.860008,65.353600,-152.881027,-0.001785,0.003619,0.091926,290.707336,14.809338,0.919259,-152.881027,294.500488,0.000000
98.210007,65.324547,-152.881027,-0.001789,0.003619,0.091926,290.578094,14.802753,0.919259,-152.881027,294.500488,0.000000
98.560005,65.298866,-152.925507,-0.001772,0.003619,0.091926,290.463867,14.796934,0.919259,-152.925507,294.500488,0.000000
98.910004,65.271309,-152.925507,-0.001776,0.003619,0.091926,290.341278,14.790690,0.919259,-152.925507,294.500488,0.000000
99.260002,65.246361,-152.925507,-0.001776,0.003619,0.091926,290.230316,14.785036,0.919259,-152.925507,294.500488,0.000000
99.610008,65.218422,-153.014465,-0.001781,0.003619,0.091935,290.106018,14.778706,0.919346,-153.014465,294.500488,0.000000
99.960007,65.176720,-153.014465,-0.001776,0.003619,0.091935,289.920532,14.769256,0.919346,-153.014465,294.500488,0.000000
100.310005,65.136879,-153.014465,-0.001781,0.003619,0.091935,289.743317,14.760228,0.919346,-153.014465,294.500488,0.000000
100.660004,65.110069,-153.103439,-0.001772,0.003620,0.091943,289.624054,14.754152,0.919433,-153.103439,294.500488,0.000000
101.010002,65.072456,-153.103439,-0.001781,0.003620,0.091943,289.456757,14.745629,0.919433,-153.103439,294.500488,0.000000
101.360008,65.035225,-153.058960,-0.001776,0.003620,0.091943,289.291138,14.737193,0.919433,-153.058960,294.500488,0.000000
101.710007,65.024055,-153.192398,-0.001781,0.003620,0.091943,289.241455,14.734662,0.919433,-153.192398,294.500488,0.000000
102.060005,64.993141,-153.103439,-0.001772,0.003620,0.091943,289.103943,14.727656,0.919433,-153.103439,294.500488,0.000000
102.410004,64.967445,-153.147919,-0.001781,0.003620,0.091943,288.989624,14.721833,0.919433,-153.147919,294.500488,0.000000
102.760002,64.925377,-153.192398,-0.001772,0.003622,0.091995,288.802490,14.712301,0.919953,-153.192398,294.500488,0.000000
103.110008,64.961861,-153.147919,-0.001785,0.003622,0.091995,288.964783,14.720568,0.919953,-153.147919,294.500488,0.000000
103.460007,64.947716,-153.192398,-0.001794,0.003622,0.091995,288.901855,14.717363,0.919953,-153.192398,294.500488,0.000000
103.810005,64.930214,-153.192398,-0.001776,0.003622,0.091995,288.824005,14.713397,0.919953,-153.192398,294.500488,0.000000
104.160004,64.906380,-153.281357,-0.001785,0.003622,0.091995,288.717987,14.707996,0.919953,-153.281357,294.500488,0.000000
104.510002,64.882927,-153.281357,-0.001772,0.003622,0.092004,288.613678,14.702682,0.920040,-153.281357,294.500488,0.000000
104.860008,64.838600,-153.281357,-0.001781,0.003622,0.092004,288.416504,14.692636,0.920040,-153.281357,294.500488,0.000000
105.210007,64.824837,-153.370316,-0.001789,0.003622,0.092004,288.355286,14.689518,0.920040,-153.370316,294.500488,0.000000
105.560005,64.793556,-153.370316,-0.001785,0.003622,0.092004,288.216125,14.682429,0.920040,-153.370316,294.500488,0.000000
105.910004,64.763008,-153.370316,-0.001785,0.003622,0.092004,288.080261,14.675508,0.920040,-153.370316,294.500488,0.000000
106.260002,64.741051,-153.370316,-0.001776,0.003622,0.092004,287.982574,14.670532,0.920040,-153.370316,294.500488,0.000000
106.610008,64.713860,-153.414795,-0.001781,0.003622,0.092004,287.861633,14.664370,0.920040,-153.414795,294.500488,0.000000
106.960007,64.681831,-153.459274,-0.001776,0.003622,0.092004,287.719147,14.657112,0.920040,-153.459274,294.500488,0.000000
107.310005,65.575905,-153.503769,-0.001781,0.003633,0.092290,291.696198,14.859713,0.922902,-153.503769,294.500488,0.000000
107.660004,65.623573,-153.503769,-0.001763,0.003633,0.092290,291.908234,14.870514,0.922902,-153.503769,294.500488,0.000000
108.010002,65.653725,-153.503769,-0.001772,0.003633,0.092290,292.042358,14.877347,0.922902,-153.503769,294.500488,0.000000
108.360008,65.660439,-153.548248,-0.001789,0.003633,0.092290,292.072205,14.878868,0.922902,-153.548248,294.500488,0.000000
108.710007,65.639946,-153.548248,-0.001776,0.003633,0.092290,291.981049,14.874225,0.922902,-153.548248,294.500488,0.000000
109.060005,65.624306,-153.637207,-0.001781,0.003633,0.092290,291.911499,14.870681,0.922902,-153.637207,294.500488,0.000000
109.410004,65.600105,-153.592728,-0.001776,0.003633,0.092290,291.803833,14.865196,0.922902,-153.592728,294.500488,0.000000
109.760002,65.594902,-153.637207,-0.001776,0.003633,0.092290,291.780701,14.864017,0.922902,-153.637207,294.500488,0.000000
110.110008,65.575905,-153.637207,-0.001772,0.003633,0.092290,291.696198,14.859713,0.922902,-153.637207,294.500488,0.000000
110.460007,65.546120,-153.637207,-0.001776,0.003633,0.092290,291.563690,14.852962,0.922902,-153.637207,294.500488,0.000000
110.810005,65.533455,-153.726166,-0.001759,0.003633,0.092290,291.507355,14.850093,0.922902,-153.726166,294.500488,0.000000
111.160004,65.507393,-153.726166,-0.001768,0.003633,0.092290,291.391449,14.844188,0.922902,-153.726166,294.500488,0.000000
111.510002,65.474998,-153.770645,-0.001772,0.003633,0.092290,291.247345,14.836846,0.922902,-153.770645,294.500488,0.000000
111.860008,65.447807,-153.770645,-0.001759,0.003633,0.092290,291.126373,14.830686,0.922902,-153.770645,294.500488,0.000000
112.210007,65.395683,-153.815125,-0.001763,0.003633,0.092290,290.894531,14.818873,0.922902,-153.815125,294.500488,0.000000
112.560005,65.383766,-153.815125,-0.001781,0.003633,0.092290,290.841522,14.816174,0.922902,-153.815125,294.500488,0.000000
112.910004,65.350990,-153.859604,-0.001772,0.003633,0.092290,290.695709,14.808746,0.922902,-153.859604,294.500488,0.000000
113.260002,65.327904,-153.859604,-0.001768,0.003633,0.092290,290.593018,14.803514,0.922902,-153.859604,294.500488,0.000000
113.610008,65.289925,-153.904083,-0.001772,0.003633,0.092290,290.424103,14.794909,0.922902,-153.904083,294.500488,0.000000
113.960007,65.270180,-153.904083,-0.001776,0.003633,0.092290,290.336273,14.790435,0.922902,-153.904083,294.500488,0.000000
114.310005,65.257896,-153.904083,-0.001763,0.003633,0.092290,290.281616,14.787651,0.922902,-153.904083,294.500488,0.000000
114.660004,65.231087,-153.948578,-0.001772,0.003633,0.092290,290.162354,14.781575,0.922902,-153.948578,294.500488,0.000000
115.010002,65.205772,-153.904083,-0.001768,0.003633,0.092290,290.049774,14.775839,0.922902,-153.904083,294.500488,0.000000
115.360008,65.152519,-153.993057,-0.001768,0.003633,0.092290,289.812866,14.763772,0.922902,-153.993057,294.500488,0.000000
115.710007,65.124214,-153.993057,-0.001763,0.003633,0.092290,289.686981,14.757359,0.922902,-153.993057,294.500488,0.000000
116.060005,65.100761,-154.037537,-0.001759,0.003633,0.092290,289.582642,14.752044,0.922902,-154.037537,294.500488,0.000000
116.410004,65.077675,-154.126495,-0.001772,0.003633,0.092290,289.479950,14.746812,0.922902,-154.126495,294.500488,0.000000
116.760002,65.050117,-154.082016,-0.001763,0.003633,0.092290,289.357361,14.740567,0.922902,-154.082016,294.500488,0.000000
117.110008,65.025169,-154.126495,-0.001768,0.003633,0.092290,289.246399,14.734915,0.922902,-154.126495,294.500488,0.000000
117.460007,64.989418,-154.126495,-0.001785,0.003633,0.092290,289.087372,14.726813,0.922902,-154.126495,294.500488,0.000000
117.810005,64.982719,-154.126495,-0.001772,0.003633,0.092290,289.057587,14.725295,0.922902,-154.126495,294.500488,0.000000
118.160004,64.964470,-154.170975,-0.001768,0.003633,0.092290,288.976410,14.721160,0.922902,-154.170975,294.500488,0.000000
118.510002,64.942131,-154.259933,-0.001772,0.003633,0.092290,288.877014,14.716098,0.922902,-154.259933,294.500488,0.000000
118.860008,64.908241,-154.259933,-0.001768,0.003633,0.092290,288.726288,14.708417,0.922902,-154.259933,294.500488,0.000000
119.210007,64.863564,-154.215454,-0.001759,0.003633,0.092290,288.527527,14.698294,0.922902,-154.215454,294.500488,0.000000
119.560005,64.844566,-154.304413,-0.001763,0.003633,0.092290,288.443024,14.693989,0.922902,-154.304413,294.500488,0.000000
119.910004,64.806953,-154.304413,-0.001772,0.003633,0.092290,288.275726,14.685465,0.922902,-154.304413,294.500488,0.000000
120.260002,64.789833,-154.304413,-0.001772,0.003633,0.092290,288.199585,14.681586,0.922902,-154.304413,294.500488,0.000000
120.610008,64.758919,-154.304413,-0.001759,0.003633,0.092290,288.062073,14.674582,0.922902,-154.304413,294.500488,0.000000
120.960007,64.754829,-154.393387,-0.001789,0.003633,0.092290,288.043854,14.673655,0.922902,-154.393387,294.500488,0.000000
121.310005,64.724663,-154.348907,-0.001755,0.003633,0.092290,287.909668,14.666818,0.922902,-154.348907,294.500488,0.000000
121.660004,64.714241,-154.393387,-0.001772,0.003633,0.092290,287.863312,14.664456,0.922902,-154.393387,294.500488,0.000000
122.010002,64.680717,-154.393387,-0.001763,0.003633,0.092290,287.714203,14.656860,0.922902,-154.393387,294.500488,0.000000
122.360008,64.656151,-154.437866,-0.001776,0.003633,0.092290,287.604919,14.651293,0.922902,-154.437866,294.500488,0.000000
122.710007,64.641991,-154.482346,-0.001772,0.003633,0.092290,287.541931,14.648084,0.922902,-154.482346,294.500488,0.000000
123.060005,64.614067,-154.526825,-0.001759,0.003633,0.092290,287.417725,14.641757,0.922902,-154.526825,294.500488,0.000000
123.410004,64.595818,-154.482346,-0.001763,0.003633,0.092290,287.336548,14.637621,0.922902,-154.482346,294.500488,0.000000
123.760002,64.553368,-154.526825,-0.001768,0.003633,0.092290,287.147736,14.628002,0.922902,-154.526825,294.500488,0.000000
124.110008,64.545921,-154.615784,-0.001763,0.003633,0.092290,287.114594,14.626315,0.922902,-154.615784,294.500488,0.000000
124.460007,64.515388,-154.615784,-0.001785,0.003633,0.092290,286.978790,14.619396,0.922902,-154.615784,294.500488,0.000000
124.810005,64.491188,-154.615784,-0.001768,0.003634,0.092299,286.871124,14.613912,0.922988,-154.615784,294.500488,0.000000
125.160004,64.470711,-154.660263,-0.001768,0.003634,0.092299,286.780029,14.609272,0.922988,-154.660263,294.500488,0.000000
125.510010,64.458412,-154.615784,-0.001763,0.003634,0.092299,286.725342,14.606484,0.922988,-154.615784,294.500488,0.000000
125.860008,66.460289,-154.704742,-0.001750,0.003621,0.091978,295.630127,15.060117,0.919780,-154.704742,294.500488,0.000000
126.210007,66.417839,-154.660263,-0.001763,0.003621,0.091978,295.441315,15.050497,0.919780,-154.660263,294.500488,0.000000
126.560005,66.421562,-154.704742,-0.001755,0.003621,0.091978,295.457855,15.051342,0.919780,-154.704742,294.500488,0.000000
126.910004,66.392143,-154.749222,-0.001750,0.003621,0.091978,295.326996,15.044675,0.919780,-154.749222,294.500488,0.000000
127.260010,66.366829,-154.749222,-0.001772,0.003621,0.091978,295.214386,15.038939,0.919780,-154.749222,0.091978,0.000000
127.610008,66.323250,-154.838196,-0.001755,0.003617,0.091874,295.020538,15.029063,0.918739,-154.838196,0.091449,0.000000
127.960007,66.251015,-154.793716,-0.001759,0.003599,0.091406,294.699219,15.012694,0.914056,-154.793716,0.090868,0.000000
128.310013,66.253624,-154.838196,-0.001750,0.003579,0.090894,294.710846,15.013286,0.908939,-154.838196,0.090278,0.000000
128.660004,66.244316,-154.838196,-0.001750,0.003555,0.090304,294.669434,15.011177,0.903042,-154.838196,0.089697,0.000000
129.010010,66.194038,-154.882675,-0.001759,0.003533,0.089732,294.445801,14.999784,0.897318,-154.882675,0.089116,0.000000
129.360001,66.169090,-154.882675,-0.001746,0.003508,0.089107,294.334808,14.994130,0.891074,-154.882675,0.088535,0.000000
129.710007,66.116966,-154.882675,-0.001750,0.003489,0.088630,294.102966,14.982318,0.886305,-154.882675,0.087945,0.000000
130.060013,66.032433,-154.927155,-0.001742,0.003466,0.088032,293.726929,14.963163,0.880321,-154.927155,0.087364,0.000000
130.410004,65.962425,-154.927155,-0.001750,0.003443,0.087442,293.415527,14.947299,0.874424,-154.927155,0.086783,0.000000
130.760010,65.619850,-155.016113,-0.001755,0.003418,0.086827,291.891663,14.869671,0.868267,-155.016113,0.086194,0.000000
131.110001,65.092567,-154.971634,-0.001763,0.003400,0.086367,289.546204,14.750187,0.863670,-154.971634,0.085613,0.000000
131.460007,64.239830,-155.060593,-0.001750,0.003376,0.085743,285.753021,14.556954,0.857426,-155.060593,0.085031,0.000000
131.810013,63.356194,-155.016113,-0.001755,0.003357,0.085266,281.822418,14.356719,0.852656,-155.016113,0.084450,0.000000
132.160004,62.599159,-155.060593,-0.001750,0.003342,0.084884,278.454956,14.185172,0.848841,-155.060593,0.083861,0.000000
132.510010,60.850868,-155.105072,-0.001738,0.003313,0.084138,270.678192,13.789003,0.841382,-155.105072,0.083280,0.000000
132.860001,59.159927,-155.149551,-0.001738,0.003289,0.083549,263.156494,13.405831,0.835485,-155.149551,0.082699,0.000000
133.210007,57.538620,-155.149551,-0.001742,0.003271,0.083089,255.944565,13.038438,0.830889,-155.149551,0.082118,0.000000
133.560013,55.419815,-155.194031,-0.001742,0.003246,0.082447,246.519653,12.558310,0.824471,-155.194031,0.081528,0.000000
133.910004,53.769463,-155.149551,-0.001742,0.003230,0.082048,239.178513,12.184335,0.820482,-155.149551,0.080947,0.000000
134.260010,52.371574,-155.194031,-0.001742,0.003217,0.081710,232.960403,11.867569,0.817100,-155.194031,0.080366,0.000000
134.610001,49.249977,-155.238525,-0.001746,0.003184,0.080886,219.074844,11.160204,0.808861,-155.238525,0.079776,0.000000
134.960007,46.739075,-155.238525,-0.001763,0.003162,0.080305,207.905792,10.591226,0.803051,-155.238525,0.079195,0.000000
135.310013,44.462013,-155.238525,-0.001759,0.003141,0.079785,197.776917,10.075235,0.797848,-155.238525,0.078614,0.000000
135.660004,41.647621,-155.283005,-0.001768,0.003113,0.079082,185.257874,9.437486,0.790823,-155.283005,0.078033,0.000000
136.010010,39.717987,-155.327484,-0.001763,0.003094,0.078579,176.674423,9.000225,0.785793,-155.327484,0.077443,0.000000
136.360001,36.651131,-155.283005,-0.001768,0.003065,0.077851,163.032379,8.305264,0.778509,-155.283005,0.076862,0.000000
136.710007,33.503838,-155.327484,-0.001772,0.003038,0.077174,149.032516,7.592078,0.771744,-155.327484,0.076281,0.000000
137.060013,31.547768,-155.371964,-0.001785,0.003021,0.076732,140.331482,7.148826,0.767321,-155.371964,0.075700,0.000000
137.410004,29.172401,-155.460922,-0.001785,0.003001,0.076220,129.765320,6.610560,0.762205,-155.460922,0.075110,0.000000
137.760010,27.771164,-155.416443,-0.001776,0.002988,0.075900,123.532310,6.293036,0.758996,-155.416443,0.074529,0.000000
138.110001,24.407898,-155.416443,-0.001802,0.002954,0.075024,108.571754,5.530909,0.750237,-155.416443,0.073948,0.000000
138.460007,21.647873,-155.416443,-0.001798,0.002927,0.074356,96.294548,4.905478,0.743559,-155.416443,0.073367,0.000000
138.810013,19.262825,-155.460922,-0.001807,0.002907,0.073836,85.685326,4.365018,0.738356,-155.460922,0.072778,0.000000
139.160004,17.441551,-155.549881,-0.001798,0.002889,0.073385,77.583893,3.952312,0.733846,-155.549881,0.072197,0.000000
139.510010,14.811111,-155.549881,-0.001811,0.002865,0.072760,65.883118,3.356246,0.727602,-155.549881,0.071616,0.000000
139.860001,12.023163,-155.505402,-0.001811,0.002837,0.072066,53.481701,2.724488,0.720665,-155.505402,0.071026,0.000000
140.210007,9.227760,-155.549881,-0.001819,0.002809,0.071355,41.047127,2.091040,0.713553,-155.549881,0.070445,0.000000
140.560013,6.288254,-155.594360,-0.001819,0.002785,0.070731,27.971550,1.424939,0.707309,-155.594360,0.069864,0.000000
140.910004,4.759659,-155.594360,-0.001832,0.002770,0.070349,21.172020,1.078554,0.703493,-155.594360,0.069283,0.000000
141.260010,2.617401,-155.638855,-0.001837,0.002749,0.069829,11.642781,0.593112,0.698290,-155.638855,0.068693,0.000000
141.610001,0.178360,-155.683334,-0.001854,0.002720,0.069083,0.793385,0.040417,0.690832,-155.683334,0.068112,0.000000
141.960007,-1.562477,-155.683334,-0.001845,0.002699,0.068546,-6.950245,-0.354062,0.685455,-155.683334,0.067531,0.000000
142.310013,-0.608086,-155.683334,-0.001863,0.002677,0.067991,-2.704900,-0.137794,0.679905,-155.683334,0.066950,0.000000
142.660004,-0.289711,-155.683334,-0.001880,0.002654,0.067401,-1.288699,-0.065649,0.674008,-155.683334,0.066360,0.000000
143.010010,-0.169807,-155.727814,-0.001910,0.002635,0.066932,-0.755341,-0.038479,0.669325,-155.727814,0.065779,0.000000
143.360001,-0.049530,-155.727814,-0.001927,0.002607,0.066213,-0.220321,-0.011224,0.662127,-155.727814,0.065198,0.000000
143.600006,-0.001862,-155.772293,-0.001936,0.002607,0.066213,-0.008281,-0.000422,0.662127,-155.772293,0.066065,0.000000