File: Data/compression 33/AutoNoHeating-12-33-reverse-1-2_11152024_175257.csv
Time (sec),S:Load (lbs),S:HL1 (DIM),S:LVDT (in),S:Position (in),Ch:Position (mm),Ch:Load (N),Ch:Stress (MPa),Ch:Strain (mm/mm),Ch:HL1 (DIM),Set Point (),Cycles ()
0.110000,-0.107620,-674.019836,-0.011848,-0.006760,-0.171693,-0.478719,-0.024387,-1.716933,-674.019836,-0.171381,0.000000
0.490000,-0.046547,-674.019836,-0.011852,-0.006702,-0.170236,-0.207051,-0.010548,-1.702364,-674.019836,-0.169595,0.000000
0.870000,-0.067772,-674.019836,-0.011745,-0.006479,-0.164573,-0.301465,-0.015357,-1.645734,-674.019836,-0.163264,0.000000
1.250000,-0.063301,-674.108826,-0.011473,-0.006227,-0.158173,-0.281577,-0.014344,-1.581733,-674.108826,-0.156933,0.000000
1.630000,-0.059952,-674.108826,-0.011223,-0.005982,-0.151938,-0.266679,-0.013585,-1.519379,-674.108826,-0.150602,0.000000
2.010000,-0.072617,-674.064331,-0.010973,-0.005731,-0.145555,-0.323015,-0.016455,-1.455552,-674.064331,-0.144272,0.000000
2.390000,-0.107620,-674.064331,-0.010701,-0.005477,-0.139120,-0.478719,-0.024387,-1.391203,-674.064331,-0.137941,0.000000
2.770000,-0.126236,-674.064331,-0.010460,-0.005234,-0.132946,-0.561526,-0.028605,-1.329457,-674.064331,-0.131610,0.000000
3.150000,-0.088997,-674.153320,-0.010214,-0.004984,-0.126589,-0.395878,-0.020167,-1.265889,-674.153320,-0.125279,0.000000
3.530000,-0.082664,-674.064331,-0.009968,-0.004736,-0.120293,-0.367710,-0.018732,-1.202929,-674.064331,-0.118949,0.000000
3.910000,-0.085648,-674.108826,-0.009697,-0.004482,-0.113841,-0.380979,-0.019408,-1.138407,-674.108826,-0.112618,0.000000
4.290000,-0.103149,-674.019836,-0.009416,-0.004232,-0.107493,-0.458832,-0.023374,-1.074926,-674.019836,-0.106287,0.000000
4.670000,-0.150810,-674.108826,-0.009175,-0.003988,-0.101301,-0.670837,-0.034174,-1.013006,-674.108826,-0.099956,0.000000
5.050000,-0.049896,-674.108826,-0.008916,-0.003741,-0.095013,-0.221950,-0.011307,-0.950132,-674.108826,-0.093626,0.000000
5.430000,-0.051018,-674.153320,-0.008662,-0.003488,-0.088587,-0.226938,-0.011561,-0.885871,-674.153320,-0.087295,0.000000
5.810000,-0.032394,-674.197754,-0.008412,-0.003240,-0.082291,-0.144098,-0.007341,-0.822910,-674.197754,-0.080964,0.000000
6.190000,-0.074104,-674.197754,-0.008149,-0.002989,-0.075917,-0.329632,-0.016792,-0.759169,-674.197754,-0.074633,0.000000
6.570000,-0.077827,-674.197754,-0.007890,-0.002736,-0.069499,-0.346194,-0.017636,-0.694995,-674.197754,-0.068303,0.000000
6.950000,-0.089745,-674.242249,-0.007649,-0.002491,-0.063264,-0.399204,-0.020336,-0.632641,-674.242249,-0.061972,0.000000
7.330000,-0.050270,-674.197754,-0.007386,-0.002243,-0.056968,-0.223612,-0.011391,-0.569681,-674.197754,-0.055641,0.000000
7.710001,-0.019737,-674.286743,-0.007136,-0.001993,-0.050611,-0.087796,-0.004473,-0.506113,-674.286743,-0.049310,0.000000
8.090000,-0.044312,-674.197754,-0.006881,-0.001742,-0.044246,-0.197107,-0.010041,-0.442458,-674.197754,-0.042980,0.000000
8.470000,-0.050270,-674.197754,-0.006622,-0.001491,-0.037872,-0.223612,-0.011391,-0.378718,-674.197754,-0.036649,0.000000
8.850000,-0.063301,-674.242249,-0.006355,-0.001243,-0.031584,-0.281577,-0.014344,-0.315844,-674.242249,-0.030318,0.000000
9.230000,-0.015266,-674.286743,-0.006096,-0.000992,-0.025193,-0.067908,-0.003459,-0.251929,-674.286743,-0.023987,0.000000
9.610001,-0.019737,-674.286743,-0.005851,-0.000746,-0.018940,-0.087796,-0.004473,-0.189402,-674.286743,-0.017657,0.000000
9.990001,-0.035751,-674.331238,-0.005596,-0.000497,-0.012627,-0.159030,-0.008101,-0.126268,-674.331238,-0.011326,0.000000
10.370001,-0.035378,-674.286743,-0.005338,-0.000251,-0.006383,-0.157367,-0.008017,-0.063828,-674.286743,-0.004995,0.000000
10.750001,0.215599,-674.331238,-0.005088,0.000004,0.000113,0.959033,0.048855,0.001127,-674.331238,0.000286,0.000000
11.130000,0.057716,-674.420166,-0.005083,0.000002,0.000061,0.256735,0.013079,0.000607,-674.420166,0.000286,0.000000
11.510000,0.136284,-674.331238,-0.005079,0.000002,0.000061,0.606221,0.030882,0.000607,-674.331238,0.000702,0.000000
11.890000,0.174644,-674.331238,-0.005088,0.000014,0.000364,0.776857,0.039575,0.003642,-674.331238,0.001336,0.000000
12.270000,0.283745,-674.331238,-0.005070,0.000037,0.000928,1.262160,0.064297,0.009279,-674.331238,0.001969,0.000000
12.650001,0.446472,-674.375671,-0.005044,0.000062,0.001570,1.986007,0.101172,0.015697,-674.375671,0.002610,0.000000
13.030001,0.701546,-674.420166,-0.005014,0.000091,0.002307,3.120631,0.158973,0.023068,-674.420166,0.003243,0.000000
13.410001,0.892578,-674.420166,-0.004997,0.000116,0.002949,3.970386,0.202261,0.029486,-674.420166,0.003876,0.000000
13.790001,1.212814,-674.420166,-0.004980,0.000141,0.003582,5.394867,0.274828,0.035816,-674.420166,0.004510,0.000000
14.170001,1.469749,-674.375671,-0.004958,0.000161,0.004102,6.537772,0.333050,0.041020,-674.375671,0.005143,0.000000
14.550001,1.707329,-674.420166,-0.004911,0.000184,0.004674,7.594578,0.386886,0.046743,-674.420166,0.005776,0.000000
14.930000,2.125130,-674.420166,-0.004894,0.000212,0.005385,9.453049,0.481561,0.053855,-674.420166,0.006409,0.000000
15.310000,2.278549,-674.464661,-0.004876,0.000230,0.005845,10.135493,0.516327,0.058451,-674.464661,0.007042,0.000000
15.690001,2.544418,-674.420166,-0.004868,0.000250,0.006357,11.318138,0.576573,0.063568,-674.420166,0.007675,0.000000
16.070002,3.134628,-674.331238,-0.004838,0.000284,0.007224,13.943523,0.710317,0.072240,-674.331238,0.008308,0.000000
16.450001,3.422478,-674.420166,-0.004803,0.000306,0.007770,15.223941,0.775545,0.077703,-674.420166,0.008941,0.000000
16.830000,3.874908,-674.420166,-0.004786,0.000334,0.008490,17.236454,0.878067,0.084901,-674.420166,0.009574,0.000000
17.210001,4.142639,-674.509155,-0.004760,0.000357,0.009080,18.427380,0.938735,0.090798,-674.509155,0.010207,0.000000
17.590000,4.482994,-674.509155,-0.004756,0.000380,0.009661,19.941353,1.015861,0.096609,-674.509155,0.010840,0.000000
17.970001,5.034103,-674.420166,-0.004708,0.000408,0.010372,22.392811,1.140744,0.103720,-674.420166,0.011473,0.000000
18.350000,5.403122,-674.509155,-0.004695,0.000435,0.011040,24.034286,1.224365,0.110398,-674.509155,0.012106,0.000000
18.730001,5.465309,-674.509155,-0.004678,0.000451,0.011447,24.310909,1.238457,0.114474,-674.509155,0.012740,0.000000
19.110001,5.968010,-674.509155,-0.004669,0.000477,0.012106,26.547033,1.352370,0.121065,-674.509155,0.013373,0.000000
19.490002,6.111000,-674.598083,-0.004635,0.000501,0.012714,27.183086,1.384772,0.127135,-674.598083,0.014006,0.000000
19.870001,6.709404,-674.553650,-0.004622,0.000524,0.013312,29.844919,1.520373,0.133119,-674.553650,0.014639,0.000000
20.250002,7.288818,-674.509155,-0.004596,0.000558,0.014162,32.422283,1.651670,0.141618,-674.509155,0.015272,0.000000
20.630001,7.688004,-674.509155,-0.004562,0.000586,0.014882,34.197948,1.742127,0.148816,-674.509155,0.015905,0.000000
21.010000,8.005264,-674.553650,-0.004523,0.000612,0.015541,35.609196,1.814019,0.155407,-674.553650,0.016538,0.000000
21.390001,8.151978,-674.598083,-0.004518,0.000633,0.016078,36.261806,1.847265,0.160784,-674.598083,0.017171,0.000000
21.770000,8.504616,-674.598083,-0.004506,0.000654,0.016607,37.830421,1.927173,0.166074,-674.598083,0.017804,0.000000
22.150002,9.095200,-674.553650,-0.004467,0.000684,0.017379,40.457470,2.061002,0.173792,-674.553650,0.018437,0.000000
22.530001,9.316757,-674.642578,-0.004437,0.000706,0.017926,41.443005,2.111207,0.179255,-674.642578,0.019070,0.000000
22.910002,9.547256,-674.598083,-0.004406,0.000732,0.018593,42.468319,2.163439,0.185933,-674.598083,0.019703,0.000000
23.290001,9.660088,-674.642578,-0.004398,0.000755,0.019174,42.970215,2.189007,0.191743,-674.642578,0.020336,0.000000
23.670002,10.415260,-674.687073,-0.004381,0.000784,0.019903,46.329391,2.360132,0.199028,-674.687073,0.020978,0.000000
24.050001,10.752625,-674.598083,-0.004346,0.000812,0.020623,47.830063,2.436579,0.206226,-674.598083,0.021611,0.000000
24.430000,10.906044,-674.598083,-0.004320,0.000834,0.021178,48.512508,2.471345,0.211776,-674.598083,0.022244,0.000000
24.810001,11.268738,-674.731567,-0.004299,0.000858,0.021793,50.125851,2.553532,0.217934,-674.731567,0.022877,0.000000
25.190001,11.497368,-674.687073,-0.004273,0.000882,0.022392,51.142845,2.605341,0.223918,-674.687073,0.023510,0.000000
25.570002,11.929695,-674.731567,-0.004264,0.000908,0.023060,53.065933,2.703307,0.230595,-674.731567,0.024144,0.000000
25.950001,12.413780,-674.687073,-0.004234,0.000936,0.023771,55.219254,2.813003,0.237707,-674.687073,0.024777,0.000000
26.330002,12.467400,-674.642578,-0.004195,0.000956,0.024282,55.457764,2.825153,0.242823,-674.642578,0.025410,0.000000
26.710001,12.807747,-674.731567,-0.004178,0.000981,0.024915,56.971703,2.902277,0.249154,-674.731567,0.026043,0.000000
27.090002,12.826744,-674.776001,-0.004169,0.001004,0.025514,57.056206,2.906582,0.255138,-674.776001,0.026676,0.000000
27.470001,13.452324,-674.731567,-0.004152,0.001029,0.026147,59.838924,3.048340,0.261468,-674.731567,0.027309,0.000000
27.850000,13.783737,-674.687073,-0.004122,0.001061,0.026953,61.313126,3.123439,0.269534,-674.687073,0.027942,0.000000
28.230001,13.969925,-674.687073,-0.004092,0.001085,0.027569,62.141331,3.165630,0.275691,-674.687073,0.028575,0.000000
28.610001,14.608170,-674.731567,-0.004066,0.001114,0.028306,64.980385,3.310259,0.283062,-674.731567,0.029208,0.000000
28.990002,14.462570,-674.776001,-0.004036,0.001135,0.028818,64.332726,3.277265,0.288179,-674.776001,0.029841,0.000000
29.370001,14.743713,-674.820496,-0.004005,0.001158,0.029408,65.583313,3.340973,0.294076,-674.820496,0.030474,0.000000
29.750002,15.044960,-674.731567,-0.003988,0.001179,0.029954,66.923325,3.409237,0.299540,-674.731567,0.031107,0.000000
30.130001,15.536499,-674.776001,-0.003971,0.001209,0.030717,69.109802,3.520621,0.307171,-674.776001,0.031740,0.000000
30.510002,15.639267,-674.776001,-0.003932,0.001228,0.031194,69.566933,3.543909,0.311941,-674.776001,0.032374,0.000000
30.890001,15.718216,-674.820496,-0.003919,0.001255,0.031888,69.918114,3.561799,0.318879,-674.820496,0.033007,0.000000
31.270002,16.470032,-674.864990,-0.003915,0.001284,0.032616,73.262360,3.732163,0.326164,-674.864990,0.033640,0.000000
31.650002,16.194481,-674.820496,-0.003889,0.001303,0.033102,72.036652,3.669722,0.331020,-674.820496,0.034273,0.000000
32.030003,16.847244,-674.776001,-0.003867,0.001330,0.033778,74.940285,3.817640,0.337784,-674.776001,0.034906,0.000000
32.410000,17.261696,-674.820496,-0.003837,0.001360,0.034542,76.783859,3.911556,0.345416,-674.820496,0.035539,0.000000
32.790001,17.402451,-674.864990,-0.003786,0.001384,0.035157,77.409966,3.943452,0.351573,-674.864990,0.036172,0.000000
33.170002,17.558105,-674.909485,-0.003794,0.001406,0.035712,78.102356,3.978724,0.357124,-674.909485,0.036805,0.000000
33.550003,18.013145,-674.820496,-0.003768,0.001434,0.036415,80.126472,4.081837,0.364148,-674.820496,0.037438,0.000000
33.930000,18.180710,-674.909485,-0.003747,0.001456,0.036970,80.871834,4.119808,0.369698,-674.909485,0.038071,0.000000
34.310001,18.636871,-674.820496,-0.003717,0.001485,0.037724,82.900948,4.223176,0.377243,-674.820496,0.038704,0.000000
34.690002,19.035683,-674.864990,-0.003704,0.001511,0.038383,84.674942,4.313547,0.383834,-674.864990,0.039346,0.000000
35.070004,19.088554,-674.909485,-0.003660,0.001534,0.038964,84.910133,4.325528,0.389644,-674.909485,0.039979,0.000000
35.450001,19.392036,-674.909485,-0.003656,0.001559,0.039589,86.260086,4.394298,0.395888,-674.909485,0.040612,0.000000
35.830002,19.492950,-674.820496,-0.003604,0.001579,0.040118,86.708977,4.417166,0.401179,-674.820496,0.041245,0.000000
36.210003,19.670944,-674.909485,-0.003591,0.001601,0.040673,87.500732,4.457500,0.406729,-674.909485,0.041878,0.000000
36.590000,20.203064,-674.909485,-0.003557,0.001631,0.041436,89.867714,4.578080,0.414360,-674.909485,0.042511,0.000000
36.970001,20.234718,-674.953979,-0.003566,0.001648,0.041870,90.008522,4.585253,0.418697,-674.953979,0.043144,0.000000
37.350002,20.634277,-674.998413,-0.003544,0.001677,0.042607,91.785851,4.675794,0.426068,-674.998413,0.043778,0.000000
37.730003,21.511215,-674.909485,-0.003510,0.001706,0.043327,95.686661,4.874511,0.433266,-674.909485,0.044411,0.000000
38.110001,21.576752,-674.953979,-0.003471,0.001730,0.043934,95.978188,4.889362,0.439337,-674.953979,0.045044,0.000000
38.490002,21.821022,-674.953979,-0.003462,0.001756,0.044610,97.064751,4.944715,0.446101,-674.953979,0.045677,0.000000
38.870003,21.851562,-674.953979,-0.003428,0.001779,0.045182,97.200607,4.951635,0.451825,-674.953979,0.046310,0.000000
39.250000,22.462250,-675.087402,-0.003415,0.001806,0.045885,99.917076,5.090019,0.458849,-675.087402,0.046943,0.000000
39.630001,22.787331,-674.998413,-0.003393,0.001833,0.046561,101.363106,5.163683,0.465613,-674.998413,0.047576,0.000000
40.010002,22.481987,-674.998413,-0.003354,0.001849,0.046969,100.004875,5.094491,0.469689,-674.998413,0.048209,0.000000
40.390003,22.958252,-675.042908,-0.003350,0.001875,0.047628,102.123405,5.202414,0.476280,-675.042908,0.048842,0.000000
40.770000,22.922874,-674.998413,-0.003333,0.001895,0.048131,101.966042,5.194397,0.481310,-674.998413,0.049475,0.000000
41.150002,23.260620,-675.087402,-0.003307,0.001919,0.048747,103.468407,5.270932,0.487467,-675.087402,0.050108,0.000000
41.530003,24.456680,-675.042908,-0.003272,0.001956,0.049692,108.788750,5.541963,0.496920,-675.042908,0.050741,0.000000
41.910004,24.584030,-675.087402,-0.003247,0.001982,0.050334,109.355225,5.570821,0.503338,-675.087402,0.051374,0.000000
42.290001,24.687546,-675.087402,-0.003212,0.002006,0.050958,109.815689,5.594277,0.509582,-675.087402,0.052008,0.000000
42.670002,24.808571,-675.087402,-0.003199,0.002029,0.051539,110.354034,5.621703,0.515392,-675.087402,0.052641,0.000000
43.050003,24.049301,-675.087402,-0.003186,0.002047,0.051999,106.976631,5.449649,0.519988,-675.087402,0.053274,0.000000
43.430000,25.639336,-675.220825,-0.003169,0.002082,0.052892,114.049461,5.809957,0.528921,-675.220825,0.053907,0.000000
43.810001,25.722000,-675.087402,-0.003143,0.002104,0.053447,114.417168,5.828689,0.534471,-675.087402,0.054540,0.000000
44.190002,25.865364,-675.087402,-0.003113,0.002126,0.054011,115.054886,5.861175,0.540108,-675.087402,0.055173,0.000000
44.570004,25.643799,-675.176331,-0.003087,0.002146,0.054505,114.069313,5.810968,0.545051,-675.176331,0.055806,0.000000
44.950001,26.311462,-675.131897,-0.003065,0.002175,0.055234,117.039230,5.962263,0.552336,-675.131897,0.056439,0.000000
45.330002,27.062538,-675.131897,-0.003040,0.002207,0.056066,120.380180,6.132459,0.560661,-675.131897,0.057072,0.000000
45.710003,26.733360,-675.131897,-0.003040,0.002230,0.056630,118.915924,6.057866,0.566298,-675.131897,0.057714,0.000000
46.090004,27.547371,-675.131897,-0.003018,0.002255,0.057289,122.536827,6.242324,0.572889,-675.131897,0.058347,0.000000
46.470001,27.083023,-675.131897,-0.002979,0.002272,0.057714,120.471306,6.137101,0.577139,-675.131897,0.058980,0.000000
46.850002,27.596519,-675.220825,-0.002971,0.002305,0.058538,122.755447,6.253461,0.585377,-675.220825,0.059613,0.000000
47.230003,27.863510,-675.131897,-0.002923,0.002323,0.059006,123.943085,6.313962,0.590060,-675.131897,0.060246,0.000000
47.610001,28.486496,-675.176331,-0.002906,0.002354,0.059795,126.714264,6.455132,0.597952,-675.176331,0.060879,0.000000
47.990002,28.316689,-675.176331,-0.002893,0.002372,0.060246,125.958923,6.416653,0.602462,-675.176331,0.061512,0.000000
48.370003,28.916214,-675.131897,-0.002871,0.002400,0.060966,128.625748,6.552507,0.609660,-675.131897,0.062145,0.000000
48.750004,29.010796,-675.220825,-0.002859,0.002428,0.061668,129.046463,6.573940,0.616684,-675.220825,0.062778,0.000000
49.130001,29.673988,-675.265320,-0.002824,0.002456,0.062371,131.996490,6.724222,0.623709,-675.265320,0.063412,0.000000
49.510002,29.815491,-675.309814,-0.002807,0.002480,0.063004,132.625931,6.756287,0.630039,-675.309814,0.064045,0.000000
49.890003,30.102219,-675.176331,-0.002785,0.002505,0.063620,133.901352,6.821260,0.636197,-675.176331,0.064678,0.000000
50.270004,30.254517,-675.220825,-0.002755,0.002531,0.064296,134.578812,6.855772,0.642961,-675.220825,0.065311,0.000000
50.650002,29.729103,-675.265320,-0.002746,0.002551,0.064790,132.241653,6.736712,0.647904,-675.265320,0.065944,0.000000
51.030003,30.313354,-675.354309,-0.002708,0.002576,0.065432,134.840530,6.869104,0.654322,-675.354309,0.066577,0.000000
51.410004,30.629120,-675.354309,-0.002703,0.002601,0.066065,136.245132,6.940658,0.660652,-675.354309,0.067210,0.000000
51.790001,31.180977,-675.309814,-0.002673,0.002627,0.066716,138.699905,7.065711,0.667157,-675.309814,0.067843,0.000000
52.170002,31.004105,-675.309814,-0.002647,0.002652,0.067366,137.913147,7.025630,0.673661,-675.309814,0.068476,0.000000
52.550003,31.949928,-675.398743,-0.002630,0.002681,0.068086,142.120377,7.239957,0.680859,-675.398743,0.069109,0.000000
52.930004,31.138901,-675.398743,-0.002596,0.002699,0.068546,138.512741,7.056176,0.685455,-675.398743,0.069742,0.000000
53.310001,32.213196,-675.354309,-0.002583,0.002728,0.069300,143.291458,7.299615,0.693000,-675.354309,0.070375,0.000000
53.690002,32.661163,-675.398743,-0.002574,0.002756,0.069994,145.284103,7.401125,0.699938,-675.398743,0.071008,0.000000
54.070004,32.444069,-675.398743,-0.002531,0.002780,0.070610,144.318420,7.351931,0.706095,-675.398743,0.071642,0.000000
54.450001,32.148407,-675.398743,-0.002531,0.002800,0.071130,143.003250,7.284933,0.711299,-675.398743,0.072275,0.000000
54.830002,32.763565,-675.354309,-0.002492,0.002827,0.071798,145.739609,7.424330,0.717976,-675.354309,0.072908,0.000000
55.210003,32.341667,-675.398743,-0.002492,0.002844,0.072231,143.862915,7.328726,0.722312,-675.398743,0.073541,0.000000
55.590004,33.196259,-675.354309,-0.002466,0.002874,0.073012,147.664337,7.522380,0.730117,-675.354309,0.074174,0.000000
55.970001,33.845306,-675.398743,-0.002449,0.002907,0.073827,150.551437,7.669456,0.738269,-675.398743,0.074807,0.000000
56.350002,33.866531,-675.354309,-0.002414,0.002929,0.074408,150.645859,7.674266,0.744080,-675.354309,0.075449,0.000000
56.730003,34.107826,-675.443237,-0.002402,0.002954,0.075024,151.719193,7.728944,0.750237,-675.443237,0.076082,0.000000
57.110004,34.110435,-675.398743,-0.002397,0.002977,0.075622,151.730789,7.729535,0.756221,-675.398743,0.076715,0.000000
57.490002,33.841949,-675.487732,-0.002363,0.002996,0.076090,150.536514,7.668695,0.760904,-675.487732,0.077348,0.000000
57.870003,34.138733,-675.487732,-0.002345,0.003024,0.076819,151.856674,7.735947,0.768188,-675.487732,0.077981,0.000000
58.250004,34.218048,-675.487732,-0.002324,0.003042,0.077261,152.209473,7.753921,0.772611,-675.487732,0.078614,0.000000
58.630001,34.452271,-675.487732,-0.002315,0.003063,0.077799,153.251358,7.806996,0.777988,-675.487732,0.079247,0.000000
59.010002,36.095551,-675.532227,-0.002294,0.003102,0.078779,160.561035,8.179368,0.787788,-675.532227,0.079880,0.000000
59.390003,35.779404,-675.532227,-0.002272,0.003120,0.079247,159.154739,8.107729,0.792471,-675.532227,0.080513,0.000000
59.770004,36.068741,-675.398743,-0.002268,0.003154,0.080123,160.441772,8.173294,0.801230,-675.398743,0.081146,0.000000
60.150002,35.694878,-675.443237,-0.002220,0.003172,0.080565,158.778748,8.088574,0.805653,-675.443237,0.081779,0.000000
60.530003,36.062408,-675.532227,-0.002212,0.003199,0.081259,160.413605,8.171859,0.812590,-675.532227,0.082412,0.000000
60.910004,37.146385,-675.621155,-0.002182,0.003228,0.081979,165.235367,8.417491,0.819788,-675.621155,0.083046,0.000000
61.290005,36.830986,-675.576660,-0.002173,0.003248,0.082508,163.832413,8.346021,0.825078,-675.576660,0.083679,0.000000
61.670002,36.494362,-675.532227,-0.002151,0.003268,0.083002,162.335022,8.269740,0.830022,-675.532227,0.084312,0.000000
62.050003,36.898010,-675.532227,-0.002143,0.003293,0.083653,164.130554,8.361209,0.836526,-675.532227,0.084945,0.000000
62.430004,37.088295,-675.576660,-0.002108,0.003318,0.084268,164.976974,8.404327,0.842683,-675.576660,0.085578,0.000000
62.810001,38.133919,-675.576660,-0.002082,0.003354,0.085179,169.628143,8.641270,0.851789,-675.576660,0.086211,0.000000
63.190002,37.891129,-675.621155,-0.002074,0.003376,0.085751,168.548157,8.586253,0.857513,-675.621155,0.086844,0.000000
63.570004,38.344307,-675.621155,-0.002044,0.003401,0.086393,170.563995,8.688944,0.863930,-675.621155,0.087477,0.000000
63.950005,38.385643,-675.576660,-0.002026,0.003427,0.087035,170.747864,8.698311,0.870348,-675.576660,0.088110,0.000000
64.330002,38.522675,-675.576660,-0.001996,0.003450,0.087642,171.357422,8.729363,0.876418,-675.576660,0.088743,0.000000
64.710007,36.926689,-675.665649,-0.001988,0.003466,0.088041,164.258118,8.367707,0.880408,-675.665649,0.089376,0.000000
65.090004,39.582817,-675.754639,-0.001975,0.003503,0.088977,176.073166,8.969594,0.889774,-675.754639,0.090009,0.000000
65.470001,39.795074,-675.665649,-0.001957,0.003528,0.089602,177.017334,9.017693,0.896018,-675.665649,0.090642,0.000000
65.850006,39.513184,-675.665649,-0.001932,0.003547,0.090105,175.763412,8.953815,0.901047,-675.665649,0.091275,0.000000
66.230003,39.755974,-675.665649,-0.001923,0.003572,0.090720,176.843399,9.008833,0.907205,-675.665649,0.091909,0.000000
66.610001,40.566628,-675.710144,-0.001876,0.003603,0.091518,180.449371,9.192529,0.915183,-675.710144,0.092542,0.000000
66.990005,40.228882,-675.710144,-0.001863,0.003625,0.092073,178.947006,9.115995,0.920733,-675.710144,0.093175,0.000000
67.370003,40.801964,-675.754639,-0.001845,0.003644,0.092568,181.496201,9.245857,0.925677,-675.754639,0.093816,0.000000
67.750000,41.289406,-675.665649,-0.001828,0.003670,0.093227,183.664444,9.356314,0.932268,-675.665649,0.094450,0.000000
68.130005,41.612991,-675.710144,-0.001815,0.003694,0.093816,185.103836,9.429638,0.938165,-675.710144,0.095083,0.000000
68.510002,42.504829,-675.710144,-0.001789,0.003722,0.094545,189.070923,9.631732,0.945449,-675.710144,0.095716,0.000000
68.890007,43.032852,-675.754639,-0.001755,0.003749,0.095213,191.419693,9.751384,0.952127,-675.754639,0.096349,0.000000
69.270004,42.958374,-675.754639,-0.001742,0.003767,0.095681,191.088394,9.734507,0.956810,-675.754639,0.096982,0.000000
69.650002,43.794350,-675.754639,-0.001729,0.003794,0.096366,194.806992,9.923942,0.963661,-675.754639,0.097615,0.000000
70.030006,43.315857,-675.799072,-0.001716,0.003816,0.096930,192.678558,9.815514,0.969298,-675.799072,0.098248,0.000000
70.410004,45.680046,-675.754639,-0.001694,0.003851,0.097823,203.194992,10.351247,0.978231,-675.754639,0.098881,0.000000
70.790001,45.500938,-675.799072,-0.001673,0.003872,0.098361,202.398285,10.310659,0.983607,-675.799072,0.099514,0.000000
71.170006,45.814102,-675.799072,-0.001656,0.003900,0.099055,203.791306,10.381624,0.990545,-675.799072,0.100147,0.000000
71.550003,47.518074,-675.799072,-0.001613,0.003928,0.099783,211.370956,10.767750,0.997830,-675.799072,0.100780,0.000000
71.930000,47.198578,-675.799072,-0.001613,0.003943,0.100147,209.949753,10.695351,1.001472,-675.799072,0.101413,0.000000
72.310005,47.963058,-675.754639,-0.001587,0.003970,0.100841,213.350342,10.868585,1.008410,-675.754639,0.102046,0.000000
72.690002,49.252960,-675.888062,-0.001561,0.003996,0.101500,219.088104,11.160880,1.015001,-675.888062,0.102680,0.000000
73.070000,50.010368,-675.932556,-0.001548,0.004023,0.102194,222.457230,11.332512,1.021939,-675.932556,0.103313,0.000000
73.450005,50.686592,-675.843567,-0.001531,0.004043,0.102680,225.465225,11.485746,1.026795,-675.843567,0.103946,0.000000
73.830002,52.020805,-675.799072,-0.001500,0.004076,0.103529,231.400101,11.788082,1.035294,-675.799072,0.104579,0.000000
74.210007,51.744507,-675.799072,-0.001500,0.004083,0.103720,230.171066,11.725473,1.037202,-675.799072,0.105212,0.000000
74.590004,54.236420,-675.888062,-0.001475,0.004126,0.104804,241.255646,12.290149,1.048042,-675.888062,0.105845,0.000000
74.970001,55.328590,-675.976990,-0.001453,0.004152,0.105455,246.113861,12.537638,1.054546,-675.976990,0.106478,0.000000
75.350006,56.256912,-675.888062,-0.001444,0.004176,0.106062,250.243240,12.747998,1.060617,-675.888062,0.107111,0.000000
75.730003,56.872070,-675.932556,-0.001431,0.004196,0.106573,252.979599,12.887396,1.065734,-675.932556,0.107744,0.000000
76.110001,58.421143,-675.843567,-0.001406,0.004225,0.107319,259.870209,13.238420,1.073192,-675.843567,0.108377,0.000000
76.490005,58.871712,-675.932556,-0.001401,0.004242,0.107744,261.874451,13.340520,1.077441,-675.932556,0.109010,0.000000
76.870003,60.669151,-675.932556,-0.001380,0.004273,0.108533,269.869873,13.747826,1.085333,-675.932556,0.109643,0.000000
77.250000,62.059593,-675.976990,-0.001358,0.004300,0.109227,276.054871,14.062905,1.092271,-675.976990,0.110276,0.000000
77.630005,62.998344,-675.932556,-0.001337,0.004323,0.109808,280.230621,14.275629,1.098081,-675.932556,0.110909,0.000000
78.010002,64.772324,-675.932556,-0.001324,0.004352,0.110537,288.121674,14.677619,1.105366,-675.932556,0.111543,0.000000
78.390007,65.809006,-675.932556,-0.001315,0.004374,0.111092,292.733063,14.912534,1.110916,-675.932556,0.112184,0.000000
78.770004,65.580368,-675.976990,-0.001281,0.004374,0.111092,291.716034,14.860724,1.110916,-675.976990,0.019495,0.000000
79.150002,65.212479,-676.065979,-0.001302,0.004387,0.111421,290.079590,14.777359,1.114212,-676.065979,294.500458,0.000000
79.530006,65.084747,-676.021484,-0.001289,0.004393,0.111595,289.511414,14.748415,1.115946,-676.021484,294.500458,0.000000
79.910004,64.735092,-676.021484,-0.001281,0.004398,0.111699,287.956085,14.669181,1.116987,-676.021484,294.500458,0.000000
80.290001,65.333862,-675.976990,-0.001268,0.004409,0.111985,290.619537,14.804865,1.119848,-675.976990,294.500458,0.000000
80.670006,64.763016,-676.021484,-0.001268,0.004409,0.111985,288.080292,14.675508,1.119848,-676.021484,294.500458,0.000000
81.050003,65.655960,-676.065979,-0.001255,0.004417,0.112184,292.052307,14.877853,1.121843,-676.065979,294.500458,0.000000
81.430000,65.085861,-676.110474,-0.001246,0.004419,0.112236,289.516357,14.748668,1.122364,-676.110474,294.500458,0.000000
81.810005,64.863190,-676.021484,-0.001255,0.004425,0.112384,288.525879,14.698209,1.123838,-676.021484,294.500458,0.000000
82.190002,65.214706,-676.065979,-0.001237,0.004432,0.112566,290.089508,14.777864,1.125659,-676.065979,294.500458,0.000000
82.570007,64.871384,-676.110474,-0.001242,0.004432,0.112566,288.562317,14.700066,1.125659,-676.110474,294.500458,0.000000
82.950005,65.190125,-676.154907,-0.001229,0.004440,0.112774,289.980164,14.772293,1.127740,-676.154907,294.500458,0.000000
83.330002,64.997238,-676.110474,-0.001246,0.004440,0.112774,289.122162,14.728585,1.127740,-676.110474,294.500458,0.000000
83.710007,64.746628,-676.021484,-0.001237,0.004440,0.112783,288.007385,14.671796,1.127827,-676.021484,294.500458,0.000000
84.090004,65.339828,-676.065979,-0.001216,0.004451,0.113052,290.646088,14.806217,1.130515,-676.065979,294.500458,0.000000
84.470001,65.314133,-676.110474,-0.001220,0.004451,0.113052,290.531769,14.800394,1.130515,-676.110474,294.500458,0.000000
84.850006,65.096664,-676.199402,-0.001229,0.004451,0.113052,289.564423,14.751115,1.130515,-676.199402,294.500458,0.000000
85.230003,64.932816,-676.243896,-0.001224,0.004451,0.113052,288.835602,14.713986,1.130515,-676.243896,294.500458,0.000000
85.610001,64.734344,-676.199402,-0.001233,0.004451,0.113060,287.952759,14.669012,1.130602,-676.199402,294.500458,0.000000
85.990005,65.479828,-676.110474,-0.001224,0.004461,0.113303,291.268829,14.837941,1.133030,-676.110474,294.500458,0.000000
86.370003,65.318604,-676.154907,-0.001220,0.004461,0.113303,290.551666,14.801407,1.133030,-676.154907,294.500458,0.000000
86.750008,65.198318,-676.288391,-0.001220,0.004461,0.113303,290.016602,14.774151,1.133030,-676.288391,294.500458,0.000000
87.130005,65.014374,-676.243896,-0.001207,0.004461,0.113312,289.198364,14.732468,1.133117,-676.243896,294.500458,0.000000
87.510002,64.890747,-676.199402,-0.001216,0.004461,0.113312,288.648468,14.704453,1.133117,-676.199402,294.500458,0.000000
87.890007,64.749237,-676.199402,-0.001220,0.004461,0.113320,288.018982,14.672387,1.133204,-676.199402,294.500458,0.000000
88.270004,64.671036,-676.199402,-0.001224,0.004462,0.113346,287.671143,14.654666,1.133464,-676.199402,294.500458,0.000000
88.650002,66.090530,-676.199402,-0.001207,0.004473,0.113615,293.985352,14.976328,1.136152,-676.199402,294.500458,0.000000
89.030006,65.823914,-676.288391,-0.001207,0.004470,0.113529,292.799377,14.915913,1.135285,-676.288391,294.500458,0.000000
89.410004,65.659683,-676.288391,-0.001194,0.004470,0.113529,292.068848,14.878696,1.135285,-676.288391,294.500458,0.000000
89.790001,65.526749,-676.288391,-0.001199,0.004470,0.113529,291.477539,14.848574,1.135285,-676.288391,294.500458,0.000000
90.170006,65.370361,-676.288391,-0.001212,0.004470,0.113529,290.781891,14.813136,1.135285,-676.288391,294.500458,0.000000
90.550003,65.272430,-676.199402,-0.001203,0.004470,0.113529,290.346283,14.790944,1.135285,-676.199402,294.500458,0.000000
90.930008,65.144699,-676.288391,-0.001212,0.004470,0.113529,289.778107,14.762000,1.135285,-676.288391,294.500458,0.000000
91.310005,65.032608,-676.377319,-0.001199,0.004470,0.113529,289.279480,14.736600,1.135285,-676.377319,294.500458,0.000000
91.690002,64.912338,-676.332886,-0.001199,0.004470,0.113529,288.744507,14.709346,1.135285,-676.332886,294.500458,0.000000
92.070007,64.796524,-676.288391,-0.001199,0.004470,0.113537,288.229340,14.683103,1.135372,-676.288391,294.500458,0.000000
92.450005,64.707535,-676.288391,-0.001207,0.004470,0.113537,287.833496,14.662937,1.135372,-676.288391,294.500458,0.000000
92.830002,64.616302,-676.377319,-0.001181,0.004470,0.113537,287.427673,14.642263,1.135372,-676.377319,294.500458,0.000000
93.210007,66.395126,-676.377319,-0.001186,0.004467,0.113450,295.340271,15.045351,1.134505,-676.377319,294.500458,0.000000
93.590004,66.267395,-676.466309,-0.001190,0.004467,0.113450,294.772095,15.016406,1.134505,-676.466309,294.500458,0.000000
93.970001,66.159042,-676.332886,-0.001194,0.004467,0.113450,294.290131,14.991854,1.134505,-676.332886,294.500458,0.000000
94.350006,66.068176,-676.332886,-0.001177,0.004467,0.113450,293.885925,14.971263,1.134505,-676.332886,294.500458,0.000000
94.730003,65.916260,-676.377319,-0.001186,0.004467,0.113450,293.210175,14.936838,1.134505,-676.377319,294.500458,0.000000
95.110008,65.856674,-676.421814,-0.001186,0.004467,0.113450,292.945129,14.923336,1.134505,-676.421814,294.500458,0.000000
95.490005,65.778854,-676.421814,-0.001190,0.004467,0.113450,292.598969,14.905701,1.134505,-676.421814,294.500458,0.000000
95.870003,65.665649,-676.421814,-0.001186,0.004467,0.113450,292.095398,14.880049,1.134505,-676.421814,294.500458,0.000000
96.250008,65.590805,-676.421814,-0.001186,0.004467,0.113450,291.762482,14.863089,1.134505,-676.421814,294.500458,0.000000
96.630005,65.538300,-676.421814,-0.001186,0.004467,0.113450,291.528931,14.851191,1.134505,-676.421814,294.500458,0.000000
97.010002,65.465683,-676.555237,-0.001181,0.004467,0.113450,291.205902,14.834736,1.134505,-676.555237,294.500458,0.000000
97.390007,65.351364,-676.510803,-0.001190,0.004467,0.113459,290.697388,14.808831,1.134591,-676.510803,294.500458,0.000000
97.770004,65.289185,-676.466309,-0.001190,0.004467,0.113459,290.420807,14.794741,1.134591,-676.466309,294.500458,0.000000
98.150002,65.224014,-676.510803,-0.001181,0.004467,0.113468,290.130920,14.779973,1.134678,-676.510803,294.500458,0.000000
98.530006,65.187897,-676.466309,-0.001181,0.004479,0.113771,289.970245,14.771788,1.137713,-676.466309,294.500458,0.000000
98.910004,65.087723,-676.599731,-0.001177,0.004479,0.113771,289.524658,14.749088,1.137713,-676.599731,294.500458,0.000000
99.290001,65.150650,-676.510803,-0.001186,0.004486,0.113945,289.804565,14.763348,1.139448,-676.510803,294.500458,0.000000
99.670006,65.094055,-676.599731,-0.001181,0.004486,0.113945,289.552826,14.750524,1.139448,-676.599731,294.500458,0.000000
100.050003,65.270935,-676.510803,-0.001177,0.004492,0.114101,290.339630,14.790605,1.141009,-676.510803,294.500458,0.000000
100.430008,65.359558,-676.466309,-0.001186,0.004491,0.114084,290.733826,14.810687,1.140835,-676.466309,294.500458,0.000000
100.810005,65.330521,-676.599731,-0.001177,0.004491,0.114084,290.604675,14.804107,1.140835,-676.599731,294.500458,0.000000
101.190002,65.302963,-676.599731,-0.001177,0.004491,0.114084,290.482086,14.797863,1.140835,-676.599731,294.500458,0.000000
101.570007,65.279129,-676.599731,-0.001190,0.004491,0.114084,290.376068,14.792462,1.140835,-676.599731,294.500458,0.000000
101.950005,65.231461,-676.599731,-0.001181,0.004491,0.114084,290.164032,14.781660,1.140835,-676.599731,294.500458,0.000000
102.330002,65.193481,-676.555237,-0.001168,0.004491,0.114084,289.995087,14.773054,1.140835,-676.555237,294.500458,0.000000
102.710007,65.123474,-676.555237,-0.001181,0.004491,0.114084,289.683685,14.757190,1.140835,-676.555237,294.500458,0.000000
103.090004,65.087723,-676.599731,-0.001190,0.004491,0.114084,289.524658,14.749088,1.140835,-676.599731,294.500458,0.000000
103.470001,65.044159,-676.599731,-0.001173,0.004491,0.114084,289.330872,14.739217,1.140835,-676.599731,294.500458,0.000000
103.850006,65.011765,-676.599731,-0.001168,0.004492,0.114092,289.186768,14.731876,1.140922,-676.599731,294.500458,0.000000
104.230003,64.974899,-676.555237,-0.001173,0.004492,0.114092,289.022797,14.723523,1.140922,-676.555237,294.500458,0.000000
104.610008,64.952179,-676.599731,-0.001173,0.004492,0.114092,288.921722,14.718374,1.140922,-676.599731,294.500458,0.000000
104.990005,64.898560,-676.599731,-0.001173,0.004492,0.114092,288.683197,14.706223,1.140922,-676.599731,294.500458,0.000000
105.370003,64.857224,-676.688721,-0.001194,0.004493,0.114110,288.499329,14.696856,1.141095,-676.688721,294.500458,0.000000
105.750008,64.896332,-676.688721,-0.001181,0.004501,0.114318,288.673309,14.705719,1.143177,-676.688721,294.500458,0.000000
106.130005,65.610168,-676.599731,-0.001186,0.004502,0.114361,291.848602,14.867476,1.143610,-676.599731,294.500458,0.000000
106.510002,65.612396,-676.644226,-0.001186,0.004502,0.114361,291.858521,14.867981,1.143610,-676.644226,294.500458,0.000000
106.890007,65.607559,-676.644226,-0.001181,0.004502,0.114361,291.837006,14.866885,1.143610,-676.644226,294.500458,0.000000
107.270004,65.586700,-676.733215,-0.001173,0.004502,0.114361,291.744202,14.862159,1.143610,-676.733215,294.500458,0.000000
107.650002,65.585968,-676.777649,-0.001177,0.004502,0.114361,291.740967,14.861993,1.143610,-676.777649,294.500458,0.000000
108.030006,65.563614,-676.688721,-0.001177,0.004502,0.114361,291.641510,14.856928,1.143610,-676.688721,294.500458,0.000000
108.410004,65.542023,-676.688721,-0.001173,0.004502,0.114361,291.545471,14.852035,1.143610,-676.688721,294.500458,0.000000
108.790009,65.506653,-676.733215,-0.001168,0.004502,0.114361,291.388153,14.844020,1.143610,-676.733215,294.500458,0.000000
109.170006,65.479095,-676.822144,-0.001181,0.004502,0.114361,291.265564,14.837775,1.143610,-676.822144,294.500458,0.000000
109.550003,65.425842,-676.822144,-0.001177,0.004502,0.114361,291.028687,14.825707,1.143610,-676.822144,294.500458,0.000000
109.930008,65.403122,-676.733215,-0.001186,0.004503,0.114370,290.927612,14.820560,1.143697,-676.733215,294.500458,0.000000
110.310005,65.368118,-676.822144,-0.001186,0.004503,0.114370,290.771912,14.812628,1.143697,-676.822144,294.500458,0.000000
110.690002,65.331635,-676.733215,-0.001160,0.004503,0.114370,290.609619,14.804359,1.143697,-676.733215,294.500458,0.000000
111.070007,65.309296,-676.822144,-0.001177,0.004503,0.114370,290.510254,14.799298,1.143697,-676.822144,294.500458,0.000000
111.450005,65.260880,-676.822144,-0.001168,0.004503,0.114370,290.294891,14.788326,1.143697,-676.822144,294.500458,0.000000
111.830002,65.236298,-676.822144,-0.001168,0.004503,0.114370,290.185547,14.782756,1.143697,-676.822144,294.500458,0.000000
112.210007,65.206512,-676.866638,-0.001177,0.004503,0.114370,290.053040,14.776007,1.143697,-676.866638,294.500458,0.000000
112.590004,65.193481,-676.822144,-0.001168,0.004503,0.114378,289.995087,14.773054,1.143784,-676.822144,294.500458,0.000000
112.970009,65.149918,-676.866638,-0.001168,0.004503,0.114378,289.801300,14.763183,1.143784,-676.866638,294.500458,0.000000
113.350006,65.164062,-676.822144,-0.001147,0.004503,0.114387,289.864227,14.766387,1.143871,-676.822144,294.500458,0.000000
113.730003,65.089584,-676.866638,-0.001164,0.004503,0.114387,289.532928,14.749511,1.143871,-676.866638,294.500458,0.000000
114.110008,65.085861,-676.866638,-0.001164,0.004503,0.114387,289.516357,14.748668,1.143871,-676.866638,294.500458,0.000000
114.490005,65.056442,-676.866638,-0.001155,0.004503,0.114387,289.385498,14.742001,1.143871,-676.866638,294.500458,0.000000
114.870003,65.012878,-676.866638,-0.001164,0.004504,0.114396,289.191711,14.732129,1.143957,-676.866638,294.500458,0.000000
115.250008,65.013626,-676.866638,-0.001155,0.004504,0.114396,289.195038,14.732298,1.143957,-676.866638,294.500458,0.000000
115.630005,64.984207,-677.000061,-0.001138,0.004504,0.114396,289.064178,14.725632,1.143957,-677.000061,294.500458,0.000000
116.010002,64.968201,-676.911133,-0.001151,0.004504,0.114396,288.992981,14.722005,1.143957,-676.911133,294.500458,0.000000
116.390007,64.947342,-676.911133,-0.001138,0.004504,0.114396,288.900208,14.717278,1.143957,-676.911133,294.500458,0.000000
116.770004,64.962982,-676.955566,-0.001233,0.004504,0.114396,288.969788,14.720822,1.143957,-676.955566,294.500458,0.000000
117.150009,64.898941,-677.000061,-0.001155,0.004504,0.114396,288.684906,14.706310,1.143957,-677.000061,294.500458,0.000000
117.530006,64.858337,-677.044556,-0.001164,0.004504,0.114396,288.504303,14.697109,1.143957,-677.044556,294.500458,0.000000
117.910004,65.760971,-677.000061,-0.001151,0.004515,0.114673,292.519409,14.901649,1.146733,-677.000061,294.500458,0.000000
118.290009,65.776993,-677.000061,-0.001143,0.004515,0.114673,292.590668,14.905280,1.146733,-677.000061,294.500458,0.000000
118.670006,65.784439,-677.000061,-0.001143,0.004515,0.114673,292.623810,14.906966,1.146733,-677.000061,294.500458,0.000000
119.050003,65.814972,-677.089050,-0.001155,0.004515,0.114673,292.759613,14.913886,1.146733,-677.089050,294.500458,0.000000
119.430008,65.794495,-677.089050,-0.001181,0.004515,0.114673,292.668518,14.909245,1.146733,-677.089050,294.500458,0.000000
119.810005,65.772522,-677.044556,-0.001151,0.004515,0.114673,292.570801,14.904266,1.146733,-677.044556,294.500458,0.000000
120.190002,65.760239,-677.044556,-0.001151,0.004515,0.114673,292.516144,14.901484,1.146733,-677.044556,294.500458,0.000000
120.570007,65.764328,-677.000061,-0.001134,0.004515,0.114673,292.534332,14.902411,1.146733,-677.000061,294.500458,0.000000
120.950005,65.740875,-677.089050,-0.001151,0.004515,0.114673,292.430023,14.897096,1.146733,-677.089050,294.500458,0.000000
121.330009,65.680908,-677.044556,-0.001130,0.004515,0.114673,292.163269,14.883507,1.146733,-677.044556,294.500458,0.000000
121.710007,65.768799,-677.089050,-0.001186,0.004515,0.114673,292.554230,14.903423,1.146733,-677.089050,294.500458,0.000000
122.090004,65.659683,-677.044556,-0.001151,0.004515,0.114673,292.068848,14.878696,1.146733,-677.044556,294.500458,0.000000
122.470009,65.620956,-677.044556,-0.001155,0.004515,0.114673,291.896606,14.869922,1.146733,-677.044556,294.500458,0.000000
122.850006,65.605698,-677.089050,-0.001143,0.004515,0.114673,291.828705,14.866464,1.146733,-677.089050,294.500458,0.000000
123.230003,65.593414,-677.089050,-0.001147,0.004515,0.114673,291.774078,14.863680,1.146733,-677.089050,294.500458,0.000000
123.610008,65.581116,-677.133545,-0.001151,0.004515,0.114673,291.719360,14.860893,1.146733,-677.133545,294.500458,0.000000
123.990005,65.556168,-677.089050,-0.001147,0.004515,0.114673,291.608398,14.855240,1.146733,-677.089050,294.500458,0.000000
124.370003,65.571442,-677.089050,-0.001173,0.004515,0.114673,291.676331,14.858701,1.146733,-677.089050,294.500458,0.000000
124.750008,65.520050,-677.089050,-0.001125,0.004515,0.114673,291.447723,14.847055,1.146733,-677.089050,294.500458,0.000000
125.130005,65.502914,-677.133545,-0.001138,0.004515,0.114673,291.371521,14.843173,1.146733,-677.133545,294.500458,0.000000
125.510010,65.497330,-677.222473,-0.001147,0.004515,0.114673,291.346680,14.841908,1.146733,-677.222473,294.500458,0.000000
125.890007,65.470901,-677.133545,-0.001155,0.004515,0.114673,291.229126,14.835918,1.146733,-677.133545,294.500458,0.000000
126.270004,65.437759,-677.177979,-0.001147,0.004515,0.114673,291.081696,14.828408,1.146733,-677.177979,294.500458,0.000000
126.650009,65.387115,-677.177979,-0.001147,0.004515,0.114673,290.856415,14.816933,1.146733,-677.177979,294.500458,0.000000
127.030006,65.388229,-677.266968,-0.001121,0.004515,0.114673,290.861359,14.817184,1.146733,-677.266968,294.500458,0.000000
127.410004,65.373703,-677.222473,-0.001164,0.004515,0.114673,290.796753,14.813893,1.146733,-677.222473,294.500458,0.000000
127.790009,65.367004,-677.222473,-0.001155,0.004515,0.114673,290.766968,14.812375,1.146733,-677.222473,294.500458,0.000000
128.170013,65.330521,-677.222473,-0.001143,0.004515,0.114673,290.604675,14.804107,1.146733,-677.222473,294.500458,0.000000
128.550003,65.303696,-677.222473,-0.001143,0.004515,0.114673,290.485352,14.798029,1.146733,-677.222473,294.500458,0.000000
128.930008,65.297379,-677.177979,-0.001138,0.004515,0.114673,290.457245,14.796597,1.146733,-677.177979,294.500458,0.000000
129.310013,65.278748,-677.266968,-0.001147,0.004515,0.114673,290.374359,14.792376,1.146733,-677.266968,294.500458,0.000000
129.690002,65.272430,-677.266968,-0.001151,0.004515,0.114673,290.346283,14.790944,1.146733,-677.266968,294.500458,0.000000
130.070007,65.233704,-677.311462,-0.001164,0.004515,0.114673,290.174011,14.782168,1.146733,-677.311462,294.500458,0.000000
130.450012,65.226990,-677.266968,-0.001138,0.004515,0.114673,290.144135,14.780647,1.146733,-677.266968,294.500458,0.000000
130.830002,65.210983,-677.311462,-0.001112,0.004515,0.114673,290.072937,14.777020,1.146733,-677.311462,294.500458,0.000000
131.210007,65.196091,-677.355896,-0.001138,0.004515,0.114673,290.006683,14.773645,1.146733,-677.355896,294.500458,0.000000
131.590012,65.171143,-677.355896,-0.001138,0.004515,0.114673,289.895721,14.767992,1.146733,-677.355896,294.500458,0.000000
131.970001,65.158112,-677.266968,-0.001130,0.004515,0.114673,289.837769,14.765039,1.146733,-677.266968,294.500458,0.000000
132.350006,65.126083,-677.266968,-0.001155,0.004515,0.114673,289.695282,14.757781,1.146733,-677.266968,294.500458,0.000000
132.730011,65.104858,-677.355896,-0.001134,0.004515,0.114673,289.600861,14.752973,1.146733,-677.355896,294.500458,0.000000
133.110001,65.088104,-677.400391,-0.001147,0.004515,0.114673,289.526337,14.749176,1.146733,-677.400391,294.500458,0.000000
133.490005,65.050110,-677.355896,-0.001147,0.004515,0.114673,289.357330,14.740566,1.146733,-677.355896,294.500458,0.000000
133.870010,65.051605,-677.355896,-0.001151,0.004515,0.114673,289.363983,14.740905,1.146733,-677.355896,294.500458,0.000000
134.250000,65.022568,-677.355896,-0.001151,0.004515,0.114673,289.234833,14.734324,1.146733,-677.355896,294.500458,0.000000
134.630005,65.012131,-677.400391,-0.001125,0.004515,0.114673,289.188416,14.731959,1.146733,-677.400391,294.500458,0.000000
135.010010,65.003204,-677.400391,-0.001143,0.004515,0.114673,289.148682,14.729937,1.146733,-677.400391,294.500458,0.000000
135.389999,64.989044,-677.444885,-0.001147,0.004515,0.114673,289.085693,14.726727,1.146733,-677.444885,294.500458,0.000000
135.770004,64.976013,-677.400391,-0.001147,0.004515,0.114673,289.027740,14.723775,1.146733,-677.400391,294.500458,0.000000
136.150009,64.949203,-677.444885,-0.001151,0.004515,0.114673,288.908478,14.717700,1.146733,-677.444885,294.500458,0.000000
136.530014,64.937286,-677.444885,-0.001147,0.004515,0.114673,288.855469,14.714999,1.146733,-677.444885,294.500458,0.000000
136.910004,64.913834,-677.444885,-0.001138,0.004515,0.114673,288.751160,14.709685,1.146733,-677.444885,294.500458,0.000000
137.290009,64.903030,-677.489380,-0.001134,0.004515,0.114673,288.703094,14.707237,1.146733,-677.489380,294.500458,0.000000
137.670013,64.882553,-677.533875,-0.001151,0.004515,0.114673,288.612000,14.702597,1.146733,-677.533875,294.500458,0.000000
138.050003,64.876587,-677.489380,-0.001147,0.004515,0.114673,288.585480,14.701244,1.146733,-677.489380,294.500458,0.000000
138.430008,64.841583,-677.444885,-0.001138,0.004515,0.114673,288.429779,14.693313,1.146733,-677.444885,294.500458,0.000000
138.810013,64.833023,-677.489380,-0.001138,0.004515,0.114673,288.391693,14.691374,1.146733,-677.489380,294.500458,0.000000
139.190002,64.804352,-677.578308,-0.001155,0.004515,0.114673,288.264160,14.684876,1.146733,-677.578308,1681.640747,0.000000
139.570007,64.694122,-677.533875,-0.001130,0.004507,0.114465,287.773834,14.659898,1.144651,-677.533875,0.114266,0.000000
139.950012,64.694504,-677.533875,-0.001155,0.004486,0.113936,287.775513,14.659984,1.139361,-677.533875,0.113633,0.000000
140.330002,64.626724,-677.533875,-0.001138,0.004467,0.113459,287.474030,14.644625,1.134591,-677.533875,0.113000,0.000000
140.710007,64.599167,-677.578308,-0.001138,0.004444,0.112887,287.351440,14.638380,1.128868,-677.578308,0.112366,0.000000
141.090012,64.589127,-677.578308,-0.001138,0.004421,0.112306,287.306793,14.636105,1.123057,-677.578308,0.111733,0.000000
141.470001,64.550766,-677.578308,-0.001138,0.004394,0.111603,287.136139,14.627413,1.116033,-677.578308,0.111100,0.000000
141.850006,64.558960,-677.578308,-0.001151,0.004371,0.111022,287.172607,14.629270,1.110222,-677.578308,0.110467,0.000000
142.230011,64.563049,-677.578308,-0.001138,0.004349,0.110459,287.190796,14.630196,1.104585,-677.578308,0.109834,0.000000
142.610001,64.487457,-677.622803,-0.001134,0.004325,0.109851,286.854523,14.613067,1.098515,-677.622803,0.109192,0.000000
142.990005,64.448364,-677.667297,-0.001125,0.004301,0.109244,286.680634,14.604208,1.092444,-677.667297,0.108559,0.000000
143.370010,64.239838,-677.667297,-0.001138,0.004275,0.108585,285.753082,14.556955,1.085853,-677.667297,0.107926,0.000000
143.750000,63.760223,-677.667297,-0.001143,0.004256,0.108091,283.619629,14.448274,1.080910,-677.667297,0.107293,0.000000
144.130005,62.804710,-677.667297,-0.001147,0.004231,0.107475,279.369293,14.231750,1.074753,-677.667297,0.106660,0.000000
144.510010,61.493217,-677.667297,-0.001130,0.004202,0.106738,273.535492,13.934563,1.067381,-677.667297,0.106027,0.000000
144.889999,60.425621,-677.667297,-0.001143,0.004184,0.106270,268.786591,13.692642,1.062698,-677.667297,0.105394,0.000000
145.270004,58.616264,-677.667297,-0.001143,0.004157,0.105585,260.738159,13.282636,1.055847,-677.667297,0.104761,0.000000
145.650009,56.689240,-677.711792,-0.001138,0.004133,0.104986,252.166336,12.845965,1.049863,-677.711792,0.104128,0.000000
146.030014,55.169960,-677.711792,-0.001138,0.004114,0.104501,245.408234,12.501692,1.045007,-677.711792,0.103495,0.000000
146.410004,52.752144,-677.667297,-0.001134,0.004089,0.103868,234.653259,11.953806,1.038676,-677.667297,0.102862,0.000000
146.790009,50.511581,-677.711792,-0.001143,0.004065,0.103252,224.686737,11.446088,1.032519,-677.711792,0.102229,0.000000
147.170013,47.566116,-677.800720,-0.001143,0.004040,0.102619,211.584656,10.778636,1.026188,-677.800720,0.101595,0.000000
147.550003,44.594582,-677.756226,-0.001160,0.004012,0.101916,198.366608,10.105276,1.019164,-677.756226,0.100962,0.000000
147.930008,42.405777,-677.711792,-0.001160,0.003990,0.101353,188.630310,9.609286,1.013527,-677.711792,0.100329,0.000000
148.310013,39.258484,-677.711792,-0.001151,0.003964,0.100676,174.630463,8.896100,1.006762,-677.711792,0.099696,0.000000
148.690002,36.701775,-677.756226,-0.001164,0.003941,0.100104,163.257645,8.316741,1.001038,-677.756226,0.099063,0.000000
149.070007,35.061470,-677.800720,-0.001168,0.003924,0.099662,155.961212,7.945043,0.996616,-677.800720,0.098430,0.000000
149.450012,31.108742,-677.800720,-0.001173,0.003889,0.098777,138.378601,7.049341,0.987770,-677.800720,0.097797,0.000000
149.830002,28.945251,-677.845215,-0.001181,0.003869,0.098274,128.754913,6.559088,0.982740,-677.845215,0.097164,0.000000
150.210007,26.442543,-677.845215,-0.001181,0.003844,0.097641,117.622307,5.991966,0.976409,-677.845215,0.096531,0.000000
150.590012,23.285942,-677.756226,-0.001190,0.003818,0.096973,103.581047,5.276670,0.969732,-677.756226,0.095898,0.000000
150.970001,21.163788,-677.800720,-0.001186,0.003796,0.096409,94.141228,4.795783,0.964095,-677.800720,0.095265,0.000000
151.350006,17.650826,-677.889709,-0.001181,0.003765,0.095620,78.514793,3.999734,0.956203,-677.889709,0.094632,0.000000
151.730011,15.317543,-677.845215,-0.001212,0.003744,0.095091,68.135834,3.471005,0.950913,-677.845215,0.093999,0.000000
152.110001,12.124077,-677.756226,-0.001207,0.003715,0.094354,53.930588,2.747355,0.943542,-677.756226,0.093366,0.000000
152.490005,9.664185,-677.845215,-0.001199,0.003690,0.093721,42.988441,2.189935,0.937211,-677.845215,0.092732,0.000000
152.870010,6.657646,-677.889709,-0.001212,0.003662,0.093027,29.614689,1.508644,0.930273,-677.889709,0.092099,0.000000
153.250000,3.939697,-677.934204,-0.001224,0.003637,0.092386,17.524649,0.892748,0.923855,-677.934204,0.091466,0.000000
153.630005,1.628387,-677.934204,-0.001233,0.003616,0.091857,7.243429,0.368998,0.918565,-677.934204,0.090825,0.000000
154.010010,-1.253780,-677.889709,-0.001250,0.003586,0.091093,-5.577094,-0.284111,0.910934,-677.889709,0.090191,0.000000
154.390015,-1.233669,-677.934204,-0.001250,0.003564,0.090530,-5.487635,-0.279553,0.905297,-677.934204,0.089558,0.000000
154.770004,-0.041710,-677.978638,-0.001263,0.003547,0.090105,-0.185535,-0.009452,0.901047,-677.978638,0.088925,0.000000
155.150009,-0.130707,-677.934204,-0.001302,0.003508,0.089099,-0.581413,-0.029619,0.890988,-677.934204,0.088292,0.000000
155.530014,-0.062561,-677.978638,-0.001319,0.003489,0.088613,-0.278285,-0.014177,0.886131,-677.978638,0.087659,0.000000
155.910004,-0.037613,-677.978638,-0.001324,0.003462,0.087937,-0.167311,-0.008523,0.879367,-677.978638,0.087026,0.000000
156.290009,-0.029419,-677.978638,-0.001362,0.003453,0.087711,-0.130862,-0.006666,0.877112,-677.978638,0.087564,0.000000
156.300003,0.001862,-677.934204,-0.001350,0.003453,0.087711,0.008281,0.000422,0.877112,-677.934204,0.087564,0.000000