File: Data/compression 26/AutoNoHeating-17-26-reverse-1-4_09262024_173709.csv
Time (sec),S:Load (lbs),S:HL1 (DIM),S:LVDT (in),S:Position (in),Ch:Position (mm),Ch:Load (N),Ch:Stress (MPa),Ch:Strain (mm/mm),Ch:HL1 (DIM),Set Point (),Cycles ()
0.110000,-0.212250,-30.291527,-0.013435,-0.009015,-0.228973,-0.944134,-0.048096,-2.289733,-30.291527,-0.229016,0.000000
0.480000,-0.255447,-30.336008,-0.013422,-0.008946,-0.227230,-1.136287,-0.057885,-2.272300,-30.336008,-0.226519,0.000000
0.850000,-0.232727,-30.336008,-0.013331,-0.008721,-0.221524,-1.035222,-0.052737,-2.215239,-30.336008,-0.220362,0.000000
1.220000,-0.203316,-30.424971,-0.013064,-0.008485,-0.215532,-0.904394,-0.046072,-2.155316,-30.424971,-0.214187,0.000000
1.590000,-0.165329,-30.336008,-0.012797,-0.008241,-0.209313,-0.735420,-0.037464,-2.093130,-30.336008,-0.208030,0.000000
1.960000,-0.198471,-30.424971,-0.012564,-0.007997,-0.203130,-0.882843,-0.044974,-2.031300,-30.424971,-0.201873,0.000000
2.330000,-0.217461,-30.380489,-0.012348,-0.007761,-0.197129,-0.967313,-0.049277,-1.971287,-30.380489,-0.195698,0.000000
2.700000,-0.242409,-30.380489,-0.012077,-0.007514,-0.190859,-1.078288,-0.054931,-1.908586,-30.380489,-0.189541,0.000000
3.070000,-0.265129,-30.424971,-0.011826,-0.007272,-0.184701,-1.179353,-0.060079,-1.847014,-30.424971,-0.183366,0.000000
3.440000,-0.210762,-30.424971,-0.011576,-0.007032,-0.178614,-0.937516,-0.047759,-1.786137,-30.424971,-0.177209,0.000000
3.810000,-0.194748,-30.424971,-0.011318,-0.006787,-0.172387,-0.866282,-0.044131,-1.723868,-30.424971,-0.171052,0.000000
4.180000,-0.196983,-30.424971,-0.011072,-0.006546,-0.166264,-0.876226,-0.044637,-1.662644,-30.424971,-0.164877,0.000000
4.550000,-0.213364,-30.424971,-0.010835,-0.006303,-0.160098,-0.949089,-0.048349,-1.600980,-30.424971,-0.158720,0.000000
4.920000,-0.230125,-30.513933,-0.010585,-0.006057,-0.153854,-1.023649,-0.052147,-1.538545,-30.513933,-0.152545,0.000000
5.290000,-0.198845,-30.424971,-0.010326,-0.005813,-0.147645,-0.884506,-0.045059,-1.476450,-30.424971,-0.146388,0.000000
5.660000,-0.173523,-30.424971,-0.010093,-0.005575,-0.141600,-0.771869,-0.039321,-1.416005,-30.424971,-0.140230,0.000000
6.030000,-0.200706,-30.469452,-0.009830,-0.005334,-0.135495,-0.892787,-0.045481,-1.354947,-30.469452,-0.134056,0.000000
6.400000,-0.215973,-30.513933,-0.009615,-0.005096,-0.129442,-0.960695,-0.048940,-1.294419,-30.513933,-0.127898,0.000000
6.770000,-0.224907,-30.558413,-0.009339,-0.004852,-0.123241,-1.000436,-0.050965,-1.232415,-30.558413,-0.121724,0.000000
7.140000,-0.260658,-30.602894,-0.009102,-0.004606,-0.116997,-1.159466,-0.059066,-1.169972,-30.602894,-0.115566,0.000000
7.510000,-0.186928,-30.513933,-0.008843,-0.004353,-0.110554,-0.831496,-0.042358,-1.105538,-30.513933,-0.109409,0.000000
7.880001,-0.200333,-30.513933,-0.008601,-0.004113,-0.104483,-0.891124,-0.045396,-1.044828,-30.513933,-0.103235,0.000000
8.250000,-0.155647,-30.558413,-0.008360,-0.003876,-0.098456,-0.692354,-0.035270,-0.984557,-30.558413,-0.097077,0.000000
8.620001,-0.185440,-30.602894,-0.008101,-0.003638,-0.092411,-0.824879,-0.042021,-0.924112,-30.602894,-0.090920,0.000000
8.990001,-0.211136,-30.558413,-0.007847,-0.003388,-0.086055,-0.939179,-0.047844,-0.860549,-30.558413,-0.084745,0.000000
9.360001,-0.217461,-30.558413,-0.007597,-0.003141,-0.079785,-0.967313,-0.049277,-0.797848,-30.558413,-0.078588,0.000000
9.730000,-0.145592,-30.558413,-0.007360,-0.002903,-0.073731,-0.647624,-0.032992,-0.737313,-30.558413,-0.072413,0.000000
10.100000,-0.158997,-30.558413,-0.007088,-0.002659,-0.067548,-0.707252,-0.036029,-0.675483,-30.558413,-0.066256,0.000000
10.470000,-0.165703,-30.602894,-0.006855,-0.002419,-0.061434,-0.737083,-0.037549,-0.614341,-30.602894,-0.060098,0.000000
10.840000,-0.207779,-30.602894,-0.006605,-0.002181,-0.055398,-0.924247,-0.047083,-0.553980,-30.602894,-0.053924,0.000000
11.210001,-0.232361,-30.647375,-0.006359,-0.001931,-0.049050,-1.033593,-0.052654,-0.490500,-30.647375,-0.047766,0.000000
11.580001,-0.214859,-30.647375,-0.006101,-0.001687,-0.042858,-0.955741,-0.048688,-0.428579,-30.647375,-0.041592,0.000000
11.950001,-0.176498,-30.647375,-0.005864,-0.001450,-0.036822,-0.785104,-0.039995,-0.368217,-30.647375,-0.035434,0.000000
12.320001,-0.137772,-30.691856,-0.005618,-0.001208,-0.030682,-0.612839,-0.031219,-0.306819,-30.691856,-0.029277,0.000000
12.690001,-0.154160,-30.691856,-0.005359,-0.000966,-0.024542,-0.685736,-0.034933,-0.245420,-30.691856,-0.023102,0.000000
13.060000,-0.179108,-30.647375,-0.005079,-0.000720,-0.018289,-0.796711,-0.040586,-0.182894,-30.647375,-0.016945,0.000000
13.430000,-0.180969,-30.691856,-0.004816,-0.000473,-0.012002,-0.804991,-0.041008,-0.120019,-30.691856,-0.010770,0.000000
13.800000,-0.082664,-30.736338,-0.004583,-0.000234,-0.005940,-0.367710,-0.018732,-0.059400,-30.736338,-0.004613,0.000000
14.170001,0.115067,-30.691856,-0.004402,-0.000000,-0.000000,0.511841,0.026074,-0.000000,-30.691856,0.000165,0.000000
14.540001,0.104271,-30.736338,-0.004411,-0.000000,-0.000009,0.463820,0.023628,-0.000091,-30.736338,0.000165,0.000000
14.910001,0.121765,-30.736338,-0.004398,-0.000000,-0.000009,0.541638,0.027592,-0.000091,-30.736338,0.000685,0.000000
15.280001,0.100540,-30.780819,-0.004402,0.000000,0.000008,0.447225,0.022783,0.000083,-30.780819,0.001300,0.000000
15.650001,0.238693,-30.736338,-0.004398,0.000032,0.000815,1.061761,0.054089,0.008153,-30.736338,0.001917,0.000000
16.020000,0.361946,-30.869780,-0.004372,0.000053,0.001335,1.610017,0.082018,0.013353,-30.869780,0.002532,0.000000
16.390001,0.517975,-30.780819,-0.004337,0.000076,0.001925,2.304067,0.117375,0.019250,-30.780819,0.003157,0.000000
16.760000,0.886246,-30.780819,-0.004316,0.000106,0.002688,3.942218,0.200826,0.026880,-30.780819,0.003772,0.000000
17.130001,1.184891,-30.780819,-0.004303,0.000134,0.003400,5.270657,0.268500,0.033996,-30.780819,0.004388,0.000000
17.500000,1.450394,-30.780819,-0.004273,0.000154,0.003920,6.451674,0.328664,0.039196,-30.780819,0.005004,0.000000
17.870001,1.719994,-30.825298,-0.004247,0.000175,0.004440,7.650914,0.389756,0.044404,-30.825298,0.005620,0.000000
18.240002,2.108002,-30.869780,-0.004234,0.000199,0.005056,9.376860,0.477680,0.050559,-30.869780,0.006235,0.000000
18.610001,2.578682,-30.869780,-0.004204,0.000227,0.005758,11.470551,0.584338,0.057583,-30.869780,0.006851,0.000000
18.980001,2.914192,-30.914261,-0.004204,0.000246,0.006253,12.962975,0.660365,0.062526,-30.914261,0.007467,0.000000
19.350000,3.369598,-30.825298,-0.004165,0.000274,0.006963,14.988722,0.763562,0.069634,-30.825298,0.008091,0.000000
19.720001,3.749794,-30.869780,-0.004161,0.000295,0.007493,16.679916,0.849715,0.074926,-30.869780,0.008707,0.000000
20.090000,4.225311,-30.914261,-0.004130,0.000320,0.008117,18.795124,0.957469,0.081171,-30.914261,0.009322,0.000000
20.460001,4.746635,-30.869780,-0.004113,0.000346,0.008794,21.114088,1.075603,0.087938,-30.869780,0.009938,0.000000
20.830002,4.893349,-30.914261,-0.004087,0.000363,0.009218,21.766703,1.108849,0.092185,-30.914261,0.010554,0.000000
21.200001,5.550217,-30.869780,-0.004070,0.000393,0.009982,24.688597,1.257697,0.099815,-30.869780,0.011170,0.000000
21.570002,5.879021,-30.914261,-0.004040,0.000416,0.010571,26.151190,1.332205,0.105712,-30.914261,0.011785,0.000000
21.940001,6.158669,-30.958742,-0.004044,0.000434,0.011031,27.395126,1.395574,0.110307,-30.958742,0.012401,0.000000
22.310001,6.839737,-31.003223,-0.003997,0.000470,0.011933,30.424669,1.549906,0.119330,-31.003223,0.013017,0.000000
22.680000,7.038963,-30.958742,-0.003984,0.000489,0.012427,31.310873,1.595052,0.124273,-30.958742,0.013642,0.000000
23.050001,6.973053,-30.958742,-0.003967,0.000500,0.012688,31.017689,1.580116,0.126877,-30.958742,0.014257,0.000000
23.420002,7.780724,-30.914261,-0.003923,0.000540,0.013710,34.610386,1.763137,0.137104,-30.914261,0.014873,0.000000
23.790001,7.776260,-30.914261,-0.003932,0.000555,0.014101,34.590534,1.762126,0.141010,-30.914261,0.015489,0.000000
24.160002,8.339287,-31.003223,-0.003902,0.000587,0.014899,37.095001,1.889709,0.148989,-31.003223,0.016104,0.000000
24.530001,8.571274,-31.003223,-0.003863,0.000610,0.015489,38.126930,1.942278,0.154885,-31.003223,0.016720,0.000000
24.900002,8.800278,-31.003223,-0.003854,0.000634,0.016113,39.145592,1.994172,0.161131,-31.003223,0.017336,0.000000
25.270000,9.168930,-31.003223,-0.003824,0.000662,0.016806,40.785439,2.077709,0.168064,-31.003223,0.017952,0.000000
25.640001,9.177864,-31.003223,-0.003794,0.000680,0.017267,40.825180,2.079734,0.172667,-31.003223,0.018567,0.000000
26.010002,9.500717,-31.047705,-0.003768,0.000705,0.017908,42.261299,2.152893,0.179079,-31.047705,0.019192,0.000000
26.380001,9.996346,-31.003223,-0.003742,0.000740,0.018801,44.465965,2.265204,0.188011,-31.003223,0.019807,0.000000
26.750002,9.903618,-31.047705,-0.003729,0.000760,0.019313,44.053493,2.244192,0.193128,-31.047705,0.020423,0.000000
27.120001,10.135979,-31.003223,-0.003708,0.000785,0.019946,45.087086,2.296846,0.199464,-31.003223,0.021039,0.000000
27.490002,10.200401,-31.047705,-0.003678,0.000804,0.020432,45.373650,2.311444,0.204316,-31.047705,0.021654,0.000000
27.860001,10.139336,-31.092184,-0.003656,0.000819,0.020813,45.102016,2.297606,0.208131,-31.092184,0.022270,0.000000
28.230001,10.722839,-31.047705,-0.003635,0.000859,0.021828,47.697571,2.429830,0.218282,-31.047705,0.022886,0.000000
28.600002,10.766037,-31.092184,-0.003613,0.000883,0.022426,47.889725,2.439619,0.224263,-31.092184,0.023502,0.000000
28.970001,10.838272,-31.003223,-0.003587,0.000902,0.022903,48.211040,2.455987,0.229032,-31.003223,0.024117,0.000000
29.340002,11.040848,-31.136665,-0.003566,0.000927,0.023545,49.112144,2.501892,0.235451,-31.136665,0.024742,0.000000
29.710001,11.332787,-31.181147,-0.003548,0.000954,0.024222,50.410751,2.568046,0.242218,-31.181147,0.025357,0.000000
30.080002,11.692123,-31.136665,-0.003531,0.000983,0.024967,52.009163,2.649473,0.249674,-31.136665,0.025973,0.000000
30.450001,11.682076,-31.092184,-0.003514,0.001007,0.025575,51.964466,2.647196,0.255745,-31.092184,0.026589,0.000000
30.820002,11.691383,-31.136665,-0.003497,0.001028,0.026104,52.005871,2.649305,0.261037,-31.136665,0.027205,0.000000
31.190001,11.967308,-31.136665,-0.003466,0.001051,0.026702,53.233246,2.711831,0.267017,-31.136665,0.027820,0.000000
31.560001,11.858948,-31.181147,-0.003458,0.001071,0.027196,52.751236,2.687276,0.271960,-31.181147,0.028436,0.000000
31.930002,12.277122,-31.181147,-0.003415,0.001099,0.027924,54.611370,2.782036,0.279242,-31.181147,0.029052,0.000000
32.300003,12.697533,-31.225628,-0.003397,0.001132,0.028757,56.481445,2.877302,0.287569,-31.225628,0.029668,0.000000
32.670002,12.746315,-31.181147,-0.003363,0.001154,0.029312,56.698441,2.888356,0.293117,-31.181147,0.030292,0.000000
33.040001,12.794724,-31.181147,-0.003346,0.001177,0.029893,56.913773,2.899326,0.298931,-31.181147,0.030907,0.000000
33.410000,12.729187,-31.225628,-0.003328,0.001195,0.030362,56.622253,2.884475,0.303617,-31.225628,0.031524,0.000000
33.780003,13.205078,-31.181147,-0.003320,0.001221,0.031012,58.739120,2.992313,0.310119,-31.181147,0.032139,0.000000
34.150002,13.437065,-31.270109,-0.003294,0.001247,0.031671,59.771049,3.044883,0.316712,-31.270109,0.032755,0.000000
34.520000,13.706291,-31.225628,-0.003260,0.001274,0.032347,60.968628,3.105890,0.323472,-31.225628,0.033371,0.000000
34.890003,13.888748,-31.225628,-0.003260,0.001299,0.032997,61.780239,3.147235,0.329975,-31.225628,0.033986,0.000000
35.260002,13.815765,-31.225628,-0.003216,0.001320,0.033518,61.455593,3.130697,0.335183,-31.225628,0.034602,0.000000
35.630001,14.064514,-31.403551,-0.003212,0.001346,0.034194,62.562084,3.187064,0.341943,-31.403551,0.035218,0.000000
36.000000,14.374695,-31.359070,-0.003195,0.001368,0.034741,63.941837,3.257352,0.347408,-31.359070,0.035842,0.000000
36.370003,14.533699,-31.225628,-0.003160,0.001390,0.035305,64.649124,3.293383,0.353047,-31.225628,0.036458,0.000000
36.740002,14.829735,-31.270109,-0.003156,0.001416,0.035955,65.965958,3.360466,0.359550,-31.270109,0.037074,0.000000
37.110001,15.009964,-31.314590,-0.003122,0.001437,0.036510,66.767654,3.401306,0.365099,-31.314590,0.037689,0.000000
37.480003,15.333931,-31.314590,-0.003091,0.001468,0.037282,68.208733,3.474719,0.372820,-31.314590,0.038305,0.000000
37.850002,15.068802,-31.403551,-0.003096,0.001478,0.037533,67.029381,3.414639,0.375333,-31.403551,0.038921,0.000000
38.220001,15.736465,-31.359070,-0.003057,0.001511,0.038392,69.999298,3.565934,0.383917,-31.359070,0.039537,0.000000
38.590000,16.108093,-31.359070,-0.003031,0.001540,0.039112,71.652374,3.650146,0.391116,-31.359070,0.040152,0.000000
38.960003,16.326302,-31.359070,-0.003009,0.001567,0.039806,72.623016,3.699593,0.398057,-31.359070,0.040768,0.000000
39.330002,15.762901,-31.403551,-0.002988,0.001576,0.040040,70.116890,3.571924,0.400396,-31.403551,0.041392,0.000000
39.700001,16.457748,-31.448032,-0.002962,0.001611,0.040925,73.207718,3.729379,0.409246,-31.448032,0.042009,0.000000
40.070004,16.821182,-31.448032,-0.002953,0.001634,0.041505,74.824356,3.811734,0.415052,-31.448032,0.042624,0.000000
40.440002,16.878532,-31.403551,-0.002910,0.001655,0.042026,75.079460,3.824730,0.420260,-31.403551,0.043239,0.000000
40.810001,17.173820,-31.448032,-0.002906,0.001683,0.042745,76.392967,3.891643,0.427451,-31.448032,0.043856,0.000000
41.180000,17.206589,-31.448032,-0.002906,0.001700,0.043171,76.538727,3.899069,0.431705,-31.448032,0.044471,0.000000
41.550003,17.729774,-31.448032,-0.002871,0.001728,0.043899,78.865974,4.017624,0.438987,-31.448032,0.045087,0.000000
41.920002,18.160980,-31.448032,-0.002833,0.001754,0.044549,80.784073,4.115337,0.445490,-31.448032,0.045703,0.000000
42.290001,18.300247,-31.492514,-0.002841,0.001779,0.045191,81.403564,4.146895,0.451909,-31.492514,0.046327,0.000000
42.660004,18.488297,-31.448032,-0.002798,0.001801,0.045746,82.240051,4.189508,0.457458,-31.448032,0.046943,0.000000
43.030003,18.862160,-31.492514,-0.002794,0.001826,0.046370,83.903076,4.274226,0.463703,-31.492514,0.047559,0.000000
43.400002,19.277351,-31.492514,-0.002759,0.001850,0.046986,85.749939,4.368310,0.469864,-31.492514,0.048174,0.000000
43.770000,19.781921,-31.492514,-0.002734,0.001881,0.047775,87.994385,4.482647,0.477752,-31.492514,0.048790,0.000000
44.140003,19.494446,-31.492514,-0.002703,0.001896,0.048148,86.715630,4.417505,0.481484,-31.492514,0.049406,0.000000
44.510002,20.033272,-31.492514,-0.002686,0.001922,0.048824,89.112442,4.539604,0.488244,-31.492514,0.050021,0.000000
44.880001,20.483841,-31.536995,-0.002656,0.001950,0.049536,91.116676,4.641705,0.495359,-31.536995,0.050637,0.000000
45.250004,20.070877,-31.492514,-0.002665,0.001960,0.049796,89.279716,4.548126,0.497963,-31.492514,0.051253,0.000000
45.620003,21.339554,-31.536995,-0.002617,0.001997,0.050715,94.923073,4.835612,0.507153,-31.536995,0.051877,0.000000
45.990002,21.631493,-31.536995,-0.002596,0.002022,0.051348,96.221687,4.901766,0.513482,-31.536995,0.052493,0.000000
46.360001,21.358917,-31.581474,-0.002583,0.002037,0.051747,95.009209,4.840000,0.517471,-31.581474,0.053109,0.000000
46.730003,22.184837,-31.581474,-0.002565,0.002068,0.052537,98.683083,5.027156,0.525366,-31.581474,0.053724,0.000000
47.100002,21.701126,-31.625956,-0.002539,0.002082,0.052875,96.531433,4.917545,0.528750,-31.625956,0.054340,0.000000
47.470001,22.824203,-31.581474,-0.002518,0.002113,0.053664,101.527130,5.172038,0.536638,-31.581474,0.054956,0.000000
47.840004,23.413666,-31.625956,-0.002483,0.002143,0.054436,104.149185,5.305613,0.544359,-31.625956,0.055571,0.000000
48.210003,23.344780,-31.581474,-0.002483,0.002160,0.054852,103.842766,5.290003,0.548522,-31.581474,0.056188,0.000000
48.580002,23.969994,-31.670437,-0.002462,0.002193,0.055702,106.623856,5.431678,0.557015,-31.670437,0.056803,0.000000
48.950001,24.149849,-31.670437,-0.002436,0.002209,0.056118,107.423897,5.472434,0.561179,-31.670437,0.057427,0.000000
49.320004,25.169029,-31.625956,-0.002419,0.002238,0.056847,111.957436,5.703384,0.568469,-31.625956,0.058044,0.000000
49.690002,25.978195,-31.625956,-0.002384,0.002269,0.057627,115.556786,5.886743,0.576273,-31.625956,0.058659,0.000000
50.060001,25.748070,-31.670437,-0.002358,0.002286,0.058060,114.533134,5.834596,0.580603,-31.670437,0.059274,0.000000
50.430004,26.031815,-31.714918,-0.002345,0.002314,0.058772,115.795296,5.898894,0.587718,-31.714918,0.059891,0.000000
50.800003,27.059196,-31.714918,-0.002315,0.002339,0.059422,120.365318,6.131702,0.594221,-31.714918,0.060506,0.000000
51.170002,27.451675,-31.670437,-0.002294,0.002360,0.059951,122.111153,6.220638,0.599512,-31.670437,0.061122,0.000000
51.540001,28.460800,-31.670437,-0.002285,0.002391,0.060732,126.599960,6.449310,0.607317,-31.670437,0.061738,0.000000
51.910004,28.346855,-31.670437,-0.002259,0.002410,0.061218,126.093109,6.423489,0.612176,-31.670437,0.062353,0.000000
52.280003,28.785515,-31.670437,-0.002251,0.002430,0.061729,128.044373,6.522891,0.617294,-31.670437,0.062978,0.000000
52.650002,29.316139,-31.759399,-0.002229,0.002453,0.062302,130.404694,6.643132,0.623016,-31.759399,0.063594,0.000000
53.020004,29.379074,-31.759399,-0.002190,0.002469,0.062718,130.684647,6.657393,0.627180,-31.759399,0.064209,0.000000
53.390003,31.192154,-31.759399,-0.002177,0.002507,0.063672,138.749634,7.068243,0.636718,-31.759399,0.064825,0.000000
53.760002,32.078400,-31.759399,-0.002151,0.002537,0.064443,142.691849,7.269069,0.644431,-31.759399,0.065441,0.000000
54.130001,32.280975,-31.759399,-0.002130,0.002559,0.064999,143.592957,7.314973,0.649988,-31.759399,0.066056,0.000000
54.500004,32.899483,-31.803881,-0.002113,0.002587,0.065701,146.344208,7.455129,0.657012,-31.803881,0.066672,0.000000
54.870003,33.157539,-31.803881,-0.002087,0.002606,0.066196,147.492096,7.513606,0.661955,-31.803881,0.067288,0.000000
55.240002,33.452454,-31.759399,-0.002082,0.002626,0.066698,148.803940,7.580434,0.666982,-31.759399,0.067903,0.000000
55.610004,34.950508,-31.803881,-0.002061,0.002657,0.067488,155.467621,7.919899,0.674877,-31.803881,0.068528,0.000000
55.980003,35.375015,-31.759399,-0.002035,0.002681,0.068103,157.355927,8.016093,0.681031,-31.759399,0.069144,0.000000
56.350002,36.861153,-31.848360,-0.002022,0.002711,0.068849,163.966599,8.352857,0.688488,-31.848360,0.069759,0.000000
56.720001,36.898766,-31.803881,-0.001996,0.002727,0.069265,164.133911,8.361380,0.692651,-31.803881,0.070376,0.000000
57.090004,37.635689,-31.848360,-0.001975,0.002748,0.069803,167.411911,8.528369,0.698025,-31.848360,0.070991,0.000000
57.460003,38.607582,-31.848360,-0.001957,0.002774,0.070454,171.735107,8.748603,0.704535,-31.848360,0.071606,0.000000
57.830002,39.049583,-31.892841,-0.001940,0.002793,0.070948,173.701218,8.848763,0.709479,-31.892841,0.072223,0.000000
58.200005,39.976051,-31.892841,-0.001923,0.002817,0.071555,177.822357,9.058703,0.715550,-31.892841,0.072838,0.000000
58.570004,40.713348,-31.848360,-0.001897,0.002840,0.072127,181.102020,9.225777,0.721272,-31.848360,0.073454,0.000000
58.940002,41.929146,-31.848360,-0.001884,0.002866,0.072803,186.510162,9.501280,0.728032,-31.848360,0.074078,0.000000
59.310001,43.089828,-31.892841,-0.001867,0.002897,0.073575,191.673126,9.764295,0.735753,-31.892841,0.074694,0.000000
59.680004,44.252747,-31.892841,-0.001854,0.002920,0.074165,196.846054,10.027816,0.741650,-31.892841,0.075310,0.000000
60.050003,44.728638,-31.937323,-0.001837,0.002938,0.074634,198.962921,10.135654,0.746336,-31.937323,0.075926,0.000000
60.420002,46.088913,-31.981804,-0.001811,0.002970,0.075440,205.013718,10.443897,0.754398,-31.981804,0.076541,0.000000
60.790005,46.953934,-31.892841,-0.001811,0.002995,0.076073,208.861526,10.639913,0.760726,-31.892841,0.077157,0.000000
61.160004,47.978706,-31.981804,-0.001789,0.003017,0.076637,213.419952,10.872130,0.766366,-31.981804,0.077773,0.000000
61.530003,48.902565,-31.937323,-0.001759,0.003041,0.077244,217.529480,11.081480,0.772436,-31.937323,0.078388,0.000000
61.900002,49.829765,-32.026283,-0.001755,0.003066,0.077876,221.653870,11.291586,0.778765,-32.026283,0.079004,0.000000
62.270004,50.831451,-31.981804,-0.001729,0.003084,0.078345,226.109589,11.518572,0.783451,-31.981804,0.079629,0.000000
62.640003,52.125816,-31.937323,-0.001699,0.003115,0.079126,231.867218,11.811879,0.791255,-31.937323,0.080244,0.000000
63.010002,53.046326,-32.026283,-0.001712,0.003135,0.079637,235.961838,12.020469,0.796372,-32.026283,0.080860,0.000000
63.380005,54.318718,-31.981804,-0.001681,0.003158,0.080201,241.621719,12.308798,0.802012,-31.981804,0.081476,0.000000
63.750004,55.566170,-31.981804,-0.001677,0.003184,0.080869,247.170670,12.591474,0.808688,-31.981804,0.082091,0.000000
64.120003,56.643814,-32.070766,-0.001656,0.003206,0.081441,251.964264,12.835671,0.814411,-32.070766,0.082708,0.000000
64.490005,57.335678,-32.070766,-0.001651,0.003225,0.081926,255.041840,12.992450,0.819263,-32.070766,0.083323,0.000000
64.860001,59.515549,-32.026283,-0.001621,0.003260,0.082811,264.738373,13.486417,0.828112,-32.026283,0.083938,0.000000
65.230003,60.892952,-32.026283,-0.001613,0.003284,0.083410,270.865387,13.798541,0.834100,-32.026283,0.084555,0.000000
65.600006,61.690575,-32.115246,-0.001595,0.003305,0.083947,274.413391,13.979283,0.839475,-32.115246,0.085179,0.000000
65.970001,63.280235,-32.070766,-0.001578,0.003334,0.084676,281.484558,14.339506,0.846757,-32.070766,0.085794,0.000000
66.340004,64.032433,-32.115246,-0.001582,0.003349,0.085057,284.830475,14.509956,0.850572,-32.115246,0.086410,0.000000
66.710007,64.705299,-32.159729,-0.001561,0.003369,0.085578,287.823547,14.662431,0.855780,-32.159729,0.087026,0.000000
67.080002,66.105049,-32.070766,-0.001544,0.003382,0.085899,294.049957,14.979618,0.858989,-32.070766,0.015090,0.000000
67.450005,64.932823,-32.115246,-0.001531,0.003380,0.085855,288.835632,14.713987,0.858550,-32.115246,294.500488,0.000000
67.820000,66.560463,-32.115246,-0.001526,0.003336,0.084745,296.075714,15.082816,0.847453,-32.115246,294.500488,0.000000
68.190002,65.581490,-32.159729,-0.001505,0.003351,0.085127,291.721039,14.860978,0.851268,-32.159729,294.500488,0.000000
68.560005,65.035225,-32.115246,-0.001509,0.003400,0.086349,289.291138,14.737193,0.863494,-32.115246,294.500488,0.000000
68.930000,65.082893,-32.115246,-0.001496,0.003411,0.086627,289.503174,14.747994,0.866272,-32.115246,294.500488,0.000000
69.300003,64.703438,-32.204208,-0.001509,0.003412,0.086653,287.815277,14.662008,0.866529,-32.204208,294.500488,0.000000
69.670006,65.593788,-32.204208,-0.001500,0.003427,0.087044,291.775757,14.863765,0.870435,-32.204208,294.500488,0.000000
70.040001,65.178963,-32.159729,-0.001483,0.003427,0.087044,289.930511,14.769765,0.870435,-32.159729,294.500488,0.000000
70.410004,64.735100,-32.159729,-0.001483,0.003427,0.087052,287.956116,14.669183,0.870518,-32.159729,294.500488,0.000000
70.780006,64.355278,-32.248688,-0.001500,0.003427,0.087052,286.266571,14.583114,0.870518,-32.248688,294.500488,0.000000
71.150002,66.189949,-32.248688,-0.001492,0.003415,0.086748,294.427612,14.998857,0.867483,-32.248688,294.500488,0.000000
71.520004,65.743477,-32.248688,-0.001462,0.003415,0.086748,292.441589,14.897685,0.867483,-32.248688,294.500488,0.000000
71.890007,65.334984,-32.204208,-0.001466,0.003416,0.086766,290.624512,14.805119,0.867657,-32.204208,294.500488,0.000000
72.260002,65.052361,-32.204208,-0.001457,0.003432,0.087174,289.367340,14.741076,0.871737,-32.204208,294.500488,0.000000
72.630005,65.329765,-32.248688,-0.001475,0.003452,0.087676,290.601318,14.803937,0.876763,-32.248688,294.500488,0.000000
73.000000,65.080650,-32.337650,-0.001470,0.003452,0.087676,289.493195,14.747486,0.876763,-32.337650,294.500488,0.000000
73.370003,64.860207,-32.248688,-0.001457,0.003453,0.087694,288.512604,14.697534,0.876937,-32.248688,294.500488,0.000000
73.740005,65.607933,-32.248688,-0.001457,0.003467,0.088058,291.838654,14.866970,0.880579,-32.248688,294.500488,0.000000
74.110001,65.581490,-32.204208,-0.001457,0.003465,0.088023,291.721039,14.860978,0.880230,-32.204208,294.500488,0.000000
74.480003,65.383766,-32.293171,-0.001462,0.003465,0.088023,290.841522,14.816174,0.880230,-32.293171,294.500488,0.000000
74.850006,65.181190,-32.337650,-0.001462,0.003466,0.088032,289.940430,14.770268,0.880321,-32.337650,294.500488,0.000000
75.220001,64.991280,-32.293171,-0.001453,0.003466,0.088032,289.095642,14.727234,0.880321,-32.293171,294.500488,0.000000
75.590004,64.783134,-32.293171,-0.001444,0.003466,0.088032,288.169769,14.680068,0.880321,-32.293171,294.500488,0.000000
75.960007,64.611092,-32.293171,-0.001453,0.003466,0.088040,287.404480,14.641083,0.880404,-32.293171,294.500488,0.000000
76.330002,65.757622,-32.248688,-0.001457,0.003481,0.088414,292.504517,14.900890,0.884136,-32.248688,294.500488,0.000000
76.700005,65.660439,-32.337650,-0.001444,0.003480,0.088405,292.072205,14.878868,0.884045,-32.337650,294.500488,0.000000
77.070007,65.537560,-32.337650,-0.001444,0.003480,0.088405,291.525635,14.851024,0.884045,-32.337650,294.500488,0.000000
77.440002,65.368492,-32.337650,-0.001444,0.003480,0.088405,290.773590,14.812712,0.884045,-32.337650,294.500488,0.000000
77.810005,65.245247,-32.337650,-0.001444,0.003480,0.088405,290.225342,14.784784,0.884045,-32.337650,294.500488,0.000000
78.180000,65.077309,-32.382133,-0.001440,0.003482,0.088439,289.478333,14.746729,0.884394,-32.382133,294.500488,0.000000
78.550003,64.982719,-32.426613,-0.001440,0.003482,0.088439,289.057587,14.725295,0.884394,-32.426613,294.500488,0.000000
78.920006,64.866539,-32.426613,-0.001444,0.003482,0.088439,288.540771,14.698968,0.884394,-32.426613,294.500488,0.000000
79.290001,64.719826,-32.337650,-0.001427,0.003482,0.088439,287.888153,14.665722,0.884394,-32.337650,294.500488,0.000000
79.660004,65.427711,-32.382133,-0.001431,0.003492,0.088691,291.036987,14.826132,0.886907,-32.382133,294.500488,0.000000
80.030006,65.368874,-32.471096,-0.001444,0.003492,0.088691,290.775269,14.812799,0.886907,-32.471096,294.500488,0.000000
80.400002,65.283974,-32.471096,-0.001427,0.003492,0.088691,290.397614,14.793560,0.886907,-32.471096,294.500488,0.000000
80.770004,65.215828,-32.471096,-0.001431,0.003492,0.088691,290.094482,14.778117,0.886907,-32.471096,294.500488,0.000000
81.140007,65.085503,-32.382133,-0.001431,0.003492,0.088691,289.514771,14.748586,0.886907,-32.382133,294.500488,0.000000
81.510002,65.007668,-32.426613,-0.001436,0.003492,0.088691,289.168549,14.730948,0.886907,-32.426613,294.500488,0.000000
81.880005,64.916817,-32.382133,-0.001427,0.003492,0.088700,288.764435,14.710361,0.886998,-32.382133,294.500488,0.000000
82.250008,64.794304,-32.471096,-0.001418,0.003492,0.088700,288.219452,14.682599,0.886998,-32.471096,294.500488,0.000000
82.620003,64.723183,-32.426613,-0.001427,0.003492,0.088708,287.903107,14.666483,0.887081,-32.426613,294.500488,0.000000
82.990005,65.540901,-32.471096,-0.001423,0.003503,0.088968,291.540497,14.851781,0.889685,-32.471096,294.500488,0.000000
83.360001,65.519676,-32.471096,-0.001423,0.003503,0.088968,291.446075,14.846972,0.889685,-32.471096,294.500488,0.000000
83.730003,65.466057,-32.560055,-0.001427,0.003503,0.088968,291.207550,14.834821,0.889685,-32.560055,294.500488,0.000000
84.100006,65.362907,-32.515575,-0.001418,0.003503,0.088968,290.748718,14.811446,0.889685,-32.515575,294.500488,0.000000
84.470001,65.299232,-32.471096,-0.001423,0.003503,0.088968,290.465485,14.797018,0.889685,-32.471096,294.500488,0.000000
84.840004,65.234444,-32.515575,-0.001436,0.003503,0.088968,290.177307,14.782336,0.889685,-32.515575,294.500488,0.000000
85.210007,65.145821,-32.515575,-0.001418,0.003503,0.088968,289.783081,14.762254,0.889685,-32.515575,294.500488,0.000000
85.580002,65.051979,-32.560055,-0.001418,0.003503,0.088968,289.365662,14.740989,0.889685,-32.560055,294.500488,0.000000
85.950005,64.980858,-32.604538,-0.001418,0.003503,0.088968,289.049286,14.724873,0.889685,-32.604538,294.500488,0.000000
86.320007,64.913826,-32.560055,-0.001414,0.003503,0.088968,288.751129,14.709682,0.889685,-32.560055,294.500488,0.000000
86.690002,64.819252,-32.560055,-0.001418,0.003503,0.088968,288.330444,14.688252,0.889685,-32.560055,294.500488,0.000000
87.060005,64.749611,-32.604538,-0.001423,0.003503,0.088978,288.020660,14.672471,0.889776,-32.604538,294.500488,0.000000
87.430008,64.703819,-32.693501,-0.001414,0.003503,0.088978,287.816956,14.662095,0.889776,-32.693501,294.500488,0.000000
87.800003,64.606621,-32.649017,-0.001414,0.003503,0.088978,287.384613,14.640070,0.889776,-32.649017,294.500488,0.000000
88.170006,64.512413,-32.649017,-0.001427,0.003503,0.088978,286.965546,14.618722,0.889776,-32.649017,294.500488,0.000000
88.540001,64.462883,-32.604538,-0.001431,0.003503,0.088978,286.745239,14.607498,0.889776,-32.604538,294.500488,0.000000
88.910004,64.412987,-32.604538,-0.001418,0.003503,0.088986,286.523285,14.596191,0.889859,-32.604538,294.500488,0.000000
89.280006,66.334068,-32.649017,-0.001414,0.003495,0.088760,295.068665,15.031515,0.887603,-32.649017,294.500488,0.000000
89.650002,66.240227,-32.649017,-0.001414,0.003495,0.088760,294.651245,15.010250,0.887603,-32.649017,294.500488,0.000000
90.020004,66.151222,-32.604538,-0.001397,0.003495,0.088760,294.255341,14.990082,0.887603,-32.604538,294.500488,0.000000
90.390007,66.060738,-32.649017,-0.001406,0.003495,0.088760,293.852844,14.969577,0.887603,-32.649017,294.500488,0.000000
90.760002,65.979561,-32.693501,-0.001418,0.003495,0.088760,293.491730,14.951182,0.887603,-32.693501,294.500488,0.000000
91.130005,65.884605,-32.782459,-0.001397,0.003495,0.088760,293.069366,14.929666,0.887603,-32.782459,294.500488,0.000000
91.500008,65.824654,-32.782459,-0.001393,0.003495,0.088760,292.802673,14.916080,0.887603,-32.782459,294.500488,0.000000
91.870003,65.793755,-32.649017,-0.001406,0.003495,0.088760,292.665222,14.909079,0.887603,-32.649017,294.500488,0.000000
92.240005,65.741982,-32.737980,-0.001393,0.003495,0.088760,292.434937,14.897346,0.887603,-32.737980,294.500488,0.000000
92.610001,65.600487,-32.737980,-0.001397,0.003495,0.088760,291.805542,14.865283,0.887603,-32.737980,294.500488,0.000000
92.980003,65.563988,-32.782459,-0.001384,0.003495,0.088760,291.643188,14.857012,0.887603,-32.782459,294.500488,0.000000
93.350006,65.500694,-32.782459,-0.001401,0.003495,0.088769,291.361633,14.842669,0.887694,-32.782459,294.500488,0.000000
93.720001,65.423607,-32.782459,-0.001388,0.003495,0.088769,291.018738,14.825201,0.887694,-32.782459,294.500488,0.000000
94.090004,65.345406,-32.737980,-0.001401,0.003495,0.088778,290.670868,14.807481,0.887777,-32.737980,294.500488,0.000000
94.460007,65.292534,-32.826942,-0.001410,0.003496,0.088786,290.435699,14.795500,0.887861,-32.826942,294.500488,0.000000
94.830002,65.262001,-32.826942,-0.001397,0.003496,0.088786,290.299866,14.788581,0.887861,-32.826942,294.500488,0.000000
95.200005,65.213966,-32.782459,-0.001375,0.003496,0.088786,290.086212,14.777697,0.887861,-32.782459,294.500488,0.000000
95.570007,65.122734,-32.782459,-0.001397,0.003496,0.088786,289.680389,14.757022,0.887861,-32.782459,294.500488,0.000000
95.940002,65.056084,-32.826942,-0.001414,0.003496,0.088786,289.383911,14.741920,0.887861,-32.826942,294.500488,0.000000
96.310005,65.024055,-32.826942,-0.001393,0.003496,0.088786,289.241455,14.734662,0.887861,-32.826942,294.500488,0.000000
96.680008,65.051613,-32.915905,-0.001397,0.003515,0.089289,289.364014,14.740906,0.892895,-32.915905,294.500488,0.000000
97.050003,65.002831,-32.871422,-0.001397,0.003515,0.089289,289.147034,14.729852,0.892895,-32.871422,294.500488,0.000000
97.420006,64.961494,-32.826942,-0.001393,0.003515,0.089289,288.963165,14.720485,0.892895,-32.826942,294.500488,0.000000
97.790001,64.919044,-32.871422,-0.001388,0.003515,0.089289,288.774323,14.710866,0.892895,-32.871422,294.500488,0.000000
98.160004,65.396431,-32.871422,-0.001414,0.003525,0.089541,290.897858,14.819043,0.895408,-32.871422,294.500488,0.000000
98.530006,65.419884,-32.960384,-0.001393,0.003525,0.089541,291.002167,14.824358,0.895408,-32.960384,294.500488,0.000000
98.900002,65.378548,-32.915905,-0.001384,0.003525,0.089541,290.818298,14.814991,0.895408,-32.915905,294.500488,0.000000
99.270004,65.352867,-32.960384,-0.001397,0.003525,0.089541,290.704071,14.809171,0.895408,-32.960384,294.500488,0.000000
99.640007,65.319344,-32.960384,-0.001393,0.003525,0.089541,290.554962,14.801575,0.895408,-32.960384,294.500488,0.000000
100.010002,65.302589,-33.004868,-0.001397,0.003525,0.089541,290.480438,14.797779,0.895408,-33.004868,294.500488,0.000000
100.380005,65.269814,-32.960384,-0.001380,0.003525,0.089541,290.334625,14.790351,0.895408,-32.960384,294.500488,0.000000
100.750008,65.235939,-32.960384,-0.001375,0.003525,0.089541,290.183960,14.782675,0.895408,-32.960384,294.500488,0.000000
101.120003,65.195351,-32.915905,-0.001388,0.003525,0.089541,290.003418,14.773478,0.895408,-32.915905,294.500488,0.000000
101.490005,65.145821,-32.960384,-0.001401,0.003525,0.089541,289.783081,14.762254,0.895408,-32.960384,294.500488,0.000000
101.860008,65.170403,-33.004868,-0.001393,0.003527,0.089584,289.892426,14.767824,0.895839,-33.004868,294.500488,0.000000
102.230003,65.151405,-32.960384,-0.001384,0.003527,0.089584,289.807922,14.763519,0.895839,-32.960384,294.500488,0.000000
102.600006,65.140602,-32.960384,-0.001397,0.003527,0.089584,289.759857,14.761071,0.895839,-32.960384,294.500488,0.000000
102.970001,65.112679,-33.004868,-0.001393,0.003527,0.089584,289.635651,14.754745,0.895839,-33.004868,294.500488,0.000000
103.340004,65.228859,-33.049347,-0.001397,0.003530,0.089663,290.152466,14.781071,0.896626,-33.049347,294.500488,0.000000
103.710007,65.223274,-33.049347,-0.001397,0.003530,0.089663,290.127625,14.779805,0.896626,-33.049347,294.500488,0.000000
104.080002,65.213585,-33.049347,-0.001401,0.003530,0.089663,290.084503,14.777609,0.896626,-33.049347,294.500488,0.000000
104.450005,65.185661,-33.049347,-0.001388,0.003530,0.089663,289.960297,14.771281,0.896626,-33.049347,294.500488,0.000000
104.820007,65.168907,-33.004868,-0.001384,0.003530,0.089663,289.885773,14.767486,0.896626,-33.004868,294.500488,0.000000
105.190002,65.164070,-33.093826,-0.001393,0.003531,0.089680,289.864258,14.766389,0.896801,-33.093826,294.500488,0.000000
105.560005,65.146187,-33.093826,-0.001401,0.003531,0.089697,289.784698,14.762337,0.896967,-33.093826,294.500488,0.000000
105.930008,65.146568,-33.093826,-0.001397,0.003531,0.089697,289.786407,14.762424,0.896967,-33.093826,294.500488,0.000000
106.300003,65.119377,-33.093826,-0.001393,0.003531,0.089697,289.665466,14.756262,0.896967,-33.093826,294.500488,0.000000
106.670006,65.258644,-33.004868,-0.001393,0.003534,0.089775,290.284943,14.787820,0.897754,-33.004868,294.500488,0.000000
107.040009,65.297752,-33.093826,-0.001397,0.003534,0.089775,290.458923,14.796682,0.897754,-33.093826,294.500488,0.000000
107.410004,65.270195,-33.138309,-0.001393,0.003534,0.089775,290.336334,14.790438,0.897754,-33.138309,294.500488,0.000000
107.780006,65.269447,-33.138309,-0.001380,0.003534,0.089775,290.333008,14.790268,0.897754,-33.138309,294.500488,0.000000
108.150002,65.256416,-33.093826,-0.001388,0.003534,0.089775,290.275024,14.787314,0.897754,-33.093826,294.500488,0.000000
108.520004,65.220299,-33.049347,-0.001397,0.003534,0.089775,290.114380,14.779131,0.897754,-33.049347,294.500488,0.000000
108.890007,65.197212,-33.138309,-0.001397,0.003534,0.089775,290.011688,14.773900,0.897754,-33.138309,294.500488,0.000000
109.260002,65.161461,-33.138309,-0.001375,0.003534,0.089775,289.852661,14.765799,0.897754,-33.138309,294.500488,0.000000
109.630005,65.136879,-33.227272,-0.001388,0.003534,0.089775,289.743317,14.760228,0.897754,-33.227272,294.500488,0.000000
110.000008,65.095924,-33.182789,-0.001380,0.003534,0.089775,289.561127,14.750948,0.897754,-33.182789,294.500488,0.000000
110.370003,65.090706,-33.182789,-0.001388,0.003534,0.089775,289.537933,14.749764,0.897754,-33.182789,294.500488,0.000000
110.740005,65.050499,-33.227272,-0.001384,0.003534,0.089775,289.359070,14.740654,0.897754,-33.227272,294.500488,0.000000
111.110008,65.034477,-33.271751,-0.001380,0.003534,0.089775,289.287811,14.737023,0.897754,-33.271751,294.500488,0.000000
111.480003,64.997612,-33.227272,-0.001380,0.003534,0.089775,289.123810,14.728669,0.897754,-33.227272,294.500488,0.000000
111.850006,64.976387,-33.138309,-0.001393,0.003534,0.089775,289.029419,14.723860,0.897754,-33.138309,294.500488,0.000000
112.220009,64.955162,-33.227272,-0.001393,0.003534,0.089775,288.934998,14.719049,0.897754,-33.227272,294.500488,0.000000
112.590004,64.923515,-33.271751,-0.001401,0.003534,0.089775,288.794220,14.711879,0.897754,-33.271751,294.500488,0.000000
112.960007,65.282112,-33.316231,-0.001388,0.003541,0.089931,290.389343,14.793138,0.899314,-33.316231,294.500488,0.000000
113.330002,65.300362,-33.271751,-0.001388,0.003541,0.089931,290.470520,14.797274,0.899314,-33.271751,294.500488,0.000000
113.700005,65.300728,-33.316231,-0.001384,0.003541,0.089931,290.472137,14.797357,0.899314,-33.316231,294.500488,0.000000
114.070007,65.300728,-33.271751,-0.001380,0.003541,0.089931,290.472137,14.797357,0.899314,-33.271751,294.500488,0.000000
114.440002,65.278389,-33.360714,-0.001397,0.003541,0.089931,290.372772,14.792295,0.899314,-33.360714,294.500488,0.000000
114.810005,65.279503,-33.316231,-0.001388,0.003541,0.089931,290.377716,14.792547,0.899314,-33.316231,294.500488,0.000000
115.180008,65.258278,-33.271751,-0.001384,0.003541,0.089931,290.283325,14.787737,0.899314,-33.271751,294.500488,0.000000
115.550003,65.240028,-33.316231,-0.001388,0.003541,0.089931,290.202148,14.783602,0.899314,-33.316231,294.500488,0.000000
115.920006,65.230354,-33.316231,-0.001375,0.003541,0.089931,290.159119,14.781409,0.899314,-33.316231,294.500488,0.000000
116.290009,65.197212,-33.360714,-0.001388,0.003541,0.089931,290.011688,14.773900,0.899314,-33.360714,294.500488,0.000000
116.660004,65.166298,-33.360714,-0.001380,0.003541,0.089931,289.874176,14.766894,0.899314,-33.360714,294.500488,0.000000
117.030006,65.115654,-33.360714,-0.001384,0.003541,0.089940,289.648895,14.755418,0.899397,-33.360714,294.500488,0.000000
117.400009,65.111183,-33.316231,-0.001384,0.003541,0.089940,289.628998,14.754405,0.899397,-33.316231,294.500488,0.000000
117.770004,65.085121,-33.360714,-0.001388,0.003541,0.089940,289.513092,14.748499,0.899397,-33.360714,294.500488,0.000000
118.140007,65.052727,-33.405193,-0.001401,0.003541,0.089940,289.368988,14.741158,0.899397,-33.405193,294.500488,0.000000
118.510002,65.025169,-33.405193,-0.001388,0.003541,0.089940,289.246399,14.734915,0.899397,-33.405193,294.500488,0.000000
118.880005,65.021080,-33.316231,-0.001388,0.003541,0.089940,289.228210,14.733988,0.899397,-33.316231,294.500488,0.000000
119.250008,64.993889,-33.360714,-0.001384,0.003541,0.089940,289.107269,14.727826,0.899397,-33.360714,294.500488,0.000000
119.620003,64.960747,-33.405193,-0.001397,0.003541,0.089940,288.959839,14.720315,0.899397,-33.405193,294.500488,0.000000
119.990005,64.937660,-33.494156,-0.001380,0.003541,0.089940,288.857147,14.715084,0.899397,-33.494156,294.500488,0.000000
120.360008,65.089592,-33.405193,-0.001384,0.003545,0.090044,289.532959,14.749513,0.900442,-33.405193,294.500488,0.000000
120.730003,65.130928,-33.494156,-0.001375,0.003545,0.090044,289.716827,14.758880,0.900442,-33.494156,294.500488,0.000000
121.100006,65.125343,-33.405193,-0.001380,0.003545,0.090044,289.691986,14.757614,0.900442,-33.405193,294.500488,0.000000
121.470009,65.136131,-33.494156,-0.001401,0.003545,0.090044,289.739990,14.760058,0.900442,-33.494156,294.500488,0.000000
121.840004,65.123100,-33.538635,-0.001380,0.003545,0.090044,289.682007,14.757106,0.900442,-33.538635,294.500488,0.000000
122.210007,65.101875,-33.538635,-0.001397,0.003545,0.090044,289.587616,14.752295,0.900442,-33.538635,294.500488,0.000000
122.580009,65.097404,-33.449677,-0.001380,0.003545,0.090044,289.567719,14.751283,0.900442,-33.449677,294.500488,0.000000
122.950005,65.073952,-33.494156,-0.001388,0.003545,0.090044,289.463379,14.745968,0.900442,-33.494156,294.500488,0.000000
123.320007,65.049004,-33.494156,-0.001397,0.003545,0.090044,289.352417,14.740315,0.900442,-33.494156,294.500488,0.000000
123.690002,65.040810,-33.538635,-0.001380,0.003545,0.090044,289.315979,14.738459,0.900442,-33.538635,294.500488,0.000000
124.060005,65.017357,-33.494156,-0.001371,0.003545,0.090044,289.211639,14.733144,0.900442,-33.494156,294.500488,0.000000
124.430008,65.003944,-33.538635,-0.001380,0.003545,0.090044,289.151978,14.730104,0.900442,-33.538635,294.500488,0.000000
124.800003,64.989052,-33.627598,-0.001375,0.003545,0.090044,289.085754,14.726729,0.900442,-33.627598,294.500488,0.000000
125.170006,64.984962,-33.627598,-0.001384,0.003545,0.090052,289.067535,14.725803,0.900525,-33.627598,294.500488,0.000000
125.540009,65.059425,-33.583118,-0.001380,0.003547,0.090105,289.398773,14.742677,0.901047,-33.583118,294.500488,0.000000
125.910004,65.078056,-33.583118,-0.001375,0.003547,0.090105,289.481659,14.746899,0.901047,-33.583118,294.500488,0.000000
126.280006,65.095543,-33.538635,-0.001367,0.003548,0.090122,289.559448,14.750860,0.901221,-33.538635,294.500488,0.000000
126.650009,65.099648,-33.627598,-0.001388,0.003548,0.090122,289.577698,14.751791,0.901221,-33.627598,294.500488,0.000000
127.020004,65.091454,-33.627598,-0.001380,0.003548,0.090122,289.541260,14.749934,0.901221,-33.627598,294.500488,0.000000
127.390007,65.080650,-33.672081,-0.001371,0.003548,0.090122,289.493195,14.747486,0.901221,-33.672081,294.500488,0.000000
127.760010,65.068733,-33.627598,-0.001380,0.003540,0.089914,289.440186,14.744785,0.899140,-33.627598,0.089992,0.000000
128.130005,64.948463,-33.583118,-0.001384,0.003527,0.089576,288.905182,14.717532,0.895756,-33.583118,0.089377,0.000000
128.500000,64.942879,-33.627598,-0.001384,0.003510,0.089142,288.880341,14.716267,0.891418,-33.627598,0.088752,0.000000
128.870010,64.853874,-33.672081,-0.001371,0.003487,0.088579,288.484436,14.696098,0.885787,-33.672081,0.088136,0.000000
129.240005,64.805473,-33.672081,-0.001367,0.003466,0.088032,288.269135,14.685130,0.880321,-33.672081,0.087520,0.000000
129.610001,64.852760,-33.716560,-0.001375,0.003438,0.087321,288.479492,14.695846,0.873206,-33.716560,0.086904,0.000000
129.980011,64.768242,-33.627598,-0.001367,0.003417,0.086801,288.103516,14.676693,0.868005,-33.627598,0.086289,0.000000
130.350006,64.762642,-33.716560,-0.001362,0.003396,0.086254,288.078613,14.675425,0.862540,-33.716560,0.085673,0.000000
130.720001,64.696373,-33.716560,-0.001371,0.003371,0.085629,287.783844,14.660408,0.856295,-33.716560,0.085057,0.000000
131.090012,64.627846,-33.716560,-0.001362,0.003344,0.084944,287.479004,14.644879,0.849444,-33.716560,0.084442,0.000000
131.460007,64.554497,-33.761044,-0.001371,0.003321,0.084364,287.152740,14.628259,0.843638,-33.761044,0.083817,0.000000
131.830002,64.194038,-33.672081,-0.001358,0.003300,0.083817,285.549347,14.546577,0.838173,-33.672081,0.083202,0.000000
132.200012,63.511848,-33.716560,-0.001358,0.003279,0.083297,282.514801,14.391991,0.832972,-33.716560,0.082586,0.000000
132.570007,62.315788,-33.805523,-0.001358,0.003254,0.082655,277.194458,14.120959,0.826553,-33.805523,0.081970,0.000000
132.940002,61.153618,-33.805523,-0.001324,0.003233,0.082109,272.024872,13.857608,0.821088,-33.805523,0.081354,0.000000
133.310013,59.883080,-33.805523,-0.001319,0.003214,0.081624,266.373230,13.569700,0.816235,-33.805523,0.080739,0.000000
133.680008,57.971321,-33.716560,-0.001319,0.003186,0.080921,257.869324,13.136489,0.809211,-33.716560,0.080123,0.000000
134.050003,56.327667,-33.761044,-0.001315,0.003166,0.080409,250.557983,12.764031,0.804093,-33.761044,0.079507,0.000000
134.420013,54.493736,-33.805523,-0.001315,0.003146,0.079898,242.400238,12.348457,0.798976,-33.805523,0.078892,0.000000
134.790009,52.654587,-33.850002,-0.001324,0.003125,0.079386,234.219299,11.931701,0.793859,-33.850002,0.078267,0.000000
135.160004,49.451439,-33.805523,-0.001298,0.003091,0.078518,219.970993,11.205855,0.785184,-33.805523,0.077651,0.000000
135.530014,46.898453,-33.761044,-0.001306,0.003068,0.077938,208.614731,10.627341,0.779378,-33.761044,0.077035,0.000000
135.900009,44.382706,-33.761044,-0.001311,0.003045,0.077339,197.424133,10.057265,0.773390,-33.761044,0.076420,0.000000
136.270004,42.292580,-33.850002,-0.001315,0.003027,0.076897,188.126785,9.583635,0.768970,-33.850002,0.075804,0.000000
136.639999,40.677971,-33.850002,-0.001319,0.003013,0.076533,180.944656,9.217760,0.765328,-33.850002,0.075188,0.000000
137.010010,37.098724,-33.850002,-0.001311,0.002980,0.075691,165.023361,8.406691,0.756911,-33.850002,0.074572,0.000000
137.380005,35.295700,-33.805523,-0.001324,0.002960,0.075188,157.003113,7.998120,0.751885,-33.805523,0.073957,0.000000
137.750000,31.598038,-33.805523,-0.001306,0.002927,0.074347,140.555084,7.160218,0.743474,-33.805523,0.073341,0.000000
138.120010,29.341461,-33.938965,-0.001319,0.002906,0.073818,130.517334,6.648870,0.738183,-33.938965,0.072717,0.000000
138.490005,26.724800,-33.938965,-0.001315,0.002884,0.073246,118.877846,6.055926,0.732460,-33.938965,0.072101,0.000000
138.860001,23.774124,-33.894485,-0.001306,0.002854,0.072500,105.752586,5.387294,0.724997,-33.894485,0.071485,0.000000
139.230011,22.017639,-33.894485,-0.001306,0.002839,0.072118,97.939354,4.989269,0.721181,-33.894485,0.070870,0.000000
139.600006,19.351830,-33.894485,-0.001315,0.002812,0.071425,86.081238,4.385187,0.714248,-33.894485,0.070254,0.000000
139.970001,16.282730,-33.983448,-0.001315,0.002786,0.070765,72.429199,3.689719,0.707654,-33.983448,0.069638,0.000000
140.340012,13.838852,-33.938965,-0.001324,0.002761,0.070124,61.558289,3.135929,0.701235,-33.938965,0.069022,0.000000
140.710007,11.506310,-33.938965,-0.001311,0.002742,0.069647,51.182621,2.607367,0.696466,-33.938965,0.068407,0.000000
141.080002,8.571648,-33.983448,-0.001319,0.002714,0.068936,38.128593,1.942363,0.689358,-33.983448,0.067791,0.000000
141.450012,7.064278,-33.938965,-0.001319,0.002694,0.068424,31.423477,1.600788,0.684241,-33.938965,0.067167,0.000000
141.820007,3.146179,-34.027927,-0.001315,0.002661,0.067583,13.994904,0.712934,0.675831,-34.027927,0.066551,0.000000
142.190002,1.191597,-34.027927,-0.001311,0.002642,0.067105,5.300488,0.270020,0.671054,-34.027927,0.065935,0.000000
142.560013,-1.639553,-33.983448,-0.001306,0.002610,0.066291,-7.293096,-0.371528,0.662909,-33.983448,0.065319,0.000000
142.930008,-2.488934,-33.938965,-0.001315,0.002588,0.065735,-11.071329,-0.564000,0.657353,-33.938965,0.064704,0.000000
143.300003,-0.287094,-34.027927,-0.001311,0.002570,0.065276,-1.277058,-0.065056,0.652758,-34.027927,0.064088,0.000000
143.670013,-0.189163,-34.027927,-0.001306,0.002545,0.064643,-0.841440,-0.042865,0.646430,-34.027927,0.063472,0.000000
144.040009,-0.198097,-34.072407,-0.001306,0.002518,0.063966,-0.881180,-0.044889,0.639662,-34.072407,0.062857,0.000000
144.410004,-0.177994,-34.072407,-0.001306,0.002497,0.063411,-0.791756,-0.040334,0.634114,-34.072407,0.062240,0.000000
144.780014,-0.200706,-34.027927,-0.001315,0.002476,0.062882,-0.892787,-0.045481,0.628822,-34.027927,0.061617,0.000000
145.150009,-0.226768,-34.027927,-0.001328,0.002445,0.062093,-1.008717,-0.051386,0.620935,-34.027927,0.061000,0.000000
145.520004,-0.270340,-34.116890,-0.001319,0.002416,0.061356,-1.202532,-0.061260,0.613562,-34.116890,0.060385,0.000000
145.889999,-0.244644,-34.072407,-0.001315,0.002394,0.060819,-1.088232,-0.055437,0.608187,-34.072407,0.059769,0.000000
146.260010,-0.247627,-34.072407,-0.001328,0.002371,0.060212,-1.101501,-0.056113,0.602116,-34.072407,0.059153,0.000000
146.630005,-0.249489,-34.072407,-0.001337,0.002346,0.059578,-1.109782,-0.056535,0.595780,-34.072407,0.058538,0.000000
147.000000,-0.236824,-34.072407,-0.001341,0.002327,0.059101,-1.053446,-0.053665,0.591011,-34.072407,0.057922,0.000000
147.370010,-0.274063,-34.161369,-0.001384,0.002294,0.058268,-1.219094,-0.062104,0.582685,-34.161369,0.057306,0.000000
147.740005,-0.284492,-34.161369,-0.001380,0.002272,0.057705,-1.265486,-0.064467,0.577053,-34.161369,0.056690,0.000000
148.110001,-0.280022,-34.161369,-0.001414,0.002256,0.057297,-1.245599,-0.063454,0.572973,-34.161369,0.056066,0.000000
148.480011,-0.243904,-34.116890,-0.001427,0.002230,0.056630,-1.084940,-0.055269,0.566296,-34.116890,0.055450,0.000000
148.850006,-0.257309,-34.205853,-0.001470,0.002205,0.056014,-1.144567,-0.058307,0.560142,-34.205853,0.054835,0.000000
149.220001,-0.281883,-34.250332,-0.001500,0.002172,0.055181,-1.253879,-0.063876,0.551815,-34.250332,0.054219,0.000000
149.590012,-0.270340,-34.205853,-0.001518,0.002148,0.054557,-1.202532,-0.061260,0.545570,-34.205853,0.053603,0.000000
149.960007,-0.276672,-34.116890,-0.001552,0.002123,0.053932,-1.230700,-0.062695,0.539325,-34.116890,0.052987,0.000000
150.330002,-0.284859,-34.161369,-0.001565,0.002104,0.053447,-1.267115,-0.064550,0.534473,-34.161369,0.052372,0.000000
150.700012,-0.270340,-34.205853,-0.001647,0.002081,0.052848,-1.202532,-0.061260,0.528485,-34.205853,0.051756,0.000000
151.070007,-0.280022,-34.250332,-0.001673,0.002054,0.052163,-1.245599,-0.063454,0.521634,-34.250332,0.051140,0.000000
151.440002,-0.258797,-34.294815,-0.001677,0.002025,0.051426,-1.151185,-0.058644,0.514261,-34.294815,0.050515,0.000000
151.810013,-0.283371,-34.250332,-0.001703,0.002004,0.050897,-1.260497,-0.064213,0.508970,-34.250332,0.049900,0.000000
152.180008,-0.278908,-34.294815,-0.001699,0.001981,0.050316,-1.240644,-0.063201,0.503164,-34.294815,0.049285,0.000000
152.550003,-0.269226,-34.250332,-0.001733,0.001959,0.049762,-1.197577,-0.061007,0.497615,-34.250332,0.049700,0.000000
152.600006,-0.272949,-34.205853,-0.001720,0.001959,0.049762,-1.214139,-0.061851,0.497615,-34.205853,0.049700,0.000000