File: Data/compression 26/AutoNoHeating-17-26-reverse-1-3_09262024_173401.csv
Time (sec),S:Load (lbs),S:HL1 (DIM),S:LVDT (in),S:Position (in),Ch:Position (mm),Ch:Load (N),Ch:Stress (MPa),Ch:Strain (mm/mm),Ch:HL1 (DIM),Set Point (),Cycles ()
0.110000,-0.166077,-25.042776,-0.010274,-0.005840,-0.148330,-0.738746,-0.037634,-1.483300,-25.042776,-0.148122,0.000000
0.470000,-0.170914,-24.998295,-0.010279,-0.005769,-0.146535,-0.760262,-0.038730,-1.465352,-24.998295,-0.145677,0.000000
0.830000,-0.167564,-24.998295,-0.010171,-0.005553,-0.141037,-0.745364,-0.037971,-1.410365,-24.998295,-0.139675,0.000000
1.190000,-0.127350,-25.087255,-0.009934,-0.005320,-0.135122,-0.566480,-0.028858,-1.351223,-25.087255,-0.133692,0.000000
1.550000,-0.146339,-25.042776,-0.009688,-0.005083,-0.129113,-0.650950,-0.033161,-1.291126,-25.042776,-0.127690,0.000000
1.910000,-0.149689,-25.087255,-0.009451,-0.004842,-0.122981,-0.665849,-0.033920,-1.229811,-25.087255,-0.121689,0.000000
2.270000,-0.173523,-25.042776,-0.009214,-0.004610,-0.117093,-0.771869,-0.039321,-1.170925,-25.042776,-0.115688,0.000000
2.630000,-0.191025,-25.087255,-0.008968,-0.004377,-0.111170,-0.849721,-0.043287,-1.111699,-25.087255,-0.109686,0.000000
2.990000,-0.159370,-25.131737,-0.008727,-0.004132,-0.104943,-0.708915,-0.036114,-1.049430,-25.131737,-0.103703,0.000000
3.350000,-0.150810,-25.131737,-0.008498,-0.003899,-0.099045,-0.670837,-0.034174,-0.990454,-25.131737,-0.097702,0.000000
3.710000,-0.144104,-25.220699,-0.008248,-0.003665,-0.093088,-0.641007,-0.032654,-0.930880,-25.220699,-0.091700,0.000000
4.070000,-0.161606,-25.131737,-0.007972,-0.003425,-0.086983,-0.718859,-0.036620,-0.869829,-25.131737,-0.085699,0.000000
4.430000,-0.158630,-25.131737,-0.007739,-0.003188,-0.080982,-0.705623,-0.035946,-0.809816,-25.131737,-0.079715,0.000000
4.790000,-0.139267,-25.131737,-0.007515,-0.002955,-0.075058,-0.619490,-0.031558,-0.750583,-25.131737,-0.073714,0.000000
5.150000,-0.141869,-25.131737,-0.007265,-0.002720,-0.069083,-0.631063,-0.032148,-0.690834,-25.131737,-0.067713,0.000000
5.510000,-0.140381,-25.131737,-0.007032,-0.002486,-0.063134,-0.624445,-0.031811,-0.631343,-25.131737,-0.061712,0.000000
5.870000,-0.164589,-25.176218,-0.006786,-0.002246,-0.057046,-0.732128,-0.037296,-0.570459,-25.176218,-0.055711,0.000000
6.230000,-0.146713,-25.176218,-0.006541,-0.002011,-0.051071,-0.652613,-0.033246,-0.510711,-25.176218,-0.049727,0.000000
6.590000,-0.165703,-25.265181,-0.006295,-0.001772,-0.045018,-0.737083,-0.037549,-0.450175,-25.265181,-0.043725,0.000000
6.950000,-0.107986,-25.220699,-0.006062,-0.001535,-0.038990,-0.480348,-0.024470,-0.389905,-25.220699,-0.037724,0.000000
7.310000,-0.123253,-25.220699,-0.005829,-0.001308,-0.033223,-0.548256,-0.027929,-0.332231,-25.220699,-0.031723,0.000000
7.670001,-0.114685,-25.220699,-0.005588,-0.001066,-0.027083,-0.510145,-0.025988,-0.270832,-25.220699,-0.025722,0.000000
8.030001,-0.146339,-25.176218,-0.005346,-0.000834,-0.021186,-0.650950,-0.033161,-0.211863,-25.176218,-0.019738,0.000000
8.390000,-0.176498,-25.265181,-0.005075,-0.000592,-0.015029,-0.785104,-0.039995,-0.150291,-25.265181,-0.013737,0.000000
8.750000,-0.156395,-25.176218,-0.004825,-0.000359,-0.009115,-0.695680,-0.035440,-0.091148,-25.176218,-0.007736,0.000000
9.110001,-0.095695,-25.220699,-0.004557,-0.000119,-0.003018,-0.425675,-0.021685,-0.030181,-25.220699,-0.001734,0.000000
9.470000,0.192520,-25.265181,-0.004329,0.000096,0.002428,0.856372,0.043626,0.024284,-25.265181,0.003954,0.000000
9.830001,0.106873,-25.265181,-0.004312,-0.000000,-0.000000,0.475393,0.024218,-0.000000,-25.265181,0.000252,0.000000
10.190001,0.119904,-25.354141,-0.004316,-0.000000,-0.000000,0.533358,0.027171,-0.000000,-25.354141,0.000599,0.000000
10.550000,0.128471,-25.265181,-0.004316,-0.000000,-0.000000,0.571469,0.029112,-0.000000,-25.265181,0.001206,0.000000
10.910001,0.115067,-25.309662,-0.004320,0.000000,0.000009,0.511841,0.026074,0.000091,-25.309662,0.001804,0.000000
11.270000,0.553719,-25.309662,-0.004277,0.000056,0.001422,2.463063,0.125474,0.014224,-25.309662,0.002403,0.000000
11.630000,0.803207,-25.265181,-0.004268,0.000082,0.002090,3.572845,0.182009,0.020900,-25.265181,0.003001,0.000000
11.990001,1.037804,-25.354141,-0.004238,0.000104,0.002654,4.616381,0.235170,0.026540,-25.354141,0.003599,0.000000
12.350000,1.318947,-25.354141,-0.004221,0.000118,0.003001,5.866969,0.298878,0.030007,-25.354141,0.004207,0.000000
12.710001,1.693184,-25.309662,-0.004195,0.000144,0.003652,7.531658,0.383681,0.036517,-25.309662,0.004805,0.000000
13.070001,2.161995,-25.398623,-0.004178,0.000168,0.004258,9.617034,0.489915,0.042580,-25.398623,0.005403,0.000000
13.430000,2.589478,-25.354141,-0.004156,0.000191,0.004857,11.518571,0.586784,0.048568,-25.354141,0.006001,0.000000
13.790001,2.872856,-25.398623,-0.004152,0.000214,0.005446,12.779102,0.650998,0.054465,-25.398623,0.006600,0.000000
14.150001,3.474236,-25.354141,-0.004126,0.000239,0.006071,15.454171,0.787273,0.060710,-25.354141,0.007198,0.000000
14.510000,3.886452,-25.398623,-0.004087,0.000261,0.006618,17.287800,0.880683,0.066175,-25.398623,0.007805,0.000000
14.870001,4.304253,-25.443104,-0.004096,0.000287,0.007293,19.146273,0.975358,0.072935,-25.443104,0.008404,0.000000
15.230000,4.821106,-25.443104,-0.004049,0.000309,0.007848,21.445351,1.092478,0.078484,-25.443104,0.009002,0.000000
15.590001,5.187897,-25.487585,-0.004057,0.000329,0.008369,23.076918,1.175594,0.083692,-25.487585,0.009601,0.000000
15.950001,5.457497,-25.398623,-0.004036,0.000349,0.008872,24.276157,1.236686,0.088718,-25.398623,0.010199,0.000000
16.310001,6.289749,-25.487585,-0.003997,0.000383,0.009739,27.978201,1.425277,0.097393,-25.487585,0.010806,0.000000
16.670000,6.532158,-25.443104,-0.003980,0.000404,0.010251,29.056490,1.480208,0.102510,-25.443104,0.011405,0.000000
17.030001,6.572380,-25.443104,-0.003954,0.000422,0.010720,29.235407,1.489323,0.107196,-25.443104,0.012003,0.000000
17.390001,7.375587,-25.532066,-0.003945,0.000453,0.011500,32.808250,1.671332,0.115000,-25.532066,0.012601,0.000000
17.750000,7.356964,-25.487585,-0.003936,0.000469,0.011925,32.725410,1.667112,0.119247,-25.487585,0.013199,0.000000
18.110001,7.786682,-25.532066,-0.003915,0.000492,0.012506,34.636890,1.764487,0.125060,-25.532066,0.013807,0.000000
18.470001,8.430145,-25.532066,-0.003880,0.000524,0.013312,37.499161,1.910298,0.133122,-25.532066,0.014405,0.000000
18.830002,8.574997,-25.487585,-0.003850,0.000545,0.013841,38.143490,1.943122,0.138414,-25.487585,0.015003,0.000000
19.190001,8.955933,-25.576548,-0.003829,0.000569,0.014457,39.837978,2.029443,0.144568,-25.576548,0.015601,0.000000
19.550001,9.031525,-25.487585,-0.003829,0.000590,0.014978,40.174229,2.046573,0.149776,-25.487585,0.016200,0.000000
19.910002,9.490662,-25.532066,-0.003798,0.000616,0.015645,42.216572,2.150615,0.156452,-25.532066,0.016807,0.000000
20.270000,9.674614,-25.487585,-0.003781,0.000641,0.016287,43.034832,2.192299,0.162872,-25.487585,0.017405,0.000000
20.630001,9.782974,-25.443104,-0.003747,0.000665,0.016903,43.516842,2.216854,0.169026,-25.443104,0.018004,0.000000
20.990002,9.978844,-25.621027,-0.003734,0.000687,0.017440,44.388115,2.261238,0.174400,-25.621027,0.018602,0.000000
21.350000,10.299454,-25.576548,-0.003704,0.000713,0.018108,45.814259,2.333889,0.181077,-25.576548,0.019201,0.000000
21.710001,10.115875,-25.665508,-0.003691,0.000726,0.018438,44.997662,2.292290,0.184377,-25.665508,0.019808,0.000000
22.070002,10.874771,-25.621027,-0.003665,0.000766,0.019444,48.373398,2.464258,0.194438,-25.621027,0.020406,0.000000
22.430000,10.904182,-25.621027,-0.003630,0.000786,0.019972,48.504227,2.470923,0.199721,-25.621027,0.021005,0.000000
22.790001,10.683372,-25.621027,-0.003613,0.000801,0.020354,47.522015,2.420887,0.203544,-25.621027,0.021603,0.000000
23.150002,11.349541,-25.576548,-0.003604,0.000835,0.021204,50.485279,2.571843,0.212037,-25.576548,0.022201,0.000000
23.510000,11.052765,-25.665508,-0.003574,0.000845,0.021472,49.165154,2.504592,0.214725,-25.665508,0.022799,0.000000
23.870001,11.598663,-25.621027,-0.003557,0.000877,0.022279,51.593430,2.628295,0.222794,-25.621027,0.023407,0.000000
24.230001,12.017952,-25.665508,-0.003523,0.000906,0.023025,53.458519,2.723307,0.230250,-25.665508,0.024005,0.000000
24.590002,11.874214,-25.709990,-0.003514,0.000923,0.023450,52.819141,2.690735,0.234505,-25.709990,0.024603,0.000000
24.950001,12.070457,-25.665508,-0.003488,0.000946,0.024040,53.692078,2.735205,0.240401,-25.665508,0.025202,0.000000
25.310001,12.280846,-25.665508,-0.003458,0.000972,0.024681,54.627930,2.782880,0.246813,-25.665508,0.025800,0.000000
25.670002,12.250687,-25.754471,-0.003458,0.000989,0.025132,54.493774,2.776045,0.251325,-25.754471,0.026407,0.000000
26.030001,12.804771,-25.621027,-0.003428,0.001018,0.025870,56.958469,2.901603,0.258698,-25.621027,0.027006,0.000000
26.390001,13.158531,-25.754471,-0.003397,0.001047,0.026590,58.532070,2.981766,0.265896,-25.754471,0.027604,0.000000
26.750002,13.304123,-25.709990,-0.003367,0.001073,0.027248,59.179695,3.014757,0.272482,-25.709990,0.028203,0.000000
27.110001,13.193901,-25.709990,-0.003359,0.001091,0.027717,58.689404,2.989781,0.277168,-25.709990,0.028801,0.000000
27.470001,13.151825,-25.709990,-0.003337,0.001109,0.028176,58.502239,2.980246,0.281763,-25.709990,0.029408,0.000000
27.830002,13.782997,-25.665508,-0.003311,0.001139,0.028931,61.309834,3.123272,0.289310,-25.665508,0.030007,0.000000
28.190001,13.997108,-25.754471,-0.003294,0.001163,0.029546,62.262249,3.171790,0.295464,-25.754471,0.030605,0.000000
28.550001,14.241013,-25.709990,-0.003268,0.001188,0.030163,63.347187,3.227059,0.301626,-25.709990,0.031203,0.000000
28.910002,14.235802,-25.798952,-0.003247,0.001206,0.030622,63.324009,3.225879,0.306221,-25.798952,0.031801,0.000000
29.270000,14.468163,-25.843433,-0.003216,0.001232,0.031290,64.357605,3.278533,0.312897,-25.843433,0.032409,0.000000
29.630001,14.955597,-25.798952,-0.003199,0.001263,0.032070,66.525818,3.388987,0.320702,-25.798952,0.033007,0.000000
29.990002,14.853943,-25.754471,-0.003186,0.001281,0.032547,66.073639,3.365952,0.325471,-25.754471,0.033605,0.000000
30.350002,14.766434,-25.843433,-0.003165,0.001300,0.033024,65.684380,3.346122,0.330240,-25.843433,0.034203,0.000000
30.710001,15.286263,-25.843433,-0.003156,0.001324,0.033631,67.996689,3.463917,0.336311,-25.843433,0.034802,0.000000
31.070002,15.042732,-25.843433,-0.003126,0.001347,0.034212,66.913414,3.408732,0.342124,-25.843433,0.035400,0.000000
31.430002,15.465752,-25.887913,-0.003109,0.001367,0.034724,68.795097,3.504589,0.347241,-25.887913,0.036007,0.000000
31.790001,15.443405,-25.843433,-0.003091,0.001385,0.035175,68.695694,3.499526,0.351753,-25.843433,0.036606,0.000000
32.150002,16.297630,-25.798952,-0.003061,0.001421,0.036103,72.495483,3.693096,0.361026,-25.798952,0.037204,0.000000
32.510002,16.011276,-25.887913,-0.003044,0.001438,0.036528,71.221710,3.628207,0.365280,-25.887913,0.037803,0.000000
32.870003,16.379181,-25.843433,-0.003005,0.001467,0.037256,72.858238,3.711575,0.372562,-25.843433,0.038401,0.000000
33.230003,16.525894,-25.843433,-0.002975,0.001490,0.037855,73.510849,3.744821,0.378550,-25.843433,0.039008,0.000000
33.590000,16.829750,-25.932394,-0.002966,0.001515,0.038470,74.862465,3.813676,0.384704,-25.932394,0.039607,0.000000
33.950001,17.266541,-25.887913,-0.002945,0.001539,0.039103,76.805405,3.912654,0.391033,-25.887913,0.040205,0.000000
34.310001,17.302292,-25.932394,-0.002923,0.001560,0.039615,76.964439,3.920755,0.396150,-25.932394,0.040803,0.000000
34.670002,17.541351,-25.887913,-0.002915,0.001587,0.040300,78.027824,3.974927,0.403000,-25.887913,0.041401,0.000000
35.030003,17.807602,-25.932394,-0.002889,0.001607,0.040821,79.212166,4.035260,0.408208,-25.932394,0.042009,0.000000
35.390003,18.441376,-25.932394,-0.002884,0.001636,0.041557,82.031334,4.178875,0.415574,-25.932394,0.042607,0.000000
35.750000,18.378448,-25.976875,-0.002846,0.001655,0.042043,81.751419,4.164616,0.420434,-25.976875,0.043205,0.000000
36.110001,18.490532,-26.021357,-0.002820,0.001679,0.042650,82.249992,4.190014,0.426505,-26.021357,0.043804,0.000000
36.470001,18.615273,-25.932394,-0.002807,0.001700,0.043171,82.804871,4.218281,0.431705,-25.932394,0.044402,0.000000
36.830002,18.939240,-25.976875,-0.002772,0.001723,0.043752,84.245941,4.291693,0.437519,-25.976875,0.045009,0.000000
37.190002,18.960464,-26.021357,-0.002764,0.001741,0.044229,84.340355,4.296503,0.442288,-26.021357,0.045608,0.000000
37.550003,19.950600,-25.976875,-0.002742,0.001776,0.045122,88.744698,4.520871,0.451220,-25.976875,0.046206,0.000000
37.910004,20.137535,-26.021357,-0.002712,0.001799,0.045703,89.576233,4.563231,0.457034,-26.021357,0.046805,0.000000
38.270000,19.729782,-26.021357,-0.002686,0.001812,0.046033,87.762451,4.470833,0.460326,-26.021357,0.047403,0.000000
38.630001,20.662209,-25.976875,-0.002660,0.001846,0.046891,91.910095,4.682124,0.468911,-25.976875,0.048002,0.000000
38.990002,20.620499,-26.065838,-0.002665,0.001865,0.047360,91.724556,4.672672,0.473596,-26.065838,0.048609,0.000000
39.350002,20.493896,-26.065838,-0.002660,0.001884,0.047845,91.161407,4.643983,0.478449,-26.065838,0.049207,0.000000
39.710003,21.747299,-26.110319,-0.002608,0.001919,0.048738,96.736816,4.928008,0.487381,-26.110319,0.049805,0.000000
40.070004,21.988968,-26.021357,-0.002600,0.001940,0.049276,97.811813,4.982771,0.492763,-26.021357,0.050403,0.000000
40.430000,22.333412,-26.065838,-0.002578,0.001966,0.049944,99.343979,5.060823,0.499440,-26.065838,0.051002,0.000000
40.790001,22.346817,-26.110319,-0.002548,0.001984,0.050386,99.403610,5.063861,0.503860,-26.110319,0.051609,0.000000
41.150002,22.519226,-26.065838,-0.002527,0.002008,0.051011,100.170517,5.102930,0.510105,-26.065838,0.052207,0.000000
41.510002,22.829414,-26.110319,-0.002501,0.002027,0.051479,101.550308,5.173219,0.514791,-26.110319,0.052805,0.000000
41.870003,23.513466,-26.110319,-0.002466,0.002058,0.052268,104.593117,5.328228,0.522679,-26.110319,0.053404,0.000000
42.230003,23.444199,-26.154799,-0.002453,0.002074,0.052684,104.285004,5.312531,0.526842,-26.154799,0.054002,0.000000
42.590000,24.464127,-26.154799,-0.002445,0.002107,0.053525,108.821869,5.543651,0.535252,-26.154799,0.054609,0.000000
42.950001,24.076118,-26.110319,-0.002423,0.002124,0.053959,107.095924,5.455726,0.539590,-26.110319,0.055208,0.000000
43.310001,25.269569,-26.199280,-0.002397,0.002154,0.054714,112.404655,5.726166,0.547137,-26.199280,0.055806,0.000000
43.670002,25.810257,-26.154799,-0.002367,0.002183,0.055442,114.809753,5.848688,0.554419,-26.154799,0.056405,0.000000
44.030003,25.588692,-26.154799,-0.002354,0.002198,0.055832,113.824188,5.798481,0.558325,-26.154799,0.057003,0.000000
44.390003,25.628914,-26.199280,-0.002345,0.002214,0.056240,114.003105,5.807595,0.562398,-26.199280,0.057610,0.000000
44.750004,26.459297,-26.199280,-0.002320,0.002243,0.056969,117.696831,5.995763,0.569687,-26.199280,0.058209,0.000000
45.110001,27.653870,-26.243761,-0.002294,0.002275,0.057775,123.010559,6.266456,0.577749,-26.243761,0.058807,0.000000
45.470001,27.933525,-26.199280,-0.002272,0.002297,0.058347,124.254524,6.329827,0.583472,-26.199280,0.059405,0.000000
45.830002,28.259346,-26.243761,-0.002246,0.002322,0.058972,125.703850,6.403659,0.589717,-26.243761,0.060003,0.000000
46.190002,28.085823,-26.199280,-0.002242,0.002333,0.059250,124.931984,6.364338,0.592495,-26.199280,0.060602,0.000000
46.550003,29.297523,-26.199280,-0.002203,0.002364,0.060038,130.321899,6.638914,0.600383,-26.199280,0.061209,0.000000
46.910004,29.035744,-26.243761,-0.002182,0.002377,0.060385,129.157440,6.579594,0.603850,-26.243761,0.061807,0.000000
47.270000,30.523743,-26.199280,-0.002182,0.002411,0.061244,135.776382,6.916779,0.612441,-26.199280,0.062406,0.000000
47.630001,31.236465,-26.288242,-0.002143,0.002434,0.061834,138.946732,7.078284,0.618338,-26.288242,0.063004,0.000000
47.990002,32.419121,-26.332724,-0.002134,0.002468,0.062675,144.207458,7.346278,0.626748,-26.332724,0.063603,0.000000
48.350002,32.653717,-26.243761,-0.002082,0.002489,0.063230,145.250992,7.399438,0.632297,-26.243761,0.064210,0.000000
48.710003,32.308525,-26.332724,-0.002087,0.002501,0.063525,143.715500,7.321216,0.635249,-26.332724,0.064808,0.000000
49.070004,32.833572,-26.288242,-0.002061,0.002522,0.064062,146.051025,7.440194,0.640624,-26.288242,0.065407,0.000000
49.430004,34.337959,-26.377205,-0.002035,0.002555,0.064903,152.742874,7.781093,0.649034,-26.377205,0.066005,0.000000
49.790001,35.167976,-26.288242,-0.002001,0.002580,0.065528,156.434967,7.969177,0.655279,-26.288242,0.066604,0.000000
50.150002,35.713501,-26.332724,-0.001988,0.002604,0.066143,158.861588,8.092794,0.661433,-26.332724,0.067211,0.000000
50.510002,36.333870,-26.421684,-0.001983,0.002627,0.066733,161.621124,8.233373,0.667330,-26.421684,0.067809,0.000000
50.870003,37.209694,-26.332724,-0.001957,0.002654,0.067410,165.516983,8.431837,0.674097,-26.332724,0.068407,0.000000
51.230003,37.339653,-26.421684,-0.001923,0.002673,0.067887,166.095078,8.461287,0.678866,-26.421684,0.069005,0.000000
51.590004,38.151421,-26.377205,-0.001914,0.002693,0.068390,169.705994,8.645235,0.683900,-26.377205,0.069603,0.000000
51.950001,39.177307,-26.332724,-0.001897,0.002718,0.069040,174.269363,8.877706,0.690403,-26.332724,0.070211,0.000000
52.310001,39.417488,-26.421684,-0.001897,0.002741,0.069613,175.337738,8.932130,0.696125,-26.421684,0.070809,0.000000
52.670002,40.931183,-26.377205,-0.001854,0.002766,0.070245,182.070999,9.275139,0.702454,-26.377205,0.071407,0.000000
53.030003,41.151253,-26.377205,-0.001841,0.002783,0.070697,183.049911,9.325007,0.706965,-26.377205,0.072006,0.000000
53.390003,42.940132,-26.421684,-0.001824,0.002815,0.071503,191.007248,9.730373,0.715027,-26.421684,0.072604,0.000000
53.750004,43.581360,-26.377205,-0.001807,0.002835,0.072006,193.859573,9.875678,0.720061,-26.377205,0.073203,0.000000
54.110004,44.998978,-26.510647,-0.001794,0.002864,0.072743,200.165451,10.196914,0.727434,-26.510647,0.073810,0.000000
54.470001,45.788780,-26.421684,-0.001768,0.002887,0.073341,203.678665,10.375886,0.733414,-26.421684,0.074408,0.000000
54.830002,46.729027,-26.466166,-0.001759,0.002912,0.073975,207.861099,10.588948,0.739750,-26.466166,0.075007,0.000000
55.190002,47.292793,-26.510647,-0.001742,0.002932,0.074460,210.368851,10.716700,0.744602,-26.510647,0.075605,0.000000
55.550003,47.728844,-26.466166,-0.001716,0.002949,0.074911,212.308502,10.815511,0.749114,-26.466166,0.076204,0.000000
55.910004,49.374359,-26.555128,-0.001699,0.002980,0.075692,219.628113,11.188390,0.756918,-26.555128,0.076811,0.000000
56.270004,50.290764,-26.466166,-0.001677,0.002998,0.076160,223.704483,11.396050,0.761604,-26.466166,0.077409,0.000000
56.630001,50.712662,-26.466166,-0.001686,0.003015,0.076576,225.581192,11.491653,0.765760,-26.466166,0.078007,0.000000
56.990002,52.481804,-26.510647,-0.001677,0.003045,0.077348,233.450729,11.892547,0.773481,-26.510647,0.078605,0.000000
57.350002,53.934799,-26.555128,-0.001625,0.003071,0.078016,239.913971,12.221800,0.780158,-26.555128,0.079204,0.000000
57.710003,55.012817,-26.555128,-0.001621,0.003096,0.078632,244.709229,12.466083,0.786319,-26.555128,0.079811,0.000000
58.070004,55.788849,-26.555128,-0.001617,0.003117,0.079178,248.161194,12.641933,0.791777,-26.555128,0.080409,0.000000
58.430004,56.913406,-26.599609,-0.001582,0.003138,0.079716,253.163483,12.896762,0.797159,-26.599609,0.081008,0.000000
58.790001,58.457642,-26.555128,-0.001582,0.003165,0.080401,260.032562,13.246691,0.804010,-26.555128,0.081606,0.000000
59.150002,60.181351,-26.510647,-0.001569,0.003193,0.081094,267.700012,13.637289,0.810944,-26.510647,0.082205,0.000000
59.510002,60.748100,-26.599609,-0.001552,0.003210,0.081546,270.221039,13.765717,0.815456,-26.599609,0.082812,0.000000
59.870003,62.108376,-26.599609,-0.001552,0.003234,0.082144,276.271851,14.073958,0.821436,-26.599609,0.083410,0.000000
60.230003,63.639198,-26.555128,-0.001535,0.003262,0.082863,283.081299,14.420849,0.828635,-26.555128,0.084009,0.000000
60.590004,63.858528,-26.599609,-0.001539,0.003275,0.083176,284.056915,14.470550,0.831761,-26.599609,0.084607,0.000000
60.950005,66.324013,-26.644089,-0.001509,0.003302,0.083879,295.023956,15.029237,0.838786,-26.644089,0.084000,0.000000
61.310001,65.052361,-26.688570,-0.001496,0.003295,0.083696,289.367340,14.741076,0.836961,-26.688570,294.500488,0.000000
61.670002,66.978645,-26.644089,-0.001492,0.003259,0.082785,297.935883,15.177578,0.827855,-26.644089,294.500488,0.000000
62.030003,65.825401,-26.644089,-0.001449,0.003219,0.081771,292.806000,14.916249,0.817711,-26.644089,294.500488,0.000000
62.390003,65.005058,-26.688570,-0.001462,0.003294,0.083670,289.156952,14.730357,0.836704,-26.688570,294.500488,0.000000
62.750004,64.961876,-26.688570,-0.001466,0.003326,0.084477,288.964844,14.720572,0.844766,-26.688570,294.500488,0.000000
63.110004,65.160713,-26.688570,-0.001470,0.003335,0.084702,289.849335,14.765629,0.847022,-26.688570,294.500488,0.000000
63.470001,64.962608,-26.688570,-0.001457,0.003339,0.084807,288.968109,14.720737,0.848066,-26.688570,294.500488,0.000000
63.830002,65.008415,-26.777533,-0.001449,0.003345,0.084971,289.171875,14.731118,0.849709,-26.777533,294.500488,0.000000
64.190002,65.554314,-26.688570,-0.001449,0.003356,0.085240,291.600159,14.854820,0.852396,-26.688570,294.500488,0.000000
64.550003,65.248222,-26.733051,-0.001449,0.003356,0.085240,290.238586,14.785459,0.852396,-26.733051,294.500488,0.000000
64.910004,64.851280,-26.688570,-0.001444,0.003356,0.085249,288.472900,14.695510,0.852487,-26.688570,294.500488,0.000000
65.270004,64.498634,-26.688570,-0.001449,0.003357,0.085257,286.904266,14.615600,0.852570,-26.688570,294.500488,0.000000
65.630005,67.011040,-26.733051,-0.001427,0.003376,0.085751,298.079987,15.184918,0.857513,-26.733051,294.500488,0.000000
65.990005,66.243568,-26.777533,-0.001431,0.003316,0.084217,294.666107,15.011007,0.842169,-26.777533,294.500488,0.000000
66.350006,65.854439,-26.822014,-0.001410,0.003316,0.084225,292.935181,14.922830,0.842253,-26.822014,294.500488,0.000000
66.710007,65.528252,-26.777533,-0.001418,0.003338,0.084798,291.484222,14.848913,0.847975,-26.777533,294.500488,0.000000
67.070000,65.234825,-26.777533,-0.001401,0.003349,0.085066,290.178986,14.782422,0.850663,-26.777533,294.500488,0.000000
67.430000,65.037834,-26.777533,-0.001406,0.003368,0.085535,289.302734,14.737784,0.855348,-26.777533,294.500488,0.000000
67.790001,65.355843,-26.777533,-0.001414,0.003382,0.085908,290.717316,14.809846,0.859080,-26.777533,294.500488,0.000000
68.150002,65.167046,-26.866495,-0.001397,0.003382,0.085908,289.877502,14.767064,0.859080,-26.866495,294.500488,0.000000
68.510002,64.977135,-26.822014,-0.001427,0.003383,0.085916,289.032745,14.724030,0.859164,-26.822014,294.500488,0.000000
68.870003,65.032249,-26.866495,-0.001397,0.003387,0.086029,289.277893,14.736519,0.860291,-26.866495,294.500488,0.000000
69.230003,64.894463,-26.866495,-0.001397,0.003387,0.086029,288.664978,14.705296,0.860291,-26.866495,294.500488,0.000000
69.590004,64.835258,-26.822014,-0.001406,0.003393,0.086194,288.401642,14.691880,0.861942,-26.822014,294.500488,0.000000
69.950005,65.122734,-26.910975,-0.001406,0.003394,0.086220,289.680389,14.757022,0.862199,-26.910975,294.500488,0.000000
70.310005,64.988686,-26.910975,-0.001388,0.003395,0.086228,289.084106,14.726646,0.862282,-26.910975,294.500488,0.000000
70.670006,64.845695,-26.910975,-0.001401,0.003395,0.086228,288.448059,14.694244,0.862282,-26.910975,294.500488,0.000000
71.030006,64.697853,-26.866495,-0.001397,0.003395,0.086237,287.790436,14.660743,0.862373,-26.866495,294.500488,0.000000
71.390007,65.787788,-26.955456,-0.001410,0.003409,0.086584,292.638702,14.907725,0.865840,-26.955456,294.500488,0.000000
71.750000,65.715172,-26.866495,-0.001388,0.003409,0.086584,292.315674,14.891271,0.865840,-26.866495,294.500488,0.000000
72.110001,65.570320,-26.955456,-0.001393,0.003409,0.086584,291.671356,14.858447,0.865840,-26.955456,294.500488,0.000000
72.470001,65.454140,-26.910975,-0.001410,0.003409,0.086584,291.154541,14.832120,0.865840,-26.910975,294.500488,0.000000
72.830002,65.313011,-26.955456,-0.001384,0.003409,0.086584,290.526794,14.800140,0.865840,-26.955456,294.500488,0.000000
73.190002,65.186043,-26.910975,-0.001393,0.003409,0.086584,289.962006,14.771369,0.865840,-26.910975,294.500488,0.000000
73.550003,65.043785,-26.955456,-0.001388,0.003409,0.086584,289.329193,14.739132,0.865840,-26.955456,294.500488,0.000000
73.910004,64.933571,-26.955456,-0.001388,0.003409,0.086584,288.838959,14.714157,0.865840,-26.955456,294.500488,0.000000
74.270004,64.787224,-26.955456,-0.001380,0.003409,0.086584,288.187958,14.680995,0.865840,-26.955456,294.500488,0.000000
74.630005,64.696739,-26.955456,-0.001397,0.003409,0.086584,287.785461,14.660490,0.865840,-26.955456,294.500488,0.000000
74.990005,64.547417,-26.955456,-0.001384,0.003410,0.086601,287.121246,14.626654,0.866014,-26.955456,294.500488,0.000000
75.350006,65.788902,-26.955456,-0.001367,0.003424,0.086966,292.643646,14.907978,0.869655,-26.955456,294.500488,0.000000
75.710007,65.754280,-27.044418,-0.001388,0.003424,0.086966,292.489655,14.900133,0.869655,-27.044418,294.500488,0.000000
76.070007,65.680550,-26.999937,-0.001375,0.003424,0.086966,292.161682,14.883426,0.869655,-26.999937,294.500488,0.000000
76.430000,65.589317,-27.044418,-0.001393,0.003424,0.086966,291.755859,14.862752,0.869655,-27.044418,294.500488,0.000000
76.790001,65.524895,-27.044418,-0.001388,0.003424,0.086966,291.469299,14.848153,0.869655,-27.044418,294.500488,0.000000
77.150002,65.416908,-27.044418,-0.001371,0.003424,0.086966,290.988953,14.823683,0.869655,-27.044418,294.500488,0.000000
77.510002,65.328651,-27.088900,-0.001388,0.003424,0.086975,290.596344,14.803684,0.869746,-27.088900,294.500488,0.000000
77.870003,65.257164,-27.088900,-0.001371,0.003424,0.086975,290.278351,14.787484,0.869746,-27.088900,294.500488,0.000000
78.230003,65.162575,-27.088900,-0.001371,0.003424,0.086975,289.857605,14.766050,0.869746,-27.088900,294.500488,0.000000
78.590004,65.060173,-27.088900,-0.001380,0.003424,0.086975,289.402100,14.742846,0.869746,-27.088900,294.500488,0.000000
78.950005,64.987938,-27.133381,-0.001371,0.003424,0.086975,289.080780,14.726477,0.869746,-27.133381,294.500488,0.000000
79.310005,64.909370,-27.088900,-0.001375,0.003425,0.086983,288.731293,14.708674,0.869829,-27.088900,294.500488,0.000000
79.670006,64.814034,-27.133381,-0.001371,0.003425,0.086983,288.307220,14.687070,0.869829,-27.133381,294.500488,0.000000
80.030006,64.743660,-27.133381,-0.001371,0.003425,0.086983,287.994171,14.671123,0.869829,-27.133381,294.500488,0.000000
80.390007,64.681847,-27.133381,-0.001375,0.003425,0.086983,287.719238,14.657116,0.869829,-27.133381,294.500488,0.000000
80.750008,65.833961,-27.133381,-0.001362,0.003436,0.087286,292.844086,14.918188,0.872865,-27.133381,294.500488,0.000000
81.110001,65.750175,-27.177860,-0.001367,0.003436,0.087286,292.471375,14.899202,0.872865,-27.177860,294.500488,0.000000
81.470001,65.648155,-27.133381,-0.001367,0.003436,0.087286,292.017578,14.876084,0.872865,-27.133381,294.500488,0.000000
81.830002,65.588570,-27.177860,-0.001358,0.003436,0.087286,291.752533,14.862582,0.872865,-27.177860,294.500488,0.000000
82.190002,65.538673,-27.133381,-0.001362,0.003436,0.087286,291.530579,14.851276,0.872865,-27.133381,294.500488,0.000000
82.550003,65.484306,-27.222342,-0.001358,0.003436,0.087286,291.288757,14.838956,0.872865,-27.222342,294.500488,0.000000
82.910004,65.376320,-27.222342,-0.001362,0.003436,0.087286,290.808380,14.814486,0.872865,-27.222342,294.500488,0.000000
83.270004,65.310783,-27.177860,-0.001354,0.003436,0.087286,290.516876,14.799635,0.872865,-27.177860,294.500488,0.000000
83.630005,65.249718,-27.222342,-0.001362,0.003436,0.087286,290.245239,14.785798,0.872865,-27.222342,294.500488,0.000000
83.990005,65.193489,-27.222342,-0.001354,0.003436,0.087286,289.995117,14.773055,0.872865,-27.222342,294.500488,0.000000
84.350006,65.101509,-27.177860,-0.001354,0.003436,0.087286,289.585968,14.752213,0.872865,-27.177860,294.500488,0.000000
84.710007,65.049751,-27.311304,-0.001367,0.003436,0.087286,289.355743,14.740485,0.872865,-27.311304,294.500488,0.000000
85.070007,64.989418,-27.266823,-0.001354,0.003436,0.087286,289.087372,14.726813,0.872865,-27.266823,294.500488,0.000000
85.430000,64.931709,-27.311304,-0.001350,0.003436,0.087286,288.830658,14.713736,0.872865,-27.311304,294.500488,0.000000
85.790001,64.849419,-27.266823,-0.001371,0.003436,0.087286,288.464630,14.695088,0.872865,-27.266823,294.500488,0.000000
86.150002,64.802116,-27.266823,-0.001362,0.003436,0.087286,288.254211,14.684369,0.872865,-27.266823,294.500488,0.000000
86.510002,64.735100,-27.311304,-0.001367,0.003436,0.087286,287.956116,14.669183,0.872865,-27.311304,294.500488,0.000000
86.870003,64.685188,-27.266823,-0.001341,0.003436,0.087286,287.734100,14.657873,0.872865,-27.266823,294.500488,0.000000
87.230003,64.624870,-27.355785,-0.001362,0.003436,0.087286,287.465790,14.644205,0.872865,-27.355785,294.500488,0.000000
87.590004,64.569389,-27.355785,-0.001354,0.003437,0.087296,287.218994,14.631633,0.872956,-27.355785,294.500488,0.000000
87.950005,66.329216,-27.266823,-0.001350,0.003444,0.087469,295.047089,15.030415,0.874689,-27.266823,294.500488,0.000000
88.310005,66.246178,-27.444746,-0.001354,0.003443,0.087460,294.677704,15.011598,0.874598,-27.444746,294.500488,0.000000
88.670006,66.153465,-27.311304,-0.001354,0.003443,0.087460,294.265320,14.990589,0.874598,-27.311304,294.500488,0.000000
89.030006,66.111015,-27.355785,-0.001350,0.003443,0.087460,294.076477,14.980970,0.874598,-27.355785,294.500488,0.000000
89.390007,66.032066,-27.400267,-0.001354,0.003443,0.087460,293.725311,14.963080,0.874598,-27.400267,294.500488,0.000000
89.750008,65.978447,-27.311304,-0.001350,0.003443,0.087460,293.486786,14.950930,0.874598,-27.311304,294.500488,0.000000
90.110001,65.865623,-27.400267,-0.001350,0.003443,0.087460,292.984924,14.925364,0.874598,-27.400267,294.500488,0.000000
90.470001,65.838066,-27.400267,-0.001341,0.003443,0.087460,292.862335,14.919119,0.874598,-27.400267,294.500488,0.000000
90.830002,65.814980,-27.355785,-0.001341,0.003443,0.087460,292.759644,14.913888,0.874598,-27.355785,294.500488,0.000000
91.190002,65.768806,-27.400267,-0.001345,0.003443,0.087460,292.554260,14.903425,0.874598,-27.400267,294.500488,0.000000
91.550003,65.670128,-27.400267,-0.001354,0.003443,0.087460,292.115326,14.881064,0.874598,-27.400267,294.500488,0.000000
91.910004,65.613899,-27.489227,-0.001350,0.003443,0.087460,291.865204,14.868322,0.874598,-27.489227,294.500488,0.000000
92.270004,65.568840,-27.444746,-0.001350,0.003443,0.087460,291.664764,14.858112,0.874598,-27.444746,294.500488,0.000000
92.630005,65.536446,-27.444746,-0.001341,0.003443,0.087460,291.520660,14.850771,0.874598,-27.444746,294.500488,0.000000
92.990005,65.469032,-27.400267,-0.001350,0.003443,0.087460,291.220795,14.835495,0.874598,-27.400267,294.500488,0.000000
93.350006,65.389717,-27.400267,-0.001337,0.003443,0.087460,290.867981,14.817522,0.874598,-27.400267,294.500488,0.000000
93.710007,65.344292,-27.489227,-0.001337,0.003443,0.087460,290.665924,14.807228,0.874598,-27.489227,294.500488,0.000000
94.070007,65.304085,-27.444746,-0.001324,0.003443,0.087460,290.487091,14.798118,0.874598,-27.444746,294.500488,0.000000
94.430008,65.265724,-27.489227,-0.001337,0.003443,0.087460,290.316437,14.789425,0.874598,-27.489227,294.500488,0.000000
94.790001,65.205406,-27.489227,-0.001332,0.003443,0.087460,290.048126,14.775756,0.874598,-27.489227,294.500488,0.000000
95.150002,65.168159,-27.489227,-0.001337,0.003443,0.087460,289.882446,14.767316,0.874598,-27.489227,294.500488,0.000000
95.510002,65.170021,-27.533709,-0.001341,0.003452,0.087685,289.890747,14.767738,0.876854,-27.533709,294.500488,0.000000
95.870003,65.197212,-27.533709,-0.001341,0.003452,0.087685,290.011688,14.773900,0.876854,-27.533709,294.500488,0.000000
96.230003,65.153267,-27.533709,-0.001332,0.003452,0.087685,289.816193,14.763942,0.876854,-27.533709,294.500488,0.000000
96.590004,65.117149,-27.533709,-0.001341,0.003452,0.087685,289.655548,14.755756,0.876854,-27.533709,294.500488,0.000000
96.950005,65.102257,-27.533709,-0.001345,0.003453,0.087711,289.589294,14.752382,0.877112,-27.533709,294.500488,0.000000
97.310005,65.092201,-27.622671,-0.001341,0.003454,0.087720,289.544586,14.750103,0.877202,-27.622671,294.500488,0.000000
97.670006,65.115288,-27.489227,-0.001337,0.003455,0.087746,289.647278,14.755335,0.877460,-27.489227,294.500488,0.000000
98.030006,65.104118,-27.578190,-0.001341,0.003455,0.087746,289.597595,14.752804,0.877460,-27.578190,294.500488,0.000000
98.390007,65.089958,-27.622671,-0.001341,0.003455,0.087746,289.534607,14.749595,0.877460,-27.622671,294.500488,0.000000
98.750008,65.059425,-27.578190,-0.001345,0.003455,0.087746,289.398773,14.742677,0.877460,-27.578190,294.500488,0.000000
99.110008,65.036339,-27.622671,-0.001337,0.003456,0.087772,289.296082,14.737446,0.877725,-27.622671,294.500488,0.000000
99.470001,65.021446,-27.622671,-0.001350,0.003456,0.087772,289.229828,14.734070,0.877725,-27.622671,294.500488,0.000000
99.830002,65.191246,-27.667152,-0.001350,0.003459,0.087850,289.985138,14.772547,0.878504,-27.667152,294.500488,0.000000
100.190002,65.193855,-27.667152,-0.001341,0.003459,0.087850,289.996765,14.773139,0.878504,-27.667152,294.500488,0.000000
100.550003,65.184547,-27.533709,-0.001332,0.003459,0.087850,289.955353,14.771029,0.878504,-27.533709,294.500488,0.000000
100.910004,65.165184,-27.711632,-0.001341,0.003459,0.087850,289.869202,14.766642,0.878504,-27.711632,294.500488,0.000000
101.270004,65.143959,-27.667152,-0.001345,0.003459,0.087850,289.774811,14.761832,0.878504,-27.667152,294.500488,0.000000
101.630005,65.111565,-27.667152,-0.001328,0.003459,0.087850,289.630707,14.754492,0.878504,-27.667152,294.500488,0.000000
101.990005,65.090340,-27.756113,-0.001345,0.003459,0.087859,289.536285,14.749682,0.878588,-27.756113,294.500488,0.000000
102.350006,65.063530,-27.667152,-0.001337,0.003459,0.087859,289.417023,14.743607,0.878588,-27.667152,294.500488,0.000000
102.710007,65.049004,-27.756113,-0.001350,0.003459,0.087859,289.352417,14.740315,0.878588,-27.756113,294.500488,0.000000
103.070007,65.015114,-27.711632,-0.001345,0.003459,0.087859,289.201660,14.732635,0.878588,-27.711632,294.500488,0.000000
103.430008,64.992409,-27.711632,-0.001324,0.003459,0.087859,289.100677,14.727489,0.878588,-27.711632,294.500488,0.000000
103.790009,65.037834,-27.756113,-0.001337,0.003463,0.087954,289.302734,14.737784,0.879541,-27.756113,294.500488,0.000000
104.150002,65.183434,-27.756113,-0.001345,0.003463,0.087954,289.950378,14.770777,0.879541,-27.756113,294.500488,0.000000
104.510002,65.186409,-27.756113,-0.001345,0.003463,0.087954,289.963623,14.771451,0.879541,-27.756113,294.500488,0.000000
104.870003,65.160347,-27.711632,-0.001345,0.003463,0.087954,289.847687,14.765546,0.879541,-27.711632,294.500488,0.000000
105.230003,65.164070,-27.756113,-0.001337,0.003463,0.087954,289.864258,14.766389,0.879541,-27.756113,294.500488,0.000000
105.590004,65.139122,-27.800594,-0.001341,0.003463,0.087954,289.753296,14.760736,0.879541,-27.800594,294.500488,0.000000
105.950005,65.114174,-27.756113,-0.001328,0.003463,0.087954,289.642303,14.755083,0.879541,-27.756113,294.500488,0.000000
106.310005,65.079536,-27.889557,-0.001332,0.003463,0.087954,289.488251,14.747233,0.879541,-27.889557,294.500488,0.000000
106.670006,65.047508,-27.800594,-0.001328,0.003463,0.087963,289.345764,14.739976,0.879632,-27.800594,294.500488,0.000000
107.030006,65.044167,-27.845076,-0.001341,0.003463,0.087963,289.330902,14.739220,0.879632,-27.845076,294.500488,0.000000
107.390007,65.009529,-27.889557,-0.001337,0.003463,0.087963,289.176819,14.731370,0.879632,-27.889557,294.500488,0.000000
107.750008,65.169273,-27.800594,-0.001319,0.003467,0.088050,289.887421,14.767569,0.880495,-27.800594,294.500488,0.000000
108.110008,65.186043,-27.845076,-0.001337,0.003467,0.088050,289.962006,14.771369,0.880495,-27.845076,294.500488,0.000000
108.470009,65.177467,-27.845076,-0.001337,0.003467,0.088050,289.923859,14.769425,0.880495,-27.845076,294.500488,0.000000
108.830002,65.184547,-27.889557,-0.001332,0.003467,0.088050,289.955353,14.771029,0.880495,-27.889557,294.500488,0.000000
109.190002,65.152153,-27.889557,-0.001341,0.003467,0.088050,289.811249,14.763689,0.880495,-27.889557,294.500488,0.000000
109.550003,65.132042,-27.889557,-0.001341,0.003467,0.088050,289.721802,14.759132,0.880495,-27.889557,294.500488,0.000000
109.910004,65.100014,-27.889557,-0.001337,0.003467,0.088050,289.579315,14.751874,0.880495,-27.889557,294.500488,0.000000
110.270004,65.084755,-27.934038,-0.001332,0.003467,0.088050,289.511444,14.748417,0.880495,-27.934038,294.500488,0.000000
110.630005,65.104118,-27.934038,-0.001324,0.003468,0.088076,289.597595,14.752804,0.880760,-27.934038,294.500488,0.000000
110.990005,65.090340,-27.934038,-0.001328,0.003468,0.088076,289.536285,14.749682,0.880760,-27.934038,294.500488,0.000000
111.350006,65.069115,-27.845076,-0.001341,0.003468,0.088076,289.441864,14.744872,0.880760,-27.845076,294.500488,0.000000
111.710007,65.040810,-27.934038,-0.001332,0.003468,0.088076,289.315979,14.738459,0.880760,-27.934038,294.500488,0.000000
112.070007,65.038582,-27.889557,-0.001328,0.003468,0.088076,289.306061,14.737954,0.880760,-27.889557,294.500488,0.000000
112.430008,65.029274,-27.934038,-0.001337,0.003468,0.088076,289.264648,14.735844,0.880760,-27.934038,294.500488,0.000000
112.790009,65.004326,-27.978518,-0.001341,0.003468,0.088076,289.153687,14.730190,0.880760,-27.978518,294.500488,0.000000
113.150009,64.987556,-27.978518,-0.001315,0.003468,0.088093,289.079102,14.726391,0.880934,-27.978518,294.500488,0.000000
113.510002,65.299614,-28.067480,-0.001332,0.003472,0.088197,290.467194,14.797104,0.881971,-28.067480,294.500488,0.000000
113.870003,65.289925,-27.978518,-0.001332,0.003472,0.088197,290.424103,14.794909,0.881971,-27.978518,294.500488,0.000000
114.230003,65.309288,-27.978518,-0.001328,0.003472,0.088197,290.510223,14.799295,0.881971,-27.978518,294.500488,0.000000
114.590004,65.290306,-28.022999,-0.001345,0.003472,0.088197,290.425781,14.794995,0.881971,-28.022999,294.500488,0.000000
114.950005,65.306313,-27.978518,-0.001332,0.003472,0.088197,290.496979,14.798622,0.881971,-27.978518,294.500488,0.000000
115.310005,65.283592,-28.067480,-0.001332,0.003472,0.088197,290.395935,14.793474,0.881971,-28.067480,294.500488,0.000000
115.670006,65.272804,-28.022999,-0.001324,0.003472,0.088197,290.347931,14.791029,0.881971,-28.022999,294.500488,0.000000
116.030006,65.247108,-28.022999,-0.001345,0.003472,0.088197,290.233643,14.785206,0.881971,-28.022999,294.500488,0.000000
116.390007,65.239281,-28.022999,-0.001315,0.003472,0.088197,290.198822,14.783432,0.881971,-28.022999,294.500488,0.000000
116.750008,65.218437,-28.022999,-0.001324,0.003472,0.088197,290.106110,14.778709,0.881971,-28.022999,294.500488,0.000000
117.110008,65.210991,-28.022999,-0.001319,0.003472,0.088197,290.072968,14.777021,0.881971,-28.022999,294.500488,0.000000
117.470009,65.168907,-28.067480,-0.001345,0.003472,0.088197,289.885773,14.767486,0.881971,-28.067480,294.500488,0.000000
117.830002,65.162956,-28.067480,-0.001328,0.003472,0.088197,289.859314,14.766137,0.881971,-28.067480,294.500488,0.000000
118.190002,65.125343,-28.111961,-0.001345,0.003472,0.088197,289.691986,14.757614,0.881971,-28.111961,294.500488,0.000000
118.550003,65.109703,-28.022999,-0.001328,0.003472,0.088197,289.622437,14.754069,0.881971,-28.022999,294.500488,0.000000
118.910004,65.089592,-28.111961,-0.001311,0.003472,0.088197,289.532959,14.749513,0.881971,-28.111961,294.500488,0.000000
119.270004,65.056084,-28.156443,-0.001328,0.003472,0.088197,289.383911,14.741920,0.881971,-28.156443,294.500488,0.000000
119.630005,65.040443,-28.156443,-0.001328,0.003472,0.088197,289.314331,14.738375,0.881971,-28.156443,294.500488,0.000000
119.990005,65.013634,-28.156443,-0.001328,0.003472,0.088197,289.195099,14.732300,0.881971,-28.156443,294.500488,0.000000
120.350006,65.012886,-28.156443,-0.001328,0.003472,0.088197,289.191772,14.732131,0.881971,-28.156443,294.500488,0.000000
120.710007,64.984581,-28.156443,-0.001328,0.003473,0.088205,289.065857,14.725716,0.882055,-28.156443,294.500488,0.000000
121.070007,64.968575,-28.289885,-0.001328,0.003473,0.088205,288.994659,14.722089,0.882055,-28.289885,294.500488,0.000000
121.430008,64.939522,-28.156443,-0.001341,0.003473,0.088205,288.865417,14.715506,0.882055,-28.156443,1681.640991,0.000000
121.790009,64.928352,-28.200924,-0.001319,0.003467,0.088067,288.815735,14.712975,0.880669,-28.200924,0.088032,0.000000
122.150009,64.842339,-28.200924,-0.001324,0.003453,0.087695,288.433136,14.693484,0.876945,-28.200924,0.087425,0.000000
122.510002,64.790581,-28.200924,-0.001324,0.003436,0.087269,288.202911,14.681756,0.872691,-28.200924,0.086827,0.000000
122.870003,64.684456,-28.245403,-0.001315,0.003413,0.086697,287.730835,14.657707,0.866968,-28.245403,0.086228,0.000000
123.230003,64.636421,-28.200924,-0.001319,0.003392,0.086150,287.517151,14.646823,0.861503,-28.200924,0.085630,0.000000
123.590004,64.672905,-28.289885,-0.001302,0.003372,0.085639,287.679443,14.655089,0.856385,-28.289885,0.085031,0.000000
123.950005,64.604012,-28.200924,-0.001324,0.003343,0.084910,287.372986,14.639479,0.849103,-28.200924,0.084424,0.000000
124.310005,64.579445,-28.200924,-0.001311,0.003322,0.084373,287.263733,14.633911,0.843729,-28.200924,0.083826,0.000000
124.670006,64.566032,-28.289885,-0.001319,0.003300,0.083818,287.204071,14.630872,0.838180,-28.289885,0.083228,0.000000
125.030006,64.493050,-28.245403,-0.001311,0.003273,0.083141,286.879425,14.614334,0.831413,-28.245403,0.082630,0.000000
125.390007,64.483376,-28.289885,-0.001302,0.003254,0.082655,286.836395,14.612142,0.826553,-28.289885,0.082032,0.000000
125.750008,64.192543,-28.334366,-0.001311,0.003230,0.082040,285.542694,14.546238,0.820399,-28.334366,0.081424,0.000000
126.110008,63.545357,-28.289885,-0.001293,0.003208,0.081485,282.663849,14.399583,0.814850,-28.289885,0.080826,0.000000
126.470009,62.617043,-28.334366,-0.001293,0.003189,0.080999,278.534515,14.189224,0.809990,-28.334366,0.080228,0.000000
126.830009,61.502899,-28.289885,-0.001281,0.003167,0.080444,273.578552,13.936756,0.804442,-28.289885,0.079629,0.000000
127.190002,60.021606,-28.334366,-0.001250,0.003144,0.079854,266.989441,13.601090,0.798545,-28.334366,0.079031,0.000000
127.550003,58.924965,-28.334366,-0.001272,0.003126,0.079412,262.111328,13.352588,0.794124,-28.334366,0.078424,0.000000
127.910004,56.757759,-28.289885,-0.001255,0.003097,0.078675,252.471115,12.861492,0.786751,-28.289885,0.077825,0.000000
128.270004,55.110756,-28.378847,-0.001268,0.003078,0.078181,245.144882,12.488276,0.781808,-28.378847,0.077227,0.000000
128.630005,53.280914,-28.334366,-0.001268,0.003060,0.077721,237.005341,12.073627,0.777213,-28.334366,0.076628,0.000000
128.990005,51.364685,-28.378847,-0.001259,0.003040,0.077218,228.481537,11.639403,0.772179,-28.378847,0.076030,0.000000
129.350006,48.341026,-28.334366,-0.001268,0.003008,0.076394,215.031631,10.954233,0.763943,-28.334366,0.075431,0.000000
129.710007,45.693459,-28.378847,-0.001246,0.002984,0.075796,203.254654,10.354286,0.757955,-28.378847,0.074824,0.000000
130.070007,42.946091,-28.378847,-0.001255,0.002959,0.075154,191.033752,9.731723,0.751544,-28.378847,0.074226,0.000000
130.430008,40.883148,-28.378847,-0.001255,0.002942,0.074729,181.857330,9.264254,0.747290,-28.378847,0.073628,0.000000
130.790009,38.448578,-28.423328,-0.001255,0.002920,0.074166,171.027817,8.712572,0.741658,-28.423328,0.073030,0.000000
131.150009,36.073959,-28.378847,-0.001276,0.002890,0.073402,160.464981,8.174476,0.734020,-28.378847,0.072431,0.000000
131.510010,33.353775,-28.467808,-0.001268,0.002873,0.072969,148.365005,7.558074,0.729690,-28.467808,0.071824,0.000000
131.870010,30.452995,-28.467808,-0.001268,0.002845,0.072267,135.461685,6.900747,0.722665,-28.467808,0.071226,0.000000
132.230011,28.099228,-28.378847,-0.001259,0.002822,0.071685,124.991608,6.367376,0.716852,-28.378847,0.070627,0.000000
132.590012,25.474747,-28.467808,-0.001259,0.002800,0.071121,113.317329,5.772660,0.711212,-28.467808,0.070029,0.000000
132.950012,23.179070,-28.512289,-0.001250,0.002774,0.070471,103.105652,5.252452,0.704710,-28.512289,0.069430,0.000000
133.310013,20.974251,-28.467808,-0.001246,0.002758,0.070055,93.298126,4.752833,0.700546,-28.467808,0.068823,0.000000
133.670013,18.251465,-28.512289,-0.001259,0.002730,0.069344,81.186569,4.135841,0.693438,-28.512289,0.068225,0.000000
134.029999,15.185349,-28.467808,-0.001255,0.002704,0.068676,67.547806,3.441049,0.686762,-28.467808,0.067626,0.000000
134.389999,13.208427,-28.467808,-0.001255,0.002686,0.068216,58.754021,2.993073,0.682159,-28.467808,0.067028,0.000000
134.750000,10.849075,-28.556770,-0.001259,0.002665,0.067688,48.259098,2.458436,0.676875,-28.556770,0.066429,0.000000
135.110001,7.523415,-28.556770,-0.001250,0.002633,0.066872,33.465820,1.704830,0.668723,-28.556770,0.065822,0.000000
135.470001,5.540535,-28.601252,-0.001263,0.002613,0.066369,24.645531,1.255503,0.663689,-28.601252,0.065224,0.000000
135.830002,2.456169,-28.601252,-0.001259,0.002584,0.065623,10.925586,0.556576,0.656233,-28.601252,0.064626,0.000000
136.190002,0.405891,-28.601252,-0.001259,0.002563,0.065103,1.805495,0.091976,0.651032,-28.601252,0.064028,0.000000
136.550003,-1.445549,-28.601252,-0.001255,0.002542,0.064557,-6.430123,-0.327566,0.645567,-28.601252,0.063430,0.000000
136.910004,-0.481850,-28.556770,-0.001250,0.002515,0.063880,-2.143374,-0.109189,0.638799,-28.556770,0.062831,0.000000
137.270004,-0.202942,-28.645733,-0.001259,0.002495,0.063386,-0.902731,-0.045987,0.633856,-28.645733,0.062224,0.000000
137.630005,-0.188042,-28.512289,-0.001255,0.002472,0.062788,-0.836451,-0.042611,0.627876,-28.512289,0.061626,0.000000
137.990005,-0.210014,-28.645733,-0.001255,0.002444,0.062068,-0.934190,-0.047590,0.620677,-28.645733,0.061027,0.000000
138.350006,-0.175011,-28.601252,-0.001268,0.002422,0.061530,-0.778486,-0.039658,0.615303,-28.601252,0.060429,0.000000
138.710007,-0.181717,-28.645733,-0.001263,0.002403,0.061044,-0.808317,-0.041178,0.610443,-28.645733,0.059830,0.000000
139.070007,-0.204803,-28.690214,-0.001268,0.002378,0.060394,-0.911011,-0.046409,0.603941,-28.690214,0.059223,0.000000
139.430008,-0.208527,-28.645733,-0.001276,0.002359,0.059917,-0.927573,-0.047253,0.599172,-28.645733,0.058625,0.000000
139.790009,-0.252090,-28.645733,-0.001285,0.002323,0.059015,-1.121354,-0.057125,0.590148,-28.645733,0.058026,0.000000
140.150009,-0.190277,-28.690214,-0.001302,0.002305,0.058555,-0.846395,-0.043117,0.585554,-28.690214,0.057428,0.000000
140.510010,-0.201080,-28.645733,-0.001315,0.002289,0.058131,-0.894450,-0.045565,0.581307,-28.645733,0.056829,0.000000
140.870010,-0.205544,-28.690214,-0.001341,0.002255,0.057281,-0.914303,-0.046577,0.572806,-28.690214,0.056222,0.000000
141.230011,-0.221931,-28.734694,-0.001350,0.002236,0.056786,-0.987200,-0.050290,0.567863,-28.734694,0.055624,0.000000
141.590012,-0.236084,-28.734694,-0.001380,0.002202,0.055936,-1.050154,-0.053497,0.559362,-28.734694,0.055026,0.000000
141.950012,-0.240547,-28.734694,-0.001401,0.002184,0.055468,-1.070007,-0.054509,0.554684,-28.734694,0.054428,0.000000
142.310013,-0.231613,-28.690214,-0.001436,0.002155,0.054739,-1.030267,-0.052484,0.547394,-28.690214,0.053829,0.000000
142.670013,-0.223793,-28.779175,-0.001453,0.002138,0.054297,-0.995481,-0.050712,0.542973,-28.779175,0.053222,0.000000
143.030014,-0.218948,-28.734694,-0.001483,0.002116,0.053742,-0.973931,-0.049614,0.537425,-28.734694,0.052624,0.000000
143.389999,-0.232361,-28.734694,-0.001509,0.002085,0.052962,-1.033593,-0.052654,0.529620,-28.734694,0.052025,0.000000
143.750000,-0.240181,-28.779175,-0.001548,0.002063,0.052398,-1.068378,-0.054426,0.523981,-28.779175,0.051427,0.000000
144.110001,-0.229378,-28.823656,-0.001548,0.002039,0.051783,-1.020323,-0.051978,0.517827,-28.823656,0.050828,0.000000
144.470001,-0.269226,-28.823656,-0.001582,0.002020,0.051305,-1.197577,-0.061007,0.513050,-28.823656,0.050230,0.000000
144.830002,-0.262520,-28.779175,-0.001608,0.001994,0.050646,-1.167747,-0.059488,0.506464,-28.779175,0.049623,0.000000
145.190002,-0.240921,-28.823656,-0.001621,0.001973,0.050126,-1.071670,-0.054593,0.501256,-28.823656,0.049024,0.000000
145.550003,-0.218582,-28.823656,-0.001660,0.001942,0.049337,-0.972302,-0.049531,0.493369,-28.823656,0.048426,0.000000
145.910004,-0.270340,-28.734694,-0.001681,0.001924,0.048868,-1.202532,-0.061260,0.488683,-28.734694,0.047827,0.000000
146.270004,-0.227516,-28.868137,-0.001716,0.001897,0.048175,-1.012043,-0.051556,0.481749,-28.868137,0.047229,0.000000
146.630005,-0.228630,-28.823656,-0.001729,0.001871,0.047533,-1.016997,-0.051808,0.475330,-28.823656,0.046622,0.000000
146.990005,-0.252090,-28.868137,-0.001738,0.001851,0.047004,-1.121354,-0.057125,0.470039,-28.868137,0.046024,0.000000
147.350006,-0.251350,-28.912619,-0.001772,0.001823,0.046301,-1.118062,-0.056957,0.463014,-28.912619,0.045426,0.000000
147.710007,-0.274063,-28.779175,-0.001781,0.001805,0.045842,-1.219094,-0.062104,0.458419,-28.779175,0.044828,0.000000
148.070007,-0.265129,-28.912619,-0.001824,0.001780,0.045209,-1.179353,-0.060079,0.452091,-28.912619,0.044229,0.000000
148.430008,-0.258423,-28.868137,-0.001841,0.001764,0.044810,-1.149522,-0.058559,0.448101,-28.868137,0.043622,0.000000
148.790009,-0.248367,-28.868137,-0.001923,0.001734,0.044038,-1.104793,-0.056281,0.440380,-28.868137,0.043024,0.000000
149.150009,-0.262894,-28.912619,-0.001944,0.001707,0.043361,-1.169410,-0.059573,0.433613,-28.912619,0.042425,0.000000
149.510010,-0.258423,-28.912619,-0.001927,0.001683,0.042746,-1.149522,-0.058559,0.427458,-28.912619,0.041827,0.000000
149.870010,-0.274811,-28.912619,-0.001957,0.001658,0.042121,-1.222420,-0.062273,0.421213,-28.912619,0.041228,0.000000
150.230011,-0.269592,-28.957100,-0.001970,0.001642,0.041705,-1.199206,-0.061090,0.417050,-28.957100,0.040621,0.000000
150.500000,-0.230125,-28.912619,-0.001988,0.001628,0.041350,-1.023649,-0.052147,0.413500,-28.912619,0.041211,0.000000