File: Data/compression 26/AutoNoHeating-17-26-reverse-2-3_09262024_182059.csv
Time (sec),S:Load (lbs),S:HL1 (DIM),S:LVDT (in),S:Position (in),Ch:Position (mm),Ch:Load (N),Ch:Stress (MPa),Ch:Strain (mm/mm),Ch:HL1 (DIM),Set Point (),Cycles ()
0.110000,-0.482964,-118.719658,-0.012137,-0.007696,-0.195472,-2.148329,-0.109441,-1.954724,-118.719658,-0.195256,0.000000
0.480000,-0.523552,-118.764137,-0.012146,-0.007613,-0.193374,-2.328875,-0.118639,-1.933741,-118.764137,-0.192654,0.000000
0.850000,-0.542542,-118.764137,-0.012051,-0.007394,-0.187815,-2.413345,-0.122942,-1.878148,-118.764137,-0.186479,0.000000
1.220000,-0.573082,-118.719658,-0.011818,-0.007150,-0.181606,-2.549196,-0.129862,-1.816061,-118.719658,-0.180322,0.000000
1.590000,-0.514244,-118.764137,-0.011559,-0.006909,-0.175483,-2.287472,-0.116529,-1.754829,-118.764137,-0.174165,0.000000
1.960000,-0.465088,-118.719658,-0.011322,-0.006668,-0.169370,-2.068814,-0.105390,-1.693695,-118.719658,-0.167990,0.000000
2.330000,-0.468445,-118.675179,-0.011076,-0.006423,-0.163134,-2.083747,-0.106151,-1.631343,-118.675179,-0.161833,0.000000
2.700000,-0.501953,-118.764137,-0.010818,-0.006180,-0.156968,-2.232799,-0.113744,-1.569679,-118.764137,-0.155658,0.000000
3.070000,-0.512383,-118.853104,-0.010563,-0.005936,-0.150776,-2.279191,-0.116108,-1.507758,-118.853104,-0.149501,0.000000
3.440000,-0.477005,-118.719658,-0.010326,-0.005695,-0.144644,-2.121824,-0.108091,-1.446443,-118.719658,-0.143344,0.000000
3.810000,-0.472908,-118.675179,-0.010059,-0.005450,-0.138426,-2.103600,-0.107162,-1.384265,-118.675179,-0.137169,0.000000
4.180000,-0.478867,-118.675179,-0.009830,-0.005213,-0.132408,-2.130105,-0.108513,-1.324077,-118.675179,-0.131012,0.000000
4.550000,-0.482964,-118.719658,-0.009580,-0.004972,-0.126294,-2.148329,-0.109441,-1.262944,-118.719658,-0.124837,0.000000
4.920000,-0.513870,-118.719658,-0.009326,-0.004734,-0.120241,-2.285809,-0.116445,-1.202408,-118.719658,-0.118680,0.000000
5.290000,-0.539192,-118.719658,-0.009071,-0.004485,-0.113928,-2.398447,-0.122183,-1.139276,-118.719658,-0.112523,0.000000
5.660000,-0.519829,-118.764137,-0.008804,-0.004232,-0.107484,-2.312314,-0.117795,-1.074842,-118.764137,-0.106348,0.000000
6.030000,-0.482216,-118.719658,-0.008576,-0.003992,-0.101405,-2.145003,-0.109272,-1.014049,-118.719658,-0.100191,0.000000
6.400000,-0.449821,-118.719658,-0.008330,-0.003754,-0.095343,-2.000906,-0.101931,-0.953430,-118.719658,-0.094016,0.000000
6.770000,-0.465462,-118.719658,-0.008084,-0.003515,-0.089281,-2.070477,-0.105475,-0.892811,-118.719658,-0.087859,0.000000
7.140000,-0.491158,-118.675179,-0.007817,-0.003267,-0.082994,-2.184778,-0.111298,-0.829937,-118.675179,-0.081701,0.000000
7.510000,-0.482590,-118.675179,-0.007562,-0.003023,-0.076784,-2.146666,-0.109356,-0.767842,-118.675179,-0.075527,0.000000
7.880001,-0.473656,-118.630699,-0.007299,-0.002782,-0.070670,-2.106926,-0.107332,-0.706700,-118.630699,-0.069370,0.000000
8.250000,-0.476631,-118.719658,-0.007058,-0.002544,-0.064608,-2.120161,-0.108006,-0.646082,-118.719658,-0.063212,0.000000
8.620001,-0.474770,-118.675179,-0.006808,-0.002302,-0.058460,-2.111881,-0.107584,-0.584600,-118.675179,-0.057038,0.000000
8.990001,-0.493393,-118.719658,-0.006558,-0.002062,-0.052363,-2.194721,-0.111804,-0.523633,-118.719658,-0.050880,0.000000
9.360001,-0.515358,-118.719658,-0.006299,-0.001812,-0.046015,-2.292427,-0.116782,-0.460152,-118.719658,-0.044706,0.000000
9.730000,-0.547386,-118.675179,-0.006062,-0.001569,-0.039849,-2.434895,-0.124039,-0.398489,-118.675179,-0.038548,0.000000
10.100000,-0.472908,-118.719658,-0.005799,-0.001327,-0.033701,-2.103600,-0.107162,-0.337007,-118.719658,-0.032391,0.000000
10.470000,-0.460625,-118.675179,-0.005536,-0.001084,-0.027526,-2.048961,-0.104379,-0.275260,-118.675179,-0.026216,0.000000
10.840000,-0.463226,-118.630699,-0.005273,-0.000840,-0.021342,-2.060534,-0.104969,-0.213423,-118.630699,-0.020059,0.000000
11.210001,-0.468811,-118.586212,-0.005027,-0.000598,-0.015185,-2.085376,-0.106234,-0.151850,-118.586212,-0.013885,0.000000
11.580001,-0.132561,-118.630699,-0.004794,-0.000353,-0.008967,-0.589660,-0.030039,-0.089672,-118.630699,-0.007727,0.000000
11.950001,0.152306,-118.675179,-0.004725,-0.000000,-0.000008,0.677489,0.034513,-0.000083,-118.675179,0.000200,0.000000
12.320001,0.148209,-118.675179,-0.004730,-0.000000,-0.000008,0.659265,0.033585,-0.000083,-118.675179,0.000442,0.000000
12.690001,0.080811,-118.630699,-0.004721,-0.000000,-0.000008,0.359463,0.018312,-0.000083,-118.630699,0.001058,0.000000
13.060000,0.176880,-118.630699,-0.004704,0.000019,0.000486,0.786801,0.040082,0.004860,-118.630699,0.001674,0.000000
13.430000,0.475151,-118.541733,-0.004691,0.000050,0.001257,2.113577,0.107671,0.012573,-118.541733,0.002289,0.000000
13.800000,0.755173,-118.630699,-0.004669,0.000074,0.001874,3.359176,0.171125,0.018735,-118.630699,0.002914,0.000000
14.170001,0.959610,-118.586212,-0.004661,0.000098,0.002497,4.268559,0.217451,0.024973,-118.586212,0.003530,0.000000
14.540001,1.238510,-118.630699,-0.004639,0.000118,0.003009,5.509168,0.280650,0.030090,-118.630699,0.004145,0.000000
14.910001,1.421722,-118.586212,-0.004626,0.000140,0.003556,6.324137,0.322167,0.035555,-118.586212,0.004761,0.000000
15.280001,1.692062,-118.630699,-0.004609,0.000163,0.004128,7.526670,0.383427,0.041278,-118.630699,0.005377,0.000000
15.650001,2.130714,-118.541733,-0.004587,0.000192,0.004874,9.477891,0.482827,0.048742,-118.541733,0.005992,0.000000
16.020000,2.634163,-118.586212,-0.004553,0.000224,0.005698,11.717341,0.596910,0.056978,-118.586212,0.006608,0.000000
16.390001,2.905624,-118.630699,-0.004531,0.000248,0.006287,12.924863,0.658424,0.062875,-118.630699,0.007224,0.000000
16.760000,3.216927,-118.586212,-0.004527,0.000272,0.006912,14.309604,0.728966,0.069120,-118.586212,0.007840,0.000000
17.130001,3.532326,-118.497253,-0.004480,0.000294,0.007467,15.712569,0.800436,0.074668,-118.497253,0.008464,0.000000
17.500000,3.838043,-118.586212,-0.004467,0.000317,0.008039,17.072470,0.869713,0.080391,-118.586212,0.009080,0.000000
17.870001,4.244675,-118.630699,-0.004441,0.000340,0.008638,18.881256,0.961857,0.086379,-118.630699,0.009695,0.000000
18.240002,4.545181,-118.541733,-0.004428,0.000361,0.009175,20.217976,1.029953,0.091753,-118.541733,0.010312,0.000000
18.610001,4.887016,-118.497253,-0.004393,0.000383,0.009739,21.738535,1.107414,0.097393,-118.497253,0.010927,0.000000
18.980001,5.145073,-118.497253,-0.004372,0.000406,0.010302,22.886427,1.165890,0.103025,-118.497253,0.011542,0.000000
19.350000,5.698792,-118.541733,-0.004350,0.000439,0.011153,25.349491,1.291365,0.111526,-118.541733,0.012159,0.000000
19.720001,5.844765,-118.541733,-0.004346,0.000458,0.011621,25.998812,1.324443,0.116211,-118.541733,0.012774,0.000000
20.090000,6.099464,-118.541733,-0.004316,0.000477,0.012124,27.131773,1.382158,0.121238,-118.541733,0.013399,0.000000
20.460001,6.663605,-118.541733,-0.004290,0.000510,0.012956,29.641193,1.509994,0.129565,-118.541733,0.014015,0.000000
20.830002,6.649834,-118.541733,-0.004273,0.000526,0.013355,29.579937,1.506874,0.133554,-118.541733,0.014630,0.000000
21.200001,7.280632,-118.497253,-0.004234,0.000556,0.014118,32.385868,1.649815,0.141184,-118.497253,0.015246,0.000000
21.570002,7.501450,-118.452774,-0.004230,0.000580,0.014726,33.368114,1.699853,0.147255,-118.452774,0.015862,0.000000
21.940001,7.717796,-118.541733,-0.004191,0.000604,0.015341,34.330471,1.748878,0.153409,-118.541733,0.016477,0.000000
22.310001,7.883125,-118.541733,-0.004174,0.000627,0.015914,35.065891,1.786342,0.159140,-118.541733,0.017093,0.000000
22.680000,8.278214,-118.497253,-0.004152,0.000658,0.016711,36.823334,1.875870,0.167111,-118.497253,0.017709,0.000000
23.050001,8.396255,-118.452774,-0.004113,0.000678,0.017223,37.348412,1.902619,0.172228,-118.452774,0.018324,0.000000
23.420002,8.697876,-118.497253,-0.004100,0.000704,0.017891,38.690086,1.970967,0.178912,-118.497253,0.018949,0.000000
23.790001,8.757088,-118.452774,-0.004087,0.000722,0.018351,38.953472,1.984384,0.183507,-118.452774,0.019565,0.000000
24.160002,8.882950,-118.497253,-0.004070,0.000751,0.019071,39.513336,2.012905,0.190706,-118.497253,0.020180,0.000000
24.530001,9.326447,-118.452774,-0.004023,0.000777,0.019738,41.486107,2.113403,0.197382,-118.452774,0.020796,0.000000
24.900002,9.162598,-118.408295,-0.004001,0.000789,0.020042,40.757271,2.076274,0.200418,-118.408295,0.021412,0.000000
25.270000,9.726372,-118.452774,-0.003980,0.000823,0.020900,43.265064,2.204027,0.209002,-118.452774,0.022027,0.000000
25.640001,9.942345,-118.452774,-0.003967,0.000847,0.021525,44.225758,2.252968,0.215247,-118.452774,0.022644,0.000000
26.010002,10.306152,-118.452774,-0.003932,0.000876,0.022245,45.844055,2.335407,0.222446,-118.452774,0.023259,0.000000
26.380001,10.134491,-118.363808,-0.003915,0.000893,0.022687,45.080467,2.296509,0.226867,-118.363808,0.023874,0.000000
26.750002,10.396271,-118.452774,-0.003906,0.000915,0.023233,46.244923,2.355829,0.232332,-118.452774,0.024499,0.000000
27.120001,10.662514,-118.408295,-0.003876,0.000944,0.023979,47.429230,2.416160,0.239788,-118.408295,0.025115,0.000000
27.490002,11.092979,-118.452774,-0.003850,0.000971,0.024664,49.344036,2.513705,0.246639,-118.452774,0.025730,0.000000
27.860001,10.897484,-118.452774,-0.003820,0.000986,0.025054,48.474430,2.469405,0.250545,-118.452774,0.026347,0.000000
28.230001,11.168198,-118.363808,-0.003820,0.001010,0.025662,49.678623,2.530750,0.256616,-118.363808,0.026962,0.000000
28.600002,11.507057,-118.363808,-0.003773,0.001039,0.026381,51.185947,2.607537,0.263807,-118.363808,0.027578,0.000000
28.970001,11.226662,-118.408295,-0.003777,0.001055,0.026797,49.938686,2.543998,0.267971,-118.408295,0.028194,0.000000
29.340002,12.188126,-118.408295,-0.003729,0.001091,0.027708,54.215492,2.761869,0.277077,-118.408295,0.028809,0.000000
29.710001,12.262604,-118.363808,-0.003721,0.001114,0.028289,54.546787,2.778746,0.282891,-118.363808,0.029425,0.000000
30.080002,12.254410,-118.363808,-0.003682,0.001134,0.028801,54.510338,2.776889,0.288008,-118.363808,0.030049,0.000000
30.450001,12.505760,-118.319328,-0.003652,0.001162,0.029503,55.628399,2.833846,0.295033,-118.319328,0.030665,0.000000
30.820002,12.683380,-118.319328,-0.003648,0.001183,0.030058,56.418491,2.874095,0.300581,-118.319328,0.031281,0.000000
31.190001,13.126129,-118.363808,-0.003622,0.001211,0.030752,58.387939,2.974423,0.307515,-118.363808,0.031897,0.000000
31.560001,13.091125,-118.363808,-0.003587,0.001233,0.031315,58.232235,2.966491,0.313155,-118.363808,0.032512,0.000000
31.930002,13.315666,-118.408295,-0.003561,0.001260,0.031992,59.231041,3.017373,0.319922,-118.408295,0.033128,0.000000
32.300003,13.484726,-118.319328,-0.003553,0.001281,0.032547,59.983055,3.055683,0.325471,-118.319328,0.033744,0.000000
32.670002,13.692513,-118.319328,-0.003523,0.001307,0.033189,60.907337,3.102768,0.331890,-118.319328,0.034359,0.000000
33.040001,14.129677,-118.408295,-0.003514,0.001338,0.033978,62.851940,3.201830,0.339778,-118.408295,0.034975,0.000000
33.410000,14.175850,-118.363808,-0.003484,0.001361,0.034567,63.057331,3.212293,0.345674,-118.363808,0.035600,0.000000
33.780003,13.945351,-118.319328,-0.003454,0.001378,0.035001,62.032017,3.160062,0.350012,-118.319328,0.036215,0.000000
34.150002,14.511360,-118.363808,-0.003428,0.001407,0.035747,64.549751,3.288321,0.357468,-118.363808,0.036831,0.000000
34.520000,14.253677,-118.274849,-0.003419,0.001424,0.036163,63.403522,3.229929,0.361632,-118.274849,0.037447,0.000000
34.890003,14.937355,-118.363808,-0.003389,0.001454,0.036926,66.444672,3.384853,0.369262,-118.363808,0.038062,0.000000
35.260002,15.233391,-118.363808,-0.003367,0.001483,0.037663,67.761505,3.451936,0.376635,-118.363808,0.038679,0.000000
35.630001,15.161522,-118.274849,-0.003328,0.001501,0.038123,67.441818,3.435650,0.381230,-118.274849,0.039294,0.000000
36.000000,15.076622,-118.230370,-0.003307,0.001521,0.038626,67.064163,3.416411,0.386264,-118.230370,0.039909,0.000000
36.370003,15.467239,-118.319328,-0.003290,0.001548,0.039311,68.801720,3.504926,0.393114,-118.319328,0.040526,0.000000
36.740002,15.621399,-118.319328,-0.003272,0.001573,0.039962,69.487450,3.539860,0.399617,-118.319328,0.041150,0.000000
37.110001,16.233955,-118.319328,-0.003251,0.001602,0.040699,72.212242,3.678667,0.406990,-118.319328,0.041766,0.000000
37.480003,16.490143,-118.274849,-0.003221,0.001632,0.041454,73.351822,3.736720,0.414537,-118.274849,0.042381,0.000000
37.850002,16.468178,-118.274849,-0.003191,0.001656,0.042069,73.254112,3.731742,0.420691,-118.274849,0.042997,0.000000
38.220001,16.421257,-118.274849,-0.003173,0.001677,0.042598,73.045403,3.721110,0.425982,-118.274849,0.043613,0.000000
38.590000,16.754906,-118.230370,-0.003156,0.001705,0.043301,74.529541,3.796716,0.433007,-118.230370,0.044229,0.000000
38.960003,16.497963,-118.319328,-0.003134,0.001720,0.043682,73.386604,3.738492,0.436822,-118.319328,0.044844,0.000000
39.330002,17.186111,-118.274849,-0.003100,0.001751,0.044471,76.447639,3.894428,0.444710,-118.274849,0.045460,0.000000
39.700001,16.662178,-118.185890,-0.003087,0.001761,0.044740,74.117073,3.775704,0.447405,-118.185890,0.046076,0.000000
40.070004,17.543961,-118.230370,-0.003070,0.001796,0.045625,78.039436,3.975518,0.456246,-118.230370,0.046700,0.000000
40.440002,17.729027,-118.230370,-0.003035,0.001819,0.046197,78.862648,4.017455,0.461969,-118.230370,0.047316,0.000000
40.810001,17.981125,-118.230370,-0.003027,0.001847,0.046917,79.984039,4.074581,0.469168,-118.230370,0.047932,0.000000
41.180000,17.961761,-118.185890,-0.002988,0.001866,0.047394,79.897903,4.070193,0.473937,-118.185890,0.048547,0.000000
41.550003,18.702034,-118.230370,-0.002975,0.001897,0.048174,83.190804,4.237941,0.481741,-118.230370,0.049163,0.000000
41.920002,18.112572,-118.230370,-0.002962,0.001909,0.048487,80.568741,4.104367,0.484868,-118.230370,0.049779,0.000000
42.290001,18.350143,-118.185890,-0.002936,0.001931,0.049059,81.625511,4.158202,0.490591,-118.185890,0.050394,0.000000
42.660004,18.645439,-118.141403,-0.002910,0.001954,0.049640,82.939056,4.225117,0.496397,-118.141403,0.051011,0.000000
43.030003,19.591263,-118.274849,-0.002876,0.001990,0.050550,87.146286,4.439444,0.505503,-118.274849,0.051634,0.000000
43.400002,19.722710,-118.185890,-0.002863,0.002013,0.051140,87.730995,4.469230,0.511400,-118.185890,0.052250,0.000000
43.770000,19.292992,-118.185890,-0.002841,0.002028,0.051513,85.819511,4.371854,0.515132,-118.185890,0.052866,0.000000
44.140003,19.829582,-118.141403,-0.002833,0.002057,0.052259,88.206390,4.493447,0.522588,-118.141403,0.053482,0.000000
44.510002,19.897728,-118.141403,-0.002802,0.002084,0.052926,88.509514,4.508890,0.529265,-118.141403,0.054098,0.000000
44.880001,20.919518,-118.141403,-0.002777,0.002112,0.053646,93.054665,4.740430,0.536463,-118.141403,0.054713,0.000000
45.250004,21.077026,-118.141403,-0.002759,0.002135,0.054236,93.755295,4.776123,0.542360,-118.141403,0.055329,0.000000
45.620003,21.371574,-118.185890,-0.002734,0.002162,0.054904,95.065514,4.842868,0.549037,-118.185890,0.055945,0.000000
45.990002,21.196930,-118.185890,-0.002699,0.002182,0.055415,94.288651,4.803293,0.554154,-118.185890,0.056561,0.000000
46.360001,21.458336,-118.185890,-0.002686,0.002204,0.055979,95.451447,4.862528,0.559794,-118.185890,0.057185,0.000000
46.730003,21.745064,-118.141403,-0.002665,0.002228,0.056595,96.726875,4.927502,0.565948,-118.141403,0.057801,0.000000
47.100002,22.421669,-118.141403,-0.002647,0.002259,0.057367,99.736565,5.080823,0.573669,-118.141403,0.058416,0.000000
47.470001,22.290222,-118.096924,-0.002630,0.002275,0.057775,99.151863,5.051036,0.577749,-118.096924,0.059032,0.000000
47.840004,22.328201,-118.230370,-0.002604,0.002300,0.058416,99.320801,5.059642,0.584161,-118.230370,0.059648,0.000000
48.210003,22.866280,-118.141403,-0.002583,0.002325,0.059058,101.714294,5.181573,0.590580,-118.141403,0.060264,0.000000
48.580002,23.844131,-118.096924,-0.002548,0.002354,0.059804,106.063995,5.403157,0.598036,-118.096924,0.060879,0.000000
48.950001,23.823273,-118.096924,-0.002544,0.002375,0.060333,105.971207,5.398431,0.603327,-118.096924,0.061495,0.000000
49.320004,23.912643,-118.096924,-0.002527,0.002395,0.060844,106.368752,5.418683,0.608445,-118.096924,0.062111,0.000000
49.690002,24.693512,-118.141403,-0.002514,0.002424,0.061564,109.842224,5.595630,0.615643,-118.141403,0.062735,0.000000
50.060001,24.428383,-118.141403,-0.002488,0.002441,0.061989,108.662872,5.535551,0.619890,-118.141403,0.063351,0.000000
50.430004,24.515518,-118.141403,-0.002475,0.002463,0.062553,109.050468,5.555295,0.625530,-118.141403,0.063966,0.000000
50.800003,25.927177,-118.141403,-0.002423,0.002495,0.063377,115.329842,5.875182,0.633766,-118.141403,0.064582,0.000000
51.170002,26.209442,-118.052444,-0.002423,0.002521,0.064028,116.585419,5.939145,0.640276,-118.052444,0.065198,0.000000
51.540001,26.567657,-118.096924,-0.002389,0.002547,0.064704,118.178841,6.020317,0.647035,-118.096924,0.065814,0.000000
51.910004,26.420944,-118.096924,-0.002376,0.002565,0.065155,117.526230,5.987072,0.651547,-118.096924,0.066429,0.000000
52.280003,27.032753,-118.096924,-0.002345,0.002587,0.065710,120.247688,6.125709,0.657096,-118.096924,0.067045,0.000000
52.650002,27.441994,-118.007965,-0.002328,0.002613,0.066369,122.068085,6.218445,0.663689,-118.007965,0.067661,0.000000
53.020004,28.404572,-118.096924,-0.002311,0.002642,0.067106,126.349846,6.436568,0.671062,-118.096924,0.068286,0.000000
53.390003,29.172035,-118.052444,-0.002294,0.002671,0.067843,129.763687,6.610478,0.678427,-118.052444,0.068901,0.000000
53.760002,29.149689,-118.096924,-0.002268,0.002691,0.068354,129.664291,6.605414,0.683544,-118.096924,0.069517,0.000000
54.130001,29.992744,-118.096924,-0.002246,0.002719,0.069074,133.414383,6.796453,0.690743,-118.096924,0.070133,0.000000
54.500004,30.100357,-118.007965,-0.002220,0.002740,0.069586,133.893082,6.820838,0.695861,-118.007965,0.070748,0.000000
54.870003,30.686844,-118.007965,-0.002216,0.002767,0.070280,136.501892,6.953738,0.702802,-118.007965,0.071364,0.000000
55.240002,31.114326,-118.052444,-0.002212,0.002787,0.070800,138.403442,7.050607,0.708002,-118.052444,0.071980,0.000000
55.610004,31.683685,-118.052444,-0.002164,0.002813,0.071442,140.936066,7.179626,0.714422,-118.052444,0.072596,0.000000
55.980003,32.224747,-118.052444,-0.002151,0.002835,0.071997,143.342834,7.302232,0.719970,-118.052444,0.073211,0.000000
56.350002,33.118439,-118.007965,-0.002139,0.002862,0.072691,147.318176,7.504745,0.726912,-118.007965,0.073836,0.000000
56.720001,33.491180,-117.963486,-0.002113,0.002886,0.073298,148.976212,7.589210,0.732983,-117.963486,0.074451,0.000000
57.090004,33.847916,-118.052444,-0.002095,0.002910,0.073922,150.563049,7.670047,0.739220,-118.052444,0.075067,0.000000
57.460003,34.995941,-118.007965,-0.002087,0.002936,0.074581,155.669724,7.930193,0.745814,-118.007965,0.075683,0.000000
57.830002,34.841034,-118.007965,-0.002052,0.002951,0.074963,154.980652,7.895091,0.749629,-118.007965,0.076298,0.000000
58.200005,36.218063,-117.963486,-0.002035,0.002983,0.075778,161.105988,8.207130,0.757781,-117.963486,0.076914,0.000000
58.570004,37.144157,-117.963486,-0.002013,0.003011,0.076472,165.225464,8.416986,0.764723,-117.963486,0.077530,0.000000
58.940002,38.422508,-117.963486,-0.001996,0.003040,0.077218,170.911850,8.706665,0.772179,-117.963486,0.078146,0.000000
59.310001,38.646683,-118.007965,-0.001979,0.003064,0.077833,171.909027,8.757463,0.778333,-118.007965,0.078761,0.000000
59.680004,38.791901,-117.963486,-0.001957,0.003084,0.078337,172.554993,8.790370,0.783367,-117.963486,0.079386,0.000000
60.050003,39.925407,-118.007965,-0.001944,0.003110,0.079004,177.597076,9.047226,0.790044,-118.007965,0.080001,0.000000
60.420002,40.259422,-117.918999,-0.001919,0.003129,0.079472,179.082855,9.122916,0.794722,-117.918999,0.080618,0.000000
60.790005,41.620819,-117.963486,-0.001888,0.003158,0.080209,185.138657,9.431413,0.802095,-117.963486,0.081233,0.000000
61.160004,42.036385,-118.052444,-0.001880,0.003180,0.080773,186.987183,9.525580,0.807734,-118.052444,0.081849,0.000000
61.530003,42.850395,-117.874519,-0.001845,0.003204,0.081371,190.608078,9.710038,0.813715,-117.874519,0.082465,0.000000
61.900002,43.923569,-117.874519,-0.001850,0.003231,0.082057,195.381790,9.953223,0.820565,-117.874519,0.083080,0.000000
62.270004,44.558090,-117.918999,-0.001828,0.003251,0.082577,198.204285,10.097008,0.825773,-117.918999,0.083696,0.000000
62.640003,45.309166,-117.963486,-0.001815,0.003274,0.083167,201.545242,10.267203,0.831670,-117.963486,0.084312,0.000000
63.010002,46.578957,-117.918999,-0.001789,0.003300,0.083817,207.193542,10.554943,0.838173,-117.918999,0.084936,0.000000
63.380005,46.860474,-117.918999,-0.001785,0.003318,0.084268,208.445801,10.618734,0.842684,-117.918999,0.085551,0.000000
63.750004,46.971062,-117.874519,-0.001763,0.003332,0.084642,208.937714,10.643795,0.846416,-117.874519,0.086168,0.000000
64.120003,47.874443,-117.874519,-0.001746,0.003354,0.085187,212.956161,10.848504,0.851874,-117.874519,0.086783,0.000000
64.490005,50.471741,-117.918999,-0.001729,0.003395,0.086237,224.509521,11.437060,0.862366,-117.918999,0.087399,0.000000
64.860001,51.710991,-117.918999,-0.001707,0.003422,0.086922,230.021973,11.717878,0.869224,-117.918999,0.088015,0.000000
65.230003,51.887871,-117.918999,-0.001694,0.003434,0.087226,230.808777,11.757959,0.872259,-117.918999,0.088630,0.000000
65.600006,53.487213,-117.918999,-0.001686,0.003464,0.087989,237.923004,12.120376,0.879890,-117.918999,0.089246,0.000000
65.970001,54.510117,-117.918999,-0.001664,0.003488,0.088587,242.473114,12.352169,0.885870,-117.918999,0.089862,0.000000
66.340004,56.265106,-117.918999,-0.001660,0.003519,0.089377,250.279694,12.749855,0.893765,-117.918999,0.090486,0.000000
66.710007,57.000542,-117.874519,-0.001643,0.003541,0.089949,253.551071,12.916508,0.899488,-117.874519,0.091102,0.000000
67.080002,58.334755,-117.874519,-0.001621,0.003567,0.090608,259.485962,13.218845,0.906081,-117.874519,0.091718,0.000000
67.450005,59.322289,-117.830040,-0.001608,0.003586,0.091093,263.878723,13.442623,0.910933,-117.830040,0.092333,0.000000
67.820000,60.359718,-117.874519,-0.001591,0.003614,0.091796,268.493439,13.677708,0.917958,-117.874519,0.092949,0.000000
68.190002,62.318024,-117.918999,-0.001578,0.003639,0.092438,277.204407,14.121466,0.924377,-117.918999,0.093565,0.000000
68.560005,63.943810,-117.830040,-0.001578,0.003665,0.093097,284.436279,14.489874,0.930971,-117.830040,0.094181,0.000000
68.930000,64.153069,-117.830040,-0.001574,0.003680,0.093461,285.367096,14.537292,0.934612,-117.830040,0.094796,0.000000
69.300003,65.212852,-117.785561,-0.001539,0.003701,0.094016,290.081268,14.777444,0.940160,-117.785561,0.095421,0.000000
69.670006,65.945305,-117.830040,-0.001531,0.003711,0.094250,293.339355,14.943420,0.942499,-117.830040,0.094510,0.000000
70.040001,64.655037,-117.874519,-0.001522,0.003709,0.094215,287.599976,14.651041,0.942151,-117.874519,294.500488,0.000000
70.410004,66.233147,-117.785561,-0.001470,0.003529,0.089636,294.619751,15.008646,0.896362,-117.785561,294.500488,0.000000
70.780006,65.190132,-117.830040,-0.001462,0.003645,0.092576,289.980194,14.772295,0.925763,-117.830040,294.500488,0.000000
71.150002,64.963356,-117.785561,-0.001475,0.003736,0.094884,288.971436,14.720907,0.948835,-117.785561,294.500488,0.000000
71.520004,65.093315,-117.874519,-0.001475,0.003748,0.095204,289.549530,14.750356,0.952037,-117.874519,294.500488,0.000000
71.890007,65.195717,-117.830040,-0.001483,0.003758,0.095456,290.005035,14.773561,0.954558,-117.830040,294.500488,0.000000
72.260002,65.272423,-117.830040,-0.001470,0.003766,0.095664,290.346252,14.790943,0.956640,-117.830040,294.500488,0.000000
72.630005,65.210991,-117.830040,-0.001470,0.003771,0.095777,290.072968,14.777021,0.957768,-117.830040,294.500488,0.000000
73.000000,64.904900,-117.741081,-0.001470,0.003773,0.095837,288.711426,14.707661,0.958373,-117.741081,294.500488,0.000000
73.370003,65.477974,-117.830040,-0.001462,0.003784,0.096123,291.260590,14.837522,0.961235,-117.830040,294.500488,0.000000
73.740005,65.012886,-117.785561,-0.001457,0.003785,0.096132,289.191772,14.732131,0.961318,-117.785561,294.500488,0.000000
74.110001,65.411324,-117.830040,-0.001453,0.003797,0.096444,290.964111,14.822417,0.964444,-117.830040,294.500488,0.000000
74.480003,65.233696,-117.785561,-0.001457,0.003797,0.096444,290.173981,14.782166,0.964444,-117.785561,294.500488,0.000000
74.850006,64.816277,-117.785561,-0.001449,0.003797,0.096444,288.317200,14.687578,0.964444,-117.785561,294.500488,0.000000
75.220001,65.511497,-117.741081,-0.001444,0.003809,0.096739,291.409698,14.845118,0.967389,-117.741081,294.500488,0.000000
75.590004,65.195717,-117.785561,-0.001427,0.003809,0.096739,290.005035,14.773561,0.967389,-117.785561,294.500488,0.000000
75.960007,64.832283,-117.785561,-0.001427,0.003810,0.096765,288.388397,14.691205,0.967654,-117.785561,294.500488,0.000000
76.330002,65.533455,-117.741081,-0.001427,0.003820,0.097025,291.507355,14.850093,0.970250,-117.741081,294.500488,0.000000
76.700005,65.225883,-117.741081,-0.001423,0.003820,0.097025,290.139221,14.780396,0.970250,-117.741081,294.500488,0.000000
77.070007,64.892982,-117.741081,-0.001414,0.003820,0.097025,288.658417,14.704960,0.970250,-117.741081,294.500488,0.000000
77.440002,65.563255,-117.741081,-0.001423,0.003831,0.097303,291.639923,14.856847,0.973028,-117.741081,294.500488,0.000000
77.810005,65.321587,-117.785561,-0.001427,0.003831,0.097303,290.564941,14.802083,0.973028,-117.785561,294.500488,0.000000
78.180000,65.052361,-117.741081,-0.001414,0.003832,0.097329,289.367340,14.741076,0.973286,-117.741081,294.500488,0.000000
78.550003,64.849785,-117.696594,-0.001410,0.003833,0.097346,288.466248,14.695170,0.973460,-117.696594,294.500488,0.000000
78.920006,64.841591,-117.696594,-0.001406,0.003836,0.097424,288.429810,14.693315,0.974240,-117.696594,294.500488,0.000000
79.290001,64.636787,-117.741081,-0.001410,0.003840,0.097537,287.518799,14.646906,0.975367,-117.741081,294.500488,0.000000
79.660004,65.179329,-117.741081,-0.001414,0.003844,0.097632,289.932129,14.769847,0.976321,-117.741081,294.500488,0.000000
80.030006,64.977135,-117.696594,-0.001401,0.003844,0.097632,289.032745,14.724030,0.976321,-117.696594,294.500488,0.000000
80.400002,64.779411,-117.652115,-0.001406,0.003845,0.097659,288.153198,14.679225,0.976586,-117.652115,294.500488,0.000000
80.770004,65.104866,-117.696594,-0.001388,0.003853,0.097858,289.600922,14.752974,0.978577,-117.696594,294.500488,0.000000
81.140007,65.113792,-117.696594,-0.001388,0.003853,0.097858,289.640625,14.754995,0.978577,-117.696594,294.500488,0.000000
81.510002,64.952187,-117.696594,-0.001388,0.003853,0.097858,288.921753,14.718376,0.978577,-117.696594,294.500488,0.000000
81.880005,64.764503,-117.607635,-0.001380,0.003853,0.097858,288.086914,14.675847,0.978577,-117.607635,294.500488,0.000000
82.250008,64.999474,-117.652115,-0.001380,0.003858,0.097988,289.132111,14.729092,0.979879,-117.652115,294.500488,0.000000
82.620003,64.857231,-117.652115,-0.001375,0.003858,0.097988,288.499359,14.696858,0.979879,-117.652115,294.500488,0.000000
82.990005,64.883675,-117.696594,-0.001388,0.003861,0.098066,288.617004,14.702851,0.980659,-117.696594,294.500488,0.000000
83.360001,64.738823,-117.696594,-0.001397,0.003861,0.098066,287.972656,14.670027,0.980659,-117.696594,294.500488,0.000000
83.730003,65.199074,-117.652115,-0.001371,0.003867,0.098222,290.019958,14.774321,0.982218,-117.652115,294.500488,0.000000
84.100006,65.066139,-117.607635,-0.001367,0.003867,0.098222,289.428650,14.744198,0.982218,-117.607635,294.500488,0.000000
84.470001,64.946236,-117.607635,-0.001375,0.003867,0.098222,288.895294,14.717027,0.982218,-117.607635,294.500488,0.000000
84.840004,64.791328,-117.563156,-0.001380,0.003867,0.098231,288.206238,14.681926,0.982309,-117.563156,294.500488,0.000000
85.210007,65.628044,-117.607635,-0.001371,0.003877,0.098482,291.928131,14.871527,0.984822,-117.607635,294.500488,0.000000
85.580002,65.543510,-117.563156,-0.001371,0.003877,0.098482,291.552094,14.852372,0.984822,-117.563156,294.500488,0.000000
85.950005,65.385994,-117.563156,-0.001362,0.003877,0.098482,290.851440,14.816678,0.984822,-117.563156,294.500488,0.000000
86.320007,65.263115,-117.518669,-0.001375,0.003877,0.098482,290.304840,14.788833,0.984822,-117.518669,294.500488,0.000000
86.690002,65.110069,-117.563156,-0.001358,0.003877,0.098482,289.624054,14.754152,0.984822,-117.563156,294.500488,0.000000
87.060005,64.965599,-117.607635,-0.001350,0.003877,0.098482,288.981415,14.721416,0.984822,-117.607635,294.500488,0.000000
87.430008,64.826332,-117.607635,-0.001341,0.003877,0.098482,288.361938,14.689857,0.984822,-117.607635,294.500488,0.000000
87.800003,64.707161,-117.518669,-0.001350,0.003877,0.098482,287.831818,14.662852,0.984822,-117.518669,294.500488,0.000000
88.170006,64.558220,-117.518669,-0.001367,0.003878,0.098491,287.169312,14.629102,0.984905,-117.518669,294.500488,0.000000
88.540001,66.060371,-117.563156,-0.001362,0.003882,0.098612,293.851196,14.969494,0.986124,-117.563156,294.500488,0.000000
88.910004,65.864128,-117.563156,-0.001354,0.003882,0.098603,292.978271,14.925024,0.986033,-117.563156,294.500488,0.000000
89.280006,65.753899,-117.563156,-0.001345,0.003882,0.098603,292.487946,14.900046,0.986033,-117.563156,294.500488,0.000000
89.650002,65.585213,-117.518669,-0.001341,0.003882,0.098603,291.737610,14.861821,0.986033,-117.518669,294.500488,0.000000
90.020004,65.460854,-117.563156,-0.001345,0.003882,0.098603,291.184418,14.833641,0.986033,-117.563156,294.500488,0.000000
90.390007,65.299614,-117.518669,-0.001354,0.003882,0.098603,290.467194,14.797104,0.986033,-117.518669,294.500488,0.000000
90.760002,65.178963,-117.607635,-0.001345,0.003882,0.098603,289.930511,14.769765,0.986033,-117.607635,294.500488,0.000000
91.130005,65.053841,-117.518669,-0.001341,0.003882,0.098612,289.373932,14.741411,0.986124,-117.518669,294.500488,0.000000
91.500008,64.943993,-117.518669,-0.001345,0.003882,0.098612,288.885315,14.716518,0.986124,-117.518669,294.500488,0.000000
91.870003,64.791695,-117.518669,-0.001350,0.003882,0.098612,288.207855,14.682008,0.986124,-117.518669,294.500488,0.000000
92.240005,65.775871,-117.474190,-0.001354,0.003901,0.099089,292.585693,14.905025,0.990893,-117.474190,294.500488,0.000000
92.610001,65.688744,-117.563156,-0.001354,0.003901,0.099089,292.198120,14.885282,0.990893,-117.563156,294.500488,0.000000
92.980003,65.593407,-117.474190,-0.001341,0.003901,0.099089,291.774048,14.863678,0.990893,-117.474190,294.500488,0.000000
93.350006,65.524147,-117.429710,-0.001332,0.003901,0.099089,291.465973,14.847984,0.990893,-117.429710,294.500488,0.000000
93.720001,65.423607,-117.429710,-0.001337,0.003901,0.099089,291.018738,14.825201,0.990893,-117.429710,294.500488,0.000000
94.090004,65.313011,-117.518669,-0.001341,0.003901,0.099089,290.526794,14.800140,0.990893,-117.518669,294.500488,0.000000
94.460007,65.232948,-117.518669,-0.001341,0.003901,0.099089,290.170654,14.781998,0.990893,-117.518669,294.500488,0.000000
94.830002,65.127205,-117.474190,-0.001337,0.003901,0.099089,289.700287,14.758035,0.990893,-117.474190,294.500488,0.000000
95.200005,65.035591,-117.474190,-0.001350,0.003901,0.099089,289.292755,14.737276,0.990893,-117.474190,294.500488,0.000000
95.570007,64.952553,-117.474190,-0.001337,0.003901,0.099089,288.923370,14.718459,0.990893,-117.474190,294.500488,0.000000
95.940002,64.878090,-117.429710,-0.001324,0.003901,0.099089,288.592163,14.701586,0.990893,-117.429710,294.500488,0.000000
96.310005,65.596397,-117.474190,-0.001328,0.003912,0.099358,291.787354,14.864356,0.993580,-117.474190,294.500488,0.000000
96.680008,65.593407,-117.429710,-0.001319,0.003912,0.099358,291.774048,14.863678,0.993580,-117.429710,294.500488,0.000000
97.050003,65.567345,-117.385231,-0.001319,0.003912,0.099358,291.658112,14.857773,0.993580,-117.385231,294.500488,0.000000
97.420006,65.510368,-117.429710,-0.001319,0.003912,0.099358,291.404663,14.844861,0.993580,-117.429710,294.500488,0.000000
97.790001,65.423988,-117.474190,-0.001332,0.003912,0.099358,291.020447,14.825288,0.993580,-117.474190,294.500488,0.000000
98.160004,65.332756,-117.429710,-0.001324,0.003912,0.099358,290.614624,14.804614,0.993580,-117.429710,294.500488,0.000000
98.530006,65.272423,-117.429710,-0.001319,0.003912,0.099358,290.346252,14.790943,0.993580,-117.429710,294.500488,0.000000
98.900002,65.209496,-117.429710,-0.001315,0.003912,0.099358,290.066315,14.776683,0.993580,-117.429710,294.500488,0.000000
99.270004,65.121239,-117.429710,-0.001315,0.003912,0.099358,289.673737,14.756683,0.993580,-117.429710,294.500488,0.000000
99.640007,65.049751,-117.385231,-0.001324,0.003912,0.099366,289.355743,14.740485,0.993664,-117.385231,294.500488,0.000000
100.010002,65.009911,-117.429710,-0.001315,0.003912,0.099375,289.178528,14.731456,0.993754,-117.429710,294.500488,0.000000
100.380005,64.951073,-117.385231,-0.001315,0.003912,0.099375,288.916809,14.718123,0.993754,-117.385231,294.500488,0.000000
100.750008,65.216194,-117.340752,-0.001319,0.003918,0.099506,290.096130,14.778201,0.995056,-117.340752,294.500488,0.000000
101.120003,65.216194,-117.385231,-0.001324,0.003918,0.099506,290.096130,14.778201,0.995056,-117.385231,294.500488,0.000000
101.490005,65.180077,-117.385231,-0.001332,0.003918,0.099506,289.935455,14.770016,0.995056,-117.385231,294.500488,0.000000
101.860008,65.111565,-117.385231,-0.001328,0.003918,0.099506,289.630707,14.754492,0.995056,-117.385231,294.500488,0.000000
102.230003,65.045280,-117.385231,-0.001328,0.003918,0.099506,289.335846,14.739471,0.995056,-117.385231,294.500488,0.000000
102.600006,65.003197,-117.340752,-0.001315,0.003918,0.099506,289.148651,14.729935,0.995056,-117.340752,294.500488,0.000000
102.970001,64.943626,-117.296265,-0.001324,0.003918,0.099506,288.883667,14.716436,0.995056,-117.296265,294.500488,0.000000
103.340004,65.238167,-117.340752,-0.001315,0.003922,0.099627,290.193848,14.783179,0.996268,-117.340752,294.500488,0.000000
103.710007,65.222908,-117.340752,-0.001328,0.003922,0.099627,290.125977,14.779722,0.996268,-117.340752,294.500488,0.000000
104.080002,65.199440,-117.296265,-0.001319,0.003922,0.099627,290.021606,14.774405,0.996268,-117.296265,294.500488,0.000000
104.450005,65.165184,-117.296265,-0.001328,0.003922,0.099627,289.869202,14.766642,0.996268,-117.296265,294.500488,0.000000
104.820007,65.092949,-117.296265,-0.001332,0.003922,0.099627,289.547913,14.750273,0.996268,-117.296265,294.500488,0.000000
105.190002,65.039696,-117.296265,-0.001324,0.003922,0.099627,289.311005,14.738206,0.996268,-117.296265,294.500488,0.000000
105.560005,64.989799,-117.296265,-0.001332,0.003922,0.099627,289.089081,14.726899,0.996268,-117.296265,294.500488,0.000000
105.930008,64.951820,-117.340752,-0.001311,0.003922,0.099627,288.920135,14.718292,0.996268,-117.340752,294.500488,0.000000
106.300003,64.886284,-117.340752,-0.001319,0.003922,0.099627,288.628601,14.703442,0.996268,-117.340752,294.500488,0.000000
106.670006,65.392708,-117.296265,-0.001311,0.003930,0.099827,290.881287,14.818199,0.998266,-117.296265,294.500488,0.000000
107.040009,65.467171,-117.296265,-0.001306,0.003930,0.099827,291.212524,14.835073,0.998266,-117.296265,294.500488,0.000000
107.410004,65.440742,-117.296265,-0.001328,0.003930,0.099827,291.094971,14.829084,0.998266,-117.296265,294.500488,0.000000
107.780006,65.388985,-117.296265,-0.001306,0.003930,0.099827,290.864716,14.817355,0.998266,-117.296265,294.500488,0.000000
108.150002,65.335365,-117.296265,-0.001319,0.003930,0.099827,290.626221,14.805205,0.998266,-117.296265,294.500488,0.000000
108.520004,65.303337,-117.296265,-0.001324,0.003930,0.099827,290.483765,14.797948,0.998266,-117.296265,294.500488,0.000000
108.890007,65.272804,-117.296265,-0.001319,0.003930,0.099827,290.347931,14.791029,0.998266,-117.296265,294.500488,0.000000
109.260002,65.229973,-117.296265,-0.001328,0.003930,0.099827,290.157410,14.781323,0.998266,-117.296265,294.500488,0.000000
109.630005,65.193108,-117.251785,-0.001319,0.003930,0.099827,289.993439,14.772969,0.998266,-117.251785,294.500488,0.000000
110.000008,65.127205,-117.251785,-0.001319,0.003930,0.099827,289.700287,14.758035,0.998266,-117.251785,294.500488,0.000000
110.370003,65.063896,-117.251785,-0.001324,0.003930,0.099827,289.418671,14.743690,0.998266,-117.251785,294.500488,0.000000
110.740005,65.023689,-117.296265,-0.001324,0.003930,0.099827,289.239807,14.734578,0.998266,-117.296265,294.500488,0.000000
111.110008,64.976768,-117.340752,-0.001324,0.003931,0.099835,289.031097,14.723947,0.998349,-117.340752,294.500488,0.000000
111.480003,64.941765,-117.251785,-0.001311,0.003931,0.099835,288.875397,14.716014,0.998349,-117.251785,294.500488,0.000000
111.850006,64.901176,-117.251785,-0.001319,0.003931,0.099835,288.694855,14.706817,0.998349,-117.251785,294.500488,0.000000
112.220009,64.821480,-117.207306,-0.001311,0.003931,0.099844,288.340332,14.688757,0.998440,-117.207306,294.500488,0.000000
112.590004,65.599373,-117.251785,-0.001311,0.003941,0.100104,291.800598,14.865030,1.001037,-117.251785,294.500488,0.000000
112.960007,65.723747,-117.162827,-0.001324,0.003941,0.100104,292.353821,14.893213,1.001037,-117.162827,294.500488,0.000000
113.330002,65.737892,-117.207306,-0.001302,0.003941,0.100104,292.416748,14.896420,1.001037,-117.207306,294.500488,0.000000
113.700005,65.680168,-117.251785,-0.001293,0.003941,0.100104,292.159973,14.883339,1.001037,-117.251785,294.500488,0.000000
114.070007,65.653358,-117.162827,-0.001311,0.003941,0.100104,292.040710,14.877264,1.001037,-117.162827,294.500488,0.000000
114.440002,65.620598,-117.162827,-0.001319,0.003941,0.100104,291.894989,14.869841,1.001037,-117.162827,294.500488,0.000000
114.810005,65.585594,-117.162827,-0.001315,0.003941,0.100104,291.739288,14.861908,1.001037,-117.162827,294.500488,0.000000
115.180008,65.556923,-117.251785,-0.001306,0.003941,0.100104,291.611755,14.855412,1.001037,-117.251785,294.500488,0.000000
115.550003,65.534584,-117.162827,-0.001311,0.003941,0.100104,291.512390,14.850348,1.001037,-117.162827,294.500488,0.000000
115.920006,65.487282,-117.118347,-0.001302,0.003941,0.100104,291.301971,14.839630,1.001037,-117.118347,294.500488,0.000000
116.290009,65.461220,-117.162827,-0.001306,0.003941,0.100104,291.186035,14.833725,1.001037,-117.162827,294.500488,0.000000
116.660004,65.381905,-117.162827,-0.001315,0.003941,0.100104,290.833252,14.815751,1.001037,-117.162827,294.500488,0.000000
117.030006,65.334618,-117.162827,-0.001306,0.003941,0.100104,290.622894,14.805036,1.001037,-117.162827,294.500488,0.000000
117.400009,65.309669,-117.118347,-0.001306,0.003941,0.100104,290.511932,14.799383,1.001037,-117.118347,294.500488,0.000000
117.770004,65.280617,-117.073860,-0.001298,0.003941,0.100104,290.382690,14.792799,1.001037,-117.073860,294.500488,0.000000
118.140007,65.258278,-117.162827,-0.001311,0.003941,0.100104,290.283325,14.787737,1.001037,-117.162827,294.500488,0.000000
118.510002,65.197960,-117.162827,-0.001319,0.003941,0.100104,290.015015,14.774069,1.001037,-117.162827,294.500488,0.000000
118.880005,65.151405,-117.118347,-0.001311,0.003941,0.100104,289.807922,14.763519,1.001037,-117.118347,294.500488,0.000000
119.250008,65.105598,-117.118347,-0.001311,0.003941,0.100104,289.604156,14.753139,1.001037,-117.118347,294.500488,0.000000
119.620003,65.066505,-117.029381,-0.001298,0.003941,0.100104,289.430267,14.744281,1.001037,-117.029381,294.500488,0.000000
119.990005,65.011391,-117.118347,-0.001298,0.003942,0.100130,289.185120,14.731791,1.001302,-117.118347,294.500488,0.000000
120.360008,64.997612,-117.029381,-0.001306,0.003942,0.100130,289.123810,14.728669,1.001302,-117.029381,294.500488,0.000000
120.730003,64.982353,-117.073860,-0.001293,0.003942,0.100138,289.055939,14.725212,1.001385,-117.073860,294.500488,0.000000
121.100006,64.957405,-117.118347,-0.001306,0.003942,0.100138,288.944977,14.719558,1.001385,-117.118347,294.500488,0.000000
121.470009,64.925743,-117.073860,-0.001293,0.003942,0.100138,288.804138,14.712383,1.001385,-117.073860,294.500488,0.000000
121.840004,64.868782,-117.029381,-0.001302,0.003942,0.100138,288.550751,14.699475,1.001385,-117.029381,294.500488,0.000000
122.210007,65.559532,-117.073860,-0.001306,0.003951,0.100364,291.623352,14.856002,1.003641,-117.073860,294.500488,0.000000
122.580009,65.579262,-117.073860,-0.001298,0.003951,0.100364,291.711121,14.860474,1.003641,-117.073860,294.500488,0.000000
122.950005,65.585960,-117.073860,-0.001298,0.003951,0.100364,291.740936,14.861991,1.003641,-117.073860,294.500488,0.000000
123.320007,65.571068,-117.029381,-0.001298,0.003951,0.100364,291.674683,14.858616,1.003641,-117.029381,294.500488,0.000000
123.690002,65.546120,-117.073860,-0.001302,0.003951,0.100364,291.563690,14.852962,1.003641,-117.073860,294.500488,0.000000
124.060005,65.545006,-117.073860,-0.001319,0.003951,0.100364,291.558746,14.852711,1.003641,-117.073860,294.500488,0.000000
124.430008,65.517448,-117.029381,-0.001293,0.003951,0.100364,291.436157,14.846466,1.003641,-117.029381,294.500488,0.000000
124.800003,65.483940,-117.029381,-0.001293,0.003951,0.100364,291.287109,14.838873,1.003641,-117.029381,294.500488,0.000000
125.170006,65.442223,-117.029381,-0.001293,0.003951,0.100364,291.101532,14.829420,1.003641,-117.029381,294.500488,0.000000
125.540009,65.401634,-116.984901,-0.001319,0.003951,0.100364,290.920990,14.820223,1.003641,-116.984901,294.500488,0.000000
125.910004,65.371483,-116.984901,-0.001302,0.003951,0.100364,290.786865,14.813390,1.003641,-116.984901,294.500488,0.000000
126.280006,65.340950,-117.029381,-0.001298,0.003951,0.100364,290.651062,14.806471,1.003641,-117.029381,294.500488,0.000000
126.650009,65.298500,-116.984901,-0.001298,0.003951,0.100364,290.462250,14.796852,1.003641,-116.984901,294.500488,0.000000
127.020004,65.288811,-116.984901,-0.001302,0.003952,0.100372,290.419128,14.794656,1.003724,-116.984901,294.500488,0.000000
127.390007,65.257912,-116.984901,-0.001306,0.003952,0.100372,290.281677,14.787654,1.003724,-116.984901,294.500488,0.000000
127.760010,65.248970,-116.984901,-0.001306,0.003952,0.100372,290.241913,14.785628,1.003724,-116.984901,294.500488,0.000000
128.130005,65.213585,-117.029381,-0.001311,0.003952,0.100372,290.084503,14.777609,1.003724,-117.029381,294.500488,0.000000
128.500000,65.170769,-116.984901,-0.001281,0.003952,0.100372,289.894043,14.767907,1.003724,-116.984901,294.500488,0.000000
128.870010,65.119759,-116.984901,-0.001285,0.003952,0.100372,289.667145,14.756349,1.003724,-116.984901,294.500488,0.000000
129.240005,65.098152,-116.940422,-0.001289,0.003952,0.100372,289.571045,14.751452,1.003724,-116.940422,294.500488,0.000000
129.610001,65.063896,-116.895943,-0.001293,0.003952,0.100372,289.418671,14.743690,1.003724,-116.895943,294.500488,0.000000
129.980011,65.032997,-116.984901,-0.001298,0.003952,0.100372,289.281219,14.736689,1.003724,-116.984901,294.500488,0.000000
130.350006,65.019585,-116.940422,-0.001285,0.003946,0.100216,289.221558,14.733649,1.002164,-116.940422,0.100277,0.000000
130.720001,64.971550,-116.940422,-0.001285,0.003933,0.099905,289.007874,14.722764,0.999046,-116.940422,0.099662,0.000000
131.090012,64.841957,-116.895943,-0.001268,0.003914,0.099419,288.431427,14.693397,0.994186,-116.895943,0.099046,0.000000
131.460007,64.758186,-116.940422,-0.001281,0.003893,0.098889,288.058807,14.674415,0.988895,-116.940422,0.098430,0.000000
131.830002,64.724297,-116.940422,-0.001276,0.003868,0.098248,287.908051,14.666736,0.982483,-116.940422,0.097815,0.000000
132.200012,64.665459,-116.984901,-0.001268,0.003845,0.097667,287.646332,14.653402,0.976669,-116.984901,0.097198,0.000000
132.570007,64.647957,-116.895943,-0.001268,0.003822,0.097086,287.568481,14.649437,0.970856,-116.895943,0.096583,0.000000
132.940002,64.587257,-116.940422,-0.001263,0.003797,0.096444,287.298462,14.635682,0.964444,-116.940422,0.095958,0.000000
133.310013,64.547783,-116.940422,-0.001276,0.003776,0.095906,287.122864,14.626737,0.959062,-116.940422,0.095343,0.000000
133.680008,64.528053,-116.940422,-0.001276,0.003755,0.095369,287.035126,14.622266,0.953688,-116.940422,0.094727,0.000000
134.050003,64.404793,-116.984901,-0.001272,0.003730,0.094753,286.486816,14.594335,0.947533,-116.984901,0.094111,0.000000
134.420013,63.973595,-116.895943,-0.001276,0.003707,0.094164,284.568756,14.496624,0.941636,-116.895943,0.093495,0.000000
134.790009,63.211342,-116.895943,-0.001259,0.003686,0.093617,281.178101,14.323895,0.936171,-116.895943,0.092880,0.000000
135.160004,62.071510,-116.851456,-0.001246,0.003660,0.092967,276.107880,14.065606,0.929669,-116.851456,0.092264,0.000000
135.530014,60.901520,-116.895943,-0.001246,0.003640,0.092455,270.903503,13.800482,0.924551,-116.895943,0.091648,0.000000
135.900009,59.733757,-116.940422,-0.001233,0.003622,0.091987,265.709015,13.535863,0.919866,-116.940422,0.091033,0.000000
136.270004,58.558922,-116.851456,-0.001224,0.003605,0.091570,260.483093,13.269641,0.915702,-116.851456,0.090408,0.000000
136.639999,56.167175,-116.806976,-0.001224,0.003574,0.090790,249.844070,12.727664,0.907898,-116.806976,0.089793,0.000000
137.010010,54.140724,-116.851456,-0.001233,0.003549,0.090148,240.829971,12.268463,0.901479,-116.851456,0.089177,0.000000
137.380005,51.822708,-116.895943,-0.001233,0.003524,0.089507,230.518921,11.743194,0.895067,-116.895943,0.088561,0.000000
137.750000,49.645447,-116.895943,-0.001233,0.003503,0.088968,220.833969,11.249819,0.889685,-116.895943,0.087945,0.000000
138.120010,47.923592,-116.895943,-0.001224,0.003487,0.088570,213.174789,10.859641,0.885696,-116.895943,0.087330,0.000000
138.490005,45.027657,-116.851456,-0.001229,0.003460,0.087876,200.293015,10.203413,0.878762,-116.851456,0.086714,0.000000
138.860001,42.486954,-116.851456,-0.001229,0.003435,0.087260,188.991409,9.627681,0.872600,-116.851456,0.086098,0.000000
139.230011,39.389191,-116.806976,-0.001229,0.003406,0.086523,175.211868,8.925718,0.865235,-116.806976,0.085483,0.000000
139.600006,37.007492,-116.851456,-0.001233,0.003385,0.085968,164.617554,8.386018,0.859678,-116.851456,0.084858,0.000000
139.970001,34.973228,-116.851456,-0.001233,0.003364,0.085439,155.568695,7.925047,0.854387,-116.851456,0.084243,0.000000
140.340012,32.228470,-116.806976,-0.001220,0.003336,0.084728,143.359390,7.303076,0.847279,-116.806976,0.083626,0.000000
140.710007,29.665428,-116.762497,-0.001233,0.003318,0.084268,131.958420,6.722282,0.842684,-116.762497,0.083011,0.000000
141.080002,26.491699,-116.806976,-0.001233,0.003286,0.083471,117.840965,6.003105,0.834706,-116.806976,0.082395,0.000000
141.450012,23.973717,-116.762497,-0.001229,0.003263,0.082881,106.640419,5.432522,0.828809,-116.762497,0.081779,0.000000
141.820007,21.023407,-116.851456,-0.001224,0.003236,0.082187,93.516785,4.763972,0.821867,-116.851456,0.081163,0.000000
142.190002,18.675224,-116.762497,-0.001224,0.003216,0.081692,83.071548,4.231866,0.816924,-116.762497,0.080548,0.000000
142.560013,16.283478,-116.806976,-0.001224,0.003194,0.081138,72.432526,3.689889,0.811375,-116.806976,0.079932,0.000000
142.930008,13.049423,-116.762497,-0.001237,0.003162,0.080305,58.046734,2.957042,0.803049,-116.762497,0.079308,0.000000
143.300003,10.708687,-116.762497,-0.001237,0.003141,0.079776,47.634617,2.426623,0.797757,-116.762497,0.078692,0.000000
143.670013,9.076210,-116.851456,-0.001233,0.003125,0.079386,40.372997,2.056699,0.793859,-116.851456,0.078076,0.000000
144.040009,5.208008,-116.806976,-0.001237,0.003088,0.078440,23.166376,1.180151,0.784404,-116.806976,0.077461,0.000000
144.410004,3.288055,-116.806976,-0.001224,0.003072,0.078024,14.626001,0.745084,0.780241,-116.806976,0.076845,0.000000
144.780014,0.841934,-116.718018,-0.001224,0.003047,0.077391,3.745110,0.190785,0.773913,-116.718018,0.076229,0.000000
145.150009,-1.534172,-116.762497,-0.001237,0.003021,0.076741,-6.824338,-0.347648,0.767410,-116.762497,0.075613,0.000000
145.520004,-3.904694,-116.806976,-0.001233,0.002995,0.076064,-17.368944,-0.884816,0.760643,-116.806976,0.074998,0.000000
145.889999,-0.630798,-116.718018,-0.001259,0.002976,0.075579,-2.805931,-0.142941,0.755791,-116.718018,0.074382,0.000000
146.260010,-0.519455,-116.762497,-0.001263,0.002947,0.074850,-2.310651,-0.117710,0.748501,-116.762497,0.073758,0.000000
146.630005,-0.525787,-116.806976,-0.001289,0.002919,0.074130,-2.338819,-0.119145,0.741302,-116.806976,0.073142,0.000000
147.000000,-0.520943,-116.762497,-0.001332,0.002892,0.073463,-2.317269,-0.118047,0.734625,-116.762497,0.072526,0.000000
147.370010,-0.453171,-116.762497,-0.001350,0.002878,0.073090,-2.015804,-0.102690,0.730901,-116.762497,0.071911,0.000000
147.740005,-0.448334,-116.762497,-0.001362,0.002859,0.072630,-1.994288,-0.101594,0.726299,-116.762497,0.071295,0.000000
148.110001,-0.463226,-116.673538,-0.001388,0.002823,0.071711,-2.060534,-0.104969,0.717109,-116.673538,0.070679,0.000000
148.480011,-0.500465,-116.673538,-0.001410,0.002801,0.071156,-2.226181,-0.113407,0.711560,-116.673538,0.070063,0.000000
148.850006,-0.519455,-116.718018,-0.001449,0.002772,0.070401,-2.310651,-0.117710,0.704013,-116.718018,0.069448,0.000000
149.220001,-0.512383,-116.718018,-0.001466,0.002751,0.069881,-2.279191,-0.116108,0.698813,-116.718018,0.068831,0.000000
149.590012,-0.490036,-116.718018,-0.001483,0.002727,0.069257,-2.179789,-0.111044,0.692568,-116.718018,0.068208,0.000000
149.960007,-0.481102,-116.718018,-0.001509,0.002705,0.068702,-2.140049,-0.109019,0.687019,-116.718018,0.067591,0.000000
150.330002,-0.492645,-116.673538,-0.001522,0.002681,0.068086,-2.191396,-0.111635,0.680857,-116.673538,0.066976,0.000000
150.700012,-0.504936,-116.673538,-0.001565,0.002648,0.067262,-2.246068,-0.114420,0.672621,-116.673538,0.066360,0.000000
151.070007,-0.540680,-116.718018,-0.001587,0.002630,0.066811,-2.405064,-0.122520,0.668110,-116.718018,0.065744,0.000000
151.440002,-0.529510,-116.718018,-0.001613,0.002605,0.066161,-2.355380,-0.119989,0.661607,-116.718018,0.065129,0.000000
151.810013,-0.514244,-116.673538,-0.001634,0.002576,0.065433,-2.287472,-0.116529,0.654325,-116.673538,0.064513,0.000000
152.180008,-0.535469,-116.629051,-0.001638,0.002554,0.064859,-2.381885,-0.121339,0.648595,-116.629051,0.063897,0.000000
152.550003,-0.510895,-116.629051,-0.001673,0.002535,0.064392,-2.272573,-0.115770,0.643917,-116.629051,0.064236,0.000000
152.600006,-0.510147,-116.629051,-0.001681,0.002535,0.064392,-2.269248,-0.115601,0.643917,-116.629051,0.064236,0.000000