File: Data/compression 26/AutoNoHeating-17-26-reverse-1-2_09262024_173025.csv
Time (sec),S:Load (lbs),S:HL1 (DIM),S:LVDT (in),S:Position (in),Ch:Position (mm),Ch:Load (N),Ch:Stress (MPa),Ch:Strain (mm/mm),Ch:HL1 (DIM),Set Point (),Cycles ()
0.110000,-0.122879,-18.948885,-0.012508,-0.007768,-0.197303,-0.546593,-0.027845,-1.973028,-18.948885,-0.197095,0.000000
0.530000,-0.111710,-18.904404,-0.012503,-0.007675,-0.194952,-0.496909,-0.025314,-1.949524,-18.904404,-0.193955,0.000000
0.950000,-0.109100,-18.904404,-0.012327,-0.007411,-0.188249,-0.485303,-0.024722,-1.882493,-18.904404,-0.186965,0.000000
1.370000,-0.159744,-18.904404,-0.012029,-0.007138,-0.181311,-0.710578,-0.036199,-1.813109,-18.904404,-0.179976,0.000000
1.790000,-0.120644,-18.993366,-0.011749,-0.006858,-0.174200,-0.536650,-0.027338,-1.741998,-18.993366,-0.172968,0.000000
2.210000,-0.141869,-18.993366,-0.011486,-0.006585,-0.167254,-0.631063,-0.032148,-1.672538,-18.993366,-0.165978,0.000000
2.630000,-0.106125,-19.037848,-0.011201,-0.006317,-0.160445,-0.472067,-0.024048,-1.604455,-19.037848,-0.158972,0.000000
3.050000,-0.113571,-18.948885,-0.010943,-0.006037,-0.153334,-0.505190,-0.025736,-1.533344,-18.948885,-0.151982,0.000000
3.470000,-0.102028,-18.993366,-0.010654,-0.005759,-0.146276,-0.453843,-0.023120,-1.462756,-18.993366,-0.144974,0.000000
3.890000,-0.097931,-19.037848,-0.010352,-0.005481,-0.139224,-0.435618,-0.022191,-1.392243,-19.037848,-0.137984,0.000000
4.310000,-0.081917,-19.082329,-0.010072,-0.005206,-0.132235,-0.364384,-0.018563,-1.322351,-19.082329,-0.130994,0.000000
4.730000,-0.096069,-19.082329,-0.009817,-0.004937,-0.125409,-0.427338,-0.021770,-1.254095,-19.082329,-0.123988,0.000000
5.150000,-0.127350,-18.993366,-0.009524,-0.004665,-0.118481,-0.566480,-0.028858,-1.184808,-18.993366,-0.116998,0.000000
5.570000,-0.114685,-19.037848,-0.009257,-0.004384,-0.111352,-0.510145,-0.025988,-1.113524,-19.037848,-0.109991,0.000000
5.990000,-0.060318,-19.082329,-0.008990,-0.004108,-0.104336,-0.268308,-0.013668,-1.043359,-19.082329,-0.103001,0.000000
6.410000,-0.074471,-19.082329,-0.008666,-0.003830,-0.097285,-0.331261,-0.016875,-0.972854,-19.082329,-0.096011,0.000000
6.830000,-0.072609,-19.082329,-0.008390,-0.003557,-0.090348,-0.322981,-0.016453,-0.903477,-19.082329,-0.089003,0.000000
7.250000,-0.115433,-19.126808,-0.008114,-0.003282,-0.083358,-0.513470,-0.026157,-0.833578,-19.126808,-0.082014,0.000000
7.670001,-0.177246,-19.126808,-0.007825,-0.003005,-0.076325,-0.788430,-0.040165,-0.763247,-19.126808,-0.075007,0.000000
8.090000,-0.145966,-19.126808,-0.007528,-0.002736,-0.069482,-0.649287,-0.033076,-0.694823,-19.126808,-0.068017,0.000000
8.510000,-0.066277,-19.171289,-0.007269,-0.002455,-0.062354,-0.294813,-0.015018,-0.623539,-19.171289,-0.061009,0.000000
8.930000,-0.065910,-19.171289,-0.006954,-0.002179,-0.055347,-0.293184,-0.014935,-0.553465,-19.171289,-0.054020,0.000000
9.350000,-0.095695,-19.126808,-0.006687,-0.001906,-0.048400,-0.425675,-0.021685,-0.484005,-19.126808,-0.047030,0.000000
9.770000,-0.131447,-19.171289,-0.006390,-0.001624,-0.041254,-0.584705,-0.029786,-0.412538,-19.171289,-0.040023,0.000000
10.190001,-0.142990,-19.171289,-0.006127,-0.001356,-0.034438,-0.636052,-0.032402,-0.344380,-19.171289,-0.033033,0.000000
10.610001,-0.086761,-19.215771,-0.005846,-0.001080,-0.027431,-0.385934,-0.019660,-0.274306,-19.215771,-0.026026,0.000000
11.030001,-0.061440,-19.171289,-0.005540,-0.000802,-0.020371,-0.273297,-0.013922,-0.203711,-19.171289,-0.019036,0.000000
11.450001,-0.085640,-19.215771,-0.005260,-0.000526,-0.013373,-0.380946,-0.019406,-0.133728,-19.215771,-0.012046,0.000000
11.870001,-0.094955,-19.171289,-0.004997,-0.000252,-0.006409,-0.422383,-0.021517,-0.064093,-19.171289,-0.005039,0.000000
12.290001,-0.113945,-19.260252,-0.004704,0.000028,0.000711,-0.506853,-0.025820,0.007108,-19.260252,0.001951,0.000000
12.710001,0.126236,-19.260252,-0.004462,-0.000000,-0.000000,0.561526,0.028605,-0.000000,-19.260252,0.000156,0.000000
13.130001,0.110970,-19.260252,-0.004458,-0.000000,-0.000008,0.493617,0.025146,-0.000083,-19.260252,0.000156,0.000000
13.550000,0.103897,-19.260252,-0.004462,-0.000000,-0.000008,0.462157,0.023543,-0.000083,-19.260252,0.000790,0.000000
13.970000,0.163101,-19.260252,-0.004449,0.000016,0.000408,0.725510,0.036959,0.004080,-19.260252,0.001483,0.000000
14.390000,0.320992,-19.304733,-0.004449,0.000041,0.001041,1.427842,0.072738,0.010408,-19.304733,0.002185,0.000000
14.810000,0.551483,-19.349215,-0.004411,0.000071,0.001804,2.453120,0.124968,0.018039,-19.349215,0.002888,0.000000
15.230000,0.759644,-19.349215,-0.004385,0.000095,0.002403,3.379063,0.172138,0.024027,-19.349215,0.003590,0.000000
15.650001,1.235535,-19.349215,-0.004359,0.000125,0.003174,5.495933,0.279976,0.031740,-19.349215,0.004285,0.000000
16.070002,1.630249,-19.349215,-0.004342,0.000155,0.003937,7.251710,0.369420,0.039370,-19.349215,0.004987,0.000000
16.490002,2.019753,-19.349215,-0.004312,0.000178,0.004527,8.984308,0.457682,0.045267,-19.349215,0.005689,0.000000
16.910002,2.537720,-19.393694,-0.004281,0.000208,0.005273,11.288342,0.575055,0.052731,-19.393694,0.006383,0.000000
17.330000,3.116760,-19.349215,-0.004260,0.000237,0.006027,13.864042,0.706268,0.060271,-19.349215,0.007085,0.000000
17.750000,3.407959,-19.349215,-0.004251,0.000255,0.006478,15.159359,0.772255,0.064782,-19.349215,0.007788,0.000000
18.170000,3.911774,-19.393694,-0.004221,0.000288,0.007319,17.400438,0.886421,0.073192,-19.393694,0.008490,0.000000
18.590000,4.580933,-19.393694,-0.004182,0.000317,0.008057,20.377007,1.038054,0.080565,-19.393694,0.009184,0.000000
19.010000,5.146935,-19.393694,-0.004156,0.000344,0.008742,22.894709,1.166312,0.087416,-19.393694,0.009886,0.000000
19.430000,5.686501,-19.393694,-0.004156,0.000374,0.009487,25.294817,1.288579,0.094872,-19.393694,0.010589,0.000000
19.850000,6.156067,-19.438175,-0.004126,0.000397,0.010094,27.383553,1.394985,0.100943,-19.438175,0.011283,0.000000
20.270000,6.463272,-19.482656,-0.004100,0.000422,0.010728,28.750071,1.464598,0.107279,-19.482656,0.011985,0.000000
20.690001,6.953690,-19.482656,-0.004061,0.000447,0.011352,30.931557,1.575729,0.113524,-19.482656,0.012688,0.000000
21.110001,7.646675,-19.482656,-0.004036,0.000487,0.012358,34.014111,1.732761,0.123577,-19.482656,0.013390,0.000000
21.530001,7.759125,-19.438175,-0.004014,0.000503,0.012774,34.514309,1.758243,0.127740,-19.438175,0.014084,0.000000
21.950001,8.468498,-19.527138,-0.003988,0.000540,0.013719,37.669762,1.918989,0.137195,-19.527138,0.014786,0.000000
22.370001,8.430519,-19.571619,-0.003949,0.000558,0.014162,37.500820,1.910383,0.141616,-19.571619,0.015489,0.000000
22.790001,9.110092,-19.571619,-0.003945,0.000594,0.015090,40.523712,2.064376,0.150896,-19.571619,0.016191,0.000000
23.210001,9.120148,-19.571619,-0.003906,0.000612,0.015532,40.568443,2.066655,0.155325,-19.571619,0.016885,0.000000
23.630001,9.609818,-19.571619,-0.003889,0.000645,0.016373,42.746605,2.177616,0.163735,-19.571619,0.017588,0.000000
24.050001,9.954636,-19.527138,-0.003876,0.000673,0.017084,44.280430,2.255753,0.170843,-19.527138,0.018290,0.000000
24.470001,10.009750,-19.616100,-0.003850,0.000700,0.017769,44.525593,2.268242,0.177693,-19.616100,0.018984,0.000000
24.890001,10.656189,-19.482656,-0.003807,0.000733,0.018611,47.401096,2.414727,0.186111,-19.482656,0.019686,0.000000
25.310001,10.830086,-19.571619,-0.003790,0.000759,0.019270,48.174629,2.454132,0.192697,-19.571619,0.020388,0.000000
25.730001,11.075104,-19.571619,-0.003773,0.000785,0.019929,49.264523,2.509655,0.199290,-19.571619,0.021091,0.000000
26.150002,11.069145,-19.616100,-0.003747,0.000810,0.020571,49.238018,2.508304,0.205709,-19.616100,0.021785,0.000000
26.570002,11.812027,-19.660580,-0.003712,0.000846,0.021482,52.542519,2.676644,0.214815,-19.660580,0.022488,0.000000
26.990002,11.979973,-19.660580,-0.003678,0.000873,0.022175,53.289581,2.714700,0.221749,-19.660580,0.023190,0.000000
27.410002,11.732346,-19.660580,-0.003656,0.000889,0.022591,52.188080,2.658587,0.225913,-19.660580,0.023883,0.000000
27.830002,12.314735,-19.660580,-0.003630,0.000922,0.023424,54.778679,2.790559,0.234240,-19.660580,0.024586,0.000000
28.250002,12.675560,-19.749542,-0.003604,0.000953,0.024204,56.383705,2.872323,0.242044,-19.749542,0.025288,0.000000
28.670002,13.144005,-19.749542,-0.003579,0.000983,0.024977,58.467453,2.978474,0.249765,-19.749542,0.025991,0.000000
29.090002,13.304497,-19.705061,-0.003544,0.001011,0.025679,59.181358,3.014842,0.256790,-19.705061,0.026684,0.000000
29.510002,13.434830,-19.705061,-0.003535,0.001034,0.026251,59.761108,3.044376,0.262513,-19.705061,0.027387,0.000000
29.930002,13.564789,-19.660580,-0.003510,0.001058,0.026867,60.339195,3.073825,0.268667,-19.660580,0.028089,0.000000
30.350002,13.729752,-19.705061,-0.003492,0.001085,0.027552,61.072987,3.111206,0.275518,-19.705061,0.028792,0.000000
30.770002,14.121483,-19.749542,-0.003462,0.001115,0.028324,62.815495,3.199974,0.283239,-19.749542,0.029486,0.000000
31.190001,14.936981,-19.749542,-0.003423,0.001154,0.029303,66.443008,3.384768,0.293034,-19.749542,0.030188,0.000000
31.610001,14.862877,-19.794024,-0.003397,0.001178,0.029928,66.113380,3.367976,0.299279,-19.794024,0.030891,0.000000
32.030003,14.699409,-19.749542,-0.003385,0.001197,0.030405,65.386238,3.330934,0.304048,-19.749542,0.031584,0.000000
32.450001,15.328346,-19.838505,-0.003380,0.001227,0.031160,68.183891,3.473453,0.311595,-19.838505,0.032287,0.000000
32.870003,15.581184,-19.838505,-0.003350,0.001256,0.031897,69.308571,3.530747,0.318968,-19.838505,0.032989,0.000000
33.290001,16.017235,-19.794024,-0.003311,0.001288,0.032712,71.248222,3.629557,0.327121,-19.794024,0.033692,0.000000
33.710003,16.196342,-19.838505,-0.003294,0.001314,0.033388,72.044930,3.670144,0.333881,-19.838505,0.034386,0.000000
34.130001,16.498337,-19.794024,-0.003264,0.001344,0.034134,73.388268,3.738576,0.341345,-19.794024,0.035088,0.000000
34.550003,16.494614,-19.882986,-0.003242,0.001367,0.034732,73.371704,3.737733,0.347325,-19.882986,0.035791,0.000000
34.970001,16.800331,-19.927465,-0.003234,0.001394,0.035418,74.731606,3.807009,0.354175,-19.927465,0.036484,0.000000
35.390003,16.999176,-19.838505,-0.003203,0.001419,0.036042,75.616112,3.852068,0.360420,-19.838505,0.037187,0.000000
35.810001,17.208076,-19.838505,-0.003169,0.001444,0.036667,76.545349,3.899406,0.366665,-19.838505,0.037889,0.000000
36.230003,17.427780,-19.838505,-0.003134,0.001469,0.037317,77.522636,3.949192,0.373168,-19.838505,0.038592,0.000000
36.650002,18.281258,-19.882986,-0.003134,0.001505,0.038218,81.319092,4.142592,0.382184,-19.882986,0.039286,0.000000
37.070004,17.842972,-19.927465,-0.003100,0.001525,0.038739,79.369499,4.043275,0.387392,-19.927465,0.039988,0.000000
37.490002,18.018364,-19.971947,-0.003078,0.001554,0.039459,80.149689,4.083020,0.394590,-19.971947,0.040691,0.000000
37.910004,18.635757,-19.882986,-0.003044,0.001590,0.040387,82.895988,4.222923,0.403871,-19.882986,0.041393,0.000000
38.330002,18.794762,-19.882986,-0.003014,0.001616,0.041037,83.603279,4.258954,0.410373,-19.882986,0.042087,0.000000
38.750000,18.864761,-20.016428,-0.002997,0.001637,0.041592,83.914650,4.274816,0.415922,-20.016428,0.042789,0.000000
39.170002,18.870354,-19.971947,-0.002992,0.001664,0.042260,83.939522,4.276083,0.422599,-19.971947,0.043491,0.000000
39.590000,19.268044,-19.927465,-0.002945,0.001689,0.042893,85.708542,4.366201,0.428927,-19.927465,0.044185,0.000000
40.010002,20.054863,-19.927465,-0.002928,0.001724,0.043786,89.208488,4.544497,0.437859,-19.927465,0.044887,0.000000
40.430000,20.195251,-20.060909,-0.002897,0.001752,0.044488,89.832962,4.576309,0.444884,-20.060909,0.045590,0.000000
40.850002,20.283875,-20.016428,-0.002897,0.001773,0.045044,90.227180,4.596392,0.450440,-20.016428,0.046292,0.000000
41.270000,20.705032,-20.016428,-0.002854,0.001803,0.045807,92.100586,4.691827,0.458071,-20.016428,0.046986,0.000000
41.690002,20.903503,-20.060909,-0.002850,0.001828,0.046440,92.983429,4.736802,0.464399,-20.060909,0.047689,0.000000
42.110001,21.639687,-20.016428,-0.002828,0.001862,0.047307,96.258133,4.903623,0.473074,-20.016428,0.048391,0.000000
42.530003,21.807999,-20.016428,-0.002790,0.001888,0.047949,97.006821,4.941763,0.479493,-20.016428,0.049085,0.000000
42.950001,22.096588,-20.060909,-0.002785,0.001914,0.048625,98.290535,5.007158,0.486253,-20.060909,0.049787,0.000000
43.370003,22.462624,-20.060909,-0.002751,0.001945,0.049415,99.918739,5.090103,0.494148,-20.060909,0.050490,0.000000
43.790001,22.223190,-20.060909,-0.002712,0.001961,0.049822,98.853691,5.035847,0.498221,-20.060909,0.051192,0.000000
44.210003,23.367867,-20.060909,-0.002695,0.001999,0.050768,103.945465,5.295234,0.507676,-20.060909,0.051886,0.000000
44.630001,23.557404,-20.105391,-0.002669,0.002026,0.051453,104.788567,5.338184,0.514526,-20.105391,0.052589,0.000000
45.050003,24.140907,-20.149870,-0.002652,0.002055,0.052207,107.384117,5.470407,0.522073,-20.149870,0.053291,0.000000
45.470001,23.999405,-20.194351,-0.002634,0.002077,0.052745,106.754684,5.438343,0.527448,-20.194351,0.053994,0.000000
45.890003,24.642868,-20.194351,-0.002596,0.002106,0.053499,109.616951,5.584154,0.534995,-20.194351,0.054687,0.000000
46.310001,25.492996,-20.149870,-0.002591,0.002138,0.054306,113.398514,5.776795,0.543057,-20.149870,0.055390,0.000000
46.730003,25.733177,-20.194351,-0.002544,0.002167,0.055034,114.466888,5.831221,0.550339,-20.194351,0.056092,0.000000
47.150002,25.650139,-20.149870,-0.002522,0.002192,0.055676,114.097519,5.812405,0.556758,-20.149870,0.056786,0.000000
47.570004,25.920853,-20.194351,-0.002501,0.002211,0.056170,115.301712,5.873749,0.561701,-20.194351,0.057489,0.000000
47.990002,27.177238,-20.194351,-0.002479,0.002250,0.057159,120.890396,6.158451,0.571587,-20.194351,0.058191,0.000000
48.410004,27.499336,-20.194351,-0.002449,0.002278,0.057870,122.323158,6.231439,0.578703,-20.194351,0.058894,0.000000
48.830002,28.015076,-20.238832,-0.002440,0.002303,0.058503,124.617279,6.348307,0.585031,-20.238832,0.059587,0.000000
49.250004,28.431755,-20.238832,-0.002410,0.002331,0.059197,126.470764,6.442728,0.591973,-20.238832,0.060290,0.000000
49.670002,28.941910,-20.283314,-0.002397,0.002356,0.059848,128.740051,6.558331,0.598475,-20.283314,0.060992,0.000000
50.090004,29.676224,-20.283314,-0.002354,0.002386,0.060611,132.006439,6.724728,0.606106,-20.283314,0.061685,0.000000
50.510002,30.067963,-20.238832,-0.002345,0.002411,0.061243,133.748978,6.813498,0.612434,-20.238832,0.062388,0.000000
50.930004,30.653328,-20.283314,-0.002328,0.002437,0.061911,136.352814,6.946144,0.619110,-20.283314,0.063090,0.000000
51.350002,30.590027,-20.283314,-0.002302,0.002461,0.062510,136.071228,6.931799,0.625098,-20.283314,0.063793,0.000000
51.770004,31.274818,-20.283314,-0.002276,0.002484,0.063082,139.117340,7.086975,0.630821,-20.283314,0.064487,0.000000
52.190002,32.983635,-20.238832,-0.002259,0.002522,0.064062,146.718536,7.474198,0.640624,-20.238832,0.065190,0.000000
52.610001,33.929092,-20.283314,-0.002220,0.002554,0.064877,150.924133,7.688442,0.648769,-20.283314,0.065892,0.000000
53.030003,33.990532,-20.327795,-0.002195,0.002577,0.065458,151.197433,7.702365,0.654582,-20.327795,0.066594,0.000000
53.450001,33.908615,-20.372276,-0.002182,0.002596,0.065944,150.833054,7.683802,0.659442,-20.372276,0.067288,0.000000
53.870003,35.551147,-20.416756,-0.002164,0.002633,0.066872,158.139404,8.056005,0.668715,-20.416756,0.067990,0.000000
54.290001,36.780724,-20.372276,-0.002121,0.002664,0.067661,163.608826,8.334631,0.676611,-20.372276,0.068693,0.000000
54.710003,37.245071,-20.372276,-0.002108,0.002690,0.068329,165.674347,8.439854,0.683287,-20.372276,0.069387,0.000000
55.130001,37.919060,-20.372276,-0.002091,0.002718,0.069031,168.672409,8.592582,0.690312,-20.372276,0.070089,0.000000
55.550003,39.153107,-20.416756,-0.002061,0.002749,0.069821,174.161713,8.872221,0.698207,-20.416756,0.070792,0.000000
55.970001,39.468880,-20.461237,-0.002048,0.002773,0.070428,175.566345,8.943776,0.704278,-20.461237,0.071494,0.000000
56.390003,39.964874,-20.372276,-0.002022,0.002793,0.070939,177.772644,9.056170,0.709388,-20.372276,0.072188,0.000000
56.810001,40.788940,-20.416756,-0.002009,0.002818,0.071581,181.438263,9.242906,0.715807,-20.416756,0.072890,0.000000
57.230003,41.633476,-20.461237,-0.001983,0.002844,0.072231,185.194946,9.434280,0.722309,-20.461237,0.073593,0.000000
57.650002,42.813896,-20.505718,-0.001975,0.002873,0.072968,190.445724,9.701767,0.729682,-20.505718,0.074287,0.000000
58.070004,44.507446,-20.461237,-0.001940,0.002908,0.073853,197.979004,10.085531,0.738531,-20.461237,0.074989,0.000000
58.490002,46.062851,-20.505718,-0.001919,0.002940,0.074686,204.897797,10.437991,0.746858,-20.505718,0.075692,0.000000
58.910004,46.863075,-20.461237,-0.001910,0.002968,0.075379,208.457367,10.619325,0.753792,-20.461237,0.076394,0.000000
59.330002,47.825661,-20.505718,-0.001906,0.002993,0.076012,212.739166,10.837449,0.760120,-20.505718,0.077088,0.000000
59.750004,48.673180,-20.550200,-0.001880,0.003018,0.076663,216.509109,11.029500,0.766630,-20.550200,0.077790,0.000000
60.170002,49.590332,-20.505718,-0.001854,0.003045,0.077339,220.588821,11.237329,0.773390,-20.505718,0.078493,0.000000
60.590004,51.033646,-20.550200,-0.001841,0.003071,0.078016,227.008987,11.564389,0.780158,-20.550200,0.079195,0.000000
61.010002,51.852867,-20.505718,-0.001837,0.003095,0.078614,230.653076,11.750028,0.786138,-20.505718,0.079889,0.000000
61.430004,53.575089,-20.594681,-0.001815,0.003128,0.079446,238.313889,12.140288,0.794465,-20.594681,0.080591,0.000000
61.850002,55.274597,-20.639162,-0.001789,0.003157,0.080175,245.873688,12.525403,0.801754,-20.639162,0.081293,0.000000
62.270004,55.489456,-20.550200,-0.001785,0.003172,0.080565,246.829422,12.574091,0.805653,-20.550200,0.081988,0.000000
62.690002,57.595222,-20.594681,-0.001763,0.003208,0.081493,256.196350,13.051264,0.814933,-20.594681,0.082690,0.000000
63.110004,58.435669,-20.594681,-0.001750,0.003230,0.082048,259.934845,13.241712,0.820482,-20.594681,0.083393,0.000000
63.530003,60.844543,-20.550200,-0.001729,0.003268,0.083011,270.650055,13.787570,0.830111,-20.550200,0.084095,0.000000
63.950005,61.711800,-20.683641,-0.001712,0.003288,0.083523,274.507782,13.984094,0.835228,-20.683641,0.084788,0.000000
64.370003,63.064629,-20.639162,-0.001712,0.003317,0.084251,280.525482,14.290649,0.842510,-20.639162,0.085491,0.000000
64.790001,65.025169,-20.639162,-0.001677,0.003347,0.085023,289.246399,14.734915,0.850231,-20.639162,0.086193,0.000000
65.210007,65.304085,-20.639162,-0.001673,0.003367,0.085526,290.487091,14.798118,0.855258,-20.639162,0.086896,0.000000
65.630005,65.724113,-20.639162,-0.001656,0.003370,0.085604,292.355469,14.893297,0.856037,-20.639162,0.015039,0.000000
66.050003,66.257729,-20.728123,-0.001643,0.003393,0.086176,294.729095,15.014216,0.861760,-20.728123,294.500488,0.000000
66.470001,65.158852,-20.683641,-0.001630,0.003380,0.085864,289.841034,14.765207,0.858641,-20.683641,294.500488,0.000000
66.889999,64.233513,-20.728123,-0.001621,0.003381,0.085882,285.724945,14.555522,0.858815,-20.728123,294.500488,0.000000
67.310005,66.194801,-20.728123,-0.001600,0.003209,0.081502,294.449188,14.999957,0.815017,-20.728123,294.500488,0.000000
67.730003,65.374825,-20.683641,-0.001608,0.003279,0.083280,290.801758,14.814147,0.832798,-20.683641,294.500488,0.000000
68.150002,65.170021,-20.772604,-0.001595,0.003408,0.086567,289.890747,14.767738,0.865666,-20.772604,294.500488,0.000000
68.570000,65.536812,-20.817085,-0.001595,0.003421,0.086888,291.522308,14.850854,0.868876,-20.817085,294.500488,0.000000
68.990005,65.077675,-20.772604,-0.001587,0.003421,0.086905,289.479950,14.746812,0.869050,-20.772604,294.500488,0.000000
69.410004,65.434776,-20.728123,-0.001587,0.003431,0.087148,291.068420,14.827732,0.871480,-20.728123,294.500488,0.000000
69.830002,65.050117,-20.817085,-0.001582,0.003431,0.087148,289.357361,14.740567,0.871480,-20.817085,294.500488,0.000000
70.250000,64.778282,-20.861567,-0.001595,0.003434,0.087217,288.148193,14.678968,0.872168,-20.861567,294.500488,0.000000
70.670006,64.806221,-20.817085,-0.001582,0.003437,0.087312,288.272461,14.685300,0.873122,-20.817085,294.500488,0.000000
71.090004,65.377068,-20.728123,-0.001582,0.003447,0.087546,290.811707,14.814655,0.875461,-20.728123,294.500488,0.000000
71.510002,65.101509,-20.772604,-0.001578,0.003447,0.087546,289.585968,14.752213,0.875461,-20.772604,294.500488,0.000000
71.930000,64.819252,-20.906048,-0.001587,0.003447,0.087555,288.330444,14.688252,0.875552,-20.906048,294.500488,0.000000
72.350006,65.583351,-20.906048,-0.001574,0.003458,0.087841,291.729309,14.861400,0.878414,-20.906048,294.500488,0.000000
72.770004,65.333870,-20.950527,-0.001569,0.003458,0.087841,290.619568,14.804866,0.878414,-20.950527,294.500488,0.000000
73.190002,65.098900,-20.817085,-0.001582,0.003458,0.087841,289.574371,14.751621,0.878414,-20.817085,294.500488,0.000000
73.610001,64.845314,-20.817085,-0.001574,0.003458,0.087841,288.446350,14.694159,0.878414,-20.817085,294.500488,0.000000
74.030006,64.625237,-20.906048,-0.001578,0.003458,0.087841,287.467407,14.644288,0.878414,-20.906048,294.500488,0.000000
74.450005,64.407784,-20.950527,-0.001561,0.003459,0.087850,286.500122,14.595013,0.878497,-20.950527,294.500488,0.000000
74.870003,66.255486,-21.039490,-0.001565,0.003467,0.088058,294.719116,15.013708,0.880579,-21.039490,294.500488,0.000000
75.290001,65.988503,-20.861567,-0.001552,0.003467,0.088058,293.531525,14.953208,0.880579,-20.861567,294.500488,0.000000
75.710007,65.756142,-20.906048,-0.001544,0.003467,0.088058,292.497925,14.900555,0.880579,-20.906048,294.500488,0.000000
76.130005,65.497719,-20.950527,-0.001561,0.003467,0.088058,291.348419,14.841995,0.880579,-20.950527,294.500488,0.000000
76.550003,65.272057,-21.039490,-0.001561,0.003468,0.088084,290.344604,14.790859,0.880843,-21.039490,294.500488,0.000000
76.970001,65.050117,-21.039490,-0.001552,0.003469,0.088102,289.357361,14.740567,0.881018,-21.039490,294.500488,0.000000
77.390007,64.922401,-20.995008,-0.001544,0.003475,0.088275,288.789276,14.711626,0.882751,-20.995008,294.500488,0.000000
77.810005,64.989799,-20.995008,-0.001548,0.003479,0.088361,289.089081,14.726899,0.883614,-20.995008,294.500488,0.000000
78.230003,64.851280,-20.995008,-0.001548,0.003479,0.088361,288.472900,14.695510,0.883614,-20.995008,294.500488,0.000000
78.650002,65.196098,-20.995008,-0.001548,0.003485,0.088518,290.006744,14.773647,0.885181,-20.995008,294.500488,0.000000
79.070007,65.073204,-21.039490,-0.001544,0.003485,0.088518,289.460083,14.745798,0.885181,-21.039490,294.500488,0.000000
79.490005,64.966331,-21.083971,-0.001526,0.003485,0.088518,288.984680,14.721581,0.885181,-21.083971,294.500488,0.000000
79.910004,64.840096,-21.039490,-0.001539,0.003485,0.088518,288.423157,14.692976,0.885181,-21.039490,294.500488,0.000000
80.330002,64.731377,-21.039490,-0.001539,0.003485,0.088526,287.939545,14.668340,0.885264,-21.039490,294.500488,0.000000
80.750008,65.677940,-21.128452,-0.001539,0.003497,0.088830,292.150055,14.882834,0.888300,-21.128452,294.500488,0.000000
81.170006,65.607933,-21.128452,-0.001539,0.003497,0.088830,291.838654,14.866970,0.888300,-21.128452,294.500488,0.000000
81.590004,65.548729,-21.083971,-0.001531,0.003497,0.088830,291.575317,14.853555,0.888300,-21.083971,294.500488,0.000000
82.010002,65.438499,-21.083971,-0.001531,0.003497,0.088830,291.084991,14.828575,0.888300,-21.083971,294.500488,0.000000
82.430000,65.304085,-21.083971,-0.001535,0.003497,0.088830,290.487091,14.798118,0.888300,-21.083971,294.500488,0.000000
82.850006,65.226631,-21.172934,-0.001544,0.003497,0.088830,290.142548,14.780566,0.888300,-21.172934,294.500488,0.000000
83.270004,65.099281,-21.217413,-0.001526,0.003498,0.088838,289.576080,14.751708,0.888383,-21.217413,294.500488,0.000000
83.690002,65.023689,-21.128452,-0.001535,0.003498,0.088838,289.239807,14.734578,0.888383,-21.128452,294.500488,0.000000
84.110001,64.902657,-21.083971,-0.001522,0.003498,0.088838,288.701447,14.707152,0.888383,-21.083971,294.500488,0.000000
84.530006,64.790947,-21.128452,-0.001539,0.003498,0.088838,288.204529,14.681838,0.888383,-21.128452,294.500488,0.000000
84.950005,65.563255,-21.217413,-0.001539,0.003507,0.089090,291.639923,14.856847,0.890904,-21.217413,294.500488,0.000000
85.370003,65.523781,-21.217413,-0.001526,0.003507,0.089090,291.464325,14.847900,0.890904,-21.217413,294.500488,0.000000
85.790001,65.467918,-21.172934,-0.001522,0.003507,0.089090,291.215851,14.835242,0.890904,-21.172934,294.500488,0.000000
86.210007,65.356590,-21.217413,-0.001526,0.003507,0.089090,290.720642,14.810016,0.890904,-21.217413,294.500488,0.000000
86.630005,65.289177,-21.217413,-0.001522,0.003507,0.089090,290.420776,14.794740,0.890904,-21.217413,294.500488,0.000000
87.050003,65.225502,-21.261894,-0.001526,0.003507,0.089090,290.137512,14.780310,0.890904,-21.261894,294.500488,0.000000
87.470001,65.102623,-21.306376,-0.001531,0.003507,0.089090,289.590942,14.752465,0.890904,-21.306376,294.500488,0.000000
87.890007,65.043419,-21.217413,-0.001518,0.003507,0.089090,289.327576,14.739050,0.890904,-21.217413,294.500488,0.000000
88.310005,64.977882,-21.261894,-0.001518,0.003507,0.089090,289.036041,14.724199,0.890904,-21.261894,294.500488,0.000000
88.730003,64.912712,-21.261894,-0.001518,0.003507,0.089090,288.746155,14.709432,0.890904,-21.261894,294.500488,0.000000
89.150002,64.809563,-21.306376,-0.001526,0.003507,0.089090,288.287323,14.686057,0.890904,-21.306376,294.500488,0.000000
89.570007,64.747749,-21.306376,-0.001531,0.003507,0.089090,288.012360,14.672050,0.890904,-21.306376,294.500488,0.000000
89.990005,64.669563,-21.395338,-0.001500,0.003507,0.089090,287.664581,14.654332,0.890904,-21.395338,294.500488,0.000000
90.410004,64.582054,-21.350857,-0.001518,0.003507,0.089090,287.275330,14.634502,0.890904,-21.350857,294.500488,0.000000
90.830002,64.515022,-21.306376,-0.001513,0.003507,0.089090,286.977142,14.619313,0.890904,-21.306376,294.500488,0.000000
91.250008,64.468849,-21.395338,-0.001518,0.003508,0.089099,286.771759,14.608850,0.890987,-21.395338,294.500488,0.000000
91.670006,64.383568,-21.395338,-0.001509,0.003508,0.089099,286.392426,14.589524,0.890987,-21.395338,294.500488,0.000000
92.090004,66.466621,-21.350857,-0.001509,0.003478,0.088344,295.658295,15.061552,0.883440,-21.350857,294.500488,0.000000
92.510002,66.386192,-21.439819,-0.001509,0.003478,0.088344,295.300537,15.043326,0.883440,-21.439819,294.500488,0.000000
92.930008,66.296074,-21.395338,-0.001509,0.003478,0.088344,294.899658,15.022905,0.883440,-21.395338,294.500488,0.000000
93.350006,66.211922,-21.395338,-0.001513,0.003478,0.088344,294.525330,15.003836,0.883440,-21.395338,294.500488,0.000000
93.770004,66.129631,-21.484299,-0.001513,0.003478,0.088344,294.159302,14.985188,0.883440,-21.484299,294.500488,0.000000
94.190002,66.054405,-21.439819,-0.001509,0.003478,0.088344,293.824677,14.968143,0.883440,-21.439819,294.500488,0.000000
94.610008,65.995567,-21.395338,-0.001505,0.003478,0.088344,293.562958,14.954809,0.883440,-21.395338,294.500488,0.000000
95.030006,65.918861,-21.395338,-0.001505,0.003478,0.088353,293.221741,14.937428,0.883531,-21.395338,294.500488,0.000000
95.450005,65.877159,-21.528780,-0.001513,0.003478,0.088353,293.036224,14.927978,0.883531,-21.528780,294.500488,0.000000
95.870003,65.803062,-21.528780,-0.001487,0.003479,0.088361,292.706635,14.911187,0.883614,-21.528780,294.500488,0.000000
96.290001,65.739388,-21.439819,-0.001505,0.003479,0.088361,292.423401,14.896758,0.883614,-21.439819,294.500488,0.000000
96.710007,65.600121,-21.484299,-0.001500,0.003479,0.088370,291.803925,14.865199,0.883705,-21.484299,294.500488,0.000000
97.130005,65.564369,-21.484299,-0.001505,0.003482,0.088440,291.644867,14.857099,0.884401,-21.484299,294.500488,0.000000
97.550003,65.517082,-21.573261,-0.001518,0.003483,0.088457,291.434540,14.846382,0.884568,-21.573261,294.500488,0.000000
97.970001,65.435524,-21.617743,-0.001513,0.003483,0.088466,291.071747,14.827902,0.884659,-21.617743,294.500488,0.000000
98.390007,65.378548,-21.573261,-0.001509,0.003488,0.088604,290.818298,14.814991,0.886044,-21.573261,294.500488,0.000000
98.810005,65.320839,-21.573261,-0.001496,0.003490,0.088657,290.561615,14.801914,0.886566,-21.573261,294.500488,0.000000
99.230003,65.294777,-21.573261,-0.001505,0.003493,0.088735,290.445679,14.796008,0.887346,-21.573261,294.500488,0.000000
99.650002,65.254555,-21.617743,-0.001518,0.003493,0.088735,290.266754,14.786894,0.887346,-21.617743,294.500488,0.000000
100.070007,65.194221,-21.617743,-0.001496,0.003493,0.088735,289.998383,14.773222,0.887346,-21.617743,294.500488,0.000000
100.490005,65.178596,-21.528780,-0.001496,0.003503,0.088986,289.928864,14.769681,0.889859,-21.528780,294.500488,0.000000
100.910004,65.112312,-21.617743,-0.001505,0.003503,0.088986,289.634033,14.754661,0.889859,-21.617743,294.500488,0.000000
101.330002,65.056084,-21.573261,-0.001500,0.003503,0.088986,289.383911,14.741920,0.889859,-21.573261,294.500488,0.000000
101.750008,65.019585,-21.662224,-0.001496,0.003503,0.088986,289.221558,14.733649,0.889859,-21.662224,294.500488,0.000000
102.170006,65.079536,-21.706703,-0.001500,0.003517,0.089342,289.488251,14.747233,0.893417,-21.706703,294.500488,0.000000
102.590004,65.028145,-21.706703,-0.001505,0.003517,0.089342,289.259644,14.735588,0.893417,-21.706703,294.500488,0.000000
103.010002,64.974525,-21.706703,-0.001492,0.003517,0.089342,289.021118,14.723438,0.893417,-21.706703,294.500488,0.000000
103.430008,65.279869,-21.662224,-0.001496,0.003526,0.089550,290.379364,14.792629,0.895499,-21.662224,294.500488,0.000000
103.850006,65.265724,-21.751184,-0.001496,0.003526,0.089550,290.316437,14.789425,0.895499,-21.751184,294.500488,0.000000
104.270004,65.240776,-21.751184,-0.001496,0.003526,0.089550,290.205475,14.783772,0.895499,-21.751184,294.500488,0.000000
104.690002,65.213585,-21.706703,-0.001500,0.003526,0.089550,290.084503,14.777609,0.895499,-21.706703,294.500488,0.000000
105.110008,65.174858,-21.751184,-0.001500,0.003526,0.089550,289.912262,14.768834,0.895499,-21.751184,294.500488,0.000000
105.530006,65.129814,-21.751184,-0.001505,0.003526,0.089567,289.711884,14.758627,0.895673,-21.751184,294.500488,0.000000
105.950005,65.108589,-21.795666,-0.001518,0.003526,0.089567,289.617462,14.753818,0.895673,-21.795666,294.500488,0.000000
106.370003,65.085503,-21.840147,-0.001487,0.003526,0.089567,289.514771,14.748586,0.895673,-21.840147,294.500488,0.000000
106.790009,65.049370,-21.751184,-0.001505,0.003527,0.089576,289.354034,14.740397,0.895756,-21.751184,294.500488,0.000000
107.210007,65.013252,-21.795666,-0.001492,0.003527,0.089576,289.193390,14.732214,0.895756,-21.795666,294.500488,0.000000
107.630005,65.081398,-21.795666,-0.001496,0.003534,0.089766,289.496521,14.747656,0.897664,-21.795666,294.500488,0.000000
108.050003,65.561394,-21.795666,-0.001509,0.003535,0.089784,291.631653,14.856424,0.897838,-21.795666,294.500488,0.000000
108.470009,65.551704,-21.795666,-0.001492,0.003535,0.089784,291.588531,14.854228,0.897838,-21.795666,294.500488,0.000000
108.890007,65.546120,-21.795666,-0.001496,0.003535,0.089784,291.563690,14.852962,0.897838,-21.795666,294.500488,0.000000
109.310005,65.508888,-21.795666,-0.001487,0.003535,0.089784,291.398102,14.844526,0.897838,-21.795666,294.500488,0.000000
109.730003,65.479836,-21.840147,-0.001505,0.003535,0.089784,291.268860,14.837942,0.897838,-21.840147,294.500488,0.000000
110.150002,65.462334,-21.884628,-0.001513,0.003535,0.089784,291.191010,14.833977,0.897838,-21.884628,294.500488,0.000000
110.570007,65.416908,-21.884628,-0.001487,0.003535,0.089784,290.988953,14.823683,0.897838,-21.884628,294.500488,0.000000
110.990005,65.384514,-21.973589,-0.001475,0.003535,0.089784,290.844849,14.816342,0.897838,-21.973589,294.500488,0.000000
111.410004,65.340202,-21.840147,-0.001492,0.003535,0.089784,290.647736,14.806301,0.897838,-21.840147,294.500488,0.000000
111.830002,65.317482,-21.884628,-0.001496,0.003535,0.089784,290.546661,14.801153,0.897838,-21.884628,294.500488,0.000000
112.250008,65.278389,-21.973589,-0.001496,0.003535,0.089784,290.372772,14.792295,0.897838,-21.973589,294.500488,0.000000
112.670006,65.266090,-21.973589,-0.001487,0.003535,0.089793,290.318085,14.789508,0.897928,-21.973589,294.500488,0.000000
113.090004,65.229973,-21.929110,-0.001487,0.003535,0.089793,290.157410,14.781323,0.897928,-21.929110,294.500488,0.000000
113.510002,65.190880,-21.929110,-0.001496,0.003535,0.089793,289.983521,14.772465,0.897928,-21.929110,294.500488,0.000000
113.930008,65.161827,-22.018070,-0.001496,0.003535,0.089801,289.854279,14.765881,0.898012,-22.018070,294.500488,0.000000
114.350006,65.137627,-21.973589,-0.001500,0.003535,0.089801,289.746643,14.760398,0.898012,-21.973589,294.500488,0.000000
114.770004,65.119377,-21.973589,-0.001496,0.003537,0.089844,289.665466,14.756262,0.898443,-21.973589,294.500488,0.000000
115.190002,65.143593,-21.973589,-0.001475,0.003537,0.089844,289.773163,14.761749,0.898443,-21.973589,294.500488,0.000000
115.610008,65.140984,-21.929110,-0.001492,0.003537,0.089844,289.761566,14.761158,0.898443,-21.929110,294.500488,0.000000
116.030006,65.174492,-22.018070,-0.001487,0.003539,0.089897,289.910614,14.768751,0.898966,-22.018070,294.500488,0.000000
116.450005,65.207634,-22.062551,-0.001505,0.003539,0.089897,290.058044,14.776261,0.898966,-22.062551,294.500488,0.000000
116.870003,65.208748,-22.107033,-0.001487,0.003539,0.089897,290.062988,14.776513,0.898966,-22.107033,294.500488,0.000000
117.290009,65.183800,-22.062551,-0.001487,0.003539,0.089897,289.952026,14.770861,0.898966,-22.062551,294.500488,0.000000
117.710007,65.163322,-22.018070,-0.001492,0.003539,0.089897,289.860931,14.766220,0.898966,-22.018070,294.500488,0.000000
118.130005,65.133904,-22.062551,-0.001492,0.003539,0.089897,289.730072,14.759553,0.898966,-22.062551,294.500488,0.000000
118.550003,65.126457,-22.151514,-0.001492,0.003539,0.089897,289.696960,14.757866,0.898966,-22.151514,294.500488,0.000000
118.970009,65.092567,-22.107033,-0.001487,0.003539,0.089897,289.546204,14.750187,0.898966,-22.107033,294.500488,0.000000
119.390007,65.084373,-22.107033,-0.001487,0.003540,0.089906,289.509766,14.748329,0.899056,-22.107033,294.500488,0.000000
119.810005,65.053474,-22.107033,-0.001492,0.003540,0.089923,289.372314,14.741328,0.899230,-22.107033,294.500488,0.000000
120.230003,65.056816,-22.107033,-0.001487,0.003541,0.089931,289.387177,14.742085,0.899314,-22.107033,294.500488,0.000000
120.650009,65.050499,-22.151514,-0.001487,0.003541,0.089931,289.359070,14.740654,0.899314,-22.151514,294.500488,0.000000
121.070007,65.039330,-22.107033,-0.001492,0.003541,0.089931,289.309387,14.738123,0.899314,-22.107033,294.500488,0.000000
121.490005,65.014748,-22.195995,-0.001466,0.003541,0.089949,289.200043,14.732553,0.899488,-22.195995,294.500488,0.000000
121.910004,65.054955,-22.195995,-0.001483,0.003543,0.089992,289.378876,14.741663,0.899919,-22.195995,294.500488,0.000000
122.330009,65.068367,-22.107033,-0.001483,0.003543,0.089992,289.438538,14.744702,0.899919,-22.107033,294.500488,0.000000
122.750008,65.072838,-22.240475,-0.001487,0.003543,0.089992,289.458435,14.745716,0.899919,-22.240475,294.500488,0.000000
123.170006,65.053841,-22.240475,-0.001483,0.003543,0.089992,289.373932,14.741411,0.899919,-22.240475,294.500488,0.000000
123.590004,65.035225,-22.240475,-0.001483,0.003543,0.089992,289.291138,14.737193,0.899919,-22.240475,294.500488,0.000000
124.010002,65.040062,-22.240475,-0.001479,0.003543,0.089992,289.312653,14.738289,0.899919,-22.240475,294.500488,0.000000
124.430008,65.017357,-22.240475,-0.001483,0.003543,0.089992,289.211639,14.733144,0.899919,-22.240475,294.500488,0.000000
124.850006,65.012138,-22.284956,-0.001487,0.003543,0.089992,289.188446,14.731961,0.899919,-22.284956,294.500488,0.000000
125.270004,65.006187,-22.240475,-0.001483,0.003544,0.090009,289.161957,14.730613,0.900093,-22.240475,294.500488,0.000000
125.690002,64.997246,-22.240475,-0.001483,0.003544,0.090009,289.122192,14.728586,0.900093,-22.240475,294.500488,0.000000
126.110008,64.944374,-22.284956,-0.001496,0.003534,0.089775,288.886993,14.716606,0.897754,-22.284956,0.089957,0.000000
126.530006,64.844566,-22.284956,-0.001483,0.003524,0.089498,288.443024,14.693989,0.894976,-22.284956,0.089255,0.000000
126.950005,64.805840,-22.373919,-0.001496,0.003503,0.088968,288.270782,14.685213,0.889685,-22.373919,0.088561,0.000000
127.370003,64.688545,-22.329437,-0.001479,0.003477,0.088318,287.749023,14.658634,0.883183,-22.329437,0.087859,0.000000
127.790009,64.688927,-22.373919,-0.001479,0.003448,0.087590,287.750732,14.658720,0.875900,-22.373919,0.087156,0.000000
128.210007,64.641624,-22.284956,-0.001487,0.003424,0.086966,287.540314,14.648002,0.869655,-22.284956,0.086462,0.000000
128.630005,64.631950,-22.373919,-0.001483,0.003400,0.086350,287.497284,14.645810,0.863501,-22.373919,0.085760,0.000000
129.050003,64.548912,-22.418400,-0.001492,0.003370,0.085586,287.127899,14.626993,0.855863,-22.418400,0.085058,0.000000
129.470001,64.517998,-22.373919,-0.001470,0.003343,0.084919,286.990387,14.619987,0.849187,-22.373919,0.084355,0.000000
129.889999,64.387291,-22.373919,-0.001466,0.003316,0.084216,286.408966,14.590369,0.842162,-22.373919,0.083661,0.000000
130.310013,63.923317,-22.418400,-0.001487,0.003292,0.083626,284.345123,14.485230,0.836265,-22.418400,0.082959,0.000000
130.730011,63.018456,-22.418400,-0.001462,0.003270,0.083054,280.320099,14.280186,0.830542,-22.418400,0.082256,0.000000
131.150009,61.599342,-22.373919,-0.001444,0.003239,0.082282,274.007568,13.958611,0.822821,-22.373919,0.081563,0.000000
131.570007,60.112091,-22.462881,-0.001444,0.003218,0.081727,267.391937,13.621595,0.817272,-22.462881,0.080860,0.000000
131.990005,58.109840,-22.418400,-0.001427,0.003188,0.080973,258.485474,13.167878,0.809733,-22.418400,0.080158,0.000000
132.410004,56.334740,-22.462881,-0.001436,0.003166,0.080409,250.589432,12.765635,0.804093,-22.462881,0.079456,0.000000
132.830002,54.160461,-22.507360,-0.001449,0.003142,0.079802,240.917770,12.272936,0.798022,-22.507360,0.078761,0.000000
133.250000,51.997719,-22.418400,-0.001444,0.003113,0.079065,231.297409,11.782851,0.790649,-22.418400,0.078059,0.000000
133.670013,48.799789,-22.462881,-0.001440,0.003087,0.078406,217.072311,11.058191,0.784056,-22.462881,0.077356,0.000000
134.090012,45.337837,-22.462881,-0.001444,0.003053,0.077556,201.672775,10.273701,0.775563,-22.462881,0.076654,0.000000
134.510010,42.673141,-22.507360,-0.001449,0.003029,0.076949,189.819611,9.669872,0.769492,-22.507360,0.075961,0.000000
134.930008,40.695473,-22.596323,-0.001436,0.003014,0.076559,181.022507,9.221726,0.765586,-22.596323,0.075258,0.000000
135.350006,36.816841,-22.507360,-0.001436,0.002975,0.075562,163.769485,8.342816,0.755616,-22.507360,0.074556,0.000000
135.770004,34.208374,-22.596323,-0.001431,0.002951,0.074955,152.166443,7.751728,0.749545,-22.596323,0.073861,0.000000
136.190002,31.077095,-22.596323,-0.001436,0.002922,0.074217,138.237823,7.042171,0.742172,-22.596323,0.073159,0.000000
136.610001,28.042625,-22.507360,-0.001431,0.002897,0.073584,124.739830,6.354550,0.735844,-22.507360,0.072457,0.000000
137.030014,25.008163,-22.596323,-0.001444,0.002867,0.072830,111.241867,5.666931,0.728297,-22.596323,0.071754,0.000000
137.450012,22.544174,-22.640804,-0.001436,0.002844,0.072231,100.281494,5.108583,0.722309,-22.640804,0.071061,0.000000
137.870010,19.666107,-22.596323,-0.001431,0.002815,0.071494,87.479218,4.456403,0.714944,-22.596323,0.070358,0.000000
138.290009,16.325554,-22.551842,-0.001431,0.002786,0.070775,72.619690,3.699423,0.707745,-22.551842,0.069656,0.000000
138.710007,13.876465,-22.640804,-0.001431,0.002759,0.070089,61.725597,3.144452,0.700894,-22.640804,0.068962,0.000000
139.130005,10.411537,-22.640804,-0.001427,0.002732,0.069395,46.312832,2.359288,0.693953,-22.640804,0.068259,0.000000
139.550003,7.784447,-22.685286,-0.001431,0.002708,0.068771,34.626949,1.763981,0.687708,-22.685286,0.067557,0.000000
139.970001,4.192917,-22.685286,-0.001440,0.002673,0.067887,18.651026,0.950129,0.678866,-22.685286,0.066855,0.000000
140.389999,1.945274,-22.596323,-0.001427,0.002649,0.067288,8.653012,0.440805,0.672879,-22.596323,0.066161,0.000000
140.810013,-0.905609,-22.685286,-0.001440,0.002623,0.066612,-4.028351,-0.205214,0.666119,-22.685286,0.065458,0.000000
141.230011,-0.586487,-22.729767,-0.001453,0.002592,0.065831,-2.608824,-0.132900,0.658314,-22.729767,0.064756,0.000000
141.650009,-0.192886,-22.729767,-0.001427,0.002570,0.065267,-0.858001,-0.043709,0.652675,-22.729767,0.064053,0.000000
142.070007,-0.147827,-22.685286,-0.001427,0.002535,0.064400,-0.657568,-0.033498,0.644000,-22.685286,0.063360,0.000000
142.490005,-0.120270,-22.685286,-0.001440,0.002510,0.063759,-0.534987,-0.027254,0.637588,-22.685286,0.062657,0.000000
142.910004,-0.153412,-22.729767,-0.001440,0.002478,0.062944,-0.682410,-0.034764,0.629436,-22.729767,0.061955,0.000000
143.330002,-0.137032,-22.774246,-0.001423,0.002460,0.062475,-0.609547,-0.031052,0.624750,-22.774246,0.061261,0.000000
143.750000,-0.153786,-22.774246,-0.001440,0.002430,0.061720,-0.684073,-0.034848,0.617203,-22.774246,0.060558,0.000000
144.170013,-0.135910,-22.685286,-0.001418,0.002398,0.060905,-0.604558,-0.030798,0.609050,-22.685286,0.059856,0.000000
144.590012,-0.148201,-22.729767,-0.001444,0.002377,0.060368,-0.659231,-0.033583,0.603676,-22.729767,0.059153,0.000000
145.010010,-0.134048,-22.774246,-0.001453,0.002345,0.059552,-0.596277,-0.030376,0.595523,-22.774246,0.058460,0.000000
145.430008,-0.182457,-22.863209,-0.001444,0.002322,0.058980,-0.811609,-0.041345,0.589800,-22.863209,0.057757,0.000000
145.850006,-0.205177,-22.818727,-0.001453,0.002285,0.058044,-0.912674,-0.046494,0.580436,-22.818727,0.057055,0.000000
146.270004,-0.207405,-22.818727,-0.001440,0.002259,0.057367,-0.922584,-0.046999,0.573669,-22.818727,0.056361,0.000000
146.690002,-0.191025,-22.818727,-0.001462,0.002234,0.056742,-0.849721,-0.043287,0.567424,-22.818727,0.055658,0.000000
147.110001,-0.190651,-22.774246,-0.001479,0.002208,0.056075,-0.848058,-0.043202,0.560747,-22.774246,0.054956,0.000000
147.530014,-0.217087,-22.863209,-0.001522,0.002174,0.055208,-0.965650,-0.049193,0.552080,-22.863209,0.054253,0.000000
147.950012,-0.229752,-22.907690,-0.001552,0.002149,0.054574,-1.021986,-0.052062,0.545744,-22.907690,0.053560,0.000000
148.370010,-0.230499,-22.907690,-0.001569,0.002121,0.053864,-1.025312,-0.052232,0.538636,-22.907690,0.052858,0.000000
148.790009,-0.220070,-22.907690,-0.001595,0.002091,0.053109,-0.978920,-0.049869,0.531089,-22.907690,0.052155,0.000000
149.210007,-0.208527,-22.863209,-0.001625,0.002065,0.052441,-0.927573,-0.047253,0.524412,-22.863209,0.051453,0.000000
149.630005,-0.206291,-22.907690,-0.001686,0.002032,0.051600,-0.917629,-0.046746,0.516002,-22.907690,0.050758,0.000000
150.050003,-0.237198,-22.952171,-0.001681,0.002011,0.051079,-1.055109,-0.053750,0.510794,-22.952171,0.050056,0.000000
150.470001,-0.215599,-22.996653,-0.001716,0.001983,0.050377,-0.959033,-0.048855,0.503770,-22.996653,0.049354,0.000000
150.890015,-0.199585,-22.952171,-0.001738,0.001952,0.049579,-0.887798,-0.045227,0.495791,-22.952171,0.048660,0.000000
151.310013,-0.217461,-22.996653,-0.001781,0.001924,0.048868,-0.967313,-0.049277,0.488683,-22.996653,0.047958,0.000000
151.730011,-0.227142,-22.952171,-0.001802,0.001897,0.048192,-1.010380,-0.051471,0.481916,-22.952171,0.047255,0.000000
152.150009,-0.246132,-22.996653,-0.001832,0.001870,0.047506,-1.094849,-0.055774,0.475065,-22.996653,0.046553,0.000000
152.570007,-0.236824,-22.952171,-0.001854,0.001841,0.046753,-1.053446,-0.053665,0.467525,-22.952171,0.045859,0.000000
152.990005,-0.249863,-22.996653,-0.001888,0.001819,0.046206,-1.111445,-0.056620,0.462060,-22.996653,0.045157,0.000000
153.410004,-0.226028,-22.996653,-0.001914,0.001786,0.045356,-1.005425,-0.051219,0.453559,-22.996653,0.044454,0.000000
153.830002,-0.258423,-23.041132,-0.001936,0.001764,0.044801,-1.149522,-0.058559,0.448010,-23.041132,0.043760,0.000000
154.250000,-0.246132,-23.085613,-0.001966,0.001733,0.044029,-1.094849,-0.055774,0.440289,-23.085613,0.043058,0.000000
154.670013,-0.231987,-23.041132,-0.001988,0.001701,0.043214,-1.031930,-0.052569,0.432137,-23.041132,0.042355,0.000000
155.090012,-0.241669,-23.041132,-0.002018,0.001676,0.042581,-1.074996,-0.054763,0.425808,-23.041132,0.041653,0.000000
155.510010,-0.246506,-23.085613,-0.002052,0.001647,0.041844,-1.096512,-0.055859,0.418435,-23.085613,0.040959,0.000000
155.930008,-0.245018,-23.085613,-0.002074,0.001628,0.041349,-1.089895,-0.055522,0.413492,-23.085613,0.040257,0.000000
156.350006,-0.234589,-23.174576,-0.002104,0.001601,0.040656,-1.043502,-0.053159,0.406558,-23.174576,0.039554,0.000000
156.770004,-0.235710,-23.130095,-0.002143,0.001572,0.039936,-1.048491,-0.053413,0.399359,-23.130095,0.038852,0.000000
157.190002,-0.239433,-23.085613,-0.002151,0.001545,0.039242,-1.065053,-0.054256,0.392418,-23.085613,0.038158,0.000000
157.610001,-0.240547,-23.085613,-0.002199,0.001512,0.038401,-1.070007,-0.054509,0.384008,-23.085613,0.037455,0.000000
158.030014,-0.211502,-23.130095,-0.002220,0.001492,0.037906,-0.940808,-0.047927,0.379065,-23.130095,0.036753,0.000000
158.450012,-0.240181,-23.174576,-0.002238,0.001460,0.037091,-1.068378,-0.054426,0.370912,-23.174576,0.036059,0.000000
158.870010,-0.236450,-23.174576,-0.002264,0.001438,0.036527,-1.051783,-0.053580,0.365273,-23.174576,0.035357,0.000000
159.290009,-0.239059,-23.174576,-0.002320,0.001406,0.035704,-1.063390,-0.054172,0.357037,-23.174576,0.034654,0.000000
159.710007,-0.235710,-23.130095,-0.002324,0.001382,0.035097,-1.048491,-0.053413,0.350966,-23.130095,0.033952,0.000000
160.130005,-0.227142,-23.219057,-0.002367,0.001358,0.034481,-1.010380,-0.051471,0.344811,-23.219057,0.033258,0.000000
160.550003,-0.260658,-23.219057,-0.002393,0.001320,0.033518,-1.159466,-0.059066,0.335183,-23.219057,0.032555,0.000000
160.970001,-0.249489,-23.219057,-0.002393,0.001308,0.033215,-1.109782,-0.056535,0.332147,-23.219057,0.031853,0.000000
161.390015,-0.242783,-23.219057,-0.002440,0.001265,0.032122,-1.079951,-0.055015,0.321224,-23.219057,0.031160,0.000000
161.810013,-0.198471,-23.174576,-0.002466,0.001245,0.031628,-0.882843,-0.044974,0.316281,-23.174576,0.030457,0.000000
162.230011,-0.219696,-23.308018,-0.002514,0.001208,0.030674,-0.977257,-0.049784,0.306735,-23.308018,0.029755,0.000000
162.650009,-0.238686,-23.263536,-0.002535,0.001192,0.030275,-1.061727,-0.054087,0.302746,-23.263536,0.029052,0.000000
163.070007,-0.222679,-23.219057,-0.002548,0.001164,0.029555,-0.990526,-0.050460,0.295555,-23.219057,0.028359,0.000000
163.490005,-0.216347,-23.219057,-0.002583,0.001129,0.028671,-0.962358,-0.049025,0.286706,-23.219057,0.027656,0.000000
163.910004,-0.193634,-23.263536,-0.002596,0.001101,0.027976,-0.861327,-0.043878,0.279764,-23.263536,0.026954,0.000000
164.330002,-0.188416,-23.308018,-0.002665,0.001074,0.027274,-0.838114,-0.042696,0.272740,-23.308018,0.026251,0.000000
164.750015,-0.190651,-23.352499,-0.002673,0.001050,0.026659,-0.848058,-0.043202,0.266585,-23.352499,0.025557,0.000000
165.170013,-0.201080,-23.352499,-0.002699,0.001014,0.025748,-0.894450,-0.045565,0.257479,-23.352499,0.024855,0.000000
165.590012,-0.173523,-23.308018,-0.002721,0.000994,0.025245,-0.771869,-0.039321,0.252452,-23.308018,0.024152,0.000000
166.010010,-0.181717,-23.352499,-0.002759,0.000967,0.024551,-0.808317,-0.041178,0.245511,-23.352499,0.023459,0.000000
166.430008,-0.164589,-23.396980,-0.002798,0.000932,0.023667,-0.732128,-0.037296,0.236669,-23.396980,0.022756,0.000000
166.850006,-0.185066,-23.396980,-0.002815,0.000909,0.023077,-0.823216,-0.041937,0.230773,-23.396980,0.022054,0.000000
167.270004,-0.221931,-23.396980,-0.002846,0.000880,0.022340,-0.987200,-0.050290,0.223400,-23.396980,0.021351,0.000000
167.690002,-0.205177,-23.352499,-0.002876,0.000859,0.021828,-0.912674,-0.046494,0.218282,-23.352499,0.020657,0.000000
168.110001,-0.219322,-23.396980,-0.002902,0.000828,0.021030,-0.975594,-0.049699,0.210304,-23.396980,0.019955,0.000000
168.530014,-0.222305,-23.396980,-0.002923,0.000798,0.020267,-0.988863,-0.050375,0.202674,-23.396980,0.019252,0.000000
168.950012,-0.199959,-23.485943,-0.002966,0.000766,0.019452,-0.889461,-0.045311,0.194521,-23.485943,0.018550,0.000000
169.370010,-0.242783,-23.396980,-0.002975,0.000745,0.018931,-1.079951,-0.055015,0.189313,-23.396980,0.017856,0.000000
169.790009,-0.224167,-23.396980,-0.003022,0.000714,0.018133,-0.997144,-0.050797,0.181334,-23.396980,0.017154,0.000000
170.210007,-0.215599,-23.441462,-0.003048,0.000684,0.017379,-0.959033,-0.048855,0.173795,-23.441462,0.016451,0.000000
170.630005,-0.238686,-23.485943,-0.003087,0.000663,0.016841,-1.061727,-0.054087,0.168413,-23.485943,0.015757,0.000000
171.050003,-0.205917,-23.530422,-0.003122,0.000628,0.015948,-0.915966,-0.046662,0.159480,-23.530422,0.015055,0.000000
171.470001,-0.233849,-23.485943,-0.003130,0.000606,0.015402,-1.040210,-0.052991,0.154023,-23.485943,0.014352,0.000000
171.890015,-0.220444,-23.485943,-0.003156,0.000575,0.014604,-0.980583,-0.049953,0.146044,-23.485943,0.013650,0.000000
172.310013,-0.210388,-23.530422,-0.003203,0.000546,0.013875,-0.935853,-0.047675,0.138754,-23.530422,0.012956,0.000000
172.730011,-0.221931,-23.530422,-0.003216,0.000518,0.013165,-0.987200,-0.050290,0.131646,-23.530422,0.012254,0.000000
173.150009,-0.250977,-23.530422,-0.003251,0.000494,0.012549,-1.116400,-0.056872,0.125492,-23.530422,0.011551,0.000000
173.570007,-0.258049,-23.530422,-0.003272,0.000465,0.011820,-1.147859,-0.058475,0.118202,-23.530422,0.010858,0.000000
173.990005,-0.202568,-23.530422,-0.003402,0.000434,0.011031,-0.901068,-0.045903,0.110315,-23.530422,0.010156,0.000000
174.410004,-0.239807,-23.574903,-0.003406,0.000410,0.010407,-1.066715,-0.054341,0.104069,-23.574903,0.009453,0.000000
174.830002,-0.240921,-23.574903,-0.003397,0.000381,0.009678,-1.071670,-0.054593,0.096780,-23.574903,0.008751,0.000000
175.250015,-0.265129,-23.574903,-0.003419,0.000357,0.009080,-1.179353,-0.060079,0.090800,-23.574903,0.008057,0.000000
175.500015,-0.205544,-23.619385,-0.003419,0.000349,0.008872,-0.914303,-0.046577,0.088718,-23.619385,0.008776,0.000000