File: Data/compression 26/AutoNoHeating-17-26-reverse-1-1_09262024_172655.csv
Time (sec),S:Load (lbs),S:HL1 (DIM),S:LVDT (in),S:Position (in),Ch:Position (mm),Ch:Load (N),Ch:Stress (MPa),Ch:Strain (mm/mm),Ch:HL1 (DIM),Set Point (),Cycles ()
0.110000,0.038727,-12.721552,-0.007205,-0.007140,-0.181363,0.172265,0.008776,-1.813631,-12.721552,-0.181112,0.000000
0.510000,-0.042450,-12.721552,-0.007174,-0.007042,-0.178874,-0.188827,-0.009619,-1.788741,-12.721552,-0.178041,0.000000
0.910000,-0.001862,-12.721552,-0.007062,-0.006808,-0.172917,-0.008281,-0.000422,-1.729167,-12.721552,-0.171382,0.000000
1.310000,-0.036865,-12.766033,-0.006795,-0.006536,-0.166022,-0.163985,-0.008354,-1.660221,-12.766033,-0.164721,0.000000
1.710000,-0.071495,-12.810513,-0.006519,-0.006275,-0.159379,-0.318026,-0.016201,-1.593789,-12.810513,-0.158044,0.000000
2.110000,-0.109100,-12.810513,-0.006222,-0.006014,-0.152762,-0.485303,-0.024722,-1.527622,-12.810513,-0.151383,0.000000
2.510000,-0.042076,-12.766033,-0.005950,-0.005748,-0.145998,-0.187164,-0.009535,-1.459978,-12.766033,-0.144723,0.000000
2.910000,-0.037979,-12.810513,-0.005683,-0.005488,-0.139389,-0.168940,-0.008606,-1.393894,-12.810513,-0.138062,0.000000
3.310000,-0.036118,-12.854995,-0.005407,-0.005230,-0.132851,-0.160659,-0.008184,-1.328506,-12.854995,-0.131402,0.000000
3.710000,-0.025688,-12.810513,-0.005148,-0.004965,-0.126112,-0.114267,-0.005821,-1.261119,-12.810513,-0.124724,0.000000
4.110000,-0.010048,-12.810513,-0.004881,-0.004700,-0.119374,-0.044695,-0.002277,-1.193741,-12.810513,-0.118065,0.000000
4.510000,0.160866,-12.899476,-0.004687,-0.000004,-0.000104,0.715567,0.036453,-0.001045,-12.899476,0.000051,0.000000
4.910000,0.149696,-12.810513,-0.004669,-0.000004,-0.000113,0.665883,0.033922,-0.001128,-12.810513,0.000051,0.000000
5.310000,0.144112,-12.854995,-0.004665,-0.000004,-0.000113,0.641041,0.032656,-0.001128,-12.854995,0.000693,0.000000
5.710000,0.147087,-12.899476,-0.004661,-0.000004,-0.000104,0.654276,0.033330,-0.001045,-12.899476,0.001361,0.000000
6.110000,0.209648,-12.943956,-0.004665,0.000029,0.000746,0.932561,0.047507,0.007456,-12.943956,0.002029,0.000000
6.510000,0.453552,-12.899476,-0.004631,0.000060,0.001526,2.017501,0.102776,0.015261,-12.899476,0.002688,0.000000
6.910000,0.637878,-12.988438,-0.004592,0.000091,0.002307,2.837425,0.144545,0.023065,-12.988438,0.003356,0.000000
7.310000,0.829651,-12.899476,-0.004587,0.000113,0.002861,3.690471,0.188002,0.028614,-12.899476,0.004023,0.000000
7.710001,1.105576,-12.943956,-0.004553,0.000144,0.003651,4.917846,0.250527,0.036509,-12.943956,0.004692,0.000000
8.110001,1.504013,-12.943956,-0.004531,0.000170,0.004319,6.690184,0.340814,0.043186,-12.943956,0.005359,0.000000
8.510000,1.815315,-13.032919,-0.004514,0.000192,0.004873,8.074925,0.411356,0.048734,-13.032919,0.006027,0.000000
8.910001,2.246155,-13.032919,-0.004475,0.000219,0.005550,9.991396,0.508986,0.055502,-13.032919,0.006695,0.000000
9.310000,2.803596,-12.988438,-0.004467,0.000244,0.006200,12.471020,0.635304,0.062004,-12.988438,0.007362,0.000000
9.710000,3.243736,-12.988438,-0.004449,0.000270,0.006851,14.428860,0.735041,0.068507,-12.988438,0.008022,0.000000
10.110001,3.606804,-13.032919,-0.004415,0.000292,0.007406,16.043865,0.817313,0.074055,-13.032919,0.008689,0.000000
10.510000,4.093864,-12.988438,-0.004406,0.000318,0.008074,18.210419,0.927683,0.080739,-12.988438,0.009357,0.000000
10.910001,4.773071,-13.032919,-0.004368,0.000350,0.008898,21.231682,1.081593,0.088975,-13.032919,0.010025,0.000000
11.310000,5.404991,-13.032919,-0.004342,0.000381,0.009686,24.042601,1.224789,0.096863,-13.032919,0.010692,0.000000
11.710001,5.832848,-13.077399,-0.004312,0.000407,0.010328,25.945803,1.321742,0.103282,-13.077399,0.011361,0.000000
12.110001,6.235756,-12.988438,-0.004286,0.000431,0.010944,27.738028,1.413043,0.109444,-12.988438,0.012028,0.000000
12.510000,6.690048,-13.121881,-0.004281,0.000456,0.011595,29.758821,1.515987,0.115946,-13.121881,0.012696,0.000000
12.910001,7.090347,-13.077399,-0.004238,0.000483,0.012262,31.539440,1.606696,0.122623,-13.077399,0.013355,0.000000
13.310000,7.376328,-13.077399,-0.004247,0.000506,0.012844,32.811543,1.671500,0.128437,-13.077399,0.014023,0.000000
13.710001,7.731575,-13.121881,-0.004212,0.000531,0.013476,34.391762,1.752000,0.134765,-13.121881,0.014691,0.000000
14.110001,8.270767,-13.077399,-0.004174,0.000557,0.014152,36.790211,1.874183,0.141525,-13.077399,0.015358,0.000000
14.510000,8.700111,-13.166362,-0.004156,0.000584,0.014829,38.700027,1.971473,0.148292,-13.166362,0.016026,0.000000
14.910001,8.946251,-13.166362,-0.004109,0.000610,0.015489,39.794910,2.027250,0.154885,-13.166362,0.016694,0.000000
15.310000,9.246010,-13.166362,-0.004113,0.000637,0.016182,41.128307,2.095176,0.161819,-13.166362,0.017361,0.000000
15.710001,9.582634,-13.210842,-0.004079,0.000664,0.016876,42.625687,2.171456,0.168761,-13.210842,0.018029,0.000000
16.110001,9.956497,-13.166362,-0.004049,0.000690,0.017535,44.288712,2.256175,0.175347,-13.166362,0.018697,0.000000
16.510000,9.945702,-13.166362,-0.004023,0.000718,0.018237,44.240692,2.253728,0.182371,-13.166362,0.019356,0.000000
16.910002,10.217903,-13.210842,-0.004005,0.000736,0.018706,45.451504,2.315410,0.187057,-13.210842,0.020024,0.000000
17.310001,10.798058,-13.166362,-0.003967,0.000772,0.019616,48.032158,2.446875,0.196164,-13.166362,0.020692,0.000000
17.710001,10.798058,-13.210842,-0.003932,0.000792,0.020128,48.032158,2.446875,0.201281,-13.210842,0.021360,0.000000
18.110001,11.224052,-13.210842,-0.003915,0.000820,0.020839,49.927078,2.543407,0.208389,-13.210842,0.022027,0.000000
18.510000,11.475029,-13.255323,-0.003880,0.000846,0.021498,51.043480,2.600279,0.214982,-13.255323,0.022695,0.000000
18.910002,11.651161,-13.255323,-0.003863,0.000872,0.022140,51.826954,2.640191,0.221401,-13.255323,0.023363,0.000000
19.310001,11.955017,-13.255323,-0.003837,0.000903,0.022929,53.178574,2.709045,0.229289,-13.255323,0.024030,0.000000
19.710001,12.019814,-13.255323,-0.003816,0.000922,0.023415,53.466801,2.723729,0.234149,-13.255323,0.024690,0.000000
20.110001,12.239517,-13.299805,-0.003790,0.000945,0.023996,54.444092,2.773514,0.239962,-13.299805,0.025357,0.000000
20.510000,12.799561,-13.255323,-0.003773,0.000979,0.024872,56.935287,2.900422,0.248721,-13.255323,0.026025,0.000000
20.910002,12.963402,-13.344285,-0.003721,0.001006,0.025557,57.664093,2.937549,0.255571,-13.344285,0.026693,0.000000
21.310001,13.308594,-13.344285,-0.003738,0.001035,0.026294,59.199581,3.015770,0.262937,-13.344285,0.027361,0.000000
21.710001,13.307854,-13.255323,-0.003699,0.001055,0.026788,59.196289,3.015603,0.267880,-13.255323,0.028029,0.000000
22.110001,13.888382,-13.388766,-0.003691,0.001090,0.027681,61.778610,3.147152,0.276812,-13.388766,0.028696,0.000000
22.510000,13.953918,-13.344285,-0.003648,0.001116,0.028341,62.070129,3.162003,0.283405,-13.344285,0.029364,0.000000
22.910002,14.159096,-13.388766,-0.003622,0.001139,0.028930,62.982803,3.208497,0.289302,-13.388766,0.030023,0.000000
23.310001,14.290169,-13.388766,-0.003591,0.001165,0.029580,63.565845,3.238199,0.295805,-13.388766,0.030691,0.000000
23.710001,14.477844,-13.388766,-0.003596,0.001190,0.030214,64.400665,3.280726,0.302141,-13.388766,0.031359,0.000000
24.110001,14.837181,-13.388766,-0.003570,0.001220,0.030977,65.999077,3.362153,0.309771,-13.388766,0.032026,0.000000
24.510000,15.005127,-13.388766,-0.003553,0.001247,0.031662,66.746140,3.400210,0.316622,-13.388766,0.032694,0.000000
24.910002,15.082947,-13.344285,-0.003518,0.001268,0.032200,67.092300,3.417845,0.321996,-13.344285,0.033362,0.000000
25.310001,15.108269,-13.433248,-0.003510,0.001293,0.032850,67.204933,3.423583,0.328499,-13.433248,0.034030,0.000000
25.710001,15.317917,-13.433248,-0.003492,0.001319,0.033492,68.137497,3.471090,0.334918,-13.433248,0.034698,0.000000
26.110001,15.659386,-13.477728,-0.003462,0.001345,0.034169,69.656425,3.548468,0.341685,-13.477728,0.035356,0.000000
26.510002,15.959885,-13.477728,-0.003458,0.001376,0.034949,70.993111,3.616561,0.349490,-13.477728,0.036025,0.000000
26.910002,16.143837,-13.477728,-0.003436,0.001405,0.035695,71.811371,3.658246,0.356946,-13.477728,0.036692,0.000000
27.310001,15.777794,-13.477728,-0.003406,0.001422,0.036111,70.183136,3.575299,0.361109,-13.477728,0.037360,0.000000
27.710001,16.125961,-13.433248,-0.003397,0.001449,0.036813,71.731857,3.654195,0.368134,-13.433248,0.038028,0.000000
28.110001,16.804428,-13.522209,-0.003367,0.001482,0.037654,74.749832,3.807938,0.376544,-13.522209,0.038695,0.000000
28.510002,16.947418,-13.477728,-0.003337,0.001511,0.038374,75.385880,3.840340,0.383743,-13.477728,0.039363,0.000000
28.910002,16.843155,-13.522209,-0.003341,0.001533,0.038929,74.922096,3.816713,0.389292,-13.522209,0.040031,0.000000
29.310001,16.849854,-13.566690,-0.003324,0.001556,0.039511,74.951889,3.818231,0.395105,-13.566690,0.040699,0.000000
29.710001,17.280693,-13.522209,-0.003294,0.001587,0.040300,76.868362,3.915861,0.403000,-13.522209,0.041358,0.000000
30.110001,17.459061,-13.611171,-0.003272,0.001613,0.040959,77.661781,3.956280,0.409586,-13.611171,0.042025,0.000000
30.510002,17.319794,-13.611171,-0.003242,0.001633,0.041470,77.042290,3.924721,0.414703,-13.611171,0.042694,0.000000
30.910002,17.498154,-13.522209,-0.003238,0.001659,0.042138,77.835678,3.965138,0.421380,-13.522209,0.043361,0.000000
31.310001,17.700729,-13.655652,-0.003229,0.001682,0.042728,78.736778,4.011043,0.427277,-13.655652,0.044029,0.000000
31.710001,17.785629,-13.611171,-0.003203,0.001705,0.043309,79.114433,4.030281,0.433090,-13.611171,0.044697,0.000000
32.110001,18.642830,-13.655652,-0.003173,0.001744,0.044298,82.927452,4.224526,0.442977,-13.655652,0.045364,0.000000
32.510002,18.855080,-13.566690,-0.003165,0.001772,0.045008,83.871582,4.272622,0.450085,-13.566690,0.046032,0.000000
32.910000,18.579155,-13.655652,-0.003134,0.001796,0.045625,82.644211,4.210096,0.456246,-13.655652,0.046691,0.000000
33.310001,18.982437,-13.655652,-0.003139,0.001823,0.046301,84.438095,4.301482,0.463006,-13.655652,0.047359,0.000000
33.710003,19.199524,-13.655652,-0.003134,0.001850,0.046977,85.403748,4.350675,0.469774,-13.655652,0.048027,0.000000
34.110001,19.319801,-13.700133,-0.003100,0.001872,0.047559,85.938766,4.377930,0.475587,-13.700133,0.048694,0.000000
34.510002,19.052071,-13.655652,-0.003091,0.001889,0.047974,84.747841,4.317261,0.479743,-13.655652,0.049362,0.000000
34.910000,19.834419,-13.700133,-0.003065,0.001923,0.048851,88.227905,4.494544,0.488509,-13.700133,0.050030,0.000000
35.310001,19.982254,-13.655652,-0.003061,0.001947,0.049466,88.885506,4.528043,0.494663,-13.655652,0.050698,0.000000
35.710003,19.881340,-13.655652,-0.003035,0.001971,0.050064,88.436615,4.505176,0.500643,-13.655652,0.051366,0.000000
36.110001,20.523682,-13.700133,-0.003005,0.002000,0.050802,91.293892,4.650733,0.508016,-13.700133,0.052025,0.000000
36.510002,20.868126,-13.744614,-0.002997,0.002028,0.051522,92.826057,4.728785,0.515215,-13.744614,0.052693,0.000000
36.910000,20.926216,-13.789095,-0.002992,0.002052,0.052111,93.084457,4.741949,0.521112,-13.789095,0.053360,0.000000
37.310001,20.904617,-13.744614,-0.002988,0.002079,0.052796,92.988380,4.737054,0.527963,-13.744614,0.054028,0.000000
37.710003,21.609146,-13.833576,-0.002958,0.002105,0.053473,96.122284,4.896702,0.534730,-13.833576,0.054696,0.000000
38.110001,21.389076,-13.833576,-0.002932,0.002127,0.054020,95.143364,4.846834,0.540195,-13.833576,0.055363,0.000000
38.510002,22.022858,-13.789095,-0.002923,0.002155,0.054748,97.962563,4.990451,0.547477,-13.789095,0.056031,0.000000
38.910004,22.669296,-13.833576,-0.002893,0.002188,0.055563,100.838066,5.136936,0.555630,-13.833576,0.056699,0.000000
39.310001,22.600777,-13.878057,-0.002884,0.002211,0.056161,100.533279,5.121409,0.561610,-13.878057,0.057358,0.000000
39.710003,23.438988,-13.833576,-0.002859,0.002242,0.056951,104.261826,5.311351,0.569506,-13.833576,0.058025,0.000000
40.110001,23.528732,-13.922538,-0.002841,0.002264,0.057515,104.661026,5.331687,0.575145,-13.922538,0.058694,0.000000
40.510002,23.919350,-13.878057,-0.002828,0.002291,0.058182,106.398582,5.420202,0.581822,-13.878057,0.059362,0.000000
40.910004,23.787903,-13.922538,-0.002811,0.002313,0.058754,105.813873,5.390416,0.587544,-13.922538,0.060029,0.000000
41.310001,24.379227,-13.922538,-0.002790,0.002342,0.059474,108.444214,5.524412,0.594743,-13.922538,0.060697,0.000000
41.710003,25.521667,-13.967019,-0.002785,0.002375,0.060333,113.526047,5.783292,0.603327,-13.967019,0.061365,0.000000
42.110001,25.581619,-13.833576,-0.002755,0.002397,0.060888,113.792725,5.796878,0.608876,-13.833576,0.062032,0.000000
42.510002,25.545502,-13.922538,-0.002746,0.002419,0.061434,113.632065,5.788693,0.614341,-13.922538,0.062700,0.000000
42.910004,26.050812,-13.967019,-0.002712,0.002447,0.062145,115.879799,5.903198,0.621449,-13.967019,0.063359,0.000000
43.310001,26.888649,-14.011499,-0.002686,0.002479,0.062978,119.606682,6.093055,0.629776,-14.011499,0.064027,0.000000
43.710003,27.367142,-14.011499,-0.002690,0.002506,0.063663,121.735123,6.201483,0.636627,-14.011499,0.064694,0.000000
44.110001,27.146324,-13.967019,-0.002660,0.002523,0.064096,120.752884,6.151445,0.640964,-13.967019,0.065363,0.000000
44.510002,27.897400,-13.967019,-0.002647,0.002551,0.064799,124.093834,6.321641,0.647989,-13.967019,0.066031,0.000000
44.910004,28.377762,-13.967019,-0.002621,0.002577,0.065458,126.230591,6.430493,0.654582,-13.967019,0.066698,0.000000
45.310001,29.261032,-14.011499,-0.002600,0.002607,0.066212,130.159576,6.630644,0.662122,-14.011499,0.067366,0.000000
45.710003,29.885498,-13.967019,-0.002587,0.002634,0.066906,132.937332,6.772151,0.669063,-13.967019,0.068033,0.000000
46.110001,29.829269,-14.055981,-0.002583,0.002653,0.067392,132.687210,6.759409,0.673916,-14.055981,0.068693,0.000000
46.510002,31.149704,-14.055981,-0.002561,0.002687,0.068251,138.560806,7.058624,0.682507,-14.055981,0.069360,0.000000
46.910004,31.209656,-14.055981,-0.002544,0.002706,0.068745,138.827484,7.072209,0.687450,-14.055981,0.070028,0.000000
47.310001,32.293633,-14.100462,-0.002522,0.002736,0.069491,143.649246,7.317842,0.694907,-14.100462,0.070696,0.000000
47.710003,33.271484,-14.100462,-0.002496,0.002768,0.070297,147.998947,7.539426,0.702969,-14.100462,0.071363,0.000000
48.110001,33.997612,-14.100462,-0.002496,0.002796,0.071026,151.228928,7.703969,0.710258,-14.100462,0.072032,0.000000
48.510002,34.262367,-14.144942,-0.002466,0.002820,0.071633,152.406616,7.763964,0.716329,-14.144942,0.072700,0.000000
48.910004,34.631760,-14.055981,-0.002445,0.002841,0.072161,154.049759,7.847669,0.721613,-14.055981,0.073367,0.000000
49.310001,35.789093,-14.189424,-0.002427,0.002869,0.072881,159.197830,8.109924,0.728812,-14.189424,0.074026,0.000000
49.710003,37.157562,-14.144942,-0.002410,0.002904,0.073757,165.285095,8.420024,0.737570,-14.144942,0.074694,0.000000
50.110001,37.279701,-14.189424,-0.002367,0.002924,0.074269,165.828400,8.447701,0.742687,-14.189424,0.075362,0.000000
50.510002,38.112694,-14.144942,-0.002367,0.002951,0.074963,169.533722,8.636460,0.749629,-14.144942,0.076029,0.000000
50.910004,39.238380,-14.189424,-0.002363,0.002979,0.075665,174.541031,8.891544,0.756653,-14.189424,0.076697,0.000000
51.310001,39.743690,-14.189424,-0.002341,0.003001,0.076238,176.788757,9.006049,0.762376,-14.189424,0.077365,0.000000
51.710003,40.428482,-14.189424,-0.002311,0.003027,0.076880,179.834869,9.161224,0.768795,-14.189424,0.078032,0.000000
52.110001,40.730850,-14.144942,-0.002302,0.003046,0.077356,181.179871,9.229742,0.773564,-14.144942,0.078701,0.000000
52.510002,42.448975,-14.233904,-0.002272,0.003077,0.078154,188.822464,9.619076,0.781543,-14.233904,0.079359,0.000000
52.910004,43.493477,-14.189424,-0.002259,0.003104,0.078830,193.468643,9.855762,0.788303,-14.189424,0.080027,0.000000
53.310001,43.165794,-14.233904,-0.002238,0.003113,0.079082,192.011047,9.781509,0.790824,-14.233904,0.080695,0.000000
53.710003,45.403008,-14.233904,-0.002233,0.003151,0.080044,201.962662,10.288468,0.800445,-14.233904,0.081363,0.000000
54.110004,47.086128,-14.233904,-0.002220,0.003187,0.080955,209.449554,10.669869,0.809551,-14.233904,0.082031,0.000000
54.510002,47.985039,-14.278385,-0.002212,0.003211,0.081554,213.448120,10.873565,0.815539,-14.278385,0.082698,0.000000
54.910004,49.050018,-14.278385,-0.002164,0.003238,0.082247,218.185379,11.114893,0.822473,-14.278385,0.083366,0.000000
55.310001,50.093781,-14.322866,-0.002147,0.003262,0.082846,222.828262,11.351413,0.828461,-14.322866,0.084034,0.000000
55.710003,51.214996,-14.322866,-0.002147,0.003287,0.083496,227.815689,11.605484,0.834963,-14.322866,0.084701,0.000000
56.110004,52.317215,-14.322866,-0.002113,0.003313,0.084138,232.718597,11.855250,0.841382,-14.322866,0.085361,0.000000
56.510002,53.277191,-14.411828,-0.002121,0.003335,0.084710,236.988785,12.072784,0.847105,-14.411828,0.086028,0.000000
56.910004,54.424469,-14.367347,-0.002104,0.003360,0.085335,242.092133,12.332761,0.853350,-14.367347,0.086696,0.000000
57.310001,56.474754,-14.367347,-0.002070,0.003392,0.086159,251.212250,12.797362,0.861586,-14.367347,0.087364,0.000000
57.710003,57.739708,-14.367347,-0.002061,0.003419,0.086853,256.839050,13.084005,0.868527,-14.367347,0.088032,0.000000
58.110004,58.875816,-14.411828,-0.002048,0.003444,0.087468,261.892700,13.341451,0.874682,-14.411828,0.088700,0.000000
58.510002,59.806000,-14.411828,-0.002022,0.003466,0.088032,266.030365,13.552233,0.880321,-14.411828,0.089367,0.000000
58.910004,62.050285,-14.456309,-0.002022,0.003501,0.088934,276.013458,14.060796,0.889337,-14.456309,0.090035,0.000000
59.310001,63.295509,-14.500790,-0.002005,0.003522,0.089463,281.552490,14.342967,0.894628,-14.500790,0.090694,0.000000
59.710003,64.563805,-14.456309,-0.001992,0.003550,0.090174,287.194153,14.630367,0.901736,-14.456309,0.091362,0.000000
60.110004,65.989616,-14.456309,-0.001970,0.003565,0.090547,293.536469,14.953461,0.905468,-14.456309,0.090772,0.000000
60.510002,65.188637,-14.456309,-0.001953,0.003576,0.090833,289.973541,14.771956,0.908329,-14.456309,294.500488,0.000000
60.910004,64.906761,-14.500790,-0.001953,0.003583,0.090998,288.719696,14.708082,0.909980,-14.500790,294.500488,0.000000
61.310001,64.677010,-14.500790,-0.001936,0.003589,0.091162,287.697693,14.656020,0.911622,-14.500790,294.500488,0.000000
61.710003,65.053093,-14.500790,-0.001936,0.003601,0.091457,289.370605,14.741241,0.914574,-14.500790,294.500488,0.000000
62.110004,64.746635,-14.545271,-0.001932,0.003605,0.091579,288.007416,14.671798,0.915786,-14.545271,294.500488,0.000000
62.510002,65.223640,-14.545271,-0.001923,0.003616,0.091839,290.129242,14.779888,0.918390,-14.545271,294.500488,0.000000
62.910004,64.665092,-14.456309,-0.001919,0.003616,0.091847,287.644684,14.653319,0.918473,-14.456309,294.500488,0.000000
63.310001,66.643135,-14.589752,-0.001884,0.003569,0.090651,296.443481,15.101550,0.906505,-14.589752,294.500488,0.000000
63.710003,65.873436,-14.589752,-0.001901,0.003571,0.090703,293.019684,14.927135,0.907027,-14.589752,294.500488,0.000000
64.110001,65.355461,-14.545271,-0.001876,0.003592,0.091232,290.715607,14.809759,0.912319,-14.545271,294.500488,0.000000
64.510002,64.986824,-14.589752,-0.001880,0.003621,0.091977,289.075836,14.726225,0.919775,-14.589752,294.500488,0.000000
64.910004,65.123100,-14.589752,-0.001880,0.003639,0.092437,289.682007,14.757106,0.924370,-14.589752,294.500488,0.000000
65.310005,65.021828,-14.589752,-0.001863,0.003641,0.092472,289.231537,14.734157,0.924718,-14.589752,294.500488,0.000000
65.710007,65.133537,-14.678714,-0.001880,0.003646,0.092611,289.728455,14.759470,0.926111,-14.678714,294.500488,0.000000
66.110001,64.986824,-14.634233,-0.001867,0.003649,0.092680,289.075836,14.726225,0.926800,-14.634233,294.500488,0.000000
66.510002,64.767494,-14.634233,-0.001854,0.003649,0.092680,288.100189,14.676524,0.926800,-14.634233,294.500488,0.000000
66.910004,65.755394,-14.634233,-0.001854,0.003662,0.093018,292.494598,14.900386,0.930183,-14.634233,294.500488,0.000000
67.310005,65.515953,-14.678714,-0.001858,0.003662,0.093018,291.429504,14.846127,0.930183,-14.678714,294.500488,0.000000
67.710007,65.257164,-14.678714,-0.001871,0.003662,0.093018,290.278351,14.787484,0.930183,-14.678714,294.500488,0.000000
68.110001,65.014748,-14.723195,-0.001871,0.003662,0.093027,289.200043,14.732553,0.930267,-14.723195,294.500488,0.000000
68.510002,64.797646,-14.678714,-0.001863,0.003663,0.093036,288.234314,14.683356,0.930357,-14.678714,294.500488,0.000000
68.910004,64.582420,-14.723195,-0.001854,0.003663,0.093036,287.276947,14.634586,0.930357,-14.723195,294.500488,0.000000
69.310005,64.395866,-14.723195,-0.001858,0.003663,0.093036,286.447113,14.592313,0.930357,-14.723195,294.500488,0.000000
69.710007,66.574989,-14.767675,-0.001841,0.003621,0.091977,296.140350,15.086108,0.919775,-14.767675,294.500488,0.000000
70.110001,66.258095,-14.767675,-0.001858,0.003620,0.091960,294.730713,15.014298,0.919601,-14.767675,294.500488,0.000000
70.510002,66.009727,-14.812157,-0.001828,0.003620,0.091960,293.625946,14.958018,0.919601,-14.812157,294.500488,0.000000
70.910004,65.822426,-14.723195,-0.001832,0.003622,0.091987,292.792786,14.915575,0.919866,-14.723195,294.500488,0.000000
71.310005,65.592674,-14.767675,-0.001832,0.003622,0.091995,291.770782,14.863513,0.919949,-14.767675,294.500488,0.000000
71.710007,65.413185,-14.812157,-0.001819,0.003645,0.092576,290.972382,14.822840,0.925763,-14.812157,294.500488,0.000000
72.110001,65.273918,-14.767675,-0.001811,0.003658,0.092915,290.352875,14.791282,0.929146,-14.767675,294.500488,0.000000
72.510002,65.146187,-14.812157,-0.001824,0.003665,0.093096,289.784698,14.762337,0.930963,-14.812157,294.500488,0.000000
72.910004,65.012138,-14.856638,-0.001819,0.003673,0.093296,289.188446,14.731961,0.932961,-14.856638,294.500488,0.000000
73.310005,64.931328,-14.901118,-0.001807,0.003676,0.093382,288.828979,14.713649,0.933824,-14.901118,294.500488,0.000000
73.710007,65.521919,-14.901118,-0.001802,0.003689,0.093703,291.456055,14.847479,0.937034,-14.901118,294.500488,0.000000
74.110001,65.395317,-14.901118,-0.001811,0.003689,0.093703,290.892914,14.818790,0.937034,-14.901118,294.500488,0.000000
74.510002,65.279503,-14.901118,-0.001815,0.003689,0.093703,290.377716,14.792547,0.937034,-14.901118,294.500488,0.000000
74.910004,65.162209,-14.901118,-0.001828,0.003689,0.093703,289.855988,14.765968,0.937034,-14.901118,294.500488,0.000000
75.310005,65.035973,-14.945600,-0.001811,0.003689,0.093712,289.294464,14.737362,0.937125,-14.945600,294.500488,0.000000
75.710007,64.908989,-14.945600,-0.001815,0.003689,0.093712,288.729614,14.708587,0.937125,-14.945600,294.500488,0.000000
76.110001,64.822227,-14.901118,-0.001811,0.003696,0.093868,288.343658,14.688927,0.938684,-14.901118,294.500488,0.000000
76.510002,65.661552,-14.990081,-0.001819,0.003701,0.094016,292.077179,14.879121,0.940160,-14.990081,294.500488,0.000000
76.910004,65.597878,-14.945600,-0.001811,0.003701,0.094016,291.793945,14.864691,0.940160,-14.945600,294.500488,0.000000
77.310005,65.527504,-14.990081,-0.001819,0.003701,0.094016,291.480896,14.848745,0.940160,-14.990081,294.500488,0.000000
77.710007,65.409081,-14.990081,-0.001807,0.003701,0.094016,290.954132,14.821909,0.940160,-14.990081,294.500488,0.000000
78.110001,65.323814,-14.990081,-0.001811,0.003701,0.094016,290.574829,14.802588,0.940160,-14.990081,294.500488,0.000000
78.510002,65.235558,-14.990081,-0.001794,0.003701,0.094016,290.182251,14.782589,0.940160,-14.990081,294.500488,0.000000
78.910004,65.130547,-15.034561,-0.001828,0.003703,0.094050,289.715149,14.758793,0.940501,-15.034561,294.500488,0.000000
79.310005,65.065758,-14.990081,-0.001815,0.003703,0.094050,289.426941,14.744112,0.940501,-14.990081,294.500488,0.000000
79.710007,65.000221,-15.034561,-0.001802,0.003703,0.094059,289.135437,14.729260,0.940592,-15.034561,294.500488,0.000000
80.110001,65.126457,-15.034561,-0.001807,0.003708,0.094172,289.696960,14.757866,0.941720,-15.034561,294.500488,0.000000
80.510002,65.153633,-14.990081,-0.001798,0.003708,0.094172,289.817841,14.764025,0.941720,-14.990081,294.500488,0.000000
80.910004,65.095924,-15.079042,-0.001802,0.003708,0.094172,289.561127,14.750948,0.941720,-15.079042,294.500488,0.000000
81.310005,65.045280,-15.079042,-0.001789,0.003708,0.094172,289.335846,14.739471,0.941720,-15.079042,294.500488,0.000000
81.710007,64.995750,-15.123524,-0.001798,0.003709,0.094207,289.115540,14.728248,0.942068,-15.123524,294.500488,0.000000
82.110001,64.997246,-15.079042,-0.001798,0.003709,0.094207,289.122192,14.728586,0.942068,-15.079042,294.500488,0.000000
82.510002,64.955544,-15.123524,-0.001789,0.003710,0.094233,288.936676,14.719137,0.942325,-15.123524,294.500488,0.000000
82.910004,64.935051,-15.168004,-0.001802,0.003710,0.094233,288.845520,14.714493,0.942325,-15.168004,294.500488,0.000000
83.310005,64.868034,-15.168004,-0.001807,0.003711,0.094250,288.547424,14.699306,0.942499,-15.168004,294.500488,0.000000
83.710007,64.843452,-15.123524,-0.001798,0.003711,0.094258,288.438080,14.693736,0.942583,-15.123524,294.500488,0.000000
84.110001,64.909370,-15.123524,-0.001789,0.003713,0.094302,288.731293,14.708674,0.943022,-15.123524,294.500488,0.000000
84.510002,64.862450,-15.168004,-0.001794,0.003713,0.094302,288.522583,14.698041,0.943022,-15.168004,294.500488,0.000000
84.910004,64.810692,-15.168004,-0.001802,0.003713,0.094302,288.292358,14.686313,0.943022,-15.168004,294.500488,0.000000
85.310005,65.241890,-15.168004,-0.001798,0.003718,0.094449,290.210419,14.784024,0.944490,-15.168004,294.500488,0.000000
85.710007,65.220665,-15.168004,-0.001789,0.003718,0.094449,290.115997,14.779214,0.944490,-15.168004,294.500488,0.000000
86.110001,65.171135,-15.212485,-0.001789,0.003718,0.094449,289.895691,14.767991,0.944490,-15.212485,294.500488,0.000000
86.510002,65.111565,-15.168004,-0.001781,0.003718,0.094449,289.630707,14.754492,0.944490,-15.168004,294.500488,0.000000
86.910004,65.063148,-15.212485,-0.001794,0.003718,0.094449,289.415344,14.743520,0.944490,-15.212485,294.500488,0.000000
87.310005,65.015114,-15.212485,-0.001789,0.003718,0.094449,289.201660,14.732635,0.944490,-15.212485,294.500488,0.000000
87.710007,64.968941,-15.212485,-0.001785,0.003718,0.094449,288.996277,14.722173,0.944490,-15.212485,294.500488,0.000000
88.110001,64.892601,-15.212485,-0.001798,0.003718,0.094449,288.656708,14.704874,0.944490,-15.212485,294.500488,0.000000
88.510002,64.859840,-15.256967,-0.001794,0.003720,0.094493,288.510986,14.697450,0.944929,-15.256967,294.500488,0.000000
88.910004,64.883675,-15.301447,-0.001811,0.003721,0.094501,288.617004,14.702851,0.945013,-15.301447,294.500488,0.000000
89.310005,64.828926,-15.301447,-0.001789,0.003721,0.094501,288.373474,14.690445,0.945013,-15.301447,294.500488,0.000000
89.710007,64.806221,-15.301447,-0.001772,0.003722,0.094536,288.272461,14.685300,0.945361,-15.301447,294.500488,0.000000
90.110001,65.510368,-15.301447,-0.001781,0.003728,0.094701,291.404663,14.844861,0.947011,-15.301447,294.500488,0.000000
90.510002,65.514091,-15.256967,-0.001789,0.003728,0.094701,291.421234,14.845706,0.947011,-15.256967,294.500488,0.000000
90.910004,65.462715,-15.345928,-0.001807,0.003728,0.094701,291.192688,14.834064,0.947011,-15.345928,294.500488,0.000000
91.310005,65.394188,-15.301447,-0.001781,0.003728,0.094701,290.887878,14.818535,0.947011,-15.301447,294.500488,0.000000
91.710007,65.351738,-15.345928,-0.001776,0.003728,0.094701,290.699036,14.808915,0.947011,-15.345928,294.500488,0.000000
92.110001,65.321587,-15.345928,-0.001785,0.003728,0.094701,290.564941,14.802083,0.947011,-15.345928,294.500488,0.000000
92.510002,65.283974,-15.301447,-0.001781,0.003728,0.094701,290.397614,14.793560,0.947011,-15.301447,294.500488,0.000000
92.910004,65.248589,-15.345928,-0.001789,0.003728,0.094701,290.240204,14.785542,0.947011,-15.345928,294.500488,0.000000
93.310005,65.195351,-15.345928,-0.001785,0.003728,0.094701,290.003418,14.773478,0.947011,-15.345928,294.500488,0.000000
93.710007,65.121239,-15.345928,-0.001785,0.003728,0.094701,289.673737,14.756683,0.947011,-15.345928,294.500488,0.000000
94.110008,65.077675,-15.390409,-0.001785,0.003728,0.094701,289.479950,14.746812,0.947011,-15.390409,294.500488,0.000000
94.510002,65.045647,-15.390409,-0.001776,0.003728,0.094701,289.337494,14.739554,0.947011,-15.390409,294.500488,0.000000
94.910004,65.012138,-15.434890,-0.001789,0.003728,0.094701,289.188446,14.731961,0.947011,-15.434890,294.500488,0.000000
95.310005,64.970802,-15.434890,-0.001781,0.003728,0.094701,289.004578,14.722594,0.947011,-15.434890,294.500488,0.000000
95.710007,64.901543,-15.390409,-0.001781,0.003728,0.094701,288.696472,14.706901,0.947011,-15.390409,294.500488,0.000000
96.110008,64.849419,-15.390409,-0.001781,0.003728,0.094701,288.464630,14.695088,0.947011,-15.390409,294.500488,0.000000
96.510002,64.797279,-15.434890,-0.001781,0.003728,0.094701,288.232697,14.683273,0.947011,-15.434890,294.500488,0.000000
96.910004,64.764503,-15.479371,-0.001789,0.003728,0.094701,288.086914,14.675847,0.947011,-15.479371,294.500488,0.000000
97.310005,64.728386,-15.479371,-0.001789,0.003728,0.094701,287.926239,14.667662,0.947011,-15.479371,294.500488,0.000000
97.710007,64.689293,-15.479371,-0.001781,0.003729,0.094709,287.752350,14.658804,0.947094,-15.479371,294.500488,0.000000
98.110008,64.631203,-15.568333,-0.001785,0.003729,0.094709,287.493958,14.645640,0.947094,-15.568333,294.500488,0.000000
98.510002,64.593971,-15.568333,-0.001768,0.003729,0.094709,287.328339,14.637203,0.947094,-15.568333,294.500488,0.000000
98.910004,64.541832,-15.523852,-0.001785,0.003732,0.094796,287.096405,14.625388,0.947965,-15.523852,294.500488,0.000000
99.310005,65.856300,-15.523852,-0.001789,0.003743,0.095083,292.943451,14.923250,0.950826,-15.523852,294.500488,0.000000
99.710007,65.856300,-15.523852,-0.001776,0.003743,0.095083,292.943451,14.923250,0.950826,-15.523852,294.500488,0.000000
100.110008,65.847374,-15.612814,-0.001772,0.003743,0.095083,292.903748,14.921227,0.950826,-15.612814,294.500488,0.000000
100.510002,65.902855,-15.568333,-0.001789,0.003743,0.095083,293.150543,14.933801,0.950826,-15.568333,294.500488,0.000000
100.910004,65.892433,-15.612814,-0.001772,0.003743,0.095083,293.104187,14.931439,0.950826,-15.612814,294.500488,0.000000
101.310005,65.831734,-15.568333,-0.001772,0.003743,0.095083,292.834167,14.917685,0.950826,-15.568333,294.500488,0.000000
101.710007,65.843269,-15.568333,-0.001781,0.003743,0.095083,292.885498,14.920299,0.950826,-15.568333,294.500488,0.000000
102.110008,65.753532,-15.612814,-0.001789,0.003743,0.095083,292.486328,14.899963,0.950826,-15.612814,294.500488,0.000000
102.510002,65.787788,-15.612814,-0.001789,0.003743,0.095083,292.638702,14.907725,0.950826,-15.612814,294.500488,0.000000
102.910004,65.671242,-15.657295,-0.001781,0.003743,0.095083,292.120270,14.881316,0.950826,-15.657295,294.500488,0.000000
103.310005,65.619850,-15.612814,-0.001772,0.003743,0.095083,291.891663,14.869671,0.950826,-15.612814,294.500488,0.000000
103.710007,65.586342,-15.701776,-0.001776,0.003743,0.095083,291.742615,14.862078,0.950826,-15.701776,294.500488,0.000000
104.110008,65.586708,-15.701776,-0.001763,0.003743,0.095083,291.744263,14.862160,0.950826,-15.701776,294.500488,0.000000
104.510002,65.554680,-15.701776,-0.001763,0.003743,0.095083,291.601776,14.854903,0.950826,-15.701776,294.500488,0.000000
104.910004,65.536446,-15.657295,-0.001776,0.003743,0.095083,291.520660,14.850771,0.950826,-15.657295,294.500488,0.000000
105.310005,65.495110,-15.701776,-0.001772,0.003743,0.095083,291.336792,14.841404,0.950826,-15.701776,294.500488,0.000000
105.710007,65.459358,-15.746257,-0.001768,0.003743,0.095083,291.177765,14.833302,0.950826,-15.746257,294.500488,0.000000
106.110008,65.386375,-15.746257,-0.001768,0.003743,0.095083,290.853119,14.816764,0.950826,-15.746257,294.500488,0.000000
106.510002,65.364769,-15.790737,-0.001776,0.003743,0.095083,290.757019,14.811869,0.950826,-15.790737,294.500488,0.000000
106.910004,65.335365,-15.790737,-0.001768,0.003743,0.095083,290.626221,14.805205,0.950826,-15.790737,294.500488,0.000000
107.310005,65.309669,-15.835218,-0.001768,0.003743,0.095083,290.511932,14.799383,0.950826,-15.835218,294.500488,0.000000
107.710007,65.288445,-15.835218,-0.001768,0.003743,0.095083,290.417511,14.794573,0.950826,-15.835218,294.500488,0.000000
108.110008,65.281731,-15.790737,-0.001763,0.003743,0.095083,290.387634,14.793052,0.950826,-15.790737,294.500488,0.000000
108.510002,65.226997,-15.835218,-0.001755,0.003743,0.095083,290.144165,14.780648,0.950826,-15.835218,294.500488,0.000000
108.910004,65.180458,-15.879700,-0.001768,0.003743,0.095083,289.937164,14.770103,0.950826,-15.879700,294.500488,0.000000
109.310005,65.160713,-15.879700,-0.001750,0.003743,0.095083,289.849335,14.765629,0.950826,-15.879700,294.500488,0.000000
109.710007,65.100014,-15.835218,-0.001789,0.003743,0.095083,289.579315,14.751874,0.950826,-15.835218,294.500488,0.000000
110.110008,65.094429,-15.879700,-0.001763,0.003743,0.095083,289.554474,14.750608,0.950826,-15.879700,294.500488,0.000000
110.510002,65.053841,-15.835218,-0.001768,0.003743,0.095083,289.373932,14.741411,0.950826,-15.835218,294.500488,0.000000
110.910004,65.015495,-15.924180,-0.001759,0.003743,0.095083,289.203369,14.732721,0.950826,-15.924180,294.500488,0.000000
111.310005,64.997246,-15.924180,-0.001772,0.003743,0.095083,289.122192,14.728586,0.950826,-15.924180,294.500488,0.000000
111.710007,64.971184,-15.924180,-0.001772,0.003743,0.095083,289.006256,14.722681,0.950826,-15.924180,294.500488,0.000000
112.110008,64.915688,-15.924180,-0.001759,0.003743,0.095083,288.759399,14.710105,0.950826,-15.924180,294.500488,0.000000
112.510002,64.878822,-15.968661,-0.001776,0.003743,0.095083,288.595428,14.701751,0.950826,-15.968661,294.500488,0.000000
112.910004,64.832283,-15.924180,-0.001776,0.003743,0.095083,288.388397,14.691205,0.950826,-15.924180,294.500488,0.000000
113.310005,64.798027,-15.924180,-0.001772,0.003743,0.095083,288.236023,14.683442,0.950826,-15.924180,294.500488,0.000000
113.710007,64.783134,-16.013142,-0.001768,0.003743,0.095083,288.169769,14.680068,0.950826,-16.013142,294.500488,0.000000
114.110008,65.488029,-15.968661,-0.001763,0.003754,0.095342,291.305298,14.839800,0.953423,-15.968661,294.500488,0.000000
114.510002,65.539787,-16.013142,-0.001759,0.003753,0.095317,291.535522,14.851528,0.953165,-16.013142,294.500488,0.000000
114.910004,65.517815,-16.013142,-0.001776,0.003753,0.095317,291.437805,14.846549,0.953165,-16.013142,294.500488,0.000000
115.310005,65.512611,-15.968661,-0.001768,0.003753,0.095317,291.414642,14.845369,0.953165,-15.968661,294.500488,0.000000
115.710007,65.488029,-16.013142,-0.001772,0.003753,0.095317,291.305298,14.839800,0.953165,-16.013142,294.500488,0.000000
116.110008,65.484306,-16.057623,-0.001776,0.003753,0.095317,291.288757,14.838956,0.953165,-16.057623,294.500488,0.000000
116.510002,65.473503,-16.013142,-0.001768,0.003753,0.095317,291.240692,14.836508,0.953165,-16.013142,294.500488,0.000000
116.910004,65.429573,-16.146585,-0.001763,0.003753,0.095317,291.045288,14.826553,0.953165,-16.146585,294.500488,0.000000
117.310005,65.405357,-16.057623,-0.001768,0.003753,0.095317,290.937561,14.821066,0.953165,-16.057623,294.500488,0.000000
117.710007,65.374825,-16.102104,-0.001759,0.003753,0.095317,290.801758,14.814147,0.953165,-16.102104,294.500488,0.000000
118.110008,65.356956,-16.102104,-0.001763,0.003753,0.095317,290.722260,14.810098,0.953165,-16.102104,294.500488,0.000000
118.510002,65.332008,-16.146585,-0.001746,0.003753,0.095317,290.611298,14.804445,0.953165,-16.146585,294.500488,0.000000
118.910004,65.323814,-16.102104,-0.001746,0.003753,0.095317,290.574829,14.802588,0.953165,-16.102104,294.500488,0.000000
119.310005,65.297005,-16.191067,-0.001759,0.003753,0.095317,290.455597,14.796514,0.953165,-16.191067,294.500488,0.000000
119.710007,65.274666,-16.191067,-0.001750,0.003753,0.095317,290.356201,14.791451,0.953165,-16.191067,294.500488,0.000000
120.110008,65.265724,-16.146585,-0.001755,0.003753,0.095317,290.316437,14.789425,0.953165,-16.146585,294.500488,0.000000
120.510002,65.226631,-16.191067,-0.001763,0.003753,0.095317,290.142548,14.780566,0.953165,-16.191067,1681.640991,0.000000
120.910004,65.189384,-16.191067,-0.001763,0.003746,0.095161,289.976868,14.772126,0.951606,-16.191067,0.095195,0.000000
121.310005,65.052361,-16.235548,-0.001759,0.003731,0.094770,289.367340,14.741076,0.947700,-16.235548,0.094536,0.000000
121.710007,65.040443,-16.235548,-0.001763,0.003712,0.094285,289.314331,14.738375,0.942848,-16.235548,0.093868,0.000000
122.110008,64.946236,-16.191067,-0.001763,0.003689,0.093703,288.895294,14.717027,0.937034,-16.191067,0.093201,0.000000
122.510002,64.894844,-16.191067,-0.001763,0.003661,0.092993,288.666687,14.705382,0.929926,-16.191067,0.092532,0.000000
122.910004,64.895210,-16.235548,-0.001768,0.003637,0.092368,288.668304,14.705465,0.923681,-16.235548,0.091865,0.000000
123.310005,64.822594,-16.235548,-0.001746,0.003610,0.091683,288.345306,14.689010,0.916830,-16.235548,0.091197,0.000000
123.710007,64.801369,-16.235548,-0.001755,0.003585,0.091059,288.250885,14.684199,0.910585,-16.235548,0.090529,0.000000
124.110008,64.773079,-16.235548,-0.001750,0.003559,0.090391,288.125031,14.677790,0.903909,-16.235548,0.089862,0.000000
124.510002,64.690041,-16.280027,-0.001750,0.003534,0.089766,287.755676,14.658973,0.897664,-16.280027,0.089202,0.000000
124.910004,64.465492,-16.280027,-0.001755,0.003512,0.089202,286.756836,14.608088,0.892024,-16.280027,0.088535,0.000000
125.310005,63.641060,-16.280027,-0.001746,0.003489,0.088622,283.089569,14.421270,0.886218,-16.280027,0.087867,0.000000
125.710007,62.500488,-16.324509,-0.001733,0.003463,0.087953,278.016052,14.162812,0.879534,-16.324509,0.087199,0.000000
126.110008,61.168137,-16.324509,-0.001729,0.003438,0.087321,272.089447,13.860897,0.873206,-16.324509,0.086532,0.000000
126.510010,59.370697,-16.324509,-0.001712,0.003411,0.086645,264.094055,13.453592,0.866446,-16.324509,0.085863,0.000000
126.910004,57.816040,-16.324509,-0.001703,0.003391,0.086124,257.178589,13.101302,0.861238,-16.324509,0.085196,0.000000
127.310005,55.997749,-16.368990,-0.001699,0.003369,0.085569,249.090424,12.689271,0.855689,-16.368990,0.084528,0.000000
127.710007,54.780830,-16.324509,-0.001699,0.003349,0.085075,243.677307,12.413513,0.850746,-16.324509,0.083869,0.000000
128.110001,51.275688,-16.324509,-0.001694,0.003317,0.084251,228.085648,11.619237,0.842510,-16.324509,0.083201,0.000000
128.510010,48.113503,-16.368990,-0.001681,0.003285,0.083444,214.019547,10.902676,0.834441,-16.368990,0.082533,0.000000
128.910004,45.758247,-16.368990,-0.001699,0.003265,0.082932,203.542847,10.368967,0.829323,-16.368990,0.081866,0.000000
129.310013,43.919098,-16.413471,-0.001686,0.003249,0.082533,195.361908,9.952209,0.825334,-16.413471,0.081198,0.000000
129.710007,40.464600,-16.413471,-0.001690,0.003216,0.081675,179.995529,9.169409,0.816750,-16.413471,0.080530,0.000000
130.110001,38.100410,-16.457952,-0.001690,0.003193,0.081094,169.479095,8.633677,0.810936,-16.457952,0.079863,0.000000
130.510010,34.354340,-16.413471,-0.001690,0.003160,0.080253,152.815735,7.784804,0.802526,-16.413471,0.079195,0.000000
130.910004,32.098511,-16.502434,-0.001694,0.003137,0.079680,142.781311,7.273627,0.796804,-16.502434,0.078536,0.000000
131.310013,28.640289,-16.413471,-0.001699,0.003108,0.078935,127.398369,6.489982,0.789347,-16.413471,0.077868,0.000000
131.710007,26.058624,-16.457952,-0.001686,0.003083,0.078302,115.914551,5.904969,0.783019,-16.457952,0.077201,0.000000
132.110001,23.962540,-16.457952,-0.001686,0.003063,0.077807,106.590698,5.429989,0.778068,-16.457952,0.076532,0.000000
132.510010,20.265259,-16.457952,-0.001686,0.003028,0.076905,90.144371,4.592173,0.769053,-16.457952,0.075864,0.000000
132.910004,17.933830,-16.502434,-0.001707,0.003009,0.076428,79.773659,4.063864,0.764284,-16.502434,0.075197,0.000000
133.310013,15.034912,-16.457952,-0.001673,0.002977,0.075621,66.878632,3.406960,0.756214,-16.457952,0.074529,0.000000
133.710007,11.413963,-16.546913,-0.001690,0.002949,0.074902,50.771843,2.586441,0.749023,-16.546913,0.073861,0.000000
134.110001,8.919441,-16.457952,-0.001694,0.002924,0.074269,39.675655,2.021174,0.742687,-16.457952,0.073194,0.000000
134.510010,5.907318,-16.591394,-0.001694,0.002896,0.073549,26.277063,1.338617,0.735488,-16.591394,0.072534,0.000000
134.910004,4.150841,-16.546913,-0.001694,0.002879,0.073132,18.463861,0.940594,0.731325,-16.546913,0.071867,0.000000
135.310013,0.386894,-16.591394,-0.001677,0.002842,0.072179,1.720991,0.087671,0.721787,-16.591394,0.071199,0.000000
135.710007,-1.186745,-16.546913,-0.001694,0.002824,0.071728,-5.278904,-0.268920,0.717283,-16.546913,0.070532,0.000000
136.110001,-0.320984,-16.591394,-0.001694,0.002796,0.071008,-1.427808,-0.072736,0.710084,-16.591394,0.069863,0.000000
136.510010,-0.062553,-16.635876,-0.001690,0.002767,0.070271,-0.278251,-0.014175,0.702711,-16.635876,0.069195,0.000000
136.910004,-0.032021,-16.591394,-0.001690,0.002747,0.069768,-0.142435,-0.007256,0.697677,-16.591394,0.068528,0.000000
137.310013,-0.026062,-16.591394,-0.001699,0.002718,0.069040,-0.115930,-0.005906,0.690395,-16.591394,0.067860,0.000000
137.710007,-0.042076,-16.635876,-0.001686,0.002696,0.068476,-0.187164,-0.009535,0.684756,-16.635876,0.067201,0.000000
138.110001,-0.106865,-16.591394,-0.001699,0.002659,0.067539,-0.475359,-0.024216,0.675392,-16.591394,0.066533,0.000000
138.510010,-0.050636,-16.635876,-0.001699,0.002635,0.066932,-0.225241,-0.011474,0.669321,-16.635876,0.065865,0.000000
138.910004,-0.054367,-16.635876,-0.001686,0.002612,0.066334,-0.241837,-0.012320,0.663341,-16.635876,0.065198,0.000000
139.310013,-0.069633,-16.591394,-0.001681,0.002579,0.065510,-0.309745,-0.015779,0.655097,-16.591394,0.064530,0.000000
139.710007,-0.101654,-16.635876,-0.001681,0.002564,0.065128,-0.452180,-0.023035,0.651282,-16.635876,0.063863,0.000000
140.110001,-0.100166,-16.635876,-0.001686,0.002525,0.064131,-0.445562,-0.022698,0.641313,-16.635876,0.063194,0.000000
140.510010,-0.113945,-16.680357,-0.001677,0.002503,0.063585,-0.506853,-0.025820,0.635847,-16.680357,0.062526,0.000000
140.910004,-0.115433,-16.635876,-0.001673,0.002476,0.062882,-0.513470,-0.026157,0.628822,-16.635876,0.061868,0.000000
141.310013,-0.112083,-16.724838,-0.001686,0.002450,0.062240,-0.498572,-0.025398,0.622403,-16.724838,0.061199,0.000000
141.710007,-0.110222,-16.635876,-0.001694,0.002430,0.061729,-0.490291,-0.024977,0.617286,-16.635876,0.060532,0.000000
142.110001,-0.110588,-16.724838,-0.001686,0.002392,0.060749,-0.491920,-0.025060,0.607491,-16.724838,0.059864,0.000000
142.510010,-0.143364,-16.724838,-0.001707,0.002376,0.060358,-0.637715,-0.032487,0.603585,-16.724838,0.059197,0.000000
142.910004,-0.162727,-16.769318,-0.001703,0.002345,0.059570,-0.723847,-0.036875,0.595697,-16.769318,0.058529,0.000000
143.310013,-0.168678,-16.813799,-0.001703,0.002318,0.058867,-0.750318,-0.038223,0.588672,-16.813799,0.057861,0.000000
143.710007,-0.159744,-16.813799,-0.001712,0.002291,0.058200,-0.710578,-0.036199,0.581996,-16.813799,0.057194,0.000000
144.110001,-0.126228,-16.813799,-0.001720,0.002260,0.057410,-0.561492,-0.028604,0.574100,-16.813799,0.056534,0.000000
144.510010,-0.168678,-16.858280,-0.001738,0.002240,0.056898,-0.750318,-0.038223,0.568983,-16.858280,0.055867,0.000000
144.910004,-0.164215,-16.769318,-0.001759,0.002211,0.056161,-0.730465,-0.037212,0.561610,-16.769318,0.055199,0.000000
145.310013,-0.145966,-16.769318,-0.001763,0.002183,0.055441,-0.649287,-0.033076,0.554411,-16.769318,0.054531,0.000000
145.710007,-0.168678,-16.813799,-0.001802,0.002156,0.054765,-0.750318,-0.038223,0.547652,-16.813799,0.053863,0.000000
146.110001,-0.201820,-16.858280,-0.001819,0.002133,0.054175,-0.897742,-0.045733,0.541755,-16.858280,0.053195,0.000000
146.510010,-0.207039,-16.813799,-0.001845,0.002106,0.053481,-0.920955,-0.046916,0.534813,-16.813799,0.052528,0.000000
146.910004,-0.188042,-16.813799,-0.001858,0.002084,0.052926,-0.836451,-0.042611,0.529265,-16.813799,0.051860,0.000000
147.310013,-0.172775,-16.858280,-0.001901,0.002054,0.052172,-0.768543,-0.039151,0.521717,-16.858280,0.051192,0.000000
147.710007,-0.169800,-16.902761,-0.001910,0.002024,0.051418,-0.755307,-0.038477,0.514178,-16.902761,0.050533,0.000000
148.110001,-0.204803,-16.858280,-0.001944,0.002001,0.050836,-0.911011,-0.046409,0.508364,-16.858280,0.049865,0.000000
148.510010,-0.202942,-16.902761,-0.001988,0.001979,0.050264,-0.902731,-0.045987,0.502642,-16.902761,0.049198,0.000000
148.910004,-0.175758,-16.947243,-0.001992,0.001958,0.049744,-0.781812,-0.039827,0.497441,-16.947243,0.048530,0.000000
149.310013,-0.201080,-16.947243,-0.002026,0.001925,0.048885,-0.894450,-0.045565,0.488849,-16.947243,0.047862,0.000000
149.710007,-0.198845,-16.902761,-0.002057,0.001895,0.048122,-0.884506,-0.045059,0.481219,-16.902761,0.047194,0.000000
150.110001,-0.190277,-16.947243,-0.002078,0.001870,0.047489,-0.846395,-0.043117,0.474891,-16.947243,0.046526,0.000000
150.510010,-0.204430,-16.947243,-0.002113,0.001844,0.046847,-0.909348,-0.046324,0.468472,-16.947243,0.045859,0.000000
150.910004,-0.182091,-16.947243,-0.002134,0.001819,0.046197,-0.809980,-0.041262,0.461969,-16.947243,0.045199,0.000000
151.310013,-0.201080,-16.991724,-0.002151,0.001794,0.045572,-0.894450,-0.045565,0.455724,-16.991724,0.044532,0.000000
151.710007,-0.199219,-16.991724,-0.002203,0.001765,0.044827,-0.886169,-0.045144,0.448268,-16.991724,0.043864,0.000000
152.110001,-0.189903,-16.991724,-0.002216,0.001743,0.044272,-0.844732,-0.043033,0.442719,-16.991724,0.043196,0.000000
152.510010,-0.181717,-16.991724,-0.002246,0.001718,0.043630,-0.808317,-0.041178,0.436300,-16.991724,0.042529,0.000000
152.910004,-0.189903,-17.080685,-0.002285,0.001686,0.042832,-0.844732,-0.043033,0.428321,-17.080685,0.041861,0.000000
153.310013,-0.187675,-17.036203,-0.002294,0.001665,0.042303,-0.834822,-0.042528,0.423030,-17.036203,0.041193,0.000000
153.710007,-0.170174,-17.036203,-0.002328,0.001639,0.041635,-0.756970,-0.038562,0.416354,-17.036203,0.040525,0.000000
154.110001,-0.194748,-17.036203,-0.002367,0.001614,0.040993,-0.866282,-0.044131,0.409934,-17.036203,0.039866,0.000000
154.510010,-0.190651,-17.080685,-0.002384,0.001587,0.040308,-0.848058,-0.043202,0.403084,-17.080685,0.039199,0.000000
154.910004,-0.202942,-17.080685,-0.002419,0.001555,0.039485,-0.902731,-0.045987,0.394848,-17.080685,0.038530,0.000000
155.310013,-0.192886,-17.125166,-0.002423,0.001531,0.038886,-0.858001,-0.043709,0.388860,-17.125166,0.037863,0.000000
155.710007,-0.179108,-17.080685,-0.002458,0.001502,0.038149,-0.796711,-0.040586,0.381487,-17.080685,0.037195,0.000000
156.110001,-0.177246,-17.125166,-0.002479,0.001481,0.037620,-0.788430,-0.040165,0.376203,-17.125166,0.036527,0.000000
156.510010,-0.180222,-17.169647,-0.002522,0.001451,0.036848,-0.801666,-0.040839,0.368482,-17.169647,0.035860,0.000000
156.910004,-0.177994,-17.125166,-0.002544,0.001428,0.036259,-0.791756,-0.040334,0.362585,-17.125166,0.035192,0.000000
157.310013,-0.185814,-17.080685,-0.002565,0.001401,0.035582,-0.826542,-0.042106,0.355818,-17.080685,0.034533,0.000000
157.710007,-0.179855,-17.169647,-0.002591,0.001372,0.034836,-0.800037,-0.040756,0.348362,-17.169647,0.033865,0.000000
158.110001,-0.154907,-17.125166,-0.002621,0.001350,0.034290,-0.689062,-0.035102,0.342896,-17.125166,0.033197,0.000000
158.510010,-0.142616,-17.258610,-0.002647,0.001321,0.033544,-0.634389,-0.032317,0.335440,-17.258610,0.032530,0.000000
158.910004,-0.146339,-17.169647,-0.002673,0.001299,0.032997,-0.650950,-0.033161,0.329975,-17.169647,0.031861,0.000000
159.310013,-0.169800,-17.214128,-0.002695,0.001267,0.032174,-0.755307,-0.038477,0.321739,-17.214128,0.031194,0.000000
159.710007,-0.180969,-17.214128,-0.002734,0.001241,0.031515,-0.804991,-0.041008,0.315145,-17.214128,0.030526,0.000000
160.110001,-0.116180,-17.258610,-0.002764,0.001218,0.030934,-0.516796,-0.026327,0.309339,-17.258610,0.029858,0.000000
160.510010,-0.136658,-17.169647,-0.002777,0.001188,0.030179,-0.607884,-0.030967,0.301792,-17.169647,0.029191,0.000000
160.910004,-0.140381,-17.258610,-0.002811,0.001166,0.029615,-0.624445,-0.031811,0.296153,-17.258610,0.028531,0.000000
161.310013,-0.160858,-17.214128,-0.002854,0.001133,0.028774,-0.715533,-0.036451,0.287743,-17.214128,0.027864,0.000000
161.710007,-0.178360,-17.258610,-0.002863,0.001110,0.028202,-0.793385,-0.040417,0.282020,-17.258610,0.027196,0.000000
162.110001,-0.142616,-17.258610,-0.002893,0.001081,0.027447,-0.634389,-0.032317,0.274473,-17.258610,0.026528,0.000000
162.510010,-0.141495,-17.258610,-0.002902,0.001061,0.026962,-0.629400,-0.032063,0.269621,-17.258610,0.025861,0.000000
162.910004,-0.167191,-17.303089,-0.002949,0.001033,0.026242,-0.743701,-0.037886,0.262422,-17.303089,0.025192,0.000000
163.310013,-0.149689,-17.303089,-0.002984,0.001001,0.025418,-0.665849,-0.033920,0.254178,-17.303089,0.024525,0.000000
163.710007,-0.148201,-17.303089,-0.003160,0.000981,0.024915,-0.659231,-0.033583,0.249152,-17.303089,0.023857,0.000000
164.110001,-0.126976,-17.303089,-0.003156,0.000957,0.024299,-0.564817,-0.028773,0.242990,-17.303089,0.023198,0.000000
164.510010,-0.158630,-17.347570,-0.003156,0.000928,0.023562,-0.705623,-0.035946,0.235625,-17.347570,0.022530,0.000000
164.910004,-0.172035,-17.303089,-0.003156,0.000901,0.022895,-0.765251,-0.038984,0.228948,-17.303089,0.021862,0.000000
165.310013,-0.152672,-17.436533,-0.003156,0.000877,0.022270,-0.679118,-0.034596,0.222703,-17.436533,0.022105,0.000000
165.400009,-0.161232,-17.347570,-0.003160,0.000877,0.022279,-0.717196,-0.036536,0.222786,-17.347570,0.022105,0.000000