File: Data/compression 26/AutoNoHeating-17-26-reverse-2-4_09262024_182410.csv
Time (sec),S:Load (lbs),S:HL1 (DIM),S:LVDT (in),S:Position (in),Ch:Position (mm),Ch:Load (N),Ch:Stress (MPa),Ch:Strain (mm/mm),Ch:HL1 (DIM),Set Point (),Cycles ()
0.110000,-0.509399,-116.940422,-0.011025,-0.006234,-0.158346,-2.265922,-0.115432,-1.583464,-116.940422,-0.158381,0.000000
0.570000,-0.494133,-116.984901,-0.011020,-0.006128,-0.155641,-2.198013,-0.111972,-1.556409,-116.984901,-0.154409,0.000000
1.030000,-0.519081,-116.940422,-0.010753,-0.005830,-0.148088,-2.308988,-0.117625,-1.480878,-116.940422,-0.146743,0.000000
1.490000,-0.514244,-116.984901,-0.010455,-0.005531,-0.140499,-2.287472,-0.116529,-1.404991,-116.984901,-0.139077,0.000000
1.950000,-0.500092,-116.984901,-0.010149,-0.005229,-0.132824,-2.224518,-0.113322,-1.328241,-116.984901,-0.131411,0.000000
2.410000,-0.516479,-116.940422,-0.009826,-0.004925,-0.125088,-2.297415,-0.117036,-1.250885,-116.940422,-0.123744,0.000000
2.870000,-0.475143,-116.984901,-0.009516,-0.004620,-0.117345,-2.113544,-0.107669,-1.173446,-116.984901,-0.116096,0.000000
3.330000,-0.506050,-116.895943,-0.009201,-0.004323,-0.109808,-2.251023,-0.114673,-1.098081,-116.895943,-0.108429,0.000000
3.790000,-0.570473,-116.984901,-0.008912,-0.004026,-0.102272,-2.537589,-0.129271,-1.022717,-116.984901,-0.100763,0.000000
4.250000,-0.479240,-116.940422,-0.008589,-0.003720,-0.094476,-2.131768,-0.108597,-0.944755,-116.940422,-0.093096,0.000000
4.710000,-0.495995,-116.895943,-0.008278,-0.003417,-0.086792,-2.206294,-0.112394,-0.867922,-116.895943,-0.085430,0.000000
5.170000,-0.518341,-116.895943,-0.007998,-0.003123,-0.079325,-2.305696,-0.117458,-0.793253,-116.895943,-0.077764,0.000000
5.630000,-0.512383,-116.895943,-0.007653,-0.002815,-0.071503,-2.279191,-0.116108,-0.715027,-116.895943,-0.070115,0.000000
6.090000,-0.532860,-116.940422,-0.007343,-0.002504,-0.063611,-2.370279,-0.120748,-0.636112,-116.940422,-0.062449,0.000000
6.550000,-0.477005,-116.895943,-0.007028,-0.002211,-0.056162,-2.121824,-0.108091,-0.561618,-116.895943,-0.054783,0.000000
7.010000,-0.469933,-116.895943,-0.006722,-0.001910,-0.048522,-2.090364,-0.106488,-0.485216,-116.895943,-0.047117,0.000000
7.470000,-0.497490,-116.895943,-0.006416,-0.001609,-0.040864,-2.212946,-0.112733,-0.408640,-116.895943,-0.039450,0.000000
7.930000,-0.513123,-116.895943,-0.006084,-0.001302,-0.033067,-2.282483,-0.116275,-0.330671,-116.895943,-0.031784,0.000000
8.390000,-0.487061,-116.895943,-0.005795,-0.001003,-0.025487,-2.166553,-0.110369,-0.254875,-116.895943,-0.024135,0.000000
8.850000,-0.476265,-116.851456,-0.005463,-0.000704,-0.017874,-2.118532,-0.107923,-0.178738,-116.851456,-0.016469,0.000000
9.310000,-0.475143,-116.895943,-0.005152,-0.000403,-0.010242,-2.113544,-0.107669,-0.102419,-116.895943,-0.008802,0.000000
9.770000,-0.425247,-116.851456,-0.004846,-0.000098,-0.002481,-1.891594,-0.096362,-0.024806,-116.851456,-0.001136,0.000000
10.230000,0.176506,-116.895943,-0.004730,0.000012,0.000304,0.785138,0.039997,0.003035,-116.895943,0.000485,0.000000
10.690001,0.113579,-116.851456,-0.004712,0.000012,0.000304,0.505224,0.025737,0.003035,-116.851456,0.000867,0.000000
11.150001,0.126236,-116.806976,-0.004730,0.000020,0.000511,0.561526,0.028605,0.005110,-116.806976,0.001630,0.000000
11.610001,0.459137,-116.806976,-0.004708,0.000052,0.001309,2.042343,0.104042,0.013088,-116.806976,0.002402,0.000000
12.070001,0.906731,-116.806976,-0.004695,0.000084,0.002124,4.033340,0.205468,0.021241,-116.806976,0.003165,0.000000
12.530001,1.296600,-116.851456,-0.004656,0.000113,0.002861,5.767566,0.293814,0.028614,-116.851456,0.003937,0.000000
12.990001,1.665627,-116.851456,-0.004635,0.000139,0.003521,7.409077,0.377436,0.035207,-116.851456,0.004700,0.000000
13.450001,1.927032,-116.762497,-0.004618,0.000161,0.004093,8.571869,0.436672,0.040930,-116.762497,0.005463,0.000000
13.910001,2.734337,-116.851456,-0.004583,0.000201,0.005099,12.162938,0.619610,0.050990,-116.851456,0.006235,0.000000
14.370001,3.415779,-116.762497,-0.004544,0.000240,0.006105,15.194144,0.774027,0.061050,-116.762497,0.006998,0.000000
14.830001,3.733780,-116.806976,-0.004506,0.000265,0.006738,16.608683,0.846087,0.067379,-116.806976,0.007770,0.000000
15.290001,4.207809,-116.762497,-0.004488,0.000296,0.007527,18.717272,0.953503,0.075274,-116.762497,0.008533,0.000000
15.750001,4.712006,-116.806976,-0.004458,0.000326,0.008290,20.960049,1.067756,0.082904,-116.806976,0.009296,0.000000
16.210001,5.174866,-116.806976,-0.004445,0.000352,0.008932,23.018953,1.172641,0.089324,-116.806976,0.010068,0.000000
16.670000,5.490639,-116.718018,-0.004419,0.000377,0.009565,24.423580,1.244197,0.095652,-116.718018,0.010832,0.000000
17.130001,6.147125,-116.718018,-0.004381,0.000414,0.010519,27.343779,1.392958,0.105190,-116.718018,0.011603,0.000000
17.590000,6.582802,-116.718018,-0.004355,0.000446,0.011334,29.281765,1.491684,0.113342,-116.718018,0.012366,0.000000
18.050001,6.788353,-116.673538,-0.004329,0.000472,0.011984,30.196102,1.538263,0.119845,-116.673538,0.013130,0.000000
18.510000,7.055344,-116.762497,-0.004316,0.000496,0.012601,31.383736,1.598764,0.126007,-116.762497,0.013901,0.000000
18.970001,7.368134,-116.718018,-0.004268,0.000526,0.013364,32.775093,1.669643,0.133637,-116.718018,0.014664,0.000000
19.430000,7.648903,-116.762497,-0.004255,0.000558,0.014170,34.024021,1.733266,0.141699,-116.762497,0.015436,0.000000
19.890001,8.067078,-116.718018,-0.004234,0.000591,0.015020,35.884155,1.828026,0.150200,-116.718018,0.016199,0.000000
20.350000,8.379501,-116.762497,-0.004191,0.000620,0.015748,37.273884,1.898822,0.157482,-116.762497,0.016971,0.000000
20.810001,8.646866,-116.718018,-0.004165,0.000654,0.016607,38.463181,1.959408,0.166074,-116.718018,0.017735,0.000000
21.270000,8.798790,-116.673538,-0.004126,0.000678,0.017214,39.138973,1.993834,0.172145,-116.673538,0.018498,0.000000
21.730001,9.068016,-116.718018,-0.004105,0.000707,0.017968,40.336552,2.054842,0.179684,-116.718018,0.019270,0.000000
22.190001,9.364052,-116.673538,-0.004083,0.000740,0.018801,41.653381,2.121925,0.188011,-116.673538,0.020033,0.000000
22.650002,9.752068,-116.673538,-0.004044,0.000772,0.019616,43.379364,2.209850,0.196164,-116.673538,0.020804,0.000000
23.110001,9.801590,-116.718018,-0.004023,0.000799,0.020284,43.599651,2.221072,0.202840,-116.718018,0.021568,0.000000
23.570002,10.279716,-116.673538,-0.003984,0.000832,0.021142,45.726463,2.329417,0.211424,-116.673538,0.022331,0.000000
24.030001,10.523247,-116.673538,-0.003962,0.000863,0.021923,46.809738,2.384602,0.219229,-116.673538,0.023102,0.000000
24.490002,10.770134,-116.629051,-0.003928,0.000893,0.022678,47.907948,2.440547,0.226776,-116.629051,0.023866,0.000000
24.950001,10.841255,-116.673538,-0.003893,0.000920,0.023363,48.224312,2.456664,0.233626,-116.673538,0.024637,0.000000
25.410002,11.313049,-116.673538,-0.003872,0.000954,0.024230,50.322956,2.563574,0.242301,-116.673538,0.025400,0.000000
25.870001,11.587860,-116.629051,-0.003829,0.000989,0.025114,51.545376,2.625847,0.251143,-116.629051,0.026164,0.000000
26.330002,11.644089,-116.629051,-0.003816,0.001013,0.025721,51.795494,2.638588,0.257214,-116.629051,0.026936,0.000000
26.790001,11.971031,-116.584572,-0.003790,0.001046,0.026580,53.249805,2.712674,0.265798,-116.584572,0.027699,0.000000
27.250002,11.785591,-116.629051,-0.003764,0.001065,0.027057,52.424927,2.670653,0.270575,-116.629051,0.028471,0.000000
27.710001,12.685616,-116.673538,-0.003734,0.001108,0.028141,56.428436,2.874602,0.281415,-116.673538,0.029234,0.000000
28.170002,12.701256,-116.540092,-0.003695,0.001136,0.028852,56.498009,2.878146,0.288523,-116.540092,0.029997,0.000000
28.630001,13.012184,-116.629051,-0.003660,0.001167,0.029650,57.881084,2.948603,0.296501,-116.629051,0.030769,0.000000
29.090002,12.953720,-116.584572,-0.003652,0.001190,0.030214,57.621025,2.935355,0.302141,-116.584572,0.031532,0.000000
29.550001,13.053894,-116.584572,-0.003604,0.001215,0.030864,58.066620,2.958055,0.308643,-116.584572,0.032304,0.000000
30.010002,13.845932,-116.629051,-0.003587,0.001259,0.031983,61.589783,3.137533,0.319831,-116.629051,0.033067,0.000000
30.470001,13.491432,-116.584572,-0.003540,0.001278,0.032451,60.012886,3.057202,0.324509,-116.584572,0.033838,0.000000
30.930002,13.987427,-116.629051,-0.003523,0.001313,0.033344,62.219181,3.169596,0.333442,-116.629051,0.034602,0.000000
31.390001,14.543007,-116.629051,-0.003479,0.001353,0.034359,64.690529,3.295493,0.343593,-116.629051,0.035365,0.000000
31.850002,14.549339,-116.584572,-0.003454,0.001381,0.035070,64.718697,3.296927,0.350701,-116.584572,0.036137,0.000000
32.310001,14.697540,-116.584572,-0.003436,0.001405,0.035686,65.377922,3.330510,0.356863,-116.584572,0.036900,0.000000
32.770000,14.877769,-116.540092,-0.003393,0.001434,0.036423,66.179626,3.371351,0.364228,-116.540092,0.037672,0.000000
33.230003,15.247910,-116.540092,-0.003354,0.001465,0.037221,67.826088,3.455226,0.372207,-116.540092,0.038435,0.000000
33.690002,15.612465,-116.540092,-0.003341,0.001501,0.038123,69.447716,3.537835,0.381230,-116.540092,0.039198,0.000000
34.150002,15.150719,-116.540092,-0.003294,0.001521,0.038635,67.393761,3.433202,0.386347,-116.540092,0.039970,0.000000
34.610001,15.920044,-116.495613,-0.003272,0.001559,0.039606,70.815895,3.607534,0.396059,-116.495613,0.040733,0.000000
35.070004,15.667198,-116.540092,-0.003238,0.001578,0.040092,69.691177,3.550238,0.400919,-116.540092,0.041505,0.000000
35.530003,16.449181,-116.540092,-0.003221,0.001622,0.041193,73.169609,3.727437,0.411925,-116.540092,0.042268,0.000000
35.990002,16.961945,-116.495613,-0.003173,0.001658,0.042103,75.450500,3.843632,0.421032,-116.495613,0.043031,0.000000
36.450001,16.975716,-116.540092,-0.003139,0.001689,0.042910,75.511757,3.846752,0.429101,-116.540092,0.043803,0.000000
36.910000,17.045723,-116.495613,-0.003109,0.001716,0.043595,75.823166,3.862616,0.435952,-116.495613,0.044566,0.000000
37.370003,16.829002,-116.451126,-0.003078,0.001740,0.044193,74.859138,3.813507,0.441932,-116.451126,0.045339,0.000000
37.830002,17.601677,-116.540092,-0.003044,0.001775,0.045078,78.296173,3.988597,0.450781,-116.540092,0.046102,0.000000
38.290001,17.573006,-116.495613,-0.003014,0.001798,0.045668,78.168633,3.982100,0.456678,-116.495613,0.046873,0.000000
38.750000,18.177368,-116.540092,-0.002997,0.001836,0.046631,80.856972,4.119051,0.466307,-116.540092,0.047637,0.000000
39.210003,18.331902,-116.495613,-0.002966,0.001864,0.047341,81.544373,4.154068,0.473415,-116.495613,0.048400,0.000000
39.670002,18.140869,-116.406647,-0.002936,0.001889,0.047992,80.694618,4.110780,0.479917,-116.406647,0.049171,0.000000
40.130001,19.037544,-116.451126,-0.002906,0.001925,0.048885,84.683228,4.313969,0.488849,-116.451126,0.049935,0.000000
40.590000,18.894554,-116.495613,-0.002884,0.001947,0.049449,84.047173,4.281567,0.494489,-116.495613,0.050706,0.000000
41.050003,18.916153,-116.451126,-0.002859,0.001972,0.050099,84.143250,4.286461,0.500991,-116.451126,0.051469,0.000000
41.510002,19.846710,-116.451126,-0.002802,0.002014,0.051166,88.282578,4.497329,0.511657,-116.451126,0.052232,0.000000
41.970001,19.719734,-116.406647,-0.002764,0.002036,0.051712,87.717758,4.468555,0.517123,-116.406647,0.053004,0.000000
42.430000,20.381065,-116.451126,-0.002755,0.002071,0.052597,90.659508,4.618415,0.525972,-116.451126,0.053767,0.000000
42.890003,20.292816,-116.406647,-0.002716,0.002095,0.053213,90.266953,4.598418,0.532126,-116.406647,0.054540,0.000000
43.350002,21.172356,-116.451126,-0.002703,0.002136,0.054244,94.179344,4.797724,0.542444,-116.451126,0.055303,0.000000
43.810001,20.832382,-116.406647,-0.002656,0.002155,0.054730,92.667061,4.720685,0.547303,-116.406647,0.056066,0.000000
44.270000,21.543236,-116.406647,-0.002643,0.002189,0.055606,95.829102,4.881767,0.556062,-116.406647,0.056838,0.000000
44.730003,22.054878,-116.495613,-0.002613,0.002221,0.056421,98.104996,4.997707,0.564214,-116.495613,0.057601,0.000000
45.190002,22.515503,-116.362167,-0.002570,0.002254,0.057254,100.153961,5.102086,0.572541,-116.362167,0.058373,0.000000
45.650002,22.291710,-116.406647,-0.002557,0.002278,0.057870,99.158478,5.051374,0.578695,-116.406647,0.059136,0.000000
46.110001,23.093056,-116.317688,-0.002518,0.002310,0.058676,102.723045,5.232961,0.586765,-116.317688,0.059899,0.000000
46.570004,22.926231,-116.451126,-0.002483,0.002332,0.059240,101.980972,5.195158,0.592397,-116.451126,0.060671,0.000000
47.030003,24.321136,-116.406647,-0.002466,0.002376,0.060350,108.185822,5.511248,0.603501,-116.406647,0.061434,0.000000
47.490002,24.110001,-116.362167,-0.002436,0.002401,0.060983,107.246635,5.463404,0.609830,-116.362167,0.062206,0.000000
47.950001,24.361351,-116.406647,-0.002402,0.002425,0.061607,108.364700,5.520361,0.616075,-116.406647,0.062969,0.000000
48.410004,25.127693,-116.362167,-0.002376,0.002461,0.062509,111.773560,5.694016,0.625091,-116.362167,0.063741,0.000000
48.870003,25.896271,-116.362167,-0.002333,0.002494,0.063351,115.192368,5.868179,0.633508,-116.362167,0.064504,0.000000
49.330002,26.425415,-116.406647,-0.002320,0.002524,0.064114,117.546120,5.988084,0.641138,-116.406647,0.065267,0.000000
49.790001,26.903168,-116.273209,-0.002276,0.002557,0.064955,119.671265,6.096345,0.649549,-116.273209,0.066039,0.000000
50.250004,27.247612,-116.406647,-0.002238,0.002585,0.065649,121.203430,6.174397,0.656490,-116.406647,0.066802,0.000000
50.710003,27.039085,-116.273209,-0.002220,0.002603,0.066117,120.275856,6.127144,0.661168,-116.273209,0.067574,0.000000
51.170002,28.488358,-116.362167,-0.002190,0.002643,0.067140,126.722542,6.455554,0.671403,-116.362167,0.068337,0.000000
51.630001,28.865944,-116.362167,-0.002173,0.002673,0.067895,128.402130,6.541116,0.678950,-116.362167,0.069100,0.000000
52.090004,29.248741,-116.362167,-0.002130,0.002708,0.068771,130.104904,6.627859,0.687708,-116.362167,0.069872,0.000000
52.550003,30.615349,-116.362167,-0.002121,0.002741,0.069612,136.183868,6.937537,0.696118,-116.362167,0.070635,0.000000
53.010002,30.890160,-116.273209,-0.002074,0.002768,0.070314,137.406296,6.999810,0.703143,-116.273209,0.071407,0.000000
53.470001,30.702484,-116.273209,-0.002044,0.002789,0.070852,136.571472,6.957282,0.708517,-116.273209,0.072170,0.000000
53.930004,31.965569,-116.273209,-0.002039,0.002824,0.071737,142.189957,7.243502,0.717366,-116.273209,0.072933,0.000000
54.390003,32.849586,-116.362167,-0.001996,0.002858,0.072595,146.122253,7.443823,0.725950,-116.362167,0.073706,0.000000
54.850002,33.757797,-116.273209,-0.001970,0.002890,0.073419,150.162186,7.649626,0.734186,-116.273209,0.074469,0.000000
55.310001,34.158104,-116.273209,-0.001949,0.002915,0.074052,151.942841,7.740337,0.740522,-116.273209,0.075240,0.000000
55.770004,35.396240,-116.273209,-0.001936,0.002951,0.074945,157.450333,8.020903,0.749455,-116.273209,0.076003,0.000000
56.230003,35.471085,-116.362167,-0.001906,0.002975,0.075553,157.783264,8.037863,0.755526,-116.362167,0.076775,0.000000
56.690002,36.817589,-116.228722,-0.001871,0.003006,0.076341,163.772812,8.342985,0.763413,-116.228722,0.077538,0.000000
57.150002,38.220314,-116.273209,-0.001832,0.003044,0.077322,170.012451,8.660848,0.773216,-116.273209,0.078301,0.000000
57.610004,39.115494,-116.273209,-0.001819,0.003075,0.078093,173.994400,8.863698,0.780930,-116.273209,0.079073,0.000000
58.070004,39.172470,-116.228722,-0.001789,0.003100,0.078744,174.247849,8.876608,0.787440,-116.228722,0.079836,0.000000
58.530003,40.494019,-116.273209,-0.001776,0.003131,0.079524,180.126389,9.176076,0.795244,-116.273209,0.080608,0.000000
58.990002,41.685608,-116.184242,-0.001733,0.003164,0.080365,185.426849,9.446094,0.803654,-116.184242,0.081371,0.000000
59.450005,41.129662,-116.273209,-0.001725,0.003177,0.080686,182.953873,9.320114,0.806864,-116.273209,0.082134,0.000000
59.910004,43.423470,-116.139763,-0.001703,0.003219,0.081753,193.157242,9.839899,0.817530,-116.139763,0.082907,0.000000
60.370003,44.843704,-116.228722,-0.001664,0.003253,0.082620,199.474762,10.161729,0.826205,-116.228722,0.083670,0.000000
60.830002,45.402634,-116.184242,-0.001660,0.003279,0.083288,201.960999,10.288384,0.832881,-116.184242,0.084442,0.000000
61.290005,46.651939,-116.184242,-0.001621,0.003314,0.084172,207.518188,10.571481,0.841723,-116.184242,0.085205,0.000000
61.750004,46.605392,-116.184242,-0.001595,0.003325,0.084450,207.311142,10.560933,0.844501,-116.184242,0.085968,0.000000
62.210003,48.784149,-116.095284,-0.001578,0.003368,0.085551,217.002731,11.054646,0.855515,-116.095284,0.086740,0.000000
62.670002,50.735382,-116.139763,-0.001561,0.003402,0.086402,225.682251,11.496801,0.864016,-116.139763,0.087503,0.000000
63.130005,51.474541,-116.184242,-0.001544,0.003429,0.087104,228.970200,11.664297,0.871041,-116.184242,0.088274,0.000000
63.590004,52.750656,-116.139763,-0.001500,0.003454,0.087737,234.646637,11.953469,0.877369,-116.139763,0.089037,0.000000
64.050003,53.671165,-116.228722,-0.001505,0.003478,0.088335,238.741272,12.162060,0.883349,-116.228722,0.089809,0.000000
64.510002,56.395065,-116.139763,-0.001475,0.003521,0.089445,250.857773,12.779305,0.894454,-116.139763,0.090573,0.000000
64.970001,57.246307,-116.139763,-0.001449,0.003548,0.090122,254.644287,12.972199,0.901221,-116.139763,0.091336,0.000000
65.430000,59.026253,-116.139763,-0.001431,0.003579,0.090903,262.561890,13.375540,0.909026,-116.139763,0.092108,0.000000
65.889999,59.985107,-116.139763,-0.001418,0.003601,0.091475,266.827087,13.592819,0.914749,-116.139763,0.092871,0.000000
66.350006,61.678658,-116.139763,-0.001401,0.003637,0.092386,274.360382,13.976583,0.923855,-116.139763,0.093643,0.000000
66.810005,63.757988,-116.050804,-0.001367,0.003671,0.093235,283.609680,14.447767,0.932348,-116.050804,0.094406,0.000000
67.270004,64.986824,-116.095284,-0.001354,0.003694,0.093834,289.075836,14.726225,0.938336,-116.095284,0.095169,0.000000
67.730003,65.479469,-116.095284,-0.001341,0.003706,0.094137,291.267212,14.837860,0.941372,-116.095284,0.016527,0.000000
68.190002,64.682594,-116.050804,-0.001341,0.003717,0.094423,287.722534,14.657286,0.944233,-116.050804,294.500488,0.000000
68.650002,64.652794,-116.095284,-0.001332,0.003728,0.094692,287.589996,14.650533,0.946920,-116.095284,294.500488,0.000000
69.110001,66.392159,-116.050804,-0.001281,0.003572,0.090720,295.327057,15.044678,0.907201,-116.050804,294.500488,0.000000
69.570000,65.232582,-116.050804,-0.001272,0.003680,0.093460,290.169006,14.781914,0.934604,-116.050804,294.500488,0.000000
70.030006,65.221779,-116.050804,-0.001285,0.003757,0.095429,290.120972,14.779467,0.954293,-116.050804,294.500488,0.000000
70.490005,65.156990,-116.050804,-0.001272,0.003766,0.095655,289.832764,14.764785,0.956549,-116.050804,294.500488,0.000000
70.950005,65.101509,-116.050804,-0.001272,0.003773,0.095828,289.585968,14.752213,0.958282,-116.050804,294.500488,0.000000
71.410004,65.612038,-116.006317,-0.001276,0.003785,0.096132,291.856934,14.867900,0.961318,-116.006317,294.500488,0.000000
71.870003,64.989799,-116.050804,-0.001281,0.003785,0.096149,289.089081,14.726899,0.961492,-116.050804,294.500488,0.000000
72.330002,64.434593,-116.095284,-0.001276,0.003786,0.096158,286.619385,14.601088,0.961575,-116.095284,294.500488,0.000000
72.790001,65.880882,-116.050804,-0.001255,0.003799,0.096488,293.052795,14.928821,0.964876,-116.050804,294.500488,0.000000
73.250000,65.297752,-116.050804,-0.001250,0.003799,0.096496,290.458923,14.796682,0.964959,-116.050804,294.500488,0.000000
73.710007,64.726906,-116.050804,-0.001255,0.003799,0.096504,287.919647,14.667326,0.965042,-116.050804,294.500488,0.000000
74.170006,66.267036,-115.917358,-0.001237,0.003816,0.096938,294.770508,15.016325,0.969380,-115.917358,294.500488,0.000000
74.630005,65.724495,-116.050804,-0.001237,0.003816,0.096938,292.357147,14.893383,0.969380,-116.050804,294.500488,0.000000
75.090004,65.232948,-115.917358,-0.001233,0.003816,0.096938,290.170654,14.781998,0.969380,-115.917358,294.500488,0.000000
75.550003,65.018837,-116.006317,-0.001233,0.003826,0.097173,289.218231,14.733479,0.971726,-116.006317,294.500488,0.000000
76.010002,64.769722,-115.917358,-0.001233,0.003826,0.097181,288.110107,14.677029,0.971810,-115.917358,294.500488,0.000000
76.470001,65.649269,-116.006317,-0.001212,0.003839,0.097502,292.022522,14.876337,0.975019,-116.006317,294.500488,0.000000
76.930000,65.320457,-115.961838,-0.001224,0.003839,0.097502,290.559906,14.801826,0.975019,-115.961838,294.500488,0.000000
77.390007,65.009163,-115.917358,-0.001216,0.003840,0.097537,289.175201,14.731286,0.975367,-115.917358,294.500488,0.000000
77.850006,65.245247,-116.006317,-0.001224,0.003851,0.097814,290.225342,14.784784,0.978138,-116.006317,294.500488,0.000000
78.310005,65.377434,-115.917358,-0.001229,0.003849,0.097771,290.813354,14.814738,0.977706,-115.917358,294.500488,0.000000
78.770004,65.079536,-115.917358,-0.001216,0.003849,0.097771,289.488251,14.747233,0.977706,-115.917358,294.500488,0.000000
79.230003,64.820000,-115.961838,-0.001216,0.003849,0.097771,288.333771,14.688422,0.977706,-115.961838,294.500488,0.000000
79.690002,65.272804,-115.872879,-0.001203,0.003857,0.097979,290.347931,14.791029,0.979788,-115.872879,294.500488,0.000000
80.150002,65.073204,-115.917358,-0.001212,0.003858,0.097996,289.460083,14.745798,0.979962,-115.917358,294.500488,0.000000
80.610001,64.909737,-115.872879,-0.001207,0.003858,0.097996,288.732941,14.708756,0.979962,-115.872879,294.500488,0.000000
81.070007,64.680351,-115.917358,-0.001203,0.003858,0.098005,287.712585,14.656777,0.980046,-115.917358,294.500488,0.000000
81.530006,65.313759,-115.917358,-0.001216,0.003868,0.098248,290.530121,14.800309,0.982475,-115.917358,294.500488,0.000000
81.990005,65.202415,-115.917358,-0.001199,0.003868,0.098248,290.034821,14.775078,0.982475,-115.917358,294.500488,0.000000
82.450005,65.012138,-115.917358,-0.001199,0.003868,0.098257,289.188446,14.731961,0.982566,-115.917358,294.500488,0.000000
82.910004,64.816643,-115.872879,-0.001203,0.003868,0.098257,288.318817,14.687661,0.982566,-115.872879,294.500488,0.000000
83.370003,65.180824,-115.872879,-0.001199,0.003876,0.098447,289.938782,14.770185,0.984474,-115.872879,294.500488,0.000000
83.830002,65.101875,-115.917358,-0.001199,0.003876,0.098438,289.587616,14.752295,0.984383,-115.917358,294.500488,0.000000
84.290001,64.976387,-115.783913,-0.001194,0.003876,0.098438,289.029419,14.723860,0.984383,-115.783913,294.500488,0.000000
84.750008,64.807701,-115.917358,-0.001186,0.003876,0.098447,288.279053,14.685635,0.984474,-115.917358,294.500488,0.000000
85.210007,64.660622,-115.783913,-0.001212,0.003876,0.098447,287.624817,14.652307,0.984474,-115.783913,294.500488,0.000000
85.670006,64.494164,-115.783913,-0.001199,0.003876,0.098456,286.884369,14.614587,0.984557,-115.783913,294.500488,0.000000
86.130005,65.900246,-115.828400,-0.001181,0.003881,0.098577,293.138947,14.933208,0.985768,-115.828400,294.500488,0.000000
86.590004,65.673851,-115.828400,-0.001177,0.003881,0.098577,292.131866,14.881907,0.985768,-115.828400,294.500488,0.000000
87.050003,65.502174,-115.872879,-0.001181,0.003881,0.098577,291.368225,14.843005,0.985768,-115.872879,294.500488,0.000000
87.510002,65.311897,-115.828400,-0.001186,0.003881,0.098586,290.521820,14.799888,0.985859,-115.828400,294.500488,0.000000
87.970001,65.145821,-115.828400,-0.001181,0.003881,0.098586,289.783081,14.762254,0.985859,-115.828400,294.500488,0.000000
88.430008,64.980110,-115.783913,-0.001173,0.003881,0.098586,289.045959,14.724703,0.985859,-115.783913,294.500488,0.000000
88.890007,64.832649,-115.739433,-0.001173,0.003882,0.098612,288.390015,14.691288,0.986117,-115.739433,294.500488,0.000000
89.350006,64.698235,-115.828400,-0.001173,0.003883,0.098629,287.792114,14.660830,0.986291,-115.828400,294.500488,0.000000
89.810005,64.542198,-115.739433,-0.001186,0.003883,0.098629,287.098022,14.625471,0.986291,-115.739433,294.500488,0.000000
90.270004,64.392143,-115.739433,-0.001168,0.003883,0.098629,286.430573,14.591468,0.986291,-115.739433,294.500488,0.000000
90.730003,66.550789,-115.783913,-0.001164,0.003848,0.097745,296.032684,15.080625,0.977449,-115.783913,294.500488,0.000000
91.190002,66.343376,-115.783913,-0.001155,0.003848,0.097745,295.110077,15.033624,0.977449,-115.783913,294.500488,0.000000
91.650002,66.183617,-115.783913,-0.001164,0.003848,0.097745,294.399445,14.997422,0.977449,-115.783913,294.500488,0.000000
92.110001,66.032814,-115.739433,-0.001155,0.003848,0.097745,293.728638,14.963250,0.977449,-115.739433,294.500488,0.000000
92.570007,65.898018,-115.694954,-0.001155,0.003849,0.097762,293.129028,14.932705,0.977623,-115.694954,294.500488,0.000000
93.030006,65.764702,-115.739433,-0.001155,0.003849,0.097771,292.536011,14.902494,0.977706,-115.739433,294.500488,0.000000
93.490005,65.597130,-115.783913,-0.001151,0.003854,0.097901,291.790619,14.864522,0.979008,-115.783913,294.500488,0.000000
93.950005,65.510750,-115.694954,-0.001164,0.003860,0.098048,291.406372,14.844948,0.980485,-115.694954,294.500488,0.000000
94.410004,65.353600,-115.739433,-0.001168,0.003861,0.098066,290.707336,14.809338,0.980659,-115.739433,294.500488,0.000000
94.870003,65.281731,-115.694954,-0.001155,0.003869,0.098282,290.387634,14.793052,0.982824,-115.694954,294.500488,0.000000
95.330002,65.194969,-115.739433,-0.001155,0.003877,0.098473,290.001709,14.773392,0.984731,-115.739433,294.500488,0.000000
95.790001,65.105232,-115.650475,-0.001151,0.003882,0.098594,289.602539,14.753057,0.985942,-115.650475,294.500488,0.000000
96.250008,65.090340,-115.739433,-0.001155,0.003898,0.099002,289.536285,14.749682,0.990023,-115.739433,294.500488,0.000000
96.710007,65.025551,-115.650475,-0.001160,0.003900,0.099054,289.248108,14.735001,0.990545,-115.650475,294.500488,0.000000
97.170006,65.355461,-115.650475,-0.001151,0.003909,0.099288,290.715607,14.809759,0.992884,-115.650475,294.500488,0.000000
97.630005,65.344292,-115.739433,-0.001143,0.003909,0.099288,290.665924,14.807228,0.992884,-115.739433,294.500488,0.000000
98.090004,65.292900,-115.650475,-0.001155,0.003909,0.099288,290.437317,14.795583,0.992884,-115.650475,294.500488,0.000000
98.550003,65.238914,-115.694954,-0.001151,0.003909,0.099288,290.197174,14.783349,0.992884,-115.694954,294.500488,0.000000
99.010002,65.145454,-115.605995,-0.001151,0.003909,0.099288,289.781464,14.762171,0.992884,-115.605995,294.500488,0.000000
99.470001,65.074699,-115.650475,-0.001143,0.003909,0.099297,289.466705,14.746138,0.992967,-115.650475,294.500488,0.000000
99.930008,64.999474,-115.650475,-0.001151,0.003909,0.099297,289.132111,14.729092,0.992967,-115.650475,294.500488,0.000000
100.390007,64.926872,-115.650475,-0.001147,0.003909,0.099297,288.809143,14.712640,0.992967,-115.650475,294.500488,0.000000
100.850006,64.837868,-115.605995,-0.001143,0.003909,0.099297,288.413239,14.692471,0.992967,-115.605995,294.500488,0.000000
101.310005,65.409828,-115.605995,-0.001160,0.003918,0.099522,290.957458,14.822079,0.995223,-115.605995,294.500488,0.000000
101.770004,65.385994,-115.561508,-0.001147,0.003918,0.099522,290.851440,14.816678,0.995223,-115.561508,294.500488,0.000000
102.230003,65.329033,-115.650475,-0.001147,0.003918,0.099522,290.598053,14.803770,0.995223,-115.650475,294.500488,0.000000
102.690002,65.272804,-115.605995,-0.001151,0.003918,0.099522,290.347931,14.791029,0.995223,-115.605995,294.500488,0.000000
103.150002,65.211723,-115.561508,-0.001147,0.003918,0.099522,290.076233,14.777188,0.995223,-115.561508,294.500488,0.000000
103.610008,65.133156,-115.605995,-0.001160,0.003918,0.099522,289.726746,14.759384,0.995223,-115.605995,294.500488,0.000000
104.070007,65.069481,-115.605995,-0.001160,0.003919,0.099531,289.443512,14.744955,0.995314,-115.605995,294.500488,0.000000
104.530006,65.167046,-115.561508,-0.001143,0.003921,0.099592,289.877502,14.767064,0.995919,-115.561508,294.500488,0.000000
104.990005,65.149910,-115.605995,-0.001151,0.003922,0.099609,289.801270,14.763181,0.996094,-115.605995,294.500488,0.000000
105.450005,65.122734,-115.561508,-0.001155,0.003922,0.099609,289.680389,14.757022,0.996094,-115.561508,294.500488,0.000000
105.910004,65.065392,-115.517029,-0.001168,0.003922,0.099609,289.425323,14.744028,0.996094,-115.517029,294.500488,0.000000
106.370003,65.021446,-115.472549,-0.001151,0.003922,0.099609,289.229828,14.734070,0.996094,-115.472549,294.500488,0.000000
106.830002,64.983101,-115.517029,-0.001155,0.003923,0.099635,289.059265,14.725381,0.996351,-115.517029,294.500488,0.000000
107.290009,64.940269,-115.472549,-0.001138,0.003923,0.099635,288.868744,14.715675,0.996351,-115.472549,294.500488,0.000000
107.750008,64.884422,-115.517029,-0.001143,0.003923,0.099635,288.620331,14.703020,0.996351,-115.517029,294.500488,0.000000
108.210007,65.578148,-115.472549,-0.001151,0.003932,0.099861,291.706177,14.860221,0.998607,-115.472549,294.500488,0.000000
108.670006,65.574791,-115.472549,-0.001138,0.003932,0.099861,291.691223,14.859460,0.998607,-115.472549,294.500488,0.000000
109.130005,65.552818,-115.517029,-0.001151,0.003932,0.099861,291.593506,14.854481,0.998607,-115.517029,294.500488,0.000000
109.590004,65.513359,-115.428070,-0.001134,0.003932,0.099861,291.417969,14.845539,0.998607,-115.428070,294.500488,0.000000
110.050003,65.462715,-115.517029,-0.001147,0.003932,0.099861,291.192688,14.834064,0.998607,-115.517029,294.500488,0.000000
110.510002,65.388237,-115.517029,-0.001138,0.003932,0.099861,290.861420,14.817186,0.998607,-115.517029,294.500488,0.000000
110.970009,65.341316,-115.472549,-0.001143,0.003932,0.099861,290.652679,14.806554,0.998607,-115.472549,294.500488,0.000000
111.430008,65.290672,-115.472549,-0.001134,0.003932,0.099861,290.427429,14.795078,0.998607,-115.472549,294.500488,0.000000
111.890007,65.249718,-115.428070,-0.001138,0.003932,0.099861,290.245239,14.785798,0.998607,-115.428070,294.500488,0.000000
112.350006,65.190880,-115.428070,-0.001147,0.003932,0.099861,289.983521,14.772465,0.998607,-115.428070,294.500488,0.000000
112.810005,65.124229,-115.472549,-0.001164,0.003932,0.099861,289.687042,14.757361,0.998607,-115.472549,294.500488,0.000000
113.270004,65.059807,-115.428070,-0.001147,0.003932,0.099870,289.400482,14.742763,0.998698,-115.428070,294.500488,0.000000
113.730003,65.013252,-115.472549,-0.001143,0.003932,0.099870,289.193390,14.732214,0.998698,-115.472549,294.500488,0.000000
114.190002,64.972664,-115.428070,-0.001151,0.003932,0.099870,289.012848,14.723016,0.998698,-115.428070,294.500488,0.000000
114.650009,64.924263,-115.294624,-0.001125,0.003932,0.099870,288.797546,14.712049,0.998698,-115.294624,294.500488,0.000000
115.110008,64.870644,-115.383591,-0.001143,0.003932,0.099870,288.559021,14.699898,0.998698,-115.383591,294.500488,0.000000
115.570007,65.267220,-115.383591,-0.001147,0.003938,0.100026,290.323090,14.789763,1.000257,-115.383591,294.500488,0.000000
116.030006,65.264229,-115.383591,-0.001134,0.003938,0.100026,290.309784,14.789085,1.000257,-115.383591,294.500488,0.000000
116.490005,65.258644,-115.383591,-0.001147,0.003938,0.100026,290.284943,14.787820,1.000257,-115.383591,294.500488,0.000000
116.950005,65.190498,-115.294624,-0.001013,0.003938,0.100026,289.981812,14.772378,1.000257,-115.294624,294.500488,0.000000
117.410004,65.188637,-115.383591,-0.001005,0.003938,0.100026,289.973541,14.771956,1.000257,-115.383591,294.500488,0.000000
117.870003,65.109322,-115.383591,-0.001013,0.003938,0.100026,289.620728,14.753983,1.000257,-115.383591,294.500488,0.000000
118.330002,65.091087,-115.339104,-0.001000,0.003938,0.100034,289.539612,14.749851,1.000340,-115.339104,294.500488,0.000000
118.790009,65.039696,-115.339104,-0.001022,0.003938,0.100034,289.311005,14.738206,1.000340,-115.339104,294.500488,0.000000
119.250008,65.009529,-115.294624,-0.001013,0.003938,0.100034,289.176819,14.731370,1.000340,-115.294624,294.500488,0.000000
119.710007,64.964470,-115.383591,-0.001000,0.003938,0.100034,288.976410,14.721160,1.000340,-115.383591,294.500488,0.000000
120.170006,64.938408,-115.294624,-0.001000,0.003938,0.100034,288.860474,14.715253,1.000340,-115.294624,294.500488,0.000000
120.630005,64.887764,-115.294624,-0.001009,0.003938,0.100034,288.635193,14.703777,1.000340,-115.294624,294.500488,0.000000
121.090004,64.831917,-115.294624,-0.001013,0.003938,0.100034,288.386780,14.691123,1.000340,-115.294624,294.500488,0.000000
121.550003,64.791328,-115.294624,-0.001000,0.003938,0.100034,288.206238,14.681926,1.000340,-115.294624,294.500488,0.000000
122.010002,65.332008,-115.383591,-0.001005,0.003946,0.100225,290.611298,14.804445,1.002248,-115.383591,294.500488,0.000000
122.470009,65.361794,-115.294624,-0.001013,0.003946,0.100225,290.743774,14.811193,1.002248,-115.294624,294.500488,0.000000
122.930008,65.339455,-115.250145,-0.001005,0.003946,0.100225,290.644409,14.806131,1.002248,-115.250145,294.500488,0.000000
123.390007,65.326790,-115.294624,-0.001026,0.003946,0.100225,290.588074,14.803262,1.002248,-115.294624,294.500488,0.000000
123.850006,65.294395,-115.250145,-0.001009,0.003946,0.100225,290.443970,14.795921,1.002248,-115.250145,294.500488,0.000000
124.310005,65.282112,-115.339104,-0.001013,0.003946,0.100225,290.389343,14.793138,1.002248,-115.339104,294.500488,0.000000
124.770004,65.253441,-115.250145,-0.001013,0.003946,0.100225,290.261810,14.786641,1.002248,-115.250145,294.500488,0.000000
125.230003,65.215462,-115.294624,-0.000996,0.003946,0.100225,290.092865,14.778035,1.002248,-115.294624,294.500488,0.000000
125.690002,65.166298,-115.294624,-0.001009,0.003946,0.100225,289.874176,14.766894,1.002248,-115.294624,294.500488,0.000000
126.150009,65.117516,-115.294624,-0.001000,0.003946,0.100225,289.657166,14.755840,1.002248,-115.294624,294.500488,0.000000
126.610008,65.103371,-115.205666,-0.001009,0.003946,0.100234,289.594269,14.752634,1.002339,-115.205666,294.500488,0.000000
127.070007,65.046776,-115.294624,-0.001009,0.003946,0.100234,289.342499,14.739810,1.002339,-115.294624,294.500488,0.000000
127.530006,65.045647,-115.205666,-0.001009,0.003946,0.100234,289.337494,14.739554,1.002339,-115.205666,294.500488,0.000000
127.990005,64.990166,-115.294624,-0.001013,0.003946,0.100234,289.090698,14.726981,1.002339,-115.294624,294.500488,0.000000
128.450012,64.952553,-115.161179,-0.001018,0.003942,0.100121,288.923370,14.718459,1.001211,-115.161179,0.099965,0.000000
128.910004,64.913826,-115.161179,-0.001009,0.003919,0.099531,288.751129,14.709682,0.995314,-115.161179,0.099201,0.000000
129.370010,64.708656,-115.250145,-0.001018,0.003896,0.098959,287.838470,14.663191,0.989591,-115.250145,0.098430,0.000000
129.830002,64.615562,-115.161179,-0.000996,0.003864,0.098135,287.424377,14.642096,0.981348,-115.161179,0.097667,0.000000
130.290009,64.570503,-115.205666,-0.001009,0.003835,0.097415,287.223938,14.631886,0.974149,-115.205666,0.096895,0.000000
130.750000,64.555244,-115.205666,-0.001013,0.003807,0.096695,287.156067,14.628428,0.966950,-115.205666,0.096132,0.000000
131.210007,64.500877,-115.161179,-0.001005,0.003780,0.096002,286.914246,14.616108,0.960016,-115.161179,0.095369,0.000000
131.670013,64.421181,-115.161179,-0.001000,0.003747,0.095186,286.559723,14.598048,0.951863,-115.161179,0.094597,0.000000
132.130005,64.248405,-115.116699,-0.001009,0.003718,0.094441,285.791168,14.558897,0.944407,-115.116699,0.093834,0.000000
132.590012,63.333488,-115.205666,-0.001005,0.003688,0.093686,281.721436,14.351574,0.936860,-115.205666,0.093061,0.000000
133.050003,62.269989,-115.161179,-0.001013,0.003664,0.093061,276.990753,14.110581,0.930615,-115.161179,0.092298,0.000000
133.510010,60.806190,-115.161179,-0.001009,0.003638,0.092394,270.479431,13.778879,0.923938,-115.161179,0.091526,0.000000
133.970001,59.046730,-115.161179,-0.001005,0.003607,0.091613,262.652985,13.380180,0.916134,-115.161179,0.090763,0.000000
134.430008,56.676956,-115.161179,-0.000996,0.003579,0.090903,252.111694,12.843182,0.909026,-115.161179,0.090000,0.000000
134.889999,54.154503,-115.161179,-0.001005,0.003548,0.090122,240.891266,12.271586,0.901221,-115.161179,0.089228,0.000000
135.350006,51.825684,-115.161179,-0.001018,0.003525,0.089532,230.532150,11.743868,0.895317,-115.161179,0.088465,0.000000
135.810013,49.178490,-115.116699,-0.001005,0.003495,0.088769,218.756851,11.144006,0.887687,-115.116699,0.087694,0.000000
136.270004,46.706306,-115.116699,-0.001000,0.003475,0.088274,207.760025,10.583800,0.882743,-115.116699,0.086931,0.000000
136.730011,42.332047,-115.072220,-0.001000,0.003431,0.087147,188.302353,9.592579,0.871472,-115.072220,0.086167,0.000000
137.190002,39.240242,-115.116699,-0.001000,0.003402,0.086419,174.549316,8.891966,0.864190,-115.116699,0.085396,0.000000
137.650009,37.591003,-115.116699,-0.001013,0.003391,0.086124,167.213135,8.518244,0.861238,-115.116699,0.084633,0.000000
138.110001,33.195892,-115.116699,-0.001000,0.003349,0.085075,147.662704,7.522297,0.850746,-115.116699,0.083860,0.000000
138.570007,29.793152,-115.161179,-0.001009,0.003316,0.084225,132.526566,6.751225,0.842245,-115.161179,0.083097,0.000000
139.030014,26.669693,-115.027740,-0.001000,0.003288,0.083514,118.632721,6.043439,0.835137,-115.027740,0.082334,0.000000
139.490005,23.095291,-115.072220,-0.000996,0.003255,0.082689,102.732986,5.233468,0.826894,-115.072220,0.081562,0.000000
139.950012,19.729416,-115.116699,-0.001018,0.003222,0.081848,87.760826,4.470749,0.818484,-115.116699,0.080799,0.000000
140.410004,17.718605,-115.027740,-0.001005,0.003201,0.081293,78.816292,4.015093,0.812935,-115.027740,0.080027,0.000000
140.870010,12.992447,-115.072220,-0.001005,0.003161,0.080296,57.793289,2.944130,0.802958,-115.072220,0.079264,0.000000
141.330002,10.880730,-115.072220,-0.001009,0.003141,0.079793,48.399902,2.465609,0.797932,-115.072220,0.078492,0.000000
141.790009,6.682968,-115.027740,-0.001013,0.003104,0.078830,29.727327,1.514382,0.788303,-115.027740,0.077729,0.000000
142.250000,4.180626,-115.072220,-0.001026,0.003073,0.078042,18.596354,0.947343,0.780415,-115.072220,0.076966,0.000000
142.710007,0.253960,-115.027740,-0.001026,0.003040,0.077209,1.129669,0.057548,0.772088,-115.027740,0.076194,0.000000
143.170013,-1.827229,-115.072220,-0.001013,0.003015,0.076576,-8.127918,-0.414056,0.765760,-115.072220,0.075431,0.000000
143.630005,-4.845306,-115.027740,-0.001026,0.002981,0.075708,-21.552999,-1.097962,0.757085,-115.027740,0.074659,0.000000
144.090012,-0.580528,-114.983261,-0.001112,0.002953,0.075006,-2.582319,-0.131550,0.750060,-114.983261,0.073896,0.000000
144.550003,-0.532120,-115.116699,-0.001155,0.002916,0.074078,-2.366987,-0.120580,0.740780,-115.116699,0.073132,0.000000
145.010010,-0.474396,-115.027740,-0.001168,0.002894,0.073497,-2.110218,-0.107500,0.734974,-115.027740,0.072361,0.000000
145.470001,-0.473656,-115.027740,-0.001224,0.002866,0.072803,-2.106926,-0.107332,0.728032,-115.027740,0.071598,0.000000
145.930008,-0.526535,-114.983261,-0.001255,0.002828,0.071832,-2.342145,-0.119315,0.718320,-114.983261,0.070826,0.000000
146.389999,-0.553345,-115.027740,-0.001289,0.002798,0.071077,-2.461400,-0.125390,0.710773,-115.027740,0.070063,0.000000
146.850006,-0.526161,-114.983261,-0.001328,0.002772,0.070410,-2.340482,-0.119230,0.704096,-114.983261,0.069300,0.000000
147.310013,-0.519081,-114.938774,-0.001380,0.002740,0.069603,-2.308988,-0.117625,0.696035,-114.938774,0.068528,0.000000
147.770004,-0.534721,-114.983261,-0.001397,0.002710,0.068823,-2.378559,-0.121170,0.688230,-114.983261,0.067765,0.000000
148.230011,-0.532486,-114.983261,-0.001449,0.002675,0.067956,-2.368616,-0.120663,0.679555,-114.983261,0.066993,0.000000
148.690002,-0.551483,-114.938774,-0.001462,0.002649,0.067288,-2.453120,-0.124968,0.672879,-114.938774,0.066230,0.000000
149.150009,-0.524300,-114.983261,-0.001492,0.002623,0.066629,-2.332201,-0.118808,0.666285,-114.983261,0.065457,0.000000
149.610001,-0.536217,-114.894295,-0.001539,0.002590,0.065778,-2.385211,-0.121508,0.657784,-114.894295,0.064694,0.000000
150.070007,-0.527275,-114.938774,-0.001569,0.002561,0.065059,-2.345437,-0.119482,0.650586,-114.938774,0.063931,0.000000
150.530014,-0.530624,-114.938774,-0.001617,0.002524,0.064114,-2.360335,-0.120241,0.641138,-114.938774,0.063160,0.000000
150.990005,-0.539940,-114.849815,-0.001647,0.002494,0.063342,-2.401772,-0.122352,0.633417,-114.849815,0.062396,0.000000
151.450012,-0.535469,-114.938774,-0.001677,0.002464,0.062596,-2.381885,-0.121339,0.625961,-114.938774,0.061625,0.000000
151.910004,-0.535469,-114.894295,-0.001707,0.002436,0.061876,-2.381885,-0.121339,0.618762,-114.894295,0.060862,0.000000
152.370010,-0.531746,-114.894295,-0.001738,0.002403,0.061035,-2.365324,-0.120495,0.610352,-114.894295,0.060098,0.000000
152.830002,-0.562279,-114.894295,-0.001768,0.002373,0.060281,-2.501141,-0.127414,0.602805,-114.894295,0.059327,0.000000
153.290009,-0.559303,-114.894295,-0.001785,0.002348,0.059639,-2.487905,-0.126740,0.596386,-114.894295,0.058564,0.000000
153.750000,-0.572334,-114.938774,-0.001837,0.002315,0.058789,-2.545870,-0.129693,0.587893,-114.938774,0.057792,0.000000
154.210007,-0.557808,-114.849815,-0.001863,0.002280,0.057913,-2.481254,-0.126401,0.579127,-114.849815,0.057029,0.000000
154.670013,-0.566002,-114.894295,-0.001888,0.002250,0.057150,-2.517702,-0.128258,0.571496,-114.894295,0.056265,0.000000
155.130005,-0.557808,-114.894295,-0.001919,0.002230,0.056630,-2.481254,-0.126401,0.566296,-114.894295,0.055493,0.000000
155.590012,-0.554832,-114.805336,-0.001953,0.002192,0.055667,-2.468018,-0.125727,0.556667,-114.805336,0.054730,0.000000
156.050003,-0.587975,-114.805336,-0.001988,0.002163,0.054939,-2.615441,-0.133237,0.549385,-114.805336,0.053958,0.000000
156.510010,-0.569351,-114.894295,-0.002026,0.002134,0.054201,-2.532601,-0.129017,0.542012,-114.894295,0.053195,0.000000
156.970001,-0.566376,-114.849815,-0.002052,0.002103,0.053412,-2.519365,-0.128343,0.534124,-114.849815,0.052432,0.000000
157.430008,-0.569725,-114.894295,-0.002087,0.002077,0.052761,-2.534264,-0.129102,0.527614,-114.894295,0.051660,0.000000
157.890015,-0.571213,-114.849815,-0.002126,0.002044,0.051930,-2.540881,-0.129439,0.519295,-114.849815,0.050897,0.000000
158.350006,-0.563400,-114.849815,-0.002156,0.002012,0.051105,-2.506130,-0.127668,0.511052,-114.849815,0.050126,0.000000
158.810013,-0.562279,-114.805336,-0.002177,0.001984,0.050385,-2.501141,-0.127414,0.503853,-114.805336,0.049362,0.000000
159.270004,-0.544037,-114.849815,-0.002207,0.001960,0.049778,-2.419997,-0.123281,0.497782,-114.849815,0.048590,0.000000
159.730011,-0.554832,-114.849815,-0.002229,0.001931,0.049058,-2.468018,-0.125727,0.490583,-114.849815,0.047827,0.000000
160.190002,-0.549248,-114.849815,-0.002281,0.001891,0.048044,-2.443176,-0.124461,0.480439,-114.849815,0.047064,0.000000
160.650009,-0.540306,-114.805336,-0.002315,0.001862,0.047298,-2.403402,-0.122435,0.472983,-114.805336,0.046292,0.000000
161.110001,-0.570099,-114.716370,-0.002363,0.001833,0.046569,-2.535926,-0.129186,0.465693,-114.716370,0.045529,0.000000
161.570007,-0.569351,-114.805336,-0.002367,0.001811,0.045997,-2.532601,-0.129017,0.459971,-114.805336,0.044757,0.000000
162.030014,-0.553719,-114.805336,-0.002410,0.001770,0.044957,-2.463063,-0.125474,0.449570,-114.805336,0.043994,0.000000
162.490005,-0.523178,-114.671890,-0.002440,0.001746,0.044350,-2.327212,-0.118554,0.443499,-114.671890,0.043231,0.000000
162.950012,-0.548500,-114.760857,-0.002471,0.001712,0.043491,-2.439850,-0.124292,0.434907,-114.760857,0.042459,0.000000
163.410004,-0.544403,-114.760857,-0.002505,0.001688,0.042875,-2.421626,-0.123363,0.428753,-114.760857,0.041696,0.000000
163.870010,-0.538078,-114.716370,-0.002544,0.001650,0.041904,-2.393492,-0.121930,0.419041,-114.716370,0.040924,0.000000
164.330002,-0.511635,-114.805336,-0.002565,0.001624,0.041254,-2.275865,-0.115938,0.412538,-114.805336,0.040161,0.000000
164.790009,-0.499352,-114.716370,-0.002587,0.001596,0.040534,-2.221226,-0.113155,0.405340,-114.716370,0.039398,0.000000
165.250015,-0.533981,-114.671890,-0.002608,0.001561,0.039658,-2.375268,-0.121002,0.396581,-114.671890,0.038626,0.000000
165.710007,-0.517967,-114.760857,-0.002669,0.001526,0.038756,-2.304033,-0.117373,0.387558,-114.760857,0.037863,0.000000
166.170013,-0.497116,-114.671890,-0.002673,0.001500,0.038088,-2.211283,-0.112648,0.380882,-114.671890,0.037091,0.000000
166.630005,-0.501213,-114.671890,-0.002721,0.001470,0.037343,-2.229507,-0.113577,0.373425,-114.671890,0.036327,0.000000
167.090012,-0.513870,-114.716370,-0.002759,0.001440,0.036588,-2.285809,-0.116445,0.365878,-114.716370,0.035556,0.000000
167.550003,-0.512383,-114.716370,-0.002772,0.001411,0.035833,-2.279191,-0.116108,0.358331,-114.716370,0.034793,0.000000
168.010010,-0.542542,-114.716370,-0.002811,0.001381,0.035070,-2.413345,-0.122942,0.350701,-114.716370,0.034029,0.000000
168.470001,-0.538078,-114.671890,-0.002846,0.001360,0.034550,-2.393492,-0.121930,0.345500,-114.671890,0.033258,0.000000
168.930008,-0.504936,-114.716370,-0.002880,0.001325,0.033665,-2.246068,-0.114420,0.336651,-114.716370,0.032495,0.000000
169.390015,-0.530998,-114.671890,-0.002910,0.001288,0.032703,-2.361998,-0.120326,0.327030,-114.671890,0.031723,0.000000
169.850006,-0.520203,-114.671890,-0.002936,0.001256,0.031905,-2.313977,-0.117880,0.319052,-114.671890,0.030960,0.000000
170.310013,-0.528763,-114.716370,-0.002971,0.001228,0.031194,-2.352055,-0.119819,0.311936,-114.716370,0.030197,0.000000
170.770004,-0.555946,-114.627411,-0.002997,0.001203,0.030561,-2.472973,-0.125979,0.305608,-114.627411,0.029425,0.000000
171.230011,-0.552223,-114.760857,-0.003027,0.001167,0.029642,-2.456412,-0.125136,0.296418,-114.760857,0.028661,0.000000
171.690002,-0.515732,-114.671890,-0.003074,0.001135,0.028817,-2.294090,-0.116866,0.288174,-114.671890,0.027889,0.000000
172.150009,-0.532120,-114.671890,-0.003083,0.001108,0.028150,-2.366987,-0.120580,0.281498,-114.671890,0.027126,0.000000
172.610001,-0.516853,-114.671890,-0.003130,0.001080,0.027430,-2.299078,-0.117121,0.274299,-114.671890,0.026363,0.000000
173.070007,-0.516853,-114.627411,-0.003147,0.001047,0.026589,-2.299078,-0.117121,0.265889,-114.627411,0.025591,0.000000
173.530014,-0.549248,-114.716370,-0.003191,0.001015,0.025774,-2.443176,-0.124461,0.257736,-114.716370,0.024828,0.000000
173.990005,-0.583878,-114.627411,-0.003212,0.000987,0.025063,-2.597217,-0.132309,0.250628,-114.627411,0.024057,0.000000
174.450012,-0.564888,-114.582932,-0.003225,0.000969,0.024612,-2.512747,-0.128005,0.246117,-114.582932,0.023293,0.000000
174.910004,-0.552597,-114.627411,-0.003294,0.000926,0.023510,-2.458074,-0.125220,0.235103,-114.627411,0.022530,0.000000
175.370010,-0.549248,-114.538452,-0.003316,0.000892,0.022652,-2.443176,-0.124461,0.226518,-114.538452,0.021759,0.000000
175.830002,-0.577545,-114.582932,-0.003333,0.000867,0.022010,-2.569049,-0.130874,0.220099,-114.582932,0.020996,0.000000
176.290009,-0.587227,-114.627411,-0.003367,0.000837,0.021264,-2.612116,-0.133068,0.212643,-114.627411,0.020223,0.000000
176.750015,-0.545898,-114.627411,-0.003397,0.000803,0.020388,-2.428277,-0.123702,0.203885,-114.627411,0.019460,0.000000
177.210007,-0.555580,-114.627411,-0.003441,0.000774,0.019669,-2.471344,-0.125896,0.196686,-114.627411,0.018688,0.000000
177.670013,-0.584251,-114.582932,-0.003466,0.000744,0.018906,-2.598880,-0.132393,0.189056,-114.582932,0.017925,0.000000
178.130005,-0.554832,-114.627411,-0.003479,0.000718,0.018229,-2.468018,-0.125727,0.182288,-114.627411,0.017162,0.000000
178.590012,-0.554085,-114.582932,-0.003523,0.000686,0.017422,-2.464692,-0.125557,0.174219,-114.582932,0.016390,0.000000
179.050003,-0.557442,-114.538452,-0.003566,0.000665,0.016902,-2.479625,-0.126318,0.169018,-114.538452,0.015627,0.000000
179.510010,-0.583504,-114.627411,-0.003596,0.000624,0.015844,-2.595554,-0.132224,0.158436,-114.627411,0.014855,0.000000
179.970001,-0.538445,-114.627411,-0.003639,0.000595,0.015107,-2.395121,-0.122013,0.151070,-114.627411,0.014092,0.000000
180.430008,-0.564140,-114.582932,-0.003656,0.000563,0.014309,-2.509422,-0.127836,0.143092,-114.582932,0.013329,0.000000
180.890015,-0.561531,-114.538452,-0.003686,0.000537,0.013641,-2.497815,-0.127245,0.136408,-114.538452,0.012557,0.000000
181.350006,-0.564888,-114.538452,-0.003712,0.000507,0.012869,-2.512747,-0.128005,0.128694,-114.538452,0.011794,0.000000
181.810013,-0.570473,-114.627411,-0.003751,0.000477,0.012115,-2.537589,-0.129271,0.121147,-114.627411,0.011022,0.000000
182.270004,-0.573448,-114.538452,-0.003777,0.000445,0.011299,-2.550825,-0.129945,0.112994,-114.538452,0.010259,0.000000
182.730011,-0.575310,-114.582932,-0.003798,0.000416,0.010562,-2.559106,-0.130367,0.105621,-114.582932,0.009496,0.000000
183.190002,-0.576805,-114.493965,-0.003846,0.000383,0.009730,-2.565757,-0.130706,0.097302,-114.493965,0.008724,0.000000
183.650009,-0.553719,-114.538452,-0.003872,0.000355,0.009028,-2.463063,-0.125474,0.090277,-114.538452,0.007961,0.000000
184.110016,-0.561165,-114.582932,-0.003919,0.000326,0.008290,-2.496186,-0.127162,0.082904,-114.582932,0.007189,0.000000
184.570007,-0.563026,-114.538452,-0.003923,0.000293,0.007440,-2.504467,-0.127584,0.074403,-114.538452,0.006426,0.000000
185.030014,-0.552971,-114.582932,-0.003949,0.000265,0.006738,-2.459737,-0.125305,0.067379,-114.582932,0.005654,0.000000
185.490005,-0.549988,-114.493965,-0.004001,0.000235,0.005967,-2.446468,-0.124629,0.059665,-114.493965,0.004891,0.000000
185.950012,-0.519081,-114.538452,-0.004018,0.000206,0.005238,-2.308988,-0.117625,0.052375,-114.538452,0.004128,0.000000
186.410004,-0.517967,-114.582932,-0.004061,0.000176,0.004475,-2.304033,-0.117373,0.044745,-114.582932,0.003356,0.000000
186.870010,-0.523926,-114.493965,-0.004092,0.000140,0.003556,-2.330538,-0.118723,0.035555,-114.493965,0.002593,0.000000
187.330002,-0.545151,-114.493965,-0.004126,0.000110,0.002801,-2.424952,-0.123533,0.028008,-114.493965,0.001821,0.000000
187.790009,-0.508659,-114.449486,-0.004156,0.000081,0.002055,-2.262630,-0.115264,0.020552,-114.449486,0.001057,0.000000
188.250015,-0.497490,-114.538452,-0.004186,0.000053,0.001335,-2.212946,-0.112733,0.013353,-114.538452,0.000294,0.000000
188.710007,-0.512009,-114.493965,-0.004234,0.000021,0.000546,-2.277528,-0.116023,0.005458,-114.493965,-0.000478,0.000000
189.170013,-0.539192,-114.449486,-0.004243,0.000006,0.000147,-2.398447,-0.122183,0.001469,-114.449486,-0.000009,0.000000
189.200012,-0.520576,-114.493965,-0.004243,0.000006,0.000147,-2.315640,-0.117964,0.001469,-114.493965,-0.000009,0.000000