File: Data/compression 26/AutoNoHeating-17-26-reverse-2-2_09262024_181743.csv
Time (sec),S:Load (lbs),S:HL1 (DIM),S:LVDT (in),S:Position (in),Ch:Position (mm),Ch:Load (N),Ch:Stress (MPa),Ch:Strain (mm/mm),Ch:HL1 (DIM),Set Point (),Cycles ()
0.110000,-0.503441,-120.454414,-0.010343,-0.005697,-0.144714,-2.239417,-0.114081,-1.447140,-120.454414,-0.144497,0.000000
0.490000,-0.493393,-120.498894,-0.010343,-0.005613,-0.142563,-2.194721,-0.111804,-1.425634,-120.498894,-0.141774,0.000000
0.870000,-0.512009,-120.498894,-0.010214,-0.005381,-0.136666,-2.277528,-0.116023,-1.366665,-120.498894,-0.135443,0.000000
1.250000,-0.482964,-120.498894,-0.009960,-0.005137,-0.130492,-2.148329,-0.109441,-1.304918,-120.498894,-0.129113,0.000000
1.630000,-0.474030,-120.454414,-0.009714,-0.004891,-0.124230,-2.108589,-0.107417,-1.242301,-120.454414,-0.122782,0.000000
2.010000,-0.478867,-120.454414,-0.009472,-0.004644,-0.117952,-2.130105,-0.108513,-1.179517,-120.454414,-0.116451,0.000000
2.390000,-0.525040,-120.543381,-0.009205,-0.004390,-0.111508,-2.335493,-0.118976,-1.115083,-120.543381,-0.110121,0.000000
2.770000,-0.541801,-120.498894,-0.008946,-0.004139,-0.105143,-2.410053,-0.122774,-1.051429,-120.498894,-0.103789,0.000000
3.150000,-0.480354,-120.498894,-0.008683,-0.003882,-0.098595,-2.136723,-0.108850,-0.985950,-120.498894,-0.097459,0.000000
3.530000,-0.479988,-120.498894,-0.008459,-0.003642,-0.092507,-2.135094,-0.108767,-0.925074,-120.498894,-0.091128,0.000000
3.910000,-0.451683,-120.409935,-0.008192,-0.003393,-0.086176,-2.009187,-0.102353,-0.861760,-120.409935,-0.084798,0.000000
4.290000,-0.485573,-120.498894,-0.007925,-0.003146,-0.079906,-2.159936,-0.110032,-0.799059,-120.498894,-0.078467,0.000000
4.670000,-0.481850,-120.454414,-0.007666,-0.002894,-0.073506,-2.143374,-0.109189,-0.735064,-120.454414,-0.072136,0.000000
5.050000,-0.490410,-120.498894,-0.007390,-0.002635,-0.066924,-2.181452,-0.111128,-0.669238,-120.498894,-0.065805,0.000000
5.430000,-0.459129,-120.454414,-0.007140,-0.002393,-0.060776,-2.042309,-0.104040,-0.607756,-120.454414,-0.059474,0.000000
5.810000,-0.437164,-120.365456,-0.006860,-0.002146,-0.054514,-1.944604,-0.099063,-0.545138,-120.365456,-0.053144,0.000000
6.190000,-0.453918,-120.409935,-0.006614,-0.001900,-0.048253,-2.019130,-0.102859,-0.482529,-120.409935,-0.046813,0.000000
6.570000,-0.477379,-120.454414,-0.006364,-0.001646,-0.041818,-2.123487,-0.108176,-0.418178,-120.454414,-0.040482,0.000000
6.950000,-0.497856,-120.498894,-0.006109,-0.001395,-0.035427,-2.214575,-0.112816,-0.354266,-120.498894,-0.034151,0.000000
7.330000,-0.447960,-120.409935,-0.005842,-0.001144,-0.029070,-1.992625,-0.101509,-0.290695,-120.409935,-0.027820,0.000000
7.710001,-0.429344,-120.409935,-0.005579,-0.000897,-0.022782,-1.909818,-0.097291,-0.227820,-120.409935,-0.021490,0.000000
8.090000,-0.434929,-120.409935,-0.005329,-0.000649,-0.016486,-1.934660,-0.098556,-0.164862,-120.409935,-0.015159,0.000000
8.470000,-0.481102,-120.409935,-0.005075,-0.000403,-0.010225,-2.140049,-0.109019,-0.102245,-120.409935,-0.008829,0.000000
8.850000,-0.454292,-120.409935,-0.004807,-0.000146,-0.003721,-2.020793,-0.102944,-0.037206,-120.409935,-0.002498,0.000000
9.230000,-0.411842,-120.409935,-0.004566,0.000095,0.002419,-1.831966,-0.093325,0.024193,-120.409935,0.003833,0.000000
9.610001,0.075226,-120.365456,-0.004419,-0.000008,-0.000200,0.334621,0.017046,-0.001998,-120.365456,0.000017,0.000000
9.990001,0.113205,-120.409935,-0.004428,-0.000008,-0.000200,0.503561,0.025653,-0.001998,-120.409935,0.000130,0.000000
10.370001,0.096451,-120.409935,-0.004419,-0.000008,-0.000200,0.429035,0.021856,-0.001998,-120.409935,0.000763,0.000000
10.750001,0.350403,-120.365456,-0.004428,0.000016,0.000399,1.558670,0.079402,0.003989,-120.365456,0.001396,0.000000
11.130000,0.637878,-120.320976,-0.004406,0.000041,0.001032,2.837425,0.144545,0.010318,-120.320976,0.002029,0.000000
11.510000,0.686661,-120.320976,-0.004376,0.000048,0.001232,3.054420,0.155600,0.012316,-120.320976,0.002662,0.000000
11.890000,1.251175,-120.365456,-0.004342,0.000091,0.002307,5.565504,0.283520,0.023065,-120.365456,0.003295,0.000000
12.270000,1.547585,-120.365456,-0.004337,0.000115,0.002931,6.884000,0.350688,0.029310,-120.365456,0.003929,0.000000
12.650001,1.939316,-120.365456,-0.004333,0.000137,0.003478,8.626508,0.439455,0.034776,-120.365456,0.004562,0.000000
13.030001,2.210037,-120.320976,-0.004290,0.000157,0.003989,9.830736,0.500802,0.039893,-120.320976,0.005203,0.000000
13.410001,2.722420,-120.276489,-0.004260,0.000184,0.004674,12.109928,0.616909,0.046743,-120.276489,0.005836,0.000000
13.790001,2.785721,-120.320976,-0.004251,0.000206,0.005229,12.391505,0.631253,0.052292,-120.320976,0.006469,0.000000
14.170001,3.516685,-120.276489,-0.004217,0.000235,0.005967,15.642999,0.796892,0.059665,-120.276489,0.007103,0.000000
14.550001,3.670853,-120.365456,-0.004217,0.000249,0.006331,16.328768,0.831827,0.063306,-120.365456,0.007736,0.000000
14.930000,4.389526,-120.320976,-0.004174,0.000289,0.007345,19.525589,0.994681,0.073450,-120.320976,0.008368,0.000000
15.310000,4.654655,-120.276489,-0.004161,0.000307,0.007805,20.704941,1.054760,0.078052,-120.276489,0.009002,0.000000
15.690001,4.783127,-120.276489,-0.004135,0.000325,0.008247,21.276411,1.083872,0.082473,-120.276489,0.009635,0.000000
16.070002,5.104858,-120.276489,-0.004122,0.000351,0.008915,22.707544,1.156778,0.089149,-120.276489,0.010268,0.000000
16.450001,5.874176,-120.320976,-0.004100,0.000388,0.009843,26.129641,1.331107,0.098430,-120.320976,0.010901,0.000000
16.830000,6.078239,-120.276489,-0.004061,0.000408,0.010363,27.037359,1.377349,0.103630,-120.276489,0.011534,0.000000
17.210001,6.198517,-120.232010,-0.004031,0.000428,0.010884,27.572380,1.404604,0.108838,-120.232010,0.012167,0.000000
17.590000,6.729149,-120.232010,-0.004018,0.000460,0.011673,29.932749,1.524847,0.116726,-120.232010,0.012801,0.000000
17.970001,6.880699,-120.276489,-0.004001,0.000482,0.012237,30.606878,1.559189,0.122366,-120.276489,0.013433,0.000000
18.350000,7.148064,-120.276489,-0.003971,0.000506,0.012861,31.796175,1.619774,0.128611,-120.276489,0.014066,0.000000
18.730001,7.351753,-120.276489,-0.003945,0.000533,0.013537,32.702232,1.665931,0.135371,-120.276489,0.014700,0.000000
19.110001,7.769928,-120.232010,-0.003915,0.000562,0.014274,34.562366,1.760691,0.142744,-120.232010,0.015333,0.000000
19.490002,7.704018,-120.187531,-0.003902,0.000581,0.014760,34.269180,1.745755,0.147603,-120.187531,0.015965,0.000000
19.870001,7.934517,-120.276489,-0.003876,0.000602,0.015298,35.294495,1.797987,0.152978,-120.276489,0.016598,0.000000
20.250002,8.503502,-120.276489,-0.003863,0.000636,0.016148,37.825466,1.926921,0.161479,-120.276489,0.017232,0.000000
20.630001,8.566429,-120.232010,-0.003833,0.000660,0.016755,38.105381,1.941181,0.167550,-120.232010,0.017865,0.000000
21.010000,8.542603,-120.276489,-0.003811,0.000681,0.017310,37.999393,1.935781,0.173098,-120.276489,0.018498,0.000000
21.390001,8.850182,-120.232010,-0.003790,0.000711,0.018047,39.367573,2.005480,0.180471,-120.232010,0.019131,0.000000
21.770000,8.806610,-120.232010,-0.003760,0.000727,0.018472,39.173759,1.995606,0.184718,-120.232010,0.019764,0.000000
22.150002,8.942902,-120.276489,-0.003768,0.000750,0.019061,39.780014,2.026490,0.190615,-120.276489,0.020397,0.000000
22.530001,9.503693,-120.187531,-0.003712,0.000786,0.019964,42.274536,2.153568,0.199638,-120.187531,0.021030,0.000000
22.910002,9.377083,-120.143051,-0.003691,0.000803,0.020406,41.711349,2.124877,0.204059,-120.143051,0.021663,0.000000
23.290001,9.670143,-120.143051,-0.003678,0.000828,0.021039,43.014946,2.191286,0.210387,-120.143051,0.022296,0.000000
23.670002,9.777390,-120.143051,-0.003652,0.000853,0.021663,43.492001,2.215588,0.216632,-120.143051,0.022930,0.000000
24.050001,10.050705,-120.187531,-0.003622,0.000880,0.022348,44.707767,2.277522,0.223483,-120.187531,0.023571,0.000000
24.430000,10.498299,-120.098564,-0.003609,0.000913,0.023181,46.698765,2.378948,0.231810,-120.098564,0.024204,0.000000
24.810001,10.452873,-120.143051,-0.003570,0.000931,0.023658,46.496704,2.368655,0.236579,-120.143051,0.024837,0.000000
25.190001,10.186249,-120.143051,-0.003548,0.000944,0.023970,45.310696,2.308237,0.239697,-120.143051,0.025470,0.000000
25.570002,10.734009,-120.143051,-0.003523,0.000980,0.024889,47.747257,2.432361,0.248895,-120.143051,0.026104,0.000000
25.950001,11.158516,-120.232010,-0.003501,0.001012,0.025713,49.635559,2.528556,0.257131,-120.232010,0.026736,0.000000
26.330002,11.216606,-120.143051,-0.003471,0.001037,0.026338,49.893955,2.541719,0.263376,-120.143051,0.027369,0.000000
26.710001,11.135056,-120.143051,-0.003445,0.001056,0.026814,49.531200,2.523240,0.268145,-120.143051,0.028003,0.000000
27.090002,11.226662,-120.098564,-0.003441,0.001077,0.027352,49.938686,2.543998,0.273519,-120.098564,0.028636,0.000000
27.470001,11.308578,-120.098564,-0.003406,0.001100,0.027951,50.303070,2.562561,0.279507,-120.098564,0.029269,0.000000
27.850000,11.993744,-120.098564,-0.003385,0.001136,0.028844,53.350838,2.717821,0.288439,-120.098564,0.029902,0.000000
28.230001,12.301697,-120.143051,-0.003359,0.001164,0.029572,54.720680,2.787604,0.295721,-120.143051,0.030535,0.000000
28.610001,12.075668,-120.098564,-0.003328,0.001182,0.030023,53.715256,2.736386,0.300233,-120.098564,0.031168,0.000000
28.990002,12.192970,-120.143051,-0.003307,0.001203,0.030552,54.237041,2.762967,0.305524,-120.143051,0.031801,0.000000
29.370001,12.425697,-120.098564,-0.003281,0.001232,0.031281,55.272263,2.815703,0.312806,-120.098564,0.032434,0.000000
29.750002,12.483047,-120.143051,-0.003281,0.001252,0.031801,55.527367,2.828699,0.318014,-120.143051,0.033067,0.000000
30.130001,13.078468,-120.098564,-0.003238,0.001283,0.032599,58.175934,2.963623,0.325993,-120.098564,0.033700,0.000000
30.510002,13.317535,-120.009605,-0.003203,0.001313,0.033353,59.239357,3.017797,0.333533,-120.009605,0.034334,0.000000
30.890001,13.271355,-120.098564,-0.003191,0.001339,0.034021,59.033936,3.007332,0.340209,-120.098564,0.034966,0.000000
31.270002,13.369293,-120.098564,-0.003160,0.001363,0.034620,59.469585,3.029525,0.346197,-120.098564,0.035599,0.000000
31.650002,13.551384,-120.143051,-0.003143,0.001390,0.035313,60.279568,3.070787,0.353131,-120.143051,0.036233,0.000000
32.030003,13.423286,-120.054085,-0.003122,0.001406,0.035704,59.709759,3.041760,0.357037,-120.054085,0.036866,0.000000
32.410000,14.100258,-120.009605,-0.003096,0.001439,0.036562,62.721081,3.195164,0.365621,-120.009605,0.037498,0.000000
32.790001,13.513397,-120.009605,-0.003074,0.001447,0.036753,60.110592,3.062180,0.367528,-120.009605,0.038132,0.000000
33.170002,14.538170,-120.054085,-0.003044,0.001488,0.037802,64.669006,3.294396,0.378020,-120.054085,0.038765,0.000000
33.550003,14.323685,-120.054085,-0.003031,0.001507,0.038288,63.714931,3.245793,0.382880,-120.054085,0.039398,0.000000
33.930000,14.631638,-120.009605,-0.003009,0.001535,0.038990,65.084778,3.315576,0.389905,-120.009605,0.040031,0.000000
34.310001,14.616364,-119.965126,-0.002984,0.001554,0.039467,65.016830,3.312115,0.394674,-119.965126,0.040664,0.000000
34.690002,15.133965,-120.009605,-0.002953,0.001583,0.040196,67.319237,3.429405,0.401956,-120.009605,0.041297,0.000000
35.070004,14.636475,-120.009605,-0.002958,0.001595,0.040508,65.106293,3.316672,0.405082,-120.009605,0.041939,0.000000
35.450001,15.122795,-120.054085,-0.002928,0.001625,0.041271,67.269554,3.426874,0.412713,-120.054085,0.042572,0.000000
35.830002,15.362228,-120.009605,-0.002893,0.001652,0.041965,68.334602,3.481131,0.419646,-120.009605,0.043205,0.000000
36.210003,16.014626,-119.965126,-0.002871,0.001684,0.042772,71.236610,3.628966,0.427716,-119.965126,0.043838,0.000000
36.590000,16.005692,-119.965126,-0.002850,0.001706,0.043326,71.196869,3.626941,0.433264,-119.965126,0.044471,0.000000
36.970001,15.778915,-120.009605,-0.002833,0.001723,0.043769,70.188118,3.575553,0.437685,-120.009605,0.045105,0.000000
37.350002,16.158737,-119.965126,-0.002815,0.001752,0.044488,71.877655,3.661622,0.444884,-119.965126,0.045737,0.000000
37.730003,16.464081,-120.009605,-0.002785,0.001776,0.045122,73.235886,3.730814,0.451220,-120.009605,0.046370,0.000000
38.110001,16.914650,-119.920647,-0.002759,0.001806,0.045876,75.240120,3.832915,0.458760,-119.920647,0.047004,0.000000
38.490002,16.894539,-119.920647,-0.002734,0.001830,0.046475,75.150665,3.828357,0.464747,-119.920647,0.047637,0.000000
38.870003,17.295959,-119.965126,-0.002708,0.001858,0.047186,76.936272,3.919320,0.471855,-119.965126,0.048270,0.000000
39.250000,17.189835,-119.920647,-0.002699,0.001876,0.047645,76.464203,3.895272,0.476450,-119.920647,0.048903,0.000000
39.630001,17.695145,-119.965126,-0.002669,0.001904,0.048374,78.711937,4.009777,0.483740,-119.965126,0.049536,0.000000
40.010002,17.968094,-119.920647,-0.002652,0.001931,0.049042,79.926071,4.071628,0.490416,-119.920647,0.050169,0.000000
40.390003,18.586227,-119.876160,-0.002626,0.001960,0.049787,82.675667,4.211699,0.497873,-119.876160,0.050802,0.000000
40.770000,18.340462,-119.965126,-0.002617,0.001977,0.050212,81.582451,4.156008,0.502119,-119.965126,0.051435,0.000000
41.150002,18.640968,-119.920647,-0.002583,0.002001,0.050819,82.919167,4.224103,0.508190,-119.920647,0.052068,0.000000
41.530003,18.881523,-119.920647,-0.002583,0.002028,0.051522,83.989212,4.278615,0.515215,-119.920647,0.052701,0.000000
41.910004,19.791229,-119.920647,-0.002544,0.002058,0.052276,88.035782,4.484756,0.522762,-119.920647,0.053334,0.000000
42.290001,19.148514,-119.876160,-0.002518,0.002071,0.052597,85.176842,4.339115,0.525972,-119.876160,0.053967,0.000000
42.670002,19.527962,-119.831680,-0.002496,0.002097,0.053265,86.864716,4.425099,0.532648,-119.831680,0.054600,0.000000
43.050003,20.083908,-119.920647,-0.002488,0.002126,0.054002,89.337685,4.551078,0.540021,-119.920647,0.055234,0.000000
43.430000,19.991936,-119.831680,-0.002466,0.002146,0.054514,88.928574,4.530237,0.545138,-119.831680,0.055867,0.000000
43.810001,21.232307,-119.831680,-0.002440,0.002181,0.055407,94.446022,4.811310,0.554071,-119.831680,0.056499,0.000000
44.190002,21.033463,-119.876160,-0.002402,0.002202,0.055927,93.561516,4.766251,0.559271,-119.876160,0.057133,0.000000
44.570004,21.669098,-119.876160,-0.002393,0.002227,0.056577,96.388962,4.910288,0.565774,-119.876160,0.057766,0.000000
44.950001,21.790871,-119.876160,-0.002363,0.002251,0.057168,96.930634,4.937882,0.571678,-119.876160,0.058399,0.000000
45.330002,22.079826,-119.787201,-0.002363,0.002273,0.057731,98.215973,5.003360,0.577310,-119.787201,0.059032,0.000000
45.710003,22.668175,-119.876160,-0.002324,0.002305,0.058546,100.833076,5.136682,0.585463,-119.876160,0.059673,0.000000
46.090004,22.651047,-119.876160,-0.002289,0.002328,0.059136,100.756889,5.132801,0.591360,-119.876160,0.060307,0.000000
46.470001,22.886017,-119.876160,-0.002289,0.002345,0.059570,101.802086,5.186046,0.595697,-119.876160,0.060940,0.000000
46.850002,23.746193,-119.876160,-0.002272,0.002378,0.060411,105.628342,5.380964,0.604107,-119.876160,0.061573,0.000000
47.230003,24.181496,-119.787201,-0.002255,0.002401,0.060983,107.564667,5.479605,0.609830,-119.787201,0.062206,0.000000
47.610001,24.498016,-119.787201,-0.002225,0.002428,0.061677,108.972618,5.551330,0.616771,-119.787201,0.062839,0.000000
47.990002,24.981728,-119.876160,-0.002195,0.002454,0.062336,111.124275,5.660940,0.623365,-119.876160,0.063472,0.000000
48.370003,25.152649,-119.787201,-0.002190,0.002473,0.062813,111.884567,5.699672,0.628134,-119.787201,0.064106,0.000000
48.750004,25.626678,-119.831680,-0.002169,0.002498,0.063455,113.993156,5.807088,0.634545,-119.831680,0.064738,0.000000
49.130001,26.739700,-119.742722,-0.002130,0.002533,0.064331,118.944130,6.059303,0.643311,-119.742722,0.065371,0.000000
49.510002,27.147820,-119.742722,-0.002108,0.002556,0.064912,120.759529,6.151783,0.649117,-119.742722,0.066005,0.000000
49.890003,27.748085,-119.831680,-0.002082,0.002581,0.065562,123.429649,6.287806,0.655620,-119.831680,0.066638,0.000000
50.270004,27.992355,-119.787201,-0.002074,0.002601,0.066074,124.516212,6.343159,0.660737,-119.787201,0.067270,0.000000
50.650002,28.223228,-119.742722,-0.002057,0.002622,0.066603,125.543190,6.395475,0.666028,-119.742722,0.067904,0.000000
51.030003,28.760193,-119.742722,-0.002039,0.002646,0.067218,127.931725,6.517153,0.672182,-119.742722,0.068537,0.000000
51.410004,30.030350,-119.787201,-0.002009,0.002676,0.067982,133.581665,6.804975,0.679820,-119.787201,0.069170,0.000000
51.790001,31.304237,-119.787201,-0.001988,0.002709,0.068797,139.248199,7.093642,0.687973,-119.787201,0.069803,0.000000
52.170002,31.433083,-119.831680,-0.001970,0.002731,0.069378,139.821335,7.122838,0.693779,-119.831680,0.070436,0.000000
52.550003,32.254158,-119.742722,-0.001944,0.002760,0.070106,143.473663,7.308897,0.701061,-119.742722,0.071069,0.000000
52.930004,32.464180,-119.742722,-0.001927,0.002782,0.070670,144.407883,7.356488,0.706700,-119.742722,0.071702,0.000000
53.310001,32.959435,-119.653755,-0.001914,0.002803,0.071208,146.610886,7.468715,0.712075,-119.653755,0.072335,0.000000
53.690002,34.306679,-119.698242,-0.001884,0.002834,0.071989,152.603729,7.774004,0.719887,-119.698242,0.072968,0.000000
54.070004,33.872116,-119.742722,-0.001867,0.002845,0.072266,150.670700,7.675531,0.722658,-119.742722,0.073601,0.000000
54.450001,35.999107,-119.653755,-0.001863,0.002884,0.073263,160.132034,8.157515,0.732635,-119.653755,0.074235,0.000000
54.830002,36.165558,-119.653755,-0.001832,0.002905,0.073783,160.872437,8.195232,0.737835,-119.653755,0.074867,0.000000
55.210003,36.584106,-119.609276,-0.001807,0.002923,0.074235,162.734238,8.290076,0.742347,-119.609276,0.075500,0.000000
55.590004,37.672554,-119.742722,-0.001794,0.002950,0.074937,167.575897,8.536722,0.749371,-119.742722,0.076134,0.000000
55.970001,39.196671,-119.698242,-0.001776,0.002983,0.075769,174.355499,8.882092,0.757691,-119.698242,0.076767,0.000000
56.350002,38.952026,-119.609276,-0.001768,0.002993,0.076029,173.267273,8.826655,0.760295,-119.609276,0.077400,0.000000
56.730003,39.911255,-119.698242,-0.001733,0.003023,0.076775,177.534134,9.044020,0.767751,-119.698242,0.078042,0.000000
57.110004,40.531258,-119.653755,-0.001712,0.003039,0.077183,180.292038,9.184515,0.771831,-119.653755,0.078674,0.000000
57.490002,42.849274,-119.653755,-0.001694,0.003079,0.078197,190.603088,9.709785,0.781974,-119.653755,0.079308,0.000000
57.870003,43.610779,-119.653755,-0.001699,0.003099,0.078718,193.990433,9.882344,0.787182,-119.653755,0.079941,0.000000
58.250004,44.189445,-119.653755,-0.001673,0.003120,0.079238,196.564468,10.013472,0.792383,-119.653755,0.080574,0.000000
58.630001,45.690102,-119.609276,-0.001647,0.003150,0.080019,203.239716,10.353525,0.800187,-119.609276,0.081207,0.000000
59.010002,46.690300,-119.653755,-0.001634,0.003175,0.080643,207.688828,10.580173,0.806432,-119.653755,0.081840,0.000000
59.390003,48.109406,-119.653755,-0.001630,0.003204,0.081371,214.001328,10.901747,0.813715,-119.653755,0.082473,0.000000
59.770004,48.985229,-119.653755,-0.001600,0.003223,0.081857,217.897186,11.100212,0.818574,-119.653755,0.083106,0.000000
60.150002,49.994354,-119.520317,-0.001600,0.003246,0.082447,222.386002,11.328883,0.824471,-119.520317,0.083739,0.000000
60.530003,51.123764,-119.609276,-0.001582,0.003271,0.083089,227.409866,11.584810,0.830890,-119.609276,0.084372,0.000000
60.910004,52.774117,-119.609276,-0.001565,0.003303,0.083887,234.750992,11.958786,0.838869,-119.609276,0.085006,0.000000
61.290005,54.126205,-119.609276,-0.001548,0.003328,0.084520,240.765381,12.265174,0.845197,-119.609276,0.085639,0.000000
61.670002,55.087669,-119.609276,-0.001531,0.003353,0.085170,245.042191,12.483044,0.851700,-119.609276,0.086271,0.000000
62.050003,56.059929,-119.564796,-0.001513,0.003373,0.085673,249.367020,12.703362,0.856734,-119.564796,0.086905,0.000000
62.430004,57.019905,-119.520317,-0.001470,0.003398,0.086306,253.637207,12.920895,0.863062,-119.520317,0.087538,0.000000
62.810001,58.869110,-119.564796,-0.001475,0.003421,0.086888,261.862885,13.339931,0.868876,-119.564796,0.088171,0.000000
63.190002,60.971901,-119.564796,-0.001462,0.003454,0.087729,271.216553,13.816430,0.877286,-119.564796,0.088803,0.000000
63.570004,61.450768,-119.609276,-0.001453,0.003469,0.088110,273.346680,13.924943,0.881101,-119.609276,0.089437,0.000000
63.950005,62.860939,-119.520317,-0.001444,0.003493,0.088735,279.619415,14.244493,0.887346,-119.520317,0.090070,0.000000
64.330002,64.591362,-119.564796,-0.001431,0.003522,0.089463,287.316742,14.636611,0.894628,-119.564796,0.090703,0.000000
64.710007,65.410942,-119.609276,-0.001410,0.003542,0.089975,290.962402,14.822331,0.899745,-119.609276,0.091336,0.000000
65.090004,65.521919,-119.564796,-0.001384,0.003543,0.089984,291.456055,14.847479,0.899836,-119.564796,0.015804,0.000000
65.470001,65.734917,-119.520317,-0.001393,0.003560,0.090426,292.403503,14.895744,0.904257,-119.520317,294.500488,0.000000
65.850006,64.819252,-119.475838,-0.001384,0.003560,0.090434,288.330444,14.688252,0.904340,-119.475838,294.500488,0.000000
66.230003,65.011024,-119.475838,-0.001371,0.003594,0.091292,289.183472,14.731709,0.912924,-119.475838,294.500488,0.000000
66.610001,66.173943,-119.520317,-0.001337,0.003422,0.086913,294.356384,14.995230,0.869133,-119.520317,294.500488,0.000000
66.990005,65.367012,-119.520317,-0.001337,0.003494,0.088743,290.766998,14.812377,0.887429,-119.520317,294.500488,0.000000
67.370003,65.090340,-119.475838,-0.001345,0.003583,0.090998,289.536285,14.749682,0.909980,-119.475838,294.500488,0.000000
67.750000,65.133156,-119.431351,-0.001332,0.003593,0.091267,289.726746,14.759384,0.912667,-119.431351,294.500488,0.000000
68.130005,65.083260,-119.475838,-0.001337,0.003597,0.091362,289.504791,14.748077,0.913621,-119.475838,294.500488,0.000000
68.510002,64.893730,-119.520317,-0.001319,0.003600,0.091440,288.661743,14.705130,0.914400,-119.520317,294.500488,0.000000
68.890007,65.073204,-119.564796,-0.001328,0.003607,0.091622,289.460083,14.745798,0.916225,-119.564796,294.500488,0.000000
69.270004,64.719078,-119.431351,-0.001332,0.003607,0.091622,287.884827,14.665552,0.916225,-119.431351,294.500488,0.000000
69.650002,66.010094,-119.431351,-0.001324,0.003620,0.091952,293.627563,14.958100,0.919518,-119.431351,294.500488,0.000000
70.030006,65.521919,-119.431351,-0.001311,0.003620,0.091943,291.456055,14.847479,0.919434,-119.431351,294.500488,0.000000
70.410004,65.072838,-119.431351,-0.001315,0.003620,0.091943,289.458435,14.745716,0.919434,-119.431351,294.500488,0.000000
70.790001,64.709770,-119.475838,-0.001306,0.003620,0.091952,287.843445,14.663444,0.919518,-119.475838,294.500488,0.000000
71.170006,65.319344,-119.431351,-0.001302,0.003632,0.092264,290.554962,14.801575,0.922644,-119.431351,294.500488,0.000000
71.550003,65.056450,-119.386871,-0.001306,0.003633,0.092273,289.385529,14.742002,0.922727,-119.386871,294.500488,0.000000
71.930000,64.840843,-119.431351,-0.001298,0.003634,0.092298,288.426483,14.693146,0.922984,-119.431351,294.500488,0.000000
72.310005,64.976768,-119.431351,-0.001306,0.003638,0.092411,289.031097,14.723947,0.924112,-119.431351,294.500488,0.000000
72.690002,64.980110,-119.475838,-0.001293,0.003641,0.092489,289.045959,14.724703,0.924892,-119.475838,294.500488,0.000000
73.070000,64.784615,-119.520317,-0.001285,0.003642,0.092498,288.176361,14.680403,0.924983,-119.520317,294.500488,0.000000
73.450005,65.298866,-119.386871,-0.001289,0.003650,0.092697,290.463867,14.796934,0.926974,-119.386871,294.500488,0.000000
73.830002,65.128319,-119.386871,-0.001268,0.003650,0.092697,289.705231,14.758287,0.926974,-119.386871,294.500488,0.000000
74.210007,64.917931,-119.386871,-0.001281,0.003650,0.092706,288.769379,14.710613,0.927065,-119.386871,294.500488,0.000000
74.590004,64.973045,-119.386871,-0.001281,0.003654,0.092802,289.014526,14.723103,0.928018,-119.386871,294.500488,0.000000
74.970001,64.802498,-119.386871,-0.001302,0.003654,0.092802,288.255920,14.684456,0.928018,-119.386871,294.500488,0.000000
75.350006,65.365517,-119.431351,-0.001272,0.003664,0.093071,290.760345,14.812038,0.930706,-119.431351,294.500488,0.000000
75.730003,65.470161,-119.297913,-0.001272,0.003664,0.093062,291.225830,14.835751,0.930622,-119.297913,294.500488,0.000000
76.110001,65.288811,-119.342392,-0.001276,0.003664,0.093062,290.419128,14.794656,0.930622,-119.342392,294.500488,0.000000
76.490005,65.107460,-119.386871,-0.001272,0.003664,0.093062,289.612457,14.753561,0.930622,-119.386871,294.500488,0.000000
76.870003,64.974159,-119.386871,-0.001281,0.003664,0.093071,289.019501,14.723354,0.930706,-119.386871,294.500488,0.000000
77.250000,64.842339,-119.342392,-0.001272,0.003665,0.093088,288.433136,14.693484,0.930880,-119.342392,294.500488,0.000000
77.630005,65.528999,-119.297913,-0.001259,0.003674,0.093331,291.487549,14.849083,0.933310,-119.297913,294.500488,0.000000
78.010002,65.500313,-119.297913,-0.001259,0.003674,0.093331,291.359955,14.842584,0.933310,-119.297913,294.500488,0.000000
78.390007,65.357323,-119.342392,-0.001246,0.003674,0.093331,290.723877,14.810181,0.933310,-119.342392,294.500488,0.000000
78.770004,65.235939,-119.342392,-0.001285,0.003674,0.093331,290.183960,14.782675,0.933310,-119.342392,294.500488,0.000000
79.150002,65.068367,-119.297913,-0.001268,0.003675,0.093339,289.438538,14.744702,0.933393,-119.297913,294.500488,0.000000
79.530006,64.964470,-119.297913,-0.001268,0.003675,0.093348,288.976410,14.721160,0.933484,-119.297913,294.500488,0.000000
79.910004,64.850533,-119.297913,-0.001259,0.003675,0.093348,288.469574,14.695340,0.933484,-119.297913,294.500488,0.000000
80.290001,64.714241,-119.386871,-0.001255,0.003675,0.093348,287.863312,14.664456,0.933484,-119.386871,294.500488,0.000000
80.670006,65.757256,-119.297913,-0.001263,0.003687,0.093660,292.502869,14.900806,0.936603,-119.297913,294.500488,0.000000
81.050003,65.680550,-119.253433,-0.001263,0.003687,0.093660,292.161682,14.883426,0.936603,-119.253433,294.500488,0.000000
81.430000,65.574425,-119.253433,-0.001268,0.003687,0.093660,291.689606,14.859378,0.936603,-119.253433,294.500488,0.000000
81.810005,65.477974,-119.342392,-0.001250,0.003687,0.093660,291.260590,14.837522,0.936603,-119.342392,294.500488,0.000000
82.190002,65.347267,-119.342392,-0.001259,0.003687,0.093660,290.679169,14.807902,0.936603,-119.342392,294.500488,0.000000
82.570007,65.251579,-119.297913,-0.001268,0.003687,0.093660,290.253510,14.786219,0.936603,-119.297913,294.500488,0.000000
82.950005,65.128685,-119.253433,-0.001255,0.003687,0.093660,289.706848,14.758371,0.936603,-119.253433,294.500488,0.000000
83.330002,65.012886,-119.208946,-0.001246,0.003687,0.093660,289.191772,14.732131,0.936603,-119.208946,294.500488,0.000000
83.710007,64.912346,-119.208946,-0.001233,0.003687,0.093660,288.744537,14.709348,0.936603,-119.208946,294.500488,0.000000
84.090004,64.798775,-119.253433,-0.001250,0.003687,0.093660,288.239349,14.683612,0.936603,-119.253433,294.500488,0.000000
84.470001,64.695244,-119.297913,-0.001246,0.003687,0.093660,287.778809,14.660151,0.936603,-119.297913,294.500488,0.000000
84.850006,65.675713,-119.208946,-0.001246,0.003700,0.093972,292.140167,14.882330,0.939721,-119.208946,294.500488,0.000000
85.230003,65.659691,-119.208946,-0.001242,0.003700,0.093972,292.068878,14.878698,0.939721,-119.208946,294.500488,0.000000
85.610001,65.577400,-119.164467,-0.001237,0.003700,0.093972,291.702850,14.860051,0.939721,-119.164467,294.500488,0.000000
85.990005,65.527870,-119.253433,-0.001237,0.003700,0.093972,291.482513,14.848827,0.939721,-119.253433,294.500488,0.000000
86.370003,65.446327,-119.164467,-0.001233,0.003700,0.093972,291.119812,14.830349,0.939721,-119.164467,294.500488,0.000000
86.750008,65.343925,-119.208946,-0.001246,0.003700,0.093972,290.664307,14.807145,0.939721,-119.208946,294.500488,0.000000
87.130005,65.265724,-119.208946,-0.001242,0.003700,0.093972,290.316437,14.789425,0.939721,-119.208946,294.500488,0.000000
87.510002,65.177467,-119.208946,-0.001233,0.003700,0.093972,289.923859,14.769425,0.939721,-119.208946,294.500488,0.000000
87.890007,65.061668,-119.253433,-0.001237,0.003700,0.093972,289.408752,14.743185,0.939721,-119.253433,294.500488,0.000000
88.270004,65.004692,-119.208946,-0.001237,0.003700,0.093972,289.155304,14.730273,0.939721,-119.208946,294.500488,0.000000
88.650002,64.923149,-119.164467,-0.001242,0.003700,0.093972,288.792603,14.711796,0.939721,-119.164467,294.500488,0.000000
89.030006,64.824089,-119.119987,-0.001246,0.003700,0.093972,288.351959,14.689349,0.939721,-119.119987,294.500488,0.000000
89.410004,64.751106,-119.164467,-0.001237,0.003700,0.093972,288.027313,14.672811,0.939721,-119.164467,294.500488,0.000000
89.790001,64.669563,-119.164467,-0.001246,0.003700,0.093972,287.664581,14.654332,0.939721,-119.164467,294.500488,0.000000
90.170006,64.591362,-119.164467,-0.001242,0.003700,0.093972,287.316742,14.636611,0.939721,-119.164467,294.500488,0.000000
90.550003,64.507576,-119.164467,-0.001242,0.003700,0.093972,286.944031,14.617626,0.939721,-119.164467,294.500488,0.000000
90.930008,66.066704,-119.031029,-0.001229,0.003708,0.094172,293.879364,14.970929,0.941720,-119.031029,294.500488,0.000000
91.310005,65.909554,-119.119987,-0.001216,0.003707,0.094164,293.180328,14.935319,0.941636,-119.119987,294.500488,0.000000
91.690002,65.827629,-119.164467,-0.001233,0.003707,0.094164,292.815918,14.916754,0.941636,-119.164467,294.500488,0.000000
92.070007,65.778481,-119.119987,-0.001224,0.003707,0.094164,292.597290,14.905617,0.941636,-119.119987,294.500488,0.000000
92.450005,65.664162,-119.075508,-0.001229,0.003707,0.094164,292.088776,14.879711,0.941636,-119.075508,294.500488,0.000000
92.830002,65.599739,-119.031029,-0.001212,0.003707,0.094164,291.802216,14.865113,0.941636,-119.031029,294.500488,0.000000
93.210007,65.531975,-119.075508,-0.001237,0.003707,0.094164,291.500793,14.849758,0.941636,-119.075508,294.500488,0.000000
93.590004,65.472389,-119.075508,-0.001224,0.003708,0.094172,291.235718,14.836256,0.941720,-119.075508,294.500488,0.000000
93.970001,65.368874,-119.119987,-0.001233,0.003708,0.094172,290.775269,14.812799,0.941720,-119.119987,294.500488,0.000000
94.350006,65.318230,-119.031029,-0.001233,0.003708,0.094172,290.549988,14.801322,0.941720,-119.031029,294.500488,0.000000
94.730003,65.252693,-119.119987,-0.001220,0.003708,0.094172,290.258484,14.786471,0.941720,-119.119987,294.500488,0.000000
95.110008,65.168907,-119.031029,-0.001224,0.003708,0.094172,289.885773,14.767486,0.941720,-119.031029,294.500488,0.000000
95.490005,65.083641,-119.119987,-0.001233,0.003708,0.094172,289.506500,14.748164,0.941720,-119.119987,294.500488,0.000000
95.870003,65.082146,-119.031029,-0.001220,0.003713,0.094310,289.499847,14.747825,0.943105,-119.031029,294.500488,0.000000
96.250008,65.075447,-119.031029,-0.001233,0.003715,0.094354,289.470032,14.746306,0.943544,-119.031029,294.500488,0.000000
96.630005,65.039696,-119.075508,-0.001220,0.003715,0.094354,289.311005,14.738206,0.943544,-119.075508,294.500488,0.000000
97.010002,65.103737,-119.075508,-0.001220,0.003717,0.094423,289.595886,14.752718,0.944233,-119.075508,294.500488,0.000000
97.390007,65.112312,-119.075508,-0.001216,0.003717,0.094423,289.634033,14.754661,0.944233,-119.075508,294.500488,0.000000
97.770004,65.089958,-118.986542,-0.001224,0.003718,0.094432,289.534607,14.749595,0.944324,-118.986542,294.500488,0.000000
98.150002,65.039696,-119.031029,-0.001224,0.003718,0.094432,289.311005,14.738206,0.944324,-119.031029,294.500488,0.000000
98.530006,65.066872,-118.986542,-0.001224,0.003719,0.094467,289.431915,14.744364,0.944672,-118.986542,294.500488,0.000000
98.910004,65.046394,-119.031029,-0.001216,0.003719,0.094467,289.340820,14.739723,0.944672,-119.031029,294.500488,0.000000
99.290001,65.065010,-119.031029,-0.001220,0.003720,0.094493,289.423615,14.743942,0.944929,-119.031029,294.500488,0.000000
99.670006,65.043419,-119.031029,-0.001216,0.003720,0.094493,289.327576,14.739050,0.944929,-119.031029,294.500488,0.000000
100.050003,65.040443,-118.986542,-0.001220,0.003721,0.094501,289.314331,14.738375,0.945013,-118.986542,294.500488,0.000000
100.430008,65.019585,-118.986542,-0.001216,0.003721,0.094510,289.221558,14.733649,0.945103,-118.986542,294.500488,0.000000
100.810005,65.026665,-119.031029,-0.001216,0.003721,0.094519,289.253052,14.735253,0.945187,-119.031029,294.500488,0.000000
101.190002,64.979744,-118.986542,-0.001224,0.003722,0.094528,289.044342,14.724620,0.945278,-118.986542,294.500488,0.000000
101.570007,65.174126,-118.986542,-0.001224,0.003725,0.094614,289.908997,14.768668,0.946140,-118.986542,294.500488,0.000000
101.950005,65.165932,-118.942062,-0.001220,0.003725,0.094614,289.872528,14.766811,0.946140,-118.942062,294.500488,0.000000
102.330002,65.162575,-118.986542,-0.001220,0.003725,0.094614,289.857605,14.766050,0.946140,-118.986542,294.500488,0.000000
102.710007,65.111931,-118.942062,-0.001220,0.003725,0.094614,289.632324,14.754575,0.946140,-118.942062,294.500488,0.000000
103.090004,65.067253,-118.942062,-0.001233,0.003725,0.094614,289.433594,14.744451,0.946140,-118.942062,294.500488,0.000000
103.470001,65.052727,-118.942062,-0.001233,0.003725,0.094614,289.368988,14.741158,0.946140,-118.942062,294.500488,0.000000
103.850006,65.022194,-118.942062,-0.001220,0.003726,0.094641,289.233154,14.734240,0.946405,-118.942062,294.500488,0.000000
104.230003,65.006920,-118.942062,-0.001220,0.003726,0.094641,289.165222,14.730779,0.946405,-118.942062,294.500488,0.000000
104.610008,64.973045,-118.942062,-0.001220,0.003726,0.094641,289.014526,14.723103,0.946405,-118.942062,294.500488,0.000000
104.990005,64.945488,-118.986542,-0.001220,0.003726,0.094641,288.891968,14.716858,0.946405,-118.986542,294.500488,0.000000
105.370003,64.906761,-118.897583,-0.001216,0.003726,0.094649,288.719696,14.708082,0.946489,-118.897583,294.500488,0.000000
105.750008,65.010643,-118.853104,-0.001203,0.003729,0.094709,289.181793,14.731623,0.947094,-118.853104,294.500488,0.000000
106.130005,65.026283,-118.853104,-0.001099,0.003729,0.094709,289.251343,14.735167,0.947094,-118.853104,294.500488,0.000000
106.510002,64.997246,-118.942062,-0.001095,0.003729,0.094709,289.122192,14.728586,0.947094,-118.942062,294.500488,0.000000
106.890007,64.962990,-118.942062,-0.001091,0.003729,0.094709,288.969818,14.720823,0.947094,-118.942062,294.500488,0.000000
107.270004,64.942879,-118.897583,-0.001095,0.003729,0.094709,288.880341,14.716267,0.947094,-118.897583,294.500488,0.000000
107.650002,64.898933,-118.853104,-0.001095,0.003729,0.094709,288.684875,14.706308,0.947094,-118.853104,294.500488,0.000000
108.030006,64.871758,-118.853104,-0.001082,0.003729,0.094709,288.563995,14.700150,0.947094,-118.853104,294.500488,0.000000
108.410004,64.805107,-118.897583,-0.001087,0.003729,0.094709,288.267517,14.685047,0.947094,-118.897583,294.500488,0.000000
108.790009,64.774193,-118.897583,-0.001104,0.003729,0.094709,288.130005,14.678041,0.947094,-118.897583,294.500488,0.000000
109.170006,64.727654,-118.897583,-0.001095,0.003729,0.094709,287.922974,14.667496,0.947094,-118.897583,294.500488,0.000000
109.550003,65.572929,-118.764137,-0.001091,0.003738,0.094952,291.682953,14.859038,0.949524,-118.764137,294.500488,0.000000
109.930008,65.557671,-118.808617,-0.001091,0.003738,0.094952,291.615082,14.855581,0.949524,-118.808617,294.500488,0.000000
110.310005,65.564735,-118.897583,-0.001091,0.003738,0.094952,291.646515,14.857182,0.949524,-118.897583,294.500488,0.000000
110.690002,65.536064,-118.853104,-0.001095,0.003738,0.094952,291.518982,14.850684,0.949524,-118.853104,294.500488,0.000000
111.070007,65.527504,-118.853104,-0.001099,0.003738,0.094952,291.480896,14.848745,0.949524,-118.853104,294.500488,0.000000
111.450005,65.510368,-118.808617,-0.001108,0.003738,0.094952,291.404663,14.844861,0.949524,-118.808617,294.500488,0.000000
111.830002,65.466057,-118.853104,-0.001091,0.003738,0.094952,291.207550,14.834821,0.949524,-118.853104,294.500488,0.000000
112.210007,65.452660,-118.853104,-0.001104,0.003738,0.094952,291.147980,14.831784,0.949524,-118.853104,294.500488,0.000000
112.590004,65.390465,-118.853104,-0.001095,0.003738,0.094952,290.871307,14.817692,0.949524,-118.853104,294.500488,0.000000
112.970009,65.389351,-118.808617,-0.001091,0.003738,0.094952,290.866364,14.817439,0.949524,-118.808617,294.500488,0.000000
113.350006,65.325310,-118.808617,-0.001099,0.003738,0.094952,290.581482,14.802927,0.949524,-118.808617,294.500488,0.000000
113.730003,65.316368,-118.719658,-0.001095,0.003738,0.094952,290.541718,14.800900,0.949524,-118.719658,294.500488,0.000000
114.110008,65.281364,-118.808617,-0.001091,0.003738,0.094952,290.386017,14.792969,0.949524,-118.808617,294.500488,0.000000
114.490005,65.234077,-118.764137,-0.001087,0.003738,0.094952,290.175659,14.782253,0.949524,-118.764137,294.500488,0.000000
114.870003,65.208382,-118.808617,-0.001095,0.003738,0.094952,290.061371,14.776431,0.949524,-118.808617,294.500488,0.000000
115.250008,65.164818,-118.808617,-0.001108,0.003738,0.094952,289.867584,14.766559,0.949524,-118.808617,294.500488,0.000000
115.630005,65.140602,-118.764137,-0.001095,0.003738,0.094952,289.759857,14.761071,0.949524,-118.764137,294.500488,0.000000
116.010002,65.106346,-118.764137,-0.001099,0.003738,0.094952,289.607483,14.753309,0.949524,-118.764137,294.500488,0.000000
116.390007,65.081032,-118.808617,-0.001099,0.003738,0.094952,289.494873,14.747572,0.949524,-118.808617,294.500488,0.000000
116.770004,65.048637,-118.719658,-0.001095,0.003738,0.094952,289.350800,14.740232,0.949524,-118.719658,294.500488,0.000000
117.150009,65.024803,-118.719658,-0.001082,0.003739,0.094962,289.244781,14.734831,0.949615,-118.719658,294.500488,0.000000
117.530006,64.998360,-118.764137,-0.001099,0.003739,0.094962,289.127136,14.728839,0.949615,-118.764137,294.500488,0.000000
117.910004,64.973412,-118.764137,-0.001087,0.003739,0.094962,289.016174,14.723186,0.949615,-118.764137,294.500488,0.000000
118.290009,64.932823,-118.719658,-0.001091,0.003739,0.094962,288.835632,14.713987,0.949615,-118.719658,294.500488,0.000000
118.670006,64.901176,-118.675179,-0.001104,0.003739,0.094962,288.694855,14.706817,0.949615,-118.675179,294.500488,0.000000
119.050003,64.861702,-118.675179,-0.001095,0.003739,0.094962,288.519257,14.697871,0.949615,-118.675179,294.500488,0.000000
119.430008,64.836754,-118.719658,-0.001095,0.003739,0.094962,288.408295,14.692219,0.949615,-118.719658,294.500488,0.000000
119.810005,64.793556,-118.764137,-0.001087,0.003739,0.094962,288.216125,14.682429,0.949615,-118.764137,294.500488,0.000000
120.190002,64.769722,-118.719658,-0.001095,0.003739,0.094962,288.110107,14.677029,0.949615,-118.719658,294.500488,0.000000
120.570007,64.726906,-118.719658,-0.001099,0.003739,0.094962,287.919647,14.667326,0.949615,-118.719658,294.500488,0.000000
120.950005,64.722054,-118.675179,-0.001104,0.003739,0.094962,287.898071,14.666227,0.949615,-118.675179,294.500488,0.000000
121.330009,64.677010,-118.675179,-0.001091,0.003739,0.094962,287.697693,14.656020,0.949615,-118.675179,294.500488,0.000000
121.710007,64.668434,-118.675179,-0.001091,0.003739,0.094962,287.659576,14.654077,0.949615,-118.675179,294.500488,0.000000
122.090004,64.624504,-118.675179,-0.001095,0.003739,0.094962,287.464142,14.644122,0.949615,-118.675179,294.500488,0.000000
122.470009,64.613701,-118.719658,-0.001082,0.003739,0.094970,287.416107,14.641673,0.949698,-118.719658,294.500488,0.000000
122.850006,64.570885,-118.675179,-0.001108,0.003739,0.094970,287.225647,14.631971,0.949698,-118.675179,294.500488,0.000000
123.230003,64.598427,-118.630699,-0.001091,0.003741,0.095022,287.348145,14.638213,0.950221,-118.630699,294.500488,0.000000
123.610008,64.604012,-118.675179,-0.001099,0.003741,0.095022,287.372986,14.639479,0.950221,-118.675179,294.500488,0.000000
123.990005,65.826897,-118.675179,-0.001087,0.003757,0.095438,292.812653,14.916588,0.954384,-118.675179,294.500488,0.000000
124.370003,65.875664,-118.630699,-0.001095,0.003755,0.095369,293.029602,14.927639,0.953688,-118.630699,294.500488,0.000000
124.750008,65.928551,-118.586212,-0.001095,0.003755,0.095369,293.264832,14.939624,0.953688,-118.586212,294.500488,0.000000
125.130005,65.919975,-118.586212,-0.001087,0.003755,0.095369,293.226685,14.937680,0.953688,-118.586212,294.500488,0.000000
125.510010,65.912910,-118.630699,-0.001082,0.003755,0.095369,293.195282,14.936079,0.953688,-118.630699,1681.640991,0.000000
125.890007,65.885353,-118.586212,-0.001091,0.003744,0.095091,293.072693,14.929834,0.950909,-118.586212,0.094883,0.000000
126.270004,65.745720,-118.630699,-0.001091,0.003721,0.094519,292.451569,14.898193,0.945187,-118.630699,0.094250,0.000000
126.650009,65.703636,-118.586212,-0.001095,0.003701,0.093999,292.264374,14.888658,0.939986,-118.586212,0.093617,0.000000
127.030006,65.625069,-118.630699,-0.001095,0.003681,0.093504,291.914886,14.870853,0.935043,-118.630699,0.092984,0.000000
127.410004,65.581123,-118.630699,-0.001095,0.003656,0.092854,291.719421,14.860894,0.928541,-118.630699,0.092351,0.000000
127.790009,65.564369,-118.630699,-0.001091,0.003633,0.092281,291.644867,14.857099,0.922810,-118.630699,0.091718,0.000000
128.170013,65.490273,-118.541733,-0.001087,0.003604,0.091535,291.315277,14.840308,0.915354,-118.541733,0.091085,0.000000
128.550003,65.477608,-118.541733,-0.001087,0.003581,0.090955,291.258942,14.837438,0.909548,-118.541733,0.090451,0.000000
128.930008,65.439247,-118.541733,-0.001095,0.003560,0.090426,291.088318,14.828745,0.904257,-118.541733,0.089819,0.000000
129.310013,65.338341,-118.586212,-0.001091,0.003533,0.089741,290.639465,14.805880,0.897406,-118.586212,0.089186,0.000000
129.690002,65.037086,-118.586212,-0.001095,0.003513,0.089229,289.299408,14.737615,0.892289,-118.586212,0.088552,0.000000
130.070007,64.049934,-118.541733,-0.001087,0.003484,0.088483,284.908325,14.513923,0.884833,-118.541733,0.087919,0.000000
130.450012,63.169273,-118.541733,-0.001091,0.003463,0.087962,280.990967,14.314363,0.879625,-118.541733,0.087286,0.000000
130.830002,61.977676,-118.586212,-0.001078,0.003442,0.087416,275.690460,14.044342,0.874159,-118.586212,0.086653,0.000000
131.210007,60.774170,-118.541733,-0.001091,0.003423,0.086956,270.337006,13.771624,0.869564,-118.541733,0.086020,0.000000
131.590012,58.884377,-118.541733,-0.001082,0.003397,0.086271,261.930786,13.343390,0.862714,-118.541733,0.085387,0.000000
131.970001,57.173325,-118.497253,-0.001091,0.003373,0.085673,254.319656,12.955661,0.856734,-118.497253,0.084754,0.000000
132.350006,54.853821,-118.497253,-0.001095,0.003347,0.085006,244.001984,12.430054,0.850057,-118.497253,0.084121,0.000000
132.730011,52.838165,-118.586212,-0.001082,0.003326,0.084477,235.035904,11.973299,0.844766,-118.586212,0.083488,0.000000
133.110001,50.582703,-118.497253,-0.001087,0.003304,0.083922,225.003098,11.462204,0.839217,-118.497253,0.082854,0.000000
133.490005,47.780228,-118.541733,-0.001091,0.003273,0.083124,212.537064,10.827154,0.831239,-118.541733,0.082222,0.000000
133.870010,45.014992,-118.541733,-0.001104,0.003249,0.082525,200.236679,10.200543,0.825251,-118.541733,0.081589,0.000000
134.250000,41.859512,-118.497253,-0.001087,0.003222,0.081832,186.200409,9.485501,0.818317,-118.497253,0.080955,0.000000
134.630005,39.368706,-118.452774,-0.001095,0.003201,0.081311,175.120743,8.921077,0.813109,-118.452774,0.080322,0.000000
135.010010,37.426041,-118.497253,-0.001095,0.003184,0.080886,166.479340,8.480863,0.808862,-118.497253,0.079689,0.000000
135.389999,34.001701,-118.452774,-0.001104,0.003152,0.080071,151.247116,7.704896,0.800710,-118.452774,0.079056,0.000000
135.770004,32.245224,-118.497253,-0.001087,0.003132,0.079559,143.433914,7.306872,0.795592,-118.497253,0.078423,0.000000
136.150009,28.708801,-118.452774,-0.001099,0.003100,0.078752,127.703125,6.505507,0.787523,-118.452774,0.077790,0.000000
136.530014,26.056396,-118.497253,-0.001091,0.003079,0.078207,115.904640,5.904464,0.782065,-118.497253,0.077157,0.000000
136.910004,23.733162,-118.497253,-0.001095,0.003055,0.077608,105.570374,5.378012,0.776078,-118.497253,0.076515,0.000000
137.290009,20.824562,-118.541733,-0.001095,0.003028,0.076914,92.632278,4.718914,0.769144,-118.541733,0.075882,0.000000
137.670013,18.849495,-118.452774,-0.001095,0.003013,0.076524,83.846741,4.271357,0.765238,-118.452774,0.075249,0.000000
138.050003,15.965103,-118.452774,-0.001087,0.002983,0.075769,71.016327,3.617744,0.757691,-118.452774,0.074616,0.000000
138.430008,12.952232,-118.363808,-0.001087,0.002956,0.075093,57.614407,2.935018,0.750931,-118.363808,0.073983,0.000000
138.810013,10.224976,-118.408295,-0.001095,0.002930,0.074434,45.482964,2.317013,0.744337,-118.408295,0.073350,0.000000
139.190002,7.629913,-118.452774,-0.001104,0.002908,0.073853,33.939548,1.728963,0.738531,-118.452774,0.072717,0.000000
139.570007,4.875107,-118.408295,-0.001112,0.002882,0.073202,21.685558,1.104715,0.732021,-118.408295,0.072084,0.000000
139.950012,2.188438,-118.408295,-0.001087,0.002854,0.072491,9.734660,0.495907,0.724913,-118.408295,0.071450,0.000000
140.330002,-0.362312,-118.363808,-0.001121,0.002831,0.071910,-1.611646,-0.082101,0.719100,-118.363808,0.070818,0.000000
140.710007,-2.182472,-118.408295,-0.001112,0.002811,0.071398,-9.708121,-0.494555,0.713983,-118.408295,0.070185,0.000000
141.090012,-0.964439,-118.408295,-0.001147,0.002789,0.070843,-4.290040,-0.218545,0.708434,-118.408295,0.069551,0.000000
141.470001,-0.548500,-118.363808,-0.001160,0.002756,0.070002,-2.439850,-0.124292,0.700024,-118.363808,0.068918,0.000000
141.850006,-0.510895,-118.363808,-0.001190,0.002733,0.069421,-2.272573,-0.115770,0.694210,-118.363808,0.068286,0.000000
142.230011,-0.516853,-118.363808,-0.001212,0.002704,0.068693,-2.299078,-0.117121,0.686928,-118.363808,0.067652,0.000000
142.610001,-0.491158,-118.408295,-0.001237,0.002682,0.068111,-2.184778,-0.111298,0.681115,-118.408295,0.067019,0.000000
142.990005,-0.444984,-118.363808,-0.001272,0.002660,0.067557,-1.979390,-0.100835,0.675566,-118.363808,0.066386,0.000000
143.370010,-0.490410,-118.408295,-0.001289,0.002629,0.066785,-2.181452,-0.111128,0.667852,-118.408295,0.065753,0.000000
143.750000,-0.488548,-118.319328,-0.001319,0.002601,0.066065,-2.173171,-0.110707,0.660653,-118.319328,0.065120,0.000000
144.130005,-0.496742,-118.319328,-0.001350,0.002577,0.065458,-2.209620,-0.112563,0.654582,-118.319328,0.064487,0.000000
144.510010,-0.454666,-118.319328,-0.001362,0.002553,0.064834,-2.022456,-0.103029,0.648337,-118.319328,0.063853,0.000000
144.889999,-0.459877,-118.408295,-0.001388,0.002532,0.064314,-2.045635,-0.104210,0.643137,-118.408295,0.063221,0.000000
145.270004,-0.474030,-118.319328,-0.001414,0.002501,0.063533,-2.108589,-0.107417,0.635332,-118.319328,0.062588,0.000000
145.650009,-0.463226,-118.319328,-0.001431,0.002488,0.063203,-2.060534,-0.104969,0.632032,-118.319328,0.061954,0.000000
146.030014,-0.518341,-118.319328,-0.001440,0.002453,0.062310,-2.305696,-0.117458,0.623100,-118.319328,0.061321,0.000000
146.410004,-0.489670,-118.274849,-0.001479,0.002432,0.061781,-2.178160,-0.110961,0.617808,-118.274849,0.060689,0.000000
146.790009,-0.488548,-118.319328,-0.001496,0.002405,0.061096,-2.173171,-0.110707,0.610958,-118.319328,0.060055,0.000000
147.170013,-0.494133,-118.363808,-0.001526,0.002380,0.060446,-2.198013,-0.111972,0.604455,-118.363808,0.059422,0.000000
147.550003,-0.492271,-118.319328,-0.001552,0.002355,0.059821,-2.189733,-0.111550,0.598210,-118.319328,0.058789,0.000000
147.930008,-0.490784,-118.274849,-0.001582,0.002323,0.059015,-2.183115,-0.111213,0.590148,-118.274849,0.058147,0.000000
148.310013,-0.496368,-118.319328,-0.001600,0.002298,0.058364,-2.207957,-0.112479,0.583638,-118.319328,0.057515,0.000000
148.690002,-0.515358,-118.230370,-0.001625,0.002283,0.057982,-2.292427,-0.116782,0.579823,-118.230370,0.056881,0.000000
149.070007,-0.519455,-118.319328,-0.001638,0.002253,0.057237,-2.310651,-0.117710,0.572367,-118.319328,0.056248,0.000000
149.450012,-0.504936,-118.319328,-0.001690,0.002234,0.056742,-2.246068,-0.114420,0.567424,-118.319328,0.055615,0.000000
149.830002,-0.477005,-118.230370,-0.001707,0.002201,0.055901,-2.121824,-0.108091,0.559014,-118.230370,0.054982,0.000000
150.210007,-0.525040,-118.230370,-0.001707,0.002178,0.055320,-2.335493,-0.118976,0.553200,-118.230370,0.054349,0.000000
150.590012,-0.478493,-118.274849,-0.001750,0.002161,0.054886,-2.128442,-0.108428,0.548863,-118.274849,0.053716,0.000000
150.970001,-0.490036,-118.319328,-0.001776,0.002124,0.053959,-2.179789,-0.111044,0.539590,-118.319328,0.053083,0.000000
151.350006,-0.510521,-118.230370,-0.001798,0.002106,0.053482,-2.270911,-0.115686,0.534821,-118.230370,0.052450,0.000000
151.730011,-0.516479,-118.230370,-0.001837,0.002073,0.052667,-2.297415,-0.117036,0.526668,-118.230370,0.051817,0.000000
152.110001,-0.525414,-118.230370,-0.001854,0.002051,0.052103,-2.337156,-0.119060,0.521029,-118.230370,0.051184,0.000000
152.490005,-0.536583,-118.274849,-0.001867,0.002040,0.051817,-2.386840,-0.121591,0.518167,-118.274849,0.050550,0.000000
152.870010,-0.507172,-118.274849,-0.001906,0.002002,0.050854,-2.256012,-0.114927,0.508538,-118.274849,0.049917,0.000000
153.250000,-0.521690,-118.319328,-0.001932,0.001984,0.050403,-2.320595,-0.118217,0.504034,-118.319328,0.049285,0.000000
153.630005,-0.524673,-118.185890,-0.001944,0.001950,0.049536,-2.333864,-0.118893,0.495359,-118.185890,0.048651,0.000000
154.010010,-0.533981,-118.185890,-0.001983,0.001928,0.048981,-2.375268,-0.121002,0.489811,-118.185890,0.048018,0.000000
154.390015,-0.532860,-118.230370,-0.001992,0.001904,0.048365,-2.370279,-0.120748,0.483649,-118.230370,0.047385,0.000000
154.770004,-0.530258,-118.230370,-0.002031,0.001893,0.048088,-2.358706,-0.120158,0.480878,-118.230370,0.046752,0.000000
155.150009,-0.538445,-118.230370,-0.002052,0.001852,0.047038,-2.395121,-0.122013,0.470379,-118.230370,0.046119,0.000000
155.530014,-0.537331,-118.141403,-0.002082,0.001825,0.046353,-2.390166,-0.121761,0.463529,-118.141403,0.045486,0.000000
155.800003,-0.494881,-118.230370,-0.002095,0.001822,0.046284,-2.201339,-0.112142,0.462840,-118.230370,0.046084,0.000000