File: Data/compression 26/AutoNoHeating-17-26-reverse-2-1_09262024_181431.csv
Time (sec),S:Load (lbs),S:HL1 (DIM),S:LVDT (in),S:Position (in),Ch:Position (mm),Ch:Load (N),Ch:Stress (MPa),Ch:Strain (mm/mm),Ch:HL1 (DIM),Set Point (),Cycles ()
0.110000,-0.477753,-122.856384,-0.009145,-0.004982,-0.126537,-2.125150,-0.108260,-1.265374,-122.856384,-0.126728,0.000000
0.470000,-0.469185,-122.811905,-0.009132,-0.004938,-0.125419,-2.087039,-0.106319,-1.254186,-122.811905,-0.124490,0.000000
0.830000,-0.483711,-122.856384,-0.009136,-0.004713,-0.119703,-2.151655,-0.109611,-1.197034,-122.856384,-0.118489,0.000000
1.190000,-0.484825,-122.811905,-0.008895,-0.004480,-0.113780,-2.156610,-0.109863,-1.137800,-122.811905,-0.112488,0.000000
1.550000,-0.465088,-122.722946,-0.008649,-0.004243,-0.107761,-2.068814,-0.105390,-1.077613,-122.722946,-0.106487,0.000000
1.910000,-0.472908,-122.767426,-0.008395,-0.004010,-0.101856,-2.103600,-0.107162,-1.018561,-122.767426,-0.100503,0.000000
2.270000,-0.453171,-122.722946,-0.008157,-0.003777,-0.095933,-2.015804,-0.102690,-0.959327,-122.722946,-0.094502,0.000000
2.630000,-0.477005,-122.722946,-0.007929,-0.003548,-0.090131,-2.121824,-0.108091,-0.901312,-122.722946,-0.088501,0.000000
2.990000,-0.487061,-122.767426,-0.007666,-0.003302,-0.083861,-2.166553,-0.110369,-0.838612,-122.767426,-0.082499,0.000000
3.350000,-0.469559,-122.767426,-0.007420,-0.003062,-0.077782,-2.088701,-0.106404,-0.777819,-122.767426,-0.076498,0.000000
3.710000,-0.467697,-122.767426,-0.007170,-0.002830,-0.071876,-2.080421,-0.105982,-0.718759,-122.767426,-0.070514,0.000000
4.070000,-0.459129,-122.678467,-0.006933,-0.002593,-0.065875,-2.042309,-0.104040,-0.658746,-122.678467,-0.064513,0.000000
4.430000,-0.448334,-122.767426,-0.006709,-0.002363,-0.060012,-1.994288,-0.101594,-0.600118,-122.767426,-0.058512,0.000000
4.790000,-0.475517,-122.722946,-0.006446,-0.002123,-0.053933,-2.115206,-0.107754,-0.539332,-122.722946,-0.052511,0.000000
5.150000,-0.483711,-122.767426,-0.006200,-0.001884,-0.047862,-2.151655,-0.109611,-0.478623,-122.767426,-0.046527,0.000000
5.510000,-0.480728,-122.722946,-0.005963,-0.001641,-0.041688,-2.138386,-0.108935,-0.416876,-122.722946,-0.040526,0.000000
5.870000,-0.436790,-122.678467,-0.005721,-0.001412,-0.035877,-1.942941,-0.098978,-0.358770,-122.678467,-0.034524,0.000000
6.230000,-0.439026,-122.722946,-0.005463,-0.001176,-0.029876,-1.952885,-0.099485,-0.298757,-122.722946,-0.028523,0.000000
6.590000,-0.442375,-122.678467,-0.005238,-0.000947,-0.024048,-1.967783,-0.100244,-0.240485,-122.678467,-0.022522,0.000000
6.950000,-0.456902,-122.633980,-0.004975,-0.000708,-0.017995,-2.032400,-0.103535,-0.179949,-122.633980,-0.016538,0.000000
7.310000,-0.386147,-122.633980,-0.004734,-0.000465,-0.011820,-1.717666,-0.087502,-0.118202,-122.633980,-0.010537,0.000000
7.670001,0.151932,-122.633980,-0.004652,-0.000000,-0.000000,0.675826,0.034428,-0.000000,-122.633980,0.000148,0.000000
8.030001,0.124001,-122.678467,-0.004639,-0.000000,-0.000009,0.551582,0.028099,-0.000091,-122.678467,0.000199,0.000000
8.390000,0.076714,-122.633980,-0.004648,-0.000000,-0.000000,0.341239,0.017384,-0.000000,-122.633980,0.000798,0.000000
8.750000,0.125496,-122.633980,-0.004648,0.000009,0.000234,0.558234,0.028438,0.002339,-122.633980,0.001396,0.000000
9.110001,0.404770,-122.678467,-0.004631,0.000038,0.000963,1.800506,0.091722,0.009629,-122.678467,0.002003,0.000000
9.470000,0.652771,-122.633980,-0.004605,0.000057,0.001448,2.903670,0.147920,0.014481,-122.633980,0.002602,0.000000
9.830001,0.861671,-122.589500,-0.004596,0.000080,0.002038,3.832906,0.195258,0.020378,-122.589500,0.003200,0.000000
10.190001,1.376663,-122.589500,-0.004562,0.000108,0.002749,6.123704,0.311956,0.027493,-122.589500,0.003799,0.000000
10.550000,1.613121,-122.589500,-0.004540,0.000128,0.003252,7.175521,0.365538,0.032520,-122.589500,0.004397,0.000000
10.910001,2.054008,-122.633980,-0.004518,0.000159,0.004042,9.136686,0.465445,0.040415,-122.633980,0.005004,0.000000
11.270000,2.271477,-122.589500,-0.004510,0.000179,0.004544,10.104033,0.514724,0.045441,-122.589500,0.005602,0.000000
11.630000,2.573845,-122.633980,-0.004484,0.000196,0.004986,11.449034,0.583242,0.049862,-122.633980,0.006200,0.000000
11.990001,3.027390,-122.589500,-0.004480,0.000222,0.005646,13.466501,0.686016,0.056455,-122.589500,0.006799,0.000000
12.350000,3.524139,-122.589500,-0.004441,0.000252,0.006409,15.676155,0.798581,0.064086,-122.589500,0.007397,0.000000
12.710001,3.707718,-122.545021,-0.004432,0.000276,0.007007,16.492752,0.840181,0.070074,-122.545021,0.008004,0.000000
13.070001,4.256218,-122.545021,-0.004402,0.000302,0.007675,18.932604,0.964473,0.076750,-122.545021,0.008603,0.000000
13.430000,4.384315,-122.589500,-0.004385,0.000322,0.008178,19.502409,0.993500,0.081776,-122.589500,0.009201,0.000000
13.790001,4.676628,-122.545021,-0.004372,0.000340,0.008629,20.802681,1.059739,0.086288,-122.545021,0.009800,0.000000
14.150001,4.919785,-122.589500,-0.004346,0.000358,0.009097,21.884295,1.114839,0.090974,-122.589500,0.010398,0.000000
14.510000,5.203163,-122.545021,-0.004329,0.000381,0.009678,23.144825,1.179054,0.096780,-122.545021,0.011005,0.000000
14.870001,5.674957,-122.500542,-0.004294,0.000408,0.010363,25.243471,1.285964,0.103630,-122.500542,0.011604,0.000000
15.230000,5.869339,-122.589500,-0.004286,0.000431,0.010944,26.108124,1.330011,0.109444,-122.589500,0.012202,0.000000
15.590001,6.276711,-122.545021,-0.004255,0.000457,0.011612,27.920202,1.422323,0.116121,-122.545021,0.012801,0.000000
15.950001,6.586525,-122.500542,-0.004234,0.000486,0.012332,29.298326,1.492528,0.123319,-122.500542,0.013399,0.000000
16.310001,6.704567,-122.500542,-0.004221,0.000505,0.012835,29.823402,1.519277,0.128346,-122.500542,0.013997,0.000000
16.670000,6.743294,-122.456055,-0.004178,0.000529,0.013424,29.995668,1.528052,0.134243,-122.456055,0.014604,0.000000
17.030001,7.177856,-122.500542,-0.004161,0.000557,0.014144,31.928699,1.626526,0.141442,-122.500542,0.015202,0.000000
17.390001,7.313774,-122.411575,-0.004139,0.000579,0.014716,32.533291,1.657325,0.147164,-122.411575,0.015800,0.000000
17.750000,7.329407,-122.500542,-0.004118,0.000601,0.015255,32.602829,1.660867,0.152546,-122.500542,0.016399,0.000000
18.110001,7.683167,-122.500542,-0.004100,0.000624,0.015844,34.176430,1.741030,0.158443,-122.500542,0.016997,0.000000
18.470001,7.711090,-122.456055,-0.004074,0.000645,0.016382,34.300640,1.747358,0.163818,-122.456055,0.017604,0.000000
18.830002,7.917755,-122.500542,-0.004044,0.000667,0.016954,35.219933,1.794189,0.169541,-122.500542,0.018203,0.000000
19.190001,8.056656,-122.411575,-0.004014,0.000689,0.017501,35.837795,1.825664,0.175006,-122.411575,0.018801,0.000000
19.550001,8.364975,-122.411575,-0.003997,0.000717,0.018211,37.209267,1.895530,0.182114,-122.411575,0.019400,0.000000
19.910002,8.626381,-122.367096,-0.003980,0.000745,0.018931,38.372059,1.954766,0.189313,-122.367096,0.019998,0.000000
20.270000,8.490471,-122.411575,-0.003949,0.000763,0.019382,37.767502,1.923968,0.193824,-122.411575,0.020605,0.000000
20.630001,8.558983,-122.411575,-0.003932,0.000786,0.019955,38.072258,1.939493,0.199547,-122.411575,0.021204,0.000000
20.990002,8.671066,-122.411575,-0.003915,0.000806,0.020466,38.570827,1.964892,0.204664,-122.411575,0.021802,0.000000
21.350000,8.844223,-122.411575,-0.003885,0.000834,0.021177,39.341068,2.004130,0.211772,-122.411575,0.022401,0.000000
21.710001,9.170792,-122.456055,-0.003876,0.000857,0.021776,40.793720,2.078131,0.217760,-122.456055,0.022999,0.000000
22.070002,9.254578,-122.367096,-0.003824,0.000884,0.022453,41.166416,2.097117,0.224528,-122.367096,0.023606,0.000000
22.430000,9.441505,-122.456055,-0.003824,0.000907,0.023042,41.997913,2.139476,0.230424,-122.456055,0.024204,0.000000
22.790001,9.566628,-122.322617,-0.003777,0.000932,0.023684,42.554485,2.167829,0.236836,-122.322617,0.024802,0.000000
23.150002,9.315643,-122.456055,-0.003751,0.000945,0.023996,41.438049,2.110955,0.239962,-122.456055,0.025401,0.000000
23.510000,9.433311,-122.411575,-0.003755,0.000964,0.024473,41.961464,2.137619,0.244731,-122.411575,0.025999,0.000000
23.870001,10.127792,-122.322617,-0.003712,0.001002,0.025453,45.050671,2.294991,0.254527,-122.322617,0.026598,0.000000
24.230001,9.936760,-122.322617,-0.003691,0.001019,0.025878,44.200916,2.251702,0.258781,-122.322617,0.027205,0.000000
24.590002,10.260353,-122.278137,-0.003678,0.001045,0.026537,45.640331,2.325029,0.265374,-122.278137,0.027803,0.000000
24.950001,10.305786,-122.322617,-0.003660,0.001067,0.027101,45.842426,2.335325,0.271006,-122.322617,0.028402,0.000000
25.310001,10.520271,-122.322617,-0.003626,0.001092,0.027743,46.796505,2.383928,0.277425,-122.322617,0.029000,0.000000
25.670002,10.846092,-122.367096,-0.003591,0.001120,0.028445,48.245827,2.457760,0.284450,-122.367096,0.029599,0.000000
26.030001,10.888176,-122.367096,-0.003570,0.001144,0.029070,48.433025,2.467296,0.290695,-122.367096,0.030206,0.000000
26.390001,10.619324,-122.322617,-0.003535,0.001157,0.029399,47.237110,2.406373,0.293988,-122.322617,0.030804,0.000000
26.750002,10.928391,-122.278137,-0.003535,0.001186,0.030127,48.611908,2.476409,0.301270,-122.278137,0.031403,0.000000
27.110001,11.145859,-122.278137,-0.003510,0.001211,0.030761,49.579254,2.525688,0.307606,-122.278137,0.032001,0.000000
27.470001,11.601639,-122.278137,-0.003479,0.001242,0.031558,51.606667,2.628969,0.315585,-122.278137,0.032599,0.000000
27.830002,11.643349,-122.278137,-0.003449,0.001267,0.032183,51.792202,2.638421,0.321830,-122.278137,0.033206,0.000000
28.190001,11.641479,-122.233650,-0.003445,0.001290,0.032764,51.783886,2.637997,0.327636,-122.233650,0.033804,0.000000
28.550001,11.769211,-122.278137,-0.003410,0.001309,0.033240,52.352066,2.666941,0.332405,-122.278137,0.034402,0.000000
28.910002,11.785217,-122.278137,-0.003402,0.001330,0.033779,52.423264,2.670568,0.337787,-122.278137,0.035001,0.000000
29.270000,12.065613,-122.189171,-0.003359,0.001356,0.034437,53.670525,2.734107,0.344372,-122.189171,0.035599,0.000000
29.630001,12.294998,-122.233650,-0.003346,0.001383,0.035131,54.690884,2.786086,0.351314,-122.233650,0.036206,0.000000
29.990002,12.129288,-122.233650,-0.003328,0.001403,0.035634,53.953766,2.748536,0.356340,-122.233650,0.036805,0.000000
30.350002,12.688965,-122.233650,-0.003307,0.001433,0.036389,56.443336,2.875361,0.363887,-122.233650,0.037403,0.000000
30.710001,12.580605,-122.278137,-0.003285,0.001451,0.036866,55.961323,2.850806,0.368656,-122.278137,0.038002,0.000000
31.070002,12.458466,-122.233650,-0.003260,0.001469,0.037317,55.418022,2.823129,0.373168,-122.233650,0.038600,0.000000
31.430002,13.012184,-122.233650,-0.003238,0.001499,0.038062,57.881084,2.948603,0.380624,-122.233650,0.039207,0.000000
31.790001,13.221458,-122.189171,-0.003203,0.001525,0.038747,58.811985,2.996025,0.387475,-122.189171,0.039806,0.000000
32.150002,13.283646,-122.189171,-0.003195,0.001552,0.039424,59.088608,3.010117,0.394242,-122.189171,0.040404,0.000000
32.510002,13.331680,-122.189171,-0.003165,0.001575,0.040005,59.302277,3.021002,0.400048,-122.189171,0.041003,0.000000
32.870003,13.395729,-122.100212,-0.003143,0.001595,0.040508,59.587177,3.035516,0.405082,-122.100212,0.041601,0.000000
33.230003,13.690651,-122.233650,-0.003122,0.001619,0.041124,60.899055,3.102346,0.411236,-122.233650,0.042199,0.000000
33.590000,14.067863,-122.144691,-0.003104,0.001647,0.041835,62.576981,3.187824,0.418352,-122.144691,0.042806,0.000000
33.950001,13.842949,-122.144691,-0.003083,0.001662,0.042217,61.576511,3.136857,0.422167,-122.144691,0.043404,0.000000
34.310001,14.503166,-122.189171,-0.003074,0.001696,0.043083,64.513306,3.286464,0.430835,-122.189171,0.044003,0.000000
34.670002,14.331871,-122.144691,-0.003035,0.001716,0.043587,63.751347,3.247648,0.435869,-122.144691,0.044601,0.000000
35.030003,14.438370,-122.189171,-0.003022,0.001736,0.044107,64.225075,3.271781,0.441069,-122.189171,0.045200,0.000000
35.390003,14.522530,-122.100212,-0.003014,0.001756,0.044610,64.599442,3.290852,0.446103,-122.100212,0.045807,0.000000
35.750000,14.679672,-122.100212,-0.002984,0.001779,0.045191,65.298447,3.326461,0.451909,-122.100212,0.046405,0.000000
36.110001,15.156303,-122.144691,-0.002962,0.001806,0.045868,67.418602,3.434467,0.458676,-122.144691,0.047004,0.000000
36.470001,15.019272,-122.144691,-0.002932,0.001827,0.046405,66.809059,3.403416,0.464051,-122.144691,0.047602,0.000000
36.830002,15.684700,-122.144691,-0.002919,0.001856,0.047133,69.769028,3.554204,0.471333,-122.144691,0.048201,0.000000
37.190002,15.062096,-122.100212,-0.002897,0.001861,0.047273,66.999550,3.413120,0.472726,-122.100212,0.048808,0.000000
37.550003,16.089104,-122.100212,-0.002871,0.001900,0.048261,71.567909,3.645843,0.482612,-122.100212,0.049406,0.000000
37.910004,15.878708,-122.055733,-0.002863,0.001921,0.048781,70.632019,3.598166,0.487812,-122.055733,0.050005,0.000000
38.270000,15.929726,-122.055733,-0.002824,0.001942,0.049336,70.858955,3.609727,0.493361,-122.055733,0.050603,0.000000
38.630001,16.139374,-122.144691,-0.002798,0.001966,0.049935,71.791519,3.657234,0.499349,-122.144691,0.051201,0.000000
38.990002,16.585472,-122.055733,-0.002785,0.001991,0.050559,73.775864,3.758322,0.505594,-122.055733,0.051808,0.000000
39.350002,16.745964,-121.966766,-0.002768,0.002016,0.051210,74.489769,3.794690,0.512096,-121.966766,0.052406,0.000000
39.710003,17.080353,-122.055733,-0.002734,0.002040,0.051808,75.977203,3.870463,0.518076,-122.055733,0.053004,0.000000
40.070004,17.390915,-122.055733,-0.002721,0.002063,0.052406,77.358650,3.940838,0.524064,-122.055733,0.053603,0.000000
40.430000,17.171585,-122.100212,-0.002716,0.002084,0.052926,76.383026,3.891137,0.529265,-122.100212,0.054201,0.000000
40.790001,17.852654,-122.011246,-0.002673,0.002112,0.053646,79.412567,4.045469,0.536463,-122.011246,0.054800,0.000000
41.150002,17.768127,-122.055733,-0.002656,0.002133,0.054185,79.036575,4.026315,0.541846,-122.055733,0.055407,0.000000
41.510002,18.316261,-122.055733,-0.002639,0.002156,0.054774,81.474800,4.150524,0.547742,-122.055733,0.056005,0.000000
41.870003,18.329666,-121.966766,-0.002617,0.002176,0.055277,81.534424,4.153562,0.552769,-121.966766,0.056604,0.000000
42.230003,18.757896,-122.011246,-0.002600,0.002202,0.055936,83.439293,4.250600,0.559362,-122.011246,0.057202,0.000000
42.590000,18.613785,-121.966766,-0.002583,0.002220,0.056387,82.798248,4.217944,0.563866,-121.966766,0.057801,0.000000
42.950001,19.875381,-121.966766,-0.002561,0.002256,0.057306,88.410110,4.503826,0.573063,-121.966766,0.058408,0.000000
43.310001,19.773727,-121.966766,-0.002522,0.002276,0.057818,87.957932,4.480791,0.578181,-121.966766,0.059006,0.000000
43.670002,20.002731,-121.966766,-0.002509,0.002301,0.058433,88.976593,4.532684,0.584335,-121.966766,0.059605,0.000000
44.030003,20.530014,-121.966766,-0.002488,0.002325,0.059050,91.322060,4.652167,0.590497,-121.966766,0.060203,0.000000
44.390003,20.195999,-122.011246,-0.002462,0.002342,0.059483,89.836288,4.576479,0.594827,-122.011246,0.060801,0.000000
44.750004,20.492401,-122.055733,-0.002449,0.002363,0.060029,91.154755,4.643644,0.600292,-122.055733,0.061408,0.000000
45.110001,21.762939,-121.966766,-0.002427,0.002398,0.060905,96.806389,4.931552,0.609050,-121.966766,0.062006,0.000000
45.470001,21.738365,-121.922287,-0.002414,0.002417,0.061399,96.697075,4.925984,0.613993,-121.922287,0.062605,0.000000
45.830002,21.310509,-121.922287,-0.002384,0.002429,0.061695,94.793877,4.829031,0.616945,-121.922287,0.063203,0.000000
46.190002,22.519974,-121.877808,-0.002363,0.002465,0.062623,100.173843,5.103099,0.626226,-121.877808,0.063802,0.000000
46.550003,22.485344,-121.922287,-0.002337,0.002487,0.063160,100.019806,5.095252,0.631601,-121.922287,0.064409,0.000000
46.910004,23.325783,-121.966766,-0.002315,0.002513,0.063828,103.758263,5.285698,0.638277,-121.966766,0.065007,0.000000
47.270000,23.662415,-121.922287,-0.002302,0.002537,0.064452,105.255676,5.361980,0.644522,-121.922287,0.065606,0.000000
47.630001,23.741730,-121.966766,-0.002285,0.002556,0.064921,105.608490,5.379953,0.649208,-121.966766,0.066204,0.000000
47.990002,24.597069,-121.877808,-0.002246,0.002586,0.065675,109.413223,5.573776,0.656747,-121.877808,0.066803,0.000000
48.350002,24.220596,-121.877808,-0.002229,0.002605,0.066178,107.738594,5.488465,0.661781,-121.877808,0.067401,0.000000
48.710003,25.541031,-121.877808,-0.002212,0.002636,0.066967,113.612183,5.787680,0.669669,-121.877808,0.068008,0.000000
49.070004,26.075386,-121.877808,-0.002199,0.002659,0.067539,115.989113,5.908767,0.675392,-121.877808,0.068607,0.000000
49.430004,25.884361,-121.877808,-0.002173,0.002673,0.067904,115.139389,5.865480,0.679040,-121.877808,0.069205,0.000000
49.790001,26.859970,-121.877808,-0.002156,0.002707,0.068762,119.479111,6.086556,0.687625,-121.877808,0.069803,0.000000
50.150002,27.279640,-121.877808,-0.002139,0.002728,0.069283,121.345901,6.181655,0.692825,-121.877808,0.070401,0.000000
50.510002,27.871712,-121.922287,-0.002126,0.002750,0.069837,123.979568,6.315820,0.698374,-121.922287,0.071008,0.000000
50.870003,28.735611,-121.788841,-0.002095,0.002778,0.070549,127.822380,6.511582,0.705489,-121.788841,0.071606,0.000000
51.230003,29.006699,-121.833328,-0.002082,0.002797,0.071034,129.028244,6.573012,0.710342,-121.833328,0.072205,0.000000
51.590004,29.436417,-121.788841,-0.002048,0.002819,0.071606,130.939728,6.670387,0.716064,-121.788841,0.072803,0.000000
51.950001,29.987526,-121.833328,-0.002031,0.002841,0.072162,133.391174,6.795271,0.721621,-121.833328,0.073402,0.000000
52.310001,29.956253,-121.877808,-0.002018,0.002857,0.072569,133.252075,6.788184,0.725693,-121.877808,0.074009,0.000000
52.670002,31.643471,-121.788841,-0.002005,0.002891,0.073428,140.757187,7.170513,0.734277,-121.788841,0.074607,0.000000
53.030003,31.845299,-121.877808,-0.001983,0.002914,0.074026,141.654968,7.216248,0.740265,-121.877808,0.075206,0.000000
53.390003,33.608482,-121.788841,-0.001957,0.002947,0.074842,149.498001,7.615791,0.748418,-121.788841,0.075804,0.000000
53.750004,33.825569,-121.788841,-0.001936,0.002969,0.075405,150.463654,7.664984,0.754049,-121.788841,0.076403,0.000000
54.110004,34.327156,-121.833328,-0.001932,0.002990,0.075934,152.694809,7.778645,0.759341,-121.833328,0.077010,0.000000
54.470001,34.774750,-121.744362,-0.001914,0.003008,0.076403,154.685806,7.880071,0.764026,-121.744362,0.077608,0.000000
54.830002,35.612961,-121.788841,-0.001893,0.003033,0.077027,158.414368,8.070012,0.770272,-121.788841,0.078207,0.000000
55.190002,36.736038,-121.788841,-0.001863,0.003060,0.077730,163.410065,8.324506,0.777296,-121.788841,0.078805,0.000000
55.550003,37.679253,-121.744362,-0.001854,0.003087,0.078397,167.605682,8.538240,0.783973,-121.744362,0.079403,0.000000
55.910004,38.180099,-121.788841,-0.001828,0.003109,0.078970,169.833557,8.651734,0.789696,-121.788841,0.080001,0.000000
56.270004,38.784828,-121.744362,-0.001811,0.003128,0.079446,172.523529,8.788768,0.794465,-121.744362,0.080608,0.000000
56.630001,39.478935,-121.744362,-0.001789,0.003149,0.079976,175.611069,8.946054,0.799756,-121.744362,0.081207,0.000000
56.990002,40.180481,-121.699883,-0.001785,0.003174,0.080618,178.731705,9.105026,0.806175,-121.699883,0.081805,0.000000
57.350002,41.319199,-121.744362,-0.001768,0.003200,0.081276,183.796982,9.363064,0.812761,-121.744362,0.082404,0.000000
57.710003,42.126129,-121.744362,-0.001746,0.003217,0.081719,187.386383,9.545917,0.817189,-121.744362,0.083002,0.000000
58.070004,42.686546,-121.744362,-0.001742,0.003238,0.082247,189.879242,9.672910,0.822473,-121.744362,0.083609,0.000000
58.430004,43.739243,-121.699883,-0.001716,0.003260,0.082794,194.561874,9.911454,0.827938,-121.699883,0.084208,0.000000
58.790001,45.759369,-121.744362,-0.001699,0.003295,0.083687,203.547836,10.369221,0.836871,-121.744362,0.084806,0.000000
59.150002,46.216637,-121.699883,-0.001686,0.003315,0.084199,205.581863,10.472839,0.841988,-121.699883,0.085405,0.000000
59.510002,47.482330,-121.744362,-0.001669,0.003337,0.084754,211.211960,10.759650,0.847536,-121.744362,0.086003,0.000000
59.870003,48.723076,-121.699883,-0.001647,0.003363,0.085413,216.731064,11.040807,0.854130,-121.699883,0.086610,0.000000
60.230003,49.814133,-121.655403,-0.001647,0.003388,0.086063,221.584335,11.288043,0.860632,-121.655403,0.087209,0.000000
60.590004,51.165100,-121.699883,-0.001621,0.003412,0.086662,227.593735,11.594177,0.866620,-121.699883,0.087807,0.000000
60.950005,51.987297,-121.655403,-0.001630,0.003431,0.087156,231.251053,11.780490,0.871563,-121.655403,0.088405,0.000000
61.310001,52.575645,-121.655403,-0.001587,0.003455,0.087763,233.868149,11.913812,0.877634,-121.655403,0.089003,0.000000
61.670002,54.387978,-121.699883,-0.001591,0.003479,0.088361,241.929810,12.324492,0.883614,-121.699883,0.089610,0.000000
62.030003,54.965157,-121.655403,-0.001574,0.003503,0.088968,244.497223,12.455282,0.889685,-121.655403,0.090208,0.000000
62.390003,56.465073,-121.655403,-0.001574,0.003523,0.089472,251.169189,12.795168,0.894719,-121.655403,0.090807,0.000000
62.750004,57.837265,-121.655403,-0.001539,0.003551,0.090200,257.273010,13.106112,0.902001,-121.655403,0.091405,0.000000
63.110004,59.548691,-121.655403,-0.001531,0.003575,0.090798,264.885803,13.493926,0.907981,-121.655403,0.092004,0.000000
63.470001,60.300140,-121.610924,-0.001531,0.003594,0.091292,268.228424,13.664207,0.912924,-121.610924,0.092602,0.000000
63.830002,61.338684,-121.610924,-0.001513,0.003615,0.091822,272.848083,13.899544,0.918216,-121.610924,0.093209,0.000000
64.190002,63.543877,-121.655403,-0.001500,0.003649,0.092680,282.657288,14.399248,0.926800,-121.655403,0.093808,0.000000
64.550003,65.143593,-121.610924,-0.001487,0.003672,0.093270,289.773163,14.761749,0.932704,-121.610924,0.094406,0.000000
64.910004,65.404243,-121.655403,-0.001475,0.003684,0.093582,290.932617,14.820813,0.935823,-121.655403,0.095005,0.000000
65.270004,66.300926,-121.655403,-0.001462,0.003699,0.093946,294.921234,15.024004,0.939464,-121.655403,0.094164,0.000000
65.630005,65.182320,-121.610924,-0.001444,0.003699,0.093946,289.945435,14.770525,0.939464,-121.610924,294.500488,0.000000
65.990005,64.246544,-121.566437,-0.001444,0.003699,0.093964,285.782898,14.558475,0.939638,-121.566437,294.500488,0.000000
66.350006,66.388420,-121.566437,-0.001414,0.003595,0.091302,295.310455,15.043831,0.913015,-121.566437,294.500488,0.000000
66.710007,65.534950,-121.566437,-0.001414,0.003619,0.091917,291.514008,14.850431,0.919169,-121.566437,294.500488,0.000000
67.070000,64.936546,-121.566437,-0.001418,0.003712,0.094276,288.852173,14.714832,0.942757,-121.566437,294.500488,0.000000
67.430000,65.247108,-121.566437,-0.001406,0.003736,0.094900,290.233643,14.785206,0.949002,-121.566437,294.500488,0.000000
67.790001,64.811058,-121.521957,-0.001414,0.003737,0.094918,288.293976,14.686396,0.949176,-121.521957,294.500488,0.000000
68.150002,64.721687,-121.521957,-0.001406,0.003742,0.095057,287.896454,14.666143,0.950569,-121.521957,294.500488,0.000000
68.510002,65.488396,-121.521957,-0.001397,0.003755,0.095386,291.306946,14.839883,0.953862,-121.521957,294.500488,0.000000
68.870003,65.073586,-121.477478,-0.001393,0.003755,0.095386,289.461761,14.745886,0.953862,-121.477478,294.500488,0.000000
69.230003,64.674019,-121.477478,-0.001397,0.003756,0.095394,287.684418,14.655342,0.953945,-121.477478,294.500488,0.000000
69.590004,64.251747,-121.521957,-0.001388,0.003756,0.095394,285.806030,14.559654,0.953945,-121.521957,294.500488,0.000000
69.950005,66.631218,-121.521957,-0.001362,0.003692,0.093765,296.390472,15.098849,0.937647,-121.521957,294.500488,0.000000
70.310005,66.106544,-121.477478,-0.001362,0.003692,0.093765,294.056610,14.979957,0.937647,-121.477478,294.500488,0.000000
70.670006,65.691353,-121.521957,-0.001371,0.003695,0.093860,292.209717,14.885874,0.938601,-121.521957,294.500488,0.000000
71.030006,65.280998,-121.477478,-0.001358,0.003739,0.094978,290.384369,14.792886,0.949782,-121.477478,294.500488,0.000000
71.390007,64.958138,-121.566437,-0.001354,0.003747,0.095178,288.948212,14.719725,0.951780,-121.566437,294.500488,0.000000
71.750000,65.398293,-121.477478,-0.001367,0.003785,0.096132,290.906128,14.819465,0.961318,-121.477478,294.500488,0.000000
72.110001,65.187157,-121.477478,-0.001358,0.003784,0.096123,289.966949,14.771621,0.961235,-121.477478,294.500488,0.000000
72.470001,65.060173,-121.521957,-0.001354,0.003788,0.096210,289.402100,14.742846,0.962098,-121.521957,294.500488,0.000000
72.830002,64.931709,-121.432999,-0.001354,0.003788,0.096227,288.830658,14.713736,0.962272,-121.432999,294.500488,0.000000
73.190002,65.346901,-121.432999,-0.001358,0.003796,0.096418,290.677521,14.807819,0.964179,-121.432999,294.500488,0.000000
73.550003,65.146935,-121.388512,-0.001367,0.003796,0.096418,289.788025,14.762506,0.964179,-121.388512,294.500488,0.000000
73.910004,65.100761,-121.432999,-0.001345,0.003799,0.096488,289.582642,14.752044,0.964876,-121.432999,294.500488,0.000000
74.270004,64.972664,-121.388512,-0.001362,0.003800,0.096531,289.012848,14.723016,0.965307,-121.388512,294.500488,0.000000
74.630005,64.944374,-121.432999,-0.001362,0.003801,0.096557,288.886993,14.716606,0.965572,-121.432999,294.500488,0.000000
74.990005,65.269447,-121.432999,-0.001354,0.003808,0.096721,290.333008,14.790268,0.967215,-121.432999,294.500488,0.000000
75.350006,65.146568,-121.388512,-0.001345,0.003808,0.096721,289.786407,14.762424,0.967215,-121.388512,294.500488,0.000000
75.710007,65.226250,-121.432999,-0.001345,0.003812,0.096834,290.140839,14.780479,0.968343,-121.432999,294.500488,0.000000
76.070007,65.177849,-121.432999,-0.001350,0.003812,0.096834,289.925537,14.769512,0.968343,-121.432999,294.500488,0.000000
76.430000,65.024803,-121.344032,-0.001337,0.003813,0.096843,289.244781,14.734831,0.968433,-121.344032,294.500488,0.000000
76.790001,65.056450,-121.432999,-0.001337,0.003815,0.096904,289.385529,14.742002,0.969039,-121.432999,294.500488,0.000000
77.150002,64.951439,-121.344032,-0.001345,0.003816,0.096921,288.918427,14.718206,0.969213,-121.344032,294.500488,0.000000
77.510002,64.808830,-121.432999,-0.001337,0.003816,0.096921,288.284088,14.685891,0.969213,-121.432999,294.500488,0.000000
77.870003,65.167046,-121.344032,-0.001337,0.003823,0.097103,289.877502,14.767064,0.971030,-121.344032,294.500488,0.000000
78.230003,65.216576,-121.344032,-0.001337,0.003823,0.097103,290.097809,14.778287,0.971030,-121.344032,294.500488,0.000000
78.590004,65.081398,-121.388512,-0.001337,0.003823,0.097103,289.496521,14.747656,0.971030,-121.388512,294.500488,0.000000
78.950005,64.976021,-121.388512,-0.001328,0.003823,0.097112,289.027771,14.723777,0.971121,-121.388512,294.500488,0.000000
79.310005,64.839363,-121.388512,-0.001328,0.003823,0.097112,288.419891,14.692809,0.971121,-121.388512,294.500488,0.000000
79.670006,64.701958,-121.344032,-0.001337,0.003823,0.097112,287.808685,14.661674,0.971121,-121.344032,294.500488,0.000000
80.030006,65.764702,-121.344032,-0.001319,0.003836,0.097433,292.536011,14.902494,0.974330,-121.344032,294.500488,0.000000
80.390007,65.671989,-121.344032,-0.001319,0.003836,0.097433,292.123596,14.881485,0.974330,-121.344032,294.500488,0.000000
80.750008,65.580009,-121.344032,-0.001332,0.003836,0.097433,291.714447,14.860642,0.974330,-121.344032,294.500488,0.000000
81.110001,65.489143,-121.299553,-0.001324,0.003836,0.097433,291.310272,14.840053,0.974330,-121.299553,294.500488,0.000000
81.470001,65.348763,-121.344032,-0.001328,0.003836,0.097433,290.685822,14.808242,0.974330,-121.344032,294.500488,0.000000
81.830002,65.248970,-121.255074,-0.001319,0.003836,0.097441,290.241913,14.785628,0.974414,-121.255074,294.500488,0.000000
82.190002,65.139870,-121.344032,-0.001328,0.003837,0.097450,289.756622,14.760905,0.974504,-121.344032,294.500488,0.000000
82.550003,65.017723,-121.255074,-0.001319,0.003837,0.097450,289.213287,14.733227,0.974504,-121.255074,294.500488,0.000000
82.910004,64.947350,-121.255074,-0.001311,0.003837,0.097459,288.900238,14.717279,0.974588,-121.255074,294.500488,0.000000
83.270004,65.024422,-121.299553,-0.001315,0.003840,0.097537,289.243073,14.734745,0.975367,-121.299553,294.500488,0.000000
83.630005,64.978630,-121.255074,-0.001315,0.003840,0.097537,289.039368,14.724368,0.975367,-121.255074,294.500488,0.000000
83.990005,64.877342,-121.299553,-0.001311,0.003840,0.097537,288.588837,14.701416,0.975367,-121.299553,294.500488,0.000000
84.350006,64.801003,-121.210594,-0.001324,0.003841,0.097554,288.249268,14.684117,0.975542,-121.210594,294.500488,0.000000
84.710007,64.735466,-121.255074,-0.001311,0.003841,0.097554,287.957733,14.669267,0.975542,-121.255074,294.500488,0.000000
85.070007,65.685020,-121.255074,-0.001315,0.003852,0.097840,292.181549,14.884439,0.978403,-121.255074,294.500488,0.000000
85.430000,65.671608,-121.166107,-0.001315,0.003852,0.097840,292.121887,14.881399,0.978403,-121.166107,294.500488,0.000000
85.790001,65.615379,-121.299553,-0.001311,0.003852,0.097840,291.871796,14.868657,0.978403,-121.299553,294.500488,0.000000
86.150002,65.547234,-121.255074,-0.001324,0.003852,0.097840,291.568665,14.853215,0.978403,-121.255074,294.500488,0.000000
86.510002,65.476860,-121.166107,-0.001319,0.003852,0.097840,291.255615,14.837269,0.978403,-121.166107,294.500488,0.000000
86.870003,65.372231,-121.255074,-0.001302,0.003852,0.097840,290.790192,14.813560,0.978403,-121.255074,294.500488,0.000000
87.230003,65.302589,-121.166107,-0.001306,0.003852,0.097840,290.480438,14.797779,0.978403,-121.166107,294.500488,0.000000
87.590004,65.233330,-121.255074,-0.001306,0.003852,0.097840,290.172333,14.782084,0.978403,-121.255074,294.500488,0.000000
87.950005,65.120506,-121.166107,-0.001311,0.003852,0.097840,289.670471,14.756518,0.978403,-121.166107,294.500488,0.000000
88.310005,65.056816,-121.166107,-0.001302,0.003854,0.097883,289.387177,14.742085,0.978834,-121.166107,294.500488,0.000000
88.670006,65.022194,-121.210594,-0.001306,0.003854,0.097883,289.233154,14.734240,0.978834,-121.210594,294.500488,0.000000
89.030006,64.971184,-121.121628,-0.001311,0.003854,0.097883,289.006256,14.722681,0.978834,-121.121628,294.500488,0.000000
89.390007,64.880318,-121.121628,-0.001315,0.003854,0.097883,288.602081,14.702090,0.978834,-121.121628,294.500488,0.000000
89.750008,65.212471,-121.121628,-0.001306,0.003860,0.098048,290.079559,14.777357,0.980485,-121.121628,294.500488,0.000000
90.110001,65.300362,-121.166107,-0.001311,0.003860,0.098048,290.470520,14.797274,0.980485,-121.166107,294.500488,0.000000
90.470001,65.264977,-121.166107,-0.001306,0.003860,0.098048,290.313110,14.789255,0.980485,-121.166107,294.500488,0.000000
90.830002,65.215828,-121.121628,-0.001302,0.003860,0.098048,290.094482,14.778117,0.980485,-121.121628,294.500488,0.000000
91.190002,65.137260,-121.121628,-0.001315,0.003860,0.098048,289.744995,14.760314,0.980485,-121.121628,294.500488,0.000000
91.550003,65.067253,-121.121628,-0.001306,0.003860,0.098048,289.433594,14.744451,0.980485,-121.121628,294.500488,0.000000
91.910004,65.031136,-121.121628,-0.001311,0.003861,0.098057,289.272949,14.736266,0.980568,-121.121628,294.500488,0.000000
92.270004,64.985695,-121.121628,-0.001298,0.003861,0.098066,289.070801,14.725968,0.980659,-121.121628,294.500488,0.000000
92.630005,64.955910,-121.077148,-0.001302,0.003862,0.098083,288.938324,14.719219,0.980833,-121.077148,294.500488,0.000000
92.990005,65.004326,-121.121628,-0.001306,0.003863,0.098126,289.153687,14.730190,0.981264,-121.121628,294.500488,0.000000
93.350006,64.984215,-121.077148,-0.001302,0.003863,0.098126,289.064240,14.725634,0.981264,-121.077148,294.500488,0.000000
93.710007,64.950691,-121.032669,-0.001315,0.003863,0.098126,288.915100,14.718037,0.981264,-121.032669,294.500488,0.000000
94.070007,64.994270,-121.121628,-0.001298,0.003865,0.098170,289.108948,14.727912,0.981696,-121.121628,294.500488,0.000000
94.430008,64.961128,-121.032669,-0.001311,0.003865,0.098170,288.961517,14.720403,0.981696,-121.032669,294.500488,0.000000
94.790001,64.919792,-121.032669,-0.001315,0.003865,0.098170,288.777649,14.711036,0.981696,-121.032669,294.500488,0.000000
95.150002,64.876228,-121.077148,-0.001302,0.003865,0.098170,288.583862,14.701163,0.981696,-121.077148,294.500488,0.000000
95.510002,64.823341,-120.988190,-0.001289,0.003865,0.098170,288.348633,14.689179,0.981696,-120.988190,294.500488,0.000000
95.870003,64.780144,-121.077148,-0.001306,0.003865,0.098170,288.156464,14.679390,0.981696,-121.077148,294.500488,0.000000
96.230003,64.711266,-121.032669,-0.001298,0.003865,0.098170,287.850098,14.663782,0.981696,-121.032669,294.500488,0.000000
96.590004,65.081032,-121.032669,-0.001302,0.003872,0.098344,289.494873,14.747572,0.983437,-121.032669,294.500488,0.000000
96.950005,65.170403,-120.943703,-0.001315,0.003872,0.098344,289.892426,14.767824,0.983437,-120.943703,294.500488,0.000000
97.310005,65.155495,-121.032669,-0.001302,0.003872,0.098344,289.826111,14.764446,0.983437,-121.032669,294.500488,0.000000
97.670006,65.123848,-121.077148,-0.001289,0.003872,0.098344,289.685333,14.757275,0.983437,-121.077148,294.500488,0.000000
98.030006,65.056816,-120.988190,-0.001302,0.003872,0.098344,289.387177,14.742085,0.983437,-120.988190,294.500488,0.000000
98.390007,65.040062,-121.032669,-0.001298,0.003872,0.098344,289.312653,14.738289,0.983437,-121.032669,294.500488,0.000000
98.750008,64.999107,-120.988190,-0.001302,0.003872,0.098344,289.130463,14.729008,0.983437,-120.988190,294.500488,0.000000
99.110008,64.971550,-120.943703,-0.001298,0.003872,0.098344,289.007874,14.722764,0.983437,-120.943703,294.500488,0.000000
99.470001,64.924629,-121.032669,-0.001298,0.003872,0.098344,288.799164,14.712132,0.983437,-121.032669,294.500488,0.000000
99.830002,64.865791,-120.988190,-0.001293,0.003872,0.098344,288.537445,14.698799,0.983437,-120.988190,294.500488,0.000000
100.190002,64.798775,-121.077148,-0.001289,0.003872,0.098360,288.239349,14.683612,0.983603,-121.077148,294.500488,0.000000
100.550003,64.776421,-120.943703,-0.001293,0.003872,0.098360,288.139923,14.678547,0.983603,-120.943703,294.500488,0.000000
100.910004,64.742912,-120.988190,-0.001298,0.003872,0.098360,287.990845,14.670954,0.983603,-120.988190,294.500488,0.000000
101.270004,64.712746,-120.943703,-0.001285,0.003872,0.098360,287.856659,14.664117,0.983603,-120.943703,294.500488,0.000000
101.630005,65.652992,-120.943703,-0.001285,0.003884,0.098656,292.039093,14.877180,0.986556,-120.943703,294.500488,0.000000
101.990005,65.705498,-120.943703,-0.001285,0.003884,0.098656,292.272644,14.889078,0.986556,-120.943703,294.500488,0.000000
102.350006,65.683891,-120.899223,-0.001293,0.003884,0.098656,292.176544,14.884183,0.986556,-120.899223,294.500488,0.000000
102.710007,65.686501,-120.988190,-0.001289,0.003884,0.098656,292.188141,14.884773,0.986556,-120.988190,294.500488,0.000000
103.070007,65.661186,-120.988190,-0.001289,0.003884,0.098656,292.075531,14.879038,0.986556,-120.988190,294.500488,0.000000
103.430008,65.616875,-120.899223,-0.001289,0.003884,0.098656,291.878448,14.868996,0.986556,-120.899223,294.500488,0.000000
103.790009,65.584099,-120.943703,-0.001272,0.003884,0.098656,291.732635,14.861569,0.986556,-120.943703,294.500488,0.000000
104.150002,65.568459,-120.899223,-0.001289,0.003884,0.098656,291.663055,14.858025,0.986556,-120.899223,294.500488,0.000000
104.510002,65.547234,-120.810265,-0.001276,0.003884,0.098656,291.568665,14.853215,0.986556,-120.810265,294.500488,0.000000
104.870003,65.493614,-120.899223,-0.001285,0.003884,0.098656,291.330139,14.841065,0.986556,-120.899223,294.500488,0.000000
105.230003,65.459358,-120.854744,-0.001281,0.003884,0.098656,291.177765,14.833302,0.986556,-120.854744,294.500488,0.000000
105.590004,65.381538,-120.899223,-0.001281,0.003884,0.098656,290.831604,14.815668,0.986556,-120.899223,294.500488,0.000000
105.950005,65.344673,-120.899223,-0.001289,0.003884,0.098656,290.667633,14.807315,0.986556,-120.899223,294.500488,0.000000
106.310005,65.299980,-120.854744,-0.001276,0.003884,0.098656,290.468811,14.797187,0.986556,-120.854744,294.500488,0.000000
106.670006,65.281731,-120.854744,-0.001289,0.003884,0.098656,290.387634,14.793052,0.986556,-120.854744,294.500488,0.000000
107.030006,65.250450,-120.810265,-0.001289,0.003884,0.098656,290.248505,14.785963,0.986556,-120.810265,294.500488,0.000000
107.390007,65.205772,-120.854744,-0.001298,0.003884,0.098656,290.049774,14.775839,0.986556,-120.854744,294.500488,0.000000
107.750008,65.143211,-120.854744,-0.001281,0.003884,0.098656,289.771484,14.761663,0.986556,-120.854744,294.500488,0.000000
108.110008,65.100395,-120.810265,-0.001285,0.003884,0.098656,289.581024,14.751961,0.986556,-120.810265,294.500488,0.000000
108.470009,65.064278,-120.810265,-0.001285,0.003884,0.098656,289.420349,14.743775,0.986556,-120.810265,294.500488,0.000000
108.830002,65.023689,-120.854744,-0.001272,0.003884,0.098656,289.239807,14.734578,0.986556,-120.854744,294.500488,0.000000
109.190002,64.989418,-120.854744,-0.001285,0.003884,0.098656,289.087372,14.726813,0.986556,-120.854744,294.500488,0.000000
109.550003,64.956276,-120.810265,-0.001293,0.003884,0.098656,288.939941,14.719302,0.986556,-120.810265,294.500488,0.000000
109.910004,64.905647,-120.810265,-0.001268,0.003884,0.098656,288.714752,14.707829,0.986556,-120.810265,294.500488,0.000000
110.270004,64.885155,-120.854744,-0.001276,0.003884,0.098656,288.623596,14.703186,0.986556,-120.854744,294.500488,0.000000
110.630005,64.831169,-120.810265,-0.001281,0.003884,0.098656,288.383453,14.690953,0.986556,-120.810265,294.500488,0.000000
110.990005,64.801003,-120.765785,-0.001285,0.003884,0.098656,288.249268,14.684117,0.986556,-120.765785,294.500488,0.000000
111.350006,64.745155,-120.765785,-0.001289,0.003884,0.098656,288.000824,14.671461,0.986556,-120.765785,294.500488,0.000000
111.710007,64.733971,-120.765785,-0.001272,0.003884,0.098656,287.951080,14.668927,0.986556,-120.765785,294.500488,0.000000
112.070007,64.679985,-120.854744,-0.001289,0.003884,0.098664,287.710937,14.656693,0.986639,-120.854744,294.500488,0.000000
112.430008,64.669182,-120.765785,-0.001285,0.003888,0.098743,287.662903,14.654246,0.987426,-120.765785,294.500488,0.000000
112.790009,65.249718,-120.765785,-0.001272,0.003893,0.098872,290.245239,14.785798,0.988721,-120.765785,294.500488,0.000000
113.150009,65.262367,-120.765785,-0.001272,0.003893,0.098872,290.301514,14.788664,0.988721,-120.765785,294.500488,0.000000
113.510002,65.264977,-120.676819,-0.001276,0.003892,0.098864,290.313110,14.789255,0.988637,-120.676819,294.500488,0.000000
113.870003,65.254173,-120.765785,-0.001281,0.003892,0.098864,290.265045,14.786807,0.988637,-120.765785,294.500488,0.000000
114.230003,65.236305,-120.721298,-0.001285,0.003892,0.098864,290.185577,14.782759,0.988637,-120.721298,294.500488,0.000000
114.590004,65.206886,-120.721298,-0.001272,0.003892,0.098864,290.054718,14.776092,0.988637,-120.721298,294.500488,0.000000
114.950005,65.187904,-120.721298,-0.001285,0.003892,0.098864,289.970276,14.771790,0.988637,-120.721298,294.500488,0.000000
115.310005,65.158485,-120.676819,-0.001272,0.003892,0.098864,289.839417,14.765123,0.988637,-120.676819,294.500488,0.000000
115.670006,65.120125,-120.676819,-0.001276,0.003892,0.098864,289.668793,14.756431,0.988637,-120.676819,294.500488,0.000000
116.030006,65.089592,-120.676819,-0.001281,0.003892,0.098864,289.532959,14.749513,0.988637,-120.676819,294.500488,0.000000
116.390007,65.053474,-120.721298,-0.001276,0.003892,0.098864,289.372314,14.741328,0.988637,-120.721298,294.500488,0.000000
116.750008,65.031136,-120.765785,-0.001285,0.003892,0.098864,289.272949,14.736266,0.988637,-120.765785,294.500488,0.000000
117.110008,65.016228,-120.632339,-0.001285,0.003892,0.098864,289.206635,14.732888,0.988637,-120.632339,294.500488,0.000000
117.470009,64.991661,-120.721298,-0.001268,0.003893,0.098872,289.097351,14.727321,0.988721,-120.721298,294.500488,0.000000
117.830002,64.963356,-120.676819,-0.001289,0.003893,0.098872,288.971436,14.720907,0.988721,-120.676819,294.500488,0.000000
118.190002,64.946602,-120.721298,-0.001272,0.003893,0.098872,288.896912,14.717111,0.988721,-120.721298,294.500488,0.000000
118.550003,64.909370,-120.676819,-0.001281,0.003893,0.098872,288.731293,14.708674,0.988721,-120.676819,294.500488,0.000000
118.910004,65.179710,-120.632339,-0.001285,0.003897,0.098994,289.933838,14.769934,0.989939,-120.632339,294.500488,0.000000
119.270004,65.217690,-120.721298,-0.001272,0.003897,0.098994,290.102783,14.778540,0.989939,-120.721298,294.500488,0.000000
119.630005,65.225502,-120.587860,-0.001289,0.003897,0.098994,290.137512,14.780310,0.989939,-120.587860,294.500488,0.000000
119.990005,65.219551,-120.676819,-0.001272,0.003897,0.098994,290.111053,14.778962,0.989939,-120.676819,294.500488,0.000000
120.350006,65.194969,-120.632339,-0.001276,0.003897,0.098994,290.001709,14.773392,0.989939,-120.632339,294.500488,0.000000
120.710007,65.180077,-120.632339,-0.001272,0.003897,0.098994,289.935455,14.770016,0.989939,-120.632339,294.500488,0.000000
121.070007,65.149544,-120.676819,-0.001281,0.003897,0.098994,289.799652,14.763098,0.989939,-120.676819,294.500488,0.000000
121.430008,65.126091,-120.632339,-0.001268,0.003897,0.098994,289.695312,14.757783,0.989939,-120.632339,294.500488,0.000000
121.790009,65.081398,-120.632339,-0.001268,0.003897,0.098994,289.496521,14.747656,0.989939,-120.632339,294.500488,0.000000
122.150009,65.065010,-120.587860,-0.001281,0.003897,0.098994,289.423615,14.743942,0.989939,-120.587860,294.500488,0.000000
122.510002,65.044533,-120.632339,-0.001281,0.003897,0.098994,289.332520,14.739302,0.989939,-120.632339,294.500488,0.000000
122.870003,65.034111,-120.632339,-0.001268,0.003897,0.098994,289.286163,14.736940,0.989939,-120.632339,294.500488,0.000000
123.230003,65.011024,-120.498894,-0.001268,0.003897,0.098994,289.183472,14.731709,0.989939,-120.498894,294.500488,0.000000
123.590004,64.979744,-120.587860,-0.001263,0.003897,0.098994,289.044342,14.724620,0.989939,-120.587860,294.500488,0.000000
123.950005,64.975273,-120.587860,-0.001276,0.003897,0.098994,289.024445,14.723607,0.989939,-120.587860,294.500488,0.000000
124.310005,64.941765,-120.543381,-0.001259,0.003897,0.098994,288.875397,14.716014,0.989939,-120.543381,294.500488,0.000000
124.670006,64.926125,-120.543381,-0.001268,0.003899,0.099029,288.805817,14.712470,0.990287,-120.543381,294.500488,0.000000
125.030006,64.911232,-120.543381,-0.001281,0.003899,0.099029,288.739594,14.709095,0.990287,-120.543381,294.500488,0.000000
125.390007,64.935799,-120.587860,-0.001281,0.003899,0.099045,288.848846,14.714663,0.990454,-120.587860,294.500488,0.000000
125.750008,64.932457,-120.543381,-0.001272,0.003900,0.099054,288.833984,14.713905,0.990545,-120.543381,1681.640991,0.000000
126.110008,64.919792,-120.543381,-0.001255,0.003891,0.098829,288.777649,14.711036,0.988289,-120.543381,0.098751,0.000000
126.470009,64.862068,-120.543381,-0.001268,0.003874,0.098395,288.520874,14.697954,0.983952,-120.543381,0.098152,0.000000
126.830009,64.720573,-120.498894,-0.001263,0.003859,0.098023,287.891479,14.665891,0.980227,-120.498894,0.097554,0.000000
127.190002,64.674019,-120.543381,-0.001229,0.003837,0.097459,287.684418,14.655342,0.974588,-120.543381,0.096956,0.000000
127.550003,64.645348,-120.454414,-0.001246,0.003811,0.096799,287.556854,14.648846,0.967994,-120.454414,0.096349,0.000000
127.910004,64.614449,-120.454414,-0.001242,0.003790,0.096254,287.419434,14.641843,0.962537,-120.454414,0.095750,0.000000
128.270004,64.576469,-120.632339,-0.001255,0.003767,0.095690,287.250488,14.633237,0.956897,-120.632339,0.095152,0.000000
128.630005,64.525078,-120.498894,-0.001242,0.003740,0.094987,287.021881,14.621593,0.949872,-120.498894,0.094553,0.000000
128.990005,64.480019,-120.498894,-0.001246,0.003720,0.094493,286.821442,14.611381,0.944929,-120.498894,0.093955,0.000000
129.350006,64.429375,-120.543381,-0.001250,0.003693,0.093808,286.596161,14.599905,0.938079,-120.543381,0.093348,0.000000
129.710007,64.367928,-120.498894,-0.001237,0.003674,0.093331,286.322845,14.585981,0.933310,-120.498894,0.092750,0.000000
130.070007,64.108757,-120.498894,-0.001237,0.003657,0.092880,285.169983,14.527252,0.928798,-120.498894,0.092152,0.000000
130.430008,63.410194,-120.409935,-0.001255,0.003636,0.092351,282.062622,14.368956,0.923507,-120.409935,0.091553,0.000000
130.790009,62.259186,-120.498894,-0.001229,0.003609,0.091657,276.942688,14.108133,0.916573,-120.498894,0.090955,0.000000
131.150009,61.123451,-120.498894,-0.001220,0.003588,0.091146,271.890686,13.850772,0.911456,-120.498894,0.090348,0.000000
131.510010,59.601196,-120.409935,-0.001207,0.003565,0.090538,265.119354,13.505824,0.905385,-120.409935,0.089749,0.000000
131.870010,58.494873,-120.498894,-0.001212,0.003549,0.090157,260.198181,13.255128,0.901570,-120.498894,0.089151,0.000000
132.230011,56.490395,-120.409935,-0.001220,0.003524,0.089506,251.281830,12.800906,0.895060,-120.409935,0.088552,0.000000
132.590012,55.479401,-120.409935,-0.001203,0.003507,0.089090,246.784698,12.571812,0.890904,-120.409935,0.087954,0.000000
132.950012,52.164543,-120.454414,-0.001212,0.003476,0.088293,232.039474,11.820654,0.882925,-120.454414,0.087355,0.000000
133.310013,49.821945,-120.409935,-0.001212,0.003451,0.087668,221.619080,11.289814,0.876680,-120.409935,0.086748,0.000000
133.670013,47.117035,-120.498894,-0.001212,0.003427,0.087044,209.587036,10.676873,0.870435,-120.498894,0.086150,0.000000
134.029999,44.721565,-120.409935,-0.001199,0.003403,0.086436,198.931458,10.134051,0.864364,-120.409935,0.085551,0.000000
134.389999,42.848160,-120.409935,-0.001207,0.003387,0.086037,190.598129,9.709532,0.860375,-120.409935,0.084953,0.000000
134.750000,40.292191,-120.409935,-0.001216,0.003366,0.085491,179.228622,9.130341,0.854909,-120.409935,0.084355,0.000000
135.110001,37.950714,-120.409935,-0.001194,0.003344,0.084936,168.813202,8.599755,0.849361,-120.409935,0.083748,0.000000
135.470001,34.905823,-120.409935,-0.001212,0.003315,0.084190,155.268860,7.909772,0.841904,-120.409935,0.083150,0.000000
135.830002,32.726326,-120.409935,-0.001216,0.003294,0.083679,145.573975,7.415892,0.836787,-120.409935,0.082551,0.000000
136.190002,30.435120,-120.409935,-0.001203,0.003270,0.083054,135.382172,6.896697,0.830542,-120.409935,0.081953,0.000000
136.550003,27.218567,-120.365456,-0.001212,0.003245,0.082421,121.074234,6.167815,0.824214,-120.365456,0.081354,0.000000
136.910004,25.396179,-120.276489,-0.001199,0.003228,0.081979,112.967850,5.754857,0.819786,-120.276489,0.080747,0.000000
137.270004,22.746002,-120.320976,-0.001207,0.003202,0.081337,101.179268,5.154318,0.813374,-120.320976,0.080149,0.000000
137.630005,19.695526,-120.320976,-0.001203,0.003174,0.080618,87.610077,4.463070,0.806175,-120.320976,0.079550,0.000000
137.990005,17.327240,-120.365456,-0.001190,0.003150,0.080019,77.075417,3.926409,0.800187,-120.365456,0.078952,0.000000
138.350006,15.057625,-120.320976,-0.001212,0.003127,0.079429,66.979660,3.412107,0.794290,-120.320976,0.078354,0.000000
138.710007,12.335213,-120.232010,-0.001203,0.003102,0.078796,54.869766,2.795199,0.787962,-120.232010,0.077747,0.000000
139.070007,10.266312,-120.409935,-0.001190,0.003087,0.078406,45.666836,2.326380,0.784056,-120.409935,0.077148,0.000000
139.430008,6.795425,-120.320976,-0.001207,0.003053,0.077547,30.227562,1.539865,0.775472,-120.320976,0.076550,0.000000
139.790009,4.653542,-120.365456,-0.001190,0.003032,0.077010,20.699987,1.054508,0.770097,-120.365456,0.075951,0.000000
140.150009,2.060715,-120.320976,-0.001220,0.003006,0.076359,9.166517,0.466965,0.763595,-120.320976,0.075353,0.000000
140.510010,-0.102776,-120.276489,-0.001203,0.002985,0.075821,-0.457169,-0.023289,0.758213,-120.276489,0.074755,0.000000
140.870010,-2.036503,-120.365456,-0.001203,0.002969,0.075414,-9.058817,-0.461478,0.754140,-120.365456,0.074148,0.000000
141.230011,-4.652046,-120.276489,-0.001207,0.002937,0.074599,-20.693335,-1.054169,0.745988,-120.276489,0.073550,0.000000
141.590012,-0.469933,-120.320976,-0.001237,0.002916,0.074070,-2.090364,-0.106488,0.740696,-120.320976,0.072951,0.000000
141.950012,-0.459129,-120.276489,-0.001259,0.002889,0.073376,-2.042309,-0.104040,0.733762,-120.276489,0.072353,0.000000
142.310013,-0.438652,-120.232010,-0.001268,0.002870,0.072908,-1.951222,-0.099400,0.729077,-120.232010,0.071754,0.000000
142.670013,-0.446098,-120.320976,-0.001289,0.002849,0.072353,-1.984344,-0.101087,0.723528,-120.320976,0.071147,0.000000
143.030014,-0.495995,-120.276489,-0.001324,0.002818,0.071572,-2.206294,-0.112394,0.715724,-120.276489,0.070549,0.000000
143.389999,-0.500092,-120.276489,-0.001345,0.002794,0.070965,-2.224518,-0.113322,0.709653,-120.276489,0.069950,0.000000
143.750000,-0.421898,-120.276489,-0.001362,0.002778,0.070557,-1.876696,-0.095603,0.705573,-120.276489,0.069352,0.000000
144.110001,-0.441261,-120.143051,-0.001384,0.002751,0.069872,-1.962828,-0.099991,0.698722,-120.143051,0.068753,0.000000
144.470001,-0.458763,-120.320976,-0.001401,0.002722,0.069144,-2.040680,-0.103957,0.691440,-120.320976,0.068146,0.000000
144.830002,-0.463974,-120.187531,-0.001440,0.002704,0.068675,-2.063859,-0.105138,0.686754,-120.187531,0.067548,0.000000
145.190002,-0.485573,-120.232010,-0.001462,0.002675,0.067938,-2.159936,-0.110032,0.679381,-120.232010,0.066949,0.000000
145.550003,-0.487808,-120.232010,-0.001475,0.002653,0.067392,-2.169879,-0.110539,0.673923,-120.232010,0.066351,0.000000
145.910004,-0.488174,-120.232010,-0.001496,0.002627,0.066733,-2.171508,-0.110622,0.667330,-120.232010,0.065753,0.000000
146.270004,-0.478127,-120.187531,-0.001513,0.002611,0.066325,-2.126813,-0.108345,0.663250,-120.187531,0.065146,0.000000
146.630005,-0.474396,-120.187531,-0.001531,0.002588,0.065727,-2.110218,-0.107500,0.657270,-120.187531,0.064548,0.000000
146.990005,-0.472908,-120.232010,-0.001582,0.002556,0.064912,-2.103600,-0.107162,0.649117,-120.232010,0.063949,0.000000
147.350006,-0.492271,-120.143051,-0.001591,0.002535,0.064392,-2.189733,-0.111550,0.643917,-120.143051,0.063351,0.000000
147.710007,-0.491531,-120.143051,-0.001613,0.002512,0.063802,-2.186441,-0.111383,0.638020,-120.143051,0.062752,0.000000
148.070007,-0.509773,-120.187531,-0.001638,0.002489,0.063212,-2.267585,-0.115516,0.632123,-120.187531,0.062154,0.000000
148.430008,-0.491531,-120.187531,-0.001660,0.002467,0.062657,-2.186441,-0.111383,0.626567,-120.187531,0.061547,0.000000
148.790009,-0.491531,-120.143051,-0.001669,0.002448,0.062171,-2.186441,-0.111383,0.621714,-120.143051,0.060949,0.000000
149.150009,-0.482590,-120.232010,-0.001703,0.002413,0.061287,-2.146666,-0.109356,0.612865,-120.232010,0.060350,0.000000
149.500000,-0.481476,-120.187531,-0.001707,0.002409,0.061191,-2.141711,-0.109104,0.611912,-120.187531,0.061078,0.000000