File: Data/compression 9/AutoHeating-13-9-4--240404_04042024_174655.csv
Time (sec),S:Load (lbs),S:HL1 (DIM),S:LVDT (in),S:Position (in),Ch:Position (mm),Ch:Load (N),Ch:Stress (MPa),Ch:Strain (mm/mm),Ch:HL1 (DIM),Set Point (),Cycles ()
0.010000,0.004097,-168.760727,-0.000013,-0.000000,-0.000000,0.018224,0.000928,-0.000000,-168.760727,0.000208,0.000000
0.280000,0.004837,-168.716248,-0.000004,-0.000000,-0.000000,0.021516,0.001096,-0.000000,-168.716248,0.000208,0.000000
0.550000,-0.023087,-168.760727,-0.000026,0.000119,0.003017,-0.102694,-0.005231,0.030173,-168.760727,0.003937,0.000000
0.820000,-0.018616,-168.760727,0.000129,0.000290,0.007354,-0.082807,-0.004218,0.073541,-168.760727,0.008446,0.000000
1.090000,0.037239,-168.760727,0.000310,0.000463,0.011759,0.165648,0.008438,0.117589,-168.760727,0.012939,0.000000
1.360000,0.010056,-168.716248,0.000479,0.000642,0.016304,0.044729,0.002279,0.163038,-168.716248,0.017431,0.000000
1.630000,0.028297,-168.760727,0.000651,0.000818,0.020770,0.125873,0.006412,0.207700,-168.760727,0.021940,0.000000
1.900000,0.025322,-168.760727,0.000836,0.001004,0.025505,0.112638,0.005738,0.255049,-168.760727,0.026433,0.000000
2.170000,0.024948,-168.805206,0.001018,0.001175,0.029849,0.110975,0.005653,0.298492,-168.805206,0.030925,0.000000
2.440000,0.023087,-168.760727,0.001186,0.001348,0.034246,0.102694,0.005231,0.342465,-168.760727,0.035434,0.000000
2.710000,-0.027184,-168.716248,0.001362,0.001527,0.038782,-0.120918,-0.006160,0.387823,-168.716248,0.039927,0.000000
2.980000,0.053619,-168.716248,0.001544,0.001703,0.043257,0.238511,0.012150,0.432568,-168.716248,0.044419,0.000000
3.250000,0.043198,-168.805206,0.001729,0.001883,0.047818,0.192153,0.009789,0.478184,-168.805206,0.048929,0.000000
3.520000,0.022713,-168.805206,0.001906,0.002061,0.052354,0.101031,0.005147,0.523542,-168.805206,0.053421,0.000000
3.790000,0.039474,-168.760727,0.002091,0.002231,0.056664,0.175591,0.008945,0.566644,-168.760727,0.057913,0.000000
4.060000,0.007072,-168.805206,0.002276,0.002416,0.061374,0.031460,0.001603,0.613736,-168.805206,0.062423,0.000000
4.330000,0.024948,-168.760727,0.002453,0.002592,0.065848,0.110975,0.005653,0.658481,-168.760727,0.066915,0.000000
4.600000,0.007446,-168.849686,0.002639,0.002772,0.070401,0.033123,0.001687,0.704013,-168.849686,0.071407,0.000000
4.870000,-0.010429,-168.849686,0.002807,0.002944,0.074780,-0.046392,-0.002363,0.747804,-168.849686,0.075917,0.000000
5.140000,0.070747,-168.849686,0.002988,0.003119,0.079221,0.314700,0.016032,0.792209,-168.849686,0.080409,0.000000
5.410000,0.036118,-168.805206,0.003169,0.003299,0.083791,0.160659,0.008184,0.837908,-168.805206,0.084901,0.000000
5.680000,0.044685,-168.849686,0.003346,0.003479,0.088361,0.198770,0.010126,0.883614,-168.849686,0.089411,0.000000
5.950000,0.053619,-168.938660,0.003518,0.003657,0.092897,0.238511,0.012150,0.928972,-168.938660,0.093902,0.000000
6.220000,0.016754,-168.849686,0.003708,0.003830,0.097285,0.074526,0.003797,0.972847,-168.849686,0.098395,0.000000
6.490000,0.055855,-168.849686,0.003872,0.004005,0.101734,0.248455,0.012657,1.017342,-168.849686,0.102904,0.000000
6.760000,-0.010429,-168.849686,0.004074,0.004187,0.106347,-0.046392,-0.002363,1.063472,-168.849686,0.107397,0.000000
7.030000,0.029045,-168.938660,0.004234,0.004360,0.110753,0.129199,0.006582,1.107528,-168.938660,0.111889,0.000000
7.300000,0.088249,-168.894165,0.004424,0.004540,0.115306,0.392552,0.019998,1.153061,-168.894165,0.116398,0.000000
7.570000,0.137405,-168.938660,0.004592,0.004714,0.119737,0.611210,0.031137,1.197374,-168.938660,0.120891,0.000000
7.840000,0.314651,-168.938660,0.004769,0.004888,0.124151,1.399640,0.071301,1.241514,-168.938660,0.125400,0.000000
8.110001,0.586861,-168.894165,0.004963,0.005071,0.128809,2.610487,0.132985,1.288091,-168.894165,0.129893,0.000000
8.380000,0.614410,-168.938660,0.005014,-0.000006,-0.000148,2.733034,0.139227,-0.001476,-168.938660,0.000017,0.000000
8.650001,0.578293,-168.938660,0.005032,-0.000006,-0.000156,2.572375,0.131043,-0.001559,-168.938660,0.000017,0.000000
8.920000,0.539940,-168.894165,0.005036,-0.000006,-0.000156,2.401772,0.122352,-0.001559,-168.894165,0.000321,0.000000
9.190001,0.570473,-168.849686,0.005023,-0.000006,-0.000156,2.537589,0.129271,-0.001559,-168.849686,0.000772,0.000000
9.460000,0.540314,-168.894165,0.005019,-0.000006,-0.000148,2.403435,0.122437,-0.001476,-168.894165,0.001223,0.000000
9.730000,0.722771,-168.983139,0.005044,0.000028,0.000711,3.215044,0.163782,0.007108,-168.983139,0.001674,0.000000
10.000000,0.818100,-169.027618,0.005075,0.000053,0.001353,3.639091,0.185384,0.013527,-169.027618,0.002125,0.000000
10.270000,0.861671,-168.983139,0.005101,0.000068,0.001717,3.832906,0.195258,0.017168,-168.983139,0.002575,0.000000
10.540001,0.891457,-168.938660,0.005105,0.000087,0.002203,3.965397,0.202007,0.022028,-168.938660,0.003026,0.000000
10.810000,0.958115,-168.894165,0.005118,0.000103,0.002610,4.261907,0.217112,0.026101,-168.894165,0.003478,0.000000
11.080001,0.997955,-168.938660,0.005113,0.000117,0.002983,4.439127,0.226140,0.029833,-168.938660,0.003929,0.000000
11.350000,1.107437,-169.072098,0.005144,0.000137,0.003478,4.926126,0.250949,0.034776,-169.072098,0.004371,0.000000
11.620001,1.127541,-169.027618,0.005174,0.000148,0.003764,5.015551,0.255504,0.037637,-169.027618,0.004822,0.000000
11.890000,1.275749,-168.983139,0.005187,0.000178,0.004518,5.674816,0.289089,0.045184,-168.983139,0.005272,0.000000
12.160001,1.331978,-169.027618,0.005208,0.000196,0.004969,5.924933,0.301831,0.049688,-169.027618,0.005724,0.000000
12.430000,1.367722,-169.027618,0.005221,0.000212,0.005385,6.083930,0.309930,0.053851,-169.027618,0.006175,0.000000
12.700001,1.428047,-169.116577,0.005234,0.000224,0.005689,6.352271,0.323600,0.056887,-169.116577,0.006626,0.000000
12.970000,1.545341,-169.027618,0.005251,0.000244,0.006192,6.874022,0.350179,0.061921,-169.027618,0.007076,0.000000
13.240001,1.676422,-169.027618,0.005282,0.000263,0.006669,7.457098,0.379883,0.066690,-169.027618,0.007527,0.000000
13.510000,1.749405,-169.072098,0.005286,0.000277,0.007042,7.781742,0.396421,0.070422,-169.072098,0.007979,0.000000
13.780001,1.870056,-169.116577,0.005312,0.000297,0.007536,8.318425,0.423761,0.075365,-169.116577,0.008421,0.000000
14.050000,1.944527,-169.027618,0.005325,0.000315,0.008004,8.649687,0.440636,0.080043,-169.027618,0.008872,0.000000
14.320001,2.061455,-169.027618,0.005346,0.000334,0.008481,9.169808,0.467132,0.084812,-169.027618,0.009323,0.000000
14.590001,2.119919,-169.116577,0.005364,0.000349,0.008863,9.429870,0.480380,0.088627,-169.116577,0.009773,0.000000
14.860001,2.196999,-169.027618,0.005381,0.000366,0.009288,9.772738,0.497847,0.092881,-169.027618,0.010225,0.000000
15.130001,2.362328,-169.116577,0.005402,0.000385,0.009782,10.508158,0.535311,0.097824,-169.116577,0.010676,0.000000
15.400001,2.407761,-169.161057,0.005415,0.000398,0.010112,10.710254,0.545606,0.101117,-169.161057,0.011127,0.000000
15.670001,2.554474,-169.072098,0.005424,0.000415,0.010545,11.362867,0.578852,0.105455,-169.072098,0.011577,0.000000
15.940001,2.778641,-169.116577,0.005454,0.000441,0.011213,12.360011,0.629649,0.112131,-169.116577,0.012028,0.000000
16.210001,2.768585,-169.072098,0.005458,0.000454,0.011525,12.315282,0.627370,0.115250,-169.072098,0.012480,0.000000
16.480001,2.870621,-169.116577,0.005480,0.000472,0.011994,12.769158,0.650492,0.119936,-169.116577,0.012922,0.000000
16.750000,2.987175,-169.161057,0.005501,0.000490,0.012445,13.287618,0.676904,0.124447,-169.161057,0.013373,0.000000
17.020000,3.197563,-169.116577,0.005527,0.000511,0.012974,14.223472,0.724578,0.129739,-169.116577,0.013823,0.000000
17.290001,3.206123,-169.205536,0.005536,0.000522,0.013251,14.261549,0.726518,0.132509,-169.205536,0.014274,0.000000
17.560001,3.403114,-169.116577,0.005536,0.000540,0.013719,15.137809,0.771157,0.137195,-169.116577,0.014726,0.000000
17.830000,3.477211,-169.250015,0.005558,0.000557,0.014144,15.467407,0.787947,0.141442,-169.250015,0.015177,0.000000
18.100000,3.703613,-169.250015,0.005596,0.000580,0.014726,16.474495,0.839251,0.147255,-169.250015,0.015627,0.000000
18.370001,3.585571,-169.116577,0.005609,0.000593,0.015072,15.949418,0.812502,0.150722,-169.116577,0.016078,0.000000
18.640001,3.842140,-169.161057,0.005627,0.000614,0.015601,17.090693,0.870641,0.156013,-169.161057,0.016529,0.000000
18.910002,3.923691,-169.161057,0.005635,0.000630,0.016000,17.453449,0.889121,0.160003,-169.161057,0.016971,0.000000
19.180000,3.972466,-169.205536,0.005639,0.000645,0.016391,17.670408,0.900174,0.163909,-169.205536,0.017423,0.000000
19.450001,4.162010,-169.250015,0.005657,0.000662,0.016816,18.513546,0.943125,0.168155,-169.250015,0.017874,0.000000
19.720001,4.315422,-169.205536,0.005683,0.000681,0.017310,19.195955,0.977889,0.173098,-169.205536,0.018324,0.000000
19.990002,4.439423,-169.205536,0.005708,0.000702,0.017839,19.747538,1.005988,0.178390,-169.205536,0.018775,0.000000
20.260000,4.528793,-169.250015,0.005713,0.000722,0.018333,20.145079,1.026239,0.183333,-169.250015,0.019227,0.000000
20.530001,4.515388,-169.250015,0.005747,0.000735,0.018672,20.085451,1.023202,0.186716,-169.250015,0.019678,0.000000
20.800001,4.672531,-169.250015,0.005760,0.000754,0.019149,20.784456,1.058811,0.191485,-169.250015,0.020128,0.000000
21.070002,4.879570,-169.161057,0.005782,0.000775,0.019694,21.705412,1.105726,0.196943,-169.161057,0.020579,0.000000
21.340000,4.929840,-169.250015,0.005790,0.000791,0.020093,21.929024,1.117118,0.200933,-169.250015,0.021030,0.000000
21.610001,5.092567,-169.205536,0.005816,0.000812,0.020631,22.652872,1.153992,0.206315,-169.205536,0.021472,0.000000
21.880001,5.085121,-169.250015,0.005821,0.000825,0.020961,22.619749,1.152305,0.209607,-169.250015,0.021924,0.000000
22.150002,5.126823,-169.250015,0.005833,0.000841,0.021369,22.805250,1.161755,0.213688,-169.250015,0.022374,0.000000
22.420002,5.260132,-169.205536,0.005868,0.000859,0.021828,23.398235,1.191963,0.218282,-169.205536,0.022825,0.000000
22.690001,5.340195,-169.250015,0.005872,0.000877,0.022270,23.754372,1.210105,0.222703,-169.250015,0.023276,0.000000
22.960001,5.568459,-169.294495,0.005907,0.000898,0.022799,24.769741,1.261831,0.227995,-169.294495,0.023728,0.000000
23.230001,5.588562,-169.294495,0.005911,0.000912,0.023155,24.859165,1.266386,0.231552,-169.294495,0.024178,0.000000
23.500002,5.744591,-169.383469,0.005928,0.000931,0.023650,25.553215,1.301743,0.236495,-169.383469,0.024629,0.000000
23.770000,5.909180,-169.294495,0.005950,0.000951,0.024160,26.285343,1.339039,0.241605,-169.294495,0.025080,0.000000
24.040001,5.969131,-169.294495,0.005967,0.000970,0.024638,26.552023,1.352625,0.246382,-169.294495,0.025522,0.000000
24.310001,5.985146,-169.383469,0.005980,0.000986,0.025045,26.623257,1.356253,0.250454,-169.383469,0.025973,0.000000
24.580002,6.032059,-169.338974,0.006002,0.001002,0.025453,26.831938,1.366884,0.254527,-169.338974,0.026425,0.000000
24.850000,6.219368,-169.383469,0.006019,0.001022,0.025964,27.665131,1.409329,0.259644,-169.383469,0.026875,0.000000
25.120001,6.307617,-169.294495,0.006019,0.001038,0.026372,28.057682,1.429327,0.263724,-169.294495,0.027326,0.000000
25.390001,6.536629,-169.294495,0.006062,0.001063,0.026997,29.076376,1.481221,0.269969,-169.294495,0.027777,0.000000
25.660002,6.574608,-169.338974,0.006075,0.001081,0.027465,29.245316,1.489827,0.274647,-169.338974,0.028229,0.000000
25.930000,6.518379,-169.383469,0.006088,0.001095,0.027820,28.995199,1.477086,0.278205,-169.383469,0.028679,0.000000
26.200001,6.496040,-169.383469,0.006096,0.001109,0.028159,28.895830,1.472024,0.281589,-169.383469,0.029130,0.000000
26.470001,6.724304,-169.338974,0.006122,0.001131,0.028723,29.911200,1.523749,0.287228,-169.338974,0.029572,0.000000
26.740002,6.834152,-169.338974,0.006144,0.001148,0.029156,30.399828,1.548641,0.291558,-169.338974,0.030023,0.000000
27.010002,6.815163,-169.427948,0.006165,0.001161,0.029494,30.315357,1.544338,0.294942,-169.427948,0.030474,0.000000
27.280001,6.928360,-169.427948,0.006170,0.001178,0.029928,30.818884,1.569989,0.299279,-169.427948,0.030925,0.000000
27.550001,7.189766,-169.338974,0.006200,0.001202,0.030526,31.981676,1.629224,0.305259,-169.338974,0.031376,0.000000
27.820002,7.190140,-169.383469,0.006204,0.001219,0.030951,31.983339,1.629309,0.309514,-169.383469,0.031827,0.000000
28.090002,7.237434,-169.427948,0.006222,0.001237,0.031428,32.193714,1.640026,0.314283,-169.427948,0.032278,0.000000
28.360001,7.237434,-169.472427,0.006234,0.001252,0.031801,32.193714,1.640026,0.318014,-169.472427,0.032729,0.000000
28.630001,7.396805,-169.472427,0.006247,0.001271,0.032278,32.902630,1.676140,0.322783,-169.472427,0.033180,0.000000
28.900002,7.415054,-169.472427,0.006265,0.001287,0.032695,32.983810,1.680275,0.326947,-169.472427,0.033631,0.000000
29.170002,7.379677,-169.427948,0.006282,0.001300,0.033024,32.826443,1.672259,0.330240,-169.427948,0.034073,0.000000
29.440001,7.845512,-169.383469,0.006295,0.001329,0.033752,34.898582,1.777819,0.337522,-169.383469,0.034524,0.000000
29.710001,7.689865,-169.427948,0.006312,0.001345,0.034151,34.206230,1.742548,0.341511,-169.427948,0.034975,0.000000
29.980001,7.708855,-169.472427,0.006338,0.001362,0.034585,34.290699,1.746851,0.345849,-169.472427,0.035426,0.000000
30.250002,7.658211,-169.472427,0.006347,0.001374,0.034888,34.065422,1.735375,0.348884,-169.472427,0.035877,0.000000
30.520002,7.938232,-169.472427,0.006368,0.001397,0.035478,35.311020,1.798829,0.354781,-169.472427,0.036328,0.000000
30.790001,7.943825,-169.561386,0.006381,0.001415,0.035929,35.335896,1.800096,0.359293,-169.561386,0.036779,0.000000
31.060001,7.797852,-169.516907,0.006390,0.001427,0.036241,34.686577,1.767018,0.362411,-169.516907,0.037230,0.000000
31.330002,8.101334,-169.516907,0.006407,0.001450,0.036840,36.036533,1.835788,0.368399,-169.516907,0.037681,0.000000
31.600002,8.228683,-169.516907,0.006437,0.001472,0.037386,36.603012,1.864646,0.373857,-169.516907,0.038123,0.000000
31.870001,8.073776,-169.561386,0.006450,0.001486,0.037733,35.913952,1.829544,0.377331,-169.561386,0.038574,0.000000
32.140003,8.090912,-169.472427,0.006463,0.001503,0.038167,35.990173,1.833427,0.381669,-169.472427,0.039025,0.000000
32.410000,8.150490,-169.561386,0.006467,0.001520,0.038600,36.255188,1.846927,0.385999,-169.561386,0.039476,0.000000
32.680000,8.254753,-169.561386,0.006485,0.001537,0.039051,36.718975,1.870554,0.390510,-169.561386,0.039927,0.000000
32.950001,8.108040,-169.516907,0.006497,0.001546,0.039277,36.066364,1.837308,0.392766,-169.516907,0.040378,0.000000
33.220001,8.554512,-169.516907,0.006519,0.001576,0.040040,38.052368,1.938480,0.400396,-169.516907,0.040829,0.000000
33.490002,8.510201,-169.605865,0.006541,0.001594,0.040491,37.855263,1.928439,0.404908,-169.605865,0.041280,0.000000
33.760002,8.462166,-169.605865,0.006545,0.001612,0.040942,37.641594,1.917554,0.409420,-169.605865,0.041731,0.000000
34.030003,8.359016,-169.605865,0.006558,0.001623,0.041219,37.182762,1.894180,0.412190,-169.605865,0.042173,0.000000
34.300003,8.512062,-169.561386,0.006579,0.001642,0.041696,37.863544,1.928861,0.416959,-169.561386,0.042624,0.000000
34.570004,8.642395,-169.516907,0.006601,0.001662,0.042208,38.443295,1.958395,0.422076,-169.516907,0.043075,0.000000
34.840000,8.664734,-169.605865,0.006597,0.001679,0.042659,38.542660,1.963457,0.426588,-169.605865,0.043526,0.000000
35.110001,8.846077,-169.650345,0.006614,0.001701,0.043205,39.349316,2.004550,0.432053,-169.650345,0.043977,0.000000
35.380001,8.727669,-169.561386,0.006640,0.001714,0.043544,38.822609,1.977718,0.435437,-169.561386,0.044428,0.000000
35.650002,8.829697,-169.561386,0.006661,0.001733,0.044021,39.276451,2.000838,0.440206,-169.561386,0.044879,0.000000
35.920002,8.760803,-169.605865,0.006657,0.001748,0.044402,38.969997,1.985226,0.444021,-169.605865,0.045330,0.000000
36.190002,8.862839,-169.561386,0.006670,0.001767,0.044879,39.423874,2.008348,0.448790,-169.561386,0.045781,0.000000
36.460003,8.968216,-169.694824,0.006691,0.001785,0.045339,39.892616,2.032227,0.453385,-169.694824,0.046232,0.000000
36.730003,8.789482,-169.694824,0.006717,0.001797,0.045634,39.097569,1.991725,0.456337,-169.694824,0.046674,0.000000
37.000000,8.860603,-169.605865,0.006700,0.001814,0.046067,39.413933,2.007841,0.460667,-169.605865,0.047125,0.000000
37.270000,9.237442,-169.605865,0.006748,0.001841,0.046769,41.090195,2.093234,0.467692,-169.605865,0.047576,0.000000
37.540001,9.069878,-169.605865,0.006748,0.001856,0.047133,40.344830,2.055264,0.471333,-169.605865,0.048027,0.000000
37.810001,9.094826,-169.694824,0.006769,0.001873,0.047567,40.455807,2.060917,0.475670,-169.694824,0.048478,0.000000
38.080002,9.030777,-169.694824,0.006773,0.001888,0.047966,40.170902,2.046403,0.479660,-169.694824,0.048929,0.000000
38.350002,9.353249,-169.650345,0.006804,0.001911,0.048538,41.605328,2.119476,0.485382,-169.650345,0.049380,0.000000
38.620003,9.150307,-169.650345,0.006808,0.001920,0.048773,40.702599,2.073489,0.487729,-169.650345,0.049830,0.000000
38.890003,9.308937,-169.605865,0.006817,0.001939,0.049250,41.408218,2.109435,0.492498,-169.605865,0.050282,0.000000
39.160004,9.289574,-169.739304,0.006838,0.001955,0.049657,41.322086,2.105047,0.496571,-169.739304,0.050724,0.000000
39.430000,9.624336,-169.694824,0.006855,0.001980,0.050291,42.811184,2.180906,0.502907,-169.694824,0.051175,0.000000
39.700001,9.417671,-169.694824,0.006864,0.001993,0.050628,41.891895,2.134075,0.506283,-169.694824,0.051626,0.000000
39.970001,9.477997,-169.694824,0.006881,0.002012,0.051114,42.160236,2.147745,0.511142,-169.694824,0.052077,0.000000
40.240002,9.511879,-169.739304,0.006894,0.002029,0.051539,42.310951,2.155423,0.515389,-169.739304,0.052528,0.000000
40.510002,9.484695,-169.739304,0.006911,0.002045,0.051955,42.190033,2.149263,0.519553,-169.739304,0.052979,0.000000
40.780003,9.648170,-169.828278,0.006920,0.002063,0.052406,42.917206,2.186307,0.524064,-169.828278,0.053430,0.000000
41.050003,9.711472,-169.783783,0.006942,0.002081,0.052848,43.198784,2.200651,0.528485,-169.783783,0.053881,0.000000
41.320004,9.775520,-169.694824,0.006954,0.002100,0.053343,43.483685,2.215165,0.533428,-169.694824,0.054331,0.000000
41.590000,9.848877,-169.739304,0.006972,0.002122,0.053907,43.809994,2.231787,0.539067,-169.739304,0.054774,0.000000
41.860001,9.686150,-169.828278,0.006985,0.002136,0.054253,43.086143,2.194913,0.542534,-169.828278,0.055225,0.000000
42.130001,9.789673,-169.783783,0.007006,0.002154,0.054713,43.546638,2.218372,0.547129,-169.783783,0.055676,0.000000
42.400002,9.976601,-169.739304,0.007011,0.002174,0.055216,44.378136,2.260730,0.552163,-169.739304,0.056127,0.000000
42.670002,9.912926,-169.783783,0.007019,0.002191,0.055641,44.094894,2.246301,0.556410,-169.783783,0.056578,0.000000
42.940002,10.102837,-169.783783,0.007036,0.002211,0.056162,44.939663,2.289335,0.561618,-169.783783,0.057029,0.000000
43.210003,9.971016,-169.872757,0.007045,0.002225,0.056526,44.353294,2.259465,0.565259,-169.872757,0.057480,0.000000
43.480003,10.054802,-169.828278,0.007067,0.002245,0.057020,44.725994,2.278451,0.570202,-169.828278,0.057931,0.000000
43.750004,9.990753,-169.783783,0.007080,0.002258,0.057359,44.441090,2.263937,0.573586,-169.783783,0.058381,0.000000
44.020000,9.999687,-169.783783,0.007092,0.002275,0.057774,44.480831,2.265962,0.577742,-169.783783,0.058832,0.000000
44.290001,10.279343,-169.739304,0.007118,0.002297,0.058347,45.724800,2.329332,0.583472,-169.739304,0.059274,0.000000
44.560001,10.170982,-169.828278,0.007136,0.002311,0.058702,45.242790,2.304778,0.587022,-169.828278,0.059726,0.000000
44.830002,10.159813,-169.828278,0.007144,0.002329,0.059162,45.193104,2.302247,0.591624,-169.828278,0.060177,0.000000
45.100002,10.413399,-169.828278,0.007157,0.002351,0.059717,46.321110,2.359710,0.597173,-169.828278,0.060628,0.000000
45.370003,10.419350,-169.828278,0.007166,0.002370,0.060194,46.347584,2.361058,0.601942,-169.828278,0.061078,0.000000
45.640003,10.379883,-169.917236,0.007179,0.002385,0.060567,46.172024,2.352115,0.605666,-169.917236,0.061530,0.000000
45.910004,10.310989,-169.828278,0.007196,0.002401,0.060983,45.865570,2.336504,0.609830,-169.828278,0.061981,0.000000
46.180000,10.557129,-169.917236,0.007200,0.002422,0.061512,46.960453,2.392280,0.615121,-169.917236,0.062432,0.000000
46.450001,10.497925,-169.917236,0.007222,0.002438,0.061928,46.697102,2.378864,0.619285,-169.917236,0.062882,0.000000
46.720001,10.750763,-169.872757,0.007235,0.002462,0.062545,47.821781,2.436158,0.625446,-169.872757,0.063325,0.000000
46.990002,10.699753,-169.961716,0.007261,0.002480,0.063004,47.594879,2.424599,0.630041,-169.961716,0.063775,0.000000
47.260002,10.492714,-169.872757,0.007269,0.002494,0.063351,46.673923,2.377683,0.633508,-169.872757,0.064227,0.000000
47.530003,10.338173,-169.961716,0.007274,0.002508,0.063698,45.986488,2.342664,0.636975,-169.961716,0.064678,0.000000
47.800003,10.639801,-169.961716,0.007308,0.002530,0.064252,47.328197,2.411013,0.642524,-169.961716,0.065129,0.000000
48.070004,10.615593,-169.917236,0.007299,0.002546,0.064669,47.220516,2.405528,0.646687,-169.917236,0.065579,0.000000
48.340004,10.551544,-169.917236,0.007312,0.002560,0.065016,46.935612,2.391014,0.650162,-169.917236,0.066031,0.000000
48.610001,10.585060,-169.917236,0.007330,0.002577,0.065449,47.084698,2.398609,0.654492,-169.917236,0.066482,0.000000
48.880001,10.958549,-169.961716,0.007360,0.002601,0.066056,48.746063,2.483243,0.660563,-169.961716,0.066932,0.000000
49.150002,10.886307,-169.917236,0.007364,0.002617,0.066473,48.424709,2.466872,0.664726,-169.917236,0.067375,0.000000
49.420002,10.897850,-170.006195,0.007381,0.002637,0.066976,48.476059,2.469488,0.669760,-170.006195,0.067825,0.000000
49.690002,10.750763,-169.917236,0.007386,0.002651,0.067331,47.821781,2.436158,0.673310,-169.917236,0.068276,0.000000
49.960003,10.896736,-170.006195,0.007411,0.002670,0.067809,48.471104,2.469236,0.678087,-170.006195,0.068728,0.000000
50.230003,10.834923,-169.961716,0.007424,0.002686,0.068216,48.196144,2.455229,0.682159,-169.961716,0.069179,0.000000
50.500004,10.734383,-170.006195,0.007437,0.002699,0.068545,47.748920,2.432446,0.685452,-170.006195,0.069629,0.000000
50.770004,11.398323,-169.961716,0.007450,0.002728,0.069283,50.702274,2.582897,0.692825,-169.961716,0.070080,0.000000
51.040001,11.181969,-170.050674,0.007463,0.002744,0.069708,49.739880,2.533870,0.697079,-170.050674,0.070532,0.000000
51.310001,11.113083,-170.095154,0.007463,0.002760,0.070115,49.433460,2.518261,0.701152,-170.095154,0.070983,0.000000
51.580002,10.834549,-170.006195,0.007476,0.002772,0.070401,48.194481,2.455144,0.704013,-170.006195,0.071433,0.000000
51.850002,11.225166,-170.006195,0.007506,0.002796,0.071008,49.932034,2.543659,0.710084,-170.006195,0.071876,0.000000
52.120003,11.144363,-170.006195,0.007524,0.002812,0.071425,49.572605,2.525349,0.714248,-170.006195,0.072326,0.000000
52.390003,10.957428,-170.006195,0.007532,0.002825,0.071746,48.741074,2.482989,0.717457,-170.006195,0.072777,0.000000
52.660004,11.447472,-170.095154,0.007545,0.002851,0.072413,50.920898,2.594034,0.724134,-170.095154,0.073229,0.000000
52.930004,11.358475,-170.006195,0.007567,0.002868,0.072855,50.525021,2.573867,0.728554,-170.006195,0.073680,0.000000
53.200001,11.303741,-170.050674,0.007567,0.002885,0.073281,50.281551,2.561465,0.732809,-170.050674,0.074130,0.000000
53.470001,11.278419,-170.006195,0.007588,0.002901,0.073688,50.168915,2.555727,0.736881,-170.006195,0.074581,0.000000
53.740002,11.408005,-170.006195,0.007606,0.002921,0.074182,50.745338,2.585091,0.741824,-170.006195,0.075033,0.000000
54.010002,11.456039,-170.095154,0.007601,0.002938,0.074616,50.959007,2.595976,0.746162,-170.095154,0.075483,0.000000
54.280003,11.246765,-170.139633,0.007623,0.002951,0.074945,50.028111,2.548553,0.749455,-170.139633,0.075926,0.000000
54.550003,11.762131,-170.095154,0.007649,0.002976,0.075587,52.320572,2.665337,0.755874,-170.095154,0.076376,0.000000
54.820004,11.732712,-170.095154,0.007666,0.002994,0.076056,52.189709,2.658670,0.760559,-170.095154,0.076827,0.000000
55.090004,11.663078,-170.095154,0.007679,0.003011,0.076481,51.879963,2.642891,0.764806,-170.095154,0.077278,0.000000
55.360004,11.428482,-170.139633,0.007692,0.003022,0.076749,50.836426,2.589731,0.767493,-170.139633,0.077730,0.000000
55.630001,11.717819,-170.184113,0.007700,0.003040,0.077218,52.123463,2.655296,0.772179,-170.184113,0.078180,0.000000
55.900002,11.931557,-170.095154,0.007713,0.003060,0.077721,53.074215,2.703729,0.777205,-170.095154,0.078631,0.000000
56.170002,11.834740,-170.095154,0.007726,0.003075,0.078102,52.643551,2.681790,0.781021,-170.095154,0.079082,0.000000
56.440002,12.091675,-170.095154,0.007752,0.003095,0.078623,53.786457,2.740013,0.786229,-170.095154,0.079534,0.000000
56.710003,12.163170,-170.139633,0.007752,0.003112,0.079057,54.104481,2.756214,0.790566,-170.139633,0.079984,0.000000
56.980003,12.407448,-170.184113,0.007769,0.003133,0.079568,55.191086,2.811568,0.795676,-170.184113,0.080427,0.000000
57.250004,12.243233,-170.228607,0.007795,0.003149,0.079984,54.460621,2.774356,0.799839,-170.228607,0.080877,0.000000
57.520004,12.360535,-170.095154,0.007800,0.003166,0.080409,54.982403,2.800937,0.804093,-170.095154,0.081328,0.000000
57.790001,12.571663,-170.139633,0.007821,0.003184,0.080869,55.921551,2.848780,0.808688,-170.139633,0.081779,0.000000
58.060001,12.348984,-170.184113,0.007830,0.003195,0.081155,54.931023,2.798320,0.811550,-170.184113,0.082231,0.000000
58.330002,12.477829,-170.273087,0.007830,0.003210,0.081545,55.504154,2.827517,0.815448,-170.273087,0.082681,0.000000
58.600002,13.226295,-170.273087,0.007847,0.003239,0.082282,58.833500,2.997122,0.822821,-170.273087,0.083132,0.000000
58.870003,13.050163,-170.139633,0.007873,0.003256,0.082708,58.050026,2.957209,0.827075,-170.139633,0.083583,0.000000
59.140003,13.137299,-170.184113,0.007899,0.003272,0.083097,58.437622,2.976954,0.830974,-170.184113,0.084034,0.000000
59.410004,13.105278,-170.184113,0.007890,0.003287,0.083496,58.295189,2.969698,0.834963,-170.184113,0.084477,0.000000
59.680004,13.682083,-170.228607,0.007907,0.003309,0.084051,60.860947,3.100404,0.840512,-170.228607,0.084927,0.000000
59.950005,13.335777,-170.228607,0.007920,0.003319,0.084312,59.320499,3.021930,0.843116,-170.228607,0.085378,0.000000
60.220001,13.708893,-170.228607,0.007938,0.003337,0.084763,60.980202,3.106480,0.847627,-170.228607,0.085829,0.000000
60.490002,13.771080,-170.184113,0.007946,0.003354,0.085179,61.256824,3.120571,0.851791,-170.184113,0.086280,0.000000
60.760002,14.383255,-170.228607,0.007972,0.003379,0.085829,63.979912,3.259292,0.858293,-170.228607,0.086731,0.000000
61.030003,14.230209,-170.317566,0.007976,0.003394,0.086202,63.299133,3.224612,0.862025,-170.317566,0.087182,0.000000
61.300003,14.403740,-170.228607,0.007985,0.003412,0.086653,64.071037,3.263934,0.866529,-170.228607,0.087633,0.000000
61.570004,14.601837,-170.228607,0.008019,0.003429,0.087104,64.952217,3.308824,0.871041,-170.228607,0.088084,0.000000
61.840004,14.644661,-170.228607,0.008028,0.003444,0.087468,65.142708,3.318527,0.874682,-170.228607,0.088526,0.000000
62.110004,14.935860,-170.273087,0.008041,0.003460,0.087876,66.438019,3.384514,0.878762,-170.273087,0.088978,0.000000
62.380001,15.254608,-170.273087,0.008054,0.003478,0.088353,67.855888,3.456743,0.883531,-170.273087,0.089428,0.000000
62.650002,15.572617,-170.317566,0.008075,0.003499,0.088865,69.270454,3.528805,0.888648,-170.317566,0.089879,0.000000
62.920002,15.931580,-170.273087,0.008093,0.003522,0.089454,70.867203,3.610147,0.894545,-170.273087,0.090330,0.000000
63.190002,15.765503,-170.273087,0.008097,0.003534,0.089775,70.128456,3.572514,0.897754,-170.273087,0.090781,0.000000
63.460003,16.185913,-170.317566,0.008106,0.003554,0.090278,71.998535,3.667780,0.902781,-170.317566,0.091232,0.000000
63.730003,16.555679,-170.362045,0.008132,0.003573,0.090747,73.643341,3.751571,0.907466,-170.362045,0.091683,0.000000
64.000000,16.657333,-170.317566,0.008153,0.003590,0.091180,74.095520,3.774606,0.911804,-170.317566,0.092134,0.000000
64.270004,17.238235,-170.317566,0.008166,0.003610,0.091691,76.679504,3.906240,0.916914,-170.317566,0.092585,0.000000
64.540001,17.187592,-170.362045,0.008166,0.003624,0.092056,76.454224,3.894764,0.920562,-170.362045,0.093027,0.000000
64.810005,17.384956,-170.362045,0.008192,0.003643,0.092541,77.332146,3.939487,0.925414,-170.362045,0.093479,0.000000
65.080002,17.748764,-170.362045,0.008201,0.003660,0.092967,78.950447,4.021927,0.929669,-170.362045,0.093929,0.000000
65.350006,17.841850,-170.362045,0.008222,0.003673,0.093296,79.364517,4.043021,0.932961,-170.362045,0.094380,0.000000
65.620003,18.553085,-170.273087,0.008244,0.003695,0.093860,82.528244,4.204189,0.938601,-170.273087,0.094831,0.000000
65.889999,18.639473,-170.317566,0.008239,0.003710,0.094224,82.912514,4.223765,0.942242,-170.317566,0.095282,0.000000
66.160004,19.240112,-170.406525,0.008248,0.003730,0.094753,85.584297,4.359872,0.947533,-170.406525,0.095733,0.000000
66.430000,19.681747,-170.362045,0.008265,0.003750,0.095239,87.548782,4.459948,0.952386,-170.362045,0.096184,0.000000
66.700005,20.038475,-170.362045,0.008300,0.003770,0.095750,89.135590,4.540783,0.957503,-170.362045,0.096635,0.000000
66.970001,20.187798,-170.406525,0.008300,0.003783,0.096089,89.799805,4.574620,0.960886,-170.406525,0.097077,0.000000
67.240005,20.420906,-170.406525,0.008313,0.003801,0.096540,90.836723,4.627443,0.965398,-170.406525,0.097528,0.000000
67.510002,21.057663,-170.451004,0.008321,0.003820,0.097017,93.669167,4.771735,0.970167,-170.451004,0.097979,0.000000
67.780006,21.400246,-170.406525,0.008343,0.003836,0.097441,95.193047,4.849365,0.974414,-170.406525,0.098430,0.000000
68.050003,22.346069,-170.406525,0.008364,0.003861,0.098074,99.400284,5.063692,0.980742,-170.406525,0.098881,0.000000
68.320000,22.641731,-170.406525,0.008377,0.003879,0.098525,100.715454,5.130690,0.985254,-170.406525,0.099332,0.000000
68.590004,22.746742,-170.406525,0.008390,0.003893,0.098881,101.182564,5.154486,0.988811,-170.406525,0.099783,0.000000
68.860001,22.781372,-170.406525,0.008390,0.003906,0.099210,101.336601,5.162333,0.992104,-170.406525,0.100234,0.000000
69.130005,23.713051,-170.451004,0.008407,0.003929,0.099792,105.480919,5.373454,0.997918,-170.451004,0.100685,0.000000
69.400002,24.015419,-170.451004,0.008429,0.003944,0.100173,106.825920,5.441972,1.001733,-170.451004,0.101127,0.000000
69.670006,24.267143,-170.406525,0.008442,0.003958,0.100537,107.945641,5.499013,1.005374,-170.406525,0.101578,0.000000
69.940002,24.731491,-170.451004,0.008451,0.003975,0.100962,110.011169,5.604236,1.009621,-170.451004,0.102029,0.000000
70.210007,25.984146,-170.495483,0.008455,0.003998,0.101561,115.583252,5.888092,1.015608,-170.495483,0.102480,0.000000
70.480003,26.275345,-170.539963,0.008476,0.004016,0.101995,116.878571,5.954078,1.019946,-170.539963,0.102931,0.000000
70.750000,26.918808,-170.451004,0.008481,0.004035,0.102489,119.740837,6.099889,1.024889,-170.451004,0.103382,0.000000
71.020004,27.341072,-170.495483,0.008511,0.004049,0.102853,121.619164,6.195575,1.028530,-170.495483,0.103833,0.000000
71.290001,27.964058,-170.495483,0.008520,0.004068,0.103322,124.390343,6.336746,1.033216,-170.495483,0.104284,0.000000
71.560005,28.472343,-170.539963,0.008515,0.004084,0.103737,126.651306,6.451925,1.037372,-170.539963,0.104735,0.000000
71.830002,28.794815,-170.539963,0.008541,0.004097,0.104067,128.085739,6.524998,1.040672,-170.539963,0.105186,0.000000
72.100006,30.348358,-170.584442,0.008567,0.004126,0.104804,134.996246,6.877036,1.048045,-170.584442,0.105628,0.000000
72.370003,30.612366,-170.539963,0.008567,0.004142,0.105212,136.170609,6.936862,1.052118,-170.539963,0.106079,0.000000
72.640007,31.285614,-170.495483,0.008580,0.004159,0.105646,139.165359,7.089421,1.056455,-170.495483,0.106530,0.000000
72.910004,31.393608,-170.539963,0.008597,0.004171,0.105940,139.645737,7.113894,1.059400,-170.539963,0.106981,0.000000
73.180000,32.593391,-170.584442,0.008601,0.004194,0.106530,144.982651,7.385768,1.065297,-170.584442,0.107432,0.000000
73.450005,33.169075,-170.584442,0.008614,0.004211,0.106963,147.543411,7.516220,1.069634,-170.584442,0.107883,0.000000
73.720001,33.385056,-170.584442,0.008632,0.004222,0.107241,148.504150,7.565162,1.072412,-170.584442,0.108334,0.000000
73.990005,34.726341,-170.539963,0.008640,0.004248,0.107901,154.470474,7.869102,1.079005,-170.539963,0.108785,0.000000
74.260002,35.635300,-170.539963,0.008649,0.004267,0.108386,158.513733,8.075074,1.083858,-170.539963,0.109236,0.000000
74.530006,36.232582,-170.628922,0.008662,0.004283,0.108794,161.170578,8.210421,1.087938,-170.628922,0.109678,0.000000
74.800003,36.796356,-170.628922,0.008679,0.004299,0.109201,163.678360,8.338173,1.092010,-170.628922,0.110129,0.000000
75.070007,37.455826,-170.539963,0.008683,0.004318,0.109678,166.611832,8.487611,1.096779,-170.539963,0.110580,0.000000
75.340004,38.400536,-170.628922,0.008692,0.004335,0.110103,170.814117,8.701686,1.101026,-170.628922,0.111031,0.000000
75.610001,38.606087,-170.584442,0.008705,0.004343,0.110320,171.728455,8.748264,1.103199,-170.584442,0.111482,0.000000
75.880005,40.441139,-170.673416,0.008714,0.004373,0.111075,179.891174,9.164093,1.110746,-170.673416,0.111933,0.000000
76.150002,41.432022,-170.628922,0.008731,0.004391,0.111534,184.298843,9.388630,1.115340,-170.628922,0.112383,0.000000
76.420006,42.219963,-170.628922,0.008748,0.004410,0.112002,187.803772,9.567181,1.120019,-170.628922,0.112835,0.000000
76.690002,42.525307,-170.584442,0.008744,0.004420,0.112262,189.162018,9.636373,1.122623,-170.584442,0.113286,0.000000
76.960007,43.515442,-170.673416,0.008757,0.004440,0.112766,193.566360,9.860741,1.127656,-170.673416,0.113728,0.000000
77.230003,44.745392,-170.717896,0.008774,0.004459,0.113260,199.037445,10.139451,1.132600,-170.717896,0.114179,0.000000
77.500000,45.348259,-170.673416,0.008783,0.004473,0.113607,201.719131,10.276062,1.136067,-170.673416,0.114630,0.000000
77.770004,46.405800,-170.628922,0.008800,0.004492,0.114109,206.423309,10.515705,1.141093,-170.628922,0.115080,0.000000
78.040001,47.596275,-170.628922,0.008804,0.004511,0.114569,211.718811,10.785470,1.145688,-170.628922,0.115532,0.000000
78.310005,48.360382,-170.673416,0.008813,0.004531,0.115080,215.117722,10.958619,1.150805,-170.673416,0.115983,0.000000
78.580002,49.431328,-170.717896,0.008821,0.004546,0.115462,219.881531,11.201300,1.154620,-170.717896,0.116434,0.000000
78.850006,50.368591,-170.673416,0.008830,0.004564,0.115922,224.050690,11.413686,1.159222,-170.673416,0.116884,0.000000
79.120003,51.578423,-170.673416,0.008847,0.004583,0.116399,229.432281,11.687838,1.163991,-170.673416,0.117336,0.000000
79.390007,52.078148,-170.673416,0.008852,0.004594,0.116676,231.655167,11.801078,1.166762,-170.673416,0.117787,0.000000
79.660004,52.895508,-170.717896,0.008860,0.004611,0.117110,235.290970,11.986294,1.171100,-170.717896,0.118229,0.000000
79.930000,55.084312,-170.717896,0.008869,0.004637,0.117787,245.027252,12.482284,1.177867,-170.717896,0.118680,0.000000
80.200005,55.699844,-170.762375,0.008873,0.004651,0.118133,247.765289,12.621765,1.181334,-170.762375,0.119131,0.000000
80.470001,56.826645,-170.717896,0.008882,0.004670,0.118628,252.777542,12.877102,1.186277,-170.717896,0.119581,0.000000
80.740005,57.609001,-170.673416,0.008895,0.004686,0.119018,256.257629,13.054387,1.190183,-170.673416,0.120033,0.000000
81.010002,59.238129,-170.717896,0.008899,0.004708,0.119581,263.504364,13.423553,1.195815,-170.717896,0.120484,0.000000
81.280006,59.732269,-170.806854,0.008903,0.004717,0.119816,265.702393,13.535525,1.198161,-170.806854,0.120934,0.000000
81.550003,60.819595,-170.762375,0.008929,0.004736,0.120284,270.539062,13.781917,1.202840,-170.762375,0.121385,0.000000
81.820007,61.909531,-170.762375,0.008942,0.004751,0.120675,275.387360,14.028900,1.206746,-170.762375,0.121837,0.000000
82.090004,63.747551,-170.762375,0.008942,0.004775,0.121290,283.563263,14.445401,1.212900,-170.762375,0.122279,0.000000
82.360001,64.677376,-170.762375,0.008951,0.004790,0.121672,287.699341,14.656103,1.216715,-170.762375,0.122730,0.000000
82.630005,66.012703,-170.806854,0.008955,0.004808,0.122123,293.639160,14.958693,1.221227,-170.806854,0.123181,0.000000
82.900002,67.248238,-170.806854,0.008972,0.004826,0.122582,299.135101,15.238668,1.225821,-170.806854,0.123631,0.000000
83.170006,67.009911,-170.806854,0.008959,0.004819,0.122400,298.074982,15.184663,1.224005,-170.806854,0.122669,0.000000
83.440002,66.421562,-170.762375,0.008977,0.004818,0.122366,295.457855,15.051342,1.223657,-170.762375,0.122400,0.000000
83.710007,65.883110,-170.806854,0.008977,0.004816,0.122323,293.062714,14.929326,1.223225,-170.806854,0.122400,0.000000
83.980003,65.419518,-170.851334,0.008985,0.004815,0.122305,291.000549,14.824275,1.223051,-170.851334,0.122400,0.000000
84.250008,64.995384,-170.851334,0.008985,0.004815,0.122296,289.113922,14.728165,1.222960,-170.851334,0.122400,0.000000
84.520004,64.643120,-170.895813,0.008985,0.004815,0.122296,287.546967,14.648341,1.222960,-170.895813,0.122400,0.000000
84.790001,64.321007,-170.806854,0.008981,0.004814,0.122288,286.114136,14.575349,1.222877,-170.806854,0.122400,0.000000
85.060005,64.030556,-170.895813,0.008990,0.004814,0.122288,284.822144,14.509531,1.222877,-170.895813,0.122400,0.000000
85.330002,63.752769,-170.940292,0.009002,0.004814,0.122288,283.586487,14.446584,1.222877,-170.940292,0.122400,0.000000
85.600006,63.515205,-170.895813,0.008994,0.004814,0.122279,282.529755,14.392752,1.222786,-170.895813,0.122400,0.000000
85.870003,63.288429,-170.851334,0.008998,0.004814,0.122279,281.520996,14.341363,1.222786,-170.851334,0.122400,0.000000
86.140007,63.071327,-170.895813,0.009002,0.004814,0.122279,280.555267,14.292167,1.222786,-170.895813,0.122400,0.000000
86.410004,62.884399,-170.895813,0.009007,0.004814,0.122279,279.723785,14.249808,1.222786,-170.895813,0.122400,0.000000
86.680000,62.702309,-170.940292,0.009007,0.004814,0.122279,278.913788,14.208547,1.222786,-170.940292,0.122400,0.000000
86.950005,62.533249,-170.984772,0.008998,0.004814,0.122279,278.161774,14.170238,1.222786,-170.984772,0.122400,0.000000
87.220001,62.374619,-170.895813,0.008998,0.004814,0.122279,277.456146,14.134291,1.222786,-170.895813,0.122400,0.000000
87.490005,62.237213,-170.895813,0.009007,0.004814,0.122279,276.844940,14.103154,1.222786,-170.895813,0.122400,0.000000
87.760002,62.073746,-170.940292,0.008998,0.004814,0.122279,276.117798,14.066113,1.222786,-170.940292,0.122400,0.000000
88.030006,61.949371,-170.940292,0.009002,0.004814,0.122279,275.564575,14.037929,1.222786,-170.940292,0.122400,0.000000
88.300003,61.813828,-170.940292,0.009020,0.004814,0.122279,274.961639,14.007214,1.222786,-170.940292,0.122400,0.000000
88.570007,61.692062,-170.940292,0.009020,0.004814,0.122279,274.420013,13.979621,1.222786,-170.940292,0.122400,0.000000
88.840004,61.575508,-170.851334,0.009020,0.004814,0.122279,273.901550,13.953210,1.222786,-170.851334,0.122400,0.000000
89.110001,61.466774,-170.940292,0.009015,0.004814,0.122279,273.417877,13.928570,1.222786,-170.940292,0.122400,0.000000
89.380005,61.380013,-170.984772,0.009015,0.004814,0.122279,273.031921,13.908910,1.222786,-170.984772,0.122400,0.000000
89.650002,61.258995,-170.984772,0.009020,0.004814,0.122279,272.493622,13.881486,1.222786,-170.984772,0.122400,0.000000
89.920006,61.153236,-170.940292,0.009011,0.004814,0.122279,272.023193,13.857521,1.222786,-170.940292,0.122400,0.000000
90.190002,61.082863,-170.984772,0.009011,0.004814,0.122279,271.710144,13.841575,1.222786,-170.984772,0.122400,0.000000
90.460007,60.980461,-171.029251,0.009015,0.004814,0.122279,271.254639,13.818370,1.222786,-171.029251,0.122400,0.000000
90.730003,60.894814,-171.029251,0.009011,0.004814,0.122279,270.873657,13.798962,1.222786,-171.029251,0.122400,0.000000
91.000008,60.833000,-171.029251,0.009011,0.004814,0.122279,270.598694,13.784955,1.222786,-171.029251,0.122400,0.000000
91.270004,60.743629,-171.029251,0.009020,0.004814,0.122279,270.201172,13.764704,1.222786,-171.029251,0.122400,0.000000
91.540001,60.675484,-171.073730,0.009020,0.004814,0.122270,269.898041,13.749261,1.222703,-171.073730,0.122400,0.000000
91.810005,60.596169,-171.029251,0.009024,0.004814,0.122270,269.545227,13.731288,1.222703,-171.029251,0.122400,0.000000
92.080002,60.516853,-171.073730,0.009007,0.004814,0.122270,269.192413,13.713315,1.222703,-171.073730,0.122400,0.000000
92.350006,60.455414,-171.073730,0.009028,0.004814,0.122270,268.919098,13.699392,1.222703,-171.073730,0.122400,0.000000
92.620003,60.385033,-170.940292,0.009007,0.004814,0.122270,268.606049,13.683444,1.222703,-170.940292,0.122400,0.000000
92.890007,60.321358,-171.073730,0.009015,0.004814,0.122270,268.322815,13.669015,1.222703,-171.073730,0.122400,0.000000
93.160004,60.255074,-171.073730,0.009011,0.004814,0.122270,268.027954,13.653996,1.222703,-171.073730,0.122400,0.000000
93.430008,60.201828,-171.029251,0.009015,0.004814,0.122270,267.791107,13.641929,1.222703,-171.029251,0.122400,0.000000
93.700005,60.149323,-171.029251,0.009024,0.004814,0.122270,267.557556,13.630032,1.222703,-171.029251,0.122400,0.000000
93.970001,60.105759,-171.029251,0.009024,0.004814,0.122270,267.363770,13.620160,1.222703,-171.029251,0.122400,0.000000
94.240005,60.029045,-171.073730,0.009015,0.004814,0.122270,267.022522,13.602777,1.222703,-171.073730,0.122400,0.000000
94.510002,59.967232,-171.118225,0.009024,0.004814,0.122270,266.747559,13.588769,1.222703,-171.118225,0.122400,0.000000
94.780006,59.914726,-171.073730,0.009015,0.004814,0.122270,266.514008,13.576871,1.222703,-171.073730,0.122400,0.000000
95.050003,59.867065,-171.029251,0.009024,0.004814,0.122270,266.302002,13.566071,1.222703,-171.029251,0.122400,0.000000
95.320007,59.826477,-171.073730,0.009020,0.004814,0.122270,266.121460,13.556873,1.222703,-171.073730,0.122400,0.000000
95.590004,59.785141,-171.118225,0.009020,0.004814,0.122270,265.937592,13.547506,1.222703,-171.118225,0.122400,0.000000
95.860008,59.715508,-171.162704,0.009020,0.004814,0.122270,265.627838,13.531727,1.222703,-171.162704,0.122400,0.000000
96.130005,59.684975,-171.118225,0.009011,0.004814,0.122270,265.492035,13.524808,1.222703,-171.118225,0.122400,0.000000
96.400002,59.636192,-171.118225,0.009015,0.004814,0.122270,265.275024,13.513755,1.222703,-171.118225,0.122400,0.000000
96.670006,59.591507,-171.118225,0.009015,0.004814,0.122270,265.076263,13.503629,1.222703,-171.118225,0.122400,0.000000
96.940002,59.549805,-171.162704,0.009020,0.004814,0.122270,264.890747,13.494179,1.222703,-171.162704,0.122400,0.000000
97.210007,59.501770,-171.162704,0.009028,0.004814,0.122270,264.677094,13.483294,1.222703,-171.162704,0.122400,0.000000
97.480003,59.461548,-171.162704,0.009028,0.004814,0.122270,264.498169,13.474179,1.222703,-171.162704,0.122400,0.000000
97.750008,59.420219,-171.207184,0.009028,0.004814,0.122270,264.314331,13.464814,1.222703,-171.207184,0.122400,0.000000
98.020004,59.385590,-171.118225,0.009024,0.004814,0.122270,264.160309,13.456967,1.222703,-171.118225,0.122400,0.000000
98.290001,59.338295,-171.207184,0.009028,0.004814,0.122270,263.949921,13.446250,1.222703,-171.207184,0.122400,0.000000
98.560005,59.299942,-171.207184,0.009015,0.004814,0.122270,263.779327,13.437559,1.222703,-171.207184,0.122400,0.000000
98.830002,59.275734,-171.207184,0.009015,0.004814,0.122270,263.671631,13.432074,1.222703,-171.207184,0.122400,0.000000
99.100006,59.225838,-171.162704,0.009033,0.004814,0.122270,263.449677,13.420767,1.222703,-171.162704,0.122400,0.000000
99.370003,59.203499,-171.162704,0.009024,0.004814,0.122270,263.350311,13.415705,1.222703,-171.162704,0.122400,0.000000
99.640007,59.151367,-171.251663,0.009024,0.004814,0.122270,263.118408,13.403891,1.222703,-171.251663,0.122400,0.000000
99.910004,59.120087,-171.251663,0.009033,0.004814,0.122270,262.979279,13.396804,1.222703,-171.251663,0.122400,0.000000
100.180008,59.084335,-171.251663,0.009028,0.004814,0.122270,262.820251,13.388702,1.222703,-171.251663,0.122400,0.000000
100.450005,59.054176,-171.251663,0.009020,0.004814,0.122270,262.686096,13.381867,1.222703,-171.251663,0.122400,0.000000
100.720001,59.042259,-171.251663,0.009020,0.004814,0.122270,262.633087,13.379167,1.222703,-171.251663,0.122400,0.000000
100.990005,59.000183,-171.296143,0.009015,0.004814,0.122270,262.445923,13.369633,1.222703,-171.296143,0.122400,0.000000
101.260002,58.953262,-171.340622,0.009028,0.004814,0.122270,262.237213,13.359000,1.222703,-171.340622,0.122400,0.000000
101.530006,58.920868,-171.296143,0.009028,0.004814,0.122270,262.093109,13.351660,1.222703,-171.296143,0.122400,0.000000
101.800003,58.884377,-171.251663,0.009015,0.004814,0.122270,261.930786,13.343390,1.222703,-171.251663,0.122400,0.000000
102.070007,58.851974,-171.251663,0.009011,0.004814,0.122270,261.786652,13.336048,1.222703,-171.251663,0.122400,0.000000
102.340004,58.826286,-171.296143,0.009024,0.004814,0.122270,261.672394,13.330227,1.222703,-171.296143,0.122400,0.000000
102.610008,58.797241,-171.340622,0.009020,0.004814,0.122270,261.543182,13.323646,1.222703,-171.340622,0.122400,0.000000
102.880005,58.771172,-171.340622,0.009024,0.004814,0.122270,261.427216,13.317738,1.222703,-171.340622,0.122400,0.000000
103.150002,58.738777,-171.340622,0.009033,0.004814,0.122270,261.283142,13.310397,1.222703,-171.340622,0.122400,0.000000
103.420006,58.700798,-171.251663,0.009041,0.004814,0.122270,261.114197,13.301790,1.222703,-171.251663,0.122400,0.000000
103.690002,58.676216,-171.340622,0.009024,0.004814,0.122270,261.004852,13.296220,1.222703,-171.340622,0.122400,0.000000
103.960007,58.643074,-171.296143,0.009020,0.004814,0.122270,260.857422,13.288711,1.222703,-171.296143,0.122400,0.000000
104.230003,58.616638,-171.385101,0.009033,0.004814,0.122270,260.739838,13.282720,1.222703,-171.385101,0.122400,0.000000
104.500008,58.585358,-171.340622,0.009024,0.004814,0.122270,260.600677,13.275632,1.222703,-171.340622,0.122400,0.000000
104.770004,58.554451,-171.251663,0.009024,0.004814,0.122270,260.463196,13.268628,1.222703,-171.251663,0.122400,0.000000
105.040009,58.525406,-171.340622,0.009028,0.004814,0.122270,260.334015,13.262047,1.222703,-171.340622,0.122400,0.000000
105.310005,58.494873,-171.429581,0.009037,0.004814,0.122270,260.198181,13.255128,1.222703,-171.429581,0.122400,0.000000
105.580002,58.469551,-171.385101,0.009041,0.004814,0.122270,260.085541,13.249390,1.222703,-171.385101,0.122400,0.000000
105.850006,58.439392,-171.385101,0.009028,0.004814,0.122270,259.951385,13.242556,1.222703,-171.385101,0.122400,0.000000
106.120003,58.420769,-171.385101,0.009037,0.004814,0.122270,259.868561,13.238336,1.222703,-171.385101,0.122400,0.000000
106.390007,58.398804,-171.385101,0.009037,0.004814,0.122270,259.770844,13.233358,1.222703,-171.385101,0.122400,0.000000
106.660004,58.372734,-171.429581,0.009024,0.004814,0.122270,259.654877,13.227450,1.222703,-171.429581,0.122400,0.000000
106.930008,58.331398,-171.474060,0.009033,0.004814,0.122270,259.471008,13.218083,1.222703,-171.474060,0.122400,0.000000
107.200005,58.318367,-171.429581,0.009028,0.004814,0.122270,259.413055,13.215131,1.222703,-171.429581,0.122400,0.000000
107.470009,58.292305,-171.385101,0.009033,0.004814,0.122270,259.297119,13.209226,1.222703,-171.385101,0.122400,0.000000
107.740005,58.256927,-171.385101,0.009033,0.004814,0.122270,259.139771,13.201208,1.222703,-171.385101,0.122400,0.000000
108.010002,58.231979,-171.518555,0.009033,0.004814,0.122270,259.028778,13.195555,1.222703,-171.518555,0.122400,0.000000
108.280006,58.217827,-171.474060,0.009037,0.004814,0.122270,258.965820,13.192348,1.222703,-171.474060,0.122400,0.000000
108.550003,58.194366,-171.429581,0.009046,0.004814,0.122270,258.861481,13.187033,1.222703,-171.429581,0.122400,0.000000
108.820007,58.173141,-171.474060,0.009037,0.004814,0.122270,258.767059,13.182222,1.222703,-171.474060,0.122400,0.000000
109.090004,58.142235,-171.474060,0.009024,0.004814,0.122270,258.629578,13.175219,1.222703,-171.474060,0.122400,0.000000
109.360008,58.125481,-171.518555,0.009020,0.004814,0.122270,258.555054,13.171422,1.222703,-171.518555,0.122400,0.000000
109.630005,58.097549,-171.474060,0.009046,0.004814,0.122270,258.430817,13.165092,1.222703,-171.474060,0.122400,0.000000
109.900002,58.077812,-171.518555,0.009046,0.004814,0.122270,258.343018,13.160621,1.222703,-171.518555,0.122400,0.000000
110.170006,58.053986,-171.429581,0.009037,0.004814,0.122270,258.237030,13.155222,1.222703,-171.429581,0.122400,0.000000
110.440002,58.025681,-171.518555,0.009028,0.004814,0.122270,258.111115,13.148807,1.222703,-171.518555,0.122400,0.000000
110.710007,57.998131,-171.518555,0.009020,0.004814,0.122270,257.988556,13.142565,1.222703,-171.518555,0.122400,0.000000
110.980003,57.969086,-171.518555,0.009041,0.004814,0.122270,257.859375,13.135983,1.222703,-171.518555,0.122400,0.000000
111.250008,57.947113,-171.518555,0.009046,0.004814,0.122270,257.761627,13.131003,1.222703,-171.518555,0.122400,0.000000
111.520004,57.920677,-171.474060,0.009037,0.004814,0.122270,257.644043,13.125013,1.222703,-171.474060,0.122400,0.000000
111.790009,57.903542,-171.518555,0.009037,0.004814,0.122270,257.567810,13.121130,1.222703,-171.518555,0.122400,0.000000
112.060005,57.868172,-171.563034,0.009033,0.004814,0.122270,257.410492,13.113115,1.222703,-171.563034,0.122400,0.000000
112.330002,57.856995,-171.607513,0.009037,0.004814,0.122270,257.360779,13.110582,1.222703,-171.607513,0.122400,0.000000
112.600006,57.831680,-171.518555,0.009037,0.004814,0.122270,257.248169,13.104846,1.222703,-171.518555,0.122400,0.000000
112.870003,57.814545,-171.563034,0.009033,0.004814,0.122270,257.171936,13.100963,1.222703,-171.563034,0.122400,0.000000
113.140007,57.799652,-171.563034,0.009033,0.004814,0.122270,257.105682,13.097589,1.222703,-171.563034,0.122400,0.000000
113.400009,57.782150,-171.563034,0.009046,0.004814,0.122270,257.027832,13.093623,1.222703,-171.563034,0.122400,0.000000