File: Data/compression 9/AutoHeating-13-9-3--240404_04042024_174359.csv
Time (sec),S:Load (lbs),S:HL1 (DIM),S:LVDT (in),S:Position (in),Ch:Position (mm),Ch:Load (N),Ch:Stress (MPa),Ch:Strain (mm/mm),Ch:HL1 (DIM),Set Point (),Cycles ()
0.010000,0.007446,-164.312637,-0.000013,-0.000000,-0.000000,0.033123,0.001687,-0.000000,-164.312637,0.000251,0.000000
0.260000,0.003723,-164.312637,0.000000,-0.000000,-0.000000,0.016561,0.000844,-0.000000,-164.312637,0.000251,0.000000
0.510000,0.037613,-164.268158,-0.000004,0.000106,0.002680,0.167311,0.008523,0.026797,-164.268158,0.003460,0.000000
0.760000,0.024948,-164.312637,0.000078,0.000248,0.006296,0.110975,0.005653,0.062958,-164.312637,0.007623,0.000000
1.010000,0.011543,-164.312637,0.000246,0.000422,0.010727,0.051347,0.002616,0.107271,-164.312637,0.011785,0.000000
1.260000,-0.011169,-164.357117,0.000418,0.000580,0.014743,-0.049684,-0.002531,0.147429,-164.357117,0.015948,0.000000
1.510000,0.040962,-164.401596,0.000569,0.000742,0.018853,0.182209,0.009282,0.188533,-164.401596,0.020111,0.000000
1.760000,0.054367,-164.357117,0.000746,0.000917,0.023285,0.241837,0.012320,0.232847,-164.357117,0.024273,0.000000
2.010000,0.015640,-164.312637,0.000901,0.001075,0.027317,0.069571,0.003544,0.273171,-164.312637,0.028453,0.000000
2.260000,0.053253,-164.357117,0.001069,0.001242,0.031541,0.236882,0.012067,0.315410,-164.357117,0.032616,0.000000
2.510000,0.026443,-164.312637,0.001229,0.001399,0.035530,0.117626,0.005992,0.355303,-164.312637,0.036779,0.000000
2.760000,0.041336,-164.357117,0.001401,0.001568,0.039831,0.183872,0.009367,0.398315,-164.357117,0.040941,0.000000
3.010000,0.000748,-164.401596,0.001552,0.001728,0.043890,0.003326,0.000169,0.438904,-164.401596,0.045104,0.000000
3.260000,0.042824,-164.446075,0.001738,0.001894,0.048104,0.190490,0.009704,0.481045,-164.446075,0.049267,0.000000
3.510000,0.066284,-164.401596,0.001884,0.002057,0.052259,0.294847,0.015020,0.522588,-164.401596,0.053430,0.000000
3.760000,0.028671,-164.357117,0.002065,0.002222,0.056439,0.127536,0.006497,0.564388,-164.357117,0.057610,0.000000
4.010000,0.048409,-164.401596,0.002229,0.002389,0.060671,0.215332,0.010970,0.606711,-164.401596,0.061773,0.000000
4.260000,0.065170,-164.401596,0.002384,0.002543,0.064591,0.289892,0.014768,0.645907,-164.401596,0.065935,0.000000
4.510000,0.033890,-164.446075,0.002557,0.002718,0.069049,0.150749,0.007680,0.690486,-164.446075,0.070098,0.000000
4.760000,0.133308,-164.401596,0.002729,0.002880,0.073142,0.592985,0.030208,0.731416,-164.401596,0.074260,0.000000
5.010000,0.709000,-164.357117,0.002880,-0.000003,-0.000086,3.153788,0.160662,-0.000863,-164.357117,0.001154,0.000000
5.260000,0.594681,-164.446075,0.002876,-0.000010,-0.000242,2.645272,0.134757,-0.002422,-164.446075,-0.000017,0.000000
5.510000,0.557816,-164.490555,0.002876,-0.000010,-0.000242,2.481287,0.126403,-0.002422,-164.490555,-0.000017,0.000000
5.760000,0.581276,-164.401596,0.002884,-0.000010,-0.000242,2.585644,0.131719,-0.002422,-164.401596,0.000365,0.000000
6.010000,0.552605,-164.490555,0.002897,-0.000010,-0.000242,2.458108,0.125222,-0.002422,-164.490555,0.000780,0.000000
6.260000,0.557442,-164.446075,0.002884,-0.000006,-0.000147,2.479625,0.126318,-0.001469,-164.446075,0.001197,0.000000
6.510000,0.860924,-164.490555,0.002923,0.000032,0.000807,3.829580,0.195088,0.008069,-164.490555,0.001613,0.000000
6.760000,0.948807,-164.446075,0.002928,0.000046,0.001163,4.220503,0.215003,0.011627,-164.446075,0.002029,0.000000
7.010000,1.037804,-164.490555,0.002940,0.000061,0.001562,4.616381,0.235170,0.015616,-164.490555,0.002446,0.000000
7.260000,1.142815,-164.446075,0.002962,0.000078,0.001986,5.083493,0.258965,0.019863,-164.446075,0.002862,0.000000
7.510000,1.262344,-164.490555,0.002979,0.000092,0.002342,5.615188,0.286051,0.023421,-164.490555,0.003278,0.000000
7.760000,1.463425,-164.446075,0.002992,0.000113,0.002862,6.509638,0.331617,0.028621,-164.446075,0.003703,0.000000
8.010000,1.523750,-164.446075,0.003001,0.000124,0.003140,6.777980,0.345287,0.031399,-164.446075,0.004119,0.000000
8.260000,1.646629,-164.446075,0.003018,0.000137,0.003469,7.324573,0.373132,0.034692,-164.446075,0.004536,0.000000
8.510000,1.773239,-164.446075,0.003027,0.000158,0.004007,7.887762,0.401822,0.040067,-164.446075,0.004952,0.000000
8.760000,1.949745,-164.490555,0.003048,0.000176,0.004458,8.672899,0.441819,0.044578,-164.490555,0.005368,0.000000
9.010000,2.001503,-164.490555,0.003061,0.000193,0.004892,8.903130,0.453547,0.048916,-164.490555,0.005785,0.000000
9.260000,2.139656,-164.490555,0.003083,0.000209,0.005299,9.517666,0.484853,0.052989,-164.490555,0.006201,0.000000
9.510000,2.272591,-164.490555,0.003096,0.000224,0.005689,10.108988,0.514976,0.056895,-164.490555,0.006618,0.000000
9.760000,2.443886,-164.579514,0.003117,0.000242,0.006141,10.870947,0.553792,0.061406,-164.579514,0.007034,0.000000
10.010000,2.437927,-164.535034,0.003130,0.000251,0.006375,10.844442,0.552442,0.063745,-164.535034,0.007449,0.000000
10.260000,2.656509,-164.446075,0.003122,0.000270,0.006860,11.816744,0.601974,0.068597,-164.446075,0.007866,0.000000
10.510000,2.820351,-164.579514,0.003160,0.000291,0.007389,12.545547,0.639101,0.073889,-164.579514,0.008282,0.000000
10.760000,2.923500,-164.579514,0.003178,0.000308,0.007814,13.004377,0.662475,0.078143,-164.579514,0.008698,0.000000
11.010000,2.994247,-164.490555,0.003195,0.000323,0.008204,13.319077,0.678506,0.082041,-164.490555,0.009115,0.000000
11.260000,3.007652,-164.579514,0.003199,0.000337,0.008568,13.378706,0.681544,0.085682,-164.579514,0.009531,0.000000
11.510000,3.161819,-164.579514,0.003225,0.000352,0.008933,14.064475,0.716479,0.089331,-164.579514,0.009947,0.000000
11.760000,3.364014,-164.579514,0.003242,0.000370,0.009393,14.963881,0.762296,0.093926,-164.579514,0.010364,0.000000
12.010000,3.426201,-164.579514,0.003247,0.000382,0.009696,15.240502,0.776388,0.096961,-164.579514,0.010780,0.000000
12.260000,3.629143,-164.579514,0.003268,0.000403,0.010242,16.143232,0.822376,0.102419,-164.579514,0.011196,0.000000
12.510000,3.689468,-164.623993,0.003272,0.000418,0.010623,16.411575,0.836046,0.106234,-164.623993,0.011613,0.000000
12.760000,3.778465,-164.535034,0.003290,0.000432,0.010979,16.807453,0.856212,0.109792,-164.535034,0.012028,0.000000
13.010000,3.909912,-164.623993,0.003311,0.000451,0.011448,17.392159,0.885999,0.114478,-164.623993,0.012454,0.000000
13.260000,4.125885,-164.623993,0.003324,0.000470,0.011950,18.352854,0.934939,0.119504,-164.623993,0.012870,0.000000
13.510000,4.210045,-164.623993,0.003333,0.000487,0.012376,18.727215,0.954010,0.123758,-164.623993,0.013286,0.000000
13.760000,4.181374,-164.623993,0.003359,0.000498,0.012653,18.599678,0.947513,0.126529,-164.623993,0.013703,0.000000
14.010000,4.359741,-164.712967,0.003367,0.000515,0.013069,19.393097,0.987931,0.130692,-164.712967,0.014118,0.000000
14.260000,4.516876,-164.623993,0.003397,0.000533,0.013538,20.092070,1.023539,0.135378,-164.623993,0.014535,0.000000
14.510000,4.639763,-164.579514,0.003397,0.000552,0.014015,20.638697,1.051385,0.140147,-164.579514,0.014951,0.000000
14.760000,4.744400,-164.668488,0.003428,0.000571,0.014492,21.104145,1.075096,0.144916,-164.668488,0.015367,0.000000
15.010001,4.786102,-164.623993,0.003445,0.000584,0.014838,21.289646,1.084546,0.148383,-164.623993,0.015784,0.000000
15.260001,4.824463,-164.668488,0.003449,0.000596,0.015151,21.460283,1.093239,0.151509,-164.668488,0.016200,0.000000
15.510001,5.038574,-164.623993,0.003475,0.000617,0.015671,22.412697,1.141757,0.156710,-164.623993,0.016616,0.000000
15.760001,5.149544,-164.623993,0.003492,0.000634,0.016096,22.906315,1.166903,0.160956,-164.623993,0.017033,0.000000
16.010000,5.375198,-164.668488,0.003510,0.000656,0.016651,23.910076,1.218037,0.166513,-164.668488,0.017449,0.000000
16.260000,5.512230,-164.668488,0.003531,0.000675,0.017136,24.519623,1.249089,0.171365,-164.668488,0.017865,0.000000
16.510000,5.454140,-164.712967,0.003544,0.000688,0.017467,24.261225,1.235926,0.174665,-164.712967,0.018282,0.000000
16.760000,5.392700,-164.668488,0.003553,0.000700,0.017770,23.987928,1.222003,0.177701,-164.668488,0.018697,0.000000
17.010000,5.493988,-164.623993,0.003566,0.000716,0.018177,24.438478,1.244956,0.181773,-164.623993,0.019114,0.000000
17.260000,5.726715,-164.668488,0.003600,0.000736,0.018689,25.473701,1.297692,0.186891,-164.668488,0.019530,0.000000
17.510000,5.798584,-164.668488,0.003596,0.000750,0.019053,25.793390,1.313978,0.190532,-164.668488,0.019946,0.000000
17.760000,5.757256,-164.712967,0.003617,0.000760,0.019314,25.609552,1.304613,0.193136,-164.712967,0.020363,0.000000
18.010000,5.823906,-164.757446,0.003617,0.000773,0.019625,25.906027,1.319716,0.196254,-164.757446,0.020787,0.000000
18.260000,6.256973,-164.757446,0.003648,0.000804,0.020432,27.832407,1.417850,0.204324,-164.757446,0.021204,0.000000
18.510000,6.150848,-164.712967,0.003660,0.000816,0.020719,27.360340,1.393802,0.207185,-164.712967,0.021620,0.000000
18.760000,6.232773,-164.712967,0.003686,0.000834,0.021195,27.724758,1.412367,0.211954,-164.712967,0.022036,0.000000
19.010000,6.251762,-164.801926,0.003695,0.000848,0.021542,27.809229,1.416670,0.215421,-164.801926,0.022453,0.000000
19.260000,6.287514,-164.801926,0.003712,0.000861,0.021880,27.968258,1.424771,0.218805,-164.801926,0.022869,0.000000
19.510000,6.443535,-164.757446,0.003729,0.000881,0.022375,28.662275,1.460126,0.223748,-164.757446,0.023285,0.000000
19.760000,6.396614,-164.801926,0.003742,0.000892,0.022653,28.453560,1.449494,0.226526,-164.801926,0.023702,0.000000
20.010000,6.487846,-164.801926,0.003751,0.000909,0.023077,28.859383,1.470167,0.230773,-164.801926,0.024118,0.000000
20.260000,6.764145,-164.801926,0.003786,0.000934,0.023719,30.088419,1.532777,0.237192,-164.801926,0.024534,0.000000
20.510000,6.689301,-164.757446,0.003786,0.000948,0.024074,29.755495,1.515817,0.240742,-164.757446,0.024950,0.000000
20.760000,6.760048,-164.801926,0.003803,0.000965,0.024500,30.070194,1.531849,0.244996,-164.801926,0.025366,0.000000
21.010000,6.694145,-164.801926,0.003811,0.000977,0.024803,29.777044,1.516915,0.248032,-164.801926,0.025783,0.000000
21.260000,6.880699,-164.757446,0.003837,0.000997,0.025332,30.606878,1.559189,0.253323,-164.757446,0.026199,0.000000
21.510000,6.911232,-164.757446,0.003850,0.001011,0.025670,30.742695,1.566108,0.256699,-164.757446,0.026615,0.000000
21.760000,6.855377,-164.801926,0.003859,0.001022,0.025956,30.494242,1.553451,0.259561,-164.801926,0.027032,0.000000
22.010000,7.165939,-164.801926,0.003885,0.001046,0.026572,31.875690,1.623825,0.265722,-164.801926,0.027448,0.000000
22.260000,7.199081,-164.801926,0.003902,0.001064,0.027014,32.023113,1.631335,0.270143,-164.801926,0.027864,0.000000
22.510000,7.192001,-164.801926,0.003919,0.001082,0.027474,31.991619,1.629731,0.274738,-164.801926,0.028281,0.000000
22.760000,7.132050,-164.890884,0.003928,0.001095,0.027821,31.724941,1.616146,0.278212,-164.890884,0.028697,0.000000
23.010000,7.177483,-164.846405,0.003945,0.001110,0.028185,31.927036,1.626441,0.281854,-164.846405,0.029122,0.000000
23.260000,7.235199,-164.846405,0.003962,0.001126,0.028602,32.183773,1.639519,0.286017,-164.846405,0.029538,0.000000
23.510000,7.222542,-164.846405,0.003971,0.001139,0.028931,32.127472,1.636651,0.289310,-164.846405,0.029954,0.000000
23.760000,7.504799,-164.846405,0.003988,0.001161,0.029495,33.383011,1.700612,0.294949,-164.846405,0.030371,0.000000
24.010000,7.545013,-164.890884,0.004001,0.001179,0.029937,33.561897,1.709724,0.299370,-164.890884,0.030787,0.000000
24.260000,7.582619,-164.846405,0.004018,0.001197,0.030406,33.729172,1.718246,0.304056,-164.846405,0.031203,0.000000
24.510000,7.525276,-164.890884,0.004049,0.001212,0.030787,33.474102,1.705252,0.307871,-164.890884,0.031619,0.000000
24.760000,7.469795,-164.846405,0.004057,0.001223,0.031073,33.227310,1.692680,0.310732,-164.846405,0.032035,0.000000
25.010002,7.483574,-164.935364,0.004074,0.001241,0.031515,33.288601,1.695802,0.315153,-164.935364,0.032452,0.000000
25.260002,7.667152,-164.890884,0.004079,0.001259,0.031984,34.105198,1.737402,0.319839,-164.890884,0.032868,0.000000
25.510002,7.640343,-164.890884,0.004109,0.001271,0.032296,33.985943,1.731326,0.322958,-164.890884,0.033284,0.000000
25.760002,7.821312,-164.890884,0.004105,0.001292,0.032816,34.790932,1.772335,0.328158,-164.890884,0.033701,0.000000
26.010002,7.895042,-164.935364,0.004139,0.001310,0.033267,35.118904,1.789042,0.332670,-164.935364,0.034117,0.000000
26.260002,7.846260,-164.890884,0.004148,0.001325,0.033648,34.901909,1.777988,0.336485,-164.890884,0.034533,0.000000
26.510002,7.845886,-164.890884,0.004156,0.001342,0.034082,34.900246,1.777903,0.340822,-164.890884,0.034950,0.000000
26.760002,7.908447,-164.935364,0.004174,0.001356,0.034446,35.178532,1.792080,0.344463,-164.935364,0.035366,0.000000
27.010002,8.051064,-164.935364,0.004191,0.001375,0.034915,35.812920,1.824397,0.349149,-164.935364,0.035782,0.000000
27.260002,8.048836,-164.979843,0.004212,0.001389,0.035279,35.803009,1.823892,0.352790,-164.979843,0.036198,0.000000
27.510002,7.895042,-164.979843,0.004230,0.001400,0.035548,35.118904,1.789042,0.355477,-164.979843,0.036614,0.000000
27.760002,8.273376,-164.935364,0.004243,0.001423,0.036155,36.801815,1.874774,0.361548,-164.935364,0.037031,0.000000
28.010002,8.284546,-165.024323,0.004255,0.001440,0.036589,36.851501,1.877305,0.365886,-165.024323,0.037447,0.000000
28.260002,8.260712,-165.024323,0.004277,0.001456,0.036979,36.745480,1.871904,0.369792,-165.024323,0.037872,0.000000
28.510002,8.184746,-164.979843,0.004281,0.001471,0.037352,36.407566,1.854690,0.373516,-164.979843,0.038288,0.000000
28.760002,8.054420,-164.979843,0.004294,0.001482,0.037638,35.827850,1.825158,0.376378,-164.979843,0.038704,0.000000
29.010002,8.502007,-165.024323,0.004324,0.001506,0.038262,37.818813,1.926582,0.382623,-165.024323,0.039121,0.000000
29.260002,8.362740,-165.024323,0.004333,0.001517,0.038523,37.199322,1.895024,0.385227,-165.024323,0.039537,0.000000
29.510002,8.298691,-164.979843,0.004337,0.001531,0.038878,36.914421,1.880510,0.388777,-164.979843,0.039953,0.000000
29.760002,8.573502,-164.935364,0.004346,0.001550,0.039381,38.136841,1.942783,0.393811,-164.935364,0.040370,0.000000
30.010002,8.624519,-165.024323,0.004381,0.001567,0.039806,38.363777,1.954344,0.398057,-165.024323,0.040786,0.000000
30.260002,8.652824,-164.979843,0.004398,0.001584,0.040231,38.489685,1.960758,0.402312,-164.979843,0.041202,0.000000
30.510002,8.650589,-165.024323,0.004402,0.001602,0.040699,38.479740,1.960251,0.406990,-165.024323,0.041619,0.000000
30.760002,8.490097,-165.024323,0.004428,0.001613,0.040968,37.765839,1.923883,0.409677,-165.024323,0.042035,0.000000
31.010002,8.814430,-165.113297,0.004419,0.001635,0.041532,39.208546,1.997378,0.415317,-165.113297,0.042451,0.000000
31.260002,8.688942,-165.068802,0.004449,0.001647,0.041835,38.650345,1.968942,0.418352,-165.068802,0.042867,0.000000
31.510002,8.850182,-165.024323,0.004458,0.001665,0.042295,39.367573,2.005480,0.422947,-165.024323,0.043283,0.000000
31.760002,8.971199,-165.113297,0.004488,0.001683,0.042738,39.905888,2.032903,0.427375,-165.113297,0.043700,0.000000
32.010002,9.030403,-165.024323,0.004497,0.001700,0.043188,40.169239,2.046319,0.431879,-165.024323,0.044116,0.000000
32.260002,9.137650,-165.068802,0.004510,0.001720,0.043700,40.646294,2.070621,0.436996,-165.068802,0.044532,0.000000
32.510002,8.932098,-165.068802,0.004536,0.001730,0.043934,39.731956,2.024042,0.439343,-165.068802,0.044949,0.000000
32.760002,9.023331,-165.068802,0.004549,0.001746,0.044342,40.137779,2.044716,0.443416,-165.068802,0.045365,0.000000
33.010002,9.272820,-165.113297,0.004566,0.001767,0.044871,41.247562,2.101251,0.448707,-165.113297,0.045781,0.000000
33.260002,9.117912,-165.113297,0.004575,0.001778,0.045165,40.558498,2.066148,0.451652,-165.113297,0.046206,0.000000
33.510002,9.333519,-165.113297,0.004596,0.001799,0.045686,41.517567,2.115006,0.456860,-165.113297,0.046622,0.000000
33.760002,9.272446,-165.157776,0.004600,0.001813,0.046041,41.245899,2.101166,0.460410,-165.157776,0.047039,0.000000
34.010002,9.371124,-165.113297,0.004618,0.001830,0.046475,41.684841,2.123527,0.464747,-165.113297,0.047455,0.000000
34.260002,9.438896,-165.113297,0.004635,0.001847,0.046908,41.986309,2.138885,0.469085,-165.113297,0.047871,0.000000
34.510002,9.377457,-165.113297,0.004648,0.001861,0.047282,41.713009,2.124962,0.472817,-165.113297,0.048288,0.000000
34.760002,9.544655,-165.202255,0.004669,0.001879,0.047732,42.456745,2.162850,0.477321,-165.202255,0.048704,0.000000
35.010002,9.545029,-165.202255,0.004678,0.001895,0.048131,42.458408,2.162934,0.481310,-165.202255,0.049120,0.000000
35.260002,9.562897,-165.113297,0.004708,0.001911,0.048547,42.537888,2.166983,0.485473,-165.113297,0.049536,0.000000
35.510002,9.603859,-165.157776,0.004712,0.001928,0.048981,42.720097,2.176265,0.489811,-165.157776,0.049952,0.000000
35.760002,9.792282,-165.202255,0.004738,0.001949,0.049493,43.558247,2.218963,0.494928,-165.202255,0.050369,0.000000
36.010002,9.708122,-165.246735,0.004734,0.001962,0.049839,43.183884,2.199892,0.498395,-165.246735,0.050785,0.000000
36.260002,9.562897,-165.202255,0.004756,0.001976,0.050187,42.537888,2.166983,0.501869,-165.202255,0.051201,0.000000
36.510002,9.682800,-165.246735,0.004773,0.001994,0.050637,43.071247,2.194154,0.506374,-165.246735,0.051618,0.000000
36.760002,9.798241,-165.202255,0.004790,0.002011,0.051089,43.584751,2.220313,0.510885,-165.202255,0.052034,0.000000
37.010002,9.803452,-165.202255,0.004794,0.002027,0.051487,43.607929,2.221494,0.514874,-165.202255,0.052450,0.000000
37.260002,9.899895,-165.157776,0.004816,0.002045,0.051947,44.036930,2.243348,0.519469,-165.157776,0.052867,0.000000
37.510002,10.036186,-165.202255,0.004838,0.002066,0.052468,44.643185,2.274232,0.524677,-165.202255,0.053283,0.000000
37.760002,9.924469,-165.202255,0.004850,0.002082,0.052875,44.146244,2.248917,0.528750,-165.202255,0.053699,0.000000
38.010002,9.674614,-165.246735,0.004872,0.002093,0.053161,43.034832,2.192299,0.531611,-165.246735,0.054115,0.000000
38.260002,9.573700,-165.291214,0.004876,0.002107,0.053508,42.585945,2.169431,0.535078,-165.291214,0.054540,0.000000
38.510002,10.072304,-165.291214,0.004898,0.002131,0.054115,44.803844,2.282417,0.541149,-165.291214,0.054957,0.000000
38.760002,9.918518,-165.202255,0.004919,0.002143,0.054428,44.119770,2.247568,0.544275,-165.202255,0.055373,0.000000
39.010002,9.828026,-165.291214,0.004937,0.002156,0.054774,43.717243,2.227063,0.547742,-165.291214,0.055789,0.000000
39.260002,9.839569,-165.246735,0.004945,0.002171,0.055147,43.768589,2.229678,0.551474,-165.246735,0.056205,0.000000
39.510002,10.389191,-165.335693,0.004958,0.002197,0.055815,46.213428,2.354224,0.558151,-165.335693,0.056621,0.000000
39.760002,10.035439,-165.291214,0.004980,0.002208,0.056092,44.639858,2.274063,0.560921,-165.291214,0.057038,0.000000
40.010002,10.101349,-165.335693,0.004988,0.002228,0.056596,44.933044,2.288998,0.565955,-165.335693,0.057454,0.000000
40.260002,10.069328,-165.291214,0.005001,0.002245,0.057020,44.790607,2.281743,0.570202,-165.291214,0.057870,0.000000
40.510002,10.001183,-165.291214,0.005023,0.002258,0.057359,44.487480,2.266300,0.573586,-165.291214,0.058287,0.000000
40.760002,10.028366,-165.291214,0.005036,0.002274,0.057767,44.608398,2.272460,0.577666,-165.291214,0.058703,0.000000
41.010002,9.802338,-165.335693,0.005044,0.002284,0.058009,43.602974,2.221241,0.580088,-165.335693,0.059119,0.000000
41.260002,9.860794,-165.335693,0.005053,0.002299,0.058390,43.863003,2.234488,0.583903,-165.335693,0.059536,0.000000
41.510002,10.589531,-165.380173,0.005083,0.002331,0.059197,47.104588,2.399622,0.591973,-165.380173,0.059952,0.000000
41.760002,10.252907,-165.469131,0.005101,0.002344,0.059527,45.607208,2.323342,0.595266,-165.469131,0.060368,0.000000
42.010002,10.112518,-165.380173,0.005101,0.002358,0.059891,44.982727,2.291529,0.598907,-165.380173,0.060784,0.000000
42.260002,9.976974,-165.335693,0.005118,0.002372,0.060238,44.379799,2.260815,0.602381,-165.335693,0.061200,0.000000
42.510002,10.114754,-165.335693,0.005139,0.002390,0.060698,44.992672,2.292036,0.606976,-165.335693,0.061617,0.000000
42.760002,10.175079,-165.424652,0.005157,0.002406,0.061122,45.261013,2.305706,0.611223,-165.424652,0.062033,0.000000
43.010002,10.070816,-165.380173,0.005170,0.002419,0.061452,44.797226,2.282079,0.614516,-165.380173,0.062449,0.000000
43.260002,10.451752,-165.424652,0.005191,0.002441,0.062007,46.491714,2.368401,0.620072,-165.424652,0.062866,0.000000
43.510002,10.470001,-165.380173,0.005204,0.002461,0.062501,46.572891,2.372536,0.625015,-165.380173,0.063290,0.000000
43.760002,10.201149,-165.424652,0.005230,0.002475,0.062866,45.376976,2.311613,0.628656,-165.424652,0.063707,0.000000
44.010002,10.159439,-165.335693,0.005234,0.002490,0.063255,45.191441,2.302162,0.632554,-165.335693,0.064123,0.000000
44.260002,10.032463,-165.424652,0.005251,0.002505,0.063637,44.626625,2.273389,0.636370,-165.424652,0.064539,0.000000
44.510002,10.190720,-165.424652,0.005269,0.002522,0.064071,45.330585,2.309250,0.640707,-165.424652,0.064956,0.000000
44.760002,10.081238,-165.424652,0.005273,0.002535,0.064392,44.843586,2.284441,0.643917,-165.424652,0.065372,0.000000
45.010002,10.111031,-165.424652,0.005299,0.002550,0.064773,44.976109,2.291192,0.647732,-165.424652,0.065788,0.000000
45.260002,10.536278,-165.424652,0.005325,0.002575,0.065415,46.867702,2.387555,0.654151,-165.424652,0.066205,0.000000
45.510002,10.348976,-165.469131,0.005325,0.002591,0.065823,46.034546,2.345111,0.658231,-165.469131,0.066620,0.000000
45.760002,10.253281,-165.380173,0.005346,0.002608,0.066239,45.608871,2.323427,0.662387,-165.380173,0.067037,0.000000
46.010002,10.175827,-165.469131,0.005368,0.002622,0.066594,45.264339,2.305875,0.665945,-165.469131,0.067453,0.000000
46.260002,10.094650,-165.424652,0.005385,0.002634,0.066907,44.903248,2.287480,0.669071,-165.424652,0.067869,0.000000
46.510002,10.316208,-165.469131,0.005385,0.002654,0.067418,45.888786,2.337686,0.674181,-165.469131,0.068286,0.000000
46.760002,10.093903,-165.469131,0.005411,0.002667,0.067739,44.899921,2.287311,0.677390,-165.469131,0.068702,0.000000
47.010002,10.090919,-165.469131,0.005407,0.002682,0.068121,44.886650,2.286635,0.681205,-165.469131,0.069118,0.000000
47.260002,10.498299,-165.469131,0.005428,0.002703,0.068667,46.698765,2.378948,0.686671,-165.469131,0.069535,0.000000
47.510002,10.310997,-165.469131,0.005454,0.002718,0.069049,45.865604,2.336505,0.690486,-165.469131,0.069951,0.000000
47.760002,10.363503,-165.513626,0.005458,0.002737,0.069508,46.099163,2.348403,0.695081,-165.513626,0.070367,0.000000
48.010002,10.229073,-165.513626,0.005476,0.002750,0.069838,45.501186,2.317941,0.698381,-165.513626,0.070784,0.000000
48.260002,10.093903,-165.513626,0.005484,0.002762,0.070150,44.899921,2.287311,0.701500,-165.513626,0.071199,0.000000
48.510002,10.428665,-165.513626,0.005510,0.002784,0.070714,46.389019,2.363169,0.707139,-165.513626,0.071625,0.000000
48.760002,10.282692,-165.469131,0.005527,0.002795,0.071000,45.739697,2.330091,0.710001,-165.469131,0.072041,0.000000
49.010002,10.694168,-165.513626,0.005532,0.002816,0.071538,47.570034,2.423333,0.715375,-165.513626,0.072457,0.000000
49.260002,10.726562,-165.602585,0.005566,0.002835,0.072014,47.714134,2.430674,0.720144,-165.602585,0.072874,0.000000
49.510002,10.521759,-165.558105,0.005562,0.002850,0.072396,46.803123,2.384265,0.723960,-165.558105,0.073289,0.000000
49.760002,10.569420,-165.513626,0.005592,0.002867,0.072830,47.015129,2.395065,0.728297,-165.513626,0.073706,0.000000
50.010002,10.348602,-165.513626,0.005601,0.002878,0.073090,46.032883,2.345027,0.730901,-165.513626,0.074122,0.000000
50.260002,10.787262,-165.513626,0.005614,0.002899,0.073637,47.984138,2.444428,0.736366,-165.513626,0.074538,0.000000
50.510002,10.777954,-165.602585,0.005622,0.002914,0.074026,47.942734,2.442319,0.740265,-165.602585,0.074955,0.000000
50.760002,10.550804,-165.602585,0.005635,0.002925,0.074295,46.932320,2.390846,0.742952,-165.602585,0.075371,0.000000
51.010002,10.895996,-165.647064,0.005665,0.002942,0.074738,48.467812,2.469068,0.747380,-165.647064,0.075787,0.000000
51.260002,10.990204,-165.602585,0.005665,0.002962,0.075241,48.886868,2.490416,0.752407,-165.602585,0.076204,0.000000
51.510002,11.365929,-165.558105,0.005687,0.002981,0.075718,50.558174,2.575556,0.757176,-165.558105,0.076620,0.000000
51.760002,11.059464,-165.558105,0.005696,0.002994,0.076048,49.194950,2.506110,0.760476,-165.558105,0.077036,0.000000
52.010002,11.072495,-165.602585,0.005726,0.003010,0.076447,49.252914,2.509063,0.764466,-165.602585,0.077453,0.000000
52.260002,11.427742,-165.647064,0.005739,0.003027,0.076889,50.833134,2.589563,0.768886,-165.647064,0.077868,0.000000
52.510002,11.472054,-165.602585,0.005760,0.003044,0.077305,51.030243,2.599605,0.773050,-165.602585,0.078284,0.000000
52.760002,11.581161,-165.647064,0.005764,0.003058,0.077677,51.515579,2.624329,0.776774,-165.647064,0.078701,0.000000
53.010002,11.800858,-165.647064,0.005782,0.003075,0.078103,52.492836,2.674113,0.781028,-165.647064,0.079117,0.000000
53.260002,12.117004,-165.647064,0.005795,0.003095,0.078605,53.899128,2.745752,0.786055,-165.647064,0.079534,0.000000
53.510002,12.247330,-165.691544,0.005816,0.003114,0.079091,54.478844,2.775285,0.790914,-165.691544,0.079958,0.000000
53.760002,12.146049,-165.647064,0.005816,0.003128,0.079456,54.028328,2.752334,0.794555,-165.647064,0.080375,0.000000
54.010002,12.363136,-165.647064,0.005838,0.003142,0.079802,54.993977,2.801527,0.798022,-165.647064,0.080791,0.000000
54.260002,12.448784,-165.691544,0.005855,0.003157,0.080193,55.374958,2.820935,0.801928,-165.691544,0.081207,0.000000
54.510002,12.685616,-165.647064,0.005872,0.003174,0.080609,56.428436,2.874602,0.806092,-165.647064,0.081624,0.000000
54.760002,13.125389,-165.691544,0.005877,0.003192,0.081077,58.384647,2.974256,0.810770,-165.691544,0.082040,0.000000
55.010002,13.204330,-165.691544,0.005911,0.003207,0.081459,58.735794,2.992144,0.814585,-165.691544,0.082456,0.000000
55.260002,13.502228,-165.691544,0.005915,0.003226,0.081936,60.060909,3.059649,0.819362,-165.691544,0.082873,0.000000
55.510002,13.577820,-165.736023,0.005933,0.003240,0.082291,60.397160,3.076778,0.822912,-165.736023,0.083289,0.000000
55.760002,13.616173,-165.736023,0.005937,0.003254,0.082655,60.567760,3.085469,0.826553,-165.736023,0.083705,0.000000
56.010002,13.894707,-165.736023,0.005967,0.003273,0.083124,61.806744,3.148585,0.831239,-165.736023,0.084122,0.000000
56.260002,14.214203,-165.736023,0.005967,0.003288,0.083514,63.227932,3.220984,0.835145,-165.736023,0.084537,0.000000
56.510002,14.497208,-165.736023,0.005989,0.003305,0.083947,64.486801,3.285114,0.839475,-165.736023,0.084953,0.000000
56.760002,15.042358,-165.780502,0.006006,0.003326,0.084468,66.911751,3.408647,0.844683,-165.780502,0.085370,0.000000
57.010002,15.371162,-165.780502,0.006010,0.003344,0.084945,68.374344,3.483155,0.849452,-165.780502,0.085786,0.000000
57.260002,15.049805,-165.736023,0.006036,0.003355,0.085222,66.944878,3.410335,0.852222,-165.736023,0.086202,0.000000
57.510002,15.381966,-165.736023,0.006053,0.003372,0.085639,68.422401,3.485603,0.856385,-165.736023,0.086619,0.000000
57.760002,15.629219,-165.824982,0.006066,0.003389,0.086072,69.522240,3.541632,0.860723,-165.824982,0.087035,0.000000
58.010002,16.197090,-165.780502,0.006075,0.003407,0.086532,72.048256,3.670313,0.865318,-165.780502,0.087452,0.000000
58.260002,16.082771,-165.736023,0.006088,0.003417,0.086792,71.539742,3.644408,0.867922,-165.736023,0.087868,0.000000
58.510002,16.684525,-165.780502,0.006101,0.003438,0.087321,74.216469,3.780767,0.873213,-165.780502,0.088284,0.000000
58.760002,17.347343,-165.780502,0.006109,0.003459,0.087850,77.164841,3.930964,0.878504,-165.780502,0.088709,0.000000
59.010002,17.504860,-165.780502,0.006127,0.003476,0.088302,77.865509,3.966658,0.883016,-165.780502,0.089125,0.000000
59.260002,17.414742,-165.824982,0.006148,0.003488,0.088596,77.464638,3.946237,0.885961,-165.824982,0.089542,0.000000
59.510002,17.603165,-165.736023,0.006148,0.003502,0.088943,78.302788,3.988934,0.889428,-165.736023,0.089958,0.000000
59.760002,18.566490,-165.824982,0.006178,0.003526,0.089550,82.587875,4.207227,0.895499,-165.824982,0.090374,0.000000
60.010002,18.756775,-165.824982,0.006191,0.003540,0.089923,83.434303,4.250346,0.899230,-165.824982,0.090790,0.000000
60.260002,18.729965,-165.824982,0.006200,0.003552,0.090227,83.315048,4.244271,0.902266,-165.824982,0.091206,0.000000
60.510002,19.130638,-165.824982,0.006217,0.003566,0.090582,85.097328,4.335064,0.905824,-165.824982,0.091622,0.000000
60.760002,20.094337,-165.824982,0.006230,0.003591,0.091224,89.384079,4.553442,0.912235,-165.824982,0.092039,0.000000
61.010002,20.403404,-165.869461,0.006243,0.003604,0.091554,90.758873,4.623477,0.915536,-165.869461,0.092455,0.000000
61.260002,20.493889,-165.913940,0.006256,0.003619,0.091918,91.161369,4.643981,0.919177,-165.913940,0.092871,0.000000
61.510002,21.044258,-165.824982,0.006269,0.003636,0.092360,93.609535,4.768697,0.923598,-165.824982,0.093288,0.000000
61.760002,21.082985,-165.869461,0.006286,0.003650,0.092706,93.781799,4.777473,0.927065,-165.869461,0.093704,0.000000
62.010002,22.006844,-165.958435,0.006295,0.003670,0.093227,97.891327,4.986822,0.932273,-165.958435,0.094120,0.000000
62.260002,22.112968,-165.913940,0.006308,0.003682,0.093513,98.363396,5.010870,0.935134,-165.913940,0.094537,0.000000
62.510002,22.335274,-165.958435,0.006316,0.003694,0.093817,99.352257,5.061245,0.938169,-165.958435,0.094953,0.000000
62.760002,23.994194,-165.869461,0.006325,0.003725,0.094615,106.731506,5.437162,0.946148,-165.869461,0.095369,0.000000
63.010002,24.009834,-165.958435,0.006334,0.003738,0.094944,106.801079,5.440706,0.949441,-165.958435,0.095785,0.000000
63.260002,24.422424,-165.869461,0.006368,0.003754,0.095360,108.636368,5.534201,0.953604,-165.869461,0.096201,0.000000
63.510002,24.795540,-165.958435,0.006364,0.003767,0.095681,110.296066,5.618750,0.956814,-165.958435,0.096618,0.000000
63.760002,25.429687,-165.913940,0.006385,0.003785,0.096150,113.116898,5.762450,0.961500,-165.913940,0.097043,0.000000
64.010002,26.068680,-165.913940,0.006394,0.003802,0.096583,115.959282,5.907247,0.965829,-165.913940,0.097459,0.000000
64.260002,26.044106,-165.958435,0.006403,0.003811,0.096800,115.849968,5.901679,0.968002,-165.958435,0.097875,0.000000
64.510002,26.464516,-165.958435,0.006407,0.003828,0.097234,117.720047,5.996945,0.972340,-165.958435,0.098291,0.000000
64.760002,28.105186,-165.913940,0.006428,0.003855,0.097910,125.018112,6.368726,0.979099,-165.913940,0.098708,0.000000
65.010002,28.480537,-165.913940,0.006437,0.003869,0.098274,126.687759,6.453782,0.982740,-165.913940,0.099124,0.000000
65.260002,28.966858,-166.002914,0.006450,0.003883,0.098630,128.851013,6.563984,0.986298,-166.002914,0.099540,0.000000
65.510002,29.317261,-166.002914,0.006467,0.003896,0.098968,130.409683,6.643386,0.989682,-166.002914,0.099957,0.000000
65.760002,30.327507,-166.002914,0.006480,0.003918,0.099515,134.903488,6.872312,0.995147,-166.002914,0.100373,0.000000
66.010002,30.613487,-166.002914,0.006493,0.003929,0.099792,136.175598,6.937116,0.997918,-166.002914,0.100789,0.000000
66.260002,30.951973,-166.002914,0.006497,0.003941,0.100113,137.681259,7.013817,1.001127,-166.002914,0.101206,0.000000
66.510002,32.355446,-166.002914,0.006506,0.003966,0.100729,143.924210,7.331849,1.007289,-166.002914,0.101622,0.000000
66.760002,33.283028,-166.002914,0.006523,0.003983,0.101171,148.050308,7.542042,1.011710,-166.002914,0.102038,0.000000
67.010002,33.896324,-166.002914,0.006532,0.004001,0.101630,150.778381,7.681017,1.016305,-166.002914,0.102454,0.000000
67.260002,34.385246,-166.002914,0.006532,0.004014,0.101960,152.953217,7.791808,1.019598,-166.002914,0.102870,0.000000
67.510002,34.671974,-166.047394,0.006549,0.004028,0.102307,154.228638,7.856782,1.023072,-166.047394,0.103287,0.000000
67.760002,36.049751,-166.047394,0.006571,0.004048,0.102819,160.357300,8.168990,1.028189,-166.047394,0.103703,0.000000
68.010002,36.682785,-166.002914,0.006575,0.004063,0.103191,163.173172,8.312438,1.031914,-166.002914,0.104119,0.000000
68.260002,37.196663,-166.047394,0.006571,0.004075,0.103512,165.459015,8.428885,1.035123,-166.047394,0.104536,0.000000
68.510002,38.230362,-166.047394,0.006597,0.004095,0.104016,170.057144,8.663124,1.040157,-166.047394,0.104952,0.000000
68.760002,39.146027,-166.091873,0.006601,0.004111,0.104423,174.130219,8.870617,1.044230,-166.091873,0.105377,0.000000
69.010002,40.041954,-166.091873,0.006605,0.004130,0.104900,178.115509,9.073636,1.048999,-166.091873,0.105793,0.000000
69.260002,40.929695,-166.047394,0.006618,0.004146,0.105308,182.064377,9.274801,1.053079,-166.047394,0.106209,0.000000
69.510002,41.160194,-166.047394,0.006631,0.004159,0.105646,183.089691,9.327034,1.056455,-166.047394,0.106626,0.000000
69.760002,42.557709,-166.091873,0.006648,0.004178,0.106114,189.306137,9.643714,1.061141,-166.091873,0.107042,0.000000
70.010002,43.106583,-166.091873,0.006648,0.004190,0.106426,191.747650,9.768091,1.064260,-166.091873,0.107458,0.000000
70.260002,43.588058,-166.091873,0.006648,0.004202,0.106729,193.889374,9.877195,1.067295,-166.091873,0.107875,0.000000
70.510002,45.629410,-166.091873,0.006670,0.004229,0.107424,202.969757,10.339772,1.074237,-166.091873,0.108291,0.000000
70.760002,46.339523,-166.047394,0.006687,0.004243,0.107779,206.128494,10.500687,1.077794,-166.047394,0.108707,0.000000
71.010002,47.177734,-166.091873,0.006691,0.004260,0.108212,209.857040,10.690628,1.082124,-166.091873,0.109123,0.000000
71.260002,48.145531,-166.091873,0.006696,0.004276,0.108603,214.162018,10.909933,1.086030,-166.091873,0.109539,0.000000
71.510002,48.573013,-166.136353,0.006704,0.004289,0.108932,216.063553,11.006803,1.089323,-166.136353,0.109956,0.000000
71.760002,50.160065,-166.136353,0.006717,0.004309,0.109444,223.123108,11.366433,1.094440,-166.136353,0.110372,0.000000
72.010002,50.580101,-166.136353,0.006713,0.004319,0.109704,224.991531,11.461615,1.097044,-166.136353,0.110788,0.000000
72.260002,51.487946,-166.180832,0.006730,0.004334,0.110086,229.029816,11.667336,1.100859,-166.180832,0.111205,0.000000
72.510002,52.859016,-166.180832,0.006739,0.004354,0.110598,235.128647,11.978024,1.105977,-166.180832,0.111621,0.000000
72.760002,54.245361,-166.136353,0.006743,0.004375,0.111118,241.295425,12.292175,1.111177,-166.136353,0.112037,0.000000
73.010002,55.115593,-166.136353,0.006748,0.004388,0.111456,245.166397,12.489371,1.114561,-166.136353,0.112454,0.000000
73.260002,55.982475,-166.180832,0.006748,0.004403,0.111829,249.022491,12.685810,1.118293,-166.180832,0.112869,0.000000
73.510002,57.176674,-166.180832,0.006773,0.004420,0.112280,254.334549,12.956420,1.122797,-166.180832,0.113286,0.000000
73.760002,58.325821,-166.180832,0.006773,0.004436,0.112670,259.446198,13.216821,1.126703,-166.180832,0.113702,0.000000
74.010002,59.039284,-166.180832,0.006791,0.004449,0.113009,262.619843,13.378493,1.130086,-166.180832,0.114127,0.000000
74.260002,60.475899,-166.180832,0.006786,0.004467,0.113460,269.010223,13.704034,1.134598,-166.180832,0.114544,0.000000
74.510002,61.972458,-166.180832,0.006804,0.004486,0.113954,275.667267,14.043159,1.139541,-166.180832,0.114959,0.000000
74.760002,63.260498,-166.180832,0.006808,0.004504,0.114396,281.396759,14.335033,1.143962,-166.180832,0.115376,0.000000
75.010002,64.384689,-166.225311,0.006821,0.004518,0.114769,286.397400,14.589780,1.147686,-166.225311,0.115792,0.000000
75.260002,64.892227,-166.180832,0.006821,0.004530,0.115056,288.655029,14.704788,1.150555,-166.180832,0.116208,0.000000
75.510002,66.210052,-166.225311,0.006821,0.004547,0.115498,294.517029,15.003412,1.154976,-166.225311,0.116625,0.000000
75.760002,67.212112,-166.180832,0.006838,0.004550,0.115576,298.974396,15.230482,1.155756,-166.180832,0.115862,0.000000
76.010002,66.621536,-166.225311,0.006851,0.004550,0.115576,296.347382,15.096657,1.155756,-166.225311,0.115862,0.000000
76.260002,66.262558,-166.269791,0.006838,0.004549,0.115532,294.750580,15.015310,1.155324,-166.269791,0.115576,0.000000
76.510002,65.820557,-166.225311,0.006847,0.004548,0.115515,292.784454,14.915152,1.155150,-166.225311,0.115576,0.000000
76.760002,65.424728,-166.269791,0.006847,0.004548,0.115515,291.023712,14.825455,1.155150,-166.269791,0.115576,0.000000
77.010002,65.085861,-166.225311,0.006838,0.004547,0.115506,289.516357,14.748668,1.155059,-166.225311,0.115576,0.000000
77.260002,64.777176,-166.225311,0.006851,0.004547,0.115506,288.143280,14.678718,1.155059,-166.225311,0.115576,0.000000
77.510002,64.516144,-166.225311,0.006860,0.004547,0.115506,286.982147,14.619568,1.155059,-166.225311,0.115576,0.000000
77.760002,64.257706,-166.314270,0.006868,0.004547,0.115506,285.832550,14.561004,1.155059,-166.314270,0.115576,0.000000
78.010002,64.040253,-166.269791,0.006873,0.004547,0.115506,284.865265,14.511728,1.155059,-166.269791,0.115576,0.000000
78.260002,63.827988,-166.269791,0.006864,0.004547,0.115498,283.921082,14.463629,1.154976,-166.269791,0.115576,0.000000
78.510002,63.632874,-166.225311,0.006868,0.004547,0.115498,283.053162,14.419415,1.154976,-166.225311,0.115576,0.000000
78.760002,63.469025,-166.269791,0.006868,0.004547,0.115498,282.324310,14.382286,1.154976,-166.269791,0.115576,0.000000
79.010002,63.291779,-166.358749,0.006873,0.004547,0.115498,281.535889,14.342122,1.154976,-166.358749,0.115576,0.000000
79.260002,63.139099,-166.314270,0.006877,0.004547,0.115498,280.856750,14.307525,1.154976,-166.314270,0.115576,0.000000
79.510002,63.001328,-166.358749,0.006873,0.004547,0.115498,280.243896,14.276304,1.154976,-166.358749,0.115576,0.000000
79.760002,62.859077,-166.314270,0.006868,0.004547,0.115498,279.611145,14.244071,1.154976,-166.314270,0.115576,0.000000
80.010002,62.732475,-166.314270,0.006873,0.004547,0.115498,279.047974,14.215383,1.154976,-166.314270,0.115576,0.000000
80.260002,62.609589,-166.358749,0.006877,0.004547,0.115498,278.501373,14.187535,1.154976,-166.358749,0.115576,0.000000
80.510002,62.484474,-166.358749,0.006873,0.004547,0.115498,277.944824,14.159184,1.154976,-166.358749,0.115576,0.000000
80.760002,62.395851,-166.358749,0.006877,0.004547,0.115498,277.550598,14.139102,1.154976,-166.358749,0.115576,0.000000
81.010002,62.273712,-166.358749,0.006868,0.004547,0.115498,277.007294,14.111425,1.154976,-166.358749,0.115576,0.000000
81.260002,62.179497,-166.314270,0.006873,0.004547,0.115498,276.588226,14.090075,1.154976,-166.314270,0.115576,0.000000
81.510002,62.086037,-166.358749,0.006881,0.004547,0.115498,276.172485,14.068896,1.154976,-166.358749,0.115576,0.000000
81.760002,61.985870,-166.358749,0.006873,0.004547,0.115498,275.726929,14.046199,1.154976,-166.358749,0.115576,0.000000
82.010002,61.907295,-166.403244,0.006873,0.004547,0.115498,275.377411,14.028393,1.154976,-166.403244,0.115576,0.000000
82.260002,61.823143,-166.358749,0.006877,0.004547,0.115498,275.003082,14.009325,1.154976,-166.358749,0.115576,0.000000
82.510002,61.737122,-166.358749,0.006885,0.004547,0.115498,274.620422,13.989832,1.154976,-166.358749,0.115576,0.000000
82.760002,61.678658,-166.358749,0.006881,0.004547,0.115498,274.360382,13.976583,1.154976,-166.358749,0.115576,0.000000
83.010002,61.581467,-166.403244,0.006890,0.004547,0.115498,273.928040,13.954559,1.154976,-166.403244,0.115576,0.000000
83.260002,61.526733,-166.403244,0.006877,0.004547,0.115498,273.684570,13.942158,1.154976,-166.403244,0.115576,0.000000
83.510002,61.451515,-166.403244,0.006877,0.004547,0.115498,273.350006,13.925113,1.154976,-166.403244,0.115576,0.000000
83.760002,61.372940,-166.403244,0.006881,0.004547,0.115498,273.000458,13.907308,1.154976,-166.403244,0.115576,0.000000
84.010002,61.316711,-166.403244,0.006877,0.004547,0.115498,272.750366,13.894566,1.154976,-166.403244,0.115576,0.000000
84.260002,61.257507,-166.403244,0.006881,0.004547,0.115498,272.487000,13.881149,1.154976,-166.403244,0.115576,0.000000
84.510002,61.200905,-166.403244,0.006873,0.004547,0.115498,272.235229,13.868323,1.154976,-166.403244,0.115576,0.000000
84.760002,61.129036,-166.447723,0.006890,0.004547,0.115498,271.915527,13.852037,1.154976,-166.447723,0.115576,0.000000
85.010002,61.073555,-166.447723,0.006885,0.004547,0.115498,271.668732,13.839465,1.154976,-166.447723,0.115576,0.000000
85.260002,61.016212,-166.447723,0.006885,0.004547,0.115498,271.413666,13.826471,1.154976,-166.447723,0.115576,0.000000
85.510002,60.975990,-166.492203,0.006894,0.004547,0.115498,271.234741,13.817356,1.154976,-166.492203,0.115576,0.000000
85.760002,60.916412,-166.447723,0.006881,0.004547,0.115498,270.969727,13.803856,1.154976,-166.447723,0.115576,0.000000
86.010002,60.852737,-166.403244,0.006890,0.004547,0.115498,270.686493,13.789428,1.154976,-166.403244,0.115576,0.000000
86.260002,60.806564,-166.447723,0.006881,0.004547,0.115498,270.481110,13.778965,1.154976,-166.447723,0.115576,0.000000
86.510002,60.767464,-166.536682,0.006881,0.004547,0.115498,270.307190,13.770104,1.154976,-166.536682,0.115576,0.000000
86.760002,60.713470,-166.492203,0.006881,0.004547,0.115498,270.067017,13.757870,1.154976,-166.492203,0.115576,0.000000
87.010002,60.653893,-166.447723,0.006890,0.004547,0.115498,269.802002,13.744369,1.154976,-166.447723,0.115576,0.000000
87.260002,60.627083,-166.536682,0.006894,0.004547,0.115498,269.682739,13.738294,1.154976,-166.536682,0.115576,0.000000
87.510002,60.561172,-166.447723,0.006885,0.004547,0.115498,269.389557,13.723357,1.154976,-166.447723,0.115576,0.000000
87.760002,60.539200,-166.492203,0.006885,0.004547,0.115498,269.291809,13.718379,1.154976,-166.492203,0.115576,0.000000
88.010002,60.497498,-166.492203,0.006903,0.004547,0.115498,269.106323,13.708929,1.154976,-166.492203,0.115576,0.000000
88.260002,60.438286,-166.492203,0.006898,0.004547,0.115498,268.842926,13.695512,1.154976,-166.492203,0.115576,0.000000
88.510002,60.404030,-166.536682,0.006903,0.004547,0.115498,268.690552,13.687749,1.154976,-166.536682,0.115576,0.000000
88.760002,60.383179,-166.536682,0.006894,0.004547,0.115498,268.597809,13.683024,1.154976,-166.536682,0.115576,0.000000
89.010002,60.313171,-166.536682,0.006898,0.004547,0.115498,268.286377,13.667159,1.154976,-166.536682,0.115576,0.000000
89.260002,60.301628,-166.581161,0.006885,0.004547,0.115498,268.235046,13.664544,1.154976,-166.581161,0.115576,0.000000
89.510002,60.249863,-166.581161,0.006898,0.004547,0.115498,268.004761,13.652814,1.154976,-166.581161,0.115576,0.000000
89.760002,60.220818,-166.536682,0.006885,0.004547,0.115498,267.875580,13.646232,1.154976,-166.536682,0.115576,0.000000
90.010002,60.179115,-166.581161,0.006903,0.004547,0.115498,267.690063,13.636783,1.154976,-166.581161,0.115576,0.000000
90.260002,60.140762,-166.625641,0.006890,0.004547,0.115498,267.519470,13.628092,1.154976,-166.625641,0.115576,0.000000
90.510002,60.123634,-166.581161,0.006881,0.004547,0.115498,267.443268,13.624210,1.154976,-166.581161,0.115576,0.000000
90.760002,60.084908,-166.625641,0.006885,0.004547,0.115498,267.271027,13.615435,1.154976,-166.625641,0.115576,0.000000
91.010002,60.041336,-166.581161,0.006890,0.004547,0.115498,267.077209,13.605560,1.154976,-166.581161,0.115576,0.000000
91.260002,60.025322,-166.625641,0.006894,0.004547,0.115498,267.005981,13.601933,1.154976,-166.625641,0.115576,0.000000
91.510002,59.982872,-166.581161,0.006894,0.004547,0.115498,266.817139,13.592313,1.154976,-166.581161,0.115576,0.000000
91.760002,59.951965,-166.581161,0.006890,0.004547,0.115498,266.679657,13.585310,1.154976,-166.581161,0.115576,0.000000
92.010002,59.923294,-166.670120,0.006894,0.004547,0.115498,266.552124,13.578812,1.154976,-166.670120,0.115576,0.000000
92.260002,59.896858,-166.581161,0.006898,0.004547,0.115498,266.434540,13.572823,1.154976,-166.581161,0.115576,0.000000
92.510002,59.873398,-166.581161,0.006894,0.004547,0.115498,266.330170,13.567506,1.154976,-166.581161,0.115576,0.000000
92.760002,59.826477,-166.625641,0.006898,0.004547,0.115498,266.121460,13.556873,1.154976,-166.625641,0.115576,0.000000
93.010002,59.794083,-166.625641,0.006898,0.004547,0.115498,265.977356,13.549532,1.154976,-166.625641,0.115576,0.000000
93.260002,59.781792,-166.625641,0.006885,0.004547,0.115498,265.922699,13.546747,1.154976,-166.625641,0.115576,0.000000
93.510002,59.726311,-166.625641,0.006894,0.004547,0.115498,265.675903,13.534175,1.154976,-166.625641,0.115576,0.000000
93.760002,59.719238,-166.625641,0.006894,0.004547,0.115498,265.644440,13.532573,1.154976,-166.625641,0.115576,0.000000
94.010002,59.675293,-166.670120,0.006894,0.004547,0.115498,265.448975,13.522615,1.154976,-166.670120,0.115576,0.000000
94.260002,59.655563,-166.625641,0.006894,0.004547,0.115498,265.361206,13.518144,1.154976,-166.625641,0.115576,0.000000
94.510002,59.635452,-166.625641,0.006890,0.004547,0.115498,265.271729,13.513586,1.154976,-166.625641,0.115576,0.000000
94.760002,59.586670,-166.670120,0.006903,0.004547,0.115498,265.054749,13.502533,1.154976,-166.670120,0.115576,0.000000
95.010002,59.566566,-166.670120,0.006903,0.004547,0.115498,264.965332,13.497977,1.154976,-166.670120,0.115576,0.000000
95.260002,59.546082,-166.759079,0.006894,0.004547,0.115498,264.874207,13.493335,1.154976,-166.759079,0.115576,0.000000
95.510002,59.512566,-166.714600,0.006894,0.004547,0.115498,264.725128,13.485741,1.154976,-166.714600,0.115576,0.000000
95.760002,59.485016,-166.625641,0.006903,0.004547,0.115498,264.602570,13.479497,1.154976,-166.625641,0.115576,0.000000
96.010002,59.458572,-166.759079,0.006894,0.004547,0.115498,264.484924,13.473505,1.154976,-166.759079,0.115576,0.000000
96.260002,59.436607,-166.670120,0.006903,0.004547,0.115498,264.387238,13.468528,1.154976,-166.670120,0.115576,0.000000
96.510002,59.410912,-166.759079,0.006890,0.004547,0.115498,264.272919,13.462705,1.154976,-166.759079,0.115576,0.000000
96.760002,59.390800,-166.759079,0.006890,0.004547,0.115498,264.183472,13.458147,1.154976,-166.759079,0.115576,0.000000
97.010002,59.374046,-166.714600,0.006898,0.004547,0.115498,264.108948,13.454351,1.154976,-166.714600,0.115576,0.000000
97.260002,59.342392,-166.714600,0.006911,0.004547,0.115498,263.968140,13.447178,1.154976,-166.714600,0.115576,0.000000
97.510002,59.327873,-166.759079,0.006903,0.004547,0.115498,263.903564,13.443888,1.154976,-166.759079,0.115576,0.000000
97.760002,59.304787,-166.759079,0.006898,0.004547,0.115498,263.800873,13.438657,1.154976,-166.759079,0.115576,0.000000
98.010002,59.275368,-166.759079,0.006894,0.004547,0.115498,263.670013,13.431991,1.154976,-166.759079,0.115576,0.000000
98.260002,59.252655,-166.759079,0.006894,0.004547,0.115498,263.568970,13.426844,1.154976,-166.759079,0.115576,0.000000
98.510002,59.229935,-166.803574,0.006898,0.004547,0.115498,263.467896,13.421695,1.154976,-166.803574,0.115576,0.000000
98.760002,59.214668,-166.714600,0.006903,0.004547,0.115498,263.399994,13.418236,1.154976,-166.714600,0.115576,0.000000
99.010002,59.186745,-166.803574,0.006890,0.004547,0.115498,263.275787,13.411908,1.154976,-166.803574,0.115576,0.000000
99.260002,59.168121,-166.803574,0.006907,0.004547,0.115498,263.192963,13.407688,1.154976,-166.803574,0.115576,0.000000
99.510002,59.159561,-166.803574,0.006907,0.004547,0.115498,263.154877,13.405748,1.154976,-166.803574,0.115576,0.000000
99.760002,59.127907,-166.759079,0.006898,0.004547,0.115498,263.014069,13.398575,1.154976,-166.759079,0.115576,0.000000
100.010002,59.110779,-166.803574,0.006907,0.004547,0.115498,262.937866,13.394693,1.154976,-166.803574,0.115576,0.000000
100.260002,59.086578,-166.803574,0.006894,0.004547,0.115498,262.830231,13.389211,1.154976,-166.803574,0.115576,0.000000
100.510002,59.078758,-166.803574,0.006894,0.004547,0.115498,262.795441,13.387438,1.154976,-166.803574,0.115576,0.000000
100.760002,59.038170,-166.892532,0.006903,0.004547,0.115498,262.614899,13.378241,1.154976,-166.892532,0.115576,0.000000
101.010002,59.016571,-166.803574,0.006894,0.004547,0.115498,262.518829,13.373345,1.154976,-166.803574,0.115576,0.000000
101.260002,59.012474,-166.848053,0.006890,0.004547,0.115498,262.500580,13.372418,1.154976,-166.848053,0.115576,0.000000
101.510002,58.993111,-166.803574,0.006911,0.004547,0.115498,262.414459,13.368031,1.154976,-166.803574,0.115576,0.000000
101.760002,58.969276,-166.892532,0.006911,0.004547,0.115498,262.308441,13.362629,1.154976,-166.892532,0.115576,0.000000
102.010002,58.947678,-166.937012,0.006907,0.004547,0.115498,262.212372,13.357735,1.154976,-166.937012,0.115576,0.000000
102.260002,58.939491,-166.848053,0.006903,0.004547,0.115498,262.175964,13.355880,1.154976,-166.848053,0.115576,0.000000
102.510002,58.923851,-166.892532,0.006898,0.004547,0.115498,262.106384,13.352336,1.154976,-166.892532,0.115576,0.000000
102.760002,58.901131,-166.892532,0.006903,0.004547,0.115498,262.005310,13.347187,1.154976,-166.892532,0.115576,0.000000
103.010002,58.886986,-166.892532,0.006898,0.004547,0.115498,261.942383,13.343982,1.154976,-166.892532,0.115576,0.000000
103.260002,58.866875,-166.937012,0.006898,0.004547,0.115498,261.852936,13.339424,1.154976,-166.937012,0.115576,0.000000
103.510002,58.859802,-166.892532,0.006903,0.004547,0.115498,261.821472,13.337822,1.154976,-166.892532,0.115576,0.000000
103.760002,58.821442,-166.892532,0.006898,0.004547,0.115498,261.650848,13.329129,1.154976,-166.892532,0.115576,0.000000
104.010002,58.813255,-166.981491,0.006911,0.004547,0.115498,261.614410,13.327273,1.154976,-166.981491,0.115576,0.000000
104.260002,58.806923,-166.981491,0.006903,0.004547,0.115498,261.586243,13.325839,1.154976,-166.981491,0.115576,0.000000
104.510002,58.766335,-166.937012,0.006907,0.004547,0.115498,261.405701,13.316642,1.154976,-166.937012,0.115576,0.000000
104.760002,58.761124,-166.892532,0.006903,0.004547,0.115498,261.382538,13.315461,1.154976,-166.892532,0.115576,0.000000
105.010002,58.735054,-166.937012,0.006911,0.004547,0.115498,261.266571,13.309554,1.154976,-166.937012,0.115576,0.000000
105.260002,58.731705,-166.937012,0.006894,0.004547,0.115498,261.251678,13.308795,1.154976,-166.937012,0.115576,0.000000
105.510002,58.698936,-166.981491,0.006903,0.004547,0.115498,261.105896,13.301370,1.154976,-166.981491,0.115576,0.000000
105.760002,58.695953,-166.937012,0.006903,0.004547,0.115498,261.092651,13.300694,1.154976,-166.937012,0.115576,0.000000
106.010002,58.678452,-166.937012,0.006898,0.004547,0.115498,261.014801,13.296727,1.154976,-166.937012,0.115576,0.000000
106.200005,58.667656,-167.025970,0.006894,0.004547,0.115498,260.966766,13.294281,1.154976,-167.025970,0.115576,0.000000