File: Data/compression 9/AutoHeating-13-9-2--240404_04042024_174116.csv
Time (sec),S:Load (lbs),S:HL1 (DIM),S:LVDT (in),S:Position (in),Ch:Position (mm),Ch:Load (N),Ch:Stress (MPa),Ch:Strain (mm/mm),Ch:HL1 (DIM),Set Point (),Cycles ()
0.010000,0.012657,-160.264862,-0.000009,0.000000,0.000008,0.056302,0.002868,0.000083,-160.264862,0.000225,0.000000
0.260000,0.009682,-160.264862,-0.000026,0.000000,0.000008,0.043066,0.002194,0.000083,-160.264862,0.000225,0.000000
0.510000,0.029785,-160.264862,0.000000,0.000099,0.002506,0.132491,0.006749,0.025056,-160.264862,0.003400,0.000000
0.760000,0.024200,-160.309341,0.000073,0.000251,0.006374,0.107649,0.005484,0.063738,-160.309341,0.007562,0.000000
1.010000,0.046173,-160.264862,0.000211,0.000409,0.010398,0.205388,0.010463,0.103979,-160.264862,0.011725,0.000000
1.260000,0.030159,-160.264862,0.000410,0.000587,0.014899,0.134154,0.006834,0.148989,-160.264862,0.015905,0.000000
1.510000,0.016380,-160.264862,0.000560,0.000746,0.018940,0.072863,0.003712,0.189396,-160.264862,0.020068,0.000000
1.760000,0.054367,-160.264862,0.000750,0.000909,0.023086,0.241837,0.012320,0.230856,-160.264862,0.024230,0.000000
2.010000,0.000374,-160.309341,0.000914,0.001079,0.027412,0.001663,0.000085,0.274125,-160.309341,0.028393,0.000000
2.260000,-0.053619,-160.309341,0.001074,0.001239,0.031471,-0.238511,-0.012150,0.314714,-160.309341,0.032555,0.000000
2.510000,0.028297,-160.309341,0.001229,0.001399,0.035547,0.125873,0.006412,0.355470,-160.309341,0.036718,0.000000
2.760000,0.042450,-160.309341,0.001401,0.001564,0.039719,0.188827,0.009619,0.397187,-160.309341,0.040881,0.000000
3.010000,0.002609,-160.353836,0.001561,0.001730,0.043934,0.011607,0.000591,0.439335,-160.353836,0.045043,0.000000
3.260000,0.029045,-160.353836,0.001742,0.001895,0.048122,0.129199,0.006582,0.481219,-160.353836,0.049223,0.000000
3.510000,0.042824,-160.309341,0.001901,0.002051,0.052094,0.190490,0.009704,0.520938,-160.309341,0.053386,0.000000
3.760000,0.022339,-160.398315,0.002078,0.002225,0.056508,0.099368,0.005062,0.565085,-160.398315,0.057549,0.000000
4.010000,-0.019737,-160.309341,0.002238,0.002386,0.060592,-0.087796,-0.004473,0.605924,-160.309341,0.061711,0.000000
4.260000,0.018990,-160.353836,0.002397,0.002550,0.064764,0.084470,0.004303,0.647641,-160.353836,0.065874,0.000000
4.510000,0.015640,-160.353836,0.002557,0.002715,0.068970,0.069571,0.003544,0.689699,-160.353836,0.070037,0.000000
4.760000,0.023460,-160.353836,0.002708,0.002873,0.072968,0.104357,0.005316,0.729682,-160.353836,0.074200,0.000000
5.010000,0.028671,-160.398315,0.002893,0.003040,0.077217,0.127536,0.006497,0.772172,-160.398315,0.078362,0.000000
5.260000,0.067024,-160.353836,0.003044,0.003199,0.081259,0.298139,0.015188,0.812587,-160.353836,0.082543,0.000000
5.510000,0.043198,-160.442795,0.003234,0.003374,0.085699,0.192153,0.009789,0.856991,-160.442795,0.086705,0.000000
5.760000,0.020103,-160.398315,0.003380,0.003532,0.089723,0.089425,0.004556,0.897232,-160.398315,0.090868,0.000000
6.010000,0.039841,-160.353836,0.003557,0.003698,0.093920,0.177220,0.009028,0.939199,-160.353836,0.095030,0.000000
6.260000,0.149696,-160.398315,0.003721,0.003863,0.098117,0.665883,0.033922,0.981173,-160.398315,0.099193,0.000000
6.510000,0.480362,-160.398315,0.003889,0.004026,0.102263,2.136757,0.108852,1.022633,-160.398315,0.103356,0.000000
6.760000,0.636383,-160.442795,0.003949,-0.000002,-0.000044,2.830773,0.144206,-0.000439,-160.442795,0.000156,0.000000
7.010000,0.586861,-160.487274,0.003949,-0.000002,-0.000052,2.610487,0.132985,-0.000522,-160.487274,0.000156,0.000000
7.260000,0.531746,-160.487274,0.003945,-0.000002,-0.000052,2.365324,0.120495,-0.000522,-160.487274,0.000425,0.000000
7.510000,0.543289,-160.442795,0.003936,-0.000002,-0.000052,2.416671,0.123111,-0.000522,-160.442795,0.000841,0.000000
7.760000,0.547012,-160.531754,0.003936,-0.000002,-0.000044,2.433232,0.123955,-0.000439,-160.531754,0.001257,0.000000
8.010000,0.770065,-160.487274,0.003949,0.000031,0.000798,3.425421,0.174499,0.007979,-160.487274,0.001674,0.000000
8.260000,0.841560,-160.531754,0.003988,0.000051,0.001283,3.743448,0.190700,0.012831,-160.531754,0.002090,0.000000
8.510000,0.892204,-160.442795,0.003997,0.000067,0.001699,3.968723,0.202176,0.016994,-160.442795,0.002506,0.000000
8.760000,0.949547,-160.487274,0.004010,0.000082,0.002081,4.223795,0.215170,0.020809,-160.487274,0.002922,0.000000
9.010000,1.009872,-160.531754,0.004031,0.000097,0.002462,4.492137,0.228840,0.024625,-160.531754,0.003338,0.000000
9.260000,1.093285,-160.442795,0.004040,0.000111,0.002827,4.863173,0.247742,0.028266,-160.442795,0.003764,0.000000
9.510000,1.255638,-160.487274,0.004049,0.000129,0.003278,5.585357,0.284532,0.032777,-160.487274,0.004180,0.000000
9.760000,1.273140,-160.487274,0.004066,0.000141,0.003590,5.663209,0.288498,0.035904,-160.487274,0.004596,0.000000
10.010000,1.420975,-160.487274,0.004092,0.000159,0.004041,6.320811,0.321997,0.040408,-160.487274,0.005012,0.000000
10.260000,1.471245,-160.487274,0.004092,0.000173,0.004388,6.544424,0.333389,0.043882,-160.487274,0.005428,0.000000
10.510000,1.624290,-160.487274,0.004126,0.000193,0.004908,7.225205,0.368069,0.049083,-160.487274,0.005845,0.000000
10.760000,1.675301,-160.531754,0.004130,0.000210,0.005325,7.452109,0.379629,0.053246,-160.531754,0.006261,0.000000
11.010000,1.788132,-160.487274,0.004152,0.000226,0.005749,7.954007,0.405196,0.057493,-160.487274,0.006677,0.000000
11.260000,1.928146,-160.531754,0.004156,0.000246,0.006253,8.576823,0.436924,0.062526,-160.531754,0.007094,0.000000
11.510000,1.982513,-160.487274,0.004174,0.000258,0.006547,8.818660,0.449244,0.065471,-160.487274,0.007510,0.000000
11.760000,2.099808,-160.576233,0.004195,0.000271,0.006894,9.340411,0.475823,0.068938,-160.576233,0.007926,0.000000
12.010000,2.243912,-160.620712,0.004212,0.000290,0.007354,9.981418,0.508478,0.073541,-160.620712,0.008343,0.000000
12.260000,2.419678,-160.531754,0.004238,0.000312,0.007917,10.763264,0.548307,0.079172,-160.531754,0.008759,0.000000
12.510000,2.452446,-160.576233,0.004247,0.000326,0.008273,10.909024,0.555732,0.082730,-160.576233,0.009175,0.000000
12.760000,2.558945,-160.576233,0.004255,0.000341,0.008672,11.382754,0.579865,0.086720,-160.576233,0.009591,0.000000
13.010000,2.639000,-160.576233,0.004277,0.000354,0.009001,11.738858,0.598006,0.090012,-160.576233,0.010007,0.000000
13.260000,2.824448,-160.531754,0.004290,0.000373,0.009470,12.563770,0.640029,0.094698,-160.531754,0.010424,0.000000
13.510000,2.910461,-160.620712,0.004303,0.000386,0.009817,12.946379,0.659520,0.098165,-160.620712,0.010840,0.000000
13.760000,3.047493,-160.531754,0.004312,0.000404,0.010250,13.555925,0.690572,0.102503,-160.531754,0.011256,0.000000
14.010000,3.290657,-160.576233,0.004346,0.000429,0.010900,14.637573,0.745674,0.109005,-160.576233,0.011673,0.000000
14.260000,3.374435,-160.531754,0.004376,0.000446,0.011326,15.010239,0.764658,0.113259,-160.531754,0.012097,0.000000
14.510000,3.363640,-160.620712,0.004368,0.000458,0.011638,14.962217,0.762212,0.116378,-160.620712,0.012514,0.000000
14.760000,3.415398,-160.576233,0.004389,0.000472,0.011976,15.192448,0.773940,0.119762,-160.576233,0.012930,0.000000
15.010001,3.707336,-160.620712,0.004406,0.000493,0.012531,16.491056,0.840094,0.125310,-160.620712,0.013346,0.000000
15.260001,3.761330,-160.620712,0.004428,0.000505,0.012826,16.731230,0.852329,0.128263,-160.620712,0.013763,0.000000
15.510001,3.859268,-160.576233,0.004445,0.000519,0.013190,17.166882,0.874523,0.131904,-160.576233,0.014179,0.000000
15.760001,3.945282,-160.665192,0.004454,0.000533,0.013537,17.549490,0.894014,0.135371,-160.665192,0.014595,0.000000
16.010000,4.326591,-160.620712,0.004475,0.000560,0.014222,19.245640,0.980420,0.142221,-160.620712,0.015012,0.000000
16.260000,4.265526,-160.665192,0.004497,0.000573,0.014543,18.974007,0.966582,0.145431,-160.665192,0.015428,0.000000
16.510000,4.363091,-160.620712,0.004510,0.000591,0.015003,19.407995,0.988690,0.150026,-160.620712,0.015844,0.000000
16.760000,4.429367,-160.620712,0.004514,0.000606,0.015401,19.702808,1.003709,0.154015,-160.620712,0.016260,0.000000
17.010000,4.570496,-160.620712,0.004553,0.000622,0.015792,20.330580,1.035689,0.157921,-160.620712,0.016676,0.000000
17.260000,4.660614,-160.665192,0.004566,0.000636,0.016165,20.731447,1.056110,0.161645,-160.665192,0.017093,0.000000
17.510000,4.660614,-160.665192,0.004579,0.000650,0.016512,20.731447,1.056110,0.165120,-160.665192,0.017509,0.000000
17.760000,4.794296,-160.665192,0.004592,0.000663,0.016832,21.326096,1.086403,0.168322,-160.665192,0.017925,0.000000
18.010000,5.218056,-160.709671,0.004618,0.000694,0.017630,23.211071,1.182428,0.176300,-160.709671,0.018342,0.000000
18.260000,5.162201,-160.665192,0.004635,0.000707,0.017968,22.962616,1.169771,0.179684,-160.665192,0.018758,0.000000
18.510000,5.189011,-160.754150,0.004644,0.000721,0.018316,23.081873,1.175847,0.183159,-160.754150,0.019174,0.000000
18.760000,5.175606,-160.665192,0.004661,0.000732,0.018585,23.022243,1.172809,0.185846,-160.665192,0.019591,0.000000
19.010000,5.422485,-160.709671,0.004678,0.000752,0.019105,24.120420,1.228753,0.191046,-160.709671,0.020007,0.000000
19.260000,5.544998,-160.754150,0.004700,0.000769,0.019538,24.665384,1.256515,0.195384,-160.754150,0.020432,0.000000
19.510000,5.397537,-160.709671,0.004700,0.000779,0.019781,24.009445,1.223099,0.197814,-160.709671,0.020848,0.000000
19.760000,5.553192,-160.709671,0.004721,0.000797,0.020232,24.701832,1.258371,0.202318,-160.709671,0.021264,0.000000
20.010000,5.905083,-160.754150,0.004747,0.000820,0.020821,26.267120,1.338111,0.208215,-160.754150,0.021681,0.000000
20.260000,5.901733,-160.709671,0.004760,0.000838,0.021273,26.252222,1.337352,0.212726,-160.709671,0.022097,0.000000
20.510000,5.905457,-160.754150,0.004786,0.000850,0.021603,26.268784,1.338196,0.216027,-160.754150,0.022513,0.000000
20.760000,5.887955,-160.843124,0.004794,0.000862,0.021897,26.190931,1.334230,0.218971,-160.843124,0.022929,0.000000
21.010000,6.157181,-160.754150,0.004820,0.000885,0.022478,27.388508,1.395237,0.224785,-160.754150,0.023345,0.000000
21.260000,6.205956,-160.798645,0.004833,0.000899,0.022834,27.605469,1.406290,0.228335,-160.798645,0.023762,0.000000
21.510000,6.235001,-160.843124,0.004838,0.000914,0.023224,27.734669,1.412871,0.232241,-160.843124,0.024178,0.000000
21.760000,6.427147,-160.798645,0.004876,0.000933,0.023709,28.589376,1.456412,0.237093,-160.798645,0.024594,0.000000
22.010000,6.487846,-160.798645,0.004885,0.000951,0.024152,28.859383,1.470167,0.241522,-160.798645,0.025011,0.000000
22.260000,6.554123,-160.798645,0.004902,0.000969,0.024620,29.154196,1.485186,0.246200,-160.798645,0.025427,0.000000
22.510000,6.541092,-160.709671,0.004919,0.000982,0.024941,29.096230,1.482233,0.249409,-160.709671,0.025843,0.000000
22.760000,6.632324,-160.843124,0.004941,0.000999,0.025366,29.502052,1.502906,0.253664,-160.843124,0.026260,0.000000
23.010000,6.755577,-160.843124,0.004950,0.001016,0.025817,30.050308,1.530836,0.258168,-160.843124,0.026676,0.000000
23.260000,6.760796,-160.843124,0.004975,0.001032,0.026207,30.073521,1.532018,0.262074,-160.843124,0.027092,0.000000
23.510000,6.864685,-160.887604,0.004988,0.001049,0.026632,30.535645,1.555560,0.266320,-160.887604,0.027508,0.000000
23.760000,6.881073,-160.843124,0.005014,0.001065,0.027048,30.608541,1.559273,0.270484,-160.843124,0.027924,0.000000
24.010000,7.027412,-160.798645,0.005023,0.001083,0.027500,31.259491,1.592435,0.274995,-160.798645,0.028341,0.000000
24.260000,6.990921,-160.843124,0.005044,0.001099,0.027916,31.097170,1.584165,0.279159,-160.843124,0.028757,0.000000
24.510000,7.040070,-160.843124,0.005062,0.001113,0.028280,31.315794,1.595302,0.282800,-160.843124,0.029182,0.000000
24.760000,7.027786,-160.843124,0.005079,0.001127,0.028618,31.261154,1.592519,0.286183,-160.843124,0.029598,0.000000
25.010002,7.198700,-160.887604,0.005092,0.001144,0.029069,32.021416,1.631249,0.290688,-160.887604,0.030014,0.000000
25.260002,7.148804,-160.843124,0.005113,0.001158,0.029425,31.799467,1.619942,0.294245,-160.843124,0.030431,0.000000
25.510002,7.202431,-160.887604,0.005118,0.001174,0.029823,32.038013,1.632094,0.298235,-160.887604,0.030847,0.000000
25.760002,7.469421,-160.843124,0.005152,0.001199,0.030456,33.225647,1.692595,0.304563,-160.843124,0.031263,0.000000
26.010002,7.410957,-160.932083,0.005161,0.001214,0.030847,32.965584,1.679347,0.308469,-160.932083,0.031680,0.000000
26.260002,7.325310,-160.932083,0.005200,0.001228,0.031194,32.584606,1.659939,0.311936,-160.932083,0.032096,0.000000
26.510002,7.358826,-160.976562,0.005187,0.001244,0.031602,32.733692,1.667534,0.316016,-160.976562,0.032512,0.000000
26.760002,7.447449,-160.932083,0.005217,0.001259,0.031974,33.127907,1.687616,0.319740,-160.932083,0.032929,0.000000
27.010002,7.552826,-160.932083,0.005243,0.001277,0.032443,33.596649,1.711495,0.324426,-160.932083,0.033344,0.000000
27.260002,7.393082,-160.843124,0.005256,0.001288,0.032711,32.886070,1.675296,0.327113,-160.843124,0.033761,0.000000
27.510002,7.418030,-160.976562,0.005264,0.001304,0.033119,32.997044,1.680950,0.331193,-160.976562,0.034177,0.000000
27.760002,7.833595,-160.932083,0.005290,0.001329,0.033752,34.845573,1.775118,0.337522,-160.932083,0.034593,0.000000
28.010002,7.769920,-160.932083,0.005325,0.001345,0.034169,34.562332,1.760689,0.341685,-160.932083,0.035010,0.000000
28.260002,7.566605,-160.887604,0.005325,0.001358,0.034498,33.657940,1.714617,0.344978,-160.887604,0.035426,0.000000
28.510002,7.634750,-160.932083,0.005342,0.001376,0.034940,33.961067,1.730059,0.349399,-160.932083,0.035842,0.000000
28.760002,7.736412,-160.976562,0.005368,0.001394,0.035418,34.413280,1.753096,0.354175,-160.976562,0.036259,0.000000
29.010002,7.689491,-160.976562,0.005376,0.001407,0.035738,34.204567,1.742464,0.357377,-160.976562,0.036675,0.000000
29.260002,7.689865,-160.932083,0.005398,0.001421,0.036094,34.206230,1.742548,0.360935,-160.932083,0.037091,0.000000
29.510002,7.887222,-160.976562,0.005420,0.001442,0.036614,35.084118,1.787270,0.366143,-160.976562,0.037516,0.000000
29.760002,7.924088,-160.932083,0.005437,0.001460,0.037074,35.248100,1.795624,0.370738,-160.932083,0.037932,0.000000
30.010002,7.880142,-161.021042,0.005467,0.001477,0.037508,35.052624,1.785666,0.375076,-161.021042,0.038349,0.000000
30.260002,7.749443,-160.976562,0.005476,0.001488,0.037794,34.471245,1.756049,0.377937,-160.976562,0.038765,0.000000
30.510002,7.692101,-160.976562,0.005489,0.001503,0.038166,34.216171,1.743055,0.381661,-160.976562,0.039181,0.000000
30.760002,7.941216,-161.021042,0.005501,0.001524,0.038704,35.324291,1.799505,0.387043,-161.021042,0.039598,0.000000
31.010002,7.854820,-161.021042,0.005523,0.001537,0.039042,34.939987,1.779928,0.390419,-161.021042,0.040013,0.000000
31.260002,8.011223,-161.065521,0.005540,0.001556,0.039511,35.635700,1.815369,0.395105,-161.065521,0.040429,0.000000
31.510002,8.024254,-161.065521,0.005553,0.001571,0.039901,35.693665,1.818322,0.399011,-161.065521,0.040846,0.000000
31.760002,8.069679,-161.065521,0.005575,0.001588,0.040343,35.895725,1.828615,0.403432,-161.065521,0.041262,0.000000
32.010002,8.051811,-161.021042,0.005588,0.001603,0.040725,35.816246,1.824566,0.407247,-161.021042,0.041679,0.000000
32.260002,7.946053,-161.021042,0.005605,0.001617,0.041063,35.345806,1.800601,0.410631,-161.021042,0.042095,0.000000
32.510002,8.143044,-161.021042,0.005622,0.001637,0.041575,36.222065,1.845240,0.415748,-161.021042,0.042511,0.000000
32.760002,8.144905,-161.110001,0.005644,0.001654,0.042008,36.230347,1.845662,0.420078,-161.110001,0.042928,0.000000
33.010002,8.090164,-161.021042,0.005674,0.001669,0.042381,35.986847,1.833257,0.423810,-161.021042,0.043344,0.000000
33.260002,8.191818,-161.065521,0.005683,0.001686,0.042823,36.439026,1.856293,0.428231,-161.065521,0.043760,0.000000
33.510002,8.398857,-161.110001,0.005700,0.001708,0.043395,37.359982,1.903208,0.433953,-161.110001,0.044177,0.000000
33.760002,8.056274,-161.021042,0.005726,0.001717,0.043621,35.836098,1.825578,0.436209,-161.021042,0.044592,0.000000
34.010002,8.146393,-161.065521,0.005747,0.001736,0.044089,36.236965,1.845999,0.440895,-161.065521,0.045008,0.000000
34.260002,8.127769,-161.154480,0.005760,0.001752,0.044497,36.154125,1.841779,0.444967,-161.154480,0.045425,0.000000
34.510002,8.307259,-161.065521,0.005782,0.001770,0.044948,36.952534,1.882452,0.449479,-161.065521,0.045850,0.000000
34.760002,8.227570,-161.110001,0.005803,0.001784,0.045321,36.598057,1.864394,0.453211,-161.110001,0.046267,0.000000
35.010002,8.149368,-161.110001,0.005812,0.001797,0.045633,36.250202,1.846673,0.456330,-161.110001,0.046682,0.000000
35.260002,8.500519,-161.154480,0.005833,0.001822,0.046283,37.812195,1.926245,0.462832,-161.154480,0.047098,0.000000
35.510002,8.430511,-161.154480,0.005851,0.001840,0.046726,37.500790,1.910381,0.467260,-161.154480,0.047515,0.000000
35.760002,8.294968,-161.154480,0.005855,0.001853,0.047073,36.897858,1.879666,0.470727,-161.154480,0.047931,0.000000
36.010002,8.149742,-161.110001,0.005881,0.001865,0.047367,36.251865,1.846758,0.473672,-161.110001,0.048347,0.000000
36.260002,8.388809,-161.154480,0.005898,0.001886,0.047905,37.315289,1.900931,0.479054,-161.154480,0.048764,0.000000
36.510002,8.397743,-161.110001,0.005915,0.001901,0.048287,37.355026,1.902956,0.482869,-161.110001,0.049180,0.000000
36.760002,8.434235,-161.198959,0.005937,0.001916,0.048677,37.517349,1.911225,0.486768,-161.198959,0.049597,0.000000
37.010002,8.445030,-161.198959,0.005950,0.001930,0.049024,37.565369,1.913671,0.490242,-161.198959,0.050013,0.000000
37.260002,8.748520,-161.154480,0.005967,0.001952,0.049587,38.915359,1.982443,0.495874,-161.154480,0.050429,0.000000
37.510002,8.621536,-161.198959,0.006002,0.001967,0.049969,38.350510,1.953668,0.499689,-161.198959,0.050846,0.000000
37.760002,8.618935,-161.198959,0.006019,0.001985,0.050420,38.338936,1.953079,0.504201,-161.198959,0.051261,0.000000
38.010002,8.627869,-161.198959,0.006036,0.002002,0.050846,38.378677,1.955103,0.508455,-161.198959,0.051677,0.000000
38.260002,8.485626,-161.243454,0.006045,0.002015,0.051192,37.745949,1.922870,0.511922,-161.243454,0.052094,0.000000
38.510002,8.568665,-161.198959,0.006071,0.002034,0.051652,38.115322,1.941687,0.516517,-161.198959,0.052510,0.000000
38.760002,8.535896,-161.198959,0.006088,0.002045,0.051955,37.969563,1.934262,0.519553,-161.198959,0.052926,0.000000
39.010002,8.462906,-161.243454,0.006101,0.002058,0.052285,37.644886,1.917722,0.522845,-161.243454,0.053343,0.000000
39.260002,9.039337,-161.243454,0.006118,0.002086,0.052979,40.208981,2.048343,0.529787,-161.243454,0.053759,0.000000
39.510002,8.854645,-161.243454,0.006140,0.002102,0.053386,39.387428,2.006491,0.533859,-161.243454,0.054175,0.000000
39.760002,8.751495,-161.243454,0.006148,0.002115,0.053724,38.928596,1.983117,0.537243,-161.243454,0.054600,0.000000
40.010002,8.719849,-161.243454,0.006178,0.002130,0.054098,38.787823,1.975946,0.540975,-161.243454,0.055016,0.000000
40.260002,8.888527,-161.198959,0.006183,0.002147,0.054530,39.538143,2.014169,0.545305,-161.198959,0.055433,0.000000
40.510002,9.035988,-161.243454,0.006213,0.002166,0.055008,40.194080,2.047584,0.550081,-161.243454,0.055849,0.000000
40.760002,8.716118,-161.287933,0.006226,0.002173,0.055199,38.771229,1.975101,0.551989,-161.287933,0.056265,0.000000
41.010002,8.732880,-161.287933,0.006230,0.002189,0.055598,38.845787,1.978899,0.555978,-161.287933,0.056682,0.000000
41.260002,9.251968,-161.243454,0.006260,0.002216,0.056291,41.154812,2.096526,0.562912,-161.243454,0.057098,0.000000
41.510002,9.124245,-161.287933,0.006282,0.002231,0.056664,40.586666,2.067583,0.566644,-161.287933,0.057514,0.000000
41.760002,9.104507,-161.287933,0.006286,0.002247,0.057081,40.498871,2.063111,0.570808,-161.287933,0.057930,0.000000
42.010002,9.034874,-161.332413,0.006312,0.002261,0.057418,40.189125,2.047332,0.574184,-161.332413,0.058346,0.000000
42.260002,9.059074,-161.332413,0.006325,0.002279,0.057887,40.296776,2.052816,0.578869,-161.332413,0.058763,0.000000
42.510002,9.240425,-161.287933,0.006351,0.002297,0.058338,41.103462,2.093910,0.583381,-161.287933,0.059179,0.000000
42.760002,8.970825,-161.287933,0.006368,0.002304,0.058529,39.904224,2.032818,0.585289,-161.287933,0.059595,0.000000
43.010002,9.423630,-161.332413,0.006394,0.002331,0.059205,41.918400,2.135425,0.592048,-161.332413,0.060012,0.000000
43.260002,9.414688,-161.332413,0.006416,0.002347,0.059604,41.878624,2.133399,0.596038,-161.332413,0.060428,0.000000
43.510002,9.400169,-161.332413,0.006420,0.002363,0.060029,41.814041,2.130109,0.600292,-161.332413,0.060844,0.000000
43.760002,9.301865,-161.332413,0.006450,0.002378,0.060393,41.376759,2.107833,0.603933,-161.332413,0.061261,0.000000
44.010002,9.222923,-161.332413,0.006437,0.002393,0.060784,41.025612,2.089944,0.607839,-161.332413,0.061677,0.000000
44.260002,9.591942,-161.332413,0.006485,0.002411,0.061252,42.667088,2.173565,0.612517,-161.332413,0.062093,0.000000
44.510002,9.483582,-161.332413,0.006485,0.002424,0.061582,42.185078,2.149010,0.615818,-161.332413,0.062509,0.000000
44.760002,9.563644,-161.421371,0.006506,0.002442,0.062015,42.541214,2.167153,0.620147,-161.421371,0.062934,0.000000
45.010002,9.499962,-161.332413,0.006528,0.002456,0.062380,42.257942,2.152722,0.623796,-161.332413,0.063351,0.000000
45.260002,9.786316,-161.376892,0.006554,0.002478,0.062943,43.531708,2.217611,0.629428,-161.376892,0.063767,0.000000
45.510002,9.639977,-161.376892,0.006562,0.002492,0.063290,42.880756,2.184450,0.632895,-161.376892,0.064183,0.000000
45.760002,9.720039,-161.376892,0.006575,0.002511,0.063767,43.236893,2.202592,0.637672,-161.376892,0.064599,0.000000
46.010002,9.691368,-161.465851,0.006588,0.002524,0.064114,43.109360,2.196095,0.641138,-161.465851,0.065015,0.000000
46.260002,9.935272,-161.421371,0.006627,0.002543,0.064582,44.194298,2.251365,0.645817,-161.421371,0.065432,0.000000
46.510002,9.810150,-161.465851,0.006627,0.002555,0.064903,43.637726,2.223012,0.649026,-161.465851,0.065848,0.000000
46.760002,9.847015,-161.421371,0.006648,0.002568,0.065233,43.801712,2.231365,0.652327,-161.421371,0.066264,0.000000
47.010002,10.244713,-161.421371,0.006670,0.002592,0.065840,45.570759,2.321485,0.658398,-161.421371,0.066681,0.000000
47.260002,10.226463,-161.465851,0.006679,0.002609,0.066264,45.489582,2.317350,0.662644,-161.465851,0.067097,0.000000
47.510002,10.047356,-161.465851,0.006704,0.002622,0.066611,44.692871,2.276763,0.666111,-161.465851,0.067513,0.000000
47.760002,10.095390,-161.510330,0.006713,0.002638,0.066993,44.906540,2.287648,0.669926,-161.510330,0.067930,0.000000
48.010002,10.080490,-161.465851,0.006735,0.002652,0.067348,44.840260,2.284272,0.673484,-161.465851,0.068346,0.000000
48.260002,10.456963,-161.465851,0.006760,0.002672,0.067868,46.514893,2.369582,0.678685,-161.465851,0.068762,0.000000
48.510002,10.228699,-161.465851,0.006769,0.002683,0.068146,45.499523,2.317856,0.681463,-161.465851,0.069178,0.000000
48.760002,10.308014,-161.465851,0.006778,0.002697,0.068510,45.852337,2.335829,0.685104,-161.465851,0.069594,0.000000
49.010002,10.630119,-161.465851,0.006812,0.002718,0.069048,47.285133,2.408819,0.690478,-161.465851,0.070011,0.000000
49.260002,10.936951,-161.421371,0.006821,0.002740,0.069603,48.649986,2.478348,0.696035,-161.421371,0.070427,0.000000
49.510002,10.691185,-161.465851,0.006847,0.002753,0.069924,47.556767,2.422657,0.699244,-161.465851,0.070843,0.000000
49.760002,10.801781,-161.465851,0.006864,0.002769,0.070340,48.048721,2.447718,0.703400,-161.465851,0.071268,0.000000
50.010002,10.976791,-161.510330,0.006881,0.002787,0.070783,48.827206,2.487376,0.707828,-161.510330,0.071684,0.000000
50.260002,10.888168,-161.510330,0.006903,0.002800,0.071130,48.432991,2.467294,0.711295,-161.510330,0.072101,0.000000
50.510002,10.733261,-161.554810,0.006903,0.002811,0.071390,47.743931,2.432192,0.713899,-161.554810,0.072517,0.000000
50.760002,11.269104,-161.554810,0.006933,0.002832,0.071927,50.127480,2.553615,0.719274,-161.554810,0.072933,0.000000
51.010002,11.532745,-161.554810,0.006946,0.002853,0.072465,51.300213,2.613358,0.724648,-161.554810,0.073350,0.000000
51.260002,11.517853,-161.554810,0.006972,0.002868,0.072855,51.233967,2.609983,0.728554,-161.554810,0.073766,0.000000
51.510002,11.478004,-161.554810,0.006976,0.002883,0.073220,51.056713,2.600953,0.732195,-161.554810,0.074182,0.000000
51.760002,11.561790,-161.599289,0.007002,0.002898,0.073618,51.429413,2.619939,0.736185,-161.599289,0.074599,0.000000
52.010002,11.764359,-161.554810,0.007019,0.002916,0.074070,52.330479,2.665842,0.740696,-161.554810,0.075014,0.000000
52.260002,11.943100,-161.599289,0.007023,0.002932,0.074469,53.125561,2.706345,0.744686,-161.599289,0.075431,0.000000
52.510002,11.889107,-161.554810,0.007045,0.002946,0.074833,52.885387,2.694110,0.748327,-161.554810,0.075847,0.000000
52.760002,12.281212,-161.554810,0.007062,0.002965,0.075318,54.629559,2.782963,0.753179,-161.554810,0.076263,0.000000
53.010002,12.440964,-161.510330,0.007088,0.002983,0.075761,55.340172,2.819163,0.757607,-161.510330,0.076680,0.000000
53.260002,12.340424,-161.554810,0.007101,0.002995,0.076082,54.892944,2.796380,0.760817,-161.554810,0.077096,0.000000
53.510002,12.418251,-161.554810,0.007114,0.003011,0.076472,55.239140,2.814016,0.764715,-161.554810,0.077512,0.000000
53.760002,12.852432,-161.599289,0.007131,0.003029,0.076931,57.170475,2.912403,0.769310,-161.599289,0.077929,0.000000
54.010002,13.028564,-161.599289,0.007153,0.003047,0.077382,57.953949,2.952315,0.773822,-161.599289,0.078345,0.000000
54.260002,13.060966,-161.599289,0.007161,0.003061,0.077755,58.098080,2.959657,0.777554,-161.599289,0.078761,0.000000
54.510002,13.173050,-161.643784,0.007183,0.003075,0.078110,58.596653,2.985056,0.781104,-161.643784,0.079178,0.000000
54.760002,13.904388,-161.599289,0.007196,0.003102,0.078787,61.849808,3.150779,0.787871,-161.599289,0.079593,0.000000
55.010002,13.677238,-161.643784,0.007213,0.003111,0.079030,60.839394,3.099307,0.790301,-161.643784,0.080019,0.000000
55.260002,14.045517,-161.643784,0.007235,0.003132,0.079550,62.477581,3.182760,0.795502,-161.643784,0.080435,0.000000
55.510002,13.842575,-161.643784,0.007248,0.003143,0.079828,61.574848,3.136772,0.798280,-161.643784,0.080851,0.000000
55.760002,14.061531,-161.599289,0.007261,0.003159,0.080244,62.548813,3.186388,0.802443,-161.599289,0.081268,0.000000
56.010002,14.458473,-161.643784,0.007269,0.003177,0.080695,64.314499,3.276337,0.806947,-161.643784,0.081683,0.000000
56.260002,14.896385,-161.688263,0.007282,0.003193,0.081111,66.262428,3.375569,0.811111,-161.688263,0.082100,0.000000
56.510002,15.504845,-161.643784,0.007295,0.003217,0.081701,68.968994,3.513448,0.817007,-161.643784,0.082516,0.000000
56.760002,15.701828,-161.643784,0.007330,0.003234,0.082134,69.845222,3.558085,0.821345,-161.643784,0.082932,0.000000
57.010002,15.612831,-161.643784,0.007338,0.003247,0.082473,69.449341,3.537918,0.824729,-161.643784,0.083349,0.000000
57.260002,15.638527,-161.688263,0.007368,0.003261,0.082829,69.563644,3.543741,0.828286,-161.688263,0.083765,0.000000
57.510002,16.178467,-161.688263,0.007368,0.003279,0.083296,71.965416,3.666093,0.832965,-161.688263,0.084181,0.000000
57.760002,16.546371,-161.688263,0.007381,0.003297,0.083739,73.601936,3.749461,0.837393,-161.688263,0.084598,0.000000
58.010002,16.531471,-161.688263,0.007394,0.003310,0.084069,73.535660,3.746085,0.840686,-161.688263,0.085014,0.000000
58.260002,16.691963,-161.688263,0.007407,0.003322,0.084380,74.249557,3.782453,0.843804,-161.688263,0.085430,0.000000
58.510002,16.985023,-161.732742,0.007420,0.003339,0.084806,75.553162,3.848861,0.848059,-161.732742,0.085847,0.000000
58.760002,17.937927,-161.732742,0.007446,0.003360,0.085352,79.791885,4.064792,0.853524,-161.732742,0.086262,0.000000
59.010002,18.249603,-161.732742,0.007455,0.003377,0.085777,81.178291,4.135419,0.857771,-161.732742,0.086679,0.000000
59.260002,18.620857,-161.688263,0.007468,0.003395,0.086237,82.829712,4.219547,0.862366,-161.688263,0.087095,0.000000
59.510002,18.736664,-161.732742,0.007480,0.003409,0.086583,83.344841,4.245789,0.865833,-161.732742,0.087511,0.000000
59.760002,19.085579,-161.777222,0.007502,0.003426,0.087017,84.896896,4.324854,0.870170,-161.777222,0.087928,0.000000
60.010002,19.380127,-161.777222,0.007506,0.003441,0.087408,86.207108,4.391599,0.874076,-161.777222,0.088352,0.000000
60.260002,19.539871,-161.732742,0.007524,0.003451,0.087659,86.917686,4.427798,0.876589,-161.732742,0.088769,0.000000
60.510002,20.364677,-161.732742,0.007528,0.003474,0.088231,90.586609,4.614702,0.882312,-161.732742,0.089185,0.000000
60.760002,21.218529,-161.777222,0.007554,0.003495,0.088760,94.384727,4.808187,0.887603,-161.777222,0.089601,0.000000
61.010002,21.190598,-161.777222,0.007562,0.003506,0.089046,94.260483,4.801858,0.890465,-161.777222,0.090018,0.000000
61.260002,21.736122,-161.821701,0.007584,0.003525,0.089541,96.687103,4.925476,0.895408,-161.821701,0.090434,0.000000
61.510002,21.853424,-161.777222,0.007601,0.003536,0.089819,97.208885,4.952056,0.898186,-161.777222,0.090850,0.000000
61.760002,22.697220,-161.821701,0.007610,0.003558,0.090373,100.962273,5.143263,0.903735,-161.821701,0.091267,0.000000
62.010002,22.900536,-161.821701,0.007627,0.003571,0.090694,101.866669,5.189335,0.906944,-161.821701,0.091683,0.000000
62.260002,23.227104,-161.866180,0.007627,0.003583,0.091006,103.319321,5.263337,0.910063,-161.866180,0.092099,0.000000
62.510002,24.435081,-161.821701,0.007644,0.003608,0.091648,108.692673,5.537068,0.916482,-161.821701,0.092516,0.000000
62.760002,24.964966,-161.821701,0.007662,0.003625,0.092065,111.049713,5.657142,0.920645,-161.821701,0.092931,0.000000
63.010002,25.112053,-161.821701,0.007670,0.003637,0.092376,111.703987,5.690473,0.923764,-161.821701,0.093348,0.000000
63.260002,25.722740,-161.821701,0.007692,0.003655,0.092836,114.420464,5.828856,0.928359,-161.821701,0.093764,0.000000
63.510002,26.164001,-161.821701,0.007700,0.003669,0.093192,116.383293,5.928847,0.931917,-161.821701,0.094180,0.000000
63.760002,27.020836,-161.866180,0.007705,0.003688,0.093678,120.194679,6.123009,0.936777,-161.866180,0.094597,0.000000
64.010002,27.263992,-161.866180,0.007722,0.003699,0.093964,121.276299,6.178109,0.939638,-161.866180,0.095013,0.000000
64.260002,28.522614,-161.866180,0.007735,0.003723,0.094553,126.874924,6.463317,0.945535,-161.866180,0.095429,0.000000
64.510002,29.149315,-161.910660,0.007743,0.003738,0.094952,129.662628,6.605329,0.949524,-161.910660,0.095846,0.000000
64.760002,29.795006,-161.866180,0.007756,0.003757,0.095420,132.534805,6.751645,0.954202,-161.866180,0.096262,0.000000
65.010002,30.400490,-161.910660,0.007769,0.003771,0.095793,135.228134,6.888850,0.957934,-161.910660,0.096687,0.000000
65.260002,30.851433,-161.910660,0.007774,0.003787,0.096184,137.234024,6.991035,0.961840,-161.910660,0.097103,0.000000
65.510002,31.393234,-161.910660,0.007782,0.003802,0.096566,139.644073,7.113809,0.965655,-161.910660,0.097519,0.000000
65.760002,32.462311,-161.866180,0.007808,0.003820,0.097025,144.399567,7.356065,0.970250,-161.866180,0.097936,0.000000
66.010002,32.904694,-161.955139,0.007808,0.003835,0.097397,146.367386,7.456310,0.973975,-161.955139,0.098352,0.000000
66.260002,33.771950,-161.955139,0.007817,0.003852,0.097831,150.225128,7.652833,0.978312,-161.955139,0.098768,0.000000
66.510002,34.868958,-161.910660,0.007830,0.003870,0.098308,155.104874,7.901419,0.983081,-161.910660,0.099184,0.000000
66.760002,35.420067,-161.910660,0.007843,0.003886,0.098707,157.556320,8.026302,0.987070,-161.910660,0.099600,0.000000
67.010002,36.070976,-161.999619,0.007847,0.003902,0.099123,160.451721,8.173800,0.991234,-161.999619,0.100017,0.000000
67.260002,36.884605,-161.955139,0.007864,0.003916,0.099471,164.070923,8.358171,0.994708,-161.955139,0.100433,0.000000
67.510002,37.587646,-161.999619,0.007860,0.003934,0.099930,167.198196,8.517483,0.999303,-161.999619,0.100849,0.000000
67.760002,38.589333,-161.955139,0.007873,0.003948,0.100285,171.653931,8.744468,1.002853,-161.955139,0.101266,0.000000
68.010002,38.638481,-161.955139,0.007894,0.003956,0.100485,171.872543,8.755605,1.004852,-161.955139,0.101682,0.000000
68.260002,40.441879,-161.910660,0.007890,0.003984,0.101205,179.894470,9.164261,1.012051,-161.910660,0.102098,0.000000
68.510002,41.506493,-161.999619,0.007912,0.004000,0.101604,184.630096,9.405506,1.016040,-161.999619,0.102515,0.000000
68.760002,42.303741,-161.955139,0.007916,0.004015,0.101986,188.176437,9.586164,1.019855,-161.955139,0.102931,0.000000
69.010002,42.983322,-161.955139,0.007916,0.004032,0.102402,191.199371,9.740160,1.024019,-161.955139,0.103347,0.000000
69.260002,43.569069,-161.999619,0.007929,0.004045,0.102731,193.804901,9.872892,1.027311,-161.999619,0.103763,0.000000
69.510002,45.042542,-162.044098,0.007946,0.004067,0.103312,200.359238,10.206785,1.033125,-162.044098,0.104179,0.000000
69.760002,45.505775,-161.999619,0.007955,0.004076,0.103538,202.419800,10.311756,1.035381,-161.999619,0.104596,0.000000
70.010002,46.125778,-162.044098,0.007955,0.004090,0.103893,205.177704,10.452250,1.038931,-162.044098,0.105012,0.000000
70.260002,47.577660,-162.044098,0.007976,0.004110,0.104405,211.636002,10.781252,1.044048,-162.044098,0.105437,0.000000
70.510002,49.109596,-162.044098,0.007972,0.004131,0.104934,218.450394,11.128393,1.049339,-162.044098,0.105853,0.000000
70.760002,49.932915,-162.088593,0.007985,0.004143,0.105237,222.112701,11.314960,1.052375,-162.088593,0.106269,0.000000
71.010002,50.799423,-162.088593,0.008002,0.004162,0.105706,225.967117,11.511313,1.057061,-162.088593,0.106686,0.000000
71.260002,51.708755,-162.133072,0.007998,0.004175,0.106053,230.012039,11.717372,1.060528,-162.133072,0.107102,0.000000
71.510002,52.977058,-162.088593,0.008015,0.004193,0.106495,235.653732,12.004773,1.064948,-162.088593,0.107518,0.000000
71.760002,53.420181,-162.044098,0.008015,0.004203,0.106755,237.624832,12.105186,1.067552,-162.044098,0.107935,0.000000
72.010002,54.726463,-162.088593,0.008024,0.004220,0.107197,243.435471,12.401194,1.071973,-162.088593,0.108351,0.000000
72.260002,56.609550,-162.088593,0.008024,0.004245,0.107813,251.811859,12.827908,1.078135,-162.088593,0.108767,0.000000
72.510002,57.547554,-162.044098,0.008045,0.004258,0.108151,255.984299,13.040462,1.081511,-162.044098,0.109184,0.000000
72.760002,58.800591,-162.088593,0.008037,0.004275,0.108594,261.558075,13.324404,1.085939,-162.088593,0.109600,0.000000
73.010002,59.541237,-162.133072,0.008058,0.004290,0.108958,264.852661,13.492237,1.089580,-162.133072,0.110016,0.000000
73.260002,60.600639,-162.177551,0.008063,0.004304,0.109322,269.565094,13.732301,1.093222,-162.177551,0.110432,0.000000
73.510002,62.295303,-162.133072,0.008075,0.004325,0.109851,277.103363,14.116318,1.098513,-162.133072,0.110848,0.000000
73.760002,63.427322,-162.133072,0.008080,0.004338,0.110190,282.138824,14.372836,1.101897,-162.133072,0.111265,0.000000
74.010002,64.750351,-162.133072,0.008084,0.004357,0.110675,288.023956,14.672639,1.106749,-162.133072,0.111681,0.000000
74.260002,65.924454,-162.088593,0.008084,0.004372,0.111039,293.246613,14.938695,1.110390,-162.088593,0.112097,0.000000
74.510002,67.302963,-162.133072,0.008097,0.004390,0.111499,299.378540,15.251069,1.114992,-162.133072,0.112514,0.000000
74.760002,67.023315,-162.177551,0.008097,0.004383,0.111334,298.134583,15.187700,1.113342,-162.177551,0.111568,0.000000
75.010002,66.534393,-162.177551,0.008114,0.004383,0.111325,295.959778,15.076909,1.113251,-162.177551,0.111334,0.000000
75.260002,66.089035,-162.177551,0.008119,0.004382,0.111291,293.978699,14.975990,1.112911,-162.177551,0.111334,0.000000
75.510002,65.689850,-162.177551,0.008123,0.004381,0.111282,292.203033,14.885532,1.112820,-162.177551,0.111334,0.000000
75.760002,65.325668,-162.177551,0.008114,0.004381,0.111274,290.583099,14.803008,1.112736,-162.177551,0.111334,0.000000
76.010002,65.008408,-162.222031,0.008119,0.004381,0.111274,289.171844,14.731116,1.112736,-162.222031,0.111334,0.000000
76.260002,64.736954,-162.222031,0.008114,0.004380,0.111265,287.964355,14.669603,1.112646,-162.222031,0.111334,0.000000
76.510002,64.466232,-162.222031,0.008114,0.004380,0.111265,286.760132,14.608257,1.112646,-162.222031,0.111334,0.000000
76.760002,64.247650,-162.222031,0.008132,0.004380,0.111265,285.787811,14.558726,1.112646,-162.222031,0.111334,0.000000
77.010002,64.031677,-162.222031,0.008127,0.004380,0.111265,284.827118,14.509786,1.112646,-162.222031,0.111334,0.000000
77.260002,63.831711,-162.177551,0.008123,0.004380,0.111256,283.937622,14.464472,1.112562,-162.177551,0.111334,0.000000
77.510002,63.657074,-162.222031,0.008136,0.004380,0.111256,283.160797,14.424899,1.112562,-162.222031,0.111334,0.000000
77.760002,63.491745,-162.222031,0.008140,0.004380,0.111256,282.425385,14.387435,1.112562,-162.222031,0.111334,0.000000
78.010002,63.328262,-162.266510,0.008132,0.004380,0.111256,281.698181,14.350389,1.112562,-162.266510,0.111334,0.000000
78.260002,63.189377,-162.266510,0.008132,0.004380,0.111256,281.080383,14.318918,1.112562,-162.266510,0.111334,0.000000
78.510002,63.053452,-162.266510,0.008140,0.004380,0.111256,280.475769,14.288116,1.112562,-162.266510,0.111334,0.000000
78.760002,62.911209,-162.222031,0.008140,0.004380,0.111256,279.843048,14.255884,1.112562,-162.222031,0.111334,0.000000
79.010002,62.808434,-162.266510,0.008132,0.004380,0.111256,279.385864,14.232594,1.112562,-162.266510,0.111334,0.000000
79.260002,62.690018,-162.266510,0.008136,0.004380,0.111256,278.859131,14.205761,1.112562,-162.266510,0.111334,0.000000
79.510002,62.576447,-162.310989,0.008140,0.004380,0.111256,278.353943,14.180025,1.112562,-162.310989,0.111334,0.000000
79.760002,62.486702,-162.310989,0.008140,0.004380,0.111256,277.954742,14.159689,1.112562,-162.310989,0.111334,0.000000
80.010002,62.383560,-162.266510,0.008144,0.004380,0.111256,277.495941,14.136316,1.112562,-162.266510,0.111334,0.000000
80.260002,62.292702,-162.310989,0.008149,0.004380,0.111256,277.091766,14.115727,1.112562,-162.310989,0.111334,0.000000
80.510002,62.198486,-162.310989,0.008144,0.004380,0.111256,276.672699,14.094378,1.112562,-162.310989,0.111334,0.000000
80.760002,62.131462,-162.266510,0.008149,0.004380,0.111256,276.374542,14.079190,1.112562,-162.266510,0.111334,0.000000
81.010002,62.031662,-162.355469,0.008144,0.004380,0.111256,275.930603,14.056576,1.112562,-162.355469,0.111334,0.000000
81.260002,61.958679,-162.310989,0.008140,0.004380,0.111256,275.605957,14.040037,1.112562,-162.310989,0.111334,0.000000
81.510002,61.888306,-162.310989,0.008153,0.004380,0.111256,275.292938,14.024090,1.112562,-162.310989,0.111334,0.000000
81.760002,61.811966,-162.355469,0.008144,0.004380,0.111256,274.953369,14.006792,1.112562,-162.355469,0.111334,0.000000
82.010002,61.736748,-162.310989,0.008140,0.004380,0.111256,274.618774,13.989747,1.112562,-162.310989,0.111334,0.000000
82.260002,61.674187,-162.399948,0.008149,0.004380,0.111256,274.340485,13.975571,1.112562,-162.399948,0.111334,0.000000
82.510002,61.601944,-162.399948,0.008149,0.004380,0.111256,274.019135,13.959201,1.112562,-162.399948,0.111334,0.000000
82.760002,61.550186,-162.399948,0.008153,0.004380,0.111256,273.788910,13.947471,1.112562,-162.399948,0.111334,0.000000
83.010002,61.490608,-162.399948,0.008140,0.004380,0.111256,273.523895,13.933970,1.112562,-162.399948,0.111334,0.000000
83.260002,61.422089,-162.355469,0.008157,0.004380,0.111256,273.219086,13.918444,1.112562,-162.355469,0.111334,0.000000
83.510002,61.364746,-162.355469,0.008153,0.004380,0.111256,272.964020,13.905450,1.112562,-162.355469,0.111334,0.000000
83.760002,61.318947,-162.355469,0.008140,0.004380,0.111256,272.760284,13.895072,1.112562,-162.355469,0.111334,0.000000
84.010002,61.253036,-162.444427,0.008149,0.004380,0.111256,272.467102,13.880136,1.112562,-162.444427,0.111334,0.000000
84.260002,61.188614,-162.444427,0.008144,0.004380,0.111256,272.180542,13.865539,1.112562,-162.444427,0.111334,0.000000
84.510002,61.153984,-162.444427,0.008149,0.004380,0.111256,272.026520,13.857691,1.112562,-162.444427,0.111334,0.000000
84.760002,61.101852,-162.444427,0.008144,0.004380,0.111256,271.794617,13.845878,1.112562,-162.444427,0.111334,0.000000
85.010002,61.053070,-162.444427,0.008153,0.004380,0.111256,271.577606,13.834824,1.112562,-162.444427,0.111334,0.000000
85.260002,61.009872,-162.488907,0.008157,0.004380,0.111256,271.385468,13.825035,1.112562,-162.488907,0.111334,0.000000
85.510002,60.958862,-162.444427,0.008149,0.004380,0.111256,271.158569,13.813476,1.112562,-162.444427,0.111334,0.000000
85.760002,60.914177,-162.399948,0.008153,0.004380,0.111247,270.959778,13.803349,1.112471,-162.399948,0.111334,0.000000
86.010002,60.874329,-162.444427,0.008157,0.004380,0.111247,270.782532,13.794320,1.112471,-162.444427,0.111334,0.000000
86.260002,60.822945,-162.444427,0.008144,0.004380,0.111247,270.553955,13.782676,1.112471,-162.444427,0.111334,0.000000
86.510002,60.787193,-162.488907,0.008157,0.004380,0.111247,270.394928,13.774574,1.112471,-162.488907,0.111334,0.000000
86.760002,60.754425,-162.444427,0.008149,0.004380,0.111247,270.249176,13.767149,1.112471,-162.444427,0.111334,0.000000
87.010002,60.706764,-162.444427,0.008149,0.004380,0.111247,270.037170,13.756350,1.112471,-162.444427,0.111334,0.000000
87.260002,60.655746,-162.533401,0.008153,0.004380,0.111247,269.810242,13.744788,1.112471,-162.533401,0.111334,0.000000
87.510002,60.640106,-162.488907,0.008166,0.004380,0.111247,269.740662,13.741244,1.112471,-162.488907,0.111334,0.000000
87.760002,60.585373,-162.488907,0.008162,0.004380,0.111247,269.497192,13.728842,1.112471,-162.488907,0.111334,0.000000
88.010002,60.539940,-162.533401,0.008149,0.004380,0.111247,269.295105,13.718546,1.112471,-162.533401,0.111334,0.000000
88.260002,60.530632,-162.444427,0.008166,0.004380,0.111247,269.253693,13.716437,1.112471,-162.444427,0.111334,0.000000
88.510002,60.483711,-162.533401,0.008153,0.004380,0.111247,269.044983,13.705805,1.112471,-162.533401,0.111334,0.000000
88.760002,60.447594,-162.533401,0.008162,0.004380,0.111247,268.884338,13.697620,1.112471,-162.533401,0.111334,0.000000
89.010002,60.426369,-162.533401,0.008157,0.004380,0.111247,268.789917,13.692811,1.112471,-162.533401,0.111334,0.000000
89.260002,60.388390,-162.533401,0.008149,0.004380,0.111247,268.620972,13.684204,1.112471,-162.533401,0.111334,0.000000
89.510002,60.357849,-162.533401,0.008162,0.004380,0.111247,268.485107,13.677284,1.112471,-162.533401,0.111334,0.000000
89.760002,60.330666,-162.577881,0.008157,0.004380,0.111247,268.364197,13.671124,1.112471,-162.577881,0.111334,0.000000
90.010002,60.291939,-162.533401,0.008157,0.004380,0.111247,268.191925,13.662349,1.112471,-162.533401,0.111334,0.000000
90.260002,60.256569,-162.533401,0.008162,0.004380,0.111247,268.034607,13.654334,1.112471,-162.533401,0.111334,0.000000
90.510002,60.249115,-162.488907,0.008157,0.004380,0.111247,268.001434,13.652644,1.112471,-162.488907,0.111334,0.000000
90.760002,60.193634,-162.577881,0.008144,0.004380,0.111247,267.754669,13.640073,1.112471,-162.577881,0.111334,0.000000
91.010002,60.166451,-162.577881,0.008162,0.004380,0.111247,267.633728,13.633913,1.112471,-162.577881,0.111334,0.000000
91.260002,60.150436,-162.533401,0.008162,0.004380,0.111247,267.562500,13.630284,1.112471,-162.533401,0.111334,0.000000
91.510002,60.109108,-162.577881,0.008157,0.004380,0.111247,267.378662,13.620918,1.112471,-162.577881,0.111334,0.000000
91.760002,60.076714,-162.577881,0.008153,0.004380,0.111247,267.234558,13.613578,1.112471,-162.577881,0.111334,0.000000
92.010002,60.070007,-162.577881,0.008153,0.004380,0.111247,267.204742,13.612059,1.112471,-162.577881,0.111334,0.000000
92.260002,60.032028,-162.622360,0.008166,0.004380,0.111247,267.035797,13.603452,1.112471,-162.622360,0.111334,0.000000
92.510002,60.005959,-162.577881,0.008157,0.004380,0.111247,266.919830,13.597545,1.112471,-162.577881,0.111334,0.000000
92.760002,59.992554,-162.666840,0.008162,0.004380,0.111247,266.860199,13.594507,1.112471,-162.666840,0.111334,0.000000
93.010002,59.956062,-162.577881,0.008157,0.004380,0.111247,266.697876,13.586238,1.112471,-162.577881,0.111334,0.000000
93.260002,59.938560,-162.577881,0.008157,0.004380,0.111247,266.620026,13.582272,1.112471,-162.577881,0.111334,0.000000
93.510002,59.911003,-162.622360,0.008162,0.004380,0.111247,266.497437,13.576027,1.112471,-162.622360,0.111334,0.000000
93.760002,59.887543,-162.666840,0.008170,0.004380,0.111247,266.393097,13.570711,1.112471,-162.666840,0.111334,0.000000
94.010002,59.862968,-162.622360,0.008153,0.004380,0.111247,266.283783,13.565143,1.112471,-162.622360,0.111334,0.000000
94.260002,59.845840,-162.666840,0.008162,0.004380,0.111247,266.207581,13.561262,1.112471,-162.666840,0.111334,0.000000
94.510002,59.816048,-162.622360,0.008157,0.004380,0.111247,266.075073,13.554510,1.112471,-162.622360,0.111334,0.000000
94.760002,59.800034,-162.666840,0.008157,0.004380,0.111247,266.003845,13.550881,1.112471,-162.666840,0.111334,0.000000
95.010002,59.774345,-162.666840,0.008157,0.004380,0.111247,265.889557,13.545060,1.112471,-162.666840,0.111334,0.000000
95.260002,59.739716,-162.622360,0.008166,0.004380,0.111247,265.735535,13.537213,1.112471,-162.622360,0.111334,0.000000
95.510002,59.723328,-162.711319,0.008170,0.004380,0.111247,265.662628,13.533499,1.112471,-162.711319,0.111334,0.000000
95.760002,59.706947,-162.711319,0.008162,0.004380,0.111247,265.589752,13.529788,1.112471,-162.711319,0.111334,0.000000
96.010002,59.676041,-162.711319,0.008153,0.004380,0.111247,265.452301,13.522783,1.112471,-162.711319,0.111334,0.000000
96.260002,59.671570,-162.666840,0.008149,0.004380,0.111247,265.432404,13.521770,1.112471,-162.666840,0.111334,0.000000
96.510002,59.637314,-162.711319,0.008162,0.004380,0.111247,265.280029,13.514009,1.112471,-162.711319,0.111334,0.000000
96.760002,59.614220,-162.711319,0.008166,0.004380,0.111247,265.177307,13.508775,1.112471,-162.711319,0.111334,0.000000
97.010002,59.592255,-162.711319,0.008166,0.004380,0.111247,265.079590,13.503798,1.112471,-162.711319,0.111334,0.000000
97.260002,59.582947,-162.711319,0.008149,0.004380,0.111247,265.038177,13.501688,1.112471,-162.711319,0.111334,0.000000
97.510002,59.549805,-162.711319,0.008162,0.004380,0.111247,264.890747,13.494179,1.112471,-162.711319,0.111334,0.000000
97.760002,59.549805,-162.666840,0.008166,0.004380,0.111247,264.890747,13.494179,1.112471,-162.666840,0.111334,0.000000
98.010002,59.503998,-162.666840,0.008162,0.004380,0.111247,264.687012,13.483798,1.112471,-162.666840,0.111334,0.000000
98.260002,59.492828,-162.711319,0.008166,0.004380,0.111247,264.637329,13.481267,1.112471,-162.711319,0.111334,0.000000
98.510002,59.493576,-162.711319,0.008162,0.004380,0.111247,264.640656,13.481437,1.112471,-162.711319,0.111334,0.000000
98.760002,59.466766,-162.800278,0.008166,0.004380,0.111247,264.521393,13.475362,1.112471,-162.800278,0.111334,0.000000
99.010002,59.441818,-162.755798,0.008166,0.004380,0.111247,264.410400,13.469708,1.112471,-162.755798,0.111334,0.000000
99.260002,59.438835,-162.800278,0.008175,0.004380,0.111247,264.397156,13.469032,1.112471,-162.800278,0.111334,0.000000
99.510002,59.400482,-162.711319,0.008170,0.004380,0.111247,264.226532,13.460341,1.112471,-162.711319,0.111334,0.000000
99.760002,59.381119,-162.755798,0.008166,0.004380,0.111247,264.140411,13.455954,1.112471,-162.755798,0.111334,0.000000
100.010002,59.369949,-162.755798,0.008157,0.004380,0.111247,264.090729,13.453423,1.112471,-162.755798,0.111334,0.000000
100.260002,59.337181,-162.844757,0.008166,0.004380,0.111247,263.944977,13.445997,1.112471,-162.844757,0.111334,0.000000
100.510002,59.343506,-162.844757,0.008175,0.004380,0.111247,263.973083,13.447431,1.112471,-162.844757,0.111334,0.000000
100.760002,59.307762,-162.800278,0.008157,0.004380,0.111247,263.814087,13.439331,1.112471,-162.800278,0.111334,0.000000
101.010002,59.292496,-162.844757,0.008166,0.004380,0.111247,263.746185,13.435872,1.112471,-162.844757,0.111334,0.000000
101.260002,59.285049,-162.755798,0.008175,0.004380,0.111247,263.713074,13.434184,1.112471,-162.755798,0.111334,0.000000
101.510002,59.248924,-162.800278,0.008162,0.004380,0.111247,263.552368,13.425998,1.112471,-162.800278,0.111334,0.000000
101.760002,59.245575,-162.844757,0.008166,0.004380,0.111247,263.537476,13.425239,1.112471,-162.844757,0.111334,0.000000
102.010002,59.245201,-162.844757,0.008157,0.004380,0.111247,263.535828,13.425155,1.112471,-162.844757,0.111334,0.000000
102.260002,59.199402,-162.844757,0.008170,0.004380,0.111247,263.332092,13.414776,1.112471,-162.844757,0.111334,0.000000
102.510002,59.200142,-162.800278,0.008166,0.004380,0.111247,263.335388,13.414944,1.112471,-162.800278,0.111334,0.000000
102.760002,59.178177,-162.800278,0.008162,0.004380,0.111247,263.237671,13.409966,1.112471,-162.800278,0.111334,0.000000
103.010002,59.174828,-162.844757,0.008166,0.004380,0.111247,263.222778,13.409207,1.112471,-162.844757,0.111334,0.000000
103.260002,59.170731,-162.844757,0.008170,0.004380,0.111247,263.204559,13.408279,1.112471,-162.844757,0.111334,0.000000
103.510002,59.136841,-162.844757,0.008170,0.004380,0.111247,263.053802,13.400599,1.112471,-162.844757,0.111334,0.000000
103.760002,59.118965,-162.889236,0.008166,0.004380,0.111247,262.974304,13.396548,1.112471,-162.889236,0.111334,0.000000
104.010002,59.109657,-162.844757,0.008166,0.004380,0.111247,262.932892,13.394440,1.112471,-162.844757,0.111334,0.000000
104.260002,59.086197,-162.889236,0.008170,0.004380,0.111247,262.828522,13.389123,1.112471,-162.889236,0.111334,0.000000
104.510002,59.079124,-162.889236,0.008166,0.004380,0.111247,262.797058,13.387521,1.112471,-162.889236,0.111334,0.000000
104.760002,59.054176,-162.889236,0.008175,0.004380,0.111247,262.686096,13.381867,1.112471,-162.889236,0.111334,0.000000
105.010002,59.043373,-162.889236,0.008162,0.004380,0.111247,262.638031,13.379419,1.112471,-162.889236,0.111334,0.000000
105.100006,59.048592,-162.844757,0.008175,0.004380,0.111247,262.661255,13.380602,1.112471,-162.844757,0.111334,0.000000