File: Data/compression 9/AutoHeating-13-9-1--240404_04042024_173756.csv
Time (sec),S:Load (lbs),S:HL1 (DIM),S:LVDT (in),S:Position (in),Ch:Position (mm),Ch:Load (N),Ch:Stress (MPa),Ch:Strain (mm/mm),Ch:HL1 (DIM),Set Point (),Cycles ()
0.110000,-0.014519,-155.283005,0.000000,-0.000000,-0.000000,-0.064583,-0.003290,-0.000000,-155.283005,0.000173,0.000000
0.370000,-0.016380,-155.194031,-0.000009,0.000010,0.000243,-0.072863,-0.003712,0.002430,-155.194031,0.000798,0.000000
0.630000,-0.023827,-155.194031,-0.000004,0.000160,0.004067,-0.105986,-0.005399,0.040672,-155.194031,0.005134,0.000000
0.890000,0.013039,-155.327484,0.000138,0.000329,0.008360,0.057999,0.002955,0.083601,-155.327484,0.009470,0.000000
1.150000,-0.017128,-155.194031,0.000306,0.000504,0.012800,-0.076189,-0.003881,0.127998,-155.194031,0.013806,0.000000
1.410000,-0.066650,-155.283005,0.000492,0.000673,0.017093,-0.296476,-0.015103,0.170926,-155.283005,0.018125,0.000000
1.670000,0.012291,-155.283005,0.000642,0.000831,0.021117,0.054673,0.002785,0.211167,-155.283005,0.022461,0.000000
1.930000,0.004845,-155.238525,0.000836,0.001012,0.025705,0.021550,0.001098,0.257047,-155.238525,0.026797,0.000000
2.190000,-0.008934,-155.283005,0.001000,0.001184,0.030066,-0.039741,-0.002024,0.300664,-155.283005,0.031133,0.000000
2.450000,0.021973,-155.283005,0.001173,0.001347,0.034203,0.097739,0.004979,0.342033,-155.283005,0.035452,0.000000
2.710000,0.004471,-155.238525,0.001354,0.001524,0.038713,0.019887,0.001013,0.387127,-155.238525,0.039788,0.000000
2.970000,-0.011909,-155.327484,0.001513,0.001692,0.042971,-0.052976,-0.002699,0.429707,-155.327484,0.044124,0.000000
3.230000,0.013039,-155.283005,0.001686,0.001856,0.047151,0.057999,0.002955,0.471507,-155.283005,0.048443,0.000000
3.490000,-0.015266,-155.371964,0.001871,0.002039,0.051790,-0.067908,-0.003459,0.517902,-155.371964,0.052779,0.000000
3.750000,-0.011543,-155.283005,0.002035,0.002207,0.056049,-0.051347,-0.002616,0.560490,-155.283005,0.057116,0.000000
4.010000,0.039101,-155.283005,0.002199,0.002369,0.060168,0.173928,0.008860,0.601677,-155.283005,0.061452,0.000000
4.270000,0.002235,-155.416443,0.002384,0.002550,0.064782,0.009944,0.000507,0.647815,-155.416443,0.065770,0.000000
4.530000,0.007454,-155.327484,0.002557,0.002716,0.068987,0.033157,0.001689,0.689873,-155.327484,0.070106,0.000000
4.790000,0.033142,-155.371964,0.002716,0.002879,0.073133,0.147423,0.007510,0.731333,-155.371964,0.074443,0.000000
5.050000,-0.007446,-155.327484,0.002897,0.003061,0.077755,-0.033123,-0.001687,0.777554,-155.327484,0.078779,0.000000
5.310000,0.007820,-155.327484,0.003083,0.003230,0.082031,0.034786,0.001772,0.820308,-155.327484,0.083097,0.000000
5.570000,0.019737,-155.371964,0.003238,0.003388,0.086063,0.087796,0.004473,0.860632,-155.371964,0.087433,0.000000
5.830000,-0.041328,-155.371964,0.003423,0.003569,0.090651,-0.183838,-0.009365,0.906513,-155.371964,0.091769,0.000000
6.090000,0.005219,-155.416443,0.003600,0.003744,0.095100,0.023213,0.001183,0.951000,-155.416443,0.096106,0.000000
6.350000,0.028305,-155.371964,0.003760,0.003906,0.099220,0.125907,0.006414,0.992195,-155.371964,0.100425,0.000000
6.610000,-0.002228,-155.371964,0.003945,0.004081,0.103659,-0.009910,-0.000505,1.036592,-155.371964,0.104761,0.000000
6.870000,0.023460,-155.416443,0.004126,0.004254,0.108047,0.104357,0.005316,1.080474,-155.416443,0.109097,0.000000
7.130000,0.005959,-155.371964,0.004273,0.004417,0.112202,0.026505,0.001350,1.122017,-155.371964,0.113433,0.000000
7.390000,-0.032021,-155.416443,0.004471,0.004592,0.116633,-0.142435,-0.007256,1.166331,-155.416443,0.117752,0.000000
7.650001,0.010429,-155.416443,0.004626,0.004763,0.120969,0.046392,0.002363,1.209690,-155.416443,0.122088,0.000000
7.910000,0.001862,-155.460922,0.004807,0.004932,0.125279,0.008281,0.000422,1.252793,-155.460922,0.126424,0.000000
8.170000,0.005592,-155.460922,0.004980,0.005098,0.129485,0.024876,0.001267,1.294850,-155.460922,0.130743,0.000000
8.430000,0.028679,-155.460922,0.005157,0.005276,0.134013,0.127570,0.006499,1.340125,-155.460922,0.135079,0.000000
8.690001,0.036865,-155.505402,0.005316,0.005439,0.138149,0.163985,0.008354,1.381487,-155.505402,0.139415,0.000000
8.950001,0.028305,-155.416443,0.005506,0.005615,0.142624,0.125907,0.006414,1.426239,-155.416443,0.143751,0.000000
9.210000,0.022346,-155.416443,0.005678,0.005785,0.146952,0.099402,0.005064,1.469516,-155.416443,0.148070,0.000000
9.470000,0.007080,-155.549881,0.005842,0.005960,0.151391,0.031494,0.001604,1.513913,-155.549881,0.152406,0.000000
9.730000,-0.036491,-155.416443,0.006010,0.006128,0.155641,-0.162322,-0.008269,1.556409,-155.416443,0.156742,0.000000
9.990001,-0.002228,-155.505402,0.006187,0.006296,0.159916,-0.009910,-0.000505,1.599164,-155.505402,0.161078,0.000000
10.250001,0.054001,-155.460922,0.006355,0.006467,0.164252,0.240208,0.012237,1.642523,-155.460922,0.165397,0.000000
10.510000,0.011177,-155.416443,0.006523,0.006637,0.168580,0.049718,0.002533,1.685800,-155.416443,0.169734,0.000000
10.770000,0.039474,-155.549881,0.006691,0.006807,0.172899,0.175591,0.008945,1.728985,-155.549881,0.174070,0.000000
11.030001,0.052132,-155.505402,0.006864,0.006981,0.177312,0.231893,0.011813,1.773125,-155.505402,0.178406,0.000000
11.290001,0.008942,-155.549881,0.007028,0.007149,0.181597,0.039774,0.002026,1.815970,-155.549881,0.182724,0.000000
11.550000,0.037239,-155.505402,0.007213,0.007320,0.185916,0.165648,0.008438,1.859156,-155.505402,0.187060,0.000000
11.810000,0.012291,-155.549881,0.007390,0.007497,0.190426,0.054673,0.002785,1.904256,-155.549881,0.191397,0.000000
12.070001,-0.021225,-155.549881,0.007562,0.007663,0.194649,-0.094413,-0.004810,1.946488,-155.549881,0.195715,0.000000
12.330001,0.167946,-155.505402,0.007705,0.007822,0.198681,0.747060,0.038057,1.986812,-155.505402,0.200051,0.000000
12.590000,0.636391,-155.549881,0.007860,-0.000002,-0.000051,2.830807,0.144208,-0.000515,-155.549881,0.000174,0.000000
12.850000,0.585373,-155.638855,0.007851,-0.000002,-0.000051,2.603869,0.132647,-0.000515,-155.638855,0.000174,0.000000
13.110001,0.570480,-155.594360,0.007851,-0.000002,-0.000051,2.537623,0.129273,-0.000515,-155.594360,0.000278,0.000000
13.370001,0.569733,-155.594360,0.007847,-0.000002,-0.000043,2.534297,0.129103,-0.000431,-155.594360,0.000712,0.000000
13.630001,0.572342,-155.549881,0.007860,0.000005,0.000139,2.545904,0.129695,0.001393,-155.549881,0.001145,0.000000
13.890000,0.738419,-155.594360,0.007864,0.000022,0.000564,3.284650,0.167328,0.005639,-155.594360,0.001578,0.000000
14.150001,0.939125,-155.594360,0.007877,0.000048,0.001232,4.177437,0.212809,0.012316,-155.594360,0.002012,0.000000
14.410001,0.985672,-155.549881,0.007899,0.000059,0.001509,4.384488,0.223356,0.015094,-155.549881,0.002446,0.000000
14.670001,1.105576,-155.638855,0.007912,0.000078,0.001969,4.917846,0.250527,0.019689,-155.638855,0.002880,0.000000
14.930000,1.215057,-155.638855,0.007942,0.000094,0.002385,5.404845,0.275336,0.023852,-155.638855,0.003313,0.000000
15.190001,1.375923,-155.594360,0.007968,0.000113,0.002870,6.120412,0.311789,0.028705,-155.594360,0.003747,0.000000
15.450001,1.505508,-155.683334,0.007968,0.000131,0.003322,6.696836,0.341153,0.033216,-155.683334,0.004180,0.000000
15.710001,1.592270,-155.594360,0.007994,0.000141,0.003590,7.082770,0.360814,0.035904,-155.594360,0.004614,0.000000
15.970001,1.838776,-155.638855,0.008015,0.000171,0.004337,8.179282,0.416673,0.043367,-155.638855,0.005048,0.000000
16.230001,1.921074,-155.638855,0.008037,0.000186,0.004727,8.545363,0.435322,0.047266,-155.638855,0.005481,0.000000
16.490002,1.954590,-155.638855,0.008041,0.000199,0.005065,8.694449,0.442916,0.050649,-155.638855,0.005915,0.000000
16.750000,2.106514,-155.638855,0.008054,0.000219,0.005551,9.370242,0.477343,0.055509,-155.638855,0.006348,0.000000
17.010000,2.206680,-155.638855,0.008071,0.000234,0.005949,9.815804,0.500041,0.059491,-155.638855,0.006782,0.000000
17.270000,2.313179,-155.683334,0.008101,0.000249,0.006314,10.289535,0.524174,0.063140,-155.683334,0.007216,0.000000
17.530001,2.386536,-155.683334,0.008106,0.000259,0.006591,10.615841,0.540797,0.065910,-155.683334,0.007649,0.000000
17.790001,2.494530,-155.727814,0.008123,0.000274,0.006964,11.096222,0.565269,0.069642,-155.727814,0.008083,0.000000
18.050001,2.770454,-155.683334,0.008153,0.000303,0.007702,12.323597,0.627794,0.077015,-155.683334,0.008517,0.000000
18.310001,2.801735,-155.638855,0.008170,0.000317,0.008039,12.462739,0.634882,0.080391,-155.638855,0.008950,0.000000
18.570002,2.913818,-155.727814,0.008179,0.000337,0.008560,12.961311,0.660281,0.085599,-155.727814,0.009384,0.000000
18.830002,2.970421,-155.683334,0.008196,0.000350,0.008881,13.213092,0.673107,0.088809,-155.683334,0.009817,0.000000
19.090000,3.140594,-155.683334,0.008226,0.000371,0.009427,13.970062,0.711669,0.094274,-155.683334,0.010251,0.000000
19.350000,3.216187,-155.727814,0.008235,0.000383,0.009739,14.306313,0.728798,0.097393,-155.727814,0.010685,0.000000
19.610001,3.213951,-155.683334,0.008252,0.000395,0.010025,14.296369,0.728292,0.100254,-155.683334,0.011119,0.000000
19.870001,3.519295,-155.727814,0.008274,0.000419,0.010650,15.654605,0.797484,0.106499,-155.727814,0.011551,0.000000
20.130001,3.540520,-155.727814,0.008287,0.000438,0.011127,15.749019,0.802293,0.111268,-155.727814,0.011977,0.000000
20.390001,3.602707,-155.772293,0.008313,0.000455,0.011551,16.025640,0.816385,0.115515,-155.772293,0.012411,0.000000
20.650002,3.671227,-155.772293,0.008326,0.000468,0.011899,16.330431,0.831912,0.118990,-155.772293,0.012844,0.000000
20.910002,3.774368,-155.727814,0.008338,0.000489,0.012419,16.789228,0.855284,0.124190,-155.727814,0.013277,0.000000
21.170000,3.939331,-155.727814,0.008382,0.000505,0.012826,17.523020,0.892665,0.128263,-155.727814,0.013711,0.000000
21.430000,3.870811,-155.816772,0.008364,0.000514,0.013061,17.218229,0.877138,0.130609,-155.816772,0.014145,0.000000
21.690001,4.018272,-155.727814,0.008390,0.000535,0.013590,17.874168,0.910554,0.135900,-155.727814,0.014579,0.000000
21.950001,4.223450,-155.772293,0.008425,0.000557,0.014153,18.786842,0.957047,0.141532,-155.772293,0.015012,0.000000
22.210001,4.247658,-155.816772,0.008429,0.000573,0.014561,18.894526,0.962533,0.145612,-155.816772,0.015445,0.000000
22.470001,4.247284,-155.816772,0.008455,0.000589,0.014969,18.892862,0.962448,0.149685,-155.816772,0.015879,0.000000
22.730001,4.363838,-155.861252,0.008472,0.000606,0.015402,19.411322,0.988860,0.154023,-155.861252,0.016313,0.000000
22.990002,4.441666,-155.772293,0.008498,0.000624,0.015844,19.757515,1.006496,0.158443,-155.772293,0.016747,0.000000
23.250002,4.462143,-155.861252,0.008507,0.000637,0.016183,19.848602,1.011136,0.161827,-155.861252,0.017180,0.000000
23.510000,4.461769,-155.816772,0.008524,0.000651,0.016529,19.846941,1.011051,0.165294,-155.816772,0.017613,0.000000
23.770000,4.752968,-155.861252,0.008571,0.000676,0.017171,21.142258,1.077038,0.171713,-155.861252,0.018047,0.000000
24.030001,4.818130,-155.816772,0.008576,0.000695,0.017666,21.432116,1.091804,0.176656,-155.816772,0.018481,0.000000
24.290001,4.769722,-155.861252,0.008601,0.000710,0.018039,21.216784,1.080834,0.180388,-155.861252,0.018915,0.000000
24.550001,4.812546,-155.861252,0.008627,0.000726,0.018429,21.407272,1.090538,0.184287,-155.861252,0.019348,0.000000
24.810001,4.868027,-155.816772,0.008645,0.000742,0.018845,21.654064,1.103111,0.188450,-155.816772,0.019781,0.000000
25.070002,4.995750,-155.816772,0.008670,0.000762,0.019348,22.222208,1.132053,0.193484,-155.816772,0.020215,0.000000
25.330002,4.912712,-155.905731,0.008679,0.000773,0.019635,21.852835,1.113236,0.196345,-155.905731,0.020649,0.000000
25.590002,5.118263,-155.861252,0.008688,0.000794,0.020164,22.767172,1.159815,0.201636,-155.861252,0.021083,0.000000
25.850000,5.212097,-155.905731,0.008727,0.000815,0.020709,23.184566,1.181078,0.207094,-155.905731,0.021516,0.000000
26.110001,5.155502,-155.861252,0.008757,0.000829,0.021057,22.932819,1.168254,0.210569,-155.861252,0.021950,0.000000
26.370001,5.192734,-155.905731,0.008778,0.000847,0.021525,23.098433,1.176690,0.215247,-155.905731,0.022383,0.000000
26.630001,5.241516,-155.905731,0.008791,0.000864,0.021941,23.315428,1.187745,0.219410,-155.905731,0.022817,0.000000
26.890001,5.345039,-155.861252,0.008813,0.000883,0.022435,23.775923,1.211203,0.224353,-155.861252,0.023251,0.000000
27.150002,5.245613,-155.905731,0.008839,0.000894,0.022713,23.333652,1.188673,0.227132,-155.905731,0.023684,0.000000
27.410002,5.156990,-155.905731,0.008839,0.000903,0.022947,22.939438,1.168591,0.229471,-155.905731,0.024118,0.000000
27.670002,5.583725,-155.861252,0.008873,0.000937,0.023788,24.837648,1.265290,0.237881,-155.861252,0.024551,0.000000
27.930002,5.400520,-156.039169,0.008899,0.000947,0.024048,24.022715,1.223775,0.240485,-156.039169,0.024985,0.000000
28.190001,5.404617,-155.905731,0.008921,0.000964,0.024491,24.040939,1.224704,0.244905,-155.905731,0.025419,0.000000
28.450001,5.460098,-155.905731,0.008942,0.000982,0.024933,24.287729,1.237276,0.249334,-155.905731,0.025852,0.000000
28.710001,5.561386,-155.950211,0.008951,0.000999,0.025375,24.738281,1.260228,0.253754,-155.950211,0.026286,0.000000
28.970001,5.649269,-155.950211,0.008972,0.001017,0.025827,25.129204,1.280143,0.258266,-155.950211,0.026720,0.000000
29.230001,5.582985,-155.994690,0.008985,0.001029,0.026130,24.834356,1.265122,0.261302,-155.994690,0.027145,0.000000
29.490002,5.620224,-155.950211,0.009002,0.001043,0.026503,25.000006,1.273561,0.265026,-155.950211,0.027578,0.000000
29.750002,5.957214,-155.950211,0.009054,0.001073,0.027266,26.499012,1.349924,0.272656,-155.950211,0.028012,0.000000
30.010002,5.735657,-156.039169,0.009063,0.001083,0.027509,25.513475,1.299718,0.275086,-156.039169,0.028445,0.000000
30.270002,5.804916,-155.950211,0.009071,0.001104,0.028029,25.821558,1.315413,0.280294,-155.950211,0.028879,0.000000
30.530001,5.911041,-156.039169,0.009110,0.001122,0.028506,26.293625,1.339461,0.285063,-156.039169,0.029312,0.000000
30.790001,5.952003,-155.994690,0.009127,0.001138,0.028896,26.475834,1.348743,0.288962,-155.994690,0.029746,0.000000
31.050001,5.851463,-156.039169,0.009145,0.001149,0.029182,26.028608,1.325961,0.291823,-156.039169,0.030180,0.000000
31.310001,6.045471,-156.039169,0.009149,0.001167,0.029651,26.891600,1.369923,0.296509,-156.039169,0.030614,0.000000
31.570002,6.244316,-156.039169,0.009184,0.001192,0.030266,27.776106,1.414982,0.302663,-156.039169,0.031047,0.000000
31.830002,6.214897,-155.994690,0.009196,0.001209,0.030717,27.645243,1.408316,0.307175,-155.994690,0.031480,0.000000
32.090000,6.125160,-156.039169,0.009222,0.001220,0.030995,27.246073,1.387981,0.309953,-156.039169,0.031914,0.000000
32.350002,6.238731,-156.039169,0.009244,0.001239,0.031463,27.751263,1.413717,0.314631,-156.039169,0.032348,0.000000
32.610001,6.335175,-156.083664,0.009253,0.001257,0.031923,28.180264,1.435571,0.319226,-156.083664,0.032782,0.000000
32.870003,6.237984,-156.039169,0.009265,0.001267,0.032183,27.747938,1.413547,0.321830,-156.039169,0.033215,0.000000
33.130001,6.372414,-156.083664,0.009300,0.001285,0.032634,28.345911,1.444010,0.326341,-156.083664,0.033648,0.000000
33.390003,6.601051,-156.039169,0.009304,0.001305,0.033146,29.362944,1.495820,0.331458,-156.039169,0.034082,0.000000
33.650002,6.436836,-156.039169,0.009330,0.001317,0.033440,28.632477,1.458608,0.334403,-156.039169,0.034516,0.000000
33.910000,6.532906,-156.083664,0.009352,0.001333,0.033857,29.059814,1.480378,0.338566,-156.083664,0.034950,0.000000
34.170002,6.713135,-156.083664,0.009373,0.001353,0.034368,29.861515,1.521218,0.343684,-156.083664,0.035383,0.000000
34.430000,6.889641,-156.083664,0.009408,0.001377,0.034985,30.646652,1.561215,0.349845,-156.083664,0.035816,0.000000
34.690002,6.829689,-156.083664,0.009421,0.001392,0.035357,30.379974,1.547630,0.353570,-156.083664,0.036250,0.000000
34.950001,6.793198,-156.128143,0.009442,0.001405,0.035687,30.217651,1.539361,0.356870,-156.128143,0.036684,0.000000
35.210003,6.831551,-156.217102,0.009455,0.001422,0.036112,30.388254,1.548051,0.361117,-156.217102,0.037118,0.000000
35.470001,7.197220,-156.128143,0.009485,0.001447,0.036762,32.014832,1.630913,0.367619,-156.128143,0.037551,0.000000
35.730003,7.013268,-156.172623,0.009494,0.001458,0.037031,31.196571,1.589229,0.370307,-156.172623,0.037984,0.000000
35.990002,7.059067,-156.128143,0.009524,0.001476,0.037499,31.400297,1.599607,0.374992,-156.128143,0.038418,0.000000
36.250000,7.092957,-156.172623,0.009541,0.001493,0.037933,31.551046,1.607287,0.379330,-156.172623,0.038852,0.000000
36.510002,7.188278,-156.172623,0.009563,0.001512,0.038401,31.975058,1.628887,0.384008,-156.172623,0.039286,0.000000
36.770000,7.271690,-156.172623,0.009567,0.001529,0.038844,32.346096,1.647789,0.388436,-156.172623,0.039719,0.000000
37.030003,7.165565,-156.083664,0.009610,0.001541,0.039138,31.874027,1.623740,0.391381,-156.083664,0.040153,0.000000
37.290001,7.561028,-156.172623,0.009632,0.001570,0.039875,33.633129,1.713353,0.398754,-156.172623,0.040586,0.000000
37.550003,7.448196,-156.172623,0.009662,0.001585,0.040265,33.131233,1.687785,0.402652,-156.172623,0.041020,0.000000
37.810001,7.315262,-156.261581,0.009675,0.001600,0.040630,32.539909,1.657662,0.406301,-156.261581,0.041454,0.000000
38.070004,7.479103,-156.172623,0.009692,0.001618,0.041090,33.268711,1.694789,0.410896,-156.172623,0.041878,0.000000
38.330002,7.464951,-156.172623,0.009718,0.001634,0.041497,33.205757,1.691582,0.414968,-156.172623,0.042312,0.000000
38.590000,7.434044,-156.217102,0.009731,0.001646,0.041818,33.068279,1.684578,0.418178,-156.217102,0.042746,0.000000
38.850002,7.396065,-156.217102,0.009748,0.001658,0.042113,32.899338,1.675972,0.421130,-156.217102,0.043180,0.000000
39.110001,7.449318,-156.261581,0.009757,0.001673,0.042495,33.136223,1.688040,0.424945,-156.261581,0.043613,0.000000
39.370003,7.920364,-156.217102,0.009791,0.001702,0.043223,35.231541,1.794780,0.432227,-156.217102,0.044046,0.000000
39.630001,7.746841,-156.217102,0.009817,0.001716,0.043587,34.459671,1.755459,0.435869,-156.217102,0.044480,0.000000
39.890003,7.888718,-156.261581,0.009843,0.001738,0.044142,35.090767,1.787609,0.441425,-156.261581,0.044914,0.000000
40.150002,7.714813,-156.261581,0.009860,0.001749,0.044437,34.317204,1.748202,0.444369,-156.261581,0.045348,0.000000
40.410004,7.788170,-156.261581,0.009886,0.001766,0.044853,34.643509,1.764825,0.448533,-156.261581,0.045781,0.000000
40.670002,7.795624,-156.217102,0.009899,0.001782,0.045261,34.676666,1.766514,0.452605,-156.217102,0.046215,0.000000
40.930000,7.633263,-156.306061,0.009908,0.001790,0.045478,33.954449,1.729722,0.454778,-156.306061,0.046648,0.000000
41.190002,8.125916,-156.217102,0.009938,0.001818,0.046180,36.145878,1.841359,0.461803,-156.217102,0.047082,0.000000
41.450001,8.096497,-156.306061,0.009964,0.001838,0.046683,36.015015,1.834692,0.466829,-156.306061,0.047516,0.000000
41.710003,8.007874,-156.306061,0.009985,0.001854,0.047082,35.620800,1.814610,0.470818,-156.306061,0.047949,0.000000
41.970001,7.933769,-156.395020,0.010003,0.001866,0.047403,35.291168,1.797818,0.474028,-156.395020,0.048383,0.000000
42.230003,8.185120,-156.261581,0.010033,0.001890,0.048002,36.409229,1.854775,0.480016,-156.261581,0.048817,0.000000
42.490002,8.122192,-156.261581,0.010046,0.001904,0.048357,36.129314,1.840515,0.483566,-156.261581,0.049250,0.000000
42.750004,7.871956,-156.306061,0.010067,0.001913,0.048582,35.016209,1.783811,0.485822,-156.306061,0.049684,0.000000
43.010002,7.788170,-156.350540,0.010080,0.001928,0.048964,34.643509,1.764825,0.489637,-156.350540,0.050117,0.000000
43.270000,8.347473,-156.350540,0.010106,0.001958,0.049736,37.131416,1.891564,0.497358,-156.350540,0.050551,0.000000
43.530003,8.225342,-156.306061,0.010141,0.001973,0.050109,36.588146,1.863889,0.501090,-156.306061,0.050985,0.000000
43.790001,8.169853,-156.395020,0.010154,0.001989,0.050525,36.341324,1.851315,0.505246,-156.395020,0.051418,0.000000
44.050003,8.090538,-156.350540,0.010184,0.002003,0.050880,35.988510,1.833342,0.508803,-156.350540,0.051852,0.000000
44.310001,8.219383,-156.395020,0.010188,0.002022,0.051366,36.561642,1.862539,0.513663,-156.395020,0.052285,0.000000
44.570004,8.100594,-156.350540,0.010218,0.002035,0.051696,36.033241,1.835621,0.516956,-156.350540,0.052719,0.000000
44.830002,8.397743,-156.350540,0.010231,0.002057,0.052260,37.355026,1.902956,0.522596,-156.350540,0.053153,0.000000
45.090004,8.353065,-156.395020,0.010266,0.002075,0.052710,37.156292,1.892832,0.527100,-156.395020,0.053587,0.000000
45.350002,8.382111,-156.306061,0.010283,0.002094,0.053188,37.285492,1.899413,0.531876,-156.306061,0.054020,0.000000
45.610001,8.243210,-156.350540,0.010313,0.002109,0.053569,36.667629,1.867938,0.535691,-156.350540,0.054453,0.000000
45.870003,8.243210,-156.395020,0.010335,0.002124,0.053942,36.667629,1.867938,0.539416,-156.395020,0.054887,0.000000
46.130001,8.247307,-156.395020,0.010352,0.002141,0.054375,36.685852,1.868866,0.543753,-156.395020,0.055321,0.000000
46.390003,8.429024,-156.439499,0.010369,0.002160,0.054870,37.494171,1.910044,0.548696,-156.439499,0.055755,0.000000
46.650002,8.303162,-156.395020,0.010386,0.002173,0.055182,36.934307,1.881523,0.551823,-156.395020,0.056188,0.000000
46.910004,8.461426,-156.350540,0.010408,0.002191,0.055659,37.638302,1.917387,0.556592,-156.350540,0.056621,0.000000
47.170002,8.602921,-156.439499,0.010430,0.002213,0.056222,38.267700,1.949450,0.562223,-156.439499,0.057047,0.000000
47.430004,8.455467,-156.395020,0.010460,0.002228,0.056586,37.611797,1.916036,0.565865,-156.395020,0.057480,0.000000
47.690002,8.498291,-156.483978,0.010473,0.002247,0.057064,37.802288,1.925740,0.570641,-156.483978,0.057913,0.000000
47.950001,8.492699,-156.439499,0.010486,0.002263,0.057471,37.777409,1.924473,0.574714,-156.439499,0.058347,0.000000
48.210003,8.577972,-156.439499,0.010529,0.002281,0.057948,38.156727,1.943796,0.579483,-156.439499,0.058781,0.000000
48.470001,8.355293,-156.439499,0.010550,0.002292,0.058217,37.166203,1.893337,0.582170,-156.439499,0.059215,0.000000
48.730003,8.302048,-156.395020,0.010559,0.002303,0.058503,36.929352,1.881271,0.585031,-156.395020,0.059648,0.000000
48.990002,8.908646,-156.528473,0.010593,0.002335,0.059310,39.627636,2.018728,0.593101,-156.528473,0.060081,0.000000
49.250004,8.550049,-156.483978,0.010615,0.002346,0.059587,38.032516,1.937469,0.595871,-156.483978,0.060515,0.000000
49.510002,8.547813,-156.439499,0.010628,0.002365,0.060073,38.022572,1.936962,0.600731,-156.439499,0.060949,0.000000
49.770000,8.587654,-156.483978,0.010641,0.002380,0.060463,38.199795,1.945990,0.604629,-156.483978,0.061383,0.000000
50.030003,8.740700,-156.439499,0.010671,0.002398,0.060906,38.880573,1.980671,0.609058,-156.439499,0.061816,0.000000
50.290001,8.817780,-156.528473,0.010701,0.002415,0.061340,39.223442,1.998137,0.613395,-156.528473,0.062249,0.000000
50.550003,8.626755,-156.528473,0.010701,0.002427,0.061634,38.373722,1.954851,0.616340,-156.528473,0.062683,0.000000
50.810001,8.823372,-156.483978,0.010718,0.002442,0.062033,39.248318,1.999405,0.620329,-156.483978,0.063117,0.000000
51.070004,9.311920,-156.572952,0.010753,0.002472,0.062788,41.421490,2.110111,0.627876,-156.572952,0.063551,0.000000
51.330002,8.871780,-156.528473,0.010779,0.002482,0.063031,39.463650,2.010374,0.630306,-156.528473,0.063984,0.000000
51.590004,9.028915,-156.528473,0.010800,0.002501,0.063533,40.162621,2.045981,0.635332,-156.528473,0.064418,0.000000
51.850002,9.100410,-156.483978,0.010822,0.002519,0.063984,40.480648,2.062182,0.639844,-156.483978,0.064851,0.000000
52.110001,9.139885,-156.483978,0.010843,0.002533,0.064349,40.656239,2.071128,0.643485,-156.483978,0.065285,0.000000
52.370003,8.986465,-156.617432,0.010852,0.002544,0.064626,39.973793,2.036362,0.646263,-156.617432,0.065719,0.000000
52.630001,9.359589,-156.617432,0.010878,0.002565,0.065155,41.633530,2.120913,0.651547,-156.617432,0.066152,0.000000
52.890003,9.742760,-156.617432,0.010908,0.002591,0.065814,43.337959,2.207741,0.658140,-156.617432,0.066586,0.000000
53.150002,9.644447,-156.572952,0.010925,0.002608,0.066239,42.900646,2.185463,0.662387,-156.572952,0.067019,0.000000
53.410004,9.421028,-156.572952,0.010943,0.002618,0.066508,41.906826,2.134835,0.665082,-156.572952,0.067453,0.000000
53.670002,9.636261,-156.572952,0.010960,0.002637,0.066968,42.864231,2.183608,0.669677,-156.572952,0.067887,0.000000
53.930004,9.784836,-156.617432,0.010981,0.002654,0.067418,43.525124,2.217276,0.674181,-156.617432,0.068320,0.000000
54.190002,9.676849,-156.617432,0.011003,0.002666,0.067705,43.044777,2.192805,0.677050,-156.617432,0.068754,0.000000
54.450001,9.823189,-156.572952,0.011007,0.002682,0.068130,43.695724,2.225966,0.681296,-156.572952,0.069188,0.000000
54.710003,10.291260,-156.528473,0.011033,0.002703,0.068650,45.777809,2.332033,0.686497,-156.528473,0.069621,0.000000
54.970001,10.115875,-156.617432,0.011055,0.002717,0.069005,44.997662,2.292290,0.690054,-156.617432,0.070055,0.000000
55.230003,10.227959,-156.572952,0.011063,0.002733,0.069430,45.496231,2.317689,0.694301,-156.572952,0.070488,0.000000
55.490002,10.492714,-156.617432,0.011098,0.002751,0.069881,46.673923,2.377683,0.698813,-156.617432,0.070922,0.000000
55.750004,10.916847,-156.661911,0.011115,0.002776,0.070506,48.560562,2.473793,0.705058,-156.661911,0.071356,0.000000
56.010002,10.824127,-156.661911,0.011137,0.002790,0.070870,48.148121,2.452782,0.708699,-156.661911,0.071790,0.000000
56.270004,10.818169,-156.706390,0.011150,0.002803,0.071208,48.121616,2.451432,0.712083,-156.706390,0.072214,0.000000
56.530003,11.010315,-156.572952,0.011175,0.002821,0.071659,48.976326,2.494973,0.716594,-156.572952,0.072648,0.000000
56.790001,11.618767,-156.706390,0.011188,0.002845,0.072257,51.682858,2.632850,0.722574,-156.706390,0.073082,0.000000
57.050003,11.414337,-156.661911,0.011193,0.002857,0.072561,50.773506,2.586526,0.725610,-156.661911,0.073515,0.000000
57.310001,11.595306,-156.661911,0.011227,0.002875,0.073020,51.578499,2.627534,0.730205,-156.661911,0.073949,0.000000
57.570004,11.695480,-156.706390,0.011240,0.002892,0.073454,52.024094,2.650234,0.734542,-156.706390,0.074382,0.000000
57.830002,12.014977,-156.661911,0.011253,0.002910,0.073905,53.445286,2.722633,0.739054,-156.661911,0.074816,0.000000
58.090004,12.320320,-156.661911,0.011288,0.002928,0.074365,54.803520,2.791824,0.743649,-156.661911,0.075250,0.000000
58.350002,12.234673,-156.706390,0.011292,0.002939,0.074660,54.422543,2.772416,0.746601,-156.706390,0.075683,0.000000
58.610004,13.176773,-156.750870,0.011326,0.002969,0.075406,58.613213,2.985899,0.754057,-156.750870,0.076117,0.000000
58.870003,13.069534,-156.750870,0.011344,0.002983,0.075770,58.136192,2.961599,0.757698,-156.750870,0.076550,0.000000
59.130001,12.969360,-156.750870,0.011361,0.002996,0.076099,57.690598,2.938899,0.760991,-156.750870,0.076984,0.000000
59.390003,13.490311,-156.795349,0.011378,0.003017,0.076620,60.007900,3.056948,0.766199,-156.795349,0.077418,0.000000
59.650002,13.651550,-156.750870,0.011378,0.003033,0.077036,60.725128,3.093486,0.770362,-156.750870,0.077852,0.000000
59.910004,13.667191,-156.750870,0.011404,0.003045,0.077331,60.794701,3.097029,0.773307,-156.750870,0.078284,0.000000
60.170002,13.801987,-156.750870,0.011413,0.003056,0.077634,61.394302,3.127575,0.776343,-156.750870,0.078718,0.000000
60.430004,13.897690,-156.750870,0.011434,0.003071,0.077998,61.820011,3.149261,0.779984,-156.750870,0.079152,0.000000
60.690002,15.138062,-156.750870,0.011456,0.003100,0.078736,67.337463,3.430334,0.787357,-156.750870,0.079586,0.000000
60.950005,15.119446,-156.750870,0.011464,0.003114,0.079091,67.254654,3.426115,0.790914,-156.750870,0.080019,0.000000
61.210003,15.746887,-156.750870,0.011495,0.003136,0.079646,70.045654,3.568296,0.796463,-156.750870,0.080452,0.000000
61.470001,15.655655,-156.795349,0.011499,0.003148,0.079950,69.639832,3.547622,0.799498,-156.795349,0.080886,0.000000
61.730003,16.126335,-156.795349,0.011512,0.003165,0.080384,71.733521,3.654280,0.803836,-156.795349,0.081320,0.000000
61.990002,16.404129,-156.750870,0.011529,0.003181,0.080791,72.969208,3.717229,0.807909,-156.750870,0.081754,0.000000
62.250004,16.339333,-156.884308,0.011538,0.003193,0.081094,72.680984,3.702546,0.810944,-156.884308,0.082187,0.000000
62.510002,17.563698,-156.839828,0.011555,0.003218,0.081736,78.127228,3.979991,0.817363,-156.839828,0.082621,0.000000
62.770004,17.868294,-156.839828,0.011585,0.003236,0.082205,79.482140,4.049013,0.822049,-156.839828,0.083054,0.000000
63.030003,18.186302,-156.839828,0.011602,0.003253,0.082638,80.896713,4.121075,0.826379,-156.839828,0.083488,0.000000
63.290005,18.359825,-156.795349,0.011611,0.003265,0.082925,81.668579,4.160396,0.829248,-156.795349,0.083922,0.000000
63.550003,19.245705,-156.839828,0.011628,0.003288,0.083523,85.609169,4.361139,0.835228,-156.839828,0.084355,0.000000
63.810001,19.506363,-156.795349,0.011624,0.003302,0.083879,86.768639,4.420205,0.838786,-156.795349,0.084789,0.000000
64.070000,19.355553,-156.839828,0.011645,0.003311,0.084104,86.097801,4.386031,0.841042,-156.839828,0.085222,0.000000
64.330002,19.883202,-156.839828,0.011654,0.003332,0.084624,88.444901,4.505598,0.846242,-156.839828,0.085656,0.000000
64.590004,21.184273,-156.839828,0.011684,0.003357,0.085257,94.232353,4.800425,0.852570,-156.839828,0.086090,0.000000
64.850006,21.428177,-156.928802,0.011693,0.003370,0.085604,95.317291,4.855694,0.856045,-156.928802,0.086523,0.000000
65.110001,21.733521,-156.839828,0.011706,0.003386,0.086003,96.675529,4.924886,0.860034,-156.839828,0.086948,0.000000
65.370003,22.398209,-156.795349,0.011723,0.003403,0.086445,99.632210,5.075507,0.864455,-156.795349,0.087382,0.000000
65.630005,22.992889,-156.884308,0.011727,0.003421,0.086888,102.277481,5.210263,0.868876,-156.884308,0.087816,0.000000
65.889999,23.293388,-156.839828,0.011745,0.003434,0.087226,103.614166,5.278358,0.872259,-156.839828,0.088249,0.000000
66.150002,23.968872,-156.973282,0.011753,0.003454,0.087738,106.618866,5.431424,0.877376,-156.973282,0.088683,0.000000
66.410004,25.095299,-156.884308,0.011770,0.003474,0.088232,111.629463,5.686676,0.882320,-156.884308,0.089116,0.000000
66.670006,25.806908,-156.928802,0.011788,0.003492,0.088701,114.794861,5.847929,0.887005,-156.928802,0.089550,0.000000
66.930000,26.143532,-156.928802,0.011788,0.003507,0.089090,116.292236,5.924209,0.890904,-156.928802,0.089984,0.000000
67.190002,26.472336,-156.839828,0.011814,0.003523,0.089472,117.754829,5.998717,0.894719,-156.839828,0.090417,0.000000
67.450005,27.189148,-156.928802,0.011826,0.003539,0.089888,120.943367,6.161149,0.898882,-156.928802,0.090851,0.000000
67.710007,28.258232,-156.928802,0.011826,0.003559,0.090392,125.698891,6.403407,0.903916,-156.928802,0.091285,0.000000
67.970001,28.434738,-156.973282,0.011852,0.003571,0.090694,126.484032,6.443404,0.906944,-156.973282,0.091718,0.000000
68.230003,29.560043,-156.973282,0.011865,0.003591,0.091224,131.489639,6.698402,0.912235,-156.973282,0.092152,0.000000
68.490005,30.838402,-156.973282,0.011874,0.003613,0.091779,137.176056,6.988081,0.917792,-156.973282,0.092585,0.000000
68.750000,31.164597,-156.973282,0.011887,0.003626,0.092099,138.627045,7.061998,0.920994,-156.973282,0.093019,0.000000
69.010002,31.918282,-156.973282,0.011883,0.003644,0.092568,141.979614,7.232786,0.925679,-156.973282,0.093453,0.000000
69.270004,32.636963,-156.973282,0.011904,0.003660,0.092976,145.176468,7.395641,0.929759,-156.973282,0.093886,0.000000
69.530006,33.656891,-157.062241,0.011917,0.003680,0.093479,149.713333,7.626760,0.934786,-157.062241,0.094320,0.000000
69.790001,33.924995,-157.017761,0.011921,0.003689,0.093712,150.905914,7.687514,0.937125,-157.017761,0.094753,0.000000
70.050003,34.237045,-157.062241,0.011939,0.003702,0.094043,152.293991,7.758225,0.940425,-157.062241,0.095187,0.000000
70.310005,36.266106,-156.973282,0.011943,0.003731,0.094779,161.319702,8.218017,0.947791,-156.973282,0.095621,0.000000
70.570000,36.883125,-157.017761,0.011969,0.003744,0.095092,164.064331,8.357836,0.950917,-157.017761,0.096055,0.000000
70.830002,37.697502,-157.106720,0.011973,0.003762,0.095560,167.686859,8.542376,0.955603,-157.106720,0.096488,0.000000
71.090004,38.460121,-157.017761,0.011982,0.003778,0.095959,171.079163,8.715188,0.959592,-157.017761,0.096921,0.000000
71.350006,39.547821,-157.062241,0.011999,0.003796,0.096427,175.917496,8.961664,0.964270,-157.062241,0.097355,0.000000
71.610001,40.575195,-156.973282,0.011995,0.003813,0.096852,180.487488,9.194470,0.968524,-156.973282,0.097789,0.000000
71.870003,40.813889,-157.062241,0.012003,0.003824,0.097129,181.549240,9.248559,0.971295,-157.062241,0.098223,0.000000
72.130005,41.485275,-157.106720,0.012008,0.003841,0.097554,184.535721,9.400698,0.975542,-157.106720,0.098656,0.000000
72.390007,44.055016,-157.062241,0.012038,0.003869,0.098274,195.966492,9.983009,0.982740,-157.062241,0.099089,0.000000
72.650002,44.576714,-157.106720,0.012038,0.003879,0.098534,198.287125,10.101228,0.985344,-157.106720,0.099523,0.000000
72.910004,45.517693,-157.062241,0.012046,0.003899,0.099029,202.472809,10.314457,0.990287,-157.062241,0.099957,0.000000
73.170006,46.625130,-157.062241,0.012064,0.003915,0.099453,207.398941,10.565406,0.994534,-157.062241,0.100391,0.000000
73.430000,47.572823,-157.106720,0.012051,0.003931,0.099836,211.614487,10.780155,0.998357,-157.106720,0.100824,0.000000
73.690002,48.259102,-157.017761,0.012072,0.003943,0.100148,214.667206,10.935669,1.001476,-157.017761,0.101257,0.000000
73.950005,49.195244,-157.151199,0.012085,0.003960,0.100572,218.831375,11.147801,1.005722,-157.151199,0.101691,0.000000
74.210007,51.467461,-157.106720,0.012089,0.003987,0.101266,228.938705,11.662693,1.012664,-157.106720,0.102116,0.000000
74.470001,52.667244,-157.151199,0.012098,0.004004,0.101691,234.275604,11.934568,1.016910,-157.151199,0.102549,0.000000
74.730003,53.424652,-157.106720,0.012115,0.004017,0.102021,237.644714,12.106199,1.020211,-157.106720,0.102983,0.000000
74.990005,53.913208,-157.151199,0.012107,0.004029,0.102333,239.817932,12.216908,1.023330,-157.151199,0.103417,0.000000
75.250000,55.544571,-157.151199,0.012124,0.004049,0.102845,247.074585,12.586579,1.028447,-157.151199,0.103851,0.000000
75.510002,56.586464,-157.106720,0.012120,0.004063,0.103200,251.709167,12.822676,1.032005,-157.106720,0.104284,0.000000
75.770004,57.274239,-157.106720,0.012137,0.004075,0.103504,254.768539,12.978528,1.035040,-157.106720,0.104717,0.000000
76.030006,59.273506,-157.151199,0.012141,0.004100,0.104128,263.661713,13.431568,1.041278,-157.151199,0.105151,0.000000
76.290001,60.217842,-157.151199,0.012146,0.004113,0.104458,267.862335,13.645558,1.044578,-157.151199,0.105585,0.000000
76.550003,61.329750,-157.151199,0.012158,0.004128,0.104839,272.808350,13.897520,1.048393,-157.151199,0.106019,0.000000
76.810005,62.803223,-157.240158,0.012158,0.004146,0.105308,279.362701,14.231414,1.053079,-157.240158,0.106452,0.000000
77.070007,64.689659,-157.106720,0.012167,0.004170,0.105914,287.753967,14.658886,1.059142,-157.106720,0.106886,0.000000
77.330002,66.101707,-157.106720,0.012176,0.004187,0.106348,294.035065,14.978861,1.063480,-157.106720,0.107319,0.000000
77.590004,66.951820,-157.195679,0.012184,0.004201,0.106704,297.816559,15.171499,1.067038,-157.195679,0.107753,0.000000
77.850006,67.355476,-157.240158,0.012202,0.004199,0.106661,299.612122,15.262969,1.066606,-157.240158,0.106903,0.000000
78.110001,66.803993,-157.195679,0.012189,0.004199,0.106661,297.158997,15.138001,1.066606,-157.195679,0.106903,0.000000
78.370003,66.405556,-157.195679,0.012206,0.004196,0.106591,295.386658,15.047713,1.065910,-157.195679,0.106661,0.000000
78.630005,66.017540,-157.240158,0.012206,0.004196,0.106574,293.660675,14.959788,1.065736,-157.240158,0.106661,0.000000
78.890007,65.672722,-157.151199,0.012206,0.004195,0.106565,292.126862,14.881652,1.065652,-157.151199,0.106661,0.000000
79.150002,65.362907,-157.240158,0.012219,0.004195,0.106556,290.748718,14.811446,1.065562,-157.240158,0.106661,0.000000
79.410004,65.081779,-157.240158,0.012202,0.004195,0.106548,289.498199,14.747742,1.065478,-157.240158,0.106661,0.000000
79.670006,64.824471,-157.195679,0.012223,0.004195,0.106548,288.353638,14.689435,1.065478,-157.195679,0.106661,0.000000
79.930000,64.622261,-157.284637,0.012210,0.004195,0.106548,287.454163,14.643614,1.065478,-157.284637,0.106661,0.000000
80.190002,64.413734,-157.195679,0.012210,0.004195,0.106548,286.526611,14.596360,1.065478,-157.195679,0.106661,0.000000
80.450005,64.237602,-157.284637,0.012215,0.004194,0.106539,285.743134,14.556449,1.065387,-157.284637,0.106661,0.000000
80.710007,64.050301,-157.284637,0.012215,0.004194,0.106539,284.909973,14.514006,1.065387,-157.284637,0.106661,0.000000
80.970001,63.906563,-157.240158,0.012219,0.004194,0.106539,284.270599,14.481434,1.065387,-157.240158,0.106661,0.000000
81.230003,63.749046,-157.329117,0.012215,0.004194,0.106539,283.569916,14.445741,1.065387,-157.329117,0.106661,0.000000
81.490005,63.612770,-157.284637,0.012219,0.004194,0.106539,282.963745,14.414859,1.065387,-157.284637,0.106661,0.000000
81.750008,63.495842,-157.373611,0.012227,0.004194,0.106539,282.443604,14.388363,1.065387,-157.373611,0.106661,0.000000
82.010002,63.351357,-157.284637,0.012206,0.004194,0.106539,281.800903,14.355623,1.065387,-157.284637,0.106661,0.000000
82.270004,63.240395,-157.329117,0.012227,0.004194,0.106539,281.307312,14.330479,1.065387,-157.329117,0.106661,0.000000
82.530006,63.126823,-157.329117,0.012236,0.004194,0.106539,280.802124,14.304743,1.065387,-157.329117,0.106661,0.000000
82.790001,63.023674,-157.329117,0.012223,0.004194,0.106539,280.343292,14.281368,1.065387,-157.329117,0.106661,0.000000
83.050003,62.917175,-157.373611,0.012223,0.004194,0.106539,279.869568,14.257236,1.065387,-157.373611,0.106661,0.000000
83.310005,62.821098,-157.284637,0.012223,0.004194,0.106539,279.442200,14.235465,1.065387,-157.284637,0.106661,0.000000
83.570007,62.732101,-157.284637,0.012223,0.004194,0.106539,279.046326,14.215298,1.065387,-157.284637,0.106661,0.000000
83.830002,62.646088,-157.373611,0.012240,0.004194,0.106539,278.663727,14.195807,1.065387,-157.373611,0.106661,0.000000
84.090004,62.563416,-157.329117,0.012227,0.004194,0.106539,278.295959,14.177073,1.065387,-157.329117,0.106661,0.000000
84.350006,62.496017,-157.418091,0.012227,0.004194,0.106539,277.996155,14.161799,1.065387,-157.418091,0.106661,0.000000
84.610001,62.405159,-157.373611,0.012227,0.004194,0.106539,277.592010,14.141212,1.065387,-157.373611,0.106661,0.000000
84.870003,62.340736,-157.373611,0.012227,0.004194,0.106539,277.305450,14.126613,1.065387,-157.373611,0.106661,0.000000
85.130005,62.267754,-157.462570,0.012240,0.004194,0.106539,276.980804,14.110074,1.065387,-157.462570,0.106661,0.000000
85.390007,62.204826,-157.373611,0.012232,0.004194,0.106539,276.700897,14.095815,1.065387,-157.373611,0.106661,0.000000
85.650002,62.135559,-157.329117,0.012232,0.004194,0.106539,276.392761,14.080119,1.065387,-157.329117,0.106661,0.000000
85.910004,62.069283,-157.462570,0.012215,0.004194,0.106539,276.097961,14.065101,1.065387,-157.462570,0.106661,0.000000
86.170006,62.016029,-157.373611,0.012227,0.004194,0.106539,275.861084,14.053033,1.065387,-157.373611,0.106661,0.000000
86.430000,61.953468,-157.418091,0.012215,0.004194,0.106539,275.582794,14.038857,1.065387,-157.418091,0.106661,0.000000
86.690002,61.899109,-157.373611,0.012219,0.004194,0.106530,275.340973,14.026539,1.065304,-157.373611,0.106661,0.000000
86.950005,61.830963,-157.462570,0.012236,0.004194,0.106530,275.037872,14.011096,1.065304,-157.462570,0.106661,0.000000
87.210007,61.771011,-157.507050,0.012227,0.004194,0.106530,274.771179,13.997511,1.065304,-157.507050,0.106661,0.000000
87.470001,61.736382,-157.462570,0.012232,0.004194,0.106530,274.617126,13.989664,1.065304,-157.462570,0.106661,0.000000
87.730003,61.687599,-157.462570,0.012219,0.004194,0.106530,274.400146,13.978610,1.065304,-157.462570,0.106661,0.000000
87.990005,61.637703,-157.418091,0.012227,0.004194,0.106530,274.178192,13.967302,1.065304,-157.418091,0.106661,0.000000
88.250008,61.578865,-157.418091,0.012240,0.004194,0.106530,273.916473,13.953970,1.065304,-157.418091,0.106661,0.000000
88.510002,61.536789,-157.507050,0.012227,0.004194,0.106530,273.729309,13.944436,1.065304,-157.507050,0.106661,0.000000
88.770004,61.506622,-157.418091,0.012227,0.004194,0.106530,273.595123,13.937600,1.065304,-157.418091,0.106661,0.000000
89.030006,61.455612,-157.507050,0.012227,0.004194,0.106530,273.368225,13.926041,1.065304,-157.507050,0.106661,0.000000
89.290001,61.400124,-157.507050,0.012236,0.004194,0.106530,273.121399,13.913466,1.065304,-157.507050,0.106661,0.000000
89.550003,61.363632,-157.507050,0.012240,0.004194,0.106530,272.959076,13.905197,1.065304,-157.507050,0.106661,0.000000
89.810005,61.331238,-157.507050,0.012227,0.004194,0.106530,272.814972,13.897858,1.065304,-157.507050,0.106661,0.000000
90.070007,61.291397,-157.507050,0.012232,0.004194,0.106530,272.637756,13.888829,1.065304,-157.507050,0.106661,0.000000
90.330002,61.248940,-157.507050,0.012236,0.004194,0.106530,272.448883,13.879208,1.065304,-157.507050,0.106661,0.000000
90.590004,61.208725,-157.462570,0.012227,0.004194,0.106530,272.270020,13.870095,1.065304,-157.462570,0.106661,0.000000
90.850006,61.184898,-157.507050,0.012232,0.004194,0.106530,272.164032,13.864696,1.065304,-157.507050,0.106661,0.000000
91.110001,61.147659,-157.551529,0.012232,0.004194,0.106530,271.998383,13.856257,1.065304,-157.551529,0.106661,0.000000
91.370003,61.104088,-157.507050,0.012232,0.004194,0.106530,271.804565,13.846384,1.065304,-157.507050,0.106661,0.000000
91.630005,61.066483,-157.551529,0.012232,0.004194,0.106530,271.637268,13.837863,1.065304,-157.551529,0.106661,0.000000
91.890007,61.050095,-157.596008,0.012227,0.004194,0.106530,271.564392,13.834148,1.065304,-157.596008,0.106661,0.000000
92.150002,61.020676,-157.507050,0.012240,0.004194,0.106530,271.433533,13.827482,1.065304,-157.507050,0.106661,0.000000
92.410004,60.967804,-157.551529,0.012227,0.004194,0.106530,271.198334,13.815501,1.065304,-157.551529,0.106661,0.000000
92.670006,60.953278,-157.507050,0.012232,0.004194,0.106530,271.133728,13.812210,1.065304,-157.507050,0.106661,0.000000
92.930008,60.922745,-157.551529,0.012240,0.004194,0.106530,270.997894,13.805291,1.065304,-157.551529,0.106661,0.000000
93.190002,60.891838,-157.640488,0.012240,0.004194,0.106530,270.860413,13.798288,1.065304,-157.640488,0.106661,0.000000
93.450005,60.856834,-157.640488,0.012240,0.004194,0.106530,270.704712,13.790356,1.065304,-157.640488,0.106661,0.000000
93.710007,60.834496,-157.640488,0.012236,0.004194,0.106530,270.605347,13.785295,1.065304,-157.640488,0.106661,0.000000
93.970001,60.821091,-157.640488,0.012240,0.004194,0.106530,270.545715,13.782256,1.065304,-157.640488,0.106661,0.000000
94.230003,60.783478,-157.640488,0.012240,0.004194,0.106530,270.378418,13.773733,1.065304,-157.640488,0.106661,0.000000
94.490005,60.753319,-157.551529,0.012240,0.004194,0.106530,270.244263,13.766898,1.065304,-157.551529,0.106661,0.000000
94.750008,60.730598,-157.596008,0.012240,0.004194,0.106530,270.143188,13.761750,1.065304,-157.596008,0.106661,0.000000
95.010002,60.713844,-157.640488,0.012232,0.004194,0.106530,270.068665,13.757954,1.065304,-157.640488,0.106661,0.000000
95.270004,60.698204,-157.640488,0.012236,0.004194,0.106530,269.999084,13.754410,1.065304,-157.640488,0.106661,0.000000
95.530006,60.654640,-157.640488,0.012240,0.004194,0.106530,269.805328,13.744537,1.065304,-157.640488,0.106661,0.000000
95.790001,60.646446,-157.684967,0.012240,0.004194,0.106530,269.768860,13.742681,1.065304,-157.684967,0.106661,0.000000
96.050003,60.628944,-157.640488,0.012240,0.004194,0.106530,269.691010,13.738715,1.065304,-157.640488,0.106661,0.000000
96.310005,60.596916,-157.729446,0.012232,0.004194,0.106530,269.548553,13.731458,1.065304,-157.729446,0.106661,0.000000
96.570007,60.568245,-157.640488,0.012240,0.004194,0.106530,269.421021,13.724961,1.065304,-157.640488,0.106661,0.000000
96.830002,60.538460,-157.684967,0.012249,0.004194,0.106530,269.288513,13.718211,1.065304,-157.684967,0.106661,0.000000
97.090004,60.541809,-157.684967,0.012236,0.004194,0.106530,269.303406,13.718970,1.065304,-157.684967,0.106661,0.000000
97.350006,60.503822,-157.684967,0.012245,0.004194,0.106530,269.134430,13.710361,1.065304,-157.684967,0.106661,0.000000
97.610008,60.475151,-157.729446,0.012236,0.004194,0.106530,269.006897,13.703865,1.065304,-157.729446,0.106661,0.000000
97.870003,60.460632,-157.729446,0.012240,0.004194,0.106530,268.942322,13.700576,1.065304,-157.729446,0.106661,0.000000
98.130005,60.444992,-157.729446,0.012245,0.004194,0.106530,268.872742,13.697031,1.065304,-157.729446,0.106661,0.000000
98.390007,60.404030,-157.729446,0.012232,0.004194,0.106530,268.690552,13.687749,1.065304,-157.729446,0.106661,0.000000
98.650002,60.385780,-157.684967,0.012253,0.004194,0.106530,268.609375,13.683614,1.065304,-157.684967,0.106661,0.000000
98.910004,60.385414,-157.729446,0.012236,0.004194,0.106530,268.607727,13.683531,1.065304,-157.729446,0.106661,0.000000
99.170006,60.355995,-157.684967,0.012249,0.004194,0.106530,268.476868,13.676865,1.065304,-157.684967,0.106661,0.000000
99.430008,60.345940,-157.684967,0.012245,0.004194,0.106530,268.432159,13.674585,1.065304,-157.684967,0.106661,0.000000
99.690002,60.311310,-157.729446,0.012236,0.004194,0.106530,268.278107,13.666739,1.065304,-157.729446,0.106661,0.000000
99.950005,60.307213,-157.773926,0.012245,0.004194,0.106530,268.259888,13.665810,1.065304,-157.773926,0.106661,0.000000
100.210007,60.279655,-157.773926,0.012245,0.004194,0.106530,268.137299,13.659566,1.065304,-157.773926,0.106661,0.000000
100.470001,60.243538,-157.773926,0.012240,0.004194,0.106530,267.976654,13.651381,1.065304,-157.773926,0.106661,0.000000
100.730003,60.251358,-157.818420,0.012240,0.004194,0.106530,268.011414,13.653152,1.065304,-157.818420,0.106661,0.000000
100.990005,60.210022,-157.773926,0.012249,0.004194,0.106530,267.827545,13.643786,1.065304,-157.773926,0.106661,0.000000
101.250008,60.205185,-157.862900,0.012245,0.004194,0.106530,267.806030,13.642690,1.065304,-157.862900,0.106661,0.000000
101.510002,60.161613,-157.773926,0.012232,0.004194,0.106530,267.612213,13.632817,1.065304,-157.773926,0.106661,0.000000
101.770004,60.174652,-157.773926,0.012232,0.004194,0.106530,267.670227,13.635771,1.065304,-157.773926,0.106661,0.000000
102.030006,60.148582,-157.862900,0.012240,0.004194,0.106530,267.554260,13.629864,1.065304,-157.862900,0.106661,0.000000
102.290009,60.116928,-157.818420,0.012236,0.004194,0.106530,267.413452,13.622691,1.065304,-157.818420,0.106661,0.000000
102.550003,60.106133,-157.773926,0.012249,0.004194,0.106530,267.365417,13.620244,1.065304,-157.773926,0.106661,0.000000
102.810005,60.083786,-157.862900,0.012249,0.004194,0.106530,267.266022,13.615180,1.065304,-157.862900,0.106661,0.000000
103.070007,60.077835,-157.862900,0.012240,0.004194,0.106530,267.239563,13.613832,1.065304,-157.862900,0.106661,0.000000
103.330002,60.037247,-157.862900,0.012245,0.004194,0.106530,267.059021,13.604634,1.065304,-157.862900,0.106661,0.000000
103.590004,60.037247,-157.862900,0.012245,0.004194,0.106530,267.059021,13.604634,1.065304,-157.862900,0.106661,0.000000
103.850006,60.020859,-157.818420,0.012253,0.004194,0.106530,266.986115,13.600921,1.065304,-157.818420,0.106661,0.000000
104.110008,59.998520,-157.907379,0.012240,0.004194,0.106530,266.886749,13.595859,1.065304,-157.907379,0.106661,0.000000
104.370003,59.981018,-157.862900,0.012240,0.004194,0.106530,266.808899,13.591893,1.065304,-157.862900,0.106661,0.000000
104.630005,59.952713,-157.907379,0.012245,0.004194,0.106530,266.682983,13.585480,1.065304,-157.907379,0.106661,0.000000
104.890007,59.944893,-157.907379,0.012245,0.004194,0.106530,266.648193,13.583707,1.065304,-157.907379,0.106661,0.000000
105.150002,59.915474,-157.862900,0.012249,0.004194,0.106530,266.517334,13.577040,1.065304,-157.862900,0.106661,0.000000
105.410004,59.894623,-157.951859,0.012240,0.004194,0.106530,266.424591,13.572315,1.065304,-157.951859,0.106661,0.000000
105.670006,59.884567,-157.862900,0.012245,0.004194,0.106530,266.379852,13.570037,1.065304,-157.862900,0.106661,0.000000
105.930008,59.876007,-157.907379,0.012249,0.004194,0.106530,266.341766,13.568097,1.065304,-157.907379,0.106661,0.000000
106.190002,59.843979,-157.996338,0.012232,0.004194,0.106530,266.199310,13.560840,1.065304,-157.996338,0.106661,0.000000
106.450005,59.816795,-157.951859,0.012245,0.004194,0.106530,266.078400,13.554680,1.065304,-157.951859,0.106661,0.000000
106.710007,59.806747,-157.951859,0.012232,0.004194,0.106530,266.033691,13.552402,1.065304,-157.951859,0.106661,0.000000
106.970009,59.792221,-157.951859,0.012249,0.004194,0.106530,265.969086,13.549111,1.065304,-157.951859,0.106661,0.000000
107.230003,59.765038,-157.907379,0.012240,0.004194,0.106530,265.848175,13.542952,1.065304,-157.907379,0.106661,0.000000
107.490005,59.741577,-157.951859,0.012245,0.004194,0.106530,265.743805,13.537635,1.065304,-157.951859,0.106661,0.000000
107.750008,59.747910,-157.951859,0.012245,0.004194,0.106530,265.771973,13.539069,1.065304,-157.951859,0.106661,0.000000
108.010002,59.723335,-157.996338,0.012245,0.004194,0.106530,265.662659,13.533501,1.065304,-157.996338,0.106661,0.000000
108.200005,59.717377,-157.907379,0.012245,0.004194,0.106530,265.636169,13.532151,1.065304,-157.907379,0.106661,0.000000