File: Data/AG AL compression 300N/AD membrane Peeled 300N_1_3_03202024_194850.csv
Time (sec),S:Load (lbs),S:HL1 (DIM),S:LVDT (in),S:Position (in),Ch:Position (mm),Ch:Load (N),Ch:Stress (MPa),Ch:Strain (mm/mm),Ch:HL1 (DIM),Set Point (),Cycles ()
0.010000,0.005219,-517.847229,0.000013,-0.000000,-0.000000,0.023213,0.001183,-0.000000,-517.847229,0.000182,0.000000
0.150000,0.002983,-517.847229,0.000009,-0.000000,-0.000000,0.013269,0.000676,-0.000000,-517.847229,0.000182,0.000000
0.290000,0.011177,-517.847229,0.000013,-0.000000,-0.000000,0.049718,0.002533,-0.000000,-517.847229,0.000182,0.000000
0.430000,0.007446,-517.758301,0.000013,0.000051,0.001292,0.033123,0.001687,0.012922,-517.758301,0.001778,0.000000
0.570000,0.006706,-517.891724,0.000009,0.000125,0.003165,0.029831,0.001520,0.031653,-517.891724,0.004119,0.000000
0.710000,-0.011543,-517.847229,0.000052,0.000209,0.005307,-0.051347,-0.002616,0.053072,-517.847229,0.006443,0.000000
0.850000,0.037239,-517.802734,0.000151,0.000310,0.007874,0.165648,0.008438,0.078745,-517.802734,0.008785,0.000000
0.990000,0.052879,-517.847229,0.000241,0.000389,0.009886,0.235219,0.011983,0.098861,-517.847229,0.011109,0.000000
1.130000,0.020859,-517.847229,0.000332,0.000487,0.012367,0.092784,0.004727,0.123668,-517.847229,0.013451,0.000000
1.270000,0.029793,-517.891724,0.000414,0.000581,0.014752,0.132525,0.006751,0.147516,-517.891724,0.015775,0.000000
1.410000,0.065536,-517.802734,0.000509,0.000665,0.016885,0.291521,0.014851,0.168848,-517.802734,0.018116,0.000000
1.550000,0.082672,-517.936218,0.000612,0.000761,0.019331,0.367744,0.018734,0.193306,-517.936218,0.020440,0.000000
1.690000,0.107986,-517.802734,0.000707,0.000853,0.021672,0.480348,0.024470,0.216719,-517.802734,0.022782,0.000000
1.830000,0.193260,-517.847229,0.000802,0.000947,0.024048,0.859664,0.043793,0.240481,-517.847229,0.025106,0.000000
1.970000,0.287476,-517.936218,0.000897,0.001030,0.026173,1.278755,0.065143,0.261729,-517.936218,0.027448,0.000000
2.110000,0.424133,-517.802734,0.000996,0.001128,0.028644,1.886639,0.096110,0.286445,-517.802734,0.029772,0.000000
2.250000,0.556702,-517.891724,0.001078,0.001214,0.030847,2.476333,0.126150,0.308473,-517.891724,0.032113,0.000000
2.390000,0.666550,-517.847229,0.001134,0.000002,0.000043,2.964961,0.151042,0.000431,-517.847229,0.000234,0.000000
2.530000,0.640480,-517.891724,0.001117,0.000002,0.000043,2.848998,0.145135,0.000431,-517.891724,0.000234,0.000000
2.670000,0.607712,-517.936218,0.001130,0.000001,0.000034,2.703237,0.137709,0.000344,-517.936218,0.000234,0.000000
2.810000,0.592445,-517.891724,0.001130,0.000001,0.000034,2.635329,0.134250,0.000344,-517.891724,0.000234,0.000000
2.950000,0.533981,-517.936218,0.001121,0.000001,0.000034,2.375268,0.121002,0.000344,-517.936218,0.000399,0.000000
3.090000,0.543297,-517.891724,0.001125,0.000001,0.000034,2.416705,0.123113,0.000344,-517.891724,0.000633,0.000000
3.230000,0.551117,-517.936218,0.001121,0.000001,0.000034,2.451491,0.124885,0.000344,-517.936218,0.000867,0.000000
3.370000,0.638992,-517.936218,0.001143,0.000012,0.000312,2.842380,0.144798,0.003119,-517.936218,0.001101,0.000000
3.510000,0.710861,-517.891724,0.001143,0.000017,0.000442,3.162069,0.161083,0.004421,-517.891724,0.001335,0.000000
3.650000,0.723518,-517.980652,0.001151,0.000023,0.000572,3.218370,0.163952,0.005723,-517.980652,0.001570,0.000000
3.790000,0.830765,-517.936218,0.001147,0.000033,0.000832,3.695426,0.188254,0.008323,-517.936218,0.001804,0.000000
3.930000,0.831512,-517.847229,0.001155,0.000038,0.000962,3.698752,0.188423,0.009625,-517.847229,0.002038,0.000000
4.070000,0.915291,-517.980652,0.001164,0.000057,0.001439,4.071417,0.207408,0.014394,-517.980652,0.002272,0.000000
4.210000,0.919388,-517.936218,0.001181,0.000065,0.001648,4.089641,0.208336,0.016476,-517.936218,0.002506,0.000000
4.350000,0.951416,-517.936218,0.001194,0.000073,0.001847,4.232110,0.215594,0.018470,-517.936218,0.002740,0.000000
4.490000,0.982323,-517.936218,0.001190,0.000081,0.002055,4.369590,0.222598,0.020552,-517.936218,0.002966,0.000000
4.630000,1.021423,-517.936218,0.001199,0.000090,0.002281,4.543518,0.231458,0.022808,-517.936218,0.003200,0.000000
4.770000,1.000198,-517.980652,0.001203,0.000097,0.002472,4.449104,0.226648,0.024715,-517.980652,0.003434,0.000000
4.910000,1.084351,-517.936218,0.001220,0.000107,0.002723,4.823432,0.245717,0.027229,-517.936218,0.003668,0.000000
5.050000,1.094406,-517.936218,0.001224,0.000114,0.002905,4.868162,0.247996,0.029049,-517.936218,0.003902,0.000000
5.190000,1.209839,-517.980652,0.001229,0.000127,0.003217,5.381632,0.274153,0.032172,-517.980652,0.004137,0.000000
5.330000,1.276123,-517.891724,0.001229,0.000136,0.003443,5.676479,0.289174,0.034427,-517.891724,0.004371,0.000000
5.470000,1.341286,-518.025146,0.001237,0.000147,0.003729,5.966337,0.303940,0.037289,-518.025146,0.004605,0.000000
5.610000,1.353577,-517.936218,0.001263,0.000152,0.003850,6.021010,0.306725,0.038504,-517.936218,0.004839,0.000000
5.750000,1.435127,-517.980652,0.001250,0.000160,0.004059,6.383765,0.325204,0.040585,-517.980652,0.005073,0.000000
5.890000,1.511459,-517.936218,0.001263,0.000171,0.004336,6.723307,0.342502,0.043360,-517.936218,0.005307,0.000000
6.030000,1.552422,-517.936218,0.001281,0.000182,0.004622,6.905516,0.351784,0.046221,-517.936218,0.005533,0.000000
6.170000,1.661156,-518.025146,0.001293,0.000194,0.004934,7.389190,0.376423,0.049344,-518.025146,0.005767,0.000000
6.310000,1.682755,-517.936218,0.001311,0.000202,0.005125,7.485266,0.381318,0.051251,-517.936218,0.006001,0.000000
6.450000,1.790367,-517.980652,0.001302,0.000210,0.005342,7.963951,0.405703,0.053420,-517.980652,0.006235,0.000000
6.590000,1.843620,-518.025146,0.001328,0.000221,0.005611,8.200832,0.417770,0.056107,-518.025146,0.006469,0.000000
6.730000,1.890533,-517.980652,0.001315,0.000228,0.005784,8.409513,0.428401,0.057841,-517.980652,0.006703,0.000000
6.870000,1.924797,-517.936218,0.001319,0.000235,0.005967,8.561925,0.436165,0.059665,-517.936218,0.006938,0.000000
7.010000,2.083054,-518.025146,0.001345,0.000246,0.006244,9.265885,0.472027,0.062439,-518.025146,0.007172,0.000000
7.150001,2.194763,-518.025146,0.001345,0.000257,0.006521,9.762794,0.497340,0.065214,-518.025146,0.007406,0.000000
7.290000,2.284508,-518.069641,0.001354,0.000265,0.006738,10.161998,0.517677,0.067382,-518.069641,0.007640,0.000000
7.430000,2.370895,-518.025146,0.001371,0.000272,0.006920,10.546269,0.537253,0.069203,-518.025146,0.007874,0.000000
7.570000,2.461014,-518.025146,0.001371,0.000281,0.007128,10.947136,0.557674,0.071285,-518.025146,0.008100,0.000000
7.710001,2.511658,-517.980652,0.001375,0.000288,0.007311,11.172412,0.569150,0.073105,-517.980652,0.008334,0.000000
7.850000,2.734703,-518.025146,0.001393,0.000302,0.007675,12.164567,0.619693,0.076746,-518.025146,0.008568,0.000000
7.990000,2.838226,-518.069641,0.001406,0.000314,0.007969,12.625061,0.643151,0.079695,-518.069641,0.008802,0.000000
8.130000,2.942863,-517.936218,0.001406,0.000323,0.008204,13.090510,0.666862,0.082038,-517.936218,0.009036,0.000000
8.270000,2.990524,-518.025146,0.001418,0.000329,0.008368,13.302516,0.677662,0.083684,-518.025146,0.009270,0.000000
8.410001,3.131653,-518.069641,0.001423,0.000339,0.008603,13.930287,0.709643,0.086027,-518.069641,0.009505,0.000000
8.550000,3.295128,-518.025146,0.001440,0.000348,0.008837,14.657461,0.746687,0.088370,-518.025146,0.009739,0.000000
8.690001,3.312630,-518.069641,0.001418,0.000355,0.009019,14.735312,0.750653,0.090190,-518.069641,0.009973,0.000000
8.830001,3.493973,-517.980652,0.001449,0.000364,0.009236,15.541967,0.791746,0.092359,-517.980652,0.010207,0.000000
8.970000,3.844002,-518.069641,0.001453,0.000379,0.009635,17.098974,0.871063,0.096348,-518.069641,0.010441,0.000000
9.110001,3.905441,-518.025146,0.001470,0.000388,0.009851,17.372271,0.884986,0.098513,-518.025146,0.010667,0.000000
9.250000,4.042107,-518.069641,0.001479,0.000396,0.010059,17.980188,0.915954,0.100595,-518.069641,0.010901,0.000000
9.390000,4.257706,-518.069641,0.001483,0.000406,0.010311,18.939220,0.964810,0.103112,-518.069641,0.011135,0.000000
9.530001,4.321388,-518.025146,0.001483,0.000411,0.010450,19.222494,0.979241,0.104497,-518.025146,0.011369,0.000000
9.670000,4.422295,-518.114136,0.001479,0.000418,0.010615,19.671349,1.002106,0.106147,-518.114136,0.011603,0.000000
9.810000,4.865417,-518.114136,0.001509,0.000435,0.011048,21.642458,1.102519,0.110481,-518.114136,0.011838,0.000000
9.950001,5.090332,-518.069641,0.001509,0.000446,0.011326,22.642927,1.153486,0.113259,-518.069641,0.012072,0.000000
10.090000,5.273544,-518.114136,0.001526,0.000455,0.011551,23.457897,1.195002,0.115511,-518.114136,0.012306,0.000000
10.230000,5.404617,-518.069641,0.001531,0.000462,0.011734,24.040939,1.224704,0.117336,-518.069641,0.012540,0.000000
10.370001,5.566223,-518.114136,0.001539,0.000469,0.011924,24.759798,1.261324,0.119243,-518.114136,0.012774,0.000000
10.510000,5.762093,-518.114136,0.001544,0.000478,0.012150,25.631067,1.305709,0.121495,-518.114136,0.013000,0.000000
10.650001,6.074516,-518.114136,0.001531,0.000489,0.012427,27.020798,1.376505,0.124273,-518.114136,0.013234,0.000000
10.790001,6.397362,-518.158569,0.001552,0.000501,0.012713,28.456886,1.449663,0.127135,-518.158569,0.013468,0.000000
10.930000,6.589134,-518.069641,0.001569,0.000510,0.012965,29.309933,1.493119,0.129648,-518.069641,0.013702,0.000000
11.070001,6.833778,-518.069641,0.001569,0.000519,0.013190,30.398165,1.548556,0.131904,-518.069641,0.013936,0.000000
11.210001,7.030022,-518.114136,0.001578,0.000526,0.013372,31.271099,1.593026,0.133724,-518.114136,0.014170,0.000000
11.350000,7.176361,-518.069641,0.001578,0.000533,0.013529,31.922049,1.626187,0.135287,-518.069641,0.014405,0.000000
11.490001,7.175247,-518.158569,0.001595,0.000534,0.013554,31.917093,1.625934,0.135545,-518.158569,0.014638,0.000000
11.630000,7.539803,-518.114136,0.001591,0.000543,0.013789,33.538715,1.708544,0.137888,-518.114136,0.014873,0.000000
11.770000,8.313591,-518.069641,0.001595,0.000561,0.014257,36.980701,1.883887,0.142569,-518.069641,0.015107,0.000000
11.910001,8.558983,-518.114136,0.001604,0.000573,0.014543,38.072258,1.939493,0.145431,-518.114136,0.015341,0.000000
12.050000,8.739960,-518.069641,0.001613,0.000579,0.014708,38.877281,1.980503,0.147081,-518.069641,0.015567,0.000000
12.190001,8.977905,-518.158569,0.001608,0.000588,0.014925,39.935719,2.034422,0.149246,-518.158569,0.015801,0.000000
12.330001,9.404640,-518.158569,0.001617,0.000599,0.015219,41.833927,2.131122,0.152194,-518.158569,0.016035,0.000000
12.470000,9.622482,-518.114136,0.001625,0.000607,0.015411,42.802940,2.180486,0.154106,-518.114136,0.016269,0.000000
12.610001,9.948303,-518.158569,0.001651,0.000616,0.015653,44.252262,2.254318,0.156532,-518.158569,0.016503,0.000000
12.750001,10.157578,-518.069641,0.001656,0.000624,0.015861,45.183163,2.301740,0.158614,-518.069641,0.016737,0.000000
12.890000,10.515800,-518.158569,0.001660,0.000633,0.016087,46.776615,2.382914,0.160869,-518.158569,0.016971,0.000000
13.030001,10.894875,-518.114136,0.001664,0.000642,0.016313,48.462822,2.468814,0.163125,-518.114136,0.017206,0.000000
13.170001,11.311188,-518.203064,0.001664,0.000653,0.016590,50.314674,2.563152,0.165900,-518.203064,0.017440,0.000000
13.310000,11.524185,-518.114136,0.001677,0.000659,0.016746,51.262135,2.611418,0.167459,-518.114136,0.017674,0.000000
13.450001,11.450829,-518.158569,0.001664,0.000660,0.016772,50.935829,2.594795,0.167720,-518.158569,0.017908,0.000000
13.590001,11.901772,-518.203064,0.001681,0.000674,0.017119,52.941723,2.696980,0.171187,-518.203064,0.018133,0.000000
13.730000,12.625290,-518.158569,0.001712,0.000687,0.017448,56.160095,2.860932,0.174484,-518.158569,0.018368,0.000000
13.870001,13.309708,-518.203064,0.001703,0.000702,0.017839,59.204536,3.016023,0.178386,-518.203064,0.018602,0.000000
14.010000,13.422539,-518.158569,0.001712,0.000708,0.017977,59.706436,3.041591,0.179775,-518.158569,0.018836,0.000000
14.150001,13.893593,-518.114136,0.001707,0.000720,0.018281,61.801788,3.148333,0.182810,-518.114136,0.019070,0.000000
14.290001,14.169144,-518.203064,0.001703,0.000728,0.018489,63.027500,3.210774,0.184892,-518.203064,0.019304,0.000000
14.430000,14.401878,-518.203064,0.001729,0.000733,0.018610,64.062752,3.263512,0.186103,-518.203064,0.019538,0.000000
14.570001,14.727707,-518.203064,0.001729,0.000742,0.018853,65.512115,3.337346,0.188533,-518.203064,0.019773,0.000000
14.710001,15.206573,-518.247559,0.001729,0.000751,0.019079,67.642220,3.445859,0.190789,-518.247559,0.020007,0.000000
14.850000,15.868652,-518.158569,0.001729,0.000764,0.019399,70.587288,3.595888,0.193995,-518.158569,0.020241,0.000000
14.990001,16.239166,-518.247559,0.001746,0.000774,0.019651,72.235420,3.679848,0.196512,-518.247559,0.020475,0.000000
15.130001,16.716171,-518.247559,0.001763,0.000783,0.019894,74.357246,3.787939,0.198942,-518.247559,0.020700,0.000000
15.270000,16.835709,-518.203064,0.001750,0.000788,0.020024,74.888969,3.815026,0.200240,-518.203064,0.020935,0.000000
15.410001,16.973854,-518.247559,0.001768,0.000793,0.020137,75.503471,3.846330,0.201368,-518.247559,0.021169,0.000000
15.550001,17.199883,-518.203064,0.001768,0.000801,0.020345,76.508896,3.897549,0.203449,-518.203064,0.021403,0.000000
15.690001,18.290939,-518.247559,0.001772,0.000816,0.020735,81.362160,4.144786,0.207352,-518.247559,0.021637,0.000000
15.830001,18.701294,-518.203064,0.001789,0.000826,0.020987,83.187508,4.237774,0.209869,-518.203064,0.021871,0.000000
15.970001,19.079994,-518.203064,0.001789,0.000836,0.021247,84.872055,4.323588,0.212469,-518.203064,0.022105,0.000000
16.110001,19.566315,-518.336548,0.001781,0.000846,0.021489,87.035316,4.433790,0.214895,-518.336548,0.022340,0.000000
16.250000,19.743187,-518.292053,0.001802,0.000854,0.021681,87.822083,4.473870,0.216806,-518.292053,0.022574,0.000000
16.390001,20.400055,-518.336548,0.001802,0.000864,0.021949,90.743973,4.622718,0.219494,-518.336548,0.022808,0.000000
16.530001,20.559433,-518.247559,0.001819,0.000870,0.022105,91.452927,4.658834,0.221053,-518.247559,0.023042,0.000000
16.670000,20.565018,-518.292053,0.001819,0.000872,0.022149,91.477768,4.660100,0.221488,-518.292053,0.023268,0.000000
16.810001,21.328377,-518.292053,0.001828,0.000889,0.022582,94.873360,4.833079,0.225822,-518.292053,0.023502,0.000000
16.950001,22.168449,-518.247559,0.001841,0.000900,0.022869,98.610191,5.023442,0.228687,-518.247559,0.023736,0.000000
17.090000,22.379585,-518.292053,0.001828,0.000907,0.023033,99.549370,5.071287,0.230334,-518.292053,0.023970,0.000000
17.230001,22.793289,-518.292053,0.001841,0.000915,0.023233,101.389610,5.165033,0.232328,-518.292053,0.024204,0.000000
17.370001,22.775047,-518.247559,0.001841,0.000915,0.023242,101.308472,5.160900,0.232415,-518.247559,0.024438,0.000000
17.510000,23.311264,-518.292053,0.001845,0.000929,0.023588,103.693680,5.282408,0.235882,-518.292053,0.024672,0.000000
17.650002,24.461525,-518.336548,0.001850,0.000944,0.023970,108.810295,5.543061,0.239701,-518.336548,0.024907,0.000000
17.790001,24.930336,-518.292053,0.001845,0.000954,0.024239,110.895676,5.649295,0.242388,-518.292053,0.025141,0.000000
17.930000,25.581993,-518.292053,0.001876,0.000966,0.024542,113.794388,5.796963,0.245424,-518.292053,0.025375,0.000000
18.070002,25.826263,-518.292053,0.001871,0.000974,0.024751,114.880959,5.852315,0.247506,-518.292053,0.025609,0.000000
18.210001,26.222847,-518.336548,0.001884,0.000982,0.024950,116.645050,5.942182,0.249500,-518.336548,0.025835,0.000000
18.350000,26.683098,-518.292053,0.001888,0.000991,0.025175,118.692345,6.046476,0.251752,-518.292053,0.026068,0.000000
18.490002,26.802254,-518.292053,0.001893,0.000996,0.025305,119.222382,6.073477,0.253054,-518.292053,0.026303,0.000000
18.630001,27.383530,-518.336548,0.001893,0.001008,0.025600,121.808022,6.205196,0.256003,-518.336548,0.026537,0.000000
18.770000,27.774895,-518.292053,0.001910,0.001015,0.025782,123.548904,6.293881,0.257823,-518.292053,0.026771,0.000000
18.910002,28.690186,-518.336548,0.001914,0.001027,0.026095,127.620316,6.501289,0.260946,-518.336548,0.027005,0.000000
19.050001,28.892380,-518.247559,0.001910,0.001034,0.026268,128.519730,6.547107,0.262679,-518.247559,0.027240,0.000000
19.190001,29.201080,-518.380981,0.001901,0.001041,0.026450,129.892899,6.617060,0.264504,-518.380981,0.027473,0.000000
19.330002,29.656860,-518.336548,0.001919,0.001049,0.026650,131.920303,6.720341,0.266498,-518.336548,0.027708,0.000000
19.470001,30.311119,-518.336548,0.001927,0.001063,0.026988,134.830597,6.868598,0.269878,-518.336548,0.027942,0.000000
19.610001,31.136299,-518.336548,0.001927,0.001074,0.027274,138.501175,7.055586,0.272740,-518.336548,0.028167,0.000000
19.750000,31.755554,-518.336548,0.001936,0.001084,0.027526,141.255753,7.195911,0.275256,-518.336548,0.028401,0.000000
19.890001,32.200539,-518.336548,0.001949,0.001093,0.027751,143.235153,7.296746,0.277512,-518.336548,0.028636,0.000000
20.030001,32.336082,-518.292053,0.001944,0.001100,0.027950,143.838074,7.327461,0.279503,-518.292053,0.028870,0.000000
20.170000,32.916985,-518.336548,0.001944,0.001110,0.028193,146.422058,7.459095,0.281933,-518.336548,0.029104,0.000000
20.310001,33.447983,-518.380981,0.001970,0.001119,0.028410,148.784058,7.579422,0.284102,-518.380981,0.029338,0.000000
20.450001,33.561562,-518.292053,0.001962,0.001122,0.028506,149.289276,7.605158,0.285056,-518.292053,0.029572,0.000000
20.590000,34.152145,-518.336548,0.001962,0.001133,0.028774,151.916336,7.738986,0.287743,-518.336548,0.029806,0.000000
20.730001,34.063148,-518.380981,0.001979,0.001138,0.028896,151.520447,7.718820,0.288958,-518.380981,0.030040,0.000000
20.870001,35.694138,-518.336548,0.001979,0.001157,0.029390,158.775452,8.088408,0.293901,-518.336548,0.030275,0.000000
21.010000,36.031509,-518.380981,0.001975,0.001165,0.029590,160.276154,8.164857,0.295896,-518.380981,0.030509,0.000000
21.150002,36.336105,-518.380981,0.002001,0.001170,0.029711,161.631073,8.233879,0.297110,-518.380981,0.030734,0.000000
21.290001,36.555435,-518.380981,0.001988,0.001177,0.029893,162.606689,8.283580,0.298931,-518.380981,0.030968,0.000000
21.430000,37.490837,-518.336548,0.002001,0.001192,0.030283,166.767578,8.495544,0.302833,-518.336548,0.031203,0.000000
21.570002,38.522308,-518.380981,0.002005,0.001206,0.030630,171.355789,8.729280,0.306304,-518.380981,0.031437,0.000000
21.710001,38.925209,-518.425476,0.002005,0.001213,0.030804,173.147980,8.820579,0.308037,-518.425476,0.031671,0.000000
21.850000,39.207840,-518.380981,0.002013,0.001221,0.031003,174.405182,8.884624,0.310032,-518.380981,0.031905,0.000000
21.990002,39.684479,-518.380981,0.002005,0.001229,0.031229,176.525375,8.992632,0.312288,-518.380981,0.032139,0.000000
22.130001,40.230751,-518.380981,0.002026,0.001240,0.031498,178.955322,9.116418,0.314975,-518.380981,0.032373,0.000000
22.270000,40.673874,-518.336548,0.002039,0.001247,0.031662,180.926422,9.216832,0.316622,-518.336548,0.032608,0.000000
22.410002,41.184395,-518.425476,0.002022,0.001256,0.031896,183.197342,9.332518,0.318964,-518.425476,0.032842,0.000000
22.550001,41.618584,-518.336548,0.002035,0.001265,0.032122,185.128708,9.430906,0.321220,-518.336548,0.033076,0.000000
22.690001,42.305984,-518.425476,0.002035,0.001275,0.032373,188.186417,9.586673,0.323733,-518.425476,0.033301,0.000000
22.830002,43.153130,-518.469971,0.002052,0.001285,0.032651,191.954712,9.778639,0.326508,-518.469971,0.033535,0.000000
22.970001,43.530342,-518.425476,0.002057,0.001293,0.032833,193.632629,9.864117,0.328328,-518.425476,0.033770,0.000000
23.110001,43.471512,-518.469971,0.002052,0.001295,0.032894,193.370941,9.850785,0.328938,-518.469971,0.034004,0.000000
23.250002,44.238220,-518.380981,0.002057,0.001307,0.033197,196.781433,10.024524,0.331973,-518.380981,0.034238,0.000000
23.390001,44.643738,-518.380981,0.002052,0.001317,0.033457,198.585266,10.116415,0.334573,-518.380981,0.034472,0.000000
23.530001,45.778358,-518.336548,0.002074,0.001330,0.033778,203.632309,10.373524,0.337783,-518.336548,0.034706,0.000000
23.670002,46.532410,-518.425476,0.002065,0.001340,0.034038,206.986496,10.544394,0.340383,-518.425476,0.034940,0.000000
23.810001,46.759926,-518.469971,0.002078,0.001344,0.034134,207.998535,10.595951,0.341337,-518.469971,0.035175,0.000000
23.950001,47.139008,-518.469971,0.002082,0.001354,0.034394,209.684784,10.681851,0.343941,-518.469971,0.035409,0.000000
24.090002,47.508400,-518.469971,0.002074,0.001358,0.034489,211.327911,10.765557,0.344895,-518.469971,0.035643,0.000000
24.230001,48.534660,-518.514465,0.002100,0.001374,0.034888,215.892944,10.998112,0.348884,-518.514465,0.035868,0.000000
24.370001,48.910378,-518.425476,0.002091,0.001381,0.035070,217.564224,11.083250,0.350705,-518.425476,0.036103,0.000000
24.510000,49.424629,-518.514465,0.002100,0.001386,0.035209,219.851730,11.199781,0.352094,-518.514465,0.036337,0.000000
24.650002,50.412155,-518.425476,0.002108,0.001404,0.035651,224.244461,11.423558,0.356514,-518.425476,0.036571,0.000000
24.790001,51.369156,-518.425476,0.002095,0.001412,0.035877,228.501419,11.640417,0.358770,-518.425476,0.036805,0.000000
24.930000,51.625351,-518.469971,0.002113,0.001419,0.036033,229.641037,11.698471,0.360330,-518.469971,0.037039,0.000000
25.070002,52.040543,-518.425476,0.002113,0.001426,0.036215,231.487900,11.792556,0.362150,-518.425476,0.037273,0.000000
25.210001,52.603943,-518.469971,0.002121,0.001434,0.036423,233.994019,11.920224,0.364232,-518.469971,0.037507,0.000000
25.350000,52.772255,-518.425476,0.002134,0.001440,0.036588,234.742706,11.958364,0.365882,-518.425476,0.037741,0.000000
25.490002,54.141838,-518.469971,0.002117,0.001456,0.036978,240.834930,12.268716,0.369784,-518.469971,0.037976,0.000000
25.630001,54.730560,-518.514465,0.002130,0.001464,0.037178,243.453690,12.402122,0.371779,-518.514465,0.038210,0.000000
25.770000,55.450356,-518.425476,0.002113,0.001475,0.037455,246.655502,12.565230,0.374553,-518.425476,0.038435,0.000000
25.910002,55.830551,-518.514465,0.002134,0.001481,0.037629,248.346695,12.651384,0.376287,-518.514465,0.038670,0.000000
26.050001,56.526138,-518.514465,0.002147,0.001492,0.037889,251.440826,12.809007,0.378891,-518.514465,0.038903,0.000000
26.190001,56.977829,-518.469971,0.002139,0.001496,0.038010,253.450043,12.911361,0.380102,-518.469971,0.039138,0.000000
26.330002,57.747894,-518.469971,0.002160,0.001508,0.038296,256.875458,13.085859,0.382963,-518.469971,0.039372,0.000000
26.470001,58.420029,-518.514465,0.002173,0.001517,0.038539,259.865265,13.238168,0.385393,-518.514465,0.039606,0.000000
26.610001,59.162537,-518.558899,0.002147,0.001527,0.038782,263.168121,13.406423,0.387823,-518.558899,0.039840,0.000000
26.750002,60.140762,-518.514465,0.002169,0.001538,0.039077,267.519470,13.628092,0.390771,-518.514465,0.040074,0.000000
26.890001,60.811401,-518.514465,0.002164,0.001546,0.039277,270.502625,13.780061,0.392766,-518.514465,0.040308,0.000000
27.030001,61.182663,-518.558899,0.002164,0.001553,0.039441,272.154083,13.864189,0.394413,-518.558899,0.040543,0.000000
27.170002,61.855537,-518.514465,0.002173,0.001562,0.039667,275.147186,14.016665,0.396668,-518.514465,0.040768,0.000000
27.310001,62.653160,-518.514465,0.002173,0.001573,0.039953,278.695160,14.197409,0.399530,-518.514465,0.041002,0.000000
27.450001,63.758736,-518.469971,0.002169,0.001586,0.040283,283.613007,14.447936,0.402826,-518.469971,0.041236,0.000000
27.590002,64.445381,-518.514465,0.002177,0.001593,0.040473,286.667358,14.603533,0.404734,-518.514465,0.041471,0.000000
27.730001,64.986824,-518.558899,0.002177,0.001602,0.040690,289.075836,14.726225,0.406899,-518.558899,0.041705,0.000000
27.870001,65.908440,-518.514465,0.002186,0.001615,0.041028,293.175385,14.935066,0.410283,-518.514465,0.041939,0.000000
28.010002,66.564552,-518.469971,0.002203,0.001621,0.041176,296.093903,15.083743,0.411759,-518.469971,0.042173,0.000000
28.150002,67.238930,-518.558899,0.002207,0.001631,0.041418,299.093689,15.236559,0.414185,-518.558899,0.042407,0.000000
28.290001,67.601982,-518.514465,0.002190,0.001627,0.041323,300.708649,15.318828,0.413231,-518.514465,0.041575,0.000000
28.430002,67.390480,-518.603394,0.002203,0.001627,0.041314,299.767822,15.270901,0.413144,-518.603394,0.041575,0.000000
28.570002,67.138008,-518.514465,0.002216,0.001627,0.041314,298.644775,15.213690,0.413144,-518.514465,0.041575,0.000000
28.710001,66.835640,-518.603394,0.002212,0.001626,0.041288,297.299774,15.145172,0.412883,-518.603394,0.041314,0.000000
28.850002,66.639030,-518.514465,0.002212,0.001625,0.041263,296.425201,15.100620,0.412625,-518.514465,0.041314,0.000000
28.990002,66.467735,-518.558899,0.002212,0.001624,0.041254,295.663239,15.061805,0.412538,-518.558899,0.041314,0.000000
29.130001,66.322884,-518.558899,0.002207,0.001624,0.041245,295.018921,15.028980,0.412451,-518.558899,0.041314,0.000000
29.270000,66.187340,-518.558899,0.002220,0.001624,0.041245,294.415985,14.998265,0.412451,-518.558899,0.041314,0.000000
29.410002,66.061852,-518.514465,0.002212,0.001623,0.041236,293.857788,14.969830,0.412364,-518.514465,0.041314,0.000000
29.550001,65.960564,-518.603394,0.002225,0.001623,0.041236,293.407227,14.946877,0.412364,-518.603394,0.041314,0.000000
29.690001,65.862633,-518.603394,0.002207,0.001623,0.041236,292.971619,14.924685,0.412364,-518.603394,0.041314,0.000000
29.830002,65.756142,-518.603394,0.002225,0.001623,0.041236,292.497925,14.900555,0.412364,-518.603394,0.041314,0.000000
29.970001,65.666771,-518.514465,0.002233,0.001623,0.041236,292.100372,14.880303,0.412364,-518.514465,0.041314,0.000000
30.110001,65.590797,-518.603394,0.002212,0.001623,0.041236,291.762451,14.863087,0.412364,-518.603394,0.041314,0.000000
30.250002,65.498833,-518.558899,0.002220,0.001623,0.041228,291.353363,14.842247,0.412277,-518.558899,0.041314,0.000000
30.390001,65.432167,-518.558899,0.002220,0.001623,0.041228,291.056824,14.827141,0.412277,-518.558899,0.041314,0.000000
30.530001,65.375572,-518.647888,0.002229,0.001623,0.041228,290.805084,14.814316,0.412277,-518.647888,0.041314,0.000000
30.670002,65.304817,-518.603394,0.002212,0.001623,0.041228,290.490326,14.798283,0.412277,-518.603394,0.041314,0.000000
30.810001,65.250084,-518.603394,0.002225,0.001623,0.041228,290.246857,14.785880,0.412277,-518.603394,0.041314,0.000000
30.950001,65.187904,-518.647888,0.002233,0.001623,0.041228,289.970276,14.771790,0.412277,-518.647888,0.041314,0.000000
31.090002,65.137260,-518.603394,0.002225,0.001623,0.041228,289.744995,14.760314,0.412277,-518.603394,0.041314,0.000000
31.230001,65.080650,-518.647888,0.002238,0.001623,0.041228,289.493195,14.747486,0.412277,-518.647888,0.041314,0.000000
31.370001,65.031868,-518.603394,0.002212,0.001623,0.041228,289.276184,14.736432,0.412277,-518.603394,0.041314,0.000000
31.510002,64.976768,-518.603394,0.002225,0.001623,0.041228,289.031097,14.723947,0.412277,-518.603394,0.041314,0.000000
31.650002,64.936546,-518.692383,0.002233,0.001623,0.041228,288.852173,14.714832,0.412277,-518.692383,0.041314,0.000000
31.790001,64.888145,-518.647888,0.002220,0.001623,0.041228,288.636871,14.703864,0.412277,-518.647888,0.041314,0.000000
31.930002,64.848671,-518.647888,0.002225,0.001623,0.041228,288.461304,14.694920,0.412277,-518.647888,0.041314,0.000000
32.070000,64.803230,-518.647888,0.002220,0.001623,0.041228,288.259155,14.684622,0.412277,-518.647888,0.041314,0.000000
32.210003,64.762276,-518.647888,0.002233,0.001623,0.041228,288.076996,14.675342,0.412277,-518.647888,0.041314,0.000000
32.350002,64.725410,-518.647888,0.002216,0.001623,0.041228,287.912994,14.666987,0.412277,-518.647888,0.041314,0.000000
32.490002,64.692268,-518.647888,0.002225,0.001623,0.041228,287.765594,14.659477,0.412277,-518.647888,0.041314,0.000000
32.630001,64.664345,-518.647888,0.002229,0.001623,0.041228,287.641357,14.653150,0.412277,-518.647888,0.041314,0.000000
32.770000,64.635292,-518.603394,0.002246,0.001623,0.041228,287.512146,14.646567,0.412277,-518.603394,0.041314,0.000000
32.910000,64.592842,-518.736877,0.002229,0.001623,0.041228,287.323303,14.636948,0.412277,-518.736877,0.041314,0.000000
33.050003,64.557838,-518.692383,0.002229,0.001623,0.041228,287.167603,14.629016,0.412277,-518.692383,0.041314,0.000000
33.190002,64.531029,-518.647888,0.002229,0.001623,0.041228,287.048340,14.622940,0.412277,-518.647888,0.041314,0.000000
33.330002,64.499016,-518.692383,0.002233,0.001623,0.041228,286.905945,14.615685,0.412277,-518.692383,0.041314,0.000000
33.470001,64.468102,-518.603394,0.002225,0.001623,0.041228,286.768433,14.608681,0.412277,-518.603394,0.041314,0.000000
33.610001,64.438316,-518.736877,0.002216,0.001623,0.041228,286.635956,14.601931,0.412277,-518.736877,0.041314,0.000000
33.750000,64.408150,-518.647888,0.002238,0.001623,0.041228,286.501770,14.595095,0.412277,-518.647888,0.041314,0.000000
33.890003,64.380974,-518.692383,0.002220,0.001623,0.041228,286.380859,14.588937,0.412277,-518.692383,0.041314,0.000000
34.030003,64.353783,-518.692383,0.002220,0.001623,0.041228,286.259918,14.582775,0.412277,-518.692383,0.041314,0.000000
34.170002,64.332191,-518.692383,0.002225,0.001623,0.041228,286.163879,14.577883,0.412277,-518.692383,0.041314,0.000000
34.310001,64.312080,-518.692383,0.002225,0.001623,0.041228,286.074432,14.573326,0.412277,-518.692383,0.041314,0.000000
34.450001,64.280052,-518.692383,0.002225,0.001623,0.041228,285.931946,14.566068,0.412277,-518.692383,0.041314,0.000000
34.590000,64.252495,-518.692383,0.002225,0.001623,0.041228,285.809357,14.559824,0.412277,-518.692383,0.041314,0.000000
34.730003,64.216011,-518.736877,0.002225,0.001623,0.041228,285.647095,14.551556,0.412277,-518.736877,0.041314,0.000000
34.870003,64.194405,-518.692383,0.002225,0.001623,0.041228,285.550964,14.546659,0.412277,-518.692383,0.041314,0.000000
35.010002,64.166847,-518.692383,0.002233,0.001623,0.041228,285.428406,14.540416,0.412277,-518.692383,0.041314,0.000000
35.150002,64.141533,-518.781311,0.002238,0.001623,0.041228,285.315796,14.534679,0.412277,-518.781311,0.041314,0.000000
35.290001,64.122536,-518.647888,0.002225,0.001623,0.041228,285.231293,14.530375,0.412277,-518.647888,0.041314,0.000000
35.430000,64.090141,-518.736877,0.002233,0.001623,0.041228,285.087189,14.523033,0.412277,-518.736877,0.041314,0.000000
35.570004,64.083809,-518.692383,0.002229,0.001623,0.041228,285.059021,14.521599,0.412277,-518.692383,0.041314,0.000000
35.710003,64.061104,-518.736877,0.002220,0.001623,0.041228,284.958008,14.516454,0.412277,-518.736877,0.041314,0.000000
35.850002,64.032799,-518.781311,0.002229,0.001623,0.041228,284.832123,14.510039,0.412277,-518.781311,0.041314,0.000000
35.990002,64.019020,-518.736877,0.002229,0.001623,0.041228,284.770813,14.506917,0.412277,-518.736877,0.041314,0.000000
36.130001,63.991463,-518.781311,0.002225,0.001623,0.041228,284.648254,14.500672,0.412277,-518.781311,0.041314,0.000000
36.270000,63.963905,-518.736877,0.002238,0.001623,0.041228,284.525665,14.494429,0.412277,-518.736877,0.041314,0.000000
36.410000,63.952736,-518.736877,0.002242,0.001623,0.041228,284.475983,14.491897,0.412277,-518.736877,0.041314,0.000000
36.550003,63.929649,-518.781311,0.002225,0.001623,0.041228,284.373291,14.486665,0.412277,-518.781311,0.041314,0.000000
36.690002,63.916618,-518.692383,0.002225,0.001623,0.041228,284.315308,14.483713,0.412277,-518.692383,0.041314,0.000000
36.830002,63.898750,-518.736877,0.002229,0.001623,0.041228,284.235840,14.479664,0.412277,-518.736877,0.041314,0.000000
36.970001,63.874168,-518.781311,0.002238,0.001623,0.041228,284.126495,14.474093,0.412277,-518.781311,0.041314,0.000000
37.110001,63.856300,-518.736877,0.002233,0.001623,0.041228,284.046997,14.470044,0.412277,-518.736877,0.041314,0.000000
37.250000,63.834328,-518.825806,0.002246,0.001623,0.041228,283.949280,14.465066,0.412277,-518.825806,0.041314,0.000000
37.390003,63.809746,-518.736877,0.002229,0.001623,0.041228,283.839935,14.459496,0.412277,-518.736877,0.041314,0.000000
37.530003,63.797462,-518.781311,0.002229,0.001623,0.041228,283.785278,14.456712,0.412277,-518.781311,0.041314,0.000000
37.670002,63.782936,-518.736877,0.002233,0.001623,0.041228,283.720673,14.453420,0.412277,-518.736877,0.041314,0.000000
37.810001,63.755379,-518.781311,0.002233,0.001623,0.041228,283.598083,14.447175,0.412277,-518.781311,0.041314,0.000000
37.950001,63.749428,-518.825806,0.002220,0.001623,0.041228,283.571625,14.445827,0.412277,-518.825806,0.041314,0.000000
38.090000,63.724846,-518.736877,0.002233,0.001623,0.041228,283.462280,14.440256,0.412277,-518.736877,0.041314,0.000000
38.230003,63.697670,-518.781311,0.002242,0.001623,0.041228,283.341400,14.434098,0.412277,-518.781311,0.041314,0.000000
38.370003,63.701012,-518.825806,0.002238,0.001623,0.041228,283.356262,14.434855,0.412277,-518.825806,0.041314,0.000000
38.510002,63.687981,-518.781311,0.002225,0.001623,0.041228,283.298279,14.431902,0.412277,-518.781311,0.041314,0.000000
38.650002,63.674950,-518.870300,0.002233,0.001623,0.041228,283.240326,14.428950,0.412277,-518.870300,0.041314,0.000000
38.790001,63.663399,-518.825806,0.002246,0.001623,0.041228,283.188934,14.426332,0.412277,-518.825806,0.041314,0.000000
38.930000,63.639946,-518.825806,0.002233,0.001623,0.041228,283.084625,14.421019,0.412277,-518.825806,0.041314,0.000000
39.070004,63.624672,-518.870300,0.002229,0.001623,0.041228,283.016663,14.417557,0.412277,-518.870300,0.041314,0.000000
39.210003,63.606438,-518.825806,0.002212,0.001623,0.041228,282.935577,14.413424,0.412277,-518.825806,0.041314,0.000000
39.350002,63.582970,-518.959229,0.002220,0.001623,0.041228,282.831177,14.408107,0.412277,-518.959229,0.041314,0.000000
39.490002,63.583717,-518.825806,0.002238,0.001623,0.041228,282.834503,14.408277,0.412277,-518.825806,0.041314,0.000000
39.630001,63.550941,-518.825806,0.002229,0.001623,0.041228,282.688721,14.400848,0.412277,-518.825806,0.041314,0.000000
39.770000,63.544991,-518.870300,0.002246,0.001623,0.041228,282.662231,14.399501,0.412277,-518.870300,0.041314,0.000000
39.910004,63.535683,-518.870300,0.002242,0.001623,0.041219,282.620819,14.397391,0.412190,-518.870300,0.041314,0.000000
40.050003,63.524513,-518.914795,0.002238,0.001623,0.041219,282.571136,14.394860,0.412190,-518.914795,0.041314,0.000000
40.190002,63.500313,-518.870300,0.002229,0.001623,0.041219,282.463501,14.389377,0.412190,-518.870300,0.041314,0.000000
40.330002,63.503288,-518.870300,0.002238,0.001623,0.041219,282.476746,14.390051,0.412190,-518.870300,0.041314,0.000000
40.470001,63.481316,-518.914795,0.002238,0.001623,0.041219,282.378998,14.385072,0.412190,-518.914795,0.041314,0.000000
40.610001,63.478706,-518.870300,0.002216,0.001623,0.041219,282.367401,14.384480,0.412190,-518.870300,0.041314,0.000000
40.750004,63.454872,-518.959229,0.002229,0.001623,0.041219,282.261383,14.379080,0.412190,-518.959229,0.041314,0.000000
40.890003,63.444817,-518.914795,0.002233,0.001623,0.041219,282.216644,14.376801,0.412190,-518.914795,0.041314,0.000000
41.030003,63.442955,-518.914795,0.002229,0.001623,0.041219,282.208344,14.376379,0.412190,-518.914795,0.041314,0.000000
41.170002,63.427315,-518.914795,0.002233,0.001623,0.041219,282.138794,14.372834,0.412190,-518.914795,0.041314,0.000000
41.310001,63.429924,-518.870300,0.002246,0.001623,0.041219,282.150391,14.373426,0.412190,-518.870300,0.041314,0.000000
41.450001,63.414665,-518.914795,0.002233,0.001623,0.041219,282.082520,14.369968,0.412190,-518.914795,0.041314,0.000000
41.590000,63.404976,-518.914795,0.002233,0.001623,0.041219,282.039429,14.367772,0.412190,-518.914795,0.041314,0.000000
41.730003,63.396782,-518.959229,0.002238,0.001623,0.041219,282.002960,14.365916,0.412190,-518.959229,0.041314,0.000000
41.870003,63.382271,-518.959229,0.002233,0.001623,0.041219,281.938416,14.362628,0.412190,-518.959229,0.041314,0.000000
42.010002,63.378532,-518.870300,0.002238,0.001623,0.041219,281.921783,14.361781,0.412190,-518.870300,0.041314,0.000000
42.150002,63.360664,-518.914795,0.002233,0.001623,0.041219,281.842316,14.357732,0.412190,-518.914795,0.041314,0.000000
42.290001,63.349861,-518.914795,0.002251,0.001623,0.041219,281.794250,14.355284,0.412190,-518.914795,0.041314,0.000000
42.430000,63.352104,-519.003723,0.002233,0.001623,0.041219,281.804230,14.355792,0.412190,-519.003723,0.041314,0.000000
42.570004,63.339073,-519.003723,0.002242,0.001623,0.041219,281.746277,14.352839,0.412190,-519.003723,0.041314,0.000000
42.710003,63.315987,-518.914795,0.002233,0.001623,0.041219,281.643585,14.347608,0.412190,-518.914795,0.041314,0.000000
42.850002,63.311882,-519.003723,0.002242,0.001623,0.041219,281.625305,14.346678,0.412190,-519.003723,0.041314,0.000000
42.990002,63.307411,-518.870300,0.002238,0.001623,0.041219,281.605438,14.345665,0.412190,-518.870300,0.041314,0.000000
43.130001,63.293266,-518.914795,0.002229,0.001623,0.041219,281.542511,14.342459,0.412190,-518.914795,0.041314,0.000000
43.270000,63.290657,-519.003723,0.002233,0.001623,0.041219,281.530914,14.341868,0.412190,-519.003723,0.041314,0.000000
43.410004,63.287315,-518.914795,0.002238,0.001623,0.041219,281.516052,14.341111,0.412190,-518.914795,0.041314,0.000000
43.550003,63.272789,-518.959229,0.002233,0.001623,0.041219,281.451416,14.337819,0.412190,-518.959229,0.041314,0.000000
43.690002,63.267204,-518.959229,0.002229,0.001623,0.041219,281.426575,14.336554,0.412190,-518.959229,0.041314,0.000000
43.830002,63.262733,-518.914795,0.002225,0.001623,0.041219,281.406708,14.335541,0.412190,-518.914795,0.041314,0.000000
43.970001,63.255287,-519.003723,0.002242,0.001623,0.041219,281.373566,14.333853,0.412190,-519.003723,0.041314,0.000000
44.110001,63.244865,-518.914795,0.002242,0.001623,0.041219,281.327209,14.331491,0.412190,-518.914795,0.041314,0.000000
44.250004,63.226982,-519.003723,0.002225,0.001623,0.041219,281.247650,14.327439,0.412190,-519.003723,0.041314,0.000000
44.390003,63.217308,-518.959229,0.002246,0.001623,0.041219,281.204620,14.325246,0.412190,-518.959229,0.041314,0.000000
44.530003,63.199806,-518.914795,0.002242,0.001623,0.041219,281.126770,14.321280,0.412190,-518.914795,0.041314,0.000000
44.670002,63.196083,-518.959229,0.002246,0.001623,0.041219,281.110229,14.320437,0.412190,-518.959229,0.041314,0.000000
44.810001,63.184166,-519.048218,0.002229,0.001623,0.041219,281.057220,14.317737,0.412190,-519.048218,0.041314,0.000000
44.950001,63.177834,-519.003723,0.002225,0.001623,0.041219,281.029053,14.316301,0.412190,-519.003723,0.041314,0.000000
45.090004,63.183052,-519.003723,0.002242,0.001623,0.041219,281.052246,14.317484,0.412190,-519.003723,0.041314,0.000000
45.230003,63.171135,-518.959229,0.002246,0.001623,0.041219,280.999237,14.314783,0.412190,-518.959229,0.041314,0.000000
45.370003,63.164421,-519.003723,0.002242,0.001623,0.041219,280.969391,14.313262,0.412190,-519.003723,0.041314,0.000000
45.510002,63.149529,-518.959229,0.002242,0.001623,0.041219,280.903137,14.309888,0.412190,-518.959229,0.041314,0.000000
45.650002,63.135384,-519.048218,0.002238,0.001623,0.041219,280.840210,14.306683,0.412190,-519.048218,0.041314,0.000000
45.790001,63.135002,-519.048218,0.002251,0.001623,0.041219,280.838501,14.306596,0.412190,-519.048218,0.041314,0.000000
45.930000,63.124580,-519.003723,0.002229,0.001623,0.041219,280.792145,14.304235,0.412190,-519.003723,0.041314,0.000000
46.070004,63.112297,-519.092712,0.002233,0.001623,0.041219,280.737518,14.301451,0.412190,-519.092712,0.041314,0.000000
46.210003,63.099632,-519.048218,0.002238,0.001623,0.041219,280.681183,14.298581,0.412190,-519.048218,0.041314,0.000000
46.350002,63.094048,-519.003723,0.002233,0.001623,0.041219,280.656342,14.297316,0.412190,-519.003723,0.041314,0.000000
46.490002,63.086601,-519.003723,0.002242,0.001623,0.041219,280.623230,14.295629,0.412190,-519.003723,0.041314,0.000000
46.630001,63.070595,-519.003723,0.002238,0.001623,0.041219,280.552032,14.292001,0.412190,-519.003723,0.041314,0.000000
46.770000,63.069466,-519.048218,0.002238,0.001623,0.041219,280.546997,14.291745,0.412190,-519.048218,0.041314,0.000000
46.910004,63.061272,-519.003723,0.002233,0.001623,0.041219,280.510559,14.289889,0.412190,-519.003723,0.041314,0.000000
47.050003,63.049370,-519.003723,0.002238,0.001623,0.041219,280.457611,14.287191,0.412190,-519.003723,0.041314,0.000000
47.190002,63.041542,-519.048218,0.002242,0.001623,0.041219,280.422791,14.285418,0.412190,-519.048218,0.041314,0.000000
47.330002,63.046761,-519.003723,0.002246,0.001623,0.041219,280.445984,14.286600,0.412190,-519.003723,0.041314,0.000000
47.470001,63.026649,-519.092712,0.002233,0.001623,0.041219,280.356537,14.282043,0.412190,-519.092712,0.041314,0.000000
47.610001,63.024040,-519.003723,0.002238,0.001623,0.041219,280.344940,14.281451,0.412190,-519.003723,0.041314,0.000000
47.750004,63.017342,-519.092712,0.002233,0.001623,0.041219,280.315125,14.279933,0.412190,-519.092712,0.041314,0.000000
47.890003,63.018829,-519.137207,0.002242,0.001623,0.041219,280.321747,14.280272,0.412190,-519.137207,0.041314,0.000000
48.030003,62.994995,-519.048218,0.002251,0.001623,0.041219,280.215729,14.274870,0.412190,-519.048218,0.041314,0.000000
48.170002,63.005424,-519.048218,0.002233,0.001623,0.041219,280.262115,14.277233,0.412190,-519.048218,0.041314,0.000000
48.310001,62.993507,-519.048218,0.002233,0.001623,0.041219,280.209106,14.274532,0.412190,-519.048218,0.041314,0.000000
48.450001,62.985313,-519.092712,0.002220,0.001623,0.041219,280.172668,14.272676,0.412190,-519.092712,0.041314,0.000000
48.590004,62.962227,-519.092712,0.002238,0.001623,0.041219,280.069977,14.267445,0.412190,-519.092712,0.041314,0.000000
48.730003,62.974892,-519.092712,0.002238,0.001623,0.041219,280.126312,14.270315,0.412190,-519.092712,0.041314,0.000000
48.870003,62.959991,-519.181641,0.002242,0.001623,0.041219,280.060028,14.266937,0.412190,-519.181641,0.041314,0.000000
49.010002,62.973030,-519.048218,0.002238,0.001623,0.041219,280.118042,14.269893,0.412190,-519.048218,0.041314,0.000000
49.150002,62.957016,-519.092712,0.002233,0.001623,0.041219,280.046783,14.266264,0.412190,-519.092712,0.041314,0.000000
49.290001,62.961113,-519.137207,0.002246,0.001623,0.041219,280.065033,14.267192,0.412190,-519.137207,0.041314,0.000000
49.430004,62.953667,-519.048218,0.002242,0.001623,0.041219,280.031891,14.265505,0.412190,-519.048218,0.041314,0.000000
49.570004,62.939888,-519.137207,0.002238,0.001623,0.041219,279.970612,14.262383,0.412190,-519.137207,0.041314,0.000000
49.710003,62.933556,-519.137207,0.002251,0.001623,0.041219,279.942444,14.260947,0.412190,-519.137207,0.041314,0.000000
49.850002,62.933182,-519.092712,0.002229,0.001623,0.041219,279.940765,14.260863,0.412190,-519.092712,0.041314,0.000000
49.990002,62.924988,-519.137207,0.002246,0.001623,0.041219,279.904327,14.259006,0.412190,-519.137207,0.041314,0.000000
50.130001,62.915306,-519.092712,0.002246,0.001623,0.041219,279.861267,14.256812,0.412190,-519.092712,0.041314,0.000000
50.270004,62.914192,-519.137207,0.002242,0.001623,0.041219,279.856293,14.256560,0.412190,-519.137207,0.041314,0.000000
50.410004,62.901901,-519.092712,0.002238,0.001623,0.041219,279.801636,14.253775,0.412190,-519.092712,0.041314,0.000000
50.550003,62.899300,-519.137207,0.002246,0.001623,0.041219,279.790070,14.253184,0.412190,-519.137207,0.041314,0.000000
50.690002,62.898926,-519.181641,0.002238,0.001623,0.041219,279.788391,14.253100,0.412190,-519.181641,0.041314,0.000000
50.830002,62.881798,-519.092712,0.002233,0.001623,0.041219,279.712219,14.249219,0.412190,-519.092712,0.041314,0.000000
50.970001,62.882164,-519.092712,0.002242,0.001623,0.041219,279.713837,14.249302,0.412190,-519.092712,0.041314,0.000000
51.110001,62.883659,-519.137207,0.002242,0.001623,0.041219,279.720490,14.249640,0.412190,-519.137207,0.041314,0.000000
51.250004,62.873978,-519.137207,0.002246,0.001623,0.041219,279.677429,14.247447,0.412190,-519.137207,0.041314,0.000000
51.390003,62.875092,-519.181641,0.002238,0.001623,0.041219,279.682373,14.247700,0.412190,-519.181641,0.041314,0.000000
51.530003,62.872116,-519.137207,0.002251,0.001623,0.041219,279.669128,14.247025,0.412190,-519.137207,0.041314,0.000000
51.670002,62.868019,-519.226135,0.002242,0.001623,0.041219,279.650909,14.246098,0.412190,-519.226135,0.041314,0.000000
51.810001,62.852379,-519.137207,0.002242,0.001623,0.041219,279.581329,14.242553,0.412190,-519.137207,0.041314,0.000000
51.950001,62.844185,-519.137207,0.002225,0.001623,0.041219,279.544891,14.240696,0.412190,-519.137207,0.041314,0.000000
52.090004,62.842323,-519.270630,0.002229,0.001623,0.041219,279.536621,14.240274,0.412190,-519.270630,0.041314,0.000000
52.230003,62.830406,-519.092712,0.002251,0.001623,0.041219,279.483612,14.237574,0.412190,-519.092712,0.041314,0.000000
52.370003,62.832268,-519.181641,0.002233,0.001623,0.041219,279.491882,14.237996,0.412190,-519.181641,0.041314,0.000000
52.510002,62.825195,-519.181641,0.002238,0.001623,0.041219,279.460419,14.236392,0.412190,-519.181641,0.041314,0.000000
52.650002,62.818123,-519.181641,0.002251,0.001623,0.041219,279.428955,14.234790,0.412190,-519.181641,0.041314,0.000000
52.790001,62.806206,-519.226135,0.002233,0.001623,0.041219,279.375946,14.232090,0.412190,-519.226135,0.041314,0.000000
52.930004,62.798386,-519.181641,0.002238,0.001623,0.041219,279.341156,14.230318,0.412190,-519.181641,0.041314,0.000000
53.070004,62.803596,-519.226135,0.002246,0.001623,0.041219,279.364349,14.231498,0.412190,-519.226135,0.041314,0.000000
53.210003,62.797264,-519.181641,0.002242,0.001623,0.041219,279.336182,14.230063,0.412190,-519.181641,0.041314,0.000000
53.350002,62.800621,-519.226135,0.002229,0.001623,0.041219,279.351105,14.230824,0.412190,-519.226135,0.041314,0.000000
53.490002,62.802109,-519.270630,0.002246,0.001623,0.041219,279.357727,14.231161,0.412190,-519.270630,0.041314,0.000000
53.630001,62.795029,-519.137207,0.002238,0.001623,0.041219,279.326233,14.229557,0.412190,-519.137207,0.041314,0.000000
53.770004,62.792427,-519.226135,0.002233,0.001623,0.041219,279.314667,14.228967,0.412190,-519.226135,0.041314,0.000000
53.910004,62.789078,-519.270630,0.002233,0.001623,0.041219,279.299774,14.228209,0.412190,-519.270630,0.041314,0.000000
54.050003,62.789444,-519.181641,0.002238,0.001623,0.041219,279.301392,14.228292,0.412190,-519.181641,0.041314,0.000000
54.190002,62.774551,-519.226135,0.002242,0.001623,0.041219,279.235138,14.224916,0.412190,-519.226135,0.041314,0.000000
54.330002,62.765617,-519.226135,0.002246,0.001623,0.041219,279.195404,14.222892,0.412190,-519.226135,0.041314,0.000000
54.470001,62.756676,-519.226135,0.002220,0.001623,0.041219,279.155640,14.220865,0.412190,-519.226135,0.041314,0.000000
54.610004,62.764870,-519.226135,0.002246,0.001623,0.041219,279.192078,14.222723,0.412190,-519.226135,0.041314,0.000000
54.750004,62.751091,-519.226135,0.002246,0.001623,0.041219,279.130798,14.219600,0.412190,-519.226135,0.041314,0.000000
54.890003,62.757050,-519.315125,0.002233,0.001623,0.041219,279.157288,14.220951,0.412190,-519.315125,0.041314,0.000000
55.030003,62.742897,-519.270630,0.002251,0.001623,0.041219,279.094330,14.217744,0.412190,-519.270630,0.041314,0.000000
55.170002,62.740295,-519.226135,0.002246,0.001623,0.041219,279.082764,14.217155,0.412190,-519.226135,0.041314,0.000000
55.310001,62.746620,-519.315125,0.002255,0.001623,0.041219,279.110901,14.218587,0.412190,-519.315125,0.041314,0.000000
55.450001,62.741409,-519.226135,0.002246,0.001623,0.041219,279.087738,14.217406,0.412190,-519.226135,0.041314,0.000000
55.590004,62.734337,-519.226135,0.002229,0.001623,0.041219,279.056274,14.215804,0.412190,-519.226135,0.041314,0.000000
55.730003,62.730614,-519.270630,0.002255,0.001623,0.041219,279.039703,14.214960,0.412190,-519.270630,0.041314,0.000000
55.870003,62.724281,-519.315125,0.002242,0.001623,0.041219,279.011536,14.213526,0.412190,-519.315125,0.041314,0.000000
56.010002,62.720932,-519.315125,0.002233,0.001623,0.041219,278.996643,14.212767,0.412190,-519.315125,0.041314,0.000000
56.150002,62.723534,-519.226135,0.002229,0.001623,0.041219,279.008209,14.213356,0.412190,-519.226135,0.041314,0.000000
56.290001,62.717583,-519.315125,0.002229,0.001623,0.041219,278.981750,14.212008,0.412190,-519.315125,0.041314,0.000000
56.430004,62.709015,-519.270630,0.002238,0.001623,0.041219,278.943634,14.210066,0.412190,-519.270630,0.041314,0.000000
56.570004,62.707527,-519.270630,0.002242,0.001623,0.041219,278.937012,14.209729,0.412190,-519.270630,0.041314,0.000000
56.710003,62.695984,-519.270630,0.002242,0.001623,0.041219,278.885651,14.207112,0.412190,-519.270630,0.041314,0.000000
56.850002,62.688164,-519.315125,0.002233,0.001623,0.041219,278.850891,14.205340,0.412190,-519.315125,0.041314,0.000000
56.990002,62.681458,-519.359558,0.002233,0.001623,0.041219,278.821045,14.203821,0.412190,-519.359558,0.041314,0.000000
57.130001,62.686668,-519.226135,0.002233,0.001623,0.041219,278.844238,14.205002,0.412190,-519.226135,0.041314,0.000000
57.270004,62.679222,-519.315125,0.002238,0.001623,0.041219,278.811096,14.203314,0.412190,-519.315125,0.041314,0.000000
57.410004,62.683693,-519.359558,0.002238,0.001623,0.041219,278.830994,14.204328,0.412190,-519.359558,0.041314,0.000000
57.550003,62.663582,-519.270630,0.002233,0.001623,0.041219,278.741547,14.199771,0.412190,-519.270630,0.041314,0.000000
57.690002,62.666191,-519.359558,0.002238,0.001623,0.041219,278.753143,14.200362,0.412190,-519.359558,0.041314,0.000000
57.830002,62.667305,-519.270630,0.002238,0.001623,0.041219,278.758087,14.200614,0.412190,-519.270630,0.041314,0.000000
57.970001,62.676247,-519.315125,0.002238,0.001623,0.041219,278.797882,14.202641,0.412190,-519.315125,0.041314,0.000000
58.110004,62.666565,-519.315125,0.002233,0.001623,0.041219,278.754791,14.200446,0.412190,-519.315125,0.041314,0.000000
58.250004,62.656883,-519.270630,0.002242,0.001623,0.041219,278.711731,14.198253,0.412190,-519.270630,0.041314,0.000000
58.390003,62.644592,-519.404053,0.002238,0.001623,0.041219,278.657074,14.195468,0.412190,-519.404053,0.041314,0.000000
58.530003,62.641243,-519.359558,0.002238,0.001623,0.041219,278.642151,14.194709,0.412190,-519.359558,0.041314,0.000000
58.670002,62.638634,-519.359558,0.002238,0.001623,0.041219,278.630554,14.194117,0.412190,-519.359558,0.041314,0.000000
58.700005,62.640869,-519.315125,0.002238,0.001623,0.041219,278.640503,14.194624,0.412190,-519.315125,0.041314,0.000000