File: Data/AG AL compression 300N/AD membrane Unpeeled 300N_1_2_03202024_210204.csv
Time (sec),S:Load (lbs),S:HL1 (DIM),S:LVDT (in),S:Position (in),Ch:Position (mm),Ch:Load (N),Ch:Stress (MPa),Ch:Strain (mm/mm),Ch:HL1 (DIM),Set Point (),Cycles ()
0.010000,0.001488,-618.907959,-0.000009,-0.000000,-0.000000,0.006618,0.000337,-0.000000,-618.907959,0.000208,0.000000
0.150000,0.000374,-618.863464,0.000009,-0.000000,-0.000000,0.001663,0.000085,-0.000000,-618.863464,0.000208,0.000000
0.290000,0.004837,-618.774536,0.000000,-0.000000,-0.000000,0.021516,0.001096,-0.000000,-618.774536,0.000208,0.000000
0.430000,-0.018990,-618.907959,0.000009,0.000055,0.001405,-0.084470,-0.004303,0.014050,-618.907959,0.001873,0.000000
0.570000,-0.004471,-618.818970,-0.000004,0.000129,0.003287,-0.019887,-0.001013,0.032868,-618.818970,0.004197,0.000000
0.710000,-0.058838,-618.907959,0.000078,0.000216,0.005498,-0.261724,-0.013333,0.054983,-618.907959,0.006539,0.000000
0.850000,-0.033516,-618.818970,0.000164,0.000314,0.007979,-0.149086,-0.007595,0.079786,-618.818970,0.008863,0.000000
0.990000,-0.001122,-618.863464,0.000250,0.000397,0.010077,-0.004989,-0.000254,0.100773,-618.863464,0.011187,0.000000
1.130000,-0.032768,-618.952454,0.000362,0.000492,0.012488,-0.145760,-0.007425,0.124883,-618.952454,0.013529,0.000000
1.270000,-0.025322,-618.907959,0.000448,0.000583,0.014803,-0.112638,-0.005738,0.148035,-618.907959,0.015853,0.000000
1.410000,0.010056,-618.907959,0.000517,0.000673,0.017093,0.044729,0.002279,0.170930,-618.907959,0.018194,0.000000
1.550000,0.002235,-618.907959,0.000625,0.000765,0.019426,0.009944,0.000507,0.194260,-618.907959,0.020519,0.000000
1.690000,-0.031281,-618.907959,0.000729,0.000858,0.021793,-0.139143,-0.007088,0.217934,-618.907959,0.022860,0.000000
1.830000,0.021973,-618.907959,0.000811,0.000952,0.024178,0.097739,0.004979,0.241783,-618.907959,0.025184,0.000000
1.970000,0.002609,-618.863464,0.000910,0.001038,0.026364,0.011607,0.000591,0.263637,-618.863464,0.027526,0.000000
2.110000,0.000374,-618.863464,0.001000,0.001136,0.028861,0.001663,0.000085,0.288613,-618.863464,0.029850,0.000000
2.250000,-0.037613,-618.863464,0.001087,0.001226,0.031151,-0.167311,-0.008523,0.311508,-618.863464,0.032191,0.000000
2.390000,-0.000000,-618.863464,0.001177,0.001318,0.033475,-0.000000,-0.000000,0.334751,-618.863464,0.034516,0.000000
2.530000,-0.001488,-618.952454,0.001276,0.001406,0.035704,-0.006618,-0.000337,0.357037,-618.952454,0.036857,0.000000
2.670000,-0.036118,-618.863464,0.001367,0.001499,0.038062,-0.160659,-0.008184,0.380624,-618.863464,0.039181,0.000000
2.810000,-0.029045,-618.952454,0.001466,0.001597,0.040569,-0.129199,-0.006582,0.405688,-618.952454,0.041523,0.000000
2.950000,-0.009308,-618.863464,0.001574,0.001684,0.042780,-0.041403,-0.002109,0.427803,-618.863464,0.043847,0.000000
3.090000,-0.004471,-618.863464,0.001634,0.001779,0.045183,-0.019887,-0.001013,0.451826,-618.863464,0.046189,0.000000
3.230000,-0.063301,-618.952454,0.001733,0.001871,0.047515,-0.281577,-0.014344,0.475152,-618.952454,0.048513,0.000000
3.370000,0.018616,-618.907959,0.001824,0.001960,0.049796,0.082807,0.004218,0.497960,-618.907959,0.050854,0.000000
3.510000,0.043564,-618.863464,0.001914,0.002047,0.051999,0.193782,0.009872,0.519988,-618.863464,0.053178,0.000000
3.650000,0.004097,-618.952454,0.002018,0.002143,0.054445,0.018224,0.000928,0.544446,-618.952454,0.055502,0.000000
3.790000,-0.014153,-618.952454,0.002126,0.002236,0.056795,-0.062954,-0.003207,0.567946,-618.952454,0.057844,0.000000
3.930000,0.047287,-618.996887,0.002195,0.002327,0.059102,0.210343,0.010715,0.591015,-618.996887,0.060168,0.000000
4.070000,0.012657,-618.863464,0.002315,0.002421,0.061486,0.056302,0.002868,0.614864,-618.863464,0.062510,0.000000
4.210000,0.020111,-618.996887,0.002393,0.002511,0.063785,0.089459,0.004557,0.637846,-618.996887,0.064834,0.000000
4.350000,0.035004,-618.907959,0.002501,0.002607,0.066213,0.155704,0.007932,0.662126,-618.907959,0.067175,0.000000
4.490000,0.045059,-618.952454,0.002565,0.002686,0.068216,0.200433,0.010211,0.682159,-618.952454,0.069499,0.000000
4.630000,0.064423,-618.952454,0.002669,0.002786,0.070774,0.286566,0.014598,0.707741,-618.952454,0.071841,0.000000
4.770000,0.084526,-618.952454,0.002759,0.002879,0.073116,0.375991,0.019154,0.731158,-618.952454,0.074165,0.000000
4.910000,0.310928,-619.041382,0.002854,0.002976,0.075587,1.383078,0.070457,0.755874,-619.041382,0.076507,0.000000
5.050000,0.771927,-618.952454,0.002958,0.000016,0.000416,3.433702,0.174921,0.004163,-618.952454,0.000512,0.000000
5.190000,0.652023,-618.907959,0.002940,0.000011,0.000286,2.900345,0.147751,0.002861,-618.907959,0.000512,0.000000
5.330000,0.676231,-618.996887,0.002945,0.000011,0.000286,3.008027,0.153236,0.002861,-618.996887,0.000512,0.000000
5.470000,0.659843,-618.952454,0.002958,0.000011,0.000286,2.935130,0.149523,0.002861,-618.952454,0.000512,0.000000
5.610000,0.642715,-618.996887,0.002949,0.000011,0.000286,2.858941,0.145641,0.002861,-618.996887,0.000607,0.000000
5.750000,0.672134,-618.907959,0.002945,0.000011,0.000286,2.989803,0.152308,0.002861,-618.907959,0.000832,0.000000
5.890000,0.679581,-618.907959,0.002940,0.000012,0.000295,3.022926,0.153995,0.002948,-618.907959,0.001067,0.000000
6.030000,0.716446,-619.041382,0.002940,0.000020,0.000512,3.186911,0.162349,0.005117,-619.041382,0.001301,0.000000
6.170000,0.770813,-618.996887,0.002953,0.000026,0.000668,3.428747,0.174669,0.006677,-618.996887,0.001535,0.000000
6.310000,0.844170,-618.952454,0.002949,0.000033,0.000850,3.755054,0.191292,0.008497,-618.952454,0.001769,0.000000
6.450000,0.935402,-618.952454,0.002962,0.000044,0.001110,4.160875,0.211965,0.011101,-618.952454,0.002003,0.000000
6.590000,1.030357,-618.907959,0.002966,0.000055,0.001388,4.583259,0.233482,0.013875,-618.907959,0.002237,0.000000
6.730000,1.171112,-618.952454,0.002971,0.000068,0.001717,5.209367,0.265378,0.017172,-618.952454,0.002472,0.000000
6.870000,1.282074,-618.952454,0.002997,0.000078,0.001977,5.702950,0.290522,0.019772,-618.952454,0.002706,0.000000
7.010000,1.357300,-619.041382,0.002997,0.000086,0.002177,6.037571,0.307569,0.021767,-619.041382,0.002940,0.000000
7.150001,1.372566,-618.952454,0.003027,0.000089,0.002255,6.105480,0.311028,0.022547,-618.952454,0.003174,0.000000
7.290000,1.551674,-618.996887,0.003005,0.000104,0.002636,6.902190,0.351614,0.026362,-618.996887,0.003400,0.000000
7.430000,1.637321,-619.041382,0.003022,0.000111,0.002827,7.283170,0.371022,0.028269,-619.041382,0.003633,0.000000
7.570000,1.751266,-618.996887,0.003027,0.000119,0.003018,7.790022,0.396843,0.030181,-618.996887,0.003868,0.000000
7.710001,1.912880,-619.041382,0.003022,0.000129,0.003287,8.508915,0.433465,0.032868,-619.041382,0.004102,0.000000
7.850000,2.105766,-618.952454,0.003048,0.000139,0.003538,9.366917,0.477173,0.035381,-618.952454,0.004336,0.000000
7.990000,2.227531,-618.996887,0.003061,0.000147,0.003746,9.908555,0.504766,0.037463,-618.996887,0.004570,0.000000
8.130000,2.379456,-619.041382,0.003057,0.000154,0.003920,10.584347,0.539192,0.039196,-619.041382,0.004805,0.000000
8.270000,2.517982,-618.952454,0.003070,0.000162,0.004111,11.200545,0.570583,0.041108,-618.952454,0.005038,0.000000
8.410001,2.749222,-619.041382,0.003087,0.000177,0.004492,12.229150,0.622983,0.044923,-619.041382,0.005273,0.000000
8.550000,2.956635,-618.996887,0.003091,0.000189,0.004813,13.151767,0.669983,0.048129,-618.996887,0.005507,0.000000
8.690001,3.186020,-618.996887,0.003096,0.000200,0.005073,14.172124,0.721962,0.050733,-618.996887,0.005741,0.000000
8.830001,3.369972,-618.996887,0.003113,0.000208,0.005290,14.990385,0.763647,0.052901,-618.996887,0.005967,0.000000
8.970000,3.482796,-618.996887,0.003122,0.000214,0.005446,15.492249,0.789213,0.054461,-618.996887,0.006201,0.000000
9.110001,3.606056,-619.041382,0.003113,0.000223,0.005654,16.040539,0.817144,0.056543,-619.041382,0.006435,0.000000
9.250000,3.833572,-619.041382,0.003139,0.000233,0.005906,17.052582,0.868700,0.059056,-619.041382,0.006669,0.000000
9.390000,4.014915,-618.996887,0.003117,0.000240,0.006105,17.859236,0.909793,0.061050,-618.996887,0.006903,0.000000
9.530001,4.218605,-618.996887,0.003152,0.000247,0.006279,18.765293,0.955950,0.062788,-618.996887,0.007137,0.000000
9.670000,4.395859,-618.996887,0.003147,0.000256,0.006496,19.553757,0.996116,0.064956,-618.996887,0.007371,0.000000
9.810000,4.690773,-619.085876,0.003152,0.000266,0.006747,20.865601,1.062944,0.067470,-619.085876,0.007605,0.000000
9.950001,4.897446,-619.041382,0.003182,0.000272,0.006920,21.784925,1.109777,0.069203,-619.041382,0.007840,0.000000
10.090000,4.982346,-618.996887,0.003160,0.000278,0.007059,22.162580,1.129016,0.070592,-618.996887,0.008074,0.000000
10.230000,5.213211,-619.085876,0.003160,0.000286,0.007267,23.189522,1.181331,0.072674,-619.085876,0.008299,0.000000
10.370001,5.535690,-619.041382,0.003182,0.000298,0.007562,24.623980,1.254405,0.075622,-619.041382,0.008533,0.000000
10.510000,5.914391,-619.130371,0.003178,0.000309,0.007848,26.308523,1.340220,0.078484,-619.130371,0.008768,0.000000
10.650001,6.284157,-619.085876,0.003191,0.000322,0.008178,27.953325,1.424010,0.081780,-619.085876,0.009002,0.000000
10.790001,6.590248,-619.041382,0.003208,0.000332,0.008429,29.314888,1.493372,0.084293,-619.041382,0.009236,0.000000
10.930000,6.806221,-619.085876,0.003221,0.000340,0.008629,30.275583,1.542312,0.086288,-619.085876,0.009470,0.000000
11.070001,6.949959,-618.996887,0.003212,0.000347,0.008802,30.914961,1.574883,0.088022,-618.996887,0.009704,0.000000
11.210001,7.396431,-619.130371,0.003221,0.000358,0.009097,32.900967,1.676055,0.090970,-619.130371,0.009938,0.000000
11.350000,7.624329,-619.041382,0.003242,0.000365,0.009271,33.914707,1.727697,0.092707,-619.041382,0.010173,0.000000
11.490001,7.761360,-619.085876,0.003234,0.000371,0.009427,34.524254,1.758749,0.094267,-619.085876,0.010407,0.000000
11.630000,8.030952,-619.085876,0.003251,0.000378,0.009609,35.723461,1.819840,0.096087,-619.085876,0.010641,0.000000
11.770000,8.550041,-619.085876,0.003247,0.000391,0.009938,38.032482,1.937467,0.099384,-619.085876,0.010866,0.000000
11.910001,8.847939,-619.085876,0.003255,0.000401,0.010181,39.357597,2.004972,0.101810,-619.085876,0.011100,0.000000
12.050000,9.192017,-619.041382,0.003268,0.000409,0.010389,40.888130,2.082941,0.103892,-619.041382,0.011335,0.000000
12.190001,9.440384,-619.130371,0.003255,0.000416,0.010554,41.992924,2.139221,0.105542,-619.130371,0.011569,0.000000
12.330001,9.826912,-619.085876,0.003281,0.000427,0.010840,43.712288,2.226810,0.108403,-619.085876,0.011803,0.000000
12.470000,10.432388,-619.041382,0.003277,0.000442,0.011239,46.405582,2.364013,0.112392,-619.041382,0.012037,0.000000
12.610001,10.872902,-619.130371,0.003285,0.000453,0.011499,48.365082,2.463835,0.114993,-619.130371,0.012271,0.000000
12.750001,11.150696,-619.085876,0.003303,0.000460,0.011690,49.600773,2.526784,0.116900,-619.085876,0.012505,0.000000
12.890000,11.424011,-619.130371,0.003298,0.000468,0.011898,50.816540,2.588718,0.118982,-619.130371,0.012740,0.000000
13.030001,11.754684,-619.085876,0.003324,0.000477,0.012106,52.287449,2.663650,0.121064,-619.085876,0.012973,0.000000
13.170001,12.201157,-619.085876,0.003320,0.000488,0.012384,54.273457,2.764822,0.123838,-619.085876,0.013208,0.000000
13.310000,12.438728,-619.174866,0.003324,0.000493,0.012514,55.330227,2.818656,0.125140,-619.174866,0.013433,0.000000
13.450001,12.810356,-619.085876,0.003341,0.000504,0.012791,56.983311,2.902868,0.127914,-619.085876,0.013667,0.000000
13.590001,13.332794,-619.085876,0.003341,0.000514,0.013052,59.307232,3.021254,0.130518,-619.085876,0.013902,0.000000
13.730000,13.454559,-619.130371,0.003337,0.000518,0.013156,59.848869,3.048847,0.131559,-619.130371,0.014136,0.000000
13.870001,13.895821,-619.130371,0.003350,0.000528,0.013416,61.811699,3.148838,0.134159,-619.130371,0.014370,0.000000
14.010000,14.315117,-619.219299,0.003346,0.000536,0.013624,63.676819,3.243852,0.136241,-619.219299,0.014604,0.000000
14.150001,14.608170,-619.174866,0.003359,0.000543,0.013780,64.980385,3.310259,0.137800,-619.174866,0.014838,0.000000
14.290001,15.086296,-619.130371,0.003372,0.000557,0.014145,67.107193,3.418604,0.141445,-619.130371,0.015072,0.000000
14.430000,15.739807,-619.130371,0.003380,0.000569,0.014448,70.014160,3.566691,0.144481,-619.130371,0.015306,0.000000
14.570001,16.314011,-619.085876,0.003372,0.000580,0.014734,72.568344,3.696808,0.147342,-619.085876,0.015541,0.000000
14.710001,16.727715,-619.219299,0.003385,0.000590,0.014977,74.408592,3.790554,0.149768,-619.219299,0.015775,0.000000
14.850000,16.972366,-619.174866,0.003389,0.000597,0.015168,75.496857,3.845993,0.151676,-619.174866,0.016000,0.000000
14.990001,17.244194,-619.174866,0.003397,0.000605,0.015367,76.706009,3.907590,0.153671,-619.174866,0.016235,0.000000
15.130001,17.580818,-619.174866,0.003415,0.000615,0.015610,78.203384,3.983870,0.156100,-619.174866,0.016468,0.000000
15.270000,18.333382,-619.130371,0.003415,0.000627,0.015931,81.550957,4.154404,0.159310,-619.130371,0.016703,0.000000
15.410001,18.546753,-619.174866,0.003406,0.000632,0.016061,82.500076,4.202754,0.160608,-619.174866,0.016937,0.000000
15.550001,19.110527,-619.219299,0.003419,0.000643,0.016339,85.007874,4.330507,0.163386,-619.219299,0.017171,0.000000
15.690001,19.414757,-619.174866,0.003419,0.000650,0.016521,86.361153,4.399447,0.165207,-619.174866,0.017405,0.000000
15.830001,19.854156,-619.219299,0.003449,0.000659,0.016746,88.315697,4.499016,0.167459,-619.219299,0.017639,0.000000
15.970001,19.960281,-619.174866,0.003436,0.000662,0.016816,88.787766,4.523064,0.168155,-619.174866,0.017873,0.000000
16.110001,20.535599,-619.174866,0.003441,0.000674,0.017110,91.346909,4.653433,0.171104,-619.174866,0.018108,0.000000
16.250000,21.291885,-619.174866,0.003449,0.000688,0.017466,94.711037,4.824811,0.174658,-619.174866,0.018342,0.000000
16.390001,21.955078,-619.219299,0.003458,0.000700,0.017787,97.661064,4.975092,0.177867,-619.219299,0.018567,0.000000
16.530001,22.329315,-619.263794,0.003475,0.000709,0.018012,99.325752,5.059895,0.180123,-619.263794,0.018801,0.000000
16.670000,22.659981,-619.130371,0.003479,0.000717,0.018203,100.796631,5.134825,0.182031,-619.130371,0.019035,0.000000
16.810001,22.927345,-619.219299,0.003479,0.000725,0.018403,101.985924,5.195411,0.184025,-619.219299,0.019270,0.000000
16.950001,23.461700,-619.219299,0.003501,0.000735,0.018671,104.362854,5.316497,0.186713,-619.219299,0.019504,0.000000
17.090000,24.038132,-619.308289,0.003492,0.000745,0.018914,106.926949,5.447118,0.189143,-619.308289,0.019738,0.000000
17.230001,24.356880,-619.263794,0.003497,0.000751,0.019070,108.344810,5.519348,0.190702,-619.263794,0.019972,0.000000
17.370001,24.814156,-619.263794,0.003510,0.000760,0.019304,110.378876,5.622968,0.193045,-619.263794,0.020206,0.000000
17.510000,25.295258,-619.219299,0.003510,0.000770,0.019556,112.518929,5.731987,0.195558,-619.219299,0.020440,0.000000
17.650002,25.997185,-619.263794,0.003514,0.000784,0.019903,115.641251,5.891047,0.199029,-619.263794,0.020675,0.000000
17.790001,26.194916,-619.263794,0.003514,0.000788,0.020016,116.520805,5.935853,0.200157,-619.263794,0.020909,0.000000
17.930000,26.355034,-619.263794,0.003527,0.000795,0.020189,117.233047,5.972136,0.201890,-619.263794,0.021134,0.000000
18.070002,26.818634,-619.174866,0.003540,0.000801,0.020336,119.295242,6.077189,0.203362,-619.174866,0.021368,0.000000
18.210001,27.113930,-619.263794,0.003523,0.000811,0.020597,120.608780,6.144104,0.205966,-619.263794,0.021603,0.000000
18.350000,28.426170,-619.263794,0.003557,0.000828,0.021030,126.445923,6.441462,0.210300,-619.263794,0.021837,0.000000
18.490002,28.530807,-619.263794,0.003544,0.000834,0.021195,126.911369,6.465173,0.211950,-619.263794,0.022071,0.000000
18.630001,29.023827,-619.308289,0.003566,0.000842,0.021394,129.104431,6.576893,0.213945,-619.308289,0.022305,0.000000
18.770000,29.562653,-619.263794,0.003570,0.000854,0.021681,131.501251,6.698993,0.216806,-619.263794,0.022539,0.000000
18.910002,30.208344,-619.308289,0.003566,0.000864,0.021941,134.373428,6.845309,0.219407,-619.308289,0.022773,0.000000
19.050001,30.524490,-619.174866,0.003574,0.000872,0.022149,135.779709,6.916948,0.221488,-619.174866,0.023008,0.000000
19.190001,30.922554,-619.308289,0.003566,0.000880,0.022348,137.550385,7.007151,0.223483,-619.308289,0.023242,0.000000
19.330002,31.570480,-619.308289,0.003596,0.000892,0.022652,140.432510,7.153973,0.226518,-619.308289,0.023467,0.000000
19.470001,31.959236,-619.263794,0.003596,0.000900,0.022860,142.161789,7.242067,0.228600,-619.263794,0.023701,0.000000
19.610001,32.335335,-619.308289,0.003587,0.000908,0.023051,143.834747,7.327291,0.230508,-619.308289,0.023935,0.000000
19.750000,32.672707,-619.308289,0.003604,0.000913,0.023181,145.335464,7.403741,0.231810,-619.308289,0.024170,0.000000
19.890001,33.024223,-619.263794,0.003600,0.000922,0.023407,146.899078,7.483396,0.234065,-619.263794,0.024403,0.000000
20.030001,33.369415,-619.308289,0.003613,0.000928,0.023562,148.434570,7.561618,0.235625,-619.308289,0.024638,0.000000
20.170000,33.647202,-619.219299,0.003617,0.000937,0.023788,149.670227,7.624565,0.237881,-619.219299,0.024872,0.000000
20.310001,35.195900,-619.397217,0.003626,0.000957,0.024308,156.559189,7.975505,0.243081,-619.397217,0.025106,0.000000
20.450001,35.616684,-619.308289,0.003617,0.000964,0.024491,158.430923,8.070856,0.244905,-619.308289,0.025340,0.000000
20.590000,36.049004,-619.352783,0.003617,0.000974,0.024733,160.353973,8.168821,0.247332,-619.352783,0.025575,0.000000
20.730001,36.248596,-619.308289,0.003648,0.000981,0.024915,161.241806,8.214049,0.249152,-619.308289,0.025808,0.000000
20.870001,36.900620,-619.352783,0.003635,0.000993,0.025210,164.142151,8.361800,0.252100,-619.352783,0.026034,0.000000
21.010000,37.477798,-619.308289,0.003660,0.001002,0.025462,166.709579,8.492591,0.254617,-619.308289,0.026268,0.000000
21.150002,37.884804,-619.263794,0.003660,0.001010,0.025644,168.520020,8.584819,0.256438,-619.263794,0.026502,0.000000
21.290001,38.368141,-619.352783,0.003656,0.001019,0.025895,170.670013,8.694345,0.258951,-619.352783,0.026736,0.000000
21.430000,38.593056,-619.352783,0.003682,0.001024,0.026017,171.670486,8.745311,0.260166,-619.352783,0.026971,0.000000
21.570002,38.911057,-619.352783,0.003652,0.001030,0.026173,173.085022,8.817372,0.261729,-619.352783,0.027205,0.000000
21.710001,39.368332,-619.352783,0.003678,0.001040,0.026416,175.119080,8.920992,0.264155,-619.352783,0.027439,0.000000
21.850000,39.557869,-619.308289,0.003673,0.001043,0.026502,175.962189,8.963941,0.265022,-619.308289,0.027673,0.000000
21.990002,40.261658,-619.397217,0.003678,0.001055,0.026797,179.092804,9.123423,0.267971,-619.397217,0.027907,0.000000
22.130001,41.595490,-619.352783,0.003682,0.001077,0.027361,185.025986,9.425673,0.273610,-619.352783,0.028141,0.000000
22.270000,42.407265,-619.308289,0.003695,0.001088,0.027630,188.636932,9.609623,0.276297,-619.308289,0.028376,0.000000
22.410002,42.683189,-619.352783,0.003704,0.001094,0.027777,189.864304,9.672149,0.277773,-619.352783,0.028601,0.000000
22.550001,43.038811,-619.352783,0.003721,0.001103,0.028011,191.446198,9.752734,0.280113,-619.352783,0.028835,0.000000
22.690001,43.443207,-619.397217,0.003712,0.001111,0.028219,193.245041,9.844372,0.282194,-619.397217,0.029070,0.000000
22.830002,43.928032,-619.352783,0.003717,0.001119,0.028419,195.401642,9.954234,0.284189,-619.352783,0.029303,0.000000
22.970001,44.181244,-619.352783,0.003738,0.001126,0.028601,196.527985,10.011614,0.286009,-619.352783,0.029538,0.000000
23.110001,44.740181,-619.441711,0.003721,0.001136,0.028844,199.014267,10.138269,0.288439,-619.441711,0.029772,0.000000
23.250002,45.424599,-619.308289,0.003738,0.001147,0.029121,202.058701,10.293361,0.291214,-619.308289,0.030006,0.000000
23.390001,45.995819,-619.397217,0.003738,0.001156,0.029356,204.599625,10.422802,0.293556,-619.397217,0.030240,0.000000
23.530001,46.459053,-619.352783,0.003751,0.001164,0.029564,206.660187,10.527772,0.295638,-619.352783,0.030474,0.000000
23.670002,46.747635,-619.352783,0.003760,0.001171,0.029755,207.943863,10.593165,0.297546,-619.352783,0.030708,0.000000
23.810001,46.932335,-619.441711,0.003755,0.001175,0.029833,208.765457,10.635019,0.298325,-619.441711,0.030943,0.000000
23.950001,47.377319,-619.308289,0.003764,0.001183,0.030041,210.744843,10.735854,0.300407,-619.308289,0.031168,0.000000
24.090002,48.753235,-619.441711,0.003773,0.001202,0.030535,216.865219,11.047641,0.305350,-619.441711,0.031402,0.000000
24.230001,49.380310,-619.441711,0.003781,0.001212,0.030786,219.654587,11.189738,0.307863,-619.441711,0.031636,0.000000
24.370001,49.832001,-619.397217,0.003781,0.001220,0.030977,221.663803,11.292092,0.309771,-619.397217,0.031870,0.000000
24.510000,49.820831,-619.397217,0.003768,0.001223,0.031055,221.614120,11.289561,0.310554,-619.397217,0.032105,0.000000
24.650002,50.761444,-619.397217,0.003781,0.001237,0.031428,225.798187,11.502708,0.314283,-619.397217,0.032339,0.000000
24.790001,51.200844,-619.397217,0.003790,0.001248,0.031706,227.752731,11.602278,0.317057,-619.397217,0.032573,0.000000
24.930000,51.663696,-619.397217,0.003794,0.001253,0.031818,229.811600,11.707161,0.318185,-619.397217,0.032807,0.000000
25.070002,51.996231,-619.397217,0.003811,0.001261,0.032027,231.290787,11.782515,0.320266,-619.397217,0.033041,0.000000
25.210001,52.755867,-619.441711,0.003820,0.001274,0.032356,234.669815,11.954651,0.323563,-619.441711,0.033275,0.000000
25.350000,53.489441,-619.486206,0.003811,0.001284,0.032608,237.932922,12.120881,0.326076,-619.486206,0.033510,0.000000
25.490002,54.090820,-619.486206,0.003816,0.001293,0.032842,240.607986,12.257155,0.328419,-619.486206,0.033735,0.000000
25.630001,54.402496,-619.397217,0.003829,0.001298,0.032972,241.994385,12.327782,0.329717,-619.397217,0.033969,0.000000
25.770000,54.527618,-619.397217,0.003837,0.001306,0.033162,242.550964,12.356135,0.331625,-619.397217,0.034203,0.000000
25.910002,55.845444,-619.486206,0.003850,0.001324,0.033622,248.412933,12.654758,0.336224,-619.486206,0.034438,0.000000
26.050001,56.683655,-619.486206,0.003842,0.001334,0.033882,252.141495,12.844700,0.338824,-619.486206,0.034672,0.000000
26.190001,57.186729,-619.530701,0.003859,0.001343,0.034117,254.379272,12.958698,0.341167,-619.530701,0.034906,0.000000
26.330002,57.763908,-619.441711,0.003854,0.001352,0.034342,256.946686,13.089488,0.343422,-619.441711,0.035140,0.000000
26.470001,58.026428,-619.486206,0.003854,0.001358,0.034489,258.114441,13.148976,0.344895,-619.486206,0.035374,0.000000
26.610001,58.482956,-619.486206,0.003863,0.001366,0.034706,260.145172,13.252427,0.347064,-619.486206,0.035608,0.000000
26.750002,59.036301,-619.441711,0.003863,0.001376,0.034949,262.606567,13.377817,0.349490,-619.441711,0.035842,0.000000
26.890001,59.436600,-619.486206,0.003872,0.001383,0.035123,264.387207,13.468526,0.351227,-619.486206,0.036068,0.000000
27.030001,59.592628,-619.486206,0.003880,0.001386,0.035192,265.081238,13.503882,0.351920,-619.486206,0.036302,0.000000
27.170002,60.446480,-619.441711,0.003885,0.001401,0.035573,268.879364,13.697368,0.355735,-619.441711,0.036536,0.000000
27.310001,61.323784,-619.486206,0.003885,0.001409,0.035790,272.781799,13.896168,0.357903,-619.486206,0.036770,0.000000
27.450001,61.979904,-619.397217,0.003893,0.001419,0.036050,275.700378,14.044847,0.360504,-619.397217,0.037005,0.000000
27.590002,62.278175,-619.486206,0.003902,0.001424,0.036181,277.027161,14.112435,0.361806,-619.486206,0.037238,0.000000
27.730001,62.847160,-619.486206,0.003915,0.001436,0.036475,279.558136,14.241370,0.364754,-619.486206,0.037473,0.000000
27.870001,63.626915,-619.530701,0.003911,0.001446,0.036727,283.026642,14.418065,0.367271,-619.530701,0.037707,0.000000
28.010002,64.636787,-619.530701,0.003919,0.001462,0.037126,287.518799,14.646906,0.371260,-619.530701,0.037941,0.000000
28.150002,65.685753,-619.486206,0.003928,0.001474,0.037430,292.184814,14.884604,0.374296,-619.486206,0.038175,0.000000
28.290001,66.199257,-619.530701,0.003915,0.001482,0.037646,294.468994,15.000966,0.376461,-619.530701,0.038409,0.000000
28.430002,66.386192,-619.530701,0.003941,0.001485,0.037724,295.300537,15.043326,0.377244,-619.530701,0.038635,0.000000
28.570002,66.731010,-619.530701,0.003936,0.001494,0.037958,296.834351,15.121463,0.379583,-619.530701,0.038869,0.000000
28.710001,67.579277,-619.575195,0.003954,0.001498,0.038054,300.607635,15.313684,0.380537,-619.575195,0.039077,0.000000
28.850002,67.171150,-619.530701,0.003954,0.001495,0.037976,298.792206,15.221201,0.379757,-619.530701,0.038210,0.000000
28.990002,66.919426,-619.575195,0.003936,0.001495,0.037976,297.672485,15.164159,0.379757,-619.575195,0.038210,0.000000
29.130001,66.767876,-619.486206,0.003958,0.001494,0.037958,296.998352,15.129817,0.379583,-619.486206,0.037976,0.000000
29.270000,66.575356,-619.530701,0.003954,0.001494,0.037950,296.141968,15.086191,0.379496,-619.530701,0.037976,0.000000
29.410002,66.401833,-619.575195,0.003945,0.001494,0.037941,295.370117,15.046870,0.379409,-619.575195,0.037976,0.000000
29.550001,66.227562,-619.530701,0.003958,0.001493,0.037932,294.594910,15.007380,0.379322,-619.530701,0.037976,0.000000
29.690001,66.089775,-619.575195,0.003945,0.001493,0.037932,293.981995,14.976157,0.379322,-619.575195,0.037976,0.000000
29.830002,65.958336,-619.530701,0.003958,0.001493,0.037932,293.397339,14.946372,0.379322,-619.530701,0.037976,0.000000
29.970001,65.838799,-619.575195,0.003954,0.001493,0.037924,292.865601,14.919285,0.379239,-619.575195,0.037976,0.000000
30.110001,65.716667,-619.530701,0.003967,0.001493,0.037924,292.322327,14.891609,0.379239,-619.530701,0.037976,0.000000
30.250002,65.616493,-619.530701,0.003949,0.001493,0.037924,291.876740,14.868910,0.379239,-619.530701,0.037976,0.000000
30.390001,65.511116,-619.619629,0.003954,0.001493,0.037924,291.407990,14.845031,0.379239,-619.619629,0.037976,0.000000
30.530001,65.429192,-619.530701,0.003958,0.001493,0.037924,291.043579,14.826467,0.379239,-619.530701,0.037976,0.000000
30.670002,65.339073,-619.575195,0.003954,0.001493,0.037924,290.642700,14.806046,0.379239,-619.575195,0.037976,0.000000
30.810001,65.266472,-619.575195,0.003962,0.001493,0.037915,290.319763,14.789594,0.379152,-619.575195,0.037976,0.000000
30.950001,65.196831,-619.530701,0.003945,0.001493,0.037915,290.009979,14.773812,0.379152,-619.530701,0.037976,0.000000
31.090002,65.114540,-619.575195,0.003971,0.001493,0.037915,289.643951,14.755165,0.379152,-619.575195,0.037976,0.000000
31.230001,65.046028,-619.530701,0.003958,0.001493,0.037915,289.339172,14.739640,0.379152,-619.530701,0.037976,0.000000
31.370001,64.990166,-619.619629,0.003958,0.001493,0.037915,289.090698,14.726981,0.379152,-619.619629,0.037976,0.000000
31.510002,64.936165,-619.619629,0.003962,0.001493,0.037915,288.850494,14.714745,0.379152,-619.619629,0.037976,0.000000
31.650002,64.864296,-619.575195,0.003962,0.001493,0.037915,288.530792,14.698460,0.379152,-619.575195,0.037976,0.000000
31.790001,64.820366,-619.664124,0.003954,0.001493,0.037915,288.335388,14.688504,0.379152,-619.664124,0.037976,0.000000
31.930002,64.769356,-619.575195,0.003954,0.001493,0.037915,288.108490,14.676946,0.379152,-619.575195,0.037976,0.000000
32.070000,64.718712,-619.575195,0.003958,0.001493,0.037915,287.883209,14.665470,0.379152,-619.575195,0.037976,0.000000
32.210003,64.665459,-619.619629,0.003971,0.001493,0.037915,287.646332,14.653402,0.379152,-619.619629,0.037976,0.000000
32.350002,64.621147,-619.619629,0.003958,0.001493,0.037915,287.449219,14.643361,0.379152,-619.619629,0.037976,0.000000
32.490002,64.577202,-619.664124,0.003949,0.001493,0.037915,287.253754,14.633403,0.379152,-619.664124,0.037976,0.000000
32.630001,64.517250,-619.619629,0.003962,0.001493,0.037915,286.987061,14.619818,0.379152,-619.619629,0.037976,0.000000
32.770000,64.484108,-619.664124,0.003967,0.001493,0.037915,286.839630,14.612308,0.379152,-619.664124,0.037976,0.000000
32.910000,64.445763,-619.664124,0.003967,0.001493,0.037915,286.669067,14.603619,0.379152,-619.664124,0.037976,0.000000
33.050003,64.413734,-619.619629,0.003962,0.001493,0.037915,286.526611,14.596360,0.379152,-619.619629,0.037976,0.000000
33.190002,64.368675,-619.664124,0.003967,0.001493,0.037915,286.326172,14.586150,0.379152,-619.664124,0.037976,0.000000
33.330002,64.331810,-619.619629,0.003954,0.001492,0.037906,286.162170,14.577796,0.379065,-619.619629,0.037976,0.000000
33.470001,64.283028,-619.708618,0.003958,0.001492,0.037906,285.945190,14.566742,0.379065,-619.708618,0.037976,0.000000
33.610001,64.256218,-619.664124,0.003971,0.001492,0.037906,285.825928,14.560667,0.379065,-619.664124,0.037976,0.000000
33.750000,64.232018,-619.619629,0.003967,0.001492,0.037906,285.718292,14.555183,0.379065,-619.619629,0.037976,0.000000
33.890003,64.190681,-619.708618,0.003971,0.001492,0.037906,285.534424,14.545816,0.379065,-619.708618,0.037976,0.000000
34.030003,64.176903,-619.708618,0.003971,0.001492,0.037906,285.473114,14.542694,0.379065,-619.708618,0.037976,0.000000
34.170002,64.138542,-619.753113,0.003975,0.001492,0.037906,285.302490,14.534001,0.379065,-619.753113,0.037976,0.000000
34.310001,64.105034,-619.664124,0.003971,0.001492,0.037906,285.153442,14.526409,0.379065,-619.664124,0.037976,0.000000
34.450001,64.074501,-619.664124,0.003958,0.001492,0.037906,285.017609,14.519489,0.379065,-619.664124,0.037976,0.000000
34.590000,64.041725,-619.753113,0.003975,0.001492,0.037906,284.871826,14.512062,0.379065,-619.753113,0.037976,0.000000
34.730003,64.013435,-619.619629,0.003958,0.001492,0.037906,284.745972,14.505651,0.379065,-619.619629,0.037976,0.000000
34.870003,63.992958,-619.664124,0.003971,0.001492,0.037906,284.654907,14.501012,0.379065,-619.664124,0.037976,0.000000
35.010002,63.965767,-619.708618,0.003975,0.001492,0.037906,284.533936,14.494850,0.379065,-619.708618,0.037976,0.000000
35.150002,63.937462,-619.708618,0.003962,0.001492,0.037906,284.408020,14.488436,0.379065,-619.708618,0.037976,0.000000
35.290001,63.910652,-619.708618,0.003954,0.001492,0.037906,284.288788,14.482361,0.379065,-619.708618,0.037976,0.000000
35.430000,63.878639,-619.664124,0.003962,0.001492,0.037906,284.146393,14.475106,0.379065,-619.664124,0.037976,0.000000
35.570004,63.847725,-619.797546,0.003962,0.001492,0.037906,284.008850,14.468102,0.379065,-619.797546,0.037976,0.000000
35.710003,63.831718,-619.753113,0.003980,0.001492,0.037906,283.937653,14.464474,0.379065,-619.753113,0.037976,0.000000
35.850002,63.811607,-619.708618,0.003984,0.001492,0.037906,283.848206,14.459916,0.379065,-619.708618,0.037976,0.000000
35.990002,63.787773,-619.753113,0.003971,0.001492,0.037906,283.742187,14.454515,0.379065,-619.753113,0.037976,0.000000
36.130001,63.772133,-619.708618,0.003975,0.001492,0.037906,283.672607,14.450972,0.379065,-619.708618,0.037976,0.000000
36.270000,63.751289,-619.797546,0.003967,0.001492,0.037906,283.579895,14.446249,0.379065,-619.797546,0.037976,0.000000
36.410000,63.722603,-619.753113,0.003975,0.001492,0.037906,283.452301,14.439748,0.379065,-619.753113,0.037976,0.000000
36.550003,63.706230,-619.753113,0.003971,0.001492,0.037906,283.379456,14.436038,0.379065,-619.753113,0.037976,0.000000
36.690002,63.671593,-619.753113,0.003962,0.001492,0.037906,283.225403,14.428189,0.379065,-619.753113,0.037976,0.000000
36.830002,63.656334,-619.664124,0.003975,0.001492,0.037906,283.157501,14.424731,0.379065,-619.664124,0.037976,0.000000
36.970001,63.631004,-619.797546,0.003967,0.001492,0.037906,283.044830,14.418992,0.379065,-619.797546,0.037976,0.000000
37.110001,63.616859,-619.753113,0.003971,0.001492,0.037906,282.981934,14.415787,0.379065,-619.753113,0.037976,0.000000
37.250000,63.594139,-619.753113,0.003984,0.001492,0.037906,282.880859,14.410638,0.379065,-619.753113,0.037976,0.000000
37.390003,63.586327,-619.842041,0.003980,0.001492,0.037906,282.846100,14.408868,0.379065,-619.842041,0.037976,0.000000
37.530003,63.559517,-619.797546,0.003980,0.001492,0.037906,282.726837,14.402792,0.379065,-619.797546,0.037976,0.000000
37.670002,63.550575,-619.797546,0.003949,0.001492,0.037906,282.687073,14.400766,0.379065,-619.797546,0.037976,0.000000
37.810001,63.525627,-619.753113,0.003975,0.001492,0.037906,282.576111,14.395113,0.379065,-619.753113,0.037976,0.000000
37.950001,63.511467,-619.753113,0.003958,0.001492,0.037906,282.513123,14.391904,0.379065,-619.753113,0.037976,0.000000
38.090000,63.496208,-619.797546,0.003975,0.001492,0.037906,282.445251,14.388447,0.379065,-619.797546,0.037976,0.000000
38.230003,63.481682,-619.797546,0.003975,0.001492,0.037906,282.380615,14.385155,0.379065,-619.797546,0.037976,0.000000
38.370003,63.466042,-619.797546,0.003962,0.001492,0.037906,282.311066,14.381611,0.379065,-619.797546,0.037976,0.000000
38.510002,63.452644,-619.797546,0.003975,0.001492,0.037906,282.251465,14.378574,0.379065,-619.797546,0.037976,0.000000
38.650002,63.448540,-619.842041,0.003954,0.001492,0.037906,282.233215,14.377645,0.379065,-619.842041,0.037976,0.000000
38.790001,63.426201,-619.753113,0.003967,0.001492,0.037906,282.133820,14.372582,0.379065,-619.753113,0.037976,0.000000
38.930000,63.405724,-619.753113,0.003958,0.001492,0.037906,282.042755,14.367942,0.379065,-619.753113,0.037976,0.000000
39.070004,63.396782,-619.797546,0.003958,0.001492,0.037906,282.002960,14.365916,0.379065,-619.797546,0.037976,0.000000
39.210003,63.375923,-619.753113,0.003975,0.001492,0.037906,281.910187,14.361190,0.379065,-619.753113,0.037976,0.000000
39.350002,63.362160,-619.797546,0.003967,0.001492,0.037906,281.848969,14.358070,0.379065,-619.797546,0.037976,0.000000
39.490002,63.353218,-619.797546,0.003980,0.001492,0.037906,281.809174,14.356044,0.379065,-619.797546,0.037976,0.000000
39.630001,63.336830,-619.842041,0.003967,0.001492,0.037906,281.736298,14.352331,0.379065,-619.842041,0.037976,0.000000
39.770000,63.322685,-619.797546,0.003971,0.001492,0.037906,281.673370,14.349125,0.379065,-619.797546,0.037976,0.000000
39.910004,63.306664,-619.797546,0.003980,0.001492,0.037906,281.602112,14.345495,0.379065,-619.797546,0.037976,0.000000
40.050003,63.289543,-619.842041,0.003967,0.001492,0.037906,281.525940,14.341616,0.379065,-619.842041,0.037976,0.000000
40.190002,63.277992,-619.886536,0.003975,0.001492,0.037906,281.474579,14.338998,0.379065,-619.886536,0.037976,0.000000
40.330002,63.261238,-619.797546,0.003967,0.001492,0.037906,281.400055,14.335202,0.379065,-619.797546,0.037976,0.000000
40.470001,63.256020,-619.842041,0.003962,0.001492,0.037906,281.376831,14.334019,0.379065,-619.842041,0.037976,0.000000
40.610001,63.240379,-619.842041,0.003984,0.001492,0.037906,281.307251,14.330475,0.379065,-619.842041,0.037976,0.000000
40.750004,63.228844,-619.842041,0.003975,0.001492,0.037906,281.255951,14.327861,0.379065,-619.842041,0.037976,0.000000
40.890003,63.213570,-619.931030,0.003967,0.001492,0.037906,281.187988,14.324400,0.379065,-619.931030,0.037976,0.000000
41.030003,63.210594,-619.842041,0.003962,0.001492,0.037906,281.174774,14.323725,0.379065,-619.842041,0.037976,0.000000
41.170002,63.194954,-619.842041,0.003971,0.001492,0.037906,281.105194,14.320182,0.379065,-619.842041,0.037976,0.000000
41.310001,63.184166,-619.842041,0.003971,0.001492,0.037906,281.057220,14.317737,0.379065,-619.842041,0.037976,0.000000
41.450001,63.171501,-619.842041,0.003975,0.001492,0.037906,281.000885,14.314867,0.379065,-619.842041,0.037976,0.000000
41.590000,63.153252,-619.842041,0.003967,0.001492,0.037906,280.919708,14.310731,0.379065,-619.842041,0.037976,0.000000
41.730003,63.141335,-619.842041,0.003967,0.001492,0.037906,280.866669,14.308031,0.379065,-619.842041,0.037976,0.000000
41.870003,63.129799,-619.931030,0.003971,0.001492,0.037906,280.815369,14.305417,0.379065,-619.931030,0.037976,0.000000
42.010002,63.106331,-619.797546,0.003975,0.001492,0.037906,280.710968,14.300099,0.379065,-619.797546,0.037976,0.000000
42.150002,63.089577,-619.886536,0.003975,0.001492,0.037906,280.636444,14.296303,0.379065,-619.886536,0.037976,0.000000
42.290001,63.085106,-619.931030,0.003975,0.001492,0.037906,280.616577,14.295290,0.379065,-619.931030,0.037976,0.000000
42.430000,63.069466,-619.797546,0.003962,0.001492,0.037906,280.546997,14.291745,0.379065,-619.797546,0.037976,0.000000
42.570004,63.058662,-619.842041,0.003971,0.001492,0.037906,280.498932,14.289297,0.379065,-619.842041,0.037976,0.000000
42.710003,63.049736,-619.842041,0.003975,0.001492,0.037906,280.459229,14.287274,0.379065,-619.842041,0.037976,0.000000
42.850002,63.042282,-619.886536,0.003984,0.001492,0.037906,280.426086,14.285585,0.379065,-619.886536,0.037976,0.000000
42.990002,63.026276,-619.931030,0.003975,0.001492,0.037906,280.354889,14.281958,0.379065,-619.931030,0.037976,0.000000
43.130001,63.025154,-619.842041,0.003971,0.001492,0.037906,280.349884,14.281704,0.379065,-619.842041,0.037976,0.000000
43.270000,63.013985,-619.931030,0.003971,0.001492,0.037906,280.300201,14.279173,0.379065,-619.931030,0.037976,0.000000
43.410004,63.002068,-619.842041,0.003988,0.001492,0.037906,280.247192,14.276473,0.379065,-619.842041,0.037976,0.000000
43.550003,62.989037,-619.842041,0.003975,0.001492,0.037906,280.189240,14.273520,0.379065,-619.842041,0.037976,0.000000
43.690002,62.974144,-619.931030,0.003971,0.001492,0.037906,280.122986,14.270145,0.379065,-619.931030,0.037976,0.000000
43.830002,62.974144,-619.842041,0.003975,0.001492,0.037906,280.122986,14.270145,0.379065,-619.842041,0.037976,0.000000
43.970001,62.953285,-619.931030,0.003975,0.001492,0.037906,280.030212,14.265418,0.379065,-619.931030,0.037976,0.000000
44.110001,62.949562,-619.886536,0.003984,0.001492,0.037906,280.013641,14.264575,0.379065,-619.886536,0.037976,0.000000
44.250004,62.932060,-619.886536,0.003975,0.001492,0.037906,279.935791,14.260610,0.379065,-619.886536,0.037976,0.000000
44.390003,62.923874,-619.886536,0.003971,0.001492,0.037906,279.899384,14.258754,0.379065,-619.886536,0.037976,0.000000
44.530003,62.918655,-619.931030,0.003975,0.001492,0.037906,279.876160,14.257571,0.379065,-619.931030,0.037976,0.000000
44.670002,62.907860,-619.886536,0.003967,0.001492,0.037906,279.828125,14.255125,0.379065,-619.886536,0.037976,0.000000
44.810001,62.903763,-619.886536,0.003971,0.001492,0.037906,279.809906,14.254196,0.379065,-619.886536,0.037976,0.000000
44.950001,62.900780,-619.931030,0.003958,0.001492,0.037906,279.796631,14.253521,0.379065,-619.931030,0.037976,0.000000
45.090004,62.896690,-619.842041,0.003980,0.001492,0.037906,279.778442,14.252594,0.379065,-619.842041,0.037976,0.000000
45.230003,62.880676,-619.842041,0.003975,0.001492,0.037906,279.707214,14.248965,0.379065,-619.842041,0.037976,0.000000
45.370003,62.872482,-619.931030,0.003971,0.001492,0.037906,279.670776,14.247108,0.379065,-619.931030,0.037976,0.000000
45.510002,62.869507,-619.931030,0.003975,0.001492,0.037906,279.657532,14.246434,0.379065,-619.931030,0.037976,0.000000
45.650002,62.841202,-619.931030,0.003980,0.001492,0.037906,279.531616,14.240020,0.379065,-619.931030,0.037976,0.000000
45.790001,62.841202,-619.886536,0.003971,0.001492,0.037906,279.531616,14.240020,0.379065,-619.886536,0.037976,0.000000
45.930000,62.836365,-619.931030,0.003971,0.001492,0.037906,279.510101,14.238923,0.379065,-619.931030,0.037976,0.000000
46.070004,62.826309,-619.975525,0.003975,0.001492,0.037906,279.465393,14.236645,0.379065,-619.975525,0.037976,0.000000
46.210003,62.825935,-619.931030,0.003967,0.001492,0.037906,279.463715,14.236561,0.379065,-619.931030,0.037976,0.000000
46.350002,62.805458,-619.931030,0.003975,0.001492,0.037906,279.372620,14.231920,0.379065,-619.931030,0.037976,0.000000
46.490002,62.803596,-619.975525,0.003988,0.001492,0.037906,279.364349,14.231498,0.379065,-619.975525,0.037976,0.000000
46.630001,62.798752,-619.931030,0.003975,0.001492,0.037906,279.342804,14.230401,0.379065,-619.931030,0.037976,0.000000
46.770000,62.790932,-620.064453,0.003984,0.001492,0.037906,279.308014,14.228628,0.379065,-620.064453,0.037976,0.000000
46.910004,62.788330,-619.931030,0.003975,0.001492,0.037906,279.296448,14.228040,0.379065,-619.931030,0.037976,0.000000
47.050003,62.783485,-619.931030,0.003967,0.001492,0.037906,279.274902,14.226941,0.379065,-619.931030,0.037976,0.000000
47.190002,62.777901,-619.975525,0.003988,0.001492,0.037906,279.250061,14.225676,0.379065,-619.975525,0.037976,0.000000
47.330002,62.774551,-619.931030,0.003980,0.001492,0.037906,279.235138,14.224916,0.379065,-619.931030,0.037976,0.000000
47.470001,62.766357,-619.931030,0.003980,0.001492,0.037906,279.198700,14.223060,0.379065,-619.931030,0.037976,0.000000
47.610001,62.742897,-619.931030,0.003984,0.001492,0.037906,279.094330,14.217744,0.379065,-619.931030,0.037976,0.000000
47.750004,62.740288,-619.975525,0.003975,0.001492,0.037906,279.082733,14.217153,0.379065,-619.975525,0.037976,0.000000
47.890003,62.728745,-619.931030,0.003984,0.001492,0.037906,279.031403,14.214537,0.379065,-619.931030,0.037976,0.000000
48.030003,62.722420,-619.975525,0.003971,0.001492,0.037906,279.003265,14.213103,0.379065,-619.975525,0.037976,0.000000
48.170002,62.705284,-620.019958,0.003988,0.001492,0.037906,278.927032,14.209221,0.379065,-620.019958,0.037976,0.000000
48.310001,62.706406,-619.975525,0.003984,0.001492,0.037906,278.932037,14.209475,0.379065,-619.975525,0.037976,0.000000
48.450001,62.704918,-620.019958,0.003967,0.001492,0.037906,278.925415,14.209137,0.379065,-620.019958,0.037976,0.000000
48.590004,62.703056,-620.019958,0.003971,0.001492,0.037906,278.917114,14.208716,0.379065,-620.019958,0.037976,0.000000
48.730003,62.689651,-619.975525,0.003971,0.001492,0.037906,278.857483,14.205678,0.379065,-619.975525,0.037976,0.000000
48.870003,62.680710,-620.064453,0.003980,0.001492,0.037906,278.817719,14.203652,0.379065,-620.064453,0.037976,0.000000
49.010002,62.677734,-619.931030,0.003984,0.001492,0.037906,278.804474,14.202977,0.379065,-619.931030,0.037976,0.000000
49.150002,62.672150,-620.064453,0.003988,0.001492,0.037906,278.779633,14.201712,0.379065,-620.064453,0.037976,0.000000
49.290001,62.655388,-619.975525,0.003975,0.001492,0.037906,278.705078,14.197913,0.379065,-619.975525,0.037976,0.000000
49.430004,62.653900,-619.975525,0.003984,0.001492,0.037906,278.698456,14.197577,0.379065,-619.975525,0.037976,0.000000
49.570004,62.631561,-620.019958,0.003975,0.001492,0.037906,278.599091,14.192514,0.379065,-620.019958,0.037976,0.000000
49.710003,62.639748,-619.975525,0.003971,0.001492,0.037906,278.635529,14.194369,0.379065,-619.975525,0.037976,0.000000
49.850002,62.628578,-620.019958,0.003980,0.001492,0.037906,278.585815,14.191838,0.379065,-620.019958,0.037976,0.000000
49.990002,62.621880,-620.019958,0.003980,0.001492,0.037906,278.556030,14.190320,0.379065,-620.019958,0.037976,0.000000
50.130001,62.609962,-620.064453,0.003980,0.001492,0.037906,278.503021,14.187620,0.379065,-620.064453,0.037976,0.000000
50.270004,62.609962,-620.064453,0.003971,0.001492,0.037906,278.503021,14.187620,0.379065,-620.064453,0.037976,0.000000
50.410004,62.605492,-620.019958,0.003980,0.001492,0.037906,278.483124,14.186607,0.379065,-620.019958,0.037976,0.000000
50.550003,62.599907,-620.019958,0.003975,0.001492,0.037906,278.458282,14.185342,0.379065,-620.019958,0.037976,0.000000
50.690002,62.584267,-620.064453,0.003975,0.001492,0.037906,278.388733,14.181798,0.379065,-620.064453,0.037976,0.000000
50.830002,62.576447,-620.108948,0.003971,0.001492,0.037906,278.353943,14.180025,0.379065,-620.108948,0.037976,0.000000
50.970001,62.571236,-620.108948,0.003975,0.001492,0.037906,278.330750,14.178844,0.379065,-620.108948,0.037976,0.000000
51.110001,62.565651,-620.019958,0.003971,0.001492,0.037906,278.305908,14.177579,0.379065,-620.019958,0.037976,0.000000
51.250004,62.558571,-620.019958,0.003984,0.001492,0.037906,278.274414,14.175975,0.379065,-620.019958,0.037976,0.000000
51.390003,62.541069,-620.064453,0.003984,0.001492,0.037906,278.196564,14.172009,0.379065,-620.064453,0.037976,0.000000
51.530003,62.534370,-620.019958,0.003967,0.001492,0.037906,278.166779,14.170491,0.379065,-620.019958,0.037976,0.000000
51.670002,62.530647,-620.019958,0.003992,0.001492,0.037906,278.150208,14.169647,0.379065,-620.019958,0.037976,0.000000
51.810001,62.509422,-620.019958,0.003980,0.001492,0.037906,278.055786,14.164837,0.379065,-620.019958,0.037976,0.000000
51.950001,62.517609,-620.064453,0.003971,0.001492,0.037906,278.092224,14.166693,0.379065,-620.064453,0.037976,0.000000
52.090004,62.510910,-620.064453,0.003980,0.001492,0.037906,278.062408,14.165175,0.379065,-620.064453,0.037976,0.000000
52.230003,62.508301,-620.064453,0.003975,0.001492,0.037906,278.050812,14.164583,0.379065,-620.064453,0.037976,0.000000
52.370003,62.498619,-620.108948,0.003975,0.001492,0.037906,278.007751,14.162390,0.379065,-620.108948,0.037976,0.000000
52.510002,62.508675,-620.064453,0.003971,0.001492,0.037906,278.052460,14.164668,0.379065,-620.064453,0.037976,0.000000
52.650002,62.488937,-620.108948,0.003975,0.001492,0.037906,277.964691,14.160195,0.379065,-620.108948,0.037976,0.000000
52.790001,62.487450,-620.108948,0.003984,0.001492,0.037906,277.958069,14.159859,0.379065,-620.108948,0.037976,0.000000
52.930004,62.491920,-620.019958,0.003967,0.001492,0.037906,277.977936,14.160872,0.379065,-620.019958,0.037976,0.000000
53.070004,62.480743,-620.108948,0.003992,0.001492,0.037906,277.928223,14.158340,0.379065,-620.108948,0.037976,0.000000
53.210003,62.465111,-620.064453,0.003975,0.001492,0.037906,277.858704,14.154797,0.379065,-620.064453,0.037976,0.000000
53.350002,62.468086,-620.153442,0.003962,0.001492,0.037906,277.871918,14.155471,0.379065,-620.153442,0.037976,0.000000
53.490002,62.450211,-620.108948,0.003988,0.001492,0.037906,277.792419,14.151421,0.379065,-620.108948,0.037976,0.000000
53.630001,62.444626,-620.064453,0.003967,0.001492,0.037906,277.767578,14.150155,0.379065,-620.064453,0.037976,0.000000
53.770004,62.446114,-620.153442,0.003971,0.001492,0.037906,277.774200,14.150492,0.379065,-620.153442,0.037976,0.000000
53.910004,62.437180,-620.108948,0.003967,0.001492,0.037906,277.734436,14.148467,0.379065,-620.108948,0.037976,0.000000
54.050003,62.437180,-620.153442,0.003975,0.001492,0.037906,277.734436,14.148467,0.379065,-620.153442,0.037976,0.000000
54.190002,62.422653,-620.153442,0.003980,0.001492,0.037906,277.669830,14.145175,0.379065,-620.153442,0.037976,0.000000
54.330002,62.431221,-620.153442,0.003962,0.001492,0.037906,277.707947,14.147118,0.379065,-620.153442,0.037976,0.000000
54.470001,62.409996,-620.197876,0.003967,0.001492,0.037906,277.613525,14.142307,0.379065,-620.197876,0.037976,0.000000
54.610004,62.412979,-620.108948,0.003975,0.001492,0.037906,277.626801,14.142983,0.379065,-620.108948,0.037976,0.000000
54.750004,62.407761,-620.153442,0.003975,0.001492,0.037906,277.603577,14.141801,0.379065,-620.153442,0.037976,0.000000
54.890003,62.412605,-620.064453,0.003975,0.001492,0.037906,277.625122,14.142899,0.379065,-620.064453,0.037976,0.000000
55.030003,62.405159,-620.108948,0.003967,0.001492,0.037906,277.592010,14.141212,0.379065,-620.108948,0.037976,0.000000
55.170002,62.397339,-620.197876,0.003988,0.001492,0.037906,277.557220,14.139440,0.379065,-620.197876,0.037976,0.000000
55.310001,62.381325,-620.064453,0.003975,0.001492,0.037906,277.485992,14.135810,0.379065,-620.064453,0.037976,0.000000
55.450001,62.384300,-620.197876,0.003980,0.001492,0.037906,277.499237,14.136484,0.379065,-620.197876,0.037976,0.000000
55.590004,62.373131,-620.108948,0.003984,0.001492,0.037906,277.449554,14.133953,0.379065,-620.108948,0.037976,0.000000
55.730003,62.375740,-620.108948,0.003975,0.001492,0.037906,277.461151,14.134544,0.379065,-620.108948,0.037976,0.000000
55.870003,62.371643,-620.153442,0.003975,0.001492,0.037906,277.442932,14.133616,0.379065,-620.153442,0.037976,0.000000
56.010002,62.360840,-620.197876,0.003984,0.001492,0.037906,277.394867,14.131168,0.379065,-620.197876,0.037976,0.000000
56.150002,62.346695,-620.153442,0.003975,0.001492,0.037906,277.331940,14.127962,0.379065,-620.153442,0.037976,0.000000
56.290001,62.366798,-620.153442,0.003997,0.001492,0.037906,277.421387,14.132518,0.379065,-620.153442,0.037976,0.000000
56.430004,62.355255,-620.197876,0.003967,0.001492,0.037906,277.370026,14.129903,0.379065,-620.197876,0.037976,0.000000
56.570004,62.342972,-620.153442,0.003975,0.001492,0.037906,277.315399,14.127119,0.379065,-620.153442,0.037976,0.000000
56.710003,62.341476,-620.242371,0.003967,0.001492,0.037906,277.308746,14.126781,0.379065,-620.242371,0.037976,0.000000
56.850002,62.332916,-620.153442,0.003984,0.001492,0.037906,277.270660,14.124841,0.379065,-620.153442,0.037976,0.000000
56.990002,62.328072,-620.153442,0.003984,0.001492,0.037906,277.249115,14.123743,0.379065,-620.153442,0.037976,0.000000
57.130001,62.328072,-620.197876,0.003980,0.001492,0.037906,277.249115,14.123743,0.379065,-620.197876,0.037976,0.000000
57.270004,62.319511,-620.242371,0.003980,0.001492,0.037906,277.211029,14.121803,0.379065,-620.242371,0.037976,0.000000
57.410004,62.309830,-620.197876,0.003984,0.001492,0.037906,277.167969,14.119610,0.379065,-620.197876,0.037976,0.000000
57.550003,62.296425,-620.197876,0.003975,0.001492,0.037906,277.108337,14.116571,0.379065,-620.197876,0.037976,0.000000
57.690002,62.303871,-620.242371,0.003984,0.001492,0.037906,277.141449,14.118258,0.379065,-620.242371,0.037976,0.000000
57.830002,62.291206,-620.153442,0.003984,0.001492,0.037906,277.085114,14.115389,0.379065,-620.153442,0.037976,0.000000
57.970001,62.293816,-620.197876,0.003971,0.001492,0.037906,277.096741,14.115980,0.379065,-620.197876,0.037976,0.000000
58.110004,62.272591,-620.197876,0.003971,0.001492,0.037906,277.002319,14.111171,0.379065,-620.197876,0.037976,0.000000
58.250004,62.278175,-620.286865,0.003980,0.001492,0.037906,277.027161,14.112435,0.379065,-620.286865,0.037976,0.000000
58.390003,62.267006,-620.153442,0.003980,0.001492,0.037906,276.977478,14.109905,0.379065,-620.153442,0.037976,0.000000
58.530003,62.262909,-620.242371,0.003980,0.001492,0.037906,276.959259,14.108977,0.379065,-620.242371,0.037976,0.000000
58.670002,62.255463,-620.286865,0.003992,0.001492,0.037906,276.926117,14.107289,0.379065,-620.286865,0.037976,0.000000
58.810001,62.265884,-620.197876,0.003992,0.001492,0.037906,276.972473,14.109652,0.379065,-620.197876,0.037976,0.000000
58.950005,62.252853,-620.242371,0.003975,0.001492,0.037906,276.914520,14.106698,0.379065,-620.242371,0.037976,0.000000
59.090004,62.246529,-620.153442,0.003984,0.001492,0.037906,276.886383,14.105265,0.379065,-620.153442,0.037976,0.000000
59.100002,62.252853,-620.242371,0.003980,0.001492,0.037906,276.914520,14.106698,0.379065,-620.242371,0.037976,0.000000