File: Data/AG AL compression 300N/AD membrane Peeled 300N_1_1_03202024_194021.csv
Time (sec),S:Load (lbs),S:HL1 (DIM),S:LVDT (in),S:Position (in),Ch:Position (mm),Ch:Load (N),Ch:Stress (MPa),Ch:Strain (mm/mm),Ch:HL1 (DIM),Set Point (),Cycles ()
0.010000,0.010429,-505.125671,-0.000030,-0.000000,-0.000000,0.046392,0.002363,-0.000000,-505.125671,0.000182,0.000000
0.170000,0.005959,-505.036713,0.000000,-0.000000,-0.000000,0.026505,0.001350,-0.000000,-505.036713,0.000182,0.000000
0.330000,-0.000374,-505.125671,-0.000017,-0.000000,-0.000000,-0.001663,-0.000085,-0.000000,-505.125671,0.000182,0.000000
0.490000,0.025696,-505.081207,-0.000026,0.000081,0.002047,0.114301,0.005823,0.020469,-505.081207,0.002645,0.000000
0.650000,0.004097,-505.125671,0.000004,0.000167,0.004241,0.018224,0.000928,0.042410,-505.125671,0.005316,0.000000
0.810000,0.025322,-505.125671,0.000112,0.000269,0.006843,0.112638,0.005738,0.068427,-505.125671,0.007987,0.000000
0.970000,0.000748,-505.081207,0.000198,0.000370,0.009410,0.003326,0.000169,0.094096,-505.081207,0.010658,0.000000
1.130000,0.020477,-505.170166,0.000306,0.000476,0.012081,0.091088,0.004640,0.120806,-505.170166,0.013312,0.000000
1.290000,-0.001862,-505.081207,0.000427,0.000585,0.014856,-0.008281,-0.000422,0.148557,-505.081207,0.015983,0.000000
1.450000,-0.026810,-505.125671,0.000530,0.000686,0.017414,-0.119255,-0.006075,0.174139,-505.125671,0.018654,0.000000
1.610000,-0.043571,-505.125671,0.000634,0.000794,0.020163,-0.193816,-0.009873,0.201633,-505.125671,0.021308,0.000000
1.770000,-0.008934,-505.125671,0.000733,0.000893,0.022678,-0.039741,-0.002024,0.226780,-505.125671,0.023979,0.000000
1.930000,0.011543,-505.125671,0.000836,0.000999,0.025366,0.051347,0.002616,0.253664,-505.125671,0.026650,0.000000
2.090000,0.030159,-505.170166,0.000957,0.001108,0.028133,0.134154,0.006834,0.281327,-505.170166,0.029304,0.000000
2.250000,0.004097,-505.170166,0.001065,0.001214,0.030839,0.018224,0.000928,0.308386,-505.170166,0.031975,0.000000
2.410000,-0.015640,-505.170166,0.001160,0.001319,0.033493,-0.069571,-0.003544,0.334925,-505.170166,0.034646,0.000000
2.570000,0.037979,-505.081207,0.001268,0.001419,0.036051,0.168940,0.008606,0.360507,-505.081207,0.037299,0.000000
2.730000,0.023087,-505.170166,0.001367,0.001522,0.038670,0.102694,0.005231,0.386699,-505.170166,0.039970,0.000000
2.890000,0.033516,-505.170166,0.001475,0.001628,0.041350,0.149086,0.007595,0.413496,-505.170166,0.042642,0.000000
3.050000,0.013779,-505.214630,0.001587,0.001740,0.044185,0.061291,0.003122,0.441852,-505.214630,0.045295,0.000000
3.210000,0.006699,-505.259125,0.001681,0.001845,0.046856,0.029797,0.001518,0.468562,-505.259125,0.047966,0.000000
3.370000,-0.018990,-505.170166,0.001807,0.001949,0.049493,-0.084470,-0.004303,0.494928,-505.170166,0.050637,0.000000
3.530000,-0.012665,-505.214630,0.001910,0.002059,0.052302,-0.056336,-0.002870,0.523023,-505.214630,0.053291,0.000000
3.690000,-0.017128,-505.125671,0.002005,0.002157,0.054783,-0.076189,-0.003881,0.547830,-505.125671,0.055962,0.000000
3.850000,0.025322,-505.125671,0.002121,0.002260,0.057410,0.112638,0.005738,0.574104,-505.125671,0.058633,0.000000
4.010000,0.016380,-505.214630,0.002199,0.002365,0.060081,0.072863,0.003712,0.600814,-505.214630,0.061287,0.000000
4.170000,0.008568,-505.125671,0.002320,0.002472,0.062779,0.038112,0.001941,0.627785,-505.125671,0.063958,0.000000
4.330000,0.006332,-505.214630,0.002427,0.002577,0.065467,0.028168,0.001435,0.654670,-505.214630,0.066629,0.000000
4.490000,0.029793,-505.170166,0.002548,0.002687,0.068251,0.132525,0.006751,0.682507,-505.170166,0.069300,0.000000
4.650000,0.046173,-505.259125,0.002630,0.002782,0.070662,0.205388,0.010463,0.706617,-505.259125,0.071954,0.000000
4.810000,0.027557,-505.125671,0.002738,0.002893,0.073472,0.122581,0.006245,0.734716,-505.125671,0.074625,0.000000
4.970000,0.027184,-505.170166,0.002867,0.002999,0.076177,0.120918,0.006160,0.761771,-505.170166,0.077296,0.000000
5.130000,0.005585,-505.214630,0.002958,0.003097,0.078666,0.024842,0.001266,0.786660,-505.214630,0.079949,0.000000
5.290000,-0.013031,-505.170166,0.003053,0.003209,0.081519,-0.057965,-0.002953,0.815194,-505.170166,0.082621,0.000000
5.450000,0.014519,-505.214630,0.003169,0.003317,0.084251,0.064583,0.003290,0.842510,-505.214630,0.085292,0.000000
5.610000,0.009682,-505.214630,0.003264,0.003416,0.086775,0.043066,0.002194,0.867748,-505.214630,0.087945,0.000000
5.770000,0.021225,-505.214630,0.003380,0.003520,0.089402,0.094413,0.004810,0.894022,-505.214630,0.090616,0.000000
5.930000,-0.036118,-505.259125,0.003492,0.003627,0.092117,-0.160659,-0.008184,0.921168,-505.259125,0.093287,0.000000
6.090000,-0.027184,-505.259125,0.003579,0.003731,0.094770,-0.120918,-0.006160,0.947704,-505.259125,0.095941,0.000000
6.250000,0.036491,-505.259125,0.003673,0.003833,0.097346,0.162322,0.008269,0.973464,-505.259125,0.098612,0.000000
6.410000,0.026436,-505.214630,0.003794,0.003942,0.100130,0.117593,0.005990,1.001302,-505.214630,0.101283,0.000000
6.570000,0.054367,-505.214630,0.003915,0.004045,0.102740,0.241837,0.012320,1.027402,-505.214630,0.103937,0.000000
6.730000,0.023834,-505.303589,0.004005,0.004154,0.105515,0.106020,0.005401,1.055153,-505.303589,0.106608,0.000000
6.890000,0.023087,-505.214630,0.004113,0.004260,0.108195,0.102694,0.005231,1.081950,-505.214630,0.109279,0.000000
7.050000,0.016754,-505.259125,0.004208,0.004363,0.110823,0.074526,0.003797,1.108229,-505.259125,0.111933,0.000000
7.210001,0.027184,-505.259125,0.004312,0.004466,0.113433,0.120918,0.006160,1.134333,-505.259125,0.114604,0.000000
7.370000,0.020477,-505.259125,0.004437,0.004573,0.116148,0.091088,0.004640,1.161478,-505.259125,0.117275,0.000000
7.530000,0.050644,-505.303589,0.004527,0.004676,0.118775,0.225275,0.011476,1.187753,-505.303589,0.119946,0.000000
7.690001,0.026436,-505.214630,0.004635,0.004784,0.121524,0.117593,0.005990,1.215243,-505.214630,0.122600,0.000000
7.850000,-0.024948,-505.303589,0.004747,0.004883,0.124039,-0.110975,-0.005653,1.240393,-505.303589,0.125271,0.000000
8.010000,-0.031654,-505.259125,0.004850,0.004990,0.126754,-0.140806,-0.007173,1.267539,-505.259125,0.127942,0.000000
8.170000,0.013031,-505.303589,0.004971,0.005096,0.129442,0.057965,0.002953,1.294423,-505.303589,0.130596,0.000000
8.330000,0.029793,-505.303589,0.005057,0.005198,0.132027,0.132525,0.006751,1.320266,-505.303589,0.133267,0.000000
8.490001,0.064423,-505.259125,0.005152,0.005305,0.134741,0.286566,0.014598,1.347411,-505.259125,0.135938,0.000000
8.650001,0.037979,-505.348083,0.005282,0.005413,0.137481,0.168940,0.008606,1.374814,-505.348083,0.138591,0.000000
8.810000,0.018616,-505.303589,0.005372,0.005517,0.140135,0.082807,0.004218,1.401350,-505.303589,0.141263,0.000000
8.970000,0.036491,-505.214630,0.005497,0.005622,0.142806,0.162322,0.008269,1.428064,-505.214630,0.143933,0.000000
9.130000,0.058090,-505.348083,0.005583,0.005727,0.145460,0.258398,0.013163,1.454599,-505.348083,0.146587,0.000000
9.290001,0.109474,-505.303589,0.005691,0.005825,0.147958,0.486965,0.024807,1.479576,-505.303589,0.149258,0.000000
9.450001,0.115807,-505.392578,0.005786,0.005935,0.150741,0.515133,0.026242,1.507414,-505.392578,0.151929,0.000000
9.610001,0.172409,-505.259125,0.005881,0.006044,0.153508,0.766914,0.039068,1.535078,-505.259125,0.154583,0.000000
9.770000,0.244278,-505.303589,0.006002,0.006146,0.156101,1.086603,0.055354,1.561008,-505.303589,0.157254,0.000000
9.930000,0.461372,-505.303589,0.006122,0.006256,0.158911,2.052287,0.104548,1.589107,-505.303589,0.159925,0.000000
10.090000,0.528397,-505.259125,0.006191,0.000011,0.000269,2.350425,0.119736,0.002691,-505.259125,0.000503,0.000000
10.250001,0.494507,-505.303589,0.006196,0.000011,0.000269,2.199676,0.112057,0.002691,-505.303589,0.000503,0.000000
10.410001,0.450943,-505.303589,0.006209,0.000011,0.000269,2.005895,0.102185,0.002691,-505.303589,0.000503,0.000000
10.570001,0.457275,-505.303589,0.006200,0.000011,0.000269,2.034063,0.103620,0.002691,-505.303589,0.000503,0.000000
10.730000,0.511642,-505.392578,0.006183,0.000011,0.000269,2.275899,0.115940,0.002691,-505.392578,0.000763,0.000000
10.890000,0.521324,-505.348083,0.006213,0.000011,0.000269,2.318966,0.118134,0.002691,-505.348083,0.001023,0.000000
11.050000,0.518715,-505.348083,0.006204,0.000011,0.000269,2.307359,0.117542,0.002691,-505.348083,0.001292,0.000000
11.210001,0.521324,-505.437042,0.006196,0.000011,0.000278,2.318966,0.118134,0.002778,-505.437042,0.001561,0.000000
11.370001,0.679207,-505.348083,0.006209,0.000032,0.000807,3.021263,0.153910,0.008066,-505.348083,0.001830,0.000000
11.530001,0.740273,-505.392578,0.006234,0.000047,0.001188,3.292897,0.167748,0.011885,-505.392578,0.002090,0.000000
11.690001,0.757034,-505.348083,0.006222,0.000055,0.001388,3.367457,0.171546,0.013879,-505.348083,0.002359,0.000000
11.850000,0.802094,-505.392578,0.006239,0.000068,0.001735,3.567890,0.181757,0.017346,-505.392578,0.002628,0.000000
12.010000,0.846771,-505.392578,0.006247,0.000078,0.001986,3.766627,0.191881,0.019863,-505.392578,0.002897,0.000000
12.170001,0.774162,-505.348083,0.006252,0.000082,0.002073,3.443646,0.175428,0.020730,-505.348083,0.003157,0.000000
12.330001,0.877312,-505.437042,0.006265,0.000098,0.002489,3.902477,0.198802,0.024889,-505.437042,0.003426,0.000000
12.490001,0.905235,-505.437042,0.006278,0.000107,0.002723,4.026688,0.205129,0.027232,-505.437042,0.003694,0.000000
12.650001,0.918266,-505.437042,0.006303,0.000116,0.002949,4.084652,0.208082,0.029488,-505.437042,0.003964,0.000000
12.810000,1.045250,-505.437042,0.006299,0.000132,0.003356,4.649504,0.236857,0.033564,-505.437042,0.004224,0.000000
12.970000,1.019180,-505.392578,0.006316,0.000138,0.003495,4.533540,0.230950,0.034950,-505.392578,0.004492,0.000000
13.130001,1.054932,-505.392578,0.006299,0.000145,0.003677,4.692570,0.239051,0.036774,-505.392578,0.004761,0.000000
13.290001,1.145416,-505.392578,0.006334,0.000157,0.003989,5.095066,0.259555,0.039893,-505.392578,0.005030,0.000000
13.450001,1.252663,-505.481537,0.006338,0.000173,0.004397,5.572122,0.283857,0.043969,-505.481537,0.005290,0.000000
13.610001,1.244843,-505.392578,0.006347,0.000181,0.004588,5.537336,0.282085,0.045877,-505.392578,0.005559,0.000000
13.770000,1.287666,-505.392578,0.006359,0.000189,0.004805,5.727826,0.291789,0.048045,-505.392578,0.005828,0.000000
13.930000,1.357666,-505.481537,0.006377,0.000201,0.005108,6.039200,0.307652,0.051081,-505.481537,0.006097,0.000000
14.090001,1.393417,-505.481537,0.006385,0.000211,0.005368,6.198230,0.315753,0.053685,-505.481537,0.006357,0.000000
14.250001,1.425072,-505.481537,0.006398,0.000221,0.005620,6.339036,0.322926,0.056198,-505.481537,0.006626,0.000000
14.410001,1.549438,-505.481537,0.006394,0.000235,0.005967,6.892247,0.351108,0.059665,-505.481537,0.006895,0.000000
14.570001,1.575134,-505.392578,0.006416,0.000242,0.006149,7.006547,0.356931,0.061489,-505.392578,0.007163,0.000000
14.730000,1.673439,-505.437042,0.006411,0.000253,0.006418,7.443829,0.379207,0.064177,-505.437042,0.007424,0.000000
14.890000,1.763184,-505.437042,0.006416,0.000262,0.006661,7.843032,0.399543,0.066607,-505.437042,0.007692,0.000000
15.050001,1.850319,-505.526001,0.006437,0.000273,0.006929,8.230630,0.419288,0.069294,-505.526001,0.007961,0.000000
15.210001,1.932983,-505.481537,0.006450,0.000283,0.007198,8.598340,0.438020,0.071981,-505.481537,0.008230,0.000000
15.370001,2.026825,-505.437042,0.006454,0.000295,0.007502,9.015768,0.459285,0.075017,-505.437042,0.008490,0.000000
15.530001,2.160873,-505.481537,0.006463,0.000310,0.007866,9.612045,0.489661,0.078658,-505.481537,0.008759,0.000000
15.690001,2.168327,-505.481537,0.006472,0.000316,0.008031,9.645202,0.491350,0.080308,-505.481537,0.009028,0.000000
15.850000,2.252480,-505.526001,0.006480,0.000326,0.008291,10.019529,0.510419,0.082908,-505.526001,0.009297,0.000000
16.010000,2.366798,-505.481537,0.006485,0.000337,0.008568,10.528045,0.536324,0.085682,-505.481537,0.009557,0.000000
16.170000,2.433456,-505.392578,0.006510,0.000349,0.008854,10.824554,0.551429,0.088544,-505.392578,0.009826,0.000000
16.330000,2.615547,-505.481537,0.006510,0.000360,0.009132,11.634535,0.592691,0.091322,-505.481537,0.010095,0.000000
16.490002,2.742523,-505.437042,0.006519,0.000370,0.009410,12.199352,0.621465,0.094096,-505.437042,0.010363,0.000000
16.650002,2.913811,-505.526001,0.006541,0.000384,0.009748,12.961277,0.660279,0.097476,-505.526001,0.010624,0.000000
16.810001,2.959991,-505.526001,0.006545,0.000392,0.009956,13.166699,0.670744,0.099558,-505.526001,0.010893,0.000000
16.970001,3.111542,-505.526001,0.006554,0.000401,0.010190,13.840829,0.705085,0.101901,-505.526001,0.011161,0.000000
17.130001,3.321938,-505.570496,0.006545,0.000413,0.010485,14.776716,0.752762,0.104849,-505.570496,0.011430,0.000000
17.290001,3.353584,-505.481537,0.006566,0.000422,0.010710,14.917488,0.759933,0.107105,-505.481537,0.011690,0.000000
17.450001,3.636589,-505.570496,0.006584,0.000438,0.011127,16.176355,0.824063,0.111268,-505.570496,0.011959,0.000000
17.610001,3.737877,-505.526001,0.006579,0.000447,0.011361,16.626907,0.847015,0.113607,-505.526001,0.012228,0.000000
17.770000,3.719627,-505.570496,0.006584,0.000454,0.011526,16.545729,0.842880,0.115258,-505.570496,0.012497,0.000000
17.930000,4.031677,-505.570496,0.006601,0.000466,0.011829,17.933796,0.913591,0.118293,-505.570496,0.012757,0.000000
18.090000,4.120674,-505.481537,0.006622,0.000475,0.012055,18.329674,0.933758,0.120545,-505.481537,0.013026,0.000000
18.250000,4.364578,-505.614960,0.006618,0.000486,0.012349,19.414614,0.989028,0.123494,-505.614960,0.013295,0.000000
18.410002,4.640503,-505.526001,0.006640,0.000501,0.012714,20.641989,1.051553,0.127138,-505.526001,0.013564,0.000000
18.570002,4.754082,-505.570496,0.006648,0.000508,0.012905,21.147211,1.077290,0.129046,-505.570496,0.013824,0.000000
18.730001,5.034477,-505.570496,0.006644,0.000520,0.013208,22.394474,1.140829,0.132081,-505.570496,0.014093,0.000000
18.890001,5.199066,-505.481537,0.006653,0.000529,0.013425,23.126602,1.178125,0.134250,-505.481537,0.014361,0.000000
19.050001,5.453766,-505.570496,0.006661,0.000539,0.013702,24.259562,1.235841,0.137025,-505.570496,0.014630,0.000000
19.210001,5.832100,-505.526001,0.006657,0.000554,0.014084,25.942476,1.321573,0.140840,-505.526001,0.014891,0.000000
19.370001,5.997429,-505.570496,0.006700,0.000565,0.014344,26.677896,1.359037,0.143440,-505.570496,0.015159,0.000000
19.530001,6.210426,-505.614960,0.006700,0.000575,0.014613,27.625357,1.407303,0.146131,-505.614960,0.015428,0.000000
19.690001,6.379860,-505.526001,0.006700,0.000582,0.014795,28.379034,1.445697,0.147952,-505.526001,0.015697,0.000000
19.850000,6.634560,-505.570496,0.006700,0.000593,0.015064,29.511995,1.503413,0.150639,-505.570496,0.015957,0.000000
20.010000,6.762657,-505.570496,0.006704,0.000602,0.015281,30.081802,1.532440,0.152808,-505.570496,0.016226,0.000000
20.170000,7.228867,-505.614960,0.006735,0.000616,0.015636,32.155605,1.638085,0.156362,-505.614960,0.016495,0.000000
20.330002,7.524529,-505.659454,0.006726,0.000627,0.015931,33.470776,1.705083,0.159310,-505.659454,0.016764,0.000000
20.490002,7.797478,-505.570496,0.006752,0.000637,0.016174,34.684914,1.766934,0.161740,-505.570496,0.017024,0.000000
20.650002,8.077873,-505.614960,0.006748,0.000647,0.016443,35.932175,1.830472,0.164427,-505.614960,0.017293,0.000000
20.810001,8.158684,-505.659454,0.006752,0.000651,0.016547,36.291637,1.848784,0.165468,-505.659454,0.017562,0.000000
20.970001,8.358643,-505.614960,0.006765,0.000662,0.016816,37.181099,1.894096,0.168155,-505.614960,0.017830,0.000000
21.130001,8.741440,-505.659454,0.006748,0.000669,0.016989,38.883865,1.980839,0.169893,-505.659454,0.018091,0.000000
21.290001,9.619125,-505.614960,0.006769,0.000689,0.017509,42.788006,2.179725,0.175093,-505.614960,0.018359,0.000000
21.450001,9.775146,-505.659454,0.006778,0.000698,0.017726,43.482021,2.215080,0.177262,-505.659454,0.018628,0.000000
21.610001,9.908829,-505.614960,0.006795,0.000705,0.017917,44.076672,2.245373,0.179169,-505.614960,0.018897,0.000000
21.770000,10.229446,-505.659454,0.006808,0.000716,0.018186,45.502850,2.318026,0.181860,-505.659454,0.019157,0.000000
21.930000,10.730659,-505.614960,0.006799,0.000728,0.018490,47.732357,2.431602,0.184896,-505.614960,0.019426,0.000000
22.090000,11.025948,-505.703918,0.006817,0.000737,0.018732,49.045864,2.498516,0.187322,-505.703918,0.019695,0.000000
22.250002,11.242294,-505.703918,0.006825,0.000749,0.019036,50.008224,2.547540,0.190358,-505.703918,0.019964,0.000000
22.410002,11.654884,-505.659454,0.006825,0.000756,0.019200,51.843513,2.641035,0.192004,-505.659454,0.020224,0.000000
22.570002,12.390694,-505.659454,0.006825,0.000774,0.019660,55.116558,2.807771,0.196603,-505.659454,0.020493,0.000000
22.730001,12.600708,-505.659454,0.006838,0.000780,0.019807,56.050747,2.855361,0.198075,-505.659454,0.020762,0.000000
22.890001,12.887436,-505.614960,0.006860,0.000788,0.020024,57.326180,2.920335,0.200244,-505.614960,0.021030,0.000000
23.050001,12.990211,-505.703918,0.006851,0.000794,0.020172,57.783348,2.943624,0.201720,-505.703918,0.021299,0.000000
23.210001,13.659363,-505.703918,0.006864,0.000807,0.020501,60.759880,3.095256,0.205013,-505.703918,0.021560,0.000000
23.370001,14.358681,-505.703918,0.006868,0.000822,0.020874,63.870602,3.253723,0.208745,-505.703918,0.021828,0.000000
23.530001,14.494972,-505.703918,0.006864,0.000830,0.021074,64.476860,3.284608,0.210739,-505.703918,0.022097,0.000000
23.690001,15.133217,-505.659454,0.006877,0.000843,0.021403,67.315910,3.429236,0.214032,-505.659454,0.022366,0.000000
23.850000,15.543198,-505.703918,0.006894,0.000854,0.021681,69.139595,3.522139,0.216806,-505.703918,0.022626,0.000000
24.010000,15.745399,-505.659454,0.006898,0.000862,0.021889,70.039032,3.567959,0.218888,-505.659454,0.022895,0.000000
24.170002,16.193733,-505.703918,0.006907,0.000874,0.022201,72.033325,3.669552,0.222011,-505.703918,0.023164,0.000000
24.330002,16.911667,-505.703918,0.006907,0.000886,0.022505,75.226852,3.832238,0.225046,-505.703918,0.023433,0.000000
24.490002,17.456078,-505.703918,0.006920,0.000897,0.022782,77.648514,3.955604,0.227820,-505.703918,0.023693,0.000000
24.650002,17.675034,-505.748413,0.006933,0.000904,0.022973,78.622475,4.005220,0.229732,-505.748413,0.023962,0.000000
24.810001,18.035484,-505.659454,0.006937,0.000913,0.023198,80.225838,4.086899,0.231984,-505.659454,0.024231,0.000000
24.970001,18.226517,-505.792908,0.006950,0.000919,0.023337,81.075592,4.130188,0.233373,-505.792908,0.024499,0.000000
25.130001,18.319611,-505.748413,0.006937,0.000923,0.023433,81.489700,4.151283,0.234327,-505.748413,0.024760,0.000000
25.290001,19.587166,-505.659454,0.006963,0.000946,0.024040,87.128067,4.438515,0.240398,-505.659454,0.025028,0.000000
25.450001,20.280891,-505.837372,0.006954,0.000959,0.024361,90.213913,4.595716,0.243607,-505.837372,0.025297,0.000000
25.610001,20.661087,-505.748413,0.006959,0.000970,0.024629,91.905106,4.681870,0.246294,-505.748413,0.025566,0.000000
25.770000,21.058777,-505.792908,0.006985,0.000980,0.024881,93.674118,4.771987,0.248808,-505.792908,0.025826,0.000000
25.930000,21.250175,-505.703918,0.006976,0.000986,0.025054,94.525505,4.815359,0.250545,-505.703918,0.026095,0.000000
26.090002,21.607285,-505.703918,0.006989,0.000994,0.025254,96.113998,4.896281,0.252540,-505.703918,0.026364,0.000000
26.250002,22.474915,-505.881866,0.006980,0.001012,0.025696,99.973412,5.092889,0.256960,-505.881866,0.026633,0.000000
26.410002,23.102730,-505.703918,0.007006,0.001022,0.025948,102.766075,5.235153,0.259477,-505.703918,0.026893,0.000000
26.570002,23.425949,-505.792908,0.007002,0.001031,0.026190,104.203827,5.308396,0.261903,-505.792908,0.027162,0.000000
26.730001,23.774864,-505.792908,0.007011,0.001037,0.026329,105.755875,5.387461,0.263292,-505.792908,0.027431,0.000000
26.890001,24.364326,-505.792908,0.007006,0.001048,0.026607,108.377937,5.521035,0.266067,-505.792908,0.027699,0.000000
27.050001,25.528366,-505.792908,0.007028,0.001067,0.027092,113.555847,5.784810,0.270923,-505.792908,0.027959,0.000000
27.210001,25.922333,-505.792908,0.007023,0.001078,0.027378,115.308296,5.874085,0.273784,-505.792908,0.028229,0.000000
27.370001,26.449242,-505.837372,0.007041,0.001089,0.027656,117.652100,5.993484,0.276558,-505.837372,0.028497,0.000000
27.530001,26.785866,-505.748413,0.007045,0.001097,0.027873,119.149483,6.069764,0.278727,-505.748413,0.028766,0.000000
27.690001,27.340332,-505.837372,0.007041,0.001110,0.028194,121.615868,6.195408,0.281937,-505.837372,0.029026,0.000000
27.850000,27.749939,-505.881866,0.007045,0.001116,0.028358,123.437897,6.288226,0.283583,-505.881866,0.029295,0.000000
28.010002,27.907082,-505.748413,0.007058,0.001122,0.028489,124.136902,6.323835,0.284885,-505.748413,0.029564,0.000000
28.170002,29.055107,-505.881866,0.007067,0.001140,0.028957,129.243576,6.583982,0.289567,-505.881866,0.029833,0.000000
28.330002,29.551849,-505.792908,0.007080,0.001149,0.029191,131.453186,6.696545,0.291910,-505.792908,0.030093,0.000000
28.490002,29.651276,-505.837372,0.007088,0.001154,0.029304,131.895462,6.719075,0.293038,-505.837372,0.030362,0.000000
28.650002,30.219887,-505.881866,0.007084,0.001165,0.029599,134.424774,6.847924,0.295986,-505.881866,0.030631,0.000000
28.810001,31.285248,-505.837372,0.007105,0.001183,0.030058,139.163727,7.089339,0.300581,-505.837372,0.030900,0.000000
28.970001,31.994987,-505.837372,0.007101,0.001192,0.030284,142.320816,7.250168,0.302837,-505.837372,0.031160,0.000000
29.130001,32.437737,-505.792908,0.007118,0.001204,0.030570,144.290253,7.350496,0.305698,-505.792908,0.031428,0.000000
29.290001,33.003746,-505.837372,0.007123,0.001214,0.030839,146.807999,7.478756,0.308386,-505.837372,0.031697,0.000000
29.450001,33.459900,-505.837372,0.007110,0.001223,0.031055,148.837067,7.582122,0.310554,-505.837372,0.031966,0.000000
29.610001,33.952919,-505.837372,0.007127,0.001235,0.031359,151.030121,7.693841,0.313590,-505.837372,0.032226,0.000000
29.770002,34.328270,-505.881866,0.007118,0.001242,0.031541,152.699768,7.778897,0.315410,-505.881866,0.032495,0.000000
29.930002,34.431419,-505.837372,0.007127,0.001247,0.031663,153.158600,7.802271,0.316625,-505.837372,0.032764,0.000000
30.090002,35.612961,-505.837372,0.007140,0.001265,0.032139,158.414368,8.070012,0.321394,-505.837372,0.033033,0.000000
30.250002,36.448563,-505.881866,0.007140,0.001275,0.032391,162.131302,8.259362,0.323911,-505.881866,0.033293,0.000000
30.410002,36.904343,-505.837372,0.007148,0.001285,0.032634,164.158722,8.362643,0.326337,-505.837372,0.033562,0.000000
30.570002,37.148994,-505.837372,0.007157,0.001291,0.032790,165.246979,8.418082,0.327901,-505.837372,0.033831,0.000000
30.730001,37.650581,-505.837372,0.007170,0.001301,0.033041,167.478149,8.531744,0.330414,-505.837372,0.034100,0.000000
30.890001,38.669022,-505.837372,0.007166,0.001316,0.033423,172.008392,8.762526,0.334229,-505.837372,0.034360,0.000000
31.050001,39.509087,-505.926331,0.007166,0.001329,0.033753,175.745193,8.952888,0.337526,-505.926331,0.034628,0.000000
31.210001,40.000992,-505.837372,0.007179,0.001338,0.033996,177.933304,9.064355,0.339955,-505.837372,0.034897,0.000000
31.370001,40.707016,-505.881866,0.007179,0.001350,0.034299,181.073853,9.224341,0.342991,-505.881866,0.035166,0.000000
31.530001,41.036560,-505.881866,0.007183,0.001360,0.034533,182.539734,9.299017,0.345330,-505.881866,0.035426,0.000000
31.690002,41.760452,-505.926331,0.007196,0.001369,0.034785,185.759766,9.463054,0.347847,-505.926331,0.035695,0.000000
31.850002,42.041595,-505.926331,0.007200,0.001376,0.034941,187.010361,9.526762,0.349406,-505.926331,0.035964,0.000000
32.010002,42.247147,-505.881866,0.007213,0.001386,0.035201,187.924698,9.573340,0.352010,-505.881866,0.036233,0.000000
32.170002,43.565720,-505.926331,0.007217,0.001402,0.035600,193.789993,9.872133,0.356000,-505.926331,0.036493,0.000000
32.330002,44.071770,-505.837372,0.007217,0.001408,0.035756,196.041016,9.986806,0.357559,-505.837372,0.036762,0.000000
32.490002,44.365944,-505.881866,0.007222,0.001414,0.035912,197.349579,10.053467,0.359118,-505.881866,0.037031,0.000000
32.650002,44.699219,-505.970825,0.007226,0.001426,0.036215,198.832062,10.128988,0.362154,-505.970825,0.037299,0.000000
32.810001,45.938103,-505.970825,0.007239,0.001442,0.036614,204.342880,10.409722,0.366143,-505.970825,0.037560,0.000000
32.970001,46.847435,-506.015289,0.007230,0.001451,0.036857,208.387802,10.615781,0.368573,-506.015289,0.037829,0.000000
33.130001,47.636864,-505.926331,0.007243,0.001464,0.037187,211.899353,10.794667,0.371870,-505.926331,0.038097,0.000000
33.290001,48.276970,-505.881866,0.007252,0.001473,0.037403,214.746689,10.939717,0.374035,-505.881866,0.038366,0.000000
33.450001,48.551781,-505.926331,0.007248,0.001479,0.037568,215.969101,11.001991,0.375685,-505.926331,0.038626,0.000000
33.610001,49.411591,-505.881866,0.007261,0.001493,0.037915,219.793732,11.196826,0.379152,-505.881866,0.038895,0.000000
33.770000,49.862534,-505.970825,0.007243,0.001500,0.038089,221.799622,11.299011,0.380889,-505.970825,0.039164,0.000000
33.930000,50.454231,-505.881866,0.007261,0.001510,0.038358,224.431625,11.433092,0.383576,-505.881866,0.039433,0.000000
34.090000,51.724770,-505.970825,0.007265,0.001527,0.038774,230.083267,11.721001,0.387740,-505.970825,0.039693,0.000000
34.250000,52.226357,-505.926331,0.007269,0.001533,0.038939,232.314438,11.834661,0.389386,-505.926331,0.039962,0.000000
34.410000,52.458717,-506.015289,0.007291,0.001538,0.039078,233.348022,11.887315,0.390775,-506.015289,0.040231,0.000000
34.570004,53.407150,-506.059784,0.007282,0.001551,0.039407,237.566864,12.102233,0.394068,-506.059784,0.040500,0.000000
34.730003,53.902031,-506.015289,0.007291,0.001560,0.039632,239.768204,12.214375,0.396324,-506.015289,0.040760,0.000000
34.890003,55.029945,-505.926331,0.007299,0.001575,0.040005,244.785416,12.469964,0.400052,-505.926331,0.041029,0.000000
35.050003,55.673409,-505.926331,0.007295,0.001584,0.040222,247.647690,12.615775,0.402221,-505.926331,0.041297,0.000000
35.210003,56.872818,-505.881866,0.007299,0.001598,0.040586,252.982925,12.887565,0.405862,-505.881866,0.041566,0.000000
35.370003,57.419830,-506.015289,0.007291,0.001607,0.040820,255.416168,13.011519,0.408205,-506.015289,0.041826,0.000000
35.530003,58.002594,-505.970825,0.007299,0.001618,0.041089,258.008423,13.143576,0.410892,-505.970825,0.042095,0.000000
35.690002,58.207771,-506.015289,0.007317,0.001623,0.041219,258.921112,13.190069,0.412194,-506.015289,0.042364,0.000000
35.850002,59.531181,-506.015289,0.007308,0.001637,0.041575,264.807922,13.489958,0.415748,-506.015289,0.042633,0.000000
36.010002,60.247261,-505.926331,0.007321,0.001647,0.041826,267.993195,13.652225,0.418265,-505.926331,0.042893,0.000000
36.170002,60.867630,-506.059784,0.007321,0.001657,0.042095,270.752747,13.792802,0.420952,-506.059784,0.043162,0.000000
36.330002,61.692810,-505.970825,0.007330,0.001667,0.042338,274.423340,13.979790,0.423382,-505.970825,0.043431,0.000000
36.490002,62.303871,-506.104248,0.007330,0.001677,0.042598,277.141449,14.118258,0.425982,-506.104248,0.043700,0.000000
36.650002,62.993134,-506.104248,0.007330,0.001683,0.042755,280.207458,14.274448,0.427546,-506.104248,0.043960,0.000000
36.810001,64.366821,-506.015289,0.007347,0.001704,0.043283,286.317932,14.585731,0.432833,-506.015289,0.044229,0.000000
36.970001,65.315247,-506.059784,0.007351,0.001713,0.043500,290.536713,14.800647,0.435002,-506.059784,0.044497,0.000000
37.130001,65.801193,-506.015289,0.007338,0.001720,0.043682,292.698334,14.910763,0.436822,-506.015289,0.044766,0.000000
37.290001,66.447266,-506.104248,0.007360,0.001730,0.043934,295.572205,15.057165,0.439339,-506.104248,0.045027,0.000000
37.450001,67.523788,-506.015289,0.007351,0.001736,0.044099,300.360809,15.301109,0.440986,-506.015289,0.045269,0.000000
37.610001,67.068008,-506.015289,0.007360,0.001733,0.044012,298.333405,15.197828,0.440119,-506.015289,0.044246,0.000000
37.770000,66.768616,-506.059784,0.007364,0.001733,0.044012,297.001648,15.129984,0.440119,-506.059784,0.044246,0.000000
37.930000,66.604034,-506.059784,0.007364,0.001732,0.043986,296.269531,15.092690,0.439858,-506.059784,0.044012,0.000000
38.090000,66.388046,-506.104248,0.007368,0.001731,0.043960,295.308777,15.043747,0.439597,-506.104248,0.044012,0.000000
38.250000,66.182495,-506.104248,0.007373,0.001730,0.043943,294.394440,14.997168,0.439426,-506.104248,0.044012,0.000000
38.410004,66.025360,-506.059784,0.007390,0.001730,0.043934,293.695465,14.961560,0.439339,-506.059784,0.044012,0.000000
38.570004,65.873810,-506.015289,0.007368,0.001729,0.043925,293.021332,14.927218,0.439252,-506.015289,0.044012,0.000000
38.730003,65.733047,-506.059784,0.007377,0.001729,0.043925,292.395203,14.895322,0.439252,-506.059784,0.044012,0.000000
38.890003,65.623566,-506.059784,0.007368,0.001729,0.043925,291.908203,14.870512,0.439252,-506.059784,0.044012,0.000000
39.050003,65.512238,-506.104248,0.007386,0.001729,0.043917,291.412994,14.845285,0.439165,-506.104248,0.044012,0.000000
39.210003,65.395309,-506.059784,0.007377,0.001729,0.043917,290.892853,14.818789,0.439165,-506.059784,0.044012,0.000000
39.370003,65.310410,-506.148743,0.007386,0.001729,0.043917,290.515198,14.799551,0.439165,-506.148743,0.044012,0.000000
39.530003,65.236298,-506.104248,0.007386,0.001729,0.043917,290.185547,14.782756,0.439165,-506.104248,0.044012,0.000000
39.690002,65.135391,-506.148743,0.007390,0.001729,0.043917,289.736694,14.759891,0.439165,-506.148743,0.044012,0.000000
39.850002,65.067612,-506.059784,0.007368,0.001729,0.043917,289.435181,14.744532,0.439165,-506.059784,0.044012,0.000000
40.010002,65.000961,-506.148743,0.007386,0.001729,0.043917,289.138702,14.729428,0.439165,-506.148743,0.044012,0.000000
40.170002,64.916809,-506.148743,0.007373,0.001729,0.043908,288.764374,14.710359,0.439078,-506.148743,0.044012,0.000000
40.330002,64.856857,-506.104248,0.007381,0.001729,0.043908,288.497711,14.696774,0.439078,-506.104248,0.044012,0.000000
40.490002,64.792068,-506.148743,0.007386,0.001729,0.043908,288.209503,14.682093,0.439078,-506.148743,0.044012,0.000000
40.650002,64.738815,-506.148743,0.007386,0.001729,0.043908,287.972626,14.670026,0.439078,-506.148743,0.044012,0.000000
40.810001,64.700089,-506.193237,0.007377,0.001729,0.043908,287.800354,14.661249,0.439078,-506.193237,0.044012,0.000000
40.970001,64.635300,-506.193237,0.007377,0.001729,0.043908,287.512177,14.646568,0.439078,-506.193237,0.044012,0.000000
41.130001,64.606995,-506.104248,0.007377,0.001729,0.043908,287.386261,14.640154,0.439078,-506.104248,0.044012,0.000000
41.290001,64.548157,-506.148743,0.007377,0.001729,0.043908,287.124542,14.626822,0.439078,-506.148743,0.044012,0.000000
41.450001,64.497894,-506.104248,0.007390,0.001729,0.043908,286.900970,14.615432,0.439078,-506.104248,0.044012,0.000000
41.610001,64.443527,-506.193237,0.007390,0.001729,0.043908,286.659119,14.603112,0.439078,-506.193237,0.044012,0.000000
41.770000,64.403305,-506.193237,0.007381,0.001729,0.043908,286.480194,14.593997,0.439078,-506.193237,0.044012,0.000000
41.930000,64.365326,-506.148743,0.007386,0.001729,0.043908,286.311279,14.585391,0.439078,-506.148743,0.044012,0.000000
42.090000,64.331436,-506.148743,0.007368,0.001729,0.043908,286.160522,14.577712,0.439078,-506.148743,0.044012,0.000000
42.250004,64.295319,-506.193237,0.007377,0.001729,0.043908,285.999847,14.569528,0.439078,-506.193237,0.044012,0.000000
42.410004,64.249893,-506.148743,0.007390,0.001729,0.043908,285.797791,14.559235,0.439078,-506.148743,0.044012,0.000000
42.570004,64.218979,-506.237701,0.007377,0.001729,0.043908,285.660278,14.552229,0.439078,-506.237701,0.044012,0.000000
42.730003,64.197388,-506.148743,0.007394,0.001729,0.043908,285.564240,14.547337,0.439078,-506.148743,0.044012,0.000000
42.890003,64.154556,-506.237701,0.007386,0.001729,0.043908,285.373718,14.537631,0.439078,-506.237701,0.044012,0.000000
43.050003,64.124405,-506.148743,0.007377,0.001729,0.043908,285.239594,14.530798,0.439078,-506.148743,0.044012,0.000000
43.210003,64.085678,-506.237701,0.007381,0.001729,0.043908,285.067322,14.522022,0.439078,-506.237701,0.044012,0.000000
43.370003,64.063324,-506.193237,0.007373,0.001729,0.043908,284.967896,14.516956,0.439078,-506.193237,0.044012,0.000000
43.530003,64.033173,-506.237701,0.007390,0.001729,0.043908,284.833771,14.510124,0.439078,-506.237701,0.044012,0.000000
43.690002,64.003372,-506.237701,0.007381,0.001729,0.043908,284.701233,14.503371,0.439078,-506.237701,0.044012,0.000000
43.850002,63.969116,-506.237701,0.007377,0.001729,0.043908,284.548828,14.495609,0.439078,-506.237701,0.044012,0.000000
44.010002,63.943802,-506.282196,0.007386,0.001729,0.043908,284.436249,14.489873,0.439078,-506.282196,0.044012,0.000000
44.170002,63.915131,-506.237701,0.007373,0.001728,0.043899,284.308685,14.483376,0.438991,-506.237701,0.044012,0.000000
44.330002,63.895767,-506.237701,0.007399,0.001728,0.043899,284.222565,14.478988,0.438991,-506.237701,0.044012,0.000000
44.490002,63.860016,-506.282196,0.007381,0.001728,0.043899,284.063538,14.470887,0.438991,-506.282196,0.044012,0.000000
44.650002,63.848465,-506.237701,0.007386,0.001728,0.043899,284.012146,14.468268,0.438991,-506.237701,0.044012,0.000000
44.810001,63.822403,-506.282196,0.007390,0.001728,0.043899,283.896240,14.462363,0.438991,-506.282196,0.044012,0.000000
44.970001,63.798950,-506.326660,0.007386,0.001728,0.043899,283.791901,14.457048,0.438991,-506.326660,0.044012,0.000000
45.130001,63.779205,-506.193237,0.007399,0.001728,0.043899,283.704071,14.452575,0.438991,-506.193237,0.044012,0.000000
45.290001,63.747559,-506.282196,0.007394,0.001728,0.043899,283.563293,14.445403,0.438991,-506.282196,0.044012,0.000000
45.450001,63.730804,-506.237701,0.007386,0.001728,0.043899,283.488770,14.441607,0.438991,-506.237701,0.044012,0.000000
45.610001,63.710327,-506.282196,0.007390,0.001728,0.043899,283.397675,14.436966,0.438991,-506.282196,0.044012,0.000000
45.770000,63.690964,-506.326660,0.007390,0.001728,0.043899,283.311554,14.432579,0.438991,-506.326660,0.044012,0.000000
45.930000,63.670105,-506.237701,0.007390,0.001728,0.043899,283.218781,14.427852,0.438991,-506.237701,0.044012,0.000000
46.090004,63.649628,-506.282196,0.007386,0.001728,0.043899,283.127686,14.423211,0.438991,-506.282196,0.044012,0.000000
46.250004,63.623566,-506.193237,0.007386,0.001728,0.043899,283.011749,14.417306,0.438991,-506.193237,0.044012,0.000000
46.410004,63.609406,-506.282196,0.007386,0.001728,0.043899,282.948761,14.414097,0.438991,-506.282196,0.044012,0.000000
46.570004,63.604568,-506.237701,0.007381,0.001728,0.043899,282.927246,14.413001,0.438991,-506.237701,0.044012,0.000000
46.730003,63.588562,-506.237701,0.007394,0.001728,0.043899,282.856049,14.409374,0.438991,-506.237701,0.044012,0.000000
46.890003,63.556152,-506.371155,0.007390,0.001728,0.043899,282.711884,14.402030,0.438991,-506.371155,0.044012,0.000000
47.050003,63.537918,-506.282196,0.007394,0.001728,0.043899,282.630768,14.397899,0.438991,-506.282196,0.044012,0.000000
47.210003,63.521149,-506.326660,0.007407,0.001728,0.043899,282.556183,14.394098,0.438991,-506.326660,0.044012,0.000000
47.370003,63.512222,-506.415619,0.007394,0.001728,0.043899,282.516479,14.392076,0.438991,-506.415619,0.044012,0.000000
47.530003,63.480942,-506.237701,0.007399,0.001728,0.043899,282.377319,14.384987,0.438991,-506.237701,0.044012,0.000000
47.690002,63.470886,-506.326660,0.007377,0.001728,0.043899,282.332611,14.382709,0.438991,-506.326660,0.044012,0.000000
47.850002,63.449661,-506.282196,0.007377,0.001728,0.043899,282.238190,14.377898,0.438991,-506.282196,0.044012,0.000000
48.010002,63.462692,-506.371155,0.007394,0.001728,0.043899,282.296143,14.380852,0.438991,-506.371155,0.044012,0.000000
48.170002,63.431412,-506.371155,0.007394,0.001728,0.043899,282.157013,14.373763,0.438991,-506.371155,0.044012,0.000000
48.330002,63.417633,-506.326660,0.007399,0.001728,0.043899,282.095734,14.370642,0.438991,-506.326660,0.044012,0.000000
48.490002,63.396408,-506.371155,0.007373,0.001728,0.043899,282.001312,14.365831,0.438991,-506.371155,0.044012,0.000000
48.650002,63.394928,-506.326660,0.007403,0.001728,0.043899,281.994720,14.365497,0.438991,-506.326660,0.044012,0.000000
48.810001,63.362518,-506.371155,0.007390,0.001728,0.043899,281.850555,14.358152,0.438991,-506.371155,0.044012,0.000000
48.970001,63.363266,-506.371155,0.007394,0.001728,0.043899,281.853882,14.358321,0.438991,-506.371155,0.044012,0.000000
49.130001,63.352478,-506.326660,0.007407,0.001728,0.043899,281.805908,14.355877,0.438991,-506.326660,0.044012,0.000000
49.290001,63.317474,-506.460114,0.007386,0.001728,0.043899,281.650208,14.347945,0.438991,-506.460114,0.044012,0.000000
49.450001,63.320068,-506.326660,0.007386,0.001728,0.043899,281.661743,14.348533,0.438991,-506.326660,0.044012,0.000000
49.610001,63.301086,-506.415619,0.007390,0.001728,0.043899,281.577301,14.344232,0.438991,-506.415619,0.044012,0.000000
49.770000,63.283951,-506.326660,0.007394,0.001728,0.043899,281.501068,14.340348,0.438991,-506.326660,0.044012,0.000000
49.930004,63.279480,-506.415619,0.007390,0.001728,0.043899,281.481171,14.339335,0.438991,-506.415619,0.044012,0.000000
50.090004,63.256393,-506.415619,0.007377,0.001728,0.043899,281.378479,14.334104,0.438991,-506.415619,0.044012,0.000000
50.250004,63.245605,-506.371155,0.007390,0.001728,0.043899,281.330505,14.331659,0.438991,-506.371155,0.044012,0.000000
50.410004,63.235168,-506.415619,0.007381,0.001728,0.043899,281.284088,14.329293,0.438991,-506.415619,0.044012,0.000000
50.570004,63.210968,-506.371155,0.007386,0.001728,0.043899,281.176422,14.323811,0.438991,-506.371155,0.044012,0.000000
50.730003,63.209106,-506.415619,0.007403,0.001728,0.043899,281.168152,14.323388,0.438991,-506.415619,0.044012,0.000000
50.890003,63.203888,-506.460114,0.007386,0.001728,0.043899,281.144928,14.322206,0.438991,-506.460114,0.044012,0.000000
51.050003,63.172241,-506.415619,0.007403,0.001728,0.043899,281.004150,14.315034,0.438991,-506.415619,0.044012,0.000000
51.210003,63.184906,-506.415619,0.007381,0.001728,0.043899,281.060486,14.317904,0.438991,-506.415619,0.044012,0.000000
51.370003,63.178940,-506.415619,0.007390,0.001728,0.043899,281.033966,14.316552,0.438991,-506.415619,0.044012,0.000000
51.530003,63.151016,-506.371155,0.007403,0.001728,0.043899,280.909760,14.310225,0.438991,-506.371155,0.044012,0.000000
51.690002,63.137985,-506.460114,0.007399,0.001728,0.043899,280.851776,14.307272,0.438991,-506.460114,0.044012,0.000000
51.850002,63.139099,-506.371155,0.007394,0.001728,0.043899,280.856750,14.307525,0.438991,-506.371155,0.044012,0.000000
52.010002,63.119370,-506.460114,0.007403,0.001728,0.043899,280.768982,14.303053,0.438991,-506.460114,0.044012,0.000000
52.170002,63.123840,-506.415619,0.007386,0.001728,0.043899,280.788879,14.304067,0.438991,-506.415619,0.044012,0.000000
52.330002,63.098892,-506.504578,0.007394,0.001728,0.043899,280.677887,14.298413,0.438991,-506.504578,0.044012,0.000000
52.490002,63.098892,-506.460114,0.007381,0.001728,0.043899,280.677887,14.298413,0.438991,-506.460114,0.044012,0.000000
52.650002,63.091064,-506.415619,0.007399,0.001728,0.043899,280.643066,14.296639,0.438991,-506.415619,0.044012,0.000000
52.810001,63.056061,-506.504578,0.007394,0.001728,0.043899,280.487366,14.288708,0.438991,-506.504578,0.044012,0.000000
52.970001,63.072815,-506.460114,0.007390,0.001728,0.043899,280.561890,14.292504,0.438991,-506.460114,0.044012,0.000000
53.130001,63.052338,-506.460114,0.007411,0.001728,0.043899,280.470795,14.287865,0.438991,-506.460114,0.044012,0.000000
53.290001,63.047127,-506.460114,0.007390,0.001728,0.043899,280.447632,14.286683,0.438991,-506.460114,0.044012,0.000000
53.450001,63.035957,-506.460114,0.007386,0.001728,0.043899,280.397949,14.284152,0.438991,-506.460114,0.044012,0.000000
53.610004,63.011375,-506.460114,0.007399,0.001728,0.043899,280.288605,14.278582,0.438991,-506.460114,0.044012,0.000000
53.770004,63.003929,-506.504578,0.007394,0.001728,0.043899,280.255463,14.276894,0.438991,-506.504578,0.044012,0.000000
53.930004,62.989037,-506.504578,0.007411,0.001728,0.043899,280.189240,14.273520,0.438991,-506.504578,0.044012,0.000000
54.090004,62.989037,-506.504578,0.007381,0.001728,0.043899,280.189240,14.273520,0.438991,-506.504578,0.044012,0.000000
54.250004,62.991272,-506.504578,0.007381,0.001728,0.043899,280.199158,14.274026,0.438991,-506.504578,0.044012,0.000000
54.410004,62.980469,-506.504578,0.007394,0.001728,0.043899,280.151123,14.271579,0.438991,-506.504578,0.044012,0.000000
54.570004,62.968925,-506.460114,0.007399,0.001728,0.043899,280.099762,14.268962,0.438991,-506.460114,0.044012,0.000000
54.730003,62.951424,-506.504578,0.007394,0.001728,0.043899,280.021912,14.264997,0.438991,-506.504578,0.044012,0.000000
54.890003,62.954033,-506.504578,0.007390,0.001728,0.043899,280.033539,14.265588,0.438991,-506.504578,0.044012,0.000000
55.050003,62.934669,-506.504578,0.007399,0.001728,0.043899,279.947388,14.261200,0.438991,-506.504578,0.044012,0.000000
55.210003,62.928337,-506.593536,0.007394,0.001728,0.043899,279.919220,14.259765,0.438991,-506.593536,0.044012,0.000000
55.370003,62.940628,-506.504578,0.007399,0.001728,0.043899,279.973907,14.262550,0.438991,-506.504578,0.044012,0.000000
55.530003,62.906738,-506.549072,0.007403,0.001728,0.043899,279.823151,14.254870,0.438991,-506.549072,0.044012,0.000000
55.690002,62.895195,-506.504578,0.007399,0.001728,0.043899,279.771790,14.252255,0.438991,-506.504578,0.044012,0.000000
55.850002,62.902275,-506.504578,0.007403,0.001728,0.043899,279.803284,14.253860,0.438991,-506.504578,0.044012,0.000000
56.010002,62.886635,-506.593536,0.007390,0.001728,0.043899,279.733734,14.250315,0.438991,-506.593536,0.044012,0.000000
56.170002,62.879929,-506.460114,0.007381,0.001728,0.043899,279.703888,14.248796,0.438991,-506.460114,0.044012,0.000000
56.330002,62.872108,-506.549072,0.007407,0.001728,0.043899,279.669098,14.247024,0.438991,-506.549072,0.044012,0.000000
56.490002,62.863548,-506.593536,0.007390,0.001728,0.043899,279.631042,14.245084,0.438991,-506.593536,0.044012,0.000000
56.650002,62.856842,-506.549072,0.007390,0.001728,0.043899,279.601196,14.243565,0.438991,-506.549072,0.044012,0.000000
56.810001,62.841576,-506.549072,0.007399,0.001728,0.043899,279.533295,14.240105,0.438991,-506.549072,0.044012,0.000000
56.970001,62.830406,-506.593536,0.007394,0.001728,0.043899,279.483612,14.237574,0.438991,-506.593536,0.044012,0.000000
57.130001,62.837105,-506.549072,0.007386,0.001728,0.043899,279.513397,14.239092,0.438991,-506.549072,0.044012,0.000000
57.290001,62.817375,-506.593536,0.007381,0.001728,0.043899,279.425629,14.234620,0.438991,-506.593536,0.044012,0.000000
57.450005,62.824074,-506.593536,0.007399,0.001728,0.043899,279.455444,14.236138,0.438991,-506.593536,0.044012,0.000000
57.610004,62.809181,-506.682526,0.007390,0.001728,0.043899,279.389191,14.232763,0.438991,-506.682526,0.044012,0.000000
57.770004,62.793167,-506.504578,0.007399,0.001728,0.043899,279.317963,14.229136,0.438991,-506.504578,0.044012,0.000000
57.930004,62.805458,-506.593536,0.007399,0.001728,0.043899,279.372620,14.231920,0.438991,-506.593536,0.044012,0.000000
58.090004,62.786095,-506.593536,0.007403,0.001728,0.043899,279.286499,14.227532,0.438991,-506.593536,0.044012,0.000000
58.250004,62.764496,-506.549072,0.007416,0.001728,0.043899,279.190430,14.222638,0.438991,-506.549072,0.044012,0.000000
58.410004,62.767105,-506.593536,0.007399,0.001728,0.043899,279.202026,14.223229,0.438991,-506.593536,0.044012,0.000000
58.570004,62.769707,-506.593536,0.007403,0.001728,0.043899,279.213593,14.223819,0.438991,-506.593536,0.044012,0.000000
58.730003,62.739922,-506.638031,0.007394,0.001728,0.043899,279.081116,14.217070,0.438991,-506.638031,0.044012,0.000000
58.890003,62.741783,-506.549072,0.007399,0.001728,0.043899,279.089386,14.217491,0.438991,-506.549072,0.044012,0.000000
59.050003,62.749969,-506.593536,0.007407,0.001728,0.043899,279.125793,14.219346,0.438991,-506.593536,0.044012,0.000000
59.210003,62.721672,-506.682526,0.007399,0.001728,0.043899,278.999939,14.212934,0.438991,-506.682526,0.044012,0.000000
59.370003,62.723160,-506.638031,0.007399,0.001728,0.043899,279.006561,14.213271,0.438991,-506.638031,0.044012,0.000000
59.530003,62.718697,-506.593536,0.007394,0.001728,0.043899,278.986694,14.212260,0.438991,-506.593536,0.044012,0.000000
59.690002,62.710129,-506.638031,0.007407,0.001728,0.043899,278.948578,14.210319,0.438991,-506.638031,0.044012,0.000000
59.850002,62.713104,-506.593536,0.007403,0.001728,0.043899,278.961823,14.210993,0.438991,-506.593536,0.044012,0.000000
60.010002,62.690392,-506.771484,0.007390,0.001728,0.043899,278.860779,14.205846,0.438991,-506.771484,0.044012,0.000000
60.170002,62.682198,-506.638031,0.007399,0.001728,0.043899,278.824341,14.203989,0.438991,-506.638031,0.044012,0.000000
60.330002,62.680336,-506.682526,0.007394,0.001728,0.043899,278.816071,14.203567,0.438991,-506.682526,0.044012,0.000000
60.490002,62.672890,-506.682526,0.007390,0.001728,0.043899,278.782928,14.201880,0.438991,-506.682526,0.044012,0.000000
60.650002,62.670654,-506.638031,0.007403,0.001728,0.043899,278.772980,14.201373,0.438991,-506.638031,0.044012,0.000000
60.810001,62.655388,-506.682526,0.007407,0.001728,0.043899,278.705078,14.197913,0.438991,-506.682526,0.044012,0.000000
60.970001,62.656136,-506.638031,0.007403,0.001728,0.043899,278.708405,14.198083,0.438991,-506.638031,0.044012,0.000000
61.130001,62.636772,-506.726990,0.007399,0.001728,0.043899,278.622284,14.193696,0.438991,-506.726990,0.044012,0.000000
61.290005,62.621506,-506.682526,0.007386,0.001728,0.043899,278.554382,14.190236,0.438991,-506.682526,0.044012,0.000000
61.450005,62.640121,-506.638031,0.007386,0.001728,0.043899,278.637177,14.194455,0.438991,-506.638031,0.044012,0.000000
61.610004,62.619644,-506.726990,0.007390,0.001728,0.043899,278.546082,14.189814,0.438991,-506.726990,0.044012,0.000000
61.770004,62.594322,-506.638031,0.007407,0.001728,0.043899,278.433441,14.184076,0.438991,-506.638031,0.044012,0.000000
61.930004,62.620758,-506.682526,0.007407,0.001728,0.043899,278.551056,14.190066,0.438991,-506.682526,0.044012,0.000000
62.090004,62.609589,-506.682526,0.007390,0.001728,0.043899,278.501373,14.187535,0.438991,-506.682526,0.044012,0.000000
62.250004,62.589111,-506.771484,0.007407,0.001728,0.043899,278.410278,14.182895,0.438991,-506.771484,0.044012,0.000000
62.410004,62.598045,-506.726990,0.007394,0.001728,0.043899,278.450012,14.184919,0.438991,-506.726990,0.044012,0.000000
62.570004,62.589478,-506.726990,0.007407,0.001728,0.043899,278.411896,14.182979,0.438991,-506.726990,0.044012,0.000000
62.730003,62.580544,-506.771484,0.007403,0.001728,0.043899,278.372162,14.180954,0.438991,-506.771484,0.044012,0.000000
62.890003,62.571236,-506.771484,0.007394,0.001728,0.043899,278.330750,14.178844,0.438991,-506.771484,0.044012,0.000000
63.050003,62.574959,-506.682526,0.007403,0.001728,0.043899,278.347321,14.179688,0.438991,-506.682526,0.044012,0.000000
63.210003,62.557083,-506.726990,0.007403,0.001728,0.043899,278.267792,14.175638,0.438991,-506.726990,0.044012,0.000000
63.370003,62.554848,-506.726990,0.007407,0.001728,0.043899,278.257874,14.175132,0.438991,-506.726990,0.044012,0.000000
63.530003,62.551498,-506.771484,0.007403,0.001728,0.043899,278.242950,14.174373,0.438991,-506.771484,0.044012,0.000000
63.690002,62.537720,-506.726990,0.007390,0.001728,0.043899,278.181671,14.171250,0.438991,-506.726990,0.044012,0.000000
63.850002,62.541069,-506.726990,0.007403,0.001728,0.043899,278.196564,14.172009,0.438991,-506.726990,0.044012,0.000000
64.010002,62.536972,-506.815948,0.007407,0.001728,0.043899,278.178345,14.171081,0.438991,-506.815948,0.044012,0.000000
64.170006,62.521706,-506.682526,0.007411,0.001728,0.043899,278.110443,14.167621,0.438991,-506.682526,0.044012,0.000000
64.330002,62.535484,-506.771484,0.007403,0.001728,0.043899,278.171722,14.170744,0.438991,-506.771484,0.044012,0.000000
64.490005,62.530647,-506.771484,0.007403,0.001728,0.043899,278.150208,14.169647,0.438991,-506.771484,0.044012,0.000000
64.650002,62.505699,-506.815948,0.007399,0.001728,0.043899,278.039246,14.163994,0.438991,-506.815948,0.044012,0.000000
64.810005,62.506439,-506.771484,0.007390,0.001728,0.043899,278.042542,14.164162,0.438991,-506.771484,0.044012,0.000000
64.970001,62.508301,-506.726990,0.007390,0.001728,0.043899,278.050812,14.164583,0.438991,-506.726990,0.044012,0.000000
65.130005,62.496758,-506.815948,0.007407,0.001728,0.043899,277.999451,14.161967,0.438991,-506.815948,0.044012,0.000000
65.290001,62.490799,-506.815948,0.007381,0.001728,0.043899,277.972961,14.160618,0.438991,-506.815948,0.044012,0.000000
65.450005,62.480377,-506.860443,0.007411,0.001728,0.043899,277.926605,14.158256,0.438991,-506.860443,0.044012,0.000000
65.610001,62.480751,-506.726990,0.007386,0.001728,0.043899,277.928253,14.158340,0.438991,-506.726990,0.044012,0.000000
65.770004,62.478142,-506.815948,0.007394,0.001728,0.043899,277.916656,14.157750,0.438991,-506.815948,0.044012,0.000000
65.930000,62.475533,-506.771484,0.007411,0.001728,0.043899,277.905060,14.157158,0.438991,-506.771484,0.044012,0.000000
66.090004,62.472557,-506.815948,0.007386,0.001728,0.043899,277.891815,14.156485,0.438991,-506.815948,0.044012,0.000000
66.250000,62.460640,-506.726990,0.007403,0.001728,0.043899,277.838806,14.153784,0.438991,-506.726990,0.044012,0.000000
66.410004,62.452446,-506.860443,0.007399,0.001728,0.043899,277.802368,14.151927,0.438991,-506.860443,0.044012,0.000000
66.570000,62.453194,-506.815948,0.007403,0.001728,0.043899,277.805695,14.152096,0.438991,-506.815948,0.044012,0.000000
66.730003,62.444626,-506.860443,0.007403,0.001728,0.043899,277.767578,14.150155,0.438991,-506.860443,0.044012,0.000000
66.889999,62.446861,-506.815948,0.007411,0.001728,0.043899,277.777527,14.150661,0.438991,-506.815948,0.044012,0.000000
67.050003,62.443512,-506.815948,0.007394,0.001728,0.043899,277.762604,14.149902,0.438991,-506.815948,0.044012,0.000000
67.210007,62.429359,-506.904907,0.007394,0.001728,0.043899,277.699646,14.146695,0.438991,-506.904907,0.044012,0.000000
67.370003,62.442764,-506.815948,0.007399,0.001728,0.043899,277.759277,14.149733,0.438991,-506.815948,0.044012,0.000000
67.530006,62.433456,-506.860443,0.007407,0.001728,0.043899,277.717896,14.147624,0.438991,-506.860443,0.044012,0.000000
67.690002,62.419678,-506.815948,0.007403,0.001728,0.043899,277.656586,14.144501,0.438991,-506.815948,0.044012,0.000000
67.850006,62.426010,-506.860443,0.007386,0.001728,0.043899,277.684753,14.145936,0.438991,-506.860443,0.044012,0.000000
68.000000,62.417068,-506.815948,0.007407,0.001728,0.043899,277.644989,14.143909,0.438991,-506.815948,0.044012,0.000000