File: Data/AG AL compression 300N/AD membrane Unpeeled 300N_1_1_03202024_202455.csv
Time (sec),S:Load (lbs),S:HL1 (DIM),S:LVDT (in),S:Position (in),Ch:Position (mm),Ch:Load (N),Ch:Stress (MPa),Ch:Strain (mm/mm),Ch:HL1 (DIM),Set Point (),Cycles ()
0.010000,0.012665,-568.599976,0.000000,-0.000000,-0.000000,0.056336,0.002870,-0.000000,-568.599976,0.000217,0.000000
0.150000,0.011917,-568.599976,0.000000,-0.000000,-0.000000,0.053010,0.002700,-0.000000,-568.599976,0.000217,0.000000
0.290000,0.018250,-568.555542,0.000013,-0.000000,-0.000000,0.081178,0.004135,-0.000000,-568.555542,0.000217,0.000000
0.430000,0.002609,-568.644470,0.000004,0.000046,0.001179,0.011607,0.000591,0.011794,-568.644470,0.001813,0.000000
0.570000,-0.003723,-568.644470,0.000009,0.000122,0.003096,-0.016561,-0.000844,0.030960,-568.644470,0.004137,0.000000
0.710000,0.029045,-568.555542,0.000078,0.000210,0.005334,0.129199,0.006582,0.053337,-568.555542,0.006478,0.000000
0.850000,-0.016006,-568.599976,0.000177,0.000304,0.007710,-0.071200,-0.003627,0.077098,-568.599976,0.008803,0.000000
0.990000,0.008942,-568.555542,0.000267,0.000394,0.010008,0.039774,0.002026,0.100080,-568.555542,0.011126,0.000000
1.130000,0.008942,-568.599976,0.000336,0.000480,0.012185,0.039774,0.002026,0.121847,-568.599976,0.013468,0.000000
1.270000,0.015640,-568.599976,0.000440,0.000579,0.014699,0.069571,0.003544,0.146994,-568.599976,0.015792,0.000000
1.410000,-0.015266,-568.599976,0.000530,0.000666,0.016920,-0.067908,-0.003459,0.169196,-568.599976,0.018134,0.000000
1.550000,-0.013405,-568.644470,0.000647,0.000769,0.019530,-0.059628,-0.003038,0.195301,-568.644470,0.020458,0.000000
1.690000,0.035004,-568.599976,0.000729,0.000850,0.021585,0.155704,0.007932,0.215853,-568.599976,0.022799,0.000000
1.830000,0.021225,-568.644470,0.000811,0.000943,0.023944,0.094413,0.004810,0.239444,-568.644470,0.025124,0.000000
1.970000,0.117676,-568.644470,0.000931,0.001039,0.026399,0.523448,0.026666,0.263985,-568.644470,0.027465,0.000000
2.110000,0.449829,-568.599976,0.001000,0.001131,0.028731,2.000940,0.101933,0.287311,-568.599976,0.029789,0.000000
2.250000,0.659103,-568.644470,0.001069,-0.000008,-0.000199,2.931838,0.149355,-0.001995,-568.644470,0.000026,0.000000
2.390000,0.634529,-568.511047,0.001052,-0.000008,-0.000199,2.822526,0.143786,-0.001995,-568.511047,0.000026,0.000000
2.530000,0.622978,-568.644470,0.001069,-0.000008,-0.000199,2.771146,0.141169,-0.001995,-568.644470,0.000026,0.000000
2.670000,0.615906,-568.644470,0.001052,-0.000008,-0.000199,2.739686,0.139566,-0.001995,-568.644470,0.000026,0.000000
2.810000,0.723892,-568.644470,0.001074,-0.000008,-0.000199,3.220033,0.164036,-0.001995,-568.644470,0.000139,0.000000
2.950000,0.663200,-568.644470,0.001065,-0.000008,-0.000199,2.950063,0.150283,-0.001995,-568.644470,0.000373,0.000000
3.090000,0.672882,-568.599976,0.001061,-0.000008,-0.000199,2.993129,0.152477,-0.001995,-568.599976,0.000607,0.000000
3.230000,0.664688,-568.644470,0.001052,-0.000008,-0.000199,2.956680,0.150620,-0.001995,-568.644470,0.000841,0.000000
3.370000,0.762253,-568.644470,0.001065,0.000008,0.000208,3.390670,0.172729,0.002082,-568.644470,0.001075,0.000000
3.510000,0.852737,-568.599976,0.001069,0.000017,0.000433,3.793165,0.193233,0.004334,-568.599976,0.001310,0.000000
3.650000,0.971153,-568.688965,0.001095,0.000028,0.000702,4.319905,0.220066,0.007025,-568.688965,0.001543,0.000000
3.790000,1.048233,-568.644470,0.001087,0.000035,0.000893,4.662774,0.237533,0.008932,-568.644470,0.001769,0.000000
3.930000,1.118607,-568.688965,0.001095,0.000041,0.001049,4.975811,0.253480,0.010492,-568.688965,0.002003,0.000000
4.070000,1.186378,-568.644470,0.001099,0.000050,0.001266,5.277275,0.268837,0.012660,-568.644470,0.002237,0.000000
4.210000,1.215057,-568.599976,0.001108,0.000056,0.001431,5.404845,0.275336,0.014307,-568.599976,0.002472,0.000000
4.350000,1.391556,-568.688965,0.001125,0.000072,0.001821,6.189950,0.315331,0.018213,-568.688965,0.002706,0.000000
4.490000,1.489120,-568.555542,0.001138,0.000081,0.002055,6.623939,0.337440,0.020552,-568.555542,0.002940,0.000000
4.630000,1.587051,-568.644470,0.001155,0.000091,0.002307,7.059557,0.359631,0.023069,-568.644470,0.003174,0.000000
4.770000,1.682755,-568.688965,0.001155,0.000100,0.002532,7.485266,0.381318,0.025321,-568.688965,0.003408,0.000000
4.910000,1.790001,-568.644470,0.001155,0.000108,0.002740,7.962322,0.405620,0.027403,-568.644470,0.003642,0.000000
5.050000,1.886070,-568.733459,0.001181,0.000115,0.002914,8.389660,0.427390,0.029140,-568.733459,0.003876,0.000000
5.190000,1.936714,-568.599976,0.001147,0.000121,0.003070,8.614935,0.438866,0.030699,-568.599976,0.004110,0.000000
5.330000,2.086403,-568.688965,0.001173,0.000132,0.003365,9.280784,0.472786,0.033648,-568.688965,0.004336,0.000000
5.470000,2.255463,-568.688965,0.001203,0.000142,0.003599,10.032799,0.511095,0.035991,-568.688965,0.004570,0.000000
5.610000,2.423401,-568.644470,0.001181,0.000150,0.003807,10.779825,0.549150,0.038072,-568.644470,0.004805,0.000000
5.750000,2.558205,-568.644470,0.001203,0.000159,0.004050,11.379462,0.579697,0.040498,-568.644470,0.005038,0.000000
5.890000,2.640121,-568.733459,0.001203,0.000165,0.004189,11.743847,0.598260,0.041887,-568.733459,0.005273,0.000000
6.030000,2.714226,-568.688965,0.001212,0.000168,0.004258,12.073480,0.615052,0.042580,-568.688965,0.005507,0.000000
6.170000,2.993881,-568.688965,0.001229,0.000184,0.004666,13.317449,0.678423,0.046656,-568.688965,0.005741,0.000000
6.310000,3.328644,-568.644470,0.001224,0.000198,0.005030,14.806547,0.754282,0.050297,-568.644470,0.005975,0.000000
6.450000,3.413544,-568.688965,0.001255,0.000205,0.005212,15.184200,0.773520,0.052118,-568.688965,0.006209,0.000000
6.590000,3.536423,-568.733459,0.001255,0.000212,0.005394,15.730794,0.801365,0.053942,-568.733459,0.006443,0.000000
6.730000,3.784050,-568.688965,0.001259,0.000223,0.005663,16.832294,0.857478,0.056630,-568.688965,0.006678,0.000000
6.870000,4.062958,-568.688965,0.001281,0.000236,0.006001,18.072939,0.920679,0.060010,-568.688965,0.006903,0.000000
7.010000,4.115463,-568.777893,0.001263,0.000241,0.006131,18.306496,0.932577,0.061312,-568.777893,0.007137,0.000000
7.150001,4.256966,-568.777893,0.001276,0.000250,0.006339,18.935928,0.964642,0.063393,-568.777893,0.007371,0.000000
7.290000,4.639763,-568.733459,0.001293,0.000263,0.006686,20.638697,1.051385,0.066864,-568.733459,0.007605,0.000000
7.430000,4.915321,-568.777893,0.001289,0.000275,0.006973,21.864441,1.113828,0.069725,-568.777893,0.007840,0.000000
7.570000,5.113419,-568.688965,0.001315,0.000281,0.007137,22.745623,1.158717,0.071372,-568.688965,0.008074,0.000000
7.710001,5.275772,-568.777893,0.001319,0.000289,0.007345,23.467806,1.195507,0.073453,-568.777893,0.008308,0.000000
7.850000,5.499573,-568.777893,0.001328,0.000295,0.007501,24.463322,1.246221,0.075013,-568.777893,0.008542,0.000000
7.990000,5.665649,-568.688965,0.001337,0.000301,0.007658,25.202066,1.283854,0.076576,-568.688965,0.008776,0.000000
8.130000,6.042122,-568.777893,0.001332,0.000316,0.008030,26.876701,1.369164,0.080304,-568.777893,0.009010,0.000000
8.270000,6.337410,-568.644470,0.001345,0.000325,0.008265,28.190208,1.436078,0.082647,-568.644470,0.009245,0.000000
8.410001,6.568283,-568.733459,0.001358,0.000334,0.008473,29.217182,1.488394,0.084729,-568.733459,0.009470,0.000000
8.550000,6.888145,-568.822388,0.001367,0.000345,0.008768,30.640001,1.560876,0.087677,-568.822388,0.009704,0.000000
8.690001,7.192749,-568.733459,0.001380,0.000353,0.008967,31.994946,1.629900,0.089672,-568.733459,0.009938,0.000000
8.830001,7.498840,-568.777893,0.001388,0.000364,0.009236,33.356506,1.699262,0.092359,-568.777893,0.010173,0.000000
8.970000,7.617996,-568.733459,0.001393,0.000369,0.009366,33.886539,1.726263,0.093661,-568.733459,0.010407,0.000000
9.110001,7.989624,-568.733459,0.001397,0.000380,0.009652,35.539623,1.810475,0.096522,-568.733459,0.010641,0.000000
9.250000,8.143791,-568.733459,0.001397,0.000386,0.009799,36.225391,1.845409,0.097995,-568.733459,0.010875,0.000000
9.390000,8.831558,-568.733459,0.001414,0.000402,0.010198,39.284733,2.001260,0.101984,-568.733459,0.011109,0.000000
9.530001,9.171539,-568.777893,0.001410,0.000411,0.010450,40.797043,2.078300,0.104501,-568.777893,0.011343,0.000000
9.670000,9.434807,-568.777893,0.001414,0.000419,0.010641,41.968117,2.137958,0.106409,-568.777893,0.011577,0.000000
9.810000,9.721161,-568.822388,0.001423,0.000426,0.010832,43.241882,2.202847,0.108316,-568.822388,0.011803,0.000000
9.950001,9.907715,-568.777893,0.001423,0.000432,0.010979,44.071716,2.245120,0.109788,-568.777893,0.012037,0.000000
10.090000,10.527718,-568.733459,0.001427,0.000447,0.011352,46.829628,2.385615,0.113520,-568.733459,0.012271,0.000000
10.230000,11.006958,-568.822388,0.001449,0.000460,0.011681,48.961395,2.494212,0.116813,-568.822388,0.012505,0.000000
10.370001,11.338371,-568.777893,0.001462,0.000469,0.011924,50.435593,2.569312,0.119243,-568.777893,0.012740,0.000000
10.510000,11.605362,-568.822388,0.001462,0.000477,0.012115,51.623230,2.629813,0.121151,-568.822388,0.012973,0.000000
10.650001,11.858200,-568.822388,0.001470,0.000484,0.012306,52.747910,2.687107,0.123058,-568.822388,0.013208,0.000000
10.790001,12.011246,-568.777893,0.001475,0.000489,0.012427,53.428688,2.721787,0.124273,-568.777893,0.013442,0.000000
10.930000,12.359421,-568.866882,0.001475,0.000500,0.012705,54.977448,2.800685,0.127048,-568.866882,0.013676,0.000000
11.070001,12.982765,-568.777893,0.001492,0.000511,0.012982,57.750225,2.941937,0.129822,-568.777893,0.013910,0.000000
11.210001,13.428871,-568.822388,0.001500,0.000522,0.013260,59.734604,3.043026,0.132596,-568.822388,0.014145,0.000000
11.350000,13.879066,-568.822388,0.001505,0.000531,0.013494,61.737171,3.145041,0.134939,-568.822388,0.014370,0.000000
11.490001,14.225372,-568.822388,0.001526,0.000540,0.013711,63.277615,3.223516,0.137108,-568.822388,0.014604,0.000000
11.630000,14.459969,-568.866882,0.001509,0.000546,0.013858,64.321152,3.276676,0.138580,-568.866882,0.014838,0.000000
11.770000,14.570190,-568.822388,0.001531,0.000550,0.013962,64.811447,3.301652,0.139621,-568.822388,0.015072,0.000000
11.910001,14.987625,-568.866882,0.001522,0.000559,0.014188,66.668289,3.396245,0.141877,-568.866882,0.015306,0.000000
12.050000,15.906639,-568.822388,0.001539,0.000577,0.014656,70.756264,3.604496,0.146559,-568.822388,0.015541,0.000000
12.190001,16.421631,-568.777893,0.001556,0.000589,0.014959,73.047066,3.721195,0.149594,-568.777893,0.015775,0.000000
12.330001,16.766075,-568.822388,0.001539,0.000596,0.015150,74.579224,3.799247,0.151502,-568.822388,0.016009,0.000000
12.470000,17.101212,-568.733459,0.001556,0.000605,0.015367,76.069984,3.875190,0.153671,-568.733459,0.016243,0.000000
12.610001,17.351067,-568.822388,0.001556,0.000615,0.015610,77.181396,3.931808,0.156100,-568.822388,0.016477,0.000000
12.750001,17.881325,-568.866882,0.001578,0.000622,0.015801,79.540108,4.051966,0.158008,-568.866882,0.016711,0.000000
12.890000,18.236946,-568.777893,0.001574,0.000630,0.015992,81.121986,4.132551,0.159916,-568.777893,0.016937,0.000000
13.030001,18.594421,-568.866882,0.001587,0.000638,0.016200,82.712120,4.213556,0.161997,-568.866882,0.017171,0.000000
13.170001,19.142555,-568.822388,0.001578,0.000649,0.016486,85.150337,4.337765,0.164859,-568.822388,0.017405,0.000000
13.310000,19.622917,-568.822388,0.001587,0.000659,0.016729,87.287094,4.446617,0.167289,-568.822388,0.017639,0.000000
13.450001,19.937195,-568.866882,0.001621,0.000667,0.016937,88.685074,4.517833,0.169370,-568.866882,0.017873,0.000000
13.590001,20.256691,-568.822388,0.001608,0.000673,0.017084,90.106262,4.590232,0.170843,-568.822388,0.018108,0.000000
13.730000,20.398941,-568.911377,0.001600,0.000678,0.017232,90.739021,4.622466,0.172319,-568.911377,0.018342,0.000000
13.870001,21.011490,-568.822388,0.001608,0.000691,0.017544,93.463776,4.761271,0.175437,-568.822388,0.018576,0.000000
14.010000,21.669472,-568.911377,0.001630,0.000701,0.017795,96.390625,4.910373,0.177954,-568.911377,0.018810,0.000000
14.150001,22.526672,-568.866882,0.001634,0.000717,0.018203,100.203644,5.104617,0.182031,-568.866882,0.019044,0.000000
14.290001,22.829788,-568.822388,0.001634,0.000723,0.018359,101.551971,5.173304,0.183590,-568.822388,0.019278,0.000000
14.430000,23.097519,-568.955872,0.001643,0.000731,0.018576,102.742897,5.233973,0.185759,-568.955872,0.019504,0.000000
14.570001,23.503410,-568.822388,0.001660,0.000741,0.018828,104.548393,5.325949,0.188276,-568.822388,0.019738,0.000000
14.710001,23.852318,-568.911377,0.001647,0.000748,0.019001,106.100410,5.405013,0.190009,-568.911377,0.019972,0.000000
14.850000,24.282784,-568.955872,0.001673,0.000758,0.019252,108.015213,5.502557,0.192522,-568.955872,0.020206,0.000000
14.990001,24.484612,-568.866882,0.001656,0.000763,0.019382,108.912994,5.548292,0.193824,-568.866882,0.020440,0.000000
15.130001,25.481453,-568.866882,0.001681,0.000778,0.019773,113.347160,5.774180,0.197727,-568.866882,0.020675,0.000000
15.270000,25.706360,-568.866882,0.001673,0.000787,0.019981,114.347603,5.825144,0.199808,-568.866882,0.020909,0.000000
15.410001,26.177788,-568.911377,0.001677,0.000795,0.020198,116.444618,5.931971,0.201977,-568.911377,0.021143,0.000000
15.550001,26.516647,-568.911377,0.001681,0.000802,0.020362,117.951935,6.008758,0.203624,-568.911377,0.021377,0.000000
15.690001,26.673416,-568.955872,0.001703,0.000805,0.020440,118.649284,6.044282,0.204403,-568.955872,0.021611,0.000000
15.830001,27.298630,-568.955872,0.001694,0.000817,0.020744,121.430367,6.185958,0.207439,-568.955872,0.021845,0.000000
15.970001,28.032944,-568.866882,0.001699,0.000830,0.021074,124.696762,6.352356,0.210735,-568.866882,0.022071,0.000000
16.110001,28.491341,-568.911377,0.001699,0.000840,0.021325,126.735809,6.456230,0.213249,-568.911377,0.022305,0.000000
16.250000,29.285233,-568.911377,0.001725,0.000852,0.021646,130.267227,6.636128,0.216458,-568.911377,0.022539,0.000000
16.390001,29.495995,-568.911377,0.001733,0.000857,0.021759,131.204742,6.683887,0.217586,-568.911377,0.022773,0.000000
16.530001,29.905235,-568.866882,0.001725,0.000868,0.022045,133.025131,6.776623,0.220447,-568.866882,0.023007,0.000000
16.670000,30.342773,-568.955872,0.001733,0.000875,0.022235,134.971390,6.875771,0.222355,-568.955872,0.023242,0.000000
16.810001,30.646629,-568.955872,0.001729,0.000883,0.022426,136.323013,6.944625,0.224263,-568.955872,0.023476,0.000000
16.950001,30.895370,-568.911377,0.001733,0.000890,0.022617,137.429474,7.000991,0.226170,-568.911377,0.023710,0.000000
17.090000,31.660599,-568.955872,0.001759,0.000903,0.022938,140.833374,7.174394,0.229380,-568.955872,0.023944,0.000000
17.230001,32.318954,-568.955872,0.001759,0.000914,0.023215,143.761887,7.323580,0.232154,-568.955872,0.024178,0.000000
17.370001,32.706223,-568.955872,0.001768,0.000920,0.023363,145.484543,7.411336,0.233630,-568.955872,0.024412,0.000000
17.510000,33.010078,-569.000305,0.001763,0.000927,0.023536,146.836166,7.480191,0.235364,-569.000305,0.024638,0.000000
17.650002,33.200356,-568.955872,0.001776,0.000932,0.023667,147.682556,7.523308,0.236666,-568.955872,0.024872,0.000000
17.790001,33.966331,-568.955872,0.001781,0.000948,0.024092,151.089783,7.696881,0.240916,-568.955872,0.025106,0.000000
17.930000,34.876778,-569.000305,0.001802,0.000960,0.024378,155.139648,7.903191,0.243778,-569.000305,0.025340,0.000000
18.070002,35.854630,-568.955872,0.001798,0.000976,0.024794,159.489365,8.124775,0.247941,-568.955872,0.025575,0.000000
18.210001,36.287331,-569.000305,0.001802,0.000985,0.025011,161.414108,8.222826,0.250106,-569.000305,0.025808,0.000000
18.350000,36.458244,-568.911377,0.001811,0.000989,0.025123,162.174377,8.261556,0.251234,-568.911377,0.026043,0.000000
18.490002,36.794868,-568.911377,0.001811,0.000999,0.025366,163.671753,8.337836,0.253664,-568.911377,0.026277,0.000000
18.630001,37.220123,-569.000305,0.001828,0.001007,0.025566,165.563370,8.434200,0.255658,-569.000305,0.026511,0.000000
18.770000,37.428650,-568.955872,0.001828,0.001012,0.025696,166.490952,8.481453,0.256957,-568.955872,0.026745,0.000000
18.910002,38.060936,-569.044800,0.001828,0.001024,0.026008,169.303497,8.624731,0.260079,-569.044800,0.026971,0.000000
19.050001,38.394958,-568.955872,0.001837,0.001030,0.026164,170.789307,8.700421,0.261642,-568.955872,0.027205,0.000000
19.190001,39.113632,-569.044800,0.001850,0.001042,0.026468,173.986130,8.863276,0.264678,-569.044800,0.027439,0.000000
19.330002,39.348602,-569.000305,0.001863,0.001046,0.026581,175.031326,8.916521,0.265806,-569.000305,0.027673,0.000000
19.470001,39.847206,-569.000305,0.001841,0.001056,0.026823,177.249222,9.029506,0.268232,-569.000305,0.027907,0.000000
19.610001,40.326080,-569.089294,0.001863,0.001067,0.027101,179.379364,9.138021,0.271006,-569.089294,0.028141,0.000000
19.750000,41.022041,-569.000305,0.001867,0.001078,0.027387,182.475159,9.295728,0.273867,-569.000305,0.028376,0.000000
19.890001,41.866585,-568.955872,0.001884,0.001091,0.027699,186.231873,9.487103,0.276990,-568.955872,0.028610,0.000000
20.030001,42.680214,-569.044800,0.001884,0.001103,0.028029,189.851074,9.671474,0.280287,-569.044800,0.028844,0.000000
20.170000,43.124832,-569.000305,0.001897,0.001112,0.028254,191.828827,9.772226,0.282542,-569.000305,0.029078,0.000000
20.310001,43.367241,-569.089294,0.001897,0.001117,0.028376,192.907120,9.827157,0.283757,-569.089294,0.029312,0.000000
20.450001,43.713181,-569.044800,0.001897,0.001129,0.028671,194.445938,9.905548,0.286706,-569.044800,0.029538,0.000000
20.590000,44.054276,-569.000305,0.001906,0.001133,0.028775,195.963211,9.982841,0.287747,-569.000305,0.029772,0.000000
20.730001,44.237480,-569.089294,0.001919,0.001138,0.028904,196.778137,10.024357,0.289045,-569.089294,0.030006,0.000000
20.870001,44.723801,-569.000305,0.001906,0.001149,0.029173,198.941406,10.134558,0.291732,-569.000305,0.030240,0.000000
21.010000,45.928421,-569.044800,0.001914,0.001165,0.029581,204.299820,10.407529,0.295808,-569.044800,0.030474,0.000000
21.150002,46.231537,-569.044800,0.001923,0.001170,0.029720,205.648148,10.476215,0.297198,-569.044800,0.030708,0.000000
21.290001,46.496666,-569.000305,0.001923,0.001177,0.029893,206.827499,10.536296,0.298931,-569.000305,0.030943,0.000000
21.430000,46.920425,-569.089294,0.001927,0.001185,0.030093,208.712479,10.632320,0.300926,-569.089294,0.031177,0.000000
21.570002,47.218697,-569.089294,0.001940,0.001191,0.030258,210.039246,10.699909,0.302576,-569.089294,0.031411,0.000000
21.710001,48.176437,-569.000305,0.001940,0.001207,0.030657,214.299500,10.916937,0.306565,-569.000305,0.031645,0.000000
21.850000,49.095451,-569.000305,0.001953,0.001223,0.031055,218.387482,11.125189,0.310554,-569.000305,0.031879,0.000000
21.990002,49.787689,-569.044800,0.001966,0.001231,0.031272,221.466705,11.282052,0.312719,-569.044800,0.032105,0.000000
22.130001,50.223366,-569.089294,0.001953,0.001240,0.031489,223.404694,11.380777,0.314888,-569.089294,0.032339,0.000000
22.270000,50.383858,-569.089294,0.001957,0.001245,0.031610,224.118591,11.417145,0.316103,-569.089294,0.032573,0.000000
22.410002,50.972206,-569.133789,0.001975,0.001256,0.031905,226.735703,11.550467,0.319052,-569.133789,0.032807,0.000000
22.550001,51.063065,-569.044800,0.001988,0.001261,0.032035,227.139862,11.571055,0.320354,-569.044800,0.033041,0.000000
22.690001,51.375114,-569.044800,0.001983,0.001267,0.032174,228.527924,11.641768,0.321739,-569.044800,0.033275,0.000000
22.830002,51.913193,-569.178223,0.001996,0.001274,0.032348,230.921417,11.763698,0.323476,-569.178223,0.033510,0.000000
22.970001,52.865349,-569.089294,0.002001,0.001289,0.032729,235.156815,11.979459,0.327291,-569.089294,0.033744,0.000000
23.110001,54.061409,-569.133789,0.001992,0.001305,0.033154,240.477158,12.250490,0.331538,-569.133789,0.033978,0.000000
23.250002,54.331383,-569.133789,0.001996,0.001310,0.033275,241.678055,12.311667,0.332753,-569.133789,0.034212,0.000000
23.390001,54.613640,-569.044800,0.002005,0.001317,0.033440,242.933609,12.375628,0.334403,-569.044800,0.034446,0.000000
23.530001,54.921219,-569.133789,0.002009,0.001323,0.033605,244.301788,12.445326,0.336049,-569.133789,0.034672,0.000000
23.670002,55.824219,-569.089294,0.002026,0.001337,0.033969,248.318527,12.649949,0.339691,-569.089294,0.034906,0.000000
23.810001,56.382034,-569.133789,0.002022,0.001347,0.034203,250.799820,12.776351,0.342033,-569.133789,0.035140,0.000000
23.950001,57.129387,-569.133789,0.002031,0.001358,0.034498,254.124207,12.945704,0.344982,-569.133789,0.035374,0.000000
24.090002,57.629112,-569.089294,0.002026,0.001366,0.034706,256.347107,13.058943,0.347064,-569.089294,0.035608,0.000000
24.230001,58.006325,-569.178223,0.002048,0.001372,0.034854,258.025024,13.144421,0.348536,-569.178223,0.035842,0.000000
24.370001,58.481094,-569.044800,0.002039,0.001381,0.035079,260.136902,13.252006,0.350792,-569.044800,0.036076,0.000000
24.510000,58.742500,-569.089294,0.002057,0.001389,0.035279,261.299683,13.311240,0.352786,-569.089294,0.036311,0.000000
24.650002,59.748283,-569.133789,0.002061,0.001401,0.035582,265.773651,13.539155,0.355822,-569.133789,0.036545,0.000000
24.790001,60.063683,-569.089294,0.002074,0.001407,0.035747,267.176605,13.610624,0.357468,-569.089294,0.036779,0.000000
24.930000,60.991264,-569.133789,0.002078,0.001423,0.036154,271.302704,13.820818,0.361545,-569.133789,0.037013,0.000000
25.070002,61.700256,-569.089294,0.002074,0.001432,0.036363,274.456451,13.981478,0.363626,-569.089294,0.037238,0.000000
25.210001,62.019753,-569.178223,0.002074,0.001438,0.036536,275.877625,14.053876,0.365360,-569.178223,0.037473,0.000000
25.350000,62.469582,-569.089294,0.002087,0.001446,0.036735,277.878571,14.155809,0.367354,-569.089294,0.037707,0.000000
25.490002,62.696358,-569.089294,0.002082,0.001451,0.036848,278.887329,14.207198,0.368482,-569.089294,0.037941,0.000000
25.630001,63.754265,-569.178223,0.002108,0.001467,0.037256,283.593140,14.446922,0.372559,-569.178223,0.038175,0.000000
25.770000,64.269997,-569.089294,0.002104,0.001475,0.037455,285.887238,14.563789,0.374553,-569.089294,0.038409,0.000000
25.910002,64.821480,-569.222717,0.002100,0.001483,0.037672,288.340332,14.688757,0.376722,-569.222717,0.038643,0.000000
26.050001,65.394188,-569.222717,0.002117,0.001492,0.037906,290.887878,14.818535,0.379065,-569.222717,0.038878,0.000000
26.190001,65.866737,-569.133789,0.002130,0.001503,0.038167,292.989868,14.925616,0.381665,-569.133789,0.039112,0.000000
26.330002,66.579826,-569.222717,0.002117,0.001512,0.038409,296.161865,15.087204,0.384095,-569.222717,0.039346,0.000000
26.470001,66.736961,-569.133789,0.002126,0.001514,0.038453,296.860840,15.122811,0.384526,-569.133789,0.039571,0.000000
26.610001,67.189034,-569.178223,0.002130,0.001522,0.038652,298.871735,15.225253,0.386521,-569.178223,0.039806,0.000000
26.750002,67.389732,-569.222717,0.002134,0.001518,0.038565,299.764496,15.270731,0.385654,-569.222717,0.038808,0.000000
26.890001,67.122002,-569.133789,0.002147,0.001518,0.038565,298.573578,15.210063,0.385654,-569.133789,0.038808,0.000000
27.030001,66.887032,-569.222717,0.002139,0.001518,0.038565,297.528381,15.156818,0.385654,-569.222717,0.038808,0.000000
27.170002,66.726173,-569.133789,0.002134,0.001517,0.038531,296.812836,15.120367,0.385306,-569.133789,0.038565,0.000000
27.310001,66.526955,-569.311707,0.002156,0.001517,0.038522,295.926666,15.075223,0.385223,-569.311707,0.038565,0.000000
27.450001,66.373909,-569.267212,0.002160,0.001516,0.038514,295.245880,15.040543,0.385136,-569.267212,0.038565,0.000000
27.590002,66.214531,-569.222717,0.002156,0.001516,0.038505,294.536957,15.004427,0.385049,-569.222717,0.038565,0.000000
27.730001,66.081963,-569.222717,0.002156,0.001516,0.038505,293.947266,14.974386,0.385049,-569.222717,0.038565,0.000000
27.870001,65.959831,-569.178223,0.002147,0.001516,0.038505,293.403992,14.946712,0.385049,-569.178223,0.038565,0.000000
28.010002,65.834709,-569.267212,0.002143,0.001516,0.038505,292.847412,14.918358,0.385049,-569.267212,0.038565,0.000000
28.150002,65.734917,-569.222717,0.002160,0.001516,0.038505,292.403503,14.895744,0.385049,-569.222717,0.038565,0.000000
28.290001,65.635857,-569.222717,0.002143,0.001516,0.038496,291.962860,14.873298,0.384962,-569.222717,0.038565,0.000000
28.430002,65.536812,-569.267212,0.002156,0.001516,0.038496,291.522308,14.850854,0.384962,-569.267212,0.038565,0.000000
28.570002,65.441856,-569.222717,0.002156,0.001516,0.038496,291.099915,14.829336,0.384962,-569.222717,0.038565,0.000000
28.710001,65.361794,-569.311707,0.002147,0.001516,0.038496,290.743774,14.811193,0.384962,-569.311707,0.038565,0.000000
28.850002,65.291039,-569.267212,0.002143,0.001516,0.038496,290.429047,14.795160,0.384962,-569.267212,0.038565,0.000000
28.990002,65.214714,-569.222717,0.002151,0.001516,0.038496,290.089539,14.777865,0.384962,-569.222717,0.038565,0.000000
29.130001,65.144707,-569.267212,0.002173,0.001516,0.038496,289.778137,14.762002,0.384962,-569.267212,0.038565,0.000000
29.270000,65.082146,-569.178223,0.002156,0.001516,0.038496,289.499847,14.747825,0.384962,-569.178223,0.038565,0.000000
29.410002,65.021080,-569.222717,0.002160,0.001516,0.038496,289.228210,14.733988,0.384962,-569.222717,0.038565,0.000000
29.550001,64.962242,-569.267212,0.002164,0.001516,0.038496,288.966492,14.720654,0.384962,-569.267212,0.038565,0.000000
29.690001,64.897072,-569.267212,0.002164,0.001516,0.038496,288.676605,14.705887,0.384962,-569.267212,0.038565,0.000000
29.830002,64.840843,-569.356201,0.002164,0.001516,0.038496,288.426483,14.693146,0.384962,-569.356201,0.038565,0.000000
29.970001,64.789085,-569.178223,0.002173,0.001516,0.038496,288.196259,14.681417,0.384962,-569.178223,0.038565,0.000000
30.110001,64.749611,-569.311707,0.002164,0.001516,0.038496,288.020660,14.672471,0.384962,-569.311707,0.038565,0.000000
30.250002,64.683327,-569.222717,0.002156,0.001516,0.038496,287.725800,14.657451,0.384962,-569.222717,0.038565,0.000000
30.390001,64.634178,-569.356201,0.002164,0.001516,0.038496,287.507172,14.646315,0.384962,-569.356201,0.038565,0.000000
30.530001,64.600288,-569.356201,0.002173,0.001516,0.038496,287.356445,14.638635,0.384962,-569.356201,0.038565,0.000000
30.670002,64.564552,-569.267212,0.002160,0.001516,0.038496,287.197479,14.630537,0.384962,-569.267212,0.038565,0.000000
30.810001,64.511299,-569.311707,0.002164,0.001516,0.038496,286.960602,14.618469,0.384962,-569.311707,0.038565,0.000000
30.950001,64.479652,-569.267212,0.002164,0.001516,0.038496,286.819824,14.611298,0.384962,-569.267212,0.038565,0.000000
31.090002,64.440926,-569.311707,0.002151,0.001516,0.038496,286.647552,14.602523,0.384962,-569.311707,0.038565,0.000000
31.230001,64.402565,-569.311707,0.002173,0.001516,0.038496,286.476929,14.593829,0.384962,-569.311707,0.038565,0.000000
31.370001,64.361610,-569.311707,0.002160,0.001516,0.038496,286.294739,14.584549,0.384962,-569.311707,0.038565,0.000000
31.510002,64.318779,-569.400635,0.002160,0.001516,0.038496,286.104218,14.574843,0.384962,-569.400635,0.038565,0.000000
31.650002,64.300529,-569.267212,0.002164,0.001516,0.038496,286.023041,14.570708,0.384962,-569.267212,0.038565,0.000000
31.790001,64.249519,-569.267212,0.002164,0.001516,0.038496,285.796143,14.559149,0.384962,-569.267212,0.038565,0.000000
31.930002,64.234627,-569.311707,0.002169,0.001516,0.038496,285.729889,14.555775,0.384962,-569.311707,0.038565,0.000000
32.070000,64.193291,-569.311707,0.002156,0.001516,0.038496,285.546021,14.546408,0.384962,-569.311707,0.038565,0.000000
32.210003,64.161644,-569.311707,0.002177,0.001516,0.038496,285.405243,14.539236,0.384962,-569.311707,0.038565,0.000000
32.350002,64.138557,-569.267212,0.002169,0.001516,0.038496,285.302551,14.534004,0.384962,-569.267212,0.038565,0.000000
32.490002,64.103172,-569.356201,0.002160,0.001516,0.038496,285.145142,14.525987,0.384962,-569.356201,0.038565,0.000000
32.630001,64.074883,-569.311707,0.002169,0.001515,0.038487,285.019318,14.519576,0.384875,-569.311707,0.038565,0.000000
32.770000,64.051048,-569.356201,0.002156,0.001515,0.038487,284.913300,14.514175,0.384875,-569.356201,0.038565,0.000000
32.910000,64.020134,-569.356201,0.002169,0.001515,0.038487,284.775787,14.507170,0.384875,-569.356201,0.038565,0.000000
33.050003,63.993324,-569.311707,0.002177,0.001515,0.038487,284.656525,14.501095,0.384875,-569.311707,0.038565,0.000000
33.190002,63.972099,-569.400635,0.002164,0.001515,0.038487,284.562103,14.496284,0.384875,-569.400635,0.038565,0.000000
33.330002,63.940071,-569.400635,0.002169,0.001515,0.038487,284.419647,14.489027,0.384875,-569.400635,0.038565,0.000000
33.470001,63.913261,-569.400635,0.002169,0.001515,0.038487,284.300385,14.482952,0.384875,-569.400635,0.038565,0.000000
33.610001,63.877892,-569.445129,0.002156,0.001515,0.038487,284.143066,14.474936,0.384875,-569.445129,0.038565,0.000000
33.750000,63.854805,-569.356201,0.002151,0.001515,0.038487,284.040344,14.469706,0.384875,-569.356201,0.038565,0.000000
33.890003,63.834694,-569.400635,0.002173,0.001515,0.038487,283.950897,14.465148,0.384875,-569.400635,0.038565,0.000000
34.030003,63.808266,-569.356201,0.002182,0.001515,0.038487,283.833344,14.459159,0.384875,-569.356201,0.038565,0.000000
34.170002,63.785545,-569.356201,0.002177,0.001515,0.038487,283.732269,14.454011,0.384875,-569.356201,0.038565,0.000000
34.310001,63.760597,-569.445129,0.002169,0.001515,0.038487,283.621307,14.448358,0.384875,-569.445129,0.038565,0.000000
34.450001,63.747566,-569.356201,0.002151,0.001515,0.038487,283.563324,14.445405,0.384875,-569.356201,0.038565,0.000000
34.590000,63.734901,-569.445129,0.002160,0.001515,0.038487,283.506989,14.442535,0.384875,-569.445129,0.038565,0.000000
34.730003,63.717766,-569.356201,0.002156,0.001515,0.038487,283.430786,14.438652,0.384875,-569.356201,0.038565,0.000000
34.870003,63.672340,-569.400635,0.002164,0.001515,0.038487,283.228729,14.428358,0.384875,-569.400635,0.038565,0.000000
35.010002,63.655952,-569.534119,0.002173,0.001515,0.038487,283.155823,14.424645,0.384875,-569.534119,0.038565,0.000000
35.150002,63.647026,-569.400635,0.002182,0.001515,0.038487,283.116119,14.422623,0.384875,-569.400635,0.038565,0.000000
35.290001,63.619469,-569.400635,0.002169,0.001515,0.038487,282.993530,14.416377,0.384875,-569.400635,0.038565,0.000000
35.430000,63.601585,-569.356201,0.002190,0.001515,0.038487,282.913971,14.412325,0.384875,-569.356201,0.038565,0.000000
35.570004,63.570305,-569.445129,0.002186,0.001515,0.038487,282.774841,14.405237,0.384875,-569.445129,0.038565,0.000000
35.710003,63.555046,-569.400635,0.002173,0.001515,0.038487,282.706970,14.401779,0.384875,-569.400635,0.038565,0.000000
35.850002,63.541634,-569.356201,0.002164,0.001515,0.038487,282.647308,14.398740,0.384875,-569.356201,0.038565,0.000000
35.990002,63.522270,-569.489624,0.002160,0.001515,0.038487,282.561157,14.394352,0.384875,-569.489624,0.038565,0.000000
36.130001,63.510735,-569.400635,0.002177,0.001515,0.038487,282.509857,14.391739,0.384875,-569.400635,0.038565,0.000000
36.270000,63.493599,-569.400635,0.002173,0.001515,0.038487,282.433624,14.387855,0.384875,-569.400635,0.038565,0.000000
36.410000,63.471260,-569.445129,0.002186,0.001515,0.038487,282.334259,14.382792,0.384875,-569.445129,0.038565,0.000000
36.550003,63.465309,-569.400635,0.002160,0.001515,0.038487,282.307800,14.381444,0.384875,-569.400635,0.038565,0.000000
36.690002,63.442223,-569.445129,0.002169,0.001515,0.038487,282.205109,14.376213,0.384875,-569.445129,0.038565,0.000000
36.830002,63.424339,-569.445129,0.002169,0.001515,0.038487,282.125549,14.372161,0.384875,-569.445129,0.038565,0.000000
36.970001,63.410942,-569.445129,0.002160,0.001515,0.038487,282.065948,14.369125,0.384875,-569.445129,0.038565,0.000000
37.110001,63.394554,-569.489624,0.002164,0.001515,0.038487,281.993073,14.365411,0.384875,-569.489624,0.038565,0.000000
37.250000,63.374825,-569.445129,0.002164,0.001515,0.038487,281.905304,14.360941,0.384875,-569.445129,0.038565,0.000000
37.390003,63.359550,-569.578552,0.002160,0.001515,0.038487,281.837341,14.357479,0.384875,-569.578552,0.038565,0.000000
37.530003,63.348747,-569.489624,0.002186,0.001515,0.038487,281.789307,14.355031,0.384875,-569.489624,0.038565,0.000000
37.670002,63.330132,-569.445129,0.002173,0.001515,0.038487,281.706482,14.350813,0.384875,-569.445129,0.038565,0.000000
37.810001,63.316734,-569.445129,0.002182,0.001515,0.038487,281.646912,14.347777,0.384875,-569.445129,0.038565,0.000000
37.950001,63.289543,-569.489624,0.002173,0.001515,0.038487,281.525940,14.341616,0.384875,-569.489624,0.038565,0.000000
38.090000,63.278740,-569.534119,0.002169,0.001515,0.038487,281.477905,14.339168,0.384875,-569.534119,0.038565,0.000000
38.230003,63.284706,-569.445129,0.002177,0.001515,0.038487,281.504425,14.340519,0.384875,-569.445129,0.038565,0.000000
38.370003,63.254539,-569.489624,0.002173,0.001515,0.038487,281.370239,14.333684,0.384875,-569.489624,0.038565,0.000000
38.510002,63.242622,-569.445129,0.002186,0.001515,0.038487,281.317230,14.330983,0.384875,-569.445129,0.038565,0.000000
38.650002,63.230339,-569.445129,0.002173,0.001515,0.038487,281.262604,14.328199,0.384875,-569.445129,0.038565,0.000000
38.790001,63.215813,-569.489624,0.002164,0.001515,0.038487,281.197968,14.324908,0.384875,-569.489624,0.038565,0.000000
38.930000,63.207253,-569.534119,0.002190,0.001515,0.038487,281.159912,14.322968,0.384875,-569.534119,0.038565,0.000000
39.070004,63.195702,-569.534119,0.002160,0.001515,0.038487,281.108521,14.320351,0.384875,-569.534119,0.038565,0.000000
39.210003,63.187889,-569.534119,0.002173,0.001515,0.038487,281.073761,14.318580,0.384875,-569.534119,0.038565,0.000000
39.350002,63.173363,-569.534119,0.002177,0.001515,0.038487,281.009155,14.315289,0.384875,-569.534119,0.038565,0.000000
39.490002,63.154366,-569.489624,0.002173,0.001515,0.038487,280.924652,14.310984,0.384875,-569.489624,0.038565,0.000000
39.630001,63.145058,-569.534119,0.002182,0.001515,0.038487,280.883240,14.308874,0.384875,-569.534119,0.038565,0.000000
39.770000,63.123466,-569.534119,0.002182,0.001515,0.038487,280.787201,14.303982,0.384875,-569.534119,0.038565,0.000000
39.910004,63.110054,-569.534119,0.002186,0.001515,0.038487,280.727539,14.300942,0.384875,-569.534119,0.038565,0.000000
40.050003,63.103355,-569.445129,0.002186,0.001515,0.038487,280.697754,14.299425,0.384875,-569.445129,0.038565,0.000000
40.190002,63.098137,-569.534119,0.002156,0.001515,0.038487,280.674530,14.298242,0.384875,-569.534119,0.038565,0.000000
40.330002,63.091072,-569.578552,0.002182,0.001515,0.038487,280.643097,14.296641,0.384875,-569.578552,0.038565,0.000000
40.470001,63.078773,-569.578552,0.002173,0.001515,0.038487,280.588409,14.293855,0.384875,-569.578552,0.038565,0.000000
40.610001,63.062019,-569.578552,0.002173,0.001515,0.038487,280.513885,14.290057,0.384875,-569.578552,0.038565,0.000000
40.750004,63.055321,-569.489624,0.002186,0.001515,0.038487,280.484070,14.288540,0.384875,-569.489624,0.038565,0.000000
40.890003,63.047874,-569.578552,0.002173,0.001515,0.038487,280.450958,14.286853,0.384875,-569.578552,0.038565,0.000000
41.030003,63.034096,-569.578552,0.002169,0.001515,0.038487,280.389648,14.283730,0.384875,-569.578552,0.038565,0.000000
41.170002,63.004303,-569.578552,0.002182,0.001515,0.038487,280.257141,14.276979,0.384875,-569.578552,0.038565,0.000000
41.310001,62.980476,-569.578552,0.002177,0.001515,0.038487,280.151154,14.271581,0.384875,-569.578552,0.038565,0.000000
41.450001,62.999840,-569.534119,0.002156,0.001515,0.038487,280.237274,14.275968,0.384875,-569.534119,0.038565,0.000000
41.590000,63.005424,-569.578552,0.002177,0.001515,0.038487,280.262115,14.277233,0.384875,-569.578552,0.038565,0.000000
41.730003,62.962227,-569.534119,0.002169,0.001515,0.038487,280.069977,14.267445,0.384875,-569.534119,0.038565,0.000000
41.870003,62.957016,-569.578552,0.002177,0.001515,0.038487,280.046783,14.266264,0.384875,-569.578552,0.038565,0.000000
42.010002,62.976753,-569.578552,0.002186,0.001515,0.038487,280.134583,14.270736,0.384875,-569.578552,0.038565,0.000000
42.150002,62.959625,-569.578552,0.002186,0.001515,0.038487,280.058411,14.266855,0.384875,-569.578552,0.038565,0.000000
42.290001,62.925735,-569.578552,0.002177,0.001515,0.038487,279.907654,14.259175,0.384875,-569.578552,0.038565,0.000000
42.430000,62.917542,-569.623047,0.002182,0.001515,0.038487,279.871216,14.257319,0.384875,-569.623047,0.038565,0.000000
42.570004,62.898926,-569.667542,0.002169,0.001515,0.038487,279.788391,14.253100,0.384875,-569.667542,0.038565,0.000000
42.710003,62.898178,-569.578552,0.002160,0.001515,0.038487,279.785065,14.252931,0.384875,-569.578552,0.038565,0.000000
42.850002,62.894455,-569.534119,0.002182,0.001515,0.038487,279.768494,14.252088,0.384875,-569.534119,0.038565,0.000000
42.990002,62.892593,-569.623047,0.002164,0.001515,0.038487,279.760223,14.251665,0.384875,-569.623047,0.038565,0.000000
43.130001,62.878075,-569.623047,0.002190,0.001515,0.038487,279.695648,14.248376,0.384875,-569.623047,0.038565,0.000000
43.270000,62.865036,-569.578552,0.002182,0.001515,0.038487,279.637634,14.245420,0.384875,-569.578552,0.038565,0.000000
43.410004,62.858711,-569.667542,0.002177,0.001515,0.038487,279.609497,14.243987,0.384875,-569.667542,0.038565,0.000000
43.550003,62.847534,-569.534119,0.002164,0.001515,0.038487,279.559784,14.241454,0.384875,-569.534119,0.038565,0.000000
43.690002,62.847168,-569.623047,0.002169,0.001515,0.038487,279.558167,14.241372,0.384875,-569.623047,0.038565,0.000000
43.830002,62.829666,-569.534119,0.002182,0.001515,0.038487,279.480316,14.237406,0.384875,-569.534119,0.038565,0.000000
43.970001,62.821098,-569.667542,0.002164,0.001515,0.038487,279.442200,14.235465,0.384875,-569.667542,0.038565,0.000000
44.110001,62.811790,-569.578552,0.002182,0.001515,0.038487,279.400787,14.233355,0.384875,-569.578552,0.038565,0.000000
44.250004,62.803970,-569.623047,0.002186,0.001515,0.038487,279.366028,14.231584,0.384875,-569.623047,0.038565,0.000000
44.390003,62.781998,-569.623047,0.002182,0.001515,0.038487,279.268280,14.226604,0.384875,-569.623047,0.038565,0.000000
44.530003,62.779762,-569.578552,0.002177,0.001515,0.038487,279.258331,14.226097,0.384875,-569.578552,0.038565,0.000000
44.670002,62.778275,-569.667542,0.002177,0.001515,0.038487,279.251709,14.225760,0.384875,-569.667542,0.038565,0.000000
44.810001,62.758537,-569.623047,0.002177,0.001515,0.038487,279.163910,14.221288,0.384875,-569.623047,0.038565,0.000000
44.950001,62.751465,-569.623047,0.002177,0.001515,0.038487,279.132446,14.219686,0.384875,-569.623047,0.038565,0.000000
45.090004,62.739548,-569.667542,0.002169,0.001515,0.038487,279.079437,14.216985,0.384875,-569.667542,0.038565,0.000000
45.230003,62.736198,-569.623047,0.002190,0.001515,0.038487,279.064545,14.216226,0.384875,-569.623047,0.038565,0.000000
45.370003,62.720184,-569.712036,0.002160,0.001515,0.038487,278.993317,14.212597,0.384875,-569.712036,0.038565,0.000000
45.510002,62.716461,-569.667542,0.002164,0.001515,0.038487,278.976746,14.211754,0.384875,-569.667542,0.038565,0.000000
45.650002,62.704918,-569.667542,0.002182,0.001515,0.038487,278.925415,14.209137,0.384875,-569.667542,0.038565,0.000000
45.790001,62.694862,-569.756531,0.002177,0.001515,0.038487,278.880676,14.206859,0.384875,-569.756531,0.038565,0.000000
45.930000,62.701569,-569.623047,0.002169,0.001515,0.038487,278.910492,14.208378,0.384875,-569.623047,0.038565,0.000000
46.070004,62.688164,-569.667542,0.002182,0.001515,0.038487,278.850891,14.205340,0.384875,-569.667542,0.038565,0.000000
46.210003,62.680717,-569.712036,0.002156,0.001515,0.038487,278.817749,14.203653,0.384875,-569.712036,0.038565,0.000000
46.350002,62.662094,-569.623047,0.002169,0.001515,0.038487,278.734924,14.199433,0.384875,-569.623047,0.038565,0.000000
46.490002,62.654648,-569.712036,0.002169,0.001515,0.038487,278.701782,14.197746,0.384875,-569.712036,0.038565,0.000000
46.630001,62.660980,-569.667542,0.002169,0.001515,0.038487,278.729950,14.199181,0.384875,-569.667542,0.038565,0.000000
46.770000,62.640869,-569.712036,0.002182,0.001515,0.038487,278.640503,14.194624,0.384875,-569.712036,0.038565,0.000000
46.910004,62.634171,-569.756531,0.002173,0.001515,0.038487,278.610718,14.193106,0.384875,-569.756531,0.038565,0.000000
47.050003,62.628212,-569.712036,0.002164,0.001515,0.038487,278.584198,14.191755,0.384875,-569.712036,0.038565,0.000000
47.190002,62.615173,-569.756531,0.002169,0.001515,0.038487,278.526215,14.188801,0.384875,-569.756531,0.038565,0.000000
47.330002,62.599907,-569.712036,0.002182,0.001515,0.038487,278.458282,14.185342,0.384875,-569.712036,0.038565,0.000000
47.470001,62.600655,-569.756531,0.002173,0.001515,0.038487,278.461609,14.185512,0.384875,-569.756531,0.038565,0.000000
47.610001,62.593208,-569.712036,0.002173,0.001515,0.038487,278.428497,14.183824,0.384875,-569.712036,0.038565,0.000000
47.750004,62.590599,-569.712036,0.002164,0.001515,0.038487,278.416901,14.183233,0.384875,-569.712036,0.038565,0.000000
47.890003,62.581291,-569.756531,0.002173,0.001515,0.038487,278.375488,14.181123,0.384875,-569.756531,0.038565,0.000000
48.030003,62.570862,-569.623047,0.002177,0.001515,0.038487,278.329102,14.178760,0.384875,-569.623047,0.038565,0.000000
48.170002,62.564903,-569.756531,0.002164,0.001515,0.038487,278.302582,14.177410,0.384875,-569.756531,0.038565,0.000000
48.310001,62.571609,-569.756531,0.002190,0.001515,0.038487,278.332428,14.178929,0.384875,-569.756531,0.038565,0.000000
48.450001,62.543312,-569.712036,0.002173,0.001515,0.038487,278.206543,14.172518,0.384875,-569.712036,0.038565,0.000000
48.590004,62.540329,-569.756531,0.002169,0.001515,0.038487,278.193268,14.171842,0.384875,-569.756531,0.038565,0.000000
48.730003,62.536606,-569.800964,0.002190,0.001515,0.038487,278.176727,14.170998,0.384875,-569.800964,0.038565,0.000000
48.870003,62.520226,-569.756531,0.002164,0.001515,0.038487,278.103851,14.167286,0.384875,-569.756531,0.038565,0.000000
49.010002,62.519478,-569.800964,0.002182,0.001515,0.038487,278.100525,14.167116,0.384875,-569.800964,0.038565,0.000000
49.150002,62.512772,-569.756531,0.002151,0.001515,0.038487,278.070709,14.165596,0.384875,-569.756531,0.038565,0.000000
49.290001,62.515755,-569.712036,0.002164,0.001515,0.038487,278.083954,14.166272,0.384875,-569.712036,0.038565,0.000000
49.430004,62.500862,-569.712036,0.002186,0.001515,0.038487,278.017731,14.162898,0.384875,-569.712036,0.038565,0.000000
49.570004,62.496391,-569.756531,0.002173,0.001515,0.038487,277.997833,14.161885,0.384875,-569.756531,0.038565,0.000000
49.710003,62.482613,-569.756531,0.002177,0.001515,0.038487,277.936554,14.158762,0.384875,-569.756531,0.038565,0.000000
49.850002,62.475906,-569.667542,0.002182,0.001515,0.038487,277.906708,14.157242,0.384875,-569.667542,0.038565,0.000000
49.990002,62.471817,-569.756531,0.002169,0.001515,0.038487,277.888519,14.156316,0.384875,-569.756531,0.038565,0.000000
50.130001,62.458405,-569.756531,0.002182,0.001515,0.038487,277.828857,14.153276,0.384875,-569.756531,0.038565,0.000000
50.270004,62.442024,-569.845459,0.002182,0.001515,0.038487,277.755981,14.149565,0.384875,-569.845459,0.038565,0.000000
50.410004,62.430855,-569.800964,0.002195,0.001515,0.038487,277.706299,14.147034,0.384875,-569.800964,0.038565,0.000000
50.550003,62.425270,-569.712036,0.002173,0.001515,0.038487,277.681458,14.145768,0.384875,-569.712036,0.038565,0.000000
50.690002,62.427498,-569.800964,0.002164,0.001515,0.038487,277.691376,14.146273,0.384875,-569.800964,0.038565,0.000000
50.830002,62.411118,-569.800964,0.002182,0.001515,0.038487,277.618530,14.142562,0.384875,-569.800964,0.038565,0.000000
50.970001,62.416328,-569.800964,0.002164,0.001515,0.038487,277.641693,14.143742,0.384875,-569.800964,0.038565,0.000000
51.110001,62.410744,-569.845459,0.002173,0.001515,0.038487,277.616852,14.142477,0.384875,-569.845459,0.038565,0.000000
51.250004,62.400322,-569.845459,0.002160,0.001515,0.038487,277.570496,14.140115,0.384875,-569.845459,0.038565,0.000000
51.390003,62.395851,-569.800964,0.002182,0.001515,0.038487,277.550598,14.139102,0.384875,-569.800964,0.038565,0.000000
51.530003,62.392128,-569.756531,0.002190,0.001515,0.038487,277.534058,14.138258,0.384875,-569.756531,0.038565,0.000000
51.670002,62.388405,-569.845459,0.002169,0.001515,0.038487,277.517487,14.137415,0.384875,-569.845459,0.038565,0.000000
51.810001,62.377228,-569.889954,0.002182,0.001515,0.038487,277.467773,14.134882,0.384875,-569.889954,0.038565,0.000000
51.950001,62.358612,-569.800964,0.002156,0.001515,0.038487,277.384949,14.130663,0.384875,-569.800964,0.038565,0.000000
52.090004,62.364944,-569.845459,0.002160,0.001515,0.038487,277.413116,14.132098,0.384875,-569.845459,0.038565,0.000000
52.230003,62.358986,-569.800964,0.002169,0.001515,0.038487,277.386627,14.130748,0.384875,-569.800964,0.038565,0.000000
52.370003,62.349678,-569.845459,0.002169,0.001515,0.038487,277.345215,14.128639,0.384875,-569.845459,0.038565,0.000000
52.510002,62.359360,-569.845459,0.002190,0.001515,0.038487,277.388275,14.130833,0.384875,-569.845459,0.038565,0.000000
52.650002,62.349304,-569.800964,0.002182,0.001515,0.038487,277.343567,14.128554,0.384875,-569.800964,0.038565,0.000000
52.790001,62.337013,-569.845459,0.002177,0.001515,0.038487,277.288879,14.125770,0.384875,-569.845459,0.038565,0.000000
52.930004,62.335899,-569.845459,0.002177,0.001515,0.038487,277.283936,14.125517,0.384875,-569.845459,0.038565,0.000000
53.070004,62.335899,-569.845459,0.002177,0.001515,0.038487,277.283936,14.125517,0.384875,-569.845459,0.038565,0.000000
53.210003,62.323608,-569.845459,0.002177,0.001515,0.038487,277.229248,14.122731,0.384875,-569.845459,0.038565,0.000000
53.350002,62.320259,-569.845459,0.002164,0.001515,0.038487,277.214355,14.121973,0.384875,-569.845459,0.038565,0.000000
53.490002,62.307968,-569.845459,0.002190,0.001515,0.038487,277.159698,14.119187,0.384875,-569.845459,0.038565,0.000000
53.630001,62.302757,-569.800964,0.002169,0.001515,0.038487,277.136505,14.118006,0.384875,-569.800964,0.038565,0.000000
53.770004,62.291954,-569.889954,0.002173,0.001515,0.038487,277.088440,14.115559,0.384875,-569.889954,0.038565,0.000000
53.910004,62.280411,-569.889954,0.002190,0.001515,0.038487,277.037109,14.112944,0.384875,-569.889954,0.038565,0.000000
54.050003,62.279297,-569.845459,0.002177,0.001515,0.038487,277.032135,14.112691,0.384875,-569.845459,0.038565,0.000000
54.190002,62.277061,-569.889954,0.002173,0.001515,0.038487,277.022217,14.112185,0.384875,-569.889954,0.038565,0.000000
54.330002,62.267006,-569.845459,0.002190,0.001515,0.038487,276.977478,14.109905,0.384875,-569.845459,0.038565,0.000000
54.470001,62.268127,-569.934448,0.002173,0.001515,0.038487,276.982452,14.110160,0.384875,-569.934448,0.038565,0.000000
54.610004,62.253601,-569.845459,0.002199,0.001515,0.038487,276.917847,14.106868,0.384875,-569.845459,0.038565,0.000000
54.750004,62.251740,-569.934448,0.002182,0.001515,0.038487,276.909576,14.106446,0.384875,-569.934448,0.038565,0.000000
54.890003,62.253601,-569.934448,0.002182,0.001515,0.038487,276.917847,14.106868,0.384875,-569.934448,0.038565,0.000000
55.030003,62.237221,-569.889954,0.002173,0.001515,0.038487,276.844971,14.103156,0.384875,-569.889954,0.038565,0.000000
55.170002,62.237221,-569.934448,0.002173,0.001515,0.038487,276.844971,14.103156,0.384875,-569.934448,0.038565,0.000000
55.310001,62.230515,-569.934448,0.002177,0.001515,0.038487,276.815155,14.101636,0.384875,-569.934448,0.038565,0.000000
55.450001,62.206314,-569.845459,0.002182,0.001515,0.038487,276.707520,14.096152,0.384875,-569.845459,0.038565,0.000000
55.590004,62.196259,-569.934448,0.002190,0.001515,0.038487,276.662781,14.093874,0.384875,-569.934448,0.038565,0.000000
55.730003,62.196632,-569.889954,0.002186,0.001515,0.038487,276.664429,14.093959,0.384875,-569.889954,0.038565,0.000000
55.870003,62.190300,-569.934448,0.002177,0.001515,0.038487,276.636261,14.092524,0.384875,-569.934448,0.038565,0.000000
56.010002,62.194023,-569.845459,0.002173,0.001515,0.038487,276.652832,14.093368,0.384875,-569.845459,0.038565,0.000000
56.150002,62.189186,-569.845459,0.002160,0.001515,0.038487,276.631317,14.092271,0.384875,-569.845459,0.038565,0.000000
56.290001,62.182106,-569.978882,0.002203,0.001515,0.038487,276.599823,14.090667,0.384875,-569.978882,0.038565,0.000000
56.430004,62.173912,-569.889954,0.002173,0.001515,0.038487,276.563385,14.088810,0.384875,-569.889954,0.038565,0.000000
56.570004,62.181366,-569.978882,0.002177,0.001515,0.038487,276.596527,14.090499,0.384875,-569.978882,0.038565,0.000000
56.710003,62.171684,-569.934448,0.002177,0.001515,0.038487,276.553467,14.088305,0.384875,-569.934448,0.038565,0.000000
56.850002,62.157158,-569.934448,0.002173,0.001515,0.038487,276.488861,14.085013,0.384875,-569.934448,0.038565,0.000000
56.990002,62.152321,-569.934448,0.002177,0.001515,0.038487,276.467346,14.083918,0.384875,-569.934448,0.038565,0.000000
57.100002,62.160141,-569.934448,0.002177,0.001515,0.038487,276.502106,14.085689,0.384875,-569.934448,0.038565,0.000000