File: Data/AG AL compression 300N/AD membrane Peeled 300N_1_2_03202024_194546.csv
Time (sec),S:Load (lbs),S:HL1 (DIM),S:LVDT (in),S:Position (in),Ch:Position (mm),Ch:Load (N),Ch:Stress (MPa),Ch:Strain (mm/mm),Ch:HL1 (DIM),Set Point (),Cycles ()
0.010000,0.002975,-513.265686,0.000004,-0.000000,-0.000000,0.013236,0.000674,-0.000000,-513.265686,0.000191,0.000000
0.180000,0.002975,-513.310181,-0.000004,-0.000000,-0.000000,0.013236,0.000674,-0.000000,-513.310181,0.000191,0.000000
0.350000,-0.002609,-513.310181,0.000000,0.000001,0.000026,-0.011607,-0.000591,0.000257,-513.310181,0.000451,0.000000
0.520000,-0.011177,-513.354675,-0.000004,0.000100,0.002532,-0.049718,-0.002533,0.025321,-513.354675,0.003278,0.000000
0.690000,-0.014900,-513.221191,0.000013,0.000199,0.005056,-0.066279,-0.003376,0.050559,-513.221191,0.006122,0.000000
0.860000,0.038353,-513.265686,0.000138,0.000315,0.008004,0.170603,0.008691,0.080043,-513.265686,0.008950,0.000000
1.030000,0.029411,-513.265686,0.000246,0.000423,0.010745,0.130828,0.006665,0.107449,-513.265686,0.011777,0.000000
1.200000,0.017502,-513.221191,0.000345,0.000527,0.013390,0.077852,0.003966,0.133898,-513.221191,0.014604,0.000000
1.370000,0.021599,-513.310181,0.000470,0.000645,0.016382,0.096076,0.004894,0.163818,-513.310181,0.017448,0.000000
1.540000,0.007446,-513.310181,0.000586,0.000754,0.019148,0.033123,0.001687,0.191482,-513.310181,0.020276,0.000000
1.710000,-0.011917,-513.265686,0.000703,0.000866,0.021993,-0.053010,-0.002700,0.219929,-513.265686,0.023103,0.000000
1.880000,-0.037987,-513.354675,0.000806,0.000979,0.024863,-0.168974,-0.008608,0.248634,-513.354675,0.025947,0.000000
2.050000,-0.039101,-513.265686,0.000931,0.001089,0.027673,-0.173928,-0.008860,0.276729,-513.265686,0.028774,0.000000
2.220000,-0.002983,-513.354675,0.001030,0.001204,0.030587,-0.013269,-0.000676,0.305869,-513.354675,0.031602,0.000000
2.390000,-0.007446,-513.310181,0.001138,0.001310,0.033267,-0.033123,-0.001687,0.332666,-513.310181,0.034429,0.000000
2.560000,0.040215,-513.310181,0.001246,0.001414,0.035903,0.178883,0.009113,0.359031,-513.310181,0.037273,0.000000
2.730000,0.022713,-513.354675,0.001362,0.001535,0.038999,0.101031,0.005147,0.389992,-513.354675,0.040101,0.000000
2.900000,0.004097,-513.443604,0.001479,0.001651,0.041948,0.018224,0.000928,0.419476,-513.443604,0.042928,0.000000
3.070000,-0.013039,-513.354675,0.001613,0.001762,0.044758,-0.057999,-0.002955,0.447575,-513.354675,0.045772,0.000000
3.240000,-0.008568,-513.354675,0.001729,0.001872,0.047541,-0.038112,-0.001941,0.475413,-513.354675,0.048599,0.000000
3.410000,0.003349,-513.310181,0.001832,0.001986,0.050455,0.014898,0.000759,0.504549,-513.310181,0.051427,0.000000
3.580000,0.008186,-513.354675,0.001949,0.002095,0.053204,0.036415,0.001855,0.532043,-513.354675,0.054253,0.000000
3.750000,0.001488,-513.443604,0.002044,0.002204,0.055988,0.006618,0.000337,0.559881,-513.443604,0.057098,0.000000
3.920000,0.026436,-513.354675,0.002151,0.002308,0.058633,0.117593,0.005990,0.586329,-513.354675,0.059925,0.000000
4.090000,0.024948,-513.354675,0.002276,0.002425,0.061590,0.110975,0.005653,0.615901,-513.354675,0.062752,0.000000
4.260000,0.003349,-513.310181,0.002397,0.002539,0.064478,0.014898,0.000759,0.644780,-513.310181,0.065597,0.000000
4.430000,-0.043198,-513.399109,0.002522,0.002649,0.067288,-0.192153,-0.009789,0.672879,-513.399109,0.068424,0.000000
4.600000,-0.033890,-513.399109,0.002608,0.002762,0.070150,-0.150749,-0.007680,0.701496,-513.399109,0.071251,0.000000
4.770000,-0.011543,-513.443604,0.002738,0.002875,0.073029,-0.051347,-0.002616,0.730288,-513.443604,0.074078,0.000000
4.940000,0.026436,-513.354675,0.002850,0.002989,0.075917,0.117593,0.005990,0.759167,-513.354675,0.076923,0.000000
5.110000,0.024574,-513.399109,0.002971,0.003103,0.078822,0.109312,0.005569,0.788220,-513.399109,0.079750,0.000000
5.280000,0.039467,-513.443604,0.003057,0.003205,0.081415,0.175557,0.008943,0.814150,-513.443604,0.082577,0.000000
5.450000,0.020103,-513.443604,0.003173,0.003317,0.084260,0.089425,0.004556,0.842597,-513.443604,0.085422,0.000000
5.620000,0.021965,-513.443604,0.003307,0.003435,0.087251,0.097705,0.004977,0.872513,-513.443604,0.088249,0.000000
5.790000,0.007446,-513.354675,0.003393,0.003539,0.089897,0.033123,0.001687,0.898966,-513.354675,0.091076,0.000000
5.960001,-0.002983,-513.399109,0.003518,0.003654,0.092802,-0.013269,-0.000676,0.928018,-513.399109,0.093920,0.000000
6.130000,-0.024948,-513.399109,0.003617,0.003766,0.095655,-0.110975,-0.005653,0.956549,-513.399109,0.096748,0.000000
6.300000,0.001488,-513.443604,0.003747,0.003879,0.098534,0.006618,0.000337,0.985341,-513.443604,0.099575,0.000000
6.470000,0.008560,-513.443604,0.003850,0.003991,0.101370,0.038078,0.001940,1.013701,-513.443604,0.102402,0.000000
6.640000,0.015266,-513.354675,0.003971,0.004096,0.104032,0.067908,0.003459,1.040324,-513.354675,0.105247,0.000000
6.810000,0.032768,-513.399109,0.004079,0.004205,0.106807,0.145760,0.007425,1.068075,-513.399109,0.108074,0.000000
6.980000,0.021225,-513.399109,0.004182,0.004324,0.109834,0.094413,0.004810,1.098339,-513.399109,0.110901,0.000000
7.150001,0.005585,-513.443604,0.004299,0.004436,0.112670,0.024842,0.001266,1.126699,-513.443604,0.113745,0.000000
7.320000,-0.005959,-513.488098,0.004424,0.004548,0.115532,-0.026505,-0.001350,1.155316,-513.488098,0.116572,0.000000
7.490000,0.012283,-513.443604,0.004531,0.004659,0.118333,0.054639,0.002783,1.183329,-513.443604,0.119399,0.000000
7.660000,0.030533,-513.399109,0.004631,0.004771,0.121177,0.135817,0.006919,1.211772,-513.399109,0.122227,0.000000
7.830000,0.036118,-513.443604,0.004747,0.004881,0.123987,0.160659,0.008184,1.239871,-513.443604,0.125071,0.000000
8.000000,0.016006,-513.532593,0.004833,0.004990,0.126745,0.071200,0.003627,1.267448,-513.532593,0.127898,0.000000
8.170000,0.021965,-513.532593,0.004945,0.005095,0.129416,0.097705,0.004977,1.294162,-513.532593,0.130725,0.000000
8.340000,0.015640,-513.443604,0.005083,0.005213,0.132416,0.069571,0.003544,1.324164,-513.443604,0.133570,0.000000
8.510000,0.004097,-513.399109,0.005191,0.005326,0.135279,0.018224,0.000928,1.352786,-513.399109,0.136397,0.000000
8.680000,-0.026810,-513.488098,0.005299,0.005437,0.138097,-0.119255,-0.006075,1.380968,-513.488098,0.139224,0.000000
8.850000,-0.011917,-513.488098,0.005420,0.005549,0.140933,-0.053010,-0.002700,1.409328,-513.488098,0.142051,0.000000
9.020000,0.029411,-513.532593,0.005540,0.005662,0.143821,0.130828,0.006665,1.438207,-513.532593,0.144896,0.000000
9.190001,0.039093,-513.488098,0.005631,0.005775,0.146691,0.173894,0.008859,1.466912,-513.488098,0.147723,0.000000
9.360001,0.048775,-513.488098,0.005739,0.005888,0.149544,0.216961,0.011053,1.495442,-513.488098,0.150550,0.000000
9.530001,0.056595,-513.532593,0.005846,0.005991,0.152172,0.251746,0.012825,1.521721,-513.532593,0.153395,0.000000
9.700001,0.026436,-513.488098,0.005980,0.006109,0.155164,0.117593,0.005990,1.551640,-513.488098,0.156222,0.000000
9.870001,0.031647,-513.443604,0.006092,0.006220,0.157982,0.140772,0.007171,1.579823,-513.443604,0.159049,0.000000
10.040001,0.006699,-513.488098,0.006196,0.006326,0.160688,0.029797,0.001518,1.606881,-513.488098,0.161876,0.000000
10.210000,-0.004471,-513.443604,0.006312,0.006442,0.163637,-0.019887,-0.001013,1.636365,-513.443604,0.164721,0.000000
10.380000,0.014519,-513.532593,0.006428,0.006554,0.166473,0.064583,0.003290,1.664726,-513.532593,0.167548,0.000000
10.550000,0.014145,-513.577087,0.006545,0.006667,0.169343,0.062920,0.003205,1.693430,-513.577087,0.170375,0.000000
10.720000,0.002975,-513.577087,0.006640,0.006772,0.171997,0.013236,0.000674,1.719966,-513.577087,0.173220,0.000000
10.890000,0.036118,-513.488098,0.006748,0.006880,0.174755,0.160659,0.008184,1.747547,-513.488098,0.176047,0.000000
11.060000,0.052132,-513.532593,0.006860,0.006994,0.177660,0.231893,0.011813,1.776596,-513.532593,0.178874,0.000000
11.230000,0.037605,-513.532593,0.006976,0.007108,0.180539,0.167277,0.008521,1.805391,-513.532593,0.181701,0.000000
11.400001,0.031647,-513.577087,0.007067,0.007220,0.183392,0.140772,0.007171,1.833922,-513.577087,0.184545,0.000000
11.570001,0.029411,-513.577087,0.007205,0.007335,0.186297,0.130828,0.006665,1.862975,-513.577087,0.187373,0.000000
11.740001,0.048775,-513.532593,0.007312,0.007448,0.189185,0.216961,0.011053,1.891853,-513.532593,0.190200,0.000000
11.910001,0.083412,-513.532593,0.007424,0.007558,0.191978,0.371036,0.018901,1.919778,-513.532593,0.193044,0.000000
12.080001,0.106125,-513.532593,0.007545,0.007669,0.194805,0.472067,0.024048,1.948048,-513.532593,0.195871,0.000000
12.250001,0.126602,-513.577087,0.007649,0.007774,0.197458,0.563155,0.028688,1.974584,-513.577087,0.198699,0.000000
12.420001,0.160492,-513.577087,0.007752,0.007884,0.200251,0.713904,0.036368,2.002508,-513.577087,0.201526,0.000000
12.590000,0.234222,-513.577087,0.007881,0.008001,0.203225,1.041873,0.053076,2.032254,-513.577087,0.204370,0.000000
12.760000,0.310928,-513.577087,0.007994,0.008111,0.206027,1.383078,0.070457,2.060266,-513.577087,0.207197,0.000000
12.930000,0.472908,-513.577087,0.008106,0.008224,0.208888,2.103600,0.107162,2.088884,-513.577087,0.210025,0.000000
13.100000,0.554832,-513.577087,0.008162,0.000004,0.000113,2.468018,0.125727,0.001128,-513.577087,0.000355,0.000000
13.270000,0.500465,-513.621521,0.008175,0.000004,0.000113,2.226181,0.113407,0.001128,-513.621521,0.000355,0.000000
13.440001,0.501953,-513.577087,0.008175,0.000004,0.000113,2.232799,0.113744,0.001128,-513.577087,0.000355,0.000000
13.610001,0.481850,-513.577087,0.008157,0.000004,0.000113,2.143374,0.109189,0.001128,-513.577087,0.000425,0.000000
13.780001,0.529884,-513.577087,0.008175,0.000004,0.000113,2.357043,0.120074,0.001128,-513.577087,0.000711,0.000000
13.950001,0.519455,-513.621521,0.008170,0.000005,0.000121,2.310651,0.117710,0.001215,-513.621521,0.000997,0.000000
14.120001,0.523178,-513.621521,0.008183,0.000005,0.000121,2.327212,0.118554,0.001215,-513.621521,0.001275,0.000000
14.290001,0.519829,-513.666016,0.008170,0.000005,0.000121,2.312314,0.117795,0.001215,-513.666016,0.001561,0.000000
14.460001,0.739532,-513.577087,0.008179,0.000035,0.000893,3.289605,0.167580,0.008932,-513.577087,0.001847,0.000000
14.630001,0.736923,-513.577087,0.008188,0.000045,0.001153,3.277998,0.166989,0.011533,-513.577087,0.002124,0.000000
14.800001,0.789803,-513.621521,0.008196,0.000058,0.001483,3.513217,0.178972,0.014829,-513.621521,0.002411,0.000000
14.970000,0.775276,-513.577087,0.008201,0.000069,0.001752,3.448601,0.175680,0.017516,-513.577087,0.002697,0.000000
15.140000,0.807671,-513.621521,0.008231,0.000079,0.002012,3.592698,0.183021,0.020121,-513.621521,0.002975,0.000000
15.310000,0.898529,-513.577087,0.008239,0.000091,0.002307,3.996857,0.203610,0.023069,-513.577087,0.003261,0.000000
15.480000,0.955505,-513.666016,0.008239,0.000103,0.002619,4.250300,0.216521,0.026191,-513.666016,0.003547,0.000000
15.650001,1.010986,-513.710510,0.008244,0.000114,0.002888,4.497092,0.229093,0.028879,-513.710510,0.003824,0.000000
15.820001,1.051575,-513.621521,0.008248,0.000122,0.003105,4.677638,0.238290,0.031047,-513.621521,0.004111,0.000000
15.990001,1.098495,-513.710510,0.008269,0.000131,0.003330,4.886352,0.248923,0.033300,-513.710510,0.004397,0.000000
16.160000,1.146904,-513.621521,0.008287,0.000141,0.003573,5.101684,0.259892,0.035729,-513.621521,0.004674,0.000000
16.330000,1.210579,-513.666016,0.008282,0.000153,0.003885,5.384924,0.274321,0.038852,-513.666016,0.004960,0.000000
16.500000,1.312981,-513.755005,0.008317,0.000173,0.004406,5.840430,0.297526,0.044056,-513.755005,0.005247,0.000000
16.670000,1.353569,-513.710510,0.008321,0.000183,0.004640,6.020976,0.306723,0.046395,-513.710510,0.005524,0.000000
16.840000,1.430283,-513.666016,0.008330,0.000196,0.004969,6.362215,0.324107,0.049692,-513.666016,0.005810,0.000000
17.010000,1.431023,-513.666016,0.008338,0.000203,0.005151,6.365507,0.324274,0.051512,-513.666016,0.006097,0.000000
17.180000,1.557632,-513.666016,0.008343,0.000215,0.005463,6.928695,0.352965,0.054635,-513.666016,0.006374,0.000000
17.350000,1.598221,-513.710510,0.008356,0.000224,0.005698,7.109241,0.362162,0.056978,-513.710510,0.006660,0.000000
17.520000,1.742699,-513.710510,0.008369,0.000237,0.006027,7.751911,0.394901,0.060271,-513.710510,0.006946,0.000000
17.690001,1.794830,-513.710510,0.008369,0.000247,0.006270,7.983804,0.406714,0.062701,-513.710510,0.007224,0.000000
17.860001,1.936333,-513.666016,0.008390,0.000257,0.006539,8.613238,0.438779,0.065388,-513.666016,0.007510,0.000000
18.030001,1.969101,-513.621521,0.008386,0.000266,0.006747,8.758999,0.446205,0.067470,-513.621521,0.007796,0.000000
18.200001,2.167953,-513.710510,0.008390,0.000285,0.007233,9.643538,0.491265,0.072326,-513.710510,0.008074,0.000000
18.370001,2.193642,-513.799438,0.008412,0.000293,0.007449,9.757806,0.497086,0.074494,-513.799438,0.008360,0.000000
18.540001,2.371635,-513.755005,0.008425,0.000307,0.007796,10.549562,0.537420,0.077961,-513.755005,0.008646,0.000000
18.710001,2.439407,-513.710510,0.008451,0.000317,0.008039,10.851026,0.552778,0.080391,-513.710510,0.008932,0.000000
18.880001,2.544044,-513.666016,0.008446,0.000326,0.008282,11.316475,0.576489,0.082821,-513.666016,0.009210,0.000000
19.050001,2.721664,-513.710510,0.008446,0.000338,0.008586,12.106568,0.616738,0.085857,-513.710510,0.009496,0.000000
19.220001,2.820717,-513.755005,0.008455,0.000350,0.008880,12.547175,0.639184,0.088805,-513.755005,0.009782,0.000000
19.390001,3.017700,-513.710510,0.008485,0.000364,0.009236,13.423401,0.683821,0.092359,-513.710510,0.010060,0.000000
19.560001,3.166283,-513.710510,0.008502,0.000373,0.009470,14.084329,0.717490,0.094702,-513.710510,0.010346,0.000000
19.730001,3.346138,-513.755005,0.008489,0.000384,0.009748,14.884365,0.758246,0.097476,-513.755005,0.010632,0.000000
19.900002,3.444817,-513.799438,0.008502,0.000391,0.009930,15.323310,0.780607,0.099297,-513.799438,0.010910,0.000000
20.070002,3.850327,-513.799438,0.008515,0.000410,0.010407,17.127108,0.872496,0.104066,-513.799438,0.011196,0.000000
20.240002,3.930763,-513.799438,0.008520,0.000421,0.010684,17.484909,0.890724,0.106840,-513.799438,0.011482,0.000000
20.410002,4.116951,-513.755005,0.008550,0.000432,0.010971,18.313112,0.932914,0.109705,-513.755005,0.011760,0.000000
20.580002,4.266640,-513.710510,0.008550,0.000441,0.011196,18.978962,0.966834,0.111957,-513.710510,0.012046,0.000000
20.750002,4.485222,-513.799438,0.008545,0.000451,0.011465,19.951263,1.016366,0.114648,-513.799438,0.012332,0.000000
20.920000,4.690399,-513.755005,0.008563,0.000463,0.011768,20.863937,1.062860,0.117684,-513.755005,0.012609,0.000000
21.090000,4.946968,-513.799438,0.008567,0.000473,0.012020,22.005213,1.120999,0.120197,-513.799438,0.012896,0.000000
21.260000,5.211723,-513.755005,0.008584,0.000487,0.012358,23.182903,1.180993,0.123581,-513.755005,0.013182,0.000000
21.430000,5.510735,-513.710510,0.008597,0.000498,0.012662,24.512972,1.248750,0.126616,-513.710510,0.013459,0.000000
21.600000,5.733788,-513.755005,0.008584,0.000508,0.012896,25.505161,1.299295,0.128955,-513.755005,0.013746,0.000000
21.770000,5.720009,-513.888428,0.008610,0.000511,0.012982,25.443871,1.296173,0.129822,-513.888428,0.014032,0.000000
21.940001,6.011581,-513.843933,0.008610,0.000521,0.013225,26.740850,1.362244,0.132252,-513.843933,0.014309,0.000000
22.110001,6.697113,-513.799438,0.008619,0.000541,0.013746,29.790247,1.517587,0.137456,-513.799438,0.014595,0.000000
22.280001,6.949585,-513.755005,0.008627,0.000553,0.014058,30.913298,1.574798,0.140579,-513.755005,0.014881,0.000000
22.450001,7.120506,-513.843933,0.008627,0.000563,0.014292,31.673594,1.613530,0.142918,-513.843933,0.015159,0.000000
22.620001,7.461227,-513.799438,0.008640,0.000575,0.014595,33.189198,1.690738,0.145953,-513.799438,0.015445,0.000000
22.790001,7.837318,-513.843933,0.008666,0.000585,0.014847,34.862133,1.775962,0.148470,-513.843933,0.015732,0.000000
22.960001,8.114738,-513.799438,0.008666,0.000594,0.015081,36.096161,1.838826,0.150809,-513.799438,0.016009,0.000000
23.130001,8.488228,-513.755005,0.008683,0.000609,0.015480,37.757523,1.923460,0.154798,-513.755005,0.016295,0.000000
23.300001,8.651329,-513.799438,0.008666,0.000612,0.015549,38.483032,1.960419,0.155495,-513.799438,0.016581,0.000000
23.470001,9.389366,-513.888428,0.008683,0.000631,0.016018,41.765987,2.127661,0.160177,-513.888428,0.016859,0.000000
23.640001,9.548370,-513.799438,0.008696,0.000638,0.016200,42.473274,2.163692,0.161997,-513.799438,0.017145,0.000000
23.810001,9.489906,-513.755005,0.008709,0.000643,0.016330,42.213211,2.150444,0.163299,-513.755005,0.017431,0.000000
23.980001,10.515053,-513.799438,0.008701,0.000662,0.016807,46.773293,2.382745,0.168068,-513.799438,0.017709,0.000000
24.150002,10.998764,-513.799438,0.008722,0.000676,0.017162,48.924946,2.492356,0.171622,-513.799438,0.017995,0.000000
24.320002,11.158508,-513.843933,0.008714,0.000684,0.017379,49.635525,2.528554,0.173791,-513.843933,0.018281,0.000000
24.490002,11.819847,-513.843933,0.008727,0.000698,0.017735,52.577305,2.678416,0.177349,-513.843933,0.018558,0.000000
24.660002,12.200783,-513.799438,0.008739,0.000710,0.018030,54.271793,2.764737,0.180297,-513.799438,0.018845,0.000000
24.830002,12.486763,-513.799438,0.008748,0.000718,0.018229,55.543896,2.829541,0.182292,-513.799438,0.019131,0.000000
25.000002,12.850197,-513.843933,0.008748,0.000728,0.018489,57.160530,2.911896,0.184892,-513.843933,0.019409,0.000000
25.170002,13.469826,-513.932922,0.008748,0.000742,0.018836,59.916779,3.052306,0.188359,-513.932922,0.019695,0.000000
25.340002,13.981842,-513.932922,0.008778,0.000756,0.019200,62.194340,3.168331,0.192004,-513.932922,0.019981,0.000000
25.510002,14.353470,-513.888428,0.008778,0.000764,0.019417,63.847424,3.252543,0.194173,-513.888428,0.020258,0.000000
25.680000,14.617851,-513.888428,0.008778,0.000770,0.019565,65.023453,3.312452,0.195645,-513.888428,0.020544,0.000000
25.850000,15.314186,-513.843933,0.008787,0.000785,0.019946,68.120903,3.470244,0.199460,-513.843933,0.020831,0.000000
26.020000,15.880936,-513.932922,0.008783,0.000797,0.020241,70.641930,3.598671,0.202409,-513.932922,0.021108,0.000000
26.190001,16.415291,-513.932922,0.008804,0.000809,0.020553,73.018860,3.719758,0.205531,-513.932922,0.021394,0.000000
26.360001,16.823044,-513.888428,0.008817,0.000819,0.020814,74.832634,3.812156,0.208135,-513.888428,0.021681,0.000000
26.530001,17.327980,-513.843933,0.008808,0.000831,0.021108,77.078705,3.926576,0.211084,-513.843933,0.021958,0.000000
26.700001,17.674660,-513.888428,0.008830,0.000840,0.021342,78.620811,4.005135,0.213423,-513.888428,0.022244,0.000000
26.870001,17.991920,-513.932922,0.008839,0.000849,0.021577,80.032059,4.077027,0.215766,-513.932922,0.022530,0.000000
27.040001,18.387749,-513.888428,0.008834,0.000860,0.021845,81.792793,4.166724,0.218453,-513.888428,0.022816,0.000000
27.210001,19.172714,-513.977417,0.008843,0.000872,0.022149,85.284492,4.344599,0.221488,-513.977417,0.023094,0.000000
27.380001,19.917831,-513.888428,0.008847,0.000884,0.022452,88.598938,4.513445,0.224524,-513.888428,0.023380,0.000000
27.550001,20.191895,-513.888428,0.008852,0.000892,0.022661,89.818031,4.575549,0.226605,-513.888428,0.023667,0.000000
27.720001,20.380318,-513.977417,0.008873,0.000900,0.022851,90.656181,4.618246,0.228513,-513.977417,0.023944,0.000000
27.890001,21.681381,-513.932922,0.008869,0.000918,0.023319,96.443604,4.913071,0.233195,-513.932922,0.024230,0.000000
28.060001,22.172546,-513.888428,0.008890,0.000931,0.023658,98.628410,5.024371,0.236579,-513.888428,0.024516,0.000000
28.230001,22.765358,-513.888428,0.008895,0.000943,0.023953,101.265373,5.158704,0.239527,-513.888428,0.024794,0.000000
28.400002,23.148529,-513.888428,0.008895,0.000953,0.024204,102.969803,5.245532,0.242040,-513.888428,0.025080,0.000000
28.570002,23.640434,-513.977417,0.008895,0.000965,0.024508,105.157906,5.356999,0.245076,-513.977417,0.025366,0.000000
28.740002,24.107765,-513.932922,0.008895,0.000974,0.024751,107.236694,5.462897,0.247506,-513.932922,0.025644,0.000000
28.910002,24.299538,-513.932922,0.008925,0.000981,0.024924,108.089745,5.506354,0.249239,-513.932922,0.025930,0.000000
29.080002,25.188759,-513.932922,0.008921,0.000994,0.025245,112.045197,5.707854,0.252449,-513.932922,0.026216,0.000000
29.250002,25.859779,-513.977417,0.008929,0.001005,0.025522,115.030045,5.859910,0.255223,-513.977417,0.026494,0.000000
29.420002,25.972603,-513.932922,0.008938,0.001012,0.025704,115.531906,5.885476,0.257044,-513.932922,0.026780,0.000000
29.590002,26.678619,-514.021851,0.008933,0.001021,0.025939,118.672424,6.045462,0.259386,-514.021851,0.027066,0.000000
29.760002,27.994217,-514.021851,0.008929,0.001042,0.026459,124.524498,6.343580,0.264591,-514.021851,0.027344,0.000000
29.930002,28.633575,-513.977417,0.008968,0.001055,0.026806,127.368507,6.488461,0.268058,-513.977417,0.027630,0.000000
30.100002,29.129951,-513.977417,0.008951,0.001065,0.027057,129.576492,6.600942,0.270575,-513.977417,0.027916,0.000000
30.270002,29.493385,-513.977417,0.008951,0.001074,0.027274,131.193130,6.683297,0.272743,-513.977417,0.028193,0.000000
30.440001,30.142059,-514.021851,0.008968,0.001086,0.027578,134.078583,6.830288,0.275779,-514.021851,0.028480,0.000000
30.610001,30.478310,-514.021851,0.008981,0.001095,0.027803,135.574295,6.906484,0.278031,-514.021851,0.028766,0.000000
30.780001,30.762062,-513.932922,0.008985,0.001100,0.027942,136.836487,6.970783,0.279420,-513.932922,0.029043,0.000000
30.950001,31.234970,-513.932922,0.008994,0.001108,0.028150,138.940079,7.077945,0.281502,-513.932922,0.029330,0.000000
31.120001,32.668236,-513.977417,0.008981,0.001129,0.028688,145.315567,7.402728,0.286876,-513.977417,0.029616,0.000000
31.290001,33.160507,-514.066345,0.008985,0.001139,0.028922,147.505310,7.514278,0.289219,-514.066345,0.029893,0.000000
31.460001,33.457664,-514.021851,0.009007,0.001146,0.029113,148.827118,7.581615,0.291127,-514.021851,0.030179,0.000000
31.630001,33.767479,-514.021851,0.009011,0.001153,0.029277,150.205246,7.651820,0.292773,-514.021851,0.030466,0.000000
31.800001,35.067802,-514.021851,0.009011,0.001174,0.029815,155.989380,7.946477,0.298151,-514.021851,0.030743,0.000000
31.970001,36.040070,-514.021851,0.009015,0.001187,0.030153,160.314240,8.166797,0.301535,-514.021851,0.031029,0.000000
32.140003,36.489891,-514.021851,0.009020,0.001197,0.030396,162.315140,8.268727,0.303961,-514.021851,0.031315,0.000000
32.310001,36.927055,-514.021851,0.009037,0.001207,0.030648,164.259750,8.367791,0.306478,-514.021851,0.031593,0.000000
32.480003,37.782394,-514.021851,0.009046,0.001220,0.030977,168.064484,8.561613,0.309771,-514.021851,0.031879,0.000000
32.650002,38.074707,-514.066345,0.009050,0.001227,0.031160,169.364761,8.627851,0.311595,-514.066345,0.032165,0.000000
32.820000,38.515602,-514.021851,0.009046,0.001235,0.031359,171.325958,8.727760,0.313590,-514.021851,0.032443,0.000000
32.990002,39.705704,-514.110840,0.009067,0.001252,0.031801,176.619797,8.997441,0.318011,-514.110840,0.032729,0.000000
33.160000,40.477257,-514.110840,0.009058,0.001265,0.032122,180.051834,9.172277,0.321220,-514.110840,0.033015,0.000000
33.330002,40.763611,-514.021851,0.009067,0.001271,0.032278,181.325592,9.237165,0.322780,-514.021851,0.033293,0.000000
33.500000,41.245834,-514.066345,0.009076,0.001281,0.032530,183.470627,9.346440,0.325297,-514.066345,0.033579,0.000000
33.670002,41.850563,-514.066345,0.009067,0.001294,0.032876,186.160599,9.483473,0.328764,-514.066345,0.033865,0.000000
33.840000,43.141953,-514.110840,0.009071,0.001308,0.033232,191.904984,9.776106,0.332321,-514.110840,0.034143,0.000000
34.010002,43.891914,-514.066345,0.009102,0.001320,0.033518,195.240982,9.946050,0.335183,-514.066345,0.034429,0.000000
34.180000,44.289230,-514.066345,0.009102,0.001329,0.033761,197.008331,10.036083,0.337609,-514.066345,0.034715,0.000000
34.350002,44.820984,-514.066345,0.009110,0.001337,0.033969,199.373688,10.156580,0.339691,-514.066345,0.034992,0.000000
34.520000,45.823036,-514.110840,0.009102,0.001352,0.034342,203.831039,10.383649,0.343422,-514.110840,0.035279,0.000000
34.690002,46.120934,-514.155334,0.009097,0.001359,0.034524,205.156158,10.451153,0.345243,-514.155334,0.035565,0.000000
34.860001,46.841476,-514.066345,0.009115,0.001370,0.034793,208.361298,10.614429,0.347930,-514.066345,0.035842,0.000000
35.030003,47.884117,-514.110840,0.009110,0.001384,0.035166,212.999191,10.850696,0.351658,-514.110840,0.036129,0.000000
35.200001,48.521248,-514.155334,0.009123,0.001392,0.035348,215.833282,10.995072,0.353479,-514.155334,0.036415,0.000000
35.370003,48.870529,-514.066345,0.009119,0.001400,0.035565,217.386978,11.074220,0.355648,-514.066345,0.036701,0.000000
35.540001,49.620491,-514.155334,0.009132,0.001412,0.035860,220.722961,11.244164,0.358596,-514.155334,0.036978,0.000000
35.710003,50.389442,-514.155334,0.009140,0.001423,0.036146,224.143433,11.418410,0.361457,-514.155334,0.037265,0.000000
35.880001,51.776901,-514.155334,0.009145,0.001438,0.036519,230.315155,11.732813,0.365189,-514.155334,0.037551,0.000000
36.050003,52.572662,-514.066345,0.009153,0.001449,0.036814,233.854889,11.913136,0.368138,-514.066345,0.037829,0.000000
36.220001,53.600777,-514.110840,0.009136,0.001464,0.037178,238.428162,12.146110,0.371779,-514.110840,0.038115,0.000000
36.390003,54.301956,-514.155334,0.009145,0.001474,0.037447,241.547165,12.304999,0.374466,-514.155334,0.038401,0.000000
36.560001,54.913391,-514.199768,0.009162,0.001484,0.037681,244.266968,12.443552,0.376809,-514.199768,0.038678,0.000000
36.730003,55.452591,-514.155334,0.009175,0.001491,0.037872,246.665451,12.565737,0.378717,-514.155334,0.038964,0.000000
36.900002,56.267708,-514.155334,0.009179,0.001503,0.038167,250.291260,12.750445,0.381665,-514.155334,0.039250,0.000000
37.070004,57.127518,-514.110840,0.009171,0.001514,0.038444,254.115891,12.945281,0.384439,-514.110840,0.039528,0.000000
37.240002,57.667458,-514.244263,0.009175,0.001522,0.038652,256.517670,13.067632,0.386521,-514.244263,0.039814,0.000000
37.410004,58.429337,-514.199768,0.009184,0.001534,0.038973,259.906677,13.240277,0.389731,-514.199768,0.040101,0.000000
37.580002,59.425430,-514.199768,0.009196,0.001546,0.039268,264.337524,13.465995,0.392679,-514.199768,0.040378,0.000000
37.750000,60.614784,-514.155334,0.009184,0.001564,0.039736,269.628021,13.735506,0.397361,-514.155334,0.040664,0.000000
37.920002,61.802284,-514.199768,0.009192,0.001574,0.039988,274.910278,14.004598,0.399878,-514.199768,0.040950,0.000000
38.090000,62.522079,-514.244263,0.009201,0.001585,0.040257,278.112091,14.167706,0.402565,-514.244263,0.041228,0.000000
38.260002,63.608284,-514.199768,0.009192,0.001598,0.040577,282.943787,14.413843,0.405775,-514.199768,0.041514,0.000000
38.430000,64.078224,-514.199768,0.009214,0.001606,0.040794,285.034180,14.520333,0.407944,-514.199768,0.041800,0.000000
38.600002,64.951805,-514.199768,0.009214,0.001618,0.041089,288.920044,14.718289,0.410892,-514.199768,0.042078,0.000000
38.770000,65.661171,-514.199768,0.009205,0.001628,0.041341,292.075470,14.879034,0.413405,-514.199768,0.042364,0.000000
38.940002,66.892616,-514.244263,0.009218,0.001641,0.041679,297.553223,15.158084,0.416789,-514.244263,0.042650,0.000000
39.110001,67.409843,-514.199768,0.009209,0.001647,0.041844,299.853973,15.275289,0.418435,-514.199768,0.042928,0.000000
39.280003,67.244881,-514.244263,0.009240,0.001641,0.041670,299.120178,15.237907,0.416702,-514.244263,0.041896,0.000000
39.450001,66.947350,-514.155334,0.009235,0.001641,0.041670,297.796692,15.170485,0.416702,-514.155334,0.041896,0.000000
39.620003,66.720573,-514.199768,0.009240,0.001640,0.041644,296.787933,15.119099,0.416441,-514.199768,0.041670,0.000000
39.790001,66.509819,-514.244263,0.009222,0.001639,0.041627,295.850464,15.071341,0.416267,-514.244263,0.041670,0.000000
39.960003,66.325859,-514.244263,0.009240,0.001639,0.041618,295.032166,15.029655,0.416179,-514.244263,0.041670,0.000000
40.130001,66.162025,-514.244263,0.009240,0.001639,0.041618,294.303375,14.992530,0.416179,-514.244263,0.041670,0.000000
40.300003,66.027214,-514.244263,0.009240,0.001638,0.041610,293.703705,14.961980,0.416096,-514.244263,0.041670,0.000000
40.470001,65.884972,-514.244263,0.009231,0.001638,0.041610,293.070984,14.929749,0.416096,-514.244263,0.041670,0.000000
40.640003,65.772896,-514.288757,0.009227,0.001638,0.041610,292.572449,14.904351,0.416096,-514.288757,0.041670,0.000000
40.810001,65.658943,-514.288757,0.009248,0.001638,0.041601,292.065552,14.878530,0.416009,-514.288757,0.041670,0.000000
40.980003,65.572929,-514.288757,0.009261,0.001638,0.041601,291.682953,14.859038,0.416009,-514.288757,0.041670,0.000000
41.150002,65.471275,-514.288757,0.009253,0.001638,0.041601,291.230774,14.836003,0.416009,-514.288757,0.041670,0.000000
41.320004,65.402382,-514.199768,0.009248,0.001638,0.041601,290.924316,14.820392,0.416009,-514.199768,0.041670,0.000000
41.490002,65.327904,-514.288757,0.009235,0.001638,0.041601,290.593018,14.803514,0.416009,-514.288757,0.041670,0.000000
41.660004,65.244865,-514.377747,0.009253,0.001638,0.041601,290.223663,14.784698,0.416009,-514.377747,0.041670,0.000000
41.830002,65.181190,-514.288757,0.009244,0.001638,0.041601,289.940430,14.770268,0.416009,-514.288757,0.041670,0.000000
42.000004,65.122353,-514.288757,0.009253,0.001638,0.041601,289.678680,14.756936,0.416009,-514.288757,0.041670,0.000000
42.170002,65.054588,-514.288757,0.009244,0.001637,0.041592,289.377258,14.741581,0.415922,-514.288757,0.041670,0.000000
42.340000,64.988304,-514.333252,0.009240,0.001637,0.041592,289.082428,14.726561,0.415922,-514.333252,0.041670,0.000000
42.510002,64.947716,-514.377747,0.009244,0.001637,0.041592,288.901855,14.717363,0.415922,-514.377747,0.041670,0.000000
42.680000,64.875099,-514.333252,0.009244,0.001637,0.041592,288.578857,14.700908,0.415922,-514.333252,0.041670,0.000000
42.850002,64.852379,-514.333252,0.009248,0.001637,0.041592,288.477783,14.695760,0.415922,-514.333252,0.041670,0.000000
43.020000,64.781639,-514.333252,0.009253,0.001637,0.041592,288.163116,14.679729,0.415922,-514.333252,0.041670,0.000000
43.190002,64.749245,-514.333252,0.009248,0.001637,0.041592,288.019012,14.672389,0.415922,-514.333252,0.041670,0.000000
43.360001,64.699333,-514.377747,0.009248,0.001637,0.041592,287.796997,14.661078,0.415922,-514.377747,0.041670,0.000000
43.530003,64.671410,-514.333252,0.009257,0.001637,0.041592,287.672791,14.654751,0.415922,-514.333252,0.041670,0.000000
43.700001,64.637901,-514.333252,0.009240,0.001637,0.041592,287.523743,14.647158,0.415922,-514.333252,0.041670,0.000000
43.870003,64.590981,-514.288757,0.009257,0.001637,0.041592,287.315033,14.636525,0.415922,-514.288757,0.041670,0.000000
44.040001,64.550392,-514.422180,0.009248,0.001637,0.041592,287.134491,14.627328,0.415922,-514.422180,0.041670,0.000000
44.210003,64.511299,-514.422180,0.009240,0.001637,0.041592,286.960602,14.618469,0.415922,-514.422180,0.041670,0.000000
44.380001,64.500496,-514.422180,0.009257,0.001637,0.041592,286.912537,14.616022,0.415922,-514.422180,0.041670,0.000000
44.550003,64.444267,-514.422180,0.009261,0.001637,0.041592,286.662415,14.603280,0.415922,-514.422180,0.041670,0.000000
44.720001,64.436073,-514.333252,0.009253,0.001637,0.041592,286.625977,14.601422,0.415922,-514.333252,0.041670,0.000000
44.890003,64.383934,-514.377747,0.009244,0.001637,0.041592,286.394043,14.589608,0.415922,-514.377747,0.041670,0.000000
45.060001,64.361977,-514.377747,0.009257,0.001637,0.041592,286.296356,14.584632,0.415922,-514.377747,0.041670,0.000000
45.230003,64.329582,-514.422180,0.009248,0.001637,0.041592,286.152283,14.577291,0.415922,-514.422180,0.041670,0.000000
45.400002,64.306114,-514.422180,0.009248,0.001637,0.041592,286.047882,14.571974,0.415922,-514.422180,0.041670,0.000000
45.570004,64.279305,-514.377747,0.009248,0.001637,0.041592,285.928619,14.565899,0.415922,-514.377747,0.041670,0.000000
45.740002,64.249519,-514.377747,0.009261,0.001637,0.041592,285.796143,14.559149,0.415922,-514.377747,0.041670,0.000000
45.910004,64.234993,-514.422180,0.009235,0.001637,0.041592,285.731506,14.555858,0.415922,-514.422180,0.041670,0.000000
46.080002,64.195900,-514.511169,0.009253,0.001637,0.041592,285.557617,14.546998,0.415922,-514.511169,0.041670,0.000000
46.250004,64.185463,-514.422180,0.009253,0.001637,0.041592,285.511200,14.544634,0.415922,-514.422180,0.041670,0.000000
46.420002,64.151955,-514.422180,0.009257,0.001637,0.041592,285.362152,14.537041,0.415922,-514.422180,0.041670,0.000000
46.590004,64.143761,-514.422180,0.009248,0.001637,0.041592,285.325684,14.535184,0.415922,-514.422180,0.041670,0.000000
46.760002,64.099083,-514.422180,0.009240,0.001637,0.041592,285.126953,14.525060,0.415922,-514.422180,0.041670,0.000000
46.930004,64.075249,-514.511169,0.009253,0.001637,0.041592,285.020935,14.519659,0.415922,-514.511169,0.041670,0.000000
47.100002,64.066673,-514.511169,0.009253,0.001637,0.041592,284.982788,14.517715,0.415922,-514.511169,0.041670,0.000000
47.270000,64.040245,-514.422180,0.009265,0.001637,0.041592,284.865234,14.511727,0.415922,-514.422180,0.041670,0.000000
47.440002,64.026085,-514.466675,0.009257,0.001637,0.041592,284.802246,14.508518,0.415922,-514.466675,0.041670,0.000000
47.610001,64.005989,-514.466675,0.009257,0.001637,0.041592,284.712860,14.503964,0.415922,-514.466675,0.041670,0.000000
47.780003,63.963539,-514.555664,0.009261,0.001637,0.041592,284.524017,14.494346,0.415922,-514.555664,0.041670,0.000000
47.950001,63.956459,-514.466675,0.009248,0.001637,0.041592,284.492523,14.492741,0.415922,-514.466675,0.041670,0.000000
48.120003,63.942314,-514.466675,0.009244,0.001637,0.041592,284.429626,14.489535,0.415922,-514.466675,0.041670,0.000000
48.290001,63.920341,-514.466675,0.009240,0.001637,0.041592,284.331879,14.484556,0.415922,-514.466675,0.041670,0.000000
48.460003,63.900978,-514.511169,0.009257,0.001637,0.041592,284.245758,14.480168,0.415922,-514.511169,0.041670,0.000000
48.630001,63.872673,-514.511169,0.009261,0.001637,0.041592,284.119843,14.473755,0.415922,-514.511169,0.041670,0.000000
48.800003,63.863365,-514.555664,0.009257,0.001637,0.041592,284.078430,14.471645,0.415922,-514.555664,0.041670,0.000000
48.970001,63.844002,-514.466675,0.009240,0.001637,0.041592,283.992310,14.467257,0.415922,-514.466675,0.041670,0.000000
49.140003,63.827248,-514.511169,0.009257,0.001637,0.041592,283.917786,14.463461,0.415922,-514.511169,0.041670,0.000000
49.310001,63.807137,-514.555664,0.009257,0.001637,0.041592,283.828308,14.458903,0.415922,-514.555664,0.041670,0.000000
49.480003,63.791862,-514.511169,0.009261,0.001637,0.041592,283.760376,14.455442,0.415922,-514.511169,0.041670,0.000000
49.650002,63.772499,-514.644592,0.009248,0.001637,0.041592,283.674255,14.451056,0.415922,-514.644592,0.041670,0.000000
49.820004,63.769524,-514.511169,0.009265,0.001637,0.041592,283.661011,14.450380,0.415922,-514.511169,0.041670,0.000000
49.990002,63.742348,-514.466675,0.009248,0.001637,0.041592,283.540131,14.444222,0.415922,-514.466675,0.041670,0.000000
50.160004,63.726707,-514.555664,0.009248,0.001637,0.041592,283.470551,14.440679,0.415922,-514.555664,0.041670,0.000000
50.330002,63.721855,-514.600098,0.009261,0.001637,0.041592,283.448975,14.439578,0.415922,-514.600098,0.041670,0.000000
50.500004,63.687981,-514.600098,0.009253,0.001637,0.041592,283.298279,14.431902,0.415922,-514.600098,0.041670,0.000000
50.670002,63.695793,-514.555664,0.009257,0.001637,0.041592,283.333038,14.433673,0.415922,-514.555664,0.041670,0.000000
50.840004,63.660423,-514.555664,0.009248,0.001637,0.041592,283.175720,14.425658,0.415922,-514.555664,0.041670,0.000000
51.010002,63.666756,-514.555664,0.009248,0.001637,0.041592,283.203888,14.427093,0.415922,-514.555664,0.041670,0.000000
51.180004,63.638084,-514.600098,0.009248,0.001637,0.041592,283.076324,14.420596,0.415922,-514.600098,0.041670,0.000000
51.350002,63.642540,-514.600098,0.009270,0.001637,0.041592,283.096161,14.421606,0.415922,-514.600098,0.041670,0.000000
51.520004,63.625786,-514.600098,0.009270,0.001637,0.041592,283.021637,14.417809,0.415922,-514.600098,0.041670,0.000000
51.690002,63.598228,-514.600098,0.009253,0.001637,0.041592,282.899048,14.411564,0.415922,-514.600098,0.041670,0.000000
51.860001,63.597862,-514.600098,0.009253,0.001637,0.041592,282.897430,14.411482,0.415922,-514.600098,0.041670,0.000000
52.030003,63.560249,-514.644592,0.009257,0.001637,0.041592,282.730103,14.402959,0.415922,-514.644592,0.041670,0.000000
52.200001,63.578133,-514.600098,0.009248,0.001637,0.041592,282.809662,14.407011,0.415922,-514.600098,0.041670,0.000000
52.370003,63.538277,-514.600098,0.009248,0.001637,0.041592,282.632385,14.397979,0.415922,-514.600098,0.041670,0.000000
52.540001,63.541634,-514.555664,0.009257,0.001637,0.041592,282.647308,14.398740,0.415922,-514.555664,0.041670,0.000000
52.710003,63.514824,-514.644592,0.009244,0.001637,0.041592,282.528046,14.392665,0.415922,-514.644592,0.041670,0.000000
52.880001,63.509239,-514.689087,0.009253,0.001637,0.041592,282.503204,14.391399,0.415922,-514.689087,0.041670,0.000000
53.050003,63.496956,-514.689087,0.009261,0.001637,0.041592,282.448578,14.388616,0.415922,-514.689087,0.041670,0.000000
53.220001,63.492104,-514.600098,0.009248,0.001637,0.041592,282.426971,14.387516,0.415922,-514.600098,0.041670,0.000000
53.390003,63.480186,-514.644592,0.009274,0.001637,0.041592,282.373962,14.384815,0.415922,-514.644592,0.041670,0.000000
53.560001,63.464180,-514.644592,0.009257,0.001637,0.041592,282.302765,14.381188,0.415922,-514.644592,0.041670,0.000000
53.730003,63.451897,-514.689087,0.009257,0.001637,0.041592,282.248138,14.378405,0.415922,-514.689087,0.041670,0.000000
53.900002,63.428062,-514.644592,0.009257,0.001637,0.041592,282.142120,14.373004,0.415922,-514.644592,0.041670,0.000000
54.070004,63.432899,-514.600098,0.009261,0.001637,0.041592,282.163635,14.374100,0.415922,-514.600098,0.041670,0.000000
54.240002,63.412056,-514.689087,0.009253,0.001637,0.041592,282.070923,14.369377,0.415922,-514.689087,0.041670,0.000000
54.410004,63.407204,-514.689087,0.009257,0.001637,0.041592,282.049316,14.368278,0.415922,-514.689087,0.041670,0.000000
54.580002,63.394920,-514.689087,0.009265,0.001637,0.041592,281.994690,14.365495,0.415922,-514.689087,0.041670,0.000000
54.750004,63.387474,-514.689087,0.009265,0.001637,0.041592,281.961578,14.363807,0.415922,-514.689087,0.041670,0.000000
54.920002,63.382637,-514.689087,0.009270,0.001637,0.041592,281.940063,14.362711,0.415922,-514.689087,0.041670,0.000000
55.090004,63.369972,-514.733582,0.009248,0.001637,0.041592,281.883728,14.359840,0.415922,-514.733582,0.041670,0.000000
55.260002,63.351357,-514.689087,0.009257,0.001637,0.041592,281.800903,14.355623,0.415922,-514.689087,0.041670,0.000000
55.430004,63.329002,-514.689087,0.009265,0.001637,0.041592,281.701477,14.350557,0.415922,-514.689087,0.041670,0.000000
55.600002,63.335716,-514.733582,0.009257,0.001637,0.041592,281.731323,14.352078,0.415922,-514.733582,0.041670,0.000000
55.770004,63.309639,-514.689087,0.009278,0.001637,0.041592,281.615326,14.346169,0.415922,-514.689087,0.041670,0.000000
55.940002,63.307777,-514.733582,0.009274,0.001637,0.041592,281.607056,14.345748,0.415922,-514.733582,0.041670,0.000000
56.110004,63.290276,-514.778076,0.009248,0.001637,0.041592,281.529205,14.341781,0.415922,-514.778076,0.041670,0.000000
56.280003,63.288414,-514.778076,0.009261,0.001637,0.041592,281.520935,14.341360,0.415922,-514.778076,0.041670,0.000000
56.450005,63.277626,-514.778076,0.009257,0.001637,0.041592,281.472931,14.338915,0.415922,-514.778076,0.041670,0.000000
56.620003,63.264214,-514.689087,0.009270,0.001637,0.041592,281.413269,14.335876,0.415922,-514.689087,0.041670,0.000000
56.790001,63.256401,-514.689087,0.009253,0.001637,0.041592,281.378540,14.334105,0.415922,-514.689087,0.041670,0.000000
56.960003,63.248955,-514.733582,0.009253,0.001637,0.041592,281.345398,14.332418,0.415922,-514.733582,0.041670,0.000000
57.130001,63.238899,-514.778076,0.009261,0.001637,0.041592,281.300659,14.330140,0.415922,-514.778076,0.041670,0.000000
57.300003,63.219536,-514.733582,0.009261,0.001637,0.041592,281.214539,14.325751,0.415922,-514.733582,0.041670,0.000000
57.470001,63.222145,-514.644592,0.009265,0.001637,0.041592,281.226135,14.326344,0.415922,-514.644592,0.041670,0.000000
57.640003,63.207619,-514.733582,0.009261,0.001637,0.041592,281.161530,14.323051,0.415922,-514.733582,0.041670,0.000000
57.810001,63.211708,-514.778076,0.009253,0.001637,0.041592,281.179718,14.323977,0.415922,-514.778076,0.041670,0.000000
57.980003,63.196068,-514.778076,0.009261,0.001637,0.041592,281.110138,14.320434,0.415922,-514.778076,0.041670,0.000000
58.150002,63.180809,-514.733582,0.009261,0.001637,0.041592,281.042267,14.316976,0.415922,-514.733582,0.041670,0.000000
58.320004,63.183037,-514.778076,0.009265,0.001637,0.041592,281.052185,14.317481,0.415922,-514.778076,0.041670,0.000000
58.490002,63.165169,-514.733582,0.009261,0.001637,0.041592,280.972717,14.313432,0.415922,-514.733582,0.041670,0.000000
58.660004,63.165169,-514.822510,0.009240,0.001637,0.041592,280.972717,14.313432,0.415922,-514.822510,0.041670,0.000000
58.830002,63.148033,-514.778076,0.009261,0.001637,0.041592,280.896484,14.309549,0.415922,-514.778076,0.041670,0.000000
59.000004,63.149529,-514.778076,0.009265,0.001637,0.041592,280.903137,14.309888,0.415922,-514.778076,0.041670,0.000000
59.170002,63.125328,-514.822510,0.009265,0.001637,0.041592,280.795471,14.304404,0.415922,-514.822510,0.041670,0.000000
59.340004,63.124947,-514.778076,0.009248,0.001637,0.041592,280.793793,14.304317,0.415922,-514.778076,0.041670,0.000000
59.510002,63.123085,-514.778076,0.009257,0.001637,0.041592,280.785492,14.303896,0.415922,-514.778076,0.041670,0.000000
59.680004,63.108559,-514.867004,0.009274,0.001637,0.041592,280.720886,14.300604,0.415922,-514.867004,0.041670,0.000000
59.850002,63.103722,-514.822510,0.009257,0.001637,0.041592,280.699371,14.299507,0.415922,-514.822510,0.041670,0.000000
60.020004,63.097771,-514.778076,0.009261,0.001637,0.041592,280.672913,14.298160,0.415922,-514.778076,0.041670,0.000000
60.190002,63.107079,-514.778076,0.009257,0.001637,0.041592,280.714294,14.300268,0.415922,-514.778076,0.041670,0.000000
60.360004,63.086220,-514.822510,0.009244,0.001637,0.041592,280.621521,14.295542,0.415922,-514.822510,0.041670,0.000000
60.530003,63.089195,-514.822510,0.009248,0.001637,0.041592,280.634766,14.296216,0.415922,-514.822510,0.041670,0.000000
60.700005,63.076164,-514.867004,0.009265,0.001637,0.041592,280.576782,14.293263,0.415922,-514.867004,0.041670,0.000000
60.870003,63.087334,-514.822510,0.009257,0.001637,0.041592,280.626465,14.295794,0.415922,-514.822510,0.041670,0.000000
61.040005,63.072441,-514.822510,0.009261,0.001637,0.041592,280.560242,14.292419,0.415922,-514.822510,0.041670,0.000000
61.210003,63.071327,-514.911499,0.009253,0.001637,0.041592,280.555267,14.292167,0.415922,-514.911499,0.041670,0.000000
61.380001,63.063881,-514.867004,0.009257,0.001637,0.041592,280.522156,14.290480,0.415922,-514.867004,0.041670,0.000000
61.550003,63.060905,-514.867004,0.009265,0.001637,0.041592,280.508911,14.289805,0.415922,-514.867004,0.041670,0.000000
61.720001,63.053825,-514.867004,0.009261,0.001637,0.041592,280.477417,14.288201,0.415922,-514.867004,0.041670,0.000000
61.890003,63.046005,-514.822510,0.009261,0.001637,0.041592,280.442627,14.286429,0.415922,-514.822510,0.041670,0.000000
62.060001,63.043030,-514.822510,0.009257,0.001637,0.041592,280.429413,14.285754,0.415922,-514.822510,0.041670,0.000000
62.230003,63.035583,-514.867004,0.009253,0.001637,0.041592,280.396271,14.284068,0.415922,-514.867004,0.041670,0.000000
62.400002,63.038185,-514.867004,0.009265,0.001637,0.041592,280.407837,14.284657,0.415922,-514.867004,0.041670,0.000000
62.570004,63.031487,-514.911499,0.009257,0.001637,0.041592,280.378052,14.283139,0.415922,-514.911499,0.041670,0.000000
62.740002,63.019196,-514.822510,0.009261,0.001637,0.041592,280.323395,14.280354,0.415922,-514.822510,0.041670,0.000000
62.910004,63.005043,-514.867004,0.009244,0.001637,0.041592,280.260437,14.277146,0.415922,-514.867004,0.041670,0.000000
63.080002,63.028503,-514.955994,0.009257,0.001637,0.041592,280.364777,14.282463,0.415922,-514.955994,0.041670,0.000000
63.250004,63.016960,-514.955994,0.009261,0.001637,0.041592,280.313446,14.279847,0.415922,-514.955994,0.041670,0.000000
63.420002,63.011002,-514.867004,0.009265,0.001637,0.041592,280.286926,14.278498,0.415922,-514.867004,0.041670,0.000000
63.590004,63.009514,-514.867004,0.009257,0.001637,0.041592,280.280304,14.278159,0.415922,-514.867004,0.041670,0.000000
63.760002,63.007652,-514.911499,0.009248,0.001637,0.041592,280.272034,14.277739,0.415922,-514.911499,0.041670,0.000000
63.930004,62.975998,-514.955994,0.009261,0.001637,0.041592,280.131226,14.270565,0.415922,-514.955994,0.041670,0.000000
64.100006,62.975998,-514.911499,0.009257,0.001637,0.041592,280.131226,14.270565,0.415922,-514.911499,0.041670,0.000000
64.270004,62.977119,-515.000427,0.009257,0.001637,0.041592,280.136230,14.270820,0.415922,-515.000427,0.041670,0.000000
64.440002,62.980469,-514.911499,0.009265,0.001637,0.041592,280.151123,14.271579,0.415922,-514.911499,0.041670,0.000000
64.610001,62.988663,-514.911499,0.009257,0.001637,0.041592,280.187561,14.273435,0.415922,-514.911499,0.041670,0.000000
64.780006,62.972649,-514.955994,0.009257,0.001637,0.041592,280.116333,14.269807,0.415922,-514.955994,0.041670,0.000000
64.950005,62.975998,-515.000427,0.009257,0.001637,0.041592,280.131226,14.270565,0.415922,-515.000427,0.041670,0.000000
65.120003,62.963715,-514.955994,0.009257,0.001637,0.041592,280.076599,14.267782,0.415922,-514.955994,0.041670,0.000000
65.290001,62.956635,-514.911499,0.009244,0.001637,0.041592,280.045105,14.266177,0.415922,-514.911499,0.041670,0.000000
65.460007,62.932808,-514.955994,0.009261,0.001637,0.041592,279.939117,14.260777,0.415922,-514.955994,0.041670,0.000000
65.630005,62.935783,-515.000427,0.009253,0.001637,0.041592,279.952332,14.261453,0.415922,-515.000427,0.041670,0.000000
65.800003,62.945465,-515.000427,0.009257,0.001637,0.041592,279.995422,14.263646,0.415922,-515.000427,0.041670,0.000000
65.970001,62.923866,-514.955994,0.009270,0.001637,0.041592,279.899323,14.258752,0.415922,-514.955994,0.041670,0.000000
66.139999,62.930946,-514.955994,0.009274,0.001637,0.041592,279.930817,14.260357,0.415922,-514.955994,0.041670,0.000000
66.310005,62.903763,-514.955994,0.009248,0.001637,0.041592,279.809906,14.254196,0.415922,-514.955994,0.041670,0.000000
66.480003,62.920891,-515.000427,0.009261,0.001637,0.041592,279.886108,14.258078,0.415922,-515.000427,0.041670,0.000000
66.650002,62.898544,-515.000427,0.009257,0.001637,0.041592,279.786713,14.253015,0.415922,-515.000427,0.041670,0.000000
66.820000,62.904503,-515.000427,0.009270,0.001637,0.041592,279.813202,14.254364,0.415922,-515.000427,0.041670,0.000000
66.990005,62.890724,-515.000427,0.009265,0.001637,0.041592,279.751923,14.251242,0.415922,-515.000427,0.041670,0.000000
67.160004,62.873222,-515.000427,0.009248,0.001637,0.041592,279.674072,14.247275,0.415922,-515.000427,0.041670,0.000000
67.330002,62.871361,-514.955994,0.009270,0.001637,0.041592,279.665771,14.246854,0.415922,-514.955994,0.041670,0.000000
67.500000,62.874718,-515.044922,0.009274,0.001637,0.041592,279.680725,14.247614,0.415922,-515.044922,0.041670,0.000000
67.670006,62.876579,-514.955994,0.009274,0.001637,0.041592,279.688995,14.248036,0.415922,-514.955994,0.041670,0.000000
67.840004,62.889610,-514.955994,0.009261,0.001637,0.041592,279.746948,14.250990,0.415922,-514.955994,0.041670,0.000000
68.010002,62.880676,-515.000427,0.009257,0.001637,0.041592,279.707214,14.248965,0.415922,-515.000427,0.041670,0.000000
68.180000,62.866524,-515.000427,0.009253,0.001637,0.041592,279.644257,14.245758,0.415922,-515.000427,0.041670,0.000000
68.350006,62.869499,-515.089417,0.009248,0.001637,0.041592,279.657501,14.246432,0.415922,-515.089417,0.041670,0.000000
68.520004,62.859818,-515.044922,0.009261,0.001637,0.041592,279.614441,14.244238,0.415922,-515.044922,0.041670,0.000000
68.690002,62.862801,-515.000427,0.009257,0.001637,0.041592,279.627716,14.244914,0.415922,-515.000427,0.041670,0.000000
68.860001,62.832268,-515.044922,0.009274,0.001637,0.041592,279.491882,14.237996,0.415922,-515.044922,0.041670,0.000000
69.030006,62.855728,-515.044922,0.009261,0.001637,0.041592,279.596252,14.243312,0.415922,-515.044922,0.041670,0.000000
69.200005,62.834869,-515.000427,0.009270,0.001637,0.041592,279.503448,14.238585,0.415922,-515.000427,0.041670,0.000000
69.370003,62.843437,-515.133911,0.009270,0.001637,0.041592,279.541565,14.240527,0.415922,-515.133911,0.041670,0.000000
69.500000,62.824448,-515.000427,0.009244,0.001637,0.041592,279.457092,14.236223,0.415922,-515.000427,0.041670,0.000000