File: Data/AG AL compression 300N/AD membrane Unpeeled 300N_1_3_03202024_210431.csv
Time (sec),S:Load (lbs),S:HL1 (DIM),S:LVDT (in),S:Position (in),Ch:Position (mm),Ch:Load (N),Ch:Stress (MPa),Ch:Strain (mm/mm),Ch:HL1 (DIM),Set Point (),Cycles ()
0.010000,-0.010056,-622.155090,0.000000,-0.000000,-0.000000,-0.044729,-0.002279,-0.000000,-622.155090,0.000260,0.000000
0.160000,-0.019363,-622.199524,-0.000009,-0.000000,-0.000000,-0.086133,-0.004388,-0.000000,-622.199524,0.000260,0.000000
0.310000,-0.010056,-622.155090,-0.000004,-0.000000,-0.000000,-0.044729,-0.002279,-0.000000,-622.155090,0.000260,0.000000
0.460000,-0.033142,-622.155090,0.000000,0.000071,0.001804,-0.147423,-0.007510,0.018039,-622.155090,0.002480,0.000000
0.610000,-0.054741,-622.110596,0.000009,0.000159,0.004032,-0.243500,-0.012404,0.040324,-622.110596,0.004978,0.000000
0.760000,-0.013039,-622.155090,0.000095,0.000250,0.006357,-0.057999,-0.002955,0.063567,-622.155090,0.007476,0.000000
0.910000,-0.012291,-622.199524,0.000207,0.000343,0.008724,-0.054673,-0.002785,0.087242,-622.199524,0.009973,0.000000
1.060000,-0.047668,-622.199524,0.000297,0.000450,0.011421,-0.212040,-0.010802,0.114213,-622.199524,0.012471,0.000000
1.210000,-0.051765,-622.199524,0.000401,0.000549,0.013936,-0.230264,-0.011730,0.139364,-622.199524,0.014986,0.000000
1.360000,-0.049896,-622.244019,0.000509,0.000650,0.016521,-0.221950,-0.011307,0.165207,-622.244019,0.017483,0.000000
1.510000,-0.048782,-622.199524,0.000595,0.000742,0.018836,-0.216995,-0.011054,0.188363,-622.199524,0.019981,0.000000
1.660000,-0.037613,-622.199524,0.000698,0.000841,0.021351,-0.167311,-0.008523,0.213510,-622.199524,0.022478,0.000000
1.810000,-0.061813,-622.199524,0.000811,0.000942,0.023927,-0.274960,-0.014007,0.239266,-622.199524,0.024976,0.000000
1.960000,-0.119164,-622.199524,0.000905,0.001040,0.026424,-0.530066,-0.027003,0.264242,-622.199524,0.027474,0.000000
2.110000,-0.066284,-622.199524,0.001013,0.001142,0.029017,-0.294847,-0.015020,0.290173,-622.199524,0.029971,0.000000
2.260000,-0.037239,-622.155090,0.001095,0.001233,0.031315,-0.165648,-0.008438,0.313155,-622.155090,0.032469,0.000000
2.410000,-0.046547,-622.199524,0.001190,0.001334,0.033891,-0.207051,-0.010548,0.338911,-622.199524,0.034966,0.000000
2.560000,-0.042450,-622.199524,0.001302,0.001430,0.036328,-0.188827,-0.009619,0.363282,-622.199524,0.037464,0.000000
2.710000,-0.028671,-622.244019,0.001410,0.001535,0.038999,-0.127536,-0.006497,0.389992,-622.244019,0.039962,0.000000
2.860000,-0.013039,-622.244019,0.001496,0.001621,0.041176,-0.057999,-0.002955,0.411759,-622.244019,0.042459,0.000000
3.010000,-0.045433,-622.199524,0.001595,0.001726,0.043838,-0.202096,-0.010295,0.438382,-622.199524,0.044957,0.000000
3.160000,-0.045807,-622.199524,0.001707,0.001827,0.046414,-0.203759,-0.010380,0.464138,-622.199524,0.047472,0.000000
3.310000,-0.052132,-622.155090,0.001798,0.001927,0.048955,-0.231893,-0.011813,0.489550,-622.155090,0.049970,0.000000
3.460000,-0.031281,-622.199524,0.001901,0.002023,0.051374,-0.139143,-0.007088,0.513743,-622.199524,0.052467,0.000000
3.610000,-0.039101,-622.199524,0.002005,0.002114,0.053690,-0.173928,-0.008860,0.536899,-622.199524,0.054965,0.000000
3.760000,-0.039474,-622.199524,0.002100,0.002222,0.056439,-0.175591,-0.008945,0.564392,-622.199524,0.057462,0.000000
3.910000,-0.078575,-622.155090,0.002216,0.002319,0.058893,-0.349520,-0.017805,0.588933,-622.155090,0.059960,0.000000
4.060000,-0.046547,-622.199524,0.002320,0.002423,0.061556,-0.207051,-0.010548,0.615556,-622.199524,0.062458,0.000000
4.210000,-0.043945,-622.244019,0.002406,0.002515,0.063871,-0.195479,-0.009958,0.638712,-622.244019,0.064955,0.000000
4.360000,-0.058464,-622.199524,0.002501,0.002615,0.066429,-0.260061,-0.013248,0.664294,-622.199524,0.067453,0.000000
4.510000,-0.083786,-622.199524,0.002604,0.002715,0.068962,-0.372699,-0.018986,0.689619,-622.199524,0.069951,0.000000
4.660000,-0.043571,-622.244019,0.002712,0.002811,0.071399,-0.193816,-0.009873,0.713986,-622.244019,0.072448,0.000000
4.810000,-0.029419,-622.244019,0.002798,0.002905,0.073783,-0.130862,-0.006666,0.737835,-622.244019,0.074945,0.000000
4.960000,-0.031281,-622.244019,0.002906,0.003000,0.076194,-0.139143,-0.007088,0.761945,-622.244019,0.077461,0.000000
5.110000,-0.052879,-622.244019,0.003009,0.003109,0.078970,-0.235219,-0.011983,0.789696,-622.244019,0.079958,0.000000
5.260000,-0.048409,-622.288513,0.003100,0.003204,0.081389,-0.215332,-0.010970,0.813892,-622.288513,0.082456,0.000000
5.410000,-0.010429,-622.288513,0.003216,0.003304,0.083930,-0.046392,-0.002363,0.839300,-622.288513,0.084953,0.000000
5.560000,-0.009682,-622.244019,0.003311,0.003394,0.086211,-0.043066,-0.002194,0.862108,-622.244019,0.087451,0.000000
5.710000,-0.045807,-622.244019,0.003397,0.003500,0.088899,-0.203759,-0.010380,0.888992,-622.244019,0.089949,0.000000
5.860000,-0.057350,-622.244019,0.003518,0.003598,0.091397,-0.255106,-0.012996,0.913969,-622.244019,0.092446,0.000000
6.010000,-0.039474,-622.244019,0.003609,0.003697,0.093903,-0.175591,-0.008945,0.939032,-622.244019,0.094944,0.000000
6.160000,-0.045807,-622.244019,0.003699,0.003794,0.096366,-0.203759,-0.010380,0.963661,-622.244019,0.097441,0.000000
6.310000,-0.035004,-622.244019,0.003807,0.003892,0.098846,-0.155704,-0.007932,0.988463,-622.244019,0.099939,0.000000
6.460001,-0.086395,-622.288513,0.003902,0.003991,0.101379,-0.384305,-0.019577,1.013788,-622.288513,0.102437,0.000000
6.610000,-0.100166,-622.244019,0.003997,0.004092,0.103937,-0.445562,-0.022698,1.039370,-622.244019,0.104934,0.000000
6.760000,-0.013039,-622.333008,0.004092,0.004185,0.106304,-0.057999,-0.002955,1.063045,-622.333008,0.107432,0.000000
6.910000,0.001862,-622.244019,0.004191,0.004281,0.108733,0.008281,0.000422,1.087328,-622.244019,0.109947,0.000000
7.060000,-0.030907,-622.288513,0.004299,0.004385,0.111386,-0.137480,-0.007004,1.113864,-622.288513,0.112444,0.000000
7.210001,-0.059578,-622.288513,0.004393,0.004481,0.113824,-0.265016,-0.013501,1.138235,-622.288513,0.114942,0.000000
7.360000,-0.016388,-622.288513,0.004501,0.004582,0.116373,-0.072897,-0.003714,1.163730,-622.288513,0.117440,0.000000
7.510000,-0.011169,-622.288513,0.004579,0.004670,0.118610,-0.049684,-0.002531,1.186103,-622.288513,0.119937,0.000000
7.660000,-0.022346,-622.333008,0.004704,0.004778,0.121368,-0.099402,-0.005064,1.213683,-622.333008,0.122435,0.000000
7.810000,-0.039101,-622.333008,0.004803,0.004879,0.123935,-0.173928,-0.008860,1.239352,-622.333008,0.124933,0.000000
7.960001,-0.026070,-622.288513,0.004889,0.004977,0.126407,-0.115964,-0.005907,1.264068,-622.288513,0.127430,0.000000
8.110001,0.001114,-622.377441,0.004993,0.005074,0.128870,0.004955,0.000252,1.288696,-622.377441,0.129928,0.000000
8.260000,0.124001,-622.288513,0.005092,0.005169,0.131298,0.551582,0.028099,1.312980,-622.288513,0.132426,0.000000
8.410001,0.420410,-622.288513,0.005200,0.005270,0.133865,1.870078,0.095266,1.338649,-622.288513,0.134923,0.000000
8.560000,0.780121,-622.333008,0.005247,-0.000003,-0.000078,3.470151,0.176778,-0.000780,-622.333008,0.000034,0.000000
8.710000,0.757401,-622.377441,0.005234,-0.000003,-0.000087,3.369086,0.171629,-0.000867,-622.377441,0.000034,0.000000
8.860001,0.736923,-622.288513,0.005256,-0.000003,-0.000087,3.277998,0.166989,-0.000867,-622.288513,0.000034,0.000000
9.010000,0.745857,-622.377441,0.005243,-0.000003,-0.000087,3.317739,0.169014,-0.000867,-622.377441,0.000061,0.000000
9.160001,0.733948,-622.288513,0.005234,-0.000003,-0.000087,3.264763,0.166315,-0.000867,-622.288513,0.000312,0.000000
9.310000,0.748466,-622.377441,0.005234,-0.000003,-0.000087,3.329345,0.169605,-0.000867,-622.377441,0.000564,0.000000
9.460000,0.729851,-622.377441,0.005256,-0.000003,-0.000069,3.246538,0.165387,-0.000693,-622.377441,0.000815,0.000000
9.610001,0.821449,-622.377441,0.005234,0.000012,0.000295,3.653989,0.186143,0.002948,-622.377441,0.001067,0.000000
9.760000,0.926834,-622.333008,0.005269,0.000022,0.000564,4.122764,0.210024,0.005636,-622.333008,0.001318,0.000000
9.910001,1.001305,-622.421936,0.005264,0.000029,0.000746,4.454025,0.226899,0.007456,-622.421936,0.001561,0.000000
10.060000,1.041153,-622.377441,0.005273,0.000039,0.000980,4.631279,0.235929,0.009799,-622.377441,0.001813,0.000000
10.210000,1.178932,-622.421936,0.005295,0.000052,0.001310,5.244152,0.267150,0.013096,-622.421936,0.002064,0.000000
10.360001,1.264946,-622.333008,0.005307,0.000059,0.001509,5.626761,0.286641,0.015090,-622.333008,0.002316,0.000000
10.510000,1.361389,-622.333008,0.005303,0.000067,0.001691,6.055761,0.308495,0.016911,-622.333008,0.002567,0.000000
10.660001,1.522629,-622.377441,0.005312,0.000079,0.002003,6.772991,0.345033,0.020033,-622.377441,0.002818,0.000000
10.810000,1.668602,-622.377441,0.005316,0.000087,0.002220,7.422312,0.378111,0.022198,-622.377441,0.003061,0.000000
10.960001,1.808235,-622.377441,0.005333,0.000098,0.002489,8.043431,0.409752,0.024889,-622.377441,0.003313,0.000000
11.110001,1.940804,-622.421936,0.005338,0.000105,0.002671,8.633125,0.439792,0.026710,-622.421936,0.003564,0.000000
11.260000,2.017143,-622.333008,0.005329,0.000114,0.002905,8.972701,0.457091,0.029053,-622.333008,0.003816,0.000000
11.410001,2.264023,-622.377441,0.005342,0.000129,0.003278,10.070876,0.513035,0.032781,-622.377441,0.004067,0.000000
11.560000,2.496758,-622.377441,0.005364,0.000142,0.003616,11.106133,0.565773,0.036161,-622.377441,0.004319,0.000000
11.710001,2.634163,-622.377441,0.005372,0.000152,0.003850,11.717341,0.596910,0.038504,-622.377441,0.004562,0.000000
11.860001,2.778267,-622.377441,0.005381,0.000159,0.004041,12.358349,0.629564,0.040411,-622.377441,0.004813,0.000000
12.010000,2.887375,-622.333008,0.005389,0.000168,0.004258,12.843685,0.654289,0.042580,-622.333008,0.005065,0.000000
12.160001,3.132393,-622.421936,0.005398,0.000178,0.004527,13.933579,0.709810,0.045267,-622.421936,0.005316,0.000000
12.310000,3.306290,-622.421936,0.005407,0.000188,0.004770,14.707111,0.749216,0.047697,-622.421936,0.005568,0.000000
12.460001,3.482796,-622.421936,0.005407,0.000195,0.004960,15.492249,0.789213,0.049605,-622.421936,0.005810,0.000000
12.610001,3.708458,-622.421936,0.005415,0.000204,0.005177,16.496044,0.840349,0.051774,-622.421936,0.006062,0.000000
12.760000,3.943420,-622.421936,0.005424,0.000213,0.005403,17.541210,0.893592,0.054026,-622.421936,0.006313,0.000000
12.910001,4.083435,-622.466431,0.005428,0.000219,0.005550,18.164026,0.925320,0.055502,-622.466431,0.006565,0.000000
13.060000,4.072639,-622.377441,0.005437,0.000221,0.005602,18.116005,0.922873,0.056020,-622.377441,0.006816,0.000000
13.210001,4.614807,-622.421936,0.005445,0.000239,0.006079,20.527687,1.045730,0.060793,-622.421936,0.007068,0.000000
13.360001,4.876213,-622.421936,0.005454,0.000251,0.006365,21.690479,1.104966,0.063654,-622.421936,0.007311,0.000000
13.510000,5.067612,-622.421936,0.005458,0.000258,0.006547,22.541862,1.148337,0.065475,-622.421936,0.007562,0.000000
13.660001,5.562500,-622.421936,0.005467,0.000276,0.007007,24.743237,1.260481,0.070070,-622.421936,0.007814,0.000000
13.810000,5.762833,-622.466431,0.005493,0.000284,0.007215,25.634359,1.305877,0.072151,-622.466431,0.008065,0.000000
13.960001,5.870453,-622.421936,0.005484,0.000290,0.007354,26.113079,1.330264,0.073541,-622.421936,0.008317,0.000000
14.110001,6.276711,-622.421936,0.005506,0.000304,0.007709,27.920202,1.422323,0.077095,-622.421936,0.008568,0.000000
14.260000,6.545937,-622.421936,0.005497,0.000312,0.007935,29.117781,1.483330,0.079350,-622.421936,0.008811,0.000000
14.410001,6.712387,-622.555420,0.005493,0.000318,0.008083,29.858189,1.521049,0.080826,-622.555420,0.009063,0.000000
14.560000,7.145828,-622.421936,0.005514,0.000331,0.008412,31.786232,1.619268,0.084119,-622.421936,0.009314,0.000000
14.710001,7.456009,-622.421936,0.005510,0.000340,0.008646,33.165985,1.689556,0.086462,-622.421936,0.009566,0.000000
14.860001,7.772903,-622.421936,0.005523,0.000349,0.008872,34.575600,1.761365,0.088718,-622.421936,0.009817,0.000000
15.010001,7.992599,-622.466431,0.005532,0.000356,0.009054,35.552856,1.811149,0.090538,-622.466431,0.010069,0.000000
15.160001,8.251396,-622.466431,0.005536,0.000366,0.009288,36.704044,1.869793,0.092878,-622.466431,0.010311,0.000000
15.310000,8.715752,-622.510925,0.005540,0.000378,0.009600,38.769600,1.975018,0.096000,-622.510925,0.010563,0.000000
15.460001,9.463097,-622.466431,0.005566,0.000395,0.010034,42.093956,2.144368,0.100338,-622.466431,0.010814,0.000000
15.610001,9.648911,-622.510925,0.005579,0.000402,0.010216,42.920498,2.186475,0.102158,-622.510925,0.011066,0.000000
15.760001,10.068207,-622.466431,0.005579,0.000412,0.010459,44.785622,2.281488,0.104588,-622.466431,0.011317,0.000000
15.910001,10.401108,-622.466431,0.005596,0.000422,0.010710,46.266438,2.356925,0.107101,-622.466431,0.011569,0.000000
16.060001,10.823746,-622.510925,0.005592,0.000433,0.011005,48.146427,2.452696,0.110050,-622.510925,0.011812,0.000000
16.210001,11.109360,-622.510925,0.005588,0.000440,0.011170,49.416901,2.517417,0.111700,-622.510925,0.012063,0.000000
16.360001,11.551361,-622.466431,0.005605,0.000452,0.011473,51.383018,2.617576,0.114732,-622.466431,0.012315,0.000000
16.510000,12.067101,-622.421936,0.005596,0.000462,0.011725,53.677143,2.734444,0.117248,-622.421936,0.012566,0.000000
16.660000,12.261108,-622.555420,0.005609,0.000468,0.011898,54.540134,2.778407,0.118982,-622.555420,0.012818,0.000000
16.810001,12.569061,-622.510925,0.005609,0.000476,0.012080,55.909977,2.848190,0.120802,-622.510925,0.013069,0.000000
16.960001,13.068039,-622.510925,0.005622,0.000485,0.012323,58.129539,2.961260,0.123232,-622.510925,0.013312,0.000000
17.110001,13.327209,-622.510925,0.005631,0.000491,0.012479,59.282387,3.019989,0.124792,-622.510925,0.013563,0.000000
17.260000,14.125206,-622.555420,0.005639,0.000508,0.012896,62.832054,3.200817,0.128955,-622.555420,0.013815,0.000000
17.410002,14.733658,-622.466431,0.005652,0.000522,0.013251,65.538582,3.338695,0.132513,-622.466431,0.014066,0.000000
17.560001,15.125023,-622.510925,0.005657,0.000531,0.013494,67.279465,3.427379,0.134939,-622.510925,0.014318,0.000000
17.710001,15.486221,-622.510925,0.005665,0.000540,0.013719,68.886154,3.509228,0.137195,-622.510925,0.014569,0.000000
17.860001,15.751724,-622.555420,0.005674,0.000547,0.013902,70.067169,3.569392,0.139015,-622.555420,0.014812,0.000000
18.010000,16.077179,-622.599854,0.005691,0.000556,0.014118,71.514862,3.643141,0.141184,-622.599854,0.015064,0.000000
18.160002,16.847244,-622.510925,0.005683,0.000571,0.014500,74.940285,3.817640,0.144999,-622.510925,0.015315,0.000000
18.310001,17.275475,-622.555420,0.005687,0.000581,0.014769,76.845146,3.914678,0.147687,-622.555420,0.015567,0.000000
18.460001,17.700722,-622.599854,0.005704,0.000589,0.014959,78.736740,4.011041,0.149594,-622.599854,0.015818,0.000000
18.610001,18.076820,-622.555420,0.005704,0.000599,0.015220,80.409714,4.096266,0.152198,-622.555420,0.016061,0.000000
18.760000,18.411583,-622.555420,0.005708,0.000605,0.015358,81.898811,4.172124,0.153583,-622.555420,0.016313,0.000000
18.910002,18.560158,-622.555420,0.005704,0.000611,0.015523,82.559708,4.205792,0.155234,-622.555420,0.016564,0.000000
19.060001,19.360390,-622.555420,0.005721,0.000626,0.015905,86.119316,4.387127,0.159049,-622.555420,0.016816,0.000000
19.210001,20.240303,-622.555420,0.005743,0.000641,0.016286,90.033363,4.586518,0.162864,-622.555420,0.017067,0.000000
19.360001,20.621239,-622.555420,0.005730,0.000650,0.016512,91.727852,4.672840,0.165120,-622.555420,0.017319,0.000000
19.510000,20.958611,-622.555420,0.005739,0.000659,0.016738,93.228554,4.749289,0.167376,-622.555420,0.017561,0.000000
19.660002,21.338432,-622.555420,0.005756,0.000668,0.016963,94.918091,4.835358,0.169628,-622.555420,0.017813,0.000000
19.810001,21.848953,-622.555420,0.005760,0.000677,0.017206,97.188995,4.951044,0.172058,-622.555420,0.018064,0.000000
19.960001,22.483849,-622.599854,0.005743,0.000689,0.017509,100.013153,5.094913,0.175093,-622.599854,0.018316,0.000000
20.110001,22.813400,-622.599854,0.005764,0.000696,0.017683,101.479073,5.169590,0.176827,-622.599854,0.018567,0.000000
20.260000,23.341797,-622.599854,0.005773,0.000706,0.017934,103.829498,5.289327,0.179340,-622.599854,0.018819,0.000000
20.410002,23.758850,-622.510925,0.005795,0.000715,0.018151,105.684647,5.383832,0.181508,-622.510925,0.019061,0.000000
20.560001,24.504341,-622.599854,0.005782,0.000729,0.018524,109.000755,5.552763,0.185240,-622.599854,0.019313,0.000000
20.710001,24.622009,-622.599854,0.005799,0.000732,0.018602,109.524170,5.579427,0.186020,-622.599854,0.019565,0.000000
20.860001,25.055824,-622.644348,0.005803,0.000742,0.018845,111.453873,5.677731,0.188446,-622.644348,0.019816,0.000000
21.010000,25.238289,-622.555420,0.005808,0.000747,0.018966,112.265518,5.719078,0.189661,-622.555420,0.020068,0.000000
21.160002,26.481262,-622.555420,0.005816,0.000769,0.019538,117.794540,6.000740,0.195384,-622.555420,0.020319,0.000000
21.310001,26.825340,-622.644348,0.005812,0.000774,0.019651,119.325073,6.078709,0.196512,-622.644348,0.020562,0.000000
21.460001,27.297882,-622.644348,0.005829,0.000784,0.019920,121.427048,6.185788,0.199203,-622.644348,0.020814,0.000000
21.610001,27.701530,-622.599854,0.005833,0.000793,0.020154,123.222565,6.277256,0.201542,-622.599854,0.021065,0.000000
21.760000,28.172951,-622.599854,0.005829,0.000805,0.020440,125.319542,6.384082,0.204403,-622.599854,0.021316,0.000000
21.910002,28.841362,-622.599854,0.005842,0.000816,0.020735,128.292786,6.535546,0.207352,-622.599854,0.021568,0.000000
22.060001,29.349648,-622.599854,0.005851,0.000826,0.020987,130.553757,6.650725,0.209869,-622.599854,0.021819,0.000000
22.210001,29.866875,-622.644348,0.005846,0.000836,0.021238,132.854492,6.767931,0.212382,-622.644348,0.022062,0.000000
22.360001,30.395645,-622.644348,0.005864,0.000847,0.021516,135.206589,6.887752,0.215156,-622.644348,0.022313,0.000000
22.510000,30.774719,-622.599854,0.005864,0.000854,0.021698,136.892792,6.973651,0.216980,-622.599854,0.022565,0.000000
22.660002,30.966866,-622.644348,0.005885,0.000860,0.021845,137.747498,7.017192,0.218453,-622.644348,0.022816,0.000000
22.810001,31.327690,-622.599854,0.005877,0.000868,0.022045,139.352524,7.098956,0.220447,-622.599854,0.023068,0.000000
22.960001,31.682564,-622.644348,0.005872,0.000874,0.022201,140.931076,7.179371,0.222011,-622.644348,0.023319,0.000000
23.110001,32.985497,-622.733337,0.005877,0.000895,0.022739,146.726822,7.474620,0.227385,-622.733337,0.023562,0.000000
23.260000,33.550385,-622.644348,0.005894,0.000906,0.023007,149.239563,7.602626,0.230072,-622.644348,0.023814,0.000000
23.410002,33.900414,-622.644348,0.005898,0.000913,0.023181,150.796570,7.681943,0.231810,-622.644348,0.024065,0.000000
23.560001,34.326035,-622.644348,0.005898,0.000922,0.023415,152.689835,7.778391,0.234149,-622.644348,0.024317,0.000000
23.710001,34.711067,-622.599854,0.005911,0.000932,0.023667,154.402542,7.865640,0.236666,-622.599854,0.024569,0.000000
23.860001,35.445763,-622.733337,0.005920,0.000945,0.024005,157.670624,8.032125,0.240046,-622.733337,0.024820,0.000000
24.010000,35.881805,-622.733337,0.005933,0.000954,0.024221,159.610245,8.130934,0.242214,-622.733337,0.025063,0.000000
24.160002,36.458611,-622.644348,0.005928,0.000964,0.024473,162.175995,8.261640,0.244731,-622.644348,0.025314,0.000000
24.310001,36.759117,-622.644348,0.005933,0.000971,0.024673,163.512726,8.329735,0.246726,-622.644348,0.025566,0.000000
24.460001,37.197403,-622.644348,0.005950,0.000980,0.024881,165.462311,8.429051,0.248808,-622.644348,0.025817,0.000000
24.610001,37.487106,-622.733337,0.005954,0.000986,0.025054,166.750977,8.494699,0.250541,-622.733337,0.026069,0.000000
24.760000,37.735107,-622.644348,0.005946,0.000993,0.025210,167.854141,8.550898,0.252100,-622.644348,0.026320,0.000000
24.910002,38.701042,-622.688843,0.005976,0.001010,0.025644,172.150833,8.769782,0.256438,-622.688843,0.026563,0.000000
25.060001,39.816666,-622.688843,0.005967,0.001025,0.026034,177.113373,9.022586,0.260340,-622.688843,0.026814,0.000000
25.210001,40.401291,-622.733337,0.005959,0.001034,0.026260,179.713913,9.155064,0.262596,-622.733337,0.027066,0.000000
25.360001,40.538322,-622.733337,0.005980,0.001039,0.026381,180.323471,9.186115,0.263811,-622.733337,0.027317,0.000000
25.510002,41.022408,-622.777771,0.005984,0.001050,0.026659,182.476776,9.295811,0.266585,-622.777771,0.027569,0.000000
25.660002,41.535538,-622.644348,0.005993,0.001062,0.026979,184.759293,9.412087,0.269795,-622.644348,0.027812,0.000000
25.810001,42.042709,-622.733337,0.005976,0.001069,0.027162,187.015305,9.527014,0.271615,-622.733337,0.028063,0.000000
25.960001,42.554726,-622.733337,0.006002,0.001079,0.027413,189.292877,9.643039,0.274129,-622.733337,0.028315,0.000000
26.110001,43.208237,-622.644348,0.006015,0.001091,0.027708,192.199829,9.791126,0.277077,-622.644348,0.028566,0.000000
26.260002,43.764191,-622.733337,0.006010,0.001100,0.027951,194.672836,9.917107,0.279507,-622.733337,0.028818,0.000000
26.410002,44.236359,-622.688843,0.006019,0.001109,0.028176,196.773148,10.024102,0.281763,-622.688843,0.029070,0.000000
26.560001,44.510422,-622.733337,0.006023,0.001116,0.028350,197.992249,10.086206,0.283496,-622.733337,0.029312,0.000000
26.710001,44.661232,-622.688843,0.006028,0.001121,0.028471,198.663086,10.120380,0.284711,-622.688843,0.029564,0.000000
26.860001,45.192986,-622.733337,0.006028,0.001135,0.028827,201.028442,10.240877,0.288265,-622.733337,0.029815,0.000000
27.010002,46.584167,-622.688843,0.006028,0.001150,0.029217,207.216721,10.556123,0.292167,-622.688843,0.030067,0.000000
27.160002,47.064156,-622.733337,0.006040,0.001161,0.029494,209.351822,10.664890,0.294942,-622.733337,0.030318,0.000000
27.310001,47.454773,-622.733337,0.006053,0.001167,0.029633,211.089371,10.753405,0.296331,-622.733337,0.030569,0.000000
27.460001,47.898643,-622.777771,0.006053,0.001177,0.029893,213.063812,10.853988,0.298931,-622.777771,0.030812,0.000000
27.610001,48.338783,-622.733337,0.006049,0.001185,0.030093,215.021652,10.953725,0.300926,-622.733337,0.031064,0.000000
27.760002,49.166199,-622.777771,0.006066,0.001197,0.030405,218.702179,11.141220,0.304048,-622.777771,0.031315,0.000000
27.910002,49.549736,-622.733337,0.006053,0.001205,0.030613,220.408234,11.228130,0.306130,-622.733337,0.031567,0.000000
28.060001,50.130638,-622.777771,0.006071,0.001217,0.030908,222.992218,11.359765,0.309078,-622.777771,0.031818,0.000000
28.210001,50.911507,-622.733337,0.006088,0.001228,0.031203,226.465698,11.536713,0.312027,-622.733337,0.032070,0.000000
28.360001,51.457031,-622.777771,0.006088,0.001238,0.031454,228.892303,11.660330,0.314544,-622.777771,0.032313,0.000000
28.510002,51.771317,-622.733337,0.006101,0.001244,0.031593,230.290314,11.731547,0.315929,-622.733337,0.032564,0.000000
28.660002,52.066605,-622.777771,0.006101,0.001252,0.031801,231.603821,11.798461,0.318011,-622.777771,0.032816,0.000000
28.810001,52.896996,-622.822266,0.006101,0.001267,0.032174,235.297592,11.986630,0.321739,-622.822266,0.033067,0.000000
28.960001,54.056564,-622.688843,0.006118,0.001280,0.032521,240.455612,12.249393,0.325210,-622.688843,0.033319,0.000000
29.110001,54.682518,-622.688843,0.006131,0.001291,0.032798,243.239990,12.391236,0.327984,-622.688843,0.033570,0.000000
29.260002,54.977440,-622.733337,0.006131,0.001298,0.032972,244.551865,12.458066,0.329717,-622.733337,0.033813,0.000000
29.410002,55.312202,-622.777771,0.006131,0.001305,0.033145,246.040970,12.533924,0.331455,-622.777771,0.034064,0.000000
29.560001,55.776924,-622.777771,0.006127,0.001314,0.033379,248.108154,12.639232,0.333794,-622.777771,0.034316,0.000000
29.710001,56.506401,-622.866760,0.006148,0.001326,0.033674,251.353027,12.804533,0.336742,-622.866760,0.034567,0.000000
29.860001,56.792755,-622.822266,0.006140,0.001331,0.033796,252.626785,12.869422,0.337957,-622.822266,0.034819,0.000000
30.010002,57.317429,-622.822266,0.006135,0.001340,0.034039,254.960663,12.988315,0.340387,-622.822266,0.035070,0.000000
30.160002,58.410339,-622.822266,0.006144,0.001354,0.034403,259.822174,13.235972,0.344028,-622.822266,0.035313,0.000000
30.310001,58.963318,-622.866760,0.006165,0.001364,0.034645,262.281952,13.361279,0.346454,-622.866760,0.035565,0.000000
30.460001,59.271637,-622.777771,0.006148,0.001369,0.034776,263.653412,13.431145,0.347756,-622.777771,0.035816,0.000000
30.610001,59.698006,-622.822266,0.006165,0.001380,0.035062,265.549988,13.527761,0.350618,-622.822266,0.036068,0.000000
30.760002,60.722031,-622.822266,0.006170,0.001392,0.035357,270.105072,13.759809,0.353566,-622.822266,0.036319,0.000000
30.910002,61.692802,-622.822266,0.006178,0.001408,0.035764,274.423279,13.979789,0.357642,-622.822266,0.036571,0.000000
31.060001,62.682571,-622.777771,0.006196,0.001420,0.036068,278.825989,14.204073,0.360678,-622.777771,0.036814,0.000000
31.210001,63.156609,-622.777771,0.006178,0.001428,0.036259,280.934631,14.311492,0.362585,-622.777771,0.037065,0.000000
31.360001,63.258263,-622.822266,0.006187,0.001431,0.036354,281.386810,14.334527,0.363539,-622.822266,0.037317,0.000000
31.510002,63.880867,-622.866760,0.006187,0.001446,0.036718,284.156281,14.475612,0.367184,-622.866760,0.037568,0.000000
31.660002,64.569756,-622.822266,0.006200,0.001452,0.036892,287.220612,14.631716,0.368917,-622.822266,0.037820,0.000000
31.810001,64.938774,-622.822266,0.006217,0.001462,0.037126,288.862091,14.715337,0.371260,-622.822266,0.038062,0.000000
31.960001,65.626915,-622.866760,0.006217,0.001472,0.037377,291.923096,14.871271,0.373774,-622.866760,0.038314,0.000000
32.110001,66.503120,-622.822266,0.006217,0.001482,0.037637,295.820648,15.069822,0.376374,-622.822266,0.038565,0.000000
32.260002,67.204292,-622.822266,0.006226,0.001494,0.037941,298.939636,15.228710,0.379409,-622.822266,0.038817,0.000000
32.410000,67.193489,-622.822266,0.006239,0.001487,0.037768,298.891571,15.226263,0.377676,-622.822266,0.038002,0.000000
32.560001,66.882561,-622.822266,0.006230,0.001487,0.037768,297.508484,15.155805,0.377676,-622.822266,0.038002,0.000000
32.710003,66.730629,-622.866760,0.006239,0.001487,0.037759,296.832672,15.121377,0.377589,-622.866760,0.037768,0.000000
32.860001,66.501625,-622.822266,0.006239,0.001486,0.037733,295.813995,15.069484,0.377328,-622.822266,0.037768,0.000000
33.010002,66.301292,-622.866760,0.006239,0.001485,0.037716,294.922882,15.024087,0.377157,-622.866760,0.037768,0.000000
33.160000,66.117714,-622.866760,0.006252,0.001485,0.037716,294.106293,14.982488,0.377157,-622.866760,0.037768,0.000000
33.310001,65.962807,-622.866760,0.006234,0.001485,0.037707,293.417206,14.947386,0.377070,-622.866760,0.037768,0.000000
33.460003,65.819069,-622.911255,0.006256,0.001485,0.037707,292.777832,14.914814,0.377070,-622.911255,0.037768,0.000000
33.610001,65.683525,-622.955750,0.006247,0.001484,0.037698,292.174927,14.884100,0.376983,-622.955750,0.037768,0.000000
33.760002,65.577766,-622.911255,0.006234,0.001484,0.037698,291.704468,14.860134,0.376983,-622.911255,0.037768,0.000000
33.910000,65.463829,-622.955750,0.006247,0.001484,0.037698,291.197662,14.834315,0.376983,-622.955750,0.037768,0.000000
34.060001,65.367744,-622.866760,0.006247,0.001484,0.037698,290.770264,14.812542,0.376983,-622.866760,0.037768,0.000000
34.210003,65.262733,-622.911255,0.006230,0.001484,0.037698,290.303131,14.788747,0.376983,-622.911255,0.037768,0.000000
34.360001,65.170769,-622.866760,0.006239,0.001484,0.037690,289.894043,14.767907,0.376896,-622.866760,0.037768,0.000000
34.510002,65.091820,-622.911255,0.006230,0.001484,0.037690,289.542877,14.750017,0.376896,-622.911255,0.037768,0.000000
34.660000,65.013618,-622.866760,0.006247,0.001484,0.037690,289.195007,14.732296,0.376896,-622.866760,0.037768,0.000000
34.810001,64.940269,-622.911255,0.006256,0.001484,0.037690,288.868744,14.715675,0.376896,-622.911255,0.037768,0.000000
34.960003,64.871010,-622.866760,0.006239,0.001484,0.037690,288.560669,14.699981,0.376896,-622.866760,0.037768,0.000000
35.110001,64.800255,-622.955750,0.006247,0.001484,0.037690,288.245941,14.683948,0.376896,-622.955750,0.037768,0.000000
35.260002,64.732109,-622.911255,0.006243,0.001484,0.037690,287.942810,14.668506,0.376896,-622.911255,0.037768,0.000000
35.410000,64.667320,-622.911255,0.006234,0.001484,0.037690,287.654602,14.653824,0.376896,-622.911255,0.037768,0.000000
35.560001,64.620033,-622.911255,0.006256,0.001484,0.037690,287.444275,14.643108,0.376896,-622.911255,0.037768,0.000000
35.710003,64.552620,-622.911255,0.006256,0.001484,0.037690,287.144409,14.627832,0.376896,-622.911255,0.037768,0.000000
35.860001,64.501610,-622.911255,0.006256,0.001484,0.037690,286.917480,14.616274,0.376896,-622.911255,0.037768,0.000000
36.010002,64.461021,-622.955750,0.006247,0.001484,0.037690,286.736938,14.607076,0.376896,-622.955750,0.037768,0.000000
36.160000,64.402184,-622.955750,0.006256,0.001484,0.037690,286.475220,14.593743,0.376896,-622.955750,0.037768,0.000000
36.310001,64.359367,-622.911255,0.006252,0.001484,0.037690,286.284760,14.584042,0.376896,-622.911255,0.037768,0.000000
36.460003,64.319527,-623.000183,0.006247,0.001484,0.037690,286.107544,14.575013,0.376896,-623.000183,0.037768,0.000000
36.610001,64.275948,-622.911255,0.006247,0.001484,0.037690,285.913696,14.565138,0.376896,-622.911255,0.037768,0.000000
36.760002,64.226051,-622.911255,0.006243,0.001484,0.037690,285.691742,14.553831,0.376896,-622.911255,0.037768,0.000000
36.910000,64.182854,-623.044678,0.006252,0.001484,0.037690,285.499603,14.544043,0.376896,-623.044678,0.037768,0.000000
37.060001,64.148979,-622.955750,0.006256,0.001484,0.037690,285.348907,14.536366,0.376896,-622.955750,0.037768,0.000000
37.210003,64.100945,-622.955750,0.006247,0.001484,0.037690,285.135254,14.525481,0.376896,-622.955750,0.037768,0.000000
37.360001,64.073753,-623.000183,0.006243,0.001484,0.037690,285.014282,14.519320,0.376896,-623.000183,0.037768,0.000000
37.510002,64.037270,-622.955750,0.006234,0.001484,0.037690,284.851990,14.511052,0.376896,-622.955750,0.037768,0.000000
37.660004,63.992958,-623.000183,0.006265,0.001484,0.037690,284.654907,14.501012,0.376896,-623.000183,0.037768,0.000000
37.810001,63.967628,-622.955750,0.006243,0.001484,0.037690,284.542236,14.495272,0.376896,-622.955750,0.037768,0.000000
37.960003,63.931877,-623.000183,0.006260,0.001484,0.037690,284.383179,14.487170,0.376896,-623.000183,0.037768,0.000000
38.110001,63.899117,-623.000183,0.006260,0.001484,0.037690,284.237457,14.479747,0.376896,-623.000183,0.037768,0.000000
38.260002,63.871178,-623.044678,0.006260,0.001484,0.037681,284.113190,14.473415,0.376809,-623.044678,0.037768,0.000000
38.410004,63.842140,-622.955750,0.006243,0.001484,0.037681,283.984009,14.466836,0.376809,-622.955750,0.037768,0.000000
38.560001,63.807137,-622.955750,0.006260,0.001484,0.037681,283.828308,14.458903,0.376809,-622.955750,0.037768,0.000000
38.710003,63.776604,-622.955750,0.006265,0.001484,0.037681,283.692505,14.451984,0.376809,-622.955750,0.037768,0.000000
38.860001,63.746819,-623.044678,0.006260,0.001484,0.037681,283.559998,14.445236,0.376809,-623.044678,0.037768,0.000000
39.010002,63.720375,-623.000183,0.006256,0.001484,0.037681,283.442383,14.439243,0.376809,-623.000183,0.037768,0.000000
39.160004,63.682396,-623.000183,0.006269,0.001484,0.037681,283.273437,14.430636,0.376809,-623.000183,0.037768,0.000000
39.310001,63.670097,-623.000183,0.006243,0.001484,0.037681,283.218750,14.427850,0.376809,-623.000183,0.037768,0.000000
39.460003,63.632500,-623.044678,0.006252,0.001484,0.037681,283.051483,14.419331,0.376809,-623.044678,0.037768,0.000000
39.610001,63.614616,-623.044678,0.006243,0.001484,0.037681,282.971954,14.415278,0.376809,-623.044678,0.037768,0.000000
39.760002,63.587440,-623.044678,0.006252,0.001484,0.037681,282.851074,14.409120,0.376809,-623.044678,0.037768,0.000000
39.910004,63.568077,-623.133667,0.006265,0.001484,0.037681,282.764923,14.404733,0.376809,-623.133667,0.037768,0.000000
40.060001,63.542381,-623.044678,0.006265,0.001484,0.037681,282.650635,14.398910,0.376809,-623.044678,0.037768,0.000000
40.210003,63.525246,-623.044678,0.006247,0.001484,0.037681,282.574402,14.395026,0.376809,-623.044678,0.037768,0.000000
40.360001,63.501411,-623.089172,0.006247,0.001484,0.037681,282.468384,14.389626,0.376809,-623.089172,0.037768,0.000000
40.510002,63.480186,-623.000183,0.006256,0.001484,0.037681,282.373962,14.384815,0.376809,-623.000183,0.037768,0.000000
40.660004,63.450783,-623.044678,0.006269,0.001484,0.037681,282.243164,14.378153,0.376809,-623.044678,0.037768,0.000000
40.810001,63.432533,-623.044678,0.006256,0.001484,0.037681,282.161987,14.374018,0.376809,-623.044678,0.037768,0.000000
40.960003,63.413170,-623.089172,0.006252,0.001484,0.037681,282.075867,14.369630,0.376809,-623.089172,0.037768,0.000000
41.110001,63.381889,-623.044678,0.006256,0.001484,0.037681,281.936737,14.362541,0.376809,-623.044678,0.037768,0.000000
41.260002,63.371468,-623.089172,0.006265,0.001484,0.037681,281.890381,14.360180,0.376809,-623.089172,0.037768,0.000000
41.410004,63.353218,-623.089172,0.006260,0.001484,0.037681,281.809174,14.356044,0.376809,-623.089172,0.037768,0.000000
41.560001,63.335335,-623.089172,0.006265,0.001484,0.037681,281.729645,14.351992,0.376809,-623.089172,0.037768,0.000000
41.710003,63.308159,-623.089172,0.006269,0.001484,0.037681,281.608765,14.345834,0.376809,-623.089172,0.037768,0.000000
41.860001,63.287300,-623.133667,0.006265,0.001484,0.037681,281.515961,14.341107,0.376809,-623.133667,0.037768,0.000000
42.010002,63.268318,-623.089172,0.006269,0.001484,0.037681,281.431549,14.336806,0.376809,-623.089172,0.037768,0.000000
42.160004,63.249702,-623.133667,0.006256,0.001484,0.037681,281.348724,14.332587,0.376809,-623.133667,0.037768,0.000000
42.310001,63.234795,-623.089172,0.006265,0.001484,0.037681,281.282410,14.329209,0.376809,-623.089172,0.037768,0.000000
42.460003,63.224739,-623.089172,0.006269,0.001484,0.037681,281.237671,14.326931,0.376809,-623.089172,0.037768,0.000000
42.610001,63.199425,-623.133667,0.006260,0.001484,0.037681,281.125092,14.321194,0.376809,-623.133667,0.037768,0.000000
42.760002,63.189003,-623.089172,0.006252,0.001484,0.037681,281.078735,14.318832,0.376809,-623.089172,0.037768,0.000000
42.910004,63.167397,-623.133667,0.006265,0.001484,0.037681,280.982605,14.313936,0.376809,-623.133667,0.037768,0.000000
43.060001,63.150276,-623.089172,0.006269,0.001484,0.037681,280.906464,14.310058,0.376809,-623.089172,0.037768,0.000000
43.210003,63.156609,-623.089172,0.006260,0.001484,0.037681,280.934631,14.311492,0.376809,-623.089172,0.037768,0.000000
43.360001,63.111916,-623.133667,0.006269,0.001484,0.037681,280.735809,14.301365,0.376809,-623.133667,0.037768,0.000000
43.510002,63.108559,-623.089172,0.006260,0.001484,0.037681,280.720886,14.300604,0.376809,-623.089172,0.037768,0.000000
43.660004,63.089195,-623.133667,0.006273,0.001484,0.037681,280.634766,14.296216,0.376809,-623.133667,0.037768,0.000000
43.810001,63.069466,-623.089172,0.006260,0.001484,0.037681,280.546997,14.291745,0.376809,-623.089172,0.037768,0.000000
43.960003,63.064629,-623.133667,0.006260,0.001484,0.037681,280.525482,14.290649,0.376809,-623.133667,0.037768,0.000000
44.110001,63.044151,-623.089172,0.006265,0.001484,0.037681,280.434387,14.286009,0.376809,-623.089172,0.037768,0.000000
44.260002,63.035576,-623.178101,0.006265,0.001484,0.037681,280.396240,14.284066,0.376809,-623.178101,0.037768,0.000000
44.410004,63.014359,-623.133667,0.006260,0.001484,0.037681,280.301880,14.279258,0.376809,-623.133667,0.037768,0.000000
44.560001,63.007652,-623.133667,0.006265,0.001484,0.037681,280.272034,14.277739,0.376809,-623.133667,0.037768,0.000000
44.710003,62.993500,-623.178101,0.006273,0.001484,0.037681,280.209076,14.274531,0.376809,-623.178101,0.037768,0.000000
44.860001,62.970413,-623.133667,0.006256,0.001484,0.037681,280.106384,14.269300,0.376809,-623.133667,0.037768,0.000000
45.010002,62.949936,-623.222595,0.006260,0.001484,0.037681,280.015289,14.264659,0.376809,-623.222595,0.037768,0.000000
45.160004,62.939507,-623.133667,0.006256,0.001484,0.037681,279.968903,14.262296,0.376809,-623.133667,0.037768,0.000000
45.310001,62.933182,-623.178101,0.006278,0.001484,0.037681,279.940765,14.260863,0.376809,-623.178101,0.037768,0.000000
45.460003,62.907112,-623.178101,0.006273,0.001484,0.037681,279.824799,14.254955,0.376809,-623.178101,0.037768,0.000000
45.610001,62.922379,-623.178101,0.006265,0.001484,0.037681,279.892731,14.258415,0.376809,-623.178101,0.037768,0.000000
45.760002,62.882538,-623.133667,0.006265,0.001484,0.037681,279.715485,14.249387,0.376809,-623.133667,0.037768,0.000000
45.910004,62.899292,-623.178101,0.006269,0.001484,0.037681,279.790039,14.253183,0.376809,-623.178101,0.037768,0.000000
46.060001,62.881416,-623.178101,0.006273,0.001484,0.037681,279.710510,14.249132,0.376809,-623.178101,0.037768,0.000000
46.210003,62.862427,-623.178101,0.006273,0.001484,0.037681,279.626038,14.244830,0.376809,-623.178101,0.037768,0.000000
46.360001,62.844185,-623.178101,0.006269,0.001484,0.037681,279.544891,14.240696,0.376809,-623.178101,0.037768,0.000000
46.510002,62.830772,-623.133667,0.006269,0.001484,0.037681,279.485229,14.237657,0.376809,-623.133667,0.037768,0.000000
46.660004,62.819603,-623.178101,0.006256,0.001484,0.037681,279.435547,14.235126,0.376809,-623.178101,0.037768,0.000000
46.810001,62.802101,-623.222595,0.006269,0.001484,0.037681,279.357697,14.231160,0.376809,-623.222595,0.037768,0.000000
46.960003,62.805458,-623.222595,0.006260,0.001484,0.037681,279.372620,14.231920,0.376809,-623.222595,0.037768,0.000000
47.110001,62.780136,-623.222595,0.006265,0.001484,0.037681,279.259979,14.226182,0.376809,-623.222595,0.037768,0.000000
47.260002,62.768959,-623.222595,0.006260,0.001484,0.037681,279.210266,14.223649,0.376809,-623.222595,0.037768,0.000000
47.410004,62.748108,-623.222595,0.006265,0.001484,0.037681,279.117523,14.218925,0.376809,-623.222595,0.037768,0.000000
47.560001,62.745132,-623.267090,0.006265,0.001484,0.037681,279.104279,14.218250,0.376809,-623.267090,0.037768,0.000000
47.710003,62.735077,-623.222595,0.006260,0.001484,0.037681,279.059570,14.215971,0.376809,-623.222595,0.037768,0.000000
47.860001,62.734329,-623.222595,0.006252,0.001484,0.037681,279.056244,14.215803,0.376809,-623.222595,0.037768,0.000000
48.010002,62.720551,-623.311584,0.006269,0.001484,0.037681,278.994934,14.212680,0.376809,-623.311584,0.037768,0.000000
48.160004,62.714226,-623.178101,0.006278,0.001484,0.037681,278.966797,14.211247,0.376809,-623.178101,0.037768,0.000000
48.310001,62.694115,-623.222595,0.006265,0.001484,0.037681,278.877350,14.206690,0.376809,-623.222595,0.037768,0.000000
48.460003,62.684059,-623.222595,0.006265,0.001484,0.037681,278.832611,14.204412,0.376809,-623.222595,0.037768,0.000000
48.610001,62.678848,-623.222595,0.006269,0.001484,0.037681,278.809448,14.203230,0.376809,-623.222595,0.037768,0.000000
48.760002,62.660599,-623.267090,0.006260,0.001484,0.037681,278.728271,14.199095,0.376809,-623.267090,0.037768,0.000000
48.910004,62.660599,-623.311584,0.006265,0.001484,0.037681,278.728271,14.199095,0.376809,-623.311584,0.037768,0.000000
49.060001,62.643097,-623.267090,0.006265,0.001484,0.037681,278.650421,14.195128,0.376809,-623.267090,0.037768,0.000000
49.210003,62.642357,-623.267090,0.006269,0.001484,0.037681,278.647125,14.194962,0.376809,-623.267090,0.037768,0.000000
49.360001,62.624481,-623.267090,0.006265,0.001484,0.037681,278.567596,14.190910,0.376809,-623.267090,0.037768,0.000000
49.510002,62.616287,-623.267090,0.006273,0.001484,0.037681,278.531158,14.189054,0.376809,-623.267090,0.037768,0.000000
49.660004,62.604370,-623.267090,0.006265,0.001484,0.037681,278.478149,14.186354,0.376809,-623.267090,0.037768,0.000000
49.810001,62.598045,-623.311584,0.006256,0.001484,0.037681,278.450012,14.184919,0.376809,-623.311584,0.037768,0.000000
49.960003,62.595810,-623.267090,0.006260,0.001484,0.037681,278.440063,14.184413,0.376809,-623.267090,0.037768,0.000000
50.110001,62.589478,-623.311584,0.006269,0.001484,0.037681,278.411896,14.182979,0.376809,-623.311584,0.037768,0.000000
50.260002,62.579422,-623.267090,0.006260,0.001484,0.037681,278.367157,14.180700,0.376809,-623.267090,0.037768,0.000000
50.410004,62.572723,-623.222595,0.006269,0.001484,0.037681,278.337372,14.179182,0.376809,-623.222595,0.037768,0.000000
50.560001,62.549637,-623.311584,0.006256,0.001484,0.037681,278.234680,14.173950,0.376809,-623.311584,0.037768,0.000000
50.710003,62.539581,-623.311584,0.006256,0.001484,0.037681,278.189941,14.171672,0.376809,-623.311584,0.037768,0.000000
50.860001,62.527290,-623.267090,0.006260,0.001484,0.037681,278.135284,14.168886,0.376809,-623.267090,0.037768,0.000000
51.010002,62.531761,-623.267090,0.006269,0.001484,0.037681,278.155151,14.169899,0.376809,-623.267090,0.037768,0.000000
51.160004,62.527290,-623.311584,0.006260,0.001484,0.037681,278.135284,14.168886,0.376809,-623.311584,0.037768,0.000000
51.310001,62.522453,-623.311584,0.006273,0.001484,0.037681,278.113770,14.167790,0.376809,-623.311584,0.037768,0.000000
51.460003,62.509789,-623.356018,0.006278,0.001484,0.037681,278.057434,14.164921,0.376809,-623.356018,0.037768,0.000000
51.610001,62.490425,-623.311584,0.006265,0.001484,0.037681,277.971283,14.160532,0.376809,-623.311584,0.037768,0.000000
51.760002,62.484467,-623.356018,0.006265,0.001484,0.037681,277.944794,14.159183,0.376809,-623.356018,0.037768,0.000000
51.910004,62.472557,-623.356018,0.006273,0.001484,0.037681,277.891815,14.156485,0.376809,-623.356018,0.037768,0.000000
52.060001,62.470695,-623.356018,0.006256,0.001484,0.037681,277.883545,14.156062,0.376809,-623.356018,0.037768,0.000000
52.210003,62.459892,-623.356018,0.006256,0.001484,0.037681,277.835480,14.153614,0.376809,-623.356018,0.037768,0.000000
52.360001,62.460640,-623.356018,0.006269,0.001484,0.037681,277.838806,14.153784,0.376809,-623.356018,0.037768,0.000000
52.510002,62.460266,-623.356018,0.006273,0.001484,0.037681,277.837128,14.153699,0.376809,-623.356018,0.037768,0.000000
52.660004,62.447235,-623.311584,0.006273,0.001484,0.037681,277.779175,14.150745,0.376809,-623.311584,0.037768,0.000000
52.810001,62.434570,-623.400513,0.006260,0.001484,0.037681,277.722839,14.147876,0.376809,-623.400513,0.037768,0.000000
52.960003,62.425262,-623.356018,0.006273,0.001484,0.037681,277.681427,14.145766,0.376809,-623.356018,0.037768,0.000000
53.110004,62.415581,-623.356018,0.006269,0.001484,0.037681,277.638367,14.143573,0.376809,-623.356018,0.037768,0.000000
53.260002,62.408875,-623.356018,0.006265,0.001484,0.037681,277.608551,14.142054,0.376809,-623.356018,0.037768,0.000000
53.410004,62.409622,-623.400513,0.006265,0.001484,0.037681,277.611877,14.142223,0.376809,-623.400513,0.037768,0.000000
53.560001,62.389511,-623.356018,0.006260,0.001484,0.037681,277.522400,14.137666,0.376809,-623.356018,0.037768,0.000000
53.710003,62.385422,-623.356018,0.006273,0.001484,0.037681,277.504211,14.136739,0.376809,-623.356018,0.037768,0.000000
53.860004,62.363449,-623.311584,0.006273,0.001484,0.037681,277.406464,14.131760,0.376809,-623.311584,0.037768,0.000000
54.010002,62.372757,-623.356018,0.006273,0.001484,0.037681,277.447876,14.133869,0.376809,-623.356018,0.037768,0.000000
54.160004,62.364563,-623.356018,0.006278,0.001484,0.037681,277.411438,14.132011,0.376809,-623.356018,0.037768,0.000000
54.310001,62.357864,-623.356018,0.006260,0.001484,0.037681,277.381622,14.130493,0.376809,-623.356018,0.037768,0.000000
54.460003,62.351532,-623.400513,0.006265,0.001484,0.037681,277.353455,14.129059,0.376809,-623.400513,0.037768,0.000000
54.610004,62.353394,-623.356018,0.006278,0.001484,0.037681,277.361755,14.129480,0.376809,-623.356018,0.037768,0.000000
54.760002,62.335152,-623.400513,0.006273,0.001484,0.037681,277.280609,14.125347,0.376809,-623.400513,0.037768,0.000000
54.910004,62.324722,-623.400513,0.006252,0.001484,0.037681,277.234222,14.122984,0.376809,-623.400513,0.037768,0.000000
55.060001,62.307220,-623.400513,0.006260,0.001484,0.037681,277.156372,14.119018,0.376809,-623.400513,0.037768,0.000000
55.210003,62.313927,-623.489502,0.006256,0.001484,0.037681,277.186188,14.120538,0.376809,-623.489502,0.037768,0.000000
55.360004,62.313179,-623.445007,0.006278,0.001484,0.037681,277.182861,14.120369,0.376809,-623.445007,0.037768,0.000000
55.510002,62.299774,-623.445007,0.006260,0.001484,0.037681,277.123230,14.117331,0.376809,-623.445007,0.037768,0.000000
55.660004,62.289719,-623.400513,0.006278,0.001484,0.037681,277.078522,14.115052,0.376809,-623.400513,0.037768,0.000000
55.810001,62.285248,-623.445007,0.006260,0.001484,0.037681,277.058624,14.114039,0.376809,-623.445007,0.037768,0.000000
55.960003,62.275940,-623.489502,0.006269,0.001484,0.037681,277.017212,14.111929,0.376809,-623.489502,0.037768,0.000000
56.110004,62.264397,-623.400513,0.006265,0.001484,0.037681,276.965881,14.109314,0.376809,-623.400513,0.037768,0.000000
56.260002,62.255836,-623.489502,0.006286,0.001484,0.037681,276.927795,14.107374,0.376809,-623.489502,0.037768,0.000000
56.410004,62.257324,-623.489502,0.006273,0.001484,0.037681,276.934418,14.107712,0.376809,-623.489502,0.037768,0.000000
56.560001,62.256577,-623.445007,0.006291,0.001484,0.037681,276.931091,14.107542,0.376809,-623.445007,0.037768,0.000000
56.710003,62.244659,-623.400513,0.006278,0.001484,0.037681,276.878082,14.104842,0.376809,-623.400513,0.037768,0.000000
56.860004,62.233490,-623.445007,0.006269,0.001484,0.037681,276.828400,14.102311,0.376809,-623.445007,0.037768,0.000000
57.010002,62.232376,-623.445007,0.006269,0.001484,0.037681,276.823425,14.102058,0.376809,-623.445007,0.037768,0.000000
57.160004,62.217476,-623.445007,0.006273,0.001484,0.037681,276.757141,14.098681,0.376809,-623.445007,0.037768,0.000000
57.310001,62.213013,-623.445007,0.006269,0.001484,0.037681,276.737305,14.097671,0.376809,-623.445007,0.037768,0.000000
57.460003,62.207794,-623.445007,0.006273,0.001484,0.037681,276.714081,14.096488,0.376809,-623.445007,0.037768,0.000000
57.610004,62.200722,-623.489502,0.006278,0.001484,0.037681,276.682617,14.094886,0.376809,-623.489502,0.037768,0.000000
57.760002,62.184334,-623.489502,0.006282,0.001484,0.037681,276.609741,14.091171,0.376809,-623.489502,0.037768,0.000000
57.910004,62.189926,-623.445007,0.006278,0.001484,0.037681,276.634613,14.092439,0.376809,-623.445007,0.037768,0.000000
58.060001,62.188431,-623.445007,0.006278,0.001484,0.037681,276.627960,14.092100,0.376809,-623.445007,0.037768,0.000000
58.210003,62.175400,-623.489502,0.006265,0.001484,0.037681,276.569977,14.089147,0.376809,-623.489502,0.037768,0.000000
58.360004,62.165718,-623.489502,0.006278,0.001484,0.037681,276.526917,14.086953,0.376809,-623.489502,0.037768,0.000000
58.510002,62.159019,-623.489502,0.006278,0.001484,0.037681,276.497131,14.085435,0.376809,-623.489502,0.037768,0.000000
58.660004,62.158272,-623.445007,0.006286,0.001484,0.037681,276.493805,14.085266,0.376809,-623.445007,0.037768,0.000000
58.810001,62.137794,-623.489502,0.006273,0.001484,0.037681,276.402710,14.080626,0.376809,-623.489502,0.037768,0.000000
58.960003,62.146729,-623.445007,0.006269,0.001484,0.037681,276.442444,14.082649,0.376809,-623.445007,0.037768,0.000000
59.110004,62.133698,-623.445007,0.006269,0.001484,0.037681,276.384491,14.079698,0.376809,-623.445007,0.037768,0.000000
59.260002,62.132950,-623.445007,0.006282,0.001484,0.037681,276.381165,14.079528,0.376809,-623.445007,0.037768,0.000000
59.410004,62.132576,-623.533997,0.006282,0.001484,0.037681,276.379517,14.079443,0.376809,-623.533997,0.037768,0.000000
59.560001,62.126244,-623.533997,0.006269,0.001484,0.037681,276.351318,14.078008,0.376809,-623.533997,0.037768,0.000000
59.710003,62.119919,-623.445007,0.006273,0.001484,0.037681,276.323212,14.076575,0.376809,-623.445007,0.037768,0.000000
59.860004,62.095711,-623.533997,0.006273,0.001484,0.037681,276.215515,14.071089,0.376809,-623.533997,0.037768,0.000000
60.010002,62.099434,-623.489502,0.006269,0.001484,0.037681,276.232086,14.071933,0.376809,-623.489502,0.037768,0.000000
60.160004,62.103157,-623.578430,0.006278,0.001484,0.037681,276.248627,14.072777,0.376809,-623.578430,0.037768,0.000000
60.310001,62.085655,-623.489502,0.006273,0.001484,0.037681,276.170776,14.068810,0.376809,-623.489502,0.037768,0.000000
60.460003,62.091988,-623.533997,0.006286,0.001484,0.037681,276.198944,14.070246,0.376809,-623.533997,0.037768,0.000000
60.610004,62.087517,-623.533997,0.006282,0.001484,0.037681,276.179077,14.069233,0.376809,-623.533997,0.037768,0.000000
60.760002,62.077469,-623.489502,0.006273,0.001484,0.037681,276.134369,14.066956,0.376809,-623.489502,0.037768,0.000000
60.910004,62.078583,-623.489502,0.006291,0.001484,0.037681,276.139313,14.067208,0.376809,-623.489502,0.037768,0.000000
61.060001,62.051773,-623.533997,0.006282,0.001484,0.037681,276.020081,14.061132,0.376809,-623.533997,0.037768,0.000000
61.210003,62.054008,-623.533997,0.006278,0.001484,0.037681,276.030029,14.061640,0.376809,-623.533997,0.037768,0.000000
61.360004,62.037247,-623.489502,0.006282,0.001484,0.037681,275.955444,14.057841,0.376809,-623.489502,0.037768,0.000000
61.510002,62.043579,-623.533997,0.006278,0.001484,0.037681,275.983612,14.059277,0.376809,-623.533997,0.037768,0.000000
61.660004,62.040604,-623.533997,0.006286,0.001484,0.037681,275.970398,14.058601,0.376809,-623.533997,0.037768,0.000000
61.810001,62.030922,-623.578430,0.006278,0.001484,0.037681,275.927307,14.056407,0.376809,-623.578430,0.037768,0.000000
61.960003,62.033524,-623.533997,0.006278,0.001484,0.037681,275.938904,14.056997,0.376809,-623.533997,0.037768,0.000000
62.110004,62.022728,-623.578430,0.006282,0.001484,0.037681,275.890869,14.054551,0.376809,-623.578430,0.037768,0.000000
62.260002,62.013420,-623.578430,0.006269,0.001484,0.037681,275.849457,14.052442,0.376809,-623.578430,0.037768,0.000000
62.410004,61.997780,-623.533997,0.006278,0.001484,0.037681,275.779907,14.048898,0.376809,-623.533997,0.037768,0.000000
62.560001,61.997032,-623.533997,0.006265,0.001484,0.037681,275.776581,14.048728,0.376809,-623.533997,0.037768,0.000000
62.700005,61.998520,-623.578430,0.006278,0.001484,0.037681,275.783203,14.049066,0.376809,-623.578430,0.037768,0.000000