File: Data/AG AL compression 300N/AG membrane Peeled 300N_1_1_03192024_183239.csv
Time (sec),S:Load (lbs),S:HL1 (DIM),S:LVDT (in),S:Position (in),Ch:Position (mm),Ch:Load (N),Ch:Stress (MPa),Ch:Strain (mm/mm),Ch:HL1 (DIM),Set Point (),Cycles ()
0.010000,-0.019737,-303.048706,0.000004,-0.000000,-0.000000,-0.087796,-0.004473,-0.000000,-303.048706,-0.000113,0.000000
0.200000,-0.012291,-303.093201,-0.000004,-0.000000,-0.000000,-0.054673,-0.002785,-0.000000,-303.093201,-0.000113,0.000000
0.390000,-0.002235,-303.093201,-0.000004,0.000019,0.000494,-0.009944,-0.000507,0.004943,-303.093201,0.001049,0.000000
0.580000,0.005959,-303.048706,0.000017,0.000131,0.003339,0.026505,0.001350,0.033387,-303.048706,0.004206,0.000000
0.770000,0.011169,-303.182159,0.000013,0.000241,0.006122,0.049684,0.002531,0.061224,-303.182159,0.007380,0.000000
0.960000,0.005959,-303.182159,0.000142,0.000371,0.009435,0.026505,0.001350,0.094354,-303.182159,0.010537,0.000000
1.150000,0.003349,-303.137695,0.000250,0.000494,0.012540,0.014898,0.000759,0.125401,-303.137695,0.013711,0.000000
1.340000,-0.007080,-303.182159,0.000392,0.000618,0.015705,-0.031494,-0.001604,0.157054,-303.182159,0.016867,0.000000
1.530000,0.010422,-303.226654,0.000517,0.000744,0.018906,0.046358,0.002362,0.189056,-303.226654,0.020041,0.000000
1.720000,0.011169,-303.271118,0.000642,0.000874,0.022201,0.049684,0.002531,0.222011,-303.271118,0.023198,0.000000
1.910000,0.004837,-303.226654,0.000767,0.000997,0.025323,0.021516,0.001096,0.253228,-303.226654,0.026372,0.000000
2.100000,0.014519,-303.271118,0.000897,0.001124,0.028540,0.064583,0.003290,0.285404,-303.271118,0.029529,0.000000
2.290000,0.021225,-303.271118,0.001013,0.001245,0.031610,0.094413,0.004810,0.316103,-303.271118,0.032703,0.000000
2.480000,0.017502,-303.315613,0.001143,0.001372,0.034845,0.077852,0.003966,0.348449,-303.315613,0.035860,0.000000
2.670000,-0.012291,-303.360077,0.001268,0.001496,0.038002,-0.054673,-0.002785,0.380019,-303.360077,0.039034,0.000000
2.860000,0.005585,-303.315613,0.001380,0.001623,0.041219,0.024842,0.001266,0.412190,-303.315613,0.042191,0.000000
3.050000,-0.001122,-303.271118,0.001492,0.001741,0.044211,-0.004989,-0.000254,0.442110,-303.271118,0.045365,0.000000
3.240000,-0.033890,-303.315613,0.001613,0.001860,0.047238,-0.150749,-0.007680,0.472378,-303.315613,0.048521,0.000000
3.430000,-0.046173,-303.271118,0.001746,0.001989,0.050516,-0.205388,-0.010463,0.505159,-303.271118,0.051695,0.000000
3.620000,-0.032402,-303.404572,0.001871,0.002115,0.053725,-0.144131,-0.007342,0.537247,-303.404572,0.054852,0.000000
3.810000,0.005959,-303.360077,0.002005,0.002241,0.056916,0.026505,0.001350,0.569157,-303.360077,0.058026,0.000000
4.000000,-0.006332,-303.449036,0.002126,0.002366,0.060107,-0.028168,-0.001435,0.601072,-303.449036,0.061183,0.000000
4.190000,-0.013779,-303.404572,0.002238,0.002493,0.063325,-0.061291,-0.003122,0.633247,-303.404572,0.064357,0.000000
4.380000,-0.004097,-303.404572,0.002367,0.002617,0.066473,-0.018224,-0.000928,0.664726,-303.404572,0.067513,0.000000
4.570000,0.018242,-303.404572,0.002514,0.002738,0.069534,0.081144,0.004134,0.695342,-303.404572,0.070687,0.000000
4.760000,-0.009308,-303.449036,0.002647,0.002866,0.072786,-0.041403,-0.002109,0.727862,-303.449036,0.073844,0.000000
4.950000,-0.011169,-303.538025,0.002746,0.002990,0.075943,-0.049684,-0.002531,0.759428,-303.538025,0.077018,0.000000
5.140000,-0.020485,-303.493530,0.002884,0.003111,0.079030,-0.091121,-0.004642,0.790301,-303.493530,0.080175,0.000000
5.330000,-0.032402,-303.449036,0.003005,0.003236,0.082195,-0.144131,-0.007342,0.821954,-303.449036,0.083349,0.000000
5.520000,-0.053627,-303.582489,0.003122,0.003363,0.085430,-0.238545,-0.012152,0.854304,-303.582489,0.086506,0.000000
5.710000,-0.031281,-303.493530,0.003255,0.003491,0.088665,-0.139143,-0.007088,0.886649,-303.493530,0.089680,0.000000
5.900000,0.009308,-303.538025,0.003376,0.003614,0.091805,0.041403,0.002109,0.918045,-303.538025,0.092836,0.000000
6.090000,0.000740,-303.582489,0.003497,0.003740,0.094987,0.003292,0.000168,0.949872,-303.582489,0.096010,0.000000
6.280000,0.011917,-303.538025,0.003626,0.003865,0.098161,0.053010,0.002700,0.981613,-303.538025,0.099167,0.000000
6.470000,0.035004,-303.626984,0.003747,0.003989,0.101309,0.155704,0.007932,1.013091,-303.626984,0.102341,0.000000
6.660000,0.055107,-303.626984,0.003880,0.004118,0.104587,0.245129,0.012487,1.045872,-303.626984,0.105498,0.000000
6.850000,0.037605,-303.671448,0.004005,0.004238,0.107648,0.167277,0.008521,1.076485,-303.671448,0.108672,0.000000
7.040000,0.026062,-303.671448,0.004135,0.004365,0.110875,0.115930,0.005906,1.108747,-303.671448,0.111829,0.000000
7.230000,0.018242,-303.626984,0.004260,0.004490,0.114040,0.081144,0.004134,1.140400,-303.626984,0.115003,0.000000
7.420001,0.014893,-303.760406,0.004381,0.004614,0.117205,0.066245,0.003375,1.172053,-303.760406,0.118159,0.000000
7.610000,0.010056,-303.671448,0.004518,0.004741,0.120432,0.044729,0.002279,1.204316,-303.671448,0.121334,0.000000
7.800000,0.005585,-303.671448,0.004631,0.004864,0.123545,0.024842,0.001266,1.235450,-303.671448,0.124490,0.000000
7.990000,0.038353,-303.715942,0.004777,0.004986,0.126649,0.170603,0.008691,1.266494,-303.715942,0.127664,0.000000
8.180000,0.045425,-303.760406,0.004898,0.005109,0.129780,0.202062,0.010294,1.297803,-303.760406,0.130821,0.000000
8.370001,0.053619,-303.760406,0.005032,0.005239,0.133067,0.238511,0.012150,1.330671,-303.760406,0.133995,0.000000
8.560000,0.050644,-303.760406,0.005148,0.005360,0.136137,0.225275,0.011476,1.361370,-303.760406,0.137152,0.000000
8.750000,0.045052,-303.760406,0.005273,0.005481,0.139224,0.200399,0.010209,1.392243,-303.760406,0.140326,0.000000
8.940001,0.037605,-303.760406,0.005420,0.005605,0.142364,0.167277,0.008521,1.423635,-303.760406,0.143482,0.000000
9.130000,0.028297,-303.760406,0.005540,0.005734,0.145642,0.125873,0.006412,1.456416,-303.760406,0.146656,0.000000
9.320001,0.037239,-303.804901,0.005657,0.005854,0.148695,0.165648,0.008438,1.486945,-303.804901,0.149813,0.000000
9.510000,0.028671,-303.760406,0.005773,0.005977,0.151825,0.127536,0.006497,1.518250,-303.760406,0.152987,0.000000
9.700001,0.039467,-303.849365,0.005885,0.006100,0.154938,0.175557,0.008943,1.549385,-303.849365,0.156144,0.000000
9.890000,0.041702,-303.938324,0.006028,0.006225,0.158104,0.185501,0.009450,1.581038,-303.938324,0.159318,0.000000
10.080001,0.071121,-303.849365,0.006144,0.006351,0.161304,0.316363,0.016116,1.613039,-303.849365,0.162475,0.000000
10.270000,0.050644,-303.893860,0.006260,0.006478,0.164530,0.225275,0.011476,1.645301,-303.893860,0.165649,0.000000
10.460000,0.058464,-303.893860,0.006394,0.006604,0.167730,0.260061,0.013248,1.677299,-303.893860,0.168806,0.000000
10.650001,0.063301,-303.938324,0.006523,0.006728,0.170887,0.281577,0.014344,1.708869,-303.938324,0.171980,0.000000
10.840000,0.045799,-303.938324,0.006618,0.006853,0.174070,0.203725,0.010378,1.740696,-303.938324,0.175136,0.000000
11.030001,0.044312,-303.938324,0.006739,0.006979,0.177269,0.197107,0.010041,1.772693,-303.938324,0.178310,0.000000
11.220000,0.042824,-303.982819,0.006864,0.007102,0.180391,0.190490,0.009704,1.803915,-303.982819,0.181467,0.000000
11.410001,0.040588,-303.938324,0.007015,0.007226,0.183531,0.180546,0.009197,1.835307,-303.938324,0.184641,0.000000
11.600000,0.033142,-303.982819,0.007127,0.007349,0.186670,0.147423,0.007510,1.866703,-303.982819,0.187798,0.000000
11.790001,0.033882,-304.027313,0.007243,0.007474,0.189836,0.150715,0.007678,1.898356,-304.027313,0.190972,0.000000
11.980000,0.013031,-304.027313,0.007381,0.007598,0.192992,0.057965,0.002953,1.929922,-304.027313,0.194128,0.000000
12.170001,0.046173,-304.027313,0.007489,0.007724,0.196184,0.205388,0.010463,1.961836,-304.027313,0.197302,0.000000
12.360001,0.053246,-304.071777,0.007614,0.007850,0.199401,0.236848,0.012066,1.994011,-304.071777,0.200459,0.000000
12.550000,0.047661,-304.071777,0.007739,0.007976,0.202584,0.212006,0.010800,2.025839,-304.071777,0.203633,0.000000
12.740001,0.050644,-304.116272,0.007864,0.008102,0.205801,0.225275,0.011476,2.058014,-304.116272,0.206790,0.000000
12.930000,0.063301,-304.071777,0.007994,0.008225,0.208906,0.281577,0.014344,2.089058,-304.071777,0.209964,0.000000
13.120001,0.064049,-304.205231,0.008110,0.008346,0.211993,0.284903,0.014514,2.119931,-304.205231,0.213121,0.000000
13.310000,0.049149,-304.116272,0.008235,0.008472,0.215193,0.218624,0.011137,2.151932,-304.116272,0.216295,0.000000
13.500001,0.046547,-304.071777,0.008360,0.008595,0.218324,0.207051,0.010548,2.183241,-304.071777,0.219451,0.000000
13.690001,0.043564,-304.160736,0.008489,0.008718,0.221428,0.193782,0.009872,2.214285,-304.160736,0.222625,0.000000
13.880001,0.037979,-304.160736,0.008627,0.008842,0.224594,0.168940,0.008606,2.245942,-304.160736,0.225782,0.000000
14.070001,0.033882,-304.249695,0.008757,0.008969,0.227803,0.150715,0.007678,2.278026,-304.249695,0.228956,0.000000
14.260000,0.073730,-304.249695,0.008912,0.009096,0.231038,0.327969,0.016708,2.310376,-304.249695,0.232113,0.000000
14.450001,0.147827,-304.205231,0.009028,0.009221,0.234212,0.657568,0.033498,2.342116,-304.205231,0.235287,0.000000
14.640000,0.193634,-304.249695,0.009158,0.009345,0.237359,0.861327,0.043878,2.373595,-304.249695,0.238443,0.000000
14.830001,0.271828,-304.249695,0.009291,0.009469,0.240508,1.209150,0.061597,2.405077,-304.249695,0.241617,0.000000
15.020000,0.398064,-304.294189,0.009408,0.009596,0.243734,1.770676,0.090203,2.437336,-304.294189,0.244774,0.000000
15.210001,0.636383,-304.249695,0.009550,0.000004,0.000113,2.830773,0.144206,0.001128,-304.249695,0.001145,0.000000
15.400001,0.557816,-304.294189,0.009567,0.000015,0.000373,2.481287,0.126403,0.003732,-304.294189,0.000590,0.000000
15.590001,0.522064,-304.294189,0.009593,0.000015,0.000373,2.322258,0.118301,0.003732,-304.294189,0.000590,0.000000
15.780001,0.489670,-304.294189,0.009585,0.000015,0.000373,2.178160,0.110961,0.003732,-304.294189,0.000607,0.000000
15.970001,0.529884,-304.338654,0.009589,0.000015,0.000373,2.357043,0.120074,0.003732,-304.338654,0.000919,0.000000
16.160000,0.546272,-304.383148,0.009572,0.000015,0.000382,2.429940,0.123787,0.003815,-304.383148,0.001240,0.000000
16.350000,0.553719,-304.338654,0.009589,0.000016,0.000399,2.463063,0.125474,0.003989,-304.338654,0.001553,0.000000
16.540001,0.692986,-304.427643,0.009585,0.000041,0.001050,3.082554,0.157033,0.010496,-304.427643,0.001873,0.000000
16.730001,0.739899,-304.427643,0.009589,0.000052,0.001327,3.291234,0.167663,0.013270,-304.427643,0.002185,0.000000
16.920000,0.743256,-304.427643,0.009585,0.000058,0.001483,3.306166,0.168424,0.014829,-304.427643,0.002506,0.000000
17.110001,0.824432,-304.383148,0.009606,0.000077,0.001951,3.667258,0.186819,0.019515,-304.383148,0.002819,0.000000
17.300001,0.831505,-304.383148,0.009632,0.000092,0.002342,3.698718,0.188422,0.023417,-304.383148,0.003140,0.000000
17.490002,0.882896,-304.561066,0.009641,0.000105,0.002663,3.927320,0.200067,0.026627,-304.561066,0.003461,0.000000
17.680000,0.906723,-304.427643,0.009649,0.000116,0.002940,4.033306,0.205466,0.029401,-304.427643,0.003772,0.000000
17.870001,0.916405,-304.516602,0.009658,0.000127,0.003235,4.076372,0.207660,0.032349,-304.516602,0.004093,0.000000
18.060001,0.966675,-304.472107,0.009675,0.000139,0.003530,4.299984,0.219052,0.035298,-304.472107,0.004406,0.000000
18.250000,1.009125,-304.472107,0.009675,0.000151,0.003825,4.488811,0.228671,0.038246,-304.472107,0.004727,0.000000
18.440001,1.046364,-304.516602,0.009692,0.000162,0.004111,4.654459,0.237109,0.041108,-304.516602,0.005039,0.000000
18.630001,1.095520,-304.472107,0.009710,0.000174,0.004414,4.873116,0.248248,0.044143,-304.472107,0.005359,0.000000
18.820002,1.109665,-304.605560,0.009714,0.000182,0.004631,4.936036,0.251454,0.046312,-304.605560,0.005672,0.000000
19.010000,1.235901,-304.561066,0.009722,0.000205,0.005195,5.497561,0.280059,0.051948,-304.561066,0.005993,0.000000
19.200001,1.257126,-304.561066,0.009740,0.000217,0.005507,5.591975,0.284869,0.055070,-304.561066,0.006305,0.000000
19.390001,1.343887,-304.561066,0.009757,0.000231,0.005880,5.977910,0.304529,0.058798,-304.561066,0.006626,0.000000
19.580002,1.367722,-304.561066,0.009766,0.000239,0.006079,6.083930,0.309930,0.060793,-304.561066,0.006938,0.000000
19.770000,1.422462,-304.650024,0.009774,0.000252,0.006400,6.327429,0.322335,0.064003,-304.650024,0.007259,0.000000
19.960001,1.498795,-304.650024,0.009800,0.000263,0.006669,6.666971,0.339632,0.066690,-304.650024,0.007571,0.000000
20.150002,1.579605,-304.605560,0.009791,0.000276,0.007007,7.026434,0.357944,0.070074,-304.605560,0.007892,0.000000
20.340000,1.656311,-304.694519,0.009809,0.000289,0.007337,7.367640,0.375325,0.073370,-304.694519,0.008204,0.000000
20.530001,1.726318,-304.650024,0.009835,0.000299,0.007588,7.679048,0.391189,0.075883,-304.650024,0.008525,0.000000
20.720001,1.784782,-304.694519,0.009817,0.000309,0.007840,7.939109,0.404437,0.078400,-304.694519,0.008837,0.000000
20.910002,1.927399,-304.694519,0.009843,0.000324,0.008230,8.573498,0.436755,0.082303,-304.694519,0.009158,0.000000
21.100000,2.017883,-304.738983,0.009843,0.000340,0.008638,8.975993,0.457259,0.086375,-304.738983,0.009470,0.000000
21.290001,2.119911,-304.783478,0.009891,0.000354,0.009002,9.429836,0.480379,0.090020,-304.783478,0.009791,0.000000
21.480001,2.187317,-304.738983,0.009878,0.000364,0.009253,9.729671,0.495653,0.092533,-304.738983,0.010103,0.000000
21.670000,2.191040,-304.783478,0.009886,0.000375,0.009514,9.746233,0.496497,0.095137,-304.783478,0.010424,0.000000
21.860001,2.358604,-304.738983,0.009899,0.000385,0.009791,10.491596,0.534467,0.097911,-304.738983,0.010736,0.000000
22.050001,2.421906,-304.738983,0.009912,0.000395,0.010042,10.773173,0.548812,0.100425,-304.738983,0.011057,0.000000
22.240002,2.647568,-304.872437,0.009916,0.000412,0.010468,11.776970,0.599947,0.104675,-304.872437,0.011369,0.000000
22.430000,2.749222,-304.827972,0.009947,0.000422,0.010719,12.229150,0.622983,0.107192,-304.827972,0.011690,0.000000
22.620001,2.841202,-304.827972,0.009955,0.000435,0.011040,12.638297,0.643826,0.110398,-304.827972,0.012003,0.000000
22.810001,3.106331,-304.916931,0.009947,0.000447,0.011361,13.817650,0.703905,0.113607,-304.916931,0.012323,0.000000
23.000002,3.292885,-304.827972,0.009947,0.000462,0.011734,14.647483,0.746178,0.117336,-304.827972,0.012644,0.000000
23.190001,3.475723,-304.872437,0.009985,0.000479,0.012159,15.460790,0.787610,0.121586,-304.872437,0.012956,0.000000
23.380001,3.621323,-304.916931,0.009994,0.000490,0.012453,16.108448,0.820603,0.124534,-304.916931,0.013277,0.000000
23.570002,3.712555,-304.872437,0.009998,0.000498,0.012653,16.514269,0.841277,0.126529,-304.872437,0.013590,0.000000
23.760000,3.922943,-304.961395,0.010016,0.000510,0.012956,17.450123,0.888952,0.129565,-304.961395,0.013910,0.000000
23.950001,4.064819,-304.872437,0.010016,0.000519,0.013182,18.081219,0.921101,0.131820,-304.872437,0.014222,0.000000
24.140001,4.307602,-304.961395,0.010037,0.000531,0.013486,19.161171,0.976117,0.134856,-304.961395,0.014543,0.000000
24.330002,4.547035,-305.005890,0.010046,0.000547,0.013893,20.226223,1.030373,0.138932,-305.005890,0.014856,0.000000
24.520000,4.867653,-305.050354,0.010050,0.000560,0.014222,21.652401,1.103026,0.142225,-305.050354,0.015177,0.000000
24.710001,4.955528,-305.005890,0.010072,0.000568,0.014439,22.043291,1.122939,0.144394,-305.005890,0.015489,0.000000
24.900002,5.279495,-305.005890,0.010059,0.000583,0.014803,23.484367,1.196351,0.148035,-305.005890,0.015810,0.000000
25.090002,5.846245,-305.050354,0.010072,0.000606,0.015394,26.005396,1.324778,0.153935,-305.050354,0.016122,0.000000
25.280001,6.040253,-305.050354,0.010115,0.000617,0.015680,26.868385,1.368741,0.156797,-305.050354,0.016443,0.000000
25.470001,6.202980,-305.050354,0.010111,0.000626,0.015888,27.592234,1.405615,0.158879,-305.050354,0.016755,0.000000
25.660002,6.459915,-305.050354,0.010128,0.000636,0.016157,28.735138,1.463838,0.161566,-305.050354,0.017076,0.000000
25.850000,6.755951,-305.094849,0.010128,0.000647,0.016434,30.051971,1.530920,0.164340,-305.094849,0.017388,0.000000
26.040001,6.961876,-305.094849,0.010154,0.000658,0.016720,30.967970,1.577584,0.167202,-305.094849,0.017709,0.000000
26.230001,7.471649,-305.094849,0.010145,0.000674,0.017110,33.235554,1.693100,0.171104,-305.094849,0.018021,0.000000
26.420002,7.644058,-305.094849,0.010162,0.000683,0.017345,34.002468,1.732168,0.173447,-305.094849,0.018342,0.000000
26.610001,8.021645,-305.183807,0.010158,0.000694,0.017631,35.682056,1.817731,0.176308,-305.183807,0.018654,0.000000
26.800001,8.248421,-305.139313,0.010179,0.000703,0.017848,36.690807,1.869119,0.178477,-305.139313,0.018975,0.000000
26.990002,9.102646,-305.183807,0.010179,0.000730,0.018533,40.490593,2.062689,0.185327,-305.183807,0.019287,0.000000
27.180002,9.355110,-305.183807,0.010214,0.000744,0.018888,41.613609,2.119898,0.188881,-305.183807,0.019608,0.000000
27.370001,9.549866,-305.183807,0.010214,0.000753,0.019122,42.479923,2.164031,0.191224,-305.183807,0.019920,0.000000
27.560001,9.858185,-305.272766,0.010223,0.000765,0.019443,43.851395,2.233897,0.194434,-305.272766,0.020241,0.000000
27.750002,10.106560,-305.183807,0.010240,0.000773,0.019625,44.956223,2.290179,0.196254,-305.183807,0.020553,0.000000
27.940001,10.399620,-305.272766,0.010231,0.000786,0.019964,46.259819,2.356588,0.199638,-305.272766,0.020874,0.000000
28.130001,11.049782,-305.317261,0.010253,0.000798,0.020267,49.151886,2.503916,0.202674,-305.317261,0.021186,0.000000
28.320002,11.272461,-305.272766,0.010236,0.000808,0.020527,50.142410,2.554376,0.205274,-305.272766,0.021507,0.000000
28.510002,11.602379,-305.361725,0.010257,0.000821,0.020848,51.609959,2.629137,0.208483,-305.361725,0.021828,0.000000
28.700001,11.920013,-305.317261,0.010279,0.000831,0.021100,53.022869,2.701114,0.210997,-305.317261,0.022140,0.000000
28.890001,12.761200,-305.317261,0.010283,0.000854,0.021689,56.764652,2.891729,0.216893,-305.317261,0.022461,0.000000
29.080002,12.892281,-305.361725,0.010309,0.000863,0.021932,57.347729,2.921432,0.219323,-305.361725,0.022773,0.000000
29.270000,13.146980,-305.317261,0.010296,0.000874,0.022192,58.480690,2.979148,0.221924,-305.317261,0.023094,0.000000
29.460001,13.648193,-305.361725,0.010309,0.000888,0.022565,60.710197,3.092725,0.225652,-305.361725,0.023407,0.000000
29.650002,13.839592,-305.361725,0.010326,0.000896,0.022756,61.561581,3.136096,0.227563,-305.361725,0.023728,0.000000
29.840002,14.167282,-305.361725,0.010335,0.000910,0.023112,63.019218,3.210352,0.231117,-305.361725,0.024040,0.000000
30.030001,14.780952,-305.450684,0.010343,0.000924,0.023467,65.748962,3.349412,0.234671,-305.450684,0.024360,0.000000
30.220001,15.253494,-305.406219,0.010365,0.000938,0.023832,67.850929,3.456491,0.238316,-305.406219,0.024673,0.000000
30.410002,15.468353,-305.495178,0.010365,0.000948,0.024092,68.806671,3.505179,0.240916,-305.495178,0.024994,0.000000
30.600002,15.781517,-305.450684,0.010378,0.000961,0.024421,70.199692,3.576143,0.244213,-305.450684,0.025306,0.000000
30.790001,16.349754,-305.495178,0.010386,0.000976,0.024785,72.727341,3.704907,0.247854,-305.495178,0.025627,0.000000
30.980001,16.637230,-305.495178,0.010404,0.000987,0.025063,74.006096,3.770050,0.250628,-305.495178,0.025939,0.000000
31.170002,17.130623,-305.495178,0.010417,0.001001,0.025436,76.200813,3.881855,0.254360,-305.495178,0.026260,0.000000
31.360001,17.362610,-305.584137,0.010417,0.001014,0.025757,77.232742,3.934423,0.257566,-305.584137,0.026572,0.000000
31.550001,17.608376,-305.539642,0.010412,0.001024,0.026008,78.325966,3.990115,0.260083,-305.539642,0.026893,0.000000
31.740002,18.010536,-305.584137,0.010425,0.001036,0.026312,80.114868,4.081246,0.263118,-305.584137,0.027205,0.000000
31.930002,18.556061,-305.584137,0.010460,0.001050,0.026667,82.541481,4.204864,0.266672,-305.584137,0.027526,0.000000
32.120003,18.818214,-305.628601,0.010460,0.001061,0.026945,83.707596,4.264268,0.269447,-305.628601,0.027838,0.000000
32.310001,19.145531,-305.628601,0.010455,0.001073,0.027248,85.163574,4.338439,0.272482,-305.628601,0.028159,0.000000
32.500000,19.531303,-305.584137,0.010468,0.001087,0.027604,86.879578,4.425857,0.276040,-305.584137,0.028471,0.000000
32.690002,20.289825,-305.628601,0.010477,0.001104,0.028037,90.253654,4.597740,0.280374,-305.628601,0.028792,0.000000
32.880001,20.459633,-305.628601,0.010494,0.001115,0.028324,91.008995,4.636219,0.283239,-305.628601,0.029104,0.000000
33.070000,20.819717,-305.673096,0.010507,0.001128,0.028662,92.610725,4.717815,0.286619,-305.673096,0.029425,0.000000
33.260002,20.853600,-305.717590,0.010499,0.001138,0.028896,92.761444,4.725493,0.288962,-305.717590,0.029737,0.000000
33.450001,21.148148,-305.673096,0.010529,0.001147,0.029139,94.071655,4.792239,0.291388,-305.673096,0.030058,0.000000
33.640003,21.738358,-305.717590,0.010533,0.001162,0.029503,96.697044,4.925982,0.295033,-305.717590,0.030370,0.000000
33.830002,22.105888,-305.717590,0.010563,0.001175,0.029850,98.331902,5.009266,0.298500,-305.717590,0.030691,0.000000
34.020000,22.540817,-305.717590,0.010542,0.001189,0.030188,100.266563,5.107822,0.301883,-305.717590,0.031012,0.000000
34.210003,22.783981,-305.806549,0.010559,0.001198,0.030440,101.348213,5.162924,0.304396,-305.806549,0.031324,0.000000
34.400002,22.628700,-305.762054,0.010589,0.001204,0.030587,100.657486,5.127737,0.305872,-305.762054,0.031645,0.000000
34.590000,23.786034,-305.806549,0.010572,0.001226,0.031151,105.805565,5.389992,0.311508,-305.806549,0.031957,0.000000
34.780003,24.148727,-305.851013,0.010593,0.001240,0.031507,107.418907,5.472180,0.315066,-305.851013,0.032278,0.000000
34.970001,24.372520,-305.851013,0.010606,0.001251,0.031784,108.414383,5.522892,0.317840,-305.851013,0.032591,0.000000
35.160000,24.428749,-305.895508,0.010619,0.001259,0.031975,108.664505,5.535634,0.319748,-305.895508,0.032911,0.000000
35.350002,24.982468,-305.762054,0.010619,0.001274,0.032365,111.127563,5.661108,0.323650,-305.762054,0.033223,0.000000
35.540001,25.443092,-305.895508,0.010632,0.001288,0.032703,113.176529,5.765487,0.327034,-305.895508,0.033544,0.000000
35.730003,25.686996,-305.895508,0.010654,0.001298,0.032963,114.261467,5.820757,0.329634,-305.895508,0.033857,0.000000
35.920002,26.077240,-305.851013,0.010654,0.001310,0.033267,115.997360,5.909187,0.332670,-305.851013,0.034178,0.000000
36.110001,26.588882,-305.939972,0.010675,0.001324,0.033640,118.273254,6.025127,0.336398,-305.939972,0.034490,0.000000
36.300003,26.510307,-305.895508,0.010667,0.001330,0.033770,117.923737,6.007321,0.337700,-305.895508,0.034810,0.000000
36.490002,26.934441,-305.939972,0.010671,0.001346,0.034186,119.810379,6.103431,0.341863,-305.939972,0.035123,0.000000
36.680000,27.672112,-305.984467,0.010693,0.001360,0.034533,123.091698,6.270590,0.345330,-305.984467,0.035444,0.000000
36.870003,28.414993,-305.939972,0.010697,0.001376,0.034949,126.396202,6.438930,0.349493,-305.939972,0.035756,0.000000
37.060001,28.554634,-306.028931,0.010710,0.001388,0.035244,127.017357,6.470573,0.352442,-306.028931,0.036077,0.000000
37.250000,28.707306,-305.939972,0.010727,0.001398,0.035504,127.696472,6.505168,0.355042,-305.939972,0.036389,0.000000
37.440002,28.975792,-306.073425,0.010718,0.001409,0.035799,128.890762,6.566008,0.357991,-306.073425,0.036710,0.000000
37.630001,29.325447,-306.028931,0.010731,0.001421,0.036094,130.446106,6.645241,0.360939,-306.028931,0.037022,0.000000
37.820004,29.958855,-306.028931,0.010762,0.001434,0.036415,133.263641,6.788773,0.364149,-306.028931,0.037343,0.000000
38.010002,30.543106,-306.162384,0.010762,0.001450,0.036831,135.862518,6.921167,0.368312,-306.162384,0.037655,0.000000
38.200001,30.493950,-306.028931,0.010766,0.001455,0.036953,135.643860,6.910028,0.369527,-306.028931,0.037976,0.000000
38.390003,30.808235,-306.117920,0.010766,0.001468,0.037282,137.041870,6.981246,0.372820,-306.117920,0.038288,0.000000
38.580002,31.761879,-306.162384,0.010792,0.001485,0.037707,141.283890,7.197345,0.377070,-306.162384,0.038609,0.000000
38.770000,32.114891,-306.117920,0.010796,0.001497,0.038019,142.854172,7.277339,0.380193,-306.117920,0.038921,0.000000
38.960003,32.772125,-306.206879,0.010796,0.001511,0.038383,145.777695,7.426270,0.383834,-306.206879,0.039242,0.000000
39.150002,33.031670,-306.162384,0.010809,0.001523,0.038678,146.932205,7.485084,0.386782,-306.162384,0.039554,0.000000
39.340000,33.272964,-306.206879,0.010818,0.001532,0.038904,148.005539,7.539762,0.389038,-306.206879,0.039875,0.000000
39.530003,33.760773,-306.206879,0.010826,0.001545,0.039251,150.175415,7.650301,0.392509,-306.206879,0.040196,0.000000
39.720001,34.308907,-306.162384,0.010848,0.001558,0.039571,152.613632,7.774509,0.395715,-306.162384,0.040508,0.000000
39.910004,34.891670,-306.251343,0.010848,0.001572,0.039919,155.205902,7.906566,0.399185,-306.251343,0.040829,0.000000
40.100002,35.211166,-306.206879,0.010852,0.001581,0.040153,156.627090,7.978964,0.401528,-306.206879,0.041141,0.000000
40.290001,35.933937,-306.295837,0.010865,0.001599,0.040612,159.842133,8.142747,0.406123,-306.295837,0.041462,0.000000
40.480003,36.657829,-306.251343,0.010874,0.001611,0.040925,163.062164,8.306783,0.409246,-306.251343,0.041774,0.000000
40.670002,37.074142,-306.206879,0.010882,0.001625,0.041280,164.914017,8.401120,0.412800,-306.206879,0.042095,0.000000
40.860001,37.587646,-306.295837,0.010887,0.001636,0.041566,167.198196,8.517483,0.415661,-306.295837,0.042407,0.000000
41.050003,37.967842,-306.251343,0.010895,0.001649,0.041878,168.889389,8.603636,0.418783,-306.251343,0.042728,0.000000
41.240002,38.353241,-306.384796,0.010904,0.001659,0.042130,170.603729,8.690969,0.421300,-306.384796,0.043041,0.000000
41.430000,38.593796,-306.384796,0.010917,0.001667,0.042330,171.673782,8.745479,0.423295,-306.384796,0.043361,0.000000
41.620003,39.348969,-306.340302,0.010912,0.001682,0.042711,175.032959,8.916603,0.427110,-306.340302,0.043674,0.000000
41.810001,40.059830,-306.384796,0.010925,0.001693,0.043015,178.195023,9.077687,0.430146,-306.384796,0.043994,0.000000
42.000004,40.387146,-306.340302,0.010951,0.001705,0.043318,179.651001,9.151857,0.433181,-306.340302,0.044307,0.000000
42.190002,41.109917,-306.429260,0.010947,0.001719,0.043656,182.866043,9.315640,0.436561,-306.429260,0.044628,0.000000
42.380001,42.008453,-306.384796,0.010969,0.001735,0.044081,186.862930,9.519252,0.440812,-306.384796,0.044940,0.000000
42.570004,42.618401,-306.429260,0.010956,0.001748,0.044402,189.576111,9.657467,0.444021,-306.429260,0.045261,0.000000
42.760002,43.147537,-306.473755,0.010956,0.001759,0.044680,191.929825,9.777371,0.446795,-306.473755,0.045573,0.000000
42.950001,43.531082,-306.429260,0.010977,0.001768,0.044914,193.635925,9.864285,0.449138,-306.429260,0.045894,0.000000
43.140003,43.952240,-306.384796,0.010973,0.001781,0.045235,195.509323,9.959721,0.452348,-306.384796,0.046206,0.000000
43.330002,44.432228,-306.473755,0.010990,0.001789,0.045451,197.644424,10.068487,0.454513,-306.473755,0.046527,0.000000
43.520000,44.995628,-306.473755,0.010990,0.001803,0.045790,200.150558,10.196155,0.457897,-306.473755,0.046839,0.000000
43.710003,46.267273,-306.473755,0.011007,0.001820,0.046223,205.807114,10.484314,0.462234,-306.473755,0.047160,0.000000
43.900002,46.542084,-306.473755,0.011007,0.001829,0.046457,207.029526,10.546587,0.464573,-306.473755,0.047472,0.000000
44.090004,47.178101,-306.562714,0.011012,0.001843,0.046822,209.858673,10.690710,0.468218,-306.562714,0.047793,0.000000
44.280003,48.030830,-306.607208,0.011033,0.001857,0.047168,213.651810,10.883942,0.471685,-306.607208,0.048105,0.000000
44.470001,49.047409,-306.562714,0.011012,0.001873,0.047576,218.173767,11.114302,0.475761,-306.562714,0.048426,0.000000
44.660004,49.786194,-306.562714,0.011033,0.001885,0.047888,221.460052,11.281713,0.478884,-306.562714,0.048747,0.000000
44.850002,50.138092,-306.562714,0.011050,0.001894,0.048105,223.025375,11.361454,0.481053,-306.562714,0.049059,0.000000
45.040001,50.818039,-306.607208,0.011046,0.001907,0.048443,226.049927,11.515532,0.484432,-306.607208,0.049380,0.000000
45.230003,51.138283,-306.696167,0.011068,0.001917,0.048695,227.474442,11.588100,0.486949,-306.696167,0.049692,0.000000
45.420002,51.597046,-306.562714,0.011055,0.001927,0.048946,229.515121,11.692058,0.489463,-306.562714,0.050013,0.000000
45.610001,52.778580,-306.696167,0.011072,0.001941,0.049311,234.770844,11.959797,0.493107,-306.696167,0.050325,0.000000
45.800003,53.654404,-306.651672,0.011089,0.001956,0.049675,238.666702,12.158262,0.496749,-306.651672,0.050646,0.000000
45.990002,53.958260,-306.696167,0.011089,0.001962,0.049839,240.018326,12.227117,0.498395,-306.696167,0.050958,0.000000
46.180000,54.836685,-306.651672,0.011089,0.001977,0.050204,243.925751,12.426170,0.502040,-306.651672,0.051279,0.000000
46.370003,56.564117,-306.740631,0.011089,0.002000,0.050794,251.609756,12.817612,0.507937,-306.740631,0.051592,0.000000
46.560001,57.498032,-306.740631,0.011102,0.002013,0.051132,255.764023,13.029241,0.511317,-306.740631,0.051912,0.000000
46.750004,58.017487,-306.740631,0.011106,0.002023,0.051392,258.074677,13.146951,0.513921,-306.740631,0.052224,0.000000
46.940002,58.276291,-306.696167,0.011111,0.002032,0.051617,259.225891,13.205596,0.516173,-306.696167,0.052545,0.000000
47.130001,58.670631,-306.785126,0.011111,0.002041,0.051843,260.980011,13.294954,0.518428,-306.785126,0.052858,0.000000
47.320004,59.642899,-306.740631,0.011111,0.002054,0.052164,265.304871,13.515274,0.521638,-306.740631,0.053179,0.000000
47.510002,60.271461,-306.740631,0.011124,0.002067,0.052493,268.100861,13.657708,0.524935,-306.740631,0.053491,0.000000
47.700001,61.301445,-306.829590,0.011128,0.002077,0.052762,272.682434,13.891106,0.527622,-306.829590,0.053811,0.000000
47.890003,61.682755,-306.829590,0.011132,0.002084,0.052936,274.378601,13.977512,0.529355,-306.829590,0.054124,0.000000
48.080002,62.699326,-306.785126,0.011141,0.002099,0.053317,278.900543,14.207870,0.533171,-306.785126,0.054445,0.000000
48.270000,64.207436,-306.829590,0.011145,0.002120,0.053837,285.608948,14.549613,0.538375,-306.829590,0.054757,0.000000
48.460003,65.840294,-306.829590,0.011158,0.002137,0.054288,292.872253,14.919623,0.542883,-306.829590,0.055078,0.000000
48.650002,66.549294,-306.918549,0.011158,0.002148,0.054566,296.026031,15.080285,0.545661,-306.918549,0.055390,0.000000
48.840004,66.958900,-306.874084,0.011171,0.002156,0.054774,297.848053,15.173104,0.547742,-306.874084,0.055711,0.000000
49.030003,67.340202,-307.007538,0.011184,0.002156,0.054757,299.544189,15.259508,0.547568,-307.007538,0.054974,0.000000
49.220001,66.916451,-306.874084,0.011188,0.002156,0.054757,297.659241,15.163485,0.547568,-306.874084,0.054974,0.000000
49.410004,66.579079,-306.963043,0.011180,0.002155,0.054748,296.158539,15.087035,0.547481,-306.963043,0.054757,0.000000
49.600002,66.274101,-306.874084,0.011188,0.002155,0.054731,294.801941,15.017926,0.547307,-306.874084,0.054757,0.000000
49.790001,66.031685,-306.963043,0.011175,0.002155,0.054731,293.723602,14.962994,0.547307,-306.963043,0.054757,0.000000
49.980003,65.812355,-307.007538,0.011197,0.002154,0.054722,292.747986,14.913293,0.547220,-307.007538,0.054757,0.000000
50.170002,65.622078,-306.963043,0.011188,0.002154,0.054722,291.901581,14.870175,0.547220,-306.963043,0.054757,0.000000
50.360001,65.466423,-307.052002,0.011184,0.002154,0.054722,291.209198,14.834903,0.547220,-307.052002,0.054757,0.000000
50.550003,65.304451,-307.007538,0.011188,0.002154,0.054722,290.488708,14.798200,0.547220,-307.007538,0.054757,0.000000
50.740002,65.184166,-307.007538,0.011175,0.002154,0.054713,289.953644,14.770943,0.547133,-307.007538,0.054757,0.000000
50.930004,65.067619,-307.096497,0.011188,0.002154,0.054713,289.435211,14.744533,0.547133,-307.096497,0.054757,0.000000
51.120003,64.945107,-307.052002,0.011184,0.002154,0.054713,288.890259,14.716771,0.547133,-307.052002,0.054757,0.000000
51.310001,64.833397,-307.052002,0.011201,0.002154,0.054713,288.393341,14.691458,0.547133,-307.052002,0.054757,0.000000
51.500004,64.738075,-307.096497,0.011188,0.002154,0.054713,287.969330,14.669857,0.547133,-307.096497,0.054757,0.000000
51.690002,64.663216,-307.096497,0.011201,0.002154,0.054713,287.636353,14.652894,0.547133,-307.096497,0.054757,0.000000
51.880001,64.585030,-307.140961,0.011206,0.002154,0.054713,287.288574,14.635177,0.547133,-307.140961,0.054757,0.000000
52.070004,64.500114,-307.140961,0.011197,0.002154,0.054713,286.910828,14.615934,0.547133,-307.140961,0.054757,0.000000
52.260002,64.413353,-307.274414,0.011193,0.002154,0.054713,286.524902,14.596274,0.547133,-307.274414,0.054757,0.000000
52.450001,64.349678,-307.140961,0.011188,0.002154,0.054713,286.241669,14.581845,0.547133,-307.140961,0.054757,0.000000
52.640003,64.292336,-307.140961,0.011184,0.002154,0.054713,285.986603,14.568851,0.547133,-307.140961,0.054757,0.000000
52.830002,64.218605,-307.229919,0.011214,0.002154,0.054713,285.658630,14.552144,0.547133,-307.229919,0.054757,0.000000
53.020004,64.159035,-307.185455,0.011193,0.002154,0.054713,285.393646,14.538646,0.547133,-307.185455,0.054757,0.000000
53.210003,64.100945,-307.229919,0.011188,0.002154,0.054713,285.135254,14.525481,0.547133,-307.229919,0.054757,0.000000
53.400002,64.059608,-307.274414,0.011201,0.002154,0.054713,284.951355,14.516114,0.547133,-307.274414,0.054757,0.000000
53.590004,63.992577,-307.318878,0.011193,0.002154,0.054713,284.653198,14.500925,0.547133,-307.318878,0.054757,0.000000
53.780003,63.947517,-307.318878,0.011197,0.002154,0.054713,284.452759,14.490714,0.547133,-307.318878,0.054757,0.000000
53.970001,63.912514,-307.229919,0.011193,0.002154,0.054713,284.297058,14.482782,0.547133,-307.229919,0.054757,0.000000
54.160004,63.860390,-307.274414,0.011206,0.002154,0.054705,284.065186,14.470971,0.547046,-307.274414,0.054757,0.000000
54.350002,63.807503,-307.318878,0.011206,0.002154,0.054705,283.829956,14.458987,0.547046,-307.318878,0.054757,0.000000
54.540001,63.763191,-307.363373,0.011197,0.002154,0.054705,283.632843,14.448945,0.547046,-307.363373,0.054757,0.000000
54.730003,63.717400,-307.407867,0.011206,0.002154,0.054705,283.429138,14.438569,0.547046,-307.407867,0.054757,0.000000
54.920002,63.687599,-307.318878,0.011188,0.002154,0.054705,283.296600,14.431816,0.547046,-307.318878,0.054757,0.000000
55.110004,63.649620,-307.407867,0.011201,0.002154,0.054705,283.127655,14.423210,0.547046,-307.407867,0.054757,0.000000
55.300003,63.615364,-307.363373,0.011206,0.002154,0.054705,282.975281,14.415448,0.547046,-307.363373,0.054757,0.000000
55.490002,63.585945,-307.452332,0.011188,0.002154,0.054705,282.844421,14.408782,0.547046,-307.452332,0.054757,0.000000
55.680004,63.549461,-307.452332,0.011206,0.002154,0.054705,282.682129,14.400514,0.547046,-307.452332,0.054757,0.000000
55.870003,63.502541,-307.407867,0.011193,0.002154,0.054705,282.473419,14.389881,0.547046,-307.407867,0.054757,0.000000
56.060001,63.473122,-307.541290,0.011188,0.002154,0.054705,282.342560,14.383215,0.547046,-307.541290,0.054757,0.000000
56.250004,63.443703,-307.407867,0.011206,0.002154,0.054705,282.211670,14.376549,0.547046,-307.407867,0.054757,0.000000
56.440002,63.422844,-307.496826,0.011193,0.002154,0.054705,282.118896,14.371821,0.547046,-307.496826,0.054757,0.000000
56.630001,63.385612,-307.496826,0.011210,0.002154,0.054705,281.953278,14.363385,0.547046,-307.496826,0.054757,0.000000
56.820004,63.348381,-307.496826,0.011197,0.002154,0.054705,281.787659,14.354948,0.547046,-307.496826,0.054757,0.000000
57.010002,63.332741,-307.585785,0.011214,0.002154,0.054705,281.718109,14.351404,0.547046,-307.585785,0.054757,0.000000
57.200005,63.303688,-307.541290,0.011206,0.002154,0.054705,281.588867,14.344820,0.547046,-307.541290,0.054757,0.000000
57.390003,63.271294,-307.541290,0.011219,0.002154,0.054705,281.444763,14.337480,0.547046,-307.541290,0.054757,0.000000
57.580002,63.240761,-307.630249,0.011201,0.002154,0.054705,281.308960,14.330561,0.547046,-307.630249,0.054757,0.000000
57.770004,63.210228,-307.585785,0.011197,0.002154,0.054705,281.173126,14.323643,0.547046,-307.585785,0.054757,0.000000
57.960003,63.198311,-307.674744,0.011201,0.002154,0.054705,281.120117,14.320942,0.547046,-307.674744,0.054757,0.000000
58.150002,63.168144,-307.585785,0.011206,0.002154,0.054705,280.985931,14.314106,0.547046,-307.585785,0.054757,0.000000
58.340004,63.137978,-307.585785,0.011206,0.002154,0.054705,280.851746,14.307270,0.547046,-307.585785,0.054757,0.000000
58.530003,63.120110,-307.719208,0.011210,0.002154,0.054705,280.772278,14.303222,0.547046,-307.719208,0.054757,0.000000
58.720001,63.092934,-307.630249,0.011206,0.002154,0.054705,280.651398,14.297064,0.547046,-307.630249,0.054757,0.000000
58.910004,63.069832,-307.630249,0.011197,0.002154,0.054705,280.548615,14.291828,0.547046,-307.630249,0.054757,0.000000
59.100002,63.052711,-307.674744,0.011210,0.002154,0.054705,280.472473,14.287949,0.547046,-307.674744,0.054757,0.000000
59.290001,63.027016,-307.674744,0.011214,0.002154,0.054705,280.358154,14.282125,0.547046,-307.674744,0.054757,0.000000
59.480003,63.005043,-307.719208,0.011197,0.002154,0.054705,280.260437,14.277146,0.547046,-307.719208,0.054757,0.000000
59.670002,62.988663,-307.719208,0.011206,0.002154,0.054705,280.187561,14.273435,0.547046,-307.719208,0.054757,0.000000
59.860004,62.964088,-307.808167,0.011206,0.002154,0.054705,280.078247,14.267866,0.547046,-307.808167,0.054757,0.000000
60.050003,62.935043,-307.719208,0.011206,0.002154,0.054705,279.949066,14.261285,0.547046,-307.719208,0.054757,0.000000
60.240002,62.928337,-307.763702,0.011206,0.002154,0.054705,279.919220,14.259765,0.547046,-307.763702,0.054757,0.000000
60.430004,62.902275,-307.763702,0.011214,0.002154,0.054705,279.803284,14.253860,0.547046,-307.763702,0.054757,0.000000
60.620003,62.888863,-307.808167,0.011210,0.002154,0.054705,279.743622,14.250820,0.547046,-307.808167,0.054757,0.000000
60.810001,62.876205,-307.808167,0.011197,0.002154,0.054705,279.687317,14.247952,0.547046,-307.808167,0.054757,0.000000
61.000004,62.837105,-307.852661,0.011219,0.002154,0.054705,279.513397,14.239092,0.547046,-307.852661,0.054757,0.000000
61.190002,62.816628,-307.897156,0.011197,0.002154,0.054705,279.422302,14.234451,0.547046,-307.897156,0.054757,0.000000
61.380001,62.804337,-307.852661,0.011214,0.002154,0.054705,279.367645,14.231667,0.547046,-307.852661,0.054757,0.000000
61.570004,62.786461,-307.852661,0.011210,0.002154,0.054705,279.288116,14.227615,0.547046,-307.852661,0.054757,0.000000
61.760002,62.772316,-307.897156,0.011210,0.002154,0.054705,279.225220,14.224410,0.547046,-307.897156,0.054757,0.000000
61.950005,62.758163,-307.897156,0.011206,0.002154,0.054705,279.162262,14.221204,0.547046,-307.897156,0.054757,0.000000
62.140003,62.732841,-307.897156,0.011201,0.002154,0.054705,279.049622,14.215465,0.547046,-307.897156,0.054757,0.000000
62.330002,62.727257,-307.941620,0.011201,0.002154,0.054705,279.024780,14.214199,0.547046,-307.941620,0.054757,0.000000
62.520004,62.699699,-307.941620,0.011201,0.002154,0.054705,278.902191,14.207955,0.547046,-307.941620,0.054757,0.000000
62.710003,62.676613,-307.986115,0.011206,0.002154,0.054705,278.799500,14.202724,0.547046,-307.986115,0.054757,0.000000
62.900002,62.662834,-307.986115,0.011206,0.002154,0.054705,278.738220,14.199601,0.547046,-307.986115,0.054757,0.000000
63.090004,62.652039,-307.941620,0.011219,0.002154,0.054705,278.690186,14.197155,0.547046,-307.941620,0.054757,0.000000
63.280003,62.634537,-308.075073,0.011206,0.002154,0.054705,278.612335,14.193190,0.547046,-308.075073,0.054757,0.000000
63.470001,62.619270,-308.030579,0.011201,0.002154,0.054705,278.544434,14.189730,0.547046,-308.030579,0.054757,0.000000
63.660004,62.614052,-308.075073,0.011201,0.002154,0.054705,278.521210,14.188546,0.547046,-308.075073,0.054757,0.000000
63.850002,62.589478,-308.075073,0.011210,0.002154,0.054705,278.411896,14.182979,0.547046,-308.075073,0.054757,0.000000
64.040001,62.568253,-308.030579,0.011201,0.002154,0.054705,278.317474,14.178169,0.547046,-308.030579,0.054757,0.000000
64.230003,62.546280,-308.164032,0.011193,0.002154,0.054705,278.219757,14.173189,0.547046,-308.164032,0.054757,0.000000
64.420006,62.541443,-308.119537,0.011210,0.002154,0.054705,278.198242,14.172093,0.547046,-308.119537,0.054757,0.000000
64.610001,62.542931,-308.119537,0.011210,0.002154,0.054705,278.204865,14.172430,0.547046,-308.119537,0.054757,0.000000
64.800003,62.515373,-308.164032,0.011214,0.002154,0.054705,278.082275,14.166186,0.547046,-308.164032,0.054757,0.000000
64.990005,62.496384,-308.075073,0.011219,0.002154,0.054705,277.997803,14.161883,0.547046,-308.075073,0.054757,0.000000
65.180000,62.502716,-308.164032,0.011206,0.002154,0.054705,278.025970,14.163318,0.547046,-308.164032,0.054757,0.000000
65.370003,62.484100,-308.119537,0.011223,0.002154,0.054705,277.943146,14.159100,0.547046,-308.119537,0.054757,0.000000
65.560005,62.467339,-308.164032,0.011201,0.002154,0.054705,277.868591,14.155301,0.547046,-308.164032,0.054757,0.000000
65.750000,62.443138,-308.252991,0.011210,0.002154,0.054705,277.760956,14.149817,0.547046,-308.252991,0.054757,0.000000
65.940002,62.441277,-308.208496,0.011206,0.002154,0.054705,277.752655,14.149396,0.547046,-308.208496,0.054757,0.000000
66.130005,62.433083,-308.252991,0.011210,0.002154,0.054705,277.716217,14.147538,0.547046,-308.252991,0.054757,0.000000
66.320000,62.410370,-308.252991,0.011201,0.002154,0.054705,277.615204,14.142392,0.547046,-308.252991,0.054757,0.000000
66.510002,62.404037,-308.297485,0.011214,0.002154,0.054705,277.587036,14.140958,0.547046,-308.297485,0.054757,0.000000
66.700005,62.385788,-308.341949,0.011206,0.002154,0.054705,277.505859,14.136822,0.547046,-308.341949,0.054757,0.000000
66.889999,62.374992,-308.341949,0.011223,0.002154,0.054705,277.457825,14.134376,0.547046,-308.341949,0.054757,0.000000
67.080002,62.357491,-308.341949,0.011206,0.002154,0.054705,277.379974,14.130409,0.547046,-308.341949,0.054757,0.000000
67.270004,62.357864,-308.341949,0.011197,0.002154,0.054705,277.381622,14.130493,0.547046,-308.341949,0.054757,0.000000
67.460007,62.340736,-308.341949,0.011214,0.002154,0.054705,277.305450,14.126613,0.547046,-308.341949,0.054757,0.000000
67.650002,62.322861,-308.386444,0.011210,0.002154,0.054705,277.225922,14.122561,0.547046,-308.386444,0.054757,0.000000
67.840004,62.318764,-308.386444,0.011219,0.002154,0.054705,277.207703,14.121634,0.547046,-308.386444,0.054757,0.000000
68.030006,62.304611,-308.430908,0.011201,0.002154,0.054705,277.144745,14.118426,0.547046,-308.430908,0.054757,0.000000
68.220001,62.293816,-308.475403,0.011219,0.002154,0.054705,277.096741,14.115980,0.547046,-308.475403,0.054757,0.000000
68.410004,62.289719,-308.386444,0.011201,0.002154,0.054705,277.078522,14.115052,0.547046,-308.386444,0.054757,0.000000
68.600006,62.271469,-308.475403,0.011201,0.002154,0.054705,276.997314,14.110917,0.547046,-308.475403,0.054757,0.000000
68.790001,62.258812,-308.430908,0.011223,0.002154,0.054705,276.941040,14.108048,0.547046,-308.430908,0.054757,0.000000
68.980003,62.251740,-308.519867,0.011206,0.002154,0.054705,276.909576,14.106446,0.547046,-308.519867,0.054757,0.000000
69.170006,62.223061,-308.564362,0.011206,0.002154,0.054705,276.781982,14.099947,0.547046,-308.564362,0.054757,0.000000
69.360001,62.218971,-308.430908,0.011206,0.002154,0.054705,276.763794,14.099021,0.547046,-308.430908,0.054757,0.000000
69.550003,62.218971,-308.475403,0.011214,0.002154,0.054705,276.763794,14.099021,0.547046,-308.475403,0.054757,0.000000
69.740005,62.211891,-308.564362,0.011206,0.002154,0.054705,276.732300,14.097416,0.547046,-308.564362,0.054757,0.000000
69.930000,62.208916,-308.475403,0.011214,0.002154,0.054705,276.719086,14.096742,0.547046,-308.475403,0.054757,0.000000
70.120003,62.202583,-308.564362,0.011227,0.002154,0.054705,276.690918,14.095306,0.547046,-308.564362,0.054757,0.000000
70.310005,62.189178,-308.519867,0.011210,0.002154,0.054705,276.631287,14.092269,0.547046,-308.519867,0.054757,0.000000
70.500000,62.169815,-308.564362,0.011201,0.002154,0.054705,276.545135,14.087881,0.547046,-308.564362,0.054757,0.000000
70.690002,62.161247,-308.608826,0.011223,0.002154,0.054705,276.507050,14.085939,0.547046,-308.608826,0.054757,0.000000
70.880005,62.157524,-308.653320,0.011201,0.002154,0.054705,276.490479,14.085096,0.547046,-308.653320,0.054757,0.000000
71.070000,62.159019,-308.697815,0.011214,0.002154,0.054705,276.497131,14.085435,0.547046,-308.697815,0.054757,0.000000
71.260002,62.135559,-308.653320,0.011227,0.002154,0.054705,276.392761,14.080119,0.547046,-308.653320,0.054757,0.000000
71.450005,62.112099,-308.697815,0.011193,0.002154,0.054705,276.288422,14.074803,0.547046,-308.697815,0.054757,0.000000
71.640007,62.112839,-308.653320,0.011214,0.002154,0.054705,276.291718,14.074970,0.547046,-308.653320,0.054757,0.000000
71.830002,62.111351,-308.697815,0.011214,0.002154,0.054705,276.285095,14.074634,0.547046,-308.697815,0.054757,0.000000
72.020004,62.087891,-308.742279,0.011223,0.002154,0.054705,276.180725,14.069317,0.547046,-308.742279,0.054757,0.000000
72.210007,62.088638,-308.742279,0.011223,0.002154,0.054705,276.184052,14.069487,0.547046,-308.742279,0.054757,0.000000
72.400002,62.080444,-308.786774,0.011201,0.002154,0.054705,276.147614,14.067629,0.547046,-308.786774,0.054757,0.000000
72.590004,62.080818,-308.742279,0.011210,0.002154,0.054705,276.149261,14.067715,0.547046,-308.742279,0.054757,0.000000
72.780006,62.073372,-308.786774,0.011206,0.002154,0.054705,276.116150,14.066027,0.547046,-308.786774,0.054757,0.000000
72.970001,62.059219,-308.831238,0.011210,0.002154,0.054705,276.053192,14.062820,0.547046,-308.831238,0.054757,0.000000
73.160004,62.055870,-308.831238,0.011210,0.002154,0.054705,276.038300,14.062061,0.547046,-308.831238,0.054757,0.000000
73.350006,62.046188,-308.831238,0.011214,0.002154,0.054705,275.995239,14.059867,0.547046,-308.831238,0.054757,0.000000
73.540001,62.030548,-308.786774,0.011210,0.002154,0.054705,275.925659,14.056323,0.547046,-308.786774,0.054757,0.000000
73.730003,62.016022,-308.875732,0.011197,0.002154,0.054705,275.861053,14.053031,0.547046,-308.875732,0.054757,0.000000
73.920006,62.007835,-308.920197,0.011206,0.002154,0.054705,275.824615,14.051176,0.547046,-308.920197,0.054757,0.000000
74.110001,62.009323,-308.786774,0.011206,0.002154,0.054705,275.831238,14.051514,0.547046,-308.786774,0.054757,0.000000
74.300003,61.988838,-308.920197,0.011210,0.002154,0.054705,275.740112,14.046871,0.547046,-308.920197,0.054757,0.000000
74.490005,61.986610,-308.920197,0.011201,0.002154,0.054705,275.730225,14.046367,0.547046,-308.920197,0.054757,0.000000
74.680000,61.984001,-308.964691,0.011219,0.002154,0.054705,275.718597,14.045775,0.547046,-308.964691,0.054757,0.000000
74.870003,61.973206,-309.009155,0.011210,0.002154,0.054705,275.670593,14.043329,0.547046,-309.009155,0.054757,0.000000
75.060005,61.976555,-308.964691,0.011223,0.002154,0.054705,275.685486,14.044088,0.547046,-308.964691,0.054757,0.000000
75.250000,61.963890,-308.964691,0.011206,0.002154,0.054705,275.629150,14.041219,0.547046,-308.964691,0.054757,0.000000
75.440002,61.948997,-308.964691,0.011210,0.002154,0.054705,275.562897,14.037843,0.547046,-308.964691,0.054757,0.000000
75.630005,61.936707,-309.009155,0.011214,0.002154,0.054705,275.508240,14.035059,0.547046,-309.009155,0.054757,0.000000
75.820007,61.934479,-309.098114,0.011214,0.002154,0.054705,275.498322,14.034554,0.547046,-309.098114,0.054757,0.000000
76.010002,61.930008,-309.098114,0.011214,0.002154,0.054705,275.478424,14.033541,0.547046,-309.098114,0.054757,0.000000
76.200005,61.919579,-309.009155,0.011214,0.002154,0.054705,275.432037,14.031177,0.547046,-309.009155,0.054757,0.000000
76.390007,61.907661,-309.053650,0.011219,0.002154,0.054705,275.379028,14.028477,0.547046,-309.053650,0.054757,0.000000
76.580002,61.914742,-309.053650,0.011206,0.002154,0.054705,275.410522,14.030081,0.547046,-309.053650,0.054757,0.000000
76.770004,61.894630,-309.187103,0.011206,0.002154,0.054705,275.321075,14.025523,0.547046,-309.187103,0.054757,0.000000
76.960007,61.886810,-309.142609,0.011210,0.002154,0.054705,275.286285,14.023751,0.547046,-309.142609,0.054757,0.000000
77.150002,61.887932,-309.053650,0.011214,0.002154,0.054705,275.291260,14.024006,0.547046,-309.053650,0.054757,0.000000
77.340004,61.880852,-309.142609,0.011201,0.002154,0.054705,275.259766,14.022402,0.547046,-309.142609,0.054757,0.000000
77.530006,61.863350,-309.142609,0.011206,0.002154,0.054705,275.181915,14.018435,0.547046,-309.142609,0.054757,0.000000
77.720001,61.866333,-309.187103,0.011214,0.002154,0.054705,275.195190,14.019112,0.547046,-309.187103,0.054757,0.000000
77.910004,61.866707,-309.142609,0.011210,0.002154,0.054705,275.196869,14.019196,0.547046,-309.142609,0.054757,0.000000
78.100006,61.848831,-309.187103,0.011206,0.002154,0.054705,275.117340,14.015145,0.547046,-309.187103,0.054757,0.000000
78.290001,61.839523,-309.231567,0.011214,0.002154,0.054705,275.075928,14.013036,0.547046,-309.231567,0.054757,0.000000
78.480003,61.835426,-309.142609,0.011206,0.002154,0.054705,275.057709,14.012108,0.547046,-309.142609,0.054757,0.000000
78.670006,61.831703,-309.276062,0.011197,0.002154,0.054705,275.041138,14.011264,0.547046,-309.276062,0.054757,0.000000
78.860001,61.822021,-309.276062,0.011210,0.002154,0.054705,274.998077,14.009069,0.547046,-309.276062,0.054757,0.000000
79.050003,61.824257,-309.320526,0.011214,0.002154,0.054705,275.008026,14.009577,0.547046,-309.320526,0.054757,0.000000
79.240005,61.818298,-309.276062,0.011214,0.002154,0.054705,274.981537,14.008226,0.547046,-309.276062,0.054757,0.000000
79.400002,61.813454,-309.276062,0.011223,0.002154,0.054705,274.959961,14.007129,0.547046,-309.276062,0.054757,0.000000