File: Data/AG AL compression 300N/AG membrane Unpeeled 300N_1_3_03192024_182705.csv
Time (sec),S:Load (lbs),S:HL1 (DIM),S:LVDT (in),S:Position (in),Ch:Position (mm),Ch:Load (N),Ch:Stress (MPa),Ch:Strain (mm/mm),Ch:HL1 (DIM),Set Point (),Cycles ()
0.110000,0.006332,-276.137756,0.000013,-0.000000,-0.000000,0.028168,0.001435,-0.000000,-276.137756,0.000208,0.000000
0.320000,0.006706,-276.137756,0.000013,-0.000000,-0.000000,0.029831,0.001520,-0.000000,-276.137756,0.000208,0.000000
0.530000,-0.001862,-276.137756,0.000000,0.000100,0.002550,-0.008281,-0.000422,0.025499,-276.137756,0.003296,0.000000
0.740000,0.007820,-276.048767,0.000082,0.000231,0.005880,0.034786,0.001772,0.058798,-276.048767,0.006799,0.000000
0.950000,-0.008560,-276.226715,0.000233,0.000366,0.009288,-0.038078,-0.001940,0.092881,-276.226715,0.010303,0.000000
1.160000,-0.061440,-276.137756,0.000366,0.000501,0.012713,-0.273297,-0.013922,0.127135,-276.137756,0.013789,0.000000
1.370000,-0.057716,-276.137756,0.000492,0.000638,0.016217,-0.256735,-0.013079,0.162171,-276.137756,0.017292,0.000000
1.580000,-0.002602,-276.226715,0.000647,0.000776,0.019703,-0.011573,-0.000590,0.197034,-276.226715,0.020796,0.000000
1.790000,-0.007072,-276.226715,0.000802,0.000914,0.023224,-0.031460,-0.001603,0.232245,-276.226715,0.024282,0.000000
2.000000,0.006706,-276.226715,0.000910,0.001054,0.026771,0.029831,0.001520,0.267713,-276.226715,0.027786,0.000000
2.210000,0.005592,-276.315674,0.001074,0.001192,0.030266,0.024876,0.001267,0.302663,-276.315674,0.031290,0.000000
2.420000,0.023460,-276.271179,0.001216,0.001325,0.033648,0.104357,0.005316,0.336485,-276.271179,0.034793,0.000000
2.630000,0.030540,-276.315674,0.001350,0.001459,0.037065,0.135851,0.006921,0.370655,-276.315674,0.038279,0.000000
2.840000,0.015274,-276.271179,0.001509,0.001602,0.040699,0.067942,0.003461,0.406990,-276.271179,0.041783,0.000000
3.050000,0.001495,-276.315674,0.001638,0.001743,0.044272,0.006652,0.000339,0.442719,-276.315674,0.045287,0.000000
3.260000,-0.007820,-276.404633,0.001772,0.001881,0.047767,-0.034786,-0.001772,0.477669,-276.404633,0.048773,0.000000
3.470000,-0.001862,-276.360138,0.001919,0.002020,0.051314,-0.008281,-0.000422,0.513137,-276.360138,0.052277,0.000000
3.680000,-0.009682,-276.404633,0.002048,0.002154,0.054705,-0.043066,-0.002194,0.547046,-276.404633,0.055780,0.000000
3.890000,-0.015266,-276.404633,0.002195,0.002291,0.058182,-0.067908,-0.003459,0.581822,-276.404633,0.059284,0.000000
4.100000,-0.004837,-276.360138,0.002333,0.002430,0.061721,-0.021516,-0.001096,0.617207,-276.360138,0.062770,0.000000
4.310000,0.021599,-276.493591,0.002453,0.002566,0.065172,0.096076,0.004894,0.651721,-276.493591,0.066274,0.000000
4.520000,0.021599,-276.449097,0.002613,0.002708,0.068780,0.096076,0.004894,0.687799,-276.449097,0.069777,0.000000
4.730000,0.010429,-276.538086,0.002734,0.002841,0.072162,0.046392,0.002363,0.721621,-276.538086,0.073263,0.000000
4.940000,0.023834,-276.493591,0.002884,0.002975,0.075570,0.106020,0.005401,0.755700,-276.493591,0.076767,0.000000
5.150000,0.024956,-276.493591,0.003031,0.003115,0.079117,0.111009,0.005655,0.791172,-276.493591,0.080270,0.000000
5.360000,0.007080,-276.582550,0.003147,0.003249,0.082517,0.031494,0.001604,0.825168,-276.582550,0.083774,0.000000
5.570000,-0.001488,-276.538086,0.003303,0.003392,0.086159,-0.006618,-0.000337,0.861590,-276.538086,0.087260,0.000000
5.780000,0.027931,-276.627045,0.003449,0.003532,0.089723,0.124244,0.006329,0.897232,-276.627045,0.090764,0.000000
5.990000,0.016014,-276.538086,0.003574,0.003672,0.093270,0.071234,0.003629,0.932700,-276.538086,0.094267,0.000000
6.200000,-0.001114,-276.538086,0.003721,0.003807,0.096704,-0.004955,-0.000252,0.967044,-276.538086,0.097754,0.000000
6.410000,0.003731,-276.582550,0.003867,0.003944,0.100173,0.016595,0.000845,1.001733,-276.582550,0.101257,0.000000
6.620000,0.024582,-276.671509,0.003992,0.004081,0.103668,0.109346,0.005570,1.036683,-276.671509,0.104761,0.000000
6.830000,0.011543,-276.716003,0.004148,0.004218,0.107146,0.051347,0.002616,1.071458,-276.716003,0.108265,0.000000
7.040000,0.014900,-276.716003,0.004286,0.004359,0.110727,0.066279,0.003376,1.107275,-276.716003,0.111751,0.000000
7.250000,0.013405,-276.716003,0.004415,0.004496,0.114196,0.059628,0.003038,1.141963,-276.716003,0.115254,0.000000
7.460001,0.024582,-276.671509,0.004536,0.004630,0.117596,0.109346,0.005570,1.175959,-276.671509,0.118758,0.000000
7.670001,0.027184,-276.716003,0.004665,0.004766,0.121056,0.120918,0.006160,1.210561,-276.716003,0.122244,0.000000
7.880001,0.039101,-276.716003,0.004820,0.004903,0.124525,0.173928,0.008860,1.245249,-276.716003,0.125748,0.000000
8.090000,0.034637,-276.804962,0.004954,0.005049,0.128245,0.154075,0.007849,1.282455,-276.804962,0.129252,0.000000
8.300000,0.058090,-276.760468,0.005096,0.005189,0.131801,0.258398,0.013163,1.318010,-276.760468,0.132738,0.000000
8.510000,0.041710,-276.804962,0.005251,0.005324,0.135227,0.185535,0.009452,1.352267,-276.804962,0.136241,0.000000
8.720000,0.026070,-276.804962,0.005372,0.005460,0.138696,0.115964,0.005907,1.386956,-276.804962,0.139745,0.000000
8.930000,0.008194,-276.893921,0.005532,0.005598,0.142199,0.036449,0.001857,1.421993,-276.893921,0.143248,0.000000
9.140000,0.011543,-276.849426,0.005648,0.005735,0.145668,0.051347,0.002616,1.456681,-276.849426,0.146735,0.000000
9.350000,0.011917,-276.849426,0.005786,0.005869,0.149076,0.053010,0.002700,1.490760,-276.849426,0.150238,0.000000
9.560000,0.028305,-276.893921,0.005902,0.006008,0.152615,0.125907,0.006414,1.526145,-276.893921,0.153742,0.000000
9.770000,0.020111,-276.849426,0.006053,0.006146,0.156109,0.089459,0.004557,1.561095,-276.849426,0.157228,0.000000
9.980000,0.056229,-276.893921,0.006217,0.006283,0.159578,0.250117,0.012742,1.595784,-276.893921,0.160732,0.000000
10.190001,0.062187,-276.982880,0.006351,0.006423,0.163143,0.276622,0.014092,1.631426,-276.982880,0.164235,0.000000
10.400001,0.054001,-276.938416,0.006485,0.006564,0.166724,0.240208,0.012237,1.667242,-276.938416,0.167739,0.000000
10.610001,0.066658,-276.938416,0.006635,0.006702,0.170228,0.296510,0.015105,1.702279,-276.938416,0.171225,0.000000
10.820001,0.045433,-276.938416,0.006773,0.006837,0.173671,0.202096,0.010295,1.736707,-276.938416,0.174729,0.000000
11.030001,0.044685,-276.982880,0.006890,0.006978,0.177235,0.198770,0.010126,1.772349,-276.982880,0.178232,0.000000
11.240001,0.015274,-277.027374,0.007041,0.007113,0.180661,0.067942,0.003461,1.806606,-277.027374,0.181718,0.000000
11.450001,0.007454,-277.027374,0.007166,0.007248,0.184095,0.033157,0.001689,1.840946,-277.027374,0.185222,0.000000
11.660001,-0.001488,-277.116333,0.007312,0.007383,0.187538,-0.006618,-0.000337,1.875378,-277.116333,0.188726,0.000000
11.870001,-0.009308,-277.071838,0.007437,0.007523,0.191093,-0.041403,-0.002109,1.910933,-277.071838,0.192230,0.000000
12.080001,0.024208,-277.071838,0.007593,0.007663,0.194649,0.107683,0.005486,1.946488,-277.071838,0.195715,0.000000
12.290001,0.049530,-277.160797,0.007705,0.007802,0.198179,0.220321,0.011224,1.981786,-277.160797,0.199219,0.000000
12.500001,0.063309,-277.116333,0.007869,0.007936,0.201569,0.281611,0.014346,2.015695,-277.116333,0.202723,0.000000
12.710001,0.080437,-277.116333,0.007998,0.008074,0.205090,0.357800,0.018227,2.050902,-277.116333,0.206209,0.000000
12.920001,0.072990,-277.116333,0.008149,0.008210,0.208533,0.324678,0.016540,2.085333,-277.116333,0.209713,0.000000
13.130001,0.050644,-277.249756,0.008278,0.008355,0.212219,0.225275,0.011476,2.122191,-277.249756,0.213216,0.000000
13.340001,0.039101,-277.205292,0.008438,0.008492,0.215688,0.173928,0.008860,2.156879,-277.205292,0.216720,0.000000
13.550000,0.035751,-277.249756,0.008554,0.008629,0.219174,0.159030,0.008101,2.191742,-277.249756,0.220206,0.000000
13.760000,-0.001862,-277.249756,0.008683,0.008763,0.222582,-0.008281,-0.000422,2.225821,-277.249756,0.223710,0.000000
13.970000,-0.009682,-277.294250,0.008817,0.008901,0.226077,-0.043066,-0.002194,2.260771,-277.294250,0.227213,0.000000
14.180000,-0.002602,-277.294250,0.008959,0.009040,0.229607,-0.011573,-0.000590,2.296069,-277.294250,0.230700,0.000000
14.390000,0.047295,-277.383209,0.009102,0.009181,0.233189,0.210377,0.010717,2.331885,-277.383209,0.234203,0.000000
14.600000,0.056602,-277.249756,0.009231,0.009318,0.236683,0.251780,0.012826,2.366835,-277.249756,0.237707,0.000000
14.810000,0.075226,-277.383209,0.009382,0.009454,0.240144,0.334621,0.017046,2.401436,-277.383209,0.241193,0.000000
15.020000,0.078949,-277.294250,0.009524,0.009588,0.243535,0.351183,0.017890,2.435345,-277.294250,0.244696,0.000000
15.230000,0.093468,-277.338715,0.009671,0.009725,0.247012,0.415765,0.021180,2.470121,-277.338715,0.248200,0.000000
15.440001,0.066284,-277.383209,0.009783,0.009866,0.250585,0.294847,0.015020,2.505850,-277.383209,0.251704,0.000000
15.650001,0.056976,-277.338715,0.009916,0.010009,0.254219,0.253443,0.012911,2.542185,-277.338715,0.255190,0.000000
15.860001,0.051392,-277.383209,0.010050,0.010144,0.257653,0.228601,0.011646,2.576530,-277.383209,0.258693,0.000000
16.070002,0.038361,-277.472168,0.010188,0.010283,0.261182,0.170636,0.008693,2.611824,-277.472168,0.262197,0.000000
16.280001,0.017502,-277.427704,0.010326,0.010419,0.264651,0.077852,0.003966,2.646512,-277.427704,0.265683,0.000000
16.490002,0.052879,-277.472168,0.010486,0.010557,0.268137,0.235219,0.011983,2.681375,-277.472168,0.269187,0.000000
16.700001,0.054741,-277.472168,0.010619,0.010694,0.271615,0.243500,0.012404,2.716150,-277.472168,0.272691,0.000000
16.910002,0.045807,-277.472168,0.010753,0.010834,0.275180,0.203759,0.010380,2.751796,-277.472168,0.276194,0.000000
17.120001,0.072243,-277.561127,0.010891,0.010969,0.278605,0.321352,0.016370,2.786050,-277.561127,0.279680,0.000000
17.330000,0.086021,-277.516663,0.011037,0.011111,0.282213,0.382642,0.019493,2.822127,-277.516663,0.283184,0.000000
17.540001,0.079315,-277.605621,0.011180,0.011241,0.285517,0.352812,0.017973,2.855170,-277.605621,0.286688,0.000000
17.750000,0.096451,-277.650085,0.011300,0.011379,0.289038,0.429035,0.021856,2.890377,-277.650085,0.290174,0.000000
17.960001,0.059586,-277.694580,0.011477,0.011518,0.292559,0.265050,0.013502,2.925588,-277.694580,0.293678,0.000000
18.170000,0.050270,-277.650085,0.011615,0.011656,0.296071,0.223612,0.011391,2.960708,-277.650085,0.297181,0.000000
18.380001,0.048782,-277.650085,0.011762,0.011798,0.299670,0.216995,0.011054,2.996698,-277.650085,0.300685,0.000000
18.590000,0.069267,-277.694580,0.011900,0.011935,0.303147,0.308116,0.015696,3.031474,-277.694580,0.304171,0.000000
18.800001,0.055489,-277.694580,0.012051,0.012072,0.306616,0.246826,0.012574,3.066162,-277.694580,0.307674,0.000000
19.010000,0.056976,-277.694580,0.012189,0.012207,0.310051,0.253443,0.012911,3.100507,-277.694580,0.311178,0.000000
19.220001,0.061073,-277.783539,0.012314,0.012346,0.313589,0.271668,0.013839,3.135888,-277.783539,0.314664,0.000000
19.430000,0.077827,-277.694580,0.012439,0.012485,0.317127,0.346194,0.017636,3.171273,-277.694580,0.318168,0.000000
19.640001,0.068146,-277.828033,0.012594,0.012621,0.320570,0.303127,0.015442,3.205700,-277.828033,0.321671,0.000000
19.850000,0.071869,-277.739044,0.012736,0.012759,0.324074,0.319689,0.016286,3.240737,-277.739044,0.325175,0.000000
20.060001,0.088257,-277.739044,0.012874,0.012895,0.327525,0.392586,0.019999,3.275251,-277.739044,0.328661,0.000000
20.270000,0.100540,-277.872498,0.012995,0.013030,0.330960,0.447225,0.022783,3.309595,-277.872498,0.332165,0.000000
20.480001,0.099800,-277.828033,0.013133,0.013169,0.334480,0.443933,0.022615,3.344803,-277.828033,0.335668,0.000000
20.690001,0.140015,-277.916992,0.013262,0.013310,0.338062,0.622816,0.031728,3.380619,-277.916992,0.339155,0.000000
20.900002,0.207413,-277.872498,0.013400,0.013452,0.341678,0.922618,0.047000,3.416784,-277.872498,0.342658,0.000000
21.110001,0.449081,-277.872498,0.013560,0.013590,0.345173,1.997614,0.101763,3.451733,-277.872498,0.346162,0.000000
21.320002,0.652397,-277.916992,0.013624,-0.000004,-0.000095,2.902008,0.147835,-0.000954,-277.916992,0.000121,0.000000
21.530001,0.643837,-277.916992,0.013629,-0.000004,-0.000095,2.863930,0.145896,-0.000954,-277.916992,0.000121,0.000000
21.740002,0.643089,-277.916992,0.013633,-0.000004,-0.000095,2.860604,0.145726,-0.000954,-277.916992,0.000130,0.000000
21.950001,0.648300,-278.005951,0.013624,-0.000004,-0.000095,2.883783,0.146907,-0.000954,-278.005951,0.000477,0.000000
22.160002,0.673256,-277.961456,0.013624,-0.000003,-0.000069,2.994792,0.152562,-0.000693,-277.961456,0.000824,0.000000
22.370001,0.704529,-278.005951,0.013642,0.000007,0.000174,3.133901,0.159649,0.001737,-278.005951,0.001180,0.000000
22.580002,0.823692,-278.005951,0.013633,0.000028,0.000702,3.663966,0.186651,0.007025,-278.005951,0.001526,0.000000
22.790001,0.913063,-278.005951,0.013642,0.000043,0.001101,4.061507,0.206903,0.011014,-278.005951,0.001882,0.000000
23.000002,0.998703,-278.094910,0.013646,0.000056,0.001422,4.442453,0.226309,0.014224,-278.094910,0.002229,0.000000
23.210001,1.031471,-278.094910,0.013676,0.000067,0.001691,4.588213,0.233735,0.016911,-278.094910,0.002576,0.000000
23.420002,1.138344,-278.139374,0.013693,0.000080,0.002021,5.063606,0.257952,0.020208,-278.139374,0.002931,0.000000
23.630001,1.237022,-278.094910,0.013693,0.000094,0.002385,5.502551,0.280313,0.023852,-278.094910,0.003278,0.000000
23.840002,1.352463,-278.183868,0.013698,0.000107,0.002715,6.016055,0.306472,0.027145,-278.183868,0.003625,0.000000
24.050001,1.477203,-278.183868,0.013741,0.000122,0.003087,6.570929,0.334739,0.030873,-278.183868,0.003981,0.000000
24.260000,1.562103,-278.094910,0.013724,0.000131,0.003322,6.948582,0.353978,0.033216,-278.094910,0.004328,0.000000
24.470001,1.661530,-278.183868,0.013732,0.000142,0.003608,7.390852,0.376508,0.036078,-278.183868,0.004674,0.000000
24.680000,1.906921,-278.183868,0.013762,0.000164,0.004163,8.482410,0.432115,0.041630,-278.183868,0.005030,0.000000
24.890001,2.015282,-278.183868,0.013784,0.000174,0.004432,8.964420,0.456669,0.044317,-278.183868,0.005377,0.000000
25.100000,2.216362,-278.272827,0.013767,0.000191,0.004839,9.858871,0.502235,0.048394,-278.272827,0.005733,0.000000
25.310001,2.355263,-278.228363,0.013797,0.000203,0.005160,10.476732,0.533710,0.051603,-278.228363,0.006079,0.000000
25.520000,2.483727,-278.272827,0.013805,0.000214,0.005438,11.048167,0.562820,0.054378,-278.272827,0.006426,0.000000
25.730001,2.790932,-278.272827,0.013810,0.000236,0.005993,12.414684,0.632434,0.059926,-278.272827,0.006782,0.000000
25.940001,3.006538,-278.272827,0.013836,0.000250,0.006340,13.373751,0.681291,0.063397,-278.272827,0.007129,0.000000
26.150002,3.171875,-278.361786,0.013844,0.000258,0.006557,14.109204,0.718757,0.065566,-278.361786,0.007476,0.000000
26.360001,3.328270,-278.361786,0.013862,0.000269,0.006834,14.804884,0.754197,0.068340,-278.361786,0.007831,0.000000
26.570002,3.660049,-278.406281,0.013870,0.000289,0.007346,16.280712,0.829379,0.073457,-278.406281,0.008178,0.000000
26.780001,3.930763,-278.406281,0.013879,0.000304,0.007710,17.484909,0.890724,0.077098,-278.406281,0.008525,0.000000
26.990002,4.199623,-278.361786,0.013900,0.000319,0.008091,18.680857,0.951648,0.080913,-278.361786,0.008880,0.000000
27.200001,4.381706,-278.406281,0.013909,0.000329,0.008360,19.490803,0.992909,0.083601,-278.406281,0.009228,0.000000
27.410002,4.601036,-278.450745,0.013909,0.000340,0.008638,20.466431,1.042610,0.086379,-278.450745,0.009583,0.000000
27.620001,4.804352,-278.450745,0.013926,0.000352,0.008950,21.370825,1.088682,0.089498,-278.450745,0.009930,0.000000
27.830002,5.267960,-278.450745,0.013931,0.000370,0.009410,23.433054,1.193737,0.094096,-278.450745,0.010277,0.000000
28.040001,5.474625,-278.495239,0.013956,0.000381,0.009678,24.352346,1.240568,0.096784,-278.495239,0.010633,0.000000
28.250002,5.677567,-278.584198,0.013965,0.000393,0.009973,25.255077,1.286555,0.099732,-278.584198,0.010979,0.000000
28.460001,6.184364,-278.539703,0.013978,0.000412,0.010459,27.509426,1.401397,0.104588,-278.539703,0.011326,0.000000
28.670002,6.499390,-278.584198,0.013982,0.000426,0.010832,28.910728,1.472783,0.108320,-278.584198,0.011682,0.000000
28.880001,6.838997,-278.584198,0.013991,0.000441,0.011214,30.421377,1.549739,0.112135,-278.584198,0.012029,0.000000
29.090002,7.156258,-278.584198,0.014017,0.000454,0.011534,31.832624,1.621631,0.115345,-278.584198,0.012375,0.000000
29.300001,7.418037,-278.584198,0.014008,0.000465,0.011821,32.997078,1.680951,0.118206,-278.584198,0.012731,0.000000
29.510002,7.790405,-278.584198,0.014034,0.000479,0.012159,34.653454,1.765331,0.121586,-278.584198,0.013078,0.000000
29.720001,8.229431,-278.717651,0.014043,0.000496,0.012610,36.606339,1.864816,0.126098,-278.717651,0.013433,0.000000
29.930002,8.464027,-278.673157,0.014064,0.000506,0.012861,37.649876,1.917976,0.128611,-278.673157,0.013780,0.000000
30.140001,8.794693,-278.673157,0.014068,0.000519,0.013173,39.120747,1.992906,0.131733,-278.673157,0.014127,0.000000
30.350002,9.351021,-278.762115,0.014068,0.000537,0.013642,41.595417,2.118972,0.136415,-278.762115,0.014483,0.000000
30.560001,9.734192,-278.673157,0.014094,0.000552,0.014015,43.299847,2.205800,0.140147,-278.673157,0.014830,0.000000
30.770002,10.022034,-278.762115,0.014112,0.000563,0.014310,44.580231,2.271025,0.143096,-278.762115,0.015177,0.000000
30.980001,10.298340,-278.762115,0.014103,0.000575,0.014604,45.809303,2.333637,0.146044,-278.762115,0.015532,0.000000
31.190001,10.669960,-278.762115,0.014125,0.000588,0.014934,47.462353,2.417847,0.149337,-278.762115,0.015879,0.000000
31.400002,10.862854,-278.851074,0.014120,0.000597,0.015168,48.320389,2.461558,0.151680,-278.851074,0.016226,0.000000
31.610001,11.402420,-278.762115,0.014133,0.000614,0.015602,50.720497,2.583825,0.156017,-278.762115,0.016582,0.000000
31.820002,11.974388,-278.762115,0.014150,0.000632,0.016052,53.264740,2.713435,0.160525,-278.762115,0.016928,0.000000
32.030003,12.199295,-278.851074,0.014159,0.000640,0.016261,54.265175,2.764400,0.162607,-278.851074,0.017275,0.000000
32.240002,12.575394,-278.895569,0.014172,0.000654,0.016599,55.938145,2.849625,0.165990,-278.895569,0.017631,0.000000
32.450001,13.092621,-278.895569,0.014172,0.000671,0.017041,58.238888,2.966830,0.170411,-278.895569,0.017978,0.000000
32.660000,13.596069,-278.895569,0.014206,0.000689,0.017501,60.478336,3.080913,0.175010,-278.895569,0.018333,0.000000
32.870003,13.789330,-278.895569,0.014206,0.000698,0.017726,61.338001,3.124707,0.177262,-278.895569,0.018680,0.000000
33.080002,14.048126,-278.940033,0.014206,0.000713,0.018099,62.489185,3.183351,0.180994,-278.940033,0.019027,0.000000
33.290001,14.493111,-278.895569,0.014232,0.000724,0.018386,64.468575,3.284186,0.183855,-278.895569,0.019383,0.000000
33.500000,15.027092,-279.028992,0.014241,0.000740,0.018801,66.843842,3.405188,0.188015,-279.028992,0.019730,0.000000
33.710003,15.386436,-278.984528,0.014232,0.000754,0.019157,68.442291,3.486616,0.191572,-278.984528,0.020077,0.000000
33.920002,15.829185,-279.028992,0.014258,0.000766,0.019461,70.411736,3.586945,0.194608,-279.028992,0.020432,0.000000
34.130001,16.169907,-279.028992,0.014275,0.000778,0.019764,71.927338,3.664153,0.197643,-279.028992,0.020779,0.000000
34.340000,16.728836,-279.073486,0.014280,0.000796,0.020224,74.413582,3.790808,0.202238,-279.073486,0.021126,0.000000
34.550003,17.172333,-279.073486,0.014293,0.000813,0.020649,76.386353,3.891306,0.206489,-279.073486,0.021482,0.000000
34.760002,17.422569,-279.028992,0.014319,0.000825,0.020944,77.499458,3.948011,0.209437,-279.028992,0.021828,0.000000
34.970001,17.700356,-279.073486,0.014310,0.000837,0.021256,78.735115,4.010958,0.212560,-279.073486,0.022184,0.000000
35.180000,17.949844,-279.162445,0.014319,0.000849,0.021568,79.844894,4.067493,0.215682,-279.162445,0.022531,0.000000
35.390003,18.471542,-279.117981,0.014323,0.000862,0.021906,82.165527,4.185711,0.219062,-279.117981,0.022877,0.000000
35.600002,18.945572,-279.162445,0.014353,0.000878,0.022305,84.274117,4.293128,0.223051,-279.162445,0.023233,0.000000
35.810001,19.145164,-279.162445,0.014357,0.000886,0.022513,85.161942,4.338356,0.225133,-279.162445,0.023580,0.000000
36.020000,19.351830,-279.206940,0.014366,0.000897,0.022774,86.081238,4.385187,0.227737,-279.206940,0.023927,0.000000
36.230003,20.140511,-279.251404,0.014362,0.000918,0.023320,89.589462,4.563905,0.233199,-279.251404,0.024282,0.000000
36.440002,20.705399,-279.206940,0.014405,0.000938,0.023823,92.102211,4.691911,0.238229,-279.206940,0.024629,0.000000
36.650002,20.862167,-279.251404,0.014396,0.000949,0.024100,92.799553,4.727435,0.241003,-279.251404,0.024976,0.000000
36.860001,21.127296,-279.295898,0.014413,0.000963,0.024465,93.978905,4.787514,0.244648,-279.295898,0.025332,0.000000
37.070004,21.423332,-279.295898,0.014422,0.000974,0.024751,95.295738,4.854597,0.247509,-279.295898,0.025679,0.000000
37.280003,21.577126,-279.340363,0.014439,0.000985,0.025020,95.979851,4.889446,0.250197,-279.340363,0.026034,0.000000
37.490002,22.145363,-279.295898,0.014448,0.001000,0.025410,98.507492,5.018211,0.254099,-279.295898,0.026381,0.000000
37.700001,22.444382,-279.384857,0.014461,0.001014,0.025757,99.837593,5.085969,0.257570,-279.384857,0.026728,0.000000
37.910004,22.693497,-279.384857,0.014457,0.001024,0.026000,100.945717,5.142420,0.259996,-279.384857,0.027084,0.000000
38.120003,22.990654,-279.384857,0.014469,0.001035,0.026286,102.267540,5.209757,0.262857,-279.384857,0.027431,0.000000
38.330002,23.796097,-279.429321,0.014491,0.001059,0.026893,105.850327,5.392273,0.268928,-279.429321,0.027777,0.000000
38.540001,24.100319,-279.429321,0.014517,0.001072,0.027240,107.203575,5.461210,0.272399,-279.429321,0.028133,0.000000
38.750000,24.341248,-279.429321,0.014530,0.001086,0.027595,108.275276,5.515806,0.275953,-279.429321,0.028480,0.000000
38.960003,24.564667,-279.473816,0.014526,0.001098,0.027881,109.269096,5.566433,0.278814,-279.473816,0.028827,0.000000
39.170002,24.727394,-279.473816,0.014526,0.001111,0.028211,109.992943,5.603307,0.282111,-279.473816,0.029182,0.000000
39.380001,25.412933,-279.473816,0.014538,0.001128,0.028662,113.042374,5.758653,0.286619,-279.473816,0.029529,0.000000
39.590000,25.609550,-279.473816,0.014551,0.001141,0.028983,113.916969,5.803207,0.289828,-279.473816,0.029876,0.000000
39.800003,25.926437,-279.518311,0.014560,0.001152,0.029252,115.326553,5.875015,0.292516,-279.518311,0.030232,0.000000
40.010002,26.331573,-279.518311,0.014569,0.001166,0.029616,117.128685,5.966820,0.296160,-279.518311,0.030579,0.000000
40.220001,26.884552,-279.562775,0.014590,0.001183,0.030058,119.588463,6.092127,0.300581,-279.562775,0.030934,0.000000
40.430000,27.299744,-279.607269,0.014612,0.001198,0.030440,121.435326,6.186211,0.304396,-279.607269,0.031281,0.000000
40.640003,27.422256,-279.562775,0.014616,0.001212,0.030778,121.980286,6.213972,0.307780,-279.562775,0.031628,0.000000
40.850002,27.747711,-279.518311,0.014638,0.001223,0.031073,123.427986,6.287721,0.310729,-279.518311,0.031983,0.000000
41.060001,28.069443,-279.740692,0.014625,0.001237,0.031420,124.859116,6.360627,0.314199,-279.740692,0.032330,0.000000
41.270000,28.650337,-279.607269,0.014659,0.001253,0.031827,127.443062,6.492259,0.318272,-279.607269,0.032677,0.000000
41.480003,28.913605,-279.696228,0.014655,0.001264,0.032105,128.614136,6.551917,0.321050,-279.696228,0.033033,0.000000
41.690002,29.144478,-279.651733,0.014659,0.001276,0.032417,129.641113,6.604233,0.324172,-279.651733,0.033380,0.000000
41.900002,29.751076,-279.696228,0.014685,0.001294,0.032877,132.339401,6.741690,0.328767,-279.696228,0.033726,0.000000
42.110001,30.232178,-279.785187,0.014694,0.001308,0.033215,134.479446,6.850709,0.332151,-279.785187,0.034082,0.000000
42.320004,30.689827,-279.651733,0.014711,0.001326,0.033683,136.515167,6.954414,0.336833,-279.651733,0.034429,0.000000
42.530003,30.800789,-279.785187,0.014707,0.001336,0.033926,137.008759,6.979558,0.339259,-279.785187,0.034785,0.000000
42.740002,30.943413,-279.829651,0.014737,0.001346,0.034195,137.643173,7.011878,0.341950,-279.829651,0.035131,0.000000
42.950001,31.542931,-279.740692,0.014750,0.001363,0.034620,140.309967,7.147730,0.346197,-279.740692,0.035478,0.000000
43.160004,31.957756,-279.918640,0.014737,0.001377,0.034975,142.155197,7.241731,0.349755,-279.918640,0.035834,0.000000
43.370003,32.245972,-279.829651,0.014767,0.001388,0.035262,143.437241,7.307042,0.352616,-279.829651,0.036181,0.000000
43.580002,32.638451,-279.918640,0.014767,0.001400,0.035565,145.183075,7.395979,0.355651,-279.918640,0.036528,0.000000
43.790001,33.078224,-279.918640,0.014780,0.001417,0.035990,147.139282,7.495633,0.359902,-279.918640,0.036883,0.000000
44.000004,33.812912,-279.874146,0.014801,0.001432,0.036380,150.407349,7.662115,0.363804,-279.874146,0.037230,0.000000
44.210003,34.181931,-279.963104,0.014797,0.001446,0.036718,152.048828,7.745736,0.367184,-279.963104,0.037577,0.000000
44.420002,34.466797,-279.918640,0.014814,0.001458,0.037031,153.315964,7.810287,0.370307,-279.918640,0.037933,0.000000
44.630001,34.830231,-280.007599,0.014810,0.001471,0.037360,154.932602,7.892643,0.373603,-280.007599,0.038280,0.000000
44.840004,35.392143,-280.007599,0.014819,0.001486,0.037733,157.432114,8.019974,0.377331,-280.007599,0.038635,0.000000
45.050003,35.807343,-280.007599,0.014836,0.001501,0.038115,159.279007,8.114059,0.381146,-280.007599,0.038982,0.000000
45.260002,36.369247,-280.007599,0.014849,0.001514,0.038444,161.778488,8.241389,0.384443,-280.007599,0.039329,0.000000
45.470001,36.648155,-280.007599,0.014862,0.001526,0.038748,163.019135,8.304590,0.387479,-280.007599,0.039684,0.000000
45.680000,36.831734,-280.007599,0.014883,0.001535,0.038990,163.835739,8.346190,0.389905,-280.007599,0.040031,0.000000
45.890003,37.482643,-280.052063,0.014883,0.001551,0.039407,166.731125,8.493689,0.394068,-280.052063,0.040378,0.000000
46.100002,38.462730,-280.052063,0.014892,0.001570,0.039867,171.090775,8.715779,0.398667,-280.052063,0.040734,0.000000
46.310001,38.793770,-280.052063,0.014888,0.001581,0.040153,172.563309,8.790793,0.401528,-280.052063,0.041080,0.000000
46.520000,39.322166,-280.096558,0.014914,0.001596,0.040543,174.913727,8.910531,0.405430,-280.096558,0.041428,0.000000
46.730003,39.707565,-280.141022,0.014918,0.001608,0.040855,176.628067,8.997864,0.408553,-280.141022,0.041783,0.000000
46.940002,40.201706,-280.229980,0.014922,0.001622,0.041211,178.826126,9.109837,0.412107,-280.229980,0.042130,0.000000
47.150002,40.936028,-280.096558,0.014939,0.001638,0.041610,182.092545,9.276237,0.416096,-280.096558,0.042477,0.000000
47.360001,41.499428,-280.229980,0.014952,0.001652,0.041965,184.598679,9.403904,0.419654,-280.229980,0.042833,0.000000
47.570004,41.654701,-280.229980,0.014944,0.001660,0.042165,185.289368,9.439091,0.421649,-280.229980,0.043179,0.000000
47.780003,42.012550,-280.229980,0.014961,0.001672,0.042468,186.881165,9.520180,0.424684,-280.229980,0.043535,0.000000
47.990002,43.168770,-280.229980,0.014961,0.001694,0.043023,192.024277,9.782183,0.430233,-280.229980,0.043882,0.000000
48.200001,43.830101,-280.229980,0.014991,0.001708,0.043379,194.966034,9.932043,0.433787,-280.229980,0.044229,0.000000
48.410004,44.214767,-280.274475,0.014991,0.001719,0.043656,196.677109,10.019209,0.436565,-280.274475,0.044584,0.000000
48.620003,44.456810,-280.229980,0.015000,0.001729,0.043925,197.753769,10.074058,0.439252,-280.229980,0.044931,0.000000
48.830002,44.966583,-280.363434,0.015013,0.001743,0.044281,200.021347,10.189574,0.442806,-280.363434,0.045278,0.000000
49.040001,45.617493,-280.407928,0.015008,0.001758,0.044654,202.916748,10.337071,0.446538,-280.407928,0.045634,0.000000
49.250004,46.561455,-280.318939,0.015017,0.001774,0.045061,207.115692,10.550977,0.450611,-280.318939,0.045980,0.000000
49.460003,46.844460,-280.407928,0.015030,0.001784,0.045321,208.374557,10.615107,0.453215,-280.407928,0.046327,0.000000
49.670002,47.565742,-280.363434,0.015034,0.001799,0.045703,211.582993,10.778551,0.457030,-280.363434,0.046683,0.000000
49.880001,48.476570,-280.496887,0.015056,0.001815,0.046093,215.634552,10.984948,0.460932,-280.496887,0.047030,0.000000
50.090004,49.161362,-280.452393,0.015073,0.001829,0.046466,218.680664,11.140123,0.464660,-280.452393,0.047385,0.000000
50.300003,49.738541,-280.452393,0.015077,0.001842,0.046787,221.248077,11.270914,0.467870,-280.452393,0.047732,0.000000
50.510002,50.389442,-280.541351,0.015064,0.001856,0.047134,224.143433,11.418410,0.471341,-280.541351,0.048079,0.000000
50.720001,50.791237,-280.452393,0.015090,0.001869,0.047463,225.930710,11.509459,0.474633,-280.452393,0.048435,0.000000
50.930004,51.519592,-280.496887,0.015116,0.001883,0.047828,229.170593,11.674506,0.478278,-280.496887,0.048782,0.000000
51.140003,52.509361,-280.541351,0.015095,0.001898,0.048218,233.573303,11.898791,0.482180,-280.541351,0.049129,0.000000
51.350002,52.849709,-280.496887,0.015120,0.001909,0.048487,235.087250,11.975915,0.484868,-280.496887,0.049484,0.000000
51.560001,53.652542,-280.585846,0.015125,0.001924,0.048860,238.658432,12.157840,0.488596,-280.585846,0.049831,0.000000
51.770004,54.659439,-280.585846,0.015116,0.001942,0.049328,243.137329,12.386005,0.493282,-280.585846,0.050178,0.000000
51.980003,55.410515,-280.496887,0.015159,0.001956,0.049675,246.478287,12.556203,0.496749,-280.496887,0.050533,0.000000
52.190002,55.888268,-280.630310,0.015142,0.001968,0.049978,248.603424,12.664462,0.499784,-280.630310,0.050880,0.000000
52.400002,56.307190,-280.630310,0.015146,0.001978,0.050247,250.466888,12.759392,0.502471,-280.630310,0.051236,0.000000
52.610001,56.830368,-280.630310,0.015164,0.001988,0.050508,252.794098,12.877945,0.505075,-280.630310,0.051583,0.000000
52.820004,57.379250,-280.674805,0.015164,0.001999,0.050776,255.235657,13.002324,0.507763,-280.674805,0.051930,0.000000
53.030003,58.552223,-280.674805,0.015177,0.002019,0.051271,260.453308,13.268124,0.512706,-280.674805,0.052285,0.000000
53.240002,59.451126,-280.763763,0.015189,0.002033,0.051626,264.451813,13.471818,0.516260,-280.763763,0.052632,0.000000
53.450001,59.929626,-280.719269,0.015194,0.002045,0.051938,266.580292,13.580247,0.519382,-280.719269,0.052979,0.000000
53.660004,60.821091,-280.763763,0.015202,0.002059,0.052294,270.545715,13.782256,0.522940,-280.763763,0.053334,0.000000
53.870003,62.041351,-280.763763,0.015198,0.002078,0.052780,275.973724,14.058771,0.527796,-280.763763,0.053682,0.000000
54.080002,62.840836,-280.808258,0.015224,0.002090,0.053092,279.529999,14.239937,0.530919,-280.808258,0.054028,0.000000
54.290001,63.256775,-280.808258,0.015220,0.002099,0.053326,281.380188,14.334190,0.533258,-280.808258,0.054384,0.000000
54.500004,63.886459,-280.852722,0.015228,0.002112,0.053647,284.181152,14.476878,0.536467,-280.852722,0.054731,0.000000
54.710003,64.544434,-280.808258,0.015250,0.002125,0.053968,287.107971,14.625978,0.539677,-280.808258,0.055086,0.000000
54.920002,65.635498,-280.897217,0.015237,0.002142,0.054401,291.961273,14.873217,0.544014,-280.897217,0.055433,0.000000
55.130001,66.557114,-280.852722,0.015258,0.002155,0.054739,296.060822,15.082057,0.547394,-280.852722,0.055780,0.000000
55.340004,67.174133,-280.897217,0.015258,0.002165,0.055000,298.805481,15.221876,0.549998,-280.897217,0.056136,0.000000
55.550003,67.227005,-280.852722,0.015276,0.002164,0.054974,299.040649,15.233856,0.549737,-280.852722,0.055208,0.000000
55.760002,66.825958,-280.897217,0.015284,0.002164,0.054974,297.256714,15.142978,0.549737,-280.897217,0.055208,0.000000
55.970001,66.571259,-280.941681,0.015267,0.002162,0.054913,296.123749,15.085263,0.549128,-280.941681,0.054974,0.000000
56.180004,66.296448,-280.986176,0.015293,0.002161,0.054896,294.901337,15.022989,0.548957,-280.986176,0.054974,0.000000
56.390003,66.026474,-281.030640,0.015284,0.002161,0.054887,293.700439,14.961813,0.548870,-281.030640,0.054974,0.000000
56.600002,65.816086,-280.941681,0.015289,0.002161,0.054887,292.764557,14.914139,0.548870,-280.941681,0.054974,0.000000
56.810001,65.628036,-280.986176,0.015293,0.002161,0.054878,291.928101,14.871526,0.548783,-280.986176,0.054974,0.000000
57.020004,65.469406,-281.030640,0.015306,0.002161,0.054878,291.222473,14.835580,0.548783,-281.030640,0.054974,0.000000
57.230003,65.315628,-281.075134,0.015276,0.002161,0.054878,290.538422,14.800733,0.548783,-281.075134,0.054974,0.000000
57.440002,65.168915,-281.075134,0.015280,0.002161,0.054878,289.885803,14.767488,0.548783,-281.075134,0.054974,0.000000
57.650002,65.047150,-281.075134,0.015289,0.002160,0.054870,289.344177,14.739895,0.548696,-281.075134,0.054974,0.000000
57.860004,64.929092,-281.119598,0.015289,0.002160,0.054870,288.819031,14.713142,0.548696,-281.119598,0.054974,0.000000
58.070004,64.821106,-281.208588,0.015306,0.002160,0.054870,288.338684,14.688673,0.548696,-281.208588,0.054974,0.000000
58.280003,64.709030,-281.075134,0.015302,0.002160,0.054870,287.840149,14.663276,0.548696,-281.075134,0.054974,0.000000
58.490002,64.619659,-281.208588,0.015306,0.002160,0.054870,287.442596,14.643024,0.548696,-281.208588,0.054974,0.000000
58.700005,64.534760,-281.208588,0.015293,0.002160,0.054870,287.064941,14.623785,0.548696,-281.208588,0.054974,0.000000
58.910004,64.448364,-281.164093,0.015289,0.002160,0.054870,286.680634,14.604208,0.548696,-281.164093,0.054974,0.000000
59.120003,64.366440,-281.253052,0.015289,0.002160,0.054870,286.316223,14.585644,0.548696,-281.253052,0.054974,0.000000
59.330002,64.290115,-281.253052,0.015293,0.002160,0.054870,285.976715,14.568348,0.548696,-281.253052,0.054974,0.000000
59.540005,64.235001,-281.297546,0.015306,0.002160,0.054870,285.731567,14.555859,0.548696,-281.297546,0.054974,0.000000
59.750004,64.154572,-281.297546,0.015297,0.002160,0.054870,285.373779,14.537634,0.548696,-281.297546,0.054974,0.000000
59.960003,64.097595,-281.297546,0.015306,0.002160,0.054870,285.120331,14.524723,0.548696,-281.297546,0.054974,0.000000
60.170002,64.032425,-281.386505,0.015289,0.002160,0.054870,284.830444,14.509954,0.548696,-281.386505,0.054974,0.000000
60.380001,63.969498,-281.297546,0.015306,0.002160,0.054861,284.550537,14.495695,0.548609,-281.297546,0.054974,0.000000
60.590004,63.911041,-281.342010,0.015302,0.002160,0.054861,284.290497,14.482449,0.548609,-281.342010,0.054974,0.000000
60.800003,63.850342,-281.386505,0.015310,0.002160,0.054861,284.020508,14.468695,0.548609,-281.386505,0.054974,0.000000
61.010002,63.808258,-281.386505,0.015310,0.002160,0.054861,283.833313,14.459158,0.548609,-281.386505,0.054974,0.000000
61.220001,63.753143,-281.430969,0.015293,0.002160,0.054861,283.588135,14.446669,0.548609,-281.430969,0.054974,0.000000
61.430004,63.712555,-281.386505,0.015315,0.002160,0.054861,283.407593,14.437471,0.548609,-281.386505,0.054974,0.000000
61.640003,63.666763,-281.519928,0.015306,0.002160,0.054861,283.203918,14.427095,0.548609,-281.519928,0.054974,0.000000
61.850002,63.609039,-281.475464,0.015315,0.002160,0.054861,282.947144,14.414014,0.548609,-281.475464,0.054974,0.000000
62.060001,63.583725,-281.475464,0.015302,0.002160,0.054861,282.834534,14.408278,0.548609,-281.475464,0.054974,0.000000
62.270004,63.525253,-281.519928,0.015310,0.002160,0.054861,282.574432,14.395029,0.548609,-281.519928,0.054974,0.000000
62.480003,63.490250,-281.519928,0.015297,0.002160,0.054861,282.418732,14.387095,0.548609,-281.519928,0.054974,0.000000
62.690002,63.457108,-281.564423,0.015297,0.002160,0.054861,282.271301,14.379586,0.548609,-281.564423,0.054974,0.000000
62.900002,63.406097,-281.564423,0.015293,0.002160,0.054861,282.044403,14.368027,0.548609,-281.564423,0.054974,0.000000
63.110004,63.369232,-281.519928,0.015302,0.002160,0.054861,281.880432,14.359674,0.548609,-281.519928,0.054974,0.000000
63.320004,63.330505,-281.608887,0.015310,0.002160,0.054861,281.708160,14.350898,0.548609,-281.608887,0.054974,0.000000
63.530003,63.298859,-281.608887,0.015289,0.002160,0.054861,281.567383,14.343726,0.548609,-281.608887,0.054974,0.000000
63.740002,63.257523,-281.697876,0.015297,0.002160,0.054861,281.383514,14.334359,0.548609,-281.697876,0.054974,0.000000
63.950005,63.215073,-281.608887,0.015310,0.002160,0.054861,281.194702,14.324739,0.548609,-281.608887,0.054974,0.000000
64.160004,63.194595,-281.608887,0.015315,0.002160,0.054861,281.103607,14.320100,0.548609,-281.608887,0.054974,0.000000
64.370003,63.158096,-281.697876,0.015306,0.002160,0.054861,280.941254,14.311830,0.548609,-281.697876,0.054974,0.000000
64.580002,63.124588,-281.608887,0.015293,0.002160,0.054861,280.792206,14.304236,0.548609,-281.608887,0.054974,0.000000
64.790001,63.088837,-281.697876,0.015306,0.002160,0.054861,280.633148,14.296135,0.548609,-281.697876,0.054974,0.000000
65.000000,63.059044,-281.742340,0.015302,0.002160,0.054861,280.500641,14.289384,0.548609,-281.742340,0.054974,0.000000
65.210007,63.035583,-281.697876,0.015302,0.002160,0.054861,280.396271,14.284068,0.548609,-281.697876,0.054974,0.000000
65.420006,63.003189,-281.742340,0.015310,0.002160,0.054861,280.252167,14.276727,0.548609,-281.742340,0.054974,0.000000
65.630005,62.977867,-281.697876,0.015297,0.002160,0.054861,280.139557,14.270988,0.548609,-281.697876,0.054974,0.000000
65.840004,62.959625,-281.786835,0.015306,0.002160,0.054861,280.058411,14.266855,0.548609,-281.786835,0.054974,0.000000
66.050003,62.919403,-281.831299,0.015310,0.002160,0.054861,279.879486,14.257740,0.548609,-281.831299,0.054974,0.000000
66.260002,62.903763,-281.786835,0.015306,0.002160,0.054861,279.809906,14.254196,0.548609,-281.786835,0.054974,0.000000
66.470001,62.866531,-281.875793,0.015297,0.002160,0.054861,279.644287,14.245759,0.548609,-281.875793,0.054974,0.000000
66.680000,62.836739,-281.875793,0.015297,0.002160,0.054861,279.511780,14.239009,0.548609,-281.875793,0.054974,0.000000
66.889999,62.810677,-281.920258,0.015310,0.002160,0.054861,279.395844,14.233103,0.548609,-281.920258,0.054974,0.000000
67.100006,62.792053,-281.920258,0.015293,0.002160,0.054861,279.312988,14.228883,0.548609,-281.920258,0.054974,0.000000
67.310005,62.765617,-281.920258,0.015306,0.002160,0.054861,279.195404,14.222892,0.548609,-281.920258,0.054974,0.000000
67.520004,62.741043,-281.964752,0.015306,0.002160,0.054861,279.086090,14.217324,0.548609,-281.964752,0.054974,0.000000
67.730003,62.724655,-281.920258,0.015289,0.002160,0.054861,279.013214,14.213610,0.548609,-281.920258,0.054974,0.000000
67.940002,62.717209,-281.964752,0.015306,0.002160,0.054861,278.980072,14.211923,0.548609,-281.964752,0.054974,0.000000
68.150002,62.689651,-282.053711,0.015319,0.002160,0.054861,278.857483,14.205678,0.548609,-282.053711,0.054974,0.000000
68.360001,62.665077,-281.964752,0.015306,0.002160,0.054861,278.748199,14.200109,0.548609,-281.964752,0.054974,0.000000
68.570000,62.645340,-282.053711,0.015306,0.002160,0.054861,278.660400,14.195637,0.548609,-282.053711,0.054974,0.000000
68.780006,62.616295,-282.009216,0.015297,0.002160,0.054861,278.531189,14.189054,0.548609,-282.009216,0.054974,0.000000
68.990005,62.602890,-282.142670,0.015323,0.002160,0.054861,278.471558,14.186018,0.548609,-282.142670,0.054974,0.000000
69.200005,62.576820,-282.098206,0.015310,0.002160,0.054861,278.355591,14.180110,0.548609,-282.098206,0.054974,0.000000
69.410004,62.547035,-282.098206,0.015310,0.002160,0.054861,278.223114,14.173361,0.548609,-282.098206,0.054974,0.000000
69.620003,62.525810,-282.142670,0.015315,0.002160,0.054861,278.128693,14.168551,0.548609,-282.142670,0.054974,0.000000
69.830002,62.512032,-282.098206,0.015315,0.002160,0.054861,278.067413,14.165429,0.548609,-282.098206,0.054974,0.000000
70.040001,62.493408,-282.142670,0.015327,0.002160,0.054861,277.984558,14.161209,0.548609,-282.142670,0.054974,0.000000
70.250000,62.468834,-282.187164,0.015302,0.002160,0.054861,277.875244,14.155640,0.548609,-282.187164,0.054974,0.000000
70.460007,62.448730,-282.142670,0.015323,0.002160,0.054861,277.785828,14.151084,0.548609,-282.142670,0.054974,0.000000
70.670006,62.434578,-282.187164,0.015315,0.002160,0.054861,277.722870,14.147878,0.548609,-282.187164,0.054974,0.000000
70.880005,62.408508,-282.187164,0.015319,0.002160,0.054861,277.606903,14.141971,0.548609,-282.187164,0.054974,0.000000
71.090004,62.407021,-282.231628,0.015315,0.002160,0.054861,277.600281,14.141633,0.548609,-282.231628,0.054974,0.000000
71.300003,62.384682,-282.320587,0.015319,0.002160,0.054861,277.500916,14.136571,0.548609,-282.320587,0.054974,0.000000
71.510002,62.364197,-282.276123,0.015306,0.002160,0.054861,277.409790,14.131928,0.548609,-282.276123,0.054974,0.000000
71.720001,62.355637,-282.320587,0.015306,0.002160,0.054861,277.371735,14.129989,0.548609,-282.320587,0.054974,0.000000
71.930000,62.325470,-282.320587,0.015306,0.002160,0.054861,277.237549,14.123154,0.548609,-282.320587,0.054974,0.000000
72.140007,62.311691,-282.276123,0.015306,0.002160,0.054861,277.176239,14.120030,0.548609,-282.276123,0.054974,0.000000
72.350006,62.288979,-282.365082,0.015306,0.002160,0.054861,277.075226,14.114884,0.548609,-282.365082,0.054974,0.000000
72.560005,62.278549,-282.409546,0.015323,0.002160,0.054861,277.028809,14.112521,0.548609,-282.409546,0.054974,0.000000
72.770004,62.257698,-282.454041,0.015310,0.002160,0.054861,276.936066,14.107796,0.548609,-282.454041,0.054974,0.000000
72.980003,62.255463,-282.409546,0.015297,0.002160,0.054861,276.926117,14.107289,0.548609,-282.409546,0.054974,0.000000
73.190002,62.233124,-282.409546,0.015302,0.002160,0.054861,276.826752,14.102227,0.548609,-282.409546,0.054974,0.000000
73.400002,62.220833,-282.498535,0.015319,0.002160,0.054861,276.772095,14.099442,0.548609,-282.498535,0.054974,0.000000
73.610001,62.206314,-282.409546,0.015319,0.002160,0.054861,276.707520,14.096152,0.548609,-282.409546,0.054974,0.000000
73.820000,62.191414,-282.498535,0.015302,0.002160,0.054861,276.641235,14.092775,0.548609,-282.498535,0.054974,0.000000
74.030006,62.182480,-282.498535,0.015302,0.002160,0.054861,276.601471,14.090751,0.548609,-282.498535,0.054974,0.000000
74.240005,62.161255,-282.498535,0.015319,0.002160,0.054861,276.507080,14.085941,0.548609,-282.498535,0.054974,0.000000
74.450005,62.149338,-282.542999,0.015319,0.002160,0.054861,276.454071,14.083241,0.548609,-282.542999,0.054974,0.000000
74.660004,62.144127,-282.454041,0.015297,0.002160,0.054861,276.430878,14.082060,0.548609,-282.454041,0.054974,0.000000
74.870003,62.124016,-282.542999,0.015310,0.002160,0.054861,276.341431,14.077503,0.548609,-282.542999,0.054974,0.000000
75.080002,62.119179,-282.587494,0.015293,0.002160,0.054861,276.319916,14.076407,0.548609,-282.587494,0.054974,0.000000
75.290001,62.092735,-282.587494,0.015315,0.002160,0.054861,276.202271,14.070415,0.548609,-282.587494,0.054974,0.000000
75.500000,62.082314,-282.676453,0.015302,0.002160,0.054861,276.155914,14.068053,0.548609,-282.676453,0.054974,0.000000
75.710007,62.073746,-282.631958,0.015302,0.002160,0.054861,276.117798,14.066113,0.548609,-282.631958,0.054974,0.000000
75.920006,62.058105,-282.631958,0.015302,0.002160,0.054861,276.048248,14.062568,0.548609,-282.631958,0.054974,0.000000
76.130005,62.052895,-282.676453,0.015306,0.002160,0.054861,276.025055,14.061387,0.548609,-282.676453,0.054974,0.000000
76.340004,62.031296,-282.631958,0.015315,0.002160,0.054861,275.928986,14.056493,0.548609,-282.631958,0.054974,0.000000
76.550003,62.023102,-282.720917,0.015310,0.002160,0.054861,275.892548,14.054635,0.548609,-282.720917,0.054974,0.000000
76.760002,62.014168,-282.720917,0.015319,0.002160,0.054861,275.852783,14.052611,0.548609,-282.720917,0.054974,0.000000
76.970001,62.005600,-282.765411,0.015327,0.002160,0.054861,275.814697,14.050670,0.548609,-282.765411,0.054974,0.000000
77.180000,61.997414,-282.765411,0.015315,0.002160,0.054861,275.778259,14.048815,0.548609,-282.765411,0.054974,0.000000
77.390007,61.966507,-282.720917,0.015327,0.002160,0.054861,275.640778,14.041811,0.548609,-282.720917,0.054974,0.000000
77.600006,61.963150,-282.809875,0.015310,0.002160,0.054861,275.625854,14.041050,0.548609,-282.809875,0.054974,0.000000
77.810005,61.957939,-282.765411,0.015306,0.002160,0.054861,275.602692,14.039869,0.548609,-282.765411,0.054974,0.000000
78.020004,61.946770,-282.765411,0.015302,0.002160,0.054861,275.553009,14.037339,0.548609,-282.765411,0.054974,0.000000
78.230003,61.943047,-282.809875,0.015310,0.002160,0.054861,275.536438,14.036495,0.548609,-282.809875,0.054974,0.000000
78.440002,61.913254,-282.854370,0.015315,0.002160,0.054861,275.403900,14.029744,0.548609,-282.854370,0.054974,0.000000
78.650002,61.897987,-282.898834,0.015319,0.002160,0.054861,275.335999,14.026284,0.548609,-282.898834,0.054974,0.000000
78.860001,61.894638,-282.854370,0.015310,0.002160,0.054861,275.321106,14.025525,0.548609,-282.854370,0.054974,0.000000
79.070007,61.892776,-282.854370,0.015319,0.002160,0.054861,275.312805,14.025105,0.548609,-282.854370,0.054974,0.000000
79.280006,61.882721,-282.943329,0.015310,0.002160,0.054861,275.268097,14.022825,0.548609,-282.943329,0.054974,0.000000
79.490005,61.876389,-282.898834,0.015315,0.002160,0.054861,275.239929,14.021390,0.548609,-282.898834,0.054974,0.000000
79.700005,61.859261,-282.943329,0.015315,0.002160,0.054861,275.163727,14.017509,0.548609,-282.943329,0.054974,0.000000
79.910004,61.847343,-282.943329,0.015315,0.002160,0.054861,275.110718,14.014809,0.548609,-282.943329,0.054974,0.000000
80.120003,61.830215,-282.943329,0.015319,0.002160,0.054861,275.034546,14.010927,0.548609,-282.943329,0.054974,0.000000
80.330002,61.830589,-282.943329,0.015319,0.002160,0.054861,275.036194,14.011012,0.548609,-282.943329,0.054974,0.000000
80.540001,61.813461,-282.987823,0.015315,0.002160,0.054861,274.960022,14.007131,0.548609,-282.987823,0.054974,0.000000
80.750008,61.797821,-283.032288,0.015310,0.002160,0.054861,274.890442,14.003587,0.548609,-283.032288,0.054974,0.000000
80.960007,61.787018,-283.032288,0.015306,0.002160,0.054861,274.842377,14.001138,0.548609,-283.032288,0.054974,0.000000
81.170006,61.783295,-283.032288,0.015315,0.002160,0.054861,274.825806,14.000295,0.548609,-283.032288,0.054974,0.000000
81.380005,61.769890,-283.121246,0.015315,0.002160,0.054861,274.766205,13.997257,0.548609,-283.121246,0.054974,0.000000
81.590004,61.750900,-283.032288,0.015319,0.002160,0.054861,274.681732,13.992954,0.548609,-283.032288,0.054974,0.000000
81.800003,61.743080,-283.121246,0.015302,0.002160,0.054861,274.646942,13.991181,0.548609,-283.121246,0.054974,0.000000
82.010002,61.740105,-283.076782,0.015302,0.002160,0.054861,274.633698,13.990508,0.548609,-283.076782,0.054974,0.000000
82.220001,61.735634,-283.121246,0.015310,0.002160,0.054861,274.613800,13.989495,0.548609,-283.121246,0.054974,0.000000
82.430000,61.714035,-283.210205,0.015315,0.002160,0.054861,274.517731,13.984600,0.548609,-283.210205,0.054974,0.000000
82.640007,61.710686,-283.210205,0.015306,0.002160,0.054861,274.502838,13.983841,0.548609,-283.210205,0.054974,0.000000
82.850006,61.705101,-283.210205,0.015310,0.002160,0.054861,274.477997,13.982575,0.548609,-283.210205,0.054974,0.000000
83.060005,61.686111,-283.254700,0.015319,0.002160,0.054861,274.393524,13.978273,0.548609,-283.254700,0.054974,0.000000
83.270004,61.678658,-283.254700,0.015323,0.002160,0.054861,274.360382,13.976583,0.548609,-283.254700,0.054974,0.000000
83.480003,61.650734,-283.299164,0.015319,0.002160,0.054861,274.236176,13.970256,0.548609,-283.299164,0.054974,0.000000
83.690002,61.648872,-283.254700,0.015297,0.002160,0.054861,274.227875,13.969833,0.548609,-283.254700,0.054974,0.000000
83.900002,61.641052,-283.299164,0.015306,0.002160,0.054861,274.193085,13.968061,0.548609,-283.299164,0.054974,0.000000
84.110001,61.641052,-283.299164,0.015302,0.002160,0.054861,274.193085,13.968061,0.548609,-283.299164,0.054974,0.000000
84.320007,61.630249,-283.254700,0.015319,0.002160,0.054861,274.145050,13.965614,0.548609,-283.254700,0.054974,0.000000
84.530006,61.619080,-283.388153,0.015306,0.002160,0.054861,274.095367,13.963083,0.548609,-283.388153,0.054974,0.000000
84.740005,61.600090,-283.299164,0.015319,0.002160,0.054861,274.010895,13.958780,0.548609,-283.299164,0.054974,0.000000
84.950005,61.590408,-283.343658,0.015332,0.002160,0.054861,273.967804,13.956586,0.548609,-283.343658,0.054974,0.000000
85.160004,61.593758,-283.388153,0.015315,0.002160,0.054861,273.982727,13.957345,0.548609,-283.388153,0.054974,0.000000
85.370003,61.576630,-283.343658,0.015315,0.002160,0.054861,273.906525,13.953464,0.548609,-283.343658,0.054974,0.000000
85.580002,61.566208,-283.432617,0.015315,0.002160,0.054861,273.860168,13.951102,0.548609,-283.432617,0.054974,0.000000
85.790001,61.550194,-283.432617,0.015310,0.002160,0.054861,273.788940,13.947474,0.548609,-283.432617,0.054974,0.000000
85.900002,61.550568,-283.432617,0.015302,0.002160,0.054861,273.790588,13.947558,0.548609,-283.432617,0.054974,0.000000