File: Data/AG AL compression 300N/AG membrane Peeled 300N_1_3_03192024_183719.csv
Time (sec),S:Load (lbs),S:HL1 (DIM),S:LVDT (in),S:Position (in),Ch:Position (mm),Ch:Load (N),Ch:Stress (MPa),Ch:Strain (mm/mm),Ch:HL1 (DIM),Set Point (),Cycles ()
0.010000,0.020111,-324.221649,-0.000013,-0.000000,-0.000000,0.089459,0.004557,-0.000000,-324.221649,0.000217,0.000000
0.180000,0.016762,-324.266144,-0.000009,-0.000000,-0.000000,0.074560,0.003798,-0.000000,-324.266144,0.000217,0.000000
0.350000,0.022346,-324.355103,-0.000017,0.000006,0.000165,0.099402,0.005064,0.001646,-324.355103,0.000737,0.000000
0.520000,0.013039,-324.355103,-0.000009,0.000106,0.002688,0.057999,0.002955,0.026884,-324.355103,0.003582,0.000000
0.690000,0.008942,-324.310608,0.000013,0.000209,0.005307,0.039774,0.002026,0.053072,-324.310608,0.006409,0.000000
0.860000,-0.017128,-324.310608,0.000134,0.000319,0.008108,-0.076189,-0.003881,0.081084,-324.310608,0.009236,0.000000
1.030000,-0.007072,-324.310608,0.000237,0.000434,0.011014,-0.031460,-0.001603,0.110137,-324.310608,0.012063,0.000000
1.200000,0.024582,-324.355103,0.000345,0.000552,0.014014,0.109346,0.005570,0.140143,-324.355103,0.014908,0.000000
1.370000,0.019363,-324.399567,0.000457,0.000659,0.016746,0.086133,0.004388,0.167459,-324.399567,0.017735,0.000000
1.540000,0.068893,-324.399567,0.000539,0.000763,0.019382,0.306453,0.015611,0.193824,-324.399567,0.020562,0.000000
1.710000,0.061073,-324.399567,0.000673,0.000882,0.022409,0.271668,0.013839,0.224088,-324.399567,0.023406,0.000000
1.880000,0.037239,-324.399567,0.000755,0.000990,0.025158,0.165648,0.008438,0.251582,-324.399567,0.026233,0.000000
2.050000,0.017502,-324.399567,0.000867,0.001102,0.028003,0.077852,0.003966,0.280025,-324.399567,0.029061,0.000000
2.220000,0.025696,-324.444061,0.000970,0.001212,0.030778,0.114301,0.005823,0.307776,-324.444061,0.031888,0.000000
2.390000,0.051018,-324.399567,0.001104,0.001324,0.033640,0.226938,0.011561,0.336398,-324.399567,0.034732,0.000000
2.560000,0.039101,-324.399567,0.001229,0.001439,0.036545,0.173928,0.008860,0.365447,-324.399567,0.037559,0.000000
2.730000,0.033890,-324.444061,0.001319,0.001551,0.039389,0.150749,0.007680,0.393894,-324.444061,0.040387,0.000000
2.900000,0.051392,-324.444061,0.001427,0.001655,0.042043,0.228601,0.011646,0.420430,-324.444061,0.043231,0.000000
3.070000,0.030540,-324.533020,0.001535,0.001770,0.044966,0.135851,0.006921,0.449657,-324.533020,0.046058,0.000000
3.240000,0.051392,-324.533020,0.001643,0.001881,0.047767,0.228601,0.011646,0.477669,-324.533020,0.048885,0.000000
3.410000,-0.012283,-324.444061,0.001733,0.001991,0.050568,-0.054639,-0.002783,0.505677,-324.444061,0.051713,0.000000
3.580000,-0.013031,-324.533020,0.001858,0.002105,0.053456,-0.057965,-0.002953,0.534556,-324.533020,0.054557,0.000000
3.750000,0.028679,-324.533020,0.001970,0.002219,0.056352,0.127570,0.006499,0.563522,-324.533020,0.057384,0.000000
3.920000,0.056229,-324.533020,0.002078,0.002332,0.059223,0.250117,0.012742,0.592226,-324.533020,0.060211,0.000000
4.090000,0.071129,-324.577515,0.002190,0.002443,0.062059,0.316397,0.016118,0.620587,-324.577515,0.063056,0.000000
4.260000,0.080063,-324.577515,0.002320,0.002549,0.064738,0.356137,0.018143,0.647384,-324.577515,0.065883,0.000000
4.430000,0.058464,-324.533020,0.002423,0.002662,0.067609,0.260061,0.013248,0.676088,-324.533020,0.068710,0.000000
4.600000,0.052879,-324.577515,0.002539,0.002778,0.070549,0.235219,0.011983,0.705486,-324.577515,0.071538,0.000000
4.770000,0.033516,-324.621979,0.002656,0.002887,0.073324,0.149086,0.007595,0.733240,-324.621979,0.074382,0.000000
4.940000,0.028679,-324.577515,0.002781,0.002997,0.076116,0.127570,0.006499,0.761161,-324.577515,0.077209,0.000000
5.110000,0.017502,-324.621979,0.002893,0.003108,0.078935,0.077852,0.003966,0.789347,-324.621979,0.080036,0.000000
5.280000,0.072990,-324.666473,0.003005,0.003225,0.081918,0.324678,0.016540,0.819180,-324.666473,0.082880,0.000000
5.450000,0.060326,-324.666473,0.003117,0.003337,0.084754,0.268342,0.013670,0.847540,-324.666473,0.085708,0.000000
5.620000,0.114693,-324.666473,0.003234,0.003442,0.087434,0.510179,0.025990,0.874337,-324.666473,0.088535,0.000000
5.790000,0.169807,-324.710937,0.003341,0.003555,0.090287,0.755341,0.038479,0.902868,-324.710937,0.091379,0.000000
5.960001,0.214493,-324.666473,0.003479,0.003673,0.093287,0.954112,0.048605,0.932874,-324.666473,0.094207,0.000000
6.130000,0.258057,-324.621979,0.003583,0.003778,0.095967,1.147893,0.058476,0.959671,-324.621979,0.097034,0.000000
6.300000,0.355247,-324.710937,0.003682,0.003889,0.098768,1.580220,0.080500,0.987683,-324.710937,0.099861,0.000000
6.470000,0.500473,-324.755432,0.003803,0.004002,0.101648,2.226215,0.113409,1.016475,-324.755432,0.102705,0.000000
6.640000,0.625961,-324.755432,0.003902,-0.000008,-0.000199,2.784415,0.141845,-0.001995,-324.755432,-0.000043,0.000000
6.810000,0.574203,-324.710937,0.003919,-0.000008,-0.000208,2.554185,0.130116,-0.002082,-324.710937,-0.000043,0.000000
6.980000,0.550743,-324.755432,0.003902,-0.000009,-0.000216,2.449828,0.124800,-0.002165,-324.755432,-0.000043,0.000000
7.150001,0.542175,-324.755432,0.003915,-0.000009,-0.000225,2.411716,0.122859,-0.002252,-324.755432,-0.000034,0.000000
7.320000,0.555214,-324.799896,0.003898,-0.000009,-0.000225,2.469715,0.125813,-0.002252,-324.799896,0.000252,0.000000
7.490000,0.523186,-324.799896,0.003915,-0.000009,-0.000216,2.327246,0.118556,-0.002165,-324.799896,0.000529,0.000000
7.660000,0.562286,-324.844391,0.003911,-0.000002,-0.000052,2.501175,0.127416,-0.000519,-324.844391,0.000815,0.000000
7.830000,0.660591,-324.799896,0.003915,0.000009,0.000226,2.938456,0.149692,0.002256,-324.799896,0.001101,0.000000
8.000000,0.702667,-324.799896,0.003893,0.000020,0.000503,3.125620,0.159227,0.005030,-324.799896,0.001379,0.000000
8.170000,0.740654,-324.844391,0.003911,0.000031,0.000798,3.294594,0.167835,0.007979,-324.844391,0.001665,0.000000
8.340000,0.755920,-324.888855,0.003923,0.000044,0.001128,3.362502,0.171294,0.011275,-324.888855,0.001951,0.000000
8.510000,0.772301,-324.844391,0.003936,0.000053,0.001353,3.435365,0.175006,0.013531,-324.844391,0.002229,0.000000
8.680000,0.825554,-324.844391,0.003941,0.000066,0.001674,3.672247,0.187073,0.016741,-324.844391,0.002515,0.000000
8.850000,0.840820,-324.933350,0.003949,0.000079,0.002003,3.740155,0.190533,0.020033,-324.933350,0.002801,0.000000
9.020000,0.876938,-324.933350,0.003971,0.000090,0.002281,3.900815,0.198717,0.022808,-324.933350,0.003079,0.000000
9.190001,0.906357,-324.933350,0.003988,0.000099,0.002524,4.031676,0.205383,0.025238,-324.933350,0.003365,0.000000
9.360001,0.945831,-324.977814,0.003992,0.000108,0.002749,4.207268,0.214328,0.027493,-324.977814,0.003651,0.000000
9.530001,0.990883,-324.933350,0.004001,0.000123,0.003122,4.407667,0.224537,0.031222,-324.933350,0.003929,0.000000
9.700001,0.996101,-324.933350,0.003997,0.000133,0.003382,4.430880,0.225720,0.033822,-324.933350,0.004215,0.000000
9.870001,1.015465,-324.977814,0.004023,0.000143,0.003634,4.517013,0.230108,0.036339,-324.977814,0.004501,0.000000
10.040001,1.067970,-325.022308,0.004027,0.000155,0.003946,4.750569,0.242006,0.039461,-325.022308,0.004778,0.000000
10.210000,1.083977,-324.977814,0.004049,0.000167,0.004250,4.821769,0.245633,0.042497,-324.977814,0.005065,0.000000
10.380000,1.107437,-325.022308,0.004066,0.000177,0.004501,4.926126,0.250949,0.045010,-325.022308,0.005351,0.000000
10.550000,1.175209,-324.977814,0.004070,0.000188,0.004770,5.227591,0.266306,0.047697,-324.977814,0.005629,0.000000
10.720000,1.228462,-325.022308,0.004083,0.000198,0.005039,5.464473,0.278374,0.050388,-325.022308,0.005915,0.000000
10.890000,1.258995,-325.066803,0.004087,0.000208,0.005290,5.600290,0.285292,0.052901,-325.066803,0.006201,0.000000
11.060000,1.303307,-325.111267,0.004087,0.000220,0.005585,5.797397,0.295334,0.055850,-325.111267,0.006478,0.000000
11.230000,1.371078,-325.066803,0.004105,0.000229,0.005828,6.098862,0.310691,0.058280,-325.066803,0.006764,0.000000
11.400001,1.420601,-325.066803,0.004105,0.000239,0.006079,6.319149,0.321913,0.060793,-325.066803,0.007051,0.000000
11.570001,1.488373,-325.111267,0.004118,0.000257,0.006539,6.620613,0.337270,0.065392,-325.111267,0.007328,0.000000
11.740001,1.540512,-325.155762,0.004130,0.000269,0.006834,6.852540,0.349085,0.068340,-325.155762,0.007614,0.000000
11.910001,1.608650,-325.111267,0.004152,0.000280,0.007120,7.155633,0.364525,0.071201,-325.111267,0.007901,0.000000
12.080001,1.641052,-325.066803,0.004156,0.000291,0.007380,7.299765,0.371868,0.073802,-325.066803,0.008178,0.000000
12.250001,1.704727,-325.111267,0.004165,0.000301,0.007641,7.583005,0.386297,0.076406,-325.111267,0.008464,0.000000
12.420001,1.778824,-325.200226,0.004174,0.000310,0.007874,7.912604,0.403087,0.078745,-325.200226,0.008750,0.000000
12.590000,1.856651,-325.200226,0.004199,0.000321,0.008161,8.258798,0.420723,0.081606,-325.200226,0.009028,0.000000
12.760000,1.960175,-325.155762,0.004208,0.000334,0.008473,8.719292,0.444182,0.084729,-325.155762,0.009314,0.000000
12.930000,2.017891,-325.111267,0.004191,0.000343,0.008716,8.976027,0.457261,0.087159,-325.111267,0.009600,0.000000
13.100000,2.067787,-325.200226,0.004221,0.000352,0.008941,9.197977,0.468567,0.089411,-325.200226,0.009878,0.000000
13.270000,2.191040,-325.200226,0.004217,0.000363,0.009228,9.746233,0.496497,0.092276,-325.200226,0.010164,0.000000
13.440001,2.258072,-325.289185,0.004238,0.000373,0.009470,10.044406,0.511686,0.094702,-325.289185,0.010450,0.000000
13.610001,2.444260,-325.289185,0.004260,0.000392,0.009956,10.872610,0.553877,0.099558,-325.289185,0.010728,0.000000
13.780001,2.505699,-325.155762,0.004273,0.000403,0.010225,11.145906,0.567800,0.102249,-325.155762,0.011014,0.000000
13.950001,2.595810,-325.289185,0.004281,0.000412,0.010468,11.546740,0.588219,0.104675,-325.289185,0.011300,0.000000
14.120001,2.694862,-325.244720,0.004273,0.000423,0.010754,11.987347,0.610665,0.107536,-325.244720,0.011586,0.000000
14.290001,2.770454,-325.333679,0.004299,0.000430,0.010927,12.323597,0.627794,0.109270,-325.333679,0.011864,0.000000
14.460001,2.840836,-325.333679,0.004294,0.000440,0.011170,12.636668,0.643743,0.111700,-325.333679,0.012150,0.000000
14.630001,3.036331,-325.333679,0.004286,0.000452,0.011491,13.506275,0.688043,0.114909,-325.333679,0.012436,0.000000
14.800001,3.321564,-325.333679,0.004320,0.000470,0.011933,14.775053,0.752677,0.119330,-325.333679,0.012714,0.000000
14.970000,3.358803,-325.378143,0.004333,0.000478,0.012132,14.940701,0.761116,0.121325,-325.378143,0.013000,0.000000
15.140000,3.404602,-325.378143,0.004333,0.000484,0.012289,15.144426,0.771494,0.122888,-325.378143,0.013286,0.000000
15.310000,3.633240,-325.378143,0.004346,0.000496,0.012592,16.161457,0.823304,0.125923,-325.378143,0.013564,0.000000
15.480000,3.935234,-325.289185,0.004350,0.000512,0.013009,17.504795,0.891737,0.130087,-325.289185,0.013850,0.000000
15.650001,4.146370,-325.378143,0.004372,0.000528,0.013399,18.443975,0.939581,0.133989,-325.378143,0.014136,0.000000
15.820001,4.263672,-325.422638,0.004372,0.000537,0.013642,18.965759,0.966162,0.136415,-325.422638,0.014413,0.000000
15.990001,4.412987,-325.467133,0.004389,0.000545,0.013850,19.629946,0.999997,0.138497,-325.467133,0.014700,0.000000
16.160000,4.598434,-325.467133,0.004393,0.000556,0.014118,20.454859,1.042020,0.141184,-325.467133,0.014986,0.000000
16.330000,4.663223,-325.422638,0.004411,0.000562,0.014266,20.743053,1.056702,0.142660,-325.422638,0.015263,0.000000
16.500000,4.885902,-325.467133,0.004411,0.000573,0.014552,21.733580,1.107161,0.145522,-325.467133,0.015549,0.000000
16.670000,5.274658,-325.467133,0.004402,0.000586,0.014882,23.462851,1.195255,0.148818,-325.467133,0.015836,0.000000
16.840000,5.633255,-325.556091,0.004424,0.000601,0.015255,25.057970,1.276514,0.152546,-325.556091,0.016113,0.000000
17.010000,5.733795,-325.467133,0.004432,0.000608,0.015454,25.505196,1.299296,0.154541,-325.467133,0.016399,0.000000
17.180000,6.000038,-325.467133,0.004441,0.000620,0.015740,26.689503,1.359628,0.157402,-325.467133,0.016686,0.000000
17.350000,6.191071,-325.511597,0.004458,0.000632,0.016052,27.539257,1.402917,0.160525,-325.511597,0.016963,0.000000
17.520000,6.780533,-325.511597,0.004475,0.000651,0.016529,30.161316,1.536491,0.165294,-325.511597,0.017249,0.000000
17.690001,7.002098,-325.556091,0.004493,0.000662,0.016807,31.146889,1.586698,0.168068,-325.556091,0.017535,0.000000
17.860001,7.265366,-325.600555,0.004493,0.000672,0.017067,32.317959,1.646355,0.170672,-325.600555,0.017813,0.000000
18.030001,7.204666,-325.467133,0.004493,0.000676,0.017171,32.047955,1.632601,0.171713,-325.467133,0.018099,0.000000
18.200001,7.588585,-325.556091,0.004497,0.000687,0.017449,33.755711,1.719598,0.174487,-325.556091,0.018386,0.000000
18.370001,7.789291,-325.556091,0.004514,0.000694,0.017640,34.648499,1.765079,0.176395,-325.556091,0.018663,0.000000
18.540001,8.257362,-325.645050,0.004531,0.000708,0.017987,36.730583,1.871145,0.179866,-325.645050,0.018949,0.000000
18.710001,8.817413,-325.600555,0.004540,0.000724,0.018386,39.221813,1.998054,0.183855,-325.600555,0.019235,0.000000
18.880001,8.980881,-325.600555,0.004540,0.000732,0.018602,39.948952,2.035097,0.186020,-325.600555,0.019513,0.000000
19.050001,9.280273,-325.645050,0.004549,0.000743,0.018862,41.280720,2.102940,0.188624,-325.645050,0.019799,0.000000
19.220001,9.534599,-325.734009,0.004544,0.000751,0.019079,42.412014,2.160571,0.190793,-325.734009,0.020085,0.000000
19.390001,10.329247,-325.689514,0.004562,0.000774,0.019669,45.946785,2.340641,0.196690,-325.689514,0.020363,0.000000
19.560001,10.574638,-325.689514,0.004583,0.000785,0.019946,47.038342,2.396247,0.199464,-325.689514,0.020649,0.000000
19.730001,10.837906,-325.645050,0.004587,0.000796,0.020215,48.209412,2.455904,0.202151,-325.645050,0.020935,0.000000
19.900002,10.970467,-325.645050,0.004592,0.000805,0.020449,48.799072,2.485943,0.204494,-325.645050,0.021212,0.000000
20.070002,11.297783,-325.689514,0.004605,0.000813,0.020649,50.255047,2.560114,0.206489,-325.689514,0.021499,0.000000
20.240002,11.518974,-325.778473,0.004609,0.000820,0.020831,51.238956,2.610237,0.208309,-325.778473,0.021785,0.000000
20.410002,12.019440,-325.734009,0.004626,0.000833,0.021161,53.465137,2.723644,0.211606,-325.734009,0.022063,0.000000
20.580002,12.481186,-325.778473,0.004631,0.000847,0.021507,55.519089,2.828277,0.215073,-325.778473,0.022349,0.000000
20.750002,12.904572,-325.734009,0.004626,0.000859,0.021811,57.402401,2.924218,0.218108,-325.734009,0.022635,0.000000
20.920000,13.012558,-325.778473,0.004626,0.000866,0.021984,57.882748,2.948688,0.219842,-325.778473,0.022912,0.000000
21.090000,13.272102,-325.822968,0.004635,0.000876,0.022253,59.037258,3.007501,0.222533,-325.822968,0.023198,0.000000
21.260000,14.147926,-325.867462,0.004661,0.000896,0.022756,62.933121,3.205966,0.227563,-325.867462,0.023485,0.000000
21.430000,14.376190,-325.822968,0.004665,0.000907,0.023042,63.948486,3.257691,0.230424,-325.822968,0.023762,0.000000
21.600000,14.549713,-325.822968,0.004678,0.000916,0.023268,64.720360,3.297012,0.232676,-325.822968,0.024048,0.000000
21.770000,14.810745,-325.867462,0.004687,0.000927,0.023545,65.881485,3.356163,0.235455,-325.867462,0.024335,0.000000
21.940001,15.132477,-325.867462,0.004704,0.000937,0.023805,67.312622,3.429068,0.238055,-325.867462,0.024612,0.000000
22.110001,15.306000,-326.000885,0.004712,0.000944,0.023979,68.084488,3.468389,0.239788,-326.000885,0.024898,0.000000
22.280001,15.739441,-325.867462,0.004708,0.000956,0.024291,70.012527,3.566608,0.242911,-325.867462,0.025184,0.000000
22.450001,16.322205,-325.911926,0.004717,0.000971,0.024664,72.604790,3.698664,0.246639,-325.911926,0.025470,0.000000
22.620001,16.722878,-326.000885,0.004725,0.000984,0.024985,74.387077,3.789458,0.249848,-326.000885,0.025748,0.000000
22.790001,16.887466,-325.956421,0.004730,0.000993,0.025210,75.119202,3.826755,0.252104,-325.956421,0.026034,0.000000
22.960001,16.976463,-325.956421,0.004743,0.000999,0.025375,75.515083,3.846922,0.253751,-325.956421,0.026321,0.000000
23.130001,17.587158,-325.911926,0.004747,0.001015,0.025774,78.231590,3.985307,0.257740,-325.911926,0.026598,0.000000
23.300001,18.058578,-325.956421,0.004751,0.001029,0.026130,80.328568,4.092133,0.261298,-325.956421,0.026884,0.000000
23.470001,18.182953,-325.956421,0.004764,0.001037,0.026346,80.881813,4.120316,0.263463,-325.956421,0.027170,0.000000
23.640001,18.549362,-326.000885,0.004777,0.001049,0.026641,82.511681,4.203345,0.266415,-326.000885,0.027448,0.000000
23.810001,18.814491,-326.045380,0.004799,0.001058,0.026884,83.691040,4.263424,0.268841,-326.045380,0.027734,0.000000
23.980001,19.008125,-326.000885,0.004803,0.001069,0.027153,84.552361,4.307303,0.271528,-326.000885,0.028020,0.000000
24.150002,19.341774,-326.000885,0.004807,0.001080,0.027422,86.036507,4.382909,0.274219,-326.000885,0.028298,0.000000
24.320002,19.710426,-326.045380,0.004794,0.001092,0.027734,87.676353,4.466446,0.277342,-326.045380,0.028584,0.000000
24.490002,20.101044,-326.045380,0.004825,0.001102,0.027986,89.413910,4.554962,0.279855,-326.045380,0.028870,0.000000
24.660002,20.333405,-326.045380,0.004820,0.001112,0.028246,90.447502,4.607615,0.282455,-326.045380,0.029147,0.000000
24.830002,20.590340,-326.134338,0.004838,0.001120,0.028445,91.590408,4.665838,0.284450,-326.134338,0.029434,0.000000
25.000002,21.011490,-326.178802,0.004855,0.001134,0.028809,93.463776,4.761271,0.288095,-326.178802,0.029720,0.000000
25.170002,21.665749,-326.134338,0.004846,0.001150,0.029208,96.374062,4.909529,0.292084,-326.134338,0.029998,0.000000
25.340002,21.906303,-326.134338,0.004855,0.001161,0.029486,97.444107,4.964039,0.294858,-326.134338,0.030284,0.000000
25.510002,22.185211,-326.178802,0.004859,0.001173,0.029798,98.684746,5.027241,0.297981,-326.178802,0.030570,0.000000
25.680000,22.253357,-326.089844,0.004885,0.001182,0.030015,98.987877,5.042683,0.300150,-326.089844,0.030847,0.000000
25.850000,22.409004,-326.178802,0.004881,0.001191,0.030240,99.680229,5.077953,0.302402,-326.178802,0.031133,0.000000
26.020000,22.865906,-326.178802,0.004889,0.001203,0.030552,101.712631,5.181489,0.305524,-326.178802,0.031420,0.000000
26.190001,23.332863,-326.223297,0.004907,0.001217,0.030900,103.789757,5.287302,0.308995,-326.223297,0.031697,0.000000
26.360001,23.654594,-326.223297,0.004919,0.001227,0.031168,105.220894,5.360208,0.311682,-326.223297,0.031983,0.000000
26.530001,23.917488,-326.223297,0.004937,0.001236,0.031403,106.390297,5.419780,0.314025,-326.223297,0.032270,0.000000
26.700001,24.113724,-326.178802,0.004932,0.001245,0.031628,107.263199,5.464248,0.316277,-326.178802,0.032547,0.000000
26.870001,24.252991,-326.223297,0.004928,0.001254,0.031845,107.882690,5.495806,0.318446,-326.223297,0.032833,0.000000
27.040001,25.095299,-326.223297,0.004954,0.001271,0.032278,111.629463,5.686676,0.322783,-326.223297,0.033119,0.000000
27.210001,25.407722,-326.223297,0.004980,0.001282,0.032573,113.019196,5.757473,0.325732,-326.223297,0.033397,0.000000
27.380001,25.625931,-326.267761,0.004980,0.001293,0.032851,113.989830,5.806919,0.328506,-326.267761,0.033683,0.000000
27.550001,25.725357,-326.223297,0.004971,0.001301,0.033050,114.432106,5.829449,0.330501,-326.223297,0.033969,0.000000
27.720001,26.098099,-326.312256,0.004993,0.001313,0.033362,116.090141,5.913914,0.333623,-326.312256,0.034247,0.000000
27.890001,26.313705,-326.356750,0.004997,0.001325,0.033666,117.049210,5.962770,0.336659,-326.356750,0.034533,0.000000
28.060001,26.693153,-326.356750,0.005006,0.001336,0.033943,118.737076,6.048755,0.339433,-326.356750,0.034819,0.000000
28.230001,27.103874,-326.312256,0.005006,0.001346,0.034178,120.564056,6.141826,0.341776,-326.312256,0.035097,0.000000
28.400002,27.455399,-326.312256,0.005027,0.001358,0.034499,122.127716,6.221482,0.344986,-326.312256,0.035383,0.000000
28.570002,27.746590,-326.356750,0.005014,0.001369,0.034785,123.422997,6.287467,0.347847,-326.356750,0.035669,0.000000
28.740002,27.787552,-326.445709,0.005032,0.001375,0.034923,123.605202,6.296749,0.349232,-326.445709,0.035947,0.000000
28.910002,28.085823,-326.445709,0.005049,0.001387,0.035227,124.931984,6.364338,0.352268,-326.445709,0.036233,0.000000
29.080002,28.762054,-326.445709,0.005057,0.001399,0.035539,127.940010,6.517575,0.355390,-326.445709,0.036519,0.000000
29.250002,29.236458,-326.445709,0.005053,0.001414,0.035903,130.050262,6.625076,0.359031,-326.445709,0.036796,0.000000
29.420002,29.586113,-326.356750,0.005066,0.001424,0.036172,131.605606,6.704309,0.361722,-326.356750,0.037083,0.000000
29.590002,29.964813,-326.445709,0.005079,0.001436,0.036484,133.290146,6.790123,0.364845,-326.445709,0.037369,0.000000
29.760002,30.207977,-326.490173,0.005079,0.001447,0.036745,134.371796,6.845225,0.367445,-326.490173,0.037646,0.000000
29.930002,30.490608,-326.445709,0.005105,0.001458,0.037022,135.628998,6.909270,0.370219,-326.445709,0.037933,0.000000
30.100002,31.058472,-326.445709,0.005101,0.001470,0.037343,138.154984,7.037950,0.373429,-326.445709,0.038219,0.000000
30.270002,31.465477,-326.534668,0.005105,0.001483,0.037673,139.965439,7.130179,0.376726,-326.534668,0.038496,0.000000
30.440001,31.802475,-326.490173,0.005113,0.001493,0.037933,141.464478,7.206544,0.379326,-326.490173,0.038782,0.000000
30.610001,31.987541,-326.534668,0.005131,0.001501,0.038132,142.287689,7.248480,0.381321,-326.534668,0.039069,0.000000
30.780001,32.257141,-326.490173,0.005144,0.001512,0.038409,143.486923,7.309573,0.384095,-326.490173,0.039355,0.000000
30.950001,32.966881,-326.534668,0.005148,0.001527,0.038782,146.644012,7.470402,0.387823,-326.534668,0.039632,0.000000
31.120001,33.339630,-326.579132,0.005139,0.001538,0.039060,148.302078,7.554868,0.390601,-326.579132,0.039919,0.000000
31.290001,33.808441,-326.623627,0.005165,0.001550,0.039364,150.387451,7.661102,0.393637,-326.623627,0.040205,0.000000
31.460001,34.093307,-326.623627,0.005178,0.001560,0.039615,151.654602,7.725654,0.396150,-326.623627,0.040482,0.000000
31.630001,34.480202,-326.579132,0.005187,0.001570,0.039884,153.375595,7.813325,0.398837,-326.579132,0.040768,0.000000
31.800001,34.751289,-326.579132,0.005182,0.001580,0.040127,154.581451,7.874755,0.401267,-326.579132,0.041055,0.000000
31.970001,35.179520,-326.623627,0.005174,0.001591,0.040404,156.486313,7.971793,0.404041,-326.623627,0.041332,0.000000
32.140003,35.694138,-326.712585,0.005182,0.001602,0.040682,158.775452,8.088408,0.406816,-326.712585,0.041618,0.000000
32.310001,36.052734,-326.712585,0.005195,0.001614,0.040994,160.370575,8.169666,0.409938,-326.712585,0.041904,0.000000
32.480003,36.434418,-326.668091,0.005217,0.001622,0.041193,162.068390,8.256157,0.411933,-326.668091,0.042182,0.000000
32.650002,36.659698,-326.623627,0.005204,0.001629,0.041375,163.070480,8.307207,0.413753,-326.623627,0.042468,0.000000
32.820000,37.781662,-326.712585,0.005217,0.001649,0.041887,168.061234,8.561447,0.418871,-326.712585,0.042754,0.000000
32.990002,38.290688,-326.712585,0.005234,0.001661,0.042182,170.325485,8.676793,0.421819,-326.712585,0.043032,0.000000
33.160000,38.752808,-326.757080,0.005234,0.001673,0.042485,172.381104,8.781512,0.424854,-326.757080,0.043318,0.000000
33.330002,39.116241,-326.757080,0.005251,0.001684,0.042772,173.997726,8.863867,0.427716,-326.757080,0.043604,0.000000
33.500000,39.633095,-326.757080,0.005256,0.001696,0.043066,176.296814,8.980988,0.430664,-326.757080,0.043882,0.000000
33.670002,39.830452,-326.757080,0.005264,0.001704,0.043275,177.174698,9.025709,0.432746,-326.757080,0.044168,0.000000
33.840000,40.214371,-326.846039,0.005269,0.001713,0.043518,178.882462,9.112707,0.435176,-326.846039,0.044454,0.000000
34.010002,40.723404,-326.846039,0.005282,0.001724,0.043795,181.146744,9.228056,0.437950,-326.846039,0.044732,0.000000
34.180000,41.496071,-326.801544,0.005299,0.001738,0.044133,184.583740,9.403144,0.441334,-326.801544,0.045018,0.000000
34.350002,41.808121,-326.757080,0.005295,0.001745,0.044324,185.971802,9.473855,0.443241,-326.757080,0.045304,0.000000
34.520000,42.176025,-326.846039,0.005299,0.001755,0.044575,187.608337,9.557224,0.445755,-326.846039,0.045581,0.000000
34.690002,42.939392,-326.846039,0.005307,0.001769,0.044940,191.003952,9.730206,0.449400,-326.846039,0.045868,0.000000
34.860001,43.684875,-326.890503,0.005325,0.001784,0.045321,194.320038,9.899135,0.453215,-326.890503,0.046154,0.000000
35.030003,44.405792,-326.801544,0.005320,0.001796,0.045616,197.526825,10.062496,0.456163,-326.801544,0.046432,0.000000
35.200001,44.782631,-326.846039,0.005316,0.001805,0.045842,199.203094,10.147889,0.458415,-326.846039,0.046718,0.000000
35.370003,45.197083,-326.846039,0.005325,0.001814,0.046085,201.046661,10.241806,0.460845,-326.846039,0.047004,0.000000
35.540001,45.683403,-326.890503,0.005329,0.001825,0.046353,203.209930,10.352008,0.463532,-326.890503,0.047281,0.000000
35.710003,45.950394,-326.934998,0.005342,0.001834,0.046596,204.397552,10.412508,0.465962,-326.934998,0.047567,0.000000
35.880001,46.177170,-326.934998,0.005351,0.001843,0.046813,205.406311,10.463896,0.468131,-326.934998,0.047854,0.000000
36.050003,47.373604,-326.934998,0.005355,0.001860,0.047246,210.728317,10.735012,0.472465,-326.934998,0.048131,0.000000
36.220001,48.316078,-326.979462,0.005355,0.001873,0.047576,214.920654,10.948580,0.475761,-326.979462,0.048418,0.000000
36.390003,48.631844,-326.934998,0.005364,0.001881,0.047767,216.325241,11.020133,0.477669,-326.934998,0.048704,0.000000
36.560001,49.055977,-326.934998,0.005368,0.001890,0.048010,218.211884,11.116242,0.480099,-326.934998,0.048981,0.000000
36.730003,49.426865,-326.979462,0.005389,0.001899,0.048244,219.861679,11.200288,0.482438,-326.979462,0.049267,0.000000
36.900002,50.805016,-326.934998,0.005376,0.001919,0.048747,225.991989,11.512581,0.487468,-326.934998,0.049553,0.000000
37.070004,51.493156,-326.979462,0.005398,0.001930,0.049024,229.052994,11.668516,0.490242,-326.979462,0.049831,0.000000
37.240002,52.016342,-327.023956,0.005385,0.001940,0.049285,231.380249,11.787072,0.492846,-327.023956,0.050117,0.000000
37.410004,52.228966,-327.068420,0.005411,0.001947,0.049458,232.326050,11.835253,0.494580,-327.068420,0.050403,0.000000
37.580002,52.681023,-327.023956,0.005411,0.001957,0.049710,234.336899,11.937690,0.497097,-327.023956,0.050681,0.000000
37.750000,53.128990,-327.023956,0.005420,0.001966,0.049935,236.329544,12.039202,0.499349,-327.023956,0.050967,0.000000
37.920002,53.722176,-327.068420,0.005415,0.001977,0.050204,238.968170,12.173619,0.502040,-327.068420,0.051253,0.000000
38.090000,54.710457,-327.112915,0.005411,0.001989,0.050516,243.364273,12.397567,0.505159,-327.112915,0.051531,0.000000
38.260002,55.488342,-327.068420,0.005445,0.002002,0.050863,246.824478,12.573838,0.508629,-327.068420,0.051817,0.000000
38.430000,55.907631,-327.023956,0.005445,0.002009,0.051028,248.689560,12.668850,0.510276,-327.023956,0.052103,0.000000
38.600002,56.721268,-327.112915,0.005454,0.002022,0.051357,252.308807,12.853223,0.513572,-327.112915,0.052381,0.000000
38.770000,58.149689,-327.112915,0.005454,0.002042,0.051860,258.662720,13.176908,0.518603,-327.112915,0.052667,0.000000
38.940002,59.032211,-327.201874,0.005454,0.002054,0.052164,262.588379,13.376890,0.521638,-327.201874,0.052953,0.000000
39.110001,59.616089,-327.157410,0.005476,0.002064,0.052433,265.185608,13.509199,0.524325,-327.157410,0.053239,0.000000
39.280003,60.013786,-327.112915,0.005476,0.002072,0.052623,266.954651,13.599319,0.526233,-327.112915,0.053517,0.000000
39.450001,60.418182,-327.068420,0.005471,0.002082,0.052884,268.753510,13.690956,0.528837,-327.068420,0.053803,0.000000
39.620003,60.849388,-327.112915,0.005458,0.002092,0.053126,270.671600,13.788669,0.531263,-327.112915,0.054089,0.000000
39.790001,61.671585,-327.246368,0.005476,0.002100,0.053352,274.328918,13.974981,0.533519,-327.246368,0.054367,0.000000
39.960003,62.267006,-327.201874,0.005489,0.002112,0.053647,276.977478,14.109905,0.536467,-327.201874,0.054653,0.000000
40.130001,63.574783,-327.201874,0.005506,0.002126,0.053993,282.794769,14.406252,0.539934,-327.201874,0.054939,0.000000
40.300003,63.958328,-327.201874,0.005501,0.002133,0.054176,284.500854,14.493164,0.541759,-327.201874,0.055216,0.000000
40.470001,64.689285,-327.201874,0.005506,0.002144,0.054453,287.752319,14.658802,0.544533,-327.201874,0.055502,0.000000
40.640003,65.814606,-327.335327,0.005497,0.002161,0.054895,292.757996,14.913802,0.548954,-327.335327,0.055789,0.000000
40.810001,67.292542,-327.246368,0.005510,0.002176,0.055277,299.332184,15.248708,0.552773,-327.246368,0.056066,0.000000
40.980003,67.232590,-327.246368,0.005519,0.002171,0.055156,299.065491,15.235123,0.551558,-327.246368,0.055347,0.000000
41.150002,66.814423,-327.290833,0.005527,0.002171,0.055147,297.205383,15.140365,0.551471,-327.290833,0.055347,0.000000
41.320004,66.480026,-327.335327,0.005514,0.002171,0.055147,295.717926,15.064590,0.551471,-327.335327,0.055147,0.000000
41.490002,66.192184,-327.335327,0.005532,0.002171,0.055138,294.437531,14.999363,0.551383,-327.335327,0.055147,0.000000
41.660004,65.953125,-327.335327,0.005523,0.002171,0.055138,293.374146,14.945192,0.551383,-327.335327,0.055147,0.000000
41.830002,65.728577,-327.379791,0.005532,0.002171,0.055138,292.375305,14.894309,0.551383,-327.379791,0.055147,0.000000
42.000004,65.551712,-327.290833,0.005545,0.002170,0.055130,291.588593,14.854230,0.551296,-327.290833,0.055147,0.000000
42.170002,65.379303,-327.424286,0.005536,0.002170,0.055130,290.821655,14.815162,0.551296,-327.424286,0.055147,0.000000
42.340000,65.232208,-327.379791,0.005532,0.002170,0.055130,290.167358,14.781830,0.551296,-327.379791,0.055147,0.000000
42.510002,65.095184,-327.424286,0.005536,0.002170,0.055130,289.557831,14.750780,0.551296,-327.424286,0.055147,0.000000
42.680000,64.978256,-327.424286,0.005540,0.002170,0.055130,289.037720,14.724283,0.551296,-327.424286,0.055147,0.000000
42.850002,64.858719,-327.379791,0.005532,0.002170,0.055130,288.505981,14.697195,0.551296,-327.379791,0.055147,0.000000
43.020000,64.755569,-327.424286,0.005514,0.002170,0.055130,288.047150,14.673822,0.551296,-327.424286,0.055147,0.000000
43.190002,64.657272,-327.513245,0.005540,0.002170,0.055130,287.609924,14.651547,0.551296,-327.513245,0.055147,0.000000
43.360001,64.570129,-327.468750,0.005532,0.002170,0.055130,287.222290,14.631801,0.551296,-327.468750,0.055147,0.000000
43.530003,64.488205,-327.468750,0.005558,0.002170,0.055130,286.857849,14.613236,0.551296,-327.468750,0.055147,0.000000
43.700001,64.411880,-327.468750,0.005532,0.002170,0.055130,286.518341,14.595941,0.551296,-327.468750,0.055147,0.000000
43.870003,64.338150,-327.513245,0.005545,0.002170,0.055130,286.190399,14.579233,0.551296,-327.513245,0.055147,0.000000
44.040001,64.253983,-327.513245,0.005540,0.002170,0.055130,285.815979,14.560161,0.551296,-327.513245,0.055147,0.000000
44.210003,64.193298,-327.557709,0.005549,0.002170,0.055121,285.546051,14.546410,0.551209,-327.557709,0.055147,0.000000
44.380001,64.124023,-327.513245,0.005549,0.002170,0.055121,285.237915,14.530711,0.551209,-327.513245,0.055147,0.000000
44.550003,64.068176,-327.468750,0.005536,0.002170,0.055121,284.989471,14.518057,0.551209,-327.468750,0.055147,0.000000
44.720001,64.015305,-327.557709,0.005536,0.002170,0.055121,284.754303,14.506076,0.551209,-327.557709,0.055147,0.000000
44.890003,63.956833,-327.557709,0.005545,0.002170,0.055121,284.494202,14.492826,0.551209,-327.557709,0.055147,0.000000
45.060001,63.907303,-327.602203,0.005545,0.002170,0.055121,284.273895,14.481603,0.551209,-327.602203,0.055147,0.000000
45.230003,63.867096,-327.602203,0.005558,0.002170,0.055121,284.095032,14.472491,0.551209,-327.602203,0.055147,0.000000
45.400002,63.813477,-327.557709,0.005545,0.002170,0.055121,283.856506,14.460340,0.551209,-327.557709,0.055147,0.000000
45.570004,63.757996,-327.646698,0.005540,0.002170,0.055121,283.609741,14.447768,0.551209,-327.646698,0.055147,0.000000
45.740002,63.713303,-327.602203,0.005545,0.002170,0.055121,283.410919,14.437641,0.551209,-327.602203,0.055147,0.000000
45.910004,63.676437,-327.602203,0.005558,0.002170,0.055121,283.246948,14.429287,0.551209,-327.602203,0.055147,0.000000
46.080002,63.637711,-327.646698,0.005545,0.002170,0.055121,283.074677,14.420511,0.551209,-327.646698,0.055147,0.000000
46.250004,63.585587,-327.691162,0.005566,0.002170,0.055121,282.842804,14.408700,0.551209,-327.691162,0.055147,0.000000
46.420002,63.566589,-327.691162,0.005540,0.002170,0.055121,282.758301,14.404395,0.551209,-327.691162,0.055147,0.000000
46.590004,63.512589,-327.691162,0.005549,0.002170,0.055121,282.518097,14.392159,0.551209,-327.691162,0.055147,0.000000
46.760002,63.469772,-327.735657,0.005553,0.002170,0.055121,282.327637,14.382456,0.551209,-327.735657,0.055147,0.000000
46.930004,63.444077,-327.735657,0.005562,0.002170,0.055121,282.213348,14.376633,0.551209,-327.735657,0.055147,0.000000
47.100002,63.415771,-327.735657,0.005566,0.002170,0.055121,282.087433,14.370219,0.551209,-327.735657,0.055147,0.000000
47.270000,63.367737,-327.735657,0.005545,0.002170,0.055121,281.873779,14.359334,0.551209,-327.735657,0.055147,0.000000
47.440002,63.346512,-327.824615,0.005545,0.002170,0.055121,281.779358,14.354525,0.551209,-327.824615,0.055147,0.000000
47.610001,63.302200,-327.780121,0.005553,0.002170,0.055121,281.582245,14.344483,0.551209,-327.780121,0.055147,0.000000
47.780003,63.299225,-327.780121,0.005545,0.002170,0.055121,281.569000,14.343809,0.551209,-327.780121,0.055147,0.000000
47.950001,63.238159,-327.780121,0.005553,0.002170,0.055121,281.297394,14.329971,0.551209,-327.780121,0.055147,0.000000
48.120003,63.221405,-327.824615,0.005536,0.002170,0.055121,281.222870,14.326175,0.551209,-327.824615,0.055147,0.000000
48.290001,63.203156,-327.824615,0.005553,0.002170,0.055121,281.141663,14.322040,0.551209,-327.824615,0.055147,0.000000
48.460003,63.159210,-327.869080,0.005562,0.002170,0.055121,280.946198,14.312082,0.551209,-327.869080,0.055147,0.000000
48.630001,63.137985,-327.824615,0.005545,0.002170,0.055121,280.851776,14.307272,0.551209,-327.824615,0.055147,0.000000
48.800003,63.114151,-327.869080,0.005549,0.002170,0.055121,280.745758,14.301871,0.551209,-327.869080,0.055147,0.000000
48.970001,63.083618,-327.913574,0.005558,0.002170,0.055121,280.609955,14.294951,0.551209,-327.913574,0.055147,0.000000
49.140003,63.064629,-327.869080,0.005540,0.002170,0.055121,280.525482,14.290649,0.551209,-327.869080,0.055147,0.000000
49.310001,63.049736,-327.913574,0.005562,0.002170,0.055121,280.459229,14.287274,0.551209,-327.913574,0.055147,0.000000
49.480003,63.025902,-327.824615,0.005549,0.002170,0.055121,280.353210,14.281874,0.551209,-327.824615,0.055147,0.000000
49.650002,62.994255,-327.913574,0.005545,0.002170,0.055121,280.212433,14.274702,0.551209,-327.913574,0.055147,0.000000
49.820004,62.970047,-327.958038,0.005558,0.002170,0.055121,280.104767,14.269217,0.551209,-327.958038,0.055147,0.000000
49.990002,62.958130,-327.913574,0.005553,0.002170,0.055121,280.051758,14.266517,0.551209,-327.913574,0.055147,0.000000
50.160004,62.918663,-327.958038,0.005553,0.002170,0.055121,279.876190,14.257573,0.551209,-327.958038,0.055147,0.000000
50.330002,62.913818,-327.958038,0.005549,0.002170,0.055121,279.854645,14.256474,0.551209,-327.958038,0.055147,0.000000
50.500004,62.882912,-327.958038,0.005536,0.002170,0.055121,279.717163,14.249472,0.551209,-327.958038,0.055147,0.000000
50.670002,62.858337,-328.047028,0.005540,0.002170,0.055121,279.607849,14.243903,0.551209,-328.047028,0.055147,0.000000
50.840004,62.844185,-328.047028,0.005545,0.002170,0.055121,279.544891,14.240696,0.551209,-328.047028,0.055147,0.000000
51.010002,62.817375,-328.091492,0.005558,0.002170,0.055121,279.425629,14.234620,0.551209,-328.091492,0.055147,0.000000
51.180004,62.798759,-328.002533,0.005558,0.002170,0.055121,279.342834,14.230402,0.551209,-328.002533,0.055147,0.000000
51.350002,62.774178,-328.002533,0.005553,0.002170,0.055121,279.233490,14.224832,0.551209,-328.002533,0.055147,0.000000
51.520004,62.758911,-328.047028,0.005549,0.002170,0.055121,279.165588,14.221373,0.551209,-328.047028,0.055147,0.000000
51.690002,62.739548,-328.135986,0.005562,0.002170,0.055121,279.079437,14.216985,0.551209,-328.135986,0.055147,0.000000
51.860001,62.716461,-328.091492,0.005558,0.002170,0.055121,278.976746,14.211754,0.551209,-328.091492,0.055147,0.000000
52.030003,62.704178,-328.091492,0.005553,0.002170,0.055121,278.922119,14.208970,0.551209,-328.091492,0.055147,0.000000
52.200001,62.685928,-328.135986,0.005553,0.002170,0.055121,278.840942,14.204834,0.551209,-328.135986,0.055147,0.000000
52.370003,62.666191,-328.135986,0.005540,0.002170,0.055121,278.753143,14.200362,0.551209,-328.135986,0.055147,0.000000
52.540001,62.652046,-328.180450,0.005553,0.002170,0.055121,278.690216,14.197156,0.551209,-328.180450,0.055147,0.000000
52.710003,62.637520,-328.135986,0.005566,0.002170,0.055121,278.625610,14.193865,0.551209,-328.135986,0.055147,0.000000
52.880001,62.607727,-328.180450,0.005562,0.002170,0.055121,278.493073,14.187114,0.551209,-328.180450,0.055147,0.000000
53.050003,62.611824,-328.135986,0.005566,0.002170,0.055121,278.511292,14.188042,0.551209,-328.135986,0.055147,0.000000
53.220001,62.581665,-328.224945,0.005553,0.002170,0.055121,278.377136,14.181209,0.551209,-328.224945,0.055147,0.000000
53.390003,62.563049,-328.269409,0.005553,0.002170,0.055121,278.294342,14.176990,0.551209,-328.269409,0.055147,0.000000
53.560001,62.549637,-328.269409,0.005553,0.002170,0.055121,278.234680,14.173950,0.551209,-328.269409,0.055147,0.000000
53.730003,62.542564,-328.224945,0.005553,0.002170,0.055121,278.203217,14.172348,0.551209,-328.224945,0.055147,0.000000
53.900002,62.513519,-328.224945,0.005553,0.002170,0.055121,278.074036,14.165766,0.551209,-328.224945,0.055147,0.000000
54.070004,62.506447,-328.224945,0.005549,0.002170,0.055121,278.042572,14.164164,0.551209,-328.224945,0.055147,0.000000
54.240002,62.479263,-328.358368,0.005545,0.002170,0.055121,277.921631,14.158004,0.551209,-328.358368,0.055147,0.000000
54.410004,62.487457,-328.269409,0.005566,0.002170,0.055121,277.958099,14.159861,0.551209,-328.269409,0.055147,0.000000
54.580002,62.461014,-328.269409,0.005562,0.002170,0.055121,277.840454,14.153868,0.551209,-328.269409,0.055147,0.000000
54.750004,62.453568,-328.313904,0.005562,0.002170,0.055121,277.807343,14.152181,0.551209,-328.313904,0.055147,0.000000
54.920002,62.426384,-328.269409,0.005558,0.002170,0.055121,277.686432,14.146020,0.551209,-328.269409,0.055147,0.000000
55.090004,62.423035,-328.358368,0.005553,0.002170,0.055121,277.671539,14.145262,0.551209,-328.358368,0.055147,0.000000
55.260002,62.398827,-328.402863,0.005558,0.002170,0.055121,277.563843,14.139776,0.551209,-328.402863,0.055147,0.000000
55.430004,62.385422,-328.269409,0.005562,0.002170,0.055121,277.504211,14.136739,0.551209,-328.269409,0.055147,0.000000
55.600002,62.364571,-328.358368,0.005558,0.002170,0.055121,277.411469,14.132013,0.551209,-328.358368,0.055147,0.000000
55.770004,62.353401,-328.358368,0.005566,0.002170,0.055121,277.361786,14.129482,0.551209,-328.358368,0.055147,0.000000
55.940002,62.347069,-328.447357,0.005549,0.002170,0.055121,277.333618,14.128048,0.551209,-328.447357,0.055147,0.000000
56.110004,62.336273,-328.447357,0.005549,0.002170,0.055121,277.285583,14.125601,0.551209,-328.447357,0.055147,0.000000
56.280003,62.310951,-328.447357,0.005545,0.002170,0.055121,277.172943,14.119864,0.551209,-328.447357,0.055147,0.000000
56.450005,62.303871,-328.491821,0.005549,0.002170,0.055121,277.141449,14.118258,0.551209,-328.491821,0.055147,0.000000
56.620003,62.287491,-328.447357,0.005553,0.002170,0.055121,277.068604,14.114548,0.551209,-328.447357,0.055147,0.000000
56.790001,62.275948,-328.536316,0.005558,0.002170,0.055121,277.017242,14.111932,0.551209,-328.536316,0.055147,0.000000
56.960003,62.256210,-328.536316,0.005558,0.002170,0.055121,276.929443,14.107459,0.551209,-328.536316,0.055147,0.000000
57.130001,62.259560,-328.491821,0.005558,0.002170,0.055121,276.944366,14.108218,0.551209,-328.491821,0.055147,0.000000
57.300003,62.233498,-328.491821,0.005536,0.002170,0.055121,276.828430,14.102312,0.551209,-328.491821,0.055147,0.000000
57.470001,62.223068,-328.491821,0.005545,0.002170,0.055121,276.782043,14.099948,0.551209,-328.491821,0.055147,0.000000
57.640003,62.210411,-328.580780,0.005558,0.002170,0.055121,276.725739,14.097080,0.551209,-328.580780,0.055147,0.000000
57.810001,62.206314,-328.580780,0.005553,0.002170,0.055121,276.707520,14.096152,0.551209,-328.580780,0.055147,0.000000
57.980003,62.185463,-328.536316,0.005562,0.002170,0.055121,276.614746,14.091427,0.551209,-328.536316,0.055147,0.000000
58.150002,62.170189,-328.536316,0.005549,0.002170,0.055121,276.546814,14.087966,0.551209,-328.536316,0.055147,0.000000
58.320004,62.175034,-328.669739,0.005562,0.002170,0.055121,276.568359,14.089065,0.551209,-328.669739,0.055147,0.000000
58.490002,62.154182,-328.669739,0.005553,0.002170,0.055121,276.475616,14.084339,0.551209,-328.669739,0.055147,0.000000
58.660004,62.144127,-328.625275,0.005570,0.002170,0.055121,276.430878,14.082060,0.551209,-328.625275,0.055147,0.000000
58.830002,62.138168,-328.580780,0.005553,0.002170,0.055121,276.404388,14.080710,0.551209,-328.580780,0.055147,0.000000
59.000004,62.124390,-328.669739,0.005540,0.002170,0.055121,276.343079,14.077588,0.551209,-328.669739,0.055147,0.000000
59.170002,62.119553,-328.625275,0.005549,0.002170,0.055121,276.321564,14.076491,0.551209,-328.625275,0.055147,0.000000
59.340004,62.100929,-328.669739,0.005553,0.002170,0.055121,276.238739,14.072272,0.551209,-328.669739,0.055147,0.000000
59.510002,62.078217,-328.625275,0.005566,0.002170,0.055121,276.137695,14.067125,0.551209,-328.625275,0.055147,0.000000
59.680004,62.079704,-328.625275,0.005558,0.002170,0.055121,276.144318,14.067462,0.551209,-328.625275,0.055147,0.000000
59.850002,62.074120,-328.714233,0.005558,0.002170,0.055121,276.119476,14.066196,0.551209,-328.714233,0.055147,0.000000
60.020004,62.065559,-328.758698,0.005553,0.002170,0.055121,276.081390,14.064257,0.551209,-328.758698,0.055147,0.000000
60.190002,62.056992,-328.758698,0.005545,0.002170,0.055121,276.043274,14.062316,0.551209,-328.758698,0.055147,0.000000
60.360004,62.042099,-328.803192,0.005558,0.002170,0.055121,275.977051,14.058940,0.551209,-328.803192,0.055147,0.000000
60.530003,62.026459,-328.758698,0.005553,0.002170,0.055121,275.907471,14.055396,0.551209,-328.758698,0.055147,0.000000
60.700005,62.029060,-328.758698,0.005549,0.002170,0.055121,275.919037,14.055986,0.551209,-328.758698,0.055147,0.000000
60.870003,62.010445,-328.758698,0.005540,0.002170,0.055121,275.836243,14.051767,0.551209,-328.758698,0.055147,0.000000
61.040005,62.002251,-328.803192,0.005549,0.002170,0.055121,275.799774,14.049911,0.551209,-328.803192,0.055147,0.000000
61.210003,61.990707,-328.847656,0.005566,0.002170,0.055121,275.748444,14.047296,0.551209,-328.847656,0.055147,0.000000
61.380001,61.984375,-328.803192,0.005558,0.002170,0.055121,275.720276,14.045860,0.551209,-328.803192,0.055147,0.000000
61.550003,61.973953,-328.803192,0.005549,0.002170,0.055121,275.673920,14.043499,0.551209,-328.803192,0.055147,0.000000
61.720001,61.969482,-328.847656,0.005549,0.002170,0.055121,275.654022,14.042485,0.551209,-328.847656,0.055147,0.000000
61.890003,61.961662,-328.892151,0.005545,0.002170,0.055121,275.619232,14.040713,0.551209,-328.892151,0.055147,0.000000
62.060001,61.945656,-328.936646,0.005558,0.002170,0.055121,275.548035,14.037086,0.551209,-328.936646,0.055147,0.000000
62.230003,61.943787,-328.892151,0.005562,0.002170,0.055121,275.539734,14.036663,0.551209,-328.892151,0.055147,0.000000
62.400002,61.930016,-328.892151,0.005558,0.002170,0.055121,275.478455,14.033543,0.551209,-328.892151,0.055147,0.000000
62.570004,61.931877,-328.892151,0.005540,0.002170,0.055121,275.486755,14.033963,0.551209,-328.892151,0.055147,0.000000
62.740002,61.911392,-328.981110,0.005558,0.002170,0.055121,275.395630,14.029322,0.551209,-328.981110,0.055147,0.000000
62.910004,61.904320,-328.936646,0.005566,0.002170,0.055121,275.364166,14.027719,0.551209,-328.936646,0.055147,0.000000
63.080002,61.895378,-328.892151,0.005553,0.002170,0.055121,275.324402,14.025693,0.551209,-328.892151,0.055147,0.000000
63.250004,61.896873,-329.025604,0.005558,0.002170,0.055121,275.331055,14.026031,0.551209,-329.025604,0.055147,0.000000
63.420002,61.879372,-328.981110,0.005562,0.002170,0.055121,275.253204,14.022066,0.551209,-328.981110,0.055147,0.000000
63.590004,61.864105,-329.025604,0.005570,0.002170,0.055121,275.185272,14.018606,0.551209,-329.025604,0.055147,0.000000
63.760002,61.853302,-328.981110,0.005553,0.002170,0.055121,275.137238,14.016158,0.551209,-328.981110,0.055147,0.000000
63.930004,61.858887,-328.981110,0.005553,0.002170,0.055121,275.162079,14.017424,0.551209,-328.981110,0.055147,0.000000
64.100006,61.846230,-329.025604,0.005566,0.002170,0.055121,275.105774,14.014556,0.551209,-329.025604,0.055147,0.000000
64.270004,61.842880,-329.070068,0.005553,0.002170,0.055121,275.090881,14.013797,0.551209,-329.070068,0.055147,0.000000
64.440002,61.829842,-329.070068,0.005536,0.002170,0.055121,275.032867,14.010842,0.551209,-329.070068,0.055147,0.000000
64.610001,61.804520,-329.114563,0.005553,0.002170,0.055121,274.920227,14.005104,0.551209,-329.114563,0.055147,0.000000
64.780006,61.816811,-329.070068,0.005558,0.002170,0.055121,274.974915,14.007890,0.551209,-329.070068,0.055147,0.000000
64.950005,61.799683,-329.070068,0.005570,0.002170,0.055121,274.898712,14.004008,0.551209,-329.070068,0.055147,0.000000
65.120003,61.804520,-329.114563,0.005545,0.002170,0.055121,274.920227,14.005104,0.551209,-329.114563,0.055147,0.000000
65.290001,61.783669,-329.159027,0.005553,0.002170,0.055121,274.827484,14.000379,0.551209,-329.159027,0.055147,0.000000
65.460007,61.780319,-329.159027,0.005558,0.002170,0.055121,274.812592,13.999620,0.551209,-329.159027,0.055147,0.000000
65.630005,61.763931,-329.159027,0.005549,0.002170,0.055121,274.739685,13.995907,0.551209,-329.159027,0.055147,0.000000
65.800003,61.766167,-329.159027,0.005562,0.002170,0.055121,274.749634,13.996413,0.551209,-329.159027,0.055147,0.000000
65.970001,61.746063,-329.114563,0.005566,0.002170,0.055121,274.660217,13.991858,0.551209,-329.114563,0.055147,0.000000
66.139999,61.755371,-329.247986,0.005562,0.002170,0.055121,274.701599,13.993967,0.551209,-329.247986,0.055147,0.000000
66.310005,61.745316,-329.203522,0.005553,0.002170,0.055121,274.656891,13.991689,0.551209,-329.203522,0.055147,0.000000
66.480003,61.736748,-329.159027,0.005553,0.002170,0.055121,274.618774,13.989747,0.551209,-329.159027,0.055147,0.000000
66.650002,61.727066,-329.114563,0.005553,0.002170,0.055121,274.575714,13.987554,0.551209,-329.114563,0.055147,0.000000
66.820000,61.715157,-329.292480,0.005558,0.002170,0.055121,274.522736,13.984854,0.551209,-329.292480,0.055147,0.000000
66.990005,61.712921,-329.292480,0.005549,0.002170,0.055121,274.512787,13.984347,0.551209,-329.292480,0.055147,0.000000
67.160004,61.703613,-329.292480,0.005558,0.002170,0.055121,274.471375,13.982239,0.551209,-329.292480,0.055147,0.000000
67.330002,61.705475,-329.247986,0.005549,0.002170,0.055121,274.479675,13.982660,0.551209,-329.247986,0.055147,0.000000
67.500000,61.682014,-329.292480,0.005545,0.002170,0.055121,274.375305,13.977345,0.551209,-329.292480,0.055147,0.000000
67.670006,61.678658,-329.336975,0.005536,0.002170,0.055121,274.360382,13.976583,0.551209,-329.336975,0.055147,0.000000
67.840004,61.664513,-329.336975,0.005558,0.002170,0.055121,274.297455,13.973378,0.551209,-329.336975,0.055147,0.000000
68.010002,61.676056,-329.336975,0.005549,0.002170,0.055121,274.348785,13.975994,0.551209,-329.336975,0.055147,0.000000
68.180000,61.655205,-329.247986,0.005562,0.002170,0.055121,274.256042,13.971269,0.551209,-329.247986,0.055147,0.000000
68.350006,61.657066,-329.292480,0.005553,0.002170,0.055121,274.264343,13.971691,0.551209,-329.292480,0.055147,0.000000
68.520004,61.637329,-329.336975,0.005540,0.002170,0.055121,274.176544,13.967218,0.551209,-329.336975,0.055147,0.000000
68.690002,61.632858,-329.425934,0.005545,0.002170,0.055121,274.156647,13.966206,0.551209,-329.425934,0.055147,0.000000
68.860001,61.631371,-329.425934,0.005553,0.002170,0.055121,274.150024,13.965868,0.551209,-329.425934,0.055147,0.000000
69.030006,61.618706,-329.381439,0.005566,0.002170,0.055121,274.093689,13.962998,0.551209,-329.381439,0.055147,0.000000
69.200005,61.617592,-329.381439,0.005549,0.002170,0.055121,274.088745,13.962747,0.551209,-329.381439,0.055147,0.000000
69.370003,61.616104,-329.381439,0.005562,0.002170,0.055121,274.082123,13.962409,0.551209,-329.381439,0.055147,0.000000
69.540001,61.597481,-329.425934,0.005549,0.002170,0.055121,273.999268,13.958189,0.551209,-329.425934,0.055147,0.000000
69.710007,61.587433,-329.381439,0.005566,0.002170,0.055121,273.954590,13.955912,0.551209,-329.381439,0.055147,0.000000
69.880005,61.587799,-329.381439,0.005562,0.002170,0.055121,273.956207,13.955995,0.551209,-329.381439,0.055147,0.000000
70.050003,61.574394,-329.425934,0.005562,0.002170,0.055121,273.896576,13.952957,0.551209,-329.425934,0.055147,0.000000
70.220001,61.574394,-329.514893,0.005562,0.002170,0.055121,273.896576,13.952957,0.551209,-329.514893,0.055147,0.000000
70.390007,61.558014,-329.514893,0.005545,0.002170,0.055121,273.823730,13.949245,0.551209,-329.514893,0.055147,0.000000
70.560005,61.552795,-329.514893,0.005562,0.002170,0.055121,273.800507,13.948063,0.551209,-329.514893,0.055147,0.000000
70.730003,61.546471,-329.425934,0.005553,0.002170,0.055121,273.772369,13.946630,0.551209,-329.425934,0.055147,0.000000
70.900002,61.542374,-329.470398,0.005558,0.002170,0.055121,273.754150,13.945702,0.551209,-329.470398,0.055147,0.000000
71.070000,61.525620,-329.514893,0.005545,0.002170,0.055121,273.679626,13.941905,0.551209,-329.514893,0.055147,0.000000
71.240005,61.528221,-329.514893,0.005553,0.002170,0.055121,273.691193,13.942494,0.551209,-329.514893,0.055147,0.000000
71.300003,61.522636,-329.514893,0.005553,0.002170,0.055121,273.666351,13.941229,0.551209,-329.514893,0.055147,0.000000