File: Data/AG AL compression 300N/AG membrane Unpeeled 300N_1_1_03192024_182300.csv
Time (sec),S:Load (lbs),S:HL1 (DIM),S:LVDT (in),S:Position (in),Ch:Position (mm),Ch:Load (N),Ch:Stress (MPa),Ch:Strain (mm/mm),Ch:HL1 (DIM),Set Point (),Cycles ()
0.010000,0.009682,-254.075195,0.000000,-0.000000,-0.000000,0.043066,0.002194,-0.000000,-254.075195,-0.000182,0.000000
0.200000,0.001862,-254.119675,0.000013,-0.000000,-0.000000,0.008281,0.000422,-0.000000,-254.119675,-0.000182,0.000000
0.390000,0.005211,-254.075195,0.000017,0.000010,0.000251,0.023179,0.001181,0.002513,-254.075195,0.000858,0.000000
0.580000,0.007072,-254.119675,0.000000,0.000131,0.003339,0.031460,0.001603,0.033387,-254.119675,0.004015,0.000000
0.770000,-0.017502,-254.208633,0.000000,0.000245,0.006235,-0.077852,-0.003966,0.062352,-254.208633,0.007189,0.000000
0.960000,0.031647,-254.119675,0.000034,0.000364,0.009253,0.140772,0.007171,0.092533,-254.119675,0.010346,0.000000
1.150000,0.023453,-254.208633,0.000147,0.000491,0.012462,0.104323,0.005314,0.124621,-254.208633,0.013520,0.000000
1.340000,0.023827,-254.208633,0.000280,0.000617,0.015679,0.105986,0.005399,0.156793,-254.208633,0.016677,0.000000
1.530000,0.029411,-254.253113,0.000392,0.000743,0.018871,0.130828,0.006665,0.188707,-254.253113,0.019851,0.000000
1.720000,0.051010,-254.253113,0.000522,0.000865,0.021975,0.226904,0.011559,0.219755,-254.253113,0.023008,0.000000
1.910000,0.034996,-254.253113,0.000634,0.000991,0.025176,0.155670,0.007930,0.251756,-254.253113,0.026182,0.000000
2.100000,0.023827,-254.342072,0.000746,0.001116,0.028341,0.105986,0.005399,0.283409,-254.342072,0.029338,0.000000
2.290000,0.003349,-254.342072,0.000884,0.001239,0.031463,0.014898,0.000759,0.314631,-254.342072,0.032512,0.000000
2.480000,-0.008568,-254.342072,0.001026,0.001362,0.034594,-0.038112,-0.001941,0.345936,-254.342072,0.035669,0.000000
2.670000,0.007072,-254.342072,0.001138,0.001491,0.037880,0.031460,0.001603,0.378804,-254.342072,0.038843,0.000000
2.860000,0.027550,-254.342072,0.001259,0.001615,0.041020,0.122547,0.006243,0.410199,-254.342072,0.042000,0.000000
3.050000,0.057716,-254.431046,0.001375,0.001740,0.044194,0.256735,0.013079,0.441939,-254.431046,0.045174,0.000000
3.240000,0.058830,-254.386566,0.001526,0.001863,0.047324,0.261690,0.013331,0.473244,-254.386566,0.048330,0.000000
3.430000,0.082664,-254.431046,0.001630,0.001990,0.050551,0.367710,0.018732,0.505507,-254.431046,0.051504,0.000000
3.620000,0.090485,-254.475525,0.001768,0.002114,0.053699,0.402496,0.020504,0.536986,-254.475525,0.054661,0.000000
3.810000,0.075218,-254.431046,0.001893,0.002240,0.056890,0.334587,0.017045,0.568900,-254.431046,0.057835,0.000000
4.000000,0.073723,-254.520004,0.002001,0.002364,0.060055,0.327936,0.016706,0.600553,-254.520004,0.060992,0.000000
4.190000,0.053619,-254.475525,0.002139,0.002489,0.063212,0.238511,0.012150,0.632119,-254.475525,0.064166,0.000000
4.380000,0.049522,-254.520004,0.002268,0.002615,0.066421,0.220287,0.011222,0.664207,-254.520004,0.067323,0.000000
4.570000,0.042076,-254.475525,0.002397,0.002736,0.069491,0.187164,0.009535,0.694907,-254.475525,0.070497,0.000000
4.760000,0.037979,-254.475525,0.002496,0.002852,0.072448,0.168940,0.008606,0.724482,-254.475525,0.073653,0.000000
4.950000,0.052498,-254.520004,0.002639,0.002982,0.075743,0.233522,0.011896,0.757433,-254.520004,0.076828,0.000000
5.140000,0.065903,-254.564484,0.002751,0.003104,0.078831,0.293150,0.014934,0.788307,-254.564484,0.079984,0.000000
5.330000,0.087875,-254.520004,0.002871,0.003229,0.082022,0.390889,0.019913,0.820221,-254.520004,0.083158,0.000000
5.520000,0.092720,-254.653442,0.003009,0.003359,0.085326,0.412439,0.021011,0.853263,-254.653442,0.086315,0.000000
5.710000,0.087135,-254.608963,0.003139,0.003483,0.088465,0.387597,0.019745,0.884655,-254.608963,0.089489,0.000000
5.900000,0.076706,-254.697922,0.003268,0.003607,0.091614,0.341205,0.017382,0.916138,-254.697922,0.092646,0.000000
6.090000,0.075958,-254.697922,0.003397,0.003732,0.094788,0.337879,0.017212,0.947878,-254.697922,0.095820,0.000000
6.280000,0.084526,-254.697922,0.003514,0.003854,0.097884,0.375991,0.019154,0.978838,-254.697922,0.098977,0.000000
6.470000,0.098305,-254.697922,0.003648,0.003975,0.100962,0.437281,0.022276,1.009624,-254.697922,0.102151,0.000000
6.660000,0.075218,-254.653442,0.003751,0.004099,0.104119,0.334587,0.017045,1.041191,-254.653442,0.105307,0.000000
6.850000,0.073723,-254.786880,0.003876,0.004222,0.107241,0.327936,0.016706,1.072412,-254.786880,0.108481,0.000000
7.040000,0.063301,-254.697922,0.003980,0.004347,0.110424,0.281577,0.014344,1.104239,-254.697922,0.111638,0.000000
7.230000,0.090858,-254.697922,0.004100,0.004476,0.113702,0.404159,0.020589,1.137020,-254.697922,0.114812,0.000000
7.420001,0.075218,-254.831375,0.004247,0.004602,0.116885,0.334587,0.017045,1.168847,-254.831375,0.117969,0.000000
7.610000,0.091599,-254.786880,0.004376,0.004727,0.120067,0.407451,0.020757,1.200675,-254.786880,0.121143,0.000000
7.800000,0.089737,-254.786880,0.004497,0.004855,0.123311,0.399170,0.020335,1.233107,-254.786880,0.124299,0.000000
7.990000,0.089737,-254.786880,0.004605,0.004979,0.126476,0.399170,0.020335,1.264760,-254.786880,0.127473,0.000000
8.180000,0.089363,-254.786880,0.004734,0.005106,0.129685,0.397507,0.020250,1.296849,-254.786880,0.130630,0.000000
8.370001,0.077454,-254.964813,0.004846,0.005228,0.132798,0.344531,0.017551,1.327983,-254.964813,0.133804,0.000000
8.560000,0.093086,-254.875854,0.004980,0.005352,0.135946,0.414068,0.021094,1.359462,-254.875854,0.136961,0.000000
8.750000,0.076332,-254.964813,0.005118,0.005471,0.138973,0.339542,0.017297,1.389730,-254.964813,0.140135,0.000000
8.940001,0.069633,-254.920334,0.005230,0.005595,0.142121,0.309745,0.015779,1.421209,-254.920334,0.143292,0.000000
9.130000,0.034256,-254.920334,0.005364,0.005724,0.145382,0.152378,0.007763,1.453816,-254.920334,0.146466,0.000000
9.320001,0.059578,-254.964813,0.005480,0.005846,0.148486,0.265016,0.013501,1.484864,-254.964813,0.149623,0.000000
9.510000,0.092720,-254.964813,0.005622,0.005972,0.151695,0.412439,0.021011,1.516952,-254.964813,0.152797,0.000000
9.700001,0.080803,-255.009293,0.005743,0.006096,0.154834,0.359429,0.018310,1.548344,-255.009293,0.155953,0.000000
9.890000,0.068886,-255.009293,0.005859,0.006223,0.158069,0.306419,0.015610,1.580693,-255.009293,0.159127,0.000000
10.080001,0.085266,-255.009293,0.006002,0.006347,0.161217,0.379283,0.019322,1.612172,-255.009293,0.162284,0.000000
10.270000,0.092720,-255.053772,0.006109,0.006473,0.164417,0.412439,0.021011,1.644174,-255.053772,0.165458,0.000000
10.460000,0.075584,-254.964813,0.006252,0.006594,0.167487,0.336216,0.017128,1.674873,-254.964813,0.168615,0.000000
10.650001,0.056221,-255.053772,0.006381,0.006719,0.170661,0.250084,0.012740,1.706613,-255.053772,0.171789,0.000000
10.840000,0.059204,-255.053772,0.006510,0.006843,0.173801,0.263353,0.013416,1.738009,-255.053772,0.174945,0.000000
11.030001,0.042450,-255.053772,0.006627,0.006968,0.176992,0.188827,0.009619,1.769919,-255.053772,0.178119,0.000000
11.220000,0.017868,-255.142731,0.006786,0.007095,0.180201,0.079481,0.004049,1.802007,-255.142731,0.181276,0.000000
11.410001,0.031647,-255.098251,0.006898,0.007221,0.183410,0.140772,0.007171,1.834096,-255.098251,0.184450,0.000000
11.600000,0.079681,-255.231705,0.007015,0.007344,0.186532,0.354441,0.018056,1.865317,-255.231705,0.187607,0.000000
11.790001,0.064041,-255.187210,0.007148,0.007469,0.189723,0.284869,0.014512,1.897228,-255.187210,0.190781,0.000000
11.980000,0.077454,-255.187210,0.007269,0.007593,0.192871,0.344531,0.017551,1.928711,-255.187210,0.193938,0.000000
12.170001,0.076706,-255.231705,0.007407,0.007719,0.196054,0.341205,0.017382,1.960538,-255.231705,0.197112,0.000000
12.360001,0.106125,-255.231705,0.007537,0.007847,0.199323,0.472067,0.024048,1.993232,-255.231705,0.200268,0.000000
12.550000,0.084900,-255.276184,0.007666,0.007969,0.202419,0.377654,0.019239,2.024192,-255.276184,0.203443,0.000000
12.740001,0.093834,-255.365143,0.007782,0.008094,0.205576,0.417394,0.021263,2.055758,-255.365143,0.206599,0.000000
12.930000,0.090111,-255.276184,0.007903,0.008218,0.208732,0.400833,0.020419,2.087324,-255.276184,0.209773,0.000000
13.120001,0.086761,-255.365143,0.008028,0.008344,0.211933,0.385934,0.019660,2.119325,-255.365143,0.212930,0.000000
13.310000,0.103516,-255.320663,0.008149,0.008467,0.215055,0.460460,0.023457,2.150547,-255.320663,0.216104,0.000000
13.500001,0.135544,-255.409622,0.008269,0.008591,0.218220,0.602929,0.030715,2.182200,-255.409622,0.219260,0.000000
13.690001,0.222305,-255.320663,0.008386,0.008718,0.221429,0.988863,0.050375,2.214288,-255.320663,0.222435,0.000000
13.880001,0.377953,-255.320663,0.008520,0.008841,0.224551,1.681217,0.085645,2.245506,-255.320663,0.225591,0.000000
14.070001,0.707130,-255.409622,0.008623,0.008944,0.227178,3.145473,0.160238,2.271785,-255.409622,0.228332,0.000000
14.260000,0.656860,-255.365143,0.008623,-0.000000,-0.000009,2.921861,0.148847,-0.000087,-255.365143,0.000208,0.000000
14.450001,0.657982,-255.454102,0.008640,-0.000000,-0.000009,2.926850,0.149101,-0.000087,-255.454102,0.000208,0.000000
14.640000,0.640480,-255.409622,0.008640,-0.000000,-0.000009,2.848998,0.145135,-0.000087,-255.409622,0.000312,0.000000
14.830001,0.673988,-255.454102,0.008645,-0.000000,-0.000000,2.998050,0.152728,-0.000000,-255.454102,0.000633,0.000000
15.020000,0.672501,-255.543060,0.008627,0.000000,0.000009,2.991432,0.152391,0.000087,-255.543060,0.000945,0.000000
15.210001,0.738037,-255.498581,0.008627,0.000021,0.000529,3.282953,0.167242,0.005287,-255.498581,0.001266,0.000000
15.400001,0.833740,-255.498581,0.008623,0.000034,0.000867,3.708662,0.188928,0.008671,-255.498581,0.001578,0.000000
15.590001,0.869110,-255.543060,0.008640,0.000040,0.001023,3.865995,0.196943,0.010231,-255.543060,0.001899,0.000000
15.780001,0.881401,-255.498581,0.008675,0.000050,0.001257,3.920668,0.199728,0.012573,-255.498581,0.002211,0.000000
15.970001,0.973381,-255.587540,0.008662,0.000067,0.001691,4.329815,0.220571,0.016911,-255.587540,0.002532,0.000000
16.160000,1.069077,-255.587540,0.008688,0.000080,0.002029,4.755490,0.242256,0.020291,-255.587540,0.002844,0.000000
16.350000,1.171478,-255.587540,0.008675,0.000092,0.002341,5.210996,0.265461,0.023413,-255.587540,0.003165,0.000000
16.540001,1.255264,-255.632019,0.008714,0.000104,0.002645,5.583694,0.284447,0.026449,-255.632019,0.003486,0.000000
16.730001,1.282822,-255.632019,0.008692,0.000109,0.002758,5.706276,0.290692,0.027577,-255.632019,0.003799,0.000000
16.920000,1.492462,-255.676514,0.008714,0.000131,0.003321,6.638803,0.338197,0.033212,-255.676514,0.004119,0.000000
17.110001,1.611626,-255.676514,0.008752,0.000143,0.003642,7.168869,0.365200,0.036422,-255.676514,0.004431,0.000000
17.300001,1.736740,-255.720993,0.008748,0.000155,0.003946,7.725406,0.393551,0.039458,-255.720993,0.004752,0.000000
17.490002,1.854782,-255.765472,0.008761,0.000165,0.004197,8.250483,0.420300,0.041974,-255.765472,0.005065,0.000000
17.680000,1.966492,-255.720993,0.008774,0.000179,0.004544,8.747392,0.445613,0.045441,-255.720993,0.005386,0.000000
17.870001,2.131454,-255.720993,0.008770,0.000192,0.004865,9.481183,0.482994,0.048651,-255.720993,0.005697,0.000000
18.060001,2.264023,-255.765472,0.008804,0.000202,0.005134,10.070876,0.513035,0.051338,-255.765472,0.006018,0.000000
18.250000,2.477760,-255.765472,0.008787,0.000216,0.005490,11.021628,0.561469,0.054896,-255.765472,0.006331,0.000000
18.440001,2.660225,-255.854431,0.008795,0.000229,0.005810,11.833271,0.602816,0.058102,-255.854431,0.006652,0.000000
18.630001,2.792793,-255.809952,0.008817,0.000236,0.005984,12.422965,0.632856,0.059839,-255.809952,0.006964,0.000000
18.820002,3.027756,-255.943390,0.008821,0.000251,0.006374,13.468130,0.686099,0.063741,-255.943390,0.007284,0.000000
19.010000,3.253418,-255.898911,0.008847,0.000265,0.006730,14.471926,0.737235,0.067295,-255.898911,0.007597,0.000000
19.200001,3.480186,-255.898911,0.008834,0.000279,0.007077,15.480642,0.788622,0.070766,-255.898911,0.007918,0.000000
19.390001,3.788887,-255.943390,0.008860,0.000294,0.007458,16.853811,0.858574,0.074581,-255.943390,0.008230,0.000000
19.580002,3.918846,-255.898911,0.008886,0.000302,0.007666,17.431898,0.888023,0.076663,-255.898911,0.008551,0.000000
19.770000,4.120300,-255.943390,0.008864,0.000315,0.007996,18.328011,0.933673,0.079956,-255.943390,0.008863,0.000000
19.960001,4.413727,-255.943390,0.008886,0.000327,0.008317,19.633238,1.000165,0.083165,-255.943390,0.009184,0.000000
20.150002,4.696732,-255.987869,0.008899,0.000340,0.008638,20.892105,1.064295,0.086375,-255.987869,0.009496,0.000000
20.340000,4.982338,-256.032349,0.008903,0.000353,0.008975,22.162546,1.129014,0.089755,-256.032349,0.009817,0.000000
20.530001,5.202042,-255.987869,0.008916,0.000363,0.009210,23.139837,1.178799,0.092098,-255.987869,0.010129,0.000000
20.720001,5.446686,-256.121307,0.008946,0.000375,0.009522,24.228069,1.234237,0.095220,-256.121307,0.010450,0.000000
20.910002,5.799324,-255.987869,0.008951,0.000391,0.009921,25.796682,1.314146,0.099210,-255.987869,0.010762,0.000000
21.100000,6.075996,-256.076843,0.008968,0.000403,0.010242,27.027382,1.376840,0.102419,-256.076843,0.011083,0.000000
21.290001,6.357513,-256.121307,0.008955,0.000414,0.010528,28.279633,1.440633,0.105281,-256.121307,0.011395,0.000000
21.480001,6.675888,-256.121307,0.008968,0.000428,0.010883,29.695833,1.512778,0.108835,-256.121307,0.011716,0.000000
21.670000,6.917931,-256.165802,0.008985,0.000439,0.011153,30.772491,1.567626,0.111526,-256.165802,0.012028,0.000000
21.860001,7.108215,-256.121307,0.009002,0.000448,0.011369,31.618921,1.610745,0.113691,-256.121307,0.012349,0.000000
22.050001,7.560272,-256.076843,0.009011,0.000464,0.011785,33.629772,1.713182,0.117854,-256.076843,0.012670,0.000000
22.240002,7.980309,-256.210266,0.009015,0.000480,0.012184,35.498184,1.808364,0.121843,-256.210266,0.012982,0.000000
22.430000,8.192192,-256.121307,0.009046,0.000488,0.012401,36.440689,1.856377,0.124012,-256.121307,0.013303,0.000000
22.620001,8.265175,-256.210266,0.009020,0.000495,0.012566,36.765335,1.872915,0.125659,-256.210266,0.013615,0.000000
22.810001,8.920181,-256.210266,0.009050,0.000516,0.013104,39.678947,2.021342,0.131037,-256.210266,0.013936,0.000000
23.000002,9.212860,-256.254761,0.009058,0.000529,0.013425,40.980850,2.087664,0.134246,-256.254761,0.014248,0.000000
23.190001,9.544647,-256.254761,0.009063,0.000540,0.013711,42.456711,2.162848,0.137108,-256.254761,0.014569,0.000000
23.380001,9.876801,-256.254761,0.009076,0.000554,0.014075,43.934204,2.238115,0.140749,-256.254761,0.014881,0.000000
23.570002,10.175072,-256.343719,0.009080,0.000564,0.014318,45.260979,2.305704,0.143179,-256.343719,0.015202,0.000000
23.760000,10.336685,-256.299225,0.009110,0.000573,0.014543,45.979874,2.342326,0.145435,-256.299225,0.015515,0.000000
23.950001,10.826729,-256.299225,0.009110,0.000589,0.014959,48.159695,2.453372,0.149594,-256.299225,0.015836,0.000000
24.140001,11.251228,-256.388214,0.009115,0.000602,0.015298,50.047962,2.549565,0.152978,-256.388214,0.016147,0.000000
24.330002,11.481354,-256.343719,0.009145,0.000610,0.015497,51.071613,2.601712,0.154973,-256.343719,0.016468,0.000000
24.520000,11.735687,-256.388214,0.009123,0.000622,0.015801,52.202946,2.659345,0.158008,-256.388214,0.016781,0.000000
24.710001,12.306534,-256.388214,0.009153,0.000639,0.016235,54.742195,2.788700,0.162345,-256.388214,0.017102,0.000000
24.900002,12.730293,-256.432678,0.009149,0.000654,0.016607,56.627174,2.884726,0.166074,-256.432678,0.017414,0.000000
25.090002,12.983505,-256.432678,0.009166,0.000664,0.016867,57.753517,2.942104,0.168674,-256.432678,0.017735,0.000000
25.280001,13.285873,-256.477173,0.009179,0.000676,0.017171,59.098518,3.010622,0.171709,-256.477173,0.018047,0.000000
25.470001,13.572227,-256.477173,0.009196,0.000688,0.017474,60.372284,3.075511,0.174745,-256.477173,0.018368,0.000000
25.660002,13.863426,-256.521637,0.009205,0.000698,0.017717,61.667599,3.141497,0.177175,-256.521637,0.018680,0.000000
25.850000,14.123711,-256.477173,0.009201,0.000709,0.018012,62.825401,3.200479,0.180123,-256.477173,0.019001,0.000000
26.040001,14.745575,-256.566132,0.009209,0.000725,0.018420,65.591591,3.341395,0.184199,-256.566132,0.019313,0.000000
26.230001,15.081451,-256.521637,0.009244,0.000736,0.018697,67.085648,3.417506,0.186974,-256.521637,0.019634,0.000000
26.420002,15.175293,-256.610596,0.009240,0.000743,0.018879,67.503075,3.438771,0.188794,-256.610596,0.019946,0.000000
26.610001,15.632195,-256.610596,0.009235,0.000758,0.019252,69.535477,3.542306,0.192522,-256.610596,0.020267,0.000000
26.800001,16.094681,-256.566132,0.009244,0.000774,0.019669,71.592712,3.647107,0.196686,-256.566132,0.020579,0.000000
26.990002,16.530357,-256.655090,0.009278,0.000789,0.020041,73.530701,3.745832,0.200414,-256.655090,0.020900,0.000000
27.180002,16.767555,-256.655090,0.009287,0.000800,0.020311,74.585808,3.799582,0.203105,-256.655090,0.021212,0.000000
27.370001,16.933258,-256.655090,0.009296,0.000811,0.020588,75.322891,3.837131,0.205879,-256.655090,0.021533,0.000000
27.560001,17.373405,-256.699554,0.009296,0.000822,0.020891,77.280769,3.936870,0.208915,-256.699554,0.021854,0.000000
27.750002,17.560333,-256.655090,0.009300,0.000834,0.021186,78.112267,3.979228,0.211863,-256.655090,0.022166,0.000000
27.940001,18.224648,-256.744049,0.009322,0.000848,0.021550,81.067284,4.129764,0.215504,-256.744049,0.022487,0.000000
28.130001,18.516586,-256.699554,0.009347,0.000860,0.021845,82.365891,4.195919,0.218453,-256.699554,0.022799,0.000000
28.320002,18.651764,-256.744049,0.009347,0.000869,0.022080,82.967186,4.226550,0.220796,-256.744049,0.023120,0.000000
28.510002,18.914658,-256.788544,0.009343,0.000880,0.022340,84.136597,4.286123,0.223396,-256.788544,0.023432,0.000000
28.700001,19.436348,-256.744049,0.009352,0.000897,0.022791,86.457191,4.404339,0.227907,-256.744049,0.023753,0.000000
28.890001,19.993790,-256.877502,0.009373,0.000913,0.023190,88.936821,4.530658,0.231897,-256.877502,0.024065,0.000000
29.080002,20.293549,-256.833008,0.009378,0.000926,0.023510,90.270210,4.598584,0.235103,-256.833008,0.024386,0.000000
29.270000,20.407494,-256.788544,0.009378,0.000938,0.023823,90.777061,4.624404,0.238225,-256.788544,0.024698,0.000000
29.460001,20.669647,-256.877502,0.009408,0.000949,0.024100,91.943184,4.683809,0.240999,-256.877502,0.025019,0.000000
29.650002,21.065109,-256.877502,0.009412,0.000962,0.024447,93.702286,4.773422,0.244470,-256.877502,0.025332,0.000000
29.840002,21.428917,-256.921967,0.009429,0.000975,0.024768,95.320580,4.855862,0.247680,-256.921967,0.025653,0.000000
30.030001,21.774849,-256.877502,0.009425,0.000986,0.025045,96.859367,4.934251,0.250454,-256.877502,0.025965,0.000000
30.220001,21.855652,-256.921967,0.009421,0.000994,0.025236,97.218796,4.952561,0.252362,-256.921967,0.026285,0.000000
30.410002,22.261536,-256.966461,0.009447,0.001007,0.025575,99.024254,5.044536,0.255745,-256.966461,0.026598,0.000000
30.600002,22.701309,-256.966461,0.009468,0.001023,0.025982,100.980469,5.144190,0.259818,-256.966461,0.026919,0.000000
30.790001,23.188377,-257.055420,0.009472,0.001038,0.026372,103.147057,5.254561,0.263724,-257.055420,0.027231,0.000000
30.980001,23.524628,-257.010925,0.009490,0.001051,0.026702,104.642769,5.330757,0.267017,-257.010925,0.027552,0.000000
31.170002,23.727943,-257.099884,0.009494,0.001063,0.027005,105.547165,5.376829,0.270052,-257.099884,0.027864,0.000000
31.360001,23.888435,-257.055420,0.009511,0.001073,0.027266,106.261070,5.413197,0.272656,-257.055420,0.028185,0.000000
31.550001,24.109627,-257.055420,0.009511,0.001085,0.027569,107.244980,5.463320,0.275692,-257.055420,0.028497,0.000000
31.740002,24.375870,-257.055420,0.009516,0.001094,0.027786,108.429283,5.523651,0.277857,-257.055420,0.028818,0.000000
31.930002,25.011139,-257.099884,0.009516,0.001111,0.028211,111.255104,5.667605,0.282107,-257.099884,0.029130,0.000000
32.120003,25.275520,-257.055420,0.009541,0.001123,0.028523,112.431129,5.727515,0.285230,-257.055420,0.029451,0.000000
32.310001,25.313133,-257.188873,0.009546,0.001131,0.028740,112.598442,5.736038,0.287398,-257.188873,0.029763,0.000000
32.500000,26.023621,-257.144379,0.009554,0.001151,0.029234,115.758842,5.897037,0.292342,-257.144379,0.030084,0.000000
32.690002,26.433975,-257.188873,0.009567,0.001164,0.029555,117.584198,5.990024,0.295551,-257.188873,0.030405,0.000000
32.880001,26.533028,-257.233337,0.009589,0.001174,0.029815,118.024803,6.012470,0.298151,-257.233337,0.030717,0.000000
33.070000,26.890503,-257.277832,0.009597,0.001188,0.030179,119.614929,6.093475,0.301792,-257.277832,0.031038,0.000000
33.260002,27.040939,-257.233337,0.009619,0.001198,0.030422,120.284103,6.127564,0.304222,-257.233337,0.031350,0.000000
33.450001,27.242393,-257.233337,0.009619,0.001207,0.030648,121.180222,6.173215,0.306478,-257.233337,0.031671,0.000000
33.640003,27.720520,-257.277832,0.009628,0.001225,0.031107,123.307030,6.281560,0.311073,-257.277832,0.031983,0.000000
33.830002,28.032944,-257.322296,0.009632,0.001236,0.031385,124.696762,6.352356,0.313847,-257.322296,0.032304,0.000000
34.020000,28.415741,-257.277832,0.009641,0.001249,0.031714,126.399529,6.439099,0.317144,-257.277832,0.032616,0.000000
34.210003,28.468987,-257.366791,0.009662,0.001255,0.031870,126.636375,6.451164,0.318703,-257.366791,0.032937,0.000000
34.400002,29.104630,-257.277832,0.009666,0.001274,0.032347,129.463852,6.595203,0.323472,-257.277832,0.033249,0.000000
34.590000,29.531738,-257.366791,0.009666,0.001285,0.032642,131.363739,6.691988,0.326424,-257.366791,0.033570,0.000000
34.780003,29.974487,-257.366791,0.009684,0.001300,0.033033,133.333176,6.792316,0.330327,-257.366791,0.033882,0.000000
34.970001,30.289146,-257.322296,0.009710,0.001314,0.033379,134.732849,6.863618,0.333794,-257.322296,0.034203,0.000000
35.160000,30.401978,-257.455750,0.009710,0.001322,0.033570,135.234756,6.889186,0.335701,-257.455750,0.034516,0.000000
35.350002,30.755356,-257.366791,0.009718,0.001335,0.033900,136.806656,6.969263,0.338998,-257.366791,0.034836,0.000000
35.540001,31.103523,-257.455750,0.009731,0.001348,0.034246,138.355377,7.048159,0.342465,-257.455750,0.035148,0.000000
35.730003,31.550743,-257.455750,0.009748,0.001360,0.034550,140.344711,7.149500,0.345500,-257.455750,0.035469,0.000000
35.920002,31.868752,-257.500214,0.009766,0.001373,0.034871,141.759293,7.221562,0.348710,-257.500214,0.035782,0.000000
36.110001,32.116379,-257.589172,0.009761,0.001383,0.035131,142.860794,7.277675,0.351314,-257.589172,0.036103,0.000000
36.300003,32.942673,-257.544708,0.009766,0.001402,0.035600,146.536331,7.464916,0.355996,-257.544708,0.036415,0.000000
36.490002,33.150826,-257.589172,0.009783,0.001412,0.035877,147.462234,7.512084,0.358770,-257.589172,0.036735,0.000000
36.680000,33.736198,-257.589172,0.009800,0.001430,0.036311,150.066101,7.644732,0.363108,-257.589172,0.037048,0.000000
36.870003,33.903763,-257.589172,0.009804,0.001438,0.036527,150.811462,7.682703,0.365273,-257.589172,0.037369,0.000000
37.060001,34.031860,-257.589172,0.009809,0.001447,0.036762,151.381271,7.711730,0.367615,-257.589172,0.037681,0.000000
37.250000,34.570686,-257.589172,0.009817,0.001463,0.037152,153.778091,7.833829,0.371518,-257.589172,0.038002,0.000000
37.440002,34.981407,-257.633667,0.009817,0.001476,0.037490,155.605072,7.926900,0.374901,-257.633667,0.038314,0.000000
37.630001,35.488579,-257.678162,0.009852,0.001488,0.037802,157.861084,8.041827,0.378024,-257.678162,0.038635,0.000000
37.820004,35.830421,-257.633667,0.009848,0.001500,0.038097,159.381668,8.119289,0.380972,-257.633667,0.038947,0.000000
38.010002,35.993515,-257.633667,0.009852,0.001507,0.038271,160.107147,8.156247,0.382706,-257.633667,0.039268,0.000000
38.200001,36.707726,-257.633667,0.009869,0.001525,0.038730,163.284119,8.318089,0.387301,-257.633667,0.039589,0.000000
38.390003,37.227936,-257.722626,0.009865,0.001537,0.039051,165.598129,8.435970,0.390510,-257.722626,0.039901,0.000000
38.580002,37.718719,-257.722626,0.009891,0.001551,0.039407,167.781250,8.547184,0.394068,-257.722626,0.040222,0.000000
38.770000,37.969330,-257.767120,0.009899,0.001561,0.039649,168.896011,8.603972,0.396494,-257.767120,0.040534,0.000000
38.960003,38.396812,-257.767120,0.009891,0.001574,0.039970,170.797546,8.700842,0.399704,-257.767120,0.040855,0.000000
39.150002,38.736412,-257.811584,0.009916,0.001588,0.040326,172.308167,8.777797,0.403258,-257.811584,0.041167,0.000000
39.340000,39.178421,-257.811584,0.009916,0.001595,0.040525,174.274323,8.877957,0.405252,-257.811584,0.041488,0.000000
39.530003,39.782410,-257.811584,0.009929,0.001611,0.040907,176.960999,9.014823,0.409068,-257.811584,0.041800,0.000000
39.720001,40.335007,-257.856079,0.009921,0.001623,0.041219,179.419067,9.140043,0.412190,-257.856079,0.042121,0.000000
39.910004,40.698448,-257.900543,0.009947,0.001633,0.041488,181.035736,9.222400,0.414881,-257.900543,0.042433,0.000000
40.100002,41.149757,-257.811584,0.009951,0.001647,0.041826,183.043259,9.324668,0.418261,-257.811584,0.042754,0.000000
40.290001,41.694916,-257.945038,0.009955,0.001659,0.042130,185.468246,9.448202,0.421297,-257.945038,0.043066,0.000000
40.480003,42.389015,-257.945038,0.009985,0.001673,0.042494,188.555756,9.605488,0.424938,-257.945038,0.043387,0.000000
40.670002,43.107697,-257.989502,0.009981,0.001691,0.042945,191.752609,9.768344,0.429449,-257.989502,0.043699,0.000000
40.860001,43.371704,-257.945038,0.009990,0.001699,0.043153,192.926971,9.828169,0.431531,-257.945038,0.044020,0.000000
41.050003,43.520287,-257.900543,0.009990,0.001707,0.043370,193.587906,9.861837,0.433700,-257.900543,0.044332,0.000000
41.240002,44.127998,-258.033997,0.010007,0.001722,0.043743,196.291138,9.999547,0.437428,-258.033997,0.044653,0.000000
41.430000,44.878700,-257.989502,0.010024,0.001736,0.044107,199.630432,10.169659,0.441069,-257.989502,0.044966,0.000000
41.620003,45.500191,-257.989502,0.010016,0.001749,0.044437,202.394958,10.310490,0.444366,-257.989502,0.045286,0.000000
41.810001,45.856178,-257.989502,0.010020,0.001760,0.044697,203.978470,10.391158,0.446966,-257.989502,0.045599,0.000000
42.000004,46.231529,-257.989502,0.010046,0.001770,0.044957,205.648117,10.476213,0.449570,-257.989502,0.045919,0.000000
42.190002,47.041809,-258.078491,0.010042,0.001785,0.045347,209.252411,10.659826,0.453472,-258.078491,0.046232,0.000000
42.380001,47.625320,-258.078491,0.010063,0.001797,0.045642,211.848007,10.792052,0.456420,-258.078491,0.046553,0.000000
42.570004,48.248299,-258.078491,0.010054,0.001810,0.045980,214.619156,10.933221,0.459800,-258.078491,0.046865,0.000000
42.760002,48.782654,-258.122955,0.010067,0.001823,0.046310,216.996078,11.054307,0.463097,-258.122955,0.047186,0.000000
42.950001,49.186676,-258.078491,0.010067,0.001833,0.046561,218.793259,11.145861,0.465614,-258.078491,0.047498,0.000000
43.140003,49.610435,-258.167450,0.010067,0.001844,0.046848,220.678238,11.241885,0.468475,-258.167450,0.047819,0.000000
43.330002,50.165268,-258.167450,0.010098,0.001856,0.047142,223.146255,11.367612,0.471424,-258.167450,0.048131,0.000000
43.520000,50.862724,-258.167450,0.010093,0.001871,0.047515,226.248703,11.525659,0.475152,-258.167450,0.048452,0.000000
43.710003,51.763863,-258.211914,0.010106,0.001884,0.047854,230.257156,11.729859,0.478536,-258.211914,0.048773,0.000000
43.900002,51.766846,-258.122955,0.010093,0.001888,0.047966,230.270432,11.730535,0.479660,-258.122955,0.049085,0.000000
44.090004,52.945404,-258.256409,0.010119,0.001909,0.048486,235.512924,11.997600,0.484864,-258.256409,0.049406,0.000000
44.280003,53.548645,-258.256409,0.010128,0.001920,0.048764,238.196274,12.134296,0.487638,-258.256409,0.049718,0.000000
44.470001,54.277748,-258.211914,0.010119,0.001934,0.049120,241.439484,12.299513,0.491196,-258.211914,0.050039,0.000000
44.660004,54.811363,-258.300873,0.010132,0.001944,0.049380,243.813126,12.420432,0.493796,-258.300873,0.050351,0.000000
44.850002,55.611214,-258.300873,0.010149,0.001960,0.049779,247.371033,12.601681,0.497786,-258.300873,0.050672,0.000000
45.040001,56.036842,-258.345367,0.010158,0.001969,0.050013,249.264328,12.698130,0.500128,-258.345367,0.050984,0.000000
45.230003,56.643433,-258.345367,0.010149,0.001980,0.050299,251.962570,12.835586,0.502990,-258.345367,0.051305,0.000000
45.420002,57.464516,-258.345367,0.010175,0.001996,0.050689,255.614929,13.021646,0.506892,-258.345367,0.051617,0.000000
45.610001,57.984718,-258.389832,0.010184,0.002007,0.050984,257.928894,13.139525,0.509840,-258.389832,0.051938,0.000000
45.800003,58.251709,-258.345367,0.010192,0.002015,0.051175,259.116547,13.200027,0.511748,-258.345367,0.052250,0.000000
45.990002,59.517403,-258.434326,0.010192,0.002034,0.051652,264.746643,13.486836,0.516517,-258.434326,0.052571,0.000000
46.180000,60.360085,-258.389832,0.010201,0.002048,0.052007,268.495056,13.677791,0.520075,-258.389832,0.052883,0.000000
46.370003,61.247818,-258.389832,0.010197,0.002062,0.052372,272.443909,13.878954,0.523716,-258.389832,0.053204,0.000000
46.560001,61.526352,-258.523285,0.010210,0.002070,0.052588,273.682892,13.942070,0.525885,-258.523285,0.053517,0.000000
46.750004,62.072998,-258.434326,0.010223,0.002082,0.052883,276.114471,14.065943,0.528833,-258.434326,0.053837,0.000000
46.940002,62.588364,-258.523285,0.010227,0.002090,0.053091,278.406952,14.182726,0.530915,-258.523285,0.054149,0.000000
47.130001,63.010262,-258.523285,0.010240,0.002099,0.053326,280.283630,14.278329,0.533258,-258.523285,0.054470,0.000000
47.320004,64.103165,-258.523285,0.010218,0.002119,0.053811,285.145111,14.525985,0.538114,-258.523285,0.054783,0.000000
47.510002,65.016602,-258.612244,0.010240,0.002133,0.054175,289.208282,14.732972,0.541755,-258.612244,0.055104,0.000000
47.700001,65.479828,-258.567780,0.010248,0.002139,0.054323,291.268829,14.837941,0.543231,-258.567780,0.055416,0.000000
47.890003,65.860397,-258.612244,0.010253,0.002150,0.054609,292.961670,14.924179,0.546092,-258.612244,0.055736,0.000000
48.080002,67.192368,-258.567780,0.010279,0.002168,0.055069,298.886566,15.226008,0.550687,-258.567780,0.056049,0.000000
48.270000,67.167801,-258.612244,0.010266,0.002162,0.054913,298.777313,15.220442,0.549128,-258.612244,0.055121,0.000000
48.460003,66.783875,-258.656738,0.010274,0.002162,0.054904,297.069519,15.133442,0.549041,-258.656738,0.055121,0.000000
48.650002,66.470337,-258.612244,0.010283,0.002161,0.054895,295.674835,15.062394,0.548954,-258.612244,0.054904,0.000000
48.840004,66.202606,-258.745697,0.010279,0.002161,0.054878,294.483887,15.001725,0.548779,-258.745697,0.054904,0.000000
49.030003,65.972855,-258.745697,0.010296,0.002161,0.054878,293.461914,14.949662,0.548779,-258.745697,0.054904,0.000000
49.220001,65.762466,-258.656738,0.010283,0.002160,0.054869,292.526062,14.901988,0.548692,-258.656738,0.054904,0.000000
49.410004,65.594147,-258.745697,0.010300,0.002160,0.054869,291.777344,14.863846,0.548692,-258.745697,0.054904,0.000000
49.600002,65.426956,-258.745697,0.010292,0.002160,0.054861,291.033630,14.825960,0.548605,-258.745697,0.054904,0.000000
49.790001,65.270187,-258.790161,0.010274,0.002160,0.054861,290.336304,14.790436,0.548605,-258.790161,0.054904,0.000000
49.980003,65.137619,-258.790161,0.010300,0.002160,0.054861,289.746613,14.760396,0.548605,-258.790161,0.054904,0.000000
50.170002,65.005432,-258.745697,0.010300,0.002160,0.054861,289.158600,14.730441,0.548605,-258.745697,0.054904,0.000000
50.360001,64.897812,-258.790161,0.010300,0.002160,0.054861,288.679871,14.706054,0.548605,-258.790161,0.054904,0.000000
50.550003,64.791321,-258.790161,0.010300,0.002160,0.054861,288.206177,14.681923,0.548605,-258.790161,0.054904,0.000000
50.740002,64.678864,-258.879150,0.010296,0.002160,0.054861,287.705963,14.656440,0.548605,-258.879150,0.054904,0.000000
50.930004,64.590240,-258.834656,0.010283,0.002160,0.054852,287.311737,14.636357,0.548518,-258.834656,0.054904,0.000000
51.120003,64.521713,-258.968109,0.010283,0.002160,0.054852,287.006927,14.620829,0.548518,-258.968109,0.054904,0.000000
51.310001,64.429367,-258.923615,0.010292,0.002160,0.054852,286.596130,14.599903,0.548518,-258.923615,0.054904,0.000000
51.500004,64.351913,-258.879150,0.010300,0.002160,0.054852,286.251617,14.582352,0.548518,-258.879150,0.054904,0.000000
51.690002,64.271118,-258.968109,0.010292,0.002160,0.054852,285.892212,14.564043,0.548518,-258.968109,0.054904,0.000000
51.880001,64.201477,-258.968109,0.010287,0.002160,0.054852,285.582428,14.548263,0.548518,-258.968109,0.054904,0.000000
52.070004,64.128860,-258.968109,0.010283,0.002160,0.054852,285.259430,14.531808,0.548518,-258.968109,0.054904,0.000000
52.260002,64.074493,-259.012573,0.010296,0.002160,0.054852,285.017578,14.519487,0.548518,-259.012573,0.054904,0.000000
52.450001,64.017151,-258.968109,0.010296,0.002160,0.054852,284.762512,14.506494,0.548518,-258.968109,0.054904,0.000000
52.640003,63.945663,-259.012573,0.010300,0.002160,0.054852,284.444519,14.490294,0.548518,-259.012573,0.054904,0.000000
52.830002,63.884964,-259.012573,0.010296,0.002160,0.054852,284.174500,14.476540,0.548518,-259.012573,0.054904,0.000000
53.020004,63.843262,-259.057068,0.010283,0.002160,0.054852,283.989014,14.467091,0.548518,-259.057068,0.054904,0.000000
53.210003,63.811234,-259.057068,0.010300,0.002160,0.054852,283.846558,14.459832,0.548518,-259.057068,0.054904,0.000000
53.400002,63.740479,-259.057068,0.010305,0.002160,0.054852,283.531799,14.443799,0.548518,-259.057068,0.054904,0.000000
53.590004,63.694305,-259.190491,0.010292,0.002160,0.054852,283.326416,14.433336,0.548518,-259.190491,0.054904,0.000000
53.780003,63.644775,-259.146027,0.010292,0.002160,0.054852,283.106110,14.422112,0.548518,-259.146027,0.054904,0.000000
53.970001,63.623550,-259.146027,0.010313,0.002160,0.054852,283.011688,14.417303,0.548518,-259.146027,0.054904,0.000000
54.160004,63.560623,-259.190491,0.010309,0.002160,0.054852,282.731781,14.403043,0.548518,-259.190491,0.054904,0.000000
54.350002,63.513336,-259.146027,0.010300,0.002160,0.054852,282.521423,14.392327,0.548518,-259.146027,0.054904,0.000000
54.540001,63.478699,-259.234985,0.010300,0.002160,0.054852,282.367340,14.384479,0.548518,-259.234985,0.054904,0.000000
54.730003,63.455612,-259.234985,0.010305,0.002160,0.054852,282.264648,14.379247,0.548518,-259.234985,0.054904,0.000000
54.920002,63.412048,-259.234985,0.010309,0.002160,0.054852,282.070892,14.369376,0.548518,-259.234985,0.054904,0.000000
55.110004,63.365494,-259.323944,0.010305,0.002160,0.054852,281.863800,14.358826,0.548518,-259.323944,0.054904,0.000000
55.300003,63.337952,-259.234985,0.010317,0.002160,0.054852,281.741272,14.352585,0.548518,-259.234985,0.054904,0.000000
55.490002,63.302567,-259.234985,0.010287,0.002160,0.054852,281.583893,14.344566,0.548518,-259.234985,0.054904,0.000000
55.680004,63.269424,-259.279449,0.010305,0.002160,0.054852,281.436462,14.337057,0.548518,-259.279449,0.054904,0.000000
55.870003,63.221390,-259.323944,0.010296,0.002160,0.054852,281.222778,14.326172,0.548518,-259.323944,0.054904,0.000000
56.060001,63.178940,-259.368439,0.010326,0.002160,0.054852,281.033966,14.316552,0.548518,-259.368439,0.054904,0.000000
56.250004,63.171127,-259.279449,0.010305,0.002160,0.054852,280.999207,14.314782,0.548518,-259.279449,0.054904,0.000000
56.440002,63.148773,-259.457397,0.010309,0.002160,0.054852,280.899780,14.309716,0.548518,-259.457397,0.054904,0.000000
56.630001,63.117874,-259.368439,0.010305,0.002160,0.054852,280.762329,14.302714,0.548518,-259.368439,0.054904,0.000000
56.820004,63.074677,-259.412903,0.010305,0.002159,0.054843,280.570160,14.292926,0.548431,-259.412903,0.054904,0.000000
57.010002,63.052711,-259.412903,0.010317,0.002159,0.054843,280.472473,14.287949,0.548431,-259.412903,0.054904,0.000000
57.200005,63.025894,-259.457397,0.010305,0.002159,0.054843,280.353180,14.281872,0.548431,-259.457397,0.054904,0.000000
57.390003,63.006165,-259.501862,0.010317,0.002159,0.054843,280.265411,14.277401,0.548431,-259.501862,0.054904,0.000000
57.580002,62.968178,-259.457397,0.010313,0.002159,0.054843,280.096436,14.268793,0.548431,-259.457397,0.054904,0.000000
57.770004,62.942856,-259.546356,0.010296,0.002159,0.054843,279.983795,14.263055,0.548431,-259.546356,0.054904,0.000000
57.960003,62.915672,-259.546356,0.010300,0.002159,0.054843,279.862885,14.256895,0.548431,-259.546356,0.054904,0.000000
58.150002,62.893707,-259.501862,0.010305,0.002159,0.054843,279.765167,14.251918,0.548431,-259.501862,0.054904,0.000000
58.340004,62.875458,-259.590820,0.010313,0.002159,0.054843,279.683990,14.247783,0.548431,-259.590820,0.054904,0.000000
58.530003,62.858704,-259.590820,0.010317,0.002159,0.054843,279.609467,14.243985,0.548431,-259.590820,0.054904,0.000000
58.720001,62.822952,-259.501862,0.010300,0.002159,0.054843,279.450439,14.235884,0.548431,-259.501862,0.054904,0.000000
58.910004,62.787582,-259.590820,0.010305,0.002159,0.054843,279.293121,14.227870,0.548431,-259.590820,0.054904,0.000000
59.100002,62.777153,-259.590820,0.010313,0.002159,0.054843,279.246735,14.225507,0.548431,-259.590820,0.054904,0.000000
59.290001,62.761513,-259.724274,0.010309,0.002159,0.054843,279.177155,14.221962,0.548431,-259.724274,0.054904,0.000000
59.480003,62.725769,-259.679779,0.010317,0.002159,0.054843,279.018158,14.213862,0.548431,-259.679779,0.054904,0.000000
59.670002,62.719437,-259.679779,0.010300,0.002159,0.054843,278.989990,14.212427,0.548431,-259.679779,0.054904,0.000000
59.860004,62.687042,-259.679779,0.010317,0.002159,0.054843,278.845886,14.205087,0.548431,-259.679779,0.054904,0.000000
60.050003,62.670654,-259.724274,0.010313,0.002159,0.054843,278.772980,14.201373,0.548431,-259.724274,0.054904,0.000000
60.240002,62.646446,-259.813232,0.010300,0.002159,0.054843,278.665314,14.195888,0.548431,-259.813232,0.054904,0.000000
60.430004,62.613312,-259.679779,0.010296,0.002159,0.054843,278.517914,14.188379,0.548431,-259.679779,0.054904,0.000000
60.620003,62.605492,-259.813232,0.010296,0.002159,0.054843,278.483124,14.186607,0.548431,-259.813232,0.054904,0.000000
60.810001,62.586868,-259.768768,0.010317,0.002159,0.054843,278.400299,14.182386,0.548431,-259.768768,0.054904,0.000000
61.000004,62.567131,-259.768768,0.010309,0.002159,0.054843,278.312500,14.177915,0.548431,-259.768768,0.054904,0.000000
61.190002,62.539955,-259.813232,0.010309,0.002159,0.054843,278.191620,14.171757,0.548431,-259.813232,0.054904,0.000000
61.380001,62.521332,-259.813232,0.010313,0.002159,0.054843,278.108765,14.167537,0.548431,-259.813232,0.054904,0.000000
61.570004,62.504951,-259.857727,0.010300,0.002159,0.054843,278.035919,14.163824,0.548431,-259.857727,0.054904,0.000000
61.760002,62.494896,-259.857727,0.010326,0.002159,0.054843,277.991180,14.161546,0.548431,-259.857727,0.054904,0.000000
61.950005,62.464363,-259.857727,0.010305,0.002159,0.054843,277.855377,14.154627,0.548431,-259.857727,0.054904,0.000000
62.140003,62.445366,-259.946686,0.010292,0.002159,0.054843,277.770874,14.150322,0.548431,-259.946686,0.054904,0.000000
62.330002,62.442390,-259.857727,0.010317,0.002159,0.054843,277.757629,14.149649,0.548431,-259.857727,0.054904,0.000000
62.520004,62.411858,-259.946686,0.010309,0.002159,0.054843,277.621796,14.142729,0.548431,-259.946686,0.054904,0.000000
62.710003,62.396217,-259.946686,0.010322,0.002159,0.054843,277.552246,14.139185,0.548431,-259.946686,0.054904,0.000000
62.900002,62.385788,-259.991150,0.010317,0.002159,0.054843,277.505859,14.136822,0.548431,-259.991150,0.054904,0.000000
63.090004,62.357864,-260.035645,0.010305,0.002159,0.054843,277.381622,14.130493,0.548431,-260.035645,0.054904,0.000000
63.280003,62.349670,-259.991150,0.010326,0.002159,0.054843,277.345184,14.128637,0.548431,-259.991150,0.054904,0.000000
63.470001,62.329933,-260.035645,0.010309,0.002159,0.054843,277.257385,14.124166,0.548431,-260.035645,0.054904,0.000000
63.660004,62.319138,-260.035645,0.010309,0.002159,0.054843,277.209381,14.121718,0.548431,-260.035645,0.054904,0.000000
63.850002,62.302002,-259.991150,0.010313,0.002159,0.054843,277.133148,14.117836,0.548431,-259.991150,0.054904,0.000000
64.040001,62.277428,-260.124603,0.010317,0.002159,0.054843,277.023834,14.112267,0.548431,-260.124603,0.054904,0.000000
64.230003,62.264023,-260.035645,0.010322,0.002159,0.054843,276.964203,14.109229,0.548431,-260.035645,0.054904,0.000000
64.420006,62.238701,-260.169098,0.010322,0.002159,0.054843,276.851562,14.103491,0.548431,-260.169098,0.054904,0.000000
64.610001,62.234230,-260.124603,0.010330,0.002159,0.054843,276.831696,14.102478,0.548431,-260.124603,0.054904,0.000000
64.800003,62.220825,-260.124603,0.010305,0.002159,0.054843,276.772064,14.099441,0.548431,-260.124603,0.054904,0.000000
64.990005,62.186569,-260.213562,0.010305,0.002159,0.054843,276.619690,14.091678,0.548431,-260.213562,0.054904,0.000000
65.180000,62.175026,-260.124603,0.010313,0.002159,0.054843,276.568329,14.089063,0.548431,-260.124603,0.054904,0.000000
65.370003,62.163483,-260.213562,0.010317,0.002159,0.054843,276.516968,14.086446,0.548431,-260.213562,0.054904,0.000000
65.560005,62.159012,-260.169098,0.010296,0.002159,0.054843,276.497101,14.085433,0.548431,-260.169098,0.054904,0.000000
65.750000,62.132202,-260.169098,0.010313,0.002159,0.054843,276.377838,14.079359,0.548431,-260.169098,0.054904,0.000000
65.940002,62.113960,-260.258057,0.010305,0.002159,0.054843,276.296692,14.075224,0.548431,-260.258057,0.054904,0.000000
66.130005,62.109116,-260.302521,0.010330,0.002159,0.054843,276.275146,14.074127,0.548431,-260.302521,0.054904,0.000000
66.320000,62.090874,-260.302521,0.010313,0.002159,0.054843,276.194000,14.069993,0.548431,-260.302521,0.054904,0.000000
66.510002,62.078957,-260.302521,0.010313,0.002159,0.054843,276.140991,14.067292,0.548431,-260.302521,0.054904,0.000000
66.700005,62.054008,-260.302521,0.010305,0.002159,0.054843,276.030029,14.061640,0.548431,-260.302521,0.054904,0.000000
66.889999,62.041718,-260.347015,0.010322,0.002159,0.054843,275.975342,14.058854,0.548431,-260.347015,0.054904,0.000000
67.080002,62.025703,-260.302521,0.010309,0.002159,0.054843,275.904114,14.055225,0.548431,-260.302521,0.054904,0.000000
67.270004,62.025703,-260.347015,0.010292,0.002159,0.054843,275.904114,14.055225,0.548431,-260.347015,0.054904,0.000000
67.460007,62.004852,-260.347015,0.010313,0.002159,0.054843,275.811371,14.050500,0.548431,-260.347015,0.054904,0.000000
67.650002,61.988838,-260.391479,0.010292,0.002159,0.054843,275.740112,14.046871,0.548431,-260.391479,0.054904,0.000000
67.840004,61.977669,-260.480438,0.010330,0.002159,0.054843,275.690430,14.044340,0.548431,-260.480438,0.054904,0.000000
68.030006,61.965378,-260.435974,0.010330,0.002159,0.054843,275.635773,14.041555,0.548431,-260.435974,0.054904,0.000000
68.220001,61.946762,-260.435974,0.010309,0.002159,0.054843,275.552948,14.037336,0.548431,-260.435974,0.054904,0.000000
68.410004,61.946014,-260.435974,0.010322,0.002159,0.054843,275.549622,14.037168,0.548431,-260.435974,0.054904,0.000000
68.600006,61.921066,-260.524933,0.010309,0.002159,0.054843,275.438660,14.031514,0.548431,-260.524933,0.054904,0.000000
68.790001,61.910645,-260.524933,0.010305,0.002159,0.054843,275.392303,14.029152,0.548431,-260.524933,0.054904,0.000000
68.980003,61.903198,-260.524933,0.010322,0.002159,0.054843,275.359192,14.027466,0.548431,-260.524933,0.054904,0.000000
69.170006,61.886063,-260.569397,0.010326,0.002159,0.054843,275.282959,14.023582,0.548431,-260.569397,0.054904,0.000000
69.360001,61.877502,-260.524933,0.010313,0.002159,0.054843,275.244873,14.021643,0.548431,-260.524933,0.054904,0.000000
69.550003,61.866333,-260.613892,0.010313,0.002159,0.054843,275.195190,14.019112,0.548431,-260.613892,0.054904,0.000000
69.740005,61.844360,-260.658386,0.010317,0.002159,0.054843,275.097443,14.014132,0.548431,-260.658386,0.054904,0.000000
69.930000,61.840263,-260.569397,0.010317,0.002159,0.054843,275.079224,14.013205,0.548431,-260.569397,0.054904,0.000000
70.120003,61.826111,-260.658386,0.010313,0.002159,0.054843,275.016266,14.009996,0.548431,-260.658386,0.054904,0.000000
70.310005,61.816429,-260.480438,0.010330,0.002159,0.054843,274.973206,14.007803,0.548431,-260.480438,0.054904,0.000000
70.500000,61.804520,-260.702850,0.010300,0.002159,0.054843,274.920227,14.005104,0.548431,-260.702850,0.054904,0.000000
70.690002,61.792603,-260.702850,0.010317,0.002159,0.054843,274.867218,14.002403,0.548431,-260.702850,0.054904,0.000000
70.880005,61.783287,-260.658386,0.010317,0.002159,0.054843,274.825775,14.000293,0.548431,-260.658386,0.054904,0.000000
71.070000,61.766907,-260.702850,0.010305,0.002159,0.054843,274.752930,13.996581,0.548431,-260.702850,0.054904,0.000000
71.260002,61.779938,-260.658386,0.010309,0.002159,0.054843,274.810883,13.999534,0.548431,-260.658386,0.054904,0.000000
71.450005,61.758339,-260.658386,0.010322,0.002159,0.054843,274.714813,13.994639,0.548431,-260.658386,0.054904,0.000000
71.640007,61.736374,-260.791809,0.010313,0.002159,0.054843,274.617096,13.989662,0.548431,-260.791809,0.054904,0.000000
71.830002,61.727432,-260.702850,0.010309,0.002159,0.054843,274.577332,13.987636,0.548431,-260.702850,0.054904,0.000000
72.020004,61.714401,-260.791809,0.010313,0.002159,0.054843,274.519379,13.984684,0.548431,-260.791809,0.054904,0.000000
72.210007,61.712914,-260.791809,0.010313,0.002159,0.054843,274.512756,13.984345,0.548431,-260.791809,0.054904,0.000000
72.400002,61.697273,-260.836304,0.010313,0.002159,0.054843,274.443176,13.980802,0.548431,-260.836304,0.054904,0.000000
72.590004,61.684982,-260.836304,0.010326,0.002159,0.054843,274.388519,13.978016,0.548431,-260.836304,0.054904,0.000000
72.780006,61.687592,-260.791809,0.010305,0.002159,0.054843,274.400116,13.978608,0.548431,-260.791809,0.054904,0.000000
72.970001,61.669342,-260.880768,0.010305,0.002159,0.054843,274.318939,13.974473,0.548431,-260.880768,0.054904,0.000000
73.160004,61.658546,-260.880768,0.010322,0.002159,0.054843,274.270905,13.972027,0.548431,-260.880768,0.054904,0.000000
73.350006,61.650352,-260.880768,0.010305,0.002159,0.054843,274.234467,13.970170,0.548431,-260.880768,0.054904,0.000000
73.540001,61.650726,-260.925262,0.010317,0.002159,0.054843,274.236115,13.970254,0.548431,-260.925262,0.054904,0.000000
73.730003,61.644394,-260.880768,0.010317,0.002159,0.054843,274.207947,13.968819,0.548431,-260.880768,0.054904,0.000000
73.920006,61.624657,-260.969727,0.010292,0.002159,0.054843,274.120178,13.964347,0.548431,-260.969727,0.054904,0.000000
74.110001,61.609024,-260.925262,0.010313,0.002159,0.054843,274.050629,13.960805,0.548431,-260.925262,0.054904,0.000000
74.300003,61.601944,-261.014221,0.010317,0.002159,0.054843,274.019135,13.959201,0.548431,-261.014221,0.054904,0.000000
74.490005,61.595612,-261.058716,0.010296,0.002159,0.054843,273.990967,13.957766,0.548431,-261.058716,0.054904,0.000000
74.680000,61.591522,-260.969727,0.010313,0.002159,0.054843,273.972778,13.956838,0.548431,-260.969727,0.054904,0.000000
74.870003,61.571411,-261.014221,0.010322,0.002159,0.054843,273.883301,13.952281,0.548431,-261.014221,0.054904,0.000000
75.060005,61.569923,-261.014221,0.010326,0.002159,0.054843,273.876709,13.951944,0.548431,-261.014221,0.054904,0.000000
75.250000,61.559120,-261.058716,0.010309,0.002159,0.054843,273.828644,13.949495,0.548431,-261.058716,0.054904,0.000000
75.440002,61.563217,-261.103180,0.010317,0.002159,0.054843,273.846863,13.950424,0.548431,-261.103180,0.054904,0.000000
75.630005,61.558006,-261.058716,0.010309,0.002159,0.054843,273.823700,13.949244,0.548431,-261.058716,0.054904,0.000000
75.820007,61.541252,-261.147675,0.010305,0.002159,0.054843,273.749176,13.945448,0.548431,-261.147675,0.054904,0.000000
76.010002,61.545341,-261.103180,0.010305,0.002159,0.054843,273.767365,13.946374,0.548431,-261.103180,0.054904,0.000000
76.200005,61.516296,-261.103180,0.010330,0.002159,0.054843,273.638153,13.939792,0.548431,-261.103180,0.054904,0.000000
76.390007,61.518906,-261.236633,0.010305,0.002159,0.054843,273.649750,13.940384,0.548431,-261.236633,0.054904,0.000000
76.580002,61.520393,-261.192139,0.010313,0.002159,0.054843,273.656372,13.940721,0.548431,-261.192139,0.054904,0.000000
76.770004,61.498428,-261.236633,0.010300,0.002159,0.054843,273.558685,13.935742,0.548431,-261.236633,0.054904,0.000000
76.960007,61.483902,-261.192139,0.010309,0.002159,0.054843,273.494049,13.932452,0.548431,-261.192139,0.054904,0.000000
77.150002,61.477570,-261.192139,0.010305,0.002159,0.054843,273.465881,13.931017,0.548431,-261.192139,0.054904,0.000000
77.340004,61.485390,-261.236633,0.010313,0.002159,0.054843,273.500671,13.932789,0.548431,-261.236633,0.054904,0.000000
77.530006,61.482040,-261.192139,0.010330,0.002159,0.054843,273.485779,13.932030,0.548431,-261.192139,0.054904,0.000000
77.720001,61.464912,-261.325592,0.010322,0.002159,0.054843,273.409576,13.928148,0.548431,-261.325592,0.054904,0.000000
77.910004,61.454117,-261.281097,0.010322,0.002159,0.054843,273.361572,13.925702,0.548431,-261.281097,0.054904,0.000000
78.100006,61.453369,-261.325592,0.010317,0.002159,0.054843,273.358246,13.925532,0.548431,-261.325592,0.054904,0.000000
78.290001,61.446297,-261.414551,0.010326,0.002159,0.054843,273.326782,13.923930,0.548431,-261.414551,0.054904,0.000000
78.480003,61.428047,-261.325592,0.010309,0.002159,0.054843,273.245605,13.919795,0.548431,-261.325592,0.054904,0.000000
78.600006,61.437355,-261.370056,0.010317,0.002159,0.054843,273.287018,13.921904,0.548431,-261.370056,0.054904,0.000000