File: Data/AG AL compression 300N/AG membrane Unpeeled 300N_1_2_03192024_182502.csv
Time (sec),S:Load (lbs),S:HL1 (DIM),S:LVDT (in),S:Position (in),Ch:Position (mm),Ch:Load (N),Ch:Stress (MPa),Ch:Strain (mm/mm),Ch:HL1 (DIM),Set Point (),Cycles ()
0.010000,0.004845,-265.328888,0.000030,-0.000000,-0.000000,0.021550,0.001098,-0.000000,-265.328888,0.000208,0.000000
0.210000,0.009682,-265.328888,-0.000004,-0.000000,-0.000000,0.043066,0.002194,-0.000000,-265.328888,0.000208,0.000000
0.410000,0.005959,-265.373352,0.000017,0.000047,0.001197,0.026505,0.001350,0.011968,-265.373352,0.001752,0.000000
0.610000,-0.023087,-265.417847,0.000013,0.000158,0.004015,-0.102694,-0.005231,0.040150,-265.417847,0.005082,0.000000
0.810000,-0.054367,-265.417847,0.000155,0.000292,0.007406,-0.241837,-0.012320,0.074059,-265.417847,0.008412,0.000000
1.010000,-0.014145,-265.417847,0.000263,0.000419,0.010632,-0.062920,-0.003205,0.106321,-265.417847,0.011742,0.000000
1.210000,0.021599,-265.506805,0.000397,0.000553,0.014040,0.096076,0.004894,0.140401,-265.506805,0.015090,0.000000
1.410000,0.014526,-265.462311,0.000530,0.000683,0.017336,0.064617,0.003292,0.173356,-265.462311,0.018420,0.000000
1.610000,0.035004,-265.462311,0.000655,0.000819,0.020804,0.155704,0.007932,0.208044,-265.462311,0.021750,0.000000
1.810000,0.037239,-265.462311,0.000793,0.000946,0.024039,0.165648,0.008438,0.240394,-265.462311,0.025080,0.000000
2.010000,0.040588,-265.506805,0.000931,0.001080,0.027439,0.180546,0.009197,0.274390,-265.506805,0.028410,0.000000
2.210000,0.015640,-265.506805,0.001039,0.001207,0.030647,0.069571,0.003544,0.306474,-265.506805,0.031740,0.000000
2.410000,0.026070,-265.506805,0.001160,0.001336,0.033926,0.115964,0.005907,0.339255,-265.506805,0.035070,0.000000
2.610000,0.029793,-265.551270,0.001289,0.001466,0.037247,0.132525,0.006751,0.372472,-265.551270,0.038400,0.000000
2.810000,0.051018,-265.551270,0.001414,0.001594,0.040499,0.226938,0.011561,0.404991,-265.551270,0.041731,0.000000
3.010000,0.053619,-265.595764,0.001552,0.001726,0.043847,0.238511,0.012150,0.438469,-265.595764,0.045061,0.000000
3.210000,0.061073,-265.595764,0.001669,0.001854,0.047090,0.271668,0.013839,0.470901,-265.595764,0.048408,0.000000
3.410000,0.048035,-265.640228,0.001841,0.001993,0.050620,0.213669,0.010885,0.506199,-265.640228,0.051738,0.000000
3.610000,0.055489,-265.640228,0.001953,0.002128,0.054063,0.246826,0.012574,0.540627,-265.640228,0.055069,0.000000
3.810000,0.050270,-265.684723,0.002065,0.002261,0.057419,0.223612,0.011391,0.574188,-265.684723,0.058399,0.000000
4.010000,0.045807,-265.684723,0.002212,0.002390,0.060697,0.203759,0.010380,0.606968,-265.684723,0.061729,0.000000
4.210000,0.047295,-265.684723,0.002350,0.002526,0.064157,0.210377,0.010717,0.641570,-265.684723,0.065059,0.000000
4.410000,0.039101,-265.684723,0.002466,0.002657,0.067479,0.173928,0.008860,0.674786,-265.684723,0.068389,0.000000
4.610000,0.051758,-265.640228,0.002578,0.002787,0.070783,0.230230,0.011728,0.707828,-265.640228,0.071719,0.000000
4.810000,0.030533,-265.773682,0.002716,0.002915,0.074044,0.135817,0.006919,0.740435,-265.773682,0.075050,0.000000
5.010000,0.036491,-265.773682,0.002884,0.003048,0.077417,0.162322,0.008269,0.774170,-265.773682,0.078397,0.000000
5.210000,0.027557,-265.773682,0.002988,0.003178,0.080713,0.122581,0.006245,0.807125,-265.773682,0.081727,0.000000
5.410000,0.030533,-265.818176,0.003122,0.003308,0.084017,0.135817,0.006919,0.840167,-265.818176,0.085057,0.000000
5.610000,0.022346,-265.862640,0.003272,0.003438,0.087330,0.099402,0.005064,0.873296,-265.862640,0.088388,0.000000
5.810000,0.016014,-265.862640,0.003389,0.003568,0.090616,0.071234,0.003629,0.906161,-265.862640,0.091717,0.000000
6.010000,0.046547,-265.818176,0.003523,0.003699,0.093955,0.207051,0.010548,0.939551,-265.818176,0.095048,0.000000
6.210001,0.050270,-265.862640,0.003656,0.003829,0.097251,0.223612,0.011391,0.972506,-265.862640,0.098378,0.000000
6.410000,0.017876,-265.862640,0.003798,0.003961,0.100598,0.079515,0.004051,1.005980,-265.862640,0.101708,0.000000
6.610000,0.027931,-265.862640,0.003915,0.004091,0.103920,0.124244,0.006329,1.039196,-265.862640,0.105038,0.000000
6.810000,0.015640,-265.951599,0.004036,0.004219,0.107154,0.069571,0.003544,1.071542,-265.951599,0.108368,0.000000
7.010000,0.009682,-265.907135,0.004182,0.004349,0.110476,0.043066,0.002194,1.104758,-265.907135,0.111716,0.000000
7.210001,-0.005585,-265.996094,0.004294,0.004484,0.113884,-0.024842,-0.001266,1.138841,-265.996094,0.115046,0.000000
7.410000,0.034256,-265.996094,0.004458,0.004615,0.117231,0.152378,0.007763,1.172314,-265.996094,0.118376,0.000000
7.610000,0.049896,-265.951599,0.004575,0.004750,0.120648,0.221950,0.011307,1.206484,-265.951599,0.121706,0.000000
7.810000,0.055489,-265.996094,0.004712,0.004880,0.123961,0.246826,0.012574,1.239610,-265.996094,0.125036,0.000000
8.010000,0.061073,-265.996094,0.004829,0.005015,0.127369,0.271668,0.013839,1.273693,-265.996094,0.128367,0.000000
8.210000,0.049530,-265.996094,0.004975,0.005144,0.130665,0.220321,0.011224,1.306648,-265.996094,0.131697,0.000000
8.410001,0.068146,-266.085052,0.005088,0.005277,0.134038,0.303127,0.015442,1.340383,-266.085052,0.135027,0.000000
8.610001,0.057350,-266.085052,0.005217,0.005404,0.137273,0.255106,0.012996,1.372728,-266.085052,0.138357,0.000000
8.810000,0.077827,-266.085052,0.005359,0.005536,0.140612,0.346194,0.017636,1.406119,-266.085052,0.141687,0.000000
9.010000,0.070381,-266.085052,0.005489,0.005664,0.143855,0.313071,0.015949,1.438552,-266.085052,0.145035,0.000000
9.210000,0.070381,-266.174011,0.005627,0.005794,0.147159,0.313071,0.015949,1.471594,-266.174011,0.148365,0.000000
9.410001,0.074852,-266.085052,0.005752,0.005922,0.150429,0.332958,0.016962,1.504288,-266.085052,0.151695,0.000000
9.610001,0.089745,-266.129517,0.005868,0.006053,0.153742,0.399204,0.020336,1.537417,-266.129517,0.155025,0.000000
9.810000,0.092346,-266.174011,0.006015,0.006191,0.157262,0.410776,0.020926,1.572624,-266.174011,0.158355,0.000000
10.010000,0.089371,-266.218506,0.006127,0.006326,0.160679,0.397541,0.020252,1.606794,-266.218506,0.161685,0.000000
10.210000,0.106125,-266.218506,0.006273,0.006457,0.164018,0.472067,0.024048,1.640180,-266.218506,0.165015,0.000000
10.410001,0.078575,-266.218506,0.006394,0.006587,0.167305,0.349520,0.017805,1.673048,-266.218506,0.168346,0.000000
10.610001,0.070755,-266.218506,0.006515,0.006721,0.170713,0.314734,0.016033,1.707132,-266.218506,0.171676,0.000000
10.810000,0.061813,-266.262970,0.006674,0.006853,0.174078,0.274960,0.014007,1.740779,-266.262970,0.175023,0.000000
11.010000,0.071121,-266.307465,0.006799,0.006982,0.177347,0.316363,0.016116,1.773473,-266.307465,0.178353,0.000000
11.210001,0.058464,-266.351929,0.006924,0.007112,0.180634,0.260061,0.013248,1.806341,-266.351929,0.181684,0.000000
11.410001,0.058464,-266.351929,0.007058,0.007243,0.183973,0.260061,0.013248,1.839731,-266.351929,0.185014,0.000000
11.610001,0.042076,-266.351929,0.007192,0.007374,0.187303,0.187164,0.009535,1.873031,-266.351929,0.188344,0.000000
11.810000,0.048782,-266.351929,0.007325,0.007505,0.190633,0.216995,0.011054,1.906334,-266.351929,0.191674,0.000000
12.010000,0.053993,-266.307465,0.007455,0.007635,0.193938,0.240174,0.012235,1.939376,-266.307465,0.195004,0.000000
12.210001,0.041710,-266.396423,0.007584,0.007764,0.197216,0.185535,0.009452,1.972157,-266.396423,0.198334,0.000000
12.410001,0.064049,-266.396423,0.007718,0.007898,0.200598,0.284903,0.014514,2.005979,-266.396423,0.201664,0.000000
12.610001,0.076714,-266.440887,0.007864,0.008028,0.203910,0.341239,0.017384,2.039105,-266.440887,0.204994,0.000000
12.810000,0.061073,-266.440887,0.007989,0.008159,0.207232,0.271668,0.013839,2.072321,-266.440887,0.208342,0.000000
13.010000,0.064049,-266.529846,0.008110,0.008289,0.210536,0.284903,0.014514,2.105363,-266.529846,0.211672,0.000000
13.210001,0.053619,-266.485382,0.008252,0.008416,0.213771,0.238511,0.012150,2.137709,-266.485382,0.215002,0.000000
13.410001,0.033516,-266.485382,0.008382,0.008548,0.217119,0.149086,0.007595,2.171186,-266.485382,0.218332,0.000000
13.610001,0.027931,-266.529846,0.008537,0.008681,0.220509,0.124244,0.006329,2.205095,-266.529846,0.221663,0.000000
13.810000,0.049530,-266.529846,0.008658,0.008814,0.223874,0.220321,0.011224,2.238743,-266.529846,0.224993,0.000000
14.010000,0.073357,-266.529846,0.008795,0.008948,0.227273,0.326307,0.016623,2.272735,-266.529846,0.228323,0.000000
14.210001,0.083038,-266.529846,0.008933,0.009079,0.230595,0.369373,0.018817,2.305951,-266.529846,0.231653,0.000000
14.410001,0.089745,-266.574341,0.009076,0.009211,0.233969,0.399204,0.020336,2.339686,-266.574341,0.234983,0.000000
14.610001,0.081551,-266.663300,0.009192,0.009342,0.237282,0.362755,0.018480,2.372815,-266.663300,0.238331,0.000000
14.810000,0.100914,-266.574341,0.009347,0.009475,0.240655,0.448888,0.022867,2.406550,-266.574341,0.241661,0.000000
15.010001,0.088997,-266.618835,0.009468,0.009602,0.243890,0.395878,0.020167,2.438895,-266.618835,0.244991,0.000000
15.210001,0.094955,-266.663300,0.009585,0.009733,0.247229,0.422383,0.021517,2.472286,-266.663300,0.248321,0.000000
15.410001,0.106499,-266.663300,0.009727,0.009862,0.250489,0.473730,0.024133,2.504893,-266.663300,0.251651,0.000000
15.610001,0.116180,-266.663300,0.009852,0.009989,0.253733,0.516796,0.026327,2.537325,-266.663300,0.254982,0.000000
15.810000,0.125862,-266.752258,0.009964,0.010121,0.257063,0.559863,0.028521,2.570629,-266.752258,0.258312,0.000000
16.010000,0.162727,-266.752258,0.010089,0.010253,0.260419,0.723847,0.036875,2.604189,-266.752258,0.261642,0.000000
16.210001,0.235344,-266.707794,0.010240,0.010390,0.263905,1.046862,0.053330,2.639052,-266.707794,0.264972,0.000000
16.410000,0.453178,-266.707794,0.010369,0.010525,0.267340,2.015838,0.102692,2.673396,-266.707794,0.268302,0.000000
16.610001,0.703415,-266.752258,0.010447,-0.000000,-0.000000,3.128946,0.159396,-0.000000,-266.752258,0.000191,0.000000
16.810001,0.682930,-266.796753,0.010442,-0.000000,-0.000009,3.037824,0.154754,-0.000087,-266.796753,0.000191,0.000000
17.010000,0.665062,-266.796753,0.010473,-0.000001,-0.000017,2.958343,0.150705,-0.000174,-266.796753,0.000191,0.000000
17.210001,0.687401,-266.841217,0.010447,-0.000001,-0.000017,3.057712,0.155767,-0.000174,-266.841217,0.000425,0.000000
17.410002,0.656494,-266.796753,0.010455,-0.000000,-0.000009,2.920232,0.148764,-0.000087,-266.796753,0.000754,0.000000
17.610001,0.668785,-266.885712,0.010442,-0.000000,-0.000000,2.974905,0.151549,-0.000000,-266.885712,0.001093,0.000000
17.810001,0.760384,-266.841217,0.010447,0.000018,0.000468,3.382355,0.172305,0.004682,-266.841217,0.001422,0.000000
18.010000,0.904495,-266.885712,0.010455,0.000039,0.000989,4.023396,0.204962,0.009886,-266.885712,0.001752,0.000000
18.210001,0.962212,-266.930176,0.010481,0.000051,0.001301,4.280131,0.218040,0.013009,-266.930176,0.002090,0.000000
18.410002,1.028122,-266.885712,0.010499,0.000065,0.001639,4.573315,0.232976,0.016389,-266.885712,0.002419,0.000000
18.610001,1.088074,-266.930176,0.010511,0.000073,0.001856,4.839993,0.246561,0.018557,-266.930176,0.002758,0.000000
18.810001,1.162552,-266.974670,0.010503,0.000088,0.002246,5.171289,0.263438,0.022460,-266.974670,0.003087,0.000000
19.010000,1.262344,-266.930176,0.010524,0.000101,0.002558,5.615188,0.286051,0.025582,-266.930176,0.003425,0.000000
19.210001,1.377411,-266.974670,0.010529,0.000115,0.002914,6.127029,0.312126,0.029136,-266.974670,0.003755,0.000000
19.410002,1.487999,-267.019135,0.010542,0.000128,0.003252,6.618950,0.337185,0.032520,-267.019135,0.004093,0.000000
19.610001,1.606041,-267.108124,0.010563,0.000140,0.003547,7.144027,0.363934,0.035468,-267.108124,0.004423,0.000000
19.810001,1.676422,-266.974670,0.010572,0.000146,0.003720,7.457098,0.379883,0.037202,-266.974670,0.004752,0.000000
20.010000,1.899101,-267.063629,0.010576,0.000168,0.004267,8.447624,0.430342,0.042667,-267.063629,0.005091,0.000000
20.210001,2.023102,-267.019135,0.010598,0.000181,0.004605,8.999207,0.458441,0.046047,-267.019135,0.005420,0.000000
20.410002,2.180244,-267.108124,0.010611,0.000195,0.004943,9.698212,0.494050,0.049431,-267.108124,0.005758,0.000000
20.610001,2.350418,-267.063629,0.010628,0.000206,0.005229,10.455182,0.532612,0.052292,-267.063629,0.006088,0.000000
20.810001,2.489311,-267.152588,0.010637,0.000216,0.005498,11.073009,0.564086,0.054983,-267.152588,0.006426,0.000000
21.010000,2.697464,-267.063629,0.010637,0.000232,0.005889,11.998919,0.611254,0.058885,-267.063629,0.006756,0.000000
21.210001,2.891846,-267.152588,0.010654,0.000248,0.006287,12.863572,0.655302,0.062875,-267.152588,0.007085,0.000000
21.410002,3.108566,-267.152588,0.010662,0.000260,0.006608,13.827594,0.704411,0.066080,-267.152588,0.007423,0.000000
21.610001,3.298477,-267.197083,0.010675,0.000272,0.006912,14.672359,0.747446,0.069116,-267.197083,0.007753,0.000000
21.810001,3.473495,-267.197083,0.010680,0.000282,0.007155,15.450880,0.787105,0.071546,-267.197083,0.008091,0.000000
22.010000,3.750168,-267.241547,0.010697,0.000298,0.007562,16.681580,0.849800,0.075622,-267.241547,0.008421,0.000000
22.210001,4.029816,-267.286041,0.010723,0.000313,0.007952,17.925516,0.913169,0.079524,-267.286041,0.008759,0.000000
22.410002,4.242439,-267.286041,0.010718,0.000326,0.008273,18.871313,0.961351,0.082734,-267.286041,0.009088,0.000000
22.610001,4.476288,-267.286041,0.010727,0.000339,0.008603,19.911522,1.014341,0.086027,-267.286041,0.009427,0.000000
22.810001,4.694130,-267.286041,0.010749,0.000349,0.008872,20.880533,1.063705,0.088718,-267.286041,0.009756,0.000000
23.010000,4.927979,-267.286041,0.010766,0.000361,0.009175,21.920744,1.116696,0.091753,-267.286041,0.010086,0.000000
23.210001,5.273537,-267.286041,0.010774,0.000375,0.009531,23.457863,1.195001,0.095307,-267.286041,0.010424,0.000000
23.410002,5.572929,-267.330505,0.010783,0.000389,0.009877,24.789627,1.262844,0.098774,-267.330505,0.010754,0.000000
23.610001,5.799332,-267.375000,0.010805,0.000399,0.010129,25.796715,1.314147,0.101291,-267.375000,0.011092,0.000000
23.810001,6.084198,-267.419464,0.010787,0.000414,0.010519,27.063864,1.378699,0.105194,-267.419464,0.011421,0.000000
24.010000,6.516144,-267.419464,0.010818,0.000431,0.010944,28.985256,1.476579,0.109444,-267.419464,0.011760,0.000000
24.210001,6.865807,-267.463959,0.010822,0.000446,0.011326,30.540632,1.555814,0.113259,-267.463959,0.012089,0.000000
24.410002,7.099281,-267.463959,0.010835,0.000455,0.011560,31.579180,1.608720,0.115602,-267.463959,0.012419,0.000000
24.610001,7.396439,-267.463959,0.010835,0.000469,0.011916,32.901001,1.676057,0.119156,-267.463959,0.012757,0.000000
24.810001,7.655983,-267.508453,0.010856,0.000480,0.012184,34.055511,1.734871,0.121843,-267.508453,0.013086,0.000000
25.010002,8.011971,-267.508453,0.010865,0.000493,0.012523,35.639027,1.815539,0.125227,-267.508453,0.013425,0.000000
25.210001,8.410408,-267.463959,0.010878,0.000508,0.012896,37.411362,1.905826,0.128955,-267.463959,0.013754,0.000000
25.410002,8.730270,-267.508453,0.010895,0.000521,0.013225,38.834183,1.978307,0.132252,-267.508453,0.014092,0.000000
25.610001,9.009926,-267.597412,0.010887,0.000532,0.013520,40.078152,2.041678,0.135200,-267.597412,0.014422,0.000000
25.810001,9.456398,-267.597412,0.010908,0.000549,0.013936,42.064159,2.142850,0.139364,-267.597412,0.014760,0.000000
26.010002,9.936012,-267.597412,0.010904,0.000564,0.014335,44.197590,2.251533,0.143353,-267.597412,0.015090,0.000000
26.210001,10.178802,-267.597412,0.010938,0.000575,0.014613,45.277576,2.306550,0.146127,-267.597412,0.015419,0.000000
26.410002,10.408188,-267.597412,0.010947,0.000585,0.014847,46.297932,2.358529,0.148470,-267.597412,0.015757,0.000000
26.610001,10.783905,-267.597412,0.010938,0.000598,0.015185,47.969204,2.443668,0.151850,-267.597412,0.016087,0.000000
26.810001,11.005096,-267.730835,0.010956,0.000607,0.015411,48.953114,2.493790,0.154106,-267.730835,0.016425,0.000000
27.010002,11.354012,-267.730835,0.010964,0.000619,0.015723,50.505165,2.572856,0.157228,-267.730835,0.016755,0.000000
27.210001,11.886505,-267.775330,0.010990,0.000635,0.016139,52.873814,2.693521,0.161392,-267.775330,0.017093,0.000000
27.410002,12.293137,-267.641876,0.011003,0.000650,0.016512,54.682602,2.785665,0.165120,-267.641876,0.017423,0.000000
27.610001,12.394791,-267.730835,0.010994,0.000656,0.016668,55.134781,2.808700,0.166679,-267.730835,0.017761,0.000000
27.810001,12.858025,-267.775330,0.011012,0.000674,0.017110,57.195351,2.913670,0.171104,-267.775330,0.018090,0.000000
28.010002,13.550636,-267.730835,0.011012,0.000693,0.017605,60.276241,3.070618,0.176047,-267.730835,0.018420,0.000000
28.210001,13.791557,-267.775330,0.011037,0.000704,0.017873,61.347912,3.125211,0.178734,-267.775330,0.018758,0.000000
28.410002,14.029137,-267.775330,0.011042,0.000714,0.018133,62.404716,3.179048,0.181334,-267.775330,0.019088,0.000000
28.610001,14.381767,-267.819794,0.011063,0.000727,0.018454,63.973297,3.258955,0.184544,-267.819794,0.019426,0.000000
28.810001,14.656212,-267.864288,0.011059,0.000738,0.018749,65.194084,3.321145,0.187492,-267.864288,0.019755,0.000000
29.010002,15.188332,-267.819794,0.011068,0.000755,0.019183,67.561073,3.441725,0.191830,-267.819794,0.020094,0.000000
29.210001,15.724548,-267.908783,0.011094,0.000770,0.019556,69.946281,3.563233,0.195558,-267.908783,0.020423,0.000000
29.410002,15.881683,-267.864288,0.011089,0.000779,0.019799,70.645256,3.598841,0.197988,-267.864288,0.020753,0.000000
29.610001,16.172882,-267.864288,0.011098,0.000790,0.020068,71.940575,3.664828,0.200675,-267.864288,0.021091,0.000000
29.810001,16.709846,-267.864288,0.011106,0.000808,0.020527,74.329109,3.786505,0.205270,-267.864288,0.021420,0.000000
30.010002,17.234886,-267.953247,0.011132,0.000824,0.020935,76.664604,3.905481,0.209346,-267.953247,0.021759,0.000000
30.210001,17.493690,-267.953247,0.011141,0.000836,0.021238,77.815819,3.964127,0.212382,-267.953247,0.022088,0.000000
30.410002,17.504486,-267.953247,0.011145,0.000846,0.021481,77.863846,3.966573,0.214812,-267.953247,0.022426,0.000000
30.610001,17.927872,-267.953247,0.011163,0.000857,0.021759,79.747154,4.062514,0.217586,-267.953247,0.022756,0.000000
30.810001,18.437653,-268.042206,0.011175,0.000872,0.022149,82.014778,4.178032,0.221488,-268.042206,0.023094,0.000000
31.010002,18.923973,-267.997742,0.011193,0.000888,0.022548,84.178040,4.288233,0.225478,-267.997742,0.023424,0.000000
31.210001,19.217400,-267.997742,0.011175,0.000899,0.022843,85.483261,4.354725,0.228426,-267.997742,0.023753,0.000000
31.410002,19.381615,-268.131165,0.011210,0.000908,0.023059,86.213730,4.391937,0.230595,-268.131165,0.024092,0.000000
31.610001,19.736488,-268.131165,0.011201,0.000921,0.023398,87.792282,4.472353,0.233978,-268.131165,0.024421,0.000000
31.810001,20.337868,-268.131165,0.011210,0.000940,0.023866,90.467354,4.608626,0.238660,-268.131165,0.024759,0.000000
32.010002,20.724762,-268.131165,0.011227,0.000954,0.024221,92.188347,4.696298,0.242214,-268.131165,0.025089,0.000000
32.210003,21.021545,-268.131165,0.011249,0.000967,0.024560,93.508507,4.763550,0.245598,-268.131165,0.025427,0.000000
32.410000,21.322418,-268.175659,0.011236,0.000981,0.024907,94.846855,4.831729,0.249065,-268.175659,0.025757,0.000000
32.610001,21.417007,-268.175659,0.011262,0.000988,0.025089,95.267609,4.853163,0.250889,-268.175659,0.026095,0.000000
32.810001,21.918221,-268.131165,0.011262,0.001003,0.025488,97.497116,4.966740,0.254879,-268.131165,0.026424,0.000000
33.010002,22.393738,-268.264618,0.011279,0.001019,0.025887,99.612320,5.074493,0.258868,-268.264618,0.026754,0.000000
33.210003,22.636520,-268.264618,0.011283,0.001029,0.026138,100.692268,5.129508,0.261381,-268.264618,0.027092,0.000000
33.410000,22.792175,-268.220123,0.011313,0.001038,0.026372,101.384659,5.164781,0.263724,-268.220123,0.027422,0.000000
33.610001,23.015968,-268.264618,0.011313,0.001049,0.026641,102.380142,5.215493,0.266411,-268.264618,0.027760,0.000000
33.810001,23.911896,-268.264618,0.011322,0.001072,0.027231,106.365425,5.418513,0.272308,-268.264618,0.028089,0.000000
34.010002,24.153572,-268.264618,0.011344,0.001085,0.027552,107.440453,5.473278,0.275518,-268.264618,0.028428,0.000000
34.210003,24.381462,-268.309082,0.011344,0.001097,0.027855,108.454163,5.524919,0.278553,-268.309082,0.028757,0.000000
34.410000,24.650314,-268.309082,0.011369,0.001111,0.028219,109.650078,5.585841,0.282194,-268.309082,0.029087,0.000000
34.610001,24.840965,-268.309082,0.011378,0.001123,0.028514,110.498131,5.629044,0.285143,-268.309082,0.029425,0.000000
34.810001,25.468040,-268.353577,0.011378,0.001139,0.028922,113.287498,5.771141,0.289219,-268.353577,0.029755,0.000000
35.010002,25.576775,-268.353577,0.011391,0.001148,0.029147,113.771179,5.795780,0.291475,-268.353577,0.030093,0.000000
35.210003,25.950264,-268.398071,0.011387,0.001161,0.029494,115.432541,5.880414,0.294942,-268.398071,0.030422,0.000000
35.410000,26.182625,-268.487030,0.011408,0.001173,0.029789,116.466133,5.933068,0.297890,-268.487030,0.030761,0.000000
35.610001,26.807098,-268.398071,0.011421,0.001190,0.030214,119.243927,6.074575,0.302141,-268.398071,0.031090,0.000000
35.810001,27.140366,-268.442535,0.011434,0.001203,0.030561,120.726379,6.150095,0.305611,-268.442535,0.031428,0.000000
36.010002,27.579025,-268.442535,0.011443,0.001217,0.030917,122.677628,6.249496,0.309165,-268.442535,0.031758,0.000000
36.210003,27.712334,-268.487030,0.011456,0.001229,0.031229,123.270615,6.279705,0.312288,-268.487030,0.032087,0.000000
36.410000,27.870216,-268.531494,0.011460,0.001239,0.031471,123.972916,6.315481,0.314714,-268.531494,0.032426,0.000000
36.610001,28.357285,-268.487030,0.011477,0.001253,0.031818,126.139503,6.425852,0.318185,-268.487030,0.032755,0.000000
36.810001,28.798912,-268.531494,0.011482,0.001269,0.032226,128.103958,6.525927,0.322261,-268.531494,0.033093,0.000000
37.010002,29.028671,-268.531494,0.011503,0.001280,0.032504,129.125977,6.577991,0.325035,-268.531494,0.033423,0.000000
37.210003,29.359337,-268.575989,0.011512,0.001290,0.032764,130.596848,6.652921,0.327636,-268.575989,0.033761,0.000000
37.410004,30.039291,-268.620453,0.011529,0.001310,0.033284,133.621445,6.807001,0.332840,-268.620453,0.034091,0.000000
37.610001,30.291008,-268.575989,0.011520,0.001322,0.033579,134.741135,6.864041,0.335788,-268.575989,0.034420,0.000000
37.810001,30.856644,-268.620453,0.011546,0.001339,0.034013,137.257202,6.992216,0.340126,-268.620453,0.034758,0.000000
38.010002,30.998894,-268.664948,0.011555,0.001348,0.034246,137.889969,7.024450,0.342465,-268.664948,0.035088,0.000000
38.210003,31.100922,-268.709412,0.011568,0.001358,0.034481,138.343811,7.047570,0.344808,-268.709412,0.035426,0.000000
38.410004,31.561172,-268.664948,0.011568,0.001373,0.034880,140.391113,7.151864,0.348797,-268.664948,0.035756,0.000000
38.610001,32.123459,-268.709412,0.011576,0.001387,0.035227,142.892288,7.279280,0.352268,-268.709412,0.036094,0.000000
38.810001,32.475349,-268.753906,0.011594,0.001399,0.035530,144.457565,7.359019,0.355303,-268.753906,0.036424,0.000000
39.010002,32.879372,-268.709412,0.011602,0.001413,0.035886,146.254745,7.450572,0.358857,-268.709412,0.036762,0.000000
39.210003,32.836548,-268.709412,0.011628,0.001417,0.035999,146.064255,7.440868,0.359985,-268.709412,0.037091,0.000000
39.410004,33.996490,-268.709412,0.011615,0.001442,0.036631,151.223938,7.703715,0.366313,-268.709412,0.037421,0.000000
39.610001,34.193474,-268.753906,0.011624,0.001454,0.036927,152.100174,7.748352,0.369266,-268.753906,0.037759,0.000000
39.810001,34.686867,-268.753906,0.011637,0.001467,0.037265,154.294891,7.860156,0.372646,-268.753906,0.038089,0.000000
40.010002,34.810493,-268.842865,0.011628,0.001478,0.037533,154.844803,7.888170,0.375333,-268.842865,0.038427,0.000000
40.210003,35.323997,-268.842865,0.011650,0.001490,0.037846,157.128983,8.004532,0.378455,-268.842865,0.038756,0.000000
40.410004,35.732117,-268.887360,0.011671,0.001504,0.038210,158.944397,8.097013,0.382100,-268.887360,0.039095,0.000000
40.610001,36.090340,-268.842865,0.011689,0.001514,0.038453,160.537842,8.178187,0.384526,-268.842865,0.039424,0.000000
40.810001,36.667892,-268.887360,0.011671,0.001530,0.038852,163.106934,8.309063,0.388516,-268.887360,0.039762,0.000000
41.010002,36.997070,-268.887360,0.011693,0.001541,0.039138,164.571182,8.383656,0.391377,-268.887360,0.040092,0.000000
41.210003,37.046967,-268.931824,0.011697,0.001550,0.039372,164.793137,8.394962,0.393720,-268.931824,0.040421,0.000000
41.410004,38.131317,-268.931824,0.011714,0.001568,0.039823,169.616577,8.640680,0.398228,-268.931824,0.040760,0.000000
41.610001,38.750198,-268.931824,0.011745,0.001584,0.040230,172.369492,8.780920,0.402304,-268.931824,0.041089,0.000000
41.810001,39.146774,-268.931824,0.011749,0.001600,0.040629,174.133545,8.870786,0.406293,-268.931824,0.041427,0.000000
42.010002,39.588409,-269.020782,0.011762,0.001609,0.040881,176.098038,8.970861,0.408810,-269.020782,0.041757,0.000000
42.210003,39.837524,-268.976318,0.011758,0.001620,0.041158,177.206161,9.027312,0.411585,-268.976318,0.042095,0.000000
42.410004,40.375603,-268.976318,0.011753,0.001634,0.041505,179.599655,9.149242,0.415052,-268.976318,0.042425,0.000000
42.610001,41.073425,-269.020782,0.011783,0.001649,0.041887,182.703720,9.307371,0.418871,-269.020782,0.042754,0.000000
42.810001,41.667732,-269.065277,0.011801,0.001664,0.042269,185.347336,9.442043,0.422686,-269.065277,0.043093,0.000000
43.010002,41.863602,-269.065277,0.011801,0.001671,0.042442,186.218597,9.486428,0.424419,-269.065277,0.043422,0.000000
43.210003,42.294807,-269.109741,0.011805,0.001684,0.042772,188.136703,9.584140,0.427716,-269.109741,0.043760,0.000000
43.410004,43.057800,-269.109741,0.011809,0.001700,0.043179,191.530655,9.757037,0.431792,-269.109741,0.044090,0.000000
43.610001,43.795471,-269.154236,0.011818,0.001714,0.043535,194.811981,9.924195,0.435346,-269.154236,0.044428,0.000000
43.810001,44.461273,-269.154236,0.011818,0.001731,0.043968,197.773621,10.075068,0.439684,-269.154236,0.044758,0.000000
44.010002,44.750610,-269.198730,0.011818,0.001741,0.044211,199.060654,10.140633,0.442110,-269.198730,0.045096,0.000000
44.210003,45.127449,-269.243195,0.011857,0.001751,0.044480,200.736923,10.226027,0.444801,-269.243195,0.045425,0.000000
44.410004,45.536316,-269.243195,0.011848,0.001763,0.044784,202.555649,10.318677,0.447836,-269.243195,0.045755,0.000000
44.610001,46.239349,-269.154236,0.011861,0.001777,0.045139,205.682892,10.477986,0.451390,-269.154236,0.046093,0.000000
44.810001,46.857117,-269.287689,0.011878,0.001789,0.045434,208.430862,10.617974,0.454339,-269.287689,0.046422,0.000000
45.010002,47.213852,-269.332153,0.011878,0.001798,0.045659,210.017700,10.698812,0.456595,-269.332153,0.046761,0.000000
45.210003,48.392784,-269.243195,0.011874,0.001819,0.046214,215.261856,10.965961,0.462143,-269.243195,0.047090,0.000000
45.410004,49.123375,-269.287689,0.011878,0.001834,0.046578,218.511688,11.131516,0.465784,-269.287689,0.047429,0.000000
45.610001,49.688637,-269.332153,0.011900,0.001846,0.046899,221.026093,11.259606,0.468994,-269.332153,0.047758,0.000000
45.810001,49.979088,-269.332153,0.011908,0.001857,0.047160,222.318085,11.325423,0.471598,-269.332153,0.048087,0.000000
46.010002,50.758095,-269.287689,0.011926,0.001871,0.047515,225.783279,11.501949,0.475152,-269.287689,0.048426,0.000000
46.210003,51.215736,-269.376648,0.011943,0.001883,0.047827,227.818970,11.605652,0.478274,-269.376648,0.048756,0.000000
46.410004,51.749344,-269.376648,0.011926,0.001896,0.048148,230.192581,11.726569,0.481484,-269.376648,0.049093,0.000000
46.610001,52.739487,-269.421112,0.011934,0.001911,0.048530,234.596954,11.950938,0.485299,-269.421112,0.049423,0.000000
46.810001,53.213516,-269.376648,0.011943,0.001921,0.048790,236.705536,12.058355,0.487899,-269.376648,0.049761,0.000000
47.010002,53.849525,-269.465607,0.011977,0.001935,0.049146,239.534653,12.202477,0.491457,-269.465607,0.050091,0.000000
47.210003,54.811737,-269.465607,0.011960,0.001951,0.049562,243.814789,12.420518,0.495617,-269.465607,0.050429,0.000000
47.410004,55.668198,-269.510071,0.011977,0.001966,0.049935,247.624512,12.614594,0.499349,-269.510071,0.050758,0.000000
47.610001,56.062538,-269.510071,0.011977,0.001976,0.050195,249.378632,12.703953,0.501949,-269.510071,0.051088,0.000000
47.810001,56.552582,-269.465607,0.011986,0.001987,0.050472,251.558441,12.814998,0.504723,-269.465607,0.051427,0.000000
48.010002,57.139809,-269.554565,0.011990,0.001999,0.050785,254.170563,12.948066,0.507846,-269.554565,0.051756,0.000000
48.210003,57.515907,-269.510071,0.011999,0.002007,0.050975,255.843536,13.033291,0.509753,-269.510071,0.052094,0.000000
48.410004,58.417046,-269.554565,0.012008,0.002025,0.051435,259.851990,13.237492,0.514352,-269.554565,0.052424,0.000000
48.610001,59.333458,-269.599030,0.012012,0.002038,0.051756,263.928406,13.445153,0.517558,-269.599030,0.052762,0.000000
48.810001,60.061073,-269.599030,0.012012,0.002049,0.052051,267.165009,13.610034,0.520506,-269.599030,0.053091,0.000000
49.010002,60.680702,-269.599030,0.012025,0.002064,0.052415,269.921234,13.750444,0.524151,-269.599030,0.053430,0.000000
49.210003,61.563965,-269.688019,0.012029,0.002077,0.052744,273.850189,13.950594,0.527444,-269.688019,0.053759,0.000000
49.410004,62.788704,-269.599030,0.012046,0.002095,0.053213,279.298096,14.228124,0.532130,-269.599030,0.054089,0.000000
49.610001,63.422478,-269.688019,0.012051,0.002107,0.053525,282.117279,14.371738,0.535252,-269.688019,0.054427,0.000000
49.810001,63.683891,-269.688019,0.012059,0.002115,0.053725,283.280090,14.430976,0.537247,-269.688019,0.054756,0.000000
50.010002,64.467354,-269.688019,0.012055,0.002131,0.054124,286.765106,14.608511,0.541236,-269.688019,0.055095,0.000000
50.210003,65.005440,-269.688019,0.012072,0.002139,0.054323,289.158630,14.730443,0.543231,-269.688019,0.055424,0.000000
50.410004,66.189201,-269.776978,0.012072,0.002156,0.054756,294.424286,14.998688,0.547565,-269.776978,0.055762,0.000000
50.610001,67.143974,-269.776978,0.012098,0.002170,0.055130,298.671326,15.215042,0.551296,-269.776978,0.056092,0.000000
50.810001,67.256050,-269.776978,0.012081,0.002167,0.055034,299.169861,15.240438,0.550339,-269.776978,0.055259,0.000000
51.010002,66.834526,-269.732483,0.012111,0.002167,0.055034,297.294830,15.144920,0.550339,-269.732483,0.055259,0.000000
51.210003,66.515770,-269.821442,0.012107,0.002165,0.054999,295.876923,15.072689,0.549994,-269.821442,0.055034,0.000000
51.410004,66.222725,-269.776978,0.012098,0.002165,0.054982,294.573395,15.006285,0.549820,-269.776978,0.055034,0.000000
51.610001,65.976952,-269.910400,0.012120,0.002164,0.054973,293.480133,14.950591,0.549733,-269.910400,0.055034,0.000000
51.810001,65.751671,-269.865936,0.012107,0.002164,0.054973,292.478027,14.899541,0.549733,-269.865936,0.055034,0.000000
52.010002,65.566978,-269.865936,0.012094,0.002164,0.054965,291.656494,14.857690,0.549646,-269.865936,0.055034,0.000000
52.210003,65.391960,-269.910400,0.012120,0.002164,0.054965,290.877960,14.818030,0.549646,-269.910400,0.055034,0.000000
52.410004,65.236671,-269.910400,0.012128,0.002164,0.054965,290.187195,14.782842,0.549646,-269.910400,0.055034,0.000000
52.610001,65.111183,-269.954895,0.012128,0.002164,0.054965,289.628998,14.754405,0.549646,-269.954895,0.055034,0.000000
52.810001,64.977135,-269.999359,0.012115,0.002164,0.054965,289.032745,14.724030,0.549646,-269.999359,0.055034,0.000000
53.010002,64.853508,-269.954895,0.012115,0.002164,0.054956,288.482819,14.696015,0.549559,-269.954895,0.055034,0.000000
53.210003,64.748863,-269.999359,0.012120,0.002164,0.054956,288.017334,14.672302,0.549559,-269.999359,0.055034,0.000000
53.410004,64.633812,-269.999359,0.012115,0.002164,0.054956,287.505554,14.646231,0.549559,-269.999359,0.055034,0.000000
53.610004,64.556358,-269.999359,0.012120,0.002164,0.054956,287.161011,14.628679,0.549559,-269.999359,0.055034,0.000000
53.810001,64.459908,-270.043854,0.012107,0.002164,0.054956,286.731995,14.606823,0.549559,-270.043854,0.055034,0.000000
54.010002,64.382454,-270.043854,0.012124,0.002164,0.054956,286.387451,14.589273,0.549559,-270.043854,0.055034,0.000000
54.210003,64.300529,-270.088348,0.012107,0.002164,0.054956,286.023041,14.570708,0.549559,-270.088348,0.055034,0.000000
54.410004,64.221596,-270.043854,0.012128,0.002164,0.054956,285.671936,14.552821,0.549559,-270.043854,0.055034,0.000000
54.610004,64.149345,-270.043854,0.012115,0.002164,0.054956,285.350525,14.536449,0.549559,-270.043854,0.055034,0.000000
54.810001,64.074883,-270.132812,0.012128,0.002164,0.054956,285.019318,14.519576,0.549559,-270.132812,0.055034,0.000000
55.010002,64.016045,-270.132812,0.012120,0.002164,0.054956,284.757599,14.506243,0.549559,-270.132812,0.055034,0.000000
55.210003,63.953850,-270.132812,0.012128,0.002164,0.054956,284.480927,14.492149,0.549559,-270.132812,0.055034,0.000000
55.410004,63.894279,-270.177307,0.012133,0.002164,0.054956,284.215942,14.478651,0.549559,-270.177307,0.055034,0.000000
55.610004,63.832832,-270.177307,0.012137,0.002164,0.054956,283.942627,14.464726,0.549559,-270.177307,0.055034,0.000000
55.810001,63.785912,-270.221771,0.012133,0.002163,0.054947,283.733917,14.454095,0.549472,-270.221771,0.055034,0.000000
56.010002,63.735268,-270.266266,0.012120,0.002163,0.054947,283.508636,14.442617,0.549472,-270.266266,0.055034,0.000000
56.210003,63.675316,-270.266266,0.012137,0.002163,0.054947,283.241943,14.429032,0.549472,-270.266266,0.055034,0.000000
56.410004,63.634361,-270.266266,0.012111,0.002163,0.054947,283.059784,14.419753,0.549472,-270.266266,0.055034,0.000000
56.610004,63.585945,-270.310730,0.012128,0.002163,0.054947,282.844421,14.408782,0.549472,-270.310730,0.055034,0.000000
56.810001,63.537544,-270.310730,0.012111,0.002163,0.054947,282.629120,14.397813,0.549472,-270.310730,0.055034,0.000000
57.010002,63.492485,-270.310730,0.012111,0.002163,0.054947,282.428680,14.387603,0.549472,-270.310730,0.055034,0.000000
57.210003,63.442955,-270.310730,0.012120,0.002163,0.054947,282.208344,14.376379,0.549472,-270.310730,0.055034,0.000000
57.410004,63.408699,-270.355225,0.012115,0.002163,0.054947,282.055969,14.368617,0.549472,-270.355225,0.055034,0.000000
57.610004,63.372215,-270.355225,0.012124,0.002163,0.054947,281.893707,14.360349,0.549472,-270.355225,0.055034,0.000000
57.810001,63.327522,-270.399689,0.012111,0.002163,0.054947,281.694885,14.350223,0.549472,-270.399689,0.055034,0.000000
58.010002,63.295128,-270.399689,0.012128,0.002163,0.054947,281.550781,14.342881,0.549472,-270.399689,0.055034,0.000000
58.210003,63.259010,-270.399689,0.012128,0.002163,0.054947,281.390137,14.334697,0.549472,-270.399689,0.055034,0.000000
58.410004,63.219170,-270.399689,0.012128,0.002163,0.054947,281.212921,14.325668,0.549472,-270.399689,0.055034,0.000000
58.610004,63.190865,-270.488678,0.012124,0.002163,0.054947,281.087006,14.319255,0.549472,-270.488678,0.055034,0.000000
58.810001,63.155861,-270.488678,0.012137,0.002163,0.054947,280.931305,14.311323,0.549472,-270.488678,0.055034,0.000000
59.010002,63.123085,-270.533142,0.012133,0.002163,0.054947,280.785492,14.303896,0.549472,-270.533142,0.055034,0.000000
59.210003,63.077293,-270.533142,0.012124,0.002163,0.054947,280.581818,14.293519,0.549472,-270.533142,0.055034,0.000000
59.410004,63.049362,-270.533142,0.012137,0.002163,0.054947,280.457581,14.287189,0.549472,-270.533142,0.055034,0.000000
59.610004,63.030373,-270.533142,0.012128,0.002163,0.054947,280.373108,14.282887,0.549472,-270.533142,0.055034,0.000000
59.810001,62.983452,-270.577637,0.012137,0.002163,0.054947,280.164398,14.272254,0.549472,-270.577637,0.055034,0.000000
60.010002,62.962227,-270.577637,0.012128,0.002163,0.054947,280.069977,14.267445,0.549472,-270.577637,0.055034,0.000000
60.210003,62.935417,-270.577637,0.012128,0.002163,0.054947,279.950714,14.261370,0.549472,-270.577637,0.055034,0.000000
60.410004,62.906372,-270.622101,0.012124,0.002163,0.054947,279.821533,14.254788,0.549472,-270.622101,0.055034,0.000000
60.610004,62.885147,-270.711060,0.012137,0.002163,0.054947,279.727112,14.249978,0.549472,-270.711060,0.055034,0.000000
60.810001,62.859451,-270.622101,0.012120,0.002163,0.054947,279.612793,14.244155,0.549472,-270.622101,0.055034,0.000000
61.010002,62.824448,-270.711060,0.012150,0.002163,0.054947,279.457092,14.236223,0.549472,-270.711060,0.055034,0.000000
61.210003,62.799500,-270.711060,0.012124,0.002163,0.054947,279.346130,14.230571,0.549472,-270.711060,0.055034,0.000000
61.410004,62.771202,-270.711060,0.012120,0.002163,0.054947,279.220245,14.224157,0.549472,-270.711060,0.055034,0.000000
61.610004,62.752579,-270.711060,0.012141,0.002163,0.054947,279.137421,14.219938,0.549472,-270.711060,0.055034,0.000000
61.810001,62.714600,-270.800018,0.012133,0.002163,0.054947,278.968475,14.211331,0.549472,-270.800018,0.055034,0.000000
62.010002,62.693001,-270.800018,0.012133,0.002163,0.054947,278.872406,14.206437,0.549472,-270.800018,0.055034,0.000000
62.210003,62.679596,-270.711060,0.012128,0.002163,0.054947,278.812775,14.203400,0.549472,-270.711060,0.055034,0.000000
62.410004,62.655396,-270.844513,0.012141,0.002163,0.054947,278.705109,14.197915,0.549472,-270.844513,0.055034,0.000000
62.610004,62.639008,-270.755554,0.012128,0.002163,0.054947,278.632233,14.194202,0.549472,-270.755554,0.055034,0.000000
62.810001,62.610710,-270.844513,0.012137,0.002163,0.054947,278.506348,14.187790,0.549472,-270.844513,0.055034,0.000000
63.010002,62.587624,-270.844513,0.012154,0.002163,0.054947,278.403656,14.182558,0.549472,-270.844513,0.055034,0.000000
63.210003,62.541443,-270.888977,0.012133,0.002163,0.054947,278.198242,14.172093,0.549472,-270.888977,0.055034,0.000000
63.410004,62.520592,-270.888977,0.012120,0.002163,0.054947,278.105469,14.167368,0.549472,-270.888977,0.055034,0.000000
63.610004,62.516121,-270.933472,0.012128,0.002163,0.054947,278.085602,14.166355,0.549472,-270.933472,0.055034,0.000000
63.810001,62.493034,-270.888977,0.012141,0.002163,0.054947,277.982910,14.161124,0.549472,-270.888977,0.055034,0.000000
64.010002,62.476280,-270.977966,0.012150,0.002163,0.054947,277.908386,14.157328,0.549472,-270.977966,0.055034,0.000000
64.210007,62.450584,-270.977966,0.012133,0.002163,0.054947,277.794067,14.151505,0.549472,-270.977966,0.055034,0.000000
64.410004,62.441277,-271.022430,0.012133,0.002163,0.054947,277.752655,14.149396,0.549472,-271.022430,0.055034,0.000000
64.610001,62.421913,-271.022430,0.012137,0.002163,0.054947,277.666534,14.145007,0.549472,-271.022430,0.055034,0.000000
64.810005,62.393616,-270.977966,0.012141,0.002163,0.054947,277.540649,14.138596,0.549472,-270.977966,0.055034,0.000000
65.010002,62.372391,-271.022430,0.012128,0.002163,0.054947,277.446259,14.133785,0.549472,-271.022430,0.055034,0.000000
65.210007,62.366432,-271.111389,0.012137,0.002163,0.054947,277.419739,14.132436,0.549472,-271.111389,0.055034,0.000000
65.410004,62.340363,-271.066925,0.012137,0.002163,0.054947,277.303772,14.126528,0.549472,-271.066925,0.055034,0.000000
65.610001,62.318398,-271.111389,0.012141,0.002163,0.054947,277.206085,14.121551,0.549472,-271.111389,0.055034,0.000000
65.810005,62.303497,-271.066925,0.012141,0.002163,0.054947,277.139801,14.118175,0.549472,-271.066925,0.055034,0.000000
66.010002,62.290466,-271.155884,0.012128,0.002163,0.054947,277.081818,14.115221,0.549472,-271.155884,0.055034,0.000000
66.210007,62.263283,-271.155884,0.012128,0.002163,0.054947,276.960907,14.109061,0.549472,-271.155884,0.055034,0.000000
66.410004,62.257324,-271.111389,0.012141,0.002163,0.054947,276.934418,14.107712,0.549472,-271.111389,0.055034,0.000000
66.610001,62.229401,-271.155884,0.012141,0.002163,0.054947,276.810211,14.101383,0.549472,-271.155884,0.055034,0.000000
66.810005,62.208176,-271.200348,0.012124,0.002163,0.054947,276.715790,14.096574,0.549472,-271.200348,0.055034,0.000000
67.010002,62.207054,-271.244843,0.012128,0.002163,0.054947,276.710785,14.096320,0.549472,-271.244843,0.055034,0.000000
67.210007,62.179497,-271.289307,0.012133,0.002163,0.054947,276.588226,14.090075,0.549472,-271.289307,0.055034,0.000000
67.410004,62.163857,-271.289307,0.012124,0.002163,0.054947,276.518646,14.086532,0.549472,-271.289307,0.055034,0.000000
67.610001,62.151947,-271.289307,0.012128,0.002163,0.054947,276.465668,14.083833,0.549472,-271.289307,0.055034,0.000000
67.810005,62.138542,-271.289307,0.012133,0.002163,0.054947,276.406036,14.080794,0.549472,-271.289307,0.055034,0.000000
68.010002,62.108376,-271.244843,0.012141,0.002163,0.054947,276.271851,14.073958,0.549472,-271.244843,0.055034,0.000000
68.210007,62.108002,-271.333801,0.012124,0.002163,0.054947,276.270203,14.073874,0.549472,-271.333801,0.055034,0.000000
68.410004,62.086777,-271.378296,0.012137,0.002163,0.054947,276.175781,14.069064,0.549472,-271.378296,0.055034,0.000000
68.610001,62.080078,-271.333801,0.012141,0.002163,0.054947,276.145966,14.067547,0.549472,-271.333801,0.055034,0.000000
68.810005,62.059967,-271.422760,0.012128,0.002163,0.054947,276.056519,14.062989,0.549472,-271.422760,0.055034,0.000000
69.010002,62.053635,-271.378296,0.012137,0.002163,0.054947,276.028351,14.061555,0.549472,-271.378296,0.055034,0.000000
69.210007,62.039490,-271.467255,0.012133,0.002163,0.054947,275.965424,14.058350,0.549472,-271.467255,0.055034,0.000000
69.410004,62.026085,-271.422760,0.012137,0.002163,0.054947,275.905792,14.055311,0.549472,-271.422760,0.055034,0.000000
69.610001,62.012680,-271.422760,0.012124,0.002163,0.054947,275.846191,14.052274,0.549472,-271.422760,0.055034,0.000000
69.810005,61.994804,-271.422760,0.012128,0.002163,0.054947,275.766663,14.048223,0.549472,-271.422760,0.055034,0.000000
70.010002,61.981400,-271.511719,0.012150,0.002163,0.054947,275.707031,14.045185,0.549472,-271.511719,0.055034,0.000000
70.210007,61.971718,-271.511719,0.012141,0.002163,0.054947,275.663971,14.042993,0.549472,-271.511719,0.055034,0.000000
70.410004,61.955330,-271.511719,0.012133,0.002163,0.054947,275.591064,14.039278,0.549472,-271.511719,0.055034,0.000000
70.610001,61.951233,-271.511719,0.012137,0.002163,0.054947,275.572845,14.038349,0.549472,-271.511719,0.055034,0.000000
70.810005,61.935226,-271.511719,0.012133,0.002163,0.054947,275.501648,14.034722,0.549472,-271.511719,0.055034,0.000000
71.010002,61.914001,-271.556213,0.012137,0.002163,0.054947,275.407227,14.029913,0.549472,-271.556213,0.055034,0.000000
71.210007,61.906181,-271.556213,0.012124,0.002163,0.054947,275.372437,14.028141,0.549472,-271.556213,0.055034,0.000000
71.410004,61.891655,-271.556213,0.012133,0.002163,0.054947,275.307831,14.024849,0.549472,-271.556213,0.055034,0.000000
71.610001,61.886070,-271.600677,0.012141,0.002163,0.054947,275.282990,14.023583,0.549472,-271.600677,0.055034,0.000000
71.810005,61.869316,-271.600677,0.012137,0.002163,0.054947,275.208466,14.019788,0.549472,-271.600677,0.055034,0.000000
72.010002,61.868942,-271.689636,0.012133,0.002163,0.054947,275.206787,14.019703,0.549472,-271.689636,0.055034,0.000000
72.210007,61.850693,-271.689636,0.012150,0.002163,0.054947,275.125610,14.015568,0.549472,-271.689636,0.055034,0.000000
72.410004,61.842133,-271.734131,0.012133,0.002163,0.054947,275.087555,14.013627,0.549472,-271.734131,0.055034,0.000000
72.610001,61.819412,-271.689636,0.012128,0.002163,0.054947,274.986481,14.008479,0.549472,-271.689636,0.055034,0.000000
72.810005,61.817551,-271.734131,0.012154,0.002163,0.054947,274.978210,14.008057,0.549472,-271.734131,0.055034,0.000000
73.010002,61.800049,-271.734131,0.012137,0.002163,0.054947,274.900360,14.004091,0.549472,-271.734131,0.055034,0.000000
73.210007,61.799683,-271.778625,0.012141,0.002163,0.054947,274.898712,14.004008,0.549472,-271.778625,0.055034,0.000000
73.410004,61.775101,-271.823090,0.012141,0.002163,0.054947,274.789368,13.998438,0.549472,-271.823090,0.055034,0.000000
73.610001,61.766167,-271.823090,0.012141,0.002163,0.054947,274.749634,13.996413,0.549472,-271.823090,0.055034,0.000000
73.810005,61.748291,-271.823090,0.012137,0.002163,0.054947,274.670105,13.992363,0.549472,-271.823090,0.055034,0.000000
74.010002,61.755737,-271.867584,0.012133,0.002163,0.054947,274.703247,13.994050,0.549472,-271.867584,0.055034,0.000000
74.210007,61.741592,-271.867584,0.012133,0.002163,0.054947,274.640320,13.990845,0.549472,-271.867584,0.055034,0.000000
74.410004,61.727440,-271.823090,0.012124,0.002163,0.054947,274.577362,13.987638,0.549472,-271.823090,0.055034,0.000000
74.610001,61.712914,-271.823090,0.012146,0.002163,0.054947,274.512756,13.984345,0.549472,-271.823090,0.055034,0.000000
74.810005,61.703606,-271.912048,0.012141,0.002163,0.054947,274.471344,13.982237,0.549472,-271.912048,0.055034,0.000000
75.010002,61.687599,-271.912048,0.012137,0.002163,0.054947,274.400146,13.978610,0.549472,-271.912048,0.055034,0.000000
75.210007,61.668236,-271.912048,0.012154,0.002163,0.054947,274.314026,13.974222,0.549472,-271.912048,0.055034,0.000000
75.410004,61.678658,-272.001007,0.012150,0.002163,0.054947,274.360382,13.976583,0.549472,-272.001007,0.055034,0.000000
75.610001,61.658180,-271.956543,0.012133,0.002163,0.054947,274.269287,13.971944,0.549472,-271.956543,0.055034,0.000000
75.810005,61.637329,-272.001007,0.012137,0.002163,0.054947,274.176544,13.967218,0.549472,-272.001007,0.055034,0.000000
76.010002,61.625786,-272.045502,0.012146,0.002163,0.054947,274.125183,13.964602,0.549472,-272.045502,0.055034,0.000000
76.210007,61.622429,-272.045502,0.012128,0.002163,0.054947,274.110260,13.963842,0.549472,-272.045502,0.055034,0.000000
76.410004,61.614609,-272.045502,0.012137,0.002163,0.054947,274.075470,13.962070,0.549472,-272.045502,0.055034,0.000000
76.610001,61.605675,-272.134460,0.012128,0.002163,0.054947,274.035736,13.960046,0.549472,-272.134460,0.055034,0.000000
76.810005,61.598228,-272.089966,0.012146,0.002163,0.054947,274.002594,13.958358,0.549472,-272.089966,0.055034,0.000000
77.010002,61.594505,-272.045502,0.012146,0.002163,0.054947,273.986053,13.957515,0.549472,-272.045502,0.055034,0.000000
77.210007,61.593384,-272.134460,0.012124,0.002163,0.054947,273.981049,13.957260,0.549472,-272.134460,0.055034,0.000000
77.410004,61.582214,-272.134460,0.012137,0.002163,0.054947,273.931366,13.954729,0.549472,-272.134460,0.055034,0.000000
77.610001,61.572533,-272.134460,0.012133,0.002163,0.054947,273.888306,13.952535,0.549472,-272.134460,0.055034,0.000000
77.810005,61.556145,-272.134460,0.012141,0.002163,0.054947,273.815399,13.948822,0.549472,-272.134460,0.055034,0.000000
78.010002,61.535667,-272.134460,0.012137,0.002163,0.054947,273.724335,13.944182,0.549472,-272.134460,0.055034,0.000000
78.210007,61.537155,-272.223419,0.012141,0.002163,0.054947,273.730927,13.944519,0.549472,-272.223419,0.055034,0.000000
78.410004,61.512955,-272.223419,0.012120,0.002163,0.054947,273.623291,13.939034,0.549472,-272.223419,0.055034,0.000000
78.610001,61.506996,-272.267914,0.012133,0.002163,0.054947,273.596771,13.937684,0.549472,-272.267914,0.055034,0.000000
78.810005,61.506622,-272.267914,0.012141,0.002163,0.054947,273.595123,13.937600,0.549472,-272.267914,0.055034,0.000000
79.010002,61.501785,-272.356873,0.012120,0.002163,0.054947,273.573608,13.936503,0.549472,-272.356873,0.055034,0.000000
79.210007,61.486511,-272.356873,0.012141,0.002163,0.054947,273.505676,13.933043,0.549472,-272.356873,0.055034,0.000000
79.410004,61.473854,-272.312378,0.012133,0.002163,0.054947,273.449371,13.930175,0.549472,-272.312378,0.055034,0.000000
79.610001,61.476463,-272.312378,0.012133,0.002163,0.054947,273.460968,13.930766,0.549472,-272.312378,0.055034,0.000000
79.810005,61.456352,-272.356873,0.012141,0.002163,0.054947,273.371521,13.926208,0.549472,-272.356873,0.055034,0.000000
80.010002,61.451515,-272.356873,0.012141,0.002163,0.054947,273.350006,13.925113,0.549472,-272.356873,0.055034,0.000000
80.210007,61.438850,-272.356873,0.012158,0.002163,0.054947,273.293671,13.922242,0.549472,-272.356873,0.055034,0.000000
80.410004,61.429543,-272.356873,0.012137,0.002163,0.054947,273.252258,13.920134,0.549472,-272.356873,0.055034,0.000000
80.610001,61.412041,-272.401337,0.012137,0.002163,0.054947,273.174408,13.916168,0.549472,-272.401337,0.055034,0.000000
80.810005,61.415764,-272.445831,0.012141,0.002163,0.054947,273.190948,13.917011,0.549472,-272.445831,0.055034,0.000000
81.010002,61.407570,-272.445831,0.012133,0.002163,0.054947,273.154510,13.915154,0.549472,-272.445831,0.055034,0.000000
81.200005,61.405334,-272.534790,0.012128,0.002163,0.054947,273.144562,13.914648,0.549472,-272.534790,0.055034,0.000000