File: Data/AG AL compression 300N/AG membrane Peeled 300N_1_2_03192024_183508.csv
Time (sec),S:Load (lbs),S:HL1 (DIM),S:LVDT (in),S:Position (in),Ch:Position (mm),Ch:Load (N),Ch:Stress (MPa),Ch:Strain (mm/mm),Ch:HL1 (DIM),Set Point (),Cycles ()
0.110000,-0.026810,-314.613770,0.000013,-0.000000,-0.000000,-0.119255,-0.006075,-0.000000,-314.613770,0.000217,0.000000
0.280000,-0.001114,-314.569275,-0.000013,-0.000000,-0.000000,-0.004955,-0.000252,-0.000000,-314.569275,0.000217,0.000000
0.450000,-0.010429,-314.569275,-0.000004,0.000057,0.001440,-0.046392,-0.002363,0.014398,-314.569275,0.002003,0.000000
0.620000,0.009308,-314.569275,0.000000,0.000151,0.003825,0.041403,0.002109,0.038246,-314.569275,0.004831,0.000000
0.790000,0.018616,-314.702728,0.000086,0.000254,0.006461,0.082807,0.004218,0.064608,-314.702728,0.007658,0.000000
0.960000,0.016754,-314.658234,0.000190,0.000369,0.009384,0.074526,0.003797,0.093835,-314.658234,0.010485,0.000000
1.130000,-0.014893,-314.658234,0.000306,0.000477,0.012124,-0.066245,-0.003375,0.121238,-314.658234,0.013329,0.000000
1.300000,-0.044685,-314.613770,0.000397,0.000589,0.014960,-0.198770,-0.010126,0.149598,-314.613770,0.016157,0.000000
1.470000,-0.060326,-314.658234,0.000517,0.000704,0.017891,-0.268342,-0.013670,0.178908,-314.658234,0.018984,0.000000
1.640000,-0.014153,-314.658234,0.000629,0.000821,0.020865,-0.062954,-0.003207,0.208654,-314.658234,0.021828,0.000000
1.810000,0.026070,-314.658234,0.000724,0.000934,0.023719,0.115964,0.005907,0.237188,-314.658234,0.024655,0.000000
1.980000,0.024574,-314.702728,0.000828,0.001041,0.026442,0.109312,0.005569,0.264417,-314.702728,0.027483,0.000000
2.150000,0.043571,-314.658234,0.000944,0.001151,0.029234,0.193816,0.009873,0.292342,-314.658234,0.030310,0.000000
2.320000,0.018990,-314.747223,0.001069,0.001265,0.032122,0.084470,0.004303,0.321220,-314.747223,0.033154,0.000000
2.490000,0.021225,-314.747223,0.001164,0.001374,0.034906,0.094413,0.004810,0.349058,-314.747223,0.035981,0.000000
2.660000,0.013405,-314.791687,0.001281,0.001479,0.037577,0.059628,0.003038,0.375768,-314.791687,0.038808,0.000000
2.830000,0.001862,-314.747223,0.001397,0.001595,0.040508,0.008281,0.000422,0.405082,-314.747223,0.041653,0.000000
3.000000,0.000748,-314.791687,0.001500,0.001711,0.043448,0.003326,0.000169,0.434479,-314.791687,0.044480,0.000000
3.170000,0.010429,-314.791687,0.001625,0.001824,0.046319,0.046392,0.002363,0.463188,-314.791687,0.047307,0.000000
3.340000,0.008568,-314.791687,0.001716,0.001930,0.049033,0.038112,0.001941,0.490329,-314.791687,0.050134,0.000000
3.510000,0.035004,-314.836182,0.001824,0.002040,0.051817,0.155704,0.007932,0.518167,-314.836182,0.052979,0.000000
3.680000,0.004471,-314.880646,0.001949,0.002150,0.054601,0.019887,0.001013,0.546005,-314.880646,0.055806,0.000000
3.850000,0.023460,-314.836182,0.002070,0.002266,0.057558,0.104357,0.005316,0.575580,-314.836182,0.058633,0.000000
4.020000,0.027184,-314.836182,0.002160,0.002376,0.060359,0.120918,0.006160,0.603589,-314.836182,0.061478,0.000000
4.190000,0.005959,-314.880646,0.002259,0.002488,0.063204,0.026505,0.001350,0.632036,-314.880646,0.064305,0.000000
4.360000,0.001862,-314.925140,0.002384,0.002602,0.066100,0.008281,0.000422,0.661002,-314.925140,0.067132,0.000000
4.530000,0.062935,-314.969604,0.002518,0.002715,0.068971,0.279948,0.014261,0.689706,-314.969604,0.069959,0.000000
4.700000,0.051018,-314.925140,0.002608,0.002825,0.071746,0.226938,0.011561,0.717457,-314.925140,0.072804,0.000000
4.870000,0.063675,-314.880646,0.002725,0.002930,0.074425,0.283240,0.014429,0.744254,-314.880646,0.075631,0.000000
5.040000,0.036118,-314.925140,0.002854,0.003045,0.077348,0.160659,0.008184,0.773481,-314.925140,0.078458,0.000000
5.210000,0.041336,-315.058563,0.002962,0.003159,0.080227,0.183872,0.009367,0.802273,-315.058563,0.081303,0.000000
5.380000,0.018990,-315.014099,0.003083,0.003262,0.082846,0.084470,0.004303,0.828461,-315.014099,0.084130,0.000000
5.550000,0.015266,-315.014099,0.003191,0.003378,0.085804,0.067908,0.003459,0.858036,-315.014099,0.086957,0.000000
5.720000,0.020477,-314.925140,0.003311,0.003493,0.088735,0.091088,0.004640,0.887346,-314.925140,0.089784,0.000000
5.890000,0.101288,-315.014099,0.003423,0.003610,0.091700,0.450551,0.022952,0.917004,-315.014099,0.092628,0.000000
6.060000,0.165703,-315.014099,0.003535,0.003719,0.094467,0.737083,0.037549,0.944668,-315.014099,0.095456,0.000000
6.230000,0.236458,-315.058563,0.003643,0.003826,0.097173,1.051817,0.053582,0.971726,-315.058563,0.098283,0.000000
6.400000,0.307579,-315.058563,0.003773,0.003938,0.100026,1.368180,0.069698,1.000261,-315.058563,0.101127,0.000000
6.570000,0.414825,-315.014099,0.003872,0.004053,0.102940,1.845236,0.094001,1.029397,-315.014099,0.103954,0.000000
6.740000,0.569359,-315.014099,0.003997,0.004163,0.105732,2.532634,0.129019,1.057322,-315.014099,0.106782,0.000000
6.910000,0.604362,-315.103058,0.004061,-0.000000,-0.000000,2.688339,0.136950,-0.000000,-315.103058,0.000113,0.000000
7.080000,0.575691,-315.147552,0.004057,-0.000000,-0.000009,2.560802,0.130453,-0.000087,-315.147552,0.000113,0.000000
7.250000,0.549622,-315.103058,0.004083,-0.000000,-0.000009,2.444839,0.124546,-0.000087,-315.103058,0.000113,0.000000
7.420001,0.544411,-315.058563,0.004070,-0.000001,-0.000017,2.421660,0.123365,-0.000174,-315.058563,0.000165,0.000000
7.590000,0.558189,-315.103058,0.004083,-0.000000,-0.000009,2.482950,0.126488,-0.000087,-315.103058,0.000442,0.000000
7.760000,0.545525,-315.147552,0.004079,-0.000000,-0.000009,2.426615,0.123618,-0.000087,-315.147552,0.000729,0.000000
7.930000,0.553719,-315.236511,0.004061,-0.000000,-0.000000,2.463063,0.125474,-0.000000,-315.236511,0.001015,0.000000
8.100000,0.612183,-315.147552,0.004074,0.000018,0.000468,2.723124,0.138723,0.004682,-315.147552,0.001292,0.000000
8.270000,0.727989,-315.192017,0.004061,0.000029,0.000746,3.238258,0.164965,0.007456,-315.192017,0.001578,0.000000
8.440001,0.733948,-315.147552,0.004096,0.000039,0.000980,3.264763,0.166315,0.009799,-315.147552,0.001864,0.000000
8.610001,0.768578,-315.192017,0.004087,0.000048,0.001223,3.418804,0.174162,0.012229,-315.192017,0.002142,0.000000
8.780001,0.760757,-315.280975,0.004092,0.000056,0.001422,3.384018,0.172390,0.014224,-315.280975,0.002428,0.000000
8.950001,0.823685,-315.280975,0.004126,0.000074,0.001873,3.663933,0.186650,0.018731,-315.280975,0.002715,0.000000
9.120001,0.862045,-315.236511,0.004126,0.000086,0.002177,3.834569,0.195342,0.021767,-315.236511,0.002992,0.000000
9.290001,0.860550,-315.236511,0.004130,0.000094,0.002376,3.827917,0.195003,0.023762,-315.236511,0.003278,0.000000
9.460000,0.905983,-315.280975,0.004130,0.000103,0.002619,4.030014,0.205299,0.026191,-315.280975,0.003564,0.000000
9.630000,0.945457,-315.325470,0.004161,0.000114,0.002905,4.205605,0.214244,0.029053,-315.325470,0.003842,0.000000
9.800000,0.961090,-315.325470,0.004169,0.000130,0.003304,4.275142,0.217786,0.033042,-315.325470,0.004128,0.000000
9.970000,1.007271,-315.369934,0.004174,0.000140,0.003564,4.480564,0.228251,0.035642,-315.369934,0.004414,0.000000
10.140000,1.047859,-315.325470,0.004191,0.000151,0.003824,4.661110,0.237448,0.038243,-315.325470,0.004692,0.000000
10.310000,1.044502,-315.369934,0.004204,0.000160,0.004059,4.646178,0.236688,0.040585,-315.369934,0.004978,0.000000
10.480000,1.075043,-315.458893,0.004204,0.000171,0.004353,4.782029,0.243608,0.043534,-315.458893,0.005264,0.000000
10.650001,1.103714,-315.414429,0.004225,0.000181,0.004605,4.909565,0.250105,0.046051,-315.414429,0.005541,0.000000
10.820001,1.174835,-315.369934,0.004243,0.000192,0.004874,5.225928,0.266221,0.048738,-315.369934,0.005828,0.000000
10.990001,1.237022,-315.369934,0.004255,0.000206,0.005221,5.502551,0.280313,0.052205,-315.369934,0.006114,0.000000
11.160001,1.269417,-315.414429,0.004243,0.000217,0.005524,5.646648,0.287654,0.055241,-315.414429,0.006392,0.000000
11.330001,1.284683,-315.414429,0.004268,0.000224,0.005680,5.714556,0.291113,0.056804,-315.414429,0.006678,0.000000
11.500001,1.355812,-315.414429,0.004247,0.000234,0.005940,6.030953,0.307231,0.059404,-315.414429,0.006964,0.000000
11.670001,1.444061,-315.414429,0.004290,0.000253,0.006435,6.423505,0.327229,0.064347,-315.414429,0.007241,0.000000
11.840000,1.479065,-315.414429,0.004290,0.000264,0.006695,6.579209,0.335161,0.066951,-315.414429,0.007527,0.000000
12.010000,1.541252,-315.369934,0.004312,0.000276,0.007016,6.855832,0.349253,0.070157,-315.369934,0.007814,0.000000
12.180000,1.568436,-315.547852,0.004299,0.000285,0.007241,6.976750,0.355413,0.072413,-315.547852,0.008091,0.000000
12.350000,1.613121,-315.503387,0.004324,0.000294,0.007476,7.175521,0.365538,0.074755,-315.503387,0.008377,0.000000
12.520000,1.691689,-315.503387,0.004329,0.000304,0.007718,7.525006,0.383342,0.077182,-315.503387,0.008664,0.000000
12.690001,1.789619,-315.458893,0.004342,0.000317,0.008048,7.960625,0.405534,0.080478,-315.458893,0.008941,0.000000
12.860001,1.861862,-315.547852,0.004346,0.000328,0.008334,8.281977,0.421904,0.083340,-315.547852,0.009227,0.000000
13.030001,1.922935,-315.547852,0.004359,0.000339,0.008620,8.553644,0.435743,0.086201,-315.547852,0.009513,0.000000
13.200001,1.960167,-315.636841,0.004359,0.000346,0.008785,8.719258,0.444180,0.087851,-315.636841,0.009791,0.000000
13.370001,2.082680,-315.592346,0.004381,0.000359,0.009123,9.264222,0.471942,0.091231,-315.592346,0.010077,0.000000
13.540001,2.203697,-315.592346,0.004385,0.000375,0.009513,9.802535,0.499365,0.095133,-315.592346,0.010363,0.000000
13.710001,2.292694,-315.592346,0.004419,0.000388,0.009860,10.198413,0.519532,0.098604,-315.592346,0.010641,0.000000
13.880001,2.355629,-315.547852,0.004406,0.000399,0.010129,10.478361,0.533793,0.101291,-315.547852,0.010927,0.000000
14.050000,2.423775,-315.636841,0.004424,0.000408,0.010355,10.781488,0.549235,0.103547,-315.636841,0.011213,0.000000
14.220000,2.464363,-315.636841,0.004437,0.000417,0.010589,10.962034,0.558433,0.105886,-315.636841,0.011491,0.000000
14.390000,2.568253,-315.636841,0.004445,0.000426,0.010823,11.424158,0.581974,0.108229,-315.636841,0.011777,0.000000
14.560000,2.663956,-315.636841,0.004441,0.000434,0.011022,11.849867,0.603661,0.110224,-315.636841,0.012063,0.000000
14.730000,2.740662,-315.681305,0.004445,0.000445,0.011300,12.191072,0.621043,0.112998,-315.681305,0.012341,0.000000
14.900001,2.990524,-315.681305,0.004471,0.000460,0.011673,13.302516,0.677662,0.116730,-315.681305,0.012627,0.000000
15.070001,3.137985,-315.725800,0.004488,0.000474,0.012046,13.958455,0.711078,0.120458,-315.725800,0.012913,0.000000
15.240001,3.100746,-315.725800,0.004493,0.000477,0.012106,13.792808,0.702639,0.121064,-315.725800,0.013199,0.000000
15.410001,3.372948,-315.725800,0.004510,0.000491,0.012470,15.003621,0.764321,0.124705,-315.725800,0.013476,0.000000
15.580001,3.546104,-315.770264,0.004510,0.000505,0.012835,15.773860,0.803559,0.128350,-315.770264,0.013763,0.000000
15.750001,3.746437,-315.770264,0.004518,0.000521,0.013243,16.664984,0.848955,0.132426,-315.770264,0.014049,0.000000
15.920001,3.871933,-315.814758,0.004549,0.000531,0.013494,17.223219,0.877393,0.134939,-315.814758,0.014327,0.000000
16.090000,3.955711,-315.770264,0.004553,0.000539,0.013685,17.595882,0.896377,0.136847,-315.770264,0.014613,0.000000
16.260000,4.186584,-315.770264,0.004557,0.000551,0.014006,18.622858,0.948694,0.140056,-315.770264,0.014899,0.000000
16.430000,4.253983,-315.814758,0.004562,0.000560,0.014214,18.922659,0.963966,0.142138,-315.814758,0.015176,0.000000
16.600000,4.434586,-315.814758,0.004549,0.000567,0.014413,19.726023,1.004892,0.144133,-315.814758,0.015462,0.000000
16.770000,4.839722,-315.859222,0.004570,0.000584,0.014838,21.528156,1.096697,0.148383,-315.859222,0.015749,0.000000
16.940001,5.027771,-315.859222,0.004596,0.000596,0.015133,22.364643,1.139309,0.151331,-315.859222,0.016026,0.000000
17.110001,5.121613,-315.770264,0.004596,0.000604,0.015333,22.782070,1.160574,0.153326,-315.770264,0.016313,0.000000
17.280001,5.257156,-315.814758,0.004600,0.000613,0.015575,23.385000,1.191289,0.155752,-315.814758,0.016599,0.000000
17.450001,5.742729,-315.903717,0.004596,0.000632,0.016044,25.544935,1.301321,0.160438,-315.903717,0.016876,0.000000
17.620001,6.041374,-315.859222,0.004622,0.000646,0.016417,26.873375,1.368995,0.164166,-315.859222,0.017162,0.000000
17.790001,6.222343,-315.992676,0.004644,0.000657,0.016685,27.678366,1.410003,0.166853,-315.992676,0.017448,0.000000
17.960001,6.413368,-315.903717,0.004648,0.000666,0.016911,28.528086,1.453290,0.169109,-315.903717,0.017726,0.000000
18.130001,6.548172,-315.948181,0.004648,0.000675,0.017154,29.127724,1.483837,0.171535,-315.948181,0.018012,0.000000
18.300001,6.822609,-315.948181,0.004665,0.000686,0.017414,30.348480,1.546025,0.174139,-315.948181,0.018298,0.000000
18.470001,7.095932,-315.992676,0.004665,0.000696,0.017683,31.564281,1.607961,0.176827,-315.992676,0.018576,0.000000
18.640001,7.273552,-315.992676,0.004682,0.000702,0.017839,32.354374,1.648210,0.178390,-315.992676,0.018862,0.000000
18.810001,7.591187,-315.992676,0.004682,0.000715,0.018151,33.767284,1.720187,0.181508,-315.992676,0.019148,0.000000
18.980001,7.836952,-315.992676,0.004691,0.000723,0.018359,34.860504,1.775879,0.183590,-315.992676,0.019426,0.000000
19.150002,8.268532,-316.037170,0.004708,0.000736,0.018689,36.780266,1.873676,0.186887,-316.037170,0.019712,0.000000
19.320002,8.452484,-316.037170,0.004717,0.000745,0.018914,37.598526,1.915360,0.189143,-316.037170,0.019998,0.000000
19.490002,9.058334,-316.037170,0.004725,0.000765,0.019443,40.293484,2.052648,0.194430,-316.037170,0.020276,0.000000
19.660002,9.456398,-315.992676,0.004747,0.000781,0.019825,42.064159,2.142850,0.198249,-315.992676,0.020562,0.000000
19.830002,9.636253,-316.037170,0.004738,0.000790,0.020076,42.864197,2.183606,0.200762,-316.037170,0.020848,0.000000
20.000000,9.825790,-316.037170,0.004751,0.000799,0.020302,43.707298,2.226556,0.203018,-316.037170,0.021125,0.000000
20.170000,10.095764,-316.126129,0.004747,0.000809,0.020553,44.908203,2.287733,0.205531,-316.126129,0.021412,0.000000
20.340000,10.376534,-316.126129,0.004786,0.000819,0.020814,46.157127,2.351356,0.208135,-316.126129,0.021698,0.000000
20.510000,10.764542,-316.081635,0.004781,0.000829,0.021047,47.883072,2.439280,0.210474,-316.081635,0.021975,0.000000
20.680000,11.103401,-316.126129,0.004790,0.000841,0.021368,49.390396,2.516067,0.213684,-316.126129,0.022262,0.000000
20.850000,11.530518,-316.126129,0.004794,0.000853,0.021672,51.290302,2.612853,0.216719,-316.126129,0.022548,0.000000
21.020000,11.742393,-316.170593,0.004794,0.000862,0.021898,52.232777,2.660864,0.218975,-316.170593,0.022825,0.000000
21.190001,12.023537,-316.215088,0.004816,0.000871,0.022123,53.483364,2.724572,0.221227,-316.215088,0.023112,0.000000
21.360001,12.725456,-316.215088,0.004820,0.000889,0.022591,56.605656,2.883630,0.225913,-316.215088,0.023398,0.000000
21.530001,13.046440,-316.259552,0.004833,0.000902,0.022904,58.033463,2.956366,0.229035,-316.259552,0.023675,0.000000
21.700001,13.153687,-316.215088,0.004838,0.000910,0.023112,58.510521,2.980668,0.231117,-316.215088,0.023961,0.000000
21.870001,13.557335,-316.259552,0.004842,0.000923,0.023441,60.306038,3.072136,0.234410,-316.259552,0.024248,0.000000
22.040001,13.750229,-316.304047,0.004859,0.000931,0.023640,61.164074,3.115846,0.236405,-316.304047,0.024525,0.000000
22.210001,13.950562,-316.304047,0.004876,0.000941,0.023892,62.055199,3.161242,0.238921,-316.304047,0.024811,0.000000
22.380001,14.487526,-316.215088,0.004868,0.000954,0.024239,64.443733,3.282920,0.242388,-316.215088,0.025098,0.000000
22.550001,14.959320,-316.259552,0.004876,0.000967,0.024569,66.542381,3.389830,0.245685,-316.259552,0.025375,0.000000
22.720001,15.307861,-316.304047,0.004881,0.000980,0.024881,68.092766,3.468811,0.248808,-316.304047,0.025661,0.000000
22.890001,15.545807,-316.304047,0.004894,0.000987,0.025080,69.151199,3.522730,0.250802,-316.304047,0.025947,0.000000
23.060001,15.760292,-316.304047,0.004915,0.000996,0.025288,70.105278,3.571333,0.252884,-316.304047,0.026225,0.000000
23.230001,16.271561,-316.348511,0.004907,0.001011,0.025679,72.379517,3.687188,0.256786,-316.348511,0.026511,0.000000
23.400002,16.612656,-316.304047,0.004915,0.001021,0.025939,73.896782,3.764482,0.259386,-316.304047,0.026797,0.000000
23.570002,16.926933,-316.393005,0.004924,0.001033,0.026251,75.294762,3.835698,0.262509,-316.393005,0.027084,0.000000
23.740002,17.247917,-316.393005,0.004941,0.001045,0.026546,76.722565,3.908434,0.265457,-316.393005,0.027361,0.000000
23.910002,17.586411,-316.393005,0.004963,0.001056,0.026814,78.228264,3.985137,0.268145,-316.393005,0.027647,0.000000
24.080002,17.685829,-316.348511,0.004963,0.001065,0.027040,78.670494,4.007666,0.270400,-316.348511,0.027933,0.000000
24.250002,18.108101,-316.437500,0.004967,0.001075,0.027317,80.548859,4.103354,0.273175,-316.437500,0.028211,0.000000
24.420002,18.668152,-316.437500,0.004980,0.001091,0.027699,83.040085,4.230264,0.276990,-316.437500,0.028497,0.000000
24.590002,18.757515,-316.481964,0.004967,0.001097,0.027855,83.437592,4.250514,0.278553,-316.481964,0.028783,0.000000
24.760000,19.200272,-316.481964,0.005006,0.001110,0.028202,85.407074,4.350843,0.282020,-316.481964,0.029061,0.000000
24.930000,19.247185,-316.481964,0.005014,0.001115,0.028315,85.615753,4.361475,0.283148,-316.481964,0.029347,0.000000
25.100000,20.029167,-316.393005,0.005019,0.001135,0.028827,89.094185,4.538674,0.288265,-316.393005,0.029633,0.000000
25.270000,20.411972,-316.481964,0.005010,0.001146,0.029113,90.796989,4.625419,0.291127,-316.481964,0.029911,0.000000
25.440001,20.655128,-316.526459,0.005019,0.001158,0.029407,91.878601,4.680519,0.294075,-316.526459,0.030197,0.000000
25.610001,21.000687,-316.526459,0.005032,0.001170,0.029711,93.415718,4.758823,0.297110,-316.526459,0.030483,0.000000
25.780001,21.004784,-316.526459,0.005049,0.001178,0.029919,93.433945,4.759752,0.299192,-316.526459,0.030761,0.000000
25.950001,21.160812,-316.526459,0.005062,0.001186,0.030119,94.127998,4.795108,0.301187,-316.526459,0.031047,0.000000
26.120001,21.782303,-316.526459,0.005062,0.001200,0.030474,96.892525,4.935941,0.304741,-316.526459,0.031333,0.000000
26.290001,22.181480,-316.615417,0.005070,0.001212,0.030786,98.668152,5.026395,0.307863,-316.615417,0.031610,0.000000
26.460001,22.590721,-316.570923,0.005083,0.001224,0.031081,100.488548,5.119131,0.310812,-316.570923,0.031896,0.000000
26.630001,22.712486,-316.526459,0.005096,0.001233,0.031315,101.030182,5.146723,0.313155,-316.526459,0.032183,0.000000
26.800001,22.938515,-316.615417,0.005101,0.001241,0.031515,102.035606,5.197942,0.315149,-316.615417,0.032460,0.000000
26.970001,23.190239,-316.615417,0.005101,0.001252,0.031801,103.155334,5.254983,0.318011,-316.615417,0.032747,0.000000
27.140001,24.011696,-316.659882,0.005113,0.001269,0.032226,106.809357,5.441128,0.322261,-316.659882,0.033033,0.000000
27.310001,24.230278,-316.704376,0.005126,0.001280,0.032504,107.781662,5.490660,0.325035,-316.704376,0.033310,0.000000
27.480001,24.433968,-316.704376,0.005135,0.001290,0.032755,108.687714,5.536816,0.327552,-316.704376,0.033596,0.000000
27.650002,24.563179,-316.570923,0.005157,0.001297,0.032955,109.262474,5.566096,0.329547,-316.570923,0.033882,0.000000
27.820002,24.896454,-316.615417,0.005144,0.001309,0.033241,110.744957,5.641617,0.332408,-316.615417,0.034160,0.000000
27.990002,25.423355,-316.659882,0.005152,0.001323,0.033614,113.088730,5.761014,0.336137,-316.659882,0.034446,0.000000
28.160002,25.650131,-316.748840,0.005178,0.001331,0.033796,114.097481,5.812403,0.337957,-316.748840,0.034732,0.000000
28.330002,25.941704,-316.704376,0.005187,0.001342,0.034091,115.394463,5.878474,0.340905,-316.704376,0.035010,0.000000
28.500002,26.404190,-316.659882,0.005182,0.001355,0.034412,117.451706,5.983275,0.344115,-316.659882,0.035296,0.000000
28.670002,26.782890,-316.704376,0.005195,0.001367,0.034724,119.136246,6.069090,0.347238,-316.704376,0.035582,0.000000
28.840002,26.754219,-316.748840,0.005208,0.001374,0.034897,119.008713,6.062593,0.348971,-316.748840,0.035860,0.000000
29.010002,27.133293,-316.793335,0.005208,0.001385,0.035175,120.694916,6.148492,0.351745,-316.793335,0.036146,0.000000
29.180002,27.595032,-316.748840,0.005226,0.001397,0.035487,122.748833,6.253123,0.354868,-316.748840,0.036432,0.000000
29.350002,28.276100,-316.748840,0.005230,0.001412,0.035860,125.778374,6.407456,0.358596,-316.748840,0.036710,0.000000
29.520000,28.347969,-316.837830,0.005247,0.001420,0.036059,126.098061,6.423742,0.360591,-316.837830,0.036996,0.000000
29.690001,28.646240,-316.748840,0.005251,0.001430,0.036311,127.424843,6.491331,0.363108,-316.748840,0.037282,0.000000
29.860001,28.971695,-316.837830,0.005264,0.001442,0.036623,128.872528,6.565080,0.366230,-316.837830,0.037559,0.000000
30.030001,29.215973,-316.837830,0.005260,0.001451,0.036848,129.959137,6.620434,0.368482,-316.837830,0.037846,0.000000
30.200001,29.780487,-316.837830,0.005277,0.001466,0.037230,132.470230,6.748355,0.372301,-316.837830,0.038132,0.000000
30.370001,30.188606,-316.882294,0.005260,0.001475,0.037455,134.285629,6.840836,0.374553,-316.882294,0.038409,0.000000
30.540001,30.732269,-316.926788,0.005286,0.001490,0.037846,136.703964,6.964032,0.378455,-316.926788,0.038696,0.000000
30.710001,30.827225,-316.882294,0.005290,0.001496,0.038002,137.126343,6.985549,0.380019,-316.882294,0.038982,0.000000
30.880001,31.036125,-316.926788,0.005312,0.001505,0.038227,138.055573,7.032887,0.382274,-316.926788,0.039259,0.000000
31.050001,31.798744,-316.926788,0.005307,0.001522,0.038661,141.447876,7.205698,0.386608,-316.926788,0.039545,0.000000
31.220001,32.224365,-316.837830,0.005307,0.001532,0.038913,143.341141,7.302145,0.389125,-316.837830,0.039831,0.000000
31.390001,32.715530,-317.015747,0.005325,0.001545,0.039250,145.525940,7.413445,0.392505,-317.015747,0.040109,0.000000
31.560001,32.883842,-316.926788,0.005316,0.001554,0.039476,146.274643,7.451585,0.394761,-316.926788,0.040395,0.000000
31.730001,33.242805,-317.015747,0.005342,0.001565,0.039754,147.871384,7.532928,0.397535,-317.015747,0.040682,0.000000
31.900002,33.485596,-316.971252,0.005368,0.001573,0.039962,148.951370,7.587945,0.399617,-316.971252,0.040968,0.000000
32.070000,33.777161,-316.926788,0.005359,0.001583,0.040213,150.248322,7.654014,0.402134,-316.926788,0.041245,0.000000
32.240002,34.571060,-317.015747,0.005372,0.001599,0.040604,153.779755,7.833914,0.406036,-317.015747,0.041531,0.000000
32.410000,35.282288,-316.971252,0.005364,0.001612,0.040942,156.943451,7.995080,0.409416,-316.971252,0.041817,0.000000
32.580002,35.446136,-317.060211,0.005364,0.001619,0.041132,157.672287,8.032209,0.411323,-317.060211,0.042095,0.000000
32.750000,35.335541,-317.060211,0.005372,0.001622,0.041211,157.180328,8.007148,0.412107,-317.060211,0.042381,0.000000
32.920002,36.604584,-317.015747,0.005389,0.001645,0.041792,162.825317,8.294718,0.417917,-317.015747,0.042667,0.000000
33.090000,37.015312,-317.015747,0.005407,0.001655,0.042034,164.652328,8.387790,0.420343,-317.015747,0.042945,0.000000
33.260002,37.438332,-317.104706,0.005407,0.001668,0.042373,166.534012,8.483647,0.423727,-317.104706,0.043231,0.000000
33.430000,38.015129,-317.060211,0.005424,0.001679,0.042650,169.099747,8.614351,0.426501,-317.060211,0.043517,0.000000
33.600002,38.362930,-317.104706,0.005428,0.001690,0.042919,170.646835,8.693165,0.429188,-317.104706,0.043795,0.000000
33.770000,38.486183,-317.149170,0.005428,0.001698,0.043136,171.195099,8.721093,0.431357,-317.149170,0.044081,0.000000
33.940002,38.758018,-317.149170,0.005428,0.001707,0.043361,172.404282,8.782692,0.433613,-317.149170,0.044367,0.000000
34.110001,39.496803,-317.149170,0.005445,0.001720,0.043700,175.690552,8.950104,0.436996,-317.149170,0.044645,0.000000
34.280003,40.235962,-317.149170,0.005441,0.001732,0.044003,178.978500,9.117599,0.440028,-317.149170,0.044931,0.000000
34.450001,40.532745,-317.149170,0.005458,0.001742,0.044246,180.298660,9.184852,0.442458,-317.149170,0.045217,0.000000
34.620003,40.769569,-317.149170,0.005454,0.001748,0.044393,181.352097,9.238517,0.443934,-317.149170,0.045494,0.000000
34.790001,41.784286,-317.238129,0.005467,0.001766,0.044853,185.865784,9.468454,0.448529,-317.238129,0.045781,0.000000
34.960003,42.626968,-317.149170,0.005463,0.001780,0.045217,189.614227,9.659409,0.452170,-317.149170,0.046067,0.000000
35.130001,43.157227,-317.238129,0.005471,0.001792,0.045521,191.972931,9.779568,0.455206,-317.238129,0.046345,0.000000
35.300003,43.537041,-317.238129,0.005489,0.001801,0.045755,193.662430,9.865634,0.457548,-317.238129,0.046631,0.000000
35.470001,43.845741,-317.193665,0.005497,0.001810,0.045963,195.035599,9.935587,0.459630,-317.193665,0.046917,0.000000
35.640003,44.157417,-317.238129,0.005510,0.001819,0.046206,196.421997,10.006213,0.462056,-317.238129,0.047194,0.000000
35.810001,44.653786,-317.238129,0.005501,0.001829,0.046466,198.629959,10.118692,0.464660,-317.238129,0.047480,0.000000
35.980003,44.810555,-317.238129,0.005506,0.001836,0.046639,199.327301,10.154217,0.466394,-317.238129,0.047767,0.000000
36.150002,45.976456,-317.327118,0.005510,0.001852,0.047047,204.513489,10.418413,0.470470,-317.327118,0.048044,0.000000
36.320004,46.704819,-317.282623,0.005532,0.001867,0.047420,207.753403,10.583464,0.474198,-317.282623,0.048330,0.000000
36.490002,47.315506,-317.282623,0.005523,0.001875,0.047619,210.469879,10.721847,0.476193,-317.282623,0.048617,0.000000
36.660000,47.526268,-317.282623,0.005527,0.001884,0.047862,211.407394,10.769607,0.478623,-317.282623,0.048894,0.000000
36.830002,48.094513,-317.371582,0.005553,0.001895,0.048131,213.935074,10.898373,0.481310,-317.371582,0.049180,0.000000
37.000000,49.154655,-317.416077,0.005553,0.001911,0.048547,218.650833,11.138604,0.485473,-317.416077,0.049467,0.000000
37.170002,50.088562,-317.371582,0.005553,0.001925,0.048885,222.805054,11.350231,0.488853,-317.371582,0.049744,0.000000
37.340000,50.589035,-317.371582,0.005553,0.001935,0.049137,225.031265,11.463639,0.491370,-317.371582,0.050030,0.000000
37.510002,50.594994,-317.371582,0.005570,0.001940,0.049276,225.057770,11.464989,0.492755,-317.371582,0.050316,0.000000
37.680000,51.577309,-317.460541,0.005566,0.001954,0.049631,229.427322,11.687586,0.496313,-317.460541,0.050594,0.000000
37.850002,51.737427,-317.505035,0.005575,0.001960,0.049787,230.139572,11.723868,0.497873,-317.505035,0.050880,0.000000
38.020000,52.495583,-317.460541,0.005596,0.001973,0.050117,233.512009,11.895669,0.501169,-317.460541,0.051166,0.000000
38.190002,53.431351,-317.371582,0.005601,0.001989,0.050516,237.674515,12.107718,0.505159,-317.371582,0.051444,0.000000
38.360001,54.365639,-317.416077,0.005601,0.002000,0.050793,241.830444,12.319430,0.507933,-317.416077,0.051730,0.000000
38.530003,54.520546,-317.505035,0.005605,0.002007,0.050967,242.519501,12.354533,0.509666,-317.505035,0.052016,0.000000
38.700001,55.184479,-317.505035,0.005601,0.002017,0.051227,245.472824,12.504981,0.512270,-317.505035,0.052294,0.000000
38.870003,56.843033,-317.505035,0.005618,0.002039,0.051799,252.850433,12.880816,0.517993,-317.505035,0.052580,0.000000
39.040001,57.693153,-317.505035,0.005635,0.002051,0.052103,256.631958,13.073455,0.521029,-317.505035,0.052866,0.000000
39.210003,58.194000,-317.505035,0.005639,0.002061,0.052337,258.859833,13.186949,0.523372,-317.505035,0.053144,0.000000
39.380001,58.358582,-317.549500,0.005631,0.002065,0.052458,259.591949,13.224244,0.524583,-317.549500,0.053430,0.000000
39.550003,59.023643,-317.593994,0.005644,0.002077,0.052753,262.550293,13.374949,0.527531,-317.593994,0.053716,0.000000
39.720001,59.635452,-317.638458,0.005648,0.002087,0.053005,265.271729,13.513586,0.530048,-317.638458,0.053993,0.000000
39.890003,60.373863,-317.549500,0.005657,0.002099,0.053308,268.556366,13.680913,0.533084,-317.549500,0.054280,0.000000
40.060001,60.929070,-317.549500,0.005648,0.002108,0.053543,271.026031,13.806725,0.535426,-317.549500,0.054566,0.000000
40.230003,61.833191,-317.593994,0.005657,0.002120,0.053837,275.047760,14.011600,0.538375,-317.593994,0.054852,0.000000
40.400002,62.345573,-317.593994,0.005665,0.002128,0.054054,277.326965,14.127708,0.540540,-317.593994,0.055130,0.000000
40.570004,63.075424,-317.682953,0.005674,0.002137,0.054288,280.573486,14.293096,0.542883,-317.682953,0.055416,0.000000
40.740002,63.737137,-317.593994,0.005678,0.002151,0.054635,283.516937,14.443042,0.546353,-317.593994,0.055702,0.000000
40.910004,65.252686,-317.682953,0.005678,0.002167,0.055043,290.258453,14.786469,0.550426,-317.682953,0.055979,0.000000
41.080002,66.481522,-317.638458,0.005687,0.002181,0.055390,295.724579,15.064928,0.553897,-317.638458,0.056265,0.000000
41.250004,67.155518,-317.727448,0.005696,0.002192,0.055676,298.722656,15.217658,0.556758,-317.727448,0.056552,0.000000
41.420002,67.283981,-317.727448,0.005687,0.002188,0.055572,299.294098,15.246768,0.555717,-317.727448,0.055771,0.000000
41.590000,66.894852,-317.682953,0.005717,0.002188,0.055563,297.563171,15.158590,0.555630,-317.682953,0.055771,0.000000
41.760002,66.553757,-317.682953,0.005704,0.002187,0.055554,296.045898,15.081297,0.555543,-317.682953,0.055563,0.000000
41.930000,66.280060,-317.727448,0.005700,0.002187,0.055546,294.828430,15.019277,0.555456,-317.727448,0.055563,0.000000
42.100002,66.038773,-317.727448,0.005704,0.002187,0.055546,293.755127,14.964600,0.555456,-317.727448,0.055563,0.000000
42.270000,65.831360,-317.771912,0.005708,0.002187,0.055546,292.832520,14.917599,0.555456,-317.771912,0.055563,0.000000
42.440002,65.651871,-317.771912,0.005717,0.002186,0.055537,292.034119,14.876926,0.555369,-317.771912,0.055563,0.000000
42.610001,65.484299,-317.771912,0.005734,0.002186,0.055537,291.288696,14.838954,0.555369,-317.771912,0.055563,0.000000
42.780003,65.334976,-317.771912,0.005713,0.002186,0.055537,290.624481,14.805117,0.555369,-317.771912,0.055563,0.000000
42.950001,65.196457,-317.860870,0.005704,0.002186,0.055537,290.008331,14.773728,0.555369,-317.860870,0.055563,0.000000
43.120003,65.073212,-317.860870,0.005721,0.002186,0.055537,289.460114,14.745800,0.555369,-317.860870,0.055563,0.000000
43.290001,64.962234,-317.860870,0.005717,0.002186,0.055537,288.966461,14.720654,0.555369,-317.860870,0.055563,0.000000
43.460003,64.854996,-317.860870,0.005726,0.002186,0.055537,288.489441,14.696352,0.555369,-317.860870,0.055563,0.000000
43.630001,64.771591,-317.816406,0.005717,0.002186,0.055537,288.118439,14.677452,0.555369,-317.816406,0.055563,0.000000
43.800003,64.670670,-317.816406,0.005713,0.002186,0.055537,287.669495,14.654583,0.555369,-317.816406,0.055563,0.000000
43.970001,64.585022,-317.949829,0.005721,0.002186,0.055537,287.288513,14.635176,0.555369,-317.949829,0.055563,0.000000
44.140003,64.506821,-317.949829,0.005717,0.002186,0.055537,286.940674,14.617455,0.555369,-317.949829,0.055563,0.000000
44.310001,64.436081,-317.905365,0.005726,0.002186,0.055537,286.626007,14.601424,0.555369,-317.905365,0.055563,0.000000
44.480003,64.367935,-317.860870,0.005726,0.002186,0.055537,286.322876,14.585983,0.555369,-317.860870,0.055563,0.000000
44.650002,64.291962,-317.949829,0.005708,0.002186,0.055537,285.984924,14.568767,0.555369,-317.949829,0.055563,0.000000
44.820004,64.239456,-317.994324,0.005721,0.002186,0.055537,285.751373,14.556869,0.555369,-317.994324,0.055563,0.000000
44.990002,64.169464,-318.083282,0.005730,0.002186,0.055537,285.440033,14.541008,0.555369,-318.083282,0.055563,0.000000
45.160004,64.117325,-317.994324,0.005717,0.002186,0.055537,285.208099,14.529194,0.555369,-317.994324,0.055563,0.000000
45.330002,64.051788,-317.994324,0.005717,0.002186,0.055529,284.916595,14.514342,0.555286,-317.994324,0.055563,0.000000
45.500004,64.011948,-317.994324,0.005717,0.002186,0.055529,284.739349,14.505315,0.555286,-317.994324,0.055563,0.000000
45.670002,63.954605,-318.038788,0.005708,0.002186,0.055529,284.484283,14.492321,0.555286,-318.038788,0.055563,0.000000
45.840004,63.916992,-318.083282,0.005730,0.002186,0.055529,284.316986,14.483797,0.555286,-318.083282,0.055563,0.000000
46.010002,63.868576,-317.994324,0.005726,0.002186,0.055529,284.101624,14.472826,0.555286,-317.994324,0.055563,0.000000
46.180000,63.825012,-317.994324,0.005721,0.002186,0.055529,283.907837,14.462955,0.555286,-317.994324,0.055563,0.000000
46.350002,63.765808,-318.038788,0.005734,0.002186,0.055529,283.644470,14.449539,0.555286,-318.038788,0.055563,0.000000
46.520000,63.733414,-318.127777,0.005717,0.002186,0.055529,283.500397,14.442198,0.555286,-318.127777,0.055563,0.000000
46.690002,63.692078,-318.127777,0.005726,0.002186,0.055529,283.316498,14.432831,0.555286,-318.127777,0.055563,0.000000
46.860001,63.650742,-318.083282,0.005739,0.002186,0.055529,283.132629,14.423464,0.555286,-318.083282,0.055563,0.000000
47.030003,63.610153,-318.127777,0.005734,0.002186,0.055529,282.952087,14.414267,0.555286,-318.127777,0.055563,0.000000
47.200001,63.584839,-318.038788,0.005721,0.002186,0.055529,282.839478,14.408531,0.555286,-318.038788,0.055563,0.000000
47.370003,63.526367,-318.127777,0.005717,0.002186,0.055529,282.579407,14.395280,0.555286,-318.127777,0.055563,0.000000
47.540001,63.509247,-318.172241,0.005739,0.002186,0.055529,282.503235,14.391400,0.555286,-318.172241,0.055563,0.000000
47.710003,63.463806,-318.172241,0.005730,0.002186,0.055529,282.301117,14.381104,0.555286,-318.172241,0.055563,0.000000
47.880001,63.445190,-318.127777,0.005730,0.002186,0.055529,282.218292,14.376885,0.555286,-318.127777,0.055563,0.000000
48.050003,63.404236,-318.216736,0.005739,0.002186,0.055529,282.036133,14.367605,0.555286,-318.216736,0.055563,0.000000
48.220001,63.374069,-318.172241,0.005717,0.002186,0.055529,281.901947,14.360769,0.555286,-318.172241,0.055563,0.000000
48.390003,63.340179,-318.261200,0.005713,0.002186,0.055529,281.751190,14.353090,0.555286,-318.261200,0.055563,0.000000
48.560001,63.302200,-318.305695,0.005734,0.002186,0.055529,281.582245,14.344483,0.555286,-318.305695,0.055563,0.000000
48.730003,63.286560,-318.261200,0.005739,0.002186,0.055529,281.512665,14.340940,0.555286,-318.261200,0.055563,0.000000
48.900002,63.255280,-318.216736,0.005713,0.002186,0.055529,281.373535,14.333851,0.555286,-318.216736,0.055563,0.000000
49.070004,63.224747,-318.261200,0.005726,0.002186,0.055529,281.237732,14.326932,0.555286,-318.261200,0.055563,0.000000
49.240002,63.196075,-318.350159,0.005721,0.002186,0.055529,281.110168,14.320436,0.555286,-318.350159,0.055563,0.000000
49.410004,63.172989,-318.350159,0.005730,0.002186,0.055529,281.007477,14.315204,0.555286,-318.350159,0.055563,0.000000
49.580002,63.152130,-318.261200,0.005730,0.002186,0.055529,280.914703,14.310477,0.555286,-318.261200,0.055563,0.000000
49.750004,63.120117,-318.350159,0.005726,0.002186,0.055529,280.772308,14.303223,0.555286,-318.350159,0.055563,0.000000
49.920002,63.094788,-318.305695,0.005721,0.002186,0.055529,280.659637,14.297482,0.555286,-318.305695,0.055563,0.000000
50.090004,63.075806,-318.439117,0.005730,0.002186,0.055529,280.575195,14.293182,0.555286,-318.439117,0.055563,0.000000
50.260002,63.055695,-318.439117,0.005734,0.002186,0.055529,280.485748,14.288625,0.555286,-318.439117,0.055563,0.000000
50.430004,63.028511,-318.394653,0.005734,0.002186,0.055529,280.364807,14.282464,0.555286,-318.394653,0.055563,0.000000
50.600002,63.008774,-318.350159,0.005734,0.002186,0.055529,280.277039,14.277992,0.555286,-318.350159,0.055563,0.000000
50.770004,62.993507,-318.305695,0.005726,0.002186,0.055529,280.209106,14.274532,0.555286,-318.305695,0.055563,0.000000
50.940002,62.959244,-318.439117,0.005721,0.002186,0.055529,280.056702,14.266768,0.555286,-318.439117,0.055563,0.000000
51.110001,62.942863,-318.439117,0.005730,0.002186,0.055529,279.983826,14.263057,0.555286,-318.439117,0.055563,0.000000
51.280003,62.915680,-318.439117,0.005747,0.002186,0.055529,279.862915,14.256897,0.555286,-318.439117,0.055563,0.000000
51.450001,62.901527,-318.439117,0.005726,0.002186,0.055529,279.799957,14.253690,0.555286,-318.439117,0.055563,0.000000
51.620003,62.868019,-318.439117,0.005730,0.002186,0.055529,279.650909,14.246098,0.555286,-318.439117,0.055563,0.000000
51.790001,62.878441,-318.483612,0.005721,0.002186,0.055529,279.697266,14.248459,0.555286,-318.483612,0.055563,0.000000
51.960003,62.838600,-318.528076,0.005721,0.002186,0.055529,279.520050,14.239430,0.555286,-318.528076,0.055563,0.000000
52.130001,62.821098,-318.483612,0.005721,0.002186,0.055529,279.442200,14.235465,0.555286,-318.483612,0.055563,0.000000
52.300003,62.793915,-318.483612,0.005730,0.002186,0.055529,279.321289,14.229305,0.555286,-318.483612,0.055563,0.000000
52.470001,62.790192,-318.483612,0.005730,0.002186,0.055529,279.304718,14.228460,0.555286,-318.483612,0.055563,0.000000
52.640003,62.767471,-318.528076,0.005734,0.002186,0.055529,279.203644,14.223312,0.555286,-318.528076,0.055563,0.000000
52.810001,62.759285,-318.572571,0.005730,0.002186,0.055529,279.167236,14.221457,0.555286,-318.572571,0.055563,0.000000
52.980003,62.726883,-318.572571,0.005726,0.002186,0.055529,279.023102,14.214115,0.555286,-318.572571,0.055563,0.000000
53.150002,62.729118,-318.572571,0.005726,0.002186,0.055529,279.033051,14.214622,0.555286,-318.572571,0.055563,0.000000
53.320004,62.690392,-318.528076,0.005739,0.002186,0.055529,278.860779,14.205846,0.555286,-318.528076,0.055563,0.000000
53.490002,62.686295,-318.617065,0.005734,0.002186,0.055529,278.842560,14.204918,0.555286,-318.617065,0.055563,0.000000
53.660004,62.670288,-318.661530,0.005726,0.002186,0.055529,278.771362,14.201291,0.555286,-318.661530,0.055563,0.000000
53.830002,62.651665,-318.661530,0.005734,0.002186,0.055529,278.688538,14.197070,0.555286,-318.661530,0.055563,0.000000
54.000004,62.640121,-318.661530,0.005743,0.002186,0.055529,278.637177,14.194455,0.555286,-318.661530,0.055563,0.000000
54.170002,62.621132,-318.706024,0.005726,0.002186,0.055529,278.552704,14.190151,0.555286,-318.706024,0.055563,0.000000
54.340004,62.599533,-318.661530,0.005739,0.002186,0.055529,278.456635,14.185257,0.555286,-318.661530,0.055563,0.000000
54.510002,62.595810,-318.706024,0.005739,0.002186,0.055529,278.440063,14.184413,0.555286,-318.706024,0.055563,0.000000
54.680004,62.561928,-318.750488,0.005726,0.002186,0.055529,278.289368,14.176735,0.555286,-318.750488,0.055563,0.000000
54.850002,62.563042,-318.706024,0.005743,0.002186,0.055529,278.294312,14.176988,0.555286,-318.706024,0.055563,0.000000
55.020004,62.544052,-318.617065,0.005734,0.002186,0.055529,278.209839,14.172685,0.555286,-318.617065,0.055563,0.000000
55.190002,62.536980,-318.706024,0.005721,0.002186,0.055529,278.178375,14.171082,0.555286,-318.706024,0.055563,0.000000
55.360004,62.508301,-318.750488,0.005739,0.002186,0.055529,278.050812,14.164583,0.555286,-318.750488,0.055563,0.000000
55.530003,62.505325,-318.750488,0.005730,0.002186,0.055529,278.037567,14.163910,0.555286,-318.750488,0.055563,0.000000
55.700001,62.488197,-318.794983,0.005726,0.002186,0.055529,277.961395,14.160028,0.555286,-318.794983,0.055563,0.000000
55.870003,62.479630,-318.750488,0.005721,0.002186,0.055529,277.923279,14.158087,0.555286,-318.750488,0.055563,0.000000
56.040001,62.459152,-318.794983,0.005730,0.002186,0.055529,277.832184,14.153446,0.555286,-318.794983,0.055563,0.000000
56.210003,62.446861,-318.794983,0.005734,0.002186,0.055529,277.777527,14.150661,0.555286,-318.794983,0.055563,0.000000
56.380001,62.438301,-318.883942,0.005734,0.002186,0.055529,277.739441,14.148721,0.555286,-318.883942,0.055563,0.000000
56.550003,62.424149,-318.883942,0.005739,0.002186,0.055529,277.676483,14.145514,0.555286,-318.883942,0.055563,0.000000
56.720001,62.417816,-318.883942,0.005730,0.002186,0.055529,277.648315,14.144079,0.555286,-318.883942,0.055563,0.000000
56.890003,62.395851,-318.839447,0.005726,0.002186,0.055529,277.550598,14.139102,0.555286,-318.839447,0.055563,0.000000
57.060001,62.395851,-318.839447,0.005730,0.002186,0.055529,277.550598,14.139102,0.555286,-318.839447,0.055563,0.000000
57.230003,62.377975,-318.883942,0.005726,0.002186,0.055529,277.471100,14.135051,0.555286,-318.883942,0.055563,0.000000
57.400002,62.374619,-318.972900,0.005743,0.002186,0.055529,277.456146,14.134291,0.555286,-318.972900,0.055563,0.000000
57.570004,62.361214,-318.928406,0.005717,0.002186,0.055529,277.396545,14.131252,0.555286,-318.928406,0.055563,0.000000
57.740002,62.353394,-318.928406,0.005743,0.002186,0.055529,277.361755,14.129480,0.555286,-318.928406,0.055563,0.000000
57.910004,62.338501,-318.883942,0.005730,0.002186,0.055529,277.295502,14.126106,0.555286,-318.883942,0.055563,0.000000
58.080002,62.315414,-318.928406,0.005721,0.002186,0.055529,277.192810,14.120875,0.555286,-318.928406,0.055563,0.000000
58.250004,62.317650,-319.017395,0.005739,0.002186,0.055529,277.202759,14.121382,0.555286,-319.017395,0.055563,0.000000
58.420002,62.309456,-319.017395,0.005730,0.002186,0.055529,277.166290,14.119524,0.555286,-319.017395,0.055563,0.000000
58.590004,62.288979,-318.972900,0.005721,0.002186,0.055529,277.075226,14.114884,0.555286,-318.972900,0.055563,0.000000
58.760002,62.274078,-319.061859,0.005743,0.002186,0.055529,277.008942,14.111508,0.555286,-319.061859,0.055563,0.000000
58.930004,62.268120,-319.106354,0.005726,0.002186,0.055529,276.982422,14.110158,0.555286,-319.106354,0.055563,0.000000
59.100002,62.249504,-319.106354,0.005721,0.002186,0.055529,276.899628,14.105939,0.555286,-319.106354,0.055563,0.000000
59.270004,62.250992,-319.061859,0.005721,0.002186,0.055529,276.906250,14.106277,0.555286,-319.061859,0.055563,0.000000
59.440002,62.241684,-319.061859,0.005730,0.002186,0.055529,276.864838,14.104167,0.555286,-319.061859,0.055563,0.000000
59.610004,62.229401,-319.061859,0.005739,0.002186,0.055529,276.810211,14.101383,0.555286,-319.061859,0.055563,0.000000
59.780003,62.215622,-319.106354,0.005726,0.002186,0.055529,276.748901,14.098262,0.555286,-319.106354,0.055563,0.000000
59.950005,62.204079,-319.195312,0.005734,0.002186,0.055529,276.697571,14.095646,0.555286,-319.195312,0.055563,0.000000
60.120003,62.200722,-319.106354,0.005730,0.002186,0.055529,276.682617,14.094886,0.555286,-319.106354,0.055563,0.000000
60.290005,62.178009,-319.106354,0.005739,0.002186,0.055529,276.581604,14.089738,0.555286,-319.106354,0.055563,0.000000
60.460003,62.175034,-319.106354,0.005739,0.002186,0.055529,276.568359,14.089065,0.555286,-319.106354,0.055563,0.000000
60.630001,62.168327,-319.239777,0.005726,0.002186,0.055529,276.538544,14.087544,0.555286,-319.239777,0.055563,0.000000
60.800003,62.158272,-319.150818,0.005721,0.002186,0.055529,276.493805,14.085266,0.555286,-319.150818,0.055563,0.000000
60.970001,62.140396,-319.195312,0.005739,0.002186,0.055529,276.414276,14.081215,0.555286,-319.195312,0.055563,0.000000
61.140003,62.133698,-319.195312,0.005730,0.002186,0.055529,276.384491,14.079698,0.555286,-319.195312,0.055563,0.000000
61.310001,62.118805,-319.150818,0.005721,0.002186,0.055529,276.318237,14.076323,0.555286,-319.150818,0.055563,0.000000
61.480003,62.118057,-319.239777,0.005717,0.002186,0.055529,276.314911,14.076153,0.555286,-319.239777,0.055563,0.000000
61.650002,62.105026,-319.239777,0.005730,0.002186,0.055529,276.256958,14.073199,0.555286,-319.239777,0.055563,0.000000
61.820004,62.092361,-319.284271,0.005734,0.002186,0.055529,276.200623,14.070330,0.555286,-319.284271,0.055563,0.000000
61.990002,62.090874,-319.195312,0.005743,0.002186,0.055529,276.194000,14.069993,0.555286,-319.195312,0.055563,0.000000
62.160004,62.074120,-319.239777,0.005747,0.002186,0.055529,276.119476,14.066196,0.555286,-319.239777,0.055563,0.000000
62.330002,62.086403,-319.284271,0.005734,0.002186,0.055529,276.174103,14.068980,0.555286,-319.284271,0.055563,0.000000
62.500004,62.055130,-319.417725,0.005721,0.002186,0.055529,276.035004,14.061893,0.555286,-319.417725,0.055563,0.000000
62.670002,62.057358,-319.417725,0.005739,0.002186,0.055529,276.044922,14.062398,0.555286,-319.417725,0.055563,0.000000
62.840004,62.037628,-319.328735,0.005743,0.002186,0.055529,275.957153,14.057927,0.555286,-319.328735,0.055563,0.000000
63.010002,62.039116,-319.284271,0.005726,0.002186,0.055529,275.963776,14.058265,0.555286,-319.284271,0.055563,0.000000
63.180004,62.022354,-319.328735,0.005739,0.002186,0.055529,275.889221,14.054466,0.555286,-319.328735,0.055563,0.000000
63.350002,62.014542,-319.417725,0.005743,0.002186,0.055529,275.854462,14.052696,0.555286,-319.417725,0.055563,0.000000
63.520004,62.008209,-319.373230,0.005726,0.002186,0.055529,275.826294,14.051261,0.555286,-319.373230,0.055563,0.000000
63.690002,62.001129,-319.373230,0.005739,0.002186,0.055529,275.794800,14.049657,0.555286,-319.373230,0.055563,0.000000
63.860004,61.987358,-319.417725,0.005730,0.002186,0.055529,275.733551,14.046536,0.555286,-319.417725,0.055563,0.000000
64.030006,61.979164,-319.462189,0.005734,0.002186,0.055529,275.697083,14.044679,0.555286,-319.462189,0.055563,0.000000
64.200005,61.960915,-319.506683,0.005734,0.002186,0.055529,275.615906,14.040544,0.555286,-319.506683,0.055563,0.000000
64.370003,61.949371,-319.506683,0.005730,0.002186,0.055529,275.564575,14.037929,0.555286,-319.506683,0.055563,0.000000
64.540001,61.947136,-319.462189,0.005726,0.002186,0.055529,275.554626,14.037422,0.555286,-319.462189,0.055563,0.000000
64.710007,61.953842,-319.462189,0.005730,0.002186,0.055529,275.584442,14.038941,0.555286,-319.462189,0.055563,0.000000
64.880005,61.938950,-319.506683,0.005721,0.002186,0.055529,275.518219,14.035567,0.555286,-319.506683,0.055563,0.000000
65.050003,61.935593,-319.551147,0.005734,0.002186,0.055529,275.503265,14.034806,0.555286,-319.551147,0.055563,0.000000
65.220001,61.913254,-319.506683,0.005739,0.002186,0.055529,275.403900,14.029744,0.555286,-319.506683,0.055563,0.000000
65.389999,61.925911,-319.551147,0.005743,0.002186,0.055529,275.460205,14.032612,0.555286,-319.551147,0.055563,0.000000
65.560005,61.893517,-319.506683,0.005739,0.002186,0.055529,275.316101,14.025271,0.555286,-319.506683,0.055563,0.000000
65.730003,61.904312,-319.506683,0.005739,0.002186,0.055529,275.364136,14.027718,0.555286,-319.506683,0.055563,0.000000
65.900002,61.895004,-319.595642,0.005747,0.002186,0.055529,275.322723,14.025608,0.555286,-319.595642,0.055563,0.000000
66.070000,61.881226,-319.551147,0.005734,0.002186,0.055529,275.261444,14.022486,0.555286,-319.551147,0.055563,0.000000
66.240005,61.864098,-319.595642,0.005739,0.002186,0.055529,275.185242,14.018605,0.555286,-319.595642,0.055563,0.000000
66.410004,61.870804,-319.595642,0.005726,0.002186,0.055529,275.215088,14.020124,0.555286,-319.595642,0.055563,0.000000
66.580002,61.858139,-319.551147,0.005743,0.002186,0.055529,275.158752,14.017255,0.555286,-319.551147,0.055563,0.000000
66.750000,61.845482,-319.595642,0.005739,0.002186,0.055529,275.102448,14.014386,0.555286,-319.595642,0.055563,0.000000
66.920006,61.835052,-319.640106,0.005734,0.002186,0.055529,275.056061,14.012023,0.555286,-319.640106,0.055563,0.000000
67.090004,61.834679,-319.684601,0.005730,0.002186,0.055529,275.054382,14.011939,0.555286,-319.684601,0.055563,0.000000
67.260002,61.822021,-319.640106,0.005739,0.002186,0.055529,274.998077,14.009069,0.555286,-319.640106,0.055563,0.000000
67.430000,61.806755,-319.595642,0.005726,0.002186,0.055529,274.930176,14.005611,0.555286,-319.595642,0.055563,0.000000
67.600006,61.817177,-319.729065,0.005734,0.002186,0.055529,274.976532,14.007973,0.555286,-319.729065,0.055563,0.000000
67.770004,61.792603,-319.640106,0.005734,0.002186,0.055529,274.867218,14.002403,0.555286,-319.640106,0.055563,0.000000
67.940002,61.781059,-319.729065,0.005730,0.002186,0.055529,274.815887,13.999788,0.555286,-319.729065,0.055563,0.000000
68.110001,61.779572,-319.640106,0.005747,0.002186,0.055529,274.809265,13.999452,0.555286,-319.640106,0.055563,0.000000
68.280006,61.775475,-319.684601,0.005739,0.002186,0.055529,274.791046,13.998523,0.555286,-319.684601,0.055563,0.000000
68.450005,61.762817,-319.773560,0.005721,0.002186,0.055529,274.734741,13.995655,0.555286,-319.773560,0.055563,0.000000
68.620003,61.759834,-319.773560,0.005726,0.002186,0.055529,274.721466,13.994978,0.555286,-319.773560,0.055563,0.000000
68.790001,61.740471,-319.818024,0.005739,0.002186,0.055529,274.635345,13.990591,0.555286,-319.818024,0.055563,0.000000
68.960007,61.759094,-319.729065,0.005743,0.002186,0.055529,274.718170,13.994810,0.555286,-319.729065,0.055563,0.000000
69.130005,61.735634,-319.773560,0.005734,0.002186,0.055529,274.613800,13.989495,0.555286,-319.773560,0.055563,0.000000
69.300003,61.722969,-319.818024,0.005734,0.002186,0.055529,274.557465,13.986625,0.555286,-319.818024,0.055563,0.000000
69.470001,61.717758,-319.862518,0.005730,0.002186,0.055529,274.534302,13.985444,0.555286,-319.862518,0.055563,0.000000
69.640007,61.712547,-319.862518,0.005743,0.002186,0.055529,274.511108,13.984263,0.555286,-319.862518,0.055563,0.000000
69.810005,61.709938,-319.818024,0.005734,0.002186,0.055529,274.499512,13.983672,0.555286,-319.818024,0.055563,0.000000
69.980003,61.702866,-319.818024,0.005739,0.002186,0.055529,274.468048,13.982069,0.555286,-319.818024,0.055563,0.000000
70.150002,61.683502,-319.818024,0.005726,0.002186,0.055529,274.381927,13.977681,0.555286,-319.818024,0.055563,0.000000
70.320000,61.682381,-319.907013,0.005730,0.002186,0.055529,274.376923,13.977427,0.555286,-319.907013,0.055563,0.000000
70.490005,61.662643,-319.907013,0.005730,0.002186,0.055529,274.289124,13.972955,0.555286,-319.907013,0.055563,0.000000
70.660004,61.670090,-319.862518,0.005730,0.002186,0.055529,274.322266,13.974642,0.555286,-319.862518,0.055563,0.000000
70.830002,61.647003,-319.907013,0.005747,0.002186,0.055529,274.219574,13.969411,0.555286,-319.907013,0.055563,0.000000
71.000000,61.652962,-319.907013,0.005747,0.002186,0.055529,274.246063,13.970761,0.555286,-319.907013,0.055563,0.000000
71.170006,61.652596,-319.951477,0.005726,0.002186,0.055529,274.244446,13.970678,0.555286,-319.951477,0.055563,0.000000
71.340004,61.641792,-319.995972,0.005739,0.002186,0.055529,274.196381,13.968229,0.555286,-319.995972,0.055563,0.000000
71.510002,61.643654,-320.040436,0.005747,0.002186,0.055529,274.204681,13.968652,0.555286,-320.040436,0.055563,0.000000
71.680000,61.619080,-319.907013,0.005739,0.002186,0.055529,274.095367,13.963083,0.555286,-319.907013,0.055563,0.000000
71.800003,61.613495,-319.951477,0.005726,0.002186,0.055529,274.070526,13.961818,0.555286,-319.951477,0.055563,0.000000