File: Data/AG AL compression 300N/AL membrane Unpeeled 300N_1_3_03192024_182023.csv
Time (sec),S:Load (lbs),S:HL1 (DIM),S:LVDT (in),S:Position (in),Ch:Position (mm),Ch:Load (N),Ch:Stress (MPa),Ch:Strain (mm/mm),Ch:HL1 (DIM),Set Point (),Cycles ()
0.110000,0.002602,-239.040634,0.000009,-0.000000,-0.000000,0.011573,0.000590,-0.000000,-239.040634,0.000208,0.000000
0.270000,-0.003723,-239.085114,0.000013,-0.000000,-0.000000,-0.016561,-0.000844,-0.000000,-239.085114,0.000208,0.000000
0.430000,0.000374,-239.129593,0.000017,0.000014,0.000356,0.001663,0.000085,0.003558,-239.129593,0.000850,0.000000
0.590000,-0.002235,-239.085114,0.000017,0.000105,0.002663,-0.009944,-0.000507,0.026627,-239.085114,0.003504,0.000000
0.750000,-0.002983,-239.174072,0.000039,0.000200,0.005091,-0.013269,-0.000676,0.050907,-239.174072,0.006175,0.000000
0.910000,-0.009308,-239.129593,0.000168,0.000307,0.007788,-0.041403,-0.002109,0.077878,-239.129593,0.008846,0.000000
1.070000,0.013031,-239.218552,0.000254,0.000416,0.010572,0.057965,0.002953,0.105716,-239.218552,0.011517,0.000000
1.230000,0.026436,-239.174072,0.000358,0.000514,0.013061,0.117593,0.005990,0.130605,-239.174072,0.014171,0.000000
1.390000,0.013779,-239.129593,0.000461,0.000618,0.015697,0.061291,0.003122,0.156971,-239.129593,0.016842,0.000000
1.550000,-0.003357,-239.218552,0.000543,0.000720,0.018281,-0.014932,-0.000761,0.182814,-239.218552,0.019513,0.000000
1.710000,-0.024208,-239.174072,0.000655,0.000827,0.021013,-0.107683,-0.005486,0.210130,-239.174072,0.022167,0.000000
1.870000,0.056602,-239.263031,0.000763,0.000939,0.023840,0.251780,0.012826,0.238403,-239.263031,0.024838,0.000000
2.030000,0.117668,-239.263031,0.000875,0.001042,0.026459,0.523414,0.026664,0.264591,-239.263031,0.027509,0.000000
2.190000,0.209274,-239.307510,0.000970,0.001142,0.029009,0.930899,0.047422,0.290089,-239.307510,0.030162,0.000000
2.350000,0.315399,-239.352005,0.001056,0.001249,0.031723,1.402966,0.071470,0.317235,-239.352005,0.032833,0.000000
2.510000,0.532860,-239.307510,0.001168,0.001356,0.034446,2.370279,0.120748,0.344463,-239.307510,0.035505,0.000000
2.670000,0.658356,-239.352005,0.001220,-0.000001,-0.000017,2.928513,0.149186,-0.000170,-239.352005,0.000174,0.000000
2.830000,0.647552,-239.307510,0.001207,-0.000001,-0.000034,2.880457,0.146737,-0.000344,-239.307510,0.000174,0.000000
2.990000,0.634895,-239.352005,0.001229,-0.000001,-0.000034,2.824156,0.143869,-0.000344,-239.352005,0.000174,0.000000
3.150000,0.573822,-239.396484,0.001229,-0.000001,-0.000034,2.552488,0.130030,-0.000344,-239.396484,0.000199,0.000000
3.310000,0.608086,-239.352005,0.001229,-0.000001,-0.000034,2.704900,0.137794,-0.000344,-239.352005,0.000469,0.000000
3.470000,0.616646,-239.485443,0.001224,-0.000001,-0.000026,2.742978,0.139734,-0.000257,-239.485443,0.000737,0.000000
3.630000,0.626328,-239.396484,0.001212,0.000001,0.000026,2.786044,0.141928,0.000261,-239.396484,0.001006,0.000000
3.790000,0.714951,-239.396484,0.001220,0.000018,0.000460,3.180259,0.162010,0.004599,-239.396484,0.001266,0.000000
3.950000,0.756287,-239.485443,0.001242,0.000029,0.000729,3.364131,0.171377,0.007286,-239.485443,0.001535,0.000000
4.110000,0.807671,-239.485443,0.001246,0.000040,0.001023,3.592698,0.183021,0.010234,-239.485443,0.001804,0.000000
4.270000,0.860176,-239.529922,0.001263,0.000051,0.001284,3.826254,0.194919,0.012838,-239.529922,0.002073,0.000000
4.430000,0.891457,-239.485443,0.001263,0.000059,0.001492,3.965397,0.202007,0.014916,-239.485443,0.002333,0.000000
4.590000,0.908218,-239.529922,0.001268,0.000069,0.001743,4.039957,0.205805,0.017433,-239.529922,0.002602,0.000000
4.750000,0.955505,-239.529922,0.001263,0.000080,0.002029,4.250300,0.216521,0.020295,-239.529922,0.002871,0.000000
4.910000,0.998703,-239.529922,0.001293,0.000090,0.002281,4.442453,0.226309,0.022812,-239.529922,0.003140,0.000000
5.070000,1.069450,-239.618881,0.001285,0.000098,0.002498,4.757153,0.242341,0.024977,-239.618881,0.003400,0.000000
5.230000,1.133125,-239.618881,0.001302,0.000112,0.002836,5.040393,0.256770,0.028360,-239.618881,0.003669,0.000000
5.390000,1.204620,-239.574402,0.001337,0.000123,0.003122,5.358419,0.272971,0.031222,-239.574402,0.003937,0.000000
5.550000,1.251915,-239.618881,0.001319,0.000128,0.003244,5.568796,0.283688,0.032437,-239.618881,0.004206,0.000000
5.710000,1.292503,-239.663361,0.001345,0.000138,0.003512,5.749342,0.292885,0.035124,-239.663361,0.004467,0.000000
5.870000,1.401978,-239.618881,0.001332,0.000152,0.003859,6.236308,0.317693,0.038595,-239.618881,0.004735,0.000000
6.030000,1.462677,-239.663361,0.001367,0.000161,0.004102,6.506312,0.331447,0.041021,-239.663361,0.005004,0.000000
6.190000,1.537155,-239.752319,0.001375,0.000175,0.004449,6.837607,0.348324,0.044491,-239.752319,0.005273,0.000000
6.350000,1.630989,-239.707840,0.001384,0.000185,0.004709,7.255002,0.369587,0.047092,-239.707840,0.005533,0.000000
6.510000,1.696899,-239.707840,0.001380,0.000195,0.004961,7.548185,0.384523,0.049609,-239.707840,0.005802,0.000000
6.670001,1.754990,-239.752319,0.001384,0.000203,0.005152,7.806584,0.397686,0.051516,-239.752319,0.006071,0.000000
6.830000,1.870796,-239.707840,0.001401,0.000215,0.005464,8.321717,0.423928,0.054639,-239.707840,0.006340,0.000000
6.990000,1.958305,-239.841293,0.001427,0.000228,0.005793,8.710978,0.443758,0.057932,-239.841293,0.006600,0.000000
7.150001,2.088264,-239.796814,0.001414,0.000239,0.006062,9.289064,0.473208,0.060619,-239.796814,0.006868,0.000000
7.310000,2.182472,-239.796814,0.001440,0.000249,0.006331,9.708121,0.494555,0.063310,-239.796814,0.007138,0.000000
7.470000,2.268494,-239.885773,0.001436,0.000256,0.006504,10.090764,0.514048,0.065043,-239.885773,0.007406,0.000000
7.630001,2.346687,-239.796814,0.001440,0.000264,0.006713,10.438586,0.531767,0.067125,-239.796814,0.007666,0.000000
7.790000,2.510162,-239.885773,0.001466,0.000279,0.007085,11.165760,0.568811,0.070853,-239.885773,0.007935,0.000000
7.950000,2.628578,-239.841293,0.001470,0.000293,0.007432,11.692500,0.595644,0.074324,-239.841293,0.008204,0.000000
8.110001,2.748848,-239.930252,0.001483,0.000303,0.007692,12.227487,0.622898,0.076924,-239.930252,0.008473,0.000000
8.270000,2.827423,-239.885773,0.001496,0.000309,0.007840,12.577006,0.640703,0.078400,-239.885773,0.008733,0.000000
8.430000,2.934296,-239.885773,0.001505,0.000322,0.008169,13.052399,0.664921,0.081693,-239.885773,0.009002,0.000000
8.590000,3.057175,-239.930252,0.001509,0.000331,0.008404,13.598992,0.692766,0.084036,-239.930252,0.009271,0.000000
8.750000,3.177826,-240.019211,0.001513,0.000340,0.008629,14.135675,0.720106,0.086292,-240.019211,0.009540,0.000000
8.910001,3.337944,-240.019211,0.001531,0.000351,0.008907,14.847917,0.756389,0.089066,-240.019211,0.009800,0.000000
9.070001,3.529716,-240.019211,0.001539,0.000365,0.009271,15.700963,0.799845,0.092707,-240.019211,0.010069,0.000000
9.230000,3.632118,-239.930252,0.001561,0.000374,0.009496,16.156469,0.823050,0.094963,-239.930252,0.010338,0.000000
9.390000,3.760963,-240.019211,0.001569,0.000381,0.009687,16.729601,0.852247,0.096871,-240.019211,0.010606,0.000000
9.550000,3.805275,-240.019211,0.001565,0.000387,0.009835,16.926708,0.862288,0.098347,-240.019211,0.010866,0.000000
9.710000,4.150085,-240.108170,0.001587,0.000408,0.010363,18.460503,0.940423,0.103634,-240.108170,0.011135,0.000000
9.870001,4.278183,-240.108170,0.001591,0.000418,0.010624,19.030308,0.969450,0.106238,-240.108170,0.011404,0.000000
10.030001,4.424156,-240.019211,0.001591,0.000429,0.010901,19.679630,1.002528,0.109013,-240.019211,0.011673,0.000000
10.190001,4.564911,-240.108170,0.001604,0.000438,0.011135,20.305738,1.034424,0.111352,-240.108170,0.011933,0.000000
10.350000,4.676994,-240.063690,0.001613,0.000447,0.011361,20.804310,1.059822,0.113607,-240.063690,0.012202,0.000000
10.510000,4.824455,-240.108170,0.001638,0.000456,0.011578,21.460249,1.093237,0.115776,-240.108170,0.012471,0.000000
10.670000,4.914200,-240.152649,0.001638,0.000464,0.011777,21.859453,1.113574,0.117771,-240.152649,0.012740,0.000000
10.830001,5.175972,-240.152649,0.001638,0.000478,0.012132,23.023872,1.172892,0.121325,-240.152649,0.013000,0.000000
10.990001,5.448555,-240.241623,0.001656,0.000492,0.012488,24.236383,1.234660,0.124883,-240.241623,0.013269,0.000000
11.150001,5.568459,-240.152649,0.001656,0.000500,0.012696,24.769741,1.261831,0.126964,-240.152649,0.013537,0.000000
11.310000,5.702507,-240.241623,0.001673,0.000508,0.012905,25.366018,1.292207,0.129046,-240.241623,0.013807,0.000000
11.470000,5.915878,-240.197128,0.001686,0.000521,0.013225,26.315142,1.340557,0.132252,-240.197128,0.014067,0.000000
11.630000,6.068176,-240.241623,0.001686,0.000531,0.013494,26.992596,1.375068,0.134943,-240.241623,0.014335,0.000000
11.790001,6.331078,-240.286102,0.001699,0.000545,0.013841,28.162039,1.434643,0.138410,-240.286102,0.014604,0.000000
11.950001,6.522850,-240.330582,0.001720,0.000555,0.014101,29.015085,1.478099,0.141014,-240.330582,0.014873,0.000000
12.110001,6.634186,-240.330582,0.001729,0.000563,0.014310,29.510332,1.503328,0.143096,-240.330582,0.015133,0.000000
12.270000,6.759300,-240.286102,0.001716,0.000571,0.014500,30.066870,1.531679,0.145003,-240.286102,0.015402,0.000000
12.430000,6.958153,-240.330582,0.001725,0.000582,0.014778,30.951410,1.576740,0.147777,-240.330582,0.015671,0.000000
12.590000,7.049011,-240.375061,0.001750,0.000589,0.014951,31.355568,1.597329,0.149511,-240.375061,0.015940,0.000000
12.750001,7.191628,-240.375061,0.001733,0.000599,0.015203,31.989956,1.629646,0.152028,-240.375061,0.016200,0.000000
12.910001,7.559532,-240.419540,0.001755,0.000611,0.015532,33.626480,1.713014,0.155321,-240.419540,0.016469,0.000000
13.070001,7.747581,-240.419540,0.001768,0.000621,0.015775,34.462963,1.755627,0.157751,-240.419540,0.016738,0.000000
13.230000,7.954620,-240.419540,0.001794,0.000633,0.016070,35.383919,1.802543,0.160699,-240.419540,0.017006,0.000000
13.390000,8.067818,-240.464020,0.001781,0.000642,0.016295,35.887444,1.828194,0.162955,-240.464020,0.017267,0.000000
13.550000,8.359390,-240.464020,0.001811,0.000656,0.016651,37.184425,1.894265,0.166509,-240.464020,0.017535,0.000000
13.710001,8.588394,-240.508499,0.001798,0.000667,0.016937,38.203087,1.946158,0.169370,-240.508499,0.017804,0.000000
13.870001,8.930237,-240.419540,0.001807,0.000682,0.017319,39.723679,2.023621,0.173185,-240.419540,0.018073,0.000000
14.030001,9.011040,-240.464020,0.001837,0.000689,0.017501,40.083107,2.041931,0.175006,-240.464020,0.018333,0.000000
14.190001,9.091103,-240.464020,0.001828,0.000695,0.017666,40.439243,2.060073,0.176656,-240.464020,0.018602,0.000000
14.350000,9.221428,-240.508499,0.001832,0.000704,0.017891,41.018959,2.089606,0.178912,-240.508499,0.018871,0.000000
14.510000,9.532730,-240.508499,0.001850,0.000716,0.018177,42.403702,2.160147,0.181773,-240.508499,0.019140,0.000000
14.670001,9.626945,-240.508499,0.001841,0.000725,0.018403,42.822792,2.181497,0.184025,-240.508499,0.019400,0.000000
14.830001,10.055916,-240.597458,0.001876,0.000739,0.018776,44.730949,2.278703,0.187757,-240.597458,0.019669,0.000000
14.990001,10.318069,-240.597458,0.001871,0.000751,0.019071,45.897064,2.338108,0.190706,-240.597458,0.019938,0.000000
15.150001,10.439835,-240.597458,0.001871,0.000758,0.019253,46.438705,2.365700,0.192526,-240.597458,0.020206,0.000000
15.310000,10.491592,-240.641953,0.001897,0.000764,0.019400,46.668934,2.377429,0.193999,-240.641953,0.020467,0.000000
15.470000,10.743690,-240.641953,0.001884,0.000775,0.019678,47.790321,2.434555,0.196777,-240.641953,0.020736,0.000000
15.630001,11.018875,-240.686432,0.001927,0.000788,0.020007,49.014404,2.496913,0.200070,-240.686432,0.021004,0.000000
15.790001,11.521576,-240.686432,0.001923,0.000805,0.020458,51.250530,2.610826,0.204581,-240.686432,0.021273,0.000000
15.950001,11.603493,-240.641953,0.001932,0.000815,0.020701,51.614914,2.629389,0.207007,-240.641953,0.021533,0.000000
16.110001,11.704781,-240.730911,0.001932,0.000822,0.020874,52.065464,2.652341,0.208745,-240.730911,0.021802,0.000000
16.270000,11.894691,-240.686432,0.001940,0.000833,0.021152,52.910229,2.695376,0.211519,-240.686432,0.022071,0.000000
16.430000,11.999329,-240.730911,0.001940,0.000841,0.021351,53.375679,2.719087,0.213513,-240.730911,0.022340,0.000000
16.590000,12.356064,-240.730911,0.001975,0.000854,0.021681,54.962517,2.799924,0.216806,-240.730911,0.022600,0.000000
16.750000,12.642792,-240.730911,0.001966,0.000865,0.021975,56.237946,2.864897,0.219755,-240.730911,0.022869,0.000000
16.910002,12.970474,-240.819870,0.001983,0.000877,0.022288,57.695553,2.939152,0.222877,-240.819870,0.023138,0.000000
17.070002,13.073624,-240.730911,0.001979,0.000885,0.022470,58.154381,2.962525,0.224702,-240.730911,0.023407,0.000000
17.230001,13.287735,-240.819870,0.001992,0.000895,0.022739,59.106796,3.011044,0.227389,-240.819870,0.023667,0.000000
17.390001,13.364075,-240.819870,0.002001,0.000901,0.022886,59.446373,3.028342,0.228861,-240.819870,0.023936,0.000000
17.550001,13.896568,-240.908829,0.002005,0.000919,0.023346,61.815022,3.149007,0.233460,-240.908829,0.024204,0.000000
17.710001,14.177704,-240.819870,0.002048,0.000933,0.023693,63.065575,3.212714,0.236927,-240.819870,0.024473,0.000000
17.870001,14.338570,-240.864349,0.002039,0.000942,0.023936,63.781143,3.249166,0.239357,-240.864349,0.024734,0.000000
18.030001,14.477470,-240.908829,0.002039,0.000952,0.024178,64.399002,3.280642,0.241783,-240.908829,0.025002,0.000000
18.190001,14.696793,-240.819870,0.002039,0.000962,0.024430,65.374596,3.330341,0.244300,-240.819870,0.025271,0.000000
18.350000,14.846863,-240.908829,0.002070,0.000970,0.024647,66.042145,3.364347,0.246469,-240.908829,0.025540,0.000000
18.510000,14.812233,-240.908829,0.002065,0.000976,0.024794,65.888100,3.356500,0.247941,-240.908829,0.025800,0.000000
18.670000,15.336906,-240.953308,0.002078,0.000991,0.025167,68.221970,3.475393,0.251669,-240.953308,0.026069,0.000000
18.830002,15.777794,-240.953308,0.002078,0.001004,0.025505,70.183136,3.575299,0.255053,-240.953308,0.026338,0.000000
18.990002,15.894714,-240.953308,0.002091,0.001013,0.025722,70.703224,3.601794,0.257221,-240.953308,0.026607,0.000000
19.150002,15.957275,-240.997787,0.002113,0.001018,0.025852,70.981506,3.615970,0.258523,-240.997787,0.026875,0.000000
19.310001,16.282356,-241.042267,0.002113,0.001030,0.026164,72.427536,3.689635,0.261642,-241.042267,0.027136,0.000000
19.470001,16.729950,-240.997787,0.002121,0.001045,0.026554,74.418533,3.791061,0.265544,-240.997787,0.027405,0.000000
19.630001,17.011833,-241.042267,0.002143,0.001058,0.026867,75.672417,3.854937,0.268667,-241.042267,0.027673,0.000000
19.790001,17.156311,-240.997787,0.002139,0.001066,0.027084,76.315086,3.887676,0.270836,-240.997787,0.027942,0.000000
19.950001,17.380486,-241.086761,0.002156,0.001078,0.027370,77.312263,3.938474,0.273697,-241.086761,0.028202,0.000000
20.110001,17.523102,-241.086761,0.002151,0.001087,0.027604,77.946648,3.970792,0.276040,-241.086761,0.028471,0.000000
20.270000,17.643005,-241.042267,0.002173,0.001094,0.027795,78.480011,3.997962,0.277948,-241.042267,0.028740,0.000000
20.430000,17.720085,-241.175720,0.002169,0.001100,0.027934,78.822876,4.015429,0.279337,-241.175720,0.029009,0.000000
20.590000,18.515472,-241.131241,0.002177,0.001122,0.028489,82.360931,4.195666,0.284885,-241.131241,0.029269,0.000000
20.750002,18.714691,-241.131241,0.002190,0.001131,0.028723,83.247101,4.240810,0.287228,-241.131241,0.029538,0.000000
20.910002,18.725868,-241.175720,0.002195,0.001137,0.028887,83.296822,4.243342,0.288875,-241.175720,0.029807,0.000000
21.070002,18.846138,-241.175720,0.002195,0.001147,0.029130,83.831810,4.270596,0.291304,-241.175720,0.030076,0.000000
21.230001,19.320541,-241.175720,0.002207,0.001160,0.029460,85.942062,4.378097,0.294597,-241.175720,0.030336,0.000000
21.390001,19.786385,-241.131241,0.002229,0.001173,0.029789,88.014236,4.483659,0.297894,-241.131241,0.030605,0.000000
21.550001,20.003845,-241.175720,0.002225,0.001182,0.030024,88.981544,4.532936,0.300237,-241.175720,0.030873,0.000000
21.710001,20.154282,-241.220200,0.002229,0.001193,0.030301,89.650719,4.567025,0.303011,-241.220200,0.031142,0.000000
21.870001,20.450325,-241.220200,0.002246,0.001203,0.030561,90.967590,4.634109,0.305611,-241.220200,0.031403,0.000000
22.030001,20.754547,-241.353638,0.002238,0.001213,0.030813,92.320839,4.703048,0.308128,-241.353638,0.031671,0.000000
22.190001,20.878548,-241.309158,0.002268,0.001222,0.031029,92.872421,4.731147,0.310293,-241.309158,0.031940,0.000000
22.350000,21.163040,-241.353638,0.002264,0.001232,0.031290,94.137901,4.795613,0.312897,-241.353638,0.032209,0.000000
22.510000,21.628136,-241.309158,0.002285,0.001245,0.031628,96.206749,4.901006,0.316277,-241.309158,0.032469,0.000000
22.670002,21.810226,-241.309158,0.002302,0.001253,0.031836,97.016731,4.942268,0.318359,-241.309158,0.032738,0.000000
22.830002,21.996040,-241.398117,0.002281,0.001262,0.032044,97.843277,4.984374,0.320441,-241.398117,0.033007,0.000000
22.990002,22.375488,-241.353638,0.002298,0.001274,0.032356,99.531143,5.070358,0.323563,-241.353638,0.033276,0.000000
23.150002,22.904999,-241.442596,0.002320,0.001288,0.032703,101.886520,5.190347,0.327034,-241.442596,0.033536,0.000000
23.310001,23.328384,-241.353638,0.002315,0.001302,0.033059,103.769836,5.286287,0.330588,-241.353638,0.033805,0.000000
23.470001,23.659058,-241.442596,0.002333,0.001313,0.033345,105.240746,5.361219,0.333449,-241.442596,0.034074,0.000000
23.630001,23.865349,-241.487076,0.002337,0.001323,0.033605,106.158371,5.407965,0.336053,-241.487076,0.034342,0.000000
23.790001,23.990097,-241.442596,0.002354,0.001330,0.033787,106.713280,5.436234,0.337874,-241.442596,0.034603,0.000000
23.950001,24.154312,-241.487076,0.002354,0.001339,0.034021,107.443748,5.473445,0.340213,-241.487076,0.034871,0.000000
24.110001,24.476044,-241.442596,0.002367,0.001349,0.034273,108.874878,5.546351,0.342730,-241.442596,0.035140,0.000000
24.270000,24.833145,-241.487076,0.002371,0.001359,0.034524,110.463348,5.627271,0.345243,-241.487076,0.035409,0.000000
24.430000,25.282227,-241.531570,0.002367,0.001372,0.034837,112.460960,5.729034,0.348366,-241.531570,0.035669,0.000000
24.590002,25.662422,-241.487076,0.002389,0.001382,0.035105,114.152153,5.815188,0.351053,-241.487076,0.035938,0.000000
24.750002,26.000908,-241.620529,0.002419,0.001393,0.035374,115.657814,5.891890,0.353744,-241.620529,0.036207,0.000000
24.910002,26.176666,-241.531570,0.002393,0.001400,0.035548,116.439629,5.931717,0.355477,-241.531570,0.036476,0.000000
25.070002,26.440674,-241.620529,0.002414,0.001412,0.035860,117.613991,5.991542,0.358600,-241.620529,0.036736,0.000000
25.230001,27.196220,-241.620529,0.002402,0.001426,0.036215,120.974831,6.162751,0.362154,-241.620529,0.037005,0.000000
25.390001,27.484062,-241.576050,0.002427,0.001437,0.036493,122.255211,6.227978,0.364932,-241.576050,0.037274,0.000000
25.550001,27.699669,-241.620529,0.002423,0.001445,0.036710,123.214279,6.276835,0.367097,-241.620529,0.037542,0.000000
25.710001,28.008736,-241.620529,0.002436,0.001456,0.036970,124.589081,6.346870,0.369701,-241.620529,0.037802,0.000000
25.870001,28.354301,-241.665009,0.002445,0.001465,0.037213,126.126228,6.425177,0.372127,-241.665009,0.038072,0.000000
26.030001,28.639168,-241.665009,0.002453,0.001473,0.037421,127.393379,6.489728,0.374209,-241.665009,0.038340,0.000000
26.190001,29.025688,-241.709488,0.002471,0.001485,0.037724,129.112717,6.577315,0.377244,-241.709488,0.038609,0.000000
26.350000,29.316879,-241.753967,0.002471,0.001493,0.037915,130.407990,6.643300,0.379152,-241.753967,0.038869,0.000000
26.510002,29.708618,-241.753967,0.002479,0.001505,0.038219,132.150528,6.732069,0.382187,-241.753967,0.039138,0.000000
26.670002,30.466766,-241.753967,0.002466,0.001519,0.038592,135.522949,6.903868,0.385915,-241.753967,0.039407,0.000000
26.830002,30.664497,-241.753967,0.002483,0.001526,0.038757,136.402496,6.948675,0.387566,-241.753967,0.039676,0.000000
26.990002,30.754616,-241.709488,0.002505,0.001534,0.038956,136.803360,6.969096,0.389560,-241.709488,0.039936,0.000000
27.150002,31.458023,-241.842926,0.002501,0.001548,0.039320,139.932281,7.128490,0.393201,-241.842926,0.040205,0.000000
27.310001,32.056053,-241.798447,0.002514,0.001560,0.039632,142.592453,7.264006,0.396324,-241.798447,0.040474,0.000000
27.470001,32.365120,-241.842926,0.002522,0.001570,0.039867,143.967239,7.334041,0.398667,-241.842926,0.040743,0.000000
27.630001,32.784790,-241.842926,0.002527,0.001580,0.040127,145.834030,7.429140,0.401267,-241.842926,0.041003,0.000000
27.790001,33.294937,-241.887405,0.002535,0.001592,0.040439,148.103271,7.544741,0.404390,-241.887405,0.041271,0.000000
27.950001,33.510910,-241.887405,0.002539,0.001600,0.040638,149.063980,7.593681,0.406384,-241.887405,0.041540,0.000000
28.110001,33.913078,-241.842926,0.002539,0.001610,0.040898,150.852905,7.684813,0.408984,-241.842926,0.041809,0.000000
28.270000,34.404610,-241.976379,0.002557,0.001622,0.041202,153.039352,7.796196,0.412020,-241.976379,0.042069,0.000000
28.430002,34.926300,-241.887405,0.002561,0.001632,0.041462,155.359940,7.914412,0.414624,-241.887405,0.042338,0.000000
28.590002,35.399590,-241.887405,0.002587,0.001644,0.041766,157.465240,8.021662,0.417659,-241.887405,0.042607,0.000000
28.750002,35.725037,-242.020859,0.002565,0.001653,0.041974,158.912903,8.095409,0.419737,-242.020859,0.042876,0.000000
28.910002,35.831169,-241.931900,0.002570,0.001659,0.042130,159.384995,8.119459,0.421300,-241.931900,0.043136,0.000000
29.070002,36.351372,-242.020859,0.002591,0.001670,0.042416,161.698975,8.237338,0.424162,-242.020859,0.043405,0.000000
29.230001,37.224586,-241.931900,0.002596,0.001685,0.042798,165.583237,8.435211,0.427977,-241.931900,0.043674,0.000000
29.390001,37.931343,-242.020859,0.002600,0.001697,0.043110,168.727036,8.595365,0.431100,-242.020859,0.043943,0.000000
29.550001,38.170036,-242.020859,0.002617,0.001705,0.043301,169.788803,8.649454,0.433007,-242.020859,0.044203,0.000000
29.710001,38.590073,-242.020859,0.002600,0.001715,0.043552,171.657211,8.744636,0.435524,-242.020859,0.044471,0.000000
29.870001,39.058517,-242.065338,0.002621,0.001725,0.043821,173.740967,8.850787,0.438211,-242.065338,0.044740,0.000000
30.030001,39.505363,-242.109818,0.002630,0.001734,0.044055,175.728638,8.952044,0.440550,-242.109818,0.045009,0.000000
30.190001,39.879601,-242.109818,0.002630,0.001744,0.044307,177.393326,9.036847,0.443067,-242.109818,0.045269,0.000000
30.350002,40.479118,-242.154297,0.002647,0.001757,0.044636,180.060104,9.172699,0.446364,-242.154297,0.045538,0.000000
30.510002,41.179550,-242.109818,0.002647,0.001768,0.044905,183.175781,9.331420,0.449051,-242.109818,0.045807,0.000000
30.670002,41.709808,-242.198776,0.002639,0.001779,0.045183,185.534500,9.451578,0.451826,-242.198776,0.046076,0.000000
30.830002,41.672203,-242.109818,0.002647,0.001782,0.045252,185.367218,9.443056,0.452518,-242.109818,0.046336,0.000000
30.990002,42.666809,-242.154297,0.002656,0.001800,0.045729,189.791443,9.668438,0.457291,-242.154297,0.046605,0.000000
31.150002,43.505760,-242.198776,0.002673,0.001813,0.046058,193.523285,9.858546,0.460584,-242.198776,0.046874,0.000000
31.310001,43.967133,-242.198776,0.002656,0.001823,0.046301,195.575577,9.963095,0.463014,-242.198776,0.047142,0.000000
31.470001,44.482124,-242.332214,0.002690,0.001833,0.046561,197.866379,10.079793,0.465614,-242.332214,0.047403,0.000000
31.630001,44.845558,-242.243256,0.002690,0.001842,0.046796,199.483002,10.162148,0.467957,-242.243256,0.047672,0.000000
31.790001,45.301346,-242.287735,0.002703,0.001851,0.047013,201.510452,10.265432,0.470126,-242.287735,0.047940,0.000000
31.950001,45.652115,-242.287735,0.002690,0.001860,0.047255,203.070755,10.344917,0.472552,-242.287735,0.048209,0.000000
32.110001,46.092636,-242.243256,0.002686,0.001869,0.047481,205.030289,10.444741,0.474808,-242.243256,0.048469,0.000000
32.270000,47.272682,-242.332214,0.002712,0.001886,0.047914,210.279388,10.712143,0.479145,-242.332214,0.048738,0.000000
32.430000,47.722137,-242.287735,0.002716,0.001894,0.048105,212.278671,10.813991,0.481053,-242.287735,0.049007,0.000000
32.590000,48.063599,-242.376709,0.002712,0.001903,0.048331,213.797562,10.891367,0.483308,-242.376709,0.049276,0.000000
32.750000,48.343628,-242.376709,0.002703,0.001910,0.048522,215.043198,10.954823,0.485216,-242.376709,0.049536,0.000000
32.910000,49.327431,-242.332214,0.002738,0.001925,0.048886,219.419373,11.177755,0.488857,-242.332214,0.049805,0.000000
33.070000,50.072182,-242.376709,0.002734,0.001938,0.049224,222.732193,11.346519,0.492241,-242.376709,0.050074,0.000000
33.230003,50.755112,-242.376709,0.002734,0.001949,0.049510,225.770020,11.501273,0.495102,-242.376709,0.050343,0.000000
33.390003,51.145355,-242.465668,0.002768,0.001957,0.049710,227.505905,11.589703,0.497097,-242.465668,0.050603,0.000000
33.550003,51.604118,-242.421188,0.002755,0.001966,0.049944,229.546585,11.693661,0.499436,-242.421188,0.050872,0.000000
33.710003,51.999207,-242.465668,0.002751,0.001974,0.050152,231.304016,11.783189,0.501518,-242.465668,0.051140,0.000000
33.870003,52.471375,-242.510147,0.002751,0.001983,0.050369,233.404327,11.890182,0.503686,-242.510147,0.051409,0.000000
34.030003,52.847839,-242.465668,0.002781,0.001991,0.050559,235.078934,11.975492,0.505594,-242.465668,0.051669,0.000000
34.190002,53.686798,-242.510147,0.002781,0.002004,0.050906,238.810806,12.165602,0.509065,-242.510147,0.051938,0.000000
34.350002,54.421120,-242.510147,0.002772,0.002016,0.051218,242.077225,12.332002,0.512183,-242.510147,0.052207,0.000000
34.510002,55.185226,-242.510147,0.002794,0.002027,0.051479,245.476151,12.505151,0.514787,-242.510147,0.052476,0.000000
34.670002,55.478279,-242.599106,0.002777,0.002035,0.051678,246.779709,12.571558,0.516782,-242.599106,0.052736,0.000000
34.830002,56.282234,-242.510147,0.002794,0.002048,0.052008,250.355881,12.753737,0.520079,-242.510147,0.053005,0.000000
34.990002,57.157310,-242.599106,0.002794,0.002059,0.052311,254.248413,12.952031,0.523110,-242.599106,0.053274,0.000000
35.150002,58.200699,-242.554626,0.002815,0.002076,0.052719,258.889648,13.188467,0.527187,-242.554626,0.053543,0.000000
35.310001,58.767822,-242.599106,0.002811,0.002085,0.052953,261.412323,13.316978,0.529530,-242.599106,0.053803,0.000000
35.470001,59.060875,-242.643585,0.002794,0.002091,0.053109,262.715881,13.383386,0.531089,-242.643585,0.054072,0.000000
35.630001,59.285416,-242.643585,0.002828,0.002096,0.053248,263.714691,13.434268,0.532478,-242.643585,0.054340,0.000000
35.790001,59.987709,-242.643585,0.002824,0.002108,0.053551,266.838654,13.593410,0.535513,-242.643585,0.054609,0.000000
35.950001,60.522064,-242.688065,0.002824,0.002117,0.053777,269.215576,13.714496,0.537769,-242.688065,0.054870,0.000000
36.110001,60.954018,-242.643585,0.002841,0.002125,0.053968,271.137024,13.812378,0.539677,-242.643585,0.055138,0.000000
36.270000,62.143745,-242.777023,0.002828,0.002140,0.054349,276.429199,14.081974,0.543492,-242.777023,0.055407,0.000000
36.430000,62.879929,-242.732544,0.002850,0.002150,0.054618,279.703888,14.248796,0.546179,-242.732544,0.055676,0.000000
36.590000,63.449287,-242.732544,0.002859,0.002161,0.054887,282.236511,14.377814,0.548870,-242.732544,0.055936,0.000000
36.750000,63.755379,-242.777023,0.002841,0.002170,0.055112,283.598083,14.447175,0.551122,-242.777023,0.056205,0.000000
36.910000,64.423790,-242.777023,0.002863,0.002179,0.055355,286.571320,14.598639,0.553552,-242.777023,0.056474,0.000000
37.070004,66.054405,-242.777023,0.002850,0.002199,0.055858,293.824677,14.968143,0.558582,-242.777023,0.056743,0.000000
37.230003,66.770470,-242.777023,0.002859,0.002210,0.056136,297.009888,15.130404,0.561357,-242.777023,0.057003,0.000000
37.390003,67.321220,-242.865997,0.002867,0.002218,0.056335,299.459747,15.255206,0.563351,-242.865997,0.057272,0.000000
37.550003,67.360313,-242.865997,0.002867,0.002213,0.056205,299.633636,15.264065,0.562049,-242.865997,0.056422,0.000000
37.710003,67.032997,-242.865997,0.002880,0.002213,0.056205,298.177673,15.189895,0.562049,-242.865997,0.056422,0.000000
37.870003,66.810326,-242.865997,0.002884,0.002212,0.056196,297.187164,15.139437,0.561962,-242.865997,0.056205,0.000000
38.030003,66.590614,-242.865997,0.002876,0.002212,0.056179,296.209839,15.089649,0.561792,-242.865997,0.056205,0.000000
38.190002,66.386940,-242.910477,0.002884,0.002211,0.056170,295.303864,15.043496,0.561705,-242.910477,0.056205,0.000000
38.350002,66.213402,-242.865997,0.002884,0.002211,0.056162,294.531921,15.004171,0.561618,-242.865997,0.056205,0.000000
38.510002,66.065208,-242.954956,0.002889,0.002211,0.056162,293.872711,14.970590,0.561618,-242.954956,0.056205,0.000000
38.670002,65.922585,-242.954956,0.002876,0.002211,0.056153,293.238312,14.938271,0.561531,-242.954956,0.056205,0.000000
38.830002,65.801186,-242.910477,0.002889,0.002211,0.056153,292.698303,14.910762,0.561531,-242.910477,0.056205,0.000000
38.990002,65.697670,-242.999435,0.002884,0.002211,0.056153,292.237823,14.887304,0.561531,-242.999435,0.056205,0.000000
39.150002,65.577766,-242.999435,0.002902,0.002211,0.056153,291.704468,14.860134,0.561531,-242.999435,0.056205,0.000000
39.310001,65.492867,-243.043915,0.002893,0.002211,0.056153,291.326813,14.840896,0.561531,-243.043915,0.056205,0.000000
39.470001,65.405739,-243.043915,0.002876,0.002211,0.056153,290.939270,14.821152,0.561531,-243.043915,0.056205,0.000000
39.630001,65.310036,-243.043915,0.002884,0.002211,0.056153,290.513550,14.799465,0.561531,-243.043915,0.056205,0.000000
39.790001,65.238914,-243.088394,0.002889,0.002211,0.056153,290.197174,14.783349,0.561531,-243.088394,0.056205,0.000000
39.950001,65.170769,-243.043915,0.002893,0.002210,0.056144,289.894043,14.767907,0.561444,-243.043915,0.056205,0.000000
40.110001,65.076180,-243.177353,0.002889,0.002210,0.056144,289.473297,14.746473,0.561444,-243.177353,0.056205,0.000000
40.270000,65.030373,-243.177353,0.002893,0.002210,0.056144,289.269531,14.736093,0.561444,-243.177353,0.056205,0.000000
40.430000,64.968941,-243.088394,0.002906,0.002210,0.056144,288.996277,14.722173,0.561444,-243.088394,0.056205,0.000000
40.590000,64.908607,-243.221848,0.002889,0.002210,0.056144,288.727905,14.708501,0.561444,-243.221848,0.056205,0.000000
40.750004,64.853508,-243.177353,0.002893,0.002210,0.056144,288.482819,14.696015,0.561444,-243.177353,0.056205,0.000000
40.910004,64.792809,-243.132874,0.002876,0.002210,0.056144,288.212799,14.682261,0.561444,-243.132874,0.056205,0.000000
41.070004,64.738075,-243.266327,0.002889,0.002210,0.056144,287.969330,14.669857,0.561444,-243.266327,0.056205,0.000000
41.230003,64.692635,-243.221848,0.002893,0.002210,0.056144,287.767212,14.659561,0.561444,-243.221848,0.056205,0.000000
41.390003,64.646095,-243.177353,0.002915,0.002210,0.056144,287.560181,14.649014,0.561444,-243.177353,0.056205,0.000000
41.550003,64.580925,-243.266327,0.002897,0.002210,0.056144,287.270294,14.634247,0.561444,-243.266327,0.056205,0.000000
41.710003,64.565285,-243.266327,0.002906,0.002210,0.056144,287.200745,14.630702,0.561444,-243.266327,0.056205,0.000000
41.870003,64.515755,-243.310806,0.002902,0.002210,0.056144,286.980408,14.619479,0.561444,-243.310806,0.056205,0.000000
42.030003,64.474434,-243.310806,0.002906,0.002210,0.056144,286.796600,14.610115,0.561444,-243.310806,0.056205,0.000000
42.190002,64.434959,-243.310806,0.002897,0.002210,0.056144,286.621002,14.601171,0.561444,-243.310806,0.056205,0.000000
42.350002,64.385063,-243.310806,0.002902,0.002210,0.056144,286.399078,14.589864,0.561444,-243.310806,0.056205,0.000000
42.510002,64.367928,-243.355286,0.002893,0.002210,0.056144,286.322845,14.585981,0.561444,-243.355286,0.056205,0.000000
42.670002,64.328835,-243.310806,0.002889,0.002210,0.056144,286.148956,14.577123,0.561444,-243.310806,0.056205,0.000000
42.830002,64.280052,-243.310806,0.002884,0.002210,0.056144,285.931946,14.566068,0.561444,-243.310806,0.056205,0.000000
42.990002,64.255852,-243.444244,0.002897,0.002210,0.056144,285.824310,14.560584,0.561444,-243.444244,0.056205,0.000000
43.150002,64.228294,-243.310806,0.002884,0.002210,0.056144,285.701721,14.554339,0.561444,-243.310806,0.056205,0.000000
43.310001,64.189186,-243.444244,0.002910,0.002210,0.056144,285.527771,14.545477,0.561444,-243.444244,0.056205,0.000000
43.470001,64.156792,-243.399765,0.002871,0.002210,0.056144,285.383667,14.538137,0.561444,-243.399765,0.056205,0.000000
43.630001,64.138924,-243.488724,0.002902,0.002210,0.056144,285.304169,14.534088,0.561444,-243.488724,0.056205,0.000000
43.790001,64.105400,-243.444244,0.002884,0.002210,0.056144,285.155060,14.526491,0.561444,-243.444244,0.056205,0.000000
43.950001,64.063332,-243.444244,0.002897,0.002210,0.056144,284.967926,14.516958,0.561444,-243.444244,0.056205,0.000000
44.110001,64.035774,-243.533203,0.002893,0.002210,0.056144,284.845337,14.510714,0.561444,-243.533203,0.056205,0.000000
44.270000,63.999657,-243.577682,0.002902,0.002210,0.056144,284.684692,14.502530,0.561444,-243.577682,0.056205,0.000000
44.430000,63.997795,-243.533203,0.002915,0.002210,0.056144,284.676422,14.502108,0.561444,-243.533203,0.056205,0.000000
44.590004,63.963158,-243.533203,0.002902,0.002210,0.056144,284.522339,14.494259,0.561444,-243.533203,0.056205,0.000000
44.750004,63.940071,-243.533203,0.002910,0.002210,0.056144,284.419647,14.489027,0.561444,-243.533203,0.056205,0.000000
44.910004,63.915871,-243.577682,0.002884,0.002210,0.056144,284.311981,14.483543,0.561444,-243.577682,0.056205,0.000000
45.070004,63.892784,-243.622162,0.002880,0.002210,0.056144,284.209290,14.478312,0.561444,-243.622162,0.056205,0.000000
45.230003,63.870445,-243.577682,0.002897,0.002210,0.056144,284.109924,14.473250,0.561444,-243.577682,0.056205,0.000000
45.390003,63.841393,-243.622162,0.002915,0.002210,0.056144,283.980682,14.466666,0.561444,-243.622162,0.056205,0.000000
45.550003,63.820168,-243.622162,0.002902,0.002210,0.056136,283.886292,14.461857,0.561357,-243.622162,0.056205,0.000000
45.710003,63.802299,-243.711136,0.002889,0.002210,0.056136,283.806793,14.457808,0.561357,-243.711136,0.056205,0.000000
45.870003,63.787025,-243.622162,0.002910,0.002210,0.056136,283.738861,14.454346,0.561357,-243.622162,0.056205,0.000000
46.030003,63.758736,-243.622162,0.002923,0.002210,0.056136,283.613007,14.447936,0.561357,-243.622162,0.056205,0.000000
46.190002,63.738243,-243.711136,0.002902,0.002210,0.056136,283.521851,14.443293,0.561357,-243.711136,0.056205,0.000000
46.350002,63.713676,-243.666656,0.002893,0.002210,0.056136,283.412598,14.437725,0.561357,-243.666656,0.056205,0.000000
46.510002,63.689095,-243.755615,0.002915,0.002210,0.056136,283.303253,14.432155,0.561357,-243.755615,0.056205,0.000000
46.670002,63.689461,-243.755615,0.002889,0.002210,0.056136,283.304871,14.432239,0.561357,-243.755615,0.056205,0.000000
46.830002,63.655952,-243.755615,0.002919,0.002210,0.056136,283.155823,14.424645,0.561357,-243.755615,0.056205,0.000000
46.990002,63.632500,-243.755615,0.002889,0.002210,0.056136,283.051483,14.419331,0.561357,-243.755615,0.056205,0.000000
47.150002,63.621696,-243.755615,0.002906,0.002210,0.056136,283.003448,14.416883,0.561357,-243.755615,0.056205,0.000000
47.310001,63.605690,-243.889053,0.002902,0.002210,0.056136,282.932251,14.413256,0.561357,-243.889053,0.056205,0.000000
47.470001,63.598610,-243.755615,0.002910,0.002210,0.056136,282.900757,14.411652,0.561357,-243.755615,0.056205,0.000000
47.630001,63.567696,-243.755615,0.002910,0.002210,0.056136,282.763245,14.404646,0.561357,-243.755615,0.056205,0.000000
47.790001,63.559883,-243.889053,0.002897,0.002210,0.056136,282.728485,14.402875,0.561357,-243.889053,0.056205,0.000000
47.950001,63.542015,-243.844574,0.002897,0.002210,0.056136,282.648987,14.398826,0.561357,-243.844574,0.056205,0.000000
48.110001,63.521904,-243.844574,0.002902,0.002210,0.056136,282.559540,14.394270,0.561357,-243.844574,0.056205,0.000000
48.270000,63.504768,-243.889053,0.002893,0.002210,0.056136,282.483307,14.390386,0.561357,-243.889053,0.056205,0.000000
48.430004,63.483925,-243.844574,0.002897,0.002210,0.056136,282.390594,14.385663,0.561357,-243.844574,0.056205,0.000000
48.590004,63.482796,-243.978012,0.002906,0.002210,0.056136,282.385590,14.385407,0.561357,-243.978012,0.056205,0.000000
48.750004,63.457848,-243.889053,0.002915,0.002210,0.056136,282.274597,14.379753,0.561357,-243.889053,0.056205,0.000000
48.910004,63.457100,-243.933533,0.002906,0.002210,0.056136,282.271271,14.379584,0.561357,-243.933533,0.056205,0.000000
49.070004,63.420982,-243.978012,0.002897,0.002210,0.056136,282.110626,14.371400,0.561357,-243.978012,0.056205,0.000000
49.230003,63.417641,-243.978012,0.002906,0.002210,0.056136,282.095764,14.370643,0.561357,-243.978012,0.056205,0.000000
49.390003,63.400505,-243.978012,0.002889,0.002210,0.056136,282.019531,14.366759,0.561357,-243.978012,0.056205,0.000000
49.550003,63.387840,-243.978012,0.002915,0.002210,0.056136,281.963196,14.363890,0.561357,-243.978012,0.056205,0.000000
49.710003,63.380775,-244.066986,0.002906,0.002210,0.056136,281.931763,14.362289,0.561357,-244.066986,0.056205,0.000000
49.870003,63.348747,-243.978012,0.002910,0.002210,0.056136,281.789307,14.355031,0.561357,-243.978012,0.056205,0.000000
50.030003,63.342415,-244.066986,0.002910,0.002210,0.056136,281.761139,14.353597,0.561357,-244.066986,0.056205,0.000000
50.190002,63.339058,-244.111465,0.002902,0.002210,0.056136,281.746216,14.352836,0.561357,-244.111465,0.056205,0.000000
50.350002,63.323051,-244.066986,0.002910,0.002210,0.056136,281.674988,14.349209,0.561357,-244.066986,0.056205,0.000000
50.510002,63.300331,-244.111465,0.002919,0.002210,0.056136,281.573944,14.344060,0.561357,-244.111465,0.056205,0.000000
50.670002,63.290657,-244.155945,0.002884,0.002210,0.056136,281.530914,14.341868,0.561357,-244.155945,0.056205,0.000000
50.830002,63.266075,-244.111465,0.002893,0.002210,0.056136,281.421570,14.336298,0.561357,-244.111465,0.056205,0.000000
50.990002,63.267189,-244.155945,0.002902,0.002210,0.056136,281.426514,14.336550,0.561357,-244.155945,0.056205,0.000000
51.150002,63.266457,-244.111465,0.002889,0.002210,0.056136,281.423248,14.336384,0.561357,-244.111465,0.056205,0.000000
51.310001,63.231819,-244.155945,0.002915,0.002210,0.056136,281.269165,14.328535,0.561357,-244.155945,0.056205,0.000000
51.470001,63.234062,-244.155945,0.002893,0.002210,0.056136,281.279144,14.329043,0.561357,-244.155945,0.056205,0.000000
51.630001,63.213951,-244.244904,0.002906,0.002210,0.056136,281.189697,14.324486,0.561357,-244.244904,0.056205,0.000000
51.790001,63.202782,-244.244904,0.002906,0.002210,0.056136,281.140015,14.321956,0.561357,-244.244904,0.056205,0.000000
51.950001,63.188622,-244.200424,0.002915,0.002210,0.056136,281.077026,14.318747,0.561357,-244.200424,0.056205,0.000000
52.110001,63.162193,-244.244904,0.002897,0.002210,0.056136,280.959473,14.312757,0.561357,-244.244904,0.056205,0.000000
52.270004,63.160698,-244.289383,0.002910,0.002210,0.056136,280.952820,14.312419,0.561357,-244.289383,0.056205,0.000000
52.430004,63.145424,-244.289383,0.002915,0.002210,0.056136,280.884888,14.308957,0.561357,-244.289383,0.056205,0.000000
52.590004,63.140221,-244.289383,0.002897,0.002210,0.056136,280.861725,14.307778,0.561357,-244.289383,0.056205,0.000000
52.750004,63.130531,-244.289383,0.002893,0.002210,0.056136,280.818634,14.305583,0.561357,-244.289383,0.056205,0.000000
52.910004,63.121971,-244.333862,0.002902,0.002210,0.056136,280.780548,14.303643,0.561357,-244.333862,0.056205,0.000000
53.070004,63.099998,-244.289383,0.002897,0.002210,0.056136,280.682800,14.298664,0.561357,-244.289383,0.056205,0.000000
53.230003,63.101860,-244.333862,0.002897,0.002210,0.056136,280.691101,14.299087,0.561357,-244.333862,0.056205,0.000000
53.390003,63.078773,-244.422821,0.002902,0.002210,0.056136,280.588409,14.293855,0.561357,-244.422821,0.056205,0.000000
53.550003,63.067238,-244.333862,0.002897,0.002210,0.056136,280.537079,14.291241,0.561357,-244.333862,0.056205,0.000000
53.710003,63.063515,-244.467300,0.002910,0.002210,0.056136,280.520538,14.290397,0.561357,-244.467300,0.056205,0.000000
53.870003,63.032974,-244.422821,0.002897,0.002210,0.056136,280.384674,14.283476,0.561357,-244.422821,0.056205,0.000000
54.030003,63.039680,-244.422821,0.002906,0.002210,0.056136,280.414490,14.284995,0.561357,-244.422821,0.056205,0.000000
54.190002,63.024406,-244.511795,0.002910,0.002210,0.056136,280.346558,14.281535,0.561357,-244.511795,0.056205,0.000000
54.350002,63.005043,-244.467300,0.002910,0.002210,0.056136,280.260437,14.277146,0.561357,-244.467300,0.056205,0.000000
54.510002,63.009514,-244.511795,0.002915,0.002210,0.056136,280.280304,14.278159,0.561357,-244.511795,0.056205,0.000000
54.670002,62.999458,-244.467300,0.002889,0.002210,0.056136,280.235596,14.275881,0.561357,-244.467300,0.056205,0.000000
54.830002,62.990524,-244.511795,0.002915,0.002210,0.056136,280.195831,14.273857,0.561357,-244.511795,0.056205,0.000000
54.990002,62.974884,-244.556274,0.002902,0.002210,0.056136,280.126282,14.270313,0.561357,-244.556274,0.056205,0.000000
55.150002,62.965576,-244.511795,0.002897,0.002210,0.056136,280.084869,14.268203,0.561357,-244.511795,0.056205,0.000000
55.310001,62.952545,-244.556274,0.002919,0.002210,0.056136,280.026917,14.265251,0.561357,-244.556274,0.056205,0.000000
55.470001,62.952911,-244.556274,0.002902,0.002210,0.056136,280.028534,14.265333,0.561357,-244.556274,0.056205,0.000000
55.630001,62.933548,-244.511795,0.002919,0.002210,0.056136,279.942413,14.260946,0.561357,-244.511795,0.056205,0.000000
55.790001,62.928337,-244.645233,0.002906,0.002210,0.056136,279.919220,14.259765,0.561357,-244.645233,0.056205,0.000000
55.950001,62.917542,-244.600754,0.002893,0.002210,0.056136,279.871216,14.257319,0.561357,-244.600754,0.056205,0.000000
56.110004,62.901154,-244.600754,0.002902,0.002210,0.056136,279.798309,14.253605,0.561357,-244.600754,0.056205,0.000000
56.270004,62.909721,-244.645233,0.002897,0.002210,0.056136,279.836426,14.255547,0.561357,-244.645233,0.056205,0.000000
56.430004,62.881050,-244.645233,0.002910,0.002210,0.056136,279.708893,14.249049,0.561357,-244.645233,0.056205,0.000000
56.590004,62.868385,-244.689713,0.002902,0.002210,0.056136,279.652557,14.246180,0.561357,-244.689713,0.056205,0.000000
56.750004,62.875092,-244.689713,0.002902,0.002210,0.056136,279.682373,14.247700,0.561357,-244.689713,0.056205,0.000000
56.910004,62.860191,-244.734192,0.002919,0.002210,0.056136,279.616089,14.244324,0.561357,-244.734192,0.056205,0.000000
57.070004,62.858330,-244.689713,0.002893,0.002210,0.056136,279.607819,14.243901,0.561357,-244.689713,0.056205,0.000000
57.230003,62.858330,-244.689713,0.002906,0.002210,0.056136,279.607819,14.243901,0.561357,-244.689713,0.056205,0.000000
57.390003,62.834869,-244.867630,0.002897,0.002210,0.056136,279.503448,14.238585,0.561357,-244.867630,0.056205,0.000000
57.550003,62.821838,-244.778671,0.002915,0.002210,0.056136,279.445496,14.235632,0.561357,-244.778671,0.056205,0.000000
57.710003,62.828171,-244.823151,0.002893,0.002210,0.056136,279.473663,14.237067,0.561357,-244.823151,0.056205,0.000000
57.870003,62.806198,-244.823151,0.002906,0.002210,0.056136,279.375916,14.232087,0.561357,-244.823151,0.056205,0.000000
58.030003,62.798752,-244.823151,0.002906,0.002210,0.056136,279.342804,14.230401,0.561357,-244.823151,0.056205,0.000000
58.190002,62.796516,-244.867630,0.002915,0.002210,0.056136,279.332855,14.229894,0.561357,-244.867630,0.056205,0.000000
58.350002,62.779388,-244.823151,0.002902,0.002210,0.056136,279.256653,14.226013,0.561357,-244.823151,0.056205,0.000000
58.510002,62.782738,-244.867630,0.002902,0.002210,0.056136,279.271576,14.226772,0.561357,-244.867630,0.056205,0.000000
58.670002,62.758537,-244.912109,0.002884,0.002210,0.056136,279.163910,14.221288,0.561357,-244.912109,0.056205,0.000000
58.830002,62.753693,-244.912109,0.002902,0.002210,0.056136,279.142365,14.220190,0.561357,-244.912109,0.056205,0.000000
58.990002,62.752579,-245.001083,0.002893,0.002210,0.056136,279.137421,14.219938,0.561357,-245.001083,0.056205,0.000000
59.150002,62.745506,-244.867630,0.002906,0.002210,0.056136,279.105957,14.218334,0.561357,-244.867630,0.056205,0.000000
59.310001,62.727257,-245.001083,0.002897,0.002210,0.056136,279.024780,14.214199,0.561357,-245.001083,0.056205,0.000000
59.470001,62.721672,-244.956604,0.002893,0.002210,0.056136,278.999939,14.212934,0.561357,-244.956604,0.056205,0.000000
59.630001,62.716827,-245.001083,0.002906,0.002210,0.056136,278.978394,14.211836,0.561357,-245.001083,0.056205,0.000000
59.790005,62.700073,-245.001083,0.002902,0.002210,0.056136,278.903870,14.208039,0.561357,-245.001083,0.056205,0.000000
59.950005,62.700821,-245.001083,0.002910,0.002210,0.056136,278.907196,14.208209,0.561357,-245.001083,0.056205,0.000000
60.110004,62.683685,-245.001083,0.002915,0.002210,0.056136,278.830963,14.204326,0.561357,-245.001083,0.056205,0.000000
60.270004,62.679222,-245.045563,0.002897,0.002210,0.056136,278.811096,14.203314,0.561357,-245.045563,0.056205,0.000000
60.430004,62.677734,-245.045563,0.002915,0.002210,0.056136,278.804474,14.202977,0.561357,-245.045563,0.056205,0.000000
60.590004,62.653900,-245.090042,0.002902,0.002210,0.056136,278.698456,14.197577,0.561357,-245.090042,0.056205,0.000000
60.750004,62.651291,-245.090042,0.002910,0.002210,0.056136,278.686859,14.196986,0.561357,-245.090042,0.056205,0.000000
60.910004,62.668053,-245.090042,0.002902,0.002210,0.056136,278.761414,14.200784,0.561357,-245.090042,0.056205,0.000000
61.070004,62.631554,-245.090042,0.002893,0.002210,0.056136,278.599060,14.192513,0.561357,-245.090042,0.056205,0.000000
61.230003,62.628204,-245.090042,0.002919,0.002210,0.056136,278.584167,14.191754,0.561357,-245.090042,0.056205,0.000000
61.390003,62.637886,-245.134521,0.002906,0.002210,0.056136,278.627228,14.193948,0.561357,-245.134521,0.056205,0.000000
61.550003,62.607727,-245.134521,0.002910,0.002210,0.056136,278.493073,14.187114,0.561357,-245.134521,0.056205,0.000000
61.710003,62.617783,-245.223480,0.002906,0.002210,0.056136,278.537811,14.189392,0.561357,-245.223480,0.056205,0.000000
61.870003,62.613312,-245.179001,0.002902,0.002210,0.056136,278.517914,14.188379,0.561357,-245.179001,0.056205,0.000000
62.030003,62.592827,-245.134521,0.002906,0.002210,0.056136,278.426788,14.183738,0.561357,-245.134521,0.056205,0.000000
62.190002,62.599159,-245.223480,0.002902,0.002210,0.056136,278.454956,14.185172,0.561357,-245.223480,0.056205,0.000000
62.350002,62.591713,-245.267960,0.002893,0.002210,0.056136,278.421844,14.183485,0.561357,-245.267960,0.056205,0.000000
62.510002,62.578308,-245.312439,0.002915,0.002210,0.056136,278.362213,14.180448,0.561357,-245.312439,0.056205,0.000000
62.670002,62.561920,-245.223480,0.002906,0.002210,0.056136,278.289307,14.176734,0.561357,-245.223480,0.056205,0.000000
62.830002,62.567139,-245.267960,0.002915,0.002210,0.056136,278.312531,14.177917,0.561357,-245.267960,0.056205,0.000000
62.990002,62.541069,-245.356934,0.002910,0.002210,0.056136,278.196564,14.172009,0.561357,-245.356934,0.056205,0.000000
63.150002,62.557457,-245.312439,0.002910,0.002210,0.056136,278.269470,14.175722,0.561357,-245.312439,0.056205,0.000000
63.310001,62.539207,-245.312439,0.002910,0.002210,0.056136,278.188293,14.171587,0.561357,-245.312439,0.056205,0.000000
63.470001,62.519470,-245.401413,0.002893,0.002210,0.056136,278.100494,14.167114,0.561357,-245.401413,0.056205,0.000000
63.630005,62.523941,-245.356934,0.002915,0.002210,0.056136,278.120392,14.168127,0.561357,-245.356934,0.056205,0.000000
63.790005,62.509422,-245.356934,0.002889,0.002210,0.056136,278.055786,14.164837,0.561357,-245.356934,0.056205,0.000000
63.950005,62.496758,-245.401413,0.002889,0.002210,0.056136,277.999451,14.161967,0.561357,-245.401413,0.056205,0.000000
64.110001,62.505692,-245.445892,0.002897,0.002210,0.056136,278.039215,14.163992,0.561357,-245.445892,0.056205,0.000000
64.270004,62.490425,-245.401413,0.002902,0.002210,0.056136,277.971283,14.160532,0.561357,-245.401413,0.056205,0.000000
64.430000,62.468826,-245.401413,0.002915,0.002210,0.056136,277.875214,14.155638,0.561357,-245.401413,0.056205,0.000000
64.590004,62.477768,-245.490372,0.002897,0.002210,0.056136,277.914978,14.157664,0.561357,-245.490372,0.056205,0.000000
64.750000,62.462875,-245.401413,0.002906,0.002210,0.056136,277.848755,14.154290,0.561357,-245.401413,0.056205,0.000000
64.910004,62.443878,-245.490372,0.002902,0.002210,0.056136,277.764252,14.149985,0.561357,-245.490372,0.056205,0.000000
65.070000,62.459892,-245.445892,0.002902,0.002210,0.056136,277.835480,14.153614,0.561357,-245.445892,0.056205,0.000000
65.230003,62.443138,-245.490372,0.002893,0.002210,0.056136,277.760956,14.149817,0.561357,-245.490372,0.056205,0.000000
65.389999,62.430473,-245.534851,0.002910,0.002210,0.056136,277.704620,14.146948,0.561357,-245.534851,0.056205,0.000000
65.550003,62.428612,-245.534851,0.002906,0.002210,0.056136,277.696320,14.146525,0.561357,-245.534851,0.056205,0.000000
65.710007,62.428986,-245.579330,0.002910,0.002210,0.056136,277.697998,14.146610,0.561357,-245.579330,0.056205,0.000000
65.870003,62.408508,-245.668289,0.002910,0.002210,0.056136,277.606903,14.141971,0.561357,-245.668289,0.056205,0.000000
66.030006,62.415581,-245.579330,0.002902,0.002210,0.056136,277.638367,14.143573,0.561357,-245.579330,0.056205,0.000000
66.190002,62.407013,-245.623810,0.002915,0.002210,0.056136,277.600250,14.141631,0.561357,-245.623810,0.056205,0.000000
66.350006,62.391380,-245.579330,0.002906,0.002210,0.056136,277.530731,14.138088,0.561357,-245.579330,0.056205,0.000000
66.510002,62.399193,-245.668289,0.002906,0.002210,0.056136,277.565460,14.139859,0.561357,-245.668289,0.056205,0.000000
66.670006,62.386536,-245.668289,0.002902,0.002210,0.056136,277.509155,14.136992,0.561357,-245.668289,0.056205,0.000000
66.830002,62.375366,-245.623810,0.002923,0.002210,0.056136,277.459473,14.134460,0.561357,-245.623810,0.056205,0.000000
66.990005,62.380951,-245.668289,0.002902,0.002210,0.056136,277.484314,14.135726,0.561357,-245.668289,0.056205,0.000000
67.150002,62.363449,-245.712769,0.002897,0.002210,0.056136,277.406464,14.131760,0.561357,-245.712769,0.056205,0.000000
67.310005,62.359726,-245.712769,0.002910,0.002210,0.056136,277.389923,14.130916,0.561357,-245.712769,0.056205,0.000000
67.470001,62.360466,-245.757248,0.002906,0.002210,0.056136,277.393219,14.131083,0.561357,-245.757248,0.056205,0.000000
67.630005,62.337753,-245.668289,0.002923,0.002210,0.056136,277.292175,14.125937,0.561357,-245.668289,0.056205,0.000000
67.790001,62.349297,-245.801743,0.002906,0.002210,0.056136,277.343536,14.128552,0.561357,-245.801743,0.056205,0.000000
67.900002,62.339989,-245.757248,0.002906,0.002210,0.056136,277.302124,14.126444,0.561357,-245.757248,0.056205,0.000000