File: Data/AG AL compression 300N/AL membrane Unpeeled 300N_1_1_03192024_181607.csv
Time (sec),S:Load (lbs),S:HL1 (DIM),S:LVDT (in),S:Position (in),Ch:Position (mm),Ch:Load (N),Ch:Stress (MPa),Ch:Strain (mm/mm),Ch:HL1 (DIM),Set Point (),Cycles ()
0.010000,-0.000374,-211.907257,0.000004,-0.000000,-0.000000,-0.001663,-0.000085,-0.000000,-211.907257,0.000173,0.000000
0.200000,-0.002975,-212.040695,-0.000013,-0.000000,-0.000000,-0.013236,-0.000674,-0.000000,-212.040695,0.000173,0.000000
0.390000,-0.020851,-211.951736,-0.000009,0.000032,0.000815,-0.092750,-0.004725,0.008153,-211.951736,0.001318,0.000000
0.580000,0.013779,-212.085175,-0.000009,0.000141,0.003582,0.061291,0.003122,0.035816,-212.085175,0.004475,0.000000
0.770000,0.013405,-212.040695,0.000095,0.000262,0.006652,0.059628,0.003038,0.066516,-212.040695,0.007649,0.000000
0.960000,-0.005959,-211.996216,0.000224,0.000388,0.009843,-0.026505,-0.001350,0.098430,-211.996216,0.010805,0.000000
1.150000,-0.006699,-212.085175,0.000358,0.000513,0.013034,-0.029797,-0.001518,0.130344,-212.085175,0.013980,0.000000
1.340000,-0.004463,-212.085175,0.000470,0.000637,0.016174,-0.019853,-0.001011,0.161736,-212.085175,0.017136,0.000000
1.530000,-0.020103,-212.129654,0.000569,0.000752,0.019096,-0.089425,-0.004556,0.190963,-212.129654,0.020311,0.000000
1.720000,-0.012283,-212.129654,0.000716,0.000878,0.022314,-0.054639,-0.002783,0.223138,-212.129654,0.023467,0.000000
1.910000,0.011917,-212.174133,0.000841,0.001001,0.025427,0.053010,0.002700,0.254269,-212.174133,0.026641,0.000000
2.100000,0.019363,-212.263092,0.000974,0.001127,0.028627,0.086133,0.004388,0.286271,-212.263092,0.029798,0.000000
2.290000,0.036491,-212.174133,0.001095,0.001259,0.031975,0.162322,0.008269,0.319748,-212.174133,0.032972,0.000000
2.480000,0.027931,-212.218613,0.001207,0.001384,0.035149,0.124244,0.006329,0.351488,-212.218613,0.036129,0.000000
2.670000,0.020111,-212.263092,0.001345,0.001507,0.038288,0.089459,0.004557,0.382880,-212.263092,0.039303,0.000000
2.860000,0.026070,-212.263092,0.001487,0.001625,0.041271,0.115964,0.005907,0.412713,-212.263092,0.042459,0.000000
3.050000,0.018250,-212.396545,0.001595,0.001748,0.044393,0.081178,0.004135,0.443934,-212.396545,0.045633,0.000000
3.240000,0.037239,-212.307587,0.001720,0.001874,0.047602,0.165648,0.008438,0.476019,-212.307587,0.048790,0.000000
3.430000,0.020485,-212.352066,0.001854,0.001998,0.050750,0.091121,0.004642,0.507501,-212.352066,0.051964,0.000000
3.620000,0.030540,-212.307587,0.001962,0.002120,0.053837,0.135851,0.006921,0.538375,-212.307587,0.055121,0.000000
3.810000,0.010803,-212.396545,0.002074,0.002245,0.057020,0.048055,0.002448,0.570202,-212.396545,0.058295,0.000000
4.000000,0.036491,-212.441025,0.002203,0.002373,0.060281,0.162322,0.008269,0.602809,-212.441025,0.061452,0.000000
4.190000,0.037613,-212.441025,0.002350,0.002499,0.063464,0.167311,0.008523,0.634636,-212.441025,0.064626,0.000000
4.380000,0.024582,-212.396545,0.002479,0.002624,0.066638,0.109346,0.005570,0.666376,-212.396545,0.067782,0.000000
4.570000,0.020485,-212.485504,0.002587,0.002753,0.069933,0.091121,0.004642,0.699331,-212.485504,0.070957,0.000000
4.760000,0.023834,-212.441025,0.002716,0.002877,0.073072,0.106020,0.005401,0.730723,-212.441025,0.074113,0.000000
4.950000,0.023460,-212.574463,0.002837,0.003003,0.076264,0.104357,0.005316,0.762637,-212.574463,0.077287,0.000000
5.140000,0.017876,-212.485504,0.002984,0.003125,0.079377,0.079515,0.004051,0.793772,-212.485504,0.080444,0.000000
5.330000,0.025322,-212.529984,0.003087,0.003250,0.082551,0.112638,0.005738,0.825512,-212.529984,0.083618,0.000000
5.520000,0.009682,-212.618942,0.003199,0.003369,0.085569,0.043066,0.002194,0.855693,-212.618942,0.086775,0.000000
5.710000,0.003357,-212.618942,0.003346,0.003493,0.088735,0.014932,0.000761,0.887346,-212.618942,0.089949,0.000000
5.900000,-0.023087,-212.707901,0.003484,0.003620,0.091960,-0.102694,-0.005231,0.919605,-212.707901,0.093105,0.000000
6.090000,-0.002602,-212.663422,0.003579,0.003744,0.095109,-0.011573,-0.000590,0.951087,-212.663422,0.096279,0.000000
6.280000,0.032028,-212.663422,0.003708,0.003871,0.098326,0.142469,0.007258,0.983259,-212.663422,0.099436,0.000000
6.470000,0.014153,-212.707901,0.003837,0.003995,0.101483,0.062954,0.003207,1.014829,-212.707901,0.102610,0.000000
6.660000,0.014900,-212.618942,0.003958,0.004123,0.104717,0.066279,0.003376,1.047174,-212.618942,0.105767,0.000000
6.850000,0.030540,-212.796875,0.004074,0.004246,0.107848,0.135851,0.006921,1.078483,-212.796875,0.108941,0.000000
7.040000,0.037239,-212.796875,0.004217,0.004369,0.110970,0.165648,0.008438,1.109701,-212.796875,0.112098,0.000000
7.230000,0.001495,-212.707901,0.004333,0.004493,0.114127,0.006652,0.000339,1.141271,-212.707901,0.115272,0.000000
7.420001,0.016762,-212.796875,0.004454,0.004617,0.117275,0.074560,0.003798,1.172750,-212.796875,0.118428,0.000000
7.610000,-0.001114,-212.841354,0.004557,0.004742,0.120449,-0.004955,-0.000252,1.204490,-212.841354,0.121602,0.000000
7.800000,-0.010796,-212.841354,0.004700,0.004865,0.123571,-0.048021,-0.002446,1.235711,-212.841354,0.124759,0.000000
7.990000,-0.025322,-212.930313,0.004833,0.004991,0.126780,-0.112638,-0.005738,1.267796,-212.930313,0.127933,0.000000
8.180000,-0.020103,-212.885834,0.004950,0.005117,0.129971,-0.089425,-0.004556,1.299710,-212.885834,0.131090,0.000000
8.370001,0.024582,-212.930313,0.005049,0.005243,0.133171,0.109346,0.005570,1.331712,-212.930313,0.134264,0.000000
8.560000,0.016388,-212.885834,0.005234,0.005368,0.136354,0.072897,0.003714,1.363539,-212.885834,0.137420,0.000000
8.750000,0.013039,-212.974792,0.005325,0.005491,0.139467,0.057999,0.002955,1.394673,-212.974792,0.140594,0.000000
8.940001,0.032768,-213.019272,0.005471,0.005617,0.142684,0.145760,0.007425,1.426845,-213.019272,0.143751,0.000000
9.130000,0.037239,-213.019272,0.005605,0.005745,0.145911,0.165648,0.008438,1.459107,-213.019272,0.146925,0.000000
9.320001,0.020485,-213.019272,0.005721,0.005869,0.149076,0.091121,0.004642,1.490760,-213.019272,0.150082,0.000000
9.510000,0.023460,-213.019272,0.005855,0.005993,0.152224,0.104357,0.005316,1.522239,-213.019272,0.153256,0.000000
9.700001,0.037239,-213.063751,0.005984,0.006118,0.155390,0.165648,0.008438,1.553896,-213.063751,0.156413,0.000000
9.890000,0.025696,-213.063751,0.006096,0.006244,0.158589,0.114301,0.005823,1.585894,-213.063751,0.159587,0.000000
10.080001,0.030540,-213.108231,0.006230,0.006369,0.161772,0.135851,0.006921,1.617721,-213.108231,0.162744,0.000000
10.270000,0.017128,-213.152710,0.006355,0.006494,0.164955,0.076189,0.003881,1.649548,-213.152710,0.165918,0.000000
10.460000,0.059586,-213.152710,0.006497,0.006614,0.168008,0.265050,0.013502,1.680077,-213.152710,0.169074,0.000000
10.650001,0.052132,-213.152710,0.006592,0.006740,0.171208,0.231893,0.011813,1.712078,-213.152710,0.172248,0.000000
10.840000,0.062561,-213.197205,0.006735,0.006869,0.174469,0.278285,0.014177,1.744685,-213.197205,0.175405,0.000000
11.030001,0.071495,-213.241684,0.006847,0.006993,0.177616,0.318026,0.016201,1.776164,-213.241684,0.178579,0.000000
11.220000,0.063675,-213.241684,0.007006,0.007116,0.180756,0.283240,0.014429,1.807560,-213.241684,0.181736,0.000000
11.410001,0.048035,-213.241684,0.007110,0.007235,0.183774,0.213669,0.010885,1.837737,-213.241684,0.184910,0.000000
11.600000,0.058464,-213.241684,0.007239,0.007363,0.187026,0.260061,0.013248,1.870260,-213.241684,0.188067,0.000000
11.790001,0.048409,-213.375122,0.007364,0.007486,0.190139,0.215332,0.010970,1.901391,-213.375122,0.191241,0.000000
11.980000,0.035004,-213.241684,0.007485,0.007607,0.193209,0.155704,0.007932,1.932091,-213.241684,0.194397,0.000000
12.170001,0.055489,-213.330643,0.007593,0.007727,0.196253,0.246826,0.012574,1.962532,-213.330643,0.197572,0.000000
12.360001,0.067398,-213.241684,0.007739,0.007852,0.199436,0.299802,0.015273,1.994360,-213.241684,0.200728,0.000000
12.550000,0.099426,-213.330643,0.007830,0.007977,0.202627,0.442270,0.022530,2.026274,-213.330643,0.203902,0.000000
12.740001,0.121025,-213.375122,0.007972,0.008104,0.205845,0.538346,0.027425,2.058445,-213.375122,0.207059,0.000000
12.930000,0.191772,-213.375122,0.008088,0.008234,0.209149,0.853047,0.043456,2.091488,-213.375122,0.210233,0.000000
13.120001,0.390617,-213.464081,0.008209,0.008358,0.212297,1.737553,0.088515,2.122970,-213.464081,0.213390,0.000000
13.310000,0.701927,-213.464081,0.008334,-0.000002,-0.000052,3.122328,0.159059,-0.000519,-213.464081,0.001292,0.000000
13.500001,0.578300,-213.464081,0.008334,-0.000002,-0.000061,2.572409,0.131045,-0.000606,-213.464081,0.000165,0.000000
13.690001,0.577553,-213.553040,0.008343,-0.000002,-0.000061,2.569083,0.130875,-0.000606,-213.553040,0.000165,0.000000
13.880001,0.567871,-213.508560,0.008334,-0.000002,-0.000061,2.526017,0.128681,-0.000606,-213.508560,0.000243,0.000000
14.070001,0.662079,-213.553040,0.008334,-0.000002,-0.000061,2.945074,0.150029,-0.000606,-213.553040,0.000555,0.000000
14.260000,0.665802,-213.597534,0.008338,-0.000002,-0.000061,2.961635,0.150873,-0.000606,-213.597534,0.000876,0.000000
14.450001,0.688522,-213.597534,0.008317,0.000014,0.000347,3.062700,0.156021,0.003471,-213.597534,0.001188,0.000000
14.640000,0.762993,-213.642014,0.008338,0.000021,0.000529,3.393962,0.172897,0.005291,-213.642014,0.001509,0.000000
14.830001,0.819969,-213.597534,0.008330,0.000034,0.000867,3.647405,0.185808,0.008671,-213.597534,0.001821,0.000000
15.020000,0.891090,-213.642014,0.008326,0.000048,0.001232,3.963768,0.201924,0.012316,-213.642014,0.002142,0.000000
15.210001,0.962212,-213.642014,0.008369,0.000065,0.001656,4.280131,0.218040,0.016563,-213.642014,0.002454,0.000000
15.400001,1.013229,-213.686493,0.008390,0.000074,0.001882,4.507069,0.229601,0.018818,-213.686493,0.002775,0.000000
15.590001,1.076904,-213.775452,0.008382,0.000088,0.002246,4.790309,0.244030,0.022460,-213.775452,0.003087,0.000000
15.780001,1.149887,-213.730972,0.008399,0.000098,0.002498,5.114953,0.260568,0.024977,-213.730972,0.003408,0.000000
15.970001,1.201645,-213.864410,0.008403,0.000110,0.002792,5.345183,0.272297,0.027925,-213.864410,0.003721,0.000000
16.160000,1.320435,-213.775452,0.008412,0.000124,0.003148,5.873586,0.299215,0.031479,-213.775452,0.004041,0.000000
16.350000,1.393791,-213.819931,0.008433,0.000138,0.003495,6.199893,0.315838,0.034950,-213.819931,0.004353,0.000000
16.540001,1.455978,-213.819931,0.008446,0.000149,0.003772,6.476515,0.329929,0.037724,-213.819931,0.004674,0.000000
16.730001,1.519653,-213.819931,0.008455,0.000159,0.004033,6.759756,0.344358,0.040328,-213.819931,0.004987,0.000000
16.920000,1.640305,-213.908890,0.008472,0.000172,0.004371,7.296439,0.371698,0.043708,-213.908890,0.005308,0.000000
17.110001,1.739723,-213.953369,0.008472,0.000186,0.004718,7.738675,0.394227,0.047179,-213.953369,0.005628,0.000000
17.300001,1.861496,-213.908890,0.008494,0.000200,0.005091,8.280348,0.421821,0.050907,-213.908890,0.005940,0.000000
17.490002,1.929260,-213.953369,0.008502,0.000213,0.005420,8.581779,0.437177,0.054203,-213.953369,0.006261,0.000000
17.680000,2.019379,-213.908890,0.008528,0.000223,0.005663,8.982645,0.457598,0.056630,-213.908890,0.006574,0.000000
17.870001,2.138908,-213.997849,0.008524,0.000236,0.005984,9.514339,0.484684,0.059839,-213.997849,0.006895,0.000000
18.060001,2.200722,-214.042343,0.008524,0.000244,0.006201,9.789299,0.498691,0.062008,-214.042343,0.007207,0.000000
18.250000,2.391754,-213.908890,0.008554,0.000262,0.006643,10.639053,0.541979,0.066429,-213.908890,0.007527,0.000000
18.440001,2.491920,-214.086823,0.008571,0.000271,0.006877,11.084616,0.564677,0.068772,-214.086823,0.007840,0.000000
18.630001,2.525429,-213.997849,0.008563,0.000275,0.006981,11.233668,0.572270,0.069812,-213.997849,0.008161,0.000000
18.820002,2.821098,-214.042343,0.008563,0.000301,0.007640,12.548872,0.639270,0.076402,-214.042343,0.008473,0.000000
19.010000,2.926102,-214.131302,0.008614,0.000312,0.007926,13.015950,0.663064,0.079263,-214.131302,0.008794,0.000000
19.200001,3.060158,-214.131302,0.008606,0.000322,0.008169,13.612262,0.693442,0.081693,-214.131302,0.009106,0.000000
19.390001,3.224373,-214.175781,0.008632,0.000339,0.008603,14.342727,0.730653,0.086031,-214.175781,0.009427,0.000000
19.580002,3.355453,-214.131302,0.008623,0.000348,0.008828,14.925802,0.760357,0.088283,-214.131302,0.009739,0.000000
19.770000,3.445564,-214.220261,0.008640,0.000356,0.009045,15.326635,0.780776,0.090451,-214.220261,0.010060,0.000000
19.960001,3.605682,-214.309219,0.008645,0.000368,0.009340,16.038876,0.817059,0.093400,-214.309219,0.010372,0.000000
20.150002,3.893898,-214.175781,0.008670,0.000386,0.009817,17.320923,0.882370,0.098169,-214.175781,0.010693,0.000000
20.340000,3.987740,-214.264740,0.008666,0.000395,0.010042,17.738352,0.903635,0.100425,-214.264740,0.011005,0.000000
20.530001,4.115089,-214.264740,0.008688,0.000406,0.010320,18.304832,0.932493,0.103199,-214.264740,0.011326,0.000000
20.720001,4.342613,-214.353699,0.008683,0.000421,0.010693,19.316908,0.984050,0.106931,-214.353699,0.011638,0.000000
20.910002,4.575340,-214.309219,0.008714,0.000436,0.011075,20.352131,1.036787,0.110746,-214.309219,0.011959,0.000000
21.100000,4.796532,-214.353699,0.008739,0.000449,0.011413,21.336039,1.086910,0.114126,-214.353699,0.012271,0.000000
21.290001,4.939148,-214.309219,0.008735,0.000460,0.011690,21.970427,1.119227,0.116904,-214.309219,0.012592,0.000000
21.480001,5.127945,-214.353699,0.008739,0.000472,0.011994,22.810238,1.162009,0.119936,-214.353699,0.012904,0.000000
21.670000,5.264977,-214.398178,0.008744,0.000482,0.012245,23.419785,1.193061,0.122453,-214.398178,0.013225,0.000000
21.860001,5.408340,-214.442657,0.008761,0.000491,0.012480,24.057499,1.225548,0.124796,-214.442657,0.013537,0.000000
22.050001,5.774384,-214.353699,0.008783,0.000508,0.012896,25.685741,1.308494,0.128955,-214.353699,0.013858,0.000000
22.240002,6.017914,-214.398178,0.008783,0.000521,0.013225,26.769018,1.363679,0.132252,-214.398178,0.014171,0.000000
22.430000,6.081963,-214.531631,0.008813,0.000529,0.013442,27.053921,1.378192,0.134421,-214.531631,0.014491,0.000000
22.620001,6.398849,-214.487152,0.008787,0.000544,0.013815,28.463505,1.450000,0.138149,-214.487152,0.014812,0.000000
22.810001,6.688553,-214.620590,0.008821,0.000559,0.014196,29.752169,1.515648,0.141964,-214.620590,0.015124,0.000000
23.000002,7.000229,-214.487152,0.008852,0.000575,0.014604,31.138573,1.586275,0.146040,-214.487152,0.015445,0.000000
23.190001,7.187904,-214.665070,0.008839,0.000586,0.014881,31.973396,1.628802,0.148814,-214.665070,0.015758,0.000000
23.380001,7.309303,-214.620590,0.008852,0.000595,0.015124,32.513405,1.656312,0.151244,-214.620590,0.016078,0.000000
23.570002,7.492508,-214.531631,0.008860,0.000606,0.015384,33.328339,1.697827,0.153845,-214.531631,0.016390,0.000000
23.760000,7.776627,-214.620590,0.008864,0.000618,0.015697,34.592163,1.762209,0.156967,-214.620590,0.016711,0.000000
23.950001,8.214539,-214.620590,0.008890,0.000634,0.016113,36.540092,1.861441,0.161131,-214.620590,0.017024,0.000000
24.140001,8.489723,-214.709549,0.008873,0.000646,0.016408,37.764175,1.923799,0.164079,-214.709549,0.017345,0.000000
24.330002,8.588028,-214.620590,0.008899,0.000654,0.016616,38.201458,1.946075,0.166161,-214.620590,0.017657,0.000000
24.520000,8.755226,-214.665070,0.008903,0.000664,0.016876,38.945190,1.983963,0.168761,-214.665070,0.017977,0.000000
24.710001,8.963005,-214.754028,0.008933,0.000676,0.017171,39.869438,2.031046,0.171709,-214.754028,0.018290,0.000000
24.900002,9.634026,-214.754028,0.008942,0.000700,0.017769,42.854286,2.183101,0.177693,-214.754028,0.018611,0.000000
25.090002,9.839569,-214.754028,0.008959,0.000712,0.018082,43.768589,2.229678,0.180816,-214.754028,0.018923,0.000000
25.280001,9.885002,-214.842987,0.008955,0.000719,0.018272,43.970684,2.239973,0.182723,-214.842987,0.019244,0.000000
25.470001,10.182152,-214.754028,0.008959,0.000732,0.018593,45.292473,2.307308,0.185933,-214.754028,0.019556,0.000000
25.660002,10.553040,-214.887482,0.008968,0.000746,0.018940,46.942265,2.391353,0.189404,-214.887482,0.019877,0.000000
25.850000,10.640549,-214.798508,0.008994,0.000755,0.019183,47.331524,2.411183,0.191830,-214.798508,0.020189,0.000000
26.040001,11.117180,-214.842987,0.009007,0.000769,0.019521,49.451687,2.519189,0.195214,-214.842987,0.020510,0.000000
26.230001,11.266129,-214.931961,0.009011,0.000777,0.019738,50.114243,2.552941,0.197382,-214.931961,0.020822,0.000000
26.420002,11.377472,-214.887482,0.009002,0.000785,0.019938,50.609524,2.578172,0.199377,-214.887482,0.021143,0.000000
26.610001,12.033966,-214.976440,0.009015,0.000807,0.020501,53.529755,2.726936,0.205013,-214.976440,0.021455,0.000000
26.800001,12.451393,-214.931961,0.009050,0.000825,0.020961,55.386562,2.821526,0.209607,-214.931961,0.021776,0.000000
26.990002,12.662903,-215.020920,0.009058,0.000838,0.021273,56.327404,2.869455,0.212730,-215.020920,0.022088,0.000000
27.180002,12.850578,-215.065399,0.009054,0.000848,0.021533,57.162228,2.911983,0.215334,-215.065399,0.022409,0.000000
27.370001,13.062080,-215.020920,0.009071,0.000858,0.021793,58.103035,2.959910,0.217934,-215.020920,0.022721,0.000000
27.560001,13.109001,-215.065399,0.009093,0.000864,0.021958,58.311749,2.970542,0.219581,-215.065399,0.023042,0.000000
27.750002,13.648941,-215.065399,0.009115,0.000883,0.022427,60.713524,3.092894,0.224266,-215.065399,0.023354,0.000000
27.940001,14.075310,-215.065399,0.009097,0.000896,0.022747,62.610104,3.189511,0.227472,-215.065399,0.023675,0.000000
28.130001,14.246231,-215.109879,0.009132,0.000906,0.023025,63.370399,3.228242,0.230250,-215.109879,0.023996,0.000000
28.320002,14.386986,-215.109879,0.009132,0.000913,0.023198,63.996510,3.260138,0.231984,-215.109879,0.024308,0.000000
28.510002,14.595139,-215.243317,0.009145,0.000923,0.023450,64.922417,3.307306,0.234497,-215.243317,0.024629,0.000000
28.700001,15.281052,-215.198837,0.009136,0.000945,0.024005,67.973511,3.462736,0.240049,-215.198837,0.024941,0.000000
28.890001,15.536499,-215.198837,0.009158,0.000958,0.024326,69.109802,3.520621,0.243255,-215.198837,0.025262,0.000000
29.080002,15.705559,-215.243317,0.009184,0.000969,0.024612,69.861816,3.558930,0.246120,-215.243317,0.025575,0.000000
29.270000,15.949829,-215.243317,0.009188,0.000980,0.024898,70.948380,3.614283,0.248982,-215.243317,0.025895,0.000000
29.460001,16.209373,-215.332291,0.009188,0.000992,0.025193,72.102898,3.673097,0.251930,-215.332291,0.026208,0.000000
29.650002,16.635742,-215.287796,0.009214,0.001007,0.025566,73.999474,3.769713,0.255658,-215.287796,0.026528,0.000000
29.840002,17.056152,-215.332291,0.009201,0.001022,0.025965,75.869553,3.864979,0.259648,-215.332291,0.026841,0.000000
30.030001,17.149612,-215.376770,0.009227,0.001030,0.026164,76.285286,3.886158,0.261642,-215.376770,0.027162,0.000000
30.220001,17.360008,-215.332291,0.009231,0.001040,0.026407,77.221176,3.933834,0.264072,-215.332291,0.027474,0.000000
30.410002,17.707802,-215.376770,0.009227,0.001057,0.026841,78.768234,4.012645,0.268406,-215.376770,0.027795,0.000000
30.600002,18.304344,-215.421249,0.009261,0.001071,0.027213,81.421791,4.147823,0.272134,-215.421249,0.028107,0.000000
30.790001,18.509521,-215.465729,0.009270,0.001082,0.027483,82.334465,4.194318,0.274825,-215.465729,0.028428,0.000000
30.980001,18.828644,-215.465729,0.009283,0.001097,0.027855,83.753990,4.266632,0.278553,-215.465729,0.028740,0.000000
31.170002,19.078506,-215.376770,0.009291,0.001108,0.028133,84.865433,4.323251,0.281327,-215.376770,0.029061,0.000000
31.360001,19.380501,-215.510208,0.009287,0.001120,0.028436,86.208771,4.391684,0.284363,-215.510208,0.029373,0.000000
31.550001,19.371193,-215.554687,0.009304,0.001130,0.028697,86.167366,4.389575,0.286967,-215.554687,0.029694,0.000000
31.740002,20.114449,-215.510208,0.009309,0.001145,0.029096,89.473534,4.558000,0.290956,-215.510208,0.030006,0.000000
31.930002,20.245522,-215.599167,0.009326,0.001156,0.029356,90.056580,4.587701,0.293556,-215.599167,0.030327,0.000000
32.120003,20.737801,-215.554687,0.009343,0.001170,0.029728,92.246346,4.699253,0.297285,-215.554687,0.030639,0.000000
32.310001,21.363754,-215.599167,0.009356,0.001187,0.030162,95.030724,4.841096,0.301622,-215.599167,0.030960,0.000000
32.500000,21.576004,-215.643646,0.009369,0.001200,0.030491,95.974861,4.889192,0.304915,-215.643646,0.031272,0.000000
32.690002,21.992317,-215.643646,0.009373,0.001214,0.030847,97.826714,4.983531,0.308473,-215.643646,0.031593,0.000000
32.880001,22.118927,-215.688126,0.009373,0.001223,0.031073,98.389900,5.012220,0.310729,-215.688126,0.031905,0.000000
33.070000,22.223190,-215.643646,0.009403,0.001233,0.031307,98.853691,5.035847,0.313068,-215.643646,0.032226,0.000000
33.260002,22.708763,-215.732620,0.009403,0.001247,0.031680,101.013626,5.145879,0.316799,-215.732620,0.032538,0.000000
33.450001,23.132523,-215.732620,0.009408,0.001260,0.031992,102.898598,5.241904,0.319918,-215.732620,0.032859,0.000000
33.640003,23.625549,-215.732620,0.009429,0.001274,0.032348,105.091690,5.353626,0.323476,-215.732620,0.033180,0.000000
33.830002,23.860886,-215.732620,0.009429,0.001284,0.032608,106.138519,5.406954,0.326076,-215.732620,0.033492,0.000000
34.020000,24.080956,-215.821579,0.009447,0.001293,0.032833,107.117439,5.456823,0.328332,-215.821579,0.033813,0.000000
34.210003,24.642868,-215.821579,0.009451,0.001307,0.033197,109.616951,5.584154,0.331973,-215.821579,0.034125,0.000000
34.400002,25.252068,-215.821579,0.009464,0.001324,0.033631,112.326805,5.722200,0.336311,-215.821579,0.034446,0.000000
34.590000,25.565605,-215.866058,0.009464,0.001336,0.033943,113.721489,5.793249,0.339433,-215.866058,0.034759,0.000000
34.780003,25.839302,-215.910538,0.009477,0.001348,0.034229,114.938957,5.855269,0.342295,-215.910538,0.035079,0.000000
34.970001,26.091393,-215.910538,0.009490,0.001358,0.034489,116.060310,5.912394,0.344895,-215.910538,0.035391,0.000000
35.160000,26.361740,-215.910538,0.009498,0.001367,0.034724,117.262878,5.973656,0.347238,-215.910538,0.035712,0.000000
35.350002,26.963120,-215.955017,0.009498,0.001381,0.035088,119.937943,6.109931,0.350879,-215.955017,0.036025,0.000000
35.540001,27.278145,-215.910538,0.009503,0.001393,0.035383,121.339249,6.181316,0.353827,-215.910538,0.036346,0.000000
35.730003,27.827393,-215.999496,0.009533,0.001408,0.035764,123.782425,6.305777,0.357642,-215.999496,0.036657,0.000000
35.920002,28.328239,-215.955017,0.009520,0.001419,0.036042,126.010300,6.419271,0.360420,-215.955017,0.036978,0.000000
36.110001,28.776573,-216.043976,0.009541,0.001433,0.036397,128.004593,6.520865,0.363974,-216.043976,0.037291,0.000000
36.300003,29.319496,-216.043976,0.009550,0.001448,0.036779,130.419632,6.643893,0.367790,-216.043976,0.037612,0.000000
36.490002,29.752563,-216.088455,0.009563,0.001460,0.037083,132.346008,6.742027,0.370825,-216.088455,0.037924,0.000000
36.680000,29.997208,-216.177429,0.009567,0.001470,0.037343,133.434250,6.797464,0.373429,-216.177429,0.038245,0.000000
36.870003,30.397141,-216.132935,0.009585,0.001482,0.037655,135.213242,6.888091,0.376548,-216.132935,0.038557,0.000000
37.060001,30.852180,-216.132935,0.009585,0.001494,0.037941,137.237350,6.991204,0.379413,-216.132935,0.038878,0.000000
37.250000,31.212265,-216.132935,0.009606,0.001504,0.038201,138.839096,7.072801,0.382013,-216.132935,0.039190,0.000000
37.440002,31.842690,-216.177429,0.009597,0.001521,0.038635,141.643356,7.215657,0.386351,-216.177429,0.039511,0.000000
37.630001,32.414650,-216.310867,0.009593,0.001534,0.038956,144.187561,7.345264,0.389557,-216.310867,0.039823,0.000000
37.820004,32.915497,-216.221909,0.009628,0.001542,0.039173,146.415436,7.458758,0.391725,-216.221909,0.040144,0.000000
38.010002,32.940071,-216.221909,0.009623,0.001548,0.039320,146.524750,7.464327,0.393201,-216.221909,0.040456,0.000000
38.200001,33.771202,-216.266388,0.009641,0.001566,0.039788,150.221817,7.652664,0.397883,-216.266388,0.040777,0.000000
38.390003,34.436638,-216.266388,0.009658,0.001580,0.040144,153.181808,7.803454,0.401437,-216.266388,0.041089,0.000000
38.580002,35.182121,-216.355347,0.009641,0.001595,0.040526,156.497894,7.972383,0.405256,-216.355347,0.041410,0.000000
38.770000,35.462151,-216.310867,0.009662,0.001607,0.040820,157.743530,8.035838,0.408205,-216.310867,0.041731,0.000000
38.960003,36.003204,-216.399826,0.009675,0.001618,0.041089,160.150253,8.158442,0.410892,-216.399826,0.042043,0.000000
39.150002,36.315254,-216.444305,0.009666,0.001629,0.041367,161.538315,8.229155,0.413666,-216.444305,0.042364,0.000000
39.340000,36.849236,-216.399826,0.009688,0.001640,0.041661,163.913589,8.350156,0.416615,-216.399826,0.042676,0.000000
39.530003,37.510201,-216.399826,0.009692,0.001655,0.042043,166.853699,8.499933,0.420430,-216.399826,0.042997,0.000000
39.720001,38.127220,-216.444305,0.009718,0.001665,0.042303,169.598343,8.639751,0.423034,-216.444305,0.043309,0.000000
39.910004,38.346542,-216.444305,0.009710,0.001673,0.042485,170.573944,8.689450,0.424854,-216.444305,0.043630,0.000000
40.100002,39.369080,-216.488785,0.009722,0.001692,0.042980,175.122406,8.921161,0.429798,-216.488785,0.043942,0.000000
40.290001,39.940674,-216.488785,0.009718,0.001704,0.043292,177.664993,9.050686,0.432920,-216.488785,0.044263,0.000000
40.480003,40.674988,-216.577744,0.009735,0.001718,0.043630,180.931381,9.217084,0.436300,-216.577744,0.044575,0.000000
40.670002,41.180672,-216.577744,0.009753,0.001730,0.043934,183.180771,9.331674,0.439335,-216.577744,0.044896,0.000000
40.860001,41.856529,-216.577744,0.009766,0.001744,0.044298,186.187134,9.484825,0.442980,-216.577744,0.045209,0.000000
41.050003,42.167458,-216.711197,0.009770,0.001753,0.044532,187.570221,9.555283,0.445319,-216.711197,0.045529,0.000000
41.240002,42.755806,-216.622238,0.009787,0.001766,0.044853,190.187317,9.688604,0.448529,-216.622238,0.045842,0.000000
41.430000,43.629021,-216.666718,0.009779,0.001781,0.045234,194.071579,9.886477,0.452344,-216.666718,0.046162,0.000000
41.620003,44.104172,-216.711197,0.009796,0.001790,0.045477,196.185150,9.994148,0.454774,-216.711197,0.046475,0.000000
41.810001,44.374512,-216.711197,0.009779,0.001798,0.045677,197.387680,10.055408,0.456769,-216.711197,0.046796,0.000000
42.000004,45.350876,-216.711197,0.009787,0.001814,0.046085,201.730774,10.276656,0.460845,-216.711197,0.047108,0.000000
42.190002,46.273613,-216.711197,0.009813,0.001831,0.046501,205.835312,10.485750,0.465008,-216.711197,0.047429,0.000000
42.380001,46.906273,-216.800156,0.009796,0.001843,0.046821,208.649521,10.629113,0.468214,-216.800156,0.047741,0.000000
42.570004,47.400414,-216.800156,0.009830,0.001853,0.047073,210.847565,10.741087,0.470731,-216.800156,0.048062,0.000000
42.760002,48.112755,-216.800156,0.009830,0.001867,0.047411,214.016220,10.902506,0.474111,-216.800156,0.048374,0.000000
42.950001,48.589394,-216.889114,0.009843,0.001878,0.047689,216.136414,11.010514,0.476889,-216.889114,0.048695,0.000000
43.140003,48.888039,-216.800156,0.009848,0.001885,0.047871,217.464859,11.078188,0.478710,-216.800156,0.049007,0.000000
43.330002,49.794762,-216.844635,0.009839,0.001902,0.048304,221.498169,11.283654,0.483043,-216.844635,0.049328,0.000000
43.520000,50.666115,-216.889114,0.009856,0.001912,0.048565,225.374130,11.481106,0.485647,-216.889114,0.049640,0.000000
43.710003,51.277184,-216.889114,0.009865,0.001924,0.048877,228.092300,11.619576,0.488770,-216.889114,0.049961,0.000000
43.900002,51.784721,-216.889114,0.009873,0.001934,0.049128,230.349945,11.734585,0.491283,-216.889114,0.050273,0.000000
44.090004,52.879128,-216.889114,0.009873,0.001952,0.049588,235.218109,11.982581,0.495878,-216.889114,0.050594,0.000000
44.280003,53.973526,-216.933594,0.009882,0.001969,0.050004,240.086227,12.230577,0.500041,-216.933594,0.050915,0.000000
44.470001,54.616615,-216.978073,0.009912,0.001981,0.050308,242.946838,12.376302,0.503077,-216.978073,0.051227,0.000000
44.660004,55.047821,-216.978073,0.009912,0.001989,0.050533,244.864944,12.474014,0.505333,-216.978073,0.051548,0.000000
44.850002,55.609360,-217.067047,0.009912,0.002000,0.050811,247.362793,12.601261,0.508107,-217.067047,0.051860,0.000000
45.040001,56.125473,-216.978073,0.009921,0.002010,0.051062,249.658569,12.718214,0.510624,-216.978073,0.052181,0.000000
45.230003,56.825157,-217.022568,0.009916,0.002023,0.051392,252.770920,12.876765,0.513917,-217.022568,0.052493,0.000000
45.420002,58.283371,-217.067047,0.009929,0.002042,0.051877,259.257385,13.207201,0.518773,-217.067047,0.052814,0.000000
45.610001,58.598770,-217.111526,0.009942,0.002050,0.052060,260.660339,13.278671,0.520597,-217.111526,0.053126,0.000000
45.800003,58.856079,-217.156006,0.009942,0.002056,0.052216,261.804901,13.336979,0.522157,-217.156006,0.053447,0.000000
45.990002,59.717003,-217.111526,0.009947,0.002069,0.052545,265.634491,13.532066,0.525453,-217.111526,0.053760,0.000000
46.180000,61.471619,-217.111526,0.009960,0.002094,0.053196,273.439423,13.929668,0.531956,-217.111526,0.054080,0.000000
46.370003,62.450958,-217.200485,0.009964,0.002107,0.053517,277.795746,14.151589,0.535165,-217.200485,0.054392,0.000000
46.560001,62.850891,-217.200485,0.009977,0.002116,0.053742,279.574738,14.242215,0.537421,-217.200485,0.054713,0.000000
46.750004,63.457481,-217.244965,0.009985,0.002127,0.054037,282.272980,14.379671,0.540369,-217.244965,0.055026,0.000000
46.940002,64.059975,-217.200485,0.009994,0.002137,0.054271,284.953003,14.516197,0.542709,-217.200485,0.055347,0.000000
47.130001,64.779030,-217.289444,0.010003,0.002149,0.054583,288.151520,14.679137,0.545831,-217.289444,0.055658,0.000000
47.320004,65.739388,-217.289444,0.009994,0.002166,0.055017,292.423401,14.896758,0.550169,-217.289444,0.055979,0.000000
47.510002,66.362740,-217.289444,0.010003,0.002171,0.055156,295.196198,15.038012,0.551558,-217.289444,0.056292,0.000000
47.700001,66.927254,-217.333923,0.010016,0.002182,0.055424,297.707306,15.165933,0.554245,-217.333923,0.056613,0.000000
47.890003,67.270943,-217.289444,0.010016,0.002180,0.055381,299.236084,15.243814,0.553810,-217.289444,0.055624,0.000000
48.080002,66.948479,-217.422882,0.010016,0.002180,0.055381,297.801697,15.170743,0.553810,-217.422882,0.055624,0.000000
48.270000,66.738823,-217.422882,0.010029,0.002179,0.055347,296.869110,15.123234,0.553465,-217.422882,0.055381,0.000000
48.460003,66.494560,-217.378403,0.010029,0.002178,0.055312,295.782562,15.067883,0.553117,-217.378403,0.055381,0.000000
48.650002,66.290871,-217.422882,0.010046,0.002177,0.055294,294.876526,15.021726,0.552943,-217.422882,0.055381,0.000000
48.840004,66.122551,-217.422882,0.010050,0.002177,0.055286,294.127808,14.983583,0.552856,-217.422882,0.055381,0.000000
49.030003,65.981056,-217.467377,0.010050,0.002176,0.055277,293.498383,14.951521,0.552769,-217.467377,0.055381,0.000000
49.220001,65.831352,-217.556335,0.010037,0.002176,0.055277,292.832489,14.917598,0.552769,-217.556335,0.055381,0.000000
49.410004,65.706978,-217.467377,0.010024,0.002176,0.055268,292.279236,14.889414,0.552682,-217.467377,0.055381,0.000000
49.600002,65.584846,-217.645294,0.010033,0.002176,0.055268,291.735962,14.861739,0.552682,-217.645294,0.055381,0.000000
49.790001,65.477608,-217.600815,0.010046,0.002176,0.055268,291.258942,14.837438,0.552682,-217.600815,0.055381,0.000000
49.980003,65.387123,-217.600815,0.010024,0.002176,0.055268,290.856445,14.816934,0.552682,-217.600815,0.055381,0.000000
50.170002,65.279137,-217.600815,0.010037,0.002176,0.055268,290.376099,14.792464,0.552682,-217.600815,0.055381,0.000000
50.360001,65.199806,-217.600815,0.010050,0.002176,0.055268,290.023224,14.774487,0.552682,-217.600815,0.055381,0.000000
50.550003,65.127953,-217.600815,0.010037,0.002176,0.055259,289.703613,14.758204,0.552595,-217.600815,0.055381,0.000000
50.740002,65.047142,-217.600815,0.010033,0.002176,0.055259,289.344147,14.739893,0.552595,-217.600815,0.055381,0.000000
50.930004,64.976387,-217.689774,0.010033,0.002176,0.055259,289.029419,14.723860,0.552595,-217.689774,0.055381,0.000000
51.120003,64.899681,-217.734253,0.010037,0.002176,0.055259,288.688202,14.706478,0.552595,-217.734253,0.055381,0.000000
51.310001,64.853508,-217.689774,0.010037,0.002176,0.055259,288.482819,14.696015,0.552595,-217.689774,0.055381,0.000000
51.500004,64.778664,-217.778732,0.010046,0.002176,0.055259,288.149902,14.679055,0.552595,-217.778732,0.055381,0.000000
51.690002,64.729134,-217.734253,0.010054,0.002176,0.055259,287.929565,14.667831,0.552595,-217.734253,0.055381,0.000000
51.880001,64.665825,-217.778732,0.010054,0.002176,0.055259,287.647949,14.653485,0.552595,-217.778732,0.055381,0.000000
52.070004,64.621147,-217.823212,0.010046,0.002176,0.055259,287.449219,14.643361,0.552595,-217.823212,0.055381,0.000000
52.260002,64.578331,-217.778732,0.010059,0.002176,0.055259,287.258759,14.633659,0.552595,-217.778732,0.055381,0.000000
52.450001,64.522835,-217.867691,0.010033,0.002176,0.055259,287.011902,14.621083,0.552595,-217.867691,0.055381,0.000000
52.640003,64.474800,-217.823212,0.010059,0.002176,0.055259,286.798248,14.610199,0.552595,-217.823212,0.055381,0.000000
52.830002,64.430122,-217.912186,0.010059,0.002176,0.055259,286.599487,14.600075,0.552595,-217.912186,0.055381,0.000000
53.020004,64.387672,-217.912186,0.010050,0.002176,0.055259,286.410675,14.590455,0.552595,-217.912186,0.055381,0.000000
53.210003,64.343361,-217.867691,0.010050,0.002176,0.055259,286.213562,14.580414,0.552595,-217.867691,0.055381,0.000000
53.400002,64.302025,-218.001144,0.010046,0.002176,0.055259,286.029694,14.571047,0.552595,-218.001144,0.055381,0.000000
53.590004,64.272240,-217.912186,0.010050,0.002176,0.055259,285.897186,14.564298,0.552595,-217.912186,0.055381,0.000000
53.780003,64.236107,-217.956665,0.010050,0.002176,0.055259,285.736481,14.556109,0.552595,-217.956665,0.055381,0.000000
53.970001,64.189934,-218.045624,0.010037,0.002176,0.055259,285.531097,14.545647,0.552595,-218.045624,0.055381,0.000000
54.160004,64.156059,-218.001144,0.010033,0.002176,0.055259,285.380402,14.537971,0.552595,-218.001144,0.055381,0.000000
54.350002,64.121788,-218.090103,0.010037,0.002176,0.055259,285.227966,14.530205,0.552595,-218.090103,0.055381,0.000000
54.540001,64.082329,-218.045624,0.010046,0.002176,0.055259,285.052429,14.521263,0.552595,-218.045624,0.055381,0.000000
54.730003,64.047691,-218.045624,0.010054,0.002176,0.055259,284.898346,14.513414,0.552595,-218.045624,0.055381,0.000000
54.920002,64.021248,-218.090103,0.010050,0.002176,0.055259,284.780731,14.507422,0.552595,-218.090103,0.055381,0.000000
55.110004,63.995567,-218.090103,0.010054,0.002176,0.055259,284.666504,14.501603,0.552595,-218.090103,0.055381,0.000000
55.300003,63.957573,-218.179062,0.010050,0.002176,0.055259,284.497498,14.492993,0.552595,-218.179062,0.055381,0.000000
55.490002,63.932259,-218.223541,0.010076,0.002176,0.055259,284.384888,14.487257,0.552595,-218.223541,0.055381,0.000000
55.680004,63.900978,-218.179062,0.010050,0.002176,0.055259,284.245758,14.480168,0.552595,-218.179062,0.055381,0.000000
55.870003,63.874916,-218.223541,0.010037,0.002176,0.055259,284.129822,14.474263,0.552595,-218.223541,0.055381,0.000000
56.060001,63.846245,-218.179062,0.010050,0.002176,0.055259,284.002289,14.467766,0.552595,-218.179062,0.055381,0.000000
56.250004,63.813469,-218.223541,0.010042,0.002176,0.055259,283.856476,14.460339,0.552595,-218.223541,0.055381,0.000000
56.440002,63.790382,-218.223541,0.010050,0.002175,0.055251,283.753784,14.455108,0.552511,-218.223541,0.055381,0.000000
56.630001,63.772881,-218.312515,0.010037,0.002175,0.055251,283.675934,14.451141,0.552511,-218.312515,0.055381,0.000000
56.820004,63.739738,-218.356995,0.010050,0.002175,0.055251,283.528503,14.443631,0.552511,-218.356995,0.055381,0.000000
57.010002,63.730431,-218.356995,0.010059,0.002175,0.055251,283.487122,14.441522,0.552511,-218.356995,0.055381,0.000000
57.200005,63.697289,-218.401474,0.010050,0.002175,0.055251,283.339691,14.434012,0.552511,-218.401474,0.055381,0.000000
57.390003,63.673088,-218.356995,0.010046,0.002175,0.055251,283.232056,14.428528,0.552511,-218.356995,0.055381,0.000000
57.580002,63.653358,-218.401474,0.010050,0.002175,0.055251,283.144287,14.424058,0.552511,-218.401474,0.055381,0.000000
57.770004,63.625420,-218.445953,0.010050,0.002175,0.055251,283.019989,14.417727,0.552511,-218.445953,0.055381,0.000000
57.960003,63.606804,-218.445953,0.010059,0.002175,0.055251,282.937195,14.413507,0.552511,-218.445953,0.055381,0.000000
58.150002,63.588554,-218.490433,0.010059,0.002175,0.055251,282.856018,14.409372,0.552511,-218.490433,0.055381,0.000000
58.340004,63.559517,-218.401474,0.010063,0.002175,0.055251,282.726837,14.402792,0.552511,-218.401474,0.055381,0.000000
58.530003,63.546852,-218.490433,0.010050,0.002175,0.055251,282.670502,14.399922,0.552511,-218.490433,0.055381,0.000000
58.720001,63.523399,-218.579391,0.010059,0.002175,0.055251,282.566193,14.394608,0.552511,-218.579391,0.055381,0.000000
58.910004,63.498817,-218.534912,0.010046,0.002175,0.055251,282.456848,14.389038,0.552511,-218.534912,0.055381,0.000000
59.100002,63.486534,-218.579391,0.010067,0.002175,0.055251,282.402222,14.386254,0.552511,-218.579391,0.055381,0.000000
59.290001,63.475349,-218.579391,0.010067,0.002175,0.055251,282.352448,14.383719,0.552511,-218.579391,0.055381,0.000000
59.480003,63.451149,-218.579391,0.010046,0.002175,0.055251,282.244812,14.378237,0.552511,-218.579391,0.055381,0.000000
59.670002,63.425087,-218.712830,0.010050,0.002175,0.055251,282.128876,14.372330,0.552511,-218.712830,0.055381,0.000000
59.860004,63.405357,-218.579391,0.010063,0.002175,0.055251,282.041107,14.367860,0.552511,-218.579391,0.055381,0.000000
60.050003,63.388969,-218.668350,0.010063,0.002175,0.055251,281.968231,14.364145,0.552511,-218.668350,0.055381,0.000000
60.240002,63.381523,-218.757324,0.010059,0.002175,0.055251,281.935089,14.362459,0.552511,-218.757324,0.055381,0.000000
60.430004,63.364769,-218.668350,0.010059,0.002175,0.055251,281.860565,14.358663,0.552511,-218.668350,0.055381,0.000000
60.620003,63.344276,-218.757324,0.010042,0.002175,0.055251,281.769409,14.354018,0.552511,-218.757324,0.055381,0.000000
60.810001,63.330498,-218.757324,0.010054,0.002175,0.055251,281.708130,14.350896,0.552511,-218.757324,0.055381,0.000000
61.000004,63.306679,-218.801804,0.010042,0.002175,0.055251,281.602173,14.345498,0.552511,-218.801804,0.055381,0.000000
61.190002,63.294762,-218.846283,0.010046,0.002175,0.055251,281.549164,14.342797,0.552511,-218.846283,0.055381,0.000000
61.380001,63.275764,-218.846283,0.010050,0.002175,0.055251,281.464661,14.338492,0.552511,-218.846283,0.055381,0.000000
61.570004,63.266090,-218.846283,0.010054,0.002175,0.055251,281.421631,14.336301,0.552511,-218.846283,0.055381,0.000000
61.760002,63.255653,-218.846283,0.010076,0.002175,0.055251,281.375214,14.333937,0.552511,-218.846283,0.055381,0.000000
61.950005,63.234062,-218.890762,0.010067,0.002175,0.055251,281.279144,14.329043,0.552511,-218.890762,0.055381,0.000000
62.140003,63.226982,-218.846283,0.010054,0.002175,0.055251,281.247650,14.327439,0.552511,-218.846283,0.055381,0.000000
62.330002,63.206871,-218.979721,0.010042,0.002175,0.055251,281.158203,14.322882,0.552511,-218.979721,0.055381,0.000000
62.520004,63.193840,-218.935242,0.010059,0.002175,0.055251,281.100250,14.319929,0.552511,-218.935242,0.055381,0.000000
62.710003,63.184914,-218.979721,0.010063,0.002175,0.055251,281.060547,14.317906,0.552511,-218.979721,0.055381,0.000000
62.900002,63.167030,-219.024200,0.010050,0.002175,0.055251,280.980988,14.313854,0.552511,-219.024200,0.055381,0.000000
63.090004,63.150276,-219.024200,0.010067,0.002175,0.055251,280.906464,14.310058,0.552511,-219.024200,0.055381,0.000000
63.280003,63.131660,-219.024200,0.010059,0.002175,0.055251,280.823639,14.305839,0.552511,-219.024200,0.055381,0.000000
63.470001,63.121971,-219.068680,0.010059,0.002175,0.055251,280.780548,14.303643,0.552511,-219.068680,0.055381,0.000000
63.660004,63.109322,-219.068680,0.010072,0.002175,0.055251,280.724274,14.300776,0.552511,-219.068680,0.055381,0.000000
63.850002,63.089211,-219.113159,0.010050,0.002175,0.055251,280.634827,14.296219,0.552511,-219.113159,0.055381,0.000000
64.040001,63.096275,-219.113159,0.010076,0.002175,0.055251,280.666260,14.297821,0.552511,-219.113159,0.055381,0.000000
64.230003,63.072449,-219.113159,0.010067,0.002175,0.055251,280.560272,14.292420,0.552511,-219.113159,0.055381,0.000000
64.420006,63.052345,-219.202133,0.010067,0.002175,0.055251,280.470825,14.287866,0.552511,-219.202133,0.055381,0.000000
64.610001,63.057182,-219.202133,0.010072,0.002175,0.055251,280.492371,14.288961,0.552511,-219.202133,0.055381,0.000000
64.800003,63.044525,-219.246613,0.010054,0.002175,0.055251,280.436066,14.286094,0.552511,-219.246613,0.055381,0.000000
64.990005,63.034096,-219.246613,0.010067,0.002175,0.055251,280.389648,14.283730,0.552511,-219.246613,0.055381,0.000000
65.180000,63.012497,-219.246613,0.010059,0.002175,0.055251,280.293579,14.278836,0.552511,-219.246613,0.055381,0.000000
65.370003,62.994255,-219.291092,0.010046,0.002175,0.055251,280.212433,14.274702,0.552511,-219.291092,0.055381,0.000000
65.560005,62.987175,-219.246613,0.010067,0.002175,0.055251,280.180939,14.273098,0.552511,-219.246613,0.055381,0.000000
65.750000,62.981964,-219.380051,0.010076,0.002175,0.055251,280.157776,14.271917,0.552511,-219.380051,0.055381,0.000000
65.940002,62.968185,-219.291092,0.010067,0.002175,0.055251,280.096466,14.268795,0.552511,-219.291092,0.055381,0.000000
66.130005,62.962975,-219.380051,0.010072,0.002175,0.055251,280.073303,14.267614,0.552511,-219.380051,0.055381,0.000000
66.320000,62.944725,-219.424530,0.010063,0.002175,0.055251,279.992126,14.263478,0.552511,-219.424530,0.055381,0.000000
66.510002,62.928711,-219.335571,0.010063,0.002175,0.055251,279.920898,14.259851,0.552511,-219.335571,0.055381,0.000000
66.700005,62.927597,-219.513489,0.010059,0.002175,0.055251,279.915924,14.259598,0.552511,-219.513489,0.055381,0.000000
66.889999,62.906746,-219.424530,0.010059,0.002175,0.055251,279.823181,14.254872,0.552511,-219.424530,0.055381,0.000000
67.080002,62.900787,-219.469009,0.010059,0.002175,0.055251,279.796661,14.253523,0.552511,-219.469009,0.055381,0.000000
67.270004,62.882538,-219.513489,0.010059,0.002175,0.055251,279.715485,14.249387,0.552511,-219.513489,0.055381,0.000000
67.460007,62.884033,-219.513489,0.010076,0.002175,0.055251,279.722137,14.249725,0.552511,-219.513489,0.055381,0.000000
67.650002,62.860939,-219.557968,0.010050,0.002175,0.055251,279.619415,14.244493,0.552511,-219.557968,0.055381,0.000000
67.840004,62.859825,-219.513489,0.010080,0.002175,0.055251,279.614471,14.244240,0.552511,-219.513489,0.055381,0.000000
68.030006,62.855728,-219.602463,0.010050,0.002175,0.055251,279.596252,14.243312,0.552511,-219.602463,0.055381,0.000000
68.220001,62.847534,-219.602463,0.010050,0.002175,0.055251,279.559784,14.241454,0.552511,-219.602463,0.055381,0.000000
68.410004,62.829666,-219.557968,0.010059,0.002175,0.055251,279.480316,14.237406,0.552511,-219.557968,0.055381,0.000000
68.600006,62.817375,-219.646942,0.010059,0.002175,0.055251,279.425629,14.234620,0.552511,-219.646942,0.055381,0.000000
68.790001,62.812164,-219.602463,0.010054,0.002175,0.055251,279.402466,14.233440,0.552511,-219.602463,0.055381,0.000000
68.980003,62.808067,-219.691422,0.010059,0.002175,0.055251,279.384247,14.232512,0.552511,-219.691422,0.055381,0.000000
69.170006,62.793541,-219.691422,0.010050,0.002175,0.055251,279.319611,14.229219,0.552511,-219.691422,0.055381,0.000000
69.360001,62.789818,-219.691422,0.010063,0.002175,0.055251,279.303070,14.228376,0.552511,-219.691422,0.055381,0.000000
69.550003,62.774178,-219.780380,0.010054,0.002175,0.055251,279.233490,14.224832,0.552511,-219.780380,0.055381,0.000000
69.740005,62.763756,-219.735901,0.010059,0.002175,0.055251,279.187134,14.222470,0.552511,-219.735901,0.055381,0.000000
69.930000,62.741409,-219.780380,0.010059,0.002175,0.055251,279.087738,14.217406,0.552511,-219.780380,0.055381,0.000000
70.120003,62.746994,-219.824860,0.010067,0.002175,0.055251,279.112579,14.218672,0.552511,-219.824860,0.055381,0.000000
70.310005,62.739174,-219.780380,0.010054,0.002175,0.055251,279.077789,14.216900,0.552511,-219.780380,0.055381,0.000000
70.500000,62.731354,-219.869339,0.010050,0.002175,0.055251,279.042999,14.215128,0.552511,-219.869339,0.055381,0.000000
70.690002,62.717949,-219.869339,0.010059,0.002175,0.055251,278.983368,14.212090,0.552511,-219.869339,0.055381,0.000000
70.880005,62.704544,-219.869339,0.010067,0.002175,0.055251,278.923737,14.209053,0.552511,-219.869339,0.055381,0.000000
71.070000,62.698219,-219.869339,0.010059,0.002175,0.055251,278.895599,14.207619,0.552511,-219.869339,0.055381,0.000000
71.260002,62.688538,-219.869339,0.010063,0.002175,0.055251,278.852539,14.205426,0.552511,-219.869339,0.055381,0.000000
71.450005,62.675125,-219.913818,0.010072,0.002175,0.055251,278.792877,14.202387,0.552511,-219.913818,0.055381,0.000000
71.640007,62.667679,-219.958298,0.010063,0.002175,0.055251,278.759766,14.200699,0.552511,-219.958298,0.055381,0.000000
71.830002,62.665817,-220.002777,0.010050,0.002175,0.055251,278.751465,14.200277,0.552511,-220.002777,0.055381,0.000000
72.020004,62.667679,-219.958298,0.010063,0.002175,0.055251,278.759766,14.200699,0.552511,-219.958298,0.055381,0.000000
72.210007,62.640129,-220.002777,0.010054,0.002175,0.055251,278.637207,14.194456,0.552511,-220.002777,0.055381,0.000000
72.400002,62.631187,-220.002777,0.010059,0.002175,0.055251,278.597443,14.192430,0.552511,-220.002777,0.055381,0.000000
72.590004,62.618896,-220.002777,0.010059,0.002175,0.055251,278.542755,14.189645,0.552511,-220.002777,0.055381,0.000000
72.780006,62.624115,-220.091751,0.010063,0.002175,0.055251,278.565979,14.190826,0.552511,-220.091751,0.055381,0.000000
72.970001,62.610336,-220.047272,0.010054,0.002175,0.055251,278.504700,14.187705,0.552511,-220.047272,0.055381,0.000000
73.160004,62.604752,-220.136230,0.010050,0.002175,0.055251,278.479858,14.186440,0.552511,-220.136230,0.055381,0.000000
73.350006,62.589485,-220.180710,0.010067,0.002175,0.055251,278.411926,14.182981,0.552511,-220.180710,0.055381,0.000000
73.540001,62.587990,-220.136230,0.010059,0.002175,0.055251,278.405273,14.182641,0.552511,-220.136230,0.055381,0.000000
73.730003,62.575706,-220.225189,0.010063,0.002175,0.055251,278.350647,14.179857,0.552511,-220.225189,0.055381,0.000000
73.920006,62.571983,-220.225189,0.010067,0.002175,0.055251,278.334076,14.179014,0.552511,-220.225189,0.055381,0.000000
74.110001,62.561554,-220.180710,0.010050,0.002175,0.055251,278.287689,14.176651,0.552511,-220.180710,0.055381,0.000000
74.300003,62.554855,-220.314148,0.010059,0.002175,0.055251,278.257904,14.175133,0.552511,-220.314148,0.055381,0.000000
74.490005,62.551872,-220.225189,0.010072,0.002175,0.055251,278.244629,14.174457,0.552511,-220.225189,0.055381,0.000000
74.680000,62.547401,-220.314148,0.010072,0.002175,0.055251,278.224731,14.173444,0.552511,-220.314148,0.055381,0.000000
74.870003,62.545540,-220.269669,0.010059,0.002175,0.055251,278.216461,14.173021,0.552511,-220.269669,0.055381,0.000000
75.060005,62.525810,-220.269669,0.010063,0.002175,0.055251,278.128693,14.168551,0.552511,-220.269669,0.055381,0.000000
75.250000,62.506073,-220.358627,0.010067,0.002175,0.055251,278.040894,14.164079,0.552511,-220.358627,0.055381,0.000000
75.440002,62.498993,-220.314148,0.010067,0.002175,0.055251,278.009399,14.162475,0.552511,-220.314148,0.055381,0.000000
75.630005,62.490433,-220.403107,0.010067,0.002175,0.055251,277.971313,14.160534,0.552511,-220.403107,0.055381,0.000000
75.820007,62.501602,-220.447586,0.010050,0.002175,0.055251,278.021027,14.163065,0.552511,-220.447586,0.055381,0.000000
76.010002,62.504211,-220.358627,0.010046,0.002175,0.055251,278.032623,14.163657,0.552511,-220.358627,0.055381,0.000000
76.200005,62.478516,-220.447586,0.010063,0.002175,0.055251,277.918304,14.157834,0.552511,-220.447586,0.055381,0.000000
76.390007,62.472183,-220.447586,0.010072,0.002175,0.055251,277.890137,14.156399,0.552511,-220.447586,0.055381,0.000000
76.580002,62.468460,-220.536560,0.010046,0.002175,0.055251,277.873596,14.155556,0.552511,-220.536560,0.055381,0.000000
76.770004,62.454681,-220.492081,0.010067,0.002175,0.055251,277.812286,14.152433,0.552511,-220.492081,0.055381,0.000000
76.960007,62.451706,-220.447586,0.010063,0.002175,0.055251,277.799072,14.151759,0.552511,-220.447586,0.055381,0.000000
77.150002,62.450584,-220.536560,0.010063,0.002175,0.055251,277.794067,14.151505,0.552511,-220.536560,0.055381,0.000000
77.340004,62.435318,-220.492081,0.010059,0.002175,0.055251,277.726166,14.148045,0.552511,-220.492081,0.055381,0.000000
77.530006,62.444260,-220.581039,0.010063,0.002175,0.055251,277.765930,14.150071,0.552511,-220.581039,0.055381,0.000000
77.720001,62.428619,-220.536560,0.010059,0.002175,0.055251,277.696381,14.146527,0.552511,-220.536560,0.055381,0.000000
77.910004,62.430107,-220.669998,0.010054,0.002175,0.055251,277.702972,14.146865,0.552511,-220.669998,0.055381,0.000000
78.100006,62.402550,-220.669998,0.010063,0.002175,0.055251,277.580414,14.140619,0.552511,-220.669998,0.055381,0.000000
78.290001,62.405907,-220.669998,0.010054,0.002175,0.055251,277.595337,14.141380,0.552511,-220.669998,0.055381,0.000000
78.300003,62.402924,-220.714478,0.010059,0.002175,0.055251,277.582062,14.140705,0.552511,-220.714478,0.055381,0.000000