File: Data/AG AL compression 300N/AL membrane Unpeeled 300N_1_2_03192024_181819.csv
Time (sec),S:Load (lbs),S:HL1 (DIM),S:LVDT (in),S:Position (in),Ch:Position (mm),Ch:Load (N),Ch:Stress (MPa),Ch:Strain (mm/mm),Ch:HL1 (DIM),Set Point (),Cycles ()
0.010000,-0.010056,-226.274597,0.000000,-0.000000,-0.000000,-0.044729,-0.002279,-0.000000,-226.274597,0.000173,0.000000
0.190000,-0.001862,-226.274597,-0.000004,-0.000000,-0.000000,-0.008281,-0.000422,-0.000000,-226.274597,0.000173,0.000000
0.370000,-0.024208,-226.363556,-0.000022,0.000022,0.000546,-0.107683,-0.005486,0.005462,-226.363556,0.001075,0.000000
0.550000,0.010056,-226.408035,-0.000009,0.000126,0.003200,0.044729,0.002279,0.032001,-226.408035,0.004076,0.000000
0.730000,0.031281,-226.363556,0.000009,0.000232,0.005889,0.139143,0.007088,0.058885,-226.363556,0.007077,0.000000
0.910000,0.020851,-226.363556,0.000147,0.000352,0.008941,0.092750,0.004725,0.089411,-226.363556,0.010060,0.000000
1.090000,0.016754,-226.452515,0.000246,0.000470,0.011933,0.074526,0.003797,0.119330,-226.452515,0.013060,0.000000
1.270000,0.003349,-226.497009,0.000358,0.000589,0.014968,0.014898,0.000759,0.149681,-226.497009,0.016061,0.000000
1.450000,0.007072,-226.497009,0.000487,0.000708,0.017995,0.031460,0.001603,0.179949,-226.497009,0.019061,0.000000
1.630000,-0.026443,-226.541489,0.000595,0.000819,0.020805,-0.117626,-0.005992,0.208048,-226.541489,0.022062,0.000000
1.810000,-0.049530,-226.541489,0.000733,0.000935,0.023753,-0.220321,-0.011224,0.237532,-226.541489,0.025063,0.000000
1.990000,-0.058090,-226.497009,0.000854,0.001056,0.026832,-0.258398,-0.013163,0.268319,-226.497009,0.028063,0.000000
2.170000,-0.052132,-226.585968,0.000966,0.001180,0.029962,-0.231893,-0.011813,0.299624,-226.585968,0.031064,0.000000
2.350000,-0.004471,-226.585968,0.001078,0.001297,0.032954,-0.019887,-0.001013,0.329543,-226.585968,0.034064,0.000000
2.530000,-0.000374,-226.630447,0.001203,0.001418,0.036007,-0.001663,-0.000085,0.360072,-226.630447,0.037048,0.000000
2.710000,0.027184,-226.541489,0.001315,0.001538,0.039068,0.120918,0.006160,0.390684,-226.541489,0.040048,0.000000
2.890000,0.047661,-226.674927,0.001440,0.001654,0.042017,0.212006,0.010800,0.420169,-226.674927,0.043049,0.000000
3.070000,0.040215,-226.719406,0.001535,0.001768,0.044913,0.178883,0.009113,0.449135,-226.719406,0.046050,0.000000
3.250000,0.030533,-226.719406,0.001664,0.001886,0.047905,0.135817,0.006919,0.479054,-226.719406,0.049050,0.000000
3.430000,0.014519,-226.674927,0.001763,0.002000,0.050811,0.064583,0.003290,0.508107,-226.674927,0.052051,0.000000
3.610000,0.035378,-226.719406,0.001867,0.002120,0.053855,0.157367,0.008017,0.538545,-226.719406,0.055051,0.000000
3.790000,0.023827,-226.763885,0.001996,0.002240,0.056890,0.105986,0.005399,0.568900,-226.763885,0.058052,0.000000
3.970000,0.004463,-226.719406,0.002100,0.002357,0.059856,0.019853,0.001011,0.598558,-226.719406,0.061053,0.000000
4.150000,-0.014526,-226.763885,0.002220,0.002478,0.062934,-0.064617,-0.003292,0.629345,-226.763885,0.064053,0.000000
4.330000,-0.021599,-226.719406,0.002354,0.002591,0.065822,-0.096076,-0.004894,0.658224,-226.719406,0.067037,0.000000
4.510000,0.013031,-226.763885,0.002492,0.002711,0.068849,0.057965,0.002953,0.688491,-226.763885,0.070037,0.000000
4.690000,0.005959,-226.852844,0.002604,0.002831,0.071919,0.026505,0.001350,0.719191,-226.852844,0.073037,0.000000
4.870000,-0.005959,-226.941818,0.002721,0.002948,0.074885,-0.026505,-0.001350,0.748849,-226.941818,0.076038,0.000000
5.050000,0.014519,-226.852844,0.002850,0.003071,0.077998,0.064583,0.003290,0.779984,-226.852844,0.079039,0.000000
5.230000,0.043564,-226.852844,0.002958,0.003191,0.081042,0.193782,0.009872,0.810422,-226.852844,0.082039,0.000000
5.410000,0.048409,-226.852844,0.003087,0.003304,0.083930,0.215332,0.010970,0.839300,-226.852844,0.085040,0.000000
5.590000,0.024574,-226.941818,0.003186,0.003423,0.086939,0.109312,0.005569,0.869394,-226.941818,0.088041,0.000000
5.770000,0.026810,-226.941818,0.003303,0.003540,0.089923,0.119255,0.006075,0.899227,-226.941818,0.091041,0.000000
5.950000,0.037239,-226.986298,0.003441,0.003655,0.092845,0.165648,0.008438,0.928450,-226.986298,0.094024,0.000000
6.130000,0.046173,-226.941818,0.003553,0.003771,0.095794,0.205388,0.010463,0.957938,-226.941818,0.097025,0.000000
6.310000,0.014145,-226.986298,0.003686,0.003894,0.098907,0.062920,0.003205,0.989069,-226.986298,0.100026,0.000000
6.490000,0.032394,-226.986298,0.003803,0.004013,0.101925,0.144098,0.007341,1.019250,-226.986298,0.103026,0.000000
6.670001,0.032768,-227.075256,0.003898,0.004132,0.104943,0.145760,0.007425,1.049430,-227.075256,0.106027,0.000000
6.850000,0.024574,-227.075256,0.004040,0.004248,0.107900,0.109312,0.005569,1.079002,-227.075256,0.109028,0.000000
7.030000,-0.001122,-227.075256,0.004148,0.004365,0.110866,-0.004989,-0.000254,1.108660,-227.075256,0.112028,0.000000
7.210001,0.019363,-227.030777,0.004281,0.004485,0.113927,0.086133,0.004388,1.139272,-227.030777,0.115029,0.000000
7.390000,0.018616,-227.119736,0.004398,0.004605,0.116971,0.082807,0.004218,1.169714,-227.119736,0.118029,0.000000
7.570000,0.032394,-227.208694,0.004523,0.004723,0.119955,0.144098,0.007341,1.199547,-227.208694,0.121030,0.000000
7.750000,0.020103,-227.119736,0.004631,0.004839,0.122921,0.089425,0.004556,1.229205,-227.119736,0.124013,0.000000
7.930000,0.027184,-227.164215,0.004760,0.004961,0.126008,0.120918,0.006160,1.260079,-227.164215,0.127014,0.000000
8.110001,0.030159,-227.208694,0.004872,0.005074,0.128878,0.134154,0.006834,1.288783,-227.208694,0.130015,0.000000
8.290000,0.038353,-227.253174,0.004984,0.005186,0.131714,0.170603,0.008691,1.317140,-227.253174,0.133015,0.000000
8.470000,0.046547,-227.297653,0.005101,0.005306,0.134767,0.207051,0.010548,1.347669,-227.297653,0.136015,0.000000
8.650001,0.074104,-227.297653,0.005187,0.005427,0.137845,0.329632,0.016792,1.378455,-227.297653,0.139016,0.000000
8.830001,0.075592,-227.297653,0.005342,0.005548,0.140924,0.336250,0.017129,1.409241,-227.297653,0.142017,0.000000
9.010000,0.115059,-227.297653,0.005454,0.005666,0.143916,0.511808,0.026073,1.439161,-227.297653,0.145017,0.000000
9.190001,0.220444,-227.297653,0.005570,0.005786,0.146969,0.980583,0.049953,1.469686,-227.297653,0.148018,0.000000
9.370001,0.474403,-227.342148,0.005674,0.005902,0.149909,2.110252,0.107501,1.499087,-227.342148,0.151001,0.000000
9.550000,0.667664,-227.342148,0.005752,-0.000000,-0.000000,2.969916,0.151295,-0.000000,-227.342148,0.000217,0.000000
9.730000,0.657234,-227.297653,0.005760,-0.000000,-0.000000,2.923524,0.148931,-0.000000,-227.297653,0.000217,0.000000
9.910001,0.654999,-227.342148,0.005764,-0.000000,-0.000000,2.913580,0.148425,-0.000000,-227.342148,0.000217,0.000000
10.090000,0.658356,-227.386627,0.005769,-0.000000,-0.000000,2.928513,0.149186,-0.000000,-227.386627,0.000425,0.000000
10.270000,0.659096,-227.475586,0.005747,0.000000,0.000009,2.931804,0.149353,0.000087,-227.475586,0.000720,0.000000
10.450001,0.654999,-227.475586,0.005747,0.000005,0.000121,2.913580,0.148425,0.001215,-227.475586,0.001023,0.000000
10.630000,0.708626,-227.431107,0.005734,0.000019,0.000486,3.152125,0.160577,0.004856,-227.431107,0.001318,0.000000
10.810000,0.757401,-227.431107,0.005760,0.000027,0.000694,3.369086,0.171629,0.006938,-227.431107,0.001621,0.000000
10.990001,0.849007,-227.520065,0.005769,0.000041,0.001032,3.776570,0.192388,0.010318,-227.520065,0.001925,0.000000
11.170000,0.883263,-227.564545,0.005777,0.000055,0.001388,3.928948,0.200150,0.013875,-227.564545,0.002220,0.000000
11.350000,0.923851,-227.520065,0.005782,0.000064,0.001621,4.109495,0.209348,0.016214,-227.520065,0.002523,0.000000
11.530001,1.000191,-227.475586,0.005795,0.000077,0.001951,4.449070,0.226646,0.019511,-227.475586,0.002818,0.000000
11.710001,1.073547,-227.564545,0.005821,0.000090,0.002298,4.775377,0.243269,0.022982,-227.564545,0.003122,0.000000
11.890000,1.159195,-227.609024,0.005825,0.000102,0.002602,5.156357,0.262677,0.026017,-227.609024,0.003425,0.000000
12.070001,1.242981,-227.653503,0.005821,0.000112,0.002853,5.529056,0.281664,0.028531,-227.653503,0.003720,0.000000
12.250001,1.267929,-227.653503,0.005825,0.000116,0.002957,5.640030,0.287317,0.029571,-227.653503,0.004024,0.000000
12.430000,1.386711,-227.609024,0.005846,0.000135,0.003434,6.168399,0.314233,0.034340,-227.609024,0.004319,0.000000
12.610001,1.478317,-227.653503,0.005881,0.000149,0.003772,6.575883,0.334991,0.037724,-227.653503,0.004622,0.000000
12.790001,1.570290,-227.653503,0.005890,0.000160,0.004059,6.984997,0.355833,0.040585,-227.653503,0.004926,0.000000
12.970000,1.642532,-227.697983,0.005864,0.000170,0.004319,7.306349,0.372203,0.043186,-227.697983,0.005221,0.000000
13.150001,1.739349,-227.653503,0.005894,0.000182,0.004631,7.737012,0.394142,0.046308,-227.653503,0.005524,0.000000
13.330001,1.791107,-227.697983,0.005915,0.000191,0.004856,7.967243,0.405871,0.048564,-227.697983,0.005819,0.000000
13.510000,1.884575,-227.697983,0.005933,0.000201,0.005108,8.383008,0.427051,0.051077,-227.697983,0.006122,0.000000
13.690001,2.037247,-227.831436,0.005928,0.000218,0.005541,9.062126,0.461647,0.055415,-227.831436,0.006426,0.000000
13.870001,2.195503,-227.786957,0.005950,0.000232,0.005889,9.766087,0.497508,0.058885,-227.786957,0.006721,0.000000
14.050000,2.237213,-227.831436,0.005946,0.000237,0.006027,9.951621,0.506960,0.060271,-227.831436,0.007024,0.000000
14.230000,2.323601,-227.786957,0.005959,0.000245,0.006218,10.335893,0.526535,0.062178,-227.786957,0.007319,0.000000
14.410001,2.571228,-227.831436,0.005984,0.000266,0.006764,11.437393,0.582649,0.067644,-227.831436,0.007623,0.000000
14.590001,2.691132,-227.920395,0.005993,0.000278,0.007051,11.970751,0.609819,0.070505,-227.920395,0.007926,0.000000
14.770000,2.823326,-227.920395,0.005997,0.000289,0.007337,12.558782,0.639775,0.073366,-227.920395,0.008221,0.000000
14.950001,2.940994,-227.964874,0.006006,0.000299,0.007588,13.082196,0.666439,0.075880,-227.964874,0.008525,0.000000
15.130001,3.105209,-227.875916,0.006015,0.000312,0.007935,13.812661,0.703651,0.079350,-227.875916,0.008820,0.000000
15.310000,3.204262,-227.920395,0.006045,0.000322,0.008186,14.253268,0.726096,0.081863,-227.920395,0.009123,0.000000
15.490001,3.359917,-227.964874,0.006040,0.000335,0.008516,14.945656,0.761368,0.085160,-227.964874,0.009427,0.000000
15.670001,3.574402,-227.920395,0.006053,0.000347,0.008811,15.899734,0.809971,0.088109,-227.920395,0.009722,0.000000
15.850000,3.722977,-227.964874,0.006071,0.000358,0.009106,16.560627,0.843639,0.091057,-227.964874,0.010025,0.000000
16.030001,3.795593,-227.964874,0.006075,0.000366,0.009288,16.883642,0.860094,0.092878,-227.964874,0.010320,0.000000
16.210001,4.056625,-227.964874,0.006092,0.000381,0.009687,18.044771,0.919244,0.096867,-227.964874,0.010623,0.000000
16.390001,4.273346,-228.098312,0.006105,0.000394,0.010016,19.008793,0.968354,0.100163,-228.098312,0.010918,0.000000
16.570002,4.505707,-228.098312,0.006092,0.000410,0.010407,20.042385,1.021008,0.104066,-228.098312,0.011222,0.000000
16.750000,4.643852,-228.098312,0.006122,0.000419,0.010650,20.656887,1.052312,0.106496,-228.098312,0.011525,0.000000
16.930000,4.800621,-228.098312,0.006135,0.000430,0.010927,21.354229,1.087836,0.109270,-228.098312,0.011820,0.000000
17.110001,4.990158,-228.098312,0.006153,0.000442,0.011222,22.197332,1.130786,0.112218,-228.098312,0.012124,0.000000
17.290001,5.098518,-228.142792,0.006135,0.000450,0.011430,22.679342,1.155341,0.114300,-228.142792,0.012419,0.000000
17.470001,5.273537,-228.187286,0.006148,0.000461,0.011707,23.457863,1.195001,0.117074,-228.187286,0.012722,0.000000
17.650002,5.627663,-228.142792,0.006165,0.000476,0.012089,25.033094,1.275247,0.120890,-228.142792,0.013026,0.000000
17.830000,5.732674,-228.142792,0.006170,0.000486,0.012341,25.500206,1.299042,0.123406,-228.142792,0.013321,0.000000
18.010000,5.938225,-228.231766,0.006187,0.000497,0.012627,26.414543,1.345621,0.126268,-228.231766,0.013624,0.000000
18.190001,6.181007,-228.231766,0.006183,0.000509,0.012930,27.494493,1.400636,0.129303,-228.231766,0.013919,0.000000
18.370001,6.473694,-228.276245,0.006209,0.000522,0.013268,28.796429,1.466960,0.132683,-228.276245,0.014222,0.000000
18.550001,6.811806,-228.231766,0.006209,0.000540,0.013719,30.300425,1.543577,0.137195,-228.231766,0.014526,0.000000
18.730001,6.966713,-228.231766,0.006226,0.000550,0.013962,30.989487,1.578680,0.139621,-228.231766,0.014821,0.000000
18.910002,7.110825,-228.320724,0.006256,0.000558,0.014179,31.630527,1.611336,0.141790,-228.320724,0.015124,0.000000
19.090000,7.320099,-228.409683,0.006252,0.000570,0.014474,32.561424,1.658758,0.144738,-228.409683,0.015419,0.000000
19.270000,7.429199,-228.320724,0.006256,0.000579,0.014708,33.046730,1.683481,0.147081,-228.320724,0.015723,0.000000
19.450001,7.759865,-228.320724,0.006269,0.000592,0.015038,34.517601,1.758410,0.150378,-228.320724,0.016026,0.000000
19.630001,8.188843,-228.320724,0.006282,0.000609,0.015480,36.425793,1.855618,0.154798,-228.320724,0.016321,0.000000
19.810001,8.284912,-228.365204,0.006286,0.000617,0.015679,36.853130,1.877388,0.156793,-228.365204,0.016625,0.000000
19.990002,8.388802,-228.454163,0.006295,0.000623,0.015818,37.315254,1.900930,0.158182,-228.454163,0.016920,0.000000
20.170000,8.607758,-228.365204,0.006312,0.000634,0.016096,38.289219,1.950546,0.160956,-228.365204,0.017223,0.000000
20.350000,9.107483,-228.409683,0.006308,0.000653,0.016599,40.512108,2.063785,0.165987,-228.409683,0.017527,0.000000
20.530001,9.457138,-228.454163,0.006321,0.000670,0.017024,42.067451,2.143018,0.170237,-228.454163,0.017822,0.000000
20.710001,9.610184,-228.454163,0.006364,0.000681,0.017292,42.748234,2.177699,0.172924,-228.454163,0.018125,0.000000
20.890001,9.628059,-228.498642,0.006355,0.000687,0.017457,42.827747,2.181749,0.174571,-228.498642,0.018420,0.000000
21.070002,9.919632,-228.543121,0.006347,0.000699,0.017761,44.124725,2.247821,0.177606,-228.543121,0.018723,0.000000
21.250002,10.114754,-228.543121,0.006359,0.000711,0.018064,44.992672,2.292036,0.180642,-228.543121,0.019027,0.000000
21.430000,10.594368,-228.498642,0.006377,0.000726,0.018446,47.126102,2.400718,0.184457,-228.498642,0.019322,0.000000
21.610001,10.808853,-228.498642,0.006385,0.000735,0.018680,48.080181,2.449321,0.186800,-228.498642,0.019625,0.000000
21.790001,10.963387,-228.632095,0.006377,0.000745,0.018931,48.767578,2.484339,0.189313,-228.632095,0.019920,0.000000
21.970001,11.098557,-228.587601,0.006390,0.000754,0.019139,49.368847,2.514969,0.191395,-228.587601,0.020223,0.000000
22.150002,11.410606,-228.632095,0.006398,0.000769,0.019530,50.756912,2.585680,0.195297,-228.632095,0.020527,0.000000
22.330002,12.055931,-228.587601,0.006450,0.000790,0.020068,53.627460,2.731913,0.200675,-228.587601,0.020822,0.000000
22.510000,12.190727,-228.632095,0.006450,0.000801,0.020354,54.227062,2.762458,0.203537,-228.632095,0.021125,0.000000
22.690001,12.324036,-228.676575,0.006463,0.000811,0.020605,54.820049,2.792666,0.206053,-228.676575,0.021420,0.000000
22.870001,12.480064,-228.676575,0.006441,0.000822,0.020883,55.514099,2.828023,0.208828,-228.676575,0.021724,0.000000
23.050001,12.678909,-228.676575,0.006450,0.000831,0.021100,56.398605,2.873082,0.210997,-228.676575,0.022027,0.000000
23.230001,12.837914,-228.721054,0.006480,0.000839,0.021316,57.105892,2.909113,0.213161,-228.721054,0.022322,0.000000
23.410002,13.308220,-228.810013,0.006485,0.000855,0.021715,59.197918,3.015686,0.217151,-228.810013,0.022626,0.000000
23.590002,13.532761,-228.765533,0.006510,0.000865,0.021975,60.196724,3.066567,0.219755,-228.765533,0.022921,0.000000
23.770000,13.602768,-228.810013,0.006506,0.000874,0.022192,60.508133,3.082431,0.221924,-228.810013,0.023224,0.000000
23.950001,13.825439,-228.810013,0.006510,0.000882,0.022409,61.498627,3.132890,0.224088,-228.810013,0.023528,0.000000
24.130001,14.010513,-228.810013,0.006519,0.000895,0.022721,62.321877,3.174828,0.227211,-228.810013,0.023823,0.000000
24.310001,14.555290,-228.898972,0.006536,0.000911,0.023137,64.745163,3.298276,0.231374,-228.898972,0.024126,0.000000
24.490002,14.894897,-228.898972,0.006549,0.000925,0.023502,66.255814,3.375232,0.235015,-228.898972,0.024421,0.000000
24.670002,15.027092,-228.854492,0.006558,0.000937,0.023805,66.843842,3.405188,0.238051,-228.854492,0.024724,0.000000
24.850000,15.297806,-228.854492,0.006575,0.000950,0.024117,68.048042,3.466532,0.241174,-228.854492,0.025019,0.000000
25.030001,15.315681,-228.898972,0.006579,0.000956,0.024282,68.127556,3.470583,0.242824,-228.898972,0.025323,0.000000
25.210001,15.846306,-228.987930,0.006575,0.000973,0.024707,70.487892,3.590824,0.247070,-228.987930,0.025626,0.000000
25.390001,16.090584,-228.987930,0.006575,0.000986,0.025037,71.574493,3.646178,0.250367,-228.987930,0.025921,0.000000
25.570002,16.345291,-228.898972,0.006605,0.000997,0.025323,72.707489,3.703896,0.253228,-228.898972,0.026225,0.000000
25.750002,16.464821,-229.032410,0.006601,0.001007,0.025583,73.239182,3.730982,0.255832,-229.032410,0.026520,0.000000
25.930000,16.726601,-228.943451,0.006605,0.001016,0.025817,74.403633,3.790302,0.258171,-228.943451,0.026823,0.000000
26.110001,17.233398,-229.076904,0.006622,0.001032,0.026225,76.657982,3.905144,0.262248,-229.076904,0.027127,0.000000
26.290001,17.582306,-229.076904,0.006635,0.001046,0.026563,78.209999,3.984208,0.265631,-229.076904,0.027422,0.000000
26.470001,17.706306,-229.032410,0.006635,0.001056,0.026823,78.761581,4.012307,0.268232,-229.032410,0.027725,0.000000
26.650002,17.970695,-229.032410,0.006640,0.001070,0.027179,79.937645,4.072218,0.271790,-229.032410,0.028020,0.000000
26.830002,18.151665,-229.076904,0.006666,0.001079,0.027413,80.742638,4.113226,0.274129,-229.076904,0.028324,0.000000
27.010002,18.376953,-229.076904,0.006674,0.001091,0.027708,81.744774,4.164277,0.277077,-229.076904,0.028627,0.000000
27.190001,18.750816,-229.165863,0.006674,0.001103,0.028029,83.407799,4.248996,0.280287,-229.165863,0.028922,0.000000
27.370001,18.998070,-229.121384,0.006674,0.001113,0.028280,84.507637,4.305024,0.282800,-229.121384,0.029225,0.000000
27.550001,19.149254,-229.121384,0.006683,0.001124,0.028558,85.180138,4.339283,0.285578,-229.121384,0.029520,0.000000
27.730001,19.725311,-229.210342,0.006722,0.001139,0.028939,87.742569,4.469820,0.289393,-229.210342,0.029824,0.000000
27.910002,19.976288,-229.299301,0.006713,0.001154,0.029303,88.858963,4.526692,0.293034,-229.299301,0.030127,0.000000
28.090002,20.361328,-229.254822,0.006735,0.001166,0.029607,90.571709,4.613943,0.296070,-229.254822,0.030422,0.000000
28.270000,20.681564,-229.254822,0.006739,0.001179,0.029954,91.996193,4.686510,0.299540,-229.254822,0.030726,0.000000
28.450001,20.970154,-229.210342,0.006756,0.001191,0.030240,93.279900,4.751905,0.302402,-229.210342,0.031021,0.000000
28.630001,20.970154,-229.254822,0.006752,0.001198,0.030440,93.279900,4.751905,0.304396,-229.254822,0.031324,0.000000
28.810001,20.934776,-229.343781,0.006778,0.001205,0.030604,93.122536,4.743888,0.306043,-229.343781,0.031628,0.000000
28.990002,21.692184,-229.343781,0.006778,0.001221,0.031003,96.491653,4.915519,0.310032,-229.343781,0.031923,0.000000
29.170002,22.048546,-229.343781,0.006782,0.001235,0.031359,98.076828,4.996272,0.313586,-229.343781,0.032226,0.000000
29.350002,22.347931,-229.299301,0.006808,0.001246,0.031636,99.408562,5.064114,0.316364,-229.299301,0.032521,0.000000
29.530001,22.725891,-229.388260,0.006817,0.001257,0.031931,101.089813,5.149760,0.319313,-229.388260,0.032825,0.000000
29.710001,22.772812,-229.477234,0.006795,0.001265,0.032122,101.298523,5.160393,0.321220,-229.477234,0.033128,0.000000
29.890001,23.281471,-229.432739,0.006817,0.001282,0.032555,103.561157,5.275657,0.325554,-229.432739,0.033423,0.000000
30.070002,23.854919,-229.432739,0.006817,0.001295,0.032902,106.111984,5.405602,0.329025,-229.432739,0.033726,0.000000
30.250002,24.101433,-229.432739,0.006842,0.001307,0.033189,107.208527,5.461462,0.331886,-229.432739,0.034021,0.000000
30.430002,24.416458,-229.477234,0.006842,0.001318,0.033466,108.609833,5.532848,0.334660,-229.477234,0.034325,0.000000
30.610001,24.587006,-229.521713,0.006864,0.001327,0.033718,109.368462,5.571496,0.337177,-229.521713,0.034628,0.000000
30.790001,25.029388,-229.521713,0.006868,0.001340,0.034039,111.336281,5.671741,0.340387,-229.521713,0.034923,0.000000
30.970001,25.314621,-229.521713,0.006864,0.001350,0.034281,112.605057,5.736375,0.342813,-229.521713,0.035227,0.000000
31.150002,25.703011,-229.521713,0.006885,0.001363,0.034611,114.332703,5.824385,0.346110,-229.521713,0.035522,0.000000
31.330002,26.138313,-229.521713,0.006898,0.001375,0.034932,116.269028,5.923027,0.349319,-229.521713,0.035825,0.000000
31.510002,26.416473,-229.610672,0.006898,0.001385,0.035183,117.506340,5.986058,0.351832,-229.610672,0.036129,0.000000
31.690002,26.693520,-229.566193,0.006907,0.001397,0.035478,118.738708,6.048838,0.354781,-229.566193,0.036424,0.000000
31.870001,27.233459,-229.566193,0.006924,0.001410,0.035808,121.140480,6.171190,0.358078,-229.566193,0.036727,0.000000
32.050003,27.846382,-229.610672,0.006924,0.001424,0.036163,123.866898,6.310081,0.361632,-229.610672,0.037022,0.000000
32.230003,28.261581,-229.655151,0.006950,0.001435,0.036449,125.713791,6.404166,0.364493,-229.655151,0.037325,0.000000
32.410000,28.549797,-229.699631,0.006946,0.001447,0.036762,126.995842,6.469476,0.367615,-229.699631,0.037620,0.000000
32.590000,28.930733,-229.744110,0.006942,0.001459,0.037048,128.690323,6.555798,0.370477,-229.744110,0.037924,0.000000
32.770000,29.229004,-229.699631,0.006963,0.001469,0.037308,130.017105,6.623387,0.373081,-229.699631,0.038227,0.000000
32.950001,29.715324,-229.699631,0.006967,0.001482,0.037655,132.180359,6.733589,0.376548,-229.699631,0.038522,0.000000
33.130001,30.057159,-229.699631,0.007002,0.001490,0.037846,133.700928,6.811049,0.378455,-229.699631,0.038825,0.000000
33.310001,30.690567,-229.788589,0.006998,0.001506,0.038262,136.518463,6.954582,0.382619,-229.788589,0.039120,0.000000
33.490002,30.855522,-229.744110,0.006993,0.001515,0.038470,137.252213,6.991961,0.384701,-229.744110,0.039424,0.000000
33.670002,31.249870,-229.788589,0.007011,0.001525,0.038730,139.006363,7.081322,0.387301,-229.788589,0.039727,0.000000
33.850002,31.810661,-229.833069,0.007011,0.001538,0.039068,141.500885,7.208399,0.390684,-229.833069,0.040022,0.000000
34.030003,32.389328,-229.877548,0.007028,0.001551,0.039398,144.074921,7.339527,0.393981,-229.877548,0.040326,0.000000
34.210003,32.908417,-229.922043,0.007049,0.001563,0.039710,146.383942,7.457154,0.397104,-229.922043,0.040621,0.000000
34.390003,33.283394,-229.877548,0.007054,0.001575,0.039996,148.051926,7.542125,0.399965,-229.877548,0.040924,0.000000
34.570004,33.631935,-229.833069,0.007054,0.001585,0.040257,149.602325,7.621105,0.402565,-229.833069,0.041228,0.000000
34.750000,33.970421,-229.922043,0.007062,0.001595,0.040508,151.107971,7.697807,0.405078,-229.922043,0.041523,0.000000
34.930000,34.290665,-230.011002,0.007075,0.001604,0.040751,152.532501,7.770376,0.407508,-230.011002,0.041826,0.000000
35.110001,35.088654,-229.966522,0.007071,0.001620,0.041150,156.082123,7.951202,0.411498,-229.966522,0.042121,0.000000
35.290001,35.717590,-229.966522,0.007084,0.001632,0.041462,158.879776,8.093721,0.414620,-229.966522,0.042425,0.000000
35.470001,35.701950,-229.966522,0.007084,0.001636,0.041566,158.810211,8.090178,0.415661,-229.966522,0.042728,0.000000
35.650002,36.656715,-230.055481,0.007105,0.001656,0.042069,163.057220,8.306531,0.420691,-230.055481,0.043023,0.000000
35.830002,37.345604,-230.055481,0.007118,0.001669,0.042398,166.121536,8.462635,0.423984,-230.055481,0.043326,0.000000
36.010002,37.779045,-230.055481,0.007118,0.001680,0.042676,168.049591,8.560854,0.426762,-230.055481,0.043621,0.000000
36.190002,38.270576,-230.099960,0.007136,0.001692,0.042971,170.236023,8.672236,0.429710,-230.099960,0.043925,0.000000
36.370003,38.911430,-230.144440,0.007131,0.001706,0.043335,173.086685,8.817456,0.433352,-230.144440,0.044228,0.000000
36.550003,39.283058,-230.144440,0.007153,0.001715,0.043561,174.739777,8.901669,0.435607,-230.144440,0.044523,0.000000
36.730003,39.561966,-230.099960,0.007140,0.001722,0.043743,175.980408,8.964869,0.437428,-230.099960,0.044827,0.000000
36.910000,40.429596,-230.144440,0.007153,0.001741,0.044220,179.839828,9.161477,0.442197,-230.144440,0.045122,0.000000
37.090000,41.009750,-230.144440,0.007161,0.001752,0.044488,182.420486,9.292943,0.444884,-230.144440,0.045425,0.000000
37.270000,41.408936,-230.188919,0.007183,0.001762,0.044758,184.196152,9.383399,0.447575,-230.188919,0.045729,0.000000
37.450001,41.677414,-230.188919,0.007174,0.001770,0.044957,185.390396,9.444237,0.449570,-230.188919,0.046024,0.000000
37.630001,42.725273,-230.233398,0.007196,0.001787,0.045399,190.051514,9.681685,0.453991,-230.233398,0.046327,0.000000
37.810001,43.378410,-230.277878,0.007196,0.001799,0.045703,192.956802,9.829688,0.457026,-230.277878,0.046622,0.000000
37.990002,44.081451,-230.233398,0.007200,0.001814,0.046067,196.084091,9.989000,0.460671,-230.233398,0.046926,0.000000
38.170002,44.476166,-230.277878,0.007205,0.001823,0.046292,197.839859,10.078444,0.462923,-230.277878,0.047229,0.000000
38.350002,44.939400,-230.322357,0.007235,0.001834,0.046587,199.900436,10.183414,0.465871,-230.322357,0.047524,0.000000
38.530003,45.455132,-230.366852,0.007226,0.001843,0.046821,202.194519,10.300280,0.468214,-230.366852,0.047827,0.000000
38.710003,45.734039,-230.366852,0.007248,0.001851,0.047003,203.435165,10.363482,0.470035,-230.366852,0.048122,0.000000
38.890003,46.304512,-230.322357,0.007252,0.001864,0.047342,205.972763,10.492752,0.473418,-230.322357,0.048426,0.000000
39.070004,47.472649,-230.322357,0.007261,0.001880,0.047758,211.168884,10.757456,0.477582,-230.322357,0.048729,0.000000
39.250000,47.885605,-230.411331,0.007261,0.001891,0.048036,213.005814,10.851033,0.480356,-230.411331,0.049024,0.000000
39.430000,48.310486,-230.500290,0.007265,0.001899,0.048235,214.895767,10.947312,0.482351,-230.500290,0.049328,0.000000
39.610001,48.918198,-230.500290,0.007256,0.001910,0.048513,217.599014,11.085022,0.485125,-230.500290,0.049623,0.000000
39.790001,50.017815,-230.411331,0.007269,0.001929,0.048989,222.490356,11.334199,0.489894,-230.411331,0.049926,0.000000
39.970001,51.060455,-230.500290,0.007278,0.001944,0.049380,227.128250,11.570465,0.493796,-230.500290,0.050221,0.000000
40.150002,51.384422,-230.500290,0.007304,0.001951,0.049562,228.569321,11.643876,0.495617,-230.500290,0.050525,0.000000
40.330002,51.864410,-230.544769,0.007312,0.001964,0.049874,230.704422,11.752644,0.498739,-230.544769,0.050828,0.000000
40.510002,52.299339,-230.544769,0.007308,0.001974,0.050143,232.639084,11.851199,0.501430,-230.544769,0.051123,0.000000
40.690002,52.678787,-230.544769,0.007299,0.001982,0.050334,234.326950,11.937183,0.503338,-230.544769,0.051427,0.000000
40.870003,53.674141,-230.589249,0.007312,0.001997,0.050724,238.754501,12.162734,0.507240,-230.589249,0.051721,0.000000
41.050003,54.803917,-230.633728,0.007321,0.002011,0.051071,243.779999,12.418745,0.510707,-230.633728,0.052025,0.000000
41.230003,55.232147,-230.678207,0.007330,0.002020,0.051314,245.684860,12.515783,0.513137,-230.678207,0.052328,0.000000
41.410004,55.214272,-230.633728,0.007325,0.002023,0.051374,245.605347,12.511733,0.513743,-230.633728,0.052623,0.000000
41.590000,56.247231,-230.633728,0.007330,0.002042,0.051860,250.200180,12.745804,0.518599,-230.633728,0.052927,0.000000
41.770000,57.723686,-230.678207,0.007368,0.002061,0.052345,256.767792,13.080375,0.523455,-230.678207,0.053222,0.000000
41.950001,58.630043,-230.722687,0.007351,0.002074,0.052675,260.799469,13.285757,0.526751,-230.722687,0.053525,0.000000
42.130001,59.125671,-230.722687,0.007381,0.002082,0.052892,263.004120,13.398068,0.528920,-230.722687,0.053829,0.000000
42.310001,59.560974,-230.722687,0.007368,0.002093,0.053169,264.940460,13.496710,0.531694,-230.722687,0.054124,0.000000
42.490002,60.116180,-230.722687,0.007390,0.002104,0.053447,267.410126,13.622521,0.534469,-230.722687,0.054427,0.000000
42.670002,60.822945,-230.767181,0.007386,0.002114,0.053690,270.553955,13.782676,0.536899,-230.767181,0.054722,0.000000
42.850002,61.804520,-230.811661,0.007399,0.002127,0.054037,274.920227,14.005104,0.540366,-230.811661,0.055026,0.000000
43.030003,62.469200,-230.767181,0.007377,0.002139,0.054332,277.876892,14.155724,0.543318,-230.767181,0.055329,0.000000
43.210003,63.023666,-230.856140,0.007403,0.002149,0.054583,280.343262,14.281367,0.545831,-230.856140,0.055624,0.000000
43.390003,63.547226,-230.856140,0.007420,0.002159,0.054826,282.672180,14.400007,0.548261,-230.856140,0.055927,0.000000
43.570004,64.545181,-230.900620,0.007420,0.002174,0.055208,287.111298,14.626147,0.552076,-230.900620,0.056222,0.000000
43.750004,66.044724,-230.945099,0.007429,0.002193,0.055693,293.781616,14.965948,0.556932,-230.945099,0.056526,0.000000
43.930000,66.776810,-230.945099,0.007437,0.002204,0.055971,297.038086,15.131842,0.559707,-230.945099,0.056829,0.000000
44.110001,67.295898,-230.900620,0.007433,0.002214,0.056239,299.347107,15.249469,0.562394,-230.900620,0.057124,0.000000
44.290001,67.492874,-230.945099,0.007442,0.002211,0.056153,300.223297,15.294104,0.561527,-230.945099,0.056370,0.000000
44.470001,67.129074,-230.945099,0.007446,0.002211,0.056153,298.605042,15.211665,0.561527,-230.945099,0.056370,0.000000
44.650002,66.868408,-230.989578,0.007429,0.002210,0.056144,297.445526,15.152597,0.561440,-230.989578,0.056153,0.000000
44.830002,66.609985,-231.034058,0.007446,0.002210,0.056127,296.296021,15.094038,0.561266,-231.034058,0.056153,0.000000
45.010002,66.409271,-230.989578,0.007455,0.002209,0.056118,295.403198,15.048556,0.561183,-230.989578,0.056153,0.000000
45.190002,66.218994,-230.989578,0.007459,0.002209,0.056118,294.556793,15.005439,0.561183,-230.989578,0.056153,0.000000
45.370003,66.056259,-231.078537,0.007446,0.002209,0.056110,293.832916,14.968562,0.561096,-231.078537,0.056153,0.000000
45.550003,65.914764,-231.078537,0.007450,0.002209,0.056110,293.203522,14.936499,0.561096,-231.078537,0.056153,0.000000
45.730003,65.778473,-231.123016,0.007476,0.002209,0.056110,292.597260,14.905615,0.561096,-231.123016,0.056153,0.000000
45.910004,65.670486,-231.123016,0.007450,0.002209,0.056110,292.116913,14.881145,0.561096,-231.123016,0.056153,0.000000
46.090004,65.553940,-231.167496,0.007455,0.002209,0.056110,291.598480,14.854734,0.561096,-231.167496,0.056153,0.000000
46.270000,65.453018,-231.167496,0.007463,0.002209,0.056101,291.149567,14.831865,0.561009,-231.167496,0.056153,0.000000
46.450001,65.362534,-231.211990,0.007468,0.002209,0.056101,290.747070,14.811362,0.561009,-231.211990,0.056153,0.000000
46.630001,65.272415,-231.167496,0.007463,0.002209,0.056101,290.346191,14.790941,0.561009,-231.167496,0.056153,0.000000
46.810001,65.190125,-231.211990,0.007463,0.002209,0.056101,289.980164,14.772293,0.561009,-231.211990,0.056153,0.000000
46.990002,65.116394,-231.256470,0.007459,0.002209,0.056101,289.652191,14.755586,0.561009,-231.256470,0.056153,0.000000
47.170002,65.036331,-231.256470,0.007468,0.002209,0.056101,289.296051,14.737443,0.561009,-231.256470,0.056153,0.000000
47.350002,64.980118,-231.389908,0.007459,0.002209,0.056101,289.045990,14.724706,0.561009,-231.389908,0.056153,0.000000
47.530003,64.908615,-231.256470,0.007459,0.002209,0.056101,288.727936,14.708503,0.561009,-231.256470,0.056153,0.000000
47.710003,64.852386,-231.300949,0.007472,0.002209,0.056101,288.477814,14.695761,0.561009,-231.300949,0.056153,0.000000
47.890003,64.787964,-231.300949,0.007459,0.002209,0.056101,288.191254,14.681162,0.561009,-231.300949,0.056153,0.000000
48.070004,64.738068,-231.389908,0.007450,0.002209,0.056101,287.969299,14.669856,0.561009,-231.389908,0.056153,0.000000
48.250004,64.675888,-231.434387,0.007455,0.002209,0.056101,287.692719,14.655766,0.561009,-231.434387,0.056153,0.000000
48.430004,64.627472,-231.389908,0.007485,0.002209,0.056101,287.477356,14.644794,0.561009,-231.389908,0.056153,0.000000
48.610001,64.584274,-231.300949,0.007476,0.002209,0.056101,287.285187,14.635006,0.561009,-231.300949,0.056153,0.000000
48.790001,64.544067,-231.434387,0.007472,0.002209,0.056101,287.106354,14.625895,0.561009,-231.434387,0.056153,0.000000
48.970001,64.490814,-231.523346,0.007455,0.002209,0.056101,286.869476,14.613828,0.561009,-231.523346,0.056153,0.000000
49.150002,64.449844,-231.434387,0.007468,0.002209,0.056101,286.687225,14.604543,0.561009,-231.434387,0.056153,0.000000
49.330002,64.412247,-231.478867,0.007455,0.002209,0.056101,286.519989,14.596024,0.561009,-231.478867,0.056153,0.000000
49.510002,64.373520,-231.523346,0.007472,0.002209,0.056101,286.347717,14.587249,0.561009,-231.523346,0.056153,0.000000
49.690002,64.320267,-231.523346,0.007468,0.002209,0.056101,286.110840,14.575181,0.561009,-231.523346,0.056153,0.000000
49.870003,64.294571,-231.567825,0.007476,0.002208,0.056092,285.996521,14.569358,0.560921,-231.567825,0.056153,0.000000
50.050003,64.257339,-231.567825,0.007463,0.002208,0.056092,285.830933,14.560921,0.560921,-231.567825,0.056153,0.000000
50.230003,64.215622,-231.523346,0.007459,0.002208,0.056092,285.645355,14.551468,0.560921,-231.523346,0.056153,0.000000
50.410004,64.173553,-231.567825,0.007480,0.002208,0.056092,285.458221,14.541936,0.560921,-231.567825,0.056153,0.000000
50.590004,64.151947,-231.612305,0.007480,0.002208,0.056092,285.362122,14.537039,0.560921,-231.612305,0.056153,0.000000
50.770004,64.106155,-231.612305,0.007450,0.002208,0.056092,285.158417,14.526663,0.560921,-231.612305,0.056153,0.000000
50.950001,64.074127,-231.656799,0.007463,0.002208,0.056092,285.015961,14.519404,0.560921,-231.656799,0.056153,0.000000
51.130001,64.048065,-231.656799,0.007476,0.002208,0.056092,284.900024,14.513499,0.560921,-231.656799,0.056153,0.000000
51.310001,64.022003,-231.612305,0.007455,0.002208,0.056092,284.784088,14.507593,0.560921,-231.612305,0.056153,0.000000
51.490002,63.985504,-231.656799,0.007480,0.002208,0.056092,284.621735,14.499322,0.560921,-231.656799,0.056153,0.000000
51.670002,63.959808,-231.790237,0.007480,0.002208,0.056092,284.507446,14.493500,0.560921,-231.790237,0.056153,0.000000
51.850002,63.935608,-231.745758,0.007472,0.002208,0.056092,284.399780,14.488016,0.560921,-231.745758,0.056153,0.000000
52.030003,63.908051,-231.790237,0.007468,0.002208,0.056092,284.277222,14.481771,0.560921,-231.790237,0.056153,0.000000
52.210003,63.877136,-231.834717,0.007463,0.002208,0.056092,284.139679,14.474767,0.560921,-231.834717,0.056153,0.000000
52.390003,63.843628,-231.790237,0.007472,0.002208,0.056092,283.990631,14.467173,0.560921,-231.790237,0.056153,0.000000
52.570004,63.825760,-231.834717,0.007480,0.002208,0.056092,283.911163,14.463124,0.560921,-231.834717,0.056153,0.000000
52.750004,63.808258,-231.834717,0.007463,0.002208,0.056092,283.833313,14.459158,0.560921,-231.834717,0.056153,0.000000
52.930004,63.784042,-231.790237,0.007476,0.002208,0.056092,283.725586,14.453671,0.560921,-231.790237,0.056153,0.000000
53.110004,63.762451,-231.968155,0.007498,0.002208,0.056092,283.629547,14.448778,0.560921,-231.968155,0.056153,0.000000
53.290001,63.727448,-231.968155,0.007472,0.002208,0.056092,283.473846,14.440845,0.560921,-231.968155,0.056153,0.000000
53.470001,63.712555,-231.923676,0.007476,0.002208,0.056092,283.407593,14.437471,0.560921,-231.923676,0.056153,0.000000
53.650002,63.681274,-231.923676,0.007476,0.002208,0.056092,283.268463,14.430383,0.560921,-231.923676,0.056153,0.000000
53.830002,63.662277,-231.923676,0.007472,0.002208,0.056092,283.183960,14.426078,0.560921,-231.923676,0.056153,0.000000
54.010002,63.639938,-232.012634,0.007480,0.002208,0.056092,283.084595,14.421017,0.560921,-232.012634,0.056153,0.000000
54.190002,63.615372,-231.968155,0.007463,0.002208,0.056092,282.975311,14.415449,0.560921,-231.968155,0.056153,0.000000
54.370003,63.594147,-232.012634,0.007476,0.002208,0.056092,282.880890,14.410640,0.560921,-232.012634,0.056153,0.000000
54.550003,63.569565,-231.968155,0.007472,0.002208,0.056092,282.771545,14.405069,0.560921,-231.968155,0.056153,0.000000
54.730003,63.554291,-232.057129,0.007485,0.002208,0.056092,282.703613,14.401608,0.560921,-232.057129,0.056153,0.000000
54.910004,63.528976,-232.057129,0.007493,0.002208,0.056092,282.591003,14.395872,0.560921,-232.057129,0.056153,0.000000
55.090004,63.528976,-232.101608,0.007468,0.002208,0.056092,282.591003,14.395872,0.560921,-232.101608,0.056153,0.000000
55.270004,63.497330,-232.146088,0.007480,0.002208,0.056092,282.450226,14.388700,0.560921,-232.146088,0.056153,0.000000
55.450001,63.486526,-232.101608,0.007489,0.002208,0.056092,282.402161,14.386252,0.560921,-232.101608,0.056153,0.000000
55.630001,63.467911,-232.101608,0.007472,0.002208,0.056092,282.319366,14.382033,0.560921,-232.101608,0.056153,0.000000
55.810001,63.451889,-232.146088,0.007480,0.002208,0.056092,282.248108,14.378404,0.560921,-232.146088,0.056153,0.000000
55.990002,63.429550,-232.279526,0.007463,0.002208,0.056092,282.148743,14.373342,0.560921,-232.279526,0.056153,0.000000
56.170002,63.415771,-232.190567,0.007489,0.002208,0.056092,282.087433,14.370219,0.560921,-232.190567,0.056153,0.000000
56.350002,63.398270,-232.235046,0.007468,0.002208,0.056092,282.009583,14.366253,0.560921,-232.235046,0.056153,0.000000
56.530003,63.380402,-232.235046,0.007485,0.002208,0.056092,281.930115,14.362205,0.560921,-232.235046,0.056153,0.000000
56.710003,63.362900,-232.279526,0.007472,0.002208,0.056092,281.852264,14.358238,0.560921,-232.279526,0.056153,0.000000
56.890003,63.340927,-232.324005,0.007485,0.002208,0.056092,281.754517,14.353259,0.560921,-232.324005,0.056153,0.000000
57.070004,63.321564,-232.279526,0.007485,0.002208,0.056092,281.668396,14.348871,0.560921,-232.279526,0.056153,0.000000
57.250004,63.317841,-232.279526,0.007480,0.002208,0.056092,281.651825,14.348028,0.560921,-232.279526,0.056153,0.000000
57.430004,63.288055,-232.324005,0.007480,0.002208,0.056092,281.519318,14.341278,0.560921,-232.324005,0.056153,0.000000
57.610004,63.281342,-232.368484,0.007489,0.002208,0.056092,281.489471,14.339757,0.560921,-232.368484,0.056153,0.000000
57.790001,63.271667,-232.368484,0.007485,0.002208,0.056092,281.446442,14.337565,0.560921,-232.368484,0.056153,0.000000
57.970001,63.250443,-232.368484,0.007472,0.002208,0.056092,281.352020,14.332755,0.560921,-232.368484,0.056153,0.000000
58.150002,63.238159,-232.368484,0.007480,0.002208,0.056092,281.297394,14.329971,0.560921,-232.368484,0.056153,0.000000
58.330002,63.224747,-232.412964,0.007485,0.002208,0.056092,281.237732,14.326932,0.560921,-232.412964,0.056153,0.000000
58.510002,63.206879,-232.457443,0.007485,0.002208,0.056092,281.158234,14.322884,0.560921,-232.457443,0.056153,0.000000
58.690002,63.195328,-232.457443,0.007493,0.002208,0.056092,281.106873,14.320266,0.560921,-232.457443,0.056153,0.000000
58.870003,63.172607,-232.457443,0.007480,0.002208,0.056092,281.005798,14.315118,0.560921,-232.457443,0.056153,0.000000
59.050003,63.159576,-232.368484,0.007480,0.002208,0.056092,280.947815,14.312164,0.560921,-232.368484,0.056153,0.000000
59.230003,63.152512,-232.501938,0.007493,0.002208,0.056092,280.916412,14.310564,0.560921,-232.501938,0.056153,0.000000
59.410004,63.126434,-232.501938,0.007472,0.002208,0.056092,280.800415,14.304655,0.560921,-232.501938,0.056153,0.000000
59.590004,63.118240,-232.590897,0.007463,0.002208,0.056092,280.763947,14.302797,0.560921,-232.590897,0.056153,0.000000
59.770004,63.115265,-232.501938,0.007480,0.002208,0.056092,280.750732,14.302124,0.560921,-232.501938,0.056153,0.000000
59.950005,63.110428,-232.501938,0.007498,0.002208,0.056092,280.729218,14.301027,0.560921,-232.501938,0.056153,0.000000
60.130001,63.086227,-232.546417,0.007480,0.002208,0.056092,280.621552,14.295544,0.560921,-232.546417,0.056153,0.000000
60.310001,63.066483,-232.590897,0.007480,0.002208,0.056092,280.533722,14.291069,0.560921,-232.590897,0.056153,0.000000
60.490002,63.060532,-232.679855,0.007472,0.002208,0.056092,280.507263,14.289721,0.560921,-232.679855,0.056153,0.000000
60.670002,63.046379,-232.590897,0.007480,0.002208,0.056092,280.444305,14.286513,0.560921,-232.590897,0.056153,0.000000
60.850002,63.035583,-232.635376,0.007480,0.002208,0.056092,280.396271,14.284068,0.560921,-232.635376,0.056153,0.000000
61.030003,63.020317,-232.679855,0.007485,0.002208,0.056092,280.328369,14.280608,0.560921,-232.679855,0.056153,0.000000
61.210003,63.010262,-232.768814,0.007480,0.002208,0.056092,280.283630,14.278329,0.560921,-232.768814,0.056153,0.000000
61.390003,63.005043,-232.724335,0.007476,0.002208,0.056092,280.260437,14.277146,0.560921,-232.724335,0.056153,0.000000
61.570004,62.989410,-232.590897,0.007476,0.002208,0.056092,280.190887,14.273604,0.560921,-232.590897,0.056153,0.000000
61.750004,62.970413,-232.724335,0.007472,0.002208,0.056092,280.106384,14.269300,0.560921,-232.724335,0.056153,0.000000
61.930004,62.970413,-232.768814,0.007480,0.002208,0.056092,280.106384,14.269300,0.560921,-232.768814,0.056153,0.000000
62.110004,62.948074,-232.813293,0.007489,0.002208,0.056092,280.007019,14.264237,0.560921,-232.813293,0.056153,0.000000
62.290005,62.941742,-232.857773,0.007468,0.002208,0.056092,279.978851,14.262802,0.560921,-232.857773,0.056153,0.000000
62.470001,62.935043,-232.768814,0.007489,0.002208,0.056092,279.949066,14.261285,0.560921,-232.768814,0.056153,0.000000
62.650002,62.917168,-232.813293,0.007480,0.002208,0.056092,279.869537,14.257234,0.560921,-232.813293,0.056153,0.000000
62.830002,62.907860,-232.902252,0.007485,0.002208,0.056092,279.828125,14.255125,0.560921,-232.902252,0.056153,0.000000
63.010002,62.895943,-232.902252,0.007476,0.002208,0.056092,279.775116,14.252424,0.560921,-232.902252,0.056153,0.000000
63.190002,62.886635,-232.902252,0.007485,0.002208,0.056092,279.733734,14.250315,0.560921,-232.902252,0.056153,0.000000
63.370003,62.880302,-232.902252,0.007476,0.002208,0.056092,279.705566,14.248879,0.560921,-232.902252,0.056153,0.000000
63.550003,62.865776,-232.902252,0.007468,0.002208,0.056092,279.640930,14.245589,0.560921,-232.902252,0.056153,0.000000
63.730003,62.860191,-232.946747,0.007485,0.002208,0.056092,279.616089,14.244324,0.560921,-232.946747,0.056153,0.000000
63.910004,62.846413,-233.035706,0.007489,0.002208,0.056092,279.554810,14.241200,0.560921,-233.035706,0.056153,0.000000
64.090004,62.847160,-232.946747,0.007459,0.002208,0.056092,279.558136,14.241370,0.560921,-232.946747,0.056153,0.000000
64.270004,62.833382,-233.035706,0.007489,0.002208,0.056092,279.496826,14.238248,0.560921,-233.035706,0.056153,0.000000
64.450005,62.817001,-232.991226,0.007502,0.002208,0.056092,279.423981,14.234536,0.560921,-232.991226,0.056153,0.000000
64.630005,62.801735,-233.035706,0.007485,0.002208,0.056092,279.356079,14.231077,0.560921,-233.035706,0.056153,0.000000
64.810005,62.798752,-233.124664,0.007476,0.002208,0.056092,279.342804,14.230401,0.560921,-233.124664,0.056153,0.000000
64.990005,62.780876,-233.124664,0.007476,0.002208,0.056092,279.263275,14.226350,0.560921,-233.124664,0.056153,0.000000
65.170006,62.772690,-233.080185,0.007485,0.002208,0.056092,279.226868,14.224495,0.560921,-233.080185,0.056153,0.000000
65.350006,62.767471,-233.169144,0.007485,0.002208,0.056092,279.203644,14.223312,0.560921,-233.169144,0.056153,0.000000
65.530006,62.759651,-233.213623,0.007480,0.002208,0.056092,279.168884,14.221540,0.560921,-233.213623,0.056153,0.000000
65.710007,62.753693,-233.169144,0.007498,0.002208,0.056092,279.142365,14.220190,0.560921,-233.169144,0.056153,0.000000
65.889999,62.739548,-233.213623,0.007480,0.002208,0.056092,279.079437,14.216985,0.560921,-233.213623,0.056153,0.000000
66.070000,62.735077,-233.124664,0.007485,0.002208,0.056092,279.059570,14.215971,0.560921,-233.124664,0.056153,0.000000
66.250000,62.730980,-233.124664,0.007480,0.002208,0.056092,279.041321,14.215044,0.560921,-233.124664,0.056153,0.000000
66.430000,62.708641,-233.213623,0.007485,0.002208,0.056092,278.941956,14.209982,0.560921,-233.213623,0.056153,0.000000
66.610001,62.710129,-233.302582,0.007485,0.002208,0.056092,278.948578,14.210319,0.560921,-233.302582,0.056153,0.000000
66.790001,62.707146,-233.258102,0.007480,0.002208,0.056092,278.935303,14.209642,0.560921,-233.258102,0.056153,0.000000
66.970001,62.679596,-233.302582,0.007463,0.002208,0.056092,278.812775,14.203400,0.560921,-233.302582,0.056153,0.000000
67.150002,62.688156,-233.347076,0.007493,0.002208,0.056092,278.850830,14.205338,0.560921,-233.347076,0.056153,0.000000
67.330002,62.653152,-233.302582,0.007463,0.002208,0.056092,278.695129,14.197407,0.560921,-233.302582,0.056153,0.000000
67.510002,62.659111,-233.347076,0.007485,0.002208,0.056092,278.721649,14.198758,0.560921,-233.347076,0.056153,0.000000
67.690002,62.662460,-233.347076,0.007480,0.002208,0.056092,278.736542,14.199517,0.560921,-233.347076,0.056153,0.000000
67.870003,62.644218,-233.302582,0.007485,0.002208,0.056092,278.655396,14.195382,0.560921,-233.302582,0.056153,0.000000
68.050003,62.636398,-233.391556,0.007493,0.002208,0.056092,278.620605,14.193610,0.560921,-233.391556,0.056153,0.000000
68.230003,62.634163,-233.391556,0.007498,0.002208,0.056092,278.610657,14.193104,0.560921,-233.391556,0.056153,0.000000
68.410004,62.619644,-233.480515,0.007489,0.002208,0.056092,278.546082,14.189814,0.560921,-233.480515,0.056153,0.000000
68.590004,62.618896,-233.436035,0.007489,0.002208,0.056092,278.542755,14.189645,0.560921,-233.436035,0.056153,0.000000
68.770004,62.606979,-233.436035,0.007476,0.002208,0.056092,278.489746,14.186944,0.560921,-233.436035,0.056153,0.000000
68.950005,62.604004,-233.480515,0.007480,0.002208,0.056092,278.476532,14.186271,0.560921,-233.480515,0.056153,0.000000
69.130005,62.595062,-233.524994,0.007480,0.002208,0.056092,278.436737,14.184244,0.560921,-233.524994,0.056153,0.000000
69.310005,62.579056,-233.569473,0.007468,0.002208,0.056092,278.365540,14.180616,0.560921,-233.569473,0.056153,0.000000
69.490005,62.570862,-233.524994,0.007489,0.002208,0.056092,278.329102,14.178760,0.560921,-233.524994,0.056153,0.000000
69.670006,62.563042,-233.524994,0.007489,0.002208,0.056092,278.294312,14.176988,0.560921,-233.524994,0.056153,0.000000
69.850006,62.542557,-233.569473,0.007489,0.002208,0.056092,278.203186,14.172346,0.560921,-233.569473,0.056153,0.000000
70.030006,62.567139,-233.658432,0.007489,0.002208,0.056092,278.312531,14.177917,0.560921,-233.658432,0.056153,0.000000
70.210007,62.542191,-233.613953,0.007468,0.002208,0.056092,278.201569,14.172263,0.560921,-233.613953,0.056153,0.000000
70.390007,62.532135,-233.613953,0.007498,0.002208,0.056092,278.156830,14.169985,0.560921,-233.613953,0.056153,0.000000
70.570000,62.532875,-233.702911,0.007493,0.002208,0.056092,278.160126,14.170152,0.560921,-233.702911,0.056153,0.000000
70.750000,62.515747,-233.702911,0.007493,0.002208,0.056092,278.083923,14.166271,0.560921,-233.702911,0.056153,0.000000
70.930000,62.517982,-233.747391,0.007476,0.002208,0.056092,278.093872,14.166778,0.560921,-233.747391,0.056153,0.000000
71.110001,62.510910,-233.747391,0.007489,0.002208,0.056092,278.062408,14.165175,0.560921,-233.747391,0.056153,0.000000
71.290001,62.489311,-233.747391,0.007493,0.002208,0.056092,277.966339,14.160280,0.560921,-233.747391,0.056153,0.000000
71.470001,62.495644,-233.747391,0.007485,0.002208,0.056092,277.994507,14.161716,0.560921,-233.747391,0.056153,0.000000
71.650002,62.480743,-233.791885,0.007472,0.002208,0.056092,277.928223,14.158340,0.560921,-233.791885,0.056153,0.000000
71.830002,62.469200,-233.791885,0.007485,0.002208,0.056092,277.876892,14.155724,0.560921,-233.791885,0.056153,0.000000
72.010002,62.471436,-233.880844,0.007493,0.002208,0.056092,277.886810,14.156230,0.560921,-233.880844,0.056153,0.000000
72.190002,62.472183,-233.747391,0.007480,0.002208,0.056092,277.890137,14.156399,0.560921,-233.747391,0.056153,0.000000
72.370003,62.450958,-233.880844,0.007472,0.002208,0.056092,277.795746,14.151589,0.560921,-233.880844,0.056153,0.000000
72.550003,62.450584,-233.836365,0.007493,0.002208,0.056092,277.794067,14.151505,0.560921,-233.836365,0.056153,0.000000
72.730003,62.436432,-233.925323,0.007493,0.002208,0.056092,277.731110,14.148297,0.560921,-233.925323,0.056153,0.000000
72.910004,62.436432,-233.925323,0.007485,0.002208,0.056092,277.731110,14.148297,0.560921,-233.925323,0.056153,0.000000
73.090004,62.431969,-233.880844,0.007485,0.002208,0.056092,277.711273,14.147285,0.560921,-233.880844,0.056153,0.000000
73.270004,62.428986,-233.925323,0.007485,0.002208,0.056092,277.697998,14.146610,0.560921,-233.925323,0.056153,0.000000
73.450005,62.411858,-233.969803,0.007485,0.002208,0.056092,277.621796,14.142729,0.560921,-233.969803,0.056153,0.000000
73.630005,62.401802,-234.014282,0.007476,0.002208,0.056092,277.577087,14.140450,0.560921,-234.014282,0.056153,0.000000
73.810005,62.396591,-234.014282,0.007480,0.002208,0.056092,277.553894,14.139270,0.560921,-234.014282,0.056153,0.000000
73.990005,62.394356,-233.969803,0.007472,0.002208,0.056092,277.543945,14.138763,0.560921,-233.969803,0.056153,0.000000
74.170006,62.385788,-234.014282,0.007489,0.002208,0.056092,277.505859,14.136822,0.560921,-234.014282,0.056153,0.000000
74.350006,62.373131,-234.103241,0.007493,0.002208,0.056092,277.449554,14.133953,0.560921,-234.103241,0.056153,0.000000
74.530006,62.361961,-234.014282,0.007489,0.002208,0.056092,277.399872,14.131422,0.560921,-234.014282,0.056153,0.000000
74.700005,62.358238,-234.058762,0.007493,0.002208,0.056092,277.383301,14.130579,0.560921,-234.058762,0.056153,0.000000