File: Data/AG AL compression 300N/AL membrane Peeled 300N_1_1_03192024_180632.csv
Time (sec),S:Load (lbs),S:HL1 (DIM),S:LVDT (in),S:Position (in),Ch:Position (mm),Ch:Load (N),Ch:Stress (MPa),Ch:Strain (mm/mm),Ch:HL1 (DIM),Set Point (),Cycles ()
0.110000,0.004471,-133.442856,-0.000026,-0.000000,-0.000000,0.019887,0.001013,-0.000000,-133.442856,0.000156,0.000000
0.320000,0.000374,-133.531815,-0.000004,-0.000000,-0.000000,0.001663,0.000085,-0.000000,-133.531815,0.000156,0.000000
0.530000,-0.008194,-133.487335,-0.000009,0.000093,0.002350,-0.036449,-0.001857,0.023500,-133.487335,0.003157,0.000000
0.740000,-0.009308,-133.531815,0.000091,0.000217,0.005515,-0.041403,-0.002109,0.055153,-133.531815,0.006660,0.000000
0.950000,-0.008934,-133.576294,0.000177,0.000352,0.008941,-0.039741,-0.002024,0.089411,-133.576294,0.010164,0.000000
1.160000,0.011543,-133.576294,0.000336,0.000484,0.012306,0.051347,0.002616,0.123058,-133.576294,0.013667,0.000000
1.370000,0.012291,-133.709732,0.000479,0.000623,0.015827,0.054673,0.002785,0.158265,-133.709732,0.017154,0.000000
1.580000,0.003349,-133.665253,0.000625,0.000764,0.019399,0.014898,0.000759,0.193995,-133.665253,0.020657,0.000000
1.790000,0.010056,-133.754227,0.000780,0.000909,0.023094,0.044729,0.002279,0.230939,-133.754227,0.024161,0.000000
2.000000,0.005959,-133.754227,0.000897,0.001051,0.026693,0.026505,0.001350,0.266930,-133.754227,0.027647,0.000000
2.210000,-0.027931,-133.754227,0.001026,0.001185,0.030093,-0.124244,-0.006329,0.300926,-133.754227,0.031150,0.000000
2.420000,0.002609,-133.887665,0.001173,0.001320,0.033527,0.011607,0.000591,0.335266,-133.887665,0.034654,0.000000
2.630000,-0.019363,-133.887665,0.001306,0.001457,0.036996,-0.086133,-0.004388,0.369958,-133.887665,0.038158,0.000000
2.840000,-0.016014,-133.887665,0.001470,0.001595,0.040525,-0.071234,-0.003629,0.405252,-133.887665,0.041644,0.000000
3.050000,-0.010796,-133.976624,0.001595,0.001732,0.043985,-0.048021,-0.002446,0.439854,-133.976624,0.045148,0.000000
3.260000,0.005211,-133.976624,0.001742,0.001869,0.047480,0.023179,0.001181,0.474804,-133.976624,0.048651,0.000000
3.470000,0.000374,-134.110062,0.001893,0.002006,0.050941,0.001663,0.000085,0.509405,-134.110062,0.052137,0.000000
3.680000,0.037979,-134.021103,0.001996,0.002142,0.054401,0.168940,0.008606,0.544011,-134.021103,0.055641,0.000000
3.890000,0.012657,-134.154541,0.002160,0.002279,0.057879,0.056302,0.002868,0.578786,-134.154541,0.059145,0.000000
4.100000,0.021225,-134.154541,0.002302,0.002428,0.061660,0.094413,0.004810,0.616597,-134.154541,0.062648,0.000000
4.310000,0.033882,-134.110062,0.002453,0.002566,0.065180,0.150715,0.007678,0.651804,-134.110062,0.066135,0.000000
4.520000,0.023834,-134.243515,0.002578,0.002705,0.068710,0.106020,0.005401,0.687102,-134.243515,0.069638,0.000000
4.730000,-0.020477,-134.199036,0.002721,0.002839,0.072110,-0.091088,-0.004640,0.721098,-134.199036,0.073142,0.000000
4.940000,-0.020477,-134.243515,0.002859,0.002974,0.075544,-0.091088,-0.004640,0.755439,-134.243515,0.076628,0.000000
5.150000,-0.036118,-134.376953,0.003005,0.003108,0.078935,-0.160659,-0.008184,0.789347,-134.376953,0.080132,0.000000
5.360000,-0.006706,-134.332474,0.003117,0.003245,0.082421,-0.029831,-0.001520,0.824210,-134.332474,0.083635,0.000000
5.570000,-0.052879,-134.421432,0.003281,0.003382,0.085899,-0.235219,-0.011983,0.858986,-134.421432,0.087138,0.000000
5.780000,0.019363,-134.376953,0.003406,0.003525,0.089541,0.086133,0.004388,0.895408,-134.376953,0.090625,0.000000
5.990000,0.029793,-134.421432,0.003544,0.003660,0.092975,0.132525,0.006751,0.929752,-134.421432,0.094128,0.000000
6.200000,0.050644,-134.554871,0.003665,0.003798,0.096478,0.225275,0.011476,0.964785,-134.554871,0.097632,0.000000
6.410000,0.053619,-134.510391,0.003850,0.003940,0.100078,0.238511,0.012150,1.000775,-134.510391,0.101118,0.000000
6.620000,0.022339,-134.643845,0.003997,0.004081,0.103650,0.099368,0.005062,1.036505,-134.643845,0.104622,0.000000
6.830000,0.015640,-134.643845,0.004135,0.004219,0.107154,0.069571,0.003544,1.071542,-134.643845,0.108125,0.000000
7.040000,0.001488,-134.643845,0.004260,0.004356,0.110632,0.006618,0.000337,1.106317,-134.643845,0.111612,0.000000
7.250000,0.005211,-134.732803,0.004381,0.004485,0.113910,0.023179,0.001181,1.139098,-134.732803,0.115115,0.000000
7.460001,-0.036118,-134.732803,0.004536,0.004624,0.117457,-0.160659,-0.008184,1.174570,-134.732803,0.118619,0.000000
7.670001,-0.051392,-134.732803,0.004687,0.004759,0.120874,-0.228601,-0.011646,1.208737,-134.732803,0.122123,0.000000
7.880001,-0.033142,-134.821762,0.004803,0.004895,0.124325,-0.147423,-0.007510,1.243255,-134.821762,0.125609,0.000000
8.090000,0.002975,-134.866241,0.004954,0.005036,0.127907,0.013236,0.000674,1.279071,-134.866241,0.129112,0.000000
8.300000,0.022713,-134.910721,0.005096,0.005177,0.131506,0.101031,0.005147,1.315058,-134.910721,0.132616,0.000000
8.510000,0.042450,-134.955200,0.005217,0.005314,0.134966,0.188827,0.009619,1.349663,-134.955200,0.136102,0.000000
8.720000,0.038727,-134.999680,0.005376,0.005452,0.138470,0.172265,0.008776,1.384696,-134.999680,0.139606,0.000000
8.930000,0.036491,-135.088654,0.005536,0.005592,0.142034,0.162322,0.008269,1.420339,-135.088654,0.143110,0.000000
9.140000,0.018616,-134.999680,0.005644,0.005729,0.145520,0.082807,0.004218,1.455201,-134.999680,0.146613,0.000000
9.350000,0.012657,-135.133133,0.005808,0.005863,0.148928,0.056302,0.002868,1.489284,-135.133133,0.150099,0.000000
9.560000,-0.001862,-135.088654,0.005933,0.006002,0.152450,-0.008281,-0.000422,1.524495,-135.088654,0.153603,0.000000
9.770000,-0.056976,-135.133133,0.006088,0.006141,0.155979,-0.253443,-0.012911,1.559789,-135.133133,0.157106,0.000000
9.980000,-0.040962,-135.133133,0.006204,0.006278,0.159474,-0.182209,-0.009282,1.594739,-135.133133,0.160593,0.000000
10.190001,0.005959,-135.177612,0.006368,0.006415,0.162943,0.026505,0.001350,1.629428,-135.177612,0.164096,0.000000
10.400001,0.002609,-135.266571,0.006497,0.006553,0.166446,0.011607,0.000591,1.664464,-135.266571,0.167600,0.000000
10.610001,0.013031,-135.266571,0.006640,0.006696,0.170072,0.057965,0.002953,1.700716,-135.266571,0.171103,0.000000
10.820001,0.022713,-135.311050,0.006791,0.006836,0.173627,0.101031,0.005147,1.736271,-135.311050,0.174590,0.000000
11.030001,0.024574,-135.311050,0.006920,0.006969,0.177009,0.109312,0.005569,1.770093,-135.311050,0.178093,0.000000
11.240001,0.030907,-135.355530,0.007058,0.007098,0.180279,0.137480,0.007004,1.802787,-135.355530,0.181597,0.000000
11.450001,0.020111,-135.488983,0.007187,0.007240,0.183904,0.089459,0.004557,1.839039,-135.488983,0.185083,0.000000
11.660001,0.002609,-135.533463,0.007343,0.007377,0.187381,0.011607,0.000591,1.873814,-135.533463,0.188587,0.000000
11.870001,0.006699,-135.488983,0.007463,0.007519,0.190989,0.029797,0.001518,1.909888,-135.488983,0.192090,0.000000
12.080001,-0.008934,-135.622421,0.007606,0.007658,0.194510,-0.039741,-0.002024,1.945099,-135.622421,0.195594,0.000000
12.290001,0.007446,-135.533463,0.007761,0.007794,0.197961,0.033123,0.001687,1.979614,-135.533463,0.199080,0.000000
12.500001,0.013779,-135.622421,0.007903,0.007931,0.201448,0.061291,0.003122,2.014476,-135.622421,0.202584,0.000000
12.710001,0.000748,-135.666901,0.008028,0.008070,0.204969,0.003326,0.000169,2.049687,-135.666901,0.206087,0.000000
12.920001,0.023834,-135.622421,0.008192,0.008207,0.208455,0.106020,0.005401,2.084550,-135.622421,0.209573,0.000000
13.130001,0.031654,-135.755859,0.008317,0.008347,0.212011,0.140806,0.007173,2.120105,-135.755859,0.213077,0.000000
13.340001,0.026810,-135.755859,0.008472,0.008481,0.215428,0.119255,0.006075,2.154275,-135.755859,0.216581,0.000000
13.550000,0.032394,-135.755859,0.008589,0.008615,0.218810,0.144098,0.007341,2.188097,-135.755859,0.220067,0.000000
13.760000,0.024200,-135.844818,0.008709,0.008749,0.222235,0.107649,0.005484,2.222350,-135.844818,0.223571,0.000000
13.970000,0.034256,-135.889313,0.008852,0.008886,0.225713,0.152378,0.007763,2.257126,-135.889313,0.227074,0.000000
14.180000,-0.004471,-135.978271,0.008998,0.009030,0.229355,-0.019887,-0.001013,2.293552,-135.978271,0.230578,0.000000
14.390000,0.033516,-135.889313,0.009153,0.009174,0.233032,0.149086,0.007595,2.330322,-135.889313,0.234064,0.000000
14.600000,0.018242,-135.978271,0.009309,0.009311,0.236510,0.081144,0.004134,2.365098,-135.978271,0.237568,0.000000
14.810000,0.007820,-136.022751,0.009438,0.009450,0.240022,0.034786,0.001772,2.400218,-136.022751,0.241071,0.000000
15.020000,0.017128,-136.022751,0.009576,0.009585,0.243465,0.076189,0.003881,2.434649,-136.022751,0.244558,0.000000
15.230000,0.029419,-136.156189,0.009722,0.009722,0.246934,0.130862,0.006666,2.469337,-136.156189,0.248061,0.000000
15.440001,0.020851,-136.111710,0.009852,0.009858,0.250403,0.092750,0.004725,2.504026,-136.111710,0.251565,0.000000
15.650001,0.027557,-136.245148,0.009998,0.009998,0.253958,0.122581,0.006245,2.539581,-136.245148,0.255068,0.000000
15.860001,0.033142,-136.245148,0.010123,0.010131,0.257332,0.147423,0.007510,2.573316,-136.245148,0.258554,0.000000
16.070002,0.023460,-136.200668,0.010266,0.010267,0.260775,0.104357,0.005316,2.607747,-136.200668,0.262058,0.000000
16.280001,0.021599,-136.334122,0.010417,0.010400,0.264157,0.096076,0.004894,2.641569,-136.334122,0.265562,0.000000
16.490002,0.042076,-136.289627,0.010550,0.010544,0.267817,0.187164,0.009535,2.678165,-136.289627,0.269048,0.000000
16.700001,0.057716,-136.378601,0.010710,0.010688,0.271476,0.256735,0.013079,2.714761,-136.378601,0.272551,0.000000
16.910002,0.051384,-136.378601,0.010843,0.010829,0.275049,0.228567,0.011644,2.750491,-136.378601,0.276055,0.000000
17.120001,0.061813,-136.378601,0.010986,0.010964,0.278483,0.274960,0.014007,2.784835,-136.378601,0.279559,0.000000
17.330000,0.031281,-136.467560,0.011128,0.011103,0.282013,0.139143,0.007088,2.820129,-136.467560,0.283045,0.000000
17.540001,-0.000374,-136.467560,0.011275,0.011239,0.285473,-0.001663,-0.000085,2.854731,-136.467560,0.286548,0.000000
17.750000,0.011169,-136.556519,0.011395,0.011375,0.288925,0.049684,0.002531,2.889249,-136.556519,0.290052,0.000000
17.960001,-0.002235,-136.556519,0.011525,0.011508,0.292316,-0.009944,-0.000507,2.923158,-136.556519,0.293538,0.000000
18.170000,0.017502,-136.645477,0.011676,0.011648,0.295854,0.077852,0.003966,2.958539,-136.645477,0.297042,0.000000
18.380001,0.001862,-136.689957,0.011801,0.011783,0.299279,0.008281,0.000422,2.992792,-136.689957,0.300546,0.000000
18.590000,0.040215,-136.689957,0.011939,0.011923,0.302844,0.178883,0.009113,3.028438,-136.689957,0.304049,0.000000
18.800001,0.059578,-136.734436,0.012089,0.012058,0.306278,0.265016,0.013501,3.062779,-136.734436,0.307535,0.000000
19.010000,0.061813,-136.734436,0.012219,0.012203,0.309955,0.274960,0.014007,3.099549,-136.734436,0.311039,0.000000
19.220001,0.068886,-136.778931,0.012383,0.012341,0.313467,0.306419,0.015610,3.134673,-136.778931,0.314543,0.000000
19.430000,0.051384,-136.867889,0.012512,0.012484,0.317083,0.228567,0.011644,3.170834,-136.867889,0.318029,0.000000
19.640001,0.028671,-136.867889,0.012641,0.012617,0.320474,0.127536,0.006497,3.204742,-136.867889,0.321532,0.000000
19.850000,0.006699,-136.867889,0.012792,0.012754,0.323961,0.029797,0.001518,3.239605,-136.867889,0.325036,0.000000
20.060001,-0.013405,-136.956848,0.012917,0.012886,0.327317,-0.059628,-0.003038,3.273170,-136.956848,0.328522,0.000000
20.270000,-0.017502,-137.001328,0.013064,0.013026,0.330855,-0.077852,-0.003966,3.308551,-137.001328,0.332026,0.000000
20.480001,-0.019737,-137.090286,0.013210,0.013161,0.334289,-0.087796,-0.004473,3.342895,-137.090286,0.335529,0.000000
20.690001,0.016754,-137.045807,0.013344,0.013300,0.337828,0.074526,0.003797,3.378276,-137.045807,0.339033,0.000000
20.900002,0.046547,-137.090286,0.013499,0.013441,0.341401,0.207051,0.010548,3.414006,-137.090286,0.342519,0.000000
21.110001,0.059952,-137.134766,0.013620,0.013579,0.344896,0.266679,0.013585,3.448955,-137.134766,0.346023,0.000000
21.320002,0.069633,-137.134766,0.013758,0.013715,0.348356,0.309745,0.015779,3.483557,-137.134766,0.349526,0.000000
21.530001,0.052132,-137.268219,0.013900,0.013852,0.351851,0.231893,0.011813,3.518507,-137.268219,0.353013,0.000000
21.740002,0.053993,-137.223740,0.014051,0.013994,0.355441,0.240174,0.012235,3.554410,-137.223740,0.356516,0.000000
21.950001,0.021973,-137.268219,0.014181,0.014133,0.358988,0.097739,0.004979,3.589878,-137.268219,0.360020,0.000000
22.160002,0.024200,-137.357178,0.014301,0.014264,0.362309,0.107649,0.005484,3.623095,-137.357178,0.363524,0.000000
22.370001,-0.000000,-137.268219,0.014452,0.014403,0.365839,-0.000000,-0.000000,3.658389,-137.268219,0.367010,0.000000
22.580002,-0.019363,-137.446136,0.014573,0.014540,0.369308,-0.086133,-0.004388,3.693077,-137.446136,0.370513,0.000000
22.790001,0.003349,-137.446136,0.014720,0.014677,0.372803,0.014898,0.000759,3.728027,-137.446136,0.374017,0.000000
23.000002,0.035378,-137.446136,0.014879,0.014817,0.376341,0.157367,0.008017,3.763412,-137.446136,0.377503,0.000000
23.210001,0.043938,-137.490616,0.015000,0.014957,0.379905,0.195445,0.009956,3.799054,-137.490616,0.381007,0.000000
23.420002,0.049522,-137.535095,0.015142,0.015098,0.383496,0.220287,0.011222,3.834958,-137.535095,0.384510,0.000000
23.630001,0.050270,-137.579575,0.015280,0.015233,0.386912,0.223612,0.011391,3.869124,-137.579575,0.388014,0.000000
23.840002,0.070007,-137.579575,0.015409,0.015366,0.390286,0.311408,0.015864,3.902863,-137.579575,0.391500,0.000000
24.050001,0.038727,-137.624069,0.015565,0.015503,0.393772,0.172265,0.008776,3.937721,-137.624069,0.395004,0.000000
24.260000,0.033882,-137.713028,0.015694,0.015642,0.397311,0.150715,0.007678,3.973106,-137.713028,0.398507,0.000000
24.470001,0.032021,-137.757507,0.015832,0.015781,0.400840,0.142435,0.007256,4.008400,-137.757507,0.401994,0.000000
24.680000,0.038353,-137.757507,0.015983,0.015919,0.404335,0.170603,0.008691,4.043350,-137.757507,0.405497,0.000000
24.890001,0.017876,-137.757507,0.016129,0.016059,0.407891,0.079515,0.004051,4.078909,-137.757507,0.409001,0.000000
25.100000,0.061813,-137.801987,0.016259,0.016196,0.411377,0.274960,0.014007,4.113768,-137.801987,0.412504,0.000000
25.310001,0.086761,-137.890945,0.016397,0.016332,0.414837,0.385934,0.019660,4.148374,-137.890945,0.415991,0.000000
25.520000,0.107246,-137.801987,0.016530,0.016474,0.418445,0.477056,0.024302,4.184447,-137.801987,0.419494,0.000000
25.730001,0.161240,-137.935425,0.016664,0.016612,0.421940,0.717230,0.036537,4.219397,-137.935425,0.422998,0.000000
25.940001,0.234222,-137.935425,0.016793,0.016749,0.425417,1.041873,0.053076,4.254173,-137.935425,0.426484,0.000000
26.150002,0.342957,-137.979904,0.016940,0.016882,0.428791,1.525547,0.077715,4.287908,-137.979904,0.429988,0.000000
26.360001,0.484459,-138.024384,0.017061,0.017015,0.432182,2.154981,0.109780,4.321816,-138.024384,0.433491,0.000000
26.570002,0.678459,-138.024384,0.017203,0.017124,0.434948,3.017937,0.153741,4.349480,-138.024384,0.435156,0.000000
26.780001,0.564514,-138.113358,0.017190,-0.000000,-0.000000,2.511084,0.127921,-0.000000,-138.113358,0.000225,0.000000
26.990002,0.559303,-138.113358,0.017181,-0.000000,-0.000000,2.487905,0.126740,-0.000000,-138.113358,0.000225,0.000000
27.200001,0.613297,-138.157837,0.017203,-0.000000,-0.000000,2.728079,0.138975,-0.000000,-138.157837,0.000355,0.000000
27.410002,0.584999,-138.202316,0.017194,-0.000000,-0.000000,2.602206,0.132563,-0.000000,-138.202316,0.000711,0.000000
27.620001,0.566002,-138.202316,0.017186,-0.000000,-0.000000,2.517702,0.128258,-0.000000,-138.202316,0.001058,0.000000
27.830002,0.573456,-138.246796,0.017203,0.000010,0.000243,2.550859,0.129947,0.002426,-138.246796,0.001405,0.000000
28.040001,0.739159,-138.291275,0.017216,0.000032,0.000824,3.287942,0.167496,0.008236,-138.291275,0.001760,0.000000
28.250002,0.776024,-138.291275,0.017237,0.000048,0.001231,3.451926,0.175850,0.012312,-138.291275,0.002107,0.000000
28.460001,0.790176,-138.424713,0.017246,0.000059,0.001500,3.514880,0.179057,0.015003,-138.424713,0.002454,0.000000
28.670002,0.773415,-138.335754,0.017250,0.000071,0.001795,3.440320,0.175258,0.017952,-138.335754,0.002810,0.000000
28.880001,0.809166,-138.469208,0.017259,0.000087,0.002211,3.599350,0.183360,0.022111,-138.469208,0.003157,0.000000
29.090002,0.861298,-138.469208,0.017272,0.000097,0.002454,3.831243,0.195173,0.024541,-138.469208,0.003512,0.000000
29.300001,0.956993,-138.469208,0.017315,0.000113,0.002862,4.256918,0.216858,0.028618,-138.469208,0.003859,0.000000
29.510002,0.999077,-138.558167,0.017311,0.000124,0.003148,4.444116,0.226394,0.031479,-138.558167,0.004206,0.000000
29.720001,1.040405,-138.513687,0.017311,0.000134,0.003399,4.627954,0.235759,0.033992,-138.513687,0.004562,0.000000
29.930002,1.141693,-138.647125,0.017328,0.000149,0.003781,5.078505,0.258711,0.037811,-138.647125,0.004908,0.000000
30.140001,1.189728,-138.647125,0.017337,0.000167,0.004241,5.292173,0.269596,0.042406,-138.647125,0.005255,0.000000
30.350002,1.288033,-138.691605,0.017375,0.000184,0.004683,5.729455,0.291872,0.046831,-138.691605,0.005611,0.000000
30.560001,1.300323,-138.780563,0.017371,0.000195,0.004960,5.784128,0.294658,0.049605,-138.780563,0.005958,0.000000
30.770002,1.317451,-138.736084,0.017393,0.000209,0.005298,5.860317,0.298539,0.052985,-138.736084,0.006304,0.000000
30.980001,1.386345,-138.825043,0.017397,0.000223,0.005663,6.166770,0.314150,0.056630,-138.825043,0.006660,0.000000
31.190001,1.518906,-138.825043,0.017406,0.000236,0.005992,6.756430,0.344189,0.059922,-138.825043,0.007007,0.000000
31.400002,1.624290,-138.825043,0.017449,0.000249,0.006322,7.225205,0.368069,0.063219,-138.825043,0.007363,0.000000
31.610001,1.670837,-138.958496,0.017440,0.000257,0.006539,7.432256,0.378617,0.065388,-138.958496,0.007709,0.000000
31.820002,1.859253,-138.914017,0.017449,0.000273,0.006946,8.270370,0.421313,0.069464,-138.914017,0.008057,0.000000
32.030003,2.030174,-139.002975,0.017462,0.000299,0.007597,9.030666,0.460044,0.075967,-139.002975,0.008412,0.000000
32.240002,2.061829,-139.002975,0.017488,0.000309,0.007857,9.171472,0.467217,0.078571,-139.002975,0.008759,0.000000
32.450001,2.204445,-139.002975,0.017496,0.000325,0.008256,9.805861,0.499534,0.082560,-139.002975,0.009106,0.000000
32.660000,2.283386,-139.136414,0.017509,0.000337,0.008551,10.157009,0.517423,0.085508,-139.136414,0.009461,0.000000
32.870003,2.338501,-139.091934,0.017518,0.000344,0.008742,10.402172,0.529912,0.087416,-139.091934,0.009808,0.000000
33.080002,2.645706,-139.225372,0.017539,0.000363,0.009227,11.768689,0.599526,0.092272,-139.225372,0.010155,0.000000
33.290001,2.773056,-139.180893,0.017526,0.000374,0.009505,12.335169,0.628383,0.095046,-139.180893,0.010511,0.000000
33.500000,2.971535,-139.225372,0.017569,0.000390,0.009904,13.218046,0.673359,0.099036,-139.225372,0.010857,0.000000
33.710003,3.099625,-139.269852,0.017561,0.000400,0.010172,13.787819,0.702385,0.101723,-139.269852,0.011213,0.000000
33.920002,3.272781,-139.225372,0.017574,0.000416,0.010554,14.558059,0.741623,0.105542,-139.225372,0.011560,0.000000
34.130001,3.528976,-139.403305,0.017604,0.000432,0.010970,15.697671,0.799677,0.109701,-139.403305,0.011907,0.000000
34.340000,3.655579,-139.358826,0.017591,0.000446,0.011326,16.260826,0.828366,0.113259,-139.358826,0.012262,0.000000
34.550003,3.893524,-139.403305,0.017630,0.000459,0.011655,17.319260,0.882285,0.116552,-139.403305,0.012609,0.000000
34.760002,4.029068,-139.536743,0.017638,0.000470,0.011950,17.922190,0.913000,0.119500,-139.536743,0.012956,0.000000
34.970001,4.353409,-139.536743,0.017638,0.000486,0.012332,19.364929,0.986497,0.123319,-139.536743,0.013312,0.000000
35.180000,4.619652,-139.536743,0.017651,0.000502,0.012740,20.549238,1.046828,0.127396,-139.536743,0.013659,0.000000
35.390003,4.736946,-139.581223,0.017669,0.000511,0.012982,21.070988,1.073407,0.129822,-139.581223,0.014006,0.000000
35.600002,4.982712,-139.625702,0.017677,0.000524,0.013312,22.164209,1.129099,0.133119,-139.625702,0.014361,0.000000
35.810001,5.321571,-139.670181,0.017682,0.000541,0.013754,23.671532,1.205885,0.137539,-139.670181,0.014708,0.000000
36.020000,5.620590,-139.625702,0.017712,0.000556,0.014110,25.001635,1.273644,0.141097,-139.625702,0.015055,0.000000
36.230003,6.014191,-139.714661,0.017733,0.000572,0.014517,26.752457,1.362835,0.145173,-139.714661,0.015411,0.000000
36.440002,6.281921,-139.714661,0.017733,0.000586,0.014881,27.943382,1.423504,0.148814,-139.714661,0.015757,0.000000
36.650002,6.471458,-139.803635,0.017742,0.000596,0.015150,28.786486,1.466453,0.151502,-139.803635,0.016113,0.000000
36.860001,6.728767,-139.848114,0.017759,0.000611,0.015515,29.931053,1.524760,0.155147,-139.848114,0.016460,0.000000
37.070004,7.075821,-139.803635,0.017785,0.000623,0.015835,31.474823,1.603404,0.158352,-139.803635,0.016807,0.000000
37.280003,7.332382,-139.937073,0.017772,0.000639,0.016243,32.616066,1.661542,0.162429,-139.937073,0.017162,0.000000
37.490002,7.495857,-139.892593,0.017781,0.000644,0.016364,33.343239,1.698586,0.163644,-139.892593,0.017509,0.000000
37.700001,8.201500,-139.892593,0.017798,0.000670,0.017015,36.482094,1.858487,0.170150,-139.892593,0.017856,0.000000
37.910004,8.431625,-140.026031,0.017824,0.000682,0.017319,37.505741,1.910634,0.173185,-140.026031,0.018212,0.000000
38.120003,8.915344,-139.937073,0.017832,0.000700,0.017769,39.657433,2.020246,0.177693,-139.937073,0.018558,0.000000
38.330002,9.048279,-140.070511,0.017850,0.000711,0.018055,40.248753,2.050369,0.180555,-140.070511,0.018906,0.000000
38.540001,9.418785,-140.070511,0.017858,0.000724,0.018385,41.896847,2.134327,0.183851,-140.070511,0.019261,0.000000
38.750000,9.766586,-140.070511,0.017876,0.000738,0.018749,43.443947,2.213140,0.187492,-140.070511,0.019608,0.000000
38.960003,10.172096,-140.203964,0.017867,0.000754,0.019139,45.247746,2.305030,0.191395,-140.203964,0.019963,0.000000
39.170002,10.441322,-140.114990,0.017888,0.000766,0.019460,46.445320,2.366037,0.194604,-140.114990,0.020310,0.000000
39.380001,10.603676,-140.203964,0.017893,0.000776,0.019703,47.167507,2.402827,0.197034,-140.203964,0.020657,0.000000
39.590000,11.283630,-140.248444,0.017901,0.000793,0.020145,50.192093,2.556907,0.201455,-140.248444,0.021013,0.000000
39.800003,11.615784,-140.292923,0.017914,0.000808,0.020536,51.669586,2.632174,0.205357,-140.292923,0.021360,0.000000
40.010002,11.984062,-140.337402,0.017923,0.000824,0.020917,53.307770,2.715627,0.209172,-140.337402,0.021706,0.000000
40.220001,12.025024,-140.337402,0.017927,0.000834,0.021186,53.489979,2.724910,0.211863,-140.337402,0.022062,0.000000
40.430000,12.582466,-140.470840,0.017966,0.000849,0.021577,55.969604,2.851228,0.215766,-140.470840,0.022409,0.000000
40.640003,12.816315,-140.470840,0.017966,0.000860,0.021837,57.009815,2.904218,0.218366,-140.470840,0.022756,0.000000
40.850002,13.195763,-140.426361,0.017970,0.000875,0.022227,58.697685,2.990203,0.222268,-140.426361,0.023111,0.000000
41.060001,13.893959,-140.515320,0.017988,0.000894,0.022712,61.803417,3.148416,0.227124,-140.515320,0.023458,0.000000
41.270000,13.742035,-140.515320,0.018001,0.000899,0.022843,61.127625,3.113990,0.228426,-140.515320,0.023814,0.000000
41.480003,13.927475,-140.648773,0.017996,0.000913,0.023198,61.952503,3.156011,0.231980,-140.648773,0.024161,0.000000
41.690002,14.789520,-140.604294,0.018022,0.000932,0.023675,65.787071,3.351353,0.236753,-140.604294,0.024508,0.000000
41.900002,15.221466,-140.604294,0.018035,0.000947,0.024048,67.708466,3.449234,0.240481,-140.604294,0.024863,0.000000
42.110001,15.478035,-140.782211,0.018035,0.000959,0.024360,68.849739,3.507373,0.243603,-140.782211,0.025210,0.000000
42.320004,15.651932,-140.648773,0.018048,0.000971,0.024655,69.623268,3.546778,0.246552,-140.648773,0.025557,0.000000
42.530003,16.126335,-140.782211,0.018057,0.000986,0.025037,71.733521,3.654280,0.250367,-140.782211,0.025913,0.000000
42.740002,16.377312,-140.737732,0.018078,0.000999,0.025366,72.849922,3.711152,0.253664,-140.737732,0.026260,0.000000
42.950001,17.032692,-140.782211,0.018087,0.001015,0.025782,75.765198,3.859663,0.257823,-140.782211,0.026606,0.000000
43.160004,17.243820,-140.826691,0.018104,0.001025,0.026034,76.704346,3.907505,0.260340,-140.826691,0.026962,0.000000
43.370003,17.394630,-140.915649,0.018100,0.001035,0.026285,77.375183,3.941679,0.262853,-140.915649,0.027309,0.000000
43.580002,18.148315,-140.915649,0.018126,0.001053,0.026754,80.727737,4.112467,0.267539,-140.915649,0.027656,0.000000
43.790001,18.620857,-140.960129,0.018126,0.001071,0.027205,82.829712,4.219547,0.272047,-140.960129,0.028011,0.000000
44.000004,18.788055,-141.049103,0.018151,0.001079,0.027413,83.573448,4.257434,0.274129,-141.049103,0.028358,0.000000
44.210003,19.274368,-141.049103,0.018151,0.001096,0.027847,85.736671,4.367634,0.278466,-141.049103,0.028714,0.000000
44.420002,19.559982,-141.004608,0.018164,0.001106,0.028098,87.007149,4.432355,0.280979,-141.004608,0.029060,0.000000
44.630001,20.068642,-141.182541,0.018182,0.001121,0.028462,89.269775,4.547619,0.284620,-141.182541,0.029407,0.000000
44.840004,20.403404,-141.093582,0.018182,0.001131,0.028740,90.758873,4.623477,0.287398,-141.093582,0.029763,0.000000
45.050003,20.838333,-141.138062,0.018182,0.001146,0.029104,92.693535,4.722034,0.291039,-141.138062,0.030110,0.000000
45.260002,20.910202,-141.271500,0.018212,0.001153,0.029277,93.013222,4.738319,0.292773,-141.271500,0.030457,0.000000
45.470001,22.287979,-141.227020,0.018216,0.001178,0.029928,99.141884,5.050529,0.299279,-141.227020,0.030812,0.000000
45.680000,22.429108,-141.315979,0.018220,0.001190,0.030223,99.769653,5.082509,0.302228,-141.315979,0.031159,0.000000
45.890003,23.031609,-141.315979,0.018251,0.001207,0.030656,102.449715,5.219037,0.306561,-141.315979,0.031506,0.000000
46.100002,23.457603,-141.271500,0.018246,0.001220,0.030986,104.344635,5.315569,0.309858,-141.271500,0.031862,0.000000
46.310001,23.697037,-141.404938,0.018242,0.001232,0.031289,105.409683,5.369825,0.312893,-141.404938,0.032209,0.000000
46.520000,24.013557,-141.404938,0.018259,0.001243,0.031575,106.817635,5.441550,0.315755,-141.404938,0.032564,0.000000
46.730003,24.852882,-141.493912,0.018268,0.001259,0.031974,110.551140,5.631744,0.319744,-141.493912,0.032911,0.000000
46.940002,24.958633,-141.449417,0.018268,0.001265,0.032139,111.021545,5.655707,0.321391,-141.449417,0.033258,0.000000
47.150002,25.306801,-141.538391,0.018289,0.001278,0.032451,112.570274,5.734603,0.324513,-141.538391,0.033614,0.000000
47.360001,26.529305,-141.627350,0.018294,0.001298,0.032980,118.008240,6.011626,0.329804,-141.627350,0.033960,0.000000
47.570004,26.998863,-141.627350,0.018302,0.001313,0.033353,120.096939,6.118030,0.333533,-141.627350,0.034307,0.000000
47.780003,27.566734,-141.716309,0.018307,0.001326,0.033674,122.622955,6.246711,0.336742,-141.716309,0.034663,0.000000
47.990002,28.043373,-141.716309,0.018315,0.001340,0.034030,124.743156,6.354719,0.340296,-141.716309,0.035010,0.000000
48.200001,28.768753,-141.671829,0.018337,0.001354,0.034403,127.969803,6.519093,0.344028,-141.671829,0.035357,0.000000
48.410004,28.923286,-141.805267,0.018341,0.001362,0.034585,128.657211,6.554111,0.345849,-141.805267,0.035712,0.000000
48.620003,29.992737,-141.716309,0.018358,0.001382,0.035105,133.414352,6.796452,0.351053,-141.716309,0.036059,0.000000
48.830002,30.151001,-141.849747,0.018371,0.001391,0.035339,134.118347,6.832314,0.353392,-141.849747,0.036415,0.000000
49.040001,30.551674,-141.805267,0.018363,0.001400,0.035556,135.900635,6.923109,0.355561,-141.805267,0.036762,0.000000
49.250004,31.418556,-141.805267,0.018380,0.001416,0.035955,139.756714,7.119546,0.359550,-141.805267,0.037109,0.000000
49.460003,32.552803,-141.894241,0.018384,0.001435,0.036441,144.802094,7.376571,0.364406,-141.894241,0.037464,0.000000
49.670002,33.352654,-141.938721,0.018389,0.001450,0.036840,148.360016,7.557819,0.368395,-141.938721,0.037811,0.000000
49.880001,33.830040,-141.983200,0.018414,0.001463,0.037169,150.483536,7.665997,0.371692,-141.983200,0.038158,0.000000
50.090004,34.661545,-142.027679,0.018402,0.001480,0.037594,154.182251,7.854418,0.375942,-142.027679,0.038513,0.000000
50.300003,35.075996,-142.027679,0.018423,0.001489,0.037811,156.025818,7.948334,0.378107,-142.027679,0.038860,0.000000
50.510002,35.784996,-142.116638,0.018427,0.001503,0.038184,159.179611,8.108996,0.381839,-142.116638,0.039207,0.000000
50.720001,36.782951,-142.116638,0.018453,0.001518,0.038565,163.618744,8.335135,0.385654,-142.116638,0.039563,0.000000
50.930004,37.198891,-142.205597,0.018440,0.001531,0.038878,165.468933,8.429390,0.388777,-142.205597,0.039909,0.000000
51.140003,37.291237,-142.205597,0.018458,0.001537,0.039042,165.879700,8.450315,0.390423,-142.205597,0.040257,0.000000
51.350002,38.644814,-142.205597,0.018466,0.001557,0.039537,171.900711,8.757040,0.395366,-142.205597,0.040612,0.000000
51.560001,39.739586,-142.250076,0.018471,0.001573,0.039953,176.770508,9.005119,0.399530,-142.250076,0.040959,0.000000
51.770004,40.686531,-142.205597,0.018471,0.001589,0.040361,180.982727,9.219700,0.403606,-142.205597,0.041314,0.000000
51.980003,40.981827,-142.383530,0.018479,0.001599,0.040603,182.296265,9.286615,0.406032,-142.383530,0.041661,0.000000
52.190002,41.818169,-142.383530,0.018501,0.001614,0.041002,186.016510,9.476132,0.410021,-142.383530,0.042008,0.000000
52.400002,42.739418,-142.339050,0.018501,0.001625,0.041280,190.114426,9.684891,0.412800,-142.339050,0.042364,0.000000
52.610001,43.687485,-142.472488,0.018514,0.001640,0.041644,194.331635,9.899726,0.416441,-142.472488,0.042711,0.000000
52.820004,44.211411,-142.428009,0.018518,0.001650,0.041921,196.662170,10.018449,0.419215,-142.428009,0.043058,0.000000
53.030003,44.966949,-142.516968,0.018505,0.001661,0.042199,200.022980,10.189656,0.421989,-142.516968,0.043413,0.000000
53.240002,45.944801,-142.516968,0.018509,0.001677,0.042589,204.372681,10.411241,0.425892,-142.516968,0.043760,0.000000
53.450001,48.014076,-142.561447,0.018544,0.001701,0.043196,213.577271,10.880145,0.431962,-142.561447,0.044107,0.000000
53.660004,48.475075,-142.605927,0.018544,0.001712,0.043474,215.627899,10.984609,0.434741,-142.605927,0.044463,0.000000
53.870003,49.529259,-142.605927,0.018540,0.001727,0.043864,220.317139,11.223491,0.438643,-142.605927,0.044809,0.000000
54.080002,50.135857,-142.739365,0.018544,0.001739,0.044159,223.015427,11.360948,0.441591,-142.739365,0.045165,0.000000
54.290001,50.540253,-142.739365,0.018574,0.001749,0.044428,224.814270,11.452585,0.444279,-142.739365,0.045512,0.000000
54.500004,52.048729,-142.783859,0.018570,0.001764,0.044818,231.524307,11.794411,0.448181,-142.783859,0.045859,0.000000
54.710003,52.944290,-142.872818,0.018565,0.001777,0.045130,235.507965,11.997347,0.451303,-142.872818,0.046214,0.000000
54.920002,54.102364,-142.828339,0.018591,0.001791,0.045486,240.659332,12.259770,0.454857,-142.828339,0.046561,0.000000
55.130001,54.695183,-142.917297,0.018587,0.001800,0.045729,243.296326,12.394106,0.457287,-142.917297,0.046908,0.000000
55.340004,56.375702,-142.828339,0.018609,0.001823,0.046310,250.771652,12.774917,0.463097,-142.828339,0.047263,0.000000
55.550003,57.433235,-142.872818,0.018583,0.001837,0.046648,255.475784,13.014557,0.466481,-142.872818,0.047611,0.000000
55.760002,58.301239,-142.961777,0.018609,0.001850,0.046995,259.336853,13.211250,0.469948,-142.961777,0.047957,0.000000
55.970001,59.288025,-143.006256,0.018600,0.001862,0.047298,263.726318,13.434858,0.472983,-143.006256,0.048313,0.000000
56.180004,60.081551,-143.050735,0.018609,0.001874,0.047611,267.256073,13.614674,0.476106,-143.050735,0.048660,0.000000
56.390003,61.741959,-143.050735,0.018626,0.001894,0.048096,274.641937,13.990928,0.480962,-143.050735,0.049016,0.000000
56.600002,62.427498,-143.095215,0.018617,0.001902,0.048304,277.691376,14.146273,0.483043,-143.095215,0.049362,0.000000
56.810001,63.582977,-143.095215,0.018643,0.001916,0.048677,282.831207,14.408109,0.486772,-143.095215,0.049709,0.000000
57.020004,64.326599,-143.139694,0.018630,0.001929,0.049007,286.139008,14.576616,0.490068,-143.139694,0.050065,0.000000
57.230003,66.105423,-143.228668,0.018639,0.001948,0.049475,294.051605,14.979703,0.494750,-143.228668,0.050412,0.000000
57.440002,66.902664,-143.228668,0.018647,0.001958,0.049744,297.597900,15.160360,0.497437,-143.228668,0.050758,0.000000
57.650002,67.330521,-143.228668,0.018652,0.001957,0.049701,299.501129,15.257315,0.497006,-143.228668,0.049917,0.000000
57.860004,66.987198,-143.317627,0.018643,0.001957,0.049701,297.973938,15.179516,0.497006,-143.317627,0.049917,0.000000
58.070004,66.712021,-143.317627,0.018669,0.001956,0.049674,296.749878,15.117160,0.496745,-143.317627,0.049701,0.000000
58.280003,66.469971,-143.362106,0.018665,0.001955,0.049666,295.673187,15.062311,0.496658,-143.362106,0.049701,0.000000
58.490002,66.266663,-143.362106,0.018673,0.001955,0.049657,294.768829,15.016241,0.496571,-143.362106,0.049701,0.000000
58.700005,66.100952,-143.451065,0.018677,0.001955,0.049657,294.031708,14.978690,0.496571,-143.451065,0.049701,0.000000
58.910004,65.953873,-143.451065,0.018656,0.001955,0.049648,293.377472,14.945361,0.496484,-143.451065,0.049701,0.000000
59.120003,65.823914,-143.451065,0.018665,0.001955,0.049648,292.799377,14.915913,0.496484,-143.451065,0.049701,0.000000
59.330002,65.694687,-143.584503,0.018669,0.001954,0.049640,292.224548,14.886628,0.496400,-143.584503,0.049701,0.000000
59.540005,65.596756,-143.540024,0.018665,0.001954,0.049640,291.788940,14.864437,0.496400,-143.540024,0.049701,0.000000
59.750004,65.505905,-143.584503,0.018656,0.001954,0.049640,291.384827,14.843851,0.496400,-143.584503,0.049701,0.000000
59.960003,65.418015,-143.717957,0.018660,0.001954,0.049640,290.993866,14.823934,0.496400,-143.717957,0.049701,0.000000
60.170002,65.346893,-143.628998,0.018665,0.001954,0.049640,290.677490,14.807817,0.496400,-143.628998,0.049701,0.000000
60.380001,65.257523,-143.762436,0.018669,0.001954,0.049640,290.279968,14.787565,0.496400,-143.762436,0.049701,0.000000
60.590004,65.194977,-143.762436,0.018673,0.001954,0.049640,290.001740,14.773393,0.496400,-143.762436,0.049701,0.000000
60.800003,65.122360,-143.762436,0.018665,0.001954,0.049640,289.678711,14.756938,0.496400,-143.762436,0.049701,0.000000
61.010002,65.063889,-143.806915,0.018656,0.001954,0.049640,289.418640,14.743688,0.496400,-143.806915,0.049701,0.000000
61.220001,65.006546,-143.851395,0.018660,0.001954,0.049640,289.163544,14.730694,0.496400,-143.851395,0.049701,0.000000
61.430004,64.936172,-143.940353,0.018673,0.001954,0.049631,288.850525,14.714746,0.496313,-143.940353,0.049701,0.000000
61.640003,64.894836,-143.895874,0.018669,0.001954,0.049631,288.666656,14.705380,0.496313,-143.895874,0.049701,0.000000
61.850002,64.844940,-143.984833,0.018686,0.001954,0.049631,288.444702,14.694074,0.496313,-143.984833,0.049701,0.000000
62.060001,64.808823,-144.073807,0.018669,0.001954,0.049631,288.284027,14.685889,0.496313,-144.073807,0.049701,0.000000
62.270004,64.762650,-144.029312,0.018686,0.001954,0.049631,288.078644,14.675426,0.496313,-144.029312,0.049701,0.000000
62.480003,64.722061,-144.073807,0.018686,0.001954,0.049631,287.898102,14.666229,0.496313,-144.073807,0.049701,0.000000
62.690002,64.685196,-144.118286,0.018677,0.001954,0.049631,287.734131,14.657875,0.496313,-144.118286,0.049701,0.000000
62.900002,64.647949,-144.118286,0.018695,0.001954,0.049631,287.568451,14.649435,0.496313,-144.118286,0.049701,0.000000
63.110004,64.611465,-144.162766,0.018660,0.001954,0.049631,287.406158,14.641167,0.496313,-144.162766,0.049701,0.000000
63.320004,64.580551,-144.118286,0.018665,0.001954,0.049631,287.268646,14.634162,0.496313,-144.118286,0.049701,0.000000
63.530003,64.535492,-144.207245,0.018669,0.001954,0.049631,287.068207,14.623952,0.496313,-144.207245,0.049701,0.000000
63.740002,64.510925,-144.207245,0.018690,0.001954,0.049631,286.958923,14.618384,0.496313,-144.207245,0.049701,0.000000
63.950005,64.476669,-144.340683,0.018673,0.001954,0.049631,286.806549,14.610621,0.496313,-144.340683,0.049701,0.000000
64.160004,64.447617,-144.385162,0.018665,0.001954,0.049631,286.677307,14.604039,0.496313,-144.385162,0.049701,0.000000
64.370003,64.419693,-144.296204,0.018690,0.001954,0.049631,286.553101,14.597712,0.496313,-144.296204,0.049701,0.000000
64.580002,64.378723,-144.385162,0.018673,0.001954,0.049631,286.370850,14.588427,0.496313,-144.385162,0.049701,0.000000
64.790001,64.364578,-144.385162,0.018686,0.001954,0.049631,286.307953,14.585222,0.496313,-144.385162,0.049701,0.000000
65.000000,64.335159,-144.474136,0.018673,0.001954,0.049631,286.177094,14.578555,0.496313,-144.474136,0.049701,0.000000
65.210007,64.306854,-144.518616,0.018677,0.001954,0.049631,286.051178,14.572142,0.496313,-144.518616,0.049701,0.000000
65.420006,64.282288,-144.518616,0.018673,0.001954,0.049631,285.941895,14.566574,0.496313,-144.518616,0.049701,0.000000
65.630005,64.246170,-144.563095,0.018690,0.001954,0.049631,285.781250,14.558390,0.496313,-144.563095,0.049701,0.000000
65.840004,64.225677,-144.563095,0.018682,0.001954,0.049631,285.690094,14.553746,0.496313,-144.563095,0.049701,0.000000
66.050003,64.201477,-144.652054,0.018673,0.001954,0.049631,285.582428,14.548263,0.496313,-144.652054,0.049701,0.000000
66.260002,64.185471,-144.696533,0.018677,0.001954,0.049631,285.511230,14.544636,0.496313,-144.696533,0.049701,0.000000
66.470001,64.168335,-144.696533,0.018677,0.001954,0.049631,285.434998,14.540752,0.496313,-144.696533,0.049701,0.000000
66.680000,64.137054,-144.829971,0.018669,0.001954,0.049631,285.295868,14.533664,0.496313,-144.829971,0.049701,0.000000
66.889999,64.115829,-144.785492,0.018677,0.001954,0.049631,285.201447,14.528854,0.496313,-144.785492,0.049701,0.000000
67.100006,64.078598,-144.874451,0.018682,0.001954,0.049631,285.035828,14.520418,0.496313,-144.874451,0.049701,0.000000
67.310005,64.062210,-144.829971,0.018682,0.001954,0.049631,284.962952,14.516704,0.496313,-144.829971,0.049701,0.000000
67.520004,64.041733,-144.874451,0.018677,0.001954,0.049631,284.871857,14.512064,0.496313,-144.874451,0.049701,0.000000
67.730003,64.019012,-144.918945,0.018682,0.001954,0.049631,284.770782,14.506916,0.496313,-144.918945,0.049701,0.000000
67.940002,64.007843,-144.918945,0.018669,0.001954,0.049631,284.721100,14.504384,0.496313,-144.918945,0.049701,0.000000
68.150002,63.979172,-144.963425,0.018673,0.001954,0.049631,284.593567,14.497888,0.496313,-144.963425,0.049701,0.000000
68.360001,63.977692,-145.052383,0.018677,0.001954,0.049631,284.586975,14.497552,0.496313,-145.052383,0.049701,0.000000
68.570000,63.959808,-145.052383,0.018686,0.001954,0.049631,284.507446,14.493500,0.496313,-145.052383,0.049701,0.000000
68.780006,63.938583,-145.096863,0.018665,0.001954,0.049631,284.413025,14.488689,0.496313,-145.096863,0.049701,0.000000
68.990005,63.933746,-145.096863,0.018669,0.001954,0.049631,284.391510,14.487594,0.496313,-145.096863,0.049701,0.000000
69.200005,63.912521,-145.141342,0.018673,0.001954,0.049631,284.297089,14.482784,0.496313,-145.141342,0.049701,0.000000
69.410004,63.891296,-145.185822,0.018660,0.001954,0.049631,284.202667,14.477974,0.496313,-145.185822,0.049701,0.000000
69.620003,63.876770,-145.274780,0.018673,0.001954,0.049631,284.138062,14.474683,0.496313,-145.274780,0.049701,0.000000
69.830002,63.864853,-145.363754,0.018686,0.001954,0.049631,284.085052,14.471983,0.496313,-145.363754,0.049701,0.000000
70.040001,63.849213,-145.319260,0.018690,0.001954,0.049631,284.015472,14.468438,0.496313,-145.319260,0.049701,0.000000
70.250000,63.830231,-145.363754,0.018686,0.001954,0.049631,283.931061,14.464137,0.496313,-145.363754,0.049701,0.000000
70.460007,63.816452,-145.452713,0.018669,0.001954,0.049631,283.869751,14.461015,0.496313,-145.452713,0.049701,0.000000
70.670006,63.811981,-145.408234,0.018686,0.001954,0.049631,283.849884,14.460002,0.496313,-145.408234,0.049701,0.000000
70.880005,63.785919,-145.452713,0.018673,0.001954,0.049631,283.733948,14.454096,0.496313,-145.452713,0.049701,0.000000
71.090004,63.784790,-145.497192,0.018677,0.001954,0.049631,283.728912,14.453839,0.496313,-145.497192,0.049701,0.000000
71.300003,63.766556,-145.541672,0.018682,0.001954,0.049631,283.647797,14.449708,0.496313,-145.541672,0.049701,0.000000
71.510002,63.752029,-145.586151,0.018673,0.001954,0.049631,283.583191,14.446416,0.496313,-145.586151,0.049701,0.000000
71.720001,63.741226,-145.586151,0.018686,0.001954,0.049631,283.535126,14.443969,0.496313,-145.586151,0.049701,0.000000
71.930000,63.717392,-145.586151,0.018669,0.001954,0.049631,283.429108,14.438568,0.496313,-145.586151,0.049701,0.000000
72.140007,63.715530,-145.630630,0.018673,0.001954,0.049631,283.420837,14.438146,0.496313,-145.630630,0.049701,0.000000
72.350006,63.699142,-145.719589,0.018690,0.001954,0.049631,283.347931,14.434432,0.496313,-145.719589,0.049701,0.000000
72.560005,63.688354,-145.764084,0.018673,0.001954,0.049631,283.299957,14.431988,0.496313,-145.764084,0.049701,0.000000
72.770004,63.674194,-145.764084,0.018686,0.001954,0.049631,283.236969,14.428779,0.496313,-145.764084,0.049701,0.000000
72.980003,63.664154,-145.808563,0.018682,0.001954,0.049631,283.192291,14.426503,0.496313,-145.808563,0.049701,0.000000
73.190002,63.653717,-145.853043,0.018686,0.001954,0.049631,283.145874,14.424139,0.496313,-145.853043,0.049701,0.000000
73.400002,63.651108,-145.808563,0.018682,0.001954,0.049631,283.134277,14.423548,0.496313,-145.808563,0.049701,0.000000
73.610001,63.629150,-145.897522,0.018673,0.001954,0.049631,283.036591,14.418571,0.496313,-145.897522,0.049701,0.000000
73.820000,63.619461,-145.897522,0.018682,0.001954,0.049631,282.993500,14.416375,0.496313,-145.897522,0.049701,0.000000
74.030006,63.606064,-145.942001,0.018686,0.001954,0.049631,282.933899,14.413340,0.496313,-145.942001,0.049701,0.000000
74.240005,63.604935,-145.986481,0.018665,0.001954,0.049631,282.928894,14.413084,0.496313,-145.986481,0.049701,0.000000
74.450005,63.586319,-146.030960,0.018690,0.001954,0.049631,282.846069,14.408866,0.496313,-146.030960,0.049701,0.000000
74.660004,63.568817,-146.164398,0.018677,0.001954,0.049631,282.768219,14.404900,0.496313,-146.164398,0.049701,0.000000
74.870003,63.569931,-146.075439,0.018677,0.001954,0.049631,282.773163,14.405152,0.496313,-146.075439,0.049701,0.000000
75.080002,63.552429,-146.164398,0.018682,0.001954,0.049631,282.695312,14.401187,0.496313,-146.164398,0.049701,0.000000
75.290001,63.552063,-146.164398,0.018669,0.001954,0.049631,282.693695,14.401103,0.496313,-146.164398,0.049701,0.000000
75.500000,63.536057,-146.208893,0.018682,0.001954,0.049631,282.622498,14.397476,0.496313,-146.208893,0.049701,0.000000
75.710007,63.522644,-146.253372,0.018686,0.001954,0.049623,282.562836,14.394437,0.496226,-146.253372,0.049701,0.000000
75.920006,63.524139,-146.297852,0.018695,0.001954,0.049623,282.569489,14.394776,0.496226,-146.297852,0.049701,0.000000
76.130005,63.502914,-146.342331,0.018682,0.001954,0.049623,282.475067,14.389966,0.496226,-146.342331,0.049701,0.000000
76.340004,63.498062,-146.342331,0.018695,0.001954,0.049623,282.453491,14.388866,0.496226,-146.342331,0.049701,0.000000
76.550003,63.466049,-146.297852,0.018686,0.001954,0.049623,282.311096,14.381613,0.496226,-146.297852,0.049701,0.000000
76.760002,63.475723,-146.475769,0.018677,0.001954,0.049623,282.354126,14.383804,0.496226,-146.475769,0.049701,0.000000
76.970001,63.460083,-146.431290,0.018686,0.001954,0.049623,282.284546,14.380260,0.496226,-146.431290,0.049701,0.000000
77.180000,63.455994,-146.431290,0.018686,0.001954,0.049623,282.266357,14.379333,0.496226,-146.431290,0.049701,0.000000
77.390007,63.443695,-146.520248,0.018686,0.001954,0.049623,282.211639,14.376547,0.496226,-146.520248,0.049701,0.000000
77.600006,63.434021,-146.520248,0.018686,0.001954,0.049623,282.168610,14.374354,0.496226,-146.520248,0.049701,0.000000
77.810005,63.423218,-146.564728,0.018695,0.001954,0.049623,282.120575,14.371907,0.496226,-146.564728,0.049701,0.000000
78.020004,63.415024,-146.609207,0.018699,0.001954,0.049623,282.084106,14.370049,0.496226,-146.609207,0.049701,0.000000
78.230003,63.413910,-146.609207,0.018682,0.001954,0.049623,282.079163,14.369797,0.496226,-146.609207,0.049701,0.000000
78.440002,63.399017,-146.698181,0.018669,0.001954,0.049623,282.012909,14.366423,0.496226,-146.698181,0.049701,0.000000
78.650002,63.393066,-146.698181,0.018682,0.001954,0.049623,281.986450,14.365074,0.496226,-146.698181,0.049701,0.000000
78.860001,63.379288,-146.742661,0.018686,0.001954,0.049623,281.925140,14.361952,0.496226,-146.742661,0.049701,0.000000
79.070007,63.380020,-146.787140,0.018682,0.001954,0.049623,281.928406,14.362118,0.496226,-146.787140,0.049701,0.000000
79.280006,63.366241,-146.787140,0.018690,0.001954,0.049623,281.867126,14.358995,0.496226,-146.787140,0.049701,0.000000
79.490005,63.364380,-146.831619,0.018690,0.001954,0.049623,281.858826,14.358574,0.496226,-146.831619,0.049701,0.000000
79.700005,63.372208,-146.876099,0.018695,0.001954,0.049623,281.893646,14.360347,0.496226,-146.876099,0.049701,0.000000
79.910004,63.342789,-146.920578,0.018686,0.001954,0.049623,281.762787,14.353681,0.496226,-146.920578,0.049701,0.000000
80.120003,63.332367,-146.920578,0.018686,0.001954,0.049623,281.716431,14.351319,0.496226,-146.920578,0.049701,0.000000
80.330002,63.326035,-146.965057,0.018682,0.001954,0.049623,281.688263,14.349884,0.496226,-146.965057,0.049701,0.000000
80.540001,63.323059,-147.009537,0.018690,0.001954,0.049623,281.675049,14.349211,0.496226,-147.009537,0.049701,0.000000
80.750008,63.323425,-147.054031,0.018699,0.001954,0.049623,281.676666,14.349294,0.496226,-147.054031,0.049701,0.000000
80.960007,63.320816,-147.142990,0.018699,0.001954,0.049623,281.665070,14.348702,0.496226,-147.142990,0.049701,0.000000
81.170006,63.309647,-147.142990,0.018677,0.001954,0.049623,281.615387,14.346171,0.496226,-147.142990,0.049701,0.000000
81.380005,63.292892,-147.142990,0.018677,0.001954,0.049623,281.540833,14.342375,0.496226,-147.142990,0.049701,0.000000
81.590004,63.293640,-147.187469,0.018690,0.001954,0.049623,281.544159,14.342544,0.496226,-147.187469,0.049701,0.000000
81.800003,63.292526,-147.187469,0.018686,0.001954,0.049623,281.539215,14.342291,0.496226,-147.187469,0.049701,0.000000
82.010002,63.291031,-147.276428,0.018695,0.001954,0.049623,281.532562,14.341952,0.496226,-147.276428,0.049701,0.000000
82.220001,63.278000,-147.276428,0.018682,0.001954,0.049623,281.474609,14.339000,0.496226,-147.276428,0.049701,0.000000
82.430000,63.279480,-147.231949,0.018690,0.001954,0.049623,281.481171,14.339335,0.496226,-147.231949,0.049701,0.000000
82.640007,63.256027,-147.365387,0.018695,0.001954,0.049623,281.376862,14.334021,0.496226,-147.365387,0.049701,0.000000
82.850006,63.254913,-147.409866,0.018686,0.001954,0.049623,281.371918,14.333768,0.496226,-147.409866,0.049701,0.000000
83.060005,63.244858,-147.454346,0.018695,0.001954,0.049623,281.327179,14.331490,0.496226,-147.454346,0.049701,0.000000
83.270004,63.231445,-147.454346,0.018682,0.001954,0.049623,281.267517,14.328450,0.496226,-147.454346,0.049701,0.000000
83.480003,63.240021,-147.454346,0.018690,0.001954,0.049623,281.305664,14.330394,0.496226,-147.454346,0.049701,0.000000
83.690002,63.224380,-147.543320,0.018695,0.001954,0.049623,281.236084,14.326850,0.496226,-147.543320,0.049701,0.000000
83.900002,63.212463,-147.454346,0.018686,0.001954,0.049623,281.183075,14.324149,0.496226,-147.454346,0.049701,0.000000
84.110001,63.204636,-147.587799,0.018695,0.001954,0.049623,281.148254,14.322375,0.496226,-147.587799,0.049701,0.000000
84.320007,63.206131,-147.587799,0.018677,0.001954,0.049623,281.154907,14.322714,0.496226,-147.587799,0.049701,0.000000
84.530006,63.196075,-147.632278,0.018699,0.001954,0.049623,281.110168,14.320436,0.496226,-147.632278,0.049701,0.000000
84.740005,63.196075,-147.721237,0.018699,0.001954,0.049623,281.110168,14.320436,0.496226,-147.721237,0.049701,0.000000
84.950005,63.173737,-147.676758,0.018699,0.001954,0.049623,281.010803,14.315373,0.496226,-147.676758,0.049701,0.000000
85.160004,63.180069,-147.765717,0.018686,0.001954,0.049623,281.038971,14.316808,0.496226,-147.765717,0.049701,0.000000
85.370003,63.164795,-147.810196,0.018677,0.001954,0.049623,280.971039,14.313348,0.496226,-147.810196,0.049701,0.000000
85.580002,63.155487,-147.810196,0.018677,0.001954,0.049623,280.929626,14.311237,0.496226,-147.810196,0.049701,0.000000
85.790001,63.159576,-147.899155,0.018690,0.001954,0.049623,280.947815,14.312164,0.496226,-147.899155,0.049701,0.000000
86.000008,63.145065,-147.854675,0.018682,0.001954,0.049623,280.883270,14.308876,0.496226,-147.854675,0.049701,0.000000
86.210007,63.140594,-147.943649,0.018690,0.001954,0.049623,280.863403,14.307863,0.496226,-147.943649,0.049701,0.000000
86.420006,63.134628,-147.943649,0.018690,0.001954,0.049623,280.836853,14.306512,0.496226,-147.943649,0.049701,0.000000
86.630005,63.124954,-147.943649,0.018695,0.001954,0.049623,280.793823,14.304318,0.496226,-147.943649,0.049701,0.000000
86.840004,63.122711,-148.032608,0.018682,0.001954,0.049623,280.783844,14.303811,0.496226,-148.032608,0.049701,0.000000
87.050003,63.111176,-148.032608,0.018682,0.001954,0.049623,280.732544,14.301197,0.496226,-148.032608,0.049701,0.000000
87.260002,63.117874,-148.077087,0.018695,0.001954,0.049623,280.762329,14.302714,0.496226,-148.077087,0.049701,0.000000
87.470001,63.096649,-148.166046,0.018690,0.001954,0.049623,280.667908,14.297905,0.496226,-148.166046,0.049701,0.000000
87.680008,63.099258,-148.121567,0.018686,0.001954,0.049623,280.679504,14.298496,0.496226,-148.121567,0.049701,0.000000
87.890007,63.091438,-148.210526,0.018695,0.001954,0.049623,280.644745,14.296724,0.496226,-148.210526,0.049701,0.000000
88.000008,63.080269,-148.121567,0.018699,0.001954,0.049623,280.595062,14.294193,0.496226,-148.121567,0.049701,0.000000