File: Data/AG AL compression 300N/AL membrane Peeled 300N_2_3_03202024_154810.csv
Time (sec),S:Load (lbs),S:HL1 (DIM),S:LVDT (in),S:Position (in),Ch:Position (mm),Ch:Load (N),Ch:Stress (MPa),Ch:Strain (mm/mm),Ch:HL1 (DIM),Set Point (),Cycles ()
0.010000,-0.014893,-68.856514,-0.000004,-0.000000,-0.000000,-0.066245,-0.003375,-0.000000,-68.856514,0.000156,0.000000
0.160000,-0.017876,-68.900993,-0.000004,-0.000000,-0.000000,-0.079515,-0.004051,-0.000000,-68.900993,0.000156,0.000000
0.310000,-0.003349,-68.856514,-0.000004,-0.000000,-0.000000,-0.014898,-0.000759,-0.000000,-68.856514,0.000156,0.000000
0.460000,-0.009682,-68.900993,0.000004,0.000040,0.001023,-0.043066,-0.002194,0.010234,-68.900993,0.001526,0.000000
0.610000,0.028671,-68.856514,0.000004,0.000116,0.002957,0.127536,0.006497,0.029571,-68.856514,0.004024,0.000000
0.760000,0.041710,-68.900993,0.000065,0.000215,0.005455,0.185535,0.009452,0.054548,-68.900993,0.006521,0.000000
0.910000,0.065536,-68.945473,0.000164,0.000312,0.007918,0.291521,0.014851,0.079176,-68.945473,0.009019,0.000000
1.060000,0.141876,-68.945473,0.000263,0.000411,0.010441,0.631097,0.032150,0.104414,-68.945473,0.011517,0.000000
1.210000,0.177254,-68.900993,0.000362,0.000501,0.012722,0.788464,0.040166,0.127222,-68.900993,0.014014,0.000000
1.360000,0.248375,-68.900993,0.000466,0.000608,0.015437,1.104827,0.056283,0.154367,-68.900993,0.016529,0.000000
1.510000,0.334389,-68.900993,0.000560,0.000702,0.017839,1.487435,0.075774,0.178390,-68.900993,0.019027,0.000000
1.660000,0.468071,-68.989952,0.000664,0.000806,0.020475,2.082084,0.106066,0.204751,-68.989952,0.021524,0.000000
1.810000,0.703415,-68.900993,0.000750,0.000002,0.000052,3.128946,0.159396,0.000519,-68.900993,0.001171,0.000000
1.960000,0.611809,-68.989952,0.000755,-0.000005,-0.000139,2.721461,0.138638,-0.001389,-68.989952,0.000009,0.000000
2.110000,0.609200,-68.900993,0.000763,-0.000006,-0.000148,2.709855,0.138047,-0.001476,-68.900993,0.000009,0.000000
2.260000,0.584625,-68.945473,0.000763,-0.000006,-0.000156,2.600543,0.132478,-0.001563,-68.945473,0.000009,0.000000
2.410000,0.525787,-68.900993,0.000759,-0.000006,-0.000156,2.338819,0.119145,-0.001563,-68.900993,0.000130,0.000000
2.560000,0.544411,-68.989952,0.000763,-0.000006,-0.000156,2.421660,0.123365,-0.001563,-68.989952,0.000382,0.000000
2.710000,0.551109,-68.945473,0.000755,-0.000006,-0.000148,2.451457,0.124883,-0.001476,-68.945473,0.000633,0.000000
2.860000,0.550743,-68.945473,0.000772,-0.000002,-0.000044,2.449828,0.124800,-0.000435,-68.945473,0.000885,0.000000
3.010000,0.663940,-69.034439,0.000772,0.000014,0.000364,2.953355,0.150451,0.003641,-69.034439,0.001136,0.000000
3.160000,0.716072,-68.945473,0.000780,0.000024,0.000598,3.185248,0.162264,0.005984,-68.945473,0.001379,0.000000
3.310000,0.743256,-69.034439,0.000798,0.000031,0.000798,3.306166,0.168424,0.007979,-69.034439,0.001630,0.000000
3.460000,0.732826,-69.034439,0.000798,0.000040,0.001023,3.259774,0.166061,0.010231,-69.034439,0.001882,0.000000
3.610000,0.751823,-69.034439,0.000806,0.000047,0.001205,3.344278,0.170366,0.012055,-69.034439,0.002133,0.000000
3.760000,0.815125,-68.989952,0.000806,0.000057,0.001439,3.625855,0.184710,0.014394,-68.989952,0.002385,0.000000
3.910000,0.790176,-69.034439,0.000819,0.000060,0.001517,3.514880,0.179057,0.015174,-69.034439,0.002636,0.000000
4.060000,0.904121,-68.989952,0.000832,0.000076,0.001942,4.021733,0.204877,0.019424,-68.989952,0.002879,0.000000
4.210000,0.950668,-69.034439,0.000836,0.000088,0.002237,4.228784,0.215425,0.022373,-69.034439,0.003130,0.000000
4.360000,0.974503,-69.034439,0.000854,0.000096,0.002437,4.334804,0.220825,0.024367,-69.034439,0.003382,0.000000
4.510000,1.006149,-69.034439,0.000854,0.000103,0.002619,4.475575,0.227997,0.026188,-69.034439,0.003633,0.000000
4.660000,1.029984,-69.078918,0.000858,0.000110,0.002801,4.581595,0.233398,0.028012,-69.078918,0.003885,0.000000
4.810000,1.126053,-69.034439,0.000871,0.000127,0.003217,5.008933,0.255167,0.032172,-69.034439,0.004137,0.000000
4.960000,1.161057,-69.034439,0.000875,0.000141,0.003573,5.164638,0.263099,0.035729,-69.034439,0.004380,0.000000
5.110000,1.176323,-69.034439,0.000892,0.000150,0.003816,5.232546,0.266559,0.038156,-69.034439,0.004631,0.000000
5.260000,1.225105,-69.078918,0.000910,0.000158,0.004015,5.449541,0.277613,0.040150,-69.078918,0.004883,0.000000
5.410000,1.226227,-69.078918,0.000905,0.000167,0.004232,5.454529,0.277867,0.042319,-69.078918,0.005134,0.000000
5.560000,1.276863,-69.078918,0.000918,0.000177,0.004484,5.679771,0.289341,0.044836,-69.078918,0.005386,0.000000
5.710000,1.249680,-69.078918,0.000931,0.000180,0.004570,5.558852,0.283181,0.045703,-69.078918,0.005637,0.000000
5.860000,1.370331,-69.123398,0.000931,0.000193,0.004891,6.095536,0.310521,0.048912,-69.123398,0.005880,0.000000
6.010000,1.493217,-69.078918,0.000961,0.000207,0.005264,6.642163,0.338368,0.052640,-69.078918,0.006131,0.000000
6.160000,1.568810,-69.078918,0.000961,0.000218,0.005533,6.978413,0.355497,0.055328,-69.078918,0.006383,0.000000
6.310000,1.625778,-69.078918,0.000970,0.000226,0.005732,7.231822,0.368407,0.057322,-69.078918,0.006634,0.000000
6.460001,1.690941,-69.078918,0.000979,0.000234,0.005949,7.521680,0.383173,0.059491,-69.078918,0.006885,0.000000
6.610000,1.798935,-69.034439,0.000992,0.000248,0.006287,8.002062,0.407644,0.062871,-69.034439,0.007128,0.000000
6.760000,1.839890,-69.123398,0.001005,0.000256,0.006513,8.184237,0.416925,0.065127,-69.123398,0.007380,0.000000
6.910000,1.919579,-69.167877,0.001005,0.000269,0.006825,8.538712,0.434983,0.068249,-69.167877,0.007631,0.000000
7.060000,2.028313,-69.123398,0.001022,0.000279,0.007094,9.022386,0.459622,0.070937,-69.123398,0.007883,0.000000
7.210001,2.053261,-69.123398,0.001030,0.000288,0.007311,9.133360,0.465276,0.073105,-69.123398,0.008134,0.000000
7.360000,2.145615,-69.078918,0.001039,0.000297,0.007545,9.544170,0.486203,0.075448,-69.078918,0.008386,0.000000
7.510000,2.245781,-69.123398,0.001048,0.000307,0.007805,9.989733,0.508901,0.078048,-69.123398,0.008629,0.000000
7.660000,2.348557,-69.167877,0.001052,0.000316,0.008022,10.446901,0.532191,0.080217,-69.167877,0.008880,0.000000
7.810000,2.470322,-69.123398,0.001061,0.000327,0.008308,10.988540,0.559783,0.083078,-69.123398,0.009132,0.000000
7.960001,2.616287,-69.167877,0.001074,0.000336,0.008542,11.637827,0.592859,0.085421,-69.167877,0.009383,0.000000
8.110001,2.746620,-69.123398,0.001087,0.000347,0.008802,12.217577,0.622393,0.088022,-69.123398,0.009635,0.000000
8.260000,2.814018,-69.212357,0.001087,0.000353,0.008958,12.517379,0.637666,0.089585,-69.212357,0.009886,0.000000
8.410001,2.905998,-69.212357,0.001099,0.000360,0.009149,12.926526,0.658509,0.091492,-69.212357,0.010129,0.000000
8.560000,3.016594,-69.167877,0.001095,0.000373,0.009470,13.418480,0.683570,0.094698,-69.167877,0.010380,0.000000
8.710000,3.273903,-69.123398,0.001130,0.000386,0.009817,14.563047,0.741877,0.098169,-69.123398,0.010632,0.000000
8.860001,3.332733,-69.212357,0.001134,0.000395,0.010025,14.824738,0.755208,0.100251,-69.212357,0.010883,0.000000
9.010000,3.465668,-69.212357,0.001143,0.000404,0.010259,15.416060,0.785332,0.102593,-69.212357,0.011135,0.000000
9.160001,3.639572,-69.212357,0.001143,0.000414,0.010528,16.189625,0.824739,0.105281,-69.212357,0.011386,0.000000
9.310000,3.726707,-69.212357,0.001160,0.000422,0.010728,16.577223,0.844484,0.107275,-69.212357,0.011629,0.000000
9.460000,3.932999,-69.256844,0.001164,0.000434,0.011014,17.494852,0.891230,0.110137,-69.256844,0.011881,0.000000
9.610001,4.020508,-69.212357,0.001173,0.000441,0.011213,17.884111,0.911060,0.112131,-69.212357,0.012132,0.000000
9.760000,4.240578,-69.212357,0.001173,0.000453,0.011517,18.863031,0.960929,0.115167,-69.212357,0.012384,0.000000
9.910001,4.447990,-69.256844,0.001194,0.000464,0.011785,19.785650,1.007929,0.117854,-69.256844,0.012635,0.000000
10.060000,4.631195,-69.256844,0.001207,0.000475,0.012063,20.600584,1.049444,0.120628,-69.256844,0.012887,0.000000
10.210000,4.729500,-69.256844,0.001194,0.000480,0.012184,21.037867,1.071720,0.121843,-69.256844,0.013130,0.000000
10.360001,4.774559,-69.212357,0.001199,0.000489,0.012410,21.238298,1.081931,0.124099,-69.212357,0.013381,0.000000
10.510000,5.245987,-69.256844,0.001212,0.000505,0.012826,23.335316,1.188758,0.128263,-69.256844,0.013633,0.000000
10.660001,5.343544,-69.256844,0.001242,0.000515,0.013078,23.769270,1.210864,0.130776,-69.256844,0.013884,0.000000
10.810000,5.440735,-69.256844,0.001237,0.000521,0.013234,24.201597,1.232888,0.132339,-69.256844,0.014136,0.000000
10.960001,5.730438,-69.256844,0.001255,0.000535,0.013581,25.490263,1.298536,0.135806,-69.256844,0.014387,0.000000
11.110001,5.832100,-69.256844,0.001255,0.000544,0.013806,25.942476,1.321573,0.138062,-69.256844,0.014630,0.000000
11.260000,6.027222,-69.301323,0.001259,0.000550,0.013962,26.810421,1.365788,0.139621,-69.301323,0.014881,0.000000
11.410001,6.113243,-69.256844,0.001259,0.000558,0.014179,27.193064,1.385281,0.141790,-69.256844,0.015133,0.000000
11.560000,6.364960,-69.301323,0.001281,0.000567,0.014396,28.312756,1.442320,0.143958,-69.301323,0.015384,0.000000
11.710001,6.784630,-69.256844,0.001285,0.000582,0.014777,30.179541,1.537419,0.147774,-69.256844,0.015636,0.000000
11.860001,6.885910,-69.301323,0.001293,0.000590,0.014977,30.630058,1.560369,0.149768,-69.301323,0.015887,0.000000
12.010000,7.135399,-69.345802,0.001311,0.000600,0.015237,31.739840,1.616904,0.152372,-69.345802,0.016130,0.000000
12.160001,7.325684,-69.256844,0.001315,0.000609,0.015462,32.586269,1.660024,0.154624,-69.256844,0.016382,0.000000
12.310000,7.456757,-69.301323,0.001319,0.000616,0.015636,33.169312,1.689725,0.156358,-69.301323,0.016633,0.000000
12.460001,8.001541,-69.301323,0.001332,0.000634,0.016104,35.592632,1.813175,0.161043,-69.301323,0.016885,0.000000
12.610001,8.112137,-69.345802,0.001345,0.000643,0.016321,36.084587,1.838237,0.163212,-69.345802,0.017136,0.000000
12.760000,8.268158,-69.301323,0.001350,0.000651,0.016546,36.778603,1.873591,0.165464,-69.301323,0.017388,0.000000
12.910001,8.555260,-69.345802,0.001358,0.000662,0.016816,38.055695,1.938650,0.168155,-69.345802,0.017630,0.000000
13.060000,8.566803,-69.390282,0.001354,0.000669,0.016998,38.107044,1.941265,0.169976,-69.390282,0.017882,0.000000
13.210001,8.848312,-69.301323,0.001367,0.000677,0.017206,39.359261,2.005056,0.172058,-69.301323,0.018133,0.000000
13.360001,9.173393,-69.345802,0.001371,0.000690,0.017535,40.805290,2.078721,0.175350,-69.345802,0.018385,0.000000
13.510000,9.484703,-69.390282,0.001375,0.000702,0.017822,42.190067,2.149264,0.178216,-69.390282,0.018636,0.000000
13.660001,9.727112,-69.390282,0.001384,0.000711,0.018064,43.268353,2.204195,0.180642,-69.390282,0.018879,0.000000
13.810000,9.898033,-69.345802,0.001401,0.000721,0.018316,44.028652,2.242926,0.183159,-69.345802,0.019131,0.000000
13.960001,10.131882,-69.390282,0.001401,0.000730,0.018541,45.068859,2.295917,0.185411,-69.390282,0.019382,0.000000
14.110001,10.146034,-69.390282,0.001406,0.000733,0.018619,45.131813,2.299124,0.186194,-69.390282,0.019634,0.000000
14.260000,10.467766,-69.345802,0.001418,0.000744,0.018888,46.562946,2.372030,0.188881,-69.345802,0.019885,0.000000
14.410001,11.026695,-69.390282,0.001423,0.000761,0.019322,49.049191,2.498685,0.193215,-69.390282,0.020137,0.000000
14.560000,11.197983,-69.434761,0.001444,0.000769,0.019530,49.811115,2.537499,0.195297,-69.434761,0.020380,0.000000
14.710001,11.317146,-69.390282,0.001444,0.000778,0.019755,50.341183,2.564502,0.197553,-69.390282,0.020631,0.000000
14.860001,11.536469,-69.479248,0.001453,0.000786,0.019963,51.316776,2.614201,0.199634,-69.479248,0.020883,0.000000
15.010001,11.674995,-69.390282,0.001466,0.000795,0.020198,51.932972,2.645592,0.201977,-69.390282,0.021134,0.000000
15.160001,12.117004,-69.479248,0.001479,0.000807,0.020493,53.899128,2.745752,0.204926,-69.479248,0.021386,0.000000
15.310000,12.313988,-69.479248,0.001475,0.000817,0.020744,54.775352,2.790390,0.207439,-69.479248,0.021637,0.000000
15.460001,12.545975,-69.390282,0.001487,0.000826,0.020978,55.807281,2.842958,0.209782,-69.390282,0.021880,0.000000
15.610001,12.720245,-69.434761,0.001505,0.000834,0.021195,56.582478,2.882449,0.211950,-69.434761,0.022131,0.000000
15.760001,13.221085,-69.434761,0.001509,0.000850,0.021585,58.810322,2.995941,0.215853,-69.434761,0.022383,0.000000
15.910001,13.343971,-69.390282,0.001513,0.000857,0.021767,59.356949,3.023787,0.217673,-69.390282,0.022634,0.000000
16.060001,13.311203,-69.434761,0.001522,0.000861,0.021863,59.211189,3.016362,0.218627,-69.434761,0.022886,0.000000
16.210001,13.555473,-69.434761,0.001539,0.000871,0.022114,60.297756,3.071714,0.221140,-69.434761,0.023137,0.000000
16.360001,14.079033,-69.479248,0.001544,0.000883,0.022426,62.626667,3.190355,0.224263,-69.479248,0.023380,0.000000
16.510000,14.196701,-69.479248,0.001548,0.000893,0.022678,63.150082,3.217019,0.226780,-69.479248,0.023632,0.000000
16.660000,14.811859,-69.479248,0.001544,0.000908,0.023051,65.886436,3.356415,0.230508,-69.479248,0.023883,0.000000
16.810001,15.040123,-69.479248,0.001552,0.000920,0.023363,66.901810,3.408141,0.233630,-69.479248,0.024135,0.000000
16.960001,15.002884,-69.434761,0.001569,0.000925,0.023502,66.736160,3.399702,0.235015,-69.434761,0.024386,0.000000
17.110001,15.303764,-69.479248,0.001574,0.000934,0.023727,68.074547,3.467882,0.237271,-69.479248,0.024638,0.000000
17.260000,15.454201,-69.523727,0.001587,0.000942,0.023935,68.743721,3.501972,0.239353,-69.523727,0.024881,0.000000
17.410002,15.766251,-69.479248,0.001591,0.000954,0.024221,70.131783,3.572684,0.242214,-69.479248,0.025132,0.000000
17.560001,16.183311,-69.479248,0.001608,0.000965,0.024499,71.986961,3.667191,0.244989,-69.479248,0.025383,0.000000
17.710001,16.503922,-69.523727,0.001608,0.000975,0.024777,73.413109,3.739842,0.247767,-69.523727,0.025635,0.000000
17.860001,16.694572,-69.523727,0.001608,0.000985,0.025011,74.261169,3.783044,0.250106,-69.523727,0.025886,0.000000
18.010000,16.636856,-69.523727,0.001617,0.000988,0.025097,74.004433,3.769966,0.250973,-69.523727,0.026138,0.000000
18.160002,16.910927,-69.523727,0.001625,0.000998,0.025340,75.223557,3.832071,0.253403,-69.523727,0.026381,0.000000
18.310001,17.420700,-69.568207,0.001625,0.001013,0.025722,77.491142,3.947587,0.257218,-69.568207,0.026632,0.000000
18.460001,17.662003,-69.568207,0.001638,0.001021,0.025930,78.564514,4.002267,0.259299,-69.568207,0.026884,0.000000
18.610001,18.252213,-69.568207,0.001647,0.001035,0.026285,81.189896,4.136010,0.262853,-69.568207,0.027135,0.000000
18.760000,18.469673,-69.523727,0.001660,0.001046,0.026563,82.157211,4.185288,0.265631,-69.523727,0.027387,0.000000
18.910002,18.584366,-69.523727,0.001673,0.001054,0.026763,82.667389,4.211277,0.267626,-69.523727,0.027638,0.000000
19.060001,18.858803,-69.568207,0.001686,0.001062,0.026979,83.888145,4.273466,0.269791,-69.568207,0.027881,0.000000
19.210001,18.853592,-69.523727,0.001677,0.001068,0.027135,83.864967,4.272285,0.271354,-69.523727,0.028133,0.000000
19.360001,18.957108,-69.523727,0.001686,0.001078,0.027370,84.325424,4.295742,0.273697,-69.523727,0.028384,0.000000
19.510000,19.979645,-69.568207,0.001690,0.001095,0.027820,88.873901,4.527452,0.278205,-69.568207,0.028636,0.000000
19.660002,20.196739,-69.568207,0.001716,0.001102,0.028003,89.839584,4.576646,0.280025,-69.568207,0.028887,0.000000
19.810001,20.423141,-69.612686,0.001716,0.001112,0.028237,90.846672,4.627950,0.282368,-69.612686,0.029130,0.000000
19.960001,20.327812,-69.612686,0.001716,0.001115,0.028315,90.422623,4.606348,0.283148,-69.612686,0.029381,0.000000
20.110001,20.702423,-69.568207,0.001729,0.001129,0.028679,92.088974,4.691236,0.286789,-69.568207,0.029633,0.000000
20.260000,21.654579,-69.612686,0.001738,0.001145,0.029078,96.324379,4.906998,0.290778,-69.612686,0.029884,0.000000
20.410002,22.059349,-69.612686,0.001755,0.001158,0.029407,98.124886,4.998720,0.294075,-69.612686,0.030136,0.000000
20.560001,22.206802,-69.657173,0.001759,0.001167,0.029633,98.780792,5.032133,0.296331,-69.657173,0.030387,0.000000
20.710001,22.326706,-69.657173,0.001776,0.001175,0.029841,99.314148,5.059304,0.298412,-69.657173,0.030630,0.000000
20.860001,22.461510,-69.657173,0.001772,0.001182,0.030015,99.913788,5.089851,0.300146,-69.657173,0.030882,0.000000
21.010000,22.782494,-69.657173,0.001776,0.001190,0.030231,101.341591,5.162587,0.302315,-69.657173,0.031133,0.000000
21.160002,23.052094,-69.657173,0.001781,0.001198,0.030440,102.540833,5.223679,0.304396,-69.657173,0.031385,0.000000
21.310001,23.166779,-69.612686,0.001785,0.001203,0.030544,103.050980,5.249667,0.305437,-69.612686,0.031636,0.000000
21.460001,24.294327,-69.568207,0.001807,0.001223,0.031072,108.066566,5.505173,0.310725,-69.568207,0.031888,0.000000
21.610001,24.357628,-69.657173,0.001811,0.001229,0.031220,108.348137,5.519517,0.312201,-69.657173,0.032131,0.000000
21.760000,24.541580,-69.612686,0.001815,0.001237,0.031428,109.166397,5.561202,0.314283,-69.612686,0.032382,0.000000
21.910002,24.894592,-69.701653,0.001802,0.001249,0.031723,110.736679,5.641195,0.317231,-69.701653,0.032634,0.000000
22.060001,25.478844,-69.612686,0.001819,0.001258,0.031957,113.335556,5.773588,0.319570,-69.612686,0.032885,0.000000
22.210001,26.147995,-69.701653,0.001824,0.001273,0.032330,116.312088,5.925220,0.323302,-69.701653,0.033137,0.000000
22.360001,26.443657,-69.701653,0.001841,0.001282,0.032573,117.627258,5.992218,0.325728,-69.701653,0.033388,0.000000
22.510000,26.767624,-69.701653,0.001841,0.001292,0.032825,119.068336,6.065630,0.328245,-69.701653,0.033631,0.000000
22.660002,27.085632,-69.701653,0.001850,0.001301,0.033041,120.482910,6.137692,0.330410,-69.701653,0.033882,0.000000
22.810001,27.262878,-69.746132,0.001854,0.001309,0.033240,121.271339,6.177856,0.332405,-69.746132,0.034134,0.000000
22.960001,27.510132,-69.746132,0.001854,0.001317,0.033449,122.371178,6.233885,0.334486,-69.746132,0.034385,0.000000
23.110001,27.738022,-69.701653,0.001867,0.001322,0.033588,123.384880,6.285526,0.335875,-69.701653,0.034637,0.000000
23.260000,28.125664,-69.746132,0.001867,0.001334,0.033891,125.109200,6.373366,0.338911,-69.746132,0.034888,0.000000
23.410002,29.293053,-69.701653,0.001880,0.001351,0.034325,130.302002,6.637900,0.343248,-69.701653,0.035131,0.000000
23.560001,29.635635,-69.701653,0.001884,0.001359,0.034507,131.825897,6.715531,0.345069,-69.701653,0.035383,0.000000
23.710001,29.795013,-69.746132,0.001897,0.001368,0.034758,132.534836,6.751647,0.347582,-69.746132,0.035634,0.000000
23.860001,30.295105,-69.746132,0.001901,0.001376,0.034949,134.759354,6.864969,0.349490,-69.746132,0.035886,0.000000
24.010000,30.409424,-69.746132,0.001893,0.001384,0.035157,135.267868,6.890874,0.351571,-69.746132,0.036137,0.000000
24.160002,31.452812,-69.701653,0.001910,0.001401,0.035582,139.909103,7.127309,0.355822,-69.701653,0.036389,0.000000
24.310001,32.010254,-69.746132,0.001927,0.001411,0.035851,142.388718,7.253627,0.358509,-69.746132,0.036631,0.000000
24.460001,32.347252,-69.790611,0.001932,0.001421,0.036094,143.887756,7.329992,0.360939,-69.790611,0.036883,0.000000
24.610001,32.733772,-69.746132,0.001932,0.001430,0.036311,145.607086,7.417579,0.363108,-69.746132,0.037134,0.000000
24.760000,32.809364,-69.746132,0.001949,0.001436,0.036467,145.943344,7.434708,0.364667,-69.746132,0.037386,0.000000
24.910002,33.108383,-69.790611,0.001940,0.001443,0.036649,147.273437,7.502467,0.366488,-69.790611,0.037637,0.000000
25.060001,33.496765,-69.790611,0.001953,0.001451,0.036848,149.001053,7.590476,0.368482,-69.790611,0.037889,0.000000
25.210001,33.786469,-69.790611,0.001949,0.001458,0.037022,150.289719,7.656123,0.370216,-69.790611,0.038132,0.000000
25.360001,34.768417,-69.790611,0.001953,0.001473,0.037412,154.657639,7.878636,0.374122,-69.790611,0.038383,0.000000
25.510002,35.483002,-69.835091,0.001970,0.001483,0.037663,157.836273,8.040563,0.376635,-69.835091,0.038635,0.000000
25.660002,35.925003,-69.835091,0.001970,0.001492,0.037898,159.802399,8.140722,0.378978,-69.835091,0.038886,0.000000
25.810001,35.946602,-69.835091,0.001979,0.001496,0.038011,159.898468,8.145617,0.380106,-69.835091,0.039138,0.000000
25.960001,36.485428,-69.835091,0.001975,0.001507,0.038279,162.295288,8.267716,0.382793,-69.835091,0.039389,0.000000
26.110001,37.240227,-69.701653,0.001988,0.001523,0.038678,165.652802,8.438756,0.386782,-69.701653,0.039632,0.000000
26.260002,38.365532,-69.835091,0.001992,0.001537,0.039034,170.658417,8.693754,0.390336,-69.835091,0.039884,0.000000
26.410002,39.038040,-69.835091,0.001992,0.001547,0.039303,173.649872,8.846147,0.393027,-69.835091,0.040135,0.000000
26.560001,39.420464,-69.879578,0.002005,0.001556,0.039519,175.350983,8.932805,0.395192,-69.879578,0.040387,0.000000
26.710001,39.486008,-69.835091,0.002009,0.001562,0.039684,175.642532,8.947657,0.396842,-69.835091,0.040638,0.000000
26.860001,40.336502,-69.835091,0.002022,0.001575,0.039996,179.425720,9.140382,0.399965,-69.835091,0.040881,0.000000
27.010002,40.436668,-69.835091,0.002018,0.001578,0.040092,179.871277,9.163079,0.400919,-69.835091,0.041132,0.000000
27.160002,40.817238,-69.790611,0.002026,0.001590,0.040378,181.564148,9.249318,0.403780,-69.790611,0.041384,0.000000
27.310001,41.458458,-69.924057,0.002026,0.001602,0.040682,184.416428,9.394621,0.406816,-69.924057,0.041635,0.000000
27.460001,42.718201,-69.835091,0.002031,0.001614,0.041002,190.020050,9.680082,0.410021,-69.835091,0.041887,0.000000
27.610001,43.395172,-69.835091,0.002035,0.001623,0.041236,193.031372,9.833487,0.412364,-69.835091,0.042138,0.000000
27.760002,43.719505,-69.835091,0.002044,0.001631,0.041427,194.474075,9.906982,0.414272,-69.835091,0.042381,0.000000
27.910002,44.253120,-69.879578,0.002052,0.001644,0.041748,196.847717,10.027901,0.417481,-69.879578,0.042633,0.000000
28.060001,45.138992,-69.879578,0.002057,0.001653,0.041991,200.788269,10.228642,0.419911,-69.879578,0.042884,0.000000
28.210001,45.786545,-69.879578,0.002057,0.001663,0.042251,203.668716,10.375379,0.422512,-69.879578,0.043136,0.000000
28.360001,46.750992,-69.924057,0.002074,0.001677,0.042598,207.958801,10.593926,0.425979,-69.924057,0.043387,0.000000
28.510002,47.091713,-69.968536,0.002061,0.001684,0.042772,209.474396,10.671135,0.427716,-69.968536,0.043639,0.000000
28.660002,47.589577,-69.968536,0.002070,0.001693,0.043014,211.689011,10.783952,0.430142,-69.968536,0.043882,0.000000
28.810001,48.117599,-69.924057,0.002074,0.001702,0.043240,214.037766,10.903604,0.432398,-69.924057,0.044133,0.000000
28.960001,48.838142,-69.968536,0.002074,0.001712,0.043483,217.242905,11.066881,0.434828,-69.968536,0.044384,0.000000
29.110001,49.266739,-69.924057,0.002082,0.001718,0.043647,219.149399,11.164002,0.436474,-69.924057,0.044636,0.000000
29.260002,49.899399,-69.924057,0.002082,0.001729,0.043916,221.963608,11.307365,0.439161,-69.924057,0.044887,0.000000
29.410002,50.724205,-69.968536,0.002091,0.001739,0.044159,225.632538,11.494268,0.441591,-69.968536,0.045139,0.000000
29.560001,51.312927,-69.924057,0.002095,0.001747,0.044376,228.251297,11.627675,0.443760,-69.924057,0.045382,0.000000
29.710001,51.861061,-69.968536,0.002104,0.001755,0.044567,230.689514,11.751884,0.445668,-69.968536,0.045633,0.000000
29.860001,52.364876,-69.924057,0.002100,0.001761,0.044740,232.930603,11.866051,0.447401,-69.924057,0.045885,0.000000
30.010002,53.790321,-69.924057,0.002117,0.001781,0.045234,239.271301,12.189061,0.452344,-69.924057,0.046136,0.000000
30.160002,54.507507,-69.924057,0.002113,0.001790,0.045460,242.461502,12.351578,0.454600,-69.924057,0.046388,0.000000
30.310001,55.327843,-69.968536,0.002113,0.001799,0.045703,246.110535,12.537468,0.457026,-69.968536,0.046639,0.000000
30.460001,55.815651,-70.013016,0.002126,0.001809,0.045946,248.280411,12.648007,0.459456,-70.013016,0.046882,0.000000
30.610001,56.688492,-69.924057,0.002121,0.001819,0.046214,252.163010,12.845796,0.462143,-69.924057,0.047134,0.000000
30.760002,57.254875,-69.968536,0.002126,0.001828,0.046431,254.682404,12.974140,0.464312,-69.968536,0.047385,0.000000
30.910002,57.868919,-70.013016,0.002130,0.001837,0.046665,257.413818,13.113285,0.466655,-70.013016,0.047637,0.000000
31.060001,58.769310,-69.968536,0.002139,0.001848,0.046952,261.418945,13.317316,0.469516,-69.968536,0.047888,0.000000
31.210001,59.671944,-70.013016,0.002147,0.001860,0.047238,265.434052,13.521856,0.472378,-70.013016,0.048140,0.000000
31.360001,60.343704,-70.013016,0.002151,0.001870,0.047489,268.422211,13.674079,0.474891,-70.013016,0.048382,0.000000
31.510002,61.112282,-69.968536,0.002147,0.001878,0.047697,271.841003,13.848241,0.476972,-69.968536,0.048634,0.000000
31.660002,61.297348,-70.013016,0.002160,0.001881,0.047784,272.664215,13.890177,0.477839,-70.013016,0.048885,0.000000
31.810001,62.187317,-70.057495,0.002156,0.001895,0.048122,276.623016,14.091847,0.481223,-70.057495,0.049137,0.000000
31.960001,63.390831,-70.013016,0.002169,0.001907,0.048435,281.976501,14.364568,0.484345,-70.013016,0.049388,0.000000
32.110001,64.081200,-70.057495,0.002160,0.001916,0.048660,285.047424,14.521008,0.486597,-70.057495,0.049640,0.000000
32.260002,64.953667,-70.057495,0.002160,0.001926,0.048911,288.928345,14.718711,0.489114,-70.057495,0.049883,0.000000
32.410000,65.903603,-70.057495,0.002164,0.001938,0.049215,293.153870,14.933970,0.492150,-70.057495,0.050134,0.000000
32.560001,66.542961,-70.013016,0.002169,0.001946,0.049441,295.997864,15.078851,0.494406,-70.013016,0.050386,0.000000
32.710003,66.831169,-70.057495,0.002186,0.001952,0.049570,297.279877,15.144159,0.495704,-70.057495,0.050637,0.000000
32.860001,67.394203,-70.057495,0.002182,0.001951,0.049562,299.784393,15.271745,0.495617,-70.057495,0.049779,0.000000
33.010002,67.136894,-70.057495,0.002186,0.001951,0.049562,298.639832,15.213437,0.495617,-70.057495,0.049779,0.000000
33.160000,66.921669,-70.057495,0.002190,0.001951,0.049562,297.682465,15.164667,0.495617,-70.057495,0.049779,0.000000
33.310001,66.766014,-70.057495,0.002190,0.001950,0.049519,296.990051,15.129395,0.495185,-70.057495,0.049562,0.000000
33.460003,66.593224,-70.057495,0.002186,0.001949,0.049501,296.221466,15.090240,0.495011,-70.057495,0.049562,0.000000
33.610001,66.430138,-70.057495,0.002203,0.001949,0.049492,295.496002,15.053285,0.494924,-70.057495,0.049562,0.000000
33.760002,66.307991,-70.101982,0.002195,0.001948,0.049484,294.952667,15.025605,0.494837,-70.101982,0.049562,0.000000
33.910000,66.179527,-70.057495,0.002190,0.001948,0.049484,294.381226,14.996495,0.494837,-70.057495,0.049562,0.000000
34.060001,66.083076,-70.146461,0.002199,0.001948,0.049475,293.952209,14.974639,0.494750,-70.146461,0.049562,0.000000
34.210003,65.990364,-70.101982,0.002186,0.001948,0.049475,293.539795,14.953630,0.494750,-70.101982,0.049562,0.000000
34.360001,65.886101,-70.101982,0.002195,0.001948,0.049475,293.076019,14.930004,0.494750,-70.101982,0.049562,0.000000
34.510002,65.809013,-70.101982,0.002190,0.001948,0.049475,292.733124,14.912536,0.494750,-70.101982,0.049562,0.000000
34.660000,65.729332,-70.146461,0.002199,0.001947,0.049466,292.378662,14.894479,0.494663,-70.146461,0.049562,0.000000
34.810001,65.642189,-70.146461,0.002195,0.001947,0.049466,291.991028,14.874733,0.494663,-70.146461,0.049562,0.000000
34.960003,65.581871,-70.146461,0.002212,0.001947,0.049466,291.722717,14.861064,0.494663,-70.146461,0.049562,0.000000
35.110001,65.528618,-70.146461,0.002199,0.001947,0.049466,291.485840,14.848997,0.494663,-70.146461,0.049562,0.000000
35.260002,65.463829,-70.101982,0.002203,0.001947,0.049466,291.197662,14.834315,0.494663,-70.101982,0.049562,0.000000
35.410000,65.414665,-70.101982,0.002199,0.001947,0.049466,290.978973,14.823174,0.494663,-70.101982,0.049562,0.000000
35.560001,65.347649,-70.146461,0.002199,0.001947,0.049466,290.680847,14.807989,0.494663,-70.146461,0.049562,0.000000
35.710003,65.294762,-70.146461,0.002203,0.001947,0.049458,290.445618,14.796005,0.494576,-70.146461,0.049562,0.000000
35.860001,65.252312,-70.146461,0.002203,0.001947,0.049458,290.256775,14.786386,0.494576,-70.146461,0.049562,0.000000
36.010002,65.210243,-70.146461,0.002207,0.001947,0.049458,290.069641,14.776852,0.494576,-70.146461,0.049562,0.000000
36.160000,65.169655,-70.146461,0.002203,0.001947,0.049458,289.889099,14.767654,0.494576,-70.146461,0.049562,0.000000
36.310001,65.143959,-70.190941,0.002212,0.001947,0.049458,289.774811,14.761832,0.494576,-70.190941,0.049562,0.000000
36.460003,65.104118,-70.190941,0.002207,0.001947,0.049458,289.597595,14.752804,0.494576,-70.190941,0.049562,0.000000
36.610001,65.050865,-70.190941,0.002203,0.001947,0.049458,289.360687,14.740736,0.494576,-70.190941,0.049562,0.000000
36.760002,65.008781,-70.101982,0.002212,0.001947,0.049458,289.173492,14.731200,0.494576,-70.101982,0.049562,0.000000
36.910000,64.967079,-70.190941,0.002199,0.001947,0.049458,288.988007,14.721750,0.494576,-70.190941,0.049562,0.000000
37.060001,64.939522,-70.146461,0.002195,0.001947,0.049458,288.865417,14.715506,0.494576,-70.146461,0.049562,0.000000
37.210003,64.896706,-70.190941,0.002207,0.001947,0.049458,288.674957,14.705804,0.494576,-70.190941,0.049562,0.000000
37.360001,64.875099,-70.235420,0.002199,0.001947,0.049458,288.578857,14.700908,0.494576,-70.235420,0.049562,0.000000
37.510002,64.854622,-70.190941,0.002203,0.001947,0.049458,288.487762,14.696267,0.494576,-70.190941,0.049562,0.000000
37.660004,64.824455,-70.146461,0.002203,0.001947,0.049458,288.353577,14.689431,0.494576,-70.146461,0.049562,0.000000
37.810001,64.795418,-70.190941,0.002207,0.001947,0.049458,288.224426,14.682852,0.494576,-70.190941,0.049562,0.000000
37.960003,64.761909,-70.235420,0.002207,0.001947,0.049458,288.075348,14.675258,0.494576,-70.235420,0.049562,0.000000
38.110001,64.729134,-70.146461,0.002207,0.001947,0.049458,287.929565,14.667831,0.494576,-70.146461,0.049562,0.000000
38.260002,64.708275,-70.279900,0.002212,0.001947,0.049458,287.836792,14.663104,0.494576,-70.279900,0.049562,0.000000
38.410004,64.678490,-70.190941,0.002212,0.001947,0.049458,287.704285,14.656355,0.494576,-70.190941,0.049562,0.000000
38.560001,64.652428,-70.279900,0.002212,0.001947,0.049458,287.588348,14.650450,0.494576,-70.279900,0.049562,0.000000
38.710003,64.625984,-70.279900,0.002199,0.001947,0.049458,287.470734,14.644457,0.494576,-70.279900,0.049562,0.000000
38.860001,64.607368,-70.324387,0.002199,0.001947,0.049458,287.387939,14.640239,0.494576,-70.324387,0.049562,0.000000
39.010002,64.582039,-70.279900,0.002207,0.001947,0.049458,287.275269,14.634499,0.494576,-70.279900,0.049562,0.000000
39.160004,64.556725,-70.324387,0.002212,0.001947,0.049458,287.162659,14.628763,0.494576,-70.324387,0.049562,0.000000
39.310001,64.540718,-70.324387,0.002203,0.001947,0.049458,287.091461,14.625135,0.494576,-70.324387,0.049562,0.000000
39.460003,64.519859,-70.324387,0.002216,0.001947,0.049458,286.998657,14.620409,0.494576,-70.324387,0.049562,0.000000
39.610001,64.495277,-70.279900,0.002199,0.001947,0.049458,286.889313,14.614839,0.494576,-70.279900,0.049562,0.000000
39.760002,64.483742,-70.324387,0.002203,0.001947,0.049458,286.838013,14.612225,0.494576,-70.324387,0.049562,0.000000
39.910004,64.466606,-70.324387,0.002203,0.001947,0.049458,286.761780,14.608341,0.494576,-70.324387,0.049562,0.000000
40.060001,64.445763,-70.279900,0.002195,0.001947,0.049458,286.669067,14.603619,0.494576,-70.279900,0.049562,0.000000
40.210003,64.429741,-70.279900,0.002212,0.001947,0.049458,286.597809,14.599988,0.494576,-70.279900,0.049562,0.000000
40.360001,64.391396,-70.324387,0.002207,0.001947,0.049458,286.427246,14.591298,0.494576,-70.324387,0.049562,0.000000
40.510002,64.377983,-70.279900,0.002212,0.001947,0.049458,286.367584,14.588260,0.494576,-70.279900,0.049562,0.000000
40.660004,64.349693,-70.324387,0.002199,0.001947,0.049458,286.241730,14.581848,0.494576,-70.324387,0.049562,0.000000
40.810001,64.337395,-70.324387,0.002207,0.001947,0.049458,286.187012,14.579062,0.494576,-70.324387,0.049562,0.000000
40.960003,64.331444,-70.324387,0.002203,0.001947,0.049458,286.160553,14.577713,0.494576,-70.324387,0.049562,0.000000
41.110001,64.322136,-70.368866,0.002207,0.001947,0.049458,286.119141,14.575604,0.494576,-70.368866,0.049562,0.000000
41.260002,64.293831,-70.324387,0.002212,0.001947,0.049458,285.993256,14.569191,0.494576,-70.324387,0.049562,0.000000
41.410004,64.284889,-70.368866,0.002199,0.001947,0.049458,285.953461,14.567164,0.494576,-70.368866,0.049562,0.000000
41.560001,64.264046,-70.324387,0.002199,0.001947,0.049458,285.860748,14.562441,0.494576,-70.324387,0.049562,0.000000
41.710003,64.249886,-70.368866,0.002199,0.001947,0.049458,285.797760,14.559232,0.494576,-70.368866,0.049562,0.000000
41.860001,64.231651,-70.324387,0.002212,0.001947,0.049458,285.716644,14.555099,0.494576,-70.324387,0.049562,0.000000
42.010002,64.210045,-70.368866,0.002199,0.001947,0.049458,285.620544,14.550204,0.494576,-70.368866,0.049562,0.000000
42.160004,64.197380,-70.368866,0.002203,0.001947,0.049458,285.564209,14.547335,0.494576,-70.368866,0.049562,0.000000
42.310001,64.180260,-70.413345,0.002190,0.001947,0.049458,285.488068,14.543455,0.494576,-70.413345,0.049562,0.000000
42.460003,64.174675,-70.457825,0.002212,0.001947,0.049458,285.463226,14.542190,0.494576,-70.457825,0.049562,0.000000
42.610001,64.153450,-70.413345,0.002203,0.001947,0.049458,285.368805,14.537380,0.494576,-70.413345,0.049562,0.000000
42.760002,64.137062,-70.413345,0.002203,0.001947,0.049458,285.295898,14.533666,0.494576,-70.413345,0.049562,0.000000
42.910004,64.123283,-70.413345,0.002207,0.001947,0.049458,285.234619,14.530544,0.494576,-70.413345,0.049562,0.000000
43.060001,64.115837,-70.368866,0.002207,0.001947,0.049458,285.201477,14.528856,0.494576,-70.368866,0.049562,0.000000
43.210003,64.092369,-70.457825,0.002207,0.001947,0.049458,285.097107,14.523539,0.494576,-70.457825,0.049562,0.000000
43.360001,64.085670,-70.457825,0.002212,0.001947,0.049458,285.067291,14.522020,0.494576,-70.457825,0.049562,0.000000
43.510002,64.080086,-70.457825,0.002216,0.001947,0.049458,285.042450,14.520755,0.494576,-70.457825,0.049562,0.000000
43.660004,64.069283,-70.413345,0.002212,0.001947,0.049458,284.994415,14.518307,0.494576,-70.413345,0.049562,0.000000
43.810001,64.055138,-70.457825,0.002199,0.001947,0.049458,284.931488,14.515101,0.494576,-70.457825,0.049562,0.000000
43.960003,64.043602,-70.413345,0.002212,0.001947,0.049458,284.880157,14.512487,0.494576,-70.413345,0.049562,0.000000
44.110001,64.026466,-70.457825,0.002203,0.001947,0.049458,284.803955,14.508605,0.494576,-70.457825,0.049562,0.000000
44.260002,64.015297,-70.502304,0.002216,0.001947,0.049458,284.754272,14.506074,0.494576,-70.502304,0.049562,0.000000
44.410004,63.997429,-70.502304,0.002207,0.001947,0.049458,284.674774,14.502025,0.494576,-70.502304,0.049562,0.000000
44.560001,63.984016,-70.457825,0.002220,0.001947,0.049458,284.615112,14.498985,0.494576,-70.457825,0.049562,0.000000
44.710003,63.959435,-70.457825,0.002199,0.001947,0.049458,284.505768,14.493415,0.494576,-70.457825,0.049562,0.000000
44.860001,63.957954,-70.457825,0.002207,0.001947,0.049458,284.499176,14.493080,0.494576,-70.457825,0.049562,0.000000
45.010002,63.954597,-70.502304,0.002203,0.001947,0.049458,284.484253,14.492319,0.494576,-70.502304,0.049562,0.000000
45.160004,63.947899,-70.502304,0.002212,0.001947,0.049458,284.454468,14.490801,0.494576,-70.502304,0.049562,0.000000
45.310001,63.925560,-70.502304,0.002212,0.001947,0.049458,284.355103,14.485739,0.494576,-70.502304,0.049562,0.000000
45.460003,63.912514,-70.502304,0.002212,0.001947,0.049458,284.297058,14.482782,0.494576,-70.502304,0.049562,0.000000
45.610001,63.909538,-70.502304,0.002212,0.001947,0.049458,284.283813,14.482109,0.494576,-70.502304,0.049562,0.000000
45.760002,63.882729,-70.502304,0.002216,0.001947,0.049458,284.164581,14.476033,0.494576,-70.502304,0.049562,0.000000
45.910004,63.884972,-70.502304,0.002207,0.001947,0.049458,284.174561,14.476542,0.494576,-70.502304,0.049562,0.000000
46.060001,63.880119,-70.457825,0.002220,0.001947,0.049458,284.152954,14.475442,0.494576,-70.457825,0.049562,0.000000
46.210003,63.866341,-70.546791,0.002203,0.001947,0.049458,284.091675,14.472320,0.494576,-70.546791,0.049562,0.000000
46.360001,63.855553,-70.546791,0.002207,0.001947,0.049458,284.043671,14.469875,0.494576,-70.546791,0.049562,0.000000
46.510002,63.864861,-70.502304,0.002207,0.001947,0.049458,284.085083,14.471985,0.494576,-70.502304,0.049562,0.000000
46.660004,63.849586,-70.546791,0.002207,0.001947,0.049458,284.017151,14.468523,0.494576,-70.546791,0.049562,0.000000
46.810001,63.829109,-70.546791,0.002207,0.001947,0.049458,283.926056,14.463882,0.494576,-70.546791,0.049562,0.000000
46.960003,63.810860,-70.546791,0.002216,0.001947,0.049458,283.844879,14.459747,0.494576,-70.546791,0.049562,0.000000
47.110001,63.801933,-70.502304,0.002212,0.001947,0.049458,283.805176,14.457725,0.494576,-70.502304,0.049562,0.000000
47.260002,63.795601,-70.591270,0.002216,0.001947,0.049458,283.777008,14.456289,0.494576,-70.591270,0.049562,0.000000
47.410004,63.784050,-70.546791,0.002212,0.001947,0.049458,283.725616,14.453672,0.494576,-70.546791,0.049562,0.000000
47.560001,63.781075,-70.591270,0.002212,0.001947,0.049458,283.712402,14.452998,0.494576,-70.591270,0.049562,0.000000
47.710003,63.771767,-70.546791,0.002212,0.001947,0.049458,283.670990,14.450889,0.494576,-70.546791,0.049562,0.000000
47.860001,63.768410,-70.591270,0.002212,0.001947,0.049458,283.656067,14.450129,0.494576,-70.591270,0.049562,0.000000
48.010002,63.752769,-70.591270,0.002216,0.001947,0.049458,283.586487,14.446584,0.494576,-70.591270,0.049562,0.000000
48.160004,63.755013,-70.591270,0.002212,0.001947,0.049458,283.596466,14.447092,0.494576,-70.591270,0.049562,0.000000
48.310001,63.736015,-70.546791,0.002216,0.001947,0.049458,283.511963,14.442787,0.494576,-70.546791,0.049562,0.000000
48.460003,63.735649,-70.546791,0.002212,0.001947,0.049458,283.510315,14.442705,0.494576,-70.546791,0.049562,0.000000
48.610001,63.716652,-70.591270,0.002207,0.001947,0.049458,283.425812,14.438400,0.494576,-70.591270,0.049562,0.000000
48.760002,63.719261,-70.591270,0.002212,0.001947,0.049458,283.437439,14.438991,0.494576,-70.591270,0.049562,0.000000
48.910004,63.704369,-70.591270,0.002207,0.001947,0.049458,283.371185,14.435616,0.494576,-70.591270,0.049562,0.000000
49.060001,63.694313,-70.635750,0.002216,0.001947,0.049458,283.326447,14.433337,0.494576,-70.635750,0.049562,0.000000
49.210003,63.692818,-70.591270,0.002216,0.001947,0.049458,283.319794,14.432999,0.494576,-70.591270,0.049562,0.000000
49.360001,63.680534,-70.635750,0.002216,0.001947,0.049458,283.265167,14.430216,0.494576,-70.635750,0.049562,0.000000
49.510002,63.666389,-70.635750,0.002216,0.001947,0.049458,283.202240,14.427010,0.494576,-70.635750,0.049562,0.000000
49.660004,63.660423,-70.724709,0.002216,0.001947,0.049458,283.175720,14.425658,0.494576,-70.724709,0.049562,0.000000
49.810001,63.652977,-70.680229,0.002216,0.001947,0.049458,283.142578,14.423970,0.494576,-70.680229,0.049562,0.000000
49.960003,63.635841,-70.635750,0.002203,0.001947,0.049458,283.066345,14.420088,0.494576,-70.635750,0.049562,0.000000
50.110001,63.643669,-70.635750,0.002212,0.001947,0.049458,283.101166,14.421862,0.494576,-70.635750,0.049562,0.000000
50.260002,63.629890,-70.680229,0.002216,0.001947,0.049458,283.039886,14.418739,0.494576,-70.680229,0.049562,0.000000
50.410004,63.620201,-70.680229,0.002216,0.001947,0.049458,282.996796,14.416544,0.494576,-70.680229,0.049562,0.000000
50.560001,63.621696,-70.635750,0.002212,0.001947,0.049458,283.003448,14.416883,0.494576,-70.635750,0.049562,0.000000
50.710003,63.607552,-70.680229,0.002207,0.001947,0.049458,282.940521,14.413677,0.494576,-70.680229,0.049562,0.000000
50.860001,63.609413,-70.680229,0.002203,0.001947,0.049458,282.948792,14.414099,0.494576,-70.680229,0.049562,0.000000
51.010002,63.599358,-70.680229,0.002212,0.001947,0.049458,282.904083,14.411821,0.494576,-70.680229,0.049562,0.000000
51.160004,63.586327,-70.680229,0.002212,0.001947,0.049458,282.846100,14.408868,0.494576,-70.680229,0.049562,0.000000
51.310001,63.582970,-70.724709,0.002203,0.001947,0.049458,282.831177,14.408107,0.494576,-70.724709,0.049562,0.000000
51.460003,63.568825,-70.724709,0.002207,0.001947,0.049458,282.768250,14.404902,0.494576,-70.724709,0.049562,0.000000
51.610001,63.565468,-70.724709,0.002220,0.001947,0.049458,282.753326,14.404140,0.494576,-70.724709,0.049562,0.000000
51.760002,63.558769,-70.680229,0.002212,0.001947,0.049458,282.723511,14.402622,0.494576,-70.680229,0.049562,0.000000
51.910004,63.559517,-70.724709,0.002207,0.001947,0.049458,282.726837,14.402792,0.494576,-70.724709,0.049562,0.000000
52.060001,63.550575,-70.724709,0.002195,0.001947,0.049458,282.687073,14.400766,0.494576,-70.724709,0.049562,0.000000
52.210003,63.537910,-70.724709,0.002220,0.001947,0.049458,282.630737,14.397897,0.494576,-70.724709,0.049562,0.000000
52.360001,63.544243,-70.769196,0.002207,0.001947,0.049458,282.658905,14.399331,0.494576,-70.769196,0.049562,0.000000
52.510002,63.520790,-70.769196,0.002203,0.001947,0.049458,282.554596,14.394017,0.494576,-70.769196,0.049562,0.000000
52.660004,63.525993,-70.769196,0.002212,0.001947,0.049458,282.577728,14.395196,0.494576,-70.769196,0.049562,0.000000
52.810001,63.515938,-70.724709,0.002212,0.001947,0.049458,282.532990,14.392917,0.494576,-70.724709,0.049562,0.000000
52.960003,63.515938,-70.724709,0.002207,0.001947,0.049458,282.532990,14.392917,0.494576,-70.724709,0.049562,0.000000
53.110004,63.517799,-70.769196,0.002216,0.001947,0.049458,282.541290,14.393339,0.494576,-70.769196,0.049562,0.000000
53.260002,63.509239,-70.724709,0.002203,0.001947,0.049458,282.503204,14.391399,0.494576,-70.724709,0.049562,0.000000
53.410004,63.498436,-70.813675,0.002216,0.001947,0.049458,282.455139,14.388951,0.494576,-70.813675,0.049562,0.000000
53.560001,63.491371,-70.724709,0.002216,0.001947,0.049458,282.423737,14.387350,0.494576,-70.724709,0.049562,0.000000
53.710003,63.474236,-70.724709,0.002212,0.001947,0.049458,282.347504,14.383468,0.494576,-70.724709,0.049562,0.000000
53.860004,63.472755,-70.769196,0.002212,0.001947,0.049458,282.340912,14.383132,0.494576,-70.769196,0.049562,0.000000
54.010002,63.461571,-70.769196,0.002203,0.001947,0.049458,282.291168,14.380598,0.494576,-70.769196,0.049562,0.000000
54.160004,63.468651,-70.813675,0.002216,0.001947,0.049458,282.322662,14.382202,0.494576,-70.813675,0.049562,0.000000
54.310001,63.461952,-70.813675,0.002216,0.001947,0.049458,282.292877,14.380684,0.494576,-70.813675,0.049562,0.000000
54.460003,63.450783,-70.858154,0.002203,0.001947,0.049458,282.243164,14.378153,0.494576,-70.858154,0.049562,0.000000
54.610004,63.442589,-70.813675,0.002216,0.001947,0.049458,282.206726,14.376296,0.494576,-70.813675,0.049562,0.000000
54.760002,63.434761,-70.813675,0.002212,0.001947,0.049458,282.171906,14.374522,0.494576,-70.813675,0.049562,0.000000
54.910004,63.426949,-70.813675,0.002216,0.001947,0.049458,282.137146,14.372752,0.494576,-70.813675,0.049562,0.000000
55.060001,63.418388,-70.813675,0.002216,0.001947,0.049458,282.099091,14.370811,0.494576,-70.813675,0.049562,0.000000
55.210003,63.416893,-70.858154,0.002216,0.001947,0.049458,282.092438,14.370473,0.494576,-70.858154,0.049562,0.000000
55.360004,63.422478,-70.813675,0.002207,0.001947,0.049458,282.117279,14.371738,0.494576,-70.813675,0.049562,0.000000
55.510002,63.412422,-70.858154,0.002220,0.001947,0.049458,282.072540,14.369460,0.494576,-70.858154,0.049562,0.000000
55.660004,63.411308,-70.902634,0.002216,0.001947,0.049458,282.067596,14.369207,0.494576,-70.902634,0.049562,0.000000
55.810001,63.396416,-70.858154,0.002216,0.001947,0.049458,282.001343,14.365833,0.494576,-70.858154,0.049562,0.000000
55.960003,63.393440,-70.858154,0.002220,0.001947,0.049458,281.988098,14.365159,0.494576,-70.858154,0.049562,0.000000
56.110004,63.381142,-70.858154,0.002216,0.001947,0.049458,281.933411,14.362371,0.494576,-70.858154,0.049562,0.000000
56.260002,63.372215,-70.813675,0.002216,0.001947,0.049458,281.893707,14.360349,0.494576,-70.813675,0.049562,0.000000
56.410004,63.369225,-70.858154,0.002216,0.001947,0.049458,281.880402,14.359672,0.494576,-70.858154,0.049562,0.000000
56.560001,63.371086,-70.858154,0.002216,0.001947,0.049458,281.888672,14.360093,0.494576,-70.858154,0.049562,0.000000
56.710003,63.366615,-70.902634,0.002216,0.001947,0.049458,281.868774,14.359080,0.494576,-70.902634,0.049562,0.000000
56.860004,63.352104,-70.947121,0.002212,0.001947,0.049458,281.804230,14.355792,0.494576,-70.947121,0.049562,0.000000
57.010002,63.349495,-70.902634,0.002216,0.001947,0.049458,281.792633,14.355201,0.494576,-70.902634,0.049562,0.000000
57.160004,63.357307,-70.902634,0.002212,0.001947,0.049458,281.827393,14.356971,0.494576,-70.902634,0.049562,0.000000
57.310001,63.354713,-70.902634,0.002216,0.001947,0.049458,281.815826,14.356383,0.494576,-70.902634,0.049562,0.000000
57.460003,63.345390,-70.902634,0.002216,0.001947,0.049458,281.774384,14.354270,0.494576,-70.902634,0.049562,0.000000
57.610004,63.332741,-70.902634,0.002212,0.001947,0.049458,281.718109,14.351404,0.494576,-70.902634,0.049562,0.000000
57.760002,63.328636,-70.947121,0.002216,0.001947,0.049458,281.699829,14.350473,0.494576,-70.947121,0.049562,0.000000
57.910004,63.333107,-70.991600,0.002220,0.001947,0.049458,281.719727,14.351488,0.494576,-70.991600,0.049562,0.000000
58.060001,63.313744,-70.947121,0.002216,0.001947,0.049458,281.633606,14.347099,0.494576,-70.947121,0.049562,0.000000
58.210003,63.310020,-70.947121,0.002203,0.001947,0.049458,281.617035,14.346255,0.494576,-70.947121,0.049562,0.000000
58.360004,63.308159,-70.947121,0.002216,0.001947,0.049458,281.608765,14.345834,0.494576,-70.947121,0.049562,0.000000
58.510002,63.316719,-70.947121,0.002203,0.001947,0.049458,281.646820,14.347774,0.494576,-70.947121,0.049562,0.000000
58.660004,63.307045,-70.991600,0.002212,0.001947,0.049458,281.603790,14.345581,0.494576,-70.991600,0.049562,0.000000
58.810001,63.309273,-70.991600,0.002207,0.001947,0.049458,281.613708,14.346086,0.494576,-70.991600,0.049562,0.000000
58.960003,63.291405,-70.991600,0.002212,0.001947,0.049458,281.534241,14.342037,0.494576,-70.991600,0.049562,0.000000
59.110004,63.285820,-70.947121,0.002216,0.001947,0.049458,281.509399,14.340772,0.494576,-70.947121,0.049562,0.000000
59.260002,63.274269,-70.991600,0.002212,0.001947,0.049458,281.458008,14.338154,0.494576,-70.991600,0.049562,0.000000
59.410004,63.284325,-70.947121,0.002207,0.001947,0.049458,281.502747,14.340433,0.494576,-70.947121,0.049562,0.000000
59.560001,63.288429,-70.991600,0.002199,0.001947,0.049458,281.520996,14.341363,0.494576,-70.991600,0.049562,0.000000
59.710003,63.276512,-70.991600,0.002216,0.001947,0.049458,281.467987,14.338662,0.494576,-70.991600,0.049562,0.000000
59.860004,63.271675,-71.036079,0.002212,0.001947,0.049458,281.446472,14.337566,0.494576,-71.036079,0.049562,0.000000
60.010002,63.267570,-71.036079,0.002212,0.001947,0.049458,281.428223,14.336637,0.494576,-71.036079,0.049562,0.000000
60.160004,63.256767,-70.991600,0.002220,0.001947,0.049458,281.380157,14.334188,0.494576,-70.991600,0.049562,0.000000
60.310001,63.251930,-70.947121,0.002207,0.001947,0.049458,281.358643,14.333092,0.494576,-70.947121,0.049562,0.000000
60.460003,63.252678,-71.036079,0.002207,0.001947,0.049458,281.361969,14.333261,0.494576,-71.036079,0.049562,0.000000
60.610004,63.251183,-71.036079,0.002212,0.001947,0.049458,281.355316,14.332923,0.494576,-71.036079,0.049562,0.000000
60.760002,63.254906,-70.991600,0.002220,0.001947,0.049458,281.371887,14.333767,0.494576,-70.991600,0.049562,0.000000
60.910004,63.249702,-71.036079,0.002212,0.001947,0.049458,281.348724,14.332587,0.494576,-71.036079,0.049562,0.000000
61.060001,63.238533,-71.036079,0.002212,0.001947,0.049458,281.299042,14.330056,0.494576,-71.036079,0.049562,0.000000
61.210003,63.232948,-71.036079,0.002212,0.001947,0.049458,281.274200,14.328791,0.494576,-71.036079,0.049562,0.000000
61.360004,63.237785,-70.991600,0.002216,0.001947,0.049458,281.295715,14.329887,0.494576,-70.991600,0.049562,0.000000
61.510002,63.237404,-71.036079,0.002216,0.001947,0.049458,281.294006,14.329801,0.494576,-71.036079,0.049562,0.000000
61.660004,63.231453,-71.036079,0.002216,0.001947,0.049458,281.267548,14.328452,0.494576,-71.036079,0.049562,0.000000
61.810001,63.224373,-71.125038,0.002216,0.001947,0.049458,281.236053,14.326848,0.494576,-71.125038,0.049562,0.000000
61.960003,63.218422,-71.080559,0.002212,0.001947,0.049458,281.209595,14.325499,0.494576,-71.080559,0.049562,0.000000
62.110004,63.215446,-71.080559,0.002212,0.001947,0.049458,281.196350,14.324825,0.494576,-71.080559,0.049562,0.000000
62.260002,63.212837,-71.080559,0.002220,0.001947,0.049458,281.184753,14.324233,0.494576,-71.080559,0.049562,0.000000
62.410004,63.207619,-71.080559,0.002216,0.001947,0.049458,281.161530,14.323051,0.494576,-71.080559,0.049562,0.000000
62.560001,63.203529,-71.080559,0.002203,0.001947,0.049458,281.143341,14.322124,0.494576,-71.080559,0.049562,0.000000
62.710003,63.188255,-71.036079,0.002216,0.001947,0.049458,281.075409,14.318664,0.494576,-71.036079,0.049562,0.000000
62.860004,63.193092,-71.125038,0.002216,0.001947,0.049458,281.096924,14.319759,0.494576,-71.125038,0.049562,0.000000
63.010002,63.180061,-71.169525,0.002216,0.001947,0.049458,281.038940,14.316806,0.494576,-71.169525,0.049562,0.000000
63.160004,63.171120,-71.125038,0.002207,0.001947,0.049458,280.999176,14.314780,0.494576,-71.125038,0.049562,0.000000
63.200005,63.176338,-71.169525,0.002207,0.001947,0.049458,281.022400,14.315963,0.494576,-71.169525,0.049562,0.000000