File: Data/AG AL compression 300N/AL membrane Peeled 300N_1_3_03192024_181246.csv
Time (sec),S:Load (lbs),S:HL1 (DIM),S:LVDT (in),S:Position (in),Ch:Position (mm),Ch:Load (N),Ch:Stress (MPa),Ch:Strain (mm/mm),Ch:HL1 (DIM),Set Point (),Cycles ()
0.110000,-0.021973,-188.332352,0.000056,-0.000000,-0.000000,-0.097739,-0.004979,-0.000000,-188.332352,0.000199,0.000000
0.290000,-0.007820,-188.287872,0.000069,-0.000000,-0.000000,-0.034786,-0.001772,-0.000000,-188.287872,0.000199,0.000000
0.470000,-0.000374,-188.332352,0.000056,0.000073,0.001865,-0.001663,-0.000085,0.018648,-188.332352,0.002402,0.000000
0.650000,0.008186,-188.465790,0.000056,0.000164,0.004163,0.036415,0.001855,0.041630,-188.465790,0.005403,0.000000
0.830000,0.001114,-188.421310,0.000151,0.000283,0.007198,0.004955,0.000252,0.071981,-188.421310,0.008404,0.000000
1.010000,-0.015274,-188.465790,0.000241,0.000401,0.010190,-0.067942,-0.003461,0.101901,-188.465790,0.011404,0.000000
1.190000,-0.022720,-188.421310,0.000345,0.000517,0.013121,-0.101065,-0.005149,0.131215,-188.421310,0.014405,0.000000
1.370000,-0.073730,-188.421310,0.000474,0.000636,0.016148,-0.327969,-0.016708,0.161479,-188.421310,0.017405,0.000000
1.550000,-0.051392,-188.465790,0.000595,0.000756,0.019209,-0.228601,-0.011646,0.192091,-188.465790,0.020406,0.000000
1.730000,-0.005592,-188.554749,0.000720,0.000876,0.022262,-0.024876,-0.001267,0.222620,-188.554749,0.023389,0.000000
1.910000,-0.024208,-188.510269,0.000841,0.000996,0.025306,-0.107683,-0.005486,0.253058,-188.510269,0.026390,0.000000
2.090000,-0.008942,-188.510269,0.000966,0.001116,0.028350,-0.039774,-0.002026,0.283496,-188.510269,0.029390,0.000000
2.270000,0.033508,-188.554749,0.001074,0.001236,0.031385,0.149052,0.007593,0.313851,-188.554749,0.032391,0.000000
2.450000,0.014519,-188.643707,0.001194,0.001354,0.034403,0.064583,0.003290,0.344032,-188.643707,0.035392,0.000000
2.630000,0.023087,-188.643707,0.001319,0.001467,0.037274,0.102694,0.005231,0.372736,-188.643707,0.038392,0.000000
2.810000,0.020851,-188.643707,0.001418,0.001582,0.040187,0.092750,0.004725,0.401873,-188.643707,0.041393,0.000000
2.990000,0.028297,-188.599228,0.001548,0.001696,0.043075,0.125873,0.006412,0.430751,-188.599228,0.044393,0.000000
3.170000,0.013771,-188.777161,0.001651,0.001816,0.046119,0.061257,0.003121,0.461193,-188.777161,0.047394,0.000000
3.350000,0.008186,-188.732681,0.001781,0.001938,0.049215,0.036415,0.001855,0.492154,-188.732681,0.050377,0.000000
3.530000,-0.002235,-188.732681,0.001910,0.002054,0.052181,-0.009944,-0.000507,0.521812,-188.732681,0.053378,0.000000
3.710000,-0.005219,-188.777161,0.002013,0.002173,0.055199,-0.023213,-0.001183,0.551989,-188.777161,0.056379,0.000000
3.890000,0.010048,-188.777161,0.002134,0.002293,0.058234,0.044695,0.002277,0.582344,-188.777161,0.059379,0.000000
4.070000,0.003349,-188.732681,0.002259,0.002412,0.061252,0.014898,0.000759,0.612525,-188.732681,0.062380,0.000000
4.250000,-0.013039,-188.866119,0.002376,0.002530,0.064261,-0.057999,-0.002955,0.642615,-188.866119,0.065380,0.000000
4.430000,0.000366,-188.910599,0.002492,0.002649,0.067297,0.001629,0.000083,0.672969,-188.910599,0.068381,0.000000
4.610000,0.013031,-188.866119,0.002617,0.002771,0.070376,0.057965,0.002953,0.703756,-188.866119,0.071382,0.000000
4.790000,0.024574,-188.955078,0.002755,0.002889,0.073376,0.109312,0.005569,0.733762,-188.955078,0.074382,0.000000
4.970000,0.016754,-188.955078,0.002867,0.003006,0.076342,0.074526,0.003797,0.763421,-188.955078,0.077383,0.000000
5.150000,0.011909,-188.955078,0.002984,0.003119,0.079213,0.052976,0.002699,0.792126,-188.955078,0.080366,0.000000
5.330000,0.003349,-188.999557,0.003083,0.003235,0.082161,0.014898,0.000759,0.821610,-188.999557,0.083366,0.000000
5.510000,0.021591,-188.999557,0.003216,0.003348,0.085032,0.096042,0.004893,0.850318,-188.999557,0.086367,0.000000
5.690000,-0.002609,-188.999557,0.003337,0.003465,0.088015,-0.011607,-0.000591,0.880151,-188.999557,0.089368,0.000000
5.870000,0.038727,-188.999557,0.003471,0.003590,0.091198,0.172265,0.008776,0.911978,-188.999557,0.092368,0.000000
6.050000,0.036491,-189.044037,0.003583,0.003711,0.094268,0.162322,0.008269,0.942677,-189.044037,0.095369,0.000000
6.230000,0.028671,-189.133011,0.003695,0.003828,0.097225,0.127536,0.006497,0.972249,-189.133011,0.098369,0.000000
6.410000,-0.000000,-189.088516,0.003829,0.003949,0.100295,-0.000000,-0.000000,1.002948,-189.088516,0.101370,0.000000
6.590000,0.024200,-189.088516,0.003932,0.004065,0.103252,0.107649,0.005484,1.032519,-189.088516,0.104371,0.000000
6.770000,0.014145,-189.088516,0.004053,0.004182,0.106235,0.062920,0.003205,1.062352,-189.088516,0.107354,0.000000
6.950000,-0.005219,-189.221970,0.004174,0.004303,0.109297,-0.023213,-0.001183,1.092968,-189.221970,0.110355,0.000000
7.130000,0.007820,-189.221970,0.004307,0.004419,0.112245,0.034786,0.001772,1.122452,-189.221970,0.113355,0.000000
7.310000,0.027924,-189.221970,0.004398,0.004538,0.115255,0.124210,0.006328,1.152546,-189.221970,0.116356,0.000000
7.490000,0.008186,-189.221970,0.004518,0.004656,0.118272,0.036415,0.001855,1.182723,-189.221970,0.119356,0.000000
7.670001,0.001862,-189.266449,0.004639,0.004765,0.121039,0.008281,0.000422,1.210390,-189.266449,0.122357,0.000000
7.850000,0.028297,-189.310928,0.004743,0.004883,0.124039,0.125873,0.006412,1.240393,-189.310928,0.125358,0.000000
8.030001,0.059204,-189.355408,0.004850,0.005004,0.127092,0.263353,0.013416,1.270922,-189.355408,0.128358,0.000000
8.210000,0.060318,-189.355408,0.004967,0.005123,0.130127,0.268308,0.013668,1.301273,-189.355408,0.131359,0.000000
8.390000,0.040215,-189.310928,0.005088,0.005244,0.133206,0.178883,0.009113,1.332060,-189.310928,0.134342,0.000000
8.570001,0.044685,-189.355408,0.005208,0.005366,0.136293,0.198770,0.010126,1.362933,-189.355408,0.137343,0.000000
8.750000,0.042076,-189.399887,0.005329,0.005483,0.139277,0.187164,0.009535,1.392766,-189.399887,0.140343,0.000000
8.930000,0.047661,-189.444366,0.005433,0.005600,0.142251,0.212006,0.010800,1.422511,-189.444366,0.143344,0.000000
9.110001,0.012657,-189.444366,0.005566,0.005716,0.145191,0.056302,0.002868,1.451912,-189.444366,0.146344,0.000000
9.290001,0.017868,-189.399887,0.005678,0.005835,0.148218,0.079481,0.004049,1.482176,-189.399887,0.149345,0.000000
9.470000,-0.007080,-189.488846,0.005795,0.005953,0.151218,-0.031494,-0.001604,1.512183,-189.488846,0.152346,0.000000
9.650001,0.007446,-189.488846,0.005920,0.006072,0.154236,0.033123,0.001687,1.542364,-189.488846,0.155346,0.000000
9.830001,0.022713,-189.488846,0.006010,0.006189,0.157193,0.101031,0.005147,1.571935,-189.488846,0.158347,0.000000
10.010000,0.024200,-189.533325,0.006153,0.006309,0.160246,0.107649,0.005484,1.602460,-189.533325,0.161347,0.000000
10.190001,0.050636,-189.533325,0.006269,0.006423,0.163151,0.225241,0.011474,1.631513,-189.533325,0.164331,0.000000
10.370001,0.051758,-189.622299,0.006364,0.006543,0.166187,0.230230,0.011728,1.661868,-189.622299,0.167331,0.000000
10.550000,0.075218,-189.666779,0.006502,0.006664,0.169265,0.334587,0.017045,1.692654,-189.666779,0.170332,0.000000
10.730000,0.069633,-189.711258,0.006614,0.006781,0.172240,0.309745,0.015779,1.722400,-189.711258,0.173333,0.000000
10.910001,0.056595,-189.711258,0.006743,0.006902,0.175319,0.251746,0.012825,1.753186,-189.711258,0.176333,0.000000
11.090000,0.049149,-189.622299,0.006838,0.007020,0.178319,0.218624,0.011137,1.783193,-189.622299,0.179334,0.000000
11.270000,0.038727,-189.711258,0.006993,0.007133,0.181172,0.172265,0.008776,1.811723,-189.711258,0.182334,0.000000
11.450001,0.046913,-189.755737,0.007105,0.007252,0.184190,0.208680,0.010631,1.841904,-189.755737,0.185335,0.000000
11.630000,0.018242,-189.711258,0.007196,0.007367,0.187121,0.081144,0.004134,1.871214,-189.711258,0.188336,0.000000
11.810000,-0.004845,-189.711258,0.007338,0.007486,0.190157,-0.021550,-0.001098,1.901569,-189.711258,0.191319,0.000000
11.990001,-0.020859,-189.755737,0.007446,0.007606,0.193201,-0.092784,-0.004727,1.932007,-189.755737,0.194320,0.000000
12.170001,0.016754,-189.755737,0.007580,0.007727,0.196262,0.074526,0.003797,1.962619,-189.755737,0.197320,0.000000
12.350000,0.069260,-189.844696,0.007679,0.007845,0.199263,0.308082,0.015694,1.992626,-189.844696,0.200320,0.000000
12.530001,0.071121,-189.844696,0.007795,0.007964,0.202289,0.316363,0.016116,2.022894,-189.844696,0.203321,0.000000
12.710001,0.094208,-189.800217,0.007933,0.008083,0.205316,0.419057,0.021348,2.053158,-189.800217,0.206322,0.000000
12.890000,0.119156,-189.844696,0.008054,0.008201,0.208316,0.530032,0.027001,2.083164,-189.844696,0.209322,0.000000
13.070001,0.137772,-189.933655,0.008157,0.008318,0.211274,0.612839,0.031219,2.112736,-189.933655,0.212323,0.000000
13.250001,0.179482,-189.978149,0.008274,0.008430,0.214127,0.798374,0.040671,2.141270,-189.978149,0.215324,0.000000
13.430000,0.226768,-189.933655,0.008386,0.008550,0.217171,1.008717,0.051386,2.171708,-189.933655,0.218324,0.000000
13.610001,0.339973,-189.933655,0.008507,0.008670,0.220223,1.512277,0.077039,2.202234,-189.933655,0.221307,0.000000
13.790001,0.451309,-190.022629,0.008610,0.008784,0.223103,2.007524,0.102268,2.231025,-190.022629,0.224308,0.000000
13.970000,0.644577,-190.022629,0.008727,0.008901,0.226077,2.867222,0.146063,2.260771,-190.022629,0.227309,0.000000
14.150001,0.617760,-190.067108,0.008744,-0.000006,-0.000147,2.747932,0.139986,-0.001472,-190.067108,0.000061,0.000000
14.330001,0.528763,-190.067108,0.008744,-0.000006,-0.000156,2.352055,0.119819,-0.001559,-190.067108,0.000061,0.000000
14.510000,0.514618,-190.111588,0.008752,-0.000006,-0.000156,2.289135,0.116614,-0.001559,-190.111588,0.000061,0.000000
14.690001,0.543663,-190.111588,0.008757,-0.000006,-0.000156,2.418334,0.123196,-0.001559,-190.111588,0.000321,0.000000
14.870001,0.547012,-190.156067,0.008757,-0.000006,-0.000147,2.433232,0.123955,-0.001472,-190.156067,0.000616,0.000000
15.050001,0.530624,-190.200546,0.008739,-0.000006,-0.000147,2.360335,0.120241,-0.001472,-190.200546,0.000919,0.000000
15.230000,0.546638,-190.200546,0.008761,-0.000006,-0.000147,2.431569,0.123870,-0.001472,-190.200546,0.001214,0.000000
15.410001,0.751816,-190.200546,0.008770,0.000023,0.000581,3.344244,0.170364,0.005810,-190.200546,0.001518,0.000000
15.590001,0.757401,-190.245026,0.008774,0.000030,0.000763,3.369086,0.171629,0.007630,-190.245026,0.001813,0.000000
15.770000,0.803574,-190.333984,0.008774,0.000039,0.000997,3.574474,0.182092,0.009973,-190.333984,0.002116,0.000000
15.950001,0.831131,-190.289505,0.008774,0.000056,0.001414,3.697055,0.188337,0.014137,-190.289505,0.002420,0.000000
16.130001,0.908211,-190.245026,0.008800,0.000072,0.001839,4.039923,0.205803,0.018387,-190.245026,0.002715,0.000000
16.310001,0.881401,-190.245026,0.008813,0.000086,0.002185,3.920668,0.199728,0.021854,-190.245026,0.003018,0.000000
16.490002,0.928696,-190.378464,0.008847,0.000095,0.002402,4.131045,0.210445,0.024023,-190.378464,0.003313,0.000000
16.670000,0.976357,-190.333984,0.008834,0.000104,0.002637,4.343050,0.221246,0.026366,-190.333984,0.003616,0.000000
16.850000,1.006149,-190.422958,0.008839,0.000116,0.002948,4.475575,0.227997,0.029484,-190.422958,0.003920,0.000000
17.030001,1.103706,-190.378464,0.008860,0.000129,0.003269,4.909531,0.250103,0.032694,-190.378464,0.004215,0.000000
17.210001,1.144669,-190.422958,0.008873,0.000138,0.003512,5.091740,0.259386,0.035124,-190.422958,0.004518,0.000000
17.390001,1.162170,-190.467438,0.008890,0.000144,0.003668,5.169592,0.263352,0.036683,-190.467438,0.004813,0.000000
17.570002,1.300697,-190.511917,0.008882,0.000159,0.004050,5.785790,0.294742,0.040498,-190.511917,0.005117,0.000000
17.750000,1.410545,-190.511917,0.008912,0.000181,0.004596,6.274419,0.319634,0.045964,-190.511917,0.005420,0.000000
17.930000,1.409798,-190.467438,0.008929,0.000192,0.004865,6.271093,0.319465,0.048651,-190.467438,0.005715,0.000000
18.110001,1.489113,-190.467438,0.008925,0.000201,0.005099,6.623905,0.337438,0.050994,-190.467438,0.006019,0.000000
18.290001,1.565453,-190.556396,0.008942,0.000215,0.005472,6.963481,0.354737,0.054722,-190.556396,0.006314,0.000000
18.470001,1.629128,-190.556396,0.008925,0.000225,0.005715,7.246721,0.369166,0.057152,-190.556396,0.006617,0.000000
18.650002,1.626518,-190.645355,0.008946,0.000233,0.005906,7.235115,0.368574,0.059060,-190.645355,0.006921,0.000000
18.830002,1.812332,-190.600876,0.008959,0.000248,0.006296,8.061656,0.410680,0.062962,-190.600876,0.007216,0.000000
19.010000,1.986603,-190.600876,0.008972,0.000262,0.006652,8.836850,0.450171,0.066516,-190.600876,0.007519,0.000000
19.190001,2.069641,-190.645355,0.008994,0.000271,0.006895,9.206223,0.468987,0.068946,-190.645355,0.007814,0.000000
19.370001,2.153801,-190.734314,0.008998,0.000280,0.007120,9.580585,0.488058,0.071201,-190.734314,0.008117,0.000000
19.550001,2.248756,-190.645355,0.009002,0.000290,0.007363,10.002968,0.509575,0.073628,-190.645355,0.008421,0.000000
19.730001,2.484467,-190.689835,0.009011,0.000308,0.007831,11.051459,0.562988,0.078309,-190.689835,0.008715,0.000000
19.910002,2.525803,-190.823273,0.009046,0.000320,0.008126,11.235332,0.572355,0.081258,-190.823273,0.009019,0.000000
20.090000,2.678101,-190.823273,0.009050,0.000333,0.008447,11.912786,0.606866,0.084468,-190.823273,0.009314,0.000000
20.270000,2.798752,-190.823273,0.009063,0.000345,0.008759,12.449470,0.634206,0.087590,-190.823273,0.009617,0.000000
20.450001,2.936897,-190.823273,0.009076,0.000354,0.009002,13.063972,0.665510,0.090020,-190.823273,0.009921,0.000000
20.630001,2.998337,-190.867767,0.009084,0.000363,0.009227,13.337268,0.679433,0.092272,-190.867767,0.010216,0.000000
20.810001,3.304802,-190.823273,0.009080,0.000378,0.009600,14.700493,0.748879,0.096004,-190.823273,0.010519,0.000000
20.990002,3.460457,-190.912247,0.009106,0.000389,0.009887,15.392880,0.784151,0.098865,-190.912247,0.010814,0.000000
21.170000,3.537910,-190.867767,0.009115,0.000397,0.010095,15.737411,0.801702,0.100947,-190.867767,0.011118,0.000000
21.350000,3.718140,-190.956726,0.009115,0.000407,0.010329,16.539112,0.842542,0.103286,-190.956726,0.011421,0.000000
21.530001,4.106522,-191.001205,0.009132,0.000428,0.010875,18.266720,0.930551,0.108751,-191.001205,0.011716,0.000000
21.710001,4.293823,-191.001205,0.009145,0.000442,0.011222,19.099880,0.972994,0.112218,-191.001205,0.012020,0.000000
21.890001,4.427132,-191.045685,0.009158,0.000450,0.011421,19.692865,1.003202,0.114213,-191.045685,0.012315,0.000000
22.070002,4.693382,-191.001205,0.009166,0.000465,0.011820,20.877207,1.063536,0.118202,-191.001205,0.012618,0.000000
22.250002,4.833389,-191.045685,0.009184,0.000474,0.012037,21.499989,1.095262,0.120371,-191.045685,0.012922,0.000000
22.430000,5.082878,-191.045685,0.009184,0.000487,0.012367,22.609772,1.151797,0.123668,-191.045685,0.013216,0.000000
22.610001,5.260872,-191.090164,0.009205,0.000497,0.012618,23.401527,1.192131,0.126181,-191.090164,0.013520,0.000000
22.790001,5.577019,-191.090164,0.009196,0.000509,0.012930,24.807817,1.263770,0.129303,-191.090164,0.013815,0.000000
22.970001,5.779221,-191.134644,0.009209,0.000519,0.013191,25.707256,1.309590,0.131907,-191.134644,0.014118,0.000000
23.150002,5.927422,-191.134644,0.009222,0.000530,0.013451,26.366488,1.343173,0.134508,-191.134644,0.014422,0.000000
23.330002,6.431618,-191.179123,0.009235,0.000547,0.013893,28.609264,1.457425,0.138928,-191.179123,0.014717,0.000000
23.510000,6.653175,-191.179123,0.009244,0.000560,0.014231,29.594803,1.507631,0.142312,-191.179123,0.015020,0.000000
23.690001,6.835266,-191.312576,0.009261,0.000571,0.014509,30.404781,1.548893,0.145086,-191.312576,0.015315,0.000000
23.870001,7.260887,-191.268097,0.009270,0.000587,0.014899,32.298038,1.645341,0.148989,-191.268097,0.015619,0.000000
24.050001,7.276527,-191.268097,0.009274,0.000593,0.015055,32.367611,1.648885,0.150552,-191.268097,0.015914,0.000000
24.230001,7.478355,-191.312576,0.009296,0.000603,0.015306,33.265385,1.694620,0.153065,-191.312576,0.016217,0.000000
24.410002,7.914032,-191.357056,0.009300,0.000617,0.015671,35.203373,1.793345,0.156710,-191.357056,0.016521,0.000000
24.590002,8.239113,-191.357056,0.009300,0.000630,0.015992,36.649403,1.867010,0.159916,-191.357056,0.016816,0.000000
24.770000,8.516899,-191.357056,0.009313,0.000641,0.016286,37.885059,1.929957,0.162864,-191.357056,0.017119,0.000000
24.950001,8.793571,-191.357056,0.009313,0.000652,0.016573,39.115761,1.992652,0.165725,-191.357056,0.017414,0.000000
25.130001,8.897095,-191.401535,0.009322,0.000660,0.016755,39.576256,2.016110,0.167550,-191.401535,0.017717,0.000000
25.310001,9.495491,-191.401535,0.009334,0.000678,0.017214,42.238052,2.151709,0.172145,-191.401535,0.018021,0.000000
25.490002,9.807541,-191.446014,0.009352,0.000691,0.017562,43.626122,2.222420,0.175615,-191.446014,0.018316,0.000000
25.670002,10.072296,-191.490494,0.009352,0.000704,0.017873,44.803810,2.282415,0.178734,-191.490494,0.018619,0.000000
25.850000,10.309128,-191.534973,0.009373,0.000715,0.018160,45.857292,2.336082,0.181599,-191.534973,0.018914,0.000000
26.030001,10.453606,-191.490494,0.009390,0.000725,0.018403,46.499962,2.368821,0.184025,-191.490494,0.019218,0.000000
26.210001,10.756721,-191.579453,0.009382,0.000733,0.018619,47.848286,2.437508,0.186194,-191.579453,0.019521,0.000000
26.390001,11.029297,-191.668411,0.009395,0.000745,0.018932,49.060764,2.499274,0.189317,-191.668411,0.019816,0.000000
26.570002,11.458267,-191.579453,0.009395,0.000757,0.019218,50.968918,2.596481,0.192178,-191.579453,0.020120,0.000000
26.750002,11.793030,-191.579453,0.009421,0.000769,0.019530,52.458015,2.672339,0.195301,-191.579453,0.020415,0.000000
26.930002,12.196312,-191.623932,0.009429,0.000784,0.019912,54.251904,2.763724,0.199116,-191.623932,0.020718,0.000000
27.110001,12.096886,-191.668411,0.009442,0.000788,0.020007,53.809635,2.741193,0.200070,-191.668411,0.021022,0.000000
27.290001,12.942543,-191.712906,0.009442,0.000810,0.020562,57.571308,2.932822,0.205618,-191.712906,0.021317,0.000000
27.470001,13.112724,-191.668411,0.009438,0.000820,0.020831,58.328312,2.971386,0.208309,-191.668411,0.021620,0.000000
27.650002,13.424400,-191.757385,0.009464,0.000832,0.021126,59.714714,3.042013,0.211258,-191.757385,0.021915,0.000000
27.830002,13.732719,-191.801865,0.009490,0.000845,0.021455,61.086185,3.111879,0.214551,-191.801865,0.022218,0.000000
28.010002,14.035088,-191.846344,0.009477,0.000855,0.021707,62.431187,3.180396,0.217068,-191.846344,0.022522,0.000000
28.190001,14.197815,-191.801865,0.009490,0.000864,0.021949,63.155037,3.217271,0.219494,-191.801865,0.022817,0.000000
28.370001,14.621201,-191.801865,0.009485,0.000876,0.022262,65.038345,3.313211,0.222616,-191.801865,0.023120,0.000000
28.550001,15.178268,-191.801865,0.009507,0.000890,0.022617,67.516312,3.439445,0.226174,-191.801865,0.023415,0.000000
28.730001,15.461273,-191.890823,0.009528,0.000902,0.022912,68.775177,3.503575,0.229122,-191.890823,0.023719,0.000000
28.910002,15.625488,-191.890823,0.009528,0.000912,0.023172,69.505646,3.540786,0.231723,-191.890823,0.024022,0.000000
29.090002,15.523460,-191.979782,0.009524,0.000915,0.023242,69.051804,3.517666,0.232415,-191.979782,0.024317,0.000000
29.270000,16.340820,-191.935303,0.009533,0.000934,0.023719,72.687599,3.702883,0.237188,-191.935303,0.024621,0.000000
29.450001,16.761971,-191.935303,0.009550,0.000946,0.024039,74.560966,3.798317,0.240394,-191.935303,0.024916,0.000000
29.630001,17.008110,-191.979782,0.009563,0.000958,0.024326,75.655853,3.854093,0.243259,-191.979782,0.025219,0.000000
29.810001,17.436340,-192.068741,0.009580,0.000972,0.024690,77.560715,3.951131,0.246900,-192.068741,0.025523,0.000000
29.990002,17.746155,-191.979782,0.009576,0.000982,0.024941,78.938843,4.021336,0.249413,-191.979782,0.025818,0.000000
30.170002,17.932335,-191.979782,0.009593,0.000992,0.025184,79.767006,4.063525,0.251843,-191.979782,0.026121,0.000000
30.350002,18.241409,-192.068741,0.009593,0.001002,0.025444,81.141838,4.133563,0.254443,-192.068741,0.026416,0.000000
30.530001,18.643944,-192.113220,0.009615,0.001012,0.025713,82.932404,4.224778,0.257134,-192.113220,0.026719,0.000000
30.710001,19.237503,-192.157715,0.009615,0.001028,0.026112,85.572685,4.359280,0.261124,-192.157715,0.027023,0.000000
30.890001,19.512688,-192.157715,0.009632,0.001038,0.026372,86.796768,4.421638,0.263724,-192.157715,0.027317,0.000000
31.070002,19.386826,-192.157715,0.009619,0.001041,0.026450,86.236908,4.393117,0.264504,-192.157715,0.027621,0.000000
31.250002,20.524422,-192.157715,0.009641,0.001065,0.027049,91.297188,4.650900,0.270488,-192.157715,0.027916,0.000000
31.430002,20.873711,-192.246674,0.009658,0.001077,0.027344,92.850899,4.730051,0.273436,-192.246674,0.028219,0.000000
31.610001,21.188736,-192.246674,0.009671,0.001087,0.027613,94.252205,4.801436,0.276127,-192.246674,0.028514,0.000000
31.790001,21.479561,-192.246674,0.009675,0.001099,0.027925,95.545860,4.867338,0.279246,-192.246674,0.028818,0.000000
31.970001,22.037003,-192.202194,0.009675,0.001111,0.028228,98.025482,4.993656,0.282281,-192.202194,0.029121,0.000000
32.150002,22.117058,-192.246674,0.009701,0.001121,0.028471,98.381584,5.011797,0.284711,-192.246674,0.029416,0.000000
32.330002,22.763123,-192.335632,0.009684,0.001133,0.028775,101.255424,5.158197,0.287747,-192.335632,0.029720,0.000000
32.510002,23.446060,-192.380112,0.009692,0.001148,0.029156,104.293282,5.312953,0.291562,-192.380112,0.030015,0.000000
32.690002,23.686981,-192.335632,0.009705,0.001157,0.029382,105.364952,5.367547,0.293818,-192.335632,0.030318,0.000000
32.870003,23.688095,-192.380112,0.009705,0.001162,0.029512,105.369911,5.367799,0.295116,-192.380112,0.030622,0.000000
33.050003,24.439171,-192.424591,0.009718,0.001178,0.029919,108.710861,5.537995,0.299192,-192.424591,0.030917,0.000000
33.230003,25.098648,-192.424591,0.009731,0.001192,0.030266,111.644363,5.687435,0.302663,-192.424591,0.031220,0.000000
33.410000,25.691833,-192.513550,0.009748,0.001205,0.030613,114.282982,5.821853,0.306130,-192.513550,0.031515,0.000000
33.590000,26.085808,-192.424591,0.009753,0.001216,0.030891,116.035469,5.911129,0.308908,-192.424591,0.031818,0.000000
33.770000,26.549782,-192.424591,0.009761,0.001228,0.031203,118.099327,6.016267,0.312027,-192.424591,0.032122,0.000000
33.950001,26.969818,-192.513550,0.009770,0.001240,0.031498,119.967743,6.111448,0.314975,-192.513550,0.032417,0.000000
34.130001,27.319847,-192.602524,0.009779,0.001249,0.031714,121.524750,6.190765,0.317144,-192.602524,0.032720,0.000000
34.310001,27.706741,-192.602524,0.009783,0.001260,0.031992,123.245743,6.278437,0.319918,-192.602524,0.033015,0.000000
34.490002,28.523727,-192.602524,0.009791,0.001274,0.032356,126.879875,6.463569,0.323563,-192.602524,0.033319,0.000000
34.670002,28.703209,-192.647003,0.009791,0.001280,0.032512,127.678253,6.504240,0.325122,-192.647003,0.033622,0.000000
34.850002,29.288956,-192.647003,0.009822,0.001293,0.032851,130.283783,6.636972,0.328506,-192.647003,0.033917,0.000000
35.030003,29.786812,-192.647003,0.009804,0.001306,0.033172,132.498352,6.749788,0.331716,-192.647003,0.034221,0.000000
35.210003,30.712158,-192.691483,0.009817,0.001320,0.033536,136.614502,6.959474,0.335357,-192.691483,0.034516,0.000000
35.390003,31.525421,-192.691483,0.009822,0.001335,0.033917,140.232071,7.143763,0.339172,-192.691483,0.034819,0.000000
35.570004,32.000938,-192.691483,0.009822,0.001346,0.034186,142.347290,7.251516,0.341859,-192.691483,0.035123,0.000000
35.750000,32.452255,-192.735962,0.009843,0.001357,0.034472,144.354843,7.353786,0.344724,-192.735962,0.035418,0.000000
35.930000,32.825005,-192.780441,0.009860,0.001367,0.034724,146.012909,7.438252,0.347238,-192.780441,0.035721,0.000000
36.110001,33.267006,-192.780441,0.009856,0.001377,0.034975,147.979034,7.538412,0.349751,-192.780441,0.036016,0.000000
36.290001,33.874344,-192.780441,0.009856,0.001390,0.035313,150.680603,7.676036,0.353134,-192.780441,0.036319,0.000000
36.470001,35.214890,-192.780441,0.009878,0.001408,0.035756,156.643646,7.979808,0.357559,-192.780441,0.036623,0.000000
36.650002,35.303886,-192.869400,0.009869,0.001415,0.035947,157.039536,7.999975,0.359467,-192.869400,0.036918,0.000000
36.830002,35.603645,-192.869400,0.009873,0.001421,0.036085,158.372925,8.067902,0.360852,-192.869400,0.037221,0.000000
37.010002,36.151405,-192.913879,0.009882,0.001432,0.036371,160.809479,8.192025,0.363713,-192.913879,0.037516,0.000000
37.190002,37.114357,-192.913879,0.009891,0.001449,0.036805,165.092911,8.410233,0.368051,-192.913879,0.037820,0.000000
37.370003,38.069870,-192.913879,0.009895,0.001462,0.037126,169.343246,8.626756,0.371260,-192.913879,0.038123,0.000000
37.550003,38.931541,-193.002853,0.009904,0.001477,0.037516,173.176147,8.822014,0.375163,-193.002853,0.038418,0.000000
37.730003,39.574623,-193.047333,0.009916,0.001488,0.037802,176.036713,8.967737,0.378024,-193.047333,0.038722,0.000000
37.910004,39.873268,-193.002853,0.009921,0.001495,0.037976,177.365158,9.035412,0.379757,-193.002853,0.039017,0.000000
38.090000,40.462364,-193.047333,0.009934,0.001508,0.038314,179.985580,9.168902,0.383141,-193.047333,0.039320,0.000000
38.270000,41.127792,-193.091812,0.009951,0.001517,0.038522,182.945557,9.319692,0.385223,-193.091812,0.039624,0.000000
38.450001,42.320503,-193.136292,0.009951,0.001533,0.038939,188.251007,9.589963,0.389386,-193.136292,0.039919,0.000000
38.630001,42.594193,-193.180771,0.009934,0.001540,0.039112,189.468430,9.651982,0.391120,-193.180771,0.040222,0.000000
38.810001,43.033218,-193.091812,0.009938,0.001549,0.039355,191.421310,9.751467,0.393546,-193.091812,0.040517,0.000000
38.990002,44.072884,-193.136292,0.009964,0.001564,0.039719,196.045975,9.987058,0.397191,-193.136292,0.040820,0.000000
39.170002,45.829369,-193.180771,0.009955,0.001584,0.040239,203.859207,10.385084,0.402395,-193.180771,0.041115,0.000000
39.350002,46.422554,-193.136292,0.009964,0.001594,0.040491,206.497833,10.519501,0.404908,-193.136292,0.041419,0.000000
39.530003,47.024307,-193.225250,0.009981,0.001606,0.040794,209.174561,10.655860,0.407944,-193.225250,0.041722,0.000000
39.710003,47.728462,-193.225250,0.009981,0.001618,0.041089,212.306808,10.815424,0.410892,-193.225250,0.042017,0.000000
39.890003,48.377510,-193.225250,0.009977,0.001629,0.041367,215.193909,10.962501,0.413666,-193.225250,0.042321,0.000000
40.070004,48.685463,-193.225250,0.009998,0.001633,0.041488,216.563751,11.032284,0.414881,-193.225250,0.042616,0.000000
40.250004,50.204369,-193.403168,0.009998,0.001651,0.041948,223.320190,11.376472,0.419476,-193.403168,0.042919,0.000000
40.430000,50.990822,-193.358688,0.009994,0.001661,0.042191,226.818497,11.554686,0.421906,-193.358688,0.043223,0.000000
40.610001,51.818230,-193.314209,0.010003,0.001674,0.042529,230.498993,11.742179,0.425290,-193.314209,0.043518,0.000000
40.790001,52.310135,-193.269730,0.010011,0.001683,0.042754,232.687103,11.853646,0.427542,-193.269730,0.043821,0.000000
40.970001,52.946144,-193.447662,0.010024,0.001695,0.043040,235.516205,11.997767,0.430403,-193.447662,0.044116,0.000000
41.150002,54.543251,-193.447662,0.010016,0.001710,0.043439,242.620499,12.359677,0.434392,-193.447662,0.044420,0.000000
41.330002,55.616806,-193.447662,0.010024,0.001725,0.043804,247.395905,12.602948,0.438037,-193.447662,0.044723,0.000000
41.510002,56.196587,-193.492142,0.010024,0.001733,0.044012,249.974899,12.734328,0.440119,-193.492142,0.045018,0.000000
41.690002,57.282799,-193.492142,0.010050,0.001746,0.044341,254.806610,12.980468,0.443412,-193.492142,0.045321,0.000000
41.870003,58.026054,-193.536621,0.010042,0.001758,0.044645,258.112793,13.148892,0.446447,-193.536621,0.045616,0.000000
42.050003,59.119339,-193.536621,0.010037,0.001770,0.044966,262.975952,13.396634,0.449657,-193.536621,0.045919,0.000000
42.230003,60.091606,-193.581100,0.010042,0.001784,0.045313,267.300812,13.616952,0.453128,-193.581100,0.046223,0.000000
42.410004,60.573456,-193.536621,0.010046,0.001789,0.045434,269.444183,13.726141,0.454339,-193.536621,0.046518,0.000000
42.590000,61.501778,-193.581100,0.010050,0.001802,0.045781,273.573578,13.936502,0.457810,-193.581100,0.046821,0.000000
42.770000,62.463989,-193.581100,0.010072,0.001816,0.046128,277.853699,14.154542,0.461277,-193.581100,0.047116,0.000000
42.950001,63.751656,-193.670059,0.010050,0.001830,0.046475,283.581512,14.446332,0.464747,-193.670059,0.047420,0.000000
43.130001,64.914574,-193.714539,0.010072,0.001842,0.046787,288.754456,14.709852,0.467870,-193.714539,0.047723,0.000000
43.310001,65.903587,-193.714539,0.010067,0.001854,0.047091,293.153809,14.933966,0.470905,-193.714539,0.048018,0.000000
43.490002,66.862083,-193.625580,0.010080,0.001867,0.047411,297.417389,15.151165,0.474111,-193.625580,0.048322,0.000000
43.670002,67.531227,-193.759018,0.010085,0.001873,0.047585,300.393890,15.302794,0.475848,-193.759018,0.047637,0.000000
43.850002,67.162209,-193.759018,0.010106,0.001866,0.047403,298.752411,15.219174,0.474028,-193.759018,0.047637,0.000000
44.030003,66.897087,-193.803497,0.010089,0.001866,0.047403,297.573120,15.159097,0.474028,-193.803497,0.047403,0.000000
44.210003,66.757439,-193.714539,0.010093,0.001865,0.047377,296.951904,15.127451,0.473767,-193.714539,0.047403,0.000000
44.390003,66.558968,-193.803497,0.010111,0.001865,0.047368,296.069061,15.082478,0.473680,-193.803497,0.047403,0.000000
44.570004,66.390663,-193.847992,0.010102,0.001865,0.047359,295.320404,15.044339,0.473593,-193.847992,0.047403,0.000000
44.750004,66.264046,-193.847992,0.010102,0.001865,0.047359,294.757202,15.015647,0.473593,-193.847992,0.047403,0.000000
44.930000,66.127022,-193.847992,0.010111,0.001865,0.047359,294.147675,14.984597,0.473593,-193.847992,0.047403,0.000000
45.110001,66.008980,-193.936951,0.010102,0.001864,0.047351,293.622620,14.957849,0.473505,-193.936951,0.047403,0.000000
45.290001,65.911034,-193.936951,0.010119,0.001864,0.047351,293.186920,14.935654,0.473505,-193.936951,0.047403,0.000000
45.470001,65.814964,-193.981430,0.010102,0.001864,0.047351,292.759583,14.913884,0.473505,-193.981430,0.047403,0.000000
45.650002,65.731560,-194.025909,0.010111,0.001864,0.047351,292.388580,14.894984,0.473505,-194.025909,0.047403,0.000000
45.830002,65.654472,-194.025909,0.010102,0.001864,0.047342,292.045685,14.877517,0.473418,-194.025909,0.047403,0.000000
46.010002,65.581490,-194.025909,0.010106,0.001864,0.047342,291.721039,14.860978,0.473418,-194.025909,0.047403,0.000000
46.190002,65.507393,-193.981430,0.010123,0.001864,0.047342,291.391449,14.844188,0.473418,-193.981430,0.047403,0.000000
46.370003,65.451912,-194.114868,0.010111,0.001864,0.047342,291.144653,14.831614,0.473418,-194.114868,0.047403,0.000000
46.550003,65.371468,-194.070389,0.010102,0.001864,0.047342,290.786804,14.813387,0.473418,-194.070389,0.047403,0.000000
46.730003,65.331627,-194.159348,0.010106,0.001864,0.047342,290.609589,14.804358,0.473418,-194.159348,0.047403,0.000000
46.910004,65.282845,-194.114868,0.010111,0.001864,0.047342,290.392609,14.793304,0.473418,-194.114868,0.047403,0.000000
47.090004,65.218056,-194.159348,0.010115,0.001864,0.047342,290.104401,14.778623,0.473418,-194.159348,0.047403,0.000000
47.270000,65.177101,-194.159348,0.010102,0.001864,0.047342,289.922211,14.769342,0.473418,-194.159348,0.047403,0.000000
47.450001,65.124596,-194.248306,0.010111,0.001864,0.047342,289.688660,14.757444,0.473418,-194.248306,0.047403,0.000000
47.630001,65.086235,-194.159348,0.010115,0.001864,0.047342,289.518036,14.748752,0.473418,-194.159348,0.047403,0.000000
47.810001,65.039696,-194.203827,0.010115,0.001864,0.047342,289.311005,14.738206,0.473418,-194.203827,0.047403,0.000000
47.990002,65.008034,-194.248306,0.010111,0.001864,0.047342,289.170166,14.731030,0.473418,-194.248306,0.047403,0.000000
48.170002,64.953667,-194.337280,0.010093,0.001864,0.047342,288.928345,14.718711,0.473418,-194.337280,0.047403,0.000000
48.350002,64.931694,-194.248306,0.010111,0.001864,0.047342,288.830597,14.713732,0.473418,-194.248306,0.047403,0.000000
48.530003,64.903404,-194.248306,0.010115,0.001864,0.047342,288.704773,14.707321,0.473418,-194.248306,0.047403,0.000000
48.710003,64.847542,-194.292801,0.010115,0.001864,0.047342,288.456268,14.694663,0.473418,-194.292801,0.047403,0.000000
48.890003,64.819237,-194.337280,0.010115,0.001864,0.047342,288.330353,14.688249,0.473418,-194.337280,0.047403,0.000000
49.070004,64.795418,-194.381760,0.010115,0.001864,0.047342,288.224426,14.682852,0.473418,-194.381760,0.047403,0.000000
49.250004,64.751839,-194.381760,0.010111,0.001864,0.047342,288.030579,14.672976,0.473418,-194.381760,0.047403,0.000000
49.430004,64.729500,-194.426239,0.010119,0.001864,0.047342,287.931183,14.667914,0.473418,-194.426239,0.047403,0.000000
49.610001,64.696358,-194.470718,0.010115,0.001864,0.047342,287.783783,14.660404,0.473418,-194.470718,0.047403,0.000000
49.790001,64.669182,-194.515198,0.010098,0.001864,0.047342,287.662903,14.654246,0.473418,-194.515198,0.047403,0.000000
49.970001,64.639015,-194.559677,0.010128,0.001864,0.047342,287.528687,14.647410,0.473418,-194.559677,0.047403,0.000000
50.150002,64.613701,-194.515198,0.010111,0.001864,0.047342,287.416107,14.641673,0.473418,-194.515198,0.047403,0.000000
50.330002,64.587257,-194.515198,0.010111,0.001864,0.047342,287.298462,14.635682,0.473418,-194.515198,0.047403,0.000000
50.510002,64.565651,-194.515198,0.010111,0.001864,0.047342,287.202362,14.630786,0.473418,-194.515198,0.047403,0.000000
50.690002,64.540337,-194.604156,0.010123,0.001864,0.047342,287.089752,14.625050,0.473418,-194.604156,0.047403,0.000000
50.870003,64.512413,-194.648636,0.010106,0.001864,0.047342,286.965546,14.618722,0.473418,-194.648636,0.047403,0.000000
51.050003,64.488197,-194.604156,0.010119,0.001864,0.047342,286.857819,14.613235,0.473418,-194.604156,0.047403,0.000000
51.230003,64.465492,-194.604156,0.010123,0.001864,0.047342,286.756836,14.608088,0.473418,-194.604156,0.047403,0.000000
51.410004,64.434578,-194.648636,0.010119,0.001864,0.047342,286.619324,14.601084,0.473418,-194.648636,0.047403,0.000000
51.590004,64.426018,-194.737610,0.010128,0.001864,0.047342,286.581238,14.599144,0.473418,-194.737610,0.047403,0.000000
51.770004,64.403297,-194.737610,0.010115,0.001864,0.047342,286.480164,14.593996,0.473418,-194.737610,0.047403,0.000000
51.950001,64.375374,-194.782089,0.010111,0.001864,0.047333,286.355957,14.587668,0.473331,-194.782089,0.047403,0.000000
52.130001,64.364952,-194.782089,0.010115,0.001864,0.047333,286.309601,14.585307,0.473331,-194.782089,0.047403,0.000000
52.310001,64.334038,-194.826569,0.010128,0.001864,0.047333,286.172089,14.578301,0.473331,-194.826569,0.047403,0.000000
52.490002,64.318398,-194.782089,0.010128,0.001864,0.047333,286.102509,14.574757,0.473331,-194.782089,0.047403,0.000000
52.670002,64.281914,-194.871048,0.010119,0.001864,0.047333,285.940247,14.566490,0.473331,-194.871048,0.047403,0.000000
52.850002,64.268135,-194.826569,0.010128,0.001864,0.047333,285.878937,14.563368,0.473331,-194.826569,0.047403,0.000000
53.030003,64.258080,-194.826569,0.010132,0.001864,0.047333,285.834229,14.561090,0.473331,-194.826569,0.047403,0.000000
53.210003,64.245796,-194.871048,0.010132,0.001864,0.047333,285.779572,14.558306,0.473331,-194.871048,0.047403,0.000000
53.390003,64.226433,-194.915527,0.010119,0.001864,0.047333,285.693451,14.553918,0.473331,-194.915527,0.047403,0.000000
53.570004,64.213768,-194.960007,0.010132,0.001864,0.047333,285.637115,14.551047,0.473331,-194.960007,0.047403,0.000000
53.750004,64.196632,-195.004486,0.010111,0.001864,0.047333,285.560883,14.547165,0.473331,-195.004486,0.047403,0.000000
53.930004,64.178398,-194.915527,0.010115,0.001864,0.047333,285.479767,14.543033,0.473331,-194.915527,0.047403,0.000000
54.110004,64.162376,-195.004486,0.010132,0.001864,0.047333,285.408508,14.539403,0.473331,-195.004486,0.047403,0.000000
54.290001,64.143013,-195.004486,0.010115,0.001864,0.047333,285.322357,14.535014,0.473331,-195.004486,0.047403,0.000000
54.470001,64.129234,-195.048965,0.010111,0.001864,0.047333,285.261078,14.531892,0.473331,-195.048965,0.047403,0.000000
54.650002,64.111366,-195.048965,0.010119,0.001864,0.047333,285.181610,14.527843,0.473331,-195.048965,0.047403,0.000000
54.830002,64.102425,-195.093445,0.010128,0.001864,0.047333,285.141815,14.525817,0.473331,-195.093445,0.047403,0.000000
55.010002,64.083809,-195.048965,0.010132,0.001864,0.047333,285.059021,14.521599,0.473331,-195.048965,0.047403,0.000000
55.190002,64.068535,-195.093445,0.010119,0.001864,0.047333,284.991089,14.518138,0.473331,-195.093445,0.047403,0.000000
55.370003,64.059608,-195.182419,0.010115,0.001864,0.047333,284.951355,14.516114,0.473331,-195.182419,0.047403,0.000000
55.550003,64.046577,-195.137939,0.010115,0.001864,0.047333,284.893402,14.513163,0.473331,-195.137939,0.047403,0.000000
55.730003,64.033165,-195.182419,0.010111,0.001864,0.047333,284.833740,14.510123,0.473331,-195.182419,0.047403,0.000000
55.910004,64.014168,-195.271378,0.010128,0.001864,0.047333,284.749237,14.505818,0.473331,-195.271378,0.047403,0.000000
56.090004,64.000404,-195.271378,0.010132,0.001864,0.047333,284.688019,14.502699,0.473331,-195.271378,0.047403,0.000000
56.270004,63.992943,-195.315857,0.010106,0.001864,0.047333,284.654816,14.501008,0.473331,-195.315857,0.047403,0.000000
56.450005,63.984764,-195.360336,0.010132,0.001864,0.047333,284.618439,14.499155,0.473331,-195.360336,0.047403,0.000000
56.630001,63.963905,-195.315857,0.010132,0.001864,0.047333,284.525665,14.494429,0.473331,-195.315857,0.047403,0.000000
56.810001,63.947517,-195.360336,0.010119,0.001864,0.047333,284.452759,14.490714,0.473331,-195.360336,0.047403,0.000000
56.990002,63.934486,-195.404816,0.010123,0.001864,0.047333,284.394806,14.487761,0.473331,-195.404816,0.047403,0.000000
57.170002,63.928535,-195.360336,0.010119,0.001864,0.047333,284.368317,14.486414,0.473331,-195.360336,0.047403,0.000000
57.350002,63.920341,-195.449295,0.010128,0.001864,0.047333,284.331879,14.484556,0.473331,-195.449295,0.047403,0.000000
57.530003,63.905449,-195.404816,0.010119,0.001864,0.047333,284.265625,14.481182,0.473331,-195.404816,0.047403,0.000000
57.710003,63.893150,-195.449295,0.010132,0.001864,0.047333,284.210937,14.478395,0.473331,-195.449295,0.047403,0.000000
57.890003,63.870445,-195.582748,0.010119,0.001864,0.047333,284.109924,14.473250,0.473331,-195.582748,0.047403,0.000000
58.070004,63.864479,-195.493774,0.010132,0.001864,0.047333,284.083405,14.471897,0.473331,-195.493774,0.047403,0.000000
58.250004,63.858894,-195.493774,0.010136,0.001864,0.047333,284.058563,14.470632,0.473331,-195.493774,0.047403,0.000000
58.430004,63.846611,-195.582748,0.010115,0.001864,0.047333,284.003906,14.467850,0.473331,-195.582748,0.047403,0.000000
58.610004,63.836174,-195.538254,0.010123,0.001864,0.047333,283.957489,14.465484,0.473331,-195.538254,0.047403,0.000000
58.790001,63.814949,-195.627228,0.010106,0.001864,0.047333,283.863068,14.460674,0.473331,-195.627228,0.047403,0.000000
58.970001,63.818306,-195.582748,0.010111,0.001864,0.047333,283.877991,14.461434,0.473331,-195.582748,0.047403,0.000000
59.150002,63.798195,-195.627228,0.010128,0.001864,0.047333,283.788544,14.456877,0.473331,-195.627228,0.047403,0.000000
59.330002,63.787025,-195.627228,0.010119,0.001864,0.047333,283.738861,14.454346,0.473331,-195.627228,0.047403,0.000000
59.510002,63.782936,-195.716187,0.010115,0.001864,0.047333,283.720673,14.453420,0.473331,-195.716187,0.047403,0.000000
59.690002,63.788139,-195.760666,0.010115,0.001864,0.047333,283.743805,14.454598,0.473331,-195.760666,0.047403,0.000000
59.870003,63.763191,-195.716187,0.010111,0.001864,0.047333,283.632843,14.448945,0.473331,-195.716187,0.047403,0.000000
60.050003,63.754265,-195.760666,0.010102,0.001864,0.047333,283.593140,14.446922,0.473331,-195.760666,0.047403,0.000000
60.230003,63.737495,-195.760666,0.010115,0.001864,0.047333,283.518555,14.443123,0.473331,-195.760666,0.047403,0.000000
60.410004,63.731178,-195.805145,0.010123,0.001864,0.047333,283.490448,14.441691,0.473331,-195.805145,0.047403,0.000000
60.590004,63.721855,-195.805145,0.010128,0.001864,0.047333,283.448975,14.439578,0.473331,-195.805145,0.047403,0.000000
60.770004,63.709206,-195.805145,0.010102,0.001864,0.047333,283.392700,14.436712,0.473331,-195.805145,0.047403,0.000000
60.950005,63.704735,-195.805145,0.010132,0.001864,0.047333,283.372803,14.435699,0.473331,-195.805145,0.047403,0.000000
61.130001,63.690590,-195.894104,0.010132,0.001864,0.047333,283.309906,14.432494,0.473331,-195.894104,0.047403,0.000000
61.310001,63.677925,-195.894104,0.010119,0.001864,0.047333,283.253571,14.429624,0.473331,-195.894104,0.047403,0.000000
61.490002,63.671593,-195.894104,0.010132,0.001864,0.047333,283.225403,14.428189,0.473331,-195.894104,0.047403,0.000000
61.670002,63.661171,-195.894104,0.010119,0.001864,0.047333,283.179047,14.425828,0.473331,-195.894104,0.047403,0.000000
61.850002,63.654839,-195.938583,0.010119,0.001864,0.047333,283.150848,14.424393,0.473331,-195.938583,0.047403,0.000000
62.030003,63.644035,-195.983063,0.010119,0.001864,0.047333,283.102814,14.421945,0.473331,-195.983063,0.047403,0.000000
62.210003,63.635094,-196.027557,0.010115,0.001864,0.047333,283.063019,14.419918,0.473331,-196.027557,0.047403,0.000000
62.390003,63.627647,-196.027557,0.010106,0.001864,0.047333,283.029907,14.418231,0.473331,-196.027557,0.047403,0.000000
62.570004,63.622063,-195.983063,0.010123,0.001864,0.047333,283.005066,14.416965,0.473331,-195.983063,0.047403,0.000000
62.750004,63.615364,-196.072037,0.010123,0.001864,0.047333,282.975281,14.415448,0.473331,-196.072037,0.047403,0.000000
62.930004,63.598610,-196.116516,0.010128,0.001864,0.047333,282.900757,14.411652,0.473331,-196.116516,0.047403,0.000000
63.110004,63.585945,-196.160995,0.010123,0.001864,0.047333,282.844421,14.408782,0.473331,-196.160995,0.047403,0.000000
63.290005,63.592644,-196.160995,0.010119,0.001864,0.047333,282.874207,14.410298,0.473331,-196.160995,0.047403,0.000000
63.470001,63.580360,-196.116516,0.010128,0.001864,0.047333,282.819580,14.407516,0.473331,-196.116516,0.047403,0.000000
63.650002,63.579994,-196.205475,0.010123,0.001864,0.047333,282.817932,14.407433,0.473331,-196.205475,0.047403,0.000000
63.830002,63.564354,-196.205475,0.010128,0.001864,0.047333,282.748383,14.403888,0.473331,-196.205475,0.047403,0.000000
64.010002,63.554298,-196.294434,0.010123,0.001864,0.047333,282.703644,14.401609,0.473331,-196.294434,0.047403,0.000000
64.190002,63.547585,-196.249954,0.010123,0.001864,0.047333,282.673767,14.400088,0.473331,-196.249954,0.047403,0.000000
64.370003,63.550941,-196.249954,0.010123,0.001864,0.047333,282.688721,14.400848,0.473331,-196.249954,0.047403,0.000000
64.550003,63.536049,-196.249954,0.010111,0.001864,0.047333,282.622467,14.397474,0.473331,-196.249954,0.047403,0.000000
64.730003,63.530464,-196.294434,0.010119,0.001864,0.047333,282.597626,14.396209,0.473331,-196.294434,0.047403,0.000000
64.910004,63.525993,-196.294434,0.010115,0.001864,0.047333,282.577728,14.395196,0.473331,-196.294434,0.047403,0.000000
65.090004,63.523018,-196.338913,0.010132,0.001864,0.047333,282.564484,14.394522,0.473331,-196.338913,0.047403,0.000000
65.270004,63.508492,-196.294434,0.010132,0.001864,0.047333,282.499878,14.391231,0.473331,-196.294434,0.047403,0.000000
65.450005,63.505516,-196.427887,0.010132,0.001864,0.047333,282.486633,14.390555,0.473331,-196.427887,0.047403,0.000000
65.630005,63.494713,-196.427887,0.010123,0.001864,0.047333,282.438599,14.388107,0.473331,-196.427887,0.047403,0.000000
65.810005,63.489876,-196.427887,0.010115,0.001864,0.047333,282.417084,14.387012,0.473331,-196.427887,0.047403,0.000000
65.990005,63.480568,-196.383392,0.010132,0.001864,0.047333,282.375671,14.384903,0.473331,-196.383392,0.047403,0.000000
66.170006,63.476845,-196.472366,0.010119,0.001864,0.047333,282.359100,14.384058,0.473331,-196.472366,0.047403,0.000000
66.350006,63.456734,-196.472366,0.010136,0.001864,0.047333,282.269653,14.379502,0.473331,-196.472366,0.047403,0.000000
66.530006,63.466042,-196.516846,0.010123,0.001864,0.047333,282.311066,14.381611,0.473331,-196.516846,0.047403,0.000000
66.710007,63.460457,-196.516846,0.010132,0.001864,0.047333,282.286224,14.380345,0.473331,-196.516846,0.047403,0.000000
66.889999,63.441841,-196.516846,0.010128,0.001864,0.047333,282.203400,14.376126,0.473331,-196.516846,0.047403,0.000000
67.070000,63.441093,-196.561325,0.010136,0.001864,0.047333,282.200073,14.375957,0.473331,-196.561325,0.047403,0.000000
67.250000,63.445564,-196.561325,0.010128,0.001864,0.047333,282.219971,14.376970,0.473331,-196.561325,0.047403,0.000000
67.430000,63.433281,-196.650284,0.010132,0.001864,0.047333,282.165314,14.374187,0.473331,-196.650284,0.047403,0.000000
67.610001,63.426201,-196.650284,0.010115,0.001864,0.047333,282.133820,14.372582,0.473331,-196.650284,0.047403,0.000000
67.790001,63.413536,-196.694763,0.010128,0.001864,0.047333,282.077484,14.369713,0.473331,-196.694763,0.047403,0.000000
67.970001,63.422478,-196.650284,0.010115,0.001864,0.047333,282.117279,14.371738,0.473331,-196.650284,0.047403,0.000000
68.150002,63.410927,-196.828201,0.010132,0.001864,0.047333,282.065887,14.369122,0.473331,-196.828201,0.047403,0.000000
68.330002,63.399391,-196.739243,0.010123,0.001864,0.047333,282.014587,14.366507,0.473331,-196.739243,0.047403,0.000000
68.510002,63.394920,-196.783722,0.010132,0.001864,0.047333,281.994690,14.365495,0.473331,-196.783722,0.047403,0.000000
68.690002,63.384865,-196.739243,0.010136,0.001864,0.047333,281.949951,14.363216,0.473331,-196.739243,0.047403,0.000000
68.870003,63.376305,-196.783722,0.010132,0.001864,0.047333,281.911896,14.361276,0.473331,-196.783722,0.047403,0.000000
69.050003,63.379280,-196.828201,0.010119,0.001864,0.047333,281.925110,14.361951,0.473331,-196.828201,0.047403,0.000000
69.230003,63.372200,-196.872696,0.010128,0.001864,0.047333,281.893616,14.360346,0.473331,-196.872696,0.047403,0.000000
69.410004,63.368111,-196.828201,0.010136,0.001864,0.047333,281.875427,14.359420,0.473331,-196.828201,0.047403,0.000000
69.590004,63.359169,-196.872696,0.010119,0.001864,0.047333,281.835663,14.357393,0.473331,-196.872696,0.047403,0.000000
69.770004,63.353966,-196.872696,0.010136,0.001864,0.047333,281.812500,14.356214,0.473331,-196.872696,0.047403,0.000000
69.950005,63.351723,-196.961655,0.010119,0.001864,0.047333,281.802551,14.355705,0.473331,-196.961655,0.047403,0.000000
70.130005,63.344276,-197.006134,0.010106,0.001864,0.047333,281.769409,14.354018,0.473331,-197.006134,0.047403,0.000000
70.310005,63.334602,-196.961655,0.010128,0.001864,0.047333,281.726379,14.351826,0.473331,-196.961655,0.047403,0.000000
70.490005,63.335716,-197.006134,0.010128,0.001864,0.047333,281.731323,14.352078,0.473331,-197.006134,0.047403,0.000000
70.670006,63.332726,-197.006134,0.010132,0.001864,0.047333,281.718048,14.351400,0.473331,-197.006134,0.047403,0.000000
70.850006,63.318581,-197.050613,0.010119,0.001864,0.047333,281.655121,14.348196,0.473331,-197.050613,0.047403,0.000000
71.030006,63.323799,-197.095093,0.010115,0.001864,0.047333,281.678314,14.349378,0.473331,-197.095093,0.047403,0.000000
71.210007,63.314857,-197.095093,0.010119,0.001864,0.047333,281.638550,14.347352,0.473331,-197.095093,0.047403,0.000000
71.390007,63.317467,-197.139572,0.010115,0.001864,0.047333,281.650146,14.347943,0.473331,-197.139572,0.047403,0.000000
71.570000,63.298470,-197.095093,0.010123,0.001864,0.047333,281.565643,14.343638,0.473331,-197.095093,0.047403,0.000000
71.750000,63.291771,-197.228531,0.010128,0.001864,0.047333,281.535858,14.342120,0.473331,-197.228531,0.047403,0.000000
71.930000,63.289543,-197.139572,0.010119,0.001864,0.047333,281.525940,14.341616,0.473331,-197.139572,0.047403,0.000000
72.110001,63.296242,-197.228531,0.010115,0.001864,0.047333,281.555756,14.343134,0.473331,-197.228531,0.047403,0.000000
72.290001,63.278374,-197.228531,0.010132,0.001864,0.047333,281.476257,14.339085,0.473331,-197.228531,0.047403,0.000000
72.470001,63.280235,-197.184052,0.010123,0.001864,0.047333,281.484558,14.339506,0.473331,-197.184052,0.047403,0.000000
72.650002,63.266457,-197.317505,0.010128,0.001864,0.047333,281.423248,14.336384,0.473331,-197.317505,0.047403,0.000000
72.830002,63.267570,-197.317505,0.010115,0.001864,0.047333,281.428223,14.336637,0.473331,-197.317505,0.047403,0.000000
73.010002,63.260872,-197.317505,0.010111,0.001864,0.047333,281.398407,14.335118,0.473331,-197.317505,0.047403,0.000000
73.190002,63.259377,-197.317505,0.010132,0.001864,0.047333,281.391754,14.334780,0.473331,-197.317505,0.047403,0.000000
73.370003,63.254158,-197.361984,0.010128,0.001864,0.047333,281.368561,14.333597,0.473331,-197.361984,0.047403,0.000000
73.550003,63.256767,-197.361984,0.010111,0.001864,0.047333,281.380157,14.334188,0.473331,-197.361984,0.047403,0.000000
73.730003,63.241875,-197.406464,0.010128,0.001864,0.047333,281.313904,14.330813,0.473331,-197.406464,0.047403,0.000000
73.910004,63.242989,-197.406464,0.010128,0.001864,0.047333,281.318878,14.331066,0.473331,-197.406464,0.047403,0.000000
74.090004,63.243736,-197.450943,0.010119,0.001864,0.047333,281.322174,14.331236,0.473331,-197.450943,0.047403,0.000000
74.100006,63.242622,-197.450943,0.010128,0.001864,0.047333,281.317230,14.330983,0.473331,-197.450943,0.047403,0.000000