File: Data/AG AL compression 300N/AL membrane Peeled 300N_1_2_03192024_181012.csv
Time (sec),S:Load (lbs),S:HL1 (DIM),S:LVDT (in),S:Position (in),Ch:Position (mm),Ch:Load (N),Ch:Stress (MPa),Ch:Strain (mm/mm),Ch:HL1 (DIM),Set Point (),Cycles ()
0.010000,0.011543,-167.871109,0.000000,-0.000000,-0.000000,0.051347,0.002616,-0.000000,-167.871109,-0.000173,0.000000
0.170000,0.010796,-167.782150,0.000000,-0.000000,-0.000000,0.048021,0.002446,-0.000000,-167.782150,-0.000173,0.000000
0.330000,0.000740,-167.826630,-0.000004,-0.000000,-0.000000,0.003292,0.000168,-0.000000,-167.826630,-0.000087,0.000000
0.490000,-0.007454,-167.915588,-0.000013,0.000068,0.001717,-0.033157,-0.001689,0.017172,-167.915588,0.002584,0.000000
0.650000,0.007446,-167.915588,0.000022,0.000173,0.004397,0.033123,0.001687,0.043969,-167.915588,0.005255,0.000000
0.810000,-0.056229,-167.960068,0.000086,0.000269,0.006825,-0.250117,-0.012742,0.068249,-167.960068,0.007909,0.000000
0.970000,-0.023834,-167.960068,0.000177,0.000374,0.009496,-0.106020,-0.005401,0.094963,-167.960068,0.010580,0.000000
1.130000,-0.024208,-167.960068,0.000289,0.000472,0.011994,-0.107683,-0.005486,0.119936,-167.960068,0.013251,0.000000
1.290000,0.001114,-168.138000,0.000392,0.000576,0.014639,0.004955,0.000252,0.146388,-168.138000,0.015905,0.000000
1.450000,0.009682,-168.004547,0.000492,0.000688,0.017483,0.043066,0.002194,0.174832,-168.004547,0.018576,0.000000
1.610000,-0.017136,-168.093521,0.000599,0.000792,0.020111,-0.076223,-0.003883,0.201110,-168.093521,0.021247,0.000000
1.770000,-0.022720,-168.049026,0.000711,0.000898,0.022817,-0.101065,-0.005149,0.228169,-168.049026,0.023901,0.000000
1.930000,0.020103,-168.093521,0.000815,0.001008,0.025609,0.089425,0.004556,0.256094,-168.093521,0.026572,0.000000
2.090000,0.026062,-168.226959,0.000905,0.001114,0.028297,0.115930,0.005906,0.282974,-168.226959,0.029243,0.000000
2.250000,0.021591,-168.138000,0.001022,0.001213,0.030804,0.096042,0.004893,0.308037,-168.138000,0.031914,0.000000
2.410000,0.028671,-168.226959,0.001125,0.001321,0.033544,0.127536,0.006497,0.335444,-168.226959,0.034567,0.000000
2.570000,0.018242,-168.271439,0.001220,0.001420,0.036076,0.081144,0.004134,0.360765,-168.271439,0.037239,0.000000
2.730000,0.116547,-168.226959,0.001332,0.001532,0.038904,0.518425,0.026410,0.389038,-168.226959,0.039910,0.000000
2.890000,0.449448,-168.271439,0.001436,0.001632,0.041453,1.999243,0.101846,0.414533,-168.271439,0.042563,0.000000
3.050000,0.638618,-168.315918,0.001535,0.001729,0.043908,2.840717,0.144713,0.439078,-168.315918,0.045234,0.000000
3.210000,0.639359,-168.271439,0.001569,-0.000003,-0.000069,2.844009,0.144881,-0.000693,-168.271439,0.000052,0.000000
3.370000,0.613670,-168.360397,0.001565,-0.000003,-0.000069,2.729742,0.139060,-0.000693,-168.360397,0.000052,0.000000
3.530000,0.596169,-168.360397,0.001578,-0.000003,-0.000078,2.651890,0.135094,-0.000780,-168.360397,0.000052,0.000000
3.690000,0.572334,-168.404877,0.001569,-0.000003,-0.000078,2.545870,0.129693,-0.000780,-168.404877,0.000148,0.000000
3.850000,0.568611,-168.360397,0.001552,-0.000003,-0.000078,2.529309,0.128849,-0.000780,-168.360397,0.000416,0.000000
4.010000,0.566750,-168.404877,0.001569,-0.000003,-0.000069,2.521028,0.128427,-0.000693,-168.404877,0.000677,0.000000
4.170000,0.573822,-168.404877,0.001556,-0.000002,-0.000061,2.552488,0.130030,-0.000606,-168.404877,0.000945,0.000000
4.330000,0.627815,-168.404877,0.001565,0.000009,0.000226,2.792662,0.142265,0.002256,-168.404877,0.001214,0.000000
4.490000,0.721283,-168.538330,0.001574,0.000026,0.000651,3.208427,0.163445,0.006506,-168.538330,0.001483,0.000000
4.650000,0.710854,-168.449356,0.001582,0.000032,0.000807,3.162035,0.161082,0.008066,-168.449356,0.001743,0.000000
4.810000,0.709366,-168.538330,0.001595,0.000039,0.000989,3.155417,0.160745,0.009890,-168.538330,0.002012,0.000000
4.970000,0.769691,-168.538330,0.001604,0.000052,0.001310,3.423759,0.174415,0.013096,-168.538330,0.002281,0.000000
5.130000,0.774529,-168.538330,0.001604,0.000053,0.001344,3.445275,0.175511,0.013444,-168.538330,0.002550,0.000000
5.290000,0.923477,-168.627289,0.001630,0.000075,0.001917,4.107831,0.209263,0.019167,-168.627289,0.002810,0.000000
5.450000,0.892204,-168.627289,0.001625,0.000082,0.002082,3.968723,0.202176,0.020817,-168.627289,0.003079,0.000000
5.610000,0.930931,-168.760727,0.001647,0.000090,0.002289,4.140988,0.210952,0.022895,-168.760727,0.003348,0.000000
5.770000,0.988274,-168.627289,0.001660,0.000098,0.002498,4.396060,0.223946,0.024977,-168.627289,0.003616,0.000000
5.930000,1.003540,-168.671768,0.001660,0.000107,0.002723,4.463969,0.227405,0.027232,-168.671768,0.003876,0.000000
6.090000,1.084343,-168.671768,0.001669,0.000127,0.003218,4.823399,0.245716,0.032175,-168.671768,0.004146,0.000000
6.250000,1.119720,-168.716248,0.001686,0.000138,0.003512,4.980765,0.253732,0.035124,-168.716248,0.004414,0.000000
6.410000,1.149887,-168.760727,0.001699,0.000153,0.003885,5.114953,0.260568,0.038852,-168.760727,0.004683,0.000000
6.570000,1.161797,-168.760727,0.001699,0.000160,0.004076,5.167929,0.263267,0.040760,-168.760727,0.004943,0.000000
6.730000,1.175575,-168.805206,0.001712,0.000165,0.004197,5.229220,0.266389,0.041974,-168.805206,0.005212,0.000000
6.890000,1.308884,-168.849686,0.001720,0.000180,0.004571,5.822206,0.296597,0.045706,-168.849686,0.005481,0.000000
7.050000,1.278351,-168.805206,0.001755,0.000186,0.004735,5.686388,0.289678,0.047353,-168.805206,0.005750,0.000000
7.210001,1.461929,-168.894165,0.001755,0.000200,0.005091,6.502986,0.331278,0.050907,-168.894165,0.006010,0.000000
7.370000,1.447784,-168.894165,0.001746,0.000205,0.005212,6.440067,0.328073,0.052122,-168.894165,0.006279,0.000000
7.530000,1.537895,-168.894165,0.001776,0.000217,0.005507,6.840899,0.348492,0.055070,-168.894165,0.006548,0.000000
7.690001,1.593376,-168.938660,0.001772,0.000225,0.005715,7.087691,0.361064,0.057152,-168.938660,0.006817,0.000000
7.850000,1.659286,-168.938660,0.001785,0.000236,0.005993,7.380875,0.376000,0.059926,-168.938660,0.007085,0.000000
8.010000,1.811592,-169.027618,0.001802,0.000258,0.006557,8.058364,0.410513,0.065566,-169.027618,0.007346,0.000000
8.170000,1.850319,-168.938660,0.001807,0.000266,0.006764,8.230630,0.419288,0.067644,-168.938660,0.007614,0.000000
8.330000,1.965378,-169.027618,0.001832,0.000281,0.007129,8.742437,0.445361,0.071288,-169.027618,0.007883,0.000000
8.490001,1.998894,-169.027618,0.001832,0.000289,0.007328,8.891523,0.452956,0.073283,-169.027618,0.008152,0.000000
8.650001,2.046181,-168.983139,0.001837,0.000298,0.007562,9.101867,0.463671,0.075622,-168.983139,0.008412,0.000000
8.810000,2.065918,-169.072098,0.001837,0.000302,0.007675,9.189662,0.468144,0.076750,-169.072098,0.008681,0.000000
8.970000,2.285995,-169.072098,0.001850,0.000314,0.007979,10.168615,0.518014,0.079786,-169.072098,0.008950,0.000000
9.130000,2.464355,-169.116577,0.001876,0.000328,0.008326,10.962001,0.558431,0.083256,-169.116577,0.009219,0.000000
9.290001,2.476646,-169.205536,0.001876,0.000334,0.008490,11.016673,0.561216,0.084903,-169.205536,0.009479,0.000000
9.450001,2.681450,-169.161057,0.001884,0.000347,0.008811,11.927685,0.607625,0.088112,-169.161057,0.009748,0.000000
9.610001,2.706398,-169.116577,0.001880,0.000354,0.009002,12.038660,0.613279,0.090020,-169.116577,0.010017,0.000000
9.770000,2.775291,-169.205536,0.001897,0.000363,0.009219,12.345113,0.628890,0.092189,-169.205536,0.010285,0.000000
9.930000,3.082497,-169.250015,0.001914,0.000380,0.009661,13.711630,0.698504,0.096609,-169.250015,0.010545,0.000000
10.090000,3.155479,-169.294495,0.001932,0.000391,0.009939,14.036274,0.715042,0.099388,-169.294495,0.010815,0.000000
10.250001,3.316345,-169.250015,0.001932,0.000401,0.010190,14.751841,0.751495,0.101901,-169.250015,0.011083,0.000000
10.410001,3.447792,-169.294495,0.001936,0.000413,0.010494,15.336545,0.781281,0.104936,-169.294495,0.011352,0.000000
10.570001,3.533066,-169.294495,0.001962,0.000420,0.010667,15.715861,0.800604,0.106670,-169.294495,0.011612,0.000000
10.730000,3.636963,-169.338974,0.001957,0.000428,0.010875,16.178019,0.824148,0.108751,-169.338974,0.011881,0.000000
10.890000,3.914375,-169.338974,0.001975,0.000441,0.011205,17.412010,0.887010,0.112048,-169.338974,0.012150,0.000000
11.050000,4.158653,-169.383469,0.001983,0.000456,0.011586,18.498613,0.942364,0.115863,-169.383469,0.012419,0.000000
11.210001,4.247276,-169.472427,0.001992,0.000464,0.011786,18.892828,0.962447,0.117858,-169.472427,0.012679,0.000000
11.370001,4.393990,-169.427948,0.001996,0.000473,0.012020,19.545443,0.995692,0.120201,-169.427948,0.012948,0.000000
11.530001,4.471077,-169.472427,0.002018,0.000480,0.012185,19.888344,1.013161,0.121847,-169.472427,0.013217,0.000000
11.690001,4.835999,-169.427948,0.002026,0.000494,0.012540,21.511597,1.095853,0.125401,-169.427948,0.013486,0.000000
11.850000,5.065010,-169.516907,0.002022,0.000507,0.012887,22.530291,1.147748,0.128872,-169.516907,0.013746,0.000000
12.010000,5.135384,-169.561386,0.002048,0.000516,0.013095,22.843327,1.163695,0.130954,-169.561386,0.014015,0.000000
12.170001,5.442596,-169.516907,0.002039,0.000529,0.013425,24.209879,1.233310,0.134250,-169.516907,0.014283,0.000000
12.330001,5.580742,-169.605865,0.002052,0.000539,0.013694,24.824379,1.264614,0.136937,-169.605865,0.014552,0.000000
12.490001,5.691711,-169.605865,0.002061,0.000547,0.013885,25.317997,1.289760,0.138845,-169.605865,0.014813,0.000000
12.650001,5.923698,-169.605865,0.002065,0.000558,0.014171,26.349926,1.342329,0.141706,-169.605865,0.015081,0.000000
12.810000,6.174675,-169.694824,0.002087,0.000570,0.014474,27.466326,1.399201,0.144742,-169.694824,0.015350,0.000000
12.970000,6.376503,-169.694824,0.002087,0.000580,0.014734,28.364101,1.444936,0.147342,-169.694824,0.015619,0.000000
13.130001,6.612961,-169.739304,0.002108,0.000588,0.014942,29.415918,1.498518,0.149424,-169.739304,0.015879,0.000000
13.290001,6.929848,-169.694824,0.002100,0.000600,0.015246,30.825502,1.570326,0.152459,-169.694824,0.016148,0.000000
13.450001,6.783882,-169.694824,0.002130,0.000600,0.015246,30.176214,1.537250,0.152459,-169.694824,0.016417,0.000000
13.610001,7.612038,-169.739304,0.002126,0.000627,0.015914,33.860035,1.724912,0.159136,-169.739304,0.016686,0.000000
13.770000,7.566605,-169.783783,0.002147,0.000632,0.016044,33.657940,1.714617,0.160438,-169.783783,0.016946,0.000000
13.930000,7.810883,-169.828278,0.002147,0.000645,0.016373,34.744541,1.769971,0.163735,-169.828278,0.017214,0.000000
14.090001,8.148994,-169.783783,0.002156,0.000656,0.016668,36.248539,1.846589,0.166683,-169.783783,0.017484,0.000000
14.250001,8.227936,-169.828278,0.002169,0.000665,0.016894,36.599686,1.864477,0.168939,-169.828278,0.017752,0.000000
14.410001,8.375771,-169.872757,0.002186,0.000673,0.017093,37.257290,1.897977,0.170933,-169.872757,0.018012,0.000000
14.570001,8.861343,-169.872757,0.002182,0.000685,0.017405,39.417225,2.008009,0.174052,-169.872757,0.018281,0.000000
14.730000,9.118279,-169.961716,0.002195,0.000698,0.017726,40.560127,2.066231,0.177262,-169.961716,0.018550,0.000000
14.890000,9.490280,-169.917236,0.002186,0.000710,0.018038,42.214874,2.150528,0.180384,-169.917236,0.018819,0.000000
15.050001,9.671631,-169.961716,0.002216,0.000720,0.018298,43.021564,2.191623,0.182985,-169.961716,0.019079,0.000000
15.210001,9.803818,-169.961716,0.002216,0.000727,0.018472,43.609558,2.221577,0.184722,-169.961716,0.019348,0.000000
15.370001,10.071930,-169.961716,0.002225,0.000737,0.018732,44.802181,2.282332,0.187322,-169.961716,0.019617,0.000000
15.530001,10.591385,-170.095154,0.002233,0.000753,0.019131,47.112831,2.400042,0.191311,-170.095154,0.019886,0.000000
15.690001,10.734375,-170.095154,0.002233,0.000763,0.019374,47.748886,2.432444,0.193741,-170.095154,0.020146,0.000000
15.850000,11.003601,-170.139633,0.002255,0.000773,0.019634,48.946461,2.493452,0.196341,-170.139633,0.020415,0.000000
16.010000,11.155907,-170.139633,0.002264,0.000782,0.019860,49.623951,2.527965,0.198597,-170.139633,0.020684,0.000000
16.170000,11.400551,-170.139633,0.002259,0.000792,0.020120,50.712181,2.583402,0.201197,-170.139633,0.020952,0.000000
16.330000,11.700310,-170.184113,0.002264,0.000801,0.020337,52.045578,2.651328,0.203366,-170.184113,0.021212,0.000000
16.490002,11.850380,-170.184113,0.002281,0.000809,0.020536,52.713123,2.685334,0.205361,-170.184113,0.021481,0.000000
16.650002,12.242111,-170.139633,0.002298,0.000820,0.020822,54.455631,2.774102,0.208222,-170.139633,0.021750,0.000000
16.810001,12.427559,-170.184113,0.002289,0.000829,0.021065,55.280544,2.816125,0.210652,-170.184113,0.022019,0.000000
16.970001,12.830093,-170.184113,0.002320,0.000844,0.021438,57.071106,2.907341,0.214380,-170.184113,0.022279,0.000000
17.130001,13.158524,-170.273087,0.002311,0.000854,0.021689,58.532036,2.981764,0.216893,-170.273087,0.022548,0.000000
17.290001,12.990211,-170.228607,0.002315,0.000858,0.021785,57.783348,2.943624,0.217847,-170.228607,0.022817,0.000000
17.450001,13.875710,-170.362045,0.002354,0.000877,0.022288,61.722240,3.144281,0.222877,-170.362045,0.023086,0.000000
17.610001,14.122223,-170.317566,0.002350,0.000890,0.022609,62.818787,3.200141,0.226087,-170.317566,0.023346,0.000000
17.770000,14.395920,-170.317566,0.002367,0.000901,0.022886,64.036247,3.262162,0.228861,-170.317566,0.023615,0.000000
17.930000,14.541885,-170.362045,0.002363,0.000909,0.023094,64.685539,3.295238,0.230943,-170.362045,0.023883,0.000000
18.090000,14.716904,-170.362045,0.002371,0.000917,0.023302,65.464058,3.334898,0.233025,-170.362045,0.024153,0.000000
18.250000,14.950378,-170.406525,0.002389,0.000926,0.023528,66.502602,3.387804,0.235280,-170.406525,0.024413,0.000000
18.410002,15.203217,-170.451004,0.002389,0.000935,0.023745,67.627281,3.445098,0.237449,-170.451004,0.024681,0.000000
18.570002,15.685814,-170.406525,0.002389,0.000947,0.024066,69.773987,3.554456,0.240659,-170.406525,0.024950,0.000000
18.730001,16.089470,-170.495483,0.002406,0.000960,0.024386,71.569534,3.645926,0.243865,-170.495483,0.025219,0.000000
18.890001,16.378052,-170.451004,0.002406,0.000970,0.024647,72.853210,3.711320,0.246469,-170.451004,0.025479,0.000000
19.050001,16.558281,-170.539963,0.002423,0.000978,0.024846,73.654915,3.752160,0.248463,-170.539963,0.025748,0.000000
19.210001,16.487534,-170.495483,0.002419,0.000982,0.024950,73.340210,3.736129,0.249504,-170.495483,0.026017,0.000000
19.370001,16.915390,-170.539963,0.002432,0.000998,0.025341,75.243416,3.833082,0.253406,-170.539963,0.026286,0.000000
19.530001,17.576347,-170.628922,0.002440,0.001010,0.025653,78.183495,3.982857,0.256529,-170.628922,0.026546,0.000000
19.690001,17.886536,-170.584442,0.002440,0.001023,0.025973,79.563286,4.053147,0.259735,-170.584442,0.026815,0.000000
19.850000,18.266731,-170.628922,0.002466,0.001034,0.026251,81.254478,4.139300,0.262513,-170.628922,0.027084,0.000000
20.010000,18.479355,-170.628922,0.002453,0.001045,0.026537,82.200279,4.187482,0.265374,-170.628922,0.027352,0.000000
20.170000,18.719162,-170.628922,0.002488,0.001053,0.026746,83.266991,4.241823,0.267456,-170.628922,0.027613,0.000000
20.330002,18.877045,-170.762375,0.002483,0.001060,0.026928,83.969292,4.277600,0.269276,-170.762375,0.027881,0.000000
20.490002,19.178299,-170.673416,0.002483,0.001071,0.027205,85.309334,4.345865,0.272051,-170.673416,0.028150,0.000000
20.650002,19.629242,-170.806854,0.002509,0.001080,0.027439,87.315231,4.448050,0.274394,-170.806854,0.028419,0.000000
20.810001,20.146461,-170.806854,0.002505,0.001094,0.027777,89.615936,4.565253,0.277773,-170.806854,0.028679,0.000000
20.970001,20.350899,-170.717896,0.002505,0.001101,0.027977,90.525322,4.611579,0.279768,-170.717896,0.028948,0.000000
21.130001,20.452179,-170.762375,0.002518,0.001107,0.028116,90.975838,4.634530,0.281157,-170.762375,0.029217,0.000000
21.290001,20.750824,-170.717896,0.002514,0.001117,0.028376,92.304276,4.702204,0.283757,-170.717896,0.029486,0.000000
21.450001,21.798683,-170.806854,0.002544,0.001137,0.028870,96.965385,4.939652,0.288700,-170.806854,0.029746,0.000000
21.610001,22.094345,-170.851334,0.002535,0.001148,0.029156,98.280556,5.006650,0.291562,-170.851334,0.030015,0.000000
21.770000,22.376228,-170.895813,0.002548,0.001158,0.029425,99.534431,5.070526,0.294253,-170.895813,0.030284,0.000000
21.930000,22.784348,-170.940292,0.002565,0.001171,0.029737,101.349838,5.163007,0.297372,-170.940292,0.030552,0.000000
22.090000,23.088577,-170.895813,0.002561,0.001180,0.029980,102.703117,5.231946,0.299802,-170.895813,0.030813,0.000000
22.250002,23.166779,-170.984772,0.002570,0.001186,0.030119,103.050980,5.249667,0.301191,-170.984772,0.031082,0.000000
22.410002,23.479568,-170.940292,0.002578,0.001196,0.030379,104.442337,5.320546,0.303791,-170.940292,0.031350,0.000000
22.570002,23.711189,-171.029251,0.002587,0.001202,0.030535,105.472641,5.373032,0.305350,-171.029251,0.031619,0.000000
22.730001,24.755692,-171.029251,0.002604,0.001220,0.030995,110.118813,5.609720,0.309949,-171.029251,0.031879,0.000000
22.890001,24.583656,-171.029251,0.002613,0.001223,0.031073,109.353561,5.570736,0.310729,-171.029251,0.032148,0.000000
23.050001,24.902031,-171.073730,0.002613,0.001232,0.031290,110.769768,5.642881,0.312897,-171.073730,0.032417,0.000000
23.210001,25.622200,-171.073730,0.002608,0.001246,0.031654,113.973236,5.806073,0.316538,-171.073730,0.032686,0.000000
23.370001,26.010216,-171.118225,0.002621,0.001256,0.031906,115.699219,5.893999,0.319055,-171.118225,0.032946,0.000000
23.530001,27.032005,-171.118225,0.002639,0.001273,0.032322,120.244362,6.125540,0.323219,-171.118225,0.033215,0.000000
23.690001,27.204041,-171.073730,0.002634,0.001280,0.032504,121.009613,6.164524,0.325039,-171.073730,0.033484,0.000000
23.850000,27.638229,-171.162704,0.002652,0.001292,0.032825,122.940987,6.262912,0.328245,-171.162704,0.033753,0.000000
24.010000,28.043739,-171.207184,0.002647,0.001302,0.033067,124.744781,6.354802,0.330675,-171.207184,0.034013,0.000000
24.170002,28.239235,-171.207184,0.002669,0.001310,0.033276,125.614388,6.399102,0.332757,-171.207184,0.034282,0.000000
24.330002,28.541977,-171.296143,0.002665,0.001317,0.033440,126.961052,6.467704,0.334403,-171.296143,0.034550,0.000000
24.490002,29.117661,-171.296143,0.002677,0.001330,0.033787,129.521820,6.598156,0.337874,-171.296143,0.034819,0.000000
24.650002,30.145782,-171.340622,0.002682,0.001346,0.034178,134.095139,6.831132,0.341776,-171.340622,0.035080,0.000000
24.810001,30.287285,-171.296143,0.002686,0.001352,0.034342,134.724579,6.863197,0.343422,-171.296143,0.035348,0.000000
24.970001,30.675293,-171.340622,0.002682,0.001362,0.034594,136.450516,6.951121,0.345939,-171.340622,0.035617,0.000000
25.130001,30.962395,-171.385101,0.002708,0.001370,0.034793,137.727615,7.016179,0.347934,-171.385101,0.035886,0.000000
25.290001,31.456909,-171.340622,0.002716,0.001380,0.035053,139.927322,7.128237,0.350534,-171.340622,0.036146,0.000000
25.450001,32.386719,-171.429581,0.002699,0.001395,0.035435,144.063324,7.338935,0.354349,-171.429581,0.036415,0.000000
25.610001,32.911392,-171.429581,0.002725,0.001405,0.035678,146.397186,7.457829,0.356779,-171.429581,0.036684,0.000000
25.770000,33.322861,-171.429581,0.002721,0.001415,0.035929,148.227493,7.551068,0.359293,-171.429581,0.036953,0.000000
25.930000,34.044151,-171.518555,0.002721,0.001428,0.036268,151.435944,7.714515,0.362676,-171.518555,0.037213,0.000000
26.090002,34.282471,-171.474060,0.002746,0.001434,0.036432,152.496048,7.768519,0.364323,-171.474060,0.037482,0.000000
26.250002,34.740860,-171.518555,0.002746,0.001445,0.036701,154.535065,7.872391,0.367010,-171.518555,0.037751,0.000000
26.410002,35.090141,-171.518555,0.002742,0.001452,0.036875,156.088745,7.951540,0.368747,-171.518555,0.038019,0.000000
26.570002,36.119751,-171.563034,0.002751,0.001468,0.037282,160.668671,8.184853,0.372824,-171.563034,0.038280,0.000000
26.730001,36.810501,-171.607513,0.002764,0.001478,0.037551,163.741287,8.341379,0.375511,-171.607513,0.038548,0.000000
26.890001,36.990364,-171.563034,0.002768,0.001486,0.037742,164.541351,8.382136,0.377418,-171.563034,0.038817,0.000000
27.050001,37.105049,-171.607513,0.002764,0.001490,0.037837,165.051498,8.408124,0.378372,-171.607513,0.039086,0.000000
27.210001,37.944748,-171.651993,0.002772,0.001503,0.038167,168.786667,8.598402,0.381669,-171.651993,0.039346,0.000000
27.370001,39.098358,-171.696472,0.002781,0.001521,0.038644,173.918182,8.859815,0.386438,-171.696472,0.039615,0.000000
27.530001,40.026688,-171.740952,0.002781,0.001535,0.038990,178.047592,9.070177,0.389905,-171.740952,0.039884,0.000000
27.690001,40.841812,-171.651993,0.002790,0.001547,0.039303,181.673447,9.254887,0.393027,-171.651993,0.040153,0.000000
27.850000,41.184395,-171.740952,0.002807,0.001556,0.039520,183.197342,9.332518,0.395196,-171.740952,0.040413,0.000000
28.010002,41.488617,-171.740952,0.002807,0.001562,0.039684,184.550583,9.401455,0.396842,-171.740952,0.040682,0.000000
28.170002,41.924294,-171.696472,0.002802,0.001573,0.039953,186.488571,9.500181,0.399534,-171.696472,0.040951,0.000000
28.330002,42.512642,-171.785431,0.002807,0.001581,0.040153,189.105682,9.633502,0.401528,-171.785431,0.041219,0.000000
28.490002,43.072693,-171.829910,0.002815,0.001593,0.040456,191.596909,9.760412,0.404564,-171.829910,0.041479,0.000000
28.650002,43.931381,-171.918869,0.002828,0.001603,0.040716,195.416550,9.954993,0.407164,-171.918869,0.041749,0.000000
28.810001,44.521225,-171.829910,0.002807,0.001612,0.040942,198.040298,10.088654,0.409420,-171.829910,0.042017,0.000000
28.970001,44.859711,-171.918869,0.002837,0.001617,0.041080,199.545959,10.165356,0.410805,-171.918869,0.042286,0.000000
29.130001,45.669991,-171.963364,0.002837,0.001629,0.041367,203.150269,10.348969,0.413670,-171.963364,0.042546,0.000000
29.290001,47.586220,-171.918869,0.002841,0.001654,0.042009,211.674072,10.783192,0.420085,-171.918869,0.042815,0.000000
29.450001,48.129509,-171.963364,0.002850,0.001661,0.042199,214.090744,10.906302,0.421993,-171.963364,0.043084,0.000000
29.610001,48.747276,-171.963364,0.002850,0.001673,0.042494,216.838715,11.046291,0.424942,-171.963364,0.043353,0.000000
29.770002,49.461861,-172.007843,0.002859,0.001684,0.042772,220.017349,11.208218,0.427716,-172.007843,0.043613,0.000000
29.930002,49.983925,-172.052322,0.002863,0.001691,0.042945,222.339600,11.326519,0.429453,-172.052322,0.043882,0.000000
30.090002,50.207718,-172.007843,0.002880,0.001697,0.043093,223.335083,11.377232,0.430925,-172.007843,0.044151,0.000000
30.250002,51.027687,-172.096802,0.002867,0.001709,0.043414,226.982483,11.563039,0.434135,-172.096802,0.044420,0.000000
30.410002,52.091553,-172.052322,0.002859,0.001723,0.043752,231.714798,11.804114,0.437519,-172.052322,0.044680,0.000000
30.570002,52.721237,-172.096802,0.002880,0.001729,0.043925,234.515778,11.946803,0.439252,-172.096802,0.044949,0.000000
30.730001,53.499496,-172.096802,0.002889,0.001742,0.044246,237.977646,12.123159,0.442462,-172.096802,0.045217,0.000000
30.890001,53.945969,-172.096802,0.002889,0.001747,0.044376,239.963654,12.224331,0.443760,-172.096802,0.045486,0.000000
31.050001,54.534691,-172.230240,0.002871,0.001756,0.044610,242.582428,12.357738,0.446103,-172.230240,0.045747,0.000000
31.210001,55.828682,-172.185760,0.002889,0.001775,0.045078,248.338379,12.650960,0.450785,-172.185760,0.046015,0.000000
31.370001,56.725357,-172.230240,0.002893,0.001784,0.045321,252.326996,12.854150,0.453215,-172.230240,0.046284,0.000000
31.530001,57.621658,-172.230240,0.002902,0.001795,0.045599,256.313934,13.057255,0.455989,-172.230240,0.046553,0.000000
31.690002,58.414810,-172.230240,0.002906,0.001807,0.045902,259.842041,13.236985,0.459024,-172.230240,0.046813,0.000000
31.850002,59.046356,-172.319199,0.002919,0.001814,0.046067,262.651306,13.380095,0.460671,-172.319199,0.047082,0.000000
32.010002,59.864082,-172.363678,0.002906,0.001825,0.046353,266.288727,13.565395,0.463532,-172.363678,0.047351,0.000000
32.170002,60.668777,-172.319199,0.002923,0.001838,0.046683,269.868195,13.747742,0.466829,-172.319199,0.047620,0.000000
32.330002,61.789993,-172.319199,0.002915,0.001851,0.047004,274.855621,14.001813,0.470039,-172.319199,0.047880,0.000000
32.490002,62.442390,-172.319199,0.002936,0.001857,0.047168,277.757629,14.149649,0.471685,-172.319199,0.048148,0.000000
32.650002,62.901527,-172.408173,0.002919,0.001864,0.047351,279.799957,14.253690,0.473505,-172.408173,0.048418,0.000000
32.810001,63.670479,-172.408173,0.002940,0.001873,0.047576,283.220428,14.427937,0.475761,-172.408173,0.048686,0.000000
32.970001,64.558586,-172.452652,0.002936,0.001888,0.047966,287.170929,14.629185,0.479664,-172.452652,0.048946,0.000000
33.130001,65.530846,-172.497131,0.002928,0.001899,0.048227,291.495758,14.849503,0.482268,-172.497131,0.049215,0.000000
33.290001,66.726158,-172.452652,0.002953,0.001910,0.048504,296.812775,15.120364,0.485042,-172.452652,0.049484,0.000000
33.450001,67.260887,-172.497131,0.002949,0.001921,0.048782,299.191376,15.241535,0.487816,-172.497131,0.049753,0.000000
33.610001,67.349892,-172.497131,0.002958,0.001913,0.048582,299.587280,15.261703,0.485822,-172.497131,0.048808,0.000000
33.770000,67.086998,-172.586090,0.002949,0.001913,0.048582,298.417877,15.202131,0.485822,-172.586090,0.048808,0.000000
33.930000,66.879204,-172.586090,0.002949,0.001912,0.048556,297.493561,15.155045,0.485560,-172.586090,0.048582,0.000000
34.090000,66.700462,-172.541611,0.002953,0.001911,0.048547,296.698486,15.114541,0.485473,-172.541611,0.048582,0.000000
34.250000,66.534767,-172.586090,0.002962,0.001911,0.048539,295.961426,15.076994,0.485386,-172.586090,0.048582,0.000000
34.410000,66.379112,-172.675049,0.002953,0.001911,0.048530,295.269043,15.041722,0.485303,-172.675049,0.048582,0.000000
34.570004,66.254738,-172.675049,0.002958,0.001911,0.048530,294.715790,15.013538,0.485303,-172.675049,0.048582,0.000000
34.730003,66.147499,-172.675049,0.002953,0.001910,0.048522,294.238770,14.989238,0.485216,-172.675049,0.048582,0.000000
34.890003,66.033180,-172.675049,0.002975,0.001910,0.048522,293.730255,14.963333,0.485216,-172.675049,0.048582,0.000000
35.050003,65.936363,-172.719528,0.002975,0.001910,0.048522,293.299591,14.941394,0.485216,-172.719528,0.048582,0.000000
35.210003,65.864128,-172.719528,0.002958,0.001910,0.048522,292.978271,14.925024,0.485216,-172.719528,0.048582,0.000000
35.370003,65.768044,-172.764008,0.002971,0.001910,0.048522,292.550873,14.903252,0.485216,-172.764008,0.048582,0.000000
35.530003,65.699532,-172.808502,0.002958,0.001910,0.048513,292.246124,14.887727,0.485129,-172.808502,0.048582,0.000000
35.690002,65.639214,-172.764008,0.002988,0.001910,0.048513,291.977814,14.874058,0.485129,-172.764008,0.048582,0.000000
35.850002,65.566231,-172.941940,0.002958,0.001910,0.048513,291.653168,14.857520,0.485129,-172.941940,0.048582,0.000000
36.010002,65.501060,-172.852982,0.002971,0.001910,0.048513,291.363281,14.842752,0.485129,-172.852982,0.048582,0.000000
36.170002,65.442223,-172.897461,0.002953,0.001910,0.048513,291.101532,14.829420,0.485129,-172.897461,0.048582,0.000000
36.330002,65.396049,-172.897461,0.002958,0.001910,0.048513,290.896149,14.818957,0.485129,-172.897461,0.048582,0.000000
36.490002,65.351738,-172.897461,0.002979,0.001910,0.048513,290.699036,14.808915,0.485129,-172.897461,0.048582,0.000000
36.650002,65.293282,-172.941940,0.002966,0.001910,0.048513,290.439026,14.795669,0.485129,-172.941940,0.048582,0.000000
36.810001,65.253059,-172.941940,0.002962,0.001910,0.048513,290.260101,14.786554,0.485129,-172.941940,0.048582,0.000000
36.970001,65.207634,-173.030899,0.002966,0.001910,0.048513,290.058044,14.776261,0.485129,-173.030899,0.048582,0.000000
37.130001,65.158104,-173.030899,0.002966,0.001910,0.048513,289.837708,14.765038,0.485129,-173.030899,0.048582,0.000000
37.290001,65.138374,-173.030899,0.002979,0.001910,0.048513,289.749969,14.760567,0.485129,-173.030899,0.048582,0.000000
37.450001,65.082512,-173.075378,0.002962,0.001910,0.048513,289.501465,14.747909,0.485129,-173.075378,0.048582,0.000000
37.610001,65.045647,-173.030899,0.002975,0.001910,0.048513,289.337494,14.739554,0.485129,-173.030899,0.048582,0.000000
37.770000,65.021812,-173.119858,0.002975,0.001910,0.048513,289.231476,14.734154,0.485129,-173.119858,0.048582,0.000000
37.930000,64.986061,-173.119858,0.002966,0.001910,0.048513,289.072449,14.726052,0.485129,-173.119858,0.048582,0.000000
38.090000,64.939888,-173.119858,0.002975,0.001910,0.048513,288.867035,14.715590,0.485129,-173.119858,0.048582,0.000000
38.250000,64.923134,-173.208817,0.002971,0.001910,0.048513,288.792511,14.711793,0.485129,-173.208817,0.048582,0.000000
38.410004,64.886269,-173.164337,0.002971,0.001910,0.048513,288.628540,14.703439,0.485129,-173.164337,0.048582,0.000000
38.570004,64.837868,-173.253311,0.002971,0.001910,0.048513,288.413239,14.692471,0.485129,-173.253311,0.048582,0.000000
38.730003,64.836372,-173.253311,0.002958,0.001910,0.048513,288.406586,14.692132,0.485129,-173.253311,0.048582,0.000000
38.890003,64.796898,-173.208817,0.002975,0.001910,0.048513,288.230988,14.683187,0.485129,-173.208817,0.048582,0.000000
39.050003,64.764137,-173.297791,0.002953,0.001910,0.048513,288.085266,14.675763,0.485129,-173.297791,0.048582,0.000000
39.210003,64.746635,-173.253311,0.002988,0.001910,0.048513,288.007416,14.671798,0.485129,-173.253311,0.048582,0.000000
39.370003,64.712746,-173.342270,0.002966,0.001910,0.048513,287.856659,14.664117,0.485129,-173.342270,0.048582,0.000000
39.530003,64.690025,-173.386749,0.002966,0.001910,0.048513,287.755615,14.658969,0.485129,-173.386749,0.048582,0.000000
39.690002,64.646095,-173.386749,0.002971,0.001910,0.048513,287.560181,14.649014,0.485129,-173.386749,0.048582,0.000000
39.850002,64.634926,-173.386749,0.002971,0.001910,0.048513,287.510498,14.646483,0.485129,-173.386749,0.048582,0.000000
40.010002,64.615562,-173.386749,0.002962,0.001910,0.048513,287.424377,14.642096,0.485129,-173.386749,0.048582,0.000000
40.170002,64.578316,-173.431229,0.002971,0.001910,0.048513,287.258698,14.633656,0.485129,-173.431229,0.048582,0.000000
40.330002,64.580177,-173.386749,0.002966,0.001910,0.048513,287.266968,14.634077,0.485129,-173.386749,0.048582,0.000000
40.490002,64.542946,-173.475708,0.002984,0.001910,0.048513,287.101349,14.625640,0.485129,-173.475708,0.048582,0.000000
40.650002,64.515388,-173.475708,0.002958,0.001910,0.048513,286.978790,14.619396,0.485129,-173.475708,0.048582,0.000000
40.810001,64.502357,-173.520187,0.002975,0.001910,0.048513,286.920807,14.616443,0.485129,-173.520187,0.048582,0.000000
40.970001,64.484856,-173.564667,0.002975,0.001910,0.048513,286.842957,14.612477,0.485129,-173.564667,0.048582,0.000000
41.130001,64.467354,-173.564667,0.002971,0.001910,0.048513,286.765106,14.608511,0.485129,-173.564667,0.048582,0.000000
41.290001,64.448357,-173.564667,0.002971,0.001910,0.048513,286.680603,14.604206,0.485129,-173.564667,0.048582,0.000000
41.450001,64.429375,-173.609146,0.002971,0.001910,0.048513,286.596161,14.599905,0.485129,-173.609146,0.048582,0.000000
41.610001,64.404793,-173.609146,0.002962,0.001910,0.048513,286.486816,14.594335,0.485129,-173.609146,0.048582,0.000000
41.770000,64.388039,-173.698120,0.002962,0.001910,0.048513,286.412292,14.590538,0.485129,-173.698120,0.048582,0.000000
41.930000,64.375374,-173.653625,0.002979,0.001910,0.048513,286.355957,14.587668,0.485129,-173.653625,0.048582,0.000000
42.090000,64.353035,-173.742599,0.002975,0.001910,0.048513,286.256592,14.582606,0.485129,-173.742599,0.048582,0.000000
42.250004,64.337029,-173.698120,0.002979,0.001910,0.048513,286.185394,14.578979,0.485129,-173.698120,0.048582,0.000000
42.410004,64.326591,-173.742599,0.002966,0.001910,0.048513,286.138977,14.576614,0.485129,-173.742599,0.048582,0.000000
42.570004,64.304619,-173.742599,0.002984,0.001910,0.048513,286.041229,14.571634,0.485129,-173.742599,0.048582,0.000000
42.730003,64.296440,-173.742599,0.002979,0.001910,0.048513,286.004852,14.569781,0.485129,-173.742599,0.048582,0.000000
42.890003,64.268883,-173.831558,0.002975,0.001910,0.048513,285.882263,14.563537,0.485129,-173.831558,0.048582,0.000000
43.050003,64.254356,-173.831558,0.002979,0.001910,0.048513,285.817657,14.560245,0.485129,-173.831558,0.048582,0.000000
43.210003,64.248024,-173.831558,0.002984,0.001910,0.048513,285.789490,14.558810,0.485129,-173.831558,0.048582,0.000000
43.370003,64.237602,-173.831558,0.002979,0.001910,0.048513,285.743134,14.556449,0.485129,-173.831558,0.048582,0.000000
43.530003,64.207069,-173.831558,0.002979,0.001910,0.048513,285.607300,14.549529,0.485129,-173.831558,0.048582,0.000000
43.690002,64.195152,-173.964996,0.002966,0.001910,0.048513,285.554291,14.546829,0.485129,-173.964996,0.048582,0.000000
43.850002,64.195518,-173.920517,0.002966,0.001910,0.048513,285.555939,14.546912,0.485129,-173.920517,0.048582,0.000000
44.010002,64.170937,-173.964996,0.002975,0.001910,0.048513,285.446594,14.541342,0.485129,-173.964996,0.048582,0.000000
44.170002,64.154930,-173.964996,0.002979,0.001910,0.048513,285.375397,14.537715,0.485129,-173.964996,0.048582,0.000000
44.330002,64.144127,-173.920517,0.002971,0.001910,0.048513,285.327332,14.535267,0.485129,-173.920517,0.048582,0.000000
44.490002,64.116203,-174.009476,0.002975,0.001910,0.048513,285.203125,14.528940,0.485129,-174.009476,0.048582,0.000000
44.650002,64.117317,-173.964996,0.002975,0.001910,0.048513,285.208069,14.529191,0.485129,-173.964996,0.048582,0.000000
44.810001,64.105034,-174.098450,0.002979,0.001910,0.048513,285.153442,14.526409,0.485129,-174.098450,0.048582,0.000000
44.970001,64.080833,-174.098450,0.002962,0.001910,0.048513,285.045776,14.520925,0.485129,-174.098450,0.048582,0.000000
45.130001,64.073753,-174.053955,0.002971,0.001910,0.048513,285.014282,14.519320,0.485129,-174.053955,0.048582,0.000000
45.290001,64.066307,-174.142929,0.002984,0.001910,0.048513,284.981171,14.517632,0.485129,-174.142929,0.048582,0.000000
45.450001,64.045082,-174.187408,0.002966,0.001910,0.048513,284.886749,14.512823,0.485129,-174.187408,0.048582,0.000000
45.610001,64.038750,-174.142929,0.002975,0.001910,0.048513,284.858582,14.511389,0.485129,-174.142929,0.048582,0.000000
45.770000,64.033165,-174.187408,0.002966,0.001910,0.048513,284.833740,14.510123,0.485129,-174.187408,0.048582,0.000000
45.930000,64.011192,-174.231888,0.002971,0.001910,0.048513,284.735992,14.505143,0.485129,-174.231888,0.048582,0.000000
46.090004,64.001137,-174.276367,0.002979,0.001910,0.048513,284.691284,14.502865,0.485129,-174.276367,0.048582,0.000000
46.250004,63.988106,-174.187408,0.002979,0.001910,0.048513,284.633301,14.499911,0.485129,-174.187408,0.048582,0.000000
46.410004,63.978798,-174.276367,0.002992,0.001910,0.048513,284.591919,14.497803,0.485129,-174.276367,0.048582,0.000000
46.570004,63.962791,-174.320847,0.002966,0.001910,0.048513,284.520721,14.494176,0.485129,-174.320847,0.048582,0.000000
46.730003,63.962791,-174.365326,0.002966,0.001910,0.048513,284.520721,14.494176,0.485129,-174.365326,0.048582,0.000000
46.890003,63.956078,-174.409805,0.002975,0.001910,0.048513,284.490845,14.492655,0.485129,-174.409805,0.048582,0.000000
47.050003,63.924065,-174.365326,0.002979,0.001910,0.048513,284.348450,14.485399,0.485129,-174.365326,0.048582,0.000000
47.210003,63.932991,-174.409805,0.002975,0.001910,0.048513,284.388153,14.487422,0.485129,-174.409805,0.048582,0.000000
47.370003,63.911400,-174.454285,0.002971,0.001910,0.048513,284.292114,14.482530,0.485129,-174.454285,0.048582,0.000000
47.530003,63.893150,-174.409805,0.002966,0.001910,0.048513,284.210937,14.478395,0.485129,-174.409805,0.048582,0.000000
47.690002,63.889809,-174.454285,0.002975,0.001910,0.048513,284.196075,14.477637,0.485129,-174.454285,0.048582,0.000000
47.850002,63.878624,-174.498764,0.002971,0.001910,0.048513,284.146301,14.475103,0.485129,-174.498764,0.048582,0.000000
48.010002,63.871178,-174.543259,0.002979,0.001910,0.048513,284.113190,14.473415,0.485129,-174.543259,0.048582,0.000000
48.170002,63.861504,-174.543259,0.002971,0.001910,0.048513,284.070160,14.471224,0.485129,-174.543259,0.048582,0.000000
48.330002,63.851082,-174.498764,0.002979,0.001910,0.048513,284.023804,14.468863,0.485129,-174.498764,0.048582,0.000000
48.490002,63.837669,-174.632217,0.002971,0.001910,0.048513,283.964142,14.465823,0.485129,-174.632217,0.048582,0.000000
48.650002,63.828728,-174.543259,0.002971,0.001910,0.048513,283.924347,14.463797,0.485129,-174.543259,0.048582,0.000000
48.810001,63.818306,-174.587738,0.002966,0.001910,0.048513,283.877991,14.461434,0.485129,-174.587738,0.048582,0.000000
48.970001,63.809746,-174.632217,0.002971,0.001910,0.048513,283.839935,14.459496,0.485129,-174.632217,0.048582,0.000000
49.130001,63.797081,-174.632217,0.002979,0.001910,0.048513,283.783600,14.456625,0.485129,-174.632217,0.048582,0.000000
49.290001,63.791496,-174.721176,0.002971,0.001910,0.048513,283.758759,14.455359,0.485129,-174.721176,0.048582,0.000000
49.450001,63.773628,-174.721176,0.002966,0.001910,0.048513,283.679260,14.451311,0.485129,-174.721176,0.048582,0.000000
49.610001,63.778465,-174.765656,0.002984,0.001910,0.048513,283.700775,14.452407,0.485129,-174.765656,0.048582,0.000000
49.770000,63.760582,-174.765656,0.002958,0.001910,0.048513,283.621246,14.448355,0.485129,-174.765656,0.048582,0.000000
49.930004,63.752403,-174.810135,0.002992,0.001910,0.048513,283.584839,14.446502,0.485129,-174.810135,0.048582,0.000000
50.090004,63.741219,-174.854614,0.002984,0.001910,0.048513,283.535095,14.443967,0.485129,-174.854614,0.048582,0.000000
50.250004,63.733772,-174.810135,0.002971,0.001910,0.048513,283.501984,14.442279,0.485129,-174.810135,0.048582,0.000000
50.410004,63.719627,-174.899094,0.002988,0.001910,0.048513,283.439056,14.439075,0.485129,-174.899094,0.048582,0.000000
50.570004,63.711433,-174.810135,0.002979,0.001910,0.048513,283.402618,14.437217,0.485129,-174.810135,0.048582,0.000000
50.730003,63.692818,-174.854614,0.002971,0.001910,0.048513,283.319794,14.432999,0.485129,-174.854614,0.048582,0.000000
50.890003,63.693184,-174.899094,0.002975,0.001910,0.048513,283.321442,14.433082,0.485129,-174.899094,0.048582,0.000000
51.050003,63.692818,-174.854614,0.002984,0.001910,0.048513,283.319794,14.432999,0.485129,-174.854614,0.048582,0.000000
51.210003,63.677925,-174.943573,0.002971,0.001910,0.048513,283.253571,14.429624,0.485129,-174.943573,0.048582,0.000000
51.370003,63.656700,-174.988068,0.002971,0.001910,0.048513,283.159149,14.424815,0.485129,-174.988068,0.048582,0.000000
51.530003,63.663033,-174.988068,0.002979,0.001910,0.048513,283.187317,14.426250,0.485129,-174.988068,0.048582,0.000000
51.690002,63.654091,-175.032547,0.002971,0.001910,0.048513,283.147552,14.424223,0.485129,-175.032547,0.048582,0.000000
51.850002,63.647392,-174.988068,0.002971,0.001910,0.048513,283.117737,14.422705,0.485129,-174.988068,0.048582,0.000000
52.010002,63.648506,-175.077026,0.002971,0.001910,0.048513,283.122681,14.422957,0.485129,-175.077026,0.048582,0.000000
52.170002,63.630638,-175.077026,0.002984,0.001910,0.048513,283.043213,14.418908,0.485129,-175.077026,0.048582,0.000000
52.330002,63.623177,-175.032547,0.002975,0.001910,0.048513,283.010010,14.417218,0.485129,-175.032547,0.048582,0.000000
52.490002,63.625420,-175.165985,0.002984,0.001910,0.048513,283.019989,14.417727,0.485129,-175.165985,0.048582,0.000000
52.650002,63.613503,-175.165985,0.002979,0.001910,0.048513,282.966980,14.415026,0.485129,-175.165985,0.048582,0.000000
52.810001,63.590416,-175.299423,0.002975,0.001910,0.048513,282.864288,14.409795,0.485129,-175.299423,0.048582,0.000000
52.970001,63.600838,-175.165985,0.002971,0.001910,0.048513,282.910645,14.412156,0.485129,-175.165985,0.048582,0.000000
53.130001,63.593773,-175.254944,0.002984,0.001910,0.048513,282.879242,14.410555,0.485129,-175.254944,0.048582,0.000000
53.290001,63.574409,-175.299423,0.002984,0.001910,0.048513,282.793091,14.406167,0.485129,-175.299423,0.048582,0.000000
53.450001,63.584831,-175.254944,0.002979,0.001910,0.048513,282.839447,14.408529,0.485129,-175.254944,0.048582,0.000000
53.610004,63.577751,-175.254944,0.002984,0.001910,0.048513,282.807953,14.406924,0.485129,-175.254944,0.048582,0.000000
53.770004,63.552437,-175.299423,0.002992,0.001910,0.048513,282.695343,14.401188,0.485129,-175.299423,0.048582,0.000000
53.930004,63.568077,-175.343903,0.002979,0.001910,0.048513,282.764923,14.404733,0.485129,-175.343903,0.048582,0.000000
54.090004,63.547966,-175.343903,0.002975,0.001910,0.048513,282.675476,14.400175,0.485129,-175.343903,0.048582,0.000000
54.250004,63.540520,-175.343903,0.002975,0.001910,0.048513,282.642334,14.398487,0.485129,-175.343903,0.048582,0.000000
54.410004,63.534935,-175.388397,0.002971,0.001910,0.048513,282.617493,14.397222,0.485129,-175.388397,0.048582,0.000000
54.570004,63.524879,-175.432877,0.002962,0.001910,0.048513,282.572784,14.394943,0.485129,-175.432877,0.048582,0.000000
54.730003,63.520409,-175.432877,0.002975,0.001910,0.048513,282.552887,14.393930,0.485129,-175.432877,0.048582,0.000000
54.890003,63.523766,-175.432877,0.002962,0.001910,0.048513,282.567810,14.394691,0.485129,-175.432877,0.048582,0.000000
55.050003,63.501411,-175.477356,0.002988,0.001910,0.048513,282.468384,14.389626,0.485129,-175.477356,0.048582,0.000000
55.210003,63.496574,-175.477356,0.002984,0.001910,0.048513,282.446869,14.388530,0.485129,-175.477356,0.048582,0.000000
55.370003,63.498817,-175.477356,0.002979,0.001910,0.048513,282.456848,14.389038,0.485129,-175.477356,0.048582,0.000000
55.530003,63.481682,-175.566315,0.002992,0.001910,0.048513,282.380615,14.385155,0.485129,-175.566315,0.048582,0.000000
55.690002,63.485405,-175.521835,0.002975,0.001910,0.048513,282.397186,14.385999,0.485129,-175.521835,0.048582,0.000000
55.850002,63.485039,-175.521835,0.002984,0.001910,0.048513,282.395569,14.385916,0.485129,-175.521835,0.048582,0.000000
56.010002,63.488380,-175.610794,0.002979,0.001910,0.048513,282.410431,14.386673,0.485129,-175.610794,0.048582,0.000000
56.170002,63.458961,-175.655273,0.002984,0.001910,0.048513,282.279572,14.380006,0.485129,-175.655273,0.048582,0.000000
56.330002,63.466042,-175.699753,0.002997,0.001910,0.048513,282.311066,14.381611,0.485129,-175.699753,0.048582,0.000000
56.490002,63.451149,-175.655273,0.002988,0.001910,0.048513,282.244812,14.378237,0.485129,-175.655273,0.048582,0.000000
56.650002,63.451515,-175.655273,0.002984,0.001910,0.048513,282.246429,14.378319,0.485129,-175.655273,0.048582,0.000000
56.810001,63.448906,-175.788712,0.002979,0.001910,0.048513,282.234833,14.377728,0.485129,-175.788712,0.048582,0.000000
56.970001,63.438118,-175.655273,0.002992,0.001910,0.048513,282.186829,14.375283,0.485129,-175.655273,0.048582,0.000000
57.130001,63.427681,-175.699753,0.002975,0.001910,0.048513,282.140411,14.372918,0.485129,-175.699753,0.048582,0.000000
57.290001,63.432899,-175.744232,0.002984,0.001910,0.048513,282.163635,14.374100,0.485129,-175.744232,0.048582,0.000000
57.450005,63.430290,-175.744232,0.002975,0.001910,0.048513,282.152008,14.373509,0.485129,-175.744232,0.048582,0.000000
57.610004,63.415398,-175.833206,0.002962,0.001910,0.048513,282.085785,14.370134,0.485129,-175.833206,0.048582,0.000000
57.770004,63.422478,-175.788712,0.002962,0.001910,0.048513,282.117279,14.371738,0.485129,-175.788712,0.048582,0.000000
57.930004,63.409813,-175.877686,0.002971,0.001910,0.048513,282.060944,14.368869,0.485129,-175.877686,0.048582,0.000000
58.090004,63.406837,-175.877686,0.002979,0.001910,0.048513,282.047699,14.368195,0.485129,-175.877686,0.048582,0.000000
58.250004,63.407204,-175.922165,0.002997,0.001910,0.048513,282.049316,14.368278,0.485129,-175.922165,0.048582,0.000000
58.410004,63.395287,-175.966644,0.002988,0.001910,0.048513,281.996307,14.365578,0.485129,-175.966644,0.048582,0.000000
58.570004,63.386360,-175.877686,0.002984,0.001910,0.048513,281.956604,14.363555,0.485129,-175.877686,0.048582,0.000000
58.730003,63.384117,-176.055603,0.002966,0.001910,0.048513,281.946625,14.363047,0.485129,-176.055603,0.048582,0.000000
58.890003,63.390831,-176.011124,0.002975,0.001910,0.048513,281.976501,14.364568,0.485129,-176.011124,0.048582,0.000000
59.050003,63.365135,-176.011124,0.002979,0.001910,0.048513,281.862213,14.358745,0.485129,-176.011124,0.048582,0.000000
59.210003,63.371086,-176.055603,0.002975,0.001910,0.048513,281.888672,14.360093,0.485129,-176.055603,0.048582,0.000000
59.370003,63.361412,-176.055603,0.002984,0.001910,0.048513,281.845642,14.357902,0.485129,-176.055603,0.048582,0.000000
59.530003,63.358055,-176.055603,0.002984,0.001910,0.048513,281.830719,14.357141,0.485129,-176.055603,0.048582,0.000000
59.690002,63.348366,-176.100082,0.002966,0.001910,0.048513,281.787598,14.354945,0.485129,-176.100082,0.048582,0.000000
59.850002,63.354332,-176.144562,0.002975,0.001910,0.048513,281.814148,14.356297,0.485129,-176.144562,0.048582,0.000000
60.010002,63.333107,-176.144562,0.002992,0.001910,0.048513,281.719727,14.351488,0.485129,-176.144562,0.048582,0.000000
60.170002,63.338692,-176.189041,0.002984,0.001910,0.048513,281.744568,14.352753,0.485129,-176.189041,0.048582,0.000000
60.330002,63.337944,-176.189041,0.002984,0.001910,0.048513,281.741241,14.352584,0.485129,-176.189041,0.048582,0.000000
60.490002,63.332359,-176.144562,0.002962,0.001910,0.048513,281.716400,14.351318,0.485129,-176.144562,0.048582,0.000000
60.650002,63.336082,-176.233521,0.002984,0.001910,0.048513,281.732971,14.352161,0.485129,-176.233521,0.048582,0.000000
60.810001,63.324165,-176.233521,0.002975,0.001910,0.048513,281.679962,14.349462,0.485129,-176.233521,0.048582,0.000000
60.970001,63.314110,-176.278015,0.002975,0.001910,0.048513,281.635223,14.347183,0.485129,-176.278015,0.048582,0.000000
61.130001,63.305183,-176.322495,0.002984,0.001910,0.048513,281.595520,14.345160,0.485129,-176.322495,0.048582,0.000000
61.290005,63.296989,-176.278015,0.002979,0.001910,0.048513,281.559082,14.343303,0.485129,-176.278015,0.048582,0.000000
61.450005,63.287682,-176.322495,0.002984,0.001910,0.048513,281.517670,14.341193,0.485129,-176.322495,0.048582,0.000000
61.610004,63.289162,-176.366974,0.002997,0.001910,0.048513,281.524261,14.341529,0.485129,-176.366974,0.048582,0.000000
61.770004,63.279854,-176.322495,0.002992,0.001910,0.048513,281.482849,14.339419,0.485129,-176.322495,0.048582,0.000000
61.930004,63.274651,-176.411453,0.002979,0.001910,0.048513,281.459717,14.338241,0.485129,-176.411453,0.048582,0.000000
62.090004,63.271294,-176.411453,0.002979,0.001910,0.048513,281.444763,14.337480,0.485129,-176.411453,0.048582,0.000000
62.250004,63.267570,-176.411453,0.002988,0.001910,0.048513,281.428223,14.336637,0.485129,-176.411453,0.048582,0.000000
62.410004,63.254539,-176.455933,0.002966,0.001910,0.048513,281.370239,14.333684,0.485129,-176.455933,0.048582,0.000000
62.570004,63.253044,-176.411453,0.002992,0.001910,0.048513,281.363586,14.333344,0.485129,-176.411453,0.048582,0.000000
62.730003,63.250816,-176.500412,0.002979,0.001910,0.048513,281.353668,14.332840,0.485129,-176.500412,0.048582,0.000000
62.890003,63.237404,-176.500412,0.002984,0.001910,0.048513,281.294006,14.329801,0.485129,-176.500412,0.048582,0.000000
63.050003,63.227730,-176.500412,0.002979,0.001910,0.048513,281.250977,14.327609,0.485129,-176.500412,0.048582,0.000000
63.210003,63.227730,-176.544891,0.002979,0.001910,0.048513,281.250977,14.327609,0.485129,-176.544891,0.048582,0.000000
63.370003,63.218040,-176.544891,0.002988,0.001910,0.048513,281.207886,14.325413,0.485129,-176.544891,0.048582,0.000000
63.530003,63.210594,-176.633850,0.002971,0.001910,0.048513,281.174774,14.323725,0.485129,-176.633850,0.048582,0.000000
63.690002,63.215813,-176.589371,0.002984,0.001910,0.048513,281.197968,14.324908,0.485129,-176.589371,0.048582,0.000000
63.850002,63.197563,-176.633850,0.002971,0.001910,0.048513,281.116791,14.320773,0.485129,-176.633850,0.048582,0.000000
64.000000,63.189003,-176.633850,0.002979,0.001910,0.048513,281.078735,14.318832,0.485129,-176.633850,0.048582,0.000000