File: Data/AG AL compression 300N/AL membrane Peeled 300N_2_1_03202024_154059.csv
Time (sec),S:Load (lbs),S:HL1 (DIM),S:LVDT (in),S:Position (in),Ch:Position (mm),Ch:Load (N),Ch:Stress (MPa),Ch:Strain (mm/mm),Ch:HL1 (DIM),Set Point (),Cycles ()
0.110000,-0.011917,-53.110256,0.000009,-0.000000,-0.000000,-0.053010,-0.002700,-0.000000,-53.110256,0.000121,0.000000
0.290000,-0.016014,-53.110256,-0.000004,-0.000000,-0.000000,-0.071234,-0.003629,-0.000000,-53.110256,0.000121,0.000000
0.470000,-0.020859,-53.154736,-0.000004,0.000038,0.000962,-0.092784,-0.004727,0.009625,-53.154736,0.001631,0.000000
0.650000,-0.022720,-53.110256,-0.000004,0.000143,0.003633,-0.101065,-0.005149,0.036335,-53.110256,0.004631,0.000000
0.830000,-0.018623,-53.110256,0.000056,0.000260,0.006608,-0.082841,-0.004220,0.066084,-53.110256,0.007614,0.000000
1.010000,0.033508,-53.110256,0.000172,0.000376,0.009539,0.149052,0.007593,0.095394,-53.110256,0.010615,0.000000
1.190000,0.018616,-53.110256,0.000285,0.000491,0.012471,0.082807,0.004218,0.124709,-53.110256,0.013615,0.000000
1.370000,0.055855,-53.110256,0.000392,0.000607,0.015428,0.248455,0.012657,0.154280,-53.110256,0.016616,0.000000
1.550000,0.037231,-53.154736,0.000517,0.000724,0.018385,0.165614,0.008437,0.183851,-53.154736,0.019617,0.000000
1.730000,0.010422,-53.199219,0.000651,0.000848,0.021542,0.046358,0.002362,0.215417,-53.199219,0.022617,0.000000
1.910000,0.008186,-53.154736,0.000755,0.000968,0.024577,0.036415,0.001855,0.245772,-53.154736,0.025618,0.000000
2.090000,0.016380,-53.199219,0.000867,0.001082,0.027491,0.072863,0.003712,0.274912,-53.199219,0.028618,0.000000
2.270000,-0.000000,-53.110256,0.000974,0.001198,0.030431,-0.000000,-0.000000,0.304309,-53.110256,0.031619,0.000000
2.450000,-0.032402,-53.199219,0.001099,0.001311,0.033293,-0.144131,-0.007342,0.332927,-53.199219,0.034602,0.000000
2.630000,-0.048409,-53.199219,0.001229,0.001431,0.036354,-0.215332,-0.010970,0.363539,-53.199219,0.037603,0.000000
2.810000,-0.048782,-53.243698,0.001341,0.001551,0.039398,-0.216995,-0.011054,0.393981,-53.243698,0.040604,0.000000
2.990000,-0.051018,-53.154736,0.001466,0.001676,0.042563,-0.226938,-0.011561,0.425634,-53.154736,0.043604,0.000000
3.170000,0.022713,-53.199219,0.001587,0.001793,0.045538,0.101031,0.005147,0.455380,-53.199219,0.046605,0.000000
3.350000,0.027924,-53.199219,0.001699,0.001912,0.048556,0.124210,0.006328,0.485560,-53.199219,0.049605,0.000000
3.530000,0.039467,-53.243698,0.001819,0.002027,0.051487,0.175557,0.008943,0.514871,-53.243698,0.052606,0.000000
3.710000,0.055855,-53.199219,0.001927,0.002139,0.054323,0.248455,0.012657,0.543231,-53.199219,0.055607,0.000000
3.890000,0.037231,-53.243698,0.002039,0.002259,0.057376,0.165614,0.008437,0.573756,-53.243698,0.058607,0.000000
4.070000,0.037979,-53.199219,0.002173,0.002378,0.060411,0.168940,0.008606,0.604111,-53.199219,0.061608,0.000000
4.250000,0.017502,-53.288177,0.002294,0.002497,0.063429,0.077852,0.003966,0.634288,-53.288177,0.064591,0.000000
4.430000,0.020477,-53.288177,0.002410,0.002618,0.066490,0.091088,0.004640,0.664900,-53.288177,0.067591,0.000000
4.610000,0.001114,-53.288177,0.002509,0.002732,0.069395,0.004955,0.000252,0.693953,-53.288177,0.070592,0.000000
4.790000,-0.025696,-53.243698,0.002639,0.002846,0.072283,-0.114301,-0.005823,0.722832,-53.243698,0.073593,0.000000
4.970000,-0.045059,-53.243698,0.002759,0.002968,0.075379,-0.200433,-0.010211,0.753792,-53.243698,0.076593,0.000000
5.150000,-0.037987,-53.288177,0.002893,0.003089,0.078449,-0.168974,-0.008608,0.784491,-53.288177,0.079594,0.000000
5.330000,0.007072,-53.377140,0.003009,0.003209,0.081502,0.031460,0.001603,0.815020,-53.377140,0.082595,0.000000
5.510000,-0.004097,-53.332661,0.003122,0.003328,0.084528,-0.018224,-0.000928,0.845284,-53.332661,0.085595,0.000000
5.690000,0.040215,-53.332661,0.003247,0.003445,0.087512,0.178883,0.009113,0.875117,-53.332661,0.088596,0.000000
5.870000,0.053619,-53.288177,0.003372,0.003564,0.090530,0.238511,0.012150,0.905298,-53.288177,0.091579,0.000000
6.050000,0.037979,-53.288177,0.003484,0.003682,0.093530,0.168940,0.008606,0.935304,-53.288177,0.094580,0.000000
6.230000,0.045052,-53.377140,0.003609,0.003798,0.096470,0.200399,0.010209,0.964702,-53.377140,0.097580,0.000000
6.410000,0.037231,-53.332661,0.003721,0.003910,0.099323,0.165614,0.008437,0.993232,-53.332661,0.100581,0.000000
6.590000,0.045425,-53.288177,0.003833,0.004030,0.102367,0.202062,0.010294,1.023674,-53.288177,0.103582,0.000000
6.770000,0.035744,-53.377140,0.003958,0.004150,0.105411,0.158996,0.008100,1.054112,-53.377140,0.106582,0.000000
6.950000,0.017868,-53.332661,0.004083,0.004267,0.108386,0.079481,0.004049,1.083858,-53.332661,0.109583,0.000000
7.130000,-0.006332,-53.421623,0.004204,0.004386,0.111404,-0.028168,-0.001435,1.114038,-53.421623,0.112583,0.000000
7.310000,0.016754,-53.421623,0.004329,0.004506,0.114448,0.074526,0.003797,1.144477,-53.421623,0.115584,0.000000
7.490000,0.019730,-53.421623,0.004441,0.004623,0.117431,0.087762,0.004471,1.174309,-53.421623,0.118585,0.000000
7.670001,0.004463,-53.377140,0.004579,0.004742,0.120458,0.019853,0.001011,1.204577,-53.377140,0.121568,0.000000
7.850000,0.012283,-53.377140,0.004691,0.004860,0.123432,0.054639,0.002783,1.234322,-53.377140,0.124568,0.000000
8.030001,0.031647,-53.377140,0.004829,0.004978,0.126450,0.140772,0.007171,1.264503,-53.377140,0.127569,0.000000
8.210000,0.042076,-53.421623,0.004937,0.005100,0.129546,0.187164,0.009535,1.295460,-53.421623,0.130569,0.000000
8.390000,0.050270,-53.466103,0.005062,0.005218,0.132538,0.223612,0.011391,1.325379,-53.466103,0.133570,0.000000
8.570001,0.024200,-53.466103,0.005182,0.005339,0.135600,0.107649,0.005484,1.355995,-53.466103,0.136571,0.000000
8.750000,0.031647,-53.377140,0.005299,0.005453,0.138496,0.140772,0.007171,1.384961,-53.377140,0.139571,0.000000
8.930000,0.041702,-53.421623,0.005420,0.005566,0.141367,0.185501,0.009450,1.413666,-53.421623,0.142572,0.000000
9.110001,0.044312,-53.510586,0.005527,0.005680,0.144263,0.197107,0.010041,1.442632,-53.510586,0.145572,0.000000
9.290001,0.026436,-53.421623,0.005639,0.005798,0.147263,0.117593,0.005990,1.472635,-53.421623,0.148556,0.000000
9.470000,0.046913,-53.421623,0.005756,0.005924,0.150464,0.208680,0.010631,1.504636,-53.421623,0.151556,0.000000
9.650001,0.045799,-53.466103,0.005872,0.006043,0.153490,0.203725,0.010378,1.534904,-53.466103,0.154557,0.000000
9.830001,0.035004,-53.510586,0.005993,0.006158,0.156421,0.155704,0.007932,1.564214,-53.510586,0.157558,0.000000
10.010000,0.024574,-53.555065,0.006105,0.006277,0.159431,0.109312,0.005569,1.594308,-53.555065,0.160558,0.000000
10.190001,0.045425,-53.466103,0.006217,0.006395,0.162423,0.202062,0.010294,1.624227,-53.466103,0.163559,0.000000
10.370001,0.041328,-53.510586,0.006342,0.006514,0.165458,0.183838,0.009365,1.654578,-53.510586,0.166559,0.000000
10.550000,0.018616,-53.510586,0.006463,0.006634,0.168502,0.082807,0.004218,1.685020,-53.510586,0.169560,0.000000
10.730000,0.036491,-53.466103,0.006597,0.006754,0.171546,0.162322,0.008269,1.715458,-53.466103,0.172561,0.000000
10.910001,0.029045,-53.555065,0.006700,0.006870,0.174503,0.129199,0.006582,1.745030,-53.555065,0.175544,0.000000
11.090000,0.029045,-53.555065,0.006808,0.006989,0.177521,0.129199,0.006582,1.775210,-53.555065,0.178544,0.000000
11.270000,0.039841,-53.599545,0.006916,0.007098,0.180296,0.177220,0.009028,1.802961,-53.599545,0.181545,0.000000
11.450001,0.057343,-53.510586,0.007041,0.007213,0.183219,0.255072,0.012994,1.832188,-53.510586,0.184546,0.000000
11.630000,0.078941,-53.510586,0.007157,0.007336,0.186341,0.351149,0.017888,1.863406,-53.510586,0.187546,0.000000
11.810000,0.057716,-53.599545,0.007278,0.007459,0.189463,0.256735,0.013079,1.894628,-53.599545,0.190547,0.000000
11.990001,0.058830,-53.599545,0.007394,0.007577,0.192446,0.261690,0.013331,1.924460,-53.599545,0.193547,0.000000
12.170001,0.054367,-53.555065,0.007524,0.007698,0.195525,0.241837,0.012320,1.955246,-53.555065,0.196548,0.000000
12.350000,0.051758,-53.555065,0.007631,0.007815,0.198499,0.230230,0.011728,1.984992,-53.555065,0.199549,0.000000
12.530001,0.065910,-53.555065,0.007761,0.007931,0.201439,0.293184,0.014935,2.014393,-53.555065,0.202549,0.000000
12.710001,0.036865,-53.688507,0.007877,0.008047,0.204388,0.163985,0.008354,2.043877,-53.688507,0.205533,0.000000
12.890000,0.023460,-53.688507,0.008015,0.008169,0.207484,0.104357,0.005316,2.074838,-53.688507,0.208533,0.000000
13.070001,0.008934,-53.555065,0.008127,0.008284,0.210423,0.039741,0.002024,2.104235,-53.555065,0.211534,0.000000
13.250001,0.037231,-53.555065,0.008274,0.008405,0.213485,0.165614,0.008437,2.134851,-53.555065,0.214534,0.000000
13.430000,0.032021,-53.555065,0.008386,0.008527,0.216589,0.142435,0.007256,2.165895,-53.555065,0.217535,0.000000
13.610001,0.057343,-53.644028,0.008481,0.008638,0.219408,0.255072,0.012994,2.194081,-53.644028,0.220536,0.000000
13.790001,0.085274,-53.688507,0.008610,0.008755,0.222365,0.379317,0.019323,2.223652,-53.688507,0.223536,0.000000
13.970000,0.110222,-53.599545,0.008727,0.008872,0.225357,0.490291,0.024977,2.253572,-53.599545,0.226537,0.000000
14.150001,0.144478,-53.599545,0.008852,0.008991,0.228375,0.642670,0.032739,2.283753,-53.599545,0.229537,0.000000
14.330001,0.133682,-53.688507,0.008981,0.009111,0.231419,0.594648,0.030293,2.314191,-53.688507,0.232520,0.000000
14.510000,0.163094,-53.688507,0.009089,0.009232,0.234498,0.725476,0.036958,2.344977,-53.688507,0.235521,0.000000
14.690001,0.229004,-53.732990,0.009201,0.009349,0.237464,1.018660,0.051893,2.374635,-53.732990,0.238522,0.000000
14.870001,0.270340,-53.644028,0.009317,0.009462,0.240326,1.202532,0.061260,2.403257,-53.644028,0.241522,0.000000
15.050001,0.370880,-53.644028,0.009455,0.009581,0.243370,1.649757,0.084043,2.433695,-53.644028,0.244523,0.000000
15.230000,0.539566,-53.688507,0.009563,0.009699,0.246344,2.400110,0.122267,2.463440,-53.688507,0.247523,0.000000
15.410001,0.566376,-53.732990,0.009632,-0.000006,-0.000147,2.519365,0.128343,-0.001472,-53.732990,0.000095,0.000000
15.590001,0.530632,-53.732990,0.009636,-0.000006,-0.000147,2.360369,0.120243,-0.001472,-53.732990,0.000095,0.000000
15.770000,0.519455,-53.777470,0.009615,-0.000006,-0.000147,2.310651,0.117710,-0.001472,-53.777470,0.000095,0.000000
15.950001,0.565262,-53.732990,0.009632,-0.000006,-0.000147,2.514410,0.128090,-0.001472,-53.732990,0.000260,0.000000
16.130001,0.557808,-53.732990,0.009645,-0.000006,-0.000147,2.481254,0.126401,-0.001472,-53.732990,0.000555,0.000000
16.310001,0.549248,-53.777470,0.009628,-0.000006,-0.000147,2.443176,0.124461,-0.001472,-53.777470,0.000859,0.000000
16.490002,0.521317,-53.777470,0.009636,-0.000006,-0.000147,2.318932,0.118132,-0.001472,-53.777470,0.001154,0.000000
16.670000,0.692612,-53.777470,0.009628,0.000026,0.000668,3.080891,0.156948,0.006680,-53.777470,0.001457,0.000000
16.850000,0.723145,-53.777470,0.009641,0.000038,0.000954,3.216707,0.163867,0.009542,-53.777470,0.001761,0.000000
17.030001,0.782349,-53.732990,0.009658,0.000048,0.001214,3.480061,0.177283,0.012142,-53.732990,0.002056,0.000000
17.210001,0.783096,-53.821949,0.009671,0.000059,0.001500,3.483386,0.177452,0.015003,-53.821949,0.002359,0.000000
17.390001,0.787941,-53.821949,0.009675,0.000068,0.001735,3.504936,0.178550,0.017346,-53.821949,0.002654,0.000000
17.570002,0.808044,-53.777470,0.009679,0.000078,0.001978,3.594361,0.183105,0.019776,-53.777470,0.002958,0.000000
17.750000,0.856453,-53.777470,0.009701,0.000089,0.002272,3.809693,0.194075,0.022725,-53.777470,0.003261,0.000000
17.930000,0.964073,-53.777470,0.009705,0.000103,0.002619,4.288412,0.218462,0.026191,-53.777470,0.003556,0.000000
18.110001,0.996094,-53.821949,0.009722,0.000117,0.002966,4.430846,0.225718,0.029662,-53.821949,0.003859,0.000000
18.290001,0.969284,-53.866432,0.009722,0.000123,0.003122,4.311591,0.219643,0.031222,-53.866432,0.004154,0.000000
18.470001,1.084343,-53.821949,0.009718,0.000136,0.003461,4.823399,0.245716,0.034605,-53.821949,0.004458,0.000000
18.650002,1.166641,-53.866432,0.009740,0.000152,0.003868,5.189479,0.264365,0.038682,-53.866432,0.004761,0.000000
18.830002,1.220261,-53.777470,0.009783,0.000172,0.004362,5.427990,0.276515,0.043625,-53.777470,0.005056,0.000000
19.010000,1.190475,-53.821949,0.009783,0.000178,0.004510,5.295499,0.269766,0.045097,-53.821949,0.005360,0.000000
19.190001,1.213562,-53.866432,0.009791,0.000186,0.004735,5.398193,0.274997,0.047353,-53.866432,0.005655,0.000000
19.370001,1.280586,-53.866432,0.009787,0.000197,0.005013,5.696332,0.290185,0.050127,-53.866432,0.005958,0.000000
19.550001,1.314842,-53.910912,0.009796,0.000207,0.005247,5.848711,0.297947,0.052470,-53.910912,0.006253,0.000000
19.730001,1.409058,-53.866432,0.009813,0.000220,0.005585,6.267801,0.319297,0.055850,-53.866432,0.006556,0.000000
19.910002,1.516296,-53.866432,0.009835,0.000233,0.005923,6.744823,0.343598,0.059234,-53.866432,0.006860,0.000000
20.090000,1.557259,-53.955395,0.009839,0.000241,0.006123,6.927032,0.352880,0.061228,-53.955395,0.007155,0.000000
20.270000,1.674927,-53.910912,0.009843,0.000253,0.006426,7.450446,0.379544,0.064264,-53.910912,0.007458,0.000000
20.450001,1.737114,-53.910912,0.009856,0.000264,0.006713,7.727069,0.393636,0.067125,-53.910912,0.007753,0.000000
20.630001,1.833557,-53.910912,0.009873,0.000279,0.007094,8.156070,0.415490,0.070940,-53.910912,0.008057,0.000000
20.810001,1.996658,-53.866432,0.009895,0.000300,0.007614,8.881579,0.452449,0.076145,-53.866432,0.008360,0.000000
20.990002,2.004852,-53.955395,0.009912,0.000308,0.007814,8.918029,0.454306,0.078139,-53.955395,0.008655,0.000000
21.170000,2.106133,-53.999874,0.009916,0.000322,0.008169,9.368546,0.477256,0.081693,-53.999874,0.008958,0.000000
21.350000,2.159760,-53.955395,0.009916,0.000328,0.008334,9.607090,0.489408,0.083343,-53.955395,0.009253,0.000000
21.530001,2.291946,-53.910912,0.009929,0.000338,0.008586,10.195086,0.519362,0.085857,-53.910912,0.009557,0.000000
21.710001,2.458771,-53.910912,0.009942,0.000352,0.008941,10.937159,0.557165,0.089414,-53.910912,0.009860,0.000000
21.890001,2.629318,-53.999874,0.009955,0.000365,0.009279,11.695791,0.595812,0.092794,-53.999874,0.010155,0.000000
22.070002,2.748482,-54.044357,0.009960,0.000378,0.009600,12.225858,0.622815,0.096004,-54.044357,0.010459,0.000000
22.250002,2.785347,-53.999874,0.009968,0.000382,0.009713,12.389842,0.631169,0.097132,-53.999874,0.010754,0.000000
22.430000,2.886627,-53.999874,0.009977,0.000392,0.009956,12.840359,0.654119,0.099558,-53.999874,0.011057,0.000000
22.610001,3.171120,-53.999874,0.009994,0.000413,0.010494,14.105844,0.718586,0.104936,-53.999874,0.011361,0.000000
22.790001,3.332733,-54.044357,0.010011,0.000426,0.010832,14.824738,0.755208,0.108320,-54.044357,0.011656,0.000000
22.970001,3.444443,-54.088837,0.010020,0.000436,0.011083,15.321647,0.780522,0.110833,-54.088837,0.011959,0.000000
23.150002,3.604187,-53.999874,0.010011,0.000448,0.011369,16.032225,0.816720,0.113694,-53.999874,0.012254,0.000000
23.330002,3.774368,-53.999874,0.010033,0.000460,0.011673,16.789228,0.855284,0.116730,-53.999874,0.012558,0.000000
23.510000,3.931503,-54.044357,0.010046,0.000470,0.011950,17.488199,0.890891,0.119504,-54.044357,0.012861,0.000000
23.690001,4.175781,-54.044357,0.010063,0.000486,0.012332,18.574802,0.946246,0.123319,-54.044357,0.013156,0.000000
23.870001,4.328079,-54.044357,0.010063,0.000496,0.012610,19.252258,0.980757,0.126098,-54.044357,0.013459,0.000000
24.050001,4.534752,-54.044357,0.010067,0.000506,0.012861,20.171583,1.027589,0.128611,-54.044357,0.013754,0.000000
24.230001,4.579063,-54.044357,0.010093,0.000513,0.013034,20.368690,1.037631,0.130344,-54.044357,0.014058,0.000000
24.410002,4.991280,-54.088837,0.010089,0.000533,0.013546,22.202320,1.131040,0.135461,-54.088837,0.014361,0.000000
24.590002,5.130173,-54.088837,0.010119,0.000543,0.013780,22.820148,1.162514,0.137804,-54.088837,0.014656,0.000000
24.770000,5.352104,-54.088837,0.010111,0.000556,0.014110,23.807348,1.212804,0.141101,-54.088837,0.014960,0.000000
24.950001,5.567337,-54.088837,0.010128,0.000569,0.014448,24.764751,1.261577,0.144481,-54.088837,0.015255,0.000000
25.130001,5.704742,-54.133316,0.010145,0.000579,0.014708,25.375961,1.292713,0.147085,-54.133316,0.015558,0.000000
25.310001,5.961311,-54.088837,0.010158,0.000589,0.014951,26.517237,1.350852,0.149511,-54.088837,0.015862,0.000000
25.490002,6.108025,-54.133316,0.010158,0.000600,0.015229,27.169851,1.384098,0.152285,-54.133316,0.016157,0.000000
25.670002,6.414856,-54.177799,0.010175,0.000612,0.015541,28.534704,1.453627,0.155408,-54.177799,0.016460,0.000000
25.850000,6.725044,-54.177799,0.010175,0.000625,0.015870,29.914492,1.523917,0.158704,-54.177799,0.016755,0.000000
26.030001,6.846436,-54.133316,0.010179,0.000633,0.016070,30.454466,1.551425,0.160699,-54.133316,0.017059,0.000000
26.210001,7.078423,-54.088837,0.010201,0.000645,0.016373,31.486397,1.603994,0.163735,-54.088837,0.017362,0.000000
26.390001,7.573685,-54.177799,0.010201,0.000662,0.016824,33.689430,1.716221,0.168242,-54.177799,0.017657,0.000000
26.570002,7.712578,-54.177799,0.010223,0.000672,0.017076,34.307259,1.747695,0.170759,-54.177799,0.017960,0.000000
26.750002,8.060371,-54.177799,0.010214,0.000687,0.017449,35.854324,1.826506,0.174487,-54.177799,0.018255,0.000000
26.930002,8.138573,-54.133316,0.010231,0.000696,0.017674,36.202179,1.844227,0.176743,-54.133316,0.018559,0.000000
27.110001,8.405190,-54.133316,0.010253,0.000706,0.017934,37.388149,1.904643,0.179343,-54.133316,0.018862,0.000000
27.290001,8.747025,-54.133316,0.010266,0.000719,0.018255,38.908707,1.982104,0.182553,-54.133316,0.019157,0.000000
27.470001,9.126099,-54.222279,0.010266,0.000733,0.018619,40.594913,2.068003,0.186194,-54.222279,0.019461,0.000000
27.650002,9.368515,-54.222279,0.010279,0.000744,0.018906,41.673237,2.122936,0.189056,-54.222279,0.019756,0.000000
27.830002,9.657478,-54.222279,0.010274,0.000757,0.019218,42.958611,2.188416,0.192178,-54.222279,0.020059,0.000000
28.010002,9.583000,-54.222279,0.010300,0.000760,0.019296,42.627316,2.171539,0.192958,-54.222279,0.020354,0.000000
28.190001,10.111771,-54.177799,0.010296,0.000779,0.019782,44.979401,2.291360,0.197818,-54.177799,0.020658,0.000000
28.370001,10.549683,-54.266762,0.010313,0.000791,0.020102,46.927334,2.390592,0.201023,-54.266762,0.020961,0.000000
28.550001,10.739967,-54.266762,0.010335,0.000803,0.020406,47.773762,2.433711,0.204059,-54.266762,0.021256,0.000000
28.730001,10.993919,-54.266762,0.010326,0.000813,0.020658,48.903397,2.491258,0.206576,-54.266762,0.021560,0.000000
28.910002,11.247505,-54.222279,0.010348,0.000826,0.020987,50.031403,2.548721,0.209869,-54.222279,0.021854,0.000000
29.090002,11.499977,-54.222279,0.010356,0.000834,0.021195,51.154453,2.605932,0.211950,-54.222279,0.022158,0.000000
29.270000,11.935654,-54.311241,0.010365,0.000849,0.021560,53.092438,2.704658,0.215595,-54.311241,0.022461,0.000000
29.450001,12.190353,-54.266762,0.010356,0.000860,0.021854,54.225399,2.762373,0.218544,-54.266762,0.022756,0.000000
29.630001,12.599220,-54.311241,0.010391,0.000875,0.022236,56.044132,2.855024,0.222359,-54.311241,0.023060,0.000000
29.810001,12.795464,-54.266762,0.010391,0.000886,0.022505,56.917065,2.899493,0.225046,-54.266762,0.023355,0.000000
29.990002,12.866959,-54.266762,0.010399,0.000894,0.022695,57.235092,2.915694,0.226954,-54.266762,0.023658,0.000000
30.170002,13.497009,-54.311241,0.010421,0.000910,0.023103,60.037697,3.058466,0.231030,-54.311241,0.023962,0.000000
30.350002,13.681335,-54.355721,0.010425,0.000919,0.023337,60.857620,3.100235,0.233373,-54.355721,0.024257,0.000000
30.530001,13.859329,-54.266762,0.010430,0.000928,0.023571,61.649376,3.140569,0.235712,-54.266762,0.024560,0.000000
30.710001,14.425705,-54.311241,0.010438,0.000947,0.024057,64.168739,3.268912,0.240572,-54.311241,0.024855,0.000000
30.890001,14.660301,-54.311241,0.010460,0.000957,0.024300,65.212280,3.322072,0.242998,-54.311241,0.025158,0.000000
31.070002,14.709457,-54.311241,0.010468,0.000966,0.024534,65.430931,3.333211,0.245341,-54.311241,0.025462,0.000000
31.250002,15.151459,-54.355721,0.010477,0.000977,0.024820,67.397057,3.433370,0.248202,-54.355721,0.025757,0.000000
31.430002,15.712624,-54.355721,0.010486,0.000993,0.025219,69.893242,3.560531,0.252191,-54.355721,0.026060,0.000000
31.610001,15.973289,-54.311241,0.010490,0.001005,0.025531,71.052742,3.619599,0.255314,-54.311241,0.026355,0.000000
31.790001,16.138245,-54.311241,0.010511,0.001014,0.025748,71.786499,3.656978,0.257483,-54.311241,0.026659,0.000000
31.970001,16.297997,-54.355721,0.010511,0.001022,0.025965,72.497108,3.693179,0.259648,-54.355721,0.026962,0.000000
32.150002,16.988373,-54.400204,0.010511,0.001041,0.026433,75.568054,3.849620,0.264333,-54.400204,0.027257,0.000000
32.330002,17.154449,-54.400204,0.010516,0.001049,0.026650,76.306801,3.887254,0.266498,-54.400204,0.027560,0.000000
32.510002,17.565178,-54.355721,0.010550,0.001064,0.027014,78.133812,3.980326,0.270143,-54.355721,0.027855,0.000000
32.690002,17.895103,-54.400204,0.010555,0.001075,0.027300,79.601395,4.055089,0.273004,-54.400204,0.028159,0.000000
32.870003,18.121880,-54.400204,0.010568,0.001085,0.027569,80.610146,4.106476,0.275692,-54.400204,0.028462,0.000000
33.050003,18.231354,-54.444683,0.010563,0.001093,0.027760,81.097115,4.131284,0.277599,-54.444683,0.028757,0.000000
33.230003,18.636124,-54.400204,0.010568,0.001105,0.028063,82.897621,4.223006,0.280635,-54.400204,0.029061,0.000000
33.410000,19.317940,-54.444683,0.010576,0.001121,0.028471,85.930489,4.377508,0.284711,-54.444683,0.029356,0.000000
33.590000,19.596100,-54.355721,0.010593,0.001132,0.028749,87.167809,4.440540,0.287485,-54.355721,0.029659,0.000000
33.770000,19.672066,-54.444683,0.010611,0.001140,0.028957,87.505722,4.457754,0.289567,-54.444683,0.029963,0.000000
33.950001,19.961395,-54.444683,0.010602,0.001150,0.029217,88.792717,4.523317,0.292171,-54.444683,0.030258,0.000000
34.130001,20.911690,-54.444683,0.010611,0.001170,0.029729,93.019844,4.738657,0.297288,-54.444683,0.030561,0.000000
34.310001,21.155968,-54.444683,0.010628,0.001180,0.029980,94.106445,4.794011,0.299802,-54.444683,0.030856,0.000000
34.490002,21.516792,-54.489166,0.010637,0.001193,0.030310,95.711472,4.875775,0.303098,-54.489166,0.031160,0.000000
34.670002,21.828102,-54.489166,0.010658,0.001207,0.030648,97.096245,4.946319,0.306478,-54.489166,0.031463,0.000000
34.850002,22.073494,-54.533646,0.010649,0.001214,0.030847,98.187805,5.001925,0.308473,-54.533646,0.031758,0.000000
35.030003,22.278297,-54.489166,0.010667,0.001223,0.031064,99.098816,5.048335,0.310641,-54.489166,0.032061,0.000000
35.210003,22.768341,-54.489166,0.010667,0.001235,0.031359,101.278641,5.159380,0.313590,-54.489166,0.032356,0.000000
35.390003,23.520157,-54.489166,0.010684,0.001251,0.031784,104.622887,5.329743,0.317840,-54.489166,0.032660,0.000000
35.570004,23.670227,-54.533646,0.010705,0.001258,0.031957,105.290428,5.363750,0.319574,-54.533646,0.032955,0.000000
35.750000,23.697037,-54.533646,0.010697,0.001264,0.032114,105.409683,5.369825,0.321137,-54.533646,0.033258,0.000000
35.930000,24.889000,-54.533646,0.010701,0.001287,0.032677,110.711800,5.639928,0.326773,-54.533646,0.033562,0.000000
36.110001,25.249832,-54.533646,0.010701,0.001298,0.032963,112.316864,5.721694,0.329634,-54.533646,0.033857,0.000000
36.290001,25.842278,-54.489166,0.010723,0.001313,0.033354,114.952194,5.855944,0.333536,-54.489166,0.034160,0.000000
36.470001,26.106285,-54.578129,0.010740,0.001322,0.033588,116.126556,5.915769,0.335879,-54.578129,0.034455,0.000000
36.650002,26.388542,-54.533646,0.010753,0.001333,0.033857,117.382095,5.979729,0.338566,-54.533646,0.034759,0.000000
36.830002,26.646225,-54.533646,0.010762,0.001341,0.034056,118.528328,6.038121,0.340561,-54.533646,0.035062,0.000000
37.010002,26.966469,-54.533646,0.010753,0.001349,0.034264,119.952843,6.110689,0.342643,-54.533646,0.035357,0.000000
37.190002,27.502686,-54.578129,0.010762,0.001362,0.034603,122.338058,6.232198,0.346026,-54.578129,0.035661,0.000000
37.370003,28.511810,-54.578129,0.010770,0.001378,0.035010,126.826866,6.460868,0.350099,-54.578129,0.035955,0.000000
37.550003,28.846199,-54.578129,0.010774,0.001388,0.035253,128.314301,6.536642,0.352529,-54.578129,0.036259,0.000000
37.730003,29.032013,-54.667088,0.010792,0.001396,0.035452,129.140839,6.578748,0.354524,-54.667088,0.036562,0.000000
37.910004,29.785698,-54.578129,0.010787,0.001411,0.035843,132.493408,6.749536,0.358426,-54.578129,0.036857,0.000000
38.090000,30.767273,-54.622608,0.010805,0.001430,0.036319,136.859665,6.971964,0.363195,-54.622608,0.037161,0.000000
38.270000,31.369026,-54.578129,0.010822,0.001443,0.036649,139.536392,7.108323,0.366491,-54.578129,0.037456,0.000000
38.450001,31.632294,-54.622608,0.010818,0.001452,0.036883,140.707474,7.167980,0.368834,-54.622608,0.037759,0.000000
38.630001,32.105209,-54.711571,0.010818,0.001465,0.037221,142.811096,7.275144,0.372214,-54.711571,0.038063,0.000000
38.810001,32.316711,-54.622608,0.010835,0.001473,0.037421,143.751907,7.323071,0.374209,-54.622608,0.038358,0.000000
38.990002,32.582214,-54.667088,0.010839,0.001478,0.037551,144.932922,7.383235,0.375511,-54.667088,0.038661,0.000000
39.170002,33.367180,-54.533646,0.010852,0.001492,0.037906,148.424622,7.561111,0.379065,-54.533646,0.038956,0.000000
39.350002,34.528610,-54.667088,0.010856,0.001509,0.038340,153.590927,7.824295,0.383402,-54.667088,0.039260,0.000000
39.530003,34.919968,-54.711571,0.010869,0.001519,0.038592,155.331772,7.912978,0.385915,-54.711571,0.039563,0.000000
39.710003,34.976570,-54.711571,0.010861,0.001525,0.038739,155.583557,7.925804,0.387392,-54.711571,0.039858,0.000000
39.890003,35.690407,-54.667088,0.010874,0.001536,0.039025,158.758865,8.087562,0.390253,-54.667088,0.040162,0.000000
40.070004,37.385445,-54.667088,0.010887,0.001561,0.039659,166.298767,8.471663,0.396585,-54.667088,0.040456,0.000000
40.250004,38.065773,-54.711571,0.010891,0.001573,0.039962,169.325012,8.625828,0.399621,-54.711571,0.040760,0.000000
40.430000,38.248238,-54.756050,0.010895,0.001583,0.040196,170.136658,8.667175,0.401960,-54.756050,0.041063,0.000000
40.610001,38.688751,-54.711571,0.010904,0.001592,0.040448,172.096161,8.766996,0.404477,-54.711571,0.041358,0.000000
40.790001,38.931168,-54.667088,0.010904,0.001599,0.040604,173.174484,8.821928,0.406036,-54.667088,0.041662,0.000000
40.970001,39.931358,-54.711571,0.010925,0.001615,0.041011,177.623550,9.048575,0.410112,-54.711571,0.041957,0.000000
41.150002,40.581894,-54.756050,0.010925,0.001624,0.041254,180.517273,9.195989,0.412542,-54.756050,0.042260,0.000000
41.330002,41.280090,-54.800533,0.010925,0.001635,0.041540,183.623016,9.354202,0.415404,-54.800533,0.042563,0.000000
41.510002,41.717628,-54.756050,0.010930,0.001644,0.041757,185.569275,9.453350,0.417572,-54.756050,0.042859,0.000000
41.690002,42.426254,-54.756050,0.010938,0.001654,0.042017,188.721405,9.613926,0.420173,-54.756050,0.043162,0.000000
41.870003,43.747429,-54.800533,0.010951,0.001673,0.042503,194.598282,9.913309,0.425029,-54.800533,0.043457,0.000000
42.050003,45.055946,-54.845013,0.010951,0.001692,0.042988,200.418854,10.209824,0.429885,-54.845013,0.043760,0.000000
42.230003,45.700897,-54.800533,0.010951,0.001702,0.043231,203.287750,10.355971,0.432314,-54.800533,0.044064,0.000000
42.410004,46.086678,-54.800533,0.010977,0.001712,0.043491,205.003784,10.443391,0.434915,-54.800533,0.044359,0.000000
42.590000,46.800888,-54.756050,0.010964,0.001724,0.043786,208.180740,10.605232,0.437863,-54.756050,0.044662,0.000000
42.770000,47.265976,-54.756050,0.010981,0.001731,0.043968,210.249557,10.710623,0.439684,-54.756050,0.044957,0.000000
42.950001,48.152969,-54.800533,0.010990,0.001745,0.044315,214.195099,10.911619,0.443154,-54.800533,0.045261,0.000000
43.130001,49.044800,-54.845013,0.010986,0.001756,0.044610,218.162170,11.113711,0.446103,-54.845013,0.045555,0.000000
43.310001,49.968285,-54.711571,0.011003,0.001770,0.044948,222.270035,11.322974,0.449483,-54.711571,0.045859,0.000000
43.490002,50.668343,-54.800533,0.011007,0.001779,0.045183,225.384048,11.481611,0.451826,-54.800533,0.046162,0.000000
43.670002,51.018005,-54.845013,0.011016,0.001786,0.045373,226.939423,11.560845,0.453733,-54.845013,0.046457,0.000000
43.850002,52.434883,-54.800533,0.011012,0.001805,0.045850,233.242004,11.881914,0.458502,-54.800533,0.046761,0.000000
44.030003,53.346451,-54.845013,0.011025,0.001817,0.046154,237.296860,12.088478,0.461538,-54.845013,0.047056,0.000000
44.210003,54.270302,-54.800533,0.011029,0.001829,0.046449,241.406357,12.297827,0.464486,-54.800533,0.047359,0.000000
44.390003,55.212776,-54.800533,0.011033,0.001843,0.046822,245.598694,12.511395,0.468218,-54.800533,0.047663,0.000000
44.570004,55.674896,-54.889492,0.011042,0.001849,0.046960,247.654312,12.616112,0.469603,-54.889492,0.047958,0.000000
44.750004,56.320587,-54.933975,0.011042,0.001860,0.047255,250.526489,12.762427,0.472552,-54.933975,0.048261,0.000000
44.930000,57.486488,-54.933975,0.011033,0.001875,0.047637,255.712677,13.026624,0.476367,-54.933975,0.048556,0.000000
45.110001,58.634514,-54.889492,0.011050,0.001889,0.047975,260.819336,13.286771,0.479751,-54.889492,0.048860,0.000000
45.290001,59.454475,-54.889492,0.011059,0.001900,0.048261,264.466705,13.472576,0.482612,-54.889492,0.049163,0.000000
45.470001,60.059578,-54.845013,0.011072,0.001907,0.048443,267.158356,13.609695,0.484432,-54.845013,0.049458,0.000000
45.650002,60.734688,-54.889492,0.011072,0.001920,0.048773,270.161377,13.762677,0.487729,-54.889492,0.049762,0.000000
45.830002,62.314667,-54.933975,0.011081,0.001936,0.049172,277.189484,14.120706,0.491718,-54.933975,0.050056,0.000000
46.010002,63.086594,-54.933975,0.011063,0.001947,0.049449,280.623169,14.295627,0.494493,-54.933975,0.050360,0.000000
46.190002,64.074127,-54.933975,0.011068,0.001958,0.049744,285.015961,14.519404,0.497441,-54.933975,0.050663,0.000000
46.370003,64.894089,-54.978455,0.011094,0.001969,0.050022,288.663330,14.705211,0.500216,-54.978455,0.050958,0.000000
46.550003,65.550217,-54.933975,0.011085,0.001979,0.050256,291.581940,14.853891,0.502558,-54.933975,0.051262,0.000000
46.730003,66.485977,-54.933975,0.011098,0.001991,0.050559,295.744385,15.065938,0.505594,-54.933975,0.051557,0.000000
46.910004,67.130936,-54.933975,0.011089,0.001998,0.050759,298.613312,15.212088,0.507589,-54.933975,0.051860,0.000000
47.090004,67.439636,-54.933975,0.011098,0.001997,0.050716,299.986481,15.282041,0.507157,-54.933975,0.050950,0.000000
47.270000,67.151779,-54.933975,0.011111,0.001997,0.050716,298.706024,15.216810,0.507157,-54.933975,0.050950,0.000000
47.450001,66.992783,-54.978455,0.011115,0.001994,0.050655,297.998779,15.180781,0.506548,-54.978455,0.050716,0.000000
47.630001,66.783875,-55.022938,0.011102,0.001993,0.050620,297.069519,15.133442,0.506199,-55.022938,0.050716,0.000000
47.810001,66.612961,-55.022938,0.011111,0.001992,0.050603,296.309235,15.094713,0.506029,-55.022938,0.050716,0.000000
47.990002,66.441299,-54.933975,0.011119,0.001992,0.050585,295.545654,15.055814,0.505855,-54.933975,0.050716,0.000000
48.170002,66.327347,-54.978455,0.011111,0.001991,0.050577,295.038788,15.029992,0.505768,-54.978455,0.050716,0.000000
48.350002,66.198883,-55.067417,0.011124,0.001991,0.050568,294.467346,15.000881,0.505681,-55.067417,0.050716,0.000000
48.530003,66.094254,-55.022938,0.011115,0.001991,0.050559,294.001923,14.977172,0.505594,-55.022938,0.050716,0.000000
48.710003,65.991104,-55.067417,0.011115,0.001990,0.050551,293.543091,14.953797,0.505507,-55.067417,0.050716,0.000000
48.890003,65.904343,-55.111897,0.011115,0.001990,0.050551,293.157166,14.934137,0.505507,-55.111897,0.050716,0.000000
49.070004,65.818695,-55.022938,0.011119,0.001990,0.050551,292.776184,14.914729,0.505507,-55.022938,0.050716,0.000000
49.250004,65.748688,-55.067417,0.011128,0.001990,0.050542,292.464783,14.898866,0.505420,-55.067417,0.050716,0.000000
49.430004,65.678680,-55.067417,0.011128,0.001990,0.050542,292.153351,14.883001,0.505420,-55.067417,0.050716,0.000000
49.610001,65.609787,-55.067417,0.011119,0.001990,0.050542,291.846893,14.867391,0.505420,-55.067417,0.050716,0.000000
49.790001,65.540161,-55.022938,0.011115,0.001990,0.050542,291.537201,14.851613,0.505420,-55.022938,0.050716,0.000000
49.970001,65.486542,-55.067417,0.011128,0.001990,0.050542,291.298676,14.839462,0.505420,-55.067417,0.050716,0.000000
50.150002,65.421371,-55.111897,0.011137,0.001990,0.050542,291.008789,14.824695,0.505420,-55.111897,0.050716,0.000000
50.330002,65.368500,-55.111897,0.011132,0.001990,0.050542,290.773621,14.812714,0.505420,-55.111897,0.050716,0.000000
50.510002,65.319717,-55.156380,0.011115,0.001990,0.050542,290.556610,14.801660,0.505420,-55.156380,0.050716,0.000000
50.690002,65.264603,-55.111897,0.011128,0.001990,0.050542,290.311462,14.789170,0.505420,-55.111897,0.050716,0.000000
50.870003,65.239655,-55.067417,0.011119,0.001989,0.050533,290.200470,14.783518,0.505333,-55.067417,0.050716,0.000000
51.050003,65.179321,-55.111897,0.011124,0.001989,0.050533,289.932098,14.769846,0.505333,-55.111897,0.050716,0.000000
51.230003,65.145447,-55.156380,0.011119,0.001989,0.050533,289.781433,14.762170,0.505333,-55.156380,0.050716,0.000000
51.410004,65.113419,-55.200859,0.011115,0.001989,0.050533,289.638947,14.754911,0.505333,-55.200859,0.050716,0.000000
51.590004,65.078049,-55.156380,0.011128,0.001989,0.050533,289.481628,14.746897,0.505333,-55.156380,0.050716,0.000000
51.770004,65.035599,-55.111897,0.011128,0.001989,0.050533,289.292786,14.737277,0.505333,-55.111897,0.050716,0.000000
51.950001,65.002075,-55.156380,0.011132,0.001989,0.050533,289.143677,14.729681,0.505333,-55.156380,0.050716,0.000000
52.130001,64.979736,-55.156380,0.011137,0.001989,0.050533,289.044312,14.724619,0.505333,-55.156380,0.050716,0.000000
52.310001,64.921280,-55.200859,0.011128,0.001989,0.050533,288.784271,14.711372,0.505333,-55.200859,0.050716,0.000000
52.490002,64.896332,-55.156380,0.011119,0.001989,0.050533,288.673309,14.705719,0.505333,-55.156380,0.050716,0.000000
52.670002,64.866165,-55.156380,0.011132,0.001989,0.050533,288.539124,14.698883,0.505333,-55.156380,0.050716,0.000000
52.850002,64.828552,-55.156380,0.011128,0.001989,0.050533,288.371796,14.690360,0.505333,-55.156380,0.050716,0.000000
53.030003,64.804718,-55.200859,0.011132,0.001989,0.050533,288.265778,14.684958,0.505333,-55.200859,0.050716,0.000000
53.210003,64.779404,-55.245342,0.011128,0.001989,0.050533,288.153168,14.679223,0.505333,-55.245342,0.050716,0.000000
53.390003,64.749237,-55.200859,0.011124,0.001989,0.050533,288.018982,14.672387,0.505333,-55.200859,0.050716,0.000000
53.570004,64.722061,-55.200859,0.011132,0.001989,0.050533,287.898102,14.666229,0.505333,-55.200859,0.050716,0.000000
53.750004,64.693390,-55.200859,0.011132,0.001989,0.050533,287.770569,14.659732,0.505333,-55.200859,0.050716,0.000000
53.930004,64.668808,-55.200859,0.011141,0.001989,0.050533,287.661224,14.654160,0.505333,-55.200859,0.050716,0.000000
54.110004,64.651306,-55.245342,0.011128,0.001989,0.050533,287.583374,14.650195,0.505333,-55.245342,0.050716,0.000000
54.290001,64.610336,-55.200859,0.011132,0.001989,0.050533,287.401123,14.640911,0.505333,-55.200859,0.050716,0.000000
54.470001,64.607361,-55.245342,0.011137,0.001989,0.050533,287.387909,14.640238,0.505333,-55.245342,0.050716,0.000000
54.650002,64.582794,-55.200859,0.011137,0.001989,0.050533,287.278625,14.634670,0.505333,-55.200859,0.050716,0.000000
54.830002,64.548523,-55.289822,0.011128,0.001989,0.050533,287.126160,14.626904,0.505333,-55.289822,0.050716,0.000000
55.010002,64.531769,-55.334305,0.011141,0.001989,0.050533,287.051636,14.623108,0.505333,-55.334305,0.050716,0.000000
55.190002,64.506073,-55.289822,0.011132,0.001989,0.050533,286.937347,14.617286,0.505333,-55.289822,0.050716,0.000000
55.370003,64.503479,-55.289822,0.011128,0.001989,0.050533,286.925812,14.616697,0.505333,-55.289822,0.050716,0.000000
55.550003,64.465118,-55.245342,0.011132,0.001989,0.050533,286.755157,14.608005,0.505333,-55.245342,0.050716,0.000000
55.730003,64.455429,-55.334305,0.011145,0.001989,0.050533,286.712067,14.605808,0.505333,-55.334305,0.050716,0.000000
55.910004,64.439804,-55.334305,0.011128,0.001989,0.050533,286.642578,14.602269,0.505333,-55.334305,0.050716,0.000000
56.090004,64.411499,-55.289822,0.011124,0.001989,0.050533,286.516663,14.595854,0.505333,-55.289822,0.050716,0.000000
56.270004,64.400330,-55.289822,0.011137,0.001989,0.050533,286.466980,14.593323,0.505333,-55.289822,0.050716,0.000000
56.450005,64.370911,-55.289822,0.011132,0.001989,0.050533,286.336121,14.586657,0.505333,-55.289822,0.050716,0.000000
56.630001,64.375381,-55.423264,0.011137,0.001989,0.050525,286.355988,14.587669,0.505246,-55.423264,0.050716,0.000000
56.810001,64.340744,-55.378784,0.011137,0.001989,0.050525,286.201935,14.579821,0.505246,-55.378784,0.050716,0.000000
56.990002,64.333664,-55.334305,0.011128,0.001989,0.050525,286.170441,14.578217,0.505246,-55.334305,0.050716,0.000000
57.170002,64.317291,-55.245342,0.011124,0.001989,0.050525,286.097595,14.574507,0.505246,-55.245342,0.050716,0.000000
57.350002,64.301270,-55.289822,0.011137,0.001989,0.050525,286.026337,14.570876,0.505246,-55.289822,0.050716,0.000000
57.530003,64.270737,-55.334305,0.011132,0.001989,0.050525,285.890503,14.563957,0.505246,-55.334305,0.050716,0.000000
57.710003,64.261063,-55.378784,0.011128,0.001989,0.050525,285.847473,14.561765,0.505246,-55.378784,0.050716,0.000000
57.890003,64.258072,-55.423264,0.011128,0.001989,0.050525,285.834167,14.561088,0.505246,-55.423264,0.050716,0.000000
58.070004,64.228668,-55.378784,0.011137,0.001989,0.050525,285.703400,14.554424,0.505246,-55.378784,0.050716,0.000000
58.250004,64.212280,-55.378784,0.011128,0.001989,0.050525,285.630493,14.550711,0.505246,-55.378784,0.050716,0.000000
58.430004,64.205200,-55.423264,0.011137,0.001989,0.050525,285.598999,14.549107,0.505246,-55.423264,0.050716,0.000000
58.610004,64.195526,-55.423264,0.011145,0.001989,0.050525,285.555969,14.546914,0.505246,-55.423264,0.050716,0.000000
58.790001,64.165359,-55.378784,0.011128,0.001989,0.050525,285.421783,14.540078,0.505246,-55.378784,0.050716,0.000000
58.970001,64.158279,-55.423264,0.011141,0.001989,0.050525,285.390289,14.538474,0.505246,-55.423264,0.050716,0.000000
59.150002,64.151215,-55.423264,0.011128,0.001989,0.050525,285.358856,14.536873,0.505246,-55.423264,0.050716,0.000000
59.330002,64.133713,-55.467747,0.011124,0.001989,0.050525,285.281006,14.532907,0.505246,-55.467747,0.050716,0.000000
59.510002,64.116943,-55.423264,0.011141,0.001989,0.050525,285.206421,14.529107,0.505246,-55.423264,0.050716,0.000000
59.690002,64.097580,-55.556709,0.011132,0.001989,0.050525,285.120270,14.524719,0.505246,-55.556709,0.050716,0.000000
59.870003,64.092377,-55.423264,0.011128,0.001989,0.050525,285.097137,14.523540,0.505246,-55.423264,0.050716,0.000000
60.050003,64.067795,-55.467747,0.011141,0.001989,0.050525,284.987793,14.517969,0.505246,-55.467747,0.050716,0.000000
60.230003,64.062576,-55.512226,0.011137,0.001989,0.050525,284.964569,14.516788,0.505246,-55.512226,0.050716,0.000000
60.410004,64.047318,-55.512226,0.011132,0.001989,0.050525,284.896698,14.513330,0.505246,-55.512226,0.050716,0.000000
60.590004,64.032043,-55.512226,0.011124,0.001989,0.050525,284.828766,14.509869,0.505246,-55.512226,0.050716,0.000000
60.770004,64.038376,-55.467747,0.011141,0.001989,0.050525,284.856934,14.511303,0.505246,-55.467747,0.050716,0.000000
60.950005,64.006729,-55.467747,0.011132,0.001989,0.050525,284.716156,14.504132,0.505246,-55.467747,0.050716,0.000000
61.130001,64.014175,-55.512226,0.011132,0.001989,0.050525,284.749268,14.505819,0.505246,-55.512226,0.050716,0.000000
61.310001,64.030563,-55.512226,0.011137,0.001989,0.050525,284.822174,14.509533,0.505246,-55.512226,0.050716,0.000000
61.490002,63.976196,-55.601189,0.011141,0.001989,0.050525,284.580322,14.497213,0.505246,-55.601189,0.050716,0.000000
61.670002,63.983643,-55.512226,0.011141,0.001989,0.050525,284.613464,14.498901,0.505246,-55.512226,0.050716,0.000000
61.850002,63.958313,-55.467747,0.011141,0.001989,0.050525,284.500793,14.493161,0.505246,-55.467747,0.050716,0.000000
62.030003,63.942307,-55.512226,0.011158,0.001989,0.050525,284.429596,14.489534,0.505246,-55.512226,0.050716,0.000000
62.210003,63.922195,-55.556709,0.011163,0.001989,0.050525,284.340118,14.484977,0.505246,-55.556709,0.050716,0.000000
62.390003,63.924057,-55.645668,0.011145,0.001989,0.050525,284.348419,14.485398,0.505246,-55.645668,0.050716,0.000000
62.570004,63.907669,-55.556709,0.011154,0.001989,0.050525,284.275513,14.481685,0.505246,-55.556709,0.050716,0.000000
62.750004,63.885330,-55.556709,0.011141,0.001989,0.050525,284.176147,14.476623,0.505246,-55.556709,0.050716,0.000000
62.930004,63.889435,-55.601189,0.011154,0.001989,0.050525,284.194397,14.477553,0.505246,-55.601189,0.050716,0.000000
63.110004,63.873795,-55.645668,0.011150,0.001989,0.050525,284.124817,14.474009,0.505246,-55.645668,0.050716,0.000000
63.290005,63.865601,-55.690151,0.011141,0.001989,0.050525,284.088379,14.472152,0.505246,-55.690151,0.050716,0.000000
63.470001,63.861130,-55.645668,0.011137,0.001989,0.050525,284.068481,14.471138,0.505246,-55.645668,0.050716,0.000000
63.650002,63.861130,-55.512226,0.011154,0.001989,0.050525,284.068481,14.471138,0.505246,-55.512226,0.050716,0.000000
63.830002,63.843262,-55.601189,0.011154,0.001989,0.050525,283.989014,14.467091,0.505246,-55.601189,0.050716,0.000000
64.010002,63.841400,-55.690151,0.011154,0.001989,0.050525,283.980743,14.466668,0.505246,-55.690151,0.050716,0.000000
64.190002,63.818314,-55.645668,0.011154,0.001989,0.050525,283.878052,14.461436,0.505246,-55.645668,0.050716,0.000000
64.370003,63.811600,-55.601189,0.011150,0.001989,0.050525,283.848175,14.459915,0.505246,-55.601189,0.050716,0.000000
64.550003,63.803787,-55.645668,0.011150,0.001989,0.050525,283.813416,14.458144,0.505246,-55.645668,0.050716,0.000000
64.730003,63.804901,-55.601189,0.011150,0.001989,0.050525,283.818390,14.458397,0.505246,-55.601189,0.050716,0.000000
64.910004,63.777344,-55.645668,0.011150,0.001989,0.050525,283.695801,14.452153,0.505246,-55.645668,0.050716,0.000000
65.090004,63.774368,-55.690151,0.011145,0.001989,0.050525,283.682556,14.451478,0.505246,-55.690151,0.050716,0.000000
65.270004,63.770264,-55.645668,0.011150,0.001989,0.050525,283.664307,14.450549,0.505246,-55.645668,0.050716,0.000000
65.450005,63.751648,-55.645668,0.011145,0.001989,0.050525,283.581482,14.446330,0.505246,-55.645668,0.050716,0.000000
65.630005,63.755005,-55.690151,0.011163,0.001989,0.050525,283.596436,14.447090,0.505246,-55.690151,0.050716,0.000000
65.810005,63.749786,-55.734631,0.011158,0.001989,0.050525,283.573212,14.445908,0.505246,-55.734631,0.050716,0.000000
65.990005,63.735275,-55.734631,0.011167,0.001989,0.050525,283.508667,14.442619,0.505246,-55.734631,0.050716,0.000000
66.170006,63.732666,-55.690151,0.011150,0.001989,0.050525,283.497070,14.442028,0.505246,-55.690151,0.050716,0.000000
66.350006,63.722229,-55.734631,0.011154,0.001989,0.050525,283.450623,14.439664,0.505246,-55.734631,0.050716,0.000000
66.530006,63.725220,-55.690151,0.011163,0.001989,0.050525,283.463928,14.440342,0.505246,-55.690151,0.050716,0.000000
66.710007,63.707718,-55.690151,0.011158,0.001989,0.050525,283.386078,14.436376,0.505246,-55.690151,0.050716,0.000000
66.889999,63.703995,-55.823593,0.011150,0.001989,0.050525,283.369507,14.435532,0.505246,-55.823593,0.050716,0.000000
67.070000,63.695801,-55.779114,0.011145,0.001989,0.050525,283.333069,14.433675,0.505246,-55.779114,0.050716,0.000000
67.250000,63.687607,-55.734631,0.011141,0.001989,0.050525,283.296631,14.431818,0.505246,-55.734631,0.050716,0.000000
67.430000,63.680161,-55.734631,0.011154,0.001989,0.050525,283.263489,14.430130,0.505246,-55.734631,0.050716,0.000000
67.610001,63.683502,-55.734631,0.011158,0.001989,0.050525,283.278351,14.430887,0.505246,-55.734631,0.050716,0.000000
67.790001,63.679047,-55.779114,0.011150,0.001989,0.050525,283.258545,14.429878,0.505246,-55.779114,0.050716,0.000000
67.970001,63.671585,-55.823593,0.011150,0.001989,0.050525,283.225342,14.428187,0.505246,-55.823593,0.050716,0.000000
68.150002,63.656693,-55.734631,0.011145,0.001989,0.050525,283.159119,14.424812,0.505246,-55.734631,0.050716,0.000000
68.330002,63.649628,-55.779114,0.011154,0.001989,0.050525,283.127686,14.423211,0.505246,-55.779114,0.050716,0.000000
68.510002,63.636597,-55.779114,0.011158,0.001989,0.050525,283.069733,14.420259,0.505246,-55.779114,0.050716,0.000000
68.690002,63.638077,-55.823593,0.011158,0.001989,0.050525,283.076294,14.420594,0.505246,-55.823593,0.050716,0.000000
68.870003,63.639572,-55.779114,0.011150,0.001989,0.050525,283.082947,14.420933,0.505246,-55.779114,0.050716,0.000000
69.050003,63.628021,-55.779114,0.011154,0.001989,0.050525,283.031586,14.418316,0.505246,-55.779114,0.050716,0.000000
69.230003,63.623550,-55.823593,0.011150,0.001989,0.050525,283.011688,14.417303,0.505246,-55.823593,0.050716,0.000000
69.410004,63.613129,-55.779114,0.011163,0.001989,0.050525,282.965332,14.414941,0.505246,-55.779114,0.050716,0.000000
69.590004,63.598984,-55.912556,0.011158,0.001989,0.050525,282.902405,14.411736,0.505246,-55.912556,0.050716,0.000000
69.770004,63.611267,-55.823593,0.011145,0.001989,0.050525,282.957062,14.414519,0.505246,-55.823593,0.050716,0.000000
69.950005,63.607178,-55.868076,0.011150,0.001989,0.050525,282.938843,14.413592,0.505246,-55.868076,0.050716,0.000000
70.130005,63.587067,-55.868076,0.011150,0.001989,0.050525,282.849396,14.409036,0.505246,-55.868076,0.050716,0.000000
70.310005,63.584091,-55.823593,0.011158,0.001989,0.050525,282.836151,14.408361,0.505246,-55.823593,0.050716,0.000000
70.490005,63.579987,-55.823593,0.011145,0.001989,0.050525,282.817902,14.407431,0.505246,-55.823593,0.050716,0.000000
70.670006,63.581848,-55.957035,0.011145,0.001989,0.050525,282.826172,14.407853,0.505246,-55.957035,0.050716,0.000000
70.850006,63.567703,-55.868076,0.011150,0.001989,0.050525,282.763275,14.404647,0.505246,-55.868076,0.050716,0.000000
71.030006,63.547958,-55.868076,0.011158,0.001989,0.050525,282.675446,14.400173,0.505246,-55.868076,0.050716,0.000000
71.210007,63.564346,-55.823593,0.011154,0.001989,0.050525,282.748322,14.403887,0.505246,-55.823593,0.050716,0.000000
71.390007,63.544617,-55.912556,0.011150,0.001989,0.050525,282.660583,14.399416,0.505246,-55.912556,0.050716,0.000000
71.570000,63.545364,-55.957035,0.011154,0.001989,0.050525,282.663910,14.399585,0.505246,-55.957035,0.050716,0.000000
71.750000,63.536057,-55.912556,0.011150,0.001989,0.050525,282.622498,14.397476,0.505246,-55.912556,0.050716,0.000000
71.930000,63.531204,-55.912556,0.011154,0.001989,0.050525,282.600922,14.396377,0.505246,-55.912556,0.050716,0.000000
72.110001,63.525620,-55.957035,0.011154,0.001989,0.050525,282.576080,14.395111,0.505246,-55.957035,0.050716,0.000000
72.290001,63.518173,-55.912556,0.011145,0.001989,0.050525,282.542938,14.393424,0.505246,-55.912556,0.050716,0.000000
72.470001,63.515198,-55.957035,0.011150,0.001989,0.050525,282.529724,14.392750,0.505246,-55.957035,0.050716,0.000000
72.650002,63.521896,-55.912556,0.011145,0.001989,0.050525,282.559509,14.394268,0.505246,-55.912556,0.050716,0.000000
72.830002,63.505142,-55.912556,0.011150,0.001989,0.050525,282.484985,14.390471,0.505246,-55.912556,0.050716,0.000000
73.010002,63.504028,-55.912556,0.011154,0.001989,0.050525,282.480011,14.390219,0.505246,-55.912556,0.050716,0.000000
73.190002,63.498810,-56.001518,0.011163,0.001989,0.050525,282.456818,14.389036,0.505246,-56.001518,0.050716,0.000000
73.370003,63.485413,-56.045998,0.011145,0.001989,0.050525,282.397217,14.386000,0.505246,-56.045998,0.050716,0.000000
73.550003,63.484283,-56.045998,0.011145,0.001989,0.050525,282.392181,14.385744,0.505246,-56.045998,0.050716,0.000000
73.730003,63.481308,-55.912556,0.011154,0.001989,0.050525,282.378967,14.385070,0.505246,-55.912556,0.050716,0.000000
73.910004,63.473114,-55.957035,0.011141,0.001989,0.050525,282.342499,14.383213,0.505246,-55.957035,0.050716,0.000000
74.090004,63.478333,-56.045998,0.011158,0.001989,0.050525,282.365723,14.384396,0.505246,-56.045998,0.050716,0.000000
74.270004,63.460831,-56.045998,0.011154,0.001989,0.050525,282.287872,14.380429,0.505246,-56.045998,0.050716,0.000000
74.450005,63.453751,-56.045998,0.011154,0.001989,0.050525,282.256378,14.378825,0.505246,-56.045998,0.050716,0.000000
74.630005,63.456360,-55.957035,0.011158,0.001989,0.050525,282.267975,14.379416,0.505246,-55.957035,0.050716,0.000000
74.810005,63.449661,-56.001518,0.011141,0.001989,0.050525,282.238190,14.377898,0.505246,-56.001518,0.050716,0.000000
74.990005,63.445938,-56.045998,0.011150,0.001989,0.050525,282.221619,14.377055,0.505246,-56.045998,0.050716,0.000000
75.170006,63.432159,-56.045998,0.011145,0.001989,0.050525,282.160339,14.373933,0.505246,-56.045998,0.050716,0.000000
75.350006,63.434021,-56.045998,0.011145,0.001989,0.050525,282.168610,14.374354,0.505246,-56.045998,0.050716,0.000000
75.530006,63.424332,-56.045998,0.011158,0.001989,0.050525,282.125519,14.372159,0.505246,-56.045998,0.050716,0.000000
75.710007,63.423965,-56.001518,0.011158,0.001989,0.050525,282.123901,14.372076,0.505246,-56.001518,0.050716,0.000000
75.890007,63.424713,-56.090481,0.011150,0.001989,0.050525,282.127228,14.372246,0.505246,-56.090481,0.050716,0.000000
76.070007,63.416138,-56.134960,0.011158,0.001989,0.050525,282.089081,14.370302,0.505246,-56.134960,0.050716,0.000000
76.250000,63.409439,-56.134960,0.011154,0.001989,0.050525,282.059265,14.368784,0.505246,-56.134960,0.050716,0.000000
76.430000,63.364380,-56.090481,0.011150,0.001989,0.050525,281.858826,14.358574,0.505246,-56.090481,0.050716,0.000000
76.610001,63.407959,-56.045998,0.011154,0.001989,0.050525,282.052673,14.368449,0.505246,-56.045998,0.050716,0.000000
76.790001,63.389328,-56.134960,0.011158,0.001989,0.050525,281.969818,14.364226,0.505246,-56.134960,0.050716,0.000000
76.970001,63.386734,-56.090481,0.011158,0.001989,0.050525,281.958282,14.363639,0.505246,-56.090481,0.050716,0.000000
77.150002,63.384491,-56.134960,0.011145,0.001989,0.050525,281.948303,14.363131,0.505246,-56.134960,0.050716,0.000000
77.330002,63.393799,-56.090481,0.011154,0.001989,0.050525,281.989716,14.365240,0.505246,-56.090481,0.050716,0.000000
77.400002,63.376297,-56.090481,0.011150,0.001989,0.050525,281.911835,14.361275,0.505246,-56.090481,0.050716,0.000000