File: Data/AG AL compression 300N/AL membrane Peeled 300N_2_2_03202024_154426.csv
Time (sec),S:Load (lbs),S:HL1 (DIM),S:LVDT (in),S:Position (in),Ch:Position (mm),Ch:Load (N),Ch:Stress (MPa),Ch:Strain (mm/mm),Ch:HL1 (DIM),Set Point (),Cycles ()
0.110000,0.008568,-60.938904,-0.000013,-0.000000,-0.000000,0.038112,0.001941,-0.000000,-60.938904,0.000191,0.000000
0.270000,-0.004463,-60.805462,-0.000004,-0.000000,-0.000000,-0.019853,-0.001011,-0.000000,-60.805462,0.000191,0.000000
0.430000,-0.005585,-60.938904,-0.000009,0.000016,0.000399,-0.024842,-0.001266,0.003989,-60.938904,0.000919,0.000000
0.590000,-0.033882,-60.894421,-0.000013,0.000105,0.002671,-0.150715,-0.007678,0.026710,-60.894421,0.003590,0.000000
0.750000,0.007080,-60.894421,0.000013,0.000210,0.005342,0.031494,0.001604,0.053424,-60.894421,0.006261,0.000000
0.910000,0.002235,-60.894421,0.000121,0.000303,0.007684,0.009944,0.000507,0.076837,-60.894421,0.008915,0.000000
1.070000,0.025696,-60.894421,0.000224,0.000416,0.010572,0.114301,0.005823,0.105716,-60.894421,0.011586,0.000000
1.230000,0.015266,-60.849941,0.000323,0.000516,0.013104,0.067908,0.003459,0.131041,-60.849941,0.014257,0.000000
1.390000,0.012291,-60.894421,0.000427,0.000621,0.015775,0.054673,0.002785,0.157751,-60.894421,0.016911,0.000000
1.550000,0.025696,-60.938904,0.000526,0.000728,0.018498,0.114301,0.005823,0.184979,-60.938904,0.019582,0.000000
1.710000,0.044312,-60.938904,0.000625,0.000838,0.021282,0.197107,0.010041,0.212817,-60.938904,0.022253,0.000000
1.870000,0.058090,-60.894421,0.000733,0.000938,0.023832,0.258398,0.013163,0.238316,-60.894421,0.024907,0.000000
2.030000,0.022346,-60.983383,0.000841,0.001045,0.026554,0.099402,0.005064,0.265544,-60.983383,0.027578,0.000000
2.190000,0.040222,-60.894421,0.000940,0.001148,0.029156,0.178917,0.009114,0.291562,-60.894421,0.030249,0.000000
2.350000,0.001122,-60.894421,0.001048,0.001253,0.031818,0.004989,0.000254,0.318185,-60.894421,0.032902,0.000000
2.510000,0.023087,-60.938904,0.001164,0.001363,0.034611,0.102694,0.005231,0.346110,-60.938904,0.035574,0.000000
2.670000,0.026443,-60.938904,0.001276,0.001469,0.037308,0.117626,0.005992,0.373081,-60.938904,0.038245,0.000000
2.830000,0.028305,-60.983383,0.001397,0.001567,0.039814,0.125907,0.006414,0.398144,-60.983383,0.040898,0.000000
2.990000,0.021225,-60.938904,0.001483,0.001670,0.042425,0.094413,0.004810,0.424249,-60.938904,0.043569,0.000000
3.150000,-0.031647,-60.983383,0.001600,0.001774,0.045061,-0.140772,-0.007171,0.450611,-60.983383,0.046240,0.000000
3.310000,-0.000000,-60.983383,0.001716,0.001886,0.047897,-0.000000,-0.000000,0.478971,-60.983383,0.048894,0.000000
3.470000,0.060699,-60.938904,0.001819,0.001989,0.050525,0.270005,0.013755,0.505246,-60.938904,0.051565,0.000000
3.630000,0.081924,-61.027866,0.001919,0.002093,0.053161,0.364418,0.018564,0.531611,-61.027866,0.054236,0.000000
3.790000,0.126236,-60.983383,0.002035,0.002198,0.055823,0.561526,0.028605,0.558234,-60.983383,0.056907,0.000000
3.950000,0.104271,-60.938904,0.002151,0.002307,0.058590,0.463820,0.023628,0.585898,-60.938904,0.059561,0.000000
4.110000,0.127357,-60.983383,0.002229,0.002409,0.061183,0.566514,0.028860,0.611828,-60.983383,0.062232,0.000000
4.270000,0.220444,-60.983383,0.002354,0.002515,0.063889,0.980583,0.049953,0.638887,-60.983383,0.064903,0.000000
4.430000,0.280769,-60.983383,0.002453,0.002619,0.066516,1.248924,0.063623,0.665165,-60.983383,0.067557,0.000000
4.590000,0.379082,-60.938904,0.002561,0.002724,0.069196,1.686240,0.085901,0.691962,-60.938904,0.070228,0.000000
4.750000,0.519836,-61.027866,0.002669,0.002824,0.071737,2.312348,0.117797,0.717370,-61.027866,0.072899,0.000000
4.910000,0.742516,-61.027866,0.002764,-0.000003,-0.000078,3.302874,0.168256,-0.000780,-61.027866,-0.000069,0.000000
5.070000,0.556328,-61.027866,0.002777,-0.000012,-0.000304,2.474670,0.126066,-0.003035,-61.027866,-0.000069,0.000000
5.230000,0.513878,-61.072346,0.002777,-0.000012,-0.000304,2.285843,0.116446,-0.003035,-61.072346,-0.000069,0.000000
5.390000,0.517601,-61.027866,0.002777,-0.000012,-0.000304,2.302404,0.117290,-0.003035,-61.027866,-0.000069,0.000000
5.550000,0.583885,-61.027866,0.002785,-0.000012,-0.000304,2.597251,0.132310,-0.003035,-61.027866,0.000147,0.000000
5.710000,0.566010,-61.027866,0.002772,-0.000012,-0.000295,2.517736,0.128260,-0.002948,-61.027866,0.000416,0.000000
5.870000,0.554840,-61.027866,0.002777,-0.000012,-0.000295,2.468052,0.125729,-0.002948,-61.027866,0.000685,0.000000
6.030000,0.548134,-61.027866,0.002785,-0.000012,-0.000295,2.438221,0.124209,-0.002948,-61.027866,0.000945,0.000000
6.190000,0.745865,-61.072346,0.002785,0.000014,0.000364,3.317773,0.169015,0.003641,-61.072346,0.001214,0.000000
6.350000,0.746979,-61.072346,0.002790,0.000021,0.000529,3.322727,0.169268,0.005291,-61.072346,0.001483,0.000000
6.510000,0.821831,-61.027866,0.002781,0.000034,0.000867,3.655686,0.186230,0.008671,-61.027866,0.001752,0.000000
6.670001,0.825554,-61.072346,0.002807,0.000040,0.001023,3.672247,0.187073,0.010234,-61.072346,0.002012,0.000000
6.830000,0.875076,-61.072346,0.002798,0.000060,0.001535,3.892534,0.198295,0.015348,-61.072346,0.002281,0.000000
6.990000,0.907104,-61.072346,0.002841,0.000072,0.001830,4.035002,0.205553,0.018300,-61.072346,0.002550,0.000000
7.150001,0.938385,-61.116825,0.002854,0.000083,0.002099,4.174145,0.212641,0.020987,-61.116825,0.002819,0.000000
7.310000,0.893700,-61.116825,0.002841,0.000090,0.002298,3.975374,0.202515,0.022982,-61.116825,0.003079,0.000000
7.470000,0.951416,-61.116825,0.002867,0.000098,0.002480,4.232110,0.215594,0.024802,-61.116825,0.003347,0.000000
7.630001,0.980461,-61.205788,0.002854,0.000106,0.002697,4.361309,0.222176,0.026971,-61.205788,0.003616,0.000000
7.790000,0.998703,-61.116825,0.002880,0.000112,0.002853,4.442453,0.226309,0.028531,-61.116825,0.003885,0.000000
7.950000,1.121590,-61.116825,0.002876,0.000128,0.003261,4.989080,0.254156,0.032607,-61.116825,0.004154,0.000000
8.110001,1.178558,-61.116825,0.002889,0.000139,0.003538,5.242489,0.267065,0.035381,-61.116825,0.004414,0.000000
8.270000,1.181915,-61.116825,0.002893,0.000149,0.003772,5.257422,0.267826,0.037724,-61.116825,0.004683,0.000000
8.430000,1.187500,-61.205788,0.002915,0.000153,0.003894,5.282264,0.269091,0.038939,-61.205788,0.004952,0.000000
8.590000,1.252663,-61.116825,0.002923,0.000165,0.004180,5.572122,0.283857,0.041800,-61.116825,0.005221,0.000000
8.750000,1.372192,-61.161308,0.002936,0.000183,0.004648,6.103817,0.310943,0.046482,-61.161308,0.005481,0.000000
8.910001,1.415390,-61.205788,0.002940,0.000197,0.005013,6.295969,0.320732,0.050127,-61.205788,0.005750,0.000000
9.070001,1.438850,-61.161308,0.002953,0.000207,0.005247,6.400326,0.326048,0.052466,-61.161308,0.006018,0.000000
9.230000,1.457100,-61.161308,0.002958,0.000215,0.005455,6.481504,0.330184,0.054548,-61.161308,0.006287,0.000000
9.390000,1.524498,-61.161308,0.002962,0.000223,0.005663,6.781306,0.345456,0.056630,-61.161308,0.006547,0.000000
9.550000,1.562851,-61.161308,0.002966,0.000233,0.005914,6.951908,0.354147,0.059143,-61.161308,0.006816,0.000000
9.710000,1.630249,-61.116825,0.002984,0.000243,0.006166,7.251710,0.369420,0.061660,-61.116825,0.007085,0.000000
9.870001,1.658180,-61.205788,0.003009,0.000250,0.006357,7.375954,0.375749,0.063567,-61.205788,0.007354,0.000000
10.030001,1.833565,-61.250271,0.003014,0.000268,0.006808,8.156103,0.415492,0.068075,-61.250271,0.007614,0.000000
10.190001,1.893143,-61.161308,0.003027,0.000279,0.007077,8.421120,0.428992,0.070766,-61.161308,0.007883,0.000000
10.350000,1.974693,-61.250271,0.003031,0.000285,0.007250,8.783875,0.447472,0.072500,-61.250271,0.008152,0.000000
10.510000,2.059593,-61.250271,0.003040,0.000299,0.007605,9.161529,0.466711,0.076054,-61.250271,0.008421,0.000000
10.670000,2.097946,-61.250271,0.003061,0.000307,0.007805,9.332130,0.475401,0.078048,-61.250271,0.008681,0.000000
10.830001,2.215988,-61.250271,0.003053,0.000320,0.008134,9.857207,0.502150,0.081345,-61.250271,0.008950,0.000000
10.990001,2.367546,-61.161308,0.003074,0.000335,0.008507,10.531371,0.536494,0.085073,-61.161308,0.009218,0.000000
11.150001,2.343346,-61.250271,0.003074,0.000343,0.008724,10.423722,0.531010,0.087242,-61.250271,0.009488,0.000000
11.310000,2.438667,-61.205788,0.003096,0.000353,0.008967,10.847733,0.552610,0.089672,-61.205788,0.009748,0.000000
11.470000,2.515381,-61.294750,0.003100,0.000360,0.009149,11.188972,0.569993,0.091492,-61.294750,0.010016,0.000000
11.630000,2.611076,-61.294750,0.003100,0.000368,0.009357,11.614648,0.591678,0.093574,-61.294750,0.010285,0.000000
11.790001,2.693748,-61.250271,0.003109,0.000377,0.009574,11.982391,0.610412,0.095743,-61.250271,0.010554,0.000000
11.950001,2.889244,-61.339233,0.003126,0.000390,0.009895,12.851999,0.654712,0.098949,-61.339233,0.010814,0.000000
12.110001,3.039680,-61.294750,0.003126,0.000401,0.010181,13.521174,0.688801,0.101814,-61.294750,0.011083,0.000000
12.270000,3.077286,-61.294750,0.003165,0.000407,0.010337,13.688451,0.697323,0.103373,-61.294750,0.011352,0.000000
12.430000,3.257141,-61.383713,0.003156,0.000419,0.010632,14.488487,0.738079,0.106321,-61.383713,0.011621,0.000000
12.590000,3.477959,-61.294750,0.003173,0.000433,0.011005,15.470733,0.788117,0.110050,-61.294750,0.011881,0.000000
12.750001,3.552811,-61.339233,0.003182,0.000445,0.011300,15.803691,0.805078,0.112998,-61.339233,0.012150,0.000000
12.910001,3.684631,-61.294750,0.003178,0.000455,0.011560,16.390059,0.834949,0.115602,-61.294750,0.012419,0.000000
13.070001,3.804535,-61.294750,0.003191,0.000465,0.011820,16.923416,0.862120,0.118202,-61.294750,0.012687,0.000000
13.230000,3.963165,-61.339233,0.003195,0.000477,0.012106,17.629040,0.898066,0.121064,-61.339233,0.012948,0.000000
13.390000,4.003380,-61.294750,0.003203,0.000484,0.012306,17.807922,0.907179,0.123058,-61.294750,0.013216,0.000000
13.550000,4.089394,-61.383713,0.003212,0.000493,0.012514,18.190531,0.926670,0.125140,-61.383713,0.013485,0.000000
13.710001,4.416710,-61.339233,0.003234,0.000507,0.012887,19.646507,1.000841,0.128868,-61.339233,0.013754,0.000000
13.870001,4.587631,-61.383713,0.003251,0.000517,0.013130,20.406803,1.039572,0.131298,-61.383713,0.014014,0.000000
14.030001,4.771957,-61.383713,0.003251,0.000529,0.013433,21.226727,1.081341,0.134333,-61.383713,0.014283,0.000000
14.190001,4.913460,-61.383713,0.003260,0.000536,0.013607,21.856161,1.113406,0.136067,-61.383713,0.014552,0.000000
14.350000,5.065758,-61.339233,0.003272,0.000547,0.013884,22.533615,1.147917,0.138841,-61.339233,0.014821,0.000000
14.510000,5.371849,-61.339233,0.003272,0.000561,0.014257,23.895178,1.217278,0.142573,-61.339233,0.015081,0.000000
14.670001,5.527130,-61.428192,0.003285,0.000572,0.014517,24.585903,1.252466,0.145173,-61.428192,0.015350,0.000000
14.830001,5.642563,-61.383713,0.003285,0.000579,0.014708,25.099373,1.278623,0.147081,-61.383713,0.015619,0.000000
14.990001,5.935989,-61.294750,0.003303,0.000593,0.015072,26.404600,1.345114,0.150722,-61.294750,0.015887,0.000000
15.150001,6.064087,-61.428192,0.003316,0.000603,0.015315,26.974405,1.374142,0.153152,-61.428192,0.016148,0.000000
15.310000,6.211548,-61.339233,0.003324,0.000611,0.015532,27.630344,1.407557,0.155321,-61.339233,0.016417,0.000000
15.470000,6.431618,-61.428192,0.003333,0.000622,0.015792,28.609264,1.457425,0.157921,-61.428192,0.016685,0.000000
15.630001,6.642754,-61.383713,0.003346,0.000635,0.016122,29.548443,1.505270,0.161218,-61.383713,0.016954,0.000000
15.790001,6.907509,-61.383713,0.003346,0.000644,0.016347,30.726133,1.565264,0.163473,-61.383713,0.017214,0.000000
15.950001,7.086624,-61.428192,0.003354,0.000653,0.016581,31.522879,1.605852,0.165812,-61.428192,0.017483,0.000000
16.110001,7.337227,-61.383713,0.003376,0.000663,0.016842,32.637615,1.662639,0.168416,-61.383713,0.017752,0.000000
16.270000,7.409843,-61.428192,0.003380,0.000670,0.017015,32.960629,1.679095,0.170150,-61.428192,0.018021,0.000000
16.430000,7.992981,-61.472675,0.003385,0.000689,0.017509,35.554554,1.811235,0.175093,-61.472675,0.018281,0.000000
16.590000,8.130386,-61.428192,0.003402,0.000701,0.017813,36.165764,1.842372,0.178129,-61.428192,0.018550,0.000000
16.750000,8.373543,-61.428192,0.003415,0.000713,0.018099,37.247379,1.897472,0.180990,-61.428192,0.018819,0.000000
16.910002,8.450249,-61.428192,0.003415,0.000718,0.018229,37.588585,1.914854,0.182292,-61.428192,0.019088,0.000000
17.070002,8.663620,-61.517155,0.003445,0.000728,0.018489,38.537708,1.963204,0.184892,-61.517155,0.019348,0.000000
17.230001,8.861351,-61.472675,0.003436,0.000737,0.018723,39.417259,2.008011,0.187235,-61.472675,0.019617,0.000000
17.390001,9.220314,-61.428192,0.003454,0.000750,0.019061,41.014004,2.089353,0.190615,-61.428192,0.019885,0.000000
17.550001,9.488052,-61.472675,0.003458,0.000763,0.019374,42.204964,2.150023,0.193737,-61.472675,0.020154,0.000000
17.710001,9.729721,-61.472675,0.003458,0.000773,0.019634,43.279961,2.204786,0.196341,-61.472675,0.020415,0.000000
17.870001,9.950539,-61.517155,0.003484,0.000784,0.019912,44.262207,2.254824,0.199116,-61.517155,0.020683,0.000000
18.030001,10.045868,-61.517155,0.003484,0.000789,0.020033,44.686253,2.276426,0.200331,-61.517155,0.020952,0.000000
18.190001,10.286423,-61.472675,0.003497,0.000799,0.020293,45.756294,2.330937,0.202931,-61.472675,0.021221,0.000000
18.350000,10.830460,-61.561638,0.003505,0.000814,0.020683,48.176289,2.454217,0.206833,-61.561638,0.021481,0.000000
18.510000,11.059090,-61.561638,0.003510,0.000827,0.020996,49.193287,2.506026,0.209956,-61.561638,0.021750,0.000000
18.670000,11.210648,-61.606117,0.003531,0.000835,0.021221,49.867451,2.540369,0.212211,-61.606117,0.022019,0.000000
18.830002,11.449715,-61.517155,0.003535,0.000846,0.021499,50.930874,2.594542,0.214986,-61.517155,0.022288,0.000000
18.990002,11.691010,-61.561638,0.003540,0.000856,0.021750,52.004208,2.649221,0.217499,-61.561638,0.022548,0.000000
19.150002,11.834373,-61.561638,0.003544,0.000864,0.021941,52.641922,2.681707,0.219407,-61.561638,0.022817,0.000000
19.310001,12.157593,-61.517155,0.003544,0.000876,0.022262,54.079674,2.754950,0.222616,-61.517155,0.023086,0.000000
19.470001,12.506508,-61.606117,0.003570,0.000887,0.022522,55.631725,2.834015,0.225216,-61.606117,0.023354,0.000000
19.630001,12.763443,-61.472675,0.003561,0.000898,0.022817,56.774632,2.892238,0.228169,-61.472675,0.023614,0.000000
19.790001,13.051659,-61.561638,0.003579,0.000909,0.023086,58.056679,2.957548,0.230856,-61.561638,0.023883,0.000000
19.950001,13.160759,-61.561638,0.003579,0.000916,0.023276,58.541981,2.982270,0.232763,-61.561638,0.024152,0.000000
20.110001,13.127625,-61.561638,0.003591,0.000922,0.023415,58.394588,2.974762,0.234149,-61.561638,0.024421,0.000000
20.270000,13.730492,-61.606117,0.003609,0.000936,0.023779,61.076279,3.111374,0.237794,-61.606117,0.024681,0.000000
20.430000,14.269318,-61.561638,0.003609,0.000952,0.024178,63.473095,3.233474,0.241783,-61.561638,0.024950,0.000000
20.590000,14.513222,-61.606117,0.003635,0.000964,0.024482,64.558037,3.288743,0.244818,-61.606117,0.025219,0.000000
20.750002,14.699409,-61.606117,0.003643,0.000975,0.024759,65.386238,3.330934,0.247593,-61.606117,0.025488,0.000000
20.910002,14.827499,-61.561638,0.003635,0.000982,0.024950,65.956009,3.359960,0.249500,-61.561638,0.025748,0.000000
21.070002,14.963043,-61.650597,0.003656,0.000990,0.025141,66.558937,3.390674,0.251408,-61.650597,0.026017,0.000000
21.230001,15.207695,-61.561638,0.003652,0.000999,0.025375,67.647209,3.446113,0.253751,-61.561638,0.026286,0.000000
21.390001,15.737579,-61.650597,0.003669,0.001013,0.025722,70.004250,3.566186,0.257218,-61.650597,0.026554,0.000000
21.550001,16.049629,-61.695080,0.003682,0.001025,0.026025,71.392319,3.636898,0.260253,-61.695080,0.026814,0.000000
21.710001,16.335983,-61.606117,0.003695,0.001036,0.026303,72.666084,3.701787,0.263027,-61.606117,0.027084,0.000000
21.870001,16.460358,-61.650597,0.003708,0.001042,0.026476,73.219330,3.729970,0.264765,-61.650597,0.027352,0.000000
22.030001,16.271561,-61.650597,0.003695,0.001044,0.026511,72.379517,3.687188,0.265109,-61.650597,0.027621,0.000000
22.190001,17.034554,-61.650597,0.003712,0.001063,0.026988,75.773476,3.860085,0.269882,-61.650597,0.027881,0.000000
22.350000,17.481773,-61.650597,0.003717,0.001075,0.027300,77.762810,3.961426,0.273001,-61.650597,0.028150,0.000000
22.510000,17.722694,-61.650597,0.003729,0.001085,0.027560,78.834480,4.016020,0.275605,-61.650597,0.028419,0.000000
22.670002,18.118904,-61.739559,0.003738,0.001099,0.027916,80.596909,4.105803,0.279159,-61.739559,0.028688,0.000000
22.830002,18.298386,-61.650597,0.003747,0.001108,0.028141,81.395287,4.146473,0.281415,-61.650597,0.028948,0.000000
22.990002,18.436539,-61.650597,0.003755,0.001115,0.028332,82.009819,4.177780,0.283322,-61.650597,0.029217,0.000000
23.150002,18.666664,-61.695080,0.003764,0.001124,0.028549,83.033470,4.229927,0.285491,-61.695080,0.029485,0.000000
23.310001,18.912430,-61.695080,0.003768,0.001135,0.028827,84.126686,4.285618,0.288265,-61.695080,0.029755,0.000000
23.470001,19.782661,-61.695080,0.003781,0.001152,0.029252,87.997673,4.482815,0.292516,-61.695080,0.030015,0.000000
23.630001,19.921928,-61.695080,0.003773,0.001160,0.029460,88.617165,4.514374,0.294597,-61.695080,0.030283,0.000000
23.790001,20.128593,-61.695080,0.003798,0.001168,0.029677,89.536453,4.561204,0.296766,-61.695080,0.030552,0.000000
23.950001,19.993797,-61.739559,0.003794,0.001171,0.029737,88.936852,4.530659,0.297372,-61.739559,0.030821,0.000000
24.110001,21.072189,-61.695080,0.003816,0.001193,0.030309,93.733780,4.775027,0.303094,-61.695080,0.031081,0.000000
24.270000,21.528717,-61.739559,0.003824,0.001206,0.030630,95.764519,4.878477,0.306304,-61.739559,0.031350,0.000000
24.430000,21.818794,-61.739559,0.003820,0.001217,0.030908,97.054848,4.944210,0.309078,-61.739559,0.031619,0.000000
24.590002,22.068283,-61.739559,0.003837,0.001227,0.031168,98.164627,5.000744,0.311682,-61.739559,0.031888,0.000000
24.750002,22.041473,-61.784042,0.003837,0.001233,0.031324,98.045372,4.994669,0.313242,-61.784042,0.032148,0.000000
24.910002,22.376984,-61.695080,0.003859,0.001243,0.031567,99.537796,5.070697,0.315672,-61.695080,0.032417,0.000000
25.070002,22.744888,-61.784042,0.003859,0.001252,0.031801,101.174316,5.154065,0.318011,-61.784042,0.032686,0.000000
25.230001,22.971291,-61.739559,0.003872,0.001260,0.032009,102.181404,5.205369,0.320092,-61.739559,0.032955,0.000000
25.390001,24.021751,-61.784042,0.003885,0.001279,0.032486,106.854088,5.443407,0.324861,-61.784042,0.033215,0.000000
25.550001,24.065315,-61.784042,0.003876,0.001286,0.032660,107.047867,5.453279,0.326599,-61.784042,0.033483,0.000000
25.710001,24.164742,-61.828522,0.003898,0.001292,0.032807,107.490135,5.475809,0.328071,-61.828522,0.033753,0.000000
25.870001,24.670799,-61.828522,0.003893,0.001305,0.033145,109.741196,5.590483,0.331455,-61.828522,0.034021,0.000000
26.030001,25.189880,-61.784042,0.003902,0.001314,0.033388,112.050186,5.708108,0.333881,-61.784042,0.034281,0.000000
26.190001,25.916382,-61.873001,0.003911,0.001331,0.033796,115.281822,5.872736,0.337957,-61.873001,0.034550,0.000000
26.350000,26.223587,-61.828522,0.003915,0.001340,0.034030,116.648338,5.942350,0.340300,-61.828522,0.034819,0.000000
26.510002,26.581436,-61.784042,0.003928,0.001350,0.034299,118.240135,6.023439,0.342987,-61.784042,0.035088,0.000000
26.670002,26.877472,-61.873001,0.003949,0.001359,0.034516,119.556969,6.090522,0.345156,-61.873001,0.035348,0.000000
26.830002,27.165688,-61.828522,0.003932,0.001369,0.034767,120.839012,6.155833,0.347669,-61.828522,0.035617,0.000000
26.990002,27.230484,-61.828522,0.003954,0.001373,0.034880,121.127243,6.170516,0.348797,-61.828522,0.035886,0.000000
27.150002,27.434174,-61.828522,0.003949,0.001381,0.035070,122.033302,6.216672,0.350705,-61.828522,0.036154,0.000000
27.310001,27.595779,-61.828522,0.003954,0.001384,0.035166,122.752159,6.253293,0.351658,-61.828522,0.036415,0.000000
27.470001,29.423759,-61.917484,0.003971,0.001413,0.035886,130.883423,6.667519,0.358857,-61.917484,0.036684,0.000000
27.630001,29.608826,-61.828522,0.003971,0.001422,0.036111,131.706635,6.709455,0.361113,-61.828522,0.036952,0.000000
27.790001,30.116745,-61.873001,0.003992,0.001432,0.036380,133.965973,6.824552,0.363800,-61.873001,0.037221,0.000000
27.950001,30.143181,-61.873001,0.003975,0.001437,0.036510,134.083572,6.830543,0.365102,-61.873001,0.037481,0.000000
28.110001,31.064430,-61.873001,0.003988,0.001454,0.036944,138.181488,7.039301,0.369436,-61.873001,0.037750,0.000000
28.270000,31.739914,-61.917484,0.004005,0.001467,0.037273,141.186188,7.192367,0.372733,-61.917484,0.038019,0.000000
28.430002,32.110428,-61.873001,0.004005,0.001477,0.037516,142.834320,7.276327,0.375163,-61.873001,0.038288,0.000000
28.590002,32.452263,-61.917484,0.004018,0.001486,0.037750,144.354874,7.353788,0.377502,-61.917484,0.038548,0.000000
28.750002,32.742340,-61.917484,0.004014,0.001496,0.038002,145.645203,7.419520,0.380019,-61.917484,0.038817,0.000000
28.910002,32.891289,-61.917484,0.004023,0.001500,0.038106,146.307755,7.453273,0.381059,-61.917484,0.039086,0.000000
29.070002,33.254356,-61.917484,0.004040,0.001508,0.038314,147.922760,7.535545,0.383141,-61.917484,0.039355,0.000000
29.230001,33.539589,-61.873001,0.004044,0.001518,0.038565,149.191544,7.600180,0.385654,-61.873001,0.039615,0.000000
29.390001,34.876778,-61.961964,0.004044,0.001536,0.039025,155.139648,7.903191,0.390253,-61.961964,0.039884,0.000000
29.550001,35.299423,-62.050926,0.004044,0.001545,0.039233,157.019684,7.998964,0.392331,-62.050926,0.040152,0.000000
29.710001,35.645355,-61.917484,0.004053,0.001551,0.039398,158.558456,8.077353,0.393981,-61.917484,0.040422,0.000000
29.870001,36.053474,-62.006447,0.004061,0.001560,0.039624,160.373871,8.169834,0.396237,-62.006447,0.040682,0.000000
30.030001,36.695450,-61.961964,0.004057,0.001575,0.040005,163.229507,8.315308,0.400052,-61.961964,0.040950,0.000000
30.190001,38.169670,-61.961964,0.004074,0.001592,0.040439,169.787170,8.649371,0.404386,-61.961964,0.041219,0.000000
30.350002,38.653755,-61.917484,0.004074,0.001602,0.040690,171.940491,8.759067,0.406903,-61.917484,0.041488,0.000000
30.510002,38.961708,-61.873001,0.004096,0.001611,0.040916,173.310333,8.828850,0.409158,-61.873001,0.041748,0.000000
30.670002,39.125923,-62.006447,0.004100,0.001619,0.041115,174.040802,8.866061,0.411153,-62.006447,0.042017,0.000000
30.830002,39.874390,-62.006447,0.004092,0.001630,0.041393,177.370148,9.035666,0.413927,-62.006447,0.042286,0.000000
30.990002,40.173035,-62.006447,0.004118,0.001636,0.041557,178.698578,9.103340,0.415574,-62.006447,0.042555,0.000000
31.150002,40.892456,-61.961964,0.004109,0.001647,0.041835,181.898727,9.266363,0.418348,-61.961964,0.042815,0.000000
31.310001,42.069527,-61.873001,0.004118,0.001663,0.042251,187.134598,9.533092,0.422512,-61.873001,0.043084,0.000000
31.470001,42.651917,-62.006447,0.004122,0.001673,0.042494,189.725204,9.665062,0.424942,-62.006447,0.043353,0.000000
31.630001,43.080147,-62.006447,0.004135,0.001682,0.042719,191.630066,9.762100,0.427194,-62.006447,0.043621,0.000000
31.790001,43.589920,-62.006447,0.004135,0.001690,0.042928,193.897644,9.877617,0.429275,-62.006447,0.043882,0.000000
31.950001,44.549896,-62.006447,0.004135,0.001704,0.043275,198.167831,10.095151,0.432746,-62.006447,0.044150,0.000000
32.110001,44.859344,-62.050926,0.004139,0.001712,0.043483,199.544327,10.165273,0.434828,-62.050926,0.044419,0.000000
32.270000,46.179398,-62.050926,0.004152,0.001729,0.043916,205.416214,10.464401,0.439161,-62.050926,0.044688,0.000000
32.430000,46.587891,-62.006447,0.004161,0.001736,0.044099,207.233292,10.556967,0.440986,-62.006447,0.044948,0.000000
32.590000,47.184059,-61.961964,0.004161,0.001747,0.044385,209.885178,10.692060,0.443847,-61.961964,0.045217,0.000000
32.750000,47.802574,-62.095409,0.004165,0.001755,0.044584,212.636475,10.832218,0.445842,-62.095409,0.045486,0.000000
32.910000,48.127655,-62.050926,0.004174,0.001762,0.044749,214.082504,10.905882,0.447488,-62.050926,0.045755,0.000000
33.070000,48.870163,-62.095409,0.004182,0.001773,0.045035,217.385345,11.074137,0.450350,-62.095409,0.046015,0.000000
33.230003,49.471916,-62.050926,0.004182,0.001784,0.045321,220.062073,11.210497,0.453211,-62.050926,0.046284,0.000000
33.390003,50.411041,-62.095409,0.004178,0.001794,0.045573,224.239517,11.423306,0.455728,-62.095409,0.046553,0.000000
33.550003,51.096954,-62.050926,0.004186,0.001805,0.045842,227.290604,11.578735,0.458415,-62.050926,0.046821,0.000000
33.710003,51.490547,-62.095409,0.004195,0.001811,0.045997,229.041397,11.667924,0.459974,-62.095409,0.047082,0.000000
33.870003,52.039055,-62.139889,0.004199,0.001818,0.046189,231.481277,11.792218,0.461886,-62.139889,0.047351,0.000000
34.030003,53.753830,-62.095409,0.004199,0.001840,0.046735,239.108978,12.180792,0.467347,-62.095409,0.047619,0.000000
34.190002,54.333244,-62.139889,0.004208,0.001849,0.046960,241.686340,12.312089,0.469603,-62.139889,0.047888,0.000000
34.350002,54.916374,-62.095409,0.004204,0.001856,0.047142,244.280228,12.444228,0.471424,-62.095409,0.048157,0.000000
34.510002,55.850288,-62.095409,0.004208,0.001872,0.047541,248.434494,12.655856,0.475413,-62.095409,0.048417,0.000000
34.670002,56.593170,-62.095409,0.004221,0.001879,0.047732,251.738998,12.824195,0.477321,-62.095409,0.048686,0.000000
34.830002,57.241470,-62.139889,0.004221,0.001888,0.047949,254.622772,12.971102,0.479489,-62.139889,0.048955,0.000000
34.990002,58.034248,-62.139889,0.004230,0.001900,0.048261,258.149231,13.150748,0.482612,-62.139889,0.049224,0.000000
35.150002,58.969650,-62.095409,0.004230,0.001910,0.048521,262.310120,13.362714,0.485212,-62.095409,0.049484,0.000000
35.310001,59.662636,-62.095409,0.004243,0.001920,0.048773,265.392670,13.519746,0.487729,-62.095409,0.049753,0.000000
35.470001,60.270721,-62.228851,0.004247,0.001928,0.048981,268.097565,13.657541,0.489807,-62.228851,0.050022,0.000000
35.630001,60.944344,-62.095409,0.004251,0.001938,0.049224,271.093994,13.810185,0.492237,-62.095409,0.050290,0.000000
35.790001,62.061462,-62.184368,0.004247,0.001953,0.049605,276.063171,14.063329,0.496052,-62.184368,0.050551,0.000000
35.950001,63.154007,-62.139889,0.004251,0.001966,0.049935,280.923065,14.310903,0.499349,-62.139889,0.050819,0.000000
36.110001,63.702499,-62.139889,0.004260,0.001973,0.050126,283.362885,14.435192,0.501256,-62.139889,0.051088,0.000000
36.270000,64.741791,-62.184368,0.004264,0.001986,0.050438,287.985870,14.670699,0.504379,-62.184368,0.051357,0.000000
36.430000,65.665649,-62.139889,0.004255,0.001996,0.050707,292.095398,14.880049,0.507066,-62.139889,0.051617,0.000000
36.590000,66.179520,-62.184368,0.004273,0.002003,0.050871,294.381195,14.996493,0.508713,-62.184368,0.051886,0.000000
36.750000,67.189407,-62.184368,0.004273,0.002017,0.051227,298.873413,15.225337,0.512270,-62.184368,0.052155,0.000000
36.910000,67.284363,-62.139889,0.004277,0.002011,0.051071,299.295807,15.246855,0.510707,-62.139889,0.051296,0.000000
37.070004,66.991669,-62.228851,0.004286,0.002011,0.051071,297.993835,15.180530,0.510707,-62.228851,0.051296,0.000000
37.230003,66.827454,-62.228851,0.004286,0.002010,0.051045,297.263367,15.143317,0.510450,-62.228851,0.051071,0.000000
37.390003,66.616699,-62.228851,0.004281,0.002009,0.051028,296.325867,15.095559,0.510276,-62.228851,0.051071,0.000000
37.550003,66.440567,-62.228851,0.004281,0.002008,0.051010,295.542389,15.055647,0.510102,-62.228851,0.051071,0.000000
37.710003,66.284164,-62.184368,0.004299,0.002008,0.051010,294.846680,15.020206,0.510102,-62.184368,0.051071,0.000000
37.870003,66.148621,-62.317814,0.004294,0.002008,0.051001,294.243774,14.989492,0.510015,-62.317814,0.051071,0.000000
38.030003,66.024612,-62.228851,0.004290,0.002008,0.051001,293.692139,14.961390,0.510015,-62.228851,0.051071,0.000000
38.190002,65.904343,-62.273331,0.004294,0.002008,0.050993,293.157166,14.934137,0.509928,-62.273331,0.051071,0.000000
38.350002,65.814606,-62.228851,0.004290,0.002008,0.050993,292.757996,14.913802,0.509928,-62.228851,0.051071,0.000000
38.510002,65.730820,-62.273331,0.004299,0.002008,0.050993,292.385284,14.894817,0.509928,-62.273331,0.051071,0.000000
38.670002,65.625061,-62.273331,0.004299,0.002007,0.050984,291.914856,14.870852,0.509840,-62.273331,0.051071,0.000000
38.830002,65.547241,-62.273331,0.004307,0.002007,0.050984,291.568695,14.853217,0.509840,-62.273331,0.051071,0.000000
38.990002,65.491760,-62.317814,0.004290,0.002007,0.050984,291.321899,14.840645,0.509840,-62.317814,0.051071,0.000000
39.150002,65.413559,-62.273331,0.004303,0.002007,0.050984,290.974030,14.822924,0.509840,-62.273331,0.051071,0.000000
39.310001,65.350632,-62.273331,0.004312,0.002007,0.050984,290.694122,14.808664,0.509840,-62.273331,0.051071,0.000000
39.470001,65.295135,-62.317814,0.004303,0.002007,0.050984,290.447266,14.796089,0.509840,-62.317814,0.051071,0.000000
39.630001,65.249710,-62.317814,0.004307,0.002007,0.050984,290.245209,14.785795,0.509840,-62.317814,0.051071,0.000000
39.790001,65.169647,-62.362293,0.004303,0.002007,0.050984,289.889069,14.767653,0.509840,-62.362293,0.051071,0.000000
39.950001,65.126083,-62.317814,0.004299,0.002007,0.050984,289.695282,14.757781,0.509840,-62.317814,0.051071,0.000000
40.110001,65.095184,-62.362293,0.004299,0.002007,0.050975,289.557831,14.750780,0.509753,-62.362293,0.051071,0.000000
40.270000,65.028519,-62.317814,0.004290,0.002007,0.050975,289.261292,14.735673,0.509753,-62.317814,0.051071,0.000000
40.430000,64.987930,-62.317814,0.004307,0.002007,0.050975,289.080750,14.726475,0.509753,-62.317814,0.051071,0.000000
40.590000,64.952927,-62.362293,0.004307,0.002007,0.050975,288.925049,14.718543,0.509753,-62.362293,0.051071,0.000000
40.750004,64.909729,-62.362293,0.004303,0.002007,0.050975,288.732910,14.708755,0.509753,-62.362293,0.051071,0.000000
40.910004,64.872131,-62.273331,0.004307,0.002007,0.050975,288.565643,14.700234,0.509753,-62.273331,0.051071,0.000000
41.070004,64.843826,-62.406773,0.004290,0.002007,0.050975,288.439758,14.693821,0.509753,-62.406773,0.051071,0.000000
41.230003,64.799515,-62.362293,0.004307,0.002007,0.050975,288.242645,14.683780,0.509753,-62.362293,0.051071,0.000000
41.390003,64.754822,-62.406773,0.004303,0.002007,0.050975,288.043823,14.673653,0.509753,-62.406773,0.051071,0.000000
41.550003,64.738815,-62.406773,0.004303,0.002007,0.050975,287.972626,14.670026,0.509753,-62.406773,0.051071,0.000000
41.710003,64.712372,-62.406773,0.004307,0.002007,0.050975,287.855011,14.664033,0.509753,-62.406773,0.051071,0.000000
41.870003,64.682968,-62.451256,0.004294,0.002007,0.050975,287.724213,14.657370,0.509753,-62.451256,0.051071,0.000000
42.030003,64.633057,-62.406773,0.004303,0.002007,0.050975,287.502197,14.646060,0.509753,-62.406773,0.051071,0.000000
42.190002,64.606995,-62.451256,0.004303,0.002007,0.050975,287.386261,14.640154,0.509753,-62.451256,0.051071,0.000000
42.350002,64.597687,-62.406773,0.004303,0.002007,0.050975,287.344849,14.638045,0.509753,-62.406773,0.051071,0.000000
42.510002,64.558212,-62.406773,0.004312,0.002007,0.050975,287.169281,14.629100,0.509753,-62.406773,0.051071,0.000000
42.670002,64.528061,-62.451256,0.004294,0.002007,0.050975,287.035156,14.622268,0.509753,-62.451256,0.051071,0.000000
42.830002,64.518005,-62.451256,0.004303,0.002007,0.050975,286.990417,14.619988,0.509753,-62.451256,0.051071,0.000000
42.990002,64.495651,-62.495735,0.004307,0.002007,0.050975,286.890991,14.614923,0.509753,-62.495735,0.051071,0.000000
43.150002,64.462143,-62.406773,0.004312,0.002007,0.050975,286.741943,14.607330,0.509753,-62.406773,0.051071,0.000000
43.310001,64.439423,-62.451256,0.004303,0.002007,0.050975,286.640869,14.602181,0.509753,-62.451256,0.051071,0.000000
43.470001,64.425659,-62.451256,0.004290,0.002007,0.050975,286.579651,14.599063,0.509753,-62.451256,0.051071,0.000000
43.630001,64.382828,-62.406773,0.004303,0.002007,0.050975,286.389130,14.589357,0.509753,-62.406773,0.051071,0.000000
43.790001,64.377991,-62.451256,0.004307,0.002007,0.050975,286.367615,14.588262,0.509753,-62.451256,0.051071,0.000000
43.950001,64.354904,-62.451256,0.004303,0.002007,0.050975,286.264923,14.583030,0.509753,-62.451256,0.051071,0.000000
44.110001,64.327347,-62.495735,0.004307,0.002007,0.050975,286.142334,14.576785,0.509753,-62.495735,0.051071,0.000000
44.270000,64.303513,-62.495735,0.004290,0.002007,0.050975,286.036316,14.571384,0.509753,-62.495735,0.051071,0.000000
44.430000,64.299423,-62.495735,0.004307,0.002007,0.050975,286.018127,14.570457,0.509753,-62.495735,0.051071,0.000000
44.590004,64.268509,-62.495735,0.004316,0.002007,0.050975,285.880615,14.563452,0.509753,-62.495735,0.051071,0.000000
44.750004,64.249527,-62.451256,0.004303,0.002007,0.050975,285.796173,14.559151,0.509753,-62.451256,0.051071,0.000000
44.910004,64.237610,-62.495735,0.004303,0.002007,0.050975,285.743164,14.556451,0.509753,-62.495735,0.051071,0.000000
45.070004,64.218613,-62.495735,0.004307,0.002007,0.050975,285.658661,14.552146,0.509753,-62.495735,0.051071,0.000000
45.230003,64.194778,-62.495735,0.004299,0.002007,0.050975,285.552643,14.546744,0.509753,-62.495735,0.051071,0.000000
45.390003,64.186218,-62.540218,0.004307,0.002007,0.050975,285.514557,14.544806,0.509753,-62.540218,0.051071,0.000000
45.550003,64.170212,-62.495735,0.004312,0.002007,0.050975,285.443359,14.541178,0.509753,-62.495735,0.051071,0.000000
45.710003,64.156799,-62.540218,0.004324,0.002007,0.050975,285.383698,14.538138,0.509753,-62.540218,0.051071,0.000000
45.870003,64.138184,-62.495735,0.004312,0.002007,0.050975,285.300903,14.533920,0.509753,-62.495735,0.051071,0.000000
46.030003,64.125153,-62.495735,0.004316,0.002007,0.050975,285.242920,14.530968,0.509753,-62.495735,0.051071,0.000000
46.190002,64.106155,-62.584698,0.004290,0.002007,0.050975,285.158417,14.526663,0.509753,-62.584698,0.051071,0.000000
46.350002,64.076370,-62.584698,0.004307,0.002007,0.050975,285.025940,14.519913,0.509753,-62.584698,0.051071,0.000000
46.510002,64.066315,-62.495735,0.004303,0.002007,0.050975,284.981201,14.517634,0.509753,-62.495735,0.051071,0.000000
46.670002,64.065933,-62.540218,0.004307,0.002007,0.050975,284.979492,14.517549,0.509753,-62.540218,0.051071,0.000000
46.830002,64.035034,-62.584698,0.004316,0.002007,0.050975,284.842072,14.510546,0.509753,-62.584698,0.051071,0.000000
46.990002,64.022369,-62.629181,0.004299,0.002007,0.050975,284.785736,14.507676,0.509753,-62.629181,0.051071,0.000000
47.150002,64.032806,-62.584698,0.004307,0.002007,0.050975,284.832153,14.510041,0.509753,-62.584698,0.051071,0.000000
47.310001,64.001892,-62.673660,0.004316,0.002007,0.050975,284.694641,14.503036,0.509753,-62.673660,0.051071,0.000000
47.470001,63.969116,-62.584698,0.004299,0.002007,0.050975,284.548828,14.495609,0.509753,-62.584698,0.051071,0.000000
47.630001,63.964279,-62.629181,0.004303,0.002007,0.050975,284.527313,14.494513,0.509753,-62.629181,0.051071,0.000000
47.790001,63.952744,-62.718140,0.004307,0.002007,0.050975,284.476013,14.491899,0.509753,-62.718140,0.051071,0.000000
47.950001,63.936356,-62.540218,0.004316,0.002007,0.050975,284.403107,14.488185,0.509753,-62.540218,0.051071,0.000000
48.110001,63.929276,-62.629181,0.004316,0.002007,0.050975,284.371613,14.486581,0.509753,-62.629181,0.051071,0.000000
48.270000,63.911774,-62.673660,0.004312,0.002007,0.050975,284.293762,14.482615,0.509753,-62.673660,0.051071,0.000000
48.430004,63.890549,-62.673660,0.004312,0.002007,0.050975,284.199341,14.477805,0.509753,-62.673660,0.051071,0.000000
48.590004,63.899490,-62.673660,0.004307,0.002007,0.050975,284.239136,14.479832,0.509753,-62.673660,0.051071,0.000000
48.750004,63.875290,-62.629181,0.004316,0.002007,0.050975,284.131470,14.474347,0.509753,-62.629181,0.051071,0.000000
48.910004,63.866714,-62.629181,0.004312,0.002007,0.050975,284.093323,14.472404,0.509753,-62.629181,0.051071,0.000000
49.070004,63.858536,-62.673660,0.004312,0.002007,0.050975,284.056946,14.470551,0.509753,-62.673660,0.051071,0.000000
49.230003,63.847733,-62.584698,0.004316,0.002007,0.050975,284.008911,14.468103,0.509753,-62.584698,0.051071,0.000000
49.390003,63.827621,-62.718140,0.004303,0.002007,0.050975,283.919434,14.463546,0.509753,-62.718140,0.051071,0.000000
49.550003,63.813477,-62.673660,0.004303,0.002007,0.050975,283.856506,14.460340,0.509753,-62.673660,0.051071,0.000000
49.710003,63.819809,-62.673660,0.004316,0.002007,0.050975,283.884674,14.461776,0.509753,-62.673660,0.051071,0.000000
49.870003,63.806396,-62.629181,0.004307,0.002007,0.050975,283.825012,14.458736,0.509753,-62.629181,0.051071,0.000000
50.030003,63.787033,-62.673660,0.004312,0.002007,0.050975,283.738892,14.454349,0.509753,-62.673660,0.051071,0.000000
50.190002,63.775482,-62.718140,0.004307,0.002007,0.050975,283.687500,14.451731,0.509753,-62.718140,0.051071,0.000000
50.350002,63.773621,-62.673660,0.004312,0.002007,0.050975,283.679230,14.451309,0.509753,-62.673660,0.051071,0.000000
50.510002,63.747192,-62.718140,0.004299,0.002007,0.050975,283.561676,14.445320,0.509753,-62.718140,0.051071,0.000000
50.670002,63.736023,-62.762623,0.004312,0.002007,0.050975,283.511993,14.442789,0.509753,-62.762623,0.051071,0.000000
50.830002,63.737885,-62.673660,0.004307,0.002007,0.050975,283.520264,14.443212,0.509753,-62.673660,0.051071,0.000000
50.990002,63.722992,-62.762623,0.004312,0.002007,0.050975,283.454010,14.439837,0.509753,-62.762623,0.051071,0.000000
51.150002,63.715530,-62.718140,0.004303,0.002007,0.050975,283.420837,14.438146,0.509753,-62.718140,0.051071,0.000000
51.310001,63.705490,-62.718140,0.004312,0.002007,0.050975,283.376160,14.435870,0.509753,-62.718140,0.051071,0.000000
51.470001,63.693192,-62.718140,0.004307,0.002007,0.050975,283.321472,14.433084,0.509753,-62.718140,0.051071,0.000000
51.630001,63.673080,-62.807102,0.004320,0.002007,0.050975,283.231995,14.428526,0.509753,-62.807102,0.051071,0.000000
51.790001,63.672348,-62.762623,0.004299,0.002007,0.050975,283.228760,14.428361,0.509753,-62.762623,0.051071,0.000000
51.950001,63.661911,-62.762623,0.004316,0.002007,0.050975,283.182312,14.425995,0.509753,-62.762623,0.051071,0.000000
52.110001,63.649261,-62.807102,0.004316,0.002007,0.050975,283.126068,14.423129,0.509753,-62.807102,0.051071,0.000000
52.270004,63.650742,-62.718140,0.004307,0.002007,0.050975,283.132629,14.423464,0.509753,-62.718140,0.051071,0.000000
52.430004,63.632126,-62.718140,0.004299,0.002007,0.050975,283.049835,14.419246,0.509753,-62.718140,0.051071,0.000000
52.590004,63.625046,-62.807102,0.004316,0.002007,0.050975,283.018341,14.417641,0.509753,-62.807102,0.051071,0.000000
52.750004,63.610535,-62.718140,0.004303,0.002007,0.050975,282.953796,14.414352,0.509753,-62.718140,0.051071,0.000000
52.910004,63.600479,-62.851585,0.004312,0.002007,0.050975,282.909058,14.412075,0.509753,-62.851585,0.051071,0.000000
53.070004,63.597122,-62.762623,0.004307,0.002007,0.050975,282.894135,14.411313,0.509753,-62.762623,0.051071,0.000000
53.230003,63.585587,-62.807102,0.004320,0.002007,0.050975,282.842804,14.408700,0.509753,-62.807102,0.051071,0.000000
53.390003,63.585205,-62.851585,0.004312,0.002007,0.050975,282.841125,14.408613,0.509753,-62.851585,0.051071,0.000000
53.550003,63.564362,-62.851585,0.004316,0.002007,0.050975,282.748413,14.403890,0.509753,-62.851585,0.051071,0.000000
53.710003,63.558029,-62.896065,0.004316,0.002007,0.050975,282.720245,14.402455,0.509753,-62.896065,0.051071,0.000000
53.870003,63.563232,-62.807102,0.004316,0.002007,0.050975,282.743378,14.403634,0.509753,-62.807102,0.051071,0.000000
54.030003,63.544250,-62.851585,0.004320,0.002007,0.050975,282.658936,14.399333,0.509753,-62.851585,0.051071,0.000000
54.190002,63.537170,-62.851585,0.004303,0.002007,0.050975,282.627441,14.397729,0.509753,-62.851585,0.051071,0.000000
54.350002,63.559891,-62.851585,0.004312,0.002007,0.050975,282.728516,14.402877,0.509753,-62.851585,0.051071,0.000000
54.510002,63.514832,-62.851585,0.004316,0.002007,0.050975,282.528076,14.392666,0.509753,-62.851585,0.051071,0.000000
54.670002,63.510727,-62.851585,0.004312,0.002007,0.050967,282.509827,14.391737,0.509666,-62.851585,0.051071,0.000000
54.830002,63.514832,-62.851585,0.004312,0.002007,0.050967,282.528076,14.392666,0.509666,-62.851585,0.051071,0.000000
54.990002,63.488022,-62.896065,0.004307,0.002007,0.050967,282.408813,14.386591,0.509666,-62.896065,0.051071,0.000000
55.150002,63.493607,-62.807102,0.004312,0.002007,0.050967,282.433655,14.387856,0.509666,-62.807102,0.051071,0.000000
55.310001,63.493973,-62.896065,0.004312,0.002007,0.050967,282.435303,14.387940,0.509666,-62.896065,0.051071,0.000000
55.470001,63.477585,-62.940544,0.004316,0.002007,0.050967,282.362396,14.384226,0.509666,-62.940544,0.051071,0.000000
55.630001,63.457108,-62.896065,0.004320,0.002007,0.050967,282.271301,14.379586,0.509666,-62.896065,0.051071,0.000000
55.790001,63.460831,-62.896065,0.004312,0.002007,0.050967,282.287872,14.380429,0.509666,-62.896065,0.051071,0.000000
55.950001,63.455627,-62.940544,0.004316,0.002007,0.050967,282.264740,14.379251,0.509666,-62.940544,0.051071,0.000000
56.110004,63.437744,-62.940544,0.004307,0.002007,0.050967,282.185181,14.375198,0.509666,-62.940544,0.051071,0.000000
56.270004,63.440720,-62.940544,0.004307,0.002007,0.050967,282.198425,14.375873,0.509666,-62.940544,0.051071,0.000000
56.430004,63.438492,-62.851585,0.004316,0.002007,0.050967,282.188507,14.375367,0.509666,-62.851585,0.051071,0.000000
56.590004,63.418015,-62.940544,0.004312,0.002007,0.050967,282.097412,14.370728,0.509666,-62.940544,0.051071,0.000000
56.750004,63.415405,-62.896065,0.004320,0.002007,0.050967,282.085815,14.370136,0.509666,-62.896065,0.051071,0.000000
56.910004,63.420242,-62.985027,0.004303,0.002007,0.050967,282.107330,14.371232,0.509666,-62.985027,0.051071,0.000000
57.070004,63.384125,-62.940544,0.004320,0.002007,0.050967,281.946655,14.363048,0.509666,-62.940544,0.051071,0.000000
57.230003,63.403854,-62.940544,0.004320,0.002007,0.050967,282.034424,14.367518,0.509666,-62.940544,0.051071,0.000000
57.390003,63.395676,-62.985027,0.004312,0.002007,0.050967,281.998047,14.365665,0.509666,-62.985027,0.051071,0.000000
57.550003,63.375931,-62.985027,0.004312,0.002007,0.050967,281.910217,14.361192,0.509666,-62.985027,0.051071,0.000000
57.710003,63.356567,-63.029507,0.004312,0.002007,0.050967,281.824097,14.356803,0.509666,-63.029507,0.051071,0.000000
57.870003,63.381897,-62.896065,0.004303,0.002007,0.050967,281.936768,14.362543,0.509666,-62.896065,0.051071,0.000000
58.030003,63.369232,-62.985027,0.004316,0.002007,0.050967,281.880432,14.359674,0.509666,-62.985027,0.051071,0.000000
58.190002,63.350983,-62.985027,0.004303,0.002007,0.050967,281.799255,14.355537,0.509666,-62.985027,0.051071,0.000000
58.350002,63.352844,-62.985027,0.004307,0.002007,0.050967,281.807526,14.355960,0.509666,-62.985027,0.051071,0.000000
58.510002,63.334595,-63.029507,0.004316,0.002007,0.050967,281.726349,14.351825,0.509666,-63.029507,0.051071,0.000000
58.670002,63.339447,-62.985027,0.004303,0.002007,0.050967,281.747925,14.352923,0.509666,-62.985027,0.051071,0.000000
58.830002,63.332001,-62.985027,0.004303,0.002007,0.050967,281.714813,14.351237,0.509666,-62.985027,0.051071,0.000000
58.990002,63.333115,-63.029507,0.004299,0.002007,0.050967,281.719757,14.351489,0.509666,-63.029507,0.051071,0.000000
59.150002,63.320816,-63.029507,0.004307,0.002007,0.050967,281.665070,14.348702,0.509666,-63.029507,0.051071,0.000000
59.310001,63.322678,-63.073990,0.004316,0.002007,0.050967,281.673340,14.349124,0.509666,-63.073990,0.051071,0.000000
59.470001,63.310776,-62.985027,0.004312,0.002007,0.050967,281.620392,14.346427,0.509666,-62.985027,0.051071,0.000000
59.630001,63.309647,-63.029507,0.004303,0.002007,0.050967,281.615387,14.346171,0.509666,-63.029507,0.051071,0.000000
59.790005,63.301834,-63.029507,0.004316,0.002007,0.050967,281.580627,14.344401,0.509666,-63.029507,0.051071,0.000000
59.950005,63.295502,-63.029507,0.004324,0.002007,0.050967,281.552460,14.342966,0.509666,-63.029507,0.051071,0.000000
60.110004,63.278366,-63.073990,0.004312,0.002007,0.050967,281.476227,14.339083,0.509666,-63.073990,0.051071,0.000000
60.270004,63.287308,-63.073990,0.004316,0.002007,0.050967,281.515991,14.341109,0.509666,-63.073990,0.051071,0.000000
60.430004,63.285080,-63.029507,0.004307,0.002007,0.050967,281.506104,14.340604,0.509666,-63.029507,0.051071,0.000000
60.590004,63.259384,-63.118469,0.004316,0.002007,0.050967,281.391785,14.334782,0.509666,-63.118469,0.051071,0.000000
60.750004,63.264221,-63.029507,0.004312,0.002007,0.050967,281.413300,14.335877,0.509666,-63.029507,0.051071,0.000000
60.910004,63.266830,-63.162949,0.004307,0.002007,0.050967,281.424927,14.336469,0.509666,-63.162949,0.051071,0.000000
61.070004,63.259750,-63.073990,0.004307,0.002007,0.050967,281.393433,14.334865,0.509666,-63.073990,0.051071,0.000000
61.230003,63.250443,-63.073990,0.004316,0.002007,0.050967,281.352020,14.332755,0.509666,-63.073990,0.051071,0.000000
61.390003,63.259003,-63.118469,0.004320,0.002007,0.050967,281.390106,14.334696,0.509666,-63.118469,0.051071,0.000000
61.550003,63.229218,-63.162949,0.004316,0.002007,0.050967,281.257599,14.327946,0.509666,-63.162949,0.051071,0.000000
61.710003,63.221771,-63.118469,0.004316,0.002007,0.050967,281.224487,14.326258,0.509666,-63.118469,0.051071,0.000000
61.870003,63.234802,-63.118469,0.004320,0.002007,0.050967,281.282440,14.329211,0.509666,-63.118469,0.051071,0.000000
62.030003,63.225494,-63.162949,0.004307,0.002007,0.050967,281.241058,14.327102,0.509666,-63.162949,0.051071,0.000000
62.190002,63.213577,-63.162949,0.004307,0.002007,0.050967,281.188049,14.324401,0.509666,-63.162949,0.051071,0.000000
62.350002,63.218414,-63.118469,0.004303,0.002007,0.050967,281.209564,14.325497,0.509666,-63.118469,0.051071,0.000000
62.510002,63.225494,-63.162949,0.004303,0.002007,0.050967,281.241058,14.327102,0.509666,-63.162949,0.051071,0.000000
62.670002,63.203522,-63.118469,0.004312,0.002007,0.050967,281.143311,14.322123,0.509666,-63.118469,0.051071,0.000000
62.830002,63.196457,-63.118469,0.004312,0.002007,0.050967,281.111877,14.320522,0.509666,-63.118469,0.051071,0.000000
62.990002,63.202774,-63.162949,0.004299,0.002007,0.050967,281.139984,14.321953,0.509666,-63.162949,0.051071,0.000000
63.150002,63.194214,-63.162949,0.004312,0.002007,0.050967,281.101898,14.320014,0.509666,-63.162949,0.051071,0.000000
63.310001,63.184540,-63.207432,0.004299,0.002007,0.050967,281.058868,14.317822,0.509666,-63.207432,0.051071,0.000000
63.470001,63.194214,-63.207432,0.004316,0.002007,0.050967,281.101898,14.320014,0.509666,-63.207432,0.051071,0.000000
63.630005,63.182678,-63.162949,0.004316,0.002007,0.050967,281.050598,14.317400,0.509666,-63.162949,0.051071,0.000000
63.790005,63.159210,-63.207432,0.004316,0.002007,0.050967,280.946198,14.312082,0.509666,-63.207432,0.051071,0.000000
63.950005,63.180435,-63.207432,0.004320,0.002007,0.050967,281.040619,14.316892,0.509666,-63.207432,0.051071,0.000000
64.110001,63.161453,-63.207432,0.004312,0.002007,0.050967,280.956177,14.312590,0.509666,-63.207432,0.051071,0.000000
64.270004,63.145813,-63.162949,0.004312,0.002007,0.050967,280.886597,14.309046,0.509666,-63.162949,0.051071,0.000000
64.430000,63.151016,-63.207432,0.004316,0.002007,0.050967,280.909760,14.310225,0.509666,-63.207432,0.051071,0.000000
64.590004,63.143951,-63.251911,0.004312,0.002007,0.050967,280.878326,14.308623,0.509666,-63.251911,0.051071,0.000000
64.750000,63.123093,-63.251911,0.004329,0.002007,0.050967,280.785553,14.303898,0.509666,-63.251911,0.051071,0.000000
64.910004,63.137619,-63.207432,0.004324,0.002007,0.050967,280.850159,14.307189,0.509666,-63.207432,0.051071,0.000000
65.070000,63.136871,-63.251911,0.004324,0.002007,0.050967,280.846832,14.307019,0.509666,-63.251911,0.051071,0.000000
65.230003,63.122345,-63.251911,0.004316,0.002007,0.050967,280.782227,14.303728,0.509666,-63.251911,0.051071,0.000000
65.389999,63.123459,-63.251911,0.004312,0.002007,0.050967,280.787170,14.303981,0.509666,-63.251911,0.051071,0.000000
65.550003,63.115280,-63.207432,0.004320,0.002007,0.050967,280.750793,14.302127,0.509666,-63.207432,0.051071,0.000000
65.710007,63.100372,-63.296394,0.004320,0.002007,0.050967,280.684479,14.298748,0.509666,-63.296394,0.051071,0.000000
65.870003,63.107819,-63.207432,0.004312,0.002007,0.050967,280.717590,14.300436,0.509666,-63.207432,0.051071,0.000000
66.030006,63.094788,-63.340874,0.004316,0.002007,0.050967,280.659637,14.297482,0.509666,-63.340874,0.051071,0.000000
66.190002,63.090317,-63.296394,0.004303,0.002007,0.050967,280.639740,14.296470,0.509666,-63.296394,0.051071,0.000000
66.350006,63.095917,-63.296394,0.004307,0.002007,0.050967,280.664642,14.297739,0.509666,-63.296394,0.051071,0.000000
66.510002,63.068726,-63.340874,0.004320,0.002007,0.050967,280.543701,14.291577,0.509666,-63.340874,0.051071,0.000000
66.670006,63.076553,-63.340874,0.004316,0.002007,0.050967,280.578522,14.293351,0.509666,-63.340874,0.051071,0.000000
66.830002,63.076553,-63.340874,0.004312,0.002007,0.050967,280.578522,14.293351,0.509666,-63.340874,0.051071,0.000000
66.990005,63.063141,-63.296394,0.004312,0.002007,0.050967,280.518860,14.290312,0.509666,-63.296394,0.051071,0.000000
67.150002,63.062027,-63.340874,0.004320,0.002007,0.050967,280.513916,14.290059,0.509666,-63.340874,0.051071,0.000000
67.300003,63.053833,-63.296394,0.004320,0.002007,0.050967,280.477448,14.288203,0.509666,-63.296394,0.051071,0.000000