File: Data/compression 36/Heating-17-36-reverse-1-2_11202024_172428(in).csv
Time (sec),S:Load (lbs),S:HL1 (DIM),S:LVDT (in),S:Position (in),Ch:Position (mm),Ch:Load (N),Ch:Stress (MPa),Ch:Strain (mm/mm),Ch:HL1 (DIM),Set Point (),Cycles ()
0.11,-0.106499,-1280.072754,-0.013655,-0.008453,-0.214706,-0.47373,-0.024133,-2.147065,-1280.072754,-0.21442,0
0.46,-0.04171,-1280.11731,-0.013624,-0.008428,-0.214066,-0.185535,-0.009452,-2.140661,-1280.11731,-0.213311,0
0.81,-0.132568,-1280.02832,-0.013542,-0.008222,-0.208828,-0.589693,-0.03004,-2.088278,-1280.02832,-0.207483,0
1.16,-0.080063,-1280.072754,-0.013327,-0.007991,-0.202964,-0.356137,-0.018143,-2.029642,-1280.072754,-0.201638,0
1.51,-0.03389,-1280.072754,-0.013073,-0.007763,-0.197172,-0.150749,-0.00768,-1.971718,-1280.072754,-0.195811,0
1.86,-0.013031,-1280.072754,-0.01284,-0.007531,-0.191284,-0.057965,-0.002953,-1.91284,-1280.072754,-0.189982,0
2.21,-0.047295,-1280.11731,-0.012594,-0.00731,-0.185672,-0.210377,-0.010717,-1.856718,-1280.11731,-0.184155,0
2.56,-0.079315,-1280.02832,-0.012365,-0.007082,-0.179888,-0.352812,-0.017973,-1.798885,-1280.02832,-0.178328,0
2.91,-0.078575,-1280.072754,-0.01212,-0.006844,-0.173827,-0.34952,-0.017805,-1.738266,-1280.072754,-0.172499,0
3.26,-0.07634,-1280.072754,-0.01187,-0.006615,-0.168033,-0.339576,-0.017299,-1.680327,-1280.072754,-0.166653,0
3.61,-0.013405,-1279.983887,-0.011641,-0.006383,-0.162136,-0.059628,-0.003038,-1.621358,-1279.983887,-0.160826,0
3.96,-0.037239,-1280.072754,-0.011417,-0.006157,-0.156395,-0.165648,-0.008438,-1.563949,-1280.072754,-0.154999,0
4.31,-0.033516,-1280.02832,-0.01118,-0.00593,-0.150628,-0.149086,-0.007595,-1.506282,-1280.02832,-0.14917,0
4.66,-0.048035,-1280.02832,-0.01093,-0.005698,-0.144722,-0.213669,-0.010885,-1.447223,-1280.02832,-0.143343,0
5.01,-0.078575,-1280.072754,-0.010693,-0.005463,-0.138765,-0.34952,-0.017805,-1.387648,-1280.072754,-0.137498,0
5.36,-0.040215,-1280.072754,-0.01046,-0.005238,-0.13305,-0.178883,-0.009113,-1.330497,-1280.072754,-0.13167,0
5.71,-0.032028,-1280.072754,-0.010236,-0.005008,-0.127195,-0.142469,-0.007258,-1.271952,-1280.072754,-0.125843,0
6.06,-0.039474,-1280.11731,-0.010016,-0.004781,-0.121445,-0.175591,-0.008945,-1.214452,-1280.11731,-0.120014,0
6.41,-0.02346,-1280.072754,-0.009766,-0.004554,-0.115662,-0.104357,-0.005316,-1.156618,-1280.072754,-0.114187,0
6.76,-0.032768,-1280.02832,-0.00952,-0.004321,-0.109756,-0.14576,-0.007425,-1.097559,-1280.02832,-0.108359,0
7.11,-0.056976,-1280.02832,-0.009257,-0.004085,-0.103764,-0.253443,-0.012911,-1.037637,-1280.02832,-0.102515,0
7.460001,-0.108734,-1280.072754,-0.009054,-0.003872,-0.09836,-0.483674,-0.02464,-0.983603,-1280.072754,-0.096686,0
7.81,-0.053993,-1279.983887,-0.008808,-0.003636,-0.09235,-0.240174,-0.012235,-0.923499,-1279.983887,-0.090859,0
8.160001,-0.046547,-1279.983887,-0.00858,-0.003406,-0.086514,-0.207051,-0.010548,-0.865136,-1279.983887,-0.085031,0
8.51,-0.011543,-1279.983887,-0.008317,-0.003174,-0.080608,-0.051347,-0.002616,-0.806077,-1279.983887,-0.079203,0
8.860001,-0.046921,-1279.983887,-0.008101,-0.002942,-0.074729,-0.208714,-0.010632,-0.74729,-1279.983887,-0.073357,0
9.21,-0.043198,-1279.939331,-0.00786,-0.002713,-0.0689,-0.192153,-0.009789,-0.689002,-1279.939331,-0.06753,0
9.56,-0.120651,-1280.072754,-0.007627,-0.00249,-0.063246,-0.536684,-0.02734,-0.632456,-1280.072754,-0.061703,0
9.910001,-0.039848,-1279.983887,-0.00739,-0.002259,-0.057384,-0.177254,-0.00903,-0.573835,-1279.983887,-0.055874,0
10.26,0.011169,-1280.02832,-0.007144,-0.002026,-0.051461,0.049684,0.002531,-0.514609,-1280.02832,-0.050047,0
10.610001,-0.007446,-1280.072754,-0.006911,-0.001791,-0.045494,-0.033123,-0.001687,-0.454944,-1280.072754,-0.04422,0
10.960001,-0.04171,-1279.983887,-0.00667,-0.001567,-0.039805,-0.185535,-0.009452,-0.39805,-1279.983887,-0.038374,0
11.31,-0.067398,-1280.072754,-0.00642,-0.001338,-0.033978,-0.299802,-0.015273,-0.339778,-1280.072754,-0.032547,0
11.660001,-0.113205,-1280.11731,-0.006196,-0.001108,-0.028149,-0.503561,-0.025653,-0.28149,-1280.11731,-0.026718,0
12.01,-0.005585,-1280.02832,-0.005963,-0.000881,-0.022366,-0.024842,-0.001266,-0.223657,-1280.02832,-0.020891,0
12.360001,0.00782,-1280.02832,-0.005721,-0.000645,-0.016372,0.034786,0.001772,-0.163719,-1280.02832,-0.015062,0
12.710001,-0.007446,-1279.983887,-0.00548,-0.000419,-0.010631,-0.033123,-0.001687,-0.10631,-1279.983887,-0.009218,0
13.06,-0.017876,-1280.02832,-0.005256,-0.00019,-0.004839,-0.079515,-0.004051,-0.048386,-1280.02832,-0.00339,0
13.410001,0.031647,-1280.072754,-0.005019,0.000039,0.000998,0.140772,0.007171,0.009977,-1280.072754,0.002437,0
13.76,0.075592,-1280.072754,-0.004988,0,-0.000009,0.33625,0.017129,-0.000091,-1280.072754,0.000207,0
14.110001,0.145226,-1280.02832,-0.004975,0,-0.000009,0.645995,0.032909,-0.000091,-1280.02832,0.000442,0
14.460001,0.087509,-1280.072754,-0.004975,0,0,0.38926,0.01983,0,-1280.072754,0.001023,0
14.81,0.161606,-1280.072754,-0.004975,0.000023,0.000581,0.718859,0.03662,0.005814,-1280.072754,0.001603,0
15.160001,0.2547,-1279.983887,-0.004945,0.000044,0.001126,1.132961,0.057716,0.011264,-1279.983887,0.002185,0
15.510001,0.356361,-1280.02832,-0.004928,0.000068,0.001733,1.585175,0.080753,0.017335,-1280.02832,0.002775,0
15.860001,0.492271,-1279.983887,-0.004919,0.000087,0.002219,2.189733,0.11155,0.022195,-1279.983887,0.003356,0
16.210001,0.607712,-1280.02832,-0.004898,0.00011,0.002783,2.703237,0.137709,0.027827,-1280.02832,0.003936,0
16.560001,0.732086,-1280.02832,-0.004881,0.000126,0.003208,3.256482,0.165893,0.032081,-1280.02832,0.004527,0
16.910002,1.205368,-1280.072754,-0.004846,0.000162,0.00411,5.361745,0.27314,0.041104,-1280.072754,0.005108,0
17.26,1.260109,-1280.02832,-0.004812,0.000178,0.004518,5.605245,0.285545,0.045177,-1280.02832,0.005688,0
17.610001,1.584068,-1280.02832,-0.004799,0.000201,0.005108,7.046288,0.358955,0.051081,-1280.02832,0.006269,0
17.960001,1.892395,-1280.02832,-0.00479,0.000223,0.005655,8.417793,0.428823,0.056546,-1280.02832,0.00686,0
18.310001,2.163857,-1280.02832,-0.004769,0.000243,0.006183,9.625315,0.490337,0.06183,-1280.02832,0.007441,0
18.660002,2.335518,-1280.072754,-0.004747,0.000262,0.006651,10.388903,0.529236,0.066508,-1280.072754,0.008021,0
19.01,3.013985,-1280.072754,-0.004734,0.000293,0.007441,13.406874,0.682979,0.074411,-1280.072754,0.008602,0
19.360001,3.220276,-1280.072754,-0.004704,0.000311,0.007909,14.324503,0.729725,0.079089,-1280.072754,0.009193,0
19.710001,3.802666,-1280.11731,-0.004665,0.000342,0.008698,16.915102,0.861696,0.086977,-1280.11731,0.009773,0
20.060001,4.041733,-1280.072754,-0.004665,0.000362,0.009193,17.978525,0.91587,0.091928,-1280.072754,0.010354,0
20.410002,4.383568,-1280.02832,-0.004656,0.000382,0.009704,19.499083,0.993331,0.097045,-1280.02832,0.010935,0
20.76,4.88813,-1280.161743,-0.004622,0.000408,0.010354,21.743488,1.107666,0.10354,-1280.161743,0.011526,0
21.110001,5.263107,-1280.11731,-0.004596,0.000434,0.011022,23.41147,1.192637,0.110216,-1280.11731,0.012106,0
21.460001,5.40126,-1280.072754,-0.004579,0.00045,0.01143,24.026007,1.223943,0.114304,-1280.072754,0.012687,0
21.810001,5.618355,-1280.11731,-0.004557,0.00047,0.011933,24.99169,1.273137,0.11933,-1280.11731,0.013277,0
22.160002,5.979553,-1280.11731,-0.004544,0.000493,0.012522,26.598381,1.354986,0.125219,-1280.11731,0.013857,0
22.51,6.466248,-1280.11731,-0.004488,0.000524,0.013303,28.763306,1.465273,0.133031,-1280.11731,0.014439,0
22.860001,6.799149,-1280.072754,-0.004501,0.000546,0.013875,30.244123,1.540709,0.138754,-1280.072754,0.01502,0
23.210001,6.842712,-1280.161743,-0.004458,0.000564,0.014334,30.437904,1.550581,0.143342,-1280.161743,0.015609,0
23.560001,7.196098,-1280.072754,-0.004458,0.00059,0.014976,32.009846,1.630659,0.149761,-1280.072754,0.01619,0
23.910002,7.391594,-1280.072754,-0.004432,0.000612,0.015541,32.879452,1.674959,0.155408,-1280.072754,0.016772,0
24.26,7.483566,-1280.11731,-0.004411,0.000629,0.015974,33.288567,1.6958,0.159738,-1280.11731,0.017353,0
24.610001,8.189957,-1280.161743,-0.004389,0.000662,0.016806,36.430748,1.855871,0.168064,-1280.161743,0.017942,0
24.960001,8.162399,-1280.11731,-0.004355,0.000684,0.017362,36.308167,1.849626,0.173621,-1280.11731,0.018523,0
25.310001,8.296829,-1280.161743,-0.004337,0.000706,0.017942,36.906139,1.880088,0.179419,-1280.161743,0.019105,0
25.660002,8.23613,-1280.11731,-0.004312,0.000723,0.018367,36.636135,1.866334,0.183673,-1280.11731,0.019686,0
26.010002,8.577972,-1280.11731,-0.004303,0.000748,0.019,38.156727,1.943796,0.190002,-1280.11731,0.020275,0
26.360001,8.95816,-1280.11731,-0.004251,0.000774,0.019651,39.847889,2.029948,0.196512,-1280.11731,0.020856,0
26.710001,9.203926,-1280.11731,-0.004251,0.000803,0.020388,40.941109,2.085639,0.203885,-1280.11731,0.021438,0
27.060001,9.112328,-1280.11731,-0.00423,0.00082,0.020831,40.533657,2.064883,0.208305,-1280.11731,0.022027,0
27.410002,9.125732,-1280.11731,-0.004208,0.00084,0.021333,40.593285,2.06792,0.213332,-1280.11731,0.022608,0
27.760002,9.578163,-1280.161743,-0.004182,0.000866,0.021984,42.605797,2.170443,0.219842,-1280.161743,0.023189,0
28.110001,9.7435,-1280.161743,-0.004148,0.000889,0.022582,43.341251,2.207909,0.225822,-1280.161743,0.023771,0
28.460001,10.089432,-1280.161743,-0.004122,0.000915,0.023241,44.880035,2.286298,0.232408,-1280.161743,0.02436,0
28.810001,10.034691,-1280.161743,-0.004113,0.000938,0.023813,44.636536,2.273893,0.23813,-1280.161743,0.024941,0
29.160002,10.03022,-1280.072754,-0.004087,0.000956,0.024282,44.616646,2.27288,0.242824,-1280.072754,0.025522,0
29.510002,10.179916,-1280.161743,-0.004066,0.000978,0.024836,45.282528,2.306802,0.248365,-1280.161743,0.026104,0
29.860001,10.374664,-1280.161743,-0.004023,0.001001,0.025427,46.148811,2.350933,0.254269,-1280.161743,0.026693,0
30.210001,10.417488,-1280.161743,-0.004023,0.001022,0.025948,46.339302,2.360636,0.259477,-1280.161743,0.027274,0
30.560001,11.093719,-1280.250732,-0.004001,0.001054,0.026762,49.347328,2.513873,0.267622,-1280.250732,0.027855,0
30.910002,10.912743,-1280.11731,-0.003967,0.001072,0.027239,48.542305,2.472863,0.272391,-1280.11731,0.028444,0
31.260002,11.028183,-1280.11731,-0.003958,0.001094,0.027786,49.055809,2.499022,0.277857,-1280.11731,0.029026,0
31.610001,11.156281,-1280.206299,-0.003932,0.001119,0.028419,49.625614,2.528049,0.284185,-1280.206299,0.029607,0
31.960001,11.084038,-1280.161743,-0.003906,0.001137,0.028886,49.304264,2.511679,0.288863,-1280.161743,0.030188,0
32.310001,11.071747,-1280.161743,-0.003893,0.001157,0.029381,49.249588,2.508894,0.293814,-1280.161743,0.030777,0
32.66,11.796387,-1280.206299,-0.003846,0.001188,0.03017,52.47295,2.6731,0.301702,-1280.206299,0.031359,0
33.010002,11.885757,-1280.206299,-0.003842,0.001211,0.030752,52.870491,2.693351,0.307515,-1280.206299,0.03194,0
33.360001,11.953529,-1280.206299,-0.003816,0.001231,0.031263,53.171955,2.708709,0.312632,-1280.206299,0.03252,0
33.710003,11.928581,-1280.206299,-0.003816,0.001252,0.031801,53.060978,2.703055,0.318007,-1280.206299,0.03311,0
34.060001,12.072685,-1280.250732,-0.003777,0.001271,0.032278,53.701984,2.735709,0.322776,-1280.250732,0.033692,0
34.41,13.063942,-1280.206299,-0.003777,0.001308,0.033215,58.111317,2.960332,0.332147,-1280.206299,0.034273,0
34.760002,12.855042,-1280.295166,-0.003725,0.001326,0.033673,57.182079,2.912994,0.336735,-1280.295166,0.034853,0
35.110001,12.610764,-1280.250732,-0.003712,0.001345,0.034159,56.095478,2.85764,0.341594,-1280.250732,0.035443,0
35.460003,12.876266,-1280.206299,-0.003691,0.001369,0.034767,57.276493,2.917804,0.347665,-1280.206299,0.036025,0
35.810001,13.255714,-1280.295166,-0.003678,0.001394,0.035408,58.964363,3.003788,0.354084,-1280.295166,0.036604,0
36.16,13.638138,-1280.295166,-0.003673,0.001422,0.036111,60.665466,3.090446,0.361109,-1280.295166,0.037195,0
36.510002,13.664207,-1280.250732,-0.003622,0.001447,0.036744,60.781429,3.096354,0.367438,-1280.250732,0.037776,0
36.860001,13.729744,-1280.250732,-0.003591,0.001469,0.037325,61.072952,3.111204,0.373251,-1280.250732,0.038358,0
37.210003,13.689529,-1280.339722,-0.003583,0.001486,0.037732,60.89407,3.102092,0.377324,-1280.339722,0.038937,0
37.560001,13.848534,-1280.250732,-0.00357,0.001508,0.038305,61.601353,3.138123,0.383047,-1280.250732,0.039528,0
37.910004,13.752083,-1280.295166,-0.003535,0.001524,0.038721,61.172321,3.116267,0.38721,-1280.295166,0.040109,0
38.260002,14.828987,-1280.250732,-0.003514,0.001561,0.039649,65.962631,3.360296,0.39649,-1280.250732,0.040689,0
38.610001,14.451401,-1280.206299,-0.003497,0.001577,0.040056,64.283043,3.274734,0.400563,-1280.206299,0.04127,0
38.960003,14.750786,-1280.295166,-0.003475,0.001603,0.040724,65.614769,3.342576,0.40724,-1280.295166,0.041861,0
39.310001,14.59774,-1280.250732,-0.003445,0.001621,0.041175,64.93399,3.307895,0.411751,-1280.250732,0.042442,0
39.660004,14.682274,-1280.250732,-0.003436,0.001643,0.04174,65.310013,3.327051,0.417398,-1280.250732,0.043022,0
40.010002,14.983147,-1280.250732,-0.003415,0.001667,0.042338,66.648369,3.39523,0.423378,-1280.250732,0.043613,0
40.360001,15.413239,-1280.250732,-0.003393,0.001694,0.043031,68.561508,3.49269,0.430312,-1280.250732,0.044194,0
40.710003,15.425529,-1280.250732,-0.003376,0.001715,0.043552,68.61618,3.495475,0.43552,-1280.250732,0.044774,0
41.060001,15.647835,-1280.206299,-0.003354,0.001739,0.044167,69.605049,3.54585,0.441667,-1280.206299,0.045355,0
41.410004,15.618042,-1280.250732,-0.003328,0.00176,0.044706,69.472519,3.539099,0.447057,-1280.250732,0.045946,0
41.760002,15.825081,-1280.250732,-0.003303,0.001785,0.045346,70.393478,3.586015,0.453461,-1280.250732,0.046527,0
42.110001,16.448433,-1280.250732,-0.003281,0.001812,0.046015,73.166283,3.727268,0.460152,-1280.250732,0.047107,0
42.460003,16.500938,-1280.250732,-0.003251,0.001834,0.046578,73.399841,3.739166,0.465784,-1280.250732,0.047688,0
42.810001,16.324059,-1280.295166,-0.003242,0.001853,0.047055,72.613037,3.699085,0.470553,-1280.295166,0.048279,0
43.160004,16.382523,-1280.295166,-0.003221,0.001873,0.047576,72.8731,3.712333,0.475761,-1280.295166,0.048858,0
43.510002,16.71431,-1280.295166,-0.003208,0.001894,0.048114,74.348961,3.787517,0.481136,-1280.295166,0.04944,0
43.860001,17.309357,-1280.250732,-0.003182,0.001924,0.048858,76.995865,3.922356,0.488585,-1280.250732,0.050021,0
44.210003,17.471718,-1280.295166,-0.003147,0.00195,0.049519,77.718086,3.959148,0.495185,-1280.295166,0.050612,0
44.560001,17.228928,-1280.295166,-0.003139,0.001969,0.050005,76.6381,3.904131,0.500045,-1280.295166,0.051191,0
44.910004,17.583801,-1280.339722,-0.003117,0.00199,0.050559,78.216652,3.984546,0.505586,-1280.339722,0.051773,0
45.260002,17.794189,-1280.250732,-0.003109,0.002013,0.05114,79.152512,4.032221,0.5114,-1280.250732,0.052363,0
45.610001,17.624016,-1280.250732,-0.003074,0.002027,0.051496,78.395538,3.993659,0.514958,-1280.250732,0.052943,0
45.960003,18.763847,-1280.295166,-0.003053,0.002065,0.05245,83.465759,4.251948,0.524496,-1280.295166,0.053524,0
46.310001,18.662933,-1280.295166,-0.003022,0.002085,0.05297,83.016876,4.229081,0.529704,-1280.295166,0.054106,0
46.660004,18.756027,-1280.295166,-0.003014,0.002105,0.053464,83.430977,4.250176,0.534639,-1280.295166,0.054696,0
47.010002,18.633888,-1280.250732,-0.002997,0.002127,0.05402,82.887672,4.222499,0.540195,-1280.250732,0.055276,0
47.360001,18.976845,-1280.206299,-0.002971,0.002147,0.054522,84.413223,4.300214,0.545222,-1280.206299,0.055857,0
47.710003,19.570404,-1280.295166,-0.002958,0.002176,0.055259,87.053505,4.434717,0.552595,-1280.295166,0.056439,0
48.060001,20.071991,-1280.339722,-0.002923,0.002203,0.055953,89.284676,4.548378,0.559529,-1280.339722,0.057028,0
48.410004,19.913734,-1280.295166,-0.002902,0.00222,0.056378,88.580711,4.512516,0.563783,-1280.295166,0.057609,0
48.760002,20.031776,-1280.250732,-0.00288,0.00224,0.05689,89.105789,4.539265,0.5689,-1280.250732,0.05819,0
49.110001,20.442131,-1280.339722,-0.002867,0.002265,0.057523,90.931137,4.632253,0.575228,-1280.339722,0.058779,0
49.460003,20.787315,-1280.339722,-0.002846,0.002288,0.058121,92.466599,4.710473,0.581208,-1280.339722,0.059361,0
49.810001,21.297096,-1280.295166,-0.002828,0.002314,0.058772,94.734215,4.825991,0.587718,-1280.295166,0.059942,0
50.160004,21.549568,-1280.384155,-0.002815,0.00234,0.059449,95.857269,4.883202,0.594486,-1280.384155,0.060523,0
50.510002,21.4561,-1280.250732,-0.002785,0.002355,0.059821,95.441498,4.862022,0.59821,-1280.250732,0.061112,0
50.860001,21.726067,-1280.295166,-0.002764,0.002377,0.060368,96.642372,4.923197,0.603676,-1280.295166,0.061694,0
51.210003,22.105515,-1280.250732,-0.002734,0.0024,0.060956,98.330238,5.009181,0.609565,-1280.250732,0.062275,0
51.560001,22.20047,-1280.295166,-0.002716,0.002418,0.061417,98.752625,5.030698,0.614167,-1280.295166,0.062857,0
51.910004,23.520905,-1280.295166,-0.00269,0.002456,0.06238,104.626205,5.329913,0.623796,-1280.295166,0.063445,0
52.260002,23.415894,-1280.250732,-0.002677,0.002476,0.062882,104.159096,5.306118,0.628822,-1280.250732,0.064027,0
52.610001,23.604317,-1280.295166,-0.00266,0.002498,0.063455,104.997246,5.348814,0.634545,-1280.295166,0.064608,0
52.960003,23.930885,-1280.206299,-0.002647,0.002519,0.063975,106.449898,5.422816,0.639753,-1280.206299,0.06519,0
53.310001,23.888062,-1280.250732,-0.002626,0.002537,0.064443,106.259407,5.413112,0.644431,-1280.250732,0.065778,0
53.660004,23.938332,-1280.339722,-0.0026,0.002559,0.06499,106.483017,5.424504,0.649897,-1280.339722,0.06636,0
54.010002,25.074814,-1280.295166,-0.002565,0.002586,0.065683,111.538345,5.682034,0.656831,-1280.295166,0.066941,0
54.360004,25.438248,-1280.206299,-0.002565,0.002609,0.066281,113.154976,5.76439,0.662811,-1280.206299,0.06753,0
54.710003,25.754021,-1280.250732,-0.002557,0.002629,0.066776,114.559608,5.835945,0.667761,-1280.250732,0.068111,0
55.060001,26.157677,-1280.250732,-0.002518,0.002655,0.067435,116.355156,5.927414,0.674347,-1280.250732,0.068693,0
55.410004,26.394875,-1280.295166,-0.002509,0.002676,0.067981,117.410263,5.981164,0.679813,-1280.295166,0.069274,0
55.760002,27.966286,-1280.339722,-0.002496,0.002708,0.068788,124.400253,6.337251,0.687882,-1280.339722,0.069863,0
56.110004,27.852715,-1280.295166,-0.002453,0.002725,0.069205,123.895065,6.311515,0.692045,-1280.295166,0.070444,0
56.460003,28.140556,-1280.250732,-0.00244,0.002751,0.069881,125.175446,6.376741,0.698813,-1280.250732,0.071026,0
56.810001,28.461914,-1280.250732,-0.002423,0.00277,0.070358,126.604919,6.449562,0.703582,-1280.250732,0.071606,0
57.160004,29.165329,-1280.295166,-0.002406,0.002794,0.070973,129.733856,6.608958,0.709728,-1280.295166,0.072196,0
57.510002,29.976723,-1280.250732,-0.002389,0.002821,0.07165,133.343124,6.792822,0.716496,-1280.250732,0.072777,0
57.860004,30.608643,-1280.250732,-0.002371,0.002848,0.072343,136.154037,6.936018,0.72343,-1280.250732,0.073359,0
58.210003,31.036125,-1280.295166,-0.002354,0.002869,0.072864,138.055573,7.032887,0.728638,-1280.295166,0.073939,0
58.560001,31.11879,-1280.339722,-0.00232,0.002887,0.073324,138.423294,7.051619,0.73324,-1280.339722,0.074529,0
58.910004,31.635277,-1280.295166,-0.002307,0.002907,0.073827,140.720734,7.168656,0.738266,-1280.295166,0.07511,0
59.260002,31.781616,-1280.295166,-0.002289,0.002923,0.074252,141.371689,7.201817,0.742521,-1280.295166,0.07569,0
59.610004,33.733223,-1280.295166,-0.002281,0.002959,0.075171,150.052872,7.644058,0.75171,-1280.295166,0.076281,0
59.960003,33.891853,-1280.250732,-0.002255,0.002981,0.075718,150.758499,7.680004,0.757176,-1280.250732,0.076862,0
60.310001,34.495842,-1280.295166,-0.002229,0.003002,0.076255,153.445175,7.816869,0.76255,-1280.295166,0.077443,0
60.660004,34.847359,-1280.295166,-0.002212,0.00302,0.076697,155.008789,7.896524,0.766971,-1280.295166,0.078023,0
61.010002,35.545929,-1280.295166,-0.002186,0.003043,0.077286,158.116196,8.054823,0.77286,-1280.295166,0.078614,0
61.360004,36.002457,-1280.295166,-0.002173,0.003065,0.077842,160.146927,8.158274,0.778417,-1280.295166,0.079195,0
61.710003,37.536629,-1280.295166,-0.002169,0.003093,0.078562,166.971268,8.505921,0.785623,-1280.295166,0.079775,0
62.060001,37.68856,-1280.295166,-0.002151,0.003108,0.078951,167.647095,8.54035,0.789514,-1280.295166,0.080356,0
62.410004,39.220871,-1280.250732,-0.002134,0.003141,0.079793,174.46315,8.887576,0.797932,-1280.250732,0.080947,0
62.760002,39.486,-1280.339722,-0.002113,0.003159,0.080226,175.642502,8.947656,0.802261,-1280.339722,0.081528,0
63.110004,40.149567,-1280.295166,-0.002087,0.00318,0.080782,178.594193,9.098022,0.807818,-1280.295166,0.082108,0
63.460003,41.775719,-1280.250732,-0.002087,0.003211,0.081561,185.827682,9.466513,0.815615,-1280.250732,0.082698,0
63.810001,42.476524,-1280.250732,-0.00207,0.003231,0.082066,188.945023,9.625318,0.820656,-1280.250732,0.08328,0
64.160004,42.931938,-1280.339722,-0.002052,0.003251,0.082585,190.970795,9.728517,0.825849,-1280.339722,0.08386,0
64.510002,43.336334,-1280.295166,-0.002031,0.003272,0.083115,192.769638,9.820153,0.831148,-1280.295166,0.084441,0
64.860001,44.390518,-1280.250732,-0.002013,0.003296,0.083722,197.458893,10.059035,0.837219,-1280.250732,0.085031,0
65.210007,46.006241,-1280.295166,-0.001992,0.003322,0.08438,204.645981,10.425163,0.843804,-1280.295166,0.085613,0
65.560005,47.052238,-1280.384155,-0.001988,0.003349,0.085057,209.298813,10.662189,0.850572,-1280.384155,0.086193,0
65.910004,47.480469,-1280.250732,-0.001957,0.003369,0.085569,211.203674,10.759228,0.855689,-1280.250732,0.086774,0
66.260002,48.557739,-1280.295166,-0.001957,0.00339,0.086097,215.995605,11.003341,0.860973,-1280.295166,0.087364,0
66.610001,49.51548,-1280.250732,-0.001949,0.003412,0.086653,220.255859,11.220367,0.866529,-1280.250732,0.087944,0
66.960007,49.875565,-1280.295166,-0.001923,0.00343,0.087121,221.85759,11.301965,0.871207,-1280.295166,0.088526,0
67.310005,52.152626,-1280.384155,-0.001919,0.003462,0.087944,231.986465,11.817954,0.879443,-1280.384155,0.089107,0
67.660004,53.131218,-1280.339722,-0.001897,0.003485,0.088509,236.339462,12.039706,0.88509,-1280.339722,0.089697,0
68.010002,54.087845,-1280.295166,-0.001863,0.003503,0.088986,240.594757,12.25648,0.889859,-1280.295166,0.090277,0
68.360001,54.567833,-1280.295166,-0.001871,0.003523,0.089472,242.729843,12.365248,0.894719,-1280.295166,0.090859,0
68.710007,56.000717,-1280.295166,-0.001854,0.003546,0.090061,249.103638,12.689944,0.900608,-1280.295166,0.091449,0
69.060005,57.534149,-1280.339722,-0.001832,0.003575,0.090798,255.924683,13.037425,0.907981,-1280.339722,0.092029,0
69.410004,59.401222,-1280.339722,-0.001815,0.003602,0.091484,264.229828,13.460509,0.914839,-1280.339722,0.09261,0
69.760002,59.950104,-1280.295166,-0.001819,0.003617,0.091882,266.671387,13.584888,0.918821,-1280.295166,0.093192,0
70.110001,60.79129,-1280.250732,-0.001794,0.003638,0.092403,270.413177,13.775503,0.924029,-1280.250732,0.093782,0
70.460007,62.522827,-1280.339722,-0.001785,0.003663,0.093045,278.115417,14.167875,0.930448,-1280.339722,0.094362,0
70.810005,63.846603,-1280.339722,-0.001781,0.003686,0.093625,284.003876,14.467848,0.936247,-1280.339722,0.094943,0
71.160004,65.509628,-1280.250732,-0.001755,0.003713,0.094301,291.401367,14.844694,0.943014,-1280.250732,0.095525,0
71.510002,65.478714,-1280.295166,-0.001729,0.003714,0.094327,291.263855,14.837688,0.943272,-1280.295166,0.016566,0
71.860001,65.279129,-1280.339722,-0.001725,0.003728,0.094692,290.376068,14.792462,0.94692,-1280.339722,294.500458,0
72.210007,65.060165,-1280.295166,-0.001725,0.00374,0.094987,289.402069,14.742845,0.949872,-1280.295166,294.500458,0
72.560005,65.163315,-1280.295166,-0.001703,0.003745,0.095134,289.860901,14.766218,0.951341,-1280.295166,294.500458,0
72.910004,65.244125,-1280.295166,-0.001712,0.003754,0.095343,290.220367,14.78453,0.95343,-1280.295166,294.500458,0
73.260002,64.987564,-1280.295166,-0.001707,0.003758,0.095464,289.079132,14.726393,0.954641,-1280.295166,294.500458,0
73.610001,65.243011,-1280.295166,-0.001703,0.003767,0.095681,290.215424,14.784278,0.956806,-1280.295166,294.500458,0
73.960007,64.720932,-1280.339722,-0.001694,0.003767,0.09569,287.893097,14.665973,0.956897,-1280.339722,294.500458,0
74.310005,65.288803,-1280.295166,-0.001686,0.003779,0.095976,290.419098,14.794654,0.959759,-1280.295166,294.500458,0
74.660004,64.765991,-1280.295166,-0.001673,0.003779,0.095993,288.093506,14.676184,0.959925,-1280.295166,294.500458,0
75.010002,64.968201,-1280.295166,-0.00166,0.003786,0.096174,288.992981,14.722005,0.961742,-1280.295166,294.500458,0
75.360001,65.33461,-1280.295166,-0.001673,0.003795,0.0964,290.622864,14.805035,0.963998,-1280.295166,294.500458,0
75.710007,64.948837,-1280.295166,-0.001664,0.003796,0.096409,288.90686,14.717617,0.964088,-1280.295166,294.500458,0
76.060005,64.769714,-1280.250732,-0.001673,0.003799,0.096488,288.110077,14.677027,0.964876,-1280.250732,294.500458,0
76.410004,65.05719,-1280.295166,-0.001664,0.003806,0.096678,289.388824,14.74217,0.966783,-1280.295166,294.500458,0
76.760002,64.810303,-1280.295166,-0.001651,0.003807,0.096704,288.290619,14.686224,0.967041,-1280.295166,294.500458,0
77.110001,64.755936,-1280.295166,-0.001664,0.00381,0.096781,288.048798,14.673904,0.967813,-1280.295166,294.500458,0
77.460007,65.161087,-1280.295166,-0.001638,0.003818,0.096972,289.850983,14.765714,0.96972,-1280.295166,294.500458,0
77.810005,64.900787,-1280.384155,-0.001638,0.003818,0.096972,288.693115,14.706729,0.96972,-1280.384155,294.500458,0
78.160004,65.013992,-1280.339722,-0.001651,0.003823,0.097111,289.196686,14.732382,0.971113,-1280.339722,294.500458,0
78.510002,64.792068,-1280.384155,-0.001638,0.003824,0.09712,288.209503,14.682093,0.971204,-1280.384155,294.500458,0
78.860001,65.592667,-1280.250732,-0.001647,0.003835,0.097397,291.770752,14.863511,0.973975,-1280.250732,294.500458,0
79.210007,65.393814,-1280.295166,-0.001634,0.003835,0.097397,290.8862,14.81845,0.973975,-1280.295166,294.500458,0
79.560005,65.14917,-1280.295166,-0.001643,0.003835,0.097397,289.797974,14.763013,0.973975,-1280.295166,294.500458,0
79.910004,65.099274,-1280.339722,-0.001613,0.00384,0.097546,289.576019,14.751707,0.975458,-1280.339722,294.500458,0
80.260002,65.113052,-1280.295166,-0.001625,0.00384,0.097546,289.637329,14.754828,0.975458,-1280.295166,294.500458,0
80.610001,64.915695,-1280.250732,-0.001613,0.00384,0.097546,288.75943,14.710107,0.975458,-1280.250732,294.500458,0
80.960007,66.015305,-1280.339722,-0.001617,0.003853,0.097865,293.650726,14.959282,0.978653,-1280.339722,294.500458,0
81.310005,65.748322,-1280.384155,-0.001625,0.003847,0.097709,292.463135,14.898783,0.977093,-1280.384155,294.500458,0
81.660004,65.480957,-1280.339722,-0.001608,0.003847,0.097709,291.273834,14.838197,0.977093,-1280.339722,294.500458,0
82.010002,65.22438,-1280.250732,-0.0016,0.003847,0.097718,290.132538,14.780056,0.977184,-1280.250732,294.500458,0
82.360001,64.981598,-1280.295166,-0.0016,0.003848,0.097727,289.052582,14.72504,0.977275,-1280.295166,294.500458,0
82.710007,65.342804,-1280.295166,-0.001608,0.003857,0.097979,290.659302,14.80689,0.979788,-1280.295166,294.500458,0
83.060005,65.205399,-1280.339722,-0.001604,0.003857,0.097979,290.048096,14.775755,0.979788,-1280.339722,294.500458,0
83.410004,65.023682,-1280.339722,-0.001591,0.003857,0.097979,289.239777,14.734576,0.979788,-1280.339722,294.500458,0
83.760002,65.053101,-1280.384155,-0.001595,0.003861,0.098065,289.370636,14.741242,0.980651,-1280.384155,294.500458,0
84.110001,64.94957,-1280.295166,-0.001591,0.003861,0.098074,288.910126,14.717783,0.980742,-1280.295166,294.500458,0
84.460007,65.29924,-1280.384155,-0.001595,0.003868,0.098248,290.465515,14.79702,0.982483,-1280.384155,294.500458,0
84.810005,65.269821,-1280.339722,-0.001591,0.003868,0.098248,290.334656,14.790353,0.982483,-1280.339722,294.500458,0
85.160004,65.123108,-1280.384155,-0.0016,0.003868,0.098248,289.682037,14.757108,0.982483,-1280.384155,294.500458,0
85.510002,64.993515,-1280.384155,-0.001582,0.003868,0.098248,289.105591,14.72774,0.982483,-1280.384155,294.500458,0
85.860001,64.918289,-1280.295166,-0.0016,0.003871,0.098316,288.770966,14.710694,0.983164,-1280.295166,294.500458,0
86.210007,64.985321,-1280.339722,-0.001582,0.003871,0.098335,289.069153,14.725884,0.983346,-1280.339722,294.500458,0
86.560005,64.876221,-1280.384155,-0.001582,0.003872,0.098344,288.583832,14.701161,0.983437,-1280.384155,294.500458,0
86.910004,65.107834,-1280.384155,-0.001578,0.003876,0.098456,289.614105,14.753646,0.984557,-1280.384155,294.500458,0
87.260002,65.027771,-1280.295166,-0.001582,0.003876,0.098456,289.257965,14.735503,0.984557,-1280.295166,294.500458,0
87.610001,64.919418,-1280.295166,-0.001574,0.003876,0.098456,288.776001,14.71095,0.984557,-1280.295166,294.500458,0
87.960007,65.156235,-1280.339722,-0.001591,0.003881,0.098577,289.829407,14.764614,0.985768,-1280.339722,294.500458,0
88.310005,65.086975,-1280.339722,-0.001582,0.003881,0.098577,289.521332,14.748919,0.985768,-1280.339722,294.500458,0
88.660004,65.083252,-1280.339722,-0.001582,0.003882,0.098612,289.504761,14.748075,0.986117,-1280.339722,294.500458,0
89.010002,65.019958,-1280.384155,-0.001578,0.003882,0.098612,289.223206,14.733733,0.986117,-1280.384155,294.500458,0
89.360001,64.913086,-1280.384155,-0.001578,0.003883,0.09863,288.747833,14.709516,0.986298,-1280.384155,294.500458,0
89.710007,64.962982,-1280.384155,-0.001574,0.003885,0.098672,288.969788,14.720822,0.986722,-1280.384155,294.500458,0
90.060005,65.236298,-1280.339722,-0.001561,0.00389,0.098802,290.185547,14.782756,0.988024,-1280.339722,294.500458,0
90.410004,65.227371,-1280.384155,-0.001574,0.00389,0.098802,290.145844,14.780734,0.988024,-1280.384155,294.500458,0
90.760002,65.135757,-1280.384155,-0.001561,0.00389,0.098802,289.738312,14.759974,0.988024,-1280.384155,294.500458,0
91.110001,65.055328,-1280.428711,-0.001569,0.00389,0.098802,289.380554,14.741748,0.988024,-1280.428711,294.500458,0
91.460007,64.961121,-1280.384155,-0.001582,0.00389,0.098802,288.961487,14.720401,0.988024,-1280.384155,294.500458,0
91.810005,64.875473,-1280.384155,-0.001561,0.00389,0.098802,288.580505,14.700992,0.988024,-1280.384155,294.500458,0
92.160004,65.54686,-1280.384155,-0.001556,0.003899,0.099037,291.566986,14.85313,0.990371,-1280.384155,294.500458,0
92.510002,65.524521,-1280.339722,-0.001565,0.003899,0.099037,291.467621,14.848068,0.990371,-1280.339722,294.500458,0
92.860001,65.474991,-1280.473145,-0.001544,0.003899,0.099037,291.247314,14.836845,0.990371,-1280.473145,294.500458,0
93.210007,65.37706,-1280.428711,-0.001552,0.003899,0.099037,290.811676,14.814653,0.990371,-1280.428711,294.500458,0
93.560005,65.298111,-1280.428711,-0.001569,0.003899,0.099037,290.46051,14.796764,0.990371,-1280.428711,294.500458,0
93.910004,65.231461,-1280.517578,-0.001565,0.003899,0.099037,290.164032,14.78166,0.990371,-1280.517578,294.500458,0
94.260002,65.133896,-1280.428711,-0.001552,0.003899,0.099037,289.730042,14.759551,0.990371,-1280.428711,294.500458,0
94.610008,65.043045,-1280.517578,-0.001565,0.0039,0.099054,289.325928,14.738965,0.990537,-1280.517578,294.500458,0
94.960007,64.986435,-1280.473145,-0.001565,0.0039,0.099054,289.074097,14.726136,0.990537,-1280.473145,294.500458,0
95.310005,64.913452,-1280.428711,-0.001574,0.0039,0.099063,288.749451,14.709599,0.990628,-1280.428711,294.500458,0
95.660004,65.433289,-1280.473145,-0.001561,0.003909,0.099279,291.061798,14.827395,0.992793,-1280.473145,294.500458,0
96.010002,65.526749,-1280.428711,-0.001552,0.003908,0.09927,291.477539,14.848574,0.992702,-1280.428711,294.500458,0
96.360008,65.491379,-1280.428711,-0.001556,0.003908,0.09927,291.32019,14.840559,0.992702,-1280.428711,294.500458,0
96.710007,65.418762,-1280.428711,-0.001552,0.003908,0.09927,290.997192,14.824103,0.992702,-1280.428711,294.500458,0
97.060005,65.309662,-1280.428711,-0.001565,0.003908,0.09927,290.511871,14.799381,0.992702,-1280.428711,294.500458,0
97.410004,65.259766,-1280.384155,-0.001561,0.003909,0.099279,290.289948,14.788074,0.992793,-1280.384155,294.500458,0
97.760002,65.197571,-1280.428711,-0.001544,0.003909,0.099279,290.013275,14.773981,0.992793,-1280.428711,294.500458,0
98.110008,65.101135,-1280.384155,-0.001565,0.003909,0.099288,289.58432,14.752128,0.992884,-1280.384155,294.500458,0
98.460007,65.05719,-1280.428711,-0.001574,0.003909,0.099297,289.388824,14.74217,0.992975,-1280.428711,294.500458,0
98.810005,64.999466,-1280.428711,-0.001544,0.003909,0.099297,289.13205,14.72909,0.992975,-1280.428711,294.500458,0
99.160004,64.945114,-1280.384155,-0.001548,0.003909,0.099297,288.890289,14.716773,0.992975,-1280.384155,294.500458,0
99.510002,64.932068,-1280.428711,-0.001544,0.003911,0.09934,288.832275,14.713818,0.993399,-1280.428711,294.500458,0
99.860008,64.904892,-1280.428711,-0.001565,0.003911,0.09934,288.711365,14.707659,0.993399,-1280.428711,294.500458,0
100.210007,65.178589,-1280.428711,-0.001556,0.003915,0.099453,289.928833,14.769679,0.994534,-1280.428711,294.500458,0
100.560005,65.188263,-1280.428711,-0.001561,0.003915,0.099453,289.971863,14.771872,0.994534,-1280.428711,294.500458,0
100.910004,65.145813,-1280.384155,-0.001552,0.003915,0.099453,289.783051,14.762252,0.994534,-1280.384155,294.500458,0
101.260002,65.087723,-1280.428711,-0.001548,0.003915,0.099453,289.524658,14.749088,0.994534,-1280.428711,294.500458,0
101.610008,65.034851,-1280.428711,-0.001544,0.003915,0.099453,289.289459,14.737107,0.994534,-1280.428711,294.500458,0
101.960007,64.997238,-1280.428711,-0.001544,0.003915,0.099453,289.122162,14.728585,0.994534,-1280.428711,294.500458,0
102.310005,64.942871,-1280.428711,-0.001556,0.003915,0.099453,288.88031,14.716265,0.994534,-1280.428711,294.500458,0
102.660004,64.881424,-1280.428711,-0.001552,0.003915,0.099453,288.606995,14.702341,0.994534,-1280.428711,294.500458,0
103.010002,65.311142,-1280.428711,-0.001535,0.003922,0.099626,290.518463,14.799716,0.99626,-1280.428711,294.500458,0
103.360008,65.332367,-1280.428711,-0.001552,0.003922,0.099626,290.612885,14.804526,0.99626,-1280.428711,294.500458,0
103.710007,65.315994,-1280.428711,-0.001544,0.003922,0.099626,290.540039,14.800816,0.99626,-1280.428711,294.500458,0
104.060005,65.289185,-1280.384155,-0.001561,0.003922,0.099626,290.420807,14.794741,0.99626,-1280.384155,294.500458,0
104.410004,65.260513,-1280.384155,-0.001526,0.003922,0.099626,290.293274,14.788243,0.99626,-1280.384155,294.500458,0
104.760002,65.205017,-1280.428711,-0.001544,0.003922,0.099626,290.046417,14.775668,0.99626,-1280.428711,294.500458,0
105.110008,65.138367,-1280.384155,-0.001556,0.003922,0.099626,289.749939,14.760565,0.99626,-1280.384155,294.500458,0
105.460007,65.091446,-1280.428711,-0.001535,0.003922,0.099626,289.541199,14.749933,0.99626,-1280.428711,294.500458,0
105.810005,65.031128,-1280.339722,-0.001544,0.003922,0.099626,289.272919,14.736264,0.99626,-1280.339722,294.500458,0
106.160004,64.999847,-1280.384155,-0.001548,0.003922,0.099626,289.133759,14.729176,0.99626,-1280.384155,294.500458,0
106.510002,64.936172,-1280.428711,-0.001544,0.003922,0.099626,288.850525,14.714746,0.99626,-1280.428711,294.500458,0
106.860008,64.88739,-1280.339722,-0.001539,0.003923,0.099635,288.633514,14.703692,0.996351,-1280.339722,294.500458,0
107.210007,64.836746,-1280.428711,-0.001531,0.003923,0.099635,288.408264,14.692217,0.996351,-1280.428711,294.500458,0
107.560005,64.775681,-1280.384155,-0.001539,0.003923,0.099635,288.136627,14.678379,0.996351,-1280.384155,294.500458,0
107.910004,64.746628,-1280.339722,-0.001535,0.003923,0.099635,288.007385,14.671796,0.996351,-1280.339722,294.500458,0
108.260002,65.346146,-1280.384155,-0.001531,0.003931,0.099844,290.674164,14.807648,0.99844,-1280.384155,294.500458,0
108.610008,65.35881,-1280.384155,-0.001552,0.003931,0.099835,290.730499,14.810518,0.998349,-1280.384155,294.500458,0
108.960007,65.33461,-1280.384155,-0.001535,0.003931,0.099835,290.622864,14.805035,0.998349,-1280.384155,294.500458,0
109.310005,65.318222,-1280.339722,-0.001531,0.003931,0.099835,290.549957,14.80132,0.998349,-1280.339722,294.500458,0
109.660004,65.287689,-1280.339722,-0.001531,0.003931,0.099835,290.414154,14.794401,0.998349,-1280.339722,294.500458,0
110.010002,65.257904,-1280.384155,-0.001539,0.003931,0.099835,290.281647,14.787653,0.998349,-1280.384155,294.500458,0
110.360008,65.209488,-1280.339722,-0.001522,0.003931,0.099835,290.066284,14.776682,0.998349,-1280.339722,294.500458,0
110.710007,65.160706,-1280.384155,-0.001526,0.003931,0.099835,289.849304,14.765627,0.998349,-1280.384155,294.500458,0
111.060005,65.103363,-1280.384155,-0.001526,0.003931,0.099844,289.594208,14.752633,0.99844,-1280.384155,294.500458,0
111.410004,65.04863,-1280.384155,-0.001535,0.003931,0.099844,289.350769,14.74023,0.99844,-1280.384155,294.500458,0
111.760002,65.016602,-1280.339722,-0.001526,0.003931,0.099844,289.208282,14.732972,0.99844,-1280.339722,294.500458,0
112.110008,64.987183,-1280.384155,-0.001531,0.003931,0.099844,289.077423,14.726306,0.99844,-1280.384155,294.500458,0
112.460007,64.956284,-1280.295166,-0.001535,0.003931,0.099844,288.939972,14.719304,0.99844,-1280.295166,294.500458,0
112.810005,64.927612,-1280.384155,-0.001522,0.003931,0.099844,288.812439,14.712808,0.99844,-1280.384155,294.500458,0
113.160004,64.887024,-1280.339722,-0.001522,0.003932,0.099877,288.631897,14.70361,0.998773,-1280.339722,294.500458,0
113.510002,64.856857,-1280.384155,-0.001526,0.003932,0.099877,288.497711,14.696774,0.998773,-1280.384155,294.500458,0
113.860008,64.833771,-1280.384155,-0.001522,0.003932,0.099877,288.39502,14.691543,0.998773,-1280.384155,294.500458,0
114.210007,64.787216,-1280.384155,-0.001518,0.003932,0.099877,288.187927,14.680993,0.998773,-1280.384155,294.500458,0
114.560005,64.759659,-1280.384155,-0.001531,0.003933,0.099886,288.065338,14.674748,0.998864,-1280.384155,294.500458,0
114.910004,64.751846,-1280.384155,-0.001526,0.003933,0.099886,288.030609,14.672977,0.998864,-1280.384155,294.500458,0
115.260002,65.507385,-1280.384155,-0.001531,0.003941,0.100112,291.391388,14.844186,1.00112,-1280.384155,294.500458,0
115.610008,65.52861,-1280.384155,-0.001505,0.003941,0.100112,291.485809,14.848995,1.00112,-1280.384155,294.500458,0
115.960007,65.507019,-1280.384155,-0.001526,0.003941,0.100112,291.389771,14.844102,1.00112,-1280.384155,294.500458,0
116.310005,65.490631,-1280.428711,-0.001526,0.003941,0.100112,291.316864,14.840389,1.00112,-1280.428711,294.500458,0
116.660004,65.470154,-1280.428711,-0.0015,0.003941,0.100112,291.2258,14.83575,1.00112,-1280.428711,294.500458,0
117.010002,65.432922,-1280.428711,-0.001522,0.003941,0.100112,291.060181,14.827312,1.00112,-1280.428711,294.500458,0
117.360008,65.388596,-1280.384155,-0.001518,0.003941,0.100112,290.863007,14.817267,1.00112,-1280.384155,294.500458,0
117.710007,65.348755,-1280.428711,-0.001518,0.003941,0.100112,290.685791,14.80824,1.00112,-1280.428711,294.500458,0
118.060005,65.315247,-1280.473145,-0.001509,0.003941,0.100112,290.536713,14.800647,1.00112,-1280.473145,294.500458,0
118.410004,65.29924,-1280.384155,-0.001513,0.003941,0.100112,290.465515,14.79702,1.00112,-1280.384155,294.500458,0
118.760002,65.270187,-1280.428711,-0.001509,0.003941,0.100112,290.336304,14.790436,1.00112,-1280.428711,294.500458,0
119.110008,65.240021,-1280.473145,-0.001522,0.003941,0.100112,290.202118,14.7836,1.00112,-1280.473145,294.500458,0
119.460007,65.196091,-1280.428711,-0.001505,0.003941,0.100112,290.006683,14.773645,1.00112,-1280.428711,294.500458,0
119.810005,65.151398,-1280.473145,-0.001518,0.003941,0.100112,289.807892,14.763517,1.00112,-1280.473145,294.500458,0
120.160004,65.113419,-1280.428711,-0.001526,0.003942,0.100121,289.638947,14.754911,1.001211,-1280.428711,294.500458,0
120.510002,65.076553,-1280.428711,-0.001531,0.003942,0.100121,289.474976,14.746557,1.001211,-1280.428711,294.500458,0
120.860008,65.041931,-1280.428711,-0.001513,0.003942,0.100121,289.320953,14.738712,1.001211,-1280.428711,294.500458,0
121.210007,65.024796,-1280.517578,-0.001526,0.003942,0.100121,289.244751,14.734829,1.001211,-1280.517578,294.500458,0
121.560005,64.990906,-1280.473145,-0.001522,0.003942,0.100121,289.093994,14.72715,1.001211,-1280.473145,294.500458,0
121.910004,64.964478,-1280.428711,-0.001505,0.003942,0.10013,288.97644,14.721162,1.001302,-1280.428711,294.500458,0
122.260002,64.9384,-1280.473145,-0.001526,0.003942,0.10013,288.860443,14.715252,1.001302,-1280.473145,294.500458,0
122.610008,64.891479,-1280.473145,-0.001509,0.003942,0.10013,288.651703,14.704619,1.001302,-1280.473145,294.500458,0
122.960007,64.854996,-1280.473145,-0.001539,0.003942,0.10013,288.489441,14.696352,1.001302,-1280.473145,294.500458,0
123.310005,64.810303,-1280.473145,-0.001505,0.003942,0.10013,288.290619,14.686224,1.001302,-1280.473145,294.500458,0
123.660004,64.789825,-1280.428711,-0.001513,0.003942,0.10013,288.199524,14.681584,1.001302,-1280.428711,294.500458,0
124.010002,65.219543,-1280.428711,-0.001522,0.003949,0.100294,290.111023,14.77896,1.002937,-1280.428711,294.500458,0
124.360008,65.261246,-1280.428711,-0.001535,0.003949,0.100294,290.296509,14.78841,1.002937,-1280.428711,294.500458,0
124.710007,65.267578,-1280.428711,-0.001522,0.003949,0.100294,290.324677,14.789845,1.002937,-1280.428711,294.500458,0
125.060005,65.25679,-1280.384155,-0.001526,0.003949,0.100294,290.276703,14.7874,1.002937,-1280.384155,294.500458,0
125.410004,65.238541,-1280.428711,-0.001526,0.003949,0.100294,290.195526,14.783265,1.002937,-1280.428711,294.500458,0
125.76001,65.219543,-1280.428711,-0.001509,0.003949,0.100294,290.111023,14.77896,1.002937,-1280.428711,294.500458,0
126.110008,65.190872,-1280.473145,-0.001518,0.003949,0.100294,289.98349,14.772463,1.002937,-1280.473145,294.500458,0
126.460007,65.149918,-1280.517578,-0.001531,0.003949,0.100294,289.8013,14.763183,1.002937,-1280.517578,294.500458,0
126.810005,65.125336,-1280.473145,-0.001513,0.003949,0.100294,289.691956,14.757612,1.002937,-1280.473145,294.500458,0
127.160004,65.110062,-1280.428711,-0.001513,0.003949,0.100294,289.624023,14.75415,1.002937,-1280.428711,294.500458,0
127.51001,65.085114,-1280.473145,-0.001518,0.003949,0.100294,289.513031,14.748498,1.002937,-1280.473145,294.500458,0
127.860008,65.038574,-1280.428711,-0.001531,0.003949,0.100294,289.30603,14.737952,1.002937,-1280.428711,294.500458,0
128.210007,65.017349,-1280.428711,-0.001522,0.003949,0.100294,289.211609,14.733142,1.002937,-1280.428711,294.500458,0
128.560013,64.997986,-1280.473145,-0.001522,0.003949,0.100294,289.125488,14.728754,1.002937,-1280.473145,294.500458,0
128.910004,64.980484,-1280.473145,-0.001513,0.003949,0.100294,289.047638,14.724789,1.002937,-1280.473145,294.500458,0
129.26001,64.936539,-1280.428711,-0.001526,0.003949,0.100294,288.852142,14.71483,1.002937,-1280.428711,294.500458,0
129.610001,64.920151,-1280.473145,-0.001509,0.003949,0.100303,288.779266,14.711117,1.003027,-1280.473145,294.500458,0
129.960007,64.886642,-1280.517578,-0.001509,0.003949,0.100303,288.630188,14.703523,1.003027,-1280.517578,294.500458,0
130.310013,64.850891,-1280.428711,-0.0015,0.003949,0.100303,288.471161,14.695421,1.003027,-1280.428711,294.500458,0
130.660004,64.821472,-1280.428711,-0.001509,0.003949,0.100303,288.340302,14.688755,1.003027,-1280.428711,294.500458,0
131.01001,64.799133,-1280.428711,-0.001505,0.003949,0.100303,288.240936,14.683693,1.003027,-1280.428711,294.500458,0
131.360001,65.012878,-1280.428711,-0.001526,0.003956,0.100493,289.191711,14.732129,1.004935,-1280.428711,294.500458,0
131.710007,65.338699,-1280.428711,-0.001513,0.003956,0.100493,290.641052,14.805962,1.004935,-1280.428711,1681.640747,0
132.060013,65.352859,-1280.517578,-0.0015,0.003947,0.100259,290.704041,14.80917,1.002588,-1280.517578,0.100433,0
132.410004,65.227737,-1280.428711,-0.001509,0.003939,0.100061,290.147461,14.780817,1.000605,-1280.428711,0.099852,0
132.76001,65.250076,-1280.473145,-0.001492,0.003922,0.099609,290.246826,14.785879,0.996094,-1280.473145,0.09927,0
133.110001,65.105972,-1280.428711,-0.001487,0.003907,0.099244,289.605835,14.753223,0.992445,-1280.428711,0.098681,0
133.460007,65.070602,-1280.473145,-0.001496,0.003884,0.098663,289.448486,14.74521,0.986631,-1280.473145,0.0981,0
133.810013,65.037827,-1280.428711,-0.001496,0.003863,0.098109,289.302704,14.737782,0.98109,-1280.428711,0.097519,0
134.160004,65.005432,-1280.473145,-0.001492,0.003843,0.097606,289.1586,14.730441,0.976064,-1280.473145,0.096939,0
134.51001,64.931702,-1280.428711,-0.0015,0.003817,0.096946,288.830627,14.713734,0.969463,-1280.428711,0.096348,0
134.860001,64.887024,-1280.428711,-0.001483,0.003795,0.0964,288.631897,14.70361,0.963998,-1280.428711,0.095767,0
135.210007,64.848663,-1280.473145,-0.001496,0.003775,0.095888,288.461273,14.694917,0.95888,-1280.473145,0.095186,0
135.560013,64.747009,-1280.517578,-0.0015,0.003751,0.095273,288.009094,14.671882,0.952734,-1280.517578,0.094606,0
135.910004,64.600296,-1280.428711,-0.001492,0.003728,0.094683,287.356476,14.638636,0.946829,-1280.428711,0.094015,0
136.26001,64.283768,-1280.473145,-0.001487,0.003711,0.09425,285.948486,14.566911,0.942499,-1280.473145,0.093434,0
136.610001,63.358795,-1280.428711,-0.001505,0.003681,0.093504,281.833984,14.357307,0.935036,-1280.428711,0.092854,0
136.960007,62.732468,-1280.384155,-0.001487,0.003669,0.093192,279.047943,14.215381,0.931917,-1280.384155,0.092264,0
137.310013,61.705467,-1280.517578,-0.001475,0.003648,0.092663,274.479614,13.982659,0.926633,-1280.517578,0.091682,0
137.660004,60.297523,-1280.428711,-0.001475,0.003621,0.091977,268.216766,13.663614,0.919775,-1280.428711,0.091101,0
138.01001,58.438644,-1280.428711,-0.001475,0.003594,0.091275,259.948059,13.242386,0.91275,-1280.428711,0.090521,0
138.360001,57.003517,-1280.428711,-0.001483,0.003576,0.090824,253.564316,12.917182,0.908239,-1280.428711,0.089931,0
138.710007,54.746941,-1280.428711,-0.001475,0.00355,0.090174,243.52655,12.405834,0.901744,-1280.428711,0.089349,0
139.060013,53.440285,-1280.473145,-0.00147,0.003533,0.08974,237.714264,12.109742,0.897399,-1280.473145,0.088769,0
139.410004,51.283508,-1280.517578,-0.001483,0.003512,0.089193,228.120438,11.621009,0.891933,-1280.517578,0.088188,0
139.76001,48.87426,-1280.428711,-0.001466,0.003488,0.088586,217.403564,11.075066,0.885862,-1280.428711,0.087598,0
140.110001,46.8452,-1280.384155,-0.001475,0.00347,0.088127,208.377853,10.615274,0.881275,-1280.384155,0.087018,0
140.460007,43.896751,-1280.473145,-0.001475,0.003442,0.087416,195.262497,9.947145,0.874159,-1280.473145,0.086436,0
140.810013,40.851494,-1280.473145,-0.001487,0.003414,0.086713,181.716522,9.257081,0.867135,-1280.473145,0.085846,0
141.160004,38.518204,-1280.384155,-0.001466,0.003393,0.086193,171.337524,8.72835,0.861927,-1280.384155,0.085265,0
141.51001,36.563622,-1280.384155,-0.001475,0.003374,0.085708,162.643112,8.285435,0.857082,-1280.384155,0.084685,0
141.860001,34.259758,-1280.428711,-0.001479,0.003353,0.085169,152.39502,7.763372,0.851692,-1280.428711,0.084103,0
142.210007,31.58947,-1280.517578,-0.0015,0.003327,0.084502,140.516983,7.158276,0.845016,-1280.517578,0.083513,0
142.560013,29.279648,-1280.517578,-0.0015,0.003307,0.083999,130.242386,6.634863,0.839989,-1280.517578,0.082933,0
142.910004,26.06868,-1280.428711,-0.0015,0.003275,0.083192,115.959282,5.907247,0.83192,-1280.428711,0.082352,0
143.26001,23.998657,-1280.384155,-0.001496,0.003256,0.082715,106.751358,5.438173,0.827151,-1280.384155,0.08177,0
143.610001,21.53653,-1280.517578,-0.001513,0.003233,0.082117,95.799271,4.880247,0.821171,-1280.517578,0.08118,0
143.960007,19.500771,-1280.473145,-0.001522,0.003216,0.081675,86.743759,4.418938,0.81675,-1280.473145,0.0806,0
144.310013,16.880013,-1280.473145,-0.001526,0.003191,0.081042,75.086044,3.825065,0.810422,-1280.473145,0.080019,0
144.660004,14.048119,-1280.473145,-0.001513,0.003165,0.0804,62.489151,3.183349,0.804003,-1280.473145,0.079437,0
145.01001,11.602753,-1280.428711,-0.001518,0.003143,0.079845,51.611622,2.629221,0.798446,-1280.428711,0.078848,0
145.360001,9.404266,-1280.428711,-0.001535,0.003122,0.079291,41.832268,2.131037,0.792905,-1280.428711,0.078267,0
145.710007,7.364784,-1280.517578,-0.001535,0.003103,0.078814,32.760197,1.668884,0.788136,-1280.517578,0.077686,0
146.060013,4.872864,-1280.562134,-0.001544,0.003074,0.078067,21.675581,1.104207,0.780672,-1280.562134,0.077095,0
146.410004,2.106506,-1280.428711,-0.001535,0.003052,0.077521,9.370208,0.477341,0.775207,-1280.428711,0.076515,0
146.76001,-0.274071,-1280.473145,-0.001552,0.003026,0.076871,-1.219128,-0.062105,0.768712,-1280.473145,0.075934,0
147.110001,-2.652412,-1280.606567,-0.001561,0.003004,0.076307,-11.79852,-0.601045,0.763065,-1280.606567,0.075353,0
147.460007,-4.399956,-1280.517578,-0.001552,0.002984,0.075786,-19.571981,-0.997044,0.757857,-1280.517578,0.074764,0
147.810013,0.001114,-1280.473145,-0.001604,0.002966,0.075336,0.004955,0.000252,0.753361,-1280.473145,0.074182,0
148.160004,-0.001488,-1280.517578,-0.001643,0.002938,0.074625,-0.006618,-0.000337,0.746245,-1280.517578,0.073601,0
148.51001,0.025322,-1280.473145,-0.001647,0.002918,0.074129,0.112638,0.005738,0.741294,-1280.473145,0.07302,0
148.860001,0.006332,-1280.473145,-0.001677,0.002891,0.073436,0.028168,0.001435,0.73436,-1280.473145,0.072431,0
149.210007,-0.044685,-1280.517578,-0.001712,0.002867,0.072812,-0.19877,-0.010126,0.728123,-1280.517578,0.071849,0
149.560013,-0.051392,-1280.517578,-0.001725,0.002849,0.072352,-0.228601,-0.011646,0.723521,-1280.517578,0.071268,0
149.910004,0.001114,-1280.562134,-0.001755,0.002821,0.071659,0.004955,0.000252,0.716587,-1280.562134,0.070687,0
150.26001,-0.001862,-1280.517578,-0.001772,0.002802,0.071182,-0.008281,-0.000422,0.711818,-1280.517578,0.070098,0
150.610001,-0.032394,-1280.562134,-0.001785,0.002777,0.07054,-0.144098,-0.007341,0.705398,-1280.562134,0.069516,0
150.960007,-0.018623,-1280.517578,-0.001815,0.00275,0.069837,-0.082841,-0.00422,0.698374,-1280.517578,0.068935,0
151.310013,-0.020485,-1280.473145,-0.001841,0.002729,0.069326,-0.091121,-0.004642,0.693256,-1280.473145,0.068346,0
151.660004,-0.024948,-1280.517578,-0.001863,0.002713,0.068918,-0.110975,-0.005653,0.689184,-1280.517578,0.067765,0
152.01001,-0.043571,-1280.517578,-0.001884,0.002682,0.068128,-0.193816,-0.009873,0.681281,-1280.517578,0.067183,0
152.360001,-0.038353,-1280.562134,-0.00191,0.002668,0.067774,-0.170603,-0.008691,0.677738,-1280.562134,0.066602,0
152.710007,-0.053993,-1280.562134,-0.00194,0.00264,0.067062,-0.240174,-0.012235,0.670623,-1280.562134,0.066013,0
153.060013,-0.023087,-1280.562134,-0.001953,0.002616,0.066437,-0.102694,-0.005231,0.66437,-1280.562134,0.065432,0
153.200012,-0.003723,-1280.517578,-0.001962,0.002612,0.066342,-0.016561,-0.000844,0.663416,-1280.517578,0.066178,0