File: Data/compression 36/Heating-15-36-reverse-1-5_11202024_171027(in).csv
Time (sec),S:Load (lbs),S:HL1 (DIM),S:LVDT (in),S:Position (in),Ch:Position (mm),Ch:Load (N),Ch:Stress (MPa),Ch:Strain (mm/mm),Ch:HL1 (DIM),Set Point (),Cycles ()
0.11,-0.046547,-1278.871826,-0.013672,-0.008926,-0.22672,-0.207051,-0.010548,-2.267198,-1278.871826,-0.226529,0
0.56,-0.050644,-1278.871826,-0.013655,-0.008808,-0.223728,-0.225275,-0.011476,-2.237282,-1278.871826,-0.222956,0
1.01,-0.081924,-1278.91626,-0.013456,-0.008535,-0.21679,-0.364418,-0.018564,-2.167897,-1278.91626,-0.215463,0
1.46,-0.057716,-1278.91626,-0.013124,-0.008242,-0.209358,-0.256735,-0.013079,-2.093577,-1278.91626,-0.207969,0
1.91,0.002602,-1278.871826,-0.012814,-0.007943,-0.201744,0.011573,0.00059,-2.01744,-1278.871826,-0.20046,0
2.36,-0.032394,-1278.871826,-0.012512,-0.00765,-0.19432,-0.144098,-0.007341,-1.943195,-1278.871826,-0.192968,0
2.81,-0.097191,-1278.91626,-0.012227,-0.007356,-0.186853,-0.432327,-0.022024,-1.868527,-1278.91626,-0.185473,0
3.26,-0.037239,-1278.91626,-0.011895,-0.007058,-0.179265,-0.165648,-0.008438,-1.792647,-1278.91626,-0.177981,0
3.71,-0.022346,-1278.91626,-0.011581,-0.006764,-0.171798,-0.099402,-0.005064,-1.717979,-1278.91626,-0.170472,0
4.16,-0.030167,-1278.827393,-0.011292,-0.006471,-0.164357,-0.134188,-0.006836,-1.643568,-1278.827393,-0.162978,0
4.61,-0.055855,-1278.827393,-0.010986,-0.006177,-0.156899,-0.248455,-0.012657,-1.56899,-1278.827393,-0.155485,0
5.06,-0.07373,-1278.871826,-0.010675,-0.005878,-0.149293,-0.327969,-0.016708,-1.492929,-1278.871826,-0.147992,0
5.51,-0.095703,-1278.871826,-0.010365,-0.005585,-0.141861,-0.425709,-0.021687,-1.418609,-1278.871826,-0.140483,0
5.960001,-0.025696,-1278.91626,-0.010089,-0.005291,-0.134394,-0.114301,-0.005823,-1.34394,-1278.91626,-0.132989,0
6.41,-0.016762,-1278.960815,-0.009753,-0.004995,-0.126876,-0.07456,-0.003798,-1.268757,-1278.960815,-0.125497,0
6.86,-0.055855,-1278.91626,-0.009472,-0.004704,-0.119479,-0.248455,-0.012657,-1.194785,-1278.91626,-0.118004,0
7.31,-0.07634,-1278.871826,-0.009171,-0.004411,-0.112037,-0.339576,-0.017299,-1.120374,-1278.871826,-0.110511,0
7.76,-0.01825,-1278.871826,-0.008856,-0.00411,-0.104389,-0.081178,-0.004135,-1.043889,-1278.871826,-0.103001,0
8.21,-0.042824,-1278.91626,-0.008558,-0.003813,-0.096862,-0.19049,-0.009704,-0.968615,-1278.91626,-0.095508,0
8.660001,-0.029419,-1278.91626,-0.008252,-0.003524,-0.089498,-0.130862,-0.006666,-0.894976,-1278.91626,-0.088015,0
9.110001,-0.047668,-1278.91626,-0.007938,-0.003221,-0.081823,-0.21204,-0.010802,-0.818234,-1278.91626,-0.080523,0
9.56,-0.125122,-1278.960815,-0.007627,-0.002924,-0.074278,-0.556571,-0.028353,-0.742778,-1278.960815,-0.073012,0
10.01,-0.010429,-1278.871826,-0.007334,-0.002634,-0.066915,-0.046392,-0.002363,-0.669154,-1278.871826,-0.06552,0
10.46,0.017502,-1278.91626,-0.007036,-0.002337,-0.059371,0.077852,0.003966,-0.593714,-1278.91626,-0.058027,0
10.910001,-0.032768,-1278.871826,-0.006709,-0.002043,-0.051895,-0.14576,-0.007425,-0.518955,-1278.871826,-0.050534,0
11.360001,-0.049156,-1278.91626,-0.006416,-0.001749,-0.044429,-0.218658,-0.011139,-0.444286,-1278.91626,-0.043024,0
11.81,-0.046921,-1278.91626,-0.006101,-0.001452,-0.036883,-0.208714,-0.010632,-0.36883,-1278.91626,-0.035531,0
12.26,-0.035004,-1278.91626,-0.005816,-0.001158,-0.029425,-0.155704,-0.007932,-0.294253,-1278.91626,-0.028039,0
12.710001,-0.02681,-1278.91626,-0.005501,-0.000862,-0.021907,-0.119255,-0.006075,-0.21907,-1278.91626,-0.020544,0
13.160001,-0.019737,-1278.91626,-0.005191,-0.000565,-0.014354,-0.087796,-0.004473,-0.143538,-1278.91626,-0.013035,0
13.610001,-0.049156,-1278.91626,-0.004902,-0.00027,-0.00686,-0.218658,-0.011139,-0.068597,-1278.91626,-0.005543,0
14.06,0.157143,-1278.871826,-0.004648,0,-0.000009,0.699005,0.035609,-0.000091,-1278.871826,0.000138,0
14.51,0.144104,-1278.827393,-0.004652,0,-0.000009,0.641007,0.032654,-0.000091,-1278.827393,0.000198,0
14.960001,0.124374,-1278.91626,-0.004652,0,0.000008,0.553245,0.028184,0.000076,-1278.91626,0.000945,0
15.410001,0.196236,-1278.91626,-0.004631,0.000024,0.000607,0.8729,0.044468,0.006071,-1278.91626,0.001699,0
15.860001,0.30423,-1278.960815,-0.004613,0.000051,0.0013,1.353281,0.068939,0.013005,-1278.960815,0.002445,0
16.310001,0.492645,-1278.871826,-0.004583,0.000077,0.001968,2.191396,0.111635,0.019681,-1278.871826,0.003199,0
16.76,0.81028,-1278.871826,-0.004553,0.000113,0.00287,3.604305,0.183612,0.028705,-1278.871826,0.003945,0
17.210001,1.006523,-1278.91626,-0.004531,0.000137,0.003478,4.477239,0.228081,0.034776,-1278.91626,0.004699,0
17.660002,1.240372,-1278.827393,-0.004514,0.000168,0.004257,5.517449,0.281072,0.042572,-1278.827393,0.005446,0
18.110001,1.574387,-1278.91626,-0.004471,0.000199,0.005064,7.003222,0.356761,0.050642,-1278.91626,0.0062,0
18.560001,1.953835,-1278.871826,-0.004437,0.00023,0.005844,8.69109,0.442745,0.058439,-1278.871826,0.006946,0
19.01,2.152687,-1278.91626,-0.004419,0.000254,0.00646,9.57563,0.487806,0.064601,-1278.91626,0.0077,0
19.460001,2.477394,-1278.91626,-0.004389,0.000283,0.007181,11.02,0.561386,0.071807,-1278.91626,0.008446,0
19.910002,2.838593,-1278.91626,-0.004372,0.000313,0.007944,12.62669,0.643234,0.079437,-1278.91626,0.0092,0
20.360001,3.318954,-1278.91626,-0.004346,0.000348,0.008845,14.763447,0.752086,0.088445,-1278.91626,0.009947,0
20.810001,3.62616,-1278.91626,-0.004312,0.000379,0.009617,16.129963,0.8217,0.096167,-1278.91626,0.010701,0
21.26,3.978424,-1278.91626,-0.004277,0.000408,0.010363,17.696915,0.901524,0.10363,-1278.91626,0.011447,0
21.710001,4.193283,-1278.827393,-0.004238,0.000432,0.010979,18.652655,0.950212,0.109792,-1278.827393,0.012201,0
22.160002,4.645348,-1278.871826,-0.004234,0.000466,0.011829,20.663538,1.052651,0.118286,-1278.871826,0.012947,0
22.610001,4.932442,-1278.871826,-0.004174,0.000496,0.012592,21.940596,1.117707,0.125916,-1278.871826,0.013701,0
23.060001,5.049744,-1278.91626,-0.004182,0.000516,0.013094,22.462381,1.144288,0.130942,-1278.91626,0.014448,0
23.51,5.561752,-1278.91626,-0.004122,0.000552,0.014022,24.73991,1.260311,0.140223,-1278.91626,0.015202,0
23.960001,5.917366,-1278.91626,-0.004113,0.000584,0.014829,26.321758,1.340894,0.148292,-1278.91626,0.015948,0
24.410002,6.274849,-1278.91626,-0.004083,0.000617,0.015671,27.911922,1.421901,0.15671,-1278.91626,0.016702,0
24.860001,6.347832,-1278.91626,-0.004057,0.00064,0.01626,28.236567,1.438439,0.162599,-1278.91626,0.017448,0
25.310001,6.628227,-1278.960815,-0.004023,0.000667,0.016946,29.483828,1.501978,0.169457,-1278.960815,0.018202,0
25.760002,6.872879,-1278.91626,-0.003992,0.000696,0.017674,30.572092,1.557417,0.176739,-1278.91626,0.018949,0
26.210001,7.485428,-1278.871826,-0.00398,0.000733,0.018619,33.296844,1.696222,0.186187,-1278.871826,0.019703,0
26.660002,7.524529,-1278.871826,-0.003945,0.000761,0.01933,33.470776,1.705083,0.193302,-1278.871826,0.020449,0
27.110001,7.794502,-1278.91626,-0.003906,0.000791,0.020084,34.671677,1.766259,0.200842,-1278.91626,0.021203,0
27.560001,8.011223,-1278.871826,-0.00388,0.000815,0.020709,35.6357,1.815369,0.207094,-1278.871826,0.021949,0
28.010002,8.265549,-1278.91626,-0.003859,0.000842,0.021377,36.766998,1.873,0.213771,-1278.91626,0.022694,0
28.460001,8.689682,-1278.871826,-0.003829,0.000876,0.022252,38.653637,1.96911,0.222522,-1278.871826,0.02345,0
28.910002,8.793205,-1278.960815,-0.003798,0.000902,0.022903,39.114132,1.992569,0.229032,-1278.960815,0.024195,0
29.360001,9.122375,-1278.871826,-0.003768,0.000933,0.02371,40.578354,2.06716,0.237101,-1278.871826,0.02495,0
29.810001,9.387138,-1278.871826,-0.003742,0.00096,0.024394,41.756077,2.127156,0.243944,-1278.871826,0.025695,0
30.260002,10.036926,-1278.91626,-0.003725,0.001001,0.025427,44.646477,2.2744,0.254269,-1278.91626,0.02645,0
30.710001,10.04512,-1278.827393,-0.003686,0.001028,0.026111,44.682926,2.276257,0.261112,-1278.827393,0.027195,0
31.160002,10.154594,-1278.91626,-0.003639,0.001053,0.026753,45.169891,2.301064,0.267532,-1278.91626,0.027951,0
31.610001,10.49234,-1278.827393,-0.003622,0.001084,0.027534,46.67226,2.377598,0.275344,-1278.827393,0.028696,0
32.060001,10.951843,-1278.960815,-0.0036,0.001118,0.028402,48.716232,2.481723,0.284019,-1278.960815,0.029451,0
32.510002,10.947006,-1278.871826,-0.003561,0.001144,0.02906,48.694717,2.480627,0.290604,-1278.871826,0.030196,0
32.960003,11.215111,-1278.871826,-0.00354,0.001175,0.02984,49.887302,2.54138,0.298401,-1278.871826,0.030951,0
33.41,11.263893,-1278.91626,-0.00351,0.001198,0.030431,50.104298,2.552435,0.304306,-1278.91626,0.031696,0
33.860001,11.762497,-1278.871826,-0.003492,0.001232,0.031289,52.322201,2.66542,0.31289,-1278.871826,0.032452,0
34.310001,11.960976,-1278.91626,-0.003454,0.00126,0.031991,53.205078,2.710396,0.319914,-1278.91626,0.033197,0
34.760002,11.795639,-1278.91626,-0.003423,0.001284,0.032608,52.469624,2.67293,0.326076,-1278.91626,0.033952,0
35.210003,12.18663,-1278.871826,-0.003393,0.001315,0.033413,54.208839,2.76153,0.334131,-1278.871826,0.034697,0
35.66,12.804771,-1279.005249,-0.003363,0.001352,0.034334,56.958469,2.901603,0.343335,-1279.005249,0.035452,0
36.110001,13.034149,-1278.91626,-0.003337,0.00138,0.035062,57.97879,2.95358,0.350618,-1278.91626,0.036197,0
36.560001,12.931007,-1278.91626,-0.003285,0.001404,0.035669,57.519993,2.930208,0.356688,-1278.91626,0.036953,0
37.010002,13.360352,-1278.871826,-0.003272,0.00144,0.03657,59.429813,3.027499,0.365697,-1278.871826,0.037698,0
37.460003,13.311569,-1278.91626,-0.003242,0.001468,0.03729,59.212818,3.016445,0.372903,-1278.91626,0.038453,0
37.910004,14.057434,-1278.91626,-0.003216,0.001502,0.03814,62.53059,3.18546,0.381396,-1278.91626,0.039198,0
38.360001,14.066742,-1278.91626,-0.003178,0.001528,0.0388,62.571995,3.187569,0.387997,-1278.91626,0.039952,0
38.810001,13.994499,-1278.960815,-0.00316,0.001549,0.039337,62.250641,3.171199,0.393372,-1278.960815,0.040698,0
39.260002,14.391075,-1278.871826,-0.003139,0.00158,0.040144,64.014702,3.261064,0.401441,-1278.871826,0.041452,0
39.710003,14.731796,-1278.91626,-0.003091,0.001611,0.040915,65.530304,3.338273,0.409147,-1278.91626,0.042199,0
40.160004,15.183487,-1278.91626,-0.00307,0.001649,0.041878,67.53952,3.440627,0.418776,-1278.91626,0.042953,0
40.610001,15.293709,-1278.960815,-0.003027,0.001676,0.042571,68.029816,3.465604,0.42571,-1278.960815,0.043699,0
41.060001,15.361481,-1278.91626,-0.003027,0.001703,0.043266,68.331276,3.480961,0.432659,-1278.91626,0.044453,0
41.510002,15.584534,-1278.960815,-0.002984,0.001729,0.043908,69.323471,3.531506,0.439078,-1278.960815,0.045199,0
41.960003,16.130432,-1278.960815,-0.002936,0.001764,0.044809,71.751747,3.655208,0.448086,-1278.960815,0.045953,0
42.410004,16.307304,-1279.005249,-0.002928,0.001794,0.045572,72.538513,3.695288,0.455716,-1279.005249,0.0467,0
42.860001,16.642441,-1278.91626,-0.00288,0.001825,0.046362,74.029274,3.771231,0.463619,-1278.91626,0.047453,0
43.310001,16.589935,-1278.960815,-0.002841,0.001848,0.046951,73.795715,3.759333,0.469509,-1278.960815,0.0482,0
43.760002,17.260208,-1278.960815,-0.002815,0.001886,0.047897,76.777237,3.911219,0.478971,-1278.960815,0.048954,0
44.210003,17.082214,-1279.005249,-0.002807,0.001909,0.048486,75.985481,3.870885,0.48486,-1279.005249,0.0497,0
44.660004,17.417717,-1279.005249,-0.002781,0.001936,0.049179,77.477875,3.946911,0.491794,-1279.005249,0.050454,0
45.110001,17.371918,-1279.005249,-0.002759,0.001963,0.049865,77.274147,3.936533,0.498652,-1279.005249,0.051201,0
45.560001,18.385513,-1279.049805,-0.002703,0.002003,0.050871,81.782845,4.166217,0.508705,-1279.049805,0.051954,0
46.010002,18.616386,-1279.049805,-0.00269,0.002033,0.051643,82.809822,4.218534,0.516426,-1279.049805,0.052701,0
46.460003,18.365036,-1279.049805,-0.002665,0.002057,0.052241,81.691757,4.161577,0.522406,-1279.049805,0.053455,0
46.910004,18.964928,-1279.005249,-0.002634,0.002086,0.052996,84.360214,4.297514,0.529961,-1279.005249,0.054201,0
47.360001,19.198402,-1279.049805,-0.002613,0.002115,0.053733,85.398758,4.35042,0.537334,-1279.049805,0.054948,0
47.810001,19.826225,-1279.049805,-0.002565,0.002149,0.054574,88.191452,4.492687,0.545736,-1279.049805,0.055702,0
48.260002,19.83963,-1279.094238,-0.002539,0.002175,0.055234,88.251083,4.495724,0.552337,-1279.094238,0.056448,0
48.710003,20.27121,-1279.005249,-0.002518,0.002206,0.056032,90.170845,4.593522,0.560316,-1279.005249,0.057202,0
49.160004,20.078697,-1279.005249,-0.002509,0.002231,0.056655,89.314507,4.549898,0.566553,-1279.005249,0.057948,0
49.610001,21.400246,-1279.049805,-0.002449,0.00227,0.057661,95.193047,4.849365,0.576606,-1279.049805,0.058702,0
50.060001,20.925095,-1279.049805,-0.00241,0.002292,0.058225,93.079468,4.741694,0.582253,-1279.049805,0.059447,0
50.510002,21.433754,-1279.094238,-0.002402,0.002319,0.058893,95.342102,4.856958,0.58893,-1279.094238,0.060203,0
50.960003,21.905922,-1279.094238,-0.002363,0.002349,0.059673,97.442406,4.963953,0.596727,-1279.094238,0.060947,0
51.410004,22.407509,-1279.049805,-0.002345,0.002383,0.06054,99.673576,5.077614,0.605402,-1279.049805,0.061703,0
51.860001,23.01001,-1279.094238,-0.002311,0.002414,0.061321,102.353638,5.214143,0.613214,-1279.094238,0.062448,0
52.310001,23.189117,-1279.094238,-0.002281,0.002442,0.062031,103.150345,5.254729,0.620314,-1279.094238,0.063203,0
52.760002,23.155235,-1279.138672,-0.002251,0.002468,0.062682,102.999634,5.247051,0.626824,-1279.138672,0.063948,0
53.210003,23.409935,-1279.138672,-0.002225,0.002495,0.063376,104.132591,5.304767,0.633758,-1279.138672,0.064704,0
53.660004,24.689034,-1279.094238,-0.002199,0.002538,0.064469,109.822304,5.594615,0.644689,-1279.094238,0.065448,0
54.110004,24.514397,-1279.005249,-0.002177,0.00256,0.065032,109.045479,5.555041,0.650321,-1279.005249,0.066204,0
54.560001,24.704308,-1279.094238,-0.002134,0.002588,0.065735,109.890251,5.598076,0.657345,-1279.094238,0.066949,0
55.010002,24.868523,-1279.049805,-0.002121,0.002612,0.066334,110.620712,5.635288,0.663341,-1279.049805,0.067704,0
55.460003,26.431366,-1279.138672,-0.002104,0.002652,0.067358,117.572586,5.989433,0.673575,-1279.138672,0.068449,0
55.910004,26.272736,-1279.138672,-0.002039,0.002674,0.067921,116.866966,5.953487,0.679207,-1279.138672,0.069205,0
56.360004,27.088974,-1279.094238,-0.002026,0.002708,0.068779,120.497772,6.138449,0.687791,-1279.094238,0.069949,0
56.810001,26.849167,-1279.094238,-0.001996,0.00273,0.069335,119.431061,6.084108,0.693347,-1279.094238,0.070705,0
57.260002,28.112633,-1279.138672,-0.001979,0.002766,0.070263,125.051239,6.370414,0.702628,-1279.138672,0.07145,0
57.710003,28.696884,-1279.138672,-0.001962,0.002797,0.071052,127.650116,6.502807,0.710516,-1279.138672,0.072205,0
58.160004,29.229744,-1279.138672,-0.00191,0.002829,0.071849,130.020401,6.623554,0.718494,-1279.138672,0.07295,0
58.610004,28.811203,-1279.138672,-0.001893,0.002851,0.072422,128.15863,6.528712,0.724217,-1279.138672,0.073706,0
59.060001,29.411469,-1279.183228,-0.001863,0.002878,0.073106,130.828751,6.664734,0.73106,-1279.183228,0.07445,0
59.510002,30.70211,-1279.138672,-0.001828,0.002917,0.074095,136.569809,6.957198,0.740946,-1279.138672,0.075206,0
59.960003,30.484268,-1279.094238,-0.001798,0.002937,0.07459,135.6008,6.907834,0.745897,-1279.094238,0.075951,0
60.410004,31.223801,-1279.138672,-0.001785,0.002966,0.075344,138.890396,7.075414,0.753436,-1279.138672,0.076706,0
60.860004,32.339058,-1279.094238,-0.00175,0.003002,0.076246,143.851318,7.328135,0.76246,-1279.094238,0.077451,0
61.310001,33.197372,-1279.183228,-0.001733,0.003032,0.077018,147.669281,7.522632,0.770181,-1279.183228,0.078207,0
61.760002,33.824448,-1279.183228,-0.00169,0.003065,0.077851,150.458664,7.66473,0.778507,-1279.183228,0.078951,0
62.210003,34.288803,-1279.138672,-0.001673,0.003092,0.078544,152.524216,7.769954,0.785441,-1279.138672,0.079707,0
62.660004,34.118996,-1279.138672,-0.001643,0.003113,0.079065,151.768875,7.731475,0.790649,-1279.138672,0.080452,0
63.110004,36.053848,-1279.138672,-0.001621,0.003155,0.08014,160.375534,8.169919,0.801399,-1279.138672,0.081207,0
63.560001,36.53495,-1279.049805,-0.001604,0.003184,0.080868,162.515579,8.278938,0.808681,-1279.049805,0.081952,0
64.010002,36.976959,-1279.094238,-0.001561,0.003207,0.081466,164.481735,8.379099,0.814661,-1279.094238,0.082708,0
64.460007,37.73436,-1279.049805,-0.001552,0.003237,0.082212,167.850815,8.550728,0.822125,-1279.049805,0.083452,0
64.910004,38.98851,-1279.049805,-0.0015,0.003272,0.083106,173.42955,8.834922,0.831057,-1279.049805,0.084208,0
65.360001,39.584679,-1279.094238,-0.001483,0.003299,0.083799,176.081451,8.970016,0.837991,-1279.094238,0.084953,0
65.810005,39.791344,-1279.049805,-0.001457,0.00332,0.084329,177.000732,9.016848,0.84329,-1279.049805,0.085707,0
66.260002,41.432762,-1279.138672,-0.001449,0.003357,0.085274,184.302124,9.388798,0.852737,-1279.138672,0.086453,0
66.710007,42.35215,-1279.138672,-0.001427,0.003383,0.085925,188.391769,9.597134,0.859247,-1279.138672,0.087199,0
67.160004,43.973465,-1279.138672,-0.001393,0.003418,0.086825,195.603745,9.96453,0.868255,-1279.138672,0.087953,0
67.610001,44.602776,-1279.138672,-0.00138,0.003444,0.087467,198.403061,10.107134,0.874674,-1279.138672,0.0887,0
68.060005,45.554558,-1279.094238,-0.001358,0.003472,0.088188,202.636795,10.32281,0.881881,-1279.094238,0.089454,0
68.510002,46.358139,-1279.138672,-0.001328,0.003497,0.08883,206.211304,10.504905,0.8883,-1279.138672,0.0902,0
68.960007,48.640778,-1279.049805,-0.001319,0.003539,0.089896,216.36499,11.022158,0.898958,-1279.049805,0.090954,0
69.410004,49.505058,-1279.094238,-0.001285,0.003563,0.090512,220.209503,11.218006,0.90512,-1279.094238,0.0917,0
69.860001,50.575996,-1279.138672,-0.001259,0.003592,0.091231,224.973267,11.460684,0.912311,-1279.138672,0.092454,0
70.310005,51.560181,-1279.094238,-0.00125,0.003621,0.091968,229.351135,11.683703,0.919684,-1279.094238,0.093201,0
70.760002,52.313118,-1279.094238,-0.001224,0.003638,0.09241,232.700363,11.854322,0.924105,-1279.094238,0.093955,0
71.210007,54.782318,-1279.138672,-0.001212,0.00368,0.093469,243.683914,12.41385,0.934687,-1279.138672,0.094701,0
71.660004,55.692772,-1279.094238,-0.001199,0.003707,0.094145,247.733826,12.620163,0.941455,-1279.094238,0.095455,0
72.110001,57.264183,-1279.094238,-0.001173,0.003731,0.094778,254.723801,12.97625,0.947783,-1279.094238,0.096201,0
72.560005,59.200516,-1279.138672,-0.00116,0.003765,0.095629,263.337036,13.415029,0.956292,-1279.138672,0.096955,0
73.010002,61.703232,-1279.094238,-0.001138,0.003803,0.096591,274.469696,13.982152,0.965905,-1279.094238,0.097702,0
73.460007,62.931686,-1279.138672,-0.001125,0.003829,0.097258,279.934113,14.260524,0.972582,-1279.138672,0.098456,0
73.910004,64.548523,-1279.138672,-0.001104,0.003856,0.097944,287.12616,14.626904,0.97944,-1279.138672,0.099202,0
74.360001,66.010086,-1279.094238,-0.001091,0.003884,0.098656,293.627533,14.958099,0.986556,-1279.094238,0.099956,0
74.810005,65.139862,-1279.138672,-0.001065,0.003879,0.098516,289.756592,14.760904,0.985163,-1279.138672,294.500458,0
75.260002,65.521164,-1279.138672,-0.001069,0.003898,0.099011,291.452698,14.847308,0.990113,-1279.138672,294.500458,0
75.710007,65.830231,-1279.094238,-0.001061,0.00391,0.099305,292.827484,14.917343,0.99305,-1279.094238,294.500458,0
76.160004,64.986069,-1279.138672,-0.001043,0.00391,0.099314,289.072479,14.726054,0.993141,-1279.138672,294.500458,0
76.610001,65.709961,-1279.183228,-0.001052,0.003915,0.099444,292.292511,14.89009,0.994443,-1279.183228,294.500458,0
77.060005,64.935425,-1279.183228,-0.001043,0.003916,0.099461,288.847198,14.714578,0.99461,-1279.183228,294.500458,0
77.510002,65.743103,-1279.183228,-0.001026,0.00393,0.099817,292.439941,14.8976,0.998168,-1279.183228,294.500458,0
77.960007,65.08847,-1279.138672,-0.001018,0.003931,0.099852,289.527985,14.749258,0.998516,-1279.138672,294.500458,0
78.410004,65.571808,-1279.183228,-0.001018,0.003945,0.100191,291.677979,14.858784,1.001907,-1279.183228,294.500458,0
78.860001,65.214706,-1279.094238,-0.001018,0.003945,0.100198,290.089508,14.777864,1.001983,-1279.094238,294.500458,0
79.310005,65.270935,-1279.138672,-0.001013,0.003951,0.100354,290.33963,14.790605,1.003542,-1279.138672,294.500458,0
79.760002,65.34317,-1279.138672,-0.001005,0.003956,0.100477,290.66095,14.806974,1.004768,-1279.138672,294.500458,0
80.210007,65.109695,-1279.183228,-0.001005,0.003956,0.100477,289.622375,14.754068,1.004768,-1279.183228,294.500458,0
80.660004,64.965591,-1279.183228,-0.000992,0.003958,0.100537,288.981384,14.721414,1.005374,-1279.183228,294.500458,0
81.110001,65.53569,-1279.138672,-0.001009,0.003969,0.100814,291.517303,14.850599,1.008145,-1279.138672,294.500458,0
81.560005,65.489517,-1279.094238,-0.000992,0.003968,0.100798,291.31192,14.840137,1.007978,-1279.094238,294.500458,0
82.010002,65.263855,-1279.183228,-0.000983,0.003968,0.100798,290.308136,14.789001,1.007978,-1279.183228,294.500458,0
82.460007,65.009903,-1279.183228,-0.000979,0.003968,0.100798,289.178497,14.731455,1.007978,-1279.183228,294.500458,0
82.910004,65.171509,-1279.183228,-0.000979,0.003976,0.100979,289.897339,14.768075,1.009795,-1279.183228,294.500458,0
83.360001,65.17337,-1279.183228,-0.000987,0.003976,0.100979,289.90564,14.768497,1.009795,-1279.183228,294.500458,0
83.810005,64.974152,-1279.138672,-0.000974,0.003976,0.100979,289.01947,14.723353,1.009795,-1279.138672,294.500458,0
84.260002,65.067993,-1279.183228,-0.000992,0.003979,0.101066,289.43689,14.744618,1.010658,-1279.183228,294.500458,0
84.710007,64.940262,-1279.183228,-0.000974,0.003979,0.101075,288.868713,14.715673,1.010749,-1279.183228,294.500458,0
85.160004,65.192368,-1279.183228,-0.000987,0.003984,0.101196,289.990143,14.772801,1.01196,-1279.183228,294.500458,0
85.610001,65.078415,-1279.183228,-0.000979,0.003984,0.101196,289.483246,14.74698,1.01196,-1279.183228,294.500458,0
86.060005,64.952179,-1279.183228,-0.00097,0.003984,0.101196,288.921722,14.718374,1.01196,-1279.183228,294.500458,0
86.510002,64.997604,-1279.183228,-0.000979,0.003987,0.101275,289.123779,14.728667,1.012747,-1279.183228,294.500458,0
86.960007,64.931335,-1279.183228,-0.000957,0.003987,0.101282,288.82901,14.713651,1.012823,-1279.183228,294.500458,0
87.410004,64.877335,-1279.094238,-0.000961,0.003989,0.101317,288.588806,14.701414,1.013171,-1279.094238,294.500458,0
87.860001,65.306686,-1279.183228,-0.000949,0.003994,0.101456,290.498657,14.798706,1.014564,-1279.183228,294.500458,0
88.310005,65.258652,-1279.183228,-0.000966,0.003994,0.101456,290.284973,14.787822,1.014564,-1279.183228,294.500458,0
88.760002,65.114166,-1279.183228,-0.000966,0.003994,0.101456,289.642273,14.755081,1.014564,-1279.183228,294.500458,0
89.210007,65.019577,-1279.183228,-0.000966,0.003994,0.101456,289.221527,14.733647,1.014564,-1279.183228,294.500458,0
89.660004,64.91011,-1279.183228,-0.000957,0.003994,0.101456,288.734589,14.708841,1.014564,-1279.183228,294.500458,0
90.110001,64.980103,-1279.183228,-0.000949,0.003998,0.101543,289.045929,14.724701,1.015427,-1279.183228,294.500458,0
90.560005,64.94548,-1279.183228,-0.000966,0.003998,0.101543,288.891937,14.716857,1.015427,-1279.183228,294.500458,0
91.010002,64.859833,-1279.183228,-0.00094,0.003998,0.101543,288.510956,14.697448,1.015427,-1279.183228,294.500458,0
91.460007,65.01474,-1279.183228,-0.000966,0.004003,0.101664,289.200012,14.732551,1.016638,-1279.183228,294.500458,0
91.910004,65.083633,-1279.227661,-0.000953,0.004003,0.101664,289.50647,14.748162,1.016638,-1279.227661,294.500458,0
92.360001,65.027023,-1279.138672,-0.00094,0.004003,0.101664,289.254639,14.735333,1.016638,-1279.138672,294.500458,0
92.810005,64.965591,-1279.138672,-0.000961,0.004003,0.101664,288.981384,14.721414,1.016638,-1279.138672,294.500458,0
93.260002,64.898193,-1279.183228,-0.000961,0.004003,0.101664,288.68158,14.706141,1.016638,-1279.183228,294.500458,0
93.710007,65.028519,-1279.183228,-0.000953,0.004006,0.101743,289.261292,14.735673,1.017425,-1279.183228,294.500458,0
94.160004,64.995743,-1279.183228,-0.000949,0.004006,0.101743,289.115509,14.728246,1.017425,-1279.183228,294.500458,0
94.610008,64.944733,-1279.227661,-0.000936,0.004006,0.101743,288.888611,14.716687,1.017425,-1279.227661,294.500458,0
95.060005,64.86467,-1279.183228,-0.000966,0.004006,0.101743,288.532471,14.698545,1.017425,-1279.183228,294.500458,0
95.510002,64.829666,-1279.227661,-0.000944,0.004007,0.101768,288.37677,14.690613,1.017683,-1279.227661,294.500458,0
95.960007,64.893723,-1279.227661,-0.000953,0.004009,0.101829,288.661682,14.705128,1.018288,-1279.227661,294.500458,0
96.410004,64.937286,-1279.272095,-0.000949,0.004009,0.101829,288.855469,14.714999,1.018288,-1279.272095,294.500458,0
96.860008,64.879562,-1279.227661,-0.00094,0.004009,0.101838,288.598694,14.701919,1.018379,-1279.227661,294.500458,0
97.310005,64.816269,-1279.272095,-0.000953,0.004009,0.101838,288.317169,14.687577,1.018379,-1279.272095,294.500458,0
97.760002,64.799515,-1279.227661,-0.000949,0.004011,0.101873,288.242645,14.68378,1.018727,-1279.227661,294.500458,0
98.210007,64.857605,-1279.272095,-0.000936,0.004012,0.101908,288.501038,14.696943,1.019075,-1279.272095,294.500458,0
98.660004,64.879944,-1279.272095,-0.000949,0.004013,0.101924,288.600403,14.702005,1.019242,-1279.272095,294.500458,0
99.110008,64.871384,-1279.183228,-0.000936,0.004013,0.101924,288.562317,14.700066,1.019242,-1279.183228,294.500458,0
99.560005,64.820358,-1279.227661,-0.000936,0.004013,0.101924,288.335358,14.688503,1.019242,-1279.227661,294.500458,0
100.010002,64.792801,-1279.272095,-0.00094,0.004013,0.101933,288.212769,14.682259,1.019333,-1279.272095,294.500458,0
100.460007,64.790573,-1279.272095,-0.000936,0.004018,0.102045,288.20285,14.681754,1.020453,-1279.272095,294.500458,0
100.910004,65.219177,-1279.227661,-0.000936,0.004019,0.102073,290.109375,14.778876,1.020726,-1279.227661,294.500458,0
101.360008,65.215073,-1279.272095,-0.00094,0.004019,0.102073,290.091125,14.777947,1.020726,-1279.272095,294.500458,0
101.810005,65.178955,-1279.227661,-0.000927,0.004019,0.102073,289.930481,14.769762,1.020726,-1279.227661,294.500458,0
102.260002,65.10672,-1279.227661,-0.000918,0.004019,0.102073,289.609161,14.753393,1.020726,-1279.227661,294.500458,0
102.710007,65.114914,-1279.227661,-0.000918,0.004019,0.102073,289.645599,14.75525,1.020726,-1279.227661,294.500458,0
103.160004,65.067245,-1279.31665,-0.000927,0.004019,0.102073,289.433563,14.744449,1.020726,-1279.31665,294.500458,0
103.610008,65.03299,-1279.227661,-0.000949,0.004019,0.102073,289.281189,14.736687,1.020726,-1279.227661,294.500458,0
104.060005,64.96373,-1279.31665,-0.000931,0.004019,0.10208,288.973114,14.720992,1.020801,-1279.31665,294.500458,0
104.510002,64.922028,-1279.227661,-0.000944,0.004019,0.10208,288.787598,14.711542,1.020801,-1279.227661,294.500458,0
104.960007,65.394196,-1279.272095,-0.000923,0.004026,0.102254,290.887909,14.818537,1.022542,-1279.272095,294.500458,0
105.410004,65.409454,-1279.272095,-0.000931,0.004026,0.102254,290.95578,14.821995,1.022542,-1279.272095,294.500458,0
105.860008,65.417648,-1279.272095,-0.000936,0.004025,0.102245,290.992218,14.823851,1.022452,-1279.272095,294.500458,0
106.310005,65.387863,-1279.361084,-0.000923,0.004025,0.102245,290.859741,14.817101,1.022452,-1279.361084,294.500458,0
106.760002,65.358444,-1279.272095,-0.000923,0.004025,0.102245,290.728882,14.810435,1.022452,-1279.272095,294.500458,0
107.210007,65.317474,-1279.272095,-0.000923,0.004025,0.102245,290.546631,14.801151,1.022452,-1279.272095,294.500458,0
107.660004,65.287323,-1279.31665,-0.000923,0.004025,0.102245,290.412506,14.794319,1.022452,-1279.31665,294.500458,0
108.110008,65.26088,-1279.227661,-0.000927,0.004025,0.102245,290.294891,14.788326,1.022452,-1279.227661,294.500458,0
108.560005,65.219925,-1279.31665,-0.000931,0.004025,0.102245,290.112701,14.779046,1.022452,-1279.31665,294.500458,0
109.010002,65.149918,-1279.272095,-0.000944,0.004026,0.102254,289.8013,14.763183,1.022542,-1279.272095,294.500458,0
109.460007,65.118256,-1279.272095,-0.000923,0.004026,0.102254,289.660461,14.756007,1.022542,-1279.272095,294.500458,0
109.910004,65.066132,-1279.272095,-0.000944,0.004026,0.102254,289.428619,14.744196,1.022542,-1279.272095,294.500458,0
110.360008,65.035217,-1279.272095,-0.000923,0.004026,0.102254,289.291107,14.737191,1.022542,-1279.272095,294.500458,0
110.810005,65.003937,-1279.272095,-0.000927,0.004026,0.102254,289.151947,14.730103,1.022542,-1279.272095,294.500458,0
111.260002,64.962234,-1279.272095,-0.00094,0.004026,0.102263,288.966461,14.720654,1.022633,-1279.272095,294.500458,0
111.710007,65.26535,-1279.31665,-0.000918,0.004031,0.102394,290.314789,14.789339,1.023935,-1279.31665,294.500458,0
112.160004,65.29364,-1279.272095,-0.000931,0.004031,0.102394,290.440613,14.795751,1.023935,-1279.272095,294.500458,0
112.610008,65.296631,-1279.361084,-0.000918,0.004031,0.102394,290.453918,14.796428,1.023935,-1279.361084,294.500458,0
113.060005,65.277634,-1279.361084,-0.000927,0.004031,0.102394,290.369415,14.792123,1.023935,-1279.361084,294.500458,0
113.510002,65.256409,-1279.361084,-0.000918,0.004031,0.102394,290.274994,14.787313,1.023935,-1279.361084,294.500458,0
113.960007,65.225128,-1279.40564,-0.000918,0.004031,0.102394,290.135864,14.780226,1.023935,-1279.40564,294.500458,0
114.410004,65.198318,-1279.272095,-0.000927,0.004031,0.102394,290.016602,14.774151,1.023935,-1279.272095,294.500458,0
114.860008,65.170013,-1279.361084,-0.000918,0.004031,0.102394,289.890686,14.767735,1.023935,-1279.361084,294.500458,0
115.310005,65.136505,-1279.361084,-0.000923,0.004031,0.102394,289.741638,14.760143,1.023935,-1279.361084,294.500458,0
115.760002,65.100388,-1279.31665,-0.00091,0.004031,0.102394,289.580994,14.751959,1.023935,-1279.31665,294.500458,0
116.210007,65.065018,-1279.361084,-0.000923,0.004031,0.102394,289.423645,14.743943,1.023935,-1279.361084,294.500458,0
116.660004,65.034851,-1279.31665,-0.00091,0.004031,0.102394,289.289459,14.737107,1.023935,-1279.31665,294.500458,0
117.110008,65.085114,-1279.361084,-0.000914,0.004033,0.102445,289.513031,14.748498,1.02445,-1279.361084,294.500458,0
117.560005,65.072464,-1279.361084,-0.00091,0.004033,0.102445,289.456787,14.745631,1.02445,-1279.361084,294.500458,0
118.010002,65.064636,-1279.361084,-0.00091,0.004033,0.102445,289.421967,14.743857,1.02445,-1279.361084,294.500458,0
118.460007,65.063156,-1279.40564,-0.00091,0.004034,0.102454,289.415375,14.743522,1.024541,-1279.40564,294.500458,0
118.910004,65.043411,-1279.31665,-0.000918,0.004034,0.102462,289.327545,14.739048,1.024616,-1279.31665,294.500458,0
119.360008,65.029633,-1279.31665,-0.000905,0.004034,0.102462,289.266266,14.735926,1.024616,-1279.31665,294.500458,0
119.810005,65.022186,-1279.361084,-0.000897,0.004034,0.102462,289.233124,14.734238,1.024616,-1279.361084,294.500458,0
120.260002,65.138367,-1279.361084,-0.000897,0.004038,0.102566,289.749939,14.760565,1.025661,-1279.361084,294.500458,0
120.710007,65.302216,-1279.31665,-0.000897,0.004038,0.102566,290.47876,14.797693,1.025661,-1279.31665,294.500458,0
121.160004,65.305557,-1279.361084,-0.000901,0.004038,0.102566,290.493622,14.79845,1.025661,-1279.361084,294.500458,0
121.610008,65.26683,-1279.272095,-0.000897,0.004038,0.102566,290.32135,14.789676,1.025661,-1279.272095,294.500458,0
122.060005,65.279129,-1279.361084,-0.000897,0.004038,0.102566,290.376068,14.792462,1.025661,-1279.361084,294.500458,0
122.510002,65.244492,-1279.31665,-0.00091,0.004038,0.102566,290.221985,14.784614,1.025661,-1279.31665,294.500458,0
122.960007,65.240402,-1279.40564,-0.000901,0.004038,0.102566,290.203796,14.783687,1.025661,-1279.40564,294.500458,0
123.410004,65.235931,-1279.31665,-0.000923,0.004038,0.102566,290.183929,14.782673,1.025661,-1279.31665,294.500458,0
123.860008,65.199814,-1279.31665,-0.000918,0.004038,0.102566,290.023254,14.774489,1.025661,-1279.31665,294.500458,0
124.310005,65.158112,-1279.361084,-0.00091,0.004038,0.102575,289.837769,14.765039,1.025752,-1279.361084,294.500458,0
124.760002,65.154007,-1279.361084,-0.000918,0.004039,0.102584,289.819489,14.764109,1.025843,-1279.361084,294.500458,0
125.210007,65.154373,-1279.31665,-0.000923,0.004039,0.102584,289.821136,14.764193,1.025843,-1279.31665,294.500458,0
125.660004,65.143951,-1279.361084,-0.000914,0.004039,0.102592,289.77478,14.76183,1.025918,-1279.361084,294.500458,0
126.110008,65.146194,-1279.450073,-0.000901,0.004039,0.102592,289.78476,14.762339,1.025918,-1279.450073,294.500458,0
126.560005,65.124222,-1279.31665,-0.000923,0.004039,0.102592,289.687012,14.75736,1.025918,-1279.31665,294.500458,0
127.01001,65.086243,-1279.272095,-0.000914,0.004039,0.102592,289.518066,14.748754,1.025918,-1279.272095,294.500458,0
127.460007,65.085861,-1279.40564,-0.00091,0.004039,0.102592,289.516357,14.748668,1.025918,-1279.40564,294.500458,0
127.910004,65.041931,-1279.361084,-0.00091,0.004039,0.102592,289.320953,14.738712,1.025918,-1279.361084,294.500458,0
128.360001,65.541641,-1279.40564,-0.000918,0.004046,0.102766,291.543793,14.851948,1.02766,-1279.40564,294.500458,0
128.810013,65.579254,-1279.450073,-0.000905,0.004046,0.102766,291.71109,14.860472,1.02766,-1279.450073,294.500458,0
129.26001,65.575912,-1279.31665,-0.00091,0.004046,0.102766,291.696228,14.859715,1.02766,-1279.31665,294.500458,0
129.710007,65.592667,-1279.361084,-0.000905,0.004046,0.102766,291.770752,14.863511,1.02766,-1279.361084,294.500458,0
130.160004,65.58223,-1279.31665,-0.000901,0.004046,0.102766,291.724335,14.861145,1.02766,-1279.31665,294.500458,0
130.610001,65.575165,-1279.40564,-0.000927,0.004046,0.102766,291.692902,14.859545,1.02766,-1279.40564,294.500458,0
131.060013,65.565109,-1279.361084,-0.000901,0.004046,0.102766,291.648163,14.857265,1.02766,-1279.361084,294.500458,0
131.51001,65.559891,-1279.361084,-0.000918,0.004046,0.102766,291.624969,14.856084,1.02766,-1279.361084,294.500458,0
131.960007,65.534943,-1279.31665,-0.000923,0.004046,0.102766,291.513977,14.85043,1.02766,-1279.31665,294.500458,0
132.410004,65.520416,-1279.31665,-0.000914,0.004046,0.102766,291.449371,14.847138,1.02766,-1279.31665,294.500458,0
132.860001,65.499191,-1279.272095,-0.000918,0.004046,0.102766,291.35495,14.842328,1.02766,-1279.272095,294.500458,0
133.310013,65.489883,-1279.361084,-0.00091,0.004046,0.102766,291.313538,14.840219,1.02766,-1279.361084,294.500458,0
133.76001,65.474625,-1279.31665,-0.000897,0.004046,0.102766,291.245667,14.836762,1.02766,-1279.31665,294.500458,0
134.210007,65.42659,-1279.361084,-0.000918,0.004046,0.102766,291.032013,14.825877,1.02766,-1279.361084,294.500458,0
134.660004,65.423981,-1279.361084,-0.000918,0.004046,0.102766,291.020386,14.825286,1.02766,-1279.361084,294.500458,0
135.110001,65.380417,-1279.361084,-0.000901,0.004041,0.102636,290.82663,14.815414,1.026358,-1279.361084,0.102766,0
135.560013,65.322327,-1279.361084,-0.00091,0.004028,0.102315,290.568207,14.802251,1.023148,-1279.361084,0.102073,0
136.01001,65.311142,-1279.361084,-0.000897,0.004006,0.101743,290.518463,14.799716,1.017425,-1279.361084,0.101326,0
136.460007,65.208008,-1279.361084,-0.000897,0.003978,0.101049,290.059692,14.776345,1.010491,-1279.361084,0.100572,0
136.910004,65.165176,-1279.31665,-0.000901,0.003952,0.100381,289.869171,14.76664,1.003815,-1279.31665,0.099826,0
137.360001,65.14061,-1279.40564,-0.000905,0.003923,0.099635,289.759918,14.761073,0.996351,-1279.40564,0.099072,0
137.810013,65.098892,-1279.31665,-0.00091,0.003891,0.098828,289.574341,14.751619,0.988281,-1279.31665,0.098326,0
138.26001,65.055695,-1279.40564,-0.000914,0.003865,0.09816,289.382172,14.741832,0.981605,-1279.40564,0.097572,0
138.710007,64.931335,-1279.31665,-0.000888,0.003833,0.097354,288.82901,14.713651,0.973536,-1279.31665,0.096825,0
139.160004,64.915314,-1279.361084,-0.000914,0.003808,0.096721,288.757751,14.710021,0.967207,-1279.361084,0.096071,0
139.610001,64.17244,-1279.361084,-0.000905,0.003778,0.095967,285.453278,14.541683,0.959668,-1279.361084,0.095325,0
140.060013,63.241882,-1279.40564,-0.000888,0.003756,0.095404,281.313934,14.330815,0.954036,-1279.40564,0.094571,0
140.51001,61.807121,-1279.40564,-0.000897,0.003726,0.094648,274.931793,14.005693,0.946481,-1279.40564,0.093825,0
140.960007,60.115807,-1279.361084,-0.000897,0.003698,0.093929,267.408478,13.622437,0.93929,-1279.361084,0.093071,0
141.410004,58.420395,-1279.361084,-0.000897,0.003677,0.093408,259.866882,13.238251,0.934082,-1279.361084,0.092324,0
141.860001,55.696495,-1279.361084,-0.000897,0.003644,0.09255,247.750381,12.621006,0.925498,-1279.361084,0.09157,0
142.310013,53.367302,-1279.361084,-0.000901,0.00362,0.091943,237.389618,12.093204,0.919427,-1279.361084,0.090824,0
142.76001,50.559242,-1279.450073,-0.000905,0.003591,0.091214,224.898743,11.456888,0.912145,-1279.450073,0.09007,0
143.210007,46.910736,-1279.40564,-0.000901,0.003556,0.090312,208.669373,10.630125,0.903121,-1279.40564,0.089324,0
143.660004,43.983887,-1279.40564,-0.000897,0.003529,0.089628,195.650101,9.966891,0.896278,-1279.40564,0.08857,0
144.110001,40.643707,-1279.494507,-0.000901,0.003501,0.088916,180.792236,9.209996,0.889163,-1279.494507,0.087823,0
144.560013,37.981987,-1279.40564,-0.000901,0.003473,0.088205,168.952316,8.606842,0.882047,-1279.40564,0.087069,0
145.01001,34.248207,-1279.450073,-0.000914,0.00344,0.087381,152.343628,7.760755,0.873811,-1279.450073,0.086323,0
145.460007,30.730782,-1279.450073,-0.00091,0.00341,0.086609,136.697342,6.963695,0.86609,-1279.450073,0.085569,0
145.910004,27.654984,-1279.450073,-0.000905,0.003381,0.085881,123.015511,6.266709,0.858808,-1279.450073,0.084823,0
146.360001,25.11689,-1279.40564,-0.000914,0.003358,0.085292,111.72551,5.691569,0.852919,-1279.40564,0.084069,0
146.810013,21.398384,-1279.494507,-0.000918,0.003323,0.084406,95.184769,4.848943,0.844062,-1279.494507,0.083322,0
147.26001,18.253693,-1279.450073,-0.000931,0.003293,0.083643,81.19648,4.136346,0.836432,-1279.450073,0.082577,0
147.710007,14.623062,-1279.450073,-0.000949,0.003264,0.082906,65.046631,3.313633,0.829059,-1279.450073,0.081822,0
148.160004,12.08609,-1279.450073,-0.000931,0.003237,0.082222,53.761612,2.738747,0.822215,-1279.450073,0.081077,0
148.610001,8.14006,-1279.494507,-0.000944,0.003202,0.081319,36.208797,1.844564,0.813192,-1279.494507,0.080322,0
149.060013,5.110809,-1279.450073,-0.000944,0.003174,0.080608,22.734015,1.158126,0.806077,-1279.450073,0.079577,0
149.51001,1.514809,-1279.494507,-0.000957,0.003138,0.079714,6.738205,0.343261,0.797144,-1279.494507,0.078821,0
149.960007,-0.911568,-1279.494507,-0.000949,0.003112,0.079047,-4.054856,-0.206564,0.790468,-1279.494507,0.078076,0
150.410004,-0.291573,-1279.494507,-0.001009,0.003083,0.078319,-1.29698,-0.066071,0.783186,-1279.494507,0.077321,0
150.860001,-0.088257,-1279.494507,-0.001048,0.003054,0.077581,-0.392586,-0.019999,0.775813,-1279.494507,0.076576,0
151.310013,-0.087509,-1279.494507,-0.001052,0.003033,0.077027,-0.38926,-0.01983,0.770272,-1279.494507,0.075821,0
151.76001,-0.06517,-1279.494507,-0.001099,0.002996,0.076107,-0.289892,-0.014768,0.761067,-1279.494507,0.075076,0
152.210007,-0.058838,-1279.450073,-0.00113,0.002973,0.075518,-0.261724,-0.013333,0.755177,-1279.450073,0.07432,0
152.660004,-0.03389,-1279.494507,-0.001199,0.002934,0.074511,-0.150749,-0.00768,0.74511,-1279.494507,0.073575,0
153.110001,-0.025322,-1279.494507,-0.001212,0.002912,0.073957,-0.112638,-0.005738,0.739568,-1279.494507,0.07282,0
153.560013,-0.04171,-1279.494507,-0.001255,0.002879,0.073115,-0.185535,-0.009452,0.731151,-1279.494507,0.072075,0
154.01001,-0.040588,-1279.539062,-0.001293,0.002851,0.072413,-0.180546,-0.009197,0.724126,-1279.539062,0.07132,0
154.460007,-0.051758,-1279.494507,-0.001341,0.002818,0.071589,-0.23023,-0.011728,0.71589,-1279.494507,0.070575,0
154.910004,-0.052879,-1279.450073,-0.001367,0.002791,0.070887,-0.235219,-0.011983,0.708865,-1279.450073,0.069819,0
155.360001,0.009308,-1279.494507,-0.001401,0.002756,0.070002,0.041403,0.002109,0.700024,-1279.494507,0.069074,0
155.810013,-0.000374,-1279.539062,-0.001423,0.002729,0.069307,-0.001663,-0.000085,0.693075,-1279.539062,0.068319,0
156.26001,-0.024582,-1279.539062,-0.001475,0.002696,0.068467,-0.109346,-0.00557,0.684672,-1279.539062,0.067574,0
156.710007,-0.048782,-1279.583496,-0.0015,0.002671,0.067842,-0.216995,-0.011054,0.67842,-1279.583496,0.066819,0
157.160004,0.011169,-1279.494507,-0.001526,0.002639,0.067027,0.049684,0.002531,0.670275,-1279.494507,0.066074,0
157.610001,0.019363,-1279.539062,-0.001552,0.002615,0.066429,0.086133,0.004388,0.664294,-1279.539062,0.065318,0
158.060013,0.00856,-1279.539062,-0.001578,0.002578,0.065492,0.038078,0.00194,0.654923,-1279.539062,0.064573,0
158.51001,-0.04245,-1279.583496,-0.001634,0.002551,0.064799,-0.188827,-0.009619,0.647989,-1279.583496,0.063819,0
158.960007,-0.040215,-1279.494507,-0.00166,0.002525,0.064131,-0.178883,-0.009113,0.641313,-1279.494507,0.063073,0
159.410004,-0.024208,-1279.583496,-0.001694,0.002493,0.063315,-0.107683,-0.005486,0.633152,-1279.583496,0.062319,0
159.860001,-0.036125,-1279.539062,-0.00172,0.002466,0.062648,-0.160693,-0.008186,0.626476,-1279.539062,0.061573,0
160.310013,-0.030907,-1279.450073,-0.001746,0.00243,0.061729,-0.13748,-0.007004,0.617286,-1279.450073,0.060819,0
160.76001,-0.042824,-1279.539062,-0.001763,0.002407,0.061131,-0.19049,-0.009704,0.611306,-1279.539062,0.060072,0
161.210007,-0.05027,-1279.583496,-0.001819,0.002374,0.060289,-0.223612,-0.011391,0.602888,-1279.583496,0.059318,0
161.660004,-0.048409,-1279.583496,-0.00185,0.00235,0.059682,-0.215332,-0.01097,0.596817,-1279.583496,0.058572,0
162.110001,-0.045433,-1279.494507,-0.001867,0.002319,0.058902,-0.202096,-0.010295,0.58902,-1279.494507,0.057818,0
162.560013,-0.033142,-1279.539062,-0.001914,0.002285,0.058035,-0.147423,-0.00751,0.580346,-1279.539062,0.057072,0
163.01001,-0.053627,-1279.583496,-0.001936,0.002258,0.057358,-0.238545,-0.012152,0.573578,-1279.583496,0.056318,0
163.460007,-0.062561,-1279.539062,-0.001975,0.002228,0.056604,-0.278285,-0.014177,0.566039,-1279.539062,0.055571,0
163.910004,-0.037613,-1279.494507,-0.001988,0.002205,0.055997,-0.167311,-0.008523,0.559968,-1279.494507,0.054817,0
164.360001,-0.05809,-1279.583496,-0.002035,0.002165,0.054999,-0.258398,-0.013163,0.549991,-1279.583496,0.054071,0
164.810013,-0.093842,-1279.494507,-0.002061,0.002139,0.054322,-0.417428,-0.021265,0.543223,-1279.494507,0.053317,0
165.26001,-0.070755,-1279.539062,-0.002091,0.002113,0.053673,-0.314734,-0.016033,0.536728,-1279.539062,0.052571,0
165.710007,-0.096817,-1279.539062,-0.002117,0.002081,0.052866,-0.430664,-0.021939,0.528659,-1279.539062,0.051817,0
166.160004,-0.124748,-1279.539062,-0.002156,0.002051,0.052094,-0.554908,-0.028268,0.520938,-1279.539062,0.05107,0
166.610001,-0.105011,-1279.494507,-0.002195,0.002024,0.051408,-0.467112,-0.023796,0.51408,-1279.494507,0.050324,0
167.060013,-0.098679,-1279.539062,-0.002199,0.001988,0.050489,-0.438944,-0.022361,0.50489,-1279.539062,0.04957,0
167.51001,-0.06852,-1279.494507,-0.002246,0.001966,0.049935,-0.30479,-0.015527,0.499349,-1279.494507,0.048824,0
167.960007,-0.11618,-1279.494507,-0.002281,0.001935,0.049137,-0.516796,-0.026327,0.49137,-1279.494507,0.04807,0
168.410004,-0.121765,-1279.539062,-0.002315,0.001902,0.048321,-0.541638,-0.027592,0.48321,-1279.539062,0.047323,0
168.860001,-0.074852,-1279.539062,-0.002358,0.00187,0.047497,-0.332958,-0.016962,0.474974,-1279.539062,0.046569,0
169.310013,-0.091232,-1279.583496,-0.002384,0.001844,0.046846,-0.405822,-0.020674,0.468464,-1279.583496,0.045823,0
169.76001,-0.093094,-1279.539062,-0.002402,0.001816,0.046118,-0.414102,-0.021095,0.461182,-1279.539062,0.045069,0
170.210007,-0.09198,-1279.494507,-0.002445,0.001782,0.04526,-0.409147,-0.020843,0.452598,-1279.494507,0.044324,0
170.660004,-0.087883,-1279.539062,-0.002462,0.001745,0.044315,-0.390923,-0.019915,0.443151,-1279.539062,0.043569,0
171.110001,-0.089745,-1279.539062,-0.002488,0.001728,0.04389,-0.399204,-0.020336,0.438896,-1279.539062,0.042824,0
171.560013,-0.093842,-1279.494507,-0.002539,0.001686,0.042831,-0.417428,-0.021265,0.428314,-1279.494507,0.042068,0
172.01001,-0.077827,-1279.583496,-0.002561,0.001665,0.042285,-0.346194,-0.017636,0.422848,-1279.583496,0.041323,0
172.460007,-0.105011,-1279.494507,-0.002587,0.001642,0.041696,-0.467112,-0.023796,0.416959,-1279.494507,0.040568,0
172.910004,-0.104263,-1279.583496,-0.002617,0.001609,0.040863,-0.463786,-0.023626,0.408632,-1279.583496,0.039823,0
173.360001,-0.113579,-1279.539062,-0.002647,0.001581,0.040161,-0.505224,-0.025737,0.401608,-1279.539062,0.039068,0
173.810013,-0.079315,-1279.494507,-0.002665,0.001546,0.039258,-0.352812,-0.017973,0.392584,-1279.494507,0.038323,0
174.26001,-0.094582,-1279.494507,-0.002716,0.001519,0.038591,-0.42072,-0.021432,0.385908,-1279.494507,0.037567,0
174.710007,-0.076714,-1279.494507,-0.002738,0.001489,0.037828,-0.341239,-0.017384,0.378278,-1279.494507,0.036822,0
175.160004,-0.091606,-1279.450073,-0.002785,0.001456,0.036995,-0.407484,-0.020758,0.369951,-1279.450073,0.036067,0
175.610016,-0.062561,-1279.494507,-0.002794,0.001428,0.036267,-0.278285,-0.014177,0.362669,-1279.494507,0.035322,0
176.060013,-0.090858,-1279.494507,-0.002837,0.0014,0.035548,-0.404159,-0.020589,0.355477,-1279.494507,0.034567,0
176.51001,-0.066284,-1279.450073,-0.00288,0.001374,0.034897,-0.294847,-0.01502,0.348967,-1279.450073,0.033822,0
176.960007,-0.044685,-1279.494507,-0.002893,0.001338,0.033994,-0.19877,-0.010126,0.339944,-1279.494507,0.033066,0
177.410004,-0.050644,-1279.450073,-0.002902,0.001311,0.033301,-0.225275,-0.011476,0.33301,-1279.450073,0.032321,0
177.860016,-0.071869,-1279.494507,-0.002953,0.001279,0.032477,-0.319689,-0.016286,0.324774,-1279.494507,0.031566,0
178.310013,-0.01564,-1279.494507,-0.002979,0.001255,0.031887,-0.069571,-0.003544,0.31887,-1279.494507,0.030821,0
178.76001,0.001114,-1279.40564,-0.003009,0.001223,0.031063,0.004955,0.000252,0.310634,-1279.40564,0.030066,0
179.210007,-0.011917,-1279.494507,-0.003035,0.001197,0.030405,-0.05301,-0.0027,0.304048,-1279.494507,0.029321,0
179.660004,-0.038727,-1279.494507,-0.003074,0.001161,0.029486,-0.172265,-0.008776,0.294858,-1279.494507,0.028565,0
180.110016,-0.070007,-1279.494507,-0.003096,0.001136,0.028861,-0.311408,-0.015864,0.288606,-1279.494507,0.02782,0
180.560013,-0.016388,-1279.494507,-0.003139,0.001103,0.028019,-0.072897,-0.003714,0.280188,-1279.494507,0.027065,0
181.01001,-0.032394,-1279.494507,-0.003178,0.001073,0.027256,-0.144098,-0.007341,0.272558,-1279.494507,0.02632,0
181.460007,-0.030907,-1279.450073,-0.003191,0.001042,0.026458,-0.13748,-0.007004,0.264579,-1279.450073,0.025565,0
181.910004,-0.041336,-1279.494507,-0.003234,0.001015,0.025774,-0.183872,-0.009367,0.257736,-1279.494507,0.02482,0
182.360016,-0.058464,-1279.494507,-0.003268,0.000982,0.024941,-0.260061,-0.013248,0.249409,-1279.494507,0.024064,0
182.810013,-0.040588,-1279.583496,-0.003281,0.000966,0.024541,-0.180546,-0.009197,0.245413,-1279.583496,0.023319,0
183.26001,-0.068146,-1279.494507,-0.00332,0.000928,0.02358,-0.303127,-0.015442,0.235799,-1279.494507,0.022564,0
183.710007,-0.03463,-1279.40564,-0.003341,0.000897,0.022773,-0.154041,-0.007847,0.22773,-1279.40564,0.021819,0
184.160004,-0.04245,-1279.494507,-0.003363,0.000878,0.022296,-0.188827,-0.009619,0.222961,-1279.494507,0.021064,0
184.610016,-0.037613,-1279.450073,-0.00341,0.000841,0.021368,-0.167311,-0.008523,0.21368,-1279.450073,0.020319,0
185.060013,-0.058838,-1279.539062,-0.003454,0.000811,0.020596,-0.261724,-0.013333,0.205959,-1279.539062,0.019563,0
185.51001,-0.081924,-1279.494507,-0.003492,0.00078,0.019807,-0.364418,-0.018564,0.198071,-1279.494507,0.018818,0
185.960007,-0.080803,-1279.494507,-0.003514,0.000754,0.019139,-0.359429,-0.01831,0.191395,-1279.494507,0.018072,0
186.410004,-0.062561,-1279.539062,-0.003535,0.00072,0.018298,-0.278285,-0.014177,0.182977,-1279.539062,0.017318,0
186.860016,-0.061813,-1279.539062,-0.003557,0.000692,0.017569,-0.27496,-0.014007,0.175695,-1279.539062,0.016572,0
187.310013,-0.071121,-1279.539062,-0.0036,0.000664,0.016867,-0.316363,-0.016116,0.16867,-1279.539062,0.015818,0
187.76001,-0.106499,-1279.494507,-0.003639,0.000633,0.016086,-0.47373,-0.024133,0.160858,-1279.494507,0.015071,0
188.210007,-0.09198,-1279.539062,-0.003673,0.000604,0.01535,-0.409147,-0.020843,0.1535,-1279.539062,0.014318,0
188.660004,-0.077827,-1279.494507,-0.003699,0.000575,0.014604,-0.346194,-0.017636,0.146036,-1279.494507,0.013571,0
189.110016,-0.06517,-1279.494507,-0.003729,0.00055,0.013971,-0.289892,-0.014768,0.139708,-1279.494507,0.012817,0
189.560013,-0.119164,-1279.494507,-0.003751,0.000514,0.013059,-0.530066,-0.027003,0.130594,-1279.494507,0.012071,0
190.01001,-0.078201,-1279.583496,-0.003786,0.000485,0.012322,-0.347857,-0.017721,0.123221,-1279.583496,0.011317,0
190.460007,-0.06852,-1279.583496,-0.003833,0.000456,0.011577,-0.30479,-0.015527,0.115772,-1279.583496,0.01057,0
190.910004,-0.070755,-1279.539062,-0.003854,0.000425,0.010788,-0.314734,-0.016033,0.107885,-1279.539062,0.009817,0
191.360016,-0.071869,-1279.583496,-0.003893,0.000393,0.009982,-0.319689,-0.016286,0.099815,-1279.583496,0.00907,0
191.810013,-0.080063,-1279.583496,-0.003923,0.000369,0.009365,-0.356137,-0.018143,0.093653,-1279.583496,0.008316,0
192.26001,-0.075592,-1279.583496,-0.003949,0.000338,0.008586,-0.33625,-0.017129,0.085857,-1279.583496,0.00757,0
192.710007,-0.069633,-1279.539062,-0.00398,0.000308,0.007823,-0.309745,-0.015779,0.078226,-1279.539062,0.006816,0
193.160004,-0.064423,-1279.539062,-0.004005,0.000277,0.007032,-0.286566,-0.014598,0.070323,-1279.539062,0.006069,0
193.610016,-0.066658,-1279.539062,-0.004031,0.000249,0.006322,-0.29651,-0.015105,0.063223,-1279.539062,0.005316,0
194.060013,-0.072617,-1279.494507,-0.004049,0.000222,0.005627,-0.323015,-0.016455,0.056274,-1279.494507,0.004569,0
194.51001,-0.089745,-1279.494507,-0.004083,0.000192,0.004864,-0.399204,-0.020336,0.048643,-1279.494507,0.003815,0
194.960007,-0.06517,-1279.583496,-0.004135,0.000159,0.004032,-0.289892,-0.014768,0.040317,-1279.583496,0.003069,0
195.410004,-0.067772,-1279.583496,-0.004161,0.000129,0.003269,-0.301465,-0.015357,0.032686,-1279.583496,0.002315,0
195.860016,-0.048782,-1279.539062,-0.004191,0.000109,0.002757,-0.216995,-0.011054,0.027569,-1279.539062,0.001568,0
196.310013,-0.053253,-1279.539062,-0.004204,0.000069,0.001743,-0.236882,-0.012067,0.017426,-1279.539062,0.000815,0
196.76001,-0.082672,-1279.494507,-0.004243,0.000041,0.001049,-0.367744,-0.018734,0.010492,-1279.494507,0.000068,0
197.210007,-0.060699,-1279.583496,-0.004268,0.000012,0.000312,-0.270005,-0.013755,0.003119,-1279.583496,-0.000686,0
197.600006,-0.011917,-1279.494507,-0.00429,0.000006,0.000147,-0.05301,-0.0027,0.001469,-1279.494507,0,0