File: Data/compression 36/Heating-15-36-reverse-1-3_11202024_170022(in).csv
Time (sec),S:Load (lbs),S:HL1 (DIM),S:LVDT (in),S:Position (in),Ch:Position (mm),Ch:Load (N),Ch:Stress (MPa),Ch:Strain (mm/mm),Ch:HL1 (DIM),Set Point (),Cycles ()
0.11,-0.044685,-1277.537354,-0.011137,-0.006684,-0.169786,-0.19877,-0.010126,-1.697858,-1277.537354,-0.170019,0
0.43,-0.021973,-1277.537354,-0.011158,-0.006684,-0.169786,-0.097739,-0.004979,-1.697858,-1277.537354,-0.169637,0
0.75,-0.01564,-1277.537354,-0.011106,-0.006515,-0.165492,-0.069571,-0.003544,-1.654923,-1277.537354,-0.164296,0
1.07,-0.039848,-1277.49292,-0.010947,-0.006309,-0.160254,-0.177254,-0.00903,-1.60254,-1277.49292,-0.158972,0
1.39,-0.040962,-1277.49292,-0.010723,-0.006102,-0.15499,-0.182209,-0.009282,-1.549899,-1277.49292,-0.153646,0
1.71,-0.143364,-1277.537354,-0.010503,-0.005888,-0.149553,-0.637715,-0.032487,-1.495533,-1277.537354,-0.148304,0
2.03,-0.032394,-1277.49292,-0.010287,-0.00568,-0.144262,-0.144098,-0.007341,-1.44262,-1277.49292,-0.14298,0
2.35,-0.033516,-1277.49292,-0.010076,-0.005481,-0.139207,-0.149086,-0.007595,-1.392069,-1277.49292,-0.137655,0
2.67,0.00856,-1277.49292,-0.009869,-0.005273,-0.133925,0.038078,0.00194,-1.339247,-1277.49292,-0.132312,0
2.99,-0.017128,-1277.537354,-0.009649,-0.00505,-0.128279,-0.076189,-0.003881,-1.282792,-1277.537354,-0.126988,0
3.31,-0.046173,-1277.537354,-0.009429,-0.004844,-0.123042,-0.205388,-0.010463,-1.230424,-1277.537354,-0.121663,0
3.63,-0.065536,-1277.49292,-0.009201,-0.00463,-0.117604,-0.291521,-0.014851,-1.176043,-1277.49292,-0.11632,0
3.95,-0.027184,-1277.448486,-0.008977,-0.004422,-0.112314,-0.120918,-0.00616,-1.123145,-1277.448486,-0.110996,0
4.27,-0.029793,-1277.537354,-0.008778,-0.004217,-0.107111,-0.132525,-0.006751,-1.07111,-1277.537354,-0.105655,0
4.59,0.010796,-1277.581909,-0.008558,-0.004005,-0.101733,0.048021,0.002446,-1.017334,-1277.581909,-0.100328,0
4.91,-0.020485,-1277.581909,-0.008343,-0.003796,-0.096409,-0.091121,-0.004642,-0.964088,-1277.581909,-0.095004,0
5.23,-0.052505,-1277.537354,-0.008132,-0.003584,-0.091033,-0.233556,-0.011898,-0.910328,-1277.537354,-0.089663,0
5.55,-0.020851,-1277.537354,-0.00792,-0.003368,-0.085543,-0.09275,-0.004725,-0.855432,-1277.537354,-0.084338,0
5.87,-0.054741,-1277.49292,-0.007709,-0.003167,-0.080444,-0.2435,-0.012404,-0.804442,-1277.49292,-0.079012,0
6.19,-0.085274,-1277.537354,-0.007498,-0.002953,-0.075006,-0.379317,-0.019323,-0.75006,-1277.537354,-0.073671,0
6.51,-0.005585,-1277.537354,-0.007265,-0.002744,-0.069698,-0.024842,-0.001266,-0.696981,-1277.537354,-0.068346,0
6.83,-0.004471,-1277.537354,-0.007036,-0.002534,-0.064366,-0.019887,-0.001013,-0.643659,-1277.537354,-0.063022,0
7.150001,-0.022713,-1277.537354,-0.006829,-0.002332,-0.059223,-0.101031,-0.005147,-0.59223,-1277.537354,-0.057679,0
7.47,-0.038353,-1277.49292,-0.006597,-0.002114,-0.053708,-0.170603,-0.008691,-0.537077,-1277.49292,-0.052354,0
7.79,-0.043571,-1277.537354,-0.00639,-0.001907,-0.048444,-0.193816,-0.009873,-0.484436,-1277.537354,-0.047011,0
8.110001,-0.125122,-1277.537354,-0.006178,-0.001693,-0.042996,-0.556571,-0.028353,-0.429964,-1277.537354,-0.041687,0
8.43,-0.008194,-1277.49292,-0.005967,-0.001483,-0.037672,-0.036449,-0.001857,-0.376718,-1277.49292,-0.036362,0
8.75,-0.030907,-1277.49292,-0.005747,-0.001284,-0.032617,-0.13748,-0.007004,-0.326167,-1277.49292,-0.031021,0
9.070001,0.024948,-1277.537354,-0.005536,-0.001078,-0.027369,0.110975,0.005653,-0.273693,-1277.537354,-0.025696,0
9.39,0.00856,-1277.448486,-0.005303,-0.000853,-0.021654,0.038078,0.00194,-0.216541,-1277.448486,-0.02037,0
9.71,-0.017502,-1277.49292,-0.005113,-0.000646,-0.016416,-0.077852,-0.003966,-0.164158,-1277.49292,-0.015029,0
10.030001,-0.043945,-1277.537354,-0.004872,-0.000433,-0.010987,-0.195479,-0.009958,-0.109868,-1277.537354,-0.009704,0
10.35,0.029045,-1277.448486,-0.004652,-0.000225,-0.005715,0.129199,0.006582,-0.057152,-1277.448486,-0.004362,0
10.67,0.134422,-1277.49292,-0.00454,-0.000003,-0.000088,0.59794,0.030461,-0.000878,-1277.49292,0.000103,0
10.990001,0.135918,-1277.537354,-0.004549,-0.000004,-0.000095,0.604592,0.030799,-0.000954,-1277.537354,0.000103,0
11.31,0.113945,-1277.581909,-0.004553,-0.000004,-0.000095,0.506853,0.02582,-0.000954,-1277.581909,0.000554,0
11.63,0.138145,-1277.537354,-0.004536,-0.000003,-0.000088,0.614502,0.031304,-0.000878,-1277.537354,0.001084,0
11.950001,0.216721,-1277.448486,-0.00454,0.00002,0.000503,0.964021,0.04911,0.005026,-1277.448486,0.001621,0
12.27,0.284119,-1277.537354,-0.004514,0.000041,0.00104,1.263823,0.064382,0.010401,-1277.537354,0.00215,0
12.59,0.308693,-1277.581909,-0.00451,0.000056,0.001431,1.373135,0.069951,0.014307,-1277.581909,0.002687,0
12.910001,0.422638,-1277.581909,-0.004475,0.000079,0.002003,1.879987,0.095771,0.02003,-1277.581909,0.003217,0
13.23,0.509773,-1277.581909,-0.004458,0.000099,0.002506,2.267585,0.115516,0.025056,-1277.581909,0.003755,0
13.55,0.662079,-1277.537354,-0.004449,0.000123,0.003131,2.945074,0.150029,0.031309,-1277.537354,0.004283,0
13.870001,0.815125,-1277.537354,-0.004402,0.000144,0.00365,3.625855,0.18471,0.036502,-1277.537354,0.00482,0
14.190001,0.981575,-1277.537354,-0.004402,0.000168,0.004275,4.366264,0.222428,0.042754,-1277.537354,0.00535,0
14.51,1.152863,-1277.670898,-0.004389,0.000186,0.004717,5.128189,0.261242,0.047175,-1277.670898,0.005888,0
14.830001,1.240746,-1277.537354,-0.004372,0.0002,0.005081,5.519112,0.281157,0.050808,-1277.537354,0.006416,0
15.150001,1.44294,-1277.537354,-0.004337,0.000224,0.00568,6.418517,0.326975,0.056804,-1277.537354,0.006955,0
15.47,1.65892,-1277.49292,-0.004324,0.000243,0.006165,7.379246,0.375917,0.061648,-1277.49292,0.007483,0
15.790001,2.03241,-1277.537354,-0.004307,0.000272,0.006902,9.040609,0.460551,0.069021,-1277.537354,0.008021,0
16.110001,2.262535,-1277.581909,-0.004273,0.000294,0.007458,10.064259,0.512698,0.074578,-1277.581909,0.008551,0
16.43,2.458405,-1277.581909,-0.004251,0.00031,0.007883,10.93553,0.557082,0.078832,-1277.581909,0.009088,0
16.75,2.62336,-1277.581909,-0.004243,0.000328,0.008342,11.669287,0.594462,0.083419,-1277.581909,0.009617,0
17.070002,2.815506,-1277.581909,-0.004234,0.000348,0.008837,12.523996,0.638003,0.08837,-1277.581909,0.010154,0
17.390001,3.292885,-1277.581909,-0.004208,0.00038,0.009651,14.647483,0.746178,0.096515,-1277.581909,0.010684,0
17.710001,3.450401,-1277.581909,-0.004161,0.000397,0.010086,15.348151,0.781872,0.10086,-1277.581909,0.011221,0
18.030001,3.612015,-1277.581909,-0.004143,0.000416,0.01057,16.067043,0.818494,0.105705,-1277.581909,0.01175,0
18.35,3.723351,-1277.537354,-0.004139,0.000432,0.01097,16.56229,0.843723,0.109701,-1277.537354,0.012287,0
18.67,4.069656,-1277.537354,-0.004113,0.000456,0.011585,18.102736,0.922197,0.115848,-1277.537354,0.012817,0
18.990002,4.177643,-1277.537354,-0.004096,0.000478,0.01215,18.583084,0.946667,0.121495,-1277.537354,0.013355,0
19.310001,4.493416,-1277.626343,-0.004066,0.0005,0.012704,19.987711,1.018223,0.127036,-1277.626343,0.013883,0
19.630001,4.690033,-1277.537354,-0.004049,0.000522,0.01325,20.862309,1.062777,0.132502,-1277.537354,0.014422,0
19.950001,4.841209,-1277.581909,-0.004031,0.000545,0.013832,21.534775,1.097034,0.138315,-1277.581909,0.01495,0
20.27,5.066498,-1277.49292,-0.003992,0.000567,0.014395,22.536907,1.148085,0.143947,-1277.49292,0.015488,0
20.59,5.012878,-1277.537354,-0.004001,0.000578,0.014681,22.298397,1.135935,0.146809,-1277.537354,0.016018,0
20.910002,5.378174,-1277.670898,-0.003975,0.000605,0.015367,23.923311,1.218712,0.153667,-1277.670898,0.016555,0
21.230001,5.349876,-1277.537354,-0.003945,0.000618,0.015704,23.79744,1.212299,0.157043,-1277.537354,0.017084,0
21.550001,5.794113,-1277.581909,-0.003936,0.00065,0.016502,25.773502,1.312965,0.165021,-1277.581909,0.017621,0
21.870001,5.747192,-1277.537354,-0.003898,0.000667,0.016946,25.564789,1.302332,0.169457,-1277.537354,0.018151,0
22.190001,5.814224,-1277.581909,-0.00388,0.000686,0.017423,25.862961,1.317522,0.174226,-1277.581909,0.018688,0
22.51,6.043228,-1277.581909,-0.003872,0.000713,0.018107,26.881622,1.369415,0.181069,-1277.581909,0.019217,0
22.830002,6.037643,-1277.581909,-0.003824,0.000727,0.018472,26.856779,1.36815,0.184718,-1277.581909,0.019754,0
23.150002,6.359375,-1277.581909,-0.003811,0.000755,0.019165,28.287912,1.441055,0.191652,-1277.581909,0.020284,0
23.470001,6.447624,-1277.49292,-0.003803,0.000774,0.019659,28.680466,1.461053,0.196587,-1277.49292,0.020821,0
23.790001,6.566414,-1277.581909,-0.003794,0.000794,0.02018,29.208868,1.487971,0.201795,-1277.581909,0.02135,0
24.110001,6.69265,-1277.626343,-0.003764,0.000816,0.020735,29.770393,1.516576,0.207352,-1277.626343,0.021889,0
24.43,6.934319,-1277.581909,-0.003721,0.000839,0.021298,30.84539,1.571339,0.212984,-1277.581909,0.022417,0
24.750002,7.024429,-1277.537354,-0.003708,0.000862,0.021905,31.246222,1.591758,0.219055,-1277.537354,0.022955,0
25.070002,7.044914,-1277.581909,-0.003699,0.000878,0.022313,31.337343,1.5964,0.223127,-1277.581909,0.023492,0
25.390001,7.005066,-1277.537354,-0.003678,0.000889,0.022591,31.160089,1.587371,0.225913,-1277.537354,0.024022,0
25.710001,7.463089,-1277.626343,-0.003626,0.000924,0.023457,33.197479,1.69116,0.234573,-1277.626343,0.024559,0
26.030001,7.607193,-1277.537354,-0.003622,0.000949,0.024099,33.838486,1.723815,0.240992,-1277.537354,0.025088,0
26.35,7.558418,-1277.581909,-0.003609,0.000966,0.024525,33.621525,1.712762,0.245246,-1277.581909,0.025625,0
26.670002,7.748322,-1277.49292,-0.003583,0.000988,0.025097,34.466255,1.755795,0.250969,-1277.49292,0.026155,0
26.990002,7.661186,-1277.581909,-0.003583,0.001001,0.025418,34.078659,1.73605,0.254178,-1277.581909,0.026693,0
27.310001,8.109901,-1277.626343,-0.003531,0.00103,0.026172,36.074642,1.83773,0.261718,-1277.626343,0.027221,0
27.630001,8.089417,-1277.537354,-0.003505,0.00105,0.026667,35.983521,1.833088,0.266669,-1277.537354,0.02776,0
27.950001,8.131126,-1277.581909,-0.003501,0.00107,0.027169,36.169056,1.84254,0.271695,-1277.581909,0.028288,0
28.27,8.281563,-1277.537354,-0.003488,0.001092,0.027725,36.83823,1.876629,0.277251,-1277.537354,0.028826,0
28.590002,8.204483,-1277.581909,-0.003449,0.001107,0.028114,36.495365,1.859162,0.281142,-1277.581909,0.029356,0
28.910002,8.363113,-1277.581909,-0.003432,0.001126,0.0286,37.200985,1.895109,0.286002,-1277.581909,0.029893,0
29.230001,8.785011,-1277.581909,-0.003402,0.001154,0.029312,39.077682,1.990712,0.293117,-1277.581909,0.030421,0
29.550001,8.803253,-1277.581909,-0.003402,0.001176,0.029875,39.158825,1.994846,0.298749,-1277.581909,0.030959,0
29.870001,8.736977,-1277.581909,-0.003367,0.001194,0.030317,38.864014,1.979827,0.30317,-1277.581909,0.031489,0
30.190001,8.970451,-1277.581909,-0.003346,0.001218,0.030942,39.902561,2.032733,0.309423,-1277.581909,0.032026,0
30.510002,8.859108,-1277.581909,-0.003311,0.001235,0.031375,39.40728,2.007503,0.313753,-1277.581909,0.032555,0
30.830002,8.779053,-1277.581909,-0.003307,0.001251,0.031775,39.051178,1.989362,0.31775,-1277.581909,0.033092,0
31.150002,9.263878,-1277.537354,-0.003264,0.001282,0.032555,41.207787,2.099225,0.325546,-1277.537354,0.033622,0
31.470001,9.269836,-1277.537354,-0.003247,0.0013,0.033024,41.234291,2.100575,0.33024,-1277.537354,0.034159,0
31.790001,9.3283,-1277.670898,-0.003234,0.001321,0.033552,41.494354,2.113823,0.335523,-1277.670898,0.034688,0
32.110001,9.380058,-1277.670898,-0.003195,0.001346,0.034185,41.724583,2.125551,0.341852,-1277.670898,0.035227,0
32.43,9.288826,-1277.581909,-0.003186,0.001362,0.034602,41.31876,2.104878,0.346015,-1277.581909,0.035755,0
32.75,9.18084,-1277.581909,-0.00316,0.001377,0.034966,40.838413,2.080408,0.349664,-1277.581909,0.036293,0
33.07,9.464958,-1277.537354,-0.003134,0.001397,0.035495,42.102238,2.14479,0.354947,-1277.537354,0.036822,0
33.390003,9.854088,-1277.670898,-0.003117,0.001428,0.036276,43.833172,2.232968,0.362759,-1277.670898,0.03736,0
33.710003,9.699554,-1277.715332,-0.003096,0.001444,0.036674,43.145775,2.19795,0.366741,-1277.715332,0.037888,0
34.030003,9.868988,-1277.626343,-0.00307,0.001465,0.037204,43.899452,2.236345,0.37204,-1277.626343,0.038426,0
34.350002,10.020912,-1277.626343,-0.003048,0.001489,0.037811,44.575245,2.270771,0.378111,-1277.626343,0.038956,0
34.670002,9.822441,-1277.626343,-0.003027,0.001505,0.038227,43.692402,2.225797,0.382274,-1277.626343,0.039493,0
34.990002,10.217529,-1277.670898,-0.003009,0.001529,0.038835,45.449841,2.315325,0.388345,-1277.670898,0.040021,0
35.310001,10.315086,-1277.626343,-0.002966,0.001551,0.039407,45.883797,2.337432,0.394068,-1277.626343,0.040559,0
35.630001,10.243965,-1277.581909,-0.002945,0.001573,0.039952,45.567432,2.321316,0.399518,-1277.581909,0.041089,0
35.950001,10.151985,-1277.581909,-0.002932,0.001588,0.040342,45.158287,2.300473,0.403424,-1277.581909,0.041626,0
36.27,10.328491,-1277.626343,-0.002906,0.001612,0.04094,45.943424,2.34047,0.409405,-1277.626343,0.042155,0
36.59,10.373177,-1277.715332,-0.002906,0.00163,0.041401,46.142193,2.350595,0.414007,-1277.715332,0.042694,0
36.91,10.534416,-1277.715332,-0.002863,0.001653,0.041982,46.859425,2.387133,0.419821,-1277.715332,0.043222,0
37.230003,10.799919,-1277.626343,-0.002833,0.001676,0.042571,48.04044,2.447297,0.42571,-1277.626343,0.043759,0
37.550003,10.821144,-1277.581909,-0.002811,0.001697,0.043101,48.134853,2.452106,0.431009,-1277.581909,0.044289,0
37.870003,10.880722,-1277.670898,-0.002811,0.001718,0.043629,48.399868,2.465607,0.436292,-1277.670898,0.044827,0
38.190002,10.945145,-1277.670898,-0.00279,0.001739,0.044159,48.686436,2.480205,0.441591,-1277.670898,0.045355,0
38.510002,10.863968,-1277.626343,-0.002742,0.001755,0.044575,48.325344,2.46181,0.445755,-1277.626343,0.045893,0
38.830002,11.105637,-1277.670898,-0.002725,0.001779,0.04519,49.400337,2.516573,0.451901,-1277.670898,0.046422,0
39.150002,11.432579,-1277.626343,-0.00269,0.001807,0.045902,50.854652,2.590659,0.459017,-1277.626343,0.04696,0
39.470001,11.366669,-1277.759766,-0.002695,0.001826,0.04637,50.561466,2.575724,0.463695,-1277.759766,0.047488,0
39.790001,11.157394,-1277.715332,-0.002656,0.001837,0.046648,49.630569,2.528302,0.466481,-1277.715332,0.048026,0
40.110001,11.698448,-1277.670898,-0.002634,0.001866,0.047402,52.037296,2.650906,0.47402,-1277.670898,0.048556,0
40.43,11.383423,-1277.626343,-0.002613,0.001877,0.047672,50.635994,2.57952,0.476715,-1277.626343,0.049093,0
40.750004,11.578545,-1277.626343,-0.0026,0.001903,0.04833,51.503941,2.623736,0.483301,-1277.626343,0.049621,0
41.070004,12.092796,-1277.670898,-0.00257,0.001933,0.049102,53.791443,2.740267,0.491022,-1277.670898,0.05016,0
41.390003,12.156845,-1277.715332,-0.002535,0.001953,0.049614,54.076347,2.754781,0.496139,-1277.715332,0.050689,0
41.710003,11.869743,-1277.670898,-0.002509,0.001965,0.049917,52.799255,2.689722,0.499167,-1277.670898,0.051226,0
42.030003,11.891716,-1277.715332,-0.002488,0.001985,0.050412,52.896996,2.694701,0.504118,-1277.715332,0.051756,0
42.350002,12.408569,-1277.626343,-0.002488,0.002011,0.05107,55.196072,2.811822,0.510703,-1277.626343,0.052294,0
42.670002,12.229454,-1277.759766,-0.002488,0.002027,0.051487,54.39933,2.771234,0.514867,-1277.759766,0.052822,0
42.990002,13.067291,-1277.759766,-0.002432,0.002061,0.052354,58.126213,2.96109,0.523542,-1277.759766,0.053359,0
43.310001,12.926537,-1277.670898,-0.00241,0.002078,0.052787,57.500107,2.929195,0.527872,-1277.670898,0.053889,0
43.630001,12.767159,-1277.715332,-0.002402,0.002096,0.053247,56.791157,2.89308,0.532474,-1277.715332,0.054427,0
43.950001,13.241188,-1277.670898,-0.002371,0.002121,0.05388,58.899746,3.000496,0.538803,-1277.670898,0.054955,0
44.27,13.153687,-1277.715332,-0.002358,0.002137,0.054278,58.510521,2.980668,0.542784,-1277.715332,0.055493,0
44.590004,13.541695,-1277.670898,-0.002328,0.002162,0.05492,60.236465,3.068592,0.549203,-1277.670898,0.056022,0
44.910004,13.681335,-1277.670898,-0.002302,0.002184,0.055485,60.85762,3.100235,0.55485,-1277.670898,0.05656,0
45.230003,13.506317,-1277.626343,-0.002281,0.002201,0.055901,60.079098,3.060575,0.559014,-1277.626343,0.057088,0
45.550003,14.007164,-1277.670898,-0.002289,0.002222,0.056446,62.306976,3.174069,0.564464,-1277.670898,0.057627,0
45.870003,14.282715,-1277.715332,-0.002255,0.002246,0.057054,63.532688,3.23651,0.570535,-1277.715332,0.058156,0
46.190002,14.06041,-1277.804321,-0.00222,0.002266,0.057565,62.543827,3.186134,0.575652,-1277.804321,0.058693,0
46.510002,14.308411,-1277.715332,-0.002203,0.002284,0.058009,63.646988,3.242332,0.580088,-1277.715332,0.059223,0
46.830002,15.026718,-1277.715332,-0.00216,0.00231,0.058684,66.842178,3.405103,0.58684,-1277.715332,0.05976,0
47.150002,15.421432,-1277.715332,-0.002151,0.002338,0.059396,68.597961,3.494546,0.593956,-1277.715332,0.060289,0
47.470001,14.961182,-1277.715332,-0.002126,0.002349,0.059665,66.550659,3.390252,0.596651,-1277.715332,0.060826,0
47.790001,14.987991,-1277.804321,-0.002113,0.002366,0.060089,66.669914,3.396327,0.60089,-1277.804321,0.061356,0
48.110001,15.891739,-1277.715332,-0.002087,0.002397,0.060887,70.689987,3.60112,0.608868,-1277.715332,0.061894,0
48.430004,15.382332,-1277.715332,-0.002082,0.002408,0.061156,68.424026,3.485686,0.611563,-1277.715332,0.062422,0
48.750004,16.473015,-1277.670898,-0.002048,0.002441,0.061989,73.275627,3.732838,0.61989,-1277.670898,0.062959,0
49.070004,16.494606,-1277.715332,-0.002039,0.00246,0.062475,73.371674,3.737731,0.62475,-1277.715332,0.063489,0
49.390003,16.598877,-1277.670898,-0.002005,0.002476,0.062882,73.835495,3.761359,0.628822,-1277.670898,0.064027,0
49.710003,16.435028,-1277.804321,-0.001988,0.002491,0.06328,73.106659,3.724231,0.632804,-1277.804321,0.064555,0
50.030003,16.702019,-1277.715332,-0.001988,0.002515,0.063888,74.294289,3.784731,0.638875,-1277.715332,0.065094,0
50.350002,17.126526,-1277.670898,-0.001953,0.002531,0.064278,76.182594,3.880926,0.642781,-1277.670898,0.065623,0
50.670002,18.181831,-1277.715332,-0.001919,0.002564,0.06512,80.876823,4.120062,0.651199,-1277.715332,0.06616,0
50.990002,18.062294,-1277.804321,-0.001919,0.002578,0.065492,80.345093,4.092974,0.654923,-1277.804321,0.066688,0
51.310001,18.254066,-1277.715332,-0.001906,0.002602,0.066083,81.198143,4.136431,0.660828,-1277.715332,0.067227,0
51.630001,18.705009,-1277.759766,-0.001858,0.002621,0.066576,83.204041,4.238616,0.665763,-1277.759766,0.067756,0
51.950001,18.976845,-1277.759766,-0.001858,0.002642,0.067097,84.413223,4.300214,0.670971,-1277.759766,0.068293,0
52.270004,19.19133,-1277.715332,-0.001858,0.002662,0.067616,85.367302,4.348817,0.676164,-1277.715332,0.068823,0
52.590004,19.880219,-1277.848755,-0.001828,0.002684,0.068163,88.431625,4.504922,0.681629,-1277.848755,0.06936,0
52.910004,20.197853,-1277.715332,-0.001789,0.002705,0.068709,89.844536,4.576899,0.687095,-1277.715332,0.069889,0
53.230003,20.678215,-1277.715332,-0.001781,0.002728,0.069282,91.981293,4.68575,0.692817,-1277.715332,0.070426,0
53.550003,20.842056,-1277.759766,-0.001755,0.002746,0.069759,92.710098,4.722878,0.697586,-1277.759766,0.070956,0
53.870003,21.282204,-1277.715332,-0.001733,0.002768,0.070305,94.667969,4.822616,0.703052,-1277.715332,0.071494,0
54.190002,21.39019,-1277.759766,-0.001725,0.002784,0.070705,95.148315,4.847086,0.707049,-1277.759766,0.072022,0
54.510002,22.543053,-1277.715332,-0.001707,0.002812,0.071433,100.276505,5.108329,0.714331,-1277.715332,0.072559,0
54.830002,22.933304,-1277.715332,-0.001677,0.002834,0.07198,102.012428,5.196761,0.719796,-1277.715332,0.073089,0
55.150002,22.607101,-1277.715332,-0.001669,0.002847,0.072308,100.561409,5.122842,0.723081,-1277.715332,0.073627,0
55.470001,23.521652,-1277.759766,-0.001664,0.002872,0.07295,104.629532,5.330082,0.729501,-1277.759766,0.074155,0
55.790001,24.022118,-1277.759766,-0.001656,0.002893,0.073488,106.855713,5.44349,0.734875,-1277.759766,0.074694,0
56.110004,24.512535,-1277.804321,-0.001617,0.00291,0.073922,109.037201,5.55462,0.73922,-1277.804321,0.075223,0
56.430004,25.252068,-1277.759766,-0.001613,0.002934,0.074529,112.326805,5.7222,0.745291,-1277.759766,0.07576,0
56.750004,25.877647,-1277.759766,-0.001587,0.002959,0.075153,115.109528,5.863959,0.751529,-1277.759766,0.07629,0
57.070004,26.550529,-1277.848755,-0.001561,0.00298,0.075699,118.102654,6.016436,0.756994,-1277.848755,0.076827,0
57.390003,26.65889,-1277.804321,-0.001556,0.002996,0.076099,118.584663,6.040991,0.760991,-1277.804321,0.077356,0
57.710003,27.099403,-1277.759766,-0.001531,0.003015,0.076593,120.544167,6.140812,0.765926,-1277.759766,0.077893,0
58.030003,27.251701,-1277.848755,-0.001535,0.00303,0.076974,121.221619,6.175323,0.769742,-1277.848755,0.078423,0
58.350002,28.31855,-1277.715332,-0.001513,0.00306,0.077721,125.967201,6.417075,0.777205,-1277.715332,0.07896,0
58.670002,28.982864,-1277.759766,-0.001483,0.003075,0.078102,128.922226,6.567611,0.781021,-1277.759766,0.079489,0
58.990002,30.194565,-1277.848755,-0.001462,0.003107,0.078909,134.312134,6.842186,0.78909,-1277.848755,0.080026,0
59.310001,30.550179,-1277.848755,-0.001449,0.003122,0.079291,135.893982,6.92277,0.792905,-1277.848755,0.080556,0
59.630001,31.254333,-1277.715332,-0.001427,0.003145,0.079879,139.026215,7.082334,0.798795,-1277.715332,0.081094,0
59.950005,31.969292,-1277.893188,-0.001414,0.003167,0.080452,142.206512,7.244345,0.804517,-1277.893188,0.081622,0
60.270004,32.503647,-1277.848755,-0.001397,0.003189,0.080989,144.583435,7.365432,0.809892,-1277.848755,0.082161,0
60.590004,33.728378,-1277.893188,-0.00138,0.003209,0.081519,150.031326,7.64296,0.815191,-1277.893188,0.082689,0
60.910004,34.045639,-1277.759766,-0.001358,0.003225,0.081926,151.442566,7.714852,0.819263,-1277.759766,0.083227,0
61.230003,33.870628,-1277.848755,-0.00135,0.003235,0.082169,150.664078,7.675194,0.821686,-1277.848755,0.083757,0
61.550003,35.528427,-1277.804321,-0.001341,0.003265,0.082932,158.03833,8.050857,0.829316,-1277.804321,0.084294,0
61.870003,36.344292,-1277.937744,-0.001345,0.003293,0.083643,161.66748,8.235734,0.836432,-1277.937744,0.084823,0
62.190002,37.64946,-1277.848755,-0.001319,0.003316,0.084215,167.47316,8.53149,0.842154,-1277.848755,0.08536,0
62.510002,38.7528,-1277.848755,-0.001285,0.003336,0.084745,172.381058,8.78151,0.847453,-1277.848755,0.08589,0
62.830002,39.594734,-1277.848755,-0.001293,0.003359,0.085325,176.126175,8.972295,0.853252,-1277.848755,0.086427,0
63.150002,39.995407,-1277.893188,-0.001276,0.003375,0.085725,177.908463,9.063089,0.857248,-1277.893188,0.086956,0
63.470001,40.440392,-1277.893188,-0.001242,0.00339,0.086106,179.887848,9.163924,0.861064,-1277.893188,0.087493,0
63.790005,41.65023,-1277.893188,-0.001224,0.003414,0.086704,185.269485,9.438077,0.867044,-1277.893188,0.088023,0
64.110001,42.670906,-1277.848755,-0.001212,0.003438,0.08733,189.809677,9.669365,0.873296,-1277.848755,0.08856,0
64.43,44.313812,-1277.804321,-0.001224,0.003463,0.08797,197.117676,10.041654,0.8797,-1277.804321,0.089089,0
64.75,45.059303,-1277.848755,-0.001207,0.003482,0.088448,200.433792,10.210584,0.884485,-1277.848755,0.089628,0
65.07,45.624931,-1277.893188,-0.001173,0.003498,0.088847,202.949829,10.338758,0.888466,-1277.893188,0.090156,0
65.389999,46.750992,-1277.848755,-0.001173,0.003523,0.089489,207.958801,10.593926,0.894885,-1277.848755,0.090694,0
65.710007,47.633141,-1277.804321,-0.001147,0.003539,0.089896,211.882797,10.793824,0.898958,-1277.804321,0.091224,0
66.030006,48.849678,-1277.804321,-0.001143,0.003562,0.090486,217.29422,11.069495,0.904862,-1277.804321,0.091761,0
66.350006,50.549187,-1277.893188,-0.001134,0.003588,0.091136,224.854019,11.45461,0.911357,-1277.893188,0.092289,0
66.670006,51.287971,-1277.848755,-0.00113,0.003605,0.09157,228.140289,11.622021,0.915702,-1277.848755,0.092827,0
66.990005,52.459084,-1277.937744,-0.001099,0.003628,0.092143,233.349655,11.887399,0.921425,-1277.937744,0.093357,0
67.310005,53.748611,-1277.848755,-0.001087,0.003648,0.092662,239.08577,12.179609,0.926618,-1277.848755,0.093894,0
67.630005,54.943924,-1277.848755,-0.001078,0.003669,0.093183,244.402786,12.450471,0.931826,-1277.848755,0.094423,0
67.950005,55.505836,-1277.893188,-0.001087,0.003683,0.093555,246.902298,12.577802,0.93555,-1277.893188,0.09496,0
68.270004,57.756454,-1277.893188,-0.001065,0.003715,0.094371,256.913544,13.0878,0.943711,-1277.893188,0.09549,0
68.590004,59.503632,-1277.937744,-0.001052,0.003742,0.095039,264.685364,13.483716,0.950387,-1277.937744,0.096027,0
68.910004,59.391174,-1277.848755,-0.001043,0.003748,0.095195,264.18515,13.458233,0.951946,-1277.848755,0.096556,0
69.230003,60.397324,-1277.848755,-0.00103,0.003767,0.095681,268.660706,13.686229,0.956806,-1277.848755,0.097095,0
69.550003,62.70417,-1277.893188,-0.001009,0.003798,0.09646,278.922089,14.208968,0.964603,-1277.893188,0.097623,0
69.870003,63.23555,-1277.893188,-0.001022,0.003815,0.096904,281.285767,14.329381,0.969039,-1277.893188,0.09816,0
70.190002,65.574417,-1277.893188,-0.000992,0.003842,0.097597,291.689575,14.859375,0.975973,-1277.893188,0.09869,0
70.510002,66.080841,-1277.848755,-0.000983,0.003848,0.097735,293.942261,14.974133,0.977351,-1277.848755,0.017156,0
70.830002,65.244125,-1277.893188,-0.00097,0.003848,0.097744,290.220367,14.78453,0.977442,-1277.893188,294.500458,0
71.150002,64.47406,-1277.937744,-0.00097,0.003853,0.097865,286.794952,14.610031,0.978653,-1277.937744,294.500458,0
71.470001,65.871948,-1277.893188,-0.000961,0.003851,0.097805,293.013062,14.926797,0.978047,-1277.893188,294.500458,0
71.790001,65.234818,-1277.982178,-0.000957,0.003852,0.09783,290.178955,14.782421,0.978305,-1277.982178,294.500458,0
72.110001,65.167419,-1277.893188,-0.000966,0.003872,0.098342,289.87915,14.767148,0.983422,-1277.893188,294.500458,0
72.43,65.000595,-1277.893188,-0.000961,0.003875,0.09843,289.137085,14.729345,0.9843,-1277.893188,294.500458,0
72.75,64.713867,-1277.937744,-0.000949,0.00388,0.098551,287.861664,14.664372,0.985511,-1277.937744,294.500458,0
73.07,65.568466,-1277.937744,-0.000949,0.003888,0.098759,291.663116,14.858027,0.987585,-1277.937744,294.500458,0
73.390007,65.268692,-1277.937744,-0.000953,0.003888,0.098768,290.329651,14.790096,0.987676,-1277.937744,294.500458,0
73.710007,64.983459,-1277.937744,-0.000931,0.003888,0.098768,289.060852,14.725462,0.987676,-1277.937744,294.500458,0
74.030006,64.7202,-1277.893188,-0.000944,0.003888,0.098768,287.889832,14.665807,0.987676,-1277.893188,294.500458,0
74.350006,65.673462,-1277.982178,-0.00094,0.003902,0.099107,292.130157,14.88182,0.991067,-1277.982178,294.500458,0
74.670006,65.512238,-1277.937744,-0.000944,0.003902,0.099107,291.412994,14.845285,0.991067,-1277.937744,294.500458,0
74.990005,65.313004,-1277.937744,-0.000923,0.003902,0.099107,290.526764,14.800138,0.991067,-1277.937744,294.500458,0
75.310005,65.105225,-1277.937744,-0.000931,0.003902,0.099107,289.602509,14.753055,0.991067,-1277.937744,294.500458,0
75.630005,64.910477,-1277.893188,-0.000927,0.003902,0.099107,288.736206,14.708923,0.991067,-1277.893188,294.500458,0
75.950005,64.686676,-1277.937744,-0.000944,0.003902,0.099114,287.740692,14.65821,0.991143,-1277.937744,294.500458,0
76.270004,64.510925,-1277.937744,-0.000931,0.003902,0.099114,286.958923,14.618384,0.991143,-1277.937744,294.500458,0
76.590004,65.354721,-1277.982178,-0.000918,0.003927,0.099756,290.712311,14.809591,0.997562,-1277.982178,294.500458,0
76.910004,66.215271,-1277.937744,-0.000914,0.003904,0.099149,294.540222,15.004595,0.991491,-1277.937744,294.500458,0
77.230003,66.012329,-1277.937744,-0.000905,0.003904,0.099149,293.637512,14.958608,0.991491,-1277.937744,294.500458,0
77.550003,65.828003,-1277.982178,-0.00091,0.003904,0.099149,292.817596,14.916839,0.991491,-1277.982178,294.500458,0
77.870003,65.611282,-1277.982178,-0.000905,0.003904,0.099158,291.853546,14.867729,0.991582,-1277.982178,294.500458,0
78.190002,65.501434,-1278.071167,-0.000923,0.003904,0.099158,291.364929,14.842837,0.991582,-1278.071167,294.500458,0
78.510002,65.310776,-1277.982178,-0.000914,0.003904,0.099158,290.516846,14.799634,0.991582,-1277.982178,294.500458,0
78.830002,65.183426,-1277.937744,-0.000901,0.003904,0.099158,289.950348,14.770775,0.991582,-1277.937744,294.500458,0
79.150002,65.027023,-1277.937744,-0.000918,0.003904,0.099167,289.254639,14.735333,0.991673,-1277.937744,294.500458,0
79.470001,65.304077,-1277.982178,-0.000901,0.003923,0.099652,290.48703,14.798116,0.996517,-1277.982178,294.500458,0
79.790001,65.272049,-1277.982178,-0.000897,0.003923,0.099644,290.344574,14.790857,0.996442,-1277.982178,294.500458,0
80.110001,65.200928,-1277.982178,-0.000914,0.003923,0.099644,290.028198,14.774741,0.996442,-1277.982178,294.500458,0
80.43,65.082886,-1278.026733,-0.000918,0.003923,0.099652,289.503143,14.747993,0.996517,-1278.026733,294.500458,0
80.750008,64.98793,-1277.982178,-0.000914,0.003923,0.099652,289.08075,14.726475,0.996517,-1277.982178,294.500458,0
81.070007,64.913452,-1278.071167,-0.000905,0.003923,0.099652,288.749451,14.709599,0.996517,-1278.071167,294.500458,0
81.390007,65.097778,-1278.071167,-0.000905,0.003929,0.099791,289.569366,14.751368,0.99791,-1278.071167,294.500458,0
81.710007,65.149918,-1277.937744,-0.000892,0.003929,0.099791,289.8013,14.763183,0.99791,-1277.937744,294.500458,0
82.030006,65.075806,-1277.937744,-0.000897,0.003929,0.099791,289.471649,14.746388,0.99791,-1277.937744,294.500458,0
82.350006,65.003204,-1278.026733,-0.000918,0.003929,0.099791,289.148682,14.729937,0.99791,-1278.026733,294.500458,0
82.670006,64.943985,-1277.982178,-0.000923,0.003929,0.099791,288.885284,14.716517,0.99791,-1277.982178,294.500458,0
82.990005,64.868393,-1278.026733,-0.00091,0.003929,0.099791,288.549011,14.699388,0.99791,-1278.026733,294.500458,0
83.310005,64.793549,-1277.982178,-0.000901,0.003929,0.0998,288.216095,14.682427,0.998001,-1277.982178,294.500458,0
83.630005,64.845688,-1277.937744,-0.000901,0.003931,0.099842,288.448029,14.694243,0.998425,-1277.937744,294.500458,0
83.950005,64.783493,-1277.937744,-0.000897,0.003931,0.099842,288.171356,14.680149,0.998425,-1277.937744,294.500458,0
84.270004,64.731735,-1278.071167,-0.000884,0.003932,0.099861,287.941132,14.668421,0.998607,-1278.071167,294.500458,0
84.590004,64.723923,-1278.026733,-0.000918,0.003932,0.099877,287.906403,14.66665,0.998773,-1278.026733,294.500458,0
84.910004,65.762085,-1277.937744,-0.000888,0.003943,0.100163,292.524353,14.901901,1.001635,-1277.937744,294.500458,0
85.230003,65.792999,-1277.982178,-0.000905,0.003943,0.100163,292.661865,14.908907,1.001635,-1277.982178,294.500458,0
85.550003,65.774384,-1277.937744,-0.000897,0.003943,0.100163,292.579071,14.904688,1.001635,-1277.937744,294.500458,0
85.870003,65.752045,-1278.026733,-0.000905,0.003943,0.100163,292.479706,14.899627,1.001635,-1278.026733,294.500458,0
86.190002,65.658569,-1278.026733,-0.000905,0.003943,0.100163,292.063904,14.878444,1.001635,-1278.026733,294.500458,0
86.510002,65.618729,-1277.982178,-0.000884,0.003943,0.100163,291.886688,14.869416,1.001635,-1277.982178,294.500458,0
86.830002,65.584091,-1277.982178,-0.000892,0.003943,0.100163,291.732605,14.861567,1.001635,-1277.982178,294.500458,0
87.150002,65.5383,-1278.026733,-0.000888,0.003943,0.100163,291.528931,14.851191,1.001635,-1278.026733,294.500458,0
87.470001,65.481689,-1278.071167,-0.000892,0.003943,0.100163,291.2771,14.838363,1.001635,-1278.071167,294.500458,0
87.790001,65.417648,-1277.982178,-0.000888,0.003943,0.100163,290.992218,14.823851,1.001635,-1277.982178,294.500458,0
88.110001,65.351364,-1277.937744,-0.00088,0.003943,0.100163,290.697388,14.808831,1.001635,-1277.937744,294.500458,0
88.430008,65.336838,-1277.982178,-0.000901,0.003944,0.100173,290.632782,14.805539,1.001725,-1277.982178,294.500458,0
88.750008,65.282104,-1278.026733,-0.000892,0.003944,0.100173,290.389313,14.793136,1.001725,-1278.026733,294.500458,0
89.070007,65.243744,-1278.026733,-0.000888,0.003944,0.100173,290.218658,14.784444,1.001725,-1278.026733,294.500458,0
89.390007,65.190872,-1278.026733,-0.000892,0.003944,0.100173,289.98349,14.772463,1.001725,-1278.026733,294.500458,0
89.710007,65.129807,-1277.982178,-0.000884,0.003944,0.100173,289.711853,14.758625,1.001725,-1277.982178,294.500458,0
90.030006,65.074326,-1277.982178,-0.000892,0.003944,0.100173,289.465057,14.746053,1.001725,-1277.982178,294.500458,0
90.350006,65.025909,-1277.982178,-0.000875,0.003944,0.100173,289.249695,14.735082,1.001725,-1277.982178,294.500458,0
90.670006,64.983093,-1278.071167,-0.000888,0.003944,0.100173,289.059235,14.725379,1.001725,-1278.071167,294.500458,0
90.990005,64.939896,-1278.071167,-0.00088,0.003944,0.100173,288.867096,14.715591,1.001725,-1278.071167,294.500458,0
91.310005,64.903778,-1278.026733,-0.00088,0.003944,0.100173,288.706421,14.707407,1.001725,-1278.026733,294.500458,0
91.630005,64.853134,-1277.982178,-0.000884,0.003944,0.100173,288.48114,14.69593,1.001725,-1277.982178,294.500458,0
91.950005,64.792801,-1278.026733,-0.000884,0.003944,0.100173,288.212769,14.682259,1.001725,-1278.026733,294.500458,0
92.270004,64.757797,-1278.026733,-0.000892,0.003944,0.100182,288.057068,14.674327,1.001816,-1278.026733,294.500458,0
92.590004,64.718338,-1278.071167,-0.000888,0.003944,0.100182,287.881531,14.665384,1.001816,-1278.071167,294.500458,0
92.910004,64.689285,-1277.982178,-0.000888,0.003944,0.100182,287.752319,14.658802,1.001816,-1277.982178,294.500458,0
93.230003,64.636414,-1278.071167,-0.000884,0.003944,0.100182,287.51712,14.646821,1.001816,-1278.071167,294.500458,0
93.550003,64.586884,-1277.982178,-0.000888,0.003944,0.100182,287.296814,14.635596,1.001816,-1277.982178,294.500458,0
93.870003,64.529541,-1278.026733,-0.00088,0.003944,0.100182,287.041748,14.622602,1.001816,-1278.026733,294.500458,0
94.190002,64.50235,-1278.115601,-0.000892,0.003944,0.100182,286.920776,14.616441,1.001816,-1278.115601,294.500458,0
94.510002,64.472198,-1278.026733,-0.00088,0.003944,0.100182,286.786652,14.609609,1.001816,-1278.026733,294.500458,0
94.830002,64.435699,-1278.026733,-0.00088,0.003944,0.100182,286.624298,14.601338,1.001816,-1278.026733,294.500458,0
95.150002,66.675522,-1278.026733,-0.000867,0.003907,0.099228,296.587524,15.10889,0.992278,-1278.026733,294.500458,0
95.470001,66.656525,-1278.115601,-0.000862,0.003907,0.099228,296.503021,15.104585,0.992278,-1278.115601,294.500458,0
95.790001,66.590988,-1278.026733,-0.000875,0.003907,0.099228,296.211517,15.089733,0.992278,-1278.026733,294.500458,0
96.110008,66.550034,-1278.026733,-0.000862,0.003907,0.099228,296.029327,15.080453,0.992278,-1278.026733,294.500458,0
96.430008,66.461777,-1278.026733,-0.000871,0.003907,0.099228,295.636749,15.060453,0.992278,-1278.026733,294.500458,0
96.750008,66.409653,-1278.026733,-0.000871,0.003907,0.099235,295.404877,15.048642,0.992354,-1278.026733,294.500458,0
97.070007,66.377258,-1278.026733,-0.000875,0.003907,0.099235,295.260803,15.041302,0.992354,-1278.026733,294.500458,0
97.390007,66.331818,-1278.160156,-0.000867,0.003907,0.099235,295.058655,15.031005,0.992354,-1278.160156,294.500458,0
97.710007,66.293839,-1277.982178,-0.000867,0.003907,0.099235,294.889709,15.022399,0.992354,-1277.982178,294.500458,0
98.030006,66.262939,-1278.071167,-0.000858,0.003907,0.099235,294.752289,15.015396,0.992354,-1278.071167,294.500458,0
98.350006,66.214523,-1277.982178,-0.000875,0.003907,0.099235,294.536896,15.004425,0.992354,-1277.982178,294.500458,0
98.670006,66.164993,-1278.071167,-0.000871,0.003907,0.099235,294.316589,14.993201,0.992354,-1278.071167,294.500458,0
98.990005,66.135208,-1278.071167,-0.000871,0.003907,0.099235,294.184113,14.986453,0.992354,-1278.071167,294.500458,0
99.310005,66.100586,-1278.071167,-0.000862,0.003907,0.099235,294.03009,14.978607,0.992354,-1278.071167,294.500458,0
99.630005,66.054398,-1278.026733,-0.000862,0.003907,0.099235,293.824646,14.968141,0.992354,-1278.026733,294.500458,0
99.950005,66.006744,-1278.026733,-0.000875,0.003907,0.099235,293.612671,14.957342,0.992354,-1278.026733,294.500458,0
100.270004,65.946411,-1278.071167,-0.000871,0.003907,0.099235,293.344299,14.943671,0.992354,-1278.071167,294.500458,0
100.590004,65.91774,-1278.115601,-0.000867,0.003908,0.099254,293.216766,14.937173,0.992536,-1278.115601,294.500458,0
100.910004,65.824646,-1278.115601,-0.000875,0.003908,0.099263,292.802643,14.916078,0.992627,-1278.115601,294.500458,0
101.230003,65.861511,-1278.071167,-0.000854,0.003908,0.099263,292.966644,14.924432,0.992627,-1278.071167,294.500458,0
101.550003,65.811249,-1278.071167,-0.000849,0.003909,0.099279,292.743042,14.913042,0.992793,-1278.071167,294.500458,0
101.870003,65.77066,-1278.071167,-0.000867,0.003909,0.099297,292.5625,14.903845,0.992975,-1278.071167,294.500458,0
102.190002,65.764328,-1278.115601,-0.000884,0.00391,0.099314,292.534332,14.902411,0.993141,-1278.115601,294.500458,0
102.510002,65.703262,-1278.071167,-0.000862,0.003911,0.099349,292.262695,14.888572,0.99349,-1278.071167,294.500458,0
102.830002,65.606812,-1278.071167,-0.000862,0.003915,0.099435,291.833679,14.866715,0.994352,-1278.071167,294.500458,0
103.150002,65.603088,-1278.071167,-0.000871,0.003918,0.099522,291.817108,14.865872,0.995215,-1278.071167,294.500458,0
103.470001,65.589691,-1278.115601,-0.000858,0.003918,0.099522,291.757507,14.862837,0.995215,-1278.115601,294.500458,0
103.790009,65.566223,-1278.071167,-0.000858,0.003919,0.09954,291.653137,14.857518,0.995397,-1278.071167,294.500458,0
104.110008,65.530106,-1278.115601,-0.000858,0.003919,0.09954,291.492462,14.849334,0.995397,-1278.115601,294.500458,0
104.430008,65.498459,-1278.115601,-0.000862,0.003922,0.099617,291.351685,14.842163,0.996169,-1278.115601,294.500458,0
104.750008,65.487274,-1278.026733,-0.000858,0.003923,0.099652,291.301941,14.839628,0.996517,-1278.026733,294.500458,0
105.070007,65.481689,-1278.115601,-0.000867,0.003923,0.099652,291.2771,14.838363,0.996517,-1278.115601,294.500458,0
105.390007,65.410568,-1278.071167,-0.000862,0.003927,0.099747,290.960754,14.822247,0.997471,-1278.071167,294.500458,0
105.710007,65.385254,-1278.160156,-0.000854,0.003927,0.099747,290.848145,14.81651,0.997471,-1278.160156,294.500458,0
106.030006,65.340942,-1278.071167,-0.000858,0.003928,0.099765,290.651031,14.80647,0.997653,-1278.071167,294.500458,0
106.350006,65.328644,-1278.071167,-0.00088,0.003929,0.0998,290.596313,14.803682,0.998001,-1278.071167,294.500458,0
106.670006,65.306305,-1278.071167,-0.00088,0.003929,0.0998,290.496948,14.79862,0.998001,-1278.071167,294.500458,0
106.990005,65.275772,-1278.071167,-0.000849,0.00393,0.099826,290.361145,14.791701,0.998258,-1278.071167,294.500458,0
107.310005,65.266464,-1278.071167,-0.000858,0.00393,0.099826,290.319733,14.789592,0.998258,-1278.071167,294.500458,0
107.630005,65.228104,-1278.115601,-0.000875,0.003931,0.099835,290.149109,14.780899,0.998349,-1278.115601,294.500458,0
107.950005,65.214325,-1278.071167,-0.000858,0.003932,0.099861,290.087799,14.777778,0.998607,-1278.071167,294.500458,0
108.270004,65.190506,-1278.071167,-0.000862,0.003932,0.099861,289.981842,14.77238,0.998607,-1278.071167,294.500458,0
108.590004,65.154373,-1278.071167,-0.000884,0.003936,0.099982,289.821136,14.764193,0.999818,-1278.071167,294.500458,0
108.910004,65.208008,-1278.071167,-0.00088,0.003946,0.100216,290.059692,14.776345,1.002164,-1278.071167,294.500458,0
109.230003,65.180817,-1278.115601,-0.00088,0.003946,0.100216,289.938751,14.770185,1.002164,-1278.115601,294.500458,0
109.550003,65.169281,-1278.160156,-0.000845,0.003948,0.100268,289.887451,14.76757,1.002679,-1278.160156,294.500458,0
109.870003,65.147675,-1278.071167,-0.000871,0.003948,0.100286,289.791321,14.762674,1.002861,-1278.071167,294.500458,0
110.190002,65.117889,-1278.115601,-0.000871,0.003948,0.100286,289.658844,14.755924,1.002861,-1278.115601,294.500458,0
110.510002,65.164429,-1278.115601,-0.000858,0.003955,0.10045,289.865845,14.766471,1.004496,-1278.115601,294.500458,0
110.830002,65.178207,-1278.115601,-0.000849,0.003956,0.100477,289.927155,14.769593,1.004768,-1278.115601,294.500458,0
111.150002,65.20018,-1278.071167,-0.000858,0.003956,0.100484,290.024872,14.774571,1.004844,-1278.071167,294.500458,0
111.470009,65.195709,-1278.071167,-0.000849,0.003956,0.100493,290.005005,14.773559,1.004935,-1278.071167,294.500458,0
111.790009,65.1689,-1278.071167,-0.000871,0.003956,0.100493,289.885742,14.767485,1.004935,-1278.071167,294.500458,0
112.110008,65.151779,-1278.160156,-0.000871,0.003956,0.100493,289.809601,14.763604,1.004935,-1278.160156,294.500458,0
112.430008,65.120499,-1278.20459,-0.000862,0.003957,0.100503,289.670441,14.756516,1.005026,-1278.20459,294.500458,0
112.750008,65.148788,-1278.115601,-0.000862,0.003961,0.100615,289.796295,14.762927,1.006146,-1278.115601,294.500458,0
113.070007,65.355087,-1278.071167,-0.000867,0.003962,0.100624,290.713959,14.809674,1.006237,-1278.071167,294.500458,0
113.390007,65.358444,-1278.160156,-0.000871,0.003962,0.100624,290.728882,14.810435,1.006237,-1278.160156,294.500458,0
113.710007,65.361786,-1278.071167,-0.000875,0.003962,0.100624,290.743744,14.811193,1.006237,-1278.071167,294.500458,0
114.030006,65.358444,-1278.115601,-0.000862,0.003962,0.100624,290.728882,14.810435,1.006237,-1278.115601,294.500458,0
114.350006,65.356949,-1278.160156,-0.00088,0.003962,0.100624,290.722229,14.810097,1.006237,-1278.160156,294.500458,0
114.670006,65.352859,-1278.071167,-0.000871,0.003962,0.100624,290.704041,14.80917,1.006237,-1278.071167,294.500458,0
114.990005,65.338699,-1278.115601,-0.000862,0.003962,0.100624,290.641052,14.805962,1.006237,-1278.115601,294.500458,0
115.310005,65.320084,-1278.115601,-0.000862,0.003962,0.100624,290.558258,14.801743,1.006237,-1278.115601,294.500458,0
115.630005,65.3078,-1278.160156,-0.000871,0.003962,0.100624,290.503601,14.798959,1.006237,-1278.160156,294.500458,0
115.950005,65.30072,-1278.115601,-0.000875,0.003962,0.100624,290.472107,14.797355,1.006237,-1278.115601,294.500458,0
116.270004,65.290665,-1278.071167,-0.000875,0.003962,0.100624,290.427368,14.795076,1.006237,-1278.071167,294.500458,0
116.590004,65.278748,-1278.071167,-0.000871,0.003962,0.100624,290.374359,14.792376,1.006237,-1278.071167,294.500458,0
116.910004,65.260513,-1278.115601,-0.000884,0.003962,0.100624,290.293274,14.788243,1.006237,-1278.115601,294.500458,0
117.230003,65.258652,-1278.160156,-0.00088,0.003962,0.100624,290.284973,14.787822,1.006237,-1278.160156,294.500458,0
117.550003,65.239655,-1278.160156,-0.000854,0.003962,0.100624,290.20047,14.783518,1.006237,-1278.160156,294.500458,0
117.870003,65.229233,-1278.071167,-0.000849,0.003962,0.100624,290.154114,14.781156,1.006237,-1278.071167,294.500458,0
118.190002,65.203537,-1278.026733,-0.00088,0.003962,0.100624,290.039825,14.775332,1.006237,-1278.026733,294.500458,0
118.510002,65.189758,-1278.160156,-0.000867,0.003962,0.100624,289.978516,14.77221,1.006237,-1278.160156,294.500458,0
118.830002,65.165924,-1278.115601,-0.000862,0.003962,0.100624,289.872498,14.766809,1.006237,-1278.115601,294.500458,0
119.150009,65.143951,-1278.115601,-0.000862,0.003962,0.100624,289.77478,14.76183,1.006237,-1278.115601,294.500458,0
119.470009,65.337585,-1278.115601,-0.000858,0.003967,0.100754,290.636108,14.805709,1.007539,-1278.115601,294.500458,0
119.790009,65.394928,-1277.982178,-0.000867,0.003967,0.100754,290.891174,14.818703,1.007539,-1277.982178,294.500458,0
120.110008,65.406097,-1278.115601,-0.000849,0.003967,0.100754,290.940857,14.821234,1.007539,-1278.115601,294.500458,0
120.430008,65.422119,-1278.160156,-0.000849,0.003967,0.100754,291.012115,14.824864,1.007539,-1278.160156,294.500458,0
120.750008,65.427322,-1278.115601,-0.000858,0.003967,0.100754,291.035278,14.826044,1.007539,-1278.115601,294.500458,0
121.070007,65.412811,-1278.115601,-0.000871,0.003967,0.100754,290.970703,14.822755,1.007539,-1278.115601,294.500458,0
121.390007,65.402756,-1278.071167,-0.000862,0.003967,0.100754,290.925995,14.820477,1.007539,-1278.071167,294.500458,0
121.710007,65.395309,-1278.115601,-0.000867,0.003967,0.100754,290.892853,14.818789,1.007539,-1278.115601,294.500458,0
122.030006,65.391586,-1278.115601,-0.000875,0.003967,0.100754,290.876312,14.817945,1.007539,-1278.115601,294.500458,0
122.350006,65.379288,-1278.071167,-0.000862,0.003967,0.100754,290.821594,14.815159,1.007539,-1278.071167,294.500458,0
122.670006,65.362167,-1278.115601,-0.000875,0.003967,0.100754,290.745453,14.811279,1.007539,-1278.115601,294.500458,0
122.990005,65.363281,-1278.071167,-0.000867,0.003967,0.100754,290.750397,14.811532,1.007539,-1278.071167,294.500458,0
123.310005,65.337585,-1278.115601,-0.000867,0.003967,0.100754,290.636108,14.805709,1.007539,-1278.115601,294.500458,0
123.630005,65.338333,-1278.160156,-0.000862,0.003967,0.100754,290.639435,14.805878,1.007539,-1278.160156,294.500458,0
123.950005,65.310028,-1278.20459,-0.000867,0.003967,0.100754,290.513519,14.799464,1.007539,-1278.20459,294.500458,0
124.270004,65.295135,-1278.071167,-0.000854,0.003967,0.100754,290.447266,14.796089,1.007539,-1278.071167,294.500458,0
124.590004,65.290298,-1278.071167,-0.000854,0.003967,0.100754,290.425751,14.794993,1.007539,-1278.071167,294.500458,0
124.910004,65.280243,-1278.115601,-0.000858,0.003967,0.100754,290.381012,14.792715,1.007539,-1278.115601,294.500458,0
125.230003,65.273163,-1278.115601,-0.000875,0.003967,0.100763,290.349518,14.79111,1.00763,-1278.115601,294.500458,0
125.550003,65.261993,-1278.115601,-0.000858,0.003967,0.100763,290.299835,14.788579,1.00763,-1278.115601,294.500458,0
125.870003,65.245605,-1278.160156,-0.000862,0.003967,0.100763,290.226959,14.784865,1.00763,-1278.160156,294.500458,0
126.190002,65.244873,-1278.115601,-0.00088,0.003967,0.100771,290.223694,14.784699,1.007706,-1278.115601,294.500458,0
126.51001,65.239288,-1278.160156,-0.000858,0.003968,0.100789,290.198853,14.783434,1.007887,-1278.160156,294.500458,0
126.830009,65.237793,-1278.160156,-0.000854,0.003969,0.100814,290.1922,14.783095,1.008145,-1278.160156,294.500458,0
127.150009,65.255661,-1278.160156,-0.000867,0.003969,0.100814,290.271667,14.787145,1.008145,-1278.160156,294.500458,0
127.470009,65.260513,-1278.160156,-0.000862,0.003969,0.100814,290.293274,14.788243,1.008145,-1278.160156,294.500458,0
127.790009,65.259384,-1278.115601,-0.000862,0.003969,0.100814,290.288239,14.787988,1.008145,-1278.115601,294.500458,0
128.110001,65.243744,-1278.115601,-0.000854,0.003969,0.100814,290.218658,14.784444,1.008145,-1278.115601,294.500458,0
128.430008,65.251938,-1278.20459,-0.000862,0.003969,0.100814,290.255127,14.7863,1.008145,-1278.20459,294.500458,0
128.75,65.237045,-1278.160156,-0.000854,0.003969,0.100814,290.188873,14.782926,1.008145,-1278.160156,294.500458,0
129.070007,65.230347,-1278.115601,-0.000862,0.003969,0.100814,290.159088,14.781407,1.008145,-1278.115601,294.500458,0
129.389999,65.229965,-1278.115601,-0.000867,0.003969,0.100814,290.157379,14.781322,1.008145,-1278.115601,294.500458,0
129.710007,65.221786,-1278.115601,-0.000862,0.003969,0.100814,290.121002,14.779469,1.008145,-1278.115601,294.500458,0
130.029999,65.20726,-1278.160156,-0.000884,0.003969,0.100814,290.056366,14.776176,1.008145,-1278.160156,294.500458,0
130.350006,65.200928,-1278.20459,-0.000849,0.003969,0.100824,290.028198,14.774741,1.008235,-1278.20459,294.500458,0
130.670013,65.182312,-1278.160156,-0.000858,0.003969,0.100824,289.945404,14.770522,1.008235,-1278.160156,294.500458,0
130.990005,65.193481,-1278.115601,-0.000862,0.003969,0.100824,289.995087,14.773054,1.008235,-1278.115601,1681.640747,0
131.310013,65.141724,-1278.115601,-0.000862,0.003961,0.100606,289.764862,14.761325,1.006055,-1278.115601,0.100537,0
131.630005,65.023682,-1278.160156,-0.000862,0.003948,0.100286,289.239777,14.734576,1.002861,-1278.160156,0.100008,0
131.950012,65.068359,-1278.20459,-0.000858,0.003933,0.099895,289.438507,14.744701,0.998955,-1278.20459,0.09947,0
132.270004,65.013245,-1278.115601,-0.000836,0.003915,0.099453,289.193359,14.732212,0.994534,-1278.115601,0.098942,0
132.590012,64.98793,-1278.115601,-0.000836,0.003895,0.098942,289.08075,14.726475,0.989417,-1278.115601,0.098404,0
132.910004,64.977509,-1278.160156,-0.000849,0.003872,0.098342,289.034393,14.724113,0.983422,-1278.160156,0.097874,0
133.230011,64.961868,-1278.160156,-0.000854,0.003854,0.097883,288.964813,14.72057,0.978834,-1278.160156,0.097337,0
133.550003,64.959625,-1278.20459,-0.000849,0.003834,0.097388,288.954834,14.720061,0.973884,-1278.20459,0.096809,0
133.87001,64.928726,-1278.20459,-0.000854,0.003813,0.096851,288.817413,14.713059,0.968509,-1278.20459,0.09627,0
134.190002,64.870255,-1278.160156,-0.000845,0.003789,0.096235,288.557312,14.69981,0.962347,-1278.160156,0.095741,0
134.51001,64.860199,-1278.160156,-0.000854,0.003774,0.095862,288.512573,14.697532,0.958623,-1278.160156,0.095204,0
134.830002,64.771576,-1278.160156,-0.000836,0.00375,0.095246,288.118347,14.677449,0.952461,-1278.160156,0.094674,0
135.150009,64.554123,-1278.20459,-0.000845,0.003729,0.094727,287.151093,14.628173,0.947268,-1278.20459,0.094136,0
135.470001,64.144882,-1278.160156,-0.000832,0.003717,0.094423,285.330688,14.535438,0.944225,-1278.160156,0.093608,0
135.790009,63.059784,-1278.115601,-0.000832,0.00369,0.093729,280.503937,14.289551,0.937291,-1278.115601,0.093071,0
136.110001,62.324348,-1278.071167,-0.000828,0.003676,0.093364,277.232544,14.1229,0.933643,-1278.071167,0.092541,0
136.430008,61.244843,-1278.160156,-0.000849,0.003656,0.092853,272.430664,13.87828,0.928526,-1278.160156,0.092003,0
136.75,60.067398,-1278.249146,-0.000836,0.003637,0.092368,267.193146,13.611467,0.923681,-1278.249146,0.091475,0
137.070007,58.561523,-1278.20459,-0.000845,0.003615,0.091812,260.494659,13.27023,0.918125,-1278.20459,0.090937,0
137.389999,56.978569,-1278.160156,-0.000828,0.003597,0.091361,253.453339,12.911528,0.913613,-1278.160156,0.090408,0
137.710007,55.32859,-1278.160156,-0.000811,0.003576,0.090842,246.113861,12.537638,0.90842,-1278.160156,0.08987,0
138.030014,53.52742,-1278.20459,-0.000819,0.003556,0.09033,238.101852,12.129486,0.903303,-1278.20459,0.089342,0
138.350006,51.433945,-1278.160156,-0.000836,0.003537,0.089844,228.789612,11.655098,0.898443,-1278.160156,0.088803,0
138.670013,49.74337,-1278.293579,-0.000819,0.003521,0.089428,221.269562,11.272009,0.89428,-1278.293579,0.088274,0
138.990005,47.077934,-1278.160156,-0.000841,0.003496,0.088795,209.413116,10.668013,0.887951,-1278.160156,0.087737,0
139.310013,44.656769,-1278.160156,-0.000828,0.003474,0.08824,198.643234,10.119369,0.882395,-1278.160156,0.087207,0
139.630005,42.428864,-1278.20459,-0.000828,0.003452,0.087693,188.733017,9.614518,0.87693,-1278.20459,0.08667,0
139.900009,40.574074,-1278.20459,-0.000836,0.003441,0.087407,180.482498,9.194217,0.874068,-1278.20459,0.087277,0