File: Data/compression 36/Heating-15-36-reverse-1-2_11202024_165635(in).csv
Time (sec),S:Load (lbs),S:HL1 (DIM),S:LVDT (in),S:Position (in),Ch:Position (mm),Ch:Load (N),Ch:Stress (MPa),Ch:Strain (mm/mm),Ch:HL1 (DIM),Set Point (),Cycles ()
0.11,-0.032028,-1276.825684,-0.008972,-0.008766,-0.22265,-0.142469,-0.007258,-2.226502,-1276.825684,-0.222434,0
0.42,-0.024582,-1276.692261,-0.008994,-0.008763,-0.22259,-0.109346,-0.00557,-2.225897,-1276.692261,-0.222052,0
0.73,-0.047295,-1276.736694,-0.008951,-0.008591,-0.218202,-0.210377,-0.010717,-2.182022,-1276.736694,-0.216884,0
1.04,-0.020485,-1276.825684,-0.008778,-0.008388,-0.213043,-0.091121,-0.004642,-2.130427,-1276.825684,-0.211733,0
1.35,-0.031281,-1276.736694,-0.008554,-0.008187,-0.207951,-0.139143,-0.007088,-2.079512,-1276.736694,-0.206564,0
1.66,0,-1276.78125,-0.008334,-0.007981,-0.202722,0,0,-2.02722,-1276.78125,-0.201396,0
1.97,-0.041336,-1276.692261,-0.008136,-0.007782,-0.197658,-0.183872,-0.009367,-1.976578,-1276.692261,-0.196227,0
2.28,-0.021599,-1276.736694,-0.007929,-0.007569,-0.192264,-0.096076,-0.004894,-1.922636,-1276.736694,-0.191075,0
2.59,-0.06144,-1276.825684,-0.007726,-0.007381,-0.187476,-0.273297,-0.013922,-1.874764,-1276.825684,-0.185906,0
2.9,-0.064049,-1276.736694,-0.007498,-0.007167,-0.182047,-0.284903,-0.014514,-1.820474,-1276.736694,-0.180738,0
3.21,0.007446,-1276.825684,-0.007291,-0.006964,-0.176888,0.033123,0.001687,-1.768878,-1276.825684,-0.175569,0
3.52,-0.025696,-1276.736694,-0.007075,-0.006763,-0.17178,-0.114301,-0.005823,-1.717797,-1276.736694,-0.170417,0
3.83,0.005211,-1276.736694,-0.006855,-0.006562,-0.166672,0.023179,0.001181,-1.666716,-1276.736694,-0.165249,0
4.14,-0.040588,-1276.736694,-0.00667,-0.006362,-0.161589,-0.180546,-0.009197,-1.615893,-1276.736694,-0.16008,0
4.45,-0.067032,-1276.736694,-0.00645,-0.006153,-0.156274,-0.298173,-0.01519,-1.562738,-1276.736694,-0.154911,0
4.76,-0.013031,-1276.825684,-0.006226,-0.005945,-0.151001,-0.057965,-0.002953,-1.510007,-1276.825684,-0.149761,0
5.07,-0.070007,-1276.692261,-0.006032,-0.00575,-0.146039,-0.311408,-0.015864,-1.460394,-1276.692261,-0.144592,0
5.38,0.005211,-1276.736694,-0.005803,-0.00554,-0.140715,0.023179,0.001181,-1.407148,-1276.736694,-0.139423,0
5.69,-0.004097,-1276.736694,-0.005596,-0.00534,-0.135625,-0.018224,-0.000928,-1.356249,-1276.736694,-0.134255,0
6,0.014893,-1276.78125,-0.005389,-0.005142,-0.130603,0.066245,0.003375,-1.306031,-1276.78125,-0.129086,0
6.31,-0.005585,-1276.870239,-0.005195,-0.004932,-0.125269,-0.024842,-0.001266,-1.252694,-1276.870239,-0.123934,0
6.62,-0.081177,-1276.736694,-0.00498,-0.004736,-0.120284,-0.361092,-0.018395,-1.20284,-1276.736694,-0.118765,0
6.93,-0.048782,-1276.825684,-0.004773,-0.004529,-0.115037,-0.216995,-0.011054,-1.150366,-1276.825684,-0.113597,0
7.24,-0.002609,-1276.825684,-0.004566,-0.004324,-0.109842,-0.011607,-0.000591,-1.098422,-1276.825684,-0.108428,0
7.55,0.104637,-1276.736694,-0.004415,0,0,0.465449,0.023711,0,-1276.736694,0.000191,0
7.860001,0.094955,-1276.78125,-0.004424,0,0,0.422383,0.021517,0,-1276.78125,0.000191,0
8.17,0.086388,-1276.736694,-0.004419,0,0,0.384271,0.019576,0,-1276.736694,0.000495,0
8.48,0.076706,-1276.825684,-0.004419,0,0,0.341205,0.017382,0,-1276.825684,0.001014,0
8.79,0.07708,-1276.736694,-0.004424,0,0,0.342868,0.017467,0,-1276.736694,0.001535,0
9.1,0.168686,-1276.736694,-0.004381,0.000039,0.000998,0.750352,0.038225,0.009977,-1276.736694,0.002047,0
9.410001,0.226028,-1276.736694,-0.004372,0.000058,0.001466,1.005425,0.051219,0.014655,-1276.736694,0.002568,0
9.72,0.276299,-1276.78125,-0.00435,0.000071,0.001796,1.229037,0.06261,0.017956,-1276.78125,0.003079,0
10.030001,0.361946,-1276.870239,-0.004329,0.000095,0.002412,1.610017,0.082018,0.024117,-1276.870239,0.003599,0
10.34,0.437164,-1276.736694,-0.004324,0.00011,0.002793,1.944604,0.099063,0.027933,-1276.736694,0.00411,0
10.650001,0.659096,-1276.78125,-0.004294,0.000139,0.003538,2.931804,0.149353,0.035381,-1276.78125,0.004631,0
10.960001,0.757401,-1276.870239,-0.004273,0.000157,0.00398,3.369086,0.171629,0.039802,-1276.870239,0.005152,0
11.27,0.970398,-1276.825684,-0.004243,0.000175,0.004457,4.316545,0.219895,0.044571,-1276.825684,0.005664,0
11.580001,1.144302,-1276.78125,-0.004221,0.000198,0.005031,5.090111,0.259303,0.050309,-1276.78125,0.006183,0
11.89,1.288406,-1276.825684,-0.004208,0.000219,0.005559,5.731118,0.291957,0.055593,-1276.825684,0.006695,0
12.200001,1.478317,-1276.78125,-0.004191,0.000239,0.006062,6.575883,0.334991,0.060619,-1276.78125,0.007216,0
12.51,1.690567,-1276.825684,-0.004169,0.000262,0.006652,7.520018,0.383088,0.066523,-1276.825684,0.007736,0
12.820001,1.946762,-1276.78125,-0.004152,0.000283,0.007181,8.65963,0.441143,0.071807,-1276.78125,0.008248,0
13.130001,2.094597,-1276.870239,-0.00413,0.0003,0.007623,9.317232,0.474642,0.076228,-1276.870239,0.008767,0
13.440001,2.216362,-1276.78125,-0.004118,0.000313,0.007953,9.858871,0.502235,0.079528,-1276.78125,0.009279,0
13.750001,2.499359,-1276.825684,-0.0041,0.000339,0.008604,11.117704,0.566363,0.086038,-1276.825684,0.0098,0
14.06,2.703796,-1276.870239,-0.00407,0.00036,0.009132,12.027087,0.612689,0.091322,-1276.870239,0.010312,0
14.370001,2.82444,-1276.736694,-0.004044,0.000374,0.009497,12.563737,0.640027,0.094971,-1276.736694,0.010832,0
14.68,3.184158,-1276.825684,-0.004014,0.000402,0.010216,14.163843,0.721541,0.102162,-1276.825684,0.011352,0
14.990001,3.307785,-1276.825684,-0.00401,0.000423,0.010737,14.713762,0.749555,0.10737,-1276.825684,0.011863,0
15.300001,3.284325,-1276.78125,-0.004001,0.000435,0.011049,14.609406,0.744239,0.110489,-1276.78125,0.012384,0
15.610001,3.574028,-1276.870239,-0.003975,0.000456,0.011577,15.89807,0.809886,0.115772,-1276.870239,0.012896,0
15.920001,3.817192,-1276.78125,-0.003949,0.000478,0.012142,16.979719,0.864988,0.121419,-1276.78125,0.013417,0
16.230001,3.92778,-1276.825684,-0.003941,0.000496,0.012601,17.47164,0.890048,0.126007,-1276.825684,0.013928,0
16.540001,4.208923,-1276.78125,-0.003915,0.000521,0.013234,18.722225,0.953756,0.132335,-1276.78125,0.014448,0
16.85,4.31691,-1276.870239,-0.003876,0.000545,0.01385,19.202574,0.978226,0.138497,-1276.870239,0.014969,0
17.160002,4.395111,-1276.870239,-0.003859,0.000564,0.014327,19.55043,0.995946,0.143266,-1276.870239,0.01548,0
17.470001,4.561935,-1276.78125,-0.003846,0.000585,0.014847,20.292501,1.033749,0.148474,-1276.78125,0.016001,0
17.780001,4.573479,-1276.870239,-0.003829,0.000599,0.01522,20.343849,1.036365,0.152198,-1276.870239,0.016513,0
18.09,4.685936,-1276.825684,-0.003811,0.000622,0.015801,20.844084,1.061848,0.158012,-1276.825684,0.017032,0
18.400002,5.024422,-1276.78125,-0.003777,0.000646,0.016417,22.349745,1.13855,0.164174,-1276.78125,0.017553,0
18.710001,5.058304,-1276.825684,-0.003764,0.000665,0.016902,22.50046,1.146228,0.169018,-1276.825684,0.018065,0
19.02,5.083626,-1276.78125,-0.003747,0.000683,0.017345,22.613096,1.151966,0.173454,-1276.78125,0.018585,0
19.330002,5.270187,-1276.870239,-0.003734,0.000705,0.0179,23.442965,1.194242,0.178995,-1276.870239,0.019097,0
19.640001,5.303329,-1276.78125,-0.003708,0.000723,0.018376,23.590387,1.201752,0.183764,-1276.78125,0.019616,0
19.950001,5.400887,-1276.825684,-0.003686,0.000747,0.018984,24.024343,1.223858,0.189835,-1276.825684,0.020128,0
20.26,5.398285,-1276.825684,-0.003682,0.00076,0.019304,24.01277,1.223269,0.193045,-1276.825684,0.020649,0
20.570002,5.731926,-1276.78125,-0.003635,0.00079,0.020058,25.49688,1.298873,0.200584,-1276.78125,0.02117,0
20.880001,5.879761,-1276.870239,-0.003617,0.000817,0.020753,26.154482,1.332373,0.207533,-1276.870239,0.021681,0
21.190001,5.702141,-1276.825684,-0.003622,0.000831,0.0211,25.364389,1.292124,0.211,-1276.825684,0.022201,0
21.500002,5.76432,-1276.870239,-0.003579,0.000847,0.021507,25.640978,1.306214,0.215073,-1276.870239,0.022712,0
21.810001,6.027588,-1276.870239,-0.003544,0.000871,0.022133,26.81205,1.365871,0.221326,-1276.870239,0.023233,0
22.120001,5.981789,-1276.78125,-0.00354,0.000884,0.022461,26.608324,1.355493,0.224611,-1276.78125,0.023754,0
22.43,6.310966,-1276.914673,-0.003514,0.000916,0.023268,28.07258,1.430085,0.23268,-1276.914673,0.024266,0
22.740002,6.237236,-1276.870239,-0.003497,0.000933,0.023701,27.744612,1.413378,0.23701,-1276.870239,0.024785,0
23.050001,6.177658,-1276.870239,-0.003475,0.000949,0.02411,27.479595,1.399877,0.241098,-1276.870239,0.025297,0
23.360001,6.248405,-1276.914673,-0.003462,0.000967,0.024552,27.794296,1.415909,0.245519,-1276.914673,0.025818,0
23.670002,6.384697,-1276.870239,-0.003449,0.000989,0.025115,28.400551,1.446793,0.25115,-1276.870239,0.026329,0
23.980001,6.405922,-1276.870239,-0.003428,0.001005,0.025531,28.494965,1.451603,0.255314,-1276.870239,0.02685,0
24.290001,6.91198,-1276.825684,-0.003385,0.00104,0.026408,30.746021,1.566277,0.26408,-1276.825684,0.027369,0
24.6,6.636795,-1276.870239,-0.003354,0.001052,0.02672,29.521938,1.503919,0.267198,-1276.870239,0.027881,0
24.910002,6.578705,-1276.914673,-0.003328,0.001067,0.027092,29.26354,1.490756,0.270923,-1276.914673,0.028402,0
25.220001,6.762283,-1276.870239,-0.003328,0.001089,0.027648,30.080139,1.532355,0.276479,-1276.870239,0.028914,0
25.530001,6.752602,-1276.914673,-0.003303,0.001108,0.028141,30.037073,1.530161,0.281415,-1276.914673,0.029434,0
25.840002,6.739937,-1276.870239,-0.003298,0.001122,0.028488,29.980736,1.527292,0.284881,-1276.870239,0.029954,0
26.150002,7.28286,-1276.914673,-0.003255,0.001156,0.029356,32.395779,1.65032,0.293556,-1276.914673,0.030465,0
26.460001,7.187531,-1276.959106,-0.003234,0.001174,0.029816,31.971733,1.628718,0.298159,-1276.959106,0.030986,0
26.77,7.100395,-1276.914673,-0.003229,0.001188,0.030172,31.584135,1.608973,0.301717,-1276.914673,0.031498,0
27.080002,7.405373,-1276.959106,-0.003208,0.001219,0.03096,32.940742,1.678081,0.309604,-1276.959106,0.032019,0
27.390001,7.409096,-1276.870239,-0.003191,0.001238,0.031454,32.957302,1.678925,0.31454,-1276.870239,0.03253,0
27.700001,7.212852,-1276.914673,-0.003156,0.001247,0.031672,32.08437,1.634456,0.31672,-1276.914673,0.03305,0
28.010002,7.608315,-1276.959106,-0.003143,0.001278,0.032461,33.843472,1.724069,0.324608,-1276.959106,0.033571,0
28.320002,7.79599,-1276.959106,-0.003096,0.0013,0.033024,34.678295,1.766597,0.33024,-1276.959106,0.034082,0
28.630001,7.581131,-1276.959106,-0.003104,0.001313,0.033345,33.722553,1.717909,0.333449,-1276.959106,0.034603,0
28.940001,7.868973,-1276.870239,-0.003078,0.001337,0.033952,35.002937,1.783135,0.33952,-1276.870239,0.035115,0
29.250002,7.945312,-1276.959106,-0.003053,0.001356,0.034438,35.342514,1.800434,0.34438,-1276.959106,0.035634,0
29.560001,7.860039,-1276.914673,-0.003035,0.001374,0.034889,34.9632,1.78111,0.348892,-1276.914673,0.036146,0
29.870001,8.23613,-1276.914673,-0.002992,0.001399,0.035539,36.636135,1.866334,0.355386,-1276.914673,0.036667,0
30.180002,8.371307,-1277.003662,-0.002984,0.001422,0.036111,37.237434,1.896965,0.361109,-1277.003662,0.037187,0
30.490002,8.416359,-1276.959106,-0.002958,0.001441,0.036606,37.437836,1.907174,0.36606,-1276.959106,0.037699,0
30.800001,8.417847,-1276.914673,-0.002949,0.001459,0.037065,37.44445,1.907511,0.370647,-1276.914673,0.038218,0
31.110001,8.531799,-1277.003662,-0.002928,0.001481,0.03762,37.95134,1.933333,0.376203,-1277.003662,0.03873,0
31.420002,8.432747,-1276.870239,-0.00291,0.001493,0.037932,37.510731,1.910888,0.379322,-1276.870239,0.039251,0
31.730001,8.464767,-1277.003662,-0.002889,0.001509,0.038323,37.653168,1.918144,0.383228,-1277.003662,0.039772,0
32.040001,8.999123,-1276.959106,-0.002846,0.001542,0.039172,40.030098,2.03923,0.391721,-1276.959106,0.040283,0
32.350002,9.017746,-1276.959106,-0.002828,0.001563,0.039702,40.112938,2.04345,0.39702,-1276.959106,0.040803,0
32.66,8.921295,-1277.048096,-0.002815,0.001577,0.040049,39.683903,2.021595,0.400487,-1277.048096,0.041314,0
32.970001,9.069878,-1276.959106,-0.002794,0.001599,0.040604,40.34483,2.055264,0.406044,-1276.959106,0.041835,0
33.280003,9.172279,-1277.003662,-0.002777,0.001617,0.041081,40.800335,2.078468,0.410812,-1277.003662,0.042347,0
33.59,9.277657,-1276.959106,-0.002759,0.001638,0.041601,41.269077,2.102347,0.416005,-1276.959106,0.042868,0
33.900002,9.645935,-1276.914673,-0.002734,0.001664,0.042277,42.907261,2.1858,0.422773,-1276.914673,0.043387,0
34.210003,9.644821,-1277.003662,-0.002716,0.001683,0.042754,42.902306,2.185548,0.427542,-1277.003662,0.043899,0
34.52,9.612419,-1276.914673,-0.002677,0.0017,0.043171,42.758175,2.178205,0.431705,-1276.914673,0.04442,0
34.830002,9.84404,-1277.003662,-0.002686,0.001722,0.043734,43.788475,2.230691,0.437337,-1277.003662,0.044931,0
35.140003,9.881271,-1276.959106,-0.002652,0.001742,0.044245,43.95409,2.239128,0.442454,-1276.959106,0.045452,0
35.450001,10.180664,-1277.048096,-0.002634,0.001762,0.044766,45.285854,2.306972,0.447662,-1277.048096,0.045971,0
35.760002,10.153107,-1276.959106,-0.002617,0.001782,0.045269,45.163273,2.300727,0.452689,-1276.959106,0.046483,0
36.070004,10.639053,-1276.914673,-0.002574,0.001808,0.045911,47.324871,2.410844,0.459108,-1276.914673,0.047004,0
36.380001,10.556015,-1277.003662,-0.00257,0.001824,0.046327,46.955502,2.392027,0.463271,-1277.003662,0.047516,0
36.690002,10.487869,-1276.914673,-0.002557,0.001838,0.046683,46.652374,2.376585,0.466829,-1276.914673,0.048036,0
37,10.741081,-1277.003662,-0.002535,0.001862,0.047299,47.778717,2.433964,0.472991,-1277.003662,0.048548,0
37.310001,10.869926,-1276.959106,-0.002527,0.001881,0.047776,48.351849,2.463161,0.47776,-1276.959106,0.049067,0
37.620003,10.938065,-1276.959106,-0.002501,0.001898,0.048209,48.654942,2.478601,0.48209,-1276.959106,0.049588,0
37.93,11.765854,-1277.003662,-0.002462,0.001933,0.049095,52.337132,2.666181,0.490946,-1277.003662,0.0501,0
38.240002,11.544662,-1277.048096,-0.002449,0.001948,0.049484,51.353222,2.616058,0.494837,-1277.048096,0.050621,0
38.550003,11.510406,-1276.959106,-0.002427,0.001965,0.049909,51.200844,2.608295,0.499091,-1276.959106,0.051132,0
38.860001,12.010872,-1277.003662,-0.002414,0.00199,0.050551,53.427025,2.721702,0.505511,-1277.003662,0.051652,0
39.170002,12.074173,-1276.959106,-0.002406,0.002008,0.051002,53.708603,2.736047,0.510022,-1276.959106,0.052163,0
39.480003,12.093536,-1277.003662,-0.002367,0.002023,0.051391,53.794735,2.740435,0.513913,-1277.003662,0.052684,0
39.790001,12.614487,-1276.914673,-0.002354,0.002048,0.052026,56.112038,2.858484,0.520257,-1276.914673,0.053205,0
40.100002,12.659172,-1276.959106,-0.00232,0.00207,0.052572,56.31081,2.868609,0.525722,-1276.959106,0.053717,0
40.410004,12.761948,-1277.003662,-0.002302,0.002086,0.052996,56.767979,2.891899,0.529961,-1277.003662,0.054236,0
40.720001,13.15815,-1276.914673,-0.002289,0.00211,0.053587,58.530373,2.981679,0.535865,-1276.914673,0.054748,0
41.030003,13.364075,-1277.003662,-0.002264,0.002131,0.054124,59.446373,3.028342,0.54124,-1277.003662,0.055269,0
41.34,13.380089,-1276.959106,-0.002251,0.002147,0.05454,59.517609,3.031971,0.545403,-1276.959106,0.055789,0
41.650002,13.303375,-1276.959106,-0.002251,0.002162,0.054922,59.176369,3.014588,0.549219,-1276.959106,0.056301,0
41.960003,14.185158,-1276.959106,-0.002216,0.002193,0.055702,63.098732,3.214403,0.557015,-1276.959106,0.05682,0
42.27,14.467041,-1277.003662,-0.002186,0.002218,0.056343,64.352615,3.278278,0.563435,-1277.003662,0.057332,0
42.580002,14.466293,-1277.048096,-0.002169,0.002235,0.056778,64.349289,3.278109,0.56778,-1277.048096,0.057853,0
42.890003,14.217926,-1277.003662,-0.002156,0.002245,0.057029,63.244495,3.221828,0.570293,-1277.003662,0.058365,0
43.200001,14.999161,-1277.003662,-0.00213,0.002272,0.057706,66.719597,3.398859,0.57706,-1277.003662,0.058885,0
43.510002,14.986504,-1277.003662,-0.00213,0.002292,0.058209,66.6633,3.39599,0.582087,-1277.003662,0.059405,0
43.820004,15.779282,-1276.959106,-0.0021,0.002317,0.058858,70.189751,3.575636,0.588581,-1276.959106,0.059916,0
44.130001,15.638901,-1277.092529,-0.002082,0.002332,0.059232,69.565308,3.543825,0.592321,-1277.092529,0.060437,0
44.440002,15.713371,-1276.959106,-0.002052,0.002349,0.059656,69.896568,3.560701,0.59656,-1276.959106,0.060949,0
44.750004,16.13266,-1277.092529,-0.002039,0.002372,0.060246,71.761658,3.655713,0.602464,-1277.092529,0.06147,0
45.060001,16.364655,-1277.003662,-0.002035,0.002388,0.060645,72.793617,3.708284,0.606446,-1277.003662,0.061989,0
45.370003,16.664413,-1277.003662,-0.002005,0.002409,0.061191,74.127014,3.77621,0.611912,-1277.003662,0.062501,0
45.68,17.772591,-1277.048096,-0.001988,0.00244,0.061981,79.056435,4.027327,0.619814,-1277.048096,0.063022,0
45.990002,17.671677,-1276.959106,-0.001949,0.002456,0.06238,78.607544,4.004459,0.623796,-1276.959106,0.063533,0
46.300003,17.455704,-1277.048096,-0.001957,0.00247,0.062744,77.646851,3.955519,0.627445,-1277.048096,0.064054,0
46.610001,17.956543,-1277.003662,-0.001936,0.002493,0.063324,79.874695,4.069011,0.633243,-1277.003662,0.064566,0
46.920002,18.259651,-1276.959106,-0.001906,0.00251,0.063759,81.222984,4.137696,0.637588,-1276.959106,0.065085,0
47.230003,18.244385,-1277.048096,-0.001897,0.00252,0.06401,81.155075,4.134236,0.640101,-1277.048096,0.065606,0
47.540001,19.821388,-1277.003662,-0.00188,0.002555,0.064887,88.169937,4.491591,0.648867,-1277.003662,0.066118,0
47.850002,19.92453,-1277.003662,-0.001858,0.002577,0.06545,88.628738,4.514963,0.654499,-1277.003662,0.066638,0
48.160004,20.652519,-1277.048096,-0.001845,0.0026,0.066039,91.866997,4.679927,0.660388,-1277.048096,0.06715,0
48.470001,20.754921,-1277.003662,-0.001824,0.002618,0.06649,92.322502,4.703133,0.6649,-1277.003662,0.067669,0
48.780003,21.092293,-1277.003662,-0.001819,0.002639,0.067027,93.823204,4.779582,0.670275,-1277.003662,0.068181,0
49.090004,21.519775,-1276.959106,-0.001802,0.00266,0.067557,95.724739,4.876451,0.675573,-1276.959106,0.068702,0
49.400002,22.267868,-1277.003662,-0.001772,0.002682,0.068121,99.052422,5.045971,0.681205,-1277.003662,0.069223,0
49.710003,22.852867,-1276.959106,-0.001755,0.002703,0.068667,101.654633,5.178534,0.686671,-1276.959106,0.069734,0
50.020004,22.707642,-1277.003662,-0.001733,0.002715,0.068971,101.008636,5.145625,0.689714,-1277.003662,0.070254,0
50.330002,23.226357,-1277.048096,-0.001716,0.002735,0.069474,103.315994,5.263167,0.69474,-1277.048096,0.070765,0
50.640003,23.688843,-1277.003662,-0.001707,0.002758,0.070046,105.373238,5.367969,0.700463,-1277.003662,0.071286,0
50.950001,24.600784,-1277.048096,-0.001686,0.002782,0.070653,109.429756,5.574617,0.706534,-1277.048096,0.071807,0
51.260002,25.090454,-1277.003662,-0.001673,0.002799,0.071086,111.60791,5.685578,0.710864,-1277.003662,0.072319,0
51.570004,25.759239,-1277.003662,-0.00166,0.002821,0.071659,114.582817,5.837127,0.716587,-1277.003662,0.072838,0
51.880001,26.126396,-1277.048096,-0.001638,0.00284,0.072128,116.216011,5.920326,0.72128,-1277.048096,0.07335,0
52.190002,26.521858,-1276.959106,-0.001613,0.002859,0.072612,117.975121,6.009939,0.726125,-1276.959106,0.073871,0
52.500004,27.32357,-1277.003662,-0.001591,0.002882,0.073194,121.541313,6.191609,0.731938,-1277.003662,0.074382,0
52.810001,27.591309,-1277.048096,-0.001587,0.002898,0.073619,122.732269,6.25228,0.736192,-1277.048096,0.074903,0
53.120003,27.852715,-1277.003662,-0.001578,0.002915,0.074052,123.895065,6.311515,0.740522,-1277.003662,0.075422,0
53.430004,29.57605,-1277.092529,-0.001548,0.002945,0.074815,131.560837,6.702029,0.748153,-1277.092529,0.075934,0
53.740002,30.191582,-1277.003662,-0.001548,0.002967,0.075371,134.298859,6.84151,0.753709,-1277.003662,0.076455,0
54.050003,30.29213,-1277.003662,-0.001518,0.002984,0.075804,134.746124,6.864295,0.758039,-1277.003662,0.076967,0
54.360004,30.591888,-1277.092529,-0.001509,0.002998,0.076143,136.079514,6.932221,0.76143,-1277.092529,0.077487,0
54.670002,31.758156,-1277.003662,-0.001487,0.003023,0.076792,141.267334,7.196501,0.767925,-1277.003662,0.078007,0
54.980003,32.037064,-1277.092529,-0.001475,0.003039,0.077192,142.50798,7.259702,0.771922,-1277.092529,0.078518,0
55.290001,33.32473,-1277.048096,-0.001487,0.003065,0.07786,148.235809,7.551492,0.778598,-1277.048096,0.079039,0
55.600002,33.761894,-1277.092529,-0.001462,0.003084,0.078328,150.180405,7.650555,0.783276,-1277.092529,0.079551,0
55.910004,34.329018,-1277.092529,-0.001444,0.0031,0.078735,152.703094,7.779067,0.787349,-1277.092529,0.080072,0
56.220001,34.550201,-1277.092529,-0.00141,0.00312,0.079247,153.686966,7.829187,0.792466,-1277.092529,0.080583,0
56.530003,36.438133,-1277.092529,-0.001414,0.003146,0.079907,162.084915,8.256999,0.799067,-1277.092529,0.081103,0
56.840004,36.972488,-1277.048096,-0.001401,0.003162,0.080314,164.461838,8.378085,0.80314,-1277.048096,0.081624,0
57.150002,37.612968,-1277.092529,-0.00138,0.003187,0.080938,167.310837,8.52322,0.809377,-1277.092529,0.082135,0
57.460003,39.03022,-1277.092529,-0.00138,0.003208,0.081477,173.615097,8.844375,0.814767,-1277.092529,0.082656,0
57.770004,39.367218,-1277.003662,-0.001345,0.003223,0.081858,175.114136,8.920739,0.818582,-1277.003662,0.083168,0
58.080002,39.986839,-1277.048096,-0.001354,0.003242,0.082335,177.870346,9.061148,0.823351,-1277.048096,0.083687,0
58.390003,41.016823,-1277.048096,-0.001324,0.003263,0.082889,182.451935,9.294545,0.828892,-1277.048096,0.084208,0
58.700005,42.053513,-1277.048096,-0.001315,0.003285,0.083445,187.06337,9.529463,0.834448,-1277.048096,0.08472,0
59.010002,42.927094,-1277.137085,-0.001293,0.003306,0.083966,190.949249,9.727418,0.839656,-1277.137085,0.08524,0
59.320004,44.742783,-1277.048096,-0.001285,0.003333,0.08465,199.025833,10.138859,0.846499,-1277.048096,0.085752,0
59.630001,45.301346,-1277.137085,-0.001272,0.003352,0.085136,201.510452,10.265432,0.851359,-1277.137085,0.086271,0
59.940002,46.062103,-1277.003662,-0.00125,0.003368,0.085552,204.89447,10.437822,0.855523,-1277.003662,0.086783,0
60.250004,47.206398,-1277.048096,-0.001246,0.00339,0.086106,209.984543,10.697123,0.861064,-1277.048096,0.087304,0
60.560001,47.885605,-1277.048096,-0.001237,0.003407,0.086532,213.005814,10.851033,0.865318,-1277.048096,0.087825,0
60.870003,48.455711,-1277.092529,-0.001233,0.003422,0.086913,215.541763,10.980221,0.869133,-1277.092529,0.088336,0
61.180004,50.496307,-1277.092529,-0.00122,0.003455,0.087746,224.61879,11.442626,0.87746,-1277.092529,0.088856,0
61.490002,51.465599,-1277.003662,-0.001207,0.003472,0.088197,228.93042,11.662271,0.881971,-1277.003662,0.089367,0
61.800003,52.11911,-1277.092529,-0.001168,0.003487,0.08857,231.837387,11.810359,0.885696,-1277.092529,0.089888,0
62.110004,53.424278,-1277.048096,-0.001173,0.003511,0.089186,237.643051,12.106114,0.891858,-1277.048096,0.0904,0
62.420002,54.598366,-1277.048096,-0.00116,0.003529,0.089646,242.865662,12.372167,0.89646,-1277.048096,0.090921,0
62.730003,55.473442,-1277.092529,-0.001151,0.003547,0.090088,246.758194,12.570462,0.900881,-1277.092529,0.09144,0
63.040005,56.530975,-1277.003662,-0.001147,0.003572,0.09073,251.462341,12.810102,0.9073,-1277.003662,0.091952,0
63.350002,58.331398,-1277.092529,-0.001143,0.003593,0.091267,259.471008,13.218083,0.912674,-1277.092529,0.092473,0
63.660004,60.04245,-1277.048096,-0.001121,0.003618,0.0919,267.082153,13.605813,0.919003,-1277.048096,0.092984,0
63.970001,60.754051,-1277.048096,-0.001121,0.003634,0.092298,270.247528,13.767065,0.922984,-1277.048096,0.093505,0
64.280006,60.991631,-1277.092529,-0.001095,0.003646,0.092612,271.304321,13.820901,0.926118,-1277.092529,0.094024,0
64.590004,62.925728,-1277.092529,-0.001087,0.003671,0.093236,279.907623,14.259174,0.932356,-1277.092529,0.094536,0
64.900002,64.401077,-1277.137085,-0.001087,0.003699,0.093947,286.470306,14.593493,0.939471,-1277.137085,0.095057,0
65.210007,66.022751,-1277.048096,-0.001082,0.003718,0.094433,293.683868,14.96097,0.944331,-1277.048096,0.095569,0
65.520004,65.710327,-1277.048096,-0.001052,0.003715,0.094354,292.294128,14.890173,0.943544,-1277.048096,0.016565,0
65.830002,65.013626,-1277.181519,-0.001061,0.003715,0.094371,289.195038,14.732298,0.943711,-1277.181519,294.500458,0
66.139999,65.62915,-1277.048096,-0.001052,0.003731,0.09478,291.933044,14.871778,0.947798,-1277.048096,294.500458,0
66.450005,65.115646,-1277.048096,-0.001043,0.003731,0.09478,289.648865,14.755416,0.947798,-1277.048096,294.500458,0
66.760002,65.000961,-1277.048096,-0.001048,0.003746,0.095152,289.138702,14.729428,0.951523,-1277.048096,294.500458,0
67.07,65.511108,-1277.092529,-0.001043,0.003745,0.095127,291.407959,14.845029,0.951265,-1277.092529,294.500458,0
67.380005,65.130554,-1277.137085,-0.001035,0.003745,0.095127,289.715179,14.758794,0.951265,-1277.137085,294.500458,0
67.690002,64.768982,-1277.092529,-0.00103,0.003745,0.095127,288.106812,14.676862,0.951265,-1277.092529,294.500458,0
68,66.008224,-1277.137085,-0.001026,0.003759,0.09549,293.619232,14.957678,0.954899,-1277.137085,294.500458,0
68.310005,65.587448,-1277.092529,-0.001026,0.003757,0.095422,291.747528,14.862329,0.954217,-1277.092529,294.500458,0
68.620003,65.264969,-1277.048096,-0.001018,0.003757,0.095422,290.31308,14.789253,0.954217,-1277.048096,294.500458,0
68.93,64.968201,-1277.137085,-0.001018,0.003757,0.095422,288.992981,14.722005,0.954217,-1277.137085,294.500458,0
69.240005,64.848663,-1277.092529,-0.001,0.003761,0.095534,288.461273,14.694917,0.955338,-1277.092529,294.500458,0
69.550003,64.724655,-1277.137085,-0.001026,0.003764,0.095594,287.909637,14.666817,0.955943,-1277.137085,294.500458,0
69.860001,64.884781,-1277.137085,-0.001009,0.003773,0.095838,288.621918,14.703102,0.958381,-1277.137085,294.500458,0
70.170006,65.451538,-1277.137085,-0.001005,0.003773,0.095829,291.142975,14.831531,0.95829,-1277.137085,294.500458,0
70.480003,65.247467,-1277.137085,-0.001009,0.003773,0.095829,290.235229,14.785287,0.95829,-1277.137085,294.500458,0
70.790001,65.047516,-1277.137085,-0.001005,0.003773,0.095838,289.345795,14.739977,0.958381,-1277.137085,294.500458,0
71.100006,64.914566,-1277.092529,-0.001009,0.003773,0.095838,288.754425,14.709851,0.958381,-1277.092529,294.500458,0
71.410004,64.726898,-1277.048096,-0.001,0.003773,0.095838,287.919617,14.667325,0.958381,-1277.048096,294.500458,0
71.720001,65.609055,-1277.137085,-0.000996,0.003785,0.096132,291.843658,14.867224,0.961318,-1277.137085,294.500458,0
72.030006,65.577774,-1277.137085,-0.000987,0.003785,0.096132,291.704498,14.860135,0.961318,-1277.137085,294.500458,0
72.340004,65.483551,-1277.137085,-0.001009,0.003785,0.096132,291.28537,14.838785,0.961318,-1277.137085,294.500458,0
72.650002,65.34169,-1277.137085,-0.001013,0.003785,0.096132,290.654358,14.806639,0.961318,-1277.137085,294.500458,0
72.960007,65.24115,-1277.137085,-0.001013,0.003785,0.096132,290.207123,14.783856,0.961318,-1277.137085,294.500458,0
73.270004,65.079529,-1277.092529,-0.001,0.003785,0.096141,289.48819,14.747232,0.961409,-1277.092529,294.500458,0
73.580002,64.962234,-1277.181519,-0.001009,0.003785,0.096141,288.966461,14.720654,0.961409,-1277.181519,294.500458,0
73.890007,64.822601,-1277.181519,-0.000987,0.003785,0.096141,288.345337,14.689012,0.961409,-1277.181519,294.500458,0
74.200005,64.725403,-1277.137085,-0.000987,0.003785,0.09615,287.912964,14.666986,0.9615,-1277.137085,294.500458,0
74.510002,64.617798,-1277.181519,-0.001,0.003785,0.09615,287.434326,14.642602,0.9615,-1277.181519,294.500458,0
74.820007,64.502731,-1277.137085,-0.000987,0.003785,0.09615,286.922485,14.616529,0.9615,-1277.137085,294.500458,0
75.130005,64.418945,-1277.181519,-0.000987,0.003785,0.09615,286.549774,14.597542,0.9615,-1277.181519,294.500458,0
75.440002,64.302399,-1277.137085,-0.000987,0.003786,0.096158,286.031342,14.571132,0.961575,-1277.137085,294.500458,0
75.75,64.207443,-1277.181519,-0.000992,0.003786,0.096158,285.608978,14.549615,0.961575,-1277.181519,294.500458,0
76.060005,66.411514,-1277.137085,-0.000992,0.003777,0.095933,295.413177,15.049065,0.959335,-1277.137085,294.500458,0
76.370003,66.294586,-1277.048096,-0.000983,0.003777,0.095933,294.893036,15.022568,0.959335,-1277.048096,294.500458,0
76.68,66.169098,-1277.137085,-0.000974,0.003777,0.095933,294.334839,14.994132,0.959335,-1277.137085,294.500458,0
76.990005,66.068558,-1277.226074,-0.00097,0.003777,0.095933,293.887634,14.971349,0.959335,-1277.226074,294.500458,0
77.300003,65.950134,-1277.181519,-0.000974,0.003777,0.095933,293.36084,14.944514,0.959335,-1277.181519,294.500458,0
77.610001,65.861511,-1277.137085,-0.000979,0.003777,0.095933,292.966644,14.924432,0.959335,-1277.137085,294.500458,0
77.920006,65.775497,-1277.181519,-0.000966,0.003777,0.095933,292.584015,14.904941,0.959335,-1277.181519,294.500458,0
78.230003,65.664536,-1277.181519,-0.000979,0.003777,0.095941,292.090454,14.879797,0.95941,-1277.181519,294.500458,0
78.540001,65.573303,-1277.181519,-0.000966,0.003777,0.095941,291.684631,14.859122,0.95941,-1277.181519,294.500458,0
78.850006,65.508499,-1277.137085,-0.000979,0.003777,0.095941,291.396362,14.844439,0.95941,-1277.137085,294.500458,0
79.160004,65.385254,-1277.137085,-0.000979,0.003778,0.09595,290.848145,14.81651,0.959501,-1277.137085,294.500458,0
79.470001,65.3078,-1277.137085,-0.000983,0.003784,0.096106,290.503601,14.798959,0.961061,-1277.137085,294.500458,0
79.780006,65.248215,-1277.137085,-0.000983,0.003784,0.096106,290.238556,14.785457,0.961061,-1277.137085,294.500458,0
80.090004,65.160706,-1277.181519,-0.000983,0.003786,0.096167,289.849304,14.765627,0.961666,-1277.181519,294.500458,0
80.400002,65.072083,-1277.181519,-0.000996,0.003786,0.096167,289.455078,14.745544,0.961666,-1277.181519,294.500458,0
80.710007,65.045273,-1277.137085,-0.000996,0.003798,0.096471,289.335815,14.73947,0.964709,-1277.137085,294.500458,0
81.020004,64.993881,-1277.181519,-0.000974,0.003798,0.096471,289.107208,14.727824,0.964709,-1277.181519,294.500458,0
81.330002,64.92984,-1277.181519,-0.000966,0.003798,0.096471,288.822357,14.713312,0.964709,-1277.181519,294.500458,0
81.640007,64.876587,-1277.137085,-0.000974,0.003799,0.096497,288.58548,14.701244,0.964967,-1277.137085,294.500458,0
81.950005,64.95665,-1277.181519,-0.000974,0.003803,0.096592,288.94162,14.719388,0.96592,-1277.181519,294.500458,0
82.260002,64.925751,-1277.226074,-0.000979,0.003803,0.096592,288.804169,14.712385,0.96592,-1277.226074,294.500458,0
82.570007,64.879196,-1277.181519,-0.000961,0.003803,0.096592,288.597076,14.701837,0.96592,-1277.181519,294.500458,0
82.880005,64.816635,-1277.226074,-0.000961,0.003803,0.096601,288.318787,14.687659,0.966011,-1277.226074,294.500458,0
83.190002,64.964096,-1277.137085,-0.000957,0.003811,0.096809,288.974731,14.721074,0.968085,-1277.137085,294.500458,0
83.500008,65.403122,-1277.181519,-0.000961,0.003812,0.096818,290.927612,14.82056,0.968176,-1277.181519,294.500458,0
83.810005,65.388596,-1277.137085,-0.000966,0.003812,0.096818,290.863007,14.817267,0.968176,-1277.137085,294.500458,0
84.120003,65.364029,-1277.092529,-0.000966,0.003812,0.096818,290.753723,14.811701,0.968176,-1277.092529,294.500458,0
84.43,65.319336,-1277.226074,-0.000966,0.003812,0.096818,290.554932,14.801573,0.968176,-1277.226074,294.500458,0
84.740005,65.304825,-1277.181519,-0.000983,0.003812,0.096818,290.490356,14.798285,0.968176,-1277.181519,294.500458,0
85.050003,65.272797,-1277.181519,-0.000966,0.003812,0.096818,290.3479,14.791027,0.968176,-1277.181519,294.500458,0
85.360001,65.226242,-1277.181519,-0.000961,0.003812,0.096818,290.140808,14.780478,0.968176,-1277.181519,294.500458,0
85.670006,65.180069,-1277.137085,-0.000961,0.003812,0.096818,289.935425,14.770015,0.968176,-1277.137085,294.500458,0
85.980003,65.126831,-1277.226074,-0.000983,0.003813,0.096843,289.698608,14.757951,0.968433,-1277.226074,294.500458,0
86.290001,65.141724,-1277.092529,-0.000979,0.003813,0.096843,289.764862,14.761325,0.968433,-1277.092529,294.500458,0
86.600006,65.113419,-1277.181519,-0.000979,0.003813,0.096843,289.638947,14.754911,0.968433,-1277.181519,294.500458,0
86.910004,65.073578,-1277.181519,-0.000961,0.003813,0.096843,289.461731,14.745884,0.968433,-1277.181519,294.500458,0
87.220001,65.10672,-1277.137085,-0.000987,0.003816,0.096922,289.609161,14.753393,0.969221,-1277.137085,294.500458,0
87.530006,65.176727,-1277.226074,-0.000957,0.003816,0.096922,289.920563,14.769257,0.969221,-1277.226074,294.500458,0
87.840004,65.148788,-1277.137085,-0.000979,0.003816,0.096922,289.796295,14.762927,0.969221,-1277.137085,294.500458,0
88.150002,65.155121,-1277.226074,-0.000974,0.003816,0.09693,289.824463,14.764361,0.969296,-1277.226074,294.500458,0
88.460007,65.157364,-1277.226074,-0.00097,0.003816,0.096939,289.834442,14.76487,0.969387,-1277.226074,294.500458,0
88.770004,65.13092,-1277.226074,-0.000961,0.003816,0.096939,289.716797,14.758878,0.969387,-1277.226074,294.500458,0
89.080002,65.101501,-1277.270508,-0.000966,0.003817,0.096948,289.585937,14.752212,0.969478,-1277.270508,294.500458,0
89.390007,65.073196,-1277.226074,-0.000961,0.003817,0.096948,289.460022,14.745797,0.969478,-1277.226074,294.500458,0
89.700005,65.053833,-1277.270508,-0.000957,0.003818,0.096974,289.373901,14.741409,0.969736,-1277.270508,294.500458,0
90.010002,65.121979,-1277.226074,-0.000961,0.003819,0.096999,289.677032,14.756851,0.969993,-1277.226074,294.500458,0
90.320007,65.142471,-1277.226074,-0.00097,0.003819,0.097008,289.768188,14.761495,0.970084,-1277.226074,294.500458,0
90.630005,65.13353,-1277.270508,-0.000966,0.003819,0.097008,289.728424,14.759469,0.970084,-1277.270508,294.500458,0
90.940002,65.107468,-1277.181519,-0.000957,0.00382,0.097017,289.612488,14.753563,0.970175,-1277.181519,294.500458,0
91.250008,65.08139,-1277.270508,-0.000949,0.00382,0.097025,289.49649,14.747654,0.97025,-1277.270508,294.500458,0
91.560005,65.083633,-1277.270508,-0.000944,0.00382,0.097025,289.50647,14.748162,0.97025,-1277.270508,294.500458,0
91.870003,65.06427,-1277.181519,-0.000953,0.00382,0.097025,289.420319,14.743774,0.97025,-1277.181519,294.500458,0
92.180008,65.025909,-1277.226074,-0.000961,0.00382,0.097025,289.249695,14.735082,0.97025,-1277.226074,294.500458,0
92.490005,65.019958,-1277.181519,-0.00097,0.00382,0.097025,289.223206,14.733733,0.97025,-1277.181519,294.500458,0
92.800003,64.983459,-1277.359497,-0.000979,0.00382,0.097025,289.060852,14.725462,0.97025,-1277.359497,294.500458,0
93.110001,64.967072,-1277.226074,-0.000957,0.00382,0.097025,288.987976,14.721749,0.97025,-1277.226074,294.500458,0
93.420006,64.925751,-1277.181519,-0.000961,0.00382,0.097025,288.804169,14.712385,0.97025,-1277.181519,294.500458,0
93.730003,65.574783,-1277.226074,-0.000953,0.003829,0.09726,291.691193,14.859459,0.972597,-1277.226074,294.500458,0
94.040001,65.568085,-1277.226074,-0.000949,0.003828,0.097234,291.661407,14.857941,0.97234,-1277.226074,294.500458,0
94.350006,65.575165,-1277.314941,-0.000953,0.003828,0.097234,291.692902,14.859545,0.97234,-1277.314941,294.500458,0
94.660004,65.556549,-1277.226074,-0.000949,0.003828,0.097234,291.610107,14.855327,0.97234,-1277.226074,294.500458,0
94.970001,65.560638,-1277.181519,-0.000957,0.003828,0.097234,291.628296,14.856253,0.97234,-1277.181519,294.500458,0
95.280006,65.544632,-1277.270508,-0.00097,0.003828,0.097234,291.557098,14.852626,0.97234,-1277.270508,294.500458,0
95.590004,65.52861,-1277.270508,-0.000957,0.003828,0.097234,291.485809,14.848995,0.97234,-1277.270508,294.500458,0
95.900002,65.492874,-1277.181519,-0.000936,0.003828,0.097234,291.326843,14.840898,0.97234,-1277.181519,294.500458,0
96.210007,65.48616,-1277.226074,-0.000957,0.003828,0.097234,291.296997,14.839376,0.97234,-1277.226074,294.500458,0
96.520004,65.458603,-1277.181519,-0.000949,0.003828,0.097234,291.174408,14.833131,0.97234,-1277.181519,294.500458,0
96.830002,65.404984,-1277.270508,-0.000953,0.003828,0.097234,290.935883,14.820981,0.97234,-1277.270508,294.500458,0
97.140007,65.386002,-1277.181519,-0.000949,0.003828,0.097234,290.851471,14.81668,0.97234,-1277.181519,294.500458,0
97.450005,65.348007,-1277.270508,-0.000944,0.003828,0.097234,290.682465,14.80807,0.97234,-1277.270508,294.500458,0
97.760002,65.336838,-1277.270508,-0.000957,0.003828,0.097234,290.632782,14.805539,0.97234,-1277.270508,294.500458,0
98.070007,65.311523,-1277.314941,-0.000953,0.003828,0.097234,290.520172,14.799802,0.97234,-1277.314941,294.500458,0
98.380005,65.293274,-1277.226074,-0.000957,0.003828,0.097234,290.438995,14.795667,0.97234,-1277.226074,294.500458,0
98.690002,65.267578,-1277.226074,-0.000953,0.003828,0.097234,290.324677,14.789845,0.97234,-1277.226074,294.500458,0
99.000008,65.247467,-1277.270508,-0.000953,0.003828,0.097234,290.235229,14.785287,0.97234,-1277.270508,294.500458,0
99.310005,65.230347,-1277.270508,-0.000953,0.003828,0.097234,290.159088,14.781407,0.97234,-1277.270508,294.500458,0
99.620003,65.204651,-1277.181519,-0.000944,0.003828,0.097234,290.044769,14.775585,0.97234,-1277.181519,294.500458,0
99.930008,65.164062,-1277.314941,-0.000944,0.003828,0.097234,289.864227,14.766387,0.97234,-1277.314941,294.500458,0
100.240005,65.132782,-1277.226074,-0.000966,0.003828,0.097234,289.725098,14.759299,0.97234,-1277.226074,294.500458,0
100.550003,65.112671,-1277.226074,-0.000944,0.003828,0.097234,289.63562,14.754742,0.97234,-1277.226074,294.500458,0
100.860008,65.075806,-1277.270508,-0.000949,0.003828,0.097234,289.471649,14.746388,0.97234,-1277.270508,294.500458,0
101.170006,65.070969,-1277.226074,-0.000953,0.003828,0.097234,289.450134,14.745292,0.97234,-1277.226074,294.500458,0
101.480003,65.043411,-1277.270508,-0.000953,0.003828,0.097234,289.327545,14.739048,0.97234,-1277.270508,294.500458,0
101.790009,65.028885,-1277.226074,-0.00094,0.003828,0.097234,289.262939,14.735756,0.97234,-1277.226074,294.500458,0
102.100006,65.002823,-1277.226074,-0.000957,0.003828,0.097234,289.147003,14.729851,0.97234,-1277.226074,294.500458,0
102.410004,64.986069,-1277.270508,-0.000961,0.003828,0.097234,289.072479,14.726054,0.97234,-1277.270508,294.500458,0
102.720001,64.970795,-1277.226074,-0.000953,0.003828,0.097234,289.004517,14.722592,0.97234,-1277.226074,294.500458,0
103.030006,64.953674,-1277.314941,-0.000949,0.003828,0.097242,288.928375,14.718713,0.972415,-1277.314941,294.500458,0
103.340004,64.939896,-1277.270508,-0.000957,0.003828,0.097242,288.867096,14.715591,0.972415,-1277.270508,294.500458,0
103.650002,64.903778,-1277.270508,-0.000961,0.003828,0.097242,288.706421,14.707407,0.972415,-1277.270508,294.500458,0
103.960007,65.834335,-1277.314941,-0.000953,0.003839,0.097511,292.845764,14.918274,0.97511,-1277.314941,294.500458,0
104.270004,65.843277,-1277.137085,-0.000949,0.003839,0.097511,292.885529,14.9203,0.97511,-1277.137085,294.500458,0
104.580002,65.845139,-1277.226074,-0.000936,0.003839,0.097511,292.893799,14.920721,0.97511,-1277.226074,294.500458,0
104.890007,65.85704,-1277.314941,-0.000957,0.003839,0.097511,292.946747,14.923419,0.97511,-1277.314941,294.500458,0
105.200005,65.844757,-1277.226074,-0.000957,0.003839,0.097511,292.89212,14.920635,0.97511,-1277.226074,294.500458,0
105.510002,65.85556,-1277.314941,-0.000927,0.003839,0.097511,292.940155,14.923083,0.97511,-1277.314941,294.500458,0
105.820007,65.841782,-1277.181519,-0.00094,0.003839,0.097511,292.878876,14.919961,0.97511,-1277.181519,294.500458,0
106.130005,65.83136,-1277.270508,-0.000931,0.003839,0.097511,292.83252,14.917599,0.97511,-1277.270508,294.500458,0
106.440002,65.844757,-1277.181519,-0.00094,0.003839,0.097511,292.89212,14.920635,0.97511,-1277.181519,294.500458,0
106.750008,65.802673,-1277.270508,-0.000931,0.003839,0.097511,292.704895,14.911099,0.97511,-1277.270508,294.500458,0
107.060005,65.785553,-1277.226074,-0.00094,0.003839,0.097511,292.628754,14.907219,0.97511,-1277.226074,294.500458,0
107.370003,65.78331,-1277.226074,-0.000949,0.003839,0.097511,292.618774,14.906711,0.97511,-1277.226074,294.500458,0
107.680008,65.763947,-1277.270508,-0.000923,0.003839,0.097511,292.532654,14.902323,0.97511,-1277.270508,294.500458,0
107.990005,65.765823,-1277.314941,-0.000927,0.003839,0.097511,292.540985,14.902749,0.97511,-1277.314941,294.500458,0
108.300003,65.734543,-1277.181519,-0.000949,0.003839,0.097511,292.401855,14.89566,0.97511,-1277.181519,294.500458,0
108.610008,65.68985,-1277.314941,-0.000944,0.003839,0.097511,292.203033,14.885532,0.97511,-1277.314941,294.500458,0
108.920006,65.658951,-1277.226074,-0.000936,0.003839,0.097511,292.065613,14.878531,0.97511,-1277.226074,294.500458,0
109.230003,65.653732,-1277.270508,-0.000944,0.003839,0.097511,292.042389,14.877348,0.97511,-1277.270508,294.500458,0
109.540009,65.628784,-1277.314941,-0.000953,0.003839,0.097511,291.931427,14.871696,0.97511,-1277.314941,294.500458,0
109.850006,65.602341,-1277.270508,-0.00094,0.003839,0.097511,291.813782,14.865703,0.97511,-1277.270508,294.500458,0
110.160004,65.585587,-1277.359497,-0.000957,0.003839,0.097511,291.739258,14.861906,0.97511,-1277.359497,294.500458,0
110.470009,65.564362,-1277.270508,-0.000936,0.003839,0.097511,291.644836,14.857098,0.97511,-1277.270508,294.500458,0
110.780006,65.559525,-1277.270508,-0.00094,0.003839,0.097511,291.623322,14.856,0.97511,-1277.270508,294.500458,0
111.090004,65.540909,-1277.314941,-0.000949,0.003839,0.097511,291.540527,14.851783,0.97511,-1277.314941,294.500458,0
111.400002,65.539413,-1277.314941,-0.000949,0.003839,0.097511,291.533875,14.851443,0.97511,-1277.314941,294.500458,0
111.710007,65.507385,-1277.314941,-0.000936,0.003839,0.097511,291.391388,14.844186,0.97511,-1277.314941,294.500458,0
112.020004,65.493988,-1277.270508,-0.000949,0.003839,0.097511,291.331818,14.84115,0.97511,-1277.270508,294.500458,0
112.330002,65.482071,-1277.226074,-0.00094,0.003839,0.097511,291.278809,14.838449,0.97511,-1277.226074,294.500458,0
112.640007,65.460464,-1277.314941,-0.000949,0.003839,0.097511,291.182678,14.833553,0.97511,-1277.314941,294.500458,0
112.950005,65.432175,-1277.314941,-0.000949,0.003839,0.097511,291.056854,14.827143,0.97511,-1277.314941,294.500458,0
113.260002,65.410568,-1277.359497,-0.000944,0.003839,0.097511,290.960754,14.822247,0.97511,-1277.359497,294.500458,0
113.570007,65.380417,-1277.270508,-0.000944,0.003839,0.097511,290.82663,14.815414,0.97511,-1277.270508,294.500458,0
113.880005,65.360306,-1277.270508,-0.000944,0.003839,0.097511,290.737152,14.810857,0.97511,-1277.270508,294.500458,0
114.190002,65.336105,-1277.314941,-0.000944,0.003839,0.097511,290.629517,14.805373,0.97511,-1277.314941,294.500458,0
114.500008,65.32605,-1277.314941,-0.000949,0.003839,0.097511,290.584778,14.803094,0.97511,-1277.314941,294.500458,0
114.810005,65.313385,-1277.359497,-0.000949,0.003839,0.097511,290.528442,14.800224,0.97511,-1277.359497,294.500458,0
115.120003,65.298111,-1277.270508,-0.000953,0.003839,0.09752,290.46051,14.796764,0.975201,-1277.270508,294.500458,0
115.430008,65.282852,-1277.314941,-0.000927,0.003839,0.09752,290.392639,14.793305,0.975201,-1277.314941,294.500458,0
115.740005,65.280609,-1277.270508,-0.000944,0.003839,0.09752,290.38266,14.792797,0.975201,-1277.270508,294.500458,0
116.050003,65.254547,-1277.226074,-0.000953,0.003839,0.09752,290.266724,14.786892,0.975201,-1277.226074,294.500458,0
116.360008,65.243011,-1277.359497,-0.000949,0.003839,0.09752,290.215424,14.784278,0.975201,-1277.359497,294.500458,0
116.670006,65.238907,-1277.226074,-0.00094,0.003839,0.09752,290.197144,14.783348,0.975201,-1277.226074,294.500458,0
116.980003,65.193848,-1277.270508,-0.000918,0.003839,0.09752,289.996704,14.773137,0.975201,-1277.270508,294.500458,0
117.290009,65.191238,-1277.270508,-0.000936,0.003839,0.09752,289.985107,14.772546,0.975201,-1277.270508,294.500458,0
117.600006,65.174484,-1277.270508,-0.000953,0.003839,0.09752,289.910583,14.768749,0.975201,-1277.270508,294.500458,0
117.910004,65.154755,-1277.270508,-0.000923,0.003839,0.09752,289.822815,14.764278,0.975201,-1277.270508,294.500458,0
118.220009,65.145813,-1277.226074,-0.000953,0.003839,0.09752,289.783051,14.762252,0.975201,-1277.226074,294.500458,0
118.530006,65.124969,-1277.226074,-0.00094,0.003839,0.09752,289.690338,14.757528,0.975201,-1277.226074,294.500458,0
118.840004,65.100754,-1277.314941,-0.000949,0.003839,0.09752,289.582611,14.752042,0.975201,-1277.314941,294.500458,0
119.150009,65.112671,-1277.270508,-0.000936,0.00384,0.097529,289.63562,14.754742,0.975292,-1277.270508,294.500458,0
119.460007,65.100754,-1277.270508,-0.000944,0.003841,0.097555,289.582611,14.752042,0.975549,-1277.270508,294.500458,0
119.770004,65.106339,-1277.270508,-0.000949,0.003841,0.097555,289.607452,14.753307,0.975549,-1277.270508,294.500458,0
120.080009,65.09108,-1277.226074,-0.00094,0.003841,0.097555,289.539581,14.749849,0.975549,-1277.226074,294.500458,0
120.390007,65.097412,-1277.314941,-0.000957,0.003841,0.097555,289.567749,14.751285,0.975549,-1277.314941,294.500458,0
120.700005,65.080276,-1277.270508,-0.000953,0.003841,0.097555,289.491516,14.747402,0.975549,-1277.270508,294.500458,0
121.010002,65.060913,-1277.359497,-0.000936,0.003841,0.097555,289.405396,14.743013,0.975549,-1277.359497,294.500458,0
121.320007,65.156982,-1277.226074,-0.000944,0.003844,0.097641,289.832733,14.764783,0.976412,-1277.226074,294.500458,0
121.630005,65.220291,-1277.314941,-0.000936,0.003844,0.097641,290.114349,14.779129,0.976412,-1277.314941,294.500458,0
121.940002,65.240768,-1277.314941,-0.000944,0.003844,0.097641,290.205444,14.783769,0.976412,-1277.314941,294.500458,0
122.250008,65.243744,-1277.270508,-0.00094,0.003844,0.097641,290.218658,14.784444,0.976412,-1277.270508,294.500458,0
122.560005,65.253433,-1277.359497,-0.00094,0.003844,0.097641,290.26178,14.786639,0.976412,-1277.359497,294.500458,0
122.870003,65.245239,-1277.270508,-0.000957,0.003844,0.097641,290.225311,14.784782,0.976412,-1277.270508,294.500458,0
123.180008,65.247849,-1277.314941,-0.000944,0.003844,0.097641,290.236938,14.785374,0.976412,-1277.314941,294.500458,0
123.490005,65.238907,-1277.359497,-0.000953,0.003844,0.097641,290.197144,14.783348,0.976412,-1277.359497,294.500458,0
123.800003,65.243744,-1277.314941,-0.000949,0.003844,0.097641,290.218658,14.784444,0.976412,-1277.314941,294.500458,0
124.110008,65.236298,-1277.359497,-0.00094,0.003844,0.097641,290.185547,14.782756,0.976412,-1277.359497,294.500458,0
124.420006,65.212463,-1277.359497,-0.000949,0.003844,0.097641,290.079529,14.777355,0.976412,-1277.359497,294.500458,0
124.730003,65.206146,-1277.270508,-0.000931,0.003844,0.097641,290.051422,14.775925,0.976412,-1277.270508,294.500458,0
125.040009,65.183792,-1277.359497,-0.00094,0.003844,0.097641,289.951996,14.770859,0.976412,-1277.359497,294.500458,0
125.350006,65.196457,-1277.270508,-0.000927,0.003844,0.097641,290.008331,14.773728,0.976412,-1277.270508,294.500458,0
125.660004,65.177475,-1277.359497,-0.000949,0.003844,0.097641,289.923889,14.769426,0.976412,-1277.359497,294.500458,0
125.970009,65.159973,-1277.403931,-0.000949,0.003844,0.097641,289.846039,14.765461,0.976412,-1277.403931,1681.640747,0
126.280006,65.143585,-1277.359497,-0.00094,0.003836,0.097441,289.773132,14.761747,0.974414,-1277.359497,0.097269,0
126.590004,65.032608,-1277.448486,-0.000927,0.003821,0.097043,289.27948,14.7366,0.970432,-1277.448486,0.096748,0
126.900009,65.067245,-1277.314941,-0.000931,0.003808,0.096713,289.433563,14.744449,0.967131,-1277.314941,0.096227,0
127.210007,65.021439,-1277.359497,-0.000923,0.003787,0.096192,289.229797,14.734068,0.961923,-1277.359497,0.095715,0
127.520004,64.992401,-1277.359497,-0.000923,0.003768,0.095699,289.100647,14.727489,0.956988,-1277.359497,0.095196,0
127.830009,64.945847,-1277.359497,-0.000918,0.003745,0.095136,288.893555,14.716939,0.951356,-1277.359497,0.094684,0
128.139999,64.931335,-1277.403931,-0.000923,0.003729,0.094719,288.82901,14.713651,0.947193,-1277.403931,0.094164,0
128.450012,64.973404,-1277.314941,-0.000927,0.00371,0.094242,289.016144,14.723184,0.942424,-1277.314941,0.093652,0
128.76001,64.910477,-1277.403931,-0.000927,0.003689,0.093696,288.736206,14.708923,0.936958,-1277.403931,0.093131,0
129.070007,64.874725,-1277.359497,-0.000927,0.003668,0.093157,288.577179,14.700823,0.931569,-1277.359497,0.092612,0
129.380005,64.877701,-1277.314941,-0.000923,0.003652,0.092768,288.590424,14.701497,0.927678,-1277.314941,0.0921,0
129.690002,64.779404,-1277.359497,-0.000918,0.003628,0.092152,288.153168,14.679223,0.921516,-1277.359497,0.091579,0
130,64.606995,-1277.314941,-0.000923,0.003607,0.091614,287.386261,14.640154,0.916141,-1277.314941,0.091068,0
130.310013,64.406281,-1277.403931,-0.000923,0.003593,0.091267,286.493439,14.594672,0.912674,-1277.403931,0.090547,0
130.62001,63.557648,-1277.359497,-0.000923,0.003569,0.090651,282.718536,14.402369,0.906513,-1277.359497,0.090028,0
130.930008,62.837479,-1277.359497,-0.000914,0.003556,0.090321,279.515076,14.239176,0.903212,-1277.359497,0.089516,0
131.240005,62.023102,-1277.359497,-0.000905,0.003539,0.089879,275.892548,14.054635,0.898791,-1277.359497,0.088995,0
131.550003,60.784218,-1277.314941,-0.000914,0.003516,0.089307,270.381714,13.773901,0.893069,-1277.314941,0.088483,0
131.860001,59.630608,-1277.359497,-0.000914,0.003498,0.088848,265.250183,13.512489,0.888481,-1277.359497,0.087962,0
132.170013,58.118401,-1277.359497,-0.000914,0.003476,0.088302,258.52356,13.169818,0.883016,-1277.359497,0.087451,0
132.480011,57.036659,-1277.270508,-0.000923,0.003464,0.087997,253.711731,12.924692,0.879973,-1277.270508,0.086931,0
132.790009,54.867218,-1277.403931,-0.000918,0.003438,0.08733,244.061569,12.433089,0.873296,-1277.403931,0.086411,0
133.100006,53.087654,-1277.359497,-0.000914,0.00342,0.086862,236.145676,12.029835,0.868618,-1277.359497,0.085899,0
133.410004,51.584381,-1277.448486,-0.000914,0.003404,0.086462,229.458786,11.689188,0.864621,-1277.448486,0.085378,0
133.720001,49.794014,-1277.359497,-0.000923,0.003384,0.08596,221.494843,11.283484,0.859595,-1277.359497,0.084866,0
134.029999,47.18853,-1277.314941,-0.000914,0.003362,0.085404,209.90506,10.693073,0.854039,-1277.314941,0.084347,0
134.340012,44.834389,-1277.403931,-0.000914,0.003342,0.084894,199.433319,10.159617,0.848937,-1277.403931,0.083835,0
134.650009,42.793045,-1277.314941,-0.000931,0.003323,0.084415,190.352966,9.697042,0.844153,-1277.314941,0.083315,0
134.900009,41.569427,-1277.448486,-0.000927,0.003316,0.084225,184.910049,9.419767,0.842245,-1277.448486,0.084087,0