File: Data/compression 36/Heating-17-36-reverse-1-3_11202024_172847(in).csv
Time (sec),S:Load (lbs),S:HL1 (DIM),S:LVDT (in),S:Position (in),Ch:Position (mm),Ch:Load (N),Ch:Stress (MPa),Ch:Strain (mm/mm),Ch:HL1 (DIM),Set Point (),Cycles ()
0.11,-0.077827,-1280.651001,-0.013995,-0.008892,-0.225869,-0.346194,-0.017636,-2.258689,-1280.651001,-0.225636,0
0.43,-0.026443,-1280.562134,-0.013974,-0.008889,-0.225774,-0.117626,-0.005992,-2.257735,-1280.562134,-0.225063,0
0.75,-0.043945,-1280.651001,-0.013935,-0.008705,-0.2211,-0.195479,-0.009958,-2.210999,-1280.651001,-0.219721,0
1.07,-0.058838,-1280.651001,-0.013715,-0.008502,-0.215957,-0.261724,-0.013333,-2.15957,-1280.651001,-0.214396,0
1.39,-0.138153,-1280.606567,-0.013495,-0.008286,-0.210458,-0.614536,-0.031306,-2.104583,-1280.606567,-0.209053,0
1.71,-0.049156,-1280.606567,-0.013279,-0.008074,-0.205082,-0.218658,-0.011139,-2.050823,-1280.606567,-0.203729,0
2.03,-0.027184,-1280.606567,-0.013055,-0.007862,-0.199705,-0.120918,-0.00616,-1.997047,-1280.606567,-0.198404,0
2.35,-0.002983,-1280.606567,-0.012874,-0.007656,-0.19445,-0.013269,-0.000676,-1.944497,-1280.606567,-0.193061,0
2.67,-0.005959,-1280.651001,-0.012611,-0.007445,-0.18909,-0.026505,-0.00135,-1.890903,-1280.651001,-0.187737,0
2.99,-0.064423,-1280.606567,-0.012421,-0.007241,-0.183922,-0.286566,-0.014598,-1.839217,-1280.606567,-0.182412,0
3.31,-0.071869,-1280.562134,-0.012189,-0.007025,-0.178441,-0.319689,-0.016286,-1.784411,-1280.562134,-0.177071,0
3.63,-0.064423,-1280.562134,-0.011977,-0.006813,-0.173056,-0.286566,-0.014598,-1.73056,-1280.562134,-0.171746,0
3.95,-0.077827,-1280.651001,-0.011788,-0.006609,-0.16786,-0.346194,-0.017636,-1.678601,-1280.651001,-0.16642,0
4.27,-0.047295,-1280.606567,-0.011538,-0.006395,-0.162431,-0.210377,-0.010717,-1.62431,-1280.606567,-0.161079,0
4.59,0.015266,-1280.606567,-0.011335,-0.006183,-0.157046,0.067908,0.003459,-1.570459,-1280.606567,-0.155754,0
4.91,-0.029419,-1280.562134,-0.011132,-0.005982,-0.151938,-0.130862,-0.006666,-1.519378,-1280.562134,-0.150412,0
5.23,-0.051018,-1280.606567,-0.010891,-0.005768,-0.146501,-0.226938,-0.011561,-1.465012,-1280.606567,-0.145087,0
5.55,-0.05027,-1280.606567,-0.010684,-0.005559,-0.141193,-0.223612,-0.011391,-1.411932,-1280.606567,-0.139763,0
5.87,-0.143364,-1280.651001,-0.010477,-0.005351,-0.135913,-0.637715,-0.032487,-1.359125,-1280.651001,-0.13442,0
6.19,-0.036865,-1280.606567,-0.010248,-0.005141,-0.130588,-0.163985,-0.008354,-1.30588,-1280.606567,-0.129095,0
6.51,-0.021973,-1280.606567,-0.010033,-0.004927,-0.12515,-0.097739,-0.004979,-1.251498,-1280.606567,-0.123771,0
6.83,-0.048409,-1280.517578,-0.00983,-0.00472,-0.119895,-0.215332,-0.01097,-1.198949,-1280.517578,-0.118429,0
7.150001,-0.035004,-1280.517578,-0.00961,-0.004507,-0.114482,-0.155704,-0.007932,-1.144825,-1280.517578,-0.113103,0
7.47,-0.048782,-1280.651001,-0.009382,-0.004305,-0.10934,-0.216995,-0.011054,-1.093396,-1280.651001,-0.107779,0
7.79,-0.109848,-1280.606567,-0.009153,-0.00409,-0.103894,-0.488628,-0.024892,-1.038939,-1280.606567,-0.102437,0
8.110001,-0.064423,-1280.606567,-0.008942,-0.003875,-0.09843,-0.286566,-0.014598,-0.9843,-1280.606567,-0.097113,0
8.43,-0.052505,-1280.606567,-0.008727,-0.003665,-0.093089,-0.233556,-0.011898,-0.930887,-1280.606567,-0.09177,0
8.75,-0.048035,-1280.651001,-0.008541,-0.003459,-0.08785,-0.213669,-0.010885,-0.878504,-1280.651001,-0.086445,0
9.070001,-0.013779,-1280.606567,-0.008295,-0.003246,-0.082456,-0.061291,-0.003122,-0.824562,-1280.606567,-0.081121,0
9.39,-0.077454,-1280.651001,-0.008097,-0.003043,-0.077304,-0.344531,-0.017551,-0.773042,-1280.651001,-0.075778,0
9.71,-0.065536,-1280.606567,-0.007856,-0.002829,-0.071868,-0.291521,-0.014851,-0.718676,-1280.606567,-0.070454,0
10.030001,-0.071495,-1280.517578,-0.007649,-0.002617,-0.066464,-0.318026,-0.016201,-0.664643,-1280.517578,-0.065129,0
10.35,-0.090485,-1280.606567,-0.007442,-0.002412,-0.061261,-0.402496,-0.020504,-0.612608,-1280.606567,-0.059786,0
10.67,-0.016762,-1280.562134,-0.007222,-0.002198,-0.055841,-0.07456,-0.003798,-0.558408,-1280.562134,-0.054462,0
10.990001,0.005585,-1280.606567,-0.007002,-0.001986,-0.050447,0.024842,0.001266,-0.504466,-1280.606567,-0.04912,0
11.31,-0.019363,-1280.562134,-0.006795,-0.001785,-0.045331,-0.086133,-0.004388,-0.453309,-1280.562134,-0.043796,0
11.63,-0.041336,-1280.606567,-0.006571,-0.001571,-0.039893,-0.183872,-0.009367,-0.398928,-1280.606567,-0.038471,0
11.950001,-0.031654,-1280.606567,-0.006347,-0.00136,-0.034542,-0.140806,-0.007173,-0.345425,-1280.606567,-0.033128,0
12.27,-0.136665,-1280.606567,-0.006144,-0.001154,-0.029313,-0.607918,-0.030969,-0.293133,-1280.606567,-0.027804,0
12.59,-0.006706,-1280.606567,-0.005924,-0.000944,-0.023987,-0.029831,-0.00152,-0.239872,-1280.606567,-0.022479,0
12.910001,-0.017128,-1280.606567,-0.0057,-0.000729,-0.018507,-0.076189,-0.003881,-0.185066,-1280.606567,-0.017136,0
13.23,-0.038353,-1280.651001,-0.005463,-0.000522,-0.013261,-0.170603,-0.008691,-0.132608,-1280.651001,-0.011812,0
13.55,-0.017502,-1280.606567,-0.00526,-0.00031,-0.007874,-0.077852,-0.003966,-0.078741,-1280.606567,-0.006487,0
13.870001,-0.039474,-1280.606567,-0.005049,-0.000108,-0.002733,-0.175591,-0.008945,-0.027327,-1280.606567,-0.001145,0
14.190001,0.178368,-1280.562134,-0.004872,0.000059,0.001491,0.793419,0.040419,0.014912,-1280.562134,0.001656,0
14.51,0.164589,-1280.695557,-0.004876,-0.000001,-0.000017,0.732128,0.037296,-0.000167,-1280.695557,0.000165,0
14.830001,0.177994,-1280.695557,-0.004868,-0.000001,-0.000017,0.791756,0.040334,-0.000167,-1280.695557,0.000416,0
15.150001,0.165703,-1280.562134,-0.004863,0,-0.000009,0.737083,0.037549,-0.000091,-1280.562134,0.000954,0
15.47,0.178734,-1280.562134,-0.00485,0.000014,0.000365,0.795048,0.040502,0.003649,-1280.562134,0.001484,0
15.790001,0.250603,-1280.695557,-0.004859,0.000034,0.000858,1.114737,0.056787,0.008584,-1280.695557,0.002021,0
16.110001,0.323219,-1280.606567,-0.004842,0.00005,0.001266,1.437751,0.073243,0.012657,-1280.606567,0.00255,0
16.43,0.686279,-1280.606567,-0.004812,0.000077,0.001968,3.052723,0.155513,0.019681,-1280.606567,0.003087,0
16.75,0.92981,-1280.562134,-0.004794,0.000102,0.002593,4.136,0.210698,0.025934,-1280.562134,0.003617,0
17.070002,1.151749,-1280.562134,-0.004751,0.00012,0.003045,5.123234,0.26099,0.030446,-1280.562134,0.004154,0
17.390001,1.312241,-1280.606567,-0.004764,0.000134,0.003408,5.837138,0.297358,0.034079,-1280.606567,0.004683,0
17.710001,1.630989,-1280.695557,-0.004738,0.000159,0.004041,7.255002,0.369587,0.040408,-1280.695557,0.00522,0
18.030001,1.91362,-1280.606567,-0.004725,0.000176,0.004483,8.512207,0.433632,0.044828,-1280.606567,0.00575,0
18.35,2.076347,-1280.606567,-0.004708,0.000187,0.004743,9.236054,0.470507,0.047432,-1280.606567,0.006287,0
18.67,2.822952,-1280.606567,-0.004674,0.000222,0.005636,12.557118,0.63969,0.056365,-1280.606567,0.006816,0
18.990002,3.072815,-1280.606567,-0.004648,0.000241,0.006132,13.668564,0.69631,0.061315,-1280.606567,0.007353,0
19.310001,3.528603,-1280.606567,-0.004652,0.000266,0.006748,15.696009,0.799593,0.067477,-1280.606567,0.007883,0
19.630001,3.990715,-1280.651001,-0.004626,0.000291,0.007381,17.751587,0.904309,0.073805,-1280.651001,0.008421,0
19.950001,4.190308,-1280.695557,-0.004605,0.000304,0.007709,18.63942,0.949537,0.077091,-1280.695557,0.008949,0
20.27,4.599541,-1280.562134,-0.004583,0.000325,0.008256,20.45978,1.042271,0.082556,-1280.562134,0.009488,0
20.59,5.281357,-1280.606567,-0.00457,0.000352,0.008949,23.492649,1.196773,0.08949,-1280.606567,0.010016,0
20.910002,5.564362,-1280.651001,-0.00454,0.000372,0.009444,24.751516,1.260902,0.094441,-1280.651001,0.010554,0
21.230001,5.642189,-1280.695557,-0.00454,0.000386,0.009817,25.09771,1.278538,0.098165,-1280.695557,0.011084,0
21.550001,6.220108,-1280.606567,-0.004506,0.00041,0.010416,27.668423,1.409497,0.10416,-1280.606567,0.011621,0
21.870001,6.594711,-1280.606567,-0.004493,0.000431,0.010944,29.334742,1.494383,0.109444,-1280.606567,0.01215,0
22.190001,6.976021,-1280.606567,-0.004467,0.000457,0.011595,31.03089,1.580789,0.115954,-1280.606567,0.012687,0
22.51,7.143219,-1280.562134,-0.004458,0.000472,0.011977,31.774626,1.618677,0.119769,-1280.562134,0.013217,0
22.830002,7.536819,-1280.606567,-0.004437,0.000495,0.012575,33.525448,1.707868,0.125749,-1280.606567,0.013754,0
23.150002,7.979942,-1280.695557,-0.004406,0.00052,0.013199,35.496555,1.808281,0.131987,-1280.695557,0.014283,0
23.470001,8.058136,-1280.606567,-0.004411,0.000534,0.013564,35.844379,1.826,0.135635,-1280.606567,0.01482,0
23.790001,8.407425,-1280.606567,-0.004368,0.000559,0.014187,37.398094,1.90515,0.141873,-1280.606567,0.01535,0
24.110001,8.546318,-1280.562134,-0.004372,0.000574,0.014578,38.015923,1.936623,0.145779,-1280.562134,0.015887,0
24.43,9.130196,-1280.606567,-0.004333,0.000604,0.015332,40.61314,2.068932,0.153319,-1280.606567,0.016416,0
24.750002,9.171906,-1280.651001,-0.00432,0.000623,0.015836,40.798672,2.078383,0.15836,-1280.651001,0.016955,0
25.070002,9.577049,-1280.695557,-0.00429,0.000647,0.016443,42.600842,2.17019,0.164431,-1280.695557,0.017483,0
25.390001,9.552094,-1280.606567,-0.004273,0.00066,0.016755,42.489834,2.164535,0.16755,-1280.606567,0.018021,0
25.710001,9.687271,-1280.562134,-0.004255,0.000678,0.017232,43.091133,2.195167,0.172319,-1280.562134,0.018551,0
26.030001,10.04847,-1280.651001,-0.004234,0.000702,0.017821,44.697826,2.277016,0.178208,-1280.651001,0.019088,0
26.35,10.475952,-1280.651001,-0.004225,0.00073,0.018532,46.599361,2.373885,0.185324,-1280.651001,0.019616,0
26.670002,10.615967,-1280.651001,-0.004178,0.000747,0.018984,47.222179,2.405612,0.189835,-1280.651001,0.020154,0
26.990002,10.649109,-1280.606567,-0.004165,0.000765,0.019435,47.369602,2.413123,0.194347,-1280.606567,0.020684,0
27.310001,10.885193,-1280.606567,-0.004143,0.000787,0.019989,48.419758,2.46662,0.199888,-1280.606567,0.021221,0
27.630001,11.21064,-1280.606567,-0.004135,0.000807,0.020501,49.867416,2.540367,0.205005,-1280.606567,0.02175,0
27.950001,11.502213,-1280.651001,-0.004105,0.000829,0.021047,51.164398,2.606439,0.21047,-1280.651001,0.022287,0
28.27,11.375977,-1280.651001,-0.0041,0.000844,0.021438,50.602871,2.577833,0.214376,-1280.651001,0.022817,0
28.590002,11.992622,-1280.606567,-0.004074,0.000875,0.022226,53.345848,2.717567,0.222264,-1280.606567,0.023354,0
28.910002,11.948311,-1280.606567,-0.00404,0.000889,0.022582,53.148743,2.707526,0.225822,-1280.606567,0.023883,0
29.230001,12.259247,-1280.651001,-0.004027,0.000912,0.023154,54.531853,2.777985,0.231545,-1280.651001,0.024422,0
29.550001,12.323296,-1280.651001,-0.004018,0.000931,0.02364,54.816757,2.792499,0.236405,-1280.651001,0.02495,0
29.870001,12.638321,-1280.695557,-0.003997,0.000951,0.024152,56.21806,2.863884,0.241522,-1280.695557,0.025487,0
30.190001,12.943665,-1280.606567,-0.003971,0.000975,0.024776,57.576294,2.933076,0.247759,-1280.606567,0.026017,0
30.510002,13.327583,-1280.651001,-0.003923,0.001001,0.025436,59.28405,3.020073,0.25436,-1280.651001,0.026555,0
30.830002,13.452698,-1280.562134,-0.003932,0.001019,0.025895,59.840588,3.048425,0.258947,-1280.562134,0.027083,0
31.150002,13.718201,-1280.651001,-0.003915,0.001045,0.026546,61.021603,3.108589,0.265457,-1280.651001,0.027621,0
31.470001,13.740913,-1280.695557,-0.003885,0.00106,0.026927,61.122635,3.113735,0.269273,-1280.695557,0.028151,0
31.790001,13.618034,-1280.651001,-0.00388,0.001074,0.027292,60.576042,3.085891,0.272921,-1280.651001,0.028688,0
32.110001,13.931572,-1280.606567,-0.00385,0.001093,0.027769,61.970726,3.15694,0.27769,-1280.606567,0.029216,0
32.43,14.75563,-1280.606567,-0.003824,0.001126,0.028609,65.636322,3.343674,0.286093,-1280.606567,0.029754,0
32.75,14.875908,-1280.651001,-0.003811,0.001149,0.029182,66.171341,3.370929,0.291815,-1280.651001,0.030284,0
33.07,14.958199,-1280.695557,-0.003781,0.001167,0.029651,66.537392,3.389576,0.296509,-1280.695557,0.030821,0
33.390003,15.076614,-1280.695557,-0.003781,0.001186,0.030119,67.064133,3.416409,0.301187,-1280.695557,0.03135,0
33.710003,15.365952,-1280.695557,-0.003751,0.001209,0.030709,68.351166,3.481974,0.307091,-1280.695557,0.031888,0
34.030003,15.283279,-1280.651001,-0.003729,0.00122,0.030977,67.983421,3.463241,0.309771,-1280.651001,0.032417,0
34.350002,16.145325,-1280.651001,-0.003721,0.001253,0.031826,71.817993,3.658583,0.318264,-1280.651001,0.032954,0
34.670002,16.333374,-1280.73999,-0.003691,0.001279,0.032487,72.65448,3.701195,0.324865,-1280.73999,0.033492,0
34.990002,15.913338,-1280.784546,-0.00366,0.001287,0.032694,70.786064,3.606014,0.326939,-1280.784546,0.034022,0
35.310001,16.014992,-1280.695557,-0.003648,0.001311,0.033293,71.238243,3.629049,0.332934,-1280.695557,0.034559,0
35.630001,16.373962,-1280.695557,-0.003648,0.001333,0.033848,72.835022,3.710393,0.338476,-1280.695557,0.035087,0
35.950001,16.861771,-1280.606567,-0.003587,0.001353,0.034359,75.004898,3.820932,0.343593,-1280.606567,0.035625,0
36.27,17.313828,-1280.695557,-0.003583,0.001379,0.035027,77.015755,3.923369,0.350269,-1280.695557,0.036155,0
36.59,17.241219,-1280.73999,-0.00357,0.001396,0.035469,76.692772,3.906916,0.35469,-1280.73999,0.036692,0
36.91,17.311592,-1280.695557,-0.003557,0.001416,0.035973,77.005806,3.922863,0.359732,-1280.695557,0.037221,0
37.230003,17.462402,-1280.695557,-0.003523,0.001439,0.036545,77.676643,3.957037,0.365454,-1280.695557,0.03776,0
37.550003,17.230042,-1280.695557,-0.003514,0.001449,0.036813,76.643051,3.904383,0.368134,-1280.695557,0.038288,0
37.870003,17.941277,-1280.651001,-0.003497,0.001477,0.037525,79.806786,4.065551,0.37525,-1280.651001,0.038825,0
38.190002,18.40451,-1280.784546,-0.003475,0.001506,0.038253,81.867348,4.170522,0.382532,-1280.784546,0.039355,0
38.510002,18.38961,-1280.695557,-0.003436,0.001526,0.038765,81.801071,4.167145,0.387649,-1280.695557,0.039893,0
38.830002,18.684532,-1280.562134,-0.003419,0.001547,0.039286,83.112953,4.233975,0.392857,-1280.562134,0.040421,0
39.150002,18.591064,-1280.651001,-0.003419,0.001563,0.039693,82.697182,4.212796,0.39693,-1280.651001,0.040959,0
39.470001,18.766823,-1280.73999,-0.00338,0.001583,0.040214,83.478996,4.252623,0.402138,-1280.73999,0.041489,0
39.790001,18.490524,-1280.784546,-0.00338,0.001596,0.040542,82.249962,4.190013,0.405423,-1280.784546,0.042026,0
40.110001,19.707809,-1280.73999,-0.003337,0.001632,0.041454,87.664711,4.465854,0.414537,-1280.73999,0.042554,0
40.43,19.732758,-1280.73999,-0.003324,0.001654,0.042,87.775688,4.471507,0.420002,-1280.73999,0.043092,0
40.750004,19.682487,-1280.73999,-0.00329,0.00167,0.042424,87.552078,4.460115,0.424241,-1280.73999,0.043622,0
41.070004,19.924904,-1280.695557,-0.003277,0.001697,0.043101,88.630402,4.515048,0.431009,-1280.695557,0.044159,0
41.390003,19.709297,-1280.73999,-0.003272,0.001713,0.043501,87.671333,4.46619,0.435006,-1280.73999,0.044687,0
41.710003,19.976288,-1280.73999,-0.003255,0.001731,0.043977,88.858963,4.526692,0.439775,-1280.73999,0.045226,0
42.030003,20.783226,-1280.695557,-0.003208,0.001761,0.04474,92.44841,4.709546,0.447405,-1280.695557,0.045755,0
42.350002,20.534851,-1280.73999,-0.003195,0.001777,0.045148,91.343582,4.653264,0.451477,-1280.73999,0.046292,0
42.670002,20.247375,-1280.695557,-0.003173,0.001791,0.045504,90.064827,4.588121,0.455035,-1280.695557,0.046822,0
42.990002,20.653633,-1280.695557,-0.003152,0.001814,0.046085,91.871948,4.68018,0.460849,-1280.695557,0.04736,0
43.310001,21.006271,-1280.784546,-0.003143,0.001838,0.046683,93.440559,4.760089,0.466829,-1280.784546,0.047888,0
43.630001,21.54435,-1280.784546,-0.003113,0.001863,0.047316,95.834053,4.88202,0.473157,-1280.784546,0.048425,0
43.950001,21.741707,-1280.695557,-0.003096,0.001886,0.047906,96.711945,4.926741,0.479062,-1280.695557,0.048955,0
44.27,21.885071,-1280.651001,-0.003078,0.001904,0.048365,97.349655,4.959228,0.483649,-1280.651001,0.049493,0
44.590004,21.698517,-1280.695557,-0.003061,0.001919,0.048737,96.519821,4.916955,0.487373,-1280.695557,0.050021,0
44.910004,21.713783,-1280.73999,-0.003044,0.001939,0.049241,96.58773,4.920414,0.492415,-1280.73999,0.050559,0
45.230003,22.247017,-1280.784546,-0.003022,0.001963,0.049849,98.959671,5.041246,0.498486,-1280.784546,0.051089,0
45.550003,22.238083,-1280.73999,-0.003001,0.001981,0.050316,98.91993,5.039222,0.503164,-1280.73999,0.051626,0
45.870003,23.219284,-1280.651001,-0.002962,0.002011,0.051079,103.284531,5.261565,0.510794,-1280.651001,0.052154,0
46.190002,23.452385,-1280.695557,-0.002945,0.002032,0.0516,104.321419,5.314386,0.516002,-1280.695557,0.052693,0
46.510002,23.490372,-1280.73999,-0.002945,0.00205,0.052077,104.490395,5.322994,0.520771,-1280.73999,0.053222,0
46.830002,23.209229,-1280.73999,-0.002923,0.002067,0.052503,103.239807,5.259286,0.525025,-1280.73999,0.053759,0
47.150002,23.580856,-1280.73999,-0.002902,0.002087,0.053022,104.892891,5.343498,0.530218,-1280.73999,0.054289,0
47.470001,24.34832,-1280.651001,-0.002876,0.002114,0.053699,108.30674,5.517408,0.536986,-1280.651001,0.054826,0
47.790001,24.43396,-1280.695557,-0.002867,0.002132,0.054141,108.687683,5.536814,0.541407,-1280.695557,0.055355,0
48.110001,24.805588,-1280.695557,-0.002837,0.002154,0.054722,110.340767,5.621027,0.54722,-1280.695557,0.055892,0
48.430004,24.49913,-1280.73999,-0.002815,0.002167,0.055034,108.977577,5.551582,0.550339,-1280.73999,0.056422,0
48.750004,24.928474,-1280.651001,-0.00279,0.002191,0.05565,110.88739,5.648873,0.556501,-1280.651001,0.05696,0
49.070004,25.35186,-1280.695557,-0.002794,0.002211,0.056162,112.770706,5.744813,0.561618,-1280.695557,0.057488,0
49.390003,25.767426,-1280.651001,-0.002755,0.002233,0.056725,114.619232,5.838982,0.56725,-1280.651001,0.058025,0
49.710003,26.444031,-1280.73999,-0.002746,0.002262,0.057446,117.628922,5.992303,0.574456,-1280.73999,0.058555,0
50.030003,26.449989,-1280.784546,-0.002734,0.002277,0.057827,117.655426,5.993653,0.578271,-1280.784546,0.059093,0
50.350002,26.751984,-1280.695557,-0.00269,0.0023,0.058416,118.998764,6.062086,0.584161,-1280.695557,0.059621,0
50.670002,27.049133,-1280.651001,-0.002682,0.002319,0.058911,120.320557,6.129421,0.589111,-1280.651001,0.06016,0
50.990002,27.201805,-1280.606567,-0.002656,0.002335,0.059318,120.999672,6.164017,0.593184,-1280.606567,0.060689,0
51.310001,27.553329,-1280.73999,-0.002643,0.00236,0.059942,122.563332,6.243674,0.599421,-1280.73999,0.061226,0
51.630001,28.460052,-1280.784546,-0.002613,0.002384,0.060549,126.596634,6.44914,0.605492,-1280.784546,0.061756,0
51.950001,28.616447,-1280.73999,-0.002608,0.002403,0.061026,127.292313,6.48458,0.610261,-1280.73999,0.062293,0
52.270004,29.071861,-1280.73999,-0.002596,0.002425,0.061607,129.3181,6.587778,0.616075,-1280.73999,0.062822,0
52.590004,29.385773,-1280.695557,-0.002561,0.00245,0.062224,130.714447,6.658911,0.622237,-1280.695557,0.063359,0
52.910004,29.218201,-1280.73999,-0.002552,0.002465,0.062622,129.969055,6.620939,0.626218,-1280.73999,0.063889,0
53.230003,29.714203,-1280.695557,-0.002527,0.002483,0.063073,132.175369,6.733335,0.63073,-1280.695557,0.064426,0
53.550003,30.82946,-1280.73999,-0.002514,0.002511,0.063785,137.136292,6.986055,0.637846,-1280.73999,0.064955,0
53.870003,30.901703,-1280.695557,-0.002483,0.002531,0.064296,137.457642,7.002426,0.642963,-1280.695557,0.065492,0
54.190002,31.205185,-1280.695557,-0.002475,0.002549,0.064738,138.807602,7.071196,0.647384,-1280.695557,0.066022,0
54.510002,31.850136,-1280.73999,-0.002471,0.002573,0.065345,141.676483,7.217344,0.653455,-1280.73999,0.06656,0
54.830002,31.676979,-1280.695557,-0.002449,0.002585,0.065666,140.906235,7.178106,0.656664,-1280.695557,0.067088,0
55.150002,32.547958,-1280.695557,-0.002427,0.002611,0.066308,144.780548,7.375473,0.663083,-1280.695557,0.067627,0
55.470001,32.225113,-1280.695557,-0.002397,0.002623,0.06662,143.344467,7.302315,0.666202,-1280.695557,0.068155,0
55.790001,34.226616,-1280.73999,-0.002393,0.002661,0.0676,152.247589,7.755862,0.675997,-1280.73999,0.068693,0
56.110004,34.406845,-1280.651001,-0.002371,0.002678,0.068016,153.049286,7.796703,0.680161,-1280.651001,0.069221,0
56.430004,34.796715,-1280.73999,-0.00235,0.002701,0.068597,154.783524,7.885048,0.685974,-1280.73999,0.06976,0
56.750004,34.473495,-1280.73999,-0.002341,0.002712,0.068874,153.345764,7.811806,0.688745,-1280.73999,0.070289,0
57.070004,35.218239,-1280.73999,-0.002302,0.002738,0.069535,156.658554,7.980567,0.695346,-1280.73999,0.070826,0
57.390003,36.107841,-1280.651001,-0.002311,0.00276,0.070107,160.615707,8.182154,0.701069,-1280.651001,0.071356,0
57.710003,36.694695,-1280.651001,-0.002272,0.002783,0.070679,163.226151,8.315137,0.706791,-1280.651001,0.071893,0
58.030003,37.491951,-1280.73999,-0.002264,0.002806,0.071277,166.772522,8.495797,0.712771,-1280.73999,0.072422,0
58.350002,37.80027,-1280.73999,-0.002246,0.002827,0.071806,168.143997,8.565663,0.718055,-1280.73999,0.072959,0
58.670002,38.058701,-1280.73999,-0.002225,0.002843,0.072222,169.293549,8.624225,0.722219,-1280.73999,0.073489,0
58.990002,38.074707,-1280.695557,-0.00222,0.002858,0.072587,169.364761,8.627851,0.725867,-1280.695557,0.074026,0
59.310001,39.871407,-1280.784546,-0.002195,0.002889,0.073385,177.356873,9.034989,0.733846,-1280.784546,0.074555,0
59.630001,40.196114,-1280.695557,-0.002195,0.002906,0.073818,178.801239,9.108569,0.738176,-1280.695557,0.075092,0
59.950005,40.65004,-1280.784546,-0.00216,0.002927,0.074338,180.820404,9.211431,0.743384,-1280.784546,0.075622,0
60.270004,41.407814,-1280.784546,-0.002147,0.00295,0.074929,184.191162,9.383145,0.749288,-1280.784546,0.07616,0
60.590004,41.678162,-1280.784546,-0.002121,0.002966,0.075336,185.393723,9.444407,0.753361,-1280.784546,0.076688,0
60.910004,42.064682,-1280.73999,-0.002108,0.002982,0.075752,187.113052,9.531994,0.757524,-1280.73999,0.077227,0
61.230003,42.656006,-1280.73999,-0.002087,0.003006,0.07635,189.743393,9.665989,0.763504,-1280.73999,0.077755,0
61.550003,44.493294,-1280.73999,-0.00207,0.003035,0.077088,197.916061,10.082324,0.770877,-1280.73999,0.078293,0
61.870003,45.597382,-1280.784546,-0.002061,0.003061,0.077746,202.827286,10.332515,0.777463,-1280.784546,0.078823,0
62.190002,46.220734,-1280.695557,-0.002052,0.003078,0.078188,205.600098,10.473768,0.781884,-1280.695557,0.07936,0
62.510002,46.640396,-1280.695557,-0.002026,0.003098,0.078683,207.466843,10.568865,0.786834,-1280.695557,0.079889,0
62.830002,46.644859,-1280.73999,-0.002001,0.003113,0.079074,207.486694,10.569876,0.79074,-1280.73999,0.080426,0
63.150002,47.267471,-1280.784546,-0.002018,0.003131,0.079525,210.25621,10.710962,0.795252,-1280.784546,0.080956,0
63.470001,49.316635,-1280.784546,-0.001966,0.003164,0.080365,219.371353,11.17531,0.803654,-1280.784546,0.081493,0
63.790005,49.256683,-1280.784546,-0.001957,0.003177,0.080695,219.104675,11.161724,0.806955,-1280.784546,0.082022,0
64.110001,50.119095,-1280.695557,-0.00194,0.0032,0.081284,222.940872,11.357149,0.812844,-1280.695557,0.082559,0
64.43,51.452934,-1280.73999,-0.001962,0.003224,0.081901,228.874084,11.659402,0.819006,-1280.73999,0.083089,0
64.75,52.088203,-1280.784546,-0.001923,0.003246,0.082447,231.699905,11.803355,0.824471,-1280.784546,0.083626,0
65.07,53.241814,-1280.73999,-0.00191,0.003268,0.083003,236.831421,12.064767,0.830027,-1280.73999,0.084155,0
65.389999,54.05172,-1280.784546,-0.001893,0.00329,0.083557,240.434052,12.248295,0.835569,-1280.784546,0.084694,0
65.710007,54.729439,-1280.73999,-0.001884,0.003308,0.084026,243.4487,12.401868,0.840262,-1280.73999,0.085222,0
66.030006,55.755325,-1280.784546,-0.001858,0.003331,0.084598,248.01207,12.634337,0.845985,-1280.784546,0.08576,0
66.350006,56.194725,-1280.784546,-0.001854,0.003345,0.084962,249.966614,12.733907,0.849618,-1280.784546,0.08629,0
66.670006,56.805786,-1280.695557,-0.001819,0.003365,0.085464,252.684753,12.872375,0.854644,-1280.695557,0.086827,0
66.990005,57.082092,-1280.695557,-0.001828,0.003382,0.085908,253.913834,12.934986,0.85908,-1280.695557,0.087355,0
67.310005,59.431763,-1280.695557,-0.001794,0.00341,0.086601,264.365692,13.46743,0.866014,-1280.695557,0.087893,0
67.630005,60.442009,-1280.73999,-0.001785,0.00343,0.08713,268.859497,13.696355,0.871298,-1280.73999,0.088423,0
67.950005,61.562851,-1280.73999,-0.001776,0.003456,0.08779,273.845245,13.950341,0.877899,-1280.73999,0.08896,0
68.270004,62.300514,-1280.828979,-0.001789,0.003476,0.088283,277.126526,14.117498,0.882834,-1280.828979,0.089489,0
68.590004,62.706779,-1280.784546,-0.001755,0.003487,0.08857,278.933685,14.209559,0.885696,-1280.784546,0.090026,0
68.910004,64.444641,-1280.784546,-0.001742,0.003513,0.089237,286.664093,14.603365,0.892372,-1280.784546,0.090556,0
69.230003,65.835449,-1280.784546,-0.001707,0.003537,0.089828,292.850708,14.918527,0.898277,-1280.784546,0.091093,0
69.550003,65.330139,-1280.784546,-0.001716,0.003535,0.089793,290.602966,14.804021,0.897928,-1280.784546,0.015768,0
69.870003,65.561386,-1280.784546,-0.001699,0.003554,0.090261,291.631622,14.856422,0.902607,-1280.784546,294.500458,0
70.190002,64.777161,-1280.828979,-0.001686,0.003556,0.090312,288.143188,14.678715,0.903121,-1280.828979,294.500458,0
70.510002,64.672165,-1280.828979,-0.00169,0.003564,0.09053,287.676147,14.654922,0.905301,-1280.828979,294.500458,0
70.830002,65.458984,-1280.784546,-0.001673,0.003581,0.090946,291.176117,14.833219,0.909465,-1280.784546,294.500458,0
71.150002,64.908249,-1280.784546,-0.001669,0.003581,0.090963,288.726318,14.70842,0.909631,-1280.784546,294.500458,0
71.470001,64.652054,-1280.784546,-0.001664,0.003589,0.091163,287.5867,14.650364,0.91163,-1280.784546,294.500458,0
71.790001,65.208008,-1280.828979,-0.001643,0.003599,0.091414,290.059692,14.776345,0.914143,-1280.828979,294.500458,0
72.110001,65.247101,-1280.784546,-0.001634,0.003608,0.091631,290.233612,14.785204,0.916308,-1280.784546,294.500458,0
72.43,64.837494,-1280.784546,-0.001638,0.003609,0.091675,288.411591,14.692387,0.916747,-1280.784546,294.500458,0
72.75,65.789642,-1280.828979,-0.001643,0.003624,0.092047,292.646942,14.908146,0.920471,-1280.828979,294.500458,0
73.07,65.282104,-1280.828979,-0.001625,0.003624,0.092047,290.389313,14.793136,0.920471,-1280.828979,294.500458,0
73.390007,64.72168,-1280.784546,-0.001621,0.003624,0.092056,287.896423,14.666142,0.920562,-1280.784546,294.500458,0
73.710007,65.58223,-1280.828979,-0.001613,0.003638,0.092412,291.724335,14.861145,0.92412,-1280.828979,294.500458,0
74.030006,65.175232,-1280.784546,-0.001587,0.003638,0.092412,289.91391,14.768919,0.92412,-1280.784546,294.500458,0
74.350006,64.722794,-1280.828979,-0.001604,0.00364,0.092447,287.901367,14.666394,0.924468,-1280.828979,294.500458,0
74.670006,65.574051,-1280.73999,-0.0016,0.003651,0.092741,291.687958,14.859292,0.927405,-1280.73999,294.500458,0
74.990005,65.129059,-1280.73999,-0.001595,0.003651,0.092741,289.708527,14.758455,0.927405,-1280.73999,294.500458,0
75.310005,65.496216,-1280.828979,-0.0016,0.003662,0.09301,291.341705,14.841655,0.9301,-1280.828979,294.500458,0
75.630005,65.278748,-1280.784546,-0.001582,0.003662,0.09301,290.374359,14.792376,0.9301,-1280.784546,294.500458,0
75.950005,64.908615,-1280.784546,-0.001595,0.003662,0.093019,288.727936,14.708503,0.930191,-1280.784546,294.500458,0
76.270004,65.348007,-1280.695557,-0.001582,0.003671,0.093245,290.682465,14.80807,0.932447,-1280.695557,294.500458,0
76.590004,65.032242,-1280.73999,-0.001587,0.003671,0.093252,289.277863,14.736517,0.932522,-1280.73999,294.500458,0
76.910004,64.745514,-1280.828979,-0.001578,0.003672,0.093261,288.002441,14.671543,0.932613,-1280.828979,294.500458,0
77.230003,65.666763,-1280.784546,-0.001565,0.003684,0.093582,292.100342,14.880301,0.935823,-1280.784546,294.500458,0
77.550003,65.434402,-1280.828979,-0.001561,0.003684,0.093582,291.066772,14.827648,0.935823,-1280.828979,294.500458,0
77.870003,65.122726,-1280.828979,-0.001569,0.003685,0.093608,289.680359,14.75702,0.93608,-1280.828979,294.500458,0
78.190002,64.879196,-1280.828979,-0.001565,0.003686,0.093626,288.597076,14.701837,0.936262,-1280.828979,294.500458,0
78.510002,65.297745,-1280.828979,-0.001556,0.003695,0.093843,290.458862,14.79668,0.938427,-1280.828979,294.500458,0
78.830002,65.102615,-1280.784546,-0.001552,0.003695,0.093843,289.590881,14.752463,0.938427,-1280.784546,294.500458,0
79.150002,64.860199,-1280.73999,-0.001535,0.003695,0.093843,288.512573,14.697532,0.938427,-1280.73999,294.500458,0
79.470001,65.042664,-1280.784546,-0.001544,0.0037,0.093973,289.324219,14.738878,0.939729,-1280.784546,294.500458,0
79.790001,64.849777,-1280.695557,-0.001548,0.0037,0.093973,288.466217,14.695169,0.939729,-1280.695557,294.500458,0
80.110001,65.051239,-1280.828979,-0.001526,0.003705,0.094111,289.362366,14.740822,0.941107,-1280.828979,294.500458,0
80.43,64.876221,-1280.784546,-0.001535,0.003705,0.094111,288.583832,14.701161,0.941107,-1280.784546,294.500458,0
80.750008,65.147675,-1280.784546,-0.001522,0.003711,0.094268,289.791321,14.762674,0.942681,-1280.784546,294.500458,0
81.070007,65.024429,-1280.784546,-0.001539,0.003711,0.094268,289.243103,14.734746,0.942681,-1280.784546,294.500458,0
81.390007,64.824463,-1280.828979,-0.001548,0.003712,0.094276,288.353607,14.689433,0.942757,-1280.828979,294.500458,0
81.710007,65.1082,-1280.873413,-0.001539,0.003718,0.094432,289.615753,14.753729,0.944316,-1280.873413,294.500458,0
82.030006,64.97937,-1280.828979,-0.001509,0.003718,0.094432,289.042664,14.724536,0.944316,-1280.828979,294.500458,0
82.350006,64.819244,-1280.784546,-0.001518,0.003723,0.094554,288.330414,14.688251,0.945542,-1280.784546,294.500458,0
82.670006,64.983093,-1280.73999,-0.001513,0.003723,0.094554,289.059235,14.725379,0.945542,-1280.73999,294.500458,0
82.990005,64.84903,-1280.784546,-0.001522,0.003723,0.094554,288.462891,14.695001,0.945542,-1280.784546,294.500458,0
83.310005,64.962616,-1280.784546,-0.001518,0.003727,0.094675,288.96814,14.720739,0.946754,-1280.784546,294.500458,0
83.630005,64.875839,-1280.828979,-0.001522,0.003728,0.094683,288.582153,14.701076,0.946829,-1280.828979,294.500458,0
83.950005,64.741425,-1280.73999,-0.001513,0.003732,0.094787,287.984253,14.670616,0.947874,-1280.73999,294.500458,0
84.270004,65.219925,-1280.784546,-0.001513,0.003735,0.094857,290.112701,14.779046,0.94857,-1280.784546,294.500458,0
84.590004,65.075058,-1280.784546,-0.001509,0.003735,0.094857,289.468323,14.746219,0.94857,-1280.784546,294.500458,0
84.910004,64.923141,-1280.784546,-0.001518,0.003735,0.094857,288.792542,14.711794,0.94857,-1280.784546,294.500458,0
85.230003,64.838974,-1280.873413,-0.001505,0.003737,0.094909,288.418152,14.692721,0.949085,-1280.873413,294.500458,0
85.550003,64.772324,-1280.828979,-0.001526,0.003737,0.094918,288.121674,14.677619,0.949176,-1280.828979,294.500458,0
85.870003,64.794296,-1280.828979,-0.001505,0.003739,0.094978,288.219421,14.682597,0.949782,-1280.828979,294.500458,0
86.190002,64.723923,-1280.73999,-0.001513,0.00374,0.094996,287.906403,14.66665,0.949963,-1280.73999,294.500458,0
86.510002,64.729874,-1280.784546,-0.001509,0.003742,0.095039,287.932861,14.667999,0.950387,-1280.784546,294.500458,0
86.830002,65.118637,-1280.784546,-0.001513,0.003748,0.095187,289.66217,14.756094,0.951871,-1280.784546,294.500458,0
87.150002,65.053833,-1280.784546,-0.001487,0.003748,0.095187,289.373901,14.741409,0.951871,-1280.784546,294.500458,0
87.470001,64.931702,-1280.828979,-0.001492,0.003748,0.095187,288.830627,14.713734,0.951871,-1280.828979,294.500458,0
87.790001,64.800247,-1280.784546,-0.001509,0.003748,0.095195,288.245911,14.683946,0.951946,-1280.784546,294.500458,0
88.110001,64.827072,-1280.73999,-0.0015,0.003752,0.09529,288.365204,14.690024,0.9529,-1280.73999,294.500458,0
88.430008,64.857224,-1280.784546,-0.001492,0.003752,0.09529,288.499329,14.696856,0.9529,-1280.784546,294.500458,0
88.750008,64.767853,-1280.828979,-0.001483,0.003752,0.095299,288.101807,14.676605,0.952991,-1280.828979,294.500458,0
89.070007,65.294769,-1280.73999,-0.001496,0.003759,0.095473,290.445648,14.796006,0.954732,-1280.73999,294.500458,0
89.390007,65.237793,-1280.73999,-0.001487,0.003759,0.095473,290.1922,14.783095,0.954732,-1280.73999,294.500458,0
89.710007,65.122726,-1280.828979,-0.001492,0.003759,0.095473,289.680359,14.75702,0.954732,-1280.828979,294.500458,0
90.030006,65.024429,-1280.828979,-0.001492,0.003759,0.095481,289.243103,14.734746,0.954808,-1280.828979,294.500458,0
90.350006,64.921646,-1280.784546,-0.001496,0.003759,0.095481,288.785919,14.711455,0.954808,-1280.784546,294.500458,0
90.670006,64.898926,-1280.828979,-0.001479,0.00376,0.095516,288.684845,14.706306,0.955156,-1280.828979,294.500458,0
90.990005,64.829666,-1280.784546,-0.001479,0.003765,0.095638,288.37677,14.690613,0.956382,-1280.784546,294.500458,0
91.310005,65.109695,-1280.828979,-0.001487,0.003766,0.095646,289.622375,14.754068,0.956458,-1280.828979,294.500458,0
91.630005,65.037827,-1280.828979,-0.001487,0.003766,0.095646,289.302704,14.737782,0.956458,-1280.828979,294.500458,0
91.950005,64.957764,-1280.873413,-0.001483,0.003766,0.095646,288.946564,14.71964,0.956458,-1280.873413,294.500458,0
92.270004,64.868774,-1280.873413,-0.001475,0.003766,0.095655,288.55072,14.699474,0.956549,-1280.873413,294.500458,0
92.590004,64.98085,-1280.873413,-0.001475,0.003769,0.095741,289.049255,14.724871,0.957412,-1280.873413,294.500458,0
92.910004,64.962982,-1280.873413,-0.001492,0.003769,0.095741,288.969788,14.720822,0.957412,-1280.873413,294.500458,0
93.230003,64.877701,-1280.828979,-0.001487,0.003769,0.095741,288.590424,14.701497,0.957412,-1280.828979,294.500458,0
93.550003,65.534576,-1280.828979,-0.001479,0.003778,0.095959,291.51236,14.850348,0.959592,-1280.828979,294.500458,0
93.870003,65.515213,-1280.873413,-0.001479,0.003778,0.09595,291.426208,14.84596,0.959501,-1280.873413,294.500458,0
94.190002,65.453018,-1280.828979,-0.001466,0.003778,0.09595,291.149567,14.831865,0.959501,-1280.828979,294.500458,0
94.510002,65.352112,-1280.828979,-0.001462,0.003778,0.09595,290.700714,14.809001,0.959501,-1280.828979,294.500458,0
94.830002,65.272797,-1280.784546,-0.001475,0.003778,0.095959,290.3479,14.791027,0.959592,-1280.784546,294.500458,0
95.150002,65.185654,-1280.873413,-0.001479,0.003778,0.095959,289.960266,14.77128,0.959592,-1280.873413,294.500458,0
95.470001,65.077667,-1280.917969,-0.001483,0.003778,0.095959,289.479919,14.74681,0.959592,-1280.917969,294.500458,0
95.790001,65.003571,-1280.873413,-0.001466,0.003778,0.095959,289.15033,14.73002,0.959592,-1280.873413,294.500458,0
96.110008,64.915695,-1280.784546,-0.001462,0.003778,0.095959,288.75943,14.710107,0.959592,-1280.784546,294.500458,0
96.430008,65.016602,-1280.828979,-0.001479,0.003781,0.096045,289.208282,14.732972,0.960455,-1280.828979,294.500458,0
96.750008,64.999466,-1280.828979,-0.001457,0.003781,0.096045,289.13205,14.72909,0.960455,-1280.828979,294.500458,0
97.070007,64.939148,-1280.828979,-0.001475,0.003781,0.096045,288.86377,14.715422,0.960455,-1280.828979,294.500458,0
97.390007,64.848663,-1280.917969,-0.001457,0.003781,0.096045,288.461273,14.694917,0.960455,-1280.917969,294.500458,0
97.710007,64.770096,-1280.873413,-0.001466,0.003781,0.096045,288.111786,14.677114,0.960455,-1280.873413,294.500458,0
98.030006,64.697113,-1280.784546,-0.001466,0.003782,0.096055,287.78714,14.660576,0.960546,-1280.784546,294.500458,0
98.350006,65.916992,-1280.917969,-0.001462,0.003795,0.096383,293.21344,14.937003,0.963831,-1280.917969,294.500458,0
98.670006,65.877151,-1280.917969,-0.001475,0.003795,0.096383,293.036194,14.927976,0.963831,-1280.917969,294.500458,0
98.990005,65.835815,-1280.917969,-0.001457,0.003795,0.096383,292.852325,14.918609,0.963831,-1280.917969,294.500458,0
99.310005,65.760971,-1280.873413,-0.001444,0.003795,0.096383,292.519409,14.901649,0.963831,-1280.873413,294.500458,0
99.630005,65.679794,-1280.873413,-0.001453,0.003795,0.096383,292.158325,14.883254,0.963831,-1280.873413,294.500458,0
99.950005,65.595276,-1280.828979,-0.001457,0.003795,0.096383,291.782349,14.864102,0.963831,-1280.828979,294.500458,0
100.270004,65.537918,-1280.917969,-0.001457,0.003795,0.096383,291.527222,14.851105,0.963831,-1280.917969,294.500458,0
100.590004,65.473511,-1280.828979,-0.001457,0.003795,0.096383,291.240723,14.83651,0.963831,-1280.828979,294.500458,0
100.910004,65.386002,-1280.873413,-0.00144,0.003795,0.096392,290.851471,14.81668,0.963922,-1280.873413,294.500458,0
101.230003,65.31636,-1280.917969,-0.001457,0.003795,0.096392,290.541687,14.8009,0.963922,-1280.917969,294.500458,0
101.550003,65.244492,-1280.784546,-0.001462,0.003795,0.096392,290.221985,14.784614,0.963922,-1280.784546,294.500458,0
101.870003,65.169647,-1280.828979,-0.001462,0.003795,0.096401,289.889069,14.767653,0.964013,-1280.828979,294.500458,0
102.190002,65.09108,-1280.873413,-0.001444,0.003796,0.096409,289.539581,14.749849,0.964088,-1280.873413,294.500458,0
102.510002,65.045273,-1280.873413,-0.001436,0.003796,0.096427,289.335815,14.73947,0.96427,-1280.873413,294.500458,0
102.830002,65.008041,-1280.873413,-0.001449,0.003797,0.096436,289.170197,14.731032,0.964361,-1280.873413,294.500458,0
103.150002,65.000961,-1280.828979,-0.001466,0.003797,0.096453,289.138702,14.729428,0.964527,-1280.828979,294.500458,0
103.470001,64.954788,-1280.828979,-0.001444,0.003797,0.096453,288.933319,14.718966,0.964527,-1280.828979,294.500458,0
103.790009,65.081024,-1280.873413,-0.001466,0.003801,0.096548,289.494843,14.747571,0.965481,-1280.873413,294.500458,0
104.110008,65.077301,-1280.873413,-0.001444,0.003801,0.096548,289.478302,14.746727,0.965481,-1280.873413,294.500458,0
104.430008,65.037827,-1280.873413,-0.00144,0.003801,0.096548,289.302704,14.737782,0.965481,-1280.873413,294.500458,0
104.750008,64.989044,-1280.73999,-0.001457,0.003801,0.096548,289.085693,14.726727,0.965481,-1280.73999,294.500458,0
105.070007,64.928345,-1280.873413,-0.001462,0.003801,0.096548,288.815704,14.712973,0.965481,-1280.873413,294.500458,0
105.390007,64.86319,-1280.917969,-0.001457,0.003801,0.096548,288.525879,14.698209,0.965481,-1280.917969,294.500458,0
105.710007,64.802856,-1280.917969,-0.001436,0.003803,0.0966,288.257507,14.684538,0.965996,-1280.917969,294.500458,0
106.030006,65.320465,-1280.828979,-0.001457,0.003808,0.09673,290.559937,14.801828,0.967298,-1280.828979,294.500458,0
106.350006,65.327911,-1280.828979,-0.00144,0.003808,0.09673,290.593048,14.803516,0.967298,-1280.828979,294.500458,0
106.670006,65.289917,-1280.828979,-0.001449,0.003808,0.09673,290.424042,14.794907,0.967298,-1280.828979,294.500458,0
106.990005,65.25679,-1280.917969,-0.001436,0.003808,0.09673,290.276703,14.7874,0.967298,-1280.917969,294.500458,0
107.310005,65.212097,-1280.917969,-0.001427,0.003808,0.09673,290.077881,14.777272,0.967298,-1280.917969,294.500458,0
107.630005,65.155869,-1280.784546,-0.001427,0.003808,0.09673,289.827789,14.764531,0.967298,-1280.784546,294.500458,0
107.950005,65.102997,-1280.873413,-0.001431,0.003808,0.09673,289.59259,14.75255,0.967298,-1280.873413,294.500458,0
108.270004,65.051971,-1280.917969,-0.001436,0.003809,0.096748,289.365631,14.740987,0.96748,-1280.917969,294.500458,0
108.590004,65.020325,-1280.828979,-0.001436,0.003811,0.09679,289.224854,14.733816,0.967904,-1280.828979,294.500458,0
108.910004,65.043793,-1280.917969,-0.00144,0.003811,0.09679,289.329254,14.739134,0.967904,-1280.917969,294.500458,0
109.230003,65.013245,-1280.873413,-0.001414,0.003811,0.09679,289.193359,14.732212,0.967904,-1280.873413,294.500458,0
109.550003,64.982712,-1280.962402,-0.001436,0.003811,0.096799,289.057526,14.725293,0.967994,-1280.962402,294.500458,0
109.870003,64.97937,-1280.873413,-0.001423,0.003814,0.096869,289.042664,14.724536,0.968691,-1280.873413,294.500458,0
110.190002,65.111923,-1280.873413,-0.001444,0.003814,0.096878,289.632294,14.754573,0.968782,-1280.873413,294.500458,0
110.510002,65.100021,-1280.962402,-0.001444,0.003814,0.096878,289.579346,14.751876,0.968782,-1280.962402,294.500458,0
110.830002,65.066498,-1280.873413,-0.001423,0.003814,0.096878,289.430237,14.744279,0.968782,-1280.873413,294.500458,0
111.150002,65.045654,-1280.828979,-0.001423,0.003814,0.096878,289.337524,14.739556,0.968782,-1280.828979,294.500458,0
111.470009,64.995743,-1280.917969,-0.001431,0.003815,0.096895,289.115509,14.728246,0.968948,-1280.917969,294.500458,0
111.790009,64.992767,-1280.917969,-0.001436,0.003815,0.096904,289.102264,14.727571,0.969039,-1280.917969,294.500458,0
112.110008,64.942871,-1280.962402,-0.001436,0.003815,0.096904,288.88031,14.716265,0.969039,-1280.962402,294.500458,0
112.430008,64.908615,-1280.873413,-0.001431,0.003815,0.096904,288.727936,14.708503,0.969039,-1280.873413,294.500458,0
112.750008,64.978622,-1280.917969,-0.001423,0.003817,0.096955,289.039337,14.724366,0.969554,-1280.917969,294.500458,0
113.070007,64.971176,-1280.873413,-0.001423,0.003817,0.096955,289.006226,14.722679,0.969554,-1280.873413,294.500458,0
113.390007,64.940643,-1280.962402,-0.00144,0.003817,0.096964,288.870422,14.71576,0.969645,-1280.962402,294.500458,0
113.710007,64.904892,-1280.962402,-0.001453,0.003817,0.096964,288.711365,14.707659,0.969645,-1280.962402,294.500458,0
114.030006,64.917175,-1280.917969,-0.001431,0.003818,0.096981,288.766022,14.710442,0.969811,-1280.917969,294.500458,0
114.350006,65.110062,-1280.962402,-0.001423,0.003822,0.097086,289.624023,14.75415,0.970856,-1280.962402,294.500458,0
114.670006,65.184174,-1280.873413,-0.001436,0.003822,0.097086,289.953674,14.770945,0.970856,-1280.873413,294.500458,0
114.990005,65.168152,-1280.873413,-0.00144,0.003822,0.097086,289.882416,14.767315,0.970856,-1280.873413,294.500458,0
115.310005,65.138748,-1280.962402,-0.001449,0.003822,0.097086,289.751617,14.760652,0.970856,-1280.962402,294.500458,0
115.630005,65.101883,-1280.962402,-0.001423,0.003822,0.097086,289.587646,14.752297,0.970856,-1280.962402,294.500458,0
115.950005,65.057556,-1280.917969,-0.001444,0.003822,0.097086,289.390472,14.742252,0.970856,-1280.917969,294.500458,0
116.270004,65.029633,-1280.873413,-0.001436,0.003822,0.097086,289.266266,14.735926,0.970856,-1280.873413,294.500458,0
116.590004,65.028152,-1280.917969,-0.001423,0.003824,0.09712,289.259674,14.73559,0.971204,-1280.917969,294.500458,0
116.910004,65.019211,-1280.962402,-0.001427,0.003824,0.09712,289.219879,14.733563,0.971204,-1280.962402,294.500458,0
117.230003,64.997986,-1280.962402,-0.001423,0.003824,0.09712,289.125488,14.728754,0.971204,-1280.962402,294.500458,0
117.550003,64.96373,-1280.873413,-0.001423,0.003824,0.09712,288.973114,14.720992,0.971204,-1280.873413,294.500458,0
117.870003,64.936539,-1280.873413,-0.001414,0.003824,0.09712,288.852142,14.71483,0.971204,-1280.873413,294.500458,0
118.190002,64.894089,-1280.873413,-0.001431,0.003824,0.097129,288.66333,14.705211,0.971295,-1280.873413,294.500458,0
118.510002,65.144333,-1280.917969,-0.001427,0.003828,0.097242,289.776459,14.761917,0.972415,-1280.917969,294.500458,0
118.830002,65.164429,-1280.962402,-0.00141,0.003828,0.097242,289.865845,14.766471,0.972415,-1280.962402,294.500458,0
119.150009,65.151398,-1280.873413,-0.001427,0.003828,0.097242,289.807892,14.763517,0.972415,-1280.873413,294.500458,0
119.470009,65.134277,-1280.873413,-0.001418,0.003828,0.097242,289.73175,14.759639,0.972415,-1280.873413,294.500458,0
119.790009,65.096664,-1280.917969,-0.001414,0.003828,0.097242,289.564423,14.751115,0.972415,-1280.917969,294.500458,0
120.110008,65.060913,-1280.962402,-0.001423,0.003828,0.097242,289.405396,14.743013,0.972415,-1280.962402,294.500458,0
120.430008,65.025162,-1280.917969,-0.001431,0.003828,0.097242,289.246368,14.734913,0.972415,-1280.917969,294.500458,0
120.750008,64.995743,-1280.917969,-0.001423,0.003828,0.097242,289.115509,14.728246,0.972415,-1280.917969,294.500458,0
121.070007,64.968201,-1280.873413,-0.001427,0.003828,0.097242,288.992981,14.722005,0.972415,-1280.873413,294.500458,0
121.390007,64.968201,-1280.917969,-0.00141,0.003832,0.097337,288.992981,14.722005,0.973369,-1280.917969,294.500458,0
121.710007,65.16629,-1280.917969,-0.001427,0.003833,0.097346,289.874146,14.766892,0.97346,-1280.917969,294.500458,0
122.030006,65.161835,-1280.962402,-0.001431,0.003833,0.097346,289.854309,14.765882,0.97346,-1280.962402,294.500458,0
122.350006,65.158844,-1281.006958,-0.001406,0.003833,0.097346,289.841003,14.765205,0.97346,-1281.006958,294.500458,0
122.670006,65.129425,-1280.828979,-0.001406,0.003833,0.097346,289.710144,14.758538,0.97346,-1280.828979,294.500458,0
122.990005,65.113052,-1280.873413,-0.00141,0.003833,0.097346,289.637329,14.754828,0.97346,-1280.873413,294.500458,0
123.310005,65.074692,-1280.873413,-0.001414,0.003833,0.097346,289.466675,14.746137,0.97346,-1280.873413,294.500458,0
123.630005,65.040802,-1281.006958,-0.00141,0.003833,0.097346,289.315948,14.738456,0.97346,-1281.006958,294.500458,0
123.950005,65.021072,-1280.962402,-0.001406,0.003833,0.097346,289.22818,14.733986,0.97346,-1280.962402,294.500458,0
124.270004,64.98085,-1280.917969,-0.001418,0.003833,0.097346,289.049255,14.724871,0.97346,-1280.917969,294.500458,0
124.590004,64.959259,-1280.917969,-0.001418,0.003833,0.097346,288.953217,14.719978,0.97346,-1280.917969,294.500458,0
124.910004,64.923141,-1280.917969,-0.001423,0.003833,0.097346,288.792542,14.711794,0.97346,-1280.917969,294.500458,0
125.230003,64.88739,-1280.917969,-0.001423,0.003833,0.097346,288.633514,14.703692,0.97346,-1280.917969,294.500458,0
125.550003,65.482071,-1281.006958,-0.001401,0.00384,0.097546,291.278809,14.838449,0.975458,-1281.006958,294.500458,0
125.870003,65.509995,-1280.917969,-0.00141,0.00384,0.097546,291.403015,14.844777,0.975458,-1280.917969,294.500458,0
126.190002,65.502548,-1280.917969,-0.001418,0.00384,0.097546,291.369873,14.843089,0.975458,-1280.917969,294.500458,0
126.51001,65.493988,-1280.917969,-0.00141,0.00384,0.097546,291.331818,14.84115,0.975458,-1280.917969,294.500458,0
126.830009,65.482819,-1280.962402,-0.001406,0.00384,0.097546,291.282135,14.838619,0.975458,-1280.962402,294.500458,0
127.150009,65.445572,-1280.962402,-0.001423,0.00384,0.097546,291.116455,14.830179,0.975458,-1280.962402,294.500458,0
127.470009,65.417648,-1280.962402,-0.00141,0.00384,0.097546,290.992218,14.823851,0.975458,-1280.962402,294.500458,0
127.790009,65.379288,-1280.917969,-0.001406,0.00384,0.097546,290.821594,14.815159,0.975458,-1280.917969,294.500458,0
128.110001,65.356201,-1280.962402,-0.001406,0.00384,0.097546,290.718903,14.809927,0.975458,-1280.962402,294.500458,0
128.430008,65.320084,-1281.006958,-0.001414,0.00384,0.097546,290.558258,14.801743,0.975458,-1281.006958,294.500458,0
128.75,65.290665,-1280.962402,-0.001423,0.00384,0.097546,290.427368,14.795076,0.975458,-1280.962402,294.500458,0
129.070007,65.279495,-1280.962402,-0.001401,0.00384,0.097546,290.377686,14.792545,0.975458,-1280.962402,294.500458,0
129.389999,65.250458,-1280.873413,-0.001418,0.00384,0.097546,290.248535,14.785965,0.975458,-1280.873413,294.500458,0
129.710007,65.213593,-1280.917969,-0.00141,0.00384,0.097546,290.084534,14.777611,0.975458,-1280.917969,294.500458,0
130.029999,65.189377,-1280.917969,-0.001418,0.00384,0.097546,289.976837,14.772124,0.975458,-1280.917969,1681.640747,0
130.350006,65.03746,-1280.962402,-0.00141,0.003832,0.097329,289.301086,14.7377,0.973293,-1280.962402,0.097129,0
130.670013,64.998734,-1281.006958,-0.00141,0.003814,0.096886,289.128815,14.728924,0.968857,-1281.006958,0.096592,0
130.990005,64.993149,-1280.962402,-0.001401,0.003798,0.096469,289.103973,14.727658,0.964694,-1280.962402,0.096062,0
131.310013,64.879196,-1280.917969,-0.001393,0.00378,0.09602,288.597076,14.701837,0.960198,-1280.917969,0.095525,0
131.630005,64.796158,-1280.962402,-0.001397,0.003761,0.095525,288.227692,14.68302,0.955247,-1280.962402,0.094996,0
131.950012,64.771957,-1280.962402,-0.001397,0.00374,0.094987,288.120056,14.677535,0.949872,-1280.962402,0.094459,0
132.270004,64.719818,-1280.917969,-0.001371,0.003718,0.09445,287.888123,14.665721,0.944498,-1280.917969,0.093929,0
132.590012,64.691528,-1280.917969,-0.001388,0.003696,0.093885,287.762299,14.65931,0.938851,-1280.917969,0.093392,0
132.910004,64.657639,-1280.873413,-0.00141,0.003674,0.093331,287.611542,14.651629,0.93331,-1280.873413,0.092863,0
133.230011,64.63678,-1280.962402,-0.001397,0.003652,0.092759,287.518768,14.646904,0.927587,-1280.962402,0.092324,0
133.550003,64.481125,-1280.962402,-0.001406,0.003633,0.092291,286.826355,14.611631,0.922909,-1280.962402,0.091796,0
133.87001,64.356766,-1280.917969,-0.001393,0.003612,0.091735,286.273193,14.583452,0.917353,-1280.917969,0.091258,0
134.190002,64.20372,-1280.917969,-0.001393,0.003597,0.09137,285.592407,14.548771,0.913704,-1280.917969,0.090728,0
134.51001,63.710693,-1280.917969,-0.001397,0.003578,0.090877,283.399323,14.43705,0.908768,-1280.917969,0.090191,0
134.830002,62.950684,-1280.917969,-0.001384,0.003556,0.09033,280.018616,14.264829,0.903303,-1280.917969,0.089663,0
135.150009,61.951233,-1280.917969,-0.001388,0.003534,0.089775,275.572845,14.038349,0.897747,-1280.917969,0.089125,0
135.470001,61.040039,-1280.917969,-0.00138,0.003515,0.089281,271.519653,13.83187,0.892811,-1280.917969,0.088595,0
135.790009,59.713646,-1280.873413,-0.001388,0.003495,0.08876,265.619568,13.531305,0.887603,-1280.873413,0.088058,0
136.110001,58.790535,-1280.828979,-0.001371,0.003481,0.088423,261.513367,13.322125,0.884227,-1280.828979,0.087529,0
136.430008,57.366585,-1280.873413,-0.001388,0.003461,0.087902,255.179321,12.999454,0.879019,-1280.873413,0.086992,0
136.75,55.565788,-1280.962402,-0.001371,0.003441,0.087408,247.168976,12.591388,0.874084,-1280.962402,0.086462,0
137.070007,53.639137,-1280.962402,-0.001388,0.003419,0.086844,238.598801,12.154802,0.868437,-1280.962402,0.085925,0
137.389999,51.526291,-1280.873413,-0.001384,0.003396,0.086255,229.200394,11.676024,0.862547,-1280.873413,0.085396,0
137.710007,50.099731,-1280.917969,-0.001375,0.003383,0.085925,222.854736,11.352762,0.859247,-1280.917969,0.084857,0
138.030014,47.393333,-1281.006958,-0.001371,0.003355,0.085206,210.816071,10.739483,0.852056,-1281.006958,0.084329,0
138.350006,45.023926,-1281.006958,-0.00138,0.003335,0.084701,200.276428,10.202568,0.847014,-1281.006958,0.083792,0
138.670013,43.106209,-1281.006958,-0.001371,0.003317,0.084259,191.745987,9.768007,0.842593,-1281.006958,0.083262,0
138.990005,41.099495,-1280.873413,-0.00138,0.003297,0.083748,182.819687,9.313278,0.837476,-1280.873413,0.082724,0
139.310013,39.480415,-1280.962402,-0.001401,0.003279,0.083289,175.617661,8.94639,0.832889,-1280.962402,0.082196,0
139.630005,36.768799,-1280.917969,-0.001393,0.003256,0.082708,163.555786,8.331929,0.827075,-1280.917969,0.081658,0
139.950012,34.435143,-1280.917969,-0.001384,0.003239,0.082265,153.175171,7.803115,0.822654,-1280.917969,0.082144,0
140.100006,34.465302,-1280.917969,-0.001367,0.003239,0.082273,153.309311,7.809949,0.82273,-1280.917969,0.082144,0