File: Data/compression 36/Heating-17-36-reverse-1-1_11202024_171748(in).csv
Time (sec),S:Load (lbs),S:HL1 (DIM),S:LVDT (in),S:Position (in),Ch:Position (mm),Ch:Load (N),Ch:Stress (MPa),Ch:Strain (mm/mm),Ch:HL1 (DIM),Set Point (),Cycles ()
0.11,-0.070007,-1279.31665,-0.014314,-0.009505,-0.241419,-0.311408,-0.015864,-2.414188,-1279.31665,-0.241211,0
0.49,-0.037613,-1279.40564,-0.014314,-0.00948,-0.240803,-0.167311,-0.008523,-2.408026,-1279.40564,-0.2401,0
0.87,0.001862,-1279.31665,-0.014237,-0.009265,-0.23534,0.008281,0.000422,-2.353402,-1279.31665,-0.23377,0
1.25,-0.033142,-1279.31665,-0.013982,-0.009007,-0.228783,-0.147423,-0.00751,-2.287833,-1279.31665,-0.227439,0
1.63,-0.062561,-1279.31665,-0.013719,-0.008756,-0.22241,-0.278285,-0.014177,-2.224095,-1279.31665,-0.221109,0
2.01,-0.079315,-1279.361084,-0.013473,-0.008508,-0.216096,-0.352812,-0.017973,-2.160963,-1279.361084,-0.214778,0
2.39,-0.02346,-1279.361084,-0.013198,-0.008256,-0.209713,-0.104357,-0.005316,-2.097135,-1279.361084,-0.208446,0
2.77,-0.005959,-1279.40564,-0.012952,-0.008008,-0.203408,-0.026505,-0.00135,-2.034078,-1279.40564,-0.202116,0
3.15,-0.0149,-1279.272095,-0.012697,-0.007758,-0.197052,-0.066279,-0.003376,-1.970522,-1279.272095,-0.195785,0
3.53,-0.02681,-1279.31665,-0.012421,-0.00751,-0.190765,-0.119255,-0.006075,-1.907648,-1279.31665,-0.189455,0
3.91,-0.034264,-1279.40564,-0.012167,-0.007257,-0.184338,-0.152412,-0.007764,-1.84338,-1279.40564,-0.183124,0
4.29,-0.067772,-1279.361084,-0.01193,-0.007021,-0.178346,-0.301465,-0.015357,-1.783458,-1279.361084,-0.176792,0
4.67,-0.027557,-1279.31665,-0.011663,-0.006764,-0.171798,-0.122581,-0.006245,-1.717979,-1279.31665,-0.170463,0
5.05,-0.0149,-1279.31665,-0.011404,-0.006513,-0.165441,-0.066279,-0.003376,-1.654408,-1279.31665,-0.164131,0
5.43,-0.024948,-1279.272095,-0.011137,-0.006271,-0.159274,-0.110975,-0.005653,-1.592744,-1279.272095,-0.157801,0
5.81,-0.035378,-1279.361084,-0.010861,-0.006021,-0.152935,-0.157367,-0.008017,-1.529355,-1279.361084,-0.15147,0
6.19,-0.080063,-1279.31665,-0.010645,-0.005773,-0.146631,-0.356137,-0.018143,-1.466314,-1279.31665,-0.14514,0
6.57,-0.093094,-1279.31665,-0.010374,-0.005522,-0.140249,-0.414102,-0.021095,-1.402485,-1279.31665,-0.138809,0
6.95,-0.03389,-1279.31665,-0.010111,-0.005273,-0.133943,-0.150749,-0.00768,-1.339429,-1279.31665,-0.132477,0
7.33,-0.046173,-1279.31665,-0.009865,-0.005023,-0.127595,-0.205388,-0.010463,-1.275949,-1279.31665,-0.126148,0
7.710001,-0.072243,-1279.40564,-0.009602,-0.004772,-0.121212,-0.321352,-0.01637,-1.21212,-1279.40564,-0.119816,0
8.09,-0.083038,-1279.361084,-0.00936,-0.004524,-0.114908,-0.369373,-0.018817,-1.149079,-1279.361084,-0.113486,0
8.47,-0.112083,-1279.31665,-0.009089,-0.004272,-0.108516,-0.498572,-0.025398,-1.08516,-1279.31665,-0.107155,0
8.85,-0.032768,-1279.361084,-0.008839,-0.004028,-0.102307,-0.14576,-0.007425,-1.023072,-1279.361084,-0.100824,0
9.23,-0.013779,-1279.31665,-0.008571,-0.003776,-0.095915,-0.061291,-0.003122,-0.959153,-1279.31665,-0.094494,0
9.610001,0.008194,-1279.450073,-0.008313,-0.003527,-0.089585,0.036449,0.001857,-0.895854,-1279.450073,-0.088162,0
9.990001,-0.037987,-1279.450073,-0.008075,-0.003278,-0.083272,-0.168974,-0.008608,-0.832722,-1279.450073,-0.081832,0
10.370001,-0.06144,-1279.31665,-0.007804,-0.003028,-0.076923,-0.273297,-0.013922,-0.769227,-1279.31665,-0.075501,0
10.750001,-0.052132,-1279.31665,-0.007545,-0.002778,-0.070549,-0.231893,-0.011813,-0.705489,-1279.31665,-0.06917,0
11.13,-0.025696,-1279.40564,-0.007265,-0.002526,-0.064166,-0.114301,-0.005823,-0.641661,-1279.40564,-0.06284,0
11.51,0.018616,-1279.450073,-0.007032,-0.002281,-0.057948,0.082807,0.004218,-0.579483,-1279.450073,-0.056508,0
11.89,-0.019737,-1279.450073,-0.006765,-0.002028,-0.051523,-0.087796,-0.004473,-0.51523,-1279.450073,-0.050179,0
12.27,-0.042824,-1279.361084,-0.006485,-0.001775,-0.045087,-0.19049,-0.009704,-0.450872,-1279.361084,-0.043847,0
12.650001,-0.066284,-1279.361084,-0.00623,-0.001527,-0.038792,-0.294847,-0.01502,-0.387921,-1279.361084,-0.037517,0
13.030001,0.007446,-1279.40564,-0.00598,-0.001279,-0.032477,0.033123,0.001687,-0.324774,-1279.40564,-0.031186,0
13.410001,-0.002609,-1279.450073,-0.005708,-0.001031,-0.026191,-0.011607,-0.000591,-0.261915,-1279.450073,-0.024855,0
13.790001,-0.016762,-1279.40564,-0.005489,-0.000784,-0.019912,-0.07456,-0.003798,-0.199116,-1279.40564,-0.018525,0
14.170001,-0.032768,-1279.40564,-0.005238,-0.000538,-0.013659,-0.14576,-0.007425,-0.136589,-1279.40564,-0.012193,0
14.550001,0.138893,-1279.40564,-0.005036,0,-0.000008,0.617827,0.031474,-0.000076,-1279.40564,0.000174,0
14.93,0.120644,-1279.450073,-0.005019,-0.000001,-0.000026,0.53665,0.027338,-0.000257,-1279.450073,0.000174,0
15.31,0.113945,-1279.40564,-0.005036,-0.000001,-0.000017,0.506853,0.02582,-0.000167,-1279.40564,0.000702,0
15.690001,0.092346,-1279.40564,-0.005057,0.000005,0.000139,0.410776,0.020926,0.001393,-1279.40564,0.001337,0
16.070002,0.156021,-1279.40564,-0.005036,0.000028,0.000721,0.694017,0.035355,0.007206,-1279.40564,0.00197,0
16.450001,0.309441,-1279.40564,-0.004988,0.000055,0.001388,1.376461,0.07012,0.013883,-1279.40564,0.002602,0
16.83,0.551109,-1279.450073,-0.004954,0.000084,0.002135,2.451457,0.124883,0.021347,-1279.450073,0.003235,0
17.210001,0.777138,-1279.494507,-0.00495,0.000111,0.002828,3.456881,0.176102,0.028281,-1279.494507,0.003868,0
17.59,0.982689,-1279.40564,-0.004911,0.000129,0.003287,4.371219,0.22268,0.032868,-1279.40564,0.004501,0
17.970001,1.155098,-1279.40564,-0.004881,0.000152,0.003859,5.138133,0.261749,0.038591,-1279.40564,0.005134,0
18.35,1.490974,-1279.450073,-0.004889,0.000178,0.004528,6.632185,0.33786,0.045282,-1279.450073,0.005776,0
18.730001,1.934845,-1279.450073,-0.004855,0.000208,0.005291,8.60662,0.438442,0.052913,-1279.450073,0.00641,0
19.110001,2.169441,-1279.40564,-0.004825,0.000229,0.005811,9.650157,0.491602,0.058106,-1279.40564,0.007043,0
19.490002,2.408134,-1279.40564,-0.004803,0.00025,0.006357,10.711917,0.545691,0.063571,-1279.40564,0.007676,0
19.870001,2.871735,-1279.361084,-0.004781,0.00028,0.007103,12.774114,0.650744,0.071035,-1279.361084,0.008309,0
20.250002,3.155853,-1279.361084,-0.004751,0.0003,0.007632,14.037936,0.715127,0.076319,-1279.361084,0.008941,0
20.630001,3.594513,-1279.40564,-0.004747,0.000323,0.008213,15.989192,0.814528,0.082132,-1279.40564,0.009574,0
21.01,4.108009,-1279.450073,-0.004734,0.000354,0.009002,18.273338,0.930888,0.09002,-1279.450073,0.010207,0
21.390001,4.325104,-1279.361084,-0.004712,0.00038,0.009662,19.239023,0.980083,0.096621,-1279.361084,0.010841,0
21.77,4.774559,-1279.361084,-0.004661,0.000408,0.010355,21.238298,1.081931,0.103555,-1279.361084,0.011474,0
22.150002,5.047882,-1279.40564,-0.004635,0.000425,0.010807,22.454102,1.143866,0.108066,-1279.40564,0.012107,0
22.530001,5.424721,-1279.450073,-0.004631,0.000449,0.011396,24.130363,1.229259,0.113956,-1279.450073,0.01274,0
22.910002,6.064827,-1279.40564,-0.004605,0.000481,0.012219,26.977697,1.374309,0.122192,-1279.40564,0.013373,0
23.290001,6.135208,-1279.361084,-0.004609,0.000503,0.012775,27.29077,1.390258,0.127748,-1279.361084,0.014006,0
23.670002,6.486725,-1279.361084,-0.004549,0.000526,0.013373,28.854393,1.469913,0.133728,-1279.361084,0.01464,0
24.050001,6.838989,-1279.40564,-0.004536,0.000549,0.013937,30.421343,1.549737,0.139375,-1279.40564,0.015273,0
24.43,7.311905,-1279.450073,-0.004506,0.00058,0.014735,32.524979,1.656901,0.147354,-1279.450073,0.015906,0
24.810001,7.543892,-1279.450073,-0.004488,0.000606,0.015385,33.556908,1.70947,0.153848,-1279.450073,0.016538,0
25.190001,7.666031,-1279.361084,-0.004458,0.000631,0.016036,34.100208,1.737147,0.160358,-1279.361084,0.017171,0
25.570002,7.927063,-1279.40564,-0.004445,0.00065,0.016504,35.261337,1.796298,0.165037,-1279.40564,0.017804,0
25.950001,8.189583,-1279.361084,-0.004428,0.000678,0.017232,36.429085,1.855786,0.172319,-1279.361084,0.018438,0
26.330002,8.369812,-1279.450073,-0.004389,0.000698,0.017736,37.230782,1.896626,0.17736,-1279.450073,0.019071,0
26.710001,8.820015,-1279.40564,-0.004359,0.000729,0.018507,39.233387,1.998644,0.185066,-1279.40564,0.019704,0
27.090002,8.998383,-1279.361084,-0.004333,0.000756,0.019209,40.026806,2.039063,0.192091,-1279.361084,0.020337,0
27.470001,8.955185,-1279.40564,-0.004307,0.000775,0.019678,39.834652,2.029274,0.196784,-1279.40564,0.02097,0
27.85,9.159241,-1279.450073,-0.004281,0.000802,0.020372,40.742336,2.075514,0.203718,-1279.450073,0.021603,0
28.230001,9.369263,-1279.40564,-0.00426,0.000832,0.021144,41.676563,2.123105,0.211439,-1279.40564,0.022237,0
28.610001,9.68615,-1279.40564,-0.004238,0.000858,0.021793,43.086143,2.194913,0.217934,-1279.40564,0.02287,0
28.990002,9.689499,-1279.450073,-0.004212,0.000877,0.022288,43.101044,2.195672,0.222885,-1279.450073,0.023503,0
29.370001,9.794884,-1279.40564,-0.004195,0.000902,0.022912,43.56982,2.219552,0.229122,-1279.40564,0.024145,0
29.750002,9.922607,-1279.494507,-0.004165,0.000927,0.023538,44.137962,2.248495,0.235375,-1279.494507,0.024777,0
30.130001,10.223488,-1279.40564,-0.004122,0.000953,0.024196,45.476345,2.316676,0.241961,-1279.40564,0.02541,0
30.510002,10.531433,-1279.450073,-0.004105,0.000985,0.025012,46.846153,2.386457,0.250121,-1279.450073,0.026043,0
30.890001,10.451378,-1279.40564,-0.004057,0.001004,0.025497,46.490051,2.368316,0.254966,-1279.40564,0.026676,0
31.270002,10.560852,-1279.450073,-0.004027,0.001028,0.026122,46.977016,2.393123,0.261218,-1279.450073,0.02731,0
31.650002,10.681129,-1279.450073,-0.004027,0.001053,0.026736,47.512035,2.420379,0.267365,-1279.450073,0.027943,0
32.030003,10.644264,-1279.494507,-0.004027,0.001076,0.027318,47.348053,2.412025,0.273179,-1279.494507,0.028576,0
32.41,11.011055,-1279.450073,-0.003971,0.001101,0.02796,48.979618,2.495141,0.279598,-1279.450073,0.029209,0
32.790001,11.144363,-1279.450073,-0.003945,0.00113,0.028697,49.572605,2.525349,0.286971,-1279.450073,0.029842,0
33.170002,11.184578,-1279.494507,-0.003911,0.001152,0.029253,49.751488,2.534461,0.292527,-1279.494507,0.030474,0
33.550003,11.281395,-1279.539062,-0.003906,0.001175,0.029842,50.182152,2.556401,0.298416,-1279.539062,0.031107,0
33.93,11.270226,-1279.494507,-0.003889,0.001197,0.030414,50.132465,2.553869,0.304139,-1279.494507,0.031742,0
34.310001,11.584503,-1279.539062,-0.003842,0.001223,0.031056,51.530445,2.625086,0.310558,-1279.539062,0.032374,0
34.690002,11.82357,-1279.494507,-0.003824,0.001254,0.031845,52.593868,2.679259,0.318446,-1279.494507,0.033007,0
35.070004,11.971031,-1279.494507,-0.003773,0.001277,0.032444,53.249805,2.712674,0.324441,-1279.494507,0.03364,0
35.450001,12.16317,-1279.539062,-0.003777,0.001302,0.033059,54.104481,2.756214,0.330588,-1279.539062,0.034273,0
35.830002,12.37915,-1279.494507,-0.003768,0.001328,0.033719,55.065212,2.805156,0.337189,-1279.494507,0.034906,0
36.210003,12.055557,-1279.450073,-0.003738,0.00134,0.03404,53.625797,2.731828,0.340398,-1279.450073,0.03554,0
36.59,12.705719,-1279.450073,-0.003695,0.001383,0.035131,56.51786,2.879157,0.351314,-1279.450073,0.036173,0
36.970001,12.572037,-1279.494507,-0.003678,0.001402,0.035601,55.923214,2.848864,0.356007,-1279.494507,0.036806,0
37.350002,12.64502,-1279.583496,-0.003665,0.001427,0.036243,56.247856,2.865402,0.362426,-1279.583496,0.037439,0
37.730003,13.017769,-1279.450073,-0.00363,0.001452,0.036875,57.90593,2.949868,0.368755,-1279.450073,0.038072,0
38.110001,13.354767,-1279.494507,-0.003622,0.001481,0.037629,59.404968,3.026233,0.376294,-1279.494507,0.038704,0
38.490002,13.563667,-1279.450073,-0.003591,0.001511,0.038367,60.334206,3.073571,0.383667,-1279.450073,0.039339,0
38.870003,13.42775,-1279.539062,-0.003548,0.001528,0.038809,59.729614,3.042772,0.388088,-1279.539062,0.039972,0
39.25,13.483978,-1279.494507,-0.00354,0.00155,0.039381,59.979733,3.055513,0.393811,-1279.494507,0.040604,0
39.630001,13.678726,-1279.494507,-0.003505,0.001576,0.040041,60.846012,3.099643,0.400412,-1279.494507,0.041237,0
40.010002,14.213081,-1279.494507,-0.003497,0.001605,0.040777,63.222942,3.22073,0.407769,-1279.494507,0.041879,0
40.390003,14.184036,-1279.539062,-0.003449,0.001627,0.041333,63.093746,3.214149,0.413326,-1279.539062,0.042512,0
40.77,14.035088,-1279.583496,-0.003432,0.001646,0.041809,62.431187,3.180396,0.418095,-1279.583496,0.043145,0
41.150002,14.527367,-1279.539062,-0.003419,0.001678,0.042625,64.620956,3.291948,0.426255,-1279.539062,0.043778,0
41.530003,14.398521,-1279.539062,-0.003397,0.001699,0.043163,64.047821,3.262752,0.431629,-1279.539062,0.044412,0
41.910004,14.741104,-1279.494507,-0.003363,0.001721,0.043717,65.571709,3.340382,0.437171,-1279.494507,0.045045,0
42.290001,15.205452,-1279.494507,-0.003341,0.001753,0.044524,67.63723,3.445605,0.44524,-1279.494507,0.045678,0
42.670002,15.199501,-1279.539062,-0.00332,0.00178,0.045201,67.610756,3.444256,0.452007,-1279.539062,0.04631,0
43.050003,15.344353,-1279.539062,-0.00329,0.001804,0.045824,68.255089,3.47708,0.458245,-1279.539062,0.046943,0
43.43,15.469841,-1279.494507,-0.003272,0.001825,0.046354,68.813286,3.505516,0.463544,-1279.494507,0.047576,0
43.810001,15.57708,-1279.450073,-0.003247,0.001847,0.046918,69.290314,3.529817,0.469176,-1279.450073,0.048209,0
44.190002,16.238792,-1279.494507,-0.003216,0.00188,0.047741,72.233757,3.679763,0.477412,-1279.494507,0.048843,0
44.570004,15.974777,-1279.583496,-0.003216,0.001899,0.048244,71.059357,3.619936,0.482438,-1279.583496,0.049476,0
44.950001,16.215332,-1279.450073,-0.003195,0.001921,0.04879,72.129402,3.674447,0.487903,-1279.450073,0.050109,0
45.330002,16.557541,-1279.494507,-0.00316,0.001947,0.049458,73.651619,3.751992,0.49458,-1279.494507,0.050742,0
45.710003,16.874802,-1279.494507,-0.003122,0.001976,0.050179,75.062866,3.823885,0.501786,-1279.494507,0.051375,0
46.090004,17.332077,-1279.583496,-0.003117,0.002002,0.050855,77.096931,3.927505,0.508554,-1279.583496,0.052007,0
46.470001,17.139557,-1279.539062,-0.003061,0.002025,0.051444,76.240555,3.883879,0.514443,-1279.539062,0.052642,0
46.850002,17.490334,-1279.539062,-0.003065,0.002048,0.052026,77.800888,3.963366,0.520257,-1279.539062,0.053275,0
47.230003,17.718597,-1279.494507,-0.003044,0.002074,0.052684,78.816261,4.015091,0.526842,-1279.494507,0.053908,0
47.610001,17.956917,-1279.539062,-0.003014,0.002095,0.053222,79.876358,4.069096,0.532217,-1279.539062,0.05454,0
47.990002,18.680061,-1279.494507,-0.002971,0.002129,0.05408,83.093063,4.232963,0.540801,-1279.494507,0.055173,0
48.370003,18.567604,-1279.539062,-0.002953,0.002148,0.054549,82.592827,4.207479,0.545494,-1279.539062,0.055806,0
48.750004,18.937744,-1279.494507,-0.00294,0.002174,0.055226,84.239296,4.291354,0.552262,-1279.494507,0.05644,0
49.130001,19.205856,-1279.494507,-0.002915,0.0022,0.055885,85.431915,4.352109,0.558847,-1279.494507,0.057073,0
49.510002,19.13063,-1279.539062,-0.002893,0.002218,0.056345,85.097298,4.335063,0.56345,-1279.539062,0.057706,0
49.890003,20.136787,-1279.494507,-0.002876,0.002254,0.057264,89.572906,4.563061,0.572639,-1279.494507,0.058339,0
50.270004,20.031776,-1279.583496,-0.002854,0.002276,0.05781,89.105789,4.539265,0.578105,-1279.583496,0.058972,0
50.650002,19.821014,-1279.583496,-0.002841,0.002292,0.058218,88.168274,4.491506,0.582177,-1279.583496,0.059605,0
51.030003,20.58065,-1279.494507,-0.002798,0.002323,0.058997,91.547302,4.663642,0.589974,-1279.494507,0.060246,0
51.410004,20.980583,-1279.494507,-0.002764,0.00235,0.0597,93.326294,4.754268,0.596999,-1279.494507,0.060879,0
51.790001,21.577866,-1279.628052,-0.002751,0.002379,0.06043,95.983139,4.889615,0.604296,-1279.628052,0.061514,0
52.170002,21.944649,-1279.583496,-0.002725,0.002402,0.061019,97.61467,4.972729,0.610186,-1279.583496,0.062146,0
52.550003,21.866829,-1279.539062,-0.002716,0.002423,0.061556,97.268517,4.955094,0.61556,-1279.539062,0.062779,0
52.930004,22.128601,-1279.494507,-0.00269,0.002446,0.062121,98.43293,5.014413,0.621207,-1279.494507,0.063412,0
53.310001,22.410492,-1279.583496,-0.002665,0.002466,0.062649,99.686844,5.07829,0.626491,-1279.583496,0.064045,0
53.690002,23.442703,-1279.628052,-0.002639,0.002499,0.063482,104.278351,5.312192,0.634818,-1279.628052,0.064678,0
54.070004,23.776352,-1279.628052,-0.00263,0.002528,0.06421,105.762497,5.387798,0.6421,-1279.628052,0.065311,0
54.450001,24.045952,-1279.583496,-0.0026,0.002549,0.064738,106.961739,5.44889,0.647384,-1279.583496,0.065945,0
54.830002,24.43322,-1279.539062,-0.002561,0.002573,0.065364,108.684387,5.536647,0.653636,-1279.539062,0.066578,0
55.210003,24.232506,-1279.583496,-0.002544,0.002589,0.065762,107.791573,5.491164,0.657618,-1279.583496,0.067211,0
55.590004,25.301964,-1279.628052,-0.002535,0.002621,0.066578,112.548759,5.733507,0.665778,-1279.628052,0.067843,0
55.970001,25.757378,-1279.628052,-0.002501,0.002648,0.067255,114.574539,5.836705,0.672546,-1279.628052,0.068476,0
56.350002,26.271248,-1279.583496,-0.002479,0.002673,0.067904,116.860344,5.95315,0.67904,-1279.583496,0.069109,0
56.730003,26.428017,-1279.583496,-0.002462,0.002693,0.068399,117.557686,5.988674,0.683991,-1279.583496,0.069743,0
57.110004,27.040199,-1279.628052,-0.002445,0.002717,0.069023,120.280815,6.127397,0.690229,-1279.628052,0.070376,0
57.490002,27.133293,-1279.583496,-0.002427,0.002738,0.069544,120.694916,6.148492,0.695437,-1279.583496,0.071009,0
57.870003,28.486122,-1279.539062,-0.002397,0.002774,0.070454,126.712601,6.455048,0.704535,-1279.539062,0.071642,0
58.250004,28.748268,-1279.583496,-0.002384,0.002799,0.071086,127.878685,6.514451,0.710864,-1279.583496,0.072275,0
58.630001,29.158623,-1279.628052,-0.002376,0.002824,0.071721,129.704025,6.607439,0.717207,-1279.628052,0.072908,0
59.010002,30.10408,-1279.672485,-0.002333,0.00285,0.072396,133.909637,6.821682,0.72396,-1279.672485,0.073542,0
59.390003,29.843788,-1279.716919,-0.002307,0.00287,0.0729,132.751801,6.762699,0.729001,-1279.716919,0.074175,0
59.770004,31.289711,-1279.583496,-0.002298,0.002902,0.073706,139.183578,7.09035,0.737055,-1279.583496,0.074808,0
60.150002,31.701927,-1279.539062,-0.002268,0.002926,0.074313,141.017212,7.183759,0.743126,-1279.539062,0.075441,0
60.530003,32.384483,-1279.539062,-0.002255,0.002948,0.074885,144.053375,7.338428,0.748849,-1279.539062,0.076073,0
60.910004,32.642914,-1279.672485,-0.002229,0.002972,0.075484,145.202927,7.39699,0.754844,-1279.672485,0.076706,0
61.290005,33.372017,-1279.628052,-0.002225,0.002997,0.076134,148.446152,7.562207,0.761339,-1279.628052,0.077339,0
61.670002,34.842888,-1279.583496,-0.002186,0.003025,0.076845,154.988907,7.895511,0.768455,-1279.583496,0.077973,0
62.050003,34.995934,-1279.628052,-0.002173,0.003044,0.077322,155.669693,7.930192,0.773224,-1279.628052,0.078615,0
62.430004,35.819252,-1279.628052,-0.002156,0.003074,0.078069,159.331985,8.116758,0.780688,-1279.628052,0.079248,0
62.810001,36.462708,-1279.672485,-0.00213,0.003093,0.078571,162.194229,8.262568,0.785714,-1279.672485,0.079881,0
63.190002,36.757256,-1279.628052,-0.0021,0.003115,0.079127,163.50444,8.329312,0.79127,-1279.628052,0.080514,0
63.570004,38.670509,-1279.628052,-0.002087,0.003147,0.079932,172.015015,8.762862,0.799324,-1279.628052,0.081147,0
63.950005,39.212311,-1279.628052,-0.002052,0.00317,0.080523,174.425064,8.885637,0.805229,-1279.628052,0.081779,0
64.330002,40.244156,-1279.672485,-0.002039,0.003197,0.081207,179.014954,9.119456,0.812072,-1279.672485,0.082412,0
64.710007,40.863411,-1279.716919,-0.002035,0.003222,0.08184,181.769531,9.259781,0.8184,-1279.716919,0.083047,0
65.090004,41.622673,-1279.716919,-0.002018,0.003245,0.082421,185.146896,9.431832,0.824214,-1279.716919,0.083679,0
65.470001,42.739792,-1279.672485,-0.001996,0.00327,0.083054,190.116089,9.684975,0.830542,-1279.672485,0.084312,0
65.850006,43.523636,-1279.672485,-0.001975,0.003293,0.083654,193.602798,9.862597,0.836537,-1279.672485,0.084945,0
66.230003,44.327217,-1279.716919,-0.001953,0.003318,0.084268,197.177307,10.04469,0.842684,-1279.716919,0.085578,0
66.610001,44.986687,-1279.672485,-0.001927,0.003341,0.084859,200.110779,10.194129,0.848589,-1279.672485,0.086211,0
66.990005,46.755455,-1279.628052,-0.001923,0.00337,0.085596,207.978653,10.594937,0.855962,-1279.628052,0.086845,0
67.370003,48.205101,-1279.628052,-0.001914,0.0034,0.08635,214.427002,10.923432,0.863501,-1279.628052,0.087478,0
67.75,48.665726,-1279.628052,-0.001901,0.003419,0.086836,216.475952,11.027811,0.868361,-1279.628052,0.088111,0
68.130005,49.655121,-1279.672485,-0.00185,0.003445,0.087513,220.877014,11.252011,0.875128,-1279.672485,0.088744,0
68.510002,50.691063,-1279.761475,-0.001854,0.00347,0.088127,225.485107,11.486759,0.881275,-1279.761475,0.089377,0
68.890007,51.518471,-1279.716919,-0.001858,0.003493,0.088718,229.165604,11.674253,0.887179,-1279.716919,0.090009,0
69.270004,53.711746,-1279.716919,-0.001794,0.003525,0.089532,238.921783,12.171256,0.895324,-1279.716919,0.090644,0
69.650002,54.745453,-1279.761475,-0.001789,0.003546,0.09007,243.519943,12.405498,0.900699,-1279.761475,0.091277,0
70.030006,55.533394,-1279.716919,-0.001794,0.003568,0.090626,247.024872,12.584047,0.906255,-1279.716919,0.091909,0
70.410004,56.705246,-1279.716919,-0.001781,0.003593,0.091258,252.237534,12.849592,0.912584,-1279.716919,0.092542,0
70.790001,57.81604,-1279.672485,-0.001776,0.003615,0.091831,257.178589,13.101302,0.918306,-1279.672485,0.093175,0
71.170006,59.626511,-1279.672485,-0.001755,0.003645,0.092594,265.231964,13.51156,0.925937,-1279.672485,0.093808,0
71.550003,61.031845,-1279.672485,-0.00172,0.003671,0.093236,271.483215,13.830013,0.932356,-1279.672485,0.094442,0
71.93,61.128288,-1279.716919,-0.001729,0.003686,0.093617,271.912201,13.851868,0.936171,-1279.716919,0.095075,0
72.310005,63.412415,-1279.761475,-0.00172,0.003716,0.094398,282.07251,14.369458,0.943983,-1279.761475,0.095708,0
72.690002,64.998352,-1279.672485,-0.001703,0.003743,0.095083,289.127106,14.728837,0.950826,-1279.672485,0.096341,0
73.07,66.385071,-1279.716919,-0.001673,0.003758,0.095464,295.295532,15.043072,0.954641,-1279.716919,0.095743,0
73.450005,65.054581,-1279.761475,-0.001669,0.003758,0.095447,289.377228,14.741579,0.954475,-1279.761475,294.500458,0
73.830002,65.852585,-1279.628052,-0.001651,0.003768,0.095699,292.926941,14.922409,0.956988,-1279.628052,294.500458,0
74.210007,64.790939,-1279.672485,-0.001647,0.003768,0.095717,288.204498,14.681837,0.95717,-1279.672485,294.500458,0
74.590004,65.243744,-1279.672485,-0.00163,0.003791,0.096289,290.218658,14.784444,0.962892,-1279.672485,294.500458,0
74.970001,65.318222,-1279.628052,-0.001621,0.003801,0.096557,290.549957,14.80132,0.965572,-1279.628052,294.500458,0
75.350006,65.110443,-1279.761475,-0.001638,0.00381,0.096783,289.625702,14.754238,0.967828,-1279.761475,294.500458,0
75.730003,64.868774,-1279.716919,-0.001638,0.003811,0.096792,288.55072,14.699474,0.967919,-1279.716919,294.500458,0
76.110001,65.247467,-1279.672485,-0.00163,0.003821,0.097043,290.235229,14.785287,0.970432,-1279.672485,294.500458,0
76.490005,64.758179,-1279.672485,-0.001604,0.003821,0.09706,288.058777,14.674413,0.970598,-1279.672485,294.500458,0
76.870003,65.170395,-1279.672485,-0.001608,0.00383,0.097295,289.892395,14.767822,0.972945,-1279.672485,294.500458,0
77.25,64.706421,-1279.761475,-0.001595,0.003833,0.097346,287.828522,14.662684,0.97346,-1279.761475,294.500458,0
77.630005,64.99202,-1279.716919,-0.0016,0.003839,0.097503,289.098938,14.727402,0.975034,-1279.716919,294.500458,0
78.010002,64.953293,-1279.672485,-0.001569,0.003843,0.097615,288.926666,14.718627,0.976155,-1279.672485,294.500458,0
78.390007,65.416534,-1279.672485,-0.001574,0.003852,0.097841,290.987274,14.823599,0.97841,-1279.672485,294.500458,0
78.770004,65.117142,-1279.672485,-0.001574,0.003852,0.09785,289.655518,14.755754,0.978501,-1279.672485,294.500458,0
79.150002,65.000595,-1279.716919,-0.001582,0.003855,0.09792,289.137085,14.729345,0.979198,-1279.716919,294.500458,0
79.530006,64.752213,-1279.672485,-0.001582,0.003857,0.097971,288.032227,14.673061,0.979712,-1279.672485,294.500458,0
79.910004,64.851639,-1279.672485,-0.001569,0.00386,0.098048,288.474487,14.695591,0.980485,-1279.672485,294.500458,0
80.290001,64.819992,-1279.672485,-0.001565,0.003865,0.098162,288.33374,14.68842,0.98162,-1279.672485,294.500458,0
80.670006,64.770096,-1279.761475,-0.001565,0.003869,0.098283,288.111786,14.677114,0.982831,-1279.761475,294.500458,0
81.050003,65.205017,-1279.716919,-0.001561,0.003873,0.098362,290.046417,14.775668,0.983618,-1279.716919,294.500458,0
81.43,64.958878,-1279.672485,-0.001561,0.003873,0.098362,288.951508,14.719893,0.983618,-1279.672485,294.500458,0
81.810005,64.940262,-1279.672485,-0.001548,0.003877,0.098483,288.868713,14.715673,0.98483,-1279.672485,294.500458,0
82.190002,64.895203,-1279.761475,-0.001552,0.003878,0.098492,288.668274,14.705463,0.984921,-1279.761475,294.500458,0
82.570007,65.027023,-1279.716919,-0.001556,0.003881,0.098587,289.254639,14.735333,0.985874,-1279.716919,294.500458,0
82.950005,64.842331,-1279.716919,-0.001544,0.003881,0.098587,288.433105,14.693482,0.985874,-1279.716919,294.500458,0
83.330002,65.188644,-1279.716919,-0.001544,0.003888,0.098743,289.973572,14.771957,0.987434,-1279.716919,294.500458,0
83.710007,65.030746,-1279.716919,-0.001552,0.003889,0.098778,289.27121,14.736178,0.987782,-1279.716919,294.500458,0
84.090004,65.059433,-1279.672485,-0.001539,0.00389,0.098813,289.398804,14.742678,0.98813,-1279.672485,294.500458,0
84.470001,65.189377,-1279.805908,-0.001535,0.003894,0.098899,289.976837,14.772124,0.988993,-1279.805908,294.500458,0
84.850006,65.085114,-1279.805908,-0.001544,0.003895,0.098925,289.513031,14.748498,0.98925,-1279.805908,294.500458,0
85.230003,65.137619,-1279.716919,-0.001544,0.003897,0.098986,289.746613,14.760396,0.989856,-1279.716919,294.500458,0
85.610001,65.043045,-1279.672485,-0.001531,0.003897,0.098995,289.325928,14.738965,0.989947,-1279.672485,294.500458,0
85.990005,64.910843,-1279.761475,-0.001526,0.003898,0.099004,288.737854,14.709007,0.990038,-1279.761475,294.500458,0
86.370003,65.874924,-1279.761475,-0.001531,0.00391,0.099323,293.026306,14.927471,0.993232,-1279.761475,294.500458,0
86.750008,65.843277,-1279.805908,-0.001539,0.00391,0.099323,292.885529,14.9203,0.993232,-1279.805908,294.500458,0
87.130005,65.735657,-1279.672485,-0.001526,0.00391,0.099323,292.406799,14.895913,0.993232,-1279.672485,294.500458,0
87.510002,65.578888,-1279.716919,-0.001518,0.00391,0.099323,291.709473,14.860388,0.993232,-1279.716919,294.500458,0
87.890007,65.451904,-1279.716919,-0.001522,0.00391,0.099323,291.144623,14.831614,0.993232,-1279.716919,294.500458,0
88.270004,65.296249,-1279.761475,-0.001526,0.003911,0.099332,290.452209,14.796342,0.993323,-1279.761475,294.500458,0
88.650002,65.18045,-1279.716919,-0.001522,0.003911,0.099332,289.937134,14.770102,0.993323,-1279.716919,294.500458,0
89.030006,65.060913,-1279.716919,-0.001496,0.003913,0.099393,289.405396,14.743013,0.993929,-1279.716919,294.500458,0
89.410004,65.052353,-1279.716919,-0.001496,0.003914,0.099411,289.36731,14.741074,0.99411,-1279.716919,294.500458,0
89.790001,64.99054,-1279.716919,-0.001505,0.003914,0.099428,289.092346,14.727067,0.994277,-1279.716919,294.500458,0
90.170006,65.182678,-1279.716919,-0.001522,0.003918,0.099523,289.947021,14.770606,0.995231,-1279.716919,294.500458,0
90.550003,65.13092,-1279.761475,-0.001513,0.003918,0.099523,289.716797,14.758878,0.995231,-1279.761475,294.500458,0
90.930008,65.031494,-1279.672485,-0.0015,0.003919,0.099532,289.274536,14.736347,0.995321,-1279.672485,294.500458,0
91.310005,64.943253,-1279.761475,-0.001492,0.003919,0.099532,288.882019,14.716352,0.995321,-1279.761475,294.500458,0
91.690002,64.954041,-1279.716919,-0.001522,0.003924,0.099679,288.929993,14.718796,0.99679,-1279.716919,294.500458,0
92.070007,65.383392,-1279.805908,-0.001509,0.003926,0.099723,290.839844,14.816088,0.997229,-1279.805908,294.500458,0
92.450005,65.31636,-1279.716919,-0.001505,0.003926,0.099723,290.541687,14.8009,0.997229,-1279.716919,294.500458,0
92.830002,65.254181,-1279.672485,-0.001496,0.003926,0.099723,290.265106,14.786808,0.997229,-1279.672485,294.500458,0
93.210007,65.13353,-1279.761475,-0.001505,0.003926,0.099723,289.728424,14.759469,0.997229,-1279.761475,294.500458,0
93.590004,65.044525,-1279.761475,-0.001518,0.003926,0.099723,289.332489,14.739301,0.997229,-1279.761475,294.500458,0
93.970001,64.978989,-1279.761475,-0.001509,0.003927,0.099749,289.040985,14.724449,0.997486,-1279.761475,294.500458,0
94.350006,65.012131,-1279.761475,-0.001505,0.003929,0.099809,289.188416,14.731959,0.998092,-1279.761475,294.500458,0
94.730003,65.047882,-1279.716919,-0.001522,0.003931,0.099835,289.347443,14.740061,0.998349,-1279.716919,294.500458,0
95.110008,65.03746,-1279.716919,-0.0015,0.003931,0.099853,289.301086,14.7377,0.998531,-1279.716919,294.500458,0
95.490005,64.991653,-1279.805908,-0.001496,0.003931,0.099853,289.097321,14.72732,0.998531,-1279.805908,294.500458,0
95.870003,64.998734,-1279.716919,-0.0015,0.003933,0.099897,289.128815,14.728924,0.99897,-1279.716919,294.500458,0
96.250008,64.960007,-1279.761475,-0.001513,0.003933,0.099897,288.956543,14.720148,0.99897,-1279.761475,294.500458,0
96.630005,64.895584,-1279.716919,-0.001492,0.003934,0.099914,288.669983,14.705549,0.999137,-1279.716919,294.500458,0
97.010002,64.9142,-1279.761475,-0.001496,0.003935,0.099948,288.752777,14.709768,0.999485,-1279.761475,294.500458,0
97.390007,64.88031,-1279.805908,-0.001487,0.003935,0.099948,288.60202,14.702088,0.999485,-1279.805908,294.500458,0
97.770004,65.259384,-1279.716919,-0.001492,0.00394,0.100088,290.288239,14.787988,1.000878,-1279.716919,294.500458,0
98.150002,65.247101,-1279.716919,-0.001496,0.00394,0.100088,290.233612,14.785204,1.000878,-1279.716919,294.500458,0
98.530006,65.199814,-1279.761475,-0.001496,0.00394,0.100088,290.023254,14.774489,1.000878,-1279.761475,294.500458,0
98.910004,65.104111,-1279.761475,-0.001475,0.00394,0.100088,289.597534,14.752803,1.000878,-1279.761475,294.500458,0
99.290001,65.077301,-1279.850464,-0.001479,0.00394,0.100088,289.478302,14.746727,1.000878,-1279.850464,294.500458,0
99.670006,64.995377,-1279.805908,-0.001483,0.003942,0.100121,289.113861,14.728163,1.001211,-1279.805908,294.500458,0
100.050003,65.006927,-1279.761475,-0.001466,0.003942,0.100121,289.165253,14.73078,1.001211,-1279.761475,294.500458,0
100.430008,64.953674,-1279.761475,-0.001457,0.003942,0.100121,288.928375,14.718713,1.001211,-1279.761475,294.500458,0
100.810005,65.212463,-1279.850464,-0.00147,0.003946,0.100235,290.079529,14.777355,1.002346,-1279.850464,294.500458,0
101.190002,65.212463,-1279.761475,-0.001457,0.003946,0.100235,290.079529,14.777355,1.002346,-1279.761475,294.500458,0
101.570007,65.097778,-1279.672485,-0.001462,0.003946,0.100235,289.569366,14.751368,1.002346,-1279.672485,294.500458,0
101.950005,65.120865,-1279.805908,-0.001457,0.003946,0.100235,289.672089,14.756599,1.002346,-1279.805908,294.500458,0
102.330002,65.09964,-1279.761475,-0.001483,0.003947,0.10026,289.577667,14.751789,1.002604,-1279.761475,294.500458,0
102.710007,65.087357,-1279.850464,-0.001466,0.003947,0.10026,289.52301,14.749006,1.002604,-1279.850464,294.500458,0
103.090004,64.970795,-1279.716919,-0.001466,0.003947,0.10026,289.004517,14.722592,1.002604,-1279.716919,294.500458,0
103.470001,64.965958,-1279.716919,-0.001457,0.003947,0.10026,288.983002,14.721497,1.002604,-1279.716919,294.500458,0
103.850006,64.964844,-1279.805908,-0.001479,0.003949,0.100295,288.978058,14.721244,1.002952,-1279.805908,294.500458,0
104.230003,64.848297,-1279.761475,-0.001449,0.003949,0.100295,288.459625,14.694834,1.002952,-1279.761475,294.500458,0
104.610008,64.848663,-1279.805908,-0.001457,0.003949,0.100304,288.461273,14.694917,1.003043,-1279.805908,294.500458,0
104.990005,65.648148,-1279.805908,-0.001466,0.00396,0.100581,292.017548,14.876082,1.005813,-1279.805908,294.500458,0
105.370003,65.732681,-1279.761475,-0.001462,0.003959,0.100556,292.393555,14.895238,1.005556,-1279.761475,294.500458,0
105.750008,65.68576,-1279.805908,-0.001457,0.003959,0.100556,292.184845,14.884606,1.005556,-1279.805908,294.500458,0
106.130005,65.653366,-1279.894897,-0.001462,0.003959,0.100556,292.040771,14.877266,1.005556,-1279.894897,294.500458,0
106.510002,65.607925,-1279.761475,-0.001444,0.003959,0.100556,291.838623,14.866968,1.005556,-1279.761475,294.500458,0
106.890007,65.560272,-1279.805908,-0.001453,0.003959,0.100556,291.626648,14.85617,1.005556,-1279.805908,294.500458,0
107.270004,65.54425,-1279.761475,-0.001453,0.003959,0.100556,291.555389,14.85254,1.005556,-1279.761475,294.500458,0
107.650002,65.472763,-1279.805908,-0.001453,0.003959,0.100556,291.237396,14.83634,1.005556,-1279.805908,294.500458,0
108.030006,65.421738,-1279.850464,-0.001453,0.003959,0.100556,291.010437,14.824779,1.005556,-1279.850464,294.500458,0
108.410004,65.345413,-1279.894897,-0.001453,0.003959,0.100556,290.670929,14.807483,1.005556,-1279.894897,294.500458,0
108.790009,65.294769,-1279.850464,-0.001462,0.003959,0.100556,290.445648,14.796006,1.005556,-1279.850464,294.500458,0
109.170006,65.257156,-1279.761475,-0.001449,0.003959,0.100565,290.27832,14.787483,1.005647,-1279.761475,294.500458,0
109.550003,65.21843,-1279.761475,-0.001462,0.003959,0.100565,290.106049,14.778708,1.005647,-1279.761475,294.500458,0
109.930008,65.156235,-1279.894897,-0.001449,0.003959,0.100565,289.829407,14.764614,1.005647,-1279.894897,294.500458,0
110.310005,65.080276,-1279.894897,-0.001444,0.003959,0.100565,289.491516,14.747402,1.005647,-1279.894897,294.500458,0
110.690002,65.043411,-1279.805908,-0.001466,0.003959,0.100565,289.327545,14.739048,1.005647,-1279.805908,294.500458,0
111.070007,64.990906,-1279.805908,-0.001449,0.003959,0.100565,289.093994,14.72715,1.005647,-1279.805908,294.500458,0
111.450005,64.942505,-1279.805908,-0.001453,0.003959,0.100565,288.878693,14.716182,1.005647,-1279.805908,294.500458,0
111.830002,64.894089,-1279.983887,-0.001453,0.003959,0.100565,288.66333,14.705211,1.005647,-1279.983887,294.500458,0
112.210007,64.838974,-1279.894897,-0.001449,0.003959,0.100565,288.418152,14.692721,1.005647,-1279.894897,294.500458,0
112.590004,64.795792,-1279.850464,-0.001466,0.003959,0.100565,288.226074,14.682936,1.005647,-1279.850464,294.500458,0
112.970009,65.641815,-1279.805908,-0.001436,0.003972,0.100893,291.98938,14.874647,1.008932,-1279.805908,294.500458,0
113.350006,65.774002,-1279.894897,-0.001449,0.003971,0.100867,292.577362,14.904602,1.008675,-1279.894897,294.500458,0
113.730003,65.787781,-1279.850464,-0.001462,0.003971,0.100867,292.638672,14.907723,1.008675,-1279.850464,294.500458,0
114.110008,65.777359,-1279.850464,-0.001466,0.003971,0.100867,292.592316,14.905362,1.008675,-1279.850464,294.500458,0
114.490005,65.757248,-1279.805908,-0.001449,0.003971,0.100867,292.502838,14.900805,1.008675,-1279.805908,294.500458,0
114.870003,65.679794,-1279.805908,-0.001427,0.003971,0.100867,292.158325,14.883254,1.008675,-1279.805908,294.500458,0
115.250008,65.631393,-1279.894897,-0.001444,0.003971,0.100867,291.943024,14.872286,1.008675,-1279.894897,294.500458,0
115.630005,65.588943,-1279.850464,-0.001466,0.003971,0.100867,291.754181,14.862667,1.008675,-1279.850464,294.500458,0
116.010002,65.563995,-1279.850464,-0.00144,0.003971,0.100867,291.643219,14.857014,1.008675,-1279.850464,294.500458,0
116.390007,65.52713,-1279.805908,-0.001444,0.003971,0.100867,291.479218,14.84866,1.008675,-1279.805908,294.500458,0
116.770004,65.492126,-1279.850464,-0.001457,0.003971,0.100867,291.323517,14.840728,1.008675,-1279.850464,294.500458,0
117.150009,65.439987,-1279.894897,-0.001462,0.003971,0.100867,291.091614,14.828914,1.008675,-1279.894897,294.500458,0
117.530006,65.374084,-1279.850464,-0.001444,0.003971,0.100867,290.798462,14.813979,1.008675,-1279.850464,294.500458,0
117.910004,65.331253,-1279.850464,-0.001462,0.003971,0.100867,290.607941,14.804274,1.008675,-1279.850464,294.500458,0
118.290009,65.298492,-1279.850464,-0.001444,0.003971,0.100867,290.462189,14.79685,1.008675,-1279.850464,294.500458,0
118.670006,65.263489,-1279.894897,-0.001444,0.003971,0.100867,290.306488,14.788918,1.008675,-1279.894897,294.500458,0
119.050003,65.235184,-1279.939331,-0.001462,0.003971,0.100867,290.180603,14.782503,1.008675,-1279.939331,294.500458,0
119.430008,65.205765,-1279.850464,-0.001444,0.003971,0.100867,290.049713,14.775837,1.008675,-1279.850464,294.500458,0
119.810005,65.139862,-1279.939331,-0.001449,0.003971,0.100867,289.756592,14.760904,1.008675,-1279.939331,294.500458,0
120.190002,65.09256,-1279.939331,-0.001444,0.003972,0.100877,289.546173,14.750185,1.008765,-1279.939331,294.500458,0
120.570007,65.057556,-1279.894897,-0.001449,0.003972,0.100877,289.390472,14.742252,1.008765,-1279.894897,294.500458,0
120.950005,65.025543,-1279.939331,-0.001444,0.003972,0.100877,289.248077,14.734999,1.008765,-1279.939331,294.500458,0
121.330009,64.997238,-1279.850464,-0.001449,0.003972,0.100877,289.122162,14.728585,1.008765,-1279.850464,294.500458,0
121.710007,64.97229,-1279.850464,-0.001466,0.003972,0.100877,289.011169,14.722932,1.008765,-1279.850464,294.500458,0
122.090004,64.933563,-1279.894897,-0.00144,0.003973,0.100902,288.838928,14.714156,1.009023,-1279.894897,294.500458,0
122.470009,64.913086,-1279.894897,-0.001427,0.003973,0.100902,288.747833,14.709516,1.009023,-1279.894897,294.500458,0
122.850006,64.862808,-1279.983887,-0.001453,0.003973,0.100902,288.52417,14.698122,1.009023,-1279.983887,294.500458,0
123.230003,64.828934,-1279.894897,-0.001457,0.003973,0.100902,288.373505,14.690447,1.009023,-1279.894897,294.500458,0
123.610008,64.805099,-1279.894897,-0.001457,0.003973,0.100902,288.267487,14.685045,1.009023,-1279.894897,294.500458,0
123.990005,64.78685,-1279.894897,-0.001457,0.003973,0.100911,288.18631,14.680909,1.009114,-1279.894897,294.500458,0
124.370003,65.147308,-1279.939331,-0.001453,0.00398,0.101084,289.789703,14.76259,1.010839,-1279.939331,294.500458,0
124.750008,65.279495,-1279.939331,-0.001453,0.00398,0.101084,290.377686,14.792545,1.010839,-1279.939331,294.500458,0
125.130005,65.286575,-1279.983887,-0.00144,0.003979,0.101076,290.40918,14.794149,1.010764,-1279.983887,294.500458,0
125.51001,65.292908,-1279.850464,-0.001449,0.003979,0.101076,290.437347,14.795585,1.010764,-1279.850464,294.500458,0
125.890007,65.278748,-1279.939331,-0.001457,0.003979,0.101076,290.374359,14.792376,1.010764,-1279.939331,294.500458,0
126.270004,65.25679,-1279.939331,-0.001444,0.003979,0.101076,290.276703,14.7874,1.010764,-1279.939331,294.500458,0
126.650009,65.246353,-1279.983887,-0.001449,0.003979,0.101076,290.230286,14.785034,1.010764,-1279.983887,294.500458,0
127.030006,65.222519,-1279.983887,-0.001457,0.003979,0.101076,290.124268,14.779634,1.010764,-1279.983887,294.500458,0
127.410004,65.174866,-1279.939331,-0.001453,0.003979,0.101076,289.912292,14.768836,1.010764,-1279.939331,294.500458,0
127.790009,65.151779,-1279.983887,-0.001462,0.003979,0.101076,289.809601,14.763604,1.010764,-1279.983887,294.500458,0
128.170013,65.12236,-1279.939331,-0.001449,0.003979,0.101076,289.678711,14.756938,1.010764,-1279.939331,294.500458,0
128.550003,65.084,-1279.983887,-0.001436,0.003979,0.101076,289.508087,14.748245,1.010764,-1279.983887,294.500458,0
128.930008,65.054962,-1279.894897,-0.001466,0.003979,0.101076,289.378937,14.741665,1.010764,-1279.894897,294.500458,0
129.310013,65.029266,-1279.983887,-0.001449,0.003979,0.101076,289.264618,14.735842,1.010764,-1279.983887,294.500458,0
129.690002,65.008041,-1279.939331,-0.001444,0.003979,0.101076,289.170197,14.731032,1.010764,-1279.939331,294.500458,0
130.070007,64.982346,-1279.983887,-0.001436,0.003979,0.101076,289.055908,14.725209,1.010764,-1279.983887,294.500458,0
130.450012,64.95665,-1279.939331,-0.00144,0.00398,0.101084,288.94162,14.719388,1.010839,-1279.939331,294.500458,0
130.830002,64.934677,-1279.939331,-0.001462,0.00398,0.101084,288.843872,14.714408,1.010839,-1279.939331,294.500458,0
131.210007,64.888885,-1279.894897,-0.00144,0.00398,0.101084,288.640167,14.704031,1.010839,-1279.894897,294.500458,0
131.590012,64.843445,-1279.894897,-0.001444,0.00398,0.101084,288.438049,14.693735,1.010839,-1279.894897,294.500458,0
131.970001,64.814026,-1279.939331,-0.00144,0.00398,0.101084,288.30719,14.687069,1.010839,-1279.939331,294.500458,0
132.350006,64.799133,-1279.894897,-0.001449,0.00398,0.101084,288.240936,14.683693,1.010839,-1279.894897,294.500458,0
132.730011,64.769348,-1279.850464,-0.001449,0.00398,0.101084,288.108459,14.676944,1.010839,-1279.850464,294.500458,0
133.110001,64.742157,-1279.939331,-0.001444,0.00398,0.101084,287.987488,14.670783,1.010839,-1279.939331,294.500458,0
133.490005,64.722061,-1279.894897,-0.001453,0.00398,0.101084,287.898102,14.666229,1.010839,-1279.894897,294.500458,0
133.87001,64.716843,-1279.983887,-0.001453,0.003971,0.100858,287.874908,14.665046,1.008584,-1279.983887,0.100972,0
134.25,64.575714,-1279.850464,-0.001436,0.003962,0.100625,287.247131,14.633066,1.006252,-1279.850464,0.100339,0
134.630005,64.640137,-1279.805908,-0.001418,0.003942,0.100139,287.533691,14.647664,1.001392,-1279.805908,0.099706,0
135.01001,64.520981,-1279.983887,-0.001431,0.00392,0.099567,287.003662,14.620664,0.99567,-1279.983887,0.099072,0
135.389999,64.481125,-1279.939331,-0.001436,0.0039,0.099072,286.826355,14.611631,0.990719,-1279.939331,0.098439,0
135.770004,64.425278,-1279.983887,-0.001436,0.003873,0.098379,286.577942,14.598977,0.983785,-1279.983887,0.097806,0
136.150009,64.381714,-1279.894897,-0.001431,0.003849,0.097771,286.384155,14.589105,0.977714,-1279.894897,0.097173,0
136.530014,64.323242,-1279.894897,-0.001423,0.003827,0.097217,286.124084,14.575855,0.972173,-1279.894897,0.096541,0
136.910004,64.303879,-1279.894897,-0.001431,0.003799,0.096506,286.037933,14.571467,0.965057,-1279.894897,0.095908,0
137.290009,64.202225,-1279.894897,-0.001423,0.003777,0.095933,285.585754,14.548432,0.959335,-1279.894897,0.095273,0
137.670013,64.02684,-1279.939331,-0.001436,0.003751,0.095282,284.805603,14.508689,0.952825,-1279.939331,0.094641,0
138.050003,63.613129,-1279.939331,-0.001427,0.00373,0.094754,282.965332,14.414941,0.947541,-1279.939331,0.094008,0
138.430008,62.929459,-1279.894897,-0.001427,0.00371,0.094233,279.924225,14.260019,0.942333,-1279.894897,0.093375,0
138.810013,61.622803,-1280.02832,-0.001423,0.003681,0.093505,274.111908,13.963926,0.935051,-1280.02832,0.092742,0
139.190002,60.671013,-1279.939331,-0.001414,0.003659,0.092933,269.878143,13.748248,0.929328,-1279.939331,0.092109,0
139.570007,58.873947,-1279.983887,-0.001423,0.003634,0.092308,261.884399,13.341026,0.923075,-1279.983887,0.091475,0
139.950012,57.082466,-1279.983887,-0.001418,0.003608,0.091649,253.915497,12.935072,0.91649,-1279.983887,0.090834,0
140.330002,55.670799,-1279.939331,-0.001423,0.00359,0.091181,247.636078,12.615183,0.911811,-1279.939331,0.0902,0
140.710007,53.295807,-1279.983887,-0.001423,0.003565,0.090539,237.071594,12.077003,0.905392,-1279.983887,0.089567,0
141.090012,50.883209,-1279.983887,-0.001423,0.003538,0.089872,226.339813,11.5303,0.898716,-1279.983887,0.088934,0
141.470001,47.922096,-1279.939331,-0.001423,0.003509,0.089134,213.168137,10.859302,0.891343,-1279.939331,0.088302,0
141.850006,46.575974,-1280.02832,-0.001418,0.003499,0.088874,207.180283,10.554266,0.888739,-1280.02832,0.087669,0
142.230011,43.613007,-1280.02832,-0.001427,0.003466,0.088032,194.000336,9.882849,0.880321,-1280.02832,0.087036,0
142.610001,40.458267,-1279.983887,-0.00144,0.003441,0.087408,179.967361,9.167974,0.874084,-1279.983887,0.086402,0
142.990005,38.213234,-1279.983887,-0.001427,0.00342,0.086862,169.980957,8.659243,0.868618,-1279.983887,0.085769,0
143.37001,35.238724,-1279.983887,-0.001431,0.003389,0.08609,156.749664,7.985209,0.860897,-1279.983887,0.085136,0
143.75,32.949005,-1279.939331,-0.001436,0.00337,0.085596,146.564499,7.466352,0.855962,-1279.939331,0.084503,0
144.130005,30.361015,-1279.983887,-0.001453,0.003348,0.085031,135.052536,6.879904,0.850314,-1279.983887,0.08387,0
144.51001,26.891991,-1280.02832,-0.00144,0.003314,0.084165,119.621552,6.093812,0.841655,-1280.02832,0.083237,0
144.889999,24.430984,-1279.983887,-0.001462,0.003292,0.08361,108.674446,5.53614,0.836098,-1279.983887,0.082605,0
145.270004,22.617157,-1279.939331,-0.001457,0.003274,0.083168,100.60614,5.125121,0.831678,-1279.939331,0.08197,0
145.650009,19.54248,-1279.983887,-0.001457,0.003244,0.082387,86.929298,4.428389,0.823866,-1279.983887,0.081337,0
146.030014,16.524025,-1279.983887,-0.001466,0.003219,0.081772,73.502533,3.744398,0.817719,-1279.983887,0.080705,0
146.410004,13.5942,-1279.983887,-0.001466,0.003191,0.08106,60.470024,3.08049,0.810603,-1279.983887,0.080072,0
146.790009,11.188675,-1279.939331,-0.001475,0.003169,0.080505,49.769711,2.53539,0.805047,-1279.939331,0.079439,0
147.170013,9.297768,-1279.983887,-0.001479,0.003148,0.079958,41.358536,2.106904,0.799582,-1279.983887,0.078806,0
147.550003,6.080093,-1280.02832,-0.001487,0.003121,0.079283,27.045607,1.377769,0.79283,-1280.02832,0.078172,0
147.930008,3.300705,-1280.02832,-0.001492,0.003094,0.07858,14.682269,0.74795,0.785805,-1280.02832,0.077539,0
148.310013,0.262894,-1279.983887,-0.001487,0.003063,0.07779,1.16941,0.059573,0.777902,-1279.983887,0.076906,0
148.690002,-1.866333,-1279.983887,-0.001479,0.003042,0.077278,-8.301864,-0.422917,0.772785,-1279.983887,0.076273,0
149.070007,-3.458595,-1280.02832,-0.001509,0.003021,0.076733,-15.3846,-0.783729,0.767334,-1280.02832,0.07564,0
149.450012,-0.049156,-1280.02832,-0.001565,0.002995,0.076073,-0.218658,-0.011139,0.760734,-1280.02832,0.075008,0
149.830002,0.009308,-1280.072754,-0.001604,0.00297,0.075441,0.041403,0.002109,0.754405,-1280.072754,0.074373,0
150.210007,0.043938,-1280.02832,-0.001617,0.00294,0.074668,0.195445,0.009956,0.746684,-1280.02832,0.07374,0
150.590012,-0.013405,-1279.983887,-0.001647,0.002917,0.074096,-0.059628,-0.003038,0.740961,-1279.983887,0.073108,0
150.970001,-0.002609,-1279.983887,-0.001656,0.002897,0.073575,-0.011607,-0.000591,0.735753,-1279.983887,0.072466,0
151.350006,0.002602,-1280.02832,-0.00169,0.002869,0.072882,0.011573,0.00059,0.728819,-1280.02832,0.071833,0
151.730011,0.016754,-1279.983887,-0.001738,0.002848,0.072328,0.074526,0.003797,0.723278,-1279.983887,0.0712,0
152.110001,-0.017128,-1279.983887,-0.001789,0.002816,0.071538,-0.076189,-0.003881,0.715375,-1279.983887,0.070567,0
152.490005,-0.002609,-1280.02832,-0.001789,0.00279,0.07087,-0.011607,-0.000591,0.708699,-1280.02832,0.069934,0
152.87001,-0.002609,-1280.02832,-0.001824,0.002774,0.070472,-0.011607,-0.000591,0.704717,-1280.02832,0.0693,0
153.25,-0.043198,-1279.983887,-0.00185,0.002742,0.069639,-0.192153,-0.009789,0.69639,-1279.983887,0.068667,0
153.630005,-0.030907,-1279.983887,-0.001854,0.002723,0.069153,-0.13748,-0.007004,0.691531,-1279.983887,0.068034,0
154.01001,-0.042076,-1280.02832,-0.001906,0.002697,0.068511,-0.187164,-0.009535,0.685111,-1280.02832,0.067401,0
154.390015,-0.024582,-1280.02832,-0.001923,0.002668,0.067757,-0.109346,-0.00557,0.677572,-1280.02832,0.066769,0
154.770004,-0.030533,-1280.02832,-0.001936,0.002647,0.067227,-0.135817,-0.006919,0.672273,-1280.02832,0.066136,0
155.150009,-0.032768,-1280.02832,-0.00197,0.002626,0.06669,-0.14576,-0.007425,0.666898,-1280.02832,0.065503,0
155.530014,-0.030907,-1280.02832,-0.002005,0.002598,0.065987,-0.13748,-0.007004,0.659874,-1280.02832,0.064869,0
155.910004,-0.042076,-1279.983887,-0.002031,0.002573,0.065355,-0.187164,-0.009535,0.653545,-1279.983887,0.064236,0
156.290009,-0.088623,-1280.072754,-0.002044,0.002544,0.064626,-0.394215,-0.020082,0.646263,-1280.072754,0.063603,0
156.670013,-0.097939,-1279.983887,-0.002078,0.00252,0.064019,-0.435652,-0.022193,0.640192,-1279.983887,0.06297,0
157.050003,-0.089371,-1280.02832,-0.0021,0.002495,0.063361,-0.397541,-0.020252,0.633607,-1280.02832,0.062337,0
157.430008,-0.081924,-1279.939331,-0.002121,0.002469,0.06271,-0.364418,-0.018564,0.627097,-1279.939331,0.061704,0
157.810013,-0.072617,-1279.983887,-0.002143,0.002449,0.062207,-0.323015,-0.016455,0.62207,-1279.983887,0.06107,0
158.190002,-0.106499,-1280.072754,-0.002169,0.00242,0.061461,-0.47373,-0.024133,0.614606,-1280.072754,0.060437,0
158.570007,-0.111343,-1280.02832,-0.002212,0.002395,0.060844,-0.49528,-0.025231,0.608445,-1280.02832,0.059804,0
158.950012,-0.096817,-1280.072754,-0.002225,0.002373,0.060265,-0.430664,-0.021939,0.602646,-1280.072754,0.059172,0
159.330002,-0.067032,-1279.939331,-0.002242,0.002353,0.05976,-0.298173,-0.01519,0.597605,-1279.939331,0.058539,0
159.710007,-0.082298,-1280.02832,-0.002276,0.002323,0.058997,-0.366081,-0.018649,0.589974,-1280.02832,0.057906,0
160.090012,-0.109848,-1280.02832,-0.002315,0.002295,0.058287,-0.488628,-0.024892,0.582874,-1280.02832,0.057272,0
160.470001,-0.12735,-1280.072754,-0.002341,0.002269,0.057627,-0.56648,-0.028858,0.576273,-1280.072754,0.056639,0
160.850006,-0.083786,-1279.983887,-0.002358,0.002251,0.057185,-0.372699,-0.018986,0.571852,-1279.983887,0.056006,0
161.230011,-0.099426,-1280.02832,-0.002384,0.002221,0.056413,-0.44227,-0.02253,0.564131,-1280.02832,0.055373,0
161.610001,-0.11097,-1280.072754,-0.002419,0.002195,0.055755,-0.493617,-0.025146,0.557545,-1280.072754,0.054731,0
161.990005,-0.0849,-1280.072754,-0.002453,0.002167,0.055052,-0.377654,-0.019239,0.550521,-1280.072754,0.054098,0
162.37001,-0.088257,-1280.072754,-0.002466,0.002141,0.054384,-0.392586,-0.019999,0.543844,-1280.072754,0.053465,0
162.750015,-0.093842,-1279.939331,-0.002492,0.002112,0.053638,-0.417428,-0.021265,0.53638,-1279.939331,0.052833,0
163.130005,-0.101662,-1279.983887,-0.002531,0.002093,0.053154,-0.452214,-0.023037,0.531536,-1279.983887,0.052198,0
163.51001,-0.10054,-1280.072754,-0.002552,0.002063,0.052398,-0.447225,-0.022783,0.523981,-1280.072754,0.051565,0
163.800003,-0.042076,-1280.072754,-0.002552,0.002055,0.052207,-0.187164,-0.009535,0.522073,-1280.072754,0.052103,0