File: Data/compression 36/Heating-15-36-reverse-1-1_11202024_164926(in).csv
Time (sec),S:Load (lbs),S:HL1 (DIM),S:LVDT (in),S:Position (in),Ch:Position (mm),Ch:Load (N),Ch:Stress (MPa),Ch:Strain (mm/mm),Ch:HL1 (DIM),Set Point (),Cycles ()
0.11,-0.057716,-1274.601685,-0.006316,-0.006269,-0.159231,-0.256735,-0.013079,-1.592305,-1274.601685,-0.159439,0
0.34,-0.070381,-1274.735107,-0.006299,-0.006269,-0.159231,-0.313071,-0.015949,-1.592305,-1274.735107,-0.159439,0
0.57,-0.02607,-1274.646118,-0.006299,-0.006207,-0.15767,-0.115964,-0.005907,-1.576696,-1274.646118,-0.156767,0
0.8,-0.053627,-1274.646118,-0.006282,-0.006073,-0.154253,-0.238545,-0.012152,-1.542526,-1274.646118,-0.152935,0
1.03,-0.070007,-1274.690674,-0.00617,-0.005936,-0.150784,-0.311408,-0.015864,-1.507842,-1274.690674,-0.149102,0
1.26,0.027557,-1274.735107,-0.006002,-0.005772,-0.146604,0.122581,0.006245,-1.466041,-1274.735107,-0.145269,0
1.49,0.004837,-1274.735107,-0.005851,-0.005619,-0.142719,0.021516,0.001096,-1.427193,-1274.735107,-0.141435,0
1.72,-0.002609,-1274.601685,-0.005691,-0.005465,-0.138807,-0.011607,-0.000591,-1.388072,-1274.601685,-0.137602,0
1.95,-0.002609,-1274.690674,-0.005549,-0.005324,-0.135227,-0.011607,-0.000591,-1.352267,-1274.690674,-0.133787,0
2.18,0.021599,-1274.646118,-0.005394,-0.00517,-0.131315,0.096076,0.004894,-1.313147,-1274.646118,-0.129954,0
2.41,0.002235,-1274.690674,-0.005243,-0.005021,-0.127525,0.009944,0.000507,-1.275252,-1274.690674,-0.12612,0
2.64,-0.015266,-1274.779541,-0.005079,-0.004867,-0.123622,-0.067908,-0.003459,-1.236222,-1274.779541,-0.122287,0
2.87,-0.025322,-1274.690674,-0.004945,-0.004726,-0.120049,-0.112638,-0.005738,-1.200493,-1274.690674,-0.118454,0
3.1,-0.097939,-1274.646118,-0.004769,-0.004572,-0.11613,-0.435652,-0.022193,-1.161297,-1274.646118,-0.11462,0
3.33,-0.047668,-1274.690674,-0.004609,-0.004416,-0.112175,-0.21204,-0.010802,-1.121752,-1274.690674,-0.110788,0
3.56,0.022713,-1274.690674,-0.004467,-0.004268,-0.108411,0.101031,0.005147,-1.084115,-1274.690674,-0.106955,0
3.79,0.040588,-1274.735107,-0.004312,-0.004112,-0.104439,0.180546,0.009197,-1.044389,-1274.735107,-0.103122,0
4.02,0.056229,-1274.646118,-0.004165,-0.003964,-0.100675,0.250117,0.012742,-1.006752,-1274.646118,-0.099288,0
4.25,0.010796,-1274.646118,-0.004018,-0.003817,-0.096964,0.048021,0.002446,-0.969645,-1274.646118,-0.095455,0
4.48,-0.022713,-1274.735107,-0.003854,-0.003668,-0.093166,-0.101031,-0.005147,-0.931659,-1274.735107,-0.091622,0
4.71,0.017502,-1274.690674,-0.003682,-0.00351,-0.089158,0.077852,0.003966,-0.891585,-1274.690674,-0.087788,0
4.94,0.004097,-1274.646118,-0.003535,-0.003356,-0.085239,0.018224,0.000928,-0.852389,-1274.646118,-0.083973,0
5.17,-0.027557,-1274.646118,-0.003385,-0.00321,-0.081536,-0.122581,-0.006245,-0.815357,-1274.646118,-0.08014,0
5.4,-0.035378,-1274.690674,-0.003229,-0.00305,-0.07746,-0.157367,-0.008017,-0.774601,-1274.690674,-0.076307,0
5.63,-0.003349,-1274.735107,-0.003074,-0.002911,-0.073939,-0.014898,-0.000759,-0.739387,-1274.735107,-0.072473,0
5.86,0.021965,-1274.646118,-0.002906,-0.002752,-0.069907,0.097705,0.004977,-0.69907,-1274.646118,-0.06864,0
6.09,0.067772,-1274.690674,-0.002755,-0.002607,-0.066213,0.301465,0.015357,-0.66213,-1274.690674,-0.064808,0
6.32,0.048782,-1274.646118,-0.002604,-0.002455,-0.062354,0.216995,0.011054,-0.623539,-1274.646118,-0.060975,0
6.55,0.032021,-1274.646118,-0.002449,-0.002306,-0.058581,0.142435,0.007256,-0.585811,-1274.646118,-0.057141,0
6.78,-0.008942,-1274.646118,-0.002302,-0.002154,-0.054713,-0.039774,-0.002026,-0.547129,-1274.646118,-0.053308,0
7.01,0.00074,-1274.690674,-0.002117,-0.001995,-0.050672,0.003292,0.000168,-0.506722,-1274.690674,-0.049475,0
7.24,-0.001862,-1274.735107,-0.001979,-0.001853,-0.047064,-0.008281,-0.000422,-0.470644,-1274.735107,-0.045641,0
7.47,0.038727,-1274.690674,-0.001824,-0.001701,-0.043196,0.172265,0.008776,-0.431962,-1274.690674,-0.041808,0
7.7,0.047661,-1274.646118,-0.001673,-0.00155,-0.039381,0.212006,0.0108,-0.393811,-1274.646118,-0.037993,0
7.93,0.032768,-1274.646118,-0.001531,-0.0014,-0.035564,0.14576,0.007425,-0.355644,-1274.646118,-0.034159,0
8.160001,0.057716,-1274.735107,-0.001341,-0.00124,-0.031505,0.256735,0.013079,-0.315055,-1274.735107,-0.030326,0
8.39,0.137405,-1274.735107,-0.001306,-0.000003,-0.000088,0.61121,0.031137,-0.000878,-1274.735107,0.000182,0
8.620001,0.141869,-1274.646118,-0.001293,-0.000003,-0.000088,0.631063,0.032148,-0.000878,-1274.646118,0.000182,0
8.85,0.114319,-1274.735107,-0.001315,-0.000003,-0.000088,0.508516,0.025905,-0.000878,-1274.735107,0.000338,0
9.080001,0.084152,-1274.690674,-0.001293,-0.000003,-0.000088,0.374328,0.019069,-0.000878,-1274.690674,0.000719,0
9.31,0.124741,-1274.690674,-0.001319,-0.000003,-0.000079,0.554874,0.028267,-0.000787,-1274.690674,0.001101,0
9.540001,0.124741,-1274.646118,-0.001293,0.000013,0.000329,0.554874,0.028267,0.003285,-1274.646118,0.001482,0
9.77,0.133682,-1274.646118,-0.001285,0.000029,0.000745,0.594648,0.030293,0.007449,-1274.646118,0.001864,0
10,0.130699,-1274.690674,-0.00125,0.000045,0.001154,0.581379,0.029617,0.011536,-1274.690674,0.002254,0
10.23,0.156395,-1274.735107,-0.001255,0.000059,0.001491,0.69568,0.03544,0.014912,-1274.735107,0.002636,0
10.46,0.119904,-1274.735107,-0.001224,0.000073,0.001847,0.533358,0.027171,0.01847,-1274.735107,0.003017,0
10.690001,0.131821,-1274.690674,-0.001224,0.00009,0.002298,0.586368,0.029871,0.022982,-1274.690674,0.003399,0
10.92,0.167564,-1274.690674,-0.001203,0.000106,0.002689,0.745364,0.037971,0.026888,-1274.690674,0.003789,0
11.150001,0.234596,-1274.735107,-0.001177,0.000124,0.003148,1.043536,0.05316,0.031475,-1274.735107,0.004171,0
11.38,0.253212,-1274.735107,-0.001155,0.000133,0.00339,1.126343,0.057379,0.033898,-1274.735107,0.004552,0
11.610001,0.273689,-1274.690674,-0.001155,0.000147,0.003738,1.217431,0.062019,0.03738,-1274.690674,0.004934,0
11.84,0.362686,-1274.735107,-0.001138,0.000167,0.00425,1.613309,0.082186,0.042497,-1274.735107,0.005316,0
12.070001,0.369019,-1274.646118,-0.001112,0.000172,0.004371,1.641477,0.083621,0.043708,-1274.646118,0.005706,0
12.3,0.441261,-1274.735107,-0.001108,0.000188,0.004787,1.962828,0.099991,0.047871,-1274.735107,0.006088,0
12.530001,0.623726,-1274.735107,-0.001087,0.000214,0.005437,2.774471,0.141338,0.054366,-1274.735107,0.006469,0
12.76,0.691864,-1274.690674,-0.001074,0.000224,0.005697,3.077565,0.156779,0.05697,-1274.690674,0.006851,0
12.990001,0.899277,-1274.735107,-0.001061,0.000242,0.006157,4.000183,0.203779,0.061573,-1274.735107,0.007232,0
13.22,1.145042,-1274.646118,-0.001039,0.00026,0.006608,5.093403,0.25947,0.066084,-1274.646118,0.007623,0
13.450001,1.31559,-1274.735107,-0.001035,0.000271,0.006885,5.852036,0.298117,0.068855,-1274.735107,0.008004,0
13.68,1.563217,-1274.779541,-0.000996,0.000284,0.007206,6.953537,0.35423,0.072064,-1274.779541,0.008386,0
13.910001,1.760574,-1274.690674,-0.001009,0.000296,0.007518,7.831426,0.398952,0.075183,-1274.690674,0.008767,0
14.14,2.23423,-1274.735107,-0.000974,0.000314,0.007986,9.938352,0.506284,0.079861,-1274.735107,0.009149,0
14.370001,2.799492,-1274.690674,-0.000966,0.000328,0.008342,12.452762,0.634374,0.083419,-1274.690674,0.009539,0
14.6,3.279114,-1274.735107,-0.000974,0.000342,0.008689,14.586226,0.743058,0.086886,-1274.735107,0.009921,0
14.830001,3.222137,-1274.735107,-0.000966,0.00035,0.008888,14.332783,0.730147,0.088884,-1274.735107,0.010302,0
15.06,4.093491,-1274.646118,-0.000974,0.000368,0.00934,18.208755,0.927598,0.093396,-1274.646118,0.010684,0
15.290001,5.275398,-1274.690674,-0.00094,0.000388,0.009851,23.466143,1.195422,0.098513,-1274.690674,0.011066,0
15.52,6.230537,-1274.735107,-0.00091,0.000402,0.010207,27.714815,1.41186,0.102071,-1274.735107,0.011456,0
15.750001,6.910484,-1274.779541,-0.000923,0.000411,0.010442,30.73937,1.565938,0.104418,-1274.779541,0.011838,0
15.98,8.677765,-1274.735107,-0.00091,0.000435,0.011056,38.600628,1.96641,0.110564,-1274.735107,0.012219,0
16.210001,9.193504,-1274.735107,-0.00091,0.000444,0.011273,40.894749,2.083278,0.112729,-1274.735107,0.012601,0
16.440001,10.784653,-1274.690674,-0.000888,0.000465,0.011819,47.97253,2.443837,0.118195,-1274.690674,0.012982,0
16.67,12.076408,-1274.735107,-0.000897,0.000481,0.012219,53.718548,2.736553,0.122192,-1274.735107,0.013373,0
16.900002,13.439667,-1274.735107,-0.000888,0.000499,0.012678,59.782623,3.045472,0.126779,-1274.735107,0.013754,0
17.130001,13.674263,-1274.779541,-0.000897,0.000501,0.012722,60.82616,3.098632,0.127218,-1274.779541,0.014136,0
17.360001,15.975151,-1274.735107,-0.00088,0.000528,0.013399,71.06102,3.620021,0.133985,-1274.735107,0.014517,0
17.59,17.350693,-1274.735107,-0.000875,0.000546,0.013866,77.179733,3.931723,0.138663,-1274.735107,0.014899,0
17.820002,18.414932,-1274.735107,-0.00088,0.000557,0.014136,81.913712,4.172883,0.141358,-1274.735107,0.015289,0
18.050001,19.683235,-1274.779541,-0.000875,0.000571,0.014508,87.555405,4.460285,0.145083,-1274.779541,0.015671,0
18.280001,21.36673,-1274.735107,-0.00088,0.00059,0.014994,95.043961,4.84177,0.149942,-1274.735107,0.016052,0
18.51,23.142578,-1274.646118,-0.000871,0.000609,0.015471,102.943329,5.244183,0.154711,-1274.646118,0.016434,0
18.740002,24.305122,-1274.690674,-0.000858,0.000621,0.015766,108.114586,5.507619,0.157664,-1274.690674,0.016816,0
18.970001,25.553314,-1274.690674,-0.000858,0.000633,0.016087,113.666817,5.790464,0.160873,-1274.690674,0.017206,0
19.200001,27.089348,-1274.779541,-0.000858,0.000651,0.016529,120.499435,6.138534,0.165294,-1274.779541,0.017588,0
19.43,28.633209,-1274.735107,-0.000854,0.000665,0.016902,127.366875,6.488378,0.169018,-1274.735107,0.017969,0
19.660002,29.52504,-1274.690674,-0.000845,0.000675,0.017136,131.333939,6.69047,0.171365,-1274.690674,0.018351,0
19.890001,30.278717,-1274.735107,-0.000858,0.000681,0.017302,134.686462,6.861256,0.173015,-1274.735107,0.01874,0
20.120001,32.096268,-1274.779541,-0.000854,0.000702,0.017821,142.771332,7.273118,0.178208,-1274.779541,0.019121,0
20.35,33.014915,-1274.779541,-0.000854,0.00071,0.018037,146.857681,7.481287,0.180373,-1274.779541,0.019503,0
20.580002,34.646652,-1274.735107,-0.000841,0.000729,0.018514,154.116013,7.851044,0.185142,-1274.735107,0.019886,0
20.810001,36.99781,-1274.690674,-0.000836,0.000753,0.019114,164.574478,8.383824,0.191137,-1274.690674,0.020267,0
21.040001,39.020164,-1274.735107,-0.000845,0.000773,0.019633,173.570358,8.842096,0.19633,-1274.735107,0.020656,0
21.27,40.384537,-1274.824097,-0.000832,0.000784,0.019919,179.639389,9.151267,0.199191,-1274.824097,0.021038,0
21.500002,41.168755,-1274.86853,-0.000845,0.000791,0.020102,183.127762,9.328973,0.201023,-1274.86853,0.021419,0
21.730001,42.635529,-1274.735107,-0.000836,0.000806,0.020475,189.652298,9.661349,0.204748,-1274.735107,0.021801,0
21.960001,44.219971,-1274.735107,-0.000836,0.000821,0.020847,196.700256,10.020389,0.208472,-1274.735107,0.022184,0
22.190001,45.323311,-1274.779541,-0.000828,0.000836,0.021229,201.608154,10.270409,0.212287,-1274.779541,0.022573,0
22.420002,47.211243,-1274.779541,-0.000828,0.000853,0.021672,210.006104,10.698221,0.216723,-1274.779541,0.022955,0
22.650002,47.661812,-1274.824097,-0.000819,0.000855,0.021724,212.01033,10.800322,0.217238,-1274.824097,0.023336,0
22.880001,50.896614,-1274.735107,-0.000828,0.000889,0.022573,226.399445,11.533338,0.225731,-1274.735107,0.023718,0
23.110001,52.747673,-1274.824097,-0.000836,0.000901,0.022894,234.633362,11.952793,0.228941,-1274.824097,0.024099,0
23.340002,53.851761,-1274.779541,-0.000824,0.000914,0.023224,239.544601,12.202983,0.232241,-1274.779541,0.02449,0
23.570002,55.251877,-1274.824097,-0.000836,0.000925,0.023492,245.772629,12.520254,0.234921,-1274.824097,0.024871,0
23.800001,58.154526,-1274.86853,-0.000828,0.000954,0.024238,258.684265,13.178004,0.242385,-1274.86853,0.025253,0
24.030001,59.651085,-1274.779541,-0.000824,0.00097,0.024638,265.341278,13.517129,0.246382,-1274.779541,0.025634,0
24.26,61.079506,-1274.735107,-0.000806,0.000981,0.024915,271.695221,13.840815,0.249152,-1274.735107,0.026016,0
24.490002,62.163857,-1274.779541,-0.000819,0.000989,0.025132,276.518646,14.086532,0.251317,-1274.779541,0.026406,0
24.720001,63.291397,-1274.824097,-0.000815,0.000999,0.025383,281.53421,14.342035,0.25383,-1274.824097,0.026788,0
24.950001,65.471268,-1274.824097,-0.000828,0.001019,0.025895,291.230743,14.836001,0.258947,-1274.824097,0.027169,0
25.18,66.266281,-1274.779541,-0.000789,0.001018,0.02586,294.767151,15.016153,0.258599,-1274.779541,0.026155,0
25.410002,66.231277,-1274.735107,-0.000811,0.001017,0.025843,294.61145,15.008222,0.258433,-1274.735107,294.427551,0
25.640001,66.149353,-1274.779541,-0.000811,0.001015,0.025774,294.247009,14.989657,0.257736,-1274.779541,294.500458,0
25.870001,66.081223,-1274.824097,-0.000806,0.001014,0.025765,293.94397,14.974219,0.257645,-1274.824097,294.500458,0
26.1,66.029083,-1274.824097,-0.000811,0.001014,0.025757,293.712036,14.962404,0.25757,-1274.824097,294.500458,0
26.330002,65.968018,-1274.824097,-0.000811,0.001014,0.025757,293.440399,14.948566,0.25757,-1274.824097,294.500458,0
26.560001,65.897263,-1274.824097,-0.000789,0.001014,0.025757,293.125671,14.932533,0.25757,-1274.824097,294.500458,0
26.790001,65.88237,-1274.824097,-0.000806,0.001014,0.025757,293.059418,14.929159,0.25757,-1274.824097,294.500458,0
27.02,65.83992,-1274.86853,-0.000811,0.001014,0.025757,292.870605,14.919539,0.25757,-1274.86853,294.500458,0
27.250002,65.833221,-1274.824097,-0.000811,0.001014,0.025757,292.84079,14.918021,0.25757,-1274.824097,294.500458,0
27.480001,65.782196,-1274.824097,-0.000802,0.001014,0.025757,292.613831,14.906458,0.25757,-1274.824097,294.500458,0
27.710001,65.757996,-1274.86853,-0.000798,0.001014,0.025757,292.506165,14.900975,0.25757,-1274.86853,294.500458,0
27.940001,65.738632,-1274.86853,-0.000802,0.001014,0.025757,292.420044,14.896587,0.25757,-1274.86853,294.500458,0
28.170002,65.666763,-1274.95752,-0.000793,0.001014,0.025757,292.100342,14.880301,0.25757,-1274.95752,294.500458,0
28.400002,65.633621,-1274.86853,-0.000798,0.001014,0.025757,291.952942,14.872791,0.25757,-1274.86853,294.500458,0
28.630001,65.60495,-1274.779541,-0.000802,0.001014,0.025757,291.825378,14.866295,0.25757,-1274.779541,294.500458,0
28.860001,65.588562,-1274.824097,-0.000798,0.001014,0.025757,291.752502,14.86258,0.25757,-1274.824097,294.500458,0
29.090002,65.562134,-1274.86853,-0.000785,0.001014,0.025757,291.634949,14.856592,0.25757,-1274.86853,294.500458,0
29.320002,65.54425,-1274.95752,-0.000811,0.001014,0.025757,291.555389,14.85254,0.25757,-1274.95752,294.500458,0
29.550001,65.52861,-1274.86853,-0.000806,0.001014,0.025757,291.485809,14.848995,0.25757,-1274.86853,294.500458,0
29.780001,65.503662,-1274.86853,-0.000793,0.001014,0.025757,291.374847,14.843342,0.25757,-1274.86853,294.500458,0
30.010002,65.477234,-1274.86853,-0.000798,0.001014,0.025757,291.257294,14.837354,0.25757,-1274.86853,294.500458,0
30.240002,65.451538,-1274.95752,-0.000806,0.001014,0.025757,291.142975,14.831531,0.25757,-1274.95752,294.500458,0
30.470001,65.412811,-1274.86853,-0.000802,0.001014,0.025757,290.970703,14.822755,0.25757,-1274.86853,294.500458,0
30.700001,65.378174,-1274.95752,-0.000798,0.001014,0.025757,290.81665,14.814906,0.25757,-1274.95752,294.500458,0
30.930002,65.363281,-1274.912964,-0.000806,0.001014,0.025757,290.750397,14.811532,0.25757,-1274.912964,294.500458,0
31.160002,65.329773,-1274.912964,-0.000806,0.001014,0.025757,290.601349,14.803939,0.25757,-1274.912964,294.500458,0
31.390001,65.321579,-1274.95752,-0.000798,0.001014,0.025757,290.56488,14.802081,0.25757,-1274.95752,294.500458,0
31.620001,65.307419,-1274.912964,-0.000819,0.001014,0.025757,290.501923,14.798873,0.25757,-1274.912964,294.500458,0
31.850002,65.289917,-1274.86853,-0.000819,0.001014,0.025757,290.424042,14.794907,0.25757,-1274.86853,294.500458,0
32.080002,65.284714,-1274.95752,-0.000793,0.001014,0.025757,290.400909,14.793728,0.25757,-1274.95752,294.500458,0
32.310001,65.263489,-1274.912964,-0.000793,0.001014,0.025757,290.306488,14.788918,0.25757,-1274.912964,294.500458,0
32.540001,65.249329,-1274.95752,-0.000811,0.001014,0.025757,290.2435,14.785709,0.25757,-1274.95752,294.500458,0
32.77,65.234436,-1275.046509,-0.000811,0.001014,0.025757,290.177277,14.782334,0.25757,-1275.046509,294.500458,0
33,65.22551,-1274.912964,-0.000793,0.001014,0.025757,290.137543,14.780312,0.25757,-1274.912964,294.500458,0
33.230003,65.198318,-1274.95752,-0.000789,0.001014,0.025757,290.016602,14.774151,0.25757,-1274.95752,294.500458,0
33.460003,65.187515,-1274.95752,-0.000806,0.001014,0.025757,289.968536,14.771702,0.25757,-1274.95752,294.500458,0
33.690002,65.15773,-1275.001953,-0.000806,0.001014,0.025757,289.83606,14.764953,0.25757,-1275.001953,294.500458,0
33.920002,65.145447,-1274.912964,-0.000811,0.001014,0.025757,289.781433,14.76217,0.25757,-1274.912964,294.500458,0
34.150002,65.126083,-1274.86853,-0.000793,0.001014,0.025757,289.695282,14.757781,0.25757,-1274.86853,294.500458,0
34.380001,65.10672,-1274.912964,-0.000798,0.001014,0.025757,289.609161,14.753393,0.25757,-1274.912964,294.500458,0
34.610001,65.101501,-1274.912964,-0.000798,0.001014,0.025757,289.585937,14.752212,0.25757,-1274.912964,294.500458,0
34.84,65.075058,-1274.95752,-0.000798,0.001014,0.025757,289.468323,14.746219,0.25757,-1274.95752,294.500458,0
35.070004,65.067245,-1274.95752,-0.000793,0.001014,0.025757,289.433563,14.744449,0.25757,-1274.95752,294.500458,0
35.300003,65.070602,-1274.912964,-0.000793,0.001014,0.025757,289.448486,14.74521,0.25757,-1274.912964,294.500458,0
35.530003,65.046387,-1274.912964,-0.000798,0.001014,0.025757,289.34079,14.739721,0.25757,-1274.912964,294.500458,0
35.760002,65.04155,-1275.001953,-0.000811,0.001014,0.025757,289.319275,14.738626,0.25757,-1275.001953,294.500458,0
35.990002,65.031876,-1275.001953,-0.000806,0.001014,0.025765,289.276245,14.736434,0.257645,-1275.001953,294.500458,0
36.220001,65.037827,-1274.912964,-0.000802,0.001014,0.025765,289.302704,14.737782,0.257645,-1274.912964,294.500458,0
36.450001,65.013626,-1274.912964,-0.000789,0.001014,0.025765,289.195038,14.732298,0.257645,-1274.912964,294.500458,0
36.68,65.019577,-1274.912964,-0.000789,0.001014,0.025765,289.221527,14.733647,0.257645,-1274.912964,294.500458,0
36.91,65.004684,-1275.001953,-0.000785,0.001014,0.025765,289.155273,14.730271,0.257645,-1275.001953,294.500458,0
37.140003,64.992401,-1275.001953,-0.000815,0.001014,0.025765,289.100647,14.727489,0.257645,-1275.001953,294.500458,0
37.370003,64.997986,-1275.001953,-0.000798,0.001014,0.025765,289.125488,14.728754,0.257645,-1275.001953,294.500458,0
37.600002,64.985703,-1274.912964,-0.000793,0.001014,0.025765,289.070831,14.72597,0.257645,-1274.912964,294.500458,0
37.830002,64.981232,-1274.912964,-0.000793,0.001014,0.025765,289.050964,14.724958,0.257645,-1274.912964,294.500458,0
38.060001,64.951431,-1275.001953,-0.000798,0.001014,0.025765,288.918396,14.718204,0.257645,-1275.001953,294.500458,0
38.290001,64.937286,-1275.001953,-0.000802,0.00102,0.025904,288.855469,14.714999,0.259038,-1275.001953,294.500458,0
38.52,65.557663,-1274.912964,-0.000811,0.001028,0.02612,291.615051,14.855579,0.261203,-1274.912964,294.500458,0
38.75,65.588196,-1274.912964,-0.00078,0.001028,0.02612,291.750854,14.862498,0.261203,-1274.912964,294.500458,0
38.980003,65.594894,-1275.001953,-0.000798,0.001028,0.02612,291.78067,14.864016,0.261203,-1275.001953,294.500458,0
39.210003,65.587814,-1275.046509,-0.000815,0.001028,0.026111,291.749176,14.862411,0.261112,-1275.046509,294.500458,0
39.440002,65.604202,-1274.95752,-0.000811,0.001028,0.026111,291.822052,14.866125,0.261112,-1274.95752,294.500458,0
39.670002,65.607559,-1275.001953,-0.000798,0.001028,0.026111,291.837006,14.866885,0.261112,-1275.001953,294.500458,0
39.900002,65.613892,-1274.95752,-0.000819,0.001028,0.026111,291.865173,14.86832,0.261112,-1274.95752,294.500458,0
40.130001,65.612396,-1275.001953,-0.000789,0.001028,0.026111,291.858521,14.867981,0.261112,-1275.001953,294.500458,0
40.360001,65.59639,-1274.95752,-0.000798,0.001028,0.026111,291.787323,14.864354,0.261112,-1274.95752,294.500458,0
40.59,65.605316,-1275.001953,-0.000815,0.001028,0.026111,291.827026,14.866377,0.261112,-1275.001953,294.500458,0
40.820004,65.609787,-1274.95752,-0.000785,0.001028,0.026111,291.846893,14.867391,0.261112,-1274.95752,294.500458,0
41.050003,65.597137,-1275.001953,-0.000798,0.001028,0.026111,291.790649,14.864524,0.261112,-1275.001953,294.500458,0
41.280003,65.603455,-1275.001953,-0.000798,0.001028,0.026111,291.818726,14.865955,0.261112,-1275.001953,294.500458,0
41.510002,65.592285,-1275.001953,-0.000798,0.001028,0.026111,291.769043,14.863424,0.261112,-1275.001953,294.500458,0
41.740002,65.605316,-1275.090942,-0.000811,0.001028,0.026111,291.827026,14.866377,0.261112,-1275.090942,294.500458,0
41.970001,65.600861,-1275.001953,-0.000793,0.001028,0.026111,291.80719,14.865368,0.261112,-1275.001953,294.500458,0
42.200001,65.594528,-1275.001953,-0.000793,0.001028,0.026111,291.779022,14.863933,0.261112,-1275.001953,294.500458,0
42.43,65.594528,-1275.046509,-0.000798,0.001028,0.026111,291.779022,14.863933,0.261112,-1275.046509,294.500458,0
42.660004,65.588196,-1275.046509,-0.000806,0.001028,0.026111,291.750854,14.862498,0.261112,-1275.046509,294.500458,0
42.890003,65.600479,-1275.046509,-0.000785,0.001028,0.026111,291.805511,14.865281,0.261112,-1275.046509,294.500458,0
43.120003,65.583359,-1274.95752,-0.000785,0.001028,0.026111,291.72934,14.861402,0.261112,-1274.95752,294.500458,0
43.350002,65.577026,-1275.001953,-0.000789,0.001028,0.026111,291.701172,14.859967,0.261112,-1275.001953,294.500458,0
43.580002,65.583359,-1275.046509,-0.000811,0.001028,0.026111,291.72934,14.861402,0.261112,-1275.046509,294.500458,0
43.810001,65.56958,-1275.001953,-0.000802,0.001028,0.026111,291.66806,14.858279,0.261112,-1275.001953,294.500458,0
44.040001,65.580368,-1275.046509,-0.000789,0.001028,0.026111,291.716034,14.860724,0.261112,-1275.046509,294.500458,0
44.27,65.563614,-1275.046509,-0.000793,0.001028,0.026111,291.64151,14.856928,0.261112,-1275.046509,294.500458,0
44.500004,65.551331,-1275.046509,-0.000793,0.001028,0.026111,291.586884,14.854144,0.261112,-1275.046509,294.500458,0
44.730003,65.556168,-1275.090942,-0.000798,0.001028,0.026111,291.608398,14.85524,0.261112,-1275.090942,294.500458,0
44.960003,65.546494,-1275.046509,-0.000806,0.001028,0.026111,291.565369,14.853048,0.261112,-1275.046509,294.500458,0
45.190002,65.55394,-1275.001953,-0.000806,0.001028,0.026111,291.59848,14.854734,0.261112,-1275.001953,294.500458,0
45.420002,65.556549,-1275.001953,-0.000789,0.001028,0.026111,291.610107,14.855327,0.261112,-1275.001953,294.500458,0
45.650002,65.540527,-1275.046509,-0.000802,0.001028,0.026111,291.538818,14.851695,0.261112,-1275.046509,294.500458,0
45.880001,65.53569,-1275.001953,-0.00078,0.001028,0.026111,291.517303,14.850599,0.261112,-1275.001953,294.500458,0
46.110001,65.52713,-1275.046509,-0.000806,0.001028,0.026111,291.479218,14.84866,0.261112,-1275.046509,294.500458,0
46.340004,65.52713,-1274.95752,-0.000793,0.001028,0.026111,291.479218,14.84866,0.261112,-1274.95752,294.500458,0
46.570004,65.518555,-1275.046509,-0.000811,0.001028,0.026111,291.441101,14.846717,0.261112,-1275.046509,294.500458,0
46.800003,65.511108,-1275.046509,-0.000798,0.001028,0.026111,291.407959,14.845029,0.261112,-1275.046509,294.500458,0
47.030003,65.511856,-1275.001953,-0.000785,0.001028,0.026111,291.411285,14.845199,0.261112,-1275.001953,294.500458,0
47.260002,65.498077,-1275.001953,-0.000806,0.001028,0.026111,291.350006,14.842077,0.261112,-1275.001953,294.500458,0
47.490002,65.490631,-1275.001953,-0.000806,0.001028,0.026111,291.316864,14.840389,0.261112,-1275.001953,294.500458,0
47.720001,65.501434,-1275.046509,-0.000789,0.001028,0.026111,291.364929,14.842837,0.261112,-1275.046509,294.500458,0
47.950001,65.479828,-1275.046509,-0.000789,0.001028,0.026111,291.268829,14.837941,0.261112,-1275.046509,294.500458,0
48.180004,65.482819,-1275.001953,-0.000789,0.001028,0.026111,291.282135,14.838619,0.261112,-1275.001953,294.500458,0
48.410004,65.474991,-1275.135376,-0.000811,0.001028,0.026111,291.247314,14.836845,0.261112,-1275.135376,294.500458,0
48.640003,65.472382,-1275.001953,-0.000793,0.001028,0.026111,291.235687,14.836254,0.261112,-1275.001953,294.500458,0
48.870003,65.48468,-1275.090942,-0.000789,0.001028,0.026111,291.290405,14.839041,0.261112,-1275.090942,294.500458,0
49.100002,65.463074,-1275.090942,-0.000798,0.001028,0.026111,291.194305,14.834145,0.261112,-1275.090942,294.500458,0
49.330002,65.463074,-1275.001953,-0.000802,0.001028,0.026111,291.194305,14.834145,0.261112,-1275.001953,294.500458,0
49.560001,65.44632,-1275.090942,-0.000789,0.001028,0.026111,291.119781,14.830348,0.261112,-1275.090942,294.500458,0
49.790001,65.44223,-1275.001953,-0.000793,0.001028,0.026111,291.101593,14.829421,0.261112,-1275.001953,294.500458,0
50.020004,65.436646,-1275.046509,-0.000789,0.001028,0.026111,291.076752,14.828156,0.261112,-1275.046509,294.500458,0
50.250004,65.414291,-1275.090942,-0.000793,0.001028,0.026111,290.977295,14.823091,0.261112,-1275.090942,294.500458,0
50.480003,65.420258,-1275.135376,-0.000802,0.001028,0.026111,291.003845,14.824442,0.261112,-1275.135376,294.500458,0
50.710003,65.41095,-1275.001953,-0.000802,0.001028,0.026111,290.962433,14.822333,0.261112,-1275.001953,294.500458,0
50.940002,65.399033,-1275.001953,-0.000798,0.001028,0.026111,290.909424,14.819633,0.261112,-1275.001953,294.500458,0
51.170002,65.407959,-1275.046509,-0.000789,0.001028,0.026111,290.949127,14.821655,0.261112,-1275.046509,294.500458,0
51.400002,65.384506,-1275.046509,-0.000793,0.001028,0.026111,290.844818,14.81634,0.261112,-1275.046509,294.500458,0
51.630001,65.387863,-1275.090942,-0.000798,0.001028,0.026111,290.859741,14.817101,0.261112,-1275.090942,294.500458,0
51.860001,65.381531,-1275.135376,-0.000798,0.001028,0.026111,290.831573,14.815667,0.261112,-1275.135376,294.500458,0
52.090004,65.376312,-1275.046509,-0.000793,0.001028,0.026111,290.80835,14.814484,0.261112,-1275.046509,294.500458,0
52.320004,65.377808,-1275.046509,-0.000785,0.001028,0.026111,290.815002,14.814822,0.261112,-1275.046509,294.500458,0
52.550003,65.369232,-1275.090942,-0.000785,0.001028,0.026111,290.776855,14.81288,0.261112,-1275.090942,294.500458,0
52.780003,65.360306,-1275.001953,-0.000793,0.001028,0.026111,290.737152,14.810857,0.261112,-1275.001953,294.500458,0
53.010002,65.359924,-1275.135376,-0.000802,0.001028,0.026111,290.735474,14.810771,0.261112,-1275.135376,294.500458,0
53.240002,65.359192,-1275.001953,-0.000785,0.001028,0.026111,290.732208,14.810605,0.261112,-1275.001953,294.500458,0
53.470001,65.355469,-1275.090942,-0.000793,0.001028,0.026111,290.715637,14.809761,0.261112,-1275.090942,294.500458,0
53.700001,65.35434,-1275.090942,-0.000793,0.001028,0.026111,290.710632,14.809505,0.261112,-1275.090942,294.500458,0
53.930004,65.362167,-1275.090942,-0.000806,0.001028,0.026111,290.745453,14.811279,0.261112,-1275.090942,294.500458,0
54.160004,65.347641,-1275.090942,-0.000806,0.001028,0.026111,290.680817,14.807987,0.261112,-1275.090942,294.500458,0
54.390003,65.346527,-1275.090942,-0.000793,0.001028,0.026111,290.675873,14.807735,0.261112,-1275.090942,294.500458,0
54.620003,65.352859,-1275.046509,-0.000802,0.001028,0.026111,290.704041,14.80917,0.261112,-1275.046509,294.500458,0
54.850002,65.336838,-1275.179932,-0.000806,0.001028,0.026111,290.632782,14.805539,0.261112,-1275.179932,294.500458,0
55.080002,65.331635,-1275.179932,-0.000819,0.001028,0.026111,290.609619,14.804359,0.261112,-1275.179932,294.500458,0
55.310001,65.335724,-1275.090942,-0.000806,0.001028,0.026111,290.627808,14.805286,0.261112,-1275.090942,294.500458,0
55.540001,65.328278,-1275.046509,-0.000802,0.001028,0.026111,290.594696,14.803599,0.261112,-1275.046509,294.500458,0
55.770004,65.323441,-1275.046509,-0.000811,0.001028,0.026111,290.573181,14.802504,0.261112,-1275.046509,294.500458,0
56.000004,65.307419,-1275.224365,-0.000806,0.001028,0.026111,290.501923,14.798873,0.261112,-1275.224365,294.500458,0
56.230003,65.323807,-1275.135376,-0.000802,0.001028,0.026111,290.574799,14.802586,0.261112,-1275.135376,294.500458,0
56.460003,65.302963,-1275.090942,-0.000802,0.001028,0.026111,290.482086,14.797863,0.261112,-1275.090942,294.500458,0
56.690002,65.305191,-1275.090942,-0.000802,0.001028,0.026111,290.492004,14.798368,0.261112,-1275.090942,294.500458,0
56.920002,65.292908,-1275.179932,-0.000785,0.001028,0.026111,290.437347,14.795585,0.261112,-1275.179932,294.500458,0
57.150002,65.304443,-1275.135376,-0.000793,0.001028,0.02612,290.488678,14.798199,0.261203,-1275.135376,294.500458,0
57.380001,65.308548,-1275.135376,-0.000798,0.001028,0.02612,290.506927,14.799129,0.261203,-1275.135376,294.500458,0
57.610004,65.297745,-1275.090942,-0.000802,0.001028,0.02612,290.458862,14.79668,0.261203,-1275.090942,294.500458,0
57.840004,65.304825,-1275.046509,-0.000789,0.001028,0.02612,290.490356,14.798285,0.261203,-1275.046509,294.500458,0
58.070004,65.288055,-1275.135376,-0.000798,0.001028,0.02612,290.415771,14.794485,0.261203,-1275.135376,294.500458,0
58.300003,65.298111,-1275.179932,-0.000793,0.001028,0.02612,290.46051,14.796764,0.261203,-1275.179932,294.500458,0
58.530003,65.290665,-1275.135376,-0.000793,0.001028,0.02612,290.427368,14.795076,0.261203,-1275.135376,294.500458,0
58.760002,65.291046,-1275.135376,-0.000789,0.001028,0.02612,290.429077,14.795162,0.261203,-1275.135376,294.500458,0
58.990002,65.299606,-1275.090942,-0.000789,0.001028,0.02612,290.467163,14.797102,0.261203,-1275.090942,294.500458,0
59.220001,65.272797,-1275.135376,-0.000798,0.001028,0.02612,290.3479,14.791027,0.261203,-1275.135376,294.500458,0
59.450005,65.280991,-1275.135376,-0.000793,0.001028,0.02612,290.384338,14.792884,0.261203,-1275.135376,294.500458,0
59.680004,65.276886,-1275.179932,-0.000793,0.001028,0.02612,290.366089,14.791954,0.261203,-1275.179932,294.500458,0
59.910004,65.272797,-1275.046509,-0.000802,0.001028,0.02612,290.3479,14.791027,0.261203,-1275.046509,294.500458,0
60.140003,65.285461,-1275.090942,-0.000802,0.001028,0.02612,290.404236,14.793897,0.261203,-1275.090942,294.500458,0
60.370003,65.270187,-1275.179932,-0.000785,0.001028,0.02612,290.336304,14.790436,0.261203,-1275.179932,294.500458,0
60.600002,65.262741,-1275.179932,-0.000793,0.001028,0.02612,290.303162,14.788749,0.261203,-1275.179932,294.500458,0
60.830002,65.267578,-1275.090942,-0.000802,0.001028,0.02612,290.324677,14.789845,0.261203,-1275.090942,294.500458,0
61.060001,65.256042,-1275.090942,-0.000785,0.001028,0.02612,290.273376,14.78723,0.261203,-1275.090942,294.500458,0
61.290005,65.254913,-1275.046509,-0.000806,0.001028,0.02612,290.268341,14.786975,0.261203,-1275.046509,294.500458,0
61.520004,65.237427,-1275.135376,-0.000793,0.001028,0.02612,290.190582,14.783012,0.261203,-1275.135376,294.500458,0
61.750004,65.233688,-1275.179932,-0.000806,0.001029,0.026129,290.17395,14.782165,0.261294,-1275.179932,294.500458,0
61.980003,65.239655,-1275.135376,-0.000793,0.001029,0.026129,290.20047,14.783518,0.261294,-1275.135376,294.500458,0
62.210003,65.229233,-1275.090942,-0.000802,0.001029,0.026129,290.154114,14.781156,0.261294,-1275.090942,294.500458,0
62.440002,65.244125,-1275.090942,-0.000798,0.001029,0.026129,290.220367,14.78453,0.261294,-1275.090942,294.500458,0
62.670002,65.229599,-1275.224365,-0.000802,0.001029,0.026129,290.155762,14.781239,0.261294,-1275.224365,294.500458,0
62.900002,65.214706,-1275.224365,-0.000802,0.001029,0.026129,290.089508,14.777864,0.261294,-1275.224365,294.500458,0
63.130005,65.219543,-1275.179932,-0.000802,0.001029,0.026129,290.111023,14.77896,0.261294,-1275.179932,294.500458,0
63.360004,65.219177,-1275.179932,-0.000789,0.001029,0.026129,290.109375,14.778876,0.261294,-1275.179932,294.500458,0
63.590004,65.218063,-1275.046509,-0.000819,0.001029,0.026129,290.104431,14.778625,0.261294,-1275.046509,294.500458,0
63.820004,65.210236,-1275.179932,-0.000802,0.001029,0.026129,290.069611,14.776851,0.261294,-1275.179932,294.500458,0
64.050003,65.214706,-1275.224365,-0.000789,0.001029,0.026129,290.089508,14.777864,0.261294,-1275.224365,294.500458,0
64.280006,65.201675,-1275.090942,-0.000793,0.001029,0.026129,290.031525,14.774911,0.261294,-1275.090942,294.500458,0
64.510002,65.209488,-1275.090942,-0.000802,0.001029,0.026129,290.066284,14.776682,0.261294,-1275.090942,294.500458,0
64.740005,65.199814,-1275.135376,-0.000785,0.001029,0.026129,290.023254,14.774489,0.261294,-1275.135376,294.500458,0
64.970001,65.194595,-1275.135376,-0.000793,0.001029,0.026129,290.000031,14.773306,0.261294,-1275.135376,294.500458,0
65.200005,65.197571,-1275.135376,-0.000793,0.001029,0.026129,290.013275,14.773981,0.261294,-1275.135376,294.500458,0
65.43,65.190506,-1275.090942,-0.000789,0.001029,0.026129,289.981842,14.77238,0.261294,-1275.090942,294.500458,0
65.660004,65.187515,-1275.046509,-0.000789,0.001029,0.026129,289.968536,14.771702,0.261294,-1275.046509,294.500458,0
65.889999,65.198318,-1275.090942,-0.000789,0.001029,0.026129,290.016602,14.774151,0.261294,-1275.090942,294.500458,0
66.120003,65.171143,-1275.179932,-0.000793,0.001029,0.026129,289.895721,14.767992,0.261294,-1275.179932,294.500458,0
66.350006,65.184174,-1275.179932,-0.000819,0.001029,0.026129,289.953674,14.770945,0.261294,-1275.179932,294.500458,0
66.580002,65.186401,-1275.090942,-0.000806,0.001029,0.026129,289.963593,14.77145,0.261294,-1275.090942,294.500458,0
66.810005,65.173004,-1275.135376,-0.000793,0.001029,0.026129,289.903992,14.768414,0.261294,-1275.135376,294.500458,0
67.040001,65.177475,-1275.135376,-0.000789,0.001029,0.026129,289.923889,14.769426,0.261294,-1275.135376,294.500458,0
67.270004,65.174484,-1275.135376,-0.000785,0.001029,0.026129,289.910583,14.768749,0.261294,-1275.135376,294.500458,0
67.5,65.168533,-1275.224365,-0.000785,0.001029,0.026129,289.884125,14.767401,0.261294,-1275.224365,294.500458,0
67.730003,65.163696,-1275.179932,-0.000811,0.001029,0.026129,289.86261,14.766305,0.261294,-1275.179932,294.500458,0
67.960007,65.153259,-1275.046509,-0.000798,0.001029,0.026129,289.816162,14.76394,0.261294,-1275.046509,294.500458,0
68.190002,65.156982,-1275.224365,-0.000793,0.001029,0.026129,289.832733,14.764783,0.261294,-1275.224365,294.500458,0
68.420006,65.152893,-1275.179932,-0.000785,0.001029,0.026129,289.814545,14.763856,0.261294,-1275.179932,294.500458,0
68.650002,65.145447,-1275.224365,-0.000798,0.001029,0.026129,289.781433,14.76217,0.261294,-1275.224365,294.500458,0
68.880005,65.147308,-1275.090942,-0.000811,0.001029,0.026129,289.789703,14.76259,0.261294,-1275.090942,294.500458,0
69.110001,65.150284,-1275.179932,-0.000793,0.001029,0.026129,289.802948,14.763266,0.261294,-1275.179932,294.500458,0
69.340004,65.149918,-1275.179932,-0.00078,0.001029,0.026129,289.8013,14.763183,0.261294,-1275.179932,294.500458,0
69.57,65.127563,-1275.224365,-0.000802,0.001029,0.026129,289.701874,14.758117,0.261294,-1275.224365,294.500458,0
69.800003,65.133148,-1275.268921,-0.000785,0.001029,0.026129,289.726715,14.759382,0.261294,-1275.268921,294.500458,0
70.030006,65.129425,-1275.135376,-0.000793,0.001029,0.026129,289.710144,14.758538,0.261294,-1275.135376,294.500458,0
70.260002,65.13092,-1275.135376,-0.000789,0.001029,0.026129,289.716797,14.758878,0.261294,-1275.135376,294.500458,0
70.490005,65.132034,-1275.179932,-0.000802,0.001029,0.026129,289.721771,14.75913,0.261294,-1275.179932,294.500458,0
70.720001,65.118256,-1275.224365,-0.000802,0.001029,0.026129,289.660461,14.756007,0.261294,-1275.224365,294.500458,0
70.950005,65.13353,-1275.268921,-0.000793,0.001029,0.026138,289.728424,14.759469,0.261385,-1275.268921,294.500458,0
71.18,65.132034,-1275.179932,-0.000793,0.001029,0.026138,289.721771,14.75913,0.261385,-1275.179932,294.500458,0
71.410004,65.118637,-1275.224365,-0.000789,0.001029,0.026138,289.66217,14.756094,0.261385,-1275.224365,294.500458,0
71.640007,65.113419,-1275.268921,-0.000793,0.001029,0.026138,289.638947,14.754911,0.261385,-1275.268921,294.500458,0
71.870003,65.114166,-1275.224365,-0.000789,0.001029,0.026138,289.642273,14.755081,0.261385,-1275.224365,294.500458,0
72.100006,65.111191,-1275.224365,-0.000798,0.001029,0.026138,289.629028,14.754407,0.261385,-1275.224365,294.500458,0
72.330002,65.117508,-1275.179932,-0.000798,0.001029,0.026138,289.657135,14.755838,0.261385,-1275.179932,294.500458,0
72.560005,65.111191,-1275.179932,-0.000793,0.001029,0.026138,289.629028,14.754407,0.261385,-1275.179932,294.500458,0
72.790001,65.108582,-1275.313354,-0.000789,0.001029,0.026138,289.617432,14.753816,0.261385,-1275.313354,294.500458,0
73.020004,65.110443,-1275.224365,-0.000793,0.001029,0.026138,289.625702,14.754238,0.261385,-1275.224365,294.500458,0
73.25,65.089218,-1275.224365,-0.000789,0.001029,0.026138,289.531311,14.749428,0.261385,-1275.224365,294.500458,0
73.480003,65.096664,-1275.224365,-0.000789,0.001029,0.026138,289.564423,14.751115,0.261385,-1275.224365,294.500458,0
73.710007,65.090332,-1275.224365,-0.000793,0.001029,0.026138,289.536255,14.749681,0.261385,-1275.224365,294.500458,0
73.940002,65.084747,-1275.224365,-0.000798,0.001029,0.026138,289.511414,14.748415,0.261385,-1275.224365,294.500458,0
74.170006,65.082886,-1275.313354,-0.000785,0.001029,0.026138,289.503143,14.747993,0.261385,-1275.313354,294.500458,0
74.400002,65.072464,-1275.268921,-0.000819,0.001029,0.026138,289.456787,14.745631,0.261385,-1275.268921,294.500458,0
74.630005,65.075806,-1275.224365,-0.00078,0.001029,0.026138,289.471649,14.746388,0.261385,-1275.224365,294.500458,0
74.860001,65.059433,-1275.268921,-0.000785,0.001029,0.026138,289.398804,14.742678,0.261385,-1275.268921,294.500458,0
75.090004,65.058304,-1275.268921,-0.000798,0.001029,0.026138,289.393799,14.742422,0.261385,-1275.268921,294.500458,0
75.320007,65.058685,-1275.268921,-0.000785,0.001029,0.026138,289.395477,14.742508,0.261385,-1275.268921,294.500458,0
75.550003,65.04863,-1275.268921,-0.000785,0.001029,0.026138,289.350769,14.74023,0.261385,-1275.268921,294.500458,0
75.780006,65.067612,-1275.179932,-0.000785,0.001029,0.026138,289.435181,14.744532,0.261385,-1275.179932,294.500458,0
76.010002,65.044159,-1275.224365,-0.000789,0.001029,0.026138,289.330872,14.739217,0.261385,-1275.224365,294.500458,0
76.240005,65.051239,-1275.357788,-0.000785,0.001029,0.026138,289.362366,14.740822,0.261385,-1275.357788,294.500458,0
76.470001,65.05719,-1275.268921,-0.000806,0.001029,0.026138,289.388824,14.74217,0.261385,-1275.268921,294.500458,0
76.700005,65.043793,-1275.224365,-0.000806,0.00103,0.026172,289.329254,14.739134,0.261718,-1275.224365,294.500458,0
76.93,65.058304,-1275.224365,-0.000798,0.00103,0.026172,289.393799,14.742422,0.261718,-1275.224365,294.500458,0
77.160004,65.069473,-1275.268921,-0.000802,0.00103,0.026172,289.443481,14.744953,0.261718,-1275.268921,294.500458,0
77.390007,65.050491,-1275.268921,-0.000798,0.00103,0.026172,289.359039,14.740652,0.261718,-1275.268921,294.500458,0
77.620003,65.046021,-1275.268921,-0.000811,0.00103,0.026172,289.339142,14.739638,0.261718,-1275.268921,294.500458,0
77.850006,65.06575,-1275.224365,-0.000798,0.00103,0.026172,289.42691,14.74411,0.261718,-1275.224365,294.500458,0
78.080002,65.054962,-1275.224365,-0.000785,0.00103,0.026172,289.378937,14.741665,0.261718,-1275.224365,294.500458,0
78.310005,65.052353,-1275.268921,-0.000793,0.00103,0.026172,289.36731,14.741074,0.261718,-1275.268921,294.500458,0
78.540001,65.045654,-1275.268921,-0.000785,0.00103,0.026172,289.337524,14.739556,0.261718,-1275.268921,294.500458,0
78.770004,65.054214,-1275.313354,-0.000789,0.00103,0.026172,289.37561,14.741495,0.261718,-1275.313354,294.500458,0
79,65.055695,-1275.268921,-0.000789,0.00103,0.026172,289.382172,14.741832,0.261718,-1275.268921,294.500458,0
79.230003,65.044907,-1275.268921,-0.000802,0.00103,0.026172,289.334198,14.739387,0.261718,-1275.268921,294.500458,0
79.460007,65.049377,-1275.268921,-0.000802,0.00103,0.026172,289.354095,14.740399,0.261718,-1275.268921,294.500458,0
79.690002,65.034851,-1275.313354,-0.000811,0.00103,0.026172,289.289459,14.737107,0.261718,-1275.313354,294.500458,0
79.920006,65.043411,-1275.357788,-0.000798,0.00103,0.026172,289.327545,14.739048,0.261718,-1275.357788,294.500458,0
80.150002,65.04007,-1275.313354,-0.000802,0.00103,0.026172,289.312683,14.738291,0.261718,-1275.313354,294.500458,0
80.380005,65.041931,-1275.268921,-0.000785,0.00103,0.026172,289.320953,14.738712,0.261718,-1275.268921,294.500458,0
80.610001,65.031494,-1275.313354,-0.000802,0.00103,0.026172,289.274536,14.736347,0.261718,-1275.313354,294.500458,0
80.840004,65.024429,-1275.313354,-0.000815,0.00103,0.026172,289.243103,14.734746,0.261718,-1275.313354,294.500458,0
81.070007,65.0233,-1275.313354,-0.000802,0.00103,0.026172,289.238098,14.73449,0.261718,-1275.313354,294.500458,0
81.300003,65.024429,-1275.224365,-0.000806,0.00103,0.026172,289.243103,14.734746,0.261718,-1275.224365,294.500458,0
81.530006,65.016235,-1275.268921,-0.000785,0.00103,0.026172,289.206665,14.73289,0.261718,-1275.268921,294.500458,0
81.760002,65.015106,-1275.268921,-0.000798,0.001031,0.026181,289.20163,14.732634,0.261809,-1275.268921,294.500458,0
81.990005,65.011017,-1275.357788,-0.000798,0.001031,0.026181,289.183441,14.731707,0.261809,-1275.357788,294.500458,0
82.220001,65.008041,-1275.268921,-0.000802,0.001031,0.026181,289.170197,14.731032,0.261809,-1275.268921,294.500458,0
82.450005,65.004684,-1275.268921,-0.000789,0.001031,0.026181,289.155273,14.730271,0.261809,-1275.268921,294.500458,0
82.68,65.006546,-1275.268921,-0.00078,0.001031,0.026181,289.163544,14.730694,0.261809,-1275.268921,294.500458,0
82.910004,65.015488,-1275.313354,-0.000802,0.001031,0.026181,289.203339,14.73272,0.261809,-1275.313354,294.500458,0
83.140007,65.011765,-1275.313354,-0.000793,0.001031,0.026181,289.186768,14.731876,0.261809,-1275.313354,294.500458,0
83.370003,65.004684,-1275.357788,-0.000806,0.001031,0.026181,289.155273,14.730271,0.261809,-1275.357788,294.500458,0
83.600006,65.001709,-1275.357788,-0.000806,0.001031,0.026181,289.142029,14.729598,0.261809,-1275.357788,294.500458,0
83.830002,64.994263,-1275.268921,-0.00078,0.001031,0.026181,289.108917,14.72791,0.261809,-1275.268921,294.500458,0
84.060005,64.990158,-1275.313354,-0.000789,0.001031,0.026181,289.090668,14.72698,0.261809,-1275.313354,294.500458,0
84.290001,64.983841,-1275.402344,-0.000806,0.001031,0.026181,289.062561,14.725549,0.261809,-1275.402344,294.500458,0
84.520004,64.993881,-1275.268921,-0.000811,0.001031,0.026181,289.107208,14.727824,0.261809,-1275.268921,294.500458,0
84.750008,64.985703,-1275.268921,-0.000785,0.001031,0.026181,289.070831,14.72597,0.261809,-1275.268921,294.500458,0
84.980003,64.991287,-1275.313354,-0.000802,0.001031,0.026181,289.095673,14.727236,0.261809,-1275.313354,294.500458,0
85.210007,64.99202,-1275.313354,-0.000785,0.001031,0.026181,289.098938,14.727402,0.261809,-1275.313354,294.500458,0
85.440002,64.975266,-1275.313354,-0.000785,0.001031,0.026181,289.024414,14.723605,0.261809,-1275.313354,294.500458,0
85.670006,64.97937,-1275.313354,-0.000785,0.001031,0.026181,289.042664,14.724536,0.261809,-1275.313354,1681.640747,0
85.900002,64.929474,-1275.268921,-0.000785,0.001022,0.025955,288.82074,14.713228,0.259553,-1275.268921,0.026155,0
86.130005,64.919785,-1275.313354,-0.000793,0.001021,0.025939,288.777618,14.711034,0.259386,-1275.313354,0.025774,0
86.360001,64.841217,-1275.313354,-0.000789,0.00101,0.025662,288.428131,14.69323,0.256616,-1275.313354,0.025392,0
86.590004,64.846436,-1275.357788,-0.000789,0.001,0.025401,288.451355,14.694413,0.254012,-1275.357788,0.025002,0
86.820007,64.764511,-1275.268921,-0.000798,0.000986,0.025054,288.086945,14.675848,0.250545,-1275.268921,0.02462,0
87.050003,64.728012,-1275.268921,-0.000763,0.000975,0.024759,287.924591,14.667577,0.247593,-1275.268921,0.024238,0
87.280006,64.725403,-1275.268921,-0.000776,0.000961,0.024413,287.912964,14.666986,0.244126,-1275.268921,0.023857,0
87.510002,64.735458,-1275.357788,-0.000772,0.000945,0.024004,287.957703,14.669265,0.240038,-1275.357788,0.023475,0
87.740005,64.719452,-1275.313354,-0.000785,0.000932,0.023666,287.886505,14.665637,0.236662,-1275.313354,0.023085,0
87.970001,64.724289,-1275.268921,-0.000793,0.000916,0.023259,287.90802,14.666734,0.232589,-1275.268921,0.022703,0
88.200005,64.750732,-1275.268921,-0.000772,0.000902,0.02292,288.025635,14.672726,0.229198,-1275.268921,0.022322,0
88.430008,64.741791,-1275.313354,-0.000772,0.000888,0.022547,287.98587,14.670699,0.225474,-1275.313354,0.02194,0
88.660004,64.732117,-1275.357788,-0.000776,0.000872,0.02214,287.942841,14.668508,0.221401,-1275.357788,0.021559,0
88.890007,64.715347,-1275.402344,-0.000793,0.000858,0.021784,287.868256,14.664707,0.217843,-1275.402344,0.021168,0
89.120003,64.691528,-1275.313354,-0.000789,0.000841,0.021359,287.762299,14.65931,0.213589,-1275.313354,0.020787,0
89.350006,64.690033,-1275.357788,-0.000772,0.000829,0.021047,287.755646,14.658971,0.21047,-1275.357788,0.020405,0
89.580002,64.642365,-1275.313354,-0.000785,0.00081,0.020579,287.54361,14.64817,0.205792,-1275.313354,0.020024,0
89.810005,64.609222,-1275.402344,-0.000776,0.000798,0.020267,287.396179,14.640658,0.202674,-1275.402344,0.019642,0
90.040001,64.475922,-1275.402344,-0.000793,0.000785,0.019946,286.803223,14.610453,0.199464,-1275.402344,0.019251,0
90.270004,64.222702,-1275.268921,-0.000802,0.000774,0.019651,285.676849,14.553072,0.196512,-1275.268921,0.01887,0
90.500008,63.650375,-1275.268921,-0.000759,0.000755,0.019174,283.131012,14.423381,0.191743,-1275.268921,0.018488,0
90.730003,63.037071,-1275.357788,-0.000763,0.000744,0.018888,280.402893,14.284405,0.188881,-1275.357788,0.018107,0
90.960007,62.494896,-1275.357788,-0.000763,0.00073,0.018541,277.99118,14.161546,0.185414,-1275.357788,0.017725,0
91.190002,61.799301,-1275.313354,-0.000767,0.000718,0.018228,274.897034,14.003922,0.182281,-1275.313354,0.017335,0
91.420006,60.805817,-1275.268921,-0.000767,0.000702,0.017821,270.477783,13.778795,0.178208,-1275.268921,0.016953,0
91.650002,59.686462,-1275.313354,-0.000767,0.000685,0.017388,265.498657,13.525146,0.173878,-1275.313354,0.016572,0
91.880005,58.758881,-1275.357788,-0.000755,0.000673,0.017102,261.372559,13.314953,0.171017,-1275.357788,0.01619,0
92.110001,57.885674,-1275.357788,-0.000772,0.000663,0.01685,257.488342,13.117082,0.168504,-1275.357788,0.015809,0
92.340004,56.708977,-1275.357788,-0.000772,0.000647,0.016434,252.25412,12.850437,0.16434,-1275.357788,0.01542,0
92.570007,55.231773,-1275.402344,-0.000759,0.000633,0.016078,245.683197,12.515699,0.160782,-1275.402344,0.015037,0
92.800003,53.810425,-1275.313354,-0.000759,0.000617,0.015662,239.360718,12.193616,0.156619,-1275.313354,0.014655,0
93.030006,52.542122,-1275.402344,-0.000772,0.000604,0.01535,233.719025,11.906215,0.1535,-1275.402344,0.014274,0
93.260002,51.098808,-1275.402344,-0.000759,0.000588,0.014925,227.298859,11.579156,0.149246,-1275.402344,0.013892,0
93.490005,49.157257,-1275.313354,-0.000767,0.000569,0.014464,218.662399,11.139194,0.144644,-1275.313354,0.013503,0
93.720001,47.691231,-1275.357788,-0.000767,0.000556,0.01411,212.14119,10.806988,0.141101,-1275.357788,0.013121,0
93.950005,45.923576,-1275.402344,-0.000767,0.000541,0.013745,204.278275,10.406431,0.137452,-1275.402344,0.012738,0
94.180008,44.380096,-1275.402344,-0.000776,0.000528,0.013415,197.412521,10.056674,0.134152,-1275.402344,0.012357,0
94.410004,42.227036,-1275.402344,-0.000767,0.000507,0.012878,187.835236,9.568783,0.128777,-1275.402344,0.011968,0
94.640007,40.622482,-1275.357788,-0.000763,0.000494,0.012548,180.69783,9.205186,0.125477,-1275.357788,0.011586,0
94.870003,39.690437,-1275.357788,-0.000776,0.000489,0.01241,176.55188,8.993981,0.124099,-1275.357788,0.011205,0
95.100006,37.954803,-1275.446777,-0.000767,0.00047,0.011933,168.83139,8.600681,0.11933,-1275.446777,0.010823,0
95.330002,35.703445,-1275.402344,-0.000767,0.000452,0.011491,158.816864,8.090516,0.114909,-1275.402344,0.010442,0
95.560005,34.628403,-1275.446777,-0.000759,0.000441,0.011205,154.034836,7.846908,0.112048,-1275.446777,0.010051,0
95.790001,32.952354,-1275.357788,-0.000763,0.000426,0.010814,146.579391,7.46711,0.108142,-1275.357788,0.00967,0
96.020004,30.823502,-1275.402344,-0.000767,0.000407,0.010346,137.109787,6.984705,0.103464,-1275.402344,0.009288,0
96.250008,29.666168,-1275.357788,-0.000742,0.000398,0.010112,131.9617,6.72245,0.101117,-1275.357788,0.008907,0
96.480003,27.066635,-1275.402344,-0.000772,0.000373,0.009479,120.398407,6.133387,0.094789,-1275.402344,0.008525,0
96.710007,25.962181,-1275.402344,-0.000755,0.000361,0.009175,115.48555,5.883114,0.091746,-1275.402344,0.008134,0
96.940002,24.379593,-1275.446777,-0.000755,0.000347,0.008811,108.445847,5.524495,0.088112,-1275.446777,0.007753,0
97.170006,22.970169,-1275.357788,-0.000755,0.000337,0.008551,102.176414,5.205114,0.085508,-1275.357788,0.007371,0
97.400002,20.357971,-1275.402344,-0.000746,0.000315,0.007995,90.556778,4.613182,0.079952,-1275.402344,0.00699,0
97.630005,18.784325,-1275.402344,-0.000759,0.000302,0.007665,83.556847,4.256589,0.076652,-1275.402344,0.006608,0
97.860008,16.946297,-1275.402344,-0.000759,0.000284,0.007216,75.38089,3.840086,0.072155,-1275.402344,0.006218,0
98.090004,15.559952,-1275.402344,-0.000767,0.000272,0.006902,69.214119,3.525935,0.069021,-1275.402344,0.005836,0
98.320007,14.047752,-1275.402344,-0.000767,0.000259,0.006581,62.487522,3.183266,0.065812,-1275.402344,0.005455,0
98.550003,12.141205,-1275.446777,-0.000776,0.00024,0.006097,54.006775,2.751236,0.060967,-1275.446777,0.005073,0
98.780006,10.699005,-1275.446777,-0.000763,0.000225,0.005706,47.591553,2.424429,0.057061,-1275.446777,0.004692,0
99.010002,9.521187,-1275.446777,-0.000776,0.000212,0.005385,42.352356,2.157532,0.053851,-1275.446777,0.004301,0
99.240005,7.811996,-1275.402344,-0.000763,0.000197,0.004995,34.749496,1.770224,0.049945,-1275.402344,0.00392,0
99.470001,6.232399,-1275.402344,-0.000763,0.000181,0.004596,27.723095,1.412282,0.045964,-1275.402344,0.003538,0
99.700005,4.753334,-1275.402344,-0.000772,0.000169,0.004292,21.143887,1.077121,0.042921,-1275.402344,0.003157,0
99.930008,3.260864,-1275.491211,-0.000759,0.000152,0.003859,14.505049,0.738922,0.038591,-1275.491211,0.002775,0
100.160004,2.010063,-1275.491211,-0.000767,0.000143,0.003643,8.941208,0.455487,0.036426,-1275.491211,0.003503,0
100.300003,2.042091,-1275.446777,-0.00075,0.000144,0.003659,9.083676,0.462745,0.036592,-1275.446777,0.003503,0