File: Data/compression 36/Heating-15-36-reverse-1-4_11202024_170418(in).csv
Time (sec),S:Load (lbs),S:HL1 (DIM),S:LVDT (in),S:Position (in),Ch:Position (mm),Ch:Load (N),Ch:Stress (MPa),Ch:Strain (mm/mm),Ch:HL1 (DIM),Set Point (),Cycles ()
0.11,-0.144852,-1278.338013,-0.01321,-0.008527,-0.216573,-0.644332,-0.032824,-2.165732,-1278.338013,-0.216287,0
0.56,-0.027931,-1278.338013,-0.013215,-0.008442,-0.214422,-0.124244,-0.006329,-2.144219,-1278.338013,-0.213719,0
1.01,-0.060699,-1278.338013,-0.013025,-0.008171,-0.207545,-0.270005,-0.013755,-2.075455,-1278.338013,-0.206227,0
1.46,-0.033142,-1278.382568,-0.012689,-0.007877,-0.200079,-0.147423,-0.00751,-2.000786,-1278.382568,-0.198734,0
1.91,-0.052132,-1278.382568,-0.012409,-0.007583,-0.192603,-0.231893,-0.011813,-1.926027,-1278.382568,-0.191223,0
2.36,-0.088623,-1278.338013,-0.012089,-0.007287,-0.185092,-0.394215,-0.020082,-1.85092,-1278.338013,-0.183731,0
2.81,-0.092354,-1278.293579,-0.011796,-0.006993,-0.177634,-0.41081,-0.020928,-1.776342,-1278.293579,-0.176238,0
3.26,-0.000748,-1278.293579,-0.011482,-0.006693,-0.170011,-0.003326,-0.000169,-1.700114,-1278.293579,-0.168746,0
3.71,-0.0149,-1278.293579,-0.011188,-0.006404,-0.162649,-0.066279,-0.003376,-1.62649,-1278.293579,-0.161235,0
4.16,-0.04953,-1278.382568,-0.010882,-0.006107,-0.155113,-0.220321,-0.011224,-1.551126,-1278.382568,-0.153742,0
4.61,-0.049156,-1278.293579,-0.010559,-0.005806,-0.147472,-0.218658,-0.011139,-1.474716,-1278.293579,-0.14625,0
5.06,-0.012291,-1278.293579,-0.01027,-0.00552,-0.140205,-0.054673,-0.002785,-1.402046,-1278.293579,-0.138757,0
5.51,-0.038353,-1278.382568,-0.009947,-0.005221,-0.132608,-0.170603,-0.008691,-1.326076,-1278.382568,-0.131247,0
5.960001,-0.009682,-1278.338013,-0.009658,-0.004922,-0.125029,-0.043066,-0.002194,-1.250287,-1278.338013,-0.123754,0
6.41,-0.046547,-1278.338013,-0.009365,-0.004629,-0.117579,-0.207051,-0.010548,-1.175785,-1278.338013,-0.116261,0
6.86,-0.143364,-1278.293579,-0.009071,-0.004342,-0.110295,-0.637715,-0.032487,-1.102949,-1278.293579,-0.108767,0
7.31,-0.001862,-1278.338013,-0.008757,-0.004039,-0.102584,-0.008281,-0.000422,-1.025843,-1278.338013,-0.101275,0
7.76,0.024574,-1278.293579,-0.008459,-0.003752,-0.095308,0.109312,0.005569,-0.953082,-1278.293579,-0.093765,0
8.21,-0.060699,-1278.249146,-0.008127,-0.003449,-0.087599,-0.270005,-0.013755,-0.875991,-1278.249146,-0.086273,0
8.660001,-0.032028,-1278.293579,-0.007834,-0.003153,-0.080097,-0.142469,-0.007258,-0.800975,-1278.293579,-0.078779,0
9.110001,-0.046921,-1278.293579,-0.007519,-0.002861,-0.072665,-0.208714,-0.010632,-0.726654,-1278.293579,-0.071286,0
9.56,-0.035004,-1278.338013,-0.007217,-0.002568,-0.065215,-0.155704,-0.007932,-0.652153,-1278.338013,-0.063777,0
10.01,-0.013031,-1278.293579,-0.006911,-0.002268,-0.05762,-0.057965,-0.002953,-0.576197,-1278.293579,-0.056283,0
10.46,-0.031654,-1278.338013,-0.006614,-0.001977,-0.050213,-0.140806,-0.007173,-0.502134,-1278.338013,-0.04879,0
10.910001,-0.103897,-1278.338013,-0.006312,-0.00168,-0.042668,-0.462157,-0.023543,-0.426679,-1278.338013,-0.041298,0
11.360001,-0.02681,-1278.249146,-0.006002,-0.001386,-0.035201,-0.119255,-0.006075,-0.35201,-1278.249146,-0.033787,0
11.81,0.007072,-1278.338013,-0.005691,-0.001088,-0.027639,0.03146,0.001603,-0.276388,-1278.338013,-0.026294,0
12.26,-0.023087,-1278.293579,-0.005372,-0.000798,-0.020267,-0.102694,-0.005231,-0.202674,-1278.293579,-0.018802,0
12.710001,-0.021973,-1278.382568,-0.005109,-0.000507,-0.01287,-0.097739,-0.004979,-0.128702,-1278.382568,-0.011309,0
13.160001,-0.052132,-1278.293579,-0.004777,-0.000202,-0.005143,-0.231893,-0.011813,-0.051429,-1278.293579,-0.003799,0
13.610001,0.094955,-1278.338013,-0.004596,0,0,0.422383,0.021517,0,-1278.338013,0.000226,0
14.06,0.163101,-1278.293579,-0.004583,0,0,0.72551,0.036959,0,-1278.293579,0.000372,0
14.51,0.090858,-1278.293579,-0.004587,0.000002,0.000061,0.404159,0.020589,0.000606,-1278.293579,0.001119,0
14.960001,0.211502,-1278.382568,-0.004579,0.000027,0.000684,0.940808,0.047927,0.006843,-1278.382568,0.001873,0
15.410001,0.458015,-1278.338013,-0.00454,0.000059,0.001508,2.037354,0.103788,0.015079,-1278.338013,0.002619,0
15.860001,0.595421,-1278.293579,-0.004523,0.000087,0.00221,2.648564,0.134924,0.022104,-1278.293579,0.003373,0
16.310001,0.743996,-1278.338013,-0.004475,0.000115,0.002922,3.309458,0.168592,0.029219,-1278.338013,0.004119,0
16.76,1.047485,-1278.293579,-0.004454,0.000148,0.003755,4.659448,0.237364,0.037546,-1278.293579,0.004873,0
17.210001,1.350594,-1278.338013,-0.004419,0.000179,0.004534,6.00774,0.306049,0.045343,-1278.338013,0.005618,0
17.660002,1.611626,-1278.338013,-0.004389,0.000203,0.00515,7.168869,0.3652,0.051505,-1278.338013,0.006374,0
18.110001,1.891281,-1278.382568,-0.004363,0.00023,0.005844,8.412839,0.42857,0.058439,-1278.382568,0.007119,0
18.560001,2.220459,-1278.338013,-0.004355,0.00026,0.006608,9.877095,0.503163,0.066084,-1278.338013,0.007874,0
19.01,2.666557,-1278.338013,-0.004337,0.000294,0.007474,11.86144,0.604251,0.074744,-1278.338013,0.008619,0
19.460001,3.056801,-1278.338013,-0.00429,0.000327,0.008316,13.597329,0.692681,0.083162,-1278.338013,0.009374,0
19.910002,3.381516,-1278.382568,-0.004255,0.000353,0.008975,15.041732,0.766262,0.089747,-1278.382568,0.010119,0
20.360001,3.617599,-1278.338013,-0.004225,0.000382,0.009695,16.091887,0.81976,0.096954,-1278.338013,0.010875,0
20.810001,4.072266,-1278.382568,-0.004204,0.000412,0.010475,18.114342,0.922789,0.104751,-1278.382568,0.01162,0
21.26,4.380585,-1278.382568,-0.004174,0.000444,0.011265,19.485813,0.992655,0.112654,-1278.382568,0.012375,0
21.710001,4.488945,-1278.382568,-0.004161,0.000463,0.011768,19.967825,1.017209,0.11768,-1278.382568,0.01312,0
22.160002,4.998352,-1278.382568,-0.00413,0.000499,0.012678,22.23378,1.132643,0.126779,-1278.382568,0.013875,0
22.610001,5.314499,-1278.382568,-0.004092,0.000533,0.013536,23.640072,1.204283,0.135363,-1278.382568,0.01462,0
23.060001,5.654472,-1278.338013,-0.004057,0.000565,0.014352,25.152349,1.281322,0.143523,-1278.338013,0.015376,0
23.51,5.755386,-1278.427002,-0.004018,0.000587,0.014899,25.601236,1.304189,0.148989,-1278.427002,0.016121,0
23.960001,6.094994,-1278.427002,-0.00401,0.000617,0.015679,27.111885,1.381145,0.156785,-1278.427002,0.016876,0
24.410002,6.226067,-1278.338013,-0.003992,0.000644,0.016364,27.694927,1.410847,0.163644,-1278.338013,0.017621,0
24.860001,6.741798,-1278.427002,-0.003945,0.000681,0.0173,29.989017,1.527713,0.173,-1278.427002,0.018376,0
25.310001,6.895592,-1278.382568,-0.003928,0.000708,0.017986,30.673124,1.562563,0.179858,-1278.382568,0.019121,0
25.760002,7.276527,-1278.427002,-0.003893,0.000741,0.018818,32.367611,1.648885,0.188185,-1278.427002,0.019877,0
26.210001,7.356216,-1278.382568,-0.003846,0.000768,0.019512,32.722084,1.666942,0.195119,-1278.382568,0.020622,0
26.660002,7.741249,-1278.382568,-0.003811,0.000801,0.020354,34.434795,1.754192,0.203537,-1278.382568,0.021377,0
27.110001,7.795616,-1278.338013,-0.00382,0.000825,0.020943,34.676632,1.766512,0.209426,-1278.338013,0.022122,0
27.560001,8.094261,-1278.427002,-0.00379,0.000853,0.021663,36.005074,1.834186,0.216632,-1278.427002,0.022877,0
28.010002,8.230919,-1278.427002,-0.003738,0.000884,0.022461,36.612957,1.865153,0.224611,-1278.427002,0.023622,0
28.460001,8.512802,-1278.427002,-0.003725,0.000911,0.023136,37.866837,1.929029,0.231363,-1278.427002,0.024378,0
28.910002,9.203926,-1278.338013,-0.003691,0.000949,0.024108,40.941109,2.085639,0.241083,-1278.338013,0.025123,0
29.360001,9.240051,-1278.427002,-0.003656,0.00098,0.02488,41.101799,2.093826,0.248804,-1278.427002,0.025878,0
29.810001,9.121635,-1278.427002,-0.003639,0.000999,0.025383,40.575062,2.066992,0.25383,-1278.427002,0.026623,0
30.260002,9.565132,-1278.382568,-0.003604,0.001032,0.026225,42.547832,2.16749,0.262248,-1278.382568,0.027378,0
30.710001,9.993355,-1278.293579,-0.003574,0.001064,0.02703,44.452663,2.264527,0.270302,-1278.293579,0.028123,0
31.160002,10.036179,-1278.427002,-0.00354,0.001095,0.027802,44.64315,2.274231,0.278023,-1278.427002,0.028879,0
31.610001,10.07975,-1278.427002,-0.00351,0.001121,0.02847,44.836967,2.284104,0.2847,-1278.427002,0.029624,0
32.060001,10.411163,-1278.338013,-0.003492,0.001149,0.029182,46.311169,2.359203,0.291815,-1278.338013,0.030379,0
32.510002,10.968971,-1278.427002,-0.003454,0.001181,0.029996,48.792419,2.485605,0.29996,-1278.427002,0.031124,0
32.960003,10.993919,-1278.338013,-0.003423,0.001211,0.030752,48.903397,2.491258,0.307515,-1278.338013,0.031878,0
33.41,11.228516,-1278.471436,-0.003406,0.001241,0.031515,49.946934,2.544418,0.315145,-1278.471436,0.032624,0
33.860001,11.082176,-1278.427002,-0.003363,0.001262,0.032052,49.295982,2.511257,0.32052,-1278.427002,0.033371,0
34.310001,11.105637,-1278.471436,-0.003337,0.001282,0.032564,49.400337,2.516573,0.325637,-1278.471436,0.034125,0
34.760002,12.145668,-1278.515991,-0.003298,0.001329,0.033752,54.02663,2.752248,0.337522,-1278.515991,0.034871,0
35.210003,11.921501,-1278.427002,-0.003277,0.001353,0.034359,53.029484,2.701451,0.343593,-1278.427002,0.035625,0
35.66,12.395531,-1278.427002,-0.003242,0.001389,0.035287,55.138073,2.808867,0.352873,-1278.427002,0.036371,0
36.110001,12.069336,-1278.382568,-0.003238,0.00141,0.035825,53.687088,2.734951,0.358248,-1278.382568,0.037125,0
36.560001,12.871796,-1278.427002,-0.003178,0.001446,0.036727,57.256607,2.91679,0.367271,-1278.427002,0.037872,0
37.010002,12.840149,-1278.382568,-0.003139,0.001476,0.03749,57.115833,2.909619,0.374901,-1278.382568,0.038626,0
37.460003,13.043091,-1278.471436,-0.00313,0.001503,0.038184,58.018566,2.955606,0.381835,-1278.471436,0.039372,0
37.910004,13.256088,-1278.471436,-0.003104,0.00153,0.038851,58.966026,3.003873,0.388512,-1278.471436,0.040126,0
38.360001,13.574089,-1278.471436,-0.003065,0.001562,0.039684,60.380562,3.075933,0.396839,-1278.471436,0.040872,0
38.810001,13.848534,-1278.382568,-0.003031,0.001597,0.040551,61.601353,3.138123,0.405514,-1278.382568,0.041626,0
39.260002,13.780014,-1278.427002,-0.003005,0.001621,0.041175,61.296562,3.122596,0.411751,-1278.427002,0.042373,0
39.710003,13.976997,-1278.471436,-0.002984,0.001649,0.041896,62.172791,3.167233,0.418958,-1278.471436,0.043127,0
40.160004,14.184036,-1278.427002,-0.002953,0.001676,0.04258,63.093746,3.214149,0.425801,-1278.427002,0.043873,0
40.610001,14.699776,-1278.471436,-0.002936,0.001712,0.043491,65.387871,3.331017,0.434915,-1278.471436,0.044627,0
41.060001,14.803291,-1278.471436,-0.00288,0.001741,0.04422,65.848328,3.354474,0.442197,-1278.471436,0.045373,0
41.510002,15.007729,-1278.427002,-0.002859,0.001771,0.044992,66.757713,3.4008,0.449918,-1278.427002,0.046127,0
41.960003,15.055763,-1278.427002,-0.002841,0.001797,0.045641,66.971382,3.411685,0.456413,-1278.427002,0.046874,0
42.410004,15.603523,-1278.471436,-0.002781,0.001833,0.04656,69.407936,3.535809,0.465603,-1278.471436,0.047628,0
42.860001,15.35627,-1278.471436,-0.002751,0.001855,0.047116,68.308098,3.47978,0.471159,-1278.471436,0.048374,0
43.310001,15.734222,-1278.560425,-0.002738,0.001884,0.047862,69.989319,3.565426,0.478623,-1278.560425,0.049128,0
43.760002,15.615807,-1278.560425,-0.002708,0.001912,0.048565,69.462578,3.538592,0.485647,-1278.560425,0.049874,0
44.210003,16.457001,-1278.471436,-0.002673,0.001951,0.049561,73.204399,3.72921,0.495609,-1278.471436,0.050628,0
44.660004,16.363907,-1278.560425,-0.002643,0.001979,0.050272,72.790291,3.708114,0.502725,-1278.560425,0.051373,0
45.110001,16.281982,-1278.515991,-0.002608,0.002003,0.05088,72.425873,3.68955,0.508796,-1278.515991,0.052129,0
45.560001,16.909058,-1278.427002,-0.002578,0.002035,0.051677,75.215248,3.831647,0.516774,-1278.427002,0.052873,0
46.010002,17.227066,-1278.471436,-0.002544,0.002063,0.052406,76.629814,3.903709,0.524057,-1278.471436,0.053629,0
46.460003,17.566666,-1278.515991,-0.002522,0.002097,0.053257,78.140434,3.980663,0.532565,-1278.515991,0.054374,0
46.910004,17.518257,-1278.471436,-0.002483,0.002123,0.053915,77.925102,3.969694,0.539151,-1278.471436,0.055129,0
47.360001,18.007187,-1278.515991,-0.002462,0.002158,0.054808,80.099968,4.080487,0.548083,-1278.515991,0.055874,0
47.810001,18.154274,-1278.471436,-0.002419,0.002188,0.05558,80.754242,4.113817,0.555804,-1278.471436,0.05663,0
48.260002,18.434296,-1278.560425,-0.002393,0.002218,0.056334,81.99984,4.177271,0.563344,-1278.560425,0.057374,0
48.710003,18.338226,-1278.515991,-0.002367,0.002239,0.056881,81.572502,4.155502,0.568809,-1278.515991,0.05813,0
49.160004,18.700546,-1278.471436,-0.002328,0.002268,0.057618,83.184181,4.237605,0.576182,-1278.471436,0.058875,0
49.610001,19.223724,-1278.515991,-0.002302,0.002302,0.058458,85.511398,4.356158,0.584585,-1278.515991,0.05963,0
50.060001,18.724747,-1278.471436,-0.002276,0.00232,0.058919,83.291832,4.243088,0.589187,-1278.471436,0.060375,0
50.510002,20.452553,-1278.471436,-0.002242,0.002371,0.060219,90.977501,4.634614,0.602192,-1278.471436,0.061131,0
50.960003,20.209396,-1278.515991,-0.00222,0.002393,0.060791,89.895882,4.579515,0.607915,-1278.515991,0.061875,0
51.410004,20.410103,-1278.471436,-0.002177,0.002422,0.061512,90.788673,4.624996,0.615121,-1278.471436,0.062631,0
51.860001,20.572456,-1278.515991,-0.002151,0.002447,0.062154,91.510857,4.661785,0.62154,-1278.515991,0.063376,0
52.310001,20.989517,-1278.560425,-0.002139,0.002479,0.062978,93.366035,4.756292,0.629776,-1278.560425,0.064131,0
52.760002,21.040535,-1278.560425,-0.002078,0.002506,0.063654,93.592972,4.767853,0.636544,-1278.560425,0.064876,0
53.210003,21.39801,-1278.515991,-0.00207,0.002534,0.064364,95.183105,4.848859,0.643644,-1278.515991,0.065632,0
53.660004,21.659416,-1278.471436,-0.002048,0.002561,0.06505,96.345894,4.908094,0.650502,-1278.471436,0.066376,0
54.110004,22.854729,-1278.471436,-0.001983,0.002602,0.06609,101.66291,5.178956,0.660903,-1278.471436,0.067123,0
54.560001,22.581039,-1278.560425,-0.001988,0.002625,0.066663,100.44548,5.116937,0.666626,-1278.560425,0.067877,0
55.010002,22.954895,-1278.515991,-0.001944,0.002653,0.067374,102.108475,5.201653,0.673742,-1278.515991,0.068623,0
55.460003,23.202156,-1278.60498,-0.001923,0.002678,0.068025,103.208344,5.257684,0.680252,-1278.60498,0.069377,0
55.910004,24.64994,-1278.560425,-0.00191,0.002715,0.068953,109.648415,5.585757,0.689532,-1278.560425,0.070124,0
56.360004,24.802986,-1278.515991,-0.00188,0.002747,0.069768,110.329193,5.620437,0.697677,-1278.515991,0.070877,0
56.810001,24.978371,-1278.560425,-0.001819,0.002774,0.070461,111.109344,5.66018,0.704611,-1278.560425,0.071624,0
57.260002,25.046143,-1278.515991,-0.001807,0.002797,0.071042,111.410805,5.675537,0.710425,-1278.515991,0.072378,0
57.710003,25.667259,-1278.560425,-0.001772,0.002827,0.071796,114.173668,5.816284,0.717964,-1278.560425,0.073124,0
58.160004,26.862572,-1278.60498,-0.001755,0.002864,0.072752,119.490685,6.087145,0.727517,-1278.60498,0.073878,0
58.610004,26.634682,-1278.515991,-0.001725,0.002884,0.073262,118.476982,6.035505,0.732619,-1278.515991,0.074625,0
59.060001,27.35746,-1278.515991,-0.001681,0.002915,0.074034,121.692062,6.199289,0.740341,-1278.515991,0.075378,0
59.510002,28.540115,-1278.560425,-0.001669,0.002949,0.074911,126.952774,6.467283,0.749106,-1278.560425,0.076125,0
59.960003,29.366783,-1278.515991,-0.001638,0.002981,0.075725,130.629974,6.654608,0.757252,-1278.515991,0.076879,0
60.410004,29.994225,-1278.515991,-0.001613,0.003012,0.076497,133.420975,6.796788,0.764973,-1278.515991,0.077625,0
60.860004,30.497673,-1278.60498,-0.001591,0.003041,0.077235,135.660431,6.910872,0.772346,-1278.60498,0.078379,0
61.310001,30.555389,-1278.60498,-0.001574,0.003061,0.077755,135.91716,6.92395,0.777554,-1278.60498,0.079126,0
61.760002,32.109673,-1278.60498,-0.001556,0.003098,0.078683,142.830963,7.276155,0.786834,-1278.60498,0.079879,0
62.210003,32.995552,-1278.60498,-0.001505,0.003127,0.079419,146.771545,7.476899,0.794192,-1278.60498,0.080626,0
62.660004,33.65316,-1278.471436,-0.001496,0.003155,0.080131,149.696732,7.625915,0.801308,-1278.471436,0.08138,0
63.110004,34.364761,-1278.560425,-0.001457,0.003183,0.080851,152.862091,7.787166,0.808514,-1278.560425,0.082126,0
63.560001,35.383575,-1278.60498,-0.001431,0.003216,0.081675,157.393997,8.018033,0.81675,-1278.60498,0.08288,0
64.010002,36.423615,-1278.60498,-0.001406,0.003245,0.08242,162.020325,8.25371,0.824199,-1278.60498,0.083626,0
64.460007,36.854446,-1278.649414,-0.001384,0.00327,0.083054,163.936768,8.351337,0.830542,-1278.649414,0.08438,0
64.910004,38.386017,-1278.560425,-0.001384,0.003303,0.083887,170.749527,8.698396,0.838869,-1278.560425,0.085127,0
65.360001,39.62825,-1278.560425,-0.001354,0.003331,0.084597,176.275253,8.97989,0.845969,-1278.560425,0.085881,0
65.810005,41.241364,-1278.60498,-0.001306,0.003367,0.085516,183.450745,9.345427,0.855159,-1278.60498,0.086627,0
66.260002,41.458832,-1278.60498,-0.001306,0.003386,0.085993,184.418091,9.394705,0.859928,-1278.60498,0.087381,0
66.710007,43.087219,-1278.515991,-0.001281,0.003419,0.086853,191.66153,9.763703,0.868527,-1278.515991,0.088127,0
67.160004,44.06842,-1278.60498,-0.001263,0.003447,0.087546,196.026123,9.986047,0.875461,-1278.60498,0.088881,0
67.610001,45.718773,-1278.515991,-0.001233,0.003479,0.088361,203.367264,10.360022,0.883606,-1278.515991,0.089628,0
68.060005,47.254807,-1278.60498,-0.001212,0.003512,0.089202,210.199875,10.708092,0.892024,-1278.60498,0.090382,0
68.510002,48.964745,-1278.560425,-0.001207,0.003545,0.090035,217.806061,11.09557,0.900351,-1278.560425,0.091128,0
68.960007,49.731087,-1278.60498,-0.001173,0.003567,0.090589,221.21492,11.269225,0.905892,-1278.60498,0.091882,0
69.410004,51.63205,-1278.560425,-0.001173,0.0036,0.09144,229.670822,11.699989,0.9144,-1278.560425,0.092628,0
69.860001,52.724586,-1278.560425,-0.001134,0.003628,0.09215,234.53067,11.947562,0.921501,-1278.560425,0.093382,0
70.310005,54.251312,-1278.60498,-0.001121,0.003654,0.092801,241.321884,12.293523,0.928011,-1278.60498,0.094129,0
70.760002,55.671913,-1278.649414,-0.001112,0.003681,0.093487,247.641037,12.615436,0.934869,-1278.649414,0.094883,0
71.210007,57.300301,-1278.60498,-0.001095,0.00371,0.094224,254.88446,12.984434,0.942242,-1278.60498,0.095629,0
71.660004,59.929253,-1278.60498,-0.001078,0.003749,0.09522,266.578644,13.580163,0.952204,-1278.60498,0.096383,0
72.110001,61.759834,-1278.649414,-0.001052,0.003777,0.095932,274.721466,13.994978,0.959319,-1278.649414,0.097128,0
72.560005,62.781624,-1278.560425,-0.001056,0.003805,0.096644,279.266602,14.22652,0.966435,-1278.560425,0.097883,0
73.010002,64.619278,-1278.60498,-0.001026,0.003829,0.097267,287.440918,14.642938,0.972673,-1278.60498,0.098628,0
73.460007,66.179153,-1278.60498,-0.001013,0.003849,0.097762,294.379578,14.99641,0.977623,-1278.60498,0.017166,0
73.910004,64.935425,-1278.560425,-0.001005,0.003854,0.097883,288.847198,14.714578,0.978834,-1278.560425,294.500458,0
74.360001,65.289551,-1278.60498,-0.000996,0.003867,0.09823,290.422424,14.794824,0.982301,-1278.60498,294.500458,0
74.810005,65.067612,-1278.560425,-0.000979,0.003873,0.098369,289.435181,14.744532,0.983694,-1278.560425,294.500458,0
75.260002,64.955536,-1278.60498,-0.00097,0.00388,0.09856,288.936646,14.719135,0.985602,-1278.60498,294.500458,0
75.710007,65.05011,-1278.560425,-0.000983,0.003885,0.098672,289.35733,14.740566,0.986722,-1278.560425,294.500458,0
76.160004,65.002457,-1278.60498,-0.000953,0.00389,0.098793,289.145355,14.729767,0.987933,-1278.60498,294.500458,0
76.610001,65.466797,-1278.60498,-0.000949,0.003899,0.099028,291.210846,14.834989,0.99028,-1278.60498,294.500458,0
77.060005,65.063522,-1278.60498,-0.000961,0.003899,0.099037,289.416992,14.743606,0.990371,-1278.60498,294.500458,0
77.510002,65.022186,-1278.693848,-0.000944,0.003903,0.09914,289.233124,14.734238,0.9914,-1278.693848,294.500458,0
77.960007,65.1689,-1278.60498,-0.000944,0.003909,0.099288,289.885742,14.767485,0.992884,-1278.60498,294.500458,0
78.410004,64.950699,-1278.60498,-0.000944,0.003909,0.099288,288.915131,14.718039,0.992884,-1278.60498,294.500458,0
78.860001,65.566223,-1278.60498,-0.00094,0.003919,0.099531,291.653137,14.857518,0.995306,-1278.60498,294.500458,0
79.310005,65.34169,-1278.515991,-0.000931,0.003919,0.099531,290.654358,14.806639,0.995306,-1278.515991,294.500458,0
79.760002,65.154755,-1278.60498,-0.000944,0.003919,0.099549,289.822815,14.764278,0.995488,-1278.60498,294.500458,0
80.210007,64.932068,-1278.60498,-0.00094,0.00392,0.099565,288.832275,14.713818,0.995654,-1278.60498,294.500458,0
80.660004,64.764511,-1278.60498,-0.000936,0.003922,0.099617,288.086945,14.675848,0.996169,-1278.60498,294.500458,0
81.110001,65.212097,-1278.560425,-0.000944,0.003928,0.099774,290.077881,14.777272,0.997744,-1278.560425,294.500458,0
81.560005,65.03746,-1278.560425,-0.000936,0.003928,0.099774,289.301086,14.7377,0.997744,-1278.560425,294.500458,0
82.010002,64.87175,-1278.60498,-0.000923,0.003928,0.099782,288.563965,14.700149,0.997819,-1278.60498,294.500458,0
82.460007,65.145065,-1278.60498,-0.000927,0.003934,0.099912,289.779724,14.762082,0.999121,-1278.60498,294.500458,0
82.910004,65.006546,-1278.60498,-0.000927,0.003934,0.099912,289.163544,14.730694,0.999121,-1278.60498,294.500458,0
83.360001,64.869522,-1278.60498,-0.000936,0.003934,0.099912,288.554047,14.699644,0.999121,-1278.60498,294.500458,0
83.810005,65.323807,-1278.649414,-0.000927,0.003941,0.100095,290.574799,14.802586,1.000953,-1278.649414,294.500458,0
84.260002,65.25827,-1278.60498,-0.000914,0.003941,0.100095,290.283295,14.787735,1.000953,-1278.60498,294.500458,0
84.710007,65.14061,-1278.60498,-0.000918,0.003941,0.100095,289.759918,14.761073,1.000953,-1278.60498,294.500458,0
85.160004,64.997986,-1278.649414,-0.000914,0.003942,0.100138,289.125488,14.728754,1.001377,-1278.649414,294.500458,0
85.610001,65.024796,-1278.60498,-0.00091,0.003943,0.100147,289.244751,14.734829,1.001468,-1278.60498,294.500458,0
86.060005,64.940643,-1278.60498,-0.000918,0.003943,0.100156,288.870422,14.71576,1.001559,-1278.60498,294.500458,0
86.510002,64.822601,-1278.649414,-0.000914,0.003943,0.100156,288.345337,14.689012,1.001559,-1278.649414,294.500458,0
86.960007,65.619095,-1278.693848,-0.000897,0.003952,0.100389,291.888306,14.869499,1.00389,-1278.693848,294.500458,0
87.410004,65.582611,-1278.60498,-0.00091,0.003952,0.100389,291.726013,14.861233,1.00389,-1278.60498,294.500458,0
87.860001,65.524887,-1278.60498,-0.000897,0.003952,0.100389,291.469269,14.848151,1.00389,-1278.60498,294.500458,0
88.310005,65.395309,-1278.649414,-0.000897,0.003952,0.100389,290.892853,14.818789,1.00389,-1278.649414,294.500458,0
88.760002,65.3078,-1278.738403,-0.000897,0.003952,0.100389,290.503601,14.798959,1.00389,-1278.738403,294.500458,0
89.210007,65.215073,-1278.649414,-0.00091,0.003953,0.100398,290.091125,14.777947,1.003981,-1278.649414,294.500458,0
89.660004,65.108582,-1278.693848,-0.000905,0.003953,0.100407,289.617432,14.753816,1.004072,-1278.693848,294.500458,0
90.110001,65.047134,-1278.738403,-0.000905,0.003953,0.100415,289.344116,14.739891,1.004148,-1278.738403,294.500458,0
90.560005,64.992401,-1278.693848,-0.000914,0.003953,0.100415,289.100647,14.727489,1.004148,-1278.693848,294.500458,0
91.010002,64.945847,-1278.649414,-0.000897,0.003954,0.100442,288.893555,14.716939,1.00442,-1278.649414,294.500458,0
91.460007,64.863937,-1278.649414,-0.000923,0.003954,0.100442,288.529205,14.698379,1.00442,-1278.649414,294.500458,0
91.910004,64.800247,-1278.693848,-0.00091,0.003955,0.100459,288.245911,14.683946,1.004587,-1278.693848,294.500458,0
92.360001,65.051971,-1278.649414,-0.000892,0.003959,0.100554,289.365631,14.740987,1.005541,-1278.649414,294.500458,0
92.810005,65.025543,-1278.693848,-0.000901,0.003959,0.100554,289.248077,14.734999,1.005541,-1278.693848,294.500458,0
93.260002,64.983841,-1278.738403,-0.00091,0.003959,0.100554,289.062561,14.725549,1.005541,-1278.738403,294.500458,0
93.710007,64.956284,-1278.649414,-0.000923,0.003959,0.100554,288.939972,14.719304,1.005541,-1278.649414,294.500458,0
94.160004,64.865799,-1278.738403,-0.000905,0.003959,0.100554,288.537476,14.6988,1.005541,-1278.738403,294.500458,0
94.610008,64.815521,-1278.693848,-0.000901,0.00396,0.10058,288.313843,14.687407,1.005798,-1278.693848,294.500458,0
95.060005,64.87175,-1278.693848,-0.000897,0.003962,0.10064,288.563965,14.700149,1.006404,-1278.693848,294.500458,0
95.510002,64.910477,-1278.738403,-0.000914,0.003962,0.10064,288.736206,14.708923,1.006404,-1278.738403,294.500458,0
95.960007,64.875107,-1278.693848,-0.000905,0.003962,0.10064,288.578888,14.70091,1.006404,-1278.693848,294.500458,0
96.410004,64.833389,-1278.738403,-0.000892,0.003963,0.100668,288.393311,14.691456,1.006676,-1278.738403,294.500458,0
96.860008,64.860947,-1278.738403,-0.000901,0.003963,0.100668,288.5159,14.697701,1.006676,-1278.738403,294.500458,0
97.310005,64.835251,-1278.693848,-0.000905,0.003963,0.100668,288.401611,14.691878,1.006676,-1278.693848,294.500458,0
97.760002,65.787415,-1278.649414,-0.000901,0.003974,0.100936,292.637024,14.907641,1.009356,-1278.649414,294.500458,0
98.210007,65.847,-1278.649414,-0.000888,0.003974,0.100936,292.9021,14.921144,1.009356,-1278.649414,294.500458,0
98.660004,65.835449,-1278.693848,-0.000892,0.003974,0.100936,292.850708,14.918527,1.009356,-1278.693848,294.500458,0
99.110008,65.769913,-1278.693848,-0.000884,0.003974,0.100936,292.559174,14.903675,1.009356,-1278.693848,294.500458,0
99.560005,65.760971,-1278.693848,-0.000892,0.003974,0.100936,292.519409,14.901649,1.009356,-1278.693848,294.500458,0
100.010002,65.667877,-1278.693848,-0.000875,0.003974,0.100936,292.105316,14.880554,1.009356,-1278.693848,294.500458,0
100.460007,65.618362,-1278.693848,-0.000888,0.003974,0.100936,291.88504,14.869334,1.009356,-1278.693848,294.500458,0
100.910004,65.575912,-1278.738403,-0.000884,0.003974,0.100936,291.696228,14.859715,1.009356,-1278.738403,294.500458,0
101.360008,65.53978,-1278.693848,-0.000884,0.003974,0.100936,291.535492,14.851526,1.009356,-1278.693848,294.500458,0
101.810005,65.491013,-1278.693848,-0.000888,0.003974,0.100936,291.318573,14.840475,1.009356,-1278.693848,294.500458,0
102.260002,65.40126,-1278.693848,-0.000888,0.003974,0.100945,290.919342,14.820137,1.009447,-1278.693848,294.500458,0
102.710007,65.342422,-1278.738403,-0.000897,0.003974,0.100945,290.657623,14.806805,1.009447,-1278.738403,294.500458,0
103.160004,65.308167,-1278.693848,-0.000888,0.003974,0.100945,290.505219,14.799042,1.009447,-1278.693848,294.500458,0
103.610008,65.269821,-1278.738403,-0.000884,0.003974,0.100945,290.334656,14.790353,1.009447,-1278.738403,294.500458,0
104.060005,65.2229,-1278.738403,-0.000884,0.003974,0.100945,290.125946,14.779721,1.009447,-1278.738403,294.500458,0
104.510002,65.178207,-1278.738403,-0.000884,0.003974,0.100945,289.927155,14.769593,1.009447,-1278.738403,294.500458,0
104.960007,65.12645,-1278.738403,-0.000892,0.003974,0.100945,289.69693,14.757865,1.009447,-1278.738403,294.500458,0
105.410004,65.079163,-1278.693848,-0.000888,0.003974,0.100945,289.486572,14.747149,1.009447,-1278.693848,294.500458,0
105.860008,65.036713,-1278.693848,-0.00088,0.003974,0.100945,289.29776,14.73753,1.009447,-1278.693848,294.500458,0
106.310005,64.995743,-1278.693848,-0.000871,0.003974,0.100945,289.115509,14.728246,1.009447,-1278.693848,294.500458,0
106.760002,64.964844,-1278.738403,-0.000892,0.003974,0.100945,288.978058,14.721244,1.009447,-1278.738403,294.500458,0
107.210007,64.923508,-1278.738403,-0.000888,0.003974,0.100945,288.794189,14.711877,1.009447,-1278.738403,294.500458,0
107.660004,64.885162,-1278.693848,-0.000884,0.003974,0.100945,288.623627,14.703188,1.009447,-1278.693848,294.500458,0
108.110008,64.8293,-1278.693848,-0.000875,0.003974,0.100945,288.375122,14.690529,1.009447,-1278.693848,294.500458,0
108.560005,64.792068,-1278.693848,-0.000884,0.003974,0.100945,288.209503,14.682093,1.009447,-1278.693848,294.500458,0
109.010002,64.745514,-1278.738403,-0.000858,0.003975,0.100954,288.002441,14.671543,1.009537,-1278.738403,294.500458,0
109.460007,64.713486,-1278.738403,-0.000888,0.003975,0.100954,287.859955,14.664286,1.009537,-1278.738403,294.500458,0
109.910004,64.677002,-1278.693848,-0.000875,0.003975,0.100954,287.697662,14.656018,1.009537,-1278.693848,294.500458,0
110.360008,64.639755,-1278.738403,-0.000871,0.003975,0.100954,287.531982,14.647577,1.009537,-1278.738403,294.500458,0
110.810005,64.589127,-1278.738403,-0.00088,0.003975,0.100954,287.306793,14.636105,1.009537,-1278.738403,294.500458,0
111.260002,64.569382,-1278.782837,-0.000871,0.003975,0.100954,287.218964,14.631631,1.009537,-1278.782837,294.500458,0
111.710007,66.425293,-1278.782837,-0.000854,0.003966,0.100745,295.474457,15.052187,1.007448,-1278.782837,294.500458,0
112.160004,66.370178,-1278.782837,-0.000871,0.003966,0.100745,295.229309,15.039698,1.007448,-1278.782837,294.500458,0
112.610008,66.320648,-1278.782837,-0.00088,0.003966,0.100745,295.008972,15.028474,1.007448,-1278.782837,294.500458,0
113.060005,66.277832,-1278.782837,-0.000871,0.003966,0.100745,294.818512,15.018772,1.007448,-1278.782837,294.500458,0
113.510002,66.218994,-1278.693848,-0.000862,0.003966,0.100745,294.556793,15.005439,1.007448,-1278.693848,294.500458,0
113.960007,66.185852,-1278.782837,-0.000875,0.003966,0.100745,294.409363,14.997929,1.007448,-1278.782837,294.500458,0
114.410004,66.143402,-1278.693848,-0.000862,0.003966,0.100745,294.220551,14.988309,1.007448,-1278.693848,294.500458,0
114.860008,66.097229,-1278.738403,-0.000858,0.003966,0.100745,294.015167,14.977846,1.007448,-1278.738403,294.500458,0
115.310005,66.059616,-1278.827393,-0.000871,0.003966,0.100745,293.847839,14.969322,1.007448,-1278.827393,294.500458,0
115.760002,66.024994,-1278.738403,-0.000849,0.003966,0.100745,293.693848,14.961478,1.007448,-1278.738403,294.500458,0
116.210007,65.940079,-1278.738403,-0.000867,0.003966,0.100745,293.316132,14.942236,1.007448,-1278.738403,294.500458,0
116.660004,65.887589,-1278.738403,-0.000862,0.003966,0.100745,293.082642,14.930341,1.007448,-1278.738403,294.500458,0
117.110008,65.826889,-1278.738403,-0.000858,0.003966,0.100745,292.812622,14.916586,1.007448,-1278.738403,294.500458,0
117.560005,65.873062,-1278.738403,-0.00088,0.003966,0.100745,293.018005,14.927049,1.007448,-1278.738403,294.500458,0
118.010002,65.850342,-1278.693848,-0.000867,0.003966,0.100745,292.916962,14.921901,1.007448,-1278.693848,294.500458,0
118.460007,65.78183,-1278.782837,-0.000862,0.003966,0.100745,292.612183,14.906376,1.007448,-1278.782837,294.500458,0
118.910004,65.781082,-1278.693848,-0.000871,0.003966,0.100745,292.608856,14.906206,1.007448,-1278.693848,294.500458,0
119.360008,65.730072,-1278.738403,-0.000875,0.003966,0.100745,292.381958,14.894648,1.007448,-1278.738403,294.500458,0
119.810005,65.679794,-1278.738403,-0.000888,0.003966,0.100745,292.158325,14.883254,1.007448,-1278.738403,294.500458,0
120.260002,65.645172,-1278.693848,-0.000875,0.003966,0.100745,292.004303,14.875408,1.007448,-1278.693848,294.500458,0
120.710007,65.60495,-1278.738403,-0.000871,0.003966,0.100745,291.825378,14.866295,1.007448,-1278.738403,294.500458,0
121.160004,65.583359,-1278.738403,-0.000871,0.003966,0.100745,291.72934,14.861402,1.007448,-1278.738403,294.500458,0
121.610008,65.549835,-1278.738403,-0.000888,0.003967,0.100754,291.580231,14.853806,1.007539,-1278.738403,294.500458,0
122.060005,65.530106,-1278.782837,-0.000854,0.003967,0.100754,291.492462,14.849334,1.007539,-1278.782837,294.500458,0
122.510002,65.49585,-1278.738403,-0.000858,0.003967,0.100754,291.340088,14.841572,1.007539,-1278.738403,294.500458,0
122.960007,65.467911,-1278.738403,-0.000871,0.003967,0.100754,291.21582,14.835241,1.007539,-1278.738403,294.500458,0
123.410004,65.435516,-1278.782837,-0.000867,0.003967,0.100754,291.071716,14.8279,1.007539,-1278.782837,294.500458,0
123.860008,65.38562,-1278.782837,-0.000862,0.003967,0.100754,290.849762,14.816593,1.007539,-1278.782837,294.500458,0
124.310005,65.378922,-1278.738403,-0.000854,0.003974,0.100936,290.819977,14.815075,1.009356,-1278.738403,294.500458,0
124.760002,65.353226,-1278.738403,-0.000871,0.003974,0.100936,290.705658,14.809253,1.009356,-1278.738403,294.500458,0
125.210007,65.304077,-1278.782837,-0.000858,0.003974,0.100945,290.48703,14.798116,1.009447,-1278.782837,294.500458,0
125.660004,65.27652,-1278.782837,-0.000858,0.003977,0.101022,290.364471,14.79187,1.010219,-1278.782837,294.500458,0
126.110008,65.252319,-1278.738403,-0.00088,0.003977,0.101022,290.256805,14.786387,1.010219,-1278.738403,294.500458,0
126.560005,65.234818,-1278.782837,-0.000867,0.003979,0.101066,290.178955,14.782421,1.010658,-1278.782837,294.500458,0
127.01001,65.226624,-1278.738403,-0.000867,0.003979,0.101075,290.142517,14.780564,1.010749,-1278.738403,294.500458,0
127.460007,65.18045,-1278.782837,-0.000862,0.00398,0.101092,289.937134,14.770102,1.010915,-1278.782837,294.500458,0
127.910004,65.149918,-1278.738403,-0.000871,0.00398,0.101092,289.8013,14.763183,1.010915,-1278.738403,294.500458,0
128.360001,65.205765,-1278.827393,-0.000867,0.003986,0.101247,290.049713,14.775837,1.012475,-1278.827393,294.500458,0
128.810013,65.175598,-1278.738403,-0.000867,0.003986,0.101257,289.915527,14.769001,1.012565,-1278.738403,294.500458,0
129.26001,65.179337,-1278.782837,-0.000862,0.003987,0.101275,289.932159,14.769849,1.012747,-1278.782837,294.500458,0
129.710007,65.206146,-1278.827393,-0.000854,0.003987,0.101282,290.051422,14.775925,1.012823,-1278.827393,294.500458,0
130.160004,65.204651,-1278.738403,-0.000867,0.003987,0.101282,290.044769,14.775585,1.012823,-1278.738403,294.500458,0
130.610001,65.188263,-1278.782837,-0.000884,0.003987,0.101282,289.971863,14.771872,1.012823,-1278.782837,294.500458,0
131.060013,65.193848,-1278.738403,-0.000867,0.003989,0.101317,289.996704,14.773137,1.013171,-1278.738403,294.500458,0
131.51001,65.191986,-1278.827393,-0.000871,0.003989,0.101317,289.988434,14.772716,1.013171,-1278.827393,294.500458,0
131.960007,65.167419,-1278.782837,-0.000858,0.00399,0.101335,289.87915,14.767148,1.013353,-1278.782837,294.500458,0
132.410004,65.383759,-1278.693848,-0.000871,0.003993,0.101422,290.841492,14.816172,1.014216,-1278.693848,294.500458,0
132.860001,65.39978,-1278.827393,-0.000871,0.003993,0.101422,290.91275,14.819802,1.014216,-1278.827393,294.500458,0
133.310013,65.420624,-1278.693848,-0.000858,0.003993,0.101422,291.005463,14.824526,1.014216,-1278.693848,294.500458,0
133.76001,65.397171,-1278.782837,-0.000862,0.003993,0.101422,290.901154,14.819211,1.014216,-1278.782837,294.500458,0
134.210007,65.369614,-1278.782837,-0.000854,0.003984,0.101205,290.778564,14.812966,1.012051,-1278.782837,0.101179,0
134.660004,65.329391,-1278.782837,-0.000854,0.003968,0.100789,290.59964,14.803851,1.007887,-1278.782837,0.100433,0
135.110001,65.264236,-1278.782837,-0.000845,0.003945,0.100198,290.309814,14.789087,1.001983,-1278.782837,0.099679,0
135.560013,65.205765,-1278.782837,-0.000854,0.003914,0.099419,290.049713,14.775837,0.994186,-1278.782837,0.098933,0
136.01001,65.188644,-1278.782837,-0.000849,0.003889,0.098777,289.973572,14.771957,0.987767,-1278.782837,0.098179,0
136.460007,65.12645,-1278.782837,-0.000841,0.003857,0.09797,289.69693,14.757865,0.979697,-1278.782837,0.097432,0
136.910004,65.086243,-1278.782837,-0.000858,0.003827,0.097216,289.518066,14.748754,0.972158,-1278.782837,0.096678,0
137.360001,65.027771,-1278.782837,-0.000862,0.003798,0.096478,289.257965,14.735503,0.964785,-1278.782837,0.095932,0
137.810013,64.893341,-1278.827393,-0.000841,0.003768,0.095715,288.660004,14.705041,0.957155,-1278.827393,0.095178,0
138.26001,64.604752,-1278.827393,-0.000841,0.003747,0.095169,287.376282,14.639646,0.951689,-1278.827393,0.094432,0
138.710007,63.553177,-1278.782837,-0.000841,0.003717,0.094406,282.698639,14.401356,0.944059,-1278.782837,0.093678,0
139.160004,62.415581,-1278.871826,-0.000845,0.003692,0.093773,277.638367,14.143573,0.93773,-1278.871826,0.092931,0
139.610001,61.171112,-1278.738403,-0.000828,0.003668,0.093157,272.102692,13.861572,0.931569,-1278.738403,0.092177,0
140.060013,58.911552,-1278.827393,-0.000824,0.003634,0.092308,262.051666,13.349548,0.923075,-1278.827393,0.091431,0
140.51001,56.903351,-1278.827393,-0.000832,0.003608,0.09164,253.118744,12.894484,0.916399,-1278.827393,0.090677,0
140.960007,54.272537,-1278.827393,-0.000836,0.00358,0.090928,241.416306,12.298333,0.909283,-1278.827393,0.089931,0
141.410004,51.708382,-1278.782837,-0.000832,0.003553,0.090252,230.010376,11.717286,0.902516,-1278.782837,0.089177,0
141.860001,48.62104,-1278.871826,-0.000832,0.003523,0.089489,216.277191,11.017685,0.894885,-1278.871826,0.08843,0
142.310013,45.628654,-1278.782837,-0.000854,0.003495,0.088777,202.966385,10.339602,0.88777,-1278.782837,0.087676,0
142.76001,41.917969,-1278.827393,-0.000828,0.003461,0.087919,186.460434,9.498748,0.879186,-1278.827393,0.08693,0
143.210007,38.657471,-1278.827393,-0.000832,0.003432,0.087181,171.957016,8.759909,0.871813,-1278.827393,0.086184,0
143.660004,35.758926,-1278.782837,-0.000828,0.003405,0.086479,159.063644,8.103088,0.864788,-1278.782837,0.08543,0
144.110001,32.638443,-1278.827393,-0.000845,0.003377,0.085769,145.183044,7.395977,0.857687,-1278.827393,0.084685,0
144.560013,28.946747,-1278.871826,-0.000832,0.003342,0.084892,128.761566,6.559427,0.848922,-1278.871826,0.083929,0
145.01001,26.258957,-1278.827393,-0.000828,0.003318,0.084276,116.805672,5.950365,0.84276,-1278.827393,0.083184,0
145.460007,23.22226,-1278.782837,-0.000832,0.003294,0.083669,103.297768,5.262239,0.836689,-1278.782837,0.082429,0
145.910004,19.167496,-1278.827393,-0.000849,0.003255,0.082689,85.261276,4.343417,0.826894,-1278.827393,0.081684,0
146.360001,16.457375,-1278.871826,-0.000858,0.003231,0.082073,73.206055,3.729295,0.820732,-1278.871826,0.080929,0
146.810013,13.32386,-1278.871826,-0.000858,0.0032,0.081275,59.26749,3.01923,0.812753,-1278.871826,0.080184,0
147.26001,9.866005,-1278.871826,-0.000862,0.003167,0.080443,43.886181,2.235669,0.804426,-1278.871826,0.079428,0
147.710007,6.360863,-1278.827393,-0.000867,0.003137,0.07968,28.294531,1.441392,0.796796,-1278.827393,0.078683,0
148.160004,3.94268,-1278.827393,-0.000875,0.003113,0.079073,17.537918,0.893424,0.790725,-1278.827393,0.077928,0
148.610001,0.854591,-1278.871826,-0.000858,0.003084,0.078335,3.801412,0.193653,0.783352,-1278.871826,0.077183,0
149.060013,-2.049911,-1278.782837,-0.00088,0.003049,0.077451,-9.118462,-0.464517,0.774511,-1278.782837,0.076428,0
149.51001,-0.103523,-1278.782837,-0.000936,0.003017,0.076644,-0.460494,-0.023459,0.766441,-1278.782837,0.075683,0
149.960007,-0.013031,-1278.871826,-0.00097,0.002992,0.075995,-0.057965,-0.002953,0.759946,-1278.871826,0.074927,0
150.410004,0.002975,-1278.827393,-0.001005,0.002964,0.075292,0.013236,0.000674,0.752922,-1278.827393,0.074182,0
150.860001,-0.005219,-1278.827393,-0.001039,0.002937,0.07459,-0.023213,-0.001183,0.745897,-1278.827393,0.073427,0
151.310013,-0.02681,-1278.827393,-0.001087,0.002897,0.073592,-0.119255,-0.006075,0.73592,-1278.827393,0.072682,0
151.76001,-0.040588,-1278.827393,-0.001134,0.00287,0.072908,-0.180546,-0.009197,0.729077,-1278.827393,0.071927,0
152.210007,-0.019363,-1278.827393,-0.001177,0.002852,0.072447,-0.086133,-0.004388,0.724474,-1278.827393,0.071182,0
152.660004,-0.032394,-1278.871826,-0.001212,0.002812,0.071424,-0.144098,-0.007341,0.71424,-1278.871826,0.070426,0
153.110001,-0.052132,-1278.871826,-0.001242,0.002785,0.07074,-0.231893,-0.011813,0.707397,-1278.871826,0.069681,0
153.560013,-0.043198,-1278.871826,-0.001285,0.002754,0.069958,-0.192153,-0.009789,0.699585,-1278.871826,0.068926,0
154.01001,-0.004097,-1278.871826,-0.001337,0.002732,0.069386,-0.018224,-0.000928,0.693862,-1278.871826,0.068181,0
154.460007,0.013031,-1278.871826,-0.001358,0.002699,0.068563,0.057965,0.002953,0.685626,-1278.871826,0.067426,0
154.910004,-0.009308,-1278.91626,-0.00141,0.002665,0.067695,-0.041403,-0.002109,0.676951,-1278.91626,0.066681,0
155.360001,-0.051758,-1278.827393,-0.001444,0.002635,0.066932,-0.23023,-0.011728,0.669321,-1278.827393,0.065925,0
155.810013,-0.021973,-1278.827393,-0.001483,0.002609,0.066264,-0.097739,-0.004979,0.662644,-1278.827393,0.06518,0
156.26001,0.005585,-1278.91626,-0.001505,0.002577,0.065467,0.024842,0.001266,0.654666,-1278.91626,0.064425,0
156.710007,0.016014,-1278.91626,-0.001556,0.002549,0.064746,0.071234,0.003629,0.647459,-1278.91626,0.06368,0
157.160004,0.002975,-1278.871826,-0.001574,0.002516,0.063906,0.013236,0.000674,0.639057,-1278.871826,0.062925,0
157.610001,-0.036865,-1278.91626,-0.001608,0.00249,0.063246,-0.163985,-0.008354,0.632456,-1278.91626,0.06218,0
158.060013,-0.02681,-1278.827393,-0.001664,0.002454,0.062336,-0.119255,-0.006075,0.623357,-1278.827393,0.061424,0
158.51001,-0.023087,-1278.871826,-0.001694,0.002429,0.061685,-0.102694,-0.005231,0.616847,-1278.871826,0.060679,0
158.960007,-0.01825,-1278.91626,-0.001729,0.002395,0.060844,-0.081178,-0.004135,0.608445,-1278.91626,0.059925,0
159.410004,-0.028305,-1278.827393,-0.001759,0.002367,0.060133,-0.125907,-0.006414,0.601329,-1278.827393,0.059179,0
159.860001,-0.055855,-1278.871826,-0.001785,0.002337,0.059361,-0.248455,-0.012657,0.593608,-1278.871826,0.058425,0
160.310013,-0.055115,-1278.871826,-0.001807,0.00231,0.058684,-0.245163,-0.012489,0.58684,-1278.871826,0.057679,0
160.76001,-0.066284,-1278.91626,-0.001841,0.002282,0.057956,-0.294847,-0.01502,0.579558,-1278.91626,0.056925,0
161.210007,-0.030907,-1278.871826,-0.001888,0.002252,0.057193,-0.13748,-0.007004,0.571928,-1278.871826,0.056178,0
161.660004,-0.010803,-1278.91626,-0.001906,0.002225,0.056525,-0.048055,-0.002448,0.565251,-1278.91626,0.055424,0
162.110001,-0.047668,-1278.871826,-0.00194,0.002196,0.055788,-0.21204,-0.010802,0.557878,-1278.871826,0.054678,0
162.560013,-0.033516,-1278.91626,-0.001975,0.002168,0.05506,-0.149086,-0.007595,0.550596,-1278.91626,0.053924,0
163.01001,-0.049896,-1278.827393,-0.002013,0.002134,0.054201,-0.22195,-0.011307,0.542012,-1278.827393,0.053178,0
163.460007,-0.067032,-1278.960815,-0.002026,0.002104,0.053438,-0.298173,-0.01519,0.534382,-1278.960815,0.052431,0
163.910004,-0.079315,-1278.91626,-0.002074,0.002073,0.052649,-0.352812,-0.017973,0.526494,-1278.91626,0.051677,0
164.360001,-0.063675,-1278.960815,-0.002091,0.002044,0.051912,-0.28324,-0.014429,0.519121,-1278.960815,0.050931,0
164.810013,-0.059212,-1278.827393,-0.00213,0.002015,0.051191,-0.263387,-0.013418,0.511915,-1278.827393,0.050177,0
165.26001,-0.099426,-1278.960815,-0.002147,0.001985,0.050412,-0.44227,-0.02253,0.504118,-1278.960815,0.049431,0
165.710007,-0.082298,-1278.91626,-0.002199,0.001957,0.049709,-0.366081,-0.018649,0.497093,-1278.91626,0.048677,0
166.160004,-0.043571,-1278.91626,-0.002229,0.001925,0.048893,-0.193816,-0.009873,0.488933,-1278.91626,0.04793,0
166.610001,-0.080803,-1278.91626,-0.002255,0.001897,0.048191,-0.359429,-0.01831,0.481908,-1278.91626,0.047176,0
167.060013,-0.082298,-1278.960815,-0.002302,0.001864,0.047351,-0.366081,-0.018649,0.473505,-1278.960815,0.04643,0
167.51001,-0.087509,-1278.960815,-0.002302,0.001839,0.0467,-0.38926,-0.01983,0.466995,-1278.960815,0.045676,0
167.960007,-0.076714,-1278.871826,-0.002358,0.001813,0.046058,-0.341239,-0.017384,0.460576,-1278.871826,0.04493,0
168.410004,-0.064796,-1278.91626,-0.002367,0.001788,0.045425,-0.288229,-0.014683,0.454248,-1278.91626,0.044176,0
168.860001,-0.088997,-1278.960815,-0.002406,0.001747,0.044385,-0.395878,-0.020167,0.443847,-1278.960815,0.043429,0
169.310013,-0.083412,-1278.91626,-0.002427,0.001722,0.043743,-0.371036,-0.018901,0.437428,-1278.91626,0.042675,0
169.76001,-0.060326,-1278.91626,-0.002475,0.001692,0.042971,-0.268342,-0.01367,0.429707,-1278.91626,0.041929,0
170.210007,-0.059952,-1278.871826,-0.002505,0.001659,0.042147,-0.266679,-0.013585,0.421471,-1278.871826,0.041175,0
170.660004,-0.080803,-1278.91626,-0.002522,0.001631,0.041419,-0.359429,-0.01831,0.414189,-1278.91626,0.04043,0
171.110001,-0.053253,-1278.871826,-0.002565,0.001601,0.040654,-0.236882,-0.012067,0.406543,-1278.871826,0.039675,0
171.560013,-0.078201,-1278.91626,-0.002583,0.001582,0.040177,-0.347857,-0.017721,0.401774,-1278.91626,0.03893,0
172.01001,-0.088257,-1278.871826,-0.002634,0.001543,0.039181,-0.392586,-0.019999,0.391812,-1278.871826,0.038174,0
172.460007,-0.078575,-1278.871826,-0.002665,0.001512,0.0384,-0.34952,-0.017805,0.384,-1278.871826,0.03743,0
172.910004,-0.05027,-1278.871826,-0.002686,0.00148,0.037586,-0.223612,-0.011391,0.375855,-1278.871826,0.036674,0
173.360001,-0.055855,-1278.871826,-0.002725,0.001456,0.036995,-0.248455,-0.012657,0.369951,-1278.871826,0.035929,0
173.810013,-0.052879,-1278.871826,-0.002772,0.001423,0.036146,-0.235219,-0.011983,0.361457,-1278.871826,0.035174,0
174.26001,-0.063309,-1278.871826,-0.002764,0.001395,0.035434,-0.281611,-0.014346,0.354342,-1278.871826,0.034429,0
174.710007,-0.048409,-1279.005249,-0.002794,0.001367,0.034723,-0.215332,-0.01097,0.347226,-1279.005249,0.033673,0
175.160004,-0.039474,-1278.871826,-0.002833,0.001339,0.034003,-0.175591,-0.008945,0.340035,-1278.871826,0.032929,0
175.610016,0.00074,-1278.91626,-0.002867,0.001303,0.033101,0.003292,0.000168,0.331012,-1278.91626,0.032173,0
176.060013,0.010796,-1278.960815,-0.002884,0.001275,0.032382,0.048021,0.002446,0.32382,-1278.960815,0.031428,0
176.51001,-0.005219,-1278.91626,-0.002923,0.001242,0.031549,-0.023213,-0.001183,0.315494,-1278.91626,0.030673,0
176.960007,-0.058464,-1278.91626,-0.002953,0.001216,0.030898,-0.260061,-0.013248,0.308984,-1278.91626,0.029928,0
177.410004,0.022339,-1278.91626,-0.002992,0.001186,0.030126,0.099368,0.005062,0.301262,-1278.91626,0.029172,0
177.860016,0.030159,-1278.871826,-0.003035,0.001164,0.029572,0.134154,0.006834,0.295721,-1278.871826,0.028428,0
178.310013,0.015266,-1278.871826,-0.003048,0.001126,0.0286,0.067908,0.003459,0.286002,-1278.871826,0.027672,0
178.76001,-0.032394,-1278.91626,-0.003078,0.001099,0.027923,-0.144098,-0.007341,0.279234,-1278.91626,0.026927,0
179.210007,-0.021225,-1278.91626,-0.003113,0.001065,0.027057,-0.094413,-0.00481,0.270575,-1278.91626,0.026172,0
179.660004,-0.03463,-1278.91626,-0.003139,0.00104,0.026406,-0.154041,-0.007847,0.264065,-1278.91626,0.025427,0
180.110016,-0.021973,-1278.91626,-0.003178,0.001015,0.025774,-0.097739,-0.004979,0.257736,-1278.91626,0.024671,0
180.560013,-0.019363,-1278.960815,-0.003195,0.000977,0.024827,-0.086133,-0.004388,0.248274,-1278.960815,0.023927,0
181.01001,-0.048782,-1278.960815,-0.003238,0.000953,0.024204,-0.216995,-0.011054,0.242036,-1278.960815,0.023171,0
181.460007,-0.035004,-1279.005249,-0.003272,0.00092,0.02338,-0.155704,-0.007932,0.233801,-1279.005249,0.022426,0
181.910004,-0.058838,-1278.960815,-0.00329,0.000897,0.022773,-0.261724,-0.013333,0.22773,-1278.960815,0.021671,0
182.360016,-0.055115,-1278.960815,-0.003328,0.000864,0.021949,-0.245163,-0.012489,0.219494,-1278.960815,0.020926,0
182.810013,-0.035378,-1278.91626,-0.00335,0.000833,0.021159,-0.157367,-0.008017,0.211591,-1278.91626,0.02018,0
183.26001,-0.017876,-1278.91626,-0.00338,0.000811,0.020596,-0.079515,-0.004051,0.205959,-1278.91626,0.019426,0
183.710007,-0.038727,-1278.960815,-0.003415,0.000774,0.019659,-0.172265,-0.008776,0.196587,-1278.960815,0.018679,0
184.160004,-0.029419,-1278.91626,-0.003428,0.000753,0.01913,-0.130862,-0.006666,0.191304,-1278.91626,0.017925,0
184.610016,-0.05809,-1279.005249,-0.003471,0.000713,0.018107,-0.258398,-0.013163,0.181069,-1279.005249,0.017179,0
185.060013,-0.090118,-1278.91626,-0.003514,0.00069,0.017518,-0.400867,-0.020421,0.17518,-1278.91626,0.016425,0
185.51001,-0.062561,-1279.005249,-0.003523,0.00066,0.016755,-0.278285,-0.014177,0.16755,-1279.005249,0.015679,0
185.960007,-0.065536,-1278.960815,-0.003561,0.000629,0.015983,-0.291521,-0.014851,0.159829,-1278.960815,0.014925,0
186.410004,-0.102036,-1278.960815,-0.003596,0.000597,0.015176,-0.453877,-0.023122,0.151759,-1278.960815,0.014178,0
186.860016,-0.097191,-1278.91626,-0.003617,0.000573,0.01456,-0.432327,-0.022024,0.145597,-1278.91626,0.013424,0
187.310013,-0.06591,-1279.005249,-0.003656,0.000544,0.013822,-0.293184,-0.014935,0.138224,-1279.005249,0.012678,0
187.76001,-0.059212,-1279.005249,-0.003704,0.000514,0.013059,-0.263387,-0.013418,0.130594,-1279.005249,0.011924,0
188.210007,-0.100166,-1278.91626,-0.003708,0.000481,0.01221,-0.445562,-0.022698,0.122101,-1278.91626,0.011178,0
188.660004,-0.10836,-1278.960815,-0.003742,0.000451,0.011456,-0.482011,-0.024555,0.114561,-1278.960815,0.010424,0
189.110016,-0.106125,-1278.91626,-0.003781,0.000427,0.01084,-0.472067,-0.024048,0.108399,-1278.91626,0.009677,0
189.560013,-0.083412,-1278.91626,-0.003807,0.000394,0.010007,-0.371036,-0.018901,0.100073,-1278.91626,0.008923,0
190.01001,-0.072617,-1278.960815,-0.003846,0.000362,0.0092,-0.323015,-0.016455,0.092003,-1278.960815,0.008177,0
190.460007,-0.08416,-1279.005249,-0.003863,0.000331,0.008402,-0.374362,-0.019071,0.084025,-1279.005249,0.007423,0
190.910004,-0.081177,-1278.960815,-0.003915,0.000295,0.007493,-0.361092,-0.018395,0.074926,-1278.960815,0.006677,0
191.360016,-0.063309,-1278.960815,-0.003919,0.000278,0.007058,-0.281611,-0.014346,0.070581,-1278.960815,0.005923,0
191.810013,-0.075592,-1278.91626,-0.003945,0.000244,0.006209,-0.33625,-0.017129,0.062087,-1278.91626,0.005176,0
192.26001,-0.056602,-1278.960815,-0.004005,0.000212,0.005385,-0.25178,-0.012826,0.053851,-1278.960815,0.004422,0
192.710007,-0.078575,-1278.960815,-0.004014,0.000191,0.004855,-0.34952,-0.017805,0.048553,-1278.960815,0.003676,0
193.160004,-0.081177,-1278.960815,-0.004053,0.000157,0.003997,-0.361092,-0.018395,0.039968,-1278.960815,0.002922,0
193.610016,-0.080803,-1278.871826,-0.004083,0.000131,0.003322,-0.359429,-0.01831,0.033216,-1278.871826,0.002176,0
194.060013,-0.061813,-1278.91626,-0.004113,0.000091,0.002315,-0.27496,-0.014007,0.023148,-1278.91626,0.001422,0
194.51001,-0.077827,-1278.91626,-0.004135,0.000068,0.001726,-0.346194,-0.017636,0.017259,-1278.91626,0.000675,0
194.960007,-0.060699,-1278.960815,-0.004161,0.000036,0.00091,-0.270005,-0.013755,0.009099,-1278.960815,-0.000079,0
195.410004,-0.055489,-1278.91626,-0.004191,0.000005,0.000121,-0.246826,-0.012574,0.001211,-1278.91626,-0.000825,0
195.700012,-0.024582,-1278.91626,-0.004212,0.000002,0.000061,-0.109346,-0.00557,0.000606,-1278.91626,-0.000018,0