File: Data/compression 16/ManualNoHeating-17-16-reverse-hand-2-1_08302024_172204.csv
Time (sec),S:Load (lbs),S:HL1 (DIM),S:LVDT (in),S:Position (in),Ch:Position (mm),Ch:Load (N),Ch:Stress (MPa),Ch:Strain (mm/mm),Ch:HL1 (DIM),Set Point (),Cycles ()
0.210000,-0.095322,-123.746002,-0.009809,-0.005205,-0.132209,-0.424012,-0.021600,-1.322087,-123.746002,-0.132209,0.000000
0.580000,-0.068886,-123.834969,-0.009804,-0.005124,-0.130153,-0.306419,-0.015610,-1.301535,-123.834969,-0.129312,0.000000
0.950000,-0.074471,-123.834969,-0.009710,-0.004898,-0.124412,-0.331261,-0.016875,-1.244121,-123.834969,-0.123155,0.000000
1.320000,-0.102402,-123.834969,-0.009459,-0.004663,-0.118429,-0.455506,-0.023205,-1.184286,-123.834969,-0.116998,0.000000
1.690000,-0.101280,-123.834969,-0.009227,-0.004414,-0.112106,-0.450517,-0.022950,-1.121063,-123.834969,-0.110823,0.000000
2.060000,-0.147087,-123.879448,-0.008977,-0.004170,-0.105906,-0.654276,-0.033330,-1.059055,-123.879448,-0.104666,0.000000
2.430000,-0.097183,-123.968414,-0.008718,-0.003921,-0.099601,-0.432293,-0.022022,-0.996010,-123.968414,-0.098508,0.000000
2.800000,-0.106491,-124.012894,-0.008472,-0.003679,-0.093444,-0.473696,-0.024131,-0.934438,-124.012894,-0.092334,0.000000
3.170000,-0.065163,-124.057373,-0.008226,-0.003446,-0.087529,-0.289858,-0.014766,-0.875291,-124.057373,-0.086176,0.000000
3.540000,-0.090111,-124.057373,-0.007963,-0.003198,-0.081233,-0.400833,-0.020419,-0.812333,-124.057373,-0.080002,0.000000
3.910000,-0.099045,-124.057373,-0.007722,-0.002952,-0.074980,-0.440573,-0.022444,-0.749803,-124.057373,-0.073844,0.000000
4.280000,-0.109100,-124.101852,-0.007489,-0.002716,-0.068979,-0.485303,-0.024722,-0.689793,-124.101852,-0.067687,0.000000
4.650000,-0.067764,-124.190819,-0.007217,-0.002471,-0.062770,-0.301431,-0.015356,-0.627698,-124.190819,-0.061512,0.000000
5.020000,-0.042076,-124.146332,-0.006946,-0.002227,-0.056578,-0.187164,-0.009535,-0.565777,-124.146332,-0.055355,0.000000
5.390000,-0.075584,-124.146332,-0.006713,-0.001985,-0.050412,-0.336216,-0.017128,-0.504118,-124.146332,-0.049181,0.000000
5.760000,-0.089737,-124.190819,-0.006480,-0.001747,-0.044376,-0.399170,-0.020335,-0.443760,-124.190819,-0.043023,0.000000
6.130000,-0.113945,-124.279778,-0.006213,-0.001499,-0.038071,-0.506853,-0.025820,-0.380711,-124.279778,-0.036866,0.000000
6.500000,-0.142616,-124.279778,-0.005976,-0.001254,-0.031845,-0.634389,-0.032317,-0.318446,-124.279778,-0.030691,0.000000
6.870000,-0.093086,-124.279778,-0.005700,-0.001008,-0.025601,-0.414068,-0.021094,-0.256007,-124.279778,-0.024534,0.000000
7.240000,-0.057716,-124.279778,-0.005480,-0.000769,-0.019521,-0.256735,-0.013079,-0.195214,-124.279778,-0.018359,0.000000
7.610000,-0.058090,-124.368736,-0.005226,-0.000525,-0.013338,-0.258398,-0.013163,-0.133380,-124.368736,-0.012202,0.000000
7.980000,-0.012283,-124.413223,-0.004997,-0.000288,-0.007320,-0.054639,-0.002783,-0.073196,-124.413223,-0.006044,0.000000
8.350000,0.222679,-124.413223,-0.004919,-0.000000,-0.000000,0.990526,0.050460,-0.000000,-124.413223,0.000251,0.000000
8.720000,0.160126,-124.457703,-0.004924,-0.000000,-0.000000,0.712275,0.036285,-0.000000,-124.457703,0.000486,0.000000
9.090000,0.141136,-124.457703,-0.004937,-0.000000,-0.000000,0.627805,0.031982,-0.000000,-124.457703,0.001101,0.000000
9.460000,0.351524,-124.457703,-0.004911,0.000030,0.000754,1.563658,0.079657,0.007543,-124.457703,0.001726,0.000000
9.830001,0.599525,-124.591141,-0.004889,0.000055,0.001396,2.666822,0.135854,0.013962,-124.591141,0.002341,0.000000
10.200001,0.926842,-124.635628,-0.004872,0.000080,0.002038,4.122798,0.210025,0.020378,-124.635628,0.002957,0.000000
10.570001,1.370705,-124.680107,-0.004833,0.000107,0.002705,6.097199,0.310606,0.027054,-124.680107,0.003573,0.000000
10.940001,1.745689,-124.680107,-0.004825,0.000130,0.003304,7.765214,0.395579,0.033038,-124.680107,0.004189,0.000000
11.310000,2.200356,-124.635628,-0.004807,0.000152,0.003859,9.787670,0.498608,0.038591,-124.635628,0.004804,0.000000
11.680000,2.678108,-124.724586,-0.004803,0.000176,0.004466,11.912820,0.606868,0.044662,-124.724586,0.005420,0.000000
12.050000,3.130913,-124.769066,-0.004773,0.000200,0.005082,13.926995,0.709475,0.050820,-124.769066,0.006036,0.000000
12.420001,3.199799,-124.724586,-0.004747,0.000207,0.005247,14.233415,0.725085,0.052466,-124.724586,0.006652,0.000000
12.790001,3.949013,-124.858032,-0.004717,0.000243,0.006183,17.566086,0.894859,0.061830,-124.858032,0.007276,0.000000
13.160001,4.481506,-124.813545,-0.004708,0.000270,0.006851,19.934736,1.015524,0.068510,-124.813545,0.007892,0.000000
13.530001,5.035225,-124.858032,-0.004682,0.000295,0.007501,22.397799,1.140998,0.075013,-124.858032,0.008507,0.000000
13.900001,5.243752,-124.902512,-0.004678,0.000313,0.007961,23.325371,1.188251,0.079611,-124.902512,0.009123,0.000000
14.270000,6.273361,-124.946991,-0.004622,0.000349,0.008863,27.905304,1.421564,0.088631,-124.946991,0.009739,0.000000
14.640000,6.587646,-124.946991,-0.004600,0.000372,0.009453,29.303314,1.492782,0.094528,-124.946991,0.010355,0.000000
15.010001,6.938049,-124.946991,-0.004600,0.000395,0.010025,30.861984,1.572184,0.100251,-124.946991,0.010970,0.000000
15.380001,7.436279,-124.991470,-0.004583,0.000419,0.010641,33.078224,1.685085,0.106409,-124.991470,0.011586,0.000000
15.750001,7.621727,-125.080437,-0.004562,0.000436,0.011074,33.903133,1.727108,0.110742,-125.080437,0.012202,0.000000
16.120001,8.071175,-125.080437,-0.004527,0.000460,0.011681,35.902378,1.828954,0.116813,-125.080437,0.012826,0.000000
16.490002,8.606651,-125.080437,-0.004514,0.000491,0.012470,38.284298,1.950295,0.124705,-125.080437,0.013442,0.000000
16.860001,9.001732,-125.080437,-0.004493,0.000517,0.013139,40.041702,2.039822,0.131385,-125.080437,0.014057,0.000000
17.230001,9.207283,-125.124916,-0.004467,0.000540,0.013728,40.956039,2.086400,0.137282,-125.124916,0.014673,0.000000
17.600000,9.312668,-125.213875,-0.004454,0.000556,0.014118,41.424816,2.110281,0.141184,-125.213875,0.015289,0.000000
17.970001,9.743126,-125.258362,-0.004424,0.000581,0.014769,43.339588,2.207824,0.147687,-125.258362,0.015905,0.000000
18.340000,10.274132,-125.213875,-0.004402,0.000612,0.015540,45.701622,2.328151,0.155404,-125.213875,0.016521,0.000000
18.710001,10.600334,-125.213875,-0.004372,0.000641,0.016278,47.152641,2.402070,0.162777,-125.213875,0.017136,0.000000
19.080002,10.764915,-125.302841,-0.004368,0.000664,0.016867,47.884735,2.439365,0.168674,-125.302841,0.017752,0.000000
19.450001,10.962646,-125.436279,-0.004329,0.000684,0.017362,48.764286,2.484171,0.173617,-125.436279,0.018376,0.000000
19.820002,11.195755,-125.436279,-0.004312,0.000707,0.017960,49.801205,2.536994,0.179601,-125.436279,0.018992,0.000000
20.190001,11.745377,-125.391800,-0.004294,0.000735,0.018680,52.246044,2.661540,0.186800,-125.391800,0.019608,0.000000
20.560001,11.976990,-125.391800,-0.004264,0.000761,0.019330,53.276310,2.714025,0.193302,-125.391800,0.020223,0.000000
20.930000,12.210838,-125.391800,-0.004247,0.000787,0.019998,54.316521,2.767015,0.199982,-125.391800,0.020839,0.000000
21.300001,12.411926,-125.480766,-0.004217,0.000808,0.020527,55.211006,2.812583,0.205270,-125.480766,0.021455,0.000000
21.670000,12.602203,-125.480766,-0.004199,0.000829,0.021056,56.057400,2.855700,0.210561,-125.480766,0.022071,0.000000
22.040001,12.770142,-125.569725,-0.004182,0.000849,0.021577,56.804428,2.893755,0.215766,-125.569725,0.022687,0.000000
22.410002,13.547661,-125.525246,-0.004156,0.000884,0.022452,60.263004,3.069944,0.224524,-125.525246,0.023302,0.000000
22.780001,13.447487,-125.614204,-0.004135,0.000904,0.022955,59.817410,3.047244,0.229554,-125.614204,0.023927,0.000000
23.150002,13.661980,-125.703171,-0.004122,0.000928,0.023562,60.771523,3.095849,0.235625,-125.703171,0.024542,0.000000
23.520000,13.494408,-125.703171,-0.004092,0.000946,0.024039,60.026123,3.057876,0.240394,-125.703171,0.025158,0.000000
23.890001,13.898064,-125.703171,-0.004079,0.000969,0.024603,61.821674,3.149346,0.246030,-125.703171,0.025774,0.000000
24.260000,14.159096,-125.747650,-0.004061,0.000993,0.025210,62.982803,3.208497,0.252100,-125.747650,0.026389,0.000000
24.630001,14.431671,-125.747650,-0.004053,0.001019,0.025895,64.195282,3.270263,0.258951,-125.747650,0.027005,0.000000
25.000002,14.146805,-125.836609,-0.004031,0.001030,0.026164,62.928131,3.205712,0.261642,-125.836609,0.027621,0.000000
25.370001,15.030075,-125.836609,-0.003992,0.001069,0.027153,66.857117,3.405864,0.271528,-125.836609,0.028237,0.000000
25.740002,15.227432,-125.836609,-0.003980,0.001099,0.027907,67.735001,3.450586,0.279072,-125.836609,0.028861,0.000000
26.110001,15.224083,-125.881088,-0.003949,0.001120,0.028454,67.720100,3.449826,0.284537,-125.881088,0.029477,0.000000
26.480001,15.301903,-125.881088,-0.003941,0.001146,0.029113,68.066261,3.467461,0.291127,-125.881088,0.030093,0.000000
26.850000,15.220352,-125.970055,-0.003919,0.001166,0.029607,67.703506,3.448981,0.296070,-125.970055,0.030708,0.000000
27.220001,14.871071,-126.014534,-0.003898,0.001174,0.029824,66.149826,3.369833,0.298238,-126.014534,0.031324,0.000000
27.590002,15.923019,-125.970055,-0.003876,0.001213,0.030821,70.829124,3.608208,0.308212,-125.970055,0.031940,0.000000
27.960001,16.057449,-126.014534,-0.003867,0.001241,0.031532,71.427101,3.638670,0.315323,-126.014534,0.032555,0.000000
28.330002,16.008667,-126.014534,-0.003829,0.001263,0.032070,71.210106,3.627616,0.320698,-126.014534,0.033171,0.000000
28.700001,16.077560,-126.103493,-0.003824,0.001286,0.032668,71.516563,3.643227,0.326682,-126.103493,0.033787,0.000000
29.070002,16.251831,-126.147980,-0.003803,0.001309,0.033240,72.291756,3.682718,0.332405,-126.147980,0.034412,0.000000
29.440001,16.639839,-126.192459,-0.003786,0.001339,0.034004,74.017700,3.770641,0.340039,-126.192459,0.035027,0.000000
29.810001,16.701653,-126.192459,-0.003760,0.001363,0.034628,74.292664,3.784648,0.346280,-126.192459,0.035643,0.000000
30.180002,16.240280,-126.192459,-0.003747,0.001380,0.035053,72.240372,3.680100,0.350530,-126.192459,0.036259,0.000000
30.550001,16.615639,-126.281418,-0.003742,0.001408,0.035764,73.910049,3.765157,0.357642,-126.281418,0.036874,0.000000
30.920002,16.662552,-126.325897,-0.003712,0.001430,0.036311,74.118736,3.775788,0.363108,-126.325897,0.037490,0.000000
31.290001,17.139565,-126.370384,-0.003678,0.001462,0.037126,76.240593,3.883881,0.371257,-126.370384,0.038106,0.000000
31.660002,17.212173,-126.325897,-0.003678,0.001488,0.037785,76.563568,3.900334,0.377850,-126.325897,0.038721,0.000000
32.030003,17.290001,-126.370384,-0.003656,0.001514,0.038461,76.909767,3.917970,0.384613,-126.370384,0.039337,0.000000
32.400002,17.110893,-126.414864,-0.003639,0.001535,0.038990,76.113052,3.877384,0.389905,-126.414864,0.039962,0.000000
32.770000,17.278084,-126.459343,-0.003622,0.001558,0.039580,76.856758,3.915270,0.395802,-126.459343,0.040577,0.000000
33.140003,17.262077,-126.459343,-0.003604,0.001578,0.040083,76.785553,3.911643,0.400832,-126.459343,0.041193,0.000000
33.510002,17.514168,-126.459343,-0.003570,0.001604,0.040733,77.906906,3.968767,0.407334,-126.459343,0.041809,0.000000
33.880001,18.188911,-126.548309,-0.003570,0.001635,0.041531,80.908318,4.121666,0.415313,-126.548309,0.042425,0.000000
34.250000,18.112572,-126.548309,-0.003548,0.001660,0.042156,80.568741,4.104367,0.421558,-126.548309,0.043040,0.000000
34.620003,18.014641,-126.592789,-0.003518,0.001683,0.042737,80.133125,4.082176,0.427368,-126.592789,0.043656,0.000000
34.990002,17.941650,-126.637268,-0.003523,0.001701,0.043214,79.808449,4.065636,0.432137,-126.637268,0.044272,0.000000
35.360001,18.048149,-126.681747,-0.003497,0.001722,0.043743,80.282173,4.089769,0.437428,-126.681747,0.044887,0.000000
35.730003,18.518829,-126.681747,-0.003462,0.001753,0.044523,82.375870,4.196427,0.445232,-126.681747,0.045512,0.000000
36.100002,18.746719,-126.681747,-0.003462,0.001782,0.045269,83.389572,4.248067,0.452692,-126.681747,0.046128,0.000000
36.470001,18.731453,-126.770714,-0.003441,0.001805,0.045859,83.321663,4.244608,0.458589,-126.770714,0.046743,0.000000
36.840000,18.850243,-126.859673,-0.003428,0.001827,0.046405,83.850067,4.271526,0.464051,-126.859673,0.047359,0.000000
37.210003,18.755287,-126.859673,-0.003393,0.001846,0.046899,83.427681,4.250009,0.468994,-126.859673,0.047975,0.000000
37.580002,19.268044,-126.815193,-0.003397,0.001873,0.047567,85.708542,4.366201,0.475670,-126.815193,0.048590,0.000000
37.950001,19.688454,-126.904152,-0.003372,0.001901,0.048287,87.578613,4.461467,0.482869,-126.904152,0.049206,0.000000
38.320004,19.838150,-126.859673,-0.003341,0.001925,0.048903,88.244499,4.495389,0.489027,-126.859673,0.049822,0.000000
38.690002,19.987465,-126.948631,-0.003324,0.001948,0.049484,88.908684,4.529224,0.494837,-126.948631,0.050438,0.000000
39.060001,20.027687,-126.948631,-0.003324,0.001969,0.050022,89.087601,4.538339,0.500216,-126.948631,0.051062,0.000000
39.430000,20.111839,-126.993118,-0.003294,0.001994,0.050646,89.461929,4.557408,0.506457,-126.993118,0.051678,0.000000
39.800003,20.577309,-126.993118,-0.003272,0.002021,0.051339,91.532440,4.662885,0.513395,-126.993118,0.052294,0.000000
40.170002,20.852119,-127.037598,-0.003251,0.002046,0.051964,92.754860,4.725158,0.519640,-127.037598,0.052909,0.000000
40.540001,20.928452,-127.126556,-0.003229,0.002068,0.052519,93.094398,4.742455,0.525192,-127.126556,0.053525,0.000000
40.910004,20.834991,-127.082077,-0.003208,0.002091,0.053100,92.678673,4.721276,0.531002,-127.082077,0.054141,0.000000
41.280003,21.642288,-127.082077,-0.003195,0.002119,0.053811,96.269707,4.904212,0.538114,-127.082077,0.054756,0.000000
41.650002,21.892151,-127.215523,-0.003173,0.002143,0.054444,97.381149,4.960832,0.544442,-127.215523,0.055372,0.000000
42.020000,22.102547,-127.260002,-0.003139,0.002169,0.055095,98.317039,5.008509,0.550948,-127.260002,0.055988,0.000000
42.390003,22.347191,-127.260002,-0.003126,0.002193,0.055711,99.405266,5.063946,0.557106,-127.260002,0.056612,0.000000
42.760002,22.279793,-127.260002,-0.003104,0.002213,0.056222,99.105469,5.048673,0.562220,-127.260002,0.057228,0.000000
43.130001,22.419060,-127.260002,-0.003087,0.002235,0.056777,99.724960,5.080232,0.567772,-127.260002,0.057844,0.000000
43.500004,22.648071,-127.304482,-0.003087,0.002255,0.057272,100.743652,5.132126,0.572715,-127.304482,0.058460,0.000000
43.870003,23.746941,-127.393440,-0.003061,0.002291,0.058191,105.631668,5.381134,0.581909,-127.393440,0.059075,0.000000
44.240002,23.802422,-127.393440,-0.003031,0.002314,0.058781,105.878456,5.393706,0.587806,-127.393440,0.059691,0.000000
44.610001,23.768166,-127.482407,-0.003009,0.002334,0.059284,105.726082,5.385943,0.592836,-127.482407,0.060307,0.000000
44.980003,23.883232,-127.393440,-0.002988,0.002356,0.059847,106.237923,5.412018,0.598471,-127.393440,0.060922,0.000000
45.350002,24.407898,-127.437927,-0.002966,0.002379,0.060437,108.571754,5.530909,0.604368,-127.437927,0.061538,0.000000
45.720001,24.666328,-127.571365,-0.002953,0.002401,0.060992,109.721306,5.589470,0.609917,-127.571365,0.062163,0.000000
46.090004,25.359314,-127.571365,-0.002928,0.002429,0.061685,112.803864,5.746502,0.616855,-127.571365,0.062778,0.000000
46.460003,26.232155,-127.571365,-0.002919,0.002457,0.062414,116.686455,5.944291,0.624141,-127.571365,0.063394,0.000000
46.830002,26.133850,-127.615852,-0.002897,0.002480,0.062986,116.249168,5.922015,0.629863,-127.615852,0.064010,0.000000
47.200001,26.773582,-127.660332,-0.002871,0.002508,0.063706,119.094841,6.066980,0.637062,-127.660332,0.064626,0.000000
47.570004,26.692780,-127.660332,-0.002854,0.002529,0.064235,118.735413,6.048670,0.642353,-127.660332,0.065241,0.000000
47.940002,26.813057,-127.749290,-0.002820,0.002551,0.064799,119.270432,6.075925,0.647989,-127.749290,0.065857,0.000000
48.310001,27.013390,-127.660332,-0.002811,0.002572,0.065328,120.161560,6.121322,0.653280,-127.660332,0.066473,0.000000
48.680004,27.818085,-127.749290,-0.002781,0.002597,0.065970,123.741020,6.303668,0.659696,-127.749290,0.067097,0.000000
49.050003,28.467880,-127.793770,-0.002772,0.002627,0.066733,126.631454,6.450914,0.667330,-127.793770,0.067713,0.000000
49.420002,28.572517,-127.793770,-0.002742,0.002645,0.067192,127.096909,6.474625,0.671925,-127.793770,0.068329,0.000000
49.790001,29.158630,-127.927216,-0.002742,0.002673,0.067895,129.704071,6.607440,0.678950,-127.927216,0.068944,0.000000
50.160004,29.194374,-127.927216,-0.002708,0.002693,0.068398,129.863068,6.615540,0.683980,-127.927216,0.069560,0.000000
50.530003,29.506424,-127.927216,-0.002677,0.002713,0.068901,131.251129,6.686251,0.689010,-127.927216,0.070176,0.000000
50.900002,30.384476,-127.927216,-0.002673,0.002741,0.069612,135.156891,6.885221,0.696122,-127.927216,0.070792,0.000000
51.270004,31.288597,-127.927216,-0.002656,0.002771,0.070393,139.178635,7.090097,0.703926,-127.927216,0.071407,0.000000
51.640003,31.640495,-128.016174,-0.002639,0.002795,0.070991,140.743958,7.169838,0.709910,-128.016174,0.072023,0.000000
52.010002,32.019196,-128.016174,-0.002600,0.002819,0.071607,142.428497,7.255653,0.716068,-128.016174,0.072647,0.000000
52.380001,32.639565,-128.105133,-0.002596,0.002843,0.072205,145.188034,7.396231,0.722052,-128.105133,0.073263,0.000000
52.750004,32.984756,-128.149612,-0.002565,0.002864,0.072751,146.723526,7.474452,0.727514,-128.149612,0.073879,0.000000
53.120003,34.039314,-128.149612,-0.002552,0.002896,0.073558,151.414429,7.713418,0.735579,-128.149612,0.074495,0.000000
53.490002,34.456001,-128.149612,-0.002522,0.002920,0.074174,153.267944,7.807841,0.741737,-128.149612,0.075110,0.000000
53.860004,34.617607,-128.194107,-0.002505,0.002940,0.074685,153.986801,7.844462,0.746854,-128.194107,0.075726,0.000000
54.230003,35.205956,-128.238586,-0.002488,0.002962,0.075240,156.603912,7.977783,0.752403,-128.238586,0.076342,0.000000
54.600002,36.051247,-128.238586,-0.002466,0.002988,0.075891,160.363953,8.169330,0.758909,-128.238586,0.076958,0.000000
54.970001,36.028526,-128.283066,-0.002458,0.003005,0.076316,160.262894,8.164181,0.763156,-128.283066,0.077573,0.000000
55.340004,37.794693,-128.372025,-0.002445,0.003039,0.077200,168.119186,8.564400,0.772001,-128.372025,0.078197,0.000000
55.710003,38.175629,-128.460983,-0.002423,0.003062,0.077773,169.813675,8.650722,0.777728,-128.460983,0.078813,0.000000
56.080002,38.680939,-128.460983,-0.002406,0.003083,0.078319,172.061401,8.765226,0.783189,-128.460983,0.079429,0.000000
56.450005,39.003036,-128.416504,-0.002389,0.003102,0.078788,173.494171,8.838214,0.787875,-128.416504,0.080045,0.000000
56.820004,39.518028,-128.416504,-0.002367,0.003129,0.079481,175.784973,8.954913,0.794813,-128.416504,0.080661,0.000000
57.190002,41.947388,-128.505463,-0.002367,0.003165,0.080400,186.591293,9.505414,0.804003,-128.505463,0.081276,0.000000
57.560001,42.444504,-128.594437,-0.002345,0.003187,0.080947,188.802582,9.618062,0.809468,-128.594437,0.081892,0.000000
57.930004,42.543182,-128.594437,-0.002302,0.003204,0.081372,189.241531,9.640423,0.813718,-128.594437,0.082508,0.000000
58.300003,43.440231,-128.505463,-0.002294,0.003231,0.082057,193.231796,9.843698,0.820569,-128.505463,0.083123,0.000000
58.670002,43.712059,-128.549942,-0.002268,0.003248,0.082499,194.440948,9.905294,0.824990,-128.549942,0.083748,0.000000
59.040001,45.601105,-128.683395,-0.002276,0.003282,0.083366,202.843842,10.333358,0.833661,-128.683395,0.084363,0.000000
59.410004,46.535759,-128.683395,-0.002246,0.003307,0.084008,207.001389,10.545154,0.840080,-128.683395,0.084979,0.000000
59.780003,47.152786,-128.727875,-0.002229,0.003327,0.084511,209.746063,10.684975,0.845110,-128.727875,0.085595,0.000000
60.150002,48.215904,-128.772354,-0.002212,0.003352,0.085153,214.475052,10.925880,0.851529,-128.772354,0.086211,0.000000
60.520004,48.807610,-128.727875,-0.002203,0.003373,0.085673,217.107086,11.059962,0.856730,-128.727875,0.086827,0.000000
60.890003,50.343643,-128.772354,-0.002186,0.003402,0.086419,223.939713,11.408033,0.864190,-128.772354,0.087442,0.000000
61.260002,51.516243,-128.816833,-0.002160,0.003429,0.087104,229.155701,11.673747,0.871041,-128.816833,0.088058,0.000000
61.630001,52.304932,-128.861313,-0.002151,0.003452,0.087676,232.663956,11.852467,0.876763,-128.861313,0.088674,0.000000
62.000004,53.302139,-128.861313,-0.002139,0.003476,0.088292,237.099762,12.078438,0.882921,-128.861313,0.089298,0.000000
62.370003,54.281479,-128.905792,-0.002113,0.003497,0.088821,241.456070,12.300359,0.888213,-128.905792,0.089914,0.000000
62.740002,55.235130,-128.994751,-0.002113,0.003518,0.089350,245.698135,12.516459,0.893500,-128.994751,0.090529,0.000000
63.110004,56.979691,-129.039246,-0.002095,0.003551,0.090200,253.458328,12.911782,0.902001,-129.039246,0.091145,0.000000
63.480003,58.124367,-129.083725,-0.002074,0.003573,0.090746,258.550110,13.171169,0.907463,-129.083725,0.091761,0.000000
63.850002,59.562469,-129.128204,-0.002061,0.003600,0.091449,264.947083,13.497048,0.914487,-129.128204,0.092377,0.000000
64.220001,59.878242,-129.083725,-0.002048,0.003617,0.091874,266.351715,13.568604,0.918738,-129.083725,0.092993,0.000000
64.590004,61.034454,-129.128204,-0.002026,0.003638,0.092394,271.494812,13.830605,0.923942,-129.128204,0.093608,0.000000
64.960007,63.143944,-129.172684,-0.002018,0.003673,0.093296,280.878296,14.308622,0.932961,-129.172684,0.094224,0.000000
65.330002,64.592476,-129.217163,-0.002005,0.003697,0.093895,287.321686,14.636864,0.938945,-129.217163,0.094848,0.000000
65.700005,65.852211,-129.217163,-0.001992,0.003721,0.094519,292.925262,14.922324,0.945187,-129.217163,0.095464,0.000000
66.070000,65.819817,-129.217163,-0.001966,0.003722,0.094536,292.781158,14.914984,0.945361,-129.217163,0.016600,0.000000
66.440002,64.543694,-129.217163,-0.001979,0.003722,0.094527,287.104675,14.625810,0.945274,-129.217163,294.500488,0.000000
66.810005,65.776985,-129.306122,-0.001953,0.003696,0.093868,292.590637,14.905278,0.938684,-129.306122,294.500488,0.000000
67.180000,64.930962,-129.350601,-0.001940,0.003743,0.095083,288.827332,14.713567,0.950826,-129.350601,294.500488,0.000000
67.550003,65.028145,-129.395081,-0.001927,0.003755,0.095369,289.259644,14.735588,0.953688,-129.395081,294.500488,0.000000
67.920006,65.289925,-129.350601,-0.001923,0.003766,0.095646,290.424103,14.794909,0.956462,-129.350601,294.500488,0.000000
68.290001,65.867104,-129.395081,-0.001919,0.003781,0.096028,292.991516,14.925699,0.960277,-129.395081,294.500488,0.000000
68.660004,65.389732,-129.439575,-0.001919,0.003780,0.096002,290.868042,14.817525,0.960016,-129.439575,294.500488,0.000000
69.030006,64.810310,-129.528534,-0.001914,0.003780,0.096010,288.290649,14.686226,0.960103,-129.528534,294.500488,0.000000
69.400002,64.264793,-129.439575,-0.001906,0.003780,0.096010,285.864075,14.562611,0.960103,-129.439575,294.500488,0.000000
69.770004,66.687065,-129.484055,-0.001880,0.003677,0.093392,296.638885,15.111506,0.933915,-129.484055,294.500488,0.000000
70.140007,66.091652,-129.573013,-0.001880,0.003678,0.093409,293.990356,14.976583,0.934089,-129.573013,294.500488,0.000000
70.510002,65.548363,-129.528534,-0.001884,0.003736,0.094901,291.573669,14.853471,0.949006,-129.528534,294.500488,0.000000
70.880005,65.191994,-129.573013,-0.001888,0.003787,0.096201,289.988464,14.772717,0.962011,-129.573013,294.500488,0.000000
71.250000,64.806221,-129.706451,-0.001867,0.003798,0.096470,288.272461,14.685300,0.964702,-129.706451,294.500488,0.000000
71.620003,65.298500,-129.617493,-0.001867,0.003813,0.096860,290.462250,14.796852,0.968604,-129.617493,294.500488,0.000000
71.990005,65.008781,-129.661972,-0.001876,0.003815,0.096895,289.173492,14.731200,0.968948,-129.661972,294.500488,0.000000
72.360001,64.724297,-129.750931,-0.001880,0.003815,0.096904,287.908051,14.666736,0.969035,-129.750931,294.500488,0.000000
72.730003,65.659691,-129.795410,-0.001871,0.003828,0.097233,292.068878,14.878698,0.972332,-129.795410,294.500488,0.000000
73.100006,65.343925,-129.795410,-0.001880,0.003828,0.097233,290.664307,14.807145,0.972332,-129.795410,294.500488,0.000000
73.470001,65.034477,-129.795410,-0.001867,0.003828,0.097233,289.287811,14.737023,0.972332,-129.795410,294.500488,0.000000
73.840004,64.752220,-129.795410,-0.001854,0.003828,0.097242,288.032257,14.673063,0.972419,-129.795410,294.500488,0.000000
74.210007,64.484108,-129.884384,-0.001871,0.003829,0.097259,286.839630,14.612308,0.972593,-129.884384,294.500488,0.000000
74.580002,66.357155,-129.973343,-0.001850,0.003803,0.096600,295.171356,15.036746,0.966000,-129.973343,294.500488,0.000000
74.950005,66.021263,-130.062302,-0.001841,0.003803,0.096600,293.677246,14.960632,0.966000,-130.062302,294.500488,0.000000
75.320007,65.779228,-129.928864,-0.001841,0.003805,0.096635,292.600616,14.905787,0.966348,-129.928864,294.500488,0.000000
75.690002,65.491386,-130.062302,-0.001837,0.003813,0.096860,291.320251,14.840561,0.968604,-130.062302,294.500488,0.000000
76.060005,65.292168,-130.062302,-0.001841,0.003827,0.097207,290.434082,14.795417,0.972071,-130.062302,294.500488,0.000000
76.430000,65.037468,-130.106781,-0.001845,0.003827,0.097207,289.301117,14.737701,0.972071,-130.106781,294.500488,0.000000
76.800003,65.828011,-130.106781,-0.001845,0.003855,0.097918,292.817627,14.916841,0.979183,-130.106781,294.500488,0.000000
77.170006,65.580009,-130.151260,-0.001837,0.003855,0.097918,291.714447,14.860642,0.979183,-130.151260,294.500488,0.000000
77.540001,65.370369,-130.106781,-0.001850,0.003855,0.097918,290.781921,14.813137,0.979183,-130.106781,294.500488,0.000000
77.910004,65.209129,-130.151260,-0.001837,0.003855,0.097918,290.064697,14.776600,0.979183,-130.151260,294.500488,0.000000
78.280006,65.013634,-130.329193,-0.001841,0.003855,0.097918,289.195099,14.732300,0.979183,-130.329193,294.500488,0.000000
78.650002,64.841591,-130.240219,-0.001824,0.003855,0.097918,288.429810,14.693315,0.979183,-130.240219,294.500488,0.000000
79.020004,64.681847,-130.284698,-0.001832,0.003855,0.097918,287.719238,14.657116,0.979183,-130.284698,294.500488,0.000000
79.390007,64.490440,-130.373672,-0.001837,0.003855,0.097927,286.867798,14.613743,0.979270,-130.373672,294.500488,0.000000
79.760002,64.340004,-130.373672,-0.001832,0.003855,0.097927,286.198639,14.579654,0.979270,-130.373672,294.500488,0.000000
80.130005,64.160530,-130.418152,-0.001824,0.003855,0.097927,285.400299,14.538984,0.979270,-130.418152,294.500488,0.000000
80.500008,66.564568,-130.418152,-0.001807,0.003717,0.094415,296.093994,15.083747,0.944146,-130.418152,294.500488,0.000000
80.870003,66.363472,-130.507111,-0.001802,0.003717,0.094423,295.199463,15.038177,0.944233,-130.507111,294.500488,0.000000
81.240005,66.170967,-130.507111,-0.001789,0.003717,0.094423,294.343170,14.994555,0.944233,-130.507111,294.500488,0.000000
81.610001,65.999672,-130.462631,-0.001798,0.003717,0.094423,293.581207,14.955739,0.944233,-130.462631,294.500488,0.000000
81.980003,65.824654,-130.551590,-0.001815,0.003721,0.094519,292.802673,14.916080,0.945187,-130.551590,294.500488,0.000000
82.350006,65.664162,-130.596069,-0.001802,0.003740,0.094996,292.088776,14.879711,0.949959,-130.596069,294.500488,0.000000
82.720001,65.554680,-130.640549,-0.001802,0.003799,0.096488,291.601776,14.854903,0.964876,-130.640549,294.500488,0.000000
83.090004,65.416542,-130.596069,-0.001802,0.003840,0.097528,290.987305,14.823601,0.975280,-130.596069,294.500488,0.000000
83.460007,65.372231,-130.640549,-0.001798,0.003857,0.097962,290.790192,14.813560,0.979618,-130.640549,294.500488,0.000000
83.830002,65.252693,-130.685028,-0.001807,0.003859,0.098031,290.258484,14.786471,0.980310,-130.685028,294.500488,0.000000
84.200005,65.152901,-130.774002,-0.001811,0.003866,0.098196,289.814575,14.763858,0.981957,-130.774002,294.500488,0.000000
84.570007,65.182686,-130.774002,-0.001798,0.003874,0.098404,289.947083,14.770608,0.984039,-130.774002,294.500488,0.000000
84.940002,65.197212,-130.774002,-0.001794,0.003878,0.098508,290.011688,14.773900,0.985079,-130.774002,294.500488,0.000000
85.310005,65.096291,-130.729523,-0.001802,0.003881,0.098569,289.562775,14.751030,0.985689,-130.729523,294.500488,0.000000
85.680000,65.254921,-130.818481,-0.001798,0.003883,0.098638,290.268372,14.786977,0.986381,-130.818481,294.500488,0.000000
86.050003,65.150658,-130.907440,-0.001798,0.003884,0.098647,289.804596,14.763350,0.986469,-130.907440,294.500488,0.000000
86.420006,65.075066,-130.951920,-0.001811,0.003884,0.098647,289.468353,14.746221,0.986469,-130.951920,294.500488,0.000000
86.790001,65.254921,-130.951920,-0.001781,0.003887,0.098742,290.268372,14.786977,0.987422,-130.951920,294.500488,0.000000
87.160004,65.219917,-130.951920,-0.001802,0.003887,0.098742,290.112671,14.779044,0.987422,-130.951920,294.500488,0.000000
87.530006,65.123100,-131.040878,-0.001807,0.003887,0.098742,289.682007,14.757106,0.987422,-131.040878,294.500488,0.000000
87.900002,65.999306,-131.129837,-0.001811,0.003895,0.098924,293.579559,14.955657,0.989243,-131.129837,294.500488,0.000000
88.270004,65.852959,-131.085358,-0.001794,0.003895,0.098924,292.928589,14.922493,0.989243,-131.085358,294.500488,0.000000
88.640007,65.769173,-131.129837,-0.001789,0.003895,0.098924,292.555878,14.903507,0.989243,-131.129837,294.500488,0.000000
89.010002,65.665657,-131.129837,-0.001794,0.003895,0.098924,292.095428,14.880051,0.989243,-131.129837,294.500488,0.000000
89.380005,65.564735,-131.174332,-0.001802,0.003895,0.098924,291.646515,14.857182,0.989243,-131.174332,294.500488,0.000000
89.750008,65.476112,-131.263290,-0.001802,0.003895,0.098924,291.252289,14.837099,0.989243,-131.263290,294.500488,0.000000
90.120003,65.365517,-131.263290,-0.001802,0.003895,0.098924,290.760345,14.812038,0.989243,-131.263290,294.500488,0.000000
90.490005,65.271690,-131.307770,-0.001789,0.003895,0.098933,290.342987,14.790776,0.989330,-131.307770,294.500488,0.000000
90.860001,65.199074,-131.307770,-0.001789,0.003895,0.098933,290.019958,14.774321,0.989330,-131.307770,294.500488,0.000000
91.230003,65.111565,-131.352249,-0.001802,0.003895,0.098942,289.630707,14.754492,0.989417,-131.352249,294.500488,0.000000
91.600006,65.037468,-131.441208,-0.001794,0.003895,0.098942,289.301117,14.737701,0.989417,-131.441208,294.500488,0.000000
91.970001,64.952553,-131.352249,-0.001789,0.003896,0.098950,288.923370,14.718459,0.989504,-131.352249,294.500488,0.000000
92.340004,64.869148,-131.441208,-0.001781,0.003896,0.098950,288.552368,14.699559,0.989504,-131.441208,294.500488,0.000000
92.710007,64.780891,-131.396729,-0.001781,0.003896,0.098950,288.159790,14.679560,0.989504,-131.396729,294.500488,0.000000
93.080002,64.727272,-131.485687,-0.001798,0.003896,0.098950,287.921295,14.667409,0.989504,-131.485687,294.500488,0.000000
93.450005,64.666206,-131.530167,-0.001789,0.003896,0.098950,287.649658,14.653572,0.989504,-131.530167,294.500488,0.000000
93.820007,64.594337,-131.574646,-0.001781,0.003896,0.098950,287.329956,14.637286,0.989504,-131.574646,294.500488,0.000000
94.190002,64.505714,-131.619141,-0.001785,0.003896,0.098950,286.935760,14.617204,0.989504,-131.619141,294.500488,0.000000
94.560005,64.429756,-131.574646,-0.001789,0.003896,0.098950,286.597870,14.599992,0.989504,-131.574646,294.500488,0.000000
94.930008,64.376122,-131.663620,-0.001785,0.003896,0.098950,286.359283,14.587838,0.989504,-131.663620,294.500488,0.000000
95.300003,66.226448,-131.663620,-0.001785,0.003942,0.100121,294.589966,15.007128,1.001211,-131.663620,294.500488,0.000000
95.670006,66.279320,-131.663620,-0.001755,0.003732,0.094805,294.825134,15.019109,0.948048,-131.663620,294.500488,0.000000
96.040001,66.173943,-131.797058,-0.001750,0.003732,0.094805,294.356384,14.995230,0.948048,-131.797058,294.500488,0.000000
96.410004,66.073402,-131.752579,-0.001750,0.003732,0.094805,293.909180,14.972447,0.948048,-131.752579,294.500488,0.000000
96.780006,66.000786,-131.752579,-0.001755,0.003732,0.094805,293.586151,14.955992,0.948048,-131.752579,294.500488,0.000000
97.150002,65.933754,-131.841537,-0.001763,0.003734,0.094840,293.287994,14.940802,0.948396,-131.841537,294.500488,0.000000
97.520004,65.824654,-131.930496,-0.001755,0.003738,0.094944,292.802673,14.916080,0.949437,-131.930496,294.500488,0.000000
97.890007,65.810127,-131.886017,-0.001772,0.003740,0.095004,292.738068,14.912787,0.950043,-131.886017,294.500488,0.000000
98.260002,65.744591,-131.886017,-0.001763,0.003753,0.095334,292.446533,14.897937,0.953339,-131.886017,294.500488,0.000000
98.630005,65.633263,-131.886017,-0.001755,0.003770,0.095759,291.951324,14.872710,0.957590,-131.886017,294.500488,0.000000
99.000008,65.577766,-131.930496,-0.001759,0.003815,0.096895,291.704468,14.860134,0.968948,-131.930496,294.500488,0.000000
99.370003,65.520058,-132.019470,-0.001763,0.003815,0.096904,291.447784,14.847057,0.969035,-132.019470,294.500488,0.000000
99.740005,65.459358,-132.063950,-0.001763,0.003870,0.098291,291.177765,14.833302,0.982911,-132.063950,294.500488,0.000000
100.110008,65.449684,-132.063950,-0.001763,0.003880,0.098551,291.134735,14.831111,0.985515,-132.063950,294.500488,0.000000
100.480003,65.399040,-132.063950,-0.001746,0.003884,0.098647,290.909454,14.819633,0.986469,-132.063950,294.500488,0.000000
100.850006,65.335365,-132.152908,-0.001755,0.003888,0.098751,290.626221,14.805205,0.987509,-132.152908,294.500488,0.000000
101.220001,65.360680,-132.152908,-0.001772,0.003901,0.099080,290.738831,14.810942,0.990802,-132.152908,294.500488,0.000000
101.590004,65.393822,-132.197388,-0.001759,0.003906,0.099202,290.886261,14.818452,0.992017,-132.197388,294.500488,0.000000
101.960007,65.333122,-132.241867,-0.001746,0.003906,0.099202,290.616241,14.804697,0.992017,-132.241867,294.500488,0.000000
102.330002,65.285454,-132.241867,-0.001746,0.003906,0.099210,290.404205,14.793895,0.992104,-132.241867,294.500488,0.000000
102.700005,65.251579,-132.241867,-0.001768,0.003907,0.099237,290.253510,14.786219,0.992365,-132.241867,294.500488,0.000000
103.070007,65.216576,-132.286346,-0.001768,0.003908,0.099263,290.097809,14.778287,0.992627,-132.286346,294.500488,0.000000
103.440002,65.175606,-132.419785,-0.001750,0.003911,0.099349,289.915588,14.769003,0.993493,-132.419785,294.500488,0.000000
103.810005,65.230721,-132.330826,-0.001759,0.003912,0.099358,290.160736,14.781493,0.993580,-132.330826,294.500488,0.000000
104.180008,65.181938,-132.375305,-0.001755,0.003912,0.099358,289.943756,14.770438,0.993580,-132.375305,294.500488,0.000000
104.550003,65.352486,-132.419785,-0.001768,0.003917,0.099488,290.702362,14.809085,0.994879,-132.419785,294.500488,0.000000
104.920006,65.323814,-132.508759,-0.001768,0.003917,0.099488,290.574829,14.802588,0.994879,-132.508759,294.500488,0.000000
105.290009,65.289192,-132.508759,-0.001759,0.003917,0.099488,290.420837,14.794743,0.994879,-132.508759,294.500488,0.000000
105.660004,65.280251,-132.508759,-0.001768,0.003918,0.099523,290.381042,14.792717,0.995227,-132.508759,294.500488,0.000000
106.030006,65.246361,-132.508759,-0.001750,0.003919,0.099531,290.230316,14.785036,0.995314,-132.508759,294.500488,0.000000
106.400002,65.241142,-132.553238,-0.001755,0.003919,0.099540,290.207092,14.783854,0.995401,-132.553238,294.500488,0.000000
106.770004,65.281364,-132.597717,-0.001763,0.003921,0.099601,290.386017,14.792969,0.996006,-132.597717,294.500488,0.000000
107.140007,65.285088,-132.686676,-0.001755,0.003921,0.099601,290.402588,14.793813,0.996006,-132.686676,294.500488,0.000000
107.510002,65.271309,-132.731155,-0.001750,0.003921,0.099601,290.341278,14.790690,0.996006,-132.731155,294.500488,0.000000
107.880005,65.247856,-132.642197,-0.001746,0.003921,0.099601,290.236969,14.785376,0.996006,-132.642197,294.500488,0.000000
108.250008,65.213600,-132.686676,-0.001759,0.003921,0.099601,290.084595,14.777613,0.996006,-132.686676,294.500488,0.000000
108.620003,65.333504,-132.731155,-0.001750,0.003926,0.099713,290.617950,14.804784,0.997134,-132.731155,294.500488,0.000000
108.990005,65.372963,-132.820114,-0.001763,0.003926,0.099713,290.793457,14.813725,0.997134,-132.820114,294.500488,0.000000
109.360008,65.343925,-132.864594,-0.001746,0.003926,0.099713,290.664307,14.807145,0.997134,-132.864594,294.500488,0.000000
109.730003,65.334984,-132.864594,-0.001759,0.003926,0.099713,290.624512,14.805119,0.997134,-132.864594,294.500488,0.000000
110.100006,65.307426,-132.864594,-0.001750,0.003926,0.099713,290.501953,14.798875,0.997134,-132.864594,294.500488,0.000000
110.470009,65.284340,-132.909088,-0.001755,0.003926,0.099713,290.399261,14.793643,0.997134,-132.909088,294.500488,0.000000
110.840004,65.255669,-132.998047,-0.001750,0.003926,0.099713,290.271698,14.787147,0.997134,-132.998047,294.500488,0.000000
111.210007,65.210609,-132.909088,-0.001746,0.003926,0.099713,290.071289,14.776936,0.997134,-132.909088,294.500488,0.000000
111.580002,65.186043,-132.998047,-0.001750,0.003927,0.099740,289.962006,14.771369,0.997396,-132.998047,294.500488,0.000000
111.950005,65.191994,-133.087006,-0.001750,0.003927,0.099757,289.988464,14.772717,0.997570,-133.087006,294.500488,0.000000
112.320007,65.209862,-133.042526,-0.001763,0.003928,0.099766,290.067963,14.776766,0.997657,-133.042526,294.500488,0.000000
112.690002,65.221046,-133.131485,-0.001768,0.003929,0.099809,290.117706,14.779301,0.998088,-133.131485,294.500488,0.000000
113.060005,65.235558,-133.131485,-0.001768,0.003929,0.099809,290.182251,14.782589,0.998088,-133.131485,294.500488,0.000000
113.430008,65.240776,-133.131485,-0.001746,0.003929,0.099809,290.205475,14.783772,0.998088,-133.131485,294.500488,0.000000
113.800003,65.199074,-133.220444,-0.001759,0.003929,0.099809,290.019958,14.774321,0.998088,-133.220444,294.500488,0.000000
114.170006,65.197960,-133.175964,-0.001772,0.003930,0.099826,290.015015,14.774069,0.998262,-133.175964,294.500488,0.000000
114.540009,65.225136,-133.220444,-0.001763,0.003932,0.099870,290.135895,14.780228,0.998698,-133.220444,294.500488,0.000000
114.910004,65.275032,-133.309418,-0.001755,0.003932,0.099870,290.357849,14.791533,0.998698,-133.309418,294.500488,0.000000
115.280006,65.276146,-133.309418,-0.001746,0.003932,0.099870,290.362793,14.791786,0.998698,-133.309418,294.500488,0.000000
115.650009,65.248222,-133.309418,-0.001755,0.003932,0.099870,290.238586,14.785459,0.998698,-133.309418,294.500488,0.000000
116.020004,65.252327,-133.353897,-0.001759,0.003932,0.099870,290.256836,14.786388,0.998698,-133.353897,294.500488,0.000000
116.390007,65.211739,-133.487335,-0.001763,0.003932,0.099870,290.076294,14.777191,0.998698,-133.487335,294.500488,0.000000
116.760002,65.189018,-133.442856,-0.001750,0.003932,0.099870,289.975250,14.772042,0.998698,-133.442856,294.500488,0.000000
117.130005,65.393822,-133.398376,-0.001746,0.003937,0.099991,290.886261,14.818452,0.999909,-133.398376,294.500488,0.000000
117.500008,65.442970,-133.442856,-0.001755,0.003937,0.099991,291.104858,14.829589,0.999909,-133.442856,294.500488,0.000000
117.870003,65.442604,-133.531815,-0.001750,0.003937,0.099991,291.103241,14.829506,0.999909,-133.531815,294.500488,0.000000
118.240005,65.418404,-133.576294,-0.001759,0.003937,0.099991,290.995605,14.824022,0.999909,-133.576294,294.500488,0.000000
118.610008,65.403496,-133.576294,-0.001755,0.003937,0.099991,290.929291,14.820643,0.999909,-133.576294,294.500488,0.000000
118.980003,65.383766,-133.620773,-0.001746,0.003937,0.099991,290.841522,14.816174,0.999909,-133.620773,294.500488,0.000000
119.350006,65.356590,-133.620773,-0.001759,0.003937,0.099991,290.720642,14.810016,0.999909,-133.620773,294.500488,0.000000
119.720009,65.318596,-133.709732,-0.001759,0.003937,0.099991,290.551636,14.801406,0.999909,-133.709732,294.500488,0.000000
120.090004,65.310783,-133.665253,-0.001763,0.003937,0.100000,290.516876,14.799635,0.999996,-133.665253,294.500488,0.000000
120.460007,65.297005,-133.798706,-0.001755,0.003937,0.100008,290.455597,14.796514,1.000083,-133.798706,294.500488,0.000000
120.830009,65.288811,-133.798706,-0.001742,0.003938,0.100017,290.419128,14.794656,1.000170,-133.798706,294.500488,0.000000
121.200005,65.284721,-133.798706,-0.001746,0.003938,0.100017,290.400940,14.793730,1.000170,-133.798706,294.500488,0.000000
121.570007,65.272057,-133.754227,-0.001746,0.003938,0.100017,290.344604,14.790859,1.000170,-133.754227,294.500488,0.000000
121.940002,65.282478,-133.887665,-0.001750,0.003939,0.100043,290.390961,14.793221,1.000431,-133.887665,294.500488,0.000000
122.310005,65.276527,-133.976624,-0.001742,0.003939,0.100052,290.364502,14.791872,1.000518,-133.976624,294.500488,0.000000
122.680008,65.282860,-133.932144,-0.001746,0.003939,0.100061,290.392670,14.793307,1.000605,-133.932144,294.500488,0.000000
123.050003,65.278008,-133.887665,-0.001763,0.003939,0.100061,290.371094,14.792209,1.000605,-133.887665,294.500488,0.000000
123.420006,65.282478,-133.976624,-0.001759,0.003940,0.100078,290.390961,14.793221,1.000775,-133.976624,294.500488,0.000000
123.790009,65.284340,-133.976624,-0.001750,0.003940,0.100086,290.399261,14.793643,1.000862,-133.976624,294.500488,0.000000
124.160004,65.297371,-134.021103,-0.001742,0.003941,0.100095,290.457214,14.796596,1.000950,-134.021103,294.500488,0.000000
124.530006,65.284721,-134.021103,-0.001750,0.003941,0.100095,290.400940,14.793730,1.000950,-134.021103,294.500488,0.000000
124.900009,65.280998,-134.021103,-0.001746,0.003941,0.100095,290.384369,14.792886,1.000950,-134.021103,294.500488,0.000000
125.270004,65.264610,-134.154541,-0.001750,0.003941,0.100095,290.311493,14.789172,1.000950,-134.154541,294.500488,0.000000
125.640007,65.238914,-134.154541,-0.001746,0.003941,0.100095,290.197174,14.783349,1.000950,-134.154541,294.500488,0.000000
126.010010,65.227364,-134.287994,-0.001750,0.003941,0.100095,290.145813,14.780732,1.000950,-134.287994,294.500488,0.000000
126.380005,65.196098,-134.243515,-0.001746,0.003941,0.100095,290.006744,14.773647,1.000950,-134.243515,294.500488,0.000000
126.750008,65.187904,-134.243515,-0.001750,0.003934,0.099913,289.970276,14.771790,0.999129,-134.243515,0.099930,0.000000
127.120003,65.090340,-134.287994,-0.001755,0.003920,0.099575,289.536285,14.749682,0.995749,-134.287994,0.099315,0.000000
127.490005,64.977882,-134.287994,-0.001738,0.003903,0.099132,289.036041,14.724199,0.991325,-134.287994,0.098699,0.000000
127.860008,64.920540,-134.376953,-0.001742,0.003880,0.098543,288.780975,14.711205,0.985428,-134.376953,0.098083,0.000000
128.230011,64.881065,-134.421432,-0.001738,0.003861,0.098057,288.605408,14.702259,0.980572,-134.421432,0.097459,0.000000
128.600006,64.844948,-134.332474,-0.001720,0.003835,0.097398,288.444733,14.694075,0.973978,-134.332474,0.096843,0.000000
128.970001,64.826332,-134.421432,-0.001725,0.003814,0.096886,288.361938,14.689857,0.968865,-134.421432,0.096227,0.000000
129.340012,64.719826,-134.421432,-0.001729,0.003785,0.096140,287.888153,14.665722,0.961405,-134.421432,0.095611,0.000000
129.710007,64.664345,-134.465912,-0.001733,0.003762,0.095542,287.641357,14.653150,0.955421,-134.465912,0.094996,0.000000
130.080002,64.678871,-134.599365,-0.001729,0.003741,0.095022,287.705994,14.656442,0.950217,-134.599365,0.094380,0.000000
130.450012,64.385811,-134.554871,-0.001742,0.003717,0.094423,286.402405,14.590034,0.944233,-134.554871,0.093764,0.000000
130.820007,63.642555,-134.554871,-0.001738,0.003698,0.093920,283.096222,14.421609,0.939203,-134.554871,0.093149,0.000000
131.190002,62.538094,-134.599365,-0.001725,0.003669,0.093192,278.183319,14.171334,0.931921,-134.599365,0.092533,0.000000
131.560013,61.252296,-134.643845,-0.001716,0.003644,0.092559,272.463837,13.879969,0.925588,-134.643845,0.091909,0.000000
131.930008,60.052513,-134.688324,-0.001707,0.003626,0.092091,267.126923,13.608093,0.920907,-134.688324,0.091293,0.000000
132.300003,58.529137,-134.732803,-0.001703,0.003602,0.091492,260.350616,13.262893,0.914923,-134.732803,0.090677,0.000000
132.670013,57.029221,-134.732803,-0.001712,0.003584,0.091032,253.678650,12.923006,0.910324,-134.732803,0.090061,0.000000
133.040009,55.141289,-134.732803,-0.001712,0.003560,0.090425,245.280701,12.495194,0.904253,-134.732803,0.089445,0.000000
133.410004,53.419067,-134.866241,-0.001720,0.003538,0.089870,237.619873,12.104934,0.898704,-134.866241,0.088830,0.000000
133.779999,50.926033,-134.866241,-0.001720,0.003516,0.089298,226.530304,11.540004,0.892982,-134.866241,0.088214,0.000000
134.150009,48.186859,-134.777283,-0.001720,0.003488,0.088596,214.345856,10.919298,0.885957,-134.777283,0.087598,0.000000
134.520004,45.478973,-134.821762,-0.001707,0.003462,0.087945,202.300583,10.305683,0.879451,-134.821762,0.086983,0.000000
134.889999,44.166359,-134.910721,-0.001716,0.003446,0.087520,196.461777,10.008240,0.875204,-134.910721,0.086358,0.000000
135.260010,40.477264,-135.044174,-0.001720,0.003415,0.086748,180.051865,9.172279,0.867483,-135.044174,0.085743,0.000000
135.630005,37.592865,-135.044174,-0.001703,0.003390,0.086107,167.221420,8.518664,0.861067,-135.044174,0.085127,0.000000
136.000000,35.270752,-134.955200,-0.001712,0.003366,0.085508,156.892136,7.992467,0.855083,-134.955200,0.084511,0.000000
136.370010,33.045822,-135.044174,-0.001716,0.003349,0.085057,146.995163,7.488290,0.850572,-135.044174,0.083895,0.000000
136.740005,30.226593,-135.088654,-0.001699,0.003323,0.084398,134.454605,6.849444,0.843982,-135.088654,0.083279,0.000000
137.110001,27.038338,-135.133133,-0.001716,0.003290,0.083574,120.272530,6.126975,0.835743,-135.133133,0.082664,0.000000
137.480011,24.058990,-135.133133,-0.001699,0.003265,0.082924,107.019737,5.451845,0.829240,-135.133133,0.082048,0.000000
137.850006,22.016525,-135.133133,-0.001720,0.003244,0.082404,97.934395,4.989016,0.824036,-135.133133,0.081424,0.000000
138.220001,19.528336,-135.133133,-0.001712,0.003222,0.081831,86.866379,4.425184,0.818313,-135.133133,0.080808,0.000000
138.590012,17.573006,-135.133133,-0.001716,0.003206,0.081441,78.168633,3.982100,0.814411,-135.133133,0.080192,0.000000
138.960007,14.858040,-135.266571,-0.001707,0.003180,0.080782,66.091866,3.366880,0.807818,-135.266571,0.079577,0.000000
139.330002,12.357559,-135.311050,-0.001712,0.003156,0.080166,54.969170,2.800263,0.801663,-135.311050,0.078961,0.000000
139.700012,9.267235,-135.266571,-0.001707,0.003127,0.079429,41.222721,2.099985,0.794290,-135.266571,0.078345,0.000000
140.070007,7.375587,-135.355530,-0.001716,0.003110,0.078987,32.808250,1.671332,0.789870,-135.355530,0.077729,0.000000
140.440002,4.127380,-135.400009,-0.001716,0.003077,0.078154,18.359505,0.935278,0.781543,-135.400009,0.077113,0.000000
140.810013,2.424522,-135.400009,-0.001729,0.003056,0.077625,10.784814,0.549405,0.776252,-135.400009,0.076498,0.000000
141.180008,-0.437531,-135.488983,-0.001712,0.003030,0.076966,-1.946233,-0.099146,0.769662,-135.488983,0.075874,0.000000
141.550003,-3.241497,-135.400009,-0.001725,0.003001,0.076220,-14.418899,-0.734534,0.762202,-135.400009,0.075258,0.000000
141.920013,-0.291565,-135.444489,-0.001742,0.002978,0.075648,-1.296946,-0.066070,0.756479,-135.444489,0.074642,0.000000
142.290009,-0.233101,-135.488983,-0.001746,0.002953,0.075015,-1.036885,-0.052821,0.750147,-135.488983,0.074026,0.000000
142.660004,-0.100166,-135.533463,-0.001776,0.002935,0.074547,-0.445562,-0.022698,0.745465,-135.533463,0.073411,0.000000
143.030014,-0.077080,-135.622421,-0.001794,0.002905,0.073783,-0.342868,-0.017467,0.737835,-135.622421,0.072795,0.000000
143.400009,-0.131813,-135.622421,-0.001811,0.002881,0.073185,-0.586334,-0.029869,0.731851,-135.622421,0.072179,0.000000
143.770004,-0.091599,-135.622421,-0.001841,0.002856,0.072552,-0.407451,-0.020757,0.725519,-135.622421,0.071563,0.000000
144.139999,-0.112823,-135.666901,-0.001854,0.002834,0.071988,-0.501864,-0.025566,0.719883,-135.666901,0.070947,0.000000
144.510010,-0.094582,-135.755859,-0.001876,0.002808,0.071321,-0.420720,-0.021432,0.713207,-135.755859,0.070323,0.000000
144.880005,-0.100906,-135.800339,-0.001901,0.002781,0.070644,-0.448854,-0.022866,0.706439,-135.800339,0.069708,0.000000
145.250000,-0.115059,-135.711380,-0.001932,0.002758,0.070046,-0.511808,-0.026073,0.700455,-135.711380,0.069092,0.000000
145.620010,-0.093086,-135.755859,-0.001936,0.002744,0.069690,-0.414068,-0.021094,0.696901,-135.755859,0.068476,0.000000
145.990005,-0.112083,-135.755859,-0.001970,0.002713,0.068910,-0.498572,-0.025398,0.689097,-135.755859,0.067860,0.000000
146.360001,-0.129585,-135.844818,-0.001992,0.002684,0.068181,-0.576424,-0.029364,0.681811,-135.844818,0.067245,0.000000
146.730011,-0.116173,-135.889313,-0.002009,0.002675,0.067956,-0.516762,-0.026325,0.679555,-135.889313,0.066629,0.000000
147.100006,-0.096809,-135.889313,-0.002035,0.002631,0.066837,-0.430630,-0.021937,0.668371,-135.889313,0.066013,0.000000
147.470001,-0.105751,-135.933792,-0.002044,0.002617,0.066473,-0.470404,-0.023964,0.664726,-135.933792,0.065397,0.000000
147.840012,-0.113197,-135.978271,-0.002065,0.002591,0.065805,-0.503527,-0.025651,0.658049,-135.978271,0.064773,0.000000
148.210007,-0.105751,-136.067230,-0.002108,0.002562,0.065085,-0.470404,-0.023964,0.650851,-136.067230,0.064157,0.000000
148.580002,-0.099792,-136.067230,-0.002104,0.002549,0.064747,-0.443899,-0.022613,0.647471,-136.067230,0.063542,0.000000
148.950012,-0.136284,-136.022751,-0.002130,0.002517,0.063923,-0.606221,-0.030882,0.639231,-136.022751,0.062926,0.000000
149.320007,-0.140755,-136.067230,-0.002139,0.002492,0.063307,-0.626108,-0.031895,0.633073,-136.067230,0.062310,0.000000
149.690002,-0.141495,-136.067230,-0.002164,0.002471,0.062770,-0.629400,-0.032063,0.627698,-136.067230,0.061694,0.000000
150.060013,-0.112450,-136.156189,-0.002199,0.002452,0.062276,-0.500201,-0.025481,0.622755,-136.156189,0.061079,0.000000
150.430008,-0.118042,-136.245148,-0.002212,0.002426,0.061625,-0.525077,-0.026749,0.616249,-136.245148,0.060463,0.000000
150.800003,-0.129585,-136.200668,-0.002220,0.002411,0.061252,-0.576424,-0.029364,0.612521,-136.200668,0.059847,0.000000
151.170013,-0.160858,-136.200668,-0.002251,0.002371,0.060211,-0.715533,-0.036451,0.602112,-136.200668,0.059223,0.000000
151.540009,-0.148575,-136.289627,-0.002281,0.002348,0.059648,-0.660894,-0.033668,0.596477,-136.289627,0.058607,0.000000
151.910004,-0.129211,-136.334122,-0.002307,0.002322,0.058989,-0.574761,-0.029280,0.589887,-136.334122,0.057991,0.000000
152.280014,-0.147453,-136.334122,-0.002315,0.002300,0.058407,-0.655905,-0.033413,0.584074,-136.334122,0.057376,0.000000
152.650009,-0.125488,-136.334122,-0.002345,0.002269,0.057636,-0.558200,-0.028436,0.576356,-136.334122,0.056760,0.000000
153.020004,-0.159370,-136.334122,-0.002376,0.002243,0.056968,-0.708915,-0.036114,0.569680,-136.334122,0.056144,0.000000
153.300003,-0.105003,-136.423080,-0.002376,0.002237,0.056829,-0.467078,-0.023794,0.568291,-136.423080,0.056664,0.000000