File: Data/compression 16/ManualNoHeating-17-16-reverse-hand-2-4_08302024_173156.csv
Time (sec),S:Load (lbs),S:HL1 (DIM),S:LVDT (in),S:Position (in),Ch:Position (mm),Ch:Load (N),Ch:Stress (MPa),Ch:Strain (mm/mm),Ch:HL1 (DIM),Set Point (),Cycles ()
0.210000,-0.113571,-170.851334,-0.010533,-0.005749,-0.146015,-0.505190,-0.025736,-1.460148,-170.851334,-0.145798,0.000000
0.570000,-0.137405,-170.940292,-0.010537,-0.005666,-0.143916,-0.611210,-0.031137,-1.439161,-170.940292,-0.143110,0.000000
0.930000,-0.182831,-170.895813,-0.010386,-0.005444,-0.138288,-0.813272,-0.041430,-1.382879,-170.895813,-0.137126,0.000000
1.290000,-0.115807,-170.895813,-0.010136,-0.005206,-0.132226,-0.515133,-0.026242,-1.322261,-170.895813,-0.131125,0.000000
1.650000,-0.090111,-170.940292,-0.009908,-0.004968,-0.126190,-0.400833,-0.020419,-1.261903,-170.940292,-0.125123,0.000000
2.010000,-0.104263,-170.984772,-0.009666,-0.004743,-0.120475,-0.463786,-0.023626,-1.204751,-170.984772,-0.119122,0.000000
2.370000,-0.108360,-171.073730,-0.009425,-0.004500,-0.114292,-0.482011,-0.024555,-1.142917,-171.073730,-0.113121,0.000000
2.730000,-0.142242,-171.073730,-0.009175,-0.004268,-0.108412,-0.632726,-0.032233,-1.084119,-171.073730,-0.107137,0.000000
3.090000,-0.168678,-171.118225,-0.008929,-0.004032,-0.102402,-0.750318,-0.038223,-1.024022,-171.118225,-0.101136,0.000000
3.450000,-0.116547,-171.118225,-0.008692,-0.003790,-0.096262,-0.518425,-0.026410,-0.962624,-171.118225,-0.095135,0.000000
3.810000,-0.138519,-171.073730,-0.008446,-0.003553,-0.090235,-0.616165,-0.031389,-0.902349,-171.073730,-0.089134,0.000000
4.170000,-0.068512,-171.207184,-0.008218,-0.003316,-0.084234,-0.304756,-0.015525,-0.842336,-171.207184,-0.083150,0.000000
4.530000,-0.116920,-171.207184,-0.007968,-0.003088,-0.078441,-0.520088,-0.026495,-0.784408,-171.207184,-0.077149,0.000000
4.890000,-0.104263,-171.251663,-0.007718,-0.002850,-0.072379,-0.463786,-0.023626,-0.723789,-171.251663,-0.071147,0.000000
5.250000,-0.121017,-171.251663,-0.007472,-0.002609,-0.066256,-0.538313,-0.027423,-0.662561,-171.251663,-0.065146,0.000000
5.610000,-0.104630,-171.296143,-0.007226,-0.002377,-0.060376,-0.465415,-0.023709,-0.603763,-171.296143,-0.059145,0.000000
5.970000,-0.118782,-171.385101,-0.006980,-0.002136,-0.054254,-0.528369,-0.026916,-0.542538,-171.385101,-0.053161,0.000000
6.330000,-0.092720,-171.296143,-0.006743,-0.001901,-0.048279,-0.412439,-0.021011,-0.482786,-171.296143,-0.047160,0.000000
6.690001,-0.126602,-171.385101,-0.006485,-0.001662,-0.042217,-0.563155,-0.028688,-0.422167,-171.385101,-0.041159,0.000000
7.050000,-0.126228,-171.385101,-0.006256,-0.001432,-0.036363,-0.561492,-0.028604,-0.363630,-171.385101,-0.035158,0.000000
7.410000,-0.088623,-171.340622,-0.006006,-0.001197,-0.030414,-0.394215,-0.020082,-0.304139,-171.340622,-0.029156,0.000000
7.770000,-0.090485,-171.429581,-0.005782,-0.000957,-0.024308,-0.402496,-0.020504,-0.243085,-171.429581,-0.023172,0.000000
8.130000,-0.096809,-171.518555,-0.005514,-0.000719,-0.018273,-0.430630,-0.021937,-0.182727,-171.518555,-0.017171,0.000000
8.490001,-0.091599,-171.518555,-0.005277,-0.000486,-0.012332,-0.407451,-0.020757,-0.123319,-171.518555,-0.011170,0.000000
8.850000,-0.111710,-171.474060,-0.005032,-0.000247,-0.006270,-0.496909,-0.025314,-0.062701,-171.474060,-0.005169,0.000000
9.210000,-0.111336,-171.563034,-0.004790,-0.000011,-0.000269,-0.495246,-0.025229,-0.002691,-171.563034,0.000815,0.000000
9.570001,0.042458,-171.607513,-0.004587,0.000215,0.005455,0.188861,0.009621,0.054548,-171.607513,0.006816,0.000000
9.930000,0.146721,-171.563034,-0.004527,-0.000008,-0.000208,0.652647,0.033247,-0.002082,-171.563034,-0.000061,0.000000
10.290001,0.189911,-171.563034,-0.004544,-0.000009,-0.000217,0.844766,0.043034,-0.002169,-171.563034,0.000234,0.000000
10.650001,0.129219,-171.607513,-0.004531,-0.000007,-0.000182,0.574795,0.029281,-0.001821,-171.607513,0.000832,0.000000
11.010000,0.217468,-171.696472,-0.004514,0.000017,0.000433,0.967347,0.049279,0.004334,-171.696472,0.001431,0.000000
11.370001,0.384666,-171.696472,-0.004514,0.000040,0.001015,1.711082,0.087167,0.010147,-171.696472,0.002029,0.000000
11.730000,0.638252,-171.696472,-0.004475,0.000064,0.001621,2.839088,0.144630,0.016214,-171.696472,0.002627,0.000000
12.090000,0.882530,-171.785431,-0.004467,0.000086,0.002177,3.925690,0.199984,0.021767,-171.785431,0.003235,0.000000
12.450001,1.205376,-171.740952,-0.004437,0.000112,0.002853,5.361779,0.273142,0.028531,-171.740952,0.003833,0.000000
12.810000,1.560989,-171.829910,-0.004411,0.000139,0.003538,6.943627,0.353725,0.035381,-171.829910,0.004431,0.000000
13.170001,1.817551,-171.918869,-0.004393,0.000159,0.004050,8.084869,0.411863,0.040498,-171.918869,0.005030,0.000000
13.530001,2.314674,-171.829910,-0.004372,0.000186,0.004717,10.296185,0.524513,0.047175,-171.829910,0.005628,0.000000
13.890000,2.675873,-171.918869,-0.004350,0.000205,0.005212,11.902877,0.606361,0.052118,-171.918869,0.006235,0.000000
14.250001,3.112663,-171.918869,-0.004333,0.000229,0.005819,13.845818,0.705340,0.058189,-171.918869,0.006834,0.000000
14.610001,3.493599,-171.918869,-0.004316,0.000254,0.006443,15.540304,0.791661,0.064434,-171.918869,0.007432,0.000000
14.970000,4.163498,-171.963364,-0.004281,0.000280,0.007120,18.520164,0.943462,0.071198,-171.963364,0.008030,0.000000
15.330001,4.640884,-172.007843,-0.004260,0.000302,0.007683,20.643684,1.051639,0.076833,-172.007843,0.008629,0.000000
15.690001,5.043045,-172.096802,-0.004238,0.000323,0.008195,22.432585,1.142770,0.081951,-172.096802,0.009236,0.000000
16.050001,5.705498,-172.052322,-0.004238,0.000350,0.008880,25.379322,1.292884,0.088801,-172.052322,0.009834,0.000000
16.410000,6.226074,-172.096802,-0.004182,0.000378,0.009591,27.694962,1.410849,0.095913,-172.096802,0.010433,0.000000
16.770000,6.550034,-172.141281,-0.004204,0.000399,0.010129,29.136005,1.484259,0.101291,-172.141281,0.011031,0.000000
17.130001,7.033745,-172.185760,-0.004161,0.000424,0.010771,31.287659,1.593869,0.107707,-172.185760,0.011629,0.000000
17.490002,7.510384,-172.185760,-0.004148,0.000448,0.011378,33.407856,1.701877,0.113778,-172.185760,0.012237,0.000000
17.850000,7.829506,-172.185760,-0.004117,0.000465,0.011812,34.827381,1.774191,0.118115,-172.185760,0.012835,0.000000
18.210001,8.350456,-172.274719,-0.004109,0.000490,0.012445,37.144684,1.892240,0.124447,-172.274719,0.013433,0.000000
18.570002,8.626015,-172.230240,-0.004074,0.000513,0.013026,38.370430,1.954683,0.130257,-172.230240,0.014032,0.000000
18.930000,8.920929,-172.274719,-0.004066,0.000537,0.013633,39.682274,2.021511,0.136328,-172.274719,0.014630,0.000000
19.290001,9.386398,-172.363678,-0.004027,0.000563,0.014292,41.752785,2.126988,0.142918,-172.363678,0.015229,0.000000
19.650002,9.559174,-172.408173,-0.004014,0.000581,0.014769,42.521328,2.166140,0.147687,-172.408173,0.015835,0.000000
20.010000,9.804199,-172.408173,-0.004001,0.000604,0.015333,43.611256,2.221663,0.153326,-172.408173,0.016434,0.000000
20.370001,10.283066,-172.363678,-0.003967,0.000631,0.016018,45.741360,2.330176,0.160177,-172.363678,0.017032,0.000000
20.730001,10.563835,-172.408173,-0.003941,0.000655,0.016633,46.990284,2.393799,0.166331,-172.408173,0.017630,0.000000
21.090000,10.906792,-172.452652,-0.003928,0.000678,0.017231,48.515831,2.471514,0.172315,-172.452652,0.018229,0.000000
21.450001,11.337257,-172.452652,-0.003906,0.000705,0.017908,50.430641,2.569059,0.179082,-172.452652,0.018836,0.000000
21.810001,11.400185,-172.541611,-0.003872,0.000723,0.018359,50.710552,2.583319,0.183590,-172.541611,0.019434,0.000000
22.170002,11.919273,-172.541611,-0.003863,0.000752,0.019096,53.019577,2.700946,0.190963,-172.541611,0.020033,0.000000
22.530001,12.162804,-172.541611,-0.003829,0.000776,0.019703,54.102852,2.756131,0.197034,-172.541611,0.020631,0.000000
22.890001,12.197067,-172.630569,-0.003816,0.000794,0.020172,54.255264,2.763895,0.201716,-172.630569,0.021229,0.000000
23.250002,12.659554,-172.630569,-0.003786,0.000819,0.020805,56.312508,2.868696,0.208048,-172.630569,0.021837,0.000000
23.610001,13.152573,-172.719528,-0.003768,0.000845,0.021464,58.505566,2.980416,0.214638,-172.719528,0.022435,0.000000
23.970001,13.453819,-172.630569,-0.003751,0.000869,0.022062,59.845577,3.048679,0.220622,-172.630569,0.023033,0.000000
24.330002,13.631813,-172.719528,-0.003721,0.000891,0.022634,60.637333,3.089013,0.226344,-172.719528,0.023632,0.000000
24.690001,13.718575,-172.764008,-0.003704,0.000912,0.023172,61.023266,3.108673,0.231723,-172.764008,0.024230,0.000000
25.050001,14.079033,-172.719528,-0.003682,0.000934,0.023736,62.626667,3.190355,0.237358,-172.719528,0.024837,0.000000
25.410002,14.487526,-172.808502,-0.003665,0.000959,0.024352,64.443733,3.282920,0.243516,-172.808502,0.025436,0.000000
25.770000,14.550461,-172.764008,-0.003639,0.000981,0.024907,64.723679,3.297181,0.249065,-172.764008,0.026034,0.000000
26.130001,15.307121,-172.852982,-0.003609,0.001011,0.025687,68.089478,3.468643,0.256869,-172.852982,0.026632,0.000000
26.490002,15.336166,-172.852982,-0.003587,0.001032,0.026216,68.218674,3.475225,0.262161,-172.852982,0.027231,0.000000
26.850000,15.362976,-172.897461,-0.003566,0.001049,0.026641,68.337929,3.481300,0.266411,-172.897461,0.027829,0.000000
27.210001,16.113678,-172.897461,-0.003557,0.001081,0.027456,71.677223,3.651412,0.274564,-172.897461,0.028436,0.000000
27.570002,16.261879,-172.941940,-0.003523,0.001101,0.027968,72.336449,3.684994,0.279681,-172.941940,0.029035,0.000000
27.930002,16.754532,-173.030899,-0.003505,0.001129,0.028688,74.527878,3.796631,0.286876,-173.030899,0.029633,0.000000
28.290001,16.889702,-173.030899,-0.003488,0.001155,0.029330,75.129143,3.827261,0.293295,-173.030899,0.030231,0.000000
28.650002,16.976463,-173.030899,-0.003454,0.001175,0.029833,75.515083,3.846922,0.298325,-173.030899,0.030830,0.000000
29.010002,17.386070,-173.030899,-0.003436,0.001200,0.030474,77.337105,3.939740,0.304741,-173.030899,0.031437,0.000000
29.370001,17.278458,-173.119858,-0.003410,0.001214,0.030847,76.858421,3.915354,0.308473,-173.119858,0.032035,0.000000
29.730001,17.814674,-173.119858,-0.003393,0.001243,0.031584,79.243629,4.036863,0.315842,-173.119858,0.032634,0.000000
30.090002,18.427971,-173.164337,-0.003380,0.001271,0.032278,81.971710,4.175838,0.322780,-173.164337,0.033232,0.000000
30.450001,18.514732,-173.208817,-0.003337,0.001294,0.032876,82.357643,4.195498,0.328764,-173.208817,0.033831,0.000000
30.810001,18.327431,-173.208817,-0.003346,0.001309,0.033249,81.524483,4.153055,0.332492,-173.208817,0.034437,0.000000
31.170002,19.148140,-173.164337,-0.003303,0.001341,0.034073,85.175179,4.339030,0.340731,-173.164337,0.035036,0.000000
31.530001,19.098984,-173.342270,-0.003290,0.001359,0.034524,84.956520,4.327892,0.345243,-173.342270,0.035634,0.000000
31.890001,19.733879,-173.253311,-0.003268,0.001390,0.035305,87.780678,4.471761,0.353047,-173.253311,0.036232,0.000000
32.250000,19.808357,-173.386749,-0.003234,0.001413,0.035894,88.111977,4.488638,0.358944,-173.386749,0.036831,0.000000
32.610001,19.780060,-173.297791,-0.003212,0.001435,0.036441,87.986099,4.482225,0.364406,-173.297791,0.037438,0.000000
32.970001,20.293930,-173.297791,-0.003195,0.001462,0.037134,90.271912,4.598670,0.371344,-173.297791,0.038036,0.000000
33.330002,20.265633,-173.431229,-0.003186,0.001482,0.037637,90.146034,4.592258,0.376374,-173.431229,0.038635,0.000000
33.690002,20.492409,-173.342270,-0.003147,0.001501,0.038114,91.154785,4.643646,0.381143,-173.342270,0.039233,0.000000
34.050003,21.105331,-173.475708,-0.003139,0.001531,0.038878,93.881203,4.782537,0.388777,-173.475708,0.039831,0.000000
34.410000,21.145920,-173.475708,-0.003109,0.001553,0.039441,94.061752,4.791734,0.394413,-173.475708,0.040439,0.000000
34.770000,21.288162,-173.431229,-0.003083,0.001576,0.040031,94.694473,4.823967,0.400309,-173.431229,0.041037,0.000000
35.130001,21.638565,-173.520187,-0.003065,0.001600,0.040647,96.253143,4.903369,0.406467,-173.520187,0.041635,0.000000
35.490002,21.588669,-173.520187,-0.003040,0.001619,0.041115,96.031197,4.892062,0.411149,-173.520187,0.042234,0.000000
35.850002,21.893272,-173.564667,-0.003009,0.001642,0.041696,97.386139,4.961086,0.416959,-173.564667,0.042832,0.000000
36.210003,22.633171,-173.609146,-0.003001,0.001675,0.042537,100.677376,5.128750,0.425373,-173.609146,0.043431,0.000000
36.570004,22.718079,-173.609146,-0.002975,0.001697,0.043092,101.055061,5.147990,0.430922,-173.609146,0.044038,0.000000
36.930000,22.890854,-173.698120,-0.002958,0.001719,0.043665,101.823601,5.187141,0.436648,-173.698120,0.044636,0.000000
37.290001,23.086723,-173.653625,-0.002936,0.001743,0.044272,102.694878,5.231526,0.442719,-173.653625,0.045234,0.000000
37.650002,23.646774,-173.742599,-0.002915,0.001770,0.044948,105.186104,5.358436,0.449483,-173.742599,0.045833,0.000000
38.010002,23.735397,-173.653625,-0.002893,0.001792,0.045529,105.580322,5.378518,0.455293,-173.653625,0.046431,0.000000
38.370003,23.802422,-173.787079,-0.002863,0.001815,0.046093,105.878456,5.393706,0.460928,-173.787079,0.047038,0.000000
38.730003,24.388908,-173.787079,-0.002854,0.001842,0.046778,108.487282,5.526606,0.467779,-173.787079,0.047637,0.000000
39.090000,24.350555,-173.831558,-0.002828,0.001861,0.047272,108.316681,5.517915,0.472722,-173.831558,0.048235,0.000000
39.450001,24.340500,-173.876038,-0.002824,0.001882,0.047793,108.271950,5.515636,0.477926,-173.876038,0.048833,0.000000
39.810001,25.132164,-173.876038,-0.002785,0.001908,0.048460,111.793449,5.695030,0.484603,-173.876038,0.049432,0.000000
40.170002,25.424103,-173.831558,-0.002777,0.001930,0.049033,113.092056,5.761184,0.490329,-173.831558,0.050039,0.000000
40.530003,25.876907,-173.920517,-0.002759,0.001956,0.049692,115.106232,5.863791,0.496919,-173.920517,0.050637,0.000000
40.890003,25.866486,-173.876038,-0.002721,0.001976,0.050195,115.059875,5.861429,0.501949,-173.876038,0.051236,0.000000
41.250004,26.054901,-174.009476,-0.002708,0.001997,0.050715,115.897987,5.904125,0.507153,-174.009476,0.051834,0.000000
41.610001,26.791832,-173.964996,-0.002690,0.002026,0.051452,119.176018,6.071116,0.514522,-173.964996,0.052433,0.000000
41.970001,27.034615,-174.053955,-0.002673,0.002048,0.052025,120.255974,6.126132,0.520249,-174.053955,0.053039,0.000000
42.330002,27.196602,-174.053955,-0.002652,0.002069,0.052545,120.976524,6.162838,0.525449,-174.053955,0.053638,0.000000
42.690002,28.027359,-174.053955,-0.002621,0.002098,0.053282,124.671921,6.351090,0.532822,-174.053955,0.054236,0.000000
43.050003,28.169983,-174.142929,-0.002617,0.002120,0.053846,125.306343,6.383410,0.538458,-174.142929,0.054834,0.000000
43.410004,28.753487,-174.053955,-0.002596,0.002146,0.054496,127.901894,6.515633,0.544964,-174.053955,0.055433,0.000000
43.770000,28.830566,-174.142929,-0.002570,0.002167,0.055043,128.244766,6.533100,0.550426,-174.142929,0.056031,0.000000
44.130001,28.921425,-174.231888,-0.002552,0.002187,0.055554,128.648926,6.553689,0.555543,-174.231888,0.056638,0.000000
44.490002,29.438278,-174.187408,-0.002527,0.002210,0.056144,130.947998,6.670809,0.561440,-174.187408,0.057237,0.000000
44.850002,29.913429,-174.276367,-0.002505,0.002236,0.056786,133.061584,6.778480,0.567859,-174.276367,0.057835,0.000000
45.210003,29.755913,-174.276367,-0.002483,0.002253,0.057228,132.360916,6.742786,0.572280,-174.276367,0.058433,0.000000
45.570004,31.186569,-174.365326,-0.002470,0.002288,0.058113,138.724792,7.066978,0.581125,-174.365326,0.059032,0.000000
45.930000,31.342224,-174.276367,-0.002436,0.002308,0.058616,139.417175,7.102250,0.586155,-174.276367,0.059639,0.000000
46.290001,31.183594,-174.276367,-0.002423,0.002326,0.059075,138.711548,7.066303,0.590754,-174.276367,0.060237,0.000000
46.650002,32.268684,-174.365326,-0.002432,0.002355,0.059821,143.538284,7.312188,0.598210,-174.365326,0.060836,0.000000
47.010002,32.601585,-174.365326,-0.002389,0.002374,0.060290,145.019089,7.387625,0.602896,-174.365326,0.061434,0.000000
47.370003,33.564911,-174.454285,-0.002363,0.002404,0.061061,149.304184,7.605917,0.610613,-174.454285,0.062033,0.000000
47.730003,33.700829,-174.454285,-0.002350,0.002424,0.061564,149.908768,7.636717,0.615643,-174.454285,0.062640,0.000000
48.090004,33.882919,-174.498764,-0.002337,0.002444,0.062084,150.718750,7.677979,0.620844,-174.498764,0.063238,0.000000
48.450001,34.219543,-174.543259,-0.002315,0.002465,0.062614,152.216125,7.754259,0.626135,-174.543259,0.063836,0.000000
48.810001,35.340759,-174.543259,-0.002298,0.002495,0.063385,157.203552,8.008330,0.633853,-174.543259,0.064435,0.000000
49.170002,36.297752,-174.632217,-0.002281,0.002523,0.064096,161.460464,8.225188,0.640964,-174.632217,0.065033,0.000000
49.530003,36.924454,-174.587738,-0.002264,0.002549,0.064747,164.248169,8.367201,0.647471,-174.587738,0.065640,0.000000
49.890003,37.034309,-174.632217,-0.002242,0.002569,0.065250,164.736832,8.392095,0.652501,-174.632217,0.066239,0.000000
50.250004,37.642387,-174.676697,-0.002220,0.002593,0.065857,167.441696,8.529886,0.658572,-174.676697,0.066837,0.000000
50.610001,38.006943,-174.632217,-0.002212,0.002612,0.066351,169.063324,8.612496,0.663515,-174.632217,0.067435,0.000000
50.970001,38.541672,-174.721176,-0.002195,0.002636,0.066950,171.441925,8.733668,0.669499,-174.721176,0.068034,0.000000
51.330002,39.031715,-174.676697,-0.002173,0.002656,0.067453,173.621735,8.844713,0.674529,-174.676697,0.068632,0.000000
51.690002,40.000252,-174.765656,-0.002160,0.002685,0.068199,177.930008,9.064186,0.681985,-174.765656,0.069239,0.000000
52.050003,40.227402,-174.765656,-0.002130,0.002704,0.068675,178.940414,9.115660,0.686754,-174.765656,0.069838,0.000000
52.410004,41.643532,-174.765656,-0.002117,0.002734,0.069447,185.239685,9.436560,0.694471,-174.765656,0.070436,0.000000
52.770004,41.290527,-174.854614,-0.002100,0.002745,0.069716,183.669434,9.356567,0.697163,-174.854614,0.071035,0.000000
53.130001,43.292023,-174.810135,-0.002091,0.002783,0.070687,192.572540,9.810113,0.706875,-174.810135,0.071633,0.000000
53.490002,43.846115,-174.899094,-0.002044,0.002804,0.071234,195.037262,9.935672,0.712340,-174.899094,0.072240,0.000000
53.850002,44.211044,-174.943573,-0.002057,0.002826,0.071789,196.660553,10.018366,0.717889,-174.943573,0.072838,0.000000
54.210003,45.355713,-174.943573,-0.002026,0.002852,0.072430,201.752289,10.277752,0.724304,-174.943573,0.073436,0.000000
54.570004,45.091705,-174.988068,-0.002001,0.002864,0.072751,200.577927,10.217927,0.727514,-174.988068,0.074035,0.000000
54.930004,46.308990,-174.943573,-0.001996,0.002895,0.073532,205.992676,10.493767,0.735318,-174.943573,0.074633,0.000000
55.290001,47.398926,-175.032547,-0.001975,0.002920,0.074165,210.840958,10.740750,0.741650,-175.032547,0.075240,0.000000
55.650002,48.466141,-175.032547,-0.001957,0.002946,0.074833,215.588165,10.982584,0.748327,-175.032547,0.075839,0.000000
56.010002,48.686958,-175.032547,-0.001936,0.002965,0.075310,216.570404,11.032622,0.753100,-175.032547,0.076437,0.000000
56.370003,50.011490,-175.165985,-0.001936,0.002993,0.076012,222.462219,11.332766,0.760120,-175.165985,0.077035,0.000000
56.730003,50.622177,-175.165985,-0.001914,0.003014,0.076567,225.178696,11.471149,0.765673,-175.165985,0.077634,0.000000
57.090004,51.522949,-175.165985,-0.001897,0.003037,0.077131,229.185532,11.675267,0.771309,-175.165985,0.078241,0.000000
57.450005,52.956955,-175.121506,-0.001893,0.003065,0.077859,235.564301,12.000217,0.778595,-175.121506,0.078839,0.000000
57.810001,53.534500,-175.254944,-0.001871,0.003086,0.078397,238.133347,12.131091,0.783969,-175.254944,0.079438,0.000000
58.170002,54.285210,-175.254944,-0.001845,0.003108,0.078952,241.472672,12.301205,0.789522,-175.254944,0.080036,0.000000
58.530003,55.353172,-175.254944,-0.001850,0.003133,0.079568,246.223206,12.543208,0.795680,-175.254944,0.080635,0.000000
58.890003,56.326180,-175.343903,-0.001815,0.003155,0.080140,250.551361,12.763695,0.801402,-175.343903,0.081233,0.000000
59.250004,57.807846,-175.343903,-0.001802,0.003185,0.080895,257.142151,13.099444,0.808946,-175.343903,0.081840,0.000000
59.610004,58.761497,-175.388397,-0.001794,0.003207,0.081459,261.384186,13.315545,0.814585,-175.388397,0.082438,0.000000
59.970001,59.736366,-175.388397,-0.001785,0.003232,0.082091,265.720642,13.536454,0.820913,-175.388397,0.083037,0.000000
60.330002,60.428978,-175.388397,-0.001750,0.003249,0.082534,268.801514,13.693402,0.825338,-175.388397,0.083635,0.000000
60.690002,61.164413,-175.432877,-0.001755,0.003270,0.083063,272.072906,13.860054,0.830629,-175.432877,0.084234,0.000000
61.050003,62.707527,-175.388397,-0.001738,0.003298,0.083757,278.937012,14.209729,0.837567,-175.388397,0.084841,0.000000
61.410004,63.883858,-175.477356,-0.001712,0.003323,0.084398,284.169586,14.476290,0.843982,-175.477356,0.085439,0.000000
61.770004,65.013634,-175.477356,-0.001720,0.003347,0.085023,289.195099,14.732300,0.850227,-175.477356,0.086037,0.000000
62.130001,66.184364,-175.521835,-0.001694,0.003358,0.085291,294.402771,14.997591,0.852915,-175.521835,0.085543,0.000000
62.490002,64.884422,-175.610794,-0.001694,0.003377,0.085786,288.620331,14.703020,0.857858,-175.610794,294.500488,0.000000
62.850002,65.056084,-175.521835,-0.001673,0.003373,0.085664,289.383911,14.741920,0.856643,-175.521835,294.500488,0.000000
63.210003,65.178215,-175.610794,-0.001677,0.003390,0.086098,289.927185,14.769595,0.860980,-175.610794,294.500488,0.000000
63.570004,64.923515,-175.610794,-0.001660,0.003400,0.086367,288.794220,14.711879,0.863668,-175.610794,294.500488,0.000000
63.930004,65.179329,-175.655273,-0.001647,0.003408,0.086566,289.932129,14.769847,0.865662,-175.655273,294.500488,0.000000
64.290001,65.452660,-175.699753,-0.001656,0.003420,0.086870,291.147980,14.831784,0.868698,-175.699753,294.500488,0.000000
64.650002,65.228859,-175.655273,-0.001647,0.003426,0.087017,290.152466,14.781071,0.870174,-175.655273,294.500488,0.000000
65.010002,65.318230,-175.788712,-0.001630,0.003433,0.087208,290.549988,14.801322,0.872081,-175.788712,294.500488,0.000000
65.370003,64.973412,-175.788712,-0.001617,0.003437,0.087304,289.016174,14.723186,0.873035,-175.788712,294.500488,0.000000
65.730003,65.175987,-175.833206,-0.001608,0.003445,0.087503,289.917267,14.769090,0.875030,-175.833206,294.500488,0.000000
66.090004,65.206886,-175.877686,-0.001617,0.003454,0.087720,290.054718,14.776092,0.877199,-175.877686,294.500488,0.000000
66.450005,65.369240,-175.788712,-0.001604,0.003460,0.087885,290.776886,14.812881,0.878845,-175.788712,294.500488,0.000000
66.810005,65.107841,-175.966644,-0.001613,0.003462,0.087945,289.614136,14.753648,0.879451,-175.966644,294.500488,0.000000
67.170006,65.089226,-175.966644,-0.001604,0.003467,0.088058,289.531342,14.749430,0.880579,-175.966644,294.500488,0.000000
67.530006,65.134651,-175.966644,-0.001600,0.003473,0.088205,289.733398,14.759723,0.882055,-175.966644,294.500488,0.000000
67.890007,65.173378,-175.966644,-0.001591,0.003483,0.088465,289.905670,14.768499,0.884655,-175.966644,294.500488,0.000000
68.250000,65.322319,-176.011124,-0.001587,0.003483,0.088474,290.568176,14.802249,0.884742,-176.011124,294.500488,0.000000
68.610001,65.605324,-176.011124,-0.001582,0.003491,0.088674,291.827057,14.866379,0.886737,-176.011124,294.500488,0.000000
68.970001,65.318596,-176.055603,-0.001574,0.003491,0.088682,290.551636,14.801406,0.886824,-176.055603,294.500488,0.000000
69.330002,65.251945,-176.100082,-0.001582,0.003495,0.088778,290.255157,14.786302,0.887777,-176.100082,294.500488,0.000000
69.690002,65.311897,-176.100082,-0.001578,0.003503,0.088986,290.521820,14.799888,0.889859,-176.100082,294.500488,0.000000
70.050003,65.286583,-176.144562,-0.001582,0.003502,0.088960,290.409210,14.794151,0.889598,-176.144562,294.500488,0.000000
70.410004,64.977882,-176.144562,-0.001565,0.003503,0.088986,289.036041,14.724199,0.889859,-176.144562,294.500488,0.000000
70.770004,65.334236,-176.144562,-0.001574,0.003511,0.089168,290.621185,14.804950,0.891680,-176.144562,294.500488,0.000000
71.130005,65.177849,-176.233521,-0.001556,0.003513,0.089220,289.925537,14.769512,0.892202,-176.233521,294.500488,0.000000
71.490005,65.119377,-176.278015,-0.001569,0.003514,0.089246,289.665466,14.756262,0.892459,-176.278015,294.500488,0.000000
71.850006,65.184914,-176.278015,-0.001561,0.003518,0.089359,289.956970,14.771112,0.893587,-176.278015,294.500488,0.000000
72.210007,65.062035,-176.322495,-0.001561,0.003520,0.089402,289.410370,14.743267,0.894022,-176.322495,294.500488,0.000000
72.570000,65.458611,-176.278015,-0.001548,0.003527,0.089584,291.174438,14.833133,0.895843,-176.278015,294.500488,0.000000
72.930000,65.310783,-176.366974,-0.001552,0.003527,0.089593,290.516876,14.799635,0.895930,-176.366974,294.500488,0.000000
73.290001,65.279869,-176.322495,-0.001552,0.003532,0.089706,290.379364,14.792629,0.897058,-176.322495,294.500488,0.000000
73.650002,65.285835,-176.500412,-0.001548,0.003532,0.089714,290.405914,14.793983,0.897145,-176.500412,294.500488,0.000000
74.010002,65.297005,-176.411453,-0.001535,0.003536,0.089810,290.455597,14.796514,0.898099,-176.411453,294.500488,0.000000
74.370003,65.205025,-176.411453,-0.001548,0.003536,0.089810,290.046448,14.775670,0.898099,-176.411453,294.500488,0.000000
74.730003,65.553200,-176.500412,-0.001544,0.003542,0.089966,291.595184,14.854568,0.899658,-176.500412,294.500488,0.000000
75.090004,65.372597,-176.500412,-0.001539,0.003542,0.089966,290.791840,14.813643,0.899658,-176.500412,294.500488,0.000000
75.450005,65.195717,-176.589371,-0.001535,0.003542,0.089966,290.005035,14.773561,0.899658,-176.589371,294.500488,0.000000
75.810005,65.343178,-176.589371,-0.001539,0.003548,0.090113,290.660980,14.806976,0.901134,-176.589371,294.500488,0.000000
76.170006,65.307060,-176.544891,-0.001526,0.003548,0.090113,290.500305,14.798792,0.901134,-176.544891,294.500488,0.000000
76.530006,65.216576,-176.633850,-0.001539,0.003549,0.090157,290.097809,14.778287,0.901566,-176.633850,294.500488,0.000000
76.890007,65.125343,-176.633850,-0.001526,0.003553,0.090235,289.691986,14.757614,0.902345,-176.633850,294.500488,0.000000
77.250000,65.185661,-176.678345,-0.001526,0.003553,0.090235,289.960297,14.771281,0.902345,-176.678345,294.500488,0.000000
77.610001,65.159233,-176.678345,-0.001518,0.003555,0.090287,289.842743,14.765293,0.902868,-176.678345,294.500488,0.000000
77.970001,65.114540,-176.767303,-0.001526,0.003556,0.090322,289.643951,14.755165,0.903216,-176.767303,294.500488,0.000000
78.330002,65.344673,-176.767303,-0.001526,0.003560,0.090434,290.667633,14.807315,0.904340,-176.767303,294.500488,0.000000
78.690002,65.276146,-176.856262,-0.001518,0.003561,0.090443,290.362793,14.791786,0.904427,-176.856262,294.500488,0.000000
79.050003,65.169655,-176.856262,-0.001522,0.003561,0.090443,289.889099,14.767654,0.904427,-176.856262,294.500488,0.000000
79.410004,65.187523,-176.945221,-0.001518,0.003563,0.090504,289.968597,14.771704,0.905037,-176.945221,294.500488,0.000000
79.770004,65.111565,-176.900742,-0.001518,0.003564,0.090521,289.630707,14.754492,0.905211,-176.900742,294.500488,0.000000
80.130005,65.531975,-176.945221,-0.001522,0.003571,0.090694,291.500793,14.849758,0.906944,-176.945221,294.500488,0.000000
80.490005,65.508507,-176.900742,-0.001522,0.003571,0.090694,291.396393,14.844440,0.906944,-176.900742,294.500488,0.000000
80.850006,65.379295,-176.989700,-0.001509,0.003571,0.090694,290.821625,14.815161,0.906944,-176.989700,294.500488,0.000000
81.210007,65.263496,-176.989700,-0.001522,0.003571,0.090703,290.306519,14.788919,0.907031,-176.989700,294.500488,0.000000
81.570007,65.187904,-176.989700,-0.001513,0.003572,0.090738,289.970276,14.771790,0.907376,-176.989700,294.500488,0.000000
81.930000,65.116783,-177.034180,-0.001522,0.003572,0.090738,289.653931,14.755673,0.907376,-177.034180,294.500488,0.000000
82.290001,65.469780,-177.078659,-0.001500,0.003577,0.090868,291.224121,14.835664,0.908678,-177.078659,294.500488,0.000000
82.650002,65.354347,-177.167633,-0.001505,0.003577,0.090868,290.710663,14.809507,0.908678,-177.167633,294.500488,0.000000
83.010002,65.264610,-177.123154,-0.001518,0.003577,0.090868,290.311493,14.789172,0.908678,-177.123154,294.500488,0.000000
83.370003,65.172630,-177.123154,-0.001487,0.003577,0.090868,289.902344,14.768330,0.908678,-177.123154,294.500488,0.000000
83.730003,65.278755,-177.212112,-0.001518,0.003581,0.090963,290.374420,14.792377,0.909631,-177.212112,294.500488,0.000000
84.090004,65.231468,-177.212112,-0.001496,0.003581,0.090963,290.164062,14.781662,0.909631,-177.212112,294.500488,0.000000
84.450005,65.138374,-177.256592,-0.001505,0.003581,0.090963,289.749969,14.760567,0.909631,-177.256592,294.500488,0.000000
84.810005,65.055336,-177.301071,-0.001492,0.003581,0.090963,289.380585,14.741750,0.909631,-177.301071,294.500488,0.000000
85.170006,65.054222,-177.256592,-0.001505,0.003584,0.091024,289.375641,14.741497,0.910241,-177.256592,294.500488,0.000000
85.530006,65.027031,-177.256592,-0.001500,0.003584,0.091032,289.254669,14.735335,0.910324,-177.256592,294.500488,0.000000
85.890007,64.997612,-177.345551,-0.001500,0.003585,0.091067,289.123810,14.728669,0.910672,-177.345551,294.500488,0.000000
86.250008,64.964851,-177.390030,-0.001505,0.003586,0.091076,288.978088,14.721246,0.910759,-177.390030,294.500488,0.000000
86.610001,65.070595,-177.390030,-0.001500,0.003588,0.091145,289.448456,14.745208,0.911452,-177.390030,294.500488,0.000000
86.970001,65.034859,-177.434509,-0.001500,0.003588,0.091145,289.289490,14.737109,0.911452,-177.434509,294.500488,0.000000
87.330002,64.981239,-177.434509,-0.001509,0.003588,0.091145,289.050995,14.724959,0.911452,-177.434509,294.500488,0.000000
87.690002,65.072456,-177.478989,-0.001487,0.003592,0.091241,289.456757,14.745629,0.912406,-177.478989,294.500488,0.000000
88.050003,65.086235,-177.478989,-0.001500,0.003592,0.091241,289.518036,14.748752,0.912406,-177.478989,294.500488,0.000000
88.410004,65.039330,-177.478989,-0.001496,0.003592,0.091241,289.309387,14.738123,0.912406,-177.478989,294.500488,0.000000
88.770004,64.964851,-177.612442,-0.001483,0.003592,0.091249,288.978088,14.721246,0.912493,-177.612442,294.500488,0.000000
89.130005,64.990547,-177.567963,-0.001513,0.003594,0.091284,289.092407,14.727069,0.912841,-177.567963,294.500488,0.000000
89.490005,65.016609,-177.567963,-0.001483,0.003595,0.091310,289.208313,14.732974,0.913102,-177.567963,294.500488,0.000000
89.850006,64.978996,-177.656921,-0.001487,0.003595,0.091310,289.041016,14.724450,0.913102,-177.656921,294.500488,0.000000
90.210007,64.894844,-177.612442,-0.001505,0.003595,0.091319,288.666687,14.705382,0.913189,-177.612442,294.500488,0.000000
90.570007,65.060555,-177.701401,-0.001492,0.003598,0.091397,289.403809,14.742932,0.913969,-177.701401,294.500488,0.000000
90.930008,65.045647,-177.656921,-0.001479,0.003599,0.091406,289.337494,14.739554,0.914056,-177.656921,294.500488,0.000000
91.290001,64.991280,-177.701401,-0.001487,0.003599,0.091406,289.095642,14.727234,0.914056,-177.701401,294.500488,0.000000
91.650002,65.041191,-177.790359,-0.001479,0.003600,0.091449,289.317657,14.738544,0.914487,-177.790359,294.500488,0.000000
92.010002,64.996880,-177.745880,-0.001483,0.003600,0.091449,289.120575,14.728503,0.914487,-177.745880,294.500488,0.000000
92.370003,64.952934,-177.834839,-0.001479,0.003600,0.091449,288.925079,14.718545,0.914487,-177.834839,294.500488,0.000000
92.730003,64.866173,-177.834839,-0.001496,0.003601,0.091457,288.539154,14.698885,0.914574,-177.834839,294.500488,0.000000
93.090004,65.381905,-177.879318,-0.001492,0.003608,0.091631,290.833252,14.815751,0.916308,-177.879318,294.500488,0.000000
93.450005,65.371101,-177.834839,-0.001492,0.003608,0.091631,290.785187,14.813304,0.916308,-177.834839,294.500488,0.000000
93.810005,65.322701,-177.923798,-0.001475,0.003608,0.091631,290.569885,14.802335,0.916308,-177.923798,294.500488,0.000000
94.170006,65.292168,-177.923798,-0.001483,0.003608,0.091631,290.434082,14.795417,0.916308,-177.923798,294.500488,0.000000
94.530006,65.228493,-178.012772,-0.001487,0.003608,0.091631,290.150818,14.780988,0.916308,-178.012772,294.500488,0.000000
94.890007,65.177467,-178.012772,-0.001475,0.003608,0.091631,289.923859,14.769425,0.916308,-178.012772,294.500488,0.000000
95.250008,65.098152,-178.057251,-0.001483,0.003608,0.091639,289.571045,14.751452,0.916395,-178.057251,294.500488,0.000000
95.610008,65.031136,-178.012772,-0.001479,0.003608,0.091639,289.272949,14.736266,0.916395,-178.012772,294.500488,0.000000
95.970001,64.995750,-178.146210,-0.001483,0.003608,0.091639,289.115540,14.728248,0.916395,-178.146210,294.500488,0.000000
96.330002,64.937294,-178.146210,-0.001470,0.003608,0.091639,288.855499,14.715001,0.916395,-178.146210,294.500488,0.000000
96.690002,65.295143,-178.190689,-0.001479,0.003614,0.091787,290.447296,14.796091,0.917871,-178.190689,294.500488,0.000000
97.050003,65.270195,-178.190689,-0.001487,0.003613,0.091778,290.336334,14.790438,0.917784,-178.190689,294.500488,0.000000
97.410004,65.255669,-178.146210,-0.001479,0.003613,0.091778,290.271698,14.787147,0.917784,-178.146210,294.500488,0.000000
97.770004,65.194969,-178.235168,-0.001483,0.003613,0.091778,290.001709,14.773392,0.917784,-178.235168,294.500488,0.000000
98.130005,65.138374,-178.279648,-0.001470,0.003614,0.091787,289.749969,14.760567,0.917871,-178.279648,294.500488,0.000000
98.490005,65.081032,-178.368607,-0.001470,0.003614,0.091796,289.494873,14.747572,0.917958,-178.368607,294.500488,0.000000
98.850006,65.031502,-178.279648,-0.001492,0.003614,0.091796,289.274567,14.736349,0.917958,-178.279648,294.500488,0.000000
99.210007,65.004326,-178.279648,-0.001479,0.003614,0.091796,289.153687,14.730190,0.917958,-178.279648,294.500488,0.000000
99.570007,65.186775,-178.324127,-0.001475,0.003618,0.091900,289.965271,14.771534,0.918999,-178.324127,294.500488,0.000000
99.930008,65.221413,-178.457581,-0.001487,0.003618,0.091900,290.119324,14.779383,0.918999,-178.457581,294.500488,0.000000
100.290009,65.173378,-178.413101,-0.001470,0.003618,0.091900,289.905670,14.768499,0.918999,-178.413101,294.500488,0.000000
100.650002,65.130928,-178.368607,-0.001462,0.003618,0.091900,289.716827,14.758880,0.918999,-178.368607,294.500488,0.000000
101.010002,65.072838,-178.457581,-0.001475,0.003618,0.091900,289.458435,14.745716,0.918999,-178.457581,294.500488,0.000000
101.370003,65.014366,-178.502060,-0.001479,0.003618,0.091900,289.198334,14.732466,0.918999,-178.502060,294.500488,0.000000
101.730003,64.988304,-178.457581,-0.001457,0.003618,0.091900,289.082428,14.726561,0.918999,-178.457581,294.500488,0.000000
102.090004,64.931328,-178.546539,-0.001466,0.003618,0.091900,288.828979,14.713649,0.918999,-178.546539,294.500488,0.000000
102.450005,65.496590,-178.591019,-0.001470,0.003625,0.092073,291.343384,14.841740,0.920732,-178.591019,294.500488,0.000000
102.810005,65.482811,-178.635498,-0.001466,0.003625,0.092073,291.282104,14.838617,0.920732,-178.635498,294.500488,0.000000
103.170006,65.463081,-178.679977,-0.001470,0.003625,0.092073,291.194336,14.834146,0.920732,-178.679977,294.500488,0.000000
103.530006,65.415047,-178.679977,-0.001475,0.003625,0.092073,290.980652,14.823262,0.920732,-178.679977,294.500488,0.000000
103.890007,65.353233,-178.724457,-0.001479,0.003625,0.092073,290.705688,14.809255,0.920732,-178.724457,294.500488,0.000000
104.250008,65.337593,-178.679977,-0.001462,0.003625,0.092073,290.636139,14.805711,0.920732,-178.679977,294.500488,0.000000
104.610008,65.296638,-178.768936,-0.001453,0.003625,0.092073,290.453949,14.796430,0.920732,-178.768936,294.500488,0.000000
104.970001,65.252327,-178.768936,-0.001462,0.003625,0.092073,290.256836,14.786388,0.920732,-178.768936,294.500488,0.000000
105.330002,65.206520,-178.768936,-0.001466,0.003625,0.092073,290.053101,14.776009,0.920732,-178.768936,294.500488,0.000000
105.690002,65.129814,-178.813431,-0.001457,0.003625,0.092073,289.711884,14.758627,0.920732,-178.813431,294.500488,0.000000
106.050003,65.096291,-178.813431,-0.001462,0.003625,0.092073,289.562775,14.751030,0.920732,-178.813431,294.500488,0.000000
106.410004,65.043419,-178.902390,-0.001466,0.003625,0.092073,289.327576,14.739050,0.920732,-178.902390,294.500488,0.000000
106.770004,64.999855,-178.946869,-0.001453,0.003625,0.092073,289.133789,14.729177,0.920732,-178.946869,294.500488,0.000000
107.130005,64.958885,-178.902390,-0.001470,0.003625,0.092073,288.951538,14.719894,0.920732,-178.902390,294.500488,0.000000
107.490005,64.905266,-178.991348,-0.001470,0.003625,0.092073,288.713043,14.707744,0.920732,-178.991348,294.500488,0.000000
107.850006,64.867653,-178.991348,-0.001470,0.003625,0.092073,288.545746,14.699220,0.920732,-178.991348,294.500488,0.000000
108.210007,64.820366,-178.991348,-0.001462,0.003625,0.092082,288.335388,14.688504,0.920820,-178.991348,294.500488,0.000000
108.570007,64.767494,-178.991348,-0.001470,0.003625,0.092082,288.100189,14.676524,0.920820,-178.991348,294.500488,0.000000
108.930008,64.736214,-179.080307,-0.001453,0.003625,0.092082,287.961060,14.669436,0.920820,-179.080307,294.500488,0.000000
109.290009,64.693764,-179.124786,-0.001462,0.003625,0.092082,287.772247,14.659817,0.920820,-179.124786,294.500488,0.000000
109.650002,64.663231,-179.035828,-0.001462,0.003625,0.092082,287.636414,14.652897,0.920820,-179.035828,294.500488,0.000000
110.010002,64.621147,-179.124786,-0.001475,0.003625,0.092082,287.449219,14.643361,0.920820,-179.124786,294.500488,0.000000
110.370003,66.051430,-179.213745,-0.001466,0.003629,0.092177,293.811432,14.967468,0.921773,-179.213745,294.500488,0.000000
110.730003,65.998558,-179.213745,-0.001444,0.003629,0.092169,293.576263,14.955487,0.921686,-179.213745,294.500488,0.000000
111.090004,65.936363,-179.169266,-0.001470,0.003629,0.092169,293.299591,14.941394,0.921686,-179.169266,294.500488,0.000000
111.450005,65.858177,-179.169266,-0.001453,0.003629,0.092169,292.951813,14.923676,0.921686,-179.169266,294.500488,0.000000
111.810005,65.833595,-179.213745,-0.001462,0.003629,0.092169,292.842468,14.918106,0.921686,-179.213745,294.500488,0.000000
112.170006,65.781837,-179.213745,-0.001444,0.003629,0.092169,292.612213,14.906377,0.921686,-179.213745,294.500488,0.000000
112.530006,65.741249,-179.302719,-0.001444,0.003629,0.092169,292.431671,14.897180,0.921686,-179.302719,294.500488,0.000000
112.890007,65.668266,-179.347198,-0.001449,0.003629,0.092169,292.107025,14.880642,0.921686,-179.347198,294.500488,0.000000
113.250008,65.614632,-179.347198,-0.001444,0.003629,0.092169,291.868469,14.868487,0.921686,-179.347198,294.500488,0.000000
113.610008,65.579262,-179.347198,-0.001453,0.003629,0.092169,291.711121,14.860474,0.921686,-179.347198,294.500488,0.000000
113.970009,65.546120,-179.347198,-0.001453,0.003629,0.092169,291.563690,14.852962,0.921686,-179.347198,294.500488,0.000000
114.330002,65.503670,-179.391678,-0.001444,0.003629,0.092169,291.374878,14.843344,0.921686,-179.391678,294.500488,0.000000
114.690002,65.461220,-179.436157,-0.001470,0.003629,0.092169,291.186035,14.833725,0.921686,-179.436157,294.500488,0.000000
115.050003,65.402016,-179.436157,-0.001449,0.003629,0.092169,290.922699,14.820309,0.921686,-179.436157,294.500488,0.000000
115.410004,65.346535,-179.480637,-0.001444,0.003629,0.092177,290.675903,14.807736,0.921773,-179.480637,294.500488,0.000000
115.770004,65.294777,-179.480637,-0.001444,0.003629,0.092186,290.445679,14.796008,0.921860,-179.480637,294.500488,0.000000
116.130005,65.278389,-179.569595,-0.001453,0.003630,0.092203,290.372772,14.792295,0.922035,-179.569595,294.500488,0.000000
116.490005,65.254189,-179.569595,-0.001453,0.003631,0.092229,290.265137,14.786810,0.922292,-179.569595,294.500488,0.000000
116.850006,65.206520,-179.525116,-0.001457,0.003631,0.092229,290.053101,14.776009,0.922292,-179.525116,294.500488,0.000000
117.210007,65.155510,-179.658554,-0.001457,0.003631,0.092229,289.826172,14.764450,0.922292,-179.658554,294.500488,0.000000
117.570007,65.172630,-179.614075,-0.001444,0.003638,0.092403,289.902344,14.768330,0.924029,-179.614075,294.500488,0.000000
117.930008,65.221046,-179.703049,-0.001453,0.003638,0.092403,290.117706,14.779301,0.924029,-179.703049,294.500488,0.000000
118.290009,65.203163,-179.658554,-0.001457,0.003638,0.092403,290.038147,14.775248,0.924029,-179.658554,294.500488,0.000000
118.650009,65.181190,-179.658554,-0.001457,0.003638,0.092403,289.940430,14.770268,0.924029,-179.658554,294.500488,0.000000
119.010002,65.142464,-179.792007,-0.001453,0.003638,0.092403,289.768158,14.761494,0.924029,-179.792007,294.500488,0.000000
119.370003,65.099281,-179.747528,-0.001453,0.003638,0.092403,289.576080,14.751708,0.924029,-179.747528,294.500488,0.000000
119.730003,65.070229,-179.880966,-0.001457,0.003638,0.092403,289.446838,14.745125,0.924029,-179.880966,294.500488,0.000000
120.090004,65.048256,-179.836487,-0.001457,0.003638,0.092403,289.349091,14.740146,0.924029,-179.836487,294.500488,0.000000
120.450005,65.024422,-179.880966,-0.001449,0.003638,0.092403,289.243073,14.734745,0.924029,-179.880966,294.500488,0.000000
120.810005,64.984215,-179.925446,-0.001457,0.003638,0.092403,289.064240,14.725634,0.924029,-179.925446,294.500488,0.000000
121.170006,65.498085,-179.880966,-0.001444,0.003647,0.092646,291.350037,14.842078,0.926455,-179.880966,294.500488,0.000000
121.530006,65.568840,-179.925446,-0.001440,0.003647,0.092628,291.664764,14.858112,0.926281,-179.925446,294.500488,0.000000
121.890007,65.574791,-179.925446,-0.001449,0.003647,0.092628,291.691223,14.859460,0.926281,-179.925446,294.500488,0.000000
122.250008,65.555809,-180.014404,-0.001440,0.003647,0.092628,291.606812,14.855159,0.926281,-180.014404,294.500488,0.000000
122.610008,65.551338,-180.058884,-0.001453,0.003647,0.092628,291.586914,14.854146,0.926281,-180.058884,1681.640991,0.000000
122.970009,65.498085,-180.058884,-0.001453,0.003638,0.092403,291.350037,14.842078,0.924029,-180.058884,0.092455,0.000000
123.330009,65.434410,-180.147858,-0.001457,0.003626,0.092099,291.066803,14.827649,0.920994,-180.147858,0.091848,0.000000
123.690002,65.304451,-180.058884,-0.001444,0.003609,0.091657,290.488708,14.798200,0.916569,-180.058884,0.091249,0.000000
124.050003,65.225883,-180.192337,-0.001440,0.003585,0.091059,290.139221,14.780396,0.910585,-180.192337,0.090651,0.000000
124.410004,65.159599,-180.147858,-0.001444,0.003563,0.090512,289.844360,14.765376,0.905124,-180.147858,0.090052,0.000000
124.770004,65.124229,-180.147858,-0.001436,0.003545,0.090035,289.687042,14.757361,0.900351,-180.147858,0.089454,0.000000
125.130005,65.038948,-180.281296,-0.001431,0.003517,0.089341,289.307678,14.738036,0.893413,-180.281296,0.088847,0.000000
125.490005,65.013634,-180.236816,-0.001440,0.003499,0.088873,289.195099,14.732300,0.888731,-180.236816,0.088249,0.000000
125.850006,64.943993,-180.281296,-0.001449,0.003473,0.088205,288.885315,14.716518,0.882055,-180.281296,0.087650,0.000000
126.210007,64.894463,-180.370255,-0.001431,0.003454,0.087737,288.664978,14.705296,0.877373,-180.370255,0.087052,0.000000
126.570007,64.682961,-180.370255,-0.001427,0.003427,0.087035,287.724182,14.657369,0.870348,-180.370255,0.086453,0.000000
126.930008,64.104668,-180.370255,-0.001431,0.003402,0.086410,285.151794,14.526325,0.864103,-180.370255,0.085847,0.000000
127.290009,63.338692,-180.414734,-0.001418,0.003386,0.085994,281.744568,14.352753,0.859940,-180.414734,0.085248,0.000000
127.650009,62.537354,-180.414734,-0.001414,0.003362,0.085404,278.180054,14.171166,0.854043,-180.414734,0.084650,0.000000
128.010010,61.323418,-180.459213,-0.001418,0.003344,0.084936,272.780182,13.896086,0.849361,-180.459213,0.084052,0.000000
128.370010,59.927391,-180.459213,-0.001414,0.003317,0.084260,266.570343,13.579741,0.842597,-180.459213,0.083453,0.000000
128.730011,58.091225,-180.503693,-0.001406,0.003291,0.083583,258.402679,13.163660,0.835830,-180.503693,0.082855,0.000000
129.090012,56.536568,-180.503693,-0.001393,0.003271,0.083071,251.487213,12.811370,0.830713,-180.503693,0.082248,0.000000
129.450012,55.331200,-180.548187,-0.001401,0.003258,0.082742,246.125473,12.538229,0.827420,-180.548187,0.081649,0.000000
129.810013,53.281662,-180.548187,-0.001397,0.003227,0.081962,237.008667,12.073797,0.819615,-180.548187,0.081051,0.000000
130.170013,50.923424,-180.592667,-0.001401,0.003209,0.081502,226.518707,11.539413,0.815017,-180.592667,0.080452,0.000000
130.529999,49.283501,-180.681625,-0.001414,0.003194,0.081129,219.223953,11.167801,0.811288,-180.681625,0.079854,0.000000
130.889999,45.973854,-180.637146,-0.001406,0.003159,0.080236,204.501923,10.417824,0.802356,-180.637146,0.079247,0.000000
131.250000,43.692696,-180.726105,-0.001401,0.003138,0.079706,194.354813,9.900907,0.797065,-180.726105,0.078649,0.000000
131.610001,40.759521,-180.637146,-0.001418,0.003113,0.079065,181.307404,9.236239,0.790649,-180.637146,0.078050,0.000000
131.970001,38.555077,-180.726105,-0.001401,0.003093,0.078571,171.501541,8.736706,0.785706,-180.726105,0.077452,0.000000
132.330002,36.963181,-180.815063,-0.001406,0.003073,0.078059,164.420441,8.375977,0.780589,-180.815063,0.076853,0.000000
132.690002,33.516129,-180.726105,-0.001406,0.003044,0.077322,149.087189,7.594863,0.773216,-180.726105,0.076246,0.000000
133.050003,31.124756,-180.815063,-0.001406,0.003021,0.076723,138.449829,7.052970,0.767232,-180.815063,0.075648,0.000000
133.410004,28.001671,-180.770584,-0.001401,0.002992,0.075995,124.557655,6.345269,0.759950,-180.770584,0.075050,0.000000
133.770004,26.639160,-180.859543,-0.001406,0.002981,0.075709,118.496902,6.036520,0.757089,-180.859543,0.074451,0.000000
134.130005,23.838173,-180.904022,-0.001401,0.002949,0.074902,106.037491,5.401807,0.749023,-180.904022,0.073853,0.000000
134.490005,20.107002,-180.904022,-0.001406,0.002920,0.074156,89.440414,4.556312,0.741563,-180.904022,0.073246,0.000000
134.850006,17.844467,-180.992996,-0.001410,0.002898,0.073619,79.376152,4.043614,0.736189,-180.992996,0.072647,0.000000
135.210007,15.758804,-180.948502,-0.001406,0.002878,0.073090,70.098663,3.570996,0.730897,-180.948502,0.072049,0.000000
135.570007,13.025589,-181.037476,-0.001397,0.002852,0.072448,57.940712,2.951641,0.724478,-181.037476,0.071450,0.000000
135.930008,10.991692,-180.992996,-0.001406,0.002829,0.071867,48.893486,2.490753,0.718668,-180.992996,0.070852,0.000000
136.290009,8.805496,-181.037476,-0.001401,0.002815,0.071494,39.168804,1.995354,0.714940,-181.037476,0.070254,0.000000
136.650009,5.774010,-181.126434,-0.001397,0.002783,0.070696,25.684078,1.308409,0.706962,-181.126434,0.069647,0.000000
137.010010,3.379280,-181.081955,-0.001418,0.002761,0.070133,15.031789,0.765756,0.701326,-181.081955,0.069048,0.000000
137.370010,0.755173,-181.170914,-0.001406,0.002734,0.069447,3.359176,0.171125,0.694471,-181.170914,0.068450,0.000000
137.730011,-1.620190,-181.126434,-0.001397,0.002711,0.068857,-7.206964,-0.367140,0.688575,-181.126434,0.067852,0.000000
138.090012,-3.527107,-181.215393,-0.001410,0.002688,0.068285,-15.689357,-0.799254,0.682852,-181.215393,0.067253,0.000000
138.450012,-0.415939,-181.259872,-0.001436,0.002664,0.067661,-1.850191,-0.094253,0.676607,-181.259872,0.066646,0.000000
138.810013,-0.106491,-181.215393,-0.001423,0.002638,0.067010,-0.473696,-0.024131,0.670104,-181.215393,0.066048,0.000000
139.170013,-0.058456,-181.304352,-0.001418,0.002614,0.066403,-0.260027,-0.013246,0.664033,-181.304352,0.065450,0.000000
139.530014,-0.049149,-181.304352,-0.001436,0.002600,0.066048,-0.218624,-0.011137,0.660479,-181.304352,0.064851,0.000000
139.889999,-0.053993,-181.304352,-0.001462,0.002574,0.065371,-0.240174,-0.012235,0.653712,-181.304352,0.064253,0.000000
140.250000,-0.107986,-181.304352,-0.001505,0.002544,0.064626,-0.480348,-0.024470,0.646256,-181.304352,0.063646,0.000000
140.610001,-0.104630,-181.348831,-0.001548,0.002519,0.063984,-0.465415,-0.023709,0.639836,-181.348831,0.063047,0.000000
140.970001,-0.104263,-181.437805,-0.001574,0.002500,0.063507,-0.463786,-0.023626,0.635068,-181.437805,0.062449,0.000000
141.330002,-0.090111,-181.437805,-0.001608,0.002480,0.063004,-0.400833,-0.020419,0.630037,-181.437805,0.061850,0.000000
141.690002,-0.094208,-181.482285,-0.001630,0.002450,0.062232,-0.419057,-0.021348,0.622320,-181.482285,0.061252,0.000000
142.050003,-0.081177,-181.437805,-0.001647,0.002433,0.061807,-0.361092,-0.018395,0.618070,-181.437805,0.060645,0.000000
142.410004,-0.108727,-181.482285,-0.001686,0.002403,0.061035,-0.483640,-0.024638,0.610352,-181.482285,0.060047,0.000000
142.770004,-0.117294,-181.571243,-0.001703,0.002381,0.060472,-0.521751,-0.026579,0.604716,-181.571243,0.059448,0.000000
143.130005,-0.126602,-181.526764,-0.001725,0.002357,0.059873,-0.563155,-0.028688,0.598733,-181.526764,0.058850,0.000000
143.490005,-0.126976,-181.571243,-0.001742,0.002332,0.059223,-0.564817,-0.028773,0.592226,-181.571243,0.058251,0.000000
143.850006,-0.113571,-181.615723,-0.001768,0.002307,0.058607,-0.505190,-0.025736,0.586068,-181.615723,0.057653,0.000000
144.210007,-0.130699,-181.571243,-0.001794,0.002286,0.058061,-0.581379,-0.029617,0.580607,-181.571243,0.057046,0.000000
144.570007,-0.097183,-181.749161,-0.001811,0.002257,0.057323,-0.432293,-0.022022,0.573234,-181.749161,0.056448,0.000000
144.930008,-0.107613,-181.660202,-0.001845,0.002234,0.056734,-0.478685,-0.024385,0.567337,-181.660202,0.055849,0.000000
145.290009,-0.125854,-181.704681,-0.001845,0.002218,0.056343,-0.559829,-0.028519,0.563435,-181.704681,0.055251,0.000000
145.650009,-0.124741,-181.704681,-0.001897,0.002186,0.055528,-0.554874,-0.028267,0.555282,-181.704681,0.054652,0.000000
146.010010,-0.092720,-181.793640,-0.001897,0.002164,0.054965,-0.412439,-0.021011,0.549646,-181.793640,0.054045,0.000000
146.370010,-0.162354,-181.749161,-0.001923,0.002143,0.054435,-0.722184,-0.036790,0.544355,-181.749161,0.053447,0.000000
146.730011,-0.164581,-181.704681,-0.001944,0.002120,0.053855,-0.732094,-0.037295,0.538545,-181.704681,0.052848,0.000000
147.090012,-0.156769,-181.838135,-0.001979,0.002096,0.053230,-0.697342,-0.035524,0.532304,-181.838135,0.052250,0.000000
147.450012,-0.135170,-181.793640,-0.002009,0.002069,0.052562,-0.601266,-0.030630,0.525624,-181.793640,0.051652,0.000000
147.810013,-0.146339,-181.838135,-0.002026,0.002051,0.052085,-0.650950,-0.033161,0.520855,-181.838135,0.051045,0.000000
148.170013,-0.109848,-181.882614,-0.002057,0.002027,0.051478,-0.488628,-0.024892,0.514784,-181.882614,0.051357,0.000000
148.200012,-0.111336,-181.927094,-0.002061,0.002027,0.051478,-0.495246,-0.025229,0.514784,-181.927094,0.051357,0.000000