File: Data/compression 16/ManualNoHeating-17-16-reverse-hand-3_08302024_171454.csv
Time (sec),S:Load (lbs),S:HL1 (DIM),S:LVDT (in),S:Position (in),Ch:Position (mm),Ch:Load (N),Ch:Stress (MPa),Ch:Strain (mm/mm),Ch:HL1 (DIM),Set Point (),Cycles ()
0.210000,-0.053246,-85.937195,-0.009610,-0.004729,-0.120128,-0.236848,-0.012066,-1.201280,-85.937195,-0.119868,0.000000
0.570000,-0.064415,-85.937195,-0.009606,-0.004645,-0.117986,-0.286532,-0.014597,-1.179862,-85.937195,-0.117214,0.000000
0.930000,-0.071861,-86.070641,-0.009459,-0.004427,-0.112436,-0.319655,-0.016284,-1.124360,-86.070641,-0.111213,0.000000
1.290000,-0.109474,-86.026161,-0.009227,-0.004193,-0.106496,-0.486965,-0.024807,-1.064956,-86.026161,-0.105229,0.000000
1.650000,-0.058090,-86.115120,-0.008994,-0.003959,-0.100564,-0.258398,-0.013163,-1.005635,-86.115120,-0.099228,0.000000
2.010000,-0.053619,-86.115120,-0.008748,-0.003718,-0.094441,-0.238511,-0.012150,-0.944411,-86.115120,-0.093227,0.000000
2.370000,-0.063301,-86.115120,-0.008494,-0.003478,-0.088353,-0.281577,-0.014344,-0.883531,-86.115120,-0.087226,0.000000
2.730000,-0.054359,-86.204086,-0.008265,-0.003251,-0.082569,-0.241803,-0.012318,-0.825686,-86.204086,-0.081225,0.000000
3.090000,-0.065903,-86.159599,-0.008006,-0.003010,-0.076455,-0.293150,-0.014934,-0.764549,-86.159599,-0.075241,0.000000
3.450000,-0.070000,-86.248566,-0.007756,-0.002768,-0.070315,-0.311374,-0.015862,-0.703146,-86.248566,-0.069239,0.000000
3.810000,-0.093086,-86.248566,-0.007528,-0.002542,-0.064574,-0.414068,-0.021094,-0.645737,-86.248566,-0.063238,0.000000
4.170000,-0.032768,-86.293045,-0.007261,-0.002302,-0.058468,-0.145760,-0.007425,-0.584683,-86.293045,-0.057237,0.000000
4.530000,-0.049896,-86.382004,-0.007015,-0.002062,-0.052381,-0.221950,-0.011307,-0.523807,-86.382004,-0.051236,0.000000
4.890000,-0.040955,-86.382004,-0.006786,-0.001833,-0.046570,-0.182175,-0.009280,-0.465701,-86.382004,-0.045252,0.000000
5.250000,-0.076332,-86.426491,-0.006523,-0.001596,-0.040543,-0.339542,-0.017297,-0.405430,-86.426491,-0.039251,0.000000
5.610000,-0.124741,-86.470970,-0.006278,-0.001351,-0.034325,-0.554874,-0.028267,-0.343248,-86.470970,-0.033250,0.000000
5.970000,-0.070374,-86.470970,-0.006053,-0.001116,-0.028341,-0.313037,-0.015947,-0.283409,-86.470970,-0.027248,0.000000
6.330000,-0.041328,-86.515450,-0.005812,-0.000888,-0.022565,-0.183838,-0.009365,-0.225652,-86.515450,-0.021264,0.000000
6.690001,-0.006699,-86.559929,-0.005583,-0.000649,-0.016495,-0.029797,-0.001518,-0.164946,-86.559929,-0.015263,0.000000
7.050000,-0.048775,-86.515450,-0.005312,-0.000412,-0.010476,-0.216961,-0.011053,-0.104762,-86.515450,-0.009262,0.000000
7.410000,-0.058090,-86.604408,-0.005088,-0.000184,-0.004674,-0.258398,-0.013163,-0.046743,-86.604408,-0.003261,0.000000
7.770000,-0.078941,-86.604408,-0.004838,0.000063,0.001596,-0.351149,-0.017888,0.015957,-86.604408,0.002740,0.000000
8.130000,0.161987,-86.737854,-0.004708,-0.000000,-0.000000,0.720556,0.036707,-0.000000,-86.737854,0.000217,0.000000
8.490001,0.121773,-86.693375,-0.004721,-0.000000,-0.000000,0.541672,0.027594,-0.000000,-86.693375,0.000234,0.000000
8.850000,0.125496,-86.693375,-0.004725,-0.000000,-0.000000,0.558234,0.028438,-0.000000,-86.693375,0.000833,0.000000
9.210000,0.130333,-86.782333,-0.004725,0.000000,0.000009,0.579750,0.029534,0.000087,-86.782333,0.001440,0.000000
9.570001,0.307953,-86.782333,-0.004700,0.000039,0.000989,1.369843,0.069783,0.009890,-86.782333,0.002038,0.000000
9.930000,0.618141,-86.871300,-0.004665,0.000063,0.001604,2.749629,0.140073,0.016044,-86.871300,0.002637,0.000000
10.290001,0.897797,-86.871300,-0.004665,0.000084,0.002142,3.993599,0.203444,0.021423,-86.871300,0.003235,0.000000
10.650001,1.326767,-86.915779,-0.004622,0.000117,0.002966,5.901754,0.300650,0.029662,-86.915779,0.003833,0.000000
11.010000,1.644028,-87.004738,-0.004613,0.000138,0.003512,7.313001,0.372542,0.035124,-87.004738,0.004440,0.000000
11.370001,2.064812,-86.960258,-0.004592,0.000164,0.004154,9.184741,0.467893,0.041543,-86.960258,0.005039,0.000000
11.730000,2.569000,-86.960258,-0.004553,0.000187,0.004744,11.427484,0.582144,0.047440,-86.960258,0.005637,0.000000
12.090000,2.603256,-87.004738,-0.004557,0.000192,0.004883,11.579862,0.589906,0.048825,-87.004738,0.006236,0.000000
12.450001,3.277252,-87.049225,-0.004536,0.000223,0.005672,14.577946,0.742636,0.056717,-87.049225,0.006834,0.000000
12.810000,3.653725,-87.093704,-0.004523,0.000244,0.006192,16.252579,0.827946,0.061921,-87.093704,0.007441,0.000000
13.170001,4.374260,-87.093704,-0.004488,0.000278,0.007059,19.457680,0.991221,0.070592,-87.093704,0.008039,0.000000
13.530001,4.773071,-87.138184,-0.004467,0.000301,0.007641,21.231682,1.081593,0.076406,-87.138184,0.008638,0.000000
13.890000,5.139114,-87.138184,-0.004454,0.000322,0.008187,22.859922,1.164540,0.081867,-87.138184,0.009236,0.000000
14.250001,5.654854,-87.182663,-0.004428,0.000342,0.008698,25.154047,1.281408,0.086984,-87.182663,0.009835,0.000000
14.610001,6.249161,-87.316109,-0.004424,0.000371,0.009436,27.797655,1.416080,0.094357,-87.316109,0.010433,0.000000
14.970000,6.858734,-87.271629,-0.004393,0.000400,0.010155,30.509172,1.554211,0.101553,-87.271629,0.011040,0.000000
15.330001,7.186050,-87.360588,-0.004363,0.000421,0.010684,31.965149,1.628382,0.106844,-87.360588,0.011638,0.000000
15.690001,7.345047,-87.360588,-0.004355,0.000439,0.011161,32.672401,1.664411,0.111613,-87.360588,0.012237,0.000000
16.050001,7.901001,-87.316109,-0.004333,0.000461,0.011699,35.145409,1.790392,0.116991,-87.316109,0.012835,0.000000
16.410000,8.156075,-87.449547,-0.004303,0.000485,0.012324,36.280033,1.848193,0.123236,-87.449547,0.013433,0.000000
16.770000,8.691177,-87.405067,-0.004290,0.000515,0.013087,38.660286,1.969449,0.130867,-87.405067,0.014040,0.000000
17.130001,9.017372,-87.494034,-0.004251,0.000537,0.013650,40.111275,2.043366,0.136502,-87.494034,0.014639,0.000000
17.490002,9.541679,-87.538513,-0.004247,0.000566,0.014379,42.443508,2.162175,0.143788,-87.538513,0.015237,0.000000
17.850000,9.673866,-87.538513,-0.004208,0.000585,0.014864,43.031506,2.192130,0.148644,-87.538513,0.015836,0.000000
18.210001,9.685036,-87.627472,-0.004191,0.000598,0.015185,43.081192,2.194660,0.151854,-87.627472,0.016434,0.000000
18.570002,10.157951,-87.627472,-0.004165,0.000630,0.015992,45.184826,2.301825,0.159919,-87.627472,0.017041,0.000000
18.930000,10.718742,-87.671951,-0.004130,0.000657,0.016686,47.679348,2.428902,0.166857,-87.671951,0.017640,0.000000
19.290001,10.826736,-87.671951,-0.004130,0.000677,0.017197,48.159729,2.453373,0.171974,-87.671951,0.018238,0.000000
19.650002,11.146973,-87.671951,-0.004105,0.000701,0.017813,49.584209,2.525940,0.178129,-87.671951,0.018836,0.000000
20.010000,11.396461,-87.760918,-0.004083,0.000722,0.018342,50.693993,2.582475,0.183420,-87.760918,0.019435,0.000000
20.370001,11.663826,-87.760918,-0.004079,0.000744,0.018889,51.883289,2.643061,0.188885,-87.760918,0.020042,0.000000
20.730001,11.940498,-87.849876,-0.004040,0.000768,0.019495,53.113991,2.705756,0.194952,-87.849876,0.020640,0.000000
21.090000,11.958748,-87.894356,-0.004018,0.000786,0.019973,53.195168,2.709891,0.199725,-87.894356,0.021239,0.000000
21.450001,12.922821,-87.849876,-0.003997,0.000821,0.020866,57.483578,2.928353,0.208657,-87.849876,0.021837,0.000000
21.810001,12.948135,-87.938843,-0.003967,0.000843,0.021412,57.596184,2.934089,0.214119,-87.938843,0.022435,0.000000
22.170002,13.331306,-88.027802,-0.003941,0.000869,0.022080,59.300613,3.020917,0.220796,-88.027802,0.023034,0.000000
22.530001,13.399826,-88.027802,-0.003919,0.000889,0.022591,59.605404,3.036444,0.225913,-88.027802,0.023641,0.000000
22.890001,13.537979,-88.072281,-0.003898,0.000912,0.023164,60.219940,3.067750,0.231639,-88.072281,0.024239,0.000000
23.250002,13.735710,-88.027802,-0.003893,0.000930,0.023623,61.099491,3.112556,0.236234,-88.027802,0.024838,0.000000
23.610001,14.297241,-88.116760,-0.003863,0.000956,0.024274,63.597305,3.239801,0.242737,-88.116760,0.025436,0.000000
23.970001,14.602959,-88.072281,-0.003829,0.000984,0.024994,64.957207,3.309078,0.249936,-88.072281,0.026034,0.000000
24.330002,14.861015,-88.161247,-0.003807,0.001008,0.025601,66.105095,3.367554,0.256007,-88.161247,0.026641,0.000000
24.690001,14.977196,-88.250206,-0.003798,0.001027,0.026095,66.621895,3.393881,0.260950,-88.250206,0.027240,0.000000
25.050001,15.273605,-88.205727,-0.003773,0.001051,0.026702,67.940392,3.461048,0.267021,-88.205727,0.027838,0.000000
25.410002,15.749870,-88.294685,-0.003742,0.001074,0.027292,70.058922,3.568972,0.272917,-88.294685,0.028437,0.000000
25.770000,16.134155,-88.339172,-0.003734,0.001101,0.027959,71.768311,3.656052,0.279594,-88.339172,0.029035,0.000000
26.130001,16.494614,-88.294685,-0.003699,0.001130,0.028697,73.371704,3.737733,0.286967,-88.294685,0.029642,0.000000
26.490002,16.410088,-88.383652,-0.003695,0.001148,0.029156,72.995712,3.718579,0.291562,-88.383652,0.030240,0.000000
26.850000,16.706123,-88.472610,-0.003678,0.001172,0.029772,74.312546,3.785662,0.297720,-88.472610,0.030839,0.000000
27.210001,16.700539,-88.428131,-0.003626,0.001190,0.030214,74.287704,3.784396,0.302144,-88.428131,0.031437,0.000000
27.570002,17.399849,-88.517090,-0.003626,0.001222,0.031038,77.398392,3.942862,0.310380,-88.517090,0.032035,0.000000
27.930002,17.713387,-88.472610,-0.003596,0.001248,0.031697,78.793076,4.013911,0.316974,-88.472610,0.032642,0.000000
28.290001,17.890266,-88.561577,-0.003583,0.001274,0.032365,79.579880,4.053992,0.323650,-88.561577,0.033241,0.000000
28.650002,17.833664,-88.606056,-0.003548,0.001294,0.032877,79.328102,4.041166,0.328767,-88.606056,0.033839,0.000000
29.010002,18.168053,-88.606056,-0.003531,0.001318,0.033484,80.815536,4.116940,0.334838,-88.606056,0.034438,0.000000
29.370001,18.377701,-88.695015,-0.003510,0.001338,0.033996,81.748093,4.164447,0.339955,-88.695015,0.035036,0.000000
29.730001,18.719543,-88.695015,-0.003505,0.001360,0.034550,83.268684,4.241909,0.345504,-88.695015,0.035634,0.000000
30.090002,19.126915,-88.739494,-0.003475,0.001389,0.035279,85.080765,4.334221,0.352790,-88.739494,0.036242,0.000000
30.450001,19.345871,-88.739494,-0.003454,0.001415,0.035938,86.054733,4.383837,0.359380,-88.739494,0.036840,0.000000
30.810001,19.215164,-88.783981,-0.003419,0.001433,0.036389,85.473320,4.354218,0.363891,-88.783981,0.037438,0.000000
31.170002,19.623291,-88.783981,-0.003428,0.001459,0.037048,87.288757,4.446701,0.370481,-88.783981,0.038037,0.000000
31.530001,19.363373,-88.828461,-0.003393,0.001474,0.037430,86.132584,4.387803,0.374296,-88.828461,0.038635,0.000000
31.890001,20.445862,-88.917419,-0.003367,0.001510,0.038349,90.947739,4.633099,0.383489,-88.917419,0.039242,0.000000
32.250000,20.322975,-88.917419,-0.003341,0.001532,0.038904,90.401108,4.605252,0.389038,-88.917419,0.039841,0.000000
32.610001,20.314781,-88.917419,-0.003311,0.001555,0.039485,90.364662,4.603395,0.394848,-88.917419,0.040439,0.000000
32.970001,20.614174,-89.050865,-0.003290,0.001577,0.040066,91.696426,4.671238,0.400661,-89.050865,0.041037,0.000000
33.330002,20.221687,-88.961899,-0.003272,0.001591,0.040404,89.950554,4.582300,0.404041,-88.961899,0.041636,0.000000
33.690002,20.815254,-89.006386,-0.003260,0.001620,0.041141,92.590874,4.716804,0.411414,-89.006386,0.042243,0.000000
34.050003,21.158951,-89.095345,-0.003247,0.001645,0.041774,94.119713,4.794687,0.417743,-89.095345,0.042841,0.000000
34.410000,21.571541,-89.139824,-0.003229,0.001672,0.042468,95.955009,4.888181,0.424680,-89.139824,0.043440,0.000000
34.770000,21.450890,-89.139824,-0.003186,0.001689,0.042910,95.418320,4.860841,0.429105,-89.139824,0.044038,0.000000
35.130001,21.737991,-89.139824,-0.003182,0.001714,0.043544,96.695412,4.925900,0.435437,-89.139824,0.044636,0.000000
35.490002,21.987480,-89.228790,-0.003165,0.001739,0.044177,97.805199,4.982434,0.441765,-89.228790,0.045243,0.000000
35.850002,22.370651,-89.228790,-0.003152,0.001764,0.044801,99.509628,5.069262,0.448010,-89.228790,0.045842,0.000000
36.210003,22.762390,-89.228790,-0.003113,0.001791,0.045504,101.252167,5.158031,0.455035,-89.228790,0.046440,0.000000
36.570004,22.783989,-89.362228,-0.003104,0.001815,0.046093,101.348244,5.162926,0.460932,-89.362228,0.047039,0.000000
36.930000,22.776535,-89.317749,-0.003091,0.001833,0.046553,101.315086,5.161237,0.465527,-89.317749,0.047637,0.000000
37.290001,23.206253,-89.362228,-0.003053,0.001859,0.047212,103.226570,5.258612,0.472120,-89.362228,0.048244,0.000000
37.650002,23.317223,-89.406715,-0.003040,0.001880,0.047741,103.720184,5.283758,0.477408,-89.406715,0.048842,0.000000
38.010002,23.706726,-89.406715,-0.003018,0.001905,0.048391,105.452782,5.372021,0.483914,-89.406715,0.049441,0.000000
38.370003,24.145752,-89.540154,-0.003005,0.001934,0.049120,107.405670,5.471506,0.491200,-89.540154,0.050039,0.000000
38.730003,24.317787,-89.540154,-0.002988,0.001958,0.049727,108.170921,5.510489,0.497267,-89.540154,0.050637,0.000000
39.090000,24.238846,-89.495674,-0.002958,0.001975,0.050169,107.819771,5.492601,0.501692,-89.495674,0.051236,0.000000
39.450001,24.359863,-89.629120,-0.002971,0.001996,0.050690,108.358086,5.520024,0.506896,-89.629120,0.051843,0.000000
39.810001,24.916565,-89.540154,-0.002932,0.002023,0.051392,110.834419,5.646174,0.513921,-89.540154,0.052441,0.000000
40.170002,25.492996,-89.673599,-0.002928,0.002051,0.052086,113.398514,5.776795,0.520858,-89.673599,0.053040,0.000000
40.530003,25.444962,-89.673599,-0.002910,0.002072,0.052632,113.184845,5.765911,0.526320,-89.673599,0.053638,0.000000
40.890003,25.864998,-89.629120,-0.002876,0.002095,0.053213,115.053253,5.861093,0.532130,-89.629120,0.054236,0.000000
41.250004,25.934258,-89.762558,-0.002859,0.002117,0.053768,115.361336,5.876787,0.537682,-89.762558,0.054844,0.000000
41.610001,26.146133,-89.807037,-0.002863,0.002138,0.054306,116.303810,5.924798,0.543057,-89.807037,0.055442,0.000000
41.970001,26.122307,-89.807037,-0.002828,0.002153,0.054679,116.197823,5.919399,0.546789,-89.807037,0.056040,0.000000
42.330002,26.804115,-89.851524,-0.002820,0.002183,0.055442,119.230659,6.073899,0.554419,-89.851524,0.056639,0.000000
42.690002,26.927002,-89.896004,-0.002790,0.002200,0.055884,119.777290,6.101746,0.558844,-89.896004,0.057237,0.000000
43.050003,27.771545,-89.940483,-0.002768,0.002233,0.056725,123.534004,6.293122,0.567254,-89.940483,0.057844,0.000000
43.410004,28.581078,-89.940483,-0.002759,0.002264,0.057497,127.134979,6.476565,0.574971,-89.940483,0.058443,0.000000
43.770000,28.614220,-89.940483,-0.002725,0.002285,0.058044,127.282410,6.484075,0.580436,-89.940483,0.059041,0.000000
44.130001,28.839882,-89.984962,-0.002721,0.002306,0.058581,128.286209,6.535211,0.585811,-89.984962,0.059639,0.000000
44.490002,28.896111,-90.029442,-0.002695,0.002327,0.059110,128.536316,6.547952,0.591102,-90.029442,0.060238,0.000000
44.850002,29.437538,-90.073929,-0.002682,0.002351,0.059717,130.944702,6.670641,0.597173,-90.073929,0.060845,0.000000
45.210003,29.979713,-90.073929,-0.002677,0.002375,0.060324,133.356430,6.793500,0.603244,-90.073929,0.061443,0.000000
45.570004,30.587791,-90.118408,-0.002652,0.002401,0.060983,136.061295,6.931293,0.609834,-90.118408,0.062042,0.000000
45.930000,30.538643,-90.162888,-0.002621,0.002426,0.061617,135.842667,6.920156,0.616166,-90.162888,0.062640,0.000000
46.290001,30.219147,-90.207367,-0.002604,0.002434,0.061833,134.421478,6.847756,0.618335,-90.207367,0.063238,0.000000
46.650002,31.765236,-90.251846,-0.002608,0.002471,0.062770,141.298828,7.198105,0.627698,-90.251846,0.063837,0.000000
47.010002,32.469391,-90.207367,-0.002570,0.002498,0.063438,144.431061,7.357669,0.634379,-90.207367,0.064444,0.000000
47.370003,32.485405,-90.296333,-0.002561,0.002519,0.063993,144.502304,7.361298,0.639927,-90.296333,0.065042,0.000000
47.730003,32.651108,-90.340813,-0.002557,0.002537,0.064444,145.239380,7.398847,0.644439,-90.340813,0.065640,0.000000
48.090004,33.538101,-90.340813,-0.002522,0.002568,0.065224,149.184921,7.599842,0.652243,-90.340813,0.066239,0.000000
48.450001,33.817757,-90.385292,-0.002527,0.002588,0.065736,150.428894,7.663213,0.657361,-90.385292,0.066837,0.000000
48.810001,34.596756,-90.429771,-0.002496,0.002617,0.066464,153.894058,7.839737,0.664643,-90.429771,0.067444,0.000000
49.170002,35.289368,-90.429771,-0.002458,0.002642,0.067115,156.974945,7.996685,0.671149,-90.429771,0.068043,0.000000
49.530003,35.797287,-90.518738,-0.002453,0.002667,0.067739,159.234283,8.111781,0.677390,-90.518738,0.068641,0.000000
49.890003,36.080292,-90.474251,-0.002445,0.002688,0.068286,160.493149,8.175911,0.682856,-90.474251,0.069239,0.000000
50.250004,36.329033,-90.607697,-0.002423,0.002710,0.068832,161.599609,8.232276,0.688317,-90.607697,0.069838,0.000000
50.610001,36.840302,-90.607697,-0.002410,0.002734,0.069456,163.873840,8.348131,0.694562,-90.607697,0.070445,0.000000
50.970001,36.008423,-90.652176,-0.002397,0.002749,0.069812,160.173462,8.159625,0.698120,-90.652176,0.071043,0.000000
51.330002,38.348038,-90.696663,-0.002367,0.002780,0.070618,170.580597,8.689789,0.706182,-90.696663,0.071642,0.000000
51.690002,38.720413,-90.696663,-0.002358,0.002802,0.071173,172.237000,8.774171,0.711734,-90.696663,0.072240,0.000000
52.050003,39.147896,-90.696663,-0.002354,0.002824,0.071720,174.138535,8.871039,0.717196,-90.696663,0.072838,0.000000
52.410004,39.449516,-90.741142,-0.002341,0.002842,0.072197,175.480209,8.939388,0.721969,-90.741142,0.073446,0.000000
52.770004,40.208412,-90.741142,-0.002311,0.002869,0.072865,178.855957,9.111356,0.728645,-90.741142,0.074044,0.000000
53.130001,42.062454,-90.785622,-0.002294,0.002902,0.073723,187.103134,9.531488,0.737229,-90.785622,0.074642,0.000000
53.490002,42.574089,-90.741142,-0.002285,0.002926,0.074313,189.379013,9.647427,0.743126,-90.741142,0.075241,0.000000
53.850002,43.083496,-90.830101,-0.002268,0.002948,0.074877,191.644958,9.762859,0.748766,-90.830101,0.075839,0.000000
54.210003,43.124832,-90.919067,-0.002238,0.002964,0.075284,191.828827,9.772226,0.752842,-90.919067,0.076437,0.000000
54.570004,43.967880,-90.963547,-0.002238,0.002989,0.075926,195.578903,9.963264,0.759257,-90.963547,0.077045,0.000000
54.930004,44.667946,-91.052505,-0.002220,0.003013,0.076524,198.692947,10.121902,0.765241,-91.052505,0.077643,0.000000
55.290001,45.725105,-91.008026,-0.002199,0.003038,0.077166,203.395432,10.361457,0.771661,-91.008026,0.078241,0.000000
55.650002,46.799026,-91.052505,-0.002190,0.003066,0.077869,208.172470,10.604812,0.778685,-91.052505,0.078840,0.000000
56.010002,47.246620,-91.096985,-0.002186,0.003087,0.078415,210.163467,10.706237,0.784147,-91.096985,0.079438,0.000000
56.370003,48.368210,-91.141472,-0.002169,0.003112,0.079048,215.152542,10.960393,0.790479,-91.141472,0.080045,0.000000
56.730003,48.556999,-91.141472,-0.002143,0.003128,0.079447,215.992325,11.003173,0.794468,-91.141472,0.080644,0.000000
57.090004,49.762741,-91.141472,-0.002130,0.003160,0.080262,221.355728,11.276399,0.802617,-91.141472,0.081242,0.000000
57.450005,50.943909,-91.230431,-0.002126,0.003184,0.080886,226.609818,11.544055,0.808862,-91.230431,0.081840,0.000000
57.810001,51.859200,-91.230431,-0.002113,0.003207,0.081467,230.681244,11.751463,0.814672,-91.230431,0.082439,0.000000
58.170002,52.515694,-91.274910,-0.002091,0.003229,0.082022,233.601471,11.900227,0.820225,-91.274910,0.083046,0.000000
58.530003,53.101807,-91.363876,-0.002082,0.003250,0.082543,236.208633,12.033042,0.825429,-91.363876,0.083644,0.000000
58.890003,54.792007,-91.363876,-0.002057,0.003278,0.083254,243.727020,12.416046,0.832537,-91.363876,0.084242,0.000000
59.250004,55.890877,-91.452835,-0.002048,0.003302,0.083878,248.615036,12.665053,0.838782,-91.452835,0.084841,0.000000
59.610004,56.807281,-91.319389,-0.002039,0.003327,0.084511,252.691406,12.872714,0.845114,-91.319389,0.085439,0.000000
59.970001,57.692787,-91.452835,-0.002022,0.003349,0.085075,256.630341,13.073372,0.850750,-91.452835,0.086046,0.000000
60.330002,58.591324,-91.497314,-0.002005,0.003371,0.085613,260.627228,13.276984,0.856128,-91.497314,0.086645,0.000000
60.690002,59.266060,-91.497314,-0.001996,0.003389,0.086072,263.628601,13.429881,0.860723,-91.497314,0.087243,0.000000
61.050003,61.045998,-91.541794,-0.001979,0.003418,0.086827,271.546173,13.833221,0.868266,-91.541794,0.087841,0.000000
61.410004,62.231636,-91.541794,-0.001975,0.003443,0.087460,276.820129,14.101891,0.874598,-91.541794,0.088440,0.000000
61.770004,62.863174,-91.586281,-0.001957,0.003462,0.087937,279.629364,14.244999,0.879367,-91.586281,0.089038,0.000000
62.130001,64.170570,-91.675240,-0.001936,0.003486,0.088544,285.444946,14.541259,0.885438,-91.675240,0.089645,0.000000
62.490002,65.293282,-91.675240,-0.001932,0.003509,0.089134,290.439026,14.795669,0.891335,-91.675240,0.090244,0.000000
62.850002,66.035042,-91.719719,-0.001923,0.003528,0.089602,293.738525,14.963754,0.896021,-91.719719,0.090842,0.000000
63.210003,65.398293,-91.675240,-0.001919,0.003527,0.089576,290.906128,14.819465,0.895760,-91.675240,0.015725,0.000000
63.570004,65.008781,-91.808685,-0.001901,0.003538,0.089871,289.173492,14.731200,0.898708,-91.808685,294.500488,0.000000
63.930004,65.258278,-91.853165,-0.001901,0.003550,0.090166,290.283325,14.787737,0.901657,-91.853165,294.500488,0.000000
64.290001,64.435707,-91.764198,-0.001876,0.003550,0.090174,286.624329,14.601340,0.901744,-91.764198,294.500488,0.000000
64.650002,66.610741,-91.853165,-0.001871,0.003477,0.088310,296.299377,15.094210,0.883099,-91.853165,294.500488,0.000000
65.010002,65.721504,-91.853165,-0.001858,0.003478,0.088353,292.343842,14.892705,0.883531,-91.853165,294.500488,0.000000
65.370003,65.032997,-91.897644,-0.001858,0.003563,0.090504,289.281219,14.736689,0.905040,-91.897644,294.500488,0.000000
65.730003,65.692467,-91.986610,-0.001858,0.003587,0.091119,292.214691,14.886127,0.911195,-91.986610,294.500488,0.000000
66.090004,65.152519,-91.986610,-0.001863,0.003587,0.091119,289.812866,14.763772,0.911195,-91.986610,294.500488,0.000000
66.450005,64.578697,-92.031090,-0.001845,0.003587,0.091119,287.260406,14.633741,0.911195,-92.031090,294.500488,0.000000
66.810005,66.961876,-91.986610,-0.001837,0.003509,0.089125,297.861298,15.173778,0.891248,-91.986610,294.500488,0.000000
67.170006,66.224953,-92.075569,-0.001832,0.003479,0.088362,294.583313,15.006789,0.883618,-92.075569,294.500488,0.000000
67.530006,65.627678,-92.120049,-0.001832,0.003488,0.088605,291.926483,14.871445,0.886048,-92.120049,294.500488,0.000000
67.890007,65.242271,-92.164528,-0.001815,0.003588,0.091137,290.212128,14.784110,0.911369,-92.164528,294.500488,0.000000
68.250000,65.441109,-92.164528,-0.001815,0.003617,0.091883,291.096588,14.829167,0.918829,-92.164528,294.500488,0.000000
68.610001,65.152901,-92.209015,-0.001828,0.003621,0.091961,289.814575,14.763858,0.919608,-92.209015,294.500488,0.000000
68.970001,65.254921,-92.209015,-0.001811,0.003626,0.092091,290.268372,14.786977,0.920910,-92.209015,294.500488,0.000000
69.330002,64.973778,-92.297974,-0.001819,0.003627,0.092125,289.017792,14.723269,0.921255,-92.297974,294.500488,0.000000
69.690002,65.228859,-92.297974,-0.001815,0.003632,0.092264,290.152466,14.781071,0.922644,-92.297974,294.500488,0.000000
70.050003,65.195351,-92.342453,-0.001811,0.003637,0.092386,290.003418,14.773478,0.923859,-92.342453,294.500488,0.000000
70.410004,65.123100,-92.342453,-0.001802,0.003639,0.092420,289.682007,14.757106,0.924203,-92.342453,294.500488,0.000000
70.770004,65.332756,-92.431419,-0.001798,0.003644,0.092568,290.614624,14.804614,0.925679,-92.431419,294.500488,0.000000
71.130005,65.191246,-92.475899,-0.001802,0.003645,0.092585,289.985138,14.772547,0.925853,-92.475899,294.500488,0.000000
71.490005,65.130180,-92.431419,-0.001798,0.003647,0.092646,289.713501,14.758710,0.926459,-92.431419,294.500488,0.000000
71.850006,65.265358,-92.431419,-0.001794,0.003652,0.092767,290.314819,14.789341,0.927674,-92.431419,294.500488,0.000000
72.210007,65.251945,-92.520378,-0.001794,0.003655,0.092828,290.255157,14.786302,0.928280,-92.520378,294.500488,0.000000
72.570000,65.582237,-92.520378,-0.001802,0.003661,0.093001,291.724365,14.861147,0.930013,-92.520378,294.500488,0.000000
72.930000,65.445961,-92.564857,-0.001802,0.003660,0.092976,291.118164,14.830267,0.929756,-92.564857,294.500488,0.000000
73.290001,65.232582,-92.609337,-0.001785,0.003660,0.092976,290.169006,14.781914,0.929756,-92.609337,294.500488,0.000000
73.650002,64.999855,-92.609337,-0.001798,0.003660,0.092976,289.133789,14.729177,0.929756,-92.609337,294.500488,0.000000
74.010002,64.807701,-92.742783,-0.001789,0.003661,0.092984,288.279053,14.685635,0.929843,-92.742783,294.500488,0.000000
74.370003,64.617424,-92.698303,-0.001781,0.003661,0.092984,287.432648,14.642518,0.929843,-92.698303,294.500488,0.000000
74.730003,66.413750,-92.742783,-0.001776,0.003637,0.092386,295.423126,15.049571,0.923859,-92.742783,294.500488,0.000000
75.090004,66.148613,-92.787262,-0.001794,0.003637,0.092386,294.243713,14.989491,0.923859,-92.787262,294.500488,0.000000
75.450005,65.923332,-92.831741,-0.001763,0.003638,0.092394,293.241638,14.938440,0.923942,-92.831741,294.500488,0.000000
75.810005,65.702141,-92.876228,-0.001768,0.003639,0.092420,292.257721,14.888318,0.924203,-92.876228,294.500488,0.000000
76.170006,65.537560,-92.831741,-0.001763,0.003648,0.092663,291.525635,14.851024,0.926633,-92.831741,294.500488,0.000000
76.530006,65.376320,-93.009666,-0.001776,0.003662,0.093027,290.808380,14.814486,0.930274,-93.009666,294.500488,0.000000
76.890007,65.264229,-92.965187,-0.001772,0.003667,0.093132,290.309784,14.789085,0.931315,-92.965187,294.500488,0.000000
77.250000,65.089592,-92.965187,-0.001772,0.003670,0.093209,289.532959,14.749513,0.932095,-92.965187,294.500488,0.000000
77.610001,65.219551,-93.054146,-0.001772,0.003679,0.093444,290.111053,14.778962,0.934438,-93.054146,294.500488,0.000000
77.970001,65.412071,-93.009666,-0.001768,0.003685,0.093600,290.967438,14.822587,0.935997,-93.009666,294.500488,0.000000
78.330002,65.362175,-93.054146,-0.001759,0.003685,0.093600,290.745483,14.811281,0.935997,-93.054146,294.500488,0.000000
78.690002,65.251198,-93.098633,-0.001772,0.003685,0.093600,290.251831,14.786133,0.935997,-93.098633,294.500488,0.000000
79.050003,65.164818,-93.143112,-0.001776,0.003686,0.093635,289.867584,14.766559,0.936345,-93.143112,294.500488,0.000000
79.410004,65.271309,-93.232071,-0.001768,0.003690,0.093721,290.341278,14.790690,0.937212,-93.232071,294.500488,0.000000
79.770004,65.201683,-93.232071,-0.001781,0.003690,0.093721,290.031586,14.774913,0.937212,-93.232071,294.500488,0.000000
80.130005,65.314140,-93.232071,-0.001759,0.003694,0.093834,290.531799,14.800396,0.938340,-93.232071,294.500488,0.000000
80.490005,65.301094,-93.321037,-0.001759,0.003694,0.093834,290.473785,14.797440,0.938340,-93.321037,294.500488,0.000000
80.850006,65.234444,-93.321037,-0.001750,0.003694,0.093834,290.177307,14.782336,0.938340,-93.321037,294.500488,0.000000
81.210007,65.254555,-93.321037,-0.001768,0.003697,0.093903,290.266754,14.786894,0.939032,-93.321037,294.500488,0.000000
81.570007,65.211357,-93.365517,-0.001750,0.003697,0.093903,290.074615,14.777104,0.939032,-93.365517,294.500488,0.000000
81.930000,65.270561,-93.409996,-0.001759,0.003699,0.093964,290.337952,14.790521,0.939642,-93.409996,294.500488,0.000000
82.290001,65.238167,-93.454475,-0.001750,0.003700,0.093973,290.193848,14.783179,0.939729,-93.454475,294.500488,0.000000
82.650002,65.202415,-93.498962,-0.001759,0.003700,0.093990,290.034821,14.775078,0.939899,-93.498962,294.500488,0.000000
83.010002,65.165932,-93.587921,-0.001755,0.003702,0.094025,289.872528,14.766811,0.940247,-93.587921,294.500488,0.000000
83.370003,65.156242,-93.543442,-0.001746,0.003702,0.094042,289.829437,14.764615,0.940422,-93.543442,294.500488,0.000000
83.730003,65.181190,-93.587921,-0.001755,0.003704,0.094085,289.940430,14.770268,0.940853,-93.587921,294.500488,0.000000
84.090004,65.130928,-93.587921,-0.001755,0.003705,0.094103,289.716827,14.758880,0.941027,-93.587921,294.500488,0.000000
84.450005,65.116035,-93.543442,-0.001750,0.003705,0.094111,289.650604,14.755505,0.941114,-93.543442,294.500488,0.000000
84.810005,65.184914,-93.721367,-0.001750,0.003708,0.094172,289.956970,14.771112,0.941724,-93.721367,294.500488,0.000000
85.170006,65.170769,-93.676880,-0.001746,0.003708,0.094172,289.894043,14.767907,0.941724,-93.676880,294.500488,0.000000
85.530006,65.070976,-93.676880,-0.001763,0.003708,0.094172,289.450165,14.745294,0.941724,-93.676880,294.500488,0.000000
85.890007,65.118263,-93.765846,-0.001746,0.003709,0.094215,289.660492,14.756009,0.942155,-93.765846,294.500488,0.000000
86.250008,65.068001,-93.810326,-0.001746,0.003710,0.094224,289.436920,14.744620,0.942242,-93.810326,294.500488,0.000000
86.610001,65.022942,-93.899284,-0.001746,0.003710,0.094233,289.236481,14.734409,0.942329,-93.899284,294.500488,0.000000
86.970001,65.186043,-93.854805,-0.001746,0.003713,0.094302,289.962006,14.771369,0.943022,-93.854805,294.500488,0.000000
87.330002,65.106346,-93.943771,-0.001746,0.003713,0.094302,289.607483,14.753309,0.943022,-93.943771,294.500488,0.000000
87.690002,65.068733,-93.943771,-0.001750,0.003713,0.094302,289.440186,14.744785,0.943022,-93.943771,294.500488,0.000000
88.050003,64.991280,-93.943771,-0.001746,0.003713,0.094302,289.095642,14.727234,0.943022,-93.943771,294.500488,0.000000
88.410004,64.925743,-94.077209,-0.001755,0.003714,0.094346,288.804138,14.712383,0.943457,-94.077209,294.500488,0.000000
88.770004,65.059059,-93.988251,-0.001750,0.003716,0.094389,289.397156,14.742594,0.943888,-93.988251,294.500488,0.000000
89.130005,65.031136,-94.077209,-0.001733,0.003716,0.094389,289.272949,14.736266,0.943888,-94.077209,294.500488,0.000000
89.490005,64.976021,-94.166176,-0.001742,0.003716,0.094389,289.027771,14.723777,0.943888,-94.166176,294.500488,0.000000
89.850006,64.911964,-94.077209,-0.001755,0.003716,0.094389,288.742828,14.709262,0.943888,-94.077209,294.500488,0.000000
90.210007,64.944374,-94.166176,-0.001738,0.003721,0.094502,288.886993,14.716606,0.945016,-94.166176,294.500488,0.000000
90.570007,65.118263,-94.255135,-0.001755,0.003721,0.094502,289.660492,14.756009,0.945016,-94.255135,294.500488,0.000000
90.930008,65.080284,-94.255135,-0.001742,0.003721,0.094502,289.491577,14.747403,0.945016,-94.255135,294.500488,0.000000
91.290001,65.032997,-94.255135,-0.001742,0.003721,0.094502,289.281219,14.736689,0.945016,-94.255135,294.500488,0.000000
91.650002,64.984581,-94.299614,-0.001733,0.003721,0.094502,289.065857,14.725716,0.945016,-94.299614,294.500488,0.000000
92.010002,64.929466,-94.344101,-0.001746,0.003721,0.094502,288.820679,14.713227,0.945016,-94.344101,294.500488,0.000000
92.370003,65.037086,-94.344101,-0.001733,0.003724,0.094580,289.299408,14.737615,0.945800,-94.344101,294.500488,0.000000
92.730003,65.032616,-94.388580,-0.001738,0.003724,0.094580,289.279510,14.736601,0.945800,-94.388580,294.500488,0.000000
93.090004,65.020332,-94.477539,-0.001729,0.003725,0.094606,289.224884,14.733818,0.946057,-94.477539,294.500488,0.000000
93.450005,65.012505,-94.433060,-0.001746,0.003725,0.094606,289.190063,14.732044,0.946057,-94.433060,294.500488,0.000000
93.810005,64.979744,-94.477539,-0.001746,0.003725,0.094623,289.044342,14.724620,0.946231,-94.477539,294.500488,0.000000
94.170006,64.971916,-94.477539,-0.001729,0.003725,0.094623,289.009521,14.722846,0.946231,-94.477539,294.500488,0.000000
94.530006,64.933571,-94.522018,-0.001738,0.003725,0.094623,288.838959,14.714157,0.946231,-94.522018,294.500488,0.000000
94.890007,64.961876,-94.610985,-0.001733,0.003727,0.094667,288.964844,14.720572,0.946667,-94.610985,294.500488,0.000000
95.250008,64.951073,-94.522018,-0.001725,0.003727,0.094667,288.916809,14.718123,0.946667,-94.522018,294.500488,0.000000
95.610008,64.914574,-94.610985,-0.001742,0.003727,0.094667,288.754456,14.709852,0.946667,-94.610985,294.500488,0.000000
95.970001,64.856117,-94.610985,-0.001720,0.003727,0.094667,288.494415,14.696606,0.946667,-94.610985,294.500488,0.000000
96.330002,64.809563,-94.744423,-0.001729,0.003727,0.094675,288.287323,14.686057,0.946754,-94.744423,294.500488,0.000000
96.690002,64.750740,-94.744423,-0.001738,0.003727,0.094675,288.025665,14.672727,0.946754,-94.744423,294.500488,0.000000
97.050003,64.720940,-94.788910,-0.001725,0.003727,0.094675,287.893127,14.665975,0.946754,-94.788910,294.500488,0.000000
97.410004,65.689110,-94.833389,-0.001725,0.003739,0.094962,292.199768,14.885365,0.949615,-94.833389,294.500488,0.000000
97.770004,65.671608,-94.833389,-0.001729,0.003739,0.094962,292.121887,14.881399,0.949615,-94.833389,294.500488,0.000000
98.130005,65.677574,-94.877869,-0.001712,0.003739,0.094962,292.148437,14.882751,0.949615,-94.877869,294.500488,0.000000
98.490005,65.623573,-94.877869,-0.001720,0.003739,0.094962,291.908234,14.870514,0.949615,-94.877869,294.500488,0.000000
98.850006,65.600487,-94.922348,-0.001729,0.003739,0.094962,291.805542,14.865283,0.949615,-94.922348,294.500488,0.000000
99.210007,65.569954,-94.966827,-0.001733,0.003739,0.094962,291.669708,14.858364,0.949615,-94.966827,294.500488,0.000000
99.570007,65.551704,-94.966827,-0.001712,0.003739,0.094962,291.588531,14.854228,0.949615,-94.966827,294.500488,0.000000
99.930008,65.495110,-95.055794,-0.001729,0.003739,0.094962,291.336792,14.841404,0.949615,-95.055794,294.500488,0.000000
100.290009,65.434410,-95.055794,-0.001733,0.003739,0.094962,291.066803,14.827649,0.949615,-95.055794,294.500488,0.000000
100.650002,65.379295,-95.055794,-0.001720,0.003739,0.094962,290.821625,14.815161,0.949615,-95.055794,294.500488,0.000000
101.010002,65.327904,-95.189232,-0.001716,0.003739,0.094962,290.593018,14.803514,0.949615,-95.189232,294.500488,0.000000
101.370003,65.291786,-95.189232,-0.001716,0.003739,0.094962,290.432373,14.795330,0.949615,-95.189232,294.500488,0.000000
101.730003,65.253807,-95.278198,-0.001712,0.003739,0.094962,290.263428,14.786724,0.949615,-95.278198,294.500488,0.000000
102.090004,65.203911,-95.189232,-0.001716,0.003739,0.094962,290.041473,14.775417,0.949615,-95.189232,294.500488,0.000000
102.450005,65.155510,-95.278198,-0.001716,0.003739,0.094962,289.826172,14.764450,0.949615,-95.278198,294.500488,0.000000
102.810005,65.080650,-95.367157,-0.001720,0.003739,0.094962,289.493195,14.747486,0.949615,-95.367157,294.500488,0.000000
103.170006,65.055702,-95.367157,-0.001725,0.003739,0.094962,289.382202,14.741833,0.949615,-95.367157,294.500488,0.000000
103.530006,65.010277,-95.367157,-0.001720,0.003739,0.094962,289.180145,14.731539,0.949615,-95.367157,294.500488,0.000000
103.890007,64.967461,-95.411636,-0.001725,0.003739,0.094962,288.989685,14.721837,0.949615,-95.411636,294.500488,0.000000
104.250008,64.927238,-95.456123,-0.001720,0.003739,0.094962,288.810791,14.712722,0.949615,-95.456123,294.500488,0.000000
104.610008,64.873238,-95.500603,-0.001720,0.003739,0.094962,288.570587,14.700485,0.949615,-95.500603,294.500488,0.000000
104.970001,64.820366,-95.500603,-0.001716,0.003739,0.094962,288.335388,14.688504,0.949615,-95.500603,294.500488,0.000000
105.330002,64.782753,-95.500603,-0.001733,0.003739,0.094962,288.168091,14.679982,0.949615,-95.500603,294.500488,0.000000
105.690002,64.742165,-95.545082,-0.001729,0.003739,0.094962,287.987518,14.670785,0.949615,-95.545082,294.500488,0.000000
106.050003,64.706047,-95.589561,-0.001720,0.003739,0.094962,287.826874,14.662601,0.949615,-95.589561,294.500488,0.000000
106.410004,64.665459,-95.634048,-0.001720,0.003739,0.094962,287.646332,14.653402,0.949615,-95.634048,294.500488,0.000000
106.770004,64.614067,-95.678528,-0.001716,0.003739,0.094962,287.417725,14.641757,0.949615,-95.678528,294.500488,0.000000
107.130005,64.563423,-95.767487,-0.001716,0.003739,0.094962,287.192444,14.630281,0.949615,-95.767487,294.500488,0.000000
107.490005,64.509804,-95.678528,-0.001712,0.003739,0.094962,286.953949,14.618131,0.949615,-95.678528,294.500488,0.000000
107.850006,64.489708,-95.767487,-0.001703,0.003739,0.094962,286.864563,14.613577,0.949615,-95.767487,294.500488,0.000000
108.210007,64.437935,-95.767487,-0.001716,0.003739,0.094962,286.634247,14.601845,0.949615,-95.767487,294.500488,0.000000
108.570007,66.598824,-95.856453,-0.001707,0.003759,0.095490,296.246368,15.091509,0.954903,-95.856453,294.500488,0.000000
108.930008,66.361610,-95.900932,-0.001725,0.003730,0.094745,295.191193,15.037756,0.947446,-95.900932,294.500488,0.000000
109.290009,66.277840,-95.856453,-0.001716,0.003730,0.094745,294.818542,15.018773,0.947446,-95.856453,294.500488,0.000000
109.650002,66.229057,-95.945412,-0.001707,0.003730,0.094745,294.601562,15.007719,0.947446,-95.945412,294.500488,0.000000
110.010002,66.180275,-95.945412,-0.001707,0.003730,0.094745,294.384552,14.996665,0.947446,-95.945412,294.500488,0.000000
110.370003,66.118828,-95.989891,-0.001707,0.003730,0.094745,294.111237,14.982740,0.947446,-95.989891,294.500488,0.000000
110.730003,66.088295,-96.078857,-0.001712,0.003730,0.094745,293.975433,14.975821,0.947446,-96.078857,294.500488,0.000000
111.090004,66.036903,-96.078857,-0.001699,0.003730,0.094745,293.746826,14.964176,0.947446,-96.078857,294.500488,0.000000
111.450005,65.987389,-96.123337,-0.001694,0.003730,0.094745,293.526550,14.952956,0.947446,-96.123337,294.500488,0.000000
111.810005,65.928917,-96.167816,-0.001716,0.003730,0.094745,293.266479,14.939706,0.947446,-96.167816,294.500488,0.000000
112.170006,65.846992,-96.123337,-0.001707,0.003730,0.094745,292.902039,14.921142,0.947446,-96.123337,294.500488,0.000000
112.530006,65.889076,-96.256775,-0.001712,0.003730,0.094745,293.089264,14.930678,0.947446,-96.256775,294.500488,0.000000
112.890007,65.857796,-96.212296,-0.001703,0.003730,0.094745,292.950104,14.923590,0.947446,-96.212296,294.500488,0.000000
113.250008,65.766197,-96.301262,-0.001729,0.003730,0.094745,292.542664,14.902833,0.947446,-96.301262,294.500488,0.000000
113.610008,65.749062,-96.256775,-0.001716,0.003730,0.094745,292.466431,14.898951,0.947446,-96.256775,294.500488,0.000000
113.970009,65.729698,-96.345741,-0.001699,0.003730,0.094745,292.380310,14.894563,0.947446,-96.345741,294.500488,0.000000
114.330002,65.634377,-96.434700,-0.001703,0.003730,0.094745,291.956299,14.872962,0.947446,-96.434700,294.500488,0.000000
114.690002,65.594536,-96.345741,-0.001690,0.003730,0.094745,291.779053,14.863934,0.947446,-96.345741,294.500488,0.000000
115.050003,65.586342,-96.479179,-0.001694,0.003730,0.094745,291.742615,14.862078,0.947446,-96.479179,294.500488,0.000000
115.410004,65.547981,-96.479179,-0.001712,0.003730,0.094745,291.571991,14.853385,0.947446,-96.479179,294.500488,0.000000
115.770004,65.515587,-96.479179,-0.001712,0.003730,0.094753,291.427887,14.846044,0.947533,-96.479179,294.500488,0.000000
116.130005,65.492134,-96.568146,-0.001699,0.003730,0.094753,291.323547,14.840730,0.947533,-96.568146,294.500488,0.000000
116.490005,65.441109,-96.523666,-0.001707,0.003730,0.094753,291.096588,14.829167,0.947533,-96.523666,294.500488,0.000000
116.850006,65.374458,-96.612625,-0.001703,0.003730,0.094753,290.800110,14.814064,0.947533,-96.612625,294.500488,0.000000
117.210007,65.343925,-96.612625,-0.001699,0.003730,0.094753,290.664307,14.807145,0.947533,-96.612625,294.500488,0.000000
117.570007,65.311897,-96.701584,-0.001690,0.003730,0.094753,290.521820,14.799888,0.947533,-96.701584,294.500488,0.000000
117.930008,65.270943,-96.657104,-0.001716,0.003730,0.094753,290.339661,14.790606,0.947533,-96.657104,294.500488,0.000000
118.290009,65.260139,-96.746071,-0.001703,0.003730,0.094753,290.291595,14.788159,0.947533,-96.746071,294.500488,0.000000
118.650009,65.230721,-96.790550,-0.001699,0.003730,0.094753,290.160736,14.781493,0.947533,-96.790550,294.500488,0.000000
119.010002,65.189766,-96.790550,-0.001707,0.003730,0.094753,289.978577,14.772212,0.947533,-96.790550,294.500488,0.000000
119.370003,65.142845,-96.790550,-0.001712,0.003730,0.094753,289.769836,14.761580,0.947533,-96.790550,294.500488,0.000000
119.730003,65.106346,-96.879509,-0.001699,0.003731,0.094771,289.607483,14.753309,0.947707,-96.879509,294.500488,0.000000
120.090004,65.076927,-96.835030,-0.001690,0.003731,0.094771,289.476624,14.746643,0.947707,-96.835030,294.500488,0.000000
120.450005,65.033730,-96.923996,-0.001703,0.003731,0.094771,289.284485,14.736854,0.947707,-96.923996,294.500488,0.000000
120.810005,65.031136,-96.968475,-0.001694,0.003731,0.094779,289.272949,14.736266,0.947794,-96.968475,294.500488,0.000000
121.170006,65.170403,-96.968475,-0.001699,0.003754,0.095343,289.892426,14.767824,0.953430,-96.968475,294.500488,0.000000
121.530006,65.132042,-97.057434,-0.001694,0.003754,0.095343,289.721802,14.759132,0.953430,-97.057434,294.500488,0.000000
121.890007,65.117149,-97.012955,-0.001707,0.003754,0.095343,289.655548,14.755756,0.953430,-97.012955,294.500488,0.000000
122.250008,65.088478,-97.101913,-0.001694,0.003754,0.095343,289.528015,14.749260,0.953430,-97.101913,294.500488,0.000000
122.610008,65.048256,-97.101913,-0.001686,0.003754,0.095343,289.349091,14.740146,0.953430,-97.101913,294.500488,0.000000
122.970009,65.020699,-97.146400,-0.001694,0.003754,0.095343,289.226501,14.733901,0.953430,-97.146400,294.500488,0.000000
123.330009,65.004692,-97.190880,-0.001707,0.003754,0.095343,289.155304,14.730273,0.953430,-97.190880,294.500488,0.000000
123.690002,64.970436,-97.190880,-0.001699,0.003752,0.095291,289.002930,14.722511,0.952908,-97.190880,0.095343,0.000000
124.050003,64.836372,-97.279839,-0.001703,0.003741,0.095031,288.406586,14.692132,0.950308,-97.279839,0.094814,0.000000
124.410004,64.803612,-97.279839,-0.001699,0.003724,0.094580,288.260864,14.684708,0.945800,-97.279839,0.094207,0.000000
124.770004,64.690407,-97.279839,-0.001690,0.003707,0.094146,287.757294,14.659056,0.941462,-97.279839,0.093608,0.000000
125.130005,64.707909,-97.279839,-0.001707,0.003685,0.093600,287.835144,14.663021,0.935997,-97.279839,0.093010,0.000000
125.490005,64.657265,-97.368805,-0.001694,0.003662,0.093027,287.609863,14.651546,0.930274,-97.368805,0.092412,0.000000
125.850006,64.579445,-97.457764,-0.001707,0.003636,0.092351,287.263733,14.633911,0.923511,-97.457764,0.091813,0.000000
126.210007,64.553749,-97.457764,-0.001690,0.003612,0.091753,287.149414,14.628089,0.917527,-97.457764,0.091206,0.000000
126.570007,64.501244,-97.546722,-0.001694,0.003589,0.091163,286.915863,14.616191,0.911630,-97.546722,0.090608,0.000000
126.930008,64.444267,-97.457764,-0.001699,0.003574,0.090781,286.662415,14.603280,0.907815,-97.457764,0.090009,0.000000
127.290009,64.331078,-97.546722,-0.001694,0.003545,0.090035,286.158936,14.577631,0.900355,-97.546722,0.089411,0.000000
127.650009,63.912529,-97.591209,-0.001694,0.003522,0.089463,284.297119,14.482786,0.894632,-97.591209,0.088813,0.000000
128.010010,63.113411,-97.591209,-0.001699,0.003501,0.088925,280.742462,14.301703,0.889253,-97.591209,0.088215,0.000000
128.370010,62.239830,-97.680168,-0.001694,0.003481,0.088414,276.856598,14.103746,0.884140,-97.680168,0.087607,0.000000
128.730011,60.866890,-97.680168,-0.001669,0.003455,0.087755,270.749451,13.792634,0.877547,-97.680168,0.087009,0.000000
129.090012,59.953461,-97.724648,-0.001673,0.003435,0.087252,266.686310,13.585649,0.872517,-97.724648,0.086411,0.000000
129.450012,57.809708,-97.724648,-0.001673,0.003407,0.086549,257.150421,13.099867,0.865492,-97.724648,0.085812,0.000000
129.810013,56.395439,-97.724648,-0.001664,0.003390,0.086098,250.859436,12.779388,0.860984,-97.724648,0.085214,0.000000
130.170013,55.546059,-97.813614,-0.001669,0.003371,0.085613,247.081207,12.586917,0.856128,-97.813614,0.084607,0.000000
130.529999,53.372894,-97.813614,-0.001677,0.003356,0.085231,237.414490,12.094471,0.852313,-97.813614,0.084008,0.000000
130.889999,50.788628,-97.858093,-0.001656,0.003328,0.084520,225.919098,11.508868,0.845201,-97.858093,0.083410,0.000000
131.250000,49.282753,-97.947052,-0.001660,0.003312,0.084112,219.220627,11.167631,0.841125,-97.947052,0.082812,0.000000
131.610001,45.742233,-97.858093,-0.001660,0.003278,0.083262,203.471619,10.365338,0.832624,-97.858093,0.082213,0.000000
131.970001,43.109192,-97.947052,-0.001664,0.003251,0.082586,191.759262,9.768682,0.825860,-97.947052,0.081606,0.000000
132.330002,41.104713,-97.991531,-0.001651,0.003237,0.082213,182.842896,9.314461,0.822132,-97.991531,0.081008,0.000000
132.690002,38.777756,-97.991531,-0.001664,0.003216,0.081693,172.492065,8.787165,0.816928,-97.991531,0.080409,0.000000
133.050003,36.321960,-98.080498,-0.001673,0.003191,0.081043,161.568146,8.230674,0.810426,-98.080498,0.079811,0.000000
133.410004,32.753143,-98.080498,-0.001656,0.003156,0.080166,145.693253,7.421968,0.801663,-98.080498,0.079213,0.000000
133.770004,30.705093,-98.169456,-0.001677,0.003139,0.079733,136.583084,6.957874,0.797330,-98.169456,0.078605,0.000000
134.130005,28.302917,-98.124977,-0.001669,0.003117,0.079178,125.897667,6.413533,0.791777,-98.124977,0.078007,0.000000
134.490005,26.946365,-98.169456,-0.001660,0.003105,0.078866,119.863419,6.106134,0.788659,-98.169456,0.077409,0.000000
134.850006,23.196571,-98.213943,-0.001673,0.003069,0.077955,103.183502,5.256418,0.779552,-98.213943,0.076810,0.000000
135.210007,19.505615,-98.213943,-0.001669,0.003034,0.077053,86.765312,4.420036,0.770533,-98.213943,0.076212,0.000000
135.570007,17.406929,-98.347382,-0.001669,0.003015,0.076576,77.429886,3.944466,0.765764,-98.347382,0.075605,0.000000
135.930008,15.671669,-98.302902,-0.001664,0.003000,0.076194,69.711067,3.551251,0.761945,-98.302902,0.075006,0.000000
136.290009,13.068787,-98.347382,-0.001660,0.002976,0.075579,58.132866,2.961429,0.755791,-98.347382,0.074408,0.000000
136.650009,10.502396,-98.347382,-0.001660,0.002951,0.074963,46.716988,2.379877,0.749633,-98.347382,0.073810,0.000000
137.010010,8.086815,-98.436348,-0.001669,0.002925,0.074304,35.971951,1.832498,0.743039,-98.436348,0.073211,0.000000
137.370010,6.627113,-98.436348,-0.001669,0.002907,0.073827,29.478872,1.501725,0.738270,-98.436348,0.072613,0.000000
137.730011,2.919777,-98.436348,-0.001660,0.002876,0.073055,12.987817,0.661631,0.730553,-98.436348,0.072006,0.000000
138.090012,0.373497,-98.525307,-0.001660,0.002851,0.072405,1.661398,0.084636,0.724047,-98.525307,0.071408,0.000000
138.450012,-1.865582,-98.569786,-0.001656,0.002827,0.071806,-8.298521,-0.422747,0.718063,-98.569786,0.070809,0.000000
138.810013,-3.206123,-98.525307,-0.001664,0.002807,0.071304,-14.261549,-0.726518,0.713036,-98.525307,0.070211,0.000000
139.170013,-0.134048,-98.614265,-0.001664,0.002776,0.070523,-0.596277,-0.030376,0.705228,-98.614265,0.069613,0.000000
139.530014,-0.007812,-98.569786,-0.001664,0.002758,0.070055,-0.034752,-0.001770,0.700546,-98.569786,0.069005,0.000000
139.889999,0.010056,-98.614265,-0.001669,0.002737,0.069525,0.044729,0.002279,0.695255,-98.614265,0.068407,0.000000
140.250000,-0.005585,-98.658752,-0.001669,0.002708,0.068780,-0.024842,-0.001266,0.687799,-98.658752,0.067809,0.000000
140.610001,-0.028671,-98.747711,-0.001673,0.002683,0.068147,-0.127536,-0.006497,0.681467,-98.747711,0.067210,0.000000
140.970001,-0.037605,-98.792191,-0.001686,0.002664,0.067670,-0.167277,-0.008521,0.676698,-98.792191,0.066612,0.000000
141.330002,-0.064415,-98.747711,-0.001699,0.002636,0.066950,-0.286532,-0.014597,0.669499,-98.747711,0.066005,0.000000
141.690002,-0.048035,-98.836670,-0.001750,0.002612,0.066334,-0.213669,-0.010885,0.663345,-98.836670,0.065406,0.000000
142.050003,-0.020851,-98.836670,-0.001750,0.002607,0.066213,-0.092750,-0.004725,0.662130,-98.836670,0.064808,0.000000
142.410004,-0.024948,-98.836670,-0.001738,0.002607,0.066213,-0.110975,-0.005653,0.662130,-98.836670,0.064210,0.000000
142.770004,-0.061066,-98.925636,-0.001802,0.002541,0.064531,-0.271634,-0.013838,0.645306,-98.925636,0.063611,0.000000
143.130005,-0.065163,-98.881157,-0.001802,0.002519,0.063993,-0.289858,-0.014766,0.639927,-98.881157,0.063004,0.000000
143.490005,-0.053993,-99.014595,-0.001815,0.002503,0.063568,-0.240174,-0.012235,0.635677,-99.014595,0.062406,0.000000
143.850006,-0.056595,-98.925636,-0.001850,0.002473,0.062822,-0.251746,-0.012825,0.628221,-98.925636,0.061807,0.000000
144.210007,-0.096809,-99.014595,-0.001832,0.002450,0.062224,-0.430630,-0.021937,0.622237,-99.014595,0.061209,0.000000
144.570007,-0.080429,-99.059074,-0.001863,0.002431,0.061738,-0.357766,-0.018225,0.617381,-99.059074,0.060611,0.000000
144.930008,-0.071495,-99.014595,-0.001888,0.002399,0.060940,-0.318026,-0.016201,0.609402,-99.014595,0.060012,0.000000
145.290009,-0.086761,-99.148041,-0.001906,0.002379,0.060437,-0.385934,-0.019660,0.604372,-99.148041,0.059405,0.000000
145.650009,-0.081543,-99.103561,-0.001910,0.002364,0.060056,-0.362721,-0.018478,0.600557,-99.103561,0.058807,0.000000
146.010010,-0.072983,-99.148041,-0.001953,0.002328,0.059136,-0.324644,-0.016538,0.591363,-99.148041,0.058208,0.000000
146.370010,-0.075218,-99.192520,-0.001970,0.002309,0.058642,-0.334587,-0.017045,0.586420,-99.192520,0.057610,0.000000
146.730011,-0.086388,-99.237000,-0.001992,0.002285,0.058035,-0.384271,-0.019576,0.580349,-99.237000,0.057011,0.000000
147.090012,-0.102402,-99.281487,-0.002013,0.002261,0.057419,-0.455506,-0.023205,0.574191,-99.281487,0.056404,0.000000
147.450012,-0.088623,-99.237000,-0.002044,0.002232,0.056699,-0.394215,-0.020082,0.566992,-99.237000,0.055806,0.000000
147.810013,-0.112823,-99.237000,-0.002057,0.002213,0.056205,-0.501864,-0.025566,0.562049,-99.237000,0.055208,0.000000
148.170013,-0.103516,-99.370445,-0.002100,0.002188,0.055572,-0.460460,-0.023457,0.555721,-99.370445,0.054609,0.000000
148.530014,-0.090485,-99.370445,-0.002104,0.002174,0.055208,-0.402496,-0.020504,0.552076,-99.370445,0.054011,0.000000
148.890015,-0.105377,-99.459404,-0.002126,0.002139,0.054340,-0.468741,-0.023879,0.543405,-99.459404,0.053404,0.000000
149.250000,-0.132561,-99.459404,-0.002151,0.002121,0.053872,-0.589660,-0.030039,0.538723,-99.459404,0.052806,0.000000
149.610001,-0.104630,-99.459404,-0.002169,0.002092,0.053144,-0.465415,-0.023709,0.531437,-99.459404,0.052207,0.000000
149.970001,-0.067398,-99.459404,-0.002199,0.002084,0.052936,-0.299802,-0.015273,0.529355,-99.459404,0.052788,0.000000
150.000000,-0.074471,-99.548370,-0.002199,0.002084,0.052936,-0.331261,-0.016875,0.529355,-99.548370,0.052788,0.000000