File: Data/compression 16/ManualNoHeating-17-16-reverse-hand-2-2_08302024_172523.csv
Time (sec),S:Load (lbs),S:HL1 (DIM),S:LVDT (in),S:Position (in),Ch:Position (mm),Ch:Load (N),Ch:Stress (MPa),Ch:Strain (mm/mm),Ch:HL1 (DIM),Set Point (),Cycles ()
0.210000,-0.088249,-140.159470,-0.009541,-0.004645,-0.117977,-0.392552,-0.019998,-1.179775,-140.159470,-0.117717,0.000000
0.570000,-0.115059,-140.203964,-0.009546,-0.004560,-0.115827,-0.511808,-0.026073,-1.158269,-140.203964,-0.115046,0.000000
0.930000,-0.095695,-140.248444,-0.009416,-0.004339,-0.110198,-0.425675,-0.021685,-1.101984,-140.248444,-0.109045,0.000000
1.290000,-0.132187,-140.248444,-0.009175,-0.004105,-0.104258,-0.587997,-0.029954,-1.042580,-140.248444,-0.103044,0.000000
1.650000,-0.099792,-140.292923,-0.008925,-0.003874,-0.098396,-0.443899,-0.022613,-0.983955,-140.292923,-0.097043,0.000000
2.010000,-0.094582,-140.248444,-0.008679,-0.003631,-0.092230,-0.420720,-0.021432,-0.922296,-140.248444,-0.091059,0.000000
2.370000,-0.095695,-140.292923,-0.008433,-0.003392,-0.086150,-0.425675,-0.021685,-0.861503,-140.292923,-0.085058,0.000000
2.730000,-0.093834,-140.381882,-0.008213,-0.003164,-0.080375,-0.417394,-0.021263,-0.803745,-140.381882,-0.079057,0.000000
3.090000,-0.115059,-140.337402,-0.007950,-0.002925,-0.074287,-0.511808,-0.026073,-0.742865,-140.337402,-0.073055,0.000000
3.450000,-0.125854,-140.426361,-0.007709,-0.002682,-0.068112,-0.559829,-0.028519,-0.681122,-140.426361,-0.067054,0.000000
3.810000,-0.121765,-140.470840,-0.007480,-0.002455,-0.062345,-0.541638,-0.027592,-0.623452,-140.470840,-0.061070,0.000000
4.170000,-0.068138,-140.470840,-0.007230,-0.002217,-0.056300,-0.303093,-0.015440,-0.563003,-140.470840,-0.055069,0.000000
4.530000,-0.091225,-140.515320,-0.006972,-0.001976,-0.050195,-0.405788,-0.020672,-0.501953,-140.515320,-0.049068,0.000000
4.890000,-0.086761,-140.515320,-0.006743,-0.001748,-0.044402,-0.385934,-0.019660,-0.444021,-140.515320,-0.043066,0.000000
5.250000,-0.121017,-140.559799,-0.006489,-0.001509,-0.038340,-0.538313,-0.027423,-0.383402,-140.559799,-0.037065,0.000000
5.610000,-0.170174,-140.559799,-0.006247,-0.001266,-0.032157,-0.756970,-0.038562,-0.321568,-140.559799,-0.031082,0.000000
5.970000,-0.118408,-140.604294,-0.005989,-0.001028,-0.026112,-0.526706,-0.026832,-0.261124,-140.604294,-0.025080,0.000000
6.330000,-0.082291,-140.648773,-0.005773,-0.000803,-0.020397,-0.366047,-0.018647,-0.203972,-140.648773,-0.019079,0.000000
6.690001,-0.049149,-140.648773,-0.005519,-0.000564,-0.014327,-0.218624,-0.011137,-0.143266,-140.648773,-0.013078,0.000000
7.050000,-0.081177,-140.693253,-0.005286,-0.000325,-0.008265,-0.361092,-0.018395,-0.082647,-140.693253,-0.007094,0.000000
7.410000,-0.062927,-140.737732,-0.005053,-0.000095,-0.002420,-0.279914,-0.014260,-0.024197,-140.737732,-0.001093,0.000000
7.770000,0.072243,-140.737732,-0.004937,-0.000000,-0.000000,0.321352,0.016370,-0.000000,-140.737732,0.000234,0.000000
8.130000,0.140388,-140.826691,-0.004945,-0.000000,-0.000000,0.624479,0.031812,-0.000000,-140.826691,0.000251,0.000000
8.490001,0.122139,-140.737732,-0.004941,-0.000000,-0.000000,0.543301,0.027677,-0.000000,-140.737732,0.000850,0.000000
8.850000,0.117302,-140.826691,-0.004954,0.000000,0.000009,0.521785,0.026581,0.000087,-140.826691,0.001457,0.000000
9.210000,0.287102,-140.826691,-0.004911,0.000036,0.000902,1.277092,0.065058,0.009019,-140.826691,0.002055,0.000000
9.570001,0.467331,-140.915649,-0.004894,0.000066,0.001674,2.078792,0.105899,0.016737,-140.915649,0.002654,0.000000
9.930000,0.671394,-140.960129,-0.004863,0.000094,0.002376,2.986511,0.152140,0.023762,-140.960129,0.003252,0.000000
10.290001,0.830025,-140.915649,-0.004833,0.000116,0.002940,3.692134,0.188086,0.029397,-140.915649,0.003850,0.000000
10.650001,1.003174,-140.960129,-0.004816,0.000138,0.003504,4.462340,0.227322,0.035037,-140.960129,0.004457,0.000000
11.010000,1.216919,-141.004608,-0.004803,0.000159,0.004032,5.413126,0.275758,0.040324,-141.004608,0.005056,0.000000
11.370001,1.561737,-141.004608,-0.004773,0.000184,0.004683,6.946953,0.353895,0.046831,-141.004608,0.005654,0.000000
11.730000,1.817184,-141.138062,-0.004756,0.000206,0.005238,8.083241,0.411780,0.052379,-141.138062,0.006253,0.000000
12.090000,2.159019,-141.093582,-0.004730,0.000235,0.005967,9.603798,0.489241,0.059665,-141.093582,0.006851,0.000000
12.450001,2.229027,-141.093582,-0.004712,0.000253,0.006417,9.915206,0.505105,0.064173,-141.093582,0.007458,0.000000
12.810000,2.572723,-141.138062,-0.004678,0.000275,0.006990,11.444045,0.582987,0.069899,-141.138062,0.008057,0.000000
13.170001,3.121605,-141.182541,-0.004669,0.000304,0.007718,13.885592,0.707366,0.077182,-141.182541,0.008655,0.000000
13.530001,3.315605,-141.227020,-0.004652,0.000322,0.008169,14.748549,0.751327,0.081693,-141.227020,0.009253,0.000000
13.890000,3.946037,-141.227020,-0.004618,0.000355,0.009019,17.552851,0.894185,0.090190,-141.227020,0.009852,0.000000
14.250001,4.214516,-141.315979,-0.004600,0.000378,0.009591,18.747103,0.955023,0.095913,-141.315979,0.010450,0.000000
14.610001,4.561569,-141.271500,-0.004600,0.000400,0.010155,20.290873,1.033666,0.101553,-141.271500,0.011057,0.000000
14.970000,4.950325,-141.404938,-0.004570,0.000422,0.010710,22.020145,1.121760,0.107101,-141.404938,0.011656,0.000000
15.330001,5.281738,-141.360458,-0.004562,0.000440,0.011170,23.494345,1.196859,0.111700,-141.360458,0.012254,0.000000
15.690001,5.775131,-141.315979,-0.004523,0.000463,0.011760,25.689066,1.308663,0.117597,-141.315979,0.012852,0.000000
16.050001,6.250275,-141.449417,-0.004501,0.000491,0.012470,27.802610,1.416332,0.124705,-141.449417,0.013451,0.000000
16.410000,6.743668,-141.449417,-0.004493,0.000518,0.013156,29.997332,1.528137,0.131559,-141.449417,0.014058,0.000000
16.770000,6.939163,-141.493912,-0.004458,0.000538,0.013667,30.866940,1.572437,0.136673,-141.493912,0.014656,0.000000
17.130001,7.410217,-141.449417,-0.004437,0.000561,0.014240,32.962292,1.679179,0.142399,-141.449417,0.015255,0.000000
17.490002,7.724129,-141.538391,-0.004419,0.000581,0.014760,34.358639,1.750313,0.147600,-141.538391,0.015853,0.000000
17.850000,8.434982,-141.627350,-0.004406,0.000610,0.015506,37.520676,1.911394,0.155060,-141.627350,0.016451,0.000000
18.210001,8.774963,-141.582870,-0.004372,0.000636,0.016156,39.032986,1.988435,0.161562,-141.582870,0.017058,0.000000
18.570002,9.003601,-141.538391,-0.004350,0.000657,0.016685,40.050018,2.040245,0.166853,-141.538391,0.017657,0.000000
18.930000,9.358467,-141.627350,-0.004342,0.000679,0.017249,41.628540,2.120659,0.172489,-141.627350,0.018255,0.000000
19.290001,9.806061,-141.582870,-0.004307,0.000703,0.017856,43.619537,2.222085,0.178560,-141.582870,0.018853,0.000000
19.650002,10.153854,-141.671829,-0.004286,0.000727,0.018472,45.166599,2.300896,0.184718,-141.671829,0.019452,0.000000
20.010000,10.549690,-141.671829,-0.004268,0.000754,0.019157,46.927364,2.390594,0.191569,-141.671829,0.020059,0.000000
20.370001,10.885941,-141.760788,-0.004212,0.000779,0.019790,48.423080,2.466789,0.197901,-141.760788,0.020657,0.000000
20.730001,11.177505,-141.716309,-0.004234,0.000802,0.020362,49.720028,2.532859,0.203624,-141.716309,0.021256,0.000000
21.090000,11.352524,-141.760788,-0.004186,0.000821,0.020857,50.498547,2.572519,0.208567,-141.760788,0.021854,0.000000
21.450001,11.495140,-141.849747,-0.004178,0.000842,0.021386,51.132938,2.604836,0.213858,-141.849747,0.022452,0.000000
21.810001,12.183655,-141.849747,-0.004152,0.000871,0.022114,54.195602,2.760855,0.221144,-141.849747,0.023059,0.000000
22.170002,12.492355,-141.894241,-0.004135,0.000896,0.022756,55.568771,2.830808,0.227559,-141.894241,0.023658,0.000000
22.530001,12.623428,-141.849747,-0.004122,0.000919,0.023346,56.151814,2.860510,0.233456,-141.849747,0.024256,0.000000
22.890001,12.995430,-141.938721,-0.004092,0.000941,0.023901,57.806561,2.944807,0.239009,-141.938721,0.024855,0.000000
23.250002,13.112358,-141.983200,-0.004083,0.000959,0.024369,58.326683,2.971303,0.243690,-141.983200,0.025453,0.000000
23.610001,13.181244,-141.983200,-0.004057,0.000975,0.024777,58.633102,2.986912,0.247767,-141.983200,0.026051,0.000000
23.970001,13.512283,-142.027679,-0.004031,0.000997,0.025332,60.105637,3.061927,0.253315,-142.027679,0.026659,0.000000
24.330002,14.103981,-142.072159,-0.004010,0.001027,0.026078,62.737640,3.196008,0.260775,-142.072159,0.027257,0.000000
24.690001,14.536682,-142.072159,-0.003984,0.001059,0.026910,64.662392,3.294059,0.269098,-142.072159,0.027855,0.000000
25.050001,14.579132,-142.116638,-0.003971,0.001078,0.027378,64.851219,3.303679,0.273784,-142.116638,0.028454,0.000000
25.410002,15.144394,-142.161118,-0.003954,0.001110,0.028193,67.365631,3.431769,0.281933,-142.161118,0.029052,0.000000
25.770000,15.046829,-142.205597,-0.003932,0.001128,0.028653,66.931641,3.409660,0.286532,-142.205597,0.029659,0.000000
26.130001,15.342491,-142.161118,-0.003898,0.001152,0.029260,68.246811,3.476658,0.292603,-142.161118,0.030258,0.000000
26.490002,15.467239,-142.250076,-0.003885,0.001175,0.029833,68.801720,3.504926,0.298325,-142.250076,0.030856,0.000000
26.850000,14.976822,-142.250076,-0.003867,0.001178,0.029928,66.620232,3.393796,0.299279,-142.250076,0.031454,0.000000
27.210001,16.237679,-142.250076,-0.003846,0.001218,0.030943,72.228798,3.679510,0.309427,-142.250076,0.032053,0.000000
27.570002,16.568344,-142.294556,-0.003820,0.001248,0.031697,73.699677,3.754441,0.316970,-142.294556,0.032660,0.000000
27.930002,16.575790,-142.339050,-0.003798,0.001271,0.032278,73.732796,3.756128,0.322780,-142.339050,0.033258,0.000000
28.290001,16.541161,-142.339050,-0.003777,0.001290,0.032755,73.578758,3.748281,0.327552,-142.339050,0.033856,0.000000
28.650002,16.825279,-142.428009,-0.003768,0.001314,0.033388,74.842583,3.812663,0.333881,-142.428009,0.034455,0.000000
29.010002,17.384956,-142.383530,-0.003751,0.001341,0.034073,77.332146,3.939487,0.340731,-142.383530,0.035053,0.000000
29.370001,17.263939,-142.516968,-0.003725,0.001361,0.034576,76.793839,3.912064,0.345762,-142.516968,0.035660,0.000000
29.730001,17.522362,-142.428009,-0.003699,0.001386,0.035209,77.943359,3.970624,0.352094,-142.428009,0.036259,0.000000
30.090002,17.712646,-142.561447,-0.003673,0.001410,0.035816,78.789787,4.013743,0.358165,-142.561447,0.036857,0.000000
30.450001,18.032883,-142.605927,-0.003669,0.001434,0.036424,80.214272,4.086309,0.364236,-142.605927,0.037455,0.000000
30.810001,18.212372,-142.605927,-0.003643,0.001459,0.037056,81.012672,4.126983,0.370564,-142.605927,0.038054,0.000000
31.170002,18.535217,-142.650406,-0.003639,0.001486,0.037733,82.448761,4.200140,0.377328,-142.650406,0.038652,0.000000
31.530001,18.630913,-142.605927,-0.003604,0.001511,0.038375,82.874435,4.221826,0.383747,-142.605927,0.039259,0.000000
31.890001,18.556068,-142.650406,-0.003583,0.001532,0.038904,82.541512,4.204865,0.389038,-142.650406,0.039858,0.000000
32.250000,18.638733,-142.694885,-0.003583,0.001555,0.039485,82.909225,4.223598,0.394848,-142.694885,0.040456,0.000000
32.610001,18.570587,-142.694885,-0.003540,0.001576,0.040031,82.606094,4.208155,0.400309,-142.694885,0.041054,0.000000
32.970001,18.247368,-142.739365,-0.003540,0.001588,0.040343,81.168343,4.134913,0.403432,-142.739365,0.041653,0.000000
33.330002,19.553658,-142.828339,-0.003518,0.001626,0.041306,86.979012,4.430922,0.413061,-142.828339,0.042260,0.000000
33.690002,19.430023,-142.783859,-0.003492,0.001647,0.041826,86.429062,4.402906,0.418261,-142.783859,0.042858,0.000000
34.050003,19.433006,-142.828339,-0.003484,0.001671,0.042451,86.442329,4.403583,0.424506,-142.828339,0.043457,0.000000
34.410000,19.798302,-142.828339,-0.003475,0.001696,0.043084,88.067245,4.486360,0.430838,-142.828339,0.044055,0.000000
34.770000,19.264694,-142.961777,-0.003454,0.001709,0.043396,85.693642,4.365442,0.433961,-142.961777,0.044653,0.000000
35.130001,20.391495,-142.917297,-0.003428,0.001748,0.044393,90.705902,4.620779,0.443934,-142.917297,0.045261,0.000000
35.490002,20.424263,-142.961777,-0.003402,0.001771,0.044983,90.851662,4.628204,0.449831,-142.961777,0.045859,0.000000
35.850002,20.340103,-142.872818,-0.003389,0.001793,0.045547,90.477295,4.609133,0.455467,-142.872818,0.046457,0.000000
36.210003,20.435059,-143.006256,-0.003363,0.001817,0.046154,90.899681,4.630651,0.461538,-143.006256,0.047056,0.000000
36.570004,20.259674,-143.050735,-0.003359,0.001834,0.046596,90.119530,4.590908,0.465958,-143.050735,0.047654,0.000000
36.930000,20.506180,-143.095215,-0.003341,0.001859,0.047212,91.216042,4.646767,0.472116,-143.095215,0.048261,0.000000
37.290001,21.097511,-143.139694,-0.003320,0.001886,0.047897,93.846420,4.780765,0.478967,-143.139694,0.048860,0.000000
37.650002,21.258751,-143.139694,-0.003311,0.001911,0.048539,94.563644,4.817302,0.485386,-143.139694,0.049458,0.000000
38.010002,21.190979,-143.139694,-0.003285,0.001933,0.049093,94.262184,4.801944,0.490935,-143.139694,0.050056,0.000000
38.370003,21.528343,-143.228668,-0.003268,0.001958,0.049744,95.762856,4.878393,0.497441,-143.228668,0.050655,0.000000
38.730003,21.323540,-143.228668,-0.003251,0.001977,0.050212,94.851845,4.831983,0.502123,-143.228668,0.051253,0.000000
39.090000,22.094727,-143.228668,-0.003238,0.002006,0.050941,98.282249,5.006737,0.509409,-143.228668,0.051860,0.000000
39.450001,22.095093,-143.273148,-0.003238,0.002029,0.051531,98.283882,5.006819,0.515306,-143.273148,0.052458,0.000000
39.810001,22.150208,-143.317627,-0.003186,0.002053,0.052138,98.529045,5.019309,0.521377,-143.317627,0.053057,0.000000
40.170002,22.247398,-143.362106,-0.003186,0.002075,0.052710,98.961372,5.041333,0.527100,-143.362106,0.053655,0.000000
40.530003,22.324852,-143.362106,-0.003173,0.002097,0.053265,99.305901,5.058884,0.532648,-143.362106,0.054253,0.000000
40.890003,22.728500,-143.406586,-0.003165,0.002123,0.053924,101.101418,5.150352,0.539242,-143.406586,0.054861,0.000000
41.250004,23.060287,-143.406586,-0.003139,0.002148,0.054566,102.577278,5.225536,0.545657,-143.406586,0.055459,0.000000
41.610001,23.104599,-143.451065,-0.003113,0.002172,0.055164,102.774391,5.235577,0.551641,-143.451065,0.056057,0.000000
41.970001,23.001450,-143.495544,-0.003100,0.002191,0.055650,102.315559,5.212203,0.556497,-143.495544,0.056656,0.000000
42.330002,23.332863,-143.495544,-0.003074,0.002218,0.056335,103.789757,5.287302,0.563348,-143.495544,0.057254,0.000000
42.690002,23.188751,-143.540024,-0.003057,0.002235,0.056760,103.148720,5.254646,0.567598,-143.540024,0.057861,0.000000
43.050003,23.992706,-143.540024,-0.003048,0.002264,0.057515,106.724884,5.436825,0.575145,-143.540024,0.058460,0.000000
43.410004,24.285393,-143.584503,-0.003014,0.002290,0.058173,108.026825,5.503149,0.581735,-143.584503,0.059058,0.000000
43.770000,24.033669,-143.628998,-0.003022,0.002311,0.058703,106.907097,5.446107,0.587026,-143.628998,0.059656,0.000000
44.130001,24.268631,-143.584503,-0.002988,0.002334,0.059275,107.952263,5.499351,0.592749,-143.584503,0.060255,0.000000
44.490002,24.372528,-143.717957,-0.002971,0.002355,0.059813,108.414421,5.522894,0.598127,-143.717957,0.060862,0.000000
44.850002,24.533760,-143.673477,-0.002966,0.002373,0.060281,109.131615,5.559430,0.602809,-143.673477,0.061460,0.000000
45.210003,25.104240,-143.717957,-0.002953,0.002398,0.060897,111.669235,5.688702,0.608967,-143.717957,0.062059,0.000000
45.570004,25.021202,-143.717957,-0.002936,0.002416,0.061374,111.299866,5.669886,0.613736,-143.717957,0.062657,0.000000
45.930000,25.241272,-143.762436,-0.002928,0.002437,0.061894,112.278786,5.719754,0.618940,-143.762436,0.063255,0.000000
46.290001,26.232903,-143.851395,-0.002893,0.002472,0.062796,116.689781,5.944461,0.627959,-143.851395,0.063854,0.000000
46.650002,26.389671,-143.762436,-0.002884,0.002494,0.063351,117.387123,5.979985,0.633508,-143.762436,0.064461,0.000000
47.010002,26.842102,-143.895874,-0.002867,0.002523,0.064079,119.399635,6.082507,0.640794,-143.895874,0.065059,0.000000
47.370003,27.084145,-143.940353,-0.002841,0.002547,0.064686,120.476295,6.137355,0.646865,-143.940353,0.065658,0.000000
47.730003,26.937798,-143.940353,-0.002815,0.002564,0.065137,119.825310,6.104192,0.651373,-143.940353,0.066256,0.000000
48.090004,26.771347,-143.940353,-0.002811,0.002581,0.065545,119.084900,6.066474,0.655449,-143.940353,0.066854,0.000000
48.450001,28.101837,-143.984833,-0.002785,0.002616,0.066438,125.003212,6.367968,0.664382,-143.984833,0.067462,0.000000
48.810001,28.852539,-144.073807,-0.002772,0.002643,0.067132,128.342499,6.538079,0.671319,-144.073807,0.068060,0.000000
49.170002,28.555389,-144.073807,-0.002751,0.002660,0.067574,127.020714,6.470744,0.675740,-144.073807,0.068658,0.000000
49.530003,29.008934,-144.118286,-0.002746,0.002686,0.068225,129.038177,6.573518,0.682246,-144.118286,0.069257,0.000000
49.890003,29.369019,-144.162766,-0.002733,0.002709,0.068814,130.639923,6.655115,0.688143,-144.162766,0.069855,0.000000
50.250004,29.643089,-144.118286,-0.002703,0.002732,0.069387,131.859039,6.717220,0.693866,-144.118286,0.070462,0.000000
50.610001,30.040779,-144.207245,-0.002690,0.002754,0.069959,133.628052,6.807338,0.699589,-144.207245,0.071060,0.000000
50.970001,30.682747,-144.207245,-0.002677,0.002781,0.070636,136.483673,6.952810,0.706356,-144.207245,0.071659,0.000000
51.330002,30.002052,-144.251724,-0.002656,0.002791,0.070887,133.455795,6.798562,0.708869,-144.251724,0.072257,0.000000
51.690002,31.546280,-144.251724,-0.002647,0.002830,0.071876,140.324860,7.148489,0.718755,-144.251724,0.072855,0.000000
52.050003,31.789810,-144.207245,-0.002617,0.002848,0.072327,141.408142,7.203674,0.723267,-144.207245,0.073463,0.000000
52.410004,32.093300,-144.340683,-0.002600,0.002871,0.072925,142.758133,7.272446,0.729251,-144.340683,0.074061,0.000000
52.770004,33.371277,-144.340683,-0.002587,0.002903,0.073749,148.442856,7.562039,0.737487,-144.340683,0.074659,0.000000
53.130001,33.658752,-144.385162,-0.002570,0.002926,0.074330,149.721603,7.627182,0.743300,-144.385162,0.075258,0.000000
53.490002,33.715721,-144.385162,-0.002561,0.002947,0.074841,149.975021,7.640091,0.748414,-144.385162,0.075856,0.000000
53.850002,34.222153,-144.385162,-0.002531,0.002967,0.075353,152.227737,7.754851,0.753531,-144.385162,0.076454,0.000000
54.210003,34.088097,-144.518616,-0.002522,0.002981,0.075726,151.631424,7.724473,0.757263,-144.518616,0.077062,0.000000
54.570004,35.072273,-144.474136,-0.002505,0.003008,0.076411,156.009262,7.947491,0.764114,-144.474136,0.077660,0.000000
54.930004,36.432556,-144.518616,-0.002488,0.003043,0.077305,162.060104,8.255734,0.773046,-144.518616,0.078258,0.000000
55.290001,37.079735,-144.607574,-0.002462,0.003065,0.077859,164.938904,8.402389,0.778595,-144.607574,0.078857,0.000000
55.650002,37.637924,-144.563095,-0.002466,0.003087,0.078406,167.421844,8.528875,0.784060,-144.563095,0.079455,0.000000
56.010002,37.993164,-144.652054,-0.002440,0.003107,0.078909,169.002029,8.609374,0.789090,-144.652054,0.080062,0.000000
56.370003,38.468315,-144.652054,-0.002423,0.003130,0.079507,171.115616,8.717044,0.795070,-144.652054,0.080661,0.000000
56.730003,40.177132,-144.652054,-0.002410,0.003162,0.080322,178.716812,9.104269,0.803223,-144.652054,0.081259,0.000000
57.090004,40.763992,-144.696533,-0.002393,0.003186,0.080929,181.327301,9.237253,0.809294,-144.696533,0.081857,0.000000
57.450005,41.289780,-144.696533,-0.002358,0.003210,0.081545,183.666107,9.356398,0.815452,-144.696533,0.082456,0.000000
57.810001,41.858017,-144.741013,-0.002363,0.003230,0.082048,186.193756,9.485163,0.820482,-144.741013,0.083063,0.000000
58.170002,42.318275,-144.741013,-0.002345,0.003250,0.082560,188.241089,9.589458,0.825599,-144.741013,0.083661,0.000000
58.530003,43.626045,-144.785492,-0.002315,0.003279,0.083280,194.058334,9.885803,0.832798,-144.785492,0.084260,0.000000
58.890003,44.534630,-144.874451,-0.002311,0.003304,0.083930,198.099930,10.091691,0.839300,-144.874451,0.084858,0.000000
59.250004,45.362793,-144.829971,-0.002294,0.003327,0.084502,201.783783,10.279356,0.845023,-144.829971,0.085456,0.000000
59.610004,46.153336,-144.963425,-0.002272,0.003351,0.085118,205.300293,10.458495,0.851181,-144.963425,0.086064,0.000000
59.970001,46.992661,-144.963425,-0.002255,0.003372,0.085647,209.033798,10.648689,0.856473,-144.963425,0.086662,0.000000
60.330002,47.171402,-144.963425,-0.002238,0.003391,0.086133,209.828873,10.689193,0.861329,-144.963425,0.087260,0.000000
60.690002,48.965492,-145.007904,-0.002233,0.003421,0.086887,217.809387,11.095739,0.868872,-145.007904,0.087859,0.000000
61.050003,50.068459,-144.963425,-0.002216,0.003446,0.087538,222.715622,11.345675,0.875378,-144.963425,0.088457,0.000000
61.410004,50.977051,-145.096863,-0.002207,0.003469,0.088101,226.757248,11.551564,0.881014,-145.096863,0.089055,0.000000
61.770004,51.547897,-145.096863,-0.002182,0.003488,0.088587,229.296494,11.680921,0.885870,-145.096863,0.089662,0.000000
62.130001,52.680283,-145.096863,-0.002160,0.003512,0.089194,234.333603,11.937522,0.891941,-145.096863,0.090261,0.000000
62.490002,54.091202,-145.141342,-0.002151,0.003539,0.089897,240.609680,12.257241,0.898966,-145.141342,0.090859,0.000000
62.850002,55.287262,-145.096863,-0.002139,0.003564,0.090530,245.930023,12.528273,0.905298,-145.096863,0.091457,0.000000
63.210003,56.414803,-145.230301,-0.002130,0.003589,0.091171,250.945572,12.783777,0.911713,-145.230301,0.092056,0.000000
63.570004,57.410904,-145.185822,-0.002113,0.003609,0.091674,255.376450,13.009497,0.916743,-145.185822,0.092663,0.000000
63.930004,58.247620,-145.274780,-0.002095,0.003631,0.092221,259.098358,13.199100,0.922209,-145.274780,0.093261,0.000000
64.290001,58.739899,-145.274780,-0.002091,0.003646,0.092602,261.288116,13.310651,0.926024,-145.274780,0.093860,0.000000
64.650002,61.085846,-145.319260,-0.002070,0.003682,0.093530,271.723419,13.842250,0.935304,-145.319260,0.094458,0.000000
65.010002,62.201103,-145.363754,-0.002065,0.003703,0.094059,276.684326,14.094972,0.940592,-145.363754,0.095056,0.000000
65.370003,63.616859,-145.319260,-0.002057,0.003728,0.094701,282.981934,14.415787,0.947011,-145.319260,0.095664,0.000000
65.730003,64.225319,-145.452713,-0.002026,0.003746,0.095161,285.688477,14.553665,0.951606,-145.452713,0.096262,0.000000
66.090004,64.764519,-145.408234,-0.002013,0.003761,0.095525,288.086975,14.675850,0.955247,-145.408234,0.096860,0.000000
66.450005,66.293480,-145.452713,-0.002005,0.003779,0.095985,294.888123,15.022318,0.959846,-145.452713,0.096210,0.000000
66.810005,65.104118,-145.497192,-0.001996,0.003779,0.095993,289.597595,14.752804,0.959933,-145.497192,294.500488,0.000000
67.170006,65.331642,-145.541672,-0.001992,0.003795,0.096383,290.609650,14.804361,0.963835,-145.541672,294.500488,0.000000
67.530006,64.511299,-145.586151,-0.001970,0.003795,0.096383,286.960602,14.618469,0.963835,-145.586151,294.500488,0.000000
67.890007,66.934700,-145.541672,-0.001957,0.003695,0.093842,297.740417,15.167620,0.938423,-145.541672,294.500488,0.000000
68.250000,65.867104,-145.630630,-0.001953,0.003689,0.093704,292.991516,14.925699,0.937038,-145.630630,294.500488,0.000000
68.610001,65.238548,-145.630630,-0.001940,0.003794,0.096375,290.195557,14.783267,0.963748,-145.630630,294.500488,0.000000
68.970001,65.169273,-145.675110,-0.001944,0.003823,0.097112,289.887421,14.767569,0.971117,-145.675110,294.500488,0.000000
69.330002,65.728218,-145.764084,-0.001936,0.003836,0.097424,292.373718,14.894227,0.974240,-145.764084,294.500488,0.000000
69.690002,65.224022,-145.719589,-0.001940,0.003836,0.097433,290.130951,14.779975,0.974327,-145.719589,294.500488,0.000000
70.050003,64.690407,-145.675110,-0.001944,0.003836,0.097433,287.757294,14.659056,0.974327,-145.675110,294.500488,0.000000
70.410004,64.210045,-145.853043,-0.001923,0.003836,0.097441,285.620544,14.550204,0.974414,-145.853043,294.500488,0.000000
70.770004,65.381157,-145.764084,-0.001897,0.003693,0.093790,290.829926,14.815581,0.937905,-145.764084,294.500488,0.000000
71.130005,65.019218,-145.808563,-0.001884,0.003824,0.097129,289.219940,14.733565,0.971291,-145.808563,294.500488,0.000000
71.490005,65.378548,-145.853043,-0.001884,0.003852,0.097832,290.818298,14.814991,0.978316,-145.853043,294.500488,0.000000
71.850006,65.696938,-145.897522,-0.001876,0.003861,0.098075,292.234589,14.887139,0.980746,-145.897522,294.500488,0.000000
72.210007,65.279503,-145.986481,-0.001897,0.003861,0.098075,290.377716,14.792547,0.980746,-145.986481,294.500488,0.000000
72.570000,64.931709,-145.942001,-0.001897,0.003861,0.098075,288.830658,14.713736,0.980746,-145.942001,294.500488,0.000000
72.930000,64.552254,-146.030960,-0.001880,0.003861,0.098075,287.142761,14.627750,0.980746,-146.030960,294.500488,0.000000
73.290001,64.255486,-146.030960,-0.001901,0.003862,0.098083,285.822662,14.560501,0.980833,-146.030960,294.500488,0.000000
73.650002,63.940086,-146.030960,-0.001888,0.003862,0.098083,284.419708,14.489031,0.980833,-146.030960,294.500488,0.000000
74.010002,66.029839,-146.164398,-0.001858,0.003875,0.098421,293.715393,14.962575,0.984213,-146.164398,294.500488,0.000000
74.370003,65.653740,-146.119919,-0.001863,0.003869,0.098283,292.042419,14.877350,0.982827,-146.119919,294.500488,0.000000
74.730003,65.327171,-146.208893,-0.001854,0.003869,0.098283,290.589783,14.803349,0.982827,-146.208893,294.500488,0.000000
75.090004,65.033730,-146.164398,-0.001863,0.003869,0.098283,289.284485,14.736854,0.982827,-146.164398,294.500488,0.000000
75.450005,65.772896,-146.119919,-0.001867,0.003890,0.098811,292.572449,14.904351,0.988115,-146.119919,294.500488,0.000000
75.810005,65.515587,-146.253372,-0.001854,0.003890,0.098811,291.427887,14.846044,0.988115,-146.253372,294.500488,0.000000
76.170006,65.283226,-146.164398,-0.001863,0.003890,0.098811,290.394287,14.793390,0.988115,-146.164398,294.500488,0.000000
76.530006,65.115654,-146.342331,-0.001867,0.003897,0.098994,289.648895,14.755418,0.989939,-146.342331,294.500488,0.000000
76.890007,65.661934,-146.253372,-0.001863,0.003901,0.099098,292.078857,14.879207,0.990980,-146.253372,294.500488,0.000000
77.250000,65.519676,-146.297852,-0.001850,0.003901,0.099098,291.446075,14.846972,0.990980,-146.297852,294.500488,0.000000
77.610001,65.313759,-146.431290,-0.001871,0.003901,0.099098,290.530121,14.800309,0.990980,-146.431290,294.500488,0.000000
77.970001,65.155128,-146.386810,-0.001845,0.003902,0.099106,289.824493,14.764363,0.991063,-146.386810,294.500488,0.000000
78.330002,64.987190,-146.475769,-0.001858,0.003902,0.099106,289.077454,14.726308,0.991063,-146.475769,294.500488,0.000000
78.690002,66.282295,-146.475769,-0.001863,0.003913,0.099401,294.838379,15.019783,0.994012,-146.475769,294.500488,0.000000
79.050003,66.046593,-146.475769,-0.001841,0.003912,0.099375,293.789917,14.966372,0.993754,-146.475769,294.500488,0.000000
79.410004,65.838066,-146.475769,-0.001845,0.003912,0.099367,292.862335,14.919119,0.993667,-146.475769,294.500488,0.000000
79.770004,65.617989,-146.520248,-0.001841,0.003912,0.099375,291.883392,14.869248,0.993754,-146.520248,294.500488,0.000000
80.130005,65.473137,-146.609207,-0.001854,0.003912,0.099375,291.239044,14.836425,0.993754,-146.609207,294.500488,0.000000
80.490005,65.280998,-146.564728,-0.001850,0.003912,0.099375,290.384369,14.792886,0.993754,-146.564728,294.500488,0.000000
80.850006,65.113426,-146.609207,-0.001854,0.003912,0.099375,289.638977,14.754913,0.993754,-146.609207,294.500488,0.000000
81.210007,64.969322,-146.609207,-0.001850,0.003912,0.099375,288.997986,14.722259,0.993754,-146.609207,294.500488,0.000000
81.570007,64.777916,-146.698181,-0.001845,0.003912,0.099375,288.146576,14.678886,0.993754,-146.698181,294.500488,0.000000
81.930000,64.644615,-146.742661,-0.001845,0.003913,0.099384,287.553619,14.648679,0.993842,-146.742661,294.500488,0.000000
82.290001,66.600304,-146.787140,-0.001854,0.003903,0.099132,296.252960,15.091845,0.991325,-146.787140,294.500488,0.000000
82.650002,66.319542,-146.742661,-0.001824,0.003903,0.099124,295.004059,15.028223,0.991238,-146.742661,294.500488,0.000000
83.010002,66.151222,-146.831619,-0.001854,0.003903,0.099124,294.255341,14.990082,0.991238,-146.831619,294.500488,0.000000
83.370003,65.992226,-146.787140,-0.001850,0.003903,0.099124,293.548096,14.954052,0.991238,-146.787140,294.500488,0.000000
83.730003,65.835075,-146.876099,-0.001832,0.003903,0.099124,292.849030,14.918441,0.991238,-146.876099,294.500488,0.000000
84.090004,65.687248,-146.876099,-0.001837,0.003903,0.099132,292.191467,14.884943,0.991325,-146.876099,294.500488,0.000000
84.450005,65.569588,-146.876099,-0.001828,0.003903,0.099132,291.668091,14.858281,0.991325,-146.876099,294.500488,0.000000
84.810005,65.457863,-146.965057,-0.001841,0.003903,0.099141,291.171112,14.832964,0.991412,-146.965057,294.500488,0.000000
85.170006,65.328285,-146.920578,-0.001837,0.003904,0.099150,290.594727,14.803600,0.991499,-146.920578,294.500488,0.000000
85.530006,65.199440,-146.965057,-0.001837,0.003904,0.099150,290.021606,14.774405,0.991499,-146.965057,294.500488,0.000000
85.890007,65.355461,-146.965057,-0.001828,0.003932,0.099878,290.715607,14.809759,0.998785,-146.965057,294.500488,0.000000
86.250008,65.277641,-147.009537,-0.001824,0.003932,0.099878,290.369446,14.792125,0.998785,-147.009537,294.500488,0.000000
86.610001,65.229973,-147.098511,-0.001828,0.003936,0.099974,290.157410,14.781323,0.999738,-147.098511,294.500488,0.000000
86.970001,65.303703,-147.009537,-0.001837,0.003937,0.099991,290.485382,14.798031,0.999913,-147.009537,294.500488,0.000000
87.330002,65.244133,-147.098511,-0.001824,0.003937,0.100000,290.220398,14.784533,0.999996,-147.098511,294.500488,0.000000
87.690002,65.229973,-147.098511,-0.001832,0.003938,0.100034,290.157410,14.781323,1.000344,-147.098511,294.500488,0.000000
88.050003,65.321205,-147.187469,-0.001819,0.003941,0.100104,290.563232,14.801996,1.001037,-147.187469,294.500488,0.000000
88.410004,65.288811,-147.231949,-0.001819,0.003941,0.100104,290.419128,14.794656,1.001037,-147.231949,294.500488,0.000000
88.770004,65.267220,-147.231949,-0.001828,0.003942,0.100138,290.323090,14.789763,1.001385,-147.231949,294.500488,0.000000
89.130005,65.285088,-147.231949,-0.001837,0.003943,0.100156,290.402588,14.793813,1.001559,-147.231949,294.500488,0.000000
89.490005,65.281731,-147.276428,-0.001811,0.003945,0.100199,290.387634,14.793052,1.001990,-147.276428,294.500488,0.000000
89.850006,65.283226,-147.365387,-0.001828,0.003945,0.100208,290.394287,14.793390,1.002077,-147.365387,294.500488,0.000000
90.210007,65.253059,-147.320908,-0.001828,0.003946,0.100216,290.260101,14.786554,1.002164,-147.320908,294.500488,0.000000
90.570007,65.216194,-147.320908,-0.001815,0.003946,0.100234,290.096130,14.778201,1.002339,-147.320908,294.500488,0.000000
90.930008,65.210243,-147.409866,-0.001824,0.003947,0.100251,290.069641,14.776852,1.002513,-147.409866,294.500488,0.000000
91.290001,65.243004,-147.454346,-0.001832,0.003949,0.100294,290.215363,14.784276,1.002944,-147.454346,294.500488,0.000000
91.650002,65.216194,-147.409866,-0.001824,0.003949,0.100294,290.096130,14.778201,1.002944,-147.409866,294.500488,0.000000
92.010002,65.211357,-147.498840,-0.001819,0.003950,0.100321,290.074615,14.777104,1.003205,-147.498840,294.500488,0.000000
92.370003,65.162575,-147.498840,-0.001819,0.003950,0.100321,289.857605,14.766050,1.003205,-147.498840,294.500488,0.000000
92.730003,65.217323,-147.587799,-0.001815,0.003952,0.100381,290.101135,14.778457,1.003815,-147.587799,294.500488,0.000000
93.090004,65.192741,-147.543320,-0.001824,0.003952,0.100381,289.991791,14.772886,1.003815,-147.543320,294.500488,0.000000
93.450005,65.173378,-147.587799,-0.001832,0.003953,0.100416,289.905670,14.768499,1.004159,-147.587799,294.500488,0.000000
93.810005,65.193855,-147.676758,-0.001815,0.003953,0.100416,289.996765,14.773139,1.004159,-147.676758,294.500488,0.000000
94.170006,65.151772,-147.632278,-0.001828,0.003954,0.100425,289.809540,14.763602,1.004246,-147.632278,294.500488,0.000000
94.530006,65.094063,-147.721237,-0.001811,0.003954,0.100425,289.552856,14.750525,1.004246,-147.721237,294.500488,0.000000
94.890007,65.267220,-147.721237,-0.001819,0.003957,0.100511,290.323090,14.789763,1.005113,-147.721237,294.500488,0.000000
95.250008,65.257912,-147.721237,-0.001824,0.003957,0.100511,290.281677,14.787654,1.005113,-147.721237,294.500488,0.000000
95.610008,65.240028,-147.854675,-0.001811,0.003957,0.100511,290.202148,14.783602,1.005113,-147.854675,294.500488,0.000000
95.970001,65.165184,-147.765717,-0.001815,0.003957,0.100511,289.869202,14.766642,1.005113,-147.765717,294.500488,0.000000
96.330002,65.165932,-147.810196,-0.001819,0.003958,0.100537,289.872528,14.766811,1.005374,-147.810196,294.500488,0.000000
96.690002,65.131294,-147.854675,-0.001815,0.003958,0.100537,289.718475,14.758963,1.005374,-147.854675,294.500488,0.000000
97.050003,65.259026,-147.854675,-0.001815,0.003961,0.100607,290.286652,14.787907,1.006067,-147.854675,294.500488,0.000000
97.410004,65.262749,-147.899155,-0.001837,0.003961,0.100607,290.303192,14.788750,1.006067,-147.899155,294.500488,0.000000
97.770004,65.219551,-147.899155,-0.001828,0.003961,0.100607,290.111053,14.778962,1.006067,-147.899155,294.500488,0.000000
98.130005,65.171135,-148.032608,-0.001794,0.003961,0.100607,289.895691,14.767991,1.006067,-148.032608,294.500488,0.000000
98.490005,65.124229,-147.988129,-0.001828,0.003962,0.100624,289.687042,14.757361,1.006241,-147.988129,294.500488,0.000000
98.850006,65.111931,-148.032608,-0.001815,0.003963,0.100650,289.632324,14.754575,1.006502,-148.032608,294.500488,0.000000
99.210007,65.118645,-148.077087,-0.001802,0.003963,0.100650,289.662201,14.756096,1.006502,-148.077087,294.500488,0.000000
99.570007,65.067253,-148.121567,-0.001807,0.003963,0.100650,289.433594,14.744451,1.006502,-148.121567,294.500488,0.000000
99.930008,65.088844,-148.121567,-0.001807,0.003965,0.100702,289.529633,14.749343,1.007020,-148.121567,294.500488,0.000000
100.290009,65.115654,-148.210526,-0.001819,0.003965,0.100702,289.648895,14.755418,1.007020,-148.210526,294.500488,0.000000
100.650002,65.141731,-148.210526,-0.001798,0.003965,0.100719,289.764893,14.761327,1.007195,-148.210526,294.500488,0.000000
101.010002,65.121620,-148.255005,-0.001807,0.003965,0.100719,289.675446,14.756769,1.007195,-148.255005,294.500488,0.000000
101.370003,65.376320,-148.210526,-0.001811,0.003970,0.100832,290.808380,14.814486,1.008322,-148.210526,294.500488,0.000000
101.730003,65.423241,-148.255005,-0.001802,0.003970,0.100832,291.017120,14.825118,1.008322,-148.255005,294.500488,0.000000
102.090004,65.389351,-148.343979,-0.001815,0.003970,0.100832,290.866364,14.817439,1.008322,-148.343979,294.500488,0.000000
102.450005,65.353233,-148.299484,-0.001811,0.003970,0.100832,290.705688,14.809255,1.008322,-148.299484,294.500488,0.000000
102.810005,65.326042,-148.388458,-0.001807,0.003970,0.100832,290.584747,14.803092,1.008322,-148.388458,294.500488,0.000000
103.170006,65.289192,-148.299484,-0.001802,0.003970,0.100832,290.420837,14.794743,1.008322,-148.299484,294.500488,0.000000
103.530006,65.274666,-148.432938,-0.001802,0.003970,0.100832,290.356201,14.791451,1.008322,-148.432938,294.500488,0.000000
103.890007,65.229225,-148.432938,-0.001815,0.003970,0.100832,290.154083,14.781154,1.008322,-148.432938,294.500488,0.000000
104.250008,65.194603,-148.432938,-0.001798,0.003970,0.100841,290.000092,14.773308,1.008410,-148.432938,294.500488,0.000000
104.610008,65.155128,-148.477417,-0.001802,0.003971,0.100876,289.824493,14.764363,1.008758,-148.477417,294.500488,0.000000
104.970001,65.261635,-148.521896,-0.001798,0.003974,0.100928,290.298248,14.788498,1.009276,-148.521896,294.500488,0.000000
105.330002,65.297371,-148.610855,-0.001807,0.003974,0.100928,290.457214,14.796596,1.009276,-148.610855,294.500488,0.000000
105.690002,65.282478,-148.610855,-0.001819,0.003974,0.100928,290.390961,14.793221,1.009276,-148.610855,294.500488,0.000000
106.050003,65.261635,-148.610855,-0.001807,0.003974,0.100928,290.298248,14.788498,1.009276,-148.610855,294.500488,0.000000
106.410004,65.229607,-148.744293,-0.001811,0.003974,0.100928,290.155792,14.781240,1.009276,-148.744293,294.500488,0.000000
106.770004,65.196098,-148.699814,-0.001807,0.003974,0.100936,290.006744,14.773647,1.009363,-148.699814,294.500488,0.000000
107.130005,65.147682,-148.655334,-0.001798,0.003974,0.100936,289.791351,14.762676,1.009363,-148.655334,294.500488,0.000000
107.490005,65.103004,-148.744293,-0.001794,0.003974,0.100936,289.592621,14.752552,1.009363,-148.744293,294.500488,0.000000
107.850006,65.155876,-148.744293,-0.001802,0.003976,0.100989,289.827820,14.764533,1.009886,-148.744293,294.500488,0.000000
108.210007,65.171883,-148.877747,-0.001798,0.003976,0.100989,289.899017,14.768160,1.009886,-148.877747,294.500488,0.000000
108.570007,65.138374,-148.744293,-0.001811,0.003976,0.100989,289.749969,14.760567,1.009886,-148.744293,294.500488,0.000000
108.930008,65.123482,-148.833267,-0.001802,0.003976,0.100989,289.683716,14.757192,1.009886,-148.833267,294.500488,0.000000
109.290009,65.089958,-148.922226,-0.001798,0.003976,0.100989,289.534607,14.749595,1.009886,-148.922226,294.500488,0.000000
109.650002,65.050117,-148.877747,-0.001807,0.003976,0.100989,289.357361,14.740567,1.009886,-148.877747,294.500488,0.000000
110.010002,65.033730,-148.966705,-0.001802,0.003977,0.101014,289.284485,14.736854,1.010143,-148.966705,294.500488,0.000000
110.370003,65.047142,-148.922226,-0.001794,0.003977,0.101023,289.344147,14.739893,1.010230,-148.922226,294.500488,0.000000
110.730003,65.044914,-149.011185,-0.001794,0.003977,0.101023,289.334229,14.739388,1.010230,-149.011185,294.500488,0.000000
111.090004,64.997612,-149.055664,-0.001798,0.003977,0.101023,289.123810,14.728669,1.010230,-149.055664,294.500488,0.000000
111.450005,64.988686,-149.011185,-0.001807,0.003977,0.101023,289.084106,14.726646,1.010230,-149.011185,294.500488,0.000000
111.810005,64.979744,-149.144623,-0.001789,0.003978,0.101049,289.044342,14.724620,1.010491,-149.144623,294.500488,0.000000
112.170006,64.985329,-149.100143,-0.001794,0.003978,0.101049,289.069183,14.725885,1.010491,-149.100143,294.500488,0.000000
112.530006,64.941383,-149.144623,-0.001798,0.003978,0.101049,288.873688,14.715928,1.010491,-149.144623,294.500488,0.000000
112.890007,64.954048,-149.144623,-0.001802,0.003979,0.101067,288.930023,14.718798,1.010665,-149.144623,294.500488,0.000000
113.250008,64.937660,-149.189117,-0.001794,0.003979,0.101067,288.857147,14.715084,1.010665,-149.189117,294.500488,0.000000
113.610008,64.897453,-149.278076,-0.001789,0.003979,0.101067,288.678284,14.705974,1.010665,-149.278076,294.500488,0.000000
113.970009,64.866920,-149.278076,-0.001789,0.003979,0.101067,288.542480,14.699055,1.010665,-149.278076,294.500488,0.000000
114.330002,64.828194,-149.278076,-0.001785,0.003979,0.101067,288.370209,14.690278,1.010665,-149.278076,294.500488,0.000000
114.690002,64.812172,-149.322556,-0.001802,0.003979,0.101067,288.298950,14.686648,1.010665,-149.322556,294.500488,0.000000
115.050003,64.775307,-149.322556,-0.001794,0.003979,0.101067,288.134949,14.678294,1.010665,-149.322556,294.500488,0.000000
115.410004,64.756325,-149.367035,-0.001798,0.003979,0.101067,288.050507,14.673992,1.010665,-149.367035,294.500488,0.000000
115.770004,64.721687,-149.367035,-0.001794,0.003979,0.101067,287.896454,14.666143,1.010665,-149.367035,294.500488,0.000000
116.130005,65.834343,-149.411514,-0.001798,0.003990,0.101344,292.845795,14.918276,1.013440,-149.411514,294.500488,0.000000
116.490005,65.807533,-149.544952,-0.001785,0.003990,0.101344,292.726532,14.912200,1.013440,-149.544952,294.500488,0.000000
116.850006,65.771400,-149.500473,-0.001789,0.003990,0.101344,292.565796,14.904013,1.013440,-149.500473,294.500488,0.000000
117.210007,65.769539,-149.544952,-0.001776,0.003990,0.101344,292.557526,14.903590,1.013440,-149.544952,294.500488,0.000000
117.570007,65.747200,-149.544952,-0.001785,0.003990,0.101344,292.458160,14.898528,1.013440,-149.544952,294.500488,0.000000
117.930008,65.728218,-149.544952,-0.001798,0.003990,0.101344,292.373718,14.894227,1.013440,-149.544952,294.500488,0.000000
118.290009,65.669746,-149.633926,-0.001807,0.003990,0.101344,292.113617,14.880977,1.013440,-149.633926,294.500488,0.000000
118.650009,65.647408,-149.678406,-0.001785,0.003990,0.101344,292.014252,14.875915,1.013440,-149.678406,294.500488,0.000000
119.010002,65.618355,-149.678406,-0.001781,0.003990,0.101344,291.885010,14.869332,1.013440,-149.678406,294.500488,0.000000
119.370003,65.582237,-149.678406,-0.001798,0.003990,0.101344,291.724365,14.861147,1.013440,-149.678406,294.500488,0.000000
119.730003,65.580009,-149.722885,-0.001785,0.003990,0.101344,291.714447,14.860642,1.013440,-149.722885,294.500488,0.000000
120.090004,65.547981,-149.722885,-0.001768,0.003990,0.101344,291.571991,14.853385,1.013440,-149.722885,294.500488,0.000000
120.450005,65.536446,-149.722885,-0.001807,0.003990,0.101344,291.520660,14.850771,1.013440,-149.722885,294.500488,0.000000
120.810005,65.489525,-149.811844,-0.001772,0.003990,0.101344,291.311951,14.840138,1.013440,-149.811844,294.500488,0.000000
121.170006,65.475746,-149.856323,-0.001785,0.003990,0.101344,291.250671,14.837016,1.013440,-149.856323,294.500488,0.000000
121.530006,65.424355,-149.856323,-0.001776,0.003990,0.101344,291.022064,14.825371,1.013440,-149.856323,294.500488,0.000000
121.890007,65.383018,-149.945282,-0.001798,0.003990,0.101344,290.838196,14.816004,1.013440,-149.945282,294.500488,0.000000
122.250008,65.370369,-149.856323,-0.001785,0.003990,0.101344,290.781921,14.813137,1.013440,-149.856323,294.500488,0.000000
122.610008,65.322319,-149.900803,-0.001789,0.003990,0.101344,290.568176,14.802249,1.013440,-149.900803,294.500488,0.000000
122.970009,65.313011,-149.989761,-0.001776,0.003990,0.101344,290.526794,14.800140,1.013440,-149.989761,294.500488,0.000000
123.330009,65.279137,-150.034241,-0.001794,0.003990,0.101344,290.376099,14.792464,1.013440,-150.034241,294.500488,0.000000
123.690002,65.249336,-150.123215,-0.001776,0.003990,0.101344,290.243530,14.785711,1.013440,-150.123215,294.500488,0.000000
124.050003,65.234444,-150.078735,-0.001785,0.003990,0.101344,290.177307,14.782336,1.013440,-150.078735,294.500488,0.000000
124.410004,65.205406,-150.123215,-0.001781,0.003990,0.101344,290.048126,14.775756,1.013440,-150.123215,294.500488,0.000000
124.770004,65.189384,-150.167694,-0.001789,0.003990,0.101344,289.976868,14.772126,1.013440,-150.167694,294.500488,0.000000
125.130005,65.140984,-150.123215,-0.001785,0.003990,0.101344,289.761566,14.761158,1.013440,-150.123215,294.500488,0.000000
125.490005,65.098900,-150.256653,-0.001768,0.003990,0.101344,289.574371,14.751621,1.013440,-150.256653,294.500488,0.000000
125.850006,65.074699,-150.212173,-0.001785,0.003990,0.101344,289.466705,14.746138,1.013440,-150.212173,294.500488,0.000000
126.210007,65.044533,-150.212173,-0.001781,0.003990,0.101344,289.332520,14.739302,1.013440,-150.212173,294.500488,0.000000
126.570007,65.025169,-150.256653,-0.001789,0.003990,0.101344,289.246399,14.734915,1.013440,-150.256653,294.500488,0.000000
126.930008,64.997993,-150.301132,-0.001781,0.003990,0.101344,289.125519,14.728755,1.013440,-150.301132,1681.640991,0.000000
127.290009,64.962990,-150.301132,-0.001785,0.003984,0.101205,288.969818,14.720823,1.012051,-150.301132,0.101110,0.000000
127.650009,64.809196,-150.256653,-0.001789,0.003968,0.100797,288.285706,14.685973,1.007974,-150.256653,0.100511,0.000000
128.010010,64.779778,-150.390091,-0.001781,0.003953,0.100416,288.154846,14.679307,1.004159,-150.390091,0.099913,0.000000
128.370010,64.728767,-150.390091,-0.001768,0.003931,0.099852,287.927948,14.667748,0.998523,-150.390091,0.099315,0.000000
128.730011,64.636040,-150.434570,-0.001776,0.003907,0.099245,287.515472,14.646736,0.992452,-150.434570,0.098716,0.000000
129.090012,64.656898,-150.479065,-0.001781,0.003880,0.098560,287.608246,14.651463,0.985602,-150.479065,0.098109,0.000000
129.450012,64.624123,-150.434570,-0.001776,0.003862,0.098101,287.462463,14.644036,0.981007,-150.434570,0.097511,0.000000
129.810013,64.534386,-150.523544,-0.001781,0.003835,0.097415,287.063293,14.623701,0.974153,-150.523544,0.096912,0.000000
130.170013,64.523964,-150.523544,-0.001781,0.003818,0.096982,287.016937,14.621340,0.969819,-150.523544,0.096314,0.000000
130.529999,64.461403,-150.568024,-0.001763,0.003790,0.096271,286.738647,14.607162,0.962707,-150.568024,0.095716,0.000000
130.889999,64.291222,-150.612503,-0.001781,0.003770,0.095750,285.981628,14.568599,0.957503,-150.612503,0.095109,0.000000
131.250000,63.708839,-150.612503,-0.001768,0.003749,0.095230,283.391083,14.436629,0.952299,-150.612503,0.094510,0.000000
131.610001,62.713860,-150.612503,-0.001772,0.003725,0.094623,278.965179,14.211164,0.946231,-150.612503,0.093912,0.000000
131.970001,61.521149,-150.701462,-0.001763,0.003703,0.094050,273.659729,13.940892,0.940505,-150.701462,0.093314,0.000000
132.330002,60.865028,-150.701462,-0.001768,0.003688,0.093686,270.741180,13.792212,0.936864,-150.701462,0.092715,0.000000
132.690002,58.674362,-150.745941,-0.001738,0.003655,0.092836,260.996613,13.295801,0.928363,-150.745941,0.092108,0.000000
133.050003,57.176682,-150.701462,-0.001746,0.003634,0.092308,254.334579,12.956422,0.923075,-150.701462,0.091510,0.000000
133.410004,56.239792,-150.790421,-0.001750,0.003620,0.091943,250.167084,12.744120,0.919430,-150.790421,0.090911,0.000000
133.770004,53.929588,-150.834900,-0.001746,0.003598,0.091397,239.890793,12.220619,0.913969,-150.834900,0.090313,0.000000
134.130005,51.941864,-150.834900,-0.001759,0.003577,0.090868,231.048950,11.770194,0.908678,-150.834900,0.089714,0.000000
134.490005,50.379761,-150.879379,-0.001750,0.003562,0.090486,224.100372,11.416217,0.904862,-150.879379,0.089107,0.000000
134.850006,46.639656,-150.834900,-0.001746,0.003525,0.089524,207.463547,10.568697,0.895237,-150.834900,0.088509,0.000000
135.210007,44.469093,-150.923874,-0.001755,0.003505,0.089029,197.808411,10.076840,0.890294,-150.923874,0.087911,0.000000
135.570007,41.734764,-150.923874,-0.001750,0.003478,0.088353,185.645508,9.457232,0.883531,-150.923874,0.087312,0.000000
135.930008,39.329239,-151.012833,-0.001742,0.003459,0.087850,174.945190,8.912133,0.878501,-151.012833,0.086714,0.000000
136.290009,37.050690,-151.012833,-0.001750,0.003434,0.087234,164.809692,8.395806,0.872343,-151.012833,0.086115,0.000000
136.650009,33.530281,-150.968353,-0.001755,0.003403,0.086428,149.150146,7.598070,0.864277,-150.968353,0.085508,0.000000
137.010010,31.468826,-151.101791,-0.001755,0.003385,0.085968,139.980331,7.130938,0.859682,-151.101791,0.084910,0.000000
137.370010,28.460434,-151.101791,-0.001755,0.003358,0.085283,126.598335,6.449226,0.852828,-151.101791,0.084312,0.000000
137.730011,27.004082,-151.101791,-0.001750,0.003337,0.084763,120.120155,6.119212,0.847627,-151.101791,0.083713,0.000000
138.090012,23.903336,-151.190750,-0.001755,0.003316,0.084225,106.327347,5.416574,0.842249,-151.190750,0.083115,0.000000
138.450012,20.301750,-151.146271,-0.001763,0.003280,0.083323,90.306694,4.600442,0.833229,-151.146271,0.082508,0.000000
138.810013,18.175873,-151.235229,-0.001755,0.003261,0.082829,80.850319,4.118712,0.828286,-151.235229,0.081909,0.000000
139.170013,16.317734,-151.279709,-0.001746,0.003244,0.082395,72.584908,3.697651,0.823949,-151.279709,0.081311,0.000000
139.530014,13.445999,-151.146271,-0.001750,0.003217,0.081701,59.810791,3.046907,0.817011,-151.146271,0.080713,0.000000
139.889999,11.482857,-151.279709,-0.001759,0.003200,0.081285,51.078297,2.602053,0.812852,-151.279709,0.080114,0.000000
140.250000,8.881828,-151.235229,-0.001750,0.003175,0.080635,39.508347,2.012651,0.806345,-151.235229,0.079507,0.000000
140.610001,6.049942,-151.279709,-0.001738,0.003148,0.079949,26.911486,1.370936,0.799495,-151.279709,0.078909,0.000000
140.970001,4.136688,-151.368683,-0.001746,0.003130,0.079499,18.400908,0.937387,0.794987,-151.368683,0.078311,0.000000
141.330002,1.447784,-151.368683,-0.001746,0.003099,0.078710,6.440067,0.328073,0.787095,-151.368683,0.077712,0.000000
141.690002,-0.907471,-151.413162,-0.001750,0.003079,0.078215,-4.036631,-0.205636,0.782149,-151.413162,0.077114,0.000000
142.050003,-2.860561,-151.413162,-0.001742,0.003056,0.077634,-12.724413,-0.648212,0.776339,-151.413162,0.076507,0.000000
142.410004,-0.451683,-151.457642,-0.001763,0.003030,0.076958,-2.009187,-0.102353,0.769575,-151.457642,0.075908,0.000000
142.770004,-0.119156,-151.457642,-0.001768,0.003004,0.076290,-0.530032,-0.027001,0.762899,-151.457642,0.075310,0.000000
143.130005,-0.064415,-151.546600,-0.001742,0.002983,0.075761,-0.286532,-0.014597,0.757607,-151.546600,0.074712,0.000000
143.490005,-0.067398,-151.591080,-0.001768,0.002957,0.075119,-0.299802,-0.015273,0.751192,-151.591080,0.074113,0.000000
143.850006,-0.062927,-151.591080,-0.001759,0.002943,0.074746,-0.279914,-0.014260,0.747460,-151.591080,0.073515,0.000000
144.210007,-0.107986,-151.591080,-0.001763,0.002914,0.074009,-0.480348,-0.024470,0.740091,-151.591080,0.072908,0.000000
144.570007,-0.135910,-151.680038,-0.001798,0.002887,0.073324,-0.604558,-0.030798,0.733240,-151.680038,0.072309,0.000000
144.930008,-0.097183,-151.591080,-0.001815,0.002860,0.072647,-0.432293,-0.022022,0.726473,-151.591080,0.071711,0.000000
145.290009,-0.118408,-151.724518,-0.001824,0.002842,0.072179,-0.526706,-0.026832,0.721791,-151.724518,0.071112,0.000000
145.650009,-0.111336,-151.724518,-0.001858,0.002813,0.071450,-0.495246,-0.025229,0.714505,-151.724518,0.070514,0.000000
146.010010,-0.113571,-151.769012,-0.001884,0.002802,0.071164,-0.505190,-0.025736,0.711644,-151.769012,0.069907,0.000000
146.370010,-0.122131,-151.769012,-0.001897,0.002768,0.070297,-0.543267,-0.027675,0.702972,-151.769012,0.069309,0.000000
146.730011,-0.084900,-151.724518,-0.001953,0.002748,0.069803,-0.377654,-0.019239,0.698029,-151.724518,0.068710,0.000000
147.090012,-0.137772,-151.857971,-0.001949,0.002721,0.069118,-0.612839,-0.031219,0.691179,-151.857971,0.068112,0.000000
147.450012,-0.131813,-151.813492,-0.001983,0.002698,0.068537,-0.586334,-0.029869,0.685369,-151.813492,0.067513,0.000000
147.810013,-0.147827,-151.902451,-0.001992,0.002676,0.067965,-0.657568,-0.033498,0.679646,-151.902451,0.066906,0.000000
148.100006,-0.101654,-151.991409,-0.002001,0.002675,0.067956,-0.452180,-0.023035,0.679559,-151.991409,0.067843,0.000000