File: Data/compression 16/ManualNoHeating-17-16-reverse-hand-4_08302024_171813.csv
Time (sec),S:Load (lbs),S:HL1 (DIM),S:LVDT (in),S:Position (in),Ch:Position (mm),Ch:Load (N),Ch:Stress (MPa),Ch:Strain (mm/mm),Ch:HL1 (DIM),Set Point (),Cycles ()
0.210000,-0.150810,-103.907501,-0.010481,-0.005773,-0.146622,-0.670837,-0.034174,-1.466215,-103.907501,-0.146396,0.000000
0.580000,-0.122505,-103.907501,-0.010499,-0.005682,-0.144332,-0.544930,-0.027760,-1.443321,-103.907501,-0.143569,0.000000
0.950000,-0.112083,-103.996460,-0.010352,-0.005454,-0.138539,-0.498572,-0.025398,-1.385393,-103.996460,-0.137412,0.000000
1.320000,-0.070747,-104.085426,-0.010102,-0.005214,-0.132434,-0.314700,-0.016032,-1.324339,-104.085426,-0.131237,0.000000
1.690000,-0.040215,-103.996460,-0.009852,-0.004977,-0.126424,-0.178883,-0.009113,-1.264238,-103.996460,-0.125080,0.000000
2.060000,-0.073723,-103.996460,-0.009619,-0.004734,-0.120241,-0.327936,-0.016706,-1.202408,-103.996460,-0.118905,0.000000
2.430000,-0.080055,-104.085426,-0.009356,-0.004490,-0.114040,-0.356103,-0.018141,-1.140400,-104.085426,-0.112748,0.000000
2.800000,-0.103516,-104.218872,-0.009110,-0.004249,-0.107926,-0.460460,-0.023457,-1.079259,-104.218872,-0.106591,0.000000
3.170000,-0.075958,-104.218872,-0.008847,-0.004000,-0.101604,-0.337879,-0.017212,-1.016040,-104.218872,-0.100416,0.000000
3.540000,-0.082291,-104.218872,-0.008606,-0.003757,-0.095421,-0.366047,-0.018647,-0.954206,-104.218872,-0.094259,0.000000
3.910000,-0.061440,-104.218872,-0.008347,-0.003515,-0.089272,-0.273297,-0.013922,-0.892720,-104.218872,-0.088101,0.000000
4.280000,-0.099419,-104.263351,-0.008106,-0.003274,-0.083150,-0.442236,-0.022529,-0.831496,-104.263351,-0.081927,0.000000
4.650000,-0.123627,-104.352310,-0.007873,-0.003033,-0.077035,-0.549919,-0.028014,-0.770355,-104.352310,-0.075769,0.000000
5.020000,-0.114685,-104.396790,-0.007606,-0.002790,-0.070861,-0.510145,-0.025988,-0.708608,-104.396790,-0.069595,0.000000
5.390000,-0.061066,-104.352310,-0.007334,-0.002546,-0.064677,-0.271634,-0.013838,-0.646774,-104.352310,-0.063437,0.000000
5.760000,-0.046539,-104.396790,-0.007075,-0.002297,-0.058356,-0.207017,-0.010546,-0.583555,-104.396790,-0.057280,0.000000
6.130000,-0.058830,-104.485756,-0.006851,-0.002064,-0.052415,-0.261690,-0.013331,-0.524151,-104.485756,-0.051106,0.000000
6.500000,-0.085266,-104.485756,-0.006610,-0.001819,-0.046214,-0.379283,-0.019322,-0.462143,-104.485756,-0.044948,0.000000
6.870000,-0.072983,-104.530235,-0.006342,-0.001573,-0.039962,-0.324644,-0.016538,-0.399617,-104.530235,-0.038774,0.000000
7.240000,-0.088623,-104.574715,-0.006084,-0.001334,-0.033874,-0.394215,-0.020082,-0.338737,-104.574715,-0.032616,0.000000
7.610000,-0.064415,-104.619194,-0.005846,-0.001088,-0.027647,-0.286532,-0.014597,-0.276471,-104.619194,-0.026459,0.000000
7.980000,-0.079315,-104.619194,-0.005596,-0.000843,-0.021420,-0.352812,-0.017973,-0.214202,-104.619194,-0.020284,0.000000
8.350000,-0.059578,-104.663681,-0.005364,-0.000608,-0.015445,-0.265016,-0.013501,-0.154450,-104.663681,-0.014127,0.000000
8.720000,-0.074471,-104.752640,-0.005092,-0.000362,-0.009201,-0.331261,-0.016875,-0.092011,-104.752640,-0.007952,0.000000
9.090000,-0.087502,-104.708160,-0.004846,-0.000115,-0.002922,-0.389226,-0.019828,-0.029223,-104.708160,-0.001795,0.000000
9.460000,0.272583,-104.752640,-0.004704,0.000000,0.000009,1.212510,0.061768,0.000087,-104.752640,0.000260,0.000000
9.830001,0.255821,-104.797119,-0.004712,0.000000,0.000009,1.137950,0.057970,0.000087,-104.797119,0.000260,0.000000
10.200001,0.146347,-104.841599,-0.004691,0.000001,0.000017,0.650984,0.033163,0.000174,-104.841599,0.000850,0.000000
10.570001,0.205925,-104.886086,-0.004691,0.000016,0.000416,0.916000,0.046663,0.004163,-104.886086,0.001466,0.000000
10.940001,0.488930,-104.841599,-0.004661,0.000043,0.001093,2.174868,0.110793,0.010927,-104.841599,0.002090,0.000000
11.310000,0.764114,-104.841599,-0.004644,0.000063,0.001596,3.398951,0.173151,0.015957,-104.841599,0.002706,0.000000
11.680000,1.169624,-104.975044,-0.004622,0.000094,0.002376,5.202749,0.265041,0.023762,-104.975044,0.003321,0.000000
12.050000,1.538277,-105.019524,-0.004605,0.000119,0.003035,6.842597,0.348578,0.030351,-105.019524,0.003937,0.000000
12.420001,1.974319,-105.019524,-0.004583,0.000144,0.003668,8.782211,0.447387,0.036683,-105.019524,0.004553,0.000000
12.790001,2.509422,-105.064003,-0.004566,0.000168,0.004275,11.162468,0.568643,0.042754,-105.064003,0.005169,0.000000
13.160001,2.851631,-105.064003,-0.004536,0.000188,0.004770,12.684689,0.646189,0.047697,-105.064003,0.005784,0.000000
13.530001,3.358803,-105.152969,-0.004527,0.000215,0.005463,14.940701,0.761116,0.054635,-105.152969,0.006400,0.000000
13.900001,3.613503,-105.152969,-0.004501,0.000231,0.005862,16.073662,0.818831,0.058624,-105.152969,0.007016,0.000000
14.270000,4.314682,-105.197449,-0.004480,0.000261,0.006634,19.192663,0.977721,0.066342,-105.197449,0.007640,0.000000
14.640000,4.862816,-105.152969,-0.004441,0.000286,0.007267,21.630886,1.101930,0.072674,-105.152969,0.008256,0.000000
15.010001,5.297005,-105.241928,-0.004445,0.000307,0.007805,23.562254,1.200318,0.078048,-105.241928,0.008872,0.000000
15.380001,5.688362,-105.286407,-0.004419,0.000329,0.008369,25.303099,1.289001,0.083688,-105.286407,0.009487,0.000000
15.750001,6.452103,-105.330894,-0.004402,0.000360,0.009149,28.700386,1.462067,0.091492,-105.330894,0.010103,0.000000
16.120001,6.930603,-105.330894,-0.004363,0.000386,0.009817,30.828861,1.570497,0.098169,-105.330894,0.010719,0.000000
16.490002,7.344307,-105.286407,-0.004355,0.000409,0.010398,32.669109,1.664244,0.103979,-105.286407,0.011335,0.000000
16.860001,7.543152,-105.375374,-0.004333,0.000425,0.010805,33.553616,1.709303,0.108055,-105.375374,0.011950,0.000000
17.230001,8.252525,-105.464333,-0.004307,0.000459,0.011664,36.709064,1.870049,0.116639,-105.464333,0.012566,0.000000
17.600000,8.582817,-105.464333,-0.004281,0.000483,0.012262,38.178276,1.944894,0.122623,-105.464333,0.013190,0.000000
17.970001,8.893372,-105.464333,-0.004251,0.000507,0.012887,39.559692,2.015267,0.128868,-105.464333,0.013806,0.000000
18.340000,9.204308,-105.508820,-0.004238,0.000530,0.013450,40.942806,2.085726,0.134504,-105.508820,0.014422,0.000000
18.710001,9.564392,-105.553299,-0.004208,0.000555,0.014092,42.544540,2.167322,0.140923,-105.553299,0.015038,0.000000
19.080002,9.721535,-105.597778,-0.004191,0.000573,0.014560,43.243546,2.202931,0.145605,-105.597778,0.015653,0.000000
19.450001,9.888725,-105.642258,-0.004161,0.000590,0.014994,43.987247,2.240817,0.149942,-105.642258,0.016269,0.000000
19.820002,10.777954,-105.642258,-0.004135,0.000629,0.015974,47.942734,2.442319,0.159741,-105.642258,0.016885,0.000000
20.190001,10.715019,-105.642258,-0.004105,0.000650,0.016521,47.662785,2.428058,0.165207,-105.642258,0.017501,0.000000
20.560001,10.964882,-105.686737,-0.004092,0.000675,0.017136,48.774231,2.484678,0.171361,-105.686737,0.018125,0.000000
20.930000,11.253471,-105.820183,-0.004070,0.000697,0.017691,50.057941,2.550073,0.176914,-105.820183,0.018741,0.000000
21.300001,11.413589,-105.820183,-0.004057,0.000718,0.018246,50.770180,2.586356,0.182462,-105.820183,0.019356,0.000000
21.670000,11.789688,-105.820183,-0.004040,0.000740,0.018801,52.443153,2.671582,0.188015,-105.820183,0.019972,0.000000
22.040001,12.312500,-105.820183,-0.003997,0.000772,0.019599,54.768734,2.790052,0.195993,-105.820183,0.020588,0.000000
22.410002,12.228714,-105.909142,-0.003988,0.000793,0.020137,54.396038,2.771066,0.201368,-105.909142,0.021204,0.000000
22.780001,12.621193,-105.909142,-0.003954,0.000814,0.020683,56.141869,2.860003,0.206833,-105.909142,0.021819,0.000000
23.150002,13.283646,-105.953629,-0.003936,0.000848,0.021542,59.088608,3.010117,0.215417,-105.953629,0.022435,0.000000
23.520000,13.354401,-105.953629,-0.003906,0.000870,0.022105,59.403339,3.026150,0.221053,-105.953629,0.023051,0.000000
23.890001,13.459030,-105.998108,-0.003889,0.000893,0.022687,59.868755,3.049860,0.226867,-105.998108,0.023675,0.000000
24.260000,13.599792,-106.042587,-0.003867,0.000912,0.023155,60.494900,3.081757,0.231549,-106.042587,0.024291,0.000000
24.630001,14.095047,-106.087067,-0.003850,0.000936,0.023762,62.697899,3.193983,0.237619,-106.087067,0.024907,0.000000
25.000002,14.302460,-106.087067,-0.003807,0.000958,0.024334,63.620518,3.240984,0.243342,-106.087067,0.025522,0.000000
25.370001,14.725471,-106.176033,-0.003786,0.000989,0.025123,65.502167,3.336839,0.251234,-106.176033,0.026138,0.000000
25.740002,14.912773,-106.176033,-0.003764,0.001013,0.025730,66.335327,3.379283,0.257305,-106.176033,0.026754,0.000000
26.110001,14.926926,-106.176033,-0.003768,0.001028,0.026112,66.398285,3.382490,0.261120,-106.176033,0.027370,0.000000
26.480001,15.266533,-106.264992,-0.003734,0.001051,0.026693,67.908928,3.459446,0.266930,-106.264992,0.027985,0.000000
26.850000,15.918930,-106.264992,-0.003712,0.001083,0.027500,70.810936,3.607281,0.274995,-106.264992,0.028601,0.000000
27.220001,15.854134,-106.176033,-0.003691,0.001102,0.027985,70.522705,3.592598,0.279851,-106.176033,0.029225,0.000000
27.590002,16.451416,-106.309471,-0.003656,0.001135,0.028818,73.179550,3.727944,0.288178,-106.309471,0.029841,0.000000
27.960001,16.464455,-106.353951,-0.003639,0.001154,0.029312,73.237549,3.730899,0.293121,-106.353951,0.030457,0.000000
28.330002,17.175308,-106.442917,-0.003604,0.001186,0.030119,76.399590,3.891981,0.301187,-106.442917,0.031072,0.000000
28.700001,17.148872,-106.442917,-0.003587,0.001206,0.030639,76.281998,3.885990,0.306391,-106.442917,0.031688,0.000000
29.070002,17.539864,-106.531876,-0.003574,0.001235,0.031376,78.021210,3.974590,0.313760,-106.531876,0.032304,0.000000
29.440001,17.600929,-106.487396,-0.003535,0.001257,0.031940,78.292847,3.988428,0.319400,-106.487396,0.032920,0.000000
29.810001,17.690300,-106.576355,-0.003518,0.001280,0.032512,78.690384,4.008679,0.325122,-106.576355,0.033536,0.000000
30.180002,17.920059,-106.620842,-0.003492,0.001301,0.033050,79.712402,4.060743,0.330497,-106.620842,0.034151,0.000000
30.550001,17.982613,-106.620842,-0.003479,0.001320,0.033527,79.990654,4.074918,0.335270,-106.620842,0.034776,0.000000
30.920002,18.404884,-106.576355,-0.003449,0.001349,0.034255,81.869011,4.170606,0.342552,-106.576355,0.035391,0.000000
31.290001,18.907219,-106.709801,-0.003436,0.001378,0.034992,84.103508,4.284437,0.349925,-106.709801,0.036007,0.000000
31.660002,18.667404,-106.709801,-0.003415,0.001398,0.035504,83.036758,4.230094,0.355042,-106.709801,0.036623,0.000000
32.030003,19.406197,-106.754280,-0.003376,0.001425,0.036207,86.323074,4.397507,0.362067,-106.754280,0.037238,0.000000
32.400002,19.202881,-106.798767,-0.003354,0.001447,0.036744,85.418678,4.351435,0.367441,-106.798767,0.037854,0.000000
32.770000,19.536896,-106.798767,-0.003337,0.001474,0.037429,86.904449,4.427124,0.374292,-106.798767,0.038470,0.000000
33.140003,19.957306,-106.843246,-0.003290,0.001502,0.038140,88.774529,4.522390,0.381404,-106.843246,0.039086,0.000000
33.510002,20.123756,-106.887726,-0.003285,0.001529,0.038843,89.514938,4.560108,0.388429,-106.887726,0.039702,0.000000
33.880001,20.021729,-106.932205,-0.003264,0.001547,0.039294,89.061096,4.536989,0.392940,-106.932205,0.040326,0.000000
34.250000,20.253716,-106.932205,-0.003234,0.001572,0.039918,90.093025,4.589558,0.399182,-106.932205,0.040942,0.000000
34.620003,20.514000,-106.976685,-0.003216,0.001594,0.040500,91.250832,4.648539,0.404995,-106.976685,0.041557,0.000000
34.990002,20.968666,-107.021172,-0.003221,0.001621,0.041185,93.273285,4.751567,0.411846,-107.021172,0.042173,0.000000
35.360001,21.211082,-107.065651,-0.003186,0.001647,0.041835,94.351608,4.806500,0.418348,-107.065651,0.042789,0.000000
35.730003,21.062881,-107.110130,-0.003152,0.001668,0.042364,93.692375,4.772917,0.423640,-107.110130,0.043404,0.000000
36.100002,21.468018,-107.065651,-0.003130,0.001696,0.043066,95.494514,4.864722,0.430664,-107.065651,0.044020,0.000000
36.470001,21.511589,-107.110130,-0.003100,0.001716,0.043578,95.688324,4.874596,0.435781,-107.110130,0.044636,0.000000
36.840000,22.028069,-107.154610,-0.003083,0.001744,0.044289,97.985741,4.991632,0.442889,-107.154610,0.045252,0.000000
37.210003,22.206436,-107.288055,-0.003070,0.001769,0.044931,98.779160,5.032051,0.449309,-107.288055,0.045876,0.000000
37.580002,22.298409,-107.154610,-0.003031,0.001792,0.045521,99.188278,5.052891,0.455206,-107.154610,0.046492,0.000000
37.950001,22.420921,-107.243576,-0.003001,0.001816,0.046119,99.733238,5.080654,0.461189,-107.243576,0.047108,0.000000
38.320004,22.696480,-107.243576,-0.002992,0.001839,0.046717,100.958984,5.143096,0.467173,-107.243576,0.047723,0.000000
38.690002,22.843567,-107.332535,-0.002975,0.001865,0.047368,101.613258,5.176426,0.473676,-107.332535,0.048339,0.000000
39.060001,23.125824,-107.377014,-0.002945,0.001888,0.047966,102.868805,5.240386,0.479660,-107.377014,0.048955,0.000000
39.430000,23.507874,-107.332535,-0.002919,0.001916,0.048660,104.568245,5.326960,0.486597,-107.332535,0.049570,0.000000
39.800003,23.672836,-107.421494,-0.002906,0.001940,0.049267,105.302032,5.364341,0.492668,-107.421494,0.050186,0.000000
40.170002,23.563736,-107.377014,-0.002876,0.001958,0.049727,104.816734,5.339619,0.497267,-107.377014,0.050802,0.000000
40.540001,23.637466,-107.465981,-0.002867,0.001977,0.050221,105.144699,5.356326,0.502210,-107.465981,0.051427,0.000000
40.910004,24.505463,-107.510460,-0.002828,0.002010,0.051053,109.005745,5.553017,0.510533,-107.510460,0.052042,0.000000
41.280003,24.935181,-107.554939,-0.002807,0.002037,0.051730,110.917221,5.650393,0.517301,-107.554939,0.052658,0.000000
41.650002,24.875603,-107.554939,-0.002798,0.002057,0.052241,110.652206,5.636892,0.522414,-107.554939,0.053274,0.000000
42.020000,25.098656,-107.599419,-0.002768,0.002081,0.052866,111.644394,5.687437,0.528659,-107.599419,0.053889,0.000000
42.390003,25.222282,-107.688385,-0.002746,0.002103,0.053404,112.194313,5.715451,0.534037,-107.688385,0.054505,0.000000
42.760002,25.494484,-107.688385,-0.002738,0.002125,0.053976,113.405128,5.777133,0.539760,-107.688385,0.055121,0.000000
43.130001,26.099586,-107.732864,-0.002721,0.002151,0.054635,116.096756,5.914251,0.546350,-107.732864,0.055736,0.000000
43.500004,26.127892,-107.777344,-0.002690,0.002170,0.055129,116.222664,5.920665,0.551293,-107.777344,0.056352,0.000000
43.870003,27.068504,-107.777344,-0.002682,0.002203,0.055953,120.406723,6.133811,0.559532,-107.777344,0.056977,0.000000
44.240002,27.009666,-107.821823,-0.002665,0.002224,0.056491,120.144997,6.120478,0.564911,-107.821823,0.057592,0.000000
44.610001,27.606209,-107.910789,-0.002626,0.002253,0.057219,122.798553,6.255656,0.572193,-107.910789,0.058208,0.000000
44.980003,27.792770,-107.910789,-0.002604,0.002277,0.057844,123.628418,6.297932,0.578438,-107.910789,0.058824,0.000000
45.350002,27.806915,-107.866310,-0.002574,0.002297,0.058356,123.691338,6.301137,0.583555,-107.866310,0.059440,0.000000
45.720001,27.351875,-107.955269,-0.002565,0.002310,0.058676,121.667221,6.198024,0.586765,-107.955269,0.060055,0.000000
46.090004,28.875626,-107.955269,-0.002557,0.002349,0.059656,128.445190,6.543310,0.596564,-107.955269,0.060671,0.000000
46.460003,29.551483,-107.999748,-0.002531,0.002375,0.060315,131.451569,6.696462,0.603153,-107.999748,0.061287,0.000000
46.830002,29.255821,-108.088715,-0.002501,0.002394,0.060818,130.136398,6.629464,0.608183,-108.088715,0.061911,0.000000
47.200001,29.265503,-108.088715,-0.002488,0.002411,0.061252,130.179459,6.631658,0.612521,-108.088715,0.062527,0.000000
47.570004,29.424873,-108.133194,-0.002449,0.002433,0.061790,130.888367,6.667772,0.617895,-108.133194,0.063143,0.000000
47.940002,30.596733,-108.133194,-0.002440,0.002467,0.062657,136.101059,6.933319,0.626570,-108.133194,0.063758,0.000000
48.310001,31.049538,-108.177673,-0.002423,0.002490,0.063255,138.115234,7.035926,0.632554,-108.177673,0.064374,0.000000
48.680004,31.344086,-108.222153,-0.002393,0.002517,0.063923,139.425461,7.102672,0.639231,-108.222153,0.064990,0.000000
49.050003,32.164421,-108.222153,-0.002358,0.002543,0.064599,143.074493,7.288562,0.645995,-108.222153,0.065605,0.000000
49.420002,32.371086,-108.222153,-0.002358,0.002565,0.065163,143.993790,7.335393,0.651634,-108.222153,0.066221,0.000000
49.790001,33.045456,-108.311119,-0.002328,0.002592,0.065840,146.993530,7.488207,0.658398,-108.311119,0.066837,0.000000
50.160004,33.100189,-108.355598,-0.002311,0.002615,0.066421,147.237000,7.500610,0.664207,-108.355598,0.067461,0.000000
50.530003,34.066124,-108.400078,-0.002289,0.002643,0.067141,151.533691,7.719494,0.671406,-108.400078,0.068077,0.000000
50.900002,34.450790,-108.400078,-0.002259,0.002667,0.067730,153.244766,7.806661,0.677303,-108.400078,0.068693,0.000000
51.270004,34.417648,-108.400078,-0.002242,0.002685,0.068207,153.097351,7.799150,0.682072,-108.400078,0.069309,0.000000
51.640003,34.770279,-108.489037,-0.002220,0.002707,0.068762,154.665924,7.879058,0.687621,-108.489037,0.069924,0.000000
52.010002,34.507385,-108.578003,-0.002225,0.002721,0.069109,153.496521,7.819485,0.691092,-108.578003,0.070540,0.000000
52.380001,36.417282,-108.533524,-0.002190,0.002760,0.070106,161.992157,8.252275,0.701065,-108.533524,0.071156,0.000000
52.750004,35.144142,-108.578003,-0.002169,0.002759,0.070089,156.328949,7.963776,0.700891,-108.578003,0.071771,0.000000
53.120003,37.748886,-108.578003,-0.002139,0.002807,0.071303,167.915436,8.554020,0.713033,-108.578003,0.072387,0.000000
53.490002,38.519325,-108.622482,-0.002143,0.002832,0.071928,171.342514,8.728604,0.719278,-108.622482,0.073012,0.000000
53.860004,38.635506,-108.666962,-0.002117,0.002850,0.072379,171.859314,8.754930,0.723785,-108.666962,0.073627,0.000000
54.230003,40.271339,-108.711441,-0.002095,0.002887,0.073324,179.135864,9.125616,0.733240,-108.711441,0.074243,0.000000
54.600002,40.776649,-108.711441,-0.002074,0.002910,0.073922,181.383591,9.240121,0.739224,-108.711441,0.074859,0.000000
54.970001,41.136734,-108.711441,-0.002065,0.002933,0.074495,182.985336,9.321717,0.744947,-108.711441,0.075475,0.000000
55.340004,40.912567,-108.800407,-0.002026,0.002954,0.075041,181.988190,9.270920,0.750408,-108.800407,0.076090,0.000000
55.710003,42.058731,-108.844887,-0.002013,0.002978,0.075631,187.086578,9.530644,0.756305,-108.844887,0.076706,0.000000
56.080002,42.654152,-108.844887,-0.001983,0.002998,0.076160,189.735138,9.665568,0.761597,-108.844887,0.077322,0.000000
56.450005,43.720253,-108.844887,-0.001975,0.003025,0.076827,194.477402,9.907151,0.768273,-108.844887,0.077937,0.000000
56.820004,44.750984,-108.933846,-0.001944,0.003054,0.077573,199.062317,10.140718,0.775733,-108.933846,0.078562,0.000000
57.190002,45.494606,-108.978333,-0.001932,0.003076,0.078137,202.370117,10.309225,0.781369,-108.978333,0.079178,0.000000
57.560001,45.904221,-108.978333,-0.001914,0.003096,0.078649,204.192169,10.402045,0.786486,-108.978333,0.079793,0.000000
57.930004,46.867546,-108.978333,-0.001897,0.003120,0.079256,208.477264,10.620338,0.792557,-108.978333,0.080409,0.000000
58.300003,47.896042,-109.022812,-0.001876,0.003149,0.079984,213.052231,10.853398,0.799843,-109.022812,0.081025,0.000000
58.670002,49.254829,-109.156258,-0.001858,0.003178,0.080713,219.096420,11.161304,0.807125,-109.156258,0.081641,0.000000
59.040001,49.994362,-109.111771,-0.001850,0.003199,0.081259,222.386032,11.328884,0.812590,-109.111771,0.082256,0.000000
59.410004,50.829964,-109.111771,-0.001824,0.003221,0.081823,226.102966,11.518235,0.818226,-109.111771,0.082872,0.000000
59.780003,51.410118,-109.200737,-0.001819,0.003242,0.082352,228.683624,11.649699,0.823517,-109.200737,0.083488,0.000000
60.150002,53.300652,-109.200737,-0.001789,0.003274,0.083158,237.093140,12.078100,0.831583,-109.200737,0.084112,0.000000
60.520004,54.167908,-109.156258,-0.001781,0.003296,0.083731,240.950882,12.274624,0.837306,-109.156258,0.084728,0.000000
60.890003,55.156189,-109.245216,-0.001772,0.003323,0.084398,245.346985,12.498570,0.843982,-109.245216,0.085344,0.000000
61.260002,56.386505,-109.334175,-0.001742,0.003346,0.084979,250.819702,12.777365,0.849792,-109.334175,0.085959,0.000000
61.630001,57.328606,-109.334175,-0.001733,0.003368,0.085543,255.010376,12.990848,0.855432,-109.334175,0.086575,0.000000
62.000004,58.005951,-109.289696,-0.001729,0.003387,0.086037,258.023346,13.144337,0.860375,-109.289696,0.087191,0.000000
62.370003,59.896858,-109.289696,-0.001699,0.003419,0.086853,266.434540,13.572823,0.868527,-109.289696,0.087807,0.000000
62.740002,60.952164,-109.423141,-0.001686,0.003440,0.087381,271.128754,13.811957,0.873815,-109.423141,0.088422,0.000000
63.110004,62.163490,-109.378662,-0.001681,0.003465,0.088006,276.517029,14.086448,0.880060,-109.378662,0.089038,0.000000
63.480003,63.156609,-109.467621,-0.001664,0.003488,0.088604,280.934631,14.311492,0.886044,-109.467621,0.089662,0.000000
63.850002,64.292351,-109.467621,-0.001651,0.003509,0.089125,285.986664,14.568854,0.891248,-109.467621,0.090278,0.000000
64.220001,65.472389,-109.467621,-0.001643,0.003531,0.089697,291.235718,14.836256,0.896971,-109.467621,0.090894,0.000000
64.590004,65.992592,-109.556580,-0.001638,0.003540,0.089923,293.549713,14.954135,0.899227,-109.556580,0.090174,0.000000
64.960007,65.247108,-109.645546,-0.001617,0.003551,0.090200,290.233643,14.785206,0.902001,-109.645546,294.500488,0.000000
65.330002,65.215080,-109.645546,-0.001600,0.003560,0.090417,290.091156,14.777948,0.904170,-109.645546,294.500488,0.000000
65.700005,65.227745,-109.645546,-0.001600,0.003568,0.090616,290.147491,14.780818,0.906164,-109.645546,294.500488,0.000000
66.070000,64.485237,-109.734505,-0.001591,0.003568,0.090625,286.844666,14.612563,0.906251,-109.734505,294.500488,0.000000
66.440002,66.563438,-109.734505,-0.001582,0.003440,0.087364,296.088959,15.083491,0.873641,-109.734505,294.500488,0.000000
66.810005,65.736031,-109.823471,-0.001569,0.003441,0.087408,292.408478,14.895997,0.874076,-109.823471,294.500488,0.000000
67.180000,65.129433,-109.823471,-0.001561,0.003570,0.090668,289.710175,14.758540,0.906683,-109.823471,294.500488,0.000000
67.550003,65.392708,-109.734505,-0.001565,0.003596,0.091345,290.881287,14.818199,0.913447,-109.734505,294.500488,0.000000
67.920006,64.850533,-109.912430,-0.001565,0.003597,0.091353,288.469574,14.695340,0.913534,-109.912430,294.500488,0.000000
68.290001,65.846992,-109.867950,-0.001569,0.003604,0.091535,292.902039,14.921142,0.915354,-109.867950,294.500488,0.000000
68.660004,65.276894,-109.956909,-0.001552,0.003604,0.091535,290.366119,14.791956,0.915354,-109.956909,294.500488,0.000000
69.030006,64.761162,-109.956909,-0.001539,0.003605,0.091562,288.072021,14.675090,0.915615,-109.956909,294.500488,0.000000
69.400002,65.979561,-110.045876,-0.001544,0.003621,0.091969,293.491730,14.951182,0.919692,-110.045876,294.500488,0.000000
69.770004,65.503304,-110.001389,-0.001535,0.003621,0.091978,291.373260,14.843261,0.919779,-110.001389,294.500488,0.000000
70.140007,65.060555,-110.045876,-0.001544,0.003622,0.091995,289.403809,14.742932,0.919953,-110.045876,294.500488,0.000000
70.510002,66.013451,-110.134834,-0.001535,0.003636,0.092342,293.642487,14.958861,0.923420,-110.134834,294.500488,0.000000
70.880005,65.596397,-110.179314,-0.001535,0.003636,0.092342,291.787354,14.864356,0.923420,-110.179314,294.500488,0.000000
71.250000,65.241524,-110.179314,-0.001531,0.003636,0.092351,290.208801,14.783940,0.923507,-110.179314,294.500488,0.000000
71.620003,64.926491,-110.179314,-0.001526,0.003637,0.092368,288.807465,14.712553,0.923681,-110.179314,294.500488,0.000000
71.990005,66.275978,-110.223793,-0.001522,0.003644,0.092559,294.810272,15.018352,0.925588,-110.223793,294.500488,0.000000
72.360001,65.920723,-110.312759,-0.001526,0.003644,0.092559,293.230011,14.937850,0.925588,-110.312759,294.500488,0.000000
72.730003,65.610542,-110.268280,-0.001509,0.003644,0.092559,291.850281,14.867561,0.925588,-110.268280,294.500488,0.000000
73.100006,65.323814,-110.312759,-0.001509,0.003644,0.092568,290.574829,14.802588,0.925676,-110.312759,294.500488,0.000000
73.470001,65.057564,-110.312759,-0.001513,0.003644,0.092568,289.390503,14.742254,0.925676,-110.312759,294.500488,0.000000
73.840004,64.782387,-110.401718,-0.001509,0.003645,0.092576,288.166443,14.679899,0.925763,-110.401718,294.500488,0.000000
74.210007,66.164253,-110.446205,-0.001509,0.003661,0.093001,294.313293,14.993033,0.930013,-110.446205,294.500488,0.000000
74.580002,65.877541,-110.446205,-0.001500,0.003661,0.092993,293.037933,14.928063,0.929926,-110.446205,294.500488,0.000000
74.950005,65.650017,-110.446205,-0.001509,0.003661,0.092993,292.025848,14.876507,0.929926,-110.446205,294.500488,0.000000
75.320007,65.424355,-110.535164,-0.001518,0.003661,0.093001,291.022064,14.825371,0.930013,-110.535164,294.500488,0.000000
75.690002,65.222527,-110.535164,-0.001487,0.003663,0.093044,290.124298,14.779635,0.930445,-110.535164,294.500488,0.000000
76.060005,65.124229,-110.579643,-0.001500,0.003669,0.093183,289.687042,14.757361,0.931834,-110.579643,294.500488,0.000000
76.430000,65.188271,-110.624123,-0.001492,0.003671,0.093244,289.971924,14.771873,0.932439,-110.624123,294.500488,0.000000
76.800003,65.113792,-110.624123,-0.001496,0.003675,0.093348,289.640625,14.754995,0.933480,-110.624123,294.500488,0.000000
77.170006,65.340202,-110.624123,-0.001496,0.003676,0.093383,290.647736,14.806301,0.933828,-110.624123,294.500488,0.000000
77.540001,65.273170,-110.713089,-0.001492,0.003678,0.093417,290.349548,14.791112,0.934173,-110.713089,294.500488,0.000000
77.910004,65.235191,-110.713089,-0.001483,0.003679,0.093443,290.180634,14.782506,0.934434,-110.713089,294.500488,0.000000
78.280006,65.221779,-110.846527,-0.001500,0.003680,0.093478,290.120972,14.779467,0.934782,-110.846527,294.500488,0.000000
78.650002,65.244865,-110.802048,-0.001500,0.003682,0.093530,290.223663,14.784698,0.935301,-110.802048,294.500488,0.000000
79.020004,65.149910,-110.846527,-0.001487,0.003683,0.093539,289.801270,14.763181,0.935388,-110.846527,294.500488,0.000000
79.390007,65.254189,-110.846527,-0.001487,0.003686,0.093617,290.265137,14.786810,0.936167,-110.846527,294.500488,0.000000
79.760002,65.194237,-110.935493,-0.001496,0.003686,0.093625,289.998444,14.773225,0.936254,-110.935493,294.500488,0.000000
80.130005,65.174873,-110.935493,-0.001475,0.003688,0.093678,289.912323,14.768838,0.936777,-110.935493,294.500488,0.000000
80.500008,65.213966,-110.935493,-0.001483,0.003689,0.093695,290.086212,14.777697,0.936951,-110.935493,294.500488,0.000000
80.870003,65.133156,-110.979973,-0.001492,0.003689,0.093712,289.726746,14.759384,0.937125,-110.979973,294.500488,0.000000
81.240005,65.143211,-111.068932,-0.001492,0.003691,0.093747,289.771484,14.761663,0.937469,-111.068932,294.500488,0.000000
81.610001,65.115654,-111.113419,-0.001479,0.003693,0.093790,289.648895,14.755418,0.937905,-111.113419,294.500488,0.000000
81.980003,65.195717,-111.068932,-0.001466,0.003694,0.093825,290.005035,14.773561,0.938249,-111.068932,294.500488,0.000000
82.350006,65.137260,-111.113419,-0.001479,0.003694,0.093834,289.744995,14.760314,0.938336,-111.113419,294.500488,0.000000
82.720001,65.057564,-111.157898,-0.001479,0.003694,0.093834,289.390503,14.742254,0.938336,-111.157898,294.500488,0.000000
83.090004,65.057945,-111.246857,-0.001487,0.003696,0.093877,289.392181,14.742341,0.938771,-111.246857,294.500488,0.000000
83.460007,65.069481,-111.246857,-0.001479,0.003698,0.093938,289.443512,14.744955,0.939377,-111.246857,294.500488,0.000000
83.830002,65.107460,-111.246857,-0.001475,0.003698,0.093938,289.612457,14.753561,0.939377,-111.246857,294.500488,0.000000
84.200005,65.055702,-111.291336,-0.001475,0.003698,0.093938,289.382202,14.741833,0.939377,-111.291336,294.500488,0.000000
84.570007,65.002464,-111.291336,-0.001479,0.003700,0.093981,289.145416,14.729769,0.939812,-111.291336,294.500488,0.000000
84.940002,65.024803,-111.380302,-0.001483,0.003701,0.093999,289.244781,14.734831,0.939986,-111.380302,294.500488,0.000000
85.310005,65.030754,-111.424782,-0.001479,0.003702,0.094024,289.271240,14.736180,0.940244,-111.424782,294.500488,0.000000
85.680000,64.987190,-111.424782,-0.001462,0.003702,0.094033,289.077454,14.726308,0.940331,-111.424782,294.500488,0.000000
86.050003,64.939522,-111.424782,-0.001479,0.003702,0.094033,288.865417,14.715506,0.940331,-111.424782,294.500488,0.000000
86.420006,65.330147,-111.513741,-0.001470,0.003708,0.094189,290.602997,14.804023,0.941894,-111.513741,294.500488,0.000000
86.790001,65.319725,-111.602707,-0.001462,0.003708,0.094189,290.556641,14.801661,0.941894,-111.602707,294.500488,0.000000
87.160004,65.297005,-111.469261,-0.001475,0.003708,0.094189,290.455597,14.796514,0.941894,-111.469261,294.500488,0.000000
87.530006,65.245613,-111.558228,-0.001470,0.003708,0.094189,290.226990,14.784867,0.941894,-111.558228,294.500488,0.000000
87.900002,65.158104,-111.558228,-0.001462,0.003708,0.094189,289.837708,14.765038,0.941894,-111.558228,294.500488,0.000000
88.270004,65.073204,-111.736153,-0.001466,0.003708,0.094189,289.460083,14.745798,0.941894,-111.736153,294.500488,0.000000
88.640007,65.002464,-111.736153,-0.001466,0.003708,0.094189,289.145416,14.729769,0.941894,-111.736153,294.500488,0.000000
89.010002,64.963356,-111.736153,-0.001462,0.003708,0.094189,288.971436,14.720907,0.941894,-111.736153,294.500488,0.000000
89.380005,65.007668,-111.691666,-0.001462,0.003713,0.094311,289.168549,14.730948,0.943109,-111.691666,294.500488,0.000000
89.750008,65.124962,-111.780632,-0.001462,0.003713,0.094302,289.690308,14.757527,0.943022,-111.780632,294.500488,0.000000
90.120003,65.074699,-111.825111,-0.001457,0.003713,0.094302,289.466705,14.746138,0.943022,-111.825111,294.500488,0.000000
90.490005,65.020699,-111.869591,-0.001462,0.003713,0.094302,289.226501,14.733901,0.943022,-111.869591,294.500488,0.000000
90.860001,64.992027,-111.869591,-0.001449,0.003713,0.094302,289.098969,14.727404,0.943022,-111.869591,294.500488,0.000000
91.230003,64.941017,-111.958557,-0.001457,0.003713,0.094302,288.872070,14.715845,0.943022,-111.958557,294.500488,0.000000
91.600006,64.875847,-111.958557,-0.001457,0.003713,0.094302,288.582184,14.701077,0.943022,-111.958557,294.500488,0.000000
91.970001,64.803978,-112.003036,-0.001470,0.003713,0.094302,288.262482,14.684792,0.943022,-112.003036,294.500488,0.000000
92.340004,64.745155,-112.003036,-0.001466,0.003713,0.094302,288.000824,14.671461,0.943022,-112.003036,294.500488,0.000000
92.710007,64.690041,-112.047516,-0.001453,0.003713,0.094302,287.755676,14.658973,0.943022,-112.047516,294.500488,0.000000
93.080002,64.628975,-112.047516,-0.001453,0.003713,0.094311,287.484039,14.645135,0.943109,-112.047516,294.500488,0.000000
93.450005,66.150475,-112.047516,-0.001462,0.003718,0.094449,294.252014,14.989912,0.944494,-112.047516,294.500488,0.000000
93.820007,66.052544,-112.136475,-0.001462,0.003718,0.094441,293.816376,14.967720,0.944407,-112.136475,294.500488,0.000000
94.190002,65.961693,-112.180962,-0.001457,0.003718,0.094432,293.412262,14.947133,0.944320,-112.180962,294.500488,0.000000
94.560005,65.879768,-112.225441,-0.001462,0.003718,0.094432,293.047852,14.928569,0.944320,-112.225441,294.500488,0.000000
94.930008,65.827263,-112.225441,-0.001449,0.003718,0.094432,292.814301,14.916672,0.944320,-112.225441,294.500488,0.000000
95.300003,65.746452,-112.269920,-0.001449,0.003718,0.094432,292.454834,14.898359,0.944320,-112.269920,294.500488,0.000000
95.670006,65.679802,-112.314400,-0.001457,0.003718,0.094432,292.158356,14.883256,0.944320,-112.314400,294.500488,0.000000
96.040001,65.580376,-112.358879,-0.001462,0.003718,0.094432,291.716095,14.860725,0.944320,-112.358879,294.500488,0.000000
96.410004,65.550224,-112.358879,-0.001440,0.003718,0.094432,291.581970,14.853893,0.944320,-112.358879,294.500488,0.000000
96.780006,65.485802,-112.358879,-0.001462,0.003718,0.094432,291.295380,14.839295,0.944320,-112.358879,294.500488,0.000000
97.150002,65.400902,-112.403366,-0.001444,0.003718,0.094432,290.917755,14.820056,0.944320,-112.403366,294.500488,0.000000
97.520004,65.346535,-112.536804,-0.001449,0.003718,0.094432,290.675903,14.807736,0.944320,-112.536804,294.500488,0.000000
97.890007,65.281731,-112.581284,-0.001444,0.003718,0.094432,290.387634,14.793052,0.944320,-112.581284,294.500488,0.000000
98.260002,65.226997,-112.581284,-0.001440,0.003718,0.094432,290.144165,14.780648,0.944320,-112.581284,294.500488,0.000000
98.630005,65.171135,-112.625771,-0.001431,0.003718,0.094441,289.895691,14.767991,0.944407,-112.625771,294.500488,0.000000
99.000008,65.097420,-112.625771,-0.001453,0.003718,0.094441,289.567780,14.751287,0.944407,-112.625771,294.500488,0.000000
99.370003,65.042305,-112.581284,-0.001449,0.003718,0.094441,289.322632,14.738797,0.944407,-112.581284,294.500488,0.000000
99.740005,64.994270,-112.714729,-0.001436,0.003718,0.094441,289.108948,14.727912,0.944407,-112.714729,294.500488,0.000000
100.110008,64.943993,-112.714729,-0.001431,0.003718,0.094441,288.885315,14.716518,0.944407,-112.714729,294.500488,0.000000
100.480003,64.890007,-112.714729,-0.001444,0.003718,0.094441,288.645172,14.704286,0.944407,-112.714729,294.500488,0.000000
100.850006,64.812920,-112.714729,-0.001449,0.003718,0.094441,288.302277,14.686818,0.944407,-112.714729,294.500488,0.000000
101.220001,64.785744,-112.848175,-0.001449,0.003718,0.094441,288.181366,14.680660,0.944407,-112.848175,294.500488,0.000000
101.590004,64.727272,-112.892654,-0.001427,0.003718,0.094441,287.921295,14.667409,0.944407,-112.892654,294.500488,0.000000
101.960007,64.678490,-112.892654,-0.001440,0.003718,0.094441,287.704285,14.656355,0.944407,-112.892654,294.500488,0.000000
102.330002,64.623009,-112.848175,-0.001453,0.003718,0.094441,287.457489,14.643784,0.944407,-112.848175,294.500488,0.000000
102.700005,64.567528,-112.937134,-0.001436,0.003718,0.094449,287.210693,14.631210,0.944494,-112.937134,294.500488,0.000000
103.070007,66.294212,-112.981613,-0.001440,0.003731,0.094770,294.891388,15.022483,0.947704,-112.981613,294.500488,0.000000
103.440002,66.234642,-112.981613,-0.001436,0.003731,0.094770,294.626404,15.008985,0.947704,-112.981613,294.500488,0.000000
103.810005,66.166115,-113.026100,-0.001440,0.003731,0.094770,294.321564,14.993456,0.947704,-113.026100,294.500488,0.000000
104.180008,66.088295,-113.026100,-0.001427,0.003731,0.094770,293.975433,14.975821,0.947704,-113.026100,294.500488,0.000000
104.550003,66.033180,-113.070580,-0.001449,0.003731,0.094770,293.730255,14.963333,0.947704,-113.070580,294.500488,0.000000
104.920006,65.978081,-113.115059,-0.001440,0.003731,0.094770,293.485168,14.950847,0.947704,-113.115059,294.500488,0.000000
105.290009,65.929665,-113.204018,-0.001427,0.003731,0.094770,293.269806,14.939876,0.947704,-113.204018,294.500488,0.000000
105.660004,65.867851,-113.204018,-0.001444,0.003731,0.094770,292.994843,14.925869,0.947704,-113.204018,294.500488,0.000000
106.030006,65.837685,-113.204018,-0.001440,0.003731,0.094770,292.860657,14.919033,0.947704,-113.204018,294.500488,0.000000
106.400002,65.817955,-113.248505,-0.001440,0.003731,0.094770,292.772888,14.914561,0.947704,-113.248505,294.500488,0.000000
106.770004,65.757256,-113.337463,-0.001444,0.003731,0.094770,292.502869,14.900806,0.947704,-113.337463,294.500488,0.000000
107.140007,65.716667,-113.292984,-0.001444,0.003731,0.094770,292.322327,14.891609,0.947704,-113.292984,294.500488,0.000000
107.510002,65.644051,-113.337463,-0.001444,0.003731,0.094770,291.999329,14.875154,0.947704,-113.337463,294.500488,0.000000
107.880005,65.603462,-113.337463,-0.001427,0.003731,0.094770,291.818787,14.865956,0.947704,-113.337463,294.500488,0.000000
108.250008,65.562508,-113.426422,-0.001436,0.003731,0.094770,291.636597,14.856677,0.947704,-113.426422,294.500488,0.000000
108.620003,65.524895,-113.515388,-0.001436,0.003731,0.094770,291.469299,14.848153,0.947704,-113.515388,294.500488,0.000000
108.990005,65.488411,-113.515388,-0.001427,0.003731,0.094770,291.307007,14.839886,0.947704,-113.515388,294.500488,0.000000
109.360008,65.448936,-113.559868,-0.001423,0.003731,0.094770,291.131409,14.830941,0.947704,-113.559868,294.500488,0.000000
109.730003,65.381905,-113.515388,-0.001427,0.003731,0.094770,290.833252,14.815751,0.947704,-113.515388,294.500488,0.000000
110.100006,65.330147,-113.559868,-0.001427,0.003731,0.094770,290.602997,14.804023,0.947704,-113.559868,294.500488,0.000000
110.470009,65.294029,-113.604347,-0.001449,0.003731,0.094770,290.442352,14.795838,0.947704,-113.604347,294.500488,0.000000
110.840004,65.248222,-113.737793,-0.001436,0.003731,0.094770,290.238586,14.785459,0.947704,-113.737793,294.500488,0.000000
111.210007,65.240776,-113.737793,-0.001436,0.003731,0.094770,290.205475,14.783772,0.947704,-113.737793,294.500488,0.000000
111.580002,65.203545,-113.648827,-0.001418,0.003731,0.094770,290.039856,14.775334,0.947704,-113.648827,294.500488,0.000000
111.950005,65.139122,-113.737793,-0.001444,0.003731,0.094770,289.753296,14.760736,0.947704,-113.737793,294.500488,0.000000
112.320007,65.089592,-113.782272,-0.001440,0.003731,0.094770,289.532959,14.749513,0.947704,-113.782272,294.500488,0.000000
112.690002,65.049370,-113.871231,-0.001436,0.003731,0.094770,289.354034,14.740397,0.947704,-113.871231,294.500488,0.000000
113.060005,65.008781,-113.826752,-0.001436,0.003731,0.094770,289.173492,14.731200,0.947704,-113.826752,294.500488,0.000000
113.430008,64.993141,-113.782272,-0.001431,0.003731,0.094770,289.103943,14.727656,0.947704,-113.782272,294.500488,0.000000
113.800003,64.948097,-113.871231,-0.001423,0.003731,0.094770,288.903564,14.717449,0.947704,-113.871231,294.500488,0.000000
114.170006,64.928734,-113.915718,-0.001436,0.003731,0.094770,288.817444,14.713061,0.947704,-113.915718,294.500488,0.000000
114.540009,65.848122,-113.960197,-0.001440,0.003750,0.095239,292.907074,14.921397,0.952386,-113.960197,294.500488,0.000000
114.910004,65.853325,-114.093643,-0.001427,0.003750,0.095239,292.930206,14.922577,0.952386,-114.093643,294.500488,0.000000
115.280006,65.836571,-114.049156,-0.001431,0.003750,0.095239,292.855682,14.918780,0.952386,-114.049156,294.500488,0.000000
115.650009,65.838066,-114.004677,-0.001440,0.003750,0.095239,292.862335,14.919119,0.952386,-114.004677,294.500488,0.000000
116.020004,65.821678,-114.093643,-0.001418,0.003750,0.095239,292.789459,14.915406,0.952386,-114.093643,294.500488,0.000000
116.390007,65.798210,-114.138123,-0.001423,0.003750,0.095239,292.685059,14.910088,0.952386,-114.138123,294.500488,0.000000
116.760002,65.775124,-114.182602,-0.001431,0.003750,0.095239,292.582367,14.904856,0.952386,-114.182602,294.500488,0.000000
117.130005,65.751671,-114.182602,-0.001427,0.003750,0.095239,292.478027,14.899541,0.952386,-114.182602,294.500488,0.000000
117.500008,65.724861,-114.138123,-0.001423,0.003750,0.095239,292.358795,14.893466,0.952386,-114.138123,294.500488,0.000000
117.870003,65.674965,-114.271561,-0.001427,0.003750,0.095239,292.136841,14.882160,0.952386,-114.271561,294.500488,0.000000
118.240005,65.647408,-114.316048,-0.001431,0.003750,0.095239,292.014252,14.875915,0.952386,-114.316048,294.500488,0.000000
118.610008,65.628410,-114.316048,-0.001427,0.003750,0.095239,291.929749,14.871611,0.952386,-114.316048,294.500488,0.000000
118.980003,65.596764,-114.316048,-0.001423,0.003750,0.095239,291.788971,14.864439,0.952386,-114.316048,294.500488,0.000000
119.350006,65.569588,-114.316048,-0.001440,0.003750,0.095239,291.668091,14.858281,0.952386,-114.316048,294.500488,0.000000
119.720009,65.546120,-114.360527,-0.001431,0.003750,0.095239,291.563690,14.852962,0.952386,-114.360527,294.500488,0.000000
120.090004,65.521919,-114.449486,-0.001431,0.003750,0.095239,291.456055,14.847479,0.952386,-114.449486,294.500488,0.000000
120.460007,65.492134,-114.538452,-0.001440,0.003750,0.095239,291.323547,14.840730,0.952386,-114.538452,294.500488,0.000000
120.830009,65.475365,-114.493965,-0.001418,0.003750,0.095239,291.248962,14.836929,0.952386,-114.493965,294.500488,0.000000
121.200005,65.431053,-114.493965,-0.001431,0.003750,0.095239,291.051849,14.826889,0.952386,-114.493965,294.500488,0.000000
121.570007,65.400520,-114.538452,-0.001431,0.003750,0.095239,290.916046,14.819970,0.952386,-114.538452,294.500488,0.000000
121.940002,65.367378,-114.538452,-0.001423,0.003750,0.095239,290.768616,14.812459,0.952386,-114.538452,294.500488,0.000000
122.310005,65.334618,-114.627411,-0.001431,0.003750,0.095239,290.622894,14.805036,0.952386,-114.627411,294.500488,0.000000
122.680008,65.304817,-114.582932,-0.001414,0.003750,0.095239,290.490326,14.798283,0.952386,-114.582932,294.500488,0.000000
123.050003,65.282860,-114.627411,-0.001431,0.003750,0.095239,290.392670,14.793307,0.952386,-114.627411,294.500488,0.000000
123.420006,65.264977,-114.716370,-0.001418,0.003750,0.095239,290.313110,14.789255,0.952386,-114.716370,294.500488,0.000000
123.790009,65.254189,-114.760857,-0.001436,0.003750,0.095239,290.265137,14.786810,0.952386,-114.760857,294.500488,0.000000
124.160004,65.224022,-114.760857,-0.001440,0.003750,0.095239,290.130951,14.779975,0.952386,-114.760857,294.500488,0.000000
124.530006,65.188637,-114.760857,-0.001423,0.003750,0.095247,289.973541,14.771956,0.952473,-114.760857,294.500488,0.000000
124.900009,65.143959,-114.805336,-0.001431,0.003750,0.095247,289.774811,14.761832,0.952473,-114.805336,294.500488,0.000000
125.270004,65.125710,-114.849815,-0.001414,0.003744,0.095108,289.693634,14.757697,0.951084,-114.849815,0.095187,0.000000
125.640007,65.104866,-114.894295,-0.001423,0.003734,0.094831,289.600922,14.752974,0.948309,-114.894295,0.094571,0.000000
126.010010,64.959267,-114.938774,-0.001410,0.003715,0.094363,288.953247,14.719980,0.943627,-114.938774,0.093955,0.000000
126.380005,64.914207,-114.938774,-0.001418,0.003692,0.093782,288.752808,14.709770,0.937818,-114.938774,0.093331,0.000000
126.750008,64.858727,-114.938774,-0.001423,0.003671,0.093235,288.506012,14.697197,0.932352,-114.938774,0.092715,0.000000
127.120003,64.842705,-114.983261,-0.001410,0.003650,0.092715,288.434753,14.693566,0.927152,-114.983261,0.092099,0.000000
127.490005,64.761528,-115.027740,-0.001418,0.003621,0.091969,288.073669,14.675172,0.919692,-115.027740,0.091484,0.000000
127.860008,64.724663,-115.116699,-0.001427,0.003600,0.091431,287.909668,14.666818,0.914313,-115.116699,0.090868,0.000000
128.230011,64.668068,-115.116699,-0.001423,0.003573,0.090746,287.657928,14.653994,0.907463,-115.116699,0.090252,0.000000
128.600006,64.671791,-115.116699,-0.001414,0.003555,0.090304,287.674500,14.654838,0.903042,-115.116699,0.089637,0.000000
128.970001,64.433846,-115.116699,-0.001410,0.003530,0.089671,286.616058,14.600918,0.896710,-115.116699,0.089021,0.000000
129.340012,63.815331,-115.161179,-0.001414,0.003506,0.089046,283.864777,14.460761,0.890465,-115.161179,0.088405,0.000000
129.710007,63.002815,-115.294624,-0.001406,0.003484,0.088500,280.250519,14.276643,0.885003,-115.294624,0.087780,0.000000
130.080002,61.880112,-115.294624,-0.001414,0.003462,0.087945,275.256470,14.022234,0.879454,-115.294624,0.087165,0.000000
130.450012,60.582397,-115.294624,-0.001401,0.003440,0.087373,269.483948,13.728168,0.873728,-115.294624,0.086549,0.000000
130.820007,59.216164,-115.294624,-0.001393,0.003419,0.086835,263.406647,13.418574,0.868353,-115.294624,0.085933,0.000000
131.190002,57.186729,-115.383591,-0.001371,0.003389,0.086072,254.379272,12.958698,0.860719,-115.383591,0.085318,0.000000
131.560013,55.550156,-115.428070,-0.001388,0.003369,0.085560,247.099426,12.587845,0.855602,-115.428070,0.084702,0.000000
131.930008,54.589432,-115.428070,-0.001380,0.003359,0.085309,242.825912,12.370142,0.853089,-115.428070,0.084086,0.000000
132.300003,52.456116,-115.428070,-0.001384,0.003335,0.084719,233.336456,11.886725,0.847192,-115.428070,0.083471,0.000000
132.670013,49.818970,-115.472549,-0.001388,0.003308,0.084025,221.605850,11.289141,0.840254,-115.472549,0.082855,0.000000
133.040009,47.159111,-115.561508,-0.001397,0.003279,0.083297,209.774200,10.686407,0.832968,-115.561508,0.082230,0.000000
133.410004,44.467232,-115.561508,-0.001384,0.003257,0.082716,197.800125,10.076419,0.827159,-115.561508,0.081614,0.000000
133.779999,41.643532,-115.605995,-0.001380,0.003229,0.082022,185.239685,9.436560,0.820221,-115.605995,0.080999,0.000000
134.150009,38.710358,-115.605995,-0.001384,0.003203,0.081363,172.192276,8.771893,0.813631,-115.605995,0.080383,0.000000
134.520004,36.889084,-115.650475,-0.001393,0.003186,0.080921,164.090836,8.359186,0.809207,-115.650475,0.079767,0.000000
134.889999,33.718704,-115.694954,-0.001388,0.003156,0.080175,149.988281,7.640768,0.801751,-115.694954,0.079152,0.000000
135.260010,30.970963,-115.739433,-0.001384,0.003131,0.079533,137.765717,7.018120,0.795331,-115.739433,0.078536,0.000000
135.630005,28.854774,-115.739433,-0.001380,0.003111,0.079013,128.352448,6.538585,0.790127,-115.739433,0.077920,0.000000
136.000000,26.581810,-115.739433,-0.001388,0.003087,0.078406,118.241798,6.023524,0.784056,-115.739433,0.077305,0.000000
136.370010,23.546234,-115.783913,-0.001393,0.003060,0.077721,104.738884,5.335653,0.777205,-115.783913,0.076680,0.000000
136.740005,21.054687,-115.872879,-0.001397,0.003041,0.077235,93.655930,4.771060,0.772349,-115.872879,0.076064,0.000000
137.110001,17.384583,-115.828400,-0.001380,0.003006,0.076350,77.330482,3.939403,0.763504,-115.828400,0.075448,0.000000
137.480011,15.433723,-115.917358,-0.001384,0.002986,0.075856,68.652634,3.497332,0.758561,-115.917358,0.074833,0.000000
137.850006,12.870682,-115.917358,-0.001388,0.002962,0.075232,57.251652,2.916538,0.752316,-115.917358,0.074217,0.000000
138.220001,10.096886,-115.872879,-0.001393,0.002937,0.074607,44.913189,2.287987,0.746075,-115.872879,0.073601,0.000000
138.590012,7.604225,-115.961838,-0.001397,0.002913,0.073983,33.825283,1.723142,0.739830,-115.961838,0.072986,0.000000
138.960007,5.861893,-116.006317,-0.001384,0.002898,0.073601,26.075001,1.328324,0.736014,-116.006317,0.072370,0.000000
139.330002,2.816254,-116.050804,-0.001397,0.002867,0.072829,12.527322,0.638172,0.728293,-116.050804,0.071754,0.000000
139.700012,0.335510,-116.050804,-0.001393,0.002842,0.072196,1.492424,0.076028,0.721965,-116.050804,0.071130,0.000000
140.070007,-1.888298,-116.006317,-0.001375,0.002817,0.071563,-8.399570,-0.427894,0.715633,-116.006317,0.070514,0.000000
140.440002,-0.487434,-116.095284,-0.001388,0.002793,0.070930,-2.168216,-0.110454,0.709304,-116.095284,0.069898,0.000000
140.810013,-0.126602,-116.184242,-0.001388,0.002767,0.070280,-0.563155,-0.028688,0.702798,-116.184242,0.069283,0.000000
141.180008,-0.055481,-116.228722,-0.001388,0.002741,0.069630,-0.246792,-0.012572,0.696296,-116.228722,0.068667,0.000000
141.550003,-0.019363,-116.184242,-0.001406,0.002719,0.069057,-0.086133,-0.004388,0.690569,-116.184242,0.068051,0.000000
141.920013,-0.055855,-116.228722,-0.001418,0.002693,0.068398,-0.248455,-0.012657,0.683980,-116.228722,0.067435,0.000000
142.290009,-0.018242,-116.317688,-0.001453,0.002680,0.068068,-0.081144,-0.004134,0.680683,-116.317688,0.066820,0.000000
142.660004,-0.031647,-116.317688,-0.001479,0.002650,0.067314,-0.140772,-0.007171,0.673140,-116.317688,0.066204,0.000000
143.030014,-0.080055,-116.362167,-0.001535,0.002621,0.066585,-0.356103,-0.018141,0.665854,-116.362167,0.065579,0.000000
143.400009,-0.048409,-116.406647,-0.001565,0.002597,0.065953,-0.215332,-0.010970,0.659526,-116.406647,0.064964,0.000000
143.770004,-0.081177,-116.406647,-0.001591,0.002576,0.065441,-0.361092,-0.018395,0.654408,-116.406647,0.064348,0.000000
144.139999,-0.076332,-116.362167,-0.001638,0.002550,0.064764,-0.339542,-0.017297,0.647645,-116.362167,0.063732,0.000000
144.510010,-0.073723,-116.451126,-0.001669,0.002525,0.064140,-0.327936,-0.016706,0.641400,-116.451126,0.063117,0.000000
144.880005,-0.077820,-116.540092,-0.001712,0.002498,0.063455,-0.346160,-0.017634,0.634549,-116.540092,0.062501,0.000000
145.250000,-0.096069,-116.584572,-0.001716,0.002483,0.063056,-0.427338,-0.021770,0.630560,-116.584572,0.061885,0.000000
145.620010,-0.099419,-116.540092,-0.001733,0.002455,0.062353,-0.442236,-0.022529,0.623535,-116.540092,0.061269,0.000000
145.990005,-0.087502,-116.584572,-0.001763,0.002433,0.061807,-0.389226,-0.019828,0.618070,-116.584572,0.060654,0.000000
146.360001,-0.080055,-116.584572,-0.001789,0.002411,0.061243,-0.356103,-0.018141,0.612434,-116.584572,0.060029,0.000000
146.730011,-0.074844,-116.673538,-0.001815,0.002375,0.060333,-0.332924,-0.016960,0.603327,-116.673538,0.059413,0.000000
147.100006,-0.072235,-116.673538,-0.001832,0.002359,0.059916,-0.321318,-0.016369,0.599164,-116.673538,0.058798,0.000000
147.470001,-0.085640,-116.762497,-0.001858,0.002333,0.059266,-0.380946,-0.019406,0.592662,-116.762497,0.058182,0.000000
147.840012,-0.081543,-116.718018,-0.001880,0.002310,0.058668,-0.362721,-0.018478,0.586678,-116.718018,0.057566,0.000000
148.210007,-0.087128,-116.762497,-0.001910,0.002291,0.058191,-0.387563,-0.019743,0.581909,-116.762497,0.056951,0.000000
148.580002,-0.116173,-116.851456,-0.001953,0.002258,0.057349,-0.516762,-0.026325,0.573495,-116.851456,0.056335,0.000000
148.950012,-0.124741,-116.851456,-0.001966,0.002235,0.056760,-0.554874,-0.028267,0.567598,-116.851456,0.055719,0.000000
149.320007,-0.136284,-116.851456,-0.001983,0.002209,0.056110,-0.606221,-0.030882,0.561096,-116.851456,0.055104,0.000000
149.690002,-0.102768,-116.851456,-0.002022,0.002188,0.055580,-0.457135,-0.023288,0.555804,-116.851456,0.054479,0.000000
150.060013,-0.106125,-116.940422,-0.002048,0.002168,0.055060,-0.472067,-0.024048,0.550600,-116.940422,0.053863,0.000000
150.430008,-0.119904,-116.984901,-0.002061,0.002136,0.054245,-0.533358,-0.027171,0.542447,-116.984901,0.053247,0.000000
150.800003,-0.125488,-117.073860,-0.002104,0.002111,0.053612,-0.558200,-0.028436,0.536119,-117.073860,0.052632,0.000000
151.170013,-0.117668,-117.029381,-0.002113,0.002087,0.053014,-0.523414,-0.026664,0.530135,-117.029381,0.052016,0.000000
151.540009,-0.118408,-117.073860,-0.002130,0.002064,0.052424,-0.526706,-0.026832,0.524238,-117.073860,0.051400,0.000000
151.910004,-0.107986,-117.073860,-0.002182,0.002035,0.051678,-0.480348,-0.024470,0.516778,-117.073860,0.050785,0.000000
152.280014,-0.124741,-117.207306,-0.002212,0.002010,0.051053,-0.554874,-0.028267,0.510533,-117.207306,0.050169,0.000000
152.500000,-0.081917,-117.162827,-0.002199,0.002010,0.051062,-0.364384,-0.018563,0.510620,-117.162827,0.050871,0.000000