File: Data/compression 16/ManualNoHeating-17-16-reverse-hand-2_08302024_171130.csv
Time (sec),S:Load (lbs),S:HL1 (DIM),S:LVDT (in),S:Position (in),Ch:Position (mm),Ch:Load (N),Ch:Stress (MPa),Ch:Strain (mm/mm),Ch:HL1 (DIM),Set Point (),Cycles ()
0.210000,0.003731,-66.632462,-0.013999,-0.008891,-0.225834,0.016595,0.000845,-2.258341,-66.632462,-0.225582,0.000000
0.590000,-0.056595,-66.721428,-0.013995,-0.008791,-0.223302,-0.251746,-0.012825,-2.233016,-66.721428,-0.222530,0.000000
0.970000,-0.074844,-66.765907,-0.013840,-0.008562,-0.217465,-0.332924,-0.016960,-2.174653,-66.765907,-0.216199,0.000000
1.350000,-0.085266,-66.721428,-0.013603,-0.008310,-0.211074,-0.379283,-0.019322,-2.110738,-66.721428,-0.209868,0.000000
1.730000,-0.075584,-66.765907,-0.013318,-0.008065,-0.204847,-0.336216,-0.017128,-2.048472,-66.765907,-0.203538,0.000000
2.110000,-0.037605,-66.810387,-0.013055,-0.007814,-0.198464,-0.167277,-0.008521,-1.984644,-66.810387,-0.197207,0.000000
2.490000,-0.022713,-66.899353,-0.012788,-0.007564,-0.192134,-0.101031,-0.005147,-1.921338,-66.899353,-0.190876,0.000000
2.870000,-0.039841,-66.899353,-0.012542,-0.007316,-0.185820,-0.177220,-0.009028,-1.858202,-66.899353,-0.184545,0.000000
3.250000,-0.043938,-66.899353,-0.012305,-0.007062,-0.179385,-0.195445,-0.009956,-1.793855,-66.899353,-0.178215,0.000000
3.630000,-0.055107,-66.988312,-0.012033,-0.006815,-0.173089,-0.245129,-0.012487,-1.730893,-66.988312,-0.171884,0.000000
4.010000,-0.038353,-67.032791,-0.011758,-0.006566,-0.166767,-0.170603,-0.008691,-1.667674,-67.032791,-0.165553,0.000000
4.390000,-0.041328,-67.077271,-0.011499,-0.006316,-0.160428,-0.183838,-0.009365,-1.604281,-67.077271,-0.159223,0.000000
4.770000,-0.037605,-67.166237,-0.011240,-0.006067,-0.154097,-0.167277,-0.008521,-1.540971,-67.166237,-0.152892,0.000000
5.150000,-0.066650,-67.121758,-0.010994,-0.005823,-0.147905,-0.296476,-0.015103,-1.479050,-67.121758,-0.146561,0.000000
5.530000,-0.090485,-67.121758,-0.010723,-0.005573,-0.141548,-0.402496,-0.020504,-1.415483,-67.121758,-0.140230,0.000000
5.910000,-0.120270,-67.210716,-0.010477,-0.005324,-0.135226,-0.534987,-0.027254,-1.352263,-67.210716,-0.133899,0.000000
6.290000,-0.049896,-67.299683,-0.010205,-0.005067,-0.128705,-0.221950,-0.011307,-1.287050,-67.299683,-0.127569,0.000000
6.670001,-0.061440,-67.299683,-0.009960,-0.004817,-0.122357,-0.273297,-0.013922,-1.223566,-67.299683,-0.121238,0.000000
7.050000,-0.052132,-67.344162,-0.009722,-0.004577,-0.116252,-0.231893,-0.011813,-1.162515,-67.344162,-0.114907,0.000000
7.430000,-0.079315,-67.344162,-0.009451,-0.004324,-0.109834,-0.352812,-0.017973,-1.098339,-67.344162,-0.108577,0.000000
7.810000,-0.114311,-67.388641,-0.009162,-0.004070,-0.103373,-0.508482,-0.025903,-1.033731,-67.388641,-0.102246,0.000000
8.190001,-0.088997,-67.433121,-0.008929,-0.003822,-0.097077,-0.395878,-0.020167,-0.970769,-67.433121,-0.095915,0.000000
8.570001,-0.045425,-67.522087,-0.008658,-0.003572,-0.090738,-0.202062,-0.010294,-0.907376,-67.522087,-0.089584,0.000000
8.950001,-0.018616,-67.522087,-0.008429,-0.003329,-0.084545,-0.082807,-0.004218,-0.845455,-67.522087,-0.083253,0.000000
9.330001,-0.029785,-67.522087,-0.008140,-0.003075,-0.078102,-0.132491,-0.006749,-0.781021,-67.522087,-0.076923,0.000000
9.710000,-0.055107,-67.611046,-0.007899,-0.002825,-0.071763,-0.245129,-0.012487,-0.717627,-67.611046,-0.070592,0.000000
10.090000,-0.076332,-67.700005,-0.007631,-0.002578,-0.065484,-0.339542,-0.017297,-0.654840,-67.700005,-0.064261,0.000000
10.470000,-0.039093,-67.700005,-0.007373,-0.002330,-0.059179,-0.173894,-0.008859,-0.591795,-67.700005,-0.057930,0.000000
10.850000,0.002609,-67.744492,-0.007118,-0.002077,-0.052753,0.011607,0.000591,-0.527531,-67.744492,-0.051600,0.000000
11.230000,-0.034256,-67.700005,-0.006868,-0.001833,-0.046570,-0.152378,-0.007763,-0.465697,-67.700005,-0.045269,0.000000
11.610001,-0.044678,-67.744492,-0.006597,-0.001582,-0.040179,-0.198736,-0.010124,-0.401786,-67.744492,-0.038938,0.000000
11.990001,-0.049896,-67.788971,-0.006351,-0.001331,-0.033804,-0.221950,-0.011307,-0.338044,-67.788971,-0.032608,0.000000
12.370001,-0.047287,-67.788971,-0.006092,-0.001085,-0.027569,-0.210343,-0.010715,-0.275688,-67.788971,-0.026277,0.000000
12.750001,-0.008186,-67.833450,-0.005842,-0.000832,-0.021134,-0.036415,-0.001855,-0.211341,-67.833450,-0.019946,0.000000
13.130001,-0.007072,-67.922409,-0.005553,-0.000584,-0.014838,-0.031460,-0.001603,-0.148379,-67.922409,-0.013615,0.000000
13.510000,-0.018616,-67.922409,-0.005316,-0.000335,-0.008507,-0.082807,-0.004218,-0.085073,-67.922409,-0.007284,0.000000
13.890000,-0.030159,-68.011375,-0.005066,-0.000088,-0.002229,-0.134154,-0.006834,-0.022285,-68.011375,-0.000954,0.000000
14.270000,0.167198,-68.055855,-0.004876,-0.000000,-0.000009,0.743735,0.037888,-0.000087,-68.055855,0.000165,0.000000
14.650001,0.161613,-68.055855,-0.004894,-0.000000,-0.000009,0.718893,0.036622,-0.000087,-68.055855,0.000165,0.000000
15.030001,0.132195,-68.055855,-0.004876,-0.000000,-0.000009,0.588031,0.029956,-0.000087,-68.055855,0.000754,0.000000
15.410001,0.234222,-68.100334,-0.004876,0.000020,0.000503,1.041873,0.053076,0.005030,-68.100334,0.001388,0.000000
15.790001,0.402542,-68.233780,-0.004855,0.000045,0.001136,1.790597,0.091217,0.011358,-68.233780,0.002020,0.000000
16.170000,0.642715,-68.322739,-0.004825,0.000065,0.001648,2.858941,0.145641,0.016476,-68.322739,0.002654,0.000000
16.550001,0.942848,-68.278259,-0.004825,0.000083,0.002107,4.193998,0.213652,0.021074,-68.278259,0.003287,0.000000
16.930000,1.296608,-68.278259,-0.004790,0.000106,0.002697,5.767601,0.293816,0.026971,-68.278259,0.003920,0.000000
17.310001,1.929268,-68.322739,-0.004777,0.000141,0.003582,8.581812,0.437178,0.035816,-68.322739,0.004553,0.000000
17.690001,2.283394,-68.322739,-0.004738,0.000164,0.004163,10.157043,0.517424,0.041626,-68.322739,0.005186,0.000000
18.070002,2.641617,-68.411705,-0.004734,0.000185,0.004700,11.750499,0.598599,0.047001,-68.411705,0.005819,0.000000
18.450001,3.226982,-68.456184,-0.004704,0.000209,0.005298,14.354333,0.731245,0.052985,-68.456184,0.006452,0.000000
18.830002,3.762085,-68.456184,-0.004700,0.000233,0.005906,16.734591,0.852501,0.059056,-68.456184,0.007094,0.000000
19.210001,4.505341,-68.545143,-0.004652,0.000267,0.006790,20.040756,1.020925,0.067901,-68.545143,0.007727,0.000000
19.590000,4.934311,-68.589630,-0.004648,0.000292,0.007415,21.948912,1.118131,0.074146,-68.589630,0.008360,0.000000
19.970001,5.352859,-68.678589,-0.004626,0.000314,0.007987,23.810709,1.212975,0.079869,-68.678589,0.008993,0.000000
20.350000,5.946793,-68.634109,-0.004605,0.000338,0.008594,26.452654,1.347562,0.085940,-68.634109,0.009626,0.000000
20.730001,6.465508,-68.634109,-0.004592,0.000364,0.009245,28.760014,1.465105,0.092446,-68.634109,0.010259,0.000000
21.110001,7.023689,-68.723068,-0.004549,0.000391,0.009938,31.242929,1.591591,0.099384,-68.723068,0.010892,0.000000
21.490002,7.312279,-68.723068,-0.004544,0.000413,0.010493,32.526642,1.656986,0.104932,-68.723068,0.011525,0.000000
21.870001,7.784447,-68.856514,-0.004514,0.000441,0.011204,34.626949,1.763981,0.112044,-68.856514,0.012158,0.000000
22.250002,8.188843,-68.812035,-0.004506,0.000467,0.011872,36.425793,1.855618,0.118721,-68.812035,0.012791,0.000000
22.630001,8.507973,-68.900993,-0.004471,0.000489,0.012419,37.845352,1.927934,0.124186,-68.900993,0.013425,0.000000
23.010000,8.775703,-68.945473,-0.004454,0.000507,0.012887,39.036278,1.988603,0.128868,-68.945473,0.014057,0.000000
23.390001,9.404640,-68.945473,-0.004411,0.000541,0.013746,41.833927,2.131122,0.137456,-68.945473,0.014691,0.000000
23.770000,9.624718,-68.945473,-0.004393,0.000566,0.014387,42.812881,2.180992,0.143871,-68.945473,0.015324,0.000000
24.150002,9.929687,-69.078918,-0.004376,0.000591,0.015020,44.169456,2.250099,0.150204,-69.078918,0.015957,0.000000
24.530001,10.129280,-69.034439,-0.004363,0.000613,0.015567,45.057289,2.295328,0.155665,-69.034439,0.016590,0.000000
24.910002,10.600334,-69.078918,-0.004337,0.000639,0.016226,47.152641,2.402070,0.162258,-69.078918,0.017223,0.000000
25.290001,10.986855,-69.034439,-0.004303,0.000664,0.016876,48.871971,2.489657,0.168761,-69.034439,0.017856,0.000000
25.670002,11.291084,-69.167877,-0.004273,0.000692,0.017570,50.225250,2.558596,0.175699,-69.167877,0.018489,0.000000
26.050001,11.500359,-69.256844,-0.004268,0.000718,0.018229,51.156151,2.606019,0.182288,-69.256844,0.019122,0.000000
26.430000,11.504082,-69.167877,-0.004230,0.000735,0.018663,51.172710,2.606862,0.186626,-69.167877,0.019755,0.000000
26.810001,11.856346,-69.212357,-0.004234,0.000759,0.019270,52.739662,2.686686,0.192697,-69.212357,0.020388,0.000000
27.190001,12.031357,-69.256844,-0.004195,0.000780,0.019816,53.518147,2.726344,0.198158,-69.256844,0.021021,0.000000
27.570002,12.700142,-69.390282,-0.004165,0.000815,0.020692,56.493053,2.877893,0.206920,-69.390282,0.021655,0.000000
27.950001,12.960052,-69.390282,-0.004135,0.000842,0.021377,57.649193,2.936790,0.213771,-69.390282,0.022288,0.000000
28.330002,13.050545,-69.390282,-0.004126,0.000859,0.021828,58.051723,2.957296,0.218279,-69.390282,0.022921,0.000000
28.710001,13.337639,-69.390282,-0.004109,0.000884,0.022461,59.328781,3.022352,0.224611,-69.390282,0.023554,0.000000
29.090002,13.320137,-69.434761,-0.004074,0.000899,0.022843,59.250927,3.018386,0.228426,-69.434761,0.024187,0.000000
29.470001,13.929710,-69.434761,-0.004066,0.000934,0.023718,61.962448,3.156518,0.237184,-69.434761,0.024820,0.000000
29.850002,13.966202,-69.568207,-0.004044,0.000949,0.024100,62.124767,3.164787,0.240999,-69.568207,0.025462,0.000000
30.230001,14.724731,-69.568207,-0.004014,0.000987,0.025072,65.498878,3.336672,0.250715,-69.568207,0.026095,0.000000
30.610001,14.733292,-69.612686,-0.003984,0.001005,0.025531,65.536957,3.338612,0.255310,-69.612686,0.026728,0.000000
30.990002,15.145882,-69.612686,-0.003954,0.001037,0.026338,67.372246,3.432106,0.263376,-69.612686,0.027361,0.000000
31.370001,15.493675,-69.701653,-0.003949,0.001063,0.026988,68.919312,3.510917,0.269878,-69.701653,0.027994,0.000000
31.750002,15.387924,-69.746132,-0.003919,0.001080,0.027439,68.448906,3.486953,0.274390,-69.746132,0.028627,0.000000
32.130001,15.601662,-69.746132,-0.003902,0.001105,0.028072,69.399658,3.535387,0.280718,-69.746132,0.029260,0.000000
32.510002,16.277519,-69.790611,-0.003872,0.001131,0.028740,72.406021,3.688539,0.287398,-69.790611,0.029893,0.000000
32.890003,16.734795,-69.835091,-0.003846,0.001159,0.029451,74.440086,3.792159,0.294510,-69.835091,0.030526,0.000000
33.270000,16.835709,-69.879578,-0.003833,0.001187,0.030153,74.888969,3.815026,0.301535,-69.879578,0.031159,0.000000
33.650002,16.823044,-69.924057,-0.003811,0.001205,0.030596,74.832634,3.812156,0.305956,-69.924057,0.031792,0.000000
34.030003,17.273247,-70.013016,-0.003781,0.001234,0.031342,76.835236,3.914174,0.313416,-70.013016,0.032426,0.000000
34.410000,17.746902,-69.968536,-0.003760,0.001261,0.032027,78.942162,4.021505,0.320266,-69.968536,0.033058,0.000000
34.790001,17.722702,-70.013016,-0.003729,0.001284,0.032616,78.834518,4.016022,0.326163,-70.013016,0.033692,0.000000
35.170002,17.659393,-70.013016,-0.003721,0.001306,0.033162,78.552902,4.001676,0.331625,-70.013016,0.034325,0.000000
35.550003,17.831062,-70.101982,-0.003699,0.001330,0.033787,79.316528,4.040576,0.337870,-70.101982,0.034958,0.000000
35.930000,18.478615,-70.235420,-0.003695,0.001362,0.034594,82.196983,4.187314,0.345936,-70.235420,0.035591,0.000000
36.310001,18.445473,-70.101982,-0.003669,0.001384,0.035148,82.049561,4.179804,0.351484,-70.101982,0.036224,0.000000
36.690002,18.906471,-70.101982,-0.003630,0.001416,0.035972,84.100182,4.284267,0.359724,-70.101982,0.036857,0.000000
37.070004,18.888969,-70.235420,-0.003600,0.001441,0.036597,84.022331,4.280302,0.365969,-70.235420,0.037490,0.000000
37.450001,18.700920,-70.279900,-0.003587,0.001459,0.037056,83.185844,4.237689,0.370564,-70.279900,0.038123,0.000000
37.830002,18.919502,-70.324387,-0.003587,0.001481,0.037629,84.158150,4.287220,0.376287,-70.324387,0.038756,0.000000
38.210003,19.237137,-70.368866,-0.003553,0.001507,0.038288,85.571060,4.359198,0.382880,-70.368866,0.039389,0.000000
38.590000,19.711540,-70.368866,-0.003531,0.001538,0.039068,87.681313,4.466699,0.390684,-70.368866,0.040022,0.000000
38.970001,19.650841,-70.413345,-0.003505,0.001562,0.039676,87.411308,4.452944,0.396755,-70.413345,0.040655,0.000000
39.350002,19.675789,-70.457825,-0.003492,0.001581,0.040170,87.522278,4.458598,0.401698,-70.457825,0.041289,0.000000
39.730003,19.981506,-70.457825,-0.003484,0.001607,0.040820,88.882179,4.527874,0.408201,-70.457825,0.041921,0.000000
40.110001,20.148331,-70.502304,-0.003458,0.001633,0.041479,89.624252,4.565677,0.414794,-70.502304,0.042555,0.000000
40.490002,20.741150,-70.546791,-0.003445,0.001664,0.042277,92.261246,4.700012,0.422773,-70.546791,0.043188,0.000000
40.870003,20.725510,-70.635750,-0.003402,0.001689,0.042893,92.191673,4.696467,0.428927,-70.635750,0.043829,0.000000
41.250004,20.631302,-70.680229,-0.003393,0.001712,0.043483,91.772614,4.675120,0.434828,-70.680229,0.044463,0.000000
41.630001,20.804077,-70.680229,-0.003385,0.001736,0.044107,92.541161,4.714271,0.441069,-70.680229,0.045096,0.000000
42.010002,20.957123,-70.635750,-0.003367,0.001761,0.044731,93.221939,4.748952,0.447314,-70.635750,0.045729,0.000000
42.390003,21.120224,-70.724709,-0.003354,0.001786,0.045373,93.947449,4.785911,0.453733,-70.724709,0.046362,0.000000
42.770000,21.237892,-70.769196,-0.003316,0.001808,0.045919,94.470863,4.812575,0.459195,-70.769196,0.046995,0.000000
43.150002,21.669846,-70.858154,-0.003303,0.001836,0.046639,96.392288,4.910457,0.466394,-70.858154,0.047628,0.000000
43.530003,21.811348,-70.813675,-0.003277,0.001860,0.047255,97.021721,4.942522,0.472552,-70.813675,0.048261,0.000000
43.910004,22.102547,-70.858154,-0.003272,0.001887,0.047923,98.317039,5.008509,0.479228,-70.858154,0.048894,0.000000
44.290001,21.929390,-70.858154,-0.003238,0.001905,0.048391,97.546799,4.969271,0.483910,-70.858154,0.049527,0.000000
44.670002,22.502846,-70.947121,-0.003234,0.001936,0.049180,100.097656,5.099217,0.491802,-70.947121,0.050160,0.000000
45.050003,22.764252,-70.991600,-0.003229,0.001964,0.049874,101.260452,5.158453,0.498739,-70.991600,0.050793,0.000000
45.430000,22.882294,-70.991600,-0.003195,0.001988,0.050498,101.785522,5.185202,0.504984,-70.991600,0.051427,0.000000
45.810001,22.803345,-71.036079,-0.003191,0.002010,0.051045,101.434341,5.167312,0.510450,-71.036079,0.052059,0.000000
46.190002,23.357063,-71.036079,-0.003143,0.002037,0.051730,103.897408,5.292786,0.517301,-71.036079,0.052693,0.000000
46.570004,23.778961,-71.080559,-0.003134,0.002062,0.052372,105.774101,5.388390,0.523716,-71.080559,0.053326,0.000000
46.950001,24.000526,-71.169525,-0.003130,0.002090,0.053083,106.759674,5.438597,0.530828,-71.169525,0.053959,0.000000
47.330002,23.930893,-71.214005,-0.003122,0.002113,0.053672,106.449928,5.422818,0.536725,-71.214005,0.054592,0.000000
47.710003,23.993454,-71.214005,-0.003087,0.002133,0.054175,106.728210,5.436995,0.541755,-71.214005,0.055225,0.000000
48.090004,24.215385,-71.214005,-0.003061,0.002157,0.054783,107.715416,5.487285,0.547826,-71.214005,0.055858,0.000000
48.470001,24.315178,-71.302963,-0.003044,0.002178,0.055329,108.159317,5.509898,0.553287,-71.302963,0.056491,0.000000
48.850002,25.114288,-71.391930,-0.003040,0.002212,0.056196,111.713936,5.690979,0.561962,-71.391930,0.057124,0.000000
49.230003,25.097160,-71.391930,-0.003031,0.002237,0.056812,111.637741,5.687098,0.568120,-71.391930,0.057757,0.000000
49.610001,25.214462,-71.436409,-0.003001,0.002257,0.057323,112.159531,5.713679,0.573234,-71.436409,0.058390,0.000000
49.990002,25.382027,-71.436409,-0.002984,0.002278,0.057870,112.904892,5.751649,0.578699,-71.436409,0.059023,0.000000
50.370003,25.294518,-71.480888,-0.002971,0.002297,0.058347,112.515633,5.731820,0.583468,-71.480888,0.059656,0.000000
50.750004,26.201248,-71.525368,-0.002958,0.002328,0.059127,116.548973,5.937288,0.591273,-71.525368,0.060290,0.000000
51.130001,26.161774,-71.569847,-0.002936,0.002348,0.059639,116.373383,5.928343,0.596390,-71.569847,0.060922,0.000000
51.510002,27.196968,-71.569847,-0.002915,0.002382,0.060506,120.978157,6.162921,0.605061,-71.569847,0.061564,0.000000
51.890003,27.203300,-71.614334,-0.002893,0.002403,0.061044,121.006325,6.164356,0.610439,-71.614334,0.062197,0.000000
52.270004,27.559288,-71.703293,-0.002871,0.002431,0.061738,122.589836,6.245024,0.617377,-71.703293,0.062830,0.000000
52.650002,28.207214,-71.747772,-0.002867,0.002461,0.062501,125.471954,6.391846,0.625007,-71.747772,0.063464,0.000000
53.030003,27.846390,-71.703293,-0.002850,0.002478,0.062952,123.866928,6.310082,0.629519,-71.703293,0.064096,0.000000
53.410004,27.176491,-71.792252,-0.002824,0.002489,0.063221,120.887070,6.158281,0.632206,-71.792252,0.064730,0.000000
53.790001,29.008934,-71.792252,-0.002811,0.002530,0.064261,129.038177,6.573518,0.642615,-71.792252,0.065363,0.000000
54.170002,29.503448,-71.970177,-0.002798,0.002558,0.064972,131.237900,6.685577,0.649723,-71.970177,0.065996,0.000000
54.550003,29.564514,-71.970177,-0.002790,0.002579,0.065519,131.509521,6.699414,0.655188,-71.970177,0.066629,0.000000
54.930004,29.728729,-72.014656,-0.002759,0.002604,0.066135,132.239990,6.736627,0.661346,-72.014656,0.067262,0.000000
55.310001,30.539757,-71.925697,-0.002755,0.002631,0.066828,135.847626,6.920408,0.668284,-71.925697,0.067895,0.000000
55.690002,31.211517,-72.014656,-0.002729,0.002658,0.067522,138.835770,7.072631,0.675222,-72.014656,0.068528,0.000000
56.070004,31.429726,-72.059143,-0.002708,0.002681,0.068103,139.806396,7.122077,0.681031,-72.059143,0.069161,0.000000
56.450005,31.004478,-72.148102,-0.002708,0.002698,0.068519,137.914810,7.025715,0.685195,-72.148102,0.069794,0.000000
56.830002,31.885139,-72.192581,-0.002682,0.002729,0.069309,141.832184,7.225276,0.693086,-72.192581,0.070427,0.000000
57.210003,32.458221,-72.192581,-0.002669,0.002759,0.070080,144.381378,7.355138,0.700804,-72.192581,0.071060,0.000000
57.590004,33.017899,-72.192581,-0.002643,0.002782,0.070661,146.870941,7.481963,0.706613,-72.192581,0.071693,0.000000
57.970001,33.817757,-72.237068,-0.002626,0.002811,0.071399,150.428894,7.663213,0.713986,-72.237068,0.072327,0.000000
58.350002,34.058678,-72.281548,-0.002608,0.002836,0.072032,151.500565,7.717807,0.720318,-72.281548,0.072960,0.000000
58.730003,34.285080,-72.237068,-0.002604,0.002857,0.072578,152.507660,7.769110,0.725780,-72.237068,0.073593,0.000000
59.110004,34.796349,-72.281548,-0.002583,0.002880,0.073150,154.781891,7.884965,0.731503,-72.281548,0.074226,0.000000
59.490002,34.668999,-72.326027,-0.002552,0.002896,0.073549,154.215408,7.856107,0.735492,-72.326027,0.074859,0.000000
59.870003,36.178970,-72.414986,-0.002557,0.002933,0.074486,160.932098,8.198272,0.744860,-72.414986,0.075492,0.000000
60.250004,36.574425,-72.503952,-0.002548,0.002952,0.074989,162.691162,8.287884,0.749890,-72.503952,0.076125,0.000000
60.630001,37.268158,-72.459473,-0.002518,0.002979,0.075665,165.777039,8.445086,0.756653,-72.459473,0.076758,0.000000
61.010002,37.737343,-72.503952,-0.002492,0.003000,0.076212,167.864090,8.551404,0.762115,-72.503952,0.077391,0.000000
61.390003,37.995399,-72.592911,-0.002479,0.003021,0.076723,169.011978,8.609881,0.767232,-72.592911,0.078024,0.000000
61.770004,40.057968,-72.637390,-0.002458,0.003060,0.077721,178.186737,9.077265,0.777205,-72.637390,0.078657,0.000000
62.150002,40.532745,-72.681877,-0.002462,0.003084,0.078328,180.298660,9.184852,0.783276,-72.681877,0.079291,0.000000
62.530003,40.877563,-72.637390,-0.002436,0.003107,0.078917,181.832489,9.262988,0.789173,-72.637390,0.079932,0.000000
62.910004,40.915916,-72.681877,-0.002410,0.003131,0.079516,182.003082,9.271679,0.795157,-72.681877,0.080565,0.000000
63.290005,41.624168,-72.770836,-0.002397,0.003147,0.079932,185.153549,9.432171,0.799321,-72.770836,0.081198,0.000000
63.670002,42.839592,-72.859795,-0.002384,0.003178,0.080721,190.560028,9.707590,0.807212,-72.859795,0.081831,0.000000
64.050003,43.500557,-72.859795,-0.002371,0.003198,0.081242,193.500137,9.857368,0.812416,-72.859795,0.082465,0.000000
64.430000,45.179207,-72.859795,-0.002341,0.003233,0.082109,200.967148,10.237755,0.821088,-72.859795,0.083097,0.000000
64.810005,45.719894,-72.859795,-0.002320,0.003257,0.082733,203.372253,10.360276,0.827333,-72.859795,0.083731,0.000000
65.190002,46.697372,-72.948761,-0.002324,0.003283,0.083392,207.720291,10.581776,0.833922,-72.948761,0.084364,0.000000
65.570000,46.887657,-72.993240,-0.002311,0.003300,0.083826,208.566711,10.624895,0.838260,-72.993240,0.084997,0.000000
65.950005,48.644135,-72.993240,-0.002285,0.003333,0.084659,216.379913,11.022919,0.846586,-72.993240,0.085630,0.000000
66.330002,49.874825,-72.993240,-0.002264,0.003360,0.085335,221.854294,11.301797,0.853350,-72.993240,0.086263,0.000000
66.710007,50.682877,-73.082199,-0.002246,0.003383,0.085916,225.448700,11.484904,0.859160,-73.082199,0.086896,0.000000
67.090004,50.966995,-73.126686,-0.002238,0.003399,0.086332,226.712524,11.549287,0.863323,-73.126686,0.087529,0.000000
67.470001,52.682144,-73.171165,-0.002225,0.003432,0.087182,234.341888,11.937944,0.871820,-73.171165,0.088162,0.000000
67.850006,53.926987,-73.171165,-0.002203,0.003458,0.087824,239.879211,12.220030,0.878239,-73.171165,0.088795,0.000000
68.230003,53.315552,-73.171165,-0.002195,0.003463,0.087962,237.159424,12.081477,0.879625,-73.171165,0.089428,0.000000
68.610001,56.135895,-73.260124,-0.002164,0.003509,0.089116,249.704926,12.720575,0.891161,-73.260124,0.090061,0.000000
68.990005,57.157684,-73.304604,-0.002160,0.003531,0.089680,254.250076,12.952117,0.896797,-73.304604,0.090694,0.000000
69.370003,57.732628,-73.304604,-0.002139,0.003547,0.090087,256.807556,13.082401,0.900873,-73.304604,0.091328,0.000000
69.750000,59.496185,-73.349091,-0.002143,0.003576,0.090842,264.652252,13.482028,0.908416,-73.349091,0.091960,0.000000
70.130005,61.202766,-73.349091,-0.002121,0.003607,0.091614,272.243500,13.868745,0.916138,-73.349091,0.092594,0.000000
70.510002,62.405907,-73.438049,-0.002113,0.003630,0.092212,277.595337,14.141380,0.922122,-73.438049,0.093226,0.000000
70.890007,63.566963,-73.438049,-0.002087,0.003653,0.092793,282.759979,14.404480,0.927931,-73.438049,0.093860,0.000000
71.270004,64.664711,-73.571495,-0.002070,0.003677,0.093392,287.643005,14.653234,0.933915,-73.571495,0.094493,0.000000
71.650002,65.650764,-73.571495,-0.002074,0.003696,0.093877,292.029175,14.876676,0.938771,-73.571495,0.095126,0.000000
72.030006,65.369240,-73.527016,-0.002048,0.003699,0.093946,290.776886,14.812881,0.939464,-73.527016,0.016492,0.000000
72.410004,64.780159,-73.571495,-0.002048,0.003708,0.094181,288.156525,14.679395,0.941807,-73.571495,294.500488,0.000000
72.790001,64.979744,-73.704933,-0.002035,0.003719,0.094458,289.044342,14.724620,0.944581,-73.704933,294.500488,0.000000
73.170006,65.581871,-73.704933,-0.002022,0.003728,0.094692,291.722717,14.861064,0.946924,-73.704933,294.500488,0.000000
73.550003,64.700096,-73.749420,-0.002035,0.003728,0.094701,287.800415,14.661251,0.947011,-73.749420,294.500488,0.000000
73.930000,66.061852,-73.749420,-0.002005,0.003725,0.094623,293.857788,14.969830,0.946228,-73.749420,294.500488,0.000000
74.310005,65.283974,-73.704933,-0.002013,0.003732,0.094805,290.397614,14.793560,0.948052,-73.704933,294.500488,0.000000
74.690002,64.891487,-73.882858,-0.001988,0.003759,0.095490,288.651764,14.704621,0.954903,-73.882858,294.500488,0.000000
75.070007,65.314140,-73.882858,-0.001992,0.003762,0.095542,290.531799,14.800396,0.955421,-73.882858,294.500488,0.000000
75.450005,65.231834,-73.971825,-0.001996,0.003767,0.095690,290.165680,14.781745,0.956897,-73.971825,294.500488,0.000000
75.830002,65.432915,-73.971825,-0.001988,0.003774,0.095854,291.060150,14.827311,0.958544,-73.971825,294.500488,0.000000
76.210007,65.129433,-73.882858,-0.001979,0.003776,0.095915,289.710175,14.758540,0.959149,-73.882858,294.500488,0.000000
76.590004,65.049370,-74.016304,-0.001962,0.003781,0.096045,289.354034,14.740397,0.960451,-74.016304,294.500488,0.000000
76.970001,65.126091,-74.105263,-0.001970,0.003784,0.096106,289.695312,14.757783,0.961057,-74.105263,294.500488,0.000000
77.350006,65.028526,-74.105263,-0.001979,0.003787,0.096193,289.261322,14.735675,0.961927,-74.105263,294.500488,0.000000
77.730003,65.324181,-74.194229,-0.001962,0.003794,0.096357,290.576477,14.802671,0.963574,-74.194229,294.500488,0.000000
78.110001,65.142464,-74.149742,-0.001966,0.003796,0.096409,289.768158,14.761494,0.964092,-74.149742,294.500488,0.000000
78.490005,65.239281,-74.238708,-0.001962,0.003801,0.096539,290.198822,14.783432,0.965394,-74.238708,294.500488,0.000000
78.870003,65.102623,-74.238708,-0.001957,0.003801,0.096557,289.590942,14.752465,0.965568,-74.238708,294.500488,0.000000
79.250000,65.389351,-74.283188,-0.001957,0.003808,0.096721,290.866364,14.817439,0.967215,-74.283188,294.500488,0.000000
79.630005,65.218437,-74.283188,-0.001957,0.003808,0.096721,290.106110,14.778709,0.967215,-74.283188,294.500488,0.000000
80.010002,65.467186,-74.327667,-0.001936,0.003814,0.096886,291.212585,14.835076,0.968865,-74.327667,294.500488,0.000000
80.390007,65.293648,-74.372147,-0.001940,0.003814,0.096886,290.440643,14.795753,0.968865,-74.372147,294.500488,0.000000
80.770004,65.584099,-74.416634,-0.001936,0.003821,0.097042,291.732635,14.861569,0.970424,-74.416634,294.500488,0.000000
81.150002,65.445961,-74.505592,-0.001940,0.003821,0.097042,291.118164,14.830267,0.970424,-74.505592,294.500488,0.000000
81.530006,65.250084,-74.461113,-0.001932,0.003821,0.097042,290.246857,14.785880,0.970424,-74.461113,294.500488,0.000000
81.910004,65.282478,-74.461113,-0.001940,0.003824,0.097138,290.390961,14.793221,0.971378,-74.461113,294.500488,0.000000
82.290001,65.155876,-74.550072,-0.001927,0.003824,0.097138,289.827820,14.764533,0.971378,-74.550072,294.500488,0.000000
82.670006,65.384880,-74.550072,-0.001932,0.003830,0.097285,290.846466,14.816426,0.972854,-74.550072,294.500488,0.000000
83.050003,65.295891,-74.639038,-0.001923,0.003830,0.097285,290.450623,14.796261,0.972854,-74.639038,294.500488,0.000000
83.430000,65.125343,-74.683517,-0.001936,0.003830,0.097285,289.691986,14.757614,0.972854,-74.683517,294.500488,0.000000
83.810005,64.993523,-74.772476,-0.001944,0.003833,0.097355,289.105621,14.727742,0.973547,-74.772476,294.500488,0.000000
84.190002,65.325676,-74.683517,-0.001923,0.003836,0.097441,290.583130,14.803010,0.974414,-74.683517,294.500488,0.000000
84.570007,65.212852,-74.816963,-0.001923,0.003836,0.097441,290.081268,14.777444,0.974414,-74.816963,294.500488,0.000000
84.950005,65.076561,-74.861443,-0.001936,0.003840,0.097528,289.475006,14.746559,0.975280,-74.861443,294.500488,0.000000
85.330002,65.296638,-74.905922,-0.001932,0.003841,0.097554,290.453949,14.796430,0.975542,-74.905922,294.500488,0.000000
85.710007,65.201302,-74.861443,-0.001932,0.003841,0.097554,290.029877,14.774826,0.975542,-74.861443,294.500488,0.000000
86.090004,65.233696,-74.905922,-0.001906,0.003843,0.097623,290.173981,14.782166,0.976234,-74.905922,294.500488,0.000000
86.470001,65.132042,-74.950401,-0.001919,0.003843,0.097623,289.721802,14.759132,0.976234,-74.950401,294.500488,0.000000
86.850006,65.286201,-75.039368,-0.001919,0.003848,0.097736,290.407532,14.794065,0.977362,-75.039368,294.500488,0.000000
87.230003,65.247856,-74.994881,-0.001923,0.003848,0.097736,290.236969,14.785376,0.977362,-74.994881,294.500488,0.000000
87.610001,65.262749,-75.039368,-0.001923,0.003852,0.097832,290.303192,14.788750,0.978316,-75.039368,294.500488,0.000000
87.990005,65.317116,-75.039368,-0.001910,0.003852,0.097832,290.545044,14.801069,0.978316,-75.039368,294.500488,0.000000
88.370003,65.265358,-75.128326,-0.001914,0.003852,0.097840,290.314819,14.789341,0.978403,-75.128326,294.500488,0.000000
88.750008,65.295891,-75.261772,-0.001901,0.003854,0.097901,290.450623,14.796261,0.979008,-75.261772,294.500488,0.000000
89.130005,65.267586,-75.306252,-0.001906,0.003855,0.097910,290.324707,14.789846,0.979096,-75.306252,294.500488,0.000000
89.510002,65.247475,-75.217285,-0.001906,0.003856,0.097936,290.235260,14.785289,0.979357,-75.217285,294.500488,0.000000
89.890007,65.256416,-75.306252,-0.001910,0.003858,0.098005,290.275024,14.787314,0.980049,-75.306252,294.500488,0.000000
90.270004,65.280617,-75.306252,-0.001884,0.003858,0.098005,290.382690,14.792799,0.980049,-75.306252,294.500488,0.000000
90.650002,65.242271,-75.395210,-0.001914,0.003859,0.098014,290.212128,14.784110,0.980136,-75.395210,294.500488,0.000000
91.030006,65.161827,-75.439690,-0.001901,0.003859,0.098022,289.854279,14.765881,0.980223,-75.439690,294.500488,0.000000
91.410004,65.285088,-75.439690,-0.001901,0.003862,0.098100,290.402588,14.793813,0.981003,-75.439690,294.500488,0.000000
91.790001,65.254921,-75.484177,-0.001897,0.003862,0.098100,290.268372,14.786977,0.981003,-75.484177,294.500488,0.000000
92.170006,65.184181,-75.484177,-0.001893,0.003862,0.098100,289.953705,14.770947,0.981003,-75.484177,294.500488,0.000000
92.550003,65.250465,-75.573135,-0.001897,0.003865,0.098170,290.248566,14.785967,0.981700,-75.573135,294.500488,0.000000
92.930008,65.234444,-75.662094,-0.001910,0.003865,0.098170,290.177307,14.782336,0.981700,-75.662094,294.500488,0.000000
93.310005,65.162575,-75.662094,-0.001906,0.003866,0.098187,289.857605,14.766050,0.981874,-75.662094,294.500488,0.000000
93.690002,65.197212,-75.617615,-0.001897,0.003867,0.098222,290.011688,14.773900,0.982218,-75.617615,294.500488,0.000000
94.070007,65.152519,-75.662094,-0.001897,0.003867,0.098231,289.812866,14.763772,0.982305,-75.662094,294.500488,0.000000
94.450005,65.156624,-75.795540,-0.001893,0.003868,0.098257,289.831146,14.764703,0.982566,-75.795540,294.500488,0.000000
94.830002,65.129066,-75.795540,-0.001888,0.003869,0.098265,289.708557,14.758457,0.982653,-75.795540,294.500488,0.000000
95.210007,65.183052,-75.795540,-0.001893,0.003870,0.098300,289.948700,14.770691,0.982998,-75.795540,294.500488,0.000000
95.590004,65.126457,-75.751060,-0.001906,0.003870,0.098308,289.696960,14.757866,0.983085,-75.751060,294.500488,0.000000
95.970001,65.126091,-75.840019,-0.001884,0.003872,0.098343,289.695312,14.757783,0.983433,-75.840019,294.500488,0.000000
96.350006,65.133537,-75.928986,-0.001893,0.003872,0.098352,289.728455,14.759470,0.983520,-75.928986,294.500488,0.000000
96.730003,65.091087,-75.928986,-0.001893,0.003873,0.098378,289.539612,14.749851,0.983781,-75.928986,294.500488,0.000000
97.110008,65.113426,-76.017944,-0.001897,0.003874,0.098395,289.638977,14.754913,0.983952,-76.017944,294.500488,0.000000
97.490005,65.072456,-76.062424,-0.001876,0.003874,0.098395,289.456757,14.745629,0.983952,-76.062424,294.500488,0.000000
97.870003,65.078423,-76.062424,-0.001884,0.003875,0.098430,289.483276,14.746982,0.984300,-76.062424,294.500488,0.000000
98.250008,65.089592,-76.106911,-0.001876,0.003876,0.098447,289.532959,14.749513,0.984474,-76.106911,294.500488,0.000000
98.630005,65.091087,-76.195869,-0.001884,0.003877,0.098465,289.539612,14.749851,0.984648,-76.195869,294.500488,0.000000
99.010002,65.059425,-76.240349,-0.001888,0.003877,0.098465,289.398773,14.742677,0.984648,-76.240349,294.500488,0.000000
99.390007,65.019966,-76.329315,-0.001884,0.003877,0.098465,289.223267,14.733735,0.984648,-76.329315,294.500488,0.000000
99.770004,64.967079,-76.195869,-0.001901,0.003877,0.098474,288.988007,14.721750,0.984735,-76.195869,294.500488,0.000000
100.150002,64.936928,-76.284828,-0.001876,0.003877,0.098474,288.853882,14.714918,0.984735,-76.284828,294.500488,0.000000
100.530006,65.496590,-76.329315,-0.001871,0.003885,0.098673,291.343384,14.841740,0.986730,-76.329315,294.500488,0.000000
100.910004,65.537560,-76.373795,-0.001897,0.003884,0.098664,291.525635,14.851024,0.986643,-76.373795,294.500488,0.000000
101.290009,65.498085,-76.373795,-0.001893,0.003884,0.098664,291.350037,14.842078,0.986643,-76.373795,294.500488,0.000000
101.670006,65.463448,-76.373795,-0.001876,0.003884,0.098664,291.195953,14.834229,0.986643,-76.373795,294.500488,0.000000
102.050003,65.382652,-76.418274,-0.001884,0.003884,0.098664,290.836548,14.815921,0.986643,-76.418274,294.500488,0.000000
102.430008,65.326790,-76.551720,-0.001893,0.003885,0.098673,290.588074,14.803262,0.986730,-76.551720,294.500488,0.000000
102.810005,65.297752,-76.596199,-0.001880,0.003885,0.098673,290.458923,14.796682,0.986730,-76.596199,294.500488,0.000000
103.190002,65.261253,-76.596199,-0.001876,0.003885,0.098673,290.296539,14.788412,0.986730,-76.596199,294.500488,0.000000
103.570007,65.200188,-76.596199,-0.001880,0.003885,0.098673,290.024933,14.774573,0.986730,-76.596199,294.500488,0.000000
103.950005,65.145821,-76.640678,-0.001876,0.003885,0.098673,289.783081,14.762254,0.986730,-76.640678,294.500488,0.000000
104.330002,65.089226,-76.685158,-0.001880,0.003885,0.098682,289.531342,14.749430,0.986817,-76.685158,294.500488,0.000000
104.710007,65.050865,-76.774124,-0.001871,0.003885,0.098682,289.360687,14.740736,0.986817,-76.774124,294.500488,0.000000
105.090004,65.019966,-76.729637,-0.001876,0.003887,0.098725,289.223267,14.733735,0.987248,-76.729637,294.500488,0.000000
105.470001,65.029640,-76.818604,-0.001858,0.003887,0.098725,289.266296,14.735928,0.987248,-76.818604,294.500488,0.000000
105.850006,65.004326,-76.818604,-0.001876,0.003887,0.098725,289.153687,14.730190,0.987248,-76.818604,294.500488,0.000000
106.230003,64.972664,-76.907562,-0.001876,0.003887,0.098725,289.012848,14.723016,0.987248,-76.907562,294.500488,0.000000
106.610008,64.927986,-76.952042,-0.001871,0.003887,0.098725,288.814117,14.712892,0.987248,-76.952042,294.500488,0.000000
106.990005,64.885536,-76.907562,-0.001880,0.003887,0.098725,288.625275,14.703272,0.987248,-76.907562,294.500488,0.000000
107.370003,64.830421,-76.952042,-0.001871,0.003887,0.098725,288.380127,14.690784,0.987248,-76.952042,294.500488,0.000000
107.750008,65.382652,-77.041008,-0.001867,0.003894,0.098907,290.836548,14.815921,0.989069,-77.041008,294.500488,0.000000
108.130005,65.402382,-77.085487,-0.001871,0.003894,0.098907,290.924316,14.820392,0.989069,-77.085487,294.500488,0.000000
108.510002,65.370369,-77.129967,-0.001867,0.003894,0.098907,290.781921,14.813137,0.989069,-77.129967,294.500488,0.000000
108.890007,65.346153,-77.174454,-0.001876,0.003894,0.098907,290.674194,14.807650,0.989069,-77.174454,294.500488,0.000000
109.270004,65.305946,-77.129967,-0.001884,0.003894,0.098907,290.495361,14.798539,0.989069,-77.129967,294.500488,0.000000
109.650002,65.274666,-77.174454,-0.001871,0.003894,0.098907,290.356201,14.791451,0.989069,-77.174454,294.500488,0.000000
110.030006,65.241524,-77.218933,-0.001867,0.003894,0.098907,290.208801,14.783940,0.989069,-77.218933,294.500488,0.000000
110.410004,65.214333,-77.263412,-0.001876,0.003894,0.098907,290.087830,14.777779,0.989069,-77.263412,294.500488,0.000000
110.790009,65.174126,-77.307892,-0.001876,0.003894,0.098916,289.908997,14.768668,0.989156,-77.307892,294.500488,0.000000
111.170006,65.124229,-77.396858,-0.001880,0.003894,0.098916,289.687042,14.757361,0.989156,-77.396858,294.500488,0.000000
111.550003,65.078423,-77.396858,-0.001863,0.003894,0.098916,289.483276,14.746982,0.989156,-77.396858,294.500488,0.000000
111.930008,65.052727,-77.441338,-0.001858,0.003894,0.098916,289.368988,14.741158,0.989156,-77.441338,294.500488,0.000000
112.310005,65.016243,-77.441338,-0.001863,0.003894,0.098916,289.206696,14.732891,0.989156,-77.441338,294.500488,0.000000
112.690002,64.991661,-77.530296,-0.001893,0.003895,0.098924,289.097351,14.727321,0.989243,-77.530296,294.500488,0.000000
113.070007,64.946602,-77.485817,-0.001863,0.003895,0.098924,288.896912,14.717111,0.989243,-77.485817,294.500488,0.000000
113.450005,64.922401,-77.530296,-0.001871,0.003894,0.098916,288.789276,14.711626,0.989156,-77.530296,294.500488,0.000000
113.830002,64.859840,-77.619263,-0.001863,0.003894,0.098916,288.510986,14.697450,0.989156,-77.619263,294.500488,0.000000
114.210007,64.812920,-77.574776,-0.001858,0.003894,0.098916,288.302277,14.686818,0.989156,-77.574776,294.500488,0.000000
114.590004,64.783501,-77.574776,-0.001876,0.003894,0.098916,288.171417,14.680152,0.989156,-77.574776,294.500488,0.000000
114.970009,64.742912,-77.663742,-0.001871,0.003894,0.098916,287.990845,14.670954,0.989156,-77.663742,294.500488,0.000000
115.350006,64.713127,-77.708221,-0.001854,0.003894,0.098916,287.858368,14.664205,0.989156,-77.708221,294.500488,0.000000
115.730003,64.674019,-77.752701,-0.001863,0.003894,0.098916,287.684418,14.655342,0.989156,-77.752701,294.500488,0.000000
116.110008,64.649818,-77.797180,-0.001871,0.003894,0.098916,287.576752,14.649858,0.989156,-77.797180,294.500488,0.000000
116.490005,64.578331,-77.841667,-0.001867,0.003894,0.098916,287.258759,14.633659,0.989156,-77.841667,294.500488,0.000000
116.870003,65.927055,-77.886147,-0.001867,0.003907,0.099228,293.258179,14.939284,0.992278,-77.886147,294.500488,0.000000
117.250008,65.854439,-77.886147,-0.001863,0.003907,0.099228,292.935181,14.922830,0.992278,-77.886147,294.500488,0.000000
117.630005,65.835823,-77.975105,-0.001858,0.003907,0.099228,292.852356,14.918611,0.992278,-77.975105,294.500488,0.000000
118.010002,65.822792,-78.019585,-0.001863,0.003907,0.099228,292.794403,14.915658,0.992278,-78.019585,294.500488,0.000000
118.390007,65.765083,-78.064072,-0.001867,0.003907,0.099228,292.537689,14.902580,0.992278,-78.064072,294.500488,0.000000
118.770004,65.752037,-78.019585,-0.001871,0.003907,0.099228,292.479675,14.899625,0.992278,-78.019585,294.500488,0.000000
119.150009,65.677940,-78.064072,-0.001858,0.003907,0.099228,292.150055,14.882834,0.992278,-78.064072,294.500488,0.000000
119.530006,65.646294,-78.108551,-0.001850,0.003907,0.099228,292.009308,14.875662,0.992278,-78.108551,294.500488,0.000000
119.910004,65.605324,-78.197510,-0.001858,0.003907,0.099228,291.827057,14.866379,0.992278,-78.197510,294.500488,0.000000
120.290009,65.576286,-78.286476,-0.001858,0.003907,0.099228,291.697876,14.859798,0.992278,-78.286476,294.500488,0.000000
120.670006,65.553200,-78.241989,-0.001854,0.003907,0.099228,291.595184,14.854568,0.992278,-78.241989,294.500488,0.000000
121.050003,65.521172,-78.241989,-0.001867,0.003907,0.099228,291.452728,14.847310,0.992278,-78.241989,294.500488,0.000000
121.430008,65.508507,-78.286476,-0.001837,0.003907,0.099228,291.396393,14.844440,0.992278,-78.286476,294.500488,0.000000
121.810005,65.441490,-78.375435,-0.001854,0.003907,0.099228,291.098297,14.829253,0.992278,-78.375435,294.500488,0.000000
122.190002,65.406487,-78.375435,-0.001858,0.003907,0.099228,290.942596,14.821321,0.992278,-78.375435,294.500488,0.000000
122.570007,65.369621,-78.330956,-0.001850,0.003907,0.099228,290.778595,14.812967,0.992278,-78.330956,294.500488,0.000000
122.950005,65.331261,-78.330956,-0.001867,0.003907,0.099228,290.607971,14.804276,0.992278,-78.330956,294.500488,0.000000
123.330009,65.298866,-78.419914,-0.001845,0.003907,0.099228,290.463867,14.796934,0.992278,-78.419914,294.500488,0.000000
123.710007,65.278389,-78.553360,-0.001850,0.003907,0.099228,290.372772,14.792295,0.992278,-78.553360,294.500488,0.000000
124.090004,65.247475,-78.553360,-0.001854,0.003907,0.099228,290.235260,14.785289,0.992278,-78.553360,294.500488,0.000000
124.470009,65.213966,-78.553360,-0.001867,0.003907,0.099228,290.086212,14.777697,0.992278,-78.553360,294.500488,0.000000
124.850006,65.180824,-78.553360,-0.001845,0.003907,0.099228,289.938782,14.770185,0.992278,-78.553360,294.500488,0.000000
125.230003,65.132423,-78.686806,-0.001858,0.003907,0.099228,289.723480,14.759218,0.992278,-78.686806,294.500488,0.000000
125.610008,65.097786,-78.731285,-0.001854,0.003907,0.099228,289.569427,14.751369,0.992278,-78.731285,294.500488,0.000000
125.990005,65.063148,-78.731285,-0.001858,0.003907,0.099245,289.415344,14.743520,0.992452,-78.731285,294.500488,0.000000
126.370003,65.040810,-78.686806,-0.001854,0.003907,0.099245,289.315979,14.738459,0.992452,-78.686806,294.500488,0.000000
126.750008,65.011772,-78.820244,-0.001863,0.003907,0.099245,289.186798,14.731878,0.992452,-78.820244,294.500488,0.000000
127.130005,64.991661,-78.864723,-0.001832,0.003907,0.099245,289.097351,14.727321,0.992452,-78.864723,294.500488,0.000000
127.510010,64.968575,-78.864723,-0.001850,0.003907,0.099245,288.994659,14.722089,0.992452,-78.864723,294.500488,0.000000
127.890007,64.933189,-78.909210,-0.001850,0.003907,0.099245,288.837250,14.714071,0.992452,-78.909210,294.500488,0.000000
128.270004,64.907509,-78.864723,-0.001845,0.003907,0.099245,288.723022,14.708252,0.992452,-78.864723,294.500488,0.000000
128.650009,64.869896,-78.953690,-0.001863,0.003907,0.099245,288.555695,14.699728,0.992452,-78.953690,294.500488,0.000000
129.029999,64.844566,-79.042648,-0.001845,0.003907,0.099245,288.443024,14.693989,0.992452,-79.042648,294.500488,0.000000
129.410004,64.804359,-79.042648,-0.001850,0.003907,0.099245,288.264191,14.684877,0.992452,-79.042648,294.500488,0.000000
129.790009,64.772697,-79.087128,-0.001863,0.003907,0.099245,288.123352,14.677703,0.992452,-79.087128,294.500488,0.000000
130.170013,64.742546,-79.042648,-0.001850,0.003907,0.099245,287.989227,14.670871,0.992452,-79.042648,294.500488,0.000000
130.550003,64.724297,-79.131615,-0.001854,0.003907,0.099245,287.908051,14.666736,0.992452,-79.131615,294.500488,0.000000
130.930008,64.702324,-79.176094,-0.001841,0.003907,0.099245,287.810303,14.661756,0.992452,-79.176094,294.500488,0.000000
131.310013,65.785927,-79.176094,-0.001845,0.003919,0.099531,292.630432,14.907305,0.995314,-79.176094,294.500488,0.000000
131.690002,65.749809,-79.309532,-0.001845,0.003919,0.099531,292.469757,14.899120,0.995314,-79.309532,294.500488,0.000000
132.070007,65.740868,-79.265053,-0.001841,0.003919,0.099531,292.429993,14.897094,0.995314,-79.265053,294.500488,0.000000
132.450012,65.725975,-79.354019,-0.001850,0.003919,0.099531,292.363739,14.893719,0.995314,-79.354019,1681.640991,0.000000
132.830002,65.629539,-79.354019,-0.001841,0.003906,0.099210,291.934784,14.871866,0.992104,-79.354019,0.099002,0.000000
133.210007,65.525276,-79.442978,-0.001850,0.003887,0.098725,291.470978,14.848240,0.987248,-79.442978,0.098369,0.000000
133.590012,65.420265,-79.354019,-0.001850,0.003869,0.098265,291.003876,14.824444,0.982653,-79.354019,0.097736,0.000000
133.970001,65.380791,-79.398499,-0.001845,0.003846,0.097693,290.828278,14.815498,0.976931,-79.398499,0.097103,0.000000
134.350006,65.330894,-79.442978,-0.001841,0.003820,0.097025,290.606323,14.804193,0.970250,-79.442978,0.096470,0.000000
134.730011,65.267220,-79.487457,-0.001841,0.003793,0.096349,290.323090,14.789763,0.963487,-79.487457,0.095837,0.000000
135.110001,65.223640,-79.576424,-0.001845,0.003769,0.095724,290.129242,14.779888,0.957242,-79.576424,0.095204,0.000000
135.490005,65.168541,-79.620903,-0.001841,0.003746,0.095143,289.884155,14.767403,0.951432,-79.620903,0.094571,0.000000
135.870010,65.146187,-79.620903,-0.001837,0.003729,0.094709,289.784698,14.762337,0.947094,-79.620903,0.093938,0.000000
136.250000,65.060555,-79.665382,-0.001841,0.003697,0.093903,289.403809,14.742932,0.939032,-79.665382,0.093305,0.000000
136.630005,64.651680,-79.709862,-0.001837,0.003675,0.093357,287.585022,14.650280,0.933567,-79.709862,0.092672,0.000000
137.010010,63.829857,-79.798828,-0.001845,0.003652,0.092750,283.929382,14.464052,0.927496,-79.798828,0.092038,0.000000
137.389999,62.974144,-79.754349,-0.001828,0.003634,0.092316,280.122986,14.270145,0.923162,-79.754349,0.091406,0.000000
137.770004,61.511841,-79.754349,-0.001807,0.003606,0.091605,273.618347,13.938782,0.916051,-79.754349,0.090772,0.000000
138.150009,59.839142,-79.843307,-0.001828,0.003579,0.090903,266.177795,13.559744,0.909026,-79.843307,0.090139,0.000000
138.530014,58.110588,-79.887787,-0.001811,0.003554,0.090278,258.488800,13.168048,0.902781,-79.887787,0.089506,0.000000
138.910004,56.873940,-79.932266,-0.001828,0.003540,0.089914,252.987915,12.887818,0.899140,-79.932266,0.088873,0.000000
139.290009,54.769287,-79.932266,-0.001807,0.003515,0.089272,243.625961,12.410898,0.892720,-79.932266,0.088240,0.000000
139.670013,53.529663,-79.976753,-0.001815,0.003502,0.088942,238.111832,12.129995,0.889424,-79.976753,0.087607,0.000000
140.050003,50.692184,-80.021233,-0.001807,0.003472,0.088197,225.490097,11.487013,0.881968,-80.021233,0.086974,0.000000
140.430008,47.150925,-80.065712,-0.001807,0.003436,0.087286,209.737793,10.684552,0.872861,-80.065712,0.086341,0.000000
140.810013,45.220543,-80.110191,-0.001807,0.003419,0.086835,201.151016,10.247122,0.868353,-80.110191,0.085708,0.000000
141.190002,42.201347,-80.110191,-0.001798,0.003389,0.086089,187.720963,9.562962,0.860893,-80.110191,0.085075,0.000000
141.570007,40.222557,-80.154671,-0.001819,0.003375,0.085725,178.918869,9.114562,0.857252,-80.154671,0.084442,0.000000
141.950012,37.662872,-80.199158,-0.001811,0.003350,0.085083,167.532822,8.534530,0.850833,-80.199158,0.083809,0.000000
142.330002,33.585762,-80.243637,-0.001807,0.003311,0.084095,149.396927,7.610642,0.840947,-80.243637,0.083175,0.000000
142.710007,31.396591,-80.288116,-0.001807,0.003289,0.083540,139.659012,7.114569,0.835398,-80.288116,0.082543,0.000000
143.090012,28.751625,-80.288116,-0.001811,0.003267,0.082985,127.893616,6.515211,0.829846,-80.288116,0.081901,0.000000
143.470001,25.940216,-80.332596,-0.001794,0.003241,0.082326,115.387840,5.878137,0.823256,-80.332596,0.081268,0.000000
143.850006,23.860512,-80.421562,-0.001807,0.003222,0.081849,106.136856,5.406869,0.818487,-80.421562,0.080635,0.000000
144.230011,19.963638,-80.466042,-0.001811,0.003184,0.080886,88.802696,4.523825,0.808859,-80.466042,0.080001,0.000000
144.610001,17.902924,-80.510521,-0.001811,0.003165,0.080392,79.636185,4.056860,0.803916,-80.510521,0.079368,0.000000
144.990005,16.834587,-80.555000,-0.001815,0.003156,0.080166,74.883980,3.814772,0.801663,-80.555000,0.078735,0.000000
145.370010,12.514694,-80.555000,-0.001815,0.003114,0.079091,55.668140,2.835870,0.790911,-80.555000,0.078102,0.000000
145.750000,10.551178,-80.599480,-0.001798,0.003096,0.078640,46.933983,2.390931,0.786399,-80.599480,0.077469,0.000000
146.130005,7.169662,-80.688446,-0.001815,0.003064,0.077816,31.892252,1.624669,0.778159,-80.688446,0.076836,0.000000
146.510010,4.746635,-80.643967,-0.001815,0.003041,0.077235,21.114088,1.075603,0.772349,-80.643967,0.076203,0.000000
146.889999,2.529900,-80.643967,-0.001815,0.003018,0.076663,11.253555,0.573283,0.766627,-80.643967,0.075570,0.000000
147.270004,0.059212,-80.688446,-0.001798,0.002995,0.076064,0.263387,0.013418,0.760643,-80.688446,0.074937,0.000000
147.650009,-2.243912,-80.777405,-0.001811,0.002968,0.075379,-9.981418,-0.508478,0.753792,-80.777405,0.074304,0.000000
148.030014,-0.321350,-80.777405,-0.001798,0.002935,0.074555,-1.429437,-0.072819,0.745552,-80.777405,0.073671,0.000000
148.410004,-0.025314,-80.866371,-0.001819,0.002916,0.074061,-0.112604,-0.005736,0.740609,-80.866371,0.073037,0.000000
148.790009,-0.028297,-80.866371,-0.001815,0.002892,0.073463,-0.125873,-0.006412,0.734625,-80.866371,0.072405,0.000000
149.170013,-0.010796,-80.910851,-0.001815,0.002866,0.072795,-0.048021,-0.002446,0.727949,-80.910851,0.071771,0.000000
149.550003,-0.030907,-80.955330,-0.001819,0.002841,0.072170,-0.137480,-0.007004,0.721704,-80.955330,0.071138,0.000000
149.930008,-0.059578,-80.999809,-0.001841,0.002820,0.071624,-0.265016,-0.013501,0.716242,-80.999809,0.070505,0.000000
150.310013,-0.080055,-81.044296,-0.001841,0.002790,0.070861,-0.356103,-0.018141,0.708608,-81.044296,0.069872,0.000000
150.690002,-0.056221,-80.999809,-0.001854,0.002764,0.070211,-0.250084,-0.012740,0.702106,-80.999809,0.069239,0.000000
151.070007,-0.070000,-81.044296,-0.001876,0.002743,0.069673,-0.311374,-0.015862,0.696727,-81.044296,0.068606,0.000000
151.450012,-0.060318,-81.088776,-0.001893,0.002723,0.069152,-0.268308,-0.013668,0.691523,-81.088776,0.067973,0.000000
151.830002,-0.080429,-81.177734,-0.001914,0.002690,0.068329,-0.357766,-0.018225,0.683287,-81.177734,0.067340,0.000000
152.210007,-0.072235,-81.222214,-0.001953,0.002666,0.067704,-0.321318,-0.016369,0.677042,-81.222214,0.066707,0.000000
152.590012,-0.073357,-81.177734,-0.001992,0.002640,0.067062,-0.326307,-0.016623,0.670623,-81.177734,0.066074,0.000000
152.970001,-0.065163,-81.222214,-0.002005,0.002613,0.066360,-0.289858,-0.014766,0.663602,-81.222214,0.065441,0.000000
153.350006,-0.069633,-81.311180,-0.002013,0.002593,0.065866,-0.309745,-0.015779,0.658659,-81.311180,0.064808,0.000000
153.730011,-0.068138,-81.355659,-0.002031,0.002577,0.065450,-0.303093,-0.015440,0.654495,-81.355659,0.064175,0.000000
154.110001,-0.045052,-81.355659,-0.002078,0.002539,0.064495,-0.200399,-0.010209,0.644954,-81.355659,0.063533,0.000000
154.490005,-0.079315,-81.400139,-0.002082,0.002515,0.063880,-0.352812,-0.017973,0.638796,-81.400139,0.062900,0.000000
154.870010,-0.061066,-81.355659,-0.002078,0.002487,0.063160,-0.271634,-0.013838,0.631601,-81.355659,0.062267,0.000000
155.250000,-0.062180,-81.400139,-0.002087,0.002467,0.062666,-0.276589,-0.014090,0.626657,-81.400139,0.061634,0.000000
155.630005,-0.059578,-81.444618,-0.002130,0.002447,0.062163,-0.265016,-0.013501,0.621627,-81.444618,0.061000,0.000000
156.010010,-0.094948,-81.578064,-0.002147,0.002417,0.061382,-0.422349,-0.021515,0.613823,-81.578064,0.060368,0.000000
156.390015,-0.062927,-81.578064,-0.002177,0.002393,0.060784,-0.279914,-0.014260,0.607839,-81.578064,0.060697,0.000000
156.500000,-0.044678,-81.578064,-0.002186,0.002393,0.060784,-0.198736,-0.010124,0.607839,-81.578064,0.060697,0.000000