File: Data/compression 16/ManualNoHeating-17-16-reverse-hand-2-3_08302024_172846.csv
Time (sec),S:Load (lbs),S:HL1 (DIM),S:LVDT (in),S:Position (in),Ch:Position (mm),Ch:Load (N),Ch:Stress (MPa),Ch:Strain (mm/mm),Ch:HL1 (DIM),Set Point (),Cycles ()
0.210000,-0.112823,-156.217102,-0.010675,-0.005734,-0.145633,-0.501864,-0.025566,-1.456333,-156.217102,-0.145451,0.000000
0.580000,-0.110962,-156.306061,-0.010688,-0.005644,-0.143361,-0.493583,-0.025144,-1.433612,-156.306061,-0.142641,0.000000
0.950000,-0.134422,-156.306061,-0.010516,-0.005420,-0.137672,-0.597940,-0.030461,-1.376722,-156.306061,-0.136484,0.000000
1.320000,-0.151176,-156.261581,-0.010279,-0.005178,-0.131515,-0.672466,-0.034257,-1.315149,-156.261581,-0.130309,0.000000
1.690000,-0.123993,-156.306061,-0.010011,-0.004932,-0.125280,-0.551548,-0.028097,-1.252796,-156.306061,-0.124152,0.000000
2.060000,-0.120270,-156.350540,-0.009779,-0.004691,-0.119139,-0.534987,-0.027254,-1.191394,-156.350540,-0.117977,0.000000
2.430000,-0.124741,-156.439499,-0.009541,-0.004449,-0.113000,-0.554874,-0.028267,-1.129996,-156.439499,-0.111820,0.000000
2.800000,-0.125114,-156.439499,-0.009283,-0.004211,-0.106964,-0.556537,-0.028351,-1.069638,-156.439499,-0.105663,0.000000
3.170000,-0.144852,-156.439499,-0.009028,-0.003967,-0.100763,-0.644332,-0.032824,-1.007630,-156.439499,-0.099488,0.000000
3.540000,-0.093460,-156.439499,-0.008795,-0.003727,-0.094666,-0.415731,-0.021178,-0.946663,-156.439499,-0.093331,0.000000
3.910000,-0.064415,-156.528473,-0.008558,-0.003483,-0.088457,-0.286532,-0.014597,-0.884572,-156.528473,-0.087156,0.000000
4.280000,-0.076332,-156.528473,-0.008287,-0.003238,-0.082239,-0.339542,-0.017297,-0.822390,-156.528473,-0.080999,0.000000
4.650000,-0.104263,-156.572952,-0.008028,-0.002993,-0.076021,-0.463786,-0.023626,-0.760211,-156.572952,-0.074842,0.000000
5.020000,-0.121765,-156.572952,-0.007804,-0.002755,-0.069968,-0.541638,-0.027592,-0.699679,-156.572952,-0.068667,0.000000
5.390000,-0.182831,-156.617432,-0.007545,-0.002512,-0.063811,-0.813272,-0.041430,-0.638107,-156.617432,-0.062510,0.000000
5.760000,-0.101654,-156.750870,-0.007286,-0.002265,-0.057523,-0.452180,-0.023035,-0.575232,-156.750870,-0.056353,0.000000
6.130000,-0.106865,-156.750870,-0.007015,-0.002020,-0.051305,-0.475359,-0.024216,-0.513050,-156.750870,-0.050178,0.000000
6.500000,-0.085640,-156.750870,-0.006782,-0.001782,-0.045252,-0.380946,-0.019406,-0.452518,-156.750870,-0.044021,0.000000
6.870000,-0.097931,-156.706390,-0.006519,-0.001534,-0.038964,-0.435618,-0.022191,-0.389644,-156.706390,-0.037846,0.000000
7.240000,-0.117668,-156.750870,-0.006269,-0.001290,-0.032773,-0.523414,-0.026664,-0.327726,-156.750870,-0.031689,0.000000
7.610000,-0.126602,-156.884308,-0.006036,-0.001056,-0.026823,-0.563155,-0.028688,-0.268232,-156.884308,-0.025531,0.000000
7.980000,-0.082291,-156.884308,-0.005786,-0.000812,-0.020614,-0.366047,-0.018647,-0.206141,-156.884308,-0.019357,0.000000
8.350000,-0.061066,-156.884308,-0.005519,-0.000568,-0.014422,-0.271634,-0.013838,-0.144220,-156.884308,-0.013199,0.000000
8.720000,-0.077080,-156.839828,-0.005273,-0.000322,-0.008187,-0.342868,-0.017467,-0.081867,-156.839828,-0.007025,0.000000
9.090000,-0.096809,-156.928802,-0.005036,-0.000087,-0.002212,-0.430630,-0.021937,-0.022115,-156.928802,-0.000867,0.000000
9.460000,0.156403,-157.062241,-0.004803,0.000000,0.000009,0.695713,0.035441,0.000087,-157.062241,0.000251,0.000000
9.830001,0.155655,-157.017761,-0.004790,0.000000,0.000009,0.692388,0.035272,0.000087,-157.017761,0.000251,0.000000
10.200001,0.147087,-157.017761,-0.004781,0.000000,0.000009,0.654276,0.033330,0.000087,-157.017761,0.000702,0.000000
10.570001,0.156029,-157.062241,-0.004786,0.000016,0.000399,0.694051,0.035357,0.003989,-157.062241,0.001318,0.000000
10.940001,0.336258,-157.106720,-0.004769,0.000038,0.000971,1.495750,0.076197,0.009712,-157.106720,0.001934,0.000000
11.310000,0.437538,-157.151199,-0.004747,0.000058,0.001466,1.946267,0.099148,0.014655,-157.151199,0.002550,0.000000
11.680000,0.540314,-157.151199,-0.004747,0.000070,0.001769,2.403435,0.122437,0.017691,-157.151199,0.003165,0.000000
12.050000,0.869492,-157.106720,-0.004708,0.000111,0.002810,3.867692,0.197030,0.028095,-157.106720,0.003790,0.000000
12.420001,1.044510,-157.195679,-0.004682,0.000133,0.003391,4.646212,0.236689,0.033909,-157.195679,0.004405,0.000000
12.790001,1.314476,-157.195679,-0.004674,0.000153,0.003894,5.847081,0.297864,0.038935,-157.195679,0.005021,0.000000
13.160001,1.758347,-157.329117,-0.004644,0.000181,0.004605,7.821516,0.398447,0.046047,-157.329117,0.005637,0.000000
13.530001,1.912140,-157.240158,-0.004613,0.000196,0.004986,8.505623,0.433297,0.049862,-157.240158,0.006253,0.000000
13.900001,2.633797,-157.329117,-0.004600,0.000234,0.005949,11.715713,0.596827,0.059491,-157.329117,0.006868,0.000000
14.270000,2.992386,-157.329117,-0.004587,0.000257,0.006530,13.310797,0.678084,0.065301,-157.329117,0.007484,0.000000
14.640000,3.477219,-157.373611,-0.004553,0.000282,0.007172,15.467441,0.787949,0.071720,-157.373611,0.008100,0.000000
15.010001,4.039497,-157.418091,-0.004531,0.000307,0.007787,17.968582,0.915363,0.077874,-157.418091,0.008715,0.000000
15.380001,4.396606,-157.462570,-0.004518,0.000325,0.008265,19.557083,0.996285,0.082647,-157.462570,0.009340,0.000000
15.750001,4.891487,-157.507050,-0.004501,0.000351,0.008915,21.758421,1.108427,0.089149,-157.507050,0.009956,0.000000
16.120001,5.498825,-157.507050,-0.004471,0.000380,0.009652,24.459995,1.246052,0.096522,-157.507050,0.010571,0.000000
16.490002,5.795235,-157.551529,-0.004454,0.000401,0.010190,25.778492,1.313219,0.101897,-157.551529,0.011187,0.000000
16.860001,6.261444,-157.640488,-0.004437,0.000422,0.010719,27.852295,1.418864,0.107188,-157.640488,0.011803,0.000000
17.230001,6.747017,-157.640488,-0.004419,0.000448,0.011369,30.012230,1.528896,0.113691,-157.640488,0.012419,0.000000
17.600000,7.324944,-157.551529,-0.004389,0.000475,0.012063,32.582977,1.659856,0.120628,-157.551529,0.013034,0.000000
17.970001,7.748329,-157.596008,-0.004363,0.000498,0.012653,34.466290,1.755796,0.126525,-157.596008,0.013650,0.000000
18.340000,8.201508,-157.684967,-0.004355,0.000525,0.013338,36.482128,1.858488,0.133380,-157.684967,0.014266,0.000000
18.710001,8.522118,-157.773926,-0.004320,0.000547,0.013902,37.908272,1.931139,0.139015,-157.773926,0.014890,0.000000
19.080002,8.835281,-157.729446,-0.004290,0.000568,0.014422,39.301296,2.002103,0.144220,-157.729446,0.015506,0.000000
19.450001,9.411720,-157.729446,-0.004286,0.000599,0.015202,41.865421,2.132726,0.152024,-157.729446,0.016122,0.000000
19.820002,9.848137,-157.729446,-0.004255,0.000623,0.015827,43.806702,2.231620,0.158265,-157.729446,0.016737,0.000000
20.190001,10.096512,-157.773926,-0.004234,0.000648,0.016468,44.911530,2.287902,0.164685,-157.773926,0.017353,0.000000
20.560001,10.341156,-157.862900,-0.004208,0.000669,0.016989,45.999760,2.343339,0.169889,-157.862900,0.017969,0.000000
20.930000,10.592140,-157.907379,-0.004186,0.000692,0.017587,47.116192,2.400213,0.175873,-157.907379,0.018585,0.000000
21.300001,10.830826,-157.907379,-0.004182,0.000710,0.018038,48.177917,2.454300,0.180381,-157.907379,0.019200,0.000000
21.670000,11.394226,-157.951859,-0.004143,0.000739,0.018758,50.684048,2.581969,0.187579,-157.951859,0.019816,0.000000
22.040001,11.753197,-157.951859,-0.004113,0.000766,0.019460,52.280830,2.663312,0.194604,-157.951859,0.020440,0.000000
22.410002,12.039551,-157.996338,-0.004096,0.000790,0.020076,53.554596,2.728201,0.200762,-157.996338,0.021056,0.000000
22.780001,12.388092,-158.040817,-0.004083,0.000815,0.020700,55.104984,2.807182,0.207003,-158.040817,0.021672,0.000000
23.150002,12.630135,-158.040817,-0.004044,0.000836,0.021238,56.181644,2.862029,0.212382,-158.040817,0.022288,0.000000
23.520000,13.152573,-157.996338,-0.004027,0.000865,0.021967,58.505566,2.980416,0.219668,-157.996338,0.022903,0.000000
23.890001,13.319023,-158.129776,-0.004014,0.000887,0.022539,59.245975,3.018134,0.225390,-158.129776,0.023519,0.000000
24.260000,13.529785,-158.129776,-0.003980,0.000909,0.023094,60.183491,3.065893,0.230939,-158.129776,0.024135,0.000000
24.630001,14.095047,-158.174255,-0.003958,0.000938,0.023831,62.697899,3.193983,0.238312,-158.174255,0.024751,0.000000
25.000002,14.199684,-158.129776,-0.003932,0.000960,0.024386,63.163349,3.217694,0.243861,-158.129776,0.025375,0.000000
25.370001,14.846123,-158.218750,-0.003911,0.000988,0.025089,66.038849,3.364180,0.250886,-158.218750,0.025990,0.000000
25.740002,14.924316,-158.263229,-0.003889,0.001010,0.025644,66.386673,3.381898,0.256438,-158.263229,0.026606,0.000000
26.110001,15.042358,-158.352188,-0.003876,0.001031,0.026199,66.911751,3.408647,0.261987,-158.352188,0.027222,0.000000
26.480001,15.494797,-158.307709,-0.003850,0.001057,0.026858,68.924301,3.511171,0.268580,-158.307709,0.027838,0.000000
26.850000,15.644859,-158.352188,-0.003824,0.001079,0.027404,69.591812,3.545176,0.274042,-158.352188,0.028454,0.000000
27.220001,15.882065,-158.307709,-0.003807,0.001103,0.028020,70.646950,3.598927,0.280200,-158.307709,0.029069,0.000000
27.590002,16.531105,-158.441147,-0.003777,0.001132,0.028749,73.534027,3.746002,0.287485,-158.441147,0.029685,0.000000
27.960001,16.603722,-158.485626,-0.003764,0.001153,0.029286,73.857040,3.762457,0.292860,-158.485626,0.030301,0.000000
28.330002,16.665161,-158.530106,-0.003742,0.001173,0.029806,74.130341,3.776379,0.298064,-158.530106,0.030925,0.000000
28.700001,17.201004,-158.485626,-0.003725,0.001201,0.030500,76.513885,3.897803,0.305002,-158.485626,0.031541,0.000000
29.070002,17.310486,-158.485626,-0.003704,0.001223,0.031072,77.000885,3.922612,0.310725,-158.485626,0.032156,0.000000
29.440001,17.963249,-158.530106,-0.003682,0.001253,0.031818,79.904526,4.070530,0.318185,-158.530106,0.032772,0.000000
29.810001,17.962875,-158.574585,-0.003669,0.001275,0.032382,79.902863,4.070446,0.323820,-158.574585,0.033388,0.000000
30.180002,18.214233,-158.619064,-0.003630,0.001297,0.032954,81.020958,4.127404,0.329543,-158.619064,0.034004,0.000000
30.550001,18.058205,-158.574585,-0.003622,0.001312,0.033336,80.326904,4.092048,0.333358,-158.574585,0.034620,0.000000
30.920002,18.814865,-158.574585,-0.003596,0.001345,0.034160,83.692703,4.263509,0.341598,-158.574585,0.035235,0.000000
31.290001,19.187981,-158.663559,-0.003561,0.001376,0.034940,85.352402,4.348058,0.349403,-158.663559,0.035851,0.000000
31.660002,19.254265,-158.752518,-0.003535,0.001399,0.035539,85.647247,4.363079,0.355386,-158.752518,0.036475,0.000000
32.030003,19.162666,-158.752518,-0.003514,0.001419,0.036050,85.239799,4.342322,0.360504,-158.752518,0.037091,0.000000
32.400002,19.516418,-158.708038,-0.003501,0.001443,0.036640,86.813362,4.422483,0.366401,-158.708038,0.037707,0.000000
32.770000,19.239746,-158.841476,-0.003479,0.001457,0.036996,85.582664,4.359788,0.369958,-158.841476,0.038322,0.000000
33.140003,20.374733,-158.841476,-0.003454,0.001497,0.038019,90.631340,4.616981,0.380189,-158.841476,0.038938,0.000000
33.510002,20.374733,-158.841476,-0.003445,0.001520,0.038609,90.631340,4.616981,0.386086,-158.841476,0.039554,0.000000
33.880001,20.422028,-158.841476,-0.003423,0.001541,0.039138,90.841713,4.627697,0.391377,-158.841476,0.040170,0.000000
34.250000,20.855843,-158.885956,-0.003402,0.001567,0.039814,92.771423,4.726001,0.398141,-158.885956,0.040786,0.000000
34.620003,20.607468,-158.885956,-0.003389,0.001582,0.040187,91.666595,4.669719,0.401873,-158.885956,0.041401,0.000000
34.990002,21.417007,-159.019394,-0.003372,0.001617,0.041072,95.267609,4.853163,0.410718,-159.019394,0.042026,0.000000
35.360001,21.419983,-159.019394,-0.003328,0.001642,0.041696,95.280846,4.853837,0.416959,-159.019394,0.042641,0.000000
35.730003,21.758469,-159.063889,-0.003303,0.001667,0.042338,96.786499,4.930539,0.423378,-159.063889,0.043257,0.000000
36.100002,21.945404,-159.063889,-0.003303,0.001691,0.042954,97.618034,4.972899,0.429536,-159.063889,0.043873,0.000000
36.470001,21.681015,-159.108368,-0.003281,0.001707,0.043361,96.441971,4.912988,0.433613,-159.108368,0.044488,0.000000
36.840000,22.018387,-159.108368,-0.003260,0.001732,0.044003,97.942673,4.989438,0.440028,-159.108368,0.045104,0.000000
37.210003,22.534126,-159.108368,-0.003225,0.001761,0.044731,100.236801,5.106306,0.447314,-159.108368,0.045720,0.000000
37.580002,22.832390,-159.152847,-0.003212,0.001786,0.045373,101.563545,5.173893,0.453729,-159.152847,0.046336,0.000000
37.950001,22.786217,-159.152847,-0.003208,0.001806,0.045885,101.358154,5.163431,0.458847,-159.152847,0.046952,0.000000
38.320004,23.188751,-159.241806,-0.003173,0.001833,0.046553,103.148720,5.254646,0.465527,-159.241806,0.047576,0.000000
38.690002,23.352600,-159.197327,-0.003169,0.001857,0.047159,103.877556,5.291775,0.471594,-159.197327,0.048192,0.000000
39.060001,23.781944,-159.286285,-0.003130,0.001882,0.047801,105.787369,5.389065,0.478013,-159.286285,0.048807,0.000000
39.430000,24.143143,-159.286285,-0.003117,0.001908,0.048469,107.394066,5.470914,0.484690,-159.286285,0.049423,0.000000
39.800003,24.154312,-159.330765,-0.003104,0.001932,0.049067,107.443748,5.473445,0.490674,-159.330765,0.050039,0.000000
40.170002,24.281296,-159.330765,-0.003087,0.001955,0.049648,108.008598,5.502220,0.496484,-159.330765,0.050654,0.000000
40.540001,24.519241,-159.419724,-0.003057,0.001977,0.050212,109.067032,5.556139,0.502123,-159.419724,0.051270,0.000000
40.910004,25.476608,-159.419724,-0.003048,0.002010,0.051045,113.325615,5.773082,0.510446,-159.419724,0.051886,0.000000
41.280003,25.271805,-159.375244,-0.003027,0.002030,0.051574,112.414604,5.726673,0.515737,-159.375244,0.052502,0.000000
41.650002,25.458740,-159.419724,-0.003005,0.002053,0.052137,113.246132,5.769033,0.521373,-159.419724,0.053126,0.000000
42.020000,26.002769,-159.508698,-0.002997,0.002081,0.052866,115.666092,5.892312,0.528659,-159.508698,0.053742,0.000000
42.390003,25.558159,-159.553177,-0.002979,0.002097,0.053274,113.688370,5.791562,0.532735,-159.553177,0.054358,0.000000
42.760002,25.881004,-159.508698,-0.002958,0.002121,0.053863,115.124458,5.864719,0.538632,-159.508698,0.054973,0.000000
43.130001,26.726295,-159.597656,-0.002940,0.002149,0.054583,118.884499,6.056265,0.545831,-159.597656,0.055589,0.000000
43.500004,26.991791,-159.597656,-0.002919,0.002173,0.055199,120.065483,6.116427,0.551989,-159.597656,0.056205,0.000000
43.870003,27.100899,-159.597656,-0.002902,0.002194,0.055728,120.550819,6.141151,0.557277,-159.597656,0.056820,0.000000
44.240002,27.434174,-159.686615,-0.002893,0.002218,0.056343,122.033302,6.216672,0.563435,-159.686615,0.057436,0.000000
44.610001,27.253197,-159.642136,-0.002863,0.002235,0.056769,121.228271,6.175663,0.567685,-159.642136,0.058052,0.000000
44.980003,28.166626,-159.642136,-0.002854,0.002266,0.057549,125.291412,6.382648,0.575490,-159.642136,0.058676,0.000000
45.350002,28.617203,-159.731094,-0.002833,0.002294,0.058269,127.295677,6.484751,0.582688,-159.731094,0.059292,0.000000
45.720001,28.895363,-159.775574,-0.002820,0.002316,0.058832,128.532990,6.547783,0.588324,-159.775574,0.059908,0.000000
46.090004,29.395828,-159.775574,-0.002807,0.002344,0.059544,130.759171,6.661190,0.595436,-159.775574,0.060523,0.000000
46.460003,29.516106,-159.820053,-0.002785,0.002363,0.060020,131.294189,6.688445,0.600205,-159.820053,0.061139,0.000000
46.830002,30.304420,-159.775574,-0.002755,0.002394,0.060801,134.800797,6.867080,0.608009,-159.775574,0.061755,0.000000
47.200001,30.596359,-159.820053,-0.002755,0.002418,0.061408,136.099396,6.933234,0.614080,-159.820053,0.062371,0.000000
47.570004,30.505501,-159.909012,-0.002733,0.002436,0.061876,135.695251,6.912645,0.618762,-159.909012,0.062986,0.000000
47.940002,31.404778,-159.997986,-0.002712,0.002466,0.062631,139.695435,7.116424,0.626309,-159.997986,0.063611,0.000000
48.310001,31.633041,-159.909012,-0.002699,0.002487,0.063169,140.710800,7.168149,0.631688,-159.909012,0.064227,0.000000
48.680004,32.238152,-159.997986,-0.002682,0.002515,0.063871,143.402466,7.305270,0.638709,-159.997986,0.064842,0.000000
49.050003,32.593391,-159.953506,-0.002673,0.002539,0.064487,144.982651,7.385768,0.644867,-159.953506,0.065458,0.000000
49.420002,32.757980,-160.042465,-0.002643,0.002559,0.065007,145.714767,7.423064,0.650071,-160.042465,0.066074,0.000000
49.790001,33.233871,-160.131424,-0.002621,0.002586,0.065675,147.831650,7.530903,0.656747,-160.131424,0.066689,0.000000
50.160004,33.533264,-160.086945,-0.002613,0.002608,0.066239,149.163406,7.598746,0.662387,-160.086945,0.067305,0.000000
50.530003,33.945480,-160.086945,-0.002600,0.002628,0.066750,150.997040,7.692155,0.667500,-160.086945,0.067921,0.000000
50.900002,34.990730,-160.175903,-0.002574,0.002660,0.067565,155.646545,7.929013,0.675653,-160.175903,0.068537,0.000000
51.270004,35.131859,-160.220383,-0.002561,0.002680,0.068077,156.274307,7.960993,0.680770,-160.220383,0.069161,0.000000
51.640003,35.394005,-160.264862,-0.002552,0.002701,0.068615,157.440399,8.020396,0.686148,-160.264862,0.069777,0.000000
52.010002,35.062225,-160.264862,-0.002527,0.002728,0.069283,155.964569,7.945214,0.692825,-160.264862,0.070393,0.000000
52.380001,37.137085,-160.220383,-0.002509,0.002757,0.070029,165.194000,8.415384,0.700285,-160.220383,0.071008,0.000000
52.750004,37.613716,-160.220383,-0.002509,0.002783,0.070679,167.314163,8.523390,0.706788,-160.220383,0.071624,0.000000
53.120003,37.960022,-160.398315,-0.002492,0.002807,0.071286,168.854614,8.601864,0.712858,-160.398315,0.072240,0.000000
53.490002,38.151794,-160.353836,-0.002458,0.002828,0.071823,169.707657,8.645321,0.718233,-160.353836,0.072855,0.000000
53.860004,38.920746,-160.353836,-0.002466,0.002853,0.072474,173.128128,8.819567,0.724739,-160.353836,0.073471,0.000000
54.230003,39.253273,-160.398315,-0.002440,0.002875,0.073020,174.607285,8.894918,0.730201,-160.398315,0.074087,0.000000
54.600002,39.973442,-160.442795,-0.002427,0.002902,0.073723,177.810745,9.058111,0.737226,-160.442795,0.074711,0.000000
54.970001,40.446732,-160.487274,-0.002410,0.002925,0.074287,179.916046,9.165359,0.742865,-160.487274,0.075327,0.000000
55.340004,40.767715,-160.531754,-0.002397,0.002945,0.074807,181.343857,9.238096,0.748066,-160.531754,0.075943,0.000000
55.710003,41.510971,-160.531754,-0.002380,0.002968,0.075397,184.650024,9.406521,0.753966,-160.531754,0.076559,0.000000
56.080002,41.525864,-160.576233,-0.002363,0.002985,0.075821,184.716263,9.409895,0.758213,-160.576233,0.077174,0.000000
56.450005,43.565720,-160.620712,-0.002376,0.003024,0.076810,193.789993,9.872133,0.768099,-160.620712,0.077790,0.000000
56.820004,43.968254,-160.665192,-0.002345,0.003047,0.077400,195.580566,9.963348,0.773996,-160.665192,0.078406,0.000000
57.190002,44.453827,-160.709671,-0.002333,0.003070,0.077989,197.740494,10.073381,0.779893,-160.709671,0.079021,0.000000
57.560001,45.295021,-160.709671,-0.002311,0.003094,0.078596,201.482315,10.263999,0.785964,-160.709671,0.079637,0.000000
57.930004,44.866043,-160.665192,-0.002298,0.003111,0.079021,199.574127,10.166791,0.790214,-160.665192,0.080262,0.000000
58.300003,46.176048,-160.754150,-0.002298,0.003141,0.079784,205.401321,10.463642,0.797845,-160.754150,0.080877,0.000000
58.670002,47.299873,-160.754150,-0.002302,0.003168,0.080478,210.400345,10.718304,0.804782,-160.754150,0.081493,0.000000
59.040001,48.298943,-160.798645,-0.002272,0.003193,0.081103,214.844421,10.944697,0.811027,-160.798645,0.082109,0.000000
59.410004,48.686211,-160.843124,-0.002251,0.003214,0.081623,216.567078,11.032453,0.816232,-160.843124,0.082725,0.000000
59.780003,49.334511,-160.843124,-0.002233,0.003235,0.082169,219.450867,11.179359,0.821693,-160.843124,0.083340,0.000000
60.150002,50.086334,-160.843124,-0.002225,0.003259,0.082776,222.795135,11.349726,0.827764,-160.843124,0.083956,0.000000
60.520004,51.038864,-160.932083,-0.002229,0.003287,0.083488,227.032211,11.565572,0.834876,-160.932083,0.084572,0.000000
60.890003,52.714165,-160.932083,-0.002195,0.003318,0.084268,234.484314,11.945201,0.842680,-160.932083,0.085187,0.000000
61.260002,52.997543,-160.976562,-0.002190,0.003335,0.084710,235.744843,12.009415,0.847105,-160.976562,0.085812,0.000000
61.630001,53.944855,-160.932083,-0.002177,0.003361,0.085361,239.958694,12.224079,0.853607,-160.932083,0.086428,0.000000
62.000004,55.105911,-160.976562,-0.002173,0.003388,0.086063,245.123337,12.487179,0.860632,-160.976562,0.087043,0.000000
62.370003,56.417786,-161.065521,-0.002151,0.003414,0.086723,250.958847,12.784452,0.867225,-161.065521,0.087659,0.000000
62.740002,57.187103,-161.110001,-0.002130,0.003437,0.087304,254.380936,12.958783,0.873035,-161.110001,0.088275,0.000000
63.110004,58.197723,-161.110001,-0.002126,0.003463,0.087971,258.876404,13.187793,0.879712,-161.110001,0.088891,0.000000
63.480003,59.143921,-161.110001,-0.002108,0.003484,0.088483,263.085297,13.402205,0.884829,-161.110001,0.089506,0.000000
63.850002,59.944519,-161.198959,-0.002113,0.003505,0.089021,266.646545,13.583622,0.890207,-161.198959,0.090122,0.000000
64.220001,61.206123,-161.198959,-0.002091,0.003531,0.089680,272.258423,13.869506,0.896797,-161.198959,0.090738,0.000000
64.590004,62.117691,-161.243454,-0.002078,0.003553,0.090252,276.313293,14.076070,0.902520,-161.243454,0.091362,0.000000
64.960007,63.242622,-161.198959,-0.002065,0.003578,0.090885,281.317230,14.330983,0.908852,-161.198959,0.091978,0.000000
65.330002,64.720192,-161.198959,-0.002052,0.003603,0.091518,287.889801,14.665805,0.915180,-161.198959,0.092594,0.000000
65.700005,65.174873,-161.243454,-0.002044,0.003626,0.092091,289.912323,14.768838,0.920907,-161.243454,0.093209,0.000000
66.070000,66.672173,-161.376892,-0.002031,0.003639,0.092429,296.572632,15.108130,0.924286,-161.376892,0.093773,0.000000
66.440002,65.264610,-161.332413,-0.002005,0.003639,0.092420,290.311493,14.789172,0.924199,-161.332413,294.500488,0.000000
66.810005,65.109322,-161.376892,-0.002001,0.003653,0.092776,289.620728,14.753983,0.927757,-161.376892,294.500488,0.000000
67.180000,65.256416,-161.421371,-0.002001,0.003665,0.093079,290.275024,14.787314,0.930793,-161.421371,294.500488,0.000000
67.550003,65.205025,-161.376892,-0.002001,0.003673,0.093287,290.046448,14.775670,0.932874,-161.376892,294.500488,0.000000
67.920006,65.056450,-161.510330,-0.001996,0.003681,0.093496,289.385529,14.742002,0.934956,-161.510330,294.500488,0.000000
68.290001,65.044167,-161.510330,-0.001979,0.003689,0.093703,289.330902,14.739220,0.937034,-161.510330,294.500488,0.000000
68.660004,65.156624,-161.465851,-0.001970,0.003697,0.093903,289.831146,14.764703,0.939029,-161.465851,294.500488,0.000000
69.030006,65.180077,-161.510330,-0.001975,0.003704,0.094077,289.935455,14.770016,0.940766,-161.510330,294.500488,0.000000
69.400002,65.363289,-161.510330,-0.001962,0.003713,0.094302,290.750427,14.811533,0.943018,-161.510330,294.500488,0.000000
69.770004,65.187157,-161.643784,-0.001975,0.003717,0.094415,289.966949,14.771621,0.944146,-161.643784,294.500488,0.000000
70.140007,65.528618,-161.599289,-0.001949,0.003726,0.094631,291.485840,14.848997,0.946315,-161.599289,294.500488,0.000000
70.510002,65.039330,-161.599289,-0.001936,0.003726,0.094640,289.309387,14.738123,0.946402,-161.599289,294.500488,0.000000
70.880005,65.603096,-161.643784,-0.001936,0.003736,0.094900,291.817139,14.865874,0.949002,-161.643784,294.500488,0.000000
71.250000,65.138008,-161.732742,-0.001940,0.003736,0.094900,289.748322,14.760484,0.949002,-161.732742,294.500488,0.000000
71.620003,64.743660,-161.732742,-0.001940,0.003737,0.094926,287.994171,14.671123,0.949263,-161.732742,294.500488,0.000000
71.990005,66.407051,-161.777222,-0.001927,0.003718,0.094441,295.393311,15.048053,0.944407,-161.777222,294.500488,0.000000
72.360001,65.945305,-161.732742,-0.001919,0.003718,0.094449,293.339355,14.943420,0.944494,-161.732742,294.500488,0.000000
72.730003,65.486168,-161.821701,-0.001914,0.003720,0.094476,291.297028,14.839377,0.944755,-161.821701,294.500488,0.000000
73.100006,65.182686,-161.777222,-0.001923,0.003747,0.095169,289.947083,14.770608,0.951693,-161.777222,294.500488,0.000000
73.470001,65.197578,-161.910660,-0.001919,0.003756,0.095412,290.013306,14.773982,0.954119,-161.910660,294.500488,0.000000
73.840004,65.232216,-161.866180,-0.001910,0.003761,0.095533,290.167389,14.781832,0.955334,-161.866180,294.500488,0.000000
74.210007,65.008049,-161.955139,-0.001901,0.003766,0.095655,289.170258,14.731034,0.956549,-161.955139,294.500488,0.000000
74.580002,65.180077,-161.910660,-0.001906,0.003768,0.095707,289.935455,14.770016,0.957067,-161.910660,294.500488,0.000000
74.950005,65.439995,-161.999619,-0.001906,0.003775,0.095880,291.091644,14.828915,0.958805,-161.999619,294.500488,0.000000
75.320007,65.266472,-162.044098,-0.001919,0.003775,0.095880,290.319763,14.789594,0.958805,-162.044098,294.500488,0.000000
75.690002,65.512611,-161.999619,-0.001884,0.003781,0.096036,291.414642,14.845369,0.960364,-161.999619,294.500488,0.000000
76.060005,65.298500,-162.044098,-0.001910,0.003781,0.096036,290.462250,14.796852,0.960364,-162.044098,294.500488,0.000000
76.430000,65.283592,-161.999619,-0.001888,0.003784,0.096123,290.395935,14.793474,0.961231,-161.999619,294.500488,0.000000
76.800003,65.311150,-162.177551,-0.001906,0.003787,0.096201,290.518494,14.799718,0.962011,-162.177551,294.500488,0.000000
77.170006,65.147682,-162.177551,-0.001893,0.003789,0.096236,289.791351,14.762676,0.962359,-162.177551,294.500488,0.000000
77.540001,65.133904,-162.222031,-0.001884,0.003791,0.096279,289.730072,14.759553,0.962794,-162.222031,294.500488,0.000000
77.910004,65.259392,-162.177551,-0.001884,0.003794,0.096366,290.288269,14.787990,0.963661,-162.177551,294.500488,0.000000
78.280006,65.124962,-162.222031,-0.001893,0.003795,0.096383,289.690308,14.757527,0.963835,-162.222031,294.500488,0.000000
78.650002,65.062782,-162.222031,-0.001901,0.003797,0.096435,289.413696,14.743437,0.964353,-162.222031,294.500488,0.000000
79.020004,64.935799,-162.310989,-0.001884,0.003797,0.096435,288.848846,14.714663,0.964353,-162.310989,294.500488,0.000000
79.390007,65.824287,-162.310989,-0.001884,0.003808,0.096713,292.801056,14.915997,0.967128,-162.310989,294.500488,0.000000
79.760002,65.647041,-162.310989,-0.001871,0.003808,0.096713,292.012634,14.875832,0.967128,-162.310989,294.500488,0.000000
80.130005,65.485054,-162.310989,-0.001871,0.003808,0.096713,291.292053,14.839126,0.967128,-162.310989,294.500488,0.000000
80.500008,65.297371,-162.355469,-0.001871,0.003808,0.096713,290.457214,14.796596,0.967128,-162.355469,294.500488,0.000000
80.870003,65.143593,-162.444427,-0.001880,0.003808,0.096713,289.773163,14.761749,0.967128,-162.444427,294.500488,0.000000
81.240005,64.990166,-162.488907,-0.001871,0.003808,0.096713,289.090698,14.726981,0.967128,-162.488907,294.500488,0.000000
81.610001,64.809563,-162.488907,-0.001880,0.003808,0.096713,288.287323,14.686057,0.967128,-162.488907,294.500488,0.000000
81.980003,65.938606,-162.533401,-0.001863,0.003813,0.096852,293.309570,14.941902,0.968517,-162.533401,294.500488,0.000000
82.350006,65.771782,-162.577881,-0.001867,0.003813,0.096852,292.567505,14.904099,0.968517,-162.577881,294.500488,0.000000
82.720001,65.565117,-162.622360,-0.001867,0.003813,0.096852,291.648193,14.857267,0.968517,-162.622360,294.500488,0.000000
83.090004,65.361046,-162.666840,-0.001854,0.003813,0.096852,290.740448,14.811025,0.968517,-162.666840,294.500488,0.000000
83.460007,65.205772,-162.577881,-0.001871,0.003813,0.096852,290.049774,14.775839,0.968517,-162.577881,294.500488,0.000000
83.830002,65.279503,-162.622360,-0.001858,0.003823,0.097094,290.377716,14.792547,0.970943,-162.622360,294.500488,0.000000
84.200005,65.247856,-162.666840,-0.001867,0.003823,0.097094,290.236969,14.785376,0.970943,-162.666840,294.500488,0.000000
84.570007,65.119011,-162.755798,-0.001863,0.003823,0.097103,289.663818,14.756179,0.971030,-162.755798,294.500488,0.000000
84.940002,65.016609,-162.755798,-0.001871,0.003823,0.097103,289.208313,14.732974,0.971030,-162.755798,294.500488,0.000000
85.310005,65.008049,-162.800278,-0.001854,0.003826,0.097181,289.170258,14.731034,0.971813,-162.800278,294.500488,0.000000
85.680000,65.000969,-162.800278,-0.001845,0.003826,0.097181,289.138763,14.729430,0.971813,-162.800278,294.500488,0.000000
86.050003,64.913826,-162.800278,-0.001854,0.003826,0.097181,288.751129,14.709682,0.971813,-162.800278,294.500488,0.000000
86.420006,65.071724,-162.844757,-0.001863,0.003831,0.097311,289.453491,14.745463,0.973112,-162.844757,294.500488,0.000000
86.790001,65.075447,-162.889236,-0.001854,0.003831,0.097311,289.470032,14.746306,0.973112,-162.889236,294.500488,0.000000
87.160004,65.010643,-162.889236,-0.001845,0.003831,0.097311,289.181793,14.731623,0.973112,-162.889236,294.500488,0.000000
87.530006,64.941017,-162.933731,-0.001850,0.003831,0.097311,288.872070,14.715845,0.973112,-162.933731,294.500488,0.000000
87.900002,65.042671,-162.978210,-0.001858,0.003835,0.097398,289.324249,14.738880,0.973978,-162.978210,294.500488,0.000000
88.270004,64.988304,-163.111649,-0.001845,0.003835,0.097398,289.082428,14.726561,0.973978,-163.111649,294.500488,0.000000
88.640007,64.916435,-163.067169,-0.001845,0.003835,0.097398,288.762726,14.710275,0.973978,-163.067169,294.500488,0.000000
89.010002,64.970802,-163.111649,-0.001845,0.003837,0.097467,289.004578,14.722594,0.974675,-163.111649,294.500488,0.000000
89.380005,65.163689,-163.022690,-0.001845,0.003840,0.097537,289.862549,14.766303,0.975367,-163.022690,294.500488,0.000000
89.750008,65.114540,-163.111649,-0.001850,0.003840,0.097537,289.643951,14.755165,0.975367,-163.111649,294.500488,0.000000
90.120003,65.038200,-163.156128,-0.001845,0.003841,0.097554,289.304352,14.737866,0.975542,-163.156128,294.500488,0.000000
90.490005,65.006920,-163.245087,-0.001845,0.003841,0.097563,289.165222,14.730779,0.975629,-163.245087,294.500488,0.000000
90.860001,64.936546,-163.245087,-0.001850,0.003841,0.097563,288.852173,14.714832,0.975629,-163.245087,294.500488,0.000000
91.230003,65.351006,-163.200607,-0.001850,0.003847,0.097710,290.695801,14.808750,0.977101,-163.200607,294.500488,0.000000
91.600006,65.317482,-163.245087,-0.001837,0.003847,0.097710,290.546661,14.801153,0.977101,-163.245087,294.500488,0.000000
91.970001,65.262001,-163.378540,-0.001845,0.003847,0.097710,290.299866,14.788581,0.977101,-163.378540,294.500488,0.000000
92.340004,65.182686,-163.378540,-0.001832,0.003847,0.097710,289.947083,14.770608,0.977101,-163.378540,294.500488,0.000000
92.710007,65.099648,-163.334045,-0.001837,0.003847,0.097719,289.577698,14.751791,0.977188,-163.334045,294.500488,0.000000
93.080002,65.119759,-163.378540,-0.001841,0.003850,0.097797,289.667145,14.756349,0.977968,-163.378540,294.500488,0.000000
93.450005,65.213219,-163.423019,-0.001828,0.003850,0.097797,290.082886,14.777527,0.977968,-163.423019,294.500488,0.000000
93.820007,65.161095,-163.467499,-0.001837,0.003850,0.097797,289.851013,14.765716,0.977968,-163.467499,294.500488,0.000000
94.190002,65.103737,-163.511978,-0.001845,0.003851,0.097805,289.595886,14.752718,0.978055,-163.511978,294.500488,0.000000
94.560005,65.288445,-163.511978,-0.001828,0.003855,0.097910,290.417511,14.794573,0.979096,-163.511978,294.500488,0.000000
94.930008,65.319344,-163.511978,-0.001832,0.003855,0.097910,290.554962,14.801575,0.979096,-163.511978,294.500488,0.000000
95.300003,65.304451,-163.511978,-0.001832,0.003855,0.097910,290.488708,14.798200,0.979096,-163.511978,294.500488,0.000000
95.670006,65.255669,-163.600937,-0.001832,0.003855,0.097918,290.271698,14.787147,0.979183,-163.600937,294.500488,0.000000
96.040001,65.224388,-163.689896,-0.001824,0.003856,0.097936,290.132568,14.780058,0.979357,-163.689896,294.500488,0.000000
96.410004,65.186409,-163.645416,-0.001828,0.003856,0.097936,289.963623,14.771451,0.979357,-163.645416,294.500488,0.000000
96.780006,65.191246,-163.645416,-0.001828,0.003857,0.097970,289.985138,14.772547,0.979705,-163.645416,294.500488,0.000000
97.150002,65.149178,-163.689896,-0.001845,0.003857,0.097979,289.798004,14.763015,0.979792,-163.689896,294.500488,0.000000
97.520004,65.241142,-163.734375,-0.001828,0.003859,0.098031,290.207092,14.783854,0.980310,-163.734375,294.500488,0.000000
97.890007,65.242638,-163.778854,-0.001824,0.003859,0.098031,290.213745,14.784193,0.980310,-163.778854,294.500488,0.000000
98.260002,65.232582,-163.823349,-0.001815,0.003860,0.098040,290.169006,14.781914,0.980398,-163.823349,294.500488,0.000000
98.630005,65.205025,-163.867828,-0.001837,0.003861,0.098066,290.046448,14.775670,0.980659,-163.867828,294.500488,0.000000
99.000008,65.200188,-163.912308,-0.001837,0.003861,0.098075,290.024933,14.774573,0.980746,-163.912308,294.500488,0.000000
99.370003,65.236305,-163.867828,-0.001824,0.003863,0.098109,290.185577,14.782759,0.981090,-163.867828,294.500488,0.000000
99.740005,65.214714,-163.956787,-0.001824,0.003863,0.098109,290.089539,14.777865,0.981090,-163.956787,294.500488,0.000000
100.110008,65.260506,-163.956787,-0.001824,0.003864,0.098153,290.293213,14.788242,0.981525,-163.956787,294.500488,0.000000
100.480003,65.264229,-164.045746,-0.001819,0.003864,0.098153,290.309784,14.789085,0.981525,-164.045746,294.500488,0.000000
100.850006,65.239662,-163.956787,-0.001828,0.003865,0.098179,290.200500,14.783519,0.981787,-163.956787,294.500488,0.000000
101.220001,65.256783,-164.001266,-0.001832,0.003866,0.098187,290.276672,14.787398,0.981870,-164.001266,294.500488,0.000000
101.590004,65.231468,-164.134705,-0.001824,0.003866,0.098187,290.164062,14.781662,0.981870,-164.134705,294.500488,0.000000
101.960007,65.180824,-164.134705,-0.001828,0.003866,0.098196,289.938782,14.770185,0.981957,-164.134705,294.500488,0.000000
102.330002,65.172630,-164.134705,-0.001815,0.003866,0.098204,289.902344,14.768330,0.982044,-164.134705,294.500488,0.000000
102.700005,65.258644,-164.134705,-0.001828,0.003869,0.098265,290.284943,14.787820,0.982653,-164.134705,294.500488,0.000000
103.070007,65.249336,-164.223679,-0.001828,0.003869,0.098265,290.243530,14.785711,0.982653,-164.223679,294.500488,0.000000
103.440002,65.229973,-164.268158,-0.001807,0.003869,0.098265,290.157410,14.781323,0.982653,-164.268158,294.500488,0.000000
103.810005,65.192375,-164.134705,-0.001815,0.003869,0.098265,289.990173,14.772803,0.982653,-164.134705,294.500488,0.000000
104.180008,65.153648,-164.268158,-0.001807,0.003869,0.098274,289.817902,14.764028,0.982740,-164.268158,294.500488,0.000000
104.550003,65.121986,-164.268158,-0.001824,0.003869,0.098274,289.677063,14.756853,0.982740,-164.268158,294.500488,0.000000
104.920006,65.120506,-164.357117,-0.001824,0.003870,0.098308,289.670471,14.756518,0.983085,-164.357117,294.500488,0.000000
105.290009,65.113426,-164.357117,-0.001815,0.003870,0.098308,289.638977,14.754913,0.983085,-164.357117,294.500488,0.000000
105.660004,65.088097,-164.401596,-0.001824,0.003870,0.098308,289.526306,14.749174,0.983085,-164.401596,294.500488,0.000000
106.030006,65.045647,-164.401596,-0.001815,0.003871,0.098317,289.337494,14.739554,0.983172,-164.401596,294.500488,0.000000
106.400002,65.017723,-164.446075,-0.001815,0.003872,0.098343,289.213287,14.733227,0.983433,-164.446075,294.500488,0.000000
106.770004,65.185295,-164.401596,-0.001815,0.003874,0.098395,289.958679,14.771199,0.983952,-164.401596,294.500488,0.000000
107.140007,65.171135,-164.535034,-0.001815,0.003874,0.098395,289.895691,14.767991,0.983952,-164.535034,294.500488,0.000000
107.510002,65.162209,-164.535034,-0.001824,0.003874,0.098395,289.855988,14.765968,0.983952,-164.535034,294.500488,0.000000
107.880005,65.116783,-164.535034,-0.001807,0.003874,0.098395,289.653931,14.755673,0.983952,-164.535034,294.500488,0.000000
108.250008,65.094063,-164.623993,-0.001828,0.003874,0.098395,289.552856,14.750525,0.983952,-164.623993,294.500488,0.000000
108.620003,65.050865,-164.535034,-0.001824,0.003874,0.098395,289.360687,14.740736,0.983952,-164.535034,294.500488,0.000000
108.990005,65.012505,-164.668488,-0.001819,0.003874,0.098395,289.190063,14.732044,0.983952,-164.668488,294.500488,0.000000
109.360008,64.979744,-164.757446,-0.001824,0.003874,0.098395,289.044342,14.724620,0.983952,-164.757446,294.500488,0.000000
109.730003,65.653740,-164.712967,-0.001819,0.003882,0.098603,292.042419,14.877350,0.986033,-164.712967,294.500488,0.000000
110.100006,65.626549,-164.668488,-0.001811,0.003881,0.098569,291.921478,14.871188,0.985689,-164.668488,294.500488,0.000000
110.470009,65.585594,-164.757446,-0.001815,0.003881,0.098569,291.739288,14.861908,0.985689,-164.757446,294.500488,0.000000
110.840004,65.555428,-164.757446,-0.001819,0.003881,0.098569,291.605103,14.855073,0.985689,-164.757446,294.500488,0.000000
111.210007,65.527504,-164.801926,-0.001802,0.003881,0.098569,291.480896,14.848745,0.985689,-164.801926,294.500488,0.000000
111.580002,65.470161,-164.801926,-0.001802,0.003881,0.098569,291.225830,14.835751,0.985689,-164.801926,294.500488,0.000000
111.950005,65.420265,-164.846405,-0.001807,0.003881,0.098569,291.003876,14.824444,0.985689,-164.846405,294.500488,0.000000
112.320007,65.366264,-164.846405,-0.001819,0.003881,0.098569,290.763672,14.812207,0.985689,-164.846405,294.500488,0.000000
112.690002,65.314507,-164.935364,-0.001824,0.003881,0.098569,290.533447,14.800479,0.985689,-164.935364,294.500488,0.000000
113.060005,65.303703,-164.935364,-0.001807,0.003881,0.098569,290.485382,14.798031,0.985689,-164.935364,294.500488,0.000000
113.430008,65.264977,-164.935364,-0.001819,0.003881,0.098569,290.313110,14.789255,0.985689,-164.935364,294.500488,0.000000
113.800003,65.221779,-164.935364,-0.001807,0.003881,0.098569,290.120972,14.779467,0.985689,-164.935364,294.500488,0.000000
114.170006,65.175606,-164.979843,-0.001802,0.003881,0.098569,289.915588,14.769003,0.985689,-164.979843,294.500488,0.000000
114.540009,65.121620,-165.157776,-0.001819,0.003881,0.098569,289.675446,14.756769,0.985689,-165.157776,294.500488,0.000000
114.910004,65.145821,-165.157776,-0.001815,0.003883,0.098621,289.783081,14.762254,0.986207,-165.157776,294.500488,0.000000
115.280006,65.155876,-165.113297,-0.001807,0.003883,0.098621,289.827820,14.764533,0.986207,-165.113297,294.500488,0.000000
115.650009,65.153648,-165.157776,-0.001807,0.003883,0.098621,289.817902,14.764028,0.986207,-165.157776,294.500488,0.000000
116.020004,65.110817,-165.157776,-0.001802,0.003883,0.098621,289.627380,14.754322,0.986207,-165.157776,294.500488,0.000000
116.390007,65.066872,-165.246735,-0.001824,0.003883,0.098621,289.431915,14.744364,0.986207,-165.246735,294.500488,0.000000
116.760002,65.045647,-165.291214,-0.001819,0.003883,0.098621,289.337494,14.739554,0.986207,-165.291214,294.500488,0.000000
117.130005,65.020332,-165.291214,-0.001815,0.003883,0.098621,289.224884,14.733818,0.986207,-165.291214,294.500488,0.000000
117.500008,64.989052,-165.246735,-0.001794,0.003883,0.098621,289.085754,14.726729,0.986207,-165.246735,294.500488,0.000000
117.870003,64.942513,-165.291214,-0.001807,0.003883,0.098621,288.878723,14.716184,0.986207,-165.291214,294.500488,0.000000
118.240005,64.918297,-165.380173,-0.001819,0.003883,0.098621,288.770996,14.710696,0.986207,-165.380173,294.500488,0.000000
118.610008,64.884041,-165.380173,-0.001811,0.003883,0.098621,288.618622,14.702934,0.986207,-165.380173,294.500488,0.000000
118.980003,64.859093,-165.380173,-0.001798,0.003883,0.098638,288.507660,14.697281,0.986381,-165.380173,294.500488,0.000000
119.350006,65.639961,-165.424652,-0.001807,0.003892,0.098864,291.981140,14.874228,0.988637,-165.424652,294.500488,0.000000
119.720009,65.623207,-165.424652,-0.001819,0.003892,0.098864,291.906616,14.870431,0.988637,-165.424652,294.500488,0.000000
120.090004,65.638100,-165.513626,-0.001807,0.003892,0.098864,291.972839,14.873806,0.988637,-165.513626,294.500488,0.000000
120.460007,65.617241,-165.513626,-0.001807,0.003892,0.098864,291.880066,14.869080,0.988637,-165.513626,294.500488,0.000000
120.830009,65.586342,-165.558105,-0.001807,0.003892,0.098864,291.742615,14.862078,0.988637,-165.558105,294.500488,0.000000
121.200005,65.577766,-165.513626,-0.001807,0.003892,0.098864,291.704468,14.860134,0.988637,-165.513626,294.500488,0.000000
121.570007,65.556923,-165.602585,-0.001811,0.003892,0.098864,291.611755,14.855412,0.988637,-165.602585,294.500488,0.000000
121.940002,65.536064,-165.602585,-0.001811,0.003892,0.098864,291.518982,14.850684,0.988637,-165.602585,294.500488,0.000000
122.310005,65.501442,-165.691544,-0.001794,0.003892,0.098864,291.364960,14.842839,0.988637,-165.691544,294.500488,0.000000
122.680008,65.469414,-165.647064,-0.001802,0.003892,0.098864,291.222504,14.835581,0.988637,-165.647064,294.500488,0.000000
123.050003,65.446327,-165.691544,-0.001811,0.003892,0.098864,291.119812,14.830349,0.988637,-165.691544,294.500488,0.000000
123.420006,65.397911,-165.602585,-0.001802,0.003892,0.098864,290.904449,14.819378,0.988637,-165.602585,294.500488,0.000000
123.790009,65.368874,-165.691544,-0.001819,0.003892,0.098864,290.775269,14.812799,0.988637,-165.691544,294.500488,0.000000
124.160004,65.343925,-165.780502,-0.001815,0.003892,0.098864,290.664307,14.807145,0.988637,-165.780502,294.500488,0.000000
124.530006,65.317863,-165.824982,-0.001798,0.003892,0.098864,290.548370,14.801239,0.988637,-165.824982,294.500488,0.000000
124.900009,65.286201,-165.824982,-0.001802,0.003892,0.098864,290.407532,14.794065,0.988637,-165.824982,294.500488,0.000000
125.270004,65.277275,-165.869461,-0.001798,0.003892,0.098864,290.367828,14.792042,0.988637,-165.869461,294.500488,0.000000
125.640007,65.239662,-165.869461,-0.001811,0.003892,0.098864,290.200500,14.783519,0.988637,-165.869461,294.500488,0.000000
126.010010,65.207268,-165.958435,-0.001802,0.003892,0.098864,290.056427,14.776178,0.988637,-165.958435,294.500488,0.000000
126.380005,65.197578,-165.913940,-0.001802,0.003893,0.098881,290.013306,14.773982,0.988808,-165.913940,294.500488,0.000000
126.750008,65.176735,-165.958435,-0.001789,0.003893,0.098881,289.920593,14.769259,0.988808,-165.958435,1681.640991,0.000000
127.120003,65.103004,-165.958435,-0.001802,0.003881,0.098577,289.592621,14.752552,0.985772,-165.958435,0.098369,0.000000
127.490005,65.011772,-166.047394,-0.001794,0.003862,0.098083,289.186798,14.731878,0.980829,-166.047394,0.097754,0.000000
127.860008,64.915321,-166.047394,-0.001802,0.003841,0.097572,288.757782,14.710022,0.975716,-166.047394,0.097138,0.000000
128.230011,64.816643,-166.136353,-0.001802,0.003822,0.097086,288.318817,14.687661,0.970856,-166.136353,0.096522,0.000000
128.600006,64.776421,-166.091873,-0.001789,0.003795,0.096401,288.139923,14.678547,0.964005,-166.091873,0.095906,0.000000
128.970001,64.755943,-166.136353,-0.001794,0.003771,0.095785,288.048828,14.673906,0.957851,-166.136353,0.095291,0.000000
129.340012,64.720940,-166.136353,-0.001789,0.003749,0.095212,287.893127,14.665975,0.952124,-166.136353,0.094675,0.000000
129.710007,64.672157,-166.225311,-0.001798,0.003729,0.094709,287.676117,14.654920,0.947094,-166.225311,0.094050,0.000000
130.080002,64.619652,-166.269791,-0.001794,0.003703,0.094068,287.442566,14.643023,0.940679,-166.269791,0.093435,0.000000
130.450012,64.524696,-166.225311,-0.001789,0.003681,0.093496,287.020172,14.621505,0.934956,-166.225311,0.092819,0.000000
130.820007,64.091637,-166.225311,-0.001776,0.003655,0.092845,285.093842,14.523373,0.928450,-166.225311,0.092203,0.000000
131.190002,63.288048,-166.225311,-0.001776,0.003633,0.092281,281.519287,14.341276,0.922814,-166.225311,0.091588,0.000000
131.560013,62.258446,-166.269791,-0.001776,0.003612,0.091744,276.939392,14.107965,0.917436,-166.269791,0.090972,0.000000
131.930008,61.339058,-166.314270,-0.001768,0.003595,0.091302,272.849762,13.899630,0.913015,-166.314270,0.090356,0.000000
132.300003,59.705086,-166.358749,-0.001755,0.003567,0.090599,265.581482,13.529366,0.905990,-166.358749,0.089740,0.000000
132.670013,57.816788,-166.358749,-0.001755,0.003539,0.089879,257.181915,13.101471,0.898791,-166.358749,0.089125,0.000000
133.040009,56.032753,-166.403244,-0.001763,0.003516,0.089298,249.246140,12.697204,0.892982,-166.403244,0.088500,0.000000
133.410004,54.593155,-166.447723,-0.001763,0.003500,0.088899,242.842484,12.370986,0.888992,-166.447723,0.087885,0.000000
133.779999,52.300461,-166.447723,-0.001750,0.003475,0.088266,232.644073,11.851454,0.882660,-166.447723,0.087269,0.000000
134.150009,51.500229,-166.492203,-0.001768,0.003457,0.087815,229.084457,11.670118,0.878152,-166.492203,0.086653,0.000000
134.520004,48.324638,-166.581161,-0.001759,0.003433,0.087199,214.958725,10.950520,0.871994,-166.581161,0.086037,0.000000
134.889999,45.055954,-166.536682,-0.001755,0.003402,0.086419,200.418900,10.209825,0.864190,-166.536682,0.085422,0.000000
135.260010,42.786346,-166.625641,-0.001755,0.003383,0.085916,190.323181,9.695525,0.859160,-166.625641,0.084806,0.000000
135.630005,39.765289,-166.625641,-0.001768,0.003356,0.085231,176.884842,9.010943,0.852309,-166.625641,0.084190,0.000000
136.000000,37.259216,-166.670120,-0.001746,0.003331,0.084606,165.737274,8.443059,0.846064,-166.670120,0.083574,0.000000
136.370010,35.208565,-166.714600,-0.001742,0.003314,0.084173,156.615524,7.978375,0.841727,-166.714600,0.082950,0.000000
136.740005,31.904129,-166.714600,-0.001763,0.003281,0.083332,141.916656,7.229579,0.833317,-166.714600,0.082334,0.000000
137.110001,29.477753,-166.714600,-0.001759,0.003259,0.082785,131.123596,6.679754,0.827851,-166.714600,0.081719,0.000000
137.480011,26.448875,-166.759079,-0.001738,0.003231,0.082066,117.650475,5.993401,0.820656,-166.759079,0.081103,0.000000
137.850006,24.155060,-166.803574,-0.001759,0.003209,0.081510,107.447075,5.473615,0.815104,-166.803574,0.080487,0.000000
138.220001,21.430786,-166.848053,-0.001746,0.003183,0.080851,95.328896,4.856286,0.808514,-166.848053,0.079871,0.000000
138.590012,18.327805,-166.803574,-0.001750,0.003154,0.080123,81.526146,4.153140,0.801228,-166.803574,0.079256,0.000000
138.960007,16.097664,-166.848053,-0.001763,0.003134,0.079611,71.605988,3.647783,0.796111,-166.848053,0.078640,0.000000
139.330002,14.047752,-166.937012,-0.001746,0.003115,0.079126,62.487522,3.183266,0.791255,-166.937012,0.078024,0.000000
139.700012,11.180489,-166.981491,-0.001763,0.003090,0.078484,49.733295,2.533535,0.784840,-166.981491,0.077400,0.000000
140.070007,8.681496,-166.937012,-0.001738,0.003064,0.077825,38.617222,1.967255,0.778246,-166.937012,0.076784,0.000000
140.440002,6.701965,-166.937012,-0.001755,0.003048,0.077417,29.811831,1.518687,0.774170,-166.937012,0.076168,0.000000
140.810013,3.307785,-166.981491,-0.001746,0.003012,0.076515,14.713762,0.749555,0.765151,-166.981491,0.075553,0.000000
141.180008,1.408691,-167.070450,-0.001768,0.002993,0.076021,6.266172,0.319214,0.760208,-167.070450,0.074937,0.000000
141.550003,-1.400116,-167.159409,-0.001755,0.002966,0.075336,-6.228027,-0.317271,0.753357,-167.159409,0.074321,0.000000
141.920013,-3.394917,-167.114929,-0.001750,0.002943,0.074755,-15.101343,-0.769299,0.747547,-167.114929,0.073706,0.000000
142.290009,-0.284859,-167.070450,-0.001750,0.002927,0.074338,-1.267115,-0.064550,0.743384,-167.070450,0.073090,0.000000
142.660004,-0.112450,-167.159409,-0.001755,0.002893,0.073471,-0.500201,-0.025481,0.734712,-167.159409,0.072474,0.000000
143.030014,-0.065163,-167.159409,-0.001768,0.002870,0.072890,-0.289858,-0.014766,0.728903,-167.159409,0.071849,0.000000
143.400009,-0.075584,-167.203888,-0.001746,0.002846,0.072283,-0.336216,-0.017128,0.722832,-167.203888,0.071234,0.000000
143.770004,-0.049522,-167.248383,-0.001755,0.002825,0.071754,-0.220287,-0.011222,0.717540,-167.248383,0.070618,0.000000
144.139999,-0.084526,-167.248383,-0.001750,0.002799,0.071104,-0.375991,-0.019154,0.711038,-167.248383,0.070002,0.000000
144.510010,-0.139267,-167.248383,-0.001763,0.002773,0.070427,-0.619490,-0.031558,0.704274,-167.248383,0.069387,0.000000
144.880005,-0.126602,-167.337341,-0.001768,0.002748,0.069803,-0.563155,-0.028688,0.698029,-167.337341,0.068771,0.000000
145.250000,-0.102402,-167.426300,-0.001781,0.002733,0.069413,-0.455506,-0.023205,0.694127,-167.426300,0.068155,0.000000
145.620010,-0.110588,-167.337341,-0.001794,0.002703,0.068667,-0.491920,-0.025060,0.686667,-167.337341,0.067540,0.000000
145.990005,-0.115059,-167.381821,-0.001815,0.002669,0.067791,-0.511808,-0.026073,0.677909,-167.381821,0.066924,0.000000
146.360001,-0.128090,-167.426300,-0.001828,0.002655,0.067444,-0.569772,-0.029026,0.674442,-167.426300,0.066299,0.000000
146.730011,-0.111336,-167.515259,-0.001876,0.002625,0.066672,-0.495246,-0.025229,0.666721,-167.515259,0.065683,0.000000
147.100006,-0.144478,-167.515259,-0.001876,0.002601,0.066056,-0.642670,-0.032739,0.660563,-167.515259,0.065068,0.000000
147.470001,-0.129211,-167.559738,-0.001919,0.002574,0.065371,-0.574761,-0.029280,0.653712,-167.559738,0.064452,0.000000
147.840012,-0.117668,-167.515259,-0.001932,0.002551,0.064790,-0.523414,-0.026664,0.647902,-167.515259,0.063836,0.000000
148.210007,-0.134048,-167.604218,-0.001944,0.002529,0.064227,-0.596277,-0.030376,0.642266,-167.604218,0.063221,0.000000
148.580002,-0.099792,-167.604218,-0.001983,0.002499,0.063472,-0.443899,-0.022613,0.634719,-167.604218,0.062605,0.000000
148.950012,-0.116173,-167.693192,-0.001996,0.002479,0.062978,-0.516762,-0.026325,0.629776,-167.693192,0.061989,0.000000
149.320007,-0.115807,-167.693192,-0.002022,0.002452,0.062275,-0.515133,-0.026242,0.622751,-167.693192,0.061374,0.000000
149.690002,-0.110588,-167.693192,-0.002035,0.002428,0.061677,-0.491920,-0.025060,0.616768,-167.693192,0.060749,0.000000
149.900009,-0.113945,-167.737671,-0.002039,0.002429,0.061685,-0.506853,-0.025820,0.616855,-167.737671,0.061634,0.000000