File: Data/compression 16/ManualNoHeating-17-16-reverse-hand-1_08302024_170803.csv
Time (sec),S:Load (lbs),S:HL1 (DIM),S:LVDT (in),S:Position (in),Ch:Position (mm),Ch:Load (N),Ch:Stress (MPa),Ch:Strain (mm/mm),Ch:HL1 (DIM),Set Point (),Cycles ()
0.210000,0.004097,-45.592976,-0.005333,-0.005309,-0.134836,0.018224,0.000928,-1.348365,-45.592976,-0.134559,0.000000
0.570000,-0.005211,-45.637455,-0.005338,-0.005226,-0.132729,-0.023179,-0.001181,-1.327291,-45.637455,-0.131957,0.000000
0.930000,-0.022339,-45.770897,-0.005204,-0.005012,-0.127300,-0.099368,-0.005062,-1.273000,-45.770897,-0.125956,0.000000
1.290000,0.086021,-45.770897,-0.004975,-0.004773,-0.121247,0.382642,0.019493,-1.212468,-45.770897,-0.119955,0.000000
1.650000,0.056229,-45.770897,-0.004941,-0.000001,-0.000017,0.250117,0.012742,-0.000170,-45.770897,0.000217,0.000000
2.010000,0.124001,-45.770897,-0.004945,-0.000001,-0.000017,0.551582,0.028099,-0.000170,-45.770897,0.000503,0.000000
2.370000,0.121773,-45.815380,-0.004924,-0.000000,-0.000008,0.541672,0.027594,-0.000083,-45.815380,0.001101,0.000000
2.730000,0.112457,-45.904343,-0.004941,-0.000000,-0.000008,0.500235,0.025483,-0.000083,-45.904343,0.001709,0.000000
3.090000,0.398445,-45.904343,-0.004911,0.000052,0.001310,1.772372,0.090289,0.013096,-45.904343,0.002307,0.000000
3.450000,0.601387,-45.904343,-0.004876,0.000077,0.001960,2.675103,0.136276,0.019602,-45.904343,0.002905,0.000000
3.810000,0.888855,-45.993305,-0.004868,0.000102,0.002584,3.953825,0.201417,0.025843,-45.993305,0.003504,0.000000
4.170000,1.131645,-46.037785,-0.004833,0.000124,0.003140,5.033809,0.256434,0.031396,-46.037785,0.004102,0.000000
4.530000,1.446297,-46.126747,-0.004820,0.000145,0.003686,6.433449,0.327736,0.036857,-46.126747,0.004709,0.000000
4.890000,1.843246,-46.082264,-0.004803,0.000169,0.004293,8.199170,0.417686,0.042928,-46.082264,0.005308,0.000000
5.250000,2.304619,-46.126747,-0.004790,0.000192,0.004883,10.251456,0.522234,0.048825,-46.126747,0.005906,0.000000
5.610000,2.711250,-46.126747,-0.004777,0.000216,0.005481,12.060244,0.614378,0.054809,-46.126747,0.006504,0.000000
5.970000,2.902649,-46.171227,-0.004747,0.000234,0.005949,12.911627,0.657750,0.059495,-46.171227,0.007103,0.000000
6.330000,3.535683,-46.260189,-0.004734,0.000260,0.006600,15.727502,0.801197,0.065997,-46.260189,0.007710,0.000000
6.690001,4.029816,-46.260189,-0.004717,0.000282,0.007172,17.925516,0.913169,0.071720,-46.260189,0.008308,0.000000
7.050000,4.426392,-46.304668,-0.004700,0.000303,0.007692,19.689573,1.003035,0.076924,-46.304668,0.008907,0.000000
7.410000,5.117516,-46.393631,-0.004674,0.000336,0.008534,22.763845,1.159646,0.085338,-46.393631,0.009505,0.000000
7.770000,5.481697,-46.349152,-0.004652,0.000359,0.009106,24.383806,1.242170,0.091061,-46.349152,0.010103,0.000000
8.130000,5.975090,-46.438114,-0.004635,0.000382,0.009704,26.578527,1.353975,0.097045,-46.438114,0.010702,0.000000
8.490001,6.493431,-46.482594,-0.004596,0.000408,0.010363,28.884224,1.471432,0.103634,-46.482594,0.011309,0.000000
8.850000,6.684090,-46.482594,-0.004583,0.000426,0.010823,29.732315,1.514636,0.108233,-46.482594,0.011907,0.000000
9.210000,7.136894,-46.571556,-0.004575,0.000446,0.011335,31.746490,1.617243,0.113350,-46.571556,0.012506,0.000000
9.570001,7.511131,-46.571556,-0.004536,0.000469,0.011925,33.411182,1.702047,0.119247,-46.571556,0.013104,0.000000
9.930000,8.010109,-46.660519,-0.004523,0.000501,0.012723,35.630745,1.815117,0.127225,-46.660519,0.013702,0.000000
10.290001,8.278214,-46.616035,-0.004510,0.000523,0.013286,36.823334,1.875870,0.132861,-46.616035,0.014310,0.000000
10.650001,8.640907,-46.749481,-0.004488,0.000547,0.013893,38.436676,1.958058,0.138932,-46.749481,0.014908,0.000000
11.010000,8.853157,-46.704998,-0.004458,0.000566,0.014388,39.380810,2.006154,0.143875,-46.704998,0.015506,0.000000
11.370001,9.238937,-46.704998,-0.004445,0.000594,0.015090,41.096848,2.093573,0.150900,-46.704998,0.016105,0.000000
11.730000,9.699562,-46.793961,-0.004428,0.000620,0.015749,43.145805,2.197952,0.157489,-46.793961,0.016703,0.000000
12.090000,9.898033,-46.793961,-0.004389,0.000644,0.016347,44.028652,2.242926,0.163473,-46.793961,0.017310,0.000000
12.450001,10.050713,-46.882923,-0.004368,0.000665,0.016885,44.707802,2.277524,0.168852,-46.882923,0.017908,0.000000
12.810000,10.275246,-46.927402,-0.004368,0.000687,0.017440,45.706577,2.328404,0.174400,-46.927402,0.018507,0.000000
13.170001,10.773109,-46.927402,-0.004324,0.000712,0.018073,47.921185,2.441221,0.180733,-46.927402,0.019105,0.000000
13.530001,11.015900,-47.016365,-0.004290,0.000738,0.018741,49.001167,2.496238,0.187409,-47.016365,0.019703,0.000000
13.890000,11.290337,-47.060844,-0.004277,0.000764,0.019400,50.221924,2.558427,0.193999,-47.060844,0.020311,0.000000
14.250001,11.498863,-47.105328,-0.004268,0.000785,0.019938,51.149498,2.605680,0.199377,-47.105328,0.020909,0.000000
14.610001,11.588608,-47.060844,-0.004247,0.000805,0.020449,51.548702,2.626016,0.204494,-47.060844,0.021507,0.000000
14.970000,11.748726,-47.149807,-0.004217,0.000826,0.020979,52.260944,2.662299,0.209785,-47.149807,0.022106,0.000000
15.330001,11.806442,-47.283253,-0.004199,0.000842,0.021386,52.517677,2.675378,0.213858,-47.283253,0.022704,0.000000
15.690001,12.113281,-47.238770,-0.004178,0.000862,0.021898,53.882565,2.744909,0.218975,-47.238770,0.023302,0.000000
16.050001,12.712425,-47.327732,-0.004152,0.000893,0.022678,56.547691,2.880677,0.226780,-47.327732,0.023910,0.000000
16.410000,13.071396,-47.283253,-0.004148,0.000917,0.023294,58.144474,2.962021,0.232938,-47.283253,0.024508,0.000000
16.770000,13.526062,-47.283253,-0.004113,0.000946,0.024031,60.166927,3.065049,0.240311,-47.283253,0.025106,0.000000
17.130001,13.314926,-47.372211,-0.004096,0.000964,0.024473,59.227749,3.017205,0.244731,-47.372211,0.025705,0.000000
17.490002,13.517494,-47.416695,-0.004092,0.000984,0.025002,60.128819,3.063108,0.250023,-47.416695,0.026303,0.000000
17.850000,14.004929,-47.461174,-0.004057,0.001017,0.025826,62.297035,3.173562,0.258262,-47.461174,0.026910,0.000000
18.210001,13.506699,-47.461174,-0.004044,0.001024,0.026000,60.080795,3.060662,0.259996,-47.461174,0.027509,0.000000
18.570002,14.487900,-47.505657,-0.004010,0.001064,0.027023,64.445396,3.283005,0.270230,-47.505657,0.028107,0.000000
18.930000,14.542641,-47.594616,-0.003980,0.001085,0.027560,64.688896,3.295409,0.275605,-47.594616,0.028705,0.000000
19.290001,14.734413,-47.550137,-0.003962,0.001111,0.028229,65.541946,3.338866,0.282285,-47.550137,0.029304,0.000000
19.650002,14.956718,-47.639099,-0.003936,0.001136,0.028861,66.530807,3.389241,0.288613,-47.639099,0.029911,0.000000
20.010000,14.770531,-47.683578,-0.003928,0.001153,0.029286,65.702599,3.347050,0.292864,-47.683578,0.030509,0.000000
20.370001,15.023743,-47.728062,-0.003923,0.001178,0.029928,66.828941,3.404429,0.299283,-47.728062,0.031108,0.000000
20.730001,15.637039,-47.861504,-0.003889,0.001205,0.030605,69.557022,3.543404,0.306047,-47.861504,0.031706,0.000000
21.090000,15.617302,-47.772541,-0.003867,0.001229,0.031212,69.469231,3.538931,0.312118,-47.772541,0.032304,0.000000
21.450001,15.979248,-47.905983,-0.003854,0.001254,0.031862,71.079247,3.620949,0.318620,-47.905983,0.032912,0.000000
21.810001,15.583794,-47.861504,-0.003824,0.001267,0.032183,69.320175,3.531338,0.321830,-47.861504,0.033510,0.000000
22.170002,16.095062,-47.905983,-0.003816,0.001297,0.032955,71.594414,3.647193,0.329547,-47.905983,0.034108,0.000000
22.530001,16.598877,-47.950466,-0.003816,0.001328,0.033726,73.835495,3.761359,0.337264,-47.950466,0.034707,0.000000
22.890001,16.492378,-47.994946,-0.003773,0.001348,0.034229,73.361763,3.737226,0.342295,-47.994946,0.035305,0.000000
23.250002,16.518822,-48.039429,-0.003773,0.001371,0.034819,73.479385,3.743218,0.348191,-48.039429,0.035903,0.000000
23.610001,16.197464,-48.039429,-0.003751,0.001386,0.035201,72.049919,3.670398,0.352010,-48.039429,0.036510,0.000000
23.970001,16.231720,-48.083908,-0.003734,0.001406,0.035721,72.202293,3.678160,0.357211,-48.083908,0.037109,0.000000
24.330002,16.993217,-48.083908,-0.003708,0.001442,0.036632,75.589607,3.850718,0.366317,-48.083908,0.037707,0.000000
24.690001,17.287025,-48.172871,-0.003691,0.001473,0.037403,76.896530,3.917296,0.374035,-48.172871,0.038305,0.000000
25.050001,17.182388,-48.217350,-0.003678,0.001496,0.037993,76.431084,3.893585,0.379932,-48.217350,0.038904,0.000000
25.410002,17.166000,-48.261833,-0.003652,0.001520,0.038600,76.358185,3.889871,0.386003,-48.261833,0.039511,0.000000
25.770000,16.963432,-48.306313,-0.003626,0.001538,0.039060,75.457115,3.843969,0.390601,-48.306313,0.040109,0.000000
26.130001,16.919495,-48.306313,-0.003635,0.001555,0.039493,75.261673,3.834012,0.394935,-48.306313,0.040708,0.000000
26.490002,16.713196,-48.306313,-0.003613,0.001570,0.039867,74.344009,3.787264,0.398667,-48.306313,0.041306,0.000000
26.850000,17.946869,-48.439754,-0.003587,0.001612,0.040951,79.831657,4.066819,0.409507,-48.439754,0.041904,0.000000
27.210001,17.520126,-48.439754,-0.003561,0.001627,0.041332,77.933411,3.970117,0.413322,-48.439754,0.042512,0.000000
27.570002,17.790840,-48.484238,-0.003535,0.001654,0.042017,79.137611,4.031462,0.420173,-48.484238,0.043110,0.000000
27.930002,17.807228,-48.573200,-0.003531,0.001675,0.042546,79.210510,4.035175,0.425464,-48.573200,0.043708,0.000000
28.290001,17.650085,-48.573200,-0.003527,0.001695,0.043041,78.511497,3.999567,0.430407,-48.573200,0.044307,0.000000
28.650002,18.182205,-48.573200,-0.003510,0.001726,0.043847,80.878487,4.120147,0.438473,-48.573200,0.044905,0.000000
29.010002,18.211998,-48.573200,-0.003497,0.001750,0.044446,81.011009,4.126898,0.444456,-48.573200,0.045512,0.000000
29.370001,18.444733,-48.662159,-0.003466,0.001778,0.045156,82.046272,4.179636,0.451564,-48.662159,0.046111,0.000000
29.730001,18.467445,-48.751122,-0.003445,0.001803,0.045798,82.147301,4.184783,0.457984,-48.751122,0.046709,0.000000
30.090002,18.224655,-48.662159,-0.003428,0.001823,0.046301,81.067314,4.129766,0.463014,-48.662159,0.047307,0.000000
30.450001,18.793266,-48.751122,-0.003428,0.001844,0.046839,83.596626,4.258615,0.468392,-48.751122,0.047906,0.000000
30.810001,19.155586,-48.795605,-0.003410,0.001870,0.047498,85.208305,4.340718,0.474982,-48.795605,0.048513,0.000000
31.170002,19.363747,-48.795605,-0.003385,0.001896,0.048166,86.134247,4.387887,0.481658,-48.795605,0.049111,0.000000
31.530001,19.147392,-48.929047,-0.003359,0.001915,0.048651,85.171852,4.338861,0.486514,-48.929047,0.049710,0.000000
31.890001,19.322411,-48.929047,-0.003367,0.001939,0.049259,85.950378,4.378521,0.492585,-48.929047,0.050308,0.000000
32.250000,19.357788,-48.973526,-0.003324,0.001961,0.049814,86.107742,4.386538,0.498138,-48.973526,0.050906,0.000000
32.610001,19.206230,-48.973526,-0.003320,0.001979,0.050265,85.433578,4.352194,0.502645,-48.973526,0.051505,0.000000
32.970001,20.003479,-49.062489,-0.003290,0.002013,0.051132,88.979919,4.532853,0.511317,-49.062489,0.052112,0.000000
33.330002,20.137909,-49.106972,-0.003277,0.002038,0.051774,89.577896,4.563315,0.517736,-49.106972,0.052710,0.000000
33.690002,20.119659,-49.106972,-0.003255,0.002059,0.052303,89.496712,4.559180,0.523027,-49.106972,0.053309,0.000000
34.050003,19.923790,-49.151451,-0.003251,0.002076,0.052736,88.625443,4.514795,0.527361,-49.151451,0.053907,0.000000
34.410000,20.112961,-49.195930,-0.003242,0.002106,0.053499,89.466919,4.557662,0.534995,-49.195930,0.054505,0.000000
34.770000,21.364876,-49.240414,-0.003208,0.002135,0.054219,95.035713,4.841350,0.542190,-49.240414,0.055112,0.000000
35.130001,21.206985,-49.329376,-0.003199,0.002157,0.054792,94.333382,4.805572,0.547917,-49.329376,0.055711,0.000000
35.490002,21.206985,-49.195930,-0.003182,0.002179,0.055355,94.333382,4.805572,0.553552,-49.195930,0.056309,0.000000
35.850002,21.189117,-49.373856,-0.003152,0.002199,0.055858,94.253899,4.801523,0.558582,-49.373856,0.056907,0.000000
36.210003,21.356682,-49.373856,-0.003139,0.002221,0.056413,94.999268,4.839493,0.564131,-49.373856,0.057506,0.000000
36.570004,21.754745,-49.373856,-0.003126,0.002249,0.057116,96.769943,4.929696,0.571156,-49.373856,0.058113,0.000000
36.930000,21.710060,-49.462818,-0.003122,0.002264,0.057506,96.571167,4.919570,0.575058,-49.462818,0.058711,0.000000
37.290001,21.740967,-49.507298,-0.003096,0.002283,0.057991,96.708649,4.926573,0.579914,-49.507298,0.059310,0.000000
37.650002,21.780815,-49.640743,-0.003083,0.002309,0.058651,96.885902,4.935603,0.586507,-49.640743,0.059908,0.000000
38.010002,23.327278,-49.551781,-0.003061,0.002341,0.059466,103.764915,5.286037,0.594660,-49.551781,0.060506,0.000000
38.370003,23.142578,-49.640743,-0.003035,0.002360,0.059952,102.943329,5.244183,0.599516,-49.640743,0.061114,0.000000
38.730003,23.511971,-49.685223,-0.003027,0.002386,0.060611,104.586472,5.327889,0.606106,-49.685223,0.061712,0.000000
39.090000,23.545113,-49.685223,-0.003005,0.002407,0.061140,104.733894,5.335399,0.611397,-49.685223,0.062310,0.000000
39.450001,23.601715,-49.729702,-0.002984,0.002425,0.061599,104.985672,5.348225,0.615992,-49.729702,0.062909,0.000000
39.810001,24.612709,-49.774185,-0.002979,0.002459,0.062449,109.482796,5.577320,0.624493,-49.774185,0.063507,0.000000
40.170002,24.711754,-49.774185,-0.002962,0.002481,0.063013,109.923370,5.599764,0.630128,-49.774185,0.064106,0.000000
40.530003,25.013748,-49.907627,-0.002945,0.002506,0.063654,111.266708,5.668196,0.636544,-49.907627,0.064713,0.000000
40.890003,25.449425,-49.907627,-0.002919,0.002533,0.064340,113.204697,5.766922,0.643398,-49.907627,0.065311,0.000000
41.250004,25.182808,-49.996590,-0.002902,0.002549,0.064756,112.018723,5.706506,0.647558,-49.996590,0.065909,0.000000
41.610001,24.671913,-49.907627,-0.002880,0.002562,0.065085,109.746147,5.590735,0.650854,-49.907627,0.066508,0.000000
41.970001,26.681236,-49.996590,-0.002867,0.002603,0.066109,118.684067,6.046055,0.661089,-49.996590,0.067106,0.000000
42.330002,26.599312,-50.041069,-0.002846,0.002620,0.066542,118.319649,6.027490,0.665422,-50.041069,0.067713,0.000000
42.690002,26.375893,-50.041069,-0.002828,0.002641,0.067071,117.325829,5.976862,0.670714,-50.041069,0.068312,0.000000
43.050003,27.252831,-50.174511,-0.002802,0.002666,0.067705,121.226646,6.175580,0.677046,-50.174511,0.068910,0.000000
43.410004,27.261017,-50.174511,-0.002790,0.002683,0.068155,121.263062,6.177435,0.681554,-50.174511,0.069508,0.000000
43.770000,27.360069,-50.218994,-0.002768,0.002711,0.068849,121.703667,6.199880,0.688491,-50.218994,0.070107,0.000000
44.130001,28.780296,-50.218994,-0.002746,0.002741,0.069621,128.021149,6.521708,0.696209,-50.218994,0.070714,0.000000
44.490002,28.490219,-50.263474,-0.002729,0.002754,0.069959,126.730827,6.455976,0.699592,-50.263474,0.071312,0.000000
44.850002,29.575317,-50.263474,-0.002699,0.002786,0.070766,131.557587,6.701863,0.707658,-50.263474,0.071910,0.000000
45.210003,29.867996,-50.352436,-0.002695,0.002809,0.071355,132.859482,6.768185,0.713555,-50.352436,0.072509,0.000000
45.570004,30.679398,-50.352436,-0.002682,0.002839,0.072101,136.468781,6.952051,0.721015,-50.352436,0.073107,0.000000
45.930000,30.951973,-50.396919,-0.002656,0.002856,0.072552,137.681259,7.013817,0.725523,-50.396919,0.073714,0.000000
46.290001,32.028877,-50.441399,-0.002626,0.002889,0.073376,142.471558,7.257847,0.733762,-50.441399,0.074313,0.000000
46.650002,32.016960,-50.574841,-0.002617,0.002911,0.073940,142.418549,7.255147,0.739398,-50.574841,0.074911,0.000000
47.010002,32.505516,-50.485878,-0.002596,0.002932,0.074460,144.591751,7.365855,0.744602,-50.485878,0.075509,0.000000
47.370003,33.035400,-50.574841,-0.002583,0.002953,0.075015,146.948807,7.485929,0.750151,-50.574841,0.076108,0.000000
47.730003,33.022736,-50.619324,-0.002565,0.002969,0.075414,146.892471,7.483059,0.754140,-50.619324,0.076706,0.000000
48.090004,33.571991,-50.619324,-0.002539,0.002991,0.075978,149.335678,7.607522,0.759780,-50.619324,0.077313,0.000000
48.450001,35.135208,-50.663803,-0.002522,0.003025,0.076828,156.289215,7.961752,0.768277,-50.663803,0.077912,0.000000
48.810001,34.800446,-50.708282,-0.002522,0.003043,0.077305,154.800110,7.885893,0.773046,-50.708282,0.078510,0.000000
49.170002,36.249344,-50.708282,-0.002496,0.003072,0.078024,161.245132,8.214218,0.780245,-50.708282,0.079108,0.000000
49.530003,36.879402,-50.841728,-0.002492,0.003093,0.078562,164.047775,8.356992,0.785623,-50.841728,0.079707,0.000000
49.890003,37.441307,-50.797245,-0.002462,0.003117,0.079161,166.547256,8.484322,0.791607,-50.797245,0.080314,0.000000
50.250004,38.144722,-50.886208,-0.002445,0.003137,0.079689,169.676193,8.643717,0.796894,-50.886208,0.080912,0.000000
50.610001,39.309502,-50.975170,-0.002432,0.003169,0.080505,174.857391,8.907660,0.805047,-50.975170,0.081511,0.000000
50.970001,39.912376,-50.930691,-0.002402,0.003192,0.081077,177.539124,9.044274,0.810770,-50.930691,0.082109,0.000000
51.330002,40.988533,-51.019650,-0.002393,0.003216,0.081693,182.326096,9.288135,0.816928,-51.019650,0.082708,0.000000
51.690002,40.272087,-51.019650,-0.002384,0.003226,0.081944,179.139191,9.125786,0.819445,-51.019650,0.083315,0.000000
52.050003,41.597733,-51.108612,-0.002354,0.003252,0.082603,185.035950,9.426181,0.826034,-51.108612,0.083913,0.000000
52.410004,43.446190,-51.019650,-0.002350,0.003289,0.083531,193.258301,9.845047,0.835315,-51.019650,0.084511,0.000000
52.770004,44.021873,-51.064133,-0.002328,0.003309,0.084060,195.819077,9.975499,0.840602,-51.064133,0.085110,0.000000
53.130001,44.551392,-51.197575,-0.002302,0.003329,0.084563,198.174484,10.095490,0.845633,-51.197575,0.085708,0.000000
53.490002,46.154823,-51.242054,-0.002302,0.003359,0.085327,205.306915,10.458833,0.853267,-51.242054,0.086315,0.000000
53.850002,46.357399,-51.242054,-0.002294,0.003375,0.085734,206.208008,10.504737,0.857339,-51.242054,0.086914,0.000000
54.210003,47.525154,-51.242054,-0.002264,0.003403,0.086445,211.402451,10.769354,0.864451,-51.242054,0.087512,0.000000
54.570004,49.162476,-51.286537,-0.002242,0.003432,0.087182,218.685608,11.140376,0.871824,-51.286537,0.088110,0.000000
54.930004,49.560547,-51.375500,-0.002229,0.003449,0.087607,220.456329,11.230580,0.876074,-51.375500,0.088709,0.000000
55.290001,50.339920,-51.375500,-0.002229,0.003472,0.088188,223.923141,11.407188,0.881884,-51.375500,0.089307,0.000000
55.650002,51.008698,-51.419979,-0.002220,0.003488,0.088605,226.898026,11.558737,0.886048,-51.419979,0.089914,0.000000
56.010002,53.325233,-51.419979,-0.002203,0.003526,0.089559,237.202484,12.083671,0.895586,-51.419979,0.090512,0.000000
56.370003,53.666321,-51.464462,-0.002164,0.003546,0.090079,238.719711,12.160962,0.900790,-51.464462,0.091111,0.000000
56.730003,55.007980,-51.553421,-0.002169,0.003571,0.090703,244.687714,12.464986,0.907035,-51.553421,0.091709,0.000000
57.090004,56.539925,-51.508942,-0.002134,0.003595,0.091319,251.502151,12.812130,0.913189,-51.508942,0.092308,0.000000
57.450005,57.325256,-51.642384,-0.002139,0.003617,0.091874,254.995468,12.990088,0.918742,-51.642384,0.092915,0.000000
57.810001,58.406250,-51.642384,-0.002117,0.003637,0.092386,259.803986,13.235045,0.923859,-51.642384,0.093513,0.000000
58.170002,59.422455,-51.686867,-0.002100,0.003659,0.092941,264.324280,13.465321,0.929407,-51.686867,0.094111,0.000000
58.530003,60.800606,-51.731346,-0.002108,0.003684,0.093583,270.454590,13.777614,0.935827,-51.731346,0.094710,0.000000
58.890003,61.685364,-51.731346,-0.002070,0.003706,0.094129,274.390198,13.978104,0.941288,-51.731346,0.095308,0.000000
59.250004,63.564720,-51.864788,-0.002070,0.003732,0.094788,282.750000,14.403972,0.947878,-51.864788,0.095915,0.000000
59.610004,64.833397,-51.820309,-0.002057,0.003755,0.095369,288.393341,14.691458,0.953691,-51.820309,0.096514,0.000000
59.970001,64.918678,-51.864788,-0.002035,0.003765,0.095620,288.772705,14.710783,0.956205,-51.864788,0.097112,0.000000
60.330002,65.448189,-51.953751,-0.002031,0.003776,0.095898,291.128082,14.830771,0.958979,-51.953751,0.016835,0.000000
60.690002,64.458427,-51.953751,-0.002009,0.003776,0.095898,286.725403,14.606488,0.958979,-51.953751,294.500488,0.000000
61.050003,65.964302,-52.042713,-0.002005,0.003755,0.095369,293.423859,14.947725,0.953691,-52.042713,294.500488,0.000000
61.410004,65.179329,-51.998230,-0.001992,0.003781,0.096037,289.932129,14.769847,0.960368,-51.998230,294.500488,0.000000
61.770004,65.063530,-52.042713,-0.001992,0.003805,0.096644,289.417023,14.743607,0.966439,-52.042713,294.500488,0.000000
62.130001,65.089226,-52.131676,-0.001992,0.003814,0.096869,289.531342,14.749430,0.968695,-52.131676,294.500488,0.000000
62.490002,65.534584,-52.087193,-0.001970,0.003825,0.097147,291.512390,14.850348,0.971469,-52.087193,294.500488,0.000000
62.850002,65.068733,-52.220638,-0.001966,0.003825,0.097156,289.440186,14.744785,0.971556,-52.220638,294.500488,0.000000
63.210003,64.555977,-52.220638,-0.001979,0.003825,0.097156,287.159332,14.628593,0.971556,-52.220638,294.500488,0.000000
63.570004,66.671425,-52.220638,-0.001944,0.003788,0.096228,296.569305,15.107961,0.962276,-52.220638,294.500488,0.000000
63.930004,66.038399,-52.354080,-0.001962,0.003789,0.096236,293.753479,14.964515,0.962363,-52.354080,294.500488,0.000000
64.290001,65.550957,-52.398560,-0.001949,0.003808,0.096722,291.585205,14.854059,0.967219,-52.398560,294.500488,0.000000
64.650002,65.126823,-52.443043,-0.001962,0.003819,0.096999,289.698578,14.757949,0.969993,-52.443043,294.500488,0.000000
65.010002,65.267952,-52.354080,-0.001944,0.003850,0.097788,290.326355,14.789929,0.977884,-52.354080,294.500488,0.000000
65.370003,65.104118,-52.487522,-0.001944,0.003853,0.097858,289.597595,14.752804,0.978581,-52.487522,294.500488,0.000000
65.730003,65.147682,-52.487522,-0.001940,0.003857,0.097979,289.791351,14.762676,0.979792,-52.487522,294.500488,0.000000
66.090004,65.136147,-52.487522,-0.001953,0.003862,0.098083,289.740051,14.760061,0.980833,-52.487522,294.500488,0.000000
66.450005,65.288063,-52.620964,-0.001944,0.003866,0.098205,290.415802,14.794487,0.982048,-52.620964,294.500488,0.000000
66.810005,65.141731,-52.576485,-0.001940,0.003868,0.098248,289.764893,14.761327,0.982483,-52.576485,294.500488,0.000000
67.170006,65.073204,-52.665447,-0.001923,0.003870,0.098291,289.460083,14.745798,0.982915,-52.665447,294.500488,0.000000
67.530006,65.235191,-52.709927,-0.001919,0.003874,0.098396,290.180634,14.782506,0.983955,-52.709927,294.500488,0.000000
67.890007,65.084755,-52.665447,-0.001923,0.003875,0.098430,289.511444,14.748417,0.984304,-52.665447,294.500488,0.000000
68.250000,65.196098,-52.798889,-0.001932,0.003879,0.098534,290.006744,14.773647,0.985344,-52.798889,294.500488,0.000000
68.610001,65.197960,-52.798889,-0.001927,0.003881,0.098586,290.015015,14.774069,0.985863,-52.798889,294.500488,0.000000
68.970001,65.264977,-52.843369,-0.001914,0.003886,0.098699,290.313110,14.789255,0.986991,-52.843369,294.500488,0.000000
69.330002,65.224388,-52.932331,-0.001923,0.003886,0.098699,290.132568,14.780058,0.986991,-52.932331,294.500488,0.000000
69.690002,65.673851,-52.843369,-0.001919,0.003894,0.098899,292.131866,14.881907,0.988985,-52.843369,294.500488,0.000000
70.050003,65.574791,-52.976814,-0.001906,0.003894,0.098899,291.691223,14.859460,0.988985,-52.976814,294.500488,0.000000
70.410004,65.435524,-52.887852,-0.001923,0.003894,0.098899,291.071747,14.827902,0.988985,-52.887852,294.500488,0.000000
70.770004,65.267220,-53.021294,-0.001919,0.003894,0.098899,290.323090,14.789763,0.988985,-53.021294,294.500488,0.000000
71.130005,65.095558,-53.065773,-0.001906,0.003894,0.098899,289.559509,14.750864,0.988985,-53.065773,294.500488,0.000000
71.490005,64.943245,-53.110256,-0.001910,0.003894,0.098899,288.881989,14.716350,0.988985,-53.110256,294.500488,0.000000
71.850006,64.765251,-53.154736,-0.001897,0.003894,0.098907,288.090240,14.676016,0.989073,-53.154736,294.500488,0.000000
72.210007,64.615562,-53.110256,-0.001906,0.003894,0.098907,287.424377,14.642096,0.989073,-53.110256,294.500488,0.000000
72.570000,64.464012,-53.199219,-0.001893,0.003894,0.098907,286.750244,14.607754,0.989073,-53.199219,294.500488,0.000000
72.930000,66.663612,-53.243698,-0.001876,0.003850,0.097780,296.534546,15.106191,0.977797,-53.243698,294.500488,0.000000
73.290001,66.425667,-53.288177,-0.001893,0.003850,0.097788,295.476135,15.052271,0.977884,-53.288177,294.500488,0.000000
73.650002,66.230171,-53.332661,-0.001880,0.003850,0.097788,294.606506,15.007971,0.977884,-53.332661,294.500488,0.000000
74.010002,66.061852,-53.332661,-0.001880,0.003850,0.097788,293.857788,14.969830,0.977884,-53.332661,294.500488,0.000000
74.370003,65.879768,-53.332661,-0.001876,0.003850,0.097797,293.047852,14.928569,0.977971,-53.332661,294.500488,0.000000
74.730003,65.766197,-53.421623,-0.001884,0.003851,0.097815,292.542664,14.902833,0.978146,-53.421623,294.500488,0.000000
75.090004,65.602730,-53.466103,-0.001876,0.003871,0.098318,291.815521,14.865791,0.983176,-53.466103,294.500488,0.000000
75.450005,65.516335,-53.555065,-0.001888,0.003879,0.098526,291.431213,14.846213,0.985257,-53.555065,294.500488,0.000000
75.810005,65.377815,-53.466103,-0.001876,0.003885,0.098673,290.815033,14.814825,0.986730,-53.466103,294.500488,0.000000
76.170006,65.324928,-53.555065,-0.001880,0.003897,0.098994,290.579803,14.802840,0.989939,-53.555065,294.500488,0.000000
76.530006,65.243752,-53.688507,-0.001884,0.003903,0.099124,290.218689,14.784445,0.991241,-53.688507,294.500488,0.000000
76.890007,65.176735,-53.599545,-0.001871,0.003908,0.099254,289.920593,14.769259,0.992543,-53.599545,294.500488,0.000000
77.250000,65.043419,-53.732990,-0.001893,0.003910,0.099315,289.327576,14.739050,0.993149,-53.732990,294.500488,0.000000
77.610001,65.454887,-53.688507,-0.001888,0.003918,0.099523,291.157867,14.832290,0.995231,-53.688507,294.500488,0.000000
77.970001,65.372963,-53.732990,-0.001876,0.003918,0.099523,290.793457,14.813725,0.995231,-53.732990,294.500488,0.000000
78.330002,65.283592,-53.777470,-0.001888,0.003918,0.099523,290.395935,14.793474,0.995231,-53.777470,294.500488,0.000000
78.690002,65.216942,-53.732990,-0.001888,0.003919,0.099532,290.099457,14.778370,0.995318,-53.732990,294.500488,0.000000
79.050003,65.165932,-53.866432,-0.001880,0.003921,0.099592,289.872528,14.766811,0.995923,-53.866432,294.500488,0.000000
79.410004,65.142845,-53.866432,-0.001876,0.003921,0.099592,289.769836,14.761580,0.995923,-53.866432,294.500488,0.000000
79.770004,65.267952,-53.866432,-0.001884,0.003924,0.099662,290.326355,14.789929,0.996616,-53.866432,294.500488,0.000000
80.130005,65.212471,-53.999874,-0.001871,0.003924,0.099662,290.079559,14.777357,0.996616,-53.999874,294.500488,0.000000
80.490005,65.151039,-53.910912,-0.001867,0.003925,0.099705,289.806305,14.763437,0.997051,-53.910912,294.500488,0.000000
80.850006,65.238548,-54.044357,-0.001876,0.003926,0.099731,290.195557,14.783267,0.997312,-54.044357,294.500488,0.000000
81.210007,65.202797,-54.044357,-0.001876,0.003928,0.099766,290.036530,14.775166,0.997657,-54.044357,294.500488,0.000000
81.570007,65.306313,-54.088837,-0.001876,0.003929,0.099809,290.496979,14.798622,0.998092,-54.088837,294.500488,0.000000
81.930000,65.282478,-54.133316,-0.001876,0.003929,0.099809,290.390961,14.793221,0.998092,-54.133316,294.500488,0.000000
82.290001,65.233696,-54.088837,-0.001876,0.003929,0.099809,290.173981,14.782166,0.998092,-54.088837,294.500488,0.000000
82.650002,65.239662,-54.266762,-0.001867,0.003931,0.099853,290.200500,14.783519,0.998527,-54.266762,294.500488,0.000000
83.010002,65.210609,-54.222279,-0.001871,0.003931,0.099853,290.071289,14.776936,0.998527,-54.222279,294.500488,0.000000
83.370003,65.201302,-54.266762,-0.001871,0.003933,0.099887,290.029877,14.774826,0.998872,-54.266762,294.500488,0.000000
83.730003,65.167793,-54.311241,-0.001867,0.003934,0.099913,289.880829,14.767234,0.999133,-54.311241,294.500488,0.000000
84.090004,65.196465,-54.355721,-0.001867,0.003934,0.099931,290.008362,14.773730,0.999307,-54.355721,294.500488,0.000000
84.450005,65.175606,-54.355721,-0.001867,0.003935,0.099948,289.915588,14.769003,0.999481,-54.355721,294.500488,0.000000
84.810005,65.161095,-54.311241,-0.001880,0.003935,0.099948,289.851013,14.765716,0.999481,-54.311241,294.500488,0.000000
85.170006,65.124229,-54.489166,-0.001867,0.003935,0.099956,289.687042,14.757361,0.999564,-54.489166,294.500488,0.000000
85.530006,65.095924,-54.444683,-0.001880,0.003936,0.099983,289.561127,14.750948,0.999825,-54.444683,294.500488,0.000000
85.890007,65.061668,-54.533646,-0.001863,0.003938,0.100017,289.408752,14.743185,1.000174,-54.533646,294.500488,0.000000
86.250008,65.210991,-54.622608,-0.001876,0.003939,0.100043,290.072968,14.777021,1.000435,-54.622608,294.500488,0.000000
86.610001,65.162956,-54.622608,-0.001871,0.003939,0.100043,289.859314,14.766137,1.000435,-54.622608,294.500488,0.000000
86.970001,65.117897,-54.578129,-0.001858,0.003939,0.100043,289.658875,14.755926,1.000435,-54.578129,294.500488,0.000000
87.330002,65.061668,-54.622608,-0.001867,0.003939,0.100043,289.408752,14.743185,1.000435,-54.622608,294.500488,0.000000
87.690002,65.038948,-54.711571,-0.001863,0.003940,0.100078,289.307678,14.738036,1.000779,-54.711571,294.500488,0.000000
88.050003,65.078423,-54.756050,-0.001876,0.003941,0.100113,289.483276,14.746982,1.001127,-54.756050,294.500488,0.000000
88.410004,65.097420,-54.800533,-0.001867,0.003941,0.100113,289.567780,14.751287,1.001127,-54.800533,294.500488,0.000000
88.770004,65.095177,-54.845013,-0.001863,0.003943,0.100148,289.557800,14.750778,1.001476,-54.845013,294.500488,0.000000
89.130005,65.137260,-54.889492,-0.001854,0.003943,0.100165,289.744995,14.760314,1.001646,-54.889492,294.500488,0.000000
89.490005,65.119377,-54.933975,-0.001850,0.003943,0.100165,289.665466,14.756262,1.001646,-54.933975,294.500488,0.000000
89.850006,65.074333,-54.978455,-0.001858,0.003944,0.100173,289.465088,14.746055,1.001733,-54.978455,294.500488,0.000000
90.210007,65.063148,-55.022938,-0.001854,0.003944,0.100173,289.415344,14.743520,1.001733,-55.022938,294.500488,0.000000
90.570007,65.012886,-55.022938,-0.001845,0.003944,0.100182,289.191772,14.732131,1.001820,-55.022938,294.500488,0.000000
90.930008,65.018837,-55.022938,-0.001863,0.003946,0.100226,289.218231,14.733479,1.002255,-55.022938,294.500488,0.000000
91.290001,65.118645,-55.022938,-0.001854,0.003947,0.100260,289.662201,14.756096,1.002600,-55.022938,294.500488,0.000000
91.650002,65.119377,-55.067417,-0.001876,0.003947,0.100260,289.665466,14.756262,1.002600,-55.067417,294.500488,0.000000
92.010002,65.099648,-55.156380,-0.001854,0.003947,0.100260,289.577698,14.751791,1.002600,-55.156380,294.500488,0.000000
92.370003,65.077675,-55.156380,-0.001845,0.003947,0.100260,289.479950,14.746812,1.002600,-55.156380,294.500488,0.000000
92.730003,65.012886,-55.245342,-0.001850,0.003947,0.100260,289.191772,14.732131,1.002600,-55.245342,294.500488,0.000000
93.090004,64.981606,-55.245342,-0.001854,0.003948,0.100269,289.052612,14.725042,1.002687,-55.245342,294.500488,0.000000
93.450005,64.949211,-55.334305,-0.001867,0.003948,0.100277,288.908508,14.717702,1.002774,-55.334305,294.500488,0.000000
93.810005,65.022194,-55.334305,-0.001850,0.003950,0.100330,289.233154,14.734240,1.003296,-55.334305,294.500488,0.000000
94.170006,65.009911,-55.423264,-0.001854,0.003950,0.100330,289.178528,14.731456,1.003296,-55.423264,294.500488,0.000000
94.530006,64.998360,-55.423264,-0.001854,0.003950,0.100330,289.127136,14.728839,1.003296,-55.423264,294.500488,0.000000
94.890007,64.969688,-55.467747,-0.001850,0.003950,0.100330,288.999603,14.722342,1.003296,-55.467747,294.500488,0.000000
95.250008,64.958153,-55.467747,-0.001854,0.003950,0.100330,288.948303,14.719728,1.003296,-55.467747,294.500488,0.000000
95.610008,64.906013,-55.512226,-0.001858,0.003950,0.100330,288.716370,14.707913,1.003296,-55.512226,294.500488,0.000000
95.970001,65.024055,-55.556709,-0.001850,0.003953,0.100408,289.241455,14.734662,1.004076,-55.556709,294.500488,0.000000
96.330002,65.019218,-55.601189,-0.001854,0.003953,0.100408,289.219940,14.733565,1.004076,-55.601189,294.500488,0.000000
96.690002,65.022942,-55.690151,-0.001832,0.003953,0.100408,289.236481,14.734409,1.004076,-55.690151,294.500488,0.000000
97.050003,64.995750,-55.690151,-0.001845,0.003953,0.100408,289.115540,14.728248,1.004076,-55.690151,294.500488,0.000000
97.410004,64.962990,-55.645668,-0.001837,0.003953,0.100408,288.969818,14.720823,1.004076,-55.645668,294.500488,0.000000
97.770004,64.931709,-55.779114,-0.001841,0.003953,0.100408,288.830658,14.713736,1.004076,-55.779114,294.500488,0.000000
98.130005,64.893730,-55.734631,-0.001858,0.003953,0.100408,288.661743,14.705130,1.004076,-55.734631,294.500488,0.000000
98.490005,64.859840,-55.868076,-0.001845,0.003953,0.100408,288.510986,14.697450,1.004076,-55.868076,294.500488,0.000000
98.850006,64.814781,-55.868076,-0.001850,0.003953,0.100408,288.310547,14.687239,1.004076,-55.868076,294.500488,0.000000
99.210007,64.777168,-55.823593,-0.001841,0.003953,0.100408,288.143250,14.678717,1.004076,-55.823593,294.500488,0.000000
99.570007,64.737328,-55.957035,-0.001845,0.003953,0.100408,287.966003,14.669687,1.004076,-55.957035,294.500488,0.000000
99.930008,65.062035,-55.957035,-0.001863,0.003959,0.100546,289.410370,14.743267,1.005465,-55.957035,294.500488,0.000000
100.290009,65.092949,-55.957035,-0.001837,0.003959,0.100546,289.547913,14.750273,1.005465,-55.957035,294.500488,0.000000
100.650002,65.088097,-56.045998,-0.001854,0.003959,0.100546,289.526306,14.749174,1.005465,-56.045998,294.500488,0.000000
101.010002,65.067253,-56.045998,-0.001845,0.003959,0.100555,289.433594,14.744451,1.005548,-56.045998,294.500488,0.000000
101.370003,65.033730,-56.090481,-0.001845,0.003959,0.100555,289.284485,14.736854,1.005548,-56.090481,294.500488,0.000000
101.730003,65.025551,-56.179440,-0.001832,0.003959,0.100555,289.248108,14.735001,1.005548,-56.179440,294.500488,0.000000
102.090004,65.001717,-56.134960,-0.001854,0.003959,0.100555,289.142090,14.729600,1.005548,-56.134960,294.500488,0.000000
102.450005,64.965965,-56.179440,-0.001854,0.003959,0.100555,288.983032,14.721498,1.005548,-56.179440,294.500488,0.000000
102.810005,64.945107,-56.134960,-0.001841,0.003959,0.100555,288.890259,14.716771,1.005548,-56.134960,294.500488,0.000000
103.170006,64.903038,-56.312885,-0.001850,0.003959,0.100555,288.703125,14.707239,1.005548,-56.312885,294.500488,0.000000
103.530006,64.881813,-56.268402,-0.001841,0.003959,0.100555,288.608704,14.702429,1.005548,-56.268402,294.500488,0.000000
103.890007,64.835258,-56.357365,-0.001845,0.003959,0.100555,288.401642,14.691880,1.005548,-56.357365,294.500488,0.000000
104.250008,64.834511,-56.401848,-0.001858,0.003960,0.100590,288.398315,14.691710,1.005896,-56.401848,294.500488,0.000000
104.610008,64.840843,-56.446327,-0.001841,0.003960,0.100590,288.426483,14.693146,1.005896,-56.446327,294.500488,0.000000
104.970001,64.814415,-56.446327,-0.001841,0.003960,0.100590,288.308929,14.687157,1.005896,-56.446327,294.500488,0.000000
105.330002,64.806221,-56.490807,-0.001854,0.003960,0.100590,288.272461,14.685300,1.005896,-56.490807,294.500488,0.000000
105.690002,64.771217,-56.579769,-0.001841,0.003960,0.100590,288.116760,14.677368,1.005896,-56.579769,294.500488,0.000000
106.050003,64.744774,-56.579769,-0.001841,0.003960,0.100590,287.999146,14.671375,1.005896,-56.579769,294.500488,0.000000
106.410004,64.733238,-56.535290,-0.001837,0.003960,0.100590,287.947815,14.668761,1.005896,-56.535290,294.500488,0.000000
106.770004,65.765450,-56.668732,-0.001832,0.003972,0.100884,292.539337,14.902664,1.008845,-56.668732,294.500488,0.000000
107.130005,65.770668,-56.668732,-0.001845,0.003972,0.100884,292.562531,14.903846,1.008845,-56.668732,294.500488,0.000000
107.490005,65.775124,-56.757694,-0.001832,0.003972,0.100884,292.582367,14.904856,1.008845,-56.757694,294.500488,0.000000
107.850006,65.770668,-56.757694,-0.001832,0.003972,0.100884,292.562531,14.903846,1.008845,-56.757694,294.500488,0.000000
108.210007,65.769173,-56.802174,-0.001832,0.003972,0.100884,292.555878,14.903507,1.008845,-56.802174,294.500488,0.000000
108.570007,65.752037,-56.846657,-0.001828,0.003972,0.100884,292.479675,14.899625,1.008845,-56.846657,294.500488,0.000000
108.930008,65.720024,-56.802174,-0.001828,0.003972,0.100884,292.337280,14.892370,1.008845,-56.802174,294.500488,0.000000
109.290009,65.674965,-56.846657,-0.001824,0.003972,0.100884,292.136841,14.882160,1.008845,-56.846657,294.500488,0.000000
109.650002,65.636238,-56.935616,-0.001837,0.003972,0.100884,291.964569,14.873384,1.008845,-56.935616,294.500488,0.000000
110.010002,65.613152,-56.935616,-0.001832,0.003972,0.100884,291.861877,14.868153,1.008845,-56.935616,294.500488,0.000000
110.370003,65.591545,-57.024578,-0.001837,0.003972,0.100884,291.765778,14.863256,1.008845,-57.024578,294.500488,0.000000
110.730003,65.566978,-56.980099,-0.001824,0.003972,0.100884,291.656494,14.857690,1.008845,-56.980099,294.500488,0.000000
111.090004,65.547234,-57.113541,-0.001828,0.003972,0.100884,291.568665,14.853215,1.008845,-57.113541,294.500488,0.000000
111.450005,65.527504,-57.113541,-0.001841,0.003972,0.100884,291.480896,14.848745,1.008845,-57.113541,294.500488,0.000000
111.810005,65.491753,-57.113541,-0.001837,0.003972,0.100884,291.321869,14.840643,1.008845,-57.113541,294.500488,0.000000
112.170006,65.483559,-57.202503,-0.001832,0.003972,0.100884,291.285431,14.838787,1.008845,-57.202503,294.500488,0.000000
112.530006,65.439995,-57.202503,-0.001828,0.003972,0.100884,291.091644,14.828915,1.008845,-57.202503,294.500488,0.000000
112.890007,65.385262,-57.246983,-0.001819,0.003972,0.100884,290.848175,14.816512,1.008845,-57.246983,294.500488,0.000000
113.250008,65.367012,-57.291466,-0.001832,0.003972,0.100884,290.766998,14.812377,1.008845,-57.291466,294.500488,0.000000
113.610008,65.337593,-57.335945,-0.001824,0.003972,0.100884,290.636139,14.805711,1.008845,-57.335945,294.500488,0.000000
113.970009,65.320839,-57.380428,-0.001828,0.003972,0.100884,290.561615,14.801914,1.008845,-57.380428,294.500488,0.000000
114.330002,65.293648,-57.335945,-0.001819,0.003972,0.100884,290.440643,14.795753,1.008845,-57.335945,294.500488,0.000000
114.690002,65.267952,-57.469387,-0.001828,0.003972,0.100884,290.326355,14.789929,1.008845,-57.469387,294.500488,0.000000
115.050003,65.250832,-57.424908,-0.001832,0.003972,0.100884,290.250183,14.786049,1.008845,-57.424908,294.500488,0.000000
115.410004,65.213966,-57.513870,-0.001828,0.003972,0.100884,290.086212,14.777697,1.008845,-57.513870,294.500488,0.000000
115.770004,65.199074,-57.558350,-0.001845,0.003972,0.100884,290.019958,14.774321,1.008845,-57.558350,294.500488,0.000000
116.130005,65.151039,-57.558350,-0.001832,0.003972,0.100884,289.806305,14.763437,1.008845,-57.558350,294.500488,0.000000
116.490005,65.113426,-57.691795,-0.001832,0.003972,0.100884,289.638977,14.754913,1.008845,-57.691795,294.500488,0.000000
116.850006,65.095924,-57.647312,-0.001824,0.003972,0.100884,289.561127,14.750948,1.008845,-57.647312,294.500488,0.000000
117.210007,65.060555,-57.691795,-0.001824,0.003972,0.100884,289.403809,14.742932,1.008845,-57.691795,294.500488,0.000000
117.570007,65.042305,-57.780754,-0.001819,0.003972,0.100884,289.322632,14.738797,1.008845,-57.780754,294.500488,0.000000
117.930008,65.006187,-57.736275,-0.001832,0.003972,0.100884,289.161957,14.730613,1.008845,-57.736275,294.500488,0.000000
118.290009,64.998741,-57.825237,-0.001828,0.003972,0.100884,289.128845,14.728925,1.008845,-57.825237,294.500488,0.000000
118.650009,64.970436,-57.825237,-0.001832,0.003972,0.100884,289.002930,14.722511,1.008845,-57.825237,294.500488,0.000000
119.010002,64.943993,-57.914200,-0.001815,0.003972,0.100884,288.885315,14.716518,1.008845,-57.914200,294.500488,0.000000
119.370003,64.921654,-57.914200,-0.001815,0.003972,0.100884,288.785950,14.711456,1.008845,-57.914200,294.500488,0.000000
119.730003,64.886284,-57.958679,-0.001841,0.003972,0.100884,288.628601,14.703442,1.008845,-57.958679,294.500488,0.000000
120.090004,64.861336,-58.003159,-0.001824,0.003972,0.100884,288.517639,14.697789,1.008845,-58.003159,294.500488,0.000000
120.450005,64.829308,-58.003159,-0.001811,0.003972,0.100884,288.375153,14.690531,1.008845,-58.003159,294.500488,0.000000
120.810005,64.812920,-58.136604,-0.001832,0.003969,0.100824,288.302277,14.686818,1.008239,-58.136604,0.100884,0.000000
121.170006,64.726158,-58.136604,-0.001841,0.003958,0.100538,287.916321,14.667156,1.005378,-58.136604,0.100330,0.000000
121.530006,64.639397,-58.092121,-0.001828,0.003941,0.100113,287.530396,14.647496,1.001127,-58.092121,0.099731,0.000000
121.890007,64.571617,-58.181084,-0.001837,0.003926,0.099714,287.228912,14.632137,0.997138,-58.181084,0.099133,0.000000
122.250008,64.477409,-58.181084,-0.001828,0.003901,0.099081,286.809845,14.610789,0.990806,-58.181084,0.098534,0.000000
122.610008,64.475182,-58.314526,-0.001815,0.003876,0.098439,286.799927,14.610285,0.984391,-58.314526,0.097927,0.000000
122.970009,64.425652,-58.225563,-0.001819,0.003854,0.097893,286.579620,14.599061,0.978925,-58.225563,0.097329,0.000000
123.330009,64.410393,-58.359009,-0.001832,0.003831,0.097312,286.511749,14.595603,0.973115,-58.359009,0.096731,0.000000
123.690002,64.373146,-58.359009,-0.001828,0.003809,0.096739,286.346069,14.587163,0.967393,-58.359009,0.096132,0.000000
124.050003,64.340004,-58.359009,-0.001837,0.003786,0.096158,286.198639,14.579654,0.961583,-58.359009,0.095534,0.000000
124.410004,64.174309,-58.447971,-0.001824,0.003759,0.095482,285.461578,14.542106,0.954815,-58.447971,0.094927,0.000000
124.770004,63.943428,-58.403488,-0.001824,0.003741,0.095031,284.434570,14.489788,0.950308,-58.403488,0.094328,0.000000
125.130005,63.159966,-58.536930,-0.001802,0.003717,0.094424,280.949554,14.312252,0.944237,-58.536930,0.093730,0.000000
125.490005,62.283768,-58.581413,-0.001798,0.003696,0.093886,277.052032,14.113704,0.938862,-58.581413,0.093132,0.000000
125.850006,61.354698,-58.581413,-0.001789,0.003682,0.093522,272.919342,13.903173,0.935217,-58.581413,0.092533,0.000000
126.210007,59.397881,-58.670376,-0.001798,0.003648,0.092655,264.214966,13.459752,0.926546,-58.670376,0.091926,0.000000
126.570007,57.878601,-58.670376,-0.001785,0.003627,0.092125,257.456879,13.115478,0.921255,-58.670376,0.091328,0.000000
126.930008,56.802818,-58.714855,-0.001794,0.003614,0.091796,252.671555,12.871702,0.917962,-58.714855,0.090729,0.000000
127.290009,55.183365,-58.670376,-0.001781,0.003594,0.091284,245.467865,12.504728,0.912845,-58.670376,0.090131,0.000000
127.650009,52.843750,-58.803818,-0.001794,0.003567,0.090599,235.060745,11.974565,0.905994,-58.803818,0.089532,0.000000
128.010010,51.127487,-58.803818,-0.001798,0.003549,0.090157,227.426422,11.585654,0.901570,-58.803818,0.088934,0.000000
128.370010,48.018921,-58.848297,-0.001789,0.003517,0.089324,213.598831,10.881243,0.893243,-58.848297,0.088327,0.000000
128.730011,45.764206,-58.892780,-0.001785,0.003498,0.088847,203.569351,10.370317,0.888474,-58.892780,0.087729,0.000000
129.090012,42.902153,-58.892780,-0.001785,0.003470,0.088127,190.838303,9.721766,0.881275,-58.892780,0.087130,0.000000
129.450012,42.281410,-58.937260,-0.001785,0.003457,0.087816,188.077103,9.581105,0.878156,-58.937260,0.086532,0.000000
129.810013,38.466080,-58.937260,-0.001785,0.003427,0.087052,171.105667,8.716537,0.870522,-58.937260,0.085933,0.000000
130.170013,35.318039,-58.937260,-0.001776,0.003400,0.086358,157.102478,8.003181,0.863584,-58.937260,0.085327,0.000000
130.529999,32.283951,-59.070702,-0.001798,0.003373,0.085673,143.606186,7.315648,0.856734,-59.070702,0.084728,0.000000
130.889999,29.914543,-59.070702,-0.001794,0.003350,0.085101,133.066528,6.778733,0.851011,-59.070702,0.084130,0.000000
131.250000,28.958290,-59.115185,-0.001781,0.003344,0.084936,128.812912,6.562042,0.849365,-59.115185,0.083531,0.000000
131.610001,25.108337,-59.248627,-0.001802,0.003305,0.083956,111.687462,5.689631,0.839562,-59.248627,0.082933,0.000000
131.970001,23.165665,-59.204147,-0.001807,0.003290,0.083566,103.046021,5.249414,0.835659,-59.204147,0.082326,0.000000
132.330002,19.279213,-59.248627,-0.001785,0.003252,0.082612,85.758224,4.368732,0.826121,-59.248627,0.081728,0.000000
132.690002,17.331337,-59.248627,-0.001789,0.003235,0.082178,77.093636,3.927337,0.821784,-59.248627,0.081129,0.000000
133.050003,14.715790,-59.293106,-0.001794,0.003210,0.081528,65.459099,3.334646,0.815282,-59.293106,0.080531,0.000000
133.410004,12.217545,-59.426552,-0.001789,0.003186,0.080912,54.346352,2.768535,0.809124,-59.426552,0.079932,0.000000
133.770004,9.571838,-59.337589,-0.001785,0.003163,0.080331,42.577663,2.169009,0.803314,-59.337589,0.079325,0.000000
134.130005,7.155510,-59.471031,-0.001798,0.003138,0.079698,31.829298,1.621462,0.796982,-59.471031,0.078727,0.000000
134.490005,4.762650,-59.426552,-0.001789,0.003116,0.079143,21.185324,1.079232,0.791433,-59.426552,0.078129,0.000000
134.850006,2.361214,-59.515514,-0.001789,0.003092,0.078536,10.503203,0.535059,0.785362,-59.515514,0.077530,0.000000
135.210007,0.065544,-59.471031,-0.001802,0.003069,0.077955,0.291555,0.014853,0.779552,-59.471031,0.076932,0.000000
135.570007,-1.500286,-59.604473,-0.001781,0.003052,0.077521,-6.673606,-0.339970,0.775215,-59.604473,0.076325,0.000000
135.930008,-0.354492,-59.648956,-0.001802,0.003019,0.076680,-1.576860,-0.080329,0.766805,-59.648956,0.075726,0.000000
136.290009,-0.065163,-59.604473,-0.001794,0.002995,0.076065,-0.289858,-0.014766,0.760647,-59.604473,0.075128,0.000000
136.650009,-0.077446,-59.693436,-0.001794,0.002973,0.075509,-0.344497,-0.017550,0.755094,-59.693436,0.074529,0.000000
137.010010,0.008568,-59.693436,-0.001807,0.002955,0.075059,0.038112,0.001941,0.750586,-59.693436,0.073931,0.000000
137.370010,0.002235,-59.737919,-0.001811,0.002936,0.074564,0.009944,0.000507,0.745643,-59.737919,0.073333,0.000000
137.730011,-0.025688,-59.826878,-0.001828,0.002910,0.073905,-0.114267,-0.005821,0.739050,-59.826878,0.072726,0.000000
138.090012,-0.059204,-59.782398,-0.001841,0.002884,0.073246,-0.263353,-0.013416,0.732460,-59.782398,0.072127,0.000000
138.450012,-0.061813,-59.915840,-0.001867,0.002859,0.072613,-0.274960,-0.014007,0.726128,-59.915840,0.071529,0.000000
138.810013,-0.024948,-59.915840,-0.001893,0.002840,0.072127,-0.110975,-0.005653,0.721272,-59.915840,0.070930,0.000000
139.170013,-0.046913,-59.960323,-0.001910,0.002808,0.071329,-0.208680,-0.010631,0.713294,-59.960323,0.070332,0.000000
139.530014,-0.033134,-60.004803,-0.001940,0.002793,0.070948,-0.147389,-0.007508,0.709479,-60.004803,0.069725,0.000000
139.889999,-0.060692,-60.004803,-0.001944,0.002762,0.070150,-0.269971,-0.013753,0.701500,-60.004803,0.069127,0.000000
140.250000,-0.042450,-60.049282,-0.001970,0.002739,0.069578,-0.188827,-0.009619,0.695777,-60.049282,0.068528,0.000000
140.610001,-0.046913,-60.093765,-0.001992,0.002715,0.068962,-0.208680,-0.010631,0.689619,-60.093765,0.067930,0.000000
140.970001,-0.052872,-60.138245,-0.002018,0.002686,0.068225,-0.235185,-0.011981,0.682250,-60.138245,0.067332,0.000000
141.330002,-0.060692,-60.182728,-0.002035,0.002668,0.067774,-0.269971,-0.013753,0.677738,-60.182728,0.066725,0.000000
141.690002,-0.042816,-60.182728,-0.002039,0.002650,0.067314,-0.190456,-0.009702,0.673144,-60.182728,0.066126,0.000000
142.050003,-0.013405,-60.227207,-0.002082,0.002616,0.066456,-0.059628,-0.003038,0.664556,-60.227207,0.065528,0.000000
142.410004,-0.060318,-60.271690,-0.002095,0.002595,0.065918,-0.268308,-0.013668,0.659181,-60.271690,0.064929,0.000000
142.770004,-0.038727,-60.360649,-0.002100,0.002573,0.065363,-0.172265,-0.008776,0.653629,-60.360649,0.064331,0.000000
143.130005,-0.042450,-60.360649,-0.002134,0.002551,0.064791,-0.188827,-0.009619,0.647906,-60.360649,0.063724,0.000000
143.490005,-0.053619,-60.360649,-0.002143,0.002528,0.064201,-0.238511,-0.012150,0.642009,-60.360649,0.063126,0.000000
143.850006,-0.070000,-60.405132,-0.002190,0.002502,0.063542,-0.311374,-0.015862,0.635420,-60.405132,0.062527,0.000000
144.210007,-0.083778,-60.405132,-0.002199,0.002477,0.062917,-0.372665,-0.018984,0.629174,-60.405132,0.061929,0.000000
144.570007,-0.068512,-60.449612,-0.002212,0.002453,0.062310,-0.304756,-0.015525,0.623103,-60.449612,0.061330,0.000000
144.930008,-0.065536,-60.583054,-0.002220,0.002444,0.062067,-0.291521,-0.014851,0.620674,-60.583054,0.060732,0.000000
145.290009,-0.061813,-60.538574,-0.002242,0.002412,0.061261,-0.274960,-0.014007,0.612612,-60.538574,0.060125,0.000000
145.650009,-0.083405,-60.672016,-0.002276,0.002384,0.060541,-0.371002,-0.018900,0.605413,-60.672016,0.059527,0.000000
146.010010,-0.064415,-60.627537,-0.002307,0.002358,0.059899,-0.286532,-0.014597,0.598994,-60.627537,0.058928,0.000000
146.370010,-0.066650,-60.716499,-0.002307,0.002343,0.059509,-0.296476,-0.015103,0.595091,-60.716499,0.058330,0.000000
146.730011,-0.062553,-60.716499,-0.002345,0.002310,0.058668,-0.278251,-0.014175,0.586681,-60.716499,0.057731,0.000000
147.090012,-0.073723,-60.760979,-0.002341,0.002299,0.058399,-0.327936,-0.016706,0.583990,-60.760979,0.057124,0.000000
147.450012,-0.077446,-60.805462,-0.002384,0.002262,0.057454,-0.344497,-0.017550,0.574539,-60.805462,0.056526,0.000000
147.810013,-0.082291,-60.760979,-0.002397,0.002235,0.056760,-0.366047,-0.018647,0.567602,-60.760979,0.055928,0.000000
148.170013,-0.057343,-60.894421,-0.002419,0.002215,0.056257,-0.255072,-0.012994,0.562572,-60.894421,0.055329,0.000000
148.530014,-0.069633,-60.849941,-0.002440,0.002191,0.055650,-0.309745,-0.015779,0.556501,-60.849941,0.054731,0.000000
148.890015,-0.058090,-60.938904,-0.002445,0.002177,0.055286,-0.258398,-0.013163,0.552860,-60.938904,0.054124,0.000000
149.250000,-0.076332,-60.938904,-0.002483,0.002150,0.054609,-0.339542,-0.017297,0.546092,-60.938904,0.053525,0.000000
149.610001,-0.072609,-60.983383,-0.002492,0.002124,0.053950,-0.322981,-0.016453,0.539503,-60.983383,0.052927,0.000000
149.970001,-0.075218,-61.027866,-0.002518,0.002100,0.053343,-0.334587,-0.017045,0.533432,-61.027866,0.052328,0.000000
150.330002,-0.058456,-61.072346,-0.002539,0.002074,0.052676,-0.260027,-0.013246,0.526755,-61.072346,0.051730,0.000000
150.690002,-0.080429,-61.116825,-0.002565,0.002051,0.052086,-0.357766,-0.018225,0.520858,-61.116825,0.051123,0.000000
150.800003,-0.036491,-61.116825,-0.002570,0.002054,0.052181,-0.162322,-0.008269,0.521812,-61.116825,0.052068,0.000000