File: Data/compression 31/ManualNoHeating-15-31-reverse-1-3_11132024_175409.csv
Time (sec),S:Load (lbs),S:HL1 (DIM),S:LVDT (in),S:Position (in),Ch:Position (mm),Ch:Load (N),Ch:Stress (MPa),Ch:Strain (mm/mm),Ch:HL1 (DIM),Set Point (),Cycles ()
0.110000,-0.052879,-241.042267,-0.010080,-0.005369,-0.136362,-0.235219,-0.011983,-1.363622,-241.042267,-0.136162,0.000000
0.490000,-0.056976,-241.042267,-0.010076,-0.005312,-0.134932,-0.253443,-0.012911,-1.349315,-241.042267,-0.134427,0.000000
0.870000,-0.055855,-241.131241,-0.009981,-0.005083,-0.129112,-0.248455,-0.012657,-1.291119,-241.131241,-0.128097,0.000000
1.250000,-0.036865,-241.131241,-0.009761,-0.004834,-0.122780,-0.163985,-0.008354,-1.227805,-241.131241,-0.121766,0.000000
1.630000,-0.070007,-241.131241,-0.009490,-0.004584,-0.116432,-0.311408,-0.015864,-1.164325,-241.131241,-0.115436,0.000000
2.010000,-0.129585,-241.175720,-0.009257,-0.004336,-0.110145,-0.576424,-0.029364,-1.101450,-241.175720,-0.109105,0.000000
2.390000,-0.103523,-241.264679,-0.008977,-0.004091,-0.103911,-0.460494,-0.023459,-1.039105,-241.264679,-0.102774,0.000000
2.770000,-0.065163,-241.309158,-0.008731,-0.003841,-0.097553,-0.289858,-0.014766,-0.975534,-241.309158,-0.096444,0.000000
3.150000,-0.049156,-241.353638,-0.008481,-0.003589,-0.091171,-0.218658,-0.011139,-0.911705,-241.353638,-0.090112,0.000000
3.530000,-0.051758,-241.309158,-0.008222,-0.003339,-0.084823,-0.230230,-0.011728,-0.848225,-241.309158,-0.083782,0.000000
3.910000,-0.083786,-241.309158,-0.007963,-0.003088,-0.078423,-0.372699,-0.018986,-0.784230,-241.309158,-0.077451,0.000000
4.290000,-0.086761,-241.398117,-0.007705,-0.002836,-0.072031,-0.385934,-0.019660,-0.720311,-241.398117,-0.071121,0.000000
4.670000,-0.026810,-241.442596,-0.007437,-0.002590,-0.065788,-0.119255,-0.006075,-0.657875,-241.442596,-0.064790,0.000000
5.050000,0.008560,-241.442596,-0.007205,-0.002345,-0.059570,0.038078,0.001940,-0.595697,-241.442596,-0.058458,0.000000
5.430000,-0.010803,-241.531570,-0.006942,-0.002095,-0.053213,-0.048055,-0.002448,-0.532126,-241.531570,-0.052129,0.000000
5.810000,-0.046547,-241.442596,-0.006670,-0.001843,-0.046804,-0.207051,-0.010548,-0.468040,-241.442596,-0.045797,0.000000
6.190000,-0.059952,-241.576050,-0.006403,-0.001593,-0.040464,-0.266679,-0.013585,-0.404636,-241.576050,-0.039467,0.000000
6.570000,-0.049896,-241.665009,-0.006153,-0.001349,-0.034271,-0.221950,-0.011307,-0.342715,-241.665009,-0.033136,0.000000
6.950000,-0.008194,-241.620529,-0.005928,-0.001102,-0.027993,-0.036449,-0.001857,-0.279931,-241.620529,-0.026805,0.000000
7.330000,0.003723,-241.620529,-0.005648,-0.000852,-0.021628,0.016561,0.000844,-0.216284,-241.620529,-0.020475,0.000000
7.710001,-0.014526,-241.665009,-0.005394,-0.000599,-0.015220,-0.064617,-0.003292,-0.152198,-241.665009,-0.014143,0.000000
8.090000,-0.011169,-241.709488,-0.005131,-0.000348,-0.008837,-0.049684,-0.002531,-0.088370,-241.709488,-0.007814,0.000000
8.470000,-0.014526,-241.753967,-0.004881,-0.000097,-0.002471,-0.064617,-0.003292,-0.024708,-241.753967,-0.001482,0.000000
8.850000,0.223419,-241.798447,-0.004652,0.000006,0.000165,0.993818,0.050628,0.001650,-241.798447,0.000330,0.000000
9.230000,0.083038,-241.798447,-0.004644,0.000004,0.000104,0.369373,0.018817,0.001045,-241.798447,0.000330,0.000000
9.610001,0.184326,-241.798447,-0.004631,0.000004,0.000104,0.819924,0.041769,0.001045,-241.798447,0.000772,0.000000
9.990001,0.269966,-241.931900,-0.004644,0.000025,0.000633,1.200869,0.061175,0.006328,-241.931900,0.001405,0.000000
10.370001,0.436790,-241.931900,-0.004631,0.000044,0.001110,1.942941,0.098978,0.011097,-241.931900,0.002038,0.000000
10.750001,0.647552,-241.931900,-0.004605,0.000074,0.001882,2.880457,0.146737,0.018818,-241.931900,0.002671,0.000000
11.130000,0.860176,-241.931900,-0.004570,0.000100,0.002533,3.826254,0.194919,0.025329,-241.931900,0.003303,0.000000
11.510000,1.101479,-241.976379,-0.004557,0.000118,0.003001,4.899621,0.249599,0.030007,-241.976379,0.003936,0.000000
11.890000,1.492470,-242.065338,-0.004566,0.000149,0.003780,6.638837,0.338198,0.037804,-242.065338,0.004571,0.000000
12.270000,1.804146,-242.065338,-0.004523,0.000169,0.004292,8.025242,0.408825,0.042921,-242.065338,0.005203,0.000000
12.650001,2.196625,-242.065338,-0.004506,0.000197,0.005013,9.771075,0.497762,0.050127,-242.065338,0.005836,0.000000
13.030001,2.532135,-242.109818,-0.004475,0.000221,0.005602,11.263499,0.573790,0.056016,-242.109818,0.006469,0.000000
13.410001,2.827423,-242.154297,-0.004454,0.000241,0.006113,12.577006,0.640703,0.061134,-242.154297,0.007102,0.000000
13.790001,3.372574,-242.198776,-0.004428,0.000271,0.006876,15.001958,0.764236,0.068764,-242.198776,0.007735,0.000000
14.170001,3.767662,-242.243256,-0.004415,0.000294,0.007467,16.759398,0.853764,0.074668,-242.243256,0.008369,0.000000
14.550001,4.136314,-242.243256,-0.004402,0.000319,0.008091,18.399246,0.937302,0.080906,-242.243256,0.009002,0.000000
14.930000,4.730621,-242.287735,-0.004368,0.000345,0.008758,21.042854,1.071974,0.087582,-242.287735,0.009635,0.000000
15.310000,5.073204,-242.332214,-0.004342,0.000371,0.009418,22.566738,1.149604,0.094183,-242.332214,0.010268,0.000000
15.690001,5.618355,-242.376709,-0.004320,0.000397,0.010095,24.991690,1.273137,0.100951,-242.376709,0.010900,0.000000
16.070002,5.931519,-242.376709,-0.004312,0.000421,0.010684,26.384712,1.344101,0.106840,-242.376709,0.011533,0.000000
16.450001,6.450981,-242.376709,-0.004281,0.000444,0.011274,28.695396,1.461813,0.112744,-242.376709,0.012168,0.000000
16.830000,6.881073,-242.465668,-0.004264,0.000471,0.011959,30.608541,1.559273,0.119588,-242.465668,0.012801,0.000000
17.210001,7.199448,-242.421188,-0.004234,0.000496,0.012592,32.024742,1.631418,0.125916,-242.421188,0.013433,0.000000
17.590000,7.713692,-242.510147,-0.004217,0.000522,0.013268,34.312214,1.747947,0.132683,-242.510147,0.014066,0.000000
17.970001,8.035797,-242.554626,-0.004195,0.000547,0.013885,35.745010,1.820938,0.138845,-242.554626,0.014699,0.000000
18.350000,8.547440,-242.510147,-0.004178,0.000573,0.014543,38.020908,1.936877,0.145431,-242.510147,0.015332,0.000000
18.730001,8.995399,-242.643585,-0.004139,0.000599,0.015211,40.013535,2.038387,0.152107,-242.643585,0.015965,0.000000
19.110001,9.025932,-242.643585,-0.004148,0.000615,0.015627,40.149353,2.045305,0.156271,-242.643585,0.016599,0.000000
19.490002,9.730461,-242.688065,-0.004109,0.000647,0.016443,43.283253,2.204954,0.164431,-242.688065,0.017232,0.000000
19.870001,9.952400,-242.599106,-0.004083,0.000667,0.016946,44.270489,2.255246,0.169457,-242.599106,0.017874,0.000000
20.250002,10.337433,-242.688065,-0.004061,0.000694,0.017622,45.983196,2.342496,0.176225,-242.688065,0.018507,0.000000
20.630001,10.948494,-242.732544,-0.004023,0.000721,0.018316,48.701332,2.480964,0.183159,-242.732544,0.019139,0.000000
21.010000,10.956688,-242.777023,-0.004018,0.000740,0.018802,48.737782,2.482821,0.188018,-242.777023,0.019772,0.000000
21.390001,11.633286,-242.865997,-0.003992,0.000770,0.019565,51.747440,2.636140,0.195649,-242.865997,0.020405,0.000000
21.770000,11.982948,-242.821518,-0.003958,0.000794,0.020163,53.302814,2.715375,0.201629,-242.821518,0.021038,0.000000
22.150002,12.206741,-242.821518,-0.003945,0.000816,0.020726,54.298298,2.766087,0.207261,-242.821518,0.021672,0.000000
22.530001,12.839027,-242.865997,-0.003923,0.000847,0.021516,57.110847,2.909365,0.215164,-242.865997,0.022305,0.000000
22.910002,12.948135,-242.954956,-0.003885,0.000868,0.022036,57.596184,2.934089,0.220357,-242.954956,0.022938,0.000000
23.290001,13.527916,-242.999435,-0.003880,0.000896,0.022756,60.175175,3.065470,0.227563,-242.999435,0.023571,0.000000
23.670002,13.870132,-243.043915,-0.003850,0.000920,0.023363,61.697430,3.143017,0.233634,-243.043915,0.024204,0.000000
24.050001,13.815765,-242.999435,-0.003816,0.000936,0.023771,61.455593,3.130697,0.237707,-242.999435,0.024836,0.000000
24.430000,14.709831,-243.043915,-0.003803,0.000972,0.024690,65.432594,3.333296,0.246896,-243.043915,0.025471,0.000000
24.810001,14.708710,-243.132874,-0.003777,0.000992,0.025192,65.427612,3.333041,0.251923,-243.132874,0.026104,0.000000
25.190001,15.201736,-243.132874,-0.003751,0.001019,0.025895,67.620705,3.444763,0.258947,-243.132874,0.026736,0.000000
25.570002,15.622139,-243.132874,-0.003734,0.001045,0.026555,69.490746,3.540027,0.265548,-243.132874,0.027369,0.000000
25.950001,15.661240,-243.177353,-0.003704,0.001063,0.027004,69.664673,3.548888,0.270045,-243.177353,0.028002,0.000000
26.330002,16.481949,-243.177353,-0.003673,0.001097,0.027872,73.315369,3.734863,0.278720,-243.177353,0.028635,0.000000
26.710001,16.490143,-243.221848,-0.003652,0.001118,0.028402,73.351822,3.736720,0.284019,-243.221848,0.029269,0.000000
27.090002,16.934380,-243.266327,-0.003630,0.001146,0.029104,75.327881,3.837385,0.291043,-243.266327,0.029902,0.000000
27.470001,17.291862,-243.266327,-0.003622,0.001171,0.029746,76.918045,3.918392,0.297462,-243.266327,0.030535,0.000000
27.850000,17.257225,-243.355286,-0.003574,0.001189,0.030196,76.763969,3.910543,0.301959,-243.355286,0.031168,0.000000
28.230001,18.189278,-243.444244,-0.003540,0.001224,0.031082,80.909950,4.121749,0.310816,-243.444244,0.031801,0.000000
28.610001,18.088364,-243.444244,-0.003535,0.001243,0.031584,80.461060,4.098882,0.315842,-243.444244,0.032434,0.000000
28.990002,18.247742,-243.399765,-0.003505,0.001266,0.032147,81.170006,4.134997,0.321474,-243.399765,0.033068,0.000000
29.370001,18.896416,-243.533203,-0.003475,0.001296,0.032910,84.055458,4.281989,0.329104,-243.533203,0.033701,0.000000
29.750002,18.955994,-243.488724,-0.003458,0.001316,0.033422,84.320473,4.295489,0.334221,-243.488724,0.034334,0.000000
30.130001,19.690308,-243.533203,-0.003423,0.001347,0.034220,87.586861,4.461887,0.342200,-243.533203,0.034966,0.000000
30.510002,19.698875,-243.577682,-0.003402,0.001372,0.034836,87.624977,4.463829,0.348362,-243.577682,0.035599,0.000000
30.890001,19.851921,-243.622162,-0.003380,0.001391,0.035331,88.305756,4.498509,0.353312,-243.622162,0.036241,0.000000
31.270002,20.487556,-243.577682,-0.003359,0.001421,0.036094,91.133202,4.642547,0.360943,-243.577682,0.036874,0.000000
31.650002,20.489792,-243.622162,-0.003320,0.001441,0.036606,91.143143,4.643054,0.366060,-243.622162,0.037507,0.000000
32.030003,21.267311,-243.711136,-0.003307,0.001471,0.037351,94.601723,4.819242,0.373509,-243.711136,0.038141,0.000000
32.410000,21.358536,-243.711136,-0.003298,0.001492,0.037897,95.007515,4.839913,0.378974,-243.711136,0.038774,0.000000
32.790001,21.442322,-243.711136,-0.003264,0.001514,0.038453,95.380211,4.858900,0.384530,-243.711136,0.039407,0.000000
33.170002,22.158768,-243.711136,-0.003221,0.001545,0.039251,98.567123,5.021249,0.392509,-243.711136,0.040040,0.000000
33.550003,22.017265,-243.844574,-0.003199,0.001564,0.039728,97.937691,4.989184,0.397278,-243.844574,0.040672,0.000000
33.930000,22.350166,-243.889053,-0.003182,0.001589,0.040370,99.418503,5.064620,0.403697,-243.889053,0.041305,0.000000
34.310001,22.151321,-243.889053,-0.003156,0.001604,0.040751,98.533997,5.019561,0.407512,-243.889053,0.041938,0.000000
34.690002,22.991768,-243.844574,-0.003134,0.001637,0.041575,102.272491,5.210009,0.415748,-243.844574,0.042572,0.000000
35.070004,23.488136,-243.933533,-0.003113,0.001667,0.042338,104.480446,5.322488,0.423378,-243.933533,0.043205,0.000000
35.450001,23.653473,-243.978012,-0.003087,0.001689,0.042901,105.215904,5.359954,0.429010,-243.978012,0.043838,0.000000
35.830002,23.334717,-244.066986,-0.003040,0.001703,0.043266,103.798004,5.287722,0.432659,-244.066986,0.044471,0.000000
36.210003,24.712128,-244.022491,-0.003035,0.001743,0.044280,109.925034,5.599848,0.442802,-244.022491,0.045104,0.000000
36.590000,24.423912,-244.022491,-0.002997,0.001763,0.044775,108.642990,5.534537,0.447753,-244.022491,0.045737,0.000000
36.970001,24.789581,-244.066986,-0.002975,0.001790,0.045460,110.269562,5.617399,0.454596,-244.066986,0.046371,0.000000
37.350002,25.168655,-244.200424,-0.002940,0.001814,0.046085,111.955772,5.703299,0.460849,-244.200424,0.047004,0.000000
37.730003,25.752533,-244.155945,-0.002932,0.001842,0.046795,114.552986,5.835607,0.467949,-244.155945,0.047637,0.000000
38.110001,26.061234,-244.244904,-0.002897,0.001868,0.047446,115.926155,5.905560,0.474459,-244.244904,0.048270,0.000000
38.490002,26.016548,-244.200424,-0.002863,0.001891,0.048035,115.727386,5.895434,0.480349,-244.200424,0.048902,0.000000
38.870003,26.548294,-244.244904,-0.002850,0.001916,0.048669,118.092712,6.015929,0.486692,-244.244904,0.049535,0.000000
39.250000,26.738205,-244.289383,-0.002811,0.001939,0.049258,118.937477,6.058964,0.492581,-244.289383,0.050170,0.000000
39.630001,26.845078,-244.333862,-0.002790,0.001960,0.049787,119.412872,6.083181,0.497865,-244.333862,0.050802,0.000000
40.010002,27.992729,-244.333862,-0.002772,0.001995,0.050672,124.517876,6.343243,0.506722,-244.333862,0.051435,0.000000
40.390003,27.523163,-244.333862,-0.002734,0.002013,0.051123,122.429146,6.236838,0.511233,-244.333862,0.052068,0.000000
40.770000,28.284668,-244.467300,-0.002703,0.002041,0.051842,125.816490,6.409397,0.518425,-244.467300,0.052701,0.000000
41.150002,28.598946,-244.467300,-0.002682,0.002065,0.052450,127.214462,6.480614,0.524496,-244.467300,0.053334,0.000000
41.530003,28.488358,-244.511795,-0.002669,0.002087,0.053013,126.722542,6.455554,0.530128,-244.511795,0.053967,0.000000
41.910004,29.629677,-244.511795,-0.002634,0.002118,0.053803,131.799377,6.714180,0.538030,-244.511795,0.054608,0.000000
42.290001,29.408112,-244.467300,-0.002591,0.002137,0.054280,130.813812,6.663973,0.542799,-244.467300,0.055243,0.000000
42.670002,29.784958,-244.511795,-0.002570,0.002162,0.054904,132.490112,6.749368,0.549037,-244.511795,0.055876,0.000000
43.050003,30.595238,-244.689713,-0.002544,0.002190,0.055632,136.094421,6.932980,0.556319,-244.689713,0.056508,0.000000
43.430000,30.347237,-244.645233,-0.002522,0.002207,0.056048,134.991257,6.876782,0.560482,-244.645233,0.057141,0.000000
43.810001,31.354134,-244.645233,-0.002488,0.002240,0.056899,139.470154,7.104948,0.568991,-244.645233,0.057774,0.000000
44.190002,31.618149,-244.689713,-0.002449,0.002262,0.057462,140.644547,7.164775,0.574623,-244.689713,0.058407,0.000000
44.570004,32.126434,-244.734192,-0.002427,0.002290,0.058165,142.905518,7.279954,0.581648,-244.734192,0.059040,0.000000
44.950001,32.626900,-244.778671,-0.002402,0.002315,0.058798,145.131699,7.393361,0.587976,-244.778671,0.059674,0.000000
45.330002,32.401619,-244.823151,-0.002376,0.002333,0.059265,144.129593,7.342312,0.592654,-244.823151,0.060307,0.000000
45.710003,33.601776,-244.734192,-0.002358,0.002368,0.060142,149.468170,7.614272,0.601420,-244.734192,0.060940,0.000000
46.090004,33.607735,-244.867630,-0.002320,0.002389,0.060689,149.494675,7.615622,0.606885,-244.867630,0.061573,0.000000
46.470001,33.873604,-244.823151,-0.002307,0.002413,0.061296,150.677322,7.675868,0.612956,-244.823151,0.062206,0.000000
46.850002,34.526001,-244.912109,-0.002268,0.002441,0.061989,153.579315,7.823704,0.619890,-244.912109,0.062838,0.000000
47.230003,34.526749,-244.956604,-0.002246,0.002459,0.062457,153.582642,7.823873,0.624568,-244.956604,0.063473,0.000000
47.610001,35.693016,-245.001083,-0.002216,0.002493,0.063315,158.770462,8.088153,0.633152,-245.001083,0.064106,0.000000
47.990002,35.926865,-244.956604,-0.002173,0.002516,0.063906,159.810669,8.141144,0.639057,-244.956604,0.064738,0.000000
48.370003,36.361053,-245.045563,-0.002164,0.002542,0.064557,161.742050,8.239532,0.645567,-245.045563,0.065371,0.000000
48.750004,36.856308,-245.134521,-0.002134,0.002567,0.065206,163.945053,8.351759,0.652062,-245.134521,0.066004,0.000000
49.130001,36.885727,-245.179001,-0.002104,0.002586,0.065683,164.075912,8.358425,0.656831,-245.179001,0.066637,0.000000
49.510002,37.413750,-245.090042,-0.002074,0.002616,0.066439,166.424667,8.478077,0.664385,-245.090042,0.067271,0.000000
49.890003,38.140617,-245.223480,-0.002070,0.002642,0.067097,169.657944,8.642788,0.670971,-245.223480,0.067904,0.000000
50.270004,38.104874,-245.223480,-0.002022,0.002661,0.067600,169.498947,8.634687,0.675997,-245.223480,0.068537,0.000000
50.650002,38.887604,-245.267960,-0.001992,0.002689,0.068293,172.980698,8.812057,0.682931,-245.267960,0.069170,0.000000
51.030003,39.415627,-245.223480,-0.001975,0.002713,0.068909,175.329468,8.931709,0.689093,-245.223480,0.069803,0.000000
51.410004,39.837898,-245.267960,-0.001944,0.002741,0.069612,177.207825,9.027397,0.696118,-245.267960,0.070435,0.000000
51.790001,40.307831,-245.356934,-0.001910,0.002763,0.070184,179.298187,9.133885,0.701841,-245.356934,0.071068,0.000000
52.170002,40.561043,-245.401413,-0.001876,0.002788,0.070826,180.424530,9.191263,0.708260,-245.401413,0.071703,0.000000
52.550003,41.257751,-245.401413,-0.001876,0.002816,0.071519,183.523651,9.349140,0.715194,-245.401413,0.072344,0.000000
52.930004,41.232056,-245.401413,-0.001828,0.002835,0.072005,183.409348,9.343317,0.720054,-245.401413,0.072977,0.000000
53.310001,42.102295,-245.445892,-0.001815,0.002866,0.072787,187.280365,9.540516,0.727866,-245.445892,0.073610,0.000000
53.690002,42.119049,-245.490372,-0.001785,0.002890,0.073394,187.354889,9.544313,0.733937,-245.490372,0.074243,0.000000
54.070004,42.474663,-245.579330,-0.001768,0.002911,0.073940,188.936737,9.624896,0.739402,-245.579330,0.074876,0.000000
54.450001,43.445442,-245.534851,-0.001738,0.002940,0.074676,193.254974,9.844878,0.746760,-245.534851,0.075509,0.000000
54.830002,42.949814,-245.534851,-0.001703,0.002957,0.075101,191.050308,9.732567,0.751014,-245.534851,0.076141,0.000000
55.210003,43.688225,-245.534851,-0.001660,0.002985,0.075822,194.334930,9.899894,0.758220,-245.534851,0.076776,0.000000
55.590004,43.978302,-245.623810,-0.001660,0.003009,0.076420,195.625259,9.965626,0.764201,-245.623810,0.077409,0.000000
55.970001,44.492920,-245.712769,-0.001625,0.003035,0.077088,197.914398,10.082240,0.770877,-245.712769,0.078042,0.000000
56.350002,45.047760,-245.623810,-0.001604,0.003061,0.077746,200.382446,10.207969,0.777463,-245.623810,0.078674,0.000000
56.730003,45.153137,-245.668289,-0.001569,0.003083,0.078319,200.851181,10.231848,0.783186,-245.668289,0.079307,0.000000
57.110004,44.937904,-245.712769,-0.001548,0.003102,0.078788,199.893784,10.183075,0.787879,-245.712769,0.079940,0.000000
57.490002,46.414368,-245.801743,-0.001518,0.003138,0.079707,206.461426,10.517646,0.797069,-245.801743,0.080574,0.000000
57.870003,46.190567,-245.846222,-0.001487,0.003159,0.080226,205.465897,10.466932,0.802261,-245.846222,0.081207,0.000000
58.250004,46.554749,-245.846222,-0.001475,0.003183,0.080842,207.085861,10.549457,0.808423,-245.846222,0.081840,0.000000
58.630001,47.061546,-245.846222,-0.001440,0.003209,0.081519,209.340210,10.664299,0.815191,-245.846222,0.082473,0.000000
59.010002,46.958405,-245.846222,-0.001410,0.003234,0.082135,208.881409,10.640926,0.821352,-245.846222,0.083106,0.000000
59.390003,47.947052,-245.935181,-0.001388,0.003262,0.082854,213.279144,10.864957,0.828544,-245.935181,0.083739,0.000000
59.770004,48.185738,-246.024139,-0.001367,0.003284,0.083401,214.340866,10.919044,0.834009,-246.024139,0.084373,0.000000
60.150002,48.621788,-245.979660,-0.001337,0.003308,0.084034,216.280518,11.017855,0.840338,-245.979660,0.085006,0.000000
60.530003,49.140877,-246.024139,-0.001298,0.003336,0.084727,218.589539,11.135482,0.847271,-246.024139,0.085639,0.000000
60.910004,49.035492,-246.068619,-0.001293,0.003356,0.085248,218.120758,11.111601,0.852479,-246.068619,0.086271,0.000000
61.290005,50.451256,-246.113098,-0.001250,0.003389,0.086081,224.418396,11.432418,0.860806,-246.113098,0.086904,0.000000
61.670002,50.432266,-246.113098,-0.001229,0.003406,0.086523,224.333923,11.428115,0.865227,-246.113098,0.087537,0.000000
62.050003,51.528152,-246.113098,-0.001212,0.003437,0.087295,229.208664,11.676446,0.872948,-246.113098,0.088171,0.000000
62.430004,52.286682,-246.157578,-0.001186,0.003462,0.087946,232.582779,11.848331,0.879458,-246.157578,0.088804,0.000000
62.810001,52.215179,-246.202057,-0.001164,0.003479,0.088370,232.264725,11.832129,0.883697,-246.202057,0.089437,0.000000
63.190002,53.765739,-246.246552,-0.001143,0.003513,0.089228,239.161957,12.183491,0.892281,-246.246552,0.090070,0.000000
63.570004,54.148911,-246.291031,-0.001108,0.003532,0.089714,240.866379,12.270319,0.897141,-246.291031,0.090712,0.000000
63.950005,55.009842,-246.335510,-0.001108,0.003558,0.090365,244.695999,12.465408,0.903651,-246.335510,0.091345,0.000000
64.330002,56.257286,-246.379990,-0.001082,0.003585,0.091059,250.244904,12.748083,0.910585,-246.379990,0.091977,0.000000
64.710007,56.809517,-246.379990,-0.001052,0.003604,0.091535,252.701355,12.873220,0.915354,-246.379990,0.092610,0.000000
65.090004,58.152290,-246.424469,-0.001035,0.003632,0.092264,258.674316,13.177497,0.922636,-246.424469,0.093245,0.000000
65.470001,59.483894,-246.513428,-0.001022,0.003659,0.092931,264.597565,13.479243,0.929313,-246.513428,0.093878,0.000000
65.850006,60.440521,-246.513428,-0.001000,0.003684,0.093564,268.852875,13.696018,0.935641,-246.513428,0.094510,0.000000
66.230003,61.834679,-246.513428,-0.000987,0.003711,0.094250,275.054382,14.011939,0.942499,-246.513428,0.095143,0.000000
66.610001,62.649803,-246.602386,-0.000983,0.003731,0.094762,278.680237,14.196648,0.947617,-246.602386,0.095776,0.000000
66.990005,64.534012,-246.646881,-0.000966,0.003763,0.095576,287.061615,14.623615,0.955762,-246.646881,0.096409,0.000000
67.370003,65.611649,-246.646881,-0.000940,0.003785,0.096132,291.855194,14.867812,0.961318,-246.646881,0.097042,0.000000
67.750000,65.903595,-246.646881,-0.000918,0.003790,0.096262,293.153839,14.933968,0.962620,-246.646881,0.016913,0.000000
68.130005,66.567535,-246.646881,-0.000901,0.003784,0.096123,296.107178,15.084418,0.961227,-246.646881,294.500458,0.000000
68.510002,65.301834,-246.691360,-0.000892,0.003807,0.096687,290.477051,14.797607,0.966874,-246.691360,294.500458,0.000000
68.890007,65.296631,-246.824799,-0.000892,0.003822,0.097076,290.453918,14.796428,0.970765,-246.824799,294.500458,0.000000
69.270004,65.393448,-246.824799,-0.000888,0.003833,0.097355,290.884583,14.818367,0.973551,-246.824799,294.500458,0.000000
69.650002,65.340561,-246.735840,-0.000871,0.003839,0.097520,290.649323,14.806382,0.975201,-246.735840,294.500458,0.000000
70.030006,65.172623,-246.869278,-0.000871,0.003845,0.097658,289.902313,14.768328,0.976579,-246.869278,294.500458,0.000000
70.410004,65.391586,-246.869278,-0.000862,0.003853,0.097858,290.876312,14.817945,0.978577,-246.869278,294.500458,0.000000
70.790001,65.491013,-246.958237,-0.000862,0.003859,0.098030,291.318573,14.840475,0.980303,-246.958237,294.500458,0.000000
71.170006,64.967819,-246.913757,-0.000845,0.003860,0.098039,288.991302,14.721919,0.980394,-246.913757,294.500458,0.000000
71.550003,66.067810,-246.958237,-0.000845,0.003858,0.097997,293.884308,14.971180,0.979970,-246.958237,294.500458,0.000000
71.930000,65.505524,-247.047195,-0.000832,0.003859,0.098014,291.383118,14.843763,0.980136,-247.047195,294.500458,0.000000
72.310005,66.003387,-247.047195,-0.000841,0.003879,0.098534,293.597717,14.956581,0.985344,-247.047195,294.500458,0.000000
72.690002,65.500320,-247.047195,-0.000815,0.003879,0.098534,291.359985,14.842586,0.985344,-247.047195,294.500458,0.000000
73.070000,65.745712,-247.047195,-0.000832,0.003890,0.098802,292.451538,14.898191,0.988024,-247.047195,294.500458,0.000000
73.450005,65.377808,-247.091690,-0.000828,0.003892,0.098846,290.815002,14.814822,0.988463,-247.091690,294.500458,0.000000
73.830002,65.402374,-247.180649,-0.000815,0.003895,0.098942,290.924286,14.820390,0.989417,-247.180649,294.500458,0.000000
74.210007,65.382645,-247.180649,-0.000811,0.003898,0.099019,290.836517,14.815919,0.990189,-247.180649,294.500458,0.000000
74.590004,65.462708,-247.225128,-0.000811,0.003902,0.099114,291.192657,14.834062,0.991143,-247.225128,294.500458,0.000000
74.970001,65.438126,-247.225128,-0.000819,0.003905,0.099184,291.083313,14.828491,0.991839,-247.225128,294.500458,0.000000
75.350006,65.360672,-247.269608,-0.000806,0.003908,0.099254,290.738800,14.810940,0.992536,-247.269608,294.500458,0.000000
75.730003,65.653732,-247.269608,-0.000798,0.003914,0.099410,292.042389,14.877348,0.994095,-247.269608,294.500458,0.000000
76.110001,65.546494,-247.314087,-0.000806,0.003914,0.099410,291.565369,14.853048,0.994095,-247.314087,294.500458,0.000000
76.490005,65.326050,-247.403046,-0.000798,0.003915,0.099435,290.584778,14.803094,0.994352,-247.403046,294.500458,0.000000
76.870003,65.357697,-247.403046,-0.000798,0.003918,0.099505,290.725555,14.810266,0.995049,-247.403046,294.500458,0.000000
77.250000,65.229233,-247.447525,-0.000785,0.003918,0.099514,290.154114,14.781156,0.995140,-247.447525,294.500458,0.000000
77.630005,65.390839,-247.492004,-0.000780,0.003922,0.099618,290.872986,14.817776,0.996184,-247.492004,294.500458,0.000000
78.010002,65.262375,-247.536499,-0.000793,0.003922,0.099626,290.301544,14.788666,0.996260,-247.536499,294.500458,0.000000
78.390007,65.228851,-247.536499,-0.000785,0.003924,0.099670,290.152435,14.781069,0.996699,-247.536499,294.500458,0.000000
78.770004,65.731934,-247.536499,-0.000780,0.003929,0.099791,292.390259,14.895069,0.997910,-247.536499,294.500458,0.000000
79.150002,65.532333,-247.625458,-0.000776,0.003929,0.099791,291.502380,14.849839,0.997910,-247.625458,294.500458,0.000000
79.530006,65.338333,-247.669937,-0.000780,0.003929,0.099791,290.639435,14.805878,0.997910,-247.669937,294.500458,0.000000
79.910004,65.190125,-247.714417,-0.000785,0.003929,0.099791,289.980164,14.772293,0.997910,-247.714417,294.500458,0.000000
80.290001,65.022934,-247.758896,-0.000780,0.003929,0.099791,289.236450,14.734407,0.997910,-247.758896,294.500458,0.000000
80.670006,64.874359,-247.714417,-0.000776,0.003929,0.099791,288.575562,14.700740,0.997910,-247.714417,294.500458,0.000000
81.050003,66.682602,-247.758896,-0.000763,0.003894,0.098916,296.619019,15.110494,0.989160,-247.758896,294.500458,0.000000
81.430000,66.434601,-247.847855,-0.000763,0.003895,0.098924,295.515869,15.054296,0.989235,-247.847855,294.500458,0.000000
81.810005,66.290497,-247.936829,-0.000776,0.003895,0.098924,294.874847,15.021642,0.989235,-247.936829,294.500458,0.000000
82.190002,66.133347,-247.892334,-0.000767,0.003895,0.098924,294.175812,14.986031,0.989235,-247.892334,294.500458,0.000000
82.570007,65.919601,-247.803375,-0.000759,0.003895,0.098933,293.225037,14.937595,0.989326,-247.803375,294.500458,0.000000
82.950005,65.844757,-247.936829,-0.000763,0.003896,0.098951,292.892120,14.920635,0.989508,-247.936829,294.500458,0.000000
83.330002,65.679428,-247.981308,-0.000759,0.003907,0.099244,292.156677,14.883171,0.992445,-247.981308,294.500458,0.000000
83.710007,65.581497,-247.981308,-0.000767,0.003914,0.099428,291.721069,14.860980,0.994277,-247.981308,294.500458,0.000000
84.090004,65.476852,-247.936829,-0.000772,0.003918,0.099514,291.255585,14.837267,0.995140,-247.936829,294.500458,0.000000
84.470001,65.367386,-248.025787,-0.000776,0.003925,0.099688,290.768646,14.812461,0.996881,-248.025787,294.500458,0.000000
84.850006,65.430679,-248.070267,-0.000767,0.003940,0.100077,291.050201,14.826804,1.000772,-248.070267,294.500458,0.000000
85.230003,65.420624,-248.159225,-0.000755,0.003942,0.100121,291.005463,14.824526,1.001211,-248.159225,294.500458,0.000000
85.610001,65.377426,-248.203705,-0.000759,0.003944,0.100165,290.813324,14.814736,1.001650,-248.203705,294.500458,0.000000
85.990005,65.390839,-248.114746,-0.000763,0.003945,0.100191,290.872986,14.817776,1.001907,-248.114746,294.500458,0.000000
86.370003,65.359558,-248.203705,-0.000763,0.003946,0.100216,290.733826,14.810687,1.002164,-248.203705,294.500458,0.000000
86.750008,65.409088,-248.248184,-0.000767,0.003947,0.100251,290.954163,14.821911,1.002513,-248.248184,294.500458,0.000000
87.130005,65.409836,-248.248184,-0.000767,0.003948,0.100286,290.957489,14.822081,1.002861,-248.248184,294.500458,0.000000
87.510002,65.403503,-248.292664,-0.000772,0.003949,0.100303,290.929321,14.820645,1.003027,-248.292664,294.500458,0.000000
87.890007,65.400894,-248.292664,-0.000763,0.003949,0.100312,290.917694,14.820054,1.003118,-248.292664,294.500458,0.000000
88.270004,65.387482,-248.292664,-0.000742,0.003950,0.100328,290.858032,14.817015,1.003285,-248.292664,294.500458,0.000000
88.650002,65.533081,-248.337143,-0.000750,0.003953,0.100398,291.505707,14.850009,1.003981,-248.337143,294.500458,0.000000
89.030006,65.508514,-248.426117,-0.000763,0.003953,0.100398,291.396423,14.844441,1.003981,-248.426117,294.500458,0.000000
89.410004,65.449295,-248.515076,-0.000755,0.003953,0.100398,291.132996,14.831022,1.003981,-248.515076,294.500458,0.000000
89.790001,65.423233,-248.470596,-0.000759,0.003954,0.100433,291.017090,14.825116,1.004329,-248.470596,294.500458,0.000000
90.170006,65.393066,-248.470596,-0.000750,0.003955,0.100451,290.882874,14.818280,1.004511,-248.470596,294.500458,0.000000
90.550003,65.445206,-248.515076,-0.000750,0.003955,0.100468,291.114807,14.830095,1.004678,-248.515076,294.500458,0.000000
90.930008,65.416153,-248.604034,-0.000755,0.003955,0.100468,290.985596,14.823512,1.004678,-248.604034,294.500458,0.000000
91.310005,65.501801,-248.604034,-0.000755,0.003958,0.100528,291.366547,14.842920,1.005283,-248.604034,294.500458,0.000000
91.690002,65.488770,-248.559555,-0.000755,0.003958,0.100528,291.308594,14.839967,1.005283,-248.559555,294.500458,0.000000
92.070007,65.469406,-248.648514,-0.000742,0.003958,0.100537,291.222473,14.835580,1.005374,-248.648514,294.500458,0.000000
92.450005,65.407227,-248.692993,-0.000746,0.003959,0.100554,290.945862,14.821489,1.005541,-248.692993,294.500458,0.000000
92.830002,65.468292,-248.781952,-0.000755,0.003960,0.100572,291.217499,14.835327,1.005722,-248.781952,294.500458,0.000000
93.210007,65.460464,-248.737473,-0.000767,0.003961,0.100598,291.182678,14.833553,1.005980,-248.737473,294.500458,0.000000
93.590004,65.460846,-248.781952,-0.000750,0.003961,0.100607,291.184387,14.833639,1.006070,-248.781952,294.500458,0.000000
93.970001,65.459351,-248.781952,-0.000742,0.003962,0.100633,291.177734,14.833301,1.006328,-248.781952,294.500458,0.000000
94.350006,65.438873,-248.826447,-0.000750,0.003962,0.100633,291.086639,14.828661,1.006328,-248.826447,294.500458,0.000000
94.730003,65.421738,-248.915405,-0.000755,0.003962,0.100642,291.010437,14.824779,1.006419,-248.915405,294.500458,0.000000
95.110008,65.498077,-248.959885,-0.000767,0.003964,0.100693,291.350006,14.842077,1.006933,-248.959885,294.500458,0.000000
95.490005,65.479462,-248.870926,-0.000746,0.003964,0.100693,291.267181,14.837858,1.006933,-248.870926,294.500458,0.000000
95.870003,65.474991,-249.004364,-0.000742,0.003965,0.100702,291.247314,14.836845,1.007024,-249.004364,294.500458,0.000000
96.250008,65.430679,-249.004364,-0.000755,0.003965,0.100702,291.050201,14.826804,1.007024,-249.004364,294.500458,0.000000
96.630005,65.413559,-249.048843,-0.000737,0.003966,0.100728,290.974030,14.822924,1.007282,-249.048843,294.500458,0.000000
97.010002,65.422485,-249.093323,-0.000737,0.003966,0.100737,291.013763,14.824946,1.007372,-249.093323,294.500458,0.000000
97.390007,65.401642,-249.093323,-0.000750,0.003966,0.100737,290.921021,14.820224,1.007372,-249.093323,294.500458,0.000000
97.770004,65.429199,-249.137802,-0.000733,0.003967,0.100772,291.043610,14.826468,1.007721,-249.137802,294.500458,0.000000
98.150002,65.418015,-249.182281,-0.000742,0.003967,0.100772,290.993866,14.823934,1.007721,-249.182281,294.500458,0.000000
98.530006,65.394196,-249.226776,-0.000737,0.003968,0.100780,290.887909,14.818537,1.007796,-249.226776,294.500458,0.000000
98.910004,65.390472,-249.182281,-0.000746,0.003968,0.100789,290.871338,14.817693,1.007887,-249.182281,294.500458,0.000000
99.290001,65.371475,-249.226776,-0.000733,0.003968,0.100789,290.786835,14.813388,1.007887,-249.226776,294.500458,0.000000
99.670006,65.412811,-249.271255,-0.000742,0.003969,0.100824,290.970703,14.822755,1.008235,-249.271255,294.500458,0.000000
100.050003,65.386749,-249.360214,-0.000746,0.003970,0.100833,290.854797,14.816849,1.008326,-249.360214,294.500458,0.000000
100.430008,65.359558,-249.404694,-0.000737,0.003970,0.100833,290.733826,14.810687,1.008326,-249.404694,294.500458,0.000000
100.810005,65.369614,-249.360214,-0.000737,0.003970,0.100840,290.778564,14.812966,1.008402,-249.360214,294.500458,0.000000
101.190002,65.352112,-249.315735,-0.000729,0.003970,0.100849,290.700714,14.809001,1.008493,-249.315735,294.500458,0.000000
101.570007,65.371841,-249.449173,-0.000724,0.003971,0.100875,290.788483,14.813471,1.008750,-249.449173,294.500458,0.000000
101.950005,65.376312,-249.493652,-0.000742,0.003971,0.100875,290.808350,14.814484,1.008750,-249.493652,294.500458,0.000000
102.330002,65.346893,-249.582611,-0.000737,0.003971,0.100875,290.677490,14.807817,1.008750,-249.582611,294.500458,0.000000
102.710007,65.324921,-249.582611,-0.000729,0.003971,0.100875,290.579773,14.802838,1.008750,-249.582611,294.500458,0.000000
103.090004,65.301834,-249.582611,-0.000737,0.003971,0.100875,290.477051,14.797607,1.008750,-249.582611,294.500458,0.000000
103.470001,65.292908,-249.671585,-0.000742,0.003971,0.100875,290.437347,14.795585,1.008750,-249.671585,294.500458,0.000000
103.850006,65.242630,-249.716064,-0.000742,0.003971,0.100875,290.213715,14.784191,1.008750,-249.716064,294.500458,0.000000
104.230003,65.213959,-249.716064,-0.000746,0.003971,0.100875,290.086182,14.777695,1.008750,-249.716064,294.500458,0.000000
104.610008,65.193848,-249.671585,-0.000746,0.003973,0.100902,289.996704,14.773137,1.009023,-249.671585,294.500458,0.000000
104.990005,65.640320,-249.671585,-0.000746,0.003978,0.101049,291.982727,14.874309,1.010491,-249.671585,294.500458,0.000000
105.370003,65.674591,-249.805023,-0.000737,0.003978,0.101049,292.135162,14.882075,1.010491,-249.805023,294.500458,0.000000
105.750008,65.655960,-249.849503,-0.000729,0.003978,0.101049,292.052307,14.877853,1.010491,-249.849503,294.500458,0.000000
106.130005,65.654480,-249.849503,-0.000737,0.003978,0.101049,292.045715,14.877518,1.010491,-249.849503,294.500458,0.000000
106.510002,65.622086,-249.849503,-0.000742,0.003978,0.101049,291.901611,14.870177,1.010491,-249.849503,294.500458,0.000000
106.890007,65.599365,-249.849503,-0.000737,0.003978,0.101049,291.800537,14.865029,1.010491,-249.849503,294.500458,0.000000
107.270004,65.578888,-249.938461,-0.000720,0.003978,0.101049,291.709473,14.860388,1.010491,-249.938461,294.500458,0.000000
107.650002,65.563248,-249.982941,-0.000737,0.003978,0.101049,291.639893,14.856845,1.010491,-249.982941,294.500458,0.000000
108.030006,65.518555,-249.982941,-0.000737,0.003978,0.101049,291.441101,14.846717,1.010491,-249.982941,294.500458,0.000000
108.410004,65.500320,-250.071899,-0.000724,0.003978,0.101049,291.359985,14.842586,1.010491,-250.071899,294.500458,0.000000
108.790009,65.476852,-250.071899,-0.000737,0.003978,0.101049,291.255585,14.837267,1.010491,-250.071899,294.500458,0.000000
109.170006,65.444839,-250.116394,-0.000737,0.003978,0.101049,291.113190,14.830012,1.010491,-250.116394,294.500458,0.000000
109.550003,65.401260,-250.160873,-0.000729,0.003978,0.101049,290.919342,14.820137,1.010491,-250.160873,294.500458,0.000000
109.930008,65.399399,-250.205353,-0.000737,0.003979,0.101066,290.911041,14.819715,1.010658,-250.205353,294.500458,0.000000
110.310005,65.412064,-250.205353,-0.000733,0.003980,0.101093,290.967377,14.822585,1.010930,-250.205353,294.500458,0.000000
110.690002,65.413925,-250.160873,-0.000720,0.003980,0.101093,290.975677,14.823008,1.010930,-250.160873,294.500458,0.000000
111.070007,65.403122,-250.294312,-0.000720,0.003981,0.101126,290.927612,14.820560,1.011263,-250.294312,294.500458,0.000000
111.450005,65.450424,-250.338791,-0.000733,0.003981,0.101126,291.138031,14.831278,1.011263,-250.338791,294.500458,0.000000
111.830002,65.439621,-250.338791,-0.000733,0.003981,0.101126,291.089966,14.828831,1.011263,-250.338791,294.500458,0.000000
112.210007,65.434784,-250.294312,-0.000733,0.003981,0.101126,291.068451,14.827734,1.011263,-250.294312,294.500458,0.000000
112.590004,65.410950,-250.294312,-0.000729,0.003981,0.101126,290.962433,14.822333,1.011263,-250.294312,294.500458,0.000000
112.970009,65.368866,-250.427750,-0.000716,0.003982,0.101145,290.775238,14.812798,1.011445,-250.427750,294.500458,0.000000
113.350006,65.428452,-250.427750,-0.000716,0.003983,0.101170,291.040283,14.826300,1.011702,-250.427750,294.500458,0.000000
113.730003,65.441849,-250.472229,-0.000733,0.003983,0.101170,291.099884,14.829334,1.011702,-250.472229,294.500458,0.000000
114.110008,65.423233,-250.472229,-0.000729,0.003983,0.101170,291.017090,14.825116,1.011702,-250.472229,294.500458,0.000000
114.490005,65.416901,-250.561203,-0.000724,0.003983,0.101170,290.988922,14.823681,1.011702,-250.561203,294.500458,0.000000
114.870003,65.387482,-250.605682,-0.000716,0.003983,0.101170,290.858032,14.817015,1.011702,-250.605682,294.500458,0.000000
115.250008,65.386368,-250.605682,-0.000720,0.003983,0.101170,290.853088,14.816763,1.011702,-250.605682,294.500458,0.000000
115.630005,65.388229,-250.650162,-0.000733,0.003984,0.101196,290.861359,14.817184,1.011960,-250.650162,294.500458,0.000000
116.010002,65.396423,-250.605682,-0.000737,0.003984,0.101196,290.897827,14.819041,1.011960,-250.605682,294.500458,0.000000
116.390007,65.395309,-250.694641,-0.000716,0.003984,0.101196,290.892853,14.818789,1.011960,-250.694641,294.500458,0.000000
116.770004,65.356949,-250.783600,-0.000720,0.003984,0.101196,290.722229,14.810097,1.011960,-250.783600,294.500458,0.000000
117.150009,65.355469,-250.783600,-0.000729,0.003984,0.101196,290.715637,14.809761,1.011960,-250.783600,294.500458,0.000000
117.530006,65.332748,-250.828079,-0.000724,0.003984,0.101196,290.614594,14.804612,1.011960,-250.828079,294.500458,0.000000
117.910004,65.329391,-250.872559,-0.000729,0.003984,0.101205,290.599640,14.803851,1.012051,-250.872559,294.500458,0.000000
118.290009,65.307053,-250.828079,-0.000724,0.003984,0.101205,290.500275,14.798789,1.012051,-250.828079,294.500458,0.000000
118.670006,65.293274,-250.917038,-0.000733,0.003984,0.101205,290.438995,14.795667,1.012051,-250.917038,294.500458,0.000000
119.050003,65.282852,-250.961533,-0.000724,0.003984,0.101205,290.392639,14.793305,1.012051,-250.961533,294.500458,0.000000
119.430008,65.249344,-251.006012,-0.000729,0.003984,0.101205,290.243591,14.785712,1.012051,-251.006012,294.500458,0.000000
119.810005,65.239288,-250.961533,-0.000729,0.003984,0.101205,290.198853,14.783434,1.012051,-250.961533,294.500458,0.000000
120.190002,65.216202,-251.050491,-0.000711,0.003986,0.101240,290.096161,14.778203,1.012399,-251.050491,294.500458,0.000000
120.570007,65.267212,-251.094971,-0.000724,0.003986,0.101257,290.323059,14.789762,1.012565,-251.094971,294.500458,0.000000
120.950005,65.280243,-251.139450,-0.000720,0.003987,0.101266,290.381012,14.792715,1.012656,-251.139450,294.500458,0.000000
121.330009,65.282852,-251.183929,-0.000716,0.003987,0.101266,290.392639,14.793305,1.012656,-251.183929,294.500458,0.000000
121.710007,65.283218,-251.228409,-0.000733,0.003987,0.101266,290.394257,14.793388,1.012656,-251.228409,294.500458,0.000000
122.090004,65.269073,-251.139450,-0.000724,0.003987,0.101266,290.331329,14.790184,1.012656,-251.139450,294.500458,0.000000
122.470009,65.260880,-251.183929,-0.000720,0.003987,0.101266,290.294891,14.788326,1.012656,-251.183929,294.500458,0.000000
122.850006,65.243011,-251.228409,-0.000729,0.003987,0.101266,290.215424,14.784278,1.012656,-251.228409,294.500458,0.000000
123.230003,65.241882,-251.272888,-0.000720,0.003987,0.101266,290.210388,14.784021,1.012656,-251.272888,294.500458,0.000000
123.610008,65.257523,-251.272888,-0.000733,0.003989,0.101310,290.279968,14.787565,1.013095,-251.272888,294.500458,0.000000
123.990005,65.262375,-251.272888,-0.000716,0.003989,0.101310,290.301544,14.788666,1.013095,-251.272888,294.500458,0.000000
124.370003,65.271683,-251.406342,-0.000716,0.003989,0.101310,290.342957,14.790774,1.013095,-251.406342,294.500458,0.000000
124.750008,65.250076,-251.450821,-0.000724,0.003989,0.101310,290.246826,14.785879,1.013095,-251.450821,294.500458,0.000000
125.130005,65.262375,-251.406342,-0.000720,0.003989,0.101310,290.301544,14.788666,1.013095,-251.406342,294.500458,0.000000
125.510010,65.243011,-251.450821,-0.000707,0.003990,0.101344,290.215424,14.784278,1.013443,-251.450821,294.500458,0.000000
125.890007,65.279877,-251.495300,-0.000707,0.003990,0.101352,290.379395,14.792631,1.013519,-251.495300,294.500458,0.000000
126.270004,65.293655,-251.539780,-0.000724,0.003990,0.101352,290.440674,14.795754,1.013519,-251.539780,294.500458,0.000000
126.650009,65.282104,-251.628738,-0.000729,0.003990,0.101352,290.389313,14.793136,1.013519,-251.628738,294.500458,0.000000
127.030006,65.285080,-251.584259,-0.000724,0.003990,0.101352,290.402527,14.793811,1.013519,-251.584259,294.500458,0.000000
127.410004,65.281357,-251.584259,-0.000733,0.003990,0.101352,290.385986,14.792967,1.013519,-251.584259,294.500458,0.000000
127.790009,65.274658,-251.628738,-0.000698,0.003991,0.101361,290.356171,14.791450,1.013610,-251.628738,294.500458,0.000000
128.170013,65.277634,-251.762177,-0.000711,0.003991,0.101361,290.369415,14.792123,1.013610,-251.762177,1681.640747,0.000000
128.550003,65.269821,-251.762177,-0.000724,0.003983,0.101170,290.334656,14.790353,1.011702,-251.762177,0.101093,0.000000
128.930008,65.223267,-251.806671,-0.000707,0.003968,0.100789,290.127594,14.779803,1.007887,-251.806671,0.100459,0.000000
129.310013,65.093689,-251.762177,-0.000707,0.003950,0.100338,289.551178,14.750442,1.003376,-251.762177,0.099826,0.000000
129.690002,65.055710,-251.806671,-0.000703,0.003934,0.099930,289.382263,14.741835,0.999303,-251.806671,0.099193,0.000000
130.070007,65.045273,-251.806671,-0.000716,0.003903,0.099132,289.335815,14.739470,0.991325,-251.806671,0.098560,0.000000
130.450012,64.995758,-251.851151,-0.000711,0.003878,0.098491,289.115570,14.728249,0.984905,-251.851151,0.097927,0.000000
130.830002,64.974152,-251.851151,-0.000711,0.003858,0.098005,289.019470,14.723353,0.980046,-251.851151,0.097295,0.000000
131.210007,64.987183,-251.895630,-0.000707,0.003832,0.097337,289.077423,14.726306,0.973369,-251.895630,0.096660,0.000000
131.590012,64.916061,-251.895630,-0.000707,0.003813,0.096860,288.761078,14.710189,0.968600,-251.895630,0.096027,0.000000
131.970001,64.849777,-251.984589,-0.000703,0.003782,0.096062,288.466217,14.695169,0.960621,-251.984589,0.095394,0.000000
132.350006,64.798401,-252.029068,-0.000711,0.003758,0.095455,288.237671,14.683528,0.954551,-252.029068,0.094762,0.000000
132.730011,64.506454,-252.029068,-0.000711,0.003736,0.094901,286.939026,14.617372,0.949009,-252.029068,0.094129,0.000000
133.110001,63.843262,-252.029068,-0.000694,0.003714,0.094329,283.989014,14.467091,0.943287,-252.029068,0.093496,0.000000
133.490005,62.852745,-252.118027,-0.000703,0.003694,0.093817,279.582977,14.242636,0.938169,-252.118027,0.092862,0.000000
133.870010,61.353951,-252.118027,-0.000690,0.003667,0.093148,272.916016,13.903004,0.931478,-252.118027,0.092229,0.000000
134.250000,60.056976,-252.251480,-0.000703,0.003646,0.092603,267.146759,13.609105,0.926028,-252.251480,0.091596,0.000000
134.630005,58.205536,-252.206985,-0.000681,0.003624,0.092047,258.911163,13.189563,0.920471,-252.206985,0.090963,0.000000
135.010010,55.201981,-252.251480,-0.000690,0.003590,0.091180,245.550674,12.508947,0.911796,-252.251480,0.090330,0.000000
135.389999,53.713608,-252.206985,-0.000694,0.003576,0.090842,238.930054,12.171678,0.908420,-252.206985,0.089697,0.000000
135.770004,51.542305,-252.295959,-0.000690,0.003556,0.090321,229.271622,11.679654,0.903212,-252.295959,0.089065,0.000000
136.150009,48.860107,-252.340439,-0.000703,0.003532,0.089714,217.340607,11.071858,0.897141,-252.340439,0.088430,0.000000
136.530014,45.970497,-252.340439,-0.000698,0.003501,0.088934,204.486984,10.417064,0.889344,-252.340439,0.087797,0.000000
136.910004,42.216240,-252.384918,-0.000694,0.003470,0.088137,187.787216,9.566337,0.881366,-252.384918,0.087165,0.000000
137.290009,40.349533,-252.384918,-0.000686,0.003455,0.087746,179.483688,9.143335,0.877460,-252.384918,0.086532,0.000000
137.670013,37.886665,-252.473877,-0.000694,0.003430,0.087121,168.528305,8.585241,0.871207,-252.473877,0.085899,0.000000
138.050003,34.807518,-252.518356,-0.000720,0.003401,0.086383,154.831573,7.887496,0.863834,-252.518356,0.085257,0.000000
138.430008,32.058662,-252.473877,-0.000698,0.003376,0.085760,142.604050,7.264597,0.857597,-252.473877,0.084624,0.000000
138.810013,29.596535,-252.518356,-0.000703,0.003354,0.085187,131.651962,6.706670,0.851874,-252.518356,0.083991,0.000000
139.190002,25.953987,-252.562836,-0.000703,0.003321,0.084364,115.449104,5.881258,0.843638,-252.562836,0.083357,0.000000
139.570007,23.924927,-252.562836,-0.000716,0.003301,0.083834,106.423386,5.421466,0.838339,-252.562836,0.082724,0.000000
139.950012,21.163788,-252.607315,-0.000711,0.003273,0.083141,94.141228,4.795783,0.831405,-252.607315,0.082091,0.000000
140.330002,18.351257,-252.607315,-0.000716,0.003248,0.082508,81.630470,4.158454,0.825077,-252.607315,0.081459,0.000000
140.710007,16.081276,-252.696289,-0.000716,0.003230,0.082031,71.533089,3.644069,0.820308,-252.696289,0.080826,0.000000
141.090012,12.807747,-252.740768,-0.000729,0.003199,0.081259,56.971703,2.902277,0.812587,-252.740768,0.080193,0.000000
141.470001,10.557877,-252.740768,-0.000733,0.003177,0.080686,46.963779,2.392449,0.806864,-252.740768,0.079558,0.000000
141.850006,8.125168,-252.829727,-0.000737,0.003154,0.080123,36.142551,1.841189,0.801232,-252.829727,0.078926,0.000000
142.230011,4.841957,-252.785248,-0.000742,0.003122,0.079307,21.538101,1.097203,0.793072,-252.785248,0.078293,0.000000
142.610001,2.567139,-252.829727,-0.000742,0.003101,0.078770,11.419203,0.581722,0.787697,-252.829727,0.077660,0.000000
142.990005,-0.385780,-252.874207,-0.000763,0.003071,0.078016,-1.716037,-0.087419,0.780158,-252.874207,0.077027,0.000000
143.370010,-2.066669,-252.874207,-0.000759,0.003051,0.077504,-9.193005,-0.468314,0.775041,-252.874207,0.076394,0.000000
143.750000,-0.451317,-252.918686,-0.000785,0.003027,0.076888,-2.007558,-0.102270,0.768879,-252.918686,0.075760,0.000000
144.130005,0.007820,-252.918686,-0.000841,0.002995,0.076073,0.034786,0.001772,0.760734,-252.918686,0.075127,0.000000
144.510010,0.009308,-252.918686,-0.000862,0.002974,0.075543,0.041403,0.002109,0.755435,-252.918686,0.074494,0.000000
144.889999,0.005211,-252.963165,-0.000905,0.002946,0.074824,0.023179,0.001181,0.748243,-252.963165,0.073861,0.000000
145.270004,-0.001862,-253.096619,-0.000918,0.002929,0.074408,-0.008281,-0.000422,0.744080,-253.096619,0.073229,0.000000
145.650009,-0.029793,-253.096619,-0.000970,0.002909,0.073887,-0.132525,-0.006751,0.738872,-253.096619,0.072596,0.000000
146.030014,-0.027931,-253.096619,-0.001026,0.002869,0.072882,-0.124244,-0.006329,0.728819,-253.096619,0.071961,0.000000
146.410004,-0.056602,-253.141098,-0.001039,0.002849,0.072352,-0.251780,-0.012826,0.723521,-253.141098,0.071329,0.000000
146.790009,-0.046547,-253.096619,-0.001078,0.002823,0.071693,-0.207051,-0.010548,0.716935,-253.096619,0.070696,0.000000
147.170013,-0.074104,-253.185577,-0.001091,0.002801,0.071147,-0.329632,-0.016792,0.711469,-253.185577,0.070063,0.000000
147.550003,-0.094955,-253.274536,-0.001121,0.002780,0.070600,-0.422383,-0.021517,0.706004,-253.274536,0.069430,0.000000
147.930008,-0.091980,-253.230057,-0.001155,0.002761,0.070124,-0.409147,-0.020843,0.701235,-253.230057,0.068797,0.000000
148.310013,-0.110596,-253.274536,-0.001186,0.002726,0.069248,-0.491954,-0.025061,0.692484,-253.274536,0.068164,0.000000
148.690002,-0.059952,-253.319016,-0.001190,0.002697,0.068511,-0.266679,-0.013585,0.685111,-253.319016,0.067530,0.000000
149.070007,-0.071495,-253.363495,-0.001203,0.002681,0.068095,-0.318026,-0.016201,0.680948,-253.363495,0.066888,0.000000
149.450012,-0.097565,-253.407974,-0.001212,0.002652,0.067367,-0.433989,-0.022108,0.673666,-253.407974,0.066255,0.000000
149.830002,-0.126976,-253.363495,-0.001263,0.002624,0.066655,-0.564817,-0.028773,0.666550,-253.363495,0.065623,0.000000
150.210007,-0.131821,-253.407974,-0.001293,0.002598,0.065987,-0.586368,-0.029871,0.659874,-253.407974,0.064990,0.000000
150.590012,-0.071495,-253.452454,-0.001315,0.002573,0.065362,-0.318026,-0.016201,0.653621,-253.452454,0.064357,0.000000
150.970001,-0.078575,-253.452454,-0.001337,0.002547,0.064704,-0.349520,-0.017805,0.647035,-253.452454,0.063724,0.000000
151.350006,-0.077454,-253.541428,-0.001354,0.002535,0.064383,-0.344531,-0.017551,0.643826,-253.541428,0.063091,0.000000
151.730011,-0.099800,-253.541428,-0.001397,0.002504,0.063610,-0.443933,-0.022615,0.636105,-253.541428,0.062457,0.000000
152.110001,-0.131073,-253.630386,-0.001414,0.002475,0.062857,-0.583042,-0.029702,0.628565,-253.630386,0.061824,0.000000
152.490005,-0.117294,-253.630386,-0.001423,0.002454,0.062319,-0.521751,-0.026579,0.623191,-253.630386,0.061191,0.000000
152.870010,-0.098305,-253.674866,-0.001457,0.002431,0.061747,-0.437281,-0.022276,0.617468,-253.674866,0.060558,0.000000
153.250000,-0.113571,-253.719345,-0.001483,0.002402,0.061009,-0.505190,-0.025736,0.610095,-253.719345,0.059925,0.000000
153.630005,-0.112831,-253.674866,-0.001526,0.002376,0.060342,-0.501898,-0.025568,0.603418,-253.674866,0.059293,0.000000
154.010010,-0.128098,-253.719345,-0.001539,0.002349,0.059656,-0.569806,-0.029027,0.596560,-253.719345,0.058658,0.000000
154.390015,-0.125114,-253.808304,-0.001569,0.002323,0.058997,-0.556537,-0.028351,0.589974,-253.808304,0.058025,0.000000
154.770004,-0.133682,-253.808304,-0.001582,0.002301,0.058442,-0.594648,-0.030293,0.584418,-253.808304,0.057393,0.000000
155.150009,-0.103523,-253.852783,-0.001625,0.002273,0.057732,-0.460494,-0.023459,0.577318,-253.852783,0.056760,0.000000
155.530014,-0.144478,-253.897263,-0.001651,0.002251,0.057185,-0.642670,-0.032739,0.571852,-253.897263,0.056127,0.000000
155.910004,-0.128098,-253.897263,-0.001669,0.002228,0.056595,-0.569806,-0.029027,0.565948,-253.897263,0.055494,0.000000
156.290009,-0.128845,-253.897263,-0.001694,0.002194,0.055727,-0.573132,-0.029197,0.557273,-253.897263,0.054860,0.000000
156.670013,-0.132935,-253.941757,-0.001716,0.002178,0.055320,-0.591322,-0.030123,0.553200,-253.941757,0.054227,0.000000
156.900009,-0.099800,-253.941757,-0.001720,0.002180,0.055364,-0.443933,-0.022615,0.553639,-253.941757,0.055320,0.000000