File: Data/compression 31/ManualNoHeating-12-31-reverse-1-2_11132024_180211.csv
Time (sec),S:Load (lbs),S:HL1 (DIM),S:LVDT (in),S:Position (in),Ch:Position (mm),Ch:Load (N),Ch:Stress (MPa),Ch:Strain (mm/mm),Ch:HL1 (DIM),Set Point (),Cycles ()
0.110000,-0.077454,-278.406281,-0.010210,-0.005287,-0.134282,-0.344531,-0.017551,-1.342820,-278.406281,-0.134082,0.000000
0.530000,-0.104263,-278.450745,-0.010218,-0.005208,-0.132279,-0.463786,-0.023626,-1.322791,-278.450745,-0.131740,0.000000
0.950000,-0.065536,-278.539703,-0.010042,-0.004957,-0.125904,-0.291521,-0.014851,-1.259038,-278.539703,-0.124752,0.000000
1.370000,-0.096817,-278.584198,-0.009753,-0.004679,-0.118853,-0.430664,-0.021939,-1.188533,-278.584198,-0.117744,0.000000
1.790000,-0.091606,-278.584198,-0.009472,-0.004403,-0.111838,-0.407484,-0.020758,-1.118376,-278.584198,-0.110754,0.000000
2.210000,-0.099426,-278.584198,-0.009192,-0.004129,-0.104882,-0.442270,-0.022530,-1.048825,-278.584198,-0.103764,0.000000
2.630000,-0.092720,-278.628693,-0.008899,-0.003854,-0.097893,-0.412439,-0.021011,-0.978925,-278.628693,-0.096757,0.000000
3.050000,-0.068893,-278.717651,-0.008640,-0.003582,-0.090972,-0.306453,-0.015611,-0.909722,-278.717651,-0.089767,0.000000
3.470000,-0.050270,-278.762115,-0.008343,-0.003300,-0.083817,-0.223612,-0.011391,-0.838173,-278.762115,-0.082761,0.000000
3.890000,-0.113571,-278.717651,-0.008054,-0.003026,-0.076871,-0.505190,-0.025736,-0.768712,-278.717651,-0.075771,0.000000
4.310000,-0.105385,-278.717651,-0.007774,-0.002747,-0.069769,-0.468775,-0.023881,-0.697692,-278.717651,-0.068762,0.000000
4.730000,-0.111710,-278.806610,-0.007472,-0.002473,-0.062814,-0.496909,-0.025314,-0.628141,-278.806610,-0.061773,0.000000
5.150000,-0.047295,-278.806610,-0.007200,-0.002205,-0.055997,-0.210377,-0.010717,-0.559968,-278.806610,-0.054783,0.000000
5.570000,-0.035004,-278.851074,-0.006924,-0.001931,-0.049060,-0.155704,-0.007932,-0.490598,-278.851074,-0.047776,0.000000
5.990000,-0.075966,-278.851074,-0.006631,-0.001644,-0.041749,-0.337913,-0.017214,-0.417489,-278.851074,-0.040786,0.000000
6.410000,-0.126610,-278.851074,-0.006338,-0.001374,-0.034898,-0.563189,-0.028690,-0.348982,-278.851074,-0.033779,0.000000
6.830000,-0.128845,-278.940033,-0.006066,-0.001100,-0.027934,-0.573132,-0.029197,-0.279340,-278.940033,-0.026789,0.000000
7.250000,-0.061073,-278.940033,-0.005777,-0.000823,-0.020909,-0.271668,-0.013839,-0.209093,-278.940033,-0.019800,0.000000
7.670001,-0.027184,-279.073486,-0.005497,-0.000553,-0.014050,-0.120918,-0.006160,-0.140495,-279.073486,-0.012791,0.000000
8.090000,-0.044312,-279.073486,-0.005234,-0.000285,-0.007234,-0.197107,-0.010041,-0.072337,-279.073486,-0.005803,0.000000
8.510000,0.145226,-279.028992,-0.005079,-0.000007,-0.000173,0.645995,0.032909,-0.001726,-279.028992,-0.000077,0.000000
8.930000,0.083412,-279.073486,-0.005075,-0.000007,-0.000173,0.371036,0.018901,-0.001726,-279.073486,0.000139,0.000000
9.350000,0.130699,-279.073486,-0.005070,0.000002,0.000053,0.581379,0.029617,0.000530,-279.073486,0.000842,0.000000
9.770000,0.274811,-279.206940,-0.005040,0.000029,0.000730,1.222420,0.062273,0.007297,-279.206940,0.001544,0.000000
10.190001,0.467697,-279.251404,-0.005032,0.000054,0.001379,2.080421,0.105982,0.013792,-279.251404,0.002238,0.000000
10.610001,0.701920,-279.206940,-0.005006,0.000083,0.002117,3.122294,0.159057,0.021165,-279.206940,0.002940,0.000000
11.030001,0.921997,-279.206940,-0.004971,0.000104,0.002646,4.101248,0.208928,0.026464,-279.206940,0.003643,0.000000
11.450001,1.257126,-279.251404,-0.004958,0.000141,0.003591,5.591975,0.284869,0.035911,-279.251404,0.004337,0.000000
11.870001,1.394165,-279.295898,-0.004937,0.000163,0.004129,6.201556,0.315922,0.041286,-279.295898,0.005040,0.000000
12.290001,1.767281,-279.384857,-0.004915,0.000194,0.004926,7.861257,0.400472,0.049264,-279.384857,0.005741,0.000000
12.710001,2.038742,-279.429321,-0.004881,0.000216,0.005482,9.068778,0.461986,0.054820,-279.429321,0.006443,0.000000
13.130001,2.255089,-279.384857,-0.004850,0.000237,0.006029,10.031136,0.511010,0.060286,-279.384857,0.007138,0.000000
13.550000,2.774544,-279.429321,-0.004820,0.000278,0.007069,12.341787,0.628721,0.070687,-279.429321,0.007841,0.000000
13.970000,2.912323,-279.429321,-0.004803,0.000299,0.007606,12.954659,0.659942,0.076061,-279.429321,0.008543,0.000000
14.390000,3.323799,-279.473816,-0.004794,0.000328,0.008334,14.784997,0.753184,0.083343,-279.473816,0.009237,0.000000
14.810000,3.580734,-279.518311,-0.004760,0.000353,0.008976,15.927901,0.811406,0.089763,-279.518311,0.009939,0.000000
15.230000,4.220840,-279.518311,-0.004734,0.000388,0.009860,18.775236,0.956456,0.098604,-279.518311,0.010642,0.000000
15.650001,4.331436,-279.562775,-0.004695,0.000413,0.010502,19.267191,0.981517,0.105023,-279.562775,0.011344,0.000000
16.070002,4.521347,-279.607269,-0.004682,0.000435,0.011049,20.111956,1.024552,0.110489,-279.607269,0.012037,0.000000
16.490002,5.112297,-279.696228,-0.004635,0.000467,0.011856,22.740633,1.158463,0.118558,-279.696228,0.012740,0.000000
16.910002,5.264229,-279.651733,-0.004626,0.000488,0.012393,23.416460,1.192891,0.123933,-279.651733,0.013442,0.000000
17.330000,5.788528,-279.696228,-0.004587,0.000525,0.013347,25.748661,1.311699,0.133471,-279.696228,0.014145,0.000000
17.750000,5.814598,-279.740692,-0.004562,0.000546,0.013868,25.864624,1.317607,0.138679,-279.740692,0.014838,0.000000
18.170000,6.319534,-279.785187,-0.004549,0.000579,0.014701,28.110693,1.432027,0.147005,-279.785187,0.015541,0.000000
18.590000,6.474815,-279.829651,-0.004518,0.000599,0.015220,28.801416,1.467214,0.152198,-279.829651,0.016243,0.000000
19.010000,6.705307,-279.785187,-0.004493,0.000622,0.015810,29.826694,1.519444,0.158103,-279.785187,0.016938,0.000000
19.430000,7.280998,-279.874146,-0.004462,0.000661,0.016799,32.387497,1.649898,0.167989,-279.874146,0.017641,0.000000
19.850000,7.390846,-279.874146,-0.004432,0.000683,0.017336,32.876125,1.674790,0.173363,-279.874146,0.018343,0.000000
20.270000,7.947174,-279.918640,-0.004411,0.000717,0.018204,35.350796,1.800855,0.182038,-279.918640,0.019046,0.000000
20.690001,8.054047,-280.007599,-0.004385,0.000738,0.018741,35.826187,1.825073,0.187413,-280.007599,0.019739,0.000000
21.110001,8.542969,-280.007599,-0.004368,0.000768,0.019504,38.001022,1.935864,0.195043,-280.007599,0.020441,0.000000
21.530001,8.773094,-280.007599,-0.004342,0.000797,0.020242,39.024673,1.988012,0.202416,-280.007599,0.021144,0.000000
21.950001,8.677391,-280.052063,-0.004307,0.000818,0.020788,38.598965,1.966325,0.207882,-280.052063,0.021837,0.000000
22.370001,9.259789,-280.096558,-0.004281,0.000851,0.021621,41.189598,2.098298,0.216208,-280.096558,0.022540,0.000000
22.790001,9.140999,-280.141022,-0.004251,0.000867,0.022028,40.661194,2.071380,0.220281,-280.141022,0.023242,0.000000
23.210001,9.919632,-280.185516,-0.004230,0.000909,0.023086,44.124725,2.247821,0.230863,-280.185516,0.023945,0.000000
23.630001,9.906967,-280.141022,-0.004186,0.000931,0.023659,44.068390,2.244951,0.236586,-280.141022,0.024638,0.000000
24.050001,10.065598,-280.185516,-0.004169,0.000956,0.024275,44.774014,2.280897,0.242748,-280.185516,0.025341,0.000000
24.470001,10.232422,-280.229980,-0.004148,0.000980,0.024899,45.516087,2.318700,0.248986,-280.229980,0.026043,0.000000
24.890001,10.490852,-280.274475,-0.004135,0.001011,0.025687,46.665642,2.377261,0.256873,-280.274475,0.026746,0.000000
25.310001,11.108612,-280.318939,-0.004092,0.001046,0.026581,49.413574,2.517247,0.265806,-280.318939,0.027439,0.000000
25.730001,11.059837,-280.407928,-0.004057,0.001068,0.027127,49.196613,2.506195,0.271271,-280.407928,0.028141,0.000000
26.150002,11.654884,-280.318939,-0.004036,0.001101,0.027960,51.843513,2.641035,0.279598,-280.318939,0.028844,0.000000
26.570002,11.713348,-280.318939,-0.004005,0.001122,0.028497,52.103577,2.654283,0.284972,-280.318939,0.029539,0.000000
26.990002,12.394417,-280.407928,-0.003980,0.001156,0.029365,55.133118,2.808615,0.293647,-280.407928,0.030241,0.000000
27.410002,12.074173,-280.452393,-0.003958,0.001177,0.029902,53.708603,2.736047,0.299022,-280.452393,0.030944,0.000000
27.830002,12.636086,-280.496887,-0.003928,0.001212,0.030788,56.208115,2.863378,0.307878,-280.496887,0.031646,0.000000
28.250002,12.658798,-280.496887,-0.003893,0.001235,0.031368,56.309147,2.868525,0.313677,-280.496887,0.032340,0.000000
28.670002,12.471497,-280.496887,-0.003872,0.001252,0.031810,55.475986,2.826082,0.318098,-280.496887,0.033042,0.000000
29.090002,13.574089,-280.541351,-0.003842,0.001297,0.032947,60.380562,3.075933,0.329468,-280.541351,0.033745,0.000000
29.510002,13.522331,-280.585846,-0.003833,0.001322,0.033571,60.150333,3.064204,0.335705,-280.585846,0.034438,0.000000
29.930002,13.866035,-280.630310,-0.003794,0.001350,0.034291,61.679207,3.142088,0.342911,-280.630310,0.035140,0.000000
30.350002,14.067490,-280.674805,-0.003773,0.001375,0.034915,62.575317,3.187739,0.349149,-280.674805,0.035843,0.000000
30.770002,14.469276,-280.630310,-0.003755,0.001402,0.035601,64.362556,3.278785,0.356007,-280.630310,0.036545,0.000000
31.190001,14.560509,-280.674805,-0.003699,0.001430,0.036311,64.768379,3.299459,0.363108,-280.674805,0.037239,0.000000
31.610001,14.823029,-280.763763,-0.003699,0.001459,0.037048,65.936127,3.358946,0.370481,-280.763763,0.037941,0.000000
32.030003,14.964531,-280.808258,-0.003665,0.001486,0.037734,66.565559,3.391011,0.377339,-280.808258,0.038644,0.000000
32.450001,14.868835,-280.808258,-0.003639,0.001504,0.038211,66.139885,3.369326,0.382108,-280.808258,0.039346,0.000000
32.870003,15.745766,-280.852722,-0.003613,0.001545,0.039251,70.040665,3.568042,0.392509,-280.852722,0.040041,0.000000
33.290001,15.568893,-280.808258,-0.003604,0.001568,0.039816,69.253899,3.527962,0.398156,-280.808258,0.040744,0.000000
33.710003,16.044411,-280.852722,-0.003566,0.001598,0.040595,71.369102,3.635715,0.405953,-280.852722,0.041445,0.000000
34.130001,15.827690,-280.941681,-0.003544,0.001617,0.041072,70.405083,3.586606,0.410722,-280.941681,0.042140,0.000000
34.550003,16.373962,-280.986176,-0.003523,0.001652,0.041956,72.835022,3.710393,0.419563,-280.986176,0.042842,0.000000
34.970001,16.725479,-280.986176,-0.003475,0.001679,0.042651,74.398643,3.790048,0.426512,-280.986176,0.043544,0.000000
35.390003,16.970131,-280.986176,-0.003471,0.001707,0.043354,75.486916,3.845487,0.433537,-280.986176,0.044247,0.000000
35.810001,17.300423,-281.030640,-0.003449,0.001734,0.044047,76.956123,3.920332,0.440471,-281.030640,0.044940,0.000000
36.230003,17.344734,-281.030640,-0.003406,0.001758,0.044645,77.153229,3.930373,0.446451,-281.030640,0.045643,0.000000
36.650002,18.244019,-281.119598,-0.003389,0.001794,0.045573,81.153450,4.134154,0.455732,-281.119598,0.046345,0.000000
37.070004,17.772964,-281.119598,-0.003376,0.001815,0.046111,79.058098,4.027411,0.461106,-281.119598,0.047039,0.000000
37.490002,18.160606,-281.119598,-0.003328,0.001843,0.046813,80.782410,4.115252,0.468131,-281.119598,0.047741,0.000000
37.910004,18.402275,-281.119598,-0.003333,0.001870,0.047508,81.857407,4.170015,0.475080,-281.119598,0.048444,0.000000
38.330002,18.045166,-281.164093,-0.003320,0.001887,0.047923,80.268906,4.089093,0.479228,-281.164093,0.049146,0.000000
38.750000,19.392784,-281.297546,-0.003272,0.001931,0.049060,86.263412,4.394468,0.490598,-281.297546,0.049839,0.000000
39.170002,19.011101,-281.342010,-0.003260,0.001954,0.049632,84.565598,4.307977,0.496321,-281.342010,0.050542,0.000000
39.590000,19.686211,-281.297546,-0.003234,0.001985,0.050430,87.568642,4.460959,0.504299,-281.297546,0.051244,0.000000
40.010002,19.212555,-281.297546,-0.003208,0.002007,0.050976,85.461716,4.353627,0.509765,-281.297546,0.051947,0.000000
40.430000,20.119659,-281.386505,-0.003191,0.002037,0.051730,89.496712,4.559180,0.517304,-281.386505,0.052642,0.000000
40.850002,20.229507,-281.386505,-0.003169,0.002066,0.052484,89.985344,4.584072,0.524844,-281.386505,0.053344,0.000000
41.270000,20.029915,-281.475464,-0.003143,0.002087,0.053014,89.097511,4.538844,0.530143,-281.475464,0.054047,0.000000
41.690002,20.758644,-281.519928,-0.003104,0.002119,0.053821,92.339058,4.703976,0.538212,-281.519928,0.054740,0.000000
42.110001,20.430962,-281.519928,-0.003104,0.002138,0.054306,90.881454,4.629722,0.543057,-281.519928,0.055443,0.000000
42.530003,21.240128,-281.430969,-0.003083,0.002172,0.055166,94.480804,4.813081,0.551656,-281.430969,0.056145,0.000000
42.950001,21.389076,-281.519928,-0.003070,0.002199,0.055859,95.143364,4.846834,0.558590,-281.519928,0.056848,0.000000
43.370003,21.571907,-281.653381,-0.003040,0.002229,0.056622,95.956635,4.888264,0.566220,-281.653381,0.057541,0.000000
43.790001,21.854538,-281.697876,-0.003027,0.002254,0.057246,97.213837,4.952309,0.572458,-281.697876,0.058243,0.000000
44.210003,21.807617,-281.653381,-0.002984,0.002282,0.057974,97.005127,4.941677,0.579740,-281.653381,0.058946,0.000000
44.630001,22.546776,-281.653381,-0.002971,0.002313,0.058739,100.293068,5.109173,0.587385,-281.653381,0.059639,0.000000
45.050003,22.314423,-281.697876,-0.002936,0.002335,0.059318,99.259506,5.056520,0.593184,-281.697876,0.060342,0.000000
45.470001,21.782295,-281.742340,-0.002949,0.002356,0.059848,96.892487,4.935939,0.598483,-281.742340,0.061044,0.000000
45.890003,21.924171,-281.831299,-0.002910,0.002379,0.060430,97.523582,4.968088,0.604296,-281.831299,0.061747,0.000000
46.310001,23.657570,-281.875793,-0.002902,0.002422,0.061521,105.234123,5.360882,0.615212,-281.875793,0.062440,0.000000
46.730003,23.461327,-281.831299,-0.002863,0.002450,0.062242,104.361191,5.316413,0.622418,-281.831299,0.063143,0.000000
47.150002,22.869995,-281.875793,-0.002854,0.002473,0.062805,101.730820,5.182415,0.628050,-281.875793,0.063845,0.000000
47.570004,23.472122,-281.875793,-0.002846,0.002504,0.063594,104.409218,5.318859,0.635938,-281.875793,0.064548,0.000000
47.990002,23.161568,-282.053711,-0.002828,0.002522,0.064063,103.027802,5.248486,0.640631,-282.053711,0.065243,0.000000
48.410004,24.633553,-281.964752,-0.002811,0.002566,0.065173,109.575516,5.582043,0.651729,-281.964752,0.065945,0.000000
48.830002,23.568573,-281.964752,-0.002790,0.002581,0.065563,104.838249,5.340715,0.655635,-281.964752,0.066647,0.000000
49.250004,24.145744,-282.009216,-0.002777,0.002616,0.066457,107.405632,5.471504,0.664567,-282.009216,0.067341,0.000000
49.670002,23.331367,-282.053711,-0.002759,0.002634,0.066899,103.783104,5.286963,0.668988,-282.053711,0.068043,0.000000
50.090004,22.989532,-282.098206,-0.002751,0.002659,0.067541,102.262550,5.209503,0.675407,-282.098206,0.068746,0.000000
50.510002,24.339752,-282.098206,-0.002734,0.002700,0.068590,108.268623,5.515467,0.685899,-282.098206,0.069448,0.000000
50.930004,23.972969,-282.142670,-0.002712,0.002725,0.069223,106.637093,5.432352,0.692227,-282.142670,0.070142,0.000000
51.350002,24.035149,-282.098206,-0.002699,0.002755,0.069977,106.913681,5.446443,0.699767,-282.098206,0.070844,0.000000
51.770004,23.436378,-282.187164,-0.002699,0.002774,0.070463,104.250221,5.310759,0.704626,-282.187164,0.071547,0.000000
52.190002,24.244423,-282.276123,-0.002682,0.002812,0.071426,107.844582,5.493865,0.714255,-282.276123,0.072249,0.000000
52.610001,23.470634,-282.320587,-0.002660,0.002834,0.071980,104.402596,5.318521,0.719796,-282.320587,0.072942,0.000000
53.030003,23.724220,-282.365082,-0.002660,0.002865,0.072761,105.530602,5.375985,0.727608,-282.365082,0.073645,0.000000
53.450001,23.128426,-282.320587,-0.002639,0.002886,0.073316,102.880379,5.240976,0.733164,-282.320587,0.074347,0.000000
53.870003,23.244606,-282.365082,-0.002626,0.002917,0.074079,103.397171,5.267303,0.740795,-282.365082,0.075042,0.000000
54.290001,23.775238,-282.365082,-0.002621,0.002951,0.074964,105.757538,5.387546,0.749636,-282.365082,0.075745,0.000000
54.710003,23.352966,-282.454041,-0.002604,0.002975,0.075571,103.879181,5.291858,0.755707,-282.454041,0.076447,0.000000
55.130001,23.413666,-282.498535,-0.002600,0.003002,0.076247,104.149185,5.305613,0.762475,-282.498535,0.077150,0.000000
55.550003,23.050224,-282.454041,-0.002570,0.003027,0.076897,102.532516,5.223256,0.768970,-282.454041,0.077843,0.000000
55.970001,24.381462,-282.498535,-0.002565,0.003062,0.077783,108.454163,5.524919,0.777826,-282.498535,0.078546,0.000000
56.390003,23.781197,-282.542999,-0.002561,0.003084,0.078329,105.784042,5.388896,0.783292,-282.542999,0.079248,0.000000
56.810001,24.016159,-282.587494,-0.002548,0.003113,0.079065,106.829208,5.442139,0.790649,-282.587494,0.079942,0.000000
57.230003,23.969986,-282.631958,-0.002522,0.003139,0.079734,106.623825,5.431676,0.797341,-282.631958,0.080644,0.000000
57.650002,23.608414,-282.631958,-0.002522,0.003160,0.080253,105.015472,5.349743,0.802534,-282.631958,0.081346,0.000000
58.070004,24.956398,-282.676453,-0.002492,0.003199,0.081242,111.011604,5.655200,0.812420,-282.676453,0.082049,0.000000
58.490002,24.346458,-282.676453,-0.002483,0.003219,0.081763,108.298454,5.516986,0.817628,-282.676453,0.082742,0.000000
58.910004,24.254478,-282.720917,-0.002458,0.003246,0.082440,107.889305,5.496144,0.824396,-282.720917,0.083445,0.000000
59.330002,24.485725,-282.765411,-0.002466,0.003269,0.083028,108.917946,5.548544,0.830285,-282.765411,0.084147,0.000000
59.750004,24.223572,-282.765411,-0.002449,0.003292,0.083610,107.751831,5.489140,0.836098,-282.765411,0.084850,0.000000
60.170002,25.814720,-282.809875,-0.002419,0.003332,0.084633,114.829613,5.849699,0.846333,-282.809875,0.085543,0.000000
60.590004,25.568954,-282.809875,-0.002406,0.003357,0.085266,113.736389,5.794008,0.852661,-282.809875,0.086246,0.000000
61.010002,26.244812,-282.854370,-0.002393,0.003388,0.086055,116.742752,5.947159,0.860549,-282.854370,0.086948,0.000000
61.430004,26.139801,-282.898834,-0.002376,0.003409,0.086585,116.275642,5.923364,0.865848,-282.898834,0.087643,0.000000
61.850002,26.913589,-282.943329,-0.002354,0.003440,0.087383,119.717628,6.098706,0.873826,-282.943329,0.088346,0.000000
62.270004,27.294899,-282.943329,-0.002341,0.003468,0.088076,121.413773,6.185112,0.880760,-282.943329,0.089048,0.000000
62.690002,27.259895,-282.987823,-0.002324,0.003490,0.088657,121.258072,6.177181,0.886574,-282.987823,0.089750,0.000000
63.110004,28.085075,-283.032288,-0.002298,0.003523,0.089472,124.928658,6.364169,0.894719,-283.032288,0.090444,0.000000
63.530003,27.865372,-283.076782,-0.002285,0.003542,0.089967,123.951363,6.314384,0.899670,-283.076782,0.091146,0.000000
63.950005,28.718857,-283.076782,-0.002255,0.003571,0.090712,127.747856,6.507786,0.907118,-283.076782,0.091849,0.000000
64.370003,29.539558,-283.121246,-0.002242,0.003604,0.091537,131.398514,6.693759,0.915369,-283.121246,0.092542,0.000000
64.790001,29.876190,-283.121246,-0.002220,0.003630,0.092195,132.895935,6.770041,0.921955,-283.121246,0.093245,0.000000
65.210007,30.395645,-283.165741,-0.002199,0.003658,0.092924,135.206589,6.887752,0.929237,-283.165741,0.093947,0.000000
65.630005,31.505692,-283.299164,-0.002182,0.003691,0.093756,140.144318,7.139292,0.937564,-283.299164,0.094650,0.000000
66.050003,31.393234,-283.254700,-0.002164,0.003716,0.094389,139.644073,7.113809,0.943892,-283.254700,0.095343,0.000000
66.470001,31.646446,-283.299164,-0.002139,0.003740,0.094987,140.770416,7.171187,0.949872,-283.299164,0.096045,0.000000
66.889999,32.485771,-283.299164,-0.002130,0.003773,0.095838,144.503922,7.361381,0.958381,-283.299164,0.096748,0.000000
67.310005,32.379646,-283.299164,-0.002126,0.003792,0.096315,144.031860,7.337333,0.963150,-283.299164,0.097450,0.000000
67.730003,33.745140,-283.432617,-0.002074,0.003828,0.097225,150.105881,7.646758,0.972249,-283.432617,0.098144,0.000000
68.150002,33.780136,-283.432617,-0.002057,0.003852,0.097850,150.261551,7.654688,0.978501,-283.432617,0.098846,0.000000
68.570000,34.473122,-283.477112,-0.002013,0.003882,0.098613,153.344101,7.811721,0.986132,-283.477112,0.099549,0.000000
68.990005,34.377800,-283.432617,-0.001992,0.003904,0.099160,152.920090,7.790121,0.991597,-283.432617,0.100244,0.000000
69.410004,34.034470,-283.477112,-0.001970,0.003923,0.099637,151.392883,7.712321,0.996366,-283.477112,0.100946,0.000000
69.830002,36.483566,-283.432617,-0.001940,0.003971,0.100851,162.287003,8.267295,1.008508,-283.432617,0.101649,0.000000
70.250000,36.512238,-283.610535,-0.001919,0.003994,0.101458,162.414551,8.273791,1.014579,-283.610535,0.102351,0.000000
70.670006,37.427528,-283.566071,-0.001897,0.004025,0.102238,166.485962,8.481199,1.022376,-283.566071,0.103045,0.000000
71.090004,37.399597,-283.610535,-0.001858,0.004045,0.102733,166.361710,8.474870,1.027326,-283.610535,0.103747,0.000000
71.510002,38.633644,-283.566071,-0.001841,0.004079,0.103600,171.851028,8.754509,1.036001,-283.566071,0.104449,0.000000
71.930000,39.124428,-283.655029,-0.001824,0.004101,0.104154,174.034149,8.865722,1.041543,-283.655029,0.105143,0.000000
72.350006,39.949982,-283.743988,-0.001811,0.004130,0.104892,177.706390,9.052795,1.048916,-283.743988,0.105845,0.000000
72.770004,41.190353,-283.743988,-0.001785,0.004158,0.105620,183.223846,9.333867,1.056198,-283.743988,0.106548,0.000000
73.190002,41.007515,-283.699493,-0.001763,0.004174,0.106010,182.410538,9.292436,1.060104,-283.699493,0.107250,0.000000
73.610001,43.644661,-283.743988,-0.001720,0.004218,0.107138,194.141144,9.890021,1.071383,-283.743988,0.107944,0.000000
74.030006,43.818184,-283.832947,-0.001712,0.004237,0.107623,194.913010,9.929342,1.076227,-283.832947,0.108646,0.000000
74.450005,45.371353,-283.877441,-0.001703,0.004268,0.108413,201.821854,10.281296,1.084130,-283.877441,0.109349,0.000000
74.870003,45.698662,-283.877441,-0.001669,0.004286,0.108872,203.277802,10.355465,1.088717,-283.877441,0.110051,0.000000
75.290001,48.111641,-283.921906,-0.001656,0.004327,0.109904,214.011261,10.902254,1.099043,-283.921906,0.110746,0.000000
75.710007,49.411964,-283.877441,-0.001630,0.004353,0.110572,219.795395,11.196911,1.105719,-283.877441,0.111449,0.000000
76.130005,50.213310,-283.966400,-0.001630,0.004376,0.111153,223.359955,11.378499,1.111533,-283.966400,0.112151,0.000000
76.550003,51.652153,-284.055359,-0.001595,0.004403,0.111838,229.760254,11.704545,1.118376,-284.055359,0.112844,0.000000
76.970001,52.720123,-284.055359,-0.001582,0.004427,0.112454,234.510818,11.946550,1.124538,-284.055359,0.113547,0.000000
77.390007,55.325607,-284.099823,-0.001565,0.004465,0.113417,246.100586,12.536962,1.134166,-284.099823,0.114249,0.000000
77.810005,56.212227,-284.055359,-0.001535,0.004487,0.113963,250.044479,12.737872,1.139632,-284.055359,0.114952,0.000000
78.230003,58.045418,-284.099823,-0.001539,0.004517,0.114726,258.198914,13.153279,1.147262,-284.099823,0.115645,0.000000
78.650002,59.372185,-284.188782,-0.001518,0.004540,0.115308,264.100677,13.453930,1.153076,-284.188782,0.116348,0.000000
79.070007,60.372375,-284.188782,-0.001496,0.004560,0.115836,268.549744,13.680575,1.158360,-284.188782,0.117050,0.000000
79.490005,63.617233,-284.233276,-0.001487,0.004601,0.116876,282.983582,14.415871,1.168760,-284.233276,0.117744,0.000000
79.910004,64.987930,-284.277771,-0.001483,0.004626,0.117501,289.080750,14.726475,1.175013,-284.277771,0.118446,0.000000
80.330002,66.334061,-284.233276,-0.001470,0.004640,0.117865,295.068634,15.031513,1.178647,-284.233276,0.020682,0.000000
80.750008,65.224014,-284.322235,-0.001449,0.004640,0.117848,290.130920,14.779973,1.178480,-284.322235,294.500458,0.000000
81.170006,65.231461,-284.366730,-0.001449,0.004655,0.118239,290.164032,14.781660,1.182386,-284.366730,294.500458,0.000000
81.590004,65.278748,-284.411194,-0.001436,0.004662,0.118411,290.374359,14.792376,1.184112,-284.411194,294.500458,0.000000
82.010002,65.155502,-284.411194,-0.001414,0.004667,0.118541,289.826141,14.764448,1.185414,-284.411194,294.500458,0.000000
82.430000,65.831360,-284.455688,-0.001431,0.004676,0.118776,292.832520,14.917599,1.187761,-284.455688,294.500458,0.000000
82.850006,65.237427,-284.455688,-0.001423,0.004676,0.118776,290.190582,14.783012,1.187761,-284.455688,294.500458,0.000000
83.270004,65.130173,-284.544647,-0.001410,0.004681,0.118888,289.713470,14.758708,1.188881,-284.544647,294.500458,0.000000
83.690002,64.937286,-284.544647,-0.001406,0.004683,0.118958,288.855469,14.714999,1.189577,-284.544647,294.500458,0.000000
84.110001,65.088104,-284.544647,-0.001406,0.004689,0.119106,289.526337,14.749176,1.191061,-284.544647,294.500458,0.000000
84.530006,64.849411,-284.589111,-0.001414,0.004691,0.119139,288.464600,14.695086,1.191394,-284.589111,294.500458,0.000000
84.950005,66.076752,-284.544647,-0.001397,0.004691,0.119158,293.924072,14.973207,1.191576,-284.544647,294.500458,0.000000
85.370003,65.721130,-284.678101,-0.001393,0.004691,0.119158,292.342194,14.892621,1.191576,-284.678101,294.500458,0.000000
85.790001,65.371475,-284.678101,-0.001393,0.004693,0.119201,290.786835,14.813388,1.192015,-284.678101,294.500458,0.000000
86.210007,65.394928,-284.722565,-0.001388,0.004704,0.119479,290.891174,14.818703,1.194785,-284.722565,294.500458,0.000000
86.630005,65.400894,-284.767059,-0.001384,0.004708,0.119574,290.917694,14.820054,1.195739,-284.767059,294.500458,0.000000
87.050003,65.386002,-284.767059,-0.001384,0.004710,0.119634,290.851471,14.816680,1.196345,-284.767059,294.500458,0.000000
87.470001,65.403870,-284.811523,-0.001406,0.004712,0.119695,290.930939,14.820729,1.196950,-284.811523,294.500458,0.000000
87.890007,65.442230,-284.900482,-0.001380,0.004715,0.119756,291.101593,14.829421,1.197556,-284.900482,294.500458,0.000000
88.310005,65.391586,-284.856018,-0.001388,0.004717,0.119799,290.876312,14.817945,1.197995,-284.856018,294.500458,0.000000
88.730003,65.397537,-284.900482,-0.001388,0.004718,0.119834,290.902771,14.819294,1.198343,-284.900482,294.500458,0.000000
89.150002,65.327530,-284.900482,-0.001380,0.004719,0.119860,290.591370,14.803431,1.198601,-284.900482,294.500458,0.000000
89.570007,65.252686,-284.989441,-0.001380,0.004720,0.119886,290.258453,14.786469,1.198858,-284.989441,294.500458,0.000000
89.990005,65.575531,-285.078430,-0.001393,0.004724,0.119999,291.694519,14.859628,1.199993,-285.078430,294.500458,0.000000
90.410004,65.486908,-285.033936,-0.001375,0.004724,0.119999,291.300323,14.839546,1.199993,-285.033936,294.500458,0.000000
90.830002,65.349503,-284.989441,-0.001388,0.004724,0.119999,290.689117,14.808409,1.199993,-284.989441,294.500458,0.000000
91.250008,65.285828,-284.989441,-0.001380,0.004729,0.120128,290.405853,14.793981,1.201280,-284.989441,294.500458,0.000000
91.670006,65.557281,-285.122894,-0.001384,0.004730,0.120137,291.613342,14.855493,1.201371,-285.122894,294.500458,0.000000
92.090004,65.495468,-285.167389,-0.001380,0.004730,0.120137,291.338379,14.841485,1.201371,-285.167389,294.500458,0.000000
92.510002,65.363647,-285.122894,-0.001375,0.004730,0.120137,290.752014,14.811614,1.201371,-285.122894,294.500458,0.000000
92.930008,65.276520,-285.167389,-0.001371,0.004730,0.120146,290.364471,14.791870,1.201462,-285.167389,294.500458,0.000000
93.350006,65.394562,-285.256348,-0.001380,0.004733,0.120223,290.889526,14.818619,1.202234,-285.256348,294.500458,0.000000
93.770004,65.338699,-285.211853,-0.001367,0.004733,0.120223,290.641052,14.805962,1.202234,-285.211853,294.500458,0.000000
94.190002,65.561752,-285.300812,-0.001367,0.004737,0.120311,291.633240,14.856505,1.203112,-285.300812,294.500458,0.000000
94.610008,65.520416,-285.256348,-0.001380,0.004737,0.120311,291.449371,14.847138,1.203112,-285.256348,294.500458,0.000000
95.030006,65.425476,-285.345306,-0.001362,0.004737,0.120311,291.027039,14.825624,1.203112,-285.345306,294.500458,0.000000
95.450005,65.341309,-285.345306,-0.001367,0.004737,0.120319,290.652649,14.806552,1.203188,-285.345306,294.500458,0.000000
95.870003,65.305939,-285.389771,-0.001393,0.004738,0.120337,290.495331,14.798536,1.203369,-285.389771,294.500458,0.000000
96.290001,65.290665,-285.434265,-0.001358,0.004739,0.120363,290.427368,14.795076,1.203627,-285.434265,294.500458,0.000000
96.710007,65.336838,-285.389771,-0.001367,0.004740,0.120407,290.632782,14.805539,1.204066,-285.389771,294.500458,0.000000
97.130005,65.317108,-285.478729,-0.001367,0.004740,0.120407,290.545013,14.801068,1.204066,-285.478729,294.500458,0.000000
97.550003,65.265717,-285.523224,-0.001367,0.004740,0.120407,290.316406,14.789423,1.204066,-285.523224,294.500458,0.000000
97.970001,65.219177,-285.523224,-0.001375,0.004741,0.120423,290.109375,14.778876,1.204232,-285.523224,294.500458,0.000000
98.390007,65.194229,-285.612183,-0.001362,0.004742,0.120458,289.998413,14.773223,1.204581,-285.612183,294.500458,0.000000
98.810005,65.231461,-285.567719,-0.001354,0.004743,0.120467,290.164032,14.781660,1.204672,-285.567719,294.500458,0.000000
99.230003,65.202789,-285.567719,-0.001358,0.004744,0.120493,290.036499,14.775164,1.204929,-285.567719,294.500458,0.000000
99.650002,65.205765,-285.656677,-0.001362,0.004744,0.120493,290.049713,14.775837,1.204929,-285.656677,294.500458,0.000000
100.070007,65.202042,-285.701141,-0.001362,0.004745,0.120511,290.033173,14.774994,1.205111,-285.701141,294.500458,0.000000
100.490005,65.175980,-285.745636,-0.001375,0.004745,0.120511,289.917236,14.769088,1.205111,-285.745636,294.500458,0.000000
100.910004,65.490265,-285.701141,-0.001367,0.004750,0.120640,291.315247,14.840306,1.206397,-285.701141,294.500458,0.000000
101.330002,65.537918,-285.701141,-0.001345,0.004750,0.120640,291.527222,14.851105,1.206397,-285.701141,294.500458,0.000000
101.750008,65.527130,-285.790100,-0.001354,0.004750,0.120640,291.479218,14.848660,1.206397,-285.790100,294.500458,0.000000
102.170006,65.490631,-285.834595,-0.001375,0.004750,0.120640,291.316864,14.840389,1.206397,-285.834595,294.500458,0.000000
102.590004,65.409836,-285.923553,-0.001358,0.004750,0.120640,290.957489,14.822081,1.206397,-285.923553,294.500458,0.000000
103.010002,65.364777,-285.879059,-0.001362,0.004750,0.120640,290.757050,14.811871,1.206397,-285.879059,294.500458,0.000000
103.430008,65.326416,-285.923553,-0.001375,0.004750,0.120640,290.586426,14.803178,1.206397,-285.923553,294.500458,0.000000
103.850006,65.293274,-285.834595,-0.001367,0.004750,0.120649,290.438995,14.795667,1.206488,-285.834595,294.500458,0.000000
104.270004,65.279877,-286.057007,-0.001362,0.004751,0.120675,290.379395,14.792631,1.206746,-286.057007,294.500458,0.000000
104.690002,65.266830,-286.012512,-0.001354,0.004752,0.120693,290.321350,14.789676,1.206927,-286.012512,294.500458,0.000000
105.110008,65.262741,-285.968048,-0.001362,0.004752,0.120702,290.303162,14.788749,1.207018,-285.968048,294.500458,0.000000
105.530006,65.248962,-286.012512,-0.001350,0.004752,0.120702,290.241882,14.785626,1.207018,-286.012512,294.500458,0.000000
105.950005,65.204285,-286.101471,-0.001350,0.004752,0.120702,290.043152,14.775502,1.207018,-286.101471,294.500458,0.000000
106.370003,65.260513,-286.101471,-0.001358,0.004754,0.120744,290.293274,14.788243,1.207442,-286.101471,294.500458,0.000000
106.790009,65.253433,-286.190430,-0.001358,0.004754,0.120744,290.261780,14.786639,1.207442,-286.190430,294.500458,0.000000
107.210007,65.233704,-286.145966,-0.001358,0.004754,0.120744,290.174011,14.782168,1.207442,-286.145966,294.500458,0.000000
107.630005,65.236679,-286.190430,-0.001354,0.004754,0.120762,290.187256,14.782843,1.207624,-286.190430,294.500458,0.000000
108.050003,65.211731,-286.145966,-0.001371,0.004754,0.120762,290.076263,14.777190,1.207624,-286.145966,294.500458,0.000000
108.470009,65.233322,-286.279388,-0.001358,0.004755,0.120788,290.172302,14.782083,1.207881,-286.279388,294.500458,0.000000
108.890007,65.234070,-286.323883,-0.001362,0.004755,0.120788,290.175629,14.782252,1.207881,-286.323883,294.500458,0.000000
109.310005,65.225876,-286.323883,-0.001341,0.004756,0.120797,290.139191,14.780395,1.207972,-286.323883,294.500458,0.000000
109.730003,65.189377,-286.323883,-0.001341,0.004756,0.120797,289.976837,14.772124,1.207972,-286.323883,294.500458,0.000000
110.150002,65.218063,-286.323883,-0.001362,0.004757,0.120840,290.104431,14.778625,1.208396,-286.323883,294.500458,0.000000
110.570007,65.215820,-286.412842,-0.001358,0.004757,0.120840,290.094452,14.778116,1.208396,-286.412842,294.500458,0.000000
110.990005,65.216202,-286.457336,-0.001358,0.004757,0.120840,290.096161,14.778203,1.208396,-286.457336,294.500458,0.000000
111.410004,65.187897,-286.501801,-0.001362,0.004757,0.120840,289.970245,14.771788,1.208396,-286.501801,294.500458,0.000000
111.830002,65.151779,-286.457336,-0.001354,0.004757,0.120840,289.809601,14.763604,1.208396,-286.457336,294.500458,0.000000
112.250008,65.175613,-286.546295,-0.001358,0.004758,0.120865,289.915619,14.769006,1.208653,-286.546295,294.500458,0.000000
112.670006,65.180069,-286.590759,-0.001345,0.004759,0.120874,289.935425,14.770015,1.208744,-286.590759,294.500458,0.000000
113.090004,65.158112,-286.679718,-0.001345,0.004759,0.120874,289.837769,14.765039,1.208744,-286.679718,294.500458,0.000000
113.510002,65.152527,-286.635254,-0.001362,0.004759,0.120874,289.812927,14.763774,1.208744,-286.635254,294.500458,0.000000
113.930008,65.164429,-286.635254,-0.001345,0.004760,0.120893,289.865845,14.766471,1.208926,-286.635254,294.500458,0.000000
114.350006,65.149918,-286.635254,-0.001354,0.004760,0.120893,289.801300,14.763183,1.208926,-286.635254,294.500458,0.000000
114.770004,65.116776,-286.724213,-0.001358,0.004760,0.120893,289.653870,14.755672,1.208926,-286.724213,294.500458,0.000000
115.190002,65.299606,-286.768677,-0.001354,0.004763,0.120988,290.467163,14.797102,1.209880,-286.768677,294.500458,0.000000
115.610008,65.334244,-286.813171,-0.001362,0.004763,0.120988,290.621216,14.804952,1.209880,-286.813171,294.500458,0.000000
116.030006,65.349503,-286.768677,-0.001362,0.004763,0.120988,290.689117,14.808409,1.209880,-286.768677,294.500458,0.000000
116.450005,65.342056,-286.813171,-0.001341,0.004763,0.120988,290.655975,14.806722,1.209880,-286.813171,294.500458,0.000000
116.870003,65.337967,-286.902130,-0.001358,0.004763,0.120988,290.637787,14.805795,1.209880,-286.902130,294.500458,0.000000
117.290009,65.330521,-286.902130,-0.001358,0.004763,0.120988,290.604675,14.804107,1.209880,-286.902130,294.500458,0.000000
117.710007,65.303329,-286.902130,-0.001350,0.004763,0.120988,290.483704,14.797946,1.209880,-286.902130,294.500458,0.000000
118.130005,65.285461,-286.991089,-0.001350,0.004763,0.120988,290.404236,14.793897,1.209880,-286.991089,294.500458,0.000000
118.550003,65.251938,-286.991089,-0.001345,0.004763,0.120988,290.255127,14.786300,1.209880,-286.991089,294.500458,0.000000
118.970009,65.234070,-287.035583,-0.001345,0.004763,0.120988,290.175629,14.782252,1.209880,-287.035583,294.500458,0.000000
119.390007,65.208740,-287.080048,-0.001354,0.004763,0.120988,290.062958,14.776512,1.209880,-287.080048,294.500458,0.000000
119.810005,65.190125,-287.124542,-0.001362,0.004763,0.120988,289.980164,14.772293,1.209880,-287.124542,294.500458,0.000000
120.230003,65.168152,-287.169006,-0.001350,0.004763,0.120988,289.882416,14.767315,1.209880,-287.169006,294.500458,0.000000
120.650009,65.246735,-287.124542,-0.001345,0.004766,0.121056,290.231964,14.785122,1.210561,-287.124542,294.500458,0.000000
121.070007,65.301468,-287.169006,-0.001358,0.004766,0.121065,290.475433,14.797524,1.210652,-287.169006,294.500458,0.000000
121.490005,65.292526,-287.169006,-0.001332,0.004766,0.121065,290.435669,14.795499,1.210652,-287.169006,294.500458,0.000000
121.910004,65.291794,-287.257996,-0.001358,0.004766,0.121065,290.432404,14.795332,1.210652,-287.257996,294.500458,0.000000
122.330009,65.291794,-287.257996,-0.001350,0.004766,0.121065,290.432404,14.795332,1.210652,-287.257996,294.500458,0.000000
122.750008,65.274292,-287.302460,-0.001354,0.004767,0.121074,290.354553,14.791366,1.210742,-287.302460,294.500458,0.000000
123.170006,65.251938,-287.302460,-0.001358,0.004767,0.121074,290.255127,14.786300,1.210742,-287.302460,294.500458,0.000000
123.590004,65.259018,-287.391418,-0.001345,0.004767,0.121074,290.286621,14.787905,1.210742,-287.391418,294.500458,0.000000
124.010002,65.243011,-287.435913,-0.001350,0.004767,0.121074,290.215424,14.784278,1.210742,-287.435913,294.500458,0.000000
124.430008,65.249710,-287.435913,-0.001350,0.004767,0.121091,290.245209,14.785795,1.210909,-287.435913,294.500458,0.000000
124.850006,65.260132,-287.480377,-0.001341,0.004768,0.121100,290.291565,14.788157,1.211000,-287.480377,294.500458,0.000000
125.270004,65.229980,-287.435913,-0.001345,0.004768,0.121100,290.157440,14.781325,1.211000,-287.435913,294.500458,0.000000
125.690002,65.233704,-287.524872,-0.001358,0.004768,0.121109,290.174011,14.782168,1.211091,-287.524872,294.500458,0.000000
126.110008,65.216568,-287.569336,-0.001350,0.004768,0.121109,290.097778,14.778286,1.211091,-287.569336,294.500458,0.000000
126.530006,65.256409,-287.569336,-0.001337,0.004769,0.121144,290.274994,14.787313,1.211439,-287.569336,294.500458,0.000000
126.950005,65.269440,-287.524872,-0.001350,0.004769,0.121144,290.332977,14.790266,1.211439,-287.524872,294.500458,0.000000
127.370003,65.260132,-287.613831,-0.001341,0.004769,0.121144,290.291565,14.788157,1.211439,-287.613831,294.500458,0.000000
127.790009,65.256042,-287.613831,-0.001345,0.004769,0.121144,290.273376,14.787230,1.211439,-287.613831,294.500458,0.000000
128.210007,65.255661,-287.702789,-0.001358,0.004769,0.121144,290.271667,14.787145,1.211439,-287.702789,294.500458,0.000000
128.630005,65.267578,-287.747284,-0.001350,0.004770,0.121161,290.324677,14.789845,1.211605,-287.747284,294.500458,0.000000
129.050003,65.252319,-287.702789,-0.001362,0.004770,0.121161,290.256805,14.786387,1.211605,-287.702789,294.500458,0.000000
129.470001,65.254181,-287.747284,-0.001337,0.004770,0.121161,290.265106,14.786808,1.211605,-287.747284,294.500458,0.000000
129.889999,65.263107,-287.791748,-0.001350,0.004770,0.121170,290.304810,14.788831,1.211696,-287.791748,294.500458,0.000000
130.310013,65.232208,-287.836243,-0.001345,0.004771,0.121186,290.167358,14.781830,1.211863,-287.836243,294.500458,0.000000
130.730011,65.254547,-287.880707,-0.001341,0.004771,0.121186,290.266724,14.786892,1.211863,-287.880707,294.500458,0.000000
131.150009,65.241882,-287.836243,-0.001341,0.004771,0.121186,290.210388,14.784021,1.211863,-287.836243,294.500458,0.000000
131.570007,65.233704,-287.880707,-0.001337,0.004771,0.121186,290.174011,14.782168,1.211863,-287.880707,294.500458,0.000000
131.990005,65.233704,-287.925201,-0.001341,0.004771,0.121186,290.174011,14.782168,1.211863,-287.925201,294.500458,0.000000
132.410004,65.209122,-287.880707,-0.001350,0.004771,0.121186,290.064667,14.776598,1.211863,-287.880707,294.500458,0.000000
132.830002,65.264969,-288.014160,-0.001350,0.004773,0.121247,290.313080,14.789253,1.212468,-288.014160,294.500458,0.000000
133.250000,65.303329,-288.058624,-0.001341,0.004773,0.121247,290.483704,14.797946,1.212468,-288.058624,294.500458,0.000000
133.670013,65.306686,-288.014160,-0.001345,0.004773,0.121247,290.498657,14.798706,1.212468,-288.014160,294.500458,0.000000
134.090012,65.306686,-288.058624,-0.001345,0.004773,0.121247,290.498657,14.798706,1.212468,-288.058624,294.500458,0.000000
134.510010,65.302963,-288.103119,-0.001350,0.004773,0.121247,290.482086,14.797863,1.212468,-288.103119,294.500458,0.000000
134.930008,65.376312,-288.192078,-0.001354,0.004776,0.121300,290.808350,14.814484,1.212998,-288.192078,294.500458,0.000000
135.350006,65.431061,-288.192078,-0.001341,0.004776,0.121300,291.051880,14.826890,1.212998,-288.192078,294.500458,0.000000
135.770004,65.448181,-288.236572,-0.001341,0.004776,0.121300,291.128052,14.830770,1.212998,-288.236572,294.500458,0.000000
136.190002,65.463074,-288.192078,-0.001345,0.004776,0.121300,291.194305,14.834145,1.212998,-288.192078,294.500458,0.000000
136.610001,65.456375,-288.281036,-0.001341,0.004776,0.121300,291.164490,14.832626,1.212998,-288.281036,294.500458,0.000000
137.030014,65.449295,-288.281036,-0.001354,0.004776,0.121300,291.132996,14.831022,1.212998,-288.281036,294.500458,0.000000
137.450012,65.434402,-288.325531,-0.001324,0.004776,0.121300,291.066772,14.827648,1.212998,-288.325531,294.500458,0.000000
137.870010,65.418015,-288.369995,-0.001332,0.004776,0.121300,290.993866,14.823934,1.212998,-288.369995,294.500458,0.000000
138.290009,65.402008,-288.325531,-0.001332,0.004776,0.121300,290.922668,14.820307,1.212998,-288.325531,294.500458,0.000000
138.710007,65.402374,-288.369995,-0.001345,0.004776,0.121300,290.924286,14.820390,1.212998,-288.369995,294.500458,0.000000
139.130005,65.379669,-288.414490,-0.001341,0.004776,0.121309,290.823303,14.815245,1.213089,-288.414490,294.500458,0.000000
139.550003,65.361053,-288.547943,-0.001354,0.004776,0.121316,290.740479,14.811027,1.213165,-288.547943,294.500458,0.000000
139.970001,65.372589,-288.458954,-0.001341,0.004777,0.121335,290.791809,14.813641,1.213346,-288.458954,294.500458,0.000000
140.389999,65.381149,-288.547943,-0.001337,0.004777,0.121335,290.829865,14.815579,1.213346,-288.547943,294.500458,0.000000
140.810013,65.408707,-288.547943,-0.001337,0.004777,0.121342,290.952454,14.821825,1.213422,-288.547943,1681.640747,0.000000
141.230011,65.426590,-288.592407,-0.001345,0.004768,0.121109,291.032013,14.825877,1.211091,-288.592407,0.120970,0.000000
141.650009,65.298859,-288.681366,-0.001354,0.004753,0.120735,290.463837,14.796933,1.207351,-288.681366,0.120267,0.000000
142.070007,65.228851,-288.681366,-0.001354,0.004726,0.120051,290.152435,14.781069,1.200508,-288.681366,0.119565,0.000000
142.490005,65.172256,-288.681366,-0.001332,0.004701,0.119400,289.900665,14.768245,1.193998,-288.681366,0.118862,0.000000
142.910004,65.187515,-288.681366,-0.001341,0.004679,0.118846,289.968536,14.771702,1.188457,-288.681366,0.118169,0.000000
143.330002,65.167038,-288.725861,-0.001354,0.004648,0.118055,289.877472,14.767062,1.180554,-288.725861,0.117466,0.000000
143.750000,65.102249,-288.859283,-0.001337,0.004627,0.117536,289.589264,14.752380,1.175361,-288.859283,0.116764,0.000000
144.170013,65.063889,-288.814819,-0.001341,0.004592,0.116625,289.418640,14.743688,1.166247,-288.814819,0.116062,0.000000
144.590012,65.020325,-288.859283,-0.001337,0.004565,0.115957,289.224854,14.733816,1.159571,-288.859283,0.115368,0.000000
145.010010,64.911972,-288.814819,-0.001337,0.004536,0.115212,288.742859,14.709263,1.152122,-288.814819,0.114666,0.000000
145.430008,64.628586,-288.859283,-0.001345,0.004518,0.114752,287.482300,14.645047,1.147520,-288.859283,0.113963,0.000000
145.850006,63.663773,-288.948273,-0.001337,0.004487,0.113980,283.190613,14.426417,1.139798,-288.948273,0.113268,0.000000
146.270004,62.415581,-288.948273,-0.001345,0.004463,0.113356,277.638367,14.143573,1.133561,-288.948273,0.112566,0.000000
146.690002,60.985298,-289.037231,-0.001341,0.004439,0.112740,271.276154,13.819467,1.127399,-289.037231,0.111863,0.000000
147.110001,58.694839,-288.992737,-0.001337,0.004407,0.111942,261.087677,13.300441,1.119421,-288.992737,0.111162,0.000000
147.530014,56.794250,-288.992737,-0.001315,0.004387,0.111421,252.633438,12.869761,1.114213,-288.992737,0.110467,0.000000
147.950012,54.412926,-289.037231,-0.001315,0.004358,0.110684,242.040787,12.330146,1.106840,-289.037231,0.109765,0.000000
148.370010,51.650291,-289.126190,-0.001306,0.004333,0.110069,229.751968,11.704123,1.100693,-289.126190,0.109063,0.000000
148.790009,47.890450,-289.170654,-0.001306,0.004299,0.109184,213.027359,10.852131,1.091836,-289.170654,0.108369,0.000000
149.210007,45.275650,-289.126190,-0.001328,0.004276,0.108620,201.396149,10.259609,1.086204,-289.126190,0.107667,0.000000
149.630005,42.519348,-289.170654,-0.001311,0.004252,0.108004,189.135513,9.635022,1.080042,-289.170654,0.106964,0.000000
150.050003,38.966171,-289.170654,-0.001315,0.004218,0.107138,173.330185,8.829861,1.071383,-289.170654,0.106262,0.000000
150.470001,36.518196,-289.215149,-0.001311,0.004197,0.106592,162.441055,8.275142,1.065917,-289.215149,0.105568,0.000000
150.890015,32.333099,-289.304108,-0.001311,0.004160,0.105655,143.824814,7.326785,1.056546,-289.304108,0.104866,0.000000
151.310013,30.391174,-289.304108,-0.001311,0.004143,0.105229,135.186691,6.886738,1.052292,-289.304108,0.104163,0.000000
151.730011,28.816040,-289.348572,-0.001311,0.004131,0.104926,128.180145,6.529808,1.049264,-289.348572,0.103461,0.000000
152.150009,24.931084,-289.304108,-0.001311,0.004094,0.103998,110.899002,5.649464,1.039983,-289.304108,0.102767,0.000000
152.570007,21.331352,-289.393066,-0.001315,0.004060,0.103114,94.886597,4.833754,1.031142,-289.393066,0.102065,0.000000
152.990005,19.028229,-289.437561,-0.001306,0.004036,0.102524,84.641792,4.311858,1.025237,-289.437561,0.101363,0.000000
153.410004,15.801994,-289.437561,-0.001311,0.004012,0.101900,70.290779,3.580783,1.019000,-289.437561,0.100668,0.000000
153.830002,15.664963,-289.437561,-0.001324,0.004012,0.101900,69.681236,3.549731,1.019000,-289.437561,0.099965,0.000000
154.250000,9.120522,-289.393066,-0.001306,0.003948,0.100286,40.570107,2.066740,1.002861,-289.393066,0.099263,0.000000
154.670013,6.496407,-289.526520,-0.001319,0.003927,0.099740,28.897459,1.472107,0.997396,-289.526520,0.098560,0.000000
155.090012,2.556709,-289.526520,-0.001311,0.003890,0.098795,11.372811,0.579359,0.987948,-289.526520,0.097867,0.000000
155.510010,0.383171,-289.570984,-0.001315,0.003869,0.098274,1.704430,0.086828,0.982740,-289.570984,0.097164,0.000000
155.930008,-2.545910,-289.615479,-0.001315,0.003841,0.097555,-11.324773,-0.576911,0.975549,-289.615479,0.096462,0.000000
156.350006,0.171661,-289.659943,-0.001306,0.003814,0.096869,0.763588,0.038899,0.968691,-289.659943,0.095768,0.000000
156.770004,0.281143,-289.704437,-0.001216,0.003787,0.096185,1.250587,0.063708,0.961848,-289.704437,0.095066,0.000000
157.190002,0.171288,-289.748901,-0.001160,0.003757,0.095438,0.761925,0.038814,0.954384,-289.748901,0.094363,0.000000
157.610001,0.118042,-289.748901,-0.001108,0.003737,0.094910,0.525077,0.026749,0.949100,-289.748901,0.093661,0.000000
158.030014,0.084526,-289.748901,-0.001052,0.003708,0.094173,0.375991,0.019154,0.941727,-289.748901,0.092968,0.000000
158.450012,-0.002609,-289.793396,-0.001069,0.003676,0.093366,-0.011607,-0.000591,0.933658,-289.793396,0.092265,0.000000
158.870010,-0.016014,-289.837891,-0.001078,0.003644,0.092560,-0.071234,-0.003629,0.925604,-289.837891,0.091563,0.000000
159.290009,-0.061440,-289.837891,-0.001078,0.003619,0.091926,-0.273297,-0.013922,0.919260,-289.837891,0.090860,0.000000
159.710007,-0.045433,-289.882355,-0.001095,0.003602,0.091484,-0.202096,-0.010295,0.914839,-289.882355,0.090167,0.000000
160.130005,-0.068520,-289.926849,-0.001125,0.003559,0.090409,-0.304790,-0.015527,0.904090,-289.926849,0.089464,0.000000
160.550003,-0.088249,-289.926849,-0.001134,0.003541,0.089941,-0.392552,-0.019998,0.899412,-289.926849,0.088762,0.000000
160.970001,-0.125488,-289.926849,-0.001147,0.003506,0.089048,-0.558200,-0.028436,0.890480,-289.926849,0.088067,0.000000
161.390015,-0.109482,-290.015808,-0.001160,0.003493,0.088727,-0.486999,-0.024809,0.887270,-290.015808,0.087364,0.000000
161.810013,-0.100540,-290.015808,-0.001186,0.003468,0.088085,-0.447225,-0.022783,0.880851,-290.015808,0.086662,0.000000
162.230011,-0.121391,-290.104767,-0.001224,0.003424,0.086975,-0.539975,-0.027508,0.869754,-290.104767,0.085960,0.000000
162.650009,-0.090858,-290.060272,-0.001237,0.003408,0.086559,-0.404159,-0.020589,0.865590,-290.060272,0.085266,0.000000
163.070007,-0.111710,-290.060272,-0.001259,0.003370,0.085604,-0.496909,-0.025314,0.856037,-290.060272,0.084564,0.000000
163.490005,-0.110970,-290.060272,-0.001285,0.003354,0.085189,-0.493617,-0.025146,0.851889,-290.060272,0.083861,0.000000
163.910004,-0.117294,-290.104767,-0.001319,0.003315,0.084208,-0.521751,-0.026579,0.842079,-290.104767,0.083168,0.000000
164.330002,-0.093094,-290.238220,-0.001341,0.003289,0.083531,-0.414102,-0.021095,0.835311,-290.238220,0.082465,0.000000
164.750015,-0.064423,-290.238220,-0.001354,0.003256,0.082700,-0.286566,-0.014598,0.827000,-290.238220,0.081763,0.000000
165.170013,-0.081924,-290.282684,-0.001384,0.003234,0.082144,-0.364418,-0.018564,0.821443,-290.282684,0.081060,0.000000
165.590012,-0.063675,-290.238220,-0.001418,0.003200,0.081286,-0.283240,-0.014429,0.812859,-290.238220,0.080367,0.000000
166.010010,-0.097931,-290.371643,-0.001457,0.003174,0.080609,-0.435618,-0.022191,0.806092,-290.371643,0.079664,0.000000
166.430008,-0.048409,-290.327179,-0.001487,0.003149,0.079976,-0.215332,-0.010970,0.799763,-290.327179,0.078962,0.000000
166.850006,-0.051392,-290.371643,-0.001496,0.003118,0.079195,-0.228601,-0.011646,0.791951,-290.371643,0.078260,0.000000
167.270004,-0.054741,-290.371643,-0.001518,0.003094,0.078597,-0.243500,-0.012404,0.785971,-290.371643,0.077565,0.000000
167.690002,-0.080803,-290.371643,-0.001561,0.003065,0.077843,-0.359429,-0.018310,0.778432,-290.371643,0.076862,0.000000
168.110001,-0.092720,-290.460602,-0.001595,0.003039,0.077183,-0.412439,-0.021011,0.771831,-290.460602,0.076160,0.000000
168.530014,-0.048782,-290.460602,-0.001625,0.003008,0.076394,-0.216995,-0.011054,0.763943,-290.460602,0.075466,0.000000
168.950012,-0.071869,-290.505096,-0.001634,0.002987,0.075874,-0.319689,-0.016286,0.758735,-290.505096,0.074764,0.000000
169.370010,-0.067398,-290.505096,-0.001669,0.002951,0.074955,-0.299802,-0.015273,0.749545,-290.505096,0.074061,0.000000
169.790009,-0.102028,-290.505096,-0.001699,0.002928,0.074366,-0.453843,-0.023120,0.743656,-290.505096,0.073359,0.000000
170.210007,-0.081177,-290.549561,-0.001725,0.002895,0.073524,-0.361092,-0.018395,0.735239,-290.549561,0.072665,0.000000
170.630005,-0.074104,-290.594055,-0.001768,0.002868,0.072847,-0.329632,-0.016792,0.728471,-290.594055,0.072744,0.000000
170.800003,-0.070755,-290.549561,-0.001763,0.002869,0.072865,-0.314734,-0.016033,0.728653,-290.549561,0.072744,0.000000