File: Data/compression 31/ManualNoHeating-10-31-reverse-1-2_11132024_181401.csv
Time (sec),S:Load (lbs),S:HL1 (DIM),S:LVDT (in),S:Position (in),Ch:Position (mm),Ch:Load (N),Ch:Stress (MPa),Ch:Strain (mm/mm),Ch:HL1 (DIM),Set Point (),Cycles ()
0.110000,-0.105751,-325.689514,-0.009791,-0.004729,-0.120119,-0.470404,-0.023964,-1.201189,-325.689514,-0.119902,0.000000
0.510000,-0.094208,-325.778473,-0.009774,-0.004662,-0.118419,-0.419057,-0.021348,-1.184188,-325.778473,-0.117856,0.000000
0.910000,-0.063301,-325.778473,-0.009606,-0.004417,-0.112184,-0.281577,-0.014344,-1.121843,-325.778473,-0.111196,0.000000
1.310000,-0.104263,-325.778473,-0.009356,-0.004157,-0.105593,-0.463786,-0.023626,-1.055925,-325.778473,-0.104518,0.000000
1.710000,-0.164963,-325.778473,-0.009084,-0.003896,-0.098951,-0.733791,-0.037381,-0.989508,-325.778473,-0.097858,0.000000
2.110000,-0.142616,-325.822968,-0.008826,-0.003636,-0.092350,-0.634389,-0.032317,-0.923499,-325.822968,-0.091198,0.000000
2.510000,-0.082664,-325.867462,-0.008554,-0.003375,-0.085725,-0.367710,-0.018732,-0.857248,-325.867462,-0.084536,0.000000
2.910000,-0.074104,-325.822968,-0.008274,-0.003110,-0.078986,-0.329632,-0.016792,-0.789862,-325.822968,-0.077876,0.000000
3.310000,-0.101288,-325.911926,-0.008015,-0.002845,-0.072257,-0.450551,-0.022952,-0.722567,-325.911926,-0.071198,0.000000
3.710000,-0.084160,-325.867462,-0.007731,-0.002581,-0.065553,-0.374362,-0.019071,-0.655529,-325.867462,-0.064539,0.000000
4.110000,-0.070755,-325.867462,-0.007468,-0.002318,-0.058867,-0.314734,-0.016033,-0.588672,-325.867462,-0.057879,0.000000
4.510000,-0.040962,-325.956421,-0.007192,-0.002060,-0.052328,-0.182209,-0.009282,-0.523284,-325.956421,-0.051219,0.000000
4.910000,-0.040588,-326.000885,-0.006924,-0.001802,-0.045771,-0.180546,-0.009197,-0.457715,-326.000885,-0.044557,0.000000
5.310000,-0.067772,-326.000885,-0.006657,-0.001545,-0.039251,-0.301465,-0.015357,-0.392509,-326.000885,-0.037881,0.000000
5.710000,-0.090118,-326.089844,-0.006381,-0.001274,-0.032364,-0.400867,-0.020421,-0.323639,-326.089844,-0.031219,0.000000
6.110000,-0.103523,-326.089844,-0.006101,-0.001007,-0.025583,-0.460494,-0.023459,-0.255829,-326.089844,-0.024559,0.000000
6.510000,-0.056976,-326.134338,-0.005829,-0.000747,-0.018984,-0.253443,-0.012911,-0.189835,-326.134338,-0.017900,0.000000
6.910000,-0.043571,-326.134338,-0.005575,-0.000482,-0.012236,-0.193816,-0.009873,-0.122358,-326.134338,-0.011221,0.000000
7.310000,-0.053619,-326.178802,-0.005282,-0.000220,-0.005585,-0.238511,-0.012150,-0.055850,-326.178802,-0.004562,0.000000
7.710001,0.160118,-326.178802,-0.005019,-0.000002,-0.000044,0.712241,0.036283,-0.000439,-326.178802,0.000103,0.000000
8.110001,0.120651,-326.223297,-0.005027,-0.000003,-0.000079,0.536684,0.027340,-0.000787,-326.223297,0.000103,0.000000
8.510000,0.126976,-326.178802,-0.005014,-0.000003,-0.000079,0.564817,0.028773,-0.000787,-326.178802,0.000615,0.000000
8.910001,0.145599,-326.267761,-0.005010,0.000016,0.000407,0.647658,0.032993,0.004073,-326.267761,0.001282,0.000000
9.310000,0.242416,-326.267761,-0.004988,0.000044,0.001126,1.078322,0.054932,0.011264,-326.267761,0.001950,0.000000
9.710000,0.327690,-326.356750,-0.004958,0.000069,0.001752,1.457639,0.074256,0.017516,-326.356750,0.002618,0.000000
10.110001,0.408867,-326.356750,-0.004932,0.000087,0.002219,1.818731,0.092651,0.022195,-326.356750,0.003278,0.000000
10.510000,0.594307,-326.356750,-0.004885,0.000126,0.003199,2.643609,0.134672,0.031990,-326.356750,0.003945,0.000000
10.910001,0.685165,-326.356750,-0.004863,0.000147,0.003746,3.047768,0.155261,0.037455,-326.356750,0.004613,0.000000
11.310000,0.834862,-326.445709,-0.004846,0.000174,0.004422,3.713650,0.189182,0.044223,-326.445709,0.005281,0.000000
11.710001,1.011734,-326.490173,-0.004825,0.000196,0.004985,4.500418,0.229262,0.049855,-326.490173,0.005948,0.000000
12.110001,1.128662,-326.490173,-0.004807,0.000219,0.005550,5.020540,0.255758,0.055502,-326.490173,0.006616,0.000000
12.510000,1.437729,-326.490173,-0.004751,0.000257,0.006530,6.395338,0.325794,0.065297,-326.490173,0.007284,0.000000
12.910001,1.537895,-326.534668,-0.004730,0.000279,0.007085,6.840899,0.348492,0.070853,-326.534668,0.007951,0.000000
13.310000,1.790367,-326.534668,-0.004700,0.000308,0.007821,7.963951,0.405703,0.078211,-326.534668,0.008611,0.000000
13.710001,1.884575,-326.579132,-0.004669,0.000324,0.008230,8.383008,0.427051,0.082299,-326.579132,0.009279,0.000000
14.110001,2.179497,-326.490173,-0.004644,0.000359,0.009123,9.694886,0.493881,0.091231,-326.490173,0.009947,0.000000
14.510000,2.367912,-326.668091,-0.004626,0.000385,0.009773,10.533000,0.536577,0.097726,-326.668091,0.010614,0.000000
14.910001,2.506813,-326.623627,-0.004605,0.000410,0.010424,11.150862,0.568052,0.104236,-326.623627,0.011282,0.000000
15.310000,2.706406,-326.668091,-0.004566,0.000435,0.011056,12.038693,0.613280,0.110564,-326.668091,0.011950,0.000000
15.710001,2.986801,-326.712585,-0.004544,0.000463,0.011768,13.285955,0.676819,0.117680,-326.712585,0.012617,0.000000
16.110001,3.204262,-326.712585,-0.004497,0.000495,0.012583,14.253268,0.726096,0.125825,-326.712585,0.013285,0.000000
16.510000,3.194580,-326.757080,-0.004458,0.000519,0.013181,14.210202,0.723902,0.131805,-326.757080,0.013953,0.000000
16.910002,3.334595,-326.757080,-0.004428,0.000539,0.013701,14.833018,0.755630,0.137013,-326.757080,0.014613,0.000000
17.310001,3.620201,-326.801544,-0.004398,0.000570,0.014490,16.103458,0.820349,0.144901,-326.801544,0.015280,0.000000
17.710001,3.730423,-326.801544,-0.004372,0.000591,0.015020,16.593750,0.845326,0.150200,-326.801544,0.015948,0.000000
18.110001,3.916237,-326.801544,-0.004342,0.000619,0.015722,17.420292,0.887432,0.157225,-326.801544,0.016616,0.000000
18.510000,4.017151,-326.934998,-0.004290,0.000647,0.016434,17.869179,0.910299,0.164340,-326.934998,0.017283,0.000000
18.910002,4.008217,-326.890503,-0.004268,0.000668,0.016971,17.829439,0.908275,0.169715,-326.890503,0.017951,0.000000
19.310001,4.149345,-326.846039,-0.004238,0.000698,0.017725,18.457211,0.940255,0.177254,-326.846039,0.018619,0.000000
19.710001,4.201477,-326.890503,-0.004195,0.000717,0.018220,18.689104,0.952068,0.182205,-326.890503,0.019286,0.000000
20.110001,4.413727,-327.023956,-0.004174,0.000749,0.019018,19.633238,1.000165,0.190183,-327.023956,0.019945,0.000000
20.510000,4.482620,-326.979462,-0.004135,0.000776,0.019719,19.939692,1.015776,0.197193,-326.979462,0.020614,0.000000
20.910002,4.442032,-327.023956,-0.004105,0.000800,0.020310,19.759144,1.006579,0.203097,-327.023956,0.021282,0.000000
21.310001,4.600288,-327.023956,-0.004074,0.000829,0.021056,20.463104,1.042440,0.210561,-327.023956,0.021949,0.000000
21.710001,4.551132,-327.112915,-0.004036,0.000845,0.021463,20.244448,1.031301,0.214634,-327.112915,0.022617,0.000000
22.110001,4.782379,-327.157410,-0.003980,0.000885,0.022487,21.273085,1.083703,0.224868,-327.157410,0.023285,0.000000
22.510000,4.700829,-327.112915,-0.003958,0.000907,0.023041,20.910330,1.065223,0.230409,-327.112915,0.023952,0.000000
22.910002,4.793922,-327.157410,-0.003923,0.000933,0.023701,21.324432,1.086318,0.237010,-327.157410,0.024620,0.000000
23.310001,4.842331,-327.157410,-0.003876,0.000959,0.024360,21.539764,1.097288,0.243596,-327.157410,0.025279,0.000000
23.710001,4.727638,-327.201874,-0.003863,0.000974,0.024741,21.029585,1.071298,0.247411,-327.201874,0.025946,0.000000
24.110001,4.975266,-327.201874,-0.003794,0.001013,0.025721,22.131086,1.127411,0.257206,-327.201874,0.026614,0.000000
24.510000,4.950691,-327.290833,-0.003773,0.001039,0.026388,22.021774,1.121843,0.263883,-327.290833,0.027282,0.000000
24.910002,4.916435,-327.246368,-0.003742,0.001063,0.027004,21.869396,1.114080,0.270045,-327.246368,0.027951,0.000000
25.310001,5.129059,-327.246368,-0.003695,0.001094,0.027786,22.815193,1.162261,0.277857,-327.246368,0.028618,0.000000
25.710001,4.932816,-327.335327,-0.003673,0.001108,0.028132,21.942259,1.117792,0.281324,-327.335327,0.029286,0.000000
26.110001,5.208748,-327.379791,-0.003626,0.001148,0.029147,23.169668,1.180319,0.291467,-327.379791,0.029954,0.000000
26.510002,5.073944,-327.379791,-0.003591,0.001166,0.029607,22.570030,1.149772,0.296070,-327.379791,0.030612,0.000000
26.910002,5.202042,-327.379791,-0.003548,0.001196,0.030387,23.139837,1.178799,0.303867,-327.379791,0.031280,0.000000
27.310001,5.315987,-327.424286,-0.003531,0.001226,0.031133,23.646690,1.204620,0.311330,-327.424286,0.031948,0.000000
27.710001,5.048996,-327.468750,-0.003497,0.001235,0.031359,22.459055,1.144119,0.313586,-327.468750,0.032615,0.000000
28.110001,5.384880,-327.468750,-0.003428,0.001275,0.032390,23.953142,1.220231,0.323896,-327.468750,0.033283,0.000000
28.510002,5.396049,-327.557709,-0.003423,0.001302,0.033075,24.002827,1.222762,0.330754,-327.557709,0.033951,0.000000
28.910002,5.479462,-327.468750,-0.003363,0.001329,0.033769,24.373863,1.241664,0.337688,-327.468750,0.034620,0.000000
29.310001,5.516327,-327.602203,-0.003333,0.001354,0.034385,24.537848,1.250018,0.343850,-327.602203,0.035287,0.000000
29.710001,5.661552,-327.557709,-0.003303,0.001381,0.035087,25.183844,1.282926,0.350875,-327.557709,0.035955,0.000000
30.110001,5.594154,-327.602203,-0.003277,0.001408,0.035764,24.884041,1.267654,0.357642,-327.602203,0.036614,0.000000
30.510002,5.638832,-327.646698,-0.003216,0.001434,0.036432,25.082777,1.277778,0.364319,-327.646698,0.037281,0.000000
30.910002,5.738258,-327.646698,-0.003195,0.001464,0.037177,25.525047,1.300308,0.371768,-327.646698,0.037949,0.000000
31.310001,5.628036,-327.646698,-0.003147,0.001482,0.037637,25.034758,1.275331,0.376370,-327.646698,0.038617,0.000000
31.710001,5.893539,-327.691162,-0.003109,0.001517,0.038521,26.215773,1.335495,0.385211,-327.691162,0.039284,0.000000
32.110001,5.736023,-327.735657,-0.003091,0.001538,0.039077,25.515104,1.299801,0.390768,-327.735657,0.039952,0.000000
32.510002,5.825768,-327.691162,-0.003031,0.001565,0.039754,25.914309,1.320138,0.397535,-327.691162,0.040619,0.000000
32.910000,5.919601,-327.735657,-0.003005,0.001593,0.040464,26.331703,1.341401,0.404636,-327.735657,0.041289,0.000000
33.310001,5.803795,-327.735657,-0.002988,0.001610,0.040889,25.816568,1.315159,0.408890,-327.735657,0.041947,0.000000
33.710003,6.050308,-327.824615,-0.002932,0.001647,0.041843,26.913115,1.371019,0.418428,-327.824615,0.042615,0.000000
34.110001,5.921463,-327.824615,-0.002906,0.001669,0.042380,26.339983,1.341823,0.423802,-327.824615,0.043283,0.000000
34.510002,6.006737,-327.824615,-0.002863,0.001695,0.043048,26.719299,1.361146,0.430479,-327.824615,0.043950,0.000000
34.910000,6.103554,-327.869080,-0.002828,0.001721,0.043716,27.149963,1.383085,0.437155,-327.869080,0.044618,0.000000
35.310001,5.997429,-327.913574,-0.002807,0.001739,0.044176,26.677896,1.359037,0.441758,-327.913574,0.045286,0.000000
35.710003,6.318047,-327.913574,-0.002746,0.001779,0.045199,28.104074,1.431690,0.451992,-327.913574,0.045953,0.000000
36.110001,6.125900,-328.002533,-0.002721,0.001800,0.045720,27.249365,1.388149,0.457200,-328.002533,0.046621,0.000000
36.510002,6.124039,-328.002533,-0.002682,0.001824,0.046318,27.241085,1.387727,0.463180,-328.002533,0.047281,0.000000
36.910000,6.318787,-328.002533,-0.002665,0.001851,0.047011,28.107367,1.431858,0.470114,-328.002533,0.047949,0.000000
37.310001,6.106537,-328.002533,-0.002621,0.001869,0.047463,27.163233,1.383761,0.474626,-328.002533,0.048616,0.000000
37.710003,6.481140,-328.047028,-0.002570,0.001911,0.048547,28.829552,1.468647,0.485466,-328.047028,0.049284,0.000000
38.110001,6.211548,-328.091492,-0.002535,0.001931,0.049042,27.630344,1.407557,0.490416,-328.091492,0.049952,0.000000
38.510002,6.614449,-328.047028,-0.002492,0.001965,0.049900,29.422537,1.498855,0.499001,-328.047028,0.050619,0.000000
38.910004,6.575722,-328.135986,-0.002475,0.001989,0.050524,29.250271,1.490080,0.505238,-328.135986,0.051287,0.000000
39.310001,6.216385,-328.135986,-0.002449,0.001997,0.050733,27.651861,1.408653,0.507327,-328.135986,0.051954,0.000000
39.710003,6.530670,-328.180450,-0.002393,0.002033,0.051626,29.049871,1.479871,0.516260,-328.180450,0.052615,0.000000
40.110001,6.514282,-328.180450,-0.002376,0.002061,0.052362,28.976974,1.476158,0.523618,-328.180450,0.053282,0.000000
40.510002,6.697861,-328.224945,-0.002324,0.002093,0.053152,29.793573,1.517757,0.531520,-328.224945,0.053950,0.000000
40.910004,6.561577,-328.269409,-0.002285,0.002113,0.053671,29.187351,1.486874,0.536713,-328.269409,0.054618,0.000000
41.310001,6.855751,-328.313904,-0.002251,0.002140,0.054366,30.495903,1.553535,0.543662,-328.313904,0.055285,0.000000
41.710003,6.728027,-328.313904,-0.002207,0.002165,0.054990,29.927761,1.524593,0.549900,-328.313904,0.055953,0.000000
42.110001,6.670677,-328.313904,-0.002169,0.002191,0.055649,29.672653,1.511597,0.556486,-328.313904,0.056621,0.000000
42.510002,6.742920,-328.358368,-0.002130,0.002219,0.056369,29.994005,1.527968,0.563692,-328.358368,0.057288,0.000000
42.910004,6.720207,-328.402863,-0.002091,0.002243,0.056976,29.892975,1.522821,0.569763,-328.402863,0.057956,0.000000
43.310001,6.967087,-328.447357,-0.002048,0.002275,0.057783,30.991150,1.578764,0.577832,-328.447357,0.058614,0.000000
43.710003,6.776802,-328.447357,-0.002022,0.002299,0.058407,30.144722,1.535645,0.584070,-328.447357,0.059284,0.000000
44.110001,6.710899,-328.447357,-0.001988,0.002322,0.058970,29.851572,1.520712,0.589702,-328.447357,0.059951,0.000000
44.510002,6.901550,-328.402863,-0.001940,0.002354,0.059786,30.699629,1.563914,0.597862,-328.402863,0.060619,0.000000
44.910004,6.711639,-328.491821,-0.001910,0.002370,0.060210,29.854862,1.520879,0.602101,-328.491821,0.061287,0.000000
45.310001,7.088112,-328.536316,-0.001876,0.002406,0.061122,31.529497,1.606189,0.611215,-328.536316,0.061954,0.000000
45.710003,6.958893,-328.536316,-0.001837,0.002431,0.061745,30.954700,1.576908,0.617453,-328.536316,0.062622,0.000000
46.110001,7.024063,-328.536316,-0.001789,0.002458,0.062422,31.244593,1.591676,0.624220,-328.536316,0.063290,0.000000
46.510002,7.009911,-328.625275,-0.001759,0.002484,0.063082,31.181639,1.588468,0.630821,-328.625275,0.063948,0.000000
46.910004,6.793564,-328.625275,-0.001738,0.002501,0.063524,30.219282,1.539443,0.635242,-328.625275,0.064616,0.000000
47.310001,7.258286,-328.580780,-0.001686,0.002541,0.064539,32.286465,1.644751,0.645385,-328.580780,0.065283,0.000000
47.710003,6.923889,-328.625275,-0.001638,0.002558,0.064981,30.798998,1.568976,0.649806,-328.625275,0.065953,0.000000
48.110001,7.087738,-328.714233,-0.001625,0.002587,0.065718,31.527834,1.606104,0.657179,-328.714233,0.066620,0.000000
48.510002,7.089600,-328.758698,-0.001565,0.002613,0.066376,31.536114,1.606526,0.663765,-328.758698,0.067288,0.000000
48.910004,6.865433,-328.714233,-0.001556,0.002629,0.066776,30.538971,1.555729,0.667761,-328.714233,0.067956,0.000000
49.310001,7.418404,-328.803192,-0.001505,0.002671,0.067842,32.998707,1.681034,0.678420,-328.803192,0.068623,0.000000
49.710003,7.107101,-328.758698,-0.001470,0.002691,0.068363,31.613966,1.610492,0.683628,-328.758698,0.069282,0.000000
50.110001,7.247856,-328.847656,-0.001436,0.002719,0.069074,32.240074,1.642388,0.690743,-328.847656,0.069949,0.000000
50.510002,7.393829,-328.803192,-0.001406,0.002747,0.069777,32.889397,1.675466,0.697768,-328.803192,0.070617,0.000000
50.910004,7.098534,-328.892151,-0.001375,0.002761,0.070140,31.575855,1.608551,0.701402,-328.892151,0.071285,0.000000
51.310001,7.461967,-328.892151,-0.001337,0.002800,0.071129,33.192490,1.690906,0.711288,-328.892151,0.071952,0.000000
51.710003,7.501442,-328.936646,-0.001298,0.002827,0.071806,33.368080,1.699851,0.718055,-328.936646,0.072622,0.000000
52.110001,7.594162,-328.892151,-0.001259,0.002854,0.072499,33.780521,1.720862,0.724989,-328.892151,0.073289,0.000000
52.510002,7.615761,-328.936646,-0.001233,0.002879,0.073124,33.876595,1.725756,0.731242,-328.936646,0.073957,0.000000
52.910004,7.856316,-328.981110,-0.001186,0.002906,0.073808,34.946636,1.780267,0.738085,-328.981110,0.074615,0.000000
53.310001,7.747208,-329.025604,-0.001143,0.002934,0.074529,34.461300,1.755542,0.745291,-329.025604,0.075283,0.000000
53.710003,7.763596,-329.025604,-0.001117,0.002955,0.075067,34.534199,1.759256,0.750666,-329.025604,0.075951,0.000000
54.110004,7.997070,-329.070068,-0.001082,0.002986,0.075839,35.572746,1.812162,0.758387,-329.070068,0.076618,0.000000
54.510002,8.052185,-329.070068,-0.001052,0.003006,0.076350,35.817909,1.824651,0.763504,-329.070068,0.077286,0.000000
54.910004,8.467751,-329.114563,-0.001018,0.003039,0.077183,37.666435,1.918820,0.771831,-329.114563,0.077954,0.000000
55.310001,8.284538,-329.159027,-0.000979,0.003064,0.077823,36.851467,1.877303,0.778235,-329.159027,0.078621,0.000000
55.710003,8.425301,-329.203522,-0.000953,0.003088,0.078431,37.477608,1.909200,0.784306,-329.203522,0.079291,0.000000
56.110004,8.653938,-329.203522,-0.000910,0.003115,0.079116,38.494640,1.961010,0.791164,-329.203522,0.079958,0.000000
56.510002,8.640533,-329.203522,-0.000905,0.003134,0.079610,38.435013,1.957973,0.796100,-329.203522,0.080617,0.000000
56.910004,9.268349,-329.292480,-0.000858,0.003171,0.080538,41.227673,2.100238,0.805380,-329.292480,0.081284,0.000000
57.310001,9.000610,-329.247986,-0.000836,0.003191,0.081059,40.036713,2.039567,0.810588,-329.247986,0.081952,0.000000
57.710003,8.934334,-329.336975,-0.000798,0.003211,0.081561,39.741901,2.024549,0.815615,-329.336975,0.082620,0.000000
58.110004,9.485443,-329.292480,-0.000767,0.003243,0.082377,42.193359,2.149432,0.823775,-329.292480,0.083287,0.000000
58.510002,9.422882,-329.381439,-0.000746,0.003262,0.082863,41.915073,2.135256,0.828635,-329.381439,0.083955,0.000000
58.910004,10.217155,-329.381439,-0.000703,0.003302,0.083878,45.448177,2.315241,0.838778,-329.381439,0.084623,0.000000
59.310001,9.883141,-329.425934,-0.000668,0.003321,0.084364,43.962406,2.239552,0.843638,-329.425934,0.085290,0.000000
59.710003,10.042137,-329.425934,-0.000642,0.003345,0.084962,44.669659,2.275581,0.849618,-329.425934,0.085950,0.000000
60.110004,10.544098,-329.425934,-0.000599,0.003376,0.085741,46.902489,2.389327,0.857415,-329.425934,0.086618,0.000000
60.510002,10.293861,-329.514893,-0.000582,0.003392,0.086150,45.789383,2.332622,0.861503,-329.514893,0.087286,0.000000
60.910004,11.057228,-329.514893,-0.000543,0.003425,0.087000,49.185005,2.505604,0.869996,-329.514893,0.087953,0.000000
61.310001,11.293312,-329.559357,-0.000526,0.003453,0.087711,50.235161,2.559101,0.877112,-329.559357,0.088621,0.000000
61.710003,11.963211,-329.514893,-0.000487,0.003485,0.088517,53.215019,2.710902,0.885166,-329.514893,0.089289,0.000000
62.110004,11.646324,-329.514893,-0.000461,0.003502,0.088959,51.805439,2.639095,0.889587,-329.514893,0.089956,0.000000
62.510002,11.609459,-329.559357,-0.000431,0.003519,0.089393,51.641453,2.630741,0.893932,-329.559357,0.090624,0.000000
62.910004,12.616722,-329.603851,-0.000401,0.003559,0.090391,56.121983,2.858990,0.903909,-329.603851,0.091284,0.000000
63.310001,12.801788,-329.648315,-0.000366,0.003582,0.090989,56.945198,2.900927,0.909889,-329.648315,0.091952,0.000000
63.710003,13.162247,-329.648315,-0.000345,0.003609,0.091666,58.548599,2.982608,0.916656,-329.648315,0.092619,0.000000
64.110001,13.433708,-329.692810,-0.000319,0.003635,0.092324,59.756119,3.044122,0.923242,-329.692810,0.093287,0.000000
64.510002,14.151268,-329.692810,-0.000293,0.003664,0.093078,62.947983,3.206723,0.930781,-329.692810,0.093955,0.000000
64.910004,14.469276,-329.737305,-0.000267,0.003690,0.093738,64.362556,3.278785,0.937382,-329.737305,0.094622,0.000000
65.310005,14.810371,-329.737305,-0.000246,0.003716,0.094380,65.879822,3.356078,0.943801,-329.737305,0.095290,0.000000
65.710007,15.461647,-329.826263,-0.000194,0.003744,0.095108,68.776840,3.503659,0.951084,-329.826263,0.095958,0.000000
66.110001,15.675018,-329.737305,-0.000190,0.003767,0.095690,69.725967,3.552010,0.956897,-329.737305,0.096616,0.000000
66.510002,16.762718,-329.870728,-0.000181,0.003797,0.096453,74.564293,3.798486,0.964527,-329.870728,0.097285,0.000000
66.910004,17.056145,-329.826263,-0.000147,0.003823,0.097111,75.869522,3.864978,0.971113,-329.826263,0.097953,0.000000
67.310005,17.062851,-329.870728,-0.000108,0.003840,0.097544,75.899353,3.866497,0.975443,-329.870728,0.098621,0.000000
67.710007,18.057083,-329.870728,-0.000091,0.003873,0.098377,80.321915,4.091794,0.983770,-329.870728,0.099288,0.000000
68.110001,18.559044,-329.915222,-0.000060,0.003896,0.098958,82.554749,4.205540,0.989583,-329.915222,0.099956,0.000000
68.510002,19.791969,-329.959686,-0.000043,0.003928,0.099782,88.039078,4.484924,0.997819,-329.959686,0.100624,0.000000
68.910004,20.039597,-329.915222,-0.000026,0.003951,0.100363,89.140579,4.541038,1.003633,-329.915222,0.101291,0.000000
69.310005,20.854721,-329.915222,0.000004,0.003980,0.101101,92.766434,4.725747,1.011006,-329.915222,0.101959,0.000000
69.710007,21.859383,-330.004181,0.000026,0.004010,0.101855,97.235390,4.953407,1.018546,-330.004181,0.102618,0.000000
70.110001,21.878746,-330.048645,0.000056,0.004025,0.102236,97.321526,4.957795,1.022361,-330.048645,0.103285,0.000000
70.510002,23.626289,-330.093140,0.000073,0.004061,0.103147,105.094986,5.353794,1.031475,-330.093140,0.103954,0.000000
70.910004,23.926422,-330.137604,0.000095,0.004081,0.103667,106.430038,5.421805,1.036668,-330.137604,0.104622,0.000000
71.310005,24.708405,-330.093140,0.000116,0.004106,0.104283,109.908470,5.599005,1.042829,-330.093140,0.105290,0.000000
71.710007,26.221352,-330.093140,0.000129,0.004138,0.105107,116.638397,5.941843,1.051065,-330.093140,0.105957,0.000000
72.110001,26.209808,-330.182098,0.000155,0.004152,0.105462,116.587051,5.939227,1.054623,-330.182098,0.106625,0.000000
72.510002,28.417603,-330.182098,0.000168,0.004193,0.106504,126.407806,6.439521,1.065039,-330.182098,0.107293,0.000000
72.910004,28.786255,-330.271057,0.000190,0.004212,0.106988,128.047653,6.523058,1.069884,-330.271057,0.107951,0.000000
73.310005,30.508102,-330.226593,0.000207,0.004245,0.107830,135.706818,6.913235,1.078301,-330.226593,0.108619,0.000000
73.710007,31.166458,-330.271057,0.000237,0.004265,0.108342,138.635330,7.062420,1.083419,-330.271057,0.109287,0.000000
74.110001,31.460632,-330.315552,0.000241,0.004283,0.108793,139.943878,7.129081,1.087930,-330.315552,0.109954,0.000000
74.510002,34.136871,-330.315552,0.000250,0.004324,0.109842,151.848389,7.735526,1.098422,-330.315552,0.110623,0.000000
74.910004,34.790756,-330.315552,0.000285,0.004345,0.110371,154.757019,7.883698,1.103706,-330.315552,0.111291,0.000000
75.310005,36.598251,-330.315552,0.000297,0.004377,0.111168,162.797150,8.293283,1.111684,-330.315552,0.111959,0.000000
75.710007,37.128883,-330.360016,0.000315,0.004393,0.111577,165.157516,8.413525,1.115772,-330.360016,0.112626,0.000000
76.110001,37.986458,-330.448975,0.000310,0.004416,0.112157,168.972198,8.607855,1.121570,-330.448975,0.113285,0.000000
76.510002,40.863777,-330.493469,0.000341,0.004454,0.113129,181.771164,9.259865,1.131290,-330.493469,0.113953,0.000000
76.910004,41.895256,-330.404510,0.000362,0.004478,0.113753,186.359406,9.493601,1.137527,-330.404510,0.114620,0.000000
77.310005,43.557526,-330.448975,0.000371,0.004506,0.114464,193.753555,9.870276,1.144643,-330.448975,0.115288,0.000000
77.710007,44.762520,-330.537933,0.000375,0.004531,0.115080,199.113632,10.143332,1.150805,-330.537933,0.115956,0.000000
78.110001,46.444901,-330.537933,0.000401,0.004558,0.115765,206.597229,10.524565,1.157648,-330.537933,0.116623,0.000000
78.510002,48.426292,-330.582428,0.000401,0.004581,0.116346,215.410904,10.973555,1.163462,-330.582428,0.117291,0.000000
78.910004,49.945946,-330.582428,0.000423,0.004606,0.116997,222.170670,11.317913,1.169972,-330.582428,0.117960,0.000000
79.310005,51.497620,-330.582428,0.000427,0.004632,0.117656,229.072845,11.669528,1.176557,-330.582428,0.118619,0.000000
79.710007,53.700203,-330.626923,0.000435,0.004659,0.118332,238.870438,12.168639,1.183325,-330.626923,0.119286,0.000000
80.110001,56.034607,-330.671387,0.000444,0.004692,0.119165,249.254379,12.697623,1.191651,-330.671387,0.119954,0.000000
80.510002,57.665230,-330.671387,0.000461,0.004716,0.119780,256.507751,13.067128,1.197798,-330.671387,0.120622,0.000000
80.910004,58.741753,-330.715881,0.000461,0.004735,0.120266,261.296356,13.311071,1.202658,-330.715881,0.121289,0.000000
81.310005,61.687218,-330.760345,0.000474,0.004769,0.121133,274.398437,13.978523,1.211333,-330.760345,0.121957,0.000000
81.710007,62.949562,-330.715881,0.000487,0.004786,0.121568,280.013641,14.264575,1.215678,-330.715881,0.122625,0.000000
82.110001,64.847168,-330.760345,0.000496,0.004814,0.122287,288.454620,14.694578,1.222869,-330.760345,0.123292,0.000000
82.510002,66.730637,-330.849304,0.000513,0.004828,0.122634,296.832703,15.121379,1.226336,-330.849304,0.122894,0.000000
82.910004,65.841034,-330.804840,0.000522,0.004827,0.122617,292.875549,14.919792,1.226170,-330.804840,294.500458,0.000000
83.310005,65.224762,-330.804840,0.000522,0.004828,0.122643,290.134216,14.780142,1.226427,-330.804840,294.500458,0.000000
83.710007,65.615753,-330.849304,0.000539,0.004839,0.122903,291.873444,14.868742,1.229031,-330.849304,294.500458,0.000000
84.110001,65.175232,-330.849304,0.000539,0.004839,0.122903,289.913910,14.768919,1.229031,-330.849304,294.500458,0.000000
84.510002,65.202042,-330.982758,0.000526,0.004844,0.123041,290.033173,14.774994,1.230409,-330.982758,294.500458,0.000000
84.910004,65.181564,-330.938263,0.000539,0.004848,0.123129,289.942078,14.770354,1.231287,-330.938263,294.500458,0.000000
85.310005,65.288437,-330.982758,0.000548,0.004851,0.123215,290.417480,14.794571,1.232150,-330.982758,294.500458,0.000000
85.710007,65.213211,-330.938263,0.000530,0.004853,0.123266,290.082855,14.777525,1.232665,-330.938263,294.500458,0.000000
86.110001,65.215454,-330.938263,0.000548,0.004855,0.123310,290.092834,14.778033,1.233104,-330.938263,294.500458,0.000000
86.510002,65.051239,-331.027252,0.000543,0.004856,0.123336,289.362366,14.740822,1.233361,-331.027252,294.500458,0.000000
86.910004,65.135025,-331.027252,0.000526,0.004858,0.123388,289.735077,14.759808,1.233876,-331.027252,294.500458,0.000000
87.310005,65.011765,-331.027252,0.000543,0.004858,0.123388,289.186768,14.731876,1.233876,-331.027252,294.500458,0.000000
87.710007,65.574417,-331.071716,0.000543,0.004865,0.123578,291.689575,14.859375,1.235783,-331.071716,294.500458,0.000000
88.110001,65.526749,-331.071716,0.000548,0.004865,0.123578,291.477539,14.848574,1.235783,-331.071716,294.500458,0.000000
88.510002,65.392700,-331.160675,0.000548,0.004865,0.123578,290.881256,14.818198,1.235783,-331.160675,294.500458,0.000000
88.910004,65.309662,-331.160675,0.000543,0.004866,0.123587,290.511871,14.799381,1.235874,-331.160675,294.500458,0.000000
89.310005,65.217316,-331.205170,0.000548,0.004866,0.123587,290.101105,14.778456,1.235874,-331.205170,294.500458,0.000000
89.710007,65.453018,-331.205170,0.000552,0.004871,0.123718,291.149567,14.831865,1.237176,-331.205170,294.500458,0.000000
90.110001,65.464935,-331.294128,0.000548,0.004871,0.123718,291.202576,14.834566,1.237176,-331.294128,294.500458,0.000000
90.510002,65.390091,-331.294128,0.000556,0.004871,0.123718,290.869659,14.817606,1.237176,-331.294128,294.500458,0.000000
90.910004,65.330139,-331.294128,0.000552,0.004871,0.123727,290.602966,14.804021,1.237267,-331.294128,294.500458,0.000000
91.310005,65.259766,-331.249634,0.000552,0.004871,0.123727,290.289948,14.788074,1.237267,-331.249634,294.500458,0.000000
91.710007,65.193115,-331.383087,0.000569,0.004871,0.123736,289.993469,14.772971,1.237358,-331.383087,294.500458,0.000000
92.110001,65.901733,-331.338593,0.000565,0.004879,0.123934,293.145538,14.933546,1.239341,-331.338593,294.500458,0.000000
92.510002,65.865616,-331.383087,0.000565,0.004879,0.123934,292.984894,14.925363,1.239341,-331.383087,294.500458,0.000000
92.910004,65.823914,-331.383087,0.000560,0.004879,0.123934,292.799377,14.915913,1.239341,-331.383087,294.500458,0.000000
93.310005,65.766190,-331.427551,0.000560,0.004879,0.123934,292.542633,14.902831,1.239341,-331.427551,294.500458,0.000000
93.710007,65.748688,-331.472046,0.000573,0.004879,0.123934,292.464783,14.898866,1.239341,-331.472046,294.500458,0.000000
94.110008,65.608307,-331.472046,0.000560,0.004879,0.123934,291.840332,14.867055,1.239341,-331.472046,294.500458,0.000000
94.510002,65.587448,-331.516541,0.000569,0.004879,0.123934,291.747528,14.862329,1.239341,-331.516541,294.500458,0.000000
94.910004,65.528610,-331.516541,0.000552,0.004879,0.123934,291.485809,14.848995,1.239341,-331.516541,294.500458,0.000000
95.310005,65.474243,-331.516541,0.000556,0.004879,0.123934,291.243988,14.836676,1.239341,-331.516541,294.500458,0.000000
95.710007,65.383759,-331.561005,0.000556,0.004879,0.123934,290.841492,14.816172,1.239341,-331.561005,294.500458,0.000000
96.110008,65.324188,-331.605499,0.000556,0.004879,0.123934,290.576508,14.802672,1.239341,-331.605499,294.500458,0.000000
96.510002,65.290665,-331.649963,0.000556,0.004880,0.123943,290.427368,14.795076,1.239432,-331.649963,294.500458,0.000000
96.910004,65.244873,-331.694458,0.000569,0.004880,0.123943,290.223694,14.784699,1.239432,-331.694458,294.500458,0.000000
97.310005,65.189377,-331.694458,0.000573,0.004880,0.123943,289.976837,14.772124,1.239432,-331.694458,294.500458,0.000000
97.710007,65.134277,-331.694458,0.000569,0.004880,0.123943,289.731750,14.759639,1.239432,-331.694458,294.500458,0.000000
98.110008,65.073578,-331.738922,0.000569,0.004880,0.123943,289.461731,14.745884,1.239432,-331.738922,294.500458,0.000000
98.510002,65.032242,-331.738922,0.000573,0.004880,0.123943,289.277863,14.736517,1.239432,-331.738922,294.500458,0.000000
98.910004,64.989426,-331.738922,0.000565,0.004880,0.123943,289.087402,14.726814,1.239432,-331.738922,294.500458,0.000000
99.310005,64.947708,-331.827881,0.000582,0.004880,0.123943,288.901825,14.717361,1.239432,-331.827881,294.500458,0.000000
99.710007,64.898193,-331.827881,0.000578,0.004880,0.123943,288.681580,14.706141,1.239432,-331.827881,294.500458,0.000000
100.110008,64.838242,-331.872375,0.000565,0.004880,0.123943,288.414917,14.692555,1.239432,-331.872375,294.500458,0.000000
100.510002,64.796524,-331.916870,0.000582,0.004880,0.123943,288.229340,14.683103,1.239432,-331.916870,294.500458,0.000000
100.910004,64.757065,-331.916870,0.000569,0.004880,0.123943,288.053802,14.674161,1.239432,-331.916870,294.500458,0.000000
101.310005,64.731735,-331.916870,0.000573,0.004880,0.123943,287.941132,14.668421,1.239432,-331.916870,294.500458,0.000000
101.710007,64.676254,-331.916870,0.000578,0.004880,0.123943,287.694336,14.655849,1.239432,-331.916870,294.500458,0.000000
102.110008,66.357147,-331.916870,0.000569,0.004887,0.124125,295.171326,15.036744,1.241249,-331.916870,294.500458,0.000000
102.510002,66.311340,-332.005829,0.000573,0.004887,0.124125,294.967560,15.026364,1.241249,-332.005829,294.500458,0.000000
102.910004,66.267395,-332.005829,0.000582,0.004887,0.124125,294.772095,15.016406,1.241249,-332.005829,294.500458,0.000000
103.310005,66.211914,-332.050293,0.000578,0.004887,0.124125,294.525299,15.003835,1.241249,-332.050293,294.500458,0.000000
103.710007,66.170212,-332.050293,0.000582,0.004887,0.124125,294.339813,14.994385,1.241249,-332.050293,294.500458,0.000000
104.110008,66.123291,-332.094788,0.000586,0.004887,0.124125,294.131104,14.983752,1.241249,-332.094788,294.500458,0.000000
104.510002,66.081589,-332.094788,0.000573,0.004887,0.124117,293.945587,14.974302,1.241173,-332.094788,294.500458,0.000000
104.910004,66.043610,-332.139252,0.000595,0.004887,0.124117,293.776642,14.965695,1.241173,-332.139252,294.500458,0.000000
105.310005,66.023499,-332.183746,0.000591,0.004887,0.124117,293.687195,14.961139,1.241173,-332.183746,294.500458,0.000000
105.710007,65.979187,-332.228210,0.000591,0.004887,0.124117,293.490082,14.951097,1.241173,-332.228210,294.500458,0.000000
106.110008,65.915512,-332.228210,0.000591,0.004887,0.124117,293.206848,14.936668,1.241173,-332.228210,294.500458,0.000000
106.510002,65.872681,-332.272705,0.000586,0.004887,0.124117,293.016327,14.926963,1.241173,-332.272705,294.500458,0.000000
106.910004,65.890564,-332.272705,0.000591,0.004887,0.124117,293.095856,14.931015,1.241173,-332.272705,294.500458,0.000000
107.310005,65.833588,-332.317200,0.000586,0.004887,0.124117,292.842438,14.918104,1.241173,-332.317200,294.500458,0.000000
107.710007,65.850723,-332.317200,0.000582,0.004887,0.124117,292.918640,14.921987,1.241173,-332.317200,294.500458,0.000000
108.110008,65.790390,-332.317200,0.000578,0.004887,0.124117,292.650269,14.908316,1.241173,-332.317200,294.500458,0.000000
108.510002,65.768417,-332.361664,0.000578,0.004887,0.124117,292.552521,14.903337,1.241173,-332.361664,294.500458,0.000000
108.910004,65.756134,-332.406158,0.000582,0.004887,0.124117,292.497894,14.900553,1.241173,-332.406158,294.500458,0.000000
109.310005,65.680176,-332.406158,0.000578,0.004887,0.124117,292.160004,14.883341,1.241173,-332.406158,294.500458,0.000000
109.710007,65.651123,-332.406158,0.000591,0.004887,0.124117,292.030792,14.876758,1.241173,-332.406158,294.500458,0.000000
110.110008,65.596756,-332.450623,0.000582,0.004887,0.124125,291.788940,14.864437,1.241249,-332.450623,294.500458,0.000000
110.510002,65.592285,-332.450623,0.000582,0.004887,0.124125,291.769043,14.863424,1.241249,-332.450623,294.500458,0.000000
110.910004,65.564362,-332.495117,0.000582,0.004887,0.124125,291.644836,14.857098,1.241249,-332.495117,294.500458,0.000000
111.310005,65.541641,-332.495117,0.000573,0.004887,0.124125,291.543793,14.851948,1.241249,-332.495117,294.500458,0.000000
111.710007,65.513351,-332.539581,0.000578,0.004887,0.124125,291.417938,14.845537,1.241249,-332.539581,294.500458,0.000000
112.110008,65.501053,-332.584076,0.000586,0.004887,0.124125,291.363220,14.842751,1.241249,-332.584076,294.500458,0.000000
112.510002,65.475739,-332.628540,0.000586,0.004887,0.124125,291.250641,14.837015,1.241249,-332.628540,294.500458,0.000000
112.910004,65.427338,-332.673035,0.000595,0.004887,0.124125,291.035339,14.826047,1.241249,-332.673035,294.500458,0.000000
113.310005,65.385620,-332.584076,0.000591,0.004889,0.124185,290.849762,14.816593,1.241854,-332.584076,294.500458,0.000000
113.710007,65.362167,-332.673035,0.000595,0.004891,0.124238,290.745453,14.811279,1.242384,-332.673035,294.500458,0.000000
114.110008,65.348755,-332.717499,0.000582,0.004892,0.124247,290.685791,14.808240,1.242475,-332.717499,294.500458,0.000000
114.510002,65.329391,-332.673035,0.000582,0.004892,0.124247,290.599640,14.803851,1.242475,-332.673035,294.500458,0.000000
114.910004,65.321579,-332.761993,0.000582,0.004892,0.124255,290.564880,14.802081,1.242551,-332.761993,294.500458,0.000000
115.310005,65.307800,-332.717499,0.000586,0.004892,0.124255,290.503601,14.798959,1.242551,-332.717499,294.500458,0.000000
115.710007,65.290298,-332.717499,0.000582,0.004892,0.124255,290.425751,14.794993,1.242551,-332.717499,294.500458,0.000000
116.110008,65.277634,-332.761993,0.000578,0.004892,0.124264,290.369415,14.792123,1.242642,-332.761993,294.500458,0.000000
116.510002,65.267212,-332.850952,0.000586,0.004892,0.124264,290.323059,14.789762,1.242642,-332.850952,294.500458,0.000000
116.910004,65.228485,-332.895447,0.000582,0.004893,0.124281,290.150787,14.780987,1.242808,-332.895447,294.500458,0.000000
117.310005,65.261627,-332.850952,0.000582,0.004894,0.124316,290.298218,14.788496,1.243156,-332.850952,294.500458,0.000000
117.710007,65.286942,-332.895447,0.000595,0.004895,0.124334,290.410828,14.794232,1.243338,-332.895447,294.500458,0.000000
118.110008,65.302216,-332.939911,0.000595,0.004895,0.124334,290.478760,14.797693,1.243338,-332.939911,294.500458,0.000000
118.510002,65.285461,-332.895447,0.000586,0.004895,0.124334,290.404236,14.793897,1.243338,-332.895447,294.500458,0.000000
118.910004,65.286575,-332.939911,0.000591,0.004895,0.124334,290.409180,14.794149,1.243338,-332.939911,294.500458,0.000000
119.310005,65.277267,-332.984406,0.000595,0.004895,0.124334,290.367798,14.792040,1.243338,-332.984406,294.500458,0.000000
119.710007,65.255661,-333.028870,0.000578,0.004895,0.124334,290.271667,14.787145,1.243338,-333.028870,294.500458,0.000000
120.110008,65.244873,-333.028870,0.000586,0.004895,0.124334,290.223694,14.784699,1.243338,-333.028870,294.500458,0.000000
120.510002,65.217316,-333.028870,0.000586,0.004895,0.124343,290.101105,14.778456,1.243429,-333.028870,294.500458,0.000000
120.910004,65.214706,-333.117828,0.000586,0.004895,0.124343,290.089508,14.777864,1.243429,-333.117828,294.500458,0.000000
121.310005,65.190872,-333.117828,0.000591,0.004895,0.124343,289.983490,14.772463,1.243429,-333.117828,294.500458,0.000000
121.710007,65.181198,-333.117828,0.000586,0.004895,0.124343,289.940460,14.770271,1.243429,-333.117828,294.500458,0.000000
122.110008,65.165176,-333.162323,0.000591,0.004895,0.124343,289.869171,14.766640,1.243429,-333.162323,294.500458,0.000000
122.510002,65.150284,-333.162323,0.000599,0.004895,0.124343,289.802948,14.763266,1.243429,-333.162323,294.500458,0.000000
122.910004,65.136505,-333.206818,0.000595,0.004895,0.124343,289.741638,14.760143,1.243429,-333.206818,294.500458,0.000000
123.310005,65.130554,-333.162323,0.000599,0.004895,0.124343,289.715179,14.758794,1.243429,-333.162323,294.500458,0.000000
123.710007,65.116776,-333.251282,0.000599,0.004895,0.124343,289.653870,14.755672,1.243429,-333.251282,294.500458,0.000000
124.110008,65.078049,-333.295776,0.000582,0.004895,0.124343,289.481628,14.746897,1.243429,-333.295776,294.500458,0.000000
124.510002,65.070221,-333.340240,0.000573,0.004895,0.124343,289.446808,14.745123,1.243429,-333.340240,294.500458,0.000000
124.910004,65.066879,-333.340240,0.000586,0.004895,0.124343,289.431946,14.744366,1.243429,-333.340240,294.500458,0.000000
125.310005,65.049744,-333.340240,0.000604,0.004895,0.124343,289.355713,14.740482,1.243429,-333.340240,294.500458,0.000000
125.710007,65.339828,-333.384735,0.000591,0.004901,0.124481,290.646088,14.806217,1.244807,-333.384735,294.500458,0.000000
126.110008,65.382278,-333.384735,0.000586,0.004901,0.124481,290.834900,14.815836,1.244807,-333.384735,294.500458,0.000000
126.510010,65.400146,-333.429199,0.000599,0.004901,0.124481,290.914368,14.819884,1.244807,-333.429199,294.500458,0.000000
126.910004,65.409454,-333.473694,0.000582,0.004901,0.124481,290.955780,14.821995,1.244807,-333.473694,294.500458,0.000000
127.310005,65.420624,-333.473694,0.000595,0.004901,0.124481,291.005463,14.824526,1.244807,-333.473694,294.500458,0.000000
127.710007,65.406113,-333.473694,0.000595,0.004901,0.124481,290.940918,14.821238,1.244807,-333.473694,294.500458,0.000000
128.110001,65.415039,-333.518158,0.000586,0.004901,0.124481,290.980621,14.823260,1.244807,-333.518158,294.500458,0.000000
128.510010,65.403503,-333.562653,0.000591,0.004901,0.124481,290.929321,14.820645,1.244807,-333.562653,294.500458,0.000000
128.910004,65.402008,-333.562653,0.000595,0.004901,0.124481,290.922668,14.820307,1.244807,-333.562653,294.500458,0.000000
129.310013,65.393448,-333.607147,0.000599,0.004901,0.124481,290.884583,14.818367,1.244807,-333.607147,294.500458,0.000000
129.710007,65.395309,-333.651611,0.000595,0.004901,0.124481,290.892853,14.818789,1.244807,-333.651611,294.500458,0.000000
130.110001,65.367386,-333.651611,0.000604,0.004901,0.124481,290.768646,14.812461,1.244807,-333.651611,294.500458,0.000000
130.510010,65.369247,-333.740570,0.000591,0.004901,0.124481,290.776947,14.812883,1.244807,-333.740570,294.500458,0.000000
130.910004,65.342804,-333.696106,0.000586,0.004901,0.124481,290.659302,14.806890,1.244807,-333.696106,294.500458,0.000000
131.310013,65.348389,-333.785065,0.000591,0.004901,0.124481,290.684143,14.808156,1.244807,-333.785065,294.500458,0.000000
131.710007,65.336105,-333.740570,0.000604,0.004901,0.124481,290.629517,14.805373,1.244807,-333.740570,294.500458,0.000000
132.110001,65.336472,-333.829529,0.000599,0.004901,0.124481,290.631134,14.805456,1.244807,-333.829529,294.500458,0.000000
132.510010,65.318222,-333.874023,0.000586,0.004901,0.124481,290.549957,14.801320,1.244807,-333.874023,294.500458,0.000000
132.910004,65.295135,-333.874023,0.000591,0.004901,0.124481,290.447266,14.796089,1.244807,-333.874023,294.500458,0.000000
133.310013,65.292526,-333.874023,0.000604,0.004901,0.124481,290.435669,14.795499,1.244807,-333.874023,294.500458,0.000000
133.710007,65.272049,-333.918488,0.000604,0.004901,0.124481,290.344574,14.790857,1.244807,-333.918488,294.500458,0.000000
134.110001,65.272797,-333.962982,0.000582,0.004901,0.124481,290.347900,14.791027,1.244807,-333.962982,294.500458,0.000000
134.510010,65.253067,-333.918488,0.000604,0.004901,0.124481,290.260132,14.786556,1.244807,-333.918488,294.500458,0.000000
134.910004,65.235565,-334.051941,0.000595,0.004901,0.124481,290.182281,14.782591,1.244807,-334.051941,294.500458,0.000000
135.310013,65.217682,-334.051941,0.000591,0.004901,0.124481,290.102753,14.778538,1.244807,-334.051941,294.500458,0.000000
135.710007,65.215073,-333.962982,0.000595,0.004901,0.124481,290.091125,14.777947,1.244807,-333.962982,294.500458,0.000000
136.110001,65.208740,-334.140900,0.000591,0.004901,0.124481,290.062958,14.776512,1.244807,-334.140900,294.500458,0.000000
136.510010,65.177094,-334.051941,0.000595,0.004901,0.124481,289.922180,14.769341,1.244807,-334.051941,294.500458,0.000000
136.910004,65.167419,-334.096436,0.000595,0.004901,0.124481,289.879150,14.767148,1.244807,-334.096436,294.500458,0.000000
137.310013,65.158478,-334.140900,0.000591,0.004901,0.124481,289.839386,14.765121,1.244807,-334.140900,294.500458,0.000000
137.710007,65.140228,-334.185394,0.000586,0.004901,0.124481,289.758209,14.760986,1.244807,-334.185394,294.500458,0.000000
138.110001,65.179337,-334.185394,0.000599,0.004902,0.124506,289.932159,14.769849,1.245064,-334.185394,294.500458,0.000000
138.510010,65.169281,-334.185394,0.000586,0.004903,0.124525,289.887451,14.767570,1.245246,-334.185394,294.500458,0.000000
138.910004,65.197571,-334.229858,0.000595,0.004903,0.124525,290.013275,14.773981,1.245246,-334.229858,294.500458,0.000000
139.310013,65.197952,-334.274353,0.000599,0.004903,0.124525,290.014984,14.774067,1.245246,-334.274353,294.500458,0.000000
139.710007,65.200562,-334.318817,0.000591,0.004903,0.124525,290.026581,14.774658,1.245246,-334.318817,294.500458,0.000000
140.110001,65.178955,-334.318817,0.000586,0.004903,0.124525,289.930481,14.769762,1.245246,-334.318817,294.500458,0.000000
140.510010,65.175613,-334.318817,0.000599,0.004903,0.124525,289.915619,14.769006,1.245246,-334.318817,294.500458,0.000000
140.910004,65.170761,-334.407776,0.000595,0.004903,0.124525,289.894012,14.767905,1.245246,-334.407776,294.500458,0.000000
141.310013,65.163696,-334.363312,0.000591,0.004903,0.124525,289.862610,14.766305,1.245246,-334.363312,294.500458,0.000000
141.710007,65.234070,-334.407776,0.000595,0.004905,0.124585,290.175629,14.782252,1.245851,-334.407776,294.500458,0.000000
142.110001,65.259018,-334.407776,0.000591,0.004905,0.124585,290.286621,14.787905,1.245851,-334.407776,294.500458,0.000000
142.510010,65.273163,-334.496765,0.000595,0.004905,0.124585,290.349518,14.791110,1.245851,-334.496765,294.500458,0.000000
142.910004,65.278015,-334.541229,0.000578,0.004905,0.124585,290.371124,14.792210,1.245851,-334.541229,1681.640747,0.000000
143.310013,65.241882,-334.541229,0.000591,0.004897,0.124376,290.210388,14.784021,1.243762,-334.541229,0.124403,0.000000
143.710007,65.177475,-334.585724,0.000612,0.004881,0.123987,289.923889,14.769426,1.239871,-334.585724,0.123736,0.000000
144.110001,65.151779,-334.585724,0.000617,0.004863,0.123518,289.809601,14.763604,1.235178,-334.585724,0.123067,0.000000
144.510010,65.121979,-334.585724,0.000621,0.004842,0.122998,289.677032,14.756851,1.229985,-334.585724,0.122399,0.000000
144.910004,65.089966,-334.585724,0.000604,0.004812,0.122226,289.534637,14.749597,1.222264,-334.585724,0.121731,0.000000
145.310013,65.107086,-334.674683,0.000608,0.004790,0.121671,289.610779,14.753476,1.216707,-334.674683,0.121064,0.000000
145.710007,65.063889,-334.630188,0.000612,0.004760,0.120899,289.418640,14.743688,1.208986,-334.630188,0.120405,0.000000
146.110001,65.066498,-334.674683,0.000612,0.004741,0.120422,289.430237,14.744279,1.204217,-334.674683,0.119737,0.000000
146.510010,64.991653,-334.719147,0.000595,0.004709,0.119598,289.097321,14.727320,1.195981,-334.719147,0.119070,0.000000
146.910004,64.940262,-334.719147,0.000599,0.004691,0.119156,288.868713,14.715673,1.191561,-334.719147,0.118402,0.000000
147.310013,64.876968,-334.763641,0.000608,0.004665,0.118488,288.587158,14.701331,1.184884,-334.763641,0.117734,0.000000
147.710007,64.348572,-334.763641,0.000604,0.004635,0.117725,286.236755,14.581594,1.177254,-334.763641,0.117067,0.000000
148.110001,63.606064,-334.852600,0.000621,0.004615,0.117223,282.933899,14.413340,1.172227,-334.852600,0.116398,0.000000
148.510010,62.109489,-334.852600,0.000617,0.004583,0.116407,276.276794,14.074211,1.164067,-334.852600,0.115730,0.000000
148.910004,60.692612,-334.852600,0.000617,0.004561,0.115853,269.974213,13.753142,1.158526,-334.852600,0.115071,0.000000
149.310013,59.183014,-334.852600,0.000617,0.004542,0.115376,263.259186,13.411063,1.153757,-334.852600,0.114404,0.000000
149.710007,56.975594,-334.852600,0.000625,0.004516,0.114707,253.440094,12.910854,1.147065,-334.852600,0.113736,0.000000
150.110001,54.781944,-334.897095,0.000629,0.004493,0.114118,243.682251,12.413766,1.141176,-334.897095,0.113068,0.000000
150.510010,52.092674,-334.941559,0.000621,0.004465,0.113415,231.719788,11.804368,1.134151,-334.941559,0.112401,0.000000
150.910004,49.180717,-334.986053,0.000621,0.004437,0.112704,218.766754,11.144510,1.127036,-334.986053,0.111733,0.000000
151.310013,46.582680,-335.030518,0.000621,0.004416,0.112157,207.210114,10.555786,1.121570,-335.030518,0.111065,0.000000
151.710007,43.386604,-335.075012,0.000625,0.004387,0.111429,192.993256,9.831545,1.114288,-335.075012,0.110398,0.000000
152.110001,40.809044,-335.030518,0.000617,0.004363,0.110831,181.527695,9.247461,1.108308,-335.030518,0.109738,0.000000
152.510010,37.949219,-334.986053,0.000625,0.004336,0.110145,168.806549,8.599416,1.101450,-334.986053,0.109070,0.000000
152.910004,35.133713,-335.119476,0.000621,0.004310,0.109477,156.282562,7.961413,1.094773,-335.119476,0.108402,0.000000
153.310013,31.997963,-335.075012,0.000621,0.004281,0.108740,142.334045,7.250842,1.087400,-335.075012,0.107735,0.000000
153.710007,29.359337,-335.119476,0.000612,0.004258,0.108160,130.596848,6.652921,1.081602,-335.119476,0.107067,0.000000
154.110001,26.331200,-335.208435,0.000612,0.004232,0.107500,117.127029,5.966735,1.075001,-335.208435,0.106399,0.000000
154.510010,23.029747,-335.163971,0.000629,0.004201,0.106695,102.441429,5.218615,1.066947,-335.163971,0.105732,0.000000
154.910004,20.804825,-335.163971,0.000621,0.004182,0.106234,92.544479,4.714441,1.062344,-335.163971,0.105064,0.000000
155.310013,18.097672,-335.252930,0.000617,0.004156,0.105558,80.502464,4.100991,1.055577,-335.252930,0.104404,0.000000
155.710007,14.052216,-335.297424,0.000612,0.004123,0.104725,62.507378,3.184278,1.047250,-335.297424,0.103736,0.000000
156.110001,11.824318,-335.252930,0.000612,0.004100,0.104145,52.597195,2.679429,1.041452,-335.252930,0.103069,0.000000
156.510010,8.920929,-335.297424,0.000604,0.004078,0.103571,39.682274,2.021511,1.035714,-335.297424,0.102401,0.000000
156.910004,6.288628,-335.341888,0.000595,0.004053,0.102957,27.973213,1.425023,1.029567,-335.341888,0.101733,0.000000
157.310013,3.022171,-335.386383,0.000608,0.004023,0.102185,13.443288,0.684834,1.021846,-335.386383,0.101066,0.000000
157.710007,0.866508,-335.475342,0.000612,0.004000,0.101612,3.854422,0.196354,1.016123,-335.475342,0.100398,0.000000
158.110001,-1.488747,-335.386383,0.000604,0.003972,0.100892,-6.622276,-0.337355,1.008917,-335.386383,0.099730,0.000000
158.510010,-0.109108,-335.475342,0.000526,0.003941,0.100103,-0.485336,-0.024724,1.001029,-335.475342,0.099063,0.000000
158.910004,-0.080063,-335.475342,0.000500,0.003917,0.099479,-0.356137,-0.018143,0.994792,-335.475342,0.098403,0.000000
159.310013,-0.128471,-335.475342,0.000453,0.003889,0.098786,-0.571469,-0.029112,0.987858,-335.475342,0.097735,0.000000
159.710007,0.011169,-335.519806,0.000392,0.003865,0.098179,0.049684,0.002531,0.981787,-335.519806,0.097067,0.000000
160.110001,0.003349,-335.519806,0.000332,0.003838,0.097493,0.014898,0.000759,0.974928,-335.519806,0.096400,0.000000
160.510010,0.053993,-335.608765,0.000259,0.003814,0.096877,0.240174,0.012235,0.968767,-335.608765,0.095732,0.000000
160.910004,0.004837,-335.564301,0.000194,0.003786,0.096174,0.021516,0.001096,0.961742,-335.564301,0.095064,0.000000
161.310013,0.049896,-335.564301,0.000095,0.003753,0.095325,0.221950,0.011307,0.953249,-335.564301,0.094397,0.000000
161.710007,0.060699,-335.653259,0.000047,0.003735,0.094874,0.270005,0.013755,0.948737,-335.653259,0.093729,0.000000
162.110001,0.026062,-335.653259,-0.000030,0.003707,0.094155,0.115930,0.005906,0.941546,-335.653259,0.093071,0.000000
162.510010,0.026810,-335.653259,-0.000116,0.003683,0.093538,0.119255,0.006075,0.935384,-335.653259,0.092403,0.000000
162.910004,-0.001488,-335.697723,-0.000203,0.003655,0.092845,-0.006618,-0.000337,0.928450,-335.697723,0.091734,0.000000
163.310013,-0.000374,-335.786713,-0.000297,0.003620,0.091943,-0.001663,-0.000085,0.919427,-335.786713,0.091066,0.000000
163.710007,-0.002235,-335.742218,-0.000341,0.003605,0.091561,-0.009944,-0.000507,0.915612,-335.742218,0.090398,0.000000
164.110001,-0.039101,-335.786713,-0.000414,0.003567,0.090598,-0.173928,-0.008860,0.905983,-335.786713,0.089731,0.000000
164.510010,-0.029793,-335.831177,-0.000479,0.003544,0.090009,-0.132525,-0.006751,0.900093,-335.831177,0.089063,0.000000
164.910004,-0.043198,-335.831177,-0.000543,0.003523,0.089479,-0.192153,-0.009789,0.894795,-335.831177,0.088395,0.000000
165.310013,-0.064796,-335.831177,-0.000586,0.003492,0.088700,-0.288229,-0.014683,0.886998,-335.831177,0.087737,0.000000
165.710007,-0.065163,-335.875671,-0.000642,0.003473,0.088223,-0.289858,-0.014766,0.882229,-335.875671,0.087069,0.000000
166.110001,-0.079315,-335.920135,-0.000681,0.003447,0.087563,-0.352812,-0.017973,0.875628,-335.920135,0.086402,0.000000
166.510010,-0.079315,-335.964630,-0.000742,0.003412,0.086670,-0.352812,-0.017973,0.866696,-335.964630,0.085734,0.000000
166.910004,-0.072983,-335.964630,-0.000767,0.003393,0.086184,-0.324644,-0.016538,0.861836,-335.964630,0.085065,0.000000
167.100006,-0.052132,-335.964630,-0.000802,0.003374,0.085699,-0.231893,-0.011813,0.856991,-335.964630,0.085629,0.000000