File: Data/compression 31/ManualNoHeating-10-31-reverse-1-1_11132024_181017.csv
Time (sec),S:Load (lbs),S:HL1 (DIM),S:LVDT (in),S:Position (in),Ch:Position (mm),Ch:Load (N),Ch:Stress (MPa),Ch:Strain (mm/mm),Ch:HL1 (DIM),Set Point (),Cycles ()
0.110000,-0.081924,-311.589050,-0.009843,-0.004678,-0.118809,-0.364418,-0.018564,-1.188094,-311.589050,-0.118628,0.000000
0.510000,-0.079689,-311.678009,-0.009848,-0.004614,-0.117188,-0.354474,-0.018058,-1.171879,-311.678009,-0.116702,0.000000
0.910000,-0.085274,-311.633545,-0.009714,-0.004376,-0.111161,-0.379317,-0.019323,-1.111609,-311.633545,-0.110024,0.000000
1.310000,-0.087135,-311.678009,-0.009425,-0.004113,-0.104483,-0.387597,-0.019745,-1.044828,-311.678009,-0.103364,0.000000
1.710000,-0.094208,-311.722504,-0.009158,-0.003849,-0.097762,-0.419057,-0.021348,-0.977623,-311.722504,-0.096704,0.000000
2.110000,-0.113945,-311.722504,-0.008873,-0.003585,-0.091068,-0.506853,-0.025820,-0.910676,-311.722504,-0.090044,0.000000
2.510000,-0.055481,-311.722504,-0.008619,-0.003331,-0.084606,-0.246792,-0.012572,-0.846060,-311.722504,-0.083366,0.000000
2.910000,-0.049896,-311.722504,-0.008334,-0.003064,-0.077825,-0.221950,-0.011307,-0.778250,-311.722504,-0.076706,0.000000
3.310000,-0.055855,-311.811462,-0.008080,-0.002805,-0.071242,-0.248455,-0.012657,-0.712423,-311.811462,-0.070045,0.000000
3.710000,-0.076340,-311.855957,-0.007817,-0.002542,-0.064573,-0.339576,-0.017299,-0.645733,-311.855957,-0.063385,0.000000
4.110000,-0.100166,-311.855957,-0.007541,-0.002275,-0.057792,-0.445562,-0.022698,-0.577923,-311.855957,-0.056725,0.000000
4.510000,-0.055481,-311.855957,-0.007252,-0.002014,-0.051157,-0.246792,-0.012572,-0.511566,-311.855957,-0.050047,0.000000
4.910000,-0.046921,-311.855957,-0.006985,-0.001750,-0.044454,-0.208714,-0.010632,-0.444543,-311.855957,-0.043387,0.000000
5.310000,-0.066658,-311.900421,-0.006709,-0.001486,-0.037732,-0.296510,-0.015105,-0.377324,-311.900421,-0.036727,0.000000
5.710000,-0.092720,-311.900421,-0.006433,-0.001227,-0.031159,-0.412439,-0.021011,-0.311588,-311.900421,-0.030066,0.000000
6.110000,-0.155655,-311.944916,-0.006174,-0.000963,-0.024464,-0.692388,-0.035272,-0.244640,-311.944916,-0.023406,0.000000
6.510000,-0.143738,-312.033875,-0.005907,-0.000706,-0.017934,-0.639378,-0.032571,-0.179343,-312.033875,-0.016728,0.000000
6.910000,-0.077454,-312.033875,-0.005622,-0.000444,-0.011265,-0.344531,-0.017551,-0.112654,-312.033875,-0.010068,0.000000
7.310000,-0.075218,-312.033875,-0.005359,-0.000180,-0.004578,-0.334587,-0.017045,-0.045782,-312.033875,-0.003408,0.000000
7.710001,-0.008194,-312.033875,-0.005075,0.000084,0.002142,-0.036449,-0.001857,0.021423,-312.033875,0.003252,0.000000
8.110001,0.147835,-312.122833,-0.005019,-0.000000,-0.000009,0.657602,0.033500,-0.000091,-312.122833,0.000130,0.000000
8.510000,0.162354,-312.122833,-0.005010,-0.000000,-0.000009,0.722184,0.036790,-0.000091,-312.122833,0.000339,0.000000
8.910001,0.124741,-312.167328,-0.004988,-0.000000,-0.000000,0.554874,0.028267,-0.000000,-312.167328,0.001007,0.000000
9.310000,0.232735,-312.167328,-0.005006,0.000030,0.000755,1.035256,0.052738,0.007555,-312.167328,0.001674,0.000000
9.710000,0.355240,-312.211792,-0.004958,0.000058,0.001484,1.580186,0.080499,0.014837,-312.211792,0.002342,0.000000
10.110001,0.480362,-312.211792,-0.004941,0.000084,0.002126,2.136757,0.108852,0.021256,-312.211792,0.003010,0.000000
10.510000,0.587975,-312.211792,-0.004907,0.000102,0.002593,2.615441,0.133237,0.025934,-312.211792,0.003677,0.000000
10.910001,0.790916,-312.300751,-0.004876,0.000140,0.003564,3.518172,0.179224,0.035639,-312.300751,0.004345,0.000000
11.310000,0.838951,-312.256287,-0.004842,0.000161,0.004085,3.731841,0.190109,0.040847,-312.256287,0.005004,0.000000
11.710001,0.990135,-312.345245,-0.004829,0.000186,0.004717,4.404341,0.224368,0.047175,-312.345245,0.005671,0.000000
12.110001,1.217285,-312.345245,-0.004794,0.000211,0.005368,5.414755,0.275841,0.053685,-312.345245,0.006339,0.000000
12.510000,1.316711,-312.300751,-0.004777,0.000233,0.005915,5.857025,0.298371,0.059150,-312.300751,0.007008,0.000000
12.910001,1.544601,-312.389709,-0.004725,0.000270,0.006869,6.870730,0.350012,0.068688,-312.389709,0.007676,0.000000
13.310000,1.635460,-312.478668,-0.004687,0.000293,0.007441,7.274889,0.370601,0.074411,-312.478668,0.008343,0.000000
13.710001,1.854790,-312.478668,-0.004674,0.000323,0.008195,8.250517,0.420301,0.081951,-312.478668,0.009011,0.000000
14.110001,1.935219,-312.434204,-0.004635,0.000340,0.008630,8.608283,0.438527,0.086296,-312.434204,0.009679,0.000000
14.510000,2.043579,-312.478668,-0.004613,0.000363,0.009218,9.090294,0.463082,0.092185,-312.478668,0.010346,0.000000
14.910001,2.316902,-312.478668,-0.004570,0.000402,0.010216,10.306095,0.525017,0.102162,-312.478668,0.011005,0.000000
15.310000,2.376854,-312.523163,-0.004562,0.000426,0.010832,10.572774,0.538603,0.108324,-312.523163,0.011673,0.000000
15.710001,2.553726,-312.523163,-0.004514,0.000453,0.011517,11.359542,0.578683,0.115167,-312.523163,0.012340,0.000000
16.110001,2.605492,-312.567657,-0.004480,0.000469,0.011916,11.589806,0.590413,0.119164,-312.567657,0.013008,0.000000
16.510000,2.648682,-312.612122,-0.004471,0.000492,0.012496,11.781924,0.600200,0.124962,-312.612122,0.013677,0.000000
16.910002,2.836731,-312.612122,-0.004415,0.000531,0.013486,12.618409,0.642812,0.134863,-312.612122,0.014345,0.000000
17.310001,2.911949,-312.656616,-0.004372,0.000555,0.014101,12.952997,0.659857,0.141010,-312.656616,0.015012,0.000000
17.710001,3.102982,-312.656616,-0.004346,0.000584,0.014829,13.802752,0.703146,0.148292,-312.656616,0.015680,0.000000
18.110001,3.113777,-312.790039,-0.004312,0.000605,0.015368,13.850773,0.705592,0.153682,-312.790039,0.016339,0.000000
18.510000,3.277252,-312.701080,-0.004281,0.000634,0.016104,14.577946,0.742636,0.161040,-312.701080,0.017006,0.000000
18.910002,3.253044,-312.745575,-0.004260,0.000660,0.016764,14.470263,0.737150,0.167641,-312.745575,0.017674,0.000000
19.310001,3.232941,-312.790039,-0.004212,0.000682,0.017327,14.380838,0.732595,0.173272,-312.790039,0.018342,0.000000
19.710001,3.366989,-312.834534,-0.004178,0.000714,0.018125,14.977116,0.762971,0.181251,-312.834534,0.019009,0.000000
20.110001,3.398643,-312.834534,-0.004143,0.000734,0.018655,15.117921,0.770144,0.186550,-312.834534,0.019677,0.000000
20.510000,3.483543,-312.878998,-0.004122,0.000761,0.019339,15.495575,0.789382,0.193393,-312.878998,0.020346,0.000000
20.910002,3.332733,-312.878998,-0.004092,0.000783,0.019895,14.824738,0.755208,0.198949,-312.878998,0.021014,0.000000
21.310001,3.466415,-312.878998,-0.004044,0.000812,0.020623,15.419386,0.785501,0.206231,-312.878998,0.021672,0.000000
21.710001,3.553551,-312.967957,-0.003997,0.000841,0.021360,15.806983,0.805246,0.213604,-312.967957,0.022340,0.000000
22.110001,3.575523,-312.923492,-0.003984,0.000862,0.021889,15.904722,0.810225,0.218888,-312.923492,0.023008,0.000000
22.510000,3.748299,-312.967957,-0.003919,0.000898,0.022808,16.673265,0.849377,0.228078,-312.967957,0.023675,0.000000
22.910002,3.668610,-313.012451,-0.003880,0.000923,0.023450,16.318790,0.831319,0.234497,-313.012451,0.024343,0.000000
23.310001,3.706596,-313.056946,-0.003854,0.000948,0.024092,16.487764,0.839927,0.240916,-313.056946,0.025011,0.000000
23.710001,3.815331,-313.056946,-0.003816,0.000977,0.024803,16.971437,0.864566,0.248032,-313.056946,0.025678,0.000000
24.110001,3.756119,-313.056946,-0.003798,0.000991,0.025176,16.708052,0.851149,0.251756,-313.056946,0.026346,0.000000
24.510000,3.977310,-313.145905,-0.003734,0.001029,0.026148,17.691959,0.901271,0.261476,-313.145905,0.027006,0.000000
24.910002,3.887566,-313.145905,-0.003725,0.001052,0.026711,17.292755,0.880935,0.267108,-313.145905,0.027674,0.000000
25.310001,3.941559,-313.190369,-0.003704,0.001076,0.027335,17.532928,0.893170,0.273345,-313.190369,0.028341,0.000000
25.710001,4.032791,-313.190369,-0.003648,0.001105,0.028064,17.938751,0.913844,0.280642,-313.190369,0.029009,0.000000
26.110001,3.917358,-313.234863,-0.003626,0.001120,0.028446,17.425280,0.887686,0.284458,-313.234863,0.029677,0.000000
26.510002,4.186211,-313.234863,-0.003570,0.001160,0.029469,18.621195,0.948609,0.294692,-313.234863,0.030344,0.000000
26.910002,4.170944,-313.279327,-0.003544,0.001185,0.030093,18.553286,0.945149,0.300929,-313.279327,0.031012,0.000000
27.310001,4.236107,-313.279327,-0.003505,0.001211,0.030770,18.843145,0.959916,0.307697,-313.279327,0.031680,0.000000
27.710001,4.169823,-313.279327,-0.003484,0.001232,0.031290,18.548298,0.944895,0.312905,-313.279327,0.032347,0.000000
28.110001,4.127747,-313.368286,-0.003449,0.001249,0.031714,18.361134,0.935361,0.317144,-313.368286,0.033007,0.000000
28.510002,4.440910,-313.412781,-0.003393,0.001292,0.032824,19.754156,1.006325,0.328241,-313.412781,0.033675,0.000000
28.910002,4.370537,-313.368286,-0.003359,0.001314,0.033371,19.441118,0.990378,0.333707,-313.368286,0.034343,0.000000
29.310001,4.473679,-313.457275,-0.003320,0.001343,0.034117,19.899916,1.013750,0.341170,-313.457275,0.035010,0.000000
29.710001,4.495651,-313.501740,-0.003294,0.001367,0.034733,19.997656,1.018729,0.347332,-313.501740,0.035678,0.000000
30.110001,4.658379,-313.501740,-0.003251,0.001397,0.035487,20.721502,1.055604,0.354872,-313.501740,0.036346,0.000000
30.510002,4.607361,-313.546234,-0.003203,0.001425,0.036190,20.494564,1.044043,0.361897,-313.546234,0.037013,0.000000
30.910002,4.649811,-313.501740,-0.003186,0.001449,0.036806,20.683392,1.053662,0.368058,-313.501740,0.037681,0.000000
31.310001,4.685936,-313.501740,-0.003134,0.001476,0.037481,20.844084,1.061848,0.374811,-313.501740,0.038341,0.000000
31.710001,4.706039,-313.590698,-0.003113,0.001498,0.038055,20.933510,1.066404,0.380548,-313.590698,0.039009,0.000000
32.110001,4.909729,-313.679657,-0.003057,0.001531,0.038886,21.839565,1.112561,0.388860,-313.679657,0.039676,0.000000
32.510002,4.758171,-313.635193,-0.003040,0.001552,0.039433,21.165401,1.078217,0.394325,-313.635193,0.040344,0.000000
32.910000,4.786102,-313.724152,-0.003009,0.001579,0.040100,21.289646,1.084546,0.401002,-313.724152,0.041012,0.000000
33.310001,4.911964,-313.768616,-0.002975,0.001606,0.040803,21.849508,1.113067,0.408027,-313.768616,0.041679,0.000000
33.710003,4.878822,-313.679657,-0.002949,0.001627,0.041314,21.702085,1.105557,0.413144,-313.679657,0.042347,0.000000
34.110001,5.061661,-313.724152,-0.002893,0.001662,0.042217,22.515392,1.146989,0.422167,-313.724152,0.043015,0.000000
34.510002,4.946594,-313.724152,-0.002863,0.001685,0.042798,22.003550,1.120914,0.427981,-313.724152,0.043673,0.000000
34.910000,4.991653,-313.768616,-0.002833,0.001711,0.043466,22.203983,1.131125,0.434657,-313.768616,0.044341,0.000000
35.310001,5.011391,-313.768616,-0.002781,0.001736,0.044099,22.291779,1.135597,0.440986,-313.768616,0.045010,0.000000
35.710003,4.960747,-313.857605,-0.002755,0.001755,0.044585,22.066504,1.124121,0.445845,-313.857605,0.045678,0.000000
36.110001,5.205765,-313.857605,-0.002716,0.001793,0.045547,23.156399,1.179643,0.455474,-313.857605,0.046345,0.000000
36.510002,5.088844,-313.902069,-0.002673,0.001816,0.046136,22.636311,1.153149,0.461364,-313.902069,0.047013,0.000000
36.910000,5.102989,-313.902069,-0.002647,0.001839,0.046709,22.699230,1.156354,0.467086,-313.902069,0.047681,0.000000
37.310001,5.196083,-313.946564,-0.002600,0.001867,0.047429,23.113333,1.177449,0.474293,-313.946564,0.048348,0.000000
37.710003,5.091820,-313.902069,-0.002570,0.001883,0.047818,22.649546,1.153823,0.478184,-313.902069,0.049007,0.000000
38.110001,5.395302,-313.991028,-0.002531,0.001926,0.048911,23.999500,1.222593,0.489114,-313.991028,0.049674,0.000000
38.510002,5.168900,-314.035522,-0.002509,0.001944,0.049381,22.992413,1.171289,0.493808,-314.035522,0.050342,0.000000
38.910004,5.318970,-314.079987,-0.002466,0.001976,0.050179,23.659960,1.205296,0.501786,-314.079987,0.051010,0.000000
39.310001,5.280617,-314.035522,-0.002436,0.001995,0.050663,23.489357,1.196605,0.506631,-314.035522,0.051679,0.000000
39.710003,5.237793,-314.124481,-0.002423,0.002013,0.051123,23.298866,1.186901,0.511233,-314.124481,0.052347,0.000000
40.110001,5.464195,-314.079987,-0.002363,0.002048,0.052017,24.305954,1.238204,0.520166,-314.079987,0.053014,0.000000
40.510002,5.447067,-314.168945,-0.002328,0.002075,0.052701,24.229765,1.234323,0.527009,-314.168945,0.053682,0.000000
40.910004,5.553558,-314.168945,-0.002281,0.002106,0.053499,24.703461,1.258454,0.534987,-314.168945,0.054350,0.000000
41.310001,5.496216,-314.213440,-0.002246,0.002128,0.054054,24.448389,1.245460,0.540544,-314.213440,0.055008,0.000000
41.710003,5.350250,-314.213440,-0.002225,0.002145,0.054487,23.799101,1.212384,0.544873,-314.213440,0.055676,0.000000
42.110001,5.644051,-314.213440,-0.002177,0.002182,0.055415,25.105991,1.278960,0.554154,-314.213440,0.056343,0.000000
42.510002,5.554680,-314.257904,-0.002156,0.002207,0.056050,24.708450,1.258708,0.560498,-314.257904,0.057011,0.000000
42.910004,5.575531,-314.346893,-0.002104,0.002233,0.056717,24.801201,1.263433,0.567174,-314.346893,0.057679,0.000000
43.310001,5.515953,-314.302399,-0.002074,0.002253,0.057229,24.536184,1.249933,0.572291,-314.302399,0.058346,0.000000
43.710003,5.845871,-314.302399,-0.002022,0.002290,0.058174,26.003733,1.324693,0.581738,-314.302399,0.059016,0.000000
44.110001,5.622078,-314.435852,-0.002005,0.002313,0.058763,25.008251,1.273981,0.587628,-314.435852,0.059683,0.000000
44.510002,5.558777,-314.346893,-0.001953,0.002335,0.059302,24.726675,1.259637,0.593017,-314.346893,0.060342,0.000000
44.910004,5.715172,-314.480316,-0.001910,0.002365,0.060081,25.422354,1.295076,0.600814,-314.480316,0.061009,0.000000
45.310001,5.662666,-314.391357,-0.001901,0.002387,0.060637,25.188797,1.283178,0.606370,-314.391357,0.061677,0.000000
45.710003,5.984772,-314.480316,-0.001841,0.002422,0.061512,26.621593,1.356169,0.615121,-314.480316,0.062345,0.000000
46.110001,5.817200,-314.480316,-0.001807,0.002446,0.062137,25.876196,1.318196,0.621374,-314.480316,0.063012,0.000000
46.510002,5.681656,-314.524811,-0.001798,0.002467,0.062657,25.273268,1.287482,0.626567,-314.524811,0.063680,0.000000
46.910004,5.913277,-314.524811,-0.001729,0.002499,0.063473,26.303568,1.339968,0.634727,-314.524811,0.064348,0.000000
47.310001,5.751289,-314.569275,-0.001720,0.002515,0.063871,25.583014,1.303261,0.638709,-314.569275,0.065015,0.000000
47.710003,6.012321,-314.613770,-0.001681,0.002546,0.064678,26.744143,1.362411,0.646778,-314.613770,0.065675,0.000000
48.110001,5.963173,-314.613770,-0.001638,0.002575,0.065415,26.525518,1.351274,0.654151,-314.613770,0.066343,0.000000
48.510002,6.059990,-314.658234,-0.001600,0.002602,0.066101,26.956181,1.373213,0.661009,-314.658234,0.067011,0.000000
48.910004,6.135956,-314.702728,-0.001578,0.002630,0.066802,27.294094,1.390427,0.668019,-314.702728,0.067678,0.000000
49.310001,5.927055,-314.658234,-0.001526,0.002644,0.067150,26.364859,1.343090,0.671501,-314.658234,0.068346,0.000000
49.710003,6.412628,-314.747223,-0.001509,0.002684,0.068164,28.524796,1.453122,0.681644,-314.747223,0.069014,0.000000
50.110001,6.172447,-314.747223,-0.001457,0.002706,0.068728,27.456417,1.398697,0.687276,-314.747223,0.069681,0.000000
50.510002,6.325119,-314.791687,-0.001436,0.002733,0.069430,28.135534,1.433293,0.694301,-314.791687,0.070349,0.000000
50.910004,6.309105,-314.791687,-0.001388,0.002757,0.070028,28.064301,1.429664,0.700281,-314.791687,0.071009,0.000000
51.310001,6.171326,-314.880646,-0.001367,0.002774,0.070463,27.451427,1.398442,0.704626,-314.880646,0.071677,0.000000
51.710003,6.669563,-314.836182,-0.001337,0.002814,0.071477,29.667700,1.511345,0.714770,-314.836182,0.072344,0.000000
52.110001,6.615570,-314.880646,-0.001298,0.002840,0.072128,29.427525,1.499110,0.721280,-314.880646,0.073012,0.000000
52.510002,6.761169,-314.969604,-0.001263,0.002866,0.072803,30.075184,1.532103,0.728032,-314.969604,0.073680,0.000000
52.910004,6.624878,-314.969604,-0.001233,0.002884,0.073254,29.468929,1.501219,0.732544,-314.969604,0.074347,0.000000
53.310001,6.913467,-314.925140,-0.001194,0.002914,0.074017,30.752640,1.566614,0.740174,-314.925140,0.075015,0.000000
53.710003,7.050499,-314.969604,-0.001160,0.002947,0.074850,31.362186,1.597666,0.748501,-314.969604,0.075683,0.000000
54.110004,7.114174,-315.058563,-0.001147,0.002972,0.075483,31.645426,1.612095,0.754829,-315.058563,0.076350,0.000000
54.510002,7.295151,-315.058563,-0.001095,0.002997,0.076117,32.450451,1.653105,0.761173,-315.058563,0.077010,0.000000
54.910004,7.190514,-315.103058,-0.001078,0.003019,0.076671,31.985003,1.629394,0.766714,-315.103058,0.077678,0.000000
55.310001,7.775879,-315.058563,-0.001035,0.003052,0.077522,34.588837,1.762039,0.775222,-315.058563,0.078346,0.000000
55.710003,7.558418,-315.147552,-0.000996,0.003074,0.078067,33.621525,1.712762,0.780672,-315.147552,0.079013,0.000000
56.110004,7.794502,-315.147552,-0.000970,0.003104,0.078848,34.671677,1.766259,0.788484,-315.147552,0.079681,0.000000
56.510002,7.948288,-315.192017,-0.000944,0.003130,0.079499,35.355751,1.801108,0.794994,-315.192017,0.080349,0.000000
56.910004,8.073776,-315.192017,-0.000905,0.003151,0.080028,35.913952,1.829544,0.800278,-315.192017,0.081016,0.000000
57.310001,8.564941,-315.236511,-0.000871,0.003184,0.080870,38.098763,1.940843,0.808696,-315.236511,0.081684,0.000000
57.710003,8.186234,-315.280975,-0.000841,0.003206,0.081442,36.414185,1.855027,0.814419,-315.280975,0.082343,0.000000
58.110004,8.325500,-315.280975,-0.000832,0.003226,0.081944,37.033676,1.886585,0.819445,-315.280975,0.083012,0.000000
58.510002,8.958908,-315.280975,-0.000802,0.003260,0.082794,39.851215,2.030118,0.827938,-315.280975,0.083679,0.000000
58.910004,8.876984,-315.414429,-0.000750,0.003278,0.083254,39.486794,2.011553,0.832541,-315.414429,0.084347,0.000000
59.310001,9.663437,-315.369934,-0.000720,0.003316,0.084234,42.985115,2.189766,0.842336,-315.369934,0.085015,0.000000
59.710003,9.374107,-315.369934,-0.000686,0.003338,0.084780,41.698112,2.124203,0.847801,-315.369934,0.085682,0.000000
60.110004,9.452675,-315.369934,-0.000651,0.003360,0.085352,42.047596,2.142007,0.853524,-315.369934,0.086350,0.000000
60.510002,9.863029,-315.547852,-0.000634,0.003387,0.086020,43.872948,2.234994,0.860201,-315.547852,0.087018,0.000000
60.910004,9.902870,-315.458893,-0.000621,0.003406,0.086523,44.050167,2.244022,0.865227,-315.458893,0.087676,0.000000
61.310001,10.775345,-315.503387,-0.000573,0.003442,0.087425,47.931129,2.441728,0.874250,-315.503387,0.088344,0.000000
61.710003,10.685600,-315.503387,-0.000552,0.003466,0.088041,47.531925,2.421392,0.880412,-315.503387,0.089012,0.000000
62.110004,11.294060,-315.503387,-0.000517,0.003497,0.088821,50.238487,2.559270,0.888209,-315.503387,0.089679,0.000000
62.510002,11.063927,-315.636841,-0.000496,0.003515,0.089281,49.214806,2.507122,0.892811,-315.636841,0.090348,0.000000
62.910004,11.225914,-315.592346,-0.000461,0.003536,0.089809,49.935360,2.543828,0.898095,-315.592346,0.091016,0.000000
63.310001,11.987038,-315.681305,-0.000435,0.003567,0.090607,53.321007,2.716301,0.906074,-315.681305,0.091684,0.000000
63.710003,12.685616,-315.681305,-0.000410,0.003599,0.091423,56.428436,2.874602,0.914234,-315.681305,0.092351,0.000000
64.110001,12.986862,-315.725800,-0.000384,0.003625,0.092082,57.768448,2.942865,0.920820,-315.725800,0.093010,0.000000
64.510002,13.177513,-315.725800,-0.000379,0.003649,0.092689,58.616505,2.986067,0.926890,-315.725800,0.093678,0.000000
64.910004,13.301888,-315.770264,-0.000332,0.003670,0.093226,59.169750,3.014251,0.932265,-315.770264,0.094345,0.000000
65.310005,14.354958,-315.770264,-0.000297,0.003706,0.094129,63.854042,3.252880,0.941288,-315.770264,0.095013,0.000000
65.710007,14.451775,-315.814758,-0.000289,0.003730,0.094753,64.284706,3.274819,0.947526,-315.814758,0.095681,0.000000
66.110001,15.281418,-315.814758,-0.000250,0.003760,0.095499,67.975143,3.462819,0.954990,-315.814758,0.096348,0.000000
66.510002,15.390526,-315.859222,-0.000220,0.003779,0.095985,68.460480,3.487543,0.959849,-315.859222,0.097017,0.000000
66.910004,15.430000,-315.859222,-0.000216,0.003796,0.096427,68.636070,3.496488,0.964270,-315.859222,0.097685,0.000000
67.310005,16.771286,-315.992676,-0.000172,0.003837,0.097460,74.602409,3.800428,0.974595,-315.992676,0.098353,0.000000
67.710007,17.113869,-315.859222,-0.000142,0.003857,0.097971,76.126289,3.878058,0.979712,-315.859222,0.099011,0.000000
68.110001,18.100655,-315.948181,-0.000129,0.003889,0.098777,80.515732,4.101667,0.987767,-315.948181,0.099679,0.000000
68.510002,18.455521,-316.037170,-0.000116,0.003913,0.099393,82.094254,4.182081,0.993929,-316.037170,0.100347,0.000000
68.910004,19.670944,-316.037170,-0.000073,0.003942,0.100130,87.500732,4.457500,1.001302,-316.037170,0.101014,0.000000
69.310005,20.373985,-316.081635,-0.000060,0.003967,0.100772,90.628014,4.616811,1.007721,-316.081635,0.101682,0.000000
69.710007,21.001434,-316.081635,-0.000039,0.003995,0.101475,93.419044,4.758993,1.014745,-316.081635,0.102350,0.000000
70.110001,21.563713,-316.081635,-0.000017,0.004020,0.102116,95.920189,4.886407,1.021165,-316.081635,0.103017,0.000000
70.510002,22.128975,-316.170593,0.000009,0.004041,0.102636,98.434593,5.014497,1.026358,-316.170593,0.103686,0.000000
70.910004,23.422600,-316.126129,0.000013,0.004071,0.103400,104.188927,5.307637,1.034003,-316.126129,0.104345,0.000000
71.310005,24.280174,-316.215088,0.000043,0.004096,0.104050,108.003609,5.501966,1.040498,-316.215088,0.105013,0.000000
71.710007,24.997734,-316.215088,0.000052,0.004120,0.104657,111.195473,5.664567,1.046569,-316.215088,0.105680,0.000000
72.110001,26.124908,-316.304047,0.000086,0.004148,0.105359,116.209396,5.919989,1.053594,-316.304047,0.106348,0.000000
72.510002,26.724426,-316.304047,0.000091,0.004169,0.105880,118.876183,6.055842,1.058802,-316.304047,0.107016,0.000000
72.910004,28.643265,-316.304047,0.000116,0.004205,0.106799,127.411606,6.490656,1.067991,-316.304047,0.107683,0.000000
73.310005,29.238312,-316.348511,0.000147,0.004228,0.107380,130.058502,6.625496,1.073805,-316.348511,0.108351,0.000000
73.710007,30.304039,-316.393005,0.000164,0.004254,0.108057,134.799103,6.866993,1.080572,-316.393005,0.109019,0.000000
74.110001,31.684425,-316.304047,0.000177,0.004281,0.108725,140.939362,7.179793,1.087249,-316.304047,0.109679,0.000000
74.510002,32.175957,-316.393005,0.000185,0.004298,0.109167,143.125809,7.291176,1.091670,-316.393005,0.110346,0.000000
74.910004,34.610161,-316.437500,0.000211,0.004338,0.110190,153.953690,7.842775,1.101904,-316.437500,0.111014,0.000000
75.310005,35.324738,-316.526459,0.000224,0.004359,0.110728,157.132278,8.004700,1.107279,-316.526459,0.111682,0.000000
75.710007,36.560646,-316.437500,0.000233,0.004387,0.111439,162.629883,8.284760,1.114394,-316.437500,0.112349,0.000000
76.110001,37.889641,-316.526459,0.000246,0.004409,0.111977,168.541534,8.585915,1.119769,-316.526459,0.113017,0.000000
76.510002,38.582253,-316.526459,0.000276,0.004428,0.112470,171.622437,8.742864,1.124704,-316.526459,0.113685,0.000000
76.910004,41.376167,-316.526459,0.000289,0.004470,0.113529,184.050385,9.375974,1.135287,-316.526459,0.114352,0.000000
77.310005,42.548393,-316.570923,0.000285,0.004494,0.114145,189.264709,9.641603,1.141449,-316.570923,0.115012,0.000000
77.710007,43.950005,-316.659882,0.000323,0.004518,0.114752,195.499390,9.959213,1.147520,-316.659882,0.115680,0.000000
78.110001,45.034355,-316.570923,0.000323,0.004536,0.115220,200.322815,10.204931,1.152198,-316.570923,0.116348,0.000000
78.510002,46.128754,-316.748840,0.000336,0.004559,0.115810,205.190948,10.452925,1.158102,-316.748840,0.117015,0.000000
78.910004,49.325203,-316.659882,0.000358,0.004598,0.116781,219.409454,11.177251,1.167807,-316.659882,0.117683,0.000000
79.310005,50.712662,-316.704376,0.000349,0.004623,0.117413,225.581192,11.491653,1.174135,-316.704376,0.118351,0.000000
79.710007,52.293007,-316.704376,0.000366,0.004647,0.118039,232.610916,11.849765,1.180388,-316.704376,0.119018,0.000000
80.110001,54.224503,-316.748840,0.000388,0.004673,0.118697,241.202637,12.287448,1.186973,-316.748840,0.119686,0.000000
80.510002,54.449417,-316.793335,0.000397,0.004686,0.119018,242.203110,12.338414,1.190183,-316.793335,0.120345,0.000000
80.910004,58.198837,-316.748840,0.000414,0.004727,0.120067,258.881348,13.188046,1.200675,-316.748840,0.121012,0.000000
81.310005,59.551292,-316.837830,0.000427,0.004750,0.120649,264.897369,13.494515,1.206488,-316.837830,0.121681,0.000000
81.710007,62.173538,-316.926788,0.000435,0.004781,0.121429,276.561707,14.088725,1.214285,-316.926788,0.122349,0.000000
82.110001,63.476837,-316.926788,0.000453,0.004800,0.121933,282.359070,14.384056,1.219327,-316.926788,0.123017,0.000000
82.510002,64.028320,-316.882294,0.000453,0.004817,0.122357,284.812195,14.509025,1.223566,-316.882294,0.123684,0.000000
82.910004,65.539780,-316.971252,0.000461,0.004827,0.122608,291.535492,14.851526,1.226079,-316.971252,0.021513,0.000000
83.310005,65.578140,-316.971252,0.000466,0.004838,0.122896,291.706146,14.860219,1.228955,-316.971252,294.500458,0.000000
83.710007,65.225510,-317.015747,0.000487,0.004840,0.122938,290.137543,14.780312,1.229379,-317.015747,294.500458,0.000000
84.110001,65.190125,-317.015747,0.000474,0.004844,0.123033,289.980164,14.772293,1.230333,-317.015747,294.500458,0.000000
84.510002,65.613510,-317.104706,0.000487,0.004853,0.123259,291.863464,14.868234,1.232589,-317.104706,294.500458,0.000000
84.910004,65.441483,-317.015747,0.000496,0.004853,0.123259,291.098267,14.829251,1.232589,-317.015747,294.500458,0.000000
85.310005,65.215073,-317.060211,0.000483,0.004853,0.123277,290.091125,14.777947,1.232771,-317.060211,294.500458,0.000000
85.710007,65.540527,-317.104706,0.000487,0.004859,0.123415,291.538818,14.851695,1.234148,-317.104706,294.500458,0.000000
86.110001,65.314499,-317.149170,0.000500,0.004859,0.123415,290.533386,14.800477,1.234148,-317.149170,294.500458,0.000000
86.510002,65.098526,-317.149170,0.000487,0.004859,0.123415,289.572693,14.751537,1.234148,-317.149170,294.500458,0.000000
86.910004,64.929092,-317.238129,0.000496,0.004859,0.123415,288.819031,14.713142,1.234148,-317.238129,294.500458,0.000000
87.310005,65.927048,-317.238129,0.000504,0.004860,0.123433,293.258148,14.939282,1.234330,-317.238129,294.500458,0.000000
87.710007,65.752777,-317.238129,0.000504,0.004860,0.123433,292.482971,14.899792,1.234330,-317.238129,294.500458,0.000000
88.110001,65.563614,-317.238129,0.000509,0.004860,0.123433,291.641510,14.856928,1.234330,-317.238129,294.500458,0.000000
88.510002,65.364029,-317.282623,0.000513,0.004860,0.123433,290.753723,14.811701,1.234330,-317.282623,294.500458,0.000000
88.910004,65.228851,-317.327118,0.000504,0.004860,0.123441,290.152435,14.781069,1.234406,-317.327118,294.500458,0.000000
89.310005,65.346527,-317.282623,0.000509,0.004873,0.123762,290.675873,14.807735,1.237615,-317.282623,294.500458,0.000000
89.710007,65.333862,-317.327118,0.000522,0.004872,0.123754,290.619537,14.804865,1.237540,-317.327118,294.500458,0.000000
90.110001,65.269073,-317.371582,0.000513,0.004872,0.123754,290.331329,14.790184,1.237540,-317.371582,294.500458,0.000000
90.510002,65.177841,-317.416077,0.000513,0.004873,0.123762,289.925507,14.769509,1.237615,-317.416077,294.500458,0.000000
90.910004,65.113052,-317.416077,0.000517,0.004874,0.123796,289.637329,14.754828,1.237963,-317.416077,294.500458,0.000000
91.310005,65.057938,-317.505035,0.000504,0.004875,0.123815,289.392151,14.742340,1.238145,-317.505035,294.500458,0.000000
91.710007,65.027023,-317.460541,0.000509,0.004875,0.123822,289.254639,14.735333,1.238221,-317.460541,294.500458,0.000000
92.110001,65.012512,-317.505035,0.000522,0.004876,0.123849,289.190094,14.732045,1.238493,-317.505035,294.500458,0.000000
92.510002,64.977127,-317.549500,0.000509,0.004876,0.123849,289.032684,14.724028,1.238493,-317.549500,294.500458,0.000000
92.910004,65.689484,-317.549500,0.000513,0.004885,0.124092,292.201416,14.885449,1.240916,-317.549500,294.500458,0.000000
93.310005,65.659683,-317.549500,0.000522,0.004884,0.124048,292.068848,14.878696,1.240477,-317.549500,294.500458,0.000000
93.710007,65.592667,-317.638458,0.000500,0.004884,0.124048,291.770752,14.863511,1.240477,-317.638458,294.500458,0.000000
94.110008,65.553192,-317.638458,0.000517,0.004884,0.124048,291.595154,14.854566,1.240477,-317.638458,294.500458,0.000000
94.510002,65.490631,-317.638458,0.000522,0.004884,0.124048,291.316864,14.840389,1.240477,-317.638458,294.500458,0.000000
94.910004,65.422119,-317.771912,0.000522,0.004884,0.124048,291.012115,14.824864,1.240477,-317.771912,294.500458,0.000000
95.310005,65.358810,-317.727448,0.000522,0.004884,0.124057,290.730499,14.810518,1.240567,-317.727448,294.500458,0.000000
95.710007,65.303329,-317.727448,0.000517,0.004884,0.124057,290.483704,14.797946,1.240567,-317.727448,294.500458,0.000000
96.110008,65.255661,-317.771912,0.000509,0.004884,0.124057,290.271667,14.787145,1.240567,-317.771912,294.500458,0.000000
96.510002,65.193481,-317.816406,0.000509,0.004884,0.124057,289.995087,14.773054,1.240567,-317.816406,294.500458,0.000000
96.910004,65.124222,-317.816406,0.000517,0.004884,0.124057,289.687012,14.757360,1.240567,-317.816406,294.500458,0.000000
97.310005,65.065018,-317.905365,0.000522,0.004884,0.124057,289.423645,14.743943,1.240567,-317.905365,294.500458,0.000000
97.710007,65.028152,-317.905365,0.000522,0.004884,0.124057,289.259674,14.735590,1.240567,-317.905365,294.500458,0.000000
98.110008,64.979736,-317.860870,0.000517,0.004884,0.124057,289.044312,14.724619,1.240567,-317.860870,294.500458,0.000000
98.510002,64.934677,-317.905365,0.000526,0.004884,0.124057,288.843872,14.714408,1.240567,-317.905365,294.500458,0.000000
98.910004,64.872864,-317.860870,0.000530,0.004884,0.124057,288.568909,14.700401,1.240567,-317.860870,294.500458,0.000000
99.310005,66.399963,-317.994324,0.000526,0.004888,0.124161,295.361786,15.046447,1.241612,-317.994324,294.500458,0.000000
99.710007,66.328094,-317.994324,0.000539,0.004888,0.124161,295.042114,15.030161,1.241612,-317.994324,294.500458,0.000000
100.110008,66.273361,-317.994324,0.000530,0.004888,0.124161,294.798645,15.017758,1.241612,-317.994324,294.500458,0.000000
100.510002,66.229416,-318.038788,0.000530,0.004888,0.124161,294.603149,15.007800,1.241612,-318.038788,294.500458,0.000000
100.910004,66.167984,-318.038788,0.000535,0.004888,0.124161,294.329895,14.993879,1.241612,-318.038788,294.500458,0.000000
101.310005,66.109146,-318.083282,0.000530,0.004888,0.124161,294.068176,14.980546,1.241612,-318.083282,294.500458,0.000000
101.710007,66.054779,-318.127777,0.000526,0.004888,0.124161,293.826324,14.968226,1.241612,-318.127777,294.500458,0.000000
102.110008,66.011581,-318.083282,0.000535,0.004888,0.124152,293.634186,14.958439,1.241521,-318.083282,294.500458,0.000000
102.510002,66.019775,-318.127777,0.000539,0.004888,0.124152,293.670624,14.960295,1.241521,-318.127777,294.500458,0.000000
102.910004,65.949402,-318.216736,0.000530,0.004888,0.124152,293.357605,14.944347,1.241521,-318.216736,294.500458,0.000000
103.310005,65.850723,-318.261200,0.000543,0.004888,0.124152,292.918640,14.921987,1.241521,-318.261200,294.500458,0.000000
103.710007,65.852951,-318.261200,0.000543,0.004888,0.124161,292.928558,14.922492,1.241612,-318.261200,294.500458,0.000000
104.110008,65.807892,-318.261200,0.000548,0.004888,0.124161,292.728119,14.912281,1.241612,-318.261200,294.500458,0.000000
104.510002,65.765823,-318.305695,0.000530,0.004888,0.124161,292.540985,14.902749,1.241612,-318.305695,294.500458,0.000000
104.910004,65.732300,-318.261200,0.000539,0.004888,0.124161,292.391876,14.895152,1.241612,-318.261200,294.500458,0.000000
105.310005,65.610535,-318.350159,0.000539,0.004888,0.124161,291.850220,14.867560,1.241612,-318.350159,294.500458,0.000000
105.710007,65.590805,-318.350159,0.000530,0.004888,0.124161,291.762482,14.863089,1.241612,-318.350159,294.500458,0.000000
106.110008,65.582611,-318.350159,0.000539,0.004888,0.124161,291.726013,14.861233,1.241612,-318.350159,294.500458,0.000000
106.510002,65.537186,-318.439117,0.000539,0.004888,0.124161,291.523956,14.850938,1.241612,-318.439117,294.500458,0.000000
106.910004,65.510376,-318.394653,0.000552,0.004888,0.124161,291.404694,14.844864,1.241612,-318.394653,294.500458,0.000000
107.310005,65.481689,-318.483612,0.000539,0.004888,0.124161,291.277100,14.838363,1.241612,-318.483612,294.500458,0.000000
107.710007,65.418015,-318.483612,0.000543,0.004888,0.124161,290.993866,14.823934,1.241612,-318.483612,294.500458,0.000000
108.110008,65.381897,-318.528076,0.000530,0.004888,0.124161,290.833191,14.815749,1.241612,-318.528076,294.500458,0.000000
108.510002,65.331635,-318.572571,0.000535,0.004888,0.124161,290.609619,14.804359,1.241612,-318.572571,294.500458,0.000000
108.910004,65.310410,-318.528076,0.000543,0.004888,0.124161,290.515198,14.799551,1.241612,-318.528076,294.500458,0.000000
109.310005,65.286942,-318.572571,0.000539,0.004888,0.124161,290.410828,14.794232,1.241612,-318.572571,294.500458,0.000000
109.710007,65.278015,-318.661530,0.000539,0.004888,0.124161,290.371124,14.792210,1.241612,-318.661530,294.500458,0.000000
110.110008,65.250076,-318.706024,0.000535,0.004888,0.124161,290.246826,14.785879,1.241612,-318.706024,294.500458,0.000000
110.510002,65.218063,-318.706024,0.000535,0.004888,0.124161,290.104431,14.778625,1.241612,-318.706024,294.500458,0.000000
110.910004,65.176346,-318.661530,0.000535,0.004888,0.124161,289.918854,14.769171,1.241612,-318.661530,294.500458,0.000000
111.310005,65.123108,-318.750488,0.000539,0.004888,0.124161,289.682037,14.757108,1.241612,-318.750488,294.500458,0.000000
111.710007,65.091446,-318.794983,0.000548,0.004888,0.124161,289.541199,14.749933,1.241612,-318.794983,294.500458,0.000000
112.110008,65.072083,-318.750488,0.000539,0.004888,0.124161,289.455078,14.745544,1.241612,-318.750488,294.500458,0.000000
112.510002,65.048996,-318.794983,0.000539,0.004888,0.124161,289.352386,14.740314,1.241612,-318.794983,294.500458,0.000000
112.910004,65.935989,-318.883942,0.000543,0.004907,0.124629,293.297943,14.941308,1.246290,-318.883942,294.500458,0.000000
113.310005,65.959457,-318.883942,0.000539,0.004906,0.124603,293.402313,14.946627,1.246033,-318.883942,294.500458,0.000000
113.710007,65.902100,-318.883942,0.000543,0.004906,0.124603,293.147186,14.933629,1.246033,-318.883942,294.500458,0.000000
114.110008,65.942322,-318.883942,0.000548,0.004906,0.124603,293.326111,14.942743,1.246033,-318.883942,294.500458,0.000000
114.510002,65.868225,-319.017395,0.000539,0.004906,0.124603,292.996490,14.925953,1.246033,-319.017395,294.500458,0.000000
114.910004,65.875290,-318.928406,0.000552,0.004906,0.124603,293.027924,14.927554,1.246033,-318.928406,294.500458,0.000000
115.310005,65.875290,-319.017395,0.000535,0.004906,0.124603,293.027924,14.927554,1.246033,-319.017395,294.500458,0.000000
115.710007,65.862259,-319.061859,0.000556,0.004906,0.124603,292.969971,14.924602,1.246033,-319.061859,294.500458,0.000000
116.110008,65.870087,-319.106354,0.000548,0.004906,0.124603,293.004791,14.926375,1.246033,-319.106354,294.500458,0.000000
116.510002,65.847366,-319.061859,0.000539,0.004906,0.124603,292.903717,14.921227,1.246033,-319.061859,294.500458,0.000000
116.910004,65.852203,-319.150818,0.000552,0.004906,0.124603,292.925232,14.922323,1.246033,-319.150818,294.500458,0.000000
117.310005,65.836563,-319.061859,0.000543,0.004906,0.124603,292.855652,14.918778,1.246033,-319.061859,294.500458,0.000000
117.710007,65.775131,-319.106354,0.000552,0.004906,0.124603,292.582397,14.904858,1.246033,-319.106354,294.500458,0.000000
118.110008,65.769547,-319.195312,0.000543,0.004906,0.124603,292.557556,14.903592,1.246033,-319.195312,294.500458,0.000000
118.510002,65.765442,-319.239777,0.000552,0.004906,0.124603,292.539307,14.902661,1.246033,-319.239777,294.500458,0.000000
118.910004,65.756500,-319.239777,0.000539,0.004906,0.124603,292.499512,14.900637,1.246033,-319.239777,294.500458,0.000000
119.310005,65.708099,-319.328735,0.000548,0.004906,0.124603,292.284210,14.889668,1.246033,-319.328735,294.500458,0.000000
119.710007,65.677567,-319.284271,0.000552,0.004906,0.124603,292.148407,14.882749,1.246033,-319.284271,294.500458,0.000000
120.110008,65.657089,-319.328735,0.000539,0.004906,0.124603,292.057312,14.878109,1.246033,-319.328735,294.500458,0.000000
120.510002,65.651871,-319.284271,0.000543,0.004906,0.124603,292.034119,14.876926,1.246033,-319.284271,294.500458,0.000000
120.910004,65.637344,-319.328735,0.000548,0.004906,0.124603,291.969482,14.873634,1.246033,-319.328735,294.500458,0.000000
121.310005,65.602341,-319.373230,0.000539,0.004906,0.124603,291.813782,14.865703,1.246033,-319.373230,294.500458,0.000000
121.710007,65.596756,-319.373230,0.000543,0.004906,0.124603,291.788940,14.864437,1.246033,-319.373230,294.500458,0.000000
122.110008,65.577393,-319.417725,0.000552,0.004906,0.124603,291.702820,14.860049,1.246033,-319.417725,294.500458,0.000000
122.510002,65.573303,-319.417725,0.000543,0.004906,0.124603,291.684631,14.859122,1.246033,-319.417725,294.500458,0.000000
122.910004,65.570328,-319.506683,0.000543,0.004906,0.124603,291.671387,14.858449,1.246033,-319.506683,294.500458,0.000000
123.310005,65.549835,-319.506683,0.000552,0.004906,0.124603,291.580231,14.853806,1.246033,-319.506683,294.500458,0.000000
123.710007,65.546494,-319.462189,0.000548,0.004906,0.124603,291.565369,14.853048,1.246033,-319.462189,294.500458,0.000000
124.110008,65.528610,-319.462189,0.000539,0.004906,0.124603,291.485809,14.848995,1.246033,-319.462189,294.500458,0.000000
124.510002,65.511108,-319.551147,0.000539,0.004906,0.124603,291.407959,14.845029,1.246033,-319.551147,294.500458,0.000000
124.910004,65.489883,-319.595642,0.000548,0.004906,0.124603,291.313538,14.840219,1.246033,-319.595642,294.500458,0.000000
125.310005,65.482071,-319.595642,0.000548,0.004906,0.124603,291.278809,14.838449,1.246033,-319.595642,294.500458,0.000000
125.710007,65.473511,-319.595642,0.000539,0.004906,0.124603,291.240723,14.836510,1.246033,-319.595642,294.500458,0.000000
126.110008,65.442596,-319.640106,0.000535,0.004906,0.124603,291.103210,14.829504,1.246033,-319.640106,294.500458,0.000000
126.510010,65.414673,-319.640106,0.000530,0.004906,0.124603,290.979004,14.823176,1.246033,-319.640106,294.500458,0.000000
126.910004,65.392700,-319.684601,0.000535,0.004906,0.124603,290.881256,14.818198,1.246033,-319.684601,294.500458,0.000000
127.310005,65.378174,-319.729065,0.000539,0.004906,0.124603,290.816650,14.814906,1.246033,-319.729065,294.500458,0.000000
127.710007,65.356583,-319.684601,0.000539,0.004906,0.124603,290.720612,14.810014,1.246033,-319.684601,294.500458,0.000000
128.110001,65.343552,-319.729065,0.000543,0.004906,0.124603,290.662628,14.807060,1.246033,-319.729065,294.500458,0.000000
128.510010,65.338333,-319.773560,0.000539,0.004906,0.124603,290.639435,14.805878,1.246033,-319.773560,294.500458,0.000000
128.910004,65.311890,-319.818024,0.000548,0.004906,0.124612,290.521790,14.799886,1.246124,-319.818024,294.500458,0.000000
129.310013,65.287689,-319.818024,0.000543,0.004906,0.124612,290.414154,14.794401,1.246124,-319.818024,294.500458,0.000000
129.710007,65.270935,-319.907013,0.000548,0.004906,0.124612,290.339630,14.790605,1.246124,-319.907013,294.500458,0.000000
130.110001,65.268326,-319.907013,0.000530,0.004906,0.124612,290.328003,14.790014,1.246124,-319.907013,294.500458,0.000000
130.510010,65.258652,-319.951477,0.000539,0.004906,0.124612,290.284973,14.787822,1.246124,-319.951477,294.500458,0.000000
130.910004,65.233322,-319.907013,0.000552,0.004906,0.124612,290.172302,14.782083,1.246124,-319.907013,294.500458,0.000000
131.310013,65.206146,-319.951477,0.000543,0.004906,0.124612,290.051422,14.775925,1.246124,-319.951477,294.500458,0.000000
131.710007,65.190872,-319.995972,0.000560,0.004906,0.124612,289.983490,14.772463,1.246124,-319.995972,294.500458,0.000000
132.110001,65.170013,-319.995972,0.000552,0.004906,0.124612,289.890686,14.767735,1.246124,-319.995972,294.500458,0.000000
132.510010,65.239288,-320.084930,0.000539,0.004909,0.124690,290.198853,14.783434,1.246896,-320.084930,294.500458,0.000000
132.910004,65.258652,-320.084930,0.000539,0.004909,0.124690,290.284973,14.787822,1.246896,-320.084930,294.500458,0.000000
133.310013,65.264236,-320.129395,0.000543,0.004909,0.124690,290.309814,14.789087,1.246896,-320.129395,294.500458,0.000000
133.710007,65.260880,-320.129395,0.000552,0.004909,0.124690,290.294891,14.788326,1.246896,-320.129395,294.500458,0.000000
134.110001,65.245987,-320.129395,0.000556,0.004909,0.124690,290.228638,14.784952,1.246896,-320.129395,294.500458,0.000000
134.510010,65.250824,-320.129395,0.000552,0.004909,0.124690,290.250153,14.786048,1.246896,-320.129395,294.500458,0.000000
134.910004,65.240402,-320.218353,0.000548,0.004909,0.124690,290.203796,14.783687,1.246896,-320.218353,294.500458,0.000000
135.310013,65.237045,-320.173889,0.000556,0.004909,0.124690,290.188873,14.782926,1.246896,-320.173889,294.500458,0.000000
135.710007,65.226624,-320.262848,0.000543,0.004909,0.124690,290.142517,14.780564,1.246896,-320.262848,294.500458,0.000000
136.110001,65.207626,-320.218353,0.000556,0.004909,0.124690,290.058014,14.776259,1.246896,-320.218353,294.500458,0.000000
136.510010,65.202789,-320.351807,0.000548,0.004909,0.124690,290.036499,14.775164,1.246896,-320.351807,294.500458,0.000000
136.910004,65.195709,-320.307343,0.000548,0.004909,0.124690,290.005005,14.773559,1.246896,-320.307343,294.500458,0.000000
137.310013,65.181198,-320.351807,0.000535,0.004909,0.124690,289.940460,14.770271,1.246896,-320.351807,294.500458,0.000000
137.710007,65.141342,-320.351807,0.000543,0.004909,0.124690,289.763153,14.761239,1.246896,-320.351807,294.500458,0.000000
138.110001,65.141724,-320.396301,0.000530,0.004909,0.124690,289.764862,14.761325,1.246896,-320.396301,294.500458,0.000000
138.510010,65.116394,-320.485260,0.000539,0.004909,0.124690,289.652191,14.755586,1.246896,-320.485260,294.500458,0.000000
138.910004,65.120499,-320.440765,0.000556,0.004909,0.124690,289.670441,14.756516,1.246896,-320.440765,294.500458,0.000000
139.310013,65.097031,-320.485260,0.000543,0.004909,0.124690,289.566040,14.751199,1.246896,-320.485260,294.500458,0.000000
139.710007,65.082138,-320.485260,0.000548,0.004909,0.124690,289.499817,14.747823,1.246896,-320.485260,294.500458,0.000000
140.110001,65.060165,-320.529724,0.000552,0.004909,0.124690,289.402069,14.742845,1.246896,-320.529724,294.500458,0.000000
140.510010,65.066879,-320.485260,0.000548,0.004909,0.124690,289.431946,14.744366,1.246896,-320.485260,294.500458,0.000000
140.910004,65.060165,-320.574219,0.000552,0.004909,0.124690,289.402069,14.742845,1.246896,-320.574219,294.500458,0.000000
141.310013,65.057190,-320.574219,0.000543,0.004909,0.124690,289.388824,14.742170,1.246896,-320.574219,294.500458,0.000000
141.710007,65.044525,-320.618683,0.000552,0.004909,0.124690,289.332489,14.739301,1.246896,-320.618683,294.500458,0.000000
142.110001,65.031876,-320.663177,0.000548,0.004909,0.124690,289.276245,14.736434,1.246896,-320.663177,294.500458,0.000000
142.510010,65.021439,-320.707672,0.000552,0.004909,0.124690,289.229797,14.734068,1.246896,-320.707672,294.500458,0.000000
142.910004,65.009903,-320.707672,0.000548,0.004909,0.124690,289.178497,14.731455,1.246896,-320.707672,294.500458,0.000000
143.310013,65.005798,-320.663177,0.000552,0.004909,0.124690,289.160248,14.730524,1.246896,-320.663177,1681.640747,0.000000
143.710007,64.860947,-320.752136,0.000548,0.004896,0.124352,288.515900,14.697701,1.243520,-320.752136,0.124135,0.000000
144.110001,64.910110,-320.796631,0.000552,0.004879,0.123936,288.734589,14.708841,1.239356,-320.796631,0.123468,0.000000
144.510010,64.872864,-320.796631,0.000569,0.004866,0.123589,288.568909,14.700401,1.235889,-320.796631,0.122799,0.000000
144.910004,64.870636,-320.841095,0.000569,0.004828,0.122626,288.558990,14.699896,1.226261,-320.841095,0.122131,0.000000
145.310013,64.862076,-320.841095,0.000560,0.004806,0.122063,288.520935,14.697956,1.220629,-320.841095,0.121463,0.000000
145.710007,64.884415,-320.885590,0.000560,0.004783,0.121498,288.620300,14.703018,1.214982,-320.885590,0.120796,0.000000
146.110001,64.808441,-320.885590,0.000578,0.004757,0.120821,288.282349,14.685803,1.208214,-320.885590,0.120128,0.000000
146.510010,64.831909,-320.930054,0.000578,0.004727,0.120077,288.386749,14.691121,1.200765,-320.930054,0.119469,0.000000
146.910004,64.773437,-320.930054,0.000569,0.004705,0.119513,288.126648,14.677870,1.195134,-320.930054,0.118802,0.000000
147.310013,64.736572,-321.019012,0.000560,0.004682,0.118932,287.962646,14.669518,1.189320,-321.019012,0.118134,0.000000
147.710007,64.479263,-320.974548,0.000573,0.004656,0.118255,286.818085,14.611210,1.182553,-320.974548,0.117466,0.000000
148.110001,63.715530,-321.019012,0.000573,0.004628,0.117553,283.420837,14.438146,1.175528,-321.019012,0.116799,0.000000
148.510010,62.659485,-321.063507,0.000578,0.004601,0.116867,278.723297,14.198842,1.168670,-321.063507,0.116131,0.000000
148.910004,61.192337,-321.063507,0.000582,0.004577,0.116252,272.197113,13.866382,1.162523,-321.063507,0.115462,0.000000
149.310013,59.893875,-321.063507,0.000578,0.004558,0.115775,266.421265,13.572145,1.157754,-321.063507,0.114794,0.000000
149.710007,57.963127,-321.107971,0.000573,0.004533,0.115141,257.832855,13.134633,1.151410,-321.107971,0.114136,0.000000
150.110001,55.656281,-321.196960,0.000573,0.004506,0.114448,247.571503,12.611893,1.144477,-321.196960,0.113468,0.000000
150.510010,53.279427,-321.152466,0.000582,0.004481,0.113815,236.998734,12.073291,1.138148,-321.152466,0.112800,0.000000
150.910004,50.116119,-321.196960,0.000573,0.004452,0.113078,222.927628,11.356475,1.130775,-321.196960,0.112133,0.000000
151.310013,47.733681,-321.196960,0.000573,0.004431,0.112549,212.330017,10.816607,1.125491,-321.196960,0.111465,0.000000
151.710007,44.774811,-321.241425,0.000569,0.004406,0.111907,199.168304,10.146117,1.119072,-321.241425,0.110798,0.000000
152.110001,41.316589,-321.285919,0.000578,0.004372,0.111049,183.785370,9.362473,1.110488,-321.285919,0.110130,0.000000
152.510010,39.043251,-321.285919,0.000565,0.004353,0.110572,173.673050,8.847327,1.105719,-321.285919,0.109462,0.000000
152.910004,36.038208,-321.330383,0.000578,0.004325,0.109860,160.305954,8.166374,1.098604,-321.330383,0.108793,0.000000
153.310013,33.348190,-321.419342,0.000582,0.004302,0.109262,148.340164,7.556808,1.092623,-321.419342,0.108134,0.000000
153.710007,30.563957,-321.419342,0.000586,0.004275,0.108577,135.955276,6.925892,1.085765,-321.419342,0.107467,0.000000
154.110001,28.285782,-321.374878,0.000573,0.004258,0.108160,125.821442,6.409650,1.081602,-321.374878,0.106799,0.000000
154.510010,24.401192,-321.463837,0.000573,0.004217,0.107111,108.541924,5.529389,1.071110,-321.463837,0.106131,0.000000
154.910004,21.520149,-321.463837,0.000565,0.004195,0.106564,95.726402,4.876535,1.065645,-321.463837,0.105464,0.000000
155.310013,17.270638,-321.463837,0.000560,0.004155,0.105541,76.823631,3.913582,1.055410,-321.463837,0.104796,0.000000
155.710007,15.056511,-321.463837,0.000560,0.004140,0.105169,66.974709,3.411854,1.051686,-321.463837,0.104129,0.000000
156.110001,12.401863,-321.508301,0.000573,0.004115,0.104527,55.166241,2.810302,1.045267,-321.508301,0.103461,0.000000
156.510010,9.950539,-321.508301,0.000560,0.004095,0.104006,44.262207,2.254824,1.040059,-321.508301,0.102801,0.000000
156.910004,6.588013,-321.552795,0.000560,0.004063,0.103191,29.304945,1.492865,1.031914,-321.552795,0.102133,0.000000
157.310013,3.328636,-321.597290,0.000543,0.004033,0.102428,14.806513,0.754280,1.024283,-321.597290,0.101465,0.000000
157.710007,1.006523,-321.641754,0.000552,0.004010,0.101856,4.477239,0.228081,1.018561,-321.641754,0.100798,0.000000
158.110001,-0.986416,-321.597290,0.000539,0.003989,0.101326,-4.387797,-0.223525,1.013262,-321.597290,0.100130,0.000000
158.510010,-0.332153,-321.686249,0.000487,0.003956,0.100495,-1.477492,-0.075267,1.004950,-321.686249,0.099462,0.000000
158.910004,-0.087883,-321.641754,0.000448,0.003933,0.099888,-0.390923,-0.019915,0.998879,-321.641754,0.098795,0.000000
159.310013,-0.209648,-321.730713,0.000414,0.003902,0.099116,-0.932561,-0.047507,0.991158,-321.730713,0.098127,0.000000
159.710007,-0.022713,-321.730713,0.000354,0.003881,0.098569,-0.101031,-0.005147,0.985693,-321.730713,0.097467,0.000000
160.110001,-0.006706,-321.775208,0.000280,0.003858,0.097988,-0.029831,-0.001520,0.979879,-321.775208,0.096799,0.000000
160.510010,-0.017128,-321.864166,0.000216,0.003828,0.097242,-0.076189,-0.003881,0.972415,-321.864166,0.096132,0.000000
160.910004,0.002235,-321.864166,0.000151,0.003805,0.096644,0.009944,0.000507,0.966435,-321.864166,0.095464,0.000000
161.310013,0.006332,-321.864166,0.000078,0.003771,0.095794,0.028168,0.001435,0.957942,-321.864166,0.094796,0.000000
161.710007,0.034630,-321.864166,0.000013,0.003752,0.095299,0.154041,0.007847,0.952991,-321.864166,0.094129,0.000000
162.110001,0.021973,-321.953125,-0.000069,0.003726,0.094641,0.097739,0.004979,0.946405,-321.953125,0.093461,0.000000
162.510010,0.025322,-321.953125,-0.000142,0.003698,0.093921,0.112638,0.005738,0.939214,-321.953125,0.092794,0.000000
162.910004,-0.012291,-321.953125,-0.000229,0.003670,0.093219,-0.054673,-0.002785,0.932189,-321.953125,0.092135,0.000000
163.310013,0.007072,-321.997620,-0.000323,0.003637,0.092386,0.031460,0.001603,0.923863,-321.997620,0.091467,0.000000
163.710007,-0.048035,-321.953125,-0.000371,0.003614,0.091787,-0.213669,-0.010885,0.917867,-321.953125,0.090798,0.000000
164.110001,-0.052132,-322.042084,-0.000457,0.003583,0.091016,-0.231893,-0.011813,0.910161,-322.042084,0.090130,0.000000
164.510010,-0.043938,-322.042084,-0.000526,0.003556,0.090330,-0.195445,-0.009956,0.903303,-322.042084,0.089463,0.000000
164.910004,-0.018616,-322.131042,-0.000599,0.003522,0.089463,-0.082807,-0.004218,0.894628,-322.131042,0.089377,0.000000
165.100006,-0.017128,-322.131042,-0.000595,0.003523,0.089472,-0.076189,-0.003881,0.894719,-322.131042,0.089377,0.000000