File: Data/compression 31/ManualNoHeating-15-31-reverse-1-2_11132024_175034.csv
Time (sec),S:Load (lbs),S:HL1 (DIM),S:LVDT (in),S:Position (in),Ch:Position (mm),Ch:Load (N),Ch:Stress (MPa),Ch:Strain (mm/mm),Ch:HL1 (DIM),Set Point (),Cycles ()
0.110000,-0.048035,-222.226837,-0.009666,-0.004899,-0.124438,-0.213669,-0.010885,-1.244383,-222.226837,-0.124255,0.000000
0.490000,-0.018990,-222.226837,-0.009666,-0.004852,-0.123232,-0.084470,-0.004303,-1.232316,-222.226837,-0.122573,0.000000
0.870000,-0.044685,-222.315796,-0.009580,-0.004617,-0.117265,-0.198770,-0.010126,-1.172651,-222.315796,-0.116242,0.000000
1.250000,-0.032394,-222.271317,-0.009304,-0.004366,-0.110891,-0.144098,-0.007341,-1.108914,-222.271317,-0.109912,0.000000
1.630000,-0.073357,-222.315796,-0.009071,-0.004122,-0.104699,-0.326307,-0.016623,-1.046993,-222.315796,-0.103580,0.000000
2.010000,-0.026810,-222.404755,-0.008830,-0.003868,-0.098256,-0.119255,-0.006075,-0.982559,-222.404755,-0.097251,0.000000
2.390000,-0.029793,-222.449234,-0.008571,-0.003624,-0.092038,-0.132525,-0.006751,-0.920380,-222.449234,-0.090919,0.000000
2.770000,-0.023087,-222.404755,-0.008308,-0.003370,-0.085586,-0.102694,-0.005231,-0.855856,-222.404755,-0.084589,0.000000
3.150000,-0.043938,-222.449234,-0.008050,-0.003120,-0.079247,-0.195445,-0.009956,-0.792466,-222.449234,-0.078258,0.000000
3.530000,-0.079689,-222.449234,-0.007795,-0.002872,-0.072959,-0.354474,-0.018058,-0.729591,-222.449234,-0.071927,0.000000
3.910000,-0.084900,-222.582672,-0.007545,-0.002628,-0.066741,-0.377654,-0.019239,-0.667413,-222.582672,-0.065597,0.000000
4.290000,-0.045059,-222.538193,-0.007269,-0.002381,-0.060471,-0.200433,-0.010211,-0.604705,-222.538193,-0.059265,0.000000
4.670000,-0.048782,-222.538193,-0.007015,-0.002127,-0.054027,-0.216995,-0.011054,-0.540271,-222.538193,-0.052936,0.000000
5.050000,-0.066284,-222.582672,-0.006752,-0.001880,-0.047749,-0.294847,-0.015020,-0.477487,-222.582672,-0.046604,0.000000
5.430000,-0.084900,-222.671646,-0.006489,-0.001630,-0.041392,-0.377654,-0.019239,-0.413916,-222.671646,-0.040273,0.000000
5.810000,-0.113945,-222.760605,-0.006243,-0.001378,-0.034992,-0.506853,-0.025820,-0.349921,-222.760605,-0.033943,0.000000
6.190000,-0.037239,-222.716125,-0.005993,-0.001128,-0.028644,-0.165648,-0.008438,-0.286441,-222.716125,-0.027612,0.000000
6.570000,-0.010056,-222.760605,-0.005730,-0.000876,-0.022261,-0.044729,-0.002279,-0.222612,-222.760605,-0.021282,0.000000
6.950000,0.008194,-222.894043,-0.005476,-0.000627,-0.015930,0.036449,0.001857,-0.159299,-222.894043,-0.014950,0.000000
7.330000,-0.026436,-222.894043,-0.005221,-0.000375,-0.009530,-0.117593,-0.005990,-0.095304,-222.894043,-0.008620,0.000000
7.710001,-0.027557,-222.849564,-0.005001,-0.000128,-0.003243,-0.122581,-0.006245,-0.032429,-222.849564,-0.002289,0.000000
8.090000,0.235336,-222.805084,-0.004790,-0.000008,-0.000198,1.046828,0.053328,-0.001983,-222.805084,-0.000051,0.000000
8.470000,0.220818,-222.938522,-0.004777,-0.000009,-0.000224,0.982246,0.050038,-0.002241,-222.938522,-0.000051,0.000000
8.850000,0.186562,-222.938522,-0.004760,-0.000009,-0.000224,0.829867,0.042275,-0.002241,-222.938522,0.000425,0.000000
9.230000,0.283745,-223.071976,-0.004773,0.000009,0.000226,1.262160,0.064297,0.002256,-223.071976,0.001058,0.000000
9.610001,0.529510,-223.027481,-0.004781,0.000031,0.000790,2.355380,0.119989,0.007903,-223.027481,0.001691,0.000000
9.990001,0.769691,-223.071976,-0.004751,0.000064,0.001631,3.423759,0.174415,0.016305,-223.071976,0.002325,0.000000
10.370001,1.025139,-223.116455,-0.004704,0.000084,0.002142,4.560045,0.232300,0.021423,-223.116455,0.002958,0.000000
10.750001,1.403847,-223.160934,-0.004691,0.000107,0.002715,6.244622,0.318116,0.027145,-223.160934,0.003591,0.000000
11.130000,1.906174,-223.205414,-0.004674,0.000136,0.003461,8.479084,0.431945,0.034609,-223.205414,0.004224,0.000000
11.510000,2.310944,-223.160934,-0.004674,0.000158,0.004017,10.279591,0.523667,0.040165,-223.160934,0.004857,0.000000
11.890000,2.823700,-223.205414,-0.004639,0.000186,0.004719,12.560445,0.639860,0.047190,-223.205414,0.005490,0.000000
12.270000,3.097397,-223.205414,-0.004609,0.000207,0.005256,13.777909,0.701880,0.052565,-223.205414,0.006132,0.000000
12.650001,3.536049,-223.338852,-0.004592,0.000230,0.005838,15.729131,0.801280,0.058378,-223.338852,0.006764,0.000000
13.030001,4.096840,-223.383331,-0.004557,0.000261,0.006618,18.223654,0.928357,0.066175,-223.383331,0.007399,0.000000
13.410001,4.443520,-223.383331,-0.004553,0.000282,0.007155,19.765762,1.006916,0.071550,-223.383331,0.008032,0.000000
13.790001,4.642365,-223.383331,-0.004540,0.000298,0.007571,20.650269,1.051975,0.075713,-223.383331,0.008664,0.000000
14.170001,5.263481,-223.472305,-0.004506,0.000328,0.008334,23.413134,1.192722,0.083343,-223.472305,0.009297,0.000000
14.550001,5.750549,-223.561264,-0.004488,0.000353,0.008967,25.579721,1.303093,0.089672,-223.561264,0.009930,0.000000
14.930000,6.375763,-223.516785,-0.004462,0.000383,0.009732,28.360809,1.444769,0.097317,-223.516785,0.010563,0.000000
15.310000,6.565674,-223.472305,-0.004445,0.000401,0.010190,29.205576,1.487803,0.101905,-223.472305,0.011197,0.000000
15.690001,6.869896,-223.561264,-0.004411,0.000423,0.010737,30.558823,1.556741,0.107370,-223.561264,0.011830,0.000000
16.070002,7.690239,-223.605743,-0.004393,0.000459,0.011647,34.207890,1.742633,0.116469,-223.605743,0.012463,0.000000
16.450001,7.892433,-223.694702,-0.004376,0.000479,0.012177,35.107296,1.788451,0.121768,-223.694702,0.013096,0.000000
16.830000,8.431999,-223.650223,-0.004359,0.000505,0.012819,37.507404,1.910718,0.128187,-223.650223,0.013729,0.000000
17.210001,8.797302,-223.650223,-0.004333,0.000528,0.013408,39.132355,1.993497,0.134076,-223.650223,0.014361,0.000000
17.590000,8.855019,-223.739182,-0.004307,0.000542,0.013763,39.389091,2.006576,0.137634,-223.739182,0.014996,0.000000
17.970001,9.896545,-223.828140,-0.004273,0.000582,0.014778,44.022034,2.242589,0.147777,-223.828140,0.015629,0.000000
18.350000,10.016449,-223.828140,-0.004264,0.000604,0.015333,44.555389,2.269760,0.153334,-223.828140,0.016261,0.000000
18.730001,10.617455,-223.828140,-0.004243,0.000630,0.016001,47.228798,2.405950,0.160010,-223.828140,0.016894,0.000000
19.110001,10.934341,-223.828140,-0.004208,0.000655,0.016625,48.638378,2.477757,0.166248,-223.828140,0.017527,0.000000
19.490002,10.929131,-223.872620,-0.004195,0.000668,0.016964,48.615200,2.476576,0.169639,-223.872620,0.018160,0.000000
19.870001,12.017578,-224.006073,-0.004169,0.000707,0.017969,53.456856,2.723222,0.179692,-224.006073,0.018793,0.000000
20.250002,11.939751,-224.050552,-0.004135,0.000727,0.018455,53.110664,2.705586,0.184551,-224.050552,0.019427,0.000000
20.630001,12.616348,-224.006073,-0.004113,0.000756,0.019192,56.120319,2.858905,0.191924,-224.006073,0.020060,0.000000
21.010000,12.987602,-224.050552,-0.004096,0.000782,0.019851,57.771740,2.943033,0.198510,-224.050552,0.020693,0.000000
21.390001,12.964890,-224.095032,-0.004074,0.000796,0.020225,57.670708,2.937886,0.202250,-224.095032,0.021326,0.000000
21.770000,13.991898,-224.139511,-0.004053,0.000834,0.021179,62.239067,3.170609,0.211788,-224.139511,0.021958,0.000000
22.150002,13.885399,-224.139511,-0.004023,0.000852,0.021647,61.765339,3.146476,0.216466,-224.139511,0.022591,0.000000
22.530001,14.239525,-224.183990,-0.004014,0.000877,0.022270,63.340569,3.226722,0.222703,-224.183990,0.023226,0.000000
22.910002,14.754883,-224.228470,-0.003980,0.000904,0.022956,65.632996,3.343504,0.229561,-224.228470,0.023866,0.000000
23.290001,14.808510,-224.228470,-0.003949,0.000923,0.023433,65.871544,3.355656,0.234330,-224.228470,0.024500,0.000000
23.670002,15.777046,-224.317429,-0.003928,0.000958,0.024344,70.179810,3.575130,0.243444,-224.317429,0.025133,0.000000
24.050001,15.650810,-224.361923,-0.003902,0.000978,0.024847,69.618279,3.546524,0.248471,-224.361923,0.025766,0.000000
24.430000,16.060051,-224.272949,-0.003863,0.001005,0.025524,71.438675,3.639260,0.255238,-224.272949,0.026399,0.000000
24.810001,16.447319,-224.361923,-0.003846,0.001031,0.026199,73.161331,3.727016,0.261990,-224.361923,0.027032,0.000000
25.190001,16.460724,-224.495361,-0.003820,0.001049,0.026650,73.220955,3.730053,0.266502,-224.495361,0.027665,0.000000
25.570002,17.271751,-224.539841,-0.003786,0.001083,0.027509,76.828590,3.913835,0.275086,-224.539841,0.028299,0.000000
25.950001,17.241219,-224.450882,-0.003777,0.001104,0.028029,76.692772,3.906916,0.280294,-224.450882,0.028932,0.000000
26.330002,17.441925,-224.495361,-0.003755,0.001126,0.028602,77.585556,3.952397,0.286017,-224.495361,0.029565,0.000000
26.710001,17.946861,-224.539841,-0.003708,0.001153,0.029288,79.831627,4.066817,0.292875,-224.539841,0.030197,0.000000
27.090002,18.208267,-224.628799,-0.003699,0.001176,0.029867,80.994415,4.126052,0.298674,-224.628799,0.030830,0.000000
27.470001,18.822311,-224.673279,-0.003660,0.001208,0.030674,83.725822,4.265197,0.306743,-224.673279,0.031463,0.000000
27.850000,18.595161,-224.673279,-0.003652,0.001230,0.031230,82.715408,4.213724,0.312299,-224.673279,0.032097,0.000000
28.230001,18.974236,-224.673279,-0.003617,0.001253,0.031819,84.401611,4.299623,0.318189,-224.673279,0.032730,0.000000
28.610001,19.440445,-224.717758,-0.003583,0.001280,0.032512,86.475418,4.405268,0.325122,-224.717758,0.033363,0.000000
28.990002,19.677277,-224.806732,-0.003561,0.001303,0.033086,87.528900,4.458934,0.330860,-224.806732,0.033996,0.000000
29.370001,20.414200,-224.851212,-0.003523,0.001334,0.033891,90.806892,4.625924,0.338915,-224.851212,0.034629,0.000000
29.750002,20.084282,-224.851212,-0.003501,0.001351,0.034326,89.339348,4.551163,0.343260,-224.851212,0.035262,0.000000
30.130001,20.325577,-224.851212,-0.003471,0.001376,0.034950,90.412682,4.605841,0.349497,-224.851212,0.035894,0.000000
30.510002,20.728111,-224.940170,-0.003445,0.001403,0.035636,92.203247,4.697057,0.356355,-224.940170,0.036529,0.000000
30.890001,20.995476,-224.940170,-0.003415,0.001426,0.036224,93.392540,4.757643,0.362245,-224.940170,0.037162,0.000000
31.270002,20.715454,-225.073608,-0.003410,0.001444,0.036685,92.146942,4.694189,0.366847,-225.073608,0.037794,0.000000
31.650002,21.806877,-225.029129,-0.003367,0.001479,0.037578,97.001831,4.941509,0.375780,-225.029129,0.038427,0.000000
32.030003,21.823257,-225.029129,-0.003333,0.001503,0.038185,97.074699,4.945221,0.381850,-225.029129,0.039060,0.000000
32.410000,22.508423,-225.073608,-0.003303,0.001533,0.038930,100.122467,5.100482,0.389299,-225.073608,0.039693,0.000000
32.790001,22.462997,-225.118088,-0.003285,0.001555,0.039486,99.920403,5.090188,0.394855,-225.118088,0.040327,0.000000
33.170002,22.104401,-225.207062,-0.003268,0.001574,0.039972,98.325287,5.008929,0.399715,-225.207062,0.040960,0.000000
33.550003,23.126938,-225.162567,-0.003221,0.001604,0.040744,102.873756,5.240639,0.407436,-225.162567,0.041593,0.000000
33.930000,23.139595,-225.118088,-0.003195,0.001626,0.041298,102.930061,5.243507,0.412977,-225.118088,0.042235,0.000000
34.310001,23.890297,-225.296021,-0.003160,0.001654,0.042018,106.269348,5.413619,0.420184,-225.296021,0.042868,0.000000
34.690002,23.790131,-225.251541,-0.003134,0.001676,0.042582,105.823784,5.390921,0.425816,-225.251541,0.043501,0.000000
35.070004,23.565216,-225.340500,-0.003113,0.001692,0.042972,104.823318,5.339954,0.429722,-225.340500,0.044133,0.000000
35.450001,24.444016,-225.296021,-0.003083,0.001724,0.043796,108.732414,5.539093,0.437958,-225.296021,0.044766,0.000000
35.830002,24.773941,-225.340500,-0.003035,0.001751,0.044473,110.199997,5.613855,0.444725,-225.340500,0.045401,0.000000
36.210003,25.323563,-225.429459,-0.003018,0.001777,0.045131,112.644829,5.738401,0.451311,-225.429459,0.046033,0.000000
36.590000,25.337708,-225.518417,-0.002988,0.001800,0.045712,112.707748,5.741607,0.457124,-225.518417,0.046666,0.000000
36.970001,24.814529,-225.562897,-0.002953,0.001814,0.046068,110.380539,5.623053,0.460682,-225.562897,0.047299,0.000000
37.350002,26.395996,-225.562897,-0.002936,0.001855,0.047108,117.415253,5.981418,0.471083,-225.562897,0.047932,0.000000
37.730003,26.213905,-225.518417,-0.002902,0.001874,0.047611,116.605278,5.940156,0.476110,-225.518417,0.048565,0.000000
38.110001,26.197517,-225.607391,-0.002871,0.001895,0.048141,116.532379,5.936442,0.481408,-225.607391,0.049199,0.000000
38.490002,26.801132,-225.651871,-0.002837,0.001924,0.048869,119.217392,6.073223,0.488690,-225.651871,0.049832,0.000000
38.870003,26.557228,-225.651871,-0.002811,0.001940,0.049267,118.132454,6.017954,0.492672,-225.651871,0.050465,0.000000
39.250000,27.986771,-225.740829,-0.002772,0.001979,0.050265,124.491371,6.341893,0.502649,-225.740829,0.051098,0.000000
39.630001,27.929420,-225.740829,-0.002742,0.002000,0.050802,124.236267,6.328897,0.508024,-225.740829,0.051730,0.000000
40.010002,27.598015,-225.785309,-0.002712,0.002024,0.051402,122.762100,6.253799,0.514019,-225.785309,0.052363,0.000000
40.390003,28.667839,-225.874268,-0.002690,0.002052,0.052130,127.520920,6.496225,0.521301,-225.874268,0.052998,0.000000
40.770000,28.076881,-225.874268,-0.002673,0.002065,0.052459,124.892204,6.362312,0.524586,-225.874268,0.053630,0.000000
41.150002,29.645317,-225.874268,-0.002630,0.002102,0.053387,131.868958,6.717725,0.533867,-225.874268,0.054263,0.000000
41.530003,29.455032,-225.829788,-0.002604,0.002122,0.053908,131.022522,6.674606,0.539075,-225.829788,0.054896,0.000000
41.910004,29.719421,-225.963226,-0.002570,0.002149,0.054575,132.198593,6.734517,0.545752,-225.963226,0.055529,0.000000
42.290001,30.429535,-226.007706,-0.002539,0.002177,0.055303,135.357330,6.895431,0.553034,-226.007706,0.056162,0.000000
42.670002,30.093277,-225.963226,-0.002509,0.002194,0.055738,133.861588,6.819234,0.557379,-225.963226,0.056795,0.000000
43.050003,31.229759,-225.963226,-0.002488,0.002227,0.056561,138.916901,7.076765,0.565615,-225.963226,0.057429,0.000000
43.430000,31.194382,-226.096680,-0.002436,0.002249,0.057116,138.759537,7.068748,0.571156,-226.096680,0.058062,0.000000
43.810001,31.184700,-226.141159,-0.002410,0.002271,0.057671,138.716476,7.066554,0.576712,-226.141159,0.058695,0.000000
44.190002,31.975998,-226.185638,-0.002397,0.002300,0.058418,142.236343,7.245864,0.584176,-226.185638,0.059327,0.000000
44.570004,31.967804,-226.141159,-0.002345,0.002320,0.058929,142.199890,7.244008,0.589293,-226.141159,0.059960,0.000000
44.950001,33.243553,-226.185638,-0.002333,0.002355,0.059804,147.874710,7.533097,0.598044,-226.185638,0.060602,0.000000
45.330002,33.035393,-226.230118,-0.002285,0.002375,0.060334,146.948761,7.485927,0.603343,-226.230118,0.061235,0.000000
45.710003,33.165352,-226.319077,-0.002242,0.002399,0.060941,147.526855,7.515377,0.609414,-226.319077,0.061868,0.000000
46.090004,33.595444,-226.319077,-0.002216,0.002426,0.061626,149.440002,7.612836,0.616257,-226.319077,0.062502,0.000000
46.470001,33.570496,-226.319077,-0.002199,0.002447,0.062146,149.329025,7.607183,0.621465,-226.319077,0.063135,0.000000
46.850002,34.524887,-226.363556,-0.002156,0.002479,0.062979,153.574371,7.823452,0.629791,-226.363556,0.063768,0.000000
47.230003,34.483551,-226.452515,-0.002113,0.002502,0.063542,153.390503,7.814084,0.635423,-226.452515,0.064401,0.000000
47.610001,34.330505,-226.497009,-0.002074,0.002523,0.064089,152.709717,7.779404,0.640889,-226.497009,0.065034,0.000000
47.990002,34.766182,-226.497009,-0.002052,0.002550,0.064766,154.647705,7.878129,0.647656,-226.497009,0.065666,0.000000
48.370003,34.973969,-226.452515,-0.002018,0.002573,0.065355,155.571976,7.925214,0.653545,-226.452515,0.066301,0.000000
48.750004,35.894096,-226.541489,-0.001979,0.002603,0.066110,159.664917,8.133718,0.661100,-226.541489,0.066934,0.000000
49.130001,35.739563,-226.585968,-0.001940,0.002623,0.066622,158.977509,8.098701,0.666217,-226.585968,0.067566,0.000000
49.510002,35.849037,-226.674927,-0.001927,0.002649,0.067297,159.464478,8.123508,0.672969,-226.674927,0.068199,0.000000
49.890003,36.432549,-226.674927,-0.001876,0.002676,0.067983,162.060074,8.255733,0.679828,-226.674927,0.068832,0.000000
50.270004,36.203911,-226.719406,-0.001832,0.002700,0.068581,161.043045,8.203923,0.685808,-226.719406,0.069465,0.000000
50.650002,36.857422,-226.674927,-0.001802,0.002728,0.069292,163.949997,8.352012,0.692923,-226.674927,0.070099,0.000000
51.030003,36.927429,-226.763885,-0.001750,0.002750,0.069839,164.261414,8.367875,0.698389,-226.763885,0.070732,0.000000
51.410004,36.860779,-226.852844,-0.001720,0.002774,0.070463,163.964935,8.352773,0.704626,-226.852844,0.071365,0.000000
51.790001,37.070053,-226.852844,-0.001681,0.002797,0.071053,164.895828,8.400194,0.710531,-226.852844,0.071998,0.000000
52.170002,37.156067,-226.852844,-0.001643,0.002821,0.071651,165.278442,8.419684,0.716511,-226.852844,0.072631,0.000000
52.550003,36.262749,-226.852844,-0.001630,0.002834,0.071972,161.304764,8.217256,0.719720,-226.852844,0.073263,0.000000
52.930004,38.408356,-226.941818,-0.001556,0.002877,0.073082,170.848892,8.703458,0.730818,-226.941818,0.073896,0.000000
53.310001,37.604034,-226.986298,-0.001531,0.002893,0.073489,167.271103,8.521195,0.734890,-226.986298,0.074531,0.000000
53.690002,38.589699,-227.075256,-0.001505,0.002927,0.074357,171.655548,8.744551,0.743565,-227.075256,0.075163,0.000000
54.070004,38.348030,-227.030777,-0.001479,0.002947,0.074859,170.580551,8.689788,0.748592,-227.030777,0.075796,0.000000
54.450001,37.849426,-227.030777,-0.001427,0.002963,0.075250,168.362656,8.576803,0.752498,-227.030777,0.076429,0.000000
54.830002,39.166878,-227.119736,-0.001388,0.002998,0.076152,174.222977,8.875341,0.761521,-227.119736,0.077062,0.000000
55.210003,38.978462,-227.164215,-0.001371,0.003020,0.076699,173.384857,8.832646,0.766986,-227.164215,0.077695,0.000000
55.590004,39.598083,-227.208694,-0.001332,0.003049,0.077453,176.141068,8.973054,0.774526,-227.208694,0.078329,0.000000
55.970001,39.826721,-227.119736,-0.001289,0.003070,0.077973,177.158096,9.024864,0.779734,-227.119736,0.078970,0.000000
56.350002,39.564949,-227.297653,-0.001276,0.003088,0.078425,175.993683,8.965546,0.784245,-227.297653,0.079604,0.000000
56.730003,40.909210,-227.297653,-0.001233,0.003123,0.079318,181.973251,9.270160,0.793178,-227.297653,0.080237,0.000000
57.110004,41.117737,-227.386627,-0.001216,0.003147,0.079925,182.900833,9.317412,0.799249,-227.386627,0.080870,0.000000
57.490002,41.620445,-227.386627,-0.001168,0.003175,0.080644,185.136993,9.431328,0.806440,-227.386627,0.081502,0.000000
57.870003,42.148468,-227.386627,-0.001134,0.003196,0.081181,187.485748,9.550980,0.811815,-227.386627,0.082135,0.000000
58.250004,41.592140,-227.431107,-0.001117,0.003211,0.081563,185.011078,9.424913,0.815630,-227.431107,0.082768,0.000000
58.630001,43.529968,-227.520065,-0.001074,0.003251,0.082570,193.630966,9.864032,0.825698,-227.520065,0.083402,0.000000
59.010002,43.351227,-227.520065,-0.001061,0.003271,0.083089,192.835892,9.823528,0.830890,-227.520065,0.084035,0.000000
59.390003,43.683754,-227.520065,-0.001030,0.003296,0.083714,194.315048,9.898880,0.837143,-227.520065,0.084668,0.000000
59.770004,44.403923,-227.520065,-0.000992,0.003320,0.084338,197.518509,10.062073,0.843381,-227.520065,0.085301,0.000000
60.150002,44.452705,-227.609024,-0.000957,0.003338,0.084773,197.735504,10.073127,0.847726,-227.609024,0.085934,0.000000
60.530003,46.262810,-227.653503,-0.000944,0.003374,0.085701,205.787262,10.483302,0.857006,-227.653503,0.086567,0.000000
60.910004,46.525703,-227.653503,-0.000918,0.003397,0.086280,206.956665,10.542874,0.862805,-227.653503,0.087201,0.000000
61.290005,46.468361,-227.742462,-0.000897,0.003414,0.086715,206.701599,10.529881,0.867150,-227.742462,0.087834,0.000000
61.670002,48.105309,-227.653503,-0.000845,0.003449,0.087599,213.983093,10.900819,0.875991,-227.653503,0.088467,0.000000
62.050003,47.950775,-227.786957,-0.000832,0.003463,0.087972,213.295700,10.865801,0.879716,-227.786957,0.089099,0.000000
62.430004,49.677834,-227.786957,-0.000806,0.003498,0.088839,220.978043,11.257158,0.888391,-227.786957,0.089732,0.000000
62.810001,50.107185,-227.786957,-0.000780,0.003519,0.089395,222.887894,11.354450,0.893947,-227.786957,0.090365,0.000000
63.190002,50.932732,-227.786957,-0.000759,0.003546,0.090071,226.560104,11.541522,0.900714,-227.786957,0.090998,0.000000
63.570004,52.153366,-227.920395,-0.000742,0.003573,0.090756,231.989761,11.818121,0.907557,-227.920395,0.091632,0.000000
63.950005,52.367485,-227.920395,-0.000716,0.003591,0.091224,232.942215,11.866642,0.912235,-227.920395,0.092265,0.000000
64.330002,53.974274,-227.964874,-0.000681,0.003623,0.092030,240.089554,12.230745,0.920305,-227.964874,0.092898,0.000000
64.710007,54.896637,-227.964874,-0.000686,0.003646,0.092603,244.192444,12.439755,0.926028,-227.964874,0.093531,0.000000
65.090004,55.432106,-228.009354,-0.000655,0.003667,0.093149,246.574326,12.561095,0.931493,-228.009354,0.094164,0.000000
65.470001,56.947289,-228.053833,-0.000642,0.003696,0.093887,253.314194,12.904440,0.938866,-228.053833,0.094796,0.000000
65.850006,57.954185,-228.098312,-0.000608,0.003718,0.094450,257.793091,13.132607,0.944498,-228.098312,0.095431,0.000000
66.230003,59.602684,-228.187286,-0.000612,0.003750,0.095240,265.125977,13.506161,0.952401,-228.187286,0.096064,0.000000
66.610001,60.769325,-228.142792,-0.000586,0.003773,0.095829,270.315460,13.770527,0.958290,-228.142792,0.096706,0.000000
66.990005,61.641418,-228.187286,-0.000556,0.003795,0.096392,274.194733,13.968145,0.963922,-228.187286,0.097338,0.000000
67.370003,63.156601,-228.231766,-0.000552,0.003822,0.097078,280.934601,14.311490,0.970780,-228.231766,0.097971,0.000000
67.750000,64.204453,-228.320724,-0.000530,0.003845,0.097667,285.595673,14.548937,0.976669,-228.320724,0.098604,0.000000
68.130005,65.908432,-228.320724,-0.000522,0.003874,0.098397,293.175354,14.935064,0.983967,-228.320724,0.099237,0.000000
68.510002,65.093307,-228.365204,-0.000504,0.003869,0.098274,289.549500,14.750354,0.982740,-228.365204,0.017249,0.000000
68.890007,65.888321,-228.409683,-0.000470,0.003833,0.097364,293.085876,14.930507,0.973642,-228.409683,294.500458,0.000000
69.270004,65.433655,-228.454163,-0.000466,0.003892,0.098855,291.063446,14.827478,0.988554,-228.454163,294.500458,0.000000
69.650002,65.207626,-228.454163,-0.000474,0.003900,0.099064,290.058014,14.776259,0.990643,-228.454163,294.500458,0.000000
70.030006,65.298859,-228.543121,-0.000466,0.003910,0.099325,290.463837,14.796933,0.993247,-228.543121,294.500458,0.000000
70.410004,65.303696,-228.498642,-0.000466,0.003918,0.099515,290.485352,14.798029,0.995155,-228.498642,294.500458,0.000000
70.790001,65.153641,-228.543121,-0.000444,0.003924,0.099662,289.817871,14.764026,0.996623,-228.543121,294.500458,0.000000
71.170006,65.495102,-228.543121,-0.000435,0.003933,0.099897,291.336761,14.841402,0.998970,-228.543121,294.500458,0.000000
71.550003,65.313019,-228.632095,-0.000427,0.003936,0.099983,290.526825,14.800141,0.999833,-228.632095,294.500458,0.000000
71.930000,65.273163,-228.676575,-0.000435,0.003942,0.100139,290.349518,14.791110,1.001392,-228.676575,294.500458,0.000000
72.310005,65.301468,-228.676575,-0.000423,0.003947,0.100244,290.475433,14.797524,1.002437,-228.676575,294.500458,0.000000
72.690002,65.248596,-228.676575,-0.000423,0.003951,0.100347,290.240265,14.785542,1.003466,-228.676575,294.500458,0.000000
73.070000,65.308167,-228.721054,-0.000410,0.003955,0.100469,290.505219,14.799042,1.004693,-228.721054,294.500458,0.000000
73.450005,65.280243,-228.810013,-0.000405,0.003959,0.100546,290.381012,14.792715,1.005465,-228.810013,294.500458,0.000000
73.830002,65.093689,-228.810013,-0.000418,0.003960,0.100581,289.551178,14.750442,1.005813,-228.810013,294.500458,0.000000
74.210007,65.715912,-228.810013,-0.000401,0.003968,0.100798,292.318970,14.891438,1.007978,-228.810013,294.500458,0.000000
74.590004,65.404984,-228.854492,-0.000401,0.003968,0.100798,290.935883,14.820981,1.007978,-228.854492,294.500458,0.000000
74.970001,65.195709,-228.943451,-0.000392,0.003970,0.100833,290.005005,14.773559,1.008326,-228.943451,294.500458,0.000000
75.350006,65.225510,-228.987930,-0.000401,0.003973,0.100920,290.137543,14.780312,1.009204,-228.987930,294.500458,0.000000
75.730003,65.120117,-228.987930,-0.000392,0.003976,0.100989,289.668762,14.756430,1.009886,-228.987930,294.500458,0.000000
76.110001,64.994263,-229.076904,-0.000392,0.003977,0.101016,289.108917,14.727910,1.010158,-229.076904,294.500458,0.000000
76.490005,65.323807,-229.076904,-0.000388,0.003982,0.101145,290.574799,14.802586,1.011445,-229.076904,294.500458,0.000000
76.870003,65.165176,-229.121384,-0.000375,0.003982,0.101145,289.869171,14.766640,1.011445,-229.121384,294.500458,0.000000
77.250000,65.775131,-229.121384,-0.000379,0.003991,0.101363,292.582397,14.904858,1.013625,-229.121384,294.500458,0.000000
77.630005,65.607559,-229.210342,-0.000375,0.003991,0.101363,291.837006,14.866885,1.013625,-229.210342,294.500458,0.000000
78.010002,65.461594,-229.165863,-0.000371,0.003991,0.101363,291.187714,14.833809,1.013625,-229.165863,294.500458,0.000000
78.390007,65.273911,-229.254822,-0.000375,0.003991,0.101363,290.352844,14.791280,1.013625,-229.254822,294.500458,0.000000
78.770004,65.683517,-229.210342,-0.000371,0.003998,0.101561,292.174866,14.884098,1.015608,-229.210342,294.500458,0.000000
79.150002,65.623199,-229.388260,-0.000384,0.003998,0.101561,291.906555,14.870430,1.015608,-229.388260,294.500458,0.000000
79.530006,65.506271,-229.343781,-0.000371,0.003998,0.101561,291.386444,14.843933,1.015608,-229.343781,294.500458,0.000000
79.910004,65.391953,-229.388260,-0.000371,0.004000,0.101588,290.877930,14.818028,1.015881,-229.388260,294.500458,0.000000
80.290001,65.378922,-229.432739,-0.000366,0.004002,0.101649,290.819977,14.815075,1.016487,-229.432739,294.500458,0.000000
80.670006,65.421005,-229.432739,-0.000371,0.004004,0.101691,291.007172,14.824612,1.016910,-229.432739,294.500458,0.000000
81.050003,65.397919,-229.432739,-0.000371,0.004005,0.101726,290.904480,14.819380,1.017259,-229.432739,294.500458,0.000000
81.430000,65.426956,-229.521713,-0.000362,0.004006,0.101761,291.033630,14.825960,1.017607,-229.521713,294.500458,0.000000
81.810005,65.402374,-229.566193,-0.000384,0.004008,0.101796,290.924286,14.820390,1.017955,-229.566193,294.500458,0.000000
82.190002,65.417648,-229.566193,-0.000366,0.004009,0.101830,290.992218,14.823851,1.018303,-229.566193,294.500458,0.000000
82.570007,65.345032,-229.610672,-0.000358,0.004010,0.101856,290.669220,14.807396,1.018561,-229.610672,294.500458,0.000000
82.950005,65.390472,-229.655151,-0.000366,0.004011,0.101891,290.871338,14.817693,1.018909,-229.655151,294.500458,0.000000
83.330002,65.365891,-229.744110,-0.000362,0.004012,0.101917,290.761993,14.812122,1.019166,-229.744110,294.500458,0.000000
83.710007,65.423233,-229.699631,-0.000362,0.004013,0.101942,291.017090,14.825116,1.019424,-229.699631,294.500458,0.000000
84.090004,65.433289,-229.699631,-0.000358,0.004015,0.101970,291.061798,14.827395,1.019696,-229.699631,294.500458,0.000000
84.470001,65.451904,-229.744110,-0.000349,0.004016,0.102012,291.144623,14.831614,1.020120,-229.744110,294.500458,0.000000
84.850006,65.441849,-229.833069,-0.000362,0.004017,0.102038,291.099884,14.829334,1.020377,-229.833069,294.500458,0.000000
85.230003,65.400513,-229.877548,-0.000362,0.004018,0.102047,290.916016,14.819968,1.020468,-229.877548,294.500458,0.000000
85.610001,65.431061,-229.877548,-0.000354,0.004019,0.102073,291.051880,14.826890,1.020726,-229.877548,294.500458,0.000000
85.990005,65.437759,-229.833069,-0.000349,0.004020,0.102107,291.081696,14.828408,1.021074,-229.833069,294.500458,0.000000
86.370003,65.393814,-229.922043,-0.000354,0.004021,0.102126,290.886200,14.818450,1.021255,-229.922043,294.500458,0.000000
86.750008,65.386002,-229.966522,-0.000354,0.004021,0.102135,290.851471,14.816680,1.021346,-229.966522,294.500458,0.000000
87.130005,65.374832,-229.966522,-0.000345,0.004025,0.102230,290.801788,14.814149,1.022300,-229.966522,294.500458,0.000000
87.510002,65.523407,-230.011002,-0.000349,0.004025,0.102230,291.462677,14.847816,1.022300,-230.011002,294.500458,0.000000
87.890007,65.490265,-229.966522,-0.000349,0.004025,0.102230,291.315247,14.840306,1.022300,-229.966522,294.500458,0.000000
88.270004,65.428452,-230.099960,-0.000358,0.004025,0.102238,291.040283,14.826300,1.022376,-230.099960,294.500458,0.000000
88.650002,65.379288,-230.099960,-0.000345,0.004026,0.102256,290.821594,14.815159,1.022557,-230.099960,294.500458,0.000000
89.030006,65.389725,-230.188919,-0.000341,0.004026,0.102272,290.868011,14.817523,1.022724,-230.188919,294.500458,0.000000
89.410004,65.361053,-230.144440,-0.000349,0.004027,0.102291,290.740479,14.811027,1.022906,-230.144440,294.500458,0.000000
89.790001,65.378555,-230.233398,-0.000345,0.004029,0.102333,290.818329,14.814992,1.023330,-230.233398,294.500458,0.000000
90.170006,65.405365,-230.188919,-0.000341,0.004029,0.102342,290.937592,14.821068,1.023420,-230.188919,294.500458,0.000000
90.550003,65.371475,-230.322357,-0.000341,0.004029,0.102342,290.786835,14.813388,1.023420,-230.322357,294.500458,0.000000
90.930008,65.320465,-230.366852,-0.000341,0.004030,0.102351,290.559937,14.801828,1.023511,-230.366852,294.500458,0.000000
91.310005,65.304825,-230.366852,-0.000349,0.004030,0.102359,290.490356,14.798285,1.023587,-230.366852,294.500458,0.000000
91.690002,65.441849,-230.366852,-0.000341,0.004033,0.102428,291.099884,14.829334,1.024283,-230.366852,294.500458,0.000000
92.070007,65.443710,-230.411331,-0.000336,0.004033,0.102428,291.108154,14.829757,1.024283,-230.411331,294.500458,0.000000
92.450005,65.412811,-230.455811,-0.000341,0.004033,0.102428,290.970703,14.822755,1.024283,-230.455811,294.500458,0.000000
92.830002,65.361053,-230.455811,-0.000332,0.004033,0.102428,290.740479,14.811027,1.024283,-230.455811,294.500458,0.000000
93.210007,65.327911,-230.589249,-0.000336,0.004033,0.102428,290.593048,14.803516,1.024283,-230.589249,294.500458,0.000000
93.590004,65.288055,-230.500290,-0.000336,0.004033,0.102437,290.415771,14.794485,1.024374,-230.500290,294.500458,0.000000
93.970001,65.270569,-230.589249,-0.000332,0.004034,0.102454,290.337982,14.790523,1.024541,-230.589249,294.500458,0.000000
94.350006,65.217316,-230.633728,-0.000323,0.004034,0.102463,290.101105,14.778456,1.024632,-230.633728,294.500458,0.000000
94.730003,65.251205,-230.678207,-0.000336,0.004036,0.102524,290.251862,14.786135,1.025237,-230.678207,294.500458,0.000000
95.110008,65.351746,-230.678207,-0.000332,0.004037,0.102542,290.699097,14.808917,1.025419,-230.678207,294.500458,0.000000
95.490005,65.351364,-230.767181,-0.000332,0.004037,0.102542,290.697388,14.808831,1.025419,-230.767181,294.500458,0.000000
95.870003,65.321198,-230.722687,-0.000323,0.004037,0.102549,290.563202,14.801995,1.025495,-230.722687,294.500458,0.000000
96.250008,65.302582,-230.767181,-0.000323,0.004037,0.102549,290.480377,14.797776,1.025495,-230.767181,294.500458,0.000000
96.630005,65.265350,-230.856140,-0.000332,0.004037,0.102549,290.314789,14.789339,1.025495,-230.856140,294.500458,0.000000
97.010002,65.248596,-230.900620,-0.000345,0.004038,0.102577,290.240265,14.785542,1.025767,-230.900620,294.500458,0.000000
97.390007,65.255661,-230.900620,-0.000332,0.004039,0.102584,290.271667,14.787145,1.025843,-230.900620,294.500458,0.000000
97.770004,65.238541,-230.900620,-0.000345,0.004039,0.102584,290.195526,14.783265,1.025843,-230.900620,294.500458,0.000000
98.150002,65.208008,-230.945099,-0.000341,0.004039,0.102602,290.059692,14.776345,1.026024,-230.945099,294.500458,0.000000
98.530006,65.330139,-230.945099,-0.000323,0.004043,0.102698,290.602966,14.804021,1.026978,-230.945099,294.500458,0.000000
98.910004,65.490631,-231.034058,-0.000336,0.004043,0.102698,291.316864,14.840389,1.026978,-231.034058,294.500458,0.000000
99.290001,65.504791,-231.078537,-0.000328,0.004043,0.102698,291.379852,14.843598,1.026978,-231.078537,294.500458,0.000000
99.670006,65.481323,-231.034058,-0.000332,0.004043,0.102698,291.275482,14.838281,1.026978,-231.034058,294.500458,0.000000
100.050003,65.434402,-231.078537,-0.000328,0.004043,0.102698,291.066772,14.827648,1.026978,-231.078537,294.500458,0.000000
100.430008,65.393066,-231.167496,-0.000319,0.004043,0.102698,290.882874,14.818280,1.026978,-231.167496,294.500458,0.000000
100.810005,65.357330,-231.211990,-0.000323,0.004044,0.102707,290.723938,14.810183,1.027069,-231.211990,294.500458,0.000000
101.190002,65.321579,-231.211990,-0.000328,0.004044,0.102724,290.564880,14.802081,1.027236,-231.211990,294.500458,0.000000
101.570007,65.323441,-231.256470,-0.000336,0.004045,0.102740,290.573181,14.802504,1.027402,-231.256470,294.500458,0.000000
101.950005,65.343170,-231.256470,-0.000332,0.004046,0.102758,290.660950,14.806974,1.027584,-231.256470,294.500458,0.000000
102.330002,65.348389,-231.389908,-0.000328,0.004046,0.102758,290.684143,14.808156,1.027584,-231.389908,294.500458,0.000000
102.710007,65.328659,-231.389908,-0.000332,0.004046,0.102767,290.596375,14.803686,1.027675,-231.389908,294.500458,0.000000
103.090004,65.313019,-231.389908,-0.000328,0.004046,0.102775,290.526825,14.800141,1.027750,-231.389908,294.500458,0.000000
103.470001,65.302216,-231.389908,-0.000332,0.004047,0.102784,290.478760,14.797693,1.027841,-231.389908,294.500458,0.000000
103.850006,65.317856,-231.389908,-0.000341,0.004047,0.102802,290.548340,14.801237,1.028023,-231.389908,294.500458,0.000000
104.230003,65.318970,-231.478867,-0.000328,0.004047,0.102802,290.553284,14.801490,1.028023,-231.478867,294.500458,0.000000
104.610008,65.311890,-231.523346,-0.000323,0.004048,0.102828,290.521790,14.799886,1.028280,-231.523346,294.500458,0.000000
104.990005,65.331635,-231.612305,-0.000315,0.004049,0.102836,290.609619,14.804359,1.028356,-231.612305,294.500458,0.000000
105.370003,65.326050,-231.612305,-0.000319,0.004049,0.102836,290.584778,14.803094,1.028356,-231.612305,294.500458,0.000000
105.750008,65.313019,-231.567825,-0.000319,0.004049,0.102836,290.526825,14.800141,1.028356,-231.567825,294.500458,0.000000
106.130005,65.305557,-231.656799,-0.000328,0.004049,0.102836,290.493622,14.798450,1.028356,-231.656799,294.500458,0.000000
106.510002,65.292160,-231.745758,-0.000319,0.004049,0.102845,290.434021,14.795415,1.028447,-231.745758,294.500458,0.000000
106.890007,65.290665,-231.745758,-0.000315,0.004049,0.102854,290.427368,14.795076,1.028538,-231.745758,294.500458,0.000000
107.270004,65.272797,-231.790237,-0.000336,0.004050,0.102863,290.347900,14.791027,1.028628,-231.790237,294.500458,0.000000
107.650002,65.277634,-231.834717,-0.000328,0.004050,0.102870,290.369415,14.792123,1.028704,-231.834717,294.500458,0.000000
108.030006,65.277634,-231.790237,-0.000315,0.004050,0.102880,290.369415,14.792123,1.028795,-231.790237,294.500458,0.000000
108.410004,65.250824,-231.879196,-0.000310,0.004050,0.102880,290.250153,14.786048,1.028795,-231.879196,294.500458,0.000000
108.790009,65.261246,-231.879196,-0.000328,0.004050,0.102880,290.296509,14.788410,1.028795,-231.879196,294.500458,0.000000
109.170006,65.250076,-231.923676,-0.000323,0.004052,0.102914,290.246826,14.785879,1.029143,-231.923676,294.500458,0.000000
109.550003,65.295135,-231.923676,-0.000315,0.004052,0.102923,290.447266,14.796089,1.029234,-231.923676,294.500458,0.000000
109.930008,65.315994,-231.968155,-0.000323,0.004053,0.102940,290.540039,14.800816,1.029401,-231.968155,294.500458,0.000000
110.310005,65.317108,-232.012634,-0.000315,0.004053,0.102949,290.545013,14.801068,1.029491,-232.012634,294.500458,0.000000
110.690002,65.307419,-232.101608,-0.000315,0.004053,0.102949,290.501923,14.798873,1.029491,-232.101608,294.500458,0.000000
111.070007,65.300354,-232.101608,-0.000319,0.004053,0.102949,290.470490,14.797272,1.029491,-232.101608,294.500458,0.000000
111.450005,65.292908,-232.101608,-0.000319,0.004053,0.102958,290.437347,14.795585,1.029582,-232.101608,294.500458,0.000000
111.830002,65.275406,-232.101608,-0.000323,0.004053,0.102958,290.359497,14.791618,1.029582,-232.101608,294.500458,0.000000
112.210007,65.289185,-232.146088,-0.000319,0.004054,0.102975,290.420807,14.794741,1.029749,-232.146088,294.500458,0.000000
112.590004,65.309296,-232.279526,-0.000306,0.004055,0.102993,290.510254,14.799298,1.029930,-232.279526,294.500458,0.000000
112.970009,65.301468,-232.324005,-0.000323,0.004055,0.102993,290.475433,14.797524,1.029930,-232.324005,294.500458,0.000000
113.350006,65.304077,-232.368484,-0.000319,0.004055,0.103001,290.487030,14.798116,1.030006,-232.368484,294.500458,0.000000
113.730003,65.307419,-232.324005,-0.000310,0.004056,0.103010,290.501923,14.798873,1.030097,-232.324005,294.500458,0.000000
114.110008,65.321945,-232.324005,-0.000306,0.004056,0.103028,290.566528,14.802165,1.030279,-232.324005,294.500458,0.000000
114.490005,65.340942,-232.412964,-0.000310,0.004057,0.103035,290.651031,14.806470,1.030354,-232.412964,294.500458,0.000000
114.870003,65.355087,-232.412964,-0.000306,0.004057,0.103035,290.713959,14.809674,1.030354,-232.412964,294.500458,0.000000
115.250008,65.345413,-232.457443,-0.000306,0.004057,0.103035,290.670929,14.807483,1.030354,-232.457443,294.500458,0.000000
115.630005,65.338333,-232.501938,-0.000315,0.004057,0.103045,290.639435,14.805878,1.030445,-232.501938,294.500458,0.000000
116.010002,65.327530,-232.501938,-0.000310,0.004057,0.103054,290.591370,14.803431,1.030536,-232.501938,294.500458,0.000000
116.390007,65.317474,-232.590897,-0.000302,0.004057,0.103054,290.546631,14.801151,1.030536,-232.590897,294.500458,0.000000
116.770004,65.313385,-232.635376,-0.000319,0.004058,0.103061,290.528442,14.800224,1.030612,-232.635376,294.500458,0.000000
117.150009,65.343170,-232.679855,-0.000315,0.004058,0.103061,290.660950,14.806974,1.030612,-232.679855,294.500458,0.000000
117.530006,65.330521,-232.679855,-0.000315,0.004058,0.103070,290.604675,14.804107,1.030703,-232.679855,294.500458,0.000000
117.910004,65.330887,-232.635376,-0.000310,0.004058,0.103070,290.606293,14.804191,1.030703,-232.635376,294.500458,0.000000
118.290009,65.304825,-232.724335,-0.000306,0.004058,0.103070,290.490356,14.798285,1.030703,-232.724335,294.500458,0.000000
118.670006,65.305557,-232.768814,-0.000323,0.004058,0.103070,290.493622,14.798450,1.030703,-232.768814,294.500458,0.000000
119.050003,65.294022,-232.857773,-0.000319,0.004060,0.103123,290.442322,14.795836,1.031232,-232.857773,294.500458,0.000000
119.430008,65.365891,-232.813293,-0.000323,0.004060,0.103131,290.761993,14.812122,1.031308,-232.813293,294.500458,0.000000
119.810005,65.379669,-232.857773,-0.000328,0.004060,0.103131,290.823303,14.815245,1.031308,-232.857773,294.500458,0.000000
120.190002,65.385254,-232.902252,-0.000319,0.004060,0.103131,290.848145,14.816510,1.031308,-232.902252,294.500458,0.000000
120.570007,65.366257,-232.991226,-0.000302,0.004060,0.103131,290.763641,14.812205,1.031308,-232.991226,294.500458,0.000000
120.950005,65.375565,-233.035706,-0.000306,0.004060,0.103131,290.805023,14.814314,1.031308,-233.035706,294.500458,0.000000
121.330009,65.345779,-232.946747,-0.000297,0.004061,0.103140,290.672546,14.807566,1.031399,-232.946747,294.500458,0.000000
121.710007,65.333862,-233.035706,-0.000315,0.004061,0.103140,290.619537,14.804865,1.031399,-233.035706,294.500458,0.000000
122.090004,65.326050,-233.080185,-0.000315,0.004061,0.103140,290.584778,14.803094,1.031399,-233.080185,294.500458,0.000000
122.470009,65.323807,-233.080185,-0.000297,0.004061,0.103157,290.574799,14.802586,1.031566,-233.080185,294.500458,0.000000
122.850006,65.325668,-233.213623,-0.000315,0.004061,0.103157,290.583099,14.803008,1.031566,-233.213623,294.500458,0.000000
123.230003,65.334244,-233.213623,-0.000336,0.004062,0.103175,290.621216,14.804952,1.031747,-233.213623,294.500458,0.000000
123.610008,65.352478,-233.258102,-0.000302,0.004062,0.103184,290.702332,14.809083,1.031838,-233.258102,294.500458,0.000000
123.990005,65.352859,-233.258102,-0.000310,0.004062,0.103184,290.704041,14.809170,1.031838,-233.258102,294.500458,0.000000
124.370003,65.338333,-233.347076,-0.000306,0.004062,0.103184,290.639435,14.805878,1.031838,-233.347076,294.500458,0.000000
124.750008,65.340942,-233.347076,-0.000323,0.004062,0.103184,290.651031,14.806470,1.031838,-233.347076,294.500458,0.000000
125.130005,65.326050,-233.347076,-0.000319,0.004062,0.103184,290.584778,14.803094,1.031838,-233.347076,294.500458,0.000000
125.510010,65.339081,-233.347076,-0.000310,0.004063,0.103210,290.642761,14.806047,1.032095,-233.347076,294.500458,0.000000
125.890007,65.366257,-233.391556,-0.000315,0.004064,0.103219,290.763641,14.812205,1.032186,-233.391556,294.500458,0.000000
126.270004,65.361786,-233.480515,-0.000319,0.004064,0.103219,290.743744,14.811193,1.032186,-233.480515,294.500458,0.000000
126.650009,65.359192,-233.524994,-0.000315,0.004064,0.103219,290.732208,14.810605,1.032186,-233.524994,294.500458,0.000000
127.030006,65.353607,-233.524994,-0.000310,0.004064,0.103219,290.707367,14.809340,1.032186,-233.524994,294.500458,0.000000
127.410004,65.346893,-233.480515,-0.000319,0.004064,0.103219,290.677490,14.807817,1.032186,-233.480515,294.500458,0.000000
127.790009,65.344666,-233.524994,-0.000328,0.004064,0.103219,290.667603,14.807313,1.032186,-233.524994,294.500458,0.000000
128.170013,65.330521,-233.569473,-0.000293,0.004064,0.103219,290.604675,14.804107,1.032186,-233.569473,294.500458,0.000000
128.550003,65.325668,-233.702911,-0.000315,0.004064,0.103219,290.583099,14.803008,1.032186,-233.702911,294.500458,0.000000
128.930008,65.355469,-233.747391,-0.000323,0.004061,0.103157,290.715637,14.809761,1.031566,-233.747391,0.103226,0.000000
129.310013,65.206879,-233.702911,-0.000306,0.004050,0.102870,290.054687,14.776090,1.028704,-233.702911,0.102663,0.000000
129.690002,65.243744,-233.702911,-0.000310,0.004030,0.102359,290.218658,14.784444,1.023587,-233.702911,0.102030,0.000000
130.070007,65.149536,-233.747391,-0.000297,0.004009,0.101839,289.799622,14.763096,1.018394,-233.747391,0.101397,0.000000
130.450012,65.094803,-233.791885,-0.000306,0.003988,0.101293,289.556152,14.750693,1.012929,-233.791885,0.100763,0.000000
130.830002,65.104477,-233.880844,-0.000297,0.003956,0.100495,289.599182,14.752885,1.004950,-233.880844,0.100130,0.000000
131.210007,65.034485,-233.836365,-0.000293,0.003936,0.099983,289.287842,14.737025,0.999833,-233.836365,0.099497,0.000000
131.590012,65.022186,-233.836365,-0.000306,0.003915,0.099446,289.233124,14.734238,0.994458,-233.836365,0.098864,0.000000
131.970001,65.033737,-233.925323,-0.000293,0.003891,0.098821,289.284515,14.736856,0.988206,-233.925323,0.098223,0.000000
132.350006,64.962234,-233.969803,-0.000302,0.003865,0.098162,288.966461,14.720654,0.981620,-233.969803,0.097590,0.000000
132.730011,64.919785,-234.058762,-0.000297,0.003843,0.097625,288.777618,14.711034,0.976246,-234.058762,0.096957,0.000000
133.110001,64.770462,-234.058762,-0.000293,0.003820,0.097017,288.113403,14.677197,0.970175,-234.058762,0.096324,0.000000
133.490005,64.319519,-234.058762,-0.000285,0.003799,0.096488,286.107513,14.575011,0.964876,-234.058762,0.095690,0.000000
133.870010,63.283585,-234.058762,-0.000280,0.003768,0.095708,281.499451,14.340265,0.957079,-234.058762,0.095057,0.000000
134.250000,62.386909,-234.103241,-0.000272,0.003752,0.095292,277.510834,14.137075,0.952915,-234.103241,0.094424,0.000000
134.630005,61.070946,-234.192200,-0.000267,0.003727,0.094659,271.657135,13.838874,0.946587,-234.192200,0.093791,0.000000
135.010010,58.827400,-234.192200,-0.000276,0.003698,0.093930,261.677338,13.330480,0.939305,-234.192200,0.093158,0.000000
135.389999,57.551277,-234.192200,-0.000272,0.003684,0.093566,256.000854,13.041306,0.935656,-234.192200,0.092526,0.000000
135.770004,55.836502,-234.236694,-0.000263,0.003667,0.093133,248.373169,12.652733,0.931326,-234.236694,0.091891,0.000000
136.150009,53.289848,-234.370132,-0.000259,0.003639,0.092438,237.045090,12.075652,0.924377,-234.370132,0.091258,0.000000
136.530014,50.029358,-234.325653,-0.000267,0.003608,0.091649,222.541702,11.336815,0.916490,-234.325653,0.090626,0.000000
136.910004,47.066765,-234.370132,-0.000280,0.003581,0.090956,209.363434,10.665482,0.909556,-234.370132,0.089993,0.000000
137.290009,44.651184,-234.325653,-0.000263,0.003558,0.090383,198.618393,10.118103,0.903833,-234.325653,0.089360,0.000000
137.670013,41.947014,-234.370132,-0.000272,0.003536,0.089819,186.589630,9.505329,0.898186,-234.370132,0.088727,0.000000
138.050003,39.433128,-234.414612,-0.000267,0.003510,0.089151,175.407318,8.935675,0.891509,-234.414612,0.088094,0.000000
138.430008,36.389351,-234.548050,-0.000267,0.003485,0.088518,161.867920,8.245945,0.885181,-234.548050,0.087460,0.000000
138.810013,33.333290,-234.548050,-0.000285,0.003455,0.087755,148.273880,7.553432,0.877551,-234.548050,0.086827,0.000000
139.190002,30.989204,-234.503571,-0.000272,0.003434,0.087234,137.846863,7.022254,0.872343,-234.503571,0.086194,0.000000
139.570007,28.482025,-234.548050,-0.000250,0.003411,0.086627,126.694374,6.454119,0.866272,-234.548050,0.085561,0.000000
139.950012,25.757744,-234.681503,-0.000263,0.003385,0.085978,114.576164,5.836788,0.859777,-234.681503,0.084928,0.000000
140.330002,22.830902,-234.725983,-0.000280,0.003359,0.085310,101.556923,5.173556,0.853100,-234.725983,0.084296,0.000000
140.710007,20.310684,-234.681503,-0.000267,0.003333,0.084659,90.346436,4.602467,0.846590,-234.681503,0.083661,0.000000
141.090012,17.526825,-234.681503,-0.000267,0.003309,0.084043,77.963211,3.971635,0.840428,-234.681503,0.083028,0.000000
141.470001,15.483246,-234.681503,-0.000267,0.003290,0.083566,68.872917,3.508554,0.835659,-234.681503,0.082396,0.000000
141.850006,12.322922,-234.725983,-0.000246,0.003259,0.082777,54.815094,2.792414,0.827772,-234.725983,0.081763,0.000000
142.230011,9.330910,-234.814941,-0.000276,0.003233,0.082119,41.505959,2.114414,0.821186,-234.814941,0.081130,0.000000
142.610001,6.738823,-234.859421,-0.000272,0.003206,0.081442,29.975782,1.527039,0.814419,-234.859421,0.080488,0.000000
142.990005,4.009331,-234.770462,-0.000276,0.003182,0.080826,17.834394,0.908527,0.808257,-234.770462,0.079855,0.000000
143.370010,2.057732,-234.859421,-0.000267,0.003163,0.080349,9.153248,0.466289,0.803488,-234.859421,0.079222,0.000000
143.750000,-1.107063,-235.037338,-0.000276,0.003129,0.079481,-4.924463,-0.250864,0.794813,-235.037338,0.078588,0.000000
144.130005,-2.083424,-234.948380,-0.000302,0.003105,0.078874,-9.267531,-0.472111,0.788742,-234.948380,0.077955,0.000000
144.510010,-0.361198,-235.037338,-0.000354,0.003081,0.078267,-1.606691,-0.081849,0.782671,-235.037338,0.077322,0.000000
144.889999,-0.120277,-235.037338,-0.000379,0.003056,0.077618,-0.535021,-0.027255,0.776176,-235.037338,0.076690,0.000000
145.270004,-0.091232,-235.037338,-0.000405,0.003039,0.077192,-0.405822,-0.020674,0.771922,-235.037338,0.076057,0.000000
145.650009,-0.115807,-235.081833,-0.000444,0.003017,0.076629,-0.515133,-0.026242,0.766290,-235.081833,0.075424,0.000000
146.030014,-0.077454,-235.126312,-0.000487,0.002980,0.075701,-0.344531,-0.017551,0.757009,-235.126312,0.074790,0.000000
146.410004,-0.089371,-235.126312,-0.000517,0.002961,0.075206,-0.397541,-0.020252,0.752059,-235.126312,0.074157,0.000000
146.790009,-0.071121,-235.259750,-0.000573,0.002932,0.074478,-0.316363,-0.016116,0.744776,-235.259750,0.073524,0.000000
147.170013,-0.079315,-235.215271,-0.000578,0.002913,0.073984,-0.352812,-0.017973,0.739841,-235.215271,0.072891,0.000000
147.550003,-0.095329,-235.215271,-0.000604,0.002888,0.073359,-0.424046,-0.021602,0.733588,-235.215271,0.072258,0.000000
147.930008,-0.126976,-235.259750,-0.000651,0.002859,0.072631,-0.564817,-0.028773,0.726306,-235.259750,0.071625,0.000000
148.310013,-0.093468,-235.348709,-0.000707,0.002837,0.072049,-0.415765,-0.021180,0.720493,-235.348709,0.070993,0.000000
148.690002,-0.050644,-235.393188,-0.000737,0.002810,0.071374,-0.225275,-0.011476,0.713740,-235.393188,0.070358,0.000000
149.070007,-0.060699,-235.348709,-0.000763,0.002787,0.070784,-0.270005,-0.013755,0.707836,-235.348709,0.069725,0.000000
149.450012,-0.075592,-235.437668,-0.000793,0.002765,0.070237,-0.336250,-0.017129,0.702371,-235.437668,0.069092,0.000000
149.830002,-0.121765,-235.482162,-0.000849,0.002734,0.069439,-0.541638,-0.027592,0.694392,-235.482162,0.068460,0.000000
150.210007,-0.128845,-235.526642,-0.000880,0.002711,0.068858,-0.573132,-0.029197,0.688578,-235.526642,0.067827,0.000000
150.590012,-0.053993,-235.482162,-0.000923,0.002685,0.068190,-0.240174,-0.012235,0.681902,-235.482162,0.067194,0.000000
150.970001,-0.077454,-235.571121,-0.000949,0.002661,0.067592,-0.344531,-0.017551,0.675922,-235.571121,0.066560,0.000000
151.350006,-0.072243,-235.615601,-0.000961,0.002647,0.067236,-0.321352,-0.016370,0.672364,-235.615601,0.065927,0.000000
151.730011,-0.128845,-235.660080,-0.001005,0.002609,0.066257,-0.573132,-0.029197,0.662569,-235.660080,0.065294,0.000000
152.110001,-0.134430,-235.660080,-0.001065,0.002586,0.065675,-0.597974,-0.030462,0.656755,-235.660080,0.064661,0.000000
152.490005,-0.107986,-235.660080,-0.001091,0.002556,0.064922,-0.480348,-0.024470,0.649215,-235.660080,0.064028,0.000000
152.870010,-0.104637,-235.704559,-0.001117,0.002537,0.064445,-0.465449,-0.023711,0.644446,-235.704559,0.063395,0.000000
153.250000,-0.118416,-235.749039,-0.001134,0.002513,0.063838,-0.526740,-0.026833,0.638376,-235.749039,0.062761,0.000000
153.630005,-0.103889,-235.837997,-0.001173,0.002489,0.063221,-0.462123,-0.023542,0.632214,-235.837997,0.062121,0.000000
154.010010,-0.128845,-235.837997,-0.001207,0.002460,0.062475,-0.573132,-0.029197,0.624750,-235.837997,0.061486,0.000000
154.390015,-0.163475,-235.837997,-0.001242,0.002436,0.061868,-0.727173,-0.037044,0.618679,-235.837997,0.060854,0.000000
154.770004,-0.151932,-235.837997,-0.001255,0.002411,0.061244,-0.675826,-0.034428,0.612441,-235.837997,0.060221,0.000000
155.150009,-0.150436,-235.882477,-0.001285,0.002385,0.060567,-0.669175,-0.034089,0.605674,-235.882477,0.059588,0.000000
155.530014,-0.137405,-235.971451,-0.001332,0.002367,0.060116,-0.611210,-0.031137,0.601162,-235.971451,0.058955,0.000000
155.910004,-0.153046,-236.015930,-0.001371,0.002338,0.059379,-0.680781,-0.034681,0.593789,-236.015930,0.058322,0.000000
156.290009,-0.125488,-235.971451,-0.001393,0.002306,0.058574,-0.558200,-0.028436,0.585735,-235.971451,0.057688,0.000000
156.670013,-0.131073,-236.060410,-0.001418,0.002293,0.058243,-0.583042,-0.029702,0.582435,-236.060410,0.057055,0.000000
157.050003,-0.107613,-236.104889,-0.001444,0.002270,0.057662,-0.478685,-0.024385,0.576621,-236.104889,0.057620,0.000000
157.100006,-0.117668,-236.104889,-0.001453,0.002271,0.057671,-0.523414,-0.026664,0.576712,-236.104889,0.057620,0.000000