File: Data/compression 31/ManualNoHeating-17-31-reverse-1-2_11132024_174010.csv
Time (sec),S:Load (lbs),S:HL1 (DIM),S:LVDT (in),S:Position (in),Ch:Position (mm),Ch:Load (N),Ch:Stress (MPa),Ch:Strain (mm/mm),Ch:HL1 (DIM),Set Point (),Cycles ()
0.110000,-0.048409,-154.126495,-0.011076,-0.005751,-0.146085,-0.215332,-0.010970,-1.460848,-154.126495,-0.146015,0.000000
0.460000,-0.035004,-154.215454,-0.011068,-0.005719,-0.145269,-0.155704,-0.007932,-1.452688,-154.215454,-0.144783,0.000000
0.810000,-0.024948,-154.215454,-0.010994,-0.005513,-0.140040,-0.110975,-0.005653,-1.400396,-154.215454,-0.138956,0.000000
1.160000,-0.055115,-154.259933,-0.010766,-0.005280,-0.134125,-0.245163,-0.012489,-1.341246,-154.259933,-0.133128,0.000000
1.510000,-0.128098,-154.259933,-0.010555,-0.005054,-0.128384,-0.569806,-0.029027,-1.283836,-154.259933,-0.127300,0.000000
1.860000,-0.045799,-154.259933,-0.010305,-0.004821,-0.122452,-0.203725,-0.010378,-1.224519,-154.259933,-0.121472,0.000000
2.210000,0.002235,-154.437866,-0.010102,-0.004599,-0.116825,0.009944,0.000507,-1.168246,-154.437866,-0.115627,0.000000
2.560000,-0.006332,-154.393387,-0.009852,-0.004368,-0.110953,-0.028168,-0.001435,-1.109534,-154.393387,-0.109800,0.000000
2.910000,-0.039474,-154.393387,-0.009602,-0.004131,-0.104934,-0.175591,-0.008945,-1.049339,-154.393387,-0.103971,0.000000
3.260000,-0.074844,-154.482346,-0.009386,-0.003906,-0.099211,-0.332924,-0.016960,-0.992112,-154.482346,-0.098144,0.000000
3.610000,-0.123627,-154.482346,-0.009162,-0.003675,-0.093348,-0.549919,-0.028014,-0.933476,-154.482346,-0.092317,0.000000
3.960000,-0.005585,-154.615784,-0.008955,-0.003448,-0.087572,-0.024842,-0.001266,-0.875719,-154.615784,-0.086471,0.000000
4.310000,0.015640,-154.571304,-0.008705,-0.003223,-0.081875,0.069571,0.003544,-0.818748,-154.571304,-0.080642,0.000000
4.660000,-0.012665,-154.660263,-0.008459,-0.002986,-0.075857,-0.056336,-0.002870,-0.758569,-154.660263,-0.074815,0.000000
5.010000,-0.039101,-154.749222,-0.008222,-0.002760,-0.070107,-0.173928,-0.008860,-0.701069,-154.749222,-0.068988,0.000000
5.360000,-0.082298,-154.749222,-0.007981,-0.002528,-0.064210,-0.366081,-0.018649,-0.642100,-154.749222,-0.063159,0.000000
5.710000,-0.054741,-154.793716,-0.007743,-0.002296,-0.058312,-0.243500,-0.012404,-0.583116,-154.793716,-0.057332,0.000000
6.060000,0.000374,-154.838196,-0.007511,-0.002073,-0.052666,0.001663,0.000085,-0.526661,-154.838196,-0.051487,0.000000
6.410000,0.007446,-154.882675,-0.007274,-0.001841,-0.046760,0.033123,0.001687,-0.467601,-154.882675,-0.045659,0.000000
6.760000,-0.012291,-154.927155,-0.007032,-0.001615,-0.041012,-0.054673,-0.002785,-0.410116,-154.927155,-0.039832,0.000000
7.110000,-0.033516,-154.971634,-0.006795,-0.001384,-0.035166,-0.149086,-0.007595,-0.351662,-154.971634,-0.034003,0.000000
7.460001,-0.025322,-155.016113,-0.006545,-0.001145,-0.029095,-0.112638,-0.005738,-0.290952,-155.016113,-0.028176,0.000000
7.810000,-0.043571,-155.060593,-0.006316,-0.000922,-0.023424,-0.193816,-0.009873,-0.234240,-155.060593,-0.022331,0.000000
8.160001,0.018616,-155.105072,-0.006066,-0.000689,-0.017492,0.082807,0.004218,-0.174923,-155.105072,-0.016504,0.000000
8.510000,-0.004845,-155.149551,-0.005859,-0.000466,-0.011838,-0.021550,-0.001098,-0.118376,-155.149551,-0.010675,0.000000
8.860001,-0.007820,-155.283005,-0.005609,-0.000237,-0.006027,-0.034786,-0.001772,-0.060271,-155.283005,-0.004848,0.000000
9.210000,0.031654,-155.238525,-0.005376,-0.000001,-0.000026,0.140806,0.007173,-0.000257,-155.238525,0.000980,0.000000
9.560000,0.143738,-155.238525,-0.005230,-0.000000,-0.000008,0.639378,0.032571,-0.000076,-155.238525,0.000209,0.000000
9.910001,0.137032,-155.283005,-0.005213,-0.000000,-0.000008,0.609547,0.031052,-0.000076,-155.283005,0.000209,0.000000
10.260000,0.152298,-155.416443,-0.005217,0.000000,0.000009,0.677455,0.034511,0.000091,-155.416443,0.000686,0.000000
10.610001,0.162354,-155.460922,-0.005221,0.000015,0.000382,0.722184,0.036790,0.003815,-155.460922,0.001267,0.000000
10.960001,0.295288,-155.460922,-0.005200,0.000041,0.001033,1.313507,0.066913,0.010325,-155.460922,0.001856,0.000000
11.310000,0.490417,-155.549881,-0.005182,0.000064,0.001623,2.181486,0.111130,0.016230,-155.549881,0.002437,0.000000
11.660001,0.672134,-155.505402,-0.005161,0.000082,0.002082,2.989803,0.152308,0.020817,-155.505402,0.003019,0.000000
12.010000,0.976357,-155.594360,-0.005144,0.000112,0.002854,4.343050,0.221246,0.028538,-155.594360,0.003608,0.000000
12.360001,1.191963,-155.683334,-0.005131,0.000134,0.003400,5.302117,0.270103,0.034003,-155.683334,0.004189,0.000000
12.710001,1.509224,-155.683334,-0.005113,0.000155,0.003938,6.713363,0.341995,0.039378,-155.683334,0.004770,0.000000
13.060000,1.960541,-155.772293,-0.005101,0.000179,0.004536,8.720921,0.444265,0.045358,-155.772293,0.005352,0.000000
13.410001,2.232368,-155.727814,-0.005070,0.000195,0.004943,9.930071,0.505862,0.049431,-155.727814,0.005941,0.000000
13.760000,2.913445,-155.861252,-0.005075,0.000226,0.005750,12.959648,0.660196,0.057500,-155.861252,0.006522,0.000000
14.110001,3.435509,-155.861252,-0.005040,0.000251,0.006366,15.281906,0.778497,0.063662,-155.861252,0.007103,0.000000
14.460001,3.806015,-155.905731,-0.005014,0.000270,0.006869,16.930000,0.862455,0.068688,-155.905731,0.007685,0.000000
14.810000,4.401443,-155.950211,-0.004993,0.000294,0.007467,19.578598,0.997381,0.074668,-155.950211,0.008274,0.000000
15.160001,4.945847,-156.039169,-0.004988,0.000316,0.008022,22.000225,1.120745,0.080225,-156.039169,0.008855,0.000000
15.510001,5.512970,-156.083664,-0.004963,0.000335,0.008508,24.522915,1.249257,0.085084,-156.083664,0.009437,0.000000
15.860001,6.181007,-156.128143,-0.004958,0.000364,0.009246,27.494493,1.400636,0.092457,-156.128143,0.010025,0.000000
16.210001,6.550774,-156.128143,-0.004919,0.000382,0.009704,29.139296,1.484426,0.097045,-156.128143,0.010607,0.000000
16.560001,7.148430,-156.128143,-0.004898,0.000407,0.010346,31.797804,1.619857,0.103464,-156.128143,0.011188,0.000000
16.910002,7.706619,-156.306061,-0.004889,0.000430,0.010910,34.280754,1.746345,0.109096,-156.306061,0.011770,0.000000
17.260000,8.134102,-156.261581,-0.004872,0.000449,0.011405,36.182293,1.843214,0.114046,-156.261581,0.012358,0.000000
17.610001,8.418968,-156.350540,-0.004838,0.000465,0.011821,37.449440,1.907765,0.118210,-156.350540,0.012940,0.000000
17.960001,9.486931,-156.395020,-0.004816,0.000503,0.012766,42.199978,2.149769,0.127657,-156.395020,0.013521,0.000000
18.310001,9.648170,-156.483978,-0.004807,0.000520,0.013200,42.917206,2.186307,0.132002,-156.483978,0.014101,0.000000
18.660002,10.088684,-156.528473,-0.004794,0.000540,0.013712,44.876709,2.286128,0.137119,-156.528473,0.014691,0.000000
19.010000,10.959663,-156.528473,-0.004773,0.000570,0.014483,48.751019,2.483495,0.144825,-156.528473,0.015273,0.000000
19.360001,11.273201,-156.528473,-0.004747,0.000588,0.014926,50.145702,2.554544,0.149261,-156.528473,0.015854,0.000000
19.710001,11.866020,-156.661911,-0.004751,0.000613,0.015576,52.782696,2.688879,0.155756,-156.661911,0.016434,0.000000
20.060001,12.208603,-156.661911,-0.004712,0.000636,0.016166,54.306580,2.766509,0.161660,-156.661911,0.017024,0.000000
20.410002,12.599968,-156.706390,-0.004704,0.000655,0.016643,56.047455,2.855194,0.166429,-156.706390,0.017606,0.000000
20.760000,13.417320,-156.750870,-0.004674,0.000684,0.017371,59.683220,3.040408,0.173712,-156.750870,0.018186,0.000000
21.110001,13.396469,-156.839828,-0.004656,0.000699,0.017762,59.590469,3.035683,0.177618,-156.839828,0.018776,0.000000
21.460001,13.744637,-156.928802,-0.004631,0.000716,0.018178,61.139198,3.114579,0.181781,-156.928802,0.019357,0.000000
21.810001,14.685997,-156.928802,-0.004622,0.000748,0.019011,65.326576,3.327894,0.190108,-156.928802,0.019939,0.000000
22.160002,15.139549,-156.973282,-0.004609,0.000771,0.019583,67.344078,3.430671,0.195830,-156.973282,0.020519,0.000000
22.510000,15.351799,-157.017761,-0.004583,0.000791,0.020086,68.288216,3.478767,0.200857,-157.017761,0.021109,0.000000
22.860001,16.152771,-157.062241,-0.004544,0.000820,0.020823,71.851112,3.660270,0.208230,-157.062241,0.021690,0.000000
23.210001,16.298370,-157.106720,-0.004540,0.000836,0.021247,72.498772,3.693264,0.212469,-157.106720,0.022270,0.000000
23.560001,16.345291,-157.151199,-0.004510,0.000853,0.021663,72.707489,3.703896,0.216632,-157.151199,0.022852,0.000000
23.910002,17.419952,-157.195679,-0.004488,0.000887,0.022531,77.487816,3.947418,0.225307,-157.195679,0.023442,0.000000
24.260000,17.591621,-157.284637,-0.004462,0.000908,0.023061,78.251442,3.986318,0.230606,-157.284637,0.024023,0.000000
24.610001,18.132301,-157.329117,-0.004449,0.000932,0.023675,80.656502,4.108838,0.236753,-157.329117,0.024603,0.000000
24.960001,18.690117,-157.240158,-0.004428,0.000957,0.024310,83.137794,4.235241,0.243096,-157.240158,0.025194,0.000000
25.310001,18.575798,-157.373611,-0.004406,0.000971,0.024664,82.629280,4.209336,0.246639,-157.373611,0.025775,0.000000
25.660002,19.614349,-157.462570,-0.004381,0.001003,0.025471,87.248985,4.444675,0.254708,-157.462570,0.026355,0.000000
26.010002,19.750633,-157.507050,-0.004385,0.001023,0.025983,87.855202,4.475557,0.259825,-157.507050,0.026936,0.000000
26.360001,19.977036,-157.551529,-0.004363,0.001043,0.026485,88.862289,4.526861,0.264852,-157.551529,0.027527,0.000000
26.710001,20.708748,-157.596008,-0.004324,0.001071,0.027213,92.117111,4.692669,0.272134,-157.596008,0.028107,0.000000
27.060001,20.896797,-157.551529,-0.004303,0.001093,0.027769,92.953598,4.735282,0.277690,-157.551529,0.028688,0.000000
27.410002,20.838707,-157.640488,-0.004307,0.001110,0.028185,92.695198,4.722118,0.281854,-157.640488,0.029269,0.000000
27.760002,21.870552,-157.684967,-0.004273,0.001142,0.029018,97.285072,4.955938,0.290180,-157.684967,0.029860,0.000000
28.110001,21.679893,-157.729446,-0.004234,0.001159,0.029443,96.436981,4.912734,0.294435,-157.729446,0.030440,0.000000
28.460001,22.402298,-157.773926,-0.004230,0.001185,0.030111,99.650398,5.076433,0.301111,-157.773926,0.031021,0.000000
28.810001,22.742271,-157.818420,-0.004195,0.001209,0.030718,101.162674,5.153472,0.307182,-157.818420,0.031602,0.000000
29.160002,22.734825,-157.951859,-0.004178,0.001226,0.031135,101.129555,5.151785,0.311345,-157.951859,0.032191,0.000000
29.510002,23.491119,-157.907379,-0.004156,0.001255,0.031888,104.493721,5.323164,0.318885,-157.907379,0.032773,0.000000
29.860001,23.796463,-157.951859,-0.004135,0.001278,0.032461,105.851952,5.392355,0.324608,-157.951859,0.033354,0.000000
30.210001,23.833328,-158.040817,-0.004126,0.001299,0.032989,106.015938,5.400710,0.329891,-158.040817,0.033944,0.000000
30.560001,24.397095,-158.174255,-0.004096,0.001325,0.033658,108.523697,5.528461,0.336583,-158.174255,0.034524,0.000000
30.910002,24.468964,-158.174255,-0.004066,0.001346,0.034187,108.843384,5.544746,0.341867,-158.174255,0.035106,0.000000
31.260002,24.014671,-158.174255,-0.004049,0.001354,0.034387,106.822594,5.441803,0.343865,-158.174255,0.035687,0.000000
31.610001,25.492615,-158.263229,-0.004031,0.001396,0.035461,113.396812,5.776709,0.354614,-158.263229,0.036276,0.000000
31.960001,25.342178,-158.263229,-0.004018,0.001414,0.035913,112.727638,5.742620,0.359126,-158.263229,0.036857,0.000000
32.310001,25.661301,-158.307709,-0.003988,0.001438,0.036529,114.147163,5.814934,0.365288,-158.307709,0.037439,0.000000
32.660000,26.070915,-158.352188,-0.003941,0.001462,0.037143,115.969223,5.907754,0.371434,-158.352188,0.038020,0.000000
33.010002,26.041122,-158.441147,-0.003932,0.001480,0.037604,115.836700,5.901002,0.376037,-158.441147,0.038609,0.000000
33.360001,26.797409,-158.396667,-0.003915,0.001511,0.038376,119.200829,6.072380,0.383758,-158.396667,0.039190,0.000000
33.710003,26.950081,-158.530106,-0.003880,0.001533,0.038930,119.879944,6.106976,0.389299,-158.530106,0.039772,0.000000
34.060001,27.069984,-158.530106,-0.003867,0.001554,0.039467,120.413307,6.134146,0.394674,-158.530106,0.040361,0.000000
34.410000,27.452042,-158.663559,-0.003842,0.001577,0.040067,122.112778,6.220722,0.400669,-158.663559,0.040942,0.000000
34.760002,27.360435,-158.663559,-0.003837,0.001594,0.040483,121.705292,6.199964,0.404832,-158.663559,0.041523,0.000000
35.110001,27.777870,-158.752518,-0.003816,0.001624,0.041246,123.562141,6.294555,0.412463,-158.752518,0.042105,0.000000
35.460003,28.602303,-158.708038,-0.003773,0.001651,0.041923,127.229393,6.481375,0.419230,-158.708038,0.042694,0.000000
35.810001,28.469360,-158.796997,-0.003764,0.001670,0.042407,126.638039,6.451249,0.424075,-158.796997,0.043275,0.000000
36.160000,28.831306,-158.885956,-0.003729,0.001693,0.043007,128.248062,6.533267,0.430070,-158.885956,0.043856,0.000000
36.510002,29.028297,-158.885956,-0.003721,0.001714,0.043544,129.124313,6.577906,0.435445,-158.885956,0.044438,0.000000
36.860001,29.215225,-158.974915,-0.003691,0.001735,0.044064,129.955811,6.620265,0.440637,-158.974915,0.045027,0.000000
37.210003,29.957367,-158.974915,-0.003673,0.001764,0.044793,133.257019,6.788436,0.447935,-158.974915,0.045608,0.000000
37.560001,29.968536,-159.019394,-0.003643,0.001781,0.045243,133.306702,6.790967,0.452431,-159.019394,0.046189,0.000000
37.910004,30.333832,-158.974915,-0.003626,0.001806,0.045877,134.931625,6.873744,0.458775,-158.974915,0.046771,0.000000
38.260002,30.677902,-159.063889,-0.003613,0.001830,0.046492,136.462128,6.951712,0.464921,-159.063889,0.047360,0.000000
38.610001,30.708069,-159.152847,-0.003583,0.001848,0.046934,136.596313,6.958548,0.469342,-159.152847,0.047941,0.000000
38.960003,30.528954,-159.241806,-0.003579,0.001864,0.047343,135.799561,6.917960,0.473430,-159.241806,0.048522,0.000000
39.310001,32.066856,-159.241806,-0.003531,0.001902,0.048323,142.640503,7.266453,0.483225,-159.241806,0.049111,0.000000
39.660004,31.818855,-159.286285,-0.003510,0.001920,0.048774,141.537338,7.210256,0.487737,-159.286285,0.049693,0.000000
40.010002,31.878059,-159.330765,-0.003510,0.001940,0.049267,141.800690,7.223671,0.492672,-159.330765,0.050274,0.000000
40.360001,32.994804,-159.330765,-0.003479,0.001971,0.050058,146.768219,7.476729,0.500575,-159.330765,0.050855,0.000000
40.710003,32.843254,-159.419724,-0.003449,0.001986,0.050447,146.094086,7.442388,0.504466,-159.419724,0.051444,0.000000
41.060001,33.467346,-159.464203,-0.003449,0.002012,0.051107,148.870193,7.583809,0.511067,-159.464203,0.052026,0.000000
41.410004,33.937653,-159.553177,-0.003428,0.002036,0.051714,150.962219,7.690382,0.517138,-159.553177,0.052607,0.000000
41.760002,33.927223,-159.508698,-0.003402,0.002056,0.052216,150.915833,7.688019,0.522164,-159.508698,0.053187,0.000000
42.110001,34.959068,-159.642136,-0.003385,0.002084,0.052936,155.505707,7.921838,0.529355,-159.642136,0.053777,0.000000
42.460003,34.633987,-159.642136,-0.003359,0.002101,0.053361,154.059677,7.848174,0.533610,-159.642136,0.054359,0.000000
42.810001,34.677559,-159.642136,-0.003341,0.002117,0.053777,154.253479,7.858047,0.537773,-159.642136,0.054940,0.000000
43.160004,35.840103,-159.731094,-0.003307,0.002148,0.054549,159.424744,8.121484,0.545494,-159.731094,0.055529,0.000000
43.510002,36.158112,-159.775574,-0.003290,0.002171,0.055147,160.839310,8.193545,0.551474,-159.775574,0.056110,0.000000
43.860001,36.415794,-159.775574,-0.003272,0.002192,0.055685,161.985550,8.251938,0.556849,-159.775574,0.056692,0.000000
44.210003,37.488968,-159.864532,-0.003247,0.002220,0.056378,166.759262,8.495122,0.563783,-159.864532,0.057272,0.000000
44.560001,37.254005,-159.953506,-0.003229,0.002235,0.056769,165.714096,8.441878,0.567689,-159.953506,0.057862,0.000000
44.910004,37.624138,-159.953506,-0.003208,0.002263,0.057480,167.360519,8.525751,0.574804,-159.953506,0.058443,0.000000
45.260002,38.584114,-159.997986,-0.003195,0.002286,0.058069,171.630707,8.743286,0.580694,-159.997986,0.059025,0.000000
45.610001,38.832863,-160.042465,-0.003169,0.002306,0.058581,172.737198,8.799652,0.585811,-160.042465,0.059605,0.000000
45.960003,39.304657,-160.131424,-0.003152,0.002330,0.059172,174.835846,8.906563,0.591715,-160.131424,0.060195,0.000000
46.310001,40.171913,-160.175903,-0.003113,0.002356,0.059848,178.693588,9.103086,0.598483,-160.175903,0.060776,0.000000
46.660004,39.729164,-160.175903,-0.003113,0.002370,0.060195,176.724152,9.002757,0.601950,-160.175903,0.061356,0.000000
47.010002,41.229820,-160.175903,-0.003113,0.002403,0.061044,183.399399,9.342811,0.610443,-160.175903,0.061938,0.000000
47.360001,41.344887,-160.309341,-0.003078,0.002424,0.061582,183.911240,9.368885,0.615818,-160.309341,0.062528,0.000000
47.710003,41.392548,-160.264862,-0.003044,0.002442,0.062033,184.123245,9.379685,0.620329,-160.264862,0.063109,0.000000
48.060001,42.508919,-160.353836,-0.003022,0.002472,0.062788,189.089111,9.632659,0.627884,-160.353836,0.063689,0.000000
48.410004,42.778145,-160.353836,-0.003001,0.002494,0.063342,190.286697,9.693666,0.633425,-160.353836,0.064280,0.000000
48.760002,42.532379,-160.398315,-0.002992,0.002513,0.063828,189.193466,9.637975,0.638285,-160.398315,0.064861,0.000000
49.110001,44.427757,-160.487274,-0.002966,0.002543,0.064582,197.624527,10.067473,0.645824,-160.487274,0.065441,0.000000
49.460003,44.285881,-160.487274,-0.002936,0.002559,0.065008,196.993439,10.035324,0.650078,-160.487274,0.066022,0.000000
49.810001,45.217934,-160.576233,-0.002923,0.002586,0.065675,201.139420,10.246530,0.656755,-160.576233,0.066613,0.000000
50.160004,45.814476,-160.620712,-0.002906,0.002609,0.066257,203.792969,10.381708,0.662569,-160.620712,0.067194,0.000000
50.510002,45.812981,-160.709671,-0.002889,0.002624,0.066655,203.786316,10.381370,0.666550,-160.709671,0.067774,0.000000
50.860001,46.970314,-160.754150,-0.002867,0.002655,0.067427,208.934387,10.643625,0.674271,-160.754150,0.068355,0.000000
51.210003,47.732567,-160.798645,-0.002854,0.002676,0.067983,212.325058,10.816355,0.679828,-160.798645,0.068946,0.000000
51.560001,47.970139,-160.709671,-0.002841,0.002698,0.068529,213.381836,10.870189,0.685293,-160.709671,0.069525,0.000000
51.910004,49.064171,-160.754150,-0.002820,0.002725,0.069223,218.248337,11.118100,0.692227,-160.754150,0.070107,0.000000
52.260002,49.343445,-160.932083,-0.002790,0.002745,0.069716,219.490601,11.181384,0.697163,-160.932083,0.070688,0.000000
52.610001,48.635941,-160.843124,-0.002781,0.002753,0.069916,216.343475,11.021062,0.699161,-160.843124,0.071277,0.000000
52.960003,51.186317,-160.932083,-0.002746,0.002795,0.070983,227.688110,11.598986,0.709834,-160.932083,0.071859,0.000000
53.310001,51.258934,-161.021042,-0.002738,0.002813,0.071442,228.011124,11.615440,0.714422,-161.021042,0.072440,0.000000
53.660004,52.098999,-161.065521,-0.002721,0.002838,0.072084,231.747925,11.805802,0.720841,-161.065521,0.073030,0.000000
54.010002,52.926414,-161.110001,-0.002695,0.002862,0.072691,235.428452,11.993298,0.726912,-161.110001,0.073610,0.000000
54.360004,53.084297,-161.110001,-0.002660,0.002879,0.073133,236.130753,12.029074,0.731333,-161.110001,0.074192,0.000000
54.710003,54.462448,-161.154480,-0.002660,0.002910,0.073924,242.261063,12.341368,0.739235,-161.154480,0.074773,0.000000
55.060001,55.003510,-161.287933,-0.002630,0.002932,0.074461,244.667831,12.463973,0.744610,-161.287933,0.075362,0.000000
55.410004,55.413116,-161.287933,-0.002608,0.002953,0.075008,246.489853,12.556791,0.750075,-161.287933,0.075943,0.000000
55.760002,56.175735,-161.332413,-0.002600,0.002977,0.075615,249.882156,12.729604,0.756146,-161.332413,0.076525,0.000000
56.110004,56.429695,-161.332413,-0.002570,0.002997,0.076126,251.011826,12.787152,0.761263,-161.332413,0.077106,0.000000
56.460003,57.492821,-161.421371,-0.002552,0.003024,0.076820,255.740845,13.028059,0.768197,-161.421371,0.077695,0.000000
56.810001,58.846764,-161.421371,-0.002531,0.003050,0.077462,261.763489,13.334867,0.774617,-161.421371,0.078276,0.000000
57.160004,59.151367,-161.465851,-0.002522,0.003069,0.077955,263.118408,13.403891,0.779552,-161.465851,0.078858,0.000000
57.510002,59.989944,-161.510330,-0.002496,0.003093,0.078571,266.848602,13.593916,0.785714,-161.510330,0.079446,0.000000
57.860004,60.487808,-161.599289,-0.002488,0.003114,0.079083,269.063202,13.706734,0.790831,-161.599289,0.080028,0.000000
58.210003,60.989395,-161.643784,-0.002471,0.003133,0.079586,271.294373,13.820395,0.795857,-161.643784,0.080609,0.000000
58.560001,62.398453,-161.732742,-0.002445,0.003163,0.080349,277.562195,14.139692,0.803488,-161.732742,0.081191,0.000000
58.910004,62.802849,-161.732742,-0.002423,0.003180,0.080765,279.361023,14.231328,0.807651,-161.732742,0.081779,0.000000
59.260002,63.725220,-161.777222,-0.002406,0.003205,0.081398,283.463928,14.440342,0.813980,-161.777222,0.082361,0.000000
59.610004,64.331436,-161.777222,-0.002389,0.003226,0.081944,286.160522,14.577712,0.819445,-161.777222,0.082942,0.000000
59.960003,65.024048,-161.821701,-0.002376,0.003246,0.082456,289.241425,14.734660,0.824562,-161.821701,0.083524,0.000000
60.310001,65.090698,-161.955139,-0.002341,0.003263,0.082882,289.537872,14.749763,0.828816,-161.955139,0.084112,0.000000
60.660004,65.908432,-161.910660,-0.002328,0.003280,0.083315,293.175354,14.935064,0.833146,-161.910660,0.014630,0.000000
61.010002,66.197021,-161.999619,-0.002311,0.003278,0.083254,294.459045,15.000460,0.832541,-161.999619,294.500458,0.000000
61.360004,65.549469,-161.999619,-0.002272,0.003306,0.083975,291.578613,14.853722,0.839747,-161.999619,294.500458,0.000000
61.710003,65.351364,-162.088593,-0.002276,0.003319,0.084312,290.697388,14.808831,0.843123,-162.088593,294.500458,0.000000
62.060001,65.167419,-162.088593,-0.002272,0.003333,0.084668,289.879150,14.767148,0.846681,-162.088593,294.500458,0.000000
62.410004,65.343918,-162.133072,-0.002259,0.003348,0.085041,290.664276,14.807143,0.850405,-162.133072,294.500458,0.000000
62.760002,65.240402,-162.266510,-0.002242,0.003356,0.085231,290.203796,14.783687,0.852313,-162.266510,294.500458,0.000000
63.110004,65.517822,-162.222031,-0.002229,0.003372,0.085648,291.437836,14.846551,0.856476,-162.222031,294.500458,0.000000
63.460003,65.290298,-162.266510,-0.002212,0.003380,0.085857,290.425751,14.794993,0.858566,-162.266510,294.500458,0.000000
63.810001,65.103363,-162.355469,-0.002203,0.003391,0.086134,289.594208,14.752633,0.861336,-162.355469,294.500458,0.000000
64.160004,65.735275,-162.399948,-0.002195,0.003400,0.086368,292.405121,14.895826,0.863683,-162.399948,294.500458,0.000000
64.510002,65.457489,-162.533401,-0.002182,0.003415,0.086732,291.169464,14.832879,0.867316,-162.533401,294.500458,0.000000
64.860001,65.101883,-162.488907,-0.002173,0.003423,0.086941,289.587646,14.752297,0.869406,-162.488907,294.500458,0.000000
65.210007,65.234436,-162.533401,-0.002151,0.003433,0.087209,290.177277,14.782334,0.872085,-162.533401,294.500458,0.000000
65.560005,65.045273,-162.622360,-0.002139,0.003441,0.087399,289.335815,14.739470,0.873993,-162.622360,294.500458,0.000000
65.910004,65.205399,-162.711319,-0.002143,0.003451,0.087651,290.048096,14.775755,0.876506,-162.711319,294.500458,0.000000
66.260002,65.321198,-162.622360,-0.002134,0.003471,0.088171,290.563202,14.801995,0.881714,-162.622360,294.500458,0.000000
66.610001,65.012878,-162.755798,-0.002121,0.003468,0.088076,289.191711,14.732129,0.880760,-162.755798,294.500458,0.000000
66.960007,65.213593,-162.800278,-0.002108,0.003475,0.088276,290.084534,14.777611,0.882759,-162.800278,294.500458,0.000000
67.310005,65.218430,-162.844757,-0.002100,0.003487,0.088562,290.106049,14.778708,0.885620,-162.844757,294.500458,0.000000
67.660004,65.333115,-162.889236,-0.002087,0.003497,0.088822,290.616211,14.804696,0.888224,-162.889236,294.500458,0.000000
68.010002,65.324188,-162.889236,-0.002070,0.003506,0.089065,290.576508,14.802672,0.890646,-162.889236,294.500458,0.000000
68.360001,65.009903,-162.978210,-0.002061,0.003512,0.089204,289.178497,14.731455,0.892039,-162.978210,294.500458,0.000000
68.710007,64.877716,-162.978210,-0.002065,0.003518,0.089351,288.590485,14.701500,0.893508,-162.978210,294.500458,0.000000
69.060005,65.790390,-163.067169,-0.002048,0.003528,0.089620,292.650269,14.908316,0.896203,-163.067169,294.500458,0.000000
69.410004,65.634003,-163.156128,-0.002044,0.003541,0.089932,291.954620,14.872878,0.899321,-163.156128,294.500458,0.000000
69.760002,65.051605,-163.245087,-0.002031,0.003544,0.090009,289.363983,14.740905,0.900093,-163.245087,294.500458,0.000000
70.110001,65.253799,-163.245087,-0.002031,0.003552,0.090218,290.263397,14.786722,0.902183,-163.245087,294.500458,0.000000
70.460007,65.280243,-163.245087,-0.002018,0.003559,0.090400,290.381012,14.792715,0.903999,-163.245087,294.500458,0.000000
70.810005,65.301468,-163.289566,-0.002009,0.003567,0.090600,290.475433,14.797524,0.905998,-163.289566,294.500458,0.000000
71.160004,65.057938,-163.423019,-0.001996,0.003572,0.090730,289.392151,14.742340,0.907300,-163.423019,294.500458,0.000000
71.510002,65.273911,-163.334045,-0.002009,0.003580,0.090930,290.352844,14.791280,0.909298,-163.334045,294.500458,0.000000
71.860001,65.183792,-163.423019,-0.001988,0.003586,0.091077,289.951996,14.770859,0.910767,-163.423019,294.500458,0.000000
72.210007,65.209488,-163.511978,-0.001988,0.003593,0.091251,290.066284,14.776682,0.912508,-163.511978,294.500458,0.000000
72.560005,65.489883,-163.556458,-0.001970,0.003601,0.091467,291.313538,14.840219,0.914673,-163.556458,294.500458,0.000000
72.910004,65.120499,-163.556458,-0.001966,0.003604,0.091544,289.670441,14.756516,0.915445,-163.556458,294.500458,0.000000
73.260002,65.150650,-163.645416,-0.001957,0.003610,0.091700,289.804565,14.763348,0.917004,-163.645416,294.500458,0.000000
73.610001,65.221039,-163.645416,-0.001953,0.003617,0.091884,290.117676,14.779299,0.918836,-163.645416,294.500458,0.000000
73.960007,65.113052,-163.778854,-0.001957,0.003622,0.091996,289.637329,14.754828,0.919957,-163.778854,294.500458,0.000000
74.310005,64.963730,-163.734375,-0.001944,0.003626,0.092100,288.973114,14.720992,0.921001,-163.734375,294.500458,0.000000
74.660004,65.132416,-163.867828,-0.001944,0.003633,0.092273,289.723450,14.759216,0.922727,-163.867828,294.500458,0.000000
75.010002,65.139114,-163.867828,-0.001944,0.003639,0.092421,289.753265,14.760735,0.924211,-163.867828,294.500458,0.000000
75.360001,64.756317,-163.867828,-0.001923,0.003642,0.092507,288.050476,14.673991,0.925074,-163.867828,294.500458,0.000000
75.710007,65.171890,-164.001266,-0.001910,0.003650,0.092698,289.899048,14.768161,0.926981,-164.001266,294.500458,0.000000
76.060005,65.861145,-164.001266,-0.001910,0.003656,0.092863,292.964996,14.924349,0.928632,-164.001266,294.500458,0.000000
76.410004,65.310776,-164.001266,-0.001901,0.003656,0.092872,290.516846,14.799634,0.928722,-164.001266,294.500458,0.000000
76.760002,65.486160,-164.045746,-0.001906,0.003683,0.093540,291.296997,14.839376,0.935399,-164.045746,294.500458,0.000000
77.110001,65.911789,-164.090225,-0.001876,0.003660,0.092968,293.190277,14.935825,0.929676,-164.090225,294.500458,0.000000
77.460007,65.374084,-164.223679,-0.001880,0.003661,0.092984,290.798462,14.813979,0.929843,-164.223679,294.500458,0.000000
77.810005,65.645538,-164.223679,-0.001880,0.003683,0.093540,292.005951,14.875492,0.935399,-164.223679,294.500458,0.000000
78.160004,65.170013,-164.312637,-0.001871,0.003683,0.093540,289.890686,14.767735,0.935399,-164.312637,294.500458,0.000000
78.510002,65.895401,-164.312637,-0.001871,0.003699,0.093947,293.117371,14.932111,0.939471,-164.312637,294.500458,0.000000
78.860001,65.478348,-164.357117,-0.001854,0.003695,0.093861,291.262238,14.837605,0.938609,-164.357117,294.500458,0.000000
79.210007,64.963730,-164.401596,-0.001858,0.003699,0.093947,288.973114,14.720992,0.939471,-164.401596,294.500458,0.000000
79.560005,65.429565,-164.446075,-0.001854,0.003706,0.094129,291.045258,14.826551,0.941288,-164.446075,294.500458,0.000000
79.910004,65.091080,-164.446075,-0.001854,0.003708,0.094182,289.539581,14.749849,0.941818,-164.446075,294.500458,0.000000
80.260002,65.131287,-164.579514,-0.001845,0.003712,0.094294,289.718445,14.758961,0.942938,-164.579514,294.500458,0.000000
80.610001,65.052719,-164.579514,-0.001837,0.003716,0.094398,289.368958,14.741157,0.943983,-164.579514,294.500458,0.000000
80.960007,65.608307,-164.623993,-0.001832,0.003726,0.094633,291.840332,14.867055,0.946330,-164.623993,294.500458,0.000000
81.310005,65.289932,-164.668488,-0.001828,0.003726,0.094650,290.424133,14.794909,0.946496,-164.668488,294.500458,0.000000
81.660004,65.349884,-164.712967,-0.001828,0.003733,0.094806,290.690796,14.808496,0.948056,-164.712967,294.500458,0.000000
82.010002,65.557281,-164.712967,-0.001828,0.003739,0.094962,291.613342,14.855493,0.949615,-164.712967,294.500458,0.000000
82.360001,65.340942,-164.757446,-0.001802,0.003739,0.094971,290.651031,14.806470,0.949706,-164.757446,294.500458,0.000000
82.710007,65.275024,-164.846405,-0.001798,0.003742,0.095057,290.357819,14.791532,0.950569,-164.846405,294.500458,0.000000
83.060005,65.313751,-164.846405,-0.001802,0.003747,0.095178,290.530090,14.800307,0.951780,-164.846405,294.500458,0.000000
83.410004,65.305191,-164.890884,-0.001807,0.003751,0.095266,290.492004,14.798368,0.952658,-164.890884,294.500458,0.000000
83.760002,65.244492,-164.979843,-0.001802,0.003753,0.095326,290.221985,14.784614,0.953264,-164.979843,294.500458,0.000000
84.110001,65.020706,-164.979843,-0.001798,0.003755,0.095378,289.226532,14.733903,0.953778,-164.979843,294.500458,0.000000
84.460007,65.384140,-165.024323,-0.001789,0.003761,0.095534,290.843170,14.816257,0.955338,-165.024323,294.500458,0.000000
84.810005,65.241516,-165.113297,-0.001789,0.003764,0.095603,290.208771,14.783938,0.956034,-165.113297,294.500458,0.000000
85.160004,65.138748,-165.113297,-0.001794,0.003766,0.095647,289.751617,14.760652,0.956473,-165.113297,294.500458,0.000000
85.510002,64.938034,-165.157776,-0.001776,0.003768,0.095699,288.858795,14.715169,0.956988,-165.157776,294.500458,0.000000
85.860001,65.151398,-165.202255,-0.001776,0.003773,0.095838,289.807892,14.763517,0.958381,-165.202255,294.500458,0.000000
86.210007,64.942123,-165.246735,-0.001785,0.003774,0.095855,288.876984,14.716096,0.958547,-165.246735,294.500458,0.000000
86.560005,65.845139,-165.291214,-0.001772,0.003785,0.096150,292.893799,14.920721,0.961500,-165.291214,294.500458,0.000000
86.910004,65.573303,-165.380173,-0.001755,0.003785,0.096141,291.684631,14.859122,0.961409,-165.380173,294.500458,0.000000
87.260002,65.304825,-165.424652,-0.001750,0.003785,0.096150,290.490356,14.798285,0.961500,-165.424652,294.500458,0.000000
87.610001,64.997238,-165.424652,-0.001742,0.003785,0.096150,289.122162,14.728585,0.961500,-165.424652,294.500458,0.000000
87.960007,64.681091,-165.469131,-0.001746,0.003785,0.096150,287.715851,14.656944,0.961500,-165.469131,294.500458,0.000000
88.310005,64.404053,-165.558105,-0.001742,0.003785,0.096150,286.483521,14.594167,0.961500,-165.558105,294.500458,0.000000
88.660004,66.869156,-165.602585,-0.001720,0.003613,0.091779,297.448853,15.152767,0.917792,-165.602585,294.500458,0.000000
89.010002,66.405930,-165.558105,-0.001720,0.003614,0.091788,295.388336,15.047799,0.917882,-165.558105,294.500458,0.000000
89.360001,66.119949,-165.647064,-0.001707,0.003614,0.091796,294.116211,14.982995,0.917958,-165.647064,294.500458,0.000000
89.710007,65.858536,-165.647064,-0.001703,0.003621,0.091961,292.953400,14.923758,0.919608,-165.647064,294.500458,0.000000
90.060005,65.512604,-165.736023,-0.001694,0.003691,0.093756,291.414612,14.845367,0.937564,-165.736023,294.500458,0.000000
90.410004,65.272049,-165.824982,-0.001699,0.003768,0.095699,290.344574,14.790857,0.956988,-165.824982,294.500458,0.000000
90.760002,65.367752,-165.824982,-0.001703,0.003805,0.096644,290.770294,14.812545,0.966435,-165.824982,294.500458,0.000000
91.110001,65.251572,-165.913940,-0.001707,0.003808,0.096731,290.253479,14.786218,0.967313,-165.913940,294.500458,0.000000
91.460007,65.332001,-165.824982,-0.001703,0.003813,0.096862,290.611267,14.804443,0.968615,-165.824982,294.500458,0.000000
91.810005,65.243378,-165.913940,-0.001694,0.003816,0.096931,290.217041,14.784361,0.969312,-165.913940,294.500458,0.000000
92.160004,65.213211,-166.002914,-0.001686,0.003819,0.096992,290.082855,14.777525,0.969917,-166.002914,294.500458,0.000000
92.510002,65.323059,-166.047394,-0.001707,0.003822,0.097087,290.571472,14.802417,0.970871,-166.047394,294.500458,0.000000
92.860001,65.210617,-166.136353,-0.001699,0.003823,0.097113,290.071320,14.776937,0.971128,-166.136353,294.500458,0.000000
93.210007,65.226624,-166.091873,-0.001677,0.003829,0.097260,290.142517,14.780564,0.972597,-166.091873,294.500458,0.000000
93.560005,65.343918,-166.180832,-0.001686,0.003829,0.097269,290.664276,14.807143,0.972688,-166.180832,294.500458,0.000000
93.910004,65.207626,-166.180832,-0.001677,0.003830,0.097278,290.058014,14.776259,0.972779,-166.180832,294.500458,0.000000
94.260002,65.327530,-166.225311,-0.001677,0.003834,0.097381,290.591370,14.803431,0.973808,-166.225311,294.500458,0.000000
94.610008,65.217682,-166.269791,-0.001690,0.003835,0.097408,290.102753,14.778538,0.974081,-166.269791,294.500458,0.000000
94.960007,65.167786,-166.314270,-0.001681,0.003837,0.097469,289.880798,14.767232,0.974686,-166.314270,294.500458,0.000000
95.310005,65.087723,-166.358749,-0.001669,0.003840,0.097529,289.524658,14.749088,0.975292,-166.358749,294.500458,0.000000
95.660004,65.070602,-166.403244,-0.001673,0.003841,0.097572,289.448486,14.745210,0.975716,-166.403244,294.500458,0.000000
96.010002,65.055328,-166.447723,-0.001673,0.003843,0.097615,289.380554,14.741748,0.976155,-166.447723,294.500458,0.000000
96.360008,65.650009,-166.536682,-0.001681,0.003852,0.097832,292.025818,14.876505,0.978320,-166.536682,294.500458,0.000000
96.710007,65.515579,-166.536682,-0.001677,0.003850,0.097797,291.427856,14.846043,0.977971,-166.536682,294.500458,0.000000
97.060005,65.313751,-166.625641,-0.001660,0.003850,0.097797,290.530090,14.800307,0.977971,-166.625641,294.500458,0.000000
97.410004,65.116028,-166.670120,-0.001677,0.003850,0.097797,289.650543,14.755503,0.977971,-166.670120,294.500458,0.000000
97.760002,64.947708,-166.714600,-0.001656,0.003850,0.097797,288.901825,14.717361,0.977971,-166.714600,294.500458,0.000000
98.110008,65.878281,-166.759079,-0.001669,0.003874,0.098404,293.041229,14.928232,0.984042,-166.759079,294.500458,0.000000
98.460007,66.225327,-166.759079,-0.001651,0.003853,0.097858,294.584961,15.006874,0.978577,-166.759079,294.500458,0.000000
98.810005,65.973969,-166.848053,-0.001660,0.003853,0.097858,293.466858,14.949915,0.978577,-166.848053,294.500458,0.000000
99.160004,65.783325,-166.892532,-0.001643,0.003853,0.097858,292.618835,14.906714,0.978577,-166.892532,294.500458,0.000000
99.510002,65.561752,-166.937012,-0.001638,0.003853,0.097858,291.633240,14.856505,0.978577,-166.937012,294.500458,0.000000
99.860008,65.314133,-166.981491,-0.001634,0.003853,0.097858,290.531769,14.800394,0.978577,-166.981491,294.500458,0.000000
100.210007,65.118637,-166.937012,-0.001638,0.003853,0.097858,289.662170,14.756094,0.978577,-166.937012,294.500458,0.000000
100.560005,65.810135,-166.981491,-0.001630,0.003872,0.098353,292.738098,14.912789,0.983528,-166.981491,294.500458,0.000000
100.910004,65.598251,-167.114929,-0.001638,0.003872,0.098353,291.795593,14.864777,0.983528,-167.114929,294.500458,0.000000
101.260002,65.427338,-167.159409,-0.001630,0.003872,0.098353,291.035339,14.826047,0.983528,-167.159409,294.500458,0.000000
101.610008,65.264969,-167.203888,-0.001625,0.003872,0.098353,290.313080,14.789253,0.983528,-167.203888,294.500458,0.000000
101.960007,65.068741,-167.203888,-0.001625,0.003872,0.098353,289.440216,14.744787,0.983528,-167.203888,294.500458,0.000000
102.310005,64.915314,-167.292862,-0.001621,0.003872,0.098353,288.757751,14.710021,0.983528,-167.292862,294.500458,0.000000
102.660004,64.738068,-167.337341,-0.001617,0.003872,0.098353,287.969299,14.669856,0.983528,-167.337341,294.500458,0.000000
103.010002,64.578690,-167.426300,-0.001613,0.003872,0.098353,287.260345,14.633740,0.983528,-167.426300,294.500458,0.000000
103.360008,64.417084,-167.381821,-0.001621,0.003872,0.098353,286.541504,14.597119,0.983528,-167.381821,294.500458,0.000000
103.710007,64.246536,-167.470779,-0.001617,0.003872,0.098353,285.782867,14.558474,0.983528,-167.470779,294.500458,0.000000
104.060005,64.090134,-167.470779,-0.001621,0.003872,0.098353,285.087158,14.523031,0.983528,-167.470779,294.500458,0.000000
104.410004,66.540344,-167.515259,-0.001613,0.003684,0.093582,295.986237,15.078258,0.935823,-167.515259,294.500458,0.000000
104.760002,66.313950,-167.604218,-0.001595,0.003685,0.093600,294.979187,15.026956,0.936005,-167.604218,294.500458,0.000000
105.110008,66.119202,-167.604218,-0.001617,0.003685,0.093600,294.112885,14.982825,0.936005,-167.604218,294.500458,0.000000
105.460007,65.947159,-167.648712,-0.001600,0.003688,0.093670,293.347626,14.943840,0.936701,-167.648712,294.500458,0.000000
105.810005,65.797836,-167.737671,-0.001604,0.003713,0.094312,292.683380,14.910003,0.943120,-167.737671,294.500458,0.000000
106.160004,65.601974,-167.737671,-0.001587,0.003766,0.095664,291.812164,14.865620,0.956640,-167.737671,294.500458,0.000000
106.510002,65.515961,-167.826630,-0.001587,0.003838,0.097476,291.429535,14.846128,0.974762,-167.826630,294.500458,0.000000
106.860008,65.373703,-167.826630,-0.001591,0.003857,0.097971,290.796753,14.813893,0.979712,-167.826630,294.500458,0.000000
107.210007,65.373337,-167.915588,-0.001587,0.003880,0.098553,290.795135,14.813809,0.985526,-167.915588,294.500458,0.000000
107.560005,65.189011,-167.915588,-0.001578,0.003881,0.098569,289.975189,14.772040,0.985693,-167.915588,294.500458,0.000000
107.910004,65.378174,-167.960068,-0.001578,0.003892,0.098864,290.816650,14.814906,0.988645,-167.960068,294.500458,0.000000
108.260002,65.267960,-168.004547,-0.001578,0.003893,0.098874,290.326385,14.789931,0.988736,-168.004547,294.500458,0.000000
108.610008,65.116776,-168.093521,-0.001587,0.003893,0.098874,289.653870,14.755672,0.988736,-168.093521,294.500458,0.000000
108.960007,65.025543,-168.093521,-0.001587,0.003894,0.098916,289.248077,14.734999,0.989160,-168.093521,294.500458,0.000000
109.310005,65.023300,-168.138000,-0.001587,0.003897,0.098986,289.238098,14.734490,0.989856,-168.138000,294.500458,0.000000
109.660004,65.019958,-168.182480,-0.001582,0.003899,0.099030,289.223206,14.733733,0.990295,-168.182480,294.500458,0.000000
110.010002,64.993515,-168.271439,-0.001574,0.003900,0.099072,289.105591,14.727740,0.990719,-168.271439,294.500458,0.000000
110.360008,64.991287,-168.271439,-0.001600,0.003903,0.099132,289.095673,14.727236,0.991325,-168.271439,294.500458,0.000000
110.710007,65.847733,-168.271439,-0.001574,0.003914,0.099419,292.905334,14.921309,0.994186,-168.271439,294.500458,0.000000
111.060005,65.781830,-168.404877,-0.001578,0.003914,0.099419,292.612183,14.906376,0.994186,-168.404877,294.500458,0.000000
111.410004,65.671600,-168.449356,-0.001587,0.003914,0.099419,292.121857,14.881397,0.994186,-168.449356,294.500458,0.000000
111.760002,65.569199,-168.493835,-0.001591,0.003914,0.099419,291.666351,14.858193,0.994186,-168.493835,294.500458,0.000000
112.110008,65.474991,-168.493835,-0.001587,0.003914,0.099419,291.247314,14.836845,0.994186,-168.493835,294.500458,0.000000
112.460007,65.339828,-168.538330,-0.001561,0.003914,0.099419,290.646088,14.806217,0.994186,-168.538330,294.500458,0.000000
112.810005,65.254929,-168.538330,-0.001565,0.003914,0.099428,290.268433,14.786978,0.994277,-168.538330,294.500458,0.000000
113.160004,65.134277,-168.627289,-0.001569,0.003914,0.099428,289.731750,14.759639,0.994277,-168.627289,294.500458,0.000000
113.510002,65.024048,-168.716248,-0.001591,0.003914,0.099428,289.241425,14.734660,0.994277,-168.716248,294.500458,0.000000
113.860008,64.920898,-168.671768,-0.001587,0.003914,0.099428,288.782593,14.711287,0.994277,-168.671768,294.500458,0.000000
114.210007,65.882736,-168.805206,-0.001574,0.003926,0.099723,293.061035,14.929241,0.997229,-168.805206,294.500458,0.000000
114.560005,65.786301,-168.760727,-0.001578,0.003926,0.099723,292.632080,14.907389,0.997229,-168.760727,294.500458,0.000000
114.910004,65.686508,-168.849686,-0.001578,0.003926,0.099723,292.188171,14.884775,0.997229,-168.849686,294.500458,0.000000
115.260002,65.579254,-168.849686,-0.001582,0.003926,0.099723,291.711090,14.860472,0.997229,-168.849686,294.500458,0.000000
115.610008,65.511490,-168.938660,-0.001569,0.003926,0.099723,291.409668,14.845116,0.997229,-168.938660,294.500458,0.000000
115.960007,65.378922,-168.983139,-0.001574,0.003926,0.099723,290.819977,14.815075,0.997229,-168.983139,294.500458,0.000000
116.310005,65.272797,-169.027618,-0.001578,0.003926,0.099723,290.347900,14.791027,0.997229,-169.027618,294.500458,0.000000
116.660004,65.202423,-169.072098,-0.001578,0.003926,0.099723,290.034851,14.775080,0.997229,-169.072098,294.500458,0.000000
117.010002,65.088104,-169.072098,-0.001578,0.003926,0.099723,289.526337,14.749176,0.997229,-169.072098,294.500458,0.000000
117.360008,65.017349,-169.161057,-0.001574,0.003926,0.099732,289.211609,14.733142,0.997320,-169.161057,294.500458,0.000000
117.710007,64.927612,-169.250015,-0.001574,0.003926,0.099732,288.812439,14.712808,0.997320,-169.250015,294.500458,0.000000
118.060005,66.010834,-169.161057,-0.001565,0.003933,0.099905,293.630859,14.958269,0.999046,-169.161057,294.500458,0.000000
118.410004,65.865616,-169.205536,-0.001561,0.003933,0.099905,292.984894,14.925363,0.999046,-169.205536,294.500458,0.000000
118.760002,65.841782,-169.250015,-0.001574,0.003933,0.099905,292.878876,14.919961,0.999046,-169.250015,294.500458,0.000000
119.110008,65.713318,-169.250015,-0.001556,0.003933,0.099905,292.307434,14.890851,0.999046,-169.250015,294.500458,0.000000
119.460007,65.582245,-169.338974,-0.001565,0.003933,0.099905,291.724396,14.861149,0.999046,-169.338974,294.500458,0.000000
119.810005,65.495468,-169.427948,-0.001556,0.003933,0.099905,291.338379,14.841485,0.999046,-169.427948,294.500458,0.000000
120.160004,65.364395,-169.472427,-0.001565,0.003933,0.099905,290.755341,14.811783,0.999046,-169.472427,294.500458,0.000000
120.510002,65.263489,-169.516907,-0.001569,0.003933,0.099905,290.306488,14.788918,0.999046,-169.516907,294.500458,0.000000
120.860008,65.157730,-169.516907,-0.001569,0.003933,0.099905,289.836060,14.764953,0.999046,-169.516907,294.500458,0.000000
121.210007,65.056824,-169.605865,-0.001574,0.003933,0.099905,289.387207,14.742087,0.999046,-169.605865,1681.640747,0.000000
121.560005,64.951065,-169.605865,-0.001556,0.003926,0.099714,288.916779,14.718122,0.997138,-169.605865,0.099472,0.000000
121.910004,64.780518,-169.605865,-0.001556,0.003910,0.099307,288.158142,14.679475,0.993066,-169.605865,0.098890,0.000000
122.260002,64.611832,-169.694824,-0.001548,0.003885,0.098683,287.407776,14.641251,0.986828,-169.694824,0.098301,0.000000
122.610008,64.454697,-169.739304,-0.001574,0.003868,0.098248,286.708801,14.605643,0.982483,-169.739304,0.097720,0.000000
122.960007,64.367187,-169.739304,-0.001556,0.003851,0.097806,286.319550,14.585814,0.978062,-169.739304,0.097139,0.000000
123.310005,64.237595,-169.872757,-0.001578,0.003833,0.097364,285.743103,14.556447,0.973642,-169.872757,0.096548,0.000000
123.660004,64.142273,-169.828278,-0.001565,0.003807,0.096696,285.319092,14.534847,0.966965,-169.828278,0.095968,0.000000
124.010002,64.079712,-169.872757,-0.001561,0.003781,0.096038,285.040802,14.520670,0.960379,-169.872757,0.095387,0.000000
124.360008,63.922577,-169.961716,-0.001548,0.003763,0.095578,284.341827,14.485063,0.955777,-169.961716,0.094806,0.000000
124.710007,63.837296,-169.961716,-0.001561,0.003745,0.095127,283.962463,14.465737,0.951265,-169.961716,0.094217,0.000000
125.060005,63.753510,-170.050674,-0.001552,0.003721,0.094519,283.589783,14.446753,0.945194,-170.050674,0.093635,0.000000
125.410004,63.421738,-170.095154,-0.001535,0.003697,0.093912,282.113983,14.371571,0.939123,-170.095154,0.093054,0.000000
125.760010,62.723160,-170.095154,-0.001535,0.003671,0.093236,279.006561,14.213271,0.932356,-170.095154,0.092473,0.000000
126.110008,62.068527,-170.139633,-0.001548,0.003652,0.092751,276.094604,14.064929,0.927511,-170.139633,0.091884,0.000000
126.460007,60.662079,-170.184113,-0.001526,0.003625,0.092082,269.838409,13.746223,0.920820,-170.184113,0.091302,0.000000
126.810005,59.743065,-170.228607,-0.001522,0.003612,0.091744,265.750427,13.537972,0.917443,-170.228607,0.090721,0.000000
127.160004,58.267349,-170.184113,-0.001526,0.003592,0.091242,259.186127,13.203569,0.912417,-170.184113,0.090140,0.000000
127.510010,55.946724,-170.317566,-0.001518,0.003562,0.090479,248.863464,12.677709,0.904787,-170.317566,0.089551,0.000000
127.860008,53.851387,-170.406525,-0.001513,0.003540,0.089906,239.542938,12.202899,0.899064,-170.406525,0.088969,0.000000
128.210007,52.263222,-170.362045,-0.001518,0.003524,0.089498,232.478424,11.843015,0.894976,-170.362045,0.088388,0.000000
128.560013,49.365044,-170.406525,-0.001505,0.003496,0.088795,219.586685,11.186279,0.887951,-170.406525,0.087799,0.000000
128.910004,47.649521,-170.451004,-0.001509,0.003483,0.088458,211.955658,10.797536,0.884575,-170.451004,0.087218,0.000000
129.260010,45.149040,-170.495483,-0.001513,0.003458,0.087841,200.832962,10.230919,0.878414,-170.495483,0.086636,0.000000
129.610001,41.978661,-170.584442,-0.001518,0.003428,0.087062,186.730408,9.512501,0.870617,-170.584442,0.086055,0.000000
129.960007,39.296837,-170.584442,-0.001509,0.003404,0.086471,174.801056,8.904791,0.864712,-170.584442,0.085466,0.000000
130.310013,37.245064,-170.673416,-0.001526,0.003382,0.085899,165.674316,8.439853,0.858989,-170.673416,0.084885,0.000000
130.660004,34.480202,-170.673416,-0.001505,0.003357,0.085275,153.375595,7.813325,0.852752,-170.673416,0.084303,0.000000
131.010010,32.826866,-170.673416,-0.001513,0.003342,0.084876,146.021194,7.438674,0.848755,-170.673416,0.083722,0.000000
131.360001,30.057159,-170.762375,-0.001518,0.003314,0.084173,133.700928,6.811049,0.841730,-170.762375,0.083133,0.000000
131.710007,27.579391,-170.806854,-0.001509,0.003289,0.083531,122.679260,6.249579,0.835311,-170.806854,0.082552,0.000000
132.060013,25.371597,-170.806854,-0.001509,0.003272,0.083098,112.858498,5.749286,0.830981,-170.806854,0.081970,0.000000
132.410004,22.586624,-170.895813,-0.001505,0.003243,0.082379,100.470322,5.118202,0.823790,-170.895813,0.081381,0.000000
132.760010,20.752686,-170.984772,-0.001526,0.003227,0.081970,92.312553,4.702626,0.819702,-170.984772,0.080800,0.000000
133.110001,18.726982,-170.984772,-0.001509,0.003208,0.081486,83.301773,4.243595,0.814858,-170.984772,0.080219,0.000000
133.460007,15.750984,-170.984772,-0.001526,0.003180,0.080765,70.063873,3.569224,0.807651,-170.984772,0.079637,0.000000
133.810013,12.945900,-171.073730,-0.001518,0.003151,0.080037,57.586239,2.933583,0.800369,-171.073730,0.079048,0.000000
134.160004,11.517853,-171.073730,-0.001500,0.003132,0.079551,51.233967,2.609983,0.795509,-171.073730,0.078467,0.000000
134.510010,9.086632,-171.162704,-0.001526,0.003110,0.079004,40.419357,2.059060,0.790044,-171.162704,0.077886,0.000000
134.860001,7.149178,-171.162704,-0.001518,0.003091,0.078520,31.801130,1.620027,0.785199,-171.162704,0.077306,0.000000
135.210007,5.009529,-171.251663,-0.001522,0.003067,0.077904,22.283499,1.135176,0.779037,-171.251663,0.076715,0.000000
135.560013,2.252106,-171.251663,-0.001518,0.003038,0.077157,10.017866,0.510334,0.771574,-171.251663,0.076134,0.000000
135.910004,0.612549,-171.340622,-0.001509,0.003018,0.076664,2.724753,0.138806,0.766638,-171.340622,0.075553,0.000000
136.260010,-1.861862,-171.340622,-0.001513,0.002988,0.075901,-8.281977,-0.421904,0.759008,-171.340622,0.074973,0.000000
136.610001,-2.314667,-171.385101,-0.001509,0.002978,0.075631,-10.296152,-0.524511,0.756313,-171.385101,0.074382,0.000000
136.960007,-0.343704,-171.429581,-0.001518,0.002952,0.074973,-1.528873,-0.077884,0.749727,-171.429581,0.073801,0.000000
137.310013,-0.126976,-171.474060,-0.001505,0.002925,0.074296,-0.564817,-0.028773,0.742960,-171.474060,0.073221,0.000000
137.660004,-0.058090,-171.474060,-0.001518,0.002900,0.073654,-0.258398,-0.013163,0.736541,-171.474060,0.072631,0.000000
138.010010,-0.012665,-171.563034,-0.001509,0.002874,0.072995,-0.056336,-0.002870,0.729955,-171.563034,0.072049,0.000000
138.360001,-0.026070,-171.563034,-0.001492,0.002857,0.072579,-0.115964,-0.005907,0.725791,-171.563034,0.071469,0.000000
138.710007,-0.024208,-171.696472,-0.001513,0.002835,0.072014,-0.107683,-0.005486,0.720144,-171.696472,0.070888,0.000000
139.060013,-0.057343,-171.651993,-0.001500,0.002806,0.071270,-0.255072,-0.012994,0.712696,-171.651993,0.070298,0.000000
139.410004,-0.030907,-171.740952,-0.001500,0.002788,0.070827,-0.137480,-0.007004,0.708275,-171.740952,0.069716,0.000000
139.760010,-0.056976,-171.829910,-0.001500,0.002765,0.070228,-0.253443,-0.012911,0.702280,-171.829910,0.069136,0.000000
140.110001,-0.081177,-171.785431,-0.001500,0.002733,0.069413,-0.361092,-0.018395,0.694135,-171.785431,0.068555,0.000000
140.460007,-0.065910,-171.829910,-0.001509,0.002720,0.069083,-0.293184,-0.014935,0.690834,-171.829910,0.067965,0.000000
140.810013,-0.083038,-171.918869,-0.001492,0.002700,0.068572,-0.369373,-0.018817,0.685717,-171.918869,0.067385,0.000000
141.160004,-0.083786,-171.918869,-0.001513,0.002684,0.068164,-0.372699,-0.018986,0.681644,-171.918869,0.066803,0.000000
141.510010,-0.136658,-172.052322,-0.001513,0.002653,0.067376,-0.607884,-0.030967,0.673757,-172.052322,0.066222,0.000000
141.860001,-0.159378,-172.052322,-0.001531,0.002629,0.066769,-0.708949,-0.036116,0.667686,-172.052322,0.065632,0.000000
142.210007,-0.177254,-172.052322,-0.001548,0.002600,0.066040,-0.788464,-0.040166,0.660404,-172.052322,0.065052,0.000000
142.560013,-0.181343,-172.052322,-0.001544,0.002583,0.065615,-0.806654,-0.041093,0.656149,-172.052322,0.064470,0.000000
142.900009,-0.128471,-172.141281,-0.001544,0.002562,0.065068,-0.571469,-0.029112,0.650684,-172.141281,0.064982,0.000000