File: Data/compression 31/ManualNoHeating-17-31-reverse-1-1_11132024_173611.csv
Time (sec),S:Load (lbs),S:HL1 (DIM),S:LVDT (in),S:Position (in),Ch:Position (mm),Ch:Load (N),Ch:Stress (MPa),Ch:Strain (mm/mm),Ch:HL1 (DIM),Set Point (),Cycles ()
0.110000,-0.012665,-117.474190,-0.005618,-0.005633,-0.143083,-0.056336,-0.002870,-1.430827,-117.474190,-0.143057,0.000000
0.490000,-0.011543,-117.563156,-0.005631,-0.005585,-0.141861,-0.051347,-0.002616,-1.418609,-117.563156,-0.141358,0.000000
0.870000,0.021599,-117.652115,-0.005532,-0.005356,-0.136041,0.096076,0.004894,-1.360412,-117.652115,-0.135027,0.000000
1.250000,0.121017,-117.652115,-0.005295,-0.000007,-0.000182,0.538313,0.027423,-0.001817,-117.652115,-0.000000,0.000000
1.630000,0.101288,-117.741081,-0.005307,-0.000008,-0.000191,0.450551,0.022952,-0.001908,-117.741081,-0.000000,0.000000
2.010000,0.135918,-117.785561,-0.005299,-0.000008,-0.000191,0.604592,0.030799,-0.001908,-117.785561,0.000521,0.000000
2.390000,0.108734,-117.830040,-0.005295,-0.000008,-0.000191,0.483674,0.024640,-0.001908,-117.830040,0.001154,0.000000
2.770000,0.240921,-117.918999,-0.005286,0.000041,0.001040,1.071670,0.054593,0.010401,-117.918999,0.001786,0.000000
3.150000,0.374603,-118.007965,-0.005277,0.000063,0.001596,1.666319,0.084886,0.015957,-118.007965,0.002419,0.000000
3.530000,0.464722,-118.141403,-0.005247,0.000078,0.001977,2.067185,0.105307,0.019772,-118.141403,0.003052,0.000000
3.910000,0.748840,-118.141403,-0.005221,0.000118,0.002992,3.331008,0.169690,0.029916,-118.141403,0.003686,0.000000
4.290000,0.878426,-118.141403,-0.005195,0.000137,0.003468,3.907432,0.199054,0.034685,-118.141403,0.004319,0.000000
4.670000,1.194572,-118.319328,-0.005174,0.000163,0.004145,5.313724,0.270694,0.041452,-118.319328,0.004952,0.000000
5.050000,1.569923,-118.319328,-0.005148,0.000189,0.004813,6.983368,0.355750,0.048129,-118.319328,0.005585,0.000000
5.430000,1.849945,-118.452774,-0.005144,0.000206,0.005229,8.228967,0.419204,0.052292,-118.452774,0.006218,0.000000
5.810000,2.490051,-118.452774,-0.005122,0.000242,0.006157,11.076302,0.564254,0.061573,-118.452774,0.006851,0.000000
6.190000,2.726135,-118.586212,-0.005101,0.000261,0.006634,12.126455,0.617751,0.066342,-118.586212,0.007483,0.000000
6.570000,3.289536,-118.541733,-0.005075,0.000287,0.007293,14.632585,0.745419,0.072927,-118.541733,0.008118,0.000000
6.950000,3.891289,-118.630699,-0.005040,0.000314,0.007969,17.309317,0.881779,0.079695,-118.630699,0.008751,0.000000
7.330000,4.336647,-118.764137,-0.005036,0.000332,0.008421,19.290369,0.982698,0.084206,-118.764137,0.009384,0.000000
7.710001,5.069481,-118.764137,-0.005010,0.000366,0.009297,22.550177,1.148761,0.092972,-118.764137,0.010016,0.000000
8.090000,5.491745,-118.853104,-0.004984,0.000388,0.009851,24.428501,1.244447,0.098513,-118.853104,0.010649,0.000000
8.470000,6.203728,-118.942062,-0.004971,0.000415,0.010546,27.595560,1.405785,0.105462,-118.942062,0.011291,0.000000
8.850000,6.773453,-118.986542,-0.004937,0.000440,0.011179,30.129822,1.534886,0.111791,-118.986542,0.011924,0.000000
9.230000,7.277649,-119.075508,-0.004928,0.000459,0.011647,32.372601,1.649139,0.116469,-119.075508,0.012557,0.000000
9.610001,8.089417,-119.075508,-0.004928,0.000490,0.012454,35.983521,1.833088,0.124538,-119.075508,0.013191,0.000000
9.990001,8.426414,-119.119987,-0.004876,0.000513,0.013043,37.482563,1.909453,0.130427,-119.119987,0.013824,0.000000
10.370001,8.858368,-119.253433,-0.004872,0.000534,0.013573,39.403988,2.007335,0.135726,-119.253433,0.014457,0.000000
10.750001,9.618752,-119.342392,-0.004850,0.000562,0.014275,42.786343,2.179640,0.142751,-119.342392,0.015090,0.000000
11.130000,9.849625,-119.342392,-0.004829,0.000586,0.014882,43.813320,2.231957,0.148822,-119.342392,0.015722,0.000000
11.510000,10.767525,-119.475838,-0.004820,0.000615,0.015610,47.896343,2.439956,0.156104,-119.475838,0.016355,0.000000
11.890000,11.091484,-119.520317,-0.004769,0.000637,0.016192,49.337387,2.513366,0.161918,-119.520317,0.016990,0.000000
12.270000,11.381561,-119.564796,-0.004769,0.000658,0.016720,50.627712,2.579099,0.167202,-119.564796,0.017622,0.000000
12.650001,12.401489,-119.653755,-0.004743,0.000688,0.017483,55.164577,2.810218,0.174832,-119.653755,0.018255,0.000000
13.030001,12.437614,-119.787201,-0.004734,0.000709,0.018021,55.325272,2.818404,0.180206,-119.787201,0.018888,0.000000
13.410001,12.541878,-119.787201,-0.004708,0.000719,0.018264,55.789059,2.842030,0.182644,-119.787201,0.019521,0.000000
13.790001,13.867523,-119.876160,-0.004669,0.000761,0.019321,61.685825,3.142426,0.193211,-119.876160,0.020154,0.000000
14.170001,14.069351,-119.920647,-0.004661,0.000785,0.019937,62.583599,3.188160,0.199373,-119.920647,0.020788,0.000000
14.550001,14.650246,-120.054085,-0.004648,0.000811,0.020588,65.167549,3.319793,0.205883,-120.054085,0.021421,0.000000
14.930000,14.644661,-120.009605,-0.004609,0.000826,0.020970,65.142708,3.318527,0.209698,-120.009605,0.022054,0.000000
15.310000,14.858406,-120.143051,-0.004592,0.000842,0.021386,66.093491,3.366963,0.213862,-120.143051,0.022687,0.000000
15.690001,15.712997,-120.098564,-0.004570,0.000877,0.022270,69.894905,3.560616,0.222703,-120.098564,0.023319,0.000000
16.070002,16.305069,-120.320976,-0.004540,0.000906,0.023017,72.528572,3.694781,0.230167,-120.320976,0.023952,0.000000
16.450001,16.641327,-120.365456,-0.004536,0.000930,0.023624,74.024323,3.770978,0.236238,-120.365456,0.024587,0.000000
16.830000,17.154083,-120.409935,-0.004501,0.000953,0.024213,76.305176,3.887171,0.242127,-120.409935,0.025220,0.000000
17.210001,17.103065,-120.409935,-0.004484,0.000968,0.024594,76.078232,3.875610,0.245942,-120.409935,0.025852,0.000000
17.590000,18.484566,-120.498894,-0.004449,0.001011,0.025678,82.223457,4.188663,0.256782,-120.498894,0.026485,0.000000
17.970001,18.353493,-120.632339,-0.004437,0.001029,0.026148,81.640411,4.158961,0.261476,-120.632339,0.027118,0.000000
18.350000,18.735916,-120.676819,-0.004419,0.001056,0.026832,83.341515,4.245619,0.268319,-120.676819,0.027751,0.000000
18.730001,19.237129,-120.676819,-0.004376,0.001080,0.027439,85.571022,4.359196,0.274390,-120.676819,0.028384,0.000000
19.110001,19.094513,-120.676819,-0.004372,0.001095,0.027820,84.936638,4.326879,0.278205,-120.676819,0.029018,0.000000
19.490002,20.216469,-120.810265,-0.004342,0.001131,0.028723,89.927345,4.581117,0.287228,-120.810265,0.029660,0.000000
19.870001,20.420906,-120.988190,-0.004307,0.001156,0.029365,90.836723,4.627443,0.293647,-120.988190,0.030293,0.000000
20.250002,20.548256,-120.943703,-0.004290,0.001181,0.029988,91.403206,4.656301,0.299885,-120.943703,0.030926,0.000000
20.630001,21.167137,-121.032669,-0.004255,0.001207,0.030656,94.156128,4.796542,0.306561,-121.032669,0.031558,0.000000
21.010000,20.968666,-121.032669,-0.004238,0.001222,0.031030,93.273285,4.751567,0.310301,-121.032669,0.032191,0.000000
21.390001,22.078339,-121.166107,-0.004186,0.001261,0.032026,98.209358,5.003023,0.320263,-121.166107,0.032824,0.000000
21.770000,21.708939,-121.255074,-0.004178,0.001277,0.032443,96.566185,4.919316,0.324426,-121.255074,0.033457,0.000000
22.150002,22.366554,-121.344032,-0.004152,0.001308,0.033224,99.491402,5.068334,0.332238,-121.344032,0.034091,0.000000
22.530001,22.662956,-121.388512,-0.004126,0.001333,0.033857,100.809868,5.135499,0.338566,-121.388512,0.034724,0.000000
22.910002,22.634285,-121.388512,-0.004100,0.001351,0.034317,100.682327,5.129002,0.343169,-121.388512,0.035357,0.000000
23.290001,23.444199,-121.521957,-0.004074,0.001384,0.035166,104.285004,5.312531,0.351662,-121.521957,0.035990,0.000000
23.670002,23.231941,-121.610924,-0.004061,0.001404,0.035652,103.340836,5.264433,0.356522,-121.610924,0.036623,0.000000
24.050001,23.716026,-121.655403,-0.004027,0.001433,0.036406,105.494156,5.374128,0.364061,-121.655403,0.037255,0.000000
24.430000,24.078720,-121.655403,-0.003980,0.001459,0.037048,107.107498,5.456316,0.370481,-121.655403,0.037890,0.000000
24.810001,23.933495,-121.788841,-0.003980,0.001476,0.037490,106.461502,5.423407,0.374901,-121.788841,0.038523,0.000000
25.190001,24.541580,-121.833328,-0.003936,0.001505,0.038227,109.166397,5.561202,0.382274,-121.833328,0.039155,0.000000
25.570002,24.819366,-121.966766,-0.003919,0.001530,0.038869,110.402054,5.624149,0.388694,-121.966766,0.039788,0.000000
25.950001,25.157486,-121.966766,-0.003889,0.001558,0.039563,111.906090,5.700768,0.395627,-121.966766,0.040421,0.000000
26.330002,25.446068,-122.011246,-0.003850,0.001584,0.040239,113.189766,5.766161,0.402395,-122.011246,0.041054,0.000000
26.710001,25.450165,-122.100212,-0.003842,0.001604,0.040742,113.207985,5.767090,0.407421,-122.100212,0.041688,0.000000
27.090002,26.086555,-122.189171,-0.003803,0.001634,0.041514,116.038795,5.911298,0.415142,-122.189171,0.042321,0.000000
27.470001,26.116714,-122.278137,-0.003773,0.001657,0.042087,116.172951,5.918132,0.420865,-122.278137,0.042954,0.000000
27.850000,26.308113,-122.233650,-0.003751,0.001682,0.042719,117.024330,5.961504,0.427194,-122.233650,0.043587,0.000000
28.230001,26.646225,-122.367096,-0.003725,0.001708,0.043379,118.528328,6.038121,0.433794,-122.367096,0.044220,0.000000
28.610001,26.826828,-122.500542,-0.003691,0.001730,0.043934,119.331688,6.079046,0.439335,-122.500542,0.044853,0.000000
28.990002,27.297134,-122.545021,-0.003673,0.001759,0.044680,121.423721,6.185619,0.446799,-122.545021,0.045485,0.000000
29.370001,27.188774,-122.545021,-0.003648,0.001780,0.045208,120.941704,6.161064,0.452083,-122.545021,0.046120,0.000000
29.750002,27.743980,-122.633980,-0.003613,0.001810,0.045964,123.411392,6.286876,0.459638,-122.633980,0.046753,0.000000
30.130001,27.936874,-122.678467,-0.003587,0.001834,0.046588,124.269424,6.330586,0.465875,-122.678467,0.047385,0.000000
30.510002,27.424484,-122.767426,-0.003548,0.001854,0.047090,121.990196,6.214477,0.470901,-122.767426,0.048027,0.000000
30.890001,28.317062,-122.900871,-0.003531,0.001883,0.047818,125.960587,6.416738,0.478184,-122.900871,0.048660,0.000000
31.270002,28.635071,-122.856384,-0.003488,0.001907,0.048435,127.375160,6.488800,0.484345,-122.856384,0.049293,0.000000
31.650002,28.902061,-122.989830,-0.003466,0.001932,0.049067,128.562790,6.549301,0.490674,-122.989830,0.049926,0.000000
32.030003,29.266609,-122.989830,-0.003445,0.001958,0.049727,130.184372,6.631908,0.497275,-122.989830,0.050559,0.000000
32.410000,28.803757,-123.123276,-0.003406,0.001972,0.050091,128.125504,6.527024,0.500908,-123.123276,0.051193,0.000000
32.790001,29.047661,-123.301193,-0.003389,0.002002,0.050846,129.210449,6.582294,0.508463,-123.301193,0.051826,0.000000
33.170002,30.249680,-123.256714,-0.003367,0.002034,0.051652,134.557297,6.854675,0.516517,-123.256714,0.052459,0.000000
33.550003,29.664680,-123.212234,-0.003341,0.002050,0.052059,131.955093,6.722113,0.520590,-123.212234,0.053091,0.000000
33.930000,31.024582,-123.345680,-0.003316,0.002085,0.052970,138.004227,7.030271,0.529704,-123.345680,0.053724,0.000000
34.310001,30.375168,-123.479118,-0.003272,0.002099,0.053308,135.115494,6.883111,0.533080,-123.479118,0.054357,0.000000
34.690002,30.316704,-123.523598,-0.003260,0.002117,0.053777,134.855438,6.869864,0.537773,-123.523598,0.054991,0.000000
35.070004,31.331421,-123.568085,-0.003238,0.002152,0.054652,139.369125,7.099802,0.546524,-123.568085,0.055624,0.000000
35.450001,31.722412,-123.568085,-0.003221,0.002178,0.055329,141.108337,7.188401,0.553291,-123.568085,0.056257,0.000000
35.830002,32.499176,-123.701523,-0.003169,0.002207,0.056066,144.563553,7.364419,0.560664,-123.701523,0.056890,0.000000
36.210003,31.974876,-123.790489,-0.003152,0.002223,0.056465,142.231354,7.245610,0.564646,-123.790489,0.057523,0.000000
36.590000,31.831139,-123.834969,-0.003126,0.002240,0.056908,141.591980,7.213039,0.569082,-123.834969,0.058156,0.000000
36.970001,32.773987,-123.834969,-0.003113,0.002271,0.057679,145.785980,7.426692,0.576788,-123.834969,0.058790,0.000000
37.350002,33.271851,-123.968414,-0.003074,0.002299,0.058407,148.000580,7.539509,0.584070,-123.968414,0.059423,0.000000
37.730003,33.682953,-124.057373,-0.003048,0.002324,0.059023,149.829254,7.632666,0.590232,-124.057373,0.060056,0.000000
38.110001,34.168526,-124.101852,-0.003022,0.002351,0.059726,151.989197,7.742698,0.597256,-124.101852,0.060689,0.000000
38.490002,33.739182,-124.235298,-0.003009,0.002366,0.060107,150.079376,7.645408,0.601072,-124.235298,0.061321,0.000000
38.870003,35.134087,-124.190819,-0.002979,0.002404,0.061061,156.284225,7.961498,0.610610,-124.190819,0.061954,0.000000
39.250000,35.119934,-124.279778,-0.002936,0.002426,0.061626,156.221268,7.958291,0.616257,-124.279778,0.062587,0.000000
39.630001,35.092751,-124.368736,-0.002910,0.002448,0.062180,156.100357,7.952131,0.621798,-124.368736,0.063221,0.000000
40.010002,36.043045,-124.457703,-0.002889,0.002478,0.062943,160.327469,8.167471,0.629428,-124.457703,0.063854,0.000000
40.390003,35.570877,-124.502182,-0.002876,0.002493,0.063333,158.227158,8.060475,0.633334,-124.502182,0.064487,0.000000
40.770000,36.841042,-124.502182,-0.002833,0.002529,0.064245,163.877136,8.348299,0.642448,-124.502182,0.065120,0.000000
41.150002,36.816093,-124.591141,-0.002807,0.002553,0.064852,163.766159,8.342647,0.648519,-124.591141,0.065762,0.000000
41.530003,36.434410,-124.680107,-0.002785,0.002570,0.065285,162.068344,8.256155,0.652849,-124.680107,0.066395,0.000000
41.910004,37.757820,-124.813545,-0.002755,0.002604,0.066152,167.955170,8.556045,0.661524,-124.813545,0.067027,0.000000
42.290001,37.356773,-124.858032,-0.002746,0.002620,0.066551,166.171234,8.465166,0.665506,-124.858032,0.067660,0.000000
42.670002,38.679817,-124.813545,-0.002699,0.002655,0.067444,172.056427,8.764972,0.674438,-124.813545,0.068295,0.000000
43.050003,38.431442,-124.946991,-0.002677,0.002675,0.067939,170.951599,8.708690,0.679389,-124.946991,0.068927,0.000000
43.430000,39.046234,-124.991470,-0.002652,0.002702,0.068641,173.686325,8.848003,0.686413,-124.991470,0.069560,0.000000
43.810001,39.552284,-125.080437,-0.002613,0.002729,0.069318,175.937347,8.962675,0.693181,-125.080437,0.070193,0.000000
44.190002,39.569412,-125.035950,-0.002596,0.002750,0.069837,176.013535,8.966558,0.698374,-125.035950,0.070826,0.000000
44.570004,40.328682,-125.169395,-0.002557,0.002781,0.070635,179.390930,9.138610,0.706352,-125.169395,0.071459,0.000000
44.950001,40.453056,-125.258362,-0.002539,0.002801,0.071138,179.944183,9.166794,0.711379,-125.258362,0.072093,0.000000
45.330002,40.673874,-125.391800,-0.002509,0.002826,0.071772,180.926422,9.216832,0.717722,-125.391800,0.072726,0.000000
45.710003,41.372070,-125.480766,-0.002488,0.002854,0.072491,184.032166,9.375045,0.724913,-125.480766,0.073359,0.000000
46.090004,41.357178,-125.480766,-0.002462,0.002873,0.072986,183.965912,9.371671,0.729864,-125.480766,0.073992,0.000000
46.470001,41.780937,-125.525246,-0.002432,0.002900,0.073662,185.850891,9.467695,0.736616,-125.525246,0.074625,0.000000
46.850002,42.554352,-125.569725,-0.002406,0.002928,0.074364,189.291214,9.642954,0.743641,-125.569725,0.075257,0.000000
47.230003,42.871239,-125.658684,-0.002367,0.002954,0.075032,190.700790,9.714761,0.750318,-125.658684,0.075892,0.000000
47.610001,43.383255,-125.747650,-0.002345,0.002980,0.075701,192.978363,9.830786,0.757009,-125.747650,0.076525,0.000000
47.990002,43.475227,-125.747650,-0.002307,0.003001,0.076229,193.387466,9.851627,0.762293,-125.747650,0.077157,0.000000
48.370003,43.769028,-125.836609,-0.002276,0.003029,0.076941,194.694366,9.918204,0.769409,-125.836609,0.077790,0.000000
48.750004,44.397224,-125.925575,-0.002242,0.003055,0.077590,197.488724,10.060555,0.775903,-125.925575,0.078423,0.000000
49.130001,44.591972,-125.881088,-0.002233,0.003079,0.078197,198.354996,10.104685,0.781974,-125.881088,0.079056,0.000000
49.510002,45.009773,-126.014534,-0.002195,0.003104,0.078848,200.213470,10.199361,0.788484,-126.014534,0.079690,0.000000
49.890003,44.187202,-126.103493,-0.002164,0.003120,0.079239,196.554489,10.012963,0.792390,-126.103493,0.080323,0.000000
50.270004,45.871819,-126.192459,-0.002121,0.003154,0.080123,204.048035,10.394702,0.801232,-126.192459,0.080956,0.000000
50.650002,46.096733,-126.236938,-0.002095,0.003177,0.080686,205.048508,10.445668,0.806864,-126.236938,0.081589,0.000000
51.030003,46.650818,-126.281418,-0.002087,0.003206,0.081442,207.513199,10.571227,0.814419,-126.281418,0.082222,0.000000
51.410004,46.834030,-126.370384,-0.002057,0.003229,0.082005,208.328171,10.612743,0.820050,-126.370384,0.082854,0.000000
51.790001,46.329834,-126.414864,-0.002022,0.003242,0.082352,206.085388,10.498490,0.823517,-126.414864,0.083487,0.000000
52.170002,46.787857,-126.414864,-0.001996,0.003267,0.082985,208.122787,10.602281,0.829846,-126.414864,0.084129,0.000000
52.550003,48.373787,-126.681747,-0.001957,0.003303,0.083904,215.177353,10.961657,0.839036,-126.681747,0.084763,0.000000
52.930004,48.767014,-126.681747,-0.001957,0.003329,0.084555,216.926514,11.050763,0.845546,-126.681747,0.085396,0.000000
53.310001,49.126350,-126.681747,-0.001923,0.003352,0.085153,218.524918,11.132190,0.851526,-126.681747,0.086029,0.000000
53.690002,49.151672,-126.681747,-0.001901,0.003370,0.085595,218.637558,11.137929,0.855946,-126.681747,0.086662,0.000000
54.070004,48.790474,-126.904152,-0.001850,0.003386,0.086003,217.030869,11.056079,0.860034,-126.904152,0.087295,0.000000
54.450001,51.185570,-126.904152,-0.001841,0.003430,0.087113,227.684784,11.598816,0.871131,-126.904152,0.087928,0.000000
54.830002,50.788994,-126.993118,-0.001807,0.003446,0.087529,225.920731,11.508950,0.875295,-126.993118,0.088560,0.000000
55.210003,51.305847,-126.993118,-0.001794,0.003473,0.088206,228.219803,11.626071,0.882062,-126.993118,0.089195,0.000000
55.590004,52.265083,-126.993118,-0.001763,0.003497,0.088813,232.486694,11.843437,0.888133,-126.993118,0.089828,0.000000
55.970001,52.123207,-127.126556,-0.001738,0.003515,0.089290,231.855606,11.811288,0.892902,-127.126556,0.090461,0.000000
56.350002,53.631317,-127.215523,-0.001720,0.003547,0.090088,238.564011,12.153030,0.900881,-127.215523,0.091093,0.000000
56.730003,54.101250,-127.215523,-0.001707,0.003571,0.090712,240.654373,12.259519,0.907118,-127.215523,0.091726,0.000000
57.110004,55.668564,-127.304482,-0.001681,0.003603,0.091519,247.626144,12.614676,0.915188,-127.304482,0.092359,0.000000
57.490002,55.628349,-127.304482,-0.001651,0.003620,0.091952,247.447250,12.605564,0.919518,-127.304482,0.092993,0.000000
57.870003,55.814163,-127.482407,-0.001630,0.003641,0.092482,248.273804,12.647670,0.924816,-127.482407,0.093626,0.000000
58.250004,57.399727,-127.482407,-0.001604,0.003670,0.093210,255.326736,13.006964,0.932099,-127.482407,0.094259,0.000000
58.630001,58.157127,-127.571365,-0.001591,0.003696,0.093868,258.695831,13.178593,0.938684,-127.571365,0.094892,0.000000
59.010002,59.005768,-127.615852,-0.001582,0.003722,0.094536,262.470764,13.370898,0.945361,-127.615852,0.095525,0.000000
59.390003,60.002609,-127.660332,-0.001548,0.003745,0.095117,266.904938,13.596786,0.951174,-127.660332,0.096158,0.000000
59.770004,60.395836,-127.793770,-0.001535,0.003763,0.095578,268.654083,13.685892,0.955777,-127.793770,0.096792,0.000000
60.150002,62.366058,-127.793770,-0.001509,0.003798,0.096478,277.418091,14.132351,0.964785,-127.793770,0.097425,0.000000
60.530003,63.060532,-127.838257,-0.001500,0.003821,0.097043,280.507263,14.289721,0.970432,-127.838257,0.098058,0.000000
60.910004,63.722244,-127.927216,-0.001487,0.003844,0.097650,283.450714,14.439667,0.976503,-127.927216,0.098690,0.000000
61.290005,65.491745,-127.971695,-0.001453,0.003874,0.098388,291.321838,14.840642,0.983876,-127.971695,0.099323,0.000000
61.670002,66.051056,-128.105133,-0.001418,0.003892,0.098846,293.809784,14.967383,0.988463,-128.105133,0.099956,0.000000
62.050003,65.536438,-128.194107,-0.001418,0.003893,0.098890,291.520630,14.850769,0.988902,-128.194107,0.017367,0.000000
62.430004,65.303696,-128.194107,-0.001410,0.003909,0.099288,290.485352,14.798029,0.992884,-128.194107,294.500458,0.000000
62.810001,65.648148,-128.238586,-0.001380,0.003920,0.099567,292.017548,14.876082,0.995670,-128.238586,294.500458,0.000000
63.190002,66.071915,-128.283066,-0.001367,0.003933,0.099895,293.902557,14.972110,0.998955,-128.283066,294.500458,0.000000
63.570004,64.871002,-128.416504,-0.001367,0.003933,0.099895,288.560638,14.699979,0.998955,-128.416504,294.500458,0.000000
63.950005,65.806412,-128.372025,-0.001350,0.003931,0.099853,292.721527,14.911946,0.998531,-128.372025,294.500458,0.000000
64.330002,65.106720,-128.505463,-0.001345,0.003963,0.100651,289.609161,14.753393,1.006510,-128.505463,294.500458,0.000000
64.710007,64.957031,-128.505463,-0.001328,0.003970,0.100833,288.943298,14.719474,1.008326,-128.505463,294.500458,0.000000
65.090004,65.260880,-128.683395,-0.001337,0.003978,0.101040,290.294891,14.788326,1.010400,-128.683395,294.500458,0.000000
65.470001,64.473679,-128.727875,-0.001311,0.003978,0.101040,286.793243,14.609944,1.010400,-128.727875,294.500458,0.000000
65.850006,66.391037,-128.727875,-0.001293,0.003787,0.096192,295.322083,15.044424,0.961923,-128.727875,294.500458,0.000000
66.230003,65.583725,-128.772354,-0.001281,0.003841,0.097555,291.730988,14.861485,0.975549,-128.772354,294.500458,0.000000
66.610001,65.471649,-128.816833,-0.001272,0.004003,0.101673,291.232452,14.836088,1.016729,-128.816833,294.500458,0.000000
66.990005,64.981232,-128.950272,-0.001285,0.004005,0.101726,289.050964,14.724958,1.017259,-128.950272,294.500458,0.000000
67.370003,65.522659,-129.039246,-0.001259,0.004017,0.102021,291.459351,14.847647,1.020211,-129.039246,294.500458,0.000000
67.750000,64.949570,-129.039246,-0.001272,0.004017,0.102021,288.910126,14.717783,1.020211,-129.039246,294.500458,0.000000
68.130005,65.736404,-129.172684,-0.001276,0.004025,0.102228,292.410126,14.896083,1.022285,-129.172684,294.500458,0.000000
68.510002,65.184540,-129.128204,-0.001255,0.004026,0.102254,289.955322,14.771028,1.022542,-129.128204,294.500458,0.000000
68.890007,65.786301,-129.261642,-0.001259,0.004037,0.102533,292.632080,14.907389,1.025328,-129.261642,294.500458,0.000000
69.270004,65.275406,-129.350601,-0.001263,0.004037,0.102540,290.359497,14.791618,1.025404,-129.350601,294.500458,0.000000
69.650002,65.589691,-129.395081,-0.001255,0.004049,0.102836,291.757507,14.862837,1.028356,-129.395081,294.500458,0.000000
70.030006,65.292526,-129.439575,-0.001250,0.004049,0.102854,290.435669,14.795499,1.028538,-129.439575,294.500458,0.000000
70.410004,65.296997,-129.528534,-0.001250,0.004054,0.102975,290.455536,14.796512,1.029749,-129.528534,294.500458,0.000000
70.790001,65.599731,-129.573013,-0.001229,0.004060,0.103122,291.802185,14.865111,1.031217,-129.573013,294.500458,0.000000
71.170006,65.277267,-129.661972,-0.001233,0.004060,0.103122,290.367798,14.792040,1.031217,-129.661972,294.500458,0.000000
71.550003,64.955170,-129.706451,-0.001224,0.004060,0.103122,288.935028,14.719051,1.031217,-129.706451,294.500458,0.000000
71.930000,64.615555,-129.706451,-0.001237,0.004060,0.103122,287.424347,14.642094,1.031217,-129.706451,294.500458,0.000000
72.310005,67.035980,-129.795410,-0.001224,0.003903,0.099132,298.190918,15.190570,0.991325,-129.795410,294.500458,0.000000
72.690002,66.525833,-129.884384,-0.001224,0.003896,0.098967,295.921692,15.074969,0.989674,-129.884384,294.500458,0.000000
73.070000,66.169846,-129.928864,-0.001224,0.003897,0.098986,294.338165,14.994301,0.989856,-129.928864,294.500458,0.000000
73.450005,65.807144,-129.973343,-0.001199,0.003901,0.099098,292.724792,14.912112,0.990976,-129.973343,294.500458,0.000000
73.830002,65.533463,-130.017822,-0.001194,0.003988,0.101300,291.507385,14.850095,1.013004,-130.017822,294.500458,0.000000
74.210007,65.425476,-130.106781,-0.001212,0.004067,0.103303,291.027039,14.825624,1.033034,-130.106781,294.500458,0.000000
74.590004,65.196091,-130.195740,-0.001186,0.004076,0.103529,290.006683,14.773645,1.035290,-130.195740,294.500458,0.000000
74.970001,65.734543,-130.106781,-0.001190,0.004090,0.103894,292.401855,14.895660,1.038939,-130.106781,294.500458,0.000000
75.350006,65.490265,-130.240219,-0.001199,0.004090,0.103894,291.315247,14.840306,1.038939,-130.240219,294.500458,0.000000
75.730003,65.261627,-130.329193,-0.001207,0.004090,0.103894,290.298218,14.788496,1.038939,-130.329193,294.500458,0.000000
76.110001,65.036346,-130.373672,-0.001199,0.004090,0.103894,289.296112,14.737447,1.038939,-130.373672,294.500458,0.000000
76.490005,64.811432,-130.507111,-0.001203,0.004090,0.103894,288.295654,14.686480,1.038939,-130.507111,294.500458,0.000000
76.870003,64.599548,-130.507111,-0.001207,0.004090,0.103894,287.353149,14.638467,1.038939,-130.507111,294.500458,0.000000
77.250000,64.403305,-130.507111,-0.001190,0.004090,0.103894,286.480194,14.593997,1.038939,-130.507111,294.500458,0.000000
77.630005,66.857239,-130.640549,-0.001181,0.003893,0.098890,297.395844,15.150066,0.988902,-130.640549,294.500458,0.000000
78.010002,66.577209,-130.729523,-0.001190,0.003893,0.098890,296.150208,15.086612,0.988902,-130.729523,294.500458,0.000000
78.390007,66.335541,-130.774002,-0.001186,0.003894,0.098907,295.075226,15.031849,0.989069,-130.774002,294.500458,0.000000
78.770004,66.112869,-130.818481,-0.001186,0.003894,0.098907,294.084717,14.981391,0.989069,-130.818481,294.500458,0.000000
79.150002,65.863754,-130.907440,-0.001173,0.003900,0.099072,292.976624,14.924940,0.990719,-130.907440,294.500458,0.000000
79.530006,65.771027,-130.951920,-0.001160,0.003905,0.099176,292.564148,14.903927,0.991764,-130.951920,294.500458,0.000000
79.910004,65.525269,-130.996399,-0.001168,0.004018,0.102056,291.470947,14.848238,1.020559,-130.996399,294.500458,0.000000
80.290001,65.435898,-131.085358,-0.001155,0.004078,0.103582,291.073425,14.827986,1.035820,-131.085358,294.500458,0.000000
80.670006,65.358444,-131.129837,-0.001155,0.004104,0.104231,290.728882,14.810435,1.042315,-131.129837,294.500458,0.000000
81.050003,65.413177,-131.218811,-0.001160,0.004113,0.104466,290.972351,14.822838,1.044661,-131.218811,294.500458,0.000000
81.430000,65.357330,-131.263290,-0.001164,0.004116,0.104545,290.723938,14.810183,1.045449,-131.263290,294.500458,0.000000
81.810005,65.409836,-131.352249,-0.001173,0.004120,0.104640,290.957489,14.822081,1.046402,-131.352249,294.500458,0.000000
82.190002,65.446701,-131.396729,-0.001155,0.004122,0.104708,291.121460,14.830435,1.047084,-131.396729,294.500458,0.000000
82.570007,65.451904,-131.352249,-0.001160,0.004125,0.104769,291.144623,14.831614,1.047689,-131.352249,294.500458,0.000000
82.950005,65.439987,-131.485687,-0.001155,0.004125,0.104787,291.091614,14.828914,1.047871,-131.485687,294.500458,0.000000
83.330002,65.412811,-131.574646,-0.001168,0.004127,0.104822,290.970703,14.822755,1.048219,-131.574646,294.500458,0.000000
83.710007,65.346893,-131.708099,-0.001160,0.004129,0.104882,290.677490,14.807817,1.048825,-131.708099,294.500458,0.000000
84.090004,65.436646,-131.663620,-0.001168,0.004130,0.104892,291.076752,14.828156,1.048916,-131.663620,294.500458,0.000000
84.470001,65.409088,-131.708099,-0.001160,0.004131,0.104926,290.954163,14.821911,1.049264,-131.708099,294.500458,0.000000
84.850006,65.317108,-131.752579,-0.001155,0.004132,0.104943,290.545013,14.801068,1.049430,-131.752579,294.500458,0.000000
85.230003,65.283600,-131.886017,-0.001164,0.004132,0.104952,290.395966,14.793475,1.049521,-131.886017,294.500458,0.000000
85.610001,65.191986,-131.930496,-0.001164,0.004132,0.104952,289.988434,14.772716,1.049521,-131.930496,294.500458,0.000000
85.990005,65.110809,-131.930496,-0.001164,0.004133,0.104969,289.627350,14.754320,1.049688,-131.930496,294.500458,0.000000
86.370003,65.057190,-132.019470,-0.001143,0.004133,0.104987,289.388824,14.742170,1.049869,-132.019470,294.500458,0.000000
86.750008,65.873428,-132.152908,-0.001147,0.004145,0.105281,293.019653,14.927133,1.052806,-132.152908,294.500458,0.000000
87.130005,65.930405,-132.197388,-0.001151,0.004145,0.105281,293.273102,14.940042,1.052806,-132.197388,294.500458,0.000000
87.510002,65.871201,-132.241867,-0.001155,0.004145,0.105281,293.009735,14.926628,1.052806,-132.241867,294.500458,0.000000
87.890007,65.836197,-132.286346,-0.001147,0.004145,0.105281,292.854034,14.918696,1.052806,-132.286346,294.500458,0.000000
88.270004,65.744598,-132.286346,-0.001147,0.004145,0.105281,292.446594,14.897939,1.052806,-132.286346,294.500458,0.000000
88.650002,65.620590,-132.419785,-0.001147,0.004145,0.105281,291.894958,14.869839,1.052806,-132.419785,294.500458,0.000000
89.030006,65.538666,-132.419785,-0.001151,0.004145,0.105281,291.530548,14.851274,1.052806,-132.419785,294.500458,0.000000
89.410004,65.451157,-132.553238,-0.001160,0.004145,0.105281,291.141296,14.831445,1.052806,-132.553238,294.500458,0.000000
89.790001,65.338333,-132.508759,-0.001134,0.004145,0.105281,290.639435,14.805878,1.052806,-132.508759,294.500458,0.000000
90.170006,65.251572,-132.642197,-0.001147,0.004145,0.105290,290.253479,14.786218,1.052897,-132.642197,294.500458,0.000000
90.550003,65.154388,-132.686676,-0.001160,0.004145,0.105290,289.821198,14.764195,1.052897,-132.686676,294.500458,0.000000
90.930008,65.067245,-132.686676,-0.001151,0.004145,0.105290,289.433563,14.744449,1.052897,-132.686676,294.500458,0.000000
91.310005,65.002075,-132.864594,-0.001151,0.004145,0.105290,289.143677,14.729681,1.052897,-132.864594,294.500458,0.000000
91.690002,64.905640,-132.820114,-0.001143,0.004145,0.105290,288.714691,14.707828,1.052897,-132.820114,294.500458,0.000000
92.070007,64.823715,-132.998047,-0.001143,0.004145,0.105290,288.350281,14.689263,1.052897,-132.998047,294.500458,0.000000
92.450005,64.740677,-132.998047,-0.001164,0.004145,0.105290,287.980927,14.670446,1.052897,-132.998047,294.500458,0.000000
92.830002,66.539612,-133.042526,-0.001138,0.004158,0.105620,295.982971,15.078092,1.056198,-133.042526,294.500458,0.000000
93.210007,66.355652,-133.131485,-0.001143,0.004147,0.105343,295.164673,15.036406,1.053427,-133.131485,294.500458,0.000000
93.590004,66.249527,-133.175964,-0.001151,0.004147,0.105343,294.692627,15.012357,1.053427,-133.175964,294.500458,0.000000
93.970001,66.131866,-133.220444,-0.001147,0.004147,0.105343,294.169220,14.985696,1.053427,-133.220444,294.500458,0.000000
94.350006,66.042114,-133.264923,-0.001134,0.004147,0.105343,293.769989,14.965357,1.053427,-133.264923,294.500458,0.000000
94.730003,65.951996,-133.309418,-0.001147,0.004147,0.105343,293.369141,14.944937,1.053427,-133.309418,294.500458,0.000000
95.110008,65.862640,-133.398376,-0.001147,0.004147,0.105343,292.971649,14.924687,1.053427,-133.398376,294.500458,0.000000
95.490005,65.817947,-133.487335,-0.001138,0.004147,0.105343,292.772858,14.914560,1.053427,-133.487335,294.500458,0.000000
95.870003,65.739380,-133.487335,-0.001151,0.004147,0.105343,292.423370,14.896756,1.053427,-133.487335,294.500458,0.000000
96.250008,65.628784,-133.576294,-0.001147,0.004147,0.105343,291.931427,14.871696,1.053427,-133.576294,294.500458,0.000000
96.630005,65.564743,-133.620773,-0.001147,0.004147,0.105343,291.646545,14.857183,1.053427,-133.620773,294.500458,0.000000
97.010002,65.490631,-133.665253,-0.001143,0.004147,0.105343,291.316864,14.840389,1.053427,-133.665253,294.500458,0.000000
97.390007,65.376312,-133.754227,-0.001125,0.004149,0.105376,290.808350,14.814484,1.053760,-133.754227,294.500458,0.000000
97.770004,65.314133,-133.843185,-0.001143,0.004149,0.105376,290.531769,14.800394,1.053760,-133.843185,294.500458,0.000000
98.150002,65.345413,-133.887665,-0.001134,0.004162,0.105715,290.670929,14.807483,1.057151,-133.887665,294.500458,0.000000
98.530006,65.416901,-133.976624,-0.001147,0.004163,0.105732,290.988922,14.823681,1.057318,-133.976624,294.500458,0.000000
98.910004,65.382645,-133.976624,-0.001125,0.004163,0.105741,290.836517,14.815919,1.057409,-133.976624,294.500458,0.000000
99.290001,65.365891,-134.065582,-0.001138,0.004164,0.105758,290.761993,14.812122,1.057575,-134.065582,294.500458,0.000000
99.670006,65.332001,-134.154541,-0.001138,0.004164,0.105767,290.611267,14.804443,1.057666,-134.154541,294.500458,0.000000
100.050003,65.283218,-134.199036,-0.001125,0.004165,0.105785,290.394257,14.793388,1.057848,-134.199036,294.500458,0.000000
100.430008,65.292908,-134.243515,-0.001138,0.004165,0.105801,290.437347,14.795585,1.058014,-134.243515,294.500458,0.000000
100.810005,65.273544,-134.287994,-0.001134,0.004165,0.105801,290.351227,14.791197,1.058014,-134.287994,294.500458,0.000000
101.190002,65.243011,-134.376953,-0.001138,0.004166,0.105820,290.215424,14.784278,1.058196,-134.376953,294.500458,0.000000
101.570007,65.265717,-134.421432,-0.001130,0.004168,0.105862,290.316406,14.789423,1.058620,-134.421432,294.500458,0.000000
101.950005,65.268326,-134.465912,-0.001134,0.004168,0.105871,290.328003,14.790014,1.058711,-134.465912,294.500458,0.000000
102.330002,65.253799,-134.554871,-0.001125,0.004169,0.105880,290.263397,14.786722,1.058802,-134.554871,294.500458,0.000000
102.710007,65.238541,-134.643845,-0.001151,0.004169,0.105897,290.195526,14.783265,1.058968,-134.643845,294.500458,0.000000
103.090004,65.228851,-134.643845,-0.001125,0.004169,0.105897,290.152435,14.781069,1.058968,-134.643845,294.500458,0.000000
103.470001,65.285461,-134.732803,-0.001143,0.004172,0.105966,290.404236,14.793897,1.059665,-134.732803,294.500458,0.000000
103.850006,65.334976,-134.732803,-0.001130,0.004172,0.105976,290.624481,14.805117,1.059755,-134.732803,294.500458,0.000000
104.230003,65.316360,-134.866241,-0.001130,0.004173,0.105983,290.541687,14.800900,1.059831,-134.866241,294.500458,0.000000
104.610008,65.303696,-134.910721,-0.001130,0.004173,0.105983,290.485352,14.798029,1.059831,-134.910721,294.500458,0.000000
104.990005,65.281357,-134.955200,-0.001134,0.004173,0.105992,290.385986,14.792967,1.059922,-134.955200,294.500458,0.000000
105.370003,65.274292,-134.999680,-0.001121,0.004173,0.106001,290.354553,14.791366,1.060013,-134.999680,294.500458,0.000000
105.750008,65.261627,-135.044174,-0.001134,0.004175,0.106053,290.298218,14.788496,1.060528,-135.044174,294.500458,0.000000
106.130005,65.287323,-135.133133,-0.001134,0.004175,0.106053,290.412506,14.794319,1.060528,-135.133133,294.500458,0.000000
106.510002,65.267960,-135.222092,-0.001130,0.004175,0.106053,290.326385,14.789931,1.060528,-135.222092,294.500458,0.000000
106.890007,65.320084,-135.177612,-0.001130,0.004177,0.106097,290.558258,14.801743,1.060967,-135.177612,294.500458,0.000000
107.270004,65.308167,-135.266571,-0.001125,0.004177,0.106097,290.505219,14.799042,1.060967,-135.266571,294.500458,0.000000
107.650002,65.288055,-135.355530,-0.001143,0.004177,0.106097,290.415771,14.794485,1.060967,-135.355530,294.500458,0.000000
108.030006,65.275406,-135.444489,-0.001125,0.004177,0.106106,290.359497,14.791618,1.061057,-135.444489,294.500458,0.000000
108.410004,65.247849,-135.444489,-0.001143,0.004178,0.106122,290.236938,14.785374,1.061224,-135.444489,294.500458,0.000000
108.790009,65.337219,-135.444489,-0.001130,0.004180,0.106174,290.634460,14.805625,1.061739,-135.444489,294.500458,0.000000
109.170006,65.339447,-135.577942,-0.001130,0.004180,0.106174,290.644379,14.806130,1.061739,-135.577942,294.500458,0.000000
109.550003,65.314133,-135.666901,-0.001121,0.004180,0.106174,290.531769,14.800394,1.061739,-135.666901,294.500458,0.000000
109.930008,65.476105,-135.755859,-0.001134,0.004184,0.106262,291.252258,14.837097,1.062617,-135.755859,294.500458,0.000000
110.310005,65.507767,-135.800339,-0.001125,0.004184,0.106262,291.393097,14.844272,1.062617,-135.800339,294.500458,0.000000
110.690002,65.491379,-135.755859,-0.001125,0.004184,0.106262,291.320190,14.840559,1.062617,-135.755859,294.500458,0.000000
111.070007,65.467926,-135.844818,-0.001112,0.004184,0.106262,291.215881,14.835244,1.062617,-135.844818,294.500458,0.000000
111.450005,65.432541,-135.978271,-0.001121,0.004184,0.106262,291.058472,14.827226,1.062617,-135.978271,294.500458,0.000000
111.830002,65.383011,-136.022751,-0.001130,0.004184,0.106262,290.838165,14.816002,1.062617,-136.022751,294.500458,0.000000
112.210007,65.356583,-135.978271,-0.001121,0.004184,0.106262,290.720612,14.810014,1.062617,-135.978271,294.500458,0.000000
112.590004,65.355835,-136.111710,-0.001125,0.004184,0.106278,290.717285,14.809844,1.062783,-136.111710,294.500458,0.000000
112.970009,65.322327,-136.111710,-0.001121,0.004185,0.106287,290.568207,14.802251,1.062874,-136.111710,294.500458,0.000000
113.350006,65.312637,-136.200668,-0.001143,0.004185,0.106287,290.525116,14.800055,1.062874,-136.200668,294.500458,0.000000
113.730003,65.285828,-136.334122,-0.001125,0.004185,0.106304,290.405853,14.793981,1.063041,-136.334122,294.500458,0.000000
114.110008,65.479095,-136.289627,-0.001112,0.004188,0.106383,291.265564,14.837775,1.063828,-136.289627,294.500458,0.000000
114.490005,65.504791,-136.378601,-0.001112,0.004188,0.106383,291.379852,14.843598,1.063828,-136.378601,294.500458,0.000000
114.870003,65.480576,-136.512039,-0.001130,0.004188,0.106383,291.272156,14.838111,1.063828,-136.512039,294.500458,0.000000
115.250008,65.470901,-136.556519,-0.001134,0.004188,0.106383,291.229126,14.835918,1.063828,-136.556519,294.500458,0.000000
115.630005,65.404236,-136.556519,-0.001134,0.004188,0.106383,290.932556,14.820811,1.063828,-136.556519,294.500458,0.000000
116.010002,65.391953,-136.645477,-0.001117,0.004188,0.106383,290.877930,14.818028,1.063828,-136.645477,294.500458,0.000000
116.390007,65.365509,-136.645477,-0.001125,0.004190,0.106434,290.760315,14.812036,1.064343,-136.645477,294.500458,0.000000
116.770004,65.496964,-136.734436,-0.001117,0.004191,0.106452,291.345032,14.841825,1.064524,-136.734436,294.500458,0.000000
117.150009,65.492874,-136.823410,-0.001117,0.004191,0.106452,291.326843,14.840898,1.064524,-136.823410,294.500458,0.000000
117.530006,65.462326,-136.778931,-0.001121,0.004191,0.106452,291.190979,14.833976,1.064524,-136.778931,294.500458,0.000000
117.910004,65.420624,-136.912369,-0.001121,0.004191,0.106452,291.005463,14.824526,1.064524,-136.912369,294.500458,0.000000
118.290009,65.454147,-137.001328,-0.001117,0.004193,0.106504,291.154602,14.832121,1.065039,-137.001328,294.500458,0.000000
118.670006,65.458603,-137.090286,-0.001117,0.004193,0.106504,291.174408,14.833131,1.065039,-137.090286,294.500458,0.000000
119.050003,65.440735,-137.134766,-0.001130,0.004193,0.106504,291.094940,14.829082,1.065039,-137.134766,294.500458,0.000000
119.430008,65.396057,-137.134766,-0.001112,0.004193,0.106504,290.896179,14.818958,1.065039,-137.134766,294.500458,0.000000
119.810005,65.384506,-137.223740,-0.001117,0.004193,0.106504,290.844818,14.816340,1.065039,-137.223740,294.500458,0.000000
120.190002,65.342804,-137.312698,-0.001112,0.004193,0.106504,290.659302,14.806890,1.065039,-137.312698,294.500458,0.000000
120.570007,65.321945,-137.312698,-0.001121,0.004193,0.106504,290.566528,14.802165,1.065039,-137.312698,294.500458,0.000000
120.950005,65.590424,-137.401657,-0.001112,0.004199,0.106643,291.760773,14.863003,1.066432,-137.401657,294.500458,0.000000
121.330009,65.670120,-137.401657,-0.001104,0.004199,0.106643,292.115295,14.881063,1.066432,-137.401657,294.500458,0.000000
121.710007,65.666397,-137.490616,-0.001121,0.004199,0.106643,292.098724,14.880218,1.066432,-137.490616,294.500458,0.000000
122.090004,65.619095,-137.535095,-0.001121,0.004199,0.106643,291.888306,14.869499,1.066432,-137.535095,294.500458,0.000000
122.470009,65.610535,-137.579575,-0.001108,0.004199,0.106643,291.850220,14.867560,1.066432,-137.579575,1681.640747,0.000000
122.850006,65.536438,-137.579575,-0.001112,0.004189,0.106399,291.520630,14.850769,1.063995,-137.579575,0.106201,0.000000
123.230003,65.521164,-137.668549,-0.001130,0.004176,0.106062,291.452698,14.847308,1.060618,-137.668549,0.105567,0.000000
123.610008,65.352859,-137.846466,-0.001117,0.004150,0.105420,290.704041,14.809170,1.054199,-137.846466,0.104934,0.000000
123.990005,65.329391,-137.935425,-0.001112,0.004132,0.104960,290.599640,14.803851,1.049597,-137.935425,0.104301,0.000000
124.370003,65.263489,-137.935425,-0.001117,0.004100,0.104145,290.306488,14.788918,1.041452,-137.935425,0.103668,0.000000
124.750008,65.219925,-137.935425,-0.001130,0.004085,0.103764,290.112701,14.779046,1.037637,-137.935425,0.103035,0.000000
125.130005,65.187149,-137.979904,-0.001117,0.004062,0.103182,289.966919,14.771620,1.031823,-137.979904,0.102403,0.000000
125.510010,65.127945,-138.068878,-0.001117,0.004034,0.102454,289.703583,14.758204,1.024541,-138.068878,0.101770,0.000000
125.890007,65.023682,-138.113358,-0.001104,0.004005,0.101735,289.239777,14.734576,1.017349,-138.113358,0.101128,0.000000
126.270004,64.998352,-138.113358,-0.001112,0.003981,0.101119,289.127106,14.728837,1.011188,-138.113358,0.100493,0.000000
126.650009,64.910477,-138.246796,-0.001095,0.003970,0.100833,288.736206,14.708923,1.008326,-138.246796,0.099861,0.000000
127.030006,64.379852,-138.335754,-0.001112,0.003938,0.100035,286.375885,14.588683,1.000348,-138.335754,0.099228,0.000000
127.410004,63.503647,-138.380234,-0.001104,0.003912,0.099376,282.478333,14.390132,0.993762,-138.380234,0.098595,0.000000
127.790009,62.647194,-138.469208,-0.001104,0.003893,0.098890,278.668640,14.196057,0.988902,-138.469208,0.097962,0.000000
128.170013,60.888481,-138.380234,-0.001091,0.003867,0.098213,270.845490,13.797527,0.982135,-138.380234,0.097329,0.000000
128.550003,59.275734,-138.513687,-0.001069,0.003846,0.097676,263.671631,13.432074,0.976760,-138.513687,0.096696,0.000000
128.930008,57.239235,-138.602646,-0.001056,0.003820,0.097025,254.612839,12.970595,0.970250,-138.602646,0.096062,0.000000
129.310013,54.786789,-138.691605,-0.001056,0.003794,0.096357,243.703812,12.414864,0.963574,-138.691605,0.095429,0.000000
129.690002,52.909286,-138.647125,-0.001043,0.003776,0.095915,235.352264,11.989415,0.959153,-138.647125,0.094796,0.000000
130.070007,49.560165,-138.736084,-0.001052,0.003744,0.095101,220.454620,11.230494,0.951008,-138.736084,0.094164,0.000000
130.450012,46.853020,-138.780563,-0.001035,0.003718,0.094450,208.412643,10.617046,0.944498,-138.780563,0.093531,0.000000
130.830002,45.066002,-138.914017,-0.001069,0.003704,0.094077,200.463593,10.212102,0.940773,-138.914017,0.092898,0.000000
131.210007,41.922440,-138.914017,-0.001048,0.003674,0.093322,186.480331,9.499761,0.933219,-138.914017,0.092264,0.000000
131.590012,39.095757,-138.958496,-0.001056,0.003647,0.092645,173.906616,8.859225,0.926451,-138.958496,0.091631,0.000000
131.970001,36.221413,-139.047455,-0.001048,0.003621,0.091970,161.120895,8.207890,0.919699,-139.047455,0.090998,0.000000
132.350006,34.104477,-139.136414,-0.001048,0.003601,0.091475,151.704285,7.728185,0.914749,-139.136414,0.090365,0.000000
132.730011,31.896683,-139.136414,-0.001065,0.003582,0.090981,141.883530,7.227891,0.909813,-139.136414,0.089732,0.000000
133.110001,28.512932,-139.180893,-0.001043,0.003548,0.090130,126.831856,6.461123,0.901305,-139.180893,0.089099,0.000000
133.490005,25.719017,-139.314346,-0.001056,0.003524,0.089498,114.403900,5.828012,0.894976,-139.314346,0.088465,0.000000
133.870010,22.713226,-139.314346,-0.001052,0.003496,0.088786,101.033478,5.146891,0.887861,-139.314346,0.087832,0.000000
134.250000,20.510651,-139.403305,-0.001061,0.003475,0.088258,91.235931,4.647780,0.882577,-139.403305,0.087199,0.000000
134.630005,17.809082,-139.492264,-0.001052,0.003447,0.087555,79.218750,4.035596,0.875552,-139.492264,0.086567,0.000000
135.010010,15.328712,-139.447784,-0.001061,0.003427,0.087044,68.185516,3.473536,0.870435,-139.447784,0.085934,0.000000
135.389999,12.449532,-139.581223,-0.001052,0.003398,0.086297,55.378281,2.821104,0.862971,-139.581223,0.085301,0.000000
135.770004,10.684113,-139.625702,-0.001056,0.003379,0.085820,47.525307,2.421055,0.858202,-139.625702,0.084667,0.000000
136.150009,7.994095,-139.714661,-0.001052,0.003354,0.085187,35.559509,1.811488,0.851874,-139.714661,0.084034,0.000000
136.530014,5.648888,-139.714661,-0.001065,0.003330,0.084580,25.127506,1.280056,0.845803,-139.714661,0.083401,0.000000
136.910004,2.806572,-139.759155,-0.001043,0.003303,0.083896,12.484256,0.635978,0.838960,-139.759155,0.082759,0.000000
137.290009,-0.017128,-139.892593,-0.001056,0.003273,0.083141,-0.076189,-0.003881,0.831405,-139.892593,0.082126,0.000000
137.670013,-2.056240,-139.937073,-0.001043,0.003247,0.082465,-9.146613,-0.465951,0.824653,-139.937073,0.081493,0.000000
138.050003,-0.424507,-140.026031,-0.001052,0.003227,0.081954,-1.888302,-0.096195,0.819536,-140.026031,0.080860,0.000000
138.430008,-0.078575,-139.981552,-0.001069,0.003207,0.081449,-0.349520,-0.017805,0.814494,-139.981552,0.080228,0.000000
138.810013,-0.048409,-139.981552,-0.001061,0.003176,0.080661,-0.215332,-0.010970,0.806607,-139.981552,0.079593,0.000000
139.190002,-0.078201,-140.070511,-0.001048,0.003148,0.079967,-0.347857,-0.017721,0.799673,-140.070511,0.078960,0.000000
139.570007,-0.049530,-140.159470,-0.001065,0.003121,0.079265,-0.220321,-0.011224,0.792648,-140.159470,0.078328,0.000000
139.950012,-0.042824,-140.248444,-0.001061,0.003104,0.078830,-0.190490,-0.009704,0.788303,-140.248444,0.077695,0.000000
140.330002,-0.061440,-140.292923,-0.001061,0.003076,0.078128,-0.273297,-0.013922,0.781278,-140.292923,0.077062,0.000000
140.710007,-0.073357,-140.337402,-0.001065,0.003051,0.077504,-0.326307,-0.016623,0.775041,-140.337402,0.076429,0.000000
141.090012,-0.090118,-140.426361,-0.001065,0.003027,0.076897,-0.400867,-0.020421,0.768970,-140.426361,0.075796,0.000000
141.470001,-0.119164,-140.515320,-0.001078,0.002998,0.076160,-0.530066,-0.027003,0.761597,-140.515320,0.075162,0.000000
141.850006,-0.111343,-140.515320,-0.001082,0.002980,0.075701,-0.495280,-0.025231,0.757009,-140.515320,0.074529,0.000000
142.230011,-0.116928,-140.470840,-0.001087,0.002964,0.075285,-0.520122,-0.026496,0.752846,-140.470840,0.073896,0.000000
142.610001,-0.157890,-140.604294,-0.001108,0.002923,0.074252,-0.702331,-0.035778,0.742521,-140.604294,0.073263,0.000000
142.990005,-0.120277,-140.737732,-0.001130,0.002905,0.073792,-0.535021,-0.027255,0.737918,-140.737732,0.072631,0.000000
143.370010,-0.134430,-140.693253,-0.001229,0.002871,0.072926,-0.597974,-0.030462,0.729258,-140.693253,0.071998,0.000000
143.750000,-0.116554,-140.782211,-0.001276,0.002847,0.072310,-0.518459,-0.026412,0.723097,-140.782211,0.071363,0.000000
144.130005,-0.139641,-140.826691,-0.001306,0.002824,0.071728,-0.621153,-0.031643,0.717283,-140.826691,0.070731,0.000000
144.510010,-0.124374,-140.960129,-0.001367,0.002809,0.071356,-0.553245,-0.028184,0.713559,-140.960129,0.070098,0.000000
144.889999,-0.157890,-141.004608,-0.001427,0.002777,0.070523,-0.702331,-0.035778,0.705232,-141.004608,0.069465,0.000000
145.270004,-0.184700,-141.049103,-0.001479,0.002752,0.069898,-0.821587,-0.041854,0.698979,-141.049103,0.068832,0.000000
145.650009,-0.161980,-141.049103,-0.001518,0.002723,0.069153,-0.720522,-0.036705,0.691531,-141.049103,0.068199,0.000000
146.030014,-0.166824,-141.138062,-0.001552,0.002707,0.068746,-0.742072,-0.037803,0.687458,-141.138062,0.067565,0.000000
146.410004,-0.153419,-141.227020,-0.001595,0.002680,0.068060,-0.682444,-0.034765,0.680600,-141.227020,0.066932,0.000000
146.790009,-0.185066,-141.271500,-0.001625,0.002651,0.067332,-0.823216,-0.041937,0.673318,-141.271500,0.066299,0.000000
147.170013,-0.172783,-141.315979,-0.001664,0.002629,0.066785,-0.768577,-0.039153,0.667852,-141.315979,0.065666,0.000000
147.550003,-0.166077,-141.360458,-0.001720,0.002595,0.065909,-0.738746,-0.037634,0.659086,-141.360458,0.065034,0.000000
147.930008,-0.160118,-141.404938,-0.001738,0.002582,0.065571,-0.712241,-0.036283,0.655710,-141.404938,0.064392,0.000000
148.310013,-0.170174,-141.538391,-0.001772,0.002556,0.064920,-0.756970,-0.038562,0.649200,-141.538391,0.063759,0.000000
148.690002,-0.214485,-141.538391,-0.001811,0.002525,0.064131,-0.954078,-0.048603,0.641313,-141.538391,0.063126,0.000000
149.070007,-0.196983,-141.582870,-0.001841,0.002504,0.063603,-0.876226,-0.044637,0.636029,-141.582870,0.062492,0.000000
149.450012,-0.161240,-141.627350,-0.001884,0.002472,0.062796,-0.717230,-0.036537,0.627959,-141.627350,0.061859,0.000000
149.830002,-0.164215,-141.671829,-0.001897,0.002454,0.062319,-0.730465,-0.037212,0.623191,-141.671829,0.061226,0.000000
150.210007,-0.164963,-141.805267,-0.001923,0.002432,0.061782,-0.733791,-0.037381,0.617816,-141.805267,0.060593,0.000000
150.590012,-0.153419,-141.849747,-0.001957,0.002404,0.061053,-0.682444,-0.034765,0.610534,-141.849747,0.059960,0.000000
150.970001,-0.183578,-141.849747,-0.001983,0.002378,0.060402,-0.816598,-0.041599,0.604024,-141.849747,0.059327,0.000000
151.350006,-0.152672,-141.894241,-0.002009,0.002346,0.059579,-0.679118,-0.034596,0.595788,-141.894241,0.058695,0.000000
151.730011,-0.153046,-141.983200,-0.002035,0.002322,0.058972,-0.680781,-0.034681,0.589717,-141.983200,0.058060,0.000000
152.110001,-0.162727,-142.027679,-0.002061,0.002305,0.058555,-0.723847,-0.036875,0.585554,-142.027679,0.057427,0.000000
152.490005,-0.169060,-142.072159,-0.002082,0.002277,0.057835,-0.752015,-0.038309,0.578347,-142.072159,0.056795,0.000000
152.870010,-0.164215,-142.116638,-0.002113,0.002252,0.057202,-0.730465,-0.037212,0.572019,-142.116638,0.056162,0.000000
153.250000,-0.152672,-142.116638,-0.002134,0.002221,0.056404,-0.679118,-0.034596,0.564040,-142.116638,0.055529,0.000000
153.630005,-0.180603,-142.294556,-0.002169,0.002201,0.055901,-0.803362,-0.040925,0.559014,-142.294556,0.054896,0.000000
154.010010,-0.171295,-142.339050,-0.002182,0.002182,0.055415,-0.761959,-0.038816,0.554154,-142.339050,0.054262,0.000000
154.390015,-0.172035,-142.339050,-0.002212,0.002153,0.054687,-0.765251,-0.038984,0.546872,-142.339050,0.053629,0.000000
154.500000,-0.113945,-142.383530,-0.002233,0.002148,0.054548,-0.506853,-0.025820,0.545479,-142.383530,0.054445,0.000000