File: Data/compression 31/ManualNoHeating-12-31-reverse-1-1_11132024_175833.csv
Time (sec),S:Load (lbs),S:HL1 (DIM),S:LVDT (in),S:Position (in),Ch:Position (mm),Ch:Load (N),Ch:Stress (MPa),Ch:Strain (mm/mm),Ch:HL1 (DIM),Set Point (),Cycles ()
0.110000,-0.083038,-262.081757,-0.009425,-0.004909,-0.124699,-0.369373,-0.018817,-1.246987,-262.081757,-0.124534,0.000000
0.510000,-0.095329,-262.126251,-0.009421,-0.004844,-0.123033,-0.424046,-0.021602,-1.230333,-262.126251,-0.122417,0.000000
0.910000,-0.124001,-262.170715,-0.009274,-0.004597,-0.116764,-0.551582,-0.028099,-1.167640,-262.170715,-0.115741,0.000000
1.310000,-0.174271,-262.170715,-0.009007,-0.004335,-0.110121,-0.775194,-0.039490,-1.101208,-262.170715,-0.109079,0.000000
1.710000,-0.088249,-262.215210,-0.008748,-0.004077,-0.103547,-0.392552,-0.019998,-1.035472,-262.215210,-0.102419,0.000000
2.110000,-0.083038,-262.215210,-0.008464,-0.003815,-0.096904,-0.369373,-0.018817,-0.969039,-262.215210,-0.095759,0.000000
2.510000,-0.062187,-262.259674,-0.008222,-0.003546,-0.090062,-0.276622,-0.014092,-0.900623,-262.259674,-0.089099,0.000000
2.910000,-0.070381,-262.304169,-0.007933,-0.003282,-0.083359,-0.313071,-0.015949,-0.833585,-262.304169,-0.082421,0.000000
3.310000,-0.083786,-262.259674,-0.007666,-0.003020,-0.076697,-0.372699,-0.018986,-0.766971,-262.259674,-0.075761,0.000000
3.710000,-0.053993,-262.393127,-0.007381,-0.002761,-0.070124,-0.240174,-0.012235,-0.701235,-262.393127,-0.069100,0.000000
4.110000,-0.033890,-262.393127,-0.007123,-0.002499,-0.063482,-0.150749,-0.007680,-0.634818,-262.393127,-0.062440,0.000000
4.510000,-0.051392,-262.437622,-0.006842,-0.002240,-0.056890,-0.228601,-0.011646,-0.568900,-262.437622,-0.055762,0.000000
4.910000,-0.066658,-262.437622,-0.006592,-0.001981,-0.050316,-0.296510,-0.015105,-0.503164,-262.437622,-0.049102,0.000000
5.310000,-0.094955,-262.482086,-0.006291,-0.001712,-0.043475,-0.422383,-0.021517,-0.434748,-262.482086,-0.042442,0.000000
5.710000,-0.082664,-262.526581,-0.006032,-0.001448,-0.036771,-0.367710,-0.018732,-0.367710,-262.526581,-0.035782,0.000000
6.110000,-0.040962,-262.526581,-0.005773,-0.001188,-0.030172,-0.182209,-0.009282,-0.301717,-262.526581,-0.029121,0.000000
6.510000,-0.010056,-262.571045,-0.005510,-0.000927,-0.023554,-0.044729,-0.002279,-0.235542,-262.571045,-0.022444,0.000000
6.910000,-0.060699,-262.571045,-0.005226,-0.000659,-0.016746,-0.270005,-0.013755,-0.167459,-262.571045,-0.015783,0.000000
7.310000,0.183578,-262.615540,-0.004958,-0.000003,-0.000079,0.816598,0.041599,-0.000787,-262.615540,0.000042,0.000000
7.710001,0.141129,-262.615540,-0.004963,-0.000006,-0.000165,0.627771,0.031980,-0.001650,-262.615540,0.000042,0.000000
8.110001,0.119156,-262.704498,-0.004967,-0.000006,-0.000165,0.530032,0.027001,-0.001650,-262.704498,0.000572,0.000000
8.510000,0.151924,-262.748993,-0.004971,0.000016,0.000398,0.675792,0.034427,0.003982,-262.748993,0.001240,0.000000
8.910001,0.347794,-262.704498,-0.004937,0.000045,0.001135,1.547063,0.078811,0.011355,-262.704498,0.001908,0.000000
9.310000,0.527275,-262.748993,-0.004894,0.000068,0.001733,2.345437,0.119482,0.017335,-262.748993,0.002575,0.000000
9.710000,0.758522,-262.793457,-0.004898,0.000098,0.002489,3.374074,0.171884,0.024889,-262.793457,0.003243,0.000000
10.110001,0.962212,-262.882416,-0.004846,0.000125,0.003164,4.280131,0.218040,0.031642,-262.882416,0.003901,0.000000
10.510000,1.099991,-262.837952,-0.004833,0.000145,0.003694,4.893003,0.249261,0.036941,-262.837952,0.004569,0.000000
10.910001,1.490234,-262.882416,-0.004794,0.000178,0.004518,6.628893,0.337692,0.045177,-262.882416,0.005237,0.000000
11.310000,1.711792,-262.926910,-0.004773,0.000202,0.005125,7.614431,0.387898,0.051247,-262.926910,0.005906,0.000000
11.710001,2.021606,-263.015869,-0.004760,0.000226,0.005748,8.992555,0.458103,0.057485,-263.015869,0.006574,0.000000
12.110001,2.246895,-263.015869,-0.004743,0.000253,0.006425,9.994687,0.509154,0.064252,-263.015869,0.007241,0.000000
12.510000,2.510536,-263.015869,-0.004712,0.000279,0.007076,11.167422,0.568896,0.070762,-263.015869,0.007909,0.000000
12.910001,2.909721,-263.060333,-0.004682,0.000307,0.007795,12.943087,0.659352,0.077954,-263.060333,0.008577,0.000000
13.310000,3.224373,-263.104828,-0.004652,0.000332,0.008421,14.342727,0.730653,0.084206,-263.104828,0.009244,0.000000
13.710001,3.452263,-263.104828,-0.004635,0.000359,0.009131,15.356432,0.782294,0.091307,-263.104828,0.009903,0.000000
14.110001,3.660423,-263.149292,-0.004609,0.000384,0.009747,16.282375,0.829464,0.097469,-263.149292,0.010570,0.000000
14.510000,4.019760,-263.193787,-0.004596,0.000409,0.010380,17.880787,0.910891,0.103797,-263.193787,0.011238,0.000000
14.910001,4.349686,-263.193787,-0.004562,0.000436,0.011082,19.348368,0.985653,0.110822,-263.193787,0.011906,0.000000
15.310000,4.612206,-263.238281,-0.004540,0.000459,0.011647,20.516115,1.045141,0.116469,-263.238281,0.012575,0.000000
15.710001,5.065384,-263.327240,-0.004510,0.000488,0.012401,22.531954,1.147832,0.124008,-263.327240,0.013243,0.000000
16.110001,5.269814,-263.282745,-0.004471,0.000516,0.013094,23.441301,1.194157,0.130942,-263.282745,0.013910,0.000000
16.510000,5.260506,-263.327240,-0.004454,0.000532,0.013520,23.399899,1.192048,0.135196,-263.327240,0.014578,0.000000
16.910002,5.769165,-263.371704,-0.004437,0.000566,0.014369,25.662527,1.307312,0.143690,-263.371704,0.015236,0.000000
17.310001,5.909180,-263.416199,-0.004402,0.000586,0.014881,26.285343,1.339039,0.148807,-263.416199,0.015904,0.000000
17.710001,6.398102,-263.416199,-0.004376,0.000617,0.015679,28.460178,1.449831,0.156785,-263.416199,0.016572,0.000000
18.110001,6.632324,-263.460663,-0.004355,0.000644,0.016355,29.502052,1.502906,0.163553,-263.460663,0.017239,0.000000
18.510000,6.587639,-263.460663,-0.004346,0.000664,0.016867,29.303282,1.492780,0.168670,-263.460663,0.017907,0.000000
18.910002,7.183807,-263.549622,-0.004312,0.000699,0.017751,31.955172,1.627874,0.177512,-263.549622,0.018575,0.000000
19.310001,7.113060,-263.594116,-0.004286,0.000715,0.018151,31.640471,1.611842,0.181508,-263.594116,0.019244,0.000000
19.710001,7.660072,-263.638611,-0.004255,0.000748,0.019009,34.073704,1.735797,0.190093,-263.638611,0.019912,0.000000
20.110001,7.775879,-263.683075,-0.004217,0.000775,0.019686,34.588837,1.762039,0.196860,-263.683075,0.020570,0.000000
20.510000,7.943077,-263.638611,-0.004199,0.000797,0.020233,35.332573,1.799927,0.202325,-263.638611,0.021238,0.000000
20.910002,8.345612,-263.683075,-0.004161,0.000828,0.021030,37.123135,1.891143,0.210304,-263.683075,0.021905,0.000000
21.310001,8.217514,-263.683075,-0.004148,0.000843,0.021419,36.553329,1.862115,0.214195,-263.683075,0.022573,0.000000
21.710001,8.922791,-263.772034,-0.004109,0.000881,0.022373,39.690556,2.021933,0.223733,-263.772034,0.023241,0.000000
22.110001,8.948479,-263.772034,-0.004092,0.000906,0.023008,39.804821,2.027754,0.230076,-263.772034,0.023908,0.000000
22.510000,9.328674,-263.816528,-0.004070,0.000932,0.023683,41.496017,2.113908,0.236828,-263.816528,0.024576,0.000000
22.910002,9.496239,-263.860992,-0.004036,0.000958,0.024334,42.241379,2.151878,0.243338,-263.860992,0.025244,0.000000
23.310001,9.473900,-263.905487,-0.004023,0.000977,0.024811,42.142010,2.146816,0.248107,-263.905487,0.025904,0.000000
23.710001,10.188484,-263.905487,-0.003967,0.001016,0.025808,45.320641,2.308743,0.258084,-263.905487,0.026571,0.000000
24.110001,9.854836,-263.949951,-0.003967,0.001031,0.026190,43.836498,2.233138,0.261900,-263.949951,0.027239,0.000000
24.510000,10.380257,-263.994446,-0.003919,0.001064,0.027030,46.173687,2.352200,0.270302,-263.994446,0.027907,0.000000
24.910002,10.624161,-264.038940,-0.003893,0.001092,0.027733,47.258629,2.407469,0.277327,-264.038940,0.028574,0.000000
25.310001,10.587296,-264.083405,-0.003880,0.001113,0.028263,47.094643,2.399116,0.282626,-264.083405,0.029242,0.000000
25.710001,11.170059,-264.083405,-0.003837,0.001145,0.029086,49.686905,2.531172,0.290862,-264.083405,0.029910,0.000000
26.110001,11.312675,-264.127899,-0.003807,0.001170,0.029728,50.321293,2.563489,0.297281,-264.127899,0.030577,0.000000
26.510002,11.587112,-264.172363,-0.003790,0.001197,0.030412,51.542049,2.625677,0.304124,-264.172363,0.031245,0.000000
26.910002,11.680580,-264.216858,-0.003755,0.001222,0.031029,51.957817,2.646857,0.310286,-264.216858,0.031905,0.000000
27.310001,12.124443,-264.216858,-0.003742,0.001247,0.031680,53.932217,2.747438,0.316796,-264.216858,0.032573,0.000000
27.710001,12.293503,-264.261322,-0.003708,0.001276,0.032417,54.684231,2.785748,0.324169,-264.261322,0.033240,0.000000
28.110001,12.526611,-264.261322,-0.003673,0.001304,0.033119,55.721149,2.838571,0.331193,-264.261322,0.033908,0.000000
28.510002,12.615982,-264.305817,-0.003648,0.001329,0.033752,56.118690,2.858822,0.337522,-264.305817,0.034576,0.000000
28.910002,12.575760,-264.350281,-0.003609,0.001349,0.034264,55.939774,2.849708,0.342639,-264.350281,0.035243,0.000000
29.310001,13.272842,-264.394775,-0.003583,0.001384,0.035157,59.040550,3.007669,0.351571,-264.394775,0.035911,0.000000
29.710001,13.080330,-264.350281,-0.003548,0.001404,0.035669,58.184212,2.964045,0.356688,-264.350281,0.036579,0.000000
30.110001,13.462379,-264.394775,-0.003527,0.001435,0.036441,59.883656,3.050619,0.364410,-264.394775,0.037239,0.000000
30.510002,13.679474,-264.528229,-0.003501,0.001462,0.037125,60.849339,3.099813,0.371253,-264.528229,0.037906,0.000000
30.910002,13.430359,-264.483734,-0.003462,0.001478,0.037551,59.741219,3.043363,0.375507,-264.483734,0.038574,0.000000
31.310001,14.189621,-264.528229,-0.003449,0.001515,0.038470,63.118587,3.215414,0.384697,-264.528229,0.039242,0.000000
31.710001,14.001945,-264.483734,-0.003419,0.001536,0.039025,62.283764,3.172886,0.390253,-264.483734,0.039909,0.000000
32.110001,14.449165,-264.617187,-0.003393,0.001566,0.039788,64.273094,3.274228,0.397883,-264.617187,0.040577,0.000000
32.510002,14.560509,-264.661652,-0.003363,0.001590,0.040386,64.768379,3.299459,0.403863,-264.661652,0.041245,0.000000
32.910000,14.445442,-264.617187,-0.003333,0.001609,0.040880,64.256538,3.273384,0.408799,-264.617187,0.041912,0.000000
33.310001,15.255730,-264.706146,-0.003307,0.001647,0.041826,67.860878,3.456998,0.418261,-264.706146,0.042571,0.000000
33.710003,15.140289,-264.661652,-0.003268,0.001669,0.042389,67.347374,3.430839,0.423893,-264.661652,0.043239,0.000000
34.110001,15.389778,-264.706146,-0.003247,0.001698,0.043136,68.457153,3.487374,0.431357,-264.706146,0.043908,0.000000
34.510002,15.416962,-264.750610,-0.003221,0.001719,0.043655,68.578072,3.493533,0.436550,-264.750610,0.044575,0.000000
34.910000,15.165985,-264.839569,-0.003186,0.001736,0.044099,67.461670,3.436661,0.440986,-264.839569,0.045243,0.000000
35.310001,16.385506,-264.839569,-0.003152,0.001778,0.045173,72.886368,3.713009,0.451735,-264.839569,0.045911,0.000000
35.710003,15.839981,-264.839569,-0.003139,0.001796,0.045606,70.459755,3.589391,0.456065,-264.839569,0.046578,0.000000
36.110001,16.455887,-264.928558,-0.003100,0.001829,0.046448,73.199440,3.728957,0.464482,-264.928558,0.047246,0.000000
36.510002,16.354599,-264.928558,-0.003048,0.001850,0.046986,72.748886,3.706005,0.469857,-264.928558,0.047905,0.000000
36.910000,16.192245,-265.017517,-0.003048,0.001867,0.047411,72.026703,3.669215,0.474111,-265.017517,0.048572,0.000000
37.310001,16.976089,-264.973022,-0.002988,0.001904,0.048356,75.513420,3.846837,0.483558,-264.973022,0.049240,0.000000
37.710003,17.136581,-265.017517,-0.002988,0.001929,0.048998,76.227318,3.883205,0.489977,-265.017517,0.049908,0.000000
38.110001,17.732376,-265.061981,-0.002953,0.001961,0.049805,78.877548,4.018214,0.498047,-265.061981,0.050577,0.000000
38.510002,17.109398,-265.106476,-0.002932,0.001975,0.050160,76.106400,3.877045,0.501605,-265.106476,0.051244,0.000000
38.910004,17.848183,-265.106476,-0.002893,0.002007,0.050975,79.392685,4.044456,0.509750,-265.106476,0.051912,0.000000
39.310001,18.042191,-265.195435,-0.002854,0.002035,0.051677,80.255669,4.088419,0.516774,-265.195435,0.052580,0.000000
39.710003,17.896965,-265.195435,-0.002846,0.002055,0.052189,79.609680,4.055511,0.521892,-265.195435,0.053247,0.000000
40.110001,18.870720,-265.150940,-0.002811,0.002092,0.053126,83.941154,4.276166,0.531263,-265.150940,0.053906,0.000000
40.510002,18.540054,-265.239899,-0.002772,0.002111,0.053629,82.470284,4.201236,0.536289,-265.239899,0.054574,0.000000
40.910004,19.301178,-265.284393,-0.002759,0.002142,0.054401,85.855927,4.373710,0.544011,-265.284393,0.055241,0.000000
41.310001,19.062119,-265.328888,-0.002721,0.002166,0.055025,84.792542,4.319538,0.550248,-265.328888,0.055909,0.000000
41.710003,19.001793,-265.373352,-0.002699,0.002188,0.055580,84.524193,4.305868,0.555804,-265.373352,0.056577,0.000000
42.110001,19.571526,-265.373352,-0.002660,0.002220,0.056386,87.058495,4.434971,0.563859,-265.373352,0.057246,0.000000
42.510002,19.300064,-265.417847,-0.002630,0.002239,0.056872,85.850975,4.373457,0.568718,-265.417847,0.057913,0.000000
42.910004,19.941292,-265.462311,-0.002600,0.002270,0.057670,88.703293,4.518761,0.576697,-265.462311,0.058581,0.000000
43.310001,20.102898,-265.417847,-0.002596,0.002297,0.058356,89.422157,4.555382,0.583555,-265.417847,0.059240,0.000000
43.710003,19.704086,-265.506805,-0.002539,0.002316,0.058823,87.648155,4.465010,0.588233,-265.506805,0.059907,0.000000
44.110001,20.509903,-265.506805,-0.002522,0.002350,0.059691,91.232605,4.647611,0.596908,-265.506805,0.060575,0.000000
44.510002,20.073479,-265.595764,-0.002505,0.002366,0.060098,89.291290,4.548716,0.600981,-265.595764,0.061243,0.000000
44.910004,21.388702,-265.595764,-0.002479,0.002407,0.061131,95.141701,4.846749,0.611306,-265.595764,0.061910,0.000000
45.310001,20.693481,-265.684723,-0.002445,0.002423,0.061547,92.049202,4.689210,0.615469,-265.684723,0.062578,0.000000
45.710003,21.345131,-265.684723,-0.002419,0.002455,0.062352,94.947884,4.836875,0.623524,-265.684723,0.063246,0.000000
46.110001,21.511581,-265.684723,-0.002393,0.002480,0.063003,95.688293,4.874594,0.630034,-265.684723,0.063915,0.000000
46.510002,20.890839,-265.729187,-0.002376,0.002498,0.063445,92.927094,4.733932,0.634454,-265.729187,0.064573,0.000000
46.910004,22.438416,-265.729187,-0.002328,0.002539,0.064487,99.811058,5.084618,0.644870,-265.729187,0.065241,0.000000
47.310001,21.691437,-265.729187,-0.002315,0.002556,0.064920,96.488327,4.915350,0.649200,-265.729187,0.065909,0.000000
47.710003,22.053757,-265.729187,-0.002285,0.002585,0.065657,98.100006,4.997453,0.656573,-265.729187,0.066576,0.000000
48.110001,22.391502,-265.862640,-0.002255,0.002613,0.066376,99.602379,5.073987,0.663765,-265.862640,0.067244,0.000000
48.510002,21.344391,-265.818176,-0.002242,0.002623,0.066620,94.944595,4.836708,0.666202,-265.818176,0.067912,0.000000
48.910004,23.247581,-265.862640,-0.002190,0.002669,0.067790,103.410408,5.267977,0.677905,-265.862640,0.068579,0.000000
49.310001,22.682320,-265.951599,-0.002169,0.002692,0.068372,100.895996,5.139887,0.683719,-265.951599,0.069247,0.000000
49.710003,23.147415,-265.907135,-0.002130,0.002721,0.069109,102.964844,5.245279,0.691092,-265.907135,0.069907,0.000000
50.110001,22.918037,-265.996094,-0.002117,0.002745,0.069724,101.944519,5.193301,0.697238,-265.996094,0.070575,0.000000
50.510002,23.071449,-266.040558,-0.002104,0.002770,0.070358,102.626930,5.228065,0.703582,-266.040558,0.071242,0.000000
50.910004,23.324295,-265.996094,-0.002070,0.002802,0.071164,103.751648,5.285361,0.711636,-265.996094,0.071910,0.000000
51.310001,22.960861,-266.040558,-0.002052,0.002823,0.071710,102.135010,5.203006,0.717101,-266.040558,0.072578,0.000000
51.710003,23.057678,-266.129517,-0.002013,0.002852,0.072431,102.565674,5.224945,0.724308,-266.129517,0.073245,0.000000
52.110001,22.776909,-266.085052,-0.001975,0.002874,0.072994,101.316750,5.161321,0.729940,-266.085052,0.073913,0.000000
52.510002,22.779137,-266.085052,-0.001957,0.002900,0.073653,101.326660,5.161826,0.736525,-266.085052,0.074581,0.000000
52.910004,22.921761,-266.218506,-0.001936,0.002931,0.074443,101.961082,5.194145,0.744428,-266.218506,0.075248,0.000000
53.310001,22.616409,-266.174011,-0.001910,0.002955,0.075057,100.602814,5.124951,0.750575,-266.174011,0.075908,0.000000
53.710003,22.627960,-266.262970,-0.001876,0.002982,0.075734,100.654198,5.127569,0.757342,-266.262970,0.076576,0.000000
54.110004,22.222443,-266.262970,-0.001867,0.003002,0.076263,98.850365,5.035677,0.762626,-266.262970,0.077244,0.000000
54.510002,22.779884,-266.262970,-0.001858,0.003037,0.077139,101.329987,5.161996,0.771392,-266.262970,0.077911,0.000000
54.910004,22.377350,-266.307465,-0.001802,0.003058,0.077668,99.539421,5.070780,0.776676,-266.307465,0.078579,0.000000
55.310001,21.903320,-266.351929,-0.001776,0.003079,0.078214,97.430832,4.963363,0.782141,-266.351929,0.079247,0.000000
55.710003,22.433578,-266.351929,-0.001750,0.003111,0.079021,99.789543,5.083521,0.790210,-266.351929,0.079914,0.000000
56.110004,22.046310,-266.396423,-0.001733,0.003129,0.079489,98.066887,4.995766,0.794888,-266.396423,0.080582,0.000000
56.510002,23.258385,-266.396423,-0.001720,0.003168,0.080470,103.458466,5.270425,0.804699,-266.396423,0.081240,0.000000
56.910004,22.708015,-266.529846,-0.001677,0.003189,0.080998,101.010300,5.145710,0.809983,-266.529846,0.081910,0.000000
57.310001,22.667801,-266.529846,-0.001669,0.003216,0.081692,100.831413,5.136597,0.816917,-266.529846,0.082577,0.000000
57.710003,22.860313,-266.529846,-0.001630,0.003240,0.082299,101.687752,5.180221,0.822988,-266.529846,0.083245,0.000000
58.110004,22.462997,-266.529846,-0.001604,0.003258,0.082759,99.920403,5.090188,0.827590,-266.529846,0.083913,0.000000
58.510002,23.578995,-266.574341,-0.001587,0.003293,0.083634,104.884605,5.343077,0.836341,-266.574341,0.084580,0.000000
58.910004,23.450157,-266.574341,-0.001565,0.003316,0.084225,104.311508,5.313882,0.842245,-266.574341,0.085248,0.000000
59.310001,24.362099,-266.618835,-0.001526,0.003351,0.085127,108.368027,5.520530,0.851268,-266.618835,0.085916,0.000000
59.710003,24.008339,-266.663300,-0.001518,0.003371,0.085611,106.794426,5.440367,0.856113,-266.663300,0.086574,0.000000
60.110004,23.740608,-266.663300,-0.001500,0.003390,0.086097,105.603500,5.379699,0.860973,-266.663300,0.087242,0.000000
60.510002,24.457794,-266.752258,-0.001475,0.003423,0.086948,108.793701,5.542216,0.869481,-266.752258,0.087909,0.000000
60.910004,25.093063,-266.752258,-0.001436,0.003450,0.087642,111.619522,5.686169,0.876415,-266.752258,0.088579,0.000000
61.310001,25.478470,-266.841217,-0.001414,0.003476,0.088291,113.333893,5.773504,0.882910,-266.841217,0.089246,0.000000
61.710003,25.484055,-266.796753,-0.001393,0.003499,0.088872,113.358734,5.774769,0.888724,-266.796753,0.089914,0.000000
62.110004,25.153763,-266.885712,-0.001362,0.003517,0.089342,111.889526,5.699924,0.893417,-266.885712,0.090582,0.000000
62.510002,25.451660,-266.930176,-0.001358,0.003542,0.089956,113.214638,5.767429,0.899564,-266.930176,0.091249,0.000000
62.910004,26.985832,-266.930176,-0.001328,0.003581,0.090954,120.038979,6.115077,0.909541,-266.930176,0.091908,0.000000
63.310001,27.458000,-266.974670,-0.001289,0.003610,0.091691,122.139282,6.222072,0.916914,-266.974670,0.092575,0.000000
63.710003,27.346657,-266.974670,-0.001255,0.003631,0.092229,121.644005,6.196841,0.922288,-266.974670,0.093243,0.000000
64.110001,28.254135,-267.019135,-0.001229,0.003662,0.093010,125.680672,6.402479,0.930100,-267.019135,0.093911,0.000000
64.510002,28.710663,-267.019135,-0.001207,0.003689,0.093703,127.711403,6.505929,0.937034,-267.019135,0.094578,0.000000
64.910004,28.594856,-267.063629,-0.001177,0.003709,0.094197,127.196274,6.479687,0.941970,-267.063629,0.095246,0.000000
65.310005,29.248367,-267.063629,-0.001155,0.003737,0.094918,130.103241,6.627775,0.949176,-267.063629,0.095915,0.000000
65.710007,29.933159,-267.108124,-0.001117,0.003764,0.095602,133.149338,6.782951,0.956019,-267.108124,0.096583,0.000000
66.110001,30.845474,-267.152588,-0.001104,0.003793,0.096348,137.207520,6.989685,0.963483,-267.152588,0.097251,0.000000
66.510002,31.337746,-267.197083,-0.001095,0.003819,0.096999,139.397247,7.101234,0.969993,-267.197083,0.097909,0.000000
66.910004,32.089569,-267.197083,-0.001048,0.003849,0.097753,142.741531,7.271601,0.977532,-267.197083,0.098577,0.000000
67.310005,32.740479,-267.286041,-0.001035,0.003874,0.098412,145.636917,7.419098,0.984118,-267.286041,0.099244,0.000000
67.710007,32.730049,-267.241547,-0.001018,0.003892,0.098854,145.590530,7.416735,0.988539,-267.241547,0.099912,0.000000
68.110001,33.536606,-267.286041,-0.000987,0.003918,0.099522,149.178268,7.599504,0.995215,-267.286041,0.100580,0.000000
68.510002,34.631012,-267.330505,-0.000957,0.003948,0.100268,154.046432,7.847499,1.002679,-267.330505,0.101247,0.000000
68.910004,35.529915,-267.375000,-0.000936,0.003975,0.100970,158.044952,8.051193,1.009704,-267.375000,0.101915,0.000000
69.310005,36.804924,-267.375000,-0.000901,0.004004,0.101708,163.716476,8.340116,1.017077,-267.375000,0.102584,0.000000
69.710007,36.886101,-267.419464,-0.000897,0.004019,0.102089,164.077576,8.358510,1.020892,-267.419464,0.103243,0.000000
70.110001,38.272438,-267.463959,-0.000880,0.004052,0.102922,170.244308,8.672658,1.029219,-267.463959,0.103911,0.000000
70.510002,39.428284,-267.463959,-0.000841,0.004078,0.103580,175.385773,8.934577,1.035805,-267.463959,0.104578,0.000000
70.910004,41.143059,-267.552917,-0.000836,0.004111,0.104431,183.013458,9.323151,1.044313,-267.552917,0.105246,0.000000
71.310005,41.922066,-267.597412,-0.000815,0.004134,0.104994,186.478668,9.499676,1.049945,-267.597412,0.105913,0.000000
71.710007,42.377472,-267.597412,-0.000811,0.004154,0.105523,188.504410,9.602873,1.055229,-267.597412,0.106581,0.000000
72.110001,44.855988,-267.597412,-0.000789,0.004191,0.106451,199.529404,10.164512,1.064509,-267.597412,0.107249,0.000000
72.510002,45.603340,-267.641876,-0.000755,0.004212,0.106981,202.853790,10.333864,1.069808,-267.641876,0.107916,0.000000
72.910004,47.204910,-267.641876,-0.000742,0.004241,0.107718,209.977921,10.696786,1.077181,-267.641876,0.108577,0.000000
73.310005,48.133240,-267.730835,-0.000737,0.004263,0.108272,214.107346,10.907147,1.082722,-267.730835,0.109244,0.000000
73.710007,49.411217,-267.730835,-0.000729,0.004292,0.109028,219.792068,11.196742,1.090277,-267.730835,0.109912,0.000000
74.110001,51.695351,-267.775330,-0.000703,0.004321,0.109765,229.952408,11.714334,1.097650,-267.775330,0.110579,0.000000
74.510002,52.542870,-267.819794,-0.000694,0.004344,0.110345,233.722351,11.906384,1.103448,-267.819794,0.111247,0.000000
74.910004,54.279617,-267.775330,-0.000664,0.004373,0.111073,241.447800,12.299937,1.110730,-267.775330,0.111915,0.000000
75.310005,55.693512,-267.908783,-0.000660,0.004396,0.111663,247.737122,12.620331,1.116635,-267.908783,0.112582,0.000000
75.710007,57.382225,-267.908783,-0.000638,0.004421,0.112287,255.248886,13.002998,1.122872,-267.908783,0.113250,0.000000
76.110001,59.525597,-267.908783,-0.000625,0.004449,0.112999,264.783081,13.488692,1.129988,-267.908783,0.113910,0.000000
76.510002,61.056419,-267.997742,-0.000612,0.004474,0.113632,271.592529,13.835583,1.136316,-267.997742,0.114578,0.000000
76.910004,62.613312,-267.908783,-0.000612,0.004498,0.114248,278.517914,14.188379,1.142478,-267.908783,0.115246,0.000000
77.310005,64.364212,-267.953247,-0.000595,0.004524,0.114899,286.306305,14.585138,1.148988,-267.953247,0.115913,0.000000
77.710007,65.359192,-268.042206,-0.000586,0.004548,0.115523,290.732208,14.810605,1.155226,-268.042206,0.116581,0.000000
78.110001,65.919601,-268.042206,-0.000569,0.004548,0.115523,293.225037,14.937595,1.155226,-268.042206,293.448669,0.000000
78.510002,65.239655,-268.086700,-0.000556,0.004555,0.115704,290.200470,14.783518,1.157042,-268.086700,294.500458,0.000000
78.910004,65.138748,-268.175659,-0.000543,0.004561,0.115844,289.751617,14.760652,1.158435,-268.175659,294.500458,0.000000
79.310005,65.204285,-268.131165,-0.000548,0.004565,0.115956,290.043152,14.775502,1.159556,-268.131165,294.500458,0.000000
79.710007,65.263489,-268.220123,-0.000539,0.004571,0.116113,290.306488,14.788918,1.161130,-268.220123,294.500458,0.000000
80.110001,65.311523,-268.220123,-0.000543,0.004576,0.116242,290.520172,14.799802,1.162417,-268.220123,294.500458,0.000000
80.510002,65.515213,-268.220123,-0.000535,0.004582,0.116381,291.426208,14.845960,1.163810,-268.220123,294.500458,0.000000
80.910004,65.340195,-268.309082,-0.000535,0.004584,0.116442,290.647705,14.806300,1.164415,-268.309082,294.500458,0.000000
81.310005,65.275024,-268.309082,-0.000526,0.004587,0.116520,290.357819,14.791532,1.165203,-268.309082,294.500458,0.000000
81.710007,65.237427,-268.309082,-0.000530,0.004590,0.116590,290.190582,14.783012,1.165899,-268.309082,294.500458,0.000000
82.110001,65.355469,-268.398071,-0.000517,0.004595,0.116720,290.715637,14.809761,1.167201,-268.398071,294.500458,0.000000
82.510002,65.288437,-268.442535,-0.000509,0.004596,0.116728,290.417480,14.794571,1.167277,-268.442535,294.500458,0.000000
82.910004,65.321945,-268.442535,-0.000517,0.004599,0.116806,290.566528,14.802165,1.168064,-268.442535,294.500458,0.000000
83.310005,65.289551,-268.442535,-0.000517,0.004601,0.116858,290.422424,14.794824,1.168579,-268.442535,294.500458,0.000000
83.710007,65.250458,-268.442535,-0.000513,0.004602,0.116902,290.248535,14.785965,1.169018,-268.442535,294.500458,0.000000
84.110001,65.176727,-268.575989,-0.000517,0.004603,0.116928,289.920563,14.769257,1.169275,-268.575989,294.500458,0.000000
84.510002,65.191620,-268.575989,-0.000513,0.004605,0.116962,289.986816,14.772633,1.169623,-268.575989,294.500458,0.000000
84.910004,65.159973,-268.531494,-0.000500,0.004607,0.117014,289.846039,14.765461,1.170138,-268.531494,294.500458,0.000000
85.310005,65.334610,-268.664948,-0.000526,0.004610,0.117093,290.622864,14.805035,1.170925,-268.664948,294.500458,0.000000
85.710007,65.255295,-268.664948,-0.000509,0.004610,0.117093,290.270050,14.787061,1.170925,-268.664948,294.500458,0.000000
86.110001,65.339828,-268.620453,-0.000517,0.004614,0.117197,290.646088,14.806217,1.171970,-268.620453,294.500458,0.000000
86.510002,65.332382,-268.709412,-0.000504,0.004614,0.117197,290.612946,14.804529,1.171970,-268.709412,294.500458,0.000000
86.910004,65.272049,-268.753906,-0.000504,0.004614,0.117205,290.344574,14.790857,1.172046,-268.753906,294.500458,0.000000
87.310005,65.204285,-268.753906,-0.000509,0.004617,0.117274,290.043152,14.775502,1.172742,-268.753906,294.500458,0.000000
87.710007,65.318604,-268.798401,-0.000487,0.004618,0.117292,290.551666,14.801407,1.172924,-268.798401,294.500458,0.000000
88.110001,65.278748,-268.842865,-0.000483,0.004618,0.117309,290.374359,14.792376,1.173090,-268.842865,294.500458,0.000000
88.510002,65.334610,-268.842865,-0.000496,0.004620,0.117361,290.622864,14.805035,1.173605,-268.842865,294.500458,0.000000
88.910004,65.325668,-268.887360,-0.000483,0.004621,0.117379,290.583099,14.803008,1.173787,-268.887360,294.500458,0.000000
89.310005,65.309296,-268.931824,-0.000487,0.004623,0.117413,290.510254,14.799298,1.174135,-268.931824,294.500458,0.000000
89.710007,65.295135,-268.931824,-0.000504,0.004623,0.117430,290.447266,14.796089,1.174302,-268.931824,294.500458,0.000000
90.110001,65.355835,-268.976318,-0.000479,0.004626,0.117491,290.717285,14.809844,1.174907,-268.976318,294.500458,0.000000
90.510002,65.397919,-269.109741,-0.000487,0.004626,0.117491,290.904480,14.819380,1.174907,-269.109741,294.500458,0.000000
90.910004,65.349884,-269.065277,-0.000509,0.004627,0.117518,290.690796,14.808496,1.175180,-269.065277,294.500458,0.000000
91.310005,65.339447,-269.109741,-0.000492,0.004627,0.117526,290.644379,14.806130,1.175255,-269.109741,294.500458,0.000000
91.710007,65.339828,-269.065277,-0.000487,0.004628,0.117544,290.646088,14.806217,1.175437,-269.065277,294.500458,0.000000
92.110001,65.353607,-269.154236,-0.000492,0.004628,0.117544,290.707367,14.809340,1.175437,-269.154236,294.500458,0.000000
92.510002,65.355469,-269.154236,-0.000496,0.004630,0.117595,290.715637,14.809761,1.175952,-269.154236,294.500458,0.000000
92.910004,65.346146,-269.198730,-0.000487,0.004630,0.117595,290.674164,14.807648,1.175952,-269.198730,294.500458,0.000000
93.310005,65.319336,-269.198730,-0.000496,0.004630,0.117604,290.554932,14.801573,1.176043,-269.198730,294.500458,0.000000
93.710007,65.295517,-269.243195,-0.000487,0.004630,0.117613,290.448975,14.796175,1.176133,-269.243195,294.500458,0.000000
94.110008,65.287689,-269.287689,-0.000492,0.004632,0.117647,290.414154,14.794401,1.176466,-269.287689,294.500458,0.000000
94.510002,65.282104,-269.332153,-0.000492,0.004632,0.117647,290.389313,14.793136,1.176466,-269.332153,294.500458,0.000000
94.910004,65.280243,-269.376648,-0.000487,0.004633,0.117674,290.381012,14.792715,1.176739,-269.376648,294.500458,0.000000
95.310005,65.294022,-269.376648,-0.000487,0.004633,0.117691,290.442322,14.795836,1.176906,-269.376648,294.500458,0.000000
95.710007,65.289932,-269.421112,-0.000492,0.004633,0.117691,290.424133,14.794909,1.176906,-269.421112,294.500458,0.000000
96.110008,65.289185,-269.465607,-0.000496,0.004634,0.117716,290.420807,14.794741,1.177163,-269.465607,294.500458,0.000000
96.510002,65.287323,-269.465607,-0.000496,0.004635,0.117734,290.412506,14.794319,1.177345,-269.465607,294.500458,0.000000
96.910004,65.273163,-269.510071,-0.000474,0.004636,0.117742,290.349518,14.791110,1.177420,-269.510071,294.500458,0.000000
97.310005,65.313019,-269.554565,-0.000479,0.004636,0.117760,290.526825,14.800141,1.177602,-269.554565,294.500458,0.000000
97.710007,65.282104,-269.599030,-0.000487,0.004636,0.117760,290.389313,14.793136,1.177602,-269.599030,294.500458,0.000000
98.110008,65.269440,-269.688019,-0.000492,0.004637,0.117777,290.332977,14.790266,1.177768,-269.688019,294.500458,0.000000
98.510002,65.267212,-269.688019,-0.000479,0.004638,0.117795,290.323059,14.789762,1.177950,-269.688019,294.500458,0.000000
98.910004,65.254929,-269.688019,-0.000496,0.004638,0.117804,290.268433,14.786978,1.178041,-269.688019,294.500458,0.000000
99.310005,65.243744,-269.732483,-0.000500,0.004638,0.117812,290.218658,14.784444,1.178117,-269.732483,294.500458,0.000000
99.710007,65.288437,-269.776978,-0.000487,0.004640,0.117856,290.417480,14.794571,1.178556,-269.776978,294.500458,0.000000
100.110008,65.301102,-269.732483,-0.000483,0.004640,0.117856,290.473816,14.797441,1.178556,-269.732483,294.500458,0.000000
100.510002,65.287689,-269.821442,-0.000483,0.004640,0.117856,290.414154,14.794401,1.178556,-269.821442,294.500458,0.000000
100.910004,65.260880,-269.821442,-0.000492,0.004640,0.117856,290.294891,14.788326,1.178556,-269.821442,294.500458,0.000000
101.310005,65.237045,-269.910400,-0.000483,0.004642,0.117899,290.188873,14.782926,1.178995,-269.910400,294.500458,0.000000
101.710007,65.270187,-269.865936,-0.000483,0.004642,0.117899,290.336304,14.790436,1.178995,-269.865936,294.500458,0.000000
102.110008,65.267578,-269.954895,-0.000479,0.004642,0.117899,290.324677,14.789845,1.178995,-269.954895,294.500458,0.000000
102.510002,65.240402,-269.954895,-0.000487,0.004642,0.117899,290.203796,14.783687,1.178995,-269.954895,294.500458,0.000000
102.910004,65.209869,-269.954895,-0.000483,0.004642,0.117907,290.067993,14.776768,1.179070,-269.954895,294.500458,0.000000
103.310005,65.212845,-269.999359,-0.000487,0.004642,0.117916,290.081207,14.777442,1.179161,-269.999359,294.500458,0.000000
103.710007,65.183060,-270.043854,-0.000487,0.004642,0.117916,289.948730,14.770692,1.179161,-270.043854,294.500458,0.000000
104.110008,65.194595,-270.043854,-0.000483,0.004643,0.117925,290.000031,14.773306,1.179252,-270.043854,294.500458,0.000000
104.510002,65.162567,-270.088348,-0.000487,0.004643,0.117933,289.857574,14.766049,1.179328,-270.088348,294.500458,0.000000
104.910004,65.185287,-270.177307,-0.000487,0.004645,0.117977,289.958649,14.771197,1.179767,-270.177307,294.500458,0.000000
105.310005,65.283966,-270.177307,-0.000474,0.004645,0.117995,290.397583,14.793558,1.179949,-270.177307,294.500458,0.000000
105.710007,65.297745,-270.266266,-0.000479,0.004646,0.118002,290.458862,14.796680,1.180024,-270.266266,294.500458,0.000000
106.110008,65.277634,-270.221771,-0.000492,0.004646,0.118002,290.369415,14.792123,1.180024,-270.221771,294.500458,0.000000
106.510002,65.276520,-270.310730,-0.000479,0.004646,0.118002,290.364471,14.791870,1.180024,-270.310730,294.500458,0.000000
106.910004,65.253799,-270.266266,-0.000479,0.004646,0.118012,290.263397,14.786722,1.180115,-270.266266,294.500458,0.000000
107.310005,65.240021,-270.355225,-0.000479,0.004646,0.118012,290.202118,14.783600,1.180115,-270.355225,294.500458,0.000000
107.710007,65.251572,-270.310730,-0.000487,0.004646,0.118021,290.253479,14.786218,1.180206,-270.310730,294.500458,0.000000
108.110008,65.245987,-270.355225,-0.000483,0.004647,0.118028,290.228638,14.784952,1.180282,-270.355225,294.500458,0.000000
108.510002,65.246735,-270.355225,-0.000474,0.004648,0.118063,290.231964,14.785122,1.180630,-270.355225,294.500458,0.000000
108.910004,65.261627,-270.444183,-0.000474,0.004648,0.118063,290.298218,14.788496,1.180630,-270.444183,294.500458,0.000000
109.310005,65.268326,-270.488678,-0.000479,0.004648,0.118063,290.328003,14.790014,1.180630,-270.488678,294.500458,0.000000
109.710007,65.265350,-270.444183,-0.000479,0.004648,0.118063,290.314789,14.789339,1.180630,-270.444183,294.500458,0.000000
110.110008,65.252686,-270.488678,-0.000483,0.004649,0.118072,290.258453,14.786469,1.180721,-270.488678,294.500458,0.000000
110.510002,65.224762,-270.577637,-0.000479,0.004649,0.118072,290.134216,14.780142,1.180721,-270.577637,294.500458,0.000000
110.910004,65.224014,-270.533142,-0.000487,0.004649,0.118090,290.130920,14.779973,1.180902,-270.533142,294.500458,0.000000
111.310005,65.220291,-270.622101,-0.000474,0.004649,0.118090,290.114349,14.779129,1.180902,-270.622101,294.500458,0.000000
111.710007,65.230713,-270.577637,-0.000474,0.004650,0.118107,290.160706,14.781491,1.181069,-270.577637,294.500458,0.000000
112.110008,65.221405,-270.622101,-0.000479,0.004650,0.118107,290.119293,14.779382,1.181069,-270.622101,294.500458,0.000000
112.510002,65.210617,-270.666595,-0.000479,0.004650,0.118116,290.071320,14.776937,1.181160,-270.666595,294.500458,0.000000
112.910004,65.257523,-270.711060,-0.000474,0.004651,0.118142,290.279968,14.787565,1.181417,-270.711060,294.500458,0.000000
113.310005,65.267212,-270.711060,-0.000487,0.004651,0.118142,290.323059,14.789762,1.181417,-270.711060,294.500458,0.000000
113.710007,65.251572,-270.755554,-0.000470,0.004652,0.118151,290.253479,14.786218,1.181508,-270.755554,294.500458,0.000000
114.110008,65.259018,-270.800018,-0.000483,0.004652,0.118151,290.286621,14.787905,1.181508,-270.800018,294.500458,0.000000
114.510002,65.245987,-270.844513,-0.000483,0.004652,0.118158,290.228638,14.784952,1.181584,-270.844513,294.500458,0.000000
114.910004,65.245239,-270.844513,-0.000479,0.004652,0.118158,290.225311,14.784782,1.181584,-270.844513,294.500458,0.000000
115.310005,65.242264,-270.888977,-0.000470,0.004652,0.118158,290.212097,14.784108,1.181584,-270.888977,294.500458,0.000000
115.710007,65.225128,-270.888977,-0.000474,0.004652,0.118167,290.135864,14.780226,1.181674,-270.888977,294.500458,0.000000
116.110008,65.237793,-270.977966,-0.000474,0.004653,0.118177,290.192200,14.783095,1.181765,-270.977966,294.500458,0.000000
116.510002,65.230347,-271.022430,-0.000487,0.004653,0.118193,290.159088,14.781407,1.181932,-271.022430,294.500458,0.000000
116.910004,65.229980,-270.977966,-0.000474,0.004653,0.118193,290.157440,14.781325,1.181932,-270.977966,294.500458,0.000000
117.310005,65.229599,-271.066925,-0.000474,0.004653,0.118193,290.155762,14.781239,1.181932,-271.066925,294.500458,0.000000
117.710007,65.203156,-271.111389,-0.000470,0.004653,0.118193,290.038116,14.775247,1.181932,-271.111389,294.500458,0.000000
118.110008,65.193481,-271.155884,-0.000470,0.004654,0.118202,289.995087,14.773054,1.182023,-271.155884,294.500458,0.000000
118.510002,65.201675,-271.111389,-0.000483,0.004654,0.118211,290.031525,14.774911,1.182114,-271.111389,294.500458,0.000000
118.910004,65.193481,-271.155884,-0.000483,0.004654,0.118211,289.995087,14.773054,1.182114,-271.155884,294.500458,0.000000
119.310005,65.195343,-271.155884,-0.000470,0.004654,0.118211,290.003357,14.773476,1.182114,-271.155884,294.500458,0.000000
119.710007,65.178207,-271.200348,-0.000479,0.004654,0.118211,289.927155,14.769593,1.182114,-271.200348,294.500458,0.000000
120.110008,65.144333,-271.289307,-0.000470,0.004654,0.118220,289.776459,14.761917,1.182204,-271.289307,294.500458,0.000000
120.510002,65.132416,-271.289307,-0.000479,0.004654,0.118220,289.723450,14.759216,1.182204,-271.289307,294.500458,0.000000
120.910004,65.116394,-271.333801,-0.000479,0.004654,0.118220,289.652191,14.755586,1.182204,-271.333801,294.500458,0.000000
121.310005,65.104111,-271.378296,-0.000479,0.004654,0.118220,289.597534,14.752803,1.182204,-271.378296,294.500458,0.000000
121.710007,65.070221,-271.378296,-0.000470,0.004654,0.118220,289.446808,14.745123,1.182204,-271.378296,294.500458,0.000000
122.110008,65.063889,-271.511719,-0.000479,0.004654,0.118220,289.418640,14.743688,1.182204,-271.511719,294.500458,0.000000
122.510002,65.065384,-271.422760,-0.000470,0.004655,0.118228,289.425293,14.744026,1.182280,-271.422760,294.500458,0.000000
122.910004,65.051971,-271.556213,-0.000483,0.004655,0.118237,289.365631,14.740987,1.182371,-271.556213,294.500458,0.000000
123.310005,65.046021,-271.556213,-0.000470,0.004655,0.118246,289.339142,14.739638,1.182462,-271.556213,294.500458,0.000000
123.710007,65.040070,-271.556213,-0.000470,0.004655,0.118246,289.312683,14.738291,1.182462,-271.556213,294.500458,0.000000
124.110008,65.036346,-271.556213,-0.000474,0.004655,0.118246,289.296112,14.737447,1.182462,-271.556213,294.500458,0.000000
124.510002,65.034485,-271.600677,-0.000470,0.004656,0.118254,289.287842,14.737025,1.182537,-271.600677,294.500458,0.000000
124.910004,65.020325,-271.600677,-0.000479,0.004656,0.118263,289.224854,14.733816,1.182628,-271.600677,294.500458,0.000000
125.310005,65.019577,-271.645172,-0.000474,0.004656,0.118263,289.221527,14.733647,1.182628,-271.645172,294.500458,0.000000
125.710007,65.020706,-271.734131,-0.000461,0.004656,0.118272,289.226532,14.733903,1.182719,-271.734131,294.500458,0.000000
126.110008,65.009155,-271.734131,-0.000466,0.004656,0.118272,289.175171,14.731285,1.182719,-271.734131,294.500458,0.000000
126.510010,65.008041,-271.778625,-0.000453,0.004656,0.118272,289.170197,14.731032,1.182719,-271.778625,294.500458,0.000000
126.910004,65.006927,-271.734131,-0.000466,0.004657,0.118281,289.165253,14.730780,1.182810,-271.734131,294.500458,0.000000
127.310005,64.991653,-271.867584,-0.000474,0.004657,0.118281,289.097321,14.727320,1.182810,-271.867584,294.500458,0.000000
127.710007,64.988678,-271.867584,-0.000479,0.004657,0.118298,289.084076,14.726645,1.182976,-271.867584,294.500458,0.000000
128.110001,65.006927,-271.912048,-0.000461,0.004657,0.118298,289.165253,14.730780,1.182976,-271.912048,294.500458,0.000000
128.510010,65.005798,-271.867584,-0.000474,0.004658,0.118307,289.160248,14.730524,1.183067,-271.867584,294.500458,0.000000
128.910004,65.007660,-271.956543,-0.000479,0.004658,0.118307,289.168518,14.730947,1.183067,-271.956543,294.500458,0.000000
129.310013,64.989792,-271.956543,-0.000474,0.004658,0.118307,289.089020,14.726897,1.183067,-271.956543,294.500458,0.000000
129.710007,64.977875,-271.956543,-0.000479,0.004658,0.118307,289.036011,14.724196,1.183067,-271.956543,294.500458,0.000000
130.110001,64.976761,-271.956543,-0.000474,0.004658,0.118307,289.031067,14.723944,1.183067,-271.956543,294.500458,0.000000
130.510010,64.976013,-272.045502,-0.000474,0.004658,0.118307,289.027740,14.723775,1.183067,-272.045502,294.500458,0.000000
130.910004,64.953293,-272.089966,-0.000461,0.004658,0.118307,288.926666,14.718627,1.183067,-272.089966,294.500458,0.000000
131.310013,64.922028,-272.089966,-0.000466,0.004658,0.118307,288.787598,14.711542,1.183067,-272.089966,294.500458,0.000000
131.710007,64.927231,-272.134460,-0.000457,0.004658,0.118316,288.810760,14.712721,1.183158,-272.134460,294.500458,0.000000
132.110001,64.978622,-272.178925,-0.000470,0.004660,0.118376,289.039337,14.724366,1.183764,-272.178925,294.500458,0.000000
132.510010,65.034851,-272.178925,-0.000479,0.004660,0.118376,289.289459,14.737107,1.183764,-272.178925,294.500458,0.000000
132.910004,65.030014,-272.223419,-0.000474,0.004660,0.118376,289.267944,14.736012,1.183764,-272.223419,294.500458,0.000000
133.310013,65.035965,-272.267914,-0.000483,0.004660,0.118376,289.294434,14.737360,1.183764,-272.267914,294.500458,0.000000
133.710007,65.025162,-272.267914,-0.000470,0.004660,0.118376,289.246368,14.734913,1.183764,-272.267914,294.500458,0.000000
134.110001,65.016983,-272.356873,-0.000474,0.004660,0.118376,289.209991,14.733059,1.183764,-272.356873,294.500458,0.000000
134.510010,65.033737,-272.401337,-0.000466,0.004660,0.118376,289.284515,14.736856,1.183764,-272.401337,294.500458,0.000000
134.910004,65.019958,-272.401337,-0.000483,0.004660,0.118376,289.223206,14.733733,1.183764,-272.401337,294.500458,0.000000
135.310013,65.002457,-272.445831,-0.000470,0.004660,0.118376,289.145355,14.729767,1.183764,-272.445831,294.500458,0.000000
135.710007,64.980118,-272.445831,-0.000461,0.004660,0.118376,289.045990,14.724706,1.183764,-272.445831,294.500458,0.000000
136.110001,64.975647,-272.490295,-0.000470,0.004660,0.118376,289.026123,14.723693,1.183764,-272.490295,294.500458,0.000000
136.510010,64.982346,-272.534790,-0.000483,0.004660,0.118376,289.055908,14.725209,1.183764,-272.534790,294.500458,0.000000
136.910004,64.972290,-272.623749,-0.000470,0.004660,0.118376,289.011169,14.722932,1.183764,-272.623749,294.500458,0.000000
137.310013,64.958511,-272.579254,-0.000457,0.004660,0.118376,288.949890,14.719809,1.183764,-272.579254,294.500458,0.000000
137.710007,64.947708,-272.579254,-0.000483,0.004661,0.118384,288.901825,14.717361,1.183839,-272.579254,294.500458,0.000000
138.110001,64.927231,-272.623749,-0.000461,0.004661,0.118384,288.810760,14.712721,1.183839,-272.623749,294.500458,0.000000
138.510010,64.889252,-272.623749,-0.000457,0.004652,0.118167,288.641815,14.704115,1.181674,-272.623749,0.118349,0.000000
138.910004,64.796524,-272.623749,-0.000470,0.004641,0.117890,288.229340,14.683103,1.178904,-272.623749,0.117681,0.000000
139.310013,64.746262,-272.712708,-0.000470,0.004622,0.117395,288.005768,14.671712,1.173953,-272.712708,0.117014,0.000000
139.710007,64.707535,-272.712708,-0.000461,0.004604,0.116953,287.833496,14.662937,1.169533,-272.712708,0.116346,0.000000
140.110001,64.662476,-272.757202,-0.000457,0.004575,0.116199,287.633057,14.652726,1.161993,-272.757202,0.115678,0.000000
140.510010,64.620392,-272.846161,-0.000461,0.004549,0.115548,287.445862,14.643189,1.155483,-272.846161,0.115011,0.000000
140.910004,64.660980,-272.846161,-0.000457,0.004518,0.114750,287.626404,14.652388,1.147504,-272.846161,0.114352,0.000000
141.310013,64.587997,-272.801666,-0.000448,0.004500,0.114292,287.301758,14.635849,1.142917,-272.801666,0.113685,0.000000
141.710007,64.580185,-272.890625,-0.000474,0.004478,0.113753,287.266998,14.634080,1.137527,-272.890625,0.113017,0.000000
142.110001,64.508682,-272.935120,-0.000461,0.004447,0.112947,286.948944,14.617876,1.129473,-272.935120,0.112349,0.000000
142.510010,64.427139,-272.890625,-0.000457,0.004420,0.112261,286.586243,14.599399,1.122615,-272.890625,0.111680,0.000000
142.910004,64.042480,-272.979584,-0.000474,0.004394,0.111620,284.875183,14.512234,1.116196,-272.979584,0.111012,0.000000
143.310013,63.362518,-273.068573,-0.000466,0.004375,0.111126,281.850555,14.358152,1.111260,-273.068573,0.110345,0.000000
143.710007,62.284882,-272.979584,-0.000466,0.004351,0.110528,277.056976,14.113955,1.105280,-272.979584,0.109677,0.000000
144.110001,60.722778,-273.068573,-0.000457,0.004326,0.109868,270.108398,13.759978,1.098679,-273.068573,0.109019,0.000000
144.510010,58.742126,-273.113037,-0.000479,0.004298,0.109175,261.298035,13.311156,1.091745,-273.113037,0.108351,0.000000
144.910004,56.794991,-273.201996,-0.000448,0.004274,0.108558,252.636734,12.869929,1.085584,-273.201996,0.107683,0.000000
145.310013,54.722366,-273.068573,-0.000440,0.004253,0.108030,243.417236,12.400266,1.080300,-273.068573,0.107016,0.000000
145.710007,52.248695,-273.157532,-0.000427,0.004229,0.107414,232.413803,11.839724,1.074138,-273.157532,0.106348,0.000000
146.110001,49.218330,-273.246490,-0.000440,0.004200,0.106677,218.934067,11.153033,1.066765,-273.246490,0.105680,0.000000
146.510010,46.391281,-273.246490,-0.000427,0.004176,0.106062,206.358719,10.512415,1.060618,-273.246490,0.105011,0.000000
146.910004,43.103226,-273.201996,-0.000423,0.004145,0.105272,191.732727,9.767330,1.052716,-273.201996,0.104343,0.000000
147.310013,40.734192,-273.246490,-0.000435,0.004126,0.104804,181.194733,9.230499,1.048037,-273.246490,0.103676,0.000000
147.710007,37.576851,-273.290955,-0.000427,0.004098,0.104085,167.150177,8.515037,1.040846,-273.290955,0.103017,0.000000
148.110001,34.304810,-273.379913,-0.000423,0.004066,0.103269,152.595413,7.773581,1.032686,-273.379913,0.102350,0.000000
148.510010,31.924606,-273.379913,-0.000435,0.004045,0.102740,142.007736,7.234219,1.027402,-273.379913,0.101682,0.000000
148.910004,27.658333,-273.424408,-0.000423,0.004006,0.101759,123.030411,6.267468,1.017592,-273.424408,0.101014,0.000000
149.310013,26.073517,-273.424408,-0.000423,0.003993,0.101422,115.980797,5.908343,1.014216,-273.424408,0.100347,0.000000
149.710007,23.321312,-273.468872,-0.000418,0.003967,0.100754,103.738380,5.284685,1.007539,-273.468872,0.099679,0.000000
150.110001,20.831261,-273.468872,-0.000423,0.003946,0.100224,92.662079,4.720431,1.002240,-273.468872,0.099011,0.000000
150.510010,18.178848,-273.513367,-0.000435,0.003919,0.099540,80.863556,4.119386,0.995397,-273.513367,0.098342,0.000000
150.910004,14.178452,-273.557861,-0.000431,0.003885,0.098681,63.068901,3.212883,0.986813,-273.557861,0.097684,0.000000
151.310013,11.656006,-273.557861,-0.000440,0.003861,0.098074,51.848503,2.641289,0.980742,-273.557861,0.097016,0.000000
151.710007,8.160545,-273.602325,-0.000427,0.003831,0.097311,36.299919,1.849206,0.973112,-273.602325,0.096348,0.000000
152.110001,6.143402,-273.646820,-0.000423,0.003810,0.096781,27.327217,1.392115,0.967813,-273.646820,0.095681,0.000000
152.510010,2.883278,-273.691284,-0.000440,0.003782,0.096071,12.825460,0.653360,0.960712,-273.691284,0.095013,0.000000
152.910004,-0.916039,-273.691284,-0.000423,0.003744,0.095108,-4.074743,-0.207577,0.951084,-273.691284,0.094345,0.000000
153.310013,-2.101299,-273.691284,-0.000440,0.003734,0.094831,-9.347046,-0.476161,0.948313,-273.691284,0.093678,0.000000
153.710007,-0.088997,-273.735779,-0.000418,0.003703,0.094067,-0.395878,-0.020167,0.940668,-273.735779,0.093010,0.000000
154.110001,0.131821,-273.780243,-0.000427,0.003680,0.093469,0.586368,0.029871,0.934687,-273.780243,0.092350,0.000000
154.510010,0.120277,-273.780243,-0.000423,0.003649,0.092697,0.535021,0.027255,0.926966,-273.780243,0.091682,0.000000
154.910004,0.122513,-273.824738,-0.000401,0.003623,0.092029,0.544964,0.027762,0.920290,-273.824738,0.091015,0.000000
155.310013,0.093834,-273.869202,-0.000410,0.003603,0.091526,0.417394,0.021263,0.915263,-273.869202,0.090347,0.000000
155.710007,0.084900,-273.913696,-0.000405,0.003581,0.090954,0.377654,0.019239,0.909541,-273.913696,0.089679,0.000000
156.110001,0.043938,-273.958191,-0.000401,0.003548,0.090130,0.195445,0.009956,0.901305,-273.958191,0.089012,0.000000
156.510010,-0.018990,-274.002655,-0.000414,0.003518,0.089367,-0.084470,-0.004303,0.893674,-274.002655,0.088344,0.000000
156.910004,-0.006332,-274.047150,-0.000418,0.003492,0.088707,-0.028168,-0.001435,0.887073,-274.047150,0.087676,0.000000
157.310013,-0.042450,-274.047150,-0.000427,0.003476,0.088283,-0.188827,-0.009619,0.882834,-274.047150,0.087016,0.000000
157.710007,-0.045059,-274.091614,-0.000479,0.003444,0.087476,-0.200433,-0.010211,0.874765,-274.091614,0.086349,0.000000
158.110001,-0.037613,-274.091614,-0.000569,0.003409,0.086592,-0.167311,-0.008523,0.865923,-274.091614,0.085681,0.000000
158.510010,-0.047295,-274.136108,-0.000608,0.003390,0.086097,-0.210377,-0.010717,0.860973,-274.136108,0.085013,0.000000
158.910004,-0.073357,-274.136108,-0.000647,0.003361,0.085378,-0.326307,-0.016623,0.853781,-274.136108,0.084346,0.000000
159.310013,-0.098679,-274.136108,-0.000677,0.003344,0.084944,-0.438944,-0.022361,0.849436,-274.136108,0.083678,0.000000
159.710007,-0.106499,-274.225067,-0.000724,0.003319,0.084311,-0.473730,-0.024133,0.843108,-274.225067,0.083010,0.000000
160.110001,-0.069633,-274.269531,-0.000819,0.003278,0.083271,-0.309745,-0.015779,0.832707,-274.269531,0.082343,0.000000
160.510010,-0.075592,-274.269531,-0.000849,0.003259,0.082776,-0.336250,-0.017129,0.827757,-274.269531,0.081684,0.000000
160.910004,-0.071495,-274.314026,-0.000901,0.003232,0.082091,-0.318026,-0.016201,0.820913,-274.314026,0.081016,0.000000
161.310013,-0.083786,-274.314026,-0.000957,0.003206,0.081440,-0.372699,-0.018986,0.814403,-274.314026,0.080347,0.000000
161.710007,-0.102776,-274.358521,-0.000983,0.003178,0.080721,-0.457169,-0.023289,0.807212,-274.358521,0.079680,0.000000
162.110001,-0.103889,-274.402985,-0.001030,0.003151,0.080044,-0.462123,-0.023542,0.800445,-274.402985,0.079012,0.000000
162.510010,-0.043198,-274.402985,-0.001052,0.003129,0.079472,-0.192153,-0.009789,0.794722,-274.402985,0.078344,0.000000
162.910004,-0.068893,-274.447479,-0.001099,0.003103,0.078805,-0.306453,-0.015611,0.788045,-274.447479,0.077677,0.000000
163.310013,-0.055115,-274.447479,-0.001134,0.003081,0.078249,-0.245163,-0.012489,0.782489,-274.447479,0.077009,0.000000
163.710007,-0.070007,-274.447479,-0.001173,0.003045,0.077347,-0.311408,-0.015864,0.773466,-274.447479,0.076341,0.000000
164.110001,-0.094955,-274.491943,-0.001220,0.003017,0.076637,-0.422383,-0.021517,0.766366,-274.491943,0.075683,0.000000
164.510010,-0.048782,-274.580902,-0.001237,0.002992,0.075995,-0.216995,-0.011054,0.759946,-274.580902,0.075015,0.000000
164.910004,-0.061440,-274.625397,-0.001259,0.002966,0.075336,-0.273297,-0.013922,0.753361,-274.625397,0.074347,0.000000
165.310013,-0.052132,-274.625397,-0.001302,0.002945,0.074806,-0.231893,-0.011813,0.748062,-274.625397,0.073678,0.000000
165.600006,-0.075218,-274.669861,-0.001319,0.002927,0.074355,-0.334587,-0.017045,0.743550,-274.669861,0.074243,0.000000