File: Data/compression 31/ManualNoHeating-15-31-reverse-1-1_11132024_174658.csv
Time (sec),S:Load (lbs),S:HL1 (DIM),S:LVDT (in),S:Position (in),Ch:Position (mm),Ch:Load (N),Ch:Stress (MPa),Ch:Strain (mm/mm),Ch:HL1 (DIM),Set Point (),Cycles ()
0.110000,-0.054367,-201.320786,-0.010098,-0.005291,-0.134403,-0.241837,-0.012320,-1.344031,-201.320786,-0.134212,0.000000
0.510000,-0.053619,-201.409744,-0.010098,-0.005220,-0.132598,-0.238511,-0.012150,-1.325985,-201.409744,-0.132113,0.000000
0.910000,-0.001122,-201.409744,-0.009973,-0.004990,-0.126736,-0.004989,-0.000254,-1.267365,-201.409744,-0.125453,0.000000
1.310000,-0.036865,-201.409744,-0.009718,-0.004726,-0.120042,-0.163985,-0.008354,-1.200417,-201.409744,-0.118793,0.000000
1.710000,-0.061073,-201.454224,-0.009421,-0.004451,-0.113052,-0.271668,-0.013839,-1.130518,-201.454224,-0.112133,0.000000
2.110000,-0.060326,-201.498703,-0.009171,-0.004186,-0.106330,-0.268342,-0.013670,-1.063298,-201.498703,-0.105455,0.000000
2.510000,-0.020485,-201.632156,-0.008886,-0.003926,-0.099723,-0.091121,-0.004642,-0.997229,-201.632156,-0.098795,0.000000
2.910000,-0.042450,-201.676636,-0.008610,-0.003667,-0.093149,-0.188827,-0.009619,-0.931493,-201.676636,-0.092133,0.000000
3.310000,-0.043571,-201.676636,-0.008347,-0.003409,-0.086583,-0.193816,-0.009873,-0.865833,-201.676636,-0.085474,0.000000
3.710000,-0.066284,-201.765594,-0.008080,-0.003149,-0.079984,-0.294847,-0.015020,-0.799839,-201.765594,-0.078814,0.000000
4.110000,-0.105385,-201.765594,-0.007812,-0.002881,-0.073168,-0.468775,-0.023881,-0.731681,-201.765594,-0.072136,0.000000
4.510000,-0.067772,-201.810074,-0.007545,-0.002621,-0.066585,-0.301465,-0.015357,-0.665854,-201.810074,-0.065476,0.000000
4.910000,-0.039848,-201.854553,-0.007256,-0.002361,-0.059968,-0.177254,-0.009030,-0.599679,-201.854553,-0.058816,0.000000
5.310000,-0.029045,-201.854553,-0.006980,-0.002092,-0.053143,-0.129199,-0.006582,-0.531430,-201.854553,-0.052154,0.000000
5.710000,-0.049156,-201.899033,-0.006709,-0.001831,-0.046501,-0.218658,-0.011139,-0.465012,-201.899033,-0.045494,0.000000
6.110000,-0.039101,-201.987991,-0.006437,-0.001567,-0.039805,-0.173928,-0.008860,-0.398050,-201.987991,-0.038816,0.000000
6.510000,-0.014526,-201.987991,-0.006178,-0.001311,-0.033293,-0.064617,-0.003292,-0.332934,-201.987991,-0.032156,0.000000
6.910000,-0.007820,-202.032486,-0.005911,-0.001051,-0.026702,-0.034786,-0.001772,-0.267017,-202.032486,-0.025497,0.000000
7.310000,0.008194,-202.076965,-0.005648,-0.000796,-0.020223,0.036449,0.001857,-0.202235,-202.076965,-0.018837,0.000000
7.710001,-0.028297,-202.121445,-0.005398,-0.000531,-0.013477,-0.125873,-0.006412,-0.134773,-202.121445,-0.012175,0.000000
8.110001,-0.028297,-202.076965,-0.005092,-0.000252,-0.006392,-0.125873,-0.006412,-0.063919,-202.076965,-0.005499,0.000000
8.510000,0.163101,-202.165924,-0.004829,0.000008,0.000200,0.725510,0.036959,0.001998,-202.165924,0.001040,0.000000
8.910001,0.181343,-202.210403,-0.004816,-0.000001,-0.000017,0.806654,0.041093,-0.000167,-202.210403,0.000156,0.000000
9.310000,0.140755,-202.210403,-0.004820,-0.000001,-0.000017,0.626108,0.031895,-0.000167,-202.210403,0.000547,0.000000
9.710000,0.184326,-202.299362,-0.004816,0.000014,0.000347,0.819924,0.041769,0.003467,-202.299362,0.001214,0.000000
10.110001,0.310555,-202.343842,-0.004812,0.000035,0.000877,1.381415,0.070373,0.008766,-202.343842,0.001874,0.000000
10.510000,0.737671,-202.343842,-0.004764,0.000068,0.001735,3.281324,0.167159,0.017350,-202.343842,0.002542,0.000000
10.910001,0.982315,-202.432816,-0.004760,0.000084,0.002133,4.369555,0.222596,0.021332,-202.432816,0.003210,0.000000
11.310000,1.546089,-202.388321,-0.004717,0.000125,0.003184,6.877348,0.350349,0.031839,-202.388321,0.003877,0.000000
11.710001,1.813828,-202.521774,-0.004700,0.000144,0.003668,8.068308,0.411019,0.036683,-202.521774,0.004545,0.000000
12.110001,2.189919,-202.521774,-0.004691,0.000171,0.004336,9.741244,0.496243,0.043360,-202.521774,0.005213,0.000000
12.510000,2.733589,-202.610733,-0.004678,0.000199,0.005057,12.159612,0.619440,0.050566,-202.610733,0.005880,0.000000
12.910001,3.014725,-202.566254,-0.004644,0.000217,0.005524,13.410166,0.683146,0.055244,-202.566254,0.006548,0.000000
13.310000,3.703247,-202.655212,-0.004609,0.000252,0.006409,16.472866,0.839168,0.064086,-202.655212,0.007216,0.000000
13.710001,3.959061,-202.655212,-0.004596,0.000271,0.006887,17.610781,0.897136,0.068870,-202.655212,0.007876,0.000000
14.110001,4.595078,-202.655212,-0.004583,0.000304,0.007718,20.439926,1.041260,0.077182,-202.655212,0.008543,0.000000
14.510000,5.019577,-202.788651,-0.004562,0.000327,0.008318,22.328194,1.137452,0.083177,-202.788651,0.009211,0.000000
14.910001,5.261253,-202.833130,-0.004531,0.000346,0.008785,23.403223,1.192217,0.087855,-202.833130,0.009879,0.000000
15.310000,5.867104,-202.833130,-0.004493,0.000379,0.009618,26.098181,1.329505,0.096182,-202.833130,0.010546,0.000000
15.710001,6.408531,-202.833130,-0.004480,0.000405,0.010286,28.506571,1.452194,0.102858,-202.833130,0.011214,0.000000
16.110001,7.094810,-202.922104,-0.004467,0.000437,0.011109,31.559294,1.607707,0.111094,-202.922104,0.011882,0.000000
16.510000,7.200935,-203.011063,-0.004432,0.000457,0.011612,32.031361,1.631755,0.116121,-203.011063,0.012549,0.000000
16.910002,7.710716,-203.055542,-0.004415,0.000487,0.012358,34.298981,1.747273,0.123584,-203.055542,0.013208,0.000000
17.310001,8.238739,-203.100021,-0.004381,0.000512,0.013017,36.647743,1.866925,0.130170,-203.100021,0.013875,0.000000
17.710001,8.650955,-203.055542,-0.004355,0.000538,0.013677,38.481369,1.960334,0.136771,-203.055542,0.014545,0.000000
18.110001,9.151794,-203.144501,-0.004337,0.000565,0.014354,40.709213,2.073826,0.143538,-203.144501,0.015212,0.000000
18.510000,9.477997,-203.144501,-0.004303,0.000591,0.015003,42.160236,2.147745,0.150033,-203.144501,0.015880,0.000000
18.910002,10.143425,-203.233459,-0.004303,0.000621,0.015775,45.120209,2.298533,0.157754,-203.233459,0.016548,0.000000
19.310001,10.197044,-203.322433,-0.004260,0.000643,0.016322,45.358719,2.310683,0.163220,-203.322433,0.017215,0.000000
19.710001,10.579475,-203.322433,-0.004230,0.000664,0.016876,47.059856,2.397343,0.168761,-203.322433,0.017883,0.000000
20.110001,11.321983,-203.322433,-0.004204,0.000699,0.017762,50.362698,2.565598,0.177618,-203.322433,0.018541,0.000000
20.510000,11.431465,-203.411392,-0.004195,0.000719,0.018255,50.849697,2.590407,0.182553,-203.411392,0.019209,0.000000
20.910002,12.159081,-203.411392,-0.004156,0.000748,0.019011,54.086292,2.755287,0.190108,-203.411392,0.019877,0.000000
21.310001,12.369095,-203.455872,-0.004122,0.000774,0.019669,55.020481,2.802877,0.196693,-203.455872,0.020544,0.000000
21.710001,12.708702,-203.455872,-0.004105,0.000801,0.020346,56.531132,2.879833,0.203461,-203.455872,0.021214,0.000000
22.110001,13.155548,-203.544830,-0.004083,0.000830,0.021074,58.518799,2.981090,0.210743,-203.544830,0.021881,0.000000
22.510000,13.125381,-203.544830,-0.004053,0.000847,0.021507,58.384613,2.974254,0.215073,-203.544830,0.022549,0.000000
22.910002,13.882042,-203.633789,-0.004018,0.000880,0.022340,61.750408,3.145716,0.223400,-203.633789,0.023217,0.000000
23.310001,13.907738,-203.633789,-0.003992,0.000903,0.022938,61.864708,3.151538,0.229380,-203.633789,0.023875,0.000000
23.710001,14.059669,-203.678268,-0.003967,0.000926,0.023519,62.540535,3.185967,0.235193,-203.678268,0.024543,0.000000
24.110001,14.721375,-203.767242,-0.003923,0.000958,0.024343,65.483948,3.335911,0.243429,-203.767242,0.025210,0.000000
24.510000,14.567955,-203.767242,-0.003923,0.000975,0.024777,64.801498,3.301146,0.247774,-203.767242,0.025878,0.000000
24.910002,15.531654,-203.856201,-0.003863,0.001015,0.025775,69.088249,3.519523,0.257751,-203.856201,0.026546,0.000000
25.310001,15.304504,-203.900681,-0.003850,0.001035,0.026287,68.077835,3.468050,0.262869,-203.900681,0.027213,0.000000
25.710001,15.777046,-203.945160,-0.003816,0.001063,0.026997,70.179810,3.575130,0.269969,-203.945160,0.027881,0.000000
26.110001,16.132668,-203.945160,-0.003781,0.001091,0.027708,71.761688,3.655715,0.277085,-203.945160,0.028550,0.000000
26.510002,15.863808,-203.989639,-0.003773,0.001111,0.028211,70.565742,3.594790,0.282111,-203.989639,0.029218,0.000000
26.910002,16.783943,-204.078598,-0.003712,0.001147,0.029139,74.658707,3.803296,0.291391,-204.078598,0.029876,0.000000
27.310001,16.565361,-204.078598,-0.003704,0.001166,0.029607,73.686409,3.753764,0.296070,-204.078598,0.030544,0.000000
27.710001,17.199135,-204.167572,-0.003665,0.001197,0.030405,76.505569,3.897380,0.304048,-204.167572,0.031212,0.000000
28.110001,17.446770,-204.212051,-0.003639,0.001222,0.031047,77.607109,3.953495,0.310467,-204.212051,0.031879,0.000000
28.510002,16.995079,-204.256531,-0.003622,0.001237,0.031412,75.597885,3.851140,0.314116,-204.256531,0.032547,0.000000
28.910002,18.066765,-204.301010,-0.003566,0.001277,0.032444,80.364983,4.093987,0.324441,-204.301010,0.033215,0.000000
29.310001,17.833664,-204.301010,-0.003557,0.001301,0.033051,79.328102,4.041166,0.330512,-204.301010,0.033882,0.000000
29.710001,18.513245,-204.345490,-0.003501,0.001330,0.033779,82.351028,4.195161,0.337794,-204.345490,0.034550,0.000000
30.110001,18.669266,-204.389969,-0.003475,0.001355,0.034421,83.045044,4.230516,0.344213,-204.389969,0.035210,0.000000
30.510002,18.817841,-204.434448,-0.003445,0.001382,0.035115,83.705933,4.264184,0.351147,-204.434448,0.035878,0.000000
30.910002,19.098236,-204.478928,-0.003423,0.001409,0.035799,84.953194,4.327722,0.357991,-204.478928,0.036545,0.000000
31.310001,19.027489,-204.567886,-0.003393,0.001429,0.036294,84.638496,4.311691,0.362941,-204.567886,0.037213,0.000000
31.710001,19.524231,-204.567886,-0.003337,0.001459,0.037048,86.848114,4.424254,0.370481,-204.567886,0.037881,0.000000
32.110001,19.612854,-204.701340,-0.003320,0.001482,0.037646,87.242332,4.444336,0.376461,-204.701340,0.038548,0.000000
32.510002,20.181473,-204.612381,-0.003285,0.001515,0.038479,89.771675,4.573187,0.384788,-204.612381,0.039216,0.000000
32.910000,20.126732,-204.701340,-0.003255,0.001539,0.039078,89.528175,4.560782,0.390783,-204.701340,0.039884,0.000000
33.310001,20.125984,-204.701340,-0.003216,0.001559,0.039598,89.524849,4.560613,0.395976,-204.701340,0.040544,0.000000
33.710003,20.653641,-204.745819,-0.003186,0.001592,0.040430,91.871979,4.680182,0.404302,-204.745819,0.041211,0.000000
34.110001,20.379196,-204.790298,-0.003139,0.001610,0.040890,90.651192,4.617992,0.408905,-204.790298,0.041879,0.000000
34.510002,21.172722,-204.879257,-0.003130,0.001644,0.041758,94.180969,4.797807,0.417580,-204.879257,0.042547,0.000000
34.910000,21.090057,-204.879257,-0.003096,0.001666,0.042321,93.813263,4.779075,0.423212,-204.879257,0.043214,0.000000
35.310001,20.840942,-204.923737,-0.003065,0.001687,0.042850,92.705139,4.722625,0.428496,-204.923737,0.043882,0.000000
35.710003,21.646011,-204.923737,-0.003027,0.001719,0.043675,96.286270,4.905056,0.436747,-204.923737,0.044550,0.000000
36.110001,21.309013,-204.923737,-0.002997,0.001739,0.044177,94.787224,4.828691,0.441773,-204.923737,0.045217,0.000000
36.510002,22.020988,-205.012711,-0.002958,0.001771,0.044975,97.954247,4.990027,0.449751,-205.012711,0.045877,0.000000
36.910000,22.109612,-205.101669,-0.002928,0.001796,0.045608,98.348465,5.010109,0.456080,-205.101669,0.046545,0.000000
37.310001,22.132698,-205.101669,-0.002893,0.001822,0.046267,98.451157,5.015341,0.462666,-205.101669,0.047213,0.000000
37.710003,22.600403,-205.146149,-0.002846,0.001851,0.047004,100.531616,5.121325,0.470039,-205.146149,0.047880,0.000000
38.110001,22.033279,-205.146149,-0.002837,0.001865,0.047369,98.008919,4.992812,0.473687,-205.146149,0.048548,0.000000
38.510002,23.233810,-205.235107,-0.002781,0.001906,0.048409,103.349152,5.264857,0.484088,-205.235107,0.049216,0.000000
38.910004,22.906494,-205.279587,-0.002746,0.001927,0.048939,101.893173,5.190686,0.489387,-205.279587,0.049883,0.000000
39.310001,23.134758,-205.279587,-0.002716,0.001954,0.049623,102.908546,5.242411,0.496230,-205.279587,0.050551,0.000000
39.710003,23.471756,-205.324066,-0.002677,0.001982,0.050335,104.407585,5.318776,0.503346,-205.324066,0.051219,0.000000
40.110001,22.707642,-205.324066,-0.002660,0.001994,0.050656,101.008636,5.145625,0.506555,-205.324066,0.051877,0.000000
40.510002,23.799438,-205.368546,-0.002626,0.002032,0.051618,105.865189,5.393030,0.516184,-205.368546,0.052546,0.000000
40.910004,23.838165,-205.457520,-0.002587,0.002058,0.052277,106.037453,5.401805,0.522770,-205.457520,0.053214,0.000000
41.310001,24.385185,-205.501999,-0.002561,0.002090,0.053075,108.470718,5.525762,0.530748,-205.501999,0.053882,0.000000
41.710003,24.310333,-205.590958,-0.002518,0.002113,0.053682,108.137764,5.508800,0.536819,-205.590958,0.054549,0.000000
42.110001,23.526489,-205.590958,-0.002475,0.002125,0.053985,104.651054,5.331179,0.539847,-205.590958,0.055217,0.000000
42.510002,24.944115,-205.546478,-0.002440,0.002166,0.055017,110.956963,5.652417,0.550172,-205.546478,0.055885,0.000000
42.910004,24.647705,-205.679916,-0.002414,0.002188,0.055580,109.638466,5.585250,0.555804,-205.679916,0.056552,0.000000
43.310001,25.034225,-205.724396,-0.002367,0.002219,0.056353,111.357796,5.672837,0.563525,-205.724396,0.057211,0.000000
43.710003,24.851768,-205.724396,-0.002337,0.002243,0.056969,110.546188,5.631491,0.569687,-205.724396,0.057879,0.000000
44.110001,24.928848,-205.768875,-0.002285,0.002269,0.057627,110.889053,5.648958,0.576273,-205.768875,0.058546,0.000000
44.510002,25.661301,-205.768875,-0.002259,0.002300,0.058408,114.147163,5.814934,0.584085,-205.768875,0.059214,0.000000
44.910004,25.189880,-205.768875,-0.002212,0.002319,0.058911,112.050186,5.708108,0.589111,-205.768875,0.059883,0.000000
45.310001,25.725723,-205.857849,-0.002186,0.002351,0.059709,114.433731,5.829532,0.597090,-205.857849,0.060551,0.000000
45.710003,25.441231,-205.857849,-0.002147,0.002373,0.060265,113.168243,5.765065,0.602646,-205.857849,0.061218,0.000000
46.110001,26.171822,-205.991287,-0.002100,0.002405,0.061097,116.418076,5.930620,0.610973,-205.991287,0.061886,0.000000
46.510002,25.589806,-205.946808,-0.002061,0.002427,0.061651,113.829140,5.798733,0.616514,-205.946808,0.062545,0.000000
46.910004,25.318718,-206.035767,-0.002018,0.002451,0.062268,112.623283,5.737303,0.622676,-206.035767,0.063212,0.000000
47.310001,25.806526,-206.035767,-0.001979,0.002483,0.063065,114.793159,5.847843,0.630654,-206.035767,0.063880,0.000000
47.710003,25.114288,-206.080246,-0.001936,0.002500,0.063508,111.713936,5.690979,0.635075,-206.080246,0.064548,0.000000
48.110001,26.030327,-206.124725,-0.001888,0.002538,0.064461,115.788673,5.898556,0.644613,-206.124725,0.065215,0.000000
48.510002,25.360054,-206.169205,-0.001850,0.002558,0.064964,112.807152,5.746671,0.649639,-206.169205,0.065883,0.000000
48.910004,25.133278,-206.258163,-0.001824,0.002579,0.065510,111.798401,5.695282,0.655105,-206.258163,0.066552,0.000000
49.310001,26.037025,-206.213684,-0.001776,0.002614,0.066387,115.818474,5.900074,0.663871,-206.213684,0.067220,0.000000
49.710003,25.364525,-206.302658,-0.001755,0.002630,0.066794,112.827042,5.747684,0.667943,-206.302658,0.067878,0.000000
50.110001,26.666710,-206.258163,-0.001694,0.002669,0.067783,118.619453,6.042763,0.677829,-206.258163,0.068546,0.000000
50.510002,26.118950,-206.391617,-0.001664,0.002688,0.068276,116.182892,5.918639,0.682765,-206.391617,0.069214,0.000000
50.910004,26.566544,-206.436096,-0.001634,0.002719,0.069058,118.173889,6.020065,0.690577,-206.436096,0.069881,0.000000
51.310001,26.822731,-206.525055,-0.001600,0.002744,0.069700,119.313469,6.078118,0.696996,-206.525055,0.070549,0.000000
51.710003,26.277580,-206.480576,-0.001582,0.002761,0.070125,116.888512,5.954585,0.701250,-206.480576,0.071217,0.000000
52.110001,27.679932,-206.569534,-0.001535,0.002800,0.071114,123.126488,6.272362,0.711136,-206.569534,0.071884,0.000000
52.510002,27.362671,-206.614014,-0.001518,0.002821,0.071659,121.715240,6.200470,0.716587,-206.614014,0.072552,0.000000
52.910004,27.320221,-206.658493,-0.001475,0.002842,0.072179,121.526413,6.190850,0.721795,-206.658493,0.073221,0.000000
53.310001,28.277962,-206.747467,-0.001423,0.002873,0.072977,125.786659,6.407877,0.729773,-206.747467,0.073880,0.000000
53.710003,27.456886,-206.747467,-0.001410,0.002885,0.073273,122.134331,6.221819,0.732725,-206.747467,0.074547,0.000000
54.110004,29.575684,-206.747467,-0.001375,0.002930,0.074426,131.559204,6.701945,0.744262,-206.747467,0.075215,0.000000
54.510002,28.833542,-206.791946,-0.001332,0.002949,0.074894,128.257996,6.533774,0.748940,-206.791946,0.075883,0.000000
54.910004,30.194565,-206.836426,-0.001319,0.002983,0.075761,134.312134,6.842186,0.757615,-206.836426,0.076550,0.000000
55.310001,30.301064,-206.836426,-0.001285,0.003006,0.076359,134.785858,6.866319,0.763595,-206.836426,0.077218,0.000000
55.710003,30.854034,-206.925385,-0.001263,0.003036,0.077113,137.245605,6.991624,0.771134,-206.925385,0.077886,0.000000
56.110004,31.123260,-206.925385,-0.001220,0.003057,0.077643,138.443176,7.052631,0.776433,-206.925385,0.078553,0.000000
56.510002,31.278915,-206.969864,-0.001186,0.003080,0.078232,139.135559,7.087903,0.782323,-206.969864,0.079213,0.000000
56.910004,32.558014,-207.103302,-0.001173,0.003113,0.079065,144.825272,7.377751,0.790649,-207.103302,0.079881,0.000000
57.310001,32.647011,-207.058823,-0.001143,0.003135,0.079621,145.221161,7.397918,0.796206,-207.058823,0.080549,0.000000
57.710003,33.598053,-207.103302,-0.001125,0.003165,0.080384,149.451599,7.613428,0.803836,-207.103302,0.081216,0.000000
58.110004,33.902275,-207.147797,-0.001095,0.003189,0.081000,150.804855,7.682365,0.809998,-207.147797,0.081884,0.000000
58.510002,33.655396,-207.192276,-0.001065,0.003207,0.081459,149.706680,7.626421,0.814585,-207.192276,0.082552,0.000000
58.910004,35.280426,-207.236755,-0.001035,0.003242,0.082352,156.935165,7.994659,0.823517,-207.236755,0.083219,0.000000
59.310001,34.845123,-207.281235,-0.001009,0.003257,0.082733,154.998856,7.896018,0.827333,-207.281235,0.083887,0.000000
59.710003,36.949776,-207.370193,-0.000987,0.003298,0.083766,164.360809,8.372939,0.837658,-207.370193,0.084547,0.000000
60.110004,36.847000,-207.325714,-0.000957,0.003317,0.084261,163.903641,8.349649,0.842608,-207.325714,0.085215,0.000000
60.510002,37.285652,-207.370193,-0.000940,0.003343,0.084901,165.854858,8.449050,0.849012,-207.370193,0.085882,0.000000
60.910004,38.868240,-207.414673,-0.000923,0.003374,0.085708,172.894562,8.807669,0.857082,-207.414673,0.086550,0.000000
61.310001,38.782593,-207.459152,-0.000880,0.003390,0.086099,172.513596,8.788261,0.860988,-207.459152,0.087218,0.000000
61.710003,40.834366,-207.548111,-0.000871,0.003427,0.087053,181.640335,9.253200,0.870526,-207.548111,0.087885,0.000000
62.110004,41.194077,-207.548111,-0.000849,0.003450,0.087634,183.240402,9.334711,0.876339,-207.548111,0.088553,0.000000
62.510002,41.786896,-207.592606,-0.000824,0.003477,0.088311,185.877396,9.469046,0.883107,-207.592606,0.089221,0.000000
62.910004,43.321808,-207.592606,-0.000811,0.003504,0.089013,192.705032,9.816862,0.890132,-207.592606,0.089879,0.000000
63.310001,43.013489,-207.637085,-0.000772,0.003517,0.089342,191.333557,9.746996,0.893417,-207.637085,0.090547,0.000000
63.710003,44.995995,-207.726044,-0.000755,0.003554,0.090270,200.152176,10.196239,0.902697,-207.726044,0.091216,0.000000
64.110001,45.802933,-207.681564,-0.000742,0.003579,0.090912,203.741623,10.379093,0.909117,-207.681564,0.091884,0.000000
64.510002,47.261139,-207.770523,-0.000733,0.003607,0.091623,210.228043,10.709527,0.916232,-207.770523,0.092551,0.000000
64.910004,48.364479,-207.770523,-0.000707,0.003633,0.092282,215.135941,10.959548,0.922818,-207.770523,0.093219,0.000000
65.310005,48.360382,-207.770523,-0.000694,0.003648,0.092647,215.117722,10.958619,0.926467,-207.770523,0.093887,0.000000
65.710007,50.805756,-207.903961,-0.000660,0.003686,0.093617,225.995285,11.512749,0.936171,-207.903961,0.094554,0.000000
66.110001,51.341599,-207.903961,-0.000651,0.003706,0.094138,228.378830,11.634172,0.941379,-207.903961,0.095222,0.000000
66.510002,52.749908,-207.903961,-0.000638,0.003735,0.094875,234.643311,11.953300,0.948752,-207.903961,0.095880,0.000000
66.910004,54.411438,-207.992920,-0.000612,0.003764,0.095613,242.034164,12.329807,0.956125,-207.992920,0.096548,0.000000
67.310005,54.752159,-208.037415,-0.000608,0.003779,0.095985,243.549774,12.407017,0.959849,-208.037415,0.097216,0.000000
67.710007,57.834282,-208.081894,-0.000595,0.003822,0.097069,257.259735,13.105435,0.970689,-208.081894,0.097885,0.000000
68.110001,58.563019,-208.081894,-0.000578,0.003843,0.097606,260.501312,13.270570,0.976064,-208.081894,0.098553,0.000000
68.510002,60.479614,-208.126373,-0.000560,0.003872,0.098353,269.026764,13.704877,0.983528,-208.126373,0.099220,0.000000
68.910004,61.835426,-208.170853,-0.000548,0.003897,0.098977,275.057709,14.012108,0.989765,-208.170853,0.099888,0.000000
69.310005,63.696167,-208.259811,-0.000539,0.003927,0.099740,283.334717,14.433758,0.997396,-208.259811,0.100556,0.000000
69.710007,65.085861,-208.259811,-0.000517,0.003952,0.100374,289.516357,14.748668,1.003739,-208.259811,0.101214,0.000000
70.110001,66.255493,-208.304291,-0.000500,0.003973,0.100911,294.719147,15.013710,1.009114,-208.304291,0.101882,0.000000
70.510002,65.078049,-208.348770,-0.000492,0.003961,0.100616,289.481628,14.746897,1.006161,-208.348770,294.500458,0.000000
70.910004,65.905090,-208.348770,-0.000474,0.003959,0.100546,293.160492,14.934307,1.005465,-208.348770,294.500458,0.000000
71.310005,65.512238,-208.482224,-0.000466,0.003992,0.101396,291.412994,14.845285,1.013958,-208.482224,294.500458,0.000000
71.710007,65.369980,-208.437744,-0.000470,0.003995,0.101475,290.780182,14.813048,1.014745,-208.437744,294.500458,0.000000
72.110001,65.366638,-208.482224,-0.000453,0.004001,0.101630,290.765320,14.812292,1.016305,-208.482224,294.500458,0.000000
72.510002,65.353607,-208.526703,-0.000461,0.004009,0.101821,290.707367,14.809340,1.018212,-208.526703,294.500458,0.000000
72.910004,65.326782,-208.571182,-0.000457,0.004012,0.101908,290.588043,14.803261,1.019075,-208.571182,294.500458,0.000000
73.310005,65.336472,-208.660141,-0.000457,0.004017,0.102021,290.631134,14.805456,1.020211,-208.660141,294.500458,0.000000
73.710007,65.355835,-208.749100,-0.000444,0.004021,0.102126,290.717285,14.809844,1.021255,-208.749100,294.500458,0.000000
74.110001,65.308548,-208.749100,-0.000448,0.004024,0.102221,290.506927,14.799129,1.022209,-208.749100,294.500458,0.000000
74.510002,65.077301,-208.749100,-0.000440,0.004025,0.102238,289.478302,14.746727,1.022376,-208.749100,294.500458,0.000000
74.910004,64.996490,-208.882553,-0.000444,0.004028,0.102316,289.118835,14.728415,1.023163,-208.882553,294.500458,0.000000
75.310005,65.000961,-208.882553,-0.000440,0.004032,0.102412,289.138702,14.729428,1.024117,-208.882553,294.500458,0.000000
75.710007,65.070969,-208.927032,-0.000435,0.004041,0.102637,289.450134,14.745292,1.026373,-208.927032,294.500458,0.000000
76.110001,65.759491,-208.971512,-0.000431,0.004042,0.102672,292.512817,14.901314,1.026721,-208.971512,294.500458,0.000000
76.510002,65.542389,-208.971512,-0.000427,0.004043,0.102680,291.547119,14.852118,1.026797,-208.971512,294.500458,0.000000
76.910004,65.307800,-209.015991,-0.000431,0.004043,0.102680,290.503601,14.798959,1.026797,-209.015991,294.500458,0.000000
77.310005,65.103745,-209.149429,-0.000435,0.004048,0.102810,289.595917,14.752720,1.028099,-209.149429,294.500458,0.000000
77.710007,65.864120,-209.104950,-0.000418,0.004049,0.102854,292.978241,14.925023,1.028538,-209.104950,294.500458,0.000000
78.110001,65.607925,-209.149429,-0.000427,0.004049,0.102854,291.838623,14.866968,1.028538,-209.149429,294.500458,0.000000
78.510002,65.396790,-209.193909,-0.000431,0.004050,0.102863,290.899445,14.819124,1.028628,-209.193909,294.500458,0.000000
78.910004,65.199066,-209.282867,-0.000427,0.004050,0.102863,290.019928,14.774320,1.028628,-209.282867,294.500458,0.000000
79.310005,65.777725,-209.238388,-0.000397,0.004060,0.103114,292.593933,14.905445,1.031142,-209.238388,294.500458,0.000000
79.710007,65.667145,-209.327362,-0.000423,0.004060,0.103114,292.102051,14.880387,1.031142,-209.327362,294.500458,0.000000
80.110001,65.557663,-209.416321,-0.000414,0.004060,0.103114,291.615051,14.855579,1.031142,-209.416321,294.500458,0.000000
80.510002,65.397171,-209.416321,-0.000423,0.004060,0.103114,290.901154,14.819211,1.031142,-209.416321,294.500458,0.000000
80.910004,65.266464,-209.460800,-0.000423,0.004060,0.103114,290.319733,14.789592,1.031142,-209.460800,294.500458,0.000000
81.310005,65.126831,-209.505280,-0.000401,0.004060,0.103114,289.698608,14.757951,1.031142,-209.505280,294.500458,0.000000
81.710007,65.001709,-209.460800,-0.000414,0.004060,0.103114,289.142029,14.729598,1.031142,-209.460800,294.500458,0.000000
82.110001,65.943817,-209.549759,-0.000405,0.004067,0.103305,293.332764,14.943082,1.033049,-209.549759,294.500458,0.000000
82.510002,65.876419,-209.638718,-0.000410,0.004067,0.103305,293.032959,14.927810,1.033049,-209.638718,294.500458,0.000000
82.910004,65.733414,-209.594238,-0.000410,0.004067,0.103305,292.396820,14.895405,1.033049,-209.594238,294.500458,0.000000
83.310005,65.575912,-209.638718,-0.000405,0.004067,0.103305,291.696228,14.859715,1.033049,-209.638718,294.500458,0.000000
83.710007,65.468658,-209.683197,-0.000414,0.004067,0.103305,291.219147,14.835410,1.033049,-209.683197,294.500458,0.000000
84.110001,65.345413,-209.727692,-0.000405,0.004067,0.103305,290.670929,14.807483,1.033049,-209.727692,294.500458,0.000000
84.510002,65.242264,-209.816650,-0.000414,0.004067,0.103305,290.212097,14.784108,1.033049,-209.816650,294.500458,0.000000
84.910004,65.123474,-209.772171,-0.000392,0.004067,0.103305,289.683685,14.757190,1.033049,-209.772171,294.500458,0.000000
85.310005,65.931900,-209.861130,-0.000405,0.004079,0.103599,293.279724,14.940382,1.035986,-209.861130,294.500458,0.000000
85.710007,65.866730,-209.905609,-0.000401,0.004079,0.103599,292.989838,14.925614,1.035986,-209.905609,294.500458,0.000000
86.110001,65.772522,-209.950089,-0.000405,0.004079,0.103599,292.570801,14.904266,1.035986,-209.950089,294.500458,0.000000
86.510002,65.735275,-209.950089,-0.000405,0.004079,0.103599,292.405121,14.895826,1.035986,-209.950089,294.500458,0.000000
86.910004,65.604202,-209.994568,-0.000401,0.004079,0.103599,291.822052,14.866125,1.035986,-209.994568,294.500458,0.000000
87.310005,65.555420,-209.994568,-0.000397,0.004079,0.103599,291.605072,14.855071,1.035986,-209.994568,294.500458,0.000000
87.710007,65.479828,-210.083527,-0.000397,0.004079,0.103599,291.268829,14.837941,1.035986,-210.083527,294.500458,0.000000
88.110001,65.385254,-210.083527,-0.000401,0.004079,0.103599,290.848145,14.816510,1.035986,-210.083527,294.500458,0.000000
88.510002,65.317474,-210.172501,-0.000392,0.004079,0.103599,290.546631,14.801151,1.035986,-210.172501,294.500458,0.000000
88.910004,65.265350,-210.172501,-0.000397,0.004079,0.103599,290.314789,14.789339,1.035986,-210.172501,294.500458,0.000000
89.310005,65.196838,-210.216980,-0.000405,0.004079,0.103599,290.010010,14.773814,1.035986,-210.216980,294.500458,0.000000
89.710007,65.087357,-210.216980,-0.000401,0.004079,0.103599,289.523010,14.749006,1.035986,-210.216980,294.500458,0.000000
90.110001,65.787048,-210.261459,-0.000392,0.004087,0.103817,292.635406,14.907558,1.038166,-210.261459,294.500458,0.000000
90.510002,65.764694,-210.305939,-0.000392,0.004087,0.103817,292.535980,14.902493,1.038166,-210.305939,294.500458,0.000000
90.910004,65.733414,-210.350418,-0.000401,0.004087,0.103817,292.396820,14.895405,1.038166,-210.350418,294.500458,0.000000
91.310005,65.668259,-210.394897,-0.000392,0.004087,0.103817,292.106995,14.880640,1.038166,-210.394897,294.500458,0.000000
91.710007,65.602341,-210.439377,-0.000392,0.004087,0.103817,291.813782,14.865703,1.038166,-210.439377,294.500458,0.000000
92.110001,65.569199,-210.439377,-0.000388,0.004087,0.103817,291.666351,14.858193,1.038166,-210.439377,294.500458,0.000000
92.510002,65.525269,-210.572815,-0.000401,0.004087,0.103817,291.470947,14.848238,1.038166,-210.572815,294.500458,0.000000
92.910004,65.476486,-210.572815,-0.000392,0.004087,0.103817,291.253967,14.837184,1.038166,-210.572815,294.500458,0.000000
93.310005,65.408340,-210.528336,-0.000384,0.004087,0.103817,290.950836,14.821742,1.038166,-210.528336,294.500458,0.000000
93.710007,65.354340,-210.661789,-0.000384,0.004087,0.103817,290.710632,14.809505,1.038166,-210.661789,294.500458,0.000000
94.110008,65.302582,-210.706268,-0.000388,0.004087,0.103817,290.480377,14.797776,1.038166,-210.706268,294.500458,0.000000
94.510002,65.268326,-210.706268,-0.000392,0.004087,0.103817,290.328003,14.790014,1.038166,-210.706268,294.500458,0.000000
94.910004,65.213211,-210.750748,-0.000379,0.004087,0.103817,290.082855,14.777525,1.038166,-210.750748,294.500458,0.000000
95.310005,65.167419,-210.795227,-0.000375,0.004087,0.103817,289.879150,14.767148,1.038166,-210.795227,294.500458,0.000000
95.710007,65.092575,-210.884186,-0.000371,0.004087,0.103817,289.546234,14.750189,1.038166,-210.884186,294.500458,0.000000
96.110008,65.052353,-210.884186,-0.000375,0.004087,0.103817,289.367310,14.741074,1.038166,-210.884186,294.500458,0.000000
96.510002,65.002823,-210.884186,-0.000388,0.004087,0.103817,289.147003,14.729851,1.038166,-210.884186,294.500458,0.000000
96.910004,64.963348,-210.973145,-0.000392,0.004087,0.103817,288.971405,14.720905,1.038166,-210.973145,294.500458,0.000000
97.310005,66.386566,-210.973145,-0.000397,0.004101,0.104154,295.302185,15.043410,1.041543,-210.973145,294.500458,0.000000
97.710007,66.264801,-211.017639,-0.000375,0.004093,0.103963,294.760559,15.015819,1.039635,-211.017639,294.500458,0.000000
98.110008,66.192184,-211.062119,-0.000388,0.004093,0.103954,294.437531,14.999363,1.039544,-211.062119,294.500458,0.000000
98.510002,66.136703,-211.106598,-0.000375,0.004093,0.103954,294.190735,14.986792,1.039544,-211.106598,294.500458,0.000000
98.910004,66.083817,-211.106598,-0.000366,0.004093,0.103954,293.955505,14.974807,1.039544,-211.106598,294.500458,0.000000
99.310005,66.028717,-211.195557,-0.000375,0.004093,0.103954,293.710388,14.962321,1.039544,-211.195557,294.500458,0.000000
99.710007,65.935242,-211.240036,-0.000375,0.004093,0.103954,293.294617,14.941140,1.039544,-211.240036,294.500458,0.000000
100.110008,65.864868,-211.284515,-0.000388,0.004093,0.103954,292.981567,14.925193,1.039544,-211.284515,294.500458,0.000000
100.510002,65.879395,-211.328995,-0.000388,0.004093,0.103954,293.046173,14.928484,1.039544,-211.328995,294.500458,0.000000
100.910004,65.829117,-211.417953,-0.000371,0.004093,0.103954,292.822540,14.917091,1.039544,-211.417953,294.500458,0.000000
101.310005,65.762100,-211.462448,-0.000388,0.004093,0.103954,292.524445,14.901905,1.039544,-211.462448,294.500458,0.000000
101.710007,65.755768,-211.462448,-0.000375,0.004093,0.103954,292.496277,14.900470,1.039544,-211.462448,294.500458,0.000000
102.110008,65.671600,-211.462448,-0.000384,0.004093,0.103954,292.121857,14.881397,1.039544,-211.462448,294.500458,0.000000
102.510002,65.609787,-211.595886,-0.000375,0.004093,0.103954,291.846893,14.867391,1.039544,-211.595886,294.500458,0.000000
102.910004,65.580368,-211.551407,-0.000392,0.004093,0.103954,291.716034,14.860724,1.039544,-211.551407,294.500458,0.000000
103.310005,65.545380,-211.640366,-0.000388,0.004093,0.103954,291.560425,14.852796,1.039544,-211.640366,294.500458,0.000000
103.710007,65.508881,-211.684845,-0.000388,0.004093,0.103954,291.398041,14.844524,1.039544,-211.684845,294.500458,0.000000
104.110008,65.464569,-211.684845,-0.000375,0.004093,0.103954,291.200958,14.834484,1.039544,-211.684845,294.500458,0.000000
104.510002,65.414673,-211.773804,-0.000384,0.004093,0.103963,290.979004,14.823176,1.039635,-211.773804,294.500458,0.000000
104.910004,65.362167,-211.773804,-0.000375,0.004093,0.103963,290.745453,14.811279,1.039635,-211.773804,294.500458,0.000000
105.310005,65.384872,-211.818283,-0.000388,0.004100,0.104145,290.846436,14.816424,1.041452,-211.818283,294.500458,0.000000
105.710007,65.381531,-211.907257,-0.000375,0.004100,0.104145,290.831573,14.815667,1.041452,-211.907257,294.500458,0.000000
106.110008,65.376312,-211.907257,-0.000375,0.004101,0.104154,290.808350,14.814484,1.041543,-211.907257,294.500458,0.000000
106.510002,65.344666,-211.951736,-0.000388,0.004101,0.104163,290.667603,14.807313,1.041633,-211.951736,294.500458,0.000000
106.910004,65.336105,-211.951736,-0.000388,0.004101,0.104163,290.629517,14.805373,1.041633,-211.951736,294.500458,0.000000
107.310005,65.315994,-211.951736,-0.000388,0.004102,0.104180,290.540039,14.800816,1.041800,-211.951736,294.500458,0.000000
107.710007,65.335724,-212.085175,-0.000384,0.004102,0.104189,290.627808,14.805286,1.041891,-212.085175,294.500458,0.000000
108.110008,65.333862,-212.040695,-0.000384,0.004102,0.104198,290.619537,14.804865,1.041982,-212.040695,294.500458,0.000000
108.510002,65.326416,-212.129654,-0.000384,0.004103,0.104206,290.586426,14.803178,1.042057,-212.129654,294.500458,0.000000
108.910004,65.334610,-212.174133,-0.000375,0.004103,0.104215,290.622864,14.805035,1.042148,-212.174133,294.500458,0.000000
109.310005,65.323059,-212.174133,-0.000384,0.004103,0.104215,290.571472,14.802417,1.042148,-212.174133,294.500458,0.000000
109.710007,65.311890,-212.218613,-0.000379,0.004103,0.104215,290.521790,14.799886,1.042148,-212.218613,294.500458,0.000000
110.110008,65.321945,-212.263092,-0.000392,0.004103,0.104224,290.566528,14.802165,1.042239,-212.263092,294.500458,0.000000
110.510002,65.297745,-212.307587,-0.000379,0.004104,0.104241,290.458862,14.796680,1.042405,-212.307587,294.500458,0.000000
110.910004,65.307053,-212.307587,-0.000366,0.004104,0.104241,290.500275,14.798789,1.042405,-212.307587,294.500458,0.000000
111.310005,65.292160,-212.352066,-0.000379,0.004104,0.104241,290.434021,14.795415,1.042405,-212.352066,294.500458,0.000000
111.710007,65.250458,-212.441025,-0.000392,0.004104,0.104250,290.248535,14.785965,1.042496,-212.441025,294.500458,0.000000
112.110008,65.265350,-212.441025,-0.000384,0.004105,0.104259,290.314789,14.789339,1.042587,-212.441025,294.500458,0.000000
112.510002,65.298859,-212.485504,-0.000371,0.004106,0.104301,290.463837,14.796933,1.043011,-212.485504,294.500458,0.000000
112.910004,65.380783,-212.529984,-0.000388,0.004107,0.104328,290.828247,14.815497,1.043284,-212.529984,294.500458,0.000000
113.310005,65.389725,-212.618942,-0.000371,0.004107,0.104328,290.868011,14.817523,1.043284,-212.618942,294.500458,0.000000
113.710007,65.384506,-212.618942,-0.000379,0.004107,0.104328,290.844818,14.816340,1.043284,-212.618942,294.500458,0.000000
114.110008,65.372971,-212.618942,-0.000371,0.004107,0.104328,290.793488,14.813726,1.043284,-212.618942,294.500458,0.000000
114.510002,65.354340,-212.707901,-0.000379,0.004107,0.104328,290.710632,14.809505,1.043284,-212.707901,294.500458,0.000000
114.910004,65.339081,-212.752396,-0.000384,0.004108,0.104336,290.642761,14.806047,1.043359,-212.752396,294.500458,0.000000
115.310005,65.363647,-212.707901,-0.000379,0.004108,0.104336,290.752014,14.811614,1.043359,-212.707901,294.500458,0.000000
115.710007,65.338333,-212.796875,-0.000375,0.004109,0.104371,290.639435,14.805878,1.043707,-212.796875,294.500458,0.000000
116.110008,65.339447,-212.841354,-0.000384,0.004109,0.104371,290.644379,14.806130,1.043707,-212.841354,294.500458,0.000000
116.510002,65.340942,-212.885834,-0.000384,0.004109,0.104371,290.651031,14.806470,1.043707,-212.885834,294.500458,0.000000
116.910004,65.336472,-212.885834,-0.000371,0.004109,0.104371,290.631134,14.805456,1.043707,-212.885834,294.500458,0.000000
117.310005,65.361786,-212.974792,-0.000375,0.004110,0.104389,290.743744,14.811193,1.043889,-212.974792,294.500458,0.000000
117.710007,65.356949,-213.019272,-0.000371,0.004110,0.104389,290.722229,14.810097,1.043889,-213.019272,294.500458,0.000000
118.110008,65.372971,-213.019272,-0.000384,0.004110,0.104389,290.793488,14.813726,1.043889,-213.019272,294.500458,0.000000
118.510002,65.321579,-213.063751,-0.000366,0.004110,0.104396,290.564880,14.802081,1.043965,-213.063751,294.500458,0.000000
118.910004,65.333115,-213.152710,-0.000358,0.004110,0.104396,290.616211,14.804696,1.043965,-213.152710,294.500458,0.000000
119.310005,65.317474,-213.197205,-0.000366,0.004110,0.104396,290.546631,14.801151,1.043965,-213.197205,294.500458,0.000000
119.710007,65.311523,-213.197205,-0.000375,0.004110,0.104396,290.520172,14.799802,1.043965,-213.197205,294.500458,0.000000
120.110008,65.289185,-213.241684,-0.000371,0.004110,0.104396,290.420807,14.794741,1.043965,-213.241684,294.500458,0.000000
120.510002,65.287323,-213.330643,-0.000375,0.004110,0.104406,290.412506,14.794319,1.044056,-213.330643,294.500458,0.000000
120.910004,65.298111,-213.330643,-0.000371,0.004112,0.104449,290.460510,14.796764,1.044495,-213.330643,294.500458,0.000000
121.310005,65.331253,-213.375122,-0.000362,0.004113,0.104459,290.607941,14.804274,1.044586,-213.375122,294.500458,0.000000
121.710007,65.347641,-213.330643,-0.000366,0.004113,0.104459,290.680817,14.807987,1.044586,-213.330643,294.500458,0.000000
122.110008,65.342804,-213.375122,-0.000362,0.004113,0.104459,290.659302,14.806890,1.044586,-213.375122,294.500458,0.000000
122.510002,65.337967,-213.464081,-0.000366,0.004113,0.104459,290.637787,14.805795,1.044586,-213.464081,294.500458,0.000000
122.910004,65.312637,-213.553040,-0.000375,0.004113,0.104459,290.525116,14.800055,1.044586,-213.553040,294.500458,0.000000
123.310005,65.319717,-213.508560,-0.000375,0.004113,0.104459,290.556610,14.801660,1.044586,-213.508560,294.500458,0.000000
123.710007,65.318604,-213.597534,-0.000366,0.004113,0.104459,290.551666,14.801407,1.044586,-213.597534,294.500458,0.000000
124.110008,65.306305,-213.642014,-0.000358,0.004113,0.104459,290.496948,14.798620,1.044586,-213.642014,294.500458,0.000000
124.510002,65.281738,-213.642014,-0.000362,0.004113,0.104466,290.387665,14.793054,1.044661,-213.642014,294.500458,0.000000
124.910004,65.278015,-213.730972,-0.000362,0.004113,0.104466,290.371124,14.792210,1.044661,-213.730972,294.500458,0.000000
125.310005,65.273544,-213.775452,-0.000366,0.004113,0.104466,290.351227,14.791197,1.044661,-213.775452,294.500458,0.000000
125.710007,65.372223,-213.819931,-0.000371,0.004116,0.104554,290.790161,14.813558,1.045539,-213.819931,294.500458,0.000000
126.110008,65.490265,-213.864410,-0.000366,0.004116,0.104554,291.315247,14.840306,1.045539,-213.864410,294.500458,0.000000
126.510010,65.495468,-213.864410,-0.000375,0.004116,0.104554,291.338379,14.841485,1.045539,-213.864410,294.500458,0.000000
126.910004,65.501434,-213.908890,-0.000371,0.004116,0.104554,291.364929,14.842837,1.045539,-213.908890,294.500458,0.000000
127.310005,65.505157,-213.997849,-0.000375,0.004116,0.104554,291.381500,14.843681,1.045539,-213.997849,294.500458,0.000000
127.710007,65.497330,-214.042343,-0.000375,0.004116,0.104554,291.346680,14.841908,1.045539,-214.042343,294.500458,0.000000
128.110001,65.479095,-214.042343,-0.000375,0.004116,0.104554,291.265564,14.837775,1.045539,-214.042343,294.500458,0.000000
128.510010,65.472382,-214.086823,-0.000366,0.004116,0.104554,291.235687,14.836254,1.045539,-214.086823,294.500458,0.000000
128.910004,65.456741,-214.131302,-0.000362,0.004116,0.104554,291.166138,14.832710,1.045539,-214.131302,294.500458,0.000000
129.310013,65.426590,-214.175781,-0.000379,0.004116,0.104554,291.032013,14.825877,1.045539,-214.175781,294.500458,0.000000
129.710007,65.400894,-214.175781,-0.000379,0.004117,0.104562,290.917694,14.820054,1.045615,-214.175781,294.500458,0.000000
130.110001,65.379288,-214.264740,-0.000358,0.004117,0.104562,290.821594,14.815159,1.045615,-214.264740,294.500458,0.000000
130.510010,65.369980,-214.309219,-0.000366,0.004117,0.104580,290.780182,14.813048,1.045797,-214.309219,1681.640747,0.000000
130.910004,65.415787,-214.398178,-0.000362,0.004110,0.104406,290.983948,14.823429,1.044056,-214.398178,0.104466,0.000000
131.310013,65.327164,-214.398178,-0.000366,0.004097,0.104068,290.589752,14.803347,1.040680,-214.398178,0.103798,0.000000
131.710007,65.228104,-214.353699,-0.000366,0.004073,0.103461,290.149109,14.780899,1.034609,-214.353699,0.103131,0.000000
132.110001,65.231842,-214.398178,-0.000375,0.004051,0.102896,290.165710,14.781747,1.028962,-214.398178,0.102472,0.000000
132.510010,65.197952,-214.531631,-0.000366,0.004023,0.102177,290.014984,14.774067,1.021770,-214.531631,0.101805,0.000000
132.910004,65.155502,-214.531631,-0.000384,0.003999,0.101587,289.826141,14.764448,1.015866,-214.531631,0.101137,0.000000
133.310013,65.127563,-214.576111,-0.000371,0.003980,0.101084,289.701874,14.758117,1.010839,-214.576111,0.100469,0.000000
133.710007,65.066498,-214.665070,-0.000366,0.003947,0.100260,289.430237,14.744279,1.002604,-214.665070,0.099800,0.000000
134.110001,65.088837,-214.576111,-0.000375,0.003927,0.099749,289.529602,14.749341,0.997486,-214.576111,0.099132,0.000000
134.510010,64.974152,-214.665070,-0.000362,0.003896,0.098969,289.019470,14.723353,0.989689,-214.665070,0.098465,0.000000
134.910004,64.886642,-214.709549,-0.000366,0.003874,0.098388,288.630188,14.703523,0.983876,-214.709549,0.097797,0.000000
135.310013,64.548904,-214.709549,-0.000366,0.003853,0.097867,287.127869,14.626991,0.978668,-214.709549,0.097139,0.000000
135.710007,63.500671,-214.754028,-0.000362,0.003821,0.097060,282.465088,14.389458,0.970598,-214.754028,0.096471,0.000000
136.110001,62.505325,-214.798508,-0.000341,0.003803,0.096609,278.037567,14.163910,0.966087,-214.798508,0.095803,0.000000
136.510010,61.292877,-214.842987,-0.000332,0.003781,0.096036,272.644348,13.889164,0.960364,-214.842987,0.095136,0.000000
136.910004,58.730957,-214.887482,-0.000332,0.003747,0.095178,261.248352,13.308625,0.951780,-214.887482,0.094468,0.000000
137.310013,57.368820,-214.887482,-0.000323,0.003731,0.094762,255.189255,12.999961,0.947617,-214.887482,0.093800,0.000000
137.710007,55.144638,-214.931961,-0.000315,0.003709,0.094198,245.295609,12.495954,0.941985,-214.931961,0.093131,0.000000
138.110001,53.328201,-214.976440,-0.000336,0.003691,0.093756,237.215683,12.084343,0.937564,-214.976440,0.092463,0.000000
138.510010,49.600014,-214.976440,-0.000319,0.003654,0.092819,220.631882,11.239524,0.928192,-214.976440,0.091805,0.000000
138.910004,46.402824,-215.065399,-0.000310,0.003625,0.092065,206.410065,10.515030,0.920653,-215.065399,0.091137,0.000000
139.310013,43.989105,-215.109879,-0.000332,0.003603,0.091519,195.673309,9.968073,0.915188,-215.109879,0.090470,0.000000
139.710007,41.391434,-215.154358,-0.000315,0.003581,0.090963,184.118286,9.379433,0.909631,-215.154358,0.089802,0.000000
140.110001,39.270027,-215.109879,-0.000332,0.003563,0.090495,174.681808,8.898715,0.904953,-215.109879,0.089134,0.000000
140.510010,35.918304,-215.287796,-0.000328,0.003529,0.089646,159.772598,8.139204,0.896460,-215.287796,0.088467,0.000000
140.910004,31.947693,-215.198837,-0.000319,0.003493,0.088727,142.110428,7.239451,0.887270,-215.198837,0.087799,0.000000
141.310013,29.733940,-215.287796,-0.000319,0.003471,0.088171,132.263168,6.737807,0.881714,-215.287796,0.087131,0.000000
141.710007,27.024933,-215.287796,-0.000315,0.003445,0.087504,120.212906,6.123938,0.875037,-215.287796,0.086471,0.000000
142.110001,25.143707,-215.376770,-0.000323,0.003432,0.087183,111.844795,5.697646,0.871828,-215.376770,0.085804,0.000000
142.510010,21.890289,-215.376770,-0.000315,0.003400,0.086359,97.372871,4.960411,0.863592,-215.376770,0.085136,0.000000
142.910004,18.221298,-215.421249,-0.000306,0.003367,0.085527,81.052383,4.129005,0.855265,-215.421249,0.084468,0.000000
143.310013,15.813911,-215.465729,-0.000310,0.003344,0.084945,70.343788,3.583484,0.849452,-215.465729,0.083801,0.000000
143.710007,12.774239,-215.465729,-0.000319,0.003313,0.084156,56.822651,2.894684,0.841564,-215.465729,0.083133,0.000000
144.110001,9.536827,-215.554687,-0.000306,0.003286,0.083471,42.421925,2.161076,0.834706,-215.554687,0.082465,0.000000
144.510010,6.331818,-215.510208,-0.000306,0.003252,0.082612,28.165331,1.434810,0.826121,-215.510208,0.081798,0.000000
144.910004,4.007103,-215.510208,-0.000319,0.003232,0.082091,17.824484,0.908022,0.820913,-215.510208,0.081130,0.000000
145.310013,1.734512,-215.599167,-0.000319,0.003211,0.081572,7.715496,0.393046,0.815721,-215.599167,0.080470,0.000000
145.710007,-1.295483,-215.643646,-0.000310,0.003180,0.080783,-5.762595,-0.293561,0.807833,-215.643646,0.079802,0.000000
146.110001,-0.484085,-215.732620,-0.000310,0.003155,0.080141,-2.153318,-0.109695,0.801414,-215.732620,0.079135,0.000000
146.510010,-0.246887,-215.777100,-0.000332,0.003120,0.079256,-1.098209,-0.055945,0.792557,-215.777100,0.078467,0.000000
146.910004,-0.102776,-215.866058,-0.000328,0.003102,0.078797,-0.457169,-0.023289,0.787970,-215.866058,0.077799,0.000000
147.310013,-0.112457,-215.777100,-0.000328,0.003082,0.078276,-0.500235,-0.025483,0.782762,-215.777100,0.077132,0.000000
147.710007,-0.094582,-215.866058,-0.000323,0.003048,0.077418,-0.420720,-0.021432,0.774178,-215.866058,0.076464,0.000000
148.110001,-0.117294,-215.910538,-0.000323,0.003023,0.076785,-0.521751,-0.026579,0.767849,-215.910538,0.075796,0.000000
148.510010,-0.102402,-215.955017,-0.000354,0.002989,0.075917,-0.455506,-0.023205,0.759174,-215.955017,0.075136,0.000000
148.910004,-0.109848,-215.999496,-0.000358,0.002973,0.075510,-0.488628,-0.024892,0.755102,-215.999496,0.074469,0.000000
149.310013,-0.127350,-216.088455,-0.000418,0.002948,0.074885,-0.566480,-0.028858,0.748849,-216.088455,0.073801,0.000000
149.710007,-0.106125,-216.088455,-0.000453,0.002923,0.074243,-0.472067,-0.024048,0.742430,-216.088455,0.073133,0.000000
150.110001,-0.109848,-216.132935,-0.000509,0.002895,0.073533,-0.488628,-0.024892,0.735329,-216.132935,0.072466,0.000000
150.510010,-0.076706,-216.177429,-0.000573,0.002860,0.072640,-0.341205,-0.017382,0.726397,-216.177429,0.071798,0.000000
150.910004,-0.072617,-216.266388,-0.000604,0.002839,0.072119,-0.323015,-0.016455,0.721189,-216.266388,0.071130,0.000000
151.310013,-0.090858,-216.266388,-0.000681,0.002808,0.071330,-0.404159,-0.020589,0.713301,-216.266388,0.070463,0.000000
151.710007,-0.118042,-216.310867,-0.000711,0.002783,0.070679,-0.525077,-0.026749,0.706791,-216.310867,0.069804,0.000000
152.110001,-0.130707,-216.355347,-0.000746,0.002762,0.070151,-0.581413,-0.029619,0.701508,-216.355347,0.069136,0.000000
152.510010,-0.061073,-216.444305,-0.000815,0.002732,0.069395,-0.271668,-0.013839,0.693953,-216.444305,0.068467,0.000000
152.910004,-0.081924,-216.444305,-0.000832,0.002712,0.068884,-0.364418,-0.018564,0.688836,-216.444305,0.067800,0.000000
153.310013,-0.096069,-216.488785,-0.000892,0.002688,0.068286,-0.427338,-0.021770,0.682856,-216.488785,0.067132,0.000000
153.710007,-0.138527,-216.577744,-0.000936,0.002653,0.067376,-0.616198,-0.031391,0.673757,-216.577744,0.066464,0.000000
154.110001,-0.135544,-216.533264,-0.000983,0.002627,0.066716,-0.602929,-0.030715,0.667156,-216.533264,0.065797,0.000000
154.510010,-0.102776,-216.577744,-0.001018,0.002603,0.066108,-0.457169,-0.023289,0.661085,-216.577744,0.065129,0.000000
154.910004,-0.121765,-216.666718,-0.001074,0.002580,0.065536,-0.541638,-0.027592,0.655362,-216.666718,0.064470,0.000000
155.310013,-0.134430,-216.711197,-0.001108,0.002547,0.064704,-0.597974,-0.030462,0.647035,-216.711197,0.063803,0.000000
155.710007,-0.147835,-216.711197,-0.001147,0.002526,0.064159,-0.657602,-0.033500,0.641585,-216.711197,0.063135,0.000000
156.110001,-0.150070,-216.800156,-0.001168,0.002492,0.063299,-0.667546,-0.034006,0.632986,-216.800156,0.062467,0.000000
156.510010,-0.152672,-216.755676,-0.001212,0.002470,0.062744,-0.679118,-0.034596,0.627445,-216.755676,0.061798,0.000000
156.910004,-0.154533,-216.800156,-0.001229,0.002449,0.062215,-0.687399,-0.035018,0.622146,-216.800156,0.061131,0.000000
157.310013,-0.144112,-216.844635,-0.001272,0.002419,0.061444,-0.641041,-0.032656,0.614440,-216.844635,0.060463,0.000000
157.710007,-0.141876,-216.933594,-0.001298,0.002396,0.060854,-0.631097,-0.032150,0.608535,-216.933594,0.059795,0.000000
158.110001,-0.163475,-216.933594,-0.001354,0.002358,0.059900,-0.727173,-0.037044,0.598997,-216.933594,0.059128,0.000000
158.510010,-0.123253,-217.022568,-0.001375,0.002339,0.059406,-0.548256,-0.027929,0.594062,-217.022568,0.058469,0.000000
158.910004,-0.146339,-217.067047,-0.001393,0.002325,0.059058,-0.650950,-0.033161,0.590580,-217.067047,0.057801,0.000000
159.310013,-0.150810,-217.067047,-0.001414,0.002293,0.058253,-0.670837,-0.034174,0.582526,-217.067047,0.057134,0.000000
159.710007,-0.182465,-217.156006,-0.001475,0.002263,0.057480,-0.811643,-0.041347,0.574804,-217.156006,0.056466,0.000000
160.110001,-0.177620,-217.156006,-0.001479,0.002233,0.056725,-0.790093,-0.040249,0.567250,-217.156006,0.055798,0.000000
160.510010,-0.185814,-217.244965,-0.001509,0.002209,0.056119,-0.826542,-0.042106,0.561194,-217.244965,0.055131,0.000000
160.910004,-0.163101,-217.244965,-0.001548,0.002183,0.055443,-0.725510,-0.036959,0.554427,-217.244965,0.054462,0.000000
161.310013,-0.173523,-217.244965,-0.001561,0.002164,0.054966,-0.771869,-0.039321,0.549658,-217.244965,0.053794,0.000000
161.710007,-0.206665,-217.289444,-0.001604,0.002133,0.054175,-0.919292,-0.046831,0.541755,-217.289444,0.053135,0.000000
162.110001,-0.173897,-217.289444,-0.001634,0.002099,0.053326,-0.773532,-0.039406,0.533261,-217.289444,0.052468,0.000000
162.510010,-0.123253,-217.378403,-0.001677,0.002079,0.052805,-0.548256,-0.027929,0.528053,-217.378403,0.052710,0.000000
162.600006,-0.122513,-217.333923,-0.001660,0.002079,0.052814,-0.544964,-0.027762,0.528144,-217.333923,0.052710,0.000000