File: Data/compression 31/ManualNoHeating-17-31-reverse-1-3_11132024_174326.csv
Time (sec),S:Load (lbs),S:HL1 (DIM),S:LVDT (in),S:Position (in),Ch:Position (mm),Ch:Load (N),Ch:Stress (MPa),Ch:Strain (mm/mm),Ch:HL1 (DIM),Set Point (),Cycles ()
0.110000,-0.052132,-178.502060,-0.010300,-0.005145,-0.130691,-0.231893,-0.011813,-1.306909,-178.502060,-0.130482,0.000000
0.460000,-0.058838,-178.591019,-0.010296,-0.005112,-0.129832,-0.261724,-0.013333,-1.298325,-178.591019,-0.129286,0.000000
0.810000,-0.038727,-178.546539,-0.010240,-0.004897,-0.124394,-0.172265,-0.008776,-1.243944,-178.546539,-0.123457,0.000000
1.160000,-0.053253,-178.591019,-0.010011,-0.004674,-0.118731,-0.236882,-0.012067,-1.187306,-178.591019,-0.117630,0.000000
1.510000,-0.020851,-178.679977,-0.009804,-0.004439,-0.112738,-0.092750,-0.004725,-1.127384,-178.679977,-0.111803,0.000000
1.860000,-0.050644,-178.679977,-0.009585,-0.004221,-0.107214,-0.225275,-0.011476,-1.072140,-178.679977,-0.105974,0.000000
2.210000,-0.023087,-178.724457,-0.009339,-0.003986,-0.101240,-0.102694,-0.005231,-1.012399,-178.724457,-0.100129,0.000000
2.560000,-0.075592,-178.724457,-0.009102,-0.003753,-0.095334,-0.336250,-0.017129,-0.953339,-178.724457,-0.094301,0.000000
2.910000,-0.027931,-178.813431,-0.008877,-0.003531,-0.089679,-0.124244,-0.006329,-0.896793,-178.813431,-0.088474,0.000000
3.260000,-0.042450,-178.813431,-0.008623,-0.003293,-0.083652,-0.188827,-0.009619,-0.836522,-178.813431,-0.082645,0.000000
3.610000,-0.006706,-178.857910,-0.008390,-0.003073,-0.078049,-0.029831,-0.001520,-0.780491,-178.857910,-0.076818,0.000000
3.960000,-0.017876,-178.946869,-0.008162,-0.002840,-0.072136,-0.079515,-0.004051,-0.721356,-178.946869,-0.070973,0.000000
4.310000,-0.040588,-178.991348,-0.007920,-0.002605,-0.066160,-0.180546,-0.009197,-0.661600,-178.991348,-0.065146,0.000000
4.660000,-0.112083,-178.991348,-0.007687,-0.002380,-0.060445,-0.498572,-0.025398,-0.604448,-178.991348,-0.059318,0.000000
5.010000,-0.032028,-178.991348,-0.007442,-0.002147,-0.054539,-0.142469,-0.007258,-0.545388,-178.991348,-0.053490,0.000000
5.360000,-0.002983,-179.035828,-0.007217,-0.001922,-0.048807,-0.013269,-0.000676,-0.488070,-179.035828,-0.047662,0.000000
5.710000,-0.003349,-179.080307,-0.006976,-0.001697,-0.043092,-0.014898,-0.000759,-0.430918,-179.080307,-0.041817,0.000000
6.060000,-0.029793,-179.124786,-0.006743,-0.001456,-0.036995,-0.132525,-0.006751,-0.369951,-179.124786,-0.035990,0.000000
6.410000,-0.066658,-179.169266,-0.006497,-0.001230,-0.031254,-0.296510,-0.015105,-0.312541,-179.169266,-0.030161,0.000000
6.760000,-0.105751,-179.213745,-0.006252,-0.001000,-0.025409,-0.470404,-0.023964,-0.254088,-179.213745,-0.024334,0.000000
7.110000,0.004471,-179.258240,-0.006049,-0.000768,-0.019495,0.019887,0.001013,-0.194952,-179.258240,-0.018507,0.000000
7.460001,0.021973,-179.258240,-0.005795,-0.000549,-0.013953,0.097739,0.004979,-0.139526,-179.258240,-0.012678,0.000000
7.810000,-0.008568,-179.347198,-0.005562,-0.000310,-0.007865,-0.038112,-0.001941,-0.078650,-179.347198,-0.006832,0.000000
8.160001,-0.025696,-179.391678,-0.005316,-0.000082,-0.002080,-0.114301,-0.005823,-0.020802,-179.391678,-0.001005,0.000000
8.510000,-0.061813,-179.347198,-0.005101,0.000146,0.003712,-0.274960,-0.014007,0.037122,-179.347198,0.004822,0.000000
8.860001,0.112083,-179.480637,-0.004859,0.000383,0.009739,0.498572,0.025398,0.097393,-179.480637,0.010651,0.000000
9.210000,0.184326,-179.525116,-0.004833,-0.000001,-0.000026,0.819924,0.041769,-0.000257,-179.525116,0.000165,0.000000
9.560000,0.167564,-179.569595,-0.004842,-0.000001,-0.000026,0.745364,0.037971,-0.000257,-179.569595,0.000442,0.000000
9.910001,0.144852,-179.525116,-0.004838,0.000001,0.000035,0.644332,0.032824,0.000348,-179.525116,0.001023,0.000000
10.260000,0.309067,-179.569595,-0.004829,0.000030,0.000754,1.374798,0.070036,0.007540,-179.569595,0.001605,0.000000
10.610001,0.546272,-179.614075,-0.004816,0.000052,0.001326,2.429940,0.123787,0.013262,-179.614075,0.002194,0.000000
10.960001,0.913055,-179.658554,-0.004794,0.000072,0.001838,4.061473,0.206901,0.018379,-179.658554,0.002775,0.000000
11.310000,1.099617,-179.658554,-0.004786,0.000088,0.002229,4.891341,0.249177,0.022285,-179.658554,0.003356,0.000000
11.660001,1.758339,-179.747528,-0.004751,0.000126,0.003208,7.821482,0.398445,0.032081,-179.747528,0.003945,0.000000
12.010000,2.086403,-179.747528,-0.004743,0.000144,0.003668,9.280784,0.472786,0.036683,-179.747528,0.004527,0.000000
12.360001,2.456909,-179.792007,-0.004721,0.000162,0.004110,10.928878,0.556744,0.041104,-179.792007,0.005108,0.000000
12.710001,3.187134,-179.836487,-0.004712,0.000194,0.004917,14.177079,0.722215,0.049173,-179.836487,0.005689,0.000000
13.060000,3.628395,-179.880966,-0.004678,0.000210,0.005343,16.139908,0.822206,0.053428,-179.880966,0.006278,0.000000
13.410001,4.334045,-179.969925,-0.004678,0.000240,0.006088,19.278797,0.982109,0.060876,-179.969925,0.006860,0.000000
13.760000,4.735832,-180.014404,-0.004648,0.000259,0.006583,21.066034,1.073155,0.065827,-180.014404,0.007441,0.000000
14.110001,5.137253,-180.058884,-0.004635,0.000279,0.007085,22.851643,1.164118,0.070853,-180.058884,0.008022,0.000000
14.460001,6.010834,-180.058884,-0.004605,0.000309,0.007839,26.737524,1.362074,0.078393,-180.058884,0.008611,0.000000
14.810000,6.332939,-180.103378,-0.004609,0.000326,0.008281,28.170321,1.435064,0.082814,-180.103378,0.009193,0.000000
15.160001,6.640518,-180.147858,-0.004592,0.000341,0.008672,29.538500,1.504763,0.086720,-180.147858,0.009774,0.000000
15.510001,7.460106,-180.236816,-0.004549,0.000371,0.009418,33.184208,1.690484,0.094183,-180.236816,0.010363,0.000000
15.860001,8.055908,-180.236816,-0.004540,0.000396,0.010051,35.834469,1.825495,0.100512,-180.236816,0.010944,0.000000
16.210001,8.364601,-180.325775,-0.004531,0.000413,0.010502,37.207603,1.895446,0.105023,-180.325775,0.011526,0.000000
16.560001,9.289574,-180.370255,-0.004488,0.000444,0.011274,41.322086,2.105047,0.112744,-180.370255,0.012107,0.000000
16.910002,9.514114,-180.325775,-0.004497,0.000462,0.011733,42.320896,2.155929,0.117332,-180.325775,0.012696,0.000000
17.260000,10.227951,-180.414734,-0.004471,0.000491,0.012470,45.496197,2.317687,0.124705,-180.414734,0.013277,0.000000
17.610001,10.659904,-180.414734,-0.004437,0.000512,0.013000,47.417622,2.415569,0.130004,-180.414734,0.013859,0.000000
17.960001,11.027435,-180.414734,-0.004441,0.000532,0.013520,49.052483,2.498852,0.135196,-180.414734,0.014440,0.000000
18.310001,11.700317,-180.503693,-0.004411,0.000557,0.014145,52.045612,2.651330,0.141449,-180.503693,0.015029,0.000000
18.660002,12.219772,-180.503693,-0.004381,0.000581,0.014752,54.356262,2.769040,0.147520,-180.503693,0.015610,0.000000
19.010000,12.278236,-180.637146,-0.004389,0.000594,0.015081,54.616322,2.782288,0.150805,-180.637146,0.016192,0.000000
19.360001,13.440781,-180.637146,-0.004350,0.000629,0.015966,59.787579,3.045724,0.159662,-180.637146,0.016772,0.000000
19.710001,13.613937,-180.726105,-0.004324,0.000648,0.016460,60.557819,3.084962,0.164598,-180.726105,0.017362,0.000000
20.060001,13.909599,-180.681625,-0.004312,0.000667,0.016937,61.872990,3.151960,0.169366,-180.681625,0.017943,0.000000
20.410002,14.712807,-180.770584,-0.004303,0.000695,0.017665,65.445831,3.333970,0.176649,-180.770584,0.018523,0.000000
20.760000,15.177528,-180.815063,-0.004255,0.000718,0.018246,67.513016,3.439277,0.182462,-180.815063,0.019114,0.000000
21.110001,15.100822,-180.815063,-0.004260,0.000736,0.018697,67.171814,3.421895,0.186974,-180.815063,0.019695,0.000000
21.460001,16.284966,-180.859543,-0.004230,0.000768,0.019495,72.439148,3.690226,0.194952,-180.859543,0.020276,0.000000
21.810001,16.190010,-180.904022,-0.004217,0.000782,0.019860,72.016762,3.668709,0.198601,-180.904022,0.020856,0.000000
22.160002,16.894165,-180.992996,-0.004182,0.000809,0.020553,75.149002,3.828273,0.205535,-180.992996,0.021447,0.000000
22.510000,17.417351,-180.992996,-0.004178,0.000833,0.021161,77.476242,3.946828,0.211606,-180.992996,0.022028,0.000000
22.860001,17.563690,-181.081955,-0.004161,0.000848,0.021551,78.127197,3.979989,0.215512,-181.081955,0.022608,0.000000
23.210001,18.557556,-181.081955,-0.004139,0.000881,0.022366,82.548134,4.205202,0.223657,-181.081955,0.023189,0.000000
23.560001,18.733688,-181.215393,-0.004126,0.000901,0.022887,83.331604,4.245115,0.228865,-181.215393,0.023780,0.000000
23.910002,19.021904,-181.170914,-0.004100,0.000922,0.023424,84.613655,4.310425,0.234240,-181.170914,0.024361,0.000000
24.260000,19.636314,-181.215393,-0.004079,0.000950,0.024117,87.346687,4.449652,0.241174,-181.215393,0.024941,0.000000
24.610001,19.793083,-181.304352,-0.004066,0.000968,0.024587,88.044029,4.485177,0.245867,-181.304352,0.025531,0.000000
24.960001,19.733879,-181.304352,-0.004049,0.000982,0.024941,87.780678,4.471761,0.249409,-181.304352,0.026113,0.000000
25.310001,21.029732,-181.348831,-0.004027,0.001021,0.025922,93.544922,4.765405,0.259220,-181.348831,0.026693,0.000000
25.660002,20.885254,-181.393326,-0.003988,0.001036,0.026320,92.902252,4.732666,0.263202,-181.393326,0.027274,0.000000
26.010002,21.492218,-181.437805,-0.003984,0.001062,0.026971,95.602158,4.870206,0.269712,-181.437805,0.027864,0.000000
26.360001,21.965881,-181.482285,-0.003945,0.001087,0.027613,97.709122,4.977540,0.276131,-181.482285,0.028446,0.000000
26.710001,21.828842,-181.482285,-0.003932,0.001102,0.027995,97.099541,4.946486,0.279946,-181.482285,0.029026,0.000000
27.060001,22.840950,-181.526764,-0.003911,0.001135,0.028827,101.601624,5.175833,0.288273,-181.526764,0.029607,0.000000
27.410002,22.934792,-181.571243,-0.003906,0.001155,0.029347,102.019051,5.197098,0.293466,-181.571243,0.030197,0.000000
27.760002,23.070335,-181.660202,-0.003880,0.001176,0.029858,102.621979,5.227813,0.298583,-181.660202,0.030777,0.000000
28.110001,23.679161,-181.660202,-0.003863,0.001201,0.030509,105.330170,5.365775,0.305093,-181.660202,0.031359,0.000000
28.460001,24.010201,-181.660202,-0.003824,0.001224,0.031091,106.802704,5.440789,0.310906,-181.660202,0.031940,0.000000
28.810001,23.610649,-181.793640,-0.003820,0.001236,0.031384,105.025414,5.350249,0.313843,-181.793640,0.032530,0.000000
29.160002,24.938156,-181.749161,-0.003790,0.001274,0.032365,110.930458,5.651067,0.323654,-181.749161,0.033110,0.000000
29.510002,24.646957,-181.838135,-0.003777,0.001289,0.032747,109.635139,5.585080,0.327469,-181.838135,0.033692,0.000000
29.860001,24.869637,-181.927094,-0.003760,0.001313,0.033345,110.625671,5.635540,0.333449,-181.927094,0.034282,0.000000
30.210001,25.589806,-181.971573,-0.003747,0.001339,0.034013,113.829140,5.798733,0.340126,-181.971573,0.034862,0.000000
30.560001,25.577148,-181.927094,-0.003725,0.001356,0.034455,113.772835,5.795865,0.344547,-181.927094,0.035443,0.000000
30.910002,26.624260,-181.971573,-0.003704,0.001389,0.035271,118.430626,6.033144,0.352707,-181.971573,0.036025,0.000000
31.260002,26.364342,-182.060532,-0.003669,0.001407,0.035738,117.274452,5.974246,0.357385,-182.060532,0.036615,0.000000
31.610001,26.682724,-182.016052,-0.003660,0.001429,0.036285,118.690681,6.046391,0.362850,-182.016052,0.037195,0.000000
31.960001,27.014877,-182.149490,-0.003639,0.001451,0.036866,120.168175,6.121659,0.368664,-182.149490,0.037776,0.000000
32.310001,27.542900,-182.105011,-0.003622,0.001477,0.037525,122.516937,6.241311,0.375250,-182.105011,0.038358,0.000000
32.660000,26.949715,-182.193970,-0.003604,0.001487,0.037767,119.878319,6.106893,0.377672,-182.193970,0.038947,0.000000
33.010002,28.484634,-182.282944,-0.003574,0.001526,0.038765,126.705978,6.454710,0.387649,-182.282944,0.039528,0.000000
33.360001,28.238869,-182.193970,-0.003553,0.001543,0.039190,125.612762,6.399019,0.391903,-182.193970,0.040109,0.000000
33.710003,28.163277,-182.282944,-0.003540,0.001561,0.039658,125.276512,6.381890,0.396581,-182.282944,0.040691,0.000000
34.060001,29.266243,-182.327423,-0.003523,0.001594,0.040491,130.182755,6.631826,0.404908,-182.327423,0.041280,0.000000
34.410000,29.058083,-182.327423,-0.003501,0.001609,0.040863,129.256805,6.584656,0.408632,-182.327423,0.041861,0.000000
34.760002,29.919754,-182.416382,-0.003475,0.001639,0.041619,133.089706,6.779913,0.416187,-182.416382,0.042442,0.000000
35.110001,30.001678,-182.416382,-0.003449,0.001658,0.042121,133.454132,6.798478,0.421213,-182.416382,0.043031,0.000000
35.460003,30.057159,-182.505341,-0.003445,0.001680,0.042668,133.700928,6.811049,0.426679,-182.505341,0.043613,0.000000
35.810001,31.071129,-182.594299,-0.003428,0.001709,0.043405,138.211288,7.040819,0.434052,-182.594299,0.044194,0.000000
36.160000,30.975433,-182.594299,-0.003402,0.001728,0.043882,137.785614,7.019134,0.438821,-182.594299,0.044775,0.000000
36.510002,30.755356,-182.638779,-0.003393,0.001743,0.044264,136.806656,6.969263,0.442636,-182.638779,0.045364,0.000000
36.860001,31.678101,-182.683273,-0.003372,0.001770,0.044966,140.911224,7.178360,0.449661,-182.683273,0.045946,0.000000
37.210003,32.124199,-182.638779,-0.003337,0.001795,0.045599,142.895569,7.279448,0.455989,-182.638779,0.046527,0.000000
37.560001,32.330864,-182.727753,-0.003320,0.001816,0.046120,143.814865,7.326279,0.461197,-182.727753,0.047108,0.000000
37.910004,33.359734,-182.772232,-0.003316,0.001843,0.046822,148.391510,7.559424,0.468222,-182.772232,0.047697,0.000000
38.260002,33.328827,-182.727753,-0.003298,0.001863,0.047316,148.254028,7.552420,0.473157,-182.727753,0.048279,0.000000
38.610001,34.170761,-182.816711,-0.003281,0.001893,0.048070,151.999130,7.743205,0.480697,-182.816711,0.048860,0.000000
38.960003,34.368118,-182.861191,-0.003255,0.001911,0.048530,152.877029,7.787927,0.485299,-182.861191,0.049449,0.000000
39.310001,34.530846,-182.905670,-0.003229,0.001934,0.049128,153.600876,7.824802,0.491279,-182.905670,0.050030,0.000000
39.660004,35.089401,-182.905670,-0.003212,0.001956,0.049693,156.085449,7.951372,0.496926,-182.905670,0.050612,0.000000
40.010002,35.670303,-182.950150,-0.003216,0.001980,0.050300,158.669434,8.083006,0.502997,-182.950150,0.051193,0.000000
40.360001,35.240959,-182.950150,-0.003195,0.001993,0.050612,156.759613,7.985716,0.506116,-182.950150,0.051782,0.000000
40.710003,36.901741,-183.039108,-0.003165,0.002028,0.051522,164.147141,8.362054,0.515215,-183.039108,0.052363,0.000000
41.060001,36.887962,-183.083588,-0.003152,0.002049,0.052042,164.085846,8.358932,0.520423,-183.083588,0.052945,0.000000
41.410004,36.805664,-183.128082,-0.003152,0.002065,0.052450,163.719772,8.340283,0.524496,-183.128082,0.053526,0.000000
41.760002,37.925758,-183.172562,-0.003122,0.002095,0.053213,168.702194,8.594100,0.532126,-183.172562,0.054115,0.000000
42.110001,38.493629,-183.172562,-0.003100,0.002117,0.053768,171.228210,8.722781,0.537682,-183.172562,0.054696,0.000000
42.460003,38.001724,-183.261520,-0.003091,0.002135,0.054236,169.040115,8.611314,0.542360,-183.261520,0.055278,0.000000
42.810001,39.976791,-183.261520,-0.003083,0.002167,0.055052,177.825653,9.058870,0.550521,-183.261520,0.055857,0.000000
43.160004,39.593620,-183.350479,-0.003057,0.002182,0.055424,176.121216,8.972042,0.554245,-183.350479,0.056448,0.000000
43.510002,40.535347,-183.350479,-0.003035,0.002208,0.056092,180.310226,9.185441,0.560921,-183.350479,0.057029,0.000000
43.860001,41.255516,-183.394958,-0.003022,0.002232,0.056699,183.513702,9.348633,0.566992,-183.394958,0.057611,0.000000
44.210003,41.122955,-183.483917,-0.003005,0.002247,0.057081,182.924042,9.318595,0.570808,-183.483917,0.058200,0.000000
44.560001,42.403915,-183.439438,-0.002984,0.002279,0.057888,188.622040,9.608865,0.578877,-183.439438,0.058781,0.000000
44.910004,43.007530,-183.483917,-0.002975,0.002300,0.058425,191.307053,9.745646,0.584252,-183.483917,0.059362,0.000000
45.260002,43.408943,-183.528397,-0.002949,0.002322,0.058972,193.092621,9.836607,0.589717,-183.528397,0.059942,0.000000
45.610001,44.438553,-183.528397,-0.002936,0.002349,0.059665,197.672562,10.069921,0.596651,-183.528397,0.060533,0.000000
45.960003,44.618416,-183.661850,-0.002915,0.002368,0.060151,198.472626,10.110678,0.601511,-183.661850,0.061114,0.000000
46.310001,44.390144,-183.706329,-0.002893,0.002383,0.060523,197.457230,10.058950,0.605235,-183.706329,0.061694,0.000000
46.660004,46.670555,-183.750809,-0.002902,0.002420,0.061470,207.600998,10.575699,0.614697,-183.750809,0.062275,0.000000
47.010002,46.487724,-183.795288,-0.002876,0.002435,0.061851,206.787720,10.534269,0.618512,-183.795288,0.062866,0.000000
47.360001,47.446953,-183.795288,-0.002863,0.002461,0.062501,211.054581,10.751633,0.625007,-183.795288,0.063447,0.000000
47.710003,48.440445,-183.839767,-0.002846,0.002486,0.063152,215.473862,10.976762,0.631517,-183.839767,0.064027,0.000000
48.060001,48.358521,-183.928726,-0.002815,0.002502,0.063542,215.109436,10.958198,0.635423,-183.928726,0.064617,0.000000
48.410004,50.081490,-183.928726,-0.002820,0.002535,0.064383,222.773590,11.348627,0.643826,-183.928726,0.065199,0.000000
48.760002,50.500778,-183.928726,-0.002802,0.002554,0.064869,224.638687,11.443640,0.648686,-183.928726,0.065778,0.000000
49.110001,50.840385,-184.017700,-0.002777,0.002574,0.065389,226.149323,11.520597,0.653894,-184.017700,0.066360,0.000000
49.460003,51.821960,-184.017700,-0.002781,0.002601,0.066074,230.515594,11.743024,0.660737,-184.017700,0.066950,0.000000
49.810001,52.643036,-184.062180,-0.002764,0.002623,0.066629,234.167923,11.929082,0.666293,-184.062180,0.067532,0.000000
50.160004,52.247955,-184.062180,-0.002746,0.002635,0.066932,232.410507,11.839557,0.669321,-184.062180,0.068111,0.000000
50.510002,54.787903,-184.151138,-0.002738,0.002674,0.067913,243.708771,12.415115,0.679131,-184.151138,0.068693,0.000000
50.860001,54.723114,-184.240097,-0.002703,0.002689,0.068295,243.420563,12.400435,0.682946,-184.240097,0.069283,0.000000
51.210003,55.509933,-184.151138,-0.002708,0.002712,0.068874,246.920517,12.578731,0.688745,-184.151138,0.069863,0.000000
51.560001,56.765945,-184.329056,-0.002686,0.002738,0.069544,252.507538,12.863347,0.695437,-184.329056,0.070444,0.000000
51.910004,57.116722,-184.329056,-0.002673,0.002755,0.069986,254.067871,12.942834,0.699857,-184.329056,0.071026,0.000000
52.260002,58.914536,-184.373535,-0.002665,0.002788,0.070809,262.064941,13.350225,0.708093,-184.373535,0.071616,0.000000
52.610001,59.198280,-184.418030,-0.002673,0.002808,0.071312,263.327087,13.414522,0.713120,-184.418030,0.072196,0.000000
52.960003,60.052879,-184.462509,-0.002643,0.002827,0.071807,267.128540,13.608177,0.718070,-184.462509,0.072777,0.000000
53.310001,60.790550,-184.506989,-0.002639,0.002850,0.072379,270.409882,13.775335,0.723793,-184.506989,0.073368,0.000000
53.660004,62.201096,-184.551468,-0.002626,0.002876,0.073055,276.684296,14.094970,0.730545,-184.551468,0.073948,0.000000
54.010002,61.799675,-184.551468,-0.002617,0.002885,0.073289,274.898682,14.004007,0.732892,-184.551468,0.074529,0.000000
54.360004,64.524323,-184.595947,-0.002583,0.002925,0.074304,287.018524,14.621421,0.743035,-184.595947,0.075110,0.000000
54.710003,64.782013,-184.595947,-0.002583,0.002941,0.074712,288.164795,14.679813,0.747123,-184.595947,0.075701,0.000000
55.060001,65.091446,-184.595947,-0.002574,0.002959,0.075171,289.541199,14.749933,0.751710,-184.595947,0.076281,0.000000
55.410004,65.482437,-184.684906,-0.002578,0.002967,0.075353,291.280426,14.838532,0.753527,-184.684906,0.013250,0.000000
55.760002,65.995193,-184.773865,-0.002548,0.002952,0.074971,293.561279,14.954724,0.749712,-184.773865,294.500458,0.000000
56.110004,65.365891,-184.773865,-0.002539,0.002993,0.076029,290.761993,14.812122,0.760295,-184.773865,294.500458,0.000000
56.460003,65.249344,-184.862839,-0.002531,0.003006,0.076350,290.243591,14.785712,0.763504,-184.862839,294.500458,0.000000
56.810001,64.892609,-184.862839,-0.002539,0.003014,0.076559,288.656738,14.704876,0.765593,-184.862839,294.500458,0.000000
57.160004,65.501801,-184.907318,-0.002522,0.003026,0.076853,291.366547,14.842920,0.768530,-184.907318,294.500458,0.000000
57.510002,65.429199,-184.951797,-0.002518,0.003036,0.077123,291.043610,14.826468,0.771225,-184.951797,294.500458,0.000000
57.860004,64.287491,-184.996277,-0.002505,0.003039,0.077183,285.965027,14.567754,0.771831,-184.996277,294.500458,0.000000
58.210003,65.567337,-184.996277,-0.002462,0.002859,0.072622,291.658081,14.857771,0.726215,-184.996277,294.500458,0.000000
58.560001,65.311523,-185.085236,-0.002453,0.003063,0.077790,290.520172,14.799802,0.777902,-185.085236,294.500458,0.000000
58.910004,65.181198,-185.085236,-0.002466,0.003072,0.078025,289.940460,14.770271,0.780249,-185.085236,294.500458,0.000000
59.260002,65.175613,-185.174194,-0.002466,0.003082,0.078276,289.915619,14.769006,0.782762,-185.174194,294.500458,0.000000
59.610004,65.548355,-185.174194,-0.002471,0.003083,0.078311,291.573639,14.853469,0.783110,-185.174194,294.500458,0.000000
59.960003,66.858353,-185.218674,-0.002462,0.003089,0.078449,297.400818,15.150319,0.784488,-185.218674,294.500458,0.000000
60.310001,65.856308,-185.218674,-0.002466,0.003068,0.077937,292.943481,14.923252,0.779370,-185.218674,294.500458,0.000000
60.660004,65.502182,-185.263168,-0.002453,0.003112,0.079056,291.368256,14.843006,0.790559,-185.263168,294.500458,0.000000
61.010002,65.417648,-185.263168,-0.002445,0.003122,0.079307,290.992218,14.823851,0.793072,-185.263168,294.500458,0.000000
61.360004,65.385254,-185.352127,-0.002445,0.003128,0.079456,290.848145,14.816510,0.794555,-185.352127,294.500458,0.000000
61.710003,65.257156,-185.396606,-0.002440,0.003134,0.079593,290.278320,14.787483,0.795933,-185.396606,294.500458,0.000000
62.060001,65.021820,-185.396606,-0.002449,0.003138,0.079716,289.231506,14.734156,0.797159,-185.396606,294.500458,0.000000
62.410004,65.721878,-185.485565,-0.002432,0.003153,0.080097,292.345520,14.892791,0.800975,-185.485565,294.500458,0.000000
62.760002,65.336838,-185.485565,-0.002427,0.003154,0.080105,290.632782,14.805539,0.801050,-185.485565,294.500458,0.000000
63.110004,65.334244,-185.485565,-0.002436,0.003160,0.080270,290.621216,14.804952,0.802701,-185.485565,294.500458,0.000000
63.460003,65.142838,-185.574524,-0.002427,0.003164,0.080375,289.769806,14.761578,0.803745,-185.574524,294.500458,0.000000
63.810001,65.058685,-185.663483,-0.002445,0.003173,0.080583,289.395477,14.742508,0.805834,-185.663483,294.500458,0.000000
64.160004,65.172623,-185.663483,-0.002427,0.003175,0.080652,289.902313,14.768328,0.806516,-185.663483,294.500458,0.000000
64.510002,65.373703,-185.663483,-0.002427,0.003183,0.080851,290.796753,14.813893,0.808514,-185.663483,294.500458,0.000000
64.860001,65.353973,-185.707977,-0.002419,0.003189,0.080998,290.708984,14.809422,0.809983,-185.707977,294.500458,0.000000
65.210007,65.310776,-185.752457,-0.002419,0.003194,0.081121,290.516846,14.799634,0.811209,-185.752457,294.500458,0.000000
65.560005,65.190125,-185.841415,-0.002427,0.003197,0.081207,289.980164,14.772293,0.812072,-185.841415,294.500458,0.000000
65.910004,65.183060,-185.885895,-0.002414,0.003202,0.081328,289.948730,14.770692,0.813283,-185.885895,294.500458,0.000000
66.260002,65.173004,-185.885895,-0.002406,0.003210,0.081528,289.903992,14.768414,0.815282,-185.885895,294.500458,0.000000
66.610001,65.305939,-185.885895,-0.002406,0.003215,0.081649,290.495331,14.798536,0.816493,-185.885895,294.500458,0.000000
66.960007,65.337967,-185.974854,-0.002406,0.003222,0.081840,290.637787,14.805795,0.818400,-185.974854,294.500458,0.000000
67.310005,65.310410,-186.019333,-0.002393,0.003222,0.081840,290.515198,14.799551,0.818400,-186.019333,294.500458,0.000000
67.660004,65.287689,-186.019333,-0.002410,0.003227,0.081954,290.414154,14.794401,0.819536,-186.019333,294.500458,0.000000
68.010002,65.659317,-186.063812,-0.002393,0.003235,0.082170,292.067230,14.878613,0.821701,-186.063812,294.500458,0.000000
68.360001,65.350998,-186.108292,-0.002393,0.003235,0.082170,290.695770,14.808748,0.821701,-186.108292,294.500458,0.000000
68.710007,65.373337,-186.108292,-0.002402,0.003240,0.082300,290.795135,14.813809,0.823003,-186.108292,294.500458,0.000000
69.060005,65.247467,-186.197266,-0.002376,0.003243,0.082370,290.235229,14.785287,0.823699,-186.197266,294.500458,0.000000
69.410004,65.200928,-186.241745,-0.002397,0.003246,0.082447,290.028198,14.774741,0.824471,-186.241745,294.500458,0.000000
69.760002,65.081772,-186.241745,-0.002380,0.003250,0.082552,289.498169,14.747741,0.825516,-186.241745,294.500458,0.000000
70.110001,65.183792,-186.330704,-0.002376,0.003254,0.082647,289.951996,14.770859,0.826470,-186.330704,294.500458,0.000000
70.460007,65.227371,-186.330704,-0.002384,0.003258,0.082759,290.145844,14.780734,0.827590,-186.330704,294.500458,0.000000
70.810005,65.182312,-186.375183,-0.002384,0.003261,0.082838,289.945404,14.770522,0.828377,-186.375183,294.500458,0.000000
71.160004,64.966705,-186.419662,-0.002358,0.003263,0.082880,288.986328,14.721666,0.828801,-186.419662,294.500458,0.000000
71.510002,65.247849,-186.508621,-0.002367,0.003269,0.083045,290.236938,14.785374,0.830451,-186.508621,294.500458,0.000000
71.860001,64.972656,-186.597595,-0.002358,0.003270,0.083054,289.012817,14.723015,0.830542,-186.597595,294.500458,0.000000
72.210007,66.392899,-186.597595,-0.002363,0.003278,0.083254,295.330353,15.044846,0.832541,-186.597595,294.500458,0.000000
72.560005,65.938599,-186.553116,-0.002376,0.003277,0.083245,293.309540,14.941900,0.832450,-186.553116,294.500458,0.000000
72.910004,65.567337,-186.686554,-0.002358,0.003278,0.083254,291.658081,14.857771,0.832541,-186.686554,294.500458,0.000000
73.260002,65.185654,-186.597595,-0.002367,0.003278,0.083254,289.960266,14.771280,0.832541,-186.597595,294.500458,0.000000
73.610001,65.701767,-186.731033,-0.002358,0.003292,0.083626,292.256042,14.888233,0.836265,-186.731033,294.500458,0.000000
73.960007,65.382278,-186.775513,-0.002358,0.003292,0.083626,290.834900,14.815836,0.836265,-186.775513,294.500458,0.000000
74.310005,65.061295,-186.819992,-0.002367,0.003293,0.083636,289.407104,14.743100,0.836356,-186.819992,294.500458,0.000000
74.660004,64.747375,-186.819992,-0.002350,0.003293,0.083636,288.010712,14.671965,0.836356,-186.819992,294.500458,0.000000
75.010002,64.458786,-186.819992,-0.002358,0.003293,0.083636,286.726990,14.606569,0.836356,-186.819992,294.500458,0.000000
75.360001,66.777176,-186.908951,-0.002354,0.003147,0.079923,297.039703,15.131925,0.799234,-186.908951,294.500458,0.000000
75.710007,66.407410,-186.908951,-0.002333,0.003147,0.079942,295.394897,15.048134,0.799415,-186.908951,294.500458,0.000000
76.060005,66.017166,-186.997925,-0.002337,0.003147,0.079942,293.659027,14.959704,0.799415,-186.997925,294.500458,0.000000
76.410004,65.710327,-187.086884,-0.002341,0.003168,0.080479,292.294128,14.890173,0.804790,-187.086884,294.500458,0.000000
76.760002,65.367752,-187.086884,-0.002337,0.003263,0.082880,290.770294,14.812545,0.828801,-187.086884,294.500458,0.000000
77.110001,65.286942,-187.175842,-0.002350,0.003311,0.084103,290.410828,14.794232,0.841034,-187.175842,294.500458,0.000000
77.460007,65.221039,-187.175842,-0.002333,0.003319,0.084303,290.117676,14.779299,0.843032,-187.175842,294.500458,0.000000
77.810005,65.287323,-187.220322,-0.002341,0.003323,0.084408,290.412506,14.794319,0.844077,-187.220322,294.500458,0.000000
78.160004,65.202042,-187.309280,-0.002333,0.003327,0.084503,290.033173,14.774994,0.845031,-187.309280,294.500458,0.000000
78.510002,65.428818,-187.264801,-0.002333,0.003333,0.084650,291.041931,14.826382,0.846499,-187.264801,294.500458,0.000000
78.860001,65.292526,-187.309280,-0.002333,0.003333,0.084650,290.435669,14.795499,0.846499,-187.309280,294.500458,0.000000
79.210007,65.253433,-187.398254,-0.002320,0.003336,0.084729,290.261780,14.786639,0.847287,-187.398254,294.500458,0.000000
79.560005,65.065750,-187.442734,-0.002324,0.003336,0.084736,289.426910,14.744110,0.847362,-187.442734,294.500458,0.000000
79.910004,65.145447,-187.442734,-0.002337,0.003340,0.084832,289.781433,14.762170,0.848316,-187.442734,294.500458,0.000000
80.260002,65.161087,-187.487213,-0.002333,0.003351,0.085110,289.850983,14.765714,0.851102,-187.487213,294.500458,0.000000
80.610001,65.595642,-187.487213,-0.002315,0.003348,0.085050,291.783997,14.864184,0.850496,-187.487213,294.500458,0.000000
80.960007,65.330887,-187.531693,-0.002328,0.003348,0.085050,290.606293,14.804191,0.850496,-187.531693,294.500458,0.000000
81.310005,65.082886,-187.620651,-0.002345,0.003348,0.085050,289.503143,14.747993,0.850496,-187.620651,294.500458,0.000000
81.660004,64.835632,-187.620651,-0.002333,0.003348,0.085050,288.403290,14.691964,0.850496,-187.620651,294.500458,0.000000
82.010002,64.594711,-187.620651,-0.002341,0.003348,0.085050,287.331635,14.637370,0.850496,-187.620651,294.500458,0.000000
82.360001,66.682968,-187.754089,-0.002337,0.003308,0.084026,296.620667,15.110577,0.840262,-187.754089,294.500458,0.000000
82.710007,66.411514,-187.798569,-0.002333,0.003308,0.084034,295.413177,15.049065,0.840338,-187.798569,294.500458,0.000000
83.060005,66.111755,-187.754089,-0.002320,0.003308,0.084034,294.079773,14.981138,0.840338,-187.754089,294.500458,0.000000
83.410004,65.840286,-187.798569,-0.002315,0.003312,0.084129,292.872223,14.919622,0.841291,-187.798569,294.500458,0.000000
83.760002,65.594528,-187.887543,-0.002311,0.003327,0.084503,291.779022,14.863933,0.845031,-187.887543,294.500458,0.000000
84.110001,65.393448,-187.932022,-0.002328,0.003336,0.084745,290.884583,14.818367,0.847453,-187.932022,294.500458,0.000000
84.460007,65.227737,-187.932022,-0.002320,0.003354,0.085196,290.147461,14.780817,0.851965,-187.932022,294.500458,0.000000
84.810005,65.506653,-187.976501,-0.002315,0.003374,0.085690,291.388153,14.844020,0.856900,-187.976501,294.500458,0.000000
85.160004,65.368866,-188.065460,-0.002311,0.003375,0.085734,290.775238,14.812798,0.857339,-188.065460,294.500458,0.000000
85.510002,65.317474,-188.065460,-0.002315,0.003377,0.085778,290.546631,14.801151,0.857778,-188.065460,294.500458,0.000000
85.860001,65.259018,-188.065460,-0.002307,0.003379,0.085820,290.286621,14.787905,0.858202,-188.065460,294.500458,0.000000
86.210007,65.289185,-188.109940,-0.002307,0.003381,0.085890,290.420807,14.794741,0.858899,-188.109940,294.500458,0.000000
86.560005,65.294388,-188.109940,-0.002307,0.003385,0.085976,290.443939,14.795919,0.859762,-188.109940,294.500458,0.000000
86.910004,65.219925,-188.154419,-0.002315,0.003386,0.085994,290.112701,14.779046,0.859943,-188.154419,294.500458,0.000000
87.260002,65.322327,-188.243378,-0.002298,0.003389,0.086072,290.568207,14.802251,0.860715,-188.243378,294.500458,0.000000
87.610001,65.163315,-188.243378,-0.002311,0.003389,0.086072,289.860901,14.766218,0.860715,-188.243378,294.500458,0.000000
87.960007,65.069855,-188.287872,-0.002302,0.003390,0.086115,289.445160,14.745040,0.861154,-188.287872,294.500458,0.000000
88.310005,64.950699,-188.376831,-0.002294,0.003391,0.086134,288.915131,14.718039,0.861336,-188.376831,294.500458,0.000000
88.660004,65.221786,-188.376831,-0.002320,0.003397,0.086271,290.121002,14.779469,0.862714,-188.376831,294.500458,0.000000
89.010002,65.090332,-188.421310,-0.002307,0.003397,0.086271,289.536255,14.749681,0.862714,-188.421310,294.500458,0.000000
89.360001,64.987930,-188.421310,-0.002302,0.003398,0.086315,289.080750,14.726475,0.863153,-188.421310,294.500458,0.000000
89.710007,64.991287,-188.465790,-0.002307,0.003400,0.086358,289.095673,14.727236,0.863577,-188.465790,294.500458,0.000000
90.060005,65.846252,-188.510269,-0.002307,0.003410,0.086611,292.898773,14.920974,0.866105,-188.510269,294.500458,0.000000
90.410004,65.664902,-188.510269,-0.002302,0.003410,0.086611,292.092072,14.879879,0.866105,-188.510269,294.500458,0.000000
90.760002,65.530106,-188.643707,-0.002294,0.003410,0.086611,291.492462,14.849334,0.866105,-188.643707,294.500458,0.000000
91.110001,65.345032,-188.643707,-0.002298,0.003410,0.086611,290.669220,14.807396,0.866105,-188.643707,294.500458,0.000000
91.460007,65.180069,-188.643707,-0.002285,0.003410,0.086611,289.935425,14.770015,0.866105,-188.643707,294.500458,0.000000
91.810005,65.017715,-188.688202,-0.002298,0.003410,0.086618,289.213257,14.733225,0.866181,-188.688202,294.500458,0.000000
92.160004,66.054779,-188.732681,-0.002289,0.003417,0.086801,293.826324,14.968226,0.868013,-188.732681,294.500458,0.000000
92.510002,65.880875,-188.821640,-0.002289,0.003417,0.086792,293.052765,14.928820,0.867922,-188.821640,294.500458,0.000000
92.860001,65.626175,-188.866119,-0.002294,0.003417,0.086792,291.919800,14.871104,0.867922,-188.866119,294.500458,0.000000
93.210007,65.403122,-188.866119,-0.002281,0.003417,0.086801,290.927612,14.820560,0.868013,-188.866119,294.500458,0.000000
93.560005,65.253433,-188.910599,-0.002285,0.003419,0.086836,290.261780,14.786639,0.868361,-188.910599,294.500458,0.000000
93.910004,65.378922,-188.955078,-0.002285,0.003425,0.087000,290.819977,14.815075,0.869996,-188.955078,294.500458,0.000000
94.260002,65.262375,-188.955078,-0.002281,0.003426,0.087009,290.301544,14.788666,0.870087,-188.955078,294.500458,0.000000
94.610008,65.396790,-188.999557,-0.002276,0.003431,0.087148,290.899445,14.819124,0.871480,-188.999557,294.500458,0.000000
94.960007,65.426208,-188.999557,-0.002276,0.003431,0.087139,291.030304,14.825791,0.871389,-188.999557,294.500458,0.000000
95.310005,65.296249,-189.044037,-0.002281,0.003431,0.087139,290.452209,14.796342,0.871389,-189.044037,294.500458,0.000000
95.660004,65.126083,-189.177490,-0.002281,0.003431,0.087148,289.695282,14.757781,0.871480,-189.177490,294.500458,0.000000
96.010002,65.659317,-189.133011,-0.002281,0.003438,0.087330,292.067230,14.878613,0.873296,-189.133011,294.500458,0.000000
96.360008,65.559891,-189.177490,-0.002289,0.003438,0.087330,291.624969,14.856084,0.873296,-189.177490,294.500458,0.000000
96.710007,65.397537,-189.266449,-0.002272,0.003438,0.087330,290.902771,14.819294,0.873296,-189.266449,294.500458,0.000000
97.060005,65.261993,-189.355408,-0.002272,0.003438,0.087330,290.299835,14.788579,0.873296,-189.355408,294.500458,0.000000
97.410004,65.575531,-189.355408,-0.002281,0.003448,0.087572,291.694519,14.859628,0.875719,-189.355408,294.500458,0.000000
97.760002,65.660431,-189.399887,-0.002276,0.003446,0.087529,292.072174,14.878866,0.875295,-189.399887,294.500458,0.000000
98.110008,65.532333,-189.444366,-0.002264,0.003446,0.087529,291.502380,14.849839,0.875295,-189.444366,294.500458,0.000000
98.460007,65.378174,-189.444366,-0.002272,0.003446,0.087529,290.816650,14.814906,0.875295,-189.444366,294.500458,0.000000
98.810005,65.234436,-189.488846,-0.002268,0.003446,0.087529,290.177277,14.782334,0.875295,-189.488846,294.500458,0.000000
99.160004,65.069473,-189.488846,-0.002272,0.003446,0.087529,289.443481,14.744953,0.875295,-189.488846,294.500458,0.000000
99.510002,64.955536,-189.488846,-0.002264,0.003446,0.087539,288.936646,14.719135,0.875386,-189.488846,294.500458,0.000000
99.860008,64.768982,-189.622299,-0.002268,0.003446,0.087539,288.106812,14.676862,0.875386,-189.622299,294.500458,0.000000
100.210007,64.631943,-189.711258,-0.002268,0.003446,0.087539,287.497253,14.645808,0.875386,-189.711258,294.500458,0.000000
100.560005,64.478531,-189.666779,-0.002268,0.003446,0.087539,286.814819,14.611044,0.875386,-189.666779,294.500458,0.000000
100.910004,66.676270,-189.711258,-0.002272,0.003430,0.087130,296.590851,15.109058,0.871298,-189.711258,294.500458,0.000000
101.260002,66.407043,-189.800217,-0.002264,0.003430,0.087130,295.393280,15.048052,0.871298,-189.800217,294.500458,0.000000
101.610008,66.303894,-189.844696,-0.002264,0.003430,0.087130,294.934448,15.024677,0.871298,-189.844696,294.500458,0.000000
101.960007,66.118088,-189.889175,-0.002264,0.003430,0.087130,294.107941,14.982573,0.871298,-189.889175,294.500458,0.000000
102.310005,65.937103,-189.889175,-0.002264,0.003430,0.087130,293.302887,14.941561,0.871298,-189.889175,294.500458,0.000000
102.660004,65.851837,-189.933655,-0.002255,0.003430,0.087130,292.923615,14.922239,0.871298,-189.933655,294.500458,0.000000
103.010002,65.652985,-189.978149,-0.002268,0.003430,0.087130,292.039062,14.877178,0.871298,-189.978149,294.500458,0.000000
103.360008,65.518188,-190.022629,-0.002259,0.003444,0.087476,291.439453,14.846633,0.874765,-190.022629,294.500458,0.000000
103.710007,65.393448,-190.067108,-0.002268,0.003452,0.087685,290.884583,14.818367,0.876854,-190.067108,294.500458,0.000000
104.060005,65.279495,-190.111588,-0.002251,0.003456,0.087790,290.377686,14.792545,0.877899,-190.111588,294.500458,0.000000
104.410004,65.176727,-190.111588,-0.002264,0.003462,0.087937,289.920563,14.769257,0.879367,-190.111588,294.500458,0.000000
104.760002,65.108582,-190.156067,-0.002251,0.003464,0.087997,289.617432,14.753816,0.879973,-190.156067,294.500458,0.000000
105.110008,65.184174,-190.156067,-0.002276,0.003474,0.088232,289.953674,14.770945,0.882320,-190.156067,294.500458,0.000000
105.460007,65.591553,-190.245026,-0.002264,0.003475,0.088267,291.765808,14.863258,0.882668,-190.245026,294.500458,0.000000
105.810005,65.520416,-190.245026,-0.002268,0.003475,0.088267,291.449371,14.847138,0.882668,-190.245026,294.500458,0.000000
106.160004,65.379288,-190.245026,-0.002255,0.003475,0.088267,290.821594,14.815159,0.882668,-190.245026,294.500458,0.000000
106.510002,65.261627,-190.378464,-0.002268,0.003476,0.088283,290.298218,14.788496,0.882834,-190.378464,294.500458,0.000000
106.860008,65.492493,-190.422958,-0.002255,0.003481,0.088423,291.325165,14.840812,0.884227,-190.422958,294.500458,0.000000
107.210007,65.452286,-190.422958,-0.002255,0.003481,0.088423,291.146301,14.831700,0.884227,-190.422958,294.500458,0.000000
107.560005,65.337219,-190.467438,-0.002242,0.003481,0.088423,290.634460,14.805625,0.884227,-190.467438,294.500458,0.000000
107.910004,65.348022,-190.467438,-0.002272,0.003484,0.088483,290.682526,14.808074,0.884833,-190.467438,294.500458,0.000000
108.260002,65.302963,-190.556396,-0.002251,0.003484,0.088500,290.482086,14.797863,0.884999,-190.556396,294.500458,0.000000
108.610008,65.315613,-190.467438,-0.002255,0.003485,0.088527,290.538361,14.800730,0.885272,-190.467438,294.500458,0.000000
108.960007,65.326416,-190.645355,-0.002251,0.003487,0.088560,290.586426,14.803178,0.885605,-190.645355,294.500458,0.000000
109.310005,65.293655,-190.600876,-0.002264,0.003489,0.088623,290.440674,14.795754,0.886226,-190.600876,294.500458,0.000000
109.660004,65.333115,-190.689835,-0.002251,0.003489,0.088630,290.616211,14.804696,0.886301,-190.689835,294.500458,0.000000
110.010002,65.288055,-190.689835,-0.002242,0.003491,0.088683,290.415771,14.794485,0.886831,-190.689835,294.500458,0.000000
110.360008,65.337967,-190.778793,-0.002255,0.003492,0.088691,290.637787,14.805795,0.886907,-190.778793,294.500458,0.000000
110.710007,65.388229,-190.778793,-0.002259,0.003495,0.088760,290.861359,14.817184,0.887603,-190.778793,294.500458,0.000000
111.060005,65.396790,-190.867767,-0.002259,0.003495,0.088760,290.899445,14.819124,0.887603,-190.867767,294.500458,0.000000
111.410004,65.363647,-190.867767,-0.002251,0.003496,0.088795,290.752014,14.811614,0.887951,-190.867767,294.500458,0.000000
111.760002,65.285828,-190.912247,-0.002255,0.003496,0.088804,290.405853,14.793981,0.888042,-190.912247,294.500458,0.000000
112.110008,65.474625,-190.956726,-0.002251,0.003500,0.088891,291.245667,14.836762,0.888905,-190.956726,294.500458,0.000000
112.460007,65.410568,-191.045685,-0.002246,0.003500,0.088891,290.960754,14.822247,0.888905,-191.045685,294.500458,0.000000
112.810005,65.342422,-191.001205,-0.002255,0.003500,0.088900,290.657623,14.806805,0.888996,-191.001205,294.500458,0.000000
113.160004,65.353973,-191.045685,-0.002238,0.003502,0.088942,290.708984,14.809422,0.889420,-191.045685,294.500458,0.000000
113.510002,65.338699,-191.090164,-0.002229,0.003503,0.088969,290.641052,14.805962,0.889693,-191.090164,294.500458,0.000000
113.860008,65.282104,-191.090164,-0.002242,0.003503,0.088969,290.389313,14.793136,0.889693,-191.090164,294.500458,0.000000
114.210007,65.199066,-191.134644,-0.002246,0.003503,0.088986,290.019928,14.774320,0.889859,-191.134644,294.500458,0.000000
114.560005,65.183792,-191.179123,-0.002246,0.003504,0.089004,289.951996,14.770859,0.890041,-191.179123,294.500458,0.000000
114.910004,65.588943,-191.268097,-0.002255,0.003511,0.089168,291.754181,14.862667,0.891676,-191.268097,294.500458,0.000000
115.260002,65.549103,-191.312576,-0.002238,0.003510,0.089160,291.576965,14.853639,0.891600,-191.312576,294.500458,0.000000
115.610008,65.483551,-191.357056,-0.002229,0.003510,0.089160,291.285370,14.838785,0.891600,-191.357056,1681.640747,0.000000
115.960007,65.349884,-191.446014,-0.002238,0.003501,0.088934,290.690796,14.808496,0.889344,-191.446014,0.089099,0.000000
116.310005,65.108582,-191.401535,-0.002238,0.003493,0.088735,289.617432,14.753816,0.887346,-191.401535,0.088518,0.000000
116.660004,64.973404,-191.401535,-0.002225,0.003483,0.088458,289.016144,14.723184,0.884575,-191.401535,0.087928,0.000000
117.010002,64.784622,-191.534973,-0.002225,0.003461,0.087902,288.176392,14.680406,0.879019,-191.534973,0.087348,0.000000
117.360008,64.676254,-191.446014,-0.002225,0.003451,0.087660,287.694336,14.655849,0.876597,-191.446014,0.086766,0.000000
117.710007,64.561569,-191.490494,-0.002251,0.003427,0.087034,287.184204,14.629861,0.870344,-191.490494,0.086185,0.000000
118.060005,64.440918,-191.579453,-0.002238,0.003397,0.086280,286.647522,14.602521,0.862805,-191.579453,0.085595,0.000000
118.410004,64.328079,-191.668411,-0.002233,0.003373,0.085673,286.145599,14.576951,0.856734,-191.668411,0.085015,0.000000
118.760002,64.159409,-191.712906,-0.002225,0.003352,0.085145,285.395294,14.538730,0.851450,-191.712906,0.084433,0.000000
119.110008,64.060349,-191.757385,-0.002229,0.003334,0.084676,284.954651,14.516283,0.846757,-191.757385,0.083843,0.000000
119.460007,63.942307,-191.712906,-0.002225,0.003305,0.083957,284.429596,14.489534,0.839565,-191.712906,0.083263,0.000000
119.810005,63.743088,-191.801865,-0.002229,0.003280,0.083324,283.543427,14.444389,0.833237,-191.801865,0.082682,0.000000
120.160004,63.333481,-191.801865,-0.002216,0.003260,0.082794,281.721405,14.351572,0.827938,-191.801865,0.082100,0.000000
120.510002,62.713104,-191.890823,-0.002220,0.003243,0.082377,278.961823,14.210993,0.823775,-191.890823,0.081510,0.000000
120.860008,61.625778,-191.846344,-0.002216,0.003217,0.081701,274.125153,13.964602,0.817007,-191.846344,0.080930,0.000000
121.210007,60.907104,-191.979782,-0.002207,0.003206,0.081424,270.928345,13.801747,0.814237,-191.979782,0.080349,0.000000
121.560005,59.178177,-191.979782,-0.002177,0.003175,0.080644,263.237671,13.409966,0.806440,-191.979782,0.079767,0.000000
121.910004,57.371056,-191.979782,-0.002190,0.003154,0.080105,255.199203,13.000467,0.801050,-191.979782,0.079178,0.000000
122.260002,55.920288,-192.024261,-0.002190,0.003134,0.079611,248.745865,12.671718,0.796115,-192.024261,0.078597,0.000000
122.610008,53.747871,-192.157715,-0.002186,0.003110,0.078995,239.082474,12.179442,0.789953,-192.157715,0.078016,0.000000
122.960007,51.702797,-192.157715,-0.002182,0.003093,0.078571,229.985535,11.716021,0.785714,-192.157715,0.077425,0.000000
123.310005,49.776512,-192.157715,-0.002186,0.003073,0.078042,221.416977,11.279519,0.780415,-192.157715,0.076845,0.000000
123.660004,45.931770,-192.202194,-0.002182,0.003037,0.077132,204.314713,10.408288,0.771316,-192.202194,0.076264,0.000000
124.010002,43.754135,-192.202194,-0.002190,0.003018,0.076662,194.628113,9.914828,0.766623,-192.202194,0.075683,0.000000
124.360008,41.176575,-192.291153,-0.002177,0.002992,0.076004,183.162552,9.330745,0.760037,-192.291153,0.075094,0.000000
124.710007,39.048462,-192.291153,-0.002182,0.002974,0.075543,173.696228,8.848508,0.755435,-192.291153,0.074512,0.000000
125.060005,37.170219,-192.380112,-0.002186,0.002957,0.075110,165.341400,8.422892,0.751105,-192.380112,0.073931,0.000000
125.410004,34.089951,-192.424591,-0.002199,0.002928,0.074364,151.639679,7.724894,0.743641,-192.424591,0.073350,0.000000
125.760010,31.920883,-192.469070,-0.002190,0.002907,0.073845,141.991180,7.233376,0.738448,-192.469070,0.072761,0.000000
126.110008,29.948051,-192.513550,-0.002195,0.002887,0.073324,133.215591,6.786325,0.733240,-192.513550,0.072179,0.000000
126.460007,26.932953,-192.513550,-0.002199,0.002857,0.072570,119.803757,6.103095,0.725701,-192.513550,0.071598,0.000000
126.810005,24.948212,-192.602524,-0.002195,0.002839,0.072110,110.975189,5.653346,0.721098,-192.602524,0.071017,0.000000
127.160004,23.689217,-192.558044,-0.002182,0.002820,0.071624,105.374901,5.368053,0.716238,-192.558044,0.070428,0.000000
127.510010,20.197113,-192.647003,-0.002182,0.002792,0.070905,89.841248,4.576731,0.709047,-192.647003,0.069846,0.000000
127.860008,17.602043,-192.602524,-0.002199,0.002767,0.070279,78.297798,3.988680,0.702794,-192.602524,0.069265,0.000000
128.210007,16.271935,-192.691483,-0.002195,0.002751,0.069881,72.381180,3.687273,0.698813,-192.691483,0.068676,0.000000
128.560013,13.268005,-192.647003,-0.002186,0.002721,0.069118,59.019035,3.006573,0.691182,-192.647003,0.068095,0.000000
128.910004,11.510033,-192.735962,-0.002186,0.002707,0.068762,51.199181,2.608211,0.687625,-192.735962,0.067513,0.000000
129.260010,8.365349,-192.824921,-0.002190,0.002675,0.067939,37.210930,1.895615,0.679389,-192.824921,0.066932,0.000000
129.610001,6.038765,-192.869400,-0.002199,0.002650,0.067314,26.861769,1.368404,0.673136,-192.869400,0.066343,0.000000
129.960007,4.232384,-192.869400,-0.002190,0.002631,0.066837,18.826584,0.959072,0.668367,-192.869400,0.065762,0.000000
130.310013,1.787018,-192.958359,-0.002190,0.002606,0.066195,7.949052,0.404944,0.661948,-192.958359,0.065180,0.000000
130.660004,0.253586,-192.913879,-0.002195,0.002587,0.065701,1.128006,0.057463,0.657012,-192.913879,0.064599,0.000000
131.010010,-1.820530,-192.958359,-0.002190,0.002564,0.065138,-8.098122,-0.412538,0.651380,-192.958359,0.064010,0.000000
131.360001,-4.117695,-193.047333,-0.002195,0.002535,0.064401,-18.316422,-0.933083,0.644007,-193.047333,0.063429,0.000000
131.710007,-0.119530,-193.047333,-0.002199,0.002516,0.063897,-0.531695,-0.027086,0.638966,-193.047333,0.062847,0.000000
132.060013,0.011169,-193.180771,-0.002190,0.002489,0.063212,0.049684,0.002531,0.632123,-193.180771,0.062258,0.000000
132.410004,0.057716,-193.136292,-0.002173,0.002475,0.062875,0.256735,0.013079,0.628747,-193.136292,0.061677,0.000000
132.760010,0.023460,-193.180771,-0.002173,0.002449,0.062215,0.104357,0.005316,0.622146,-193.180771,0.061096,0.000000
133.110001,0.014893,-193.136292,-0.002182,0.002419,0.061442,0.066245,0.003375,0.614425,-193.136292,0.060514,0.000000
133.460007,0.011543,-193.225250,-0.002164,0.002403,0.061044,0.051347,0.002616,0.610443,-193.225250,0.059925,0.000000
133.810013,-0.013031,-193.269730,-0.002173,0.002380,0.060454,-0.057965,-0.002953,0.604539,-193.269730,0.059344,0.000000
134.160004,-0.031281,-193.269730,-0.002160,0.002350,0.059691,-0.139143,-0.007088,0.596908,-193.269730,0.058763,0.000000
134.510010,-0.022713,-193.314209,-0.002160,0.002334,0.059284,-0.101031,-0.005147,0.592836,-193.314209,0.058183,0.000000
134.860001,-0.043198,-193.358688,-0.002156,0.002322,0.058981,-0.192153,-0.009789,0.589808,-193.358688,0.057592,0.000000
135.210007,-0.021973,-193.403168,-0.002182,0.002301,0.058451,-0.097739,-0.004979,0.584509,-193.403168,0.057011,0.000000
135.560013,-0.102402,-193.447662,-0.002169,0.002262,0.057462,-0.455506,-0.023205,0.574623,-193.447662,0.056430,0.000000
135.910004,-0.108360,-193.447662,-0.002164,0.002238,0.056846,-0.482011,-0.024555,0.568461,-193.447662,0.055850,0.000000
136.260010,-0.097931,-193.492142,-0.002160,0.002221,0.056413,-0.435618,-0.022191,0.564131,-193.492142,0.055259,0.000000
136.610001,-0.094208,-193.536621,-0.002169,0.002196,0.055789,-0.419057,-0.021348,0.557894,-193.536621,0.054678,0.000000
136.960007,-0.098305,-193.536621,-0.002173,0.002173,0.055190,-0.437281,-0.022276,0.551898,-193.536621,0.054098,0.000000
137.310013,-0.132195,-193.581100,-0.002173,0.002149,0.054575,-0.588031,-0.029956,0.545752,-193.581100,0.053508,0.000000
137.660004,-0.116554,-193.670059,-0.002164,0.002128,0.054045,-0.518459,-0.026412,0.540453,-193.670059,0.052926,0.000000
138.010010,-0.112831,-193.670059,-0.002156,0.002098,0.053291,-0.501898,-0.025568,0.532913,-193.670059,0.052345,0.000000
138.360001,-0.137779,-193.670059,-0.002151,0.002081,0.052857,-0.612873,-0.031221,0.528568,-193.670059,0.051765,0.000000
138.710007,-0.133308,-193.759018,-0.002169,0.002061,0.052345,-0.592985,-0.030208,0.523451,-193.759018,0.051175,0.000000
139.060013,-0.139267,-193.759018,-0.002160,0.002039,0.051800,-0.619490,-0.031558,0.518001,-193.759018,0.050593,0.000000
139.410004,-0.181717,-193.803497,-0.002156,0.002010,0.051063,-0.808317,-0.041178,0.510628,-193.803497,0.050014,0.000000
139.760010,-0.159004,-193.892471,-0.002173,0.001988,0.050498,-0.707286,-0.036031,0.504981,-193.892471,0.049432,0.000000
140.110001,-0.153046,-193.936951,-0.002177,0.001963,0.049849,-0.680781,-0.034681,0.498486,-193.936951,0.048842,0.000000
140.460007,-0.146339,-193.936951,-0.002186,0.001954,0.049640,-0.650950,-0.033161,0.496397,-193.936951,0.048260,0.000000
140.810013,-0.169434,-193.981430,-0.002186,0.001920,0.048765,-0.753678,-0.038394,0.487646,-193.981430,0.047681,0.000000
141.160004,-0.166451,-194.025909,-0.002182,0.001891,0.048027,-0.740409,-0.037718,0.480273,-194.025909,0.047090,0.000000
141.510010,-0.194382,-194.025909,-0.002199,0.001871,0.047532,-0.864653,-0.044048,0.475322,-194.025909,0.046509,0.000000
141.860001,-0.152298,-194.114868,-0.002199,0.001843,0.046822,-0.677455,-0.034511,0.468222,-194.114868,0.045929,0.000000
142.210007,-0.194382,-194.070389,-0.002212,0.001827,0.046406,-0.864653,-0.044048,0.464058,-194.070389,0.045348,0.000000
142.560013,-0.167938,-194.159348,-0.002233,0.001809,0.045946,-0.747027,-0.038055,0.459456,-194.159348,0.044757,0.000000
142.910004,-0.184326,-194.159348,-0.002276,0.001781,0.045234,-0.819924,-0.041769,0.452340,-194.159348,0.044177,0.000000
143.260010,-0.156021,-194.292801,-0.002298,0.001756,0.044592,-0.694017,-0.035355,0.445921,-194.292801,0.043596,0.000000
143.500000,-0.116180,-194.337280,-0.002302,0.001750,0.044454,-0.516796,-0.026327,0.444543,-194.337280,0.044298,0.000000