File: Data/compression 31/ManualNoHeating-12-31-reverse-1-3_11132024_180554.csv
Time (sec),S:Load (lbs),S:HL1 (DIM),S:LVDT (in),S:Position (in),Ch:Position (mm),Ch:Load (N),Ch:Stress (MPa),Ch:Strain (mm/mm),Ch:HL1 (DIM),Set Point (),Cycles ()
0.110000,-0.071869,-294.108063,-0.009580,-0.004524,-0.114915,-0.319689,-0.016286,-1.149155,-294.108063,-0.114716,0.000000
0.530000,-0.065910,-294.152527,-0.009585,-0.004441,-0.112799,-0.293184,-0.014935,-1.127990,-294.152527,-0.112287,0.000000
0.950000,-0.080437,-294.197021,-0.009382,-0.004182,-0.106225,-0.357800,-0.018227,-1.062253,-294.197021,-0.105297,0.000000
1.370000,-0.129959,-294.285980,-0.009102,-0.003907,-0.099244,-0.578087,-0.029449,-0.992445,-294.285980,-0.098291,0.000000
1.790000,-0.135544,-294.285980,-0.008821,-0.003638,-0.092410,-0.602929,-0.030715,-0.924105,-294.285980,-0.091301,0.000000
2.210000,-0.080063,-294.241486,-0.008545,-0.003362,-0.085386,-0.356137,-0.018143,-0.853857,-294.241486,-0.084311,0.000000
2.630000,-0.073730,-294.330444,-0.008274,-0.003084,-0.078328,-0.327969,-0.016708,-0.783276,-294.330444,-0.077304,0.000000
3.050000,-0.076340,-294.374939,-0.007985,-0.002813,-0.071442,-0.339576,-0.017299,-0.714422,-294.374939,-0.070314,0.000000
3.470000,-0.102402,-294.419403,-0.007692,-0.002531,-0.064278,-0.455506,-0.023205,-0.642781,-294.419403,-0.063306,0.000000
3.890000,-0.103149,-294.374939,-0.007407,-0.002256,-0.057297,-0.458832,-0.023374,-0.572973,-294.374939,-0.056318,0.000000
4.310000,-0.071869,-294.419403,-0.007136,-0.001986,-0.050438,-0.319689,-0.016286,-0.504375,-294.419403,-0.049310,0.000000
4.730000,-0.064049,-294.463898,-0.006847,-0.001710,-0.043422,-0.284903,-0.014514,-0.434218,-294.463898,-0.042320,0.000000
5.150000,-0.077080,-294.508362,-0.006532,-0.001431,-0.036337,-0.342868,-0.017467,-0.363365,-294.508362,-0.035330,0.000000
5.570000,-0.078941,-294.508362,-0.006265,-0.001158,-0.029407,-0.351149,-0.017888,-0.294071,-294.508362,-0.028323,0.000000
5.990000,-0.086761,-294.552856,-0.005980,-0.000880,-0.022357,-0.385934,-0.019660,-0.223566,-294.552856,-0.021333,0.000000
6.410000,-0.045799,-294.552856,-0.005704,-0.000608,-0.015453,-0.203725,-0.010378,-0.154530,-294.552856,-0.014327,0.000000
6.830000,-0.061073,-294.597351,-0.005411,-0.000333,-0.008446,-0.271668,-0.013839,-0.084464,-294.597351,-0.007337,0.000000
7.250000,0.122139,-294.686310,-0.005178,-0.000000,-0.000000,0.543301,0.027677,-0.000000,-294.686310,0.000148,0.000000
7.670001,0.087875,-294.686310,-0.005182,-0.000000,-0.000008,0.390889,0.019913,-0.000076,-294.686310,0.000148,0.000000
8.090000,0.096817,-294.686310,-0.005174,-0.000000,-0.000008,0.430664,0.021939,-0.000076,-294.686310,0.000798,0.000000
8.510000,0.228264,-294.730774,-0.005174,0.000028,0.000721,1.015368,0.051725,0.007206,-294.730774,0.001500,0.000000
8.930000,0.323967,-294.819733,-0.005152,0.000053,0.001335,1.441077,0.073412,0.013353,-294.819733,0.002203,0.000000
9.350000,0.575684,-294.819733,-0.005109,0.000082,0.002091,2.560769,0.130452,0.020908,-294.819733,0.002905,0.000000
9.770000,0.819962,-294.819733,-0.005079,0.000108,0.002740,3.647371,0.185806,0.027403,-294.819733,0.003599,0.000000
10.190001,1.076157,-294.864227,-0.005057,0.000136,0.003461,4.786983,0.243861,0.034609,-294.864227,0.004301,0.000000
10.610001,1.354317,-294.819733,-0.005027,0.000166,0.004206,6.024302,0.306893,0.042058,-294.819733,0.005004,0.000000
11.030001,1.650352,-294.908691,-0.005006,0.000192,0.004866,7.341135,0.373975,0.048659,-294.908691,0.005699,0.000000
11.450001,1.983627,-294.908691,-0.004993,0.000220,0.005585,8.823615,0.449496,0.055850,-294.908691,0.006401,0.000000
11.870001,2.214874,-294.953186,-0.004967,0.000240,0.006097,9.852253,0.501898,0.060967,-294.953186,0.007103,0.000000
12.290001,2.664322,-294.953186,-0.004937,0.000277,0.007043,11.851496,0.603744,0.070429,-294.953186,0.007806,0.000000
12.710001,2.809174,-294.997681,-0.004911,0.000299,0.007597,12.495829,0.636568,0.075970,-294.997681,0.008499,0.000000
13.130001,3.150642,-294.997681,-0.004885,0.000325,0.008248,14.014757,0.713946,0.082480,-294.997681,0.009202,0.000000
13.550000,3.509613,-295.086639,-0.004863,0.000351,0.008925,15.611539,0.795290,0.089248,-295.086639,0.009904,0.000000
13.970000,3.995926,-295.086639,-0.004829,0.000384,0.009765,17.774767,0.905490,0.097650,-295.086639,0.010598,0.000000
14.390000,4.280792,-295.042145,-0.004790,0.000414,0.010520,19.041914,0.970041,0.105205,-295.042145,0.011300,0.000000
14.810000,4.506821,-295.175598,-0.004777,0.000440,0.011170,20.047340,1.021260,0.111700,-295.175598,0.012003,0.000000
15.230000,4.922020,-295.175598,-0.004756,0.000467,0.011856,21.894238,1.115346,0.118558,-295.175598,0.012705,0.000000
15.650001,5.111931,-295.264557,-0.004721,0.000492,0.012505,22.739004,1.158380,0.125053,-295.264557,0.013399,0.000000
16.070002,5.689476,-295.175598,-0.004695,0.000524,0.013321,25.308054,1.289254,0.133213,-295.175598,0.014101,0.000000
16.490002,5.786293,-295.220062,-0.004674,0.000548,0.013928,25.738716,1.311193,0.139284,-295.220062,0.014803,0.000000
16.910002,5.903961,-295.309021,-0.004669,0.000570,0.014483,26.262131,1.337857,0.144825,-295.309021,0.015506,0.000000
17.330000,6.481888,-295.353516,-0.004631,0.000601,0.015273,28.832876,1.468817,0.152728,-295.353516,0.016201,0.000000
17.750000,6.720947,-295.309021,-0.004618,0.000627,0.015922,29.896267,1.522988,0.159223,-295.309021,0.016903,0.000000
18.170000,7.196098,-295.309021,-0.004557,0.000662,0.016816,32.009846,1.630659,0.168155,-295.309021,0.017604,0.000000
18.590000,7.228493,-295.353516,-0.004557,0.000685,0.017388,32.153942,1.638000,0.173878,-295.353516,0.018299,0.000000
19.010000,7.732315,-295.442474,-0.004540,0.000716,0.018195,34.395054,1.752168,0.181947,-295.442474,0.019002,0.000000
19.430000,7.848495,-295.486969,-0.004497,0.000737,0.018723,34.911850,1.778494,0.187231,-295.486969,0.019704,0.000000
19.850000,8.237625,-295.531433,-0.004484,0.000765,0.019426,36.642788,1.866673,0.194256,-295.531433,0.020407,0.000000
20.270000,8.557121,-295.531433,-0.004462,0.000794,0.020172,38.063976,1.939071,0.201720,-295.531433,0.021100,0.000000
20.690001,8.674042,-295.531433,-0.004419,0.000819,0.020805,38.584064,1.965566,0.208048,-295.531433,0.021803,0.000000
21.110001,9.147697,-295.575928,-0.004411,0.000851,0.021621,40.690990,2.072898,0.216208,-295.575928,0.022505,0.000000
21.530001,9.305962,-295.620392,-0.004376,0.000876,0.022254,41.394985,2.108761,0.222537,-295.620392,0.023198,0.000000
21.950001,9.516724,-295.664886,-0.004346,0.000903,0.022947,42.332500,2.156520,0.229471,-295.664886,0.023901,0.000000
22.370001,9.923355,-295.620392,-0.004320,0.000932,0.023684,44.141289,2.248664,0.236844,-295.620392,0.024603,0.000000
22.790001,10.191833,-295.664886,-0.004303,0.000960,0.024387,45.335541,2.309503,0.243868,-295.664886,0.025306,0.000000
23.210001,10.433502,-295.709351,-0.004281,0.000989,0.025124,46.410534,2.364265,0.251241,-295.709351,0.025999,0.000000
23.630001,10.315460,-295.798309,-0.004260,0.001010,0.025653,45.885460,2.337517,0.256525,-295.798309,0.026702,0.000000
24.050001,10.991692,-295.798309,-0.004221,0.001047,0.026590,48.893486,2.490753,0.265896,-295.798309,0.027404,0.000000
24.470001,11.073608,-295.709351,-0.004182,0.001072,0.027241,49.257870,2.509315,0.272406,-295.709351,0.028107,0.000000
24.890001,11.453056,-295.842804,-0.004195,0.001101,0.027976,50.945740,2.595300,0.279764,-295.842804,0.028802,0.000000
25.310001,11.622864,-295.842804,-0.004165,0.001127,0.028637,51.701080,2.633779,0.286365,-295.842804,0.029504,0.000000
25.730001,11.714088,-295.931763,-0.004130,0.001150,0.029200,52.106869,2.654450,0.291997,-295.931763,0.030206,0.000000
26.150002,12.079765,-295.887299,-0.004100,0.001182,0.030032,53.733479,2.737314,0.300324,-295.887299,0.030900,0.000000
26.570002,12.054070,-295.887299,-0.004100,0.001204,0.030588,53.619179,2.731491,0.305880,-295.887299,0.031602,0.000000
26.990002,12.550438,-295.931763,-0.004074,0.001236,0.031393,55.827137,2.843970,0.313934,-295.931763,0.032305,0.000000
27.410002,12.748543,-296.065216,-0.004044,0.001263,0.032088,56.708351,2.888861,0.320883,-296.065216,0.033007,0.000000
27.830002,12.923187,-296.065216,-0.004014,0.001290,0.032756,57.485207,2.928436,0.327560,-296.065216,0.033701,0.000000
28.250002,13.148102,-296.065216,-0.003988,0.001317,0.033440,58.485680,2.979402,0.334403,-296.065216,0.034403,0.000000
28.670002,13.508926,-296.065216,-0.003975,0.001348,0.034238,60.090706,3.061167,0.342382,-296.065216,0.035106,0.000000
29.090002,13.482491,-296.065216,-0.003949,0.001370,0.034794,59.973114,3.055176,0.347938,-296.065216,0.035808,0.000000
29.510002,13.968811,-296.198639,-0.003928,0.001401,0.035583,62.136375,3.165378,0.355826,-296.198639,0.036502,0.000000
29.930002,14.269310,-296.198639,-0.003880,0.001434,0.036424,63.473061,3.233472,0.364243,-296.198639,0.037204,0.000000
30.350002,14.389214,-296.198639,-0.003872,0.001458,0.037022,64.006416,3.260642,0.370223,-296.198639,0.037906,0.000000
30.770002,14.710945,-296.243134,-0.003850,0.001488,0.037785,65.437553,3.333548,0.377854,-296.243134,0.038600,0.000000
31.190001,14.712433,-296.287628,-0.003837,0.001509,0.038332,65.444168,3.333885,0.383319,-296.287628,0.039302,0.000000
31.610001,15.015175,-296.332092,-0.003811,0.001538,0.039060,66.790833,3.402487,0.390601,-296.332092,0.040005,0.000000
32.030003,15.162262,-296.332092,-0.003781,0.001566,0.039779,67.445107,3.435817,0.397792,-296.332092,0.040707,0.000000
32.450001,15.253120,-296.332092,-0.003751,0.001592,0.040439,67.849266,3.456407,0.404393,-296.332092,0.041402,0.000000
32.870003,15.599052,-296.332092,-0.003747,0.001621,0.041177,69.388054,3.534796,0.411766,-296.332092,0.042105,0.000000
33.290001,15.720444,-296.421051,-0.003721,0.001646,0.041809,69.928024,3.562304,0.418095,-296.421051,0.042807,0.000000
33.710003,16.346031,-296.465546,-0.003704,0.001681,0.042703,72.710777,3.704064,0.427027,-296.465546,0.043501,0.000000
34.130001,16.195595,-296.421051,-0.003678,0.001707,0.043361,72.041603,3.669974,0.433613,-296.421051,0.044203,0.000000
34.550003,16.474876,-296.465546,-0.003652,0.001733,0.044012,73.283913,3.733260,0.440123,-296.465546,0.044906,0.000000
34.970001,16.242516,-296.510010,-0.003630,0.001751,0.044480,72.250320,3.680607,0.444801,-296.510010,0.045608,0.000000
35.390003,16.963425,-296.598969,-0.003617,0.001787,0.045399,75.457085,3.843967,0.453991,-296.598969,0.046301,0.000000
35.810001,17.266167,-296.598969,-0.003596,0.001818,0.046180,76.803749,3.912569,0.461803,-296.598969,0.047004,0.000000
36.230003,17.243454,-296.687958,-0.003570,0.001843,0.046813,76.702713,3.907423,0.468131,-296.687958,0.047706,0.000000
36.650002,17.388680,-296.598969,-0.003566,0.001869,0.047464,77.348709,3.940331,0.474641,-296.598969,0.048409,0.000000
37.070004,17.534645,-296.643463,-0.003535,0.001893,0.048071,77.997993,3.973407,0.480712,-296.643463,0.049102,0.000000
37.490002,18.327431,-296.732422,-0.003501,0.001930,0.049025,81.524483,4.153055,0.490250,-296.732422,0.049805,0.000000
37.910004,18.017616,-296.687958,-0.003510,0.001954,0.049632,80.146362,4.082850,0.496321,-296.687958,0.050507,0.000000
38.330002,18.106613,-296.732422,-0.003475,0.001978,0.050239,80.542236,4.103017,0.502392,-296.732422,0.051202,0.000000
38.750000,18.222046,-296.821381,-0.003436,0.002005,0.050933,81.055710,4.129175,0.509326,-296.821381,0.051905,0.000000
39.170002,18.259285,-296.821381,-0.003441,0.002028,0.051514,81.221359,4.137613,0.515139,-296.821381,0.052607,0.000000
39.590000,19.053551,-296.865875,-0.003406,0.002067,0.052510,84.754425,4.317596,0.525101,-296.865875,0.053308,0.000000
40.010002,19.063606,-296.865875,-0.003393,0.002093,0.053152,84.799156,4.319875,0.531520,-296.865875,0.054003,0.000000
40.430000,19.332085,-296.865875,-0.003359,0.002121,0.053873,85.993408,4.380713,0.538727,-296.865875,0.054705,0.000000
40.850002,19.272507,-296.865875,-0.003359,0.002145,0.054471,85.728394,4.367213,0.544707,-296.865875,0.055408,0.000000
41.270000,19.549553,-296.954834,-0.003341,0.002174,0.055208,86.960754,4.429992,0.552080,-296.954834,0.056101,0.000000
41.690002,19.773720,-296.954834,-0.003333,0.002202,0.055936,87.957901,4.480789,0.559362,-296.954834,0.056804,0.000000
42.110001,19.519394,-297.043793,-0.003307,0.002224,0.056492,86.826599,4.423158,0.564918,-297.043793,0.057506,0.000000
42.530003,19.896980,-296.999298,-0.003281,0.002253,0.057237,88.506187,4.508720,0.572367,-296.999298,0.058209,0.000000
42.950001,19.985229,-297.043793,-0.003251,0.002280,0.057913,88.898743,4.528718,0.579134,-297.043793,0.058902,0.000000
43.370003,20.076462,-297.043793,-0.003247,0.002308,0.058616,89.304565,4.549391,0.586159,-297.043793,0.059605,0.000000
43.790001,20.432823,-297.177246,-0.003225,0.002338,0.059397,90.889740,4.630144,0.593971,-297.177246,0.060307,0.000000
44.210003,20.586609,-297.177246,-0.003208,0.002365,0.060072,91.573807,4.664992,0.600723,-297.177246,0.061009,0.000000
44.630001,20.859932,-297.177246,-0.003203,0.002396,0.060870,92.789612,4.726928,0.608702,-297.177246,0.061703,0.000000
45.050003,20.976860,-297.132751,-0.003182,0.002423,0.061556,93.309731,4.753425,0.615560,-297.132751,0.062405,0.000000
45.470001,20.734070,-297.266205,-0.003169,0.002447,0.062163,92.229752,4.698408,0.621631,-297.266205,0.063108,0.000000
45.890003,20.589592,-297.221710,-0.003143,0.002473,0.062814,91.587082,4.665668,0.628141,-297.221710,0.063803,0.000000
46.310001,21.001808,-297.310669,-0.003122,0.002505,0.063638,93.420708,4.759078,0.636377,-297.310669,0.064505,0.000000
46.730003,20.571716,-297.266205,-0.003117,0.002526,0.064157,91.507561,4.661618,0.641570,-297.266205,0.065208,0.000000
47.150002,21.199539,-297.355164,-0.003109,0.002561,0.065059,94.300262,4.803884,0.650593,-297.355164,0.065910,0.000000
47.570004,20.933662,-297.355164,-0.003109,0.002587,0.065701,93.117584,4.743636,0.657012,-297.355164,0.066604,0.000000
47.990002,21.038673,-297.444122,-0.003078,0.002616,0.066439,93.584694,4.767432,0.664385,-297.444122,0.067306,0.000000
48.410004,20.696831,-297.444122,-0.003065,0.002639,0.067029,92.064102,4.689969,0.670290,-297.444122,0.068009,0.000000
48.830002,20.632042,-297.399628,-0.003061,0.002666,0.067722,91.775909,4.675288,0.677224,-297.399628,0.068702,0.000000
49.250004,21.374550,-297.444122,-0.003053,0.002700,0.068590,95.078743,4.843543,0.685899,-297.444122,0.069404,0.000000
49.670002,20.849136,-297.577576,-0.003044,0.002722,0.069127,92.741592,4.724482,0.691273,-297.577576,0.070107,0.000000
50.090004,20.930313,-297.577576,-0.003040,0.002752,0.069890,93.102684,4.742877,0.698904,-297.577576,0.070809,0.000000
50.510002,20.223175,-297.533081,-0.003022,0.002770,0.070349,89.957176,4.582637,0.703491,-297.533081,0.071503,0.000000
50.930004,21.162300,-297.577576,-0.003022,0.002808,0.071312,94.134613,4.795446,0.713120,-297.577576,0.072205,0.000000
51.350002,21.049095,-297.577576,-0.003014,0.002835,0.072014,93.631050,4.769793,0.720144,-297.577576,0.072908,0.000000
51.770004,20.745613,-297.710999,-0.003009,0.002861,0.072682,92.281097,4.701023,0.726821,-297.710999,0.073610,0.000000
52.190002,20.881905,-297.666534,-0.002988,0.002890,0.073394,92.887352,4.731907,0.733937,-297.666534,0.074304,0.000000
52.610001,20.325203,-297.710999,-0.002979,0.002909,0.073880,90.411018,4.605757,0.738796,-297.710999,0.075006,0.000000
53.030003,21.471367,-297.755493,-0.002971,0.002951,0.074945,95.509407,4.865481,0.749455,-297.755493,0.075708,0.000000
53.450001,20.734444,-297.755493,-0.002953,0.002971,0.075466,92.231415,4.698492,0.754663,-297.755493,0.076403,0.000000
53.870003,20.846527,-297.844452,-0.002958,0.003002,0.076238,92.729980,4.723891,0.762384,-297.844452,0.077106,0.000000
54.290001,20.422020,-297.888916,-0.002936,0.003022,0.076759,90.841682,4.627696,0.767592,-297.888916,0.077808,0.000000
54.710003,20.788811,-297.844452,-0.002953,0.003053,0.077548,92.473251,4.710812,0.775480,-297.844452,0.078511,0.000000
55.130001,21.393173,-297.888916,-0.002919,0.003089,0.078458,95.161591,4.847763,0.784578,-297.888916,0.079204,0.000000
55.550003,20.868126,-297.933411,-0.002923,0.003110,0.078995,92.826057,4.728785,0.789953,-297.933411,0.079907,0.000000
55.970001,21.190598,-297.977905,-0.002928,0.003140,0.079751,94.260483,4.801858,0.797508,-297.977905,0.080609,0.000000
56.390003,21.137352,-297.977905,-0.002910,0.003163,0.080349,94.023636,4.789793,0.803488,-297.977905,0.081303,0.000000
56.810001,21.749161,-297.977905,-0.002906,0.003198,0.081225,96.745102,4.928431,0.812254,-297.977905,0.082005,0.000000
57.230003,21.381256,-298.022369,-0.002876,0.003222,0.081832,95.108574,4.845062,0.818325,-298.022369,0.082708,0.000000
57.650002,21.406944,-298.066864,-0.002871,0.003247,0.082482,95.222847,4.850883,0.824819,-298.066864,0.083410,0.000000
58.070004,21.309013,-298.111328,-0.002871,0.003273,0.083142,94.787224,4.828691,0.831420,-298.111328,0.084103,0.000000
58.490002,21.290764,-298.111328,-0.002850,0.003298,0.083757,94.706047,4.824556,0.837567,-298.111328,0.084806,0.000000
58.910004,22.076103,-298.066864,-0.002837,0.003333,0.084668,98.199409,5.002517,0.846681,-298.066864,0.085508,0.000000
59.330002,21.751022,-298.244781,-0.002824,0.003361,0.085361,96.753380,4.928852,0.853615,-298.244781,0.086211,0.000000
59.750004,21.704842,-298.200287,-0.002820,0.003383,0.085917,96.547958,4.918387,0.859171,-298.200287,0.086906,0.000000
60.170002,22.209412,-298.244781,-0.002798,0.003412,0.086671,98.792397,5.032724,0.866711,-298.244781,0.087608,0.000000
60.590004,22.706154,-298.244781,-0.002794,0.003444,0.087469,101.002014,5.145288,0.874689,-298.244781,0.088311,0.000000
61.010002,22.675995,-298.244781,-0.002772,0.003472,0.088188,100.867867,5.138454,0.881881,-298.244781,0.089004,0.000000
61.430004,22.365807,-298.378235,-0.002764,0.003493,0.088718,99.488075,5.068164,0.887179,-298.378235,0.089707,0.000000
61.850002,22.973892,-298.378235,-0.002764,0.003525,0.089532,102.192978,5.205958,0.895324,-298.378235,0.090409,0.000000
62.270004,22.900536,-298.378235,-0.002734,0.003546,0.090062,101.866669,5.189335,0.900623,-298.378235,0.091112,0.000000
62.690002,23.581230,-298.378235,-0.002721,0.003577,0.090851,104.894554,5.343583,0.908511,-298.378235,0.091805,0.000000
63.110004,23.832954,-298.422699,-0.002721,0.003605,0.091563,106.014275,5.400625,0.915627,-298.422699,0.092507,0.000000
63.530003,24.325233,-298.511658,-0.002725,0.003634,0.092298,108.204041,5.512177,0.922984,-298.511658,0.093210,0.000000
63.950005,24.256714,-298.467194,-0.002716,0.003658,0.092924,107.899254,5.496650,0.929237,-298.467194,0.093903,0.000000
64.370003,24.998108,-298.556152,-0.002686,0.003689,0.093703,111.197136,5.664652,0.937034,-298.556152,0.094606,0.000000
64.790001,25.075562,-298.556152,-0.002695,0.003715,0.094363,111.541672,5.682203,0.943635,-298.556152,0.095308,0.000000
65.210007,25.378296,-298.511658,-0.002686,0.003743,0.095083,112.888298,5.750804,0.950826,-298.511658,0.096011,0.000000
65.630005,25.657951,-298.645111,-0.002673,0.003769,0.095725,114.132271,5.814175,0.957245,-298.645111,0.096704,0.000000
66.050003,26.232521,-298.689575,-0.002669,0.003797,0.096445,116.688080,5.944374,0.964452,-298.689575,0.097407,0.000000
66.470001,26.915825,-298.734070,-0.002643,0.003829,0.097251,119.727570,6.099213,0.972506,-298.734070,0.098109,0.000000
66.889999,26.948219,-298.689575,-0.002630,0.003854,0.097893,119.871666,6.106554,0.978925,-298.689575,0.098811,0.000000
67.310005,27.366768,-298.689575,-0.002630,0.003883,0.098630,121.733467,6.201398,0.986298,-298.689575,0.099506,0.000000
67.730003,27.863510,-298.778534,-0.002596,0.003910,0.099323,123.943085,6.313962,0.993232,-298.778534,0.100209,0.000000
68.150002,28.029961,-298.823029,-0.002578,0.003935,0.099939,124.683495,6.351680,0.999394,-298.823029,0.100911,0.000000
68.570000,29.089737,-298.823029,-0.002570,0.003965,0.100702,129.397614,6.591828,1.007024,-298.823029,0.101605,0.000000
68.990005,29.493019,-298.823029,-0.002587,0.003994,0.101440,131.191498,6.683214,1.014397,-298.823029,0.102307,0.000000
69.410004,30.265312,-298.823029,-0.002557,0.004022,0.102168,134.626831,6.858218,1.021679,-298.823029,0.103010,0.000000
69.830002,31.100922,-298.956482,-0.002557,0.004049,0.102854,138.343811,7.047570,1.028538,-298.956482,0.103712,0.000000
70.250000,31.787201,-299.000946,-0.002522,0.004074,0.103478,141.396530,7.203083,1.034775,-299.000946,0.104406,0.000000
70.670006,32.702492,-298.911987,-0.002505,0.004105,0.104275,145.467941,7.410491,1.042754,-298.911987,0.105108,0.000000
71.090004,33.660980,-299.000946,-0.002505,0.004133,0.104978,149.731522,7.627687,1.049778,-299.000946,0.105811,0.000000
71.510002,34.604202,-299.000946,-0.002488,0.004160,0.105664,153.927185,7.841424,1.056637,-299.000946,0.106504,0.000000
71.930000,34.858902,-299.089905,-0.002475,0.004180,0.106175,155.060135,7.899140,1.061754,-299.089905,0.107206,0.000000
72.350006,36.470901,-299.089905,-0.002466,0.004216,0.107076,162.230667,8.264425,1.070762,-299.089905,0.107909,0.000000
72.770004,37.039886,-299.089905,-0.002445,0.004237,0.107632,164.761642,8.393358,1.076318,-299.089905,0.108611,0.000000
73.190002,38.247116,-299.089905,-0.002432,0.004267,0.108386,170.131668,8.666921,1.083858,-299.089905,0.109305,0.000000
73.610001,39.487122,-299.134399,-0.002436,0.004293,0.109046,175.647491,8.947909,1.090459,-299.134399,0.110007,0.000000
74.030006,40.951660,-299.267853,-0.002406,0.004325,0.109851,182.162079,9.279779,1.098513,-299.267853,0.110710,0.000000
74.450005,42.459770,-299.223358,-0.002384,0.004356,0.110632,188.870483,9.621521,1.106325,-299.223358,0.111412,0.000000
74.870003,43.391075,-299.223358,-0.002371,0.004379,0.111230,193.013138,9.832558,1.112305,-299.223358,0.112107,0.000000
75.290001,44.979988,-299.223358,-0.002371,0.004408,0.111968,200.080978,10.192611,1.119678,-299.223358,0.112810,0.000000
75.710007,45.882248,-299.356812,-0.002350,0.004431,0.112558,204.094437,10.397066,1.125582,-299.356812,0.113512,0.000000
76.130005,47.749695,-299.356812,-0.002341,0.004464,0.113389,212.401245,10.820235,1.133894,-299.356812,0.114205,0.000000
76.550003,49.060440,-299.356812,-0.002315,0.004489,0.114024,218.231735,11.117254,1.140237,-299.356812,0.114908,0.000000
76.970001,49.995842,-299.312317,-0.002298,0.004512,0.114596,222.392609,11.329220,1.145960,-299.312317,0.115610,0.000000
77.390007,51.990273,-299.401276,-0.002302,0.004544,0.115420,231.264282,11.781164,1.154196,-299.401276,0.116313,0.000000
77.810005,53.067169,-299.445770,-0.002298,0.004567,0.116001,236.054565,12.025192,1.160010,-299.445770,0.117006,0.000000
78.230003,55.387054,-299.490234,-0.002272,0.004599,0.116825,246.373917,12.550886,1.168246,-299.490234,0.117709,0.000000
78.650002,56.701897,-299.490234,-0.002255,0.004625,0.117483,252.222626,12.848833,1.174831,-299.490234,0.118411,0.000000
79.070007,58.522057,-299.534729,-0.002251,0.004653,0.118177,260.319122,13.261288,1.181765,-299.534729,0.119105,0.000000
79.490005,59.869675,-299.534729,-0.002229,0.004675,0.118741,266.313599,13.566663,1.187412,-299.534729,0.119807,0.000000
79.910004,61.968361,-299.623688,-0.002220,0.004708,0.119581,275.649048,14.042232,1.195815,-299.623688,0.120510,0.000000
80.330002,64.395111,-299.623688,-0.002203,0.004740,0.120388,286.443756,14.592141,1.203884,-299.623688,0.121212,0.000000
80.750008,65.753525,-299.668182,-0.002190,0.004761,0.120918,292.486298,14.899961,1.209183,-299.668182,0.121907,0.000000
81.170006,65.954239,-299.668182,-0.002173,0.004764,0.121005,293.379120,14.945444,1.210046,-299.668182,0.021234,0.000000
81.590004,65.794861,-299.668182,-0.002169,0.004780,0.121421,292.670166,14.909328,1.214209,-299.668182,294.500458,0.000000
82.010002,65.244873,-299.757141,-0.002156,0.004778,0.121351,290.223694,14.784699,1.213513,-299.757141,294.500458,0.000000
82.430000,64.584656,-299.846100,-0.002147,0.004778,0.121351,287.286896,14.635093,1.213513,-299.846100,294.500458,0.000000
82.850006,66.380234,-299.801605,-0.002147,0.004689,0.119097,295.274017,15.041976,1.190970,-299.801605,294.500458,0.000000
83.270004,65.811615,-299.757141,-0.002147,0.004707,0.119556,292.744690,14.913126,1.195557,-299.757141,294.500458,0.000000
83.690002,65.284714,-299.890564,-0.002130,0.004767,0.121074,290.400909,14.793728,1.210742,-299.890564,294.500458,0.000000
84.110001,65.230347,-299.846100,-0.002126,0.004795,0.121793,290.159088,14.781407,1.217934,-299.846100,294.500458,0.000000
84.530006,65.280991,-299.979523,-0.002130,0.004800,0.121924,290.384338,14.792884,1.219236,-299.979523,294.500458,0.000000
84.950005,65.226242,-299.979523,-0.002121,0.004803,0.121993,290.140808,14.780478,1.219932,-299.979523,294.500458,0.000000
85.370003,65.621338,-299.890564,-0.002134,0.004811,0.122193,291.898285,14.870008,1.221931,-299.890564,294.500458,0.000000
85.790001,65.388611,-300.068481,-0.002130,0.004810,0.122166,290.863068,14.817271,1.221658,-300.068481,294.500458,0.000000
86.210007,65.143951,-300.112976,-0.002126,0.004810,0.122166,289.774780,14.761830,1.221658,-300.112976,294.500458,0.000000
86.630005,64.895203,-300.068481,-0.002147,0.004810,0.122166,288.668274,14.705463,1.221658,-300.068481,294.500458,0.000000
87.050003,65.953857,-300.024017,-0.002117,0.004821,0.122461,293.377411,14.945357,1.224610,-300.024017,294.500458,0.000000
87.470001,65.666763,-300.157471,-0.002143,0.004821,0.122461,292.100342,14.880301,1.224610,-300.157471,294.500458,0.000000
87.890007,65.453400,-300.157471,-0.002121,0.004821,0.122461,291.151276,14.831953,1.224610,-300.157471,294.500458,0.000000
88.310005,65.300720,-300.201935,-0.002134,0.004822,0.122470,290.472107,14.797355,1.224701,-300.201935,294.500458,0.000000
88.730003,65.133896,-300.246429,-0.002117,0.004822,0.122479,289.730042,14.759551,1.224792,-300.246429,294.500458,0.000000
89.150002,64.972656,-300.246429,-0.002117,0.004822,0.122487,289.012817,14.723015,1.224868,-300.246429,294.500458,0.000000
89.570007,66.090897,-300.246429,-0.002117,0.004832,0.122731,293.987000,14.976411,1.227305,-300.246429,294.500458,0.000000
89.990005,65.910675,-300.290894,-0.002113,0.004832,0.122721,293.185333,14.935573,1.227214,-300.290894,294.500458,0.000000
90.410004,65.769547,-300.335388,-0.002108,0.004832,0.122721,292.557556,14.903592,1.227214,-300.335388,294.500458,0.000000
90.830002,65.603470,-300.290894,-0.002117,0.004832,0.122721,291.818817,14.865958,1.227214,-300.290894,294.500458,0.000000
91.250008,65.474625,-300.335388,-0.002113,0.004832,0.122721,291.245667,14.836762,1.227214,-300.335388,294.500458,0.000000
91.670006,65.310028,-300.424347,-0.002113,0.004832,0.122721,290.513519,14.799464,1.227214,-300.424347,294.500458,0.000000
92.090004,65.317108,-300.513306,-0.002104,0.004836,0.122843,290.545013,14.801068,1.228426,-300.513306,294.500458,0.000000
92.510002,65.275772,-300.468811,-0.002108,0.004837,0.122852,290.361145,14.791701,1.228516,-300.468811,294.500458,0.000000
92.930008,65.281357,-300.468811,-0.002100,0.004838,0.122886,290.385986,14.792967,1.228865,-300.468811,294.500458,0.000000
93.350006,65.237045,-300.424347,-0.002108,0.004838,0.122896,290.188873,14.782926,1.228955,-300.424347,294.500458,0.000000
93.770004,65.430679,-300.513306,-0.002126,0.004842,0.122998,291.050201,14.826804,1.229985,-300.513306,294.500458,0.000000
94.190002,65.403870,-300.602264,-0.002104,0.004842,0.122998,290.930939,14.820729,1.229985,-300.602264,294.500458,0.000000
94.610008,65.337219,-300.646759,-0.002108,0.004842,0.122998,290.634460,14.805625,1.229985,-300.646759,294.500458,0.000000
95.030006,65.316360,-300.646759,-0.002113,0.004844,0.123033,290.541687,14.800900,1.230333,-300.646759,294.500458,0.000000
95.450005,65.348389,-300.646759,-0.002100,0.004846,0.123077,290.684143,14.808156,1.230772,-300.646759,294.500458,0.000000
95.870003,65.353973,-300.691223,-0.002104,0.004846,0.123077,290.708984,14.809422,1.230772,-300.691223,294.500458,0.000000
96.290001,65.342056,-300.735718,-0.002113,0.004846,0.123094,290.655975,14.806722,1.230939,-300.735718,294.500458,0.000000
96.710007,65.317108,-300.735718,-0.002113,0.004847,0.123103,290.545013,14.801068,1.231030,-300.735718,294.500458,0.000000
97.130005,65.542023,-300.735718,-0.002095,0.004851,0.123207,291.545471,14.852035,1.232074,-300.735718,294.500458,0.000000
97.550003,65.557663,-300.780182,-0.002100,0.004851,0.123207,291.615051,14.855579,1.232074,-300.780182,294.500458,0.000000
97.970001,65.528992,-300.824677,-0.002104,0.004851,0.123207,291.487518,14.849082,1.232074,-300.824677,294.500458,0.000000
98.390007,65.463074,-300.913635,-0.002100,0.004851,0.123216,291.194305,14.834145,1.232165,-300.913635,294.500458,0.000000
98.810005,65.387863,-300.869141,-0.002100,0.004851,0.123224,290.859741,14.817101,1.232241,-300.869141,294.500458,0.000000
99.230003,65.361786,-300.913635,-0.002100,0.004852,0.123233,290.743744,14.811193,1.232332,-300.913635,294.500458,0.000000
99.650002,65.342422,-300.958130,-0.002100,0.004852,0.123242,290.657623,14.806805,1.232422,-300.958130,294.500458,0.000000
100.070007,65.302582,-300.958130,-0.002091,0.004852,0.123242,290.480377,14.797776,1.232422,-300.958130,294.500458,0.000000
100.490005,65.263489,-301.047089,-0.002087,0.004852,0.123242,290.306488,14.788918,1.232422,-301.047089,294.500458,0.000000
100.910004,65.244873,-301.002594,-0.002095,0.004853,0.123268,290.223694,14.784699,1.232680,-301.002594,294.500458,0.000000
101.330002,65.237045,-301.091553,-0.002095,0.004854,0.123294,290.188873,14.782926,1.232937,-301.091553,294.500458,0.000000
101.750008,65.343918,-301.047089,-0.002091,0.004856,0.123354,290.664276,14.807143,1.233543,-301.047089,294.500458,0.000000
102.170006,65.369614,-301.136047,-0.002108,0.004856,0.123354,290.778564,14.812966,1.233543,-301.136047,294.500458,0.000000
102.590004,65.336838,-301.225006,-0.002091,0.004856,0.123354,290.632782,14.805539,1.233543,-301.225006,294.500458,0.000000
103.010002,65.334610,-301.180511,-0.002108,0.004857,0.123372,290.622864,14.805035,1.233724,-301.180511,294.500458,0.000000
103.430008,65.371841,-301.180511,-0.002113,0.004859,0.123407,290.788483,14.813471,1.234073,-301.180511,294.500458,0.000000
103.850006,65.397919,-301.225006,-0.002100,0.004859,0.123415,290.904480,14.819380,1.234148,-301.225006,294.500458,0.000000
104.270004,65.369980,-301.313965,-0.002104,0.004859,0.123415,290.780182,14.813048,1.234148,-301.313965,294.500458,0.000000
104.690002,65.338699,-301.313965,-0.002082,0.004859,0.123424,290.641052,14.805962,1.234239,-301.313965,294.500458,0.000000
105.110008,65.476486,-301.269470,-0.002087,0.004861,0.123475,291.253967,14.837184,1.234754,-301.269470,294.500458,0.000000
105.530006,65.483932,-301.313965,-0.002104,0.004861,0.123475,291.287079,14.838871,1.234754,-301.313965,294.500458,0.000000
105.950005,65.454147,-301.358429,-0.002091,0.004861,0.123475,291.154602,14.832121,1.234754,-301.358429,294.500458,0.000000
106.370003,65.405365,-301.402924,-0.002087,0.004861,0.123475,290.937592,14.821068,1.234754,-301.402924,294.500458,0.000000
106.790009,65.378555,-301.447418,-0.002091,0.004862,0.123503,290.818329,14.814992,1.235026,-301.447418,294.500458,0.000000
107.210007,65.455627,-301.402924,-0.002091,0.004863,0.123528,291.161163,14.832458,1.235284,-301.402924,294.500458,0.000000
107.630005,65.446701,-301.402924,-0.002091,0.004863,0.123528,291.121460,14.830435,1.235284,-301.402924,294.500458,0.000000
108.050003,65.416153,-301.491882,-0.002095,0.004863,0.123528,290.985596,14.823512,1.235284,-301.491882,294.500458,0.000000
108.470009,65.367386,-301.580841,-0.002100,0.004863,0.123528,290.768646,14.812461,1.235284,-301.580841,294.500458,0.000000
108.890007,65.330887,-301.580841,-0.002074,0.004863,0.123528,290.606293,14.804191,1.235284,-301.580841,294.500458,0.000000
109.310005,65.363281,-301.536377,-0.002091,0.004866,0.123598,290.750397,14.811532,1.235980,-301.536377,294.500458,0.000000
109.730003,65.458984,-301.580841,-0.002091,0.004866,0.123598,291.176117,14.833219,1.235980,-301.580841,294.500458,0.000000
110.150002,65.444458,-301.669800,-0.002095,0.004866,0.123598,291.111481,14.829926,1.235980,-301.669800,294.500458,0.000000
110.570007,65.411697,-301.714294,-0.002087,0.004866,0.123598,290.965759,14.822503,1.235980,-301.714294,294.500458,0.000000
110.990005,65.389725,-301.758759,-0.002087,0.004866,0.123606,290.868011,14.817523,1.236056,-301.758759,294.500458,0.000000
111.410004,65.359192,-301.758759,-0.002091,0.004866,0.123606,290.732208,14.810605,1.236056,-301.758759,294.500458,0.000000
111.830002,65.381149,-301.714294,-0.002091,0.004867,0.123631,290.829865,14.815579,1.236313,-301.714294,294.500458,0.000000
112.250008,65.385620,-301.803253,-0.002104,0.004868,0.123640,290.849762,14.816593,1.236404,-301.803253,294.500458,0.000000
112.670006,65.375565,-301.847748,-0.002087,0.004868,0.123649,290.805023,14.814314,1.236495,-301.847748,294.500458,0.000000
113.090004,65.379669,-301.847748,-0.002095,0.004868,0.123659,290.823303,14.815245,1.236586,-301.847748,294.500458,0.000000
113.510002,65.387482,-301.847748,-0.002070,0.004869,0.123666,290.858032,14.817015,1.236661,-301.847748,294.500458,0.000000
113.930008,65.375198,-301.892212,-0.002087,0.004869,0.123666,290.803406,14.814232,1.236661,-301.892212,294.500458,0.000000
114.350006,65.364029,-301.936707,-0.002091,0.004869,0.123675,290.753723,14.811701,1.236752,-301.936707,294.500458,0.000000
114.770004,65.355087,-302.025665,-0.002087,0.004869,0.123675,290.713959,14.809674,1.236752,-302.025665,294.500458,0.000000
115.190002,65.342804,-301.981171,-0.002100,0.004869,0.123675,290.659302,14.806890,1.236752,-301.981171,294.500458,0.000000
115.610008,65.314133,-302.070129,-0.002095,0.004869,0.123684,290.531769,14.800394,1.236843,-302.070129,294.500458,0.000000
116.030006,65.308914,-302.025665,-0.002100,0.004870,0.123701,290.508545,14.799212,1.237010,-302.025665,294.500458,0.000000
116.450005,65.314499,-302.114624,-0.002091,0.004870,0.123701,290.533386,14.800477,1.237010,-302.114624,294.500458,0.000000
116.870003,65.307419,-302.114624,-0.002087,0.004870,0.123701,290.501923,14.798873,1.237010,-302.114624,294.500458,0.000000
117.290009,65.289551,-302.114624,-0.002082,0.004871,0.123719,290.422424,14.794824,1.237191,-302.114624,294.500458,0.000000
117.710007,65.353226,-302.203583,-0.002091,0.004872,0.123745,290.705658,14.809253,1.237449,-302.203583,294.500458,0.000000
118.130005,65.351746,-302.203583,-0.002100,0.004872,0.123754,290.699097,14.808917,1.237540,-302.203583,294.500458,0.000000
118.550003,65.337219,-302.292542,-0.002091,0.004872,0.123754,290.634460,14.805625,1.237540,-302.292542,294.500458,0.000000
118.970009,65.327911,-302.292542,-0.002074,0.004872,0.123754,290.593048,14.803516,1.237540,-302.292542,294.500458,0.000000
119.390007,65.316742,-302.248077,-0.002087,0.004873,0.123762,290.543365,14.800985,1.237615,-302.248077,294.500458,0.000000
119.810005,65.308548,-302.337036,-0.002095,0.004873,0.123762,290.506927,14.799129,1.237615,-302.337036,294.500458,0.000000
120.230003,65.311523,-302.381500,-0.002087,0.004873,0.123771,290.520172,14.799802,1.237706,-302.381500,294.500458,0.000000
120.650009,65.333862,-302.470459,-0.002087,0.004874,0.123796,290.619537,14.804865,1.237963,-302.470459,294.500458,0.000000
121.070007,65.344284,-302.425995,-0.002091,0.004874,0.123796,290.665894,14.807227,1.237963,-302.425995,294.500458,0.000000
121.490005,65.340942,-302.425995,-0.002070,0.004874,0.123796,290.651031,14.806470,1.237963,-302.425995,294.500458,0.000000
121.910004,65.324554,-302.470459,-0.002078,0.004874,0.123796,290.578125,14.802755,1.237963,-302.470459,294.500458,0.000000
122.330009,65.323441,-302.514954,-0.002091,0.004874,0.123796,290.573181,14.802504,1.237963,-302.514954,294.500458,0.000000
122.750008,65.317474,-302.514954,-0.002091,0.004874,0.123805,290.546631,14.801151,1.238054,-302.514954,294.500458,0.000000
123.170006,65.315994,-302.559418,-0.002095,0.004874,0.123805,290.540039,14.800816,1.238054,-302.559418,294.500458,0.000000
123.590004,65.302216,-302.559418,-0.002091,0.004875,0.123815,290.478760,14.797693,1.238145,-302.559418,294.500458,0.000000
124.010002,65.307800,-302.559418,-0.002087,0.004875,0.123815,290.503601,14.798959,1.238145,-302.559418,294.500458,0.000000
124.430008,65.292908,-302.603912,-0.002095,0.004875,0.123815,290.437347,14.795585,1.238145,-302.603912,294.500458,0.000000
124.850006,65.272430,-302.692871,-0.002087,0.004875,0.123824,290.346283,14.790944,1.238236,-302.692871,294.500458,0.000000
125.270004,65.257156,-302.737366,-0.002091,0.004875,0.123831,290.278320,14.787483,1.238312,-302.737366,294.500458,0.000000
125.690002,65.242630,-302.692871,-0.002087,0.004875,0.123831,290.213715,14.784191,1.238312,-302.692871,294.500458,0.000000
126.110008,65.253067,-302.692871,-0.002082,0.004876,0.123840,290.260132,14.786556,1.238402,-302.692871,294.500458,0.000000
126.530006,65.242264,-302.737366,-0.002082,0.004876,0.123840,290.212097,14.784108,1.238402,-302.737366,294.500458,0.000000
126.950005,65.234436,-302.826324,-0.002078,0.004877,0.123866,290.177277,14.782334,1.238660,-302.826324,294.500458,0.000000
127.370003,65.318604,-302.826324,-0.002087,0.004878,0.123892,290.551666,14.801407,1.238917,-302.826324,294.500458,0.000000
127.790009,65.330521,-302.826324,-0.002070,0.004878,0.123892,290.604675,14.804107,1.238917,-302.826324,294.500458,0.000000
128.210007,65.330521,-302.826324,-0.002100,0.004878,0.123892,290.604675,14.804107,1.238917,-302.826324,294.500458,0.000000
128.630005,65.326416,-302.915283,-0.002078,0.004878,0.123892,290.586426,14.803178,1.238917,-302.915283,294.500458,0.000000
129.050003,65.308914,-302.959747,-0.002078,0.004878,0.123892,290.508545,14.799212,1.238917,-302.959747,294.500458,0.000000
129.470001,65.307053,-302.959747,-0.002082,0.004878,0.123892,290.500275,14.798789,1.238917,-302.959747,294.500458,0.000000
129.889999,65.303329,-302.959747,-0.002078,0.004878,0.123892,290.483704,14.797946,1.238917,-302.959747,294.500458,0.000000
130.310013,65.305939,-303.004242,-0.002082,0.004878,0.123892,290.495331,14.798536,1.238917,-303.004242,294.500458,0.000000
130.730011,65.274658,-303.048706,-0.002078,0.004878,0.123901,290.356171,14.791450,1.239008,-303.048706,294.500458,0.000000
131.150009,65.273163,-303.182159,-0.002091,0.004878,0.123901,290.349518,14.791110,1.239008,-303.182159,294.500458,0.000000
131.570007,65.249344,-303.182159,-0.002082,0.004878,0.123901,290.243591,14.785712,1.239008,-303.182159,294.500458,0.000000
131.990005,65.234436,-303.137695,-0.002082,0.004878,0.123901,290.177277,14.782334,1.239008,-303.137695,294.500458,0.000000
132.410004,65.251938,-303.137695,-0.002087,0.004879,0.123919,290.255127,14.786300,1.239190,-303.137695,294.500458,0.000000
132.830002,65.291794,-303.182159,-0.002074,0.004881,0.123987,290.432404,14.795332,1.239871,-303.182159,294.500458,0.000000
133.250000,65.583725,-303.315613,-0.002074,0.004883,0.124031,291.730988,14.861485,1.240310,-303.315613,294.500458,0.000000
133.670013,65.583359,-303.271118,-0.002074,0.004883,0.124031,291.729340,14.861402,1.240310,-303.271118,294.500458,0.000000
134.090012,65.596756,-303.271118,-0.002087,0.004883,0.124031,291.788940,14.864437,1.240310,-303.271118,294.500458,0.000000
134.510010,65.607925,-303.226654,-0.002087,0.004883,0.124031,291.838623,14.866968,1.240310,-303.226654,294.500458,0.000000
134.930008,65.600479,-303.360077,-0.002091,0.004883,0.124031,291.805511,14.865281,1.240310,-303.360077,294.500458,0.000000
135.350006,65.612030,-303.360077,-0.002082,0.004883,0.124031,291.856873,14.867899,1.240310,-303.360077,294.500458,0.000000
135.770004,65.589310,-303.404572,-0.002074,0.004883,0.124031,291.755829,14.862750,1.240310,-303.404572,294.500458,0.000000
136.190002,65.597870,-303.404572,-0.002078,0.004883,0.124031,291.793884,14.864690,1.240310,-303.404572,294.500458,0.000000
136.610001,65.587448,-303.449036,-0.002078,0.004883,0.124031,291.747528,14.862329,1.240310,-303.449036,294.500458,0.000000
137.030014,65.583725,-303.449036,-0.002078,0.004883,0.124031,291.730988,14.861485,1.240310,-303.449036,294.500458,0.000000
137.450012,65.578140,-303.538025,-0.002087,0.004883,0.124031,291.706146,14.860219,1.240310,-303.538025,294.500458,0.000000
137.870010,65.550583,-303.582489,-0.002078,0.004883,0.124031,291.583557,14.853974,1.240310,-303.582489,294.500458,0.000000
138.290009,65.536438,-303.538025,-0.002074,0.004883,0.124031,291.520630,14.850769,1.240310,-303.538025,294.500458,0.000000
138.710007,65.513718,-303.626984,-0.002070,0.004883,0.124031,291.419556,14.845620,1.240310,-303.626984,294.500458,0.000000
139.130005,65.513718,-303.626984,-0.002087,0.004883,0.124031,291.419556,14.845620,1.240310,-303.626984,294.500458,0.000000
139.550003,65.498825,-303.671448,-0.002091,0.004883,0.124031,291.353333,14.842246,1.240310,-303.671448,294.500458,0.000000
139.970001,65.480576,-303.671448,-0.002070,0.004883,0.124031,291.272156,14.838111,1.240310,-303.671448,294.500458,0.000000
140.389999,65.443344,-303.626984,-0.002078,0.004883,0.124040,291.106537,14.829674,1.240401,-303.626984,294.500458,0.000000
140.810013,65.453400,-303.671448,-0.002074,0.004884,0.124048,291.151276,14.831953,1.240477,-303.671448,294.500458,0.000000
141.230011,65.428452,-303.760406,-0.002078,0.004884,0.124048,291.040283,14.826300,1.240477,-303.760406,294.500458,0.000000
141.650009,65.409836,-303.849365,-0.002087,0.004884,0.124048,290.957489,14.822081,1.240477,-303.849365,0.124048,0.000000
142.070007,65.348389,-303.804901,-0.002082,0.004870,0.123701,290.684143,14.808156,1.237010,-303.804901,0.123468,0.000000
142.490005,65.348022,-303.760406,-0.002078,0.004855,0.123319,290.682526,14.808074,1.233194,-303.760406,0.122773,0.000000
142.910004,65.282852,-303.849365,-0.002087,0.004828,0.122635,290.392639,14.793305,1.226351,-303.849365,0.122070,0.000000
143.330002,65.250076,-303.938324,-0.002065,0.004797,0.121845,290.246826,14.785879,1.218449,-303.938324,0.121368,0.000000
143.750000,65.228104,-303.938324,-0.002082,0.004773,0.121230,290.149109,14.780899,1.212302,-303.938324,0.120675,0.000000
144.170013,65.198700,-303.982819,-0.002078,0.004740,0.120388,290.018311,14.774237,1.203884,-303.982819,0.119972,0.000000
144.590012,65.176727,-303.938324,-0.002065,0.004715,0.119765,289.920563,14.769257,1.197647,-303.938324,0.119270,0.000000
145.010010,65.168152,-303.982819,-0.002091,0.004693,0.119192,289.882416,14.767315,1.191924,-303.982819,0.118567,0.000000
145.430008,65.110809,-304.027313,-0.002074,0.004666,0.118507,289.627350,14.754320,1.185066,-304.027313,0.117874,0.000000
145.850006,64.914948,-304.160736,-0.002078,0.004642,0.117918,288.756104,14.709937,1.179176,-304.160736,0.117171,0.000000
146.270004,64.314682,-304.116272,-0.002070,0.004611,0.117111,286.085999,14.573915,1.171107,-304.116272,0.116469,0.000000
146.690002,63.251556,-304.160736,-0.002061,0.004586,0.116495,281.356964,14.333008,1.164945,-304.160736,0.115766,0.000000
147.110001,62.125504,-304.116272,-0.002052,0.004567,0.115992,276.348053,14.077841,1.159919,-304.116272,0.115073,0.000000
147.530014,60.288589,-304.160736,-0.002031,0.004538,0.115271,268.177032,13.661590,1.152712,-304.160736,0.114370,0.000000
147.950012,58.069252,-304.249695,-0.002022,0.004511,0.114578,258.304932,13.158680,1.145779,-304.249695,0.113668,0.000000
148.370010,55.729263,-304.249695,-0.002022,0.004485,0.113910,247.896149,12.628431,1.139102,-304.249695,0.112975,0.000000
148.790009,53.449966,-304.338654,-0.002026,0.004460,0.113294,237.757324,12.111936,1.132940,-304.338654,0.112272,0.000000
149.210007,49.589584,-304.338654,-0.002022,0.004425,0.112384,220.585495,11.237160,1.123841,-304.338654,0.111570,0.000000
149.630005,47.506905,-304.294189,-0.002031,0.004406,0.111916,211.321259,10.765219,1.119163,-304.294189,0.110867,0.000000
150.050003,44.645226,-304.338654,-0.002013,0.004384,0.111361,198.591888,10.116754,1.113607,-304.338654,0.110172,0.000000
150.470001,41.163170,-304.383148,-0.002026,0.004353,0.110554,183.102921,9.327707,1.105538,-304.383148,0.109470,0.000000
150.890015,38.307068,-304.383148,-0.002022,0.004324,0.109835,170.398346,8.680506,1.098346,-304.383148,0.108767,0.000000
151.310013,34.483925,-304.472107,-0.002035,0.004290,0.108967,153.392166,7.814169,1.089671,-304.472107,0.108074,0.000000
151.730011,32.164413,-304.472107,-0.002026,0.004267,0.108386,143.074463,7.288560,1.083858,-304.472107,0.107371,0.000000
152.150009,28.997757,-304.516602,-0.002022,0.004241,0.107711,128.988464,6.570985,1.077105,-304.516602,0.106669,0.000000
152.570007,26.255608,-304.472107,-0.002035,0.004214,0.107041,116.790779,5.949606,1.070414,-304.472107,0.105966,0.000000
152.990005,23.099754,-304.561066,-0.002013,0.004186,0.106322,102.752838,5.234479,1.063222,-304.561066,0.105273,0.000000
153.410004,20.216103,-304.516602,-0.002035,0.004161,0.105689,89.925713,4.581035,1.056894,-304.516602,0.104571,0.000000
153.830002,17.230789,-304.605560,-0.002022,0.004131,0.104934,76.646378,3.904553,1.049339,-304.605560,0.103868,0.000000
154.250000,14.377670,-304.605560,-0.002031,0.004104,0.104241,63.955070,3.258027,1.042405,-304.605560,0.103166,0.000000
154.670013,10.492714,-304.694519,-0.002031,0.004075,0.103496,46.673923,2.377683,1.034957,-304.694519,0.102472,0.000000
155.090012,8.591003,-304.605560,-0.002018,0.004058,0.103061,38.214691,1.946749,1.030612,-304.605560,0.101770,0.000000
155.510010,5.221031,-304.694519,-0.002018,0.004027,0.102298,23.224306,1.183103,1.022981,-304.694519,0.101067,0.000000
155.930008,1.993683,-304.738983,-0.002022,0.003997,0.101526,8.868344,0.451775,1.015260,-304.738983,0.100372,0.000000
156.350006,-0.704155,-304.738983,-0.002044,0.003968,0.100789,-3.132238,-0.159564,1.007887,-304.738983,0.099670,0.000000
156.770004,-0.266251,-304.783478,-0.002044,0.003939,0.100053,-1.184342,-0.060333,1.000529,-304.783478,0.098967,0.000000
157.190002,0.160492,-304.827972,-0.002026,0.003910,0.099307,0.713904,0.036368,0.993066,-304.827972,0.098265,0.000000
157.610001,0.125862,-304.783478,-0.002013,0.003884,0.098656,0.559863,0.028521,0.986556,-304.783478,0.097572,0.000000
158.030014,0.193260,-304.783478,-0.001983,0.003874,0.098404,0.859664,0.043793,0.984042,-304.783478,0.096869,0.000000
158.450012,0.035744,-304.916931,-0.001923,0.003823,0.097113,0.158996,0.008100,0.971128,-304.916931,0.096167,0.000000
158.870010,0.087135,-304.916931,-0.001888,0.003803,0.096592,0.387597,0.019745,0.965920,-304.916931,0.095473,0.000000
159.290009,0.041336,-304.916931,-0.001828,0.003771,0.095776,0.183872,0.009367,0.957760,-304.916931,0.094771,0.000000
159.710007,0.025322,-304.961395,-0.001819,0.003745,0.095127,0.112638,0.005738,0.951265,-304.961395,0.094068,0.000000
160.130005,-0.000000,-304.916931,-0.001798,0.003715,0.094363,-0.000000,-0.000000,0.943635,-304.916931,0.093366,0.000000
160.550003,-0.001488,-305.050354,-0.001772,0.003688,0.093670,-0.006618,-0.000337,0.936701,-305.050354,0.092672,0.000000
160.970001,-0.004845,-305.094849,-0.001755,0.003657,0.092880,-0.021550,-0.001098,0.928798,-305.094849,0.091970,0.000000
161.390015,-0.038353,-305.094849,-0.001768,0.003631,0.092221,-0.170603,-0.008691,0.922212,-305.094849,0.091267,0.000000
161.810013,-0.009682,-305.050354,-0.001763,0.003621,0.091970,-0.043066,-0.002194,0.919699,-305.050354,0.090565,0.000000
162.230011,-0.042824,-305.050354,-0.001768,0.003575,0.090800,-0.190490,-0.009704,0.907996,-305.050354,0.089872,0.000000
162.650009,-0.055855,-305.139313,-0.001763,0.003552,0.090209,-0.248455,-0.012657,0.902092,-305.139313,0.089169,0.000000
163.070007,-0.042824,-305.228271,-0.001759,0.003524,0.089498,-0.190490,-0.009704,0.894976,-305.228271,0.088467,0.000000
163.490005,-0.037979,-305.228271,-0.001763,0.003500,0.088900,-0.168940,-0.008606,0.888996,-305.228271,0.087772,0.000000
163.910004,-0.058464,-305.228271,-0.001759,0.003471,0.088162,-0.260061,-0.013248,0.881623,-305.228271,0.087069,0.000000
164.330002,-0.039101,-305.272766,-0.001755,0.003445,0.087495,-0.173928,-0.008860,0.874947,-305.272766,0.086367,0.000000
164.750015,-0.009682,-305.272766,-0.001763,0.003420,0.086871,-0.043066,-0.002194,0.868709,-305.272766,0.085664,0.000000
165.170013,-0.020485,-305.406219,-0.001772,0.003389,0.086090,-0.091121,-0.004642,0.860897,-305.406219,0.084971,0.000000
165.590012,-0.027557,-305.361725,-0.001772,0.003359,0.085327,-0.122581,-0.006245,0.853267,-305.361725,0.084268,0.000000
166.010010,-0.054741,-305.317261,-0.001776,0.003329,0.084564,-0.243500,-0.012404,0.845636,-305.317261,0.083566,0.000000
166.430008,-0.080063,-305.406219,-0.001776,0.003302,0.083861,-0.356137,-0.018143,0.838612,-305.406219,0.082873,0.000000
166.850006,-0.035004,-305.450684,-0.001789,0.003272,0.083107,-0.155704,-0.007932,0.831072,-305.450684,0.082170,0.000000
167.270004,-0.045433,-305.495178,-0.001794,0.003246,0.082447,-0.202096,-0.010295,0.824471,-305.495178,0.081468,0.000000
167.690002,-0.051018,-305.450684,-0.001811,0.003215,0.081649,-0.226938,-0.011561,0.816493,-305.450684,0.080765,0.000000
168.110001,-0.094955,-305.539642,-0.001819,0.003192,0.081068,-0.422383,-0.021517,0.810679,-305.539642,0.080072,0.000000
168.530014,-0.074104,-305.539642,-0.001837,0.003167,0.080453,-0.329632,-0.016792,0.804532,-305.539642,0.079369,0.000000
168.950012,-0.086021,-305.539642,-0.001845,0.003138,0.079707,-0.382642,-0.019493,0.797069,-305.539642,0.078667,0.000000
169.370010,-0.085274,-305.628601,-0.001871,0.003109,0.078979,-0.379317,-0.019323,0.789786,-305.628601,0.077964,0.000000
169.790009,-0.073730,-305.628601,-0.001876,0.003079,0.078197,-0.327969,-0.016708,0.781974,-305.628601,0.077271,0.000000
170.210007,-0.106499,-305.584137,-0.001906,0.003054,0.077574,-0.473730,-0.024133,0.775737,-305.584137,0.076568,0.000000
170.630005,-0.107246,-305.673096,-0.001936,0.003019,0.076680,-0.477056,-0.024302,0.766805,-305.673096,0.075866,0.000000
171.050003,-0.105751,-305.673096,-0.001957,0.002997,0.076134,-0.470404,-0.023964,0.761339,-305.673096,0.075171,0.000000
171.470001,-0.099052,-305.762054,-0.001966,0.002976,0.075587,-0.440607,-0.022446,0.755874,-305.762054,0.074469,0.000000
171.890015,-0.082664,-305.717590,-0.001996,0.002950,0.074929,-0.367710,-0.018732,0.749288,-305.717590,0.073766,0.000000
172.310013,-0.093842,-305.762054,-0.002018,0.002919,0.074148,-0.417428,-0.021265,0.741476,-305.762054,0.073064,0.000000
172.730011,-0.098679,-305.851013,-0.002048,0.002883,0.073220,-0.438944,-0.022361,0.732195,-305.851013,0.072370,0.000000
173.150009,-0.078941,-305.895508,-0.002065,0.002867,0.072812,-0.351149,-0.017888,0.728123,-305.895508,0.071668,0.000000
173.570007,-0.106499,-305.895508,-0.002082,0.002834,0.071980,-0.473730,-0.024133,0.719796,-305.895508,0.070965,0.000000
173.990005,-0.078941,-305.895508,-0.002121,0.002815,0.071503,-0.351149,-0.017888,0.715027,-305.895508,0.071400,0.000000
174.000015,-0.078201,-305.851013,-0.002117,0.002815,0.071503,-0.347857,-0.017721,0.715027,-305.851013,0.071400,0.000000