File: Data/compression 31/ManualNoHeating-10-31-reverse-1-3_11132024_181747.csv
Time (sec),S:Load (lbs),S:HL1 (DIM),S:LVDT (in),S:Position (in),Ch:Position (mm),Ch:Load (N),Ch:Stress (MPa),Ch:Strain (mm/mm),Ch:HL1 (DIM),Set Point (),Cycles ()
0.110000,-0.097565,-339.300690,-0.008658,-0.003659,-0.092942,-0.433989,-0.022108,-0.929419,-339.300690,-0.092733,0.000000
0.490000,-0.070755,-339.389648,-0.008662,-0.003602,-0.091484,-0.314734,-0.016033,-0.914839,-339.389648,-0.090965,0.000000
0.870000,-0.085274,-339.345184,-0.008528,-0.003373,-0.085673,-0.379317,-0.019323,-0.856734,-339.345184,-0.084633,0.000000
1.250000,-0.081924,-339.345184,-0.008261,-0.003127,-0.079430,-0.364418,-0.018564,-0.794298,-339.345184,-0.078302,0.000000
1.630000,-0.113571,-339.389648,-0.008006,-0.002874,-0.072995,-0.505190,-0.025736,-0.729955,-339.389648,-0.071972,0.000000
2.010000,-0.124374,-339.434143,-0.007756,-0.002624,-0.066647,-0.553245,-0.028184,-0.666475,-339.434143,-0.065641,0.000000
2.390000,-0.166451,-339.478607,-0.007502,-0.002378,-0.060411,-0.740409,-0.037718,-0.604115,-339.478607,-0.059311,0.000000
2.770000,-0.080803,-339.478607,-0.007235,-0.002129,-0.054089,-0.359429,-0.018310,-0.540892,-339.478607,-0.052979,0.000000
3.150000,-0.091232,-339.434143,-0.006980,-0.001881,-0.047785,-0.405822,-0.020674,-0.477851,-339.434143,-0.046648,0.000000
3.530000,-0.068520,-339.523102,-0.006726,-0.001630,-0.041402,-0.304790,-0.015527,-0.414022,-339.523102,-0.040318,0.000000
3.910000,-0.099426,-339.567566,-0.006476,-0.001380,-0.035054,-0.442270,-0.022530,-0.350542,-339.567566,-0.033987,0.000000
4.290000,-0.129959,-339.612061,-0.006209,-0.001127,-0.028637,-0.578087,-0.029449,-0.286365,-339.612061,-0.027657,0.000000
4.670000,-0.088997,-339.567566,-0.005937,-0.000873,-0.022184,-0.395878,-0.020167,-0.221840,-339.567566,-0.021326,0.000000
5.050000,-0.055115,-339.656555,-0.005700,-0.000631,-0.016036,-0.245163,-0.012489,-0.160358,-339.656555,-0.014994,0.000000
5.430000,-0.032028,-339.612061,-0.005424,-0.000385,-0.009774,-0.142469,-0.007258,-0.097741,-339.612061,-0.008664,0.000000
5.810000,-0.065536,-339.656555,-0.005182,-0.000150,-0.003799,-0.291521,-0.014851,-0.037985,-339.656555,-0.002333,0.000000
6.190000,0.100166,-339.701019,-0.004924,0.000112,0.002836,0.445562,0.022698,0.028356,-339.701019,0.003997,0.000000
6.570000,0.157516,-339.701019,-0.004889,-0.000010,-0.000253,0.700668,0.035694,-0.002528,-339.701019,-0.000114,0.000000
6.950000,0.145966,-339.656555,-0.004885,-0.000010,-0.000253,0.649287,0.033076,-0.002528,-339.656555,0.000259,0.000000
7.330000,0.169060,-339.789978,-0.004881,0.000005,0.000121,0.752015,0.038309,0.001211,-339.789978,0.000893,0.000000
7.710001,0.233849,-339.834473,-0.004876,0.000025,0.000640,1.040210,0.052991,0.006404,-339.834473,0.001526,0.000000
8.090000,0.354500,-339.789978,-0.004838,0.000054,0.001361,1.576894,0.080331,0.013610,-339.789978,0.002159,0.000000
8.470000,0.480362,-339.745514,-0.004812,0.000074,0.001889,2.136757,0.108852,0.018894,-339.745514,0.002792,0.000000
8.850000,0.571594,-339.789978,-0.004799,0.000093,0.002350,2.542578,0.129525,0.023497,-339.789978,0.003425,0.000000
9.230000,0.832253,-339.967896,-0.004734,0.000131,0.003320,3.702044,0.188591,0.033201,-339.967896,0.004057,0.000000
9.610001,0.919014,-339.834473,-0.004760,0.000148,0.003764,4.087978,0.208252,0.037637,-339.834473,0.004690,0.000000
9.990001,1.115623,-339.878937,-0.004717,0.000175,0.004439,4.962541,0.252804,0.044389,-339.878937,0.005325,0.000000
10.370001,1.350220,-339.834473,-0.004700,0.000201,0.005116,6.006077,0.305964,0.051157,-339.834473,0.005957,0.000000
10.750001,1.487625,-339.923431,-0.004678,0.000219,0.005550,6.617287,0.337101,0.055502,-339.923431,0.006590,0.000000
11.130000,1.818665,-340.056885,-0.004635,0.000257,0.006530,8.089824,0.412115,0.065297,-340.056885,0.007223,0.000000
11.510000,1.861488,-340.012390,-0.004622,0.000273,0.006946,8.280313,0.421819,0.069460,-340.012390,0.007856,0.000000
11.890000,2.044327,-340.012390,-0.004592,0.000296,0.007509,9.093619,0.463251,0.075092,-340.012390,0.008489,0.000000
12.270000,2.416695,-340.012390,-0.004557,0.000325,0.008256,10.749994,0.547631,0.082556,-340.012390,0.009123,0.000000
12.650001,2.535110,-340.056885,-0.004540,0.000341,0.008672,11.276734,0.574464,0.086720,-340.056885,0.009756,0.000000
13.030001,2.958870,-340.101349,-0.004506,0.000382,0.009695,13.161711,0.670490,0.096954,-340.101349,0.010389,0.000000
13.410001,2.973022,-340.145844,-0.004493,0.000400,0.010154,13.224665,0.673697,0.101541,-340.145844,0.011022,0.000000
13.790001,3.122711,-340.056885,-0.004462,0.000421,0.010684,13.890513,0.707617,0.106840,-340.056885,0.011664,0.000000
14.170001,3.485405,-340.145844,-0.004424,0.000452,0.011473,15.503856,0.789804,0.114728,-340.145844,0.012296,0.000000
14.550001,3.620949,-340.190308,-0.004402,0.000470,0.011933,16.106785,0.820519,0.119330,-340.190308,0.012929,0.000000
14.930000,3.931137,-340.279266,-0.004376,0.000502,0.012748,17.486570,0.890808,0.127475,-340.279266,0.013562,0.000000
15.310000,4.034653,-340.234802,-0.004342,0.000526,0.013364,17.947031,0.914265,0.133637,-340.234802,0.014196,0.000000
15.690001,4.074127,-340.234802,-0.004320,0.000546,0.013857,18.122623,0.923210,0.138573,-340.234802,0.014829,0.000000
16.070002,4.377235,-340.234802,-0.004273,0.000573,0.014543,19.470915,0.991896,0.145431,-340.234802,0.015462,0.000000
16.450001,4.552254,-340.279266,-0.004264,0.000595,0.015115,20.249435,1.031556,0.151154,-340.279266,0.016095,0.000000
16.830000,4.875099,-340.368225,-0.004243,0.000623,0.015818,21.685524,1.104713,0.158178,-340.368225,0.016728,0.000000
17.210001,4.952553,-340.368225,-0.004186,0.000649,0.016495,22.030056,1.122265,0.164946,-340.368225,0.017361,0.000000
17.590000,4.951805,-340.279266,-0.004169,0.000671,0.017032,22.026730,1.122095,0.170320,-340.279266,0.017995,0.000000
17.970001,5.241516,-340.368225,-0.004122,0.000701,0.017804,23.315428,1.187745,0.178041,-340.368225,0.018628,0.000000
18.350000,5.266838,-340.412720,-0.004096,0.000721,0.018323,23.428066,1.193483,0.183234,-340.412720,0.019261,0.000000
18.730001,5.575157,-340.457214,-0.004057,0.000752,0.019096,24.799538,1.263349,0.190956,-340.457214,0.019893,0.000000
19.110001,5.461212,-340.412720,-0.004061,0.000773,0.019642,24.292685,1.237528,0.196421,-340.412720,0.020526,0.000000
19.490002,5.605324,-340.412720,-0.004010,0.000797,0.020240,24.933725,1.270185,0.202401,-340.412720,0.021159,0.000000
19.870001,5.824280,-340.501678,-0.003980,0.000826,0.020986,25.907690,1.319801,0.209865,-340.501678,0.021793,0.000000
20.250002,5.696556,-340.501678,-0.003954,0.000844,0.021445,25.339546,1.290858,0.214452,-340.501678,0.022426,0.000000
20.630001,5.703629,-340.501678,-0.003932,0.000860,0.021845,25.371006,1.292461,0.218449,-340.501678,0.023059,0.000000
21.010000,6.067810,-340.590637,-0.003885,0.000897,0.022790,26.990967,1.374985,0.227896,-340.590637,0.023692,0.000000
21.390001,6.040627,-340.501678,-0.003850,0.000921,0.023388,26.870049,1.368826,0.233876,-340.501678,0.024325,0.000000
21.770000,6.195534,-340.590637,-0.003803,0.000949,0.024099,27.559111,1.403928,0.240992,-340.590637,0.024958,0.000000
22.150002,6.166489,-340.724091,-0.003786,0.000971,0.024671,27.429911,1.397346,0.246715,-340.724091,0.025590,0.000000
22.530001,5.973969,-340.679596,-0.003764,0.000982,0.024932,26.573540,1.353721,0.249319,-340.679596,0.026225,0.000000
22.910002,6.439438,-340.679596,-0.003712,0.001025,0.026034,28.644051,1.459198,0.260340,-340.679596,0.026858,0.000000
23.290001,6.274475,-340.679596,-0.003673,0.001043,0.026502,27.910259,1.421816,0.265018,-340.679596,0.027490,0.000000
23.670002,6.387680,-340.724091,-0.003630,0.001072,0.027221,28.413820,1.447469,0.272210,-340.724091,0.028123,0.000000
24.050001,6.327728,-340.724091,-0.003617,0.001092,0.027733,28.147141,1.433884,0.277327,-340.724091,0.028756,0.000000
24.430000,6.237236,-340.768555,-0.003600,0.001109,0.028158,27.744612,1.413378,0.281581,-340.768555,0.029398,0.000000
24.810001,6.750366,-340.768555,-0.003527,0.001151,0.029225,30.027128,1.529655,0.292254,-340.768555,0.030031,0.000000
25.190001,6.438316,-340.813049,-0.003501,0.001168,0.029675,28.639061,1.458943,0.296751,-340.813049,0.030664,0.000000
25.570002,6.556732,-340.768555,-0.003454,0.001197,0.030405,29.165802,1.485777,0.304048,-340.768555,0.031298,0.000000
25.950001,6.536995,-340.813049,-0.003428,0.001220,0.030985,29.078005,1.481304,0.309847,-340.813049,0.031931,0.000000
26.330002,6.334801,-340.857513,-0.003406,0.001234,0.031333,28.178600,1.435486,0.313329,-340.857513,0.032564,0.000000
26.710001,6.809204,-340.857513,-0.003363,0.001276,0.032399,30.288853,1.542988,0.323987,-340.857513,0.033197,0.000000
27.090002,6.592857,-340.857513,-0.003307,0.001294,0.032876,29.326494,1.493963,0.328756,-340.857513,0.033829,0.000000
27.470001,6.762657,-340.902008,-0.003290,0.001325,0.033648,30.081802,1.532440,0.336477,-340.902008,0.034462,0.000000
27.850000,6.642006,-340.946503,-0.003255,0.001345,0.034169,29.545118,1.505100,0.341685,-340.946503,0.035097,0.000000
28.230001,6.561943,-340.946503,-0.003229,0.001361,0.034567,29.188980,1.486958,0.345667,-340.946503,0.035729,0.000000
28.610001,6.966347,-340.946503,-0.003191,0.001402,0.035608,30.987858,1.578597,0.356083,-340.946503,0.036362,0.000000
28.990002,6.760796,-340.990967,-0.003147,0.001423,0.036137,30.073521,1.532018,0.361367,-340.990967,0.036995,0.000000
29.370001,6.880325,-341.079926,-0.003100,0.001448,0.036788,30.605215,1.559104,0.367877,-341.079926,0.037628,0.000000
29.750002,6.882561,-341.079926,-0.003083,0.001471,0.037360,30.615160,1.559610,0.373599,-341.079926,0.038261,0.000000
30.130001,6.789467,-341.035461,-0.003061,0.001489,0.037819,30.201057,1.538515,0.378187,-341.035461,0.038895,0.000000
30.510002,7.130562,-341.079926,-0.003014,0.001527,0.038782,31.718323,1.615808,0.387815,-341.079926,0.039528,0.000000
30.890001,6.935440,-341.124420,-0.002975,0.001546,0.039277,30.850378,1.571593,0.392766,-341.124420,0.040161,0.000000
31.270002,7.004700,-341.213379,-0.002945,0.001571,0.039891,31.158461,1.587288,0.398913,-341.213379,0.040794,0.000000
31.650002,7.165192,-341.213379,-0.002910,0.001599,0.040612,31.872364,1.623656,0.406119,-341.213379,0.041426,0.000000
32.030003,7.041565,-341.168884,-0.002889,0.001616,0.041045,31.322445,1.595641,0.410449,-341.168884,0.042059,0.000000
32.410000,7.429947,-341.124420,-0.002824,0.001653,0.041990,33.050053,1.683650,0.419896,-341.124420,0.042692,0.000000
32.790001,7.138008,-341.213379,-0.002807,0.001671,0.042441,31.751446,1.617496,0.424408,-341.213379,0.043326,0.000000
33.170002,7.085503,-341.302338,-0.002768,0.001691,0.042962,31.517889,1.605598,0.429616,-341.302338,0.043959,0.000000
33.550003,7.380424,-341.213379,-0.002725,0.001723,0.043769,32.829769,1.672428,0.437685,-341.213379,0.044592,0.000000
33.930000,7.244133,-341.257843,-0.002708,0.001740,0.044202,32.223515,1.641544,0.442015,-341.257843,0.045225,0.000000
34.310001,7.765457,-341.302338,-0.002665,0.001779,0.045181,34.542480,1.759678,0.451810,-341.302338,0.045858,0.000000
34.690002,7.396065,-341.302338,-0.002634,0.001798,0.045659,32.899338,1.675972,0.456595,-341.302338,0.046491,0.000000
35.070004,7.309296,-341.435791,-0.002596,0.001816,0.046127,32.513371,1.656310,0.461273,-341.435791,0.047125,0.000000
35.450001,7.606079,-341.346832,-0.002539,0.001849,0.046960,33.833530,1.723562,0.469599,-341.346832,0.047765,0.000000
35.830002,7.571449,-341.346832,-0.002527,0.001868,0.047446,33.679489,1.715715,0.474459,-341.346832,0.048400,0.000000
36.210003,7.774391,-341.391296,-0.002492,0.001897,0.048174,34.582218,1.761702,0.481741,-341.391296,0.049033,0.000000
36.590000,7.624695,-341.435791,-0.002440,0.001918,0.048712,33.916336,1.727780,0.487116,-341.435791,0.049665,0.000000
36.970001,7.539795,-341.524750,-0.002406,0.001940,0.049275,33.538681,1.708542,0.492748,-341.524750,0.050298,0.000000
37.350002,7.829872,-341.480255,-0.002384,0.001971,0.050056,34.829010,1.774274,0.500560,-341.480255,0.050931,0.000000
37.730003,7.803436,-341.435791,-0.002363,0.001993,0.050628,34.711418,1.768284,0.506283,-341.435791,0.051564,0.000000
38.110001,8.094635,-341.435791,-0.002320,0.002020,0.051313,36.006733,1.834270,0.513126,-341.435791,0.052198,0.000000
38.490002,7.942703,-341.524750,-0.002285,0.002045,0.051938,35.330910,1.799842,0.519378,-341.524750,0.052831,0.000000
38.870003,7.808281,-341.613708,-0.002255,0.002067,0.052501,34.732967,1.769382,0.525010,-341.613708,0.053464,0.000000
39.250000,8.030586,-341.524750,-0.002220,0.002096,0.053229,35.721832,1.819757,0.532292,-341.524750,0.054097,0.000000
39.630001,7.967651,-341.613708,-0.002195,0.002119,0.053827,35.441883,1.805496,0.538273,-341.613708,0.054730,0.000000
40.010002,8.220497,-341.658173,-0.002143,0.002147,0.054522,36.566597,1.862791,0.545222,-341.658173,0.055362,0.000000
40.390003,7.970261,-341.658173,-0.002104,0.002169,0.055094,35.453491,1.806087,0.550944,-341.658173,0.055997,0.000000
40.770000,8.000793,-341.702667,-0.002078,0.002194,0.055736,35.589306,1.813006,0.557364,-341.702667,0.056630,0.000000
41.150002,8.169106,-341.702667,-0.002035,0.002221,0.056421,36.337997,1.851146,0.564207,-341.702667,0.057262,0.000000
41.530003,7.846260,-341.702667,-0.002009,0.002237,0.056828,34.901909,1.777988,0.568279,-341.702667,0.057895,0.000000
41.910004,7.854454,-341.702667,-0.001983,0.002256,0.057314,34.938358,1.779845,0.573139,-341.702667,0.058528,0.000000
42.290001,8.265175,-341.747162,-0.001932,0.002295,0.058286,36.765335,1.872915,0.582859,-341.747162,0.059161,0.000000
42.670002,8.116600,-341.836121,-0.001910,0.002319,0.058893,36.104439,1.839248,0.588930,-341.836121,0.059794,0.000000
43.050003,8.155701,-341.791626,-0.001880,0.002342,0.059482,36.278370,1.848108,0.594819,-341.791626,0.060428,0.000000
43.430000,8.047340,-341.747162,-0.001850,0.002363,0.060019,35.796356,1.823553,0.600194,-341.747162,0.061061,0.000000
43.810001,7.947548,-341.836121,-0.001798,0.002380,0.060445,35.352459,1.800940,0.604448,-341.836121,0.061694,0.000000
44.190002,8.617439,-341.836121,-0.001768,0.002423,0.061555,38.332283,1.952740,0.615545,-341.836121,0.062327,0.000000
44.570004,8.275604,-341.925079,-0.001742,0.002442,0.062024,36.811726,1.875279,0.620238,-341.925079,0.062959,0.000000
44.950001,8.350822,-341.880585,-0.001703,0.002468,0.062691,37.146313,1.892323,0.626915,-341.880585,0.063592,0.000000
45.330002,8.328110,-341.925079,-0.001677,0.002490,0.063255,37.045280,1.887177,0.632547,-341.925079,0.064227,0.000000
45.710003,8.114738,-341.925079,-0.001638,0.002507,0.063680,36.096161,1.838826,0.636801,-341.925079,0.064859,0.000000
46.090004,8.708672,-342.014038,-0.001595,0.002545,0.064643,38.738106,1.973413,0.646430,-342.014038,0.065492,0.000000
46.470001,8.305763,-342.014038,-0.001552,0.002564,0.065137,36.945881,1.882113,0.651365,-342.014038,0.066134,0.000000
46.850002,8.530304,-342.058502,-0.001531,0.002593,0.065874,37.944687,1.932994,0.658738,-342.058502,0.066767,0.000000
47.230003,8.498657,-342.014038,-0.001500,0.002616,0.066455,37.803917,1.925823,0.664552,-342.014038,0.067400,0.000000
47.610001,8.263687,-342.058502,-0.001453,0.002632,0.066846,36.758717,1.872578,0.668458,-342.058502,0.068033,0.000000
47.990002,8.839378,-342.191956,-0.001414,0.002673,0.067886,39.319519,2.003032,0.678859,-342.191956,0.068666,0.000000
48.370003,8.573502,-342.147461,-0.001388,0.002692,0.068389,38.136841,1.942783,0.683885,-342.147461,0.069300,0.000000
48.750004,8.666595,-342.147461,-0.001350,0.002719,0.069056,38.550941,1.963879,0.690562,-342.147461,0.069933,0.000000
49.130001,8.612602,-342.191956,-0.001319,0.002742,0.069638,38.310768,1.951644,0.696375,-342.191956,0.070566,0.000000
49.510002,8.468491,-342.191956,-0.001302,0.002759,0.070080,37.669727,1.918987,0.700796,-342.191956,0.071198,0.000000
49.890003,9.074341,-342.280914,-0.001237,0.002799,0.071094,40.364685,2.056275,0.710940,-342.280914,0.071831,0.000000
50.270004,8.658028,-342.236450,-0.001203,0.002818,0.071589,38.512829,1.961937,0.715890,-342.236450,0.072464,0.000000
50.650002,8.785385,-342.280914,-0.001173,0.002843,0.072213,39.079346,1.990797,0.722128,-342.280914,0.073098,0.000000
51.030003,8.889648,-342.280914,-0.001143,0.002869,0.072864,39.543133,2.014423,0.728638,-342.280914,0.073731,0.000000
51.410004,8.727669,-342.325409,-0.001108,0.002885,0.073289,38.822609,1.977718,0.732892,-342.325409,0.074364,0.000000
51.790001,9.313408,-342.325409,-0.001030,0.002923,0.074251,41.428108,2.110448,0.742506,-342.325409,0.074997,0.000000
52.170002,8.955185,-342.414368,-0.001035,0.002943,0.074746,39.834652,2.029274,0.747456,-342.414368,0.075630,0.000000
52.550003,9.088493,-342.369873,-0.001000,0.002967,0.075362,40.427639,2.059482,0.753618,-342.369873,0.076263,0.000000
52.930004,9.215469,-342.414368,-0.000970,0.002991,0.075960,40.992455,2.088255,0.759598,-342.414368,0.076897,0.000000
53.310001,9.384903,-342.414368,-0.000940,0.003013,0.076523,41.746132,2.126649,0.765230,-342.414368,0.077530,0.000000
53.690002,10.001923,-342.458832,-0.000901,0.003049,0.077442,44.490772,2.266468,0.774420,-342.458832,0.078163,0.000000
54.070004,9.427353,-342.503326,-0.000871,0.003069,0.077954,41.934959,2.136269,0.779537,-342.503326,0.078795,0.000000
54.450001,9.484695,-342.592285,-0.000849,0.003088,0.078423,42.190033,2.149263,0.784230,-342.592285,0.079428,0.000000
54.830002,10.150131,-342.503326,-0.000828,0.003117,0.079177,45.150040,2.300052,0.791770,-342.503326,0.080061,0.000000
55.210003,10.209709,-342.547791,-0.000789,0.003138,0.079714,45.415054,2.313553,0.797144,-342.547791,0.080694,0.000000
55.590004,11.079567,-342.592285,-0.000746,0.003174,0.080626,49.284374,2.510666,0.806258,-342.592285,0.081328,0.000000
55.970001,10.484146,-342.592285,-0.000724,0.003196,0.081172,46.635811,2.375741,0.811724,-342.592285,0.081961,0.000000
56.350002,10.453987,-342.681244,-0.000690,0.003213,0.081622,46.501656,2.368907,0.816220,-342.681244,0.082594,0.000000
56.730003,11.121651,-342.681244,-0.000664,0.003244,0.082385,49.471573,2.520202,0.823851,-342.681244,0.083227,0.000000
57.110004,10.917213,-342.681244,-0.000629,0.003264,0.082915,48.562191,2.473876,0.829149,-342.681244,0.083860,0.000000
57.490002,11.724144,-342.681244,-0.000599,0.003292,0.083617,52.151596,2.656729,0.836174,-342.681244,0.084502,0.000000
57.870003,11.632912,-342.725739,-0.000578,0.003316,0.084215,51.745777,2.636055,0.842154,-342.725739,0.085134,0.000000
58.250004,11.712975,-342.725739,-0.000552,0.003338,0.084779,52.101913,2.654198,0.847786,-342.725739,0.085767,0.000000
58.630001,12.153488,-342.725739,-0.000509,0.003366,0.085499,54.061417,2.754020,0.854993,-342.725739,0.086402,0.000000
59.010002,11.925224,-342.725739,-0.000504,0.003383,0.085932,53.046047,2.702294,0.859323,-342.725739,0.087034,0.000000
59.390003,11.999702,-342.859161,-0.000466,0.003401,0.086392,53.377342,2.719172,0.863925,-342.859161,0.087667,0.000000
59.770004,13.231880,-342.814697,-0.000444,0.003442,0.087416,58.858341,2.998387,0.874159,-342.814697,0.088300,0.000000
60.150002,13.121658,-342.859161,-0.000405,0.003464,0.087979,58.368050,2.973410,0.879791,-342.859161,0.088933,0.000000
60.530003,13.450462,-342.859161,-0.000375,0.003489,0.088621,59.830647,3.047918,0.886210,-342.859161,0.089566,0.000000
60.910004,13.540581,-342.859161,-0.000349,0.003511,0.089184,60.231510,3.068340,0.891842,-342.859161,0.090200,0.000000
61.290005,14.506516,-342.948120,-0.000332,0.003543,0.089982,64.528206,3.287223,0.899821,-342.948120,0.090833,0.000000
61.670002,14.773506,-342.948120,-0.000306,0.003567,0.090589,65.715836,3.347724,0.905892,-342.948120,0.091466,0.000000
62.050003,14.710945,-342.948120,-0.000267,0.003589,0.091171,65.437553,3.333548,0.911705,-342.948120,0.092099,0.000000
62.430004,15.399834,-342.948120,-0.000237,0.003618,0.091891,68.501884,3.489652,0.918912,-342.948120,0.092731,0.000000
62.810001,15.461273,-343.037109,-0.000216,0.003635,0.092324,68.775177,3.503575,0.923242,-343.037109,0.093364,0.000000
63.190002,15.680603,-343.081573,-0.000194,0.003654,0.092810,69.750809,3.553275,0.928102,-343.081573,0.093999,0.000000
63.570004,16.891930,-343.081573,-0.000164,0.003688,0.093669,75.139053,3.827766,0.936686,-343.081573,0.094631,0.000000
63.950005,17.325371,-343.037109,-0.000134,0.003715,0.094353,77.067101,3.925985,0.943529,-343.037109,0.095264,0.000000
64.330002,17.524963,-343.037109,-0.000125,0.003735,0.094865,77.954933,3.971214,0.948646,-343.037109,0.095897,0.000000
64.710007,18.063416,-343.170532,-0.000086,0.003760,0.095507,80.350082,4.093228,0.955065,-343.170532,0.096530,0.000000
65.090004,18.155762,-343.126068,-0.000069,0.003778,0.095967,80.760864,4.114154,0.959668,-343.126068,0.097163,0.000000
65.470001,20.141251,-343.170532,-0.000047,0.003821,0.097042,89.592758,4.564073,0.970417,-343.170532,0.097796,0.000000
65.850006,20.003479,-343.170532,-0.000022,0.003837,0.097458,88.979919,4.532853,0.974580,-343.170532,0.098430,0.000000
66.230003,20.808548,-343.126068,0.000000,0.003864,0.098144,92.561043,4.715284,0.981438,-343.126068,0.099063,0.000000
66.610001,21.357422,-343.170532,0.000030,0.003887,0.098733,95.002556,4.839661,0.987328,-343.170532,0.099696,0.000000
66.990005,21.522758,-343.259491,0.000052,0.003902,0.099123,95.738014,4.877127,0.991234,-343.259491,0.100328,0.000000
67.370003,23.470634,-343.259491,0.000052,0.003940,0.100077,104.402596,5.318521,1.000772,-343.259491,0.100961,0.000000
67.750000,23.621445,-343.303986,0.000086,0.003961,0.100606,105.073433,5.352696,1.006055,-343.303986,0.101594,0.000000
68.130005,24.515137,-343.303986,0.000121,0.003987,0.101266,109.048775,5.555210,1.012656,-343.303986,0.102236,0.000000
68.510002,25.556297,-343.348450,0.000121,0.004014,0.101959,113.680084,5.791140,1.019590,-343.348450,0.102869,0.000000
68.890007,25.780090,-343.348450,0.000142,0.004029,0.102331,114.675568,5.841852,1.023314,-343.348450,0.103503,0.000000
69.270004,27.860161,-343.437408,0.000177,0.004067,0.103294,123.928185,6.313202,1.032943,-343.437408,0.104136,0.000000
69.650002,28.174820,-343.348450,0.000198,0.004086,0.103789,125.327858,6.384506,1.037894,-343.348450,0.104769,0.000000
70.030006,29.198845,-343.392944,0.000211,0.004111,0.104413,129.882950,6.616553,1.044131,-343.392944,0.105402,0.000000
70.410004,30.321541,-343.481903,0.000233,0.004137,0.105072,134.876953,6.870959,1.050717,-343.481903,0.106035,0.000000
70.790001,31.054001,-343.481903,0.000233,0.004157,0.105593,138.135101,7.036937,1.055925,-343.481903,0.106667,0.000000
71.170006,33.327332,-343.481903,0.000246,0.004194,0.106537,148.247375,7.552081,1.065372,-343.481903,0.107302,0.000000
71.550003,33.687050,-343.481903,0.000259,0.004211,0.106972,149.847488,7.633595,1.069717,-343.481903,0.107935,0.000000
71.930000,34.603455,-343.526398,0.000297,0.004238,0.107639,153.923859,7.841255,1.076394,-343.526398,0.108567,0.000000
72.310005,36.116402,-343.526398,0.000302,0.004265,0.108325,160.653778,8.184093,1.083252,-343.526398,0.109200,0.000000
72.690002,37.076378,-343.615356,0.000315,0.004282,0.108775,164.923965,8.401627,1.087749,-343.615356,0.109833,0.000000
73.070000,39.318810,-343.615356,0.000341,0.004318,0.109668,174.898804,8.909769,1.096681,-343.615356,0.110466,0.000000
73.450005,39.986099,-343.615356,0.000345,0.004339,0.110207,177.867050,9.060979,1.102071,-343.615356,0.111100,0.000000
73.830002,41.472237,-343.704315,0.000354,0.004362,0.110796,184.477722,9.397743,1.107960,-343.704315,0.111733,0.000000
74.210007,42.784103,-343.704315,0.000371,0.004385,0.111377,190.313202,9.695017,1.113773,-343.704315,0.112366,0.000000
74.590004,43.778343,-343.704315,0.000379,0.004411,0.112036,194.735794,9.920315,1.120359,-343.704315,0.112999,0.000000
74.970001,46.635925,-343.704315,0.000401,0.004444,0.112878,207.446960,10.567851,1.128777,-343.704315,0.113632,0.000000
75.350006,47.436523,-343.748779,0.000414,0.004459,0.113268,211.008194,10.749269,1.132683,-343.748779,0.114264,0.000000
75.730003,48.912239,-343.793274,0.000423,0.004484,0.113901,217.572510,11.083673,1.139011,-343.793274,0.114897,0.000000
76.110001,51.050026,-343.793274,0.000435,0.004514,0.114655,227.081863,11.568101,1.146551,-343.793274,0.115532,0.000000
76.490005,51.572838,-343.837738,0.000435,0.004528,0.115002,229.407440,11.686572,1.150018,-343.837738,0.116164,0.000000
76.870003,53.349060,-343.837738,0.000453,0.004562,0.115869,237.308472,12.089070,1.158693,-343.837738,0.116797,0.000000
77.250000,56.296761,-343.793274,0.000466,0.004587,0.116520,250.420502,12.757028,1.165203,-343.793274,0.117430,0.000000
77.630005,57.359138,-343.837738,0.000474,0.004607,0.117023,255.146194,12.997766,1.170229,-343.837738,0.118063,0.000000
78.010002,59.912865,-343.926727,0.000483,0.004640,0.117856,266.505737,13.576449,1.178556,-343.926727,0.118696,0.000000
78.390007,60.841934,-343.882233,0.000500,0.004653,0.118184,270.638428,13.786980,1.181841,-343.882233,0.119330,0.000000
78.770004,62.071136,-343.882233,0.000496,0.004672,0.118679,276.106201,14.065520,1.186792,-343.882233,0.119963,0.000000
79.150002,65.162567,-343.926727,0.000513,0.004709,0.119598,289.857574,14.766049,1.195981,-343.926727,0.120605,0.000000
79.530006,65.738266,-343.926727,0.000530,0.004712,0.119694,292.418427,14.896503,1.196935,-343.926727,0.021004,0.000000
79.910004,65.578888,-344.015686,0.000535,0.004725,0.120024,291.709473,14.860388,1.200236,-344.015686,294.500458,0.000000
80.290001,65.176346,-343.971191,0.000526,0.004723,0.119963,289.918854,14.769171,1.199630,-343.971191,294.500458,0.000000
80.670006,65.593781,-344.015686,0.000552,0.004733,0.120214,291.775696,14.863764,1.202143,-344.015686,294.500458,0.000000
81.050003,65.301834,-344.060150,0.000565,0.004733,0.120214,290.477051,14.797607,1.202143,-344.060150,294.500458,0.000000
81.430000,65.152893,-344.104645,0.000552,0.004736,0.120284,289.814545,14.763856,1.202840,-344.104645,294.500458,0.000000
81.810005,65.050491,-344.149109,0.000543,0.004741,0.120422,289.359039,14.740652,1.204217,-344.149109,294.500458,0.000000
82.190002,65.339828,-344.149109,0.000560,0.004742,0.120449,290.646088,14.806217,1.204490,-344.149109,294.500458,0.000000
82.570007,65.154388,-344.149109,0.000565,0.004742,0.120449,289.821198,14.764195,1.204490,-344.149109,294.500458,0.000000
82.950005,65.619843,-344.193604,0.000556,0.004750,0.120647,291.891632,14.869669,1.206473,-344.193604,294.500458,0.000000
83.330002,65.544250,-344.238068,0.000560,0.004750,0.120647,291.555389,14.852540,1.206473,-344.238068,294.500458,0.000000
83.710007,65.369980,-344.238068,0.000548,0.004750,0.120647,290.780182,14.813048,1.206473,-344.238068,294.500458,0.000000
84.090004,65.242630,-344.238068,0.000569,0.004750,0.120656,290.213715,14.784191,1.206564,-344.238068,294.500458,0.000000
84.470001,65.505905,-344.238068,0.000578,0.004755,0.120768,291.384827,14.843851,1.207684,-344.238068,294.500458,0.000000
84.850006,65.371109,-344.327057,0.000578,0.004755,0.120768,290.785217,14.813306,1.207684,-344.327057,294.500458,0.000000
85.230003,65.294022,-344.371521,0.000556,0.004756,0.120812,290.442322,14.795836,1.208123,-344.371521,294.500458,0.000000
85.610001,65.320465,-344.327057,0.000569,0.004757,0.120838,290.559937,14.801828,1.208381,-344.327057,294.500458,0.000000
85.990005,65.304077,-344.282562,0.000565,0.004758,0.120864,290.487030,14.798116,1.208638,-344.282562,294.500458,0.000000
86.370003,65.265350,-344.371521,0.000591,0.004758,0.120864,290.314789,14.789339,1.208638,-344.371521,294.500458,0.000000
86.750008,65.237427,-344.416016,0.000578,0.004760,0.120899,290.190582,14.783012,1.208986,-344.416016,294.500458,0.000000
87.130005,65.215820,-344.460480,0.000573,0.004760,0.120908,290.094452,14.778116,1.209077,-344.460480,294.500458,0.000000
87.510002,65.260513,-344.460480,0.000582,0.004762,0.120943,290.293274,14.788243,1.209425,-344.460480,294.500458,0.000000
87.890007,65.294022,-344.460480,0.000573,0.004764,0.120994,290.442322,14.795836,1.209940,-344.460480,294.500458,0.000000
88.270004,65.303329,-344.460480,0.000582,0.004764,0.120994,290.483704,14.797946,1.209940,-344.460480,294.500458,0.000000
88.650002,65.251572,-344.549438,0.000573,0.004764,0.121003,290.253479,14.786218,1.210031,-344.549438,294.500458,0.000000
89.030006,65.375565,-344.549438,0.000573,0.004766,0.121064,290.805023,14.814314,1.210636,-344.549438,294.500458,0.000000
89.410004,65.345779,-344.549438,0.000573,0.004766,0.121064,290.672546,14.807566,1.210636,-344.549438,294.500458,0.000000
89.790001,65.319717,-344.593933,0.000582,0.004766,0.121064,290.556610,14.801660,1.210636,-344.593933,294.500458,0.000000
90.170006,65.270187,-344.638397,0.000573,0.004766,0.121064,290.336304,14.790436,1.210636,-344.638397,294.500458,0.000000
90.550003,65.228851,-344.682892,0.000582,0.004766,0.121064,290.152435,14.781069,1.210636,-344.682892,294.500458,0.000000
90.930008,65.418762,-344.682892,0.000578,0.004770,0.121159,290.997192,14.824103,1.211590,-344.682892,294.500458,0.000000
91.310005,65.423233,-344.638397,0.000582,0.004770,0.121159,291.017090,14.825116,1.211590,-344.638397,294.500458,0.000000
91.690002,65.371109,-344.638397,0.000586,0.004770,0.121159,290.785217,14.813306,1.211590,-344.638397,294.500458,0.000000
92.070007,65.329773,-344.727356,0.000582,0.004770,0.121159,290.601349,14.803939,1.211590,-344.727356,294.500458,0.000000
92.450005,65.302582,-344.771851,0.000582,0.004770,0.121159,290.480377,14.797776,1.211590,-344.771851,294.500458,0.000000
92.830002,65.260132,-344.727356,0.000578,0.004770,0.121159,290.291565,14.788157,1.211590,-344.727356,294.500458,0.000000
93.210007,65.214706,-344.816345,0.000578,0.004770,0.121159,290.089508,14.777864,1.211590,-344.816345,294.500458,0.000000
93.590004,65.173370,-344.816345,0.000586,0.004771,0.121185,289.905640,14.768497,1.211848,-344.816345,294.500458,0.000000
93.970001,65.216568,-344.816345,0.000582,0.004772,0.121212,290.097778,14.778286,1.212120,-344.816345,294.500458,0.000000
94.350006,65.205399,-344.905304,0.000573,0.004772,0.121212,290.048096,14.775755,1.212120,-344.905304,294.500458,0.000000
94.730003,65.179703,-344.860809,0.000591,0.004772,0.121212,289.933807,14.769932,1.212120,-344.860809,294.500458,0.000000
95.110008,65.158478,-344.905304,0.000591,0.004773,0.121238,289.839386,14.765121,1.212378,-344.905304,294.500458,0.000000
95.490005,65.180069,-344.994263,0.000586,0.004773,0.121238,289.935425,14.770015,1.212378,-344.994263,294.500458,0.000000
95.870003,65.145065,-344.994263,0.000591,0.004773,0.121247,289.779724,14.762082,1.212468,-344.994263,294.500458,0.000000
96.250008,65.132416,-344.949768,0.000578,0.004775,0.121289,289.723450,14.759216,1.212892,-344.949768,294.500458,0.000000
96.630005,65.233704,-345.038727,0.000591,0.004775,0.121289,290.174011,14.782168,1.212892,-345.038727,294.500458,0.000000
97.010002,65.212097,-344.949768,0.000582,0.004775,0.121289,290.077881,14.777272,1.212892,-344.949768,294.500458,0.000000
97.390007,65.190506,-345.083221,0.000595,0.004775,0.121289,289.981842,14.772380,1.212892,-345.083221,294.500458,0.000000
97.770004,65.167419,-345.127686,0.000591,0.004775,0.121289,289.879150,14.767148,1.212892,-345.127686,294.500458,0.000000
98.150002,65.109695,-345.127686,0.000582,0.004776,0.121315,289.622375,14.754068,1.213150,-345.127686,294.500458,0.000000
98.530006,65.194595,-345.083221,0.000595,0.004778,0.121350,290.000031,14.773306,1.213498,-345.083221,294.500458,0.000000
98.910004,65.198318,-345.083221,0.000599,0.004778,0.121350,290.016602,14.774151,1.213498,-345.083221,294.500458,0.000000
99.290001,65.217316,-345.172180,0.000599,0.004778,0.121350,290.101105,14.778456,1.213498,-345.172180,294.500458,0.000000
99.670006,65.182312,-345.216675,0.000591,0.004778,0.121350,289.945404,14.770522,1.213498,-345.216675,294.500458,0.000000
100.050003,65.161453,-345.216675,0.000591,0.004778,0.121350,289.852631,14.765797,1.213498,-345.216675,294.500458,0.000000
100.430008,65.125702,-345.261139,0.000608,0.004778,0.121350,289.693604,14.757695,1.213498,-345.261139,294.500458,0.000000
100.810005,65.105606,-345.305634,0.000591,0.004778,0.121350,289.604187,14.753141,1.213498,-345.305634,294.500458,0.000000
101.190002,65.056442,-345.305634,0.000595,0.004778,0.121350,289.385498,14.742001,1.213498,-345.305634,294.500458,0.000000
101.570007,65.044525,-345.394592,0.000599,0.004778,0.121350,289.332489,14.739301,1.213498,-345.394592,294.500458,0.000000
101.950005,65.021072,-345.350098,0.000586,0.004778,0.121350,289.228180,14.733986,1.213498,-345.350098,294.500458,0.000000
102.330002,64.993881,-345.350098,0.000599,0.004778,0.121359,289.107208,14.727824,1.213589,-345.350098,294.500458,0.000000
102.710007,65.065750,-345.394592,0.000604,0.004782,0.121463,289.426910,14.744110,1.214633,-345.394592,294.500458,0.000000
103.090004,65.466797,-345.439056,0.000599,0.004784,0.121506,291.210846,14.834989,1.215057,-345.439056,294.500458,0.000000
103.470001,65.478348,-345.439056,0.000608,0.004784,0.121506,291.262238,14.837605,1.215057,-345.439056,294.500458,0.000000
103.850006,65.450043,-345.394592,0.000608,0.004784,0.121506,291.136322,14.831192,1.215057,-345.394592,294.500458,0.000000
104.230003,65.471268,-345.439056,0.000599,0.004784,0.121506,291.230743,14.836001,1.215057,-345.439056,294.500458,0.000000
104.610008,65.419876,-345.483551,0.000604,0.004784,0.121506,291.002136,14.824356,1.215057,-345.483551,294.500458,0.000000
104.990005,65.417282,-345.528015,0.000608,0.004784,0.121506,290.990601,14.823769,1.215057,-345.528015,294.500458,0.000000
105.370003,65.382645,-345.528015,0.000586,0.004784,0.121506,290.836517,14.815919,1.215057,-345.528015,294.500458,0.000000
105.750008,65.377060,-345.528015,0.000591,0.004784,0.121506,290.811676,14.814653,1.215057,-345.528015,294.500458,0.000000
106.130005,65.371841,-345.572510,0.000612,0.004784,0.121506,290.788483,14.813471,1.215057,-345.572510,294.500458,0.000000
106.510002,65.360672,-345.661469,0.000595,0.004784,0.121515,290.738800,14.810940,1.215148,-345.661469,294.500458,0.000000
106.890007,65.342804,-345.617004,0.000595,0.004784,0.121515,290.659302,14.806890,1.215148,-345.617004,294.500458,0.000000
107.270004,65.323059,-345.661469,0.000595,0.004784,0.121515,290.571472,14.802417,1.215148,-345.661469,294.500458,0.000000
107.650002,65.324921,-345.617004,0.000595,0.004784,0.121515,290.579773,14.802838,1.215148,-345.617004,294.500458,0.000000
108.030006,65.304077,-345.617004,0.000591,0.004784,0.121515,290.487030,14.798116,1.215148,-345.617004,294.500458,0.000000
108.410004,65.299606,-345.750427,0.000604,0.004784,0.121515,290.467163,14.797102,1.215148,-345.750427,294.500458,0.000000
108.790009,65.267212,-345.750427,0.000604,0.004784,0.121524,290.323059,14.789762,1.215239,-345.750427,294.500458,0.000000
109.170006,65.261993,-345.750427,0.000599,0.004784,0.121524,290.299835,14.788579,1.215239,-345.750427,294.500458,0.000000
109.550003,65.248962,-345.750427,0.000595,0.004784,0.121524,290.241882,14.785626,1.215239,-345.750427,294.500458,0.000000
109.930008,65.231094,-345.839386,0.000591,0.004784,0.121524,290.162415,14.781577,1.215239,-345.839386,294.500458,0.000000
110.310005,65.210617,-345.839386,0.000599,0.004784,0.121524,290.071320,14.776937,1.215239,-345.839386,294.500458,0.000000
110.690002,65.193115,-345.839386,0.000599,0.004784,0.121524,289.993469,14.772971,1.215239,-345.839386,294.500458,0.000000
111.070007,65.181198,-345.839386,0.000599,0.004784,0.121524,289.940460,14.770271,1.215239,-345.839386,294.500458,0.000000
111.450005,65.162201,-345.839386,0.000595,0.004784,0.121524,289.855957,14.765966,1.215239,-345.839386,294.500458,0.000000
111.830002,65.169647,-345.928345,0.000599,0.004785,0.121541,289.889069,14.767653,1.215405,-345.928345,294.500458,0.000000
112.210007,65.136139,-346.017303,0.000599,0.004785,0.121541,289.740021,14.760059,1.215405,-346.017303,294.500458,0.000000
112.590004,65.138748,-346.017303,0.000599,0.004785,0.121541,289.751617,14.760652,1.215405,-346.017303,294.500458,0.000000
112.970009,65.104858,-345.928345,0.000595,0.004785,0.121541,289.600861,14.752973,1.215405,-345.928345,294.500458,0.000000
113.350006,65.406479,-345.972839,0.000591,0.004790,0.121671,290.942535,14.821320,1.216707,-345.972839,294.500458,0.000000
113.730003,65.476486,-346.061798,0.000612,0.004790,0.121671,291.253967,14.837184,1.216707,-346.061798,294.500458,0.000000
114.110008,65.506653,-346.061798,0.000591,0.004790,0.121671,291.388153,14.844020,1.216707,-346.061798,294.500458,0.000000
114.490005,65.502182,-346.061798,0.000595,0.004790,0.121662,291.368256,14.843006,1.216617,-346.061798,294.500458,0.000000
114.870003,65.493240,-346.061798,0.000591,0.004790,0.121662,291.328491,14.840981,1.216617,-346.061798,294.500458,0.000000
115.250008,65.497330,-346.017303,0.000608,0.004790,0.121662,291.346680,14.841908,1.216617,-346.017303,294.500458,0.000000
115.630005,65.491013,-346.106293,0.000608,0.004790,0.121662,291.318573,14.840475,1.216617,-346.106293,294.500458,0.000000
116.010002,65.477600,-346.150757,0.000595,0.004790,0.121662,291.258911,14.837436,1.216617,-346.150757,294.500458,0.000000
116.390007,65.469788,-346.150757,0.000599,0.004790,0.121662,291.224152,14.835666,1.216617,-346.150757,294.500458,0.000000
116.770004,65.463074,-346.150757,0.000604,0.004790,0.121662,291.194305,14.834145,1.216617,-346.150757,294.500458,0.000000
117.150009,65.445953,-346.195251,0.000612,0.004790,0.121662,291.118134,14.830265,1.216617,-346.195251,294.500458,0.000000
117.530006,65.438507,-346.239716,0.000612,0.004790,0.121662,291.085022,14.828578,1.216617,-346.239716,294.500458,0.000000
117.910004,65.412811,-346.328674,0.000604,0.004790,0.121662,290.970703,14.822755,1.216617,-346.328674,294.500458,0.000000
118.290009,65.402756,-346.284210,0.000595,0.004790,0.121662,290.925995,14.820477,1.216617,-346.284210,294.500458,0.000000
118.670006,65.377060,-346.328674,0.000608,0.004790,0.121662,290.811676,14.814653,1.216617,-346.328674,294.500458,0.000000
119.050003,65.374451,-346.328674,0.000608,0.004790,0.121662,290.800079,14.814062,1.216617,-346.328674,294.500458,0.000000
119.430008,65.356201,-346.328674,0.000599,0.004790,0.121662,290.718903,14.809927,1.216617,-346.328674,294.500458,0.000000
119.810005,65.349503,-346.417633,0.000586,0.004790,0.121662,290.689117,14.808409,1.216617,-346.417633,294.500458,0.000000
120.190002,65.335724,-346.417633,0.000595,0.004790,0.121671,290.627808,14.805286,1.216707,-346.417633,294.500458,0.000000
120.570007,65.345413,-346.417633,0.000617,0.004790,0.121671,290.670929,14.807483,1.216707,-346.417633,294.500458,0.000000
120.950005,65.315613,-346.417633,0.000608,0.004790,0.121671,290.538361,14.800730,1.216707,-346.417633,294.500458,0.000000
121.330009,65.307053,-346.506622,0.000599,0.004790,0.121671,290.500275,14.798789,1.216707,-346.506622,294.500458,0.000000
121.710007,65.279495,-346.462128,0.000599,0.004790,0.121671,290.377686,14.792545,1.216707,-346.462128,294.500458,0.000000
122.090004,65.281357,-346.506622,0.000599,0.004790,0.121671,290.385986,14.792967,1.216707,-346.506622,294.500458,0.000000
122.470009,65.263855,-346.506622,0.000599,0.004790,0.121671,290.308136,14.789001,1.216707,-346.506622,294.500458,0.000000
122.850006,65.248962,-346.551086,0.000608,0.004790,0.121671,290.241882,14.785626,1.216707,-346.551086,294.500458,0.000000
123.230003,65.230347,-346.640045,0.000608,0.004790,0.121671,290.159088,14.781407,1.216707,-346.640045,294.500458,0.000000
123.610008,65.224014,-346.595581,0.000604,0.004790,0.121671,290.130920,14.779973,1.216707,-346.595581,294.500458,0.000000
123.990005,65.208374,-346.595581,0.000604,0.004790,0.121671,290.061340,14.776429,1.216707,-346.595581,294.500458,0.000000
124.370003,65.206879,-346.595581,0.000612,0.004790,0.121671,290.054687,14.776090,1.216707,-346.595581,294.500458,0.000000
124.750008,65.183426,-346.640045,0.000617,0.004790,0.121671,289.950348,14.770775,1.216707,-346.640045,294.500458,0.000000
125.130005,65.174866,-346.684540,0.000595,0.004790,0.121671,289.912292,14.768836,1.216707,-346.684540,294.500458,0.000000
125.510010,65.143204,-346.684540,0.000604,0.004790,0.121671,289.771454,14.761662,1.216707,-346.684540,294.500458,0.000000
125.890007,65.148422,-346.684540,0.000612,0.004790,0.121671,289.794647,14.762843,1.216707,-346.684540,294.500458,0.000000
126.270004,65.126450,-346.773499,0.000599,0.004790,0.121671,289.696930,14.757865,1.216707,-346.773499,294.500458,0.000000
126.650009,65.116028,-346.817963,0.000612,0.004791,0.121680,289.650543,14.755503,1.216798,-346.817963,294.500458,0.000000
127.030006,65.091080,-346.817963,0.000608,0.004791,0.121680,289.539581,14.749849,1.216798,-346.817963,294.500458,0.000000
127.410004,65.095551,-346.729004,0.000591,0.004791,0.121680,289.559479,14.750862,1.216798,-346.729004,294.500458,0.000000
127.790009,65.065384,-346.817963,0.000608,0.004791,0.121680,289.425293,14.744026,1.216798,-346.817963,294.500458,0.000000
128.170013,65.064270,-346.773499,0.000612,0.004791,0.121680,289.420319,14.743774,1.216798,-346.773499,294.500458,0.000000
128.550003,65.054581,-346.862457,0.000591,0.004791,0.121680,289.377228,14.741579,1.216798,-346.862457,294.500458,0.000000
128.930008,65.044159,-346.906952,0.000591,0.004791,0.121680,289.330872,14.739217,1.216798,-346.906952,294.500458,0.000000
129.310013,65.036346,-346.862457,0.000595,0.004792,0.121706,289.296112,14.737447,1.217056,-346.862457,294.500458,0.000000
129.690002,65.047882,-346.906952,0.000608,0.004792,0.121706,289.347443,14.740061,1.217056,-346.906952,294.500458,0.000000
130.070007,65.036346,-346.995911,0.000608,0.004792,0.121706,289.296112,14.737447,1.217056,-346.995911,294.500458,0.000000
130.450012,65.037827,-347.040375,0.000608,0.004792,0.121706,289.302704,14.737782,1.217056,-347.040375,294.500458,0.000000
130.830002,65.018845,-347.040375,0.000604,0.004792,0.121706,289.218262,14.733480,1.217056,-347.040375,294.500458,0.000000
131.210007,65.027771,-346.951416,0.000608,0.004792,0.121706,289.257965,14.735503,1.217056,-346.951416,294.500458,0.000000
131.590012,65.014740,-346.995911,0.000612,0.004792,0.121706,289.200012,14.732551,1.217056,-346.995911,294.500458,0.000000
131.970001,65.006546,-347.084869,0.000612,0.004792,0.121706,289.163544,14.730694,1.217056,-347.084869,294.500458,0.000000
132.350006,65.005798,-347.129333,0.000604,0.004792,0.121706,289.160248,14.730524,1.217056,-347.129333,294.500458,0.000000
132.730011,65.008789,-347.084869,0.000599,0.004792,0.121706,289.173523,14.731202,1.217056,-347.084869,294.500458,0.000000
133.110001,64.999481,-347.084869,0.000599,0.004792,0.121706,289.132141,14.729094,1.217056,-347.084869,294.500458,0.000000
133.490005,64.995377,-347.040375,0.000612,0.004792,0.121715,289.113861,14.728163,1.217147,-347.040375,294.500458,0.000000
133.870010,64.995377,-347.218292,0.000617,0.004792,0.121715,289.113861,14.728163,1.217147,-347.218292,294.500458,0.000000
134.250000,64.980850,-347.218292,0.000604,0.004792,0.121715,289.049255,14.724871,1.217147,-347.218292,294.500458,0.000000
134.630005,64.995010,-347.173828,0.000604,0.004792,0.121715,289.112244,14.728080,1.217147,-347.173828,294.500458,0.000000
135.010010,64.970795,-347.262787,0.000621,0.004792,0.121715,289.004517,14.722592,1.217147,-347.262787,294.500458,0.000000
135.389999,64.961121,-347.262787,0.000612,0.004792,0.121715,288.961487,14.720401,1.217147,-347.262787,294.500458,0.000000
135.770004,64.964478,-347.307251,0.000617,0.004792,0.121715,288.976440,14.721162,1.217147,-347.307251,294.500458,0.000000
136.150009,64.948090,-347.262787,0.000595,0.004792,0.121715,288.903534,14.717447,1.217147,-347.262787,294.500458,0.000000
136.530014,64.947342,-347.307251,0.000599,0.004792,0.121715,288.900208,14.717278,1.217147,-347.307251,294.500458,0.000000
136.910004,64.942505,-347.307251,0.000599,0.004792,0.121715,288.878693,14.716182,1.217147,-347.307251,294.500458,0.000000
137.290009,64.942123,-347.351746,0.000608,0.004792,0.121724,288.876984,14.716096,1.217237,-347.351746,294.500458,0.000000
137.670013,64.918671,-347.396240,0.000612,0.004792,0.121724,288.772675,14.710781,1.217237,-347.396240,294.500458,0.000000
138.050003,64.917557,-347.396240,0.000599,0.004792,0.121724,288.767700,14.710528,1.217237,-347.396240,294.500458,0.000000
138.430008,64.898941,-347.440704,0.000595,0.004792,0.121724,288.684906,14.706310,1.217237,-347.440704,294.500458,0.000000
138.810013,64.907501,-347.396240,0.000604,0.004792,0.121724,288.722992,14.708250,1.217237,-347.396240,294.500458,0.000000
139.190002,64.886642,-347.440704,0.000612,0.004792,0.121724,288.630188,14.703523,1.217237,-347.440704,294.500458,0.000000
139.570007,64.982712,-347.529663,0.000617,0.004795,0.121792,289.057526,14.725293,1.217919,-347.529663,294.500458,0.000000
139.950012,65.006546,-347.485199,0.000612,0.004795,0.121792,289.163544,14.730694,1.217919,-347.485199,1681.640747,0.000000
140.330002,64.979370,-347.529663,0.000608,0.004785,0.121550,289.042664,14.724536,1.215496,-347.529663,0.121376,0.000000
140.710007,64.948090,-347.529663,0.000617,0.004768,0.121117,288.903534,14.717447,1.211166,-347.529663,0.120743,0.000000
141.090012,64.844940,-347.574158,0.000625,0.004750,0.120647,288.444702,14.694074,1.206473,-347.574158,0.120110,0.000000
141.470001,64.841965,-347.663116,0.000617,0.004729,0.120119,288.431458,14.693399,1.201189,-347.663116,0.119477,0.000000
141.850006,64.852386,-347.663116,0.000625,0.004696,0.119286,288.477814,14.695761,1.192863,-347.663116,0.118844,0.000000
142.230011,64.800629,-347.618622,0.000617,0.004675,0.118749,288.247589,14.684032,1.187488,-347.618622,0.118211,0.000000
142.610001,64.776047,-347.663116,0.000621,0.004648,0.118063,288.138245,14.678462,1.180630,-347.663116,0.117577,0.000000
142.990005,64.765991,-347.707581,0.000621,0.004629,0.117577,288.093506,14.676184,1.175770,-347.707581,0.116944,0.000000
143.370010,64.733597,-347.796570,0.000612,0.004605,0.116979,287.949432,14.668842,1.169790,-347.796570,0.116311,0.000000
143.750000,64.686676,-347.707581,0.000621,0.004581,0.116364,287.740692,14.658210,1.163643,-347.707581,0.115678,0.000000
144.130005,64.630081,-347.707581,0.000608,0.004560,0.115825,287.488953,14.645386,1.158254,-347.707581,0.115046,0.000000
144.510010,64.496399,-347.752075,0.000625,0.004538,0.115271,286.894318,14.615093,1.152712,-347.752075,0.114413,0.000000
144.889999,63.404602,-347.841034,0.000629,0.004506,0.114455,282.037750,14.367688,1.144552,-347.841034,0.113780,0.000000
145.270004,62.508301,-347.841034,0.000638,0.004485,0.113927,278.050812,14.164583,1.139269,-347.841034,0.113146,0.000000
145.650009,61.094032,-347.841034,0.000621,0.004461,0.113302,271.759827,13.844105,1.133016,-347.841034,0.112513,0.000000
146.030014,59.527458,-347.841034,0.000625,0.004438,0.112729,264.791351,13.489115,1.127293,-347.841034,0.111880,0.000000
146.410004,57.918816,-347.841034,0.000634,0.004420,0.112271,257.635773,13.124591,1.122706,-347.841034,0.111247,0.000000
146.790009,55.615318,-347.929993,0.000642,0.004392,0.111568,247.389297,12.602612,1.115681,-347.929993,0.110614,0.000000
147.170013,53.339745,-347.974487,0.000638,0.004371,0.111012,237.267029,12.086959,1.110125,-347.974487,0.109981,0.000000
147.550003,50.713776,-347.929993,0.000629,0.004344,0.110345,225.586136,11.491906,1.103448,-347.929993,0.109347,0.000000
147.930008,48.474701,-347.974487,0.000629,0.004326,0.109868,215.626236,10.984524,1.098679,-347.974487,0.108714,0.000000
148.310013,45.261497,-348.018951,0.000634,0.004296,0.109122,201.333191,10.256402,1.091215,-348.018951,0.108081,0.000000
148.690002,42.975502,-348.063446,0.000647,0.004276,0.108619,191.164581,9.738388,1.086189,-348.063446,0.107449,0.000000
149.070007,39.546326,-348.018951,0.000621,0.004244,0.107786,175.910843,8.961326,1.077862,-348.018951,0.106816,0.000000
149.450012,37.087181,-348.018951,0.000642,0.004221,0.107223,164.972015,8.404076,1.072230,-348.018951,0.106183,0.000000
149.830002,34.488022,-348.063446,0.000647,0.004200,0.106677,153.410385,7.815097,1.066765,-348.063446,0.105549,0.000000
150.210007,31.708633,-348.107910,0.000634,0.004173,0.105983,141.047043,7.185279,1.059831,-348.107910,0.104916,0.000000
150.590012,28.611984,-348.152405,0.000634,0.004142,0.105211,127.272461,6.483568,1.052110,-348.152405,0.104283,0.000000
150.970001,26.566170,-348.107910,0.000625,0.004124,0.104760,118.172226,6.019980,1.047598,-348.107910,0.103641,0.000000
151.350006,23.055809,-348.152405,0.000612,0.004095,0.104015,102.557358,5.224521,1.040150,-348.152405,0.103008,0.000000
151.730011,20.433197,-348.152405,0.000625,0.004073,0.103443,90.891403,4.630229,1.034427,-348.152405,0.102375,0.000000
152.110001,18.311790,-348.241364,0.000617,0.004053,0.102939,81.454910,4.149511,1.029385,-348.241364,0.101743,0.000000
152.490005,13.979607,-348.241364,0.000617,0.004014,0.101950,62.184395,3.167824,1.019499,-348.241364,0.101110,0.000000
152.870010,12.255898,-348.241364,0.000617,0.003999,0.101577,54.516956,2.777226,1.015775,-348.241364,0.100475,0.000000
153.250000,9.911064,-348.241364,0.000608,0.003977,0.101005,44.086617,2.245879,1.010052,-348.241364,0.099842,0.000000
153.630005,7.514847,-348.330322,0.000608,0.003957,0.100519,33.427708,1.702889,1.005192,-348.330322,0.099210,0.000000
154.010010,4.293457,-348.330322,0.000604,0.003924,0.099677,19.098251,0.972911,0.996775,-348.330322,0.098577,0.000000
154.390015,0.875816,-348.374817,0.000608,0.003893,0.098880,3.895826,0.198463,0.988796,-348.374817,0.097944,0.000000
154.770004,-0.439400,-348.330322,0.000617,0.003877,0.098472,-1.954548,-0.099569,0.984724,-348.330322,0.097311,0.000000
155.150009,-0.346306,-348.285858,0.000578,0.003849,0.097770,-1.540445,-0.078474,0.977699,-348.285858,0.096678,0.000000
155.530014,-0.256569,-348.374817,0.000539,0.003821,0.097042,-1.141276,-0.058139,0.970417,-348.374817,0.096044,0.000000
155.910004,-0.033142,-348.419281,0.000474,0.003797,0.096444,-0.147423,-0.007510,0.964437,-348.419281,0.095411,0.000000
156.290009,-0.013405,-348.419281,0.000440,0.003782,0.096062,-0.059628,-0.003038,0.960621,-348.419281,0.094778,0.000000
156.670013,0.014893,-348.463776,0.000362,0.003749,0.095220,0.066245,0.003375,0.952204,-348.463776,0.094145,0.000000
157.050003,0.004097,-348.463776,0.000315,0.003724,0.094597,0.018224,0.000928,0.945966,-348.463776,0.093513,0.000000
157.430008,0.032394,-348.552734,0.000250,0.003698,0.093937,0.144098,0.007341,0.939366,-348.552734,0.092880,0.000000
157.810013,-0.002983,-348.552734,0.000185,0.003674,0.093322,-0.013269,-0.000676,0.933219,-348.552734,0.092245,0.000000
158.190002,0.013405,-348.552734,0.000125,0.003652,0.092757,0.059628,0.003038,0.927572,-348.552734,0.091613,0.000000
158.570007,0.033516,-348.597198,0.000056,0.003626,0.092090,0.149086,0.007595,0.920895,-348.597198,0.090980,0.000000
158.950012,0.045059,-348.597198,0.000000,0.003605,0.091578,0.200433,0.010211,0.915778,-348.597198,0.090347,0.000000
159.100006,0.125862,-348.597198,-0.000030,0.003609,0.091673,0.559863,0.028521,0.916732,-348.597198,0.091578,0.000000