File: Data/type 1 compression/Support type 1-3 - same point_04162024_185949.csv
Time (sec),S:Load (lbs),S:HL1 (DIM),S:LVDT (in),S:Position (in),Ch:Position (mm),Ch:Load (N),Ch:Stress (MPa),Ch:Strain (mm/mm),Ch:HL1 (DIM),Set Point (),Cycles ()
0.110000,-0.006699,-175.922165,0.000000,-0.000000,-0.000000,-0.029797,-0.001518,-0.000000,-175.922165,0.000208,0.000000
0.250000,-0.004463,-176.011124,-0.000004,-0.000000,-0.000000,-0.019853,-0.001011,-0.000000,-176.011124,0.000208,0.000000
0.390000,-0.023453,-176.011124,-0.000009,0.000001,0.000026,-0.104323,-0.005314,0.000265,-176.011124,0.000451,0.000000
0.530000,-0.009682,-176.011124,0.000000,0.000078,0.001969,-0.043066,-0.002194,0.019689,-176.011124,0.002792,0.000000
0.670000,-0.020477,-176.011124,0.000017,0.000161,0.004085,-0.091088,-0.004640,0.040847,-176.011124,0.005116,0.000000
0.810000,-0.068138,-176.011124,0.000091,0.000251,0.006375,-0.303093,-0.015440,0.063745,-176.011124,0.007459,0.000000
0.950000,0.019363,-176.011124,0.000190,0.000339,0.008611,0.086133,0.004388,0.086114,-176.011124,0.009782,0.000000
1.090000,0.015640,-176.011124,0.000267,0.000424,0.010763,0.069571,0.003544,0.107627,-176.011124,0.012124,0.000000
1.230000,-0.000000,-176.100082,0.000371,0.000524,0.013321,-0.000000,-0.000000,0.133206,-176.100082,0.014448,0.000000
1.370000,0.014526,-176.144562,0.000466,0.000622,0.015801,0.064617,0.003292,0.158012,-176.144562,0.016790,0.000000
1.510000,0.034264,-176.100082,0.000548,0.000704,0.017882,0.152412,0.007764,0.178821,-176.100082,0.019114,0.000000
1.650000,0.014526,-176.144562,0.000638,0.000801,0.020345,0.064617,0.003292,0.203453,-176.144562,0.021455,0.000000
1.790000,0.018250,-176.100082,0.000742,0.000891,0.022626,0.081178,0.004135,0.226261,-176.100082,0.023780,0.000000
1.930000,0.020485,-176.189041,0.000832,0.000988,0.025098,0.091121,0.004642,0.250976,-176.189041,0.026121,0.000000
2.070000,0.022346,-176.189041,0.000927,0.001071,0.027213,0.099402,0.005064,0.272134,-176.189041,0.028445,0.000000
2.210000,0.009315,-176.278015,0.001018,0.001168,0.029668,0.041437,0.002111,0.296683,-176.278015,0.030769,0.000000
2.350000,-0.038353,-176.278015,0.001104,0.001262,0.032053,-0.170603,-0.008691,0.320528,-176.278015,0.033111,0.000000
2.490000,-0.001862,-176.233521,0.001199,0.001348,0.034246,-0.008281,-0.000422,0.342465,-176.233521,0.035435,0.000000
2.630000,0.013779,-176.322495,0.001293,0.001444,0.036675,0.061291,0.003122,0.366749,-176.322495,0.037776,0.000000
2.770000,-0.052132,-176.322495,0.001393,0.001532,0.038913,-0.231893,-0.011813,0.389125,-176.322495,0.040101,0.000000
2.910000,-0.003723,-176.278015,0.001483,0.001631,0.041419,-0.016561,-0.000844,0.414189,-176.278015,0.042442,0.000000
3.050000,0.047668,-176.366974,0.001569,0.001713,0.043517,0.212040,0.010802,0.435172,-176.366974,0.044766,0.000000
3.190000,0.015640,-176.322495,0.001669,0.001810,0.045963,0.069571,0.003544,0.459630,-176.322495,0.047108,0.000000
3.330000,-0.002602,-176.411453,0.001755,0.001901,0.048296,-0.011573,-0.000590,0.482960,-176.411453,0.049432,0.000000
3.470000,0.042084,-176.366974,0.001876,0.002002,0.050855,0.187198,0.009536,0.508546,-176.366974,0.051774,0.000000
3.610000,0.042824,-176.411453,0.001949,0.002086,0.052988,0.190490,0.009704,0.529878,-176.411453,0.054098,0.000000
3.750000,0.007820,-176.500412,0.002052,0.002180,0.055381,0.034786,0.001772,0.553813,-176.500412,0.056439,0.000000
3.890000,0.027184,-176.411453,0.002147,0.002274,0.057748,0.120918,0.006160,0.577484,-176.411453,0.058764,0.000000
4.030000,0.027557,-176.500412,0.002238,0.002365,0.060081,0.122581,0.006245,0.600814,-176.500412,0.061105,0.000000
4.170000,0.009682,-176.455933,0.002333,0.002458,0.062432,0.043066,0.002194,0.624318,-176.455933,0.063429,0.000000
4.310000,-0.005211,-176.500412,0.002414,0.002544,0.064617,-0.023179,-0.001181,0.646172,-176.500412,0.065771,0.000000
4.450000,-0.001114,-176.500412,0.002518,0.002641,0.067089,-0.004955,-0.000252,0.670888,-176.500412,0.068095,0.000000
4.590000,0.020485,-176.500412,0.002596,0.002727,0.069274,0.091121,0.004642,0.692742,-176.500412,0.070419,0.000000
4.730000,-0.010422,-176.589371,0.002695,0.002819,0.071607,-0.046358,-0.002362,0.716072,-176.589371,0.072760,0.000000
4.870000,-0.051010,-176.544891,0.002790,0.002914,0.074009,-0.226904,-0.011559,0.740091,-176.544891,0.075085,0.000000
5.010000,0.004471,-176.589371,0.002867,0.002997,0.076134,0.019887,0.001013,0.761339,-176.589371,0.077426,0.000000
5.150000,0.031281,-176.589371,0.002984,0.003095,0.078605,0.139143,0.007088,0.786055,-176.589371,0.079750,0.000000
5.290000,0.014153,-176.589371,0.003065,0.003187,0.080947,0.062954,0.003207,0.809468,-176.589371,0.082091,0.000000
5.430000,0.028679,-176.678345,0.003169,0.003281,0.083349,0.127570,0.006499,0.833494,-176.678345,0.084416,0.000000
5.570000,0.067406,-176.633850,0.003251,0.003372,0.085656,0.299836,0.015274,0.856560,-176.633850,0.086757,0.000000
5.710000,0.035751,-176.678345,0.003354,0.003472,0.088188,0.159030,0.008101,0.881881,-176.678345,0.089081,0.000000
5.850000,0.006332,-176.722824,0.003432,0.003557,0.090356,0.028168,0.001435,0.903560,-176.722824,0.091423,0.000000
5.990000,0.045433,-176.678345,0.003527,0.003657,0.092889,0.202096,0.010295,0.928889,-176.678345,0.093747,0.000000
6.130000,0.031281,-176.722824,0.003622,0.003740,0.095005,0.139143,0.007088,0.950046,-176.722824,0.096089,0.000000
6.270000,0.005219,-176.678345,0.003721,0.003829,0.097260,0.023213,0.001183,0.972597,-176.678345,0.098413,0.000000
6.410000,0.005959,-176.767303,0.003816,0.003928,0.099766,0.026505,0.001350,0.997660,-176.767303,0.100755,0.000000
6.550000,0.024582,-176.767303,0.003906,0.004015,0.101986,0.109346,0.005570,1.019855,-176.767303,0.103079,0.000000
6.690001,0.017502,-176.811783,0.003992,0.004109,0.104371,0.077852,0.003966,1.043707,-176.811783,0.105420,0.000000
6.830000,-0.040215,-176.811783,0.004079,0.004199,0.106660,-0.178883,-0.009113,1.066599,-176.811783,0.107745,0.000000
6.970000,0.011177,-176.811783,0.004191,0.004291,0.108985,0.049718,0.002533,1.089845,-176.811783,0.110086,0.000000
7.110000,0.033890,-176.856262,0.004260,0.004379,0.111222,0.150749,0.007680,1.112222,-176.856262,0.112410,0.000000
7.250000,-0.013771,-176.900742,0.004355,0.004471,0.113554,-0.061257,-0.003121,1.135544,-176.900742,0.114734,0.000000
7.390000,0.010429,-176.900742,0.004454,0.004567,0.116009,0.046392,0.002363,1.160085,-176.900742,0.117076,0.000000
7.530000,0.028305,-176.900742,0.004544,0.004658,0.118324,0.125907,0.006414,1.183241,-176.900742,0.119400,0.000000
7.670001,0.025322,-176.900742,0.004644,0.004752,0.120692,0.112638,0.005738,1.206920,-176.900742,0.121741,0.000000
7.810000,0.008194,-176.945221,0.004738,0.004848,0.123138,0.036449,0.001857,1.231378,-176.945221,0.124065,0.000000
7.950000,0.065170,-176.945221,0.004820,0.004937,0.125392,0.289892,0.014768,1.253921,-176.945221,0.126407,0.000000
8.090000,0.049530,-176.945221,0.004894,0.005026,0.127655,0.220321,0.011224,1.276554,-176.945221,0.128731,0.000000
8.230000,0.036499,-176.989700,0.005010,0.005120,0.130058,0.162356,0.008271,1.300581,-176.989700,0.131072,0.000000
8.370001,0.001869,-176.989700,0.005113,0.005210,0.132321,0.008315,0.000424,1.323214,-176.989700,0.133397,0.000000
8.510000,0.027931,-177.078659,0.005182,0.005310,0.134871,0.124244,0.006329,1.348709,-177.078659,0.135738,0.000000
8.650001,0.040962,-177.034180,0.005290,0.005391,0.136935,0.182209,0.009282,1.369352,-177.034180,0.138062,0.000000
8.790000,0.004471,-177.034180,0.005381,0.005481,0.139216,0.019887,0.001013,1.392160,-177.034180,0.140404,0.000000
8.930000,0.007454,-177.078659,0.005476,0.005581,0.141757,0.033157,0.001689,1.417572,-177.078659,0.142728,0.000000
9.070001,0.049904,-177.078659,0.005558,0.005661,0.143786,0.221983,0.011308,1.437859,-177.078659,0.145070,0.000000
9.210000,0.045433,-177.123154,0.005652,0.005765,0.146422,0.202096,0.010295,1.464224,-177.123154,0.147394,0.000000
9.350000,0.052505,-177.167633,0.005734,0.005850,0.148590,0.233556,0.011898,1.485904,-177.167633,0.149735,0.000000
9.490001,0.197365,-177.123154,0.005833,0.005943,0.150941,0.877923,0.044724,1.509409,-177.123154,0.152060,0.000000
9.630000,0.369400,-177.167633,0.005911,0.006031,0.153196,1.643173,0.083707,1.531959,-177.167633,0.154401,0.000000
9.770000,0.672508,-177.123154,0.006006,0.006131,0.155719,2.991466,0.152393,1.557189,-177.123154,0.156725,0.000000
9.910001,0.710487,-177.167633,0.006036,-0.000002,-0.000061,3.160406,0.160999,-0.000606,-177.167633,0.000148,0.000000
10.050000,0.699692,-177.167633,0.006032,-0.000002,-0.000061,3.112385,0.158552,-0.000606,-177.167633,0.000148,0.000000
10.190001,0.639366,-177.212112,0.006023,-0.000003,-0.000069,2.844043,0.144882,-0.000689,-177.212112,0.000148,0.000000
10.330001,0.661339,-177.256592,0.006023,-0.000003,-0.000069,2.941782,0.149862,-0.000689,-177.256592,0.000217,0.000000
10.470000,0.671021,-177.212112,0.006028,-0.000002,-0.000061,2.984848,0.152055,-0.000606,-177.212112,0.000451,0.000000
10.610001,0.661713,-177.345551,0.006028,-0.000002,-0.000061,2.943445,0.149946,-0.000606,-177.345551,0.000686,0.000000
10.750001,0.698944,-177.301071,0.006036,-0.000002,-0.000061,3.109059,0.158383,-0.000606,-177.301071,0.000911,0.000000
10.890000,0.699692,-177.301071,0.006023,-0.000002,-0.000061,3.112385,0.158552,-0.000606,-177.301071,0.001145,0.000000
11.030001,0.704903,-177.301071,0.006023,-0.000002,-0.000061,3.135564,0.159733,-0.000606,-177.301071,0.001379,0.000000
11.170000,0.942848,-177.301071,0.006049,0.000032,0.000824,4.193998,0.213652,0.008244,-177.301071,0.001613,0.000000
11.310000,1.007271,-177.390030,0.006049,0.000043,0.001093,4.480564,0.228251,0.010931,-177.390030,0.001848,0.000000
11.450001,1.064613,-177.301071,0.006066,0.000052,0.001310,4.735637,0.241245,0.013096,-177.301071,0.002082,0.000000
11.590000,1.158455,-177.345551,0.006071,0.000062,0.001587,5.153065,0.262510,0.015874,-177.345551,0.002316,0.000000
11.730000,1.221016,-177.434509,0.006084,0.000072,0.001839,5.431350,0.276686,0.018387,-177.434509,0.002550,0.000000
11.870001,1.278358,-177.434509,0.006096,0.000078,0.001978,5.686422,0.289680,0.019780,-177.434509,0.002784,0.000000
12.010000,1.318947,-177.434509,0.006096,0.000086,0.002194,5.866969,0.298878,0.021945,-177.434509,0.003018,0.000000
12.150001,1.457840,-177.434509,0.006105,0.000100,0.002550,6.484796,0.330351,0.025503,-177.434509,0.003253,0.000000
12.290001,1.532318,-177.478989,0.006118,0.000108,0.002749,6.816092,0.347228,0.027493,-177.478989,0.003478,0.000000
12.430000,1.655945,-177.523483,0.006122,0.000118,0.003010,7.366011,0.375242,0.030097,-177.523483,0.003712,0.000000
12.570001,1.794098,-177.478989,0.006122,0.000128,0.003261,7.980546,0.406548,0.032611,-177.478989,0.003946,0.000000
12.710001,1.909904,-177.567963,0.006148,0.000138,0.003504,8.495680,0.432791,0.035041,-177.567963,0.004180,0.000000
12.850000,2.032410,-177.523483,0.006140,0.000146,0.003712,9.040609,0.460551,0.037122,-177.523483,0.004415,0.000000
12.990001,2.071510,-177.567963,0.006153,0.000150,0.003808,9.214538,0.469411,0.038076,-177.567963,0.004649,0.000000
13.130001,2.210403,-177.612442,0.006157,0.000158,0.004016,9.832366,0.500885,0.040158,-177.612442,0.004883,0.000000
13.270000,2.447983,-177.523483,0.006161,0.000173,0.004406,10.889172,0.554721,0.044056,-177.523483,0.005117,0.000000
13.410001,2.616669,-177.656921,0.006178,0.000183,0.004640,11.639524,0.592946,0.046403,-177.656921,0.005351,0.000000
13.550000,2.764870,-177.567963,0.006183,0.000192,0.004883,12.298755,0.626528,0.048825,-177.567963,0.005585,0.000000
13.690001,2.872482,-177.612442,0.006191,0.000198,0.005030,12.777439,0.650914,0.050301,-177.612442,0.005820,0.000000
13.830001,2.996857,-177.656921,0.006200,0.000206,0.005230,13.330685,0.679097,0.052300,-177.656921,0.006045,0.000000
13.970000,3.148041,-177.612442,0.006209,0.000215,0.005456,14.003184,0.713356,0.054555,-177.612442,0.006279,0.000000
14.110001,3.360664,-177.745880,0.006209,0.000225,0.005707,14.948981,0.761537,0.057069,-177.745880,0.006513,0.000000
14.250001,3.554298,-177.656921,0.006222,0.000234,0.005932,15.810308,0.805416,0.059324,-177.656921,0.006748,0.000000
14.390000,3.710320,-177.745880,0.006226,0.000240,0.006097,16.504326,0.840770,0.060967,-177.745880,0.006982,0.000000
14.530001,4.086792,-177.790359,0.006243,0.000256,0.006496,18.178959,0.926080,0.064956,-177.790359,0.007216,0.000000
14.670001,4.322876,-177.790359,0.006243,0.000265,0.006721,19.229113,0.979578,0.067212,-177.790359,0.007450,0.000000
14.810000,4.490074,-177.834839,0.006252,0.000272,0.006912,19.972847,1.017465,0.069120,-177.834839,0.007684,0.000000
14.950001,4.675514,-177.745880,0.006256,0.000276,0.007016,20.797726,1.059487,0.070164,-177.745880,0.007918,0.000000
15.090001,4.822975,-177.790359,0.006256,0.000284,0.007207,21.453665,1.092902,0.072072,-177.790359,0.008153,0.000000
15.230000,5.332008,-177.879318,0.006260,0.000301,0.007649,23.717958,1.208250,0.076493,-177.879318,0.008387,0.000000
15.370001,5.677193,-177.834839,0.006278,0.000312,0.007918,25.253414,1.286470,0.079180,-177.834839,0.008612,0.000000
15.510001,5.972488,-177.923798,0.006291,0.000321,0.008153,26.566956,1.353385,0.081527,-177.923798,0.008846,0.000000
15.650001,6.183990,-177.834839,0.006295,0.000328,0.008334,27.507763,1.401312,0.083343,-177.834839,0.009080,0.000000
15.790001,6.411888,-177.923798,0.006312,0.000335,0.008508,28.521503,1.452955,0.085077,-177.923798,0.009315,0.000000
15.930000,6.614456,-177.968292,0.006303,0.000343,0.008708,29.422571,1.498857,0.087075,-177.968292,0.009549,0.000000
16.070002,6.979752,-177.923798,0.006303,0.000350,0.008898,31.047485,1.581634,0.088983,-177.923798,0.009782,0.000000
16.210001,7.311539,-178.012772,0.006312,0.000359,0.009124,32.523350,1.656818,0.091239,-178.012772,0.010017,0.000000
16.350000,7.543152,-177.923798,0.006321,0.000366,0.009297,33.553616,1.709303,0.092972,-177.923798,0.010251,0.000000
16.490002,8.046227,-178.057251,0.006329,0.000378,0.009592,35.791405,1.823301,0.095917,-178.057251,0.010485,0.000000
16.630001,8.458817,-178.012772,0.006342,0.000389,0.009878,37.626694,1.916795,0.098778,-178.012772,0.010720,0.000000
16.770000,8.793953,-178.057251,0.006347,0.000396,0.010069,39.117455,1.992738,0.100686,-178.057251,0.010953,0.000000
16.910002,9.170052,-178.101730,0.006355,0.000404,0.010268,40.790428,2.077963,0.102684,-178.101730,0.011179,0.000000
17.050001,9.375229,-177.968292,0.006351,0.000410,0.010424,41.703102,2.124457,0.104244,-177.968292,0.011413,0.000000
17.190001,9.971764,-178.146210,0.006351,0.000428,0.010866,44.356621,2.259634,0.108664,-178.146210,0.011647,0.000000
17.330000,10.833061,-178.101730,0.006385,0.000440,0.011179,48.187862,2.454807,0.111791,-178.101730,0.011882,0.000000
17.470001,10.996162,-178.146210,0.006372,0.000444,0.011274,48.913372,2.491766,0.112744,-178.146210,0.012115,0.000000
17.610001,11.305603,-178.146210,0.006385,0.000452,0.011483,50.289833,2.561886,0.114826,-178.146210,0.012349,0.000000
17.750000,11.955765,-178.190689,0.006377,0.000463,0.011769,53.181896,2.709215,0.117688,-178.190689,0.012584,0.000000
17.890001,12.308403,-178.235168,0.006385,0.000472,0.011977,54.750511,2.789124,0.119769,-178.235168,0.012818,0.000000
18.030001,12.705727,-178.146210,0.006398,0.000479,0.012176,56.517895,2.879159,0.121760,-178.146210,0.013052,0.000000
18.170000,13.208427,-178.190689,0.006394,0.000487,0.012367,58.754021,2.993073,0.123668,-178.190689,0.013286,0.000000
18.310001,13.617668,-178.190689,0.006411,0.000496,0.012592,60.574413,3.085808,0.125923,-178.190689,0.013512,0.000000
18.450001,14.307297,-178.235168,0.006416,0.000509,0.012922,63.642033,3.242080,0.129224,-178.235168,0.013746,0.000000
18.590000,14.912407,-178.279648,0.006411,0.000518,0.013156,66.333702,3.379200,0.131563,-178.279648,0.013980,0.000000
18.730001,15.390160,-178.235168,0.006424,0.000525,0.013338,68.458847,3.487460,0.133380,-178.235168,0.014215,0.000000
18.870001,15.705185,-178.235168,0.006437,0.000530,0.013460,69.860153,3.558846,0.134598,-178.235168,0.014448,0.000000
19.010000,15.862328,-178.324127,0.006428,0.000536,0.013616,70.559158,3.594455,0.136158,-178.324127,0.014682,0.000000
19.150002,17.012955,-178.279648,0.006437,0.000554,0.014075,75.677399,3.855191,0.140753,-178.279648,0.014917,0.000000
19.290001,18.020226,-178.368607,0.006437,0.000568,0.014431,80.157967,4.083441,0.144310,-178.368607,0.015151,0.000000
19.430000,18.525909,-178.324127,0.006450,0.000577,0.014657,82.407364,4.198031,0.146566,-178.324127,0.015385,0.000000
19.570002,18.943336,-178.368607,0.006459,0.000584,0.014838,84.264168,4.292622,0.148383,-178.368607,0.015619,0.000000
19.710001,19.533173,-178.413101,0.006467,0.000591,0.015012,86.887894,4.426280,0.150124,-178.413101,0.015853,0.000000
19.850000,20.018005,-178.413101,0.006463,0.000600,0.015229,89.044533,4.536145,0.152289,-178.413101,0.016079,0.000000
19.990002,20.483467,-178.457581,0.006450,0.000607,0.015428,91.115013,4.641620,0.154280,-178.457581,0.016313,0.000000
20.130001,20.918396,-178.457581,0.006463,0.000613,0.015576,93.049675,4.740176,0.155756,-178.457581,0.016547,0.000000
20.270000,21.717880,-178.502060,0.006467,0.000624,0.015862,96.605957,4.921342,0.158617,-178.502060,0.016781,0.000000
20.410002,22.565033,-178.502060,0.006480,0.000635,0.016140,100.374283,5.113309,0.161395,-178.502060,0.017015,0.000000
20.550001,23.135132,-178.502060,0.006489,0.000644,0.016348,102.910210,5.242496,0.163477,-178.502060,0.017249,0.000000
20.690001,23.640442,-178.546539,0.006485,0.000652,0.016564,105.157936,5.357001,0.165642,-178.546539,0.017484,0.000000
20.830002,24.203094,-178.502060,0.006497,0.000660,0.016755,107.660744,5.484499,0.167550,-178.502060,0.017718,0.000000
20.970001,24.733727,-178.546539,0.006493,0.000667,0.016937,110.021111,5.604743,0.169374,-178.546539,0.017952,0.000000
21.110001,25.528000,-178.591019,0.006502,0.000678,0.017232,113.554214,5.784728,0.172319,-178.591019,0.018186,0.000000
21.250002,26.549042,-178.591019,0.006497,0.000693,0.017605,118.096039,6.016098,0.176051,-178.591019,0.018420,0.000000
21.390001,27.169785,-178.635498,0.006510,0.000702,0.017822,120.857239,6.156761,0.178216,-178.635498,0.018646,0.000000
21.530001,27.718666,-178.591019,0.006519,0.000709,0.018004,123.298782,6.281140,0.180040,-178.591019,0.018880,0.000000
21.670000,28.499527,-178.635498,0.006506,0.000720,0.018282,126.772224,6.458086,0.182818,-178.635498,0.019114,0.000000
21.810001,29.015640,-178.679977,0.006519,0.000725,0.018411,129.068008,6.575038,0.184112,-178.679977,0.019348,0.000000
21.950001,29.518715,-178.635498,0.006519,0.000732,0.018602,131.305801,6.689036,0.186020,-178.635498,0.019582,0.000000
22.090000,30.241119,-178.768936,0.006519,0.000743,0.018871,134.519211,6.852736,0.188715,-178.768936,0.019816,0.000000
22.230001,30.602318,-178.635498,0.006532,0.000746,0.018949,136.125916,6.934584,0.189495,-178.635498,0.020051,0.000000
22.370001,31.941368,-178.768936,0.006528,0.000763,0.019392,142.082306,7.238018,0.193915,-178.768936,0.020285,0.000000
22.510000,32.631744,-178.768936,0.006541,0.000774,0.019652,145.153244,7.394459,0.196519,-178.768936,0.020519,0.000000
22.650002,33.133331,-178.724457,0.006536,0.000778,0.019773,147.384415,7.508121,0.197730,-178.724457,0.020753,0.000000
22.790001,33.649071,-178.857910,0.006536,0.000786,0.019964,149.678543,7.624989,0.199638,-178.857910,0.020987,0.000000
22.930000,34.213585,-178.724457,0.006541,0.000792,0.020111,152.189621,7.752909,0.201114,-178.724457,0.021213,0.000000
23.070002,35.166489,-178.857910,0.006545,0.000810,0.020563,156.428360,7.968840,0.205626,-178.857910,0.021447,0.000000
23.210001,36.383026,-178.857910,0.006562,0.000819,0.020796,161.839783,8.244512,0.207965,-178.857910,0.021681,0.000000
23.350000,37.184746,-178.813431,0.006554,0.000830,0.021074,165.406006,8.426184,0.210743,-178.813431,0.021915,0.000000
23.490002,37.693031,-178.902390,0.006554,0.000836,0.021230,167.666977,8.541363,0.212302,-178.902390,0.022149,0.000000
23.630001,38.523796,-178.857910,0.006575,0.000846,0.021490,171.362396,8.729617,0.214899,-178.857910,0.022383,0.000000
23.770000,39.159065,-178.946869,0.006566,0.000855,0.021707,174.188217,8.873570,0.217071,-178.946869,0.022618,0.000000
23.910002,39.860985,-178.902390,0.006566,0.000862,0.021906,177.310516,9.032628,0.219062,-178.902390,0.022852,0.000000
24.050001,40.309692,-178.946869,0.006584,0.000869,0.022071,179.306473,9.134306,0.220712,-178.946869,0.023086,0.000000
24.190001,41.318451,-178.946869,0.006579,0.000882,0.022410,183.793655,9.362894,0.224096,-178.946869,0.023320,0.000000
24.330002,42.145866,-178.991348,0.006588,0.000890,0.022618,187.474182,9.550390,0.226178,-178.991348,0.023554,0.000000
24.470001,43.097275,-179.080307,0.006575,0.000901,0.022895,191.706253,9.765983,0.228948,-179.080307,0.023780,0.000000
24.610001,43.791008,-179.035828,0.006592,0.000910,0.023112,194.792130,9.923184,0.231121,-179.035828,0.024014,0.000000
24.750002,44.046455,-179.035828,0.006588,0.000912,0.023164,195.928421,9.981070,0.231643,-179.035828,0.024248,0.000000
24.890001,44.760666,-179.080307,0.006592,0.000923,0.023433,199.105392,10.142912,0.234330,-179.080307,0.024482,0.000000
25.030001,45.414925,-178.991348,0.006605,0.000933,0.023710,202.015671,10.291169,0.237101,-178.991348,0.024716,0.000000
25.170002,46.802010,-179.080307,0.006597,0.000946,0.024031,208.185730,10.605487,0.240311,-179.080307,0.024951,0.000000
25.310001,47.717674,-179.080307,0.006601,0.000956,0.024291,212.258820,10.812980,0.242915,-179.080307,0.025185,0.000000
25.450001,48.508217,-179.124786,0.006597,0.000966,0.024543,215.775330,10.992119,0.245428,-179.124786,0.025419,0.000000
25.590002,49.244400,-179.169266,0.006597,0.000973,0.024716,219.050034,11.158940,0.247161,-179.169266,0.025653,0.000000
25.730001,49.732582,-179.169266,0.006614,0.000981,0.024924,221.221573,11.269565,0.249243,-179.169266,0.025887,0.000000
25.870001,50.424072,-179.213745,0.006610,0.000988,0.025107,224.297470,11.426258,0.251067,-179.213745,0.026121,0.000000
26.010002,51.313301,-179.124786,0.006627,0.000999,0.025384,228.252960,11.627761,0.253838,-179.124786,0.026347,0.000000
26.150002,52.079643,-179.213745,0.006610,0.001008,0.025601,231.661819,11.801416,0.256010,-179.213745,0.026581,0.000000
26.290001,53.251869,-179.258240,0.006614,0.001023,0.025983,236.876144,12.067046,0.259825,-179.258240,0.026815,0.000000
26.430000,54.257278,-179.169266,0.006648,0.001033,0.026226,241.348434,12.294875,0.262255,-179.169266,0.027049,0.000000
26.570002,54.691467,-179.258240,0.006618,0.001037,0.026338,243.279800,12.393264,0.263383,-179.258240,0.027283,0.000000
26.710001,55.095863,-179.258240,0.006631,0.001041,0.026451,245.078644,12.484901,0.264511,-179.258240,0.027518,0.000000
26.850000,55.762032,-179.213745,0.006635,0.001050,0.026668,248.041901,12.635858,0.266676,-179.213745,0.027752,0.000000
26.990002,56.567848,-179.347198,0.006622,0.001064,0.027014,251.626358,12.818458,0.270143,-179.347198,0.027986,0.000000
27.130001,58.111702,-179.258240,0.006640,0.001077,0.027353,258.493774,13.168300,0.273527,-179.258240,0.028220,0.000000
27.270000,59.000557,-179.436157,0.006631,0.001086,0.027596,262.447571,13.369718,0.275957,-179.436157,0.028454,0.000000
27.410002,59.738976,-179.302719,0.006657,0.001095,0.027812,265.732239,13.537045,0.278122,-179.302719,0.028680,0.000000
27.550001,60.284874,-179.391678,0.006648,0.001103,0.028012,268.160522,13.660748,0.280120,-179.391678,0.028914,0.000000
27.690001,61.078026,-179.391678,0.006661,0.001110,0.028203,271.688629,13.840478,0.282028,-179.391678,0.029147,0.000000
27.830002,61.781067,-179.480637,0.006657,0.001119,0.028419,274.815918,13.999790,0.284193,-179.480637,0.029382,0.000000
27.970001,61.923683,-179.480637,0.006666,0.001119,0.028428,275.450287,14.032107,0.284283,-179.480637,0.029616,0.000000
28.110001,63.083618,-179.391678,0.006661,0.001134,0.028810,280.609955,14.294951,0.288099,-179.391678,0.029850,0.000000
28.250002,64.194031,-179.436157,0.006661,0.001147,0.029139,285.549316,14.546576,0.291391,-179.436157,0.030085,0.000000
28.390001,64.872498,-179.480637,0.006661,0.001155,0.029339,288.567291,14.700318,0.293390,-179.480637,0.030319,0.000000
28.530001,65.723373,-179.569595,0.006670,0.001165,0.029581,292.352173,14.893129,0.295812,-179.569595,0.030552,0.000000
28.670002,66.320282,-179.525116,0.006674,0.001172,0.029781,295.007355,15.028390,0.297811,-179.525116,0.030787,0.000000
28.810001,67.077682,-179.525116,0.006674,0.001179,0.029954,298.376434,15.200021,0.299544,-179.525116,0.031021,0.000000
28.950001,67.565125,-179.525116,0.006666,0.001176,0.029867,300.544678,15.310475,0.298674,-179.525116,0.030110,0.000000
29.090002,67.406128,-179.614075,0.006666,0.001176,0.029867,299.837433,15.274447,0.298674,-179.614075,0.030110,0.000000
29.230001,67.292923,-179.569595,0.006674,0.001176,0.029867,299.333862,15.248795,0.298674,-179.569595,0.030110,0.000000
29.370001,67.251953,-179.614075,0.006687,0.001174,0.029816,299.151642,15.239511,0.298159,-179.614075,0.029867,0.000000
29.510002,67.148437,-179.614075,0.006687,0.001172,0.029781,298.691162,15.216054,0.297811,-179.614075,0.029867,0.000000
29.650002,67.082535,-179.658554,0.006674,0.001172,0.029764,298.398010,15.201119,0.297637,-179.658554,0.029867,0.000000
29.790001,67.008423,-179.658554,0.006687,0.001171,0.029746,298.068359,15.184326,0.297462,-179.658554,0.029867,0.000000
29.930002,66.931351,-179.658554,0.006679,0.001171,0.029738,297.725525,15.166861,0.297379,-179.658554,0.029867,0.000000
30.070002,66.878464,-179.703049,0.006683,0.001170,0.029729,297.490265,15.154877,0.297288,-179.703049,0.029867,0.000000
30.210001,66.812561,-179.703049,0.006679,0.001170,0.029721,297.197113,15.139943,0.297205,-179.703049,0.029867,0.000000
30.350002,66.774582,-179.747528,0.006687,0.001170,0.029721,297.028168,15.131337,0.297205,-179.747528,0.029867,0.000000
30.490002,66.721329,-179.703049,0.006683,0.001170,0.029711,296.791290,15.119268,0.297114,-179.703049,0.029867,0.000000
30.630001,66.666595,-179.836487,0.006687,0.001170,0.029711,296.547821,15.106867,0.297114,-179.836487,0.029867,0.000000
30.770002,66.620041,-179.747528,0.006687,0.001169,0.029703,296.340729,15.096317,0.297031,-179.747528,0.029867,0.000000
30.910002,66.578339,-179.747528,0.006691,0.001169,0.029703,296.155243,15.086867,0.297031,-179.747528,0.029867,0.000000
31.050001,66.534775,-179.836487,0.006687,0.001169,0.029703,295.961456,15.076995,0.297031,-179.836487,0.029867,0.000000
31.190001,66.490829,-179.880966,0.006683,0.001169,0.029703,295.765991,15.067038,0.297031,-179.880966,0.029867,0.000000
31.330002,66.454330,-179.836487,0.006683,0.001169,0.029703,295.603638,15.058767,0.297031,-179.836487,0.029867,0.000000
31.470001,66.422318,-179.925446,0.006679,0.001169,0.029703,295.461212,15.051512,0.297031,-179.925446,0.029867,0.000000
31.610001,66.402206,-179.792007,0.006696,0.001169,0.029694,295.371765,15.046955,0.296940,-179.792007,0.029867,0.000000
31.750002,66.361618,-179.880966,0.006683,0.001169,0.029694,295.191223,15.037758,0.296940,-179.880966,0.029867,0.000000
31.890001,66.328842,-179.925446,0.006683,0.001169,0.029694,295.045441,15.030331,0.296940,-179.925446,0.029867,0.000000
32.030003,66.286392,-179.969925,0.006683,0.001169,0.029694,294.856598,15.020711,0.296940,-179.969925,0.029867,0.000000
32.170002,66.262939,-179.969925,0.006691,0.001169,0.029694,294.752289,15.015396,0.296940,-179.969925,0.029867,0.000000
32.310001,66.232025,-179.969925,0.006687,0.001169,0.029694,294.614777,15.008391,0.296940,-179.969925,0.029867,0.000000
32.450001,66.195908,-180.014404,0.006683,0.001169,0.029694,294.454102,15.000207,0.296940,-180.014404,0.029867,0.000000
32.590000,66.178787,-180.014404,0.006691,0.001169,0.029694,294.377960,14.996327,0.296940,-180.014404,0.029867,0.000000
32.730003,66.136703,-180.058884,0.006683,0.001169,0.029694,294.190735,14.986792,0.296940,-180.058884,0.029867,0.000000
32.870003,66.125168,-180.014404,0.006683,0.001169,0.029694,294.139435,14.984178,0.296940,-180.014404,0.029867,0.000000
33.010002,66.089035,-180.014404,0.006687,0.001169,0.029694,293.978699,14.975990,0.296940,-180.014404,0.029867,0.000000
33.150002,66.068558,-180.103378,0.006691,0.001169,0.029694,293.887634,14.971349,0.296940,-180.103378,0.029867,0.000000
33.290001,66.035797,-180.058884,0.006700,0.001169,0.029694,293.741882,14.963925,0.296940,-180.058884,0.029867,0.000000
33.430000,66.016800,-180.147858,0.006683,0.001169,0.029686,293.657379,14.959620,0.296857,-180.147858,0.029867,0.000000
33.570000,65.998550,-180.147858,0.006687,0.001169,0.029686,293.576202,14.955485,0.296857,-180.147858,0.029867,0.000000
33.710003,65.970261,-180.103378,0.006700,0.001169,0.029686,293.450378,14.949075,0.296857,-180.103378,0.029867,0.000000
33.850002,65.950150,-180.192337,0.006691,0.001169,0.029686,293.360931,14.944517,0.296857,-180.192337,0.029867,0.000000
33.990002,65.927429,-180.147858,0.006691,0.001169,0.029686,293.259857,14.939369,0.296857,-180.147858,0.029867,0.000000
34.130001,65.895782,-180.192337,0.006687,0.001169,0.029686,293.119080,14.932199,0.296857,-180.192337,0.029867,0.000000
34.270000,65.886841,-180.236816,0.006687,0.001169,0.029686,293.079315,14.930172,0.296857,-180.236816,0.029867,0.000000
34.410000,65.869720,-180.192337,0.006683,0.001169,0.029686,293.003143,14.926291,0.296857,-180.192337,0.029867,0.000000
34.550003,65.842896,-180.325775,0.006696,0.001169,0.029686,292.883820,14.920213,0.296857,-180.325775,0.029867,0.000000
34.690002,65.813492,-180.236816,0.006696,0.001169,0.029686,292.753021,14.913550,0.296857,-180.236816,0.029867,0.000000
34.830002,65.799332,-180.325775,0.006687,0.001169,0.029686,292.690033,14.910342,0.296857,-180.325775,0.029867,0.000000
34.970001,65.771774,-180.325775,0.006704,0.001169,0.029686,292.567474,14.904097,0.296857,-180.325775,0.029867,0.000000
35.110001,65.765823,-180.281296,0.006691,0.001169,0.029686,292.540985,14.902749,0.296857,-180.281296,0.029867,0.000000
35.250000,65.740494,-180.370255,0.006691,0.001169,0.029686,292.428314,14.897009,0.296857,-180.370255,0.029867,0.000000
35.390003,65.723373,-180.325775,0.006691,0.001169,0.029686,292.352173,14.893129,0.296857,-180.325775,0.029867,0.000000
35.530003,65.705872,-180.370255,0.006696,0.001169,0.029686,292.274323,14.889164,0.296857,-180.370255,0.029867,0.000000
35.670002,65.694321,-180.370255,0.006700,0.001169,0.029686,292.222931,14.886546,0.296857,-180.370255,0.029867,0.000000
35.810001,65.679428,-180.414734,0.006691,0.001169,0.029686,292.156677,14.883171,0.296857,-180.414734,0.029867,0.000000
35.950001,65.664902,-180.414734,0.006687,0.001169,0.029686,292.092072,14.879879,0.296857,-180.414734,0.029867,0.000000
36.090000,65.646667,-180.414734,0.006700,0.001169,0.029686,292.010956,14.875748,0.296857,-180.414734,0.029867,0.000000
36.230003,65.626923,-180.459213,0.006687,0.001169,0.029686,291.923126,14.871273,0.296857,-180.459213,0.029867,0.000000
36.370003,65.612396,-180.459213,0.006700,0.001169,0.029686,291.858521,14.867981,0.296857,-180.459213,0.029867,0.000000
36.510002,65.606445,-180.414734,0.006696,0.001169,0.029686,291.832031,14.866633,0.296857,-180.414734,0.029867,0.000000
36.650002,65.574417,-180.548187,0.006700,0.001169,0.029686,291.689575,14.859375,0.296857,-180.548187,0.029867,0.000000
36.790001,65.565857,-180.503693,0.006696,0.001169,0.029686,291.651489,14.857435,0.296857,-180.503693,0.029867,0.000000
36.930000,65.546127,-180.592667,0.006687,0.001169,0.029686,291.563751,14.852964,0.296857,-180.592667,0.029867,0.000000
37.070004,65.533829,-180.548187,0.006704,0.001169,0.029686,291.509033,14.850178,0.296857,-180.548187,0.029867,0.000000
37.210003,65.517075,-180.592667,0.006691,0.001169,0.029686,291.434509,14.846381,0.296857,-180.592667,0.029867,0.000000
37.350002,65.495850,-180.592667,0.006696,0.001169,0.029686,291.340088,14.841572,0.296857,-180.592667,0.029867,0.000000
37.490002,65.486908,-180.637146,0.006691,0.001169,0.029686,291.300323,14.839546,0.296857,-180.637146,0.029867,0.000000
37.630001,65.473877,-180.637146,0.006696,0.001169,0.029686,291.242340,14.836593,0.296857,-180.637146,0.029867,0.000000
37.770000,65.464203,-180.681625,0.006700,0.001169,0.029686,291.199310,14.834400,0.296857,-180.681625,0.029867,0.000000
37.910004,65.455627,-180.637146,0.006700,0.001169,0.029686,291.161163,14.832458,0.296857,-180.637146,0.029867,0.000000
38.050003,65.428818,-180.681625,0.006691,0.001169,0.029686,291.041931,14.826382,0.296857,-180.681625,0.029867,0.000000
38.190002,65.428452,-180.726105,0.006696,0.001169,0.029686,291.040283,14.826300,0.296857,-180.726105,0.029867,0.000000
38.330002,65.404251,-180.770584,0.006700,0.001169,0.029686,290.932648,14.820815,0.296857,-180.770584,0.029867,0.000000
38.470001,65.389725,-180.726105,0.006700,0.001169,0.029686,290.868011,14.817523,0.296857,-180.726105,0.029867,0.000000
38.610001,65.385254,-180.770584,0.006696,0.001169,0.029686,290.848145,14.816510,0.296857,-180.770584,0.029867,0.000000
38.750000,65.374832,-180.815063,0.006696,0.001169,0.029686,290.801788,14.814149,0.296857,-180.815063,0.029867,0.000000
38.890003,65.362549,-180.726105,0.006687,0.001169,0.029686,290.747131,14.811365,0.296857,-180.726105,0.029867,0.000000
39.030003,65.355087,-180.815063,0.006704,0.001169,0.029686,290.713959,14.809674,0.296857,-180.815063,0.029867,0.000000
39.170002,65.345779,-180.815063,0.006704,0.001169,0.029686,290.672546,14.807566,0.296857,-180.815063,0.029867,0.000000
39.310001,65.332748,-180.859543,0.006691,0.001169,0.029686,290.614594,14.804612,0.296857,-180.859543,0.029867,0.000000
39.450001,65.313385,-180.904022,0.006691,0.001169,0.029686,290.528442,14.800224,0.296857,-180.904022,0.029867,0.000000
39.590000,65.310043,-180.859543,0.006691,0.001169,0.029686,290.513580,14.799467,0.296857,-180.859543,0.029867,0.000000
39.730003,65.293274,-180.859543,0.006696,0.001169,0.029686,290.438995,14.795667,0.296857,-180.859543,0.029867,0.000000
39.870003,65.286957,-180.948502,0.006704,0.001169,0.029686,290.410889,14.794236,0.296857,-180.948502,0.029867,0.000000
40.010002,65.269073,-180.948502,0.006696,0.001169,0.029686,290.331329,14.790184,0.296857,-180.948502,0.029867,0.000000
40.150002,65.264984,-180.992996,0.006700,0.001169,0.029686,290.313141,14.789257,0.296857,-180.992996,0.029867,0.000000
40.290001,65.248962,-180.948502,0.006687,0.001169,0.029686,290.241882,14.785626,0.296857,-180.948502,0.029867,0.000000
40.430000,65.227737,-180.992996,0.006691,0.001169,0.029686,290.147461,14.780817,0.296857,-180.992996,0.029867,0.000000
40.570004,65.225143,-180.992996,0.006696,0.001169,0.029686,290.135925,14.780230,0.296857,-180.992996,0.029867,0.000000
40.710003,65.211365,-180.992996,0.006691,0.001169,0.029686,290.074646,14.777106,0.296857,-180.992996,0.029867,0.000000
40.850002,65.197952,-181.037476,0.006700,0.001169,0.029686,290.014984,14.774067,0.296857,-181.037476,0.029867,0.000000
40.990002,65.197586,-181.037476,0.006683,0.001169,0.029686,290.013336,14.773984,0.296857,-181.037476,0.029867,0.000000
41.130001,65.180450,-181.170914,0.006700,0.001169,0.029686,289.937134,14.770102,0.296857,-181.170914,0.029867,0.000000
41.270000,65.172638,-181.081955,0.006700,0.001169,0.029686,289.902374,14.768331,0.296857,-181.081955,0.029867,0.000000
41.410004,65.170776,-181.170914,0.006696,0.001169,0.029686,289.894104,14.767909,0.296857,-181.170914,0.029867,0.000000
41.550003,65.149918,-181.081955,0.006696,0.001169,0.029686,289.801300,14.763183,0.296857,-181.081955,0.029867,0.000000
41.690002,65.151031,-181.215393,0.006696,0.001169,0.029686,289.806274,14.763435,0.296857,-181.215393,0.029867,0.000000
41.830002,65.148056,-181.170914,0.006691,0.001169,0.029686,289.793030,14.762760,0.296857,-181.170914,0.029867,0.000000
41.970001,65.138748,-181.126434,0.006700,0.001169,0.029686,289.751617,14.760652,0.296857,-181.126434,0.029867,0.000000
42.110001,65.134277,-181.259872,0.006683,0.001169,0.029686,289.731750,14.759639,0.296857,-181.259872,0.029867,0.000000
42.250004,65.122726,-181.215393,0.006709,0.001169,0.029686,289.680359,14.757020,0.296857,-181.215393,0.029867,0.000000
42.390003,65.117142,-181.215393,0.006691,0.001169,0.029686,289.655518,14.755754,0.296857,-181.215393,0.029867,0.000000
42.530003,65.095551,-181.304352,0.006696,0.001169,0.029686,289.559479,14.750862,0.296857,-181.304352,0.029867,0.000000
42.670002,65.086243,-181.215393,0.006704,0.001169,0.029686,289.518066,14.748754,0.296857,-181.215393,0.029867,0.000000
42.810001,65.081024,-181.304352,0.006687,0.001169,0.029686,289.494843,14.747571,0.296857,-181.304352,0.029867,0.000000
42.950001,65.079163,-181.304352,0.006704,0.001169,0.029686,289.486572,14.747149,0.296857,-181.304352,0.029867,0.000000
43.090000,65.073959,-181.304352,0.006691,0.001169,0.029686,289.463440,14.745970,0.296857,-181.304352,0.029867,0.000000
43.230003,65.059052,-181.348831,0.006691,0.001169,0.029686,289.397125,14.742592,0.296857,-181.348831,0.029867,0.000000
43.370003,65.046021,-181.304352,0.006700,0.001169,0.029686,289.339142,14.739638,0.296857,-181.304352,0.029867,0.000000
43.510002,65.028152,-181.393326,0.006696,0.001169,0.029686,289.259674,14.735590,0.296857,-181.393326,0.029867,0.000000
43.650002,65.031128,-181.393326,0.006683,0.001169,0.029686,289.272919,14.736264,0.296857,-181.393326,0.029867,0.000000
43.790001,65.024048,-181.393326,0.006696,0.001169,0.029686,289.241425,14.734660,0.296857,-181.393326,0.029867,0.000000
43.930000,65.011017,-181.437805,0.006700,0.001169,0.029686,289.183441,14.731707,0.296857,-181.437805,0.029867,0.000000
44.070004,65.006927,-181.393326,0.006704,0.001169,0.029686,289.165253,14.730780,0.296857,-181.393326,0.029867,0.000000
44.210003,65.000229,-181.482285,0.006700,0.001169,0.029686,289.135468,14.729262,0.296857,-181.482285,0.029867,0.000000
44.350002,64.997238,-181.437805,0.006704,0.001169,0.029686,289.122162,14.728585,0.296857,-181.437805,0.029867,0.000000
44.490002,64.978622,-181.482285,0.006696,0.001169,0.029686,289.039337,14.724366,0.296857,-181.482285,0.029867,0.000000
44.630001,64.986816,-181.526764,0.006704,0.001169,0.029686,289.075806,14.726223,0.296857,-181.526764,0.029867,0.000000
44.770000,64.970810,-181.437805,0.006696,0.001169,0.029686,289.004608,14.722596,0.296857,-181.437805,0.029867,0.000000
44.910004,64.960007,-181.571243,0.006709,0.001169,0.029686,288.956543,14.720148,0.296857,-181.571243,0.029867,0.000000
45.050003,64.968948,-181.571243,0.006700,0.001169,0.029686,288.996307,14.722175,0.296857,-181.571243,0.029867,0.000000
45.190002,64.956650,-181.571243,0.006691,0.001169,0.029686,288.941620,14.719388,0.296857,-181.571243,0.029867,0.000000
45.330002,64.951447,-181.571243,0.006700,0.001169,0.029686,288.918457,14.718208,0.296857,-181.571243,0.029867,0.000000
45.470001,64.937286,-181.571243,0.006704,0.001169,0.029686,288.855469,14.714999,0.296857,-181.571243,0.029867,0.000000
45.610001,64.925003,-181.615723,0.006700,0.001169,0.029686,288.800842,14.712215,0.296857,-181.615723,0.029867,0.000000
45.750004,64.923141,-181.615723,0.006704,0.001169,0.029686,288.792542,14.711794,0.296857,-181.615723,0.029867,0.000000
45.890003,64.913834,-181.704681,0.006670,0.001169,0.029686,288.751160,14.709685,0.296857,-181.704681,0.029867,0.000000
46.030003,64.910858,-181.660202,0.006696,0.001169,0.029686,288.737915,14.709011,0.296857,-181.660202,0.029867,0.000000
46.170002,64.898941,-181.660202,0.006696,0.001169,0.029686,288.684906,14.706310,0.296857,-181.660202,0.029867,0.000000
46.310001,64.880325,-181.704681,0.006704,0.001169,0.029686,288.602112,14.702092,0.296857,-181.704681,0.029867,0.000000
46.450001,64.892975,-181.704681,0.006700,0.001169,0.029686,288.658356,14.704958,0.296857,-181.704681,0.029867,0.000000
46.590004,64.876602,-181.704681,0.006696,0.001169,0.029686,288.585541,14.701248,0.296857,-181.704681,0.029867,0.000000
46.730003,64.880692,-181.793640,0.006691,0.001169,0.029686,288.603729,14.702175,0.296857,-181.793640,0.029867,0.000000
46.870003,64.878464,-181.749161,0.006696,0.001169,0.029686,288.593811,14.701670,0.296857,-181.749161,0.029867,0.000000
47.010002,64.859833,-181.882614,0.006709,0.001169,0.029686,288.510956,14.697448,0.296857,-181.882614,0.029867,0.000000
47.150002,64.857239,-181.793640,0.006696,0.001169,0.029686,288.499420,14.696860,0.296857,-181.793640,0.029867,0.000000
47.290001,64.846436,-181.882614,0.006691,0.001169,0.029686,288.451355,14.694413,0.296857,-181.882614,0.029867,0.000000
47.430004,64.844193,-181.927094,0.006704,0.001169,0.029686,288.441376,14.693904,0.296857,-181.927094,0.029867,0.000000
47.570004,64.830795,-181.838135,0.006700,0.001169,0.029686,288.381775,14.690868,0.296857,-181.838135,0.029867,0.000000
47.710003,64.824097,-181.927094,0.006700,0.001169,0.029686,288.351990,14.689350,0.296857,-181.927094,0.029867,0.000000
47.850002,64.819244,-181.793640,0.006700,0.001169,0.029686,288.330414,14.688251,0.296857,-181.793640,0.029867,0.000000
47.990002,64.820740,-181.971573,0.006700,0.001169,0.029686,288.337036,14.688590,0.296857,-181.971573,0.029867,0.000000
48.130001,64.804733,-181.971573,0.006700,0.001169,0.029686,288.265839,14.684962,0.296857,-181.971573,0.029867,0.000000
48.270000,64.802872,-181.882614,0.006700,0.001169,0.029686,288.257568,14.684541,0.296857,-181.882614,0.029867,0.000000
48.410004,64.798019,-181.971573,0.006704,0.001169,0.029686,288.235992,14.683441,0.296857,-181.971573,0.029867,0.000000
48.550003,64.791321,-182.016052,0.006704,0.001169,0.029686,288.206177,14.681923,0.296857,-182.016052,0.029867,0.000000
48.690002,64.789459,-182.016052,0.006700,0.001169,0.029686,288.197906,14.681501,0.296857,-182.016052,0.029867,0.000000
48.830002,64.794678,-182.016052,0.006704,0.001169,0.029686,288.221130,14.682683,0.296857,-182.016052,0.029867,0.000000
48.970001,64.776062,-182.060532,0.006700,0.001169,0.029686,288.138306,14.678466,0.296857,-182.060532,0.029867,0.000000
49.110001,64.769730,-182.060532,0.006696,0.001169,0.029686,288.110138,14.677031,0.296857,-182.060532,0.029867,0.000000
49.250004,64.763016,-182.016052,0.006704,0.001169,0.029686,288.080292,14.675508,0.296857,-182.016052,0.029867,0.000000
49.390003,64.759293,-182.105011,0.006687,0.001169,0.029686,288.063721,14.674665,0.296857,-182.105011,0.029867,0.000000
49.530003,64.748123,-182.149490,0.006709,0.001169,0.029686,288.014038,14.672134,0.296857,-182.149490,0.029867,0.000000
49.670002,64.738815,-182.105011,0.006700,0.001169,0.029686,287.972626,14.670026,0.296857,-182.105011,0.029867,0.000000
49.810001,64.740677,-182.149490,0.006700,0.001169,0.029686,287.980927,14.670446,0.296857,-182.149490,0.029867,0.000000
49.950001,64.728760,-182.149490,0.006687,0.001169,0.029686,287.927917,14.667747,0.296857,-182.149490,0.029867,0.000000
50.090004,64.727646,-182.149490,0.006696,0.001169,0.029686,287.922943,14.667495,0.296857,-182.149490,0.029867,0.000000
50.230003,64.721695,-182.149490,0.006704,0.001169,0.029686,287.896484,14.666146,0.296857,-182.149490,0.029867,0.000000
50.370003,64.725784,-182.149490,0.006696,0.001169,0.029686,287.914673,14.667072,0.296857,-182.149490,0.029867,0.000000
50.510002,64.716110,-182.238449,0.006700,0.001169,0.029686,287.871643,14.664881,0.296857,-182.238449,0.029867,0.000000
50.650002,64.709396,-182.238449,0.006691,0.001169,0.029686,287.841766,14.663360,0.296857,-182.238449,0.029867,0.000000
50.790001,64.705673,-182.282944,0.006709,0.001169,0.029686,287.825195,14.662515,0.296857,-182.282944,0.029867,0.000000
50.930004,64.702332,-182.238449,0.006709,0.001169,0.029686,287.810333,14.661757,0.296857,-182.238449,0.029867,0.000000
51.070004,64.685944,-182.327423,0.006696,0.001169,0.029686,287.737457,14.658045,0.296857,-182.327423,0.029867,0.000000
51.210003,64.678864,-182.327423,0.006713,0.001169,0.029686,287.705963,14.656440,0.296857,-182.327423,0.029867,0.000000
51.350002,64.679245,-182.282944,0.006700,0.001169,0.029686,287.707642,14.656527,0.296857,-182.282944,0.029867,0.000000
51.490002,64.674774,-182.416382,0.006700,0.001169,0.029686,287.687775,14.655514,0.296857,-182.416382,0.029867,0.000000
51.630001,64.669189,-182.327423,0.006704,0.001169,0.029686,287.662933,14.654248,0.296857,-182.327423,0.029867,0.000000
51.770004,64.664337,-182.371902,0.006683,0.001169,0.029686,287.641327,14.653148,0.296857,-182.371902,0.029867,0.000000
51.910004,64.659134,-182.416382,0.006704,0.001169,0.029686,287.618195,14.651969,0.296857,-182.416382,0.029867,0.000000
52.050003,64.658386,-182.371902,0.006691,0.001169,0.029686,287.614868,14.651799,0.296857,-182.371902,0.029867,0.000000
52.190002,64.647964,-182.460861,0.006704,0.001169,0.029686,287.568512,14.649438,0.296857,-182.460861,0.029867,0.000000
52.330002,64.647964,-182.416382,0.006704,0.001169,0.029686,287.568512,14.649438,0.296857,-182.416382,0.029867,0.000000
52.470001,64.645355,-182.460861,0.006704,0.001169,0.029686,287.556915,14.648848,0.296857,-182.460861,0.029867,0.000000
52.610001,64.641998,-182.416382,0.006704,0.001169,0.029686,287.541962,14.648087,0.296857,-182.416382,0.029867,0.000000
52.750004,64.624496,-182.549820,0.006696,0.001169,0.029686,287.464111,14.644120,0.296857,-182.549820,0.029867,0.000000
52.890003,64.620773,-182.505341,0.006696,0.001169,0.029686,287.447571,14.643277,0.296857,-182.505341,0.029867,0.000000
53.030003,64.609970,-182.549820,0.006709,0.001169,0.029686,287.399506,14.640828,0.296857,-182.549820,0.029867,0.000000
53.170002,64.610718,-182.638779,0.006683,0.001169,0.029686,287.402832,14.640998,0.296857,-182.638779,0.029867,0.000000
53.310001,64.600296,-182.549820,0.006704,0.001169,0.029686,287.356476,14.638636,0.296857,-182.549820,0.029867,0.000000
53.450001,64.596939,-182.594299,0.006700,0.001169,0.029686,287.341522,14.637876,0.296857,-182.594299,0.029867,0.000000
53.590004,64.600662,-182.594299,0.006700,0.001169,0.029686,287.358093,14.638720,0.296857,-182.594299,0.029867,0.000000
53.730003,64.606995,-182.549820,0.006696,0.001169,0.029686,287.386261,14.640154,0.296857,-182.549820,0.029867,0.000000
53.870003,64.596573,-182.638779,0.006691,0.001169,0.029686,287.339905,14.637793,0.296857,-182.638779,0.029867,0.000000
54.010002,64.592850,-182.683273,0.006700,0.001169,0.029686,287.323334,14.636950,0.296857,-182.683273,0.029867,0.000000
54.150002,64.589874,-182.683273,0.006700,0.001169,0.029686,287.310120,14.636274,0.296857,-182.683273,0.029867,0.000000
54.290001,64.576843,-182.727753,0.006704,0.001169,0.029686,287.252136,14.633322,0.296857,-182.727753,0.029867,0.000000
54.430004,64.572372,-182.683273,0.006709,0.001169,0.029686,287.232269,14.632309,0.296857,-182.683273,0.029867,0.000000
54.570004,64.560455,-182.683273,0.006700,0.001169,0.029686,287.179260,14.629608,0.296857,-182.683273,0.029867,0.000000
54.710003,64.565292,-182.727753,0.006704,0.001169,0.029686,287.200775,14.630704,0.296857,-182.727753,0.029867,0.000000
54.850002,64.563065,-182.683273,0.006709,0.001169,0.029686,287.190857,14.630199,0.296857,-182.683273,0.029867,0.000000
54.990002,64.560074,-182.772232,0.006691,0.001169,0.029686,287.177551,14.629522,0.296857,-182.772232,0.029867,0.000000
55.130001,64.563431,-182.772232,0.006709,0.001169,0.029686,287.192474,14.630283,0.296857,-182.772232,0.029867,0.000000
55.270004,64.553741,-182.816711,0.006696,0.001169,0.029686,287.149384,14.628087,0.296857,-182.816711,0.029867,0.000000
55.410004,64.542953,-182.816711,0.006713,0.001169,0.029686,287.101410,14.625642,0.296857,-182.816711,0.029867,0.000000
55.550003,64.545929,-182.816711,0.006704,0.001169,0.029686,287.114624,14.626316,0.296857,-182.816711,0.029867,0.000000
55.690002,64.531403,-182.905670,0.006700,0.001169,0.029686,287.050018,14.623025,0.296857,-182.905670,0.029867,0.000000
55.830002,64.519485,-182.816711,0.006691,0.001169,0.029686,286.997009,14.620324,0.296857,-182.816711,0.029867,0.000000
55.970001,64.506836,-182.950150,0.006700,0.001169,0.029686,286.940735,14.617457,0.296857,-182.950150,0.029867,0.000000
56.110004,64.509430,-182.861191,0.006704,0.001169,0.029686,286.952271,14.618046,0.296857,-182.861191,0.029867,0.000000
56.250004,64.513535,-182.950150,0.006704,0.001169,0.029686,286.970520,14.618976,0.296857,-182.950150,0.029867,0.000000
56.390003,64.506454,-182.950150,0.006696,0.001169,0.029686,286.939026,14.617372,0.296857,-182.950150,0.029867,0.000000
56.530003,64.511292,-182.905670,0.006704,0.001169,0.029686,286.960571,14.618467,0.296857,-182.905670,0.029867,0.000000
56.670002,64.505341,-182.950150,0.006709,0.001169,0.029686,286.934082,14.617119,0.296857,-182.950150,0.029867,0.000000
56.810001,64.498260,-182.950150,0.006700,0.001169,0.029686,286.902588,14.615515,0.296857,-182.950150,0.029867,0.000000
56.950005,64.484863,-182.994629,0.006696,0.001169,0.029686,286.842987,14.612479,0.296857,-182.994629,0.029867,0.000000
57.090004,64.472946,-182.994629,0.006700,0.001169,0.029686,286.789978,14.609778,0.296857,-182.994629,0.029867,0.000000
57.230003,64.475555,-182.950150,0.006704,0.001169,0.029686,286.801605,14.610370,0.296857,-182.950150,0.029867,0.000000
57.370003,64.483368,-183.039108,0.006709,0.001169,0.029686,286.836334,14.612140,0.296857,-183.039108,0.029867,0.000000
57.510002,64.457672,-183.039108,0.006704,0.001169,0.029686,286.722046,14.606317,0.296857,-183.039108,0.029867,0.000000
57.650002,64.466980,-183.083588,0.006696,0.001169,0.029686,286.763458,14.608427,0.296857,-183.083588,0.029867,0.000000
57.790001,64.472946,-183.083588,0.006696,0.001169,0.029686,286.789978,14.609778,0.296857,-183.083588,0.029867,0.000000
57.930004,64.456192,-183.128082,0.006700,0.001169,0.029686,286.715454,14.605982,0.296857,-183.128082,0.029867,0.000000
58.070004,64.460663,-183.128082,0.006691,0.001169,0.029686,286.735352,14.606995,0.296857,-183.128082,0.029867,0.000000
58.210003,64.455811,-183.083588,0.006704,0.001169,0.029686,286.713776,14.605896,0.296857,-183.083588,0.029867,0.000000
58.350002,64.444641,-183.172562,0.006696,0.001169,0.029686,286.664093,14.603365,0.296857,-183.172562,0.029867,0.000000
58.490002,64.435333,-183.172562,0.006691,0.001169,0.029686,286.622681,14.601255,0.296857,-183.172562,0.029867,0.000000
58.630001,64.434586,-183.128082,0.006704,0.001169,0.029686,286.619354,14.601086,0.296857,-183.128082,0.029867,0.000000
58.770004,64.439804,-183.217041,0.006704,0.001169,0.029686,286.642578,14.602269,0.296857,-183.217041,0.029867,0.000000
58.910004,64.433105,-183.217041,0.006700,0.001169,0.029686,286.612762,14.600751,0.296857,-183.217041,0.029867,0.000000
59.050003,64.435333,-183.306000,0.006696,0.001169,0.029686,286.622681,14.601255,0.296857,-183.306000,0.029867,0.000000
59.190002,64.434586,-183.172562,0.006704,0.001169,0.029686,286.619354,14.601086,0.296857,-183.172562,0.029867,0.000000
59.300003,64.424164,-183.306000,0.006696,0.001169,0.029686,286.572998,14.598724,0.296857,-183.306000,0.029867,0.000000