File: Data/type 1 compression/Support type 1-3_04162024_185726.csv
Time (sec),S:Load (lbs),S:HL1 (DIM),S:LVDT (in),S:Position (in),Ch:Position (mm),Ch:Load (N),Ch:Stress (MPa),Ch:Strain (mm/mm),Ch:HL1 (DIM),Set Point (),Cycles ()
0.110000,0.010056,-157.017761,-0.000022,-0.000000,-0.000000,0.044729,0.002279,-0.000000,-157.017761,0.000156,0.000000
0.280000,-0.006332,-157.017761,-0.000013,-0.000000,-0.000000,-0.028168,-0.001435,-0.000000,-157.017761,0.000156,0.000000
0.450000,0.008568,-157.062241,-0.000022,0.000027,0.000685,0.038112,0.001941,0.006851,-157.062241,0.001284,0.000000
0.620000,-0.024200,-157.017761,-0.000009,0.000129,0.003269,-0.107649,-0.005484,0.032694,-157.017761,0.004111,0.000000
0.790000,-0.046547,-157.106720,0.000030,0.000227,0.005767,-0.207051,-0.010548,0.057674,-157.106720,0.006938,0.000000
0.960000,-0.018250,-157.106720,0.000160,0.000345,0.008751,-0.081178,-0.004135,0.087507,-157.106720,0.009782,0.000000
1.130000,0.002983,-157.195679,0.000276,0.000458,0.011639,0.013269,0.000676,0.116386,-157.195679,0.012610,0.000000
1.300000,0.020851,-157.151199,0.000384,0.000570,0.014474,0.092750,0.004725,0.144742,-157.151199,0.015437,0.000000
1.470000,0.032394,-157.106720,0.000479,0.000672,0.017067,0.144098,0.007341,0.170668,-157.106720,0.018264,0.000000
1.640000,0.018990,-157.151199,0.000582,0.000786,0.019955,0.084470,0.004303,0.199547,-157.151199,0.021108,0.000000
1.810000,0.032028,-157.284637,0.000711,0.000904,0.022973,0.142469,0.007258,0.229728,-157.284637,0.023936,0.000000
1.980000,-0.006332,-157.284637,0.000819,0.001013,0.025740,-0.028168,-0.001435,0.257396,-157.284637,0.026763,0.000000
2.150000,-0.013779,-157.284637,0.000927,0.001119,0.028428,-0.061291,-0.003122,0.284276,-157.284637,0.029607,0.000000
2.320000,-0.048035,-157.240158,0.001052,0.001233,0.031307,-0.213669,-0.010885,0.313071,-157.240158,0.032434,0.000000
2.490000,-0.018250,-157.329117,0.001160,0.001349,0.034264,-0.081178,-0.004135,0.342639,-157.329117,0.035262,0.000000
2.660000,-0.024200,-157.329117,0.001259,0.001456,0.036970,-0.107649,-0.005484,0.369701,-157.329117,0.038089,0.000000
2.830000,-0.004471,-157.418091,0.001367,0.001563,0.039693,-0.019887,-0.001013,0.396930,-157.418091,0.040933,0.000000
3.000000,0.030907,-157.373611,0.001492,0.001674,0.042511,0.137480,0.007004,0.425112,-157.373611,0.043760,0.000000
3.170000,0.044685,-157.418091,0.001595,0.001787,0.045391,0.198770,0.010126,0.453907,-157.418091,0.046588,0.000000
3.340000,0.033890,-157.462570,0.001716,0.001903,0.048339,0.150749,0.007680,0.483392,-157.462570,0.049432,0.000000
3.510000,0.060699,-157.462570,0.001824,0.002017,0.051227,0.270005,0.013755,0.512270,-157.462570,0.052259,0.000000
3.680000,0.203690,-157.551529,0.001932,0.002125,0.053985,0.906056,0.046157,0.539847,-157.551529,0.055086,0.000000
3.850000,0.539566,-157.507050,0.002065,0.002240,0.056890,2.400110,0.122267,0.568900,-157.507050,0.057913,0.000000
4.020000,0.717934,-157.507050,0.002104,-0.000002,-0.000061,3.193528,0.162686,-0.000606,-157.507050,0.000130,0.000000
4.190000,0.673248,-157.551529,0.002091,-0.000003,-0.000078,2.994758,0.152560,-0.000780,-157.551529,0.000130,0.000000
4.360000,0.695595,-157.596008,0.002104,-0.000003,-0.000078,3.094160,0.157624,-0.000780,-157.596008,0.000130,0.000000
4.530000,0.677345,-157.596008,0.002100,-0.000003,-0.000078,3.012982,0.153489,-0.000780,-157.596008,0.000251,0.000000
4.700000,0.697083,-157.596008,0.002091,-0.000003,-0.000078,3.100778,0.157961,-0.000780,-157.596008,0.000529,0.000000
4.870000,0.687027,-157.596008,0.002108,-0.000003,-0.000078,3.056049,0.155683,-0.000780,-157.596008,0.000815,0.000000
5.040000,0.762245,-157.684967,0.002091,0.000014,0.000364,3.390636,0.172727,0.003641,-157.684967,0.001101,0.000000
5.210000,0.807678,-157.729446,0.002117,0.000024,0.000615,3.592732,0.183022,0.006154,-157.729446,0.001378,0.000000
5.380000,0.853104,-157.773926,0.002121,0.000030,0.000755,3.794795,0.193316,0.007547,-157.773926,0.001665,0.000000
5.550000,0.924232,-157.729446,0.002121,0.000039,0.000980,4.111191,0.209434,0.009795,-157.729446,0.001951,0.000000
5.720000,1.018440,-157.729446,0.002134,0.000056,0.001413,4.530249,0.230782,0.014133,-157.729446,0.002229,0.000000
5.890000,1.098129,-157.773926,0.002143,0.000069,0.001743,4.884723,0.248840,0.017433,-157.773926,0.002515,0.000000
6.060000,1.175209,-157.862900,0.002164,0.000080,0.002020,5.227591,0.266306,0.020204,-157.862900,0.002801,0.000000
6.230000,1.235161,-157.862900,0.002169,0.000090,0.002281,5.494270,0.279891,0.022808,-157.862900,0.003079,0.000000
6.400000,1.304047,-157.862900,0.002173,0.000100,0.002532,5.800689,0.295501,0.025321,-157.862900,0.003365,0.000000
6.570000,1.393791,-157.862900,0.002182,0.000109,0.002767,6.199893,0.315838,0.027668,-157.862900,0.003651,0.000000
6.740000,1.473106,-157.907379,0.002195,0.000121,0.003061,6.552704,0.333811,0.030612,-157.907379,0.003929,0.000000
6.910000,1.610886,-157.907379,0.002203,0.000136,0.003452,7.165577,0.365032,0.034518,-157.907379,0.004215,0.000000
7.080000,1.734886,-157.996338,0.002216,0.000147,0.003729,7.717159,0.393131,0.037289,-157.996338,0.004501,0.000000
7.250000,1.808617,-157.996338,0.002233,0.000154,0.003920,8.045129,0.409838,0.039196,-157.996338,0.004787,0.000000
7.420001,1.862976,-157.996338,0.002242,0.000159,0.004032,8.286931,0.422156,0.040324,-157.996338,0.005064,0.000000
7.590000,2.081932,-158.085297,0.002233,0.000181,0.004587,9.260897,0.471773,0.045873,-158.085297,0.005351,0.000000
7.760000,2.205193,-158.040817,0.002264,0.000192,0.004873,9.809186,0.499704,0.048734,-158.040817,0.005637,0.000000
7.930000,2.293442,-158.129776,0.002268,0.000201,0.005108,10.201738,0.519701,0.051081,-158.129776,0.005914,0.000000
8.100000,2.485588,-158.085297,0.002289,0.000215,0.005472,11.056448,0.563242,0.054722,-158.085297,0.006200,0.000000
8.270000,2.566017,-158.129776,0.002281,0.000224,0.005698,11.414214,0.581468,0.056978,-158.129776,0.006487,0.000000
8.440001,2.647568,-158.174255,0.002302,0.000233,0.005906,11.776970,0.599947,0.059060,-158.174255,0.006764,0.000000
8.610001,2.736938,-158.263229,0.002311,0.000239,0.006062,12.174510,0.620199,0.060619,-158.263229,0.007051,0.000000
8.780001,2.937645,-158.218750,0.002311,0.000253,0.006418,13.067297,0.665680,0.064177,-158.218750,0.007337,0.000000
8.950001,3.192719,-158.218750,0.002341,0.000269,0.006842,14.201921,0.723480,0.068423,-158.218750,0.007614,0.000000
9.120001,3.283951,-158.218750,0.002337,0.000279,0.007076,14.607742,0.744154,0.070762,-158.218750,0.007901,0.000000
9.290001,3.429924,-158.263229,0.002341,0.000287,0.007284,15.257064,0.777232,0.072844,-158.263229,0.008187,0.000000
9.460000,3.509613,-158.352188,0.002354,0.000294,0.007475,15.611539,0.795290,0.074752,-158.352188,0.008464,0.000000
9.630000,3.724472,-158.352188,0.002371,0.000309,0.007857,16.567280,0.843977,0.078567,-158.352188,0.008750,0.000000
9.800000,3.944542,-158.352188,0.002376,0.000322,0.008187,17.546198,0.893846,0.081867,-158.352188,0.009036,0.000000
9.970000,4.076736,-158.352188,0.002384,0.000333,0.008464,18.134230,0.923802,0.084638,-158.352188,0.009314,0.000000
10.140000,4.265526,-158.396667,0.002397,0.000346,0.008785,18.974007,0.966582,0.087847,-158.396667,0.009600,0.000000
10.310000,4.323616,-158.441147,0.002393,0.000352,0.008950,19.232405,0.979745,0.089498,-158.441147,0.009886,0.000000
10.480000,4.494911,-158.441147,0.002414,0.000364,0.009253,19.994364,1.018561,0.092533,-158.441147,0.010164,0.000000
10.650001,4.668434,-158.485626,0.002427,0.000373,0.009470,20.766232,1.057882,0.094698,-158.485626,0.010450,0.000000
10.820001,5.015488,-158.485626,0.002436,0.000390,0.009913,22.310003,1.136526,0.099126,-158.485626,0.010736,0.000000
10.990001,5.169273,-158.485626,0.002440,0.000401,0.010181,22.994076,1.171374,0.101814,-158.485626,0.011014,0.000000
11.160001,5.332375,-158.574585,0.002458,0.000411,0.010433,23.719587,1.208333,0.104327,-158.574585,0.011300,0.000000
11.330001,5.462708,-158.619064,0.002458,0.000418,0.010623,24.299337,1.237867,0.106234,-158.619064,0.011586,0.000000
11.500001,5.476112,-158.530106,0.002466,0.000422,0.010727,24.358965,1.240905,0.107271,-158.530106,0.011863,0.000000
11.670001,5.944923,-158.530106,0.002479,0.000443,0.011248,26.444340,1.347139,0.112480,-158.530106,0.012150,0.000000
11.840000,6.122551,-158.663559,0.002483,0.000456,0.011577,27.234467,1.387390,0.115772,-158.663559,0.012436,0.000000
12.010000,6.381348,-158.708038,0.002501,0.000471,0.011968,28.385653,1.446034,0.119678,-158.708038,0.012713,0.000000
12.180000,6.464012,-158.708038,0.002518,0.000479,0.012159,28.753363,1.464766,0.121586,-158.708038,0.013000,0.000000
12.350000,6.564178,-158.663559,0.002527,0.000486,0.012349,29.198925,1.487464,0.123494,-158.663559,0.013286,0.000000
12.520000,6.774200,-158.708038,0.002527,0.000499,0.012670,30.133148,1.535056,0.126703,-158.708038,0.013564,0.000000
12.690001,6.973793,-158.708038,0.002539,0.000508,0.012896,31.020981,1.580284,0.128959,-158.708038,0.013850,0.000000
12.860001,7.390846,-158.841476,0.002557,0.000526,0.013355,32.876125,1.674790,0.133554,-158.841476,0.014136,0.000000
13.030001,7.497719,-158.841476,0.002561,0.000534,0.013554,33.351521,1.699007,0.135545,-158.841476,0.014413,0.000000
13.200001,7.511497,-158.796997,0.002570,0.000538,0.013667,33.412811,1.702130,0.136673,-158.796997,0.014700,0.000000
13.370001,7.738647,-158.841476,0.002574,0.000550,0.013962,34.423222,1.753603,0.139625,-158.841476,0.014986,0.000000
13.540001,8.086441,-158.885956,0.002583,0.000564,0.014335,35.970287,1.832414,0.143349,-158.885956,0.015263,0.000000
13.710001,8.367584,-158.930435,0.002600,0.000578,0.014682,37.220875,1.896122,0.146824,-158.930435,0.015549,0.000000
13.880001,8.543716,-158.930435,0.002613,0.000590,0.014994,38.004349,1.936034,0.149942,-158.930435,0.015835,0.000000
14.050000,8.697128,-158.930435,0.002621,0.000601,0.015263,38.686760,1.970797,0.152630,-158.930435,0.016113,0.000000
14.220000,8.820389,-158.974915,0.002617,0.000611,0.015514,39.235050,1.998729,0.155143,-158.974915,0.016399,0.000000
14.390000,9.014397,-159.019394,0.002630,0.000621,0.015784,40.098038,2.042691,0.157838,-159.019394,0.016685,0.000000
14.560000,9.293671,-159.063889,0.002647,0.000633,0.016070,41.340313,2.105976,0.160699,-159.063889,0.016963,0.000000
14.730000,9.469803,-159.019394,0.002652,0.000644,0.016356,42.123787,2.145888,0.163560,-159.019394,0.017249,0.000000
14.900001,9.719666,-159.019394,0.002673,0.000654,0.016607,43.235233,2.202508,0.166074,-159.019394,0.017535,0.000000
15.070001,9.778130,-159.063889,0.002665,0.000661,0.016790,43.495293,2.215756,0.167898,-159.063889,0.017812,0.000000
15.240001,9.939369,-159.152847,0.002669,0.000672,0.017059,44.212521,2.252293,0.170585,-159.152847,0.018099,0.000000
15.410001,10.191833,-159.108368,0.002690,0.000680,0.017267,45.335541,2.309503,0.172667,-159.108368,0.018385,0.000000
15.580001,10.563835,-159.108368,0.002699,0.000699,0.017761,46.990284,2.393799,0.177610,-159.108368,0.018672,0.000000
15.750001,11.017754,-159.197327,0.002725,0.000716,0.018194,49.009415,2.496659,0.181940,-159.197327,0.018949,0.000000
15.920001,11.004723,-159.286285,0.002734,0.000723,0.018368,48.951450,2.493706,0.183681,-159.286285,0.019235,0.000000
16.090000,11.113083,-159.286285,0.002734,0.000734,0.018645,49.433460,2.518261,0.186451,-159.286285,0.019521,0.000000
16.260000,11.278046,-159.241806,0.002742,0.000744,0.018896,50.167252,2.555642,0.188965,-159.241806,0.019799,0.000000
16.430000,11.282143,-159.330765,0.002746,0.000746,0.018958,50.185478,2.556570,0.189578,-159.330765,0.020085,0.000000
16.600000,11.665688,-159.330765,0.002755,0.000762,0.019365,51.891571,2.643482,0.193650,-159.330765,0.020371,0.000000
16.770000,11.867142,-159.330765,0.002764,0.000772,0.019599,52.787682,2.689133,0.195989,-159.330765,0.020649,0.000000
16.940001,12.280098,-159.419724,0.002785,0.000786,0.019972,54.624603,2.782710,0.199721,-159.419724,0.020935,0.000000
17.110001,12.329994,-159.375244,0.002794,0.000793,0.020137,54.846554,2.794017,0.201372,-159.375244,0.021221,0.000000
17.280001,12.689339,-159.419724,0.002807,0.000806,0.020475,56.444996,2.875445,0.204748,-159.419724,0.021498,0.000000
17.450001,12.858391,-159.419724,0.002794,0.000818,0.020770,57.196980,2.913753,0.207700,-159.419724,0.021784,0.000000
17.620001,13.203209,-159.464203,0.002811,0.000833,0.021169,58.730808,2.991890,0.211689,-159.464203,0.022070,0.000000
17.790001,13.548401,-159.508698,0.002824,0.000848,0.021533,60.266296,3.070112,0.215330,-159.508698,0.022348,0.000000
17.960001,13.612450,-159.508698,0.002837,0.000858,0.021784,60.551201,3.084625,0.217843,-159.508698,0.022634,0.000000
18.130001,13.690277,-159.419724,0.002854,0.000865,0.021975,60.897392,3.102261,0.219751,-159.419724,0.022921,0.000000
18.300001,13.920769,-159.597656,0.002854,0.000877,0.022288,61.922672,3.154491,0.222877,-159.597656,0.023198,0.000000
18.470001,14.049614,-159.553177,0.002854,0.000886,0.022513,62.495804,3.183688,0.225133,-159.553177,0.023485,0.000000
18.640001,14.353844,-159.642136,0.002876,0.000899,0.022825,63.849087,3.252627,0.228252,-159.642136,0.023771,0.000000
18.810001,14.554924,-159.642136,0.002880,0.000908,0.023059,64.743538,3.298193,0.230591,-159.642136,0.024048,0.000000
18.980001,14.613014,-159.642136,0.002897,0.000915,0.023251,65.001930,3.311356,0.232506,-159.642136,0.024335,0.000000
19.150002,14.974586,-159.686615,0.002897,0.000929,0.023597,66.610291,3.393290,0.235973,-159.686615,0.024621,0.000000
19.320002,15.358505,-159.686615,0.002902,0.000942,0.023927,68.318047,3.480287,0.239266,-159.686615,0.024898,0.000000
19.490002,15.764763,-159.775574,0.002919,0.000958,0.024326,70.125168,3.572346,0.243255,-159.775574,0.025184,0.000000
19.660002,15.940895,-159.775574,0.002932,0.000969,0.024621,70.908646,3.612258,0.246207,-159.775574,0.025470,0.000000
19.830002,16.132294,-159.731094,0.002945,0.000982,0.024933,71.760025,3.655630,0.249326,-159.731094,0.025748,0.000000
20.000000,16.298370,-159.775574,0.002949,0.000991,0.025184,72.498772,3.693264,0.251839,-159.775574,0.026034,0.000000
20.170000,16.455139,-159.820053,0.002971,0.001002,0.025453,73.196114,3.728788,0.254527,-159.820053,0.026320,0.000000
20.340000,16.572433,-159.820053,0.002971,0.001010,0.025661,73.717865,3.755367,0.256608,-159.820053,0.026598,0.000000
20.510000,16.968269,-159.909012,0.002971,0.001023,0.025973,75.478630,3.845065,0.259735,-159.909012,0.026884,0.000000
20.680000,17.171585,-159.820053,0.002979,0.001032,0.026207,76.383026,3.891137,0.262074,-159.820053,0.027170,0.000000
20.850000,17.335426,-159.909012,0.002997,0.001043,0.026485,77.111824,3.928264,0.264852,-159.909012,0.027447,0.000000
21.020000,17.710037,-159.953506,0.002988,0.001055,0.026806,78.778183,4.013152,0.268061,-159.953506,0.027733,0.000000
21.190001,18.152412,-159.997986,0.003005,0.001069,0.027161,80.745964,4.113396,0.271612,-159.997986,0.028020,0.000000
21.360001,18.408607,-159.953506,0.003035,0.001083,0.027500,81.885574,4.171450,0.274995,-159.953506,0.028297,0.000000
21.530001,18.761986,-159.909012,0.003044,0.001096,0.027830,83.457481,4.251527,0.278296,-159.909012,0.028584,0.000000
21.700001,18.901253,-160.042465,0.003040,0.001107,0.028107,84.076973,4.283085,0.281066,-160.042465,0.028870,0.000000
21.870001,18.980568,-160.086945,0.003057,0.001115,0.028315,84.429787,4.301058,0.283148,-160.086945,0.029147,0.000000
22.040001,19.225220,-160.131424,0.003065,0.001126,0.028593,85.518051,4.356497,0.285926,-160.131424,0.029434,0.000000
22.210001,19.560722,-160.131424,0.003078,0.001138,0.028904,87.010437,4.432523,0.289045,-160.131424,0.029720,0.000000
22.380001,19.841866,-160.131424,0.003070,0.001149,0.029182,88.261024,4.496231,0.291823,-160.131424,0.029998,0.000000
22.550001,20.130455,-160.131424,0.003087,0.001161,0.029477,89.544739,4.561626,0.294768,-160.131424,0.030284,0.000000
22.720001,20.240677,-160.086945,0.003096,0.001167,0.029633,90.035027,4.586603,0.296327,-160.086945,0.030570,0.000000
22.890001,20.268608,-160.220383,0.003104,0.001172,0.029772,90.159271,4.592932,0.297720,-160.220383,0.030847,0.000000
23.060001,20.544907,-160.220383,0.003104,0.001185,0.030110,91.388306,4.655542,0.301104,-160.220383,0.031133,0.000000
23.230001,21.540260,-160.220383,0.003113,0.001206,0.030630,95.815865,4.881093,0.306304,-160.220383,0.031419,0.000000
23.400002,21.800171,-160.220383,0.003122,0.001215,0.030864,96.972000,4.939989,0.308643,-160.220383,0.031697,0.000000
23.570002,21.934601,-160.264862,0.003143,0.001226,0.031142,97.569977,4.970452,0.311421,-160.264862,0.031983,0.000000
23.740002,22.217606,-160.309341,0.003143,0.001237,0.031419,98.828842,5.034582,0.314192,-160.309341,0.032269,0.000000
23.910002,22.590721,-160.309341,0.003147,0.001248,0.031697,100.488548,5.119131,0.316970,-160.309341,0.032555,0.000000
24.080002,22.835373,-160.309341,0.003169,0.001259,0.031975,101.576813,5.174569,0.319748,-160.309341,0.032833,0.000000
24.250002,23.041664,-160.353836,0.003165,0.001268,0.032209,102.494438,5.221316,0.322087,-160.353836,0.033119,0.000000
24.420002,23.501915,-160.442795,0.003182,0.001282,0.032573,104.541740,5.325610,0.325728,-160.442795,0.033405,0.000000
24.590002,23.783798,-160.487274,0.003195,0.001291,0.032781,105.795616,5.389486,0.327810,-160.487274,0.033683,0.000000
24.760000,24.143517,-160.398315,0.003186,0.001302,0.033059,107.395729,5.470999,0.330588,-160.398315,0.033969,0.000000
24.930000,24.012810,-160.398315,0.003208,0.001306,0.033172,106.814316,5.441381,0.331716,-160.398315,0.034256,0.000000
25.100000,25.037209,-160.442795,0.003212,0.001327,0.033709,111.371063,5.673512,0.337090,-160.442795,0.034533,0.000000
25.270000,25.510864,-160.487274,0.003221,0.001339,0.034013,113.477989,5.780844,0.340126,-160.487274,0.034819,0.000000
25.440001,25.817329,-160.531754,0.003242,0.001351,0.034316,114.841217,5.850291,0.343161,-160.531754,0.035105,0.000000
25.610001,26.107780,-160.576233,0.003242,0.001362,0.034594,116.133209,5.916108,0.345939,-160.576233,0.035383,0.000000
25.780001,26.306625,-160.576233,0.003255,0.001372,0.034836,117.017715,5.961166,0.348362,-160.576233,0.035669,0.000000
25.950001,26.410889,-160.531754,0.003247,0.001379,0.035027,117.481499,5.984793,0.350269,-160.531754,0.035955,0.000000
26.120001,26.805229,-160.620712,0.003264,0.001390,0.035313,119.235611,6.074152,0.353131,-160.620712,0.036233,0.000000
26.290001,27.528755,-160.665192,0.003281,0.001406,0.035712,122.454018,6.238105,0.357120,-160.665192,0.036519,0.000000
26.460001,28.117844,-160.665192,0.003277,0.001419,0.036033,125.074417,6.371594,0.360330,-160.665192,0.036805,0.000000
26.630001,28.276100,-160.665192,0.003298,0.001426,0.036233,125.778374,6.407456,0.362328,-160.665192,0.037082,0.000000
26.800001,28.351692,-160.709671,0.003285,0.001433,0.036397,126.114624,6.424585,0.363971,-160.709671,0.037369,0.000000
26.970001,28.981750,-160.843124,0.003303,0.001448,0.036779,128.917267,6.567358,0.367793,-160.843124,0.037655,0.000000
27.140001,29.558929,-160.843124,0.003316,0.001459,0.037056,131.484680,6.698149,0.370564,-160.843124,0.037932,0.000000
27.310001,29.897789,-160.754150,0.003320,0.001470,0.037334,132.992004,6.774936,0.373342,-160.754150,0.038218,0.000000
27.480001,30.517044,-160.754150,0.003328,0.001484,0.037681,135.746597,6.915261,0.376809,-160.754150,0.038504,0.000000
27.650002,30.803398,-160.887604,0.003333,0.001494,0.037959,137.020355,6.980150,0.379587,-160.887604,0.038782,0.000000
27.820002,31.096077,-160.843124,0.003354,0.001503,0.038184,138.322266,7.046472,0.381835,-160.843124,0.039068,0.000000
27.990002,31.525429,-160.932083,0.003350,0.001513,0.038436,140.232117,7.143764,0.384356,-160.932083,0.039355,0.000000
28.160002,32.022545,-160.843124,0.003359,0.001525,0.038730,142.443390,7.256412,0.387301,-160.843124,0.039632,0.000000
28.330002,32.810486,-160.932083,0.003363,0.001541,0.039138,145.948334,7.434962,0.391381,-160.932083,0.039919,0.000000
28.500002,33.157532,-160.976562,0.003363,0.001550,0.039372,147.492065,7.513604,0.393720,-160.976562,0.040205,0.000000
28.670002,33.237968,-161.021042,0.003385,0.001555,0.039502,147.849869,7.531831,0.395022,-161.021042,0.040482,0.000000
28.840002,33.458786,-161.021042,0.003380,0.001564,0.039736,148.832108,7.581869,0.397361,-161.021042,0.040768,0.000000
29.010002,34.759850,-161.021042,0.003393,0.001586,0.040283,154.619537,7.876694,0.402826,-161.021042,0.041055,0.000000
29.180002,35.114349,-160.976562,0.003402,0.001594,0.040482,156.196426,7.957025,0.404817,-160.976562,0.041332,0.000000
29.350002,35.449860,-161.110001,0.003410,0.001606,0.040785,157.688858,8.033053,0.407853,-161.110001,0.041618,0.000000
29.520000,36.124222,-161.110001,0.003419,0.001617,0.041080,160.688568,8.185865,0.410805,-161.110001,0.041904,0.000000
29.690001,36.385628,-161.154480,0.003436,0.001626,0.041289,161.851349,8.245101,0.412887,-161.154480,0.042182,0.000000
29.860001,36.688744,-161.065521,0.003432,0.001633,0.041488,163.199677,8.313787,0.414877,-161.065521,0.042468,0.000000
30.030001,37.157188,-161.198959,0.003441,0.001647,0.041844,165.283432,8.419939,0.418435,-161.198959,0.042754,0.000000
30.200001,38.146584,-161.198959,0.003432,0.001663,0.042242,169.684479,8.644139,0.422425,-161.198959,0.043032,0.000000
30.370001,38.709610,-161.243454,0.003449,0.001673,0.042485,172.188950,8.771723,0.424854,-161.243454,0.043318,0.000000
30.540001,39.017563,-161.287933,0.003458,0.001682,0.042711,173.558792,8.841506,0.427110,-161.287933,0.043604,0.000000
30.710001,39.353065,-161.243454,0.003475,0.001689,0.042910,175.051178,8.917532,0.429101,-161.243454,0.043881,0.000000
30.880001,39.883324,-161.243454,0.003479,0.001703,0.043257,177.409882,9.037690,0.432568,-161.243454,0.044167,0.000000
31.050001,40.728981,-161.287933,0.003475,0.001716,0.043595,181.171555,9.229320,0.435952,-161.287933,0.044454,0.000000
31.220001,41.273018,-161.421371,0.003488,0.001727,0.043873,183.591553,9.352599,0.438730,-161.421371,0.044731,0.000000
31.390001,41.809235,-161.421371,0.003492,0.001737,0.044124,185.976761,9.474108,0.441243,-161.421371,0.045018,0.000000
31.560001,42.429611,-161.376892,0.003510,0.001749,0.044428,188.736343,9.614687,0.444279,-161.376892,0.045304,0.000000
31.730001,42.761765,-161.376892,0.003505,0.001758,0.044653,190.213821,9.689955,0.446534,-161.376892,0.045581,0.000000
31.900002,43.197441,-161.421371,0.003510,0.001768,0.044896,192.151810,9.788680,0.448964,-161.421371,0.045868,0.000000
32.070000,43.869576,-161.465851,0.003514,0.001778,0.045156,195.141617,9.940988,0.451561,-161.465851,0.046154,0.000000
32.240002,44.843697,-161.510330,0.003523,0.001794,0.045564,199.474731,10.161727,0.455641,-161.510330,0.046440,0.000000
32.410000,45.321823,-161.465851,0.003535,0.001803,0.045798,201.601532,10.270072,0.457980,-161.465851,0.046718,0.000000
32.580002,45.723244,-161.510330,0.003535,0.001811,0.046006,203.387146,10.361035,0.460062,-161.510330,0.047004,0.000000
32.750000,45.937729,-161.554810,0.003531,0.001817,0.046162,204.341217,10.409638,0.461621,-161.554810,0.047290,0.000000
32.920002,46.375267,-161.688263,0.003548,0.001834,0.046578,206.287491,10.508785,0.465784,-161.688263,0.047567,0.000000
33.090000,47.762726,-161.599289,0.003553,0.001848,0.046943,212.459213,10.823188,0.469425,-161.599289,0.047853,0.000000
33.260002,48.395012,-161.554810,0.003566,0.001859,0.047229,215.271759,10.966466,0.472287,-161.554810,0.048139,0.000000
33.430000,49.282005,-161.599289,0.003561,0.001874,0.047594,219.217316,11.167462,0.475935,-161.599289,0.048417,0.000000
33.600002,49.499847,-161.643784,0.003557,0.001880,0.047740,220.186325,11.216826,0.477404,-161.643784,0.048703,0.000000
33.770000,50.125061,-161.643784,0.003583,0.001891,0.048036,222.967407,11.358501,0.480356,-161.643784,0.048989,0.000000
33.940002,50.532806,-161.643784,0.003587,0.001899,0.048235,224.781143,11.450897,0.482347,-161.643784,0.049267,0.000000
34.110001,51.197121,-161.643784,0.003587,0.001913,0.048600,227.736160,11.601433,0.485996,-161.643784,0.049553,0.000000
34.280003,52.432648,-161.732742,0.003596,0.001927,0.048955,233.232071,11.881408,0.489546,-161.732742,0.049839,0.000000
34.450001,52.777466,-161.777222,0.003600,0.001935,0.049145,234.765900,11.959545,0.491453,-161.777222,0.050117,0.000000
34.620003,52.825874,-161.821701,0.003604,0.001939,0.049258,234.981232,11.970514,0.492581,-161.821701,0.050403,0.000000
34.790001,53.502106,-161.821701,0.003609,0.001951,0.049544,237.989258,12.123751,0.495443,-161.821701,0.050690,0.000000
34.960003,54.516815,-161.910660,0.003609,0.001965,0.049917,242.502899,12.353686,0.499175,-161.910660,0.050967,0.000000
35.130001,55.543449,-161.821701,0.003630,0.001980,0.050299,247.069595,12.586326,0.502990,-161.821701,0.051253,0.000000
35.300003,56.507149,-161.999619,0.003626,0.001996,0.050690,251.356354,12.804703,0.506896,-161.999619,0.051539,0.000000
35.470001,56.870583,-161.955139,0.003635,0.002003,0.050880,252.972992,12.887058,0.508803,-161.955139,0.051817,0.000000
35.640003,57.499893,-161.910660,0.003639,0.002013,0.051132,255.772293,13.029662,0.511317,-161.910660,0.052103,0.000000
35.810001,58.132179,-161.955139,0.003648,0.002024,0.051418,258.584839,13.172940,0.514178,-161.955139,0.052389,0.000000
35.980003,58.928688,-161.999619,0.003643,0.002035,0.051678,262.127899,13.353432,0.516782,-161.999619,0.052667,0.000000
36.150002,59.841743,-162.044098,0.003656,0.002049,0.052033,266.189362,13.560333,0.520332,-162.044098,0.052953,0.000000
36.320004,60.221939,-162.044098,0.003673,0.002056,0.052224,267.880554,13.646486,0.522240,-162.044098,0.053239,0.000000
36.490002,60.532494,-161.999619,0.003669,0.002062,0.052363,269.261993,13.716860,0.523633,-161.999619,0.053516,0.000000
36.660000,61.375175,-162.088593,0.003665,0.002074,0.052684,273.010406,13.907814,0.526842,-162.088593,0.053802,0.000000
36.830002,61.649986,-162.088593,0.003669,0.002080,0.052831,274.232849,13.970086,0.528311,-162.088593,0.054089,0.000000
37.000000,63.300705,-162.133072,0.003669,0.002103,0.053412,281.575592,14.344145,0.534124,-162.133072,0.054366,0.000000
37.170002,64.674026,-162.133072,0.003699,0.002119,0.053811,287.684448,14.655344,0.538114,-162.133072,0.054652,0.000000
37.340000,65.061295,-162.177551,0.003708,0.002127,0.054020,289.407104,14.743100,0.540195,-162.177551,0.054939,0.000000
37.510002,65.648895,-162.177551,0.003691,0.002136,0.054245,292.020874,14.876252,0.542451,-162.177551,0.055216,0.000000
37.680000,66.146378,-162.177551,0.003691,0.002144,0.054462,294.233795,14.988984,0.544616,-162.177551,0.055502,0.000000
37.850002,66.528442,-162.222031,0.003717,0.002154,0.054713,295.933289,15.075561,0.547129,-162.222031,0.055789,0.000000
38.020000,67.421387,-162.222031,0.003717,0.002167,0.055043,299.905304,15.277905,0.550430,-162.222031,0.056066,0.000000
38.190002,67.398300,-162.310989,0.003729,0.002158,0.054808,299.802612,15.272674,0.548083,-162.310989,0.055051,0.000000
38.360001,67.091843,-162.266510,0.003717,0.002158,0.054808,298.439423,15.203229,0.548083,-162.266510,0.055051,0.000000
38.530003,66.881073,-162.355469,0.003725,0.002155,0.054730,297.501862,15.155468,0.547303,-162.355469,0.054808,0.000000
38.700001,66.660263,-162.399948,0.003712,0.002154,0.054705,296.519653,15.105432,0.547046,-162.399948,0.054808,0.000000
38.870003,66.477051,-162.355469,0.003738,0.002153,0.054687,295.704681,15.063915,0.546872,-162.355469,0.054808,0.000000
39.040001,66.312454,-162.399948,0.003729,0.002153,0.054679,294.972534,15.026616,0.546789,-162.399948,0.054808,0.000000
39.210003,66.154205,-162.399948,0.003738,0.002152,0.054670,294.268616,14.990758,0.546698,-162.399948,0.054808,0.000000
39.380001,66.022003,-162.444427,0.003734,0.002152,0.054661,293.680542,14.960800,0.546615,-162.444427,0.054808,0.000000
39.550003,65.875671,-162.444427,0.003734,0.002152,0.054661,293.029633,14.927641,0.546615,-162.444427,0.054808,0.000000
39.720001,65.778854,-162.488907,0.003738,0.002152,0.054652,292.598969,14.905701,0.546524,-162.488907,0.054808,0.000000
39.890003,65.663788,-162.488907,0.003721,0.002152,0.054652,292.087128,14.879627,0.546524,-162.488907,0.054808,0.000000
40.060001,65.572189,-162.533401,0.003738,0.002152,0.054652,291.679657,14.858871,0.546524,-162.533401,0.054808,0.000000
40.230003,65.474625,-162.577881,0.003725,0.002152,0.054652,291.245667,14.836762,0.546524,-162.577881,0.054808,0.000000
40.400002,65.374451,-162.622360,0.003742,0.002152,0.054652,290.800079,14.814062,0.546524,-162.622360,0.054808,0.000000
40.570004,65.298859,-162.577881,0.003734,0.002152,0.054652,290.463837,14.796933,0.546524,-162.577881,0.054808,0.000000
40.740002,65.232956,-162.622360,0.003738,0.002152,0.054652,290.170685,14.782000,0.546524,-162.622360,0.054808,0.000000
40.910004,65.149918,-162.622360,0.003725,0.002151,0.054644,289.801300,14.763183,0.546440,-162.622360,0.054808,0.000000
41.080002,65.067245,-162.711319,0.003725,0.002151,0.054644,289.433563,14.744449,0.546440,-162.711319,0.054808,0.000000
41.250004,65.018463,-162.755798,0.003734,0.002151,0.054644,289.216583,14.733395,0.546440,-162.755798,0.054808,0.000000
41.420002,64.943619,-162.666840,0.003725,0.002151,0.054644,288.883636,14.716434,0.546440,-162.666840,0.054808,0.000000
41.590000,64.899673,-162.755798,0.003725,0.002151,0.054644,288.688171,14.706476,0.546440,-162.755798,0.054808,0.000000
41.760002,64.835266,-162.755798,0.003738,0.002151,0.054644,288.401672,14.691882,0.546440,-162.755798,0.054808,0.000000
41.930000,64.779770,-162.800278,0.003734,0.002151,0.054644,288.154816,14.679305,0.546440,-162.800278,0.054808,0.000000
42.100002,64.726151,-162.844757,0.003734,0.002151,0.054644,287.916290,14.667155,0.546440,-162.844757,0.054808,0.000000
42.270000,64.667694,-162.800278,0.003747,0.002151,0.054644,287.656281,14.653909,0.546440,-162.800278,0.054808,0.000000
42.440002,64.628220,-162.844757,0.003747,0.002151,0.054644,287.480682,14.644963,0.546440,-162.844757,0.054808,0.000000
42.610001,64.572739,-162.889236,0.003738,0.002151,0.054644,287.233887,14.632392,0.546440,-162.889236,0.054808,0.000000
42.780003,64.538483,-162.933731,0.003747,0.002151,0.054644,287.081512,14.624629,0.546440,-162.933731,0.054808,0.000000
42.950001,64.476288,-162.978210,0.003742,0.002151,0.054644,286.804840,14.610536,0.546440,-162.978210,0.054808,0.000000
43.120003,64.457306,-162.933731,0.003742,0.002151,0.054644,286.720428,14.606235,0.546440,-162.933731,0.054808,0.000000
43.290001,64.401443,-162.978210,0.003738,0.002151,0.054644,286.471924,14.593575,0.546440,-162.978210,0.054808,0.000000
43.460003,64.347076,-162.978210,0.003747,0.002151,0.054644,286.230103,14.581256,0.546440,-162.978210,0.054808,0.000000
43.630001,64.314682,-163.067169,0.003742,0.002151,0.054644,286.085999,14.573915,0.546440,-163.067169,0.054808,0.000000
43.800003,64.273346,-163.067169,0.003742,0.002151,0.054644,285.902130,14.564548,0.546440,-163.067169,0.054808,0.000000
43.970001,64.245056,-163.067169,0.003747,0.002151,0.054644,285.776276,14.558138,0.546440,-163.067169,0.054808,0.000000
44.140003,64.209305,-163.111649,0.003738,0.002151,0.054644,285.617249,14.550036,0.546440,-163.111649,0.054808,0.000000
44.310001,64.171326,-163.111649,0.003742,0.002151,0.054644,285.448303,14.541430,0.546440,-163.111649,0.054808,0.000000
44.480003,64.132965,-163.200607,0.003738,0.002151,0.054644,285.277679,14.532737,0.546440,-163.200607,0.054808,0.000000
44.650002,64.117325,-163.156128,0.003738,0.002151,0.054644,285.208099,14.529194,0.546440,-163.156128,0.054808,0.000000
44.820004,64.084930,-163.200607,0.003742,0.002151,0.054644,285.063995,14.521853,0.546440,-163.200607,0.054808,0.000000
44.990002,64.054398,-163.200607,0.003734,0.002151,0.054644,284.928192,14.514935,0.546440,-163.200607,0.054808,0.000000
45.160004,64.003754,-163.200607,0.003738,0.002151,0.054644,284.702911,14.503457,0.546440,-163.200607,0.054808,0.000000
45.330002,63.984390,-163.289566,0.003747,0.002151,0.054644,284.616791,14.499070,0.546440,-163.289566,0.054808,0.000000
45.500004,63.968750,-163.289566,0.003742,0.002151,0.054644,284.547211,14.495525,0.546440,-163.289566,0.054808,0.000000
45.670002,63.930023,-163.289566,0.003751,0.002151,0.054644,284.374939,14.486751,0.546440,-163.289566,0.054808,0.000000
45.840004,63.913635,-163.245087,0.003742,0.002151,0.054644,284.302063,14.483037,0.546440,-163.245087,0.054808,0.000000
46.010002,63.881989,-163.378540,0.003725,0.002151,0.054644,284.161285,14.475865,0.546440,-163.378540,0.054808,0.000000
46.180000,63.861877,-163.378540,0.003747,0.002151,0.054644,284.071808,14.471308,0.546440,-163.378540,0.054808,0.000000
46.350002,63.827621,-163.467499,0.003755,0.002151,0.054644,283.919434,14.463546,0.546440,-163.467499,0.054808,0.000000
46.520000,63.804901,-163.378540,0.003751,0.002151,0.054644,283.818390,14.458397,0.546440,-163.378540,0.054808,0.000000
46.690002,63.771759,-163.423019,0.003738,0.002151,0.054644,283.670959,14.450888,0.546440,-163.423019,0.054808,0.000000
46.860001,63.756500,-163.511978,0.003729,0.002151,0.054644,283.603088,14.447429,0.546440,-163.511978,0.054808,0.000000
47.030003,63.716278,-163.511978,0.003751,0.002151,0.054644,283.424164,14.438315,0.546440,-163.511978,0.054808,0.000000
47.200001,63.712921,-163.511978,0.003747,0.002151,0.054644,283.409241,14.437554,0.546440,-163.511978,0.054808,0.000000
47.370003,63.671600,-163.511978,0.003747,0.002151,0.054644,283.225433,14.428191,0.546440,-163.511978,0.054808,0.000000
47.540001,63.662292,-163.467499,0.003747,0.002151,0.054644,283.184021,14.426082,0.546440,-163.467499,0.054808,0.000000
47.710003,63.631744,-163.600937,0.003738,0.002151,0.054644,283.048126,14.419159,0.546440,-163.600937,0.054808,0.000000
47.880001,63.618347,-163.600937,0.003738,0.002151,0.054644,282.988556,14.416123,0.546440,-163.600937,0.054808,0.000000
48.050003,63.588928,-163.645416,0.003751,0.002151,0.054644,282.857666,14.409457,0.546440,-163.645416,0.054808,0.000000
48.220001,63.572922,-163.600937,0.003747,0.002151,0.054644,282.786469,14.405830,0.546440,-163.600937,0.054808,0.000000
48.390003,63.553925,-163.645416,0.003751,0.002151,0.054644,282.701965,14.401525,0.546440,-163.645416,0.054808,0.000000
48.560001,63.526001,-163.689896,0.003742,0.002151,0.054644,282.577759,14.395197,0.546440,-163.689896,0.054808,0.000000
48.730003,63.517426,-163.778854,0.003747,0.002151,0.054644,282.539612,14.393255,0.546440,-163.778854,0.054808,0.000000
48.900002,63.480942,-163.823349,0.003751,0.002151,0.054644,282.377319,14.384987,0.546440,-163.823349,0.054808,0.000000
49.070004,63.486526,-163.734375,0.003742,0.002151,0.054644,282.402161,14.386252,0.546440,-163.734375,0.054808,0.000000
49.240002,63.439606,-163.778854,0.003755,0.002151,0.054644,282.193451,14.375620,0.546440,-163.778854,0.054808,0.000000
49.410004,63.440353,-163.867828,0.003734,0.002151,0.054644,282.196777,14.375790,0.546440,-163.867828,0.054808,0.000000
49.580002,63.405716,-163.912308,0.003742,0.002151,0.054644,282.042725,14.367941,0.546440,-163.912308,0.054808,0.000000
49.750004,63.411301,-163.823349,0.003751,0.002151,0.054644,282.067566,14.369206,0.546440,-163.823349,0.054808,0.000000
49.920002,63.375183,-163.823349,0.003747,0.002151,0.054644,281.906891,14.361022,0.546440,-163.823349,0.054808,0.000000
50.090004,63.372574,-163.912308,0.003751,0.002151,0.054644,281.895294,14.360431,0.546440,-163.912308,0.054808,0.000000
50.260002,63.349487,-163.956787,0.003755,0.002151,0.054644,281.792603,14.355199,0.546440,-163.956787,0.054808,0.000000
50.430004,63.333481,-163.956787,0.003742,0.002151,0.054644,281.721405,14.351572,0.546440,-163.956787,0.054808,0.000000
50.600002,63.316345,-164.001266,0.003751,0.002151,0.054644,281.645172,14.347690,0.546440,-164.001266,0.054808,0.000000
50.770004,63.300705,-163.956787,0.003755,0.002151,0.054644,281.575592,14.344145,0.546440,-163.956787,0.054808,0.000000
50.940002,63.289169,-164.001266,0.003760,0.002151,0.054644,281.524292,14.341531,0.546440,-164.001266,0.054808,0.000000
51.110001,63.260117,-164.134705,0.003751,0.002151,0.054644,281.395050,14.334947,0.546440,-164.134705,0.054808,0.000000
51.280003,63.254913,-164.090225,0.003751,0.002151,0.054644,281.371918,14.333768,0.546440,-164.090225,0.054808,0.000000
51.450001,63.230713,-164.134705,0.003755,0.002151,0.054644,281.264252,14.328284,0.546440,-164.134705,0.054808,0.000000
51.620003,63.209488,-164.134705,0.003760,0.002151,0.054644,281.169830,14.323474,0.546440,-164.134705,0.054808,0.000000
51.790001,63.202408,-164.134705,0.003751,0.002151,0.054644,281.138336,14.321870,0.546440,-164.134705,0.054808,0.000000
51.960003,63.187881,-164.223679,0.003747,0.002151,0.054644,281.073730,14.318579,0.546440,-164.223679,0.054808,0.000000
52.130001,63.163681,-164.179184,0.003751,0.002151,0.054644,280.966095,14.313095,0.546440,-164.179184,0.054808,0.000000
52.300003,63.168152,-164.179184,0.003747,0.002151,0.054644,280.985962,14.314108,0.546440,-164.179184,0.054808,0.000000
52.470001,63.130539,-164.268158,0.003751,0.002151,0.054644,280.818665,14.305584,0.546440,-164.268158,0.054808,0.000000
52.640003,63.140213,-164.268158,0.003747,0.002151,0.054644,280.861694,14.307777,0.546440,-164.268158,0.054808,0.000000
52.810001,63.114899,-164.312637,0.003747,0.002151,0.054644,280.749084,14.302040,0.546440,-164.312637,0.054808,0.000000
52.980003,63.103348,-164.312637,0.003742,0.002151,0.054644,280.697723,14.299423,0.546440,-164.312637,0.054808,0.000000
53.150002,63.083984,-164.312637,0.003760,0.002151,0.054644,280.611572,14.295035,0.546440,-164.312637,0.054808,0.000000
53.320004,63.075058,-164.357117,0.003747,0.002151,0.054644,280.571869,14.293013,0.546440,-164.357117,0.054808,0.000000
53.490002,63.057922,-164.401596,0.003747,0.002151,0.054644,280.495636,14.289130,0.546440,-164.401596,0.054808,0.000000
53.660004,63.056442,-164.446075,0.003755,0.002151,0.054644,280.489075,14.288794,0.546440,-164.446075,0.054808,0.000000
53.830002,63.019577,-164.401596,0.003747,0.002151,0.054644,280.325073,14.280439,0.546440,-164.401596,0.054808,0.000000
54.000004,63.018829,-164.401596,0.003755,0.002151,0.054644,280.321747,14.280272,0.546440,-164.401596,0.054808,0.000000
54.170002,63.002075,-164.490555,0.003734,0.002151,0.054644,280.247223,14.276474,0.546440,-164.490555,0.054808,0.000000
54.340004,62.995743,-164.490555,0.003751,0.002151,0.054644,280.219055,14.275039,0.546440,-164.490555,0.054808,0.000000
54.510002,62.974144,-164.535034,0.003751,0.002151,0.054644,280.122986,14.270145,0.546440,-164.535034,0.054808,0.000000
54.680004,62.980843,-164.579514,0.003734,0.002151,0.054644,280.152771,14.271663,0.546440,-164.579514,0.054808,0.000000
54.850002,62.946587,-164.490555,0.003747,0.002151,0.054644,280.000397,14.263900,0.546440,-164.490555,0.054808,0.000000
55.020004,62.941376,-164.579514,0.003751,0.002151,0.054644,279.977234,14.262720,0.546440,-164.579514,0.054808,0.000000
55.190002,62.920891,-164.623993,0.003751,0.002151,0.054644,279.886108,14.258078,0.546440,-164.623993,0.054808,0.000000
55.360004,62.911209,-164.668488,0.003734,0.002151,0.054644,279.843048,14.255884,0.546440,-164.668488,0.054808,0.000000
55.530003,62.889244,-164.623993,0.003751,0.002151,0.054644,279.745331,14.250906,0.546440,-164.623993,0.054808,0.000000
55.700001,62.894455,-164.623993,0.003747,0.002151,0.054644,279.768494,14.252088,0.546440,-164.623993,0.054808,0.000000
55.870003,62.890358,-164.668488,0.003760,0.002151,0.054644,279.750275,14.251159,0.546440,-164.668488,0.054808,0.000000
56.040001,62.867645,-164.801926,0.003747,0.002151,0.054644,279.649261,14.246012,0.546440,-164.801926,0.054808,0.000000
56.210003,62.864662,-164.757446,0.003751,0.002151,0.054644,279.635986,14.245337,0.546440,-164.757446,0.054808,0.000000
56.380001,62.854980,-164.757446,0.003755,0.002151,0.054644,279.592926,14.243142,0.546440,-164.757446,0.054808,0.000000
56.550003,62.829292,-164.757446,0.003751,0.002151,0.054644,279.478638,14.237321,0.546440,-164.757446,0.054808,0.000000
56.720001,62.821838,-164.846405,0.003760,0.002151,0.054644,279.445496,14.235632,0.546440,-164.846405,0.054808,0.000000
56.890003,62.806572,-164.846405,0.003747,0.002151,0.054644,279.377594,14.232173,0.546440,-164.846405,0.054808,0.000000
57.060001,62.797264,-164.846405,0.003755,0.002151,0.054644,279.336182,14.230063,0.546440,-164.846405,0.054808,0.000000
57.230003,62.787582,-164.846405,0.003755,0.002151,0.054644,279.293121,14.227870,0.546440,-164.846405,0.054808,0.000000
57.400002,62.779022,-164.846405,0.003738,0.002151,0.054644,279.255035,14.225929,0.546440,-164.846405,0.054808,0.000000
57.570004,62.767471,-164.935364,0.003755,0.002151,0.054644,279.203644,14.223312,0.546440,-164.935364,0.054808,0.000000
57.740002,62.752579,-164.935364,0.003747,0.002151,0.054644,279.137421,14.219938,0.546440,-164.935364,0.054808,0.000000
57.910004,62.738800,-164.979843,0.003760,0.002151,0.054644,279.076111,14.216816,0.546440,-164.979843,0.054808,0.000000
58.080002,62.730614,-164.979843,0.003760,0.002151,0.054644,279.039703,14.214960,0.546440,-164.979843,0.054808,0.000000
58.250004,62.722794,-165.024323,0.003751,0.002151,0.054644,279.004913,14.213188,0.546440,-165.024323,0.054808,0.000000
58.420002,62.710129,-165.068802,0.003751,0.002151,0.054644,278.948578,14.210319,0.546440,-165.068802,0.054808,0.000000
58.590004,62.696350,-165.024323,0.003751,0.002151,0.054644,278.887299,14.207196,0.546440,-165.024323,0.054808,0.000000
58.760002,62.699333,-165.113297,0.003747,0.002151,0.054644,278.900574,14.207871,0.546440,-165.113297,0.054808,0.000000
58.930004,62.682205,-165.113297,0.003755,0.002151,0.054644,278.824371,14.203991,0.546440,-165.113297,0.054808,0.000000
59.100002,62.673264,-165.068802,0.003751,0.002151,0.054644,278.784607,14.201964,0.546440,-165.068802,0.054808,0.000000
59.270004,62.654274,-165.157776,0.003742,0.002151,0.054644,278.700134,14.197661,0.546440,-165.157776,0.054808,0.000000
59.440002,62.647942,-165.202255,0.003751,0.002151,0.054644,278.671967,14.196227,0.546440,-165.202255,0.054808,0.000000
59.610004,62.635658,-165.202255,0.003747,0.002151,0.054644,278.617310,14.193443,0.546440,-165.202255,0.054808,0.000000
59.780003,62.634911,-165.202255,0.003747,0.002151,0.054644,278.613983,14.193274,0.546440,-165.202255,0.054808,0.000000
59.950005,62.613312,-165.246735,0.003747,0.002151,0.054644,278.517914,14.188379,0.546440,-165.246735,0.054808,0.000000
60.120003,62.611450,-165.291214,0.003747,0.002151,0.054644,278.509644,14.187957,0.546440,-165.291214,0.054808,0.000000
60.290005,62.593208,-165.335693,0.003747,0.002151,0.054644,278.428497,14.183824,0.546440,-165.335693,0.054808,0.000000
60.460003,62.602890,-165.335693,0.003751,0.002151,0.054644,278.471558,14.186018,0.546440,-165.335693,0.054808,0.000000
60.630001,62.577568,-165.291214,0.003751,0.002151,0.054644,278.358917,14.180280,0.546440,-165.291214,0.054808,0.000000
60.800003,62.576820,-165.291214,0.003755,0.002151,0.054644,278.355591,14.180110,0.546440,-165.291214,0.054808,0.000000
60.970001,62.557083,-165.380173,0.003747,0.002151,0.054644,278.267792,14.175638,0.546440,-165.380173,0.054808,0.000000
61.140003,62.558571,-165.424652,0.003760,0.002151,0.054644,278.274414,14.175975,0.546440,-165.424652,0.054808,0.000000
61.310001,62.529160,-165.424652,0.003755,0.002151,0.054644,278.143585,14.169311,0.546440,-165.424652,0.054808,0.000000
61.480003,62.538841,-165.469131,0.003751,0.002151,0.054644,278.186646,14.171504,0.546440,-165.469131,0.054808,0.000000
61.650002,62.512024,-165.469131,0.003742,0.002151,0.054644,278.067383,14.165427,0.546440,-165.469131,0.054808,0.000000
61.820004,62.522827,-165.558105,0.003742,0.002151,0.054644,278.115417,14.167875,0.546440,-165.558105,0.054808,0.000000
61.990002,62.494156,-165.558105,0.003751,0.002151,0.054644,277.987885,14.161378,0.546440,-165.558105,0.054808,0.000000
62.160004,62.511658,-165.513626,0.003755,0.002151,0.054644,278.065735,14.165344,0.546440,-165.513626,0.054808,0.000000
62.330002,62.478516,-165.558105,0.003764,0.002151,0.054644,277.918304,14.157834,0.546440,-165.558105,0.054808,0.000000
62.500004,62.480751,-165.602585,0.003751,0.002151,0.054644,277.928253,14.158340,0.546440,-165.602585,0.054808,0.000000
62.670002,62.471069,-165.647064,0.003755,0.002151,0.054644,277.885193,14.156146,0.546440,-165.647064,0.054808,0.000000
62.840004,62.466972,-165.647064,0.003747,0.002151,0.054644,277.866974,14.155219,0.546440,-165.647064,0.054808,0.000000
63.010002,62.450958,-165.647064,0.003755,0.002151,0.054644,277.795746,14.151589,0.546440,-165.647064,0.054808,0.000000
63.180004,62.445000,-165.647064,0.003747,0.002151,0.054644,277.769226,14.150239,0.546440,-165.647064,0.054808,0.000000
63.350002,62.439415,-165.691544,0.003755,0.002151,0.054644,277.744385,14.148973,0.546440,-165.691544,0.054808,0.000000
63.520004,62.436440,-165.736023,0.003751,0.002151,0.054644,277.731140,14.148299,0.546440,-165.736023,0.054808,0.000000
63.690002,62.418564,-165.736023,0.003755,0.002151,0.054644,277.651642,14.144248,0.546440,-165.736023,0.054808,0.000000
63.860004,62.417816,-165.780502,0.003755,0.002151,0.054644,277.648315,14.144079,0.546440,-165.780502,0.054808,0.000000
64.030006,62.396965,-165.736023,0.003751,0.002151,0.054644,277.555573,14.139354,0.546440,-165.736023,0.054808,0.000000
64.200005,62.404411,-165.780502,0.003760,0.002151,0.054644,277.588684,14.141042,0.546440,-165.780502,0.054808,0.000000
64.370003,62.395103,-165.824982,0.003742,0.002151,0.054644,277.547272,14.138933,0.546440,-165.824982,0.054808,0.000000
64.540001,62.394356,-165.869461,0.003760,0.002151,0.054644,277.543945,14.138763,0.546440,-165.869461,0.054808,0.000000
64.710007,62.368668,-165.913940,0.003755,0.002151,0.054644,277.429687,14.132942,0.546440,-165.913940,0.054808,0.000000
64.880005,62.367172,-165.869461,0.003755,0.002151,0.054644,277.423035,14.132604,0.546440,-165.869461,0.054808,0.000000
65.050003,62.372757,-165.869461,0.003755,0.002151,0.054644,277.447876,14.133869,0.546440,-165.869461,0.054808,0.000000
65.220001,62.339622,-166.002914,0.003738,0.002151,0.054644,277.300476,14.126360,0.546440,-166.002914,0.054808,0.000000
65.389999,62.350792,-165.958435,0.003755,0.002151,0.054644,277.350189,14.128891,0.546440,-165.958435,0.054808,0.000000
65.560005,62.338501,-166.002914,0.003751,0.002151,0.054644,277.295502,14.126106,0.546440,-166.002914,0.054808,0.000000
65.730003,62.339249,-166.002914,0.003751,0.002151,0.054644,277.298828,14.126276,0.546440,-166.002914,0.054808,0.000000
65.900002,62.320259,-166.002914,0.003738,0.002151,0.054644,277.214355,14.121973,0.546440,-166.002914,0.054808,0.000000
66.070000,62.306107,-166.047394,0.003760,0.002151,0.054644,277.151398,14.118765,0.546440,-166.047394,0.054808,0.000000
66.240005,62.305733,-166.136353,0.003764,0.002151,0.054644,277.149750,14.118681,0.546440,-166.136353,0.054808,0.000000
66.410004,62.305359,-166.091873,0.003751,0.002151,0.054644,277.148071,14.118596,0.546440,-166.091873,0.054808,0.000000
66.580002,62.300148,-166.136353,0.003755,0.002151,0.054644,277.124908,14.117415,0.546440,-166.136353,0.054808,0.000000
66.750000,62.289352,-166.180832,0.003747,0.002151,0.054644,277.076874,14.114968,0.546440,-166.180832,0.054808,0.000000
66.920006,62.276314,-166.180832,0.003747,0.002151,0.054644,277.018890,14.112015,0.546440,-166.180832,0.054808,0.000000
67.090004,62.283020,-166.225311,0.003755,0.002151,0.054644,277.048706,14.113534,0.546440,-166.225311,0.054808,0.000000
67.260002,62.268494,-166.225311,0.003755,0.002151,0.054644,276.984100,14.110243,0.546440,-166.225311,0.054808,0.000000
67.430000,62.272217,-166.225311,0.003755,0.002151,0.054644,277.000641,14.111086,0.546440,-166.225311,0.054808,0.000000
67.600006,62.253227,-166.314270,0.003747,0.002151,0.054644,276.916199,14.106783,0.546440,-166.314270,0.054808,0.000000
67.770004,62.258812,-166.225311,0.003760,0.002151,0.054644,276.941040,14.108048,0.546440,-166.225311,0.054808,0.000000
67.940002,62.244293,-166.269791,0.003747,0.002151,0.054644,276.876434,14.104758,0.546440,-166.269791,0.054808,0.000000
68.110001,62.246895,-166.269791,0.003734,0.002151,0.054644,276.888031,14.105349,0.546440,-166.269791,0.054808,0.000000
68.280006,62.243919,-166.358749,0.003755,0.002151,0.054644,276.874786,14.104673,0.546440,-166.358749,0.054808,0.000000
68.450005,62.216736,-166.358749,0.003747,0.002151,0.054644,276.753876,14.098514,0.546440,-166.358749,0.054808,0.000000
68.500000,62.223808,-166.403244,0.003742,0.002151,0.054644,276.785309,14.100117,0.546440,-166.403244,0.054808,0.000000