File: Data/type 1 compression/Support type 1-1_04162024_185320.csv
Time (sec),S:Load (lbs),S:HL1 (DIM),S:LVDT (in),S:Position (in),Ch:Position (mm),Ch:Load (N),Ch:Stress (MPa),Ch:Strain (mm/mm),Ch:HL1 (DIM),Set Point (),Cycles ()
0.110000,-0.001114,-117.385231,0.000013,-0.000000,-0.000000,-0.004955,-0.000252,-0.000000,-117.385231,0.000199,0.000000
0.280000,0.006332,-117.385231,-0.000004,-0.000000,-0.000000,0.028168,0.001435,-0.000000,-117.385231,0.000199,0.000000
0.450000,-0.004471,-117.474190,-0.000013,0.000029,0.000746,-0.019887,-0.001013,0.007456,-117.474190,0.001223,0.000000
0.620000,0.003723,-117.518669,-0.000004,0.000116,0.002957,0.016561,0.000844,0.029568,-117.518669,0.004050,0.000000
0.790000,-0.004097,-117.607635,0.000056,0.000229,0.005827,-0.018224,-0.000928,0.058272,-117.607635,0.006876,0.000000
0.960000,-0.021973,-117.518669,0.000168,0.000339,0.008611,-0.097739,-0.004979,0.086114,-117.518669,0.009704,0.000000
1.130000,-0.053246,-117.563156,0.000280,0.000449,0.011412,-0.236848,-0.012066,0.114122,-117.563156,0.012548,0.000000
1.300000,-0.072609,-117.563156,0.000379,0.000564,0.014335,-0.322981,-0.016453,0.143349,-117.563156,0.015376,0.000000
1.470000,-0.016014,-117.607635,0.000492,0.000676,0.017162,-0.071234,-0.003629,0.171622,-117.607635,0.018203,0.000000
1.640000,0.005585,-117.696594,0.000608,0.000781,0.019833,0.024842,0.001266,0.198328,-117.696594,0.021047,0.000000
1.810000,0.029045,-117.696594,0.000724,0.000893,0.022678,0.129199,0.006582,0.226776,-117.696594,0.023874,0.000000
1.980000,0.039101,-117.741081,0.000828,0.001008,0.025600,0.173928,0.008860,0.256003,-117.741081,0.026702,0.000000
2.150000,0.009308,-117.741081,0.000940,0.001124,0.028540,0.041403,0.002109,0.285404,-117.741081,0.029529,0.000000
2.320000,0.005959,-117.830040,0.001061,0.001235,0.031359,0.026505,0.001350,0.313586,-117.830040,0.032373,0.000000
2.490000,0.003723,-117.830040,0.001164,0.001345,0.034159,0.016561,0.000844,0.341594,-117.830040,0.035200,0.000000
2.660000,-0.016014,-117.785561,0.001281,0.001456,0.036978,-0.071234,-0.003629,0.369784,-117.785561,0.038028,0.000000
2.830000,0.008934,-117.830040,0.001397,0.001568,0.039822,0.039741,0.002024,0.398224,-117.830040,0.040872,0.000000
3.000000,-0.000374,-117.918999,0.001513,0.001679,0.042659,-0.001663,-0.000085,0.426588,-117.918999,0.043699,0.000000
3.170000,0.010056,-117.918999,0.001613,0.001782,0.045251,0.044729,0.002279,0.452514,-117.918999,0.046526,0.000000
3.340000,0.009682,-118.007965,0.001720,0.001893,0.048079,0.043066,0.002194,0.480788,-118.007965,0.049354,0.000000
3.510000,0.007446,-118.052444,0.001837,0.002011,0.051079,0.033123,0.001687,0.510794,-118.052444,0.052198,0.000000
3.680000,-0.026436,-118.007965,0.001932,0.002116,0.053750,-0.117593,-0.005990,0.537501,-118.007965,0.055025,0.000000
3.850000,0.026810,-118.052444,0.002057,0.002233,0.056716,0.119255,0.006075,0.567159,-118.052444,0.057852,0.000000
4.020000,0.017876,-118.096924,0.002169,0.002347,0.059613,0.079515,0.004051,0.596129,-118.096924,0.060697,0.000000
4.190000,0.081551,-118.185890,0.002281,0.002463,0.062570,0.362755,0.018480,0.625696,-118.185890,0.063524,0.000000
4.360000,0.195869,-118.141403,0.002402,0.002574,0.065371,0.871271,0.044385,0.653712,-118.141403,0.066351,0.000000
4.530000,0.401047,-118.185890,0.002514,0.002681,0.068103,1.783945,0.090878,0.681031,-118.185890,0.069195,0.000000
4.700000,0.706390,-118.230370,0.002596,0.002747,0.069785,3.142181,0.160070,0.697851,-118.230370,0.069950,0.000000
4.870000,0.690010,-118.185890,0.002596,-0.000001,-0.000026,3.069318,0.156359,-0.000257,-118.185890,0.000165,0.000000
5.040000,0.680695,-118.319328,0.002608,-0.000001,-0.000035,3.027881,0.154248,-0.000348,-118.319328,0.000165,0.000000
5.210000,0.738045,-118.363808,0.002600,-0.000002,-0.000043,3.282987,0.167243,-0.000431,-118.363808,0.000226,0.000000
5.380000,0.645691,-118.319328,0.002596,-0.000002,-0.000043,2.872177,0.146316,-0.000431,-118.319328,0.000512,0.000000
5.550000,0.656120,-118.408295,0.002600,-0.000001,-0.000035,2.918569,0.148679,-0.000348,-118.408295,0.000790,0.000000
5.720000,0.666916,-118.408295,0.002591,-0.000001,-0.000035,2.966590,0.151125,-0.000348,-118.408295,0.001076,0.000000
5.890000,0.777145,-118.452774,0.002608,0.000023,0.000581,3.456915,0.176104,0.005814,-118.452774,0.001362,0.000000
6.060000,0.836349,-118.497253,0.002613,0.000030,0.000755,3.720268,0.189520,0.007547,-118.497253,0.001639,0.000000
6.230000,0.888855,-118.497253,0.002613,0.000037,0.000945,3.953825,0.201417,0.009455,-118.497253,0.001926,0.000000
6.400000,0.990135,-118.541733,0.002630,0.000054,0.001370,4.404341,0.224368,0.013701,-118.541733,0.002212,0.000000
6.570000,1.053070,-118.630699,0.002634,0.000065,0.001648,4.684289,0.238629,0.016479,-118.630699,0.002489,0.000000
6.740000,1.143555,-118.630699,0.002639,0.000076,0.001942,5.086785,0.259133,0.019424,-118.630699,0.002775,0.000000
6.910000,1.231438,-118.675179,0.002660,0.000088,0.002246,5.477708,0.279048,0.022460,-118.675179,0.003061,0.000000
7.080000,1.268303,-118.675179,0.002673,0.000099,0.002515,5.641693,0.287402,0.025154,-118.675179,0.003347,0.000000
7.250000,1.372940,-118.675179,0.002686,0.000110,0.002792,6.107142,0.311113,0.027925,-118.675179,0.003625,0.000000
7.420001,1.436989,-118.808617,0.002695,0.000118,0.003001,6.392045,0.325626,0.030007,-118.808617,0.003911,0.000000
7.590000,1.525238,-118.808617,0.002682,0.000128,0.003244,6.784598,0.345624,0.032437,-118.808617,0.004197,0.000000
7.760000,1.689827,-118.808617,0.002712,0.000144,0.003651,7.516726,0.382920,0.036509,-118.808617,0.004475,0.000000
7.930000,1.789993,-118.853104,0.002725,0.000154,0.003903,7.962288,0.405618,0.039030,-118.853104,0.004761,0.000000
8.100000,1.814941,-118.808617,0.002721,0.000156,0.003972,8.073262,0.411272,0.039719,-118.808617,0.005048,0.000000
8.270000,1.986610,-118.897583,0.002734,0.000175,0.004449,8.836884,0.450172,0.044488,-118.897583,0.005325,0.000000
8.440001,2.148216,-118.942062,0.002742,0.000188,0.004770,9.555743,0.486793,0.047697,-118.942062,0.005611,0.000000
8.610001,2.237961,-118.986542,0.002759,0.000199,0.005048,9.954947,0.507129,0.050475,-118.986542,0.005898,0.000000
8.780001,2.413345,-118.986542,0.002759,0.000212,0.005394,10.735096,0.546872,0.053942,-118.986542,0.006175,0.000000
8.950001,2.493782,-118.986542,0.002777,0.000222,0.005646,11.092896,0.565099,0.056455,-118.986542,0.006461,0.000000
9.120001,2.598412,-119.031029,0.002781,0.000232,0.005880,11.558311,0.588808,0.058802,-119.031029,0.006747,0.000000
9.290001,2.671028,-119.119987,0.002777,0.000237,0.006027,11.881327,0.605264,0.060271,-119.119987,0.007025,0.000000
9.460000,2.866898,-119.119987,0.002807,0.000250,0.006348,12.752598,0.649648,0.063480,-119.119987,0.007311,0.000000
9.630000,3.105583,-119.164467,0.002820,0.000266,0.006756,13.814324,0.703735,0.067560,-119.164467,0.007597,0.000000
9.800000,3.228096,-119.119987,0.002820,0.000276,0.007016,14.359288,0.731497,0.070157,-119.119987,0.007875,0.000000
9.970000,3.276878,-119.119987,0.002820,0.000283,0.007190,14.576283,0.742551,0.071898,-119.119987,0.008161,0.000000
10.140000,3.454498,-119.342392,0.002841,0.000292,0.007424,15.366376,0.782800,0.074237,-119.342392,0.008447,0.000000
10.310000,3.678299,-119.297913,0.002850,0.000306,0.007779,16.361891,0.833514,0.077795,-119.297913,0.008724,0.000000
10.480000,3.867088,-119.253433,0.002854,0.000322,0.008169,17.201668,0.876295,0.081693,-119.253433,0.009010,0.000000
10.650001,3.968376,-119.297913,0.002871,0.000329,0.008352,17.652218,0.899247,0.083517,-119.297913,0.009296,0.000000
10.820001,4.187332,-119.342392,0.002871,0.000343,0.008724,18.626184,0.948863,0.087242,-119.342392,0.009574,0.000000
10.990001,4.302391,-119.386871,0.002884,0.000352,0.008950,19.137991,0.974936,0.089498,-119.386871,0.009860,0.000000
11.160001,4.473312,-119.475838,0.002910,0.000363,0.009228,19.898287,1.013667,0.092276,-119.475838,0.010147,0.000000
11.330001,4.548531,-119.475838,0.002919,0.000371,0.009436,20.232874,1.030712,0.094357,-119.475838,0.010424,0.000000
11.500001,4.965584,-119.475838,0.002915,0.000389,0.009886,22.088020,1.125217,0.098861,-119.475838,0.010710,0.000000
11.670001,5.124588,-119.520317,0.002940,0.000401,0.010181,22.795305,1.161248,0.101814,-119.520317,0.010997,0.000000
11.840000,5.212471,-119.564796,0.002936,0.000407,0.010346,23.186230,1.181163,0.103464,-119.564796,0.011274,0.000000
12.010000,5.280243,-119.564796,0.002932,0.000414,0.010511,23.487694,1.196520,0.105107,-119.564796,0.011561,0.000000
12.180000,5.456375,-119.653755,0.002945,0.000422,0.010719,24.271170,1.236432,0.107188,-119.653755,0.011847,0.000000
12.350000,5.970245,-119.653755,0.002971,0.000445,0.011291,26.556978,1.352877,0.112911,-119.653755,0.012124,0.000000
12.520000,6.112495,-119.698242,0.002988,0.000455,0.011561,27.189737,1.385111,0.115606,-119.698242,0.012410,0.000000
12.690001,6.249153,-119.742722,0.002988,0.000465,0.011803,27.797621,1.416078,0.118028,-119.742722,0.012696,0.000000
12.860001,6.402946,-119.742722,0.002997,0.000477,0.012115,28.481728,1.450928,0.121154,-119.742722,0.012974,0.000000
13.030001,6.635681,-119.742722,0.003014,0.000489,0.012427,29.516983,1.503667,0.124273,-119.742722,0.013260,0.000000
13.200001,6.700096,-119.787201,0.003022,0.000494,0.012549,29.803516,1.518263,0.125492,-119.787201,0.013546,0.000000
13.370001,6.999115,-119.831680,0.003035,0.000508,0.012896,31.133619,1.586022,0.128959,-119.831680,0.013824,0.000000
13.540001,7.374092,-119.876160,0.003044,0.000523,0.013286,32.801601,1.670993,0.132857,-119.876160,0.014110,0.000000
13.710001,7.483940,-119.920647,0.003057,0.000532,0.013520,33.290230,1.695885,0.135204,-119.920647,0.014396,0.000000
13.880001,7.513733,-120.009605,0.003053,0.000536,0.013624,33.422752,1.702636,0.136241,-120.009605,0.014673,0.000000
14.050000,7.834343,-119.965126,0.003061,0.000551,0.013997,34.848900,1.775287,0.139973,-119.965126,0.014959,0.000000
14.220000,7.973984,-119.920647,0.003070,0.000559,0.014196,35.470051,1.806931,0.141964,-119.920647,0.015246,0.000000
14.390000,8.356041,-119.965126,0.003087,0.000576,0.014630,37.169525,1.893506,0.146301,-119.965126,0.015523,0.000000
14.560000,8.609253,-120.054085,0.003091,0.000589,0.014959,38.295868,1.950885,0.149594,-120.054085,0.015810,0.000000
14.730000,8.750008,-120.098564,0.003113,0.000599,0.015220,38.921978,1.982780,0.152198,-120.098564,0.016096,0.000000
14.900001,8.915710,-120.098564,0.003122,0.000609,0.015480,39.659061,2.020329,0.154802,-120.098564,0.016373,0.000000
15.070001,9.063545,-120.098564,0.003117,0.000620,0.015749,40.316662,2.053829,0.157489,-120.098564,0.016660,0.000000
15.240001,9.165947,-120.187531,0.003139,0.000628,0.015949,40.772167,2.077033,0.159488,-120.187531,0.016946,0.000000
15.410001,9.508530,-120.232010,0.003147,0.000642,0.016304,42.296051,2.154664,0.163038,-120.232010,0.017232,0.000000
15.580001,9.717056,-120.276489,0.003147,0.000651,0.016529,43.223625,2.201916,0.165294,-120.276489,0.017510,0.000000
15.750001,9.889465,-120.276489,0.003147,0.000660,0.016772,43.990540,2.240985,0.167724,-120.276489,0.017796,0.000000
15.920001,9.951279,-120.320976,0.003169,0.000666,0.016920,44.265499,2.254992,0.169200,-120.320976,0.018082,0.000000
16.090000,10.229820,-120.320976,0.003165,0.000678,0.017214,45.504513,2.318110,0.172145,-120.320976,0.018359,0.000000
16.260000,10.635704,-120.454414,0.003169,0.000697,0.017700,47.309975,2.410085,0.177004,-120.454414,0.018645,0.000000
16.430000,11.065048,-120.409935,0.003208,0.000712,0.018082,49.219791,2.507376,0.180820,-120.409935,0.018932,0.000000
16.600000,11.184204,-120.409935,0.003212,0.000723,0.018376,49.749825,2.534377,0.183764,-120.409935,0.019209,0.000000
16.770000,11.256073,-120.409935,0.003221,0.000733,0.018628,50.069515,2.550663,0.186285,-120.409935,0.019495,0.000000
16.940001,11.510406,-120.454414,0.003229,0.000744,0.018888,51.200844,2.608295,0.188881,-120.454414,0.019781,0.000000
17.110001,11.327942,-120.498894,0.003225,0.000744,0.018906,50.389202,2.566948,0.189056,-120.498894,0.020059,0.000000
17.280001,11.763992,-120.543381,0.003229,0.000761,0.019322,52.328850,2.665759,0.193219,-120.543381,0.020345,0.000000
17.450001,12.100243,-120.587860,0.003255,0.000774,0.019651,53.824566,2.741954,0.196512,-120.587860,0.020631,0.000000
17.620001,12.430908,-120.543381,0.003264,0.000786,0.019972,55.295441,2.816884,0.199721,-120.543381,0.020909,0.000000
17.790001,12.433517,-120.721298,0.003272,0.000792,0.020120,55.307049,2.817475,0.201197,-120.721298,0.021195,0.000000
17.960001,12.715027,-120.632339,0.003268,0.000804,0.020432,56.559265,2.881266,0.204316,-120.632339,0.021482,0.000000
18.130001,12.962288,-120.721298,0.003290,0.000815,0.020709,57.659138,2.937296,0.207094,-120.721298,0.021759,0.000000
18.300001,13.343597,-120.810265,0.003303,0.000831,0.021108,59.355286,3.023702,0.211084,-120.810265,0.022045,0.000000
18.470001,13.483978,-120.721298,0.003311,0.000841,0.021369,59.979733,3.055513,0.213688,-120.721298,0.022331,0.000000
18.640001,13.822464,-120.765785,0.003320,0.000855,0.021715,61.485390,3.132215,0.217155,-120.765785,0.022609,0.000000
18.810001,13.822090,-120.854744,0.003333,0.000863,0.021924,61.483727,3.132130,0.219236,-120.854744,0.022895,0.000000
18.980001,14.106956,-120.943703,0.003328,0.000875,0.022235,62.750877,3.196682,0.222355,-120.943703,0.023181,0.000000
19.150002,14.289421,-120.899223,0.003350,0.000886,0.022513,63.562519,3.238029,0.225133,-120.899223,0.023459,0.000000
19.320002,14.621208,-120.854744,0.003350,0.000898,0.022809,65.038383,3.313213,0.228085,-120.854744,0.023745,0.000000
19.490002,14.821167,-120.943703,0.003363,0.000909,0.023077,65.927841,3.358525,0.230773,-120.943703,0.024031,0.000000
19.660002,14.982033,-121.032669,0.003376,0.000918,0.023319,66.643410,3.394977,0.233195,-121.032669,0.024308,0.000000
19.830002,15.071030,-121.077148,0.003389,0.000928,0.023580,67.039291,3.415144,0.235799,-121.077148,0.024595,0.000000
20.000000,15.562187,-121.032669,0.003376,0.000943,0.023944,69.224068,3.526442,0.239440,-121.032669,0.024881,0.000000
20.170000,16.024307,-121.077148,0.003402,0.000959,0.024352,71.279678,3.631160,0.243520,-121.077148,0.025158,0.000000
20.340000,15.986694,-121.077148,0.003415,0.000966,0.024534,71.112366,3.622637,0.245337,-121.077148,0.025444,0.000000
20.510000,16.333000,-121.121628,0.003419,0.000978,0.024846,72.652817,3.701111,0.248463,-121.121628,0.025730,0.000000
20.680000,16.500572,-121.210594,0.003423,0.000989,0.025123,73.398209,3.739083,0.251234,-121.210594,0.026008,0.000000
20.850000,16.581749,-121.210594,0.003445,0.001000,0.025410,73.759300,3.757478,0.254095,-121.210594,0.026294,0.000000
21.020000,17.004387,-121.255074,0.003445,0.001012,0.025696,75.639290,3.853249,0.256964,-121.255074,0.026581,0.000000
21.190001,17.242706,-121.255074,0.003458,0.001023,0.025973,76.699387,3.907253,0.259735,-121.255074,0.026858,0.000000
21.360001,17.589012,-121.255074,0.003458,0.001035,0.026294,78.239830,3.985727,0.262944,-121.255074,0.027145,0.000000
21.530001,17.882072,-121.299553,0.003466,0.001046,0.026563,79.543434,4.052135,0.265631,-121.299553,0.027431,0.000000
21.700001,17.881699,-121.432999,0.003484,0.001055,0.026806,79.541771,4.052051,0.268061,-121.432999,0.027708,0.000000
21.870001,18.469673,-121.388512,0.003488,0.001070,0.027170,82.157211,4.185288,0.271702,-121.388512,0.027994,0.000000
22.040001,18.756775,-121.432999,0.003510,0.001082,0.027491,83.434303,4.250346,0.274912,-121.432999,0.028281,0.000000
22.210001,19.122818,-121.477478,0.003514,0.001096,0.027830,85.062546,4.333292,0.278296,-121.477478,0.028558,0.000000
22.380001,19.233414,-121.521957,0.003514,0.001105,0.028055,85.554497,4.358354,0.280552,-121.521957,0.028844,0.000000
22.550001,19.272881,-121.521957,0.003535,0.001113,0.028272,85.730057,4.367297,0.282717,-121.521957,0.029130,0.000000
22.720001,19.573013,-121.566437,0.003548,0.001125,0.028584,87.065109,4.435308,0.285843,-121.566437,0.029408,0.000000
22.890001,19.905167,-121.566437,0.003548,0.001135,0.028827,88.542603,4.510575,0.288265,-121.566437,0.029694,0.000000
23.060001,20.244400,-121.610924,0.003548,0.001147,0.029139,90.051590,4.587447,0.291391,-121.610924,0.029980,0.000000
23.230001,20.590332,-121.655403,0.003570,0.001158,0.029408,91.590370,4.665836,0.294079,-121.655403,0.030258,0.000000
23.400002,20.909828,-121.744362,0.003574,0.001170,0.029720,93.011559,4.738235,0.297198,-121.744362,0.030544,0.000000
23.570002,20.919144,-121.699883,0.003583,0.001174,0.029824,93.053001,4.740345,0.298242,-121.699883,0.030830,0.000000
23.740002,21.238266,-121.744362,0.003591,0.001188,0.030179,94.472527,4.812660,0.301792,-121.744362,0.031116,0.000000
23.910002,21.817673,-121.788841,0.003596,0.001201,0.030518,97.049858,4.943955,0.305176,-121.788841,0.031393,0.000000
24.080002,22.319633,-121.788841,0.003609,0.001216,0.030882,99.282692,5.057701,0.308817,-121.788841,0.031680,0.000000
24.250002,22.524063,-121.877808,0.003613,0.001226,0.031151,100.192039,5.104026,0.311512,-121.877808,0.031966,0.000000
24.420002,22.735947,-121.788841,0.003630,0.001236,0.031393,101.134544,5.152039,0.313934,-121.788841,0.032244,0.000000
24.590002,23.118744,-121.877808,0.003626,0.001248,0.031689,102.837311,5.238782,0.316887,-121.877808,0.032530,0.000000
24.760000,23.457230,-121.966766,0.003635,0.001260,0.032001,104.342972,5.315484,0.320005,-121.966766,0.032816,0.000000
24.930000,23.574158,-121.877808,0.003648,0.001267,0.032183,104.863091,5.341981,0.321830,-121.877808,0.033094,0.000000
25.100000,24.067924,-121.966766,0.003648,0.001282,0.032556,107.059479,5.453870,0.325562,-121.966766,0.033380,0.000000
25.270000,24.465240,-122.055733,0.003660,0.001292,0.032816,108.826828,5.543903,0.328158,-122.055733,0.033666,0.000000
25.440001,24.734093,-121.966766,0.003673,0.001300,0.033016,110.022736,5.604825,0.330156,-121.966766,0.033944,0.000000
25.610001,24.821228,-122.055733,0.003682,0.001308,0.033224,110.410339,5.624570,0.332238,-122.055733,0.034230,0.000000
25.780001,25.576775,-122.144691,0.003691,0.001323,0.033614,113.771179,5.795780,0.336137,-122.144691,0.034516,0.000000
25.950001,25.991974,-122.144691,0.003686,0.001339,0.034004,115.618073,5.889865,0.340043,-122.144691,0.034793,0.000000
26.120001,26.302528,-122.189171,0.003704,0.001347,0.034203,116.999489,5.960238,0.342033,-122.189171,0.035079,0.000000
26.290001,26.585907,-122.189171,0.003704,0.001357,0.034472,118.260017,6.024453,0.344721,-122.189171,0.035365,0.000000
26.460001,27.038338,-122.189171,0.003708,0.001370,0.034802,120.272530,6.126975,0.348021,-122.189171,0.035643,0.000000
26.630001,27.374962,-122.233650,0.003721,0.001380,0.035045,121.769913,6.203255,0.350451,-122.233650,0.035929,0.000000
26.800001,27.562637,-122.322617,0.003734,0.001388,0.035253,122.604736,6.245783,0.352525,-122.322617,0.036215,0.000000
26.970001,28.201630,-122.367096,0.003742,0.001402,0.035617,125.447113,6.390581,0.356174,-122.367096,0.036493,0.000000
27.140001,28.736725,-122.322617,0.003760,0.001415,0.035938,127.827339,6.511835,0.359383,-122.322617,0.036779,0.000000
27.310001,29.070374,-122.367096,0.003755,0.001424,0.036181,129.311478,6.587441,0.361806,-122.367096,0.037065,0.000000
27.480001,29.090851,-122.367096,0.003760,0.001430,0.036320,129.402573,6.592081,0.363199,-122.367096,0.037343,0.000000
27.650002,29.292679,-122.500542,0.003764,0.001437,0.036502,130.300339,6.637816,0.365015,-122.500542,0.037629,0.000000
27.820002,30.327873,-122.456055,0.003781,0.001457,0.036996,134.905121,6.872394,0.369958,-122.456055,0.037916,0.000000
27.990002,30.883080,-122.456055,0.003781,0.001470,0.037334,137.374802,6.998206,0.373342,-122.456055,0.038193,0.000000
28.160002,31.214493,-122.500542,0.003798,0.001481,0.037612,138.848999,7.073305,0.376120,-122.500542,0.038479,0.000000
28.330002,31.580536,-122.545021,0.003798,0.001490,0.037854,140.477234,7.156251,0.378542,-122.545021,0.038765,0.000000
28.500002,32.102600,-122.589500,0.003807,0.001503,0.038175,142.799500,7.274553,0.381752,-122.589500,0.039043,0.000000
28.670002,32.465668,-122.633980,0.003820,0.001512,0.038401,144.414505,7.356825,0.384008,-122.633980,0.039329,0.000000
28.840002,32.827240,-122.633980,0.003833,0.001522,0.038652,146.022858,7.438759,0.386521,-122.633980,0.039615,0.000000
29.010002,33.465858,-122.633980,0.003824,0.001536,0.039017,148.863571,7.583472,0.390170,-122.633980,0.039893,0.000000
29.180002,33.996864,-122.678467,0.003833,0.001547,0.039294,151.225601,7.703800,0.392940,-122.678467,0.040179,0.000000
29.350002,34.264221,-122.722946,0.003842,0.001554,0.039459,152.414871,7.764384,0.394590,-122.722946,0.040465,0.000000
29.520000,34.435890,-122.811905,0.003837,0.001562,0.039676,153.178497,7.803284,0.396755,-122.811905,0.040742,0.000000
29.690001,35.533646,-122.767426,0.003854,0.001580,0.040144,158.061554,8.052039,0.401441,-122.767426,0.041028,0.000000
29.860001,36.044167,-122.811905,0.003854,0.001591,0.040413,160.332458,8.167725,0.404128,-122.811905,0.041315,0.000000
30.030001,36.461220,-122.856384,0.003863,0.001601,0.040673,162.187607,8.262231,0.406732,-122.856384,0.041592,0.000000
30.200001,37.061485,-122.945351,0.003867,0.001614,0.041003,164.857727,8.398252,0.410025,-122.945351,0.041878,0.000000
30.370001,37.530678,-122.945351,0.003885,0.001624,0.041246,166.944794,8.504573,0.412455,-122.945351,0.042164,0.000000
30.540001,37.817406,-122.945351,0.003889,0.001632,0.041445,168.220215,8.569547,0.414446,-122.945351,0.042442,0.000000
30.710001,38.297020,-122.989830,0.003898,0.001645,0.041792,170.353653,8.678228,0.417921,-122.989830,0.042728,0.000000
30.880001,39.097992,-122.989830,0.003893,0.001659,0.042139,173.916550,8.859732,0.421387,-122.989830,0.043015,0.000000
31.050001,39.702354,-123.078789,0.003902,0.001670,0.042407,176.604889,8.996682,0.424075,-123.078789,0.043292,0.000000
31.220001,40.078445,-123.123276,0.003906,0.001677,0.042607,178.277832,9.081906,0.426073,-123.123276,0.043579,0.000000
31.390001,40.384911,-123.123276,0.003928,0.001687,0.042841,179.641052,9.151351,0.428412,-123.123276,0.043865,0.000000
31.560001,41.163544,-123.167755,0.003923,0.001703,0.043248,183.104584,9.327792,0.432485,-123.167755,0.044142,0.000000
31.730001,42.066544,-123.167755,0.003923,0.001716,0.043579,187.121338,9.532414,0.435785,-123.167755,0.044428,0.000000
31.900002,42.571480,-123.212234,0.003923,0.001725,0.043821,189.367401,9.646835,0.438208,-123.212234,0.044714,0.000000
32.070000,42.832512,-123.256714,0.003932,0.001733,0.044012,190.528534,9.705986,0.440115,-123.256714,0.045000,0.000000
32.240002,43.719131,-123.256714,0.003958,0.001747,0.044385,194.472412,9.906897,0.443847,-123.256714,0.045278,0.000000
32.410000,44.159279,-123.256714,0.003962,0.001757,0.044619,196.430283,10.006636,0.446186,-123.256714,0.045564,0.000000
32.580002,44.539841,-123.256714,0.003958,0.001766,0.044862,198.123108,10.092873,0.448616,-123.256714,0.045850,0.000000
32.750000,45.123352,-123.390160,0.003962,0.001776,0.045122,200.718689,10.225098,0.451220,-123.390160,0.046128,0.000000
32.920002,46.146255,-123.434639,0.003975,0.001793,0.045538,205.268799,10.456891,0.455383,-123.434639,0.046414,0.000000
33.090000,46.691040,-123.390160,0.003980,0.001801,0.045755,207.692123,10.580340,0.457548,-123.390160,0.046700,0.000000
33.260002,46.810570,-123.390160,0.003988,0.001807,0.045902,208.223816,10.607427,0.459024,-123.390160,0.046978,0.000000
33.430000,47.229118,-123.434639,0.003980,0.001815,0.046111,210.085617,10.702271,0.461106,-123.434639,0.047264,0.000000
33.600002,47.390724,-123.523598,0.003984,0.001821,0.046241,210.804474,10.738892,0.462408,-123.523598,0.047550,0.000000
33.770000,49.442123,-123.568085,0.003992,0.001849,0.046961,219.929550,11.203745,0.469607,-123.568085,0.047827,0.000000
33.940002,49.846153,-123.568085,0.004005,0.001859,0.047212,221.726761,11.295300,0.472120,-123.568085,0.048114,0.000000
34.110001,50.577118,-123.568085,0.004018,0.001872,0.047550,224.978256,11.460938,0.475504,-123.568085,0.048400,0.000000
34.280003,51.125992,-123.612564,0.004014,0.001881,0.047784,227.419769,11.585316,0.477843,-123.612564,0.048678,0.000000
34.450001,51.638748,-123.657043,0.004023,0.001891,0.048027,229.700623,11.701508,0.480273,-123.657043,0.048964,0.000000
34.620003,51.936279,-123.701523,0.004018,0.001900,0.048253,231.024109,11.768929,0.482529,-123.701523,0.049250,0.000000
34.790001,53.018761,-123.701523,0.004036,0.001914,0.048608,235.839233,12.014223,0.486079,-123.701523,0.049528,0.000000
34.960003,53.727760,-123.701523,0.004027,0.001923,0.048851,238.993011,12.174885,0.488509,-123.701523,0.049814,0.000000
35.130001,54.182800,-123.790489,0.004036,0.001933,0.049102,241.017136,12.277998,0.491022,-123.790489,0.050100,0.000000
35.300003,54.313133,-123.834969,0.004036,0.001939,0.049241,241.596878,12.307532,0.492415,-123.834969,0.050377,0.000000
35.470001,55.194160,-123.879448,0.004053,0.001952,0.049571,245.515884,12.507175,0.495708,-123.879448,0.050664,0.000000
35.640003,56.112061,-123.879448,0.004053,0.001967,0.049961,249.598907,12.715175,0.499614,-123.879448,0.050950,0.000000
35.810001,57.167366,-123.923927,0.004049,0.001980,0.050291,254.293152,12.954309,0.502907,-123.923927,0.051227,0.000000
35.980003,57.979141,-123.923927,0.004057,0.001993,0.050612,257.904114,13.138261,0.506116,-123.923927,0.051513,0.000000
36.150002,58.316505,-124.012894,0.004061,0.002001,0.050837,259.404785,13.214708,0.508372,-124.012894,0.051799,0.000000
36.320004,59.128281,-124.012894,0.004074,0.002013,0.051123,263.015717,13.398660,0.511233,-124.012894,0.052077,0.000000
36.490002,59.839882,-124.057373,0.004074,0.002023,0.051383,266.181091,13.559911,0.513830,-124.057373,0.052363,0.000000
36.660000,60.367165,-124.012894,0.004087,0.002033,0.051643,268.526550,13.679396,0.516434,-124.012894,0.052649,0.000000
36.830002,61.368469,-124.057373,0.004074,0.002046,0.051964,272.980591,13.906294,0.519643,-124.057373,0.052927,0.000000
37.000000,61.743080,-124.101852,0.004074,0.002053,0.052155,274.646942,13.991181,0.521551,-124.101852,0.053213,0.000000
37.170002,62.129227,-124.190819,0.004087,0.002059,0.052311,276.364594,14.078684,0.523110,-124.190819,0.053499,0.000000
37.340000,62.954033,-124.190819,0.004096,0.002072,0.052641,280.033539,14.265588,0.526411,-124.190819,0.053777,0.000000
37.510002,63.203529,-124.235298,0.004092,0.002078,0.052771,281.143341,14.322124,0.527705,-124.235298,0.054063,0.000000
37.680000,65.225502,-124.235298,0.004087,0.002105,0.053456,290.137512,14.780310,0.534556,-124.235298,0.054349,0.000000
37.850002,65.984032,-124.324257,0.004105,0.002115,0.053725,293.511627,14.952195,0.537251,-124.324257,0.054627,0.000000
38.020000,66.614830,-124.368736,0.004113,0.002125,0.053976,296.317566,15.095137,0.539764,-124.368736,0.054913,0.000000
38.190002,67.219933,-124.368736,0.004100,0.002135,0.054228,299.009186,15.232254,0.542277,-124.368736,0.055199,0.000000
38.360001,67.287697,-124.279778,0.004122,0.002129,0.054089,299.310638,15.247610,0.540892,-124.279778,0.054315,0.000000
38.530003,66.971565,-124.324257,0.004130,0.002129,0.054089,297.904388,15.175974,0.540892,-124.324257,0.054315,0.000000
38.700001,66.740318,-124.457703,0.004118,0.002129,0.054072,296.875763,15.123572,0.540718,-124.457703,0.054089,0.000000
38.870003,66.524345,-124.457703,0.004126,0.002128,0.054063,295.915070,15.074632,0.540627,-124.457703,0.054089,0.000000
39.040001,66.322517,-124.457703,0.004139,0.002128,0.054054,295.017303,15.028897,0.540544,-124.457703,0.054089,0.000000
39.210003,66.145271,-124.502182,0.004135,0.002128,0.054054,294.228851,14.988733,0.540544,-124.502182,0.054089,0.000000
39.380001,65.989616,-124.502182,0.004130,0.002128,0.054046,293.536469,14.953461,0.540460,-124.502182,0.054089,0.000000
39.550003,65.832100,-124.591141,0.004126,0.002128,0.054046,292.835815,14.917768,0.540460,-124.591141,0.054089,0.000000
39.720001,65.706612,-124.591141,0.004126,0.002128,0.054046,292.277618,14.889331,0.540460,-124.591141,0.054089,0.000000
39.890003,65.593788,-124.635628,0.004130,0.002128,0.054046,291.775757,14.863765,0.540460,-124.635628,0.054089,0.000000
40.060001,65.487663,-124.635628,0.004152,0.002128,0.054046,291.303680,14.839716,0.540460,-124.635628,0.054089,0.000000
40.230003,65.382652,-124.680107,0.004139,0.002127,0.054037,290.836548,14.815921,0.540369,-124.680107,0.054089,0.000000
40.400002,65.272057,-124.635628,0.004139,0.002127,0.054037,290.344604,14.790859,0.540369,-124.635628,0.054089,0.000000
40.570004,65.193108,-124.769066,0.004135,0.002127,0.054037,289.993439,14.772969,0.540369,-124.769066,0.054089,0.000000
40.740002,65.100395,-124.769066,0.004143,0.002127,0.054037,289.581024,14.751961,0.540369,-124.769066,0.054089,0.000000
40.910004,65.035591,-124.769066,0.004152,0.002127,0.054037,289.292755,14.737276,0.540369,-124.769066,0.054089,0.000000
41.080002,64.944740,-124.769066,0.004148,0.002127,0.054037,288.888641,14.716688,0.540369,-124.769066,0.054089,0.000000
41.250004,64.884789,-124.858032,0.004135,0.002127,0.054037,288.621948,14.703104,0.540369,-124.858032,0.054089,0.000000
41.420002,64.806221,-124.902512,0.004139,0.002127,0.054037,288.272461,14.685300,0.540369,-124.902512,0.054089,0.000000
41.590000,64.754829,-124.991470,0.004156,0.002127,0.054037,288.043854,14.673655,0.540369,-124.991470,0.054089,0.000000
41.760002,64.678490,-124.946991,0.004152,0.002127,0.054037,287.704285,14.656355,0.540369,-124.946991,0.054089,0.000000
41.930000,64.624123,-124.946991,0.004148,0.002127,0.054037,287.462463,14.644036,0.540369,-124.946991,0.054089,0.000000
42.100002,64.576088,-124.946991,0.004130,0.002127,0.054037,287.248779,14.633151,0.540369,-124.946991,0.054089,0.000000
42.270000,64.519112,-125.035950,0.004139,0.002127,0.054037,286.995331,14.620239,0.540369,-125.035950,0.054089,0.000000
42.440002,64.461021,-125.080437,0.004152,0.002127,0.054037,286.736938,14.607076,0.540369,-125.080437,0.054089,0.000000
42.610001,64.416344,-125.124916,0.004152,0.002127,0.054037,286.538208,14.596952,0.540369,-125.124916,0.054089,0.000000
42.780003,64.379097,-125.124916,0.004143,0.002127,0.054037,286.372528,14.588511,0.540369,-125.124916,0.054089,0.000000
42.950001,64.319527,-125.169395,0.004148,0.002127,0.054037,286.107544,14.575013,0.540369,-125.169395,0.054089,0.000000
43.120003,64.272606,-125.124916,0.004130,0.002127,0.054037,285.898834,14.564381,0.540369,-125.124916,0.054089,0.000000
43.290001,64.229042,-125.213875,0.004139,0.002127,0.054037,285.705048,14.554509,0.540369,-125.213875,0.054089,0.000000
43.460003,64.191048,-125.258362,0.004148,0.002127,0.054037,285.536041,14.545899,0.540369,-125.258362,0.054089,0.000000
43.630001,64.140785,-125.302841,0.004148,0.002127,0.054037,285.312469,14.534510,0.540369,-125.302841,0.054089,0.000000
43.800003,64.119926,-125.302841,0.004148,0.002127,0.054037,285.219666,14.529783,0.540369,-125.302841,0.054089,0.000000
43.970001,64.071526,-125.347321,0.004148,0.002127,0.054037,285.004395,14.518815,0.540369,-125.347321,0.054089,0.000000
44.140003,64.040611,-125.436279,0.004156,0.002127,0.054037,284.866852,14.511809,0.540369,-125.436279,0.054089,0.000000
44.310001,63.996300,-125.436279,0.004152,0.002127,0.054037,284.669769,14.501769,0.540369,-125.436279,0.054089,0.000000
44.480003,63.970604,-125.436279,0.004152,0.002127,0.054037,284.555450,14.495946,0.540369,-125.436279,0.054089,0.000000
44.650002,63.931145,-125.436279,0.004148,0.002127,0.054037,284.379944,14.487004,0.540369,-125.436279,0.054089,0.000000
44.820004,63.909920,-125.525246,0.004130,0.002127,0.054037,284.285522,14.482195,0.540369,-125.525246,0.054089,0.000000
44.990002,63.860756,-125.525246,0.004161,0.002127,0.054037,284.066833,14.471054,0.540369,-125.525246,0.054089,0.000000
45.160004,63.839912,-125.569725,0.004139,0.002127,0.054037,283.974121,14.466331,0.540369,-125.569725,0.054089,0.000000
45.330002,63.790749,-125.525246,0.004156,0.002127,0.054037,283.755432,14.455191,0.540369,-125.525246,0.054089,0.000000
45.500004,63.774742,-125.569725,0.004156,0.002127,0.054037,283.684235,14.451564,0.540369,-125.569725,0.054089,0.000000
45.670002,63.736382,-125.614204,0.004135,0.002127,0.054037,283.513580,14.442870,0.540369,-125.614204,0.054089,0.000000
45.840004,63.727821,-125.747650,0.004156,0.002127,0.054037,283.475494,14.440931,0.540369,-125.747650,0.054089,0.000000
46.010002,63.686485,-125.747650,0.004143,0.002127,0.054037,283.291626,14.431563,0.540369,-125.747650,0.054089,0.000000
46.180000,63.676811,-125.703171,0.004152,0.002127,0.054037,283.248596,14.429371,0.540369,-125.703171,0.054089,0.000000
46.350002,63.635841,-125.747650,0.004148,0.002127,0.054037,283.066345,14.420088,0.540369,-125.747650,0.054089,0.000000
46.520000,63.613503,-125.747650,0.004156,0.002127,0.054037,282.966980,14.415026,0.540369,-125.747650,0.054089,0.000000
46.690002,63.578499,-125.792130,0.004156,0.002127,0.054037,282.811279,14.407094,0.540369,-125.792130,0.054089,0.000000
46.860001,63.563972,-125.836609,0.004156,0.002127,0.054037,282.746674,14.403802,0.540369,-125.836609,0.054089,0.000000
47.030003,63.528236,-125.881088,0.004152,0.002127,0.054037,282.587708,14.395704,0.540369,-125.881088,0.054089,0.000000
47.200001,63.517799,-125.881088,0.004152,0.002127,0.054037,282.541290,14.393339,0.540369,-125.881088,0.054089,0.000000
47.370003,63.482430,-125.970055,0.004152,0.002127,0.054037,282.383942,14.385324,0.540369,-125.970055,0.054089,0.000000
47.540001,63.469017,-126.059013,0.004143,0.002127,0.054037,282.324280,14.382284,0.540369,-126.059013,0.054089,0.000000
47.710003,63.445564,-126.014534,0.004152,0.002127,0.054037,282.219971,14.376970,0.540369,-126.014534,0.054089,0.000000
47.880001,63.423973,-126.014534,0.004148,0.002127,0.054037,282.123932,14.372077,0.540369,-126.014534,0.054089,0.000000
48.050003,63.398277,-126.014534,0.004156,0.002127,0.054037,282.009613,14.366256,0.540369,-126.014534,0.054089,0.000000
48.220001,63.377052,-126.059013,0.004152,0.002127,0.054037,281.915222,14.361445,0.540369,-126.059013,0.054089,0.000000
48.390003,63.346886,-126.147980,0.004152,0.002127,0.054037,281.781006,14.354609,0.540369,-126.147980,0.054089,0.000000
48.560001,63.344276,-126.192459,0.004161,0.002127,0.054037,281.769409,14.354018,0.540369,-126.192459,0.054089,0.000000
48.730003,63.319710,-126.147980,0.004152,0.002127,0.054037,281.660126,14.348452,0.540369,-126.147980,0.054089,0.000000
48.900002,63.296242,-126.192459,0.004152,0.002127,0.054037,281.555756,14.343134,0.540369,-126.192459,0.054089,0.000000
49.070004,63.276512,-126.236938,0.004152,0.002127,0.054037,281.467987,14.338662,0.540369,-126.236938,0.054089,0.000000
49.240002,63.260490,-126.281418,0.004161,0.002127,0.054037,281.396729,14.335032,0.540369,-126.281418,0.054089,0.000000
49.410004,63.239265,-126.281418,0.004156,0.002127,0.054037,281.302307,14.330222,0.540369,-126.281418,0.054089,0.000000
49.580002,63.218040,-126.281418,0.004143,0.002127,0.054037,281.207886,14.325413,0.540369,-126.281418,0.054089,0.000000
49.750004,63.193474,-126.325897,0.004156,0.002127,0.054037,281.098602,14.319845,0.540369,-126.325897,0.054089,0.000000
49.920002,63.190865,-126.325897,0.004148,0.002127,0.054037,281.087006,14.319255,0.540369,-126.325897,0.054089,0.000000
50.090004,63.158470,-126.370384,0.004143,0.002127,0.054037,280.942902,14.311913,0.540369,-126.370384,0.054089,0.000000
50.260002,63.148781,-126.414864,0.004152,0.002127,0.054037,280.899811,14.309718,0.540369,-126.414864,0.054089,0.000000
50.430004,63.130913,-126.503822,0.004148,0.002127,0.054037,280.820312,14.305670,0.540369,-126.503822,0.054089,0.000000
50.600002,63.107826,-126.459343,0.004156,0.002127,0.054037,280.717621,14.300438,0.540369,-126.459343,0.054089,0.000000
50.770004,63.107445,-126.459343,0.004152,0.002127,0.054037,280.715942,14.300352,0.540369,-126.459343,0.054089,0.000000
50.940002,63.082878,-126.548309,0.004161,0.002127,0.054037,280.606659,14.294785,0.540369,-126.548309,0.054089,0.000000
51.110001,63.064629,-126.592789,0.004152,0.002127,0.054037,280.525482,14.290649,0.540369,-126.592789,0.054089,0.000000
51.280003,63.057549,-126.637268,0.004165,0.002127,0.054037,280.493988,14.289044,0.540369,-126.637268,0.054089,0.000000
51.450001,63.039680,-126.681747,0.004161,0.002127,0.054037,280.414490,14.284995,0.540369,-126.681747,0.054089,0.000000
51.620003,63.022926,-126.637268,0.004139,0.002127,0.054037,280.339966,14.281199,0.540369,-126.637268,0.054089,0.000000
51.790001,63.005043,-126.726227,0.004152,0.002127,0.054037,280.260437,14.277146,0.540369,-126.726227,0.054089,0.000000
51.960003,62.995369,-126.770714,0.004156,0.002127,0.054037,280.217407,14.274955,0.540369,-126.770714,0.054089,0.000000
52.130001,62.979347,-126.770714,0.004156,0.002127,0.054037,280.146118,14.271324,0.540369,-126.770714,0.054089,0.000000
52.300003,62.962601,-126.815193,0.004169,0.002127,0.054037,280.071625,14.267529,0.540369,-126.815193,0.054089,0.000000
52.470001,62.949196,-126.770714,0.004148,0.002127,0.054037,280.011993,14.264492,0.540369,-126.770714,0.054089,0.000000
52.640003,62.932060,-126.859673,0.004156,0.002127,0.054037,279.935791,14.260610,0.540369,-126.859673,0.054089,0.000000
52.810001,62.930573,-126.859673,0.004152,0.002127,0.054037,279.929169,14.260271,0.540369,-126.859673,0.054089,0.000000
52.980003,62.901527,-126.948631,0.004165,0.002127,0.054037,279.799957,14.253690,0.540369,-126.948631,0.054089,0.000000
53.150002,62.916794,-126.904152,0.004156,0.002127,0.054037,279.867889,14.257150,0.540369,-126.904152,0.054089,0.000000
53.320004,62.881050,-126.904152,0.004165,0.002127,0.054037,279.708893,14.249049,0.540369,-126.904152,0.054089,0.000000
53.490002,62.875832,-126.993118,0.004165,0.002127,0.054037,279.685669,14.247867,0.540369,-126.993118,0.054089,0.000000
53.660004,62.854240,-127.037598,0.004156,0.002127,0.054037,279.589630,14.242974,0.540369,-127.037598,0.054089,0.000000
53.830002,62.859451,-127.037598,0.004174,0.002127,0.054037,279.612793,14.244155,0.540369,-127.037598,0.054089,0.000000
54.000004,62.827057,-127.126556,0.004165,0.002127,0.054037,279.468719,14.236814,0.540369,-127.126556,0.054089,0.000000
54.170002,62.828918,-127.126556,0.004156,0.002127,0.054037,279.476990,14.237237,0.540369,-127.126556,0.054089,0.000000
54.340004,62.800987,-127.126556,0.004161,0.002127,0.054037,279.352753,14.230907,0.540369,-127.126556,0.054089,0.000000
54.510002,62.799500,-127.171036,0.004152,0.002127,0.054037,279.346130,14.230571,0.540369,-127.171036,0.054089,0.000000
54.680004,62.787209,-127.260002,0.004152,0.002127,0.054037,279.291443,14.227785,0.540369,-127.260002,0.054089,0.000000
54.850002,62.765610,-127.260002,0.004169,0.002127,0.054037,279.195374,14.222890,0.540369,-127.260002,0.054089,0.000000
55.020004,62.758163,-127.171036,0.004156,0.002127,0.054037,279.162262,14.221204,0.540369,-127.171036,0.054089,0.000000
55.190002,62.745880,-127.304482,0.004156,0.002127,0.054037,279.107605,14.218420,0.540369,-127.304482,0.054089,0.000000
55.360004,62.735825,-127.393440,0.004156,0.002127,0.054037,279.062897,14.216141,0.540369,-127.393440,0.054089,0.000000
55.530003,62.719063,-127.348961,0.004165,0.002127,0.054037,278.988312,14.212343,0.540369,-127.348961,0.054089,0.000000
55.700001,62.711990,-127.437927,0.004165,0.002127,0.054037,278.956879,14.210740,0.540369,-127.437927,0.054089,0.000000
55.870003,62.691513,-127.393440,0.004161,0.002127,0.054037,278.865784,14.206100,0.540369,-127.393440,0.054089,0.000000
56.040001,62.693001,-127.482407,0.004161,0.002127,0.054037,278.872406,14.206437,0.540369,-127.482407,0.054089,0.000000
56.210003,62.699333,-127.526886,0.004152,0.002127,0.054037,278.900574,14.207871,0.540369,-127.526886,0.054089,0.000000
56.380001,62.671028,-127.526886,0.004169,0.002127,0.054037,278.774658,14.201458,0.540369,-127.526886,0.054089,0.000000
56.550003,62.662468,-127.571365,0.004161,0.002127,0.054037,278.736572,14.199518,0.540369,-127.571365,0.054089,0.000000
56.720001,62.659485,-127.526886,0.004156,0.002127,0.054037,278.723297,14.198842,0.540369,-127.526886,0.054089,0.000000
56.890003,62.633049,-127.571365,0.004161,0.002127,0.054037,278.605713,14.192851,0.540369,-127.571365,0.054089,0.000000
57.060001,62.636772,-127.660332,0.004156,0.002127,0.054037,278.622284,14.193696,0.540369,-127.660332,0.054089,0.000000
57.230003,62.626343,-127.660332,0.004165,0.002127,0.054037,278.575897,14.191332,0.540369,-127.660332,0.054089,0.000000
57.400002,62.608841,-127.660332,0.004161,0.002127,0.054037,278.498047,14.187366,0.540369,-127.660332,0.054089,0.000000
57.570004,62.582779,-127.660332,0.004169,0.002127,0.054037,278.382111,14.181460,0.540369,-127.660332,0.054089,0.000000
57.740002,62.586502,-127.749290,0.004165,0.002127,0.054037,278.398651,14.182304,0.540369,-127.749290,0.054089,0.000000
57.910004,62.573845,-127.749290,0.004152,0.002127,0.054037,278.342377,14.179437,0.540369,-127.749290,0.054089,0.000000
58.080002,62.571609,-127.793770,0.004161,0.002127,0.054037,278.332428,14.178929,0.540369,-127.793770,0.054089,0.000000
58.250004,62.552246,-127.882736,0.004156,0.002127,0.054037,278.246277,14.174541,0.540369,-127.882736,0.054089,0.000000
58.420002,62.556709,-127.793770,0.004152,0.002127,0.054037,278.266144,14.175552,0.540369,-127.793770,0.054089,0.000000
58.590004,62.527298,-127.882736,0.004152,0.002127,0.054037,278.135315,14.168888,0.540369,-127.882736,0.054089,0.000000
58.760002,62.548149,-127.971695,0.004148,0.002127,0.054037,278.228058,14.173614,0.540369,-127.971695,0.054089,0.000000
58.930004,62.502342,-128.016174,0.004148,0.002127,0.054037,278.024292,14.163233,0.540369,-128.016174,0.054089,0.000000
59.100002,62.525436,-127.971695,0.004152,0.002127,0.054037,278.127045,14.168467,0.540369,-127.971695,0.054089,0.000000
59.270004,62.505325,-127.971695,0.004148,0.002127,0.054037,278.037567,14.163910,0.540369,-127.971695,0.054089,0.000000
59.440002,62.491920,-128.016174,0.004152,0.002127,0.054037,277.977936,14.160872,0.540369,-128.016174,0.054089,0.000000
59.610004,62.480377,-128.105133,0.004156,0.002127,0.054037,277.926605,14.158256,0.540369,-128.105133,0.054089,0.000000
59.780003,62.474419,-128.149612,0.004169,0.002127,0.054037,277.900085,14.156905,0.540369,-128.149612,0.054089,0.000000
59.950005,62.463989,-128.149612,0.004161,0.002127,0.054037,277.853699,14.154542,0.540369,-128.149612,0.054089,0.000000
60.120003,62.445374,-128.149612,0.004169,0.002127,0.054037,277.770905,14.150324,0.540369,-128.149612,0.054089,0.000000
60.290005,62.444252,-128.194107,0.004165,0.002127,0.054037,277.765900,14.150069,0.540369,-128.194107,0.054089,0.000000
60.460003,62.442024,-128.238586,0.004152,0.002127,0.054037,277.755981,14.149565,0.540369,-128.238586,0.054089,0.000000
60.630001,62.421913,-128.238586,0.004156,0.002127,0.054037,277.666534,14.145007,0.540369,-128.238586,0.054089,0.000000
60.800003,62.424522,-128.283066,0.004165,0.002127,0.054037,277.678131,14.145599,0.540369,-128.283066,0.054089,0.000000
60.970001,62.404037,-128.238586,0.004165,0.002127,0.054037,277.587036,14.140958,0.540369,-128.238586,0.054089,0.000000
61.140003,62.408134,-128.327545,0.004161,0.002127,0.054037,277.605255,14.141885,0.540369,-128.327545,0.054089,0.000000
61.310001,62.394730,-128.416504,0.004161,0.002127,0.054037,277.545624,14.138847,0.540369,-128.416504,0.054089,0.000000
61.480003,62.388771,-128.416504,0.004161,0.002127,0.054037,277.519104,14.137498,0.540369,-128.416504,0.054089,0.000000
61.650002,62.368668,-128.505463,0.004148,0.002127,0.054037,277.429687,14.132942,0.540369,-128.505463,0.054089,0.000000
61.820004,62.369034,-128.416504,0.004165,0.002127,0.054037,277.431305,14.133025,0.540369,-128.416504,0.054089,0.000000
61.990002,62.353394,-128.416504,0.004152,0.002127,0.054037,277.361755,14.129480,0.540369,-128.416504,0.054089,0.000000
62.160004,62.371269,-128.460983,0.004152,0.002127,0.054037,277.441254,14.133532,0.540369,-128.460983,0.054089,0.000000
62.330002,62.324348,-128.594437,0.004148,0.002127,0.054037,277.232544,14.122900,0.540369,-128.594437,0.054089,0.000000
62.500004,62.328079,-128.594437,0.004161,0.002127,0.054037,277.249146,14.123745,0.540369,-128.594437,0.054089,0.000000
62.670002,62.321747,-128.638916,0.004161,0.002127,0.054037,277.220978,14.122310,0.540369,-128.638916,0.054089,0.000000
62.840004,62.325470,-128.683395,0.004156,0.002127,0.054037,277.237549,14.123154,0.540369,-128.683395,0.054089,0.000000
63.010002,62.307220,-128.683395,0.004161,0.002127,0.054037,277.156372,14.119018,0.540369,-128.683395,0.054089,0.000000
63.180004,62.297539,-128.727875,0.004152,0.002127,0.054037,277.113281,14.116824,0.540369,-128.727875,0.054089,0.000000
63.350002,62.299774,-128.683395,0.004156,0.002127,0.054037,277.123230,14.117331,0.540369,-128.683395,0.054089,0.000000
63.520004,62.293076,-128.816833,0.004156,0.002127,0.054037,277.093445,14.115813,0.540369,-128.816833,0.054089,0.000000
63.690002,62.261421,-128.727875,0.004178,0.002127,0.054037,276.952637,14.108640,0.540369,-128.727875,0.054089,0.000000
63.860004,62.284508,-128.772354,0.004152,0.002127,0.054037,277.055328,14.113871,0.540369,-128.772354,0.054089,0.000000
64.030006,62.258438,-128.905792,0.004165,0.002127,0.054037,276.939362,14.107964,0.540369,-128.905792,0.054089,0.000000
64.200005,62.269989,-128.905792,0.004156,0.002127,0.054037,276.990753,14.110581,0.540369,-128.905792,0.054089,0.000000
64.370003,62.246895,-128.905792,0.004165,0.002127,0.054037,276.888031,14.105349,0.540369,-128.905792,0.054089,0.000000
64.540001,62.240196,-128.950272,0.004156,0.002127,0.054037,276.858215,14.103830,0.540369,-128.950272,0.054089,0.000000
64.710007,62.233864,-128.994751,0.004156,0.002127,0.054037,276.830048,14.102395,0.540369,-128.994751,0.054089,0.000000
64.880005,62.242432,-129.039246,0.004161,0.002127,0.054037,276.868164,14.104337,0.540369,-129.039246,0.054089,0.000000
65.050003,62.218597,-129.083725,0.004161,0.002127,0.054037,276.762146,14.098935,0.540369,-129.083725,0.054089,0.000000
65.220001,62.226418,-128.994751,0.004161,0.002127,0.054037,276.796936,14.100707,0.540369,-128.994751,0.054089,0.000000
65.389999,62.203705,-129.039246,0.004156,0.002127,0.054037,276.695892,14.095561,0.540369,-129.039246,0.054089,0.000000
65.560005,62.214874,-129.083725,0.004156,0.002127,0.054037,276.745575,14.098092,0.540369,-129.083725,0.054089,0.000000
65.730003,62.189552,-129.172684,0.004156,0.002127,0.054037,276.632935,14.092355,0.540369,-129.172684,0.054089,0.000000
65.900002,62.187317,-129.172684,0.004148,0.002127,0.054037,276.623016,14.091847,0.540369,-129.172684,0.054089,0.000000
66.070000,62.172798,-129.217163,0.004165,0.002127,0.054037,276.558411,14.088557,0.540369,-129.217163,0.054089,0.000000
66.240005,62.175774,-129.217163,0.004165,0.002127,0.054037,276.571655,14.089231,0.540369,-129.217163,0.054089,0.000000
66.410004,62.162369,-129.261642,0.004161,0.002127,0.054037,276.512024,14.086194,0.540369,-129.261642,0.054089,0.000000
66.580002,62.163857,-129.350601,0.004161,0.002127,0.054037,276.518646,14.086532,0.540369,-129.350601,0.054089,0.000000
66.750000,62.155670,-129.350601,0.004152,0.002127,0.054037,276.482239,14.084676,0.540369,-129.350601,0.054089,0.000000
66.920006,62.147850,-129.350601,0.004165,0.002127,0.054037,276.447449,14.082905,0.540369,-129.350601,0.054089,0.000000
67.090004,62.143379,-129.350601,0.004165,0.002127,0.054037,276.427551,14.081891,0.540369,-129.350601,0.054089,0.000000
67.260002,62.127739,-129.350601,0.004152,0.002127,0.054037,276.357971,14.078347,0.540369,-129.350601,0.054089,0.000000
67.430000,62.130348,-129.439575,0.004152,0.002127,0.054037,276.369598,14.078938,0.540369,-129.439575,0.054089,0.000000
67.600006,62.116196,-129.528534,0.004169,0.002127,0.054037,276.306641,14.075731,0.540369,-129.528534,0.054089,0.000000
67.770004,62.118057,-129.484055,0.004161,0.002127,0.054037,276.314911,14.076153,0.540369,-129.484055,0.054089,0.000000
67.940002,62.107628,-129.573013,0.004156,0.002127,0.054037,276.268524,14.073790,0.540369,-129.573013,0.054089,0.000000
68.110001,62.100555,-129.484055,0.004165,0.002127,0.054037,276.237061,14.072186,0.540369,-129.484055,0.054089,0.000000
68.280006,62.086777,-129.528534,0.004156,0.002127,0.054037,276.175781,14.069064,0.540369,-129.528534,0.054089,0.000000
68.450005,62.085289,-129.661972,0.004156,0.002127,0.054037,276.169159,14.068727,0.540369,-129.661972,0.054089,0.000000
68.620003,62.068901,-129.617493,0.004165,0.002127,0.054037,276.096252,14.065014,0.540369,-129.617493,0.054089,0.000000
68.700005,62.062943,-129.706451,0.004165,0.002127,0.054037,276.069763,14.063663,0.540369,-129.706451,0.054089,0.000000