File: Data/type 1 compression/Support type 1-2_04162024_185524.csv
Time (sec),S:Load (lbs),S:HL1 (DIM),S:LVDT (in),S:Position (in),Ch:Position (mm),Ch:Load (N),Ch:Stress (MPa),Ch:Strain (mm/mm),Ch:HL1 (DIM),Set Point (),Cycles ()
0.110000,-0.007812,-138.869522,0.000000,-0.000000,-0.000000,-0.034752,-0.001770,-0.000000,-138.869522,-0.000173,0.000000
0.270000,-0.014145,-138.914017,-0.000013,-0.000000,-0.000000,-0.062920,-0.003205,-0.000000,-138.914017,-0.000173,0.000000
0.430000,0.012291,-139.002975,-0.000017,0.000003,0.000078,0.054673,0.002785,0.000780,-139.002975,0.000625,0.000000
0.590000,-0.001862,-138.958496,-0.000009,0.000100,0.002532,-0.008281,-0.000422,0.025321,-138.958496,0.003296,0.000000
0.750000,-0.011543,-139.047455,-0.000009,0.000198,0.005038,-0.051347,-0.002616,0.050385,-139.047455,0.005949,0.000000
0.910000,-0.013031,-139.002975,0.000060,0.000299,0.007589,-0.057965,-0.002953,0.075887,-139.002975,0.008620,0.000000
1.070000,0.087509,-139.002975,0.000181,0.000405,0.010294,0.389260,0.019830,0.102942,-139.002975,0.011291,0.000000
1.230000,0.179489,-139.047455,0.000259,0.000503,0.012783,0.798408,0.040673,0.127831,-139.047455,0.013945,0.000000
1.390000,0.491905,-139.002975,0.000384,0.000609,0.015480,2.188104,0.111467,0.154802,-139.002975,0.016616,0.000000
1.550000,0.713097,-139.136414,0.000431,-0.000000,-0.000000,3.172012,0.161590,-0.000000,-139.136414,0.000148,0.000000
1.710000,0.687775,-139.091934,0.000427,-0.000000,-0.000008,3.059375,0.155852,-0.000083,-139.091934,0.000148,0.000000
1.870000,0.687401,-139.136414,0.000431,-0.000001,-0.000017,3.057712,0.155767,-0.000174,-139.136414,0.000148,0.000000
2.030000,0.634529,-139.180893,0.000431,-0.000001,-0.000017,2.822526,0.143786,-0.000174,-139.180893,0.000226,0.000000
2.190000,0.667671,-139.136414,0.000423,-0.000001,-0.000017,2.969950,0.151296,-0.000174,-139.136414,0.000486,0.000000
2.350000,0.680702,-139.225372,0.000435,-0.000001,-0.000017,3.027915,0.154249,-0.000174,-139.225372,0.000755,0.000000
2.510000,0.671761,-139.225372,0.000431,-0.000001,-0.000017,2.988140,0.152223,-0.000174,-139.225372,0.001023,0.000000
2.670000,0.736557,-139.225372,0.000431,0.000018,0.000469,3.276369,0.166906,0.004686,-139.225372,0.001292,0.000000
2.830000,0.800980,-139.314346,0.000440,0.000027,0.000694,3.562935,0.181505,0.006941,-139.314346,0.001553,0.000000
2.990000,0.868004,-139.314346,0.000440,0.000036,0.000902,3.861074,0.196692,0.009023,-139.314346,0.001821,0.000000
3.150000,0.924606,-139.358826,0.000457,0.000045,0.001136,4.112854,0.209519,0.011362,-139.358826,0.002090,0.000000
3.310000,1.045624,-139.358826,0.000470,0.000062,0.001578,4.651167,0.236942,0.015783,-139.358826,0.002359,0.000000
3.470000,1.123451,-139.403305,0.000483,0.000071,0.001813,4.997361,0.254578,0.018130,-139.403305,0.002619,0.000000
3.630000,1.178192,-139.447784,0.000483,0.000077,0.001960,5.240860,0.266982,0.019598,-139.447784,0.002888,0.000000
3.790000,1.226974,-139.403305,0.000496,0.000083,0.002117,5.457855,0.278036,0.021165,-139.403305,0.003157,0.000000
3.950000,1.348740,-139.492264,0.000504,0.000104,0.002637,5.999494,0.305629,0.026366,-139.492264,0.003426,0.000000
4.110000,1.434753,-139.492264,0.000522,0.000114,0.002888,6.382102,0.325120,0.028879,-139.492264,0.003686,0.000000
4.270000,1.540878,-139.536743,0.000539,0.000122,0.003096,6.854169,0.349168,0.030960,-139.536743,0.003954,0.000000
4.430000,1.667488,-139.581223,0.000530,0.000136,0.003443,7.417357,0.377858,0.034427,-139.581223,0.004224,0.000000
4.590000,1.730789,-139.492264,0.000539,0.000145,0.003686,7.698935,0.392202,0.036857,-139.492264,0.004493,0.000000
4.750000,1.796700,-139.625702,0.000565,0.000152,0.003868,7.992119,0.407138,0.038682,-139.625702,0.004752,0.000000
4.910000,1.893517,-139.625702,0.000556,0.000161,0.004085,8.422782,0.429077,0.040847,-139.625702,0.005022,0.000000
5.070000,2.036507,-139.670181,0.000573,0.000173,0.004406,9.058834,0.461479,0.044056,-139.670181,0.005291,0.000000
5.230000,2.219719,-139.714661,0.000578,0.000187,0.004752,9.873803,0.502995,0.047523,-139.714661,0.005559,0.000000
5.390000,2.294937,-139.625702,0.000595,0.000195,0.004952,10.208390,0.520040,0.049522,-139.625702,0.005820,0.000000
5.550000,2.391754,-139.759155,0.000604,0.000203,0.005151,10.639053,0.541979,0.051512,-139.759155,0.006088,0.000000
5.710000,2.498619,-139.759155,0.000612,0.000212,0.005386,11.114412,0.566195,0.053859,-139.759155,0.006357,0.000000
5.870000,2.664703,-139.803635,0.000621,0.000225,0.005724,11.853192,0.603830,0.057235,-139.803635,0.006626,0.000000
6.030000,2.813278,-139.848114,0.000625,0.000236,0.005984,12.514087,0.637498,0.059839,-139.848114,0.006886,0.000000
6.190000,2.977867,-139.803635,0.000638,0.000249,0.006314,13.246215,0.674794,0.063140,-139.803635,0.007155,0.000000
6.350000,3.066490,-139.848114,0.000651,0.000256,0.006513,13.640429,0.694877,0.065130,-139.848114,0.007424,0.000000
6.510000,3.215065,-139.892593,0.000664,0.000270,0.006851,14.301323,0.728544,0.068514,-139.892593,0.007692,0.000000
6.670001,3.358429,-139.892593,0.000681,0.000280,0.007112,14.939038,0.761031,0.071118,-139.892593,0.007953,0.000000
6.830000,3.489510,-139.981552,0.000677,0.000289,0.007328,15.522114,0.790734,0.073283,-139.981552,0.008222,0.000000
6.990000,3.541267,-139.981552,0.000681,0.000294,0.007459,15.752344,0.802463,0.074585,-139.981552,0.008490,0.000000
7.150001,3.876770,-139.981552,0.000694,0.000311,0.007901,17.244734,0.878489,0.079006,-139.981552,0.008759,0.000000
7.310000,3.975822,-139.981552,0.000703,0.000320,0.008126,17.685341,0.900934,0.081262,-139.981552,0.009019,0.000000
7.470000,4.142273,-140.026031,0.000711,0.000330,0.008377,18.425751,0.938652,0.083775,-140.026031,0.009288,0.000000
7.630001,4.191803,-140.026031,0.000711,0.000335,0.008499,18.646070,0.949876,0.084994,-140.026031,0.009557,0.000000
7.790000,4.292717,-140.070511,0.000724,0.000340,0.008646,19.094959,0.972744,0.086462,-140.070511,0.009826,0.000000
7.950000,4.521347,-140.114990,0.000737,0.000360,0.009150,20.111956,1.024552,0.091496,-140.114990,0.010086,0.000000
8.110001,4.887764,-140.114990,0.000759,0.000374,0.009496,21.741859,1.107583,0.094963,-140.114990,0.010355,0.000000
8.270000,5.045647,-140.114990,0.000759,0.000383,0.009739,22.444157,1.143360,0.097393,-140.114990,0.010623,0.000000
8.430000,5.220291,-140.159470,0.000772,0.000398,0.010103,23.221014,1.182935,0.101034,-140.159470,0.010892,0.000000
8.590000,5.311150,-140.203964,0.000785,0.000405,0.010277,23.625174,1.203524,0.102767,-140.203964,0.011153,0.000000
8.750000,5.485046,-140.337402,0.000785,0.000414,0.010520,24.398705,1.242929,0.105197,-140.337402,0.011421,0.000000
8.910001,5.590431,-140.292923,0.000789,0.000420,0.010676,24.867479,1.266810,0.106757,-140.292923,0.011690,0.000000
9.070001,5.910301,-140.292923,0.000811,0.000437,0.011092,26.290333,1.339293,0.110920,-140.292923,0.011960,0.000000
9.230000,6.199257,-140.292923,0.000815,0.000448,0.011387,27.575672,1.404772,0.113872,-140.292923,0.012219,0.000000
9.390000,6.241714,-140.337402,0.000828,0.000455,0.011561,27.764532,1.414393,0.115606,-140.337402,0.012488,0.000000
9.550000,6.283791,-140.381882,0.000823,0.000459,0.011664,27.951696,1.423927,0.116643,-140.381882,0.012757,0.000000
9.710000,6.569023,-140.292923,0.000841,0.000472,0.011985,29.220474,1.488562,0.119852,-140.292923,0.013026,0.000000
9.870001,6.923149,-140.426361,0.000858,0.000487,0.012376,30.795706,1.568808,0.123758,-140.426361,0.013286,0.000000
10.030001,7.110458,-140.381882,0.000862,0.000499,0.012662,31.628899,1.611253,0.126620,-140.381882,0.013555,0.000000
10.190001,7.316002,-140.426361,0.000867,0.000511,0.012974,32.543201,1.657830,0.129739,-140.426361,0.013824,0.000000
10.350000,7.456390,-140.515320,0.000884,0.000521,0.013243,33.167683,1.689642,0.132426,-140.515320,0.014093,0.000000
10.510000,7.576668,-140.470840,0.000880,0.000531,0.013486,33.702702,1.716897,0.134856,-140.470840,0.014353,0.000000
10.670000,7.759125,-140.470840,0.000897,0.000541,0.013737,34.514309,1.758243,0.137369,-140.470840,0.014622,0.000000
10.830001,7.915901,-140.559799,0.000897,0.000549,0.013945,35.211685,1.793769,0.139451,-140.559799,0.014891,0.000000
10.990001,8.089798,-140.559799,0.000914,0.000560,0.014214,35.985218,1.833174,0.142138,-140.559799,0.015159,0.000000
11.150001,8.375778,-140.604294,0.000914,0.000571,0.014492,37.257320,1.897978,0.144916,-140.604294,0.015420,0.000000
11.310000,8.545204,-140.648773,0.000931,0.000579,0.014708,38.010967,1.936371,0.147081,-140.648773,0.015688,0.000000
11.470000,8.676285,-140.693253,0.000940,0.000588,0.014925,38.594044,1.966074,0.149254,-140.693253,0.015957,0.000000
11.630000,8.875504,-140.693253,0.000949,0.000597,0.015159,39.480213,2.011218,0.151593,-140.693253,0.016226,0.000000
11.790001,8.920189,-140.693253,0.000957,0.000603,0.015315,39.678982,2.021344,0.153152,-140.693253,0.016486,0.000000
11.950001,9.557686,-140.737732,0.000970,0.000628,0.015957,42.514709,2.165802,0.159571,-140.737732,0.016755,0.000000
12.110001,9.668655,-140.737732,0.000992,0.000638,0.016200,43.008327,2.190948,0.162001,-140.737732,0.017024,0.000000
12.270000,9.782600,-140.782211,0.000992,0.000647,0.016426,43.515179,2.216769,0.164257,-140.782211,0.017292,0.000000
12.430000,9.917397,-140.782211,0.000996,0.000657,0.016694,44.114784,2.247314,0.166944,-140.782211,0.017553,0.000000
12.590000,9.958733,-140.871170,0.001000,0.000663,0.016842,44.298656,2.256681,0.168420,-140.871170,0.017822,0.000000
12.750001,10.032837,-140.871170,0.001000,0.000666,0.016928,44.628288,2.273473,0.169283,-140.871170,0.018090,0.000000
12.910001,10.488617,-140.826691,0.001018,0.000686,0.017432,46.655697,2.376755,0.174317,-140.826691,0.018359,0.000000
13.070001,10.756729,-140.960129,0.001026,0.000696,0.017683,47.848320,2.437510,0.176830,-140.960129,0.018619,0.000000
13.230000,10.946266,-140.915649,0.001039,0.000706,0.017934,48.691425,2.480459,0.179343,-140.915649,0.018888,0.000000
13.390000,11.011429,-141.004608,0.001048,0.000713,0.018117,48.981281,2.495225,0.181168,-141.004608,0.019157,0.000000
13.550000,11.207298,-141.004608,0.001056,0.000726,0.018429,49.852554,2.539610,0.184287,-141.004608,0.019426,0.000000
13.710001,11.427368,-140.960129,0.001065,0.000737,0.018724,50.831470,2.589479,0.187239,-140.960129,0.019686,0.000000
13.870001,11.877197,-141.049103,0.001082,0.000751,0.019071,52.832413,2.691411,0.190706,-141.049103,0.019955,0.000000
14.030001,12.000450,-141.004608,0.001099,0.000761,0.019331,53.380669,2.719341,0.193310,-141.004608,0.020224,0.000000
14.190001,12.172485,-141.138062,0.001108,0.000773,0.019643,54.145920,2.758325,0.196428,-141.138062,0.020493,0.000000
14.350000,12.364632,-141.182541,0.001104,0.000783,0.019877,55.000629,2.801866,0.198768,-141.182541,0.020753,0.000000
14.510000,12.399635,-141.093582,0.001112,0.000791,0.020102,55.156334,2.809798,0.201023,-141.093582,0.021022,0.000000
14.670001,12.594383,-141.182541,0.001130,0.000801,0.020354,56.022614,2.853928,0.203537,-141.182541,0.021291,0.000000
14.830001,12.827118,-141.182541,0.001125,0.000811,0.020597,57.057869,2.906666,0.205966,-141.182541,0.021560,0.000000
14.990001,13.049797,-141.227020,0.001134,0.000823,0.020909,58.048397,2.957126,0.209093,-141.227020,0.021820,0.000000
15.150001,13.305244,-141.271500,0.001147,0.000834,0.021186,59.184685,3.015012,0.211863,-141.271500,0.022089,0.000000
15.310000,13.375252,-141.227020,0.001155,0.000840,0.021342,59.496090,3.030875,0.213423,-141.227020,0.022357,0.000000
15.470000,13.570000,-141.315979,0.001151,0.000852,0.021637,60.362373,3.075006,0.216375,-141.315979,0.022626,0.000000
15.630001,13.906250,-141.271500,0.001177,0.000864,0.021949,61.858089,3.151201,0.219494,-141.271500,0.022887,0.000000
15.790001,14.278252,-141.315979,0.001177,0.000878,0.022297,63.512836,3.235498,0.222968,-141.315979,0.023155,0.000000
15.950001,14.284958,-141.315979,0.001181,0.000886,0.022496,63.542667,3.237018,0.224959,-141.315979,0.023424,0.000000
16.110001,14.624931,-141.271500,0.001216,0.000900,0.022860,65.054947,3.314057,0.228600,-141.271500,0.023693,0.000000
16.270000,14.754143,-141.404938,0.001224,0.000909,0.023095,65.629707,3.343336,0.230947,-141.404938,0.023953,0.000000
16.430000,14.859901,-141.404938,0.001220,0.000917,0.023303,66.100143,3.367302,0.233028,-141.404938,0.024222,0.000000
16.590000,15.095612,-141.449417,0.001229,0.000930,0.023632,67.148636,3.420714,0.236321,-141.449417,0.024491,0.000000
16.750000,15.321266,-141.449417,0.001233,0.000941,0.023893,68.152397,3.471849,0.238925,-141.449417,0.024759,0.000000
16.910002,15.621399,-141.493912,0.001250,0.000952,0.024179,69.487450,3.539860,0.241787,-141.493912,0.025020,0.000000
17.070002,15.741676,-141.538391,0.001250,0.000962,0.024430,70.022476,3.567115,0.244300,-141.538391,0.025288,0.000000
17.230001,15.872749,-141.538391,0.001263,0.000968,0.024586,70.605515,3.596816,0.245859,-141.538391,0.025557,0.000000
17.390001,16.321091,-141.582870,0.001276,0.000985,0.025020,72.599838,3.698412,0.250197,-141.582870,0.025826,0.000000
17.550001,16.531105,-141.627350,0.001281,0.000995,0.025263,73.534027,3.746002,0.252627,-141.627350,0.026086,0.000000
17.710001,16.878906,-141.538391,0.001298,0.001009,0.025627,75.081123,3.824815,0.256268,-141.538391,0.026355,0.000000
17.870001,17.079613,-141.671829,0.001311,0.001020,0.025895,75.973915,3.870296,0.258955,-141.671829,0.026624,0.000000
18.030001,17.192070,-141.582870,0.001306,0.001029,0.026138,76.474144,3.895779,0.261385,-141.582870,0.026893,0.000000
18.190001,17.173820,-141.716309,0.001319,0.001036,0.026312,76.392967,3.891643,0.263118,-141.716309,0.027153,0.000000
18.350000,17.412888,-141.716309,0.001324,0.001047,0.026590,77.456390,3.945817,0.265896,-141.716309,0.027422,0.000000
18.510000,17.701843,-141.805267,0.001332,0.001057,0.026858,78.741730,4.011295,0.268584,-141.805267,0.027691,0.000000
18.670000,18.029160,-141.805267,0.001337,0.001069,0.027153,80.197708,4.085466,0.271528,-141.805267,0.027960,0.000000
18.830002,18.187050,-141.760788,0.001358,0.001078,0.027387,80.900040,4.121244,0.273875,-141.760788,0.028219,0.000000
18.990002,18.464462,-141.894241,0.001362,0.001088,0.027639,82.134033,4.184107,0.276388,-141.894241,0.028489,0.000000
19.150002,18.589951,-141.805267,0.001371,0.001095,0.027812,82.692230,4.212543,0.278122,-141.805267,0.028758,0.000000
19.310001,18.495369,-141.894241,0.001367,0.001102,0.027995,82.271507,4.191111,0.279946,-141.894241,0.029026,0.000000
19.470001,19.259850,-141.894241,0.001384,0.001119,0.028428,85.672089,4.364344,0.284276,-141.894241,0.029287,0.000000
19.630001,19.627754,-141.805267,0.001393,0.001132,0.028758,87.308609,4.447712,0.287576,-141.805267,0.029555,0.000000
19.790001,19.823250,-141.983200,0.001406,0.001141,0.028974,88.178223,4.492013,0.289741,-141.983200,0.029824,0.000000
19.950001,20.148331,-141.983200,0.001414,0.001154,0.029303,89.624252,4.565677,0.293034,-141.983200,0.030093,0.000000
20.110001,20.286858,-142.027679,0.001431,0.001164,0.029555,90.240448,4.597068,0.295555,-142.027679,0.030353,0.000000
20.270000,20.461868,-141.983200,0.001431,0.001173,0.029789,91.018936,4.636725,0.297894,-141.983200,0.030622,0.000000
20.430000,20.782852,-142.027679,0.001431,0.001183,0.030050,92.446747,4.709461,0.300498,-142.027679,0.030891,0.000000
20.590000,20.865898,-142.072159,0.001449,0.001192,0.030284,92.816147,4.728280,0.302837,-142.072159,0.031160,0.000000
20.750002,21.145172,-142.116638,0.001453,0.001202,0.030535,94.058426,4.791564,0.305350,-142.116638,0.031420,0.000000
20.910002,21.570793,-142.116638,0.001466,0.001213,0.030813,95.951683,4.888011,0.308128,-142.116638,0.031689,0.000000
21.070002,21.814697,-142.161118,0.001462,0.001222,0.031038,97.036621,4.943281,0.310384,-142.161118,0.031957,0.000000
21.230001,21.758102,-142.116638,0.001462,0.001228,0.031185,96.784874,4.930457,0.311853,-142.116638,0.032226,0.000000
21.390001,22.374374,-142.250076,0.001483,0.001244,0.031593,99.526192,5.070106,0.315933,-142.250076,0.032487,0.000000
21.550001,22.623489,-142.250076,0.001483,0.001252,0.031810,100.634308,5.126556,0.318098,-142.250076,0.032755,0.000000
21.710001,23.214821,-142.250076,0.001505,0.001267,0.032191,103.264679,5.260554,0.321913,-142.250076,0.033024,0.000000
21.870001,23.538414,-142.250076,0.001505,0.001279,0.032487,104.704094,5.333881,0.324865,-142.250076,0.033293,0.000000
22.030001,23.636345,-142.294556,0.001522,0.001288,0.032712,105.139709,5.356072,0.327121,-142.294556,0.033553,0.000000
22.190001,23.806892,-142.339050,0.001526,0.001295,0.032885,105.898346,5.394719,0.328854,-142.339050,0.033822,0.000000
22.350000,24.125641,-142.383530,0.001518,0.001305,0.033154,107.316208,5.466948,0.331542,-142.383530,0.034091,0.000000
22.510000,24.510674,-142.383530,0.001531,0.001316,0.033432,109.028923,5.554198,0.334320,-142.383530,0.034360,0.000000
22.670002,24.872620,-142.428009,0.001535,0.001328,0.033726,110.638939,5.636216,0.337264,-142.428009,0.034620,0.000000
22.830002,25.426712,-142.383530,0.001552,0.001342,0.034082,113.103661,5.761775,0.340822,-142.383530,0.034888,0.000000
22.990002,25.587204,-142.428009,0.001556,0.001349,0.034273,113.817566,5.798143,0.342730,-142.428009,0.035158,0.000000
23.150002,25.586464,-142.472488,0.001569,0.001355,0.034429,113.814278,5.797976,0.344289,-142.472488,0.035427,0.000000
23.310001,25.869087,-142.472488,0.001587,0.001367,0.034732,115.071449,5.862019,0.347325,-142.472488,0.035686,0.000000
23.470001,26.610115,-142.561447,0.001582,0.001379,0.035028,118.367706,6.029938,0.350277,-142.561447,0.035956,0.000000
23.630001,27.002220,-142.516968,0.001582,0.001393,0.035383,120.111877,6.118791,0.353827,-142.516968,0.036224,0.000000
23.790001,27.311287,-142.605927,0.001595,0.001402,0.035608,121.486671,6.188826,0.356083,-142.605927,0.036493,0.000000
23.950001,27.611794,-142.605927,0.001600,0.001411,0.035843,122.823395,6.256922,0.358430,-142.605927,0.036753,0.000000
24.110001,27.931290,-142.605927,0.001617,0.001421,0.036103,124.244583,6.329321,0.361026,-142.605927,0.037022,0.000000
24.270000,28.181526,-142.650406,0.001621,0.001431,0.036355,125.357689,6.386025,0.363547,-142.650406,0.037291,0.000000
24.430000,28.655556,-142.650406,0.001634,0.001442,0.036632,127.466278,6.493442,0.366317,-142.650406,0.037560,0.000000
24.590002,29.210014,-142.650406,0.001630,0.001456,0.036978,129.932632,6.619084,0.369784,-142.650406,0.037829,0.000000
24.750002,29.681068,-142.739365,0.001638,0.001466,0.037239,132.027985,6.725826,0.372388,-142.739365,0.038089,0.000000
24.910002,29.886246,-142.783859,0.001647,0.001474,0.037439,132.940659,6.772320,0.374387,-142.783859,0.038358,0.000000
25.070002,29.823311,-142.783859,0.001660,0.001477,0.037517,132.660706,6.758059,0.375166,-142.783859,0.038626,0.000000
25.230001,30.143929,-142.783859,0.001673,0.001490,0.037838,134.086884,6.830712,0.378376,-142.783859,0.038895,0.000000
25.390001,31.293816,-142.828339,0.001677,0.001507,0.038280,139.201843,7.091280,0.382797,-142.828339,0.039155,0.000000
25.550001,31.669167,-142.828339,0.001673,0.001518,0.038548,140.871490,7.176336,0.385484,-142.828339,0.039424,0.000000
25.710001,32.124573,-142.872818,0.001681,0.001529,0.038826,142.897232,7.279532,0.388262,-142.872818,0.039693,0.000000
25.870001,32.599724,-142.872818,0.001694,0.001540,0.039121,145.010818,7.387203,0.391207,-142.872818,0.039962,0.000000
26.030001,32.734894,-142.872818,0.001712,0.001547,0.039294,145.612076,7.417833,0.392940,-142.872818,0.040222,0.000000
26.190001,32.982895,-142.961777,0.001725,0.001556,0.039520,146.715240,7.474031,0.395196,-142.961777,0.040491,0.000000
26.350000,33.345589,-142.917297,0.001712,0.001568,0.039815,148.328583,7.556219,0.398148,-142.917297,0.040760,0.000000
26.510002,34.188637,-143.006256,0.001725,0.001583,0.040196,152.078659,7.747256,0.401963,-143.006256,0.041029,0.000000
26.670002,34.698418,-142.961777,0.001738,0.001590,0.040378,154.346268,7.862774,0.403780,-142.961777,0.041289,0.000000
26.830002,35.106163,-143.006256,0.001746,0.001601,0.040656,156.160019,7.955170,0.406558,-143.006256,0.041557,0.000000
26.990002,35.269630,-143.095215,0.001746,0.001607,0.040821,156.887146,7.992213,0.408208,-143.095215,0.041826,0.000000
27.150002,35.515770,-143.050735,0.001750,0.001614,0.041003,157.982040,8.047988,0.410025,-143.050735,0.042096,0.000000
27.310001,36.555809,-143.228668,0.001755,0.001634,0.041497,162.608353,8.283665,0.414968,-143.228668,0.042355,0.000000
27.470001,37.071915,-143.228668,0.001755,0.001645,0.041775,164.904114,8.400617,0.417746,-143.228668,0.042624,0.000000
27.630001,37.460304,-143.228668,0.001781,0.001653,0.041974,166.631760,8.488626,0.419737,-143.228668,0.042893,0.000000
27.790001,37.898582,-143.228668,0.001781,0.001664,0.042277,168.581314,8.587941,0.422773,-143.228668,0.043162,0.000000
27.950001,38.218826,-143.184189,0.001794,0.001672,0.042460,170.005829,8.660509,0.424597,-143.184189,0.043422,0.000000
28.110001,38.676094,-143.228668,0.001794,0.001684,0.042763,172.039856,8.764128,0.427633,-143.228668,0.043691,0.000000
28.270000,39.164650,-143.273148,0.001802,0.001692,0.042980,174.213058,8.874836,0.429798,-143.273148,0.043960,0.000000
28.430002,39.814064,-143.273148,0.001802,0.001706,0.043344,177.101807,9.021996,0.433439,-143.273148,0.044229,0.000000
28.590002,40.486946,-143.273148,0.001811,0.001715,0.043569,180.094925,9.174473,0.435694,-143.273148,0.044489,0.000000
28.750002,40.928581,-143.317627,0.001811,0.001726,0.043830,182.059418,9.274549,0.438298,-143.317627,0.044758,0.000000
28.910002,40.956131,-143.317627,0.001819,0.001730,0.043943,182.181976,9.280792,0.439426,-143.317627,0.045027,0.000000
29.070002,41.286430,-143.362106,0.001815,0.001738,0.044133,183.651215,9.355639,0.441334,-143.362106,0.045295,0.000000
29.230001,41.497566,-143.451065,0.001832,0.001744,0.044307,184.590393,9.403483,0.443067,-143.451065,0.045556,0.000000
29.390001,43.312134,-143.495544,0.001828,0.001771,0.044974,192.661987,9.814670,0.449744,-143.495544,0.045824,0.000000
29.550001,43.696053,-143.406586,0.001845,0.001780,0.045217,194.369751,9.901668,0.452174,-143.406586,0.046093,0.000000
29.710001,44.230034,-143.540024,0.001858,0.001792,0.045529,196.745010,10.022669,0.455293,-143.540024,0.046362,0.000000
29.870001,44.695869,-143.540024,0.001863,0.001800,0.045712,198.817154,10.128229,0.457117,-143.540024,0.046622,0.000000
30.030001,45.176231,-143.540024,0.001876,0.001810,0.045972,200.953918,10.237081,0.459721,-143.540024,0.046891,0.000000
30.190001,45.379547,-143.628998,0.001850,0.001818,0.046189,201.858307,10.283153,0.461886,-143.628998,0.047160,0.000000
30.350002,45.814476,-143.540024,0.001876,0.001828,0.046422,203.792969,10.381708,0.464225,-143.540024,0.047429,0.000000
30.510002,47.115547,-143.628998,0.001880,0.001844,0.046839,209.580414,10.676536,0.468388,-143.628998,0.047689,0.000000
30.670002,47.495735,-143.628998,0.001884,0.001851,0.047012,211.271576,10.762688,0.470122,-143.628998,0.047958,0.000000
30.830002,47.615273,-143.673477,0.001897,0.001856,0.047151,211.803314,10.789775,0.471515,-143.673477,0.048226,0.000000
30.990002,48.078873,-143.673477,0.001888,0.001867,0.047420,213.865509,10.894829,0.474202,-143.673477,0.048495,0.000000
31.150002,48.419594,-143.673477,0.001906,0.001875,0.047619,215.381104,10.972036,0.476193,-143.673477,0.048756,0.000000
31.310001,49.734070,-143.806915,0.001914,0.001892,0.048062,221.228195,11.269901,0.480621,-143.806915,0.049024,0.000000
31.470001,50.373802,-143.762436,0.001910,0.001902,0.048304,224.073868,11.414866,0.483043,-143.762436,0.049293,0.000000
31.630001,51.182602,-143.806915,0.001919,0.001917,0.048687,227.671585,11.598143,0.486866,-143.806915,0.049562,0.000000
31.790001,51.657745,-143.895874,0.001919,0.001925,0.048903,229.785126,11.705812,0.489031,-143.895874,0.049822,0.000000
31.950001,52.163055,-143.851395,0.001936,0.001934,0.049111,232.032852,11.820317,0.491113,-143.851395,0.050091,0.000000
32.110001,52.843376,-143.984833,0.001936,0.001945,0.049415,235.059082,11.974481,0.494148,-143.984833,0.050360,0.000000
32.270000,53.204956,-143.940353,0.001944,0.001953,0.049606,236.667465,12.056416,0.496056,-143.940353,0.050629,0.000000
32.430000,54.227859,-143.940353,0.001936,0.001968,0.049979,241.217560,12.288209,0.499788,-143.940353,0.050889,0.000000
32.590000,54.559273,-144.029312,0.001953,0.001976,0.050178,242.691772,12.363308,0.501779,-144.029312,0.051158,0.000000
32.750000,54.897011,-143.984833,0.001966,0.001982,0.050334,244.194107,12.439841,0.503338,-143.984833,0.051427,0.000000
32.910000,55.454086,-144.029312,0.001970,0.001992,0.050603,246.672089,12.566075,0.506025,-144.029312,0.051696,0.000000
33.070000,55.951942,-144.073807,0.001962,0.001999,0.050785,248.886673,12.678892,0.507850,-144.073807,0.051956,0.000000
33.230003,57.458939,-144.073807,0.001975,0.002021,0.051322,255.590118,13.020382,0.513224,-144.073807,0.052225,0.000000
33.390003,58.376091,-144.073807,0.001962,0.002033,0.051643,259.669830,13.228211,0.516434,-144.073807,0.052493,0.000000
33.550003,58.816231,-144.073807,0.001983,0.002041,0.051852,261.627655,13.327949,0.518515,-144.073807,0.052762,0.000000
33.710003,59.388573,-144.118286,0.001975,0.002051,0.052095,264.173553,13.457644,0.520945,-144.118286,0.053023,0.000000
33.870003,59.705833,-144.118286,0.001996,0.002059,0.052311,265.584808,13.529535,0.523110,-144.118286,0.053291,0.000000
34.030003,60.122513,-144.162766,0.002001,0.002065,0.052441,267.438293,13.623957,0.524412,-144.162766,0.053560,0.000000
34.190002,60.809547,-144.162766,0.001992,0.002079,0.052805,270.494385,13.779640,0.528053,-144.162766,0.053829,0.000000
34.350002,62.107635,-144.207245,0.002001,0.002093,0.053161,276.268555,14.073792,0.531611,-144.207245,0.054089,0.000000
34.510002,62.669174,-144.296204,0.002009,0.002102,0.053395,278.766418,14.201038,0.533950,-144.296204,0.054358,0.000000
34.670002,63.249329,-144.251724,0.002013,0.002112,0.053638,281.347076,14.332502,0.536380,-144.251724,0.054627,0.000000
34.830002,63.693192,-144.251724,0.002026,0.002119,0.053829,283.321472,14.433084,0.538288,-144.251724,0.054895,0.000000
34.990002,64.292709,-144.340683,0.002031,0.002130,0.054098,285.988251,14.568936,0.540975,-144.340683,0.055156,0.000000
35.150002,65.418396,-144.340683,0.002026,0.002146,0.054496,290.995544,14.824020,0.544964,-144.340683,0.055424,0.000000
35.310001,66.338531,-144.385162,0.002039,0.002156,0.054765,295.088531,15.032526,0.547652,-144.385162,0.055693,0.000000
35.470001,66.906769,-144.340683,0.002035,0.002167,0.055043,297.616180,15.161290,0.550430,-144.340683,0.055962,0.000000
35.630001,67.441498,-144.385162,0.002052,0.002166,0.055008,299.994751,15.282461,0.550081,-144.385162,0.055234,0.000000
35.790001,67.126846,-144.385162,0.002044,0.002166,0.055008,298.595123,15.211161,0.550081,-144.385162,0.055234,0.000000
35.950001,66.831924,-144.429642,0.002044,0.002166,0.055008,297.283234,15.144331,0.550081,-144.429642,0.055234,0.000000
36.110001,66.625626,-144.518616,0.002057,0.002164,0.054973,296.365570,15.097583,0.549733,-144.518616,0.055008,0.000000
36.270000,66.413376,-144.518616,0.002061,0.002164,0.054956,295.421448,15.049486,0.549559,-144.518616,0.055008,0.000000
36.430000,66.233521,-144.563095,0.002065,0.002163,0.054948,294.621399,15.008730,0.549476,-144.563095,0.055008,0.000000
36.590000,66.066330,-144.563095,0.002052,0.002163,0.054939,293.877716,14.970844,0.549393,-144.563095,0.055008,0.000000
36.750000,65.898758,-144.518616,0.002070,0.002163,0.054939,293.132324,14.932872,0.549393,-144.518616,0.055008,0.000000
36.910000,65.775131,-144.607574,0.002057,0.002163,0.054939,292.582397,14.904858,0.549393,-144.607574,0.055008,0.000000
37.070004,65.645538,-144.607574,0.002061,0.002163,0.054930,292.005951,14.875492,0.549302,-144.607574,0.055008,0.000000
37.230003,65.526764,-144.652054,0.002065,0.002163,0.054930,291.477600,14.848577,0.549302,-144.652054,0.055008,0.000000
37.390003,65.434402,-144.652054,0.002070,0.002163,0.054930,291.066772,14.827648,0.549302,-144.652054,0.055008,0.000000
37.550003,65.314499,-144.696533,0.002070,0.002163,0.054930,290.533386,14.800477,0.549302,-144.696533,0.055008,0.000000
37.710003,65.216568,-144.696533,0.002074,0.002163,0.054930,290.097778,14.778286,0.549302,-144.696533,0.055008,0.000000
37.870003,65.150284,-144.696533,0.002065,0.002162,0.054922,289.802948,14.763266,0.549219,-144.696533,0.055008,0.000000
38.030003,65.047516,-144.785492,0.002065,0.002162,0.054922,289.345795,14.739977,0.549219,-144.785492,0.055008,0.000000
38.190002,64.987198,-144.741013,0.002057,0.002162,0.054922,289.077484,14.726310,0.549219,-144.741013,0.055008,0.000000
38.350002,64.911606,-144.785492,0.002065,0.002162,0.054922,288.741241,14.709181,0.549219,-144.785492,0.055008,0.000000
38.510002,64.811066,-144.829971,0.002070,0.002162,0.054922,288.294006,14.686398,0.549219,-144.829971,0.055008,0.000000
38.670002,64.744781,-144.874451,0.002065,0.002162,0.054922,287.999176,14.671377,0.549219,-144.874451,0.055008,0.000000
38.830002,64.712387,-144.918945,0.002074,0.002162,0.054922,287.855072,14.664037,0.549219,-144.918945,0.055008,0.000000
38.990002,64.621155,-144.918945,0.002057,0.002162,0.054922,287.449249,14.643363,0.549219,-144.918945,0.055008,0.000000
39.150002,64.565292,-144.963425,0.002074,0.002162,0.054922,287.200775,14.630704,0.549219,-144.963425,0.055008,0.000000
39.310001,64.512039,-145.007904,0.002074,0.002162,0.054922,286.963867,14.618637,0.549219,-145.007904,0.055008,0.000000
39.470001,64.457672,-145.007904,0.002074,0.002162,0.054922,286.722046,14.606317,0.549219,-145.007904,0.055008,0.000000
39.630001,64.411499,-145.007904,0.002065,0.002162,0.054922,286.516663,14.595854,0.549219,-145.007904,0.055008,0.000000
39.790001,64.361603,-145.007904,0.002074,0.002162,0.054922,286.294708,14.584548,0.549219,-145.007904,0.055008,0.000000
39.950001,64.303513,-145.052383,0.002074,0.002162,0.054922,286.036316,14.571384,0.549219,-145.052383,0.055008,0.000000
40.110001,64.265900,-145.052383,0.002078,0.002162,0.054922,285.868988,14.562861,0.549219,-145.052383,0.055008,0.000000
40.270000,64.224579,-145.096863,0.002074,0.002162,0.054922,285.685181,14.553497,0.549219,-145.096863,0.055008,0.000000
40.430000,64.170578,-145.185822,0.002065,0.002162,0.054922,285.444977,14.541261,0.549219,-145.185822,0.055008,0.000000
40.590000,64.116959,-145.141342,0.002074,0.002162,0.054922,285.206482,14.529110,0.549219,-145.141342,0.055008,0.000000
40.750004,64.095352,-145.230301,0.002074,0.002162,0.054922,285.110352,14.524215,0.549219,-145.230301,0.055008,0.000000
40.910004,64.054764,-145.185822,0.002061,0.002162,0.054922,284.929810,14.515018,0.549219,-145.185822,0.055008,0.000000
41.070004,64.004868,-145.185822,0.002061,0.002162,0.054922,284.707855,14.503710,0.549219,-145.185822,0.055008,0.000000
41.230003,63.983276,-145.319260,0.002070,0.002162,0.054922,284.611816,14.498817,0.549219,-145.319260,0.055008,0.000000
41.390003,63.935989,-145.274780,0.002074,0.002162,0.054922,284.401489,14.488102,0.549219,-145.274780,0.055008,0.000000
41.550003,63.889069,-145.363754,0.002070,0.002162,0.054922,284.192780,14.477469,0.549219,-145.363754,0.055008,0.000000
41.710003,63.872681,-145.363754,0.002074,0.002162,0.054922,284.119873,14.473757,0.549219,-145.363754,0.055008,0.000000
41.870003,63.831726,-145.363754,0.002078,0.002162,0.054922,283.937714,14.464476,0.549219,-145.363754,0.055008,0.000000
42.030003,63.786285,-145.452713,0.002065,0.002162,0.054922,283.735565,14.454179,0.549219,-145.452713,0.055008,0.000000
42.190002,63.773636,-145.363754,0.002078,0.002162,0.054922,283.679291,14.451313,0.549219,-145.363754,0.055008,0.000000
42.350002,63.733047,-145.408234,0.002078,0.002162,0.054922,283.498749,14.442116,0.549219,-145.408234,0.055008,0.000000
42.510002,63.695435,-145.452713,0.002074,0.002162,0.054922,283.331451,14.433592,0.549219,-145.452713,0.055008,0.000000
42.670002,63.667130,-145.452713,0.002087,0.002162,0.054922,283.205536,14.427178,0.549219,-145.452713,0.055008,0.000000
42.830002,63.639206,-145.541672,0.002070,0.002162,0.054922,283.081329,14.420850,0.549219,-145.541672,0.055008,0.000000
42.990002,63.626175,-145.497192,0.002074,0.002162,0.054922,283.023376,14.417897,0.549219,-145.497192,0.055008,0.000000
43.150002,63.593399,-145.586151,0.002078,0.002162,0.054922,282.877563,14.410470,0.549219,-145.586151,0.055008,0.000000
43.310001,63.547592,-145.630630,0.002078,0.002162,0.054922,282.673798,14.400090,0.549219,-145.630630,0.055008,0.000000
43.470001,63.522278,-145.586151,0.002074,0.002162,0.054922,282.561218,14.394354,0.549219,-145.586151,0.055008,0.000000
43.630001,63.504028,-145.675110,0.002078,0.002162,0.054922,282.480011,14.390219,0.549219,-145.675110,0.055008,0.000000
43.790001,63.483551,-145.675110,0.002078,0.002162,0.054922,282.388947,14.385578,0.549219,-145.675110,0.055008,0.000000
43.950001,63.448914,-145.675110,0.002082,0.002162,0.054922,282.234863,14.377729,0.549219,-145.675110,0.055008,0.000000
44.110001,63.431046,-145.675110,0.002070,0.002162,0.054922,282.155396,14.373681,0.549219,-145.675110,0.055008,0.000000
44.270000,63.410187,-145.675110,0.002065,0.002162,0.054922,282.062592,14.368954,0.549219,-145.675110,0.055008,0.000000
44.430000,63.369232,-145.764084,0.002087,0.002162,0.054922,281.880432,14.359674,0.549219,-145.764084,0.055008,0.000000
44.590004,63.358810,-145.764084,0.002074,0.002162,0.054922,281.834076,14.357311,0.549219,-145.764084,0.055008,0.000000
44.750004,63.342056,-145.808563,0.002078,0.002162,0.054922,281.759552,14.353516,0.549219,-145.808563,0.055008,0.000000
44.910004,63.310776,-145.853043,0.002074,0.002162,0.054922,281.620392,14.346427,0.549219,-145.853043,0.055008,0.000000
45.070004,63.289917,-145.808563,0.002082,0.002162,0.054922,281.527618,14.341701,0.549219,-145.808563,0.055008,0.000000
45.230003,63.276138,-145.942001,0.002087,0.002162,0.054922,281.466309,14.338578,0.549219,-145.942001,0.055008,0.000000
45.390003,63.244858,-145.853043,0.002082,0.002162,0.054922,281.327179,14.331490,0.549219,-145.853043,0.055008,0.000000
45.550003,63.231827,-145.942001,0.002078,0.002162,0.054922,281.269226,14.328536,0.549219,-145.942001,0.055008,0.000000
45.710003,63.210236,-145.942001,0.002065,0.002162,0.054922,281.173157,14.323644,0.549219,-145.942001,0.055008,0.000000
45.870003,63.186768,-145.942001,0.002091,0.002162,0.054922,281.068787,14.318326,0.549219,-145.942001,0.055008,0.000000
46.030003,63.173370,-146.075439,0.002078,0.002162,0.054922,281.009186,14.315290,0.549219,-146.075439,0.055008,0.000000
46.190002,63.145065,-146.030960,0.002078,0.002162,0.054922,280.883270,14.308876,0.549219,-146.030960,0.055008,0.000000
46.350002,63.132782,-146.075439,0.002078,0.002162,0.054922,280.828644,14.306092,0.549219,-146.075439,0.055008,0.000000
46.510002,63.097778,-146.075439,0.002087,0.002162,0.054922,280.672943,14.298161,0.549219,-146.075439,0.055008,0.000000
46.670002,63.089951,-146.164398,0.002082,0.002162,0.054922,280.638123,14.296387,0.549219,-146.164398,0.055008,0.000000
46.830002,63.073563,-146.119919,0.002070,0.002162,0.054922,280.565216,14.292673,0.549219,-146.119919,0.055008,0.000000
46.990002,63.048996,-146.119919,0.002078,0.002162,0.054913,280.455933,14.287107,0.549128,-146.119919,0.055008,0.000000
47.150002,63.046005,-146.119919,0.002078,0.002162,0.054913,280.442627,14.286429,0.549128,-146.119919,0.055008,0.000000
47.310001,63.018829,-146.208893,0.002082,0.002162,0.054913,280.321747,14.280272,0.549128,-146.208893,0.055008,0.000000
47.470001,62.999832,-146.164398,0.002087,0.002162,0.054913,280.237244,14.275967,0.549128,-146.164398,0.055008,0.000000
47.630001,63.000214,-146.297852,0.002074,0.002162,0.054913,280.238953,14.276052,0.549128,-146.297852,0.055008,0.000000
47.790001,62.962601,-146.208893,0.002082,0.002162,0.054913,280.071625,14.267529,0.549128,-146.208893,0.055008,0.000000
47.950001,62.952919,-146.297852,0.002087,0.002162,0.054913,280.028564,14.265335,0.549128,-146.297852,0.055008,0.000000
48.110001,62.951805,-146.253372,0.002082,0.002162,0.054913,280.023621,14.265082,0.549128,-146.253372,0.055008,0.000000
48.270000,62.914566,-146.342331,0.002087,0.002162,0.054913,279.857971,14.256644,0.549128,-146.342331,0.055008,0.000000
48.430004,62.910843,-146.342331,0.002074,0.002162,0.054913,279.841400,14.255801,0.549128,-146.342331,0.055008,0.000000
48.590004,62.893715,-146.386810,0.002082,0.002162,0.054913,279.765228,14.251919,0.549128,-146.386810,0.055008,0.000000
48.750004,62.872490,-146.431290,0.002074,0.002162,0.054913,279.670807,14.247110,0.549128,-146.431290,0.055008,0.000000
48.910004,62.860199,-146.431290,0.002078,0.002162,0.054913,279.616119,14.244325,0.549128,-146.431290,0.055008,0.000000
49.070004,62.846794,-146.475769,0.002082,0.002162,0.054913,279.556488,14.241287,0.549128,-146.475769,0.055008,0.000000
49.230003,62.830780,-146.520248,0.002087,0.002162,0.054913,279.485260,14.237658,0.549128,-146.520248,0.055008,0.000000
49.390003,62.817375,-146.475769,0.002078,0.002162,0.054913,279.425629,14.234620,0.549128,-146.475769,0.055008,0.000000
49.550003,62.791679,-146.520248,0.002078,0.002162,0.054913,279.311340,14.228798,0.549128,-146.520248,0.055008,0.000000
49.710003,62.791679,-146.520248,0.002091,0.002162,0.054913,279.311340,14.228798,0.549128,-146.520248,0.055008,0.000000
49.870003,62.765617,-146.609207,0.002082,0.002162,0.054913,279.195404,14.222892,0.549128,-146.609207,0.055008,0.000000
50.030003,62.770454,-146.653702,0.002082,0.002162,0.054913,279.216919,14.223989,0.549128,-146.653702,0.055008,0.000000
50.190002,62.741409,-146.653702,0.002078,0.002162,0.054913,279.087738,14.217406,0.549128,-146.653702,0.055008,0.000000
50.350002,62.714600,-146.653702,0.002065,0.002162,0.054913,278.968475,14.211331,0.549128,-146.653702,0.055008,0.000000
50.510002,62.720184,-146.698181,0.002074,0.002162,0.054913,278.993317,14.212597,0.549128,-146.698181,0.055008,0.000000
50.670002,62.700081,-146.698181,0.002095,0.002162,0.054913,278.903900,14.208041,0.549128,-146.698181,0.055008,0.000000
50.830002,62.676247,-146.698181,0.002074,0.002162,0.054913,278.797882,14.202641,0.549128,-146.698181,0.055008,0.000000
50.990002,62.681458,-146.698181,0.002087,0.002162,0.054913,278.821045,14.203821,0.549128,-146.698181,0.055008,0.000000
51.150002,62.663589,-146.787140,0.002078,0.002162,0.054913,278.741577,14.199773,0.549128,-146.787140,0.055008,0.000000
51.310001,62.646454,-146.831619,0.002078,0.002162,0.054913,278.665344,14.195889,0.549128,-146.831619,0.055008,0.000000
51.470001,62.644592,-146.876099,0.002087,0.002162,0.054913,278.657074,14.195468,0.549128,-146.876099,0.055008,0.000000
51.630001,62.639381,-146.876099,0.002091,0.002162,0.054913,278.633881,14.194286,0.549128,-146.876099,0.055008,0.000000
51.790001,62.608101,-146.831619,0.002087,0.002162,0.054913,278.494751,14.187199,0.549128,-146.831619,0.055008,0.000000
51.950001,62.607361,-146.920578,0.002082,0.002162,0.054913,278.491455,14.187031,0.549128,-146.920578,0.055008,0.000000
52.110001,62.587997,-146.876099,0.002087,0.002162,0.054913,278.405304,14.182643,0.549128,-146.876099,0.055008,0.000000
52.270004,62.585388,-146.920578,0.002091,0.002162,0.054913,278.393707,14.182052,0.549128,-146.920578,0.055008,0.000000
52.430004,62.567886,-146.965057,0.002078,0.002162,0.054913,278.315857,14.178085,0.549128,-146.965057,0.055008,0.000000
52.590004,62.559319,-146.965057,0.002082,0.002162,0.054913,278.277740,14.176145,0.549128,-146.965057,0.055008,0.000000
52.750004,62.545174,-147.054031,0.002070,0.002162,0.054913,278.214813,14.172938,0.549128,-147.054031,0.055008,0.000000
52.910004,62.534744,-147.009537,0.002087,0.002162,0.054913,278.168427,14.170576,0.549128,-147.009537,0.055008,0.000000
53.070004,62.537354,-147.054031,0.002087,0.002162,0.054913,278.180054,14.171166,0.549128,-147.054031,0.055008,0.000000
53.230003,62.512772,-147.142990,0.002078,0.002162,0.054913,278.070709,14.165596,0.549128,-147.142990,0.055008,0.000000
53.390003,62.503090,-147.098511,0.002095,0.002162,0.054913,278.027618,14.163403,0.549128,-147.098511,0.055008,0.000000
53.550003,62.505325,-147.142990,0.002087,0.002162,0.054913,278.037567,14.163910,0.549128,-147.142990,0.055008,0.000000
53.710003,62.477776,-147.142990,0.002087,0.002162,0.054913,277.915039,14.157666,0.549128,-147.142990,0.055008,0.000000
53.870003,62.477028,-147.187469,0.002091,0.002162,0.054913,277.911713,14.157497,0.549128,-147.187469,0.055008,0.000000
54.030003,62.469208,-147.231949,0.002078,0.002162,0.054913,277.876923,14.155725,0.549128,-147.231949,0.055008,0.000000
54.190002,62.449097,-147.231949,0.002078,0.002162,0.054913,277.787445,14.151168,0.549128,-147.231949,0.055008,0.000000
54.350002,62.435326,-147.276428,0.002087,0.002162,0.054913,277.726196,14.148046,0.549128,-147.276428,0.055008,0.000000
54.510002,62.437927,-147.320908,0.002091,0.002162,0.054913,277.737762,14.148637,0.549128,-147.320908,0.055008,0.000000
54.670002,62.432343,-147.320908,0.002078,0.002162,0.054913,277.712921,14.147371,0.549128,-147.320908,0.055008,0.000000
54.830002,62.420052,-147.365387,0.002087,0.002162,0.054913,277.658264,14.144586,0.549128,-147.365387,0.055008,0.000000
54.990002,62.408142,-147.365387,0.002091,0.002162,0.054913,277.605286,14.141887,0.549128,-147.365387,0.055008,0.000000
55.150002,62.391380,-147.409866,0.002082,0.002162,0.054913,277.530731,14.138088,0.549128,-147.409866,0.055008,0.000000
55.310001,62.389893,-147.365387,0.002078,0.002162,0.054913,277.524109,14.137752,0.549128,-147.365387,0.055008,0.000000
55.470001,62.386169,-147.409866,0.002091,0.002162,0.054913,277.507538,14.136909,0.549128,-147.409866,0.055008,0.000000
55.630001,62.361595,-147.409866,0.002074,0.002162,0.054913,277.398224,14.131340,0.549128,-147.409866,0.055008,0.000000
55.790001,62.363083,-147.409866,0.002074,0.002162,0.054913,277.404846,14.131677,0.549128,-147.409866,0.055008,0.000000
55.950001,62.351913,-147.498840,0.002087,0.002162,0.054913,277.355164,14.129146,0.549128,-147.498840,0.055008,0.000000
56.110004,62.356377,-147.498840,0.002082,0.002162,0.054913,277.375031,14.130157,0.549128,-147.498840,0.055008,0.000000
56.270004,62.351166,-147.498840,0.002082,0.002162,0.054913,277.351837,14.128976,0.549128,-147.498840,0.055008,0.000000
56.430004,62.313553,-147.587799,0.002087,0.002162,0.054913,277.184540,14.120453,0.549128,-147.587799,0.055008,0.000000
56.590004,62.327332,-147.543320,0.002091,0.002162,0.054913,277.245819,14.123575,0.549128,-147.543320,0.055008,0.000000
56.750004,62.310577,-147.632278,0.002091,0.002162,0.054913,277.171295,14.119779,0.549128,-147.632278,0.055008,0.000000
56.910004,62.263283,-147.587799,0.002091,0.002162,0.054913,276.960907,14.109061,0.549128,-147.587799,0.055008,0.000000
57.070004,62.319145,-147.587799,0.002082,0.002162,0.054913,277.209412,14.121720,0.549128,-147.587799,0.055008,0.000000
57.230003,62.293823,-147.632278,0.002087,0.002162,0.054913,277.096771,14.115982,0.549128,-147.632278,0.055008,0.000000
57.390003,62.252861,-147.676758,0.002091,0.002162,0.054913,276.914551,14.106700,0.549128,-147.676758,0.055008,0.000000
57.550003,62.276688,-147.765717,0.002091,0.002162,0.054913,277.020538,14.112099,0.549128,-147.765717,0.055008,0.000000
57.710003,62.257698,-147.765717,0.002091,0.002162,0.054913,276.936066,14.107796,0.549128,-147.765717,0.055008,0.000000
57.870003,62.237961,-147.810196,0.002091,0.002162,0.054913,276.848267,14.103324,0.549128,-147.810196,0.055008,0.000000
58.030003,62.242058,-147.810196,0.002078,0.002162,0.054913,276.866486,14.104252,0.549128,-147.810196,0.055008,0.000000
58.190002,62.232750,-147.765717,0.002074,0.002162,0.054913,276.825104,14.102142,0.549128,-147.765717,0.055008,0.000000
58.350002,62.215248,-147.899155,0.002087,0.002162,0.054913,276.747253,14.098176,0.549128,-147.899155,0.055008,0.000000
58.510002,62.206314,-147.854675,0.002078,0.002162,0.054913,276.707520,14.096152,0.549128,-147.854675,0.055008,0.000000
58.670002,62.192909,-147.854675,0.002095,0.002162,0.054913,276.647888,14.093115,0.549128,-147.854675,0.055008,0.000000
58.830002,62.186577,-147.943649,0.002087,0.002162,0.054913,276.619720,14.091680,0.549128,-147.943649,0.055008,0.000000
58.990002,62.180618,-147.899155,0.002095,0.002162,0.054913,276.593201,14.090330,0.549128,-147.899155,0.055008,0.000000
59.150002,62.165352,-148.032608,0.002091,0.002162,0.054913,276.525299,14.086870,0.549128,-148.032608,0.055008,0.000000
59.310001,62.145988,-147.943649,0.002078,0.002162,0.054913,276.439148,14.082482,0.549128,-147.943649,0.055008,0.000000
59.470001,62.145615,-147.988129,0.002104,0.002162,0.054913,276.437500,14.082398,0.549128,-147.988129,0.055008,0.000000
59.630001,62.116570,-148.077087,0.002087,0.002162,0.054913,276.308289,14.075816,0.549128,-148.077087,0.055008,0.000000
59.790005,62.110237,-148.032608,0.002091,0.002162,0.054913,276.280121,14.074381,0.549128,-148.032608,0.055008,0.000000
59.950005,62.100929,-148.077087,0.002074,0.002162,0.054913,276.238739,14.072272,0.549128,-148.077087,0.055008,0.000000
60.110004,62.078217,-148.032608,0.002078,0.002162,0.054913,276.137695,14.067125,0.549128,-148.032608,0.055008,0.000000
60.270004,62.082687,-148.121567,0.002095,0.002162,0.054913,276.157593,14.068138,0.549128,-148.121567,0.055008,0.000000
60.430004,62.074493,-148.210526,0.002091,0.002162,0.054913,276.121124,14.066281,0.549128,-148.210526,0.055008,0.000000
60.590004,62.040977,-148.166046,0.002091,0.002162,0.054913,275.972046,14.058686,0.549128,-148.166046,0.055008,0.000000
60.750004,62.035393,-148.255005,0.002091,0.002162,0.054913,275.947205,14.057421,0.549128,-148.255005,0.055008,0.000000
60.910004,62.030556,-148.210526,0.002087,0.002162,0.054913,275.925690,14.056325,0.549128,-148.210526,0.055008,0.000000
61.070004,62.016403,-148.210526,0.002095,0.002162,0.054913,275.862732,14.053119,0.549128,-148.210526,0.055008,0.000000
61.230003,62.002251,-148.255005,0.002078,0.002162,0.054913,275.799774,14.049911,0.549128,-148.255005,0.055008,0.000000
61.390003,62.009697,-148.299484,0.002082,0.002162,0.054913,275.832916,14.051599,0.549128,-148.299484,0.055008,0.000000
61.550003,61.978424,-148.343979,0.002095,0.002162,0.054913,275.693787,14.044512,0.549128,-148.343979,0.055008,0.000000
61.710003,61.975441,-148.299484,0.002082,0.002162,0.054913,275.680542,14.043836,0.549128,-148.299484,0.055008,0.000000
61.870003,61.982147,-148.388458,0.002095,0.002162,0.054913,275.710358,14.045355,0.549128,-148.388458,0.055008,0.000000
62.030003,61.943420,-148.432938,0.002078,0.002162,0.054913,275.538086,14.036580,0.549128,-148.432938,0.055008,0.000000
62.190002,61.941185,-148.432938,0.002087,0.002162,0.054913,275.528137,14.036074,0.549128,-148.432938,0.055008,0.000000
62.350002,61.947884,-148.477417,0.002087,0.002162,0.054913,275.557953,14.037592,0.549128,-148.477417,0.055008,0.000000
62.510002,61.918839,-148.477417,0.002087,0.002162,0.054913,275.428741,14.031010,0.549128,-148.477417,0.055008,0.000000
62.670002,61.903572,-148.432938,0.002100,0.002162,0.054913,275.360840,14.027550,0.549128,-148.432938,0.055008,0.000000
62.830002,61.922195,-148.477417,0.002078,0.002162,0.054913,275.443695,14.031771,0.549128,-148.477417,0.055008,0.000000
62.990002,61.897987,-148.521896,0.002091,0.002162,0.054913,275.335999,14.026284,0.549128,-148.521896,0.055008,0.000000
63.150002,61.888680,-148.566376,0.002100,0.002162,0.054913,275.294586,14.024176,0.549128,-148.566376,0.055008,0.000000
63.310001,61.869316,-148.566376,0.002091,0.002162,0.054913,275.208466,14.019788,0.549128,-148.566376,0.055008,0.000000
63.470001,61.864845,-148.566376,0.002082,0.002162,0.054913,275.188568,14.018775,0.549128,-148.566376,0.055008,0.000000
63.630005,61.858887,-148.655334,0.002095,0.002162,0.054913,275.162079,14.017424,0.549128,-148.655334,0.055008,0.000000
63.790005,61.865593,-148.655334,0.002082,0.002162,0.054913,275.191895,14.018944,0.549128,-148.655334,0.055008,0.000000
63.950005,61.842133,-148.655334,0.002100,0.002162,0.054913,275.087555,14.013627,0.549128,-148.655334,0.055008,0.000000
64.110001,61.845482,-148.610855,0.002082,0.002162,0.054913,275.102448,14.014386,0.549128,-148.610855,0.055008,0.000000
64.270004,61.843994,-148.744293,0.002082,0.002162,0.054913,275.095825,14.014050,0.549128,-148.744293,0.055008,0.000000
64.430000,61.817184,-148.744293,0.002091,0.002162,0.054913,274.976562,14.007974,0.549128,-148.744293,0.055008,0.000000
64.590004,61.825005,-148.744293,0.002087,0.002162,0.054913,275.011353,14.009747,0.549128,-148.744293,0.055008,0.000000
64.750000,61.819046,-148.833267,0.002091,0.002162,0.054913,274.984863,14.008396,0.549128,-148.833267,0.055008,0.000000
64.910004,61.805641,-148.877747,0.002082,0.002162,0.054913,274.925232,14.005359,0.549128,-148.877747,0.055008,0.000000
65.070000,61.791862,-148.788788,0.002095,0.002162,0.054913,274.863922,14.002236,0.549128,-148.788788,0.055008,0.000000
65.230003,61.801918,-148.877747,0.002100,0.002162,0.054913,274.908661,14.004515,0.549128,-148.877747,0.055008,0.000000
65.389999,61.772125,-148.877747,0.002091,0.002162,0.054913,274.776123,13.997764,0.549128,-148.877747,0.055008,0.000000
65.550003,61.778831,-148.966705,0.002091,0.002162,0.054913,274.805969,13.999283,0.549128,-148.966705,0.055008,0.000000
65.710007,61.776596,-148.966705,0.002087,0.002162,0.054913,274.796021,13.998776,0.549128,-148.966705,0.055008,0.000000
65.870003,61.769150,-148.966705,0.002095,0.002162,0.054913,274.762909,13.997089,0.549128,-148.966705,0.055008,0.000000
66.030006,61.756485,-149.055664,0.002091,0.002162,0.054913,274.706573,13.994220,0.549128,-149.055664,0.055008,0.000000
66.100006,61.747925,-149.011185,0.002091,0.002162,0.054913,274.668488,13.992280,0.549128,-149.011185,0.055008,0.000000