File: Data/compression 37/Heating-17-37-reverse-1-1_11202024_172847_11212024_105627(in).csv
Time (sec),S:Load (lbs),S:HL1 (DIM),S:LVDT (in),S:Position (in),Ch:Position (mm),Ch:Load (N),Ch:Stress (MPa),Ch:Strain (mm/mm),Ch:HL1 (DIM),Set Point (),Cycles ()
0.11,0.466583,-1288.568726,-0.006916,-0.007543,-0.191597,2.075466,0.105729,-1.915974,-1288.568726,-0.191389,0
0.51,0.466957,-1288.568726,-0.006907,0,0,2.077129,0.105814,0,-1288.568726,0,0
0.91,0.472542,-1288.657593,-0.006911,0,0,2.101971,0.10708,0,-1288.657593,0,0
1.31,0.519089,-1288.613159,-0.00692,0.000006,0.000157,2.309022,0.117627,0.001575,-1288.613159,0.000556,0
1.71,0.47403,-1288.613159,-0.006907,0.000031,0.00079,2.108589,0.107417,0.007903,-1288.613159,0.001223,0
2.11,0.48111,-1288.657593,-0.006916,0.000051,0.001302,2.140082,0.109021,0.01302,-1288.657593,0.001891,0
2.51,0.487068,-1288.568726,-0.006924,0.000078,0.001986,2.166587,0.110371,0.019863,-1288.568726,0.002559,0
2.91,0.46994,-1288.702148,-0.006924,0.000095,0.002421,2.090398,0.10649,0.024208,-1288.702148,0.003219,0
3.31,0.517975,-1288.568726,-0.006903,0.000115,0.002933,2.304067,0.117375,0.029325,-1288.568726,0.003886,0
3.71,0.499725,-1288.702148,-0.006911,0.000134,0.003391,2.222889,0.113239,0.033913,-1288.702148,0.004554,0
4.11,0.449455,-1288.613159,-0.006911,0.000165,0.00418,1.999277,0.101848,0.0418,-1288.613159,0.005222,0
4.51,0.464722,-1288.613159,-0.006911,0.000186,0.004736,2.067185,0.105307,0.047357,-1288.613159,0.005889,0
4.91,0.495255,-1288.657593,-0.006873,0.000214,0.005429,2.203002,0.112226,0.054291,-1288.657593,0.006557,0
5.31,0.503075,-1288.613159,-0.006847,0.000239,0.006071,2.237788,0.113998,0.06071,-1288.613159,0.007225,0
5.71,0.498985,-1288.657593,-0.006834,0.000266,0.006748,2.219597,0.113072,0.067477,-1288.657593,0.007892,0
6.11,0.47776,-1288.613159,-0.006821,0.000285,0.00725,2.125184,0.108262,0.072503,-1288.613159,0.008551,0
6.51,0.480736,-1288.657593,-0.006782,0.000309,0.007841,2.13842,0.108936,0.078408,-1288.657593,0.00922,0
6.91,0.484833,-1288.657593,-0.006743,0.000344,0.008725,2.156644,0.109865,0.087249,-1288.657593,0.009888,0
7.31,0.479622,-1288.702148,-0.006722,0.000368,0.009358,2.133465,0.108684,0.093578,-1288.702148,0.010555,0
7.710001,0.481483,-1288.702148,-0.006691,0.000393,0.009983,2.141745,0.109106,0.09983,-1288.702148,0.011223,0
8.110001,0.452805,-1288.702148,-0.00667,0.000421,0.010693,2.014175,0.102607,0.106931,-1288.702148,0.011891,0
8.51,0.441261,-1288.746582,-0.006648,0.000444,0.011284,1.962828,0.099991,0.112835,-1288.746582,0.012558,0
8.910001,0.468079,-1288.702148,-0.006601,0.000474,0.012037,2.082118,0.106068,0.120375,-1288.702148,0.013226,0
9.31,0.460625,-1288.702148,-0.006571,0.000503,0.012784,2.048961,0.104379,0.127839,-1288.702148,0.013885,0
9.71,0.474403,-1288.702148,-0.006562,0.000526,0.013356,2.110252,0.107501,0.133561,-1288.702148,0.014552,0
10.110001,0.449829,-1288.702148,-0.006528,0.000551,0.014007,2.00094,0.101933,0.140071,-1288.702148,0.01522,0
10.51,0.463982,-1288.791016,-0.006502,0.000578,0.014682,2.063893,0.10514,0.146824,-1288.791016,0.015889,0
10.910001,0.483711,-1288.702148,-0.006497,0.000608,0.015454,2.151655,0.109611,0.154545,-1288.702148,0.016557,0
11.31,0.479622,-1288.746582,-0.006459,0.000634,0.016113,2.133465,0.108684,0.161131,-1288.746582,0.017224,0
11.710001,0.444618,-1288.702148,-0.006424,0.000657,0.016694,1.977761,0.100752,0.166944,-1288.702148,0.017892,0
12.110001,0.415199,-1288.746582,-0.006407,0.000676,0.01718,1.846899,0.094085,0.171804,-1288.746582,0.01856,0
12.51,0.444244,-1288.746582,-0.006368,0.000703,0.017857,1.976098,0.100667,0.178571,-1288.746582,0.019218,0
12.910001,0.461372,-1288.702148,-0.006342,0.00074,0.018793,2.052287,0.104548,0.187928,-1288.702148,0.019886,0
13.31,0.452805,-1288.791016,-0.006321,0.000761,0.019339,2.014175,0.102607,0.193393,-1288.791016,0.020553,0
13.710001,0.439774,-1288.791016,-0.006303,0.000781,0.019843,1.95621,0.099654,0.198434,-1288.791016,0.021221,0
14.110001,0.397697,-1288.791016,-0.00626,0.000814,0.020684,1.769047,0.09012,0.206837,-1288.791016,0.021889,0
14.51,0.42041,-1288.746582,-0.006243,0.00084,0.021344,1.870078,0.095266,0.213438,-1288.746582,0.022558,0
14.910001,0.475151,-1288.791016,-0.006204,0.000871,0.022133,2.113577,0.107671,0.221326,-1288.791016,0.023226,0
15.31,0.438286,-1288.791016,-0.006183,0.000892,0.022653,1.949593,0.099317,0.226534,-1288.791016,0.023893,0
15.710001,0.396576,-1288.835571,-0.006144,0.000919,0.023347,1.764058,0.089865,0.233467,-1288.835571,0.024561,0
16.110001,0.367531,-1288.835571,-0.006122,0.000943,0.023954,1.634859,0.083284,0.239538,-1288.835571,0.02522,0
16.51,0.417435,-1288.880005,-0.006122,0.000964,0.024473,1.856842,0.094592,0.244731,-1288.880005,0.025887,0
16.910002,0.480362,-1288.791016,-0.006096,0.000998,0.025359,2.136757,0.108852,0.253588,-1288.791016,0.026555,0
17.310001,0.438286,-1288.791016,-0.00604,0.001028,0.026104,1.949593,0.099317,0.261037,-1288.791016,0.027222,0
17.710001,0.409988,-1288.835571,-0.006023,0.001055,0.026799,1.82372,0.092905,0.267986,-1288.835571,0.02789,0
18.110001,0.402908,-1288.924561,-0.005997,0.001072,0.027232,1.792226,0.0913,0.272316,-1288.924561,0.028558,0
18.51,0.46286,-1288.791016,-0.00598,0.001098,0.027899,2.058905,0.104886,0.278992,-1288.791016,0.029227,0
18.910002,0.48632,-1288.835571,-0.005941,0.001134,0.028811,2.163262,0.110202,0.288106,-1288.835571,0.029895,0
19.310001,0.478874,-1288.791016,-0.005915,0.001151,0.029244,2.130139,0.108514,0.292436,-1288.791016,0.030553,0
19.710001,0.457275,-1288.880005,-0.00589,0.001177,0.029886,2.034063,0.10362,0.298855,-1288.880005,0.031221,0
20.110001,0.460258,-1288.924561,-0.005868,0.001205,0.030605,2.047332,0.104296,0.306047,-1288.924561,0.031888,0
20.51,0.477013,-1288.880005,-0.005812,0.001234,0.031351,2.121858,0.108093,0.31351,-1288.880005,0.032556,0
20.910002,0.494888,-1288.924561,-0.005808,0.001264,0.032114,2.201373,0.112143,0.321141,-1288.924561,0.033224,0
21.310001,0.511269,-1288.924561,-0.005782,0.001287,0.032686,2.274236,0.115855,0.326864,-1288.924561,0.033891,0
21.710001,0.439034,-1288.880005,-0.005756,0.001312,0.033328,1.952919,0.099486,0.333283,-1288.880005,0.034559,0
22.110001,0.46286,-1288.924561,-0.005721,0.001333,0.033857,2.058905,0.104886,0.338566,-1288.924561,0.035227,0
22.51,0.513504,-1288.968994,-0.005687,0.001367,0.034724,2.28418,0.116362,0.347241,-1288.968994,0.035887,0
22.910002,0.494888,-1288.924561,-0.00567,0.001386,0.035201,2.201373,0.112143,0.35201,-1288.924561,0.036555,0
23.310001,0.503448,-1288.924561,-0.005635,0.001419,0.036034,2.239451,0.114083,0.360337,-1288.924561,0.037222,0
23.710001,0.446106,-1288.968994,-0.005618,0.001441,0.036606,1.984378,0.101089,0.36606,-1288.968994,0.03789,0
24.110001,0.463608,-1288.968994,-0.005583,0.001468,0.037283,2.06223,0.105055,0.372827,-1288.968994,0.038557,0
24.51,0.509781,-1288.924561,-0.005545,0.001494,0.037959,2.267619,0.115518,0.379595,-1288.924561,0.039225,0
24.910002,0.507545,-1288.968994,-0.005536,0.001525,0.038739,2.257675,0.115011,0.387392,-1288.968994,0.039893,0
25.310001,0.524673,-1288.968994,-0.005501,0.001549,0.039346,2.333864,0.118893,0.393463,-1288.968994,0.04056,0
25.710001,0.475891,-1288.924561,-0.005484,0.001576,0.040023,2.116869,0.107838,0.40023,-1288.924561,0.041221,0
26.110001,0.464722,-1289.013428,-0.005437,0.001599,0.040621,2.067185,0.105307,0.40621,-1289.013428,0.041888,0
26.510002,0.488556,-1289.013428,-0.005411,0.001632,0.041446,2.173205,0.110708,0.414461,-1289.013428,0.042556,0
26.910002,0.503075,-1288.924561,-0.005415,0.001652,0.041965,2.237788,0.113998,0.419654,-1288.924561,0.043224,0
27.310001,0.510529,-1288.924561,-0.005359,0.001675,0.042547,2.270944,0.115687,0.425468,-1288.924561,0.043891,0
27.710001,0.478127,-1288.968994,-0.005329,0.001699,0.043163,2.126813,0.108345,0.431629,-1288.968994,0.044559,0
28.110001,0.483711,-1289.013428,-0.005325,0.001723,0.043761,2.151655,0.109611,0.43761,-1289.013428,0.045226,0
28.510002,0.502708,-1288.968994,-0.005273,0.001762,0.044759,2.236159,0.113915,0.447587,-1288.968994,0.045894,0
28.910002,0.506805,-1288.968994,-0.00526,0.001784,0.045322,2.254383,0.114844,0.453218,-1288.968994,0.046562,0
29.310001,0.437912,-1289.013428,-0.005234,0.001815,0.046094,1.94793,0.099232,0.46094,-1289.013428,0.047222,0
29.710001,0.465469,-1288.880005,-0.005204,0.001837,0.046666,2.070511,0.105477,0.466662,-1288.880005,0.04789,0
30.110001,0.472542,-1288.924561,-0.005195,0.001858,0.047187,2.101971,0.10708,0.47187,-1288.924561,0.048557,0
30.510002,0.488182,-1288.880005,-0.005152,0.001893,0.048071,2.171542,0.110624,0.480712,-1288.880005,0.049225,0
30.910002,0.46212,-1288.924561,-0.005131,0.001914,0.048625,2.055613,0.104718,0.486253,-1288.924561,0.049892,0
31.310001,0.452065,-1289.013428,-0.005088,0.001945,0.049416,2.010883,0.102439,0.494156,-1289.013428,0.05056,0
31.710001,0.447594,-1288.968994,-0.005083,0.001965,0.049909,1.990996,0.101426,0.499091,-1288.968994,0.051228,0
32.110001,0.4785,-1288.968994,-0.005062,0.001985,0.05043,2.128476,0.10843,0.504299,-1288.968994,0.051895,0
32.510002,0.470306,-1288.968994,-0.005023,0.002024,0.051409,2.092027,0.106573,0.514095,-1288.968994,0.052554,0
32.91,0.453926,-1289.013428,-0.004988,0.002047,0.051991,2.019164,0.102861,0.519908,-1289.013428,0.053222,0
33.310001,0.411102,-1288.968994,-0.004958,0.002071,0.052607,1.828674,0.093157,0.52607,-1288.968994,0.053891,0
33.710003,0.425255,-1288.924561,-0.004928,0.002099,0.053309,1.891628,0.096364,0.533095,-1288.924561,0.054559,0
34.110001,0.463982,-1289.013428,-0.004915,0.002129,0.054073,2.063893,0.10514,0.540725,-1289.013428,0.055226,0
34.510002,0.434189,-1288.968994,-0.004868,0.002155,0.05474,1.931368,0.098389,0.547402,-1288.968994,0.055894,0
34.91,0.460625,-1288.924561,-0.004842,0.002176,0.055269,2.048961,0.104379,0.552685,-1288.924561,0.056561,0
35.310001,0.399559,-1289.057983,-0.004842,0.002203,0.055963,1.777327,0.090541,0.559635,-1289.057983,0.057229,0
35.710003,0.406631,-1288.968994,-0.004799,0.002225,0.056508,1.808787,0.092144,0.565085,-1288.968994,0.057888,0
36.110001,0.476265,-1288.968994,-0.004756,0.002265,0.057541,2.118532,0.107923,0.57541,-1288.968994,0.058555,0
36.510002,0.437912,-1288.924561,-0.004738,0.002288,0.058113,1.94793,0.099232,0.581133,-1288.924561,0.059223,0
36.91,0.439034,-1289.102417,-0.004708,0.002309,0.05866,1.952919,0.099486,0.586598,-1289.102417,0.059891,0
37.310001,0.364182,-1288.924561,-0.004691,0.002333,0.059267,1.61996,0.082525,0.592669,-1288.924561,0.060558,0
37.710003,0.3936,-1288.968994,-0.004669,0.002355,0.059804,1.750822,0.089191,0.598044,-1288.968994,0.061227,0
38.110001,0.490417,-1289.013428,-0.004635,0.002392,0.060758,2.181486,0.11113,0.607582,-1289.013428,0.061895,0
38.510002,0.452065,-1289.057983,-0.004605,0.002417,0.061391,2.010883,0.102439,0.61391,-1289.057983,0.062563,0
38.910004,0.445358,-1289.013428,-0.004587,0.002445,0.062112,1.981053,0.10092,0.621116,-1289.013428,0.063221,0
39.310001,0.407379,-1289.057983,-0.00457,0.002463,0.062563,1.812113,0.092313,0.625628,-1289.057983,0.063889,0
39.710003,0.427116,-1289.013428,-0.004527,0.00249,0.063256,1.899909,0.096786,0.632562,-1289.013428,0.064557,0
40.110001,0.503075,-1289.102417,-0.004501,0.002525,0.064133,2.237788,0.113998,0.641328,-1289.102417,0.065224,0
40.510002,0.484833,-1289.057983,-0.004493,0.002546,0.064661,2.156644,0.109865,0.646611,-1289.057983,0.065892,0
40.910004,0.493393,-1289.057983,-0.004458,0.00257,0.065268,2.194721,0.111804,0.652682,-1289.057983,0.06656,0
41.310001,0.472542,-1289.057983,-0.004415,0.002596,0.065927,2.101971,0.10708,0.659268,-1289.057983,0.067227,0
41.710003,0.484085,-1289.102417,-0.004406,0.002626,0.066699,2.153318,0.109695,0.666989,-1289.102417,0.067896,0
42.110001,0.502708,-1289.102417,-0.004372,0.002655,0.067427,2.236159,0.113915,0.674271,-1289.102417,0.068564,0
42.510002,0.501587,-1289.057983,-0.004337,0.002681,0.068104,2.23117,0.113661,0.681039,-1289.057983,0.069223,0
42.910004,0.453552,-1289.102417,-0.004329,0.002702,0.068641,2.017501,0.102776,0.686413,-1289.102417,0.06989,0
43.310001,0.458397,-1289.102417,-0.004299,0.002726,0.069248,2.039051,0.103874,0.692484,-1289.102417,0.070558,0
43.710003,0.458023,-1289.146973,-0.004286,0.002746,0.069743,2.037388,0.10379,0.697435,-1289.146973,0.071226,0
44.110001,0.515366,-1289.102417,-0.004234,0.002784,0.070705,2.292461,0.116784,0.707049,-1289.102417,0.071893,0
44.510002,0.523186,-1289.102417,-0.004212,0.002809,0.071356,2.327246,0.118556,0.713559,-1289.102417,0.072561,0
44.910004,0.475891,-1289.102417,-0.004178,0.002837,0.072067,2.116869,0.107838,0.720674,-1289.102417,0.073229,0
45.310001,0.46212,-1289.146973,-0.004156,0.00286,0.07264,2.055613,0.104718,0.726397,-1289.146973,0.073896,0
45.710003,0.496002,-1289.146973,-0.004135,0.002891,0.073438,2.206328,0.112396,0.734376,-1289.146973,0.074556,0
46.110001,0.535477,-1289.191406,-0.004109,0.002916,0.07407,2.381919,0.121341,0.740704,-1289.191406,0.075224,0
46.510002,0.533981,-1289.146973,-0.004092,0.002934,0.074522,2.375268,0.121002,0.745216,-1289.146973,0.075892,0
46.910004,0.479248,-1289.191406,-0.004057,0.002968,0.075389,2.131802,0.108599,0.753891,-1289.191406,0.076559,0
47.310001,0.488182,-1289.191406,-0.004036,0.002993,0.076013,2.171542,0.110624,0.760128,-1289.191406,0.077227,0
47.710003,0.515366,-1289.191406,-0.004005,0.003019,0.07668,2.292461,0.116784,0.766805,-1289.191406,0.077895,0
48.110001,0.512016,-1289.191406,-0.003962,0.003046,0.077357,2.277562,0.116025,0.773572,-1289.191406,0.078562,0
48.510002,0.501213,-1289.191406,-0.003958,0.003063,0.077799,2.229507,0.113577,0.777993,-1289.191406,0.07923,0
48.910004,0.479622,-1289.146973,-0.003928,0.003092,0.078537,2.133465,0.108684,0.785366,-1289.146973,0.07989,0
49.310001,0.491531,-1289.23584,-0.003906,0.003112,0.079057,2.186441,0.111383,0.790574,-1289.23584,0.080558,0
49.710003,0.511642,-1289.191406,-0.00388,0.003154,0.080123,2.275899,0.11594,0.801232,-1289.191406,0.081225,0
50.110001,0.490791,-1289.23584,-0.003859,0.003175,0.080653,2.183149,0.111215,0.806531,-1289.23584,0.081893,0
50.510002,0.48632,-1289.23584,-0.003816,0.003206,0.081425,2.163262,0.110202,0.814252,-1289.23584,0.082561,0
50.910004,0.451317,-1289.23584,-0.00379,0.003228,0.081997,2.007558,0.10227,0.819975,-1289.23584,0.083228,0
51.310001,0.46286,-1289.191406,-0.00376,0.003249,0.082517,2.058905,0.104886,0.825168,-1289.191406,0.083896,0
51.710003,0.495255,-1289.324829,-0.003721,0.003287,0.083489,2.203002,0.112226,0.834887,-1289.324829,0.084564,0
52.110001,0.480362,-1289.23584,-0.003704,0.003309,0.084043,2.136757,0.108852,0.840428,-1289.23584,0.085224,0
52.510002,0.478127,-1289.280396,-0.003678,0.003334,0.084685,2.126813,0.108345,0.846848,-1289.280396,0.085891,0
52.910004,0.436798,-1289.191406,-0.003656,0.003357,0.085266,1.942975,0.09898,0.852661,-1289.191406,0.086559,0
53.310001,0.474777,-1289.280396,-0.003643,0.003382,0.085908,2.111915,0.107586,0.85908,-1289.280396,0.087227,0
53.710003,0.49675,-1289.324829,-0.003609,0.003416,0.086776,2.209654,0.112565,0.867755,-1289.324829,0.087894,0
54.110004,0.472168,-1289.280396,-0.00357,0.003444,0.087487,2.100308,0.106995,0.874871,-1289.280396,0.088562,0
54.510002,0.423393,-1289.23584,-0.003544,0.003464,0.087981,1.883347,0.095942,0.879806,-1289.23584,0.08923,0
54.910004,0.433075,-1289.324829,-0.003527,0.003486,0.088553,1.926414,0.098136,0.885529,-1289.324829,0.089897,0
55.310001,0.465096,-1289.324829,-0.003492,0.003511,0.089186,2.068848,0.105392,0.891858,-1289.324829,0.090565,0
55.710003,0.452065,-1289.369385,-0.003462,0.003545,0.090053,2.010883,0.102439,0.900532,-1289.369385,0.091224,0
56.110004,0.468079,-1289.23584,-0.003445,0.003573,0.090747,2.082118,0.106068,0.907466,-1289.23584,0.091891,0
56.510002,0.403656,-1289.369385,-0.003419,0.003596,0.091337,1.795552,0.09147,0.913371,-1289.369385,0.09256,0
56.910004,0.412216,-1289.324829,-0.003406,0.003616,0.09184,1.833629,0.09341,0.918397,-1289.324829,0.093228,0
57.310001,0.472916,-1289.280396,-0.003354,0.003656,0.092854,2.103634,0.107164,0.928541,-1289.280396,0.093896,0
57.710003,0.443497,-1289.369385,-0.003324,0.003677,0.093384,1.972772,0.100498,0.93384,-1289.369385,0.094563,0
58.110004,0.434189,-1289.324829,-0.003303,0.003699,0.093947,1.931368,0.098389,0.939471,-1289.324829,0.095231,0
58.510002,0.382805,-1289.324829,-0.003281,0.003724,0.094589,1.702801,0.086745,0.945891,-1289.324829,0.095899,0
58.910004,0.401794,-1289.369385,-0.003268,0.003746,0.095152,1.787271,0.091048,0.951523,-1289.369385,0.096557,0
59.310001,0.455788,-1289.324829,-0.003229,0.003782,0.096055,2.027445,0.103283,0.960546,-1289.324829,0.097225,0
59.710003,0.472542,-1289.280396,-0.003199,0.00381,0.096774,2.101971,0.10708,0.967737,-1289.280396,0.097893,0
60.110004,0.450203,-1289.369385,-0.00316,0.003828,0.097234,2.002603,0.102017,0.97234,-1289.369385,0.09856,0
60.510002,0.435677,-1289.413818,-0.003134,0.003862,0.098083,1.937986,0.098726,0.980833,-1289.413818,0.099229,0
60.910004,0.433815,-1289.413818,-0.003122,0.003884,0.098648,1.929706,0.098304,0.98648,-1289.413818,0.099897,0
61.310001,0.5243,-1289.458252,-0.003096,0.003916,0.099462,2.332201,0.118808,0.994625,-1289.458252,0.100565,0
61.710003,0.496002,-1289.413818,-0.003065,0.00394,0.100088,2.206328,0.112396,1.000878,-1289.413818,0.101232,0
62.110004,0.491905,-1289.369385,-0.003035,0.003955,0.10046,2.188104,0.111467,1.004602,-1289.369385,0.101891,0
62.510002,0.468819,-1289.369385,-0.003005,0.003985,0.101207,2.08541,0.106236,1.012066,-1289.369385,0.102559,0
62.910004,0.49749,-1289.458252,-0.002975,0.00402,0.102116,2.212946,0.112733,1.021165,-1289.458252,0.103226,0
63.310001,0.512756,-1289.413818,-0.002949,0.004047,0.102793,2.280854,0.116192,1.027932,-1289.413818,0.103894,0
63.710003,0.511642,-1289.458252,-0.002919,0.00407,0.103375,2.275899,0.11594,1.033746,-1289.458252,0.104562,0
64.110001,0.503448,-1289.458252,-0.002893,0.004094,0.103982,2.239451,0.114083,1.039817,-1289.458252,0.105229,0
64.510002,0.468445,-1289.413818,-0.002871,0.004118,0.104589,2.083747,0.106151,1.045888,-1289.413818,0.105898,0
64.910004,0.480736,-1289.502808,-0.00285,0.004141,0.105178,2.13842,0.108936,1.051777,-1289.502808,0.106566,0
65.310005,0.534729,-1289.458252,-0.00282,0.004178,0.106122,2.378593,0.121171,1.061224,-1289.458252,0.107225,0
65.710007,0.522812,-1289.458252,-0.002781,0.0042,0.106669,2.325583,0.118471,1.066689,-1289.458252,0.107892,0
66.110001,0.479988,-1289.458252,-0.002768,0.004226,0.107337,2.135094,0.108767,1.073366,-1289.458252,0.10856,0
66.510002,0.472542,-1289.458252,-0.002738,0.004249,0.107927,2.101971,0.10708,1.07927,-1289.458252,0.109228,0
66.910004,0.517227,-1289.502808,-0.002729,0.004276,0.10862,2.300741,0.117205,1.086204,-1289.502808,0.109895,0
67.310005,0.534729,-1289.502808,-0.002673,0.004309,0.109453,2.378593,0.121171,1.094531,-1289.502808,0.110563,0
67.710007,0.527283,-1289.502808,-0.002652,0.004324,0.109818,2.345471,0.119484,1.09818,-1289.502808,0.11123,0
68.110001,0.48967,-1289.502808,-0.002621,0.004362,0.110798,2.17816,0.110961,1.107975,-1289.502808,0.111898,0
68.510002,0.492279,-1289.502808,-0.002591,0.004385,0.11137,2.189767,0.111552,1.113698,-1289.502808,0.112567,0
68.910004,0.507919,-1289.502808,-0.002583,0.004414,0.112107,2.259338,0.115096,1.121071,-1289.502808,0.113226,0
69.310005,0.538452,-1289.502808,-0.002548,0.004438,0.112723,2.395155,0.122015,1.127233,-1289.502808,0.113894,0
69.710007,0.529892,-1289.502808,-0.002518,0.004462,0.11333,2.357077,0.120075,1.133304,-1289.502808,0.114561,0
70.110001,0.510155,-1289.547241,-0.002496,0.004486,0.113954,2.269282,0.115603,1.139541,-1289.547241,0.115229,0
70.510002,0.529518,-1289.502808,-0.002492,0.004505,0.114414,2.355414,0.119991,1.144143,-1289.502808,0.115897,0
70.910004,0.573456,-1289.547241,-0.002432,0.004543,0.115394,2.550859,0.129947,1.153939,-1289.547241,0.116564,0
71.310005,0.615166,-1289.591675,-0.002402,0.004565,0.115957,2.736394,0.139399,1.159571,-1289.591675,0.117232,0
71.710007,0.729111,-1289.502808,-0.00238,0.004596,0.116729,3.243247,0.165219,1.167292,-1289.502808,0.117899,0
72.110001,0.834862,-1289.547241,-0.002354,0.00462,0.117336,3.71365,0.189182,1.173363,-1289.547241,0.11856,0
72.510002,1.02961,-1289.547241,-0.002333,0.004645,0.117995,4.579933,0.233313,1.179949,-1289.547241,0.119227,0
72.910004,1.362885,-1289.547241,-0.002307,0.004673,0.11869,6.062413,0.308834,1.186898,-1289.547241,0.119895,0
73.310005,1.74382,-1289.502808,-0.002272,0.0047,0.119392,7.7569,0.395155,1.193922,-1289.502808,0.120563,0
73.710007,2.250626,-1289.502808,-0.002276,0.004727,0.120067,10.011283,0.509999,1.200675,-1289.502808,0.12123,0
74.110001,2.53437,-1289.591675,-0.002242,0.004747,0.120579,11.273442,0.574297,1.205792,-1289.591675,0.121898,0
74.510002,3.112289,-1289.591675,-0.002238,0.004775,0.121291,13.844154,0.705255,1.212907,-1289.591675,0.122565,0
74.910004,3.900978,-1289.547241,-0.00219,0.004809,0.12214,17.352417,0.883974,1.221401,-1289.547241,0.123233,0
75.310005,4.271858,-1289.547241,-0.002173,0.00483,0.122687,19.002174,0.968017,1.226866,-1289.547241,0.123893,0
75.710007,4.923882,-1289.547241,-0.002151,0.004862,0.123494,21.902519,1.115767,1.234936,-1289.547241,0.124561,0
76.110001,5.229233,-1289.547241,-0.00213,0.00488,0.123954,23.26079,1.184961,1.239538,-1289.547241,0.125229,0
76.510002,5.711823,-1289.591675,-0.002104,0.0049,0.124466,25.407455,1.294317,1.244655,-1289.591675,0.125896,0
76.910004,6.644615,-1289.591675,-0.002074,0.004939,0.125445,29.556725,1.505691,1.25445,-1289.591675,0.126564,0
77.310005,7.007309,-1289.591675,-0.002057,0.004962,0.126034,31.170067,1.587879,1.26034,-1289.591675,0.127232,0
77.710007,7.585228,-1289.547241,-0.002018,0.004988,0.126685,33.74078,1.718837,1.26685,-1289.547241,0.127899,0
78.110001,7.863762,-1289.502808,-0.002013,0.00501,0.127248,34.979759,1.781954,1.272482,-1289.502808,0.128567,0
78.510002,8.570152,-1289.63623,-0.001996,0.005037,0.127943,38.121941,1.942024,1.279431,-1289.63623,0.129225,0
78.910004,8.931732,-1289.591675,-0.001957,0.005069,0.128758,39.730328,2.023959,1.287576,-1289.591675,0.129893,0
79.310005,9.083656,-1289.591675,-0.001932,0.005089,0.129269,40.40612,2.058386,1.292693,-1289.591675,0.130562,0
79.710007,9.508904,-1289.63623,-0.001906,0.005115,0.129911,42.297714,2.154748,1.299112,-1289.63623,0.13123,0
80.110001,9.920006,-1289.591675,-0.001884,0.005139,0.130527,44.126389,2.247905,1.305274,-1289.591675,0.131898,0
80.510002,10.192207,-1289.591675,-0.001893,0.005163,0.131134,45.337204,2.309587,1.311345,-1289.591675,0.132565,0
80.910004,10.899345,-1289.591675,-0.001828,0.005197,0.131993,48.482708,2.469827,1.319929,-1289.591675,0.133233,0
81.310005,11.302994,-1289.591675,-0.001819,0.005226,0.132747,50.278229,2.561295,1.327469,-1289.591675,0.1339,0
81.710007,11.61393,-1289.63623,-0.001768,0.005253,0.133415,51.661339,2.631754,1.334145,-1289.63623,0.134568,0
82.110001,11.59568,-1289.63623,-0.00175,0.005269,0.133822,51.580162,2.627619,1.338218,-1289.63623,0.135227,0
82.510002,12.614868,-1289.63623,-0.001725,0.005305,0.134759,56.113735,2.85857,1.347589,-1289.63623,0.135894,0
82.910004,12.872177,-1289.591675,-0.001694,0.005334,0.135487,57.258305,2.916877,1.354871,-1289.591675,0.136562,0
83.310005,12.644653,-1289.680664,-0.001673,0.005348,0.135834,56.246227,2.865319,1.358338,-1289.680664,0.137231,0
83.710007,13.525688,-1289.63623,-0.001647,0.005381,0.136676,60.165264,3.064965,1.366756,-1289.63623,0.137899,0
84.110001,13.995247,-1289.591675,-0.001625,0.005407,0.137343,62.253967,3.171368,1.373432,-1289.591675,0.138567,0
84.510002,14.211227,-1289.63623,-0.001604,0.005437,0.138097,63.214695,3.22031,1.380972,-1289.63623,0.139234,0
84.910004,14.733292,-1289.63623,-0.001569,0.005464,0.138783,65.536957,3.338612,1.38783,-1289.63623,0.139902,0
85.310005,14.753403,-1289.63623,-0.001552,0.005483,0.13926,65.626411,3.343169,1.392599,-1289.63623,0.14056,0
85.710007,15.374519,-1289.63623,-0.001518,0.005512,0.140014,68.389275,3.483916,1.400139,-1289.63623,0.141228,0
86.110001,15.46389,-1289.591675,-0.001509,0.005533,0.140544,68.786819,3.504168,1.405437,-1289.591675,0.141896,0
86.510002,16.566483,-1289.680664,-0.001483,0.005565,0.141358,73.691391,3.754019,1.413583,-1289.680664,0.142563,0
86.910004,16.620102,-1289.680664,-0.00147,0.005593,0.142052,73.929909,3.766169,1.420516,-1289.680664,0.143231,0
87.310005,17.230423,-1289.63623,-0.001436,0.005615,0.142633,76.644753,3.90447,1.42633,-1289.63623,0.1439,0
87.710007,17.355911,-1289.769653,-0.001401,0.005637,0.143189,77.20295,3.932906,1.431886,-1289.769653,0.144568,0
88.110001,18.06044,-1289.72522,-0.001393,0.005665,0.143891,80.336853,4.092554,1.438911,-1289.72522,0.145235,0
88.510002,19.234901,-1289.680664,-0.001367,0.005699,0.144759,85.561111,4.358691,1.447586,-1289.680664,0.145894,0
88.910004,19.323524,-1289.769653,-0.001324,0.005722,0.145331,85.95533,4.378773,1.453309,-1289.769653,0.146562,0
89.310005,20.017632,-1289.63623,-0.001315,0.005748,0.145999,89.04287,4.53606,1.459985,-1289.63623,0.147229,0
89.710007,20.36319,-1289.680664,-0.001285,0.005771,0.146587,90.579994,4.614365,1.465875,-1289.680664,0.147897,0
90.110001,20.862541,-1289.769653,-0.001263,0.005799,0.14729,92.801216,4.727519,1.472899,-1289.769653,0.148565,0
90.510002,22.097328,-1289.769653,-0.001246,0.005832,0.148123,98.293823,5.007326,1.481226,-1289.769653,0.149232,0
90.910004,22.289848,-1289.72522,-0.001216,0.005853,0.148678,99.1502,5.050951,1.486782,-1289.72522,0.1499,0
91.310005,22.915062,-1289.63623,-0.001212,0.005878,0.149293,101.93129,5.192627,1.492929,-1289.63623,0.150569,0
91.710007,23.277748,-1289.769653,-0.00119,0.0059,0.149849,103.544594,5.274813,1.498485,-1289.769653,0.151228,0
92.110001,24.044464,-1289.769653,-0.001164,0.005924,0.150472,106.955116,5.448554,1.504723,-1289.769653,0.151895,0
92.510002,25.637848,-1289.680664,-0.001125,0.005959,0.151366,114.042847,5.809619,1.513655,-1289.680664,0.152563,0
92.910004,25.825523,-1289.72522,-0.001121,0.005984,0.151982,114.877663,5.852147,1.519817,-1289.72522,0.153231,0
93.310005,27.048019,-1289.72522,-0.001082,0.006015,0.15277,120.315598,6.129169,1.527705,-1289.72522,0.153898,0
93.710007,27.348526,-1289.680664,-0.001065,0.006033,0.153231,121.652321,6.197265,1.532307,-1289.680664,0.154566,0
94.110008,27.867989,-1289.72522,-0.001065,0.006055,0.153786,123.963005,6.314976,1.537863,-1289.72522,0.155234,0
94.510002,29.727989,-1289.72522,-0.00103,0.006094,0.154775,132.236694,6.736459,1.54775,-1289.72522,0.155901,0
94.910004,30.177811,-1289.680664,-0.001018,0.006114,0.155303,134.23761,6.838389,1.553033,-1289.680664,0.156569,0
95.310005,31.315041,-1289.72522,-0.000996,0.006141,0.15598,139.296265,7.09609,1.559801,-1289.72522,0.157229,0
95.710007,32.088081,-1289.72522,-0.000983,0.006168,0.156673,142.734909,7.271263,1.566735,-1289.72522,0.157897,0
96.110008,32.419121,-1289.72522,-0.000953,0.006182,0.157013,144.207458,7.346278,1.570126,-1289.72522,0.158564,0
96.510002,35.051796,-1289.72522,-0.000949,0.006227,0.158165,155.918182,7.942851,1.581647,-1289.72522,0.159232,0
96.910004,35.356026,-1289.814087,-0.000923,0.006245,0.158634,157.271454,8.01179,1.58634,-1289.814087,0.1599,0
97.310005,36.203545,-1289.769653,-0.00091,0.006269,0.159232,161.041412,8.20384,1.59232,-1289.769653,0.160567,0
97.710007,37.436844,-1289.814087,-0.000897,0.006294,0.159874,166.527405,8.48331,1.59874,-1289.814087,0.161235,0
98.110008,39.330353,-1289.814087,-0.00088,0.006326,0.160681,174.95015,8.912386,1.606809,-1289.814087,0.161903,0
98.510002,40.516357,-1289.814087,-0.000858,0.006351,0.161305,180.225754,9.181137,1.613047,-1289.814087,0.162563,0
98.910004,41.360901,-1289.903076,-0.000849,0.006372,0.161842,183.982483,9.372514,1.618421,-1289.903076,0.16323,0
99.310005,42.73719,-1289.769653,-0.000828,0.006401,0.162588,190.104523,9.684385,1.625885,-1289.769653,0.163898,0
99.710007,43.677429,-1289.769653,-0.000815,0.00642,0.163074,194.286911,9.897447,1.630745,-1289.769653,0.164566,0
100.110008,46.784134,-1289.858643,-0.000793,0.006463,0.164158,208.106216,10.601436,1.641585,-1289.858643,0.165233,0
100.510002,47.698685,-1289.814087,-0.00078,0.006485,0.164731,212.174347,10.808676,1.647307,-1289.814087,0.165901,0
100.910004,48.675789,-1289.858643,-0.000763,0.006508,0.165303,216.520721,11.030091,1.65303,-1289.858643,0.166569,0
101.310005,49.840569,-1289.814087,-0.000767,0.00653,0.16585,221.70192,11.294034,1.658496,-1289.814087,0.167236,0
101.710007,50.99865,-1289.814087,-0.00075,0.00655,0.166369,226.853317,11.556459,1.663688,-1289.814087,0.167895,0
102.110008,54.078163,-1289.814087,-0.000737,0.00659,0.167376,240.551682,12.254287,1.673756,-1289.814087,0.168564,0
102.510002,56.016739,-1289.858643,-0.000733,0.006619,0.16813,249.174896,12.693574,1.681296,-1289.858643,0.169232,0
102.910004,57.320786,-1289.858643,-0.000703,0.00664,0.168667,254.975586,12.989076,1.68667,-1289.858643,0.169899,0
103.310005,58.334381,-1289.769653,-0.000694,0.006659,0.169127,259.484283,13.21876,1.691273,-1289.769653,0.170567,0
103.710007,60.205925,-1289.858643,-0.00069,0.006686,0.169821,267.809326,13.642858,1.698207,-1289.858643,0.171235,0
104.110008,63.158844,-1289.858643,-0.000668,0.006721,0.170723,280.94458,14.311998,1.70723,-1289.858643,0.171902,0
104.510002,64.299049,-1289.858643,-0.000668,0.006741,0.171217,286.016449,14.570373,1.712165,-1289.858643,0.17257,0
104.910004,65.72448,-1289.858643,-0.00066,0.006765,0.171842,292.357086,14.89338,1.718418,-1289.858643,0.173229,0
105.310005,65.913658,-1289.858643,-0.000621,0.006765,0.171842,293.198608,14.936248,1.718418,-1289.858643,0.030138,0
105.710007,65.150291,-1289.858643,-0.000634,0.006764,0.171816,289.802979,14.763268,1.718161,-1289.858643,294.500488,0
106.110008,65.507393,-1289.858643,-0.000621,0.00678,0.172223,291.391449,14.844188,1.722233,-1289.858643,294.500488,0
106.510002,65.209862,-1289.903076,-0.000638,0.006781,0.172232,290.067963,14.776766,1.722324,-1289.903076,294.500488,0
106.910004,64.831169,-1289.947632,-0.000612,0.006781,0.17224,288.383453,14.690953,1.7224,-1289.947632,294.500488,0
107.310005,64.674019,-1289.858643,-0.000621,0.006784,0.17231,287.684418,14.655342,1.723096,-1289.858643,294.500488,0
107.710007,65.343544,-1289.947632,-0.000621,0.006793,0.172552,290.662598,14.807058,1.725518,-1289.947632,294.500488,0
108.110008,65.127205,-1289.903076,-0.000612,0.006794,0.172561,289.700287,14.758035,1.725609,-1289.903076,294.500488,0
108.510002,64.929848,-1289.903076,-0.000617,0.006794,0.17257,288.822388,14.713314,1.7257,-1289.903076,294.500488,0
108.910004,64.918678,-1289.858643,-0.000599,0.006797,0.17264,288.772705,14.710783,1.726397,-1289.858643,294.500488,0
109.310005,65.19944,-1289.947632,-0.000621,0.006802,0.17277,290.021606,14.774405,1.727699,-1289.947632,294.500488,0
109.710007,65.06353,-1289.903076,-0.000608,0.006802,0.17277,289.417023,14.743607,1.727699,-1289.903076,294.500488,0
110.110008,64.929848,-1289.947632,-0.000591,0.006802,0.172777,288.822388,14.713314,1.727774,-1289.947632,294.500488,0
110.510002,64.99128,-1289.947632,-0.000599,0.006805,0.172847,289.095642,14.727234,1.728471,-1289.947632,294.500488,0
110.910004,64.895958,-1289.947632,-0.000599,0.006806,0.172865,288.671631,14.705635,1.728652,-1289.947632,294.500488,0
111.310005,65.236687,-1289.947632,-0.000595,0.00681,0.172977,290.187286,14.782845,1.729773,-1289.947632,294.500488,0
111.710007,65.12162,-1289.903076,-0.000599,0.00681,0.172977,289.675446,14.756769,1.729773,-1289.903076,294.500488,0
112.110008,65.02964,-1289.992065,-0.000586,0.00681,0.172977,289.266296,14.735928,1.729773,-1289.992065,294.500488,0
112.510002,64.942131,-1289.992065,-0.000599,0.006811,0.172995,288.877014,14.716098,1.729954,-1289.992065,294.500488,0
112.910004,65.302589,-1290.036499,-0.000595,0.006816,0.173133,290.480438,14.797779,1.731332,-1290.036499,294.500488,0
113.310005,65.27578,-1289.992065,-0.000578,0.006816,0.173133,290.361176,14.791703,1.731332,-1289.992065,294.500488,0
113.710007,65.215446,-1289.992065,-0.000582,0.006816,0.173133,290.092804,14.778031,1.731332,-1289.992065,294.500488,0
114.110008,65.099648,-1290.036499,-0.000586,0.006816,0.173133,289.577698,14.751791,1.731332,-1290.036499,294.500488,0
114.510002,65.055336,-1289.992065,-0.000591,0.006817,0.173151,289.380585,14.74175,1.731514,-1289.992065,294.500488,0
114.910004,64.994637,-1290.036499,-0.000591,0.006817,0.173151,289.110596,14.727995,1.731514,-1290.036499,294.500488,0
115.310005,64.927605,-1290.036499,-0.000586,0.006817,0.173151,288.812408,14.712806,1.731514,-1290.036499,294.500488,0
115.710007,64.831917,-1290.081055,-0.000578,0.006818,0.173186,288.38678,14.691123,1.731862,-1290.081055,294.500488,0
116.110008,65.580757,-1289.992065,-0.000595,0.006826,0.173377,291.717773,14.860812,1.73377,-1289.992065,294.500488,0
116.510002,65.574425,-1289.992065,-0.000578,0.006826,0.173377,291.689606,14.859378,1.73377,-1289.992065,294.500488,0
116.910004,65.539421,-1290.036499,-0.000595,0.006826,0.173377,291.533905,14.851445,1.73377,-1290.036499,294.500488,0
117.310005,65.490273,-1289.992065,-0.000582,0.006826,0.173377,291.315277,14.840308,1.73377,-1289.992065,294.500488,0
117.710007,65.408348,-1290.036499,-0.000582,0.006826,0.173377,290.950867,14.821744,1.73377,-1290.036499,294.500488,0
118.110008,65.345406,-1290.081055,-0.000586,0.006826,0.173377,290.670868,14.807481,1.73377,-1290.081055,294.500488,0
118.510002,65.280998,-1290.081055,-0.000582,0.006826,0.173377,290.384369,14.792886,1.73377,-1290.081055,294.500488,0
118.910004,65.240028,-1290.081055,-0.000591,0.006826,0.173377,290.202148,14.783602,1.73377,-1290.081055,294.500488,0
119.310005,65.17971,-1290.036499,-0.000573,0.006826,0.173377,289.933838,14.769934,1.73377,-1290.036499,294.500488,0
119.710007,65.107094,-1290.081055,-0.000569,0.006826,0.173377,289.610809,14.753479,1.73377,-1290.081055,294.500488,0
120.110008,65.036339,-1290.125488,-0.000556,0.006826,0.173377,289.296082,14.737446,1.73377,-1290.125488,294.500488,0
120.510002,65.015862,-1290.081055,-0.000595,0.006826,0.173385,289.204987,14.732804,1.733845,-1290.081055,294.500488,0
120.910004,64.974159,-1290.170044,-0.000582,0.006826,0.173385,289.019501,14.723354,1.733845,-1290.170044,294.500488,0
121.310005,64.90638,-1290.081055,-0.000578,0.006826,0.173385,288.717987,14.707996,1.733845,-1290.081055,294.500488,0
121.710007,64.849419,-1290.125488,-0.000582,0.006826,0.173385,288.46463,14.695088,1.733845,-1290.125488,294.500488,0
122.110008,64.792809,-1290.125488,-0.000582,0.006827,0.173394,288.212799,14.682261,1.733936,-1290.125488,294.500488,0
122.510002,64.748878,-1290.170044,-0.000578,0.006827,0.173394,288.017395,14.672306,1.733936,-1290.170044,294.500488,0
122.910004,64.707542,-1290.170044,-0.000569,0.006827,0.173394,287.833527,14.662939,1.733936,-1290.170044,294.500488,0
123.310005,64.676262,-1290.125488,-0.000573,0.006827,0.173394,287.694366,14.65585,1.733936,-1290.125488,294.500488,0
123.710007,64.637154,-1290.214478,-0.000582,0.006827,0.173394,287.520416,14.646988,1.733936,-1290.214478,294.500488,0
124.110008,66.018288,-1290.125488,-0.00056,0.00683,0.17348,293.664001,14.959958,1.734799,-1290.125488,294.500488,0
124.510002,65.965782,-1290.214478,-0.000573,0.00683,0.173472,293.43045,14.94806,1.734723,-1290.214478,294.500488,0
124.910004,65.870461,-1290.170044,-0.00056,0.00683,0.173472,293.006439,14.926459,1.734723,-1290.170044,294.500488,0
125.310005,65.826515,-1290.125488,-0.000565,0.00683,0.173472,292.810974,14.916502,1.734723,-1290.125488,294.500488,0
125.710007,65.837685,-1290.170044,-0.000565,0.00683,0.173472,292.860657,14.919033,1.734723,-1290.170044,294.500488,0
126.110008,65.766945,-1290.258911,-0.000578,0.00683,0.173472,292.54599,14.903003,1.734723,-1290.258911,294.500488,0
126.51001,65.746834,-1290.214478,-0.000543,0.00683,0.173472,292.456512,14.898445,1.734723,-1290.214478,294.500488,0
126.910004,65.67086,-1290.125488,-0.000565,0.00683,0.173472,292.118561,14.881229,1.734723,-1290.125488,294.500488,0
127.310005,65.624321,-1290.214478,-0.000565,0.00683,0.173472,291.91156,14.870684,1.734723,-1290.214478,294.500488,0
127.710007,65.581871,-1290.214478,-0.000565,0.00683,0.173472,291.722717,14.861064,1.734723,-1290.214478,294.500488,0
128.110001,65.558784,-1290.170044,-0.000582,0.00683,0.173472,291.620026,14.855833,1.734723,-1290.170044,294.500488,0
128.51001,65.525642,-1290.214478,-0.000569,0.00683,0.173472,291.472626,14.848323,1.734723,-1290.214478,294.500488,0
128.910004,65.480949,-1290.258911,-0.00056,0.00683,0.173472,291.273804,14.838195,1.734723,-1290.258911,294.500488,0
129.310013,65.418022,-1290.303467,-0.000569,0.00683,0.173472,290.993896,14.823936,1.734723,-1290.303467,294.500488,0
129.710007,65.368874,-1290.258911,-0.000573,0.00683,0.173472,290.775269,14.812799,1.734723,-1290.258911,294.500488,0
130.110001,65.340202,-1290.214478,-0.000556,0.00683,0.173472,290.647736,14.806301,1.734723,-1290.214478,294.500488,0
130.51001,65.310783,-1290.214478,-0.000565,0.00683,0.173472,290.516876,14.799635,1.734723,-1290.214478,294.500488,0
130.910004,65.280617,-1290.258911,-0.000552,0.00683,0.173472,290.38269,14.792799,1.734723,-1290.258911,294.500488,0
131.310013,65.24897,-1290.258911,-0.000556,0.00683,0.173472,290.241913,14.785628,1.734723,-1290.258911,294.500488,0
131.710007,65.217323,-1290.303467,-0.000552,0.00683,0.173472,290.101135,14.778457,1.734723,-1290.303467,294.500488,0
132.110001,65.178596,-1290.303467,-0.00056,0.00683,0.173472,289.928864,14.769681,1.734723,-1290.303467,294.500488,0
132.51001,65.126457,-1290.3479,-0.00056,0.00683,0.173472,289.69696,14.757866,1.734723,-1290.3479,294.500488,0
132.910004,65.08326,-1290.303467,-0.00056,0.00683,0.17348,289.504791,14.748077,1.734799,-1290.303467,294.500488,0
133.310013,65.065758,-1290.3479,-0.000565,0.00683,0.17348,289.426941,14.744112,1.734799,-1290.3479,294.500488,0
133.710007,65.31414,-1290.3479,-0.000552,0.006841,0.173766,290.531799,14.800396,1.73766,-1290.3479,294.500488,0
134.110001,65.364037,-1290.3479,-0.000582,0.006841,0.173766,290.753754,14.811702,1.73766,-1290.3479,294.500488,0
134.51001,65.355843,-1290.303467,-0.000578,0.006841,0.173766,290.717316,14.809846,1.73766,-1290.303467,294.500488,0
134.910004,65.354347,-1290.258911,-0.000573,0.006841,0.173766,290.710663,14.809507,1.73766,-1290.258911,294.500488,0
135.310013,65.344292,-1290.303467,-0.000556,0.006841,0.173766,290.665924,14.807228,1.73766,-1290.303467,294.500488,0
135.710007,65.328651,-1290.303467,-0.000569,0.006841,0.173766,290.596344,14.803684,1.73766,-1290.303467,294.500488,0
136.110001,65.319725,-1290.258911,-0.000565,0.006841,0.173766,290.556641,14.801661,1.73766,-1290.258911,294.500488,0
136.51001,65.316368,-1290.3479,-0.00056,0.006841,0.173766,290.541718,14.8009,1.73766,-1290.3479,294.500488,0
136.910004,65.285835,-1290.392334,-0.000578,0.006841,0.173766,290.405914,14.793983,1.73766,-1290.392334,294.500488,0
137.310013,65.270195,-1290.3479,-0.000565,0.006841,0.173766,290.336334,14.790438,1.73766,-1290.3479,294.500488,0
137.710007,65.252312,-1290.303467,-0.000565,0.006842,0.173775,290.256775,14.786386,1.737751,-1290.303467,294.500488,0
138.110001,65.21769,-1290.392334,-0.000578,0.006842,0.173775,290.102783,14.77854,1.737751,-1290.392334,294.500488,0
138.51001,65.207634,-1290.3479,-0.00056,0.006842,0.173775,290.058044,14.776261,1.737751,-1290.3479,294.500488,0
138.910004,65.185295,-1290.43689,-0.000552,0.006842,0.173775,289.958679,14.771199,1.737751,-1290.43689,294.500488,0
139.310013,65.159966,-1290.392334,-0.000565,0.006842,0.173775,289.846008,14.76546,1.737751,-1290.392334,294.500488,0
139.710007,65.152901,-1290.43689,-0.000556,0.006843,0.173801,289.814575,14.763858,1.738009,-1290.43689,294.500488,0
140.110001,65.169655,-1290.43689,-0.000569,0.006843,0.17381,289.889099,14.767654,1.738099,-1290.43689,294.500488,0
140.51001,65.14843,-1290.392334,-0.000569,0.006843,0.17381,289.794678,14.762845,1.738099,-1290.392334,294.500488,0
140.910004,65.127571,-1290.392334,-0.000573,0.006843,0.17381,289.701904,14.758119,1.738099,-1290.392334,294.500488,0
141.310013,65.086983,-1290.3479,-0.000573,0.006843,0.173819,289.521362,14.748921,1.73819,-1290.3479,294.500488,0
141.710007,65.132042,-1290.392334,-0.00056,0.006844,0.173845,289.721802,14.759132,1.738448,-1290.392334,294.500488,0
142.110001,65.131676,-1290.392334,-0.000548,0.006844,0.173845,289.720154,14.759048,1.738448,-1290.392334,294.500488,0
142.51001,65.126823,-1290.43689,-0.000565,0.006844,0.173845,289.698578,14.757949,1.738448,-1290.43689,294.500488,0
142.910004,65.127571,-1290.392334,-0.00056,0.006844,0.173845,289.701904,14.758119,1.738448,-1290.392334,294.500488,0
143.310013,65.101875,-1290.43689,-0.000548,0.006844,0.173845,289.587616,14.752295,1.738448,-1290.43689,294.500488,0
143.710007,65.093681,-1290.43689,-0.000565,0.006845,0.173854,289.551147,14.75044,1.738539,-1290.43689,294.500488,0
144.110001,65.082146,-1290.43689,-0.000556,0.006845,0.173854,289.499847,14.747825,1.738539,-1290.43689,294.500488,0
144.51001,65.060921,-1290.43689,-0.000573,0.006845,0.173854,289.405426,14.743015,1.738539,-1290.43689,294.500488,0
144.910004,65.050117,-1290.481323,-0.000565,0.006845,0.173854,289.357361,14.740567,1.738539,-1290.481323,294.500488,0
145.310013,65.044167,-1290.481323,-0.00056,0.006845,0.173854,289.330902,14.73922,1.738539,-1290.481323,294.500488,0
145.710007,65.014748,-1290.481323,-0.000565,0.006845,0.173854,289.200043,14.732553,1.738539,-1290.481323,294.500488,0
146.110001,65.003197,-1290.43689,-0.000552,0.006845,0.173854,289.148651,14.729935,1.738539,-1290.43689,294.500488,0
146.51001,64.981972,-1290.525879,-0.000556,0.006845,0.173854,289.05426,14.725125,1.738539,-1290.525879,294.500488,0
146.910004,64.988686,-1290.43689,-0.000556,0.006845,0.173854,289.084106,14.726646,1.738539,-1290.43689,294.500488,0
147.310013,64.959999,-1290.43689,-0.000556,0.006845,0.173854,288.956512,14.720146,1.738539,-1290.43689,294.500488,0
147.710007,64.957405,-1290.43689,-0.000556,0.006845,0.173854,288.944977,14.719558,1.738539,-1290.43689,294.500488,0
148.110001,64.93766,-1290.43689,-0.00056,0.006845,0.173854,288.857147,14.715084,1.738539,-1290.43689,294.500488,0
148.51001,64.898933,-1290.43689,-0.000556,0.006845,0.173854,288.684875,14.706308,1.738539,-1290.43689,294.500488,0
148.910004,65.243752,-1290.43689,-0.000552,0.00685,0.174001,290.218689,14.784445,1.740007,-1290.43689,294.500488,0
149.310013,65.266472,-1290.481323,-0.000556,0.00685,0.174001,290.319763,14.789594,1.740007,-1290.481323,294.500488,0
149.710007,65.271675,-1290.525879,-0.00056,0.00685,0.174001,290.342926,14.790773,1.740007,-1290.525879,294.500488,0
150.110001,65.264977,-1290.43689,-0.000556,0.00685,0.174001,290.31311,14.789255,1.740007,-1290.43689,294.500488,0
150.51001,65.25753,-1290.481323,-0.00056,0.00685,0.174001,290.279999,14.787567,1.740007,-1290.481323,294.500488,0
150.910004,65.243004,-1290.481323,-0.000543,0.00685,0.174001,290.215363,14.784276,1.740007,-1290.481323,294.500488,0
151.310013,65.235191,-1290.43689,-0.000552,0.00685,0.174001,290.180634,14.782506,1.740007,-1290.43689,294.500488,0
151.710007,65.23333,-1290.481323,-0.000565,0.00685,0.174001,290.172333,14.782084,1.740007,-1290.481323,294.500488,0
152.110001,65.216942,-1290.525879,-0.000556,0.00685,0.174001,290.099457,14.77837,1.740007,-1290.525879,294.500488,0
152.51001,65.214714,-1290.570312,-0.000565,0.00685,0.174001,290.089539,14.777865,1.740007,-1290.570312,294.500488,0
152.910004,65.200935,-1290.481323,-0.00056,0.00685,0.174001,290.028259,14.774743,1.740007,-1290.481323,294.500488,0
153.310013,65.193108,-1290.525879,-0.000548,0.00685,0.174001,289.993439,14.772969,1.740007,-1290.525879,294.500488,0
153.710007,65.170021,-1290.570312,-0.000552,0.00685,0.174001,289.890747,14.767738,1.740007,-1290.570312,294.500488,0
154.110001,65.152519,-1290.43689,-0.000548,0.00685,0.174001,289.812866,14.763772,1.740007,-1290.43689,294.500488,0
154.51001,65.139488,-1290.525879,-0.000552,0.00685,0.174001,289.754913,14.760818,1.740007,-1290.525879,294.500488,0
154.910004,65.129814,-1290.525879,-0.00056,0.00685,0.174001,289.711884,14.758627,1.740007,-1290.525879,294.500488,0
155.310013,65.114906,-1290.481323,-0.000535,0.00685,0.174001,289.645569,14.755248,1.740007,-1290.481323,294.500488,0
155.710007,65.110817,-1290.570312,-0.000548,0.00685,0.174001,289.62738,14.754322,1.740007,-1290.570312,294.500488,0
156.110001,65.09182,-1290.525879,-0.000552,0.00685,0.174001,289.542877,14.750017,1.740007,-1290.525879,294.500488,0
156.51001,65.087364,-1290.570312,-0.000552,0.006851,0.174026,289.523041,14.749007,1.740264,-1290.570312,294.500488,0
156.910004,65.093315,-1290.570312,-0.00056,0.006851,0.174026,289.54953,14.750356,1.740264,-1290.570312,294.500488,0
157.310013,65.089592,-1290.659302,-0.000569,0.006851,0.174026,289.532959,14.749513,1.740264,-1290.659302,294.500488,0
157.710007,65.093681,-1290.614746,-0.00056,0.006852,0.174036,289.551147,14.75044,1.740355,-1290.614746,294.500488,0
158.110001,65.101509,-1290.570312,-0.00056,0.006852,0.174036,289.585968,14.752213,1.740355,-1290.570312,294.500488,0
158.51001,65.096672,-1290.614746,-0.000552,0.006852,0.174036,289.564453,14.751117,1.740355,-1290.614746,294.500488,0
158.910004,65.092949,-1290.659302,-0.000548,0.006852,0.174036,289.547913,14.750273,1.740355,-1290.659302,294.500488,0
159.310013,65.092567,-1290.570312,-0.000548,0.006852,0.174036,289.546204,14.750187,1.740355,-1290.570312,294.500488,0
159.710007,65.091087,-1290.570312,-0.00056,0.006852,0.174036,289.539612,14.749851,1.740355,-1290.570312,294.500488,0
160.110001,65.074699,-1290.614746,-0.000548,0.006852,0.174036,289.466705,14.746138,1.740355,-1290.614746,294.500488,0
160.51001,65.081032,-1290.614746,-0.000548,0.006852,0.174036,289.494873,14.747572,1.740355,-1290.614746,294.500488,0
160.910004,65.06353,-1290.570312,-0.000548,0.006852,0.174036,289.417023,14.743607,1.740355,-1290.570312,294.500488,0
161.310013,65.050865,-1290.659302,-0.000573,0.006852,0.174036,289.360687,14.740736,1.740355,-1290.659302,294.500488,0
161.710007,65.054588,-1290.570312,-0.000548,0.006852,0.174036,289.377258,14.741581,1.740355,-1290.570312,294.500488,0
162.110001,65.046776,-1290.614746,-0.00056,0.006852,0.174036,289.342499,14.73981,1.740355,-1290.614746,294.500488,0
162.51001,65.044167,-1290.659302,-0.00056,0.006852,0.174036,289.330902,14.73922,1.740355,-1290.659302,294.500488,0
162.910004,65.031502,-1290.659302,-0.000552,0.006852,0.174036,289.274567,14.736349,1.740355,-1290.659302,294.500488,0
163.310013,65.055702,-1290.659302,-0.000548,0.006852,0.174036,289.382202,14.741833,1.740355,-1290.659302,294.500488,0
163.710007,65.007301,-1290.659302,-0.000556,0.006852,0.174036,289.166931,14.730865,1.740355,-1290.659302,294.500488,0
164.110001,65.003578,-1290.659302,-0.000548,0.006852,0.174036,289.15036,14.730021,1.740355,-1290.659302,294.500488,0
164.51001,65.015862,-1290.703735,-0.000569,0.006852,0.174045,289.204987,14.732804,1.740446,-1290.703735,294.500488,0
164.910004,65.003197,-1290.659302,-0.000556,0.006852,0.174045,289.148651,14.729935,1.740446,-1290.659302,294.500488,0
165.310013,64.996864,-1290.703735,-0.00056,0.006852,0.174052,289.120483,14.728499,1.740522,-1290.703735,294.500488,0
165.710007,65.112679,-1290.659302,-0.000556,0.006855,0.174122,289.635651,14.754745,1.741218,-1290.659302,1681.640991,0
166.110001,65.029274,-1290.703735,-0.000552,0.006842,0.173784,289.264648,14.735844,1.737842,-1290.703735,0.173584,0
166.51001,65.037834,-1290.703735,-0.000552,0.006823,0.173298,289.302734,14.737784,1.732982,-1290.703735,0.172917,0
166.910004,64.933937,-1290.703735,-0.000535,0.006801,0.172752,288.840576,14.71424,1.727517,-1290.703735,0.172249,0
167.310013,64.92054,-1290.659302,-0.00053,0.006776,0.172102,288.780975,14.711205,1.721022,-1290.659302,0.171581,0
167.710007,64.908623,-1290.703735,-0.00053,0.006747,0.171382,288.727966,14.708505,1.713816,-1290.703735,0.170923,0
168.110001,64.903404,-1290.748291,-0.000522,0.006724,0.170793,288.704773,14.707321,1.707926,-1290.748291,0.170255,0
168.51001,64.919411,-1290.748291,-0.000539,0.006701,0.170202,288.77597,14.710948,1.702022,-1290.748291,0.169586,0
168.910004,64.872871,-1290.703735,-0.000526,0.006673,0.1695,288.568939,14.700402,1.694997,-1290.703735,0.168918,0
169.310013,64.819618,-1290.659302,-0.00053,0.006652,0.168953,288.332062,14.688335,1.689532,-1290.659302,0.168251,0
169.710007,64.767113,-1290.703735,-0.00053,0.006626,0.168295,288.098511,14.676437,1.682946,-1290.703735,0.167583,0
170.110001,64.398094,-1290.659302,-0.000548,0.0066,0.167644,286.457031,14.592816,1.676436,-1290.659302,0.166915,0
170.51001,63.680168,-1290.748291,-0.000535,0.006577,0.167064,283.26355,14.430132,1.670637,-1290.748291,0.166248,0
170.910004,62.485962,-1290.659302,-0.000517,0.006553,0.166448,277.951447,14.159521,1.664476,-1290.659302,0.165589,0
171.310013,61.087708,-1290.703735,-0.000504,0.006527,0.16578,271.731689,13.842672,1.657799,-1290.703735,0.164921,0
171.710007,59.351707,-1290.748291,-0.000509,0.006501,0.16512,264.009583,13.449289,1.651198,-1290.748291,0.164254,0
172.110001,57.499893,-1290.703735,-0.000522,0.006478,0.164531,255.772293,13.029662,1.645309,-1290.703735,0.163586,0
172.51001,55.220604,-1290.703735,-0.000513,0.00645,0.163828,245.633514,12.513168,1.638284,-1290.703735,0.162917,0
172.910004,53.188568,-1290.703735,-0.000526,0.006427,0.163256,236.594574,12.052702,1.632561,-1290.703735,0.162249,0
173.310013,50.393166,-1290.703735,-0.000509,0.006401,0.162598,224.159988,11.419255,1.625976,-1290.703735,0.161582,0
173.710007,46.527939,-1290.792725,-0.0005,0.006375,0.161937,206.966614,10.543382,1.619375,-1290.792725,0.161765,0
173.900009,46.548798,-1290.703735,-0.000513,0.006376,0.161956,207.059387,10.548108,1.619557,-1290.703735,0.161765,0