File: Data/compression 37/Heating-17-37-reverse-1-2_11212024_110043(in).csv
Time (sec),S:Load (lbs),S:HL1 (DIM),S:LVDT (in),S:Position (in),Ch:Position (mm),Ch:Load (N),Ch:Stress (MPa),Ch:Strain (mm/mm),Ch:HL1 (DIM),Set Point (),Cycles ()
0.11,0.429718,-1291.192993,-0.015375,-0.008133,-0.206572,1.911481,0.097375,-2.06572,-1291.192993,-0.206365,0
0.81,0.428978,-1291.192993,-0.015349,0,0,1.908189,0.097208,0,-1291.192993,0,0
1.51,0.446106,-1291.237549,-0.015366,0.000018,0.000451,1.984378,0.101089,0.004512,-1291.237549,0.000893,0
2.21,0.473663,-1291.281982,-0.015379,0.000056,0.001431,2.10696,0.107334,0.014307,-1291.281982,0.002064,0
2.91,0.436424,-1291.281982,-0.015362,0.0001,0.00254,1.941312,0.098895,0.025404,-1291.281982,0.003226,0
3.61,0.437172,-1291.237549,-0.015379,0.00013,0.003313,1.944638,0.099065,0.033125,-1291.237549,0.004397,0
4.31,0.395462,-1291.281982,-0.015358,0.000168,0.004275,1.759103,0.089613,0.042754,-1291.281982,0.005567,0
5.01,0.444618,-1291.326538,-0.015319,0.000219,0.00555,1.977761,0.100752,0.055502,-1291.326538,0.00673,0
5.71,0.42041,-1291.237549,-0.015271,0.000258,0.006546,1.870078,0.095266,0.065464,-1291.237549,0.0079,0
6.41,0.417061,-1291.281982,-0.01522,0.000308,0.00783,1.855179,0.094507,0.078302,-1291.281982,0.009063,0
7.11,0.4543,-1291.326538,-0.015168,0.000358,0.009088,2.020827,0.102946,0.090883,-1291.326538,0.010233,0
7.81,0.376846,-1291.281982,-0.015103,0.000408,0.010372,1.676296,0.085395,0.103721,-1291.281982,0.011396,0
8.51,0.39621,-1291.237549,-0.015095,0.000445,0.0113,1.762429,0.089782,0.113002,-1291.237549,0.012566,0
9.21,0.413338,-1291.370972,-0.01503,0.000498,0.012652,1.838618,0.093664,0.126521,-1291.370972,0.013727,0
9.910001,0.359718,-1291.326538,-0.014987,0.000536,0.013615,1.600107,0.081513,0.13615,-1291.326538,0.014899,0
10.610001,0.409988,-1291.326538,-0.014948,0.000586,0.01489,1.82372,0.092905,0.148898,-1291.326538,0.01606,0
11.31,0.406631,-1291.281982,-0.014892,0.000635,0.016121,1.808787,0.092144,0.161206,-1291.281982,0.017232,0
12.01,0.33812,-1291.326538,-0.014857,0.000673,0.017084,1.504031,0.076619,0.170835,-1291.326538,0.018393,0
12.710001,0.415573,-1291.326538,-0.014814,0.000726,0.018428,1.848562,0.09417,0.184279,-1291.326538,0.019565,0
13.410001,0.43158,-1291.326538,-0.01475,0.000768,0.019512,1.919762,0.097797,0.195119,-1291.326538,0.020735,0
14.110001,0.379448,-1291.370972,-0.014724,0.000812,0.020622,1.687869,0.085984,0.206216,-1291.370972,0.021896,0
14.81,0.466583,-1291.326538,-0.014672,0.000867,0.022019,2.075466,0.105729,0.22019,-1291.326538,0.023068,0
15.510001,0.467331,-1291.281982,-0.014625,0.000907,0.023033,2.078792,0.105899,0.230334,-1291.281982,0.024229,0
16.210001,0.422646,-1291.326538,-0.01456,0.000958,0.024334,1.880021,0.095773,0.243338,-1291.326538,0.025401,0
16.910002,0.476639,-1291.370972,-0.014521,0.001001,0.025418,2.120195,0.108008,0.254178,-1291.370972,0.026562,0
17.610001,0.417061,-1291.415405,-0.014487,0.001043,0.026493,1.855179,0.094507,0.264928,-1291.415405,0.027733,0
18.310001,0.43866,-1291.370972,-0.014431,0.001084,0.027525,1.951256,0.099402,0.275253,-1291.370972,0.028895,0
19.01,0.484833,-1291.370972,-0.014383,0.001138,0.028895,2.156644,0.109865,0.288954,-1291.370972,0.030066,0
19.710001,0.424881,-1291.370972,-0.014327,0.001183,0.030049,1.889965,0.096279,0.30049,-1291.370972,0.031228,0
20.410002,0.468079,-1291.459961,-0.014263,0.001231,0.03128,2.082118,0.106068,0.312799,-1291.459961,0.032399,0
21.110001,0.492279,-1291.415405,-0.014228,0.001268,0.032208,2.189767,0.111552,0.322079,-1291.415405,0.033561,0
21.810001,0.434937,-1291.415405,-0.014185,0.001318,0.033475,1.934694,0.098558,0.334751,-1291.415405,0.034732,0
22.51,0.461746,-1291.370972,-0.014129,0.00137,0.03481,2.05395,0.104633,0.348104,-1291.370972,0.035902,0
23.210001,0.475891,-1291.415405,-0.014099,0.001408,0.035773,2.116869,0.107838,0.357733,-1291.415405,0.037065,0
23.910002,0.446854,-1291.415405,-0.014047,0.001454,0.036944,1.987704,0.101258,0.369436,-1291.415405,0.038235,0
24.610001,0.459511,-1291.415405,-0.013978,0.001506,0.038262,2.044006,0.104127,0.382623,-1291.415405,0.039398,0
25.310001,0.422646,-1291.415405,-0.013935,0.00155,0.039372,1.880021,0.095773,0.39372,-1291.415405,0.040568,0
26.010002,0.411476,-1291.370972,-0.013913,0.001592,0.04043,1.830337,0.093242,0.404302,-1291.370972,0.041731,0
26.710001,0.433815,-1291.370972,-0.013857,0.001645,0.041791,1.929706,0.098304,0.417913,-1291.370972,0.042901,0
27.410002,0.417435,-1291.459961,-0.013797,0.001691,0.042945,1.856842,0.094592,0.429449,-1291.459961,0.044064,0
28.110001,0.425621,-1291.370972,-0.013762,0.001726,0.043838,1.893257,0.096447,0.438382,-1291.370972,0.045234,0
28.810001,0.436424,-1291.415405,-0.013715,0.001785,0.045346,1.941312,0.098895,0.453461,-1291.415405,0.046397,0
29.510002,0.389877,-1291.459961,-0.013646,0.001829,0.046465,1.734261,0.088347,0.464649,-1291.459961,0.047567,0
30.210001,0.442383,-1291.459961,-0.013607,0.00188,0.04774,1.967817,0.100245,0.477396,-1291.459961,0.048728,0
30.910002,0.422646,-1291.415405,-0.013577,0.001918,0.048728,1.880021,0.095773,0.487283,-1291.415405,0.0499,0
31.610001,0.381683,-1291.326538,-0.013534,0.001964,0.049882,1.697812,0.086491,0.498819,-1291.326538,0.05107,0
32.310001,0.443871,-1291.415405,-0.013478,0.002014,0.051149,1.974435,0.100583,0.511491,-1291.415405,0.052233,0
33.010002,0.412964,-1291.459961,-0.013439,0.002056,0.052224,1.836955,0.093579,0.52224,-1291.459961,0.053403,0
33.710003,0.357109,-1291.415405,-0.013392,0.002097,0.053264,1.5885,0.080922,0.532641,-1291.415405,0.054566,0
34.41,0.416313,-1291.415405,-0.013323,0.002145,0.054478,1.851853,0.094338,0.544783,-1291.415405,0.055736,0
35.110001,0.39621,-1291.504395,-0.013279,0.002197,0.055806,1.762429,0.089782,0.55806,-1291.504395,0.056898,0
35.810001,0.3936,-1291.415405,-0.013228,0.002233,0.056725,1.750822,0.089191,0.56725,-1291.415405,0.058069,0
36.510002,0.454666,-1291.504395,-0.013185,0.002284,0.058009,2.022456,0.103029,0.580088,-1291.504395,0.059231,0
37.210003,0.420784,-1291.459961,-0.013142,0.002328,0.059135,1.871741,0.095351,0.591352,-1291.459961,0.060402,0
37.910004,0.468819,-1291.459961,-0.013073,0.002382,0.060498,2.08541,0.106236,0.604978,-1291.459961,0.061564,0
38.610001,0.478127,-1291.459961,-0.013038,0.002423,0.061547,2.126813,0.108345,0.615469,-1291.459961,0.062735,0
39.310001,0.440147,-1291.504395,-0.012978,0.002467,0.062666,1.957873,0.099739,0.626657,-1291.504395,0.063897,0
40.010002,0.48967,-1291.415405,-0.012935,0.002515,0.063888,2.17816,0.110961,0.638875,-1291.415405,0.065067,0
40.710003,0.488556,-1291.459961,-0.012883,0.00256,0.065032,2.173205,0.110708,0.650321,-1291.459961,0.066239,0
41.410004,0.424881,-1291.459961,-0.012844,0.002601,0.066055,1.889965,0.096279,0.660555,-1291.459961,0.0674,0
42.110001,0.501213,-1291.415405,-0.012779,0.002653,0.067374,2.229507,0.113577,0.673742,-1291.415405,0.068572,0
42.810001,0.440521,-1291.504395,-0.012753,0.002693,0.068398,1.959536,0.099824,0.683976,-1291.504395,0.069733,0
43.510002,0.458763,-1291.504395,-0.012693,0.002742,0.069638,2.04068,0.103957,0.696375,-1291.504395,0.070903,0
44.210003,0.492653,-1291.504395,-0.012641,0.002793,0.07093,2.19143,0.111637,0.709304,-1291.504395,0.072066,0
44.910004,0.450577,-1291.504395,-0.01262,0.002833,0.071961,2.004266,0.102102,0.719615,-1291.504395,0.073236,0
45.610001,0.459137,-1291.54895,-0.012542,0.002885,0.073289,2.042343,0.104042,0.732892,-1291.54895,0.074399,0
46.310001,0.461372,-1291.54895,-0.012499,0.002926,0.074313,2.052287,0.104548,0.743126,-1291.54895,0.075569,0
47.010002,0.400673,-1291.504395,-0.012452,0.002969,0.075404,1.782282,0.090794,0.754042,-1291.504395,0.076732,0
47.710003,0.444618,-1291.504395,-0.012413,0.003026,0.076862,1.977761,0.100752,0.768621,-1291.504395,0.077902,0
48.410004,0.441261,-1291.459961,-0.012383,0.003057,0.077642,1.962828,0.099991,0.776418,-1291.459961,0.079065,0
49.110001,0.410355,-1291.54895,-0.012348,0.003111,0.079021,1.825348,0.092988,0.79021,-1291.54895,0.080235,0
49.810001,0.446106,-1291.54895,-0.012266,0.003162,0.080322,1.984378,0.101089,0.803215,-1291.54895,0.081406,0
50.510002,0.39621,-1291.593384,-0.012215,0.003208,0.081475,1.762429,0.089782,0.814752,-1291.593384,0.082568,0
51.210003,0.392113,-1291.54895,-0.012184,0.003245,0.082412,1.744205,0.088854,0.824123,-1291.54895,0.083739,0
51.910004,0.423759,-1291.593384,-0.012128,0.003298,0.083773,1.884976,0.096025,0.837734,-1291.593384,0.084901,0
52.610001,0.358597,-1291.682373,-0.012085,0.003342,0.084876,1.595118,0.081259,0.848755,-1291.682373,0.086072,0
53.310001,0.416687,-1291.593384,-0.012038,0.003394,0.086202,1.853516,0.094423,0.862017,-1291.593384,0.087234,0
54.010002,0.408867,-1291.682373,-0.011986,0.003433,0.087199,1.818731,0.092651,0.871994,-1291.682373,0.088405,0
54.710003,0.325081,-1291.682373,-0.011952,0.003478,0.088335,1.446032,0.073664,0.883349,-1291.682373,0.089567,0
55.410004,0.461746,-1291.637817,-0.011887,0.003527,0.089593,2.05395,0.104633,0.89593,-1291.637817,0.090738,0
56.110004,0.421532,-1291.637817,-0.011844,0.003574,0.090772,1.875067,0.09552,0.907724,-1291.637817,0.091899,0
56.810001,0.37014,-1291.682373,-0.011814,0.003614,0.091796,1.646465,0.083875,0.917958,-1291.682373,0.093071,0
57.510002,0.478127,-1291.637817,-0.011762,0.003666,0.093122,2.126813,0.108345,0.93122,-1291.637817,0.094232,0
58.210003,0.460999,-1291.637817,-0.011706,0.003709,0.094197,2.050624,0.104464,0.94197,-1291.637817,0.095404,0
58.910004,0.446106,-1291.726807,-0.011667,0.003758,0.095464,1.984378,0.101089,0.954641,-1291.726807,0.096565,0
59.610004,0.459511,-1291.682373,-0.011611,0.003806,0.09666,2.044006,0.104127,0.966602,-1291.682373,0.097737,0
60.310001,0.439034,-1291.726807,-0.011568,0.00385,0.097788,1.952919,0.099486,0.977881,-1291.726807,0.098907,0
61.010002,0.449829,-1291.726807,-0.011546,0.003884,0.098646,2.00094,0.101933,0.986465,-1291.726807,0.100068,0
61.710003,0.466217,-1291.637817,-0.011486,0.003941,0.100103,2.073837,0.105646,1.001029,-1291.637817,0.10124,0
62.410004,0.432701,-1291.682373,-0.011421,0.003983,0.101161,1.924751,0.098051,1.011612,-1291.682373,0.102401,0
63.110004,0.487068,-1291.593384,-0.011369,0.004033,0.102436,2.166587,0.110371,1.024359,-1291.593384,0.103573,0
63.810001,0.491165,-1291.726807,-0.011344,0.004068,0.10332,2.184812,0.1113,1.033201,-1291.726807,0.104734,0
64.510002,0.444984,-1291.637817,-0.011279,0.004115,0.104527,1.97939,0.100835,1.045267,-1291.637817,0.105904,0
65.210007,0.466217,-1291.682373,-0.011232,0.004175,0.106035,2.073837,0.105646,1.060346,-1291.682373,0.107067,0
65.910004,0.476639,-1291.726807,-0.011197,0.004214,0.107032,2.120195,0.108008,1.070323,-1291.726807,0.108237,0
66.610001,0.451691,-1291.682373,-0.011137,0.004252,0.108012,2.00922,0.102355,1.080118,-1291.682373,0.1094,0
67.310005,0.468079,-1291.726807,-0.011102,0.004308,0.109435,2.082118,0.106068,1.094349,-1291.726807,0.11057,0
68.010002,0.433075,-1291.726807,-0.011029,0.004355,0.110605,1.926414,0.098136,1.106052,-1291.726807,0.111733,0
68.710007,0.435677,-1291.726807,-0.011007,0.004393,0.111577,1.937986,0.098726,1.115772,-1291.726807,0.112903,0
69.410004,0.4394,-1291.77124,-0.010934,0.004443,0.112843,1.954548,0.099569,1.128429,-1291.77124,0.114074,0
70.110001,0.42041,-1291.682373,-0.010891,0.004488,0.113987,1.870078,0.095266,1.139874,-1291.682373,0.115236,0
70.810005,0.443123,-1291.77124,-0.010856,0.004524,0.114906,1.971109,0.100413,1.149064,-1291.77124,0.116407,0
71.510002,0.4394,-1291.77124,-0.010792,0.004581,0.116364,1.954548,0.099569,1.163643,-1291.77124,0.117569,0
72.210007,0.405518,-1291.682373,-0.010762,0.004627,0.117518,1.803832,0.091892,1.17518,-1291.682373,0.11874,0
72.910004,0.459137,-1291.726807,-0.010697,0.004681,0.118896,2.042343,0.104042,1.188957,-1291.726807,0.119902,0
73.610001,0.42823,-1291.815796,-0.010667,0.004722,0.119937,1.904863,0.097038,1.199373,-1291.815796,0.121073,0
74.310005,0.393227,-1291.726807,-0.010611,0.004765,0.121029,1.749159,0.089106,1.210288,-1291.726807,0.122235,0
75.010002,0.41967,-1291.77124,-0.010559,0.004813,0.122252,1.866786,0.095099,1.222521,-1291.77124,0.123406,0
75.710007,0.419296,-1291.815796,-0.010529,0.004853,0.123266,1.865123,0.095014,1.232665,-1291.815796,0.124568,0
76.410004,0.364182,-1291.726807,-0.01046,0.004901,0.12449,1.61996,0.082525,1.244897,-1291.726807,0.125739,0
77.110001,0.434937,-1291.77124,-0.01043,0.00495,0.12573,1.934694,0.098558,1.257297,-1291.77124,0.1269,0
77.810005,0.397697,-1291.726807,-0.010378,0.004994,0.126848,1.769047,0.09012,1.268485,-1291.726807,0.128072,0
78.510002,0.464348,-1291.77124,-0.010322,0.005045,0.128132,2.065522,0.105223,1.281323,-1291.77124,0.129242,0
79.210007,0.458763,-1291.726807,-0.010279,0.005085,0.129147,2.04068,0.103957,1.291467,-1291.726807,0.130405,0
79.910004,0.43084,-1291.815796,-0.010248,0.005132,0.130344,1.91647,0.09763,1.303442,-1291.815796,0.131575,0
80.610001,0.488556,-1291.815796,-0.010188,0.005183,0.131654,2.173205,0.110708,1.316538,-1291.815796,0.132738,0
81.310005,0.464722,-1291.860229,-0.010145,0.005224,0.132694,2.067185,0.105307,1.326939,-1291.860229,0.133908,0
82.010002,0.436424,-1291.860229,-0.010115,0.005264,0.133717,1.941312,0.098895,1.337173,-1291.860229,0.135069,0
82.710007,0.485207,-1291.860229,-0.010046,0.005319,0.135113,2.158307,0.109949,1.351132,-1291.860229,0.136241,0
83.410004,0.465843,-1291.904785,-0.009998,0.005359,0.136111,2.072174,0.105562,1.361109,-1291.904785,0.137402,0
84.110001,0.446106,-1291.860229,-0.00996,0.005402,0.137212,1.984378,0.101089,1.372115,-1291.860229,0.138574,0
84.810005,0.490044,-1291.904785,-0.009912,0.005455,0.138556,2.179823,0.111045,1.385559,-1291.904785,0.139735,0
85.510002,0.451691,-1291.860229,-0.00986,0.005502,0.139761,2.00922,0.102355,1.39761,-1291.860229,0.140907,0
86.210007,0.46286,-1291.904785,-0.009826,0.005548,0.140907,2.058905,0.104886,1.409071,-1291.904785,0.142068,0
86.910004,0.466583,-1291.949219,-0.009757,0.005589,0.141973,2.075466,0.105729,1.419729,-1291.949219,0.143239,0
87.610001,0.456535,-1291.904785,-0.009735,0.005632,0.14304,2.030771,0.103452,1.430403,-1291.904785,0.14441,0
88.310005,0.465096,-1291.904785,-0.009653,0.005686,0.144436,2.068848,0.105392,1.444361,-1291.904785,0.145572,0
89.010002,0.453926,-1291.904785,-0.009615,0.005729,0.145511,2.019164,0.102861,1.45511,-1291.904785,0.146743,0
89.710007,0.41967,-1291.993652,-0.009597,0.005767,0.146483,1.866786,0.095099,1.46483,-1291.993652,0.147905,0
90.410004,0.451317,-1291.993652,-0.009528,0.005826,0.147983,2.007558,0.10227,1.479833,-1291.993652,0.149075,0
91.110001,0.449455,-1291.993652,-0.009485,0.005873,0.149163,1.999277,0.101848,1.491627,-1291.993652,0.150238,0
91.810005,0.436424,-1291.993652,-0.009451,0.005913,0.150186,1.941312,0.098895,1.501861,-1291.993652,0.151408,0
92.510002,0.462486,-1292.038208,-0.009395,0.00596,0.151382,2.057242,0.104801,1.513822,-1292.038208,0.152571,0
93.210007,0.408493,-1292.038208,-0.009347,0.006005,0.152536,1.817068,0.092566,1.525358,-1292.038208,0.153741,0
93.910004,0.429718,-1292.082642,-0.009304,0.006047,0.153585,1.911481,0.097375,1.53585,-1292.082642,0.154904,0
94.610008,0.426743,-1292.038208,-0.009248,0.0061,0.154938,1.898246,0.096701,1.549385,-1292.038208,0.156074,0
95.310005,0.370514,-1291.993652,-0.009201,0.006142,0.156004,1.648128,0.08396,1.560043,-1291.993652,0.157237,0
96.010002,0.456902,-1292.082642,-0.00914,0.006196,0.157367,2.0324,0.103535,1.573668,-1292.082642,0.158407,0
96.710007,0.403656,-1292.082642,-0.009093,0.00623,0.158242,1.795552,0.09147,1.582419,-1292.082642,0.159577,0
97.410004,0.358971,-1292.082642,-0.009058,0.006279,0.159474,1.596781,0.081344,1.594743,-1292.082642,0.16074,0
98.110008,0.467331,-1292.082642,-0.00902,0.006332,0.160835,2.078792,0.105899,1.608353,-1292.082642,0.16191,0
98.810005,0.434563,-1292.038208,-0.008972,0.006379,0.162015,1.933031,0.098473,1.620147,-1292.038208,0.163073,0
99.510002,0.405144,-1292.082642,-0.008933,0.006419,0.163038,1.802169,0.091807,1.630381,-1292.082642,0.164243,0
100.210007,0.464348,-1292.082642,-0.008877,0.006469,0.164322,2.065522,0.105223,1.64322,-1292.082642,0.165406,0
100.910004,0.468819,-1292.127197,-0.008826,0.006507,0.165276,2.08541,0.106236,1.652758,-1292.127197,0.166576,0
101.610008,0.460625,-1292.082642,-0.008778,0.006558,0.166567,2.048961,0.104379,1.665672,-1292.082642,0.167739,0
102.310005,0.461372,-1292.082642,-0.008714,0.006604,0.167747,2.052287,0.104548,1.677465,-1292.082642,0.168909,0
103.010002,0.452065,-1292.082642,-0.008675,0.006647,0.16884,2.010883,0.102439,1.688396,-1292.082642,0.17007,0
103.710007,0.460258,-1292.127197,-0.008645,0.006691,0.169949,2.047332,0.104296,1.699494,-1292.127197,0.171242,0
104.410004,0.502708,-1292.171631,-0.008593,0.006743,0.171285,2.236159,0.113915,1.712847,-1292.171631,0.172403,0
105.110008,0.42823,-1292.082642,-0.008558,0.006784,0.172308,1.904863,0.097038,1.723081,-1292.082642,0.173575,0
105.810005,0.494141,-1292.127197,-0.008494,0.006831,0.173506,2.198047,0.111974,1.735056,-1292.127197,0.174746,0
106.510002,0.506805,-1292.171631,-0.008451,0.006872,0.174537,2.254383,0.114844,1.745366,-1292.171631,0.175908,0
107.210007,0.441635,-1292.127197,-0.008416,0.006924,0.175864,1.964491,0.100076,1.758644,-1292.127197,0.177079,0
107.910004,0.477386,-1292.127197,-0.00836,0.006973,0.177121,2.123521,0.108177,1.77121,-1292.127197,0.17824,0
108.610008,0.475151,-1292.127197,-0.0083,0.007013,0.178137,2.113577,0.107671,1.781368,-1292.127197,0.179412,0
109.310005,0.46286,-1292.082642,-0.008269,0.007049,0.179056,2.058905,0.104886,1.790558,-1292.082642,0.180573,0
110.010002,0.453926,-1292.171631,-0.008205,0.00711,0.180582,2.019164,0.102861,1.805819,-1292.171631,0.181745,0
110.710007,0.42823,-1292.127197,-0.00817,0.007155,0.181726,1.904863,0.097038,1.817264,-1292.127197,0.182906,0
111.410004,0.427116,-1292.171631,-0.008119,0.007195,0.182741,1.899909,0.096786,1.827408,-1292.171631,0.184078,0
112.110008,0.449829,-1292.216064,-0.00808,0.007243,0.183981,2.00094,0.101933,1.839807,-1292.216064,0.185239,0
112.810005,0.436798,-1292.127197,-0.008019,0.007293,0.185248,1.942975,0.09898,1.852479,-1292.127197,0.186409,0
113.510002,0.443871,-1292.127197,-0.007998,0.007328,0.186132,1.974435,0.100583,1.86132,-1292.127197,0.187572,0
114.210007,0.458397,-1292.127197,-0.007916,0.007382,0.187502,2.039051,0.103874,1.875022,-1292.127197,0.188742,0
114.910004,0.405144,-1292.127197,-0.007869,0.007434,0.188821,1.802169,0.091807,1.888208,-1292.127197,0.189914,0
115.610008,0.462486,-1292.171631,-0.00783,0.00748,0.19,2.057242,0.104801,1.900002,-1292.171631,0.191075,0
116.310005,0.423759,-1292.171631,-0.007787,0.007525,0.191128,1.884976,0.096025,1.911281,-1292.171631,0.192245,0
117.010002,0.38578,-1292.216064,-0.007731,0.007563,0.192089,1.716037,0.087419,1.920895,-1292.216064,0.193408,0
117.710007,0.417061,-1292.171631,-0.007692,0.007617,0.19346,1.855179,0.094507,1.934596,-1292.171631,0.194578,0
118.410004,0.371262,-1292.171631,-0.00764,0.007658,0.19451,1.651454,0.084129,1.945103,-1292.171631,0.195741,0
119.110008,0.439034,-1292.127197,-0.007588,0.007706,0.195732,1.952919,0.099486,1.957321,-1292.127197,0.196911,0
119.810005,0.440521,-1292.127197,-0.007545,0.007755,0.196964,1.959536,0.099824,1.969644,-1292.127197,0.198074,0
120.510002,0.409615,-1292.171631,-0.007502,0.007799,0.198091,1.822057,0.09282,1.980908,-1292.171631,0.199244,0
121.210007,0.457275,-1292.127197,-0.007455,0.007846,0.199279,2.034063,0.10362,1.992793,-1292.127197,0.200407,0
121.910004,0.464348,-1292.171631,-0.007403,0.007882,0.200191,2.065522,0.105223,2.001907,-1292.171631,0.201577,0
122.610008,0.432701,-1292.216064,-0.007373,0.007931,0.201447,1.924751,0.098051,2.014472,-1292.216064,0.20274,0
123.310005,0.480736,-1292.216064,-0.007286,0.007986,0.202852,2.13842,0.108936,2.028522,-1292.216064,0.20391,0
124.010002,0.452065,-1292.171631,-0.007265,0.008022,0.203755,2.010883,0.102439,2.037545,-1292.171631,0.205081,0
124.710007,0.459511,-1292.216064,-0.007196,0.008062,0.204778,2.044006,0.104127,2.04778,-1292.216064,0.206243,0
125.410004,0.498611,-1292.171631,-0.007157,0.008119,0.206225,2.217935,0.112987,2.062253,-1292.171631,0.207414,0
126.110008,0.492279,-1292.216064,-0.007123,0.008159,0.207241,2.189767,0.111552,2.072412,-1292.216064,0.208576,0
126.810005,0.452438,-1292.26062,-0.00708,0.008211,0.208549,2.012546,0.102524,2.085492,-1292.26062,0.209747,0
127.51001,0.507545,-1292.171631,-0.007028,0.008259,0.209782,2.257675,0.115011,2.097816,-1292.171631,0.210909,0
128.210007,0.440895,-1292.216064,-0.006976,0.0083,0.210831,1.961199,0.099908,2.108308,-1292.216064,0.21208,0
128.910004,0.466583,-1292.26062,-0.006911,0.008353,0.212157,2.075466,0.105729,2.12157,-1292.26062,0.213241,0
129.610001,0.494888,-1292.216064,-0.00689,0.008394,0.213199,2.201373,0.112143,2.131986,-1292.216064,0.214413,0
130.310013,0.469193,-1292.26062,-0.006817,0.00844,0.214387,2.087073,0.106321,2.143871,-1292.26062,0.215574,0
131.01001,0.48111,-1292.26062,-0.00676,0.008492,0.215697,2.140082,0.109021,2.156966,-1292.26062,0.216746,0
131.710007,0.481483,-1292.305054,-0.00673,0.008533,0.216746,2.141745,0.109106,2.167458,-1292.305054,0.217907,0
132.410004,0.425995,-1292.26062,-0.006683,0.008573,0.21776,1.89492,0.096532,2.177602,-1292.26062,0.219079,0
133.110001,0.48111,-1292.305054,-0.006644,0.008626,0.219105,2.140082,0.109021,2.191046,-1292.305054,0.220249,0
133.810013,0.442383,-1292.26062,-0.006571,0.00867,0.220223,1.967817,0.100245,2.202234,-1292.26062,0.22141,0
134.51001,0.423393,-1292.216064,-0.006532,0.008713,0.221307,1.883347,0.095942,2.213073,-1292.216064,0.222582,0
135.210007,0.457649,-1292.26062,-0.006502,0.008765,0.222624,2.035725,0.103705,2.226245,-1292.26062,0.223743,0
135.910004,0.399933,-1292.216064,-0.006441,0.008802,0.223571,1.77899,0.090626,2.235707,-1292.216064,0.224915,0
136.610001,0.44648,-1292.305054,-0.006407,0.008853,0.224855,1.986041,0.101174,2.248546,-1292.305054,0.226076,0
137.310013,0.436424,-1292.305054,-0.006359,0.008901,0.226094,1.941312,0.098895,2.260945,-1292.305054,0.227247,0
138.01001,0.394714,-1292.305054,-0.006312,0.008947,0.227256,1.755777,0.089444,2.272557,-1292.305054,0.228409,0
138.710007,0.464348,-1292.305054,-0.006256,0.008999,0.228583,2.065522,0.105223,2.285834,-1292.305054,0.22958,0
139.410004,0.433075,-1292.349609,-0.006209,0.009039,0.229598,1.926414,0.098136,2.295978,-1292.349609,0.230742,0
140.110001,0.3694,-1292.305054,-0.006174,0.009076,0.230533,1.643173,0.083707,2.305334,-1292.305054,0.231913,0
140.810013,0.482971,-1292.394043,-0.006109,0.009129,0.231878,2.148363,0.109443,2.318778,-1292.394043,0.233075,0
141.51001,0.421532,-1292.305054,-0.006062,0.00918,0.23318,1.875067,0.09552,2.331798,-1292.305054,0.234246,0
142.210007,0.383919,-1292.305054,-0.006036,0.009216,0.23409,1.707756,0.086997,2.340897,-1292.305054,0.235408,0
142.910004,0.476639,-1292.349609,-0.005971,0.009272,0.23552,2.120195,0.108008,2.355204,-1292.349609,0.236579,0
143.610001,0.468445,-1292.349609,-0.005941,0.009306,0.236362,2.083747,0.106151,2.363621,-1292.349609,0.237749,0
144.310013,0.472542,-1292.349609,-0.005872,0.009362,0.237793,2.101971,0.10708,2.377928,-1292.349609,0.238912,0
145.01001,0.472168,-1292.349609,-0.005851,0.009406,0.238903,2.100308,0.106995,2.389026,-1292.349609,0.240082,0
145.710007,0.452065,-1292.349609,-0.005777,0.00945,0.240021,2.010883,0.102439,2.400214,-1292.349609,0.241245,0
146.410004,0.472168,-1292.349609,-0.005734,0.009499,0.241279,2.100308,0.106995,2.412795,-1292.349609,0.242415,0
147.110001,0.491531,-1292.349609,-0.005678,0.009544,0.242406,2.186441,0.111383,2.424059,-1292.349609,0.243578,0
147.810013,0.451317,-1292.349609,-0.005648,0.009581,0.243369,2.007558,0.10227,2.433687,-1292.349609,0.244748,0
148.51001,0.509781,-1292.438477,-0.005596,0.00964,0.244852,2.267619,0.115518,2.448524,-1292.438477,0.245911,0
149.210007,0.501213,-1292.349609,-0.005575,0.009669,0.24559,2.229507,0.113577,2.455897,-1292.349609,0.247081,0
149.910004,0.449829,-1292.438477,-0.005514,0.009722,0.246942,2.00094,0.101933,2.469417,-1292.438477,0.248242,0
150.610001,0.502708,-1292.349609,-0.005437,0.009774,0.248251,2.236159,0.113915,2.482513,-1292.349609,0.249414,0
151.310013,0.452065,-1292.394043,-0.005402,0.009815,0.2493,2.010883,0.102439,2.493004,-1292.394043,0.250575,0
152.01001,0.477013,-1292.438477,-0.005364,0.009857,0.250377,2.121858,0.108093,2.503769,-1292.438477,0.251747,0
152.710007,0.473289,-1292.394043,-0.005307,0.009909,0.251686,2.105297,0.107249,2.516864,-1292.394043,0.252917,0
153.410004,0.442757,-1292.438477,-0.005277,0.009956,0.252882,1.96948,0.10033,2.528825,-1292.438477,0.25408,0
154.110001,0.440147,-1292.349609,-0.005213,0.009992,0.253785,1.957873,0.099739,2.537848,-1292.349609,0.25525,0
154.810013,0.453552,-1292.438477,-0.00517,0.010049,0.255232,2.017501,0.102776,2.552321,-1292.438477,0.256411,0
155.51001,0.439034,-1292.438477,-0.005131,0.010093,0.256351,1.952919,0.099486,2.563509,-1292.438477,0.257583,0
156.210007,0.475525,-1292.438477,-0.005079,0.010145,0.257695,2.11524,0.107755,2.576953,-1292.438477,0.258745,0
156.910004,0.4543,-1292.438477,-0.005027,0.01019,0.258814,2.020827,0.102946,2.588141,-1292.438477,0.259916,0
157.610001,0.417809,-1292.527466,-0.004963,0.010231,0.259863,1.858505,0.094677,2.598633,-1292.527466,0.261077,0
158.310013,0.443871,-1292.438477,-0.004919,0.010281,0.261147,1.974435,0.100583,2.611472,-1292.438477,0.262249,0
159.01001,0.422272,-1292.438477,-0.004881,0.010325,0.262249,1.878358,0.095688,2.622493,-1292.438477,0.263411,0
159.710007,0.387268,-1292.483032,-0.004855,0.010364,0.263245,1.722654,0.087756,2.632455,-1292.483032,0.264581,0
160.410004,0.425995,-1292.483032,-0.00479,0.01042,0.26466,1.89492,0.096532,2.646595,-1292.483032,0.265744,0
161.110001,0.376099,-1292.571899,-0.004743,0.010458,0.265622,1.67297,0.085225,2.656224,-1292.571899,0.266914,0
161.810013,0.418549,-1292.527466,-0.0047,0.010508,0.266906,1.861797,0.094844,2.669063,-1292.527466,0.268086,0
162.51001,0.425621,-1292.571899,-0.004644,0.010558,0.268172,1.893257,0.096447,2.681719,-1292.571899,0.269247,0
163.210007,0.414452,-1292.527466,-0.004605,0.0106,0.269238,1.843573,0.093916,2.692378,-1292.527466,0.270417,0
163.910004,0.48967,-1292.527466,-0.004562,0.010648,0.27047,2.17816,0.110961,2.704701,-1292.527466,0.27158,0
164.610001,0.47403,-1292.571899,-0.004518,0.010684,0.27138,2.108589,0.107417,2.7138,-1292.571899,0.27275,0
165.310013,0.4543,-1292.483032,-0.004449,0.01074,0.272794,2.020827,0.102946,2.72794,-1292.483032,0.273913,0
166.01001,0.49675,-1292.527466,-0.004393,0.010784,0.273904,2.209654,0.112565,2.739038,-1292.527466,0.275083,0
166.710007,0.477386,-1292.571899,-0.004372,0.01083,0.275092,2.123521,0.108177,2.750922,-1292.571899,0.276246,0
167.410004,0.447594,-1292.527466,-0.00432,0.010863,0.275916,1.990996,0.101426,2.759158,-1292.527466,0.277416,0
168.110001,0.49675,-1292.616455,-0.004277,0.010923,0.277434,2.209654,0.112565,2.774343,-1292.616455,0.278579,0
168.810013,0.453552,-1292.571899,-0.004225,0.010959,0.278362,2.017501,0.102776,2.783624,-1292.571899,0.279749,0
169.51001,0.497864,-1292.571899,-0.004174,0.011011,0.27967,2.214609,0.112818,2.796704,-1292.571899,0.280912,0
170.210007,0.51239,-1292.616455,-0.004126,0.011056,0.280816,2.279225,0.116109,2.808165,-1292.616455,0.282082,0
170.910004,0.447594,-1292.616455,-0.004079,0.0111,0.281952,1.990996,0.101426,2.81952,-1292.616455,0.283252,0
171.610001,0.480736,-1292.616455,-0.004036,0.011153,0.283287,2.13842,0.108936,2.832873,-1292.616455,0.284415,0
172.310013,0.483711,-1292.616455,-0.003997,0.011193,0.284311,2.151655,0.109611,2.843107,-1292.616455,0.285585,0
173.01001,0.46212,-1292.616455,-0.003949,0.011238,0.285446,2.055613,0.104718,2.854462,-1292.616455,0.286748,0
173.710007,0.464348,-1292.616455,-0.003893,0.011293,0.286844,2.065522,0.105223,2.868436,-1292.616455,0.287918,0
174.410004,0.473289,-1292.527466,-0.00385,0.011337,0.287953,2.105297,0.107249,2.879533,-1292.527466,0.289081,0
175.110016,0.43605,-1292.660889,-0.003824,0.011375,0.288924,1.939649,0.09881,2.889237,-1292.660889,0.290251,0
175.810013,0.457649,-1292.616455,-0.003751,0.01143,0.290312,2.035725,0.103705,2.903121,-1292.616455,0.291413,0
176.51001,0.426743,-1292.705444,-0.003717,0.011469,0.29131,1.898246,0.096701,2.913097,-1292.705444,0.292584,0
177.210007,0.440521,-1292.660889,-0.003669,0.01151,0.292359,1.959536,0.099824,2.923589,-1292.660889,0.293746,0
177.910004,0.44722,-1292.705444,-0.003604,0.011564,0.293738,1.989333,0.101341,2.937381,-1292.705444,0.294917,0
178.610016,0.390625,-1292.705444,-0.00357,0.011616,0.295048,1.737587,0.088517,2.950477,-1292.705444,0.296079,0
179.310013,0.431213,-1292.705444,-0.003531,0.01166,0.296174,1.918133,0.097714,2.961741,-1292.705444,0.297251,0
180.01001,0.465096,-1292.660889,-0.003454,0.011703,0.297258,2.068848,0.105392,2.972581,-1292.660889,0.298421,0
180.710007,0.374985,-1292.705444,-0.003428,0.011746,0.29836,1.668015,0.084973,2.983603,-1292.705444,0.299582,0
181.410004,0.451691,-1292.705444,-0.003376,0.011801,0.299739,2.00922,0.102355,2.997395,-1292.705444,0.300754,0
182.110016,0.441261,-1292.705444,-0.003328,0.011837,0.300658,1.962828,0.099991,3.006584,-1292.705444,0.301915,0
182.810013,0.382057,-1292.705444,-0.003303,0.011879,0.301717,1.699475,0.086575,3.017167,-1292.705444,0.303087,0
183.51001,0.459885,-1292.705444,-0.003234,0.011933,0.303087,2.045669,0.104211,3.030868,-1292.705444,0.304248,0
184.210007,0.410355,-1292.705444,-0.003191,0.011982,0.304334,1.825348,0.092988,3.043343,-1292.705444,0.30542,0
184.910004,0.41967,-1292.749878,-0.003139,0.012021,0.305332,1.866786,0.095099,3.05332,-1292.749878,0.306581,0
185.610016,0.491165,-1292.794312,-0.003078,0.012072,0.306625,2.184812,0.1113,3.066249,-1292.794312,0.307751,0
186.310013,0.454666,-1292.705444,-0.003048,0.012113,0.307665,2.022456,0.103029,3.07665,-1292.705444,0.308914,0
187.01001,0.48185,-1292.749878,-0.002997,0.012164,0.308958,2.143374,0.109189,3.08958,-1292.749878,0.310084,0
187.710007,0.485947,-1292.749878,-0.002953,0.01221,0.310145,2.161599,0.110117,3.101449,-1292.749878,0.311247,0
188.410004,0.450943,-1292.660889,-0.00291,0.01225,0.311161,2.005895,0.102185,3.111608,-1292.660889,0.312417,0
189.110016,0.526535,-1292.749878,-0.002859,0.012303,0.312496,2.342145,0.119315,3.124961,-1292.749878,0.313588,0
189.810013,0.522438,-1292.794312,-0.002824,0.012344,0.313545,2.32392,0.118386,3.135453,-1292.794312,0.31475,0
190.51001,0.47776,-1292.705444,-0.002777,0.012385,0.314569,2.125184,0.108262,3.145687,-1292.705444,0.315921,0
191.210007,0.554466,-1292.705444,-0.002712,0.01244,0.315965,2.466389,0.125644,3.159646,-1292.705444,0.317083,0
191.910004,0.56601,-1292.749878,-0.00266,0.012481,0.317023,2.517736,0.12826,3.170228,-1292.749878,0.318254,0
192.610016,0.530258,-1292.616455,-0.002617,0.012529,0.318228,2.358706,0.120158,3.182279,-1292.616455,0.319416,0
193.310013,0.581276,-1292.705444,-0.002574,0.012576,0.319433,2.585644,0.131719,3.19433,-1292.705444,0.320587,0
194.01001,0.598404,-1292.749878,-0.002544,0.012614,0.320396,2.661834,0.1356,3.203959,-1292.749878,0.321749,0
194.710007,0.786079,-1292.749878,-0.002496,0.012663,0.321628,3.496656,0.178128,3.216283,-1292.749878,0.32292,0
195.410004,1.261971,-1292.660889,-0.002432,0.012712,0.322885,5.613525,0.285967,3.228848,-1292.660889,0.324082,0
196.110016,1.804146,-1292.660889,-0.002393,0.012754,0.323952,8.025242,0.408825,3.239522,-1292.660889,0.325253,0
196.810013,2.716461,-1292.705444,-0.002358,0.012805,0.325235,12.083423,0.615559,3.252345,-1292.705444,0.326414,0
197.51001,3.608665,-1292.794312,-0.00232,0.012848,0.326346,16.052145,0.817735,3.263458,-1292.794312,0.327586,0
198.210007,4.590981,-1292.749878,-0.002281,0.012896,0.32756,20.421701,1.040331,3.275599,-1292.749878,0.328756,0
198.910004,5.75502,-1292.749878,-0.002238,0.012946,0.328817,25.599607,1.304106,3.288165,-1292.749878,0.329919,0
199.610016,6.604774,-1292.794312,-0.002199,0.012994,0.33004,29.379503,1.496663,3.300398,-1292.794312,0.331089,0
200.310013,7.170036,-1292.794312,-0.002156,0.013029,0.330933,31.893915,1.624753,3.30933,-1292.794312,0.332252,0
201.01001,8.347847,-1292.794312,-0.002113,0.013085,0.332364,37.13308,1.891649,3.323637,-1292.794312,0.333422,0
201.710007,8.799911,-1292.749878,-0.002082,0.013124,0.333352,39.143963,1.994088,3.333524,-1292.749878,0.334583,0
202.410004,9.562531,-1292.749878,-0.002031,0.01317,0.334523,42.536259,2.1669,3.345227,-1292.749878,0.335755,0
203.110016,10.338181,-1292.749878,-0.001975,0.013219,0.335763,45.986523,2.342665,3.357626,-1292.749878,0.336916,0
203.810013,10.654694,-1292.838867,-0.00194,0.013255,0.336665,47.394444,2.414388,3.366649,-1292.838867,0.338088,0
204.51001,11.844795,-1292.749878,-0.001906,0.013311,0.338088,52.688282,2.684069,3.38088,-1292.749878,0.339249,0
205.210007,12.176582,-1292.794312,-0.001854,0.013355,0.339207,54.164143,2.759253,3.392068,-1292.794312,0.340421,0
205.910004,12.511719,-1292.838867,-0.001807,0.013398,0.340298,55.654903,2.835196,3.402984,-1292.838867,0.341582,0
206.610016,13.785233,-1292.838867,-0.001755,0.013452,0.341678,61.319778,3.123778,3.416776,-1292.838867,0.342753,0
207.310013,13.581543,-1292.838867,-0.001712,0.013485,0.342527,60.413719,3.077622,3.425269,-1292.838867,0.343924,0
208.01001,15.098587,-1292.838867,-0.001673,0.01354,0.343906,67.161873,3.421389,3.439062,-1292.838867,0.345086,0
208.710007,15.276215,-1292.838867,-0.001643,0.013583,0.345008,67.951996,3.46164,3.450083,-1292.838867,0.346257,0
209.410004,16.109581,-1292.794312,-0.001582,0.013628,0.346144,71.658997,3.650483,3.461438,-1292.794312,0.347419,0
210.110016,16.539299,-1292.838867,-0.001556,0.013665,0.347081,73.570473,3.747859,3.470809,-1292.838867,0.348589,0
210.810013,18.27977,-1292.838867,-0.001505,0.013727,0.348677,81.312477,4.142255,3.486766,-1292.838867,0.349752,0
211.51001,18.218323,-1292.883301,-0.001462,0.013765,0.34964,81.039146,4.128331,3.496395,-1292.883301,0.350922,0
212.210007,19.562218,-1292.883301,-0.00144,0.013808,0.350714,87.01709,4.432862,3.507144,-1292.883301,0.352085,0
212.910004,20.394096,-1292.838867,-0.001393,0.013854,0.351903,90.717468,4.621368,3.519029,-1292.838867,0.353255,0
213.610016,21.451263,-1292.794312,-0.001345,0.013898,0.353022,95.419983,4.860926,3.530217,-1292.794312,0.354418,0
214.310013,23.295998,-1292.794312,-0.001298,0.013956,0.354495,103.625771,5.278948,3.544948,-1292.794312,0.355588,0
215.01001,23.405472,-1292.838867,-0.001263,0.013993,0.355432,104.11274,5.303756,3.554319,-1292.838867,0.356751,0
215.710007,25.247971,-1292.883301,-0.001242,0.014041,0.356629,112.308578,5.721272,3.566295,-1292.883301,0.357921,0
216.410004,27.111694,-1292.838867,-0.001199,0.014092,0.357938,120.598839,6.143598,3.579375,-1292.838867,0.359084,0
217.110016,28.186363,-1292.883301,-0.001164,0.014137,0.359075,125.379204,6.387121,3.590745,-1292.883301,0.360254,0
217.810013,29.274437,-1292.838867,-0.001134,0.014177,0.360107,130.219193,6.633682,3.60107,-1292.838867,0.361424,0
218.51001,31.56192,-1292.883301,-0.001091,0.014229,0.361407,140.39444,7.152033,3.614075,-1292.883301,0.362587,0
219.210007,33.100937,-1292.883301,-0.001056,0.014273,0.362543,147.240326,7.50078,3.62543,-1292.883301,0.363757,0
219.910004,34.209488,-1292.883301,-0.00103,0.014312,0.363515,152.171402,7.751981,3.635149,-1292.883301,0.36492,0
220.610016,37.501633,-1292.838867,-0.001018,0.01437,0.365006,166.815598,8.497992,3.650062,-1292.838867,0.36609,0
221.310013,39.251411,-1292.838867,-0.000966,0.014415,0.366142,174.598999,8.894498,3.661417,-1292.838867,0.367253,0
222.01001,41.371704,-1292.883301,-0.00094,0.014462,0.367339,184.030533,9.374963,3.673392,-1292.883301,0.368423,0
222.710007,43.177338,-1292.838867,-0.000905,0.014502,0.368344,192.062393,9.784124,3.683445,-1292.838867,0.369584,0
223.410004,45.207138,-1292.927856,-0.000884,0.014548,0.369507,201.0914,10.244084,3.695072,-1292.927856,0.370756,0
224.110016,48.892509,-1292.838867,-0.000858,0.0146,0.370842,217.484741,11.079201,3.708425,-1292.838867,0.371917,0
224.810013,50.430031,-1292.927856,-0.000845,0.014637,0.371787,224.323975,11.427608,3.717872,-1292.927856,0.373089,0
225.51001,52.80912,-1292.883301,-0.000815,0.014676,0.372776,234.906693,11.966718,3.727758,-1292.883301,0.37425,0
226.210007,56.60434,-1292.883301,-0.000798,0.014729,0.37412,251.788681,12.826727,3.741202,-1292.883301,0.375422,0
226.910004,59.598213,-1292.838867,-0.000776,0.014777,0.375343,265.106079,13.505148,3.753435,-1292.838867,0.376592,0
227.610016,62.890732,-1292.883301,-0.000759,0.014824,0.376523,279.751953,14.251244,3.765229,-1292.883301,0.377754,0
228.310013,66.011955,-1292.883301,-0.000733,0.014858,0.377399,293.635834,14.958523,3.773994,-1292.883301,0.377625,0
229.01001,65.111565,-1292.883301,-0.00072,0.01487,0.377693,289.630707,14.754492,3.776932,-1292.883301,294.500488,0
229.710007,64.867287,-1292.927856,-0.00072,0.014878,0.377911,288.544098,14.699137,3.779112,-1292.927856,294.500488,0
230.410004,65.128685,-1292.927856,-0.00069,0.014887,0.378128,289.706848,14.758371,3.781277,-1292.927856,294.500488,0
231.110016,64.564171,-1292.927856,-0.000698,0.014887,0.378135,287.19577,14.63045,3.781352,-1292.927856,294.500488,0
231.810013,64.11956,-1292.883301,-0.00069,0.014888,0.378144,285.218048,14.5297,3.781443,-1292.883301,294.500488,0
232.51001,66.178413,-1292.97229,-0.000673,0.014861,0.377477,294.376282,14.996243,3.774767,-1292.97229,294.500488,0
233.210007,65.768059,-1292.927856,-0.000694,0.014862,0.377502,292.550934,14.903255,3.775024,-1292.927856,294.500488,0
233.910004,65.35099,-1292.927856,-0.00066,0.014871,0.377728,290.695709,14.808746,3.77728,-1292.927856,294.500488,0
234.610016,65.051231,-1293.016724,-0.000673,0.01488,0.377954,289.362335,14.74082,3.779536,-1293.016724,294.500488,0
235.310013,64.962242,-1292.927856,-0.000664,0.014899,0.37843,288.966492,14.720654,3.784305,-1292.927856,294.500488,0
236.01001,64.888512,-1292.97229,-0.000664,0.014902,0.378509,288.638519,14.703947,3.785092,-1292.97229,294.500488,0
236.710007,65.295509,-1292.97229,-0.000655,0.01491,0.378709,290.448944,14.796174,3.78709,-1292.97229,294.500488,0
237.410004,65.208748,-1292.927856,-0.000651,0.01491,0.378709,290.062988,14.776513,3.78709,-1292.927856,294.500488,0
238.110016,65.048637,-1293.016724,-0.000681,0.01491,0.378709,289.3508,14.740232,3.78709,-1293.016724,294.500488,0
238.810013,64.924629,-1292.97229,-0.000664,0.01491,0.378709,288.799164,14.712132,3.78709,-1292.97229,294.500488,0
239.51001,64.780144,-1293.016724,-0.000677,0.01491,0.378717,288.156464,14.67939,3.787166,-1293.016724,294.500488,0
240.210007,65.06501,-1293.016724,-0.000664,0.014916,0.378865,289.423615,14.743942,3.78865,-1293.016724,294.500488,0
240.910019,65.018471,-1293.016724,-0.000655,0.014916,0.378865,289.216614,14.733397,3.78865,-1293.016724,294.500488,0
241.610016,64.949211,-1293.016724,-0.00066,0.014916,0.378865,288.908508,14.717702,3.78865,-1293.016724,294.500488,0
242.310013,64.824471,-1293.016724,-0.000677,0.014916,0.378865,288.353638,14.689435,3.78865,-1293.016724,294.500488,0
243.01001,65.213966,-1292.97229,-0.000651,0.014922,0.379012,290.086212,14.777697,3.790118,-1292.97229,294.500488,0
243.710007,65.164818,-1293.016724,-0.00066,0.014922,0.379012,289.867584,14.766559,3.790118,-1293.016724,294.500488,0
244.410019,65.087364,-1292.97229,-0.000664,0.014922,0.379012,289.523041,14.749007,3.790118,-1292.97229,294.500488,0
245.110016,65.015862,-1293.061279,-0.000651,0.014922,0.379012,289.204987,14.732804,3.790118,-1293.061279,294.500488,0
245.810013,64.940636,-1293.016724,-0.00066,0.014922,0.379012,288.870361,14.715758,3.790118,-1293.016724,294.500488,0
246.51001,64.883675,-1293.016724,-0.000655,0.014923,0.379047,288.617004,14.702851,3.790466,-1293.016724,294.500488,0
247.210007,64.850151,-1293.105713,-0.000655,0.014923,0.379056,288.467865,14.695254,3.790557,-1293.105713,294.500488,0
247.910019,65.054588,-1293.105713,-0.00066,0.014927,0.379151,289.377258,14.741581,3.791511,-1293.105713,294.500488,0
248.610016,65.059425,-1293.150269,-0.000655,0.014927,0.379151,289.398773,14.742677,3.791511,-1293.150269,294.500488,0
249.310013,65.021828,-1293.061279,-0.000629,0.014927,0.379151,289.231537,14.734157,3.791511,-1293.061279,294.500488,0
250.01001,64.981606,-1293.150269,-0.000668,0.014927,0.379151,289.052612,14.725042,3.791511,-1293.150269,294.500488,0
250.710007,65.048637,-1293.061279,-0.000651,0.01493,0.379212,289.3508,14.740232,3.792117,-1293.061279,294.500488,0
251.410019,65.02964,-1293.016724,-0.000664,0.01493,0.379212,289.266296,14.735928,3.792117,-1293.016724,294.500488,0
252.110016,64.996132,-1293.061279,-0.000651,0.01493,0.379212,289.117249,14.728334,3.792117,-1293.061279,294.500488,0
252.810013,64.961494,-1293.194702,-0.000651,0.01493,0.379212,288.963165,14.720485,3.792117,-1293.194702,294.500488,0
253.51001,65.28286,-1293.105713,-0.000651,0.014935,0.379342,290.39267,14.793307,3.793419,-1293.105713,294.500488,0
254.210007,65.294029,-1293.016724,-0.000647,0.014935,0.379342,290.442352,14.795838,3.793419,-1293.016724,294.500488,0
254.910019,65.276527,-1293.105713,-0.000642,0.014935,0.379342,290.364502,14.791872,3.793419,-1293.105713,294.500488,0
255.610016,65.24041,-1293.150269,-0.000655,0.014935,0.379342,290.203827,14.783688,3.793419,-1293.150269,294.500488,0
256.309998,65.203911,-1293.150269,-0.000651,0.014935,0.379342,290.041473,14.775417,3.793419,-1293.150269,294.500488,0
257.01001,65.13726,-1293.105713,-0.000651,0.014935,0.379342,289.744995,14.760314,3.793419,-1293.105713,294.500488,0
257.710022,65.109322,-1293.150269,-0.00066,0.014935,0.379342,289.620728,14.753983,3.793419,-1293.150269,294.500488,0
258.410004,65.050499,-1293.194702,-0.000642,0.014935,0.379342,289.35907,14.740654,3.793419,-1293.194702,294.500488,0
259.110016,65.020699,-1293.194702,-0.000634,0.014935,0.379342,289.226501,14.733901,3.793419,-1293.194702,294.500488,0
259.809998,65.062782,-1293.105713,-0.000634,0.014938,0.379428,289.413696,14.743437,3.794281,-1293.105713,294.500488,0
260.51001,65.145821,-1293.150269,-0.000655,0.014938,0.379428,289.783081,14.762254,3.794281,-1293.150269,294.500488,0
261.210022,65.126091,-1293.150269,-0.000647,0.014938,0.379428,289.695312,14.757783,3.794281,-1293.150269,294.500488,0
261.910004,65.107841,-1293.150269,-0.000642,0.014938,0.379428,289.614136,14.753648,3.794281,-1293.150269,294.500488,0
262.610016,65.098152,-1293.239136,-0.000647,0.014938,0.379428,289.571045,14.751452,3.794281,-1293.239136,294.500488,0
263.309998,65.052727,-1293.283691,-0.000651,0.014938,0.379428,289.368988,14.741158,3.794281,-1293.283691,294.500488,0
264.01001,65.039314,-1293.194702,-0.000655,0.014938,0.379428,289.309326,14.738119,3.794281,-1293.194702,294.500488,0
264.710022,65.007668,-1293.283691,-0.000647,0.014938,0.379428,289.168549,14.730948,3.794281,-1293.283691,294.500488,0
265.410004,65.054222,-1293.194702,-0.000647,0.01494,0.37948,289.375641,14.741497,3.794796,-1293.194702,294.500488,0
266.110016,65.065392,-1293.239136,-0.000647,0.01494,0.37948,289.425323,14.744028,3.794796,-1293.239136,294.500488,0
266.809998,65.058311,-1293.194702,-0.000642,0.01494,0.37948,289.393829,14.742424,3.794796,-1293.194702,294.500488,0
267.51001,65.030754,-1293.239136,-0.000638,0.01494,0.37948,289.27124,14.73618,3.794796,-1293.239136,294.500488,0
268.210022,65.024803,-1293.194702,-0.000638,0.01494,0.37948,289.244781,14.734831,3.794796,-1293.194702,294.500488,0
268.910004,65.156242,-1293.239136,-0.000634,0.014944,0.379567,289.829437,14.764615,3.795674,-1293.239136,294.500488,0
269.610016,65.202415,-1293.194702,-0.000638,0.014944,0.379567,290.034821,14.775078,3.795674,-1293.194702,294.500488,0
270.310028,65.205772,-1293.283691,-0.000655,0.014944,0.379567,290.049774,14.775839,3.795674,-1293.283691,294.500488,0
271.01001,65.181938,-1293.239136,-0.000651,0.014944,0.379567,289.943756,14.770438,3.795674,-1293.239136,294.500488,0
271.710022,65.161461,-1293.150269,-0.000647,0.014944,0.379567,289.852661,14.765799,3.795674,-1293.150269,294.500488,0
272.410004,65.135765,-1293.194702,-0.000651,0.014944,0.379567,289.738342,14.759975,3.795674,-1293.194702,294.500488,0
273.110016,65.101875,-1293.194702,-0.000634,0.014944,0.379567,289.587616,14.752295,3.795674,-1293.194702,294.500488,0
273.810028,65.07917,-1293.239136,-0.000634,0.014944,0.379567,289.486603,14.747151,3.795674,-1293.239136,294.500488,0
274.51001,65.054222,-1293.194702,-0.000651,0.014944,0.379567,289.375641,14.741497,3.795674,-1293.194702,294.500488,0
275.210022,65.034111,-1293.194702,-0.000647,0.014944,0.379567,289.286163,14.73694,3.795674,-1293.194702,294.500488,0
275.910004,65.014,-1293.239136,-0.000638,0.014944,0.379567,289.196716,14.732384,3.795674,-1293.239136,294.500488,0
276.610016,64.989052,-1293.150269,-0.000647,0.014944,0.379567,289.085754,14.726729,3.795674,-1293.150269,294.500488,0
277.310028,64.958519,-1293.283691,-0.000634,0.014944,0.379567,288.949921,14.71981,3.795674,-1293.283691,294.500488,0
278.01001,64.941765,-1293.194702,-0.000638,0.014944,0.379567,288.875397,14.716014,3.795674,-1293.194702,294.500488,0
278.710022,64.891869,-1293.283691,-0.000651,0.014944,0.379567,288.653442,14.704707,3.795674,-1293.283691,294.500488,0
279.410004,65.235191,-1293.239136,-0.000642,0.014949,0.379705,290.180634,14.782506,3.797052,-1293.239136,294.500488,0
280.110016,65.254173,-1293.194702,-0.000642,0.014949,0.379705,290.265045,14.786807,3.797052,-1293.194702,294.500488,0
280.810028,65.255302,-1293.283691,-0.000642,0.014949,0.379705,290.270081,14.787063,3.797052,-1293.283691,294.500488,0
281.51001,65.264977,-1293.194702,-0.000647,0.014949,0.379705,290.31311,14.789255,3.797052,-1293.194702,294.500488,0
282.210022,65.234444,-1293.283691,-0.000642,0.014949,0.379705,290.177307,14.782336,3.797052,-1293.283691,294.500488,0
282.910004,65.237053,-1293.283691,-0.000638,0.014949,0.379705,290.188904,14.782928,3.797052,-1293.283691,294.500488,0
283.610016,65.202049,-1293.194702,-0.000638,0.014949,0.379705,290.033203,14.774996,3.797052,-1293.194702,294.500488,0
284.310028,65.165932,-1293.328125,-0.000629,0.014949,0.379705,289.872528,14.766811,3.797052,-1293.328125,294.500488,0
285.01001,65.14135,-1293.283691,-0.000655,0.014949,0.379705,289.763184,14.761241,3.797052,-1293.283691,294.500488,0
285.710022,65.096672,-1293.283691,-0.000638,0.014949,0.379705,289.564453,14.751117,3.797052,-1293.283691,294.500488,0
286.410004,65.077309,-1293.239136,-0.000634,0.014949,0.379705,289.478333,14.746729,3.797052,-1293.239136,294.500488,0
287.110016,65.056816,-1293.328125,-0.000647,0.014949,0.379705,289.387177,14.742085,3.797052,-1293.328125,294.500488,0
287.810028,65.037453,-1293.283691,-0.000647,0.014949,0.379705,289.301025,14.737697,3.797052,-1293.283691,294.500488,0
288.51001,65.021446,-1293.239136,-0.000642,0.014949,0.379705,289.229828,14.73407,3.797052,-1293.239136,294.500488,0
289.210022,64.978996,-1293.194702,-0.000638,0.014942,0.379533,289.041016,14.72445,3.795326,-1293.194702,0.379402,0
289.910004,64.881813,-1293.283691,-0.000621,0.014908,0.378674,288.608704,14.702429,3.786742,-1293.283691,0.378231,0
290.610016,64.79319,-1293.283691,-0.000625,0.014866,0.37759,288.214508,14.682346,3.775902,-1293.283691,0.37706,0
291.310028,64.778282,-1293.328125,-0.000608,0.014823,0.376506,288.148193,14.678968,3.765062,-1293.328125,0.375899,0
292.01001,64.736961,-1293.328125,-0.000617,0.014781,0.375439,287.964386,14.669605,3.754389,-1293.328125,0.374727,0
292.710022,64.668068,-1293.283691,-0.000621,0.014733,0.374208,287.657928,14.653994,3.74208,-1293.283691,0.373566,0
293.410004,64.136314,-1293.239136,-0.000612,0.014692,0.373185,285.292572,14.533496,3.731846,-1293.239136,0.372394,0
294.110016,62.214874,-1293.328125,-0.000599,0.014648,0.372048,276.745575,14.098092,3.720476,-1293.328125,0.371233,0
294.810028,59.695404,-1293.239136,-0.000586,0.014606,0.370989,265.538422,13.527172,3.709893,-1293.239136,0.370063,0
295.51001,56.384644,-1293.372559,-0.000586,0.014566,0.369967,250.811417,12.776943,3.699674,-1293.372559,0.3689,0
296.210022,51.773178,-1293.372559,-0.000586,0.014516,0.368718,230.298599,11.73197,3.687184,-1293.372559,0.36773,0
296.910004,46.98484,-1293.283691,-0.000595,0.014472,0.367591,208.999008,10.646917,3.675905,-1293.283691,0.366567,0
297.610016,41.770508,-1293.283691,-0.000586,0.014427,0.366437,185.804504,9.465333,3.664369,-1293.283691,0.365397,0
298.310028,36.754654,-1293.328125,-0.000595,0.01438,0.365248,163.492859,8.328724,3.652484,-1293.328125,0.364234,0
299.01001,31.740662,-1293.328125,-0.000595,0.014332,0.364043,141.189514,7.192536,3.640433,-1293.328125,0.363064,0
299.710022,26.955299,-1293.372559,-0.000582,0.014291,0.363003,119.90316,6.108158,3.630032,-1293.372559,0.361893,0
300.410004,21.653091,-1293.372559,-0.000582,0.014242,0.361745,96.317764,4.906661,3.617451,-1293.372559,0.360731,0
301.110016,16.912415,-1293.328125,-0.000591,0.014201,0.360705,75.230179,3.832408,3.60705,-1293.328125,0.35956,0
301.810028,11.974014,-1293.372559,-0.000586,0.014155,0.359526,53.263077,2.71335,3.595257,-1293.372559,0.358398,0
302.51001,6.187347,-1293.461548,-0.000608,0.014105,0.358258,27.522696,1.402073,3.582585,-1293.461548,0.357227,0
303.210022,1.300697,-1293.461548,-0.000595,0.014058,0.357079,5.78579,0.294742,3.570791,-1293.461548,0.356065,0
303.910004,-3.469391,-1293.372559,-0.000595,0.01401,0.355865,-15.432621,-0.786175,3.558649,-1293.372559,0.354894,0
304.610016,0.372375,-1293.417114,-0.000686,0.013969,0.354825,1.656409,0.084381,3.548248,-1293.417114,0.353732,0
305.310028,0.363068,-1293.372559,-0.00072,0.013931,0.353854,1.615005,0.082272,3.538544,-1293.372559,0.352561,0
306.01001,0.389503,-1293.372559,-0.000798,0.013879,0.352518,1.732598,0.088263,3.525176,-1293.372559,0.351399,0
306.710022,0.392487,-1293.461548,-0.000841,0.013835,0.351399,1.745867,0.088939,3.513987,-1293.461548,0.350228,0
307.410004,0.425255,-1293.461548,-0.000888,0.013788,0.350219,1.891628,0.096364,3.502194,-1293.461548,0.349067,0
308.110016,0.418549,-1293.417114,-0.000966,0.013734,0.348842,1.861797,0.094844,3.488417,-1293.417114,0.347895,0
308.810028,0.426743,-1293.461548,-0.001,0.013693,0.347792,1.898246,0.096701,3.477925,-1293.461548,0.346725,0
309.51001,0.394714,-1293.372559,-0.001052,0.013645,0.346595,1.755777,0.089444,3.46595,-1293.372559,0.345562,0
310.210022,0.431953,-1293.461548,-0.001095,0.013602,0.345502,1.921425,0.097882,3.455019,-1293.461548,0.344392,0
310.910004,0.417061,-1293.461548,-0.001151,0.01356,0.344427,1.855179,0.094507,3.44427,-1293.461548,0.343229,0
311.610016,0.398445,-1293.506104,-0.001181,0.01351,0.343152,1.772372,0.090289,3.431522,-1293.506104,0.342059,0
312.100006,0.452805,-1293.372559,-0.00122,0.013479,0.342371,2.014175,0.102607,3.42371,-1293.372559,0.342259,0