File: Data/compression 21/AutoNoHeating-10-21-reverse-1-1re_09132024_162523.csv
Time (sec),S:Load (lbs),S:HL1 (DIM),S:LVDT (in),S:Position (in),Ch:Position (mm),Ch:Load (N),Ch:Stress (MPa),Ch:Strain (mm/mm),Ch:HL1 (DIM),Set Point (),Cycles ()
0.110000,0.075966,-184.551468,-0.009438,-0.009280,-0.235704,0.337913,0.017214,-2.357036,-184.551468,-0.235452,0.000000
0.550000,-0.003349,-184.640427,-0.009438,-0.009208,-0.233873,-0.014898,-0.000759,-2.338732,-184.640427,-0.233162,0.000000
0.990000,0.008194,-184.729385,-0.009270,-0.008943,-0.227144,0.036449,0.001857,-2.271437,-184.729385,-0.225826,0.000000
1.430000,-0.017128,-184.729385,-0.008994,-0.008648,-0.219668,-0.076189,-0.003881,-2.196685,-184.729385,-0.218507,0.000000
1.870000,0.022339,-184.862839,-0.008670,-0.008358,-0.212305,0.099368,0.005062,-2.123054,-184.862839,-0.211169,0.000000
2.310000,0.032394,-184.818344,-0.008395,-0.008076,-0.205134,0.144098,0.007341,-2.051337,-184.818344,-0.203832,0.000000
2.750000,0.020477,-184.907318,-0.008093,-0.007788,-0.197805,0.091088,0.004640,-1.978054,-184.907318,-0.196513,0.000000
3.190000,-0.023087,-184.996277,-0.007778,-0.007494,-0.190339,-0.102694,-0.005231,-1.903386,-184.996277,-0.189177,0.000000
3.630000,-0.030159,-184.996277,-0.007502,-0.007209,-0.183097,-0.134154,-0.006834,-1.830973,-184.996277,-0.181840,0.000000
4.070000,0.042076,-185.129715,-0.007200,-0.006922,-0.175821,0.187164,0.009535,-1.758212,-185.129715,-0.174521,0.000000
4.510000,0.059952,-185.085236,-0.006911,-0.006634,-0.168510,0.266679,0.013585,-1.685103,-185.085236,-0.167184,0.000000
4.950000,-0.007072,-185.174194,-0.006614,-0.006345,-0.161165,-0.031460,-0.001603,-1.611654,-185.174194,-0.159864,0.000000
5.390000,-0.004471,-185.263168,-0.006312,-0.006055,-0.153802,-0.019887,-0.001013,-1.538022,-185.263168,-0.152527,0.000000
5.830000,0.010796,-185.307648,-0.006023,-0.005769,-0.146535,0.048021,0.002446,-1.465352,-185.307648,-0.145191,0.000000
6.270000,0.049522,-185.396606,-0.005717,-0.005472,-0.138999,0.220287,0.011222,-1.389988,-185.396606,-0.137872,0.000000
6.710001,0.063301,-185.396606,-0.005420,-0.005184,-0.131662,0.281577,0.014344,-1.316621,-185.396606,-0.130535,0.000000
7.150001,0.088997,-185.396606,-0.005346,0.000004,0.000113,0.395878,0.020167,0.001128,-185.396606,0.000269,0.000000
7.590000,0.098679,-185.530045,-0.005338,0.000004,0.000113,0.438944,0.022361,0.001128,-185.530045,0.000711,0.000000
8.030001,0.097191,-185.530045,-0.005359,0.000006,0.000148,0.432327,0.022024,0.001476,-185.530045,0.001448,0.000000
8.470000,0.126236,-185.619003,-0.005325,0.000043,0.001101,0.561526,0.028605,0.011014,-185.619003,0.002176,0.000000
8.910001,0.159378,-185.619003,-0.005295,0.000063,0.001604,0.708949,0.036116,0.016040,-185.619003,0.002914,0.000000
9.350000,0.230125,-185.752457,-0.005277,0.000101,0.002575,1.023649,0.052147,0.025752,-185.752457,0.003642,0.000000
9.790001,0.331787,-185.752457,-0.005234,0.000132,0.003347,1.475863,0.075184,0.033474,-185.752457,0.004379,0.000000
10.230000,0.474403,-185.796936,-0.005208,0.000162,0.004119,2.110252,0.107501,0.041195,-185.796936,0.005108,0.000000
10.670000,0.550735,-185.885895,-0.005191,0.000185,0.004692,2.449794,0.124798,0.046918,-185.885895,0.005845,0.000000
11.110001,0.671013,-185.974854,-0.005157,0.000208,0.005281,2.984814,0.152054,0.052814,-185.974854,0.006582,0.000000
11.550000,0.904861,-185.930374,-0.005126,0.000246,0.006253,4.025025,0.205045,0.062526,-185.930374,0.007311,0.000000
11.990001,1.000938,-186.063812,-0.005113,0.000271,0.006885,4.452396,0.226816,0.068855,-186.063812,0.008047,0.000000
12.430000,1.221008,-186.108292,-0.005070,0.000304,0.007726,5.431316,0.276684,0.077265,-186.108292,0.008776,0.000000
12.870001,1.423210,-186.152786,-0.005036,0.000332,0.008438,6.330755,0.322504,0.084380,-186.152786,0.009513,0.000000
13.310000,1.603806,-186.197266,-0.005023,0.000355,0.009010,7.134083,0.363428,0.090103,-186.197266,0.010242,0.000000
13.750001,1.897606,-186.197266,-0.004988,0.000398,0.010103,8.440972,0.430004,0.101034,-186.197266,0.010979,0.000000
14.190001,1.940063,-186.330704,-0.004954,0.000423,0.010745,8.629833,0.439625,0.107446,-186.330704,0.011707,0.000000
14.630001,2.100555,-186.330704,-0.004924,0.000445,0.011309,9.343738,0.475993,0.113085,-186.330704,0.012445,0.000000
15.070001,2.383553,-186.375183,-0.004907,0.000478,0.012132,10.602571,0.540121,0.121321,-186.375183,0.013182,0.000000
15.510001,2.548141,-186.508621,-0.004894,0.000508,0.012904,11.334700,0.577417,0.129042,-186.508621,0.013910,0.000000
15.950001,2.768585,-186.464142,-0.004846,0.000539,0.013702,12.315282,0.627370,0.137021,-186.464142,0.014648,0.000000
16.390001,2.935783,-186.597595,-0.004816,0.000567,0.014413,13.059017,0.665258,0.144129,-186.597595,0.015376,0.000000
16.830000,3.178200,-186.508621,-0.004777,0.000596,0.015142,14.137339,0.720190,0.151419,-186.508621,0.016113,0.000000
17.270000,3.388962,-186.686554,-0.004773,0.000621,0.015775,15.074855,0.767950,0.157747,-186.686554,0.016841,0.000000
17.710001,3.530464,-186.731033,-0.004725,0.000650,0.016512,15.704289,0.800015,0.165120,-186.731033,0.017579,0.000000
18.150002,3.704361,-186.686554,-0.004700,0.000683,0.017353,16.477821,0.839420,0.173530,-186.686554,0.018316,0.000000
18.590000,3.835434,-186.731033,-0.004682,0.000709,0.018021,17.060862,0.869122,0.180206,-186.731033,0.019044,0.000000
19.030001,4.086044,-186.775513,-0.004652,0.000738,0.018741,18.175632,0.925911,0.187405,-186.775513,0.019781,0.000000
19.470001,4.249146,-186.908951,-0.004622,0.000763,0.019391,18.901144,0.962870,0.193908,-186.908951,0.020510,0.000000
19.910002,4.536987,-186.997925,-0.004583,0.000801,0.020345,20.181528,1.028096,0.203453,-186.997925,0.021247,0.000000
20.350000,4.529541,-186.953430,-0.004562,0.000824,0.020926,20.148405,1.026409,0.209259,-186.953430,0.021975,0.000000
20.790001,4.778282,-187.042404,-0.004540,0.000850,0.021603,21.254860,1.082774,0.216027,-187.042404,0.022712,0.000000
21.230001,5.030006,-187.131363,-0.004510,0.000880,0.022348,22.374586,1.139816,0.223483,-187.131363,0.023450,0.000000
21.670000,5.193108,-187.131363,-0.004471,0.000909,0.023077,23.100096,1.176775,0.230765,-187.131363,0.024178,0.000000
22.110001,5.445206,-187.220322,-0.004449,0.000943,0.023952,24.221485,1.233901,0.239523,-187.220322,0.024915,0.000000
22.550001,5.607925,-187.175842,-0.004424,0.000972,0.024699,24.945297,1.270774,0.246987,-187.175842,0.025643,0.000000
22.990002,5.616867,-187.353760,-0.004402,0.000996,0.025288,24.985073,1.272800,0.252884,-187.353760,0.026381,0.000000
23.430000,6.010834,-187.353760,-0.004376,0.001030,0.026164,26.737524,1.362074,0.261642,-187.353760,0.027110,0.000000
23.870001,6.070045,-187.398254,-0.004359,0.001055,0.026806,27.000912,1.375492,0.268061,-187.398254,0.027846,0.000000
24.310001,6.221596,-187.531693,-0.004324,0.001086,0.027578,27.675039,1.409834,0.275775,-187.531693,0.028584,0.000000
24.750002,6.385071,-187.487213,-0.004303,0.001112,0.028245,28.402214,1.446878,0.282452,-187.487213,0.029312,0.000000
25.190001,6.589874,-187.576172,-0.004277,0.001138,0.028913,29.313225,1.493287,0.289128,-187.576172,0.030049,0.000000
25.630001,6.942139,-187.665131,-0.004260,0.001174,0.029815,30.880175,1.573111,0.298151,-187.665131,0.030778,0.000000
26.070002,7.050499,-187.665131,-0.004208,0.001205,0.030596,31.362186,1.597666,0.305956,-187.665131,0.031515,0.000000
26.510002,7.068748,-187.754089,-0.004199,0.001232,0.031298,31.443363,1.601801,0.312981,-187.754089,0.032244,0.000000
26.950001,7.120132,-187.754089,-0.004165,0.001255,0.031879,31.671930,1.613445,0.318794,-187.754089,0.032980,0.000000
27.390001,7.588577,-187.843063,-0.004148,0.001287,0.032686,33.755676,1.719596,0.326856,-187.843063,0.033709,0.000000
27.830002,7.795242,-187.932022,-0.004109,0.001319,0.033501,34.674969,1.766427,0.335009,-187.932022,0.034446,0.000000
28.270000,7.905464,-187.976501,-0.004083,0.001351,0.034307,35.165260,1.791404,0.343070,-187.976501,0.035183,0.000000
28.710001,7.829872,-188.020981,-0.004079,0.001372,0.034836,34.829010,1.774274,0.348362,-188.020981,0.035912,0.000000
29.150002,7.955734,-188.109940,-0.004049,0.001395,0.035426,35.388874,1.802795,0.354259,-188.109940,0.036649,0.000000
29.590002,8.178787,-188.109940,-0.004018,0.001423,0.036155,36.381062,1.853340,0.361548,-188.109940,0.037377,0.000000
30.030001,8.408173,-188.154419,-0.003997,0.001454,0.036926,37.401421,1.905319,0.369262,-188.154419,0.038115,0.000000
30.470001,8.802513,-188.198898,-0.003967,0.001491,0.037880,39.155533,1.994678,0.378800,-188.198898,0.038843,0.000000
30.910002,8.744423,-188.243378,-0.003949,0.001516,0.038514,38.897137,1.981515,0.385136,-188.243378,0.039580,0.000000
31.350002,8.840866,-188.287872,-0.003923,0.001544,0.039224,39.326138,2.003369,0.392244,-188.287872,0.040317,0.000000
31.790001,9.078438,-188.376831,-0.003898,0.001575,0.040014,40.382908,2.057204,0.400139,-188.376831,0.041046,0.000000
32.230003,9.015511,-188.465790,-0.003876,0.001595,0.040526,40.102993,2.042944,0.405256,-188.465790,0.041783,0.000000
32.670002,9.508156,-188.465790,-0.003859,0.001630,0.041410,42.294388,2.154579,0.414098,-188.465790,0.042511,0.000000
33.110001,9.597900,-188.510269,-0.003833,0.001661,0.042182,42.693592,2.174915,0.421819,-188.510269,0.043248,0.000000
33.550003,9.696579,-188.599228,-0.003807,0.001691,0.042962,43.132538,2.197276,0.429623,-188.599228,0.043977,0.000000
33.990002,9.401657,-188.643707,-0.003790,0.001709,0.043404,41.820660,2.130446,0.434044,-188.643707,0.044714,0.000000
34.430000,9.919632,-188.732681,-0.003773,0.001742,0.044237,44.124725,2.247821,0.442371,-188.732681,0.045451,0.000000
34.870003,10.146034,-188.777161,-0.003747,0.001774,0.045052,45.131813,2.299124,0.450524,-188.777161,0.046180,0.000000
35.310001,10.445419,-188.821640,-0.003721,0.001812,0.046024,46.463547,2.366966,0.460236,-188.821640,0.046917,0.000000
35.750000,9.926704,-188.910599,-0.003704,0.001828,0.046422,44.156185,2.249424,0.464225,-188.910599,0.047645,0.000000
36.190002,10.127785,-188.910599,-0.003691,0.001858,0.047203,45.050636,2.294989,0.472029,-188.910599,0.048382,0.000000
36.630001,10.606285,-188.955078,-0.003656,0.001893,0.048079,47.179111,2.403419,0.480788,-188.955078,0.049111,0.000000
37.070004,10.877373,-188.955078,-0.003635,0.001927,0.048946,48.384972,2.464848,0.489463,-188.955078,0.049848,0.000000
37.510002,10.793587,-189.088516,-0.003617,0.001956,0.049692,48.012272,2.445862,0.496919,-189.088516,0.050585,0.000000
37.950001,10.714272,-189.133011,-0.003583,0.001979,0.050256,47.659462,2.427889,0.502558,-189.133011,0.051313,0.000000
38.390003,10.854660,-189.133011,-0.003583,0.002009,0.051019,48.283939,2.459701,0.510189,-189.133011,0.052051,0.000000
38.830002,11.113457,-189.221970,-0.003574,0.002035,0.051687,49.435123,2.518345,0.516865,-189.221970,0.052779,0.000000
39.270000,11.485825,-189.221970,-0.003531,0.002069,0.052545,51.091499,2.602725,0.525449,-189.221970,0.053516,0.000000
39.710003,11.198357,-189.310928,-0.003518,0.002093,0.053161,49.812778,2.537584,0.531611,-189.310928,0.054245,0.000000
40.150002,11.502213,-189.444366,-0.003505,0.002124,0.053959,51.164398,2.606439,0.539590,-189.444366,0.054982,0.000000
40.590000,11.488060,-189.399887,-0.003497,0.002149,0.054574,51.101444,2.603232,0.545744,-189.399887,0.055711,0.000000
41.030003,12.058907,-189.533325,-0.003475,0.002188,0.055563,53.640694,2.732587,0.555630,-189.533325,0.056448,0.000000
41.470001,11.841446,-189.533325,-0.003449,0.002217,0.056318,52.673382,2.683310,0.563177,-189.533325,0.057184,0.000000
41.910004,11.848145,-189.622299,-0.003432,0.002244,0.056985,52.703178,2.684828,0.569854,-189.622299,0.057913,0.000000
42.350002,11.794525,-189.666779,-0.003406,0.002268,0.057601,52.464668,2.672678,0.576008,-189.666779,0.058650,0.000000
42.790001,12.217911,-189.666779,-0.003415,0.002302,0.058468,54.347980,2.768618,0.584683,-189.666779,0.059379,0.000000
43.230003,12.267067,-189.755737,-0.003380,0.002329,0.059162,54.566639,2.779757,0.591617,-189.755737,0.060116,0.000000
43.670002,12.153488,-189.800217,-0.003363,0.002357,0.059856,54.061417,2.754020,0.598558,-189.800217,0.060844,0.000000
44.110001,12.153488,-189.844696,-0.003333,0.002385,0.060576,54.061417,2.754020,0.605757,-189.844696,0.061582,0.000000
44.550003,12.284943,-189.933655,-0.003328,0.002414,0.061304,54.646152,2.783808,0.613039,-189.933655,0.062319,0.000000
44.990002,12.336700,-189.933655,-0.003324,0.002441,0.061989,54.876385,2.795536,0.619890,-189.933655,0.063047,0.000000
45.430000,12.532936,-189.978149,-0.003294,0.002473,0.062804,55.749283,2.840004,0.628043,-189.978149,0.063785,0.000000
45.870003,12.327759,-189.978149,-0.003281,0.002497,0.063411,54.836609,2.793510,0.634114,-189.978149,0.064513,0.000000
46.310001,12.662895,-190.111588,-0.003272,0.002529,0.064227,56.327370,2.869453,0.642266,-190.111588,0.065250,0.000000
46.750004,12.832329,-190.111588,-0.003238,0.002558,0.064981,57.081051,2.907847,0.649813,-190.111588,0.065978,0.000000
47.190002,12.945152,-190.156067,-0.003225,0.002589,0.065770,57.582912,2.933414,0.657701,-190.156067,0.066716,0.000000
47.630001,12.904938,-190.289505,-0.003195,0.002617,0.066482,57.404030,2.924301,0.664817,-190.289505,0.067453,0.000000
48.070004,12.816689,-190.289505,-0.003178,0.002644,0.067158,57.011478,2.904303,0.671577,-190.289505,0.068181,0.000000
48.510002,12.687477,-190.422958,-0.003178,0.002667,0.067739,56.436718,2.875023,0.677390,-190.422958,0.068918,0.000000
48.950001,13.326836,-190.422958,-0.003143,0.002704,0.068675,59.280727,3.019904,0.686754,-190.422958,0.069647,0.000000
49.390003,13.188690,-190.467438,-0.003122,0.002732,0.069395,58.666225,2.988600,0.693953,-190.467438,0.070384,0.000000
49.830002,13.024841,-190.511917,-0.003109,0.002759,0.070089,57.937389,2.951471,0.700887,-190.511917,0.071112,0.000000
50.270004,13.117935,-190.556396,-0.003104,0.002786,0.070757,58.351490,2.972567,0.707571,-190.556396,0.071849,0.000000
50.710003,13.310829,-190.645355,-0.003065,0.002815,0.071503,59.209526,3.016277,0.715027,-190.645355,0.072587,0.000000
51.150002,13.488823,-190.645355,-0.003057,0.002842,0.072196,60.001282,3.056611,0.721961,-190.645355,0.073315,0.000000
51.590004,13.927849,-190.689835,-0.003035,0.002881,0.073176,61.954166,3.156096,0.731764,-190.689835,0.074052,0.000000
52.030003,13.447487,-190.734314,-0.003014,0.002902,0.073714,59.817410,3.047244,0.737139,-190.734314,0.074780,0.000000
52.470001,13.648567,-190.778793,-0.002992,0.002932,0.074469,60.711861,3.092809,0.744686,-190.778793,0.075518,0.000000
52.910004,13.779640,-190.912247,-0.002984,0.002960,0.075188,61.294899,3.122511,0.751885,-190.912247,0.076246,0.000000
53.350002,13.459778,-190.956726,-0.002966,0.002983,0.075769,59.872082,3.050029,0.757691,-190.956726,0.076983,0.000000
53.790001,13.817993,-190.956726,-0.002958,0.003011,0.076489,61.465504,3.131202,0.764889,-190.956726,0.077712,0.000000
54.230003,14.133400,-191.045685,-0.002936,0.003045,0.077347,62.868504,3.202674,0.773474,-191.045685,0.078449,0.000000
54.670002,14.159462,-191.045685,-0.002906,0.003077,0.078163,62.984432,3.208580,0.781626,-191.045685,0.079186,0.000000
55.110004,14.200798,-191.179123,-0.002910,0.003105,0.078857,63.168304,3.217947,0.788568,-191.179123,0.079915,0.000000
55.550003,14.200424,-191.134644,-0.002884,0.003130,0.079490,63.166641,3.217862,0.794896,-191.134644,0.080652,0.000000
55.990002,14.672592,-191.268097,-0.002863,0.003163,0.080340,65.266953,3.324857,0.803397,-191.268097,0.081381,0.000000
56.430004,15.182739,-191.357056,-0.002854,0.003201,0.081293,67.536194,3.440458,0.812935,-191.357056,0.082117,0.000000
56.870003,14.381027,-191.312576,-0.002820,0.003223,0.081875,63.970005,3.258787,0.818748,-191.312576,0.082846,0.000000
57.310001,14.143082,-191.401535,-0.002824,0.003243,0.082377,62.911568,3.204868,0.823775,-191.401535,0.083583,0.000000
57.750004,14.800690,-191.490494,-0.002790,0.003279,0.083280,65.836754,3.353884,0.832798,-191.490494,0.084320,0.000000
58.190002,15.182373,-191.446014,-0.002794,0.003312,0.084129,67.534569,3.440375,0.841291,-191.446014,0.085049,0.000000
58.630001,15.130608,-191.534973,-0.002759,0.003343,0.084901,67.304306,3.428645,0.849012,-191.534973,0.085786,0.000000
59.070004,14.722862,-191.579453,-0.002746,0.003367,0.085526,65.490562,3.336248,0.855258,-191.579453,0.086514,0.000000
59.510002,14.869202,-191.623932,-0.002729,0.003393,0.086185,66.141510,3.369409,0.861851,-191.623932,0.087252,0.000000
59.950005,15.083694,-191.668411,-0.002703,0.003421,0.086888,67.095627,3.418014,0.868876,-191.668411,0.087980,0.000000
60.390003,15.440048,-191.712906,-0.002695,0.003455,0.087746,68.680763,3.498765,0.877460,-191.712906,0.088717,0.000000
60.830002,15.365578,-191.846344,-0.002690,0.003482,0.088431,68.349503,3.481889,0.884310,-191.846344,0.089454,0.000000
61.270004,15.388664,-191.801865,-0.002660,0.003509,0.089124,68.452194,3.487121,0.891244,-191.801865,0.090183,0.000000
61.710003,15.491066,-191.935303,-0.002647,0.003536,0.089819,68.907700,3.510326,0.898186,-191.935303,0.090920,0.000000
62.150002,15.944244,-192.024261,-0.002621,0.003570,0.090677,70.923538,3.613018,0.906770,-192.024261,0.091648,0.000000
62.590004,15.995628,-191.979782,-0.002617,0.003602,0.091501,71.152107,3.624661,0.915006,-191.979782,0.092386,0.000000
63.030003,15.386429,-192.113220,-0.002600,0.003625,0.092073,68.442253,3.486615,0.920729,-192.113220,0.093114,0.000000
63.470001,15.412125,-192.113220,-0.002570,0.003653,0.092784,68.556557,3.492437,0.927844,-192.113220,0.093851,0.000000
63.910004,15.790451,-192.202194,-0.002570,0.003679,0.093444,70.239433,3.578167,0.934438,-192.202194,0.094588,0.000000
64.350006,16.230598,-192.202194,-0.002548,0.003716,0.094380,72.197311,3.677906,0.943801,-192.202194,0.095317,0.000000
64.790001,16.489021,-192.246674,-0.002527,0.003745,0.095126,73.346832,3.736466,0.951258,-192.246674,0.096054,0.000000
65.230003,16.467796,-192.380112,-0.002505,0.003772,0.095811,73.252419,3.731656,0.958108,-192.380112,0.096782,0.000000
65.670006,16.272301,-192.291153,-0.002505,0.003795,0.096383,72.382805,3.687356,0.963831,-192.291153,0.097519,0.000000
66.110001,17.339149,-192.513550,-0.002488,0.003834,0.097381,77.128387,3.929107,0.973808,-192.513550,0.098248,0.000000
66.550003,16.950020,-192.469070,-0.002462,0.003857,0.097979,75.397453,3.840929,0.979788,-192.469070,0.098985,0.000000
66.990005,17.550285,-192.558044,-0.002462,0.003890,0.098811,78.067566,3.976952,0.988115,-192.558044,0.099714,0.000000
67.430000,17.184242,-192.602524,-0.002436,0.003909,0.099288,76.439323,3.894005,0.992884,-192.602524,0.100450,0.000000
67.870003,17.622902,-192.602524,-0.002414,0.003936,0.099973,78.390579,3.993407,0.999735,-192.602524,0.101188,0.000000
68.310005,18.635010,-192.735962,-0.002397,0.003973,0.100919,82.892662,4.222754,1.009189,-192.735962,0.101916,0.000000
68.750000,18.993599,-192.735962,-0.002393,0.004004,0.101699,84.487747,4.304011,1.016994,-192.735962,0.102653,0.000000
69.190002,19.424438,-192.735962,-0.002367,0.004035,0.102480,86.404221,4.401640,1.024798,-192.735962,0.103382,0.000000
69.630005,19.408424,-192.824921,-0.002345,0.004057,0.103052,86.332985,4.398012,1.030521,-192.824921,0.104119,0.000000
70.070000,20.552727,-192.824921,-0.002337,0.004088,0.103833,91.423096,4.657315,1.038325,-192.824921,0.104848,0.000000
70.510002,21.329865,-192.958359,-0.002324,0.004120,0.104639,94.879974,4.833416,1.046395,-192.958359,0.105585,0.000000
70.950005,22.134933,-193.002853,-0.002294,0.004152,0.105472,98.461105,5.015847,1.054722,-193.002853,0.106321,0.000000
71.390007,21.824379,-193.047333,-0.002276,0.004168,0.105879,97.079689,4.945475,1.058794,-193.047333,0.107050,0.000000
71.830002,22.810043,-193.136292,-0.002268,0.004199,0.106660,101.464142,5.168829,1.066599,-193.136292,0.107787,0.000000
72.270004,23.872055,-193.136292,-0.002246,0.004230,0.107440,106.188202,5.409485,1.074403,-193.136292,0.108516,0.000000
72.710007,23.936844,-193.225250,-0.002233,0.004249,0.107926,106.476402,5.424166,1.079263,-193.225250,0.109253,0.000000
73.150002,25.812485,-193.225250,-0.002212,0.004292,0.109019,114.819664,5.849193,1.090186,-193.225250,0.109981,0.000000
73.590004,26.165871,-193.225250,-0.002203,0.004315,0.109600,116.391609,5.929271,1.096000,-193.225250,0.110719,0.000000
74.030006,27.064774,-193.403168,-0.002169,0.004342,0.110293,120.390129,6.132965,1.102934,-193.403168,0.111455,0.000000
74.470001,28.239983,-193.358688,-0.002147,0.004373,0.111083,125.617714,6.399272,1.110829,-193.358688,0.112184,0.000000
74.910004,28.989571,-193.403168,-0.002126,0.004398,0.111707,128.952057,6.569130,1.117074,-193.403168,0.112922,0.000000
75.350006,30.783661,-193.492142,-0.002113,0.004433,0.112609,136.932556,6.975677,1.126090,-193.492142,0.113650,0.000000
75.790001,31.958862,-193.492142,-0.002091,0.004461,0.113311,142.160126,7.241982,1.133114,-193.492142,0.114387,0.000000
76.230003,33.026459,-193.670059,-0.002078,0.004487,0.113979,146.909027,7.483902,1.139791,-193.670059,0.115115,0.000000
76.670006,33.700081,-193.625580,-0.002048,0.004510,0.114560,149.905441,7.636548,1.145604,-193.625580,0.115853,0.000000
77.110001,35.259575,-193.714539,-0.002048,0.004541,0.115333,156.842422,7.989934,1.153326,-193.714539,0.116590,0.000000
77.550003,36.985893,-193.803497,-0.002031,0.004574,0.116191,164.521469,8.381124,1.161910,-193.803497,0.117318,0.000000
77.990005,39.150124,-193.759018,-0.002001,0.004612,0.117145,174.148453,8.871545,1.171448,-193.759018,0.118055,0.000000
78.430000,39.739960,-193.847992,-0.002001,0.004633,0.117682,176.772171,9.005203,1.176822,-193.847992,0.118784,0.000000
78.870003,40.895432,-193.892471,-0.001970,0.004666,0.118515,181.911972,9.267037,1.185149,-193.892471,0.119521,0.000000
79.310005,43.143814,-193.981430,-0.001962,0.004694,0.119217,191.913269,9.776528,1.192174,-193.981430,0.120249,0.000000
79.750000,45.048134,-194.070389,-0.001944,0.004726,0.120033,200.384109,10.208053,1.200326,-194.070389,0.120986,0.000000
80.190002,46.834030,-193.981430,-0.001936,0.004757,0.120839,208.328171,10.612743,1.208388,-193.981430,0.121715,0.000000
80.630005,47.807037,-194.159348,-0.001923,0.004778,0.121360,212.656326,10.833230,1.213596,-194.159348,0.122452,0.000000
81.070007,49.775398,-194.159348,-0.001893,0.004808,0.122123,221.412033,11.279266,1.221227,-194.159348,0.123189,0.000000
81.510002,51.375114,-194.248306,-0.001897,0.004832,0.122721,228.527924,11.641768,1.227207,-194.248306,0.123917,0.000000
81.950005,53.843567,-194.248306,-0.001876,0.004866,0.123596,239.508148,12.201127,1.235965,-194.248306,0.124655,0.000000
82.390007,55.334549,-194.248306,-0.001863,0.004891,0.124238,246.140366,12.538988,1.242384,-194.248306,0.125383,0.000000
82.830002,57.366585,-194.381760,-0.001850,0.004921,0.125001,255.179321,12.999454,1.250015,-194.381760,0.126120,0.000000
83.270004,59.299942,-194.426239,-0.001837,0.004946,0.125618,263.779327,13.437559,1.256176,-194.426239,0.126849,0.000000
83.710007,62.407761,-194.470718,-0.001819,0.004986,0.126632,277.603577,14.141801,1.266320,-194.470718,0.127586,0.000000
84.150002,64.678116,-194.515198,-0.001798,0.005015,0.127378,287.702637,14.656271,1.273776,-194.515198,0.128323,0.000000
84.590004,66.348953,-194.604156,-0.001807,0.005029,0.127725,295.134888,15.034888,1.277251,-194.604156,0.129000,0.000000
85.030006,65.323059,-194.648636,-0.001776,0.005028,0.127699,290.571472,14.802417,1.276986,-194.648636,294.500458,0.000000
85.470001,64.583160,-194.648636,-0.001785,0.005028,0.127699,287.280243,14.634753,1.276986,-194.648636,294.500458,0.000000
85.910004,66.662125,-194.693115,-0.001768,0.004893,0.124291,296.527954,15.105854,1.242907,-194.693115,294.500458,0.000000
86.350006,66.059616,-194.782089,-0.001763,0.004894,0.124299,293.847839,14.969322,1.242990,-194.782089,294.500458,0.000000
86.790001,65.551331,-194.782089,-0.001759,0.004936,0.125375,291.586884,14.854144,1.253747,-194.782089,294.500458,0.000000
87.230003,65.267960,-194.871048,-0.001750,0.005032,0.127820,290.326385,14.789931,1.278204,-194.871048,294.500458,0.000000
87.670006,65.093307,-194.960007,-0.001738,0.005046,0.128167,289.549500,14.750354,1.281671,-194.960007,294.500458,0.000000
88.110001,65.632874,-194.915527,-0.001750,0.005059,0.128496,291.949615,14.872622,1.284964,-194.915527,294.500458,0.000000
88.550003,65.452286,-195.048965,-0.001746,0.005059,0.128496,291.146301,14.831700,1.284964,-195.048965,294.500458,0.000000
88.990005,65.244492,-195.004486,-0.001746,0.005059,0.128506,290.221985,14.784614,1.285055,-195.004486,294.500458,0.000000
89.430008,65.047134,-195.137939,-0.001750,0.005059,0.128506,289.344116,14.739891,1.285055,-195.137939,294.500458,0.000000
89.870003,65.284714,-195.093445,-0.001738,0.005065,0.128644,290.400909,14.793728,1.286440,-195.093445,294.500458,0.000000
90.310005,65.210617,-195.182419,-0.001746,0.005066,0.128670,290.071320,14.776937,1.286698,-195.182419,294.500458,0.000000
90.750008,65.119751,-195.315857,-0.001742,0.005066,0.128679,289.667114,14.756347,1.286789,-195.315857,294.500458,0.000000
91.190002,65.189011,-195.271378,-0.001742,0.005069,0.128748,289.975189,14.772040,1.287485,-195.271378,294.500458,0.000000
91.630005,65.126450,-195.315857,-0.001755,0.005071,0.128792,289.696930,14.757865,1.287917,-195.315857,294.500458,0.000000
92.070007,65.101501,-195.360336,-0.001742,0.005071,0.128792,289.585937,14.752212,1.287917,-195.360336,294.500458,0.000000
92.510002,65.159973,-195.449295,-0.001755,0.005073,0.128861,289.846039,14.765461,1.288605,-195.449295,294.500458,0.000000
92.950005,65.129807,-195.538254,-0.001742,0.005074,0.128870,289.711853,14.758625,1.288696,-195.538254,294.500458,0.000000
93.390007,65.051605,-195.582748,-0.001733,0.005074,0.128870,289.363983,14.740905,1.288696,-195.582748,294.500458,0.000000
93.830002,65.091080,-195.582748,-0.001750,0.005077,0.128948,289.539581,14.749849,1.289476,-195.582748,294.500458,0.000000
94.270004,65.101883,-195.627228,-0.001733,0.005077,0.128948,289.587646,14.752297,1.289476,-195.627228,294.500458,0.000000
94.710007,65.034485,-195.716187,-0.001738,0.005077,0.128948,289.287842,14.737025,1.289476,-195.716187,294.500458,0.000000
95.150002,65.423981,-195.760666,-0.001746,0.005083,0.129113,291.020386,14.825286,1.291126,-195.760666,294.500458,0.000000
95.590004,65.454147,-195.805145,-0.001738,0.005082,0.129095,291.154602,14.832121,1.290952,-195.805145,294.500458,0.000000
96.030006,65.361420,-195.938583,-0.001729,0.005082,0.129095,290.742126,14.811110,1.290952,-195.938583,294.500458,0.000000
96.470001,65.314133,-195.894104,-0.001725,0.005082,0.129095,290.531769,14.800394,1.290952,-195.894104,294.500458,0.000000
96.910004,65.268326,-195.983063,-0.001729,0.005082,0.129095,290.328003,14.790014,1.290952,-195.983063,294.500458,0.000000
97.350006,65.184921,-196.072037,-0.001738,0.005082,0.129095,289.957001,14.771114,1.290952,-196.072037,294.500458,0.000000
97.790001,65.107834,-196.027557,-0.001729,0.005082,0.129095,289.614105,14.753646,1.290952,-196.027557,294.500458,0.000000
98.230003,65.022934,-196.160995,-0.001725,0.005082,0.129095,289.236450,14.734407,1.290952,-196.160995,294.500458,0.000000
98.670006,64.982346,-196.205475,-0.001720,0.005082,0.129095,289.055908,14.725209,1.290952,-196.205475,294.500458,0.000000
99.110008,65.894287,-196.160995,-0.001733,0.005094,0.129390,293.112427,14.931859,1.293897,-196.160995,294.500458,0.000000
99.550003,65.875290,-196.294434,-0.001729,0.005094,0.129390,293.027924,14.927554,1.293897,-196.294434,294.500458,0.000000
99.990005,65.909927,-196.294434,-0.001712,0.005094,0.129390,293.182007,14.935403,1.293897,-196.294434,294.500458,0.000000
100.430008,65.838806,-196.338913,-0.001720,0.005094,0.129390,292.865631,14.919287,1.293897,-196.338913,294.500458,0.000000
100.870003,65.859283,-196.472366,-0.001720,0.005094,0.129390,292.956726,14.923927,1.293897,-196.472366,294.500458,0.000000
101.310005,65.791885,-196.427887,-0.001716,0.005094,0.129390,292.656921,14.908654,1.293897,-196.427887,294.500458,0.000000
101.750008,65.751663,-196.605804,-0.001716,0.005094,0.129390,292.477997,14.899540,1.293897,-196.605804,294.500458,0.000000
102.190002,65.664902,-196.516846,-0.001712,0.005094,0.129390,292.092072,14.879879,1.293897,-196.516846,294.500458,0.000000
102.630005,65.619095,-196.605804,-0.001712,0.005094,0.129390,291.888306,14.869499,1.293897,-196.605804,294.500458,0.000000
103.070007,65.587830,-196.650284,-0.001725,0.005094,0.129390,291.749237,14.862414,1.293897,-196.650284,294.500458,0.000000
103.510002,65.561020,-196.694763,-0.001725,0.005094,0.129390,291.629974,14.856339,1.293897,-196.694763,294.500458,0.000000
103.950005,65.521545,-196.828201,-0.001725,0.005094,0.129390,291.454376,14.847394,1.293897,-196.828201,294.500458,0.000000
104.390007,65.479095,-196.783722,-0.001720,0.005094,0.129390,291.265564,14.837775,1.293897,-196.783722,294.500458,0.000000
104.830002,65.400146,-196.917175,-0.001707,0.005094,0.129390,290.914368,14.819884,1.293897,-196.917175,294.500458,0.000000
105.270004,65.348755,-196.961655,-0.001712,0.005094,0.129390,290.685791,14.808240,1.293897,-196.961655,294.500458,0.000000
105.710007,65.324554,-196.961655,-0.001712,0.005094,0.129390,290.578125,14.802755,1.293897,-196.961655,294.500458,0.000000
106.150002,65.280243,-197.006134,-0.001716,0.005094,0.129390,290.381012,14.792715,1.293897,-197.006134,294.500458,0.000000
106.590004,65.254547,-197.050613,-0.001712,0.005094,0.129390,290.266724,14.786892,1.293897,-197.050613,294.500458,0.000000
107.030006,65.218796,-197.095093,-0.001720,0.005094,0.129390,290.107697,14.778790,1.293897,-197.095093,294.500458,0.000000
107.470009,65.157730,-197.184052,-0.001707,0.005094,0.129390,289.836060,14.764953,1.293897,-197.184052,294.500458,0.000000
107.910004,65.114914,-197.228531,-0.001720,0.005094,0.129390,289.645599,14.755250,1.293897,-197.228531,294.500458,0.000000
108.350006,65.067245,-197.317505,-0.001716,0.005094,0.129390,289.433563,14.744449,1.293897,-197.317505,294.500458,0.000000
108.790009,65.036713,-197.317505,-0.001712,0.005094,0.129390,289.297760,14.737530,1.293897,-197.317505,294.500458,0.000000
109.230003,65.004318,-197.317505,-0.001720,0.005094,0.129390,289.153656,14.730189,1.293897,-197.317505,294.500458,0.000000
109.670006,64.964844,-197.406464,-0.001703,0.005094,0.129390,288.978058,14.721244,1.293897,-197.406464,294.500458,0.000000
110.110008,64.926865,-197.450943,-0.001720,0.005094,0.129390,288.809113,14.712638,1.293897,-197.450943,294.500458,0.000000
110.550003,64.905258,-197.495422,-0.001712,0.005094,0.129390,288.713013,14.707742,1.293897,-197.495422,294.500458,0.000000
110.990005,64.860947,-197.584381,-0.001712,0.005094,0.129390,288.515900,14.697701,1.293897,-197.584381,294.500458,0.000000
111.430008,64.814407,-197.628860,-0.001712,0.005094,0.129390,288.308868,14.687155,1.293897,-197.628860,294.500458,0.000000
111.870003,64.796158,-197.717834,-0.001725,0.005094,0.129390,288.227692,14.683020,1.293897,-197.717834,294.500458,0.000000
112.310005,64.762650,-197.673340,-0.001699,0.005094,0.129390,288.078644,14.675426,1.293897,-197.673340,294.500458,0.000000
112.750008,64.749237,-197.851273,-0.001716,0.005094,0.129390,288.018982,14.672387,1.293897,-197.851273,294.500458,0.000000
113.190002,64.714233,-197.762314,-0.001707,0.005094,0.129399,287.863281,14.664455,1.293988,-197.762314,294.500458,0.000000
113.630005,64.685196,-197.851273,-0.001712,0.005094,0.129399,287.734131,14.657875,1.293988,-197.851273,294.500458,0.000000
114.070007,64.655396,-197.940231,-0.001703,0.005094,0.129399,287.601562,14.651122,1.293988,-197.940231,294.500458,0.000000
114.510002,64.627472,-197.895752,-0.001703,0.005094,0.129399,287.477356,14.644794,1.293988,-197.895752,294.500458,0.000000
114.950005,64.601776,-198.073669,-0.001712,0.005094,0.129399,287.363037,14.638972,1.293988,-198.073669,294.500458,0.000000
115.390007,64.565292,-198.118149,-0.001712,0.005094,0.129399,287.200775,14.630704,1.293988,-198.118149,294.500458,0.000000
115.830002,64.532898,-198.118149,-0.001725,0.005094,0.129399,287.056671,14.623363,1.293988,-198.118149,294.500458,0.000000
116.270004,64.490448,-198.207123,-0.001707,0.005094,0.129399,286.867828,14.613745,1.293988,-198.207123,294.500458,0.000000
116.710007,64.474808,-198.162643,-0.001707,0.005094,0.129399,286.798279,14.610201,1.293988,-198.162643,294.500458,0.000000
117.150009,64.450974,-198.296082,-0.001712,0.005094,0.129399,286.692261,14.604800,1.293988,-198.296082,294.500458,0.000000
117.590004,64.436081,-198.340561,-0.001703,0.005094,0.129399,286.626007,14.601424,1.293988,-198.340561,294.500458,0.000000
118.030006,64.404053,-198.296082,-0.001716,0.005094,0.129399,286.483521,14.594167,1.293988,-198.296082,294.500458,0.000000
118.470009,64.379471,-198.429520,-0.001703,0.005094,0.129399,286.374176,14.588596,1.293988,-198.429520,294.500458,0.000000
118.910004,64.363831,-198.429520,-0.001707,0.005094,0.129399,286.304626,14.585052,1.293988,-198.429520,294.500458,0.000000
119.350006,66.691528,-198.562973,-0.001707,0.004938,0.125435,296.658722,15.112516,1.254352,-198.562973,294.500458,0.000000
119.790009,66.675888,-198.562973,-0.001699,0.004938,0.125435,296.589172,15.108973,1.254352,-198.562973,294.500458,0.000000
120.230003,66.667328,-198.651932,-0.001720,0.004938,0.125435,296.551086,15.107032,1.254352,-198.651932,294.500458,0.000000
120.670006,66.607376,-198.696411,-0.001703,0.004938,0.125435,296.284393,15.093448,1.254352,-198.696411,294.500458,0.000000
121.110008,66.594345,-198.651932,-0.001690,0.004938,0.125435,296.226440,15.090494,1.254352,-198.651932,294.500458,0.000000
121.550003,66.578339,-198.740891,-0.001720,0.004938,0.125435,296.155243,15.086867,1.254352,-198.740891,294.500458,0.000000
121.990005,66.481140,-198.785370,-0.001694,0.004938,0.125435,295.722870,15.064842,1.254352,-198.785370,294.500458,0.000000
122.430008,66.446884,-198.829849,-0.001703,0.004938,0.125435,295.570496,15.057079,1.254352,-198.829849,294.500458,0.000000
122.870003,66.429382,-198.918808,-0.001694,0.004938,0.125435,295.492645,15.053113,1.254352,-198.918808,294.500458,0.000000
123.310005,66.436462,-198.874329,-0.001686,0.004938,0.125435,295.524139,15.054718,1.254352,-198.874329,294.500458,0.000000
123.750008,66.388046,-198.963287,-0.001690,0.004938,0.125435,295.308777,15.043747,1.254352,-198.963287,294.500458,0.000000
124.190002,66.360489,-199.052261,-0.001690,0.004938,0.125435,295.186188,15.037501,1.254352,-199.052261,294.500458,0.000000
124.630005,66.333679,-199.096741,-0.001699,0.004938,0.125435,295.066956,15.031426,1.254352,-199.096741,294.500458,0.000000
125.070007,66.313583,-199.141220,-0.001699,0.004938,0.125435,294.977539,15.026873,1.254352,-199.141220,294.500458,0.000000
125.510010,66.296082,-199.185699,-0.001690,0.004938,0.125435,294.899689,15.022907,1.254352,-199.185699,294.500458,0.000000
125.950005,66.265167,-199.230179,-0.001681,0.004938,0.125435,294.762177,15.015902,1.254352,-199.230179,294.500458,0.000000
126.390007,66.251770,-199.319138,-0.001694,0.004938,0.125435,294.702606,15.012865,1.254352,-199.319138,294.500458,0.000000
126.830009,66.226822,-199.319138,-0.001690,0.004938,0.125435,294.591614,15.007212,1.254352,-199.319138,294.500458,0.000000
127.270004,66.206711,-199.408096,-0.001690,0.004938,0.125435,294.502167,15.002655,1.254352,-199.408096,294.500458,0.000000
127.710007,66.178772,-199.363617,-0.001694,0.004938,0.125435,294.377869,14.996324,1.254352,-199.363617,294.500458,0.000000
128.150009,66.151962,-199.497070,-0.001703,0.004938,0.125435,294.258636,14.990250,1.254352,-199.497070,294.500458,0.000000
128.590012,66.130005,-199.630508,-0.001690,0.004938,0.125435,294.160950,14.985273,1.254352,-199.630508,294.500458,0.000000
129.029999,66.102814,-199.586029,-0.001694,0.004938,0.125435,294.040009,14.979112,1.254352,-199.586029,294.500458,0.000000
129.470001,66.077499,-199.674988,-0.001686,0.004938,0.125435,293.927399,14.973375,1.254352,-199.674988,294.500458,0.000000
129.910004,66.052917,-199.719467,-0.001677,0.004938,0.125435,293.818054,14.967805,1.254352,-199.719467,294.500458,0.000000
130.350006,66.035782,-199.763947,-0.001707,0.004938,0.125435,293.741821,14.963922,1.254352,-199.763947,294.500458,0.000000
130.790009,66.017166,-199.852921,-0.001694,0.004938,0.125435,293.659027,14.959704,1.254352,-199.852921,294.500458,0.000000
131.230011,65.976212,-199.852921,-0.001694,0.004939,0.125444,293.476837,14.950423,1.254443,-199.852921,294.500458,0.000000
131.670013,65.968384,-199.897400,-0.001694,0.004939,0.125462,293.442017,14.948649,1.254617,-199.897400,294.500458,0.000000
132.110001,65.935623,-199.897400,-0.001690,0.004940,0.125487,293.296295,14.941226,1.254874,-199.897400,294.500458,0.000000
132.550003,65.910675,-199.986359,-0.001699,0.004941,0.125505,293.185333,14.935573,1.255049,-199.986359,294.500458,0.000000
132.990005,65.960571,-200.075317,-0.001681,0.004941,0.125505,293.407288,14.946878,1.255049,-200.075317,294.500458,0.000000
133.430008,65.825394,-200.075317,-0.001690,0.004942,0.125522,292.805969,14.916247,1.255223,-200.075317,294.500458,0.000000
133.870010,65.883484,-200.253235,-0.001681,0.004943,0.125540,293.064362,14.929411,1.255397,-200.253235,294.500458,0.000000
134.310013,65.855927,-200.164276,-0.001681,0.004943,0.125548,292.941803,14.923166,1.255480,-200.164276,294.500458,0.000000
134.750000,65.856308,-200.253235,-0.001694,0.004943,0.125548,292.943481,14.923252,1.255480,-200.253235,294.500458,0.000000
135.190002,65.855927,-200.297729,-0.001681,0.004943,0.125548,292.941803,14.923166,1.255480,-200.297729,294.500458,0.000000
135.630005,65.795975,-200.297729,-0.001677,0.004944,0.125574,292.675110,14.909581,1.255745,-200.297729,294.500458,0.000000
136.070007,65.774002,-200.431168,-0.001686,0.004946,0.125626,292.577362,14.904602,1.256260,-200.431168,294.500458,0.000000
136.510010,65.761719,-200.431168,-0.001686,0.004947,0.125661,292.522736,14.901818,1.256608,-200.431168,294.500458,0.000000
136.950012,65.755020,-200.520126,-0.001694,0.004947,0.125661,292.492950,14.900300,1.256608,-200.520126,294.500458,0.000000
137.389999,65.759491,-200.564606,-0.001686,0.004948,0.125678,292.512817,14.901314,1.256782,-200.564606,294.500458,0.000000
137.830002,65.686874,-200.564606,-0.001686,0.004949,0.125713,292.189819,14.884859,1.257130,-200.564606,294.500458,0.000000
138.270004,65.693207,-200.653564,-0.001699,0.004953,0.125817,292.217987,14.886293,1.258167,-200.653564,294.500458,0.000000
138.710007,65.636230,-200.698044,-0.001677,0.005027,0.127681,291.964539,14.873382,1.276812,-200.698044,294.500458,0.000000
139.150009,65.657822,-200.787018,-0.001694,0.005046,0.128167,292.060577,14.878275,1.281671,-200.787018,294.500458,0.000000
139.590012,65.639587,-200.787018,-0.001686,0.005054,0.128384,291.979462,14.874144,1.283836,-200.787018,294.500458,0.000000
140.030014,65.630646,-200.831497,-0.001677,0.005058,0.128462,291.939697,14.872117,1.284624,-200.831497,294.500458,0.000000
140.470001,65.601227,-200.875977,-0.001690,0.005058,0.128462,291.808838,14.865450,1.284624,-200.875977,294.500458,0.000000
140.910004,65.590424,-200.920456,-0.001677,0.005058,0.128462,291.760773,14.863003,1.284624,-200.920456,294.500458,0.000000
141.350006,65.603836,-201.009415,-0.001707,0.005058,0.128462,291.820435,14.866042,1.284624,-201.009415,294.500458,0.000000
141.790009,65.584106,-201.053894,-0.001690,0.005059,0.128496,291.732666,14.861570,1.284964,-201.053894,294.500458,0.000000
142.230011,65.562500,-201.053894,-0.001690,0.005062,0.128574,291.636566,14.856675,1.285744,-201.053894,294.500458,0.000000
142.670013,65.548721,-201.187347,-0.001690,0.005062,0.128574,291.575287,14.853553,1.285744,-201.187347,294.500458,0.000000
143.110001,65.538300,-201.142868,-0.001681,0.005062,0.128574,291.528931,14.851191,1.285744,-201.142868,294.500458,0.000000
143.550003,65.521545,-201.231827,-0.001690,0.005062,0.128574,291.454376,14.847394,1.285744,-201.231827,294.500458,0.000000
143.990005,65.553192,-201.276306,-0.001686,0.005069,0.128748,291.595154,14.854566,1.287485,-201.276306,294.500458,0.000000
144.430008,65.543884,-201.276306,-0.001690,0.005069,0.128748,291.553772,14.852456,1.287485,-201.276306,294.500458,0.000000
144.870010,65.505157,-201.454224,-0.001686,0.005070,0.128774,291.381500,14.843681,1.287742,-201.454224,294.500458,0.000000
145.310013,65.472763,-201.409744,-0.001699,0.005068,0.128731,291.237396,14.836340,1.287311,-201.409744,0.128792,0.000000
145.750000,65.469788,-201.454224,-0.001686,0.005060,0.128531,291.224152,14.835666,1.285313,-201.454224,0.128107,0.000000
146.190002,65.413925,-201.498703,-0.001673,0.005039,0.128002,290.975677,14.823008,1.280021,-201.498703,0.127378,0.000000
146.630005,65.419144,-201.587677,-0.001703,0.005010,0.127256,290.998871,14.824189,1.272565,-201.587677,0.126641,0.000000
147.070007,65.370361,-201.632156,-0.001694,0.004977,0.126415,290.781891,14.813136,1.264155,-201.632156,0.125912,0.000000
147.510010,65.364395,-201.587677,-0.001690,0.004951,0.125748,290.755341,14.811783,1.257478,-201.587677,0.125176,0.000000
147.950012,65.370728,-201.721115,-0.001699,0.004927,0.125158,290.783508,14.813218,1.251582,-201.721115,0.124447,0.000000
148.390015,65.218430,-201.721115,-0.001681,0.004897,0.124394,290.106049,14.778708,1.243944,-201.721115,0.123709,0.000000
148.830002,64.867661,-201.810074,-0.001694,0.004877,0.123883,288.545776,14.699222,1.238834,-201.810074,0.122973,0.000000
149.270004,63.345398,-201.854553,-0.001686,0.004839,0.122921,281.774414,14.354272,1.229205,-201.854553,0.122244,0.000000
149.710007,62.253227,-201.854553,-0.001681,0.004819,0.122391,276.916199,14.106783,1.223914,-201.854553,0.121506,0.000000
150.150009,60.615532,-201.987991,-0.001694,0.004794,0.121759,269.631348,13.735676,1.217586,-201.987991,0.120778,0.000000
150.590012,58.935387,-201.987991,-0.001673,0.004771,0.121177,262.157684,13.354949,1.211772,-201.987991,0.120041,0.000000
151.030014,56.836700,-202.032486,-0.001681,0.004740,0.120388,252.822266,12.879380,1.203884,-202.032486,0.119313,0.000000
151.470001,53.492790,-202.076965,-0.001686,0.004706,0.119529,237.947815,12.121640,1.195293,-202.076965,0.118575,0.000000
151.910004,50.933479,-202.121445,-0.001686,0.004679,0.118836,226.563431,11.541692,1.188359,-202.121445,0.117838,0.000000
152.350006,47.583618,-202.121445,-0.001699,0.004650,0.118116,211.662506,10.782602,1.181160,-202.121445,0.117110,0.000000
152.790009,44.456429,-202.210403,-0.001686,0.004621,0.117379,197.752075,10.073970,1.173787,-202.210403,0.116373,0.000000
153.230011,41.297226,-202.343842,-0.001694,0.004591,0.116616,183.699234,9.358085,1.166156,-202.343842,0.115644,0.000000
153.670013,38.603851,-202.343842,-0.001681,0.004569,0.116043,171.718506,8.747758,1.160434,-202.343842,0.114907,0.000000
154.110001,35.535873,-202.343842,-0.001681,0.004542,0.115376,158.071457,8.052544,1.153757,-202.343842,0.114179,0.000000
154.550003,32.152496,-202.432816,-0.001681,0.004506,0.114465,143.021454,7.285860,1.144651,-202.432816,0.113442,0.000000
154.990005,29.562653,-202.477295,-0.001677,0.004482,0.113849,131.501251,6.698993,1.138489,-202.477295,0.112713,0.000000
155.430008,25.059921,-202.477295,-0.001690,0.004448,0.112973,111.472099,5.678659,1.129731,-202.477295,0.111976,0.000000
155.870010,22.068283,-202.655212,-0.001677,0.004423,0.112340,98.164627,5.000744,1.123402,-202.655212,0.111239,0.000000
156.310013,18.784325,-202.610733,-0.001669,0.004392,0.111560,83.556847,4.256589,1.115598,-202.610733,0.110511,0.000000
156.750000,16.454391,-202.655212,-0.001686,0.004374,0.111100,73.192787,3.728618,1.111003,-202.655212,0.109773,0.000000
157.190002,11.743507,-202.744171,-0.001686,0.004329,0.109964,52.237728,2.661117,1.099641,-202.744171,0.109045,0.000000
157.630005,9.423256,-202.744171,-0.001690,0.004304,0.109331,41.916737,2.135340,1.093312,-202.744171,0.108308,0.000000
158.070007,7.763596,-202.922104,-0.001677,0.004283,0.108793,34.534199,1.759256,1.087930,-202.922104,0.107579,0.000000
158.510010,3.385239,-202.833130,-0.001677,0.004251,0.107987,15.058293,0.767106,1.079868,-202.833130,0.106842,0.000000
158.950012,0.068146,-202.877625,-0.001686,0.004219,0.107172,0.303127,0.015442,1.071716,-202.877625,0.106105,0.000000
159.390015,-0.346306,-203.011063,-0.001686,0.004194,0.106539,-1.540445,-0.078474,1.065387,-203.011063,0.105377,0.000000
159.830002,0.076332,-203.011063,-0.001690,0.004164,0.105758,0.339542,0.017297,1.057583,-203.011063,0.104639,0.000000
160.270004,0.123627,-203.055542,-0.001677,0.004138,0.105116,0.549919,0.028014,1.051164,-203.055542,0.103911,0.000000
160.710007,0.051758,-203.011063,-0.001677,0.004106,0.104301,0.230230,0.011728,1.043011,-203.011063,0.103174,0.000000
161.150009,0.032394,-203.100021,-0.001694,0.004074,0.103468,0.144098,0.007341,1.034684,-203.100021,0.102445,0.000000
161.590012,0.097931,-203.188980,-0.001669,0.004041,0.102636,0.435618,0.022191,1.026358,-203.188980,0.101708,0.000000
162.030014,0.093468,-203.233459,-0.001677,0.004020,0.102116,0.415765,0.021180,1.021157,-203.233459,0.100971,0.000000
162.470001,0.085274,-203.233459,-0.001677,0.003994,0.101456,0.379317,0.019323,1.014564,-203.233459,0.100242,0.000000
162.910004,0.071495,-203.277939,-0.001669,0.003960,0.100572,0.318026,0.016201,1.005722,-203.277939,0.099506,0.000000
163.350006,0.056976,-203.366913,-0.001669,0.003927,0.099757,0.253443,0.012911,0.997570,-203.366913,0.098777,0.000000
163.790009,0.087883,-203.411392,-0.001647,0.003904,0.099167,0.390923,0.019915,0.991673,-203.411392,0.098039,0.000000
164.230011,0.082291,-203.411392,-0.001660,0.003879,0.098525,0.366047,0.018647,0.985254,-203.411392,0.097311,0.000000
164.670013,0.065536,-203.544830,-0.001656,0.003850,0.097788,0.291521,0.014851,0.977881,-203.544830,0.096574,0.000000
165.110001,0.058838,-203.633789,-0.001634,0.003814,0.096869,0.261724,0.013333,0.968691,-203.633789,0.095837,0.000000
165.550003,0.061813,-203.589310,-0.001638,0.003784,0.096106,0.274960,0.014007,0.961061,-203.589310,0.095108,0.000000
165.990005,0.021225,-203.722763,-0.001625,0.003759,0.095490,0.094413,0.004810,0.954899,-203.722763,0.094371,0.000000
166.430008,0.033516,-203.633789,-0.001617,0.003735,0.094874,0.149086,0.007595,0.948744,-203.633789,0.093643,0.000000
166.870010,0.056229,-203.856201,-0.001625,0.003695,0.093843,0.250117,0.012742,0.938427,-203.856201,0.092906,0.000000
167.310013,0.043938,-203.811722,-0.001604,0.003668,0.093174,0.195445,0.009956,0.931743,-203.811722,0.092177,0.000000
167.750015,0.028671,-203.811722,-0.001613,0.003641,0.092489,0.127536,0.006497,0.924892,-203.811722,0.091440,0.000000
168.190002,0.028297,-203.900681,-0.001613,0.003612,0.091753,0.125873,0.006412,0.917527,-203.900681,0.090712,0.000000
168.630005,0.025322,-203.900681,-0.001613,0.003583,0.091015,0.112638,0.005738,0.910154,-203.900681,0.089975,0.000000
169.070007,0.036865,-203.989639,-0.001621,0.003554,0.090278,0.163985,0.008354,0.902781,-203.989639,0.089237,0.000000
169.510010,0.062561,-204.034119,-0.001613,0.003529,0.089636,0.278285,0.014177,0.896362,-204.034119,0.088509,0.000000
169.950012,0.044312,-204.078598,-0.001634,0.003496,0.088795,0.197107,0.010041,0.887951,-204.078598,0.087772,0.000000
170.390015,0.042450,-204.167572,-0.001634,0.003473,0.088223,0.188827,0.009619,0.882229,-204.167572,0.087044,0.000000
170.830002,0.028297,-204.167572,-0.001660,0.003434,0.087225,0.125873,0.006412,0.872252,-204.167572,0.086306,0.000000
171.270004,0.052879,-204.256531,-0.001669,0.003408,0.086575,0.235219,0.011983,0.865749,-204.256531,0.085578,0.000000
171.710007,0.023834,-204.301010,-0.001677,0.003379,0.085829,0.106020,0.005401,0.858293,-204.301010,0.084841,0.000000
172.150009,0.032768,-204.301010,-0.001712,0.003355,0.085205,0.145760,0.007425,0.852048,-204.301010,0.084103,0.000000
172.590012,0.007446,-204.389969,-0.001720,0.003320,0.084320,0.033123,0.001687,0.843199,-204.389969,0.083375,0.000000
173.030014,0.002609,-204.389969,-0.001733,0.003292,0.083626,0.011607,0.000591,0.836265,-204.389969,0.082638,0.000000
173.470001,-0.002609,-204.434448,-0.001759,0.003267,0.082985,-0.011607,-0.000591,0.829846,-204.434448,0.081910,0.000000
173.910004,-0.001114,-204.612381,-0.001794,0.003233,0.082117,-0.004955,-0.000252,0.821171,-204.612381,0.081172,0.000000
174.350006,-0.001488,-204.567886,-0.001824,0.003207,0.081459,-0.006618,-0.000337,0.814585,-204.567886,0.080443,0.000000
174.790009,0.008568,-204.656860,-0.001845,0.003177,0.080695,0.038112,0.001941,0.806955,-204.656860,0.079707,0.000000
175.230011,0.007446,-204.656860,-0.001858,0.003148,0.079949,0.033123,0.001687,0.799491,-204.656860,0.078970,0.000000
175.670013,-0.018250,-204.745819,-0.001880,0.003123,0.079325,-0.081178,-0.004135,0.793253,-204.745819,0.078241,0.000000
176.110016,-0.010796,-204.745819,-0.001906,0.003092,0.078527,-0.048021,-0.002446,0.785275,-204.745819,0.077504,0.000000
176.550003,0.015266,-204.790298,-0.001936,0.003056,0.077634,0.067908,0.003459,0.776343,-204.790298,0.076775,0.000000
176.990005,0.001114,-204.879257,-0.001966,0.003031,0.076975,0.004955,0.000252,0.769749,-204.879257,0.076039,0.000000
177.430008,-0.008194,-204.879257,-0.001988,0.003002,0.076263,-0.036449,-0.001857,0.762634,-204.879257,0.075310,0.000000
177.870010,0.003723,-204.968216,-0.002009,0.002976,0.075578,0.016561,0.000844,0.755783,-204.968216,0.074572,0.000000
178.310013,-0.027931,-205.012711,-0.002039,0.002943,0.074755,-0.124244,-0.006329,0.747547,-205.012711,0.073836,0.000000
178.750015,-0.037979,-205.057190,-0.002061,0.002920,0.074165,-0.168940,-0.008606,0.741650,-205.057190,0.073107,0.000000
179.190002,0.000374,-205.146149,-0.002082,0.002896,0.073550,0.001663,0.000085,0.735496,-205.146149,0.072369,0.000000
179.630005,-0.003723,-205.101669,-0.002113,0.002867,0.072821,-0.016561,-0.000844,0.728206,-205.101669,0.071641,0.000000
180.070007,-0.040215,-205.235107,-0.002147,0.002842,0.072179,-0.178883,-0.009113,0.721787,-205.235107,0.070904,0.000000
180.510010,-0.044685,-205.279587,-0.002169,0.002803,0.071208,-0.198770,-0.010126,0.712075,-205.279587,0.070176,0.000000
180.950012,-0.021599,-205.324066,-0.002203,0.002772,0.070401,-0.096076,-0.004894,0.704013,-205.324066,0.069438,0.000000
181.390015,-0.029045,-205.368546,-0.002229,0.002760,0.070115,-0.129199,-0.006582,0.701152,-205.368546,0.068710,0.000000
181.830002,-0.025696,-205.368546,-0.002264,0.002712,0.068892,-0.114301,-0.005823,0.688919,-205.368546,0.067973,0.000000
182.270004,-0.055115,-205.413025,-0.002285,0.002686,0.068224,-0.245163,-0.012489,0.682242,-205.413025,0.067236,0.000000
182.710007,-0.018990,-205.546478,-0.002324,0.002653,0.067392,-0.084470,-0.004303,0.673923,-205.546478,0.066507,0.000000
183.150009,-0.030533,-205.546478,-0.002350,0.002633,0.066889,-0.135817,-0.006919,0.668889,-205.546478,0.065770,0.000000
183.590012,-0.033142,-205.590958,-0.002363,0.002610,0.066291,-0.147423,-0.007510,0.662909,-205.590958,0.065042,0.000000
183.700012,0.009308,-205.724396,-0.002376,0.002602,0.066083,0.041403,0.002109,0.660828,-205.724396,0.066004,0.000000