File: Data/compression 21/AutoNoHeating-10-21-reverse-2-3_09132024_170557.csv
Time (sec),S:Load (lbs),S:HL1 (DIM),S:LVDT (in),S:Position (in),Ch:Position (mm),Ch:Load (N),Ch:Stress (MPa),Ch:Strain (mm/mm),Ch:HL1 (DIM),Set Point (),Cycles ()
0.210000,-0.018990,-376.887085,-0.008951,-0.004174,-0.106010,-0.084470,-0.004303,-1.060096,-376.887085,-0.105741,0.000000
0.580000,-0.043198,-376.931580,-0.008955,-0.004075,-0.103512,-0.192153,-0.009789,-1.035116,-376.931580,-0.102688,0.000000
0.950000,0.005959,-377.020538,-0.008817,-0.003851,-0.097805,0.026505,0.001350,-0.978055,-377.020538,-0.096531,0.000000
1.320000,0.001488,-376.976074,-0.008541,-0.003609,-0.091657,0.006618,0.000337,-0.916573,-376.976074,-0.090356,0.000000
1.690000,-0.008194,-376.976074,-0.008300,-0.003359,-0.085318,-0.036449,-0.001857,-0.853176,-376.976074,-0.084199,0.000000
2.060000,-0.022346,-377.020538,-0.008063,-0.003116,-0.079143,-0.099402,-0.005064,-0.791429,-377.020538,-0.078042,0.000000
2.430000,-0.054741,-377.020538,-0.007804,-0.002882,-0.073211,-0.243500,-0.012404,-0.732112,-377.020538,-0.071867,0.000000
2.800000,-0.077080,-377.065033,-0.007562,-0.002634,-0.066906,-0.342868,-0.017467,-0.669063,-377.065033,-0.065710,0.000000
3.170000,-0.011169,-377.065033,-0.007299,-0.002389,-0.060679,-0.049684,-0.002531,-0.606794,-377.065033,-0.059535,0.000000
3.540000,-0.000374,-377.065033,-0.007045,-0.002143,-0.054444,-0.001663,-0.000085,-0.544442,-377.065033,-0.053378,0.000000
3.910000,0.024948,-377.020538,-0.006795,-0.001901,-0.048296,0.110975,0.005653,-0.482960,-377.020538,-0.047220,0.000000
4.280000,-0.023834,-377.198456,-0.006558,-0.001664,-0.042260,-0.106020,-0.005401,-0.422599,-377.198456,-0.041046,0.000000
4.650000,-0.035378,-377.198456,-0.006312,-0.001421,-0.036094,-0.157367,-0.008017,-0.360935,-377.198456,-0.034888,0.000000
5.020000,0.000374,-377.153992,-0.006058,-0.001183,-0.030041,0.001663,0.000085,-0.300407,-377.153992,-0.028714,0.000000
5.390000,0.007072,-377.198456,-0.005816,-0.000938,-0.023831,0.031460,0.001603,-0.238312,-377.198456,-0.022556,0.000000
5.760000,0.020851,-377.198456,-0.005553,-0.000689,-0.017509,0.092750,0.004725,-0.175089,-377.198456,-0.016399,0.000000
6.130000,0.003349,-377.198456,-0.005303,-0.000444,-0.011283,0.014898,0.000759,-0.112828,-377.198456,-0.010225,0.000000
6.500000,-0.029793,-377.287415,-0.005079,-0.000215,-0.005472,-0.132525,-0.006751,-0.054722,-377.287415,-0.004067,0.000000
6.870000,-0.034256,-377.331909,-0.004812,0.000037,0.000928,-0.152378,-0.007763,0.009281,-377.331909,0.002090,0.000000
7.240000,0.161240,-377.242950,-0.004579,0.000014,0.000347,0.717230,0.036537,0.003475,-377.242950,0.000425,0.000000
7.610000,0.125862,-377.331909,-0.004566,0.000011,0.000269,0.559863,0.028521,0.002687,-377.331909,0.000425,0.000000
7.980000,0.109474,-377.331909,-0.004562,0.000011,0.000269,0.486965,0.024807,0.002687,-377.331909,0.000815,0.000000
8.350000,0.086761,-377.287415,-0.004575,0.000021,0.000529,0.385934,0.019660,0.005291,-377.287415,0.001431,0.000000
8.720000,0.105751,-377.376404,-0.004566,0.000037,0.000945,0.470404,0.023964,0.009455,-377.376404,0.002047,0.000000
9.090000,0.190651,-377.331909,-0.004544,0.000059,0.001500,0.848058,0.043202,0.015003,-377.331909,0.002662,0.000000
9.460000,0.287102,-377.509827,-0.004510,0.000086,0.002185,1.277092,0.065058,0.021854,-377.509827,0.003278,0.000000
9.830001,0.355614,-377.465363,-0.004488,0.000116,0.002940,1.581849,0.080583,0.029401,-377.465363,0.003894,0.000000
10.200001,0.398064,-377.465363,-0.004449,0.000142,0.003617,1.770676,0.090203,0.036168,-377.465363,0.004510,0.000000
10.570001,0.479988,-377.509827,-0.004424,0.000166,0.004224,2.135094,0.108767,0.042239,-377.509827,0.005126,0.000000
10.940001,0.554459,-377.465363,-0.004406,0.000192,0.004883,2.466355,0.125642,0.048825,-377.465363,0.005741,0.000000
11.310000,0.618507,-377.598785,-0.004398,0.000209,0.005308,2.751258,0.140156,0.053079,-377.598785,0.006365,0.000000
11.680000,0.763367,-377.598785,-0.004368,0.000239,0.006062,3.395625,0.172981,0.060619,-377.598785,0.006982,0.000000
12.050000,0.840820,-377.598785,-0.004346,0.000265,0.006730,3.740155,0.190533,0.067295,-377.598785,0.007597,0.000000
12.420001,0.901138,-377.554321,-0.004312,0.000288,0.007303,4.008463,0.204201,0.073026,-377.554321,0.008212,0.000000
12.790001,1.022537,-377.643280,-0.004299,0.000313,0.007961,4.548473,0.231710,0.079611,-377.643280,0.008829,0.000000
13.160001,1.063492,-377.687744,-0.004273,0.000329,0.008369,4.730648,0.240991,0.083692,-377.687744,0.009444,0.000000
13.530001,1.156219,-377.643280,-0.004234,0.000352,0.008932,5.143121,0.262003,0.089324,-377.643280,0.010060,0.000000
13.900001,1.349480,-377.687744,-0.004225,0.000388,0.009852,6.002785,0.305796,0.098521,-377.687744,0.010676,0.000000
14.270000,1.376289,-377.732239,-0.004199,0.000411,0.010450,6.122041,0.311872,0.104501,-377.732239,0.011300,0.000000
14.640000,1.452621,-377.732239,-0.004161,0.000434,0.011022,6.461583,0.329169,0.110224,-377.732239,0.011916,0.000000
15.010001,1.512947,-377.821198,-0.004148,0.000454,0.011526,6.729925,0.342839,0.115258,-377.821198,0.012532,0.000000
15.380001,1.612747,-377.821198,-0.004118,0.000475,0.012072,7.173858,0.365454,0.120723,-377.821198,0.013147,0.000000
15.750001,1.772865,-377.821198,-0.004092,0.000507,0.012887,7.886099,0.401737,0.128868,-377.821198,0.013763,0.000000
16.120001,1.777336,-377.821198,-0.004070,0.000531,0.013486,7.905986,0.402750,0.134856,-377.821198,0.014379,0.000000
16.490002,1.848831,-377.910156,-0.004053,0.000558,0.014171,8.224011,0.418951,0.141706,-377.910156,0.014994,0.000000
16.860001,1.888298,-377.910156,-0.004031,0.000578,0.014682,8.399570,0.427894,0.146824,-377.910156,0.015610,0.000000
17.230001,1.974693,-377.910156,-0.004001,0.000599,0.015211,8.783875,0.447472,0.152115,-377.910156,0.016226,0.000000
17.600000,2.128105,-377.865692,-0.003975,0.000628,0.015949,9.466285,0.482236,0.159488,-377.865692,0.016850,0.000000
17.970001,2.093475,-377.910156,-0.003936,0.000651,0.016538,9.312243,0.474388,0.165385,-377.910156,0.017466,0.000000
18.340000,2.179123,-377.999115,-0.003932,0.000675,0.017136,9.693223,0.493796,0.171365,-377.999115,0.018082,0.000000
18.710001,2.218964,-377.999115,-0.003902,0.000700,0.017778,9.870443,0.502824,0.177784,-377.999115,0.018697,0.000000
19.080002,2.237587,-377.999115,-0.003880,0.000718,0.018247,9.953284,0.507044,0.182470,-377.999115,0.019314,0.000000
19.450001,2.239449,-378.043610,-0.003867,0.000732,0.018585,9.961565,0.507466,0.185846,-378.043610,0.019929,0.000000
19.820002,2.444626,-378.043610,-0.003833,0.000774,0.019660,10.874239,0.553960,0.196603,-378.043610,0.020544,0.000000
20.190001,2.403290,-378.088074,-0.003807,0.000795,0.020189,10.690367,0.544593,0.201894,-378.088074,0.021161,0.000000
20.560001,2.520958,-378.132568,-0.003773,0.000822,0.020883,11.213781,0.571257,0.208828,-378.132568,0.021776,0.000000
20.930000,2.502716,-378.132568,-0.003760,0.000838,0.021273,11.132637,0.567124,0.212734,-378.132568,0.022401,0.000000
21.300001,2.573463,-378.177032,-0.003742,0.000864,0.021949,11.447337,0.583155,0.219494,-378.177032,0.023017,0.000000
21.670000,2.734703,-378.177032,-0.003708,0.000897,0.022791,12.164567,0.619693,0.227911,-378.177032,0.023632,0.000000
22.040001,2.686668,-378.221527,-0.003686,0.000914,0.023216,11.950898,0.608808,0.232158,-378.221527,0.024248,0.000000
22.410002,2.657623,-378.266022,-0.003648,0.000928,0.023572,11.821699,0.602226,0.235716,-378.266022,0.024864,0.000000
22.780001,2.834496,-378.221527,-0.003630,0.000957,0.024300,12.608466,0.642306,0.242998,-378.221527,0.025479,0.000000
23.150002,2.920517,-378.310486,-0.003613,0.000984,0.024994,12.991108,0.661799,0.249939,-378.310486,0.026095,0.000000
23.520000,3.013985,-378.399445,-0.003583,0.001017,0.025843,13.406874,0.682979,0.258433,-378.399445,0.026711,0.000000
23.890001,2.968552,-378.354980,-0.003548,0.001038,0.026372,13.204777,0.672683,0.263724,-378.354980,0.027326,0.000000
24.260000,2.998718,-378.354980,-0.003523,0.001058,0.026867,13.338965,0.679519,0.268667,-378.354980,0.027951,0.000000
24.630001,3.161438,-378.354980,-0.003510,0.001086,0.027596,14.062778,0.716392,0.275957,-378.354980,0.028567,0.000000
25.000002,3.226234,-378.399445,-0.003488,0.001110,0.028194,14.351007,0.731075,0.281937,-378.399445,0.029182,0.000000
25.370001,3.325661,-378.488403,-0.003458,0.001138,0.028904,14.793278,0.753605,0.289045,-378.488403,0.029798,0.000000
25.740002,3.306297,-378.488403,-0.003432,0.001162,0.029503,14.707145,0.749218,0.295033,-378.488403,0.030414,0.000000
26.110001,3.302940,-378.488403,-0.003423,0.001181,0.029989,14.692212,0.748457,0.299892,-378.488403,0.031029,0.000000
26.480001,3.483543,-378.488403,-0.003376,0.001208,0.030691,15.495575,0.789382,0.306910,-378.488403,0.031646,0.000000
26.850000,3.450027,-378.488403,-0.003367,0.001222,0.031038,15.346489,0.781787,0.310384,-378.488403,0.032261,0.000000
27.220001,3.585205,-378.532898,-0.003337,0.001255,0.031871,15.947788,0.812419,0.318711,-378.532898,0.032876,0.000000
27.590002,3.715157,-378.577362,-0.003303,0.001282,0.032556,16.525843,0.841866,0.325562,-378.577362,0.033501,0.000000
27.960001,3.699890,-378.488403,-0.003277,0.001305,0.033154,16.457933,0.838407,0.331542,-378.488403,0.034117,0.000000
28.330002,3.819054,-378.532898,-0.003268,0.001331,0.033813,16.987999,0.865410,0.338135,-378.532898,0.034732,0.000000
28.700001,3.809746,-378.577362,-0.003229,0.001350,0.034290,16.946596,0.863301,0.342904,-378.577362,0.035349,0.000000
29.070002,3.860016,-378.666351,-0.003221,0.001372,0.034837,17.170208,0.874692,0.348369,-378.666351,0.035964,0.000000
29.440001,4.089020,-378.710815,-0.003169,0.001408,0.035756,18.188868,0.926585,0.357559,-378.710815,0.036579,0.000000
29.810001,4.005608,-378.666351,-0.003147,0.001426,0.036233,17.817833,0.907684,0.362328,-378.666351,0.037196,0.000000
30.180002,4.102798,-378.710815,-0.003143,0.001450,0.036822,18.250158,0.929707,0.368225,-378.710815,0.037811,0.000000
30.550001,4.116577,-378.755310,-0.003104,0.001465,0.037213,18.311449,0.932830,0.372131,-378.755310,0.038427,0.000000
30.920002,4.379845,-378.755310,-0.003078,0.001500,0.038106,19.482523,0.992487,0.381063,-378.755310,0.039051,0.000000
31.290001,4.399956,-378.755310,-0.003053,0.001527,0.038791,19.571981,0.997044,0.387914,-378.755310,0.039667,0.000000
31.660002,4.473679,-378.755310,-0.003022,0.001549,0.039355,19.899916,1.013750,0.393546,-378.755310,0.040283,0.000000
32.030003,4.567146,-378.799774,-0.003009,0.001575,0.040014,20.315681,1.034930,0.400139,-378.799774,0.040899,0.000000
32.400002,4.583534,-378.888733,-0.002997,0.001598,0.040586,20.388578,1.038644,0.405862,-378.888733,0.041514,0.000000
32.770000,4.655029,-378.844269,-0.002958,0.001618,0.041098,20.706604,1.054845,0.410979,-378.844269,0.042130,0.000000
33.140003,4.843445,-378.844269,-0.002932,0.001648,0.041861,21.544718,1.097540,0.418609,-378.844269,0.042746,0.000000
33.510002,4.813286,-378.844269,-0.002902,0.001671,0.042451,21.410564,1.090706,0.424506,-378.844269,0.043361,0.000000
33.880001,4.873238,-378.977692,-0.002876,0.001694,0.043023,21.677244,1.104291,0.430229,-378.977692,0.043977,0.000000
34.250000,4.923508,-379.022186,-0.002846,0.001715,0.043569,21.900856,1.115683,0.435694,-379.022186,0.044602,0.000000
34.620003,5.098892,-378.977692,-0.002820,0.001741,0.044220,22.681005,1.155426,0.442197,-378.977692,0.045217,0.000000
34.990002,5.105972,-378.977692,-0.002811,0.001757,0.044636,22.712500,1.157030,0.446360,-378.977692,0.045833,0.000000
35.360001,5.306305,-378.977692,-0.002768,0.001791,0.045486,23.603622,1.202426,0.454861,-378.977692,0.046449,0.000000
35.730003,5.380409,-379.066650,-0.002746,0.001819,0.046198,23.933256,1.219218,0.461977,-379.066650,0.047064,0.000000
36.100002,5.419136,-379.111145,-0.002725,0.001840,0.046726,24.105520,1.227994,0.467260,-379.111145,0.047681,0.000000
36.470001,5.451157,-379.066650,-0.002699,0.001861,0.047282,24.247955,1.235250,0.472817,-379.066650,0.048296,0.000000
36.840000,5.610535,-379.022186,-0.002677,0.001886,0.047905,24.956905,1.271365,0.479054,-379.022186,0.048911,0.000000
37.210003,5.815338,-379.111145,-0.002643,0.001914,0.048625,25.867916,1.317775,0.486253,-379.111145,0.049536,0.000000
37.580002,5.812737,-379.155640,-0.002621,0.001938,0.049232,25.856344,1.317185,0.492324,-379.155640,0.050152,0.000000
37.950001,5.970245,-379.155640,-0.002591,0.001966,0.049944,26.556978,1.352877,0.499440,-379.155640,0.050768,0.000000
38.320004,5.904335,-379.200104,-0.002561,0.001983,0.050378,26.263794,1.337941,0.503777,-379.200104,0.051383,0.000000
38.690002,5.997429,-379.200104,-0.002561,0.002005,0.050923,26.677896,1.359037,0.509235,-379.200104,0.051999,0.000000
39.060001,6.322884,-379.200104,-0.002531,0.002037,0.051748,28.125591,1.432786,0.517478,-379.200104,0.052615,0.000000
39.430000,6.318047,-379.244598,-0.002514,0.002059,0.052303,28.104074,1.431690,0.523027,-379.244598,0.053231,0.000000
39.800003,6.429382,-379.333557,-0.002475,0.002085,0.052953,28.599321,1.456919,0.529530,-379.333557,0.053846,0.000000
40.170002,6.557854,-379.289062,-0.002449,0.002109,0.053560,29.170790,1.486031,0.535600,-379.289062,0.054462,0.000000
40.540001,6.539604,-379.289062,-0.002449,0.002127,0.054020,29.089613,1.481895,0.540195,-379.289062,0.055086,0.000000
40.910004,6.957405,-379.422516,-0.002406,0.002156,0.054765,30.948084,1.576571,0.547652,-379.422516,0.055702,0.000000
41.280003,6.966713,-379.422516,-0.002380,0.002182,0.055416,30.989487,1.578680,0.554162,-379.422516,0.056318,0.000000
41.650002,6.855003,-379.422516,-0.002345,0.002199,0.055867,30.492579,1.553366,0.558666,-379.422516,0.056934,0.000000
42.020000,6.974907,-379.422516,-0.002333,0.002222,0.056448,31.025936,1.580537,0.564479,-379.422516,0.057549,0.000000
42.390003,7.210617,-379.422516,-0.002324,0.002248,0.057107,32.074425,1.633949,0.571073,-379.422516,0.058165,0.000000
42.760002,7.517082,-379.511475,-0.002289,0.002276,0.057818,33.437653,1.703395,0.578181,-379.511475,0.058781,0.000000
43.130001,7.491760,-379.511475,-0.002251,0.002301,0.058434,33.325012,1.697657,0.584342,-379.511475,0.059396,0.000000
43.500004,7.446335,-379.511475,-0.002225,0.002320,0.058919,33.122952,1.687364,0.589195,-379.511475,0.060013,0.000000
43.870003,7.721886,-379.511475,-0.002203,0.002342,0.059474,34.348663,1.749804,0.594743,-379.511475,0.060636,0.000000
44.240002,8.086067,-379.555969,-0.002199,0.002371,0.060221,35.968624,1.832329,0.602207,-379.555969,0.061252,0.000000
44.610001,8.130005,-379.644928,-0.002156,0.002395,0.060827,36.164066,1.842286,0.608270,-379.644928,0.061868,0.000000
44.980003,8.361252,-379.644928,-0.002121,0.002426,0.061608,37.192707,1.894687,0.616082,-379.644928,0.062484,0.000000
45.350002,8.318428,-379.600433,-0.002108,0.002445,0.062111,37.002216,1.884983,0.621109,-379.600433,0.063099,0.000000
45.720001,8.218262,-379.600433,-0.002100,0.002459,0.062467,36.556652,1.862285,0.624667,-379.600433,0.063715,0.000000
46.090004,8.702347,-379.733887,-0.002057,0.002491,0.063273,38.709972,1.971980,0.632728,-379.733887,0.064331,0.000000
46.460003,8.962631,-379.733887,-0.002039,0.002519,0.063993,39.867775,2.030961,0.639927,-379.733887,0.064947,0.000000
46.830002,9.268723,-379.689392,-0.002005,0.002546,0.064678,41.229336,2.100322,0.646778,-379.689392,0.065563,0.000000
47.200001,9.275795,-379.733887,-0.001988,0.002569,0.065242,41.260796,2.101925,0.652417,-379.733887,0.066187,0.000000
47.570004,9.485069,-379.733887,-0.001962,0.002591,0.065805,42.191696,2.149347,0.658049,-379.733887,0.066803,0.000000
47.940002,9.541298,-379.778351,-0.001944,0.002610,0.066291,42.441814,2.162089,0.662909,-379.778351,0.067418,0.000000
48.310001,10.001923,-379.778351,-0.001919,0.002636,0.066950,44.490772,2.266468,0.669502,-379.778351,0.068034,0.000000
48.680004,9.896545,-379.867310,-0.001897,0.002653,0.067384,44.022034,2.242589,0.673840,-379.867310,0.068650,0.000000
49.050003,10.559738,-379.867310,-0.001880,0.002690,0.068320,46.972061,2.392871,0.683204,-379.867310,0.069266,0.000000
49.420002,10.521759,-379.822845,-0.001850,0.002710,0.068832,46.803123,2.384265,0.688321,-379.822845,0.069881,0.000000
49.790001,10.818535,-379.911804,-0.001815,0.002733,0.069422,48.123245,2.451515,0.694218,-379.911804,0.070497,0.000000
50.160004,10.892265,-379.956299,-0.001789,0.002751,0.069864,48.451218,2.468223,0.698639,-379.956299,0.071113,0.000000
50.530003,11.626961,-380.045258,-0.001768,0.002782,0.070670,51.719303,2.634707,0.706700,-380.045258,0.071737,0.000000
50.900002,12.041039,-379.956299,-0.001746,0.002813,0.071460,53.561214,2.728538,0.714596,-379.956299,0.072353,0.000000
51.270004,11.882408,-379.956299,-0.001720,0.002832,0.071936,52.855591,2.692592,0.719365,-379.956299,0.072968,0.000000
51.640003,11.845169,-380.000763,-0.001720,0.002848,0.072327,52.689945,2.684154,0.723271,-380.000763,0.073584,0.000000
52.010002,12.780937,-380.000763,-0.001673,0.002881,0.073185,56.852448,2.896202,0.731855,-380.000763,0.074200,0.000000
52.380001,13.118309,-380.045258,-0.001656,0.002909,0.073896,58.353153,2.972651,0.738963,-380.045258,0.074816,0.000000
52.750004,13.403549,-380.045258,-0.001617,0.002933,0.074495,59.621964,3.037288,0.744951,-380.045258,0.075431,0.000000
53.120003,13.834007,-380.178680,-0.001608,0.002958,0.075137,61.536739,3.134831,0.751370,-380.178680,0.076047,0.000000
53.490002,14.122223,-380.178680,-0.001578,0.002983,0.075770,62.818787,3.200141,0.757698,-380.178680,0.076663,0.000000
53.860004,14.142708,-380.134216,-0.001556,0.003001,0.076229,62.909904,3.204783,0.762293,-380.134216,0.077288,0.000000
54.230003,15.005493,-380.134216,-0.001539,0.003029,0.076932,66.747765,3.400293,0.769318,-380.134216,0.077903,0.000000
54.600002,15.324989,-380.178680,-0.001522,0.003055,0.077599,68.168961,3.472692,0.775994,-380.178680,0.078519,0.000000
54.970001,15.730499,-380.312134,-0.001492,0.003079,0.078216,69.972755,3.564582,0.782156,-380.312134,0.079135,0.000000
55.340004,16.277519,-380.267639,-0.001475,0.003107,0.078909,72.406021,3.688539,0.789090,-380.267639,0.079750,0.000000
55.710003,16.387367,-380.223175,-0.001462,0.003124,0.079343,72.894653,3.713430,0.793428,-380.223175,0.080366,0.000000
56.080002,16.646164,-380.312134,-0.001431,0.003143,0.079820,74.045837,3.772075,0.798196,-380.312134,0.080982,0.000000
56.450005,16.310661,-380.356598,-0.001427,0.003148,0.079967,72.553444,3.696049,0.799673,-380.356598,0.081598,0.000000
56.820004,18.594788,-380.356598,-0.001388,0.003201,0.081303,82.713745,4.213639,0.813026,-380.356598,0.082213,0.000000
57.190002,19.067329,-380.267639,-0.001362,0.003228,0.081997,84.815720,4.320718,0.819967,-380.267639,0.082838,0.000000
57.560001,19.274742,-380.312134,-0.001328,0.003248,0.082491,85.738335,4.367719,0.824910,-380.312134,0.083453,0.000000
57.930004,19.498535,-380.401093,-0.001324,0.003265,0.082941,86.733818,4.418431,0.829414,-380.401093,0.084069,0.000000
58.300003,20.817108,-380.445587,-0.001315,0.003298,0.083774,92.599121,4.717224,0.837741,-380.445587,0.084685,0.000000
58.670002,21.246086,-380.445587,-0.001281,0.003323,0.084399,94.507309,4.814432,0.843986,-380.445587,0.085300,0.000000
59.040001,21.806877,-380.445587,-0.001259,0.003345,0.084953,97.001831,4.941509,0.849535,-380.445587,0.085916,0.000000
59.410004,22.525925,-380.490051,-0.001229,0.003371,0.085621,100.200317,5.104447,0.856211,-380.490051,0.086532,0.000000
59.780003,22.635780,-380.490051,-0.001229,0.003387,0.086037,100.688980,5.129341,0.860375,-380.490051,0.087148,0.000000
60.150002,24.182610,-380.579010,-0.001203,0.003420,0.086879,107.569618,5.479858,0.868792,-380.579010,0.087763,0.000000
60.520004,24.916557,-380.623505,-0.001190,0.003443,0.087452,110.834381,5.646173,0.874515,-380.623505,0.088388,0.000000
60.890003,25.649017,-380.579010,-0.001164,0.003469,0.088102,114.092529,5.812150,0.881018,-380.579010,0.089003,0.000000
61.260002,26.600426,-380.623505,-0.001160,0.003495,0.088761,118.324600,6.027743,0.887611,-380.623505,0.089619,0.000000
61.630001,26.820496,-380.579010,-0.001134,0.003512,0.089194,119.303520,6.077611,0.891941,-380.579010,0.090235,0.000000
62.000004,27.221542,-380.667969,-0.001130,0.003529,0.089628,121.087471,6.168490,0.896278,-380.667969,0.090851,0.000000
62.370003,28.914352,-380.579010,-0.001095,0.003559,0.090408,128.617462,6.552086,0.904083,-380.579010,0.091467,0.000000
62.740002,29.984550,-380.667969,-0.001095,0.003588,0.091146,133.377945,6.794596,0.911456,-380.667969,0.092082,0.000000
63.110004,31.001122,-380.623505,-0.001082,0.003613,0.091761,137.899872,7.024955,0.917610,-380.623505,0.092698,0.000000
63.480003,31.140388,-380.756927,-0.001043,0.003627,0.092126,138.519363,7.056513,0.921259,-380.756927,0.093323,0.000000
63.850002,32.581848,-380.756927,-0.001022,0.003654,0.092819,144.931305,7.383152,0.928192,-380.756927,0.093938,0.000000
64.220001,34.311516,-380.756927,-0.001026,0.003685,0.093591,152.625244,7.775101,0.935914,-380.756927,0.094553,0.000000
64.590004,35.160896,-380.756927,-0.001000,0.003709,0.094207,156.403473,7.967573,0.942068,-380.756927,0.095170,0.000000
64.960007,35.393257,-380.756927,-0.001000,0.003724,0.094580,157.437073,8.020226,0.945800,-380.756927,0.095785,0.000000
65.330002,37.008240,-380.845917,-0.000983,0.003752,0.095308,164.620865,8.386188,0.953082,-380.845917,0.096401,0.000000
65.700005,38.243393,-380.890381,-0.000966,0.003777,0.095933,170.115112,8.666077,0.959327,-380.890381,0.097017,0.000000
66.070000,40.205429,-380.845917,-0.000944,0.003808,0.096731,178.842682,9.110681,0.967306,-380.845917,0.097632,0.000000
66.440002,41.170616,-380.890381,-0.000936,0.003830,0.097285,183.136047,9.329395,0.972854,-380.890381,0.098248,0.000000
66.810005,41.973450,-380.979340,-0.000918,0.003851,0.097806,186.707230,9.511319,0.978062,-380.979340,0.098873,0.000000
67.180000,43.370224,-380.979340,-0.000905,0.003876,0.098456,192.920395,9.827833,0.984565,-380.979340,0.099488,0.000000
67.550003,44.193535,-380.979340,-0.000888,0.003894,0.098899,196.582657,10.014398,0.988985,-380.979340,0.100104,0.000000
67.920006,46.564056,-380.979340,-0.000871,0.003929,0.099792,207.127274,10.551565,0.997918,-380.979340,0.100720,0.000000
68.290001,47.768311,-380.934875,-0.000871,0.003953,0.100416,212.484055,10.824453,1.004163,-380.934875,0.101335,0.000000
68.660004,49.003845,-381.023834,-0.000858,0.003973,0.100919,217.979996,11.104430,1.009189,-381.023834,0.101951,0.000000
69.030006,50.713776,-381.023834,-0.000841,0.004000,0.101596,225.586136,11.491906,1.015957,-381.023834,0.102567,0.000000
69.400002,51.714714,-381.068298,-0.000815,0.004019,0.102082,230.038544,11.718721,1.020816,-381.068298,0.103183,0.000000
69.770004,53.428375,-381.023834,-0.000815,0.004045,0.102732,237.661285,12.107042,1.027319,-381.023834,0.103798,0.000000
70.140007,55.446632,-381.157257,-0.000789,0.004072,0.103417,246.638931,12.564386,1.034170,-381.157257,0.104423,0.000000
70.510002,56.848244,-381.157257,-0.000785,0.004096,0.104050,252.873611,12.881996,1.040498,-381.157257,0.105038,0.000000
70.880005,58.229370,-381.157257,-0.000767,0.004117,0.104571,259.017181,13.194964,1.045706,-381.157257,0.105655,0.000000
71.250000,59.633957,-381.201752,-0.000767,0.004137,0.105091,265.265076,13.513247,1.050906,-381.201752,0.106270,0.000000
71.620003,61.114143,-381.157257,-0.000763,0.004160,0.105655,271.849274,13.848662,1.056546,-381.157257,0.106885,0.000000
71.990005,63.875275,-381.246246,-0.000746,0.004195,0.106565,284.131409,14.474344,1.065652,-381.246246,0.107502,0.000000
72.360001,65.699905,-381.246246,-0.000733,0.004219,0.107172,292.247772,14.887812,1.071716,-381.246246,0.108117,0.000000
72.730003,65.898758,-381.246246,-0.000729,0.004218,0.107128,293.132324,14.932872,1.071284,-381.246246,0.018805,0.000000
73.100006,65.037460,-381.290710,-0.000720,0.004218,0.107128,289.301086,14.737700,1.071284,-381.290710,294.500458,0.000000
73.470001,66.093140,-381.290710,-0.000698,0.004227,0.107371,293.996979,14.976919,1.073714,-381.290710,294.500458,0.000000
73.840004,65.524521,-381.246246,-0.000716,0.004227,0.107371,291.467621,14.848068,1.073714,-381.246246,294.500458,0.000000
74.210007,65.042664,-381.335205,-0.000694,0.004235,0.107570,289.324219,14.738878,1.075705,-381.335205,294.500458,0.000000
74.580002,65.186401,-381.379669,-0.000694,0.004241,0.107718,289.963593,14.771450,1.077181,-381.379669,294.500458,0.000000
74.950005,65.210983,-381.290710,-0.000703,0.004244,0.107805,290.072937,14.777020,1.078052,-381.290710,294.500458,0.000000
75.320007,64.953674,-381.424164,-0.000711,0.004244,0.107805,288.928375,14.718713,1.078052,-381.424164,294.500458,0.000000
75.690002,65.610168,-381.424164,-0.000698,0.004254,0.108039,291.848602,14.867476,1.080391,-381.424164,294.500458,0.000000
76.060005,65.476486,-381.424164,-0.000690,0.004254,0.108039,291.253967,14.837184,1.080391,-381.424164,294.500458,0.000000
76.430000,65.266846,-381.468628,-0.000686,0.004254,0.108048,290.321442,14.789679,1.080482,-381.468628,294.500458,0.000000
76.800003,65.090714,-381.468628,-0.000690,0.004254,0.108048,289.537964,14.749766,1.080482,-381.468628,294.500458,0.000000
77.170006,64.947342,-381.513123,-0.000690,0.004254,0.108048,288.900208,14.717278,1.080482,-381.513123,294.500458,0.000000
77.540001,64.760788,-381.602081,-0.000686,0.004254,0.108048,288.070374,14.675004,1.080482,-381.602081,294.500458,0.000000
77.910004,64.641998,-381.602081,-0.000681,0.004254,0.108048,287.541962,14.648087,1.080482,-381.602081,294.500458,0.000000
78.280006,64.483734,-381.557587,-0.000668,0.004254,0.108048,286.837982,14.612224,1.080482,-381.557587,294.500458,0.000000
78.650002,64.362350,-381.602081,-0.000677,0.004254,0.108048,286.298035,14.584718,1.080482,-381.602081,294.500458,0.000000
79.020004,64.280426,-381.602081,-0.000686,0.004254,0.108056,285.933624,14.566153,1.080565,-381.602081,294.500458,0.000000
79.390007,64.173187,-381.646545,-0.000686,0.004254,0.108056,285.456604,14.541852,1.080565,-381.646545,294.500458,0.000000
79.760002,64.057373,-381.691040,-0.000686,0.004254,0.108056,284.941437,14.515608,1.080565,-381.691040,294.500458,0.000000
80.130005,66.267410,-381.646545,-0.000647,0.004062,0.103166,294.772156,15.016410,1.031656,-381.646545,294.500458,0.000000
80.500008,65.807892,-381.691040,-0.000647,0.004099,0.104102,292.728119,14.912281,1.041020,-381.691040,294.500458,0.000000
80.870003,65.655228,-381.735535,-0.000651,0.004130,0.104900,292.049042,14.877687,1.048999,-381.735535,294.500458,0.000000
81.240005,65.557281,-381.779999,-0.000647,0.004157,0.105585,291.613342,14.855493,1.055849,-381.779999,294.500458,0.000000
81.610001,65.516327,-381.824493,-0.000638,0.004227,0.107363,291.431183,14.846212,1.073631,-381.824493,294.500458,0.000000
81.980003,65.419510,-381.779999,-0.000638,0.004230,0.107449,291.000519,14.824273,1.074494,-381.779999,294.500458,0.000000
82.350006,65.304443,-381.824493,-0.000647,0.004231,0.107467,290.488678,14.798199,1.074668,-381.824493,294.500458,0.000000
82.720001,65.254929,-381.824493,-0.000660,0.004234,0.107554,290.268433,14.786978,1.075539,-381.824493,294.500458,0.000000
83.090004,65.205765,-381.868958,-0.000634,0.004240,0.107701,290.049713,14.775837,1.077007,-381.868958,294.500458,0.000000
83.460007,65.176727,-381.868958,-0.000647,0.004246,0.107840,289.920563,14.769257,1.078400,-381.868958,294.500458,0.000000
83.830002,65.107834,-381.868958,-0.000651,0.004248,0.107891,289.614105,14.753646,1.078915,-381.868958,294.500458,0.000000
84.200005,65.326416,-381.913452,-0.000660,0.004257,0.108126,290.586426,14.803178,1.081261,-381.913452,294.500458,0.000000
84.570007,65.255661,-382.002411,-0.000651,0.004257,0.108126,290.271667,14.787145,1.081261,-382.002411,294.500458,0.000000
84.940002,65.185654,-382.002411,-0.000642,0.004257,0.108134,289.960266,14.771280,1.081344,-382.002411,294.500458,0.000000
85.310005,65.120499,-381.957916,-0.000647,0.004257,0.108134,289.670441,14.756516,1.081344,-381.957916,294.500458,0.000000
85.680000,65.050110,-382.002411,-0.000647,0.004257,0.108134,289.357330,14.740566,1.081344,-382.002411,294.500458,0.000000
86.050003,65.339828,-382.046875,-0.000647,0.004266,0.108352,290.646088,14.806217,1.083517,-382.046875,294.500458,0.000000
86.420006,65.386368,-382.046875,-0.000651,0.004266,0.108352,290.853088,14.816763,1.083517,-382.046875,294.500458,0.000000
86.790001,65.337585,-382.091370,-0.000647,0.004266,0.108352,290.636108,14.805709,1.083517,-382.091370,294.500458,0.000000
87.160004,65.298111,-382.046875,-0.000647,0.004266,0.108352,290.460510,14.796764,1.083517,-382.046875,294.500458,0.000000
87.530006,65.255295,-382.091370,-0.000660,0.004266,0.108352,290.270050,14.787061,1.083517,-382.091370,294.500458,0.000000
87.900002,65.212479,-382.135864,-0.000647,0.004266,0.108368,290.079590,14.777359,1.083684,-382.135864,294.500458,0.000000
88.270004,65.175980,-382.135864,-0.000642,0.004266,0.108368,289.917236,14.769088,1.083684,-382.135864,294.500458,0.000000
88.640007,65.151398,-382.224823,-0.000642,0.004267,0.108377,289.807892,14.763517,1.083774,-382.224823,294.500458,0.000000
89.010002,65.082886,-382.135864,-0.000634,0.004267,0.108377,289.503143,14.747993,1.083774,-382.135864,294.500458,0.000000
89.380005,65.044159,-382.224823,-0.000655,0.004267,0.108377,289.330872,14.739217,1.083774,-382.224823,294.500458,0.000000
89.750008,65.268707,-382.313782,-0.000647,0.004271,0.108490,290.329712,14.790100,1.084902,-382.313782,294.500458,0.000000
90.120003,65.238541,-382.269287,-0.000642,0.004271,0.108490,290.195526,14.783265,1.084902,-382.269287,294.500458,0.000000
90.490005,65.234818,-382.269287,-0.000629,0.004271,0.108490,290.178955,14.782421,1.084902,-382.269287,294.500458,0.000000
90.860001,65.210236,-382.313782,-0.000647,0.004271,0.108490,290.069611,14.776851,1.084902,-382.313782,294.500458,0.000000
91.230003,65.147675,-382.313782,-0.000655,0.004271,0.108490,289.791321,14.762674,1.084902,-382.313782,294.500458,0.000000
91.600006,65.121979,-382.358246,-0.000651,0.004271,0.108490,289.677032,14.756851,1.084902,-382.358246,294.500458,0.000000
91.970001,65.083633,-382.402740,-0.000664,0.004271,0.108490,289.506470,14.748162,1.084902,-382.402740,294.500458,0.000000
92.340004,65.046768,-382.402740,-0.000655,0.004271,0.108490,289.342468,14.739808,1.084902,-382.402740,294.500458,0.000000
92.710007,65.464935,-382.402740,-0.000655,0.004278,0.108664,291.202576,14.834566,1.086636,-382.402740,294.500458,0.000000
93.080002,65.488770,-382.447205,-0.000642,0.004278,0.108664,291.308594,14.839967,1.086636,-382.447205,294.500458,0.000000
93.450005,65.487656,-382.491699,-0.000660,0.004278,0.108664,291.303650,14.839715,1.086636,-382.491699,294.500458,0.000000
93.820007,65.480957,-382.491699,-0.000655,0.004278,0.108664,291.273834,14.838197,1.086636,-382.491699,294.500458,0.000000
94.190002,65.460846,-382.536194,-0.000664,0.004278,0.108664,291.184387,14.833639,1.086636,-382.536194,294.500458,0.000000
94.560005,65.418762,-382.580658,-0.000647,0.004278,0.108664,290.997192,14.824103,1.086636,-382.580658,294.500458,0.000000
94.930008,65.386368,-382.580658,-0.000655,0.004278,0.108664,290.853088,14.816763,1.086636,-382.580658,294.500458,0.000000
95.300003,65.357697,-382.669617,-0.000634,0.004278,0.108664,290.725555,14.810266,1.086636,-382.669617,294.500458,0.000000
95.670006,65.336105,-382.669617,-0.000647,0.004278,0.108664,290.629517,14.805373,1.086636,-382.669617,294.500458,0.000000
96.040001,65.310028,-382.625153,-0.000651,0.004278,0.108664,290.513519,14.799464,1.086636,-382.625153,294.500458,0.000000
96.410004,65.288437,-382.625153,-0.000647,0.004278,0.108664,290.417480,14.794571,1.086636,-382.625153,294.500458,0.000000
96.780006,65.266098,-382.714111,-0.000651,0.004278,0.108664,290.318115,14.789509,1.086636,-382.714111,294.500458,0.000000
97.150002,65.241516,-382.669617,-0.000638,0.004278,0.108664,290.208771,14.783938,1.086636,-382.669617,294.500458,0.000000
97.520004,65.220657,-382.714111,-0.000638,0.004278,0.108664,290.115967,14.779213,1.086636,-382.714111,294.500458,0.000000
97.890007,65.208374,-382.669617,-0.000638,0.004278,0.108664,290.061340,14.776429,1.086636,-382.669617,294.500458,0.000000
98.260002,65.159592,-382.714111,-0.000642,0.004278,0.108672,289.844330,14.765374,1.086719,-382.714111,294.500458,0.000000
98.630005,65.137619,-382.758575,-0.000647,0.004278,0.108672,289.746613,14.760396,1.086719,-382.758575,294.500458,0.000000
99.000008,65.126083,-382.803070,-0.000638,0.004279,0.108681,289.695282,14.757781,1.086810,-382.803070,294.500458,0.000000
99.370003,65.213959,-382.758575,-0.000651,0.004281,0.108733,290.086182,14.777695,1.087332,-382.758575,294.500458,0.000000
99.740005,65.215820,-382.803070,-0.000647,0.004281,0.108733,290.094452,14.778116,1.087332,-382.803070,294.500458,0.000000
100.110008,65.214340,-382.892029,-0.000647,0.004281,0.108733,290.087860,14.777781,1.087332,-382.892029,294.500458,0.000000
100.480003,65.205017,-382.892029,-0.000647,0.004281,0.108733,290.046417,14.775668,1.087332,-382.892029,294.500458,0.000000
100.850006,65.180450,-382.936493,-0.000647,0.004281,0.108733,289.937134,14.770102,1.087332,-382.936493,294.500458,0.000000
101.220001,65.155869,-382.847534,-0.000647,0.004281,0.108742,289.827789,14.764531,1.087415,-382.847534,294.500458,0.000000
101.590004,65.160339,-382.936493,-0.000642,0.004281,0.108742,289.847656,14.765544,1.087415,-382.936493,294.500458,0.000000
101.960007,65.152145,-382.936493,-0.000638,0.004281,0.108742,289.811218,14.763687,1.087415,-382.936493,294.500458,0.000000
102.330002,65.124588,-383.025482,-0.000647,0.004282,0.108751,289.688629,14.757442,1.087506,-383.025482,294.500458,0.000000
102.700005,65.165176,-383.025482,-0.000647,0.004283,0.108776,289.869171,14.766640,1.087764,-383.025482,294.500458,0.000000
103.070007,65.185654,-382.980988,-0.000642,0.004283,0.108776,289.960266,14.771280,1.087764,-382.980988,294.500458,0.000000
103.440002,65.185287,-383.069946,-0.000642,0.004283,0.108776,289.958649,14.771197,1.087764,-383.069946,294.500458,0.000000
103.810005,65.176346,-383.025482,-0.000664,0.004283,0.108785,289.918854,14.769171,1.087847,-383.025482,294.500458,0.000000
104.180008,65.167786,-383.114441,-0.000647,0.004283,0.108785,289.880798,14.767232,1.087847,-383.114441,294.500458,0.000000
104.550003,65.160339,-383.158905,-0.000647,0.004283,0.108794,289.847656,14.765544,1.087938,-383.158905,294.500458,0.000000
104.920006,65.164429,-383.114441,-0.000638,0.004283,0.108794,289.865845,14.766471,1.087938,-383.114441,294.500458,0.000000
105.290009,65.165558,-383.158905,-0.000647,0.004283,0.108794,289.870880,14.766726,1.087938,-383.158905,294.500458,0.000000
105.660004,65.136139,-383.203400,-0.000655,0.004283,0.108794,289.740021,14.760059,1.087938,-383.203400,294.500458,0.000000
106.030006,65.132034,-383.247864,-0.000651,0.004284,0.108811,289.721771,14.759130,1.088112,-383.247864,294.500458,0.000000
106.400002,65.142471,-383.203400,-0.000647,0.004284,0.108811,289.768188,14.761495,1.088112,-383.203400,294.500458,0.000000
106.770004,65.130173,-383.247864,-0.000651,0.004284,0.108811,289.713470,14.758708,1.088112,-383.247864,294.500458,0.000000
107.140007,65.116776,-383.247864,-0.000647,0.004284,0.108811,289.653870,14.755672,1.088112,-383.247864,294.500458,0.000000
107.510002,65.215820,-383.292358,-0.000642,0.004287,0.108880,290.094452,14.778116,1.088801,-383.292358,294.500458,0.000000
107.880005,65.266846,-383.292358,-0.000642,0.004287,0.108880,290.321442,14.789679,1.088801,-383.292358,294.500458,0.000000
108.250008,65.285461,-383.292358,-0.000642,0.004287,0.108880,290.404236,14.793897,1.088801,-383.292358,294.500458,0.000000
108.620003,65.292160,-383.336823,-0.000651,0.004287,0.108880,290.434021,14.795415,1.088801,-383.336823,294.500458,0.000000
108.990005,65.281357,-383.381317,-0.000638,0.004287,0.108880,290.385986,14.792967,1.088801,-383.381317,294.500458,0.000000
109.360008,65.274292,-383.470276,-0.000647,0.004287,0.108880,290.354553,14.791366,1.088801,-383.470276,294.500458,0.000000
109.730003,65.280243,-383.381317,-0.000634,0.004287,0.108880,290.381012,14.792715,1.088801,-383.381317,294.500458,0.000000
110.100006,65.273544,-383.381317,-0.000647,0.004287,0.108880,290.351227,14.791197,1.088801,-383.381317,294.500458,0.000000
110.470009,65.245239,-383.425812,-0.000638,0.004287,0.108880,290.225311,14.784782,1.088801,-383.425812,294.500458,0.000000
110.840004,65.232956,-383.514771,-0.000638,0.004287,0.108880,290.170685,14.782000,1.088801,-383.514771,294.500458,0.000000
111.210007,65.225876,-383.559235,-0.000638,0.004287,0.108880,290.139191,14.780395,1.088801,-383.559235,294.500458,0.000000
111.580002,65.222519,-383.559235,-0.000647,0.004287,0.108880,290.124268,14.779634,1.088801,-383.559235,294.500458,0.000000
111.950005,65.200180,-383.559235,-0.000642,0.004287,0.108880,290.024872,14.774571,1.088801,-383.559235,294.500458,0.000000
112.320007,65.164429,-383.603729,-0.000642,0.004287,0.108880,289.865845,14.766471,1.088801,-383.603729,294.500458,0.000000
112.690002,65.159973,-383.648193,-0.000651,0.004287,0.108880,289.846039,14.765461,1.088801,-383.648193,294.500458,0.000000
113.060005,65.138000,-383.648193,-0.000642,0.004287,0.108880,289.748291,14.760482,1.088801,-383.648193,294.500458,0.000000
113.430008,65.110077,-383.692688,-0.000647,0.004287,0.108880,289.624084,14.754154,1.088801,-383.692688,294.500458,0.000000
113.800003,65.096298,-383.648193,-0.000647,0.004287,0.108889,289.562805,14.751032,1.088892,-383.648193,294.500458,0.000000
114.170006,65.215454,-383.692688,-0.000660,0.004290,0.108959,290.092834,14.778033,1.089588,-383.692688,294.500458,0.000000
114.540009,65.255295,-383.737152,-0.000634,0.004290,0.108959,290.270050,14.787061,1.089588,-383.737152,294.500458,0.000000
114.910004,65.267578,-383.737152,-0.000647,0.004290,0.108959,290.324677,14.789845,1.089588,-383.737152,294.500458,0.000000
115.280006,65.249344,-383.781647,-0.000642,0.004290,0.108959,290.243591,14.785712,1.089588,-383.781647,294.500458,0.000000
115.650009,65.260513,-383.781647,-0.000651,0.004290,0.108959,290.293274,14.788243,1.089588,-383.781647,294.500458,0.000000
116.020004,65.265717,-383.826141,-0.000651,0.004290,0.108959,290.316406,14.789423,1.089588,-383.826141,294.500458,0.000000
116.390007,65.251572,-383.870605,-0.000642,0.004290,0.108959,290.253479,14.786218,1.089588,-383.870605,294.500458,0.000000
116.760002,65.227737,-383.870605,-0.000638,0.004290,0.108959,290.147461,14.780817,1.089588,-383.870605,294.500458,0.000000
117.130005,65.226990,-383.781647,-0.000642,0.004290,0.108959,290.144135,14.780647,1.089588,-383.781647,294.500458,0.000000
117.500008,65.222519,-383.826141,-0.000660,0.004290,0.108959,290.124268,14.779634,1.089588,-383.826141,294.500458,0.000000
117.870003,65.200180,-383.915100,-0.000647,0.004290,0.108959,290.024872,14.774571,1.089588,-383.915100,294.500458,0.000000
118.240005,65.191254,-384.004059,-0.000642,0.004290,0.108959,289.985168,14.772549,1.089588,-384.004059,294.500458,0.000000
118.610008,65.199814,-383.959564,-0.000638,0.004290,0.108959,290.023254,14.774489,1.089588,-383.959564,294.500458,0.000000
118.980003,65.175232,-383.959564,-0.000634,0.004290,0.108959,289.913910,14.768919,1.089588,-383.959564,294.500458,0.000000
119.350006,65.160706,-384.004059,-0.000642,0.004290,0.108959,289.849304,14.765627,1.089588,-384.004059,294.500458,0.000000
119.720009,65.154755,-384.093018,-0.000642,0.004290,0.108967,289.822815,14.764278,1.089671,-384.093018,294.500458,0.000000
120.090004,65.140610,-384.048523,-0.000647,0.004290,0.108967,289.759918,14.761073,1.089671,-384.048523,294.500458,0.000000
120.460007,65.143951,-384.093018,-0.000642,0.004290,0.108967,289.774780,14.761830,1.089671,-384.093018,294.500458,0.000000
120.830009,65.120117,-384.004059,-0.000651,0.004290,0.108967,289.668762,14.756430,1.089671,-384.004059,294.500458,0.000000
121.200005,65.111938,-384.048523,-0.000642,0.004290,0.108967,289.632355,14.754577,1.089671,-384.048523,294.500458,0.000000
121.570007,65.099274,-384.181976,-0.000647,0.004290,0.108967,289.576019,14.751707,1.089671,-384.181976,294.500458,0.000000
121.940002,65.083252,-384.137482,-0.000642,0.004290,0.108967,289.504761,14.748075,1.089671,-384.137482,294.500458,0.000000
122.310005,65.066498,-384.181976,-0.000634,0.004290,0.108967,289.430237,14.744279,1.089671,-384.181976,294.500458,0.000000
122.680008,65.585220,-384.226440,-0.000638,0.004298,0.109175,291.737640,14.861823,1.091753,-384.226440,294.500458,0.000000
123.050003,65.636230,-384.226440,-0.000642,0.004297,0.109150,291.964539,14.873382,1.091496,-384.226440,294.500458,0.000000
123.420006,65.665649,-384.270935,-0.000642,0.004297,0.109150,292.095398,14.880049,1.091496,-384.270935,294.500458,0.000000
123.790009,65.654846,-384.315430,-0.000642,0.004297,0.109150,292.047333,14.877601,1.091496,-384.315430,294.500458,0.000000
124.160004,65.658203,-384.270935,-0.000647,0.004297,0.109150,292.062286,14.878362,1.091496,-384.270935,294.500458,0.000000
124.530006,65.669739,-384.270935,-0.000642,0.004297,0.109150,292.113586,14.880975,1.091496,-384.270935,294.500458,0.000000
124.900009,65.685760,-384.404388,-0.000647,0.004297,0.109150,292.184845,14.884606,1.091496,-384.404388,294.500458,0.000000
125.270004,65.670120,-384.359894,-0.000638,0.004297,0.109150,292.115295,14.881063,1.091496,-384.359894,294.500458,0.000000
125.640007,65.664154,-384.359894,-0.000638,0.004297,0.109150,292.088745,14.879709,1.091496,-384.359894,294.500458,0.000000
126.010010,65.655594,-384.404388,-0.000634,0.004297,0.109150,292.050659,14.877770,1.091496,-384.404388,294.500458,0.000000
126.380005,65.659698,-384.359894,-0.000647,0.004297,0.109150,292.068939,14.878700,1.091496,-384.359894,294.500458,0.000000
126.750008,65.653732,-384.493347,-0.000647,0.004297,0.109150,292.042389,14.877348,1.091496,-384.493347,294.500458,0.000000
127.120003,65.651871,-384.493347,-0.000629,0.004297,0.109150,292.034119,14.876926,1.091496,-384.493347,294.500458,0.000000
127.490005,65.634735,-384.448853,-0.000634,0.004297,0.109150,291.957886,14.873043,1.091496,-384.448853,294.500458,0.000000
127.860008,65.628036,-384.493347,-0.000642,0.004297,0.109150,291.928101,14.871526,1.091496,-384.493347,294.500458,0.000000
128.230011,65.623199,-384.537811,-0.000660,0.004297,0.109150,291.906555,14.870430,1.091496,-384.537811,294.500458,0.000000
128.600006,65.587448,-384.582306,-0.000647,0.004297,0.109150,291.747528,14.862329,1.091496,-384.582306,294.500458,0.000000
128.970001,65.602722,-384.537811,-0.000634,0.004297,0.109150,291.815491,14.865789,1.091496,-384.537811,294.500458,0.000000
129.340012,65.601974,-384.537811,-0.000638,0.004297,0.109150,291.812164,14.865620,1.091496,-384.537811,294.500458,0.000000
129.710007,65.585587,-384.582306,-0.000638,0.004297,0.109150,291.739258,14.861906,1.091496,-384.582306,294.500458,0.000000
130.080002,65.583359,-384.626770,-0.000638,0.004297,0.109150,291.729340,14.861402,1.091496,-384.626770,294.500458,0.000000
130.450012,65.553558,-384.671265,-0.000651,0.004297,0.109150,291.596802,14.854649,1.091496,-384.671265,294.500458,0.000000
130.820007,65.569199,-384.671265,-0.000647,0.004297,0.109150,291.666351,14.858193,1.091496,-384.671265,294.500458,0.000000
131.190002,65.569946,-384.671265,-0.000634,0.004297,0.109150,291.669678,14.858362,1.091496,-384.671265,294.500458,0.000000
131.560013,65.561020,-384.715759,-0.000647,0.004297,0.109150,291.629974,14.856339,1.091496,-384.715759,294.500458,0.000000
131.930008,65.523026,-384.715759,-0.000655,0.004297,0.109150,291.460968,14.847730,1.091496,-384.715759,294.500458,0.000000
132.300003,65.539413,-384.760223,-0.000651,0.004297,0.109150,291.533875,14.851443,1.091496,-384.760223,294.500458,0.000000
132.670013,65.536804,-384.804718,-0.000638,0.004297,0.109150,291.522278,14.850852,1.091496,-384.804718,294.500458,0.000000
133.040009,65.524521,-384.760223,-0.000642,0.004297,0.109150,291.467621,14.848068,1.091496,-384.760223,294.500458,0.000000
133.410004,65.473129,-384.804718,-0.000647,0.004293,0.109045,291.239014,14.836423,1.090451,-384.804718,0.108941,0.000000
133.779999,65.354340,-384.893677,-0.000647,0.004277,0.108629,290.710632,14.809505,1.086288,-384.893677,0.108325,0.000000
134.150009,65.300720,-384.849182,-0.000638,0.004257,0.108117,290.472107,14.797355,1.081170,-384.849182,0.107710,0.000000
134.520004,65.241150,-384.938141,-0.000629,0.004236,0.107597,290.207123,14.783856,1.075970,-384.938141,0.107085,0.000000
134.889999,65.212845,-384.849182,-0.000638,0.004219,0.107172,290.081207,14.777442,1.071716,-384.849182,0.106470,0.000000
135.260010,65.202042,-384.893677,-0.000629,0.004189,0.106400,290.033173,14.774994,1.064002,-384.893677,0.105854,0.000000
135.630005,65.184540,-384.893677,-0.000651,0.004164,0.105776,289.955322,14.771028,1.057757,-384.893677,0.105238,0.000000
136.000000,65.175232,-385.027100,-0.000647,0.004140,0.105169,289.913910,14.768919,1.051686,-385.027100,0.104622,0.000000
136.370010,65.168152,-384.938141,-0.000629,0.004119,0.104614,289.882416,14.767315,1.046137,-384.938141,0.104007,0.000000
136.740005,65.127945,-384.938141,-0.000634,0.004098,0.104085,289.703583,14.758204,1.040846,-384.938141,0.103391,0.000000
137.110001,64.683701,-385.027100,-0.000634,0.004072,0.103434,287.727478,14.657537,1.034344,-385.027100,0.102775,0.000000
137.480011,63.914383,-385.071594,-0.000617,0.004047,0.102784,284.305389,14.483207,1.027841,-385.071594,0.102160,0.000000
137.850006,63.156975,-385.027100,-0.000604,0.004028,0.102306,280.936249,14.311575,1.023065,-385.027100,0.101535,0.000000
138.220001,61.943413,-385.071594,-0.000608,0.004007,0.101786,275.538055,14.036578,1.017864,-385.071594,0.100919,0.000000
138.590012,60.745117,-384.982635,-0.000612,0.003987,0.101266,270.207764,13.765040,1.012664,-384.982635,0.100304,0.000000
138.960007,58.947304,-385.116089,-0.000599,0.003960,0.100590,262.210693,13.357650,1.005896,-385.116089,0.099688,0.000000
139.330002,56.949158,-385.205048,-0.000612,0.003936,0.099974,253.322510,12.904863,0.999742,-385.205048,0.099072,0.000000
139.700012,55.023613,-385.205048,-0.000604,0.003913,0.099402,244.757248,12.468529,0.994019,-385.205048,0.098456,0.000000
140.070007,53.190430,-385.205048,-0.000591,0.003889,0.098768,236.602844,12.053124,0.987683,-385.205048,0.097840,0.000000
140.440002,50.235275,-385.205048,-0.000604,0.003865,0.098179,223.457672,11.383476,0.981787,-385.205048,0.097225,0.000000
140.810013,48.123184,-385.249512,-0.000617,0.003845,0.097667,214.062607,10.904869,0.976669,-385.249512,0.096600,0.000000
141.180008,45.611526,-385.294006,-0.000604,0.003822,0.097077,202.890198,10.335720,0.970773,-385.294006,0.095985,0.000000
141.550003,42.437798,-385.294006,-0.000612,0.003792,0.096306,188.772751,9.616543,0.963059,-385.294006,0.095369,0.000000
141.920013,40.308945,-385.294006,-0.000608,0.003774,0.095872,179.303146,9.134138,0.958721,-385.294006,0.094753,0.000000
142.290009,37.590630,-385.338470,-0.000604,0.003749,0.095230,167.211472,8.518158,0.952302,-385.338470,0.094138,0.000000
142.660004,34.629890,-385.294006,-0.000591,0.003721,0.094510,154.041443,7.847245,0.945103,-385.294006,0.093522,0.000000
143.030014,32.959061,-385.382965,-0.000595,0.003708,0.094189,146.609222,7.468630,0.941894,-385.382965,0.092906,0.000000
143.400009,29.061440,-385.382965,-0.000608,0.003669,0.093201,129.271744,6.585416,0.932008,-385.382965,0.092290,0.000000
143.770004,26.756081,-385.338470,-0.000608,0.003651,0.092724,119.016991,6.063015,0.927239,-385.338470,0.091675,0.000000
144.139999,24.206444,-385.382965,-0.000604,0.003627,0.092134,107.675636,5.485259,0.921342,-385.382965,0.091050,0.000000
144.510010,21.989342,-385.427429,-0.000599,0.003605,0.091579,97.813477,4.982856,0.915793,-385.427429,0.090435,0.000000
144.880005,18.722145,-385.471924,-0.000595,0.003575,0.090816,83.280258,4.242499,0.908163,-385.471924,0.089819,0.000000
145.250000,15.926743,-385.427429,-0.000595,0.003551,0.090200,70.845688,3.609051,0.902001,-385.427429,0.089203,0.000000
145.620010,13.416206,-385.471924,-0.000608,0.003529,0.089628,59.678265,3.040156,0.896278,-385.471924,0.088587,0.000000
145.990005,10.957428,-385.560883,-0.000608,0.003508,0.089108,48.741074,2.482989,0.891078,-385.560883,0.087972,0.000000
146.360001,8.129265,-385.605377,-0.000608,0.003481,0.088405,36.160774,1.842118,0.884053,-385.605377,0.087356,0.000000
146.730011,5.712196,-385.560883,-0.000608,0.003460,0.087885,25.409119,1.294402,0.878845,-385.560883,0.086740,0.000000
147.100006,3.957199,-385.560883,-0.000608,0.003439,0.087347,17.602501,0.896714,0.873470,-385.560883,0.086125,0.000000
147.470001,0.514244,-385.694336,-0.000612,0.003410,0.086610,2.287472,0.116529,0.866098,-385.694336,0.085500,0.000000
147.840012,-1.872662,-385.649841,-0.000612,0.003382,0.085907,-8.330015,-0.424351,0.859073,-385.649841,0.084885,0.000000
148.210007,-0.332527,-385.694336,-0.000655,0.003359,0.085318,-1.479155,-0.075352,0.853176,-385.694336,0.084268,0.000000
148.580002,-0.066658,-385.649841,-0.000677,0.003332,0.084624,-0.296510,-0.015105,0.846242,-385.649841,0.083653,0.000000
148.950012,-0.053253,-385.694336,-0.000703,0.003308,0.084025,-0.236882,-0.012067,0.840254,-385.694336,0.083037,0.000000
149.320007,-0.070755,-385.827759,-0.000737,0.003285,0.083436,-0.314734,-0.016033,0.834357,-385.827759,0.082421,0.000000
149.690002,-0.042450,-385.783295,-0.000780,0.003256,0.082690,-0.188827,-0.009619,0.826901,-385.783295,0.081806,0.000000
150.060013,-0.068886,-385.827759,-0.000780,0.003239,0.082265,-0.306419,-0.015610,0.822654,-385.827759,0.081190,0.000000
150.430008,-0.043938,-385.738800,-0.000802,0.003215,0.081658,-0.195445,-0.009956,0.816584,-385.738800,0.080574,0.000000
150.800003,-0.046173,-385.783295,-0.000836,0.003192,0.081069,-0.205388,-0.010463,0.810687,-385.783295,0.079950,0.000000
151.170013,-0.065910,-385.872253,-0.000880,0.003164,0.080357,-0.293184,-0.014935,0.803571,-385.872253,0.079334,0.000000
151.540009,-0.017876,-385.872253,-0.000918,0.003134,0.079611,-0.079515,-0.004051,0.796115,-385.872253,0.078718,0.000000
151.910004,-0.021973,-385.872253,-0.000944,0.003120,0.079256,-0.097739,-0.004979,0.792557,-385.872253,0.078103,0.000000
152.280014,-0.052505,-385.916718,-0.000974,0.003091,0.078502,-0.233556,-0.011898,0.785017,-385.916718,0.077487,0.000000
152.650009,-0.058838,-385.872253,-0.000979,0.003075,0.078103,-0.261724,-0.013333,0.781028,-385.872253,0.076871,0.000000
153.020004,-0.042450,-385.961212,-0.001018,0.003042,0.077270,-0.188827,-0.009619,0.772701,-385.961212,0.076255,0.000000
153.300003,-0.004471,-385.961212,-0.001039,0.003030,0.076958,-0.019887,-0.001013,0.769575,-385.961212,0.076819,0.000000