File: Data/compression 21/AutoNoHeating-10-21-reverse-2-2_09132024_170234.csv
Time (sec),S:Load (lbs),S:HL1 (DIM),S:LVDT (in),S:Position (in),Ch:Position (mm),Ch:Load (N),Ch:Stress (MPa),Ch:Strain (mm/mm),Ch:HL1 (DIM),Set Point (),Cycles ()
0.110000,-0.014526,-364.832764,-0.011654,-0.007050,-0.179065,-0.064617,-0.003292,-1.790649,-364.832764,-0.178796,0.000000
0.510000,0.004097,-364.788269,-0.011650,-0.006990,-0.177556,0.018224,0.000928,-1.775562,-364.788269,-0.176905,0.000000
0.910000,-0.020477,-364.832764,-0.011499,-0.006745,-0.171312,-0.091088,-0.004640,-1.713119,-364.832764,-0.170245,0.000000
1.310000,0.015640,-364.921722,-0.011232,-0.006484,-0.164686,0.069571,0.003544,-1.646861,-364.921722,-0.163568,0.000000
1.710000,-0.008934,-364.877228,-0.010973,-0.006223,-0.158061,-0.039741,-0.002024,-1.580610,-364.877228,-0.156907,0.000000
2.110000,-0.060699,-364.921722,-0.010705,-0.005960,-0.151383,-0.270005,-0.013755,-1.513829,-364.921722,-0.150247,0.000000
2.510000,-0.087883,-365.010681,-0.010425,-0.005700,-0.144784,-0.390923,-0.019915,-1.447836,-365.010681,-0.143587,0.000000
2.910000,-0.028671,-365.055176,-0.010154,-0.005435,-0.138037,-0.127536,-0.006497,-1.380366,-365.055176,-0.136926,0.000000
3.310000,-0.032028,-365.055176,-0.009895,-0.005169,-0.131281,-0.142469,-0.007258,-1.312806,-365.055176,-0.130249,0.000000
3.710000,-0.009308,-365.010681,-0.009606,-0.004908,-0.124656,-0.041403,-0.002109,-1.246555,-365.010681,-0.123589,0.000000
4.110000,-0.034630,-365.010681,-0.009373,-0.004661,-0.118394,-0.154041,-0.007847,-1.183938,-365.010681,-0.116928,0.000000
4.510000,-0.028671,-365.010681,-0.009084,-0.004391,-0.111534,-0.127536,-0.006497,-1.115340,-365.010681,-0.110268,0.000000
4.910000,-0.025322,-365.099640,-0.008808,-0.004129,-0.104874,-0.112638,-0.005738,-1.048741,-365.099640,-0.103608,0.000000
5.310000,-0.000374,-365.144135,-0.008541,-0.003868,-0.098257,-0.001663,-0.000085,-0.982566,-365.144135,-0.096930,0.000000
5.710000,0.005585,-365.144135,-0.008291,-0.003607,-0.091622,0.024842,0.001266,-0.916225,-365.144135,-0.090270,0.000000
6.110000,-0.014526,-365.144135,-0.008011,-0.003345,-0.084963,-0.064617,-0.003292,-0.849626,-365.144135,-0.083610,0.000000
6.510000,-0.029419,-365.233093,-0.007731,-0.003075,-0.078094,-0.130862,-0.006666,-0.780937,-365.233093,-0.076949,0.000000
6.910000,-0.032394,-365.188599,-0.007472,-0.002820,-0.071625,-0.144098,-0.007341,-0.716246,-365.188599,-0.070272,0.000000
7.310000,-0.002609,-365.188599,-0.007200,-0.002547,-0.064687,-0.011607,-0.000591,-0.646869,-365.188599,-0.063611,0.000000
7.710001,0.029793,-365.233093,-0.006929,-0.002286,-0.058052,0.132525,0.006751,-0.580520,-365.233093,-0.056951,0.000000
8.110001,-0.011169,-365.277557,-0.006661,-0.002025,-0.051427,-0.049684,-0.002531,-0.514269,-365.277557,-0.050291,0.000000
8.510000,-0.043571,-365.322052,-0.006385,-0.001764,-0.044810,-0.193816,-0.009873,-0.448101,-365.322052,-0.043630,0.000000
8.910001,-0.070755,-365.322052,-0.006135,-0.001502,-0.038141,-0.314734,-0.016033,-0.381411,-365.322052,-0.036953,0.000000
9.310000,0.005585,-365.322052,-0.005859,-0.001237,-0.031420,0.024842,0.001266,-0.314199,-365.322052,-0.030293,0.000000
9.710000,-0.007446,-365.277557,-0.005579,-0.000972,-0.024690,-0.033123,-0.001687,-0.246904,-365.277557,-0.023632,0.000000
10.110001,0.006699,-365.366547,-0.005307,-0.000710,-0.018030,0.029797,0.001518,-0.180297,-365.366547,-0.016971,0.000000
10.510000,0.007072,-365.411011,-0.005049,-0.000459,-0.011656,0.031460,0.001603,-0.116560,-365.411011,-0.010312,0.000000
10.910001,0.138519,-365.411011,-0.004829,-0.000000,-0.000000,0.616165,0.031389,-0.000000,-365.411011,0.000156,0.000000
11.310000,0.132561,-365.455505,-0.004820,-0.000000,-0.000008,0.589660,0.030039,-0.000083,-365.455505,0.000156,0.000000
11.710001,0.112831,-365.411011,-0.004846,-0.000000,-0.000008,0.501898,0.025568,-0.000083,-365.411011,0.000677,0.000000
12.110001,0.082664,-365.499969,-0.004829,-0.000000,-0.000000,0.367710,0.018732,-0.000000,-365.499969,0.001344,0.000000
12.510000,0.164215,-365.455505,-0.004799,0.000043,0.001093,0.730465,0.037212,0.010931,-365.455505,0.002012,0.000000
12.910001,0.226776,-365.499969,-0.004773,0.000062,0.001587,1.008751,0.051388,0.015874,-365.499969,0.002680,0.000000
13.310000,0.333649,-365.499969,-0.004751,0.000089,0.002272,1.484143,0.075606,0.022725,-365.499969,0.003347,0.000000
13.710001,0.353012,-365.588928,-0.004730,0.000107,0.002715,1.570276,0.079994,0.027145,-365.588928,0.004015,0.000000
14.110001,0.425621,-365.588928,-0.004717,0.000144,0.003660,1.893257,0.096447,0.036600,-365.588928,0.004683,0.000000
14.510000,0.563400,-365.633423,-0.004700,0.000172,0.004362,2.506130,0.127668,0.043625,-365.633423,0.005342,0.000000
14.910001,0.688889,-365.544464,-0.004661,0.000194,0.004926,3.064329,0.156104,0.049257,-365.544464,0.006010,0.000000
15.310000,0.845284,-365.722382,-0.004631,0.000218,0.005542,3.760009,0.191544,0.055418,-365.722382,0.006678,0.000000
15.710001,0.898163,-365.588928,-0.004613,0.000238,0.006044,3.995228,0.203527,0.060445,-365.588928,0.007346,0.000000
16.110001,1.100731,-365.722382,-0.004575,0.000278,0.007060,4.896296,0.249429,0.070596,-365.722382,0.008013,0.000000
16.510000,1.203506,-365.633423,-0.004566,0.000295,0.007502,5.353464,0.272718,0.075017,-365.633423,0.008681,0.000000
16.910002,1.412781,-365.722382,-0.004544,0.000326,0.008274,6.284363,0.320141,0.082738,-365.722382,0.009349,0.000000
17.310001,1.584442,-365.722382,-0.004506,0.000354,0.008993,7.047951,0.359040,0.089929,-365.722382,0.010016,0.000000
17.710001,1.676422,-365.722382,-0.004475,0.000379,0.009635,7.457098,0.379883,0.096348,-365.722382,0.010676,0.000000
18.110001,1.851807,-365.766846,-0.004458,0.000411,0.010442,8.237247,0.419625,0.104418,-365.766846,0.011343,0.000000
18.510000,1.999268,-365.811340,-0.004424,0.000438,0.011127,8.893187,0.453041,0.111268,-365.811340,0.012011,0.000000
18.910002,2.014908,-365.811340,-0.004398,0.000454,0.011534,8.962758,0.456585,0.115341,-365.811340,0.012679,0.000000
19.310001,2.261421,-365.900299,-0.004368,0.000488,0.012402,10.059304,0.512445,0.124016,-365.900299,0.013347,0.000000
19.710001,2.357117,-365.900299,-0.004342,0.000516,0.013095,10.484979,0.534130,0.130950,-365.900299,0.014015,0.000000
20.110001,2.429733,-365.944794,-0.004329,0.000541,0.013737,10.807993,0.550585,0.137369,-365.944794,0.014682,0.000000
20.510000,2.571976,-365.989258,-0.004307,0.000567,0.014396,11.440720,0.582818,0.143962,-365.989258,0.015350,0.000000
20.910002,2.653900,-365.944794,-0.004268,0.000589,0.014959,11.805138,0.601382,0.149594,-365.944794,0.016009,0.000000
21.310001,2.921631,-366.033752,-0.004247,0.000621,0.015784,12.996063,0.662051,0.157838,-366.033752,0.016677,0.000000
21.710001,2.951424,-366.078217,-0.004217,0.000649,0.016495,13.128588,0.668802,0.164946,-366.078217,0.017345,0.000000
22.110001,3.048615,-366.033752,-0.004191,0.000673,0.017084,13.560915,0.690826,0.170843,-366.033752,0.018012,0.000000
22.510000,3.214317,-366.167175,-0.004161,0.000701,0.017796,14.297997,0.728375,0.177958,-366.167175,0.018680,0.000000
22.910002,3.312622,-366.122711,-0.004148,0.000722,0.018333,14.735279,0.750651,0.183333,-366.122711,0.019348,0.000000
23.310001,3.488754,-366.122711,-0.004105,0.000748,0.019001,15.518754,0.790563,0.190009,-366.122711,0.020016,0.000000
23.710001,3.602333,-366.122711,-0.004092,0.000779,0.019799,16.023977,0.816300,0.197988,-366.122711,0.020684,0.000000
24.110001,3.698776,-366.167175,-0.004053,0.000807,0.020510,16.452978,0.838155,0.205103,-366.167175,0.021351,0.000000
24.510000,3.731171,-366.211670,-0.004036,0.000830,0.021074,16.597076,0.845495,0.210735,-366.211670,0.022011,0.000000
24.910002,3.922569,-366.211670,-0.004027,0.000851,0.021612,17.448460,0.888867,0.216118,-366.211670,0.022678,0.000000
25.310001,4.203339,-366.256165,-0.003988,0.000885,0.022478,18.697384,0.952490,0.224785,-366.256165,0.023346,0.000000
25.710001,4.198128,-366.300629,-0.003949,0.000907,0.023033,18.674206,0.951309,0.230334,-366.300629,0.024014,0.000000
26.110001,4.290100,-366.300629,-0.003941,0.000931,0.023650,19.083319,0.972151,0.236495,-366.300629,0.024681,0.000000
26.510002,4.456924,-366.345123,-0.003915,0.000960,0.024395,19.825390,1.009953,0.243952,-366.345123,0.025349,0.000000
26.910002,4.474426,-366.389587,-0.003876,0.000980,0.024881,19.903242,1.013919,0.248811,-366.389587,0.026017,0.000000
27.310001,4.798019,-366.389587,-0.003846,0.001012,0.025705,21.342657,1.087247,0.257047,-366.389587,0.026685,0.000000
27.710001,4.876587,-366.434082,-0.003833,0.001041,0.026450,21.692142,1.105050,0.264504,-366.434082,0.027344,0.000000
28.110001,5.033356,-366.434082,-0.003803,0.001068,0.027127,22.389484,1.140575,0.271271,-366.434082,0.028011,0.000000
28.510002,4.913452,-366.567505,-0.003781,0.001085,0.027552,21.856127,1.113404,0.275518,-366.567505,0.028679,0.000000
28.910002,5.135017,-366.478546,-0.003760,0.001108,0.028133,22.841698,1.163612,0.281331,-366.478546,0.029347,0.000000
29.310001,5.514091,-366.523041,-0.003725,0.001148,0.029157,24.527905,1.249511,0.291566,-366.523041,0.030015,0.000000
29.710001,5.370354,-366.523041,-0.003695,0.001165,0.029599,23.888527,1.216940,0.295986,-366.523041,0.030683,0.000000
30.110001,5.631760,-366.656494,-0.003673,0.001193,0.030292,25.051317,1.276175,0.302920,-366.656494,0.031350,0.000000
30.510002,5.589684,-366.612000,-0.003665,0.001207,0.030657,24.864155,1.266640,0.306569,-366.612000,0.032018,0.000000
30.910002,5.906570,-366.656494,-0.003639,0.001245,0.031611,26.273737,1.338448,0.316107,-366.656494,0.032677,0.000000
31.310001,6.059616,-366.656494,-0.003596,0.001276,0.032417,26.954519,1.373129,0.324169,-366.656494,0.033345,0.000000
31.710001,6.001900,-366.700958,-0.003574,0.001298,0.032972,26.697783,1.360050,0.329717,-366.700958,0.034013,0.000000
32.110001,6.172447,-366.700958,-0.003557,0.001325,0.033657,27.456417,1.398697,0.336568,-366.700958,0.034680,0.000000
32.510002,6.264793,-366.700958,-0.003523,0.001345,0.034151,27.867193,1.419622,0.341511,-366.700958,0.035348,0.000000
32.910000,6.675522,-366.745453,-0.003501,0.001382,0.035114,29.694204,1.512695,0.351140,-366.745453,0.036016,0.000000
33.310001,6.661369,-366.834412,-0.003471,0.001407,0.035738,29.631250,1.509488,0.357385,-366.834412,0.036684,0.000000
33.710003,6.664352,-366.789917,-0.003449,0.001430,0.036320,29.644520,1.510164,0.363199,-366.789917,0.037352,0.000000
34.110001,6.913094,-366.834412,-0.003436,0.001458,0.037022,30.750977,1.566529,0.370223,-366.834412,0.038011,0.000000
34.510002,7.099655,-366.878876,-0.003402,0.001483,0.037673,31.580843,1.608805,0.376726,-366.878876,0.038679,0.000000
34.910000,7.131302,-366.878876,-0.003385,0.001507,0.038271,31.721615,1.615976,0.382706,-366.878876,0.039346,0.000000
35.310001,7.355103,-367.012329,-0.003350,0.001539,0.039095,32.717129,1.666690,0.390949,-367.012329,0.040014,0.000000
35.710003,7.295891,-366.923370,-0.003328,0.001562,0.039667,32.453743,1.653273,0.396672,-366.923370,0.040682,0.000000
36.110001,7.439255,-366.923370,-0.003303,0.001584,0.040239,33.091457,1.685759,0.402395,-366.923370,0.041349,0.000000
36.510002,7.658958,-366.923370,-0.003281,0.001611,0.040925,34.068748,1.735545,0.409246,-366.923370,0.042017,0.000000
36.910000,7.669754,-367.012329,-0.003260,0.001631,0.041436,34.116772,1.737991,0.414363,-367.012329,0.042685,0.000000
37.310001,8.055908,-367.012329,-0.003221,0.001672,0.042477,35.834469,1.825495,0.424771,-367.012329,0.043353,0.000000
37.710003,7.891319,-367.056793,-0.003208,0.001692,0.042989,35.102341,1.788198,0.429888,-367.056793,0.044012,0.000000
38.110001,8.077873,-367.101288,-0.003182,0.001714,0.043526,35.932175,1.830472,0.435263,-367.101288,0.044680,0.000000
38.510002,8.366837,-367.101288,-0.003156,0.001744,0.044307,37.217548,1.895952,0.443067,-367.101288,0.045348,0.000000
38.910004,8.531425,-367.101288,-0.003130,0.001774,0.045052,37.949677,1.933249,0.450524,-367.101288,0.046015,0.000000
39.310001,8.701973,-367.145782,-0.003117,0.001802,0.045781,38.708309,1.971895,0.457813,-367.145782,0.046683,0.000000
39.710003,8.823738,-367.145782,-0.003074,0.001830,0.046475,39.249947,1.999488,0.464747,-367.145782,0.047351,0.000000
40.110001,8.768997,-367.190247,-0.003048,0.001851,0.047004,39.006447,1.987083,0.470039,-367.190247,0.048018,0.000000
40.510002,9.148071,-367.190247,-0.003031,0.001880,0.047749,40.692654,2.072983,0.477495,-367.190247,0.048686,0.000000
40.910004,9.168556,-367.234741,-0.003009,0.001905,0.048382,40.783775,2.077625,0.483823,-367.234741,0.049345,0.000000
41.310001,9.394958,-367.323700,-0.002975,0.001935,0.049137,41.790863,2.128928,0.491370,-367.323700,0.050013,0.000000
41.710003,9.543533,-367.279205,-0.002949,0.001962,0.049831,42.451756,2.162596,0.498312,-367.279205,0.050680,0.000000
42.110001,9.397560,-367.279205,-0.002936,0.001980,0.050282,41.802437,2.129518,0.502816,-367.279205,0.051349,0.000000
42.510002,9.552467,-367.279205,-0.002910,0.002002,0.050846,42.491497,2.164620,0.508455,-367.279205,0.052017,0.000000
42.910004,10.083473,-367.323700,-0.002893,0.002038,0.051756,44.853527,2.284948,0.517562,-367.323700,0.052684,0.000000
43.310001,10.199654,-367.279205,-0.002859,0.002067,0.052511,45.370327,2.311275,0.525109,-367.279205,0.053352,0.000000
43.710003,10.236145,-367.412659,-0.002837,0.002093,0.053152,45.532646,2.319544,0.531520,-367.412659,0.054020,0.000000
44.110001,10.204865,-367.412659,-0.002815,0.002111,0.053630,45.393505,2.312455,0.536297,-367.412659,0.054679,0.000000
44.510002,10.526970,-367.412659,-0.002798,0.002140,0.054349,46.826302,2.385445,0.543488,-367.412659,0.055347,0.000000
44.910004,10.840134,-367.457123,-0.002764,0.002169,0.055095,48.219322,2.456409,0.550952,-367.457123,0.056014,0.000000
45.310001,10.855400,-367.457123,-0.002738,0.002195,0.055754,48.287231,2.459869,0.557538,-367.457123,0.056682,0.000000
45.710003,10.948120,-367.501617,-0.002712,0.002222,0.056448,48.699669,2.480879,0.564479,-367.501617,0.057349,0.000000
46.110001,10.886681,-367.546112,-0.002699,0.002242,0.056951,48.426373,2.466957,0.569506,-367.546112,0.058018,0.000000
46.510002,11.583389,-367.546112,-0.002695,0.002275,0.057783,51.525490,2.624834,0.577832,-367.546112,0.058686,0.000000
46.910004,11.431465,-367.501617,-0.002665,0.002297,0.058347,50.849697,2.590407,0.583472,-367.501617,0.059353,0.000000
47.310001,11.571098,-367.590576,-0.002652,0.002323,0.058997,51.470818,2.622048,0.589974,-367.590576,0.060012,0.000000
47.710003,12.035080,-367.635071,-0.002608,0.002356,0.059830,53.534710,2.727188,0.598301,-367.635071,0.060680,0.000000
48.110001,11.848145,-367.590576,-0.002591,0.002376,0.060350,52.703178,2.684828,0.603501,-367.590576,0.061348,0.000000
48.510002,12.353828,-367.679535,-0.002596,0.002405,0.061079,54.952572,2.799417,0.610791,-367.679535,0.062016,0.000000
48.910004,12.430908,-367.679535,-0.002552,0.002431,0.061755,55.295441,2.816884,0.617551,-367.679535,0.062683,0.000000
49.310001,12.308769,-367.635071,-0.002535,0.002456,0.062371,54.752140,2.789207,0.623713,-367.635071,0.063351,0.000000
49.710003,12.374306,-367.679535,-0.002518,0.002477,0.062909,55.043659,2.804058,0.629087,-367.679535,0.064018,0.000000
50.110001,12.725830,-367.724030,-0.002492,0.002503,0.063576,56.607319,2.883714,0.635764,-367.724030,0.064686,0.000000
50.510002,12.884834,-367.724030,-0.002471,0.002532,0.064322,57.314606,2.919745,0.643220,-367.724030,0.065355,0.000000
50.910004,13.193153,-367.812988,-0.002458,0.002561,0.065059,58.686077,2.989611,0.650593,-367.812988,0.066013,0.000000
51.310001,12.802162,-367.812988,-0.002419,0.002576,0.065433,56.946861,2.901011,0.654325,-367.812988,0.066681,0.000000
51.710003,13.427750,-367.857452,-0.002414,0.002605,0.066178,59.729614,3.042772,0.661781,-367.857452,0.067349,0.000000
52.110001,13.726021,-367.857452,-0.002389,0.002634,0.066898,61.056389,3.110361,0.668980,-367.857452,0.068017,0.000000
52.510002,14.150154,-367.901947,-0.002354,0.002669,0.067800,62.943027,3.206471,0.677996,-367.901947,0.068684,0.000000
52.910004,13.771080,-367.857452,-0.002337,0.002691,0.068355,61.256824,3.120571,0.683552,-367.857452,0.069352,0.000000
53.310001,13.795280,-367.946442,-0.002315,0.002714,0.068945,61.364471,3.126055,0.689449,-367.946442,0.070020,0.000000
53.710003,14.211594,-367.946442,-0.002298,0.002741,0.069630,63.216324,3.220393,0.696300,-367.946442,0.070687,0.000000
54.110004,14.885590,-368.035400,-0.002268,0.002772,0.070410,66.214409,3.373123,0.704104,-368.035400,0.071347,0.000000
54.510002,14.823029,-367.990906,-0.002246,0.002798,0.071061,65.936127,3.358946,0.710606,-367.990906,0.072014,0.000000
54.910004,14.835693,-367.990906,-0.002238,0.002824,0.071720,65.992462,3.361816,0.717200,-367.990906,0.072682,0.000000
55.310001,15.056137,-368.035400,-0.002212,0.002851,0.072422,66.973045,3.411770,0.724225,-368.035400,0.073350,0.000000
55.710003,15.104546,-368.124359,-0.002186,0.002871,0.072925,67.188377,3.422739,0.729251,-368.124359,0.074018,0.000000
56.110004,15.317917,-368.124359,-0.002182,0.002896,0.073558,68.137497,3.471090,0.735579,-368.124359,0.074686,0.000000
56.510002,15.688423,-368.124359,-0.002147,0.002928,0.074373,69.785591,3.555048,0.743732,-368.124359,0.075353,0.000000
56.910004,15.900673,-368.124359,-0.002134,0.002954,0.075024,70.729729,3.603144,0.750242,-368.124359,0.076021,0.000000
57.310001,16.175858,-368.213318,-0.002117,0.002981,0.075709,71.953812,3.665502,0.757093,-368.213318,0.076680,0.000000
57.710003,16.052979,-368.213318,-0.002100,0.003001,0.076221,71.407211,3.637657,0.762210,-368.213318,0.077348,0.000000
58.110004,16.737022,-368.213318,-0.002074,0.003030,0.076958,74.449997,3.792664,0.769575,-368.213318,0.078016,0.000000
58.510002,17.155945,-368.302277,-0.002057,0.003063,0.077799,76.313454,3.887593,0.777993,-368.302277,0.078683,0.000000
58.910004,16.734421,-368.257782,-0.002031,0.003082,0.078284,74.438423,3.792074,0.782845,-368.257782,0.079351,0.000000
59.310001,17.077370,-368.302277,-0.002005,0.003106,0.078892,75.963936,3.869787,0.788916,-368.302277,0.080019,0.000000
59.710003,17.565178,-368.391235,-0.002013,0.003134,0.079603,78.133812,3.980326,0.796032,-368.391235,0.080687,0.000000
60.110004,18.164703,-368.391235,-0.001979,0.003165,0.080400,80.800636,4.116181,0.804003,-368.391235,0.081355,0.000000
60.510002,18.375465,-368.391235,-0.001949,0.003193,0.081112,81.738152,4.163940,0.811118,-368.391235,0.082013,0.000000
60.910004,18.456268,-368.391235,-0.001923,0.003218,0.081745,82.097580,4.182250,0.817446,-368.391235,0.082682,0.000000
61.310001,18.550850,-368.435730,-0.001919,0.003243,0.082369,82.518303,4.203683,0.823692,-368.435730,0.083349,0.000000
61.710003,18.924339,-368.480194,-0.001901,0.003267,0.082994,84.179665,4.288317,0.829937,-368.480194,0.084017,0.000000
62.110004,19.621796,-368.524689,-0.001876,0.003297,0.083739,87.282104,4.446362,0.837393,-368.524689,0.084685,0.000000
62.510002,19.887665,-368.524689,-0.001863,0.003325,0.084451,88.464752,4.506609,0.844508,-368.524689,0.085352,0.000000
62.910004,20.393349,-368.569153,-0.001837,0.003352,0.085144,90.714142,4.621199,0.851442,-368.569153,0.086020,0.000000
63.310001,20.387764,-368.613647,-0.001824,0.003372,0.085656,90.689301,4.619933,0.856560,-368.613647,0.086688,0.000000
63.710003,20.705025,-368.658112,-0.001811,0.003395,0.086228,92.100548,4.691826,0.862282,-368.658112,0.087356,0.000000
64.110001,22.014290,-368.658112,-0.001798,0.003431,0.087148,97.924454,4.988510,0.871480,-368.658112,0.088015,0.000000
64.510002,22.160629,-368.658112,-0.001776,0.003457,0.087816,98.575401,5.021670,0.878156,-368.658112,0.088682,0.000000
64.910004,22.329315,-368.747070,-0.001750,0.003479,0.088361,99.325752,5.059895,0.883614,-368.747070,0.089350,0.000000
65.310005,22.677856,-368.747070,-0.001729,0.003506,0.089047,100.876144,5.138876,0.890472,-368.747070,0.090018,0.000000
65.710007,22.906860,-368.747070,-0.001720,0.003525,0.089542,101.894806,5.190769,0.895415,-368.747070,0.090686,0.000000
66.110001,24.522957,-368.836060,-0.001694,0.003560,0.090426,109.083557,5.556981,0.904257,-368.836060,0.091354,0.000000
66.510002,25.001457,-368.791565,-0.001681,0.003588,0.091137,111.212036,5.665411,0.911372,-368.791565,0.092021,0.000000
66.910004,25.615501,-368.880524,-0.001651,0.003615,0.091822,113.943443,5.804555,0.918223,-368.880524,0.092689,0.000000
67.310005,25.479584,-368.791565,-0.001647,0.003632,0.092255,113.338852,5.773756,0.922553,-368.791565,0.093348,0.000000
67.710007,26.000534,-368.925018,-0.001634,0.003654,0.092819,115.656151,5.891805,0.928192,-368.925018,0.094016,0.000000
68.110001,27.458748,-368.880524,-0.001621,0.003690,0.093738,122.142609,6.222241,0.937382,-368.880524,0.094684,0.000000
68.510002,28.279083,-368.969482,-0.001595,0.003718,0.094441,125.791641,6.408132,0.944407,-368.969482,0.095351,0.000000
68.910004,29.161606,-368.969482,-0.001591,0.003746,0.095143,129.717300,6.608114,0.951432,-368.969482,0.096019,0.000000
69.310005,29.237198,-369.013977,-0.001569,0.003764,0.095603,130.053558,6.625244,0.956034,-369.013977,0.096687,0.000000
69.710007,29.252838,-369.013977,-0.001561,0.003779,0.095976,130.123123,6.628788,0.959759,-369.013977,0.097355,0.000000
70.110001,31.623360,-369.102936,-0.001531,0.003821,0.097052,140.667725,7.165956,0.970515,-369.102936,0.098023,0.000000
70.510002,32.208725,-369.102936,-0.001509,0.003846,0.097684,143.271561,7.298602,0.976844,-369.102936,0.098682,0.000000
70.910004,33.193657,-369.058441,-0.001500,0.003870,0.098309,147.652756,7.521790,0.983089,-369.058441,0.099350,0.000000
71.310005,33.897812,-369.147400,-0.001496,0.003895,0.098933,150.785004,7.681354,0.989334,-369.147400,0.100017,0.000000
71.710007,35.367561,-369.191895,-0.001470,0.003924,0.099662,157.322769,8.014403,0.996616,-369.191895,0.100685,0.000000
72.110001,36.521172,-369.236389,-0.001453,0.003952,0.100381,162.454285,8.275815,1.003815,-369.236389,0.101353,0.000000
72.510002,36.727837,-369.236389,-0.001440,0.003969,0.100806,163.373581,8.322646,1.008061,-369.236389,0.102020,0.000000
72.910004,38.195732,-369.236389,-0.001423,0.003998,0.101543,169.903107,8.655276,1.015434,-369.236389,0.102688,0.000000
73.310005,39.420837,-369.280853,-0.001406,0.004020,0.102107,175.352646,8.932889,1.021074,-369.280853,0.103356,0.000000
73.710007,41.876259,-369.280853,-0.001388,0.004060,0.103122,186.274902,9.489296,1.031217,-369.280853,0.104015,0.000000
74.110001,42.555099,-369.325348,-0.001380,0.004082,0.103677,189.294540,9.643124,1.036766,-369.325348,0.104683,0.000000
74.510002,43.266327,-369.325348,-0.001367,0.004104,0.104250,192.458237,9.804290,1.042496,-369.325348,0.105351,0.000000
74.910004,44.895454,-369.414307,-0.001354,0.004131,0.104917,199.704956,10.173455,1.049173,-369.414307,0.106019,0.000000
75.310005,46.299675,-369.369812,-0.001345,0.004157,0.105576,205.951233,10.491656,1.055759,-369.369812,0.106686,0.000000
75.710007,48.257233,-369.414307,-0.001328,0.004189,0.106409,214.658890,10.935246,1.064085,-369.414307,0.107354,0.000000
76.110001,49.485321,-369.458771,-0.001315,0.004215,0.107050,220.121704,11.213534,1.070505,-369.458771,0.108022,0.000000
76.510002,50.954704,-369.458771,-0.001293,0.004238,0.107649,226.657852,11.546501,1.076492,-369.458771,0.108689,0.000000
76.910004,51.960854,-369.414307,-0.001285,0.004258,0.108160,231.133423,11.774498,1.081602,-369.414307,0.109357,0.000000
77.310005,53.994003,-369.458771,-0.001276,0.004291,0.109002,240.177322,12.235216,1.090019,-369.458771,0.110016,0.000000
77.710007,54.513466,-369.458771,-0.001263,0.004302,0.109279,242.488007,12.352928,1.092790,-369.458771,0.110684,0.000000
78.110001,57.495796,-369.547729,-0.001250,0.004345,0.110355,255.754074,13.028734,1.103547,-369.547729,0.111352,0.000000
78.510002,59.138702,-369.458771,-0.001237,0.004370,0.110987,263.062073,13.401021,1.109875,-369.458771,0.112020,0.000000
78.910004,60.495628,-369.547729,-0.001233,0.004390,0.111517,269.097992,13.708506,1.115166,-369.547729,0.112688,0.000000
79.310005,62.198860,-369.592224,-0.001216,0.004415,0.112132,276.674347,14.094463,1.121321,-369.592224,0.113355,0.000000
79.710007,65.241882,-369.547729,-0.001207,0.004453,0.113104,290.210388,14.784021,1.131040,-369.547729,0.114023,0.000000
80.110001,65.866364,-369.636688,-0.001199,0.004458,0.113225,292.988220,14.925531,1.132251,-369.636688,0.019868,0.000000
80.510002,64.952927,-369.592224,-0.001186,0.004458,0.113225,288.925049,14.718543,1.132251,-369.592224,294.500458,0.000000
80.910004,66.060364,-369.636688,-0.001199,0.004454,0.113130,293.851166,14.969492,1.131298,-369.636688,294.500458,0.000000
81.310005,65.370361,-369.681183,-0.001177,0.004454,0.113138,290.781891,14.813136,1.131381,-369.681183,294.500458,0.000000
81.710007,65.122726,-369.725677,-0.001181,0.004478,0.113745,289.680359,14.757020,1.137452,-369.725677,294.500458,0.000000
82.110001,64.958511,-369.725677,-0.001168,0.004481,0.113815,288.949890,14.719809,1.138148,-369.725677,294.500458,0.000000
82.510002,64.935806,-369.681183,-0.001186,0.004485,0.113910,288.848907,14.714664,1.139102,-369.681183,294.500458,0.000000
82.910004,65.259766,-369.770142,-0.001168,0.004491,0.114084,290.289948,14.788074,1.140836,-369.770142,294.500458,0.000000
83.310005,65.067612,-369.814636,-0.001155,0.004494,0.114153,289.435181,14.744532,1.141532,-369.814636,294.500458,0.000000
83.710007,65.013260,-369.814636,-0.001160,0.004494,0.114153,289.193420,14.732215,1.141532,-369.814636,294.500458,0.000000
84.110001,65.622086,-369.859100,-0.001164,0.004503,0.114379,291.901611,14.870177,1.143788,-369.859100,294.500458,0.000000
84.510002,65.493607,-369.814636,-0.001143,0.004503,0.114379,291.330109,14.841063,1.143788,-369.814636,294.500458,0.000000
84.910004,65.299973,-369.903595,-0.001147,0.004503,0.114379,290.468781,14.797185,1.143788,-369.903595,294.500458,0.000000
85.310005,65.145447,-369.903595,-0.001160,0.004503,0.114379,289.781433,14.762170,1.143788,-369.903595,294.500458,0.000000
85.710007,64.978622,-369.948059,-0.001147,0.004503,0.114387,289.039337,14.724366,1.143871,-369.948059,294.500458,0.000000
86.110001,64.795792,-369.948059,-0.001160,0.004503,0.114387,288.226074,14.682936,1.143871,-369.948059,294.500458,0.000000
86.510002,64.669922,-369.948059,-0.001151,0.004503,0.114387,287.666168,14.654413,1.143871,-369.948059,294.500458,0.000000
86.910004,64.514648,-369.992554,-0.001151,0.004503,0.114387,286.975494,14.619228,1.143871,-369.992554,294.500458,0.000000
87.310005,64.408142,-370.037018,-0.001155,0.004503,0.114387,286.501740,14.595094,1.143871,-370.037018,294.500458,0.000000
87.710007,64.277451,-370.037018,-0.001151,0.004504,0.114396,285.920380,14.565478,1.143962,-370.037018,294.500458,0.000000
88.110001,66.679245,-370.081512,-0.001147,0.004452,0.113069,296.604095,15.109733,1.130692,-370.081512,294.500458,0.000000
88.510002,66.489716,-370.037018,-0.001130,0.004452,0.113069,295.761017,15.066785,1.130692,-370.037018,294.500458,0.000000
88.910004,66.372040,-370.126007,-0.001138,0.004452,0.113078,295.237579,15.040119,1.130775,-370.126007,294.500458,0.000000
89.310005,66.243195,-370.170471,-0.001155,0.004452,0.113078,294.664459,15.010922,1.130775,-370.170471,294.500458,0.000000
89.710007,66.118454,-370.170471,-0.001143,0.004452,0.113078,294.109558,14.982656,1.130775,-370.170471,294.500458,0.000000
90.110001,66.007492,-370.214966,-0.001147,0.004452,0.113078,293.615997,14.957512,1.130775,-370.214966,294.500458,0.000000
90.510002,65.849594,-370.170471,-0.001138,0.004469,0.113511,292.913635,14.921731,1.135113,-370.170471,294.500458,0.000000
90.910004,65.769547,-370.214966,-0.001134,0.004477,0.113719,292.557556,14.903592,1.137194,-370.214966,294.500458,0.000000
91.310005,65.671234,-370.259430,-0.001117,0.004479,0.113772,292.120239,14.881314,1.137717,-370.259430,294.500458,0.000000
91.710007,65.578888,-370.348389,-0.001130,0.004482,0.113832,291.709473,14.860388,1.138322,-370.348389,294.500458,0.000000
92.110001,65.517075,-370.303925,-0.001121,0.004483,0.113858,291.434509,14.846381,1.138580,-370.303925,294.500458,0.000000
92.510002,65.405731,-370.348389,-0.001134,0.004485,0.113910,290.939209,14.821150,1.139102,-370.348389,294.500458,0.000000
92.910004,65.378555,-370.348389,-0.001138,0.004494,0.114153,290.818329,14.814992,1.141532,-370.348389,294.500458,0.000000
93.310005,65.295517,-370.437347,-0.001143,0.004494,0.114153,290.448975,14.796175,1.141532,-370.437347,294.500458,0.000000
93.710007,65.243744,-370.437347,-0.001130,0.004494,0.114153,290.218658,14.784444,1.141532,-370.437347,294.500458,0.000000
94.110008,65.170761,-370.437347,-0.001134,0.004494,0.114153,289.894012,14.767905,1.141532,-370.437347,294.500458,0.000000
94.510002,65.204651,-370.437347,-0.001138,0.004507,0.114474,290.044769,14.775585,1.144742,-370.437347,294.500458,0.000000
94.910004,65.098526,-370.526337,-0.001138,0.004507,0.114474,289.572693,14.751537,1.144742,-370.526337,294.500458,0.000000
95.310005,65.051239,-370.570801,-0.001134,0.004507,0.114474,289.362366,14.740822,1.144742,-370.570801,294.500458,0.000000
95.710007,65.092941,-370.570801,-0.001130,0.004518,0.114769,289.547852,14.750272,1.147686,-370.570801,294.500458,0.000000
96.110008,65.273544,-370.570801,-0.001125,0.004519,0.114778,290.351227,14.791197,1.147777,-370.570801,294.500458,0.000000
96.510002,65.228119,-370.570801,-0.001151,0.004519,0.114778,290.149170,14.780903,1.147777,-370.570801,294.500458,0.000000
96.910004,65.191620,-370.615295,-0.001117,0.004520,0.114803,289.986816,14.772633,1.148034,-370.615295,294.500458,0.000000
97.310005,65.158478,-370.704254,-0.001117,0.004520,0.114803,289.839386,14.765121,1.148034,-370.704254,294.500458,0.000000
97.710007,65.143951,-370.659760,-0.001134,0.004521,0.114838,289.774780,14.761830,1.148383,-370.659760,294.500458,0.000000
98.110008,65.153641,-370.748718,-0.001134,0.004521,0.114838,289.817871,14.764026,1.148383,-370.748718,294.500458,0.000000
98.510002,65.114914,-370.748718,-0.001134,0.004521,0.114838,289.645599,14.755250,1.148383,-370.748718,294.500458,0.000000
98.910004,65.083252,-370.793213,-0.001138,0.004521,0.114838,289.504761,14.748075,1.148383,-370.793213,294.500458,0.000000
99.310005,65.056442,-370.837677,-0.001147,0.004522,0.114847,289.385498,14.742001,1.148466,-370.837677,294.500458,0.000000
99.710007,65.221405,-370.793213,-0.001130,0.004525,0.114925,290.119293,14.779382,1.149246,-370.793213,294.500458,0.000000
100.110008,65.224380,-370.882172,-0.001130,0.004525,0.114925,290.132538,14.780056,1.149246,-370.882172,294.500458,0.000000
100.510002,65.199432,-370.882172,-0.001125,0.004525,0.114925,290.021545,14.774403,1.149246,-370.882172,294.500458,0.000000
100.910004,65.156982,-370.971130,-0.001130,0.004525,0.114925,289.832733,14.764783,1.149246,-370.971130,294.500458,0.000000
101.310005,65.190125,-370.971130,-0.001125,0.004526,0.114959,289.980164,14.772293,1.149594,-370.971130,294.500458,0.000000
101.710007,65.175232,-370.926636,-0.001130,0.004526,0.114959,289.913910,14.768919,1.149594,-370.926636,294.500458,0.000000
102.110008,65.172256,-371.015625,-0.001134,0.004526,0.114968,289.900665,14.768245,1.149685,-371.015625,294.500458,0.000000
102.510002,65.154755,-371.060089,-0.001138,0.004526,0.114968,289.822815,14.764278,1.149685,-371.060089,294.500458,0.000000
102.910004,65.111191,-371.060089,-0.001125,0.004526,0.114968,289.629028,14.754407,1.149685,-371.060089,294.500458,0.000000
103.310005,65.209869,-371.104584,-0.001130,0.004528,0.115020,290.067993,14.776768,1.150199,-371.104584,294.500458,0.000000
103.710007,65.222519,-371.104584,-0.001130,0.004528,0.115020,290.124268,14.779634,1.150199,-371.104584,294.500458,0.000000
104.110008,65.189392,-371.149048,-0.001117,0.004528,0.115020,289.976898,14.772127,1.150199,-371.149048,294.500458,0.000000
104.510002,65.194229,-371.149048,-0.001121,0.004528,0.115020,289.998413,14.773223,1.150199,-371.149048,294.500458,0.000000
104.910004,65.162949,-371.149048,-0.001108,0.004529,0.115037,289.859283,14.766135,1.150373,-371.149048,294.500458,0.000000
105.310005,65.203903,-371.193542,-0.001130,0.004530,0.115072,290.041443,14.775416,1.150722,-371.193542,294.500458,0.000000
105.710007,65.222900,-371.193542,-0.001130,0.004530,0.115072,290.125946,14.779721,1.150722,-371.193542,294.500458,0.000000
106.110008,65.211731,-371.238007,-0.001125,0.004530,0.115072,290.076263,14.777190,1.150722,-371.238007,294.500458,0.000000
106.510002,65.209869,-371.282501,-0.001130,0.004530,0.115072,290.067993,14.776768,1.150722,-371.282501,294.500458,0.000000
106.910004,65.174484,-371.282501,-0.001125,0.004530,0.115072,289.910583,14.768749,1.150722,-371.282501,294.500458,0.000000
107.310005,65.140228,-371.326965,-0.001125,0.004530,0.115072,289.758209,14.760986,1.150722,-371.326965,294.500458,0.000000
107.710007,65.140228,-371.326965,-0.001134,0.004531,0.115090,289.758209,14.760986,1.150896,-371.326965,294.500458,0.000000
108.110008,65.127563,-371.326965,-0.001112,0.004531,0.115099,289.701874,14.758117,1.150987,-371.326965,294.500458,0.000000
108.510002,65.205399,-371.415955,-0.001117,0.004533,0.115150,290.048096,14.775755,1.151501,-371.415955,294.500458,0.000000
108.910004,65.253799,-371.415955,-0.001130,0.004533,0.115150,290.263397,14.786722,1.151501,-371.415955,294.500458,0.000000
109.310005,65.240768,-371.460419,-0.001112,0.004533,0.115150,290.205444,14.783769,1.151501,-371.460419,294.500458,0.000000
109.710007,65.242630,-371.460419,-0.001117,0.004533,0.115150,290.213715,14.784191,1.151501,-371.460419,294.500458,0.000000
110.110008,65.224014,-371.460419,-0.001112,0.004533,0.115150,290.130920,14.779973,1.151501,-371.460419,294.500458,0.000000
110.510002,65.193115,-371.504913,-0.001117,0.004533,0.115150,289.993469,14.772971,1.151501,-371.504913,294.500458,0.000000
110.910004,65.178955,-371.504913,-0.001121,0.004533,0.115150,289.930481,14.769762,1.151501,-371.504913,294.500458,0.000000
111.310005,65.138000,-371.504913,-0.001112,0.004533,0.115150,289.748291,14.760482,1.151501,-371.504913,294.500458,0.000000
111.710007,65.139862,-371.638336,-0.001125,0.004533,0.115150,289.756592,14.760904,1.151501,-371.638336,294.500458,0.000000
112.110008,65.123108,-371.593872,-0.001112,0.004534,0.115159,289.682037,14.757108,1.151592,-371.593872,294.500458,0.000000
112.510002,65.135757,-371.593872,-0.001125,0.004536,0.115211,289.738312,14.759974,1.152107,-371.593872,294.500458,0.000000
112.910004,65.205017,-371.593872,-0.001121,0.004536,0.115211,290.046417,14.775668,1.152107,-371.593872,294.500458,0.000000
113.310005,65.205399,-371.638336,-0.001112,0.004536,0.115211,290.048096,14.775755,1.152107,-371.638336,294.500458,0.000000
113.710007,65.214706,-371.682831,-0.001117,0.004536,0.115211,290.089508,14.777864,1.152107,-371.682831,294.500458,0.000000
114.110008,65.203537,-371.682831,-0.001112,0.004536,0.115211,290.039825,14.775332,1.152107,-371.682831,294.500458,0.000000
114.510002,65.173370,-371.682831,-0.001112,0.004536,0.115211,289.905640,14.768497,1.152107,-371.682831,294.500458,0.000000
114.910004,65.164810,-371.727295,-0.001112,0.004536,0.115211,289.867554,14.766557,1.152107,-371.727295,294.500458,0.000000
115.310005,65.151398,-371.727295,-0.001121,0.004536,0.115211,289.807892,14.763517,1.152107,-371.727295,294.500458,0.000000
115.710007,65.130173,-371.771790,-0.001134,0.004536,0.115211,289.713470,14.758708,1.152107,-371.771790,294.500458,0.000000
116.110008,65.137619,-371.816284,-0.001108,0.004537,0.115228,289.746613,14.760396,1.152281,-371.816284,294.500458,0.000000
116.510002,65.128311,-371.816284,-0.001112,0.004537,0.115228,289.705200,14.758286,1.152281,-371.816284,294.500458,0.000000
116.910004,65.126450,-371.860748,-0.001121,0.004537,0.115228,289.696930,14.757865,1.152281,-371.860748,294.500458,0.000000
117.310005,65.105972,-371.905243,-0.001112,0.004537,0.115228,289.605835,14.753223,1.152281,-371.905243,294.500458,0.000000
117.710007,65.078415,-371.905243,-0.001125,0.004537,0.115237,289.483246,14.746980,1.152372,-371.905243,294.500458,0.000000
118.110008,65.164062,-371.905243,-0.001112,0.004539,0.115289,289.864227,14.766387,1.152894,-371.905243,294.500458,0.000000
118.510002,65.190506,-371.905243,-0.001108,0.004539,0.115289,289.981842,14.772380,1.152894,-371.905243,294.500458,0.000000
118.910004,65.198318,-371.949707,-0.001130,0.004539,0.115289,290.016602,14.774151,1.152894,-371.949707,294.500458,0.000000
119.310005,65.201294,-371.994202,-0.001117,0.004539,0.115289,290.029846,14.774824,1.152894,-371.994202,294.500458,0.000000
119.710007,65.180069,-372.038666,-0.001121,0.004539,0.115289,289.935425,14.770015,1.152894,-372.038666,294.500458,0.000000
120.110008,65.175232,-371.994202,-0.001108,0.004539,0.115289,289.913910,14.768919,1.152894,-371.994202,294.500458,0.000000
120.510002,65.167038,-372.038666,-0.001117,0.004539,0.115289,289.877472,14.767062,1.152894,-372.038666,294.500458,0.000000
120.910004,65.148056,-372.083160,-0.001121,0.004539,0.115289,289.793030,14.762760,1.152894,-372.083160,294.500458,0.000000
121.310005,65.136887,-372.083160,-0.001117,0.004539,0.115289,289.743347,14.760229,1.152894,-372.083160,294.500458,0.000000
121.710007,65.107834,-372.083160,-0.001108,0.004539,0.115289,289.614105,14.753646,1.152894,-372.083160,294.500458,0.000000
122.110008,65.107468,-372.127625,-0.001117,0.004539,0.115289,289.612488,14.753563,1.152894,-372.127625,294.500458,0.000000
122.510002,65.095917,-372.127625,-0.001099,0.004539,0.115289,289.561096,14.750946,1.152894,-372.127625,294.500458,0.000000
122.910004,65.063156,-372.127625,-0.001117,0.004539,0.115289,289.415375,14.743522,1.152894,-372.127625,294.500458,0.000000
123.310005,65.054581,-372.216583,-0.001112,0.004539,0.115289,289.377228,14.741579,1.152894,-372.216583,294.500458,0.000000
123.710007,65.562881,-372.261078,-0.001117,0.004546,0.115480,291.638275,14.856761,1.154802,-372.261078,294.500458,0.000000
124.110008,65.621338,-372.261078,-0.001121,0.004546,0.115471,291.898285,14.870008,1.154711,-372.261078,294.500458,0.000000
124.510002,65.644424,-372.350037,-0.001112,0.004546,0.115471,292.000977,14.875239,1.154711,-372.350037,294.500458,0.000000
124.910004,65.638458,-372.261078,-0.001121,0.004546,0.115471,291.974457,14.873887,1.154711,-372.261078,294.500458,0.000000
125.310005,65.647034,-372.305573,-0.001112,0.004546,0.115471,292.012604,14.875831,1.154711,-372.305573,294.500458,0.000000
125.710007,65.636597,-372.350037,-0.001125,0.004546,0.115471,291.966156,14.873466,1.154711,-372.350037,294.500458,0.000000
126.110008,65.636230,-372.350037,-0.001108,0.004546,0.115471,291.964539,14.873382,1.154711,-372.350037,294.500458,0.000000
126.510010,65.615753,-372.350037,-0.001117,0.004546,0.115471,291.873444,14.868742,1.154711,-372.350037,294.500458,0.000000
126.910004,65.611649,-372.394531,-0.001130,0.004546,0.115471,291.855194,14.867812,1.154711,-372.394531,294.500458,0.000000
127.310005,65.597870,-372.438995,-0.001104,0.004546,0.115471,291.793884,14.864690,1.154711,-372.438995,294.500458,0.000000
127.710007,65.590805,-372.438995,-0.001117,0.004546,0.115471,291.762482,14.863089,1.154711,-372.438995,294.500458,0.000000
128.110001,65.596756,-372.483490,-0.001099,0.004546,0.115471,291.788940,14.864437,1.154711,-372.483490,294.500458,0.000000
128.510010,65.572922,-372.572449,-0.001112,0.004546,0.115471,291.682922,14.859036,1.154711,-372.572449,294.500458,0.000000
128.910004,65.555420,-372.527954,-0.001117,0.004546,0.115471,291.605072,14.855071,1.154711,-372.527954,294.500458,0.000000
129.310013,65.555054,-372.572449,-0.001117,0.004546,0.115471,291.603455,14.854987,1.154711,-372.572449,294.500458,0.000000
129.710007,65.544250,-372.661407,-0.001117,0.004546,0.115471,291.555389,14.852540,1.154711,-372.661407,294.500458,0.000000
130.110001,65.528244,-372.616913,-0.001121,0.004546,0.115471,291.484192,14.848912,1.154711,-372.616913,294.500458,0.000000
130.510010,65.513718,-372.616913,-0.001099,0.004546,0.115471,291.419556,14.845620,1.154711,-372.616913,294.500458,0.000000
130.910004,65.491379,-372.661407,-0.001112,0.004546,0.115471,291.320190,14.840559,1.154711,-372.661407,294.500458,0.000000
131.310013,65.495850,-372.661407,-0.001104,0.004546,0.115471,291.340088,14.841572,1.154711,-372.661407,294.500458,0.000000
131.710007,65.473877,-372.705902,-0.001112,0.004546,0.115471,291.242340,14.836593,1.154711,-372.705902,294.500458,0.000000
132.110001,65.446701,-372.705902,-0.001112,0.004546,0.115471,291.121460,14.830435,1.154711,-372.705902,294.500458,0.000000
132.510010,65.447067,-372.750366,-0.001121,0.004546,0.115471,291.123108,14.830518,1.154711,-372.750366,294.500458,0.000000
132.910004,65.409454,-372.794861,-0.001112,0.004546,0.115471,290.955780,14.821995,1.154711,-372.794861,294.500458,0.000000
133.310013,65.408340,-372.794861,-0.001108,0.004546,0.115471,290.950836,14.821742,1.154711,-372.794861,294.500458,0.000000
133.710007,65.378922,-372.794861,-0.001112,0.004546,0.115471,290.819977,14.815075,1.154711,-372.794861,294.500458,0.000000
134.110001,65.354721,-372.839325,-0.001108,0.004546,0.115471,290.712311,14.809591,1.154711,-372.839325,294.500458,0.000000
134.510010,65.364777,-372.883820,-0.001112,0.004546,0.115471,290.757050,14.811871,1.154711,-372.883820,294.500458,0.000000
134.910004,65.346161,-372.928284,-0.001108,0.004546,0.115471,290.674255,14.807652,1.154711,-372.928284,294.500458,0.000000
135.310013,65.319336,-372.928284,-0.001108,0.004546,0.115480,290.554932,14.801573,1.154802,-372.928284,294.500458,0.000000
135.710007,65.302963,-372.928284,-0.001130,0.004546,0.115480,290.482086,14.797863,1.154802,-372.928284,294.500458,0.000000
136.110001,65.299240,-372.972778,-0.001112,0.004546,0.115480,290.465515,14.797020,1.154802,-372.972778,294.500458,0.000000
136.510010,65.297379,-373.061737,-0.001125,0.004546,0.115480,290.457245,14.796597,1.154802,-373.061737,294.500458,0.000000
136.910004,65.276520,-373.061737,-0.001121,0.004546,0.115480,290.364471,14.791870,1.154802,-373.061737,294.500458,0.000000
137.310013,65.256042,-373.061737,-0.001125,0.004546,0.115480,290.273376,14.787230,1.154802,-373.061737,294.500458,0.000000
137.710007,65.253799,-373.150696,-0.001121,0.004546,0.115480,290.263397,14.786722,1.154802,-373.150696,294.500458,0.000000
138.110001,65.244492,-373.150696,-0.001112,0.004546,0.115480,290.221985,14.784614,1.154802,-373.150696,294.500458,0.000000
138.510010,65.236679,-373.150696,-0.001130,0.004546,0.115480,290.187256,14.782843,1.154802,-373.150696,294.500458,0.000000
138.910004,65.223267,-373.150696,-0.001108,0.004546,0.115480,290.127594,14.779803,1.154802,-373.150696,294.500458,0.000000
139.310013,65.210983,-373.195190,-0.001112,0.004547,0.115488,290.072937,14.777020,1.154885,-373.195190,294.500458,0.000000
139.710007,65.217316,-373.195190,-0.001095,0.004547,0.115488,290.101105,14.778456,1.154885,-373.195190,294.500458,0.000000
140.110001,65.191620,-373.239655,-0.001112,0.004547,0.115488,289.986816,14.772633,1.154885,-373.239655,294.500458,0.000000
140.510010,65.171890,-373.239655,-0.001104,0.004547,0.115488,289.899048,14.768161,1.154885,-373.239655,1681.640747,0.000000
140.910004,65.148056,-373.284149,-0.001125,0.004540,0.115315,289.793030,14.762760,1.153152,-373.284149,0.115115,0.000000
141.310013,65.039688,-373.328613,-0.001121,0.004521,0.114829,289.310974,14.738203,1.148292,-373.328613,0.114448,0.000000
141.710007,64.923889,-373.328613,-0.001104,0.004500,0.114309,288.795868,14.711963,1.143091,-373.328613,0.113780,0.000000
142.110001,64.900803,-373.417572,-0.001117,0.004475,0.113659,288.693176,14.706732,1.136589,-373.417572,0.113121,0.000000
142.510010,64.889999,-373.328613,-0.001112,0.004449,0.113017,288.645142,14.704284,1.130170,-373.328613,0.112453,0.000000
142.910004,64.868393,-373.462067,-0.001104,0.004422,0.112306,288.549011,14.699388,1.123062,-373.462067,0.111785,0.000000
143.310013,64.846054,-373.373108,-0.001099,0.004393,0.111595,288.449646,14.694325,1.115946,-373.373108,0.111118,0.000000
143.710007,64.827805,-373.462067,-0.001117,0.004372,0.111057,288.368469,14.690190,1.110572,-373.462067,0.110450,0.000000
144.110001,64.755203,-373.417572,-0.001104,0.004353,0.110563,288.045532,14.673738,1.105628,-373.417572,0.109782,0.000000
144.510010,64.380219,-373.462067,-0.001117,0.004320,0.109739,286.377502,14.588766,1.097392,-373.462067,0.109115,0.000000
144.910004,63.601212,-373.551025,-0.001099,0.004294,0.109080,282.912323,14.412240,1.090799,-373.551025,0.108446,0.000000
145.310013,62.518356,-373.462067,-0.001099,0.004272,0.108508,278.095551,14.166862,1.085076,-373.462067,0.107788,0.000000
145.710007,61.493591,-373.551025,-0.001091,0.004253,0.108031,273.537170,13.934647,1.080307,-373.551025,0.107120,0.000000
146.110001,59.986595,-373.639984,-0.001091,0.004228,0.107389,266.833710,13.593157,1.073888,-373.639984,0.106452,0.000000
146.510010,58.062172,-373.595520,-0.001087,0.004200,0.106677,258.273437,13.157077,1.066773,-373.595520,0.105784,0.000000
146.910004,55.670425,-373.639984,-0.001099,0.004171,0.105941,247.634415,12.615099,1.059407,-373.639984,0.105116,0.000000
147.310013,53.754196,-373.684479,-0.001091,0.004151,0.105446,239.110611,12.180875,1.054464,-373.684479,0.104449,0.000000
147.710007,51.420540,-373.773437,-0.001082,0.004123,0.104735,228.729980,11.652061,1.047349,-373.773437,0.103781,0.000000
148.110001,48.864944,-373.728943,-0.001087,0.004098,0.104093,217.362122,11.072954,1.040929,-373.728943,0.103113,0.000000
148.510010,46.304886,-373.773437,-0.001082,0.004077,0.103555,205.974426,10.492837,1.035555,-373.773437,0.102454,0.000000
148.910004,42.654892,-373.817902,-0.001095,0.004043,0.102697,189.738434,9.665737,1.026971,-373.817902,0.101786,0.000000
149.310013,40.001740,-373.862396,-0.001091,0.004016,0.102012,177.936630,9.064524,1.020120,-373.862396,0.101119,0.000000
149.710007,37.449501,-373.862396,-0.001099,0.003996,0.101491,166.583694,8.486178,1.014912,-373.862396,0.100451,0.000000
150.110001,34.554298,-373.862396,-0.001095,0.003971,0.100876,153.705200,7.830116,1.008758,-373.862396,0.099783,0.000000
150.510010,32.291023,-373.906860,-0.001082,0.003945,0.100191,143.637650,7.317250,1.001907,-373.906860,0.099115,0.000000
150.910004,28.199020,-373.862396,-0.001087,0.003913,0.099385,125.435509,6.389989,0.993845,-373.862396,0.098447,0.000000
151.310013,25.255043,-373.951355,-0.001091,0.003884,0.098647,112.340042,5.722875,0.986472,-373.951355,0.097780,0.000000
151.710007,22.809677,-374.040314,-0.001091,0.003862,0.098092,101.462509,5.168747,0.980924,-374.040314,0.097120,0.000000
152.110001,20.135292,-373.995850,-0.001091,0.003841,0.097572,89.566254,4.562723,0.975716,-373.995850,0.096453,0.000000
152.510010,16.736282,-374.040314,-0.001082,0.003808,0.096721,74.446701,3.792496,0.967215,-374.040314,0.095785,0.000000
152.910004,13.758789,-374.084808,-0.001082,0.003783,0.096098,61.202152,3.117786,0.960977,-374.084808,0.095117,0.000000
153.310013,11.798622,-374.040314,-0.001087,0.003767,0.095681,52.482891,2.673606,0.956814,-374.040314,0.094450,0.000000
153.710007,8.224586,-374.084808,-0.001078,0.003733,0.094806,36.584789,1.863718,0.948056,-374.084808,0.093782,0.000000
154.110001,6.350067,-374.218231,-0.001091,0.003717,0.094407,28.246510,1.438946,0.944066,-374.218231,0.093114,0.000000
154.510010,2.953659,-374.129272,-0.001091,0.003682,0.093522,13.138532,0.669309,0.935217,-374.129272,0.092446,0.000000
154.910004,0.444611,-374.218231,-0.001087,0.003658,0.092915,1.977727,0.100750,0.929146,-374.218231,0.091778,0.000000
155.310013,-1.606415,-374.173767,-0.001078,0.003632,0.092264,-7.145690,-0.364019,0.922644,-374.173767,0.091120,0.000000
155.710007,-0.142616,-374.218231,-0.001074,0.003600,0.091440,-0.634389,-0.032317,0.914400,-374.218231,0.090451,0.000000
156.110001,-0.037239,-374.262726,-0.001091,0.003577,0.090868,-0.165648,-0.008438,0.908678,-374.262726,0.089784,0.000000
156.510010,-0.074478,-374.262726,-0.001087,0.003549,0.090148,-0.331295,-0.016877,0.901479,-374.262726,0.089116,0.000000
156.910004,-0.064049,-374.307190,-0.001095,0.003525,0.089542,-0.284903,-0.014514,0.895415,-374.307190,0.088448,0.000000
157.310013,-0.049522,-374.351685,-0.001099,0.003497,0.088813,-0.220287,-0.011222,0.888126,-374.351685,0.087781,0.000000
157.710007,-0.069633,-374.351685,-0.001117,0.003475,0.088275,-0.309745,-0.015779,0.882751,-374.351685,0.087113,0.000000
158.110001,-0.054367,-374.351685,-0.001134,0.003457,0.087798,-0.241837,-0.012320,0.877982,-374.351685,0.086445,0.000000
158.510010,-0.060699,-374.396179,-0.001168,0.003418,0.086818,-0.270005,-0.013755,0.868179,-374.396179,0.085786,0.000000
158.910004,-0.040962,-374.440643,-0.001207,0.003385,0.085985,-0.182209,-0.009282,0.859852,-374.440643,0.085119,0.000000
159.310013,-0.023460,-374.440643,-0.001216,0.003373,0.085665,-0.104357,-0.005316,0.856650,-374.440643,0.084451,0.000000
159.710007,-0.059204,-374.485138,-0.001242,0.003342,0.084876,-0.263353,-0.013416,0.848755,-374.485138,0.083782,0.000000
160.110001,-0.038353,-374.529602,-0.001255,0.003318,0.084268,-0.170603,-0.008691,0.842684,-374.529602,0.083115,0.000000
160.510010,-0.049896,-374.574097,-0.001293,0.003285,0.083445,-0.221950,-0.011307,0.834448,-374.574097,0.082447,0.000000
160.910004,-0.060699,-374.574097,-0.001315,0.003260,0.082803,-0.270005,-0.013755,0.828029,-374.574097,0.081779,0.000000
161.310013,-0.083412,-374.574097,-0.001328,0.003234,0.082153,-0.371036,-0.018901,0.821527,-374.574097,0.081112,0.000000
161.710007,-0.066284,-374.618561,-0.001362,0.003212,0.081589,-0.294847,-0.015020,0.815887,-374.618561,0.080452,0.000000
162.110001,-0.045433,-374.574097,-0.001380,0.003183,0.080843,-0.202096,-0.010295,0.808431,-374.574097,0.079785,0.000000
162.510010,-0.046547,-374.574097,-0.001371,0.003153,0.080097,-0.207051,-0.010548,0.800975,-374.574097,0.079117,0.000000
162.910004,-0.025322,-374.663055,-0.001380,0.003133,0.079577,-0.112638,-0.005738,0.795767,-374.663055,0.078450,0.000000
163.310013,-0.033142,-374.663055,-0.001423,0.003106,0.078892,-0.147423,-0.007510,0.788916,-374.663055,0.077782,0.000000
163.710007,-0.036118,-374.663055,-0.001449,0.003073,0.078059,-0.160659,-0.008184,0.780589,-374.663055,0.077114,0.000000
164.100006,-0.007072,-374.752014,-0.001466,0.003059,0.077704,-0.031460,-0.001603,0.777039,-374.752014,0.077530,0.000000