File: Data/compression 21/AutoNoHeating-10-21-reverse-2-1_09132024_165857.csv
Time (sec),S:Load (lbs),S:HL1 (DIM),S:LVDT (in),S:Position (in),Ch:Position (mm),Ch:Load (N),Ch:Stress (MPa),Ch:Strain (mm/mm),Ch:HL1 (DIM),Set Point (),Cycles ()
0.110000,-0.036118,-351.266083,-0.005894,-0.005905,-0.149995,-0.160659,-0.008184,-1.499954,-351.266083,-0.149718,0.000000
0.490000,-0.006706,-351.266083,-0.005890,-0.005872,-0.149137,-0.029831,-0.001520,-1.491370,-351.266083,-0.148452,0.000000
0.870000,0.008934,-351.310547,-0.005786,-0.005647,-0.143439,0.039741,0.002024,-1.434392,-351.310547,-0.142121,0.000000
1.250000,0.021225,-351.355042,-0.005532,-0.005391,-0.136935,0.094413,0.004810,-1.369352,-351.355042,-0.135791,0.000000
1.630000,0.004471,-351.355042,-0.005264,-0.005139,-0.130535,0.019887,0.001013,-1.305350,-351.355042,-0.129460,0.000000
2.010000,-0.014526,-351.444000,-0.005032,-0.004924,-0.125063,-0.064617,-0.003292,-1.250628,-351.444000,-0.123129,0.000000
2.390000,0.001114,-351.399506,-0.004751,-0.004644,-0.117969,0.004955,0.000252,-1.179691,-351.399506,-0.116798,0.000000
2.770000,0.148201,-351.444000,-0.004544,-0.000000,-0.000000,0.659231,0.033583,-0.000000,-351.444000,0.000164,0.000000
3.150000,0.128838,-351.488464,-0.004544,-0.000000,-0.000009,0.573098,0.029195,-0.000091,-351.488464,0.000164,0.000000
3.530000,0.134056,-351.444000,-0.004536,-0.000000,-0.000009,0.596311,0.030378,-0.000091,-351.444000,0.000668,0.000000
3.910000,0.111710,-351.532959,-0.004549,0.000016,0.000407,0.496909,0.025314,0.004073,-351.532959,0.001300,0.000000
4.290000,0.144478,-351.532959,-0.004527,0.000031,0.000789,0.642670,0.032739,0.007888,-351.532959,0.001933,0.000000
4.670000,0.191399,-351.488464,-0.004501,0.000048,0.001214,0.851384,0.043372,0.012142,-351.488464,0.002567,0.000000
5.050000,0.322105,-351.577423,-0.004475,0.000082,0.002090,1.432796,0.072990,0.020900,-351.577423,0.003200,0.000000
5.430000,0.377586,-351.621918,-0.004437,0.000113,0.002870,1.679588,0.085562,0.028705,-351.621918,0.003833,0.000000
5.810000,0.463600,-351.666412,-0.004424,0.000139,0.003521,2.062196,0.105053,0.035207,-351.666412,0.004466,0.000000
6.190000,0.525414,-351.666412,-0.004389,0.000165,0.004180,2.337156,0.119060,0.041800,-351.666412,0.005099,0.000000
6.570000,0.608459,-351.621918,-0.004376,0.000181,0.004587,2.706563,0.137879,0.045873,-351.621918,0.005732,0.000000
6.950000,0.682182,-351.710876,-0.004355,0.000197,0.005012,3.034498,0.154585,0.050120,-351.710876,0.006365,0.000000
7.330000,0.877678,-351.755371,-0.004316,0.000237,0.006027,3.904106,0.198885,0.060271,-351.755371,0.006998,0.000000
7.710001,0.952904,-351.799835,-0.004312,0.000263,0.006677,4.238728,0.215931,0.066773,-351.799835,0.007631,0.000000
8.090000,1.118607,-351.799835,-0.004286,0.000292,0.007406,4.975811,0.253480,0.074055,-351.799835,0.008265,0.000000
8.470000,1.222496,-351.799835,-0.004251,0.000312,0.007917,5.437934,0.277022,0.079172,-351.799835,0.008898,0.000000
8.850000,1.339050,-351.799835,-0.004234,0.000330,0.008394,5.956393,0.303433,0.083941,-351.799835,0.009530,0.000000
9.230000,1.561356,-351.888794,-0.004208,0.000365,0.009262,6.945257,0.353808,0.092616,-351.888794,0.010164,0.000000
9.610001,1.605301,-351.888794,-0.004178,0.000391,0.009921,7.140735,0.363766,0.099210,-351.888794,0.010797,0.000000
9.990001,1.729294,-351.933289,-0.004182,0.000417,0.010589,7.692283,0.391864,0.105886,-351.933289,0.011430,0.000000
10.370001,1.871170,-351.888794,-0.004135,0.000438,0.011135,8.323380,0.424013,0.111352,-351.888794,0.012063,0.000000
10.750001,1.951973,-351.933289,-0.004118,0.000456,0.011595,8.682810,0.442323,0.115946,-351.933289,0.012696,0.000000
11.130000,2.177635,-351.977753,-0.004087,0.000489,0.012410,9.686605,0.493459,0.124099,-351.977753,0.013329,0.000000
11.510000,2.202583,-352.022247,-0.004079,0.000514,0.013052,9.797580,0.499113,0.130518,-352.022247,0.013962,0.000000
11.890000,2.298653,-352.022247,-0.004036,0.000535,0.013598,10.224917,0.520882,0.135976,-352.022247,0.014604,0.000000
12.270000,2.424141,-352.066742,-0.004018,0.000562,0.014283,10.783117,0.549318,0.142827,-352.066742,0.015237,0.000000
12.650001,2.409248,-352.111206,-0.003997,0.000577,0.014656,10.716872,0.545943,0.146559,-352.111206,0.015870,0.000000
13.030001,2.627831,-352.111206,-0.003975,0.000602,0.015289,11.689174,0.595475,0.152887,-352.111206,0.016503,0.000000
13.410001,2.780502,-352.155701,-0.003945,0.000633,0.016069,12.368292,0.630071,0.160691,-352.155701,0.017136,0.000000
13.790001,2.948074,-352.200165,-0.003919,0.000662,0.016806,13.113689,0.668043,0.168064,-352.200165,0.017769,0.000000
14.170001,3.044144,-352.066742,-0.003893,0.000690,0.017526,13.541027,0.689813,0.175263,-352.066742,0.018402,0.000000
14.550001,3.022545,-352.155701,-0.003885,0.000707,0.017951,13.444951,0.684918,0.179510,-352.155701,0.019035,0.000000
14.930000,3.203148,-352.200165,-0.003859,0.000730,0.018541,14.248313,0.725844,0.185407,-352.200165,0.019669,0.000000
15.310000,3.367363,-352.244659,-0.003829,0.000760,0.019313,14.978779,0.763055,0.193128,-352.244659,0.020301,0.000000
15.690001,3.415398,-352.289124,-0.003798,0.000785,0.019946,15.192448,0.773940,0.199456,-352.289124,0.020934,0.000000
16.070002,3.537537,-352.289124,-0.003781,0.000811,0.020588,15.735749,0.801617,0.205876,-352.289124,0.021568,0.000000
16.450001,3.375557,-352.333618,-0.003781,0.000820,0.020831,15.015227,0.764912,0.208305,-352.333618,0.022201,0.000000
16.830000,3.811974,-352.333618,-0.003734,0.000858,0.021793,16.956505,0.863806,0.217934,-352.333618,0.022834,0.000000
17.210001,3.973587,-352.333618,-0.003704,0.000886,0.022504,17.675398,0.900428,0.225042,-352.333618,0.023467,0.000000
17.590000,3.887199,-352.378082,-0.003695,0.000906,0.023008,17.291126,0.880852,0.230076,-352.378082,0.024100,0.000000
17.970001,3.921455,-352.422577,-0.003682,0.000924,0.023458,17.443504,0.888615,0.234580,-352.422577,0.024733,0.000000
18.350000,4.195145,-352.422577,-0.003678,0.000951,0.024152,18.660936,0.950633,0.241522,-352.422577,0.025366,0.000000
18.730001,4.310585,-352.378082,-0.003626,0.000977,0.024820,19.174440,0.976793,0.248198,-352.378082,0.025999,0.000000
19.110001,4.411499,-352.511536,-0.003596,0.001013,0.025721,19.623327,0.999660,0.257214,-352.511536,0.026632,0.000000
19.490002,4.388412,-352.511536,-0.003574,0.001035,0.026277,19.520634,0.994428,0.262770,-352.511536,0.027266,0.000000
19.870001,4.440544,-352.556030,-0.003557,0.001052,0.026727,19.752527,1.006242,0.267274,-352.556030,0.027898,0.000000
20.250002,4.663223,-352.511536,-0.003548,0.001081,0.027456,20.743053,1.056702,0.274564,-352.511536,0.028531,0.000000
20.630001,4.875473,-352.556030,-0.003518,0.001111,0.028210,21.687187,1.104798,0.282103,-352.556030,0.029165,0.000000
21.010000,4.884407,-352.644989,-0.003492,0.001139,0.028922,21.726927,1.106822,0.289219,-352.644989,0.029798,0.000000
21.390001,4.833023,-352.644989,-0.003471,0.001159,0.029451,21.498360,1.095179,0.294510,-352.644989,0.030431,0.000000
21.770000,4.979362,-352.600494,-0.003458,0.001182,0.030032,22.149311,1.128340,0.300316,-352.600494,0.031064,0.000000
22.150002,5.013992,-352.600494,-0.003454,0.001202,0.030526,22.303352,1.136187,0.305259,-352.600494,0.031697,0.000000
22.530001,5.217308,-352.689453,-0.003415,0.001233,0.031306,23.207745,1.182259,0.313064,-352.689453,0.032330,0.000000
22.910002,5.388603,-352.689453,-0.003393,0.001263,0.032078,23.969704,1.221075,0.320785,-352.689453,0.032972,0.000000
23.290001,5.284706,-352.778412,-0.003372,0.001285,0.032651,23.507547,1.197532,0.326508,-352.778412,0.033605,0.000000
23.670002,5.434402,-352.822906,-0.003363,0.001311,0.033293,24.173429,1.231453,0.332927,-352.822906,0.034238,0.000000
24.050001,5.435524,-352.822906,-0.003350,0.001332,0.033839,24.178419,1.231707,0.338392,-352.822906,0.034871,0.000000
24.430000,5.568085,-352.778412,-0.003324,0.001353,0.034368,24.768078,1.261746,0.343676,-352.778412,0.035504,0.000000
24.810001,5.868217,-352.778412,-0.003290,0.001390,0.035305,26.103134,1.329757,0.353047,-352.778412,0.036137,0.000000
25.190001,5.752037,-352.911865,-0.003290,0.001412,0.035877,25.586338,1.303430,0.358770,-352.911865,0.036770,0.000000
25.570002,5.659317,-352.867371,-0.003268,0.001430,0.036311,25.173899,1.282420,0.363108,-352.867371,0.037403,0.000000
25.950001,5.582611,-352.867371,-0.003251,0.001445,0.036692,24.832695,1.265038,0.366923,-352.867371,0.038036,0.000000
26.330002,5.987373,-352.822906,-0.003238,0.001480,0.037586,26.633167,1.356758,0.375855,-352.822906,0.038670,0.000000
26.710001,6.062965,-352.956360,-0.003199,0.001508,0.038314,26.969418,1.373888,0.383137,-352.956360,0.039302,0.000000
27.090002,6.158295,-352.956360,-0.003199,0.001536,0.039016,27.393463,1.395490,0.390162,-352.956360,0.039935,0.000000
27.470001,6.099831,-353.000824,-0.003173,0.001560,0.039615,27.133402,1.382241,0.396150,-353.000824,0.040569,0.000000
27.850000,6.071533,-353.000824,-0.003169,0.001579,0.040118,27.007528,1.375829,0.401176,-353.000824,0.041202,0.000000
28.230001,6.215271,-353.000824,-0.003139,0.001603,0.040725,27.646906,1.408401,0.407247,-353.000824,0.041834,0.000000
28.610001,6.470345,-353.045319,-0.003109,0.001636,0.041548,28.781530,1.466201,0.415483,-353.045319,0.042468,0.000000
28.990002,6.285271,-353.089783,-0.003117,0.001658,0.042112,27.958281,1.424263,0.421123,-353.089783,0.043101,0.000000
29.370001,6.401825,-353.134277,-0.003096,0.001686,0.042832,28.476740,1.450674,0.428321,-353.134277,0.043734,0.000000
29.750002,6.429756,-353.178741,-0.003074,0.001707,0.043370,28.600985,1.457004,0.433696,-353.178741,0.044367,0.000000
30.130001,6.458054,-353.178741,-0.003057,0.001729,0.043916,28.726856,1.463416,0.439161,-353.178741,0.045000,0.000000
30.510002,6.854256,-353.223236,-0.003027,0.001762,0.044749,30.489252,1.553197,0.447488,-353.223236,0.045633,0.000000
30.890001,6.702332,-353.223236,-0.003009,0.001787,0.045382,29.813459,1.518770,0.453816,-353.223236,0.046267,0.000000
31.270002,6.533272,-353.312195,-0.002988,0.001808,0.045911,29.061445,1.480461,0.459108,-353.312195,0.046899,0.000000
31.650002,6.726532,-353.223236,-0.002984,0.001836,0.046639,29.921108,1.524254,0.466390,-353.223236,0.047532,0.000000
32.030003,6.709038,-353.267700,-0.002971,0.001855,0.047116,29.843290,1.520290,0.471159,-353.267700,0.048166,0.000000
32.410000,7.025925,-353.267700,-0.002940,0.001885,0.047879,31.252874,1.592097,0.478789,-353.267700,0.048799,0.000000
32.790001,6.835266,-353.312195,-0.002928,0.001909,0.048495,30.404781,1.548893,0.484951,-353.312195,0.049431,0.000000
33.170002,6.823349,-353.401154,-0.002915,0.001933,0.049102,30.351772,1.546193,0.491022,-353.401154,0.050065,0.000000
33.550003,6.895966,-353.401154,-0.002910,0.001960,0.049787,30.674788,1.562648,0.497873,-353.401154,0.050698,0.000000
33.930000,6.598442,-353.445648,-0.002897,0.001971,0.050065,29.351336,1.495228,0.500651,-353.445648,0.051340,0.000000
34.310001,6.983101,-353.401154,-0.002871,0.002002,0.050862,31.062384,1.582393,0.508622,-353.401154,0.051973,0.000000
34.690002,6.990173,-353.445648,-0.002854,0.002028,0.051504,31.093843,1.583996,0.515041,-353.445648,0.052605,0.000000
35.070004,7.228493,-353.490112,-0.002837,0.002060,0.052319,32.153942,1.638000,0.523194,-353.490112,0.053239,0.000000
35.450001,7.262009,-353.534607,-0.002824,0.002086,0.052979,32.303028,1.645595,0.529787,-353.534607,0.053872,0.000000
35.830002,7.007675,-353.445648,-0.002820,0.002104,0.053430,31.171696,1.587962,0.534298,-353.445648,0.054505,0.000000
36.210003,7.164070,-353.534607,-0.002794,0.002128,0.054063,31.867376,1.623401,0.540627,-353.534607,0.055138,0.000000
36.590000,7.407974,-353.579071,-0.002781,0.002159,0.054843,32.952316,1.678671,0.548431,-353.579071,0.055771,0.000000
36.970001,7.293655,-353.623566,-0.002781,0.002183,0.055459,32.443798,1.652766,0.554586,-353.623566,0.056404,0.000000
37.350002,7.368881,-353.668030,-0.002755,0.002209,0.056110,32.778419,1.669812,0.561096,-353.668030,0.057037,0.000000
37.730003,6.911980,-353.579071,-0.002746,0.002220,0.056378,30.746021,1.566277,0.563783,-353.579071,0.057670,0.000000
38.110001,7.528625,-353.623566,-0.002708,0.002255,0.057280,33.488998,1.706011,0.572798,-353.623566,0.058303,0.000000
38.490002,7.721146,-353.712524,-0.002695,0.002284,0.058017,34.345371,1.749637,0.580171,-353.712524,0.058936,0.000000
38.870003,7.408348,-353.712524,-0.002695,0.002303,0.058486,32.953979,1.678756,0.584857,-353.712524,0.059570,0.000000
39.250000,7.096298,-353.801483,-0.002677,0.002311,0.058702,31.565910,1.608044,0.587022,-353.801483,0.060203,0.000000
39.630001,7.616508,-353.756989,-0.002660,0.002345,0.059552,33.879921,1.725925,0.595523,-353.756989,0.060835,0.000000
40.010002,7.787422,-353.756989,-0.002639,0.002376,0.060350,34.640182,1.764655,0.603501,-353.756989,0.061469,0.000000
40.390003,7.892059,-353.845978,-0.002613,0.002408,0.061156,35.105633,1.788366,0.611563,-353.845978,0.062102,0.000000
40.770000,7.779236,-353.801483,-0.002596,0.002432,0.061763,34.603767,1.762800,0.617634,-353.801483,0.062735,0.000000
41.150002,7.784073,-353.934937,-0.002608,0.002450,0.062232,34.625286,1.763896,0.622320,-353.934937,0.063368,0.000000
41.530003,8.389549,-353.934937,-0.002587,0.002480,0.062995,37.318581,1.901099,0.629950,-353.934937,0.064001,0.000000
41.910004,8.324760,-353.934937,-0.002557,0.002506,0.063645,37.030384,1.886418,0.636453,-353.934937,0.064634,0.000000
42.290001,8.411522,-353.890442,-0.002539,0.002535,0.064400,37.416317,1.906078,0.644000,-353.890442,0.065267,0.000000
42.670002,8.288269,-353.979401,-0.002531,0.002557,0.064937,36.868061,1.878149,0.649374,-353.979401,0.065900,0.000000
43.050003,8.332207,-354.023895,-0.002518,0.002577,0.065467,37.063507,1.888105,0.654666,-354.023895,0.066533,0.000000
43.430000,8.376144,-354.023895,-0.002483,0.002598,0.065987,37.258949,1.898061,0.659866,-354.023895,0.067167,0.000000
43.810001,8.708305,-354.023895,-0.002462,0.002628,0.066750,38.736477,1.973330,0.667504,-354.023895,0.067800,0.000000
44.190002,9.200203,-354.068359,-0.002458,0.002660,0.067566,40.924545,2.084796,0.675657,-354.068359,0.068432,0.000000
44.570004,8.990189,-354.068359,-0.002436,0.002681,0.068094,39.990356,2.037206,0.680940,-354.068359,0.069065,0.000000
44.950001,9.118286,-354.157318,-0.002423,0.002703,0.068658,40.560162,2.066233,0.686580,-354.157318,0.069707,0.000000
45.330002,9.020348,-354.201813,-0.002414,0.002720,0.069083,40.124512,2.044040,0.690827,-354.201813,0.070341,0.000000
45.710003,9.480232,-354.157318,-0.002384,0.002750,0.069846,42.170177,2.148251,0.698465,-354.157318,0.070974,0.000000
46.090004,9.494011,-354.201813,-0.002363,0.002771,0.070375,42.231468,2.151374,0.703748,-354.201813,0.071606,0.000000
46.470001,10.050331,-354.290771,-0.002328,0.002810,0.071373,44.706104,2.277438,0.713725,-354.290771,0.072240,0.000000
46.850002,9.829514,-354.290771,-0.002328,0.002828,0.071832,43.723862,2.227400,0.718320,-354.290771,0.072873,0.000000
47.230003,9.902130,-354.290771,-0.002320,0.002843,0.072223,44.046875,2.243855,0.722226,-354.290771,0.073506,0.000000
47.610001,10.629372,-354.290771,-0.002285,0.002876,0.073055,47.281807,2.408650,0.730545,-354.290771,0.074139,0.000000
47.990002,11.098930,-354.290771,-0.002268,0.002906,0.073801,49.370506,2.515054,0.738009,-354.290771,0.074772,0.000000
48.370003,11.201332,-354.335266,-0.002233,0.002933,0.074486,49.826015,2.538258,0.744860,-354.335266,0.075405,0.000000
48.750004,11.336510,-354.335266,-0.002225,0.002956,0.075076,50.427315,2.568890,0.750757,-354.335266,0.076038,0.000000
49.130001,11.421410,-354.424225,-0.002225,0.002978,0.075639,50.804966,2.588129,0.756389,-354.424225,0.076671,0.000000
49.510002,11.745369,-354.379730,-0.002207,0.003002,0.076246,52.246010,2.661539,0.762460,-354.379730,0.077304,0.000000
49.890003,12.556030,-354.424225,-0.002182,0.003034,0.077070,55.852013,2.845237,0.770703,-354.424225,0.077937,0.000000
50.270004,12.436493,-354.424225,-0.002151,0.003054,0.077565,55.320282,2.818150,0.775646,-354.424225,0.078571,0.000000
50.650002,12.767159,-354.468689,-0.002134,0.003080,0.078223,56.791157,2.893080,0.782232,-354.468689,0.079203,0.000000
51.030003,13.189430,-354.557648,-0.002108,0.003106,0.078883,58.669518,2.988768,0.788825,-354.557648,0.079836,0.000000
51.410004,13.475784,-354.513184,-0.002104,0.003127,0.079429,59.943283,3.053656,0.794290,-354.513184,0.080470,0.000000
51.790001,14.445816,-354.513184,-0.002082,0.003158,0.080209,64.258202,3.273469,0.802095,-354.513184,0.081103,0.000000
52.170002,14.697166,-354.602142,-0.002052,0.003184,0.080877,65.376259,3.330426,0.808771,-354.602142,0.081736,0.000000
52.550003,14.785049,-354.646637,-0.002031,0.003205,0.081397,65.767181,3.350340,0.813972,-354.646637,0.082369,0.000000
52.930004,15.274345,-354.691101,-0.002009,0.003231,0.082057,67.943680,3.461216,0.820565,-354.691101,0.083002,0.000000
53.310001,15.467606,-354.691101,-0.002005,0.003251,0.082568,68.803345,3.505010,0.825682,-354.691101,0.083635,0.000000
53.690002,16.313263,-354.691101,-0.001996,0.003278,0.083253,72.565018,3.696638,0.832533,-354.691101,0.084268,0.000000
54.070004,17.080353,-354.735596,-0.001949,0.003305,0.083947,75.977203,3.870463,0.839475,-354.735596,0.084901,0.000000
54.450001,17.606888,-354.780060,-0.001932,0.003331,0.084615,78.319351,3.989778,0.846151,-354.780060,0.085534,0.000000
54.830002,18.241035,-354.780060,-0.001910,0.003358,0.085291,81.140175,4.133478,0.852911,-354.780060,0.086168,0.000000
55.210003,18.016869,-354.824554,-0.001897,0.003370,0.085586,80.143036,4.082681,0.855863,-354.824554,0.086801,0.000000
55.590004,19.205856,-354.824554,-0.001876,0.003401,0.086384,85.431915,4.352109,0.863842,-354.824554,0.087442,0.000000
55.970001,20.040710,-354.869019,-0.001863,0.003426,0.087026,89.145531,4.541290,0.870261,-354.869019,0.088075,0.000000
56.350002,21.109795,-354.869019,-0.001841,0.003456,0.087789,93.901054,4.783547,0.877891,-354.869019,0.088708,0.000000
56.730003,21.940559,-354.913513,-0.001824,0.003483,0.088457,97.596481,4.971802,0.884568,-354.913513,0.089342,0.000000
57.110004,21.989342,-354.957977,-0.001802,0.003500,0.088908,97.813477,4.982856,0.889079,-354.957977,0.089975,0.000000
57.490002,22.323730,-354.913513,-0.001798,0.003517,0.089333,99.300911,5.058630,0.893326,-354.913513,0.090607,0.000000
57.870003,24.056007,-354.957977,-0.001772,0.003554,0.090278,107.006462,5.451169,0.902781,-354.957977,0.091241,0.000000
58.250004,24.880814,-355.002472,-0.001742,0.003578,0.090876,110.675385,5.638073,0.908761,-355.002472,0.091874,0.000000
58.630001,25.973724,-355.091431,-0.001738,0.003604,0.091544,115.536896,5.885730,0.915437,-355.091431,0.092507,0.000000
59.010002,25.678062,-355.091431,-0.001725,0.003613,0.091761,114.221725,5.818732,0.917610,-355.091431,0.093139,0.000000
59.390003,26.816399,-355.002472,-0.001707,0.003644,0.092559,119.285301,6.076683,0.925588,-355.002472,0.093773,0.000000
59.770004,29.507164,-355.046967,-0.001681,0.003682,0.093522,131.254425,6.686419,0.935217,-355.046967,0.094406,0.000000
60.150002,29.782722,-355.091431,-0.001664,0.003699,0.093946,132.480164,6.748861,0.939464,-355.091431,0.095039,0.000000
60.530003,29.854965,-355.224884,-0.001660,0.003712,0.094293,132.801514,6.765232,0.942931,-355.224884,0.095672,0.000000
60.910004,31.405518,-355.224884,-0.001660,0.003744,0.095100,139.698715,7.116592,0.951000,-355.224884,0.096305,0.000000
61.290005,33.403671,-355.224884,-0.001621,0.003773,0.095846,148.586945,7.569380,0.958457,-355.224884,0.096938,0.000000
61.670002,35.131477,-355.180389,-0.001613,0.003804,0.096626,156.272614,7.960907,0.966261,-355.180389,0.097572,0.000000
62.050003,35.842712,-355.224884,-0.001587,0.003826,0.097190,159.436340,8.122074,0.971900,-355.224884,0.098204,0.000000
62.430004,36.559898,-355.269348,-0.001574,0.003844,0.097650,162.626556,8.284592,0.976495,-355.269348,0.098837,0.000000
62.810001,38.346916,-355.358307,-0.001565,0.003876,0.098438,170.575607,8.689535,0.984383,-355.358307,0.099471,0.000000
63.190002,39.459190,-355.313843,-0.001548,0.003895,0.098942,175.523239,8.941580,0.989417,-355.313843,0.100104,0.000000
63.570004,41.640175,-355.313843,-0.001539,0.003931,0.099835,185.224747,9.435799,0.998349,-355.313843,0.100736,0.000000
63.950005,42.634415,-355.358307,-0.001509,0.003953,0.100398,189.647354,9.661097,1.003981,-355.358307,0.101370,0.000000
64.330002,44.079964,-355.358307,-0.001509,0.003977,0.101014,196.077469,9.988662,1.010143,-355.358307,0.102003,0.000000
64.710007,45.150162,-355.447266,-0.001500,0.003995,0.101474,200.837952,10.231173,1.014738,-355.447266,0.102636,0.000000
65.090004,46.955421,-355.447266,-0.001487,0.004024,0.102202,208.868149,10.640251,1.022020,-355.447266,0.103269,0.000000
65.470001,49.209763,-355.402802,-0.001475,0.004055,0.103000,218.895950,11.151092,1.029999,-355.402802,0.103902,0.000000
65.850006,50.398003,-355.447266,-0.001462,0.004076,0.103529,224.181519,11.420351,1.035290,-355.447266,0.104535,0.000000
66.230003,51.778389,-355.536255,-0.001449,0.004097,0.104058,230.321777,11.733150,1.040581,-355.536255,0.105168,0.000000
66.610001,53.315170,-355.536255,-0.001444,0.004118,0.104605,237.157715,12.081390,1.046047,-355.536255,0.105810,0.000000
66.990005,55.162514,-355.580719,-0.001427,0.004146,0.105298,245.375122,12.500005,1.052981,-355.580719,0.106443,0.000000
67.370003,56.943199,-355.580719,-0.001418,0.004168,0.105870,253.296005,12.903514,1.058703,-355.580719,0.107076,0.000000
67.750000,59.596352,-355.580719,-0.001406,0.004204,0.106773,265.097809,13.504725,1.067726,-355.580719,0.107709,0.000000
68.130005,60.639366,-355.536255,-0.001393,0.004220,0.107189,269.737366,13.741077,1.071890,-355.536255,0.108343,0.000000
68.510002,62.334030,-355.669678,-0.001388,0.004242,0.107736,277.275604,14.125093,1.077355,-355.669678,0.108975,0.000000
68.890007,64.624496,-355.714172,-0.001367,0.004271,0.108481,287.464111,14.644120,1.084811,-355.714172,0.109608,0.000000
69.270004,66.275223,-355.669678,-0.001371,0.004285,0.108837,294.806915,15.018180,1.088369,-355.669678,0.109053,0.000000
69.650002,65.501053,-355.714172,-0.001371,0.004285,0.108828,291.363220,14.842751,1.088278,-355.714172,294.500458,0.000000
70.030006,65.953125,-355.758636,-0.001337,0.004302,0.109270,293.374146,14.945192,1.092699,-355.758636,294.500458,0.000000
70.410004,65.523773,-355.803131,-0.001350,0.004295,0.109097,291.464294,14.847898,1.090966,-355.803131,294.500458,0.000000
70.790001,65.067993,-355.847595,-0.001341,0.004295,0.109106,289.436890,14.744618,1.091057,-355.847595,294.500458,0.000000
71.170006,64.698227,-355.803131,-0.001337,0.004296,0.109114,287.792084,14.660829,1.091140,-355.803131,294.500458,0.000000
71.550003,67.630280,-355.803131,-0.001341,0.004320,0.109738,300.834503,15.325240,1.097385,-355.803131,294.500458,0.000000
71.930000,66.565674,-355.803131,-0.001324,0.004153,0.105498,296.098907,15.083998,1.054979,-355.803131,294.500458,0.000000
72.310005,66.251770,-355.936584,-0.001311,0.004154,0.105515,294.702606,15.012865,1.055153,-355.936584,294.500458,0.000000
72.690002,65.998917,-355.936584,-0.001319,0.004154,0.105515,293.577850,14.955568,1.055153,-355.936584,294.500458,0.000000
73.070000,65.776245,-355.936584,-0.001319,0.004167,0.105836,292.587341,14.905110,1.058363,-355.936584,294.500458,0.000000
73.450005,65.556549,-355.981049,-0.001332,0.004232,0.107493,291.610107,14.855327,1.074925,-355.981049,294.500458,0.000000
73.830002,65.355469,-355.936584,-0.001319,0.004232,0.107501,290.715637,14.809761,1.075009,-355.936584,294.500458,0.000000
74.210007,65.363647,-356.070007,-0.001324,0.004298,0.109157,290.752014,14.811614,1.091571,-356.070007,294.500458,0.000000
74.590004,65.340195,-355.981049,-0.001315,0.004310,0.109470,290.647705,14.806300,1.094698,-355.981049,294.500458,0.000000
74.970001,65.217316,-356.070007,-0.001319,0.004310,0.109470,290.101105,14.778456,1.094698,-356.070007,294.500458,0.000000
75.350006,65.468292,-356.070007,-0.001328,0.004318,0.109686,291.217499,14.835327,1.096863,-356.070007,294.500458,0.000000
75.730003,65.388611,-356.114502,-0.001324,0.004318,0.109686,290.863068,14.817271,1.096863,-356.114502,294.500458,0.000000
76.110001,65.318222,-356.114502,-0.001315,0.004319,0.109695,290.549957,14.801320,1.096953,-356.114502,294.500458,0.000000
76.490005,65.245605,-356.114502,-0.001319,0.004319,0.109695,290.226959,14.784865,1.096953,-356.114502,294.500458,0.000000
76.870003,65.597870,-356.203461,-0.001319,0.004325,0.109860,291.793884,14.864690,1.098596,-356.203461,294.500458,0.000000
77.250000,65.584839,-356.247925,-0.001306,0.004325,0.109860,291.735931,14.861737,1.098596,-356.247925,294.500458,0.000000
77.630005,65.568832,-356.158966,-0.001311,0.004325,0.109860,291.664734,14.858110,1.098596,-356.158966,294.500458,0.000000
78.010002,65.498077,-356.292419,-0.001315,0.004325,0.109860,291.350006,14.842077,1.098596,-356.292419,294.500458,0.000000
78.390007,65.402374,-356.247925,-0.001298,0.004325,0.109860,290.924286,14.820390,1.098596,-356.247925,294.500458,0.000000
78.770004,65.336105,-356.381378,-0.001302,0.004326,0.109869,290.629517,14.805373,1.098687,-356.381378,294.500458,0.000000
79.150002,65.290298,-356.336914,-0.001328,0.004326,0.109886,290.425751,14.794993,1.098861,-356.336914,294.500458,0.000000
79.530006,65.337585,-356.336914,-0.001315,0.004328,0.109929,290.636108,14.805709,1.099293,-356.336914,294.500458,0.000000
79.910004,65.318222,-356.425873,-0.001311,0.004329,0.109955,290.549957,14.801320,1.099550,-356.425873,294.500458,0.000000
80.290001,65.353226,-356.381378,-0.001302,0.004329,0.109964,290.705658,14.809253,1.099641,-356.381378,294.500458,0.000000
80.670006,65.310410,-356.470337,-0.001298,0.004329,0.109964,290.515198,14.799551,1.099641,-356.470337,294.500458,0.000000
81.050003,65.308167,-356.425873,-0.001324,0.004330,0.109990,290.505219,14.799042,1.099898,-356.425873,294.500458,0.000000
81.430000,65.303329,-356.425873,-0.001315,0.004331,0.110007,290.483704,14.797946,1.100072,-356.425873,294.500458,0.000000
81.810005,65.332001,-356.470337,-0.001311,0.004332,0.110034,290.611267,14.804443,1.100337,-356.470337,294.500458,0.000000
82.190002,65.308914,-356.470337,-0.001298,0.004332,0.110042,290.508545,14.799212,1.100420,-356.470337,294.500458,0.000000
82.570007,65.301102,-356.603790,-0.001306,0.004333,0.110050,290.473816,14.797441,1.100504,-356.603790,294.500458,0.000000
82.950005,65.306305,-356.648254,-0.001315,0.004333,0.110068,290.496948,14.798620,1.100678,-356.648254,294.500458,0.000000
83.330002,65.295135,-356.514832,-0.001306,0.004334,0.110077,290.447266,14.796089,1.100769,-356.514832,294.500458,0.000000
83.710007,65.271301,-356.603790,-0.001319,0.004334,0.110085,290.341248,14.790689,1.100852,-356.603790,294.500458,0.000000
84.090004,65.308914,-356.648254,-0.001293,0.004335,0.110120,290.508545,14.799212,1.101200,-356.648254,294.500458,0.000000
84.470001,65.315247,-356.648254,-0.001293,0.004335,0.110120,290.536713,14.800647,1.101200,-356.648254,294.500458,0.000000
84.850006,65.299606,-356.737213,-0.001302,0.004335,0.110120,290.467163,14.797102,1.101200,-356.737213,294.500458,0.000000
85.230003,65.320084,-356.781708,-0.001306,0.004336,0.110137,290.558258,14.801743,1.101374,-356.781708,294.500458,0.000000
85.610001,65.307434,-356.692749,-0.001302,0.004337,0.110155,290.501984,14.798876,1.101548,-356.692749,294.500458,0.000000
85.990005,65.309296,-356.737213,-0.001298,0.004337,0.110172,290.510254,14.799298,1.101722,-356.737213,294.500458,0.000000
86.370003,65.320084,-356.781708,-0.001298,0.004337,0.110172,290.558258,14.801743,1.101722,-356.781708,294.500458,0.000000
86.750008,65.299240,-356.781708,-0.001302,0.004338,0.110181,290.465515,14.797020,1.101806,-356.781708,294.500458,0.000000
87.130005,65.294769,-356.826202,-0.001306,0.004339,0.110198,290.445648,14.796006,1.101980,-356.826202,294.500458,0.000000
87.510002,65.325302,-356.826202,-0.001293,0.004339,0.110215,290.581451,14.802925,1.102154,-356.826202,294.500458,0.000000
87.890007,65.321945,-356.781708,-0.001306,0.004339,0.110215,290.566528,14.802165,1.102154,-356.781708,294.500458,0.000000
88.270004,65.308914,-356.870667,-0.001298,0.004339,0.110215,290.508545,14.799212,1.102154,-356.870667,294.500458,0.000000
88.650002,65.292526,-357.004120,-0.001315,0.004339,0.110215,290.435669,14.795499,1.102154,-357.004120,294.500458,0.000000
89.030006,65.385254,-356.959625,-0.001311,0.004342,0.110285,290.848145,14.816510,1.102850,-356.959625,294.500458,0.000000
89.410004,65.424728,-356.959625,-0.001293,0.004342,0.110285,291.023712,14.825455,1.102850,-356.959625,294.500458,0.000000
89.790001,65.406845,-357.004120,-0.001298,0.004342,0.110285,290.944183,14.821403,1.102850,-357.004120,294.500458,0.000000
90.170006,65.388229,-357.004120,-0.001298,0.004342,0.110285,290.861359,14.817184,1.102850,-357.004120,294.500458,0.000000
90.550003,65.368500,-357.093079,-0.001298,0.004342,0.110285,290.773621,14.812714,1.102850,-357.093079,294.500458,0.000000
90.930008,65.351746,-357.137543,-0.001293,0.004342,0.110285,290.699097,14.808917,1.102850,-357.137543,294.500458,0.000000
91.310005,65.362534,-357.093079,-0.001302,0.004343,0.110320,290.747070,14.811362,1.103199,-357.093079,294.500458,0.000000
91.690002,65.370361,-357.048584,-0.001298,0.004343,0.110320,290.781891,14.813136,1.103199,-357.048584,294.500458,0.000000
92.070007,65.375198,-357.137543,-0.001281,0.004343,0.110320,290.803406,14.814232,1.103199,-357.137543,294.500458,0.000000
92.450005,65.356201,-357.182037,-0.001281,0.004343,0.110320,290.718903,14.809927,1.103199,-357.182037,294.500458,0.000000
92.830002,65.340942,-357.226532,-0.001293,0.004344,0.110328,290.651031,14.806470,1.103282,-357.226532,294.500458,0.000000
93.210007,65.324188,-357.182037,-0.001302,0.004344,0.110328,290.576508,14.802672,1.103282,-357.182037,294.500458,0.000000
93.590004,65.310028,-357.226532,-0.001298,0.004344,0.110328,290.513519,14.799464,1.103282,-357.226532,294.500458,0.000000
93.970001,65.305191,-357.315491,-0.001298,0.004344,0.110337,290.492004,14.798368,1.103373,-357.315491,294.500458,0.000000
94.350006,65.305557,-357.226532,-0.001293,0.004344,0.110346,290.493622,14.798450,1.103456,-357.226532,294.500458,0.000000
94.730003,65.299240,-357.448914,-0.001302,0.004345,0.110363,290.465515,14.797020,1.103630,-357.448914,294.500458,0.000000
95.110008,65.298859,-357.359955,-0.001302,0.004345,0.110363,290.463837,14.796933,1.103630,-357.359955,294.500458,0.000000
95.490005,65.289932,-357.404449,-0.001293,0.004345,0.110363,290.424133,14.794909,1.103630,-357.404449,294.500458,0.000000
95.870003,65.298492,-357.359955,-0.001298,0.004346,0.110380,290.462189,14.796850,1.103804,-357.359955,294.500458,0.000000
96.250008,65.340195,-357.359955,-0.001298,0.004347,0.110406,290.647705,14.806300,1.104061,-357.359955,294.500458,0.000000
96.630005,65.355835,-357.448914,-0.001293,0.004347,0.110406,290.717285,14.809844,1.104061,-357.448914,294.500458,0.000000
97.010002,65.353607,-357.537872,-0.001289,0.004347,0.110406,290.707367,14.809340,1.104061,-357.537872,294.500458,0.000000
97.390007,65.343918,-357.404449,-0.001293,0.004347,0.110406,290.664276,14.807143,1.104061,-357.404449,294.500458,0.000000
97.770004,65.340942,-357.448914,-0.001289,0.004347,0.110415,290.651031,14.806470,1.104152,-357.448914,294.500458,0.000000
98.150002,65.346893,-357.493408,-0.001285,0.004347,0.110424,290.677490,14.807817,1.104236,-357.493408,294.500458,0.000000
98.530006,65.329773,-357.493408,-0.001289,0.004347,0.110424,290.601349,14.803939,1.104236,-357.493408,294.500458,0.000000
98.910004,65.333862,-357.582367,-0.001289,0.004347,0.110424,290.619537,14.804865,1.104236,-357.582367,294.500458,0.000000
99.290001,65.320831,-357.582367,-0.001293,0.004347,0.110424,290.561584,14.801912,1.104236,-357.582367,294.500458,0.000000
99.670006,65.314133,-357.537872,-0.001293,0.004348,0.110441,290.531769,14.800394,1.104410,-357.537872,294.500458,0.000000
100.050003,65.317856,-357.582367,-0.001306,0.004348,0.110441,290.548340,14.801237,1.104410,-357.582367,294.500458,0.000000
100.430008,65.314499,-357.626862,-0.001298,0.004348,0.110441,290.533386,14.800477,1.104410,-357.626862,294.500458,0.000000
100.810005,65.295883,-357.671326,-0.001298,0.004348,0.110441,290.450592,14.796259,1.104410,-357.671326,294.500458,0.000000
101.190002,65.286942,-357.715820,-0.001293,0.004348,0.110441,290.410828,14.794232,1.104410,-357.715820,294.500458,0.000000
101.570007,65.283966,-357.715820,-0.001298,0.004348,0.110449,290.397583,14.793558,1.104493,-357.715820,294.500458,0.000000
101.950005,65.283600,-357.715820,-0.001293,0.004349,0.110467,290.395966,14.793475,1.104667,-357.715820,294.500458,0.000000
102.330002,65.306305,-357.715820,-0.001276,0.004349,0.110476,290.496948,14.798620,1.104758,-357.715820,294.500458,0.000000
102.710007,65.316742,-357.804779,-0.001281,0.004349,0.110476,290.543365,14.800985,1.104758,-357.804779,294.500458,0.000000
103.090004,65.314499,-357.893738,-0.001276,0.004349,0.110476,290.533386,14.800477,1.104758,-357.893738,294.500458,0.000000
103.470001,65.293274,-357.804779,-0.001289,0.004349,0.110476,290.438995,14.795667,1.104758,-357.804779,294.500458,0.000000
103.850006,65.295135,-357.893738,-0.001298,0.004349,0.110476,290.447266,14.796089,1.104758,-357.893738,294.500458,0.000000
104.230003,65.292526,-357.849243,-0.001281,0.004349,0.110476,290.435669,14.795499,1.104758,-357.849243,294.500458,0.000000
104.610008,65.286194,-357.938202,-0.001298,0.004349,0.110476,290.407501,14.794064,1.104758,-357.938202,294.500458,0.000000
104.990005,65.267212,-357.982697,-0.001306,0.004349,0.110476,290.323059,14.789762,1.104758,-357.982697,294.500458,0.000000
105.370003,65.260132,-357.938202,-0.001293,0.004350,0.110484,290.291565,14.788157,1.104841,-357.938202,294.500458,0.000000
105.750008,65.251572,-357.938202,-0.001289,0.004350,0.110502,290.253479,14.786218,1.105015,-357.938202,294.500458,0.000000
106.130005,65.288071,-358.027161,-0.001298,0.004351,0.110519,290.415833,14.794489,1.105189,-358.027161,294.500458,0.000000
106.510002,65.307053,-357.982697,-0.001293,0.004351,0.110519,290.500275,14.798789,1.105189,-357.982697,294.500458,0.000000
106.890007,65.300720,-358.071655,-0.001293,0.004351,0.110519,290.472107,14.797355,1.105189,-358.071655,294.500458,0.000000
107.270004,65.292908,-358.071655,-0.001298,0.004351,0.110528,290.437347,14.795585,1.105280,-358.071655,294.500458,0.000000
107.650002,65.282104,-358.071655,-0.001293,0.004352,0.110536,290.389313,14.793136,1.105363,-358.071655,294.500458,0.000000
108.030006,65.330887,-358.116150,-0.001289,0.004353,0.110554,290.606293,14.804191,1.105538,-358.116150,294.500458,0.000000
108.410004,65.339447,-358.160614,-0.001293,0.004353,0.110554,290.644379,14.806130,1.105538,-358.160614,294.500458,0.000000
108.790009,65.345032,-358.205109,-0.001281,0.004353,0.110554,290.669220,14.807396,1.105538,-358.205109,294.500458,0.000000
109.170006,65.350616,-358.205109,-0.001289,0.004353,0.110554,290.694061,14.808661,1.105538,-358.205109,294.500458,0.000000
109.550003,65.342056,-358.205109,-0.001302,0.004353,0.110554,290.655975,14.806722,1.105538,-358.205109,294.500458,0.000000
109.930008,65.354340,-358.205109,-0.001285,0.004353,0.110554,290.710632,14.809505,1.105538,-358.205109,294.500458,0.000000
110.310005,65.334976,-358.249573,-0.001298,0.004353,0.110554,290.624481,14.805117,1.105538,-358.249573,294.500458,0.000000
110.690002,65.329025,-358.294067,-0.001293,0.004353,0.110554,290.598022,14.803769,1.105538,-358.294067,294.500458,0.000000
111.070007,65.319336,-358.338531,-0.001285,0.004353,0.110554,290.554932,14.801573,1.105538,-358.338531,294.500458,0.000000
111.450005,65.309296,-358.338531,-0.001298,0.004353,0.110554,290.510254,14.799298,1.105538,-358.338531,294.500458,0.000000
111.830002,65.310028,-358.338531,-0.001289,0.004353,0.110554,290.513519,14.799464,1.105538,-358.338531,294.500458,0.000000
112.210007,65.284332,-358.338531,-0.001281,0.004353,0.110554,290.399200,14.793641,1.105538,-358.338531,294.500458,0.000000
112.590004,65.276886,-358.427490,-0.001289,0.004353,0.110554,290.366089,14.791954,1.105538,-358.427490,294.500458,0.000000
112.970009,65.259384,-358.427490,-0.001285,0.004353,0.110562,290.288239,14.787988,1.105621,-358.427490,294.500458,0.000000
113.350006,65.284714,-358.427490,-0.001285,0.004354,0.110589,290.400909,14.793728,1.105886,-358.427490,294.500458,0.000000
113.730003,65.280243,-358.471985,-0.001289,0.004354,0.110589,290.381012,14.792715,1.105886,-358.471985,294.500458,0.000000
114.110008,65.290665,-358.471985,-0.001272,0.004354,0.110589,290.427368,14.795076,1.105886,-358.471985,294.500458,0.000000
114.490005,65.280609,-358.605438,-0.001281,0.004354,0.110589,290.382660,14.792797,1.105886,-358.605438,294.500458,0.000000
114.870003,65.268326,-358.560944,-0.001285,0.004354,0.110589,290.328003,14.790014,1.105886,-358.560944,294.500458,0.000000
115.250008,65.271683,-358.605438,-0.001285,0.004354,0.110589,290.342957,14.790774,1.105886,-358.605438,294.500458,0.000000
115.630005,65.270935,-358.516479,-0.001293,0.004354,0.110589,290.339630,14.790605,1.105886,-358.516479,294.500458,0.000000
116.010002,65.256790,-358.605438,-0.001293,0.004354,0.110589,290.276703,14.787400,1.105886,-358.605438,294.500458,0.000000
116.390007,65.248596,-358.649902,-0.001289,0.004354,0.110589,290.240265,14.785542,1.105886,-358.649902,294.500458,0.000000
116.770004,65.244125,-358.694397,-0.001298,0.004354,0.110589,290.220367,14.784530,1.105886,-358.694397,294.500458,0.000000
117.150009,65.234436,-358.649902,-0.001293,0.004354,0.110589,290.177277,14.782334,1.105886,-358.649902,294.500458,0.000000
117.530006,65.227737,-358.783356,-0.001298,0.004354,0.110589,290.147461,14.780817,1.105886,-358.783356,294.500458,0.000000
117.910004,65.194229,-358.738861,-0.001289,0.004354,0.110589,289.998413,14.773223,1.105886,-358.738861,294.500458,0.000000
118.290009,65.511490,-358.783356,-0.001276,0.004359,0.110719,291.409668,14.845116,1.107188,-358.783356,294.500458,0.000000
118.670006,65.530472,-358.827820,-0.001276,0.004359,0.110710,291.494110,14.849417,1.107097,-358.827820,294.500458,0.000000
119.050003,65.561386,-358.872314,-0.001289,0.004359,0.110710,291.631622,14.856422,1.107097,-358.872314,294.500458,0.000000
119.430008,65.565475,-358.738861,-0.001281,0.004359,0.110710,291.649811,14.857348,1.107097,-358.738861,294.500458,0.000000
119.810005,65.571442,-358.827820,-0.001293,0.004359,0.110710,291.676331,14.858701,1.107097,-358.827820,294.500458,0.000000
120.190002,65.570694,-358.916809,-0.001276,0.004359,0.110710,291.673004,14.858532,1.107097,-358.916809,294.500458,0.000000
120.570007,65.567719,-358.961273,-0.001285,0.004359,0.110710,291.659790,14.857858,1.107097,-358.961273,294.500458,0.000000
120.950005,65.572922,-358.916809,-0.001289,0.004359,0.110710,291.682922,14.859036,1.107097,-358.916809,294.500458,0.000000
121.330009,65.571060,-358.961273,-0.001298,0.004359,0.110710,291.674652,14.858614,1.107097,-358.961273,294.500458,0.000000
121.710007,65.565109,-358.961273,-0.001289,0.004359,0.110710,291.648163,14.857265,1.107097,-358.961273,294.500458,0.000000
122.090004,65.565109,-359.005768,-0.001276,0.004359,0.110710,291.648163,14.857265,1.107097,-359.005768,294.500458,0.000000
122.470009,65.547241,-359.005768,-0.001272,0.004359,0.110710,291.568695,14.853217,1.107097,-359.005768,294.500458,0.000000
122.850006,65.545380,-359.139191,-0.001289,0.004359,0.110710,291.560425,14.852796,1.107097,-359.139191,294.500458,0.000000
123.230003,65.520798,-359.050232,-0.001281,0.004359,0.110710,291.451050,14.847225,1.107097,-359.050232,294.500458,0.000000
123.610008,65.516693,-359.050232,-0.001272,0.004359,0.110710,291.432800,14.846294,1.107097,-359.050232,294.500458,0.000000
123.990005,65.518936,-359.050232,-0.001276,0.004359,0.110710,291.442780,14.846803,1.107097,-359.050232,294.500458,0.000000
124.370003,65.505157,-359.139191,-0.001281,0.004359,0.110710,291.381500,14.843681,1.107097,-359.139191,294.500458,0.000000
124.750008,65.487656,-359.183685,-0.001285,0.004359,0.110710,291.303650,14.839715,1.107097,-359.183685,294.500458,0.000000
125.130005,65.489517,-359.139191,-0.001276,0.004359,0.110710,291.311920,14.840137,1.107097,-359.139191,294.500458,0.000000
125.510010,65.482437,-359.183685,-0.001272,0.004359,0.110710,291.280426,14.838532,1.107097,-359.183685,294.500458,0.000000
125.890007,65.480209,-359.183685,-0.001289,0.004359,0.110710,291.270508,14.838028,1.107097,-359.183685,294.500458,0.000000
126.270004,65.461594,-359.272644,-0.001285,0.004359,0.110710,291.187714,14.833809,1.107097,-359.272644,294.500458,0.000000
126.650009,65.461594,-359.317108,-0.001281,0.004359,0.110710,291.187714,14.833809,1.107097,-359.317108,294.500458,0.000000
127.030006,65.434402,-359.317108,-0.001293,0.004359,0.110710,291.066772,14.827648,1.107097,-359.317108,294.500458,0.000000
127.410004,65.436264,-359.317108,-0.001281,0.004359,0.110710,291.075043,14.828069,1.107097,-359.317108,294.500458,0.000000
127.790009,65.404251,-359.272644,-0.001289,0.004359,0.110710,290.932648,14.820815,1.107097,-359.272644,294.500458,0.000000
128.170013,65.385620,-359.317108,-0.001276,0.004359,0.110710,290.849762,14.816593,1.107097,-359.317108,294.500458,0.000000
128.550003,65.365891,-359.406097,-0.001289,0.004359,0.110719,290.761993,14.812122,1.107188,-359.406097,294.500458,0.000000
128.930008,65.388977,-359.450562,-0.001289,0.004359,0.110719,290.864685,14.817353,1.107188,-359.450562,294.500458,0.000000
129.310013,65.382278,-359.361603,-0.001285,0.004359,0.110719,290.834900,14.815836,1.107188,-359.361603,294.500458,0.000000
129.690002,65.361786,-359.406097,-0.001285,0.004359,0.110719,290.743744,14.811193,1.107188,-359.406097,294.500458,0.000000
130.070007,65.354340,-359.450562,-0.001268,0.004351,0.110511,290.710632,14.809505,1.105106,-359.450562,0.110554,0.000000
130.450012,65.303696,-359.539520,-0.001276,0.004341,0.110268,290.485352,14.798029,1.102676,-359.539520,0.109921,0.000000
130.830002,65.189011,-359.495056,-0.001298,0.004323,0.109808,289.975189,14.772040,1.098081,-359.495056,0.109287,0.000000
131.210007,65.154388,-359.584015,-0.001289,0.004295,0.109088,289.821198,14.764195,1.090882,-359.584015,0.108654,0.000000
131.590012,65.108948,-359.539520,-0.001281,0.004273,0.108542,289.619049,14.753899,1.085417,-359.539520,0.108022,0.000000
131.970001,65.111191,-359.628479,-0.001281,0.004250,0.107952,289.629028,14.754407,1.079520,-359.628479,0.107388,0.000000
132.350006,65.048630,-359.672974,-0.001276,0.004226,0.107337,289.350769,14.740230,1.073366,-359.672974,0.106755,0.000000
132.730011,65.034103,-359.672974,-0.001302,0.004206,0.106833,289.286133,14.736938,1.068332,-359.672974,0.106122,0.000000
133.110001,65.003204,-359.628479,-0.001293,0.004177,0.106105,289.148682,14.729937,1.061050,-359.628479,0.105489,0.000000
133.490005,64.995377,-359.761932,-0.001276,0.004154,0.105506,289.113861,14.728163,1.055062,-359.761932,0.104856,0.000000
133.870010,64.634171,-359.761932,-0.001276,0.004133,0.104977,287.507141,14.646313,1.049771,-359.761932,0.104223,0.000000
134.250000,63.755005,-359.806427,-0.001293,0.004107,0.104309,283.596436,14.447090,1.043094,-359.806427,0.103590,0.000000
134.630005,62.886635,-359.806427,-0.001281,0.004087,0.103807,279.733734,14.250315,1.038068,-359.806427,0.102957,0.000000
135.010010,62.173538,-359.850891,-0.001281,0.004069,0.103356,276.561707,14.088725,1.033556,-359.850891,0.102315,0.000000
135.389999,59.849190,-359.806427,-0.001263,0.004034,0.102471,266.222504,13.562019,1.024715,-359.806427,0.101682,0.000000
135.770004,58.217453,-359.850891,-0.001255,0.004011,0.101873,258.964172,13.192264,1.018727,-359.850891,0.101049,0.000000
136.150009,56.598381,-359.895386,-0.001268,0.003995,0.101465,251.762177,12.825377,1.014655,-359.895386,0.100416,0.000000
136.530014,54.338448,-359.939850,-0.001263,0.003968,0.100780,241.709488,12.313268,1.007804,-359.939850,0.099783,0.000000
136.910004,52.699265,-359.895386,-0.001263,0.003946,0.100225,234.418030,11.941824,1.002248,-359.895386,0.099150,0.000000
137.290009,49.163589,-359.939850,-0.001259,0.003915,0.099436,218.690567,11.140629,0.994360,-359.939850,0.098516,0.000000
137.670013,46.344360,-359.984344,-0.001259,0.003890,0.098802,206.150009,10.501782,0.988024,-359.984344,0.097883,0.000000
138.050003,43.863617,-360.028809,-0.001268,0.003869,0.098282,195.115112,9.939638,0.982824,-360.028809,0.097251,0.000000
138.430008,41.872910,-360.073303,-0.001272,0.003852,0.097849,186.260010,9.488537,0.978486,-360.073303,0.096617,0.000000
138.810013,39.008995,-360.073303,-0.001263,0.003826,0.097173,173.520676,8.839565,0.971726,-360.073303,0.095984,0.000000
139.190002,35.715729,-360.073303,-0.001272,0.003792,0.096314,158.871490,8.093300,0.963142,-360.073303,0.095351,0.000000
139.570007,33.204453,-360.117767,-0.001259,0.003770,0.095759,147.700775,7.524236,0.957586,-360.117767,0.094719,0.000000
139.950012,30.235527,-360.162262,-0.001272,0.003743,0.095083,134.494339,6.851469,0.950826,-360.162262,0.094085,0.000000
140.330002,28.443298,-360.162262,-0.001263,0.003730,0.094744,126.522110,6.445344,0.947442,-360.162262,0.093452,0.000000
140.710007,25.031624,-360.162262,-0.001263,0.003696,0.093877,111.346222,5.672247,0.938767,-360.162262,0.092819,0.000000
141.090012,21.864967,-360.206757,-0.001259,0.003669,0.093183,97.260231,4.954672,0.931834,-360.206757,0.092186,0.000000
141.470001,19.179047,-360.295715,-0.001255,0.003647,0.092637,85.312660,4.346034,0.926368,-360.295715,0.091553,0.000000
141.850006,16.087608,-360.295715,-0.001263,0.003618,0.091909,71.561256,3.645504,0.919086,-360.295715,0.090920,0.000000
142.230011,13.484726,-360.295715,-0.001259,0.003596,0.091345,59.983055,3.055683,0.913447,-360.295715,0.090286,0.000000
142.610001,10.877747,-360.295715,-0.001268,0.003570,0.090677,48.386635,2.464933,0.906770,-360.295715,0.089654,0.000000
142.990005,7.603470,-360.340179,-0.001268,0.003543,0.089992,33.821922,1.722971,0.899919,-360.340179,0.089021,0.000000
143.370010,5.103363,-360.340179,-0.001259,0.003520,0.089411,22.700893,1.156439,0.894106,-360.340179,0.088387,0.000000
143.750000,2.867638,-360.340179,-0.001276,0.003500,0.088891,12.755889,0.649816,0.888905,-360.340179,0.087754,0.000000
144.130005,-0.013031,-360.429138,-0.001276,0.003470,0.088145,-0.057965,-0.002953,0.881449,-360.429138,0.087121,0.000000
144.510010,-1.441456,-360.384674,-0.001259,0.003448,0.087572,-6.411916,-0.326639,0.875719,-360.384674,0.086488,0.000000
144.889999,-0.129585,-360.384674,-0.001268,0.003423,0.086956,-0.576424,-0.029364,0.869564,-360.384674,0.085855,0.000000
145.270004,-0.030907,-360.473633,-0.001259,0.003400,0.086358,-0.137480,-0.007004,0.863584,-360.473633,0.085222,0.000000
145.650009,-0.043198,-360.473633,-0.001255,0.003371,0.085612,-0.192153,-0.009789,0.856121,-360.473633,0.084580,0.000000
146.030014,-0.016754,-360.473633,-0.001272,0.003358,0.085300,-0.074526,-0.003797,0.853002,-360.473633,0.083947,0.000000
146.410004,0.000748,-360.518097,-0.001272,0.003328,0.084537,0.003326,0.000169,0.845371,-360.518097,0.083314,0.000000
146.790009,-0.037613,-360.518097,-0.001268,0.003296,0.083713,-0.167311,-0.008523,0.837128,-360.518097,0.082681,0.000000
147.170013,-0.040588,-360.562592,-0.001272,0.003270,0.083054,-0.180546,-0.009197,0.830542,-360.562592,0.082048,0.000000
147.550003,-0.017876,-360.651550,-0.001293,0.003243,0.082377,-0.079515,-0.004051,0.823775,-360.651550,0.081415,0.000000
147.930008,-0.017128,-360.651550,-0.001293,0.003226,0.081935,-0.076189,-0.003881,0.819354,-360.651550,0.080782,0.000000
148.310013,-0.018990,-360.607056,-0.001285,0.003200,0.081268,-0.084470,-0.004303,0.812678,-360.607056,0.080149,0.000000
148.690002,-0.042450,-360.607056,-0.001285,0.003172,0.080574,-0.188827,-0.009619,0.805736,-360.607056,0.079515,0.000000
149.070007,-0.043571,-360.696045,-0.001302,0.003144,0.079863,-0.193816,-0.009873,0.798628,-360.696045,0.078883,0.000000
149.450012,0.000374,-360.740509,-0.001319,0.003119,0.079212,0.001663,0.000085,0.792118,-360.740509,0.078250,0.000000
149.830002,-0.042450,-360.740509,-0.001332,0.003096,0.078649,-0.188827,-0.009619,0.786486,-360.740509,0.077617,0.000000
150.210007,-0.021973,-360.696045,-0.001328,0.003079,0.078207,-0.097739,-0.004979,0.782065,-360.696045,0.076983,0.000000
150.590012,-0.022346,-360.740509,-0.001345,0.003063,0.077790,-0.099402,-0.005064,0.777902,-360.740509,0.076350,0.000000
150.970001,-0.032394,-360.740509,-0.001362,0.003022,0.076767,-0.144098,-0.007341,0.767668,-360.740509,0.075718,0.000000
151.350006,-0.035751,-360.829468,-0.001358,0.002997,0.076125,-0.159030,-0.008101,0.761248,-360.829468,0.075084,0.000000
151.730011,-0.042076,-360.873962,-0.001406,0.002972,0.075492,-0.187164,-0.009535,0.754920,-360.873962,0.074451,0.000000
152.110001,-0.030159,-360.873962,-0.001406,0.002949,0.074911,-0.134154,-0.006834,0.749106,-360.873962,0.073818,0.000000
152.490005,-0.051018,-360.873962,-0.001406,0.002928,0.074382,-0.226938,-0.011561,0.743815,-360.873962,0.073185,0.000000
152.870010,-0.014153,-360.918427,-0.001436,0.002893,0.073488,-0.062954,-0.003207,0.734883,-360.918427,0.072552,0.000000
153.250000,-0.027931,-360.962921,-0.001444,0.002874,0.073003,-0.124244,-0.006329,0.730031,-360.962921,0.071919,0.000000
153.630005,-0.007446,-360.918427,-0.001470,0.002844,0.072231,-0.033123,-0.001687,0.722309,-360.918427,0.071285,0.000000
154.010010,-0.027184,-360.962921,-0.001487,0.002820,0.071624,-0.120918,-0.006160,0.716238,-360.962921,0.070653,0.000000
154.390015,-0.014153,-360.962921,-0.001483,0.002796,0.071017,-0.062954,-0.003207,0.710167,-360.962921,0.070020,0.000000
154.770004,-0.014153,-361.051880,-0.001509,0.002769,0.070341,-0.062954,-0.003207,0.703408,-361.051880,0.069386,0.000000
155.000000,0.010796,-361.007385,-0.001526,0.002764,0.070211,0.048021,0.002446,0.702106,-361.007385,0.070071,0.000000