File: Data/compression 21/AutoNoHeating-10-21-reverse-2-4_09132024_170909.csv
Time (sec),S:Load (lbs),S:HL1 (DIM),S:LVDT (in),S:Position (in),Ch:Position (mm),Ch:Load (N),Ch:Stress (MPa),Ch:Strain (mm/mm),Ch:HL1 (DIM),Set Point (),Cycles ()
0.110000,0.013031,-388.229736,-0.012400,-0.007779,-0.197597,0.057965,0.002953,-1.975973,-388.229736,-0.197329,0.000000
0.490000,-0.030533,-388.185272,-0.012404,-0.007727,-0.196262,-0.135817,-0.006919,-1.962619,-388.185272,-0.195750,0.000000
0.870000,-0.039474,-388.140778,-0.012309,-0.007503,-0.190572,-0.175591,-0.008945,-1.905725,-388.140778,-0.189420,0.000000
1.250000,-0.046173,-388.274231,-0.012055,-0.007252,-0.184207,-0.205388,-0.010463,-1.842071,-388.274231,-0.183088,0.000000
1.630000,-0.038353,-388.274231,-0.011788,-0.007014,-0.178154,-0.170603,-0.008691,-1.781543,-388.274231,-0.176758,0.000000
2.010000,-0.003723,-388.274231,-0.011551,-0.006759,-0.171667,-0.016561,-0.000844,-1.716669,-388.274231,-0.170427,0.000000
2.390000,0.008568,-388.318695,-0.011283,-0.006512,-0.165414,0.038112,0.001941,-1.654143,-388.318695,-0.164096,0.000000
2.770000,-0.010796,-388.363190,-0.011025,-0.006261,-0.159031,-0.048021,-0.002446,-1.590315,-388.363190,-0.157766,0.000000
3.150000,-0.022713,-388.363190,-0.010774,-0.006013,-0.152718,-0.101031,-0.005147,-1.527182,-388.363190,-0.151434,0.000000
3.530000,-0.040962,-388.363190,-0.010520,-0.005765,-0.146431,-0.182209,-0.009282,-1.464308,-388.363190,-0.145104,0.000000
3.910000,-0.015640,-388.363190,-0.010283,-0.005514,-0.140048,-0.069571,-0.003544,-1.400479,-388.363190,-0.138773,0.000000
4.290000,-0.016754,-388.363190,-0.009985,-0.005261,-0.133630,-0.074526,-0.003797,-1.336303,-388.363190,-0.132443,0.000000
4.670000,-0.014526,-388.363190,-0.009740,-0.005010,-0.127256,-0.064617,-0.003292,-1.272565,-388.363190,-0.126112,0.000000
5.050000,-0.017502,-388.496613,-0.009494,-0.004765,-0.121030,-0.077852,-0.003966,-1.210296,-388.496613,-0.119781,0.000000
5.430000,-0.043198,-388.496613,-0.009253,-0.004517,-0.114742,-0.192153,-0.009789,-1.147421,-388.496613,-0.113450,0.000000
5.810000,-0.075218,-388.452148,-0.008972,-0.004264,-0.108299,-0.334587,-0.017045,-1.082987,-388.452148,-0.107119,0.000000
6.190000,-0.007446,-388.452148,-0.008722,-0.004010,-0.101864,-0.033123,-0.001687,-1.018644,-388.452148,-0.100789,0.000000
6.570000,-0.031281,-388.541107,-0.008468,-0.003760,-0.095516,-0.139143,-0.007088,-0.955164,-388.541107,-0.094458,0.000000
6.950000,-0.000000,-388.541107,-0.008235,-0.003514,-0.089255,-0.000000,-0.000000,-0.892546,-388.541107,-0.088127,0.000000
7.330000,-0.040588,-388.496613,-0.007981,-0.003273,-0.083132,-0.180546,-0.009197,-0.831322,-388.496613,-0.081797,0.000000
7.710001,-0.065536,-388.496613,-0.007692,-0.003016,-0.076602,-0.291521,-0.014851,-0.766017,-388.496613,-0.075466,0.000000
8.090000,-0.071121,-388.541107,-0.007442,-0.002764,-0.070193,-0.316363,-0.016116,-0.701931,-388.541107,-0.069135,0.000000
8.470000,-0.032028,-388.674561,-0.007192,-0.002515,-0.063880,-0.142469,-0.007258,-0.638799,-388.674561,-0.062804,0.000000
8.850000,-0.003723,-388.630066,-0.006924,-0.002265,-0.057540,-0.016561,-0.000844,-0.575402,-388.630066,-0.056474,0.000000
9.230000,-0.009682,-388.674561,-0.006679,-0.002018,-0.051262,-0.043066,-0.002194,-0.512619,-388.674561,-0.050143,0.000000
9.610001,-0.026436,-388.630066,-0.006411,-0.001767,-0.044870,-0.117593,-0.005990,-0.448699,-388.630066,-0.043812,0.000000
9.990001,-0.058838,-388.719025,-0.006174,-0.001523,-0.038695,-0.261724,-0.013333,-0.386953,-388.719025,-0.037481,0.000000
10.370001,-0.007446,-388.763519,-0.005898,-0.001268,-0.032200,-0.033123,-0.001687,-0.321996,-388.763519,-0.031150,0.000000
10.750001,0.013779,-388.807983,-0.005665,-0.001027,-0.026095,0.061291,0.003122,-0.260946,-388.807983,-0.024820,0.000000
11.130000,0.008934,-388.719025,-0.005407,-0.000779,-0.019781,0.039741,0.002024,-0.197814,-388.719025,-0.018489,0.000000
11.510000,-0.011543,-388.807983,-0.005157,-0.000530,-0.013468,-0.051347,-0.002616,-0.134682,-388.807983,-0.012159,0.000000
11.890000,-0.015640,-388.763519,-0.004898,-0.000278,-0.007068,-0.069571,-0.003544,-0.070679,-388.763519,-0.005827,0.000000
12.270000,0.009308,-388.896942,-0.004631,-0.000033,-0.000841,0.041403,0.002109,-0.008410,-388.896942,0.000503,0.000000
12.650001,0.122879,-388.852478,-0.004398,-0.000003,-0.000078,0.546593,0.027845,-0.000780,-388.852478,0.000113,0.000000
13.030001,0.106499,-388.896942,-0.004398,-0.000003,-0.000078,0.473730,0.024133,-0.000780,-388.896942,0.000113,0.000000
13.410001,0.141502,-388.852478,-0.004411,-0.000003,-0.000078,0.629434,0.032065,-0.000780,-388.852478,0.000564,0.000000
13.790001,0.100540,-388.852478,-0.004398,-0.000003,-0.000078,0.447225,0.022783,-0.000780,-388.852478,0.001197,0.000000
14.170001,0.190651,-388.896942,-0.004363,0.000037,0.000945,0.848058,0.043202,0.009455,-388.896942,0.001830,0.000000
14.550001,0.240181,-389.030396,-0.004337,0.000060,0.001535,1.068378,0.054426,0.015352,-389.030396,0.002463,0.000000
14.930000,0.272949,-389.074890,-0.004346,0.000087,0.002203,1.214139,0.061851,0.022028,-389.074890,0.003096,0.000000
15.310000,0.343697,-389.030396,-0.004299,0.000113,0.002870,1.528839,0.077883,0.028705,-389.030396,0.003738,0.000000
15.690001,0.414078,-389.030396,-0.004264,0.000135,0.003417,1.841910,0.093831,0.034170,-389.030396,0.004371,0.000000
16.070002,0.487434,-389.030396,-0.004247,0.000154,0.003903,2.168216,0.110454,0.039030,-389.030396,0.005004,0.000000
16.450001,0.614410,-389.074890,-0.004204,0.000190,0.004814,2.733034,0.139227,0.048136,-389.074890,0.005637,0.000000
16.830000,0.654633,-389.119354,-0.004199,0.000211,0.005368,2.911951,0.148342,0.053685,-389.119354,0.006270,0.000000
17.210001,0.752190,-389.119354,-0.004182,0.000237,0.006010,3.345906,0.170449,0.060104,-389.119354,0.006904,0.000000
17.590000,0.824059,-389.119354,-0.004152,0.000258,0.006548,3.665596,0.186734,0.065479,-389.119354,0.007536,0.000000
17.970001,0.898537,-389.163849,-0.004122,0.000279,0.007077,3.996891,0.203611,0.070770,-389.163849,0.008169,0.000000
18.350000,1.040779,-389.163849,-0.004105,0.000312,0.007935,4.629617,0.235844,0.079354,-389.163849,0.008803,0.000000
18.730001,1.057907,-389.208313,-0.004074,0.000336,0.008525,4.705806,0.239725,0.085251,-389.208313,0.009436,0.000000
19.110001,1.133873,-389.297272,-0.004066,0.000361,0.009158,5.043719,0.256939,0.091579,-389.297272,0.010069,0.000000
19.490002,1.182655,-389.252808,-0.004040,0.000383,0.009739,5.260714,0.267994,0.097393,-389.252808,0.010702,0.000000
19.870001,1.286919,-389.252808,-0.004018,0.000406,0.010303,5.724500,0.291620,0.103032,-389.252808,0.011335,0.000000
20.250002,1.404587,-389.297272,-0.003967,0.000438,0.011119,6.247914,0.318284,0.111185,-389.297272,0.011968,0.000000
20.630001,1.403473,-389.297272,-0.003958,0.000455,0.011551,6.242959,0.318031,0.115515,-389.297272,0.012601,0.000000
21.010000,1.505875,-389.386230,-0.003932,0.000485,0.012324,6.698465,0.341236,0.123236,-389.386230,0.013234,0.000000
21.390001,1.582207,-389.386230,-0.003885,0.000512,0.013017,7.038007,0.358533,0.130170,-389.386230,0.013867,0.000000
21.770000,1.609764,-389.341766,-0.003889,0.000530,0.013468,7.160588,0.364778,0.134682,-389.341766,0.014501,0.000000
22.150002,1.681633,-389.341766,-0.003859,0.000558,0.014162,7.480277,0.381063,0.141623,-389.341766,0.015134,0.000000
22.530001,1.699883,-389.430725,-0.003833,0.000583,0.014803,7.561455,0.385199,0.148035,-389.430725,0.015766,0.000000
22.910002,1.719986,-389.519684,-0.003811,0.000605,0.015377,7.650880,0.389754,0.153765,-389.519684,0.016399,0.000000
23.290001,1.786644,-389.475220,-0.003773,0.000629,0.015984,7.947389,0.404859,0.159836,-389.475220,0.017033,0.000000
23.670002,1.874893,-389.475220,-0.003773,0.000654,0.016599,8.339941,0.424857,0.165990,-389.475220,0.017666,0.000000
24.050001,1.952347,-389.475220,-0.003742,0.000679,0.017249,8.684472,0.442408,0.172493,-389.475220,0.018298,0.000000
24.430000,1.955696,-389.519684,-0.003695,0.000706,0.017934,8.699370,0.443167,0.179343,-389.519684,0.018932,0.000000
24.810001,1.975060,-389.519684,-0.003682,0.000724,0.018394,8.785503,0.447555,0.183938,-389.519684,0.019565,0.000000
25.190001,1.923676,-389.564178,-0.003669,0.000731,0.018576,8.556936,0.435911,0.185763,-389.564178,0.020198,0.000000
25.570002,2.162369,-389.608643,-0.003639,0.000779,0.019790,9.618697,0.490000,0.197905,-389.608643,0.020831,0.000000
25.950001,2.188057,-389.608643,-0.003609,0.000807,0.020501,9.732964,0.495821,0.205013,-389.608643,0.021472,0.000000
26.330002,2.198112,-389.653137,-0.003570,0.000832,0.021143,9.777693,0.498099,0.211432,-389.653137,0.022106,0.000000
26.710001,2.173164,-389.742096,-0.003544,0.000854,0.021698,9.666718,0.492446,0.216980,-389.742096,0.022739,0.000000
27.090002,2.269608,-389.653137,-0.003527,0.000881,0.022375,10.095718,0.514300,0.223748,-389.653137,0.023372,0.000000
27.470001,2.301262,-389.653137,-0.003510,0.000900,0.022860,10.236525,0.521473,0.228600,-389.653137,0.024005,0.000000
27.850000,2.421913,-389.697601,-0.003488,0.000936,0.023762,10.773208,0.548813,0.237623,-389.697601,0.024638,0.000000
28.230001,2.453934,-389.742096,-0.003445,0.000960,0.024387,10.915643,0.556069,0.243868,-389.742096,0.025271,0.000000
28.610001,2.409622,-389.742096,-0.003441,0.000981,0.024916,10.718534,0.546028,0.249160,-389.742096,0.025905,0.000000
28.990002,2.548515,-389.831055,-0.003406,0.001008,0.025601,11.336362,0.577502,0.256010,-389.831055,0.026537,0.000000
29.370001,2.539581,-389.786560,-0.003393,0.001027,0.026095,11.296622,0.575477,0.260953,-389.786560,0.027170,0.000000
29.750002,2.575325,-389.786560,-0.003367,0.001048,0.026607,11.455618,0.583577,0.266071,-389.786560,0.027804,0.000000
30.130001,2.710129,-389.875549,-0.003333,0.001081,0.027448,12.055255,0.614124,0.274481,-389.875549,0.028437,0.000000
30.510002,2.687042,-389.964508,-0.003307,0.001106,0.028098,11.952560,0.608893,0.280983,-389.964508,0.029070,0.000000
30.890001,2.752579,-389.920013,-0.003281,0.001129,0.028688,12.244081,0.623743,0.286880,-389.920013,0.029703,0.000000
31.270002,2.793541,-389.875549,-0.003268,0.001152,0.029269,12.426291,0.633025,0.292693,-389.875549,0.030336,0.000000
31.650002,2.843063,-389.920013,-0.003247,0.001173,0.029807,12.646578,0.644247,0.298068,-389.920013,0.030969,0.000000
32.030003,3.038559,-389.920013,-0.003208,0.001212,0.030778,13.516186,0.688547,0.307780,-389.920013,0.031602,0.000000
32.410000,2.997597,-390.053467,-0.003178,0.001235,0.031359,13.333976,0.679265,0.313594,-390.053467,0.032235,0.000000
32.790001,3.047867,-389.964508,-0.003147,0.001258,0.031957,13.557589,0.690656,0.319574,-389.964508,0.032868,0.000000
33.170002,3.003555,-389.964508,-0.003139,0.001268,0.032218,13.360481,0.680615,0.322178,-389.964508,0.033501,0.000000
33.550003,3.271667,-389.964508,-0.003104,0.001308,0.033232,14.553103,0.741370,0.332321,-389.964508,0.034134,0.000000
33.930000,3.296242,-390.008972,-0.003074,0.001334,0.033883,14.662416,0.746939,0.338831,-390.008972,0.034767,0.000000
34.310001,3.317841,-390.097931,-0.003044,0.001358,0.034490,14.758492,0.751833,0.344902,-390.097931,0.035400,0.000000
34.690002,3.397896,-390.142426,-0.003022,0.001384,0.035158,15.114595,0.769974,0.351579,-390.142426,0.036034,0.000000
35.070004,3.410561,-390.097931,-0.003009,0.001404,0.035661,15.170931,0.772844,0.356605,-390.097931,0.036667,0.000000
35.450001,3.590790,-390.186890,-0.002971,0.001432,0.036380,15.972631,0.813685,0.363804,-390.186890,0.037299,0.000000
35.830002,3.642174,-390.097931,-0.002953,0.001459,0.037048,16.201199,0.825328,0.370481,-390.097931,0.037933,0.000000
36.210003,3.660049,-390.186890,-0.002923,0.001484,0.037690,16.280712,0.829379,0.376900,-390.186890,0.038566,0.000000
36.590000,3.774742,-390.231384,-0.002906,0.001510,0.038358,16.790892,0.855369,0.383576,-390.231384,0.039199,0.000000
36.970001,3.770645,-390.231384,-0.002871,0.001529,0.038826,16.772667,0.854440,0.388262,-390.231384,0.039841,0.000000
37.350002,3.879379,-390.186890,-0.002841,0.001552,0.039416,17.256340,0.879080,0.394159,-390.186890,0.040473,0.000000
37.730003,4.083435,-390.275879,-0.002828,0.001583,0.040214,18.164026,0.925320,0.402138,-390.275879,0.041107,0.000000
38.110001,4.084557,-390.364838,-0.002802,0.001608,0.040838,18.169016,0.925574,0.408383,-390.364838,0.041740,0.000000
38.490002,4.163498,-390.320343,-0.002764,0.001635,0.041523,18.520164,0.943462,0.415233,-390.320343,0.042373,0.000000
38.870003,4.256592,-390.320343,-0.002759,0.001656,0.042069,18.934265,0.964558,0.420691,-390.320343,0.043006,0.000000
39.250000,4.278557,-390.364838,-0.002734,0.001675,0.042547,19.031971,0.969535,0.425468,-390.364838,0.043639,0.000000
39.630001,4.562683,-390.364838,-0.002699,0.001710,0.043423,20.295828,1.033919,0.434226,-390.364838,0.044272,0.000000
40.010002,4.542198,-390.453796,-0.002682,0.001733,0.044021,20.204706,1.029277,0.440206,-390.453796,0.044906,0.000000
40.390003,4.535126,-390.498260,-0.002656,0.001755,0.044585,20.173246,1.027674,0.445845,-390.498260,0.045538,0.000000
40.770000,4.609596,-390.498260,-0.002626,0.001778,0.045157,20.504509,1.044549,0.451568,-390.498260,0.046171,0.000000
41.150002,4.759666,-390.453796,-0.002613,0.001802,0.045781,21.172054,1.078556,0.457813,-390.453796,0.046805,0.000000
41.530003,5.056076,-390.542755,-0.002583,0.001832,0.046535,22.490549,1.145723,0.465353,-390.542755,0.047438,0.000000
41.910004,4.952553,-390.542755,-0.002561,0.001852,0.047047,22.030056,1.122265,0.470470,-390.542755,0.048070,0.000000
42.290001,5.136879,-390.587219,-0.002531,0.001880,0.047749,22.849979,1.164033,0.477495,-390.587219,0.048704,0.000000
42.670002,5.347641,-390.542755,-0.002522,0.001910,0.048522,23.787495,1.211793,0.485216,-390.542755,0.049337,0.000000
43.050003,5.346153,-390.587219,-0.002479,0.001929,0.048998,23.780878,1.211456,0.489985,-390.587219,0.049970,0.000000
43.430000,5.455627,-390.542755,-0.002462,0.001953,0.049606,24.267843,1.236263,0.496056,-390.542755,0.050603,0.000000
43.810001,5.633621,-390.676178,-0.002436,0.001979,0.050265,25.059599,1.276597,0.502649,-390.676178,0.051236,0.000000
44.190002,5.679428,-390.765167,-0.002427,0.002003,0.050872,25.263357,1.286977,0.508720,-390.765167,0.051869,0.000000
44.570004,5.826141,-390.765167,-0.002393,0.002028,0.051522,25.915972,1.320222,0.515223,-390.765167,0.052502,0.000000
44.950001,5.963547,-390.720673,-0.002371,0.002051,0.052086,26.527182,1.351359,0.520862,-390.720673,0.053135,0.000000
45.330002,6.230164,-390.676178,-0.002337,0.002077,0.052762,27.713152,1.411775,0.527622,-390.676178,0.053768,0.000000
45.710003,6.292725,-390.765167,-0.002324,0.002103,0.053422,27.991438,1.425952,0.534215,-390.765167,0.054401,0.000000
46.090004,6.274849,-390.765167,-0.002281,0.002123,0.053916,27.911922,1.421901,0.539158,-390.765167,0.055035,0.000000
46.470001,6.589127,-390.898590,-0.002268,0.002149,0.054575,29.309898,1.493117,0.545752,-390.898590,0.055667,0.000000
46.850002,6.710899,-390.854126,-0.002255,0.002176,0.055260,29.851572,1.520712,0.552602,-390.854126,0.056300,0.000000
47.230003,6.920540,-390.809631,-0.002220,0.002202,0.055936,30.784100,1.568217,0.559362,-390.809631,0.056934,0.000000
47.610001,7.123116,-390.898590,-0.002190,0.002231,0.056665,31.685200,1.614121,0.566652,-390.898590,0.057567,0.000000
47.990002,7.108963,-390.943085,-0.002173,0.002251,0.057185,31.622248,1.610914,0.571852,-390.943085,0.058209,0.000000
48.370003,7.226257,-390.943085,-0.002156,0.002270,0.057662,32.143997,1.637493,0.576621,-390.943085,0.058841,0.000000
48.750004,7.544640,-390.898590,-0.002126,0.002299,0.058382,33.560234,1.709640,0.583820,-390.898590,0.059474,0.000000
49.130001,7.975098,-390.943085,-0.002095,0.002331,0.059215,35.475006,1.807183,0.592147,-390.943085,0.060108,0.000000
49.510002,8.060745,-390.943085,-0.002052,0.002356,0.059848,35.855984,1.826591,0.598475,-390.943085,0.060741,0.000000
49.890003,8.205223,-391.032043,-0.002044,0.002379,0.060429,36.498653,1.859330,0.604289,-391.032043,0.061374,0.000000
50.270004,8.336304,-391.076508,-0.002031,0.002401,0.060992,37.081730,1.889033,0.609921,-391.076508,0.062007,0.000000
50.650002,8.315819,-391.032043,-0.002013,0.002422,0.061513,36.990608,1.884392,0.615129,-391.032043,0.062640,0.000000
51.030003,8.896347,-391.076508,-0.001979,0.002449,0.062215,39.572929,2.015941,0.622153,-391.076508,0.063273,0.000000
51.410004,9.412834,-391.076508,-0.001966,0.002480,0.063004,41.870377,2.132979,0.630041,-391.076508,0.063906,0.000000
51.790001,9.449692,-391.121002,-0.001923,0.002503,0.063576,42.034328,2.141331,0.635764,-391.121002,0.064539,0.000000
52.170002,9.689133,-391.209961,-0.001910,0.002527,0.064183,43.099415,2.195589,0.641835,-391.209961,0.065172,0.000000
52.550003,9.710358,-391.165497,-0.001888,0.002546,0.064660,43.193829,2.200399,0.646604,-391.165497,0.065806,0.000000
52.930004,10.115494,-391.121002,-0.001863,0.002571,0.065294,44.995964,2.292204,0.652940,-391.121002,0.066439,0.000000
53.310001,10.959663,-391.121002,-0.001832,0.002608,0.066239,48.751019,2.483495,0.662387,-391.121002,0.067071,0.000000
53.690002,10.838272,-391.254456,-0.001798,0.002630,0.066803,48.211040,2.455987,0.668026,-391.254456,0.067705,0.000000
54.070004,10.946632,-391.209961,-0.001785,0.002651,0.067340,48.693054,2.480542,0.673401,-391.209961,0.068338,0.000000
54.450001,11.082924,-391.298920,-0.001781,0.002667,0.067739,49.299309,2.511426,0.677390,-391.298920,0.068971,0.000000
54.830002,12.049225,-391.254456,-0.001750,0.002703,0.068667,53.597630,2.730393,0.686671,-391.254456,0.069604,0.000000
55.210003,12.443573,-391.298920,-0.001720,0.002732,0.069387,55.351776,2.819754,0.693870,-391.298920,0.070237,0.000000
55.590004,12.588799,-391.343414,-0.001677,0.002754,0.069942,55.997772,2.852663,0.699418,-391.343414,0.070870,0.000000
55.970001,13.026337,-391.343414,-0.001681,0.002781,0.070627,57.944038,2.951810,0.706269,-391.343414,0.071503,0.000000
56.350002,13.239700,-391.298920,-0.001643,0.002802,0.071165,58.893127,3.000159,0.711651,-391.298920,0.072136,0.000000
56.730003,13.701073,-391.387878,-0.001643,0.002828,0.071824,60.945415,3.104707,0.718237,-391.387878,0.072769,0.000000
57.110004,14.292397,-391.387878,-0.001613,0.002855,0.072509,63.575756,3.238703,0.725087,-391.387878,0.073402,0.000000
57.490002,14.649879,-391.387878,-0.001574,0.002880,0.073151,65.165916,3.319710,0.731507,-391.387878,0.074036,0.000000
57.870003,15.238594,-391.521332,-0.001556,0.002906,0.073818,67.784653,3.453115,0.738183,-391.521332,0.074668,0.000000
58.250004,15.319031,-391.476837,-0.001548,0.002925,0.074295,68.142448,3.471342,0.742952,-391.476837,0.075301,0.000000
58.630001,15.792313,-391.521332,-0.001531,0.002946,0.074816,70.247711,3.578589,0.748160,-391.521332,0.075943,0.000000
59.010002,16.975716,-391.521332,-0.001496,0.002978,0.075649,75.511757,3.846752,0.756487,-391.521332,0.076576,0.000000
59.390003,17.305634,-391.521332,-0.001470,0.003003,0.076282,76.979301,3.921513,0.762815,-391.521332,0.077210,0.000000
59.770004,17.612846,-391.521332,-0.001444,0.003025,0.076845,78.345856,3.991128,0.768455,-391.521332,0.077842,0.000000
60.150002,18.276413,-391.610291,-0.001427,0.003054,0.077565,81.297546,4.141495,0.775646,-391.610291,0.078475,0.000000
60.530003,18.647667,-391.565826,-0.001410,0.003071,0.077998,82.948967,4.225622,0.779984,-391.565826,0.079109,0.000000
60.910004,19.882454,-391.654785,-0.001380,0.003101,0.078753,88.441574,4.505429,0.787531,-391.654785,0.079742,0.000000
61.290005,20.366913,-391.654785,-0.001362,0.003128,0.079456,90.596550,4.615209,0.794555,-391.654785,0.080375,0.000000
61.670002,20.822693,-391.743744,-0.001345,0.003150,0.080010,92.623962,4.718490,0.800104,-391.743744,0.081008,0.000000
62.050003,21.587173,-391.743744,-0.001324,0.003176,0.080670,96.024544,4.891723,0.806697,-391.743744,0.081641,0.000000
62.430004,21.955826,-391.699249,-0.001315,0.003197,0.081216,97.664391,4.975262,0.812163,-391.699249,0.082274,0.000000
62.810001,23.057678,-391.743744,-0.001285,0.003227,0.081962,102.565674,5.224945,0.819619,-391.743744,0.082907,0.000000
63.190002,23.766670,-391.788208,-0.001259,0.003248,0.082499,105.719429,5.385604,0.824994,-391.788208,0.083540,0.000000
63.570004,24.836494,-391.877167,-0.001246,0.003277,0.083228,110.478249,5.628030,0.832283,-391.877167,0.084173,0.000000
63.950005,25.946541,-391.877167,-0.001233,0.003307,0.084000,115.415977,5.879570,0.839997,-391.877167,0.084807,0.000000
64.330002,26.162148,-391.877167,-0.001203,0.003326,0.084477,116.375046,5.928428,0.844766,-391.877167,0.085439,0.000000
64.710007,26.808586,-391.832703,-0.001190,0.003345,0.084953,119.250549,6.074912,0.849535,-391.832703,0.086072,0.000000
65.090004,28.432495,-391.832703,-0.001173,0.003376,0.085760,126.474052,6.442895,0.857604,-391.832703,0.086706,0.000000
65.470001,29.091225,-391.877167,-0.001147,0.003400,0.086358,129.404236,6.592166,0.863584,-391.877167,0.087339,0.000000
65.850006,30.302551,-392.010620,-0.001134,0.003426,0.087026,134.792480,6.866656,0.870261,-392.010620,0.087972,0.000000
66.230003,30.625397,-391.966125,-0.001125,0.003444,0.087486,136.228561,6.939814,0.874863,-391.966125,0.088604,0.000000
66.610001,32.095154,-391.877167,-0.001104,0.003472,0.088197,142.766373,7.272866,0.881971,-391.877167,0.089238,0.000000
66.990005,33.758545,-392.010620,-0.001078,0.003501,0.088917,150.165512,7.649796,0.889170,-392.010620,0.089871,0.000000
67.370003,34.117882,-392.010620,-0.001069,0.003520,0.089420,151.763916,7.731222,0.894197,-392.010620,0.090504,0.000000
67.750000,35.242447,-392.099579,-0.001056,0.003546,0.090062,156.766235,7.986053,0.900616,-392.099579,0.091137,0.000000
68.130005,35.140785,-392.099579,-0.001048,0.003551,0.090200,156.314026,7.963016,0.902001,-392.099579,0.091770,0.000000
68.510002,37.874748,-392.099579,-0.001022,0.003593,0.091258,168.475296,8.582541,0.912584,-392.099579,0.092403,0.000000
68.890007,39.910133,-392.144073,-0.001013,0.003627,0.092117,177.529144,9.043766,0.921168,-392.144073,0.093037,0.000000
69.270004,40.610199,-392.144073,-0.000992,0.003649,0.092672,180.643188,9.202403,0.926724,-392.144073,0.093669,0.000000
69.650002,41.440216,-392.233032,-0.000979,0.003668,0.093175,184.335281,9.390488,0.931750,-392.233032,0.094311,0.000000
70.030006,43.116264,-392.144073,-0.000953,0.003695,0.093852,191.790726,9.770286,0.938518,-392.144073,0.094944,0.000000
70.410004,44.976265,-392.144073,-0.000953,0.003725,0.094623,200.064423,10.191767,0.946231,-392.144073,0.095577,0.000000
70.790001,46.345848,-392.188538,-0.000931,0.003752,0.095291,206.156631,10.502119,0.952908,-392.188538,0.096211,0.000000
71.170006,47.529251,-392.188538,-0.000927,0.003775,0.095890,211.420670,10.770283,0.958896,-392.188538,0.096843,0.000000
71.550003,48.959900,-392.233032,-0.000918,0.003797,0.096454,217.784515,11.094472,0.964535,-392.233032,0.097476,0.000000
71.930000,49.804070,-392.321991,-0.000905,0.003814,0.096886,221.539566,11.285763,0.968865,-392.321991,0.098110,0.000000
72.310005,51.923615,-392.233032,-0.000880,0.003847,0.097702,230.967773,11.766059,0.977018,-392.233032,0.098743,0.000000
72.690002,52.388710,-392.277496,-0.000862,0.003858,0.097988,233.036621,11.871451,0.979879,-392.277496,0.099375,0.000000
73.070000,55.375877,-392.321991,-0.000862,0.003898,0.099011,246.324203,12.548353,0.990113,-392.321991,0.100009,0.000000
73.450005,56.867233,-392.366455,-0.000836,0.003922,0.099628,252.958084,12.886299,0.996275,-392.366455,0.100642,0.000000
73.830002,58.098297,-392.410950,-0.000832,0.003941,0.100095,258.434143,13.165262,1.000953,-392.410950,0.101275,0.000000
74.210007,59.734871,-392.366455,-0.000828,0.003963,0.100668,265.713989,13.536116,1.006676,-392.366455,0.101908,0.000000
74.590004,62.495270,-392.410950,-0.000815,0.004000,0.101605,277.992859,14.161631,1.016047,-392.410950,0.102541,0.000000
74.970001,64.307983,-392.455444,-0.000793,0.004025,0.102228,286.056183,14.572397,1.022285,-392.455444,0.103174,0.000000
75.350006,65.390839,-392.499908,-0.000793,0.004044,0.102706,290.872986,14.817776,1.027062,-392.499908,0.103808,0.000000
75.730003,65.815338,-392.544403,-0.000789,0.004044,0.102706,292.761230,14.913969,1.027062,-392.544403,0.018034,0.000000
76.110001,65.159592,-392.499908,-0.000776,0.004056,0.103010,289.844330,14.765374,1.030097,-392.499908,294.500458,0.000000
76.490005,65.302963,-392.499908,-0.000759,0.004058,0.103070,290.482086,14.797863,1.030703,-392.499908,294.500458,0.000000
76.870003,65.153641,-392.544403,-0.000767,0.004061,0.103157,289.817871,14.764026,1.031566,-392.544403,294.500458,0.000000
77.250000,65.199432,-392.588867,-0.000755,0.004064,0.103235,290.021545,14.774403,1.032345,-392.588867,294.500458,0.000000
77.630005,65.011383,-392.677826,-0.000759,0.004065,0.103261,289.185089,14.731790,1.032610,-392.677826,294.500458,0.000000
78.010002,64.760040,-392.633362,-0.000763,0.004065,0.103261,288.067047,14.674835,1.032610,-392.633362,294.500458,0.000000
78.390007,65.608673,-392.633362,-0.000759,0.004076,0.103521,291.841949,14.867138,1.035214,-392.633362,294.500458,0.000000
78.770004,65.406845,-392.633362,-0.000746,0.004076,0.103521,290.944183,14.821403,1.035214,-392.633362,294.500458,0.000000
79.150002,65.210236,-392.677826,-0.000746,0.004076,0.103521,290.069611,14.776851,1.035214,-392.677826,294.500458,0.000000
79.530006,65.031876,-392.722321,-0.000750,0.004076,0.103521,289.276245,14.736434,1.035214,-392.722321,294.500458,0.000000
79.910004,64.824463,-392.722321,-0.000746,0.004076,0.103521,288.353607,14.689433,1.035214,-392.722321,294.500458,0.000000
80.290001,64.688538,-392.722321,-0.000763,0.004076,0.103521,287.748993,14.658632,1.035214,-392.722321,294.500458,0.000000
80.670006,64.518372,-392.766785,-0.000733,0.004076,0.103521,286.992065,14.620072,1.035214,-392.766785,294.500458,0.000000
81.050003,64.402557,-392.766785,-0.000737,0.004076,0.103530,286.476868,14.593828,1.035298,-392.766785,294.500458,0.000000
81.430000,66.687439,-392.900238,-0.000733,0.004026,0.102263,296.640533,15.111589,1.022633,-392.900238,294.500458,0.000000
81.810005,66.521729,-392.900238,-0.000733,0.004026,0.102263,295.903412,15.074039,1.022633,-392.900238,294.500458,0.000000
82.190002,66.366455,-392.855774,-0.000733,0.004026,0.102272,295.212738,15.038854,1.022724,-392.855774,294.500458,0.000000
82.570007,66.241333,-392.900238,-0.000733,0.004026,0.102272,294.656158,15.010501,1.022724,-392.900238,294.500458,0.000000
82.950005,66.109512,-392.944733,-0.000724,0.004026,0.102272,294.069794,14.980630,1.022724,-392.944733,294.500458,0.000000
83.330002,65.983658,-392.944733,-0.000737,0.004026,0.102272,293.509979,14.952111,1.022724,-392.944733,294.500458,0.000000
83.710007,65.874557,-392.944733,-0.000733,0.004027,0.102281,293.024658,14.927388,1.022807,-392.944733,294.500458,0.000000
84.090004,65.762100,-392.944733,-0.000720,0.004027,0.102281,292.524445,14.901905,1.022807,-392.944733,294.500458,0.000000
84.470001,65.637726,-392.989197,-0.000720,0.004051,0.102897,291.971191,14.873721,1.028969,-392.989197,294.500458,0.000000
84.850006,65.567337,-392.900238,-0.000711,0.004054,0.102966,291.658081,14.857771,1.029658,-392.900238,294.500458,0.000000
85.230003,65.513351,-393.078156,-0.000720,0.004059,0.103105,291.417938,14.845537,1.031051,-393.078156,294.500458,0.000000
85.610001,65.427338,-393.033691,-0.000720,0.004060,0.103113,291.035339,14.826047,1.031134,-393.033691,294.500458,0.000000
85.990005,65.351364,-393.033691,-0.000720,0.004065,0.103261,290.697388,14.808831,1.032610,-393.033691,294.500458,0.000000
86.370003,65.288803,-393.122650,-0.000724,0.004065,0.103261,290.419098,14.794654,1.032610,-393.122650,294.500458,0.000000
86.750008,65.227371,-393.078156,-0.000716,0.004065,0.103261,290.145844,14.780734,1.032610,-393.078156,294.500458,0.000000
87.130005,65.228851,-393.122650,-0.000720,0.004076,0.103538,290.152435,14.781069,1.035381,-393.122650,294.500458,0.000000
87.510002,65.150665,-393.167114,-0.000729,0.004082,0.103677,289.804626,14.763351,1.036774,-393.167114,294.500458,0.000000
87.890007,65.183792,-393.211609,-0.000729,0.004084,0.103746,289.951996,14.770859,1.037462,-393.211609,294.500458,0.000000
88.270004,65.164429,-393.167114,-0.000729,0.004087,0.103808,289.865845,14.766471,1.038076,-393.167114,294.500458,0.000000
88.650002,65.226624,-393.167114,-0.000716,0.004090,0.103886,290.142517,14.780564,1.038855,-393.167114,294.500458,0.000000
89.030006,65.230347,-393.211609,-0.000729,0.004090,0.103886,290.159088,14.781407,1.038855,-393.211609,294.500458,0.000000
89.410004,65.193481,-393.300568,-0.000720,0.004090,0.103886,289.995087,14.773054,1.038855,-393.300568,294.500458,0.000000
89.790001,65.228851,-393.389526,-0.000724,0.004092,0.103937,290.152435,14.781069,1.039370,-393.389526,294.500458,0.000000
90.170006,65.228119,-393.256104,-0.000724,0.004092,0.103937,290.149170,14.780903,1.039370,-393.256104,294.500458,0.000000
90.550003,65.208374,-393.300568,-0.000720,0.004092,0.103937,290.061340,14.776429,1.039370,-393.300568,294.500458,0.000000
90.930008,65.164062,-393.345062,-0.000733,0.004092,0.103937,289.864227,14.766387,1.039370,-393.345062,294.500458,0.000000
91.310005,65.120117,-393.345062,-0.000716,0.004092,0.103937,289.668762,14.756430,1.039370,-393.345062,294.500458,0.000000
91.690002,65.546494,-393.434021,-0.000729,0.004099,0.104119,291.565369,14.853048,1.041194,-393.434021,294.500458,0.000000
92.070007,65.590805,-393.389526,-0.000733,0.004099,0.104119,291.762482,14.863089,1.041194,-393.389526,294.500458,0.000000
92.450005,65.589310,-393.434021,-0.000720,0.004099,0.104119,291.755829,14.862750,1.041194,-393.434021,294.500458,0.000000
92.830002,65.578140,-393.434021,-0.000716,0.004099,0.104119,291.706146,14.860219,1.041194,-393.434021,294.500458,0.000000
93.210007,65.553558,-393.478485,-0.000716,0.004099,0.104119,291.596802,14.854649,1.041194,-393.478485,294.500458,0.000000
93.590004,65.524887,-393.522980,-0.000724,0.004099,0.104119,291.469269,14.848151,1.041194,-393.522980,294.500458,0.000000
93.970001,65.500320,-393.522980,-0.000711,0.004099,0.104119,291.359985,14.842586,1.041194,-393.522980,294.500458,0.000000
94.350006,65.451904,-393.522980,-0.000729,0.004099,0.104119,291.144623,14.831614,1.041194,-393.522980,294.500458,0.000000
94.730003,65.394928,-393.567444,-0.000720,0.004099,0.104119,290.891174,14.818703,1.041194,-393.567444,294.500458,0.000000
95.110008,65.363281,-393.611938,-0.000720,0.004099,0.104119,290.750397,14.811532,1.041194,-393.611938,294.500458,0.000000
95.490005,65.332001,-393.611938,-0.000729,0.004099,0.104119,290.611267,14.804443,1.041194,-393.611938,294.500458,0.000000
95.870003,65.320465,-393.611938,-0.000711,0.004099,0.104119,290.559937,14.801828,1.041194,-393.611938,294.500458,0.000000
96.250008,65.282852,-393.656403,-0.000716,0.004099,0.104119,290.392639,14.793305,1.041194,-393.656403,294.500458,0.000000
96.630005,65.285461,-393.656403,-0.000720,0.004100,0.104145,290.404236,14.793897,1.041452,-393.656403,294.500458,0.000000
97.010002,65.263855,-393.656403,-0.000711,0.004100,0.104145,290.308136,14.789001,1.041452,-393.656403,294.500458,0.000000
97.390007,65.260880,-393.700897,-0.000720,0.004100,0.104145,290.294891,14.788326,1.041452,-393.700897,294.500458,0.000000
97.770004,65.236679,-393.834351,-0.000711,0.004100,0.104145,290.187256,14.782843,1.041452,-393.834351,294.500458,0.000000
98.150002,65.213959,-393.745392,-0.000716,0.004101,0.104172,290.086182,14.777695,1.041717,-393.745392,294.500458,0.000000
98.530006,65.208755,-393.745392,-0.000724,0.004101,0.104172,290.063019,14.776515,1.041717,-393.745392,294.500458,0.000000
98.910004,65.182678,-393.789856,-0.000711,0.004101,0.104172,289.947021,14.770606,1.041717,-393.789856,294.500458,0.000000
99.290001,65.220657,-393.789856,-0.000716,0.004105,0.104258,290.115967,14.779213,1.042580,-393.789856,294.500458,0.000000
99.670006,65.336838,-393.878815,-0.000720,0.004105,0.104258,290.632782,14.805539,1.042580,-393.878815,294.500458,0.000000
100.050003,65.340561,-393.834351,-0.000711,0.004105,0.104258,290.649323,14.806382,1.042580,-393.834351,294.500458,0.000000
100.430008,65.349503,-393.878815,-0.000707,0.004105,0.104258,290.689117,14.808409,1.042580,-393.878815,294.500458,0.000000
100.810005,65.345413,-393.878815,-0.000716,0.004105,0.104258,290.670929,14.807483,1.042580,-393.878815,294.500458,0.000000
101.190002,65.326050,-393.923309,-0.000716,0.004105,0.104258,290.584778,14.803094,1.042580,-393.923309,294.500458,0.000000
101.570007,65.310410,-394.012268,-0.000720,0.004105,0.104258,290.515198,14.799551,1.042580,-394.012268,294.500458,0.000000
101.950005,65.302216,-393.967773,-0.000720,0.004105,0.104258,290.478760,14.797693,1.042580,-393.967773,294.500458,0.000000
102.330002,65.302582,-394.012268,-0.000707,0.004105,0.104258,290.480377,14.797776,1.042580,-394.012268,294.500458,0.000000
102.710007,65.275024,-394.012268,-0.000707,0.004105,0.104258,290.357819,14.791532,1.042580,-394.012268,294.500458,0.000000
103.090004,65.244492,-394.012268,-0.000716,0.004105,0.104258,290.221985,14.784614,1.042580,-394.012268,294.500458,0.000000
103.470001,65.241516,-394.101227,-0.000716,0.004105,0.104258,290.208771,14.783938,1.042580,-394.101227,294.500458,0.000000
103.850006,65.211731,-394.101227,-0.000711,0.004105,0.104258,290.076263,14.777190,1.042580,-394.101227,294.500458,0.000000
104.230003,65.185654,-394.056732,-0.000724,0.004105,0.104258,289.960266,14.771280,1.042580,-394.056732,294.500458,0.000000
104.610008,65.169647,-394.145721,-0.000724,0.004105,0.104258,289.889069,14.767653,1.042580,-394.145721,294.500458,0.000000
104.990005,65.555801,-394.190186,-0.000716,0.004112,0.104449,291.606781,14.855157,1.044487,-394.190186,294.500458,0.000000
105.370003,65.619095,-394.190186,-0.000703,0.004110,0.104406,291.888306,14.869499,1.044056,-394.190186,294.500458,0.000000
105.750008,65.615753,-394.234680,-0.000716,0.004110,0.104406,291.873444,14.868742,1.044056,-394.234680,294.500458,0.000000
106.130005,65.594147,-394.190186,-0.000716,0.004110,0.104406,291.777344,14.863846,1.044056,-394.190186,294.500458,0.000000
106.510002,65.593781,-394.190186,-0.000707,0.004110,0.104406,291.775696,14.863764,1.044056,-394.190186,294.500458,0.000000
106.890007,65.582611,-394.234680,-0.000707,0.004110,0.104406,291.726013,14.861233,1.044056,-394.234680,294.500458,0.000000
107.270004,65.562881,-394.323639,-0.000698,0.004110,0.104406,291.638275,14.856761,1.044056,-394.323639,294.500458,0.000000
107.650002,65.568085,-394.368103,-0.000716,0.004110,0.104406,291.661407,14.857941,1.044056,-394.368103,294.500458,0.000000
108.030006,65.562500,-394.323639,-0.000716,0.004110,0.104406,291.636566,14.856675,1.044056,-394.323639,294.500458,0.000000
108.410004,65.553558,-394.368103,-0.000716,0.004110,0.104406,291.596802,14.854649,1.044056,-394.368103,294.500458,0.000000
108.790009,65.541275,-394.323639,-0.000707,0.004110,0.104406,291.542145,14.851865,1.044056,-394.323639,294.500458,0.000000
109.170006,65.504791,-394.412598,-0.000711,0.004110,0.104406,291.379852,14.843598,1.044056,-394.412598,294.500458,0.000000
109.550003,65.498077,-394.501556,-0.000711,0.004110,0.104406,291.350006,14.842077,1.044056,-394.501556,294.500458,0.000000
109.930008,65.475372,-394.457062,-0.000707,0.004110,0.104406,291.248993,14.836931,1.044056,-394.457062,294.500458,0.000000
110.310005,65.457123,-394.412598,-0.000707,0.004110,0.104406,291.167816,14.832796,1.044056,-394.412598,294.500458,0.000000
110.690002,65.440735,-394.501556,-0.000716,0.004110,0.104406,291.094940,14.829082,1.044056,-394.501556,294.500458,0.000000
111.070007,65.437012,-394.501556,-0.000703,0.004110,0.104406,291.078369,14.828238,1.044056,-394.501556,294.500458,0.000000
111.450005,65.399033,-394.501556,-0.000703,0.004110,0.104406,290.909424,14.819633,1.044056,-394.501556,294.500458,0.000000
111.830002,65.370361,-394.590515,-0.000703,0.004110,0.104406,290.781891,14.813136,1.044056,-394.590515,294.500458,0.000000
112.210007,65.344666,-394.546051,-0.000707,0.004110,0.104406,290.667603,14.807313,1.044056,-394.546051,294.500458,0.000000
112.590004,65.318604,-394.546051,-0.000711,0.004110,0.104406,290.551666,14.801407,1.044056,-394.546051,294.500458,0.000000
112.970009,65.320084,-394.635010,-0.000707,0.004110,0.104406,290.558258,14.801743,1.044056,-394.635010,294.500458,0.000000
113.350006,65.308167,-394.679474,-0.000694,0.004110,0.104406,290.505219,14.799042,1.044056,-394.679474,294.500458,0.000000
113.730003,65.304077,-394.679474,-0.000720,0.004110,0.104406,290.487030,14.798116,1.044056,-394.679474,294.500458,0.000000
114.110008,65.276520,-394.679474,-0.000711,0.004110,0.104406,290.364471,14.791870,1.044056,-394.679474,294.500458,0.000000
114.490005,65.263107,-394.635010,-0.000716,0.004110,0.104406,290.304810,14.788831,1.044056,-394.635010,294.500458,0.000000
114.870003,65.245605,-394.768433,-0.000694,0.004110,0.104406,290.226959,14.784865,1.044056,-394.768433,294.500458,0.000000
115.250008,65.233322,-394.768433,-0.000716,0.004110,0.104406,290.172302,14.782083,1.044056,-394.768433,294.500458,0.000000
115.630005,65.219177,-394.768433,-0.000716,0.004110,0.104406,290.109375,14.778876,1.044056,-394.768433,294.500458,0.000000
116.010002,65.196091,-394.812927,-0.000707,0.004110,0.104406,290.006683,14.773645,1.044056,-394.812927,294.500458,0.000000
116.390007,65.184174,-394.768433,-0.000711,0.004110,0.104406,289.953674,14.770945,1.044056,-394.768433,294.500458,0.000000
116.770004,65.175980,-394.768433,-0.000703,0.004111,0.104423,289.917236,14.769088,1.044230,-394.768433,294.500458,0.000000
117.150009,65.170029,-394.812927,-0.000703,0.004111,0.104423,289.890778,14.767740,1.044230,-394.812927,294.500458,0.000000
117.530006,65.145447,-394.857391,-0.000720,0.004111,0.104423,289.781433,14.762170,1.044230,-394.857391,294.500458,0.000000
117.910004,65.122726,-394.901886,-0.000707,0.004111,0.104423,289.680359,14.757020,1.044230,-394.901886,294.500458,0.000000
118.290009,65.107834,-394.857391,-0.000711,0.004111,0.104423,289.614105,14.753646,1.044230,-394.857391,294.500458,0.000000
118.670006,65.091080,-394.857391,-0.000711,0.004111,0.104423,289.539581,14.749849,1.044230,-394.857391,294.500458,0.000000
119.050003,65.072830,-394.990845,-0.000698,0.004111,0.104423,289.458405,14.745714,1.044230,-394.990845,294.500458,0.000000
119.430008,65.056076,-394.990845,-0.000716,0.004111,0.104423,289.383881,14.741918,1.044230,-394.990845,294.500458,0.000000
119.810005,65.054581,-395.035339,-0.000707,0.004111,0.104423,289.377228,14.741579,1.044230,-395.035339,294.500458,0.000000
120.190002,65.041183,-394.990845,-0.000711,0.004111,0.104423,289.317627,14.738543,1.044230,-394.990845,294.500458,0.000000
120.570007,65.030746,-395.035339,-0.000707,0.004111,0.104423,289.271210,14.736178,1.044230,-395.035339,294.500458,0.000000
120.950005,65.024429,-395.035339,-0.000711,0.004111,0.104423,289.243103,14.734746,1.044230,-395.035339,294.500458,0.000000
121.330009,65.018845,-395.035339,-0.000711,0.004111,0.104423,289.218262,14.733480,1.044230,-395.035339,294.500458,0.000000
121.710007,65.001709,-395.079803,-0.000711,0.004111,0.104423,289.142029,14.729598,1.044230,-395.079803,294.500458,0.000000
122.090004,64.987183,-395.168762,-0.000707,0.004111,0.104423,289.077423,14.726306,1.044230,-395.168762,294.500458,0.000000
122.470009,64.975647,-395.079803,-0.000716,0.004111,0.104423,289.026123,14.723693,1.044230,-395.079803,294.500458,0.000000
122.850006,64.948837,-395.124298,-0.000703,0.004111,0.104423,288.906860,14.717617,1.044230,-395.124298,294.500458,0.000000
123.230003,64.943985,-395.213257,-0.000698,0.004111,0.104423,288.885284,14.716517,1.044230,-395.213257,294.500458,0.000000
123.610008,64.927231,-395.213257,-0.000707,0.004111,0.104423,288.810760,14.712721,1.044230,-395.213257,294.500458,0.000000
123.990005,64.907501,-395.213257,-0.000711,0.004111,0.104423,288.722992,14.708250,1.044230,-395.213257,294.500458,0.000000
124.370003,64.887756,-395.302216,-0.000716,0.004111,0.104423,288.635162,14.703775,1.044230,-395.302216,294.500458,0.000000
124.750008,64.889999,-395.213257,-0.000707,0.004111,0.104423,288.645142,14.704284,1.044230,-395.213257,294.500458,0.000000
125.130005,64.865417,-395.213257,-0.000711,0.004111,0.104423,288.535797,14.698713,1.044230,-395.213257,294.500458,0.000000
125.510010,64.851639,-395.257721,-0.000698,0.004111,0.104423,288.474487,14.695591,1.044230,-395.257721,294.500458,0.000000
125.890007,64.831528,-395.346680,-0.000703,0.004111,0.104423,288.385040,14.691034,1.044230,-395.346680,294.500458,0.000000
126.270004,64.825211,-395.257721,-0.000724,0.004111,0.104423,288.356934,14.689603,1.044230,-395.257721,294.500458,0.000000
126.650009,64.824463,-395.302216,-0.000716,0.004111,0.104423,288.353607,14.689433,1.044230,-395.302216,294.500458,0.000000
127.030006,64.807327,-395.391174,-0.000707,0.004111,0.104423,288.277374,14.685551,1.044230,-395.391174,294.500458,0.000000
127.410004,64.792435,-395.391174,-0.000703,0.004111,0.104423,288.211151,14.682175,1.044230,-395.391174,294.500458,0.000000
127.790009,64.787964,-395.435669,-0.000694,0.004111,0.104423,288.191254,14.681162,1.044230,-395.435669,294.500458,0.000000
128.170013,64.772324,-395.435669,-0.000707,0.004111,0.104423,288.121674,14.677619,1.044230,-395.435669,294.500458,0.000000
128.550003,64.757431,-395.435669,-0.000711,0.004111,0.104423,288.055450,14.674243,1.044230,-395.435669,294.500458,0.000000
128.930008,64.762650,-395.435669,-0.000703,0.004111,0.104423,288.078644,14.675426,1.044230,-395.435669,294.500458,0.000000
129.310013,64.736206,-395.480133,-0.000694,0.004111,0.104423,287.961029,14.669434,1.044230,-395.480133,294.500458,0.000000
129.690002,64.716095,-395.613586,-0.000703,0.004111,0.104431,287.871582,14.664876,1.044313,-395.613586,294.500458,0.000000
130.070007,64.688171,-395.569092,-0.000707,0.004111,0.104431,287.747345,14.658549,1.044313,-395.569092,294.500458,0.000000
130.450012,64.683701,-395.569092,-0.000724,0.004111,0.104431,287.727478,14.657537,1.044313,-395.569092,294.500458,0.000000
130.830002,64.675140,-395.569092,-0.000698,0.004111,0.104431,287.689392,14.655596,1.044313,-395.569092,294.500458,0.000000
131.210007,66.491943,-395.658051,-0.000694,0.004093,0.103972,295.770935,15.067289,1.039718,-395.658051,294.500458,0.000000
131.590012,66.490829,-395.702545,-0.000686,0.004093,0.103972,295.765991,15.067038,1.039718,-395.702545,294.500458,0.000000
131.970001,66.456192,-395.658051,-0.000707,0.004093,0.103972,295.611908,15.059188,1.039718,-395.658051,294.500458,0.000000
132.350006,66.463638,-395.747009,-0.000698,0.004093,0.103972,295.645020,15.060876,1.039718,-395.747009,294.500458,0.000000
132.730011,66.410019,-395.658051,-0.000703,0.004093,0.103972,295.406525,15.048725,1.039718,-395.658051,294.500458,0.000000
133.110001,66.438690,-395.702545,-0.000690,0.004093,0.103972,295.534058,15.055223,1.039718,-395.702545,294.500458,0.000000
133.490005,66.423431,-395.702545,-0.000690,0.004093,0.103972,295.466187,15.051764,1.039718,-395.702545,294.500458,0.000000
133.870010,66.405548,-395.835999,-0.000694,0.004093,0.103972,295.386627,15.047712,1.039718,-395.835999,294.500458,0.000000
134.250000,66.389908,-395.880463,-0.000694,0.004093,0.103972,295.317047,15.044168,1.039718,-395.880463,294.500458,0.000000
134.630005,66.366821,-395.791504,-0.000690,0.004093,0.103972,295.214355,15.038937,1.039718,-395.791504,294.500458,0.000000
135.010010,66.356033,-395.791504,-0.000690,0.004093,0.103972,295.166382,15.036491,1.039718,-395.791504,294.500458,0.000000
135.389999,66.331085,-395.880463,-0.000698,0.004093,0.103972,295.055389,15.030839,1.039718,-395.880463,294.500458,0.000000
135.770004,66.325500,-395.924957,-0.000690,0.004093,0.103972,295.030548,15.029573,1.039718,-395.924957,294.500458,0.000000
136.150009,66.312088,-395.924957,-0.000686,0.004093,0.103972,294.970886,15.026534,1.039718,-395.924957,1681.640747,0.000000
136.530014,66.310226,-395.835999,-0.000690,0.004092,0.103937,294.962616,15.026112,1.039370,-395.835999,0.103530,0.000000
136.910004,66.290863,-395.880463,-0.000694,0.004074,0.103478,294.876495,15.021724,1.034775,-395.880463,0.102897,0.000000
137.290009,66.261078,-395.924957,-0.000686,0.004050,0.102870,294.743988,15.014976,1.028704,-395.924957,0.102263,0.000000
137.670013,66.252502,-395.969421,-0.000694,0.004027,0.102290,294.705841,15.013032,1.022898,-395.969421,0.101630,0.000000
138.050003,66.186218,-396.058380,-0.000703,0.003998,0.101553,294.411011,14.998012,1.015525,-396.058380,0.100998,0.000000
138.430008,66.168350,-396.058380,-0.000694,0.003973,0.100911,294.331512,14.993962,1.009106,-396.058380,0.100364,0.000000
138.810013,66.110260,-396.013916,-0.000681,0.003948,0.100269,294.073120,14.980799,1.002687,-396.013916,0.099731,0.000000
139.190002,66.012329,-396.058380,-0.000686,0.003926,0.099714,293.637512,14.958608,0.997138,-396.058380,0.099098,0.000000
139.570007,65.657822,-396.102875,-0.000694,0.003907,0.099237,292.060577,14.878275,0.992369,-396.102875,0.098465,0.000000
139.950012,64.604385,-396.102875,-0.000677,0.003876,0.098456,287.374664,14.639563,0.984565,-396.102875,0.097832,0.000000
140.330002,63.677551,-396.147339,-0.000677,0.003854,0.097884,283.251892,14.429540,0.978842,-396.147339,0.097199,0.000000
140.710007,62.495644,-396.102875,-0.000673,0.003829,0.097251,277.994507,14.161716,0.972514,-396.102875,0.096566,0.000000
141.090012,61.226967,-396.147339,-0.000664,0.003812,0.096818,272.351166,13.874229,0.968176,-396.147339,0.095933,0.000000
141.470001,59.628372,-396.191833,-0.000664,0.003786,0.096158,265.240234,13.511982,0.961583,-396.191833,0.095300,0.000000
141.850006,57.709915,-396.236298,-0.000664,0.003764,0.095612,256.706512,13.077253,0.956117,-396.236298,0.094667,0.000000
142.230011,55.495415,-396.236298,-0.000655,0.003737,0.094927,246.855927,12.575440,0.949267,-396.236298,0.094033,0.000000
142.610001,53.379593,-396.191833,-0.000673,0.003716,0.094389,237.444290,12.095988,0.943892,-396.191833,0.093401,0.000000
142.990005,50.711914,-396.236298,-0.000655,0.003691,0.093747,225.577866,11.491484,0.937473,-396.236298,0.092768,0.000000
143.370010,48.420334,-396.280792,-0.000651,0.003670,0.093227,215.384399,10.972205,0.932273,-396.280792,0.092134,0.000000
143.750000,45.246231,-396.369751,-0.000660,0.003639,0.092438,201.265289,10.252942,0.924377,-396.369751,0.091501,0.000000
144.130005,42.858582,-396.280792,-0.000664,0.003616,0.091848,190.644485,9.711893,0.918480,-396.280792,0.090869,0.000000
144.510010,40.168190,-396.369751,-0.000668,0.003592,0.091241,178.677032,9.102242,0.912409,-396.369751,0.090235,0.000000
144.889999,37.632332,-396.369751,-0.000647,0.003566,0.090582,167.396973,8.527608,0.905824,-396.369751,0.089602,0.000000
145.270004,35.100945,-396.369751,-0.000664,0.003545,0.090053,156.136795,7.953988,0.900532,-396.369751,0.088969,0.000000
145.650009,32.554291,-396.458710,-0.000677,0.003523,0.089489,144.808716,7.376908,0.894893,-396.458710,0.088336,0.000000
146.030014,29.760750,-396.458710,-0.000673,0.003494,0.088752,132.382431,6.743882,0.887520,-396.458710,0.087695,0.000000
146.410004,26.454826,-396.458710,-0.000668,0.003467,0.088059,117.676949,5.994750,0.880586,-396.458710,0.087061,0.000000
146.790009,23.506012,-396.503204,-0.000660,0.003440,0.087364,104.559967,5.326539,0.873645,-396.503204,0.086428,0.000000
147.170013,20.992867,-396.503204,-0.000660,0.003417,0.086784,93.380936,4.757051,0.867839,-396.503204,0.085795,0.000000
147.550003,19.107178,-396.592163,-0.000668,0.003403,0.086428,84.992973,4.329748,0.864281,-396.592163,0.085162,0.000000
147.930008,15.997124,-396.547668,-0.000668,0.003371,0.085621,71.158760,3.625000,0.856211,-396.547668,0.084529,0.000000
148.310013,12.338936,-396.547668,-0.000677,0.003341,0.084850,54.886330,2.796043,0.848498,-396.547668,0.083896,0.000000
148.690002,9.793770,-396.592163,-0.000677,0.003318,0.084268,43.564865,2.219300,0.842684,-396.592163,0.083262,0.000000
149.070007,8.952576,-396.636627,-0.000664,0.003312,0.084130,39.823044,2.028683,0.841299,-396.636627,0.082630,0.000000
149.450012,4.904892,-396.636627,-0.000668,0.003274,0.083159,21.818048,1.111465,0.831587,-396.636627,0.081997,0.000000
149.830002,2.550751,-396.681122,-0.000681,0.003252,0.082612,11.346306,0.578008,0.826121,-396.681122,0.081363,0.000000
150.210007,-0.493767,-396.725616,-0.000673,0.003221,0.081814,-2.196384,-0.111889,0.818143,-396.725616,0.080730,0.000000
150.590012,-1.124565,-396.681122,-0.000681,0.003197,0.081199,-5.002316,-0.254830,0.811989,-396.681122,0.080097,0.000000
150.970001,-0.017502,-396.725616,-0.000724,0.003176,0.080670,-0.077852,-0.003966,0.806697,-396.725616,0.079464,0.000000
151.350006,-0.065910,-396.725616,-0.000772,0.003145,0.079889,-0.293184,-0.014935,0.798893,-396.725616,0.078831,0.000000
151.730011,-0.035751,-396.814575,-0.000789,0.003121,0.079282,-0.159030,-0.008101,0.792822,-396.814575,0.078198,0.000000
152.110001,-0.061440,-396.770081,-0.000824,0.003094,0.078597,-0.273297,-0.013922,0.785971,-396.770081,0.077565,0.000000
152.490005,-0.030533,-396.770081,-0.000858,0.003065,0.077842,-0.135817,-0.006919,0.778424,-396.770081,0.076932,0.000000
152.870010,-0.016388,-396.814575,-0.000884,0.003050,0.077461,-0.072897,-0.003714,0.774609,-396.814575,0.076299,0.000000
153.250000,-0.034630,-396.859039,-0.000901,0.003024,0.076819,-0.154041,-0.007847,0.768190,-396.859039,0.075666,0.000000
153.630005,-0.013779,-396.992493,-0.000936,0.002998,0.076143,-0.061291,-0.003122,0.761430,-396.992493,0.075033,0.000000
154.010010,-0.053253,-396.903534,-0.000970,0.002968,0.075397,-0.236882,-0.012067,0.753966,-396.903534,0.074400,0.000000
154.390015,-0.031654,-396.859039,-0.000987,0.002940,0.074677,-0.140806,-0.007173,0.746775,-396.859039,0.073767,0.000000
154.770004,-0.015266,-396.947998,-0.001000,0.002928,0.074382,-0.067908,-0.003459,0.743823,-396.947998,0.073133,0.000000
155.150009,-0.051758,-396.947998,-0.001026,0.002897,0.073576,-0.230230,-0.011728,0.735761,-396.947998,0.072500,0.000000
155.500000,0.005959,-396.947998,-0.001030,0.002885,0.073273,0.026505,0.001350,0.732725,-396.947998,0.073168,0.000000