File: Data/compression 21/AutoNoHeating-10-21-reverse-1-3_09132024_163251.csv
Time (sec),S:Load (lbs),S:HL1 (DIM),S:LVDT (in),S:Position (in),Ch:Position (mm),Ch:Load (N),Ch:Stress (MPa),Ch:Strain (mm/mm),Ch:HL1 (DIM),Set Point (),Cycles ()
0.110000,-0.022346,-232.501938,-0.010473,-0.005298,-0.134567,-0.099402,-0.005064,-1.345674,-232.501938,-0.134178,0.000000
0.510000,-0.001862,-232.679855,-0.010490,-0.005232,-0.132903,-0.008281,-0.000422,-1.329028,-232.679855,-0.132270,0.000000
0.910000,-0.032394,-232.724335,-0.010356,-0.004997,-0.126927,-0.144098,-0.007341,-1.269272,-232.724335,-0.125609,0.000000
1.310000,0.013031,-232.724335,-0.010080,-0.004734,-0.120242,0.057965,0.002953,-1.202416,-232.724335,-0.118949,0.000000
1.710000,0.030159,-232.724335,-0.009822,-0.004475,-0.113668,0.134154,0.006834,-1.136680,-232.724335,-0.112289,0.000000
2.110000,0.005959,-232.813293,-0.009554,-0.004212,-0.106982,0.026505,0.001350,-1.069816,-232.813293,-0.105611,0.000000
2.510000,-0.018990,-232.857773,-0.009278,-0.003941,-0.100104,-0.084470,-0.004303,-1.001044,-232.857773,-0.098951,0.000000
2.910000,-0.037613,-232.813293,-0.009002,-0.003682,-0.093531,-0.167311,-0.008523,-0.935308,-232.813293,-0.092291,0.000000
3.310000,0.022339,-232.857773,-0.008735,-0.003416,-0.086757,0.099368,0.005062,-0.867574,-232.857773,-0.085630,0.000000
3.710000,-0.008934,-232.857773,-0.008459,-0.003154,-0.080106,-0.039741,-0.002024,-0.801058,-232.857773,-0.078970,0.000000
4.110000,-0.002235,-232.991226,-0.008205,-0.002896,-0.073567,-0.009944,-0.000507,-0.735670,-232.991226,-0.072292,0.000000
4.510000,-0.024948,-233.035706,-0.007912,-0.002635,-0.066925,-0.110975,-0.005653,-0.669245,-233.035706,-0.065632,0.000000
4.910000,-0.062935,-233.080185,-0.007649,-0.002368,-0.060143,-0.279948,-0.014261,-0.601427,-233.080185,-0.058972,0.000000
5.310000,-0.032394,-233.080185,-0.007386,-0.002108,-0.053552,-0.144098,-0.007341,-0.535517,-233.080185,-0.052312,0.000000
5.710000,0.005211,-233.080185,-0.007101,-0.001840,-0.046727,0.023179,0.001181,-0.467268,-233.080185,-0.045651,0.000000
6.110000,0.002235,-233.169144,-0.006851,-0.001578,-0.040075,0.009944,0.000507,-0.400752,-233.169144,-0.038974,0.000000
6.510000,0.001488,-233.213623,-0.006592,-0.001328,-0.033744,0.006618,0.000337,-0.337439,-233.213623,-0.032313,0.000000
6.910000,-0.001114,-233.258102,-0.006303,-0.001058,-0.026884,-0.004955,-0.000252,-0.268841,-233.258102,-0.025653,0.000000
7.310000,0.000374,-233.302582,-0.006036,-0.000798,-0.020267,0.001663,0.000085,-0.202674,-233.302582,-0.018993,0.000000
7.710001,0.036118,-233.347076,-0.005786,-0.000535,-0.013590,0.160659,0.008184,-0.135900,-233.347076,-0.012332,0.000000
8.110001,0.054741,-233.391556,-0.005506,-0.000277,-0.007025,0.243500,0.012404,-0.070248,-233.391556,-0.005655,0.000000
8.510000,0.021225,-233.391556,-0.005230,-0.000014,-0.000356,0.094413,0.004810,-0.003558,-233.391556,0.001005,0.000000
8.910001,0.060326,-233.480515,-0.005010,-0.000000,-0.000000,0.268342,0.013670,-0.000000,-233.480515,0.000242,0.000000
9.310000,0.037613,-233.480515,-0.004988,-0.000000,-0.000000,0.167311,0.008523,-0.000000,-233.480515,0.000242,0.000000
9.710000,0.110222,-233.524994,-0.005001,0.000000,0.000008,0.490291,0.024977,0.000083,-233.524994,0.000780,0.000000
10.110001,0.104637,-233.524994,-0.004988,0.000000,0.000008,0.465449,0.023711,0.000083,-233.524994,0.001439,0.000000
10.510000,0.208900,-233.524994,-0.004963,0.000051,0.001300,0.929236,0.047338,0.013005,-233.524994,0.002107,0.000000
10.910001,0.233475,-233.613953,-0.004937,0.000073,0.001847,1.038548,0.052906,0.018470,-233.613953,0.002775,0.000000
11.310000,0.277786,-233.658432,-0.004915,0.000091,0.002324,1.235655,0.062947,0.023239,-233.658432,0.003443,0.000000
11.710001,0.444237,-233.702911,-0.004881,0.000122,0.003104,1.976064,0.100665,0.031044,-233.702911,0.004110,0.000000
12.110001,0.573082,-233.747391,-0.004868,0.000149,0.003772,2.549196,0.129862,0.037720,-233.747391,0.004778,0.000000
12.510000,0.664314,-233.791885,-0.004833,0.000180,0.004570,2.955018,0.150536,0.045699,-233.791885,0.005446,0.000000
12.910001,0.768951,-233.880844,-0.004799,0.000204,0.005177,3.420467,0.174247,0.051770,-233.880844,0.006113,0.000000
13.310000,0.900024,-233.880844,-0.004781,0.000229,0.005819,4.003509,0.203948,0.058189,-233.880844,0.006773,0.000000
13.710001,1.032585,-233.880844,-0.004756,0.000250,0.006348,4.593168,0.233987,0.063480,-233.880844,0.007440,0.000000
14.110001,1.192337,-233.880844,-0.004725,0.000280,0.007119,5.303780,0.270187,0.071194,-233.880844,0.008108,0.000000
14.510000,1.373680,-233.925323,-0.004704,0.000310,0.007866,6.110435,0.311280,0.078658,-233.925323,0.008776,0.000000
14.910001,1.406822,-234.014282,-0.004665,0.000334,0.008490,6.257858,0.318790,0.084895,-234.014282,0.009444,0.000000
15.310000,1.567314,-234.014282,-0.004656,0.000361,0.009158,6.971762,0.355158,0.091579,-234.014282,0.010112,0.000000
15.710001,1.697273,-234.103241,-0.004635,0.000381,0.009669,7.549849,0.384608,0.096689,-234.103241,0.010779,0.000000
16.110001,1.814201,-234.058762,-0.004618,0.000400,0.010164,8.069971,0.411104,0.101640,-234.058762,0.011447,0.000000
16.510000,2.071136,-234.058762,-0.004566,0.000444,0.011274,9.212875,0.469326,0.112737,-234.058762,0.012106,0.000000
16.910002,2.124756,-234.192200,-0.004540,0.000469,0.011916,9.451386,0.481477,0.119156,-234.192200,0.012774,0.000000
17.310001,2.266258,-234.192200,-0.004518,0.000494,0.012540,10.080820,0.513541,0.125401,-234.192200,0.013442,0.000000
17.710001,2.335892,-234.236694,-0.004497,0.000513,0.013043,10.390565,0.529321,0.130427,-234.236694,0.014109,0.000000
18.110001,2.530640,-234.281174,-0.004475,0.000542,0.013771,11.256847,0.573451,0.137710,-234.281174,0.014777,0.000000
18.510000,2.652405,-234.325653,-0.004445,0.000568,0.014430,11.798486,0.601044,0.144303,-234.325653,0.015445,0.000000
18.910002,2.809921,-234.370132,-0.004419,0.000599,0.015211,12.499154,0.636737,0.152107,-234.370132,0.016113,0.000000
19.310001,2.924988,-234.370132,-0.004389,0.000626,0.015905,13.010996,0.662812,0.159049,-234.370132,0.016781,0.000000
19.710001,2.947327,-234.414612,-0.004376,0.000645,0.016382,13.110364,0.667874,0.163818,-234.414612,0.017439,0.000000
20.110001,3.207619,-234.503571,-0.004333,0.000676,0.017180,14.268201,0.726857,0.171796,-234.503571,0.018108,0.000000
20.510000,3.243362,-234.548050,-0.004324,0.000701,0.017812,14.427197,0.734956,0.178125,-234.548050,0.018775,0.000000
20.910002,3.406837,-234.548050,-0.004273,0.000728,0.018489,15.154370,0.772000,0.184892,-234.548050,0.019443,0.000000
21.310001,3.532326,-234.592529,-0.004255,0.000754,0.019157,15.712569,0.800436,0.191569,-234.592529,0.020111,0.000000
21.710001,3.629143,-234.681503,-0.004238,0.000777,0.019729,16.143232,0.822376,0.197291,-234.681503,0.020778,0.000000
22.110001,3.758728,-234.725983,-0.004208,0.000798,0.020258,16.719658,0.851740,0.202583,-234.725983,0.021446,0.000000
22.510000,3.925552,-234.681503,-0.004169,0.000830,0.021082,17.461729,0.889543,0.210819,-234.681503,0.022114,0.000000
22.910002,4.075989,-234.814941,-0.004156,0.000860,0.021845,18.130903,0.923632,0.218449,-234.814941,0.022782,0.000000
23.310001,4.212646,-234.814941,-0.004118,0.000886,0.022504,18.738787,0.954599,0.225042,-234.814941,0.023441,0.000000
23.710001,4.268135,-234.903900,-0.004105,0.000909,0.023094,18.985613,0.967173,0.230939,-234.903900,0.024108,0.000000
24.110001,4.554115,-234.814941,-0.004074,0.000937,0.023796,20.257717,1.031977,0.237964,-234.814941,0.024777,0.000000
24.510000,4.676254,-234.859421,-0.004049,0.000967,0.024569,20.801018,1.059654,0.245685,-234.859421,0.025444,0.000000
24.910002,4.779030,-234.903900,-0.004014,0.000996,0.025288,21.258186,1.082944,0.252876,-234.903900,0.026112,0.000000
25.310001,4.765251,-234.992859,-0.003980,0.001016,0.025808,21.196896,1.079821,0.258084,-234.992859,0.026780,0.000000
25.710001,4.916435,-234.992859,-0.003975,0.001038,0.026372,21.869396,1.114080,0.263724,-234.992859,0.027447,0.000000
26.110001,4.910477,-235.081833,-0.003958,0.001058,0.026883,21.842892,1.112730,0.268834,-235.081833,0.028115,0.000000
26.510002,5.226250,-235.126312,-0.003911,0.001090,0.027699,23.247520,1.184285,0.276986,-235.126312,0.028774,0.000000
26.910002,5.360672,-235.126312,-0.003880,0.001122,0.028488,23.845461,1.214746,0.284881,-235.126312,0.029442,0.000000
27.310001,5.451530,-235.170792,-0.003854,0.001147,0.029138,24.249619,1.235335,0.291384,-235.170792,0.030110,0.000000
27.710001,5.471268,-235.215271,-0.003829,0.001166,0.029624,24.337414,1.239807,0.296244,-235.215271,0.030777,0.000000
28.110001,5.680542,-235.259750,-0.003811,0.001193,0.030300,25.268312,1.287229,0.303004,-235.259750,0.031446,0.000000
28.510002,5.935242,-235.393188,-0.003768,0.001228,0.031185,26.401274,1.344945,0.311853,-235.393188,0.032113,0.000000
28.910002,5.836937,-235.348709,-0.003755,0.001249,0.031714,25.963993,1.322669,0.317144,-235.348709,0.032781,0.000000
29.310001,5.784805,-235.348709,-0.003742,0.001263,0.032087,25.732100,1.310856,0.320868,-235.348709,0.033449,0.000000
29.710001,6.150475,-235.393188,-0.003712,0.001295,0.032902,27.358677,1.393717,0.329021,-235.393188,0.034108,0.000000
30.110001,6.507950,-235.393188,-0.003665,0.001333,0.033856,28.948807,1.474723,0.338559,-235.393188,0.034776,0.000000
30.510002,6.424911,-235.437668,-0.003639,0.001354,0.034394,28.579433,1.455906,0.343941,-235.437668,0.035443,0.000000
30.910002,6.375015,-235.526642,-0.003613,0.001373,0.034879,28.357485,1.444599,0.348793,-235.526642,0.036111,0.000000
31.310001,6.818138,-235.526642,-0.003591,0.001409,0.035782,30.328592,1.545012,0.357816,-235.526642,0.036779,0.000000
31.710001,6.867294,-235.615601,-0.003570,0.001436,0.036475,30.547251,1.556151,0.364750,-235.615601,0.037446,0.000000
32.110001,7.026665,-235.615601,-0.003531,0.001468,0.037299,31.256166,1.592265,0.372994,-235.615601,0.038114,0.000000
32.510002,6.872505,-235.704559,-0.003514,0.001487,0.037759,30.570431,1.557332,0.377589,-235.704559,0.038782,0.000000
32.910000,6.640518,-235.660080,-0.003488,0.001494,0.037950,29.538500,1.504763,0.379496,-235.660080,0.039441,0.000000
33.310001,7.224022,-235.749039,-0.003462,0.001532,0.038921,32.134056,1.636987,0.389208,-235.749039,0.040109,0.000000
33.710003,7.646667,-235.793518,-0.003410,0.001570,0.039884,34.014076,1.732760,0.398837,-235.793518,0.040777,0.000000
34.110001,7.550972,-235.837997,-0.003389,0.001596,0.040534,33.588402,1.711075,0.405340,-235.837997,0.041445,0.000000
34.510002,7.540916,-235.837997,-0.003376,0.001620,0.041158,33.543671,1.708796,0.411585,-235.837997,0.042112,0.000000
34.910000,7.736038,-235.926971,-0.003341,0.001645,0.041774,34.411617,1.753011,0.417739,-235.926971,0.042780,0.000000
35.310001,7.897278,-235.882477,-0.003316,0.001671,0.042433,35.128845,1.789549,0.424332,-235.882477,0.043448,0.000000
35.710003,7.715553,-235.926971,-0.003290,0.001686,0.042832,34.320496,1.748369,0.428321,-235.926971,0.044115,0.000000
36.110001,8.262573,-236.015930,-0.003255,0.001728,0.043890,36.753761,1.872326,0.438896,-236.015930,0.044775,0.000000
36.510002,8.116600,-236.015930,-0.003225,0.001749,0.044428,36.104439,1.839248,0.444279,-236.015930,0.045442,0.000000
36.910000,8.254005,-236.104889,-0.003203,0.001775,0.045078,36.715649,1.870384,0.450781,-236.104889,0.046110,0.000000
37.310001,8.171715,-236.104889,-0.003169,0.001789,0.045442,36.349602,1.851737,0.454422,-236.104889,0.046778,0.000000
37.710003,8.912735,-236.149368,-0.003147,0.001832,0.046526,39.645824,2.019655,0.465262,-236.149368,0.047446,0.000000
38.110001,8.896347,-236.149368,-0.003113,0.001862,0.047289,39.572929,2.015941,0.472892,-236.149368,0.048114,0.000000
38.510002,8.738838,-236.238327,-0.003091,0.001882,0.047801,38.872295,1.980249,0.478010,-236.238327,0.048781,0.000000
38.910004,8.987579,-236.238327,-0.003057,0.001910,0.048503,39.978748,2.036615,0.485034,-236.238327,0.049449,0.000000
39.310001,8.984978,-236.327286,-0.003027,0.001931,0.049050,39.967178,2.036025,0.490500,-236.327286,0.050117,0.000000
39.710003,9.164085,-236.327286,-0.003014,0.001957,0.049709,40.763889,2.076612,0.497093,-236.327286,0.050776,0.000000
40.110001,9.402031,-236.460739,-0.002966,0.001987,0.050463,41.822323,2.130531,0.504632,-236.460739,0.051444,0.000000
40.510002,9.635139,-236.416260,-0.002928,0.002017,0.051244,42.859241,2.183354,0.512437,-236.416260,0.052111,0.000000
40.910004,9.528641,-236.460739,-0.002906,0.002039,0.051782,42.385509,2.159221,0.517819,-236.460739,0.052779,0.000000
41.310001,9.747963,-236.505219,-0.002906,0.002066,0.052467,43.361103,2.208920,0.524670,-236.505219,0.053447,0.000000
41.710003,9.838821,-236.549698,-0.002846,0.002092,0.053135,43.765263,2.229509,0.531346,-236.549698,0.054115,0.000000
42.110001,9.992615,-236.549698,-0.002815,0.002120,0.053837,44.449371,2.264359,0.538371,-236.549698,0.054783,0.000000
42.510002,10.173218,-236.594177,-0.002798,0.002147,0.054522,45.252731,2.305284,0.545222,-236.594177,0.055450,0.000000
42.910004,9.985168,-236.683136,-0.002768,0.002167,0.055042,44.416248,2.262671,0.550422,-236.683136,0.056110,0.000000
43.310001,9.975861,-236.727615,-0.002742,0.002187,0.055554,44.374844,2.260562,0.555539,-236.727615,0.056777,0.000000
43.710003,10.657303,-236.727615,-0.002703,0.002225,0.056525,47.406052,2.414979,0.565251,-236.727615,0.057445,0.000000
44.110001,10.669960,-236.816589,-0.002677,0.002253,0.057219,47.462353,2.417847,0.572193,-236.816589,0.058113,0.000000
44.510002,10.593254,-236.816589,-0.002656,0.002277,0.057844,47.121147,2.400466,0.578438,-236.816589,0.058780,0.000000
44.910004,10.393661,-236.861069,-0.002617,0.002297,0.058356,46.233315,2.355237,0.583555,-236.861069,0.059448,0.000000
45.310001,10.385841,-236.905548,-0.002596,0.002317,0.058858,46.198528,2.353465,0.588581,-236.905548,0.060115,0.000000
45.710003,11.092606,-236.905548,-0.002570,0.002356,0.059847,49.342373,2.513620,0.598468,-236.905548,0.060784,0.000000
46.110001,10.944397,-236.950027,-0.002531,0.002382,0.060506,48.683109,2.480036,0.605061,-236.950027,0.061442,0.000000
46.510002,10.971954,-236.994507,-0.002501,0.002410,0.061209,48.805691,2.486280,0.612086,-236.994507,0.062110,0.000000
46.910004,10.430901,-237.038986,-0.002471,0.002422,0.061512,46.398964,2.363676,0.615121,-237.038986,0.062779,0.000000
47.310001,10.855026,-237.083466,-0.002449,0.002450,0.062223,48.285568,2.459784,0.622229,-237.083466,0.063446,0.000000
47.710003,11.181229,-237.083466,-0.002397,0.002478,0.062934,49.736588,2.533703,0.629345,-237.083466,0.064114,0.000000
48.110001,11.480614,-237.172424,-0.002376,0.002511,0.063775,51.068321,2.601544,0.637755,-237.172424,0.064782,0.000000
48.510002,11.455292,-237.216919,-0.002345,0.002542,0.064573,50.955681,2.595806,0.645733,-237.216919,0.065449,0.000000
48.910004,11.323471,-237.216919,-0.002324,0.002565,0.065146,50.369316,2.565935,0.651456,-237.216919,0.066117,0.000000
49.310001,11.314537,-237.350357,-0.002289,0.002585,0.065666,50.329575,2.563911,0.656657,-237.350357,0.066776,0.000000
49.710003,11.406143,-237.305878,-0.002264,0.002612,0.066351,50.737061,2.584669,0.663515,-237.305878,0.067444,0.000000
50.110001,11.480614,-237.305878,-0.002229,0.002642,0.067115,51.068321,2.601544,0.671145,-237.305878,0.068111,0.000000
50.510002,11.208786,-237.439316,-0.002207,0.002660,0.067557,49.859169,2.539947,0.675566,-237.439316,0.068779,0.000000
50.910004,11.795639,-237.439316,-0.002169,0.002694,0.068415,52.469624,2.672930,0.684150,-237.439316,0.069447,0.000000
51.310001,12.016083,-237.439316,-0.002139,0.002725,0.069205,53.450207,2.722883,0.692045,-237.439316,0.070115,0.000000
51.710003,11.760635,-237.572754,-0.002113,0.002747,0.069768,52.313919,2.664998,0.697677,-237.572754,0.070783,0.000000
52.110001,11.408745,-237.528275,-0.002070,0.002764,0.070211,50.748631,2.585258,0.702106,-237.528275,0.071450,0.000000
52.510002,12.038803,-237.572754,-0.002048,0.002799,0.071095,53.551270,2.728032,0.710947,-237.572754,0.072118,0.000000
52.910004,12.211952,-237.617233,-0.002013,0.002827,0.071797,54.321476,2.767268,0.717972,-237.617233,0.072777,0.000000
53.310001,12.496071,-237.661728,-0.001983,0.002860,0.072638,55.585300,2.831650,0.726382,-237.661728,0.073445,0.000000
53.710003,12.137482,-237.750687,-0.001944,0.002881,0.073185,53.990215,2.750393,0.731847,-237.750687,0.074113,0.000000
54.110004,11.714462,-237.750687,-0.001936,0.002893,0.073471,52.108532,2.654535,0.734709,-237.750687,0.074780,0.000000
54.510002,12.624916,-237.839645,-0.001897,0.002929,0.074408,56.158432,2.860847,0.744080,-237.839645,0.075448,0.000000
54.910004,13.137299,-237.795166,-0.001863,0.002959,0.075171,58.437622,2.976954,0.751710,-237.795166,0.076116,0.000000
55.310001,13.191666,-237.884125,-0.001815,0.002988,0.075899,58.679459,2.989274,0.758993,-237.884125,0.076784,0.000000
55.710003,13.017769,-237.884125,-0.001802,0.003011,0.076489,57.905930,2.949868,0.764889,-237.884125,0.077452,0.000000
56.110004,13.343597,-237.973083,-0.001781,0.003039,0.077191,59.355286,3.023702,0.771914,-237.973083,0.078110,0.000000
56.510002,13.253105,-237.973083,-0.001729,0.003060,0.077721,58.952755,3.003196,0.777205,-237.973083,0.078779,0.000000
56.910004,13.451958,-238.017563,-0.001712,0.003084,0.078336,59.837296,3.048257,0.783360,-238.017563,0.079446,0.000000
57.310001,14.182175,-238.151016,-0.001690,0.003118,0.079186,63.085464,3.213727,0.791861,-238.151016,0.080114,0.000000
57.710003,14.087593,-238.106537,-0.001643,0.003141,0.079793,62.664745,3.192294,0.797932,-238.106537,0.080782,0.000000
58.110004,14.299850,-238.151016,-0.001621,0.003168,0.080470,63.608913,3.240392,0.804699,-238.151016,0.081449,0.000000
58.510002,14.596252,-238.239975,-0.001591,0.003192,0.081068,64.927376,3.307558,0.810679,-238.239975,0.082117,0.000000
58.910004,15.282166,-238.195496,-0.001574,0.003223,0.081857,67.978470,3.462988,0.818574,-238.195496,0.082785,0.000000
59.310001,15.212906,-238.239975,-0.001522,0.003251,0.082586,67.670387,3.447294,0.825857,-238.239975,0.083444,0.000000
59.710003,14.875160,-238.328934,-0.001509,0.003273,0.083123,66.168015,3.370759,0.831231,-238.328934,0.084112,0.000000
60.110004,15.415100,-238.284454,-0.001479,0.003300,0.083817,68.569786,3.493112,0.838173,-238.284454,0.084779,0.000000
60.510002,15.453827,-238.417892,-0.001444,0.003322,0.084380,68.742058,3.501887,0.843804,-238.417892,0.085448,0.000000
60.910004,16.203041,-238.417892,-0.001418,0.003355,0.085213,72.074730,3.671662,0.852131,-238.417892,0.086115,0.000000
61.310001,16.326668,-238.417892,-0.001393,0.003380,0.085847,72.624649,3.699676,0.858467,-238.417892,0.086783,0.000000
61.710003,16.474129,-238.506866,-0.001354,0.003405,0.086480,73.280586,3.733091,0.864796,-238.506866,0.087451,0.000000
62.110004,16.882248,-238.506866,-0.001332,0.003433,0.087208,75.095993,3.825572,0.872078,-238.506866,0.088118,0.000000
62.510002,16.843895,-238.551346,-0.001302,0.003454,0.087719,74.925385,3.816881,0.877195,-238.551346,0.088778,0.000000
62.910004,17.517891,-238.551346,-0.001276,0.003485,0.088509,77.923470,3.969611,0.885090,-238.551346,0.089445,0.000000
63.310001,17.643005,-238.684784,-0.001237,0.003510,0.089159,78.480011,3.997962,0.891593,-238.684784,0.090113,0.000000
63.710003,18.289070,-238.640305,-0.001207,0.003539,0.089887,81.353844,4.144362,0.898875,-238.640305,0.090781,0.000000
64.110001,18.076073,-238.684784,-0.001194,0.003559,0.090408,80.406387,4.096097,0.904083,-238.684784,0.091448,0.000000
64.510002,18.454033,-238.773743,-0.001160,0.003583,0.090998,82.087639,4.181744,0.909980,-238.773743,0.092117,0.000000
64.910004,19.269157,-238.818222,-0.001134,0.003616,0.091839,85.713493,4.366454,0.918390,-238.818222,0.092784,0.000000
65.310005,19.616211,-238.818222,-0.001099,0.003643,0.092541,87.257263,4.445097,0.925414,-238.818222,0.093452,0.000000
65.710007,20.016884,-238.818222,-0.001074,0.003670,0.093226,89.039543,4.535891,0.932265,-238.818222,0.094120,0.000000
66.110001,20.127480,-238.951675,-0.001035,0.003693,0.093799,89.531502,4.560952,0.937988,-238.951675,0.094779,0.000000
66.510002,20.245148,-238.951675,-0.001018,0.003712,0.094285,90.054916,4.587616,0.942848,-238.951675,0.095447,0.000000
66.910004,21.307899,-238.996155,-0.000987,0.003747,0.095169,94.782272,4.828439,0.951689,-238.996155,0.096114,0.000000
67.310005,22.075729,-238.996155,-0.000974,0.003774,0.095871,98.197746,5.002432,0.958714,-238.996155,0.096782,0.000000
67.710007,22.576569,-239.040634,-0.000949,0.003802,0.096574,100.425591,5.115924,0.965739,-239.040634,0.097450,0.000000
68.110001,22.297287,-239.040634,-0.000897,0.003819,0.097008,99.183289,5.052637,0.970076,-239.040634,0.098117,0.000000
68.510002,22.833138,-239.129593,-0.000897,0.003842,0.097580,101.566872,5.174063,0.975799,-239.129593,0.098786,0.000000
68.910004,24.269745,-239.218552,-0.000862,0.003876,0.098456,107.957214,5.499603,0.984557,-239.218552,0.099453,0.000000
69.310005,24.940392,-239.174072,-0.000841,0.003905,0.099184,110.940399,5.651574,0.991839,-239.174072,0.100112,0.000000
69.710007,25.849724,-239.218552,-0.000811,0.003933,0.099895,114.985313,5.857631,0.998955,-239.218552,0.100780,0.000000
70.110001,25.773758,-239.352005,-0.000798,0.003954,0.100425,114.647400,5.840417,1.004246,-239.352005,0.101448,0.000000
70.510002,26.005005,-239.307510,-0.000763,0.003974,0.100945,115.676041,5.892818,1.009447,-239.307510,0.102116,0.000000
70.910004,27.790527,-239.352005,-0.000742,0.004009,0.101830,123.618439,6.297423,1.018296,-239.352005,0.102783,0.000000
71.310005,28.445908,-239.396484,-0.000724,0.004033,0.102437,126.533714,6.445935,1.024367,-239.396484,0.103451,0.000000
71.710007,29.238312,-239.396484,-0.000707,0.004057,0.103052,130.058502,6.625496,1.030521,-239.396484,0.104119,0.000000
72.110001,30.334206,-239.485443,-0.000681,0.004084,0.103729,134.933289,6.873829,1.037288,-239.485443,0.104786,0.000000
72.510002,31.522072,-239.529922,-0.000664,0.004111,0.104422,140.217178,7.143003,1.044222,-239.529922,0.105446,0.000000
72.910004,32.401245,-239.529922,-0.000638,0.004139,0.105125,144.127930,7.342227,1.051247,-239.529922,0.106113,0.000000
73.310005,32.933365,-239.574402,-0.000621,0.004158,0.105619,146.494919,7.462807,1.056190,-239.574402,0.106781,0.000000
73.710007,34.591537,-239.529922,-0.000599,0.004191,0.106452,153.870850,7.838555,1.064517,-239.529922,0.107449,0.000000
74.110001,35.522469,-239.663361,-0.000582,0.004214,0.107033,158.011826,8.049506,1.070331,-239.663361,0.108117,0.000000
74.510002,37.728035,-239.663361,-0.000552,0.004251,0.107969,167.822678,8.549295,1.079694,-239.663361,0.108785,0.000000
74.910004,38.281380,-239.752319,-0.000548,0.004271,0.108489,170.284088,8.674685,1.084895,-239.752319,0.109452,0.000000
75.310005,38.805679,-239.841293,-0.000535,0.004288,0.108923,172.616287,8.793493,1.089232,-239.841293,0.110120,0.000000
75.710007,40.655998,-239.752319,-0.000535,0.004319,0.109704,180.846909,9.212781,1.097037,-239.752319,0.110779,0.000000
76.110001,42.001007,-239.841293,-0.000496,0.004344,0.110328,186.829803,9.517565,1.103282,-239.841293,0.111447,0.000000
76.510002,44.237473,-239.930252,-0.000483,0.004380,0.111256,196.778107,10.024355,1.112562,-239.930252,0.112115,0.000000
76.910004,45.230965,-239.930252,-0.000457,0.004404,0.111854,201.197372,10.249483,1.118542,-239.930252,0.112782,0.000000
77.310005,46.543205,-239.930252,-0.000448,0.004426,0.112418,207.034515,10.546842,1.124182,-239.930252,0.113450,0.000000
77.710007,47.706123,-240.019211,-0.000440,0.004447,0.112965,212.207428,10.810362,1.129647,-240.019211,0.114118,0.000000
78.110001,49.819710,-240.019211,-0.000423,0.004480,0.113780,221.609131,11.289308,1.137800,-240.019211,0.114786,0.000000
78.510002,51.801476,-240.063690,-0.000414,0.004508,0.114508,230.424469,11.738382,1.145082,-240.063690,0.115454,0.000000
78.910004,53.435074,-240.152649,-0.000384,0.004534,0.115158,237.691086,12.108561,1.151585,-240.152649,0.116121,0.000000
79.310005,54.986008,-240.152649,-0.000388,0.004558,0.115783,244.589981,12.460008,1.157830,-240.152649,0.116781,0.000000
79.710007,56.188766,-240.197128,-0.000366,0.004579,0.116303,249.940109,12.732556,1.163030,-240.197128,0.117448,0.000000
80.110001,57.945625,-240.286102,-0.000358,0.004603,0.116910,257.755005,13.130666,1.169101,-240.286102,0.118116,0.000000
80.510002,61.311127,-240.286102,-0.000332,0.004641,0.117890,272.725525,13.893300,1.178904,-240.286102,0.118784,0.000000
80.910004,62.925362,-240.286102,-0.000336,0.004665,0.118497,279.905975,14.259091,1.184975,-240.286102,0.119451,0.000000
81.310005,64.620407,-240.330582,-0.000323,0.004690,0.119122,287.445923,14.643193,1.191220,-240.330582,0.120119,0.000000
81.710007,66.106537,-240.330582,-0.000315,0.004710,0.119625,294.056549,14.979956,1.196246,-240.330582,0.120787,0.000000
82.110001,65.512604,-240.419540,-0.000297,0.004702,0.119426,291.414612,14.845367,1.194255,-240.419540,291.548798,0.000000
82.510002,64.809570,-240.464020,-0.000293,0.004702,0.119426,288.287354,14.686059,1.194255,-240.464020,294.500458,0.000000
82.910004,64.243561,-240.464020,-0.000302,0.004703,0.119451,285.769623,14.557799,1.194513,-240.464020,294.500458,0.000000
83.310005,66.402573,-240.552979,-0.000267,0.004548,0.115514,295.373383,15.047038,1.155142,-240.552979,294.500458,0.000000
83.710007,65.846252,-240.552979,-0.000263,0.004549,0.115549,292.898773,14.920974,1.155491,-240.552979,294.500458,0.000000
84.110001,65.546112,-240.641953,-0.000267,0.004602,0.116893,291.563660,14.852961,1.168927,-240.641953,294.500458,0.000000
84.510002,65.288803,-240.641953,-0.000267,0.004698,0.119321,290.419098,14.794654,1.193211,-240.641953,294.500458,0.000000
84.910004,65.212845,-240.686432,-0.000272,0.004719,0.119859,290.081207,14.777442,1.198593,-240.686432,294.500458,0.000000
85.310005,65.121979,-240.730911,-0.000263,0.004725,0.120015,289.677032,14.756851,1.200152,-240.730911,294.500458,0.000000
85.710007,65.002457,-240.819870,-0.000267,0.004727,0.120058,289.145355,14.729767,1.200584,-240.819870,294.500458,0.000000
86.110001,65.540527,-240.775391,-0.000272,0.004736,0.120284,291.538818,14.851695,1.202840,-240.775391,294.500458,0.000000
86.510002,65.404251,-240.775391,-0.000272,0.004736,0.120284,290.932648,14.820815,1.202840,-240.775391,294.500458,0.000000
86.910004,65.256790,-240.819870,-0.000259,0.004736,0.120284,290.276703,14.787400,1.202840,-240.819870,294.500458,0.000000
87.310005,65.098160,-240.908829,-0.000263,0.004737,0.120310,289.571075,14.751454,1.203097,-240.908829,294.500458,0.000000
87.710007,65.574051,-240.908829,-0.000263,0.004743,0.120466,291.687958,14.859292,1.204664,-240.908829,294.500458,0.000000
88.110001,65.475372,-240.908829,-0.000263,0.004743,0.120466,291.248993,14.836931,1.204664,-240.908829,294.500458,0.000000
88.510002,65.350616,-240.997787,-0.000259,0.004743,0.120466,290.694061,14.808661,1.204664,-240.997787,294.500458,0.000000
88.910004,65.244492,-241.042267,-0.000259,0.004743,0.120466,290.221985,14.784614,1.204664,-241.042267,294.500458,0.000000
89.310005,65.143585,-241.042267,-0.000254,0.004743,0.120466,289.773132,14.761747,1.204664,-241.042267,294.500458,0.000000
89.710007,65.011017,-241.131241,-0.000250,0.004743,0.120466,289.183441,14.731707,1.204664,-241.131241,294.500458,0.000000
90.110001,64.928345,-241.175720,-0.000263,0.004743,0.120466,288.815704,14.712973,1.204664,-241.175720,294.500458,0.000000
90.510002,64.815155,-241.175720,-0.000254,0.004743,0.120483,288.312195,14.687325,1.204831,-241.175720,294.500458,0.000000
90.910004,64.754074,-241.175720,-0.000254,0.004743,0.120483,288.040497,14.673483,1.204831,-241.175720,294.500458,0.000000
91.310005,66.370178,-241.220200,-0.000267,0.004746,0.120544,295.229309,15.039698,1.205444,-241.220200,294.500458,0.000000
91.710007,66.242447,-241.309158,-0.000250,0.004746,0.120544,294.661133,15.010753,1.205444,-241.309158,294.500458,0.000000
92.110001,66.151230,-241.309158,-0.000259,0.004746,0.120544,294.255371,14.990083,1.205444,-241.309158,294.500458,0.000000
92.510002,66.047333,-241.309158,-0.000250,0.004746,0.120544,293.793213,14.966539,1.205444,-241.309158,294.500458,0.000000
92.910004,65.962051,-241.398117,-0.000246,0.004746,0.120544,293.413849,14.947214,1.205444,-241.398117,294.500458,0.000000
93.310005,65.822052,-241.442596,-0.000250,0.004746,0.120544,292.791107,14.915490,1.205444,-241.442596,294.500458,0.000000
93.710007,65.797104,-241.487076,-0.000241,0.004746,0.120544,292.680145,14.909837,1.205444,-241.487076,294.500458,0.000000
94.110008,65.750549,-241.487076,-0.000237,0.004746,0.120544,292.473053,14.899287,1.205444,-241.487076,294.500458,0.000000
94.510002,65.620972,-241.531570,-0.000254,0.004746,0.120553,291.896667,14.869925,1.205527,-241.531570,294.500458,0.000000
94.910004,65.568832,-241.620529,-0.000241,0.004746,0.120553,291.664734,14.858110,1.205527,-241.620529,294.500458,0.000000
95.310005,65.514832,-241.620529,-0.000246,0.004746,0.120553,291.424530,14.845873,1.205527,-241.620529,294.500458,0.000000
95.710007,65.410202,-241.665009,-0.000237,0.004746,0.120553,290.959106,14.822164,1.205527,-241.665009,294.500458,0.000000
96.110008,65.343170,-241.709488,-0.000254,0.004746,0.120553,290.660950,14.806974,1.205527,-241.709488,294.500458,0.000000
96.510002,65.285080,-241.709488,-0.000237,0.004746,0.120553,290.402527,14.793811,1.205527,-241.709488,294.500458,0.000000
96.910004,65.242264,-241.798447,-0.000237,0.004746,0.120553,290.212097,14.784108,1.205527,-241.798447,294.500458,0.000000
97.310005,65.162949,-241.798447,-0.000237,0.004746,0.120553,289.859283,14.766135,1.205527,-241.798447,294.500458,0.000000
97.710007,65.070602,-241.842926,-0.000254,0.004747,0.120562,289.448486,14.745210,1.205618,-241.842926,294.500458,0.000000
98.110008,65.059433,-241.842926,-0.000250,0.004747,0.120562,289.398804,14.742678,1.205618,-241.842926,294.500458,0.000000
98.510002,64.984207,-241.931900,-0.000241,0.004747,0.120562,289.064178,14.725632,1.205618,-241.931900,294.500458,0.000000
98.910004,64.960754,-241.931900,-0.000254,0.004747,0.120562,288.959869,14.720317,1.205618,-241.931900,294.500458,0.000000
99.310005,64.895218,-241.976379,-0.000250,0.004747,0.120562,288.668335,14.705466,1.205618,-241.976379,294.500458,0.000000
99.710007,64.816269,-241.931900,-0.000250,0.004747,0.120562,288.317169,14.687577,1.205618,-241.931900,294.500458,0.000000
100.110008,64.789078,-242.065338,-0.000250,0.004747,0.120562,288.196198,14.681415,1.205618,-242.065338,294.500458,0.000000
100.510002,66.681107,-242.065338,-0.000241,0.004773,0.121247,296.612366,15.110155,1.212468,-242.065338,294.500458,0.000000
100.910004,66.391403,-242.109818,-0.000241,0.004740,0.120405,295.323700,15.044507,1.204051,-242.109818,294.500458,0.000000
101.310005,66.343735,-242.154297,-0.000254,0.004740,0.120405,295.111664,15.033705,1.204051,-242.154297,294.500458,0.000000
101.710007,66.294952,-242.243256,-0.000229,0.004740,0.120405,294.894684,15.022651,1.204051,-242.243256,294.500458,0.000000
102.110008,66.224579,-242.243256,-0.000237,0.004740,0.120405,294.581635,15.006704,1.204051,-242.243256,294.500458,0.000000
102.510002,66.188095,-242.332214,-0.000233,0.004740,0.120405,294.419342,14.998437,1.204051,-242.332214,294.500458,0.000000
102.910004,66.137451,-242.287735,-0.000237,0.004740,0.120405,294.194061,14.986961,1.204051,-242.287735,294.500458,0.000000
103.310005,66.100586,-242.376709,-0.000237,0.004740,0.120405,294.030090,14.978607,1.204051,-242.376709,294.500458,0.000000
103.710007,66.041367,-242.376709,-0.000246,0.004740,0.120405,293.766663,14.965187,1.204051,-242.376709,294.500458,0.000000
104.110008,66.017548,-242.421188,-0.000246,0.004740,0.120405,293.660706,14.959790,1.204051,-242.421188,294.500458,0.000000
104.510002,65.909927,-242.465668,-0.000224,0.004740,0.120405,293.182007,14.935403,1.204051,-242.465668,294.500458,0.000000
104.910004,65.890930,-242.465668,-0.000229,0.004740,0.120405,293.097504,14.931098,1.204051,-242.465668,294.500458,0.000000
105.310005,65.848480,-242.465668,-0.000233,0.004741,0.120414,292.908661,14.921478,1.204142,-242.465668,294.500458,0.000000
105.710007,65.868958,-242.510147,-0.000224,0.004741,0.120414,292.999756,14.926120,1.204142,-242.510147,294.500458,0.000000
106.110008,65.836197,-242.554626,-0.000233,0.004741,0.120414,292.854034,14.918696,1.204142,-242.554626,294.500458,0.000000
106.510002,65.776611,-242.599106,-0.000224,0.004741,0.120414,292.588989,14.905192,1.204142,-242.599106,294.500458,0.000000
106.910004,65.750916,-242.688065,-0.000224,0.004741,0.120414,292.474670,14.899371,1.204142,-242.688065,294.500458,0.000000
107.310005,65.679794,-242.732544,-0.000237,0.004741,0.120414,292.158325,14.883254,1.204142,-242.732544,294.500458,0.000000
107.710007,65.643311,-242.732544,-0.000224,0.004741,0.120414,291.996033,14.874987,1.204142,-242.732544,294.500458,0.000000
108.110008,65.615372,-242.777023,-0.000246,0.004741,0.120414,291.871765,14.868656,1.204142,-242.777023,294.500458,0.000000
108.510002,65.586334,-242.821518,-0.000237,0.004741,0.120414,291.742584,14.862076,1.204142,-242.821518,294.500458,0.000000
108.910004,65.555420,-242.865997,-0.000237,0.004741,0.120414,291.605072,14.855071,1.204142,-242.865997,294.500458,0.000000
109.310005,65.526382,-242.865997,-0.000224,0.004741,0.120414,291.475922,14.848491,1.204142,-242.865997,294.500458,0.000000
109.710007,65.510742,-242.910477,-0.000233,0.004741,0.120414,291.406342,14.844947,1.204142,-242.910477,294.500458,0.000000
110.110008,65.504791,-242.954956,-0.000229,0.004741,0.120432,291.379852,14.843598,1.204316,-242.954956,294.500458,0.000000
110.510002,65.457870,-242.999435,-0.000233,0.004741,0.120432,291.171143,14.832966,1.204316,-242.999435,294.500458,0.000000
110.910004,65.400894,-243.043915,-0.000224,0.004741,0.120432,290.917694,14.820054,1.204316,-243.043915,294.500458,0.000000
111.310005,65.377060,-243.043915,-0.000224,0.004741,0.120432,290.811676,14.814653,1.204316,-243.043915,294.500458,0.000000
111.710007,65.459732,-243.132874,-0.000233,0.004759,0.120891,291.179443,14.833387,1.208911,-243.132874,294.500458,0.000000
112.110008,65.410950,-243.132874,-0.000220,0.004759,0.120891,290.962433,14.822333,1.208911,-243.132874,294.500458,0.000000
112.510002,65.388229,-243.177353,-0.000220,0.004759,0.120891,290.861359,14.817184,1.208911,-243.177353,294.500458,0.000000
112.910004,65.373337,-243.177353,-0.000224,0.004762,0.120961,290.795135,14.813809,1.209607,-243.177353,294.500458,0.000000
113.310005,65.337967,-243.266327,-0.000229,0.004762,0.120961,290.637787,14.805795,1.209607,-243.266327,294.500458,0.000000
113.710007,65.310776,-243.221848,-0.000246,0.004762,0.120961,290.516846,14.799634,1.209607,-243.221848,294.500458,0.000000
114.110008,65.302582,-243.355286,-0.000216,0.004762,0.120961,290.480377,14.797776,1.209607,-243.355286,294.500458,0.000000
114.510002,65.283966,-243.310806,-0.000237,0.004762,0.120961,290.397583,14.793558,1.209607,-243.310806,294.500458,0.000000
114.910004,65.254547,-243.444244,-0.000229,0.004762,0.120961,290.266724,14.786892,1.209607,-243.444244,294.500458,0.000000
115.310005,65.233322,-243.533203,-0.000220,0.004762,0.120961,290.172302,14.782083,1.209607,-243.533203,294.500458,0.000000
115.710007,65.202789,-243.533203,-0.000224,0.004762,0.120961,290.036499,14.775164,1.209607,-243.533203,294.500458,0.000000
116.110008,65.180450,-243.533203,-0.000224,0.004762,0.120961,289.937134,14.770102,1.209607,-243.533203,294.500458,0.000000
116.510002,65.142838,-243.577682,-0.000220,0.004762,0.120961,289.769806,14.761578,1.209607,-243.577682,294.500458,0.000000
116.910004,65.512970,-243.577682,-0.000224,0.004775,0.121281,291.416260,14.845451,1.212809,-243.577682,294.500458,0.000000
117.310005,65.561752,-243.666656,-0.000229,0.004775,0.121281,291.633240,14.856505,1.212809,-243.666656,294.500458,0.000000
117.710007,65.572556,-243.666656,-0.000224,0.004775,0.121281,291.681305,14.858953,1.212809,-243.666656,294.500458,0.000000
118.110008,65.556549,-243.666656,-0.000220,0.004775,0.121281,291.610107,14.855327,1.212809,-243.666656,294.500458,0.000000
118.510002,65.550583,-243.711136,-0.000229,0.004775,0.121281,291.583557,14.853974,1.212809,-243.711136,294.500458,0.000000
118.910004,65.535690,-243.844574,-0.000233,0.004775,0.121281,291.517303,14.850599,1.212809,-243.844574,294.500458,0.000000
119.310005,65.526016,-243.844574,-0.000224,0.004775,0.121281,291.474274,14.848407,1.212809,-243.844574,294.500458,0.000000
119.710007,65.526016,-243.800095,-0.000229,0.004775,0.121281,291.474274,14.848407,1.212809,-243.800095,294.500458,0.000000
120.110008,65.489883,-243.889053,-0.000216,0.004775,0.121281,291.313538,14.840219,1.212809,-243.889053,294.500458,0.000000
120.510002,65.484299,-243.933533,-0.000224,0.004775,0.121281,291.288696,14.838954,1.212809,-243.933533,294.500458,0.000000
120.910004,65.476486,-243.933533,-0.000224,0.004775,0.121281,291.253967,14.837184,1.212809,-243.933533,294.500458,0.000000
121.310005,65.454147,-244.022491,-0.000224,0.004775,0.121281,291.154602,14.832121,1.212809,-244.022491,294.500458,0.000000
121.710007,65.423981,-244.066986,-0.000216,0.004775,0.121281,291.020386,14.825286,1.212809,-244.066986,294.500458,0.000000
122.110008,65.403503,-244.111465,-0.000233,0.004775,0.121281,290.929321,14.820645,1.212809,-244.111465,294.500458,0.000000
122.510002,65.374832,-244.111465,-0.000233,0.004775,0.121281,290.801788,14.814149,1.212809,-244.111465,294.500458,0.000000
122.910004,65.369247,-244.111465,-0.000229,0.004775,0.121281,290.776947,14.812883,1.212809,-244.111465,294.500458,0.000000
123.310005,65.349136,-244.200424,-0.000224,0.004775,0.121281,290.687469,14.808326,1.212809,-244.200424,294.500458,0.000000
123.710007,65.329391,-244.200424,-0.000224,0.004775,0.121281,290.599640,14.803851,1.212809,-244.200424,294.500458,0.000000
124.110008,65.315994,-244.289383,-0.000220,0.004775,0.121290,290.540039,14.800816,1.212900,-244.289383,294.500458,0.000000
124.510002,65.318970,-244.333862,-0.000237,0.004775,0.121290,290.553284,14.801490,1.212900,-244.333862,294.500458,0.000000
124.910004,65.285461,-244.333862,-0.000233,0.004776,0.121298,290.404236,14.793897,1.212983,-244.333862,294.500458,0.000000
125.310005,65.294388,-244.333862,-0.000237,0.004776,0.121316,290.443939,14.795919,1.213157,-244.333862,294.500458,0.000000
125.710007,65.295517,-244.422821,-0.000229,0.004776,0.121316,290.448975,14.796175,1.213157,-244.422821,294.500458,0.000000
126.110008,65.301102,-244.422821,-0.000224,0.004776,0.121316,290.473816,14.797441,1.213157,-244.422821,294.500458,0.000000
126.510010,65.270187,-244.511795,-0.000224,0.004777,0.121333,290.336304,14.790436,1.213331,-244.511795,294.500458,0.000000
126.910004,65.309296,-244.467300,-0.000233,0.004777,0.121342,290.510254,14.799298,1.213422,-244.467300,294.500458,0.000000
127.310005,65.311890,-244.556274,-0.000224,0.004778,0.121351,290.521790,14.799886,1.213506,-244.556274,294.500458,0.000000
127.710007,65.297745,-244.556274,-0.000224,0.004778,0.121351,290.458862,14.796680,1.213506,-244.556274,294.500458,0.000000
128.110001,65.287323,-244.689713,-0.000241,0.004778,0.121351,290.412506,14.794319,1.213506,-244.689713,294.500458,0.000000
128.510010,65.308548,-244.689713,-0.000237,0.004778,0.121351,290.506927,14.799129,1.213506,-244.689713,294.500458,0.000000
128.910004,65.294022,-244.734192,-0.000229,0.004778,0.121351,290.442322,14.795836,1.213506,-244.734192,294.500458,0.000000
129.310013,65.281738,-244.734192,-0.000220,0.004778,0.121351,290.387665,14.793054,1.213506,-244.734192,294.500458,0.000000
129.710007,65.282852,-244.778671,-0.000220,0.004778,0.121351,290.392639,14.793305,1.213506,-244.778671,294.500458,0.000000
130.110001,65.283966,-244.823151,-0.000229,0.004778,0.121351,290.397583,14.793558,1.213506,-244.823151,294.500458,0.000000
130.510010,65.251938,-244.956604,-0.000220,0.004778,0.121351,290.255127,14.786300,1.213506,-244.956604,294.500458,0.000000
130.910004,65.251205,-244.912109,-0.000229,0.004778,0.121351,290.251862,14.786135,1.213506,-244.912109,294.500458,0.000000
131.310013,65.257156,-244.867630,-0.000229,0.004778,0.121351,290.278320,14.787483,1.213506,-244.867630,294.500458,0.000000
131.710007,65.226990,-244.956604,-0.000216,0.004778,0.121351,290.144135,14.780647,1.213506,-244.956604,294.500458,0.000000
132.110001,65.291046,-245.045563,-0.000224,0.004780,0.121411,290.429077,14.795162,1.214111,-245.045563,294.500458,0.000000
132.510010,65.313019,-245.045563,-0.000224,0.004780,0.121420,290.526825,14.800141,1.214202,-245.045563,294.500458,0.000000
132.910004,65.316742,-245.134521,-0.000203,0.004780,0.121420,290.543365,14.800985,1.214202,-245.134521,294.500458,0.000000
133.310013,65.331635,-245.134521,-0.000229,0.004780,0.121420,290.609619,14.804359,1.214202,-245.134521,294.500458,0.000000
133.710007,65.321579,-245.134521,-0.000224,0.004780,0.121420,290.564880,14.802081,1.214202,-245.134521,294.500458,0.000000
134.110001,65.326416,-245.223480,-0.000211,0.004780,0.121420,290.586426,14.803178,1.214202,-245.223480,294.500458,0.000000
134.510010,65.340561,-245.267960,-0.000237,0.004780,0.121420,290.649323,14.806382,1.214202,-245.267960,294.500458,0.000000
134.910004,65.321945,-245.267960,-0.000220,0.004780,0.121420,290.566528,14.802165,1.214202,-245.267960,294.500458,0.000000
135.310013,65.314880,-245.312439,-0.000224,0.004780,0.121420,290.535095,14.800563,1.214202,-245.312439,294.500458,0.000000
135.710007,65.300354,-245.312439,-0.000216,0.004780,0.121420,290.470490,14.797272,1.214202,-245.312439,294.500458,0.000000
136.110001,65.298859,-245.312439,-0.000224,0.004781,0.121446,290.463837,14.796933,1.214459,-245.312439,294.500458,0.000000
136.510010,65.330139,-245.445892,-0.000207,0.004781,0.121446,290.602966,14.804021,1.214459,-245.445892,294.500458,0.000000
136.910004,65.329773,-245.490372,-0.000224,0.004781,0.121446,290.601349,14.803939,1.214459,-245.490372,294.500458,0.000000
137.310013,65.330139,-245.534851,-0.000229,0.004781,0.121446,290.602966,14.804021,1.214459,-245.534851,294.500458,0.000000
137.710007,65.313019,-245.534851,-0.000220,0.004781,0.121446,290.526825,14.800141,1.214459,-245.534851,294.500458,0.000000
138.110001,65.326797,-245.579330,-0.000216,0.004781,0.121446,290.588104,14.803264,1.214459,-245.579330,294.500458,0.000000
138.510010,65.320084,-245.534851,-0.000211,0.004781,0.121446,290.558258,14.801743,1.214459,-245.534851,294.500458,0.000000
138.910004,65.314499,-245.623810,-0.000224,0.004781,0.121446,290.533386,14.800477,1.214459,-245.623810,294.500458,0.000000
139.310013,65.313019,-245.668289,-0.000229,0.004781,0.121446,290.526825,14.800141,1.214459,-245.668289,294.500458,0.000000
139.710007,65.298111,-245.668289,-0.000224,0.004782,0.121463,290.460510,14.796764,1.214633,-245.668289,294.500458,0.000000
140.110001,65.324921,-245.757248,-0.000211,0.004783,0.121481,290.579773,14.802838,1.214808,-245.757248,294.500458,0.000000
140.510010,65.320465,-245.757248,-0.000220,0.004783,0.121481,290.559937,14.801828,1.214808,-245.757248,294.500458,0.000000
140.910004,65.332382,-245.846222,-0.000224,0.004783,0.121481,290.612946,14.804529,1.214808,-245.846222,294.500458,0.000000
141.310013,65.324554,-245.846222,-0.000224,0.004783,0.121481,290.578125,14.802755,1.214808,-245.846222,294.500458,0.000000
141.710007,65.324921,-245.846222,-0.000224,0.004783,0.121481,290.579773,14.802838,1.214808,-245.846222,294.500458,0.000000
142.110001,65.329391,-245.935181,-0.000224,0.004783,0.121481,290.599640,14.803851,1.214808,-245.935181,294.500458,0.000000
142.510010,65.323059,-246.024139,-0.000229,0.004777,0.121333,290.571472,14.802417,1.213331,-246.024139,0.121481,0.000000
142.910004,65.185287,-246.024139,-0.000216,0.004766,0.121064,289.958649,14.771197,1.210644,-246.024139,0.120839,0.000000
143.310013,65.156250,-246.068619,-0.000220,0.004745,0.120527,289.829468,14.764617,1.205270,-246.068619,0.120171,0.000000
143.710007,65.092575,-246.068619,-0.000216,0.004723,0.119971,289.546234,14.750189,1.199713,-246.068619,0.119504,0.000000
144.110001,65.062408,-246.113098,-0.000224,0.004698,0.119338,289.412048,14.743353,1.193385,-246.113098,0.118836,0.000000
144.510010,65.054581,-246.157578,-0.000216,0.004681,0.118905,289.377228,14.741579,1.189047,-246.157578,0.118177,0.000000
144.910004,65.047134,-246.157578,-0.000220,0.004653,0.118194,289.344116,14.739891,1.181939,-246.157578,0.117509,0.000000
145.310013,65.022568,-246.202057,-0.000224,0.004623,0.117422,289.234833,14.734324,1.174218,-246.202057,0.116841,0.000000
145.710007,64.988678,-246.246552,-0.000229,0.004597,0.116772,289.084076,14.726645,1.167716,-246.246552,0.116174,0.000000
146.110001,64.903778,-246.246552,-0.000229,0.004576,0.116242,288.706421,14.707407,1.162425,-246.246552,0.115505,0.000000
146.510010,64.288620,-246.291031,-0.000216,0.004547,0.115505,285.970062,14.568009,1.155052,-246.291031,0.114837,0.000000
146.910004,63.662659,-246.335510,-0.000216,0.004529,0.115046,283.185638,14.426165,1.150457,-246.335510,0.114170,0.000000
147.310013,62.243172,-246.424469,-0.000198,0.004498,0.114257,276.871460,14.104504,1.142569,-246.424469,0.113502,0.000000
147.710007,61.022537,-246.424469,-0.000185,0.004476,0.113702,271.441803,13.827905,1.137020,-246.424469,0.112843,0.000000
148.110001,59.628746,-246.513428,-0.000190,0.004458,0.113224,265.241913,13.512067,1.132244,-246.513428,0.112175,0.000000
148.510010,57.462280,-246.468948,-0.000190,0.004428,0.112461,255.604996,13.021139,1.124613,-246.468948,0.111508,0.000000
148.910004,55.235497,-246.602386,-0.000181,0.004399,0.111741,245.699753,12.516542,1.117415,-246.602386,0.110840,0.000000
149.310013,53.036263,-246.646881,-0.000194,0.004376,0.111161,235.917084,12.018188,1.111609,-246.646881,0.110172,0.000000
149.710007,50.419975,-246.646881,-0.000185,0.004351,0.110519,224.279251,11.425330,1.105189,-246.646881,0.109505,0.000000
150.110001,47.538559,-246.691360,-0.000177,0.004323,0.109816,211.462067,10.772391,1.098165,-246.691360,0.108836,0.000000
150.510010,44.829918,-246.691360,-0.000181,0.004298,0.109175,199.413437,10.158605,1.091745,-246.691360,0.108169,0.000000
150.910004,41.783165,-246.780319,-0.000185,0.004269,0.108437,185.860794,9.468201,1.084372,-246.780319,0.107501,0.000000
151.310013,39.218269,-246.780319,-0.000181,0.004246,0.107857,174.451569,8.886987,1.078566,-246.780319,0.106842,0.000000
151.710007,36.267960,-246.824799,-0.000185,0.004222,0.107240,161.327942,8.218437,1.072405,-246.824799,0.106174,0.000000
152.110001,33.483734,-246.869278,-0.000190,0.004194,0.106521,148.943085,7.587523,1.065213,-246.869278,0.105506,0.000000
152.510010,31.440155,-246.913757,-0.000190,0.004175,0.106053,139.852798,7.124441,1.060528,-246.913757,0.104839,0.000000
152.910004,27.728714,-246.869278,-0.000198,0.004145,0.105290,123.343483,6.283416,1.052897,-246.869278,0.104171,0.000000
153.310013,24.320389,-246.913757,-0.000185,0.004111,0.104431,108.182495,5.511079,1.044313,-246.913757,0.103503,0.000000
153.710007,21.368217,-247.002716,-0.000190,0.004088,0.103833,95.050575,4.842107,1.038325,-247.002716,0.102836,0.000000
154.110001,18.861778,-247.047195,-0.000181,0.004065,0.103260,83.901382,4.274140,1.032603,-247.047195,0.102167,0.000000
154.510010,15.639641,-247.002716,-0.000185,0.004036,0.102515,69.568596,3.543993,1.025146,-247.002716,0.101509,0.000000
154.910004,13.806824,-247.136169,-0.000185,0.004017,0.102038,61.415821,3.128671,1.020377,-247.136169,0.100841,0.000000
155.310013,9.204300,-247.091690,-0.000181,0.003979,0.101075,40.942772,2.085724,1.010749,-247.091690,0.100173,0.000000
155.710007,7.316002,-247.180649,-0.000185,0.003960,0.100589,32.543201,1.657830,1.005889,-247.180649,0.099505,0.000000
156.110001,5.046394,-247.225128,-0.000194,0.003944,0.100173,22.447483,1.143529,1.001733,-247.225128,0.098837,0.000000
156.510010,1.300323,-247.314087,-0.000185,0.003906,0.099219,5.784128,0.294658,0.992187,-247.314087,0.098170,0.000000
156.910004,-0.231613,-247.269608,-0.000194,0.003893,0.098872,-1.030267,-0.052484,0.988721,-247.269608,0.097502,0.000000
157.310013,-0.065163,-247.314087,-0.000172,0.003855,0.097927,-0.289858,-0.014766,0.979266,-247.314087,0.096834,0.000000
157.710007,0.116928,-247.314087,-0.000194,0.003837,0.097459,0.520122,0.026496,0.974588,-247.314087,0.096175,0.000000
158.110001,0.072983,-247.403046,-0.000198,0.003803,0.096609,0.324644,0.016538,0.966087,-247.403046,0.095507,0.000000
158.510010,0.079315,-247.447525,-0.000233,0.003772,0.095819,0.352812,0.017973,0.958192,-247.447525,0.094840,0.000000
158.910004,0.125114,-247.492004,-0.000306,0.003747,0.095186,0.556537,0.028351,0.951863,-247.492004,0.094172,0.000000
159.310013,0.093094,-247.536499,-0.000379,0.003720,0.094476,0.414102,0.021095,0.944755,-247.536499,0.093504,0.000000
159.710007,0.135544,-247.580978,-0.000414,0.003691,0.093764,0.602929,0.030715,0.937640,-247.580978,0.092836,0.000000
160.110001,0.068146,-247.580978,-0.000457,0.003671,0.093252,0.303127,0.015442,0.932522,-247.580978,0.092168,0.000000
160.510010,0.095695,-247.669937,-0.000522,0.003647,0.092645,0.425675,0.021685,0.926451,-247.669937,0.091501,0.000000
160.910004,0.056229,-247.625458,-0.000556,0.003617,0.091874,0.250117,0.012742,0.918738,-247.625458,0.090841,0.000000
161.310013,0.043938,-247.669937,-0.000621,0.003589,0.091154,0.195445,0.009956,0.911539,-247.669937,0.090174,0.000000
161.710007,0.078941,-247.803375,-0.000668,0.003567,0.090607,0.351149,0.017888,0.906074,-247.803375,0.089506,0.000000
162.110001,0.077827,-247.758896,-0.000694,0.003560,0.090426,0.346194,0.017636,0.904257,-247.758896,0.088838,0.000000
162.510010,0.025696,-247.803375,-0.000737,0.003520,0.089411,0.114301,0.005823,0.894106,-247.803375,0.088171,0.000000
162.910004,0.009682,-247.847855,-0.000811,0.003485,0.088509,0.043066,0.002194,0.885090,-247.847855,0.087503,0.000000
163.100006,0.059578,-247.936829,-0.000832,0.003476,0.088301,0.265016,0.013501,0.883008,-247.936829,0.088153,0.000000