File: Data/compression 21/AutoNoHeating-10-21-reverse-1-4_09132024_163615.csv
Time (sec),S:Load (lbs),S:HL1 (DIM),S:LVDT (in),S:Position (in),Ch:Position (mm),Ch:Load (N),Ch:Stress (MPa),Ch:Strain (mm/mm),Ch:HL1 (DIM),Set Point (),Cycles ()
0.110000,-0.033516,-251.406342,-0.012378,-0.007387,-0.187625,-0.149086,-0.007595,-1.876248,-251.406342,-0.187399,0.000000
0.510000,-0.015266,-251.450821,-0.012374,-0.007335,-0.186306,-0.067908,-0.003459,-1.863062,-251.450821,-0.185543,0.000000
0.910000,-0.016014,-251.450821,-0.012258,-0.007091,-0.180114,-0.071234,-0.003629,-1.801141,-251.450821,-0.178866,0.000000
1.310000,-0.041336,-251.495300,-0.011995,-0.006828,-0.173419,-0.183872,-0.009367,-1.734193,-251.495300,-0.172205,0.000000
1.710000,-0.043571,-251.539780,-0.011710,-0.006567,-0.166811,-0.193816,-0.009873,-1.668109,-251.539780,-0.165545,0.000000
2.110000,-0.012665,-251.628738,-0.011447,-0.006298,-0.159960,-0.056336,-0.002870,-1.599603,-251.628738,-0.158885,0.000000
2.510000,0.029045,-251.628738,-0.011184,-0.006046,-0.153577,0.129199,0.006582,-1.535774,-251.628738,-0.152225,0.000000
2.910000,0.007072,-251.717697,-0.010917,-0.005784,-0.146908,0.031460,0.001603,-1.469084,-251.717697,-0.145547,0.000000
3.310000,-0.054367,-251.717697,-0.010637,-0.005512,-0.139996,-0.241837,-0.012320,-1.399965,-251.717697,-0.138887,0.000000
3.710000,-0.064796,-251.762177,-0.010369,-0.005251,-0.133380,-0.288229,-0.014683,-1.333797,-251.762177,-0.132226,0.000000
4.110000,-0.006706,-251.806671,-0.010102,-0.004988,-0.126693,-0.029831,-0.001520,-1.266933,-251.806671,-0.125566,0.000000
4.510000,-0.017128,-251.806671,-0.009848,-0.004727,-0.120077,-0.076189,-0.003881,-1.200765,-251.806671,-0.118905,0.000000
4.910000,-0.004471,-251.851151,-0.009580,-0.004470,-0.113529,-0.019887,-0.001013,-1.135287,-251.851151,-0.112228,0.000000
5.310000,-0.021225,-251.895630,-0.009309,-0.004215,-0.107060,-0.094413,-0.004810,-1.070595,-251.895630,-0.105568,0.000000
5.710000,-0.016388,-251.940109,-0.009024,-0.003941,-0.100113,-0.072897,-0.003714,-1.001127,-251.940109,-0.098908,0.000000
6.110000,-0.009682,-251.895630,-0.008783,-0.003682,-0.093531,-0.043066,-0.002194,-0.935308,-251.895630,-0.092247,0.000000
6.510000,0.007820,-251.984589,-0.008489,-0.003421,-0.086905,0.034786,0.001772,-0.869050,-251.984589,-0.085587,0.000000
6.910000,0.020111,-251.984589,-0.008222,-0.003161,-0.080297,0.089459,0.004557,-0.802965,-251.984589,-0.078909,0.000000
7.310000,0.002235,-252.073547,-0.007976,-0.002896,-0.073567,0.009944,0.000507,-0.735670,-252.073547,-0.072249,0.000000
7.710001,-0.026810,-252.073547,-0.007687,-0.002629,-0.066768,-0.119255,-0.006075,-0.667678,-252.073547,-0.065588,0.000000
8.110001,-0.028297,-252.118027,-0.007424,-0.002369,-0.060177,-0.125873,-0.006412,-0.601768,-252.118027,-0.058929,0.000000
8.510000,0.008934,-252.118027,-0.007136,-0.002100,-0.053334,0.039741,0.002024,-0.533345,-252.118027,-0.052250,0.000000
8.910001,0.041702,-252.162506,-0.006881,-0.001844,-0.046839,0.185501,0.009450,-0.468388,-252.162506,-0.045591,0.000000
9.310000,0.005959,-252.206985,-0.006610,-0.001585,-0.040249,0.026505,0.001350,-0.402486,-252.206985,-0.038930,0.000000
9.710000,-0.035378,-252.295959,-0.006316,-0.001317,-0.033440,-0.157367,-0.008017,-0.334403,-252.295959,-0.032270,0.000000
10.110001,-0.045433,-252.295959,-0.006071,-0.001053,-0.026754,-0.202096,-0.010295,-0.267539,-252.295959,-0.025609,0.000000
10.510000,0.010796,-252.295959,-0.005803,-0.000790,-0.020068,0.048021,0.002446,-0.200683,-252.295959,-0.018932,0.000000
10.910001,0.007820,-252.384918,-0.005527,-0.000529,-0.013442,0.034786,0.001772,-0.134424,-252.384918,-0.012271,0.000000
11.310000,0.027931,-252.384918,-0.005247,-0.000270,-0.006869,0.124244,0.006329,-0.068688,-252.384918,-0.005611,0.000000
11.710001,0.011917,-252.429398,-0.004993,-0.000015,-0.000382,0.053010,0.002700,-0.003815,-252.429398,0.001049,0.000000
12.110001,0.129585,-252.473877,-0.004902,0.000007,0.000173,0.576424,0.029364,0.001733,-252.473877,0.000382,0.000000
12.510000,0.164963,-252.473877,-0.004902,0.000006,0.000164,0.733791,0.037381,0.001643,-252.473877,0.000607,0.000000
12.910001,0.096069,-252.518356,-0.004885,0.000007,0.000173,0.427338,0.021770,0.001733,-252.518356,0.001275,0.000000
13.310000,0.117294,-252.562836,-0.004876,0.000036,0.000919,0.521751,0.026579,0.009190,-252.562836,0.001933,0.000000
13.710001,0.149323,-252.562836,-0.004863,0.000045,0.001145,0.664220,0.033837,0.011446,-252.562836,0.002602,0.000000
14.110001,0.310555,-252.607315,-0.004825,0.000087,0.002219,1.381415,0.070373,0.022195,-252.607315,0.003269,0.000000
14.510000,0.433815,-252.562836,-0.004799,0.000121,0.003070,1.929706,0.098304,0.030695,-252.562836,0.003937,0.000000
14.910001,0.542175,-252.651794,-0.004769,0.000142,0.003607,2.411716,0.122859,0.036070,-252.651794,0.004605,0.000000
15.310000,0.653137,-252.696289,-0.004756,0.000169,0.004301,2.905299,0.148003,0.043012,-252.696289,0.005272,0.000000
15.710001,0.813263,-252.696289,-0.004721,0.000195,0.004960,3.617574,0.184288,0.049605,-252.696289,0.005940,0.000000
16.110001,0.964073,-252.785248,-0.004691,0.000219,0.005558,4.288412,0.218462,0.055585,-252.785248,0.006608,0.000000
16.510000,1.111900,-252.829727,-0.004682,0.000248,0.006287,4.945980,0.251960,0.062875,-252.829727,0.007267,0.000000
16.910002,1.257126,-252.874207,-0.004639,0.000276,0.006998,5.591975,0.284869,0.069983,-252.874207,0.007935,0.000000
17.310001,1.374428,-252.874207,-0.004618,0.000301,0.007640,6.113760,0.311450,0.076402,-252.874207,0.008602,0.000000
17.710001,1.587425,-252.874207,-0.004587,0.000326,0.008273,7.061220,0.359716,0.082730,-252.874207,0.009271,0.000000
18.110001,1.734512,-252.963165,-0.004570,0.000346,0.008785,7.715496,0.393046,0.087847,-252.963165,0.009938,0.000000
18.510000,1.979530,-253.007645,-0.004536,0.000383,0.009721,8.805390,0.448568,0.097211,-253.007645,0.010606,0.000000
18.910002,2.084541,-253.052124,-0.004501,0.000410,0.010406,9.272503,0.472364,0.104062,-253.052124,0.011274,0.000000
19.310001,2.206680,-252.963165,-0.004488,0.000432,0.010962,9.815804,0.500041,0.109618,-252.963165,0.011941,0.000000
19.710001,2.404411,-253.096619,-0.004462,0.000454,0.011542,10.695355,0.544847,0.115424,-253.096619,0.012609,0.000000
20.110001,2.580910,-253.096619,-0.004428,0.000484,0.012288,11.480460,0.584843,0.122880,-253.096619,0.013268,0.000000
20.510000,2.789070,-253.096619,-0.004402,0.000512,0.013008,12.406404,0.632012,0.130079,-253.096619,0.013936,0.000000
20.910002,2.896683,-253.185577,-0.004376,0.000539,0.013685,12.885088,0.656398,0.136847,-253.185577,0.014604,0.000000
21.310001,3.077286,-253.230057,-0.004368,0.000565,0.014361,13.688451,0.697323,0.143606,-253.230057,0.015271,0.000000
21.710001,3.151016,-253.274536,-0.004324,0.000587,0.014899,14.016420,0.714030,0.148989,-253.274536,0.015939,0.000000
22.110001,3.411674,-253.274536,-0.004299,0.000615,0.015619,15.175886,0.773097,0.156187,-253.274536,0.016607,0.000000
22.510000,3.531204,-253.274536,-0.004277,0.000643,0.016321,15.707581,0.800182,0.163212,-253.274536,0.017275,0.000000
22.910002,3.591530,-253.274536,-0.004251,0.000665,0.016902,15.975923,0.813852,0.169018,-253.274536,0.017943,0.000000
23.310001,3.862244,-253.363495,-0.004217,0.000698,0.017717,17.180119,0.875197,0.177171,-253.363495,0.018602,0.000000
23.710001,3.844742,-253.407974,-0.004191,0.000715,0.018151,17.102266,0.871231,0.181508,-253.407974,0.019270,0.000000
24.110001,4.028328,-253.407974,-0.004178,0.000741,0.018827,17.918898,0.912832,0.188268,-253.407974,0.019937,0.000000
24.510000,4.272598,-253.541428,-0.004122,0.000772,0.019608,19.005466,0.968185,0.196080,-253.541428,0.020605,0.000000
24.910002,4.455437,-253.541428,-0.004113,0.000801,0.020345,19.818771,1.009616,0.203446,-253.541428,0.021273,0.000000
25.310001,4.504959,-253.541428,-0.004070,0.000824,0.020934,20.039059,1.020838,0.209343,-253.541428,0.021940,0.000000
25.710001,4.596191,-253.630386,-0.004049,0.000848,0.021541,20.444880,1.041512,0.215414,-253.630386,0.022608,0.000000
26.110001,4.776421,-253.630386,-0.004014,0.000872,0.022158,21.246580,1.082352,0.221575,-253.630386,0.023276,0.000000
26.510002,4.974525,-253.719345,-0.003988,0.000902,0.022921,22.127794,1.127244,0.229206,-253.719345,0.023935,0.000000
26.910002,5.078041,-253.674866,-0.003967,0.000929,0.023597,22.588255,1.150700,0.235973,-253.674866,0.024603,0.000000
27.310001,5.180817,-253.763824,-0.003928,0.000957,0.024299,23.045424,1.173990,0.242990,-253.763824,0.025271,0.000000
27.710001,5.260132,-253.808304,-0.003911,0.000980,0.024898,23.398235,1.191963,0.248978,-253.808304,0.025939,0.000000
28.110001,5.280243,-253.852783,-0.003867,0.000997,0.025322,23.487694,1.196520,0.253225,-253.852783,0.026606,0.000000
28.510002,5.615379,-253.852783,-0.003846,0.001030,0.026173,24.978455,1.272463,0.261725,-253.852783,0.027274,0.000000
28.910002,5.744217,-253.897263,-0.003811,0.001058,0.026867,25.551554,1.301658,0.268667,-253.897263,0.027942,0.000000
29.310001,5.830978,-253.897263,-0.003777,0.001087,0.027612,25.937487,1.321319,0.276123,-253.897263,0.028609,0.000000
29.710001,5.912903,-253.941757,-0.003755,0.001112,0.028237,26.301905,1.339883,0.282368,-253.941757,0.029269,0.000000
30.110001,5.811615,-253.941757,-0.003734,0.001126,0.028601,25.851355,1.316931,0.286009,-253.941757,0.029936,0.000000
30.510002,6.144516,-254.075195,-0.003691,0.001159,0.029451,27.332172,1.392367,0.294510,-254.075195,0.030604,0.000000
30.910002,6.160530,-254.030716,-0.003665,0.001183,0.030058,27.403406,1.395996,0.300581,-254.030716,0.031272,0.000000
31.310001,6.308731,-254.075195,-0.003635,0.001209,0.030717,28.062637,1.429579,0.307167,-254.075195,0.031940,0.000000
31.710001,6.603653,-254.164154,-0.003600,0.001240,0.031506,29.374516,1.496409,0.315062,-254.164154,0.032608,0.000000
32.110001,6.485611,-254.119675,-0.003574,0.001260,0.031991,28.849438,1.469660,0.319914,-254.119675,0.033275,0.000000
32.510002,6.845695,-254.297592,-0.003531,0.001297,0.032937,30.451174,1.551257,0.329369,-254.297592,0.033943,0.000000
32.910000,6.624504,-254.297592,-0.003514,0.001310,0.033266,29.467266,1.501134,0.332662,-254.297592,0.034611,0.000000
33.310001,6.751114,-254.253113,-0.003488,0.001330,0.033787,30.030455,1.529824,0.337870,-254.253113,0.035270,0.000000
33.710003,7.267967,-254.297592,-0.003445,0.001369,0.034784,32.329533,1.646945,0.347839,-254.297592,0.035938,0.000000
34.110001,7.456383,-254.342072,-0.003415,0.001405,0.035695,33.167648,1.689641,0.356946,-254.342072,0.036605,0.000000
34.510002,7.152161,-254.431046,-0.003372,0.001423,0.036146,31.814400,1.620703,0.361457,-254.431046,0.037273,0.000000
34.910000,7.229614,-254.386566,-0.003363,0.001443,0.036657,32.158932,1.638254,0.366575,-254.386566,0.037941,0.000000
35.310001,7.725235,-254.475525,-0.003316,0.001477,0.037516,34.363560,1.750563,0.375159,-254.475525,0.038609,0.000000
35.710003,7.944191,-254.475525,-0.003277,0.001511,0.038374,35.337528,1.800179,0.383743,-254.475525,0.039277,0.000000
36.110001,7.932648,-254.520004,-0.003242,0.001537,0.039042,35.286179,1.797564,0.390419,-254.520004,0.039944,0.000000
36.510002,7.910309,-254.608963,-0.003208,0.001562,0.039666,35.186810,1.792502,0.396665,-254.608963,0.040604,0.000000
36.910000,8.091278,-254.608963,-0.003186,0.001585,0.040265,35.991802,1.833510,0.402652,-254.608963,0.041271,0.000000
37.310001,8.232407,-254.653442,-0.003160,0.001611,0.040924,36.619572,1.865490,0.409238,-254.653442,0.041939,0.000000
37.710003,8.200760,-254.653442,-0.003126,0.001631,0.041436,36.478802,1.858319,0.414355,-254.653442,0.042607,0.000000
38.110001,8.704208,-254.653442,-0.003083,0.001665,0.042295,38.718254,1.972402,0.422947,-254.653442,0.043274,0.000000
38.510002,8.535522,-254.742401,-0.003074,0.001691,0.042945,37.967899,1.934177,0.429449,-254.742401,0.043942,0.000000
38.910004,8.673302,-254.831375,-0.003031,0.001716,0.043595,38.580772,1.965398,0.435952,-254.831375,0.044610,0.000000
39.310001,8.729156,-254.920334,-0.003009,0.001740,0.044202,38.829227,1.978055,0.442023,-254.920334,0.045278,0.000000
39.710003,9.031525,-254.875854,-0.002979,0.001769,0.044940,40.174229,2.046573,0.449396,-254.875854,0.045937,0.000000
40.110001,9.218826,-254.920334,-0.002932,0.001802,0.045781,41.007389,2.089016,0.457806,-254.920334,0.046604,0.000000
40.510002,9.073601,-254.875854,-0.002906,0.001825,0.046345,40.361393,2.056108,0.463445,-254.875854,0.047272,0.000000
40.910004,9.160362,-255.009293,-0.002876,0.001846,0.046882,40.747326,2.075768,0.468820,-255.009293,0.047940,0.000000
41.310001,9.383415,-255.053772,-0.002841,0.001872,0.047550,41.739517,2.126312,0.475496,-255.053772,0.048608,0.000000
41.710003,9.635506,-255.053772,-0.002798,0.001902,0.048322,42.860870,2.183437,0.483218,-255.053772,0.049276,0.000000
42.110001,9.698441,-255.098251,-0.002768,0.001929,0.049007,43.140820,2.197698,0.490068,-255.098251,0.049943,0.000000
42.510002,9.619499,-255.142731,-0.002742,0.001951,0.049562,42.789669,2.179810,0.495617,-255.142731,0.050611,0.000000
42.910004,9.829140,-255.053772,-0.002699,0.001980,0.050299,43.722198,2.227315,0.502990,-255.053772,0.051270,0.000000
43.310001,9.976601,-255.187210,-0.002682,0.002006,0.050958,44.378136,2.260730,0.509576,-255.187210,0.051938,0.000000
43.710003,10.118477,-255.231705,-0.002643,0.002036,0.051704,45.009232,2.292880,0.517039,-255.231705,0.052605,0.000000
44.110001,9.866379,-255.276184,-0.002604,0.002053,0.052154,43.887844,2.235753,0.521543,-255.276184,0.053273,0.000000
44.510002,10.455849,-255.320663,-0.002578,0.002089,0.053065,46.509937,2.369329,0.530650,-255.320663,0.053941,0.000000
44.910004,10.221992,-255.365143,-0.002548,0.002109,0.053568,45.469692,2.316337,0.535684,-255.365143,0.054609,0.000000
45.310001,10.305038,-255.365143,-0.002522,0.002132,0.054158,45.839100,2.335155,0.541581,-255.365143,0.055277,0.000000
45.710003,10.764168,-255.409622,-0.002466,0.002166,0.055016,47.881409,2.439195,0.550165,-255.409622,0.055945,0.000000
46.110001,10.626396,-255.454102,-0.002432,0.002191,0.055658,47.268570,2.407976,0.556584,-255.454102,0.056612,0.000000
46.510002,10.530693,-255.454102,-0.002397,0.002214,0.056239,46.842861,2.386289,0.562390,-255.454102,0.057272,0.000000
46.910004,10.554153,-255.498581,-0.002367,0.002239,0.056864,46.947220,2.391605,0.568635,-255.498581,0.057939,0.000000
47.310001,10.674805,-255.498581,-0.002350,0.002262,0.057453,47.483902,2.418945,0.574532,-255.498581,0.058607,0.000000
47.710003,11.136917,-255.587540,-0.002307,0.002295,0.058286,49.539482,2.523662,0.582859,-255.587540,0.059274,0.000000
48.110001,10.985733,-255.587540,-0.002255,0.002321,0.058954,48.866982,2.489403,0.589535,-255.587540,0.059942,0.000000
48.510002,10.976791,-255.676514,-0.002220,0.002349,0.059673,48.827206,2.487376,0.596734,-255.676514,0.060610,0.000000
48.910004,10.587669,-255.676514,-0.002186,0.002368,0.060150,47.096306,2.399200,0.601503,-255.676514,0.061278,0.000000
49.310001,10.895248,-255.765472,-0.002151,0.002395,0.060844,48.464485,2.468899,0.608445,-255.765472,0.061946,0.000000
49.710003,11.375603,-255.720993,-0.002104,0.002426,0.061625,50.601208,2.577748,0.616249,-255.720993,0.062604,0.000000
50.110001,10.821144,-255.809952,-0.002078,0.002445,0.062093,48.134853,2.452106,0.620927,-255.809952,0.063273,0.000000
50.510002,11.275063,-255.854431,-0.002035,0.002483,0.063056,50.153984,2.554965,0.630556,-255.854431,0.063941,0.000000
50.910004,10.999512,-255.854431,-0.001992,0.002506,0.063663,48.928272,2.492525,0.636627,-255.854431,0.064608,0.000000
51.310001,10.663628,-255.898911,-0.001957,0.002524,0.064122,47.434185,2.416413,0.641222,-255.898911,0.065276,0.000000
51.710003,11.069885,-255.943390,-0.001914,0.002555,0.064903,49.241310,2.508472,0.649026,-255.943390,0.065943,0.000000
52.110001,10.803268,-255.987869,-0.001876,0.002578,0.065484,48.055340,2.448056,0.654840,-255.987869,0.066611,0.000000
52.510002,10.880348,-256.032349,-0.001837,0.002604,0.066152,48.398205,2.465522,0.661516,-256.032349,0.067279,0.000000
52.910004,10.934341,-256.076843,-0.001798,0.002632,0.066863,48.638378,2.477757,0.668632,-256.076843,0.067938,0.000000
53.310001,10.798798,-256.076843,-0.001759,0.002658,0.067513,48.035450,2.447042,0.675134,-256.076843,0.068606,0.000000
53.710003,10.858749,-256.121307,-0.001712,0.002688,0.068276,48.302128,2.460628,0.682765,-256.121307,0.069273,0.000000
54.110004,10.483398,-256.121307,-0.001677,0.002708,0.068788,46.632484,2.375572,0.687882,-256.121307,0.069942,0.000000
54.510002,10.751137,-256.210266,-0.001656,0.002730,0.069343,47.823444,2.436242,0.693431,-256.210266,0.070609,0.000000
54.910004,10.938065,-256.165802,-0.001613,0.002764,0.070211,48.654942,2.478601,0.702106,-256.165802,0.071277,0.000000
55.310001,11.191650,-256.254761,-0.001556,0.002797,0.071034,49.782948,2.536064,0.710342,-256.254761,0.071945,0.000000
55.710003,10.710175,-256.299225,-0.001513,0.002820,0.071633,47.641235,2.426960,0.716329,-256.299225,0.072612,0.000000
56.110004,10.522499,-256.299225,-0.001500,0.002839,0.072110,46.806412,2.384432,0.721098,-256.299225,0.073272,0.000000
56.510002,10.841995,-256.299225,-0.001462,0.002868,0.072838,48.227604,2.456831,0.728380,-256.299225,0.073939,0.000000
56.910004,11.024834,-256.432678,-0.001427,0.002892,0.073453,49.040909,2.498263,0.734535,-256.432678,0.074607,0.000000
57.310001,11.435188,-256.432678,-0.001380,0.002929,0.074408,50.866257,2.591251,0.744080,-256.432678,0.075275,0.000000
57.710003,11.252350,-256.521637,-0.001350,0.002954,0.075023,50.052952,2.549819,0.750234,-256.521637,0.075942,0.000000
58.110004,11.355873,-256.521637,-0.001319,0.002977,0.075621,50.513447,2.573277,0.756214,-256.521637,0.076611,0.000000
58.510002,11.144363,-256.521637,-0.001289,0.002994,0.076047,49.572605,2.525349,0.760469,-256.521637,0.077278,0.000000
58.910004,11.754311,-256.566132,-0.001246,0.003027,0.076880,52.285786,2.663565,0.768795,-256.566132,0.077946,0.000000
59.310001,12.263718,-256.610596,-0.001199,0.003059,0.077703,54.551739,2.778998,0.777031,-256.610596,0.078614,0.000000
59.710003,12.199669,-256.655090,-0.001177,0.003085,0.078371,54.266838,2.764485,0.783708,-256.655090,0.079273,0.000000
60.110004,12.026512,-256.699554,-0.001147,0.003108,0.078952,53.496597,2.725247,0.789522,-256.699554,0.079941,0.000000
60.510002,12.301697,-256.788544,-0.001112,0.003132,0.079542,54.720680,2.787604,0.795418,-256.788544,0.080608,0.000000
60.910004,12.738487,-256.833008,-0.001069,0.003162,0.080313,56.663620,2.886583,0.803132,-256.833008,0.081276,0.000000
61.310001,12.968246,-256.788544,-0.001022,0.003191,0.081060,57.685642,2.938647,0.810596,-256.788544,0.081944,0.000000
61.710003,12.731041,-256.877502,-0.000992,0.003215,0.081667,56.630497,2.884895,0.816667,-256.877502,0.082611,0.000000
62.110004,12.856529,-256.833008,-0.000983,0.003238,0.082256,57.188698,2.913331,0.822564,-256.833008,0.083279,0.000000
62.510002,13.155922,-256.921967,-0.000940,0.003265,0.082932,58.520462,2.981174,0.829323,-256.921967,0.083947,0.000000
62.910004,13.598297,-256.921967,-0.000892,0.003295,0.083695,60.488247,3.081418,0.836954,-256.921967,0.084606,0.000000
63.310001,13.493660,-256.966461,-0.000845,0.003321,0.084364,60.022797,3.057707,0.843638,-256.966461,0.085274,0.000000
63.710003,13.669792,-257.010925,-0.000828,0.003347,0.085022,60.806271,3.097619,0.850224,-257.010925,0.085942,0.000000
64.110001,13.849274,-257.055420,-0.000793,0.003373,0.085673,61.604645,3.138290,0.856726,-257.055420,0.086610,0.000000
64.510002,13.593826,-257.188873,-0.000772,0.003390,0.086106,60.468361,3.080405,0.861064,-257.188873,0.087277,0.000000
64.910004,14.500557,-257.144379,-0.000724,0.003427,0.087052,64.501701,3.285873,0.870518,-257.144379,0.087945,0.000000
65.310005,14.348999,-257.144379,-0.000703,0.003449,0.087616,63.827534,3.251530,0.876158,-257.144379,0.088613,0.000000
65.710007,14.401878,-257.188873,-0.000673,0.003473,0.088205,64.062752,3.263512,0.882055,-257.188873,0.089280,0.000000
66.110001,14.862877,-257.233337,-0.000647,0.003501,0.088916,66.113380,3.367976,0.889163,-257.233337,0.089940,0.000000
66.510002,14.998421,-257.233337,-0.000599,0.003522,0.089471,66.716309,3.398691,0.894711,-257.233337,0.090607,0.000000
66.910004,15.966957,-257.277832,-0.000573,0.003556,0.090330,71.024574,3.618164,0.903303,-257.277832,0.091275,0.000000
67.310005,15.882057,-257.322296,-0.000530,0.003579,0.090911,70.646919,3.598926,0.909109,-257.322296,0.091943,0.000000
67.710007,16.108459,-257.366791,-0.000509,0.003609,0.091657,71.654007,3.650229,0.916565,-257.366791,0.092611,0.000000
68.110001,16.548973,-257.411255,-0.000483,0.003632,0.092264,73.613510,3.750051,0.922636,-257.411255,0.093279,0.000000
68.510002,16.823418,-257.366791,-0.000461,0.003654,0.092819,74.834297,3.812241,0.928192,-257.366791,0.093946,0.000000
68.910004,17.673172,-257.500214,-0.000418,0.003683,0.093547,78.614197,4.004798,0.935475,-257.500214,0.094614,0.000000
69.310005,18.151299,-257.500214,-0.000401,0.003713,0.094310,80.741005,4.113143,0.943105,-257.500214,0.095273,0.000000
69.710007,18.884499,-257.544708,-0.000362,0.003743,0.095074,84.002441,4.279289,0.950735,-257.544708,0.095941,0.000000
70.110001,18.782097,-257.589172,-0.000349,0.003763,0.095568,83.546936,4.256084,0.955678,-257.589172,0.096609,0.000000
70.510002,19.427040,-257.589172,-0.000332,0.003785,0.096140,86.415787,4.402230,0.961401,-257.589172,0.097276,0.000000
70.910004,19.393906,-257.633667,-0.000310,0.003800,0.096531,86.268402,4.394722,0.965307,-257.633667,0.097944,0.000000
71.310005,20.818970,-257.678162,-0.000289,0.003836,0.097424,92.607399,4.717646,0.974240,-257.678162,0.098612,0.000000
71.710007,22.444008,-257.722626,-0.000254,0.003874,0.098403,99.835930,5.085885,0.984035,-257.722626,0.099280,0.000000
72.110001,22.376976,-257.678162,-0.000237,0.003894,0.098907,99.537758,5.070695,0.989069,-257.678162,0.099948,0.000000
72.510002,22.532257,-257.767120,-0.000211,0.003914,0.099427,100.228485,5.105883,0.994269,-257.767120,0.100615,0.000000
72.910004,24.010948,-257.811584,-0.000203,0.003944,0.100173,106.806030,5.440958,1.001733,-257.811584,0.101275,0.000000
73.310005,24.909485,-257.856079,-0.000160,0.003971,0.100876,110.802925,5.644570,1.008758,-257.856079,0.101942,0.000000
73.710007,26.056015,-257.900543,-0.000164,0.004000,0.101612,115.902946,5.904377,1.016123,-257.900543,0.102610,0.000000
74.110001,26.931465,-257.945038,-0.000134,0.004025,0.102228,119.797142,6.102757,1.022285,-257.945038,0.103278,0.000000
74.510002,28.086189,-257.945038,-0.000103,0.004050,0.102870,124.933609,6.364421,1.028697,-257.945038,0.103945,0.000000
74.910004,29.269592,-257.989502,-0.000091,0.004078,0.103581,130.197647,6.632584,1.035812,-257.989502,0.104613,0.000000
75.310005,29.843048,-258.033997,-0.000082,0.004101,0.104162,132.748505,6.762531,1.041618,-258.033997,0.105281,0.000000
75.710007,30.825737,-258.033997,-0.000073,0.004124,0.104743,137.119720,6.985212,1.047432,-258.033997,0.105949,0.000000
76.110001,32.231071,-258.078491,-0.000052,0.004154,0.105524,143.370972,7.303665,1.055236,-258.078491,0.106608,0.000000
76.510002,34.191612,-258.122955,-0.000034,0.004188,0.106365,152.091888,7.747930,1.063646,-258.122955,0.107275,0.000000
76.910004,35.426399,-258.167450,-0.000013,0.004213,0.106998,157.584488,8.027737,1.069982,-258.167450,0.107943,0.000000
77.310005,35.954796,-258.167450,0.000004,0.004233,0.107527,159.934921,8.147473,1.075274,-258.167450,0.108611,0.000000
77.710007,37.649834,-258.256409,0.000022,0.004263,0.108281,167.474823,8.531574,1.082813,-258.256409,0.109279,0.000000
78.110001,39.069321,-258.256409,0.000026,0.004289,0.108949,173.789017,8.853234,1.089490,-258.256409,0.109947,0.000000
78.510002,41.171730,-258.300873,0.000039,0.004320,0.109738,183.141006,9.329648,1.097385,-258.300873,0.110614,0.000000
78.910004,42.319382,-258.345367,0.000056,0.004344,0.110336,188.246017,9.589708,1.103365,-258.345367,0.111282,0.000000
79.310005,43.437248,-258.345367,0.000069,0.004365,0.110866,193.218536,9.843020,1.108656,-258.345367,0.111941,0.000000
79.710007,44.732361,-258.389832,0.000082,0.004388,0.111455,198.979477,10.136497,1.114553,-258.389832,0.112609,0.000000
80.110001,46.553635,-258.434326,0.000099,0.004418,0.112210,207.080902,10.549204,1.122100,-258.434326,0.113277,0.000000
80.510002,48.580452,-258.434326,0.000095,0.004447,0.112956,216.096649,11.008488,1.129557,-258.434326,0.113944,0.000000
80.910004,50.307892,-258.478821,0.000103,0.004471,0.113572,223.780685,11.399931,1.135718,-258.478821,0.114612,0.000000
81.310005,51.950798,-258.478821,0.000129,0.004499,0.114283,231.088684,11.772219,1.142826,-258.478821,0.115280,0.000000
81.710007,53.680840,-258.567780,0.000142,0.004522,0.114847,238.784302,12.164252,1.148466,-258.567780,0.115948,0.000000
82.110001,55.124901,-258.612244,0.000129,0.004546,0.115462,245.207809,12.491481,1.154620,-258.612244,0.116616,0.000000
82.510002,57.837265,-258.612244,0.000147,0.004581,0.116364,257.273010,13.106112,1.163643,-258.612244,0.117275,0.000000
82.910004,60.158630,-258.701202,0.000164,0.004609,0.117058,267.598938,13.632140,1.170577,-258.701202,0.117943,0.000000
83.310005,61.534920,-258.701202,0.000172,0.004627,0.117526,273.721008,13.944013,1.175263,-258.701202,0.118610,0.000000
83.710007,63.332367,-258.701202,0.000185,0.004652,0.118168,281.716431,14.351319,1.181682,-258.701202,0.119278,0.000000
84.110001,65.647781,-258.790161,0.000190,0.004681,0.118905,292.015930,14.876000,1.189047,-258.790161,0.119946,0.000000
84.510002,65.782196,-258.790161,0.000203,0.004681,0.118896,292.613831,14.906458,1.188964,-258.790161,0.020860,0.000000
84.910004,65.053848,-258.879150,0.000194,0.004682,0.118922,289.373962,14.741412,1.189222,-258.879150,294.500458,0.000000
85.310005,65.597504,-258.879150,0.000224,0.004694,0.119235,291.792267,14.864607,1.192348,-258.879150,294.500458,0.000000
85.710007,65.218430,-258.923615,0.000216,0.004694,0.119235,290.106049,14.778708,1.192348,-258.923615,294.500458,0.000000
86.110001,64.849030,-258.968109,0.000216,0.004695,0.119243,288.462891,14.695001,1.192431,-258.968109,294.500458,0.000000
86.510002,64.515396,-258.879150,0.000220,0.004695,0.119252,286.978821,14.619398,1.192522,-258.879150,294.500458,0.000000
86.910004,66.472580,-259.057068,0.000233,0.004628,0.117561,295.684814,15.062902,1.175611,-259.057068,294.500458,0.000000
87.310005,66.179520,-259.057068,0.000224,0.004629,0.117569,294.381195,14.996493,1.175694,-259.057068,294.500458,0.000000
87.710007,65.869339,-259.101532,0.000224,0.004630,0.117595,293.001465,14.926206,1.175952,-259.101532,294.500458,0.000000
88.110001,65.627289,-259.101532,0.000233,0.004650,0.118107,291.924774,14.871357,1.181069,-259.101532,294.500458,0.000000
88.510002,65.431061,-259.234985,0.000224,0.004666,0.118515,291.051880,14.826890,1.185149,-259.234985,294.500458,0.000000
88.910004,65.367004,-259.146027,0.000233,0.004693,0.119191,290.766968,14.812375,1.191909,-259.146027,294.500458,0.000000
89.310005,65.346527,-259.234985,0.000241,0.004706,0.119521,290.675873,14.807735,1.195209,-259.234985,294.500458,0.000000
89.710007,65.287323,-259.234985,0.000237,0.004707,0.119564,290.412506,14.794319,1.195641,-259.234985,294.500458,0.000000
90.110001,65.176346,-259.279449,0.000233,0.004708,0.119573,289.918854,14.769171,1.195732,-259.279449,294.500458,0.000000
90.510002,65.502930,-259.323944,0.000241,0.004714,0.119729,291.371582,14.843176,1.197291,-259.323944,294.500458,0.000000
90.910004,65.424347,-259.323944,0.000233,0.004714,0.119729,291.022034,14.825369,1.197291,-259.323944,294.500458,0.000000
91.310005,65.317856,-259.368439,0.000229,0.004714,0.119729,290.548340,14.801237,1.197291,-259.368439,294.500458,0.000000
91.710007,65.245987,-259.457397,0.000233,0.004714,0.119737,290.228638,14.784952,1.197374,-259.457397,294.500458,0.000000
92.110001,65.183060,-259.457397,0.000233,0.004720,0.119876,289.948730,14.770692,1.198760,-259.457397,294.500458,0.000000
92.510002,65.563995,-259.501862,0.000229,0.004721,0.119911,291.643219,14.857014,1.199108,-259.501862,294.500458,0.000000
92.910004,65.541275,-259.501862,0.000246,0.004721,0.119902,291.542145,14.851865,1.199024,-259.501862,294.500458,0.000000
93.310005,65.477234,-259.590820,0.000233,0.004721,0.119902,291.257294,14.837354,1.199024,-259.590820,294.500458,0.000000
93.710007,65.373337,-259.635315,0.000246,0.004721,0.119911,290.795135,14.813809,1.199108,-259.635315,294.500458,0.000000
94.110008,65.320831,-259.635315,0.000237,0.004721,0.119920,290.561584,14.801912,1.199199,-259.635315,294.500458,0.000000
94.510002,65.284714,-259.679779,0.000241,0.004722,0.119928,290.400909,14.793728,1.199282,-259.679779,294.500458,0.000000
94.910004,65.288437,-259.724274,0.000250,0.004723,0.119972,290.417480,14.794571,1.199721,-259.724274,294.500458,0.000000
95.310005,65.294022,-259.768768,0.000241,0.004724,0.119989,290.442322,14.795836,1.199887,-259.768768,294.500458,0.000000
95.710007,65.279495,-259.813232,0.000237,0.004724,0.119989,290.377686,14.792545,1.199887,-259.813232,294.500458,0.000000
96.110008,65.276886,-259.857727,0.000237,0.004725,0.120024,290.366089,14.791954,1.200236,-259.857727,294.500458,0.000000
96.510002,65.271683,-259.857727,0.000246,0.004726,0.120033,290.342957,14.790774,1.200326,-259.857727,294.500458,0.000000
96.910004,65.294388,-259.902191,0.000241,0.004727,0.120058,290.443939,14.795919,1.200584,-259.902191,294.500458,0.000000
97.310005,65.288071,-259.902191,0.000237,0.004727,0.120067,290.415833,14.794489,1.200675,-259.902191,294.500458,0.000000
97.710007,65.302216,-259.946686,0.000241,0.004728,0.120093,290.478760,14.797693,1.200932,-259.946686,294.500458,0.000000
98.110008,65.292908,-259.991150,0.000237,0.004728,0.120093,290.437347,14.795585,1.200932,-259.991150,294.500458,0.000000
98.510002,65.291794,-260.035645,0.000241,0.004729,0.120111,290.432404,14.795332,1.201106,-260.035645,294.500458,0.000000
98.910004,65.260132,-260.080109,0.000233,0.004729,0.120111,290.291565,14.788157,1.201106,-260.080109,294.500458,0.000000
99.310005,65.274292,-260.124603,0.000237,0.004730,0.120154,290.354553,14.791366,1.201538,-260.124603,294.500458,0.000000
99.710007,65.301468,-260.124603,0.000254,0.004730,0.120154,290.475433,14.797524,1.201538,-260.124603,294.500458,0.000000
100.110008,65.272049,-260.124603,0.000237,0.004730,0.120154,290.344574,14.790857,1.201538,-260.124603,294.500458,0.000000
100.510002,65.239288,-260.213562,0.000246,0.004730,0.120154,290.198853,14.783434,1.201538,-260.213562,294.500458,0.000000
100.910004,65.290298,-260.302521,0.000246,0.004732,0.120189,290.425751,14.794993,1.201886,-260.302521,294.500458,0.000000
101.310005,65.315247,-260.302521,0.000250,0.004733,0.120214,290.536713,14.800647,1.202143,-260.302521,294.500458,0.000000
101.710007,65.317108,-260.302521,0.000246,0.004733,0.120214,290.545013,14.801068,1.202143,-260.302521,294.500458,0.000000
102.110008,65.316360,-260.347015,0.000246,0.004733,0.120214,290.541687,14.800900,1.202143,-260.347015,294.500458,0.000000
102.510002,65.288437,-260.347015,0.000250,0.004733,0.120223,290.417480,14.794571,1.202234,-260.347015,294.500458,0.000000
102.910004,65.300720,-260.435974,0.000237,0.004735,0.120258,290.472107,14.797355,1.202582,-260.435974,294.500458,0.000000
103.310005,65.303696,-260.480438,0.000254,0.004735,0.120258,290.485352,14.798029,1.202582,-260.480438,294.500458,0.000000
103.710007,65.292160,-260.480438,0.000246,0.004735,0.120258,290.434021,14.795415,1.202582,-260.480438,294.500458,0.000000
104.110008,65.296997,-260.524933,0.000250,0.004735,0.120267,290.455536,14.796512,1.202666,-260.524933,294.500458,0.000000
104.510002,65.370361,-260.569397,0.000250,0.004737,0.120319,290.781891,14.813136,1.203188,-260.569397,294.500458,0.000000
104.910004,65.388229,-260.613892,0.000263,0.004737,0.120319,290.861359,14.817184,1.203188,-260.613892,294.500458,0.000000
105.310005,65.390472,-260.613892,0.000237,0.004737,0.120319,290.871338,14.817693,1.203188,-260.613892,294.500458,0.000000
105.710007,65.372223,-260.658386,0.000250,0.004737,0.120319,290.790161,14.813558,1.203188,-260.658386,294.500458,0.000000
106.110008,65.357697,-260.702850,0.000254,0.004737,0.120319,290.725555,14.810266,1.203188,-260.702850,294.500458,0.000000
106.510002,65.338699,-260.747345,0.000259,0.004737,0.120319,290.641052,14.805962,1.203188,-260.747345,294.500458,0.000000
106.910004,65.339447,-260.747345,0.000254,0.004738,0.120345,290.644379,14.806130,1.203445,-260.747345,294.500458,0.000000
107.310005,65.346161,-260.791809,0.000254,0.004738,0.120354,290.674255,14.807652,1.203536,-260.791809,294.500458,0.000000
107.710007,65.348022,-260.836304,0.000259,0.004738,0.120354,290.682526,14.808074,1.203536,-260.836304,294.500458,0.000000
108.110008,65.315613,-260.836304,0.000241,0.004739,0.120362,290.538361,14.800730,1.203619,-260.836304,294.500458,0.000000
108.510002,65.315247,-260.925262,0.000259,0.004739,0.120362,290.536713,14.800647,1.203619,-260.925262,294.500458,0.000000
108.910004,65.302582,-260.836304,0.000254,0.004739,0.120362,290.480377,14.797776,1.203619,-260.836304,294.500458,0.000000
109.310005,65.299973,-260.969727,0.000246,0.004739,0.120362,290.468781,14.797185,1.203619,-260.969727,294.500458,0.000000
109.710007,65.292526,-260.969727,0.000246,0.004739,0.120371,290.435669,14.795499,1.203710,-260.969727,294.500458,0.000000
110.110008,65.290665,-261.014221,0.000259,0.004740,0.120388,290.427368,14.795076,1.203877,-261.014221,294.500458,0.000000
110.510002,65.303329,-261.103180,0.000254,0.004740,0.120388,290.483704,14.797946,1.203877,-261.103180,294.500458,0.000000
110.910004,65.281738,-261.058716,0.000259,0.004740,0.120397,290.387665,14.793054,1.203968,-261.058716,294.500458,0.000000
111.310005,65.259384,-261.147675,0.000250,0.004740,0.120397,290.288239,14.787988,1.203968,-261.147675,294.500458,0.000000
111.710007,65.290298,-261.147675,0.000254,0.004741,0.120432,290.425751,14.794993,1.204316,-261.147675,294.500458,0.000000
112.110008,65.376694,-261.192139,0.000259,0.004742,0.120457,290.810059,14.814571,1.204573,-261.192139,294.500458,0.000000
112.510002,65.390091,-261.192139,0.000254,0.004742,0.120457,290.869659,14.817606,1.204573,-261.192139,294.500458,0.000000
112.910004,65.400513,-261.236633,0.000246,0.004742,0.120457,290.916016,14.819968,1.204573,-261.236633,294.500458,0.000000
113.310005,65.366257,-261.281097,0.000241,0.004742,0.120457,290.763641,14.812205,1.204573,-261.281097,294.500458,0.000000
113.710007,65.364395,-261.325592,0.000250,0.004742,0.120457,290.755341,14.811783,1.204573,-261.325592,294.500458,0.000000
114.110008,65.349136,-261.414551,0.000246,0.004742,0.120457,290.687469,14.808326,1.204573,-261.414551,294.500458,0.000000
114.510002,65.330887,-261.414551,0.000259,0.004742,0.120457,290.606293,14.804191,1.204573,-261.414551,294.500458,0.000000
114.910004,65.332382,-261.325592,0.000241,0.004742,0.120457,290.612946,14.804529,1.204573,-261.325592,294.500458,0.000000
115.310005,65.291412,-261.503510,0.000254,0.004743,0.120466,290.430695,14.795246,1.204664,-261.503510,294.500458,0.000000
115.710007,65.290665,-261.459045,0.000241,0.004743,0.120475,290.427368,14.795076,1.204747,-261.459045,294.500458,0.000000
116.110008,65.300720,-261.548004,0.000259,0.004743,0.120475,290.472107,14.797355,1.204747,-261.548004,294.500458,0.000000
116.510002,65.282852,-261.548004,0.000254,0.004743,0.120483,290.392639,14.793305,1.204831,-261.548004,294.500458,0.000000
116.910004,65.284714,-261.636963,0.000254,0.004743,0.120483,290.400909,14.793728,1.204831,-261.636963,294.500458,0.000000
117.310005,65.278015,-261.681427,0.000254,0.004743,0.120483,290.371124,14.792210,1.204831,-261.681427,294.500458,0.000000
117.710007,65.259384,-261.636963,0.000254,0.004743,0.120483,290.288239,14.787988,1.204831,-261.636963,294.500458,0.000000
118.110008,65.253799,-261.681427,0.000246,0.004744,0.120510,290.263397,14.786722,1.205095,-261.681427,294.500458,0.000000
118.510002,65.272430,-261.725922,0.000259,0.004744,0.120510,290.346283,14.790944,1.205095,-261.725922,294.500458,0.000000
118.910004,65.266846,-261.770386,0.000250,0.004744,0.120510,290.321442,14.789679,1.205095,-261.770386,294.500458,0.000000
119.310005,65.264603,-261.814880,0.000259,0.004744,0.120510,290.311462,14.789170,1.205095,-261.814880,294.500458,0.000000
119.710007,65.272430,-261.903839,0.000241,0.004744,0.120510,290.346283,14.790944,1.205095,-261.903839,294.500458,0.000000
120.110008,65.241516,-261.903839,0.000263,0.004745,0.120518,290.208771,14.783938,1.205179,-261.903839,294.500458,0.000000
120.510002,65.262375,-261.903839,0.000250,0.004747,0.120562,290.301544,14.788666,1.205618,-261.903839,294.500458,0.000000
120.910004,65.315613,-261.948334,0.000241,0.004747,0.120562,290.538361,14.800730,1.205618,-261.948334,294.500458,0.000000
121.310005,65.316742,-261.948334,0.000250,0.004747,0.120562,290.543365,14.800985,1.205618,-261.948334,294.500458,0.000000
121.710007,65.323807,-262.037292,0.000250,0.004747,0.120562,290.574799,14.802586,1.205618,-262.037292,294.500458,0.000000
122.110008,65.326050,-262.081757,0.000267,0.004747,0.120562,290.584778,14.803094,1.205618,-262.081757,294.500458,0.000000
122.510002,65.315613,-262.081757,0.000263,0.004747,0.120562,290.538361,14.800730,1.205618,-262.081757,294.500458,0.000000
122.910004,65.299606,-262.037292,0.000250,0.004747,0.120562,290.467163,14.797102,1.205618,-262.037292,294.500458,0.000000
123.310005,65.307800,-262.126251,0.000246,0.004747,0.120570,290.503601,14.798959,1.205701,-262.126251,294.500458,0.000000
123.710007,65.325302,-262.170715,0.000254,0.004748,0.120588,290.581451,14.802925,1.205875,-262.170715,294.500458,0.000000
124.110008,65.308914,-262.215210,0.000263,0.004748,0.120588,290.508545,14.799212,1.205875,-262.215210,294.500458,0.000000
124.510002,65.318970,-262.215210,0.000272,0.004748,0.120588,290.553284,14.801490,1.205875,-262.215210,294.500458,0.000000
124.910004,65.317108,-262.215210,0.000250,0.004748,0.120588,290.545013,14.801068,1.205875,-262.215210,294.500458,0.000000
125.310005,65.294769,-262.348663,0.000267,0.004748,0.120588,290.445648,14.796006,1.205875,-262.348663,294.500458,0.000000
125.710007,65.302582,-262.304169,0.000250,0.004748,0.120588,290.480377,14.797776,1.205875,-262.304169,294.500458,0.000000
126.110008,65.302216,-262.348663,0.000254,0.004748,0.120588,290.478760,14.797693,1.205875,-262.348663,294.500458,0.000000
126.510010,65.283966,-262.393127,0.000246,0.004748,0.120588,290.397583,14.793558,1.205875,-262.393127,294.500458,0.000000
126.910004,65.272797,-262.482086,0.000259,0.004748,0.120588,290.347900,14.791027,1.205875,-262.482086,294.500458,0.000000
127.310005,65.271683,-262.526581,0.000246,0.004748,0.120588,290.342957,14.790774,1.205875,-262.526581,294.500458,0.000000
127.710007,65.238907,-262.571045,0.000250,0.004748,0.120588,290.197144,14.783348,1.205875,-262.571045,294.500458,0.000000
128.110001,65.252686,-262.571045,0.000254,0.004748,0.120588,290.258453,14.786469,1.205875,-262.571045,294.500458,0.000000
128.510010,65.228119,-262.571045,0.000259,0.004748,0.120588,290.149170,14.780903,1.205875,-262.571045,294.500458,0.000000
128.910004,65.218796,-262.615540,0.000254,0.004748,0.120588,290.107697,14.778790,1.205875,-262.615540,294.500458,0.000000
129.310013,65.206512,-262.660004,0.000259,0.004748,0.120588,290.053040,14.776007,1.205875,-262.660004,294.500458,0.000000
129.710007,65.215454,-262.704498,0.000263,0.004748,0.120588,290.092834,14.778033,1.205875,-262.704498,294.500458,0.000000
130.110001,65.190125,-262.793457,0.000259,0.004748,0.120588,289.980164,14.772293,1.205875,-262.793457,294.500458,0.000000
130.510010,65.161453,-262.793457,0.000250,0.004748,0.120596,289.852631,14.765797,1.205958,-262.793457,294.500458,0.000000
130.910004,65.165924,-262.793457,0.000250,0.004748,0.120596,289.872498,14.766809,1.205958,-262.793457,294.500458,0.000000
131.310013,65.175613,-262.882416,0.000254,0.004749,0.120622,289.915619,14.769006,1.206223,-262.882416,294.500458,0.000000
131.710007,65.177094,-262.926910,0.000250,0.004749,0.120622,289.922180,14.769341,1.206223,-262.926910,294.500458,0.000000
132.110001,65.194229,-262.926910,0.000246,0.004749,0.120622,289.998413,14.773223,1.206223,-262.926910,294.500458,0.000000
132.510010,65.180069,-262.971375,0.000259,0.004749,0.120622,289.935425,14.770015,1.206223,-262.971375,294.500458,0.000000
132.910004,65.172623,-262.971375,0.000263,0.004749,0.120622,289.902313,14.768328,1.206223,-262.971375,294.500458,0.000000
133.310013,65.171509,-263.060333,0.000259,0.004749,0.120622,289.897339,14.768075,1.206223,-263.060333,294.500458,0.000000
133.710007,65.151779,-263.015869,0.000254,0.004749,0.120622,289.809601,14.763604,1.206223,-263.015869,294.500458,0.000000
134.110001,65.121979,-263.060333,0.000263,0.004750,0.120640,289.677032,14.756851,1.206397,-263.060333,294.500458,0.000000
134.510010,65.617981,-263.060333,0.000259,0.004756,0.120796,291.883362,14.869246,1.207957,-263.060333,294.500458,0.000000
134.910004,65.687241,-263.149292,0.000267,0.004756,0.120796,292.191437,14.884942,1.207957,-263.149292,294.500458,0.000000
135.310013,65.690964,-263.193787,0.000267,0.004755,0.120787,292.208008,14.885785,1.207866,-263.193787,294.500458,0.000000
135.710007,65.753906,-263.193787,0.000254,0.004755,0.120787,292.487976,14.900048,1.207866,-263.193787,294.500458,0.000000
136.110001,65.771408,-263.282745,0.000254,0.004754,0.120753,292.565826,14.904015,1.207525,-263.282745,294.500458,0.000000
136.510010,65.745331,-263.282745,0.000250,0.004754,0.120753,292.449829,14.898106,1.207525,-263.282745,294.500458,0.000000
136.910004,65.744598,-263.327240,0.000254,0.004754,0.120753,292.446594,14.897939,1.207525,-263.327240,294.500458,0.000000
137.310013,65.677185,-263.282745,0.000241,0.004754,0.120753,292.146698,14.882663,1.207525,-263.282745,294.500458,0.000000
137.710007,65.655960,-263.416199,0.000259,0.004754,0.120753,292.052307,14.877853,1.207525,-263.416199,294.500458,0.000000
138.110001,65.642929,-263.416199,0.000254,0.004754,0.120753,291.994324,14.874900,1.207525,-263.416199,294.500458,0.000000
138.510010,65.627289,-263.460663,0.000246,0.004754,0.120753,291.924774,14.871357,1.207525,-263.460663,294.500458,0.000000
138.910004,65.610916,-263.505157,0.000254,0.004754,0.120753,291.851929,14.867646,1.207525,-263.505157,294.500458,0.000000
139.310013,65.603470,-263.549622,0.000254,0.004754,0.120753,291.818817,14.865958,1.207525,-263.549622,294.500458,0.000000
139.710007,65.599747,-263.505157,0.000250,0.004754,0.120753,291.802246,14.865115,1.207525,-263.505157,294.500458,0.000000
140.110001,65.591919,-263.638611,0.000259,0.004754,0.120753,291.767426,14.863341,1.207525,-263.638611,294.500458,0.000000
140.510010,65.582977,-263.638611,0.000254,0.004754,0.120753,291.727661,14.861315,1.207525,-263.638611,294.500458,0.000000
140.910004,65.582611,-263.638611,0.000263,0.004754,0.120753,291.726013,14.861233,1.207525,-263.638611,294.500458,0.000000
141.310013,65.565475,-263.683075,0.000246,0.004754,0.120753,291.649811,14.857348,1.207525,-263.683075,294.500458,0.000000
141.710007,65.561752,-263.772034,0.000259,0.004754,0.120753,291.633240,14.856505,1.207525,-263.772034,294.500458,0.000000
142.110001,65.567337,-263.772034,0.000259,0.004754,0.120753,291.658081,14.857771,1.207525,-263.772034,294.500458,0.000000
142.510010,65.562881,-263.816528,0.000263,0.004754,0.120753,291.638275,14.856761,1.207525,-263.816528,294.500458,0.000000
142.910004,65.536057,-263.860992,0.000263,0.004754,0.120753,291.518951,14.850682,1.207525,-263.860992,294.500458,0.000000
143.310013,65.516327,-263.905487,0.000259,0.004754,0.120753,291.431183,14.846212,1.207525,-263.905487,294.500458,0.000000
143.710007,65.528610,-263.949951,0.000272,0.004754,0.120753,291.485809,14.848995,1.207525,-263.949951,294.500458,0.000000
144.110001,65.528244,-263.949951,0.000272,0.004754,0.120753,291.484192,14.848912,1.207525,-263.949951,294.500458,0.000000
144.510010,65.503296,-263.949951,0.000263,0.004754,0.120753,291.373199,14.843259,1.207525,-263.949951,294.500458,0.000000
144.910004,65.473511,-263.994446,0.000250,0.004753,0.120735,291.240723,14.836510,1.207351,-263.994446,0.120753,0.000000
145.310013,65.372971,-264.038940,0.000263,0.004740,0.120405,290.793488,14.813726,1.204051,-264.038940,0.120154,0.000000
145.710007,65.310776,-264.083405,0.000250,0.004720,0.119893,290.516846,14.799634,1.198934,-264.083405,0.119486,0.000000
146.110001,65.278015,-264.083405,0.000241,0.004694,0.119235,290.371124,14.792210,1.192348,-264.083405,0.118818,0.000000
146.510010,65.211349,-264.083405,0.000267,0.004670,0.118628,290.074585,14.777102,1.186277,-264.083405,0.118151,0.000000
146.910004,65.203156,-264.172363,0.000272,0.004649,0.118081,290.038116,14.775247,1.180812,-264.172363,0.117491,0.000000
147.310013,65.162567,-264.172363,0.000272,0.004626,0.117509,289.857574,14.766049,1.175089,-264.172363,0.116824,0.000000
147.710007,65.128693,-264.261322,0.000259,0.004602,0.116884,289.706879,14.758373,1.168844,-264.261322,0.116156,0.000000
148.110001,65.127945,-264.216858,0.000254,0.004571,0.116112,289.703583,14.758204,1.161123,-264.216858,0.115488,0.000000
148.510010,65.048630,-264.261322,0.000267,0.004544,0.115427,289.350769,14.740230,1.154272,-264.261322,0.114820,0.000000
148.910004,64.698593,-264.261322,0.000259,0.004523,0.114872,287.793701,14.660911,1.148723,-264.261322,0.114152,0.000000
149.310013,63.931137,-264.394775,0.000280,0.004499,0.114274,284.379913,14.487003,1.142743,-264.394775,0.113485,0.000000
149.710007,62.948074,-264.350281,0.000297,0.004480,0.113797,280.007019,14.264237,1.137974,-264.350281,0.112817,0.000000
150.110001,61.133133,-264.439240,0.000297,0.004444,0.112878,271.933746,13.852965,1.128777,-264.439240,0.112158,0.000000
150.510010,59.630981,-264.439240,0.000306,0.004423,0.112349,265.251862,13.512573,1.123486,-264.439240,0.111490,0.000000
150.910004,57.909134,-264.483734,0.000297,0.004400,0.111768,257.592682,13.122397,1.117679,-264.483734,0.110822,0.000000
151.310013,56.368629,-264.572693,0.000297,0.004383,0.111317,250.740189,12.773314,1.113168,-264.572693,0.110155,0.000000
151.710007,53.248886,-264.572693,0.000297,0.004346,0.110380,236.862869,12.066370,1.103804,-264.572693,0.109487,0.000000
152.110001,50.764046,-264.572693,0.000297,0.004323,0.109799,225.809753,11.503298,1.097991,-264.572693,0.108820,0.000000
152.510010,47.849113,-264.617187,0.000293,0.004296,0.109123,212.843491,10.842764,1.091231,-264.617187,0.108151,0.000000
152.910004,44.702568,-264.661652,0.000297,0.004269,0.108429,198.846954,10.129747,1.084289,-264.661652,0.107483,0.000000
153.310013,42.343216,-264.661652,0.000302,0.004244,0.107796,188.352036,9.595109,1.077961,-264.661652,0.106825,0.000000
153.710007,39.090172,-264.706146,0.000306,0.004216,0.107085,173.881775,8.857960,1.070845,-264.706146,0.106156,0.000000
154.110001,36.475746,-264.795105,0.000306,0.004191,0.106460,162.252228,8.265522,1.064600,-264.795105,0.105489,0.000000
154.510010,33.690399,-264.750610,0.000285,0.004167,0.105845,149.862381,7.634354,1.058446,-264.750610,0.104821,0.000000
154.910004,30.567307,-264.795105,0.000289,0.004139,0.105125,135.970169,6.926651,1.051247,-264.795105,0.104153,0.000000
155.310013,28.735237,-264.884064,0.000306,0.004118,0.104605,127.820717,6.511497,1.046047,-264.884064,0.103486,0.000000
155.710007,25.041306,-264.928558,0.000310,0.004089,0.103867,111.389290,5.674441,1.038674,-264.928558,0.102818,0.000000
156.110001,22.064926,-264.884064,0.000306,0.004061,0.103139,98.149696,4.999984,1.031392,-264.884064,0.102151,0.000000
156.510010,19.252769,-264.928558,0.000302,0.004034,0.102462,85.640594,4.362740,1.024624,-264.928558,0.101491,0.000000
156.910004,16.338211,-265.017517,0.000310,0.004011,0.101890,72.675995,3.702291,1.018901,-265.017517,0.100824,0.000000
157.310013,13.356628,-265.017517,0.000289,0.003984,0.101205,59.413250,3.026655,1.012051,-265.017517,0.100156,0.000000
157.710007,10.102463,-265.061981,0.000306,0.003954,0.100442,44.938000,2.289251,1.004420,-265.061981,0.099487,0.000000
158.110001,7.028900,-265.061981,0.000306,0.003926,0.099730,31.266109,1.592772,0.997305,-265.061981,0.098820,0.000000
158.510010,5.129799,-265.106476,0.000302,0.003910,0.099323,22.818485,1.162429,0.993232,-265.106476,0.098152,0.000000
158.910004,2.502342,-265.106476,0.000293,0.003885,0.098673,11.130974,0.567039,0.986730,-265.106476,0.097485,0.000000
159.310013,-0.506798,-265.150940,0.000302,0.003854,0.097893,-2.254349,-0.114842,0.978925,-265.150940,0.096817,0.000000
159.710007,-0.289337,-265.195435,0.000293,0.003836,0.097432,-1.287036,-0.065565,0.974323,-265.195435,0.096149,0.000000
160.110001,0.019363,-265.239899,0.000285,0.003803,0.096609,0.086133,0.004388,0.966087,-265.239899,0.095490,0.000000
160.510010,0.035004,-265.328888,0.000280,0.003783,0.096097,0.155704,0.007932,0.960970,-265.328888,0.094822,0.000000
160.910004,0.114319,-265.328888,0.000207,0.003753,0.095334,0.508516,0.025905,0.953339,-265.328888,0.094155,0.000000
161.310013,0.090858,-265.417847,0.000142,0.003723,0.094553,0.404159,0.020589,0.945535,-265.417847,0.093487,0.000000
161.710007,0.102402,-265.373352,0.000073,0.003694,0.093825,0.455506,0.023205,0.938245,-265.373352,0.092819,0.000000
162.110001,0.075218,-265.417847,0.000026,0.003667,0.093139,0.334587,0.017045,0.931395,-265.417847,0.092151,0.000000
162.510010,0.122139,-265.417847,-0.000047,0.003638,0.092411,0.543301,0.027677,0.924112,-265.417847,0.091483,0.000000
162.910004,0.120651,-265.506805,-0.000082,0.003619,0.091934,0.536684,0.027340,0.919343,-265.506805,0.090816,0.000000
163.310013,0.106125,-265.551270,-0.000155,0.003594,0.091275,0.472067,0.024048,0.912750,-265.551270,0.090156,0.000000
163.710007,0.125488,-265.595764,-0.000241,0.003567,0.090590,0.558200,0.028436,0.905899,-265.595764,0.089489,0.000000
164.110001,0.100540,-265.595764,-0.000319,0.003536,0.089819,0.447225,0.022783,0.898186,-265.595764,0.088821,0.000000
164.510010,0.109474,-265.595764,-0.000392,0.003509,0.089134,0.486965,0.024807,0.891335,-265.595764,0.088153,0.000000
164.910004,0.075592,-265.684723,-0.000457,0.003484,0.088492,0.336250,0.017129,0.884916,-265.684723,0.087486,0.000000
165.300003,0.140015,-265.773682,-0.000509,0.003476,0.088292,0.622816,0.031728,0.882918,-265.773682,0.088223,0.000000