File: Data/compression 21/AutoNoHeating-10-21-reverse-1-2_09132024_162918.csv
Time (sec),S:Load (lbs),S:HL1 (DIM),S:LVDT (in),S:Position (in),Ch:Position (mm),Ch:Load (N),Ch:Stress (MPa),Ch:Strain (mm/mm),Ch:HL1 (DIM),Set Point (),Cycles ()
0.110000,0.020111,-211.151077,-0.009791,-0.004486,-0.113945,0.089459,0.004557,-1.139450,-211.151077,-0.113728,0.000000
0.520000,0.017128,-211.195557,-0.009800,-0.004433,-0.112601,0.076189,0.003881,-1.126006,-211.195557,-0.111855,0.000000
0.930000,0.023460,-211.240036,-0.009658,-0.004190,-0.106418,0.104357,0.005316,-1.064176,-211.240036,-0.105021,0.000000
1.340000,-0.009308,-211.240036,-0.009390,-0.003915,-0.099436,-0.041403,-0.002109,-0.994360,-211.240036,-0.098188,0.000000
1.750000,-0.057343,-211.284515,-0.009115,-0.003640,-0.092446,-0.255072,-0.012994,-0.924461,-211.284515,-0.091371,0.000000
2.160000,-0.037239,-211.328995,-0.008821,-0.003371,-0.085630,-0.165648,-0.008438,-0.856302,-211.328995,-0.084537,0.000000
2.570000,0.004097,-211.373474,-0.008558,-0.003104,-0.078848,0.018224,0.000928,-0.788484,-211.373474,-0.077704,0.000000
2.980000,0.005585,-211.417953,-0.008274,-0.002832,-0.071928,0.024842,0.001266,-0.719281,-211.417953,-0.070870,0.000000
3.390000,-0.001862,-211.373474,-0.007998,-0.002577,-0.065458,-0.008281,-0.000422,-0.654582,-211.373474,-0.064036,0.000000
3.800000,0.002975,-211.462448,-0.007731,-0.002303,-0.058495,0.013236,0.000674,-0.584948,-211.462448,-0.057220,0.000000
4.210000,0.005959,-211.462448,-0.007463,-0.002037,-0.051730,0.026505,0.001350,-0.517304,-211.462448,-0.050386,0.000000
4.620000,0.020111,-211.551407,-0.007166,-0.001760,-0.044714,0.089459,0.004557,-0.447140,-211.551407,-0.043552,0.000000
5.030000,0.036491,-211.640366,-0.006907,-0.001494,-0.037950,0.162322,0.008269,-0.379496,-211.640366,-0.036719,0.000000
5.440000,0.001862,-211.640366,-0.006618,-0.001225,-0.031116,0.008281,0.000422,-0.311164,-211.640366,-0.029885,0.000000
5.850000,-0.031281,-211.729324,-0.006334,-0.000954,-0.024239,-0.139143,-0.007088,-0.242392,-211.729324,-0.023051,0.000000
6.260000,-0.048782,-211.684845,-0.006071,-0.000686,-0.017423,-0.216995,-0.011054,-0.174226,-211.684845,-0.016235,0.000000
6.670001,0.021973,-211.773804,-0.005777,-0.000414,-0.010528,0.097739,0.004979,-0.105281,-211.773804,-0.009401,0.000000
7.080000,0.035004,-211.862762,-0.005501,-0.000149,-0.003781,0.155704,0.007932,-0.037811,-211.862762,-0.002567,0.000000
7.490000,0.102402,-211.862762,-0.005230,0.000121,0.003079,0.455506,0.023205,0.030786,-211.862762,0.004266,0.000000
7.900001,0.125862,-211.862762,-0.005178,-0.000000,-0.000009,0.559863,0.028521,-0.000091,-211.862762,0.000156,0.000000
8.310000,0.112831,-211.907257,-0.005195,-0.000000,-0.000009,0.501898,0.025568,-0.000091,-211.907257,0.000503,0.000000
8.720000,0.133308,-211.951736,-0.005174,-0.000000,-0.000009,0.592985,0.030208,-0.000091,-211.951736,0.001179,0.000000
9.130000,0.163841,-212.085175,-0.005161,0.000034,0.000858,0.728802,0.037127,0.008584,-212.085175,0.001864,0.000000
9.540001,0.245392,-212.040695,-0.005152,0.000058,0.001483,1.091558,0.055607,0.014829,-212.040695,0.002550,0.000000
9.950001,0.367905,-212.085175,-0.005122,0.000087,0.002211,1.636522,0.083368,0.022111,-212.085175,0.003235,0.000000
10.360001,0.443123,-212.174133,-0.005092,0.000113,0.002879,1.971109,0.100413,0.028788,-212.174133,0.003920,0.000000
10.770000,0.570847,-212.218613,-0.005075,0.000143,0.003624,2.539252,0.129356,0.036244,-212.218613,0.004596,0.000000
11.180000,0.630051,-212.263092,-0.005040,0.000159,0.004041,2.802605,0.142772,0.040408,-212.263092,0.005281,0.000000
11.590000,0.747726,-212.263092,-0.005023,0.000182,0.004630,3.326053,0.169437,0.046304,-212.263092,0.005967,0.000000
12.000001,0.986786,-212.307587,-0.004980,0.000222,0.005646,4.389443,0.223609,0.056455,-212.307587,0.006652,0.000000
12.410001,1.176697,-212.352066,-0.004945,0.000255,0.006487,5.234209,0.266643,0.064866,-212.352066,0.007337,0.000000
12.820001,1.260849,-212.396545,-0.004928,0.000278,0.007067,5.608536,0.285712,0.070672,-212.396545,0.008013,0.000000
13.230000,1.368095,-212.441025,-0.004911,0.000299,0.007596,6.085592,0.310015,0.075963,-212.441025,0.008698,0.000000
13.640000,1.608276,-212.441025,-0.004876,0.000329,0.008359,7.153971,0.364441,0.083593,-212.441025,0.009383,0.000000
14.050000,1.823135,-212.529984,-0.004842,0.000361,0.009166,8.109712,0.413128,0.091663,-212.529984,0.010068,0.000000
14.460001,1.934105,-212.663422,-0.004829,0.000388,0.009851,8.603329,0.438274,0.098513,-212.663422,0.010753,0.000000
14.870001,2.033524,-212.574463,-0.004794,0.000413,0.010502,9.045565,0.460803,0.105016,-212.574463,0.011430,0.000000
15.280001,2.308708,-212.707901,-0.004773,0.000442,0.011221,10.269647,0.523161,0.112215,-212.707901,0.012115,0.000000
15.690001,2.362328,-212.663422,-0.004760,0.000462,0.011733,10.508158,0.535311,0.117332,-212.663422,0.012800,0.000000
16.100000,2.469200,-212.707901,-0.004725,0.000487,0.012366,10.983551,0.559529,0.123660,-212.707901,0.013485,0.000000
16.510000,2.703796,-212.841354,-0.004691,0.000520,0.013199,12.027087,0.612689,0.131987,-212.841354,0.014170,0.000000
16.920000,2.774918,-212.841354,-0.004665,0.000545,0.013849,12.343450,0.628805,0.138489,-212.841354,0.014847,0.000000
17.330000,3.023293,-212.930313,-0.004631,0.000571,0.014508,13.448277,0.685088,0.145083,-212.930313,0.015532,0.000000
17.740002,3.166656,-212.885834,-0.004613,0.000595,0.015107,14.085992,0.717575,0.151070,-212.885834,0.016217,0.000000
18.150002,3.390450,-212.930313,-0.004592,0.000625,0.015870,15.081472,0.768287,0.158701,-212.930313,0.016902,0.000000
18.560001,3.539772,-213.019272,-0.004549,0.000659,0.016728,15.745692,0.802124,0.167285,-213.019272,0.017587,0.000000
18.970001,3.514450,-213.063751,-0.004540,0.000678,0.017214,15.633055,0.796386,0.172137,-213.063751,0.018264,0.000000
19.380001,3.723351,-213.108231,-0.004501,0.000700,0.017769,16.562290,0.843723,0.177693,-213.108231,0.018949,0.000000
19.790001,3.984009,-213.197205,-0.004480,0.000729,0.018523,17.721756,0.902789,0.185233,-213.197205,0.019634,0.000000
20.200001,4.265900,-213.197205,-0.004454,0.000764,0.019408,18.975670,0.966667,0.194082,-213.197205,0.020319,0.000000
20.610001,4.342979,-213.241684,-0.004432,0.000790,0.020068,19.318537,0.984133,0.200675,-213.241684,0.021004,0.000000
21.020000,4.541824,-213.330643,-0.004411,0.000819,0.020796,20.203043,1.029192,0.207957,-213.330643,0.021681,0.000000
21.430000,4.519485,-213.375122,-0.004385,0.000837,0.021255,20.103676,1.024130,0.212552,-213.375122,0.022366,0.000000
21.840000,4.880684,-213.330643,-0.004368,0.000868,0.022053,21.710367,1.105979,0.220531,-213.330643,0.023051,0.000000
22.250002,4.978622,-213.419601,-0.004324,0.000897,0.022773,22.146019,1.128172,0.227730,-213.419601,0.023736,0.000000
22.660002,5.119751,-213.464081,-0.004299,0.000924,0.023475,22.773790,1.160152,0.234754,-213.464081,0.024421,0.000000
23.070002,5.311890,-213.419601,-0.004277,0.000953,0.024204,23.628466,1.203691,0.242036,-213.419601,0.025097,0.000000
23.480001,5.285080,-213.553040,-0.004247,0.000972,0.024681,23.509211,1.197616,0.246805,-213.553040,0.025782,0.000000
23.890001,5.622078,-213.597534,-0.004230,0.001002,0.025453,25.008251,1.273981,0.254527,-213.597534,0.026467,0.000000
24.300001,5.755013,-213.597534,-0.004195,0.001030,0.026173,25.599575,1.304104,0.261725,-213.597534,0.027153,0.000000
24.710001,5.843269,-213.686493,-0.004174,0.001059,0.026892,25.992161,1.324104,0.268924,-213.686493,0.027838,0.000000
25.120001,6.083076,-213.730972,-0.004143,0.001087,0.027621,27.058876,1.378445,0.276206,-213.730972,0.028514,0.000000
25.530001,6.184731,-213.730972,-0.004122,0.001110,0.028185,27.511055,1.401480,0.281846,-213.730972,0.029199,0.000000
25.940001,6.459915,-213.819931,-0.004092,0.001138,0.028895,28.735138,1.463838,0.288954,-213.819931,0.029884,0.000000
26.350000,6.630463,-213.775452,-0.004057,0.001168,0.029658,29.493771,1.502484,0.296584,-213.775452,0.030569,0.000000
26.760002,6.761909,-213.908890,-0.004031,0.001196,0.030387,30.078476,1.532271,0.303874,-213.908890,0.031254,0.000000
27.170002,6.672173,-213.908890,-0.004018,0.001217,0.030907,29.679306,1.511936,0.309075,-213.908890,0.031931,0.000000
27.580002,6.885910,-213.953369,-0.004001,0.001242,0.031540,30.630058,1.560369,0.315403,-213.953369,0.032616,0.000000
27.990002,6.840485,-214.042343,-0.003975,0.001258,0.031948,30.427996,1.550076,0.319483,-214.042343,0.033301,0.000000
28.400002,7.140984,-214.086823,-0.003936,0.001289,0.032737,31.764681,1.618170,0.327371,-214.086823,0.033986,0.000000
28.810001,7.616508,-214.131302,-0.003919,0.001332,0.033821,33.879921,1.725925,0.338211,-214.131302,0.034671,0.000000
29.220001,7.436279,-214.175781,-0.003885,0.001351,0.034324,33.078224,1.685085,0.343245,-214.175781,0.035348,0.000000
29.630001,7.568100,-214.220261,-0.003876,0.001377,0.034975,33.664589,1.714956,0.349747,-214.220261,0.036033,0.000000
30.040001,7.903976,-214.220261,-0.003846,0.001407,0.035729,35.158642,1.791067,0.357294,-214.220261,0.036718,0.000000
30.450001,8.052925,-214.309219,-0.003807,0.001434,0.036423,35.821201,1.824819,0.364228,-214.309219,0.037403,0.000000
30.860001,8.090912,-214.309219,-0.003786,0.001458,0.037022,35.990173,1.833427,0.370216,-214.309219,0.038088,0.000000
31.270002,8.449875,-214.398178,-0.003781,0.001487,0.037759,37.586922,1.914769,0.377589,-214.398178,0.038765,0.000000
31.680002,8.377632,-214.398178,-0.003738,0.001507,0.038288,37.265568,1.898399,0.382880,-214.398178,0.039450,0.000000
32.090000,8.674416,-214.531631,-0.003717,0.001540,0.039120,38.585728,1.965651,0.391199,-214.531631,0.040135,0.000000
32.500000,8.537758,-214.442657,-0.003673,0.001560,0.039632,37.977844,1.934684,0.396316,-214.442657,0.040820,0.000000
32.910000,8.548180,-214.531631,-0.003669,0.001580,0.040143,38.024200,1.937045,0.401434,-214.531631,0.041505,0.000000
33.320000,9.128342,-214.620590,-0.003639,0.001620,0.041149,40.604893,2.068512,0.411494,-214.620590,0.042181,0.000000
33.730003,9.444481,-214.620590,-0.003626,0.001655,0.042025,42.011150,2.140150,0.420252,-214.620590,0.042867,0.000000
34.140003,9.264999,-214.754028,-0.003596,0.001677,0.042597,41.212776,2.099479,0.425975,-214.754028,0.043552,0.000000
34.550003,9.203186,-214.709549,-0.003574,0.001698,0.043118,40.937817,2.085472,0.431183,-214.709549,0.044237,0.000000
34.960003,9.636627,-214.798508,-0.003535,0.001729,0.043907,42.865860,2.183691,0.439071,-214.798508,0.044922,0.000000
35.370003,10.018684,-214.798508,-0.003510,0.001760,0.044697,44.565334,2.270266,0.446966,-214.798508,0.045598,0.000000
35.780003,10.016449,-214.798508,-0.003501,0.001788,0.045425,44.555389,2.269760,0.454248,-214.798508,0.046283,0.000000
36.190002,9.977722,-214.931961,-0.003479,0.001812,0.046014,44.383125,2.260984,0.460145,-214.931961,0.046968,0.000000
36.600002,10.285301,-214.931961,-0.003445,0.001841,0.046752,45.751305,2.330683,0.467518,-214.931961,0.047653,0.000000
37.010002,10.230560,-214.976440,-0.003419,0.001861,0.047281,45.507805,2.318278,0.472809,-214.976440,0.048339,0.000000
37.420002,10.316208,-215.065399,-0.003402,0.001885,0.047879,45.888786,2.337686,0.478789,-215.065399,0.049015,0.000000
37.830002,10.754860,-215.020920,-0.003389,0.001918,0.048721,47.840008,2.437086,0.487207,-215.020920,0.049700,0.000000
38.240002,10.699379,-215.109879,-0.003359,0.001943,0.049362,47.593216,2.424514,0.493618,-215.109879,0.050385,0.000000
38.650002,10.898224,-215.154358,-0.003333,0.001970,0.050039,48.477722,2.469573,0.500386,-215.154358,0.051070,0.000000
39.060001,10.979027,-215.243317,-0.003311,0.001994,0.050637,48.837151,2.487883,0.506366,-215.243317,0.051755,0.000000
39.470001,11.349541,-215.243317,-0.003290,0.002023,0.051391,50.485279,2.571843,0.513913,-215.243317,0.052432,0.000000
39.880001,11.602005,-215.243317,-0.003277,0.002059,0.052294,51.608295,2.629052,0.522936,-215.243317,0.053117,0.000000
40.290001,11.278046,-215.287796,-0.003238,0.002079,0.052805,50.167252,2.555642,0.528053,-215.287796,0.053802,0.000000
40.700001,11.684677,-215.376770,-0.003225,0.002108,0.053551,51.976040,2.647786,0.535510,-215.376770,0.054487,0.000000
41.110001,11.674622,-215.421249,-0.003208,0.002129,0.054071,51.931309,2.645507,0.540710,-215.421249,0.055172,0.000000
41.520000,12.171738,-215.465729,-0.003195,0.002163,0.054929,54.142593,2.758155,0.549294,-215.465729,0.055849,0.000000
41.930000,12.193336,-215.510208,-0.003152,0.002189,0.055589,54.238670,2.763050,0.555888,-215.510208,0.056534,0.000000
42.340000,12.340797,-215.554687,-0.003130,0.002217,0.056317,54.894608,2.796465,0.563170,-215.554687,0.057219,0.000000
42.750004,12.124817,-215.554687,-0.003126,0.002238,0.056846,53.933880,2.747523,0.568461,-215.554687,0.057904,0.000000
43.160004,12.599968,-215.643646,-0.003091,0.002267,0.057583,56.047455,2.855194,0.575834,-215.643646,0.058589,0.000000
43.570004,12.696037,-215.688126,-0.003074,0.002296,0.058312,56.474796,2.876963,0.583116,-215.688126,0.059266,0.000000
43.980003,12.786156,-215.643646,-0.003057,0.002323,0.059006,56.875660,2.897384,0.590058,-215.643646,0.059951,0.000000
44.390003,13.015907,-215.732620,-0.003027,0.002351,0.059717,57.897648,2.949447,0.597166,-215.732620,0.060636,0.000000
44.800003,12.823761,-215.821579,-0.003031,0.002373,0.060272,57.042938,2.905906,0.602722,-215.821579,0.061321,0.000000
45.210003,12.968613,-215.777100,-0.003001,0.002395,0.060835,57.687271,2.938730,0.608354,-215.777100,0.062006,0.000000
45.620003,13.371147,-215.910538,-0.002992,0.002429,0.061694,59.477833,3.029945,0.616938,-215.910538,0.062682,0.000000
46.030003,13.416954,-215.910538,-0.002966,0.002458,0.062440,59.681591,3.040325,0.624402,-215.910538,0.063367,0.000000
46.440002,13.561432,-215.955017,-0.002928,0.002486,0.063143,60.324261,3.073064,0.631426,-215.955017,0.064053,0.000000
46.850002,13.583031,-215.999496,-0.002928,0.002508,0.063715,60.420338,3.077959,0.637149,-215.999496,0.064738,0.000000
47.260002,13.896942,-216.043976,-0.002906,0.002536,0.064426,61.816685,3.149092,0.644257,-216.043976,0.065423,0.000000
47.670002,14.137123,-216.088455,-0.002889,0.002568,0.065215,62.885063,3.203518,0.652153,-216.088455,0.066099,0.000000
48.080002,14.125580,-216.088455,-0.002867,0.002596,0.065926,62.833717,3.200902,0.659261,-216.088455,0.066784,0.000000
48.490002,13.566643,-216.132935,-0.002841,0.002615,0.066420,60.347443,3.074245,0.664204,-216.132935,0.067470,0.000000
48.900002,13.978119,-216.266388,-0.002854,0.002641,0.067071,62.177776,3.167487,0.670706,-216.266388,0.068155,0.000000
49.310001,13.656013,-216.266388,-0.002828,0.002658,0.067513,60.744984,3.094497,0.675134,-216.266388,0.068840,0.000000
49.720001,14.039185,-216.355347,-0.002820,0.002687,0.068259,62.449413,3.181325,0.682591,-216.355347,0.069516,0.000000
50.130001,15.060234,-216.355347,-0.002777,0.002730,0.069334,66.991264,3.412698,0.693340,-216.355347,0.070201,0.000000
50.540001,14.437996,-216.355347,-0.002751,0.002750,0.069855,64.223412,3.271697,0.698548,-216.355347,0.070887,0.000000
50.950001,14.603706,-216.444305,-0.002755,0.002778,0.070566,64.960533,3.309247,0.705656,-216.444305,0.071572,0.000000
51.360001,14.902344,-216.444305,-0.002729,0.002805,0.071242,66.288933,3.376919,0.712423,-216.444305,0.072257,0.000000
51.770004,14.889313,-216.533264,-0.002703,0.002832,0.071936,66.230972,3.373967,0.719357,-216.533264,0.072933,0.000000
52.180004,14.877396,-216.533264,-0.002695,0.002856,0.072543,66.177963,3.371266,0.725428,-216.533264,0.073618,0.000000
52.590004,15.378235,-216.577744,-0.002660,0.002885,0.073289,68.405807,3.484758,0.732892,-216.577744,0.074304,0.000000
53.000004,15.348824,-216.622238,-0.002639,0.002913,0.074000,68.274979,3.478093,0.740000,-216.622238,0.074989,0.000000
53.410004,15.492554,-216.711197,-0.002639,0.002941,0.074711,68.914322,3.510663,0.747108,-216.711197,0.075674,0.000000
53.820004,14.789520,-216.800156,-0.002604,0.002955,0.075067,65.787071,3.351353,0.750666,-216.800156,0.076350,0.000000
54.230003,15.561447,-216.800156,-0.002600,0.002992,0.075986,69.220772,3.526274,0.759863,-216.800156,0.077035,0.000000
54.640003,15.971428,-216.755676,-0.002557,0.003020,0.076705,71.044456,3.619177,0.767054,-216.755676,0.077721,0.000000
55.050003,16.441360,-216.889114,-0.002539,0.003054,0.077582,73.134827,3.725665,0.775820,-216.889114,0.078406,0.000000
55.460003,15.891739,-216.844635,-0.002518,0.003076,0.078137,70.689987,3.601120,0.781369,-216.844635,0.079091,0.000000
55.870003,15.558464,-216.933594,-0.002488,0.003096,0.078649,69.207504,3.525598,0.786486,-216.933594,0.079767,0.000000
56.280003,16.121490,-216.978073,-0.002471,0.003127,0.079429,71.711967,3.653182,0.794290,-216.978073,0.080452,0.000000
56.690002,16.722878,-217.022568,-0.002479,0.003159,0.080227,74.387077,3.789458,0.802269,-217.022568,0.081138,0.000000
57.100002,16.647285,-217.111526,-0.002427,0.003187,0.080955,74.050827,3.772329,0.809551,-217.111526,0.081823,0.000000
57.510002,16.410828,-217.067047,-0.002406,0.003210,0.081545,72.999008,3.718747,0.815448,-217.067047,0.082508,0.000000
57.920002,16.790649,-217.156006,-0.002389,0.003240,0.082300,74.688538,3.804816,0.822995,-217.156006,0.083184,0.000000
58.330002,16.529243,-217.200485,-0.002371,0.003259,0.082776,73.525749,3.745580,0.827764,-217.200485,0.083869,0.000000
58.740002,16.633881,-217.244965,-0.002350,0.003284,0.083401,73.991196,3.769291,0.834009,-217.244965,0.084554,0.000000
59.150002,17.218132,-217.333923,-0.002337,0.003317,0.084242,76.590073,3.901685,0.842419,-217.333923,0.085240,0.000000
59.560001,17.059128,-217.289444,-0.002315,0.003342,0.084892,75.882790,3.865654,0.848922,-217.289444,0.085925,0.000000
59.970001,17.175308,-217.333923,-0.002285,0.003367,0.085534,76.399590,3.891981,0.855341,-217.333923,0.086601,0.000000
60.380001,17.241592,-217.422882,-0.002289,0.003392,0.086159,76.694435,3.907001,0.861586,-217.422882,0.087286,0.000000
60.790005,17.844460,-217.378403,-0.002255,0.003422,0.086913,79.376122,4.043612,0.869133,-217.378403,0.087971,0.000000
61.200005,18.092087,-217.511856,-0.002238,0.003457,0.087815,80.477623,4.099725,0.878149,-217.511856,0.088656,0.000000
61.610004,17.468361,-217.511856,-0.002212,0.003478,0.088335,77.703148,3.958387,0.883349,-217.511856,0.089341,0.000000
62.020004,17.339897,-217.645294,-0.002195,0.003497,0.088813,77.131714,3.929277,0.888126,-217.645294,0.090018,0.000000
62.430004,17.864197,-217.600815,-0.002169,0.003527,0.089593,79.463913,4.048085,0.895930,-217.600815,0.090703,0.000000
62.840004,18.611549,-217.645294,-0.002143,0.003562,0.090486,82.788307,4.217437,0.904862,-217.645294,0.091388,0.000000
63.250004,18.484566,-217.689774,-0.002134,0.003587,0.091110,82.223457,4.188663,0.911100,-217.689774,0.092073,0.000000
63.660004,18.603729,-217.734253,-0.002100,0.003616,0.091847,82.753517,4.215665,0.918473,-217.734253,0.092758,0.000000
64.070000,18.314018,-217.823212,-0.002087,0.003637,0.092376,81.464821,4.150016,0.923764,-217.823212,0.093435,0.000000
64.480003,18.694214,-217.823212,-0.002074,0.003662,0.093027,83.156013,4.236169,0.930267,-217.823212,0.094120,0.000000
64.889999,18.912422,-217.823212,-0.002052,0.003694,0.093834,84.126656,4.285616,0.938336,-217.823212,0.094805,0.000000
65.300003,19.258728,-217.912186,-0.002031,0.003722,0.094536,85.667099,4.364090,0.945361,-217.912186,0.095490,0.000000
65.710007,19.577110,-217.912186,-0.002001,0.003749,0.095229,87.083336,4.436236,0.952295,-217.912186,0.096175,0.000000
66.120003,19.268410,-218.001144,-0.001983,0.003769,0.095741,85.710167,4.366284,0.957412,-218.001144,0.096852,0.000000
66.530006,19.765160,-218.001144,-0.001970,0.003798,0.096470,87.919823,4.478849,0.964702,-218.001144,0.097537,0.000000
66.940002,20.387016,-218.045624,-0.001949,0.003828,0.097224,90.685974,4.619764,0.972241,-218.045624,0.098222,0.000000
67.350006,20.574692,-218.090103,-0.001932,0.003857,0.097961,91.520798,4.662292,0.979614,-218.090103,0.098907,0.000000
67.760002,20.906853,-218.090103,-0.001910,0.003884,0.098656,92.998329,4.737560,0.986556,-218.090103,0.099592,0.000000
68.170006,20.998825,-218.179062,-0.001880,0.003907,0.099236,93.407440,4.758402,0.992362,-218.179062,0.100268,0.000000
68.580002,22.003487,-218.179062,-0.001876,0.003935,0.099948,97.876396,4.986061,0.999477,-218.179062,0.100954,0.000000
68.990005,22.665939,-218.268021,-0.001845,0.003966,0.100746,100.823135,5.136176,1.007456,-218.268021,0.101639,0.000000
69.400002,23.058044,-218.268021,-0.001832,0.003995,0.101465,102.567307,5.225028,1.014647,-218.268021,0.102324,0.000000
69.810005,22.859200,-218.312515,-0.001807,0.004014,0.101951,101.682800,5.179969,1.019507,-218.312515,0.103009,0.000000
70.220001,23.510109,-218.401474,-0.001781,0.004039,0.102593,104.578186,5.327466,1.025926,-218.401474,0.103685,0.000000
70.630005,24.481628,-218.401474,-0.001776,0.004068,0.103330,108.899719,5.547616,1.033299,-218.401474,0.104370,0.000000
71.040001,25.007416,-218.445953,-0.001746,0.004093,0.103971,111.238541,5.666761,1.039711,-218.445953,0.105055,0.000000
71.450005,25.761475,-218.490433,-0.001746,0.004121,0.104674,114.592766,5.837634,1.046735,-218.490433,0.105740,0.000000
71.860001,26.458183,-218.490433,-0.001725,0.004149,0.105385,117.691879,5.995510,1.053851,-218.490433,0.106426,0.000000
72.270004,27.112442,-218.579391,-0.001694,0.004176,0.106070,120.602165,6.143767,1.060702,-218.579391,0.107102,0.000000
72.680000,28.192688,-218.623871,-0.001686,0.004203,0.106764,125.407341,6.388554,1.067636,-218.623871,0.107787,0.000000
73.090004,29.013397,-218.668350,-0.001677,0.004231,0.107458,129.058029,6.574530,1.074577,-218.668350,0.108472,0.000000
73.500000,29.767456,-218.757324,-0.001656,0.004255,0.108065,132.412262,6.745402,1.080648,-218.757324,0.109157,0.000000
73.910004,31.042831,-218.712830,-0.001630,0.004284,0.108810,138.085403,7.034406,1.088104,-218.712830,0.109842,0.000000
74.320007,32.247826,-218.801804,-0.001613,0.004313,0.109548,143.445496,7.307462,1.095477,-218.801804,0.110519,0.000000
74.730003,33.163116,-218.890762,-0.001604,0.004337,0.110163,147.516907,7.514870,1.101632,-218.890762,0.111204,0.000000
75.140007,33.485962,-218.846283,-0.001578,0.004358,0.110701,148.953003,7.588027,1.107014,-218.846283,0.111889,0.000000
75.550003,35.288620,-218.935242,-0.001582,0.004390,0.111508,156.971619,7.996515,1.115075,-218.935242,0.112574,0.000000
75.960007,36.585968,-218.979721,-0.001561,0.004418,0.112218,162.742508,8.290499,1.122184,-218.979721,0.113259,0.000000
76.370003,38.663803,-218.979721,-0.001531,0.004453,0.113094,171.985184,8.761343,1.130942,-218.979721,0.113936,0.000000
76.780006,39.389183,-219.068680,-0.001526,0.004474,0.113650,175.211838,8.925716,1.136498,-219.068680,0.114621,0.000000
77.190002,40.119408,-219.157639,-0.001513,0.004495,0.114162,178.460037,9.091187,1.141615,-219.157639,0.115306,0.000000
77.600006,41.804764,-219.157639,-0.001457,0.004526,0.114950,185.956879,9.473095,1.149503,-219.157639,0.115991,0.000000
78.010002,43.774986,-219.202133,-0.001449,0.004557,0.115740,194.720871,9.919554,1.157398,-219.202133,0.116676,0.000000
78.420006,45.417900,-219.291092,-0.001440,0.004585,0.116460,202.028915,10.291843,1.164597,-219.291092,0.117353,0.000000
78.830002,46.730881,-219.246613,-0.001436,0.004609,0.117067,207.869339,10.589369,1.170668,-219.246613,0.118038,0.000000
79.240005,48.450127,-219.291092,-0.001436,0.004638,0.117803,215.516922,10.978955,1.178033,-219.291092,0.118723,0.000000
79.650002,49.521065,-219.380051,-0.001423,0.004657,0.118298,220.280701,11.221633,1.182976,-219.380051,0.119408,0.000000
80.060005,51.028061,-219.380051,-0.001393,0.004682,0.118922,226.984146,11.563124,1.189222,-219.380051,0.120093,0.000000
80.470001,53.366188,-219.469009,-0.001388,0.004714,0.119747,237.384659,12.092951,1.197465,-219.469009,0.120778,0.000000
80.880005,54.987495,-219.469009,-0.001401,0.004740,0.120397,244.596588,12.460344,1.203968,-219.469009,0.121454,0.000000
81.290001,56.888084,-219.557968,-0.001380,0.004766,0.121047,253.050842,12.891025,1.210470,-219.557968,0.122140,0.000000
81.700005,58.563759,-219.602463,-0.001358,0.004790,0.121672,260.504608,13.270737,1.216715,-219.602463,0.122825,0.000000
82.110001,60.853104,-219.557968,-0.001358,0.004820,0.122426,270.688110,13.789511,1.224262,-219.557968,0.123510,0.000000
82.520004,63.439240,-219.735901,-0.001345,0.004854,0.123285,282.191833,14.375537,1.232846,-219.735901,0.124195,0.000000
82.930000,64.590240,-219.735901,-0.001345,0.004874,0.123787,287.311737,14.636357,1.237873,-219.735901,0.124871,0.000000
83.340004,65.923706,-219.735901,-0.001311,0.004882,0.124013,293.243286,14.938525,1.240128,-219.735901,0.021762,0.000000
83.750008,65.037460,-219.824860,-0.001311,0.004882,0.124013,289.301086,14.737700,1.240128,-219.824860,294.500458,0.000000
84.160004,64.376495,-219.824860,-0.001311,0.004882,0.124013,286.360962,14.587922,1.240128,-219.824860,294.500458,0.000000
84.570007,66.247665,-219.913818,-0.001289,0.004708,0.119590,294.684326,15.011936,1.195898,-219.913818,294.500458,0.000000
84.980003,65.730438,-219.913818,-0.001281,0.004737,0.120327,292.383606,14.894730,1.203271,-219.913818,294.500458,0.000000
85.390007,65.348022,-219.958298,-0.001276,0.004877,0.123865,290.682526,14.808074,1.238652,-219.958298,294.500458,0.000000
85.800003,65.193115,-220.047272,-0.001281,0.004895,0.124342,289.993469,14.772971,1.243421,-220.047272,294.500458,0.000000
86.210007,65.218430,-220.002777,-0.001285,0.004904,0.124550,290.106049,14.778708,1.245503,-220.002777,294.500458,0.000000
86.620003,65.110809,-220.180710,-0.001276,0.004908,0.124655,289.627350,14.754320,1.246548,-220.180710,294.500458,0.000000
87.030006,65.258270,-220.180710,-0.001281,0.004912,0.124768,290.283295,14.787735,1.247676,-220.180710,294.500458,0.000000
87.440002,65.109695,-220.180710,-0.001276,0.004914,0.124811,289.622375,14.754068,1.248107,-220.180710,294.500458,0.000000
87.850006,65.249710,-220.225189,-0.001272,0.004916,0.124863,290.245209,14.785795,1.248629,-220.225189,294.500458,0.000000
88.260002,65.199066,-220.225189,-0.001268,0.004918,0.124915,290.019928,14.774320,1.249152,-220.225189,294.500458,0.000000
88.670006,65.104477,-220.314148,-0.001281,0.004918,0.124923,289.599182,14.752885,1.249235,-220.314148,294.500458,0.000000
89.080002,65.210236,-220.314148,-0.001276,0.004921,0.125001,290.069611,14.776851,1.250015,-220.314148,294.500458,0.000000
89.490005,65.198318,-220.358627,-0.001259,0.004922,0.125019,290.016602,14.774151,1.250189,-220.358627,294.500458,0.000000
89.900002,65.070969,-220.447586,-0.001281,0.004922,0.125027,289.450134,14.745292,1.250272,-220.447586,294.500458,0.000000
90.310005,65.139862,-220.403107,-0.001276,0.004924,0.125079,289.756592,14.760904,1.250794,-220.403107,294.500458,0.000000
90.720001,65.103363,-220.536560,-0.001276,0.004926,0.125114,289.594208,14.752633,1.251143,-220.536560,294.500458,0.000000
91.130005,65.035965,-220.536560,-0.001276,0.004926,0.125132,289.294434,14.737360,1.251317,-220.536560,294.500458,0.000000
91.540001,65.465683,-220.625519,-0.001263,0.004932,0.125262,291.205902,14.834736,1.252619,-220.625519,294.500458,0.000000
91.950005,65.399399,-220.669998,-0.001259,0.004932,0.125262,290.911041,14.819715,1.252619,-220.669998,294.500458,0.000000
92.360001,65.311523,-220.581039,-0.001268,0.004932,0.125262,290.520172,14.799802,1.252619,-220.581039,294.500458,0.000000
92.770004,65.234070,-220.714478,-0.001255,0.004932,0.125262,290.175629,14.782252,1.252619,-220.714478,294.500458,0.000000
93.180008,65.147675,-220.714478,-0.001268,0.004932,0.125262,289.791321,14.762674,1.252619,-220.714478,294.500458,0.000000
93.590004,65.261627,-220.803436,-0.001263,0.004936,0.125366,290.298218,14.788496,1.253656,-220.803436,294.500458,0.000000
94.000008,65.274292,-220.803436,-0.001263,0.004936,0.125366,290.354553,14.791366,1.253656,-220.803436,294.500458,0.000000
94.410004,65.246353,-220.847916,-0.001272,0.004936,0.125366,290.230286,14.785034,1.253656,-220.847916,294.500458,0.000000
94.820007,65.175980,-220.936890,-0.001263,0.004936,0.125366,289.917236,14.769088,1.253656,-220.936890,294.500458,0.000000
95.230003,65.523026,-220.936890,-0.001263,0.004941,0.125513,291.460968,14.847730,1.255132,-220.936890,294.500458,0.000000
95.640007,65.556915,-220.981369,-0.001272,0.004941,0.125505,291.611725,14.855410,1.255049,-220.981369,294.500458,0.000000
96.050003,65.533829,-221.070328,-0.001255,0.004941,0.125505,291.509033,14.850178,1.255049,-221.070328,294.500458,0.000000
96.460007,65.504410,-221.025848,-0.001250,0.004941,0.125505,291.378174,14.843512,1.255049,-221.025848,294.500458,0.000000
96.870003,65.432175,-221.203766,-0.001259,0.004941,0.125505,291.056854,14.827143,1.255049,-221.203766,294.500458,0.000000
97.280006,65.386002,-221.159286,-0.001263,0.004941,0.125513,290.851471,14.816680,1.255132,-221.159286,294.500458,0.000000
97.690002,65.324188,-221.114807,-0.001246,0.004941,0.125513,290.576508,14.802672,1.255132,-221.114807,294.500458,0.000000
98.100006,65.278381,-221.248245,-0.001246,0.004941,0.125513,290.372742,14.792293,1.255132,-221.248245,294.500458,0.000000
98.510002,65.242264,-221.248245,-0.001246,0.004941,0.125513,290.212097,14.784108,1.255132,-221.248245,294.500458,0.000000
98.920006,65.174118,-221.292725,-0.001263,0.004941,0.125513,289.908966,14.768666,1.255132,-221.292725,294.500458,0.000000
99.330002,65.412064,-221.381699,-0.001263,0.004946,0.125634,290.967377,14.822585,1.256343,-221.381699,294.500458,0.000000
99.740005,65.456741,-221.426178,-0.001250,0.004946,0.125626,291.166138,14.832710,1.256260,-221.426178,294.500458,0.000000
100.150002,65.400513,-221.470657,-0.001263,0.004946,0.125618,290.916016,14.819968,1.256176,-221.470657,294.500458,0.000000
100.560005,65.360306,-221.470657,-0.001255,0.004946,0.125618,290.737152,14.810857,1.256176,-221.470657,294.500458,0.000000
100.970001,65.329025,-221.604095,-0.001246,0.004946,0.125618,290.598022,14.803769,1.256176,-221.604095,294.500458,0.000000
101.380005,65.293274,-221.559616,-0.001250,0.004946,0.125618,290.438995,14.795667,1.256176,-221.559616,294.500458,0.000000
101.790009,65.260880,-221.604095,-0.001250,0.004946,0.125618,290.294891,14.788326,1.256176,-221.604095,294.500458,0.000000
102.200005,65.223267,-221.693054,-0.001259,0.004946,0.125618,290.127594,14.779803,1.256176,-221.693054,294.500458,0.000000
102.610008,65.175980,-221.559616,-0.001246,0.004946,0.125626,289.917236,14.769088,1.256260,-221.559616,294.500458,0.000000
103.020004,65.140976,-221.782028,-0.001255,0.004946,0.125634,289.761536,14.761156,1.256343,-221.782028,294.500458,0.000000
103.430008,65.090714,-221.737534,-0.001255,0.004946,0.125634,289.537964,14.749766,1.256343,-221.737534,294.500458,0.000000
103.840004,65.083633,-221.870987,-0.001250,0.004947,0.125652,289.506470,14.748162,1.256517,-221.870987,294.500458,0.000000
104.250008,65.066132,-221.915466,-0.001255,0.004947,0.125652,289.428619,14.744196,1.256517,-221.915466,294.500458,0.000000
104.660004,65.062027,-221.870987,-0.001255,0.004947,0.125652,289.410339,14.743266,1.256517,-221.870987,294.500458,0.000000
105.070007,64.991287,-221.870987,-0.001250,0.004949,0.125696,289.095673,14.727236,1.256956,-221.870987,294.500458,0.000000
105.480003,65.784058,-222.004425,-0.001250,0.004955,0.125869,292.622101,14.906880,1.258690,-222.004425,294.500458,0.000000
105.890007,65.779602,-222.048904,-0.001242,0.004955,0.125869,292.602295,14.905870,1.258690,-222.048904,294.500458,0.000000
106.300003,65.764694,-222.093384,-0.001246,0.004955,0.125869,292.535980,14.902493,1.258690,-222.093384,294.500458,0.000000
106.710007,65.771027,-222.137863,-0.001246,0.004955,0.125869,292.564148,14.903927,1.258690,-222.137863,294.500458,0.000000
107.120003,65.762100,-222.226837,-0.001242,0.004955,0.125869,292.524445,14.901905,1.258690,-222.226837,294.500458,0.000000
107.530006,65.752045,-222.182358,-0.001255,0.004955,0.125869,292.479706,14.899627,1.258690,-222.182358,294.500458,0.000000
107.940002,65.673096,-222.271317,-0.001246,0.004955,0.125869,292.128510,14.881736,1.258690,-222.271317,294.500458,0.000000
108.350006,65.650757,-222.315796,-0.001250,0.004955,0.125869,292.029144,14.876674,1.258690,-222.315796,294.500458,0.000000
108.760002,65.634003,-222.315796,-0.001233,0.004955,0.125869,291.954620,14.872878,1.258690,-222.315796,294.500458,0.000000
109.170006,65.583725,-222.315796,-0.001250,0.004955,0.125869,291.730988,14.861485,1.258690,-222.315796,294.500458,0.000000
109.580002,65.588196,-222.404755,-0.001246,0.004955,0.125869,291.750854,14.862498,1.258690,-222.404755,294.500458,0.000000
109.990005,65.566605,-222.493713,-0.001246,0.004955,0.125869,291.654816,14.857605,1.258690,-222.493713,294.500458,0.000000
110.400002,65.544632,-222.493713,-0.001250,0.004955,0.125869,291.557098,14.852626,1.258690,-222.493713,294.500458,0.000000
110.810005,65.495102,-222.493713,-0.001242,0.004955,0.125869,291.336761,14.841402,1.258690,-222.493713,294.500458,0.000000
111.220009,65.490265,-222.627167,-0.001242,0.004955,0.125869,291.315247,14.840306,1.258690,-222.627167,294.500458,0.000000
111.630005,65.437378,-222.582672,-0.001229,0.004955,0.125869,291.079987,14.828321,1.258690,-222.582672,294.500458,0.000000
112.040009,65.416534,-222.671646,-0.001246,0.004955,0.125869,290.987274,14.823599,1.258690,-222.671646,294.500458,0.000000
112.450005,65.360672,-222.716125,-0.001237,0.004955,0.125869,290.738800,14.810940,1.258690,-222.716125,294.500458,0.000000
112.860008,65.350998,-222.716125,-0.001242,0.004955,0.125869,290.695770,14.808748,1.258690,-222.716125,294.500458,0.000000
113.270004,65.322327,-222.760605,-0.001255,0.004955,0.125869,290.568207,14.802251,1.258690,-222.760605,294.500458,0.000000
113.680008,65.301102,-222.849564,-0.001242,0.004955,0.125869,290.473816,14.797441,1.258690,-222.849564,294.500458,0.000000
114.090004,65.271683,-222.894043,-0.001242,0.004955,0.125869,290.342957,14.790774,1.258690,-222.894043,294.500458,0.000000
114.500008,65.260132,-222.894043,-0.001242,0.004955,0.125869,290.291565,14.788157,1.258690,-222.894043,294.500458,0.000000
114.910004,65.239288,-222.894043,-0.001255,0.004955,0.125869,290.198853,14.783434,1.258690,-222.894043,294.500458,0.000000
115.320007,65.213593,-222.983002,-0.001255,0.004955,0.125869,290.084534,14.777611,1.258690,-222.983002,294.500458,0.000000
115.730003,65.180817,-223.027481,-0.001242,0.004955,0.125869,289.938751,14.770185,1.258690,-223.027481,294.500458,0.000000
116.140007,65.137253,-223.116455,-0.001242,0.004955,0.125869,289.744965,14.760312,1.258690,-223.116455,294.500458,0.000000
116.550003,65.103363,-223.160934,-0.001242,0.004955,0.125869,289.594208,14.752633,1.258690,-223.160934,294.500458,0.000000
116.960007,65.092575,-223.160934,-0.001237,0.004955,0.125869,289.546234,14.750189,1.258690,-223.160934,294.500458,0.000000
117.370003,65.059433,-223.160934,-0.001233,0.004955,0.125869,289.398804,14.742678,1.258690,-223.160934,294.500458,0.000000
117.780006,65.050110,-223.205414,-0.001246,0.004955,0.125869,289.357330,14.740566,1.258690,-223.205414,294.500458,0.000000
118.190002,65.022568,-223.249893,-0.001242,0.004955,0.125869,289.234833,14.734324,1.258690,-223.249893,294.500458,0.000000
118.600006,65.004684,-223.249893,-0.001237,0.004955,0.125869,289.155273,14.730271,1.258690,-223.249893,294.500458,0.000000
119.010002,64.983093,-223.338852,-0.001233,0.004955,0.125869,289.059235,14.725379,1.258690,-223.338852,294.500458,0.000000
119.420006,64.961121,-223.427811,-0.001246,0.004955,0.125869,288.961487,14.720401,1.258690,-223.427811,294.500458,0.000000
119.830009,64.941757,-223.383331,-0.001233,0.004956,0.125877,288.875366,14.716012,1.258773,-223.383331,294.500458,0.000000
120.240005,64.913834,-223.472305,-0.001233,0.004956,0.125877,288.751160,14.709685,1.258773,-223.472305,294.500458,0.000000
120.650009,64.901535,-223.516785,-0.001237,0.004956,0.125877,288.696442,14.706899,1.258773,-223.516785,294.500458,0.000000
121.060005,64.909363,-223.516785,-0.001250,0.004956,0.125877,288.731262,14.708673,1.258773,-223.516785,294.500458,0.000000
121.470009,64.871384,-223.605743,-0.001237,0.004956,0.125877,288.562317,14.700066,1.258773,-223.605743,294.500458,0.000000
121.880005,64.828186,-223.694702,-0.001242,0.004956,0.125877,288.370178,14.690277,1.258773,-223.694702,294.500458,0.000000
122.290009,64.812912,-223.694702,-0.001259,0.004956,0.125877,288.302246,14.686816,1.258773,-223.694702,294.500458,0.000000
122.700005,64.768600,-223.694702,-0.001242,0.004956,0.125877,288.105133,14.676774,1.258773,-223.694702,294.500458,0.000000
123.110008,64.777542,-223.783661,-0.001237,0.004956,0.125877,288.144897,14.678801,1.258773,-223.783661,294.500458,0.000000
123.520004,64.743286,-223.739182,-0.001250,0.004956,0.125877,287.992523,14.671039,1.258773,-223.739182,294.500458,0.000000
123.930008,64.743652,-223.783661,-0.001246,0.004956,0.125877,287.994141,14.671122,1.258773,-223.783661,294.500458,0.000000
124.340004,64.717590,-223.872620,-0.001224,0.004956,0.125877,287.878204,14.665215,1.258773,-223.872620,294.500458,0.000000
124.750008,64.713867,-223.872620,-0.001255,0.004956,0.125877,287.861664,14.664372,1.258773,-223.872620,294.500458,0.000000
125.160004,64.684814,-223.872620,-0.001237,0.004956,0.125877,287.732422,14.657789,1.258773,-223.872620,294.500458,0.000000
125.570007,64.663223,-224.006073,-0.001242,0.004956,0.125877,287.636383,14.652895,1.258773,-224.006073,294.500458,0.000000
125.980003,64.653534,-224.006073,-0.001229,0.004956,0.125877,287.593292,14.650701,1.258773,-224.006073,294.500458,0.000000
126.390007,64.621140,-224.050552,-0.001237,0.004956,0.125877,287.449188,14.643359,1.258773,-224.050552,294.500458,0.000000
126.800003,64.602158,-224.050552,-0.001255,0.004956,0.125877,287.364746,14.639058,1.258773,-224.050552,294.500458,0.000000
127.210007,64.589127,-224.139511,-0.001229,0.004956,0.125877,287.306793,14.636105,1.258773,-224.139511,294.500458,0.000000
127.620003,64.579803,-224.183990,-0.001246,0.004956,0.125877,287.265320,14.633992,1.258773,-224.183990,294.500458,0.000000
128.029999,64.543320,-224.183990,-0.001246,0.004956,0.125877,287.103027,14.625726,1.258773,-224.183990,294.500458,0.000000
128.440002,64.539597,-224.272949,-0.001233,0.004956,0.125877,287.086456,14.624881,1.258773,-224.272949,294.500458,0.000000
128.850006,64.508682,-224.317429,-0.001259,0.004956,0.125877,286.948944,14.617876,1.258773,-224.317429,294.500458,0.000000
129.260010,64.497147,-224.317429,-0.001237,0.004956,0.125877,286.897644,14.615263,1.258773,-224.317429,294.500458,0.000000
129.670013,64.485596,-224.450882,-0.001250,0.004956,0.125877,286.846252,14.612644,1.258773,-224.450882,294.500458,0.000000
130.080002,66.699722,-224.406403,-0.001233,0.004891,0.124238,296.695190,15.114373,1.242384,-224.406403,294.500458,0.000000
130.490005,66.699356,-224.539841,-0.001250,0.004889,0.124169,296.693542,15.114290,1.241688,-224.539841,294.500458,0.000000
130.900009,66.669937,-224.495361,-0.001246,0.004889,0.124169,296.562683,15.107624,1.241688,-224.495361,294.500458,0.000000
131.310013,66.664352,-224.539841,-0.001229,0.004889,0.124169,296.537842,15.106359,1.241688,-224.539841,294.500458,0.000000
131.720001,66.658401,-224.584320,-0.001233,0.004889,0.124169,296.511383,15.105009,1.241688,-224.584320,294.500458,0.000000
132.130005,66.621536,-224.584320,-0.001233,0.004889,0.124169,296.347382,15.096657,1.241688,-224.584320,294.500458,0.000000
132.540009,66.596573,-224.717758,-0.001237,0.004889,0.124169,296.236359,15.090999,1.241688,-224.717758,294.500458,0.000000
132.950012,66.582062,-224.717758,-0.001246,0.004889,0.124169,296.171814,15.087710,1.241688,-224.717758,294.500458,0.000000
133.360001,66.566422,-224.806732,-0.001233,0.004889,0.124169,296.102234,15.084167,1.241688,-224.806732,294.500458,0.000000
133.770004,66.479279,-224.762253,-0.001242,0.004889,0.124169,295.714600,15.064420,1.241688,-224.762253,294.500458,0.000000
134.180008,66.477798,-224.851212,-0.001237,0.004889,0.124169,295.708008,15.064085,1.241688,-224.851212,294.500458,0.000000
134.590012,66.485611,-224.895691,-0.001237,0.004889,0.124178,295.742767,15.065855,1.241779,-224.895691,294.500458,0.000000
135.000000,66.474075,-224.895691,-0.001229,0.004889,0.124178,295.691467,15.063240,1.241779,-224.895691,294.500458,0.000000
135.410004,66.441299,-224.984650,-0.001233,0.004889,0.124178,295.545654,15.055814,1.241779,-224.984650,294.500458,0.000000
135.820007,66.432358,-225.029129,-0.001224,0.004889,0.124178,295.505890,15.053787,1.241779,-225.029129,294.500458,0.000000
136.230011,66.410400,-225.029129,-0.001224,0.004889,0.124178,295.408203,15.048812,1.241779,-225.029129,294.500458,0.000000
136.639999,66.404434,-225.162567,-0.001224,0.004889,0.124178,295.381683,15.047460,1.241779,-225.162567,294.500458,0.000000
137.050003,66.383957,-225.162567,-0.001229,0.004889,0.124178,295.290588,15.042820,1.241779,-225.162567,294.500458,0.000000
137.460007,66.379120,-225.207062,-0.001224,0.004889,0.124178,295.269073,15.041724,1.241779,-225.207062,294.500458,0.000000
137.870010,66.366455,-225.296021,-0.001233,0.004889,0.124178,295.212738,15.038854,1.241779,-225.296021,294.500458,0.000000
138.280014,66.346725,-225.251541,-0.001220,0.004889,0.124178,295.124969,15.034383,1.241779,-225.251541,294.500458,0.000000
138.690002,66.335922,-225.340500,-0.001229,0.004889,0.124178,295.076904,15.031935,1.241779,-225.340500,294.500458,0.000000
139.100006,66.304642,-225.384979,-0.001224,0.004889,0.124178,294.937775,15.024846,1.241779,-225.384979,294.500458,0.000000
139.510010,66.304642,-225.429459,-0.001220,0.004889,0.124178,294.937775,15.024846,1.241779,-225.429459,294.500458,0.000000
139.920013,66.280441,-225.473938,-0.001233,0.004889,0.124178,294.830139,15.019362,1.241779,-225.473938,294.500458,0.000000
140.330002,66.261810,-225.473938,-0.001233,0.004889,0.124178,294.747253,15.015141,1.241779,-225.473938,294.500458,0.000000
140.740005,66.251022,-225.518417,-0.001233,0.004889,0.124178,294.699280,15.012696,1.241779,-225.518417,294.500458,0.000000
141.150009,66.230545,-225.518417,-0.001233,0.004889,0.124178,294.608185,15.008057,1.241779,-225.518417,294.500458,0.000000
141.560013,66.219360,-225.651871,-0.001229,0.004889,0.124178,294.558441,15.005521,1.241779,-225.651871,294.500458,0.000000
141.970001,66.195541,-225.651871,-0.001229,0.004889,0.124178,294.452484,15.000124,1.241779,-225.651871,294.500458,0.000000
142.380005,66.175430,-225.607391,-0.001229,0.004889,0.124178,294.363007,14.995566,1.241779,-225.607391,294.500458,0.000000
142.790009,66.165375,-225.740829,-0.001229,0.004889,0.124178,294.318298,14.993288,1.241779,-225.740829,294.500458,0.000000
143.200012,66.154953,-225.740829,-0.001229,0.004889,0.124178,294.271942,14.990927,1.241779,-225.740829,294.500458,0.000000
143.610001,66.140793,-225.785309,-0.001233,0.004889,0.124178,294.208954,14.987719,1.241779,-225.785309,294.500458,0.000000
144.020004,66.119949,-225.874268,-0.001237,0.004889,0.124178,294.116211,14.982995,1.241779,-225.874268,0.124065,0.000000
144.430008,66.082336,-225.874268,-0.001233,0.004879,0.123927,293.948914,14.974472,1.239265,-225.874268,0.123380,0.000000
144.840012,66.083084,-226.007706,-0.001233,0.004858,0.123388,293.952240,14.974641,1.233883,-226.007706,0.122695,0.000000
145.250000,66.047699,-225.963226,-0.001224,0.004825,0.122565,293.794830,14.966622,1.225647,-225.963226,0.122018,0.000000
145.660004,66.061859,-226.052200,-0.001224,0.004799,0.121905,293.857819,14.969831,1.219054,-226.052200,0.121333,0.000000
146.070007,66.018280,-226.052200,-0.001216,0.004776,0.121298,293.663971,14.959956,1.212983,-226.052200,0.120648,0.000000
146.480011,65.658569,-226.096680,-0.001229,0.004755,0.120769,292.063904,14.878444,1.207692,-226.096680,0.119963,0.000000
146.889999,65.159225,-226.185638,-0.001224,0.004734,0.120241,289.842712,14.765291,1.202408,-226.185638,0.119278,0.000000
147.300003,63.596741,-226.141159,-0.001220,0.004695,0.119261,282.892426,14.411227,1.192605,-226.141159,0.118601,0.000000
147.710007,62.497131,-226.230118,-0.001220,0.004675,0.118749,278.001129,14.162052,1.187488,-226.230118,0.117916,0.000000
148.120010,61.135735,-226.274597,-0.001220,0.004656,0.118254,271.945343,13.853556,1.182545,-226.274597,0.117231,0.000000
148.530014,59.090668,-226.319077,-0.001220,0.004626,0.117509,262.848419,13.390137,1.175089,-226.319077,0.116546,0.000000
148.940002,57.019157,-226.363556,-0.001220,0.004602,0.116893,253.633881,12.920725,1.168927,-226.363556,0.115861,0.000000
149.350006,54.472130,-226.452515,-0.001229,0.004573,0.116147,242.304138,12.343561,1.161471,-226.452515,0.115184,0.000000
149.760010,52.026390,-226.452515,-0.001212,0.004548,0.115514,231.424942,11.789348,1.155142,-226.452515,0.114499,0.000000
150.170013,49.062309,-226.452515,-0.001229,0.004522,0.114847,218.240051,11.117678,1.148466,-226.452515,0.113814,0.000000
150.580002,46.687683,-226.497009,-0.001207,0.004501,0.114317,207.677185,10.579579,1.143175,-226.497009,0.113129,0.000000
150.990005,43.274895,-226.585968,-0.001220,0.004468,0.113493,192.496353,9.806231,1.134931,-226.585968,0.112444,0.000000
151.400009,40.020729,-226.630447,-0.001203,0.004437,0.112704,178.021088,9.068827,1.127043,-226.630447,0.111768,0.000000
151.810013,37.843842,-226.630447,-0.001220,0.004417,0.112193,168.337814,8.575538,1.121926,-226.630447,0.111083,0.000000
152.220001,34.704369,-226.674927,-0.001207,0.004391,0.111542,154.372742,7.864122,1.115424,-226.674927,0.110398,0.000000
152.630005,31.334770,-226.719406,-0.001220,0.004358,0.110684,139.384018,7.100561,1.106840,-226.719406,0.109712,0.000000
153.040009,29.195488,-226.763885,-0.001220,0.004343,0.110302,129.868011,6.615792,1.103024,-226.763885,0.109027,0.000000
153.450012,24.893097,-226.719406,-0.001224,0.004302,0.109262,110.730026,5.640856,1.092616,-226.719406,0.108351,0.000000
153.860001,22.284256,-226.852844,-0.001229,0.004276,0.108620,99.125320,5.049685,1.086197,-226.852844,0.107666,0.000000
154.270004,19.598335,-226.897339,-0.001216,0.004255,0.108073,87.177750,4.441046,1.080731,-226.897339,0.106981,0.000000
154.680008,17.025986,-226.941818,-0.001216,0.004234,0.107553,75.735367,3.858144,1.075531,-226.941818,0.106296,0.000000
155.090012,14.193352,-226.941818,-0.001229,0.004200,0.106677,63.135181,3.216259,1.066773,-226.941818,0.105611,0.000000
155.500000,10.014587,-226.897339,-0.001220,0.004171,0.105931,44.547112,2.269338,1.059309,-226.897339,0.104934,0.000000
155.910004,7.554695,-227.030777,-0.001224,0.004148,0.105368,33.604961,1.711918,1.053677,-227.030777,0.104249,0.000000
156.320007,4.569008,-227.075256,-0.001242,0.004120,0.104656,20.323961,1.035352,1.046561,-227.075256,0.103564,0.000000
156.730011,1.967247,-227.119736,-0.001212,0.004096,0.104049,8.750751,0.445785,1.040490,-227.119736,0.102879,0.000000
157.140015,-0.946571,-227.253174,-0.001220,0.004066,0.103278,-4.210560,-0.214496,1.032777,-227.253174,0.102194,0.000000
157.550003,0.048782,-227.164215,-0.001212,0.004043,0.102688,0.216995,0.011054,1.026880,-227.164215,0.101517,0.000000
157.960007,0.182465,-227.208694,-0.001212,0.004012,0.101908,0.811643,0.041347,1.019075,-227.208694,0.100832,0.000000
158.370010,0.216721,-227.208694,-0.001212,0.003987,0.101266,0.964021,0.049110,1.012656,-227.208694,0.100147,0.000000
158.780014,0.182091,-227.342148,-0.001212,0.003967,0.100762,0.809980,0.041262,1.007622,-227.342148,0.099462,0.000000
159.190002,0.093094,-227.386627,-0.001212,0.003926,0.099713,0.414102,0.021095,0.997131,-227.386627,0.098777,0.000000
159.600006,0.071495,-227.386627,-0.001212,0.003896,0.098950,0.318026,0.016201,0.989500,-227.386627,0.098092,0.000000
160.010010,0.056602,-227.520065,-0.001199,0.003875,0.098413,0.251780,0.012826,0.984126,-227.520065,0.097415,0.000000
160.420013,0.039101,-227.431107,-0.001212,0.003851,0.097805,0.173928,0.008860,0.978055,-227.431107,0.096730,0.000000
160.830002,0.023834,-227.520065,-0.001212,0.003828,0.097242,0.106020,0.005401,0.972415,-227.520065,0.096045,0.000000
161.240005,0.013779,-227.609024,-0.001207,0.003793,0.096340,0.061291,0.003122,0.963400,-227.609024,0.095360,0.000000
161.650009,0.023460,-227.520065,-0.001229,0.003767,0.095689,0.104357,0.005316,0.956890,-227.520065,0.094675,0.000000
162.060013,-0.013405,-227.653503,-0.001229,0.003740,0.095004,-0.059628,-0.003038,0.950039,-227.653503,0.093998,0.000000
162.470001,-0.020477,-227.609024,-0.001237,0.003715,0.094354,-0.091088,-0.004640,0.943536,-227.609024,0.093313,0.000000
162.880005,-0.007446,-227.742462,-0.001246,0.003686,0.093625,-0.033123,-0.001687,0.936254,-227.742462,0.092628,0.000000
163.290009,-0.008934,-227.742462,-0.001268,0.003660,0.092975,-0.039741,-0.002024,0.929752,-227.742462,0.091943,0.000000
163.700012,-0.011169,-227.786957,-0.001272,0.003632,0.092264,-0.049684,-0.002531,0.922636,-227.786957,0.091258,0.000000
164.110001,-0.039474,-227.831436,-0.001293,0.003608,0.091639,-0.175591,-0.008945,0.916391,-227.831436,0.090582,0.000000
164.520004,-0.046921,-227.831436,-0.001315,0.003590,0.091197,-0.208714,-0.010632,0.911970,-227.831436,0.089897,0.000000
164.930008,-0.010056,-227.920395,-0.001315,0.003549,0.090156,-0.044729,-0.002279,0.901562,-227.920395,0.089211,0.000000
165.340012,-0.010429,-228.009354,-0.001350,0.003525,0.089523,-0.046392,-0.002363,0.895234,-228.009354,0.088526,0.000000
165.750015,0.017128,-227.964874,-0.001337,0.003505,0.089029,0.076189,0.003881,0.890291,-227.964874,0.087841,0.000000
166.160004,-0.026070,-228.053833,-0.001393,0.003482,0.088439,-0.115964,-0.005907,0.884394,-228.053833,0.087165,0.000000
166.570007,-0.019737,-228.009354,-0.001384,0.003444,0.087468,-0.087796,-0.004473,0.874682,-228.009354,0.086480,0.000000
166.980011,0.020851,-228.142792,-0.001431,0.003422,0.086931,0.092750,0.004725,0.869307,-228.142792,0.086748,0.000000
167.000015,0.015266,-228.142792,-0.001431,0.003422,0.086931,0.067908,0.003459,0.869307,-228.142792,0.086748,0.000000