File: Data/AD compression/AD membrane peeled punched 300N 2_07302024_195611.csv
Time (sec),S:Load (lbs),S:HL1 (DIM),S:LVDT (in),S:Position (in),Ch:Position (mm),Ch:Load (N),Ch:Stress (MPa),Ch:Strain (mm/mm),Ch:HL1 (DIM),Set Point (),Cycles ()
0.110000,-0.103516,-235.660080,-0.005976,-0.004263,-0.108273,-0.460460,-0.023457,-1.082730,-235.660080,-0.108056,0.000000
0.260000,-0.087509,-235.660080,-0.005976,-0.004262,-0.108265,-0.389260,-0.019830,-1.082646,-235.660080,-0.108056,0.000000
0.410000,-0.084900,-235.793518,-0.005976,-0.004262,-0.108265,-0.377654,-0.019239,-1.082646,-235.793518,-0.107882,0.000000
0.560000,-0.038353,-235.749039,-0.005959,-0.004171,-0.105940,-0.170603,-0.008691,-1.059400,-235.749039,-0.105385,0.000000
0.710000,-0.045059,-235.749039,-0.005954,-0.004091,-0.103902,-0.200433,-0.010211,-1.039022,-235.749039,-0.102888,0.000000
0.860000,-0.054741,-235.793518,-0.005872,-0.004000,-0.101596,-0.243500,-0.012404,-1.015957,-235.793518,-0.100390,0.000000
1.010000,-0.030907,-235.793518,-0.005756,-0.003890,-0.098794,-0.137480,-0.007004,-0.987941,-235.793518,-0.097893,0.000000
1.160000,0.005959,-235.793518,-0.005665,-0.003809,-0.096756,0.026505,0.001350,-0.967563,-235.793518,-0.095394,0.000000
1.310000,-0.024574,-235.837997,-0.005558,-0.003701,-0.094016,-0.109312,-0.005569,-0.940160,-235.837997,-0.092897,0.000000
1.460000,-0.038727,-235.837997,-0.005441,-0.003608,-0.091640,-0.172265,-0.008776,-0.916399,-235.837997,-0.090382,0.000000
1.610000,-0.031281,-235.837997,-0.005355,-0.003502,-0.088960,-0.139143,-0.007088,-0.889602,-235.837997,-0.087885,0.000000
1.760000,-0.023834,-235.882477,-0.005256,-0.003415,-0.086731,-0.106020,-0.005401,-0.867309,-235.882477,-0.085387,0.000000
1.910000,-0.027557,-235.793518,-0.005139,-0.003313,-0.084147,-0.122581,-0.006245,-0.841465,-235.793518,-0.082889,0.000000
2.060000,-0.046547,-235.837997,-0.005053,-0.003215,-0.081667,-0.207051,-0.010548,-0.816667,-235.837997,-0.080392,0.000000
2.210000,-0.065910,-235.837997,-0.004971,-0.003112,-0.079056,-0.293184,-0.014935,-0.790559,-235.837997,-0.077894,0.000000
2.360000,-0.033142,-235.926971,-0.004838,-0.003007,-0.076376,-0.147423,-0.007510,-0.763762,-235.926971,-0.075397,0.000000
2.510000,-0.025696,-235.971451,-0.004708,-0.002916,-0.074070,-0.114301,-0.005823,-0.740696,-235.971451,-0.072899,0.000000
2.660000,-0.051758,-235.971451,-0.004626,-0.002816,-0.071528,-0.230230,-0.011728,-0.715285,-235.971451,-0.070401,0.000000
2.810000,-0.060326,-235.971451,-0.004527,-0.002720,-0.069092,-0.268342,-0.013670,-0.690917,-235.971451,-0.067903,0.000000
2.960000,-0.030159,-235.971451,-0.004424,-0.002617,-0.066464,-0.134154,-0.006834,-0.664643,-235.971451,-0.065406,0.000000
3.110000,-0.026810,-235.971451,-0.004337,-0.002522,-0.064071,-0.119255,-0.006075,-0.640707,-235.971451,-0.062909,0.000000
3.260000,-0.011169,-235.971451,-0.004234,-0.002427,-0.061651,-0.049684,-0.002531,-0.616506,-235.971451,-0.060411,0.000000
3.410000,-0.031654,-235.971451,-0.004100,-0.002323,-0.059006,-0.140806,-0.007173,-0.590058,-235.971451,-0.057896,0.000000
3.560000,-0.046173,-236.060410,-0.004010,-0.002225,-0.056508,-0.205388,-0.010463,-0.565085,-236.060410,-0.055398,0.000000
3.710000,0.001114,-236.015930,-0.003941,-0.002132,-0.054141,0.004955,0.000252,-0.541407,-236.015930,-0.052901,0.000000
3.860000,-0.001862,-236.015930,-0.003807,-0.002033,-0.051634,-0.008281,-0.000422,-0.516343,-236.015930,-0.050403,0.000000
4.010000,-0.035004,-236.015930,-0.003734,-0.001928,-0.048972,-0.155704,-0.007932,-0.489720,-236.015930,-0.047905,0.000000
4.160000,-0.030159,-236.104889,-0.003604,-0.001834,-0.046578,-0.134154,-0.006834,-0.465784,-236.104889,-0.045408,0.000000
4.310000,-0.037605,-236.060410,-0.003505,-0.001729,-0.043924,-0.167277,-0.008521,-0.439245,-236.060410,-0.042910,0.000000
4.460000,-0.042450,-236.149368,-0.003359,-0.001629,-0.041367,-0.188827,-0.009619,-0.413666,-236.149368,-0.040413,0.000000
4.610000,-0.029045,-236.104889,-0.003303,-0.001534,-0.038964,-0.129199,-0.006582,-0.389640,-236.104889,-0.037915,0.000000
4.760000,-0.070381,-236.149368,-0.003182,-0.001442,-0.036632,-0.313071,-0.015949,-0.366317,-236.149368,-0.035418,0.000000
4.910000,-0.079315,-236.149368,-0.003083,-0.001338,-0.033986,-0.352812,-0.017973,-0.339861,-236.149368,-0.032920,0.000000
5.060000,-0.013779,-236.193848,-0.002971,-0.001231,-0.031263,-0.061291,-0.003122,-0.312632,-236.193848,-0.030422,0.000000
5.210000,0.008194,-236.149368,-0.002876,-0.001144,-0.029070,0.036449,0.001857,-0.290695,-236.149368,-0.027924,0.000000
5.360000,-0.005959,-236.149368,-0.002777,-0.001046,-0.026563,-0.026505,-0.001350,-0.265631,-236.149368,-0.025410,0.000000
5.510000,-0.025322,-236.149368,-0.002695,-0.000948,-0.024074,-0.112638,-0.005738,-0.240742,-236.149368,-0.022912,0.000000
5.660000,0.036491,-236.193848,-0.002596,-0.000846,-0.021481,0.162322,0.008269,-0.214808,-236.193848,-0.020414,0.000000
5.810000,0.023087,-236.193848,-0.002496,-0.000761,-0.019339,0.102694,0.005231,-0.193393,-236.193848,-0.017917,0.000000
5.960001,0.020111,-236.238327,-0.002389,-0.000646,-0.016417,0.089459,0.004557,-0.164166,-236.238327,-0.015419,0.000000
6.110000,0.004471,-236.238327,-0.002289,-0.000553,-0.014040,0.019887,0.001013,-0.140404,-236.238327,-0.012922,0.000000
6.260000,0.026070,-236.282806,-0.002173,-0.000451,-0.011447,0.115964,0.005907,-0.114470,-236.282806,-0.010424,0.000000
6.410000,0.075218,-236.238327,-0.002087,-0.000359,-0.009123,0.334587,0.017045,-0.091231,-236.238327,-0.007926,0.000000
6.560000,0.166077,-236.327286,-0.001953,-0.000256,-0.006496,0.738746,0.037634,-0.064956,-236.327286,-0.005428,0.000000
6.710001,0.261032,-236.282806,-0.001854,-0.000156,-0.003972,1.161129,0.059151,-0.039719,-236.282806,-0.002931,0.000000
6.860000,0.423759,-236.371780,-0.001763,-0.000062,-0.001578,1.884976,0.096025,-0.015783,-236.371780,-0.000434,0.000000
7.010000,0.549248,-236.327286,-0.001673,-0.000000,-0.000000,2.443176,0.124461,-0.000000,-236.327286,0.000234,0.000000
7.160000,0.496376,-236.327286,-0.001690,-0.000000,-0.000000,2.207991,0.112480,-0.000000,-236.327286,0.000234,0.000000
7.310000,0.463974,-236.371780,-0.001673,-0.000000,-0.000000,2.063859,0.105138,-0.000000,-236.371780,0.000234,0.000000
7.460001,0.466583,-236.416260,-0.001686,-0.000000,-0.000000,2.075466,0.105729,-0.000000,-236.416260,0.000234,0.000000
7.610000,0.546646,-236.371780,-0.001681,-0.000000,-0.000000,2.431603,0.123872,-0.000000,-236.371780,0.000425,0.000000
7.760000,0.531746,-236.416260,-0.001686,-0.000000,-0.000000,2.365324,0.120495,-0.000000,-236.416260,0.000676,0.000000
7.910000,0.531380,-236.460739,-0.001677,-0.000000,-0.000000,2.363695,0.120412,-0.000000,-236.460739,0.000927,0.000000
8.060000,0.529884,-236.416260,-0.001673,-0.000000,-0.000000,2.357043,0.120074,-0.000000,-236.416260,0.001179,0.000000
8.210000,0.512383,-236.460739,-0.001686,0.000000,0.000008,2.279191,0.116108,0.000083,-236.460739,0.001422,0.000000
8.360001,0.707512,-236.549698,-0.001673,0.000035,0.000902,3.147170,0.160324,0.009016,-236.549698,0.001674,0.000000
8.510000,0.819962,-236.505219,-0.001647,0.000049,0.001240,3.647371,0.185806,0.012399,-236.505219,0.001925,0.000000
8.660001,0.876938,-236.505219,-0.001647,0.000059,0.001500,3.900815,0.198717,0.014996,-236.505219,0.002176,0.000000
8.810000,0.853477,-236.460739,-0.001630,0.000063,0.001604,3.796458,0.193401,0.016040,-236.460739,0.002428,0.000000
8.960000,0.907471,-236.505219,-0.001604,0.000072,0.001830,4.036631,0.205636,0.018296,-236.505219,0.002680,0.000000
9.110001,0.987534,-236.549698,-0.001604,0.000081,0.002055,4.392769,0.223778,0.020552,-236.549698,0.002922,0.000000
9.260000,0.917526,-236.594177,-0.001608,0.000084,0.002133,4.081360,0.207914,0.021332,-236.594177,0.003174,0.000000
9.410001,1.114883,-236.549698,-0.001591,0.000103,0.002610,4.959249,0.252636,0.026101,-236.549698,0.003425,0.000000
9.560000,1.206490,-236.549698,-0.001569,0.000115,0.002914,5.366734,0.273394,0.029136,-236.549698,0.003677,0.000000
9.710000,1.213188,-236.638657,-0.001565,0.000121,0.003079,5.396531,0.274912,0.030786,-236.638657,0.003928,0.000000
9.860001,1.239632,-236.594177,-0.001565,0.000128,0.003260,5.514157,0.280905,0.032603,-236.594177,0.004179,0.000000
10.010000,1.406822,-236.594177,-0.001561,0.000140,0.003564,6.257858,0.318790,0.035639,-236.594177,0.004422,0.000000
10.160001,1.514069,-236.638657,-0.001535,0.000155,0.003945,6.734913,0.343093,0.039454,-236.638657,0.004674,0.000000
10.310000,1.572533,-236.638657,-0.001535,0.000166,0.004214,6.994975,0.356341,0.042141,-236.638657,0.004926,0.000000
10.460000,1.645889,-236.638657,-0.001552,0.000175,0.004449,7.321281,0.372964,0.044488,-236.638657,0.005177,0.000000
10.610001,1.733391,-236.683136,-0.001518,0.000185,0.004708,7.710507,0.392792,0.047084,-236.683136,0.005428,0.000000
10.760000,1.733765,-236.727615,-0.001518,0.000189,0.004795,7.712170,0.392877,0.047955,-236.727615,0.005680,0.000000
10.910001,1.761696,-236.727615,-0.001505,0.000195,0.004960,7.836414,0.399206,0.049605,-236.727615,0.005923,0.000000
11.060000,1.909157,-236.772110,-0.001496,0.000207,0.005255,8.492353,0.432621,0.052549,-236.772110,0.006174,0.000000
11.210001,1.978416,-236.727615,-0.001492,0.000214,0.005446,8.800436,0.448316,0.054457,-236.727615,0.006426,0.000000
11.360001,2.231255,-236.727615,-0.001470,0.000234,0.005940,9.925116,0.505610,0.059400,-236.727615,0.006677,0.000000
11.510000,2.346321,-236.772110,-0.001462,0.000244,0.006200,10.436957,0.531684,0.062004,-236.772110,0.006929,0.000000
11.660001,2.377968,-236.816589,-0.001466,0.000250,0.006339,10.577729,0.538855,0.063389,-236.816589,0.007180,0.000000
11.810000,2.468086,-236.816589,-0.001427,0.000256,0.006504,10.978596,0.559276,0.065040,-236.816589,0.007423,0.000000
11.960001,2.602509,-236.816589,-0.001479,0.000264,0.006703,11.576536,0.589737,0.067030,-236.816589,0.007674,0.000000
12.110001,2.671402,-236.861069,-0.001449,0.000271,0.006885,11.882990,0.605348,0.068855,-236.861069,0.007926,0.000000
12.260000,3.060532,-236.861069,-0.001406,0.000292,0.007415,13.613925,0.693526,0.074146,-236.861069,0.008178,0.000000
12.410001,3.149529,-236.905548,-0.001388,0.000302,0.007683,14.009803,0.713693,0.076833,-236.905548,0.008429,0.000000
12.560000,3.343163,-236.905548,-0.001388,0.000313,0.007952,14.871130,0.757571,0.079521,-236.905548,0.008680,0.000000
12.710001,3.340927,-236.861069,-0.001410,0.000318,0.008073,14.861186,0.757065,0.080732,-236.861069,0.008923,0.000000
12.860001,3.410934,-236.905548,-0.001375,0.000324,0.008238,15.172594,0.772929,0.082382,-236.905548,0.009175,0.000000
13.010000,3.604568,-236.861069,-0.001371,0.000334,0.008490,16.033922,0.816807,0.084895,-236.861069,0.009427,0.000000
13.160001,3.699150,-236.994507,-0.001371,0.000340,0.008629,16.454641,0.838239,0.086288,-236.994507,0.009678,0.000000
13.310000,3.886826,-236.905548,-0.001358,0.000348,0.008837,17.289463,0.880767,0.088370,-236.905548,0.009929,0.000000
13.460001,4.170197,-236.950027,-0.001341,0.000360,0.009149,18.549961,0.944980,0.091488,-236.950027,0.010172,0.000000
13.610001,4.437187,-236.994507,-0.001354,0.000372,0.009452,19.737595,1.005481,0.094524,-236.994507,0.010424,0.000000
13.760000,4.475548,-236.994507,-0.001345,0.000378,0.009600,19.908232,1.014174,0.096000,-236.994507,0.010675,0.000000
13.910001,4.665825,-236.994507,-0.001332,0.000384,0.009756,20.754625,1.057291,0.097559,-236.994507,0.010927,0.000000
14.060000,4.951065,-237.038986,-0.001315,0.000396,0.010068,22.023437,1.121927,0.100678,-237.038986,0.011178,0.000000
14.210001,5.577766,-236.994507,-0.001293,0.000418,0.010614,24.811144,1.263940,0.106144,-236.994507,0.011430,0.000000
14.360001,5.700653,-237.083466,-0.001293,0.000427,0.010848,25.357771,1.291786,0.108483,-237.083466,0.011673,0.000000
14.510000,5.974716,-237.083466,-0.001302,0.000438,0.011118,26.576864,1.353890,0.111178,-237.083466,0.011924,0.000000
14.660001,6.063339,-237.083466,-0.001289,0.000444,0.011274,26.971081,1.373972,0.112737,-237.083466,0.012175,0.000000
14.810000,6.226440,-237.127945,-0.001293,0.000451,0.011464,27.696590,1.410932,0.114644,-237.127945,0.012427,0.000000
14.960001,6.577591,-237.083466,-0.001281,0.000464,0.011794,29.258585,1.490503,0.117937,-237.083466,0.012679,0.000000
15.110001,6.648712,-237.127945,-0.001276,0.000467,0.011854,29.574949,1.506620,0.118543,-237.127945,0.012930,0.000000
15.260001,7.222168,-237.127945,-0.001263,0.000482,0.012236,32.125809,1.636567,0.122358,-237.127945,0.013173,0.000000
15.410001,7.650764,-237.083466,-0.001246,0.000494,0.012548,34.032299,1.733688,0.125484,-237.083466,0.013424,0.000000
15.560000,7.745346,-237.083466,-0.001255,0.000502,0.012757,34.453018,1.755121,0.127566,-237.083466,0.013676,0.000000
15.710001,7.852592,-237.172424,-0.001255,0.000507,0.012878,34.930077,1.779423,0.128777,-237.172424,0.013927,0.000000
15.860001,8.039146,-237.172424,-0.001212,0.000512,0.013000,35.759911,1.821697,0.129996,-237.172424,0.014179,0.000000
16.010000,8.453224,-237.216919,-0.001233,0.000522,0.013259,37.601818,1.915528,0.132592,-237.216919,0.014430,0.000000
16.160000,8.965240,-237.172424,-0.001229,0.000538,0.013658,39.879383,2.031553,0.136582,-237.172424,0.014673,0.000000
16.310001,9.719292,-237.216919,-0.001199,0.000555,0.014092,43.233570,2.202423,0.140919,-237.216919,0.014925,0.000000
16.460001,9.810898,-237.261398,-0.001194,0.000562,0.014283,43.641052,2.223181,0.142827,-237.261398,0.015176,0.000000
16.610001,10.021660,-237.305878,-0.001190,0.000570,0.014473,44.578571,2.270941,0.144734,-237.305878,0.015427,0.000000
16.760000,10.468506,-237.305878,-0.001160,0.000581,0.014760,46.566238,2.372197,0.147596,-237.305878,0.015679,0.000000
16.910002,10.752625,-237.305878,-0.001173,0.000592,0.015046,47.830063,2.436579,0.150457,-237.305878,0.015931,0.000000
17.060001,11.087387,-237.350357,-0.001173,0.000599,0.015219,49.319160,2.512438,0.152191,-237.350357,0.016174,0.000000
17.210001,11.707390,-237.350357,-0.001177,0.000614,0.015584,52.077072,2.652932,0.155839,-237.350357,0.016425,0.000000
17.360001,12.187378,-237.305878,-0.001134,0.000625,0.015870,54.212166,2.761699,0.158701,-237.305878,0.016676,0.000000
17.510000,12.429420,-237.305878,-0.001147,0.000633,0.016078,55.288822,2.816547,0.160782,-237.305878,0.016928,0.000000
17.660002,12.491608,-237.394836,-0.001147,0.000637,0.016182,55.565445,2.830639,0.161819,-237.394836,0.017180,0.000000
17.810001,12.544113,-237.305878,-0.001143,0.000643,0.016330,55.799004,2.842537,0.163296,-237.305878,0.017431,0.000000
17.960001,12.794350,-237.350357,-0.001138,0.000649,0.016485,56.912109,2.899241,0.164855,-237.350357,0.017674,0.000000
18.110001,14.285324,-237.394836,-0.001117,0.000672,0.017075,63.544296,3.237101,0.170752,-237.394836,0.017925,0.000000
18.260000,14.739990,-237.394836,-0.001121,0.000684,0.017379,65.566750,3.340130,0.173787,-237.394836,0.018177,0.000000
18.410002,14.994698,-237.394836,-0.001121,0.000693,0.017604,66.699745,3.397847,0.176043,-237.394836,0.018428,0.000000
18.560001,14.945541,-237.439316,-0.001065,0.000696,0.017674,66.481087,3.386708,0.176739,-237.439316,0.018680,0.000000
18.710001,15.645973,-237.439316,-0.001061,0.000710,0.018029,69.596764,3.545428,0.180290,-237.439316,0.018931,0.000000
18.860001,16.033615,-237.528275,-0.001104,0.000719,0.018264,71.321083,3.633269,0.182636,-237.528275,0.019174,0.000000
19.010000,16.504295,-237.394836,-0.001078,0.000730,0.018541,73.414772,3.739927,0.185407,-237.394836,0.019426,0.000000
19.160002,17.341385,-237.528275,-0.001078,0.000745,0.018922,77.138336,3.929614,0.189222,-237.528275,0.019677,0.000000
19.310001,17.681732,-237.528275,-0.001043,0.000754,0.019157,78.652275,4.006738,0.191569,-237.528275,0.019928,0.000000
19.460001,17.959152,-237.483795,-0.001056,0.000762,0.019356,79.886299,4.069602,0.193560,-237.483795,0.020180,0.000000
19.610001,18.076447,-237.528275,-0.001056,0.000766,0.019460,80.408051,4.096181,0.194604,-237.528275,0.020432,0.000000
19.760000,18.343437,-237.528275,-0.001069,0.000775,0.019677,81.595680,4.156682,0.196769,-237.528275,0.020675,0.000000
19.910002,18.617134,-237.572754,-0.001052,0.000779,0.019781,82.813148,4.218703,0.197814,-237.572754,0.020926,0.000000
20.060001,20.100670,-237.572754,-0.001043,0.000803,0.020388,89.412247,4.554877,0.203885,-237.572754,0.021177,0.000000
20.210001,20.422394,-237.572754,-0.001018,0.000811,0.020596,90.843346,4.627781,0.205959,-237.572754,0.021429,0.000000
20.360001,20.834984,-237.572754,-0.001013,0.000821,0.020856,92.678635,4.721275,0.208563,-237.572754,0.021681,0.000000
20.510000,20.867378,-237.617233,-0.001009,0.000826,0.020978,92.822731,4.728616,0.209782,-237.617233,0.021923,0.000000
20.660002,21.504883,-237.661728,-0.000987,0.000837,0.021255,95.658493,4.873076,0.212552,-237.661728,0.022175,0.000000
20.810001,21.888802,-237.617233,-0.000992,0.000847,0.021507,97.366249,4.960073,0.215065,-237.617233,0.022426,0.000000
20.960001,22.444748,-237.661728,-0.000992,0.000857,0.021759,99.839226,5.086052,0.217586,-237.661728,0.022678,0.000000
21.110001,23.051346,-237.661728,-0.000983,0.000869,0.022062,102.537506,5.223510,0.220622,-237.661728,0.022929,0.000000
21.260000,23.744705,-237.706207,-0.000987,0.000879,0.022331,105.621727,5.380627,0.223309,-237.706207,0.023180,0.000000
21.410002,23.999031,-237.706207,-0.000970,0.000886,0.022504,106.753021,5.438258,0.225042,-237.706207,0.023423,0.000000
21.560001,24.212029,-237.750687,-0.000983,0.000891,0.022643,107.700485,5.486524,0.226428,-237.750687,0.023675,0.000000
21.710001,24.655525,-237.750687,-0.000944,0.000903,0.022929,109.673256,5.587022,0.229289,-237.750687,0.023927,0.000000
21.860001,25.359680,-237.750687,-0.000940,0.000913,0.023198,112.805489,5.746586,0.231976,-237.750687,0.024178,0.000000
22.010000,26.615692,-237.750687,-0.000936,0.000931,0.023649,118.392509,6.031202,0.236488,-237.750687,0.024429,0.000000
22.160002,26.819382,-237.795166,-0.000953,0.000938,0.023831,119.298569,6.077359,0.238312,-237.795166,0.024681,0.000000
22.310001,27.376823,-237.750687,-0.000918,0.000950,0.024117,121.778191,6.203677,0.241174,-237.750687,0.024924,0.000000
22.460001,27.664665,-237.839645,-0.000931,0.000955,0.024256,123.058578,6.268903,0.242559,-237.839645,0.025175,0.000000
22.610001,28.059013,-237.795166,-0.000940,0.000966,0.024534,124.812721,6.358263,0.245337,-237.795166,0.025427,0.000000
22.760000,28.466759,-237.839645,-0.000918,0.000973,0.024707,126.626465,6.450660,0.247070,-237.839645,0.025678,0.000000
22.910002,28.800774,-237.839645,-0.000918,0.000979,0.024855,128.112244,6.526349,0.248546,-237.839645,0.025930,0.000000
23.060001,29.474396,-237.839645,-0.000897,0.000990,0.025149,131.108658,6.678994,0.251491,-237.839645,0.026181,0.000000
23.210001,30.498421,-237.839645,-0.000901,0.001005,0.025522,135.663757,6.911041,0.255223,-237.839645,0.026424,0.000000
23.360001,30.810471,-237.884125,-0.000901,0.001011,0.025687,137.051819,6.981753,0.256866,-237.884125,0.026675,0.000000
23.510000,30.824249,-237.884125,-0.000871,0.001016,0.025799,137.113113,6.984875,0.257994,-237.884125,0.026927,0.000000
23.660002,31.392860,-237.928604,-0.000892,0.001026,0.026051,139.642410,7.113724,0.260514,-237.928604,0.027179,0.000000
23.810001,32.386353,-237.928604,-0.000871,0.001041,0.026450,144.061691,7.338852,0.264504,-237.928604,0.027430,0.000000
23.960001,33.248390,-237.973083,-0.000875,0.001053,0.026745,147.896225,7.534193,0.267448,-237.973083,0.027681,0.000000
24.110001,33.974892,-237.973083,-0.000880,0.001066,0.027074,151.127869,7.698821,0.270741,-237.973083,0.027924,0.000000
24.260000,34.667877,-237.928604,-0.000871,0.001076,0.027335,154.210419,7.855853,0.273345,-237.928604,0.028176,0.000000
24.410002,34.732300,-237.973083,-0.000862,0.001081,0.027456,154.496979,7.870451,0.274556,-237.973083,0.028428,0.000000
24.560001,35.344849,-237.973083,-0.000854,0.001092,0.027743,157.221741,8.009257,0.277425,-237.973083,0.028679,0.000000
24.710001,35.668442,-238.062057,-0.000841,0.001099,0.027916,158.661148,8.082584,0.279159,-238.062057,0.028930,0.000000
24.860001,36.134277,-238.062057,-0.000854,0.001106,0.028098,160.733292,8.188144,0.280975,-238.062057,0.029182,0.000000
25.010002,36.814980,-238.062057,-0.000832,0.001120,0.028453,163.761215,8.342394,0.284533,-238.062057,0.029425,0.000000
25.160002,38.271324,-238.062057,-0.000819,0.001137,0.028878,170.239349,8.672406,0.288780,-238.062057,0.029676,0.000000
25.310001,38.470917,-238.062057,-0.000811,0.001143,0.029026,171.127182,8.717634,0.290256,-238.062057,0.029928,0.000000
25.460001,38.909569,-238.106537,-0.000823,0.001151,0.029242,173.078400,8.817034,0.292421,-238.106537,0.030179,0.000000
25.610001,39.731400,-238.106537,-0.000798,0.001165,0.029598,176.734085,9.003264,0.295979,-238.106537,0.030431,0.000000
25.760002,40.774040,-238.151016,-0.000811,0.001178,0.029928,181.371994,9.239530,0.299279,-238.151016,0.030682,0.000000
25.910002,41.304672,-238.106537,-0.000793,0.001187,0.030153,183.732361,9.359773,0.301527,-238.106537,0.030925,0.000000
26.060001,41.572777,-238.151016,-0.000793,0.001194,0.030318,184.924942,9.420527,0.303178,-238.151016,0.031176,0.000000
26.210001,42.132828,-238.195496,-0.000802,0.001204,0.030569,187.416183,9.547435,0.305691,-238.195496,0.031428,0.000000
26.360001,42.602386,-238.151016,-0.000806,0.001210,0.030742,189.504883,9.653838,0.307424,-238.151016,0.031680,0.000000
26.510002,43.321068,-238.195496,-0.000789,0.001223,0.031055,192.701736,9.816694,0.310551,-238.195496,0.031931,0.000000
26.660002,43.551193,-238.195496,-0.000802,0.001226,0.031141,193.725388,9.868842,0.311414,-238.195496,0.032174,0.000000
26.810001,44.104912,-238.195496,-0.000759,0.001236,0.031402,196.188446,9.994316,0.314018,-238.195496,0.032425,0.000000
26.960001,45.681168,-238.239975,-0.000785,0.001256,0.031896,203.199982,10.351501,0.318961,-238.239975,0.032677,0.000000
27.110001,46.268394,-238.239975,-0.000759,0.001264,0.032104,205.812103,10.484568,0.321042,-238.239975,0.032928,0.000000
27.260002,46.596458,-238.239975,-0.000780,0.001269,0.032243,207.271393,10.558908,0.322428,-238.239975,0.033180,0.000000
27.410002,46.825836,-238.328934,-0.000746,0.001277,0.032425,208.291718,10.610886,0.324252,-238.328934,0.033431,0.000000
27.560001,47.672615,-238.284454,-0.000746,0.001286,0.032677,212.058380,10.802769,0.326765,-238.284454,0.033674,0.000000
27.710001,49.064911,-238.284454,-0.000737,0.001305,0.033145,218.251617,11.118267,0.331451,-238.284454,0.033926,0.000000
27.860001,49.795509,-238.328934,-0.000746,0.001315,0.033405,221.501495,11.283824,0.334055,-238.328934,0.034177,0.000000
28.010002,50.474716,-238.328934,-0.000733,0.001325,0.033657,224.522751,11.437734,0.336568,-238.328934,0.034428,0.000000
28.160002,51.028061,-238.328934,-0.000733,0.001333,0.033848,226.984146,11.563124,0.338476,-238.328934,0.034680,0.000000
28.310001,50.976303,-238.328934,-0.000724,0.001335,0.033917,226.753922,11.551395,0.339172,-238.328934,0.034932,0.000000
28.460001,51.769455,-238.373413,-0.000729,0.001351,0.034307,230.282043,11.731127,0.343070,-238.373413,0.035175,0.000000
28.610001,52.377914,-238.373413,-0.000720,0.001353,0.034377,232.988602,11.869004,0.343767,-238.373413,0.035426,0.000000
28.760002,52.448662,-238.373413,-0.000703,0.001357,0.034472,233.303299,11.885036,0.344721,-238.373413,0.035677,0.000000
28.910002,53.788834,-238.462372,-0.000703,0.001376,0.034957,239.264679,12.188724,0.349573,-238.462372,0.035928,0.000000
29.060001,54.732048,-238.417892,-0.000724,0.001385,0.035175,243.460312,12.402459,0.351745,-238.417892,0.036181,0.000000
29.210001,55.165489,-238.417892,-0.000690,0.001391,0.035339,245.388351,12.500679,0.353388,-238.417892,0.036432,0.000000
29.360001,55.670425,-238.462372,-0.000703,0.001399,0.035539,247.634415,12.615099,0.355386,-238.462372,0.036675,0.000000
29.510002,56.975594,-238.417892,-0.000724,0.001415,0.035928,253.440094,12.910854,0.359285,-238.417892,0.036926,0.000000
29.660002,58.593552,-238.551346,-0.000694,0.001433,0.036389,260.637146,13.277489,0.363887,-238.551346,0.037178,0.000000
29.810001,59.355423,-238.506866,-0.000686,0.001443,0.036648,264.026123,13.450131,0.366484,-238.506866,0.037429,0.000000
29.960001,60.138153,-238.551346,-0.000673,0.001453,0.036917,267.507874,13.627501,0.369171,-238.551346,0.037681,0.000000
30.110001,60.674744,-238.551346,-0.000681,0.001460,0.037082,269.894745,13.749093,0.370821,-238.551346,0.037932,0.000000
30.260002,61.000565,-238.462372,-0.000677,0.001466,0.037238,271.344055,13.822926,0.372381,-238.462372,0.038175,0.000000
30.410002,61.441460,-238.595825,-0.000690,0.001475,0.037464,273.305267,13.922834,0.374636,-238.595825,0.038427,0.000000
30.560001,62.076355,-238.640305,-0.000673,0.001480,0.037602,276.129425,14.066703,0.376022,-238.640305,0.038678,0.000000
30.710001,62.381325,-238.595825,-0.000655,0.001490,0.037854,277.485992,14.135810,0.378542,-238.595825,0.038929,0.000000
30.860001,64.536987,-238.595825,-0.000677,0.001509,0.038339,287.074860,14.624290,0.383395,-238.595825,0.039181,0.000000
31.010002,65.302963,-238.595825,-0.000655,0.001518,0.038565,290.482086,14.797863,0.385651,-238.595825,0.039433,0.000000
31.160002,65.679794,-238.640305,-0.000634,0.001523,0.038695,292.158325,14.883254,0.386953,-238.640305,0.039676,0.000000
31.310001,66.303894,-238.640305,-0.000642,0.001533,0.038938,294.934448,15.024677,0.389382,-238.640305,0.039927,0.000000
31.460001,67.610184,-238.640305,-0.000668,0.001546,0.039277,300.745117,15.320687,0.392766,-238.640305,0.040170,0.000000
31.610001,67.292542,-238.640305,-0.000655,0.001538,0.039077,299.332184,15.248708,0.390768,-238.640305,0.039311,0.000000
31.760002,67.041931,-238.640305,-0.000634,0.001538,0.039077,298.217407,15.191919,0.390768,-238.640305,0.039311,0.000000
31.910002,66.904160,-238.729263,-0.000647,0.001536,0.039016,297.604553,15.160699,0.390162,-238.729263,0.039077,0.000000
32.060001,66.713501,-238.773743,-0.000642,0.001535,0.038981,296.756470,15.117496,0.389814,-238.773743,0.039077,0.000000
32.210003,66.540359,-238.684784,-0.000642,0.001534,0.038964,295.986298,15.078260,0.389640,-238.684784,0.039077,0.000000
32.360001,66.382462,-238.773743,-0.000638,0.001533,0.038947,295.283936,15.042481,0.389466,-238.773743,0.039077,0.000000
32.510002,66.248047,-238.773743,-0.000617,0.001533,0.038938,294.686035,15.012022,0.389382,-238.773743,0.039077,0.000000
32.660000,66.124420,-238.773743,-0.000647,0.001533,0.038938,294.136108,14.984008,0.389382,-238.773743,0.039077,0.000000
32.810001,66.028336,-238.818222,-0.000647,0.001533,0.038929,293.708710,14.962234,0.389292,-238.818222,0.039077,0.000000
32.960003,65.921844,-238.773743,-0.000660,0.001533,0.038929,293.235016,14.938104,0.389292,-238.773743,0.039077,0.000000
33.110001,65.838806,-238.862701,-0.000634,0.001533,0.038929,292.865631,14.919287,0.389292,-238.862701,0.039077,0.000000
33.260002,65.749802,-238.818222,-0.000647,0.001533,0.038929,292.469727,14.899118,0.389292,-238.818222,0.039077,0.000000
33.410000,65.666763,-238.862701,-0.000638,0.001533,0.038929,292.100342,14.880301,0.389292,-238.862701,0.039077,0.000000
33.560001,65.596390,-238.862701,-0.000634,0.001533,0.038929,291.787323,14.864354,0.389292,-238.862701,0.039077,0.000000
33.710003,65.517441,-238.907181,-0.000629,0.001533,0.038929,291.436127,14.846464,0.389292,-238.907181,0.039077,0.000000
33.860001,65.460098,-238.862701,-0.000634,0.001533,0.038929,291.181061,14.833470,0.389292,-238.862701,0.039077,0.000000
34.010002,65.391953,-238.951675,-0.000625,0.001533,0.038929,290.877930,14.818028,0.389292,-238.951675,0.039077,0.000000
34.160000,65.334244,-238.907181,-0.000638,0.001533,0.038929,290.621216,14.804952,0.389292,-238.907181,0.039077,0.000000
34.310001,65.280243,-238.951675,-0.000629,0.001533,0.038929,290.381012,14.792715,0.389292,-238.951675,0.039077,0.000000
34.460003,65.218796,-238.907181,-0.000629,0.001533,0.038929,290.107697,14.778790,0.389292,-238.907181,0.039077,0.000000
34.610001,65.184540,-238.907181,-0.000629,0.001532,0.038921,289.955322,14.771028,0.389208,-238.907181,0.039077,0.000000
34.760002,65.140976,-239.040634,-0.000621,0.001532,0.038921,289.761536,14.761156,0.389208,-239.040634,0.039077,0.000000
34.910000,65.098160,-238.996155,-0.000642,0.001532,0.038921,289.571075,14.751454,0.389208,-238.996155,0.039077,0.000000
35.060001,65.059799,-238.951675,-0.000608,0.001532,0.038921,289.400452,14.742761,0.389208,-238.951675,0.039077,0.000000
35.210003,65.002075,-238.996155,-0.000647,0.001532,0.038921,289.143677,14.729681,0.389208,-238.996155,0.039077,0.000000
35.360001,64.973404,-239.040634,-0.000625,0.001532,0.038921,289.016144,14.723184,0.389208,-239.040634,0.039077,0.000000
35.510002,64.925369,-239.040634,-0.000604,0.001532,0.038921,288.802460,14.712299,0.389208,-239.040634,0.039077,0.000000
35.660000,64.891113,-239.085114,-0.000638,0.001532,0.038921,288.650085,14.704536,0.389208,-239.085114,0.039077,0.000000
35.810001,64.849777,-239.085114,-0.000629,0.001532,0.038921,288.466217,14.695169,0.389208,-239.085114,0.039077,0.000000
35.960003,64.820358,-239.129593,-0.000621,0.001532,0.038921,288.335358,14.688503,0.389208,-239.129593,0.039077,0.000000
36.110001,64.790207,-239.085114,-0.000621,0.001532,0.038921,288.201233,14.681670,0.389208,-239.085114,0.039077,0.000000
36.260002,64.771591,-239.129593,-0.000642,0.001532,0.038921,288.118439,14.677452,0.389208,-239.129593,0.039077,0.000000
36.410000,64.730255,-239.174072,-0.000660,0.001532,0.038921,287.934570,14.668085,0.389208,-239.174072,0.039077,0.000000
36.560001,64.705307,-239.218552,-0.000634,0.001532,0.038921,287.823578,14.662433,0.389208,-239.218552,0.039077,0.000000
36.710003,64.672165,-239.174072,-0.000612,0.001532,0.038921,287.676147,14.654922,0.389208,-239.174072,0.039077,0.000000
36.860001,64.649445,-239.174072,-0.000638,0.001532,0.038921,287.575104,14.649774,0.389208,-239.174072,0.039077,0.000000
37.010002,64.607361,-239.218552,-0.000629,0.001532,0.038921,287.387909,14.640238,0.389208,-239.218552,0.039077,0.000000
37.160004,64.587997,-239.129593,-0.000604,0.001532,0.038921,287.301758,14.635849,0.389208,-239.129593,0.039077,0.000000
37.310001,64.547043,-239.218552,-0.000629,0.001532,0.038921,287.119598,14.626569,0.389208,-239.218552,0.039077,0.000000
37.460003,64.541458,-239.218552,-0.000642,0.001532,0.038921,287.094757,14.625303,0.389208,-239.218552,0.039077,0.000000
37.610001,64.510178,-239.352005,-0.000629,0.001532,0.038921,286.955597,14.618215,0.389208,-239.352005,0.039077,0.000000
37.760002,64.497513,-239.263031,-0.000612,0.001532,0.038921,286.899261,14.615345,0.389208,-239.263031,0.039077,0.000000
37.910004,64.464371,-239.218552,-0.000638,0.001532,0.038921,286.751831,14.607835,0.389208,-239.218552,0.039077,0.000000
38.060001,64.448730,-239.307510,-0.000629,0.001532,0.038921,286.682281,14.604291,0.389208,-239.307510,0.039077,0.000000
38.210003,64.420807,-239.396484,-0.000629,0.001532,0.038921,286.558075,14.597964,0.389208,-239.396484,0.039077,0.000000
38.360001,64.391769,-239.352005,-0.000647,0.001532,0.038921,286.428894,14.591384,0.389208,-239.352005,0.039077,0.000000
38.510002,64.368301,-239.352005,-0.000647,0.001532,0.038921,286.324493,14.586065,0.389208,-239.352005,0.039077,0.000000
38.660004,64.357498,-239.307510,-0.000612,0.001532,0.038921,286.276459,14.583617,0.389208,-239.307510,0.039077,0.000000
38.810001,64.342239,-239.352005,-0.000647,0.001532,0.038921,286.208588,14.580160,0.389208,-239.352005,0.039077,0.000000
38.960003,64.314316,-239.440964,-0.000625,0.001532,0.038921,286.084351,14.573833,0.389208,-239.440964,0.039077,0.000000
39.110001,64.304260,-239.352005,-0.000612,0.001532,0.038921,286.039642,14.571554,0.389208,-239.352005,0.039077,0.000000
39.260002,64.284149,-239.396484,-0.000642,0.001532,0.038921,285.950165,14.566997,0.389208,-239.396484,0.039077,0.000000
39.410004,64.260681,-239.440964,-0.000647,0.001532,0.038921,285.845795,14.561678,0.389208,-239.440964,0.039077,0.000000
39.560001,64.237228,-239.485443,-0.000647,0.001532,0.038921,285.741455,14.556364,0.389208,-239.485443,0.039077,0.000000
39.710003,64.218979,-239.485443,-0.000621,0.001532,0.038921,285.660278,14.552229,0.389208,-239.485443,0.039077,0.000000
39.860001,64.210052,-239.529922,-0.000651,0.001532,0.038921,285.620575,14.550206,0.389208,-239.529922,0.039077,0.000000
40.010002,64.176529,-239.574402,-0.000621,0.001532,0.038921,285.471466,14.542609,0.389208,-239.574402,0.039077,0.000000
40.160004,64.173187,-239.529922,-0.000621,0.001532,0.038921,285.456604,14.541852,0.389208,-239.529922,0.039077,0.000000
40.310001,64.165741,-239.485443,-0.000625,0.001532,0.038921,285.423462,14.540165,0.389208,-239.485443,0.039077,0.000000
40.460003,64.143021,-239.529922,-0.000651,0.001532,0.038921,285.322418,14.535016,0.389208,-239.529922,0.039077,0.000000
40.610001,64.140045,-239.574402,-0.000625,0.001532,0.038921,285.309174,14.534342,0.389208,-239.574402,0.039077,0.000000
40.760002,64.113235,-239.574402,-0.000634,0.001532,0.038921,285.189911,14.528267,0.389208,-239.574402,0.039077,0.000000
40.910004,64.089767,-239.618881,-0.000638,0.001532,0.038921,285.085510,14.522949,0.389208,-239.618881,0.039077,0.000000
41.060001,64.069656,-239.707840,-0.000617,0.001532,0.038921,284.996063,14.518392,0.389208,-239.707840,0.039077,0.000000
41.210003,64.063705,-239.663361,-0.000625,0.001532,0.038921,284.969604,14.517043,0.389208,-239.663361,0.039077,0.000000
41.360001,64.049179,-239.663361,-0.000642,0.001532,0.038921,284.904968,14.513752,0.389208,-239.663361,0.039077,0.000000
41.510002,64.029068,-239.663361,-0.000629,0.001532,0.038921,284.815521,14.509194,0.389208,-239.663361,0.039077,0.000000
41.660004,64.013809,-239.663361,-0.000629,0.001532,0.038921,284.747650,14.505736,0.389208,-239.663361,0.039077,0.000000
41.810001,63.998917,-239.707840,-0.000651,0.001532,0.038921,284.681396,14.502361,0.389208,-239.707840,0.039077,0.000000
41.960003,63.994812,-239.752319,-0.000634,0.001532,0.038921,284.663147,14.501431,0.389208,-239.752319,0.039077,0.000000
42.110001,63.981033,-239.752319,-0.000625,0.001532,0.038921,284.601837,14.498309,0.389208,-239.752319,0.039077,0.000000
42.260002,63.971359,-239.752319,-0.000604,0.001532,0.038921,284.558807,14.496118,0.389208,-239.752319,0.039077,0.000000
42.410004,63.946411,-239.752319,-0.000621,0.001532,0.038921,284.447845,14.490463,0.389208,-239.752319,0.039077,0.000000
42.560001,63.946411,-239.707840,-0.000617,0.001532,0.038921,284.447845,14.490463,0.389208,-239.707840,0.039077,0.000000
42.710003,63.920334,-239.841293,-0.000612,0.001532,0.038921,284.331848,14.484554,0.389208,-239.841293,0.039077,0.000000
42.860001,63.914017,-239.841293,-0.000612,0.001532,0.038921,284.303741,14.483124,0.389208,-239.841293,0.039077,0.000000
43.010002,63.903961,-239.796814,-0.000634,0.001532,0.038921,284.259003,14.480844,0.389208,-239.796814,0.039077,0.000000
43.160004,63.886078,-239.841293,-0.000612,0.001532,0.038921,284.179474,14.476792,0.389208,-239.841293,0.039077,0.000000
43.310001,63.879745,-239.841293,-0.000617,0.001532,0.038921,284.151306,14.475357,0.389208,-239.841293,0.039077,0.000000
43.460003,63.870438,-239.841293,-0.000625,0.001532,0.038921,284.109894,14.473248,0.389208,-239.841293,0.039077,0.000000
43.610001,63.862244,-239.930252,-0.000629,0.001532,0.038921,284.073456,14.471391,0.389208,-239.930252,0.039077,0.000000
43.760002,63.845871,-239.885773,-0.000651,0.001532,0.038921,284.000610,14.467681,0.389208,-239.885773,0.039077,0.000000
43.910004,63.835815,-239.930252,-0.000625,0.001532,0.038921,283.955902,14.465403,0.389208,-239.930252,0.039077,0.000000
44.060001,63.817932,-239.974731,-0.000617,0.001532,0.038921,283.876343,14.461350,0.389208,-239.974731,0.039077,0.000000
44.210003,63.815704,-239.974731,-0.000634,0.001532,0.038921,283.866425,14.460845,0.389208,-239.974731,0.039077,0.000000
44.360001,63.797455,-239.930252,-0.000634,0.001532,0.038921,283.785248,14.456710,0.389208,-239.930252,0.039077,0.000000
44.510002,63.790009,-239.930252,-0.000629,0.001532,0.038921,283.752136,14.455023,0.389208,-239.930252,0.039077,0.000000
44.660004,63.778473,-239.974731,-0.000621,0.001532,0.038921,283.700806,14.452409,0.389208,-239.974731,0.039077,0.000000
44.810001,63.775116,-239.974731,-0.000629,0.001532,0.038921,283.685883,14.451648,0.389208,-239.974731,0.039077,0.000000
44.960003,63.757614,-240.019211,-0.000595,0.001532,0.038921,283.608032,14.447681,0.389208,-240.019211,0.039077,0.000000
45.110001,63.757980,-240.019211,-0.000638,0.001532,0.038921,283.609650,14.447765,0.389208,-240.019211,0.039077,0.000000
45.260002,63.743835,-240.063690,-0.000638,0.001532,0.038921,283.546753,14.444559,0.389208,-240.063690,0.039077,0.000000
45.410004,63.724472,-240.063690,-0.000647,0.001532,0.038921,283.460602,14.440172,0.389208,-240.063690,0.039077,0.000000
45.560001,63.717773,-240.019211,-0.000651,0.001532,0.038921,283.430817,14.438654,0.389208,-240.019211,0.039077,0.000000
45.710003,63.698776,-240.108170,-0.000634,0.001532,0.038921,283.346313,14.434349,0.389208,-240.108170,0.039077,0.000000
45.860001,63.694687,-240.108170,-0.000629,0.001532,0.038921,283.328125,14.433422,0.389208,-240.108170,0.039077,0.000000
46.010002,63.696915,-240.108170,-0.000651,0.001532,0.038921,283.338013,14.433927,0.389208,-240.108170,0.039077,0.000000
46.160004,63.689835,-240.152649,-0.000612,0.001532,0.038921,283.306519,14.432323,0.389208,-240.152649,0.039077,0.000000
46.310001,63.678299,-240.197128,-0.000612,0.001532,0.038921,283.255219,14.429709,0.389208,-240.197128,0.039077,0.000000
46.460003,63.663025,-240.152649,-0.000621,0.001532,0.038921,283.187286,14.426248,0.389208,-240.152649,0.039077,0.000000
46.610001,63.658936,-240.197128,-0.000629,0.001532,0.038921,283.169098,14.425322,0.389208,-240.197128,0.039077,0.000000
46.760002,63.645523,-240.197128,-0.000625,0.001532,0.038921,283.109436,14.422282,0.389208,-240.197128,0.039077,0.000000
46.910004,63.634354,-240.241623,-0.000617,0.001532,0.038921,283.059753,14.419751,0.389208,-240.241623,0.039077,0.000000
47.060001,63.628403,-240.286102,-0.000604,0.001532,0.038921,283.033264,14.418402,0.389208,-240.286102,0.039077,0.000000
47.210003,63.625793,-240.152649,-0.000625,0.001532,0.038921,283.021667,14.417810,0.389208,-240.152649,0.039077,0.000000
47.360001,63.609787,-240.152649,-0.000625,0.001532,0.038921,282.950470,14.414184,0.389208,-240.152649,0.039077,0.000000
47.510002,63.597870,-240.241623,-0.000638,0.001532,0.038921,282.897461,14.411483,0.389208,-240.241623,0.039077,0.000000
47.660004,63.602707,-240.286102,-0.000617,0.001532,0.038921,282.918976,14.412579,0.389208,-240.286102,0.039077,0.000000
47.810001,63.590424,-240.286102,-0.000621,0.001532,0.038921,282.864319,14.409797,0.389208,-240.286102,0.039077,0.000000
47.960003,63.580734,-240.286102,-0.000629,0.001532,0.038921,282.821228,14.407600,0.389208,-240.286102,0.039077,0.000000
48.110001,63.581848,-240.286102,-0.000612,0.001532,0.038921,282.826172,14.407853,0.389208,-240.286102,0.039077,0.000000
48.260002,63.568817,-240.330582,-0.000651,0.001532,0.038921,282.768219,14.404900,0.389208,-240.330582,0.039077,0.000000
48.410004,63.559509,-240.330582,-0.000625,0.001532,0.038921,282.726807,14.402791,0.389208,-240.330582,0.039077,0.000000
48.560001,63.559509,-240.330582,-0.000629,0.001532,0.038921,282.726807,14.402791,0.389208,-240.330582,0.039077,0.000000
48.710003,63.541260,-240.330582,-0.000621,0.001532,0.038921,282.645630,14.398656,0.389208,-240.330582,0.039077,0.000000
48.860001,63.526749,-240.419540,-0.000621,0.001532,0.038921,282.581085,14.395367,0.389208,-240.419540,0.039077,0.000000
49.010002,63.523026,-240.375061,-0.000638,0.001532,0.038921,282.564545,14.394524,0.389208,-240.375061,0.039077,0.000000
49.160004,63.507385,-240.375061,-0.000638,0.001532,0.038921,282.494965,14.390980,0.389208,-240.375061,0.039077,0.000000
49.310001,63.507385,-240.375061,-0.000629,0.001532,0.038921,282.494965,14.390980,0.389208,-240.375061,0.039077,0.000000
49.460003,63.499557,-240.419540,-0.000595,0.001532,0.038921,282.460144,14.389206,0.389208,-240.419540,0.039077,0.000000
49.610001,63.494720,-240.419540,-0.000629,0.001532,0.038921,282.438629,14.388109,0.389208,-240.419540,0.039077,0.000000
49.760002,63.489883,-240.419540,-0.000608,0.001532,0.038921,282.417114,14.387013,0.389208,-240.419540,0.039077,0.000000
49.910004,63.489136,-240.508499,-0.000634,0.001532,0.038921,282.413788,14.386844,0.389208,-240.508499,0.039077,0.000000
50.060001,63.482056,-240.464020,-0.000608,0.001532,0.038921,282.382294,14.385240,0.389208,-240.464020,0.039077,0.000000
50.210003,63.476471,-240.508499,-0.000638,0.001532,0.038921,282.357452,14.383974,0.389208,-240.508499,0.039077,0.000000
50.360001,63.461578,-240.552979,-0.000634,0.001532,0.038921,282.291199,14.380599,0.389208,-240.552979,0.039077,0.000000
50.510002,63.452271,-240.552979,-0.000634,0.001532,0.038921,282.249786,14.378490,0.389208,-240.552979,0.039077,0.000000
50.660004,63.442215,-240.552979,-0.000625,0.001532,0.038921,282.205078,14.376212,0.389208,-240.552979,0.039077,0.000000
50.810001,63.441101,-240.552979,-0.000608,0.001532,0.038921,282.200104,14.375959,0.389208,-240.552979,0.039077,0.000000
50.960003,63.437378,-240.552979,-0.000629,0.001532,0.038921,282.183563,14.375115,0.389208,-240.552979,0.039077,0.000000
51.110001,63.437378,-240.641953,-0.000617,0.001532,0.038921,282.183563,14.375115,0.389208,-240.641953,0.039077,0.000000
51.260002,63.423599,-240.597458,-0.000621,0.001532,0.038921,282.122253,14.371993,0.389208,-240.597458,0.039077,0.000000
51.410004,63.421738,-240.552979,-0.000617,0.001532,0.038921,282.113983,14.371571,0.389208,-240.552979,0.039077,0.000000
51.560001,63.409439,-240.552979,-0.000629,0.001532,0.038921,282.059265,14.368784,0.389208,-240.552979,0.039077,0.000000
51.710003,63.415405,-240.641953,-0.000604,0.001532,0.038921,282.085815,14.370136,0.389208,-240.641953,0.039077,0.000000
51.860001,63.401993,-240.641953,-0.000591,0.001532,0.038921,282.026154,14.367097,0.389208,-240.641953,0.039077,0.000000
52.010002,63.384872,-240.641953,-0.000625,0.001532,0.038921,281.949982,14.363217,0.389208,-240.641953,0.039077,0.000000
52.160004,63.384872,-240.641953,-0.000608,0.001532,0.038921,281.949982,14.363217,0.389208,-240.641953,0.039077,0.000000
52.310001,63.385239,-240.730911,-0.000604,0.001532,0.038921,281.951630,14.363300,0.389208,-240.730911,0.039077,0.000000
52.460003,63.373703,-240.730911,-0.000608,0.001532,0.038921,281.900299,14.360686,0.389208,-240.730911,0.039077,0.000000
52.610001,63.366623,-240.730911,-0.000604,0.001532,0.038921,281.868805,14.359081,0.389208,-240.730911,0.039077,0.000000
52.760002,63.355072,-240.775391,-0.000621,0.001532,0.038921,281.817444,14.356464,0.389208,-240.775391,0.039077,0.000000
52.910004,63.358063,-240.819870,-0.000629,0.001532,0.038921,281.830750,14.357142,0.389208,-240.819870,0.039077,0.000000
53.060001,63.343536,-240.730911,-0.000629,0.001532,0.038921,281.766113,14.353850,0.389208,-240.730911,0.039077,0.000000
53.210003,63.338318,-240.775391,-0.000608,0.001532,0.038921,281.742920,14.352668,0.389208,-240.775391,0.039077,0.000000
53.360004,63.321564,-240.775391,-0.000617,0.001532,0.038921,281.668396,14.348871,0.389208,-240.775391,0.039077,0.000000
53.510002,63.331253,-240.819870,-0.000638,0.001532,0.038921,281.711487,14.351068,0.389208,-240.819870,0.039077,0.000000
53.660004,63.326035,-240.775391,-0.000638,0.001532,0.038921,281.688263,14.349884,0.389208,-240.775391,0.039077,0.000000
53.810001,63.314865,-240.775391,-0.000621,0.001532,0.038921,281.638580,14.347353,0.389208,-240.775391,0.039077,0.000000
53.960003,63.318207,-240.864349,-0.000608,0.001532,0.038921,281.653442,14.348110,0.389208,-240.864349,0.039077,0.000000
54.110004,63.302200,-240.819870,-0.000612,0.001532,0.038921,281.582245,14.344483,0.389208,-240.819870,0.039077,0.000000
54.260002,63.300705,-240.819870,-0.000621,0.001532,0.038921,281.575592,14.344145,0.389208,-240.819870,0.039077,0.000000
54.410004,63.311508,-240.908829,-0.000608,0.001532,0.038921,281.623657,14.346593,0.389208,-240.908829,0.039077,0.000000
54.560001,63.289917,-240.864349,-0.000625,0.001532,0.038921,281.527618,14.341701,0.389208,-240.864349,0.039077,0.000000
54.710003,63.293640,-240.908829,-0.000625,0.001532,0.038921,281.544159,14.342544,0.389208,-240.908829,0.039077,0.000000
54.860004,63.289536,-240.864349,-0.000629,0.001532,0.038921,281.525909,14.341614,0.389208,-240.864349,0.039077,0.000000
55.010002,63.282089,-240.953308,-0.000625,0.001532,0.038921,281.492798,14.339927,0.389208,-240.953308,0.039077,0.000000
55.160004,63.274643,-240.908829,-0.000612,0.001532,0.038921,281.459656,14.338239,0.389208,-240.908829,0.039077,0.000000
55.310001,63.266457,-240.908829,-0.000599,0.001532,0.038921,281.423248,14.336384,0.389208,-240.908829,0.039077,0.000000
55.460003,63.259377,-240.997787,-0.000612,0.001532,0.038921,281.391754,14.334780,0.389208,-240.997787,0.039077,0.000000
55.610004,63.261612,-240.953308,-0.000634,0.001532,0.038921,281.401703,14.335286,0.389208,-240.953308,0.039077,0.000000
55.760002,63.251930,-241.042267,-0.000612,0.001532,0.038921,281.358643,14.333092,0.389208,-241.042267,0.039077,0.000000
55.910004,63.242622,-240.997787,-0.000617,0.001532,0.038921,281.317230,14.330983,0.389208,-240.997787,0.039077,0.000000
56.060001,63.238525,-240.997787,-0.000604,0.001532,0.038921,281.299011,14.330054,0.389208,-240.997787,0.039077,0.000000
56.210003,63.234802,-241.086761,-0.000621,0.001532,0.038921,281.282440,14.329211,0.389208,-241.086761,0.039077,0.000000
56.360004,63.226234,-241.042267,-0.000629,0.001532,0.038921,281.244324,14.327270,0.389208,-241.042267,0.039077,0.000000
56.510002,63.223259,-241.042267,-0.000612,0.001532,0.038921,281.231110,14.326595,0.389208,-241.042267,0.039077,0.000000
56.660004,63.214325,-241.042267,-0.000621,0.001532,0.038921,281.191376,14.324571,0.389208,-241.042267,0.039077,0.000000
56.810001,63.222145,-241.042267,-0.000604,0.001532,0.038921,281.226135,14.326344,0.389208,-241.042267,0.039077,0.000000
56.960003,63.208740,-241.086761,-0.000617,0.001532,0.038921,281.166504,14.323305,0.389208,-241.086761,0.039077,0.000000
57.110004,63.203522,-241.131241,-0.000625,0.001532,0.038921,281.143311,14.322123,0.389208,-241.131241,0.039077,0.000000
57.260002,63.205757,-241.131241,-0.000629,0.001532,0.038921,281.153259,14.322629,0.389208,-241.131241,0.039077,0.000000
57.410004,63.197563,-241.086761,-0.000612,0.001532,0.038921,281.116791,14.320773,0.389208,-241.086761,0.039077,0.000000
57.560001,63.206131,-241.175720,-0.000625,0.001532,0.038921,281.154907,14.322714,0.389208,-241.175720,0.039077,0.000000
57.710003,63.196823,-241.175720,-0.000608,0.001532,0.038921,281.113495,14.320604,0.389208,-241.175720,0.039077,0.000000
57.860004,63.193840,-241.175720,-0.000621,0.001532,0.038921,281.100250,14.319929,0.389208,-241.175720,0.039077,0.000000
58.010002,63.180435,-241.175720,-0.000621,0.001532,0.038921,281.040619,14.316892,0.389208,-241.175720,0.039077,0.000000
58.160004,63.183418,-241.220200,-0.000634,0.001532,0.038921,281.053894,14.317567,0.389208,-241.220200,0.039077,0.000000
58.310001,63.178574,-241.264679,-0.000604,0.001532,0.038921,281.032318,14.316469,0.389208,-241.264679,0.039077,0.000000
58.460003,63.163681,-241.175720,-0.000617,0.001532,0.038921,280.966095,14.313095,0.389208,-241.175720,0.039077,0.000000
58.610004,63.154373,-241.220200,-0.000608,0.001532,0.038921,280.924683,14.310986,0.389208,-241.220200,0.039077,0.000000
58.760002,63.150650,-241.264679,-0.000629,0.001532,0.038921,280.908112,14.310142,0.389208,-241.264679,0.039077,0.000000
58.910004,63.143196,-241.264679,-0.000617,0.001532,0.038921,280.874969,14.308453,0.389208,-241.264679,0.039077,0.000000
59.060001,63.149529,-241.264679,-0.000599,0.001532,0.038921,280.903137,14.309888,0.389208,-241.264679,0.039077,0.000000
59.210003,63.136497,-241.264679,-0.000625,0.001532,0.038921,280.845154,14.306935,0.389208,-241.264679,0.039077,0.000000
59.360004,63.128304,-241.353638,-0.000608,0.001532,0.038921,280.808716,14.305078,0.389208,-241.353638,0.039077,0.000000
59.510002,63.133148,-241.309158,-0.000621,0.001532,0.038921,280.830261,14.306176,0.389208,-241.309158,0.039077,0.000000
59.660004,63.123833,-241.309158,-0.000621,0.001532,0.038921,280.788818,14.304065,0.389208,-241.309158,0.039077,0.000000
59.810001,63.122345,-241.353638,-0.000604,0.001532,0.038921,280.782227,14.303728,0.389208,-241.353638,0.039077,0.000000
59.960003,63.126816,-241.353638,-0.000629,0.001532,0.038921,280.802094,14.304741,0.389208,-241.353638,0.039077,0.000000
60.110004,63.121605,-241.353638,-0.000629,0.001532,0.038921,280.778931,14.303560,0.389208,-241.353638,0.039077,0.000000
60.260002,63.126068,-241.353638,-0.000621,0.001532,0.038921,280.798767,14.304571,0.389208,-241.353638,0.039077,0.000000
60.410004,63.115646,-241.309158,-0.000625,0.001532,0.038921,280.752411,14.302210,0.389208,-241.309158,0.039077,0.000000
60.560001,63.104103,-241.353638,-0.000604,0.001532,0.038921,280.701080,14.299595,0.389208,-241.353638,0.039077,0.000000
60.710003,63.109688,-241.442596,-0.000608,0.001532,0.038921,280.725922,14.300860,0.389208,-241.442596,0.039077,0.000000
60.860004,63.108940,-241.442596,-0.000608,0.001532,0.038921,280.722595,14.300691,0.389208,-241.442596,0.039077,0.000000
61.010002,63.096283,-241.487076,-0.000612,0.001532,0.038921,280.666290,14.297822,0.389208,-241.487076,0.039077,0.000000
61.160004,63.092560,-241.442596,-0.000617,0.001532,0.038921,280.649719,14.296978,0.389208,-241.442596,0.039077,0.000000
61.310001,63.083618,-241.531570,-0.000604,0.001532,0.038921,280.609955,14.294951,0.389208,-241.531570,0.039077,0.000000
61.460003,63.077660,-241.487076,-0.000599,0.001532,0.038921,280.583435,14.293602,0.389208,-241.487076,0.039077,0.000000
61.610004,63.067978,-241.487076,-0.000621,0.001532,0.038921,280.540375,14.291408,0.389208,-241.487076,0.039077,0.000000
61.760002,63.062019,-241.531570,-0.000634,0.001532,0.038921,280.513885,14.290057,0.389208,-241.531570,0.039077,0.000000
61.900002,63.064629,-241.487076,-0.000647,0.001532,0.038921,280.525482,14.290649,0.389208,-241.487076,0.039077,0.000000