File: Data/AD compression/AD membrane peeled punched 300N 3_07302024_200454.csv
Time (sec),S:Load (lbs),S:HL1 (DIM),S:LVDT (in),S:Position (in),Ch:Position (mm),Ch:Load (N),Ch:Stress (MPa),Ch:Strain (mm/mm),Ch:HL1 (DIM),Set Point (),Cycles ()
0.110000,-0.119904,-281.653381,-0.010839,-0.008884,-0.225661,-0.533358,-0.027171,-2.256615,-281.653381,-0.225366,0.000000
0.280000,-0.119904,-281.653381,-0.010869,-0.008884,-0.225661,-0.533358,-0.027171,-2.256615,-281.653381,-0.225366,0.000000
0.450000,-0.060326,-281.653381,-0.010865,-0.008855,-0.224907,-0.268342,-0.013670,-2.249068,-281.653381,-0.224308,0.000000
0.620000,-0.072609,-281.697876,-0.010865,-0.008766,-0.222652,-0.322981,-0.016453,-2.226517,-281.697876,-0.221464,0.000000
0.790000,-0.077827,-281.697876,-0.010762,-0.008651,-0.219729,-0.346194,-0.017636,-2.197290,-281.697876,-0.218637,0.000000
0.960000,-0.096069,-281.697876,-0.010675,-0.008540,-0.216920,-0.427338,-0.021770,-2.169199,-281.697876,-0.215809,0.000000
1.130000,-0.118416,-281.742340,-0.010550,-0.008428,-0.214083,-0.526740,-0.026833,-2.140835,-281.742340,-0.212965,0.000000
1.300000,-0.123253,-281.697876,-0.010442,-0.008317,-0.211256,-0.548256,-0.027929,-2.112562,-281.697876,-0.210138,0.000000
1.470000,-0.049522,-281.786835,-0.010287,-0.008199,-0.208247,-0.220287,-0.011222,-2.082472,-281.786835,-0.207311,0.000000
1.640000,-0.065163,-281.786835,-0.010175,-0.008088,-0.205437,-0.289858,-0.014766,-2.054373,-281.786835,-0.204483,0.000000
1.810000,-0.036118,-281.786835,-0.010067,-0.007991,-0.202966,-0.160659,-0.008184,-2.029658,-281.786835,-0.201639,0.000000
1.980000,-0.043938,-281.786835,-0.009985,-0.007878,-0.200104,-0.195445,-0.009956,-2.001044,-281.786835,-0.198812,0.000000
2.150000,-0.060326,-281.742340,-0.009856,-0.007758,-0.197060,-0.268342,-0.013670,-1.970598,-281.742340,-0.195985,0.000000
2.320000,-0.045799,-281.831299,-0.009727,-0.007649,-0.194276,-0.203725,-0.010378,-1.942764,-281.831299,-0.193140,0.000000
2.490000,-0.077454,-281.831299,-0.009632,-0.007539,-0.191492,-0.344531,-0.017551,-1.914922,-281.831299,-0.190313,0.000000
2.660000,-0.094955,-281.831299,-0.009511,-0.007424,-0.188561,-0.422383,-0.021517,-1.885612,-281.831299,-0.187486,0.000000
2.830000,-0.055107,-281.875793,-0.009382,-0.007311,-0.185708,-0.245129,-0.012487,-1.857081,-281.875793,-0.184659,0.000000
3.000000,-0.077454,-281.875793,-0.009265,-0.007196,-0.182768,-0.344531,-0.017551,-1.827680,-281.875793,-0.181814,0.000000
3.170000,-0.071121,-281.920258,-0.009149,-0.007091,-0.180123,-0.316363,-0.016116,-1.801232,-281.920258,-0.178987,0.000000
3.340000,-0.064049,-281.875793,-0.009050,-0.006983,-0.177356,-0.284903,-0.014514,-1.773564,-281.875793,-0.176160,0.000000
3.510000,-0.059952,-281.875793,-0.008899,-0.006862,-0.174287,-0.266679,-0.013585,-1.742868,-281.875793,-0.173316,0.000000
3.680000,-0.061066,-281.920258,-0.008791,-0.006752,-0.171503,-0.271634,-0.013838,-1.715027,-281.920258,-0.170488,0.000000
3.850000,-0.075966,-281.875793,-0.008670,-0.006647,-0.168840,-0.337913,-0.017214,-1.688404,-281.875793,-0.167661,0.000000
4.020000,-0.074104,-282.053711,-0.008584,-0.006535,-0.165987,-0.329632,-0.016792,-1.659873,-282.053711,-0.164816,0.000000
4.190000,-0.030533,-282.009216,-0.008446,-0.006419,-0.163039,-0.135817,-0.006919,-1.630389,-282.009216,-0.161990,0.000000
4.360000,-0.042076,-281.964752,-0.008338,-0.006312,-0.160324,-0.187164,-0.009535,-1.603244,-281.964752,-0.159162,0.000000
4.530000,-0.053619,-281.964752,-0.008257,-0.006203,-0.157567,-0.238511,-0.012150,-1.575667,-281.964752,-0.156335,0.000000
4.700000,-0.043198,-282.009216,-0.008114,-0.006094,-0.154792,-0.192153,-0.009789,-1.547916,-282.009216,-0.153490,0.000000
4.870000,-0.059952,-282.009216,-0.007963,-0.005978,-0.151843,-0.266679,-0.013585,-1.518432,-282.009216,-0.150664,0.000000
5.040000,-0.077080,-282.009216,-0.007881,-0.005867,-0.149033,-0.342868,-0.017467,-1.490333,-282.009216,-0.147836,0.000000
5.210000,-0.099792,-282.009216,-0.007765,-0.005754,-0.146163,-0.443899,-0.022613,-1.461628,-282.009216,-0.144992,0.000000
5.380000,-0.124741,-282.098206,-0.007657,-0.005642,-0.143301,-0.554874,-0.028267,-1.433007,-282.098206,-0.142164,0.000000
5.550000,-0.077827,-282.053711,-0.007506,-0.005525,-0.140335,-0.346194,-0.017636,-1.403348,-282.053711,-0.139338,0.000000
5.720000,-0.040588,-282.098206,-0.007360,-0.005409,-0.137377,-0.180546,-0.009197,-1.373773,-282.098206,-0.136511,0.000000
5.890000,-0.039474,-282.142670,-0.007282,-0.005304,-0.134732,-0.175591,-0.008945,-1.347324,-282.142670,-0.133666,0.000000
6.060000,-0.023834,-282.098206,-0.007136,-0.005201,-0.132096,-0.106020,-0.005401,-1.320959,-282.098206,-0.130839,0.000000
6.230000,-0.042450,-282.053711,-0.007041,-0.005083,-0.129104,-0.188827,-0.009619,-1.291043,-282.053711,-0.128011,0.000000
6.400000,-0.051384,-282.187164,-0.006942,-0.004973,-0.126303,-0.228567,-0.011644,-1.263035,-282.187164,-0.125167,0.000000
6.570000,-0.048782,-282.187164,-0.006799,-0.004861,-0.123476,-0.216995,-0.011054,-1.234761,-282.187164,-0.122340,0.000000
6.740000,-0.077827,-282.187164,-0.006679,-0.004751,-0.120666,-0.346194,-0.017636,-1.206662,-282.187164,-0.119513,0.000000
6.910000,-0.067398,-282.142670,-0.006549,-0.004635,-0.117735,-0.299802,-0.015273,-1.177352,-282.142670,-0.116685,0.000000
7.080000,-0.058090,-282.142670,-0.006433,-0.004525,-0.114943,-0.258398,-0.013163,-1.149427,-282.142670,-0.113841,0.000000
7.250000,-0.075592,-282.231628,-0.006312,-0.004408,-0.111959,-0.336250,-0.017129,-1.119595,-282.231628,-0.111014,0.000000
7.420001,-0.047287,-282.276123,-0.006191,-0.004304,-0.109331,-0.210343,-0.010715,-1.093312,-282.276123,-0.108187,0.000000
7.590000,-0.072609,-282.231628,-0.006140,-0.004198,-0.106634,-0.322981,-0.016453,-1.066341,-282.231628,-0.105342,0.000000
7.760000,-0.048782,-282.231628,-0.005963,-0.004074,-0.103478,-0.216995,-0.011054,-1.034775,-282.231628,-0.102515,0.000000
7.930000,-0.042450,-282.276123,-0.005898,-0.003969,-0.100815,-0.188827,-0.009619,-1.008152,-282.276123,-0.099688,0.000000
8.100000,-0.059578,-282.231628,-0.005747,-0.003861,-0.098075,-0.265016,-0.013501,-0.980750,-282.231628,-0.096861,0.000000
8.270000,-0.068886,-282.276123,-0.005648,-0.003743,-0.095083,-0.306419,-0.015610,-0.950834,-282.276123,-0.094016,0.000000
8.440001,-0.013031,-282.276123,-0.005519,-0.003635,-0.092325,-0.057965,-0.002953,-0.923249,-282.276123,-0.091189,0.000000
8.610001,-0.021225,-282.320587,-0.005428,-0.003533,-0.089732,-0.094413,-0.004810,-0.897323,-282.320587,-0.088362,0.000000
8.780001,-0.025696,-282.276123,-0.005290,-0.003414,-0.086723,-0.114301,-0.005823,-0.867233,-282.276123,-0.085517,0.000000
8.950001,-0.055855,-282.320587,-0.005182,-0.003300,-0.083826,-0.248455,-0.012657,-0.838263,-282.320587,-0.082690,0.000000
9.120001,-0.051758,-282.320587,-0.005062,-0.003191,-0.081060,-0.230230,-0.011728,-0.810603,-282.320587,-0.079864,0.000000
9.290001,-0.069633,-282.365082,-0.004919,-0.003081,-0.078268,-0.309745,-0.015779,-0.782678,-282.365082,-0.077036,0.000000
9.460000,-0.099426,-282.365082,-0.004820,-0.002966,-0.075328,-0.442270,-0.022530,-0.753277,-282.365082,-0.074192,0.000000
9.630000,-0.126236,-282.409546,-0.004700,-0.002854,-0.072483,-0.561526,-0.028605,-0.724830,-282.409546,-0.071364,0.000000
9.800000,-0.049522,-282.365082,-0.004557,-0.002732,-0.069396,-0.220287,-0.011222,-0.693960,-282.365082,-0.068537,0.000000
9.970000,-0.037979,-282.409546,-0.004467,-0.002623,-0.066621,-0.168940,-0.008606,-0.666210,-282.409546,-0.065693,0.000000
10.140000,-0.000374,-282.365082,-0.004350,-0.002523,-0.064088,-0.001663,-0.000085,-0.640881,-282.365082,-0.062866,0.000000
10.310000,-0.035744,-282.409546,-0.004225,-0.002411,-0.061235,-0.158996,-0.008100,-0.612351,-282.409546,-0.060038,0.000000
10.480000,-0.040962,-282.498535,-0.004130,-0.002294,-0.058261,-0.182209,-0.009282,-0.582609,-282.498535,-0.057211,0.000000
10.650001,-0.043198,-282.498535,-0.004014,-0.002187,-0.055537,-0.192153,-0.009789,-0.555373,-282.498535,-0.054367,0.000000
10.820001,-0.037239,-282.498535,-0.003876,-0.002074,-0.052684,-0.165648,-0.008438,-0.526842,-282.498535,-0.051540,0.000000
10.990001,-0.062187,-282.542999,-0.003760,-0.001962,-0.049831,-0.276622,-0.014092,-0.498312,-282.542999,-0.048712,0.000000
11.160001,-0.047661,-282.498535,-0.003639,-0.001846,-0.046900,-0.212006,-0.010800,-0.469001,-282.498535,-0.045868,0.000000
11.330001,-0.053993,-282.542999,-0.003535,-0.001744,-0.044289,-0.240174,-0.012235,-0.442893,-282.542999,-0.043041,0.000000
11.500001,-0.053246,-282.587494,-0.003423,-0.001625,-0.041272,-0.236848,-0.012066,-0.412720,-282.587494,-0.040214,0.000000
11.670001,-0.040588,-282.587494,-0.003294,-0.001516,-0.038505,-0.180546,-0.009197,-0.385053,-282.587494,-0.037369,0.000000
11.840000,-0.042076,-282.542999,-0.003195,-0.001408,-0.035773,-0.187164,-0.009535,-0.357733,-282.542999,-0.034542,0.000000
12.010000,-0.064049,-282.542999,-0.003070,-0.001291,-0.032790,-0.284903,-0.014514,-0.327901,-282.542999,-0.031715,0.000000
12.180000,-0.041336,-282.631958,-0.002962,-0.001182,-0.030032,-0.183872,-0.009367,-0.300324,-282.631958,-0.028888,0.000000
12.350000,-0.056969,-282.631958,-0.002841,-0.001072,-0.027222,-0.253409,-0.012909,-0.272225,-282.631958,-0.026043,0.000000
12.520000,0.001862,-282.676453,-0.002708,-0.000953,-0.024196,0.008281,0.000422,-0.241961,-282.676453,-0.023216,0.000000
12.690001,-0.003349,-282.676453,-0.002621,-0.000851,-0.021620,-0.014898,-0.000759,-0.216201,-282.676453,-0.020388,0.000000
12.860001,-0.000748,-282.676453,-0.002514,-0.000745,-0.018932,-0.003326,-0.000169,-0.189320,-282.676453,-0.017545,0.000000
13.030001,-0.003723,-282.720917,-0.002371,-0.000623,-0.015836,-0.016561,-0.000844,-0.158360,-282.720917,-0.014717,0.000000
13.200001,-0.030533,-282.720917,-0.002251,-0.000510,-0.012956,-0.135817,-0.006919,-0.129565,-282.720917,-0.011890,0.000000
13.370001,0.005211,-282.720917,-0.002130,-0.000404,-0.010268,0.023179,0.001181,-0.102684,-282.720917,-0.009063,0.000000
13.540001,0.018250,-282.676453,-0.002035,-0.000292,-0.007406,0.081178,0.004135,-0.074063,-282.676453,-0.006219,0.000000
13.710001,0.077080,-282.720917,-0.001893,-0.000177,-0.004484,0.342868,0.017467,-0.044836,-282.720917,-0.003391,0.000000
13.880001,0.306091,-282.720917,-0.001772,-0.000061,-0.001562,1.361562,0.069361,-0.015616,-282.720917,-0.000564,0.000000
14.050000,0.642342,-282.765411,-0.001681,0.000055,0.001396,2.857278,0.145557,0.013959,-282.765411,0.002281,0.000000
14.220000,0.613297,-282.854370,-0.001656,-0.000000,-0.000000,2.728079,0.138975,-0.000000,-282.854370,0.000191,0.000000
14.390000,0.582016,-282.765411,-0.001625,-0.000000,-0.000009,2.588936,0.131887,-0.000091,-282.765411,0.000191,0.000000
14.560000,0.567123,-282.809875,-0.001630,-0.000000,-0.000009,2.522691,0.128512,-0.000091,-282.809875,0.000191,0.000000
14.730000,0.581650,-282.809875,-0.001669,-0.000000,-0.000009,2.587307,0.131804,-0.000091,-282.809875,0.000425,0.000000
14.900001,0.541428,-282.854370,-0.001651,-0.000000,-0.000000,2.408390,0.122689,-0.000000,-282.854370,0.000711,0.000000
15.070001,0.535469,-282.809875,-0.001617,-0.000000,-0.000000,2.381885,0.121339,-0.000000,-282.809875,0.000997,0.000000
15.240001,0.511269,-282.809875,-0.001625,-0.000000,-0.000000,2.274236,0.115855,-0.000000,-282.809875,0.001283,0.000000
15.410001,0.719795,-282.854370,-0.001630,0.000031,0.000798,3.201809,0.163108,0.007979,-282.854370,0.001561,0.000000
15.580001,0.725380,-282.898834,-0.001617,0.000032,0.000815,3.226651,0.164373,0.008153,-282.898834,0.001847,0.000000
15.750001,0.899651,-282.898834,-0.001604,0.000054,0.001370,4.001846,0.203864,0.013701,-282.898834,0.002133,0.000000
15.920001,0.973007,-282.943329,-0.001595,0.000065,0.001656,4.328152,0.220487,0.016563,-282.943329,0.002411,0.000000
16.090000,0.999451,-282.854370,-0.001591,0.000071,0.001812,4.445779,0.226479,0.018122,-282.854370,0.002697,0.000000
16.260000,1.101852,-282.854370,-0.001569,0.000081,0.002055,4.901284,0.249683,0.020552,-282.854370,0.002983,0.000000
16.430000,1.222870,-282.943329,-0.001569,0.000099,0.002524,5.439597,0.277106,0.025238,-282.943329,0.003260,0.000000
16.600000,1.290642,-282.943329,-0.001548,0.000112,0.002845,5.741061,0.292464,0.028447,-282.943329,0.003547,0.000000
16.770000,1.358788,-282.943329,-0.001544,0.000123,0.003113,6.044189,0.307906,0.031135,-282.943329,0.003833,0.000000
16.940001,1.433632,-283.032288,-0.001518,0.000133,0.003382,6.377113,0.324866,0.033822,-283.032288,0.004110,0.000000
17.110001,1.444435,-282.987823,-0.001544,0.000138,0.003503,6.425169,0.327314,0.035033,-282.987823,0.004397,0.000000
17.280001,1.572533,-283.032288,-0.001518,0.000149,0.003772,6.994975,0.356341,0.037720,-283.032288,0.004683,0.000000
17.450001,1.688713,-282.987823,-0.001475,0.000159,0.004032,7.511771,0.382668,0.040324,-282.987823,0.004960,0.000000
17.620001,1.867073,-283.032288,-0.001475,0.000176,0.004475,8.305156,0.423085,0.044745,-283.032288,0.005247,0.000000
17.790001,1.939316,-283.032288,-0.001457,0.000188,0.004778,8.626508,0.439455,0.047781,-283.032288,0.005533,0.000000
17.960001,2.014908,-283.032288,-0.001466,0.000197,0.005004,8.962758,0.456585,0.050036,-283.032288,0.005811,0.000000
18.130001,2.107628,-283.121246,-0.001444,0.000204,0.005177,9.375197,0.477595,0.051770,-283.121246,0.006097,0.000000
18.300001,2.223061,-283.076782,-0.001427,0.000212,0.005394,9.888667,0.503753,0.053942,-283.076782,0.006383,0.000000
18.470001,2.512772,-283.076782,-0.001414,0.000232,0.005897,11.177366,0.569402,0.058969,-283.076782,0.006660,0.000000
18.640001,2.605865,-283.121246,-0.001401,0.000244,0.006209,11.591469,0.590498,0.062095,-283.121246,0.006946,0.000000
18.810001,2.668419,-283.121246,-0.001423,0.000252,0.006400,11.869720,0.604672,0.064003,-283.121246,0.007233,0.000000
18.980001,2.850883,-283.210205,-0.001393,0.000263,0.006669,12.681363,0.646019,0.066690,-283.210205,0.007510,0.000000
19.150002,2.928337,-283.165741,-0.001371,0.000271,0.006895,13.025894,0.663571,0.068946,-283.165741,0.007796,0.000000
19.320002,3.107452,-283.121246,-0.001388,0.000281,0.007128,13.822639,0.704159,0.071285,-283.121246,0.008082,0.000000
19.490002,3.248207,-283.165741,-0.001371,0.000292,0.007424,14.448747,0.736054,0.074237,-283.165741,0.008360,0.000000
19.660002,3.493599,-283.210205,-0.001362,0.000301,0.007649,15.540304,0.791661,0.076485,-283.210205,0.008646,0.000000
19.830002,3.699890,-283.343658,-0.001358,0.000315,0.008013,16.457933,0.838407,0.080134,-283.343658,0.008932,0.000000
20.000000,3.856659,-283.254700,-0.001362,0.000324,0.008222,17.155275,0.873931,0.082215,-283.254700,0.009210,0.000000
20.170000,4.070030,-283.299164,-0.001315,0.000332,0.008430,18.104399,0.922282,0.084297,-283.299164,0.009496,0.000000
20.340000,4.262177,-283.254700,-0.001332,0.000342,0.008689,18.959108,0.965823,0.086894,-283.254700,0.009782,0.000000
20.510000,4.802116,-283.299164,-0.001298,0.000366,0.009288,21.360880,1.088175,0.092881,-283.299164,0.010059,0.000000
20.680000,4.983459,-283.254700,-0.001289,0.000376,0.009557,22.167536,1.129268,0.095569,-283.254700,0.010346,0.000000
20.850000,5.237045,-283.343658,-0.001298,0.000387,0.009817,23.295542,1.186731,0.098173,-283.343658,0.010632,0.000000
21.020000,5.374077,-283.254700,-0.001281,0.000396,0.010069,23.905088,1.217783,0.100686,-283.254700,0.010910,0.000000
21.190001,5.592659,-283.299164,-0.001276,0.000404,0.010250,24.877390,1.267315,0.102503,-283.299164,0.011196,0.000000
21.360001,5.952377,-283.388153,-0.001263,0.000414,0.010519,26.477497,1.348828,0.105190,-283.388153,0.011482,0.000000
21.530001,5.940460,-283.388153,-0.001255,0.000420,0.010658,26.424486,1.346128,0.106583,-283.388153,0.011760,0.000000
21.700001,6.570885,-283.343658,-0.001237,0.000439,0.011161,29.228754,1.488984,0.111609,-283.343658,0.012046,0.000000
21.870001,6.844948,-283.343658,-0.001242,0.000450,0.011430,30.447849,1.551087,0.114296,-283.343658,0.012332,0.000000
22.040001,6.988312,-283.432617,-0.001237,0.000456,0.011595,31.085564,1.583574,0.115946,-283.432617,0.012609,0.000000
22.210001,7.122368,-283.477112,-0.001216,0.000461,0.011716,31.681875,1.613952,0.117158,-283.477112,0.012896,0.000000
22.380001,7.489899,-283.477112,-0.001199,0.000470,0.011950,33.316734,1.697235,0.119504,-283.477112,0.013182,0.000000
22.550001,8.530312,-283.432617,-0.001190,0.000497,0.012635,37.944721,1.932996,0.126355,-283.432617,0.013459,0.000000
22.720001,8.702721,-283.432617,-0.001216,0.000508,0.012896,38.711636,1.972065,0.128959,-283.432617,0.013745,0.000000
22.890001,8.868050,-283.477112,-0.001207,0.000513,0.013043,39.447056,2.009529,0.130427,-283.477112,0.014031,0.000000
23.060001,9.426613,-283.521576,-0.001181,0.000529,0.013424,41.931667,2.136101,0.134243,-283.521576,0.014309,0.000000
23.230001,9.691742,-283.521576,-0.001164,0.000540,0.013728,43.111023,2.196180,0.137278,-283.521576,0.014595,0.000000
23.400002,9.976974,-283.432617,-0.001134,0.000547,0.013901,44.379799,2.260815,0.139012,-283.432617,0.014881,0.000000
23.570002,10.388817,-283.477112,-0.001160,0.000558,0.014171,46.211765,2.354140,0.141706,-283.477112,0.015168,0.000000
23.740002,11.122025,-283.566071,-0.001147,0.000574,0.014578,49.473236,2.520287,0.145779,-283.566071,0.015445,0.000000
23.910002,11.360710,-283.610535,-0.001121,0.000583,0.014812,50.534962,2.574374,0.148118,-283.610535,0.015732,0.000000
24.080002,11.424019,-283.610535,-0.001138,0.000587,0.014899,50.816574,2.588720,0.148989,-283.610535,0.016018,0.000000
24.250002,11.709251,-283.610535,-0.001117,0.000597,0.015168,52.085350,2.653354,0.151676,-283.610535,0.016295,0.000000
24.420002,12.698273,-283.566071,-0.001121,0.000617,0.015679,56.484737,2.877470,0.156793,-283.566071,0.016582,0.000000
24.590002,13.451584,-283.610535,-0.001104,0.000631,0.016035,59.835632,3.048172,0.160351,-283.610535,0.016868,0.000000
24.760000,13.740547,-283.655029,-0.001091,0.000641,0.016278,61.121006,3.113652,0.162781,-283.655029,0.017145,0.000000
24.930000,13.686920,-283.610535,-0.001086,0.000646,0.016417,60.882462,3.101501,0.164166,-283.610535,0.017431,0.000000
25.100000,14.476349,-283.655029,-0.001082,0.000662,0.016806,64.394012,3.280387,0.168064,-283.655029,0.017717,0.000000
25.270000,14.855057,-283.699493,-0.001065,0.000672,0.017067,66.078590,3.366204,0.170668,-283.699493,0.017995,0.000000
25.440001,15.316795,-283.655029,-0.001082,0.000680,0.017283,68.132507,3.470835,0.172833,-283.655029,0.018281,0.000000
25.610001,16.314011,-283.743988,-0.001039,0.000699,0.017752,72.568344,3.696808,0.177519,-283.743988,0.018567,0.000000
25.780001,16.602226,-283.699493,-0.001048,0.000709,0.018003,73.850388,3.762118,0.180032,-283.699493,0.018845,0.000000
25.950001,16.710960,-283.743988,-0.001039,0.000714,0.018133,74.334061,3.786758,0.181334,-283.743988,0.019131,0.000000
26.120001,17.277336,-283.699493,-0.001039,0.000725,0.018420,76.853432,3.915100,0.184196,-283.699493,0.019417,0.000000
26.290001,17.519379,-283.743988,-0.001043,0.000734,0.018654,77.930092,3.969948,0.186542,-283.743988,0.019694,0.000000
26.460001,18.649155,-283.832947,-0.001000,0.000752,0.019096,82.955582,4.225959,0.190963,-283.832947,0.019980,0.000000
26.630001,18.960831,-283.743988,-0.001005,0.000763,0.019391,84.341988,4.296586,0.193908,-283.743988,0.020267,0.000000
26.800001,19.327995,-283.788483,-0.000996,0.000771,0.019582,85.975220,4.379786,0.195815,-283.788483,0.020544,0.000000
26.970001,19.990074,-283.788483,-0.000987,0.000785,0.019929,88.920288,4.529816,0.199290,-283.788483,0.020831,0.000000
27.140001,20.390747,-283.788483,-0.000983,0.000792,0.020120,90.702576,4.620609,0.201197,-283.788483,0.021117,0.000000
27.310001,20.965691,-283.832947,-0.000983,0.000805,0.020458,93.260048,4.750894,0.204581,-283.832947,0.021394,0.000000
27.480001,21.899597,-283.832947,-0.000970,0.000821,0.020848,97.414276,4.962520,0.208480,-283.832947,0.021681,0.000000
27.650002,22.375114,-283.877441,-0.000961,0.000830,0.021082,99.529480,5.070273,0.210819,-283.877441,0.021967,0.000000
27.820002,22.557205,-283.877441,-0.000979,0.000836,0.021229,100.339462,5.111536,0.212295,-283.877441,0.022245,0.000000
27.990002,22.700195,-283.921906,-0.000970,0.000841,0.021368,100.975510,5.143938,0.213680,-283.921906,0.022531,0.000000
28.160002,23.623680,-283.921906,-0.000931,0.000855,0.021724,105.083374,5.353203,0.217238,-283.921906,0.022817,0.000000
28.330002,24.965714,-283.877441,-0.000936,0.000877,0.022270,111.053040,5.657311,0.222703,-283.877441,0.023094,0.000000
28.500002,25.284836,-283.966400,-0.000931,0.000885,0.022469,112.472565,5.729626,0.224694,-283.966400,0.023380,0.000000
28.670002,25.922340,-283.921906,-0.000905,0.000897,0.022773,115.308327,5.874086,0.227730,-283.921906,0.023666,0.000000
28.840002,26.358383,-284.010864,-0.000918,0.000908,0.023068,117.247948,5.972895,0.230682,-284.010864,0.023944,0.000000
29.010002,26.835022,-284.055359,-0.000914,0.000917,0.023294,119.368141,6.080903,0.232938,-284.055359,0.024230,0.000000
29.180002,26.957161,-284.010864,-0.000880,0.000924,0.023458,119.911438,6.108580,0.234580,-284.010864,0.024516,0.000000
29.350002,27.831490,-283.966400,-0.000888,0.000937,0.023788,123.800652,6.306705,0.237881,-283.966400,0.024794,0.000000
29.520000,28.652573,-284.055359,-0.000918,0.000949,0.024100,127.453011,6.492766,0.240999,-284.055359,0.025080,0.000000
29.690001,28.968719,-284.010864,-0.000884,0.000956,0.024291,128.859299,6.564406,0.242907,-284.010864,0.025366,0.000000
29.860001,29.284485,-284.055359,-0.000884,0.000963,0.024464,130.263901,6.635959,0.244640,-284.055359,0.025643,0.000000
30.030001,30.137962,-284.010864,-0.000875,0.000977,0.024820,134.060349,6.829360,0.248198,-284.010864,0.025930,0.000000
30.200001,30.765785,-284.099823,-0.000867,0.000988,0.025106,136.853043,6.971627,0.251060,-284.099823,0.026216,0.000000
30.370001,31.971901,-284.055359,-0.000849,0.001007,0.025575,142.218124,7.244936,0.255745,-284.055359,0.026494,0.000000
30.540001,32.954590,-284.099823,-0.000841,0.001021,0.025939,146.589340,7.467617,0.259386,-284.099823,0.026780,0.000000
30.710001,33.164612,-284.144318,-0.000849,0.001028,0.026104,147.523560,7.515208,0.261037,-284.144318,0.027066,0.000000
30.880001,33.632309,-284.144318,-0.000828,0.001040,0.026407,149.603989,7.621190,0.264072,-284.144318,0.027344,0.000000
31.050001,34.007286,-284.144318,-0.000841,0.001046,0.026581,151.271957,7.706161,0.265806,-284.144318,0.027630,0.000000
31.220001,34.600853,-284.144318,-0.000836,0.001056,0.026824,153.912277,7.840665,0.268236,-284.144318,0.027916,0.000000
31.390001,35.432358,-284.188782,-0.000836,0.001072,0.027231,157.610992,8.029087,0.272308,-284.188782,0.028194,0.000000
31.560001,36.721138,-284.188782,-0.000789,0.001086,0.027595,163.343781,8.321129,0.275949,-284.188782,0.028480,0.000000
31.730001,36.887215,-284.099823,-0.000811,0.001094,0.027795,164.082520,8.358762,0.277948,-284.099823,0.028766,0.000000
31.900002,37.504234,-284.233276,-0.000798,0.001105,0.028072,166.827164,8.498581,0.280718,-284.233276,0.029052,0.000000
32.070000,39.003784,-284.188782,-0.000793,0.001124,0.028558,173.497498,8.838384,0.285578,-284.188782,0.029329,0.000000
32.240002,39.639420,-284.322235,-0.000763,0.001135,0.028818,176.324951,8.982421,0.288182,-284.322235,0.029615,0.000000
32.410000,40.133186,-284.277771,-0.000793,0.001145,0.029078,178.521332,9.094310,0.290778,-284.277771,0.029902,0.000000
32.580002,40.740524,-284.233276,-0.000759,0.001154,0.029312,181.222900,9.231935,0.293125,-284.233276,0.030179,0.000000
32.750000,41.084602,-284.277771,-0.000780,0.001161,0.029494,182.753433,9.309904,0.294942,-284.277771,0.030465,0.000000
32.920002,41.721359,-284.277771,-0.000755,0.001172,0.029772,185.585876,9.454195,0.297720,-284.277771,0.030752,0.000000
33.090000,42.312683,-284.233276,-0.000763,0.001182,0.030014,188.216217,9.588191,0.300142,-284.233276,0.031029,0.000000
33.260002,43.778717,-284.366730,-0.000746,0.001200,0.030492,194.737457,9.920399,0.304919,-284.366730,0.031315,0.000000
33.430000,44.349930,-284.277771,-0.000755,0.001209,0.030717,197.278336,10.049838,0.307167,-284.277771,0.031602,0.000000
33.600002,44.863060,-284.366730,-0.000724,0.001217,0.030908,199.560852,10.166115,0.309082,-284.366730,0.031879,0.000000
33.770000,45.221657,-284.366730,-0.000742,0.001227,0.031168,201.155975,10.247375,0.311679,-284.366730,0.032166,0.000000
33.940002,46.090401,-284.411194,-0.000742,0.001241,0.031515,205.020340,10.444234,0.315145,-284.411194,0.032452,0.000000
34.110001,47.659950,-284.455688,-0.000742,0.001257,0.031940,212.002045,10.799899,0.319400,-284.455688,0.032729,0.000000
34.280003,48.543221,-284.411194,-0.000711,0.001269,0.032244,215.931030,11.000051,0.322435,-284.411194,0.033015,0.000000
34.450001,49.243279,-284.366730,-0.000711,0.001279,0.032495,219.045044,11.158687,0.324948,-284.366730,0.033301,0.000000
34.620003,49.243652,-284.411194,-0.000716,0.001282,0.032564,219.046707,11.158772,0.325645,-284.411194,0.033579,0.000000
34.790001,49.905357,-284.500153,-0.000694,0.001296,0.032920,221.990112,11.308716,0.329195,-284.500153,0.033865,0.000000
34.960003,50.610260,-284.500153,-0.000686,0.001302,0.033059,225.125687,11.468449,0.330588,-284.500153,0.034151,0.000000
35.130001,51.069763,-284.455688,-0.000681,0.001309,0.033258,227.169647,11.572574,0.332579,-284.455688,0.034429,0.000000
35.300003,52.231194,-284.411194,-0.000690,0.001324,0.033639,232.335953,11.835758,0.336394,-284.411194,0.034715,0.000000
35.470001,52.829224,-284.500153,-0.000686,0.001332,0.033839,234.996124,11.971273,0.338392,-284.500153,0.035001,0.000000
35.640003,53.282402,-284.455688,-0.000677,0.001340,0.034038,237.011963,12.073964,0.340383,-284.455688,0.035279,0.000000
35.810001,54.894035,-284.544647,-0.000677,0.001360,0.034550,244.180862,12.439166,0.345500,-284.544647,0.035565,0.000000
35.980003,56.755524,-284.500153,-0.000668,0.001379,0.035036,252.461182,12.860986,0.350360,-284.500153,0.035851,0.000000
36.150002,57.744171,-284.500153,-0.000642,0.001392,0.035365,256.858887,13.085016,0.353653,-284.500153,0.036128,0.000000
36.320004,58.607330,-284.544647,-0.000642,0.001404,0.035661,260.698425,13.280611,0.356605,-284.544647,0.036414,0.000000
36.490002,58.934647,-284.544647,-0.000660,0.001409,0.035790,262.154388,13.354781,0.357900,-284.544647,0.036701,0.000000
36.660000,59.358032,-284.633606,-0.000629,0.001418,0.036016,264.037720,13.450722,0.360155,-284.633606,0.036978,0.000000
36.830002,60.252472,-284.589111,-0.000642,0.001428,0.036276,268.016388,13.653405,0.362759,-284.589111,0.037265,0.000000
37.000000,60.322853,-284.544647,-0.000638,0.001433,0.036389,268.329437,13.669353,0.363887,-284.544647,0.037551,0.000000
37.170002,62.733215,-284.589111,-0.000617,0.001458,0.037031,279.051270,14.215550,0.370307,-284.589111,0.037829,0.000000
37.340000,63.493225,-284.678101,-0.000634,0.001467,0.037265,282.431976,14.387771,0.372646,-284.678101,0.038115,0.000000
37.510002,63.886078,-284.678101,-0.000599,0.001474,0.037430,284.179474,14.476792,0.374296,-284.678101,0.038401,0.000000
37.680000,64.736954,-284.678101,-0.000617,0.001485,0.037707,287.964355,14.669603,0.377066,-284.678101,0.038678,0.000000
37.850002,66.414490,-284.633606,-0.000591,0.001503,0.038167,295.426392,15.049738,0.381669,-284.633606,0.038965,0.000000
38.020000,67.392334,-284.678101,-0.000617,0.001514,0.038453,299.776062,15.271321,0.384530,-284.678101,0.039251,0.000000
38.190002,67.243027,-284.767059,-0.000591,0.001507,0.038271,299.111908,15.237488,0.382706,-284.767059,0.038479,0.000000
38.360001,66.966354,-284.722565,-0.000586,0.001506,0.038262,297.881226,15.174792,0.382623,-284.722565,0.038479,0.000000
38.530003,66.714630,-284.678101,-0.000582,0.001506,0.038262,296.761505,15.117751,0.382623,-284.678101,0.038262,0.000000
38.700001,66.503494,-284.722565,-0.000582,0.001506,0.038253,295.822327,15.069907,0.382532,-284.722565,0.038262,0.000000
38.870003,66.320648,-284.811523,-0.000586,0.001506,0.038245,295.008972,15.028474,0.382448,-284.811523,0.038262,0.000000
39.040001,66.157928,-284.856018,-0.000599,0.001506,0.038245,294.285156,14.991601,0.382448,-284.856018,0.038262,0.000000
39.210003,66.028717,-284.811523,-0.000591,0.001506,0.038245,293.710388,14.962321,0.382448,-284.811523,0.038262,0.000000
39.380001,65.906952,-284.811523,-0.000591,0.001506,0.038245,293.168762,14.934729,0.382448,-284.811523,0.038262,0.000000
39.550003,65.798584,-284.811523,-0.000595,0.001506,0.038245,292.686707,14.910172,0.382448,-284.811523,0.038262,0.000000
39.720001,65.690979,-284.900482,-0.000586,0.001506,0.038245,292.208069,14.885788,0.382448,-284.900482,0.038262,0.000000
39.890003,65.595642,-284.900482,-0.000560,0.001506,0.038245,291.783997,14.864184,0.382448,-284.900482,0.038262,0.000000
40.060001,65.495850,-284.856018,-0.000569,0.001505,0.038236,291.340088,14.841572,0.382358,-284.856018,0.038262,0.000000
40.230003,65.428818,-284.900482,-0.000595,0.001505,0.038236,291.041931,14.826382,0.382358,-284.900482,0.038262,0.000000
40.400002,65.356583,-284.856018,-0.000586,0.001505,0.038236,290.720612,14.810014,0.382358,-284.856018,0.038262,0.000000
40.570004,65.280991,-284.989441,-0.000569,0.001505,0.038236,290.384338,14.792884,0.382358,-284.989441,0.038262,0.000000
40.740002,65.226990,-284.944977,-0.000582,0.001505,0.038236,290.144135,14.780647,0.382358,-284.944977,0.038262,0.000000
40.910004,65.147308,-284.989441,-0.000573,0.001505,0.038236,289.789703,14.762590,0.382358,-284.989441,0.038262,0.000000
41.080002,65.116776,-284.900482,-0.000586,0.001505,0.038236,289.653870,14.755672,0.382358,-284.900482,0.038262,0.000000
41.250004,65.039688,-284.900482,-0.000560,0.001505,0.038236,289.310974,14.738203,0.382358,-284.900482,0.038262,0.000000
41.420002,65.003571,-284.944977,-0.000569,0.001505,0.038236,289.150330,14.730020,0.382358,-284.944977,0.038262,0.000000
41.590000,64.939896,-284.989441,-0.000578,0.001505,0.038236,288.867096,14.715591,0.382358,-284.989441,0.038262,0.000000
41.760002,64.904144,-285.033936,-0.000586,0.001505,0.038236,288.708038,14.707489,0.382358,-285.033936,0.038262,0.000000
41.930000,64.856491,-284.989441,-0.000569,0.001505,0.038236,288.496094,14.696691,0.382358,-284.989441,0.038262,0.000000
42.100002,64.824463,-284.989441,-0.000586,0.001505,0.038236,288.353607,14.689433,0.382358,-284.989441,0.038262,0.000000
42.270000,64.774185,-285.033936,-0.000582,0.001505,0.038236,288.129974,14.678040,0.382358,-285.033936,0.038262,0.000000
42.440002,64.739929,-285.078430,-0.000573,0.001505,0.038236,287.977600,14.670278,0.382358,-285.078430,0.038262,0.000000
42.610001,64.693756,-285.033936,-0.000578,0.001505,0.038236,287.772186,14.659815,0.382358,-285.033936,0.038262,0.000000
42.780003,64.663971,-285.122894,-0.000560,0.001505,0.038236,287.639709,14.653065,0.382358,-285.122894,0.038262,0.000000
42.950001,64.619278,-285.078430,-0.000569,0.001505,0.038236,287.440918,14.642938,0.382358,-285.078430,0.038262,0.000000
43.120003,64.601776,-285.122894,-0.000548,0.001505,0.038236,287.363037,14.638972,0.382358,-285.122894,0.038262,0.000000
43.290001,64.557846,-285.211853,-0.000569,0.001505,0.038236,287.167633,14.629017,0.382358,-285.211853,0.038262,0.000000
43.460003,64.532516,-285.078430,-0.000591,0.001505,0.038236,287.054962,14.623278,0.382358,-285.078430,0.038262,0.000000
43.630001,64.502365,-285.122894,-0.000586,0.001505,0.038236,286.920837,14.616445,0.382358,-285.122894,0.038262,0.000000
43.800003,64.459167,-285.167389,-0.000560,0.001505,0.038236,286.728699,14.606656,0.382358,-285.167389,0.038262,0.000000
43.970001,64.436081,-285.167389,-0.000560,0.001505,0.038236,286.626007,14.601424,0.382358,-285.167389,0.038262,0.000000
44.140003,64.417084,-285.211853,-0.000586,0.001505,0.038236,286.541504,14.597119,0.382358,-285.211853,0.038262,0.000000
44.310001,64.393250,-285.211853,-0.000578,0.001505,0.038236,286.435486,14.591719,0.382358,-285.211853,0.038262,0.000000
44.480003,64.360855,-285.211853,-0.000556,0.001505,0.038236,286.291382,14.584378,0.382358,-285.211853,0.038262,0.000000
44.650002,64.343353,-285.167389,-0.000582,0.001505,0.038236,286.213531,14.580413,0.382358,-285.167389,0.038262,0.000000
44.820004,64.309464,-285.256348,-0.000591,0.001505,0.038236,286.062775,14.572733,0.382358,-285.256348,0.038262,0.000000
44.990002,64.293823,-285.300812,-0.000569,0.001505,0.038236,285.993195,14.569189,0.382358,-285.300812,0.038262,0.000000
45.160004,64.256592,-285.345306,-0.000578,0.001505,0.038236,285.827606,14.560751,0.382358,-285.345306,0.038262,0.000000
45.330002,64.246170,-285.211853,-0.000569,0.001505,0.038236,285.781250,14.558390,0.382358,-285.211853,0.038262,0.000000
45.500004,64.218231,-285.300812,-0.000573,0.001505,0.038236,285.656952,14.552059,0.382358,-285.300812,0.038262,0.000000
45.670002,64.206696,-285.345306,-0.000586,0.001505,0.038236,285.605652,14.549445,0.382358,-285.345306,0.038262,0.000000
45.840004,64.169464,-285.389771,-0.000569,0.001505,0.038236,285.440033,14.541008,0.382358,-285.389771,0.038262,0.000000
46.010002,64.163879,-285.345306,-0.000591,0.001505,0.038236,285.415192,14.539742,0.382358,-285.345306,0.038262,0.000000
46.180000,64.136688,-285.345306,-0.000595,0.001505,0.038236,285.294250,14.533582,0.382358,-285.345306,0.038262,0.000000
46.350002,64.119934,-285.345306,-0.000569,0.001505,0.038236,285.219727,14.529785,0.382358,-285.345306,0.038262,0.000000
46.520000,64.098328,-285.389771,-0.000573,0.001505,0.038236,285.123596,14.524889,0.382358,-285.389771,0.038262,0.000000
46.690002,64.092377,-285.478729,-0.000586,0.001505,0.038236,285.097137,14.523540,0.382358,-285.478729,0.038262,0.000000
46.860001,64.058121,-285.434265,-0.000565,0.001505,0.038236,284.944763,14.515778,0.382358,-285.434265,0.038262,0.000000
47.030003,64.044342,-285.478729,-0.000599,0.001505,0.038236,284.883453,14.512656,0.382358,-285.478729,0.038262,0.000000
47.200001,64.030930,-285.478729,-0.000569,0.001505,0.038236,284.823792,14.509617,0.382358,-285.478729,0.038262,0.000000
47.370003,64.014923,-285.478729,-0.000586,0.001505,0.038236,284.752594,14.505988,0.382358,-285.478729,0.038262,0.000000
47.540001,64.000031,-285.523224,-0.000560,0.001505,0.038236,284.686340,14.502614,0.382358,-285.523224,0.038262,0.000000
47.710003,63.978806,-285.478729,-0.000569,0.001505,0.038236,284.591949,14.497805,0.382358,-285.478729,0.038262,0.000000
47.880001,63.968384,-285.478729,-0.000586,0.001505,0.038236,284.545593,14.495443,0.382358,-285.478729,0.038262,0.000000
48.050003,63.945663,-285.434265,-0.000578,0.001505,0.038236,284.444519,14.490294,0.382358,-285.434265,0.038262,0.000000
48.220001,63.919968,-285.567719,-0.000552,0.001505,0.038236,284.330231,14.484472,0.382358,-285.567719,0.038262,0.000000
48.390003,63.915497,-285.567719,-0.000573,0.001505,0.038236,284.310333,14.483459,0.382358,-285.567719,0.038262,0.000000
48.560001,63.897629,-285.567719,-0.000543,0.001505,0.038236,284.230835,14.479409,0.382358,-285.567719,0.038262,0.000000
48.730003,63.881989,-285.567719,-0.000569,0.001505,0.038236,284.161285,14.475865,0.382358,-285.567719,0.038262,0.000000
48.900002,63.871567,-285.567719,-0.000595,0.001505,0.038236,284.114929,14.473504,0.382358,-285.567719,0.038262,0.000000
49.070004,63.855545,-285.567719,-0.000582,0.001505,0.038236,284.043640,14.469872,0.382358,-285.567719,0.038262,0.000000
49.240002,63.852570,-285.656677,-0.000586,0.001505,0.038236,284.030426,14.469199,0.382358,-285.656677,0.038262,0.000000
49.410004,63.825760,-285.567719,-0.000569,0.001505,0.038236,283.911163,14.463124,0.382358,-285.567719,0.038262,0.000000
49.580002,63.818680,-285.612183,-0.000591,0.001505,0.038236,283.879669,14.461520,0.382358,-285.612183,0.038262,0.000000
49.750004,63.813477,-285.612183,-0.000582,0.001505,0.038236,283.856506,14.460340,0.382358,-285.612183,0.038262,0.000000
49.920002,63.792618,-285.745636,-0.000586,0.001505,0.038236,283.763733,14.455614,0.382358,-285.745636,0.038262,0.000000
50.090004,63.783310,-285.745636,-0.000573,0.001505,0.038236,283.722321,14.453505,0.382358,-285.745636,0.038262,0.000000
50.260002,63.759109,-285.701141,-0.000582,0.001505,0.038236,283.614685,14.448021,0.382358,-285.701141,0.038262,0.000000
50.430004,63.753143,-285.701141,-0.000569,0.001505,0.038236,283.588135,14.446669,0.382358,-285.701141,0.038262,0.000000
50.600002,63.744949,-285.701141,-0.000556,0.001505,0.038236,283.551697,14.444812,0.382358,-285.701141,0.038262,0.000000
50.770004,63.718140,-285.745636,-0.000552,0.001505,0.038236,283.432434,14.438737,0.382358,-285.745636,0.038262,0.000000
50.940002,63.725586,-285.790100,-0.000569,0.001505,0.038236,283.465576,14.440424,0.382358,-285.790100,0.038262,0.000000
51.110001,63.705475,-285.701141,-0.000560,0.001505,0.038236,283.376099,14.435867,0.382358,-285.701141,0.038262,0.000000
51.280003,63.687607,-285.745636,-0.000548,0.001505,0.038236,283.296631,14.431818,0.382358,-285.745636,0.038262,0.000000
51.450001,63.698029,-285.745636,-0.000591,0.001505,0.038236,283.342987,14.434179,0.382358,-285.745636,0.038262,0.000000
51.620003,63.667130,-285.834595,-0.000586,0.001505,0.038236,283.205536,14.427178,0.382358,-285.834595,0.038262,0.000000
51.790001,63.678299,-285.834595,-0.000556,0.001505,0.038236,283.255219,14.429709,0.382358,-285.834595,0.038262,0.000000
51.960003,63.648880,-285.834595,-0.000578,0.001505,0.038236,283.124359,14.423043,0.382358,-285.834595,0.038262,0.000000
52.130001,63.646652,-285.790100,-0.000578,0.001505,0.038236,283.114441,14.422538,0.382358,-285.790100,0.038262,0.000000
52.300003,63.629517,-285.879059,-0.000599,0.001505,0.038236,283.038239,14.418654,0.382358,-285.879059,0.038262,0.000000
52.470001,63.614624,-285.879059,-0.000578,0.001505,0.038236,282.971985,14.415279,0.382358,-285.879059,0.038262,0.000000
52.640003,63.610153,-285.879059,-0.000591,0.001505,0.038236,282.952087,14.414267,0.382358,-285.879059,0.038262,0.000000
52.810001,63.598618,-285.879059,-0.000556,0.001505,0.038236,282.900787,14.411653,0.382358,-285.879059,0.038262,0.000000
52.980003,63.591156,-285.879059,-0.000569,0.001505,0.038236,282.867584,14.409962,0.382358,-285.879059,0.038262,0.000000
53.150002,63.574783,-285.879059,-0.000586,0.001505,0.038236,282.794769,14.406252,0.382358,-285.879059,0.038262,0.000000
53.320004,63.579620,-285.923553,-0.000591,0.001505,0.038236,282.816284,14.407348,0.382358,-285.923553,0.038262,0.000000
53.490002,63.557648,-285.968048,-0.000595,0.001505,0.038236,282.718536,14.402369,0.382358,-285.968048,0.038262,0.000000
53.660004,63.555038,-285.923553,-0.000565,0.001505,0.038236,282.706940,14.401777,0.382358,-285.923553,0.038262,0.000000
53.830002,63.543503,-285.968048,-0.000569,0.001505,0.038236,282.655609,14.399164,0.382358,-285.968048,0.038262,0.000000
54.000004,63.529343,-285.923553,-0.000569,0.001505,0.038236,282.592621,14.395955,0.382358,-285.923553,0.038262,0.000000
54.170002,63.529343,-286.012512,-0.000578,0.001505,0.038236,282.592621,14.395955,0.382358,-286.012512,0.038262,0.000000
54.340004,63.504776,-286.057007,-0.000556,0.001505,0.038236,282.483337,14.390388,0.382358,-286.057007,0.038262,0.000000
54.510002,63.516312,-286.012512,-0.000560,0.001505,0.038236,282.534668,14.393003,0.382358,-286.012512,0.038262,0.000000
54.680004,63.493225,-286.012512,-0.000573,0.001505,0.038236,282.431976,14.387771,0.382358,-286.012512,0.038262,0.000000
54.850002,63.492859,-286.057007,-0.000573,0.001505,0.038236,282.430328,14.387688,0.382358,-286.057007,0.038262,0.000000
55.020004,63.475723,-286.057007,-0.000599,0.001505,0.038236,282.354126,14.383804,0.382358,-286.057007,0.038262,0.000000
55.190002,63.469772,-286.057007,-0.000569,0.001505,0.038236,282.327637,14.382456,0.382358,-286.057007,0.038262,0.000000
55.360004,63.468658,-286.012512,-0.000552,0.001505,0.038236,282.322693,14.382203,0.382358,-286.012512,0.038262,0.000000
55.530003,63.454132,-286.057007,-0.000586,0.001505,0.038236,282.258087,14.378912,0.382358,-286.057007,0.038262,0.000000
55.700001,63.450775,-286.057007,-0.000578,0.001505,0.038236,282.243134,14.378151,0.382358,-286.057007,0.038262,0.000000
55.870003,63.426575,-286.145966,-0.000573,0.001505,0.038236,282.135498,14.372667,0.382358,-286.145966,0.038262,0.000000
56.040001,63.433655,-286.234924,-0.000556,0.001505,0.038236,282.166992,14.374271,0.382358,-286.234924,0.038262,0.000000
56.210003,63.416519,-286.101471,-0.000569,0.001505,0.038236,282.090759,14.370389,0.382358,-286.101471,0.038262,0.000000
56.380001,63.406097,-286.101471,-0.000582,0.001505,0.038236,282.044403,14.368027,0.382358,-286.101471,0.038262,0.000000
56.550003,63.412796,-286.190430,-0.000539,0.001505,0.038236,282.074219,14.369545,0.382358,-286.190430,0.038262,0.000000
56.720001,63.373322,-286.190430,-0.000552,0.001505,0.038236,281.898621,14.360600,0.382358,-286.190430,0.038262,0.000000
56.890003,63.396790,-286.190430,-0.000573,0.001505,0.038236,282.002991,14.365917,0.382358,-286.190430,0.038262,0.000000
57.060001,63.382263,-286.190430,-0.000548,0.001505,0.038236,281.938385,14.362626,0.382358,-286.190430,0.038262,0.000000
57.230003,63.375565,-286.190430,-0.000573,0.001505,0.038236,281.908600,14.361108,0.382358,-286.190430,0.038262,0.000000
57.400002,63.365509,-286.234924,-0.000586,0.001505,0.038236,281.863861,14.358829,0.382358,-286.234924,0.038262,0.000000
57.570004,63.352478,-286.234924,-0.000569,0.001505,0.038236,281.805908,14.355877,0.382358,-286.234924,0.038262,0.000000
57.740002,63.353592,-286.279388,-0.000578,0.001505,0.038236,281.810852,14.356130,0.382358,-286.279388,0.038262,0.000000
57.910004,63.345398,-286.323883,-0.000560,0.001505,0.038236,281.774414,14.354272,0.382358,-286.323883,0.038262,0.000000
58.080002,63.327896,-286.279388,-0.000548,0.001505,0.038236,281.696564,14.350307,0.382358,-286.279388,0.038262,0.000000
58.250004,63.326401,-286.323883,-0.000552,0.001505,0.038236,281.689911,14.349967,0.382358,-286.323883,0.038262,0.000000
58.420002,63.324921,-286.323883,-0.000552,0.001505,0.038236,281.683319,14.349632,0.382358,-286.323883,0.038262,0.000000
58.590004,63.308899,-286.368378,-0.000569,0.001505,0.038236,281.612061,14.346002,0.382358,-286.368378,0.038262,0.000000
58.760002,63.302948,-286.368378,-0.000569,0.001505,0.038236,281.585571,14.344653,0.382358,-286.368378,0.038262,0.000000
58.930004,63.303314,-286.323883,-0.000569,0.001505,0.038236,281.587219,14.344736,0.382358,-286.323883,0.038262,0.000000
59.100002,63.293259,-286.323883,-0.000560,0.001505,0.038236,281.542480,14.342458,0.382358,-286.323883,0.038262,0.000000
59.270004,63.288055,-286.368378,-0.000586,0.001505,0.038236,281.519318,14.341278,0.382358,-286.368378,0.038262,0.000000
59.440002,63.273163,-286.412842,-0.000582,0.001505,0.038236,281.453094,14.337903,0.382358,-286.412842,0.038262,0.000000
59.610004,63.277252,-286.412842,-0.000569,0.001505,0.038236,281.471283,14.338831,0.382358,-286.412842,0.038262,0.000000
59.780003,63.270180,-286.412842,-0.000556,0.001505,0.038236,281.439819,14.337227,0.382358,-286.412842,0.038262,0.000000
59.950005,63.266083,-286.412842,-0.000560,0.001505,0.038236,281.421600,14.336299,0.382358,-286.412842,0.038262,0.000000
60.120003,63.256775,-286.501801,-0.000556,0.001505,0.038236,281.380188,14.334190,0.382358,-286.501801,0.038262,0.000000
60.290005,63.247467,-286.590759,-0.000573,0.001505,0.038236,281.338776,14.332081,0.382358,-286.590759,0.038262,0.000000
60.460003,63.240761,-286.501801,-0.000548,0.001505,0.038236,281.308960,14.330561,0.382358,-286.501801,0.038262,0.000000
60.630001,63.237785,-286.457336,-0.000556,0.001505,0.038236,281.295715,14.329887,0.382358,-286.457336,0.038262,0.000000
60.800003,63.223259,-286.546295,-0.000569,0.001505,0.038236,281.231110,14.326595,0.382358,-286.546295,0.038262,0.000000
60.970001,63.218048,-286.546295,-0.000582,0.001505,0.038236,281.207916,14.325415,0.382358,-286.546295,0.038262,0.000000
61.140003,63.215439,-286.590759,-0.000573,0.001505,0.038236,281.196320,14.324823,0.382358,-286.590759,0.038262,0.000000
61.310001,63.191238,-286.546295,-0.000604,0.001505,0.038236,281.088654,14.319339,0.382358,-286.546295,0.038262,0.000000
61.480003,63.211716,-286.590759,-0.000556,0.001505,0.038236,281.179749,14.323979,0.382358,-286.590759,0.038262,0.000000
61.650002,63.193840,-286.590759,-0.000543,0.001505,0.038236,281.100250,14.319929,0.382358,-286.590759,0.038262,0.000000
61.820004,63.190491,-286.635254,-0.000578,0.001505,0.038236,281.085327,14.319170,0.382358,-286.635254,0.038262,0.000000
61.990002,63.181183,-286.679718,-0.000565,0.001505,0.038236,281.043945,14.317060,0.382358,-286.679718,0.038262,0.000000
62.160004,63.182297,-286.635254,-0.000548,0.001505,0.038236,281.048889,14.317313,0.382358,-286.635254,0.038262,0.000000
62.330002,63.184158,-286.635254,-0.000573,0.001505,0.038236,281.057159,14.317735,0.382358,-286.635254,0.038262,0.000000
62.500004,63.158096,-286.635254,-0.000582,0.001505,0.038236,280.941254,14.311830,0.382358,-286.635254,0.038262,0.000000
62.670002,63.149155,-286.635254,-0.000535,0.001505,0.038236,280.901459,14.309803,0.382358,-286.635254,0.038262,0.000000
62.840004,63.154373,-286.679718,-0.000560,0.001505,0.038236,280.924683,14.310986,0.382358,-286.679718,0.038262,0.000000
63.010002,63.153252,-286.724213,-0.000552,0.001505,0.038236,280.919708,14.310731,0.382358,-286.724213,0.038262,0.000000
63.180004,63.138733,-286.635254,-0.000569,0.001505,0.038236,280.855103,14.307441,0.382358,-286.635254,0.038262,0.000000
63.350002,63.145432,-286.724213,-0.000560,0.001505,0.038236,280.884918,14.308959,0.382358,-286.724213,0.038262,0.000000
63.520004,63.136871,-286.768677,-0.000578,0.001505,0.038236,280.846832,14.307019,0.382358,-286.768677,0.038262,0.000000
63.690002,63.131287,-286.768677,-0.000573,0.001505,0.038236,280.821991,14.305754,0.382358,-286.768677,0.038262,0.000000
63.860004,63.124954,-286.768677,-0.000560,0.001505,0.038236,280.793823,14.304318,0.382358,-286.768677,0.038262,0.000000
64.030006,63.120483,-286.768677,-0.000560,0.001505,0.038236,280.773926,14.303306,0.382358,-286.768677,0.038262,0.000000
64.200005,63.103729,-286.768677,-0.000578,0.001505,0.038236,280.699402,14.299509,0.382358,-286.768677,0.038262,0.000000
64.370003,63.119736,-286.813171,-0.000586,0.001505,0.038236,280.770599,14.303137,0.382358,-286.813171,0.038262,0.000000
64.540001,63.097023,-286.813171,-0.000573,0.001505,0.038236,280.669586,14.297990,0.382358,-286.813171,0.038262,0.000000
64.710007,63.097023,-286.768677,-0.000573,0.001505,0.038236,280.669586,14.297990,0.382358,-286.768677,0.038262,0.000000
64.880005,63.103729,-286.857666,-0.000569,0.001505,0.038236,280.699402,14.299509,0.382358,-286.857666,0.038262,0.000000
65.050003,63.092560,-286.813171,-0.000569,0.001505,0.038236,280.649719,14.296978,0.382358,-286.813171,0.038262,0.000000
65.220001,63.086967,-286.857666,-0.000582,0.001505,0.038236,280.624847,14.295711,0.382358,-286.857666,0.038262,0.000000
65.389999,63.083992,-286.902130,-0.000560,0.001505,0.038236,280.611603,14.295037,0.382358,-286.902130,0.038262,0.000000
65.560005,63.079895,-286.902130,-0.000565,0.001505,0.038236,280.593384,14.294108,0.382358,-286.902130,0.038262,0.000000
65.730003,63.072823,-286.857666,-0.000560,0.001505,0.038236,280.561920,14.292506,0.382358,-286.857666,0.038262,0.000000
65.900002,63.070961,-286.902130,-0.000591,0.001505,0.038236,280.553650,14.292084,0.382358,-286.902130,0.038262,0.000000
66.070000,63.061653,-286.857666,-0.000586,0.001505,0.038236,280.512238,14.289975,0.382358,-286.857666,0.038262,0.000000
66.240005,63.070961,-286.902130,-0.000578,0.001505,0.038236,280.553650,14.292084,0.382358,-286.902130,0.038262,0.000000
66.410004,63.066490,-286.946625,-0.000565,0.001505,0.038236,280.533752,14.291071,0.382358,-286.946625,0.038262,0.000000
66.580002,63.063515,-286.946625,-0.000573,0.001505,0.038236,280.520538,14.290397,0.382358,-286.946625,0.038262,0.000000
66.750000,63.053459,-286.946625,-0.000556,0.001505,0.038236,280.475800,14.288118,0.382358,-286.946625,0.038262,0.000000
66.920006,63.051224,-286.946625,-0.000573,0.001505,0.038236,280.465851,14.287612,0.382358,-286.946625,0.038262,0.000000
67.090004,63.037071,-286.991089,-0.000552,0.001505,0.038236,280.402893,14.284405,0.382358,-286.991089,0.038262,0.000000
67.260002,63.039307,-287.035583,-0.000565,0.001505,0.038236,280.412842,14.284911,0.382358,-287.035583,0.038262,0.000000
67.430000,63.039680,-286.991089,-0.000560,0.001505,0.038236,280.414490,14.284995,0.382358,-286.991089,0.038262,0.000000
67.600006,63.026649,-287.035583,-0.000578,0.001505,0.038236,280.356537,14.282043,0.382358,-287.035583,0.038262,0.000000
67.770004,63.029625,-287.035583,-0.000548,0.001505,0.038236,280.369781,14.282717,0.382358,-287.035583,0.038262,0.000000
67.940002,63.025902,-287.080048,-0.000535,0.001505,0.038236,280.353210,14.281874,0.382358,-287.080048,0.038262,0.000000
68.110001,63.019943,-287.080048,-0.000578,0.001505,0.038236,280.326721,14.280523,0.382358,-287.080048,0.038262,0.000000
68.280006,63.013985,-287.080048,-0.000556,0.001505,0.038236,280.300201,14.279173,0.382358,-287.080048,0.038262,0.000000
68.450005,63.016220,-287.124542,-0.000578,0.001505,0.038236,280.310150,14.279679,0.382358,-287.124542,0.038262,0.000000
68.600006,63.007652,-287.080048,-0.000552,0.001505,0.038236,280.272034,14.277739,0.382358,-287.080048,0.038262,0.000000