File: Data/AD compression/AD membrane peeled punched 300N 1_07302024_195120.csv
Time (sec),S:Load (lbs),S:HL1 (DIM),S:LVDT (in),S:Position (in),Ch:Position (mm),Ch:Load (N),Ch:Stress (MPa),Ch:Strain (mm/mm),Ch:HL1 (DIM),Set Point (),Cycles ()
0.210000,-0.045059,-206.258163,-0.011012,-0.010639,-0.270220,-0.200433,-0.010211,-2.702195,-206.258163,-0.270020,0.000000
0.380000,-0.062187,-206.302658,-0.011046,-0.010639,-0.270220,-0.276622,-0.014092,-2.702195,-206.302658,-0.270020,0.000000
0.550000,-0.049522,-206.213684,-0.011025,-0.010553,-0.268042,-0.220287,-0.011222,-2.680425,-206.213684,-0.267453,0.000000
0.720000,-0.035378,-206.258163,-0.010990,-0.010467,-0.265857,-0.157367,-0.008017,-2.658571,-206.258163,-0.264608,0.000000
0.890000,-0.055855,-206.391617,-0.010891,-0.010351,-0.262917,-0.248455,-0.012657,-2.629170,-206.391617,-0.261781,0.000000
1.060000,-0.065163,-206.391617,-0.010757,-0.010238,-0.260038,-0.289858,-0.014766,-2.600382,-206.391617,-0.258954,0.000000
1.230000,-0.101288,-206.391617,-0.010611,-0.010135,-0.257419,-0.450551,-0.022952,-2.574190,-206.391617,-0.256127,0.000000
1.400000,-0.111336,-206.347137,-0.010533,-0.010021,-0.254531,-0.495246,-0.025229,-2.545312,-206.347137,-0.253282,0.000000
1.570000,-0.086761,-206.347137,-0.010404,-0.009900,-0.251461,-0.385934,-0.019660,-2.514609,-206.347137,-0.250455,0.000000
1.740000,-0.043198,-206.480576,-0.010287,-0.009791,-0.248703,-0.192153,-0.009789,-2.487032,-206.480576,-0.247628,0.000000
1.910000,-0.025696,-206.436096,-0.010179,-0.009693,-0.246214,-0.114301,-0.005823,-2.462142,-206.436096,-0.244784,0.000000
2.080000,-0.019737,-206.391617,-0.010089,-0.009581,-0.243370,-0.087796,-0.004473,-2.433695,-206.391617,-0.241956,0.000000
2.250000,-0.032768,-206.436096,-0.009951,-0.009463,-0.240361,-0.145760,-0.007425,-2.403605,-206.436096,-0.239129,0.000000
2.420000,-0.047287,-206.436096,-0.009835,-0.009345,-0.237352,-0.210343,-0.010715,-2.373515,-206.436096,-0.236302,0.000000
2.590000,-0.034256,-206.569534,-0.009727,-0.009235,-0.234576,-0.152378,-0.007763,-2.345764,-206.569534,-0.233458,0.000000
2.760000,-0.081924,-206.525055,-0.009597,-0.009123,-0.231732,-0.364418,-0.018564,-2.317317,-206.525055,-0.230630,0.000000
2.930000,-0.068520,-206.525055,-0.009455,-0.009009,-0.228818,-0.304790,-0.015527,-2.288181,-206.525055,-0.227803,0.000000
3.100000,-0.064423,-206.525055,-0.009378,-0.008907,-0.226234,-0.286566,-0.014598,-2.262338,-206.525055,-0.224959,0.000000
3.270000,-0.067398,-206.525055,-0.009253,-0.008785,-0.223146,-0.299802,-0.015273,-2.231461,-206.525055,-0.222132,0.000000
3.440000,-0.032021,-206.614014,-0.009132,-0.008683,-0.220544,-0.142435,-0.007256,-2.205443,-206.614014,-0.219304,0.000000
3.610000,-0.070381,-206.614014,-0.009011,-0.008576,-0.217821,-0.313071,-0.015949,-2.178215,-206.614014,-0.216477,0.000000
3.780000,-0.053993,-206.569534,-0.008882,-0.008457,-0.214803,-0.240174,-0.012235,-2.148034,-206.569534,-0.213632,0.000000
3.950000,-0.059578,-206.658493,-0.008778,-0.008346,-0.211993,-0.265016,-0.013501,-2.119935,-206.658493,-0.210806,0.000000
4.120000,-0.066284,-206.702972,-0.008662,-0.008235,-0.209175,-0.294847,-0.015020,-2.091753,-206.702972,-0.207978,0.000000
4.290000,-0.060326,-206.702972,-0.008541,-0.008119,-0.206227,-0.268342,-0.013670,-2.062268,-206.702972,-0.205134,0.000000
4.460000,-0.014893,-206.702972,-0.008429,-0.008009,-0.203417,-0.066245,-0.003375,-2.034169,-206.702972,-0.202306,0.000000
4.630000,-0.029793,-206.747467,-0.008295,-0.007908,-0.200858,-0.132525,-0.006751,-2.008583,-206.747467,-0.199480,0.000000
4.800000,-0.020477,-206.747467,-0.008183,-0.007790,-0.197858,-0.091088,-0.004640,-1.978577,-206.747467,-0.196635,0.000000
4.970000,-0.038727,-206.791946,-0.008080,-0.007678,-0.195022,-0.172265,-0.008776,-1.950220,-206.791946,-0.193808,0.000000
5.140000,-0.043938,-206.836426,-0.007950,-0.007562,-0.192074,-0.195445,-0.009956,-1.920736,-206.836426,-0.190980,0.000000
5.310000,-0.078201,-206.791946,-0.007812,-0.007455,-0.189351,-0.347857,-0.017721,-1.893507,-206.791946,-0.188154,0.000000
5.480000,-0.089371,-206.836426,-0.007722,-0.007343,-0.186506,-0.397541,-0.020252,-1.865060,-206.836426,-0.185309,0.000000
5.650000,-0.103149,-206.836426,-0.007614,-0.007231,-0.183661,-0.458832,-0.023374,-1.836613,-206.836426,-0.182482,0.000000
5.820000,-0.062927,-206.836426,-0.007502,-0.007110,-0.180583,-0.279914,-0.014260,-1.805826,-206.836426,-0.179655,0.000000
5.990000,-0.032394,-206.925385,-0.007325,-0.007002,-0.177860,-0.144098,-0.007341,-1.778598,-206.925385,-0.176811,0.000000
6.160000,-0.029793,-206.925385,-0.007269,-0.006904,-0.175353,-0.132525,-0.006751,-1.753534,-206.925385,-0.173983,0.000000
6.330000,-0.037239,-206.836426,-0.007136,-0.006789,-0.172448,-0.165648,-0.008438,-1.724481,-206.836426,-0.171156,0.000000
6.500000,-0.036865,-206.925385,-0.007036,-0.006670,-0.169422,-0.163985,-0.008354,-1.694217,-206.925385,-0.168329,0.000000
6.670001,-0.045425,-206.925385,-0.006929,-0.006561,-0.166647,-0.202062,-0.010294,-1.666467,-206.925385,-0.165485,0.000000
6.840000,-0.042824,-207.058823,-0.006786,-0.006448,-0.163776,-0.190490,-0.009704,-1.637762,-207.058823,-0.162657,0.000000
7.010000,-0.068520,-206.969864,-0.006622,-0.006336,-0.160931,-0.304790,-0.015527,-1.609315,-206.969864,-0.159830,0.000000
7.180000,-0.052132,-207.014343,-0.006549,-0.006220,-0.158000,-0.231893,-0.011813,-1.580004,-207.014343,-0.156985,0.000000
7.350000,-0.044685,-207.103302,-0.006416,-0.006123,-0.155520,-0.198770,-0.010126,-1.555198,-207.103302,-0.154158,0.000000
7.520000,-0.062561,-207.058823,-0.006303,-0.005998,-0.152346,-0.278285,-0.014177,-1.523458,-207.058823,-0.151331,0.000000
7.690001,-0.028671,-207.103302,-0.006200,-0.005894,-0.149709,-0.127536,-0.006497,-1.497092,-207.103302,-0.148504,0.000000
7.860001,-0.069260,-207.058823,-0.006075,-0.005785,-0.146952,-0.308082,-0.015694,-1.469516,-207.058823,-0.145659,0.000000
8.030001,-0.068520,-207.103302,-0.005954,-0.005672,-0.144073,-0.304790,-0.015527,-1.440728,-207.103302,-0.142832,0.000000
8.200001,-0.048035,-207.103302,-0.005842,-0.005559,-0.141211,-0.213669,-0.010885,-1.412107,-207.103302,-0.140006,0.000000
8.370001,-0.045799,-207.103302,-0.005743,-0.005446,-0.138340,-0.203725,-0.010378,-1.383402,-207.103302,-0.137161,0.000000
8.540000,-0.029045,-207.192276,-0.005609,-0.005329,-0.135365,-0.129199,-0.006582,-1.353653,-207.192276,-0.134333,0.000000
8.710000,-0.007446,-207.192276,-0.005501,-0.005228,-0.132781,-0.033123,-0.001687,-1.327809,-207.192276,-0.131506,0.000000
8.880000,-0.011169,-207.192276,-0.005385,-0.005121,-0.130075,-0.049684,-0.002531,-1.300755,-207.192276,-0.128680,0.000000
9.050000,-0.021225,-207.236755,-0.005264,-0.005001,-0.127023,-0.094413,-0.004810,-1.270226,-207.236755,-0.125835,0.000000
9.220000,-0.056229,-207.192276,-0.005170,-0.004885,-0.124083,-0.250117,-0.012742,-1.240832,-207.192276,-0.123008,0.000000
9.390000,-0.044312,-207.281235,-0.005036,-0.004778,-0.121360,-0.197107,-0.010041,-1.213596,-207.281235,-0.120180,0.000000
9.560000,-0.062927,-207.281235,-0.004907,-0.004668,-0.118559,-0.279914,-0.014260,-1.185588,-207.281235,-0.117336,0.000000
9.730000,-0.092720,-207.281235,-0.004769,-0.004553,-0.115636,-0.412439,-0.021011,-1.156361,-207.281235,-0.114509,0.000000
9.900001,-0.067398,-207.236755,-0.004674,-0.004440,-0.112766,-0.299802,-0.015273,-1.127656,-207.236755,-0.111682,0.000000
10.070001,-0.040215,-207.325714,-0.004549,-0.004324,-0.109826,-0.178883,-0.009113,-1.098255,-207.325714,-0.108854,0.000000
10.240001,-0.020477,-207.370193,-0.004449,-0.004222,-0.107250,-0.091088,-0.004640,-1.072503,-207.370193,-0.106010,0.000000
10.410001,-0.001862,-207.414673,-0.004333,-0.004113,-0.104475,-0.008281,-0.000422,-1.044752,-207.414673,-0.103183,0.000000
10.580001,-0.021599,-207.325714,-0.004230,-0.003999,-0.101570,-0.096076,-0.004894,-1.015699,-207.325714,-0.100356,0.000000
10.750001,-0.030533,-207.370193,-0.004122,-0.003882,-0.098612,-0.135817,-0.006919,-0.986124,-207.370193,-0.097511,0.000000
10.920000,-0.034630,-207.414673,-0.003992,-0.003773,-0.095846,-0.154041,-0.007847,-0.958464,-207.414673,-0.094684,0.000000
11.090000,-0.022339,-207.459152,-0.003867,-0.003661,-0.092993,-0.099368,-0.005062,-0.929926,-207.459152,-0.091857,0.000000
11.260000,-0.044312,-207.459152,-0.003764,-0.003546,-0.090071,-0.197107,-0.010041,-0.900707,-207.459152,-0.089030,0.000000
11.430000,-0.035378,-207.459152,-0.003635,-0.003434,-0.087217,-0.157367,-0.008017,-0.872168,-207.459152,-0.086185,0.000000
11.600000,-0.013031,-207.459152,-0.003527,-0.003337,-0.084763,-0.057965,-0.002953,-0.847627,-207.459152,-0.083358,0.000000
11.770000,-0.025322,-207.503632,-0.003410,-0.003214,-0.081624,-0.112638,-0.005738,-0.816235,-207.503632,-0.080531,0.000000
11.940001,-0.039841,-207.503632,-0.003303,-0.003102,-0.078779,-0.177220,-0.009028,-0.787788,-207.503632,-0.077686,0.000000
12.110001,-0.056969,-207.503632,-0.003169,-0.002998,-0.076160,-0.253409,-0.012909,-0.761604,-207.503632,-0.074859,0.000000
12.280001,-0.064789,-207.503632,-0.003057,-0.002883,-0.073238,-0.288195,-0.014681,-0.732377,-207.503632,-0.072032,0.000000
12.450001,-0.027184,-207.548111,-0.002975,-0.002772,-0.070419,-0.120918,-0.006160,-0.704187,-207.548111,-0.069188,0.000000
12.620001,-0.014153,-207.637085,-0.002841,-0.002659,-0.067548,-0.062954,-0.003207,-0.675483,-207.637085,-0.066361,0.000000
12.790001,0.016014,-207.637085,-0.002682,-0.002541,-0.064548,0.071234,0.003629,-0.645476,-207.637085,-0.063533,0.000000
12.960001,0.020477,-207.592606,-0.002604,-0.002443,-0.062042,0.091088,0.004640,-0.620420,-207.592606,-0.060706,0.000000
13.130001,0.017128,-207.637085,-0.002483,-0.002333,-0.059258,0.076189,0.003881,-0.592578,-207.637085,-0.057862,0.000000
13.300000,0.005959,-207.726044,-0.002371,-0.002210,-0.056136,0.026505,0.001350,-0.561360,-207.726044,-0.055035,0.000000
13.470000,0.008934,-207.681564,-0.002255,-0.002097,-0.053266,0.039741,0.002024,-0.532656,-207.681564,-0.052207,0.000000
13.640000,0.038353,-207.770523,-0.002151,-0.001991,-0.050559,0.170603,0.008691,-0.505594,-207.770523,-0.049363,0.000000
13.810000,0.061813,-207.681564,-0.002009,-0.001877,-0.047663,0.274960,0.014007,-0.476632,-207.681564,-0.046535,0.000000
13.980000,0.139641,-207.681564,-0.001906,-0.001762,-0.044758,0.621153,0.031643,-0.447579,-207.681564,-0.043709,0.000000
14.150001,0.322472,-207.726044,-0.001781,-0.001649,-0.041896,1.434425,0.073073,-0.418958,-207.726044,-0.040881,0.000000
14.320001,0.602875,-207.815002,-0.001707,0.000024,0.000607,2.681721,0.136613,0.006071,-207.815002,0.001778,0.000000
14.490001,0.605103,-207.770523,-0.001634,0.000037,0.000937,2.691631,0.137118,0.009371,-207.770523,0.001128,0.000000
14.660001,0.578293,-207.770523,-0.001638,0.000037,0.000937,2.572375,0.131043,0.009371,-207.770523,0.001128,0.000000
14.830001,0.564514,-207.815002,-0.001651,0.000037,0.000937,2.511084,0.127921,0.009371,-207.815002,0.001128,0.000000
15.000001,0.540314,-207.815002,-0.001651,0.000037,0.000937,2.403435,0.122437,0.009371,-207.815002,0.001327,0.000000
15.170001,0.552605,-207.903961,-0.001617,0.000037,0.000937,2.458108,0.125222,0.009371,-207.903961,0.001613,0.000000
15.340001,0.519829,-207.859482,-0.001643,0.000037,0.000937,2.312314,0.117795,0.009371,-207.859482,0.001899,0.000000
15.510001,0.511269,-207.859482,-0.001630,0.000037,0.000937,2.274236,0.115855,0.009371,-207.859482,0.002177,0.000000
15.680000,0.501587,-207.903961,-0.001647,0.000037,0.000945,2.231170,0.113661,0.009455,-207.903961,0.002463,0.000000
15.850000,0.722778,-207.992920,-0.001613,0.000069,0.001761,3.215079,0.163784,0.017607,-207.992920,0.002749,0.000000
16.020000,0.790916,-207.992920,-0.001634,0.000080,0.002029,3.518172,0.179224,0.020295,-207.992920,0.003027,0.000000
16.190001,0.882523,-207.992920,-0.001582,0.000095,0.002403,3.925657,0.199982,0.024027,-207.992920,0.003313,0.000000
16.360001,0.961838,-207.992920,-0.001578,0.000107,0.002724,4.278468,0.217956,0.027236,-207.992920,0.003599,0.000000
16.530001,0.949547,-207.992920,-0.001565,0.000111,0.002827,4.223795,0.215170,0.028273,-207.992920,0.003876,0.000000
16.700001,1.067223,-208.037415,-0.001565,0.000124,0.003148,4.747243,0.241836,0.031483,-208.037415,0.004163,0.000000
16.870001,1.175949,-208.126373,-0.001565,0.000142,0.003617,5.230883,0.266474,0.036168,-208.126373,0.004449,0.000000
17.040001,1.209091,-208.037415,-0.001535,0.000155,0.003946,5.378306,0.273984,0.039461,-208.037415,0.004727,0.000000
17.210001,1.275002,-208.037415,-0.001518,0.000166,0.004215,5.671490,0.288919,0.042149,-208.037415,0.005013,0.000000
17.380001,1.311493,-208.037415,-0.001505,0.000173,0.004388,5.833812,0.297189,0.043882,-208.037415,0.005299,0.000000
17.550001,1.309265,-208.126373,-0.001513,0.000180,0.004571,5.823902,0.296684,0.045706,-208.126373,0.005577,0.000000
17.720001,1.427673,-208.170853,-0.001513,0.000192,0.004874,6.350608,0.323515,0.048742,-208.170853,0.005863,0.000000
17.890001,1.511833,-208.170853,-0.001492,0.000203,0.005169,6.724970,0.342586,0.051687,-208.170853,0.006149,0.000000
18.060001,1.663017,-208.126373,-0.001462,0.000221,0.005611,7.397470,0.376845,0.056115,-208.126373,0.006426,0.000000
18.230001,1.767281,-208.170853,-0.001483,0.000232,0.005880,7.861257,0.400472,0.058802,-208.170853,0.006712,0.000000
18.400002,1.829094,-208.259811,-0.001475,0.000240,0.006097,8.136216,0.414479,0.060967,-208.259811,0.006999,0.000000
18.570002,1.841385,-208.259811,-0.001466,0.000245,0.006227,8.190889,0.417264,0.062269,-208.259811,0.007276,0.000000
18.740002,1.976929,-208.170853,-0.001431,0.000254,0.006443,8.793818,0.447978,0.064434,-208.170853,0.007562,0.000000
18.910002,2.255836,-208.259811,-0.001436,0.000276,0.007007,10.034462,0.511180,0.070074,-208.259811,0.007848,0.000000
19.080002,2.243546,-208.215332,-0.001401,0.000282,0.007172,9.979789,0.508395,0.071724,-208.215332,0.008126,0.000000
19.250000,2.505325,-208.348770,-0.001410,0.000298,0.007562,11.144243,0.567715,0.075622,-208.348770,0.008412,0.000000
19.420000,2.546654,-208.348770,-0.001393,0.000307,0.007788,11.328082,0.577080,0.077878,-208.348770,0.008698,0.000000
19.590000,2.551498,-208.348770,-0.001384,0.000314,0.007979,11.349631,0.578178,0.079786,-208.348770,0.008976,0.000000
19.760000,2.759651,-208.304291,-0.001371,0.000324,0.008230,12.275541,0.625346,0.082299,-208.304291,0.009262,0.000000
19.930000,2.952171,-208.348770,-0.001375,0.000337,0.008560,13.131914,0.668972,0.085599,-208.348770,0.009549,0.000000
20.100000,3.209854,-208.393250,-0.001345,0.000349,0.008872,14.278144,0.727363,0.088718,-208.393250,0.009826,0.000000
20.270000,3.266083,-208.437744,-0.001324,0.000358,0.009097,14.528262,0.740105,0.090974,-208.437744,0.010112,0.000000
20.440001,3.383377,-208.393250,-0.001341,0.000365,0.009280,15.050013,0.766684,0.092798,-208.393250,0.010398,0.000000
20.610001,3.442215,-208.437744,-0.001345,0.000370,0.009401,15.311737,0.780017,0.094009,-208.437744,0.010676,0.000000
20.780001,3.892036,-208.437744,-0.001315,0.000391,0.009930,17.312643,0.881948,0.099301,-208.437744,0.010962,0.000000
20.950001,4.241692,-208.482224,-0.001311,0.000410,0.010415,18.867987,0.961181,0.104153,-208.482224,0.011248,0.000000
21.120001,4.415222,-208.437744,-0.001298,0.000421,0.010685,19.639889,1.000504,0.106848,-208.437744,0.011526,0.000000
21.290001,4.605133,-208.482224,-0.001289,0.000429,0.010901,20.484655,1.043538,0.109013,-208.482224,0.011812,0.000000
21.460001,4.717590,-208.437744,-0.001289,0.000437,0.011109,20.984890,1.069021,0.111094,-208.437744,0.012098,0.000000
21.630001,5.003571,-208.571182,-0.001268,0.000452,0.011474,22.256994,1.133825,0.114735,-208.571182,0.012376,0.000000
21.800001,5.078789,-208.615662,-0.001276,0.000458,0.011639,22.591581,1.150870,0.116386,-208.615662,0.012662,0.000000
21.970001,5.650749,-208.526703,-0.001259,0.000474,0.012028,25.135788,1.280478,0.120284,-208.526703,0.012948,0.000000
22.140001,5.911415,-208.571182,-0.001246,0.000484,0.012289,26.295288,1.339546,0.122888,-208.571182,0.013225,0.000000
22.310001,6.032059,-208.571182,-0.001229,0.000492,0.012488,26.831938,1.366884,0.124879,-208.571182,0.013511,0.000000
22.480001,6.237610,-208.615662,-0.001220,0.000498,0.012645,27.746275,1.413463,0.126446,-208.615662,0.013797,0.000000
22.650002,6.477051,-208.749100,-0.001212,0.000508,0.012904,28.811361,1.467721,0.129042,-208.749100,0.014075,0.000000
22.820002,7.132423,-208.749100,-0.001199,0.000525,0.013347,31.726604,1.616230,0.133471,-208.749100,0.014361,0.000000
22.990002,7.607941,-208.704620,-0.001190,0.000541,0.013746,33.841812,1.723984,0.137460,-208.704620,0.014648,0.000000
23.160002,7.705879,-208.749100,-0.001199,0.000550,0.013980,34.277462,1.746177,0.139799,-208.749100,0.014925,0.000000
23.330002,8.200760,-208.793579,-0.001160,0.000563,0.014309,36.478802,1.858319,0.143092,-208.793579,0.015211,0.000000
23.500002,8.404449,-208.793579,-0.001168,0.000571,0.014500,37.384857,1.904475,0.144999,-208.793579,0.015498,0.000000
23.670002,8.715378,-208.793579,-0.001160,0.000583,0.014813,38.767937,1.974933,0.148126,-208.793579,0.015784,0.000000
23.840002,9.369263,-208.749100,-0.001151,0.000598,0.015194,41.676563,2.123105,0.151941,-208.749100,0.016061,0.000000
24.010000,9.832870,-208.749100,-0.001164,0.000610,0.015506,43.738792,2.228160,0.155060,-208.749100,0.016348,0.000000
24.180000,10.038788,-208.838058,-0.001151,0.000619,0.015732,44.654758,2.274822,0.157315,-208.838058,0.016634,0.000000
24.350000,10.156456,-208.927032,-0.001134,0.000624,0.015853,45.178173,2.301486,0.158534,-208.927032,0.016911,0.000000
24.520000,10.359772,-208.927032,-0.001143,0.000630,0.016009,46.082565,2.347558,0.160093,-208.927032,0.017197,0.000000
24.690001,11.113831,-208.882553,-0.001125,0.000647,0.016443,49.436787,2.518430,0.164431,-208.882553,0.017483,0.000000
24.860001,11.963211,-208.927032,-0.001099,0.000668,0.016963,53.215019,2.710902,0.169631,-208.927032,0.017761,0.000000
25.030001,12.040665,-208.927032,-0.001095,0.000673,0.017084,53.559551,2.728454,0.170843,-208.927032,0.018047,0.000000
25.200001,12.329254,-208.971512,-0.001099,0.000683,0.017336,54.843262,2.793849,0.173363,-208.971512,0.018333,0.000000
25.370001,12.976433,-208.927032,-0.001074,0.000695,0.017648,57.722057,2.940502,0.176482,-208.927032,0.018611,0.000000
25.540001,13.546913,-208.927032,-0.001091,0.000708,0.017977,60.259678,3.069774,0.179775,-208.927032,0.018897,0.000000
25.710001,13.938271,-208.971512,-0.001052,0.000718,0.018238,62.000523,3.158457,0.182379,-208.971512,0.019183,0.000000
25.880001,14.744087,-209.015991,-0.001065,0.000734,0.018645,65.584976,3.341058,0.186451,-209.015991,0.019460,0.000000
26.050001,15.006607,-209.015991,-0.001048,0.000744,0.018888,66.752724,3.400546,0.188881,-209.015991,0.019747,0.000000
26.220001,15.330574,-209.060471,-0.001056,0.000751,0.019079,68.193802,3.473958,0.190789,-209.060471,0.020033,0.000000
26.390001,15.578201,-209.060471,-0.001043,0.000759,0.019270,69.295303,3.530071,0.192697,-209.060471,0.020311,0.000000
26.560001,15.851898,-209.060471,-0.001039,0.000765,0.019426,70.512764,3.592092,0.194264,-209.060471,0.020597,0.000000
26.730001,17.218132,-209.104950,-0.001065,0.000789,0.020033,76.590073,3.901685,0.200334,-209.104950,0.020883,0.000000
26.900002,17.561455,-209.149429,-0.001018,0.000797,0.020250,78.117249,3.979482,0.202499,-209.149429,0.021161,0.000000
27.070002,18.028412,-209.149429,-0.001035,0.000809,0.020544,80.194382,4.085297,0.205444,-209.149429,0.021447,0.000000
27.240002,18.442490,-209.149429,-0.000996,0.000820,0.020840,82.036293,4.179128,0.208396,-209.149429,0.021733,0.000000
27.410002,18.879288,-209.149429,-0.000996,0.000831,0.021117,83.979263,4.278108,0.211174,-209.149429,0.022011,0.000000
27.580002,19.421829,-209.193909,-0.000992,0.000842,0.021377,86.392609,4.401050,0.213771,-209.193909,0.022297,0.000000
27.750002,19.712654,-209.238388,-0.000992,0.000852,0.021628,87.686264,4.466951,0.216284,-209.238388,0.022583,0.000000
27.920002,20.823067,-209.193909,-0.000979,0.000867,0.022019,92.625626,4.718575,0.220190,-209.193909,0.022860,0.000000
28.090002,21.083733,-209.238388,-0.000974,0.000874,0.022192,93.785126,4.777642,0.221924,-209.238388,0.023146,0.000000
28.260002,21.224487,-209.327362,-0.000992,0.000879,0.022314,94.411232,4.809538,0.223142,-209.327362,0.023432,0.000000
28.430002,21.981895,-209.282867,-0.000983,0.000892,0.022652,97.780357,4.981169,0.226518,-209.282867,0.023710,0.000000
28.600002,23.036079,-209.327362,-0.000949,0.000911,0.023129,102.469597,5.220050,0.231287,-209.327362,0.023996,0.000000
28.770000,23.665764,-209.282867,-0.000957,0.000922,0.023424,105.270576,5.362739,0.234240,-209.282867,0.024282,0.000000
28.940001,24.182983,-209.327362,-0.000931,0.000934,0.023736,107.571281,5.479942,0.237358,-209.327362,0.024560,0.000000
29.110001,24.586266,-209.371841,-0.000949,0.000941,0.023910,109.365173,5.571327,0.239099,-209.371841,0.024846,0.000000
29.280001,25.118385,-209.371841,-0.000910,0.000954,0.024222,111.732155,5.691908,0.242218,-209.371841,0.025132,0.000000
29.450001,25.418892,-209.416321,-0.000936,0.000961,0.024404,113.068878,5.760004,0.244042,-209.416321,0.025410,0.000000
29.620001,25.646782,-209.416321,-0.000931,0.000965,0.024508,114.082581,5.811644,0.245080,-209.416321,0.025696,0.000000
29.790001,26.917313,-209.371841,-0.000901,0.000984,0.024985,119.734184,6.099550,0.249848,-209.371841,0.025983,0.000000
29.960001,27.510132,-209.460800,-0.000923,0.000996,0.025297,122.371178,6.233885,0.252975,-209.460800,0.026260,0.000000
30.130001,27.726479,-209.505280,-0.000914,0.001001,0.025419,123.333534,6.282910,0.254186,-209.505280,0.026546,0.000000
30.300001,28.277222,-209.460800,-0.000888,0.001011,0.025687,125.783363,6.407710,0.256873,-209.460800,0.026832,0.000000
30.470001,28.678268,-209.505280,-0.000880,0.001018,0.025861,127.567307,6.498589,0.258607,-209.505280,0.027110,0.000000
30.640001,29.734314,-209.505280,-0.000875,0.001035,0.026286,132.264832,6.737892,0.262861,-209.505280,0.027396,0.000000
30.810001,31.201088,-209.505280,-0.000888,0.001055,0.026806,138.789368,7.070268,0.268061,-209.505280,0.027682,0.000000
30.980001,31.553352,-209.549759,-0.000888,0.001065,0.027049,140.356323,7.150092,0.270491,-209.549759,0.027960,0.000000
31.150002,31.738426,-209.505280,-0.000867,0.001075,0.027309,141.179565,7.192030,0.273088,-209.505280,0.028246,0.000000
31.320002,32.262726,-209.505280,-0.000849,0.001084,0.027543,143.511765,7.310838,0.275434,-209.505280,0.028532,0.000000
31.490002,32.854797,-209.594238,-0.000854,0.001093,0.027752,146.145432,7.445004,0.277516,-209.594238,0.028809,0.000000
31.660002,33.623375,-209.594238,-0.000871,0.001107,0.028107,149.564240,7.619165,0.281066,-209.594238,0.029095,0.000000
31.830002,34.957954,-209.727692,-0.000858,0.001124,0.028540,155.500748,7.921586,0.285404,-209.727692,0.029382,0.000000
32.000000,35.214523,-209.638718,-0.000836,0.001131,0.028723,156.642029,7.979725,0.287228,-209.638718,0.029668,0.000000
32.170002,35.682594,-209.683197,-0.000836,0.001139,0.028939,158.724106,8.085792,0.289393,-209.683197,0.029945,0.000000
32.340000,37.006004,-209.683197,-0.000836,0.001159,0.029434,164.610931,8.385680,0.294336,-209.683197,0.030231,0.000000
32.510002,37.545570,-209.727692,-0.000832,0.001168,0.029659,167.011032,8.507948,0.296592,-209.727692,0.030518,0.000000
32.680000,38.182701,-209.772171,-0.000841,0.001180,0.029963,169.845139,8.652324,0.299627,-209.772171,0.030795,0.000000
32.850002,38.871964,-209.816650,-0.000828,0.001190,0.030231,172.911133,8.808513,0.302315,-209.816650,0.031082,0.000000
33.020000,39.246567,-209.727692,-0.000798,0.001198,0.030440,174.577454,8.893399,0.304396,-209.727692,0.031368,0.000000
33.190002,39.670326,-209.772171,-0.000802,0.001206,0.030622,176.462418,8.989424,0.306221,-209.772171,0.031646,0.000000
33.360001,40.019241,-209.816650,-0.000789,0.001214,0.030848,178.014481,9.068490,0.308477,-209.816650,0.031932,0.000000
33.530003,41.652092,-209.816650,-0.000798,0.001233,0.031325,185.277756,9.438498,0.313245,-209.816650,0.032218,0.000000
33.700001,42.424767,-209.816650,-0.000780,0.001245,0.031611,188.714783,9.613589,0.316107,-209.816650,0.032495,0.000000
33.870003,43.003807,-209.816650,-0.000772,0.001254,0.031845,191.290482,9.744802,0.318446,-209.816650,0.032781,0.000000
34.040001,43.247337,-209.861130,-0.000772,0.001260,0.031992,192.373764,9.799987,0.319922,-209.861130,0.033067,0.000000
34.210003,44.200241,-209.861130,-0.000776,0.001273,0.032331,196.612488,10.015918,0.323306,-209.861130,0.033345,0.000000
34.380001,45.559402,-209.861130,-0.000767,0.001290,0.032773,202.658340,10.323908,0.327726,-209.861130,0.033631,0.000000
34.550003,46.205093,-209.950089,-0.000763,0.001302,0.033067,205.530518,10.470223,0.330671,-209.950089,0.033917,0.000000
34.720001,47.071228,-209.950089,-0.000776,0.001314,0.033371,209.383286,10.666492,0.333707,-209.950089,0.034195,0.000000
34.890003,47.311043,-209.994568,-0.000776,0.001319,0.033493,210.450027,10.720835,0.334925,-209.994568,0.034481,0.000000
35.060001,47.806297,-209.950089,-0.000755,0.001328,0.033744,212.653030,10.833061,0.337439,-209.950089,0.034767,0.000000
35.230003,48.766640,-210.039047,-0.000759,0.001339,0.034022,216.924850,11.050678,0.340217,-210.039047,0.035045,0.000000
35.400002,48.851173,-210.039047,-0.000750,0.001343,0.034108,217.300873,11.069834,0.341080,-210.039047,0.035331,0.000000
35.570004,49.932541,-210.039047,-0.000755,0.001360,0.034542,222.111038,11.314876,0.345417,-210.039047,0.035617,0.000000
35.740002,50.840012,-210.128006,-0.000733,0.001369,0.034776,226.147659,11.520511,0.347756,-210.128006,0.035894,0.000000
35.910000,51.381439,-210.128006,-0.000742,0.001376,0.034958,228.556061,11.643200,0.349580,-210.128006,0.036181,0.000000
36.080002,51.589600,-210.128006,-0.000720,0.001381,0.035079,229.481995,11.690371,0.350792,-210.128006,0.036467,0.000000
36.250000,54.122475,-210.128006,-0.000729,0.001412,0.035869,240.748795,12.264328,0.358687,-210.128006,0.036745,0.000000
36.420002,55.360245,-210.128006,-0.000711,0.001424,0.036181,246.254669,12.544811,0.361806,-210.128006,0.037031,0.000000
36.590000,56.230103,-210.083527,-0.000724,0.001436,0.036484,250.123993,12.741923,0.364841,-210.083527,0.037317,0.000000
36.760002,56.908195,-210.128006,-0.000716,0.001446,0.036719,253.140289,12.895581,0.367188,-210.128006,0.037595,0.000000
36.930000,57.155823,-210.216980,-0.000698,0.001452,0.036883,254.241791,12.951694,0.368830,-210.216980,0.037881,0.000000
37.100002,57.527824,-210.172501,-0.000720,0.001458,0.037040,255.896545,13.035991,0.370397,-210.172501,0.038167,0.000000
37.270000,58.367897,-210.172501,-0.000703,0.001471,0.037360,259.633362,13.226355,0.373599,-210.172501,0.038444,0.000000
37.440002,59.261589,-210.172501,-0.000711,0.001481,0.037620,263.608704,13.428867,0.376203,-210.172501,0.038731,0.000000
37.610001,60.996475,-210.305939,-0.000707,0.001501,0.038115,271.325867,13.822000,0.381146,-210.305939,0.039017,0.000000
37.780003,61.631371,-210.305939,-0.000694,0.001506,0.038262,274.150024,13.965868,0.382623,-210.305939,0.039294,0.000000
37.950001,62.087151,-210.261459,-0.000673,0.001515,0.038470,276.177429,14.069149,0.384704,-210.261459,0.039580,0.000000
38.120003,62.908234,-210.261459,-0.000686,0.001525,0.038739,279.829803,14.255209,0.387392,-210.261459,0.039866,0.000000
38.290001,64.917175,-210.305939,-0.000686,0.001547,0.039294,288.766022,14.710442,0.392940,-210.305939,0.040144,0.000000
38.460003,65.840286,-210.394897,-0.000677,0.001557,0.039554,292.872223,14.919622,0.395544,-210.394897,0.040430,0.000000
38.630001,66.732132,-210.394897,-0.000677,0.001568,0.039831,296.839355,15.121717,0.398315,-210.394897,0.040716,0.000000
38.800003,67.012146,-210.350418,-0.000660,0.001573,0.039962,298.084900,15.185169,0.399617,-210.350418,0.040994,0.000000
38.970001,67.612411,-210.394897,-0.000655,0.001573,0.039944,300.755035,15.321191,0.399443,-210.394897,0.040187,0.000000
39.140003,67.263870,-210.394897,-0.000690,0.001573,0.039944,299.204651,15.242210,0.399443,-210.394897,0.040187,0.000000
39.310001,67.023697,-210.528336,-0.000673,0.001573,0.039944,298.136292,15.187786,0.399443,-210.528336,0.040187,0.000000
39.480003,66.863571,-210.483856,-0.000673,0.001571,0.039910,297.424011,15.151502,0.399102,-210.483856,0.039944,0.000000
39.650002,66.697495,-210.483856,-0.000660,0.001571,0.039893,296.685272,15.113868,0.398928,-210.483856,0.039944,0.000000
39.820004,66.522476,-210.439377,-0.000655,0.001571,0.039893,295.906738,15.074208,0.398928,-210.439377,0.039944,0.000000
39.990002,66.391769,-210.528336,-0.000642,0.001570,0.039884,295.325348,15.044590,0.398837,-210.528336,0.039944,0.000000
40.160004,66.268524,-210.528336,-0.000647,0.001570,0.039875,294.777130,15.016662,0.398754,-210.528336,0.039944,0.000000
40.330002,66.148987,-210.572815,-0.000651,0.001570,0.039875,294.245392,14.989574,0.398754,-210.572815,0.039944,0.000000
40.500004,66.057007,-210.617310,-0.000638,0.001570,0.039875,293.836243,14.968732,0.398754,-210.617310,0.039944,0.000000
40.670002,65.961319,-210.528336,-0.000642,0.001570,0.039875,293.410614,14.947048,0.398754,-210.528336,0.039944,0.000000
40.840000,65.871567,-210.572815,-0.000664,0.001570,0.039875,293.011353,14.926710,0.398754,-210.572815,0.039944,0.000000
41.010002,65.787781,-210.617310,-0.000655,0.001570,0.039866,292.638672,14.907723,0.398663,-210.617310,0.039944,0.000000
41.180000,65.722992,-210.661789,-0.000647,0.001570,0.039866,292.350464,14.893044,0.398663,-210.661789,0.039944,0.000000
41.350002,65.654480,-210.617310,-0.000647,0.001570,0.039866,292.045715,14.877518,0.398663,-210.617310,0.039944,0.000000
41.520000,65.591171,-210.572815,-0.000634,0.001570,0.039866,291.764099,14.863172,0.398663,-210.572815,0.039944,0.000000
41.690002,65.516708,-210.706268,-0.000608,0.001570,0.039866,291.432861,14.846298,0.398663,-210.706268,0.039944,0.000000
41.860001,65.464935,-210.750748,-0.000629,0.001570,0.039866,291.202576,14.834566,0.398663,-210.750748,0.039944,0.000000
42.030003,65.405731,-210.706268,-0.000634,0.001570,0.039866,290.939209,14.821150,0.398663,-210.706268,0.039944,0.000000
42.200001,65.357697,-210.795227,-0.000642,0.001570,0.039866,290.725555,14.810266,0.398663,-210.795227,0.039944,0.000000
42.370003,65.313019,-210.750748,-0.000673,0.001570,0.039866,290.526825,14.800141,0.398663,-210.750748,0.039944,0.000000
42.540001,65.269821,-210.795227,-0.000655,0.001570,0.039866,290.334656,14.790353,0.398663,-210.795227,0.039944,0.000000
42.710003,65.220291,-210.795227,-0.000638,0.001570,0.039866,290.114349,14.779129,0.398663,-210.795227,0.039944,0.000000
42.880001,65.187531,-210.839706,-0.000625,0.001570,0.039866,289.968628,14.771706,0.398663,-210.839706,0.039944,0.000000
43.050003,65.132782,-210.839706,-0.000647,0.001570,0.039866,289.725098,14.759299,0.398663,-210.839706,0.039944,0.000000
43.220001,65.104858,-210.839706,-0.000647,0.001570,0.039866,289.600861,14.752973,0.398663,-210.839706,0.039944,0.000000
43.390003,65.053101,-210.884186,-0.000647,0.001570,0.039866,289.370636,14.741242,0.398663,-210.884186,0.039944,0.000000
43.560001,65.031494,-210.884186,-0.000638,0.001570,0.039866,289.274536,14.736347,0.398663,-210.884186,0.039944,0.000000
43.730003,65.002075,-210.928665,-0.000655,0.001570,0.039866,289.143677,14.729681,0.398663,-210.928665,0.039944,0.000000
43.900002,64.965591,-210.884186,-0.000638,0.001570,0.039866,288.981384,14.721414,0.398663,-210.884186,0.039944,0.000000
44.070004,64.925003,-210.973145,-0.000642,0.001570,0.039866,288.800842,14.712215,0.398663,-210.973145,0.039944,0.000000
44.240002,64.894089,-211.017639,-0.000660,0.001570,0.039866,288.663330,14.705211,0.398663,-211.017639,0.039944,0.000000
44.410004,64.870270,-210.973145,-0.000655,0.001570,0.039866,288.557373,14.699814,0.398663,-210.973145,0.039944,0.000000
44.580002,64.841217,-211.017639,-0.000608,0.001570,0.039866,288.428131,14.693230,0.398663,-211.017639,0.039944,0.000000
44.750004,64.824463,-211.017639,-0.000651,0.001570,0.039866,288.353607,14.689433,0.398663,-211.017639,0.039944,0.000000
44.920002,64.788712,-211.017639,-0.000660,0.001570,0.039866,288.194580,14.681332,0.398663,-211.017639,0.039944,0.000000
45.090004,64.754456,-211.062119,-0.000664,0.001570,0.039866,288.042206,14.673570,0.398663,-211.062119,0.039944,0.000000
45.260002,64.732483,-211.062119,-0.000647,0.001570,0.039866,287.944458,14.668591,0.398663,-211.062119,0.039944,0.000000
45.430000,64.713501,-211.062119,-0.000660,0.001570,0.039866,287.860016,14.664289,0.398663,-211.062119,0.039944,0.000000
45.600002,64.700089,-211.151077,-0.000617,0.001570,0.039866,287.800354,14.661249,0.398663,-211.151077,0.039944,0.000000
45.770000,64.668808,-211.151077,-0.000634,0.001570,0.039866,287.661224,14.654160,0.398663,-211.151077,0.039944,0.000000
45.940002,64.637161,-211.151077,-0.000647,0.001570,0.039866,287.520447,14.646990,0.398663,-211.151077,0.039944,0.000000
46.110001,64.615189,-211.240036,-0.000655,0.001570,0.039866,287.422699,14.642012,0.398663,-211.240036,0.039944,0.000000
46.280003,64.591354,-211.195557,-0.000647,0.001570,0.039866,287.316681,14.636610,0.398663,-211.195557,0.039944,0.000000
46.450001,64.581680,-211.151077,-0.000638,0.001570,0.039866,287.273651,14.634418,0.398663,-211.151077,0.039944,0.000000
46.620003,64.552628,-211.240036,-0.000681,0.001570,0.039866,287.144440,14.627834,0.398663,-211.240036,0.039944,0.000000
46.790001,64.533264,-211.240036,-0.000647,0.001570,0.039866,287.058289,14.623446,0.398663,-211.240036,0.039944,0.000000
46.960003,64.515015,-211.284515,-0.000655,0.001570,0.039866,286.977112,14.619310,0.398663,-211.284515,0.039944,0.000000
47.130001,64.499756,-211.240036,-0.000647,0.001570,0.039866,286.909241,14.615853,0.398663,-211.240036,0.039944,0.000000
47.300003,64.473679,-211.240036,-0.000629,0.001570,0.039866,286.793243,14.609944,0.398663,-211.240036,0.039944,0.000000
47.470001,64.465866,-211.328995,-0.000655,0.001570,0.039866,286.758484,14.608174,0.398663,-211.328995,0.039944,0.000000
47.640003,64.434952,-211.417953,-0.000647,0.001570,0.039866,286.620972,14.601169,0.398663,-211.417953,0.039944,0.000000
47.810001,64.417084,-211.373474,-0.000642,0.001570,0.039866,286.541504,14.597119,0.398663,-211.373474,0.039944,0.000000
47.980003,64.406281,-211.417953,-0.000660,0.001570,0.039866,286.493439,14.594672,0.398663,-211.417953,0.039944,0.000000
48.150002,64.399963,-211.328995,-0.000651,0.001570,0.039866,286.465332,14.593240,0.398663,-211.328995,0.039944,0.000000
48.320004,64.358994,-211.417953,-0.000647,0.001570,0.039866,286.283112,14.583957,0.398663,-211.417953,0.039944,0.000000
48.490002,64.356384,-211.506927,-0.000638,0.001570,0.039866,286.271484,14.583364,0.398663,-211.506927,0.039944,0.000000
48.660004,64.334793,-211.462448,-0.000629,0.001570,0.039866,286.175446,14.578472,0.398663,-211.462448,0.039944,0.000000
48.830002,64.329208,-211.462448,-0.000647,0.001570,0.039866,286.150604,14.577207,0.398663,-211.462448,0.039944,0.000000
49.000004,64.314682,-211.417953,-0.000655,0.001570,0.039866,286.085999,14.573915,0.398663,-211.417953,0.039944,0.000000
49.170002,64.296432,-211.506927,-0.000638,0.001570,0.039866,286.004822,14.569780,0.398663,-211.506927,0.039944,0.000000
49.340004,64.280426,-211.551407,-0.000642,0.001570,0.039866,285.933624,14.566153,0.398663,-211.551407,0.039944,0.000000
49.510002,64.264786,-211.506927,-0.000642,0.001570,0.039866,285.864044,14.562609,0.398663,-211.506927,0.039944,0.000000
49.680004,64.249893,-211.551407,-0.000647,0.001570,0.039866,285.797791,14.559235,0.398663,-211.551407,0.039944,0.000000
49.850002,64.243195,-211.506927,-0.000629,0.001570,0.039866,285.768005,14.557716,0.398663,-211.506927,0.039944,0.000000
50.020004,64.220093,-211.595886,-0.000660,0.001570,0.039866,285.665253,14.552481,0.398663,-211.595886,0.039944,0.000000
50.190002,64.206329,-211.640366,-0.000664,0.001570,0.039866,285.604004,14.549362,0.398663,-211.640366,0.039944,0.000000
50.360001,64.204468,-211.684845,-0.000642,0.001570,0.039866,285.595734,14.548941,0.398663,-211.684845,0.039944,0.000000
50.530003,64.194031,-211.595886,-0.000638,0.001570,0.039866,285.549316,14.546576,0.398663,-211.595886,0.039944,0.000000
50.700001,64.166473,-211.595886,-0.000651,0.001570,0.039866,285.426727,14.540331,0.398663,-211.595886,0.039944,0.000000
50.870003,64.159409,-211.684845,-0.000625,0.001570,0.039866,285.395294,14.538730,0.398663,-211.684845,0.039944,0.000000
51.040001,64.145996,-211.684845,-0.000655,0.001570,0.039866,285.335632,14.535690,0.398663,-211.684845,0.039944,0.000000
51.210003,64.135193,-211.729324,-0.000629,0.001570,0.039866,285.287598,14.533242,0.398663,-211.729324,0.039944,0.000000
51.380001,64.113968,-211.640366,-0.000642,0.001570,0.039866,285.193176,14.528432,0.398663,-211.640366,0.039944,0.000000
51.550003,64.101318,-211.684845,-0.000629,0.001570,0.039866,285.136902,14.525566,0.398663,-211.684845,0.039944,0.000000
51.720001,64.093872,-211.773804,-0.000655,0.001570,0.039866,285.103790,14.523879,0.398663,-211.773804,0.039944,0.000000
51.890003,64.086044,-211.773804,-0.000651,0.001570,0.039866,285.068970,14.522105,0.398663,-211.773804,0.039944,0.000000
52.060001,64.076370,-211.818283,-0.000629,0.001570,0.039866,285.025940,14.519913,0.398663,-211.818283,0.039944,0.000000
52.230003,64.073380,-211.862762,-0.000629,0.001570,0.039866,285.012634,14.519235,0.398663,-211.862762,0.039944,0.000000
52.400002,64.051041,-211.818283,-0.000629,0.001570,0.039866,284.913269,14.514174,0.398663,-211.818283,0.039944,0.000000
52.570004,64.036896,-211.862762,-0.000621,0.001570,0.039866,284.850342,14.510968,0.398663,-211.862762,0.039944,0.000000
52.740002,64.022736,-211.951736,-0.000642,0.001570,0.039866,284.787354,14.507759,0.398663,-211.951736,0.039944,0.000000
52.910004,64.024979,-211.907257,-0.000655,0.001570,0.039866,284.797333,14.508267,0.398663,-211.907257,0.039944,0.000000
53.080002,64.010834,-211.907257,-0.000651,0.001570,0.039866,284.734406,14.505062,0.398663,-211.907257,0.039944,0.000000
53.250004,64.003754,-211.862762,-0.000621,0.001570,0.039866,284.702911,14.503457,0.398663,-211.862762,0.039944,0.000000
53.420002,63.985138,-211.862762,-0.000625,0.001570,0.039866,284.620117,14.499240,0.398663,-211.862762,0.039944,0.000000
53.590004,63.980286,-211.951736,-0.000617,0.001570,0.039866,284.598511,14.498140,0.398663,-211.951736,0.039944,0.000000
53.760002,63.969864,-211.951736,-0.000651,0.001570,0.039866,284.552155,14.495778,0.398663,-211.951736,0.039944,0.000000
53.930004,63.946411,-211.996216,-0.000621,0.001570,0.039866,284.447845,14.490463,0.398663,-211.996216,0.039944,0.000000
54.100002,63.944168,-211.996216,-0.000655,0.001570,0.039866,284.437866,14.489955,0.398663,-211.996216,0.039944,0.000000
54.270004,63.936722,-211.951736,-0.000625,0.001570,0.039866,284.404755,14.488269,0.398663,-211.951736,0.039944,0.000000
54.440002,63.926300,-212.085175,-0.000647,0.001570,0.039866,284.358398,14.485908,0.398663,-212.085175,0.039944,0.000000
54.610004,63.916992,-212.040695,-0.000608,0.001570,0.039866,284.316986,14.483797,0.398663,-212.040695,0.039944,0.000000
54.780003,63.917358,-212.040695,-0.000642,0.001570,0.039866,284.318604,14.483881,0.398663,-212.040695,0.039944,0.000000
54.950001,63.899109,-212.085175,-0.000625,0.001570,0.039866,284.237427,14.479745,0.398663,-212.085175,0.039944,0.000000
55.120003,63.898743,-212.129654,-0.000638,0.001570,0.039866,284.235809,14.479662,0.398663,-212.129654,0.039944,0.000000
55.290001,63.888687,-212.085175,-0.000617,0.001570,0.039866,284.191071,14.477384,0.398663,-212.085175,0.039944,0.000000
55.460003,63.875656,-212.218613,-0.000625,0.001570,0.039866,284.133118,14.474430,0.398663,-212.218613,0.039944,0.000000
55.630001,63.860016,-212.129654,-0.000651,0.001570,0.039866,284.063538,14.470887,0.398663,-212.129654,0.039944,0.000000
55.800003,63.868210,-212.174133,-0.000647,0.001570,0.039866,284.099976,14.472743,0.398663,-212.174133,0.039944,0.000000
55.970001,63.852203,-212.218613,-0.000651,0.001570,0.039866,284.028778,14.469116,0.398663,-212.218613,0.039944,0.000000
56.140003,63.851456,-212.263092,-0.000651,0.001570,0.039866,284.025452,14.468946,0.398663,-212.263092,0.039944,0.000000
56.310001,63.836563,-212.218613,-0.000629,0.001570,0.039866,283.959229,14.465572,0.398663,-212.218613,0.039944,0.000000
56.480003,63.829849,-212.263092,-0.000629,0.001570,0.039866,283.929352,14.464051,0.398663,-212.263092,0.039944,0.000000
56.650002,63.816818,-212.263092,-0.000634,0.001570,0.039866,283.871399,14.461098,0.398663,-212.263092,0.039944,0.000000
56.820004,63.806763,-212.263092,-0.000634,0.001570,0.039866,283.826660,14.458819,0.398663,-212.263092,0.039944,0.000000
56.990002,63.803421,-212.396545,-0.000638,0.001570,0.039866,283.811798,14.458062,0.398663,-212.396545,0.039944,0.000000
57.160004,63.797455,-212.307587,-0.000617,0.001570,0.039866,283.785248,14.456710,0.398663,-212.307587,0.039944,0.000000
57.330002,63.777725,-212.352066,-0.000625,0.001570,0.039866,283.697479,14.452239,0.398663,-212.352066,0.039944,0.000000
57.500004,63.778839,-212.307587,-0.000638,0.001570,0.039866,283.702454,14.452492,0.398663,-212.307587,0.039944,0.000000
57.670002,63.759109,-212.396545,-0.000638,0.001570,0.039866,283.614685,14.448021,0.398663,-212.396545,0.039944,0.000000
57.840004,63.768784,-212.441025,-0.000655,0.001570,0.039866,283.657715,14.450212,0.398663,-212.441025,0.039944,0.000000
58.010002,63.751282,-212.441025,-0.000629,0.001570,0.039866,283.579865,14.446247,0.398663,-212.441025,0.039944,0.000000
58.180004,63.758362,-212.396545,-0.000634,0.001570,0.039866,283.611359,14.447851,0.398663,-212.396545,0.039944,0.000000
58.350002,63.742722,-212.396545,-0.000651,0.001570,0.039866,283.541779,14.444307,0.398663,-212.396545,0.039944,0.000000
58.520004,63.745331,-212.529984,-0.000642,0.001570,0.039866,283.553406,14.444898,0.398663,-212.529984,0.039944,0.000000
58.690002,63.722244,-212.529984,-0.000642,0.001570,0.039866,283.450714,14.439667,0.398663,-212.529984,0.039944,0.000000
58.860004,63.728195,-212.529984,-0.000638,0.001570,0.039866,283.477173,14.441015,0.398663,-212.529984,0.039944,0.000000
59.030003,63.713669,-212.485504,-0.000651,0.001570,0.039866,283.412567,14.437723,0.398663,-212.485504,0.039944,0.000000
59.200005,63.712555,-212.529984,-0.000621,0.001570,0.039866,283.407593,14.437471,0.398663,-212.529984,0.039944,0.000000
59.370003,63.696167,-212.529984,-0.000642,0.001570,0.039866,283.334717,14.433758,0.398663,-212.529984,0.039944,0.000000
59.540005,63.694305,-212.574463,-0.000625,0.001570,0.039866,283.326416,14.433336,0.398663,-212.574463,0.039944,0.000000
59.710003,63.688354,-212.618942,-0.000638,0.001570,0.039866,283.299957,14.431988,0.398663,-212.618942,0.039944,0.000000
59.880001,63.683517,-212.618942,-0.000642,0.001570,0.039866,283.278442,14.430891,0.398663,-212.618942,0.039944,0.000000
60.050003,63.680161,-212.618942,-0.000655,0.001570,0.039866,283.263489,14.430130,0.398663,-212.618942,0.039944,0.000000
60.220001,63.681274,-212.707901,-0.000617,0.001570,0.039866,283.268463,14.430383,0.398663,-212.707901,0.039944,0.000000
60.390003,63.660049,-212.707901,-0.000673,0.001570,0.039866,283.174042,14.425574,0.398663,-212.707901,0.039944,0.000000
60.560001,63.652603,-212.663422,-0.000608,0.001570,0.039866,283.140930,14.423886,0.398663,-212.663422,0.039944,0.000000
60.730003,63.649246,-212.663422,-0.000629,0.001570,0.039866,283.125977,14.423125,0.398663,-212.663422,0.039944,0.000000
60.900002,63.643661,-212.707901,-0.000634,0.001570,0.039866,283.101135,14.421860,0.398663,-212.707901,0.039944,0.000000
61.070004,63.634354,-212.796875,-0.000647,0.001570,0.039866,283.059753,14.419751,0.398663,-212.796875,0.039944,0.000000
61.240002,63.634354,-212.796875,-0.000638,0.001570,0.039866,283.059753,14.419751,0.398663,-212.796875,0.039944,0.000000
61.410004,63.628021,-212.752396,-0.000634,0.001570,0.039866,283.031586,14.418316,0.398663,-212.752396,0.039944,0.000000
61.580002,63.623932,-212.752396,-0.000638,0.001570,0.039866,283.013397,14.417389,0.398663,-212.752396,0.039944,0.000000
61.750004,63.616852,-212.796875,-0.000617,0.001570,0.039866,282.981903,14.415785,0.398663,-212.796875,0.039944,0.000000
61.920002,63.606064,-212.796875,-0.000651,0.001570,0.039866,282.933899,14.413340,0.398663,-212.796875,0.039944,0.000000
62.090004,63.602341,-212.841354,-0.000638,0.001570,0.039866,282.917328,14.412497,0.398663,-212.841354,0.039944,0.000000
62.260002,63.591537,-212.796875,-0.000638,0.001570,0.039866,282.869293,14.410048,0.398663,-212.796875,0.039944,0.000000
62.430004,63.595261,-212.885834,-0.000638,0.001570,0.039866,282.885834,14.410892,0.398663,-212.885834,0.039944,0.000000
62.600002,63.583710,-212.885834,-0.000625,0.001570,0.039866,282.834473,14.408275,0.398663,-212.885834,0.039944,0.000000
62.770004,63.580368,-212.885834,-0.000629,0.001570,0.039866,282.819611,14.407517,0.398663,-212.885834,0.039944,0.000000
62.940002,63.578125,-212.930313,-0.000642,0.001570,0.039866,282.809631,14.407009,0.398663,-212.930313,0.039944,0.000000
63.110004,63.576263,-212.930313,-0.000617,0.001570,0.039866,282.801331,14.406588,0.398663,-212.930313,0.039944,0.000000
63.280003,63.575897,-212.974792,-0.000608,0.001570,0.039866,282.799713,14.406505,0.398663,-212.974792,0.039944,0.000000
63.450005,63.564346,-212.974792,-0.000634,0.001570,0.039866,282.748322,14.403887,0.398663,-212.974792,0.039944,0.000000
63.620003,63.553177,-212.974792,-0.000629,0.001570,0.039866,282.698639,14.401356,0.398663,-212.974792,0.039944,0.000000
63.790005,63.547974,-213.063751,-0.000629,0.001570,0.039866,282.675507,14.400177,0.398663,-213.063751,0.039944,0.000000
63.960003,63.540894,-213.063751,-0.000625,0.001570,0.039866,282.644012,14.398572,0.398663,-213.063751,0.039944,0.000000
64.130005,63.550949,-213.019272,-0.000629,0.001570,0.039866,282.688751,14.400850,0.398663,-213.019272,0.039944,0.000000
64.300003,63.528976,-212.974792,-0.000651,0.001570,0.039866,282.591003,14.395872,0.398663,-212.974792,0.039944,0.000000
64.470001,63.542007,-213.108231,-0.000647,0.001570,0.039866,282.648956,14.398825,0.398663,-213.108231,0.039944,0.000000
64.639999,63.514084,-213.152710,-0.000634,0.001570,0.039866,282.524750,14.392497,0.398663,-213.152710,0.039944,0.000000
64.810005,63.526749,-213.108231,-0.000621,0.001570,0.039866,282.581085,14.395367,0.398663,-213.108231,0.039944,0.000000
64.980003,63.510361,-213.152710,-0.000651,0.001570,0.039866,282.508179,14.391653,0.398663,-213.152710,0.039944,0.000000
65.150002,63.511841,-213.152710,-0.000625,0.001570,0.039866,282.514771,14.391990,0.398663,-213.152710,0.039944,0.000000
65.320000,63.489883,-213.197205,-0.000642,0.001570,0.039866,282.417114,14.387013,0.398663,-213.197205,0.039944,0.000000
65.490005,63.504028,-213.197205,-0.000634,0.001570,0.039866,282.480011,14.390219,0.398663,-213.197205,0.039944,0.000000
65.660004,63.490997,-213.241684,-0.000625,0.001570,0.039866,282.422058,14.387265,0.398663,-213.241684,0.039944,0.000000
65.830002,63.493225,-213.197205,-0.000647,0.001570,0.039866,282.431976,14.387771,0.398663,-213.197205,0.039944,0.000000
66.000000,63.477966,-213.241684,-0.000617,0.001570,0.039866,282.364105,14.384313,0.398663,-213.241684,0.039944,0.000000
66.170006,63.485413,-213.241684,-0.000638,0.001570,0.039866,282.397217,14.386000,0.398663,-213.241684,0.039944,0.000000
66.340004,63.476471,-213.286163,-0.000629,0.001570,0.039866,282.357452,14.383974,0.398663,-213.286163,0.039944,0.000000
66.510002,63.474243,-213.330643,-0.000638,0.001570,0.039866,282.347534,14.383469,0.398663,-213.330643,0.039944,0.000000
66.680000,63.465302,-213.286163,-0.000664,0.001570,0.039866,282.307770,14.381443,0.398663,-213.286163,0.039944,0.000000
66.850006,63.459351,-213.330643,-0.000651,0.001570,0.039866,282.281281,14.380095,0.398663,-213.330643,0.039944,0.000000
67.020004,63.439606,-213.375122,-0.000634,0.001570,0.039866,282.193451,14.375620,0.398663,-213.375122,0.039944,0.000000
67.190002,63.456360,-213.375122,-0.000642,0.001570,0.039866,282.267975,14.379416,0.398663,-213.375122,0.039944,0.000000
67.360001,63.444824,-213.330643,-0.000629,0.001570,0.039866,282.216675,14.376802,0.398663,-213.330643,0.039944,0.000000
67.530006,63.446686,-213.375122,-0.000634,0.001570,0.039866,282.224945,14.377225,0.398663,-213.375122,0.039944,0.000000
67.700005,63.428802,-213.419601,-0.000642,0.001570,0.039866,282.145416,14.373173,0.398663,-213.419601,0.039944,0.000000
67.870003,63.436249,-213.464081,-0.000634,0.001570,0.039866,282.178528,14.374859,0.398663,-213.464081,0.039944,0.000000
68.040001,63.426575,-213.419601,-0.000642,0.001570,0.039866,282.135498,14.372667,0.398663,-213.419601,0.039944,0.000000
68.210007,63.432159,-213.464081,-0.000625,0.001570,0.039866,282.160339,14.373933,0.398663,-213.464081,0.039944,0.000000
68.380005,63.418015,-213.464081,-0.000634,0.001570,0.039866,282.097412,14.370728,0.398663,-213.464081,0.039944,0.000000
68.550003,63.419128,-213.508560,-0.000660,0.001570,0.039866,282.102386,14.370980,0.398663,-213.508560,0.039944,0.000000
68.720001,63.412048,-213.508560,-0.000642,0.001570,0.039866,282.070892,14.369376,0.398663,-213.508560,0.039944,0.000000
68.890007,63.403488,-213.553040,-0.000629,0.001570,0.039866,282.032806,14.367435,0.398663,-213.553040,0.039944,0.000000
69.060005,63.399017,-213.553040,-0.000647,0.001570,0.039866,282.012909,14.366423,0.398663,-213.553040,0.039944,0.000000
69.230003,63.399765,-213.553040,-0.000604,0.001570,0.039866,282.016235,14.366592,0.398663,-213.553040,0.039944,0.000000
69.400002,63.382263,-213.553040,-0.000638,0.001570,0.039866,281.938385,14.362626,0.398663,-213.553040,0.039944,0.000000