File: PDMS and AD/AD Peeled Test 1-1 150N.csv
Time (sec),S:Load (lbs),S:HL1 (DIM),S:LVDT (in),S:Position (in),Ch:Position (mm),Ch:Load (N),Ch:Stress (MPa),Ch:Strain (mm/mm),Ch:HL1 (DIM),Set Point (),Cycles ()
0.110000,0.006699,-184.640427,0.000000,-0.000000,-0.000000,0.029797,0.001518,-0.000000,-184.640427,0.000182,0.000000
0.190000,0.004837,-184.684906,0.000000,-0.000000,-0.000000,0.021516,0.001096,-0.000000,-184.684906,0.000182,0.000000
0.270000,0.009682,-184.773865,-0.000009,-0.000000,-0.000000,0.043066,0.002194,-0.000000,-184.773865,0.000182,0.000000
0.350000,0.013405,-184.729385,-0.000004,-0.000000,-0.000000,0.059628,0.003038,-0.000000,-184.729385,0.000199,0.000000
0.430000,0.029411,-184.684906,0.000000,0.000018,0.000451,0.130828,0.006665,0.004510,-184.684906,0.000867,0.000000
0.510000,0.020851,-184.684906,-0.000013,0.000043,0.001093,0.092750,0.004725,0.010927,-184.684906,0.001535,0.000000
0.590000,-0.018250,-184.684906,0.000000,0.000066,0.001665,-0.081178,-0.004135,0.016652,-184.684906,0.002203,0.000000
0.670000,0.012657,-184.729385,-0.000009,0.000086,0.002177,0.056302,0.002868,0.021767,-184.729385,0.002870,0.000000
0.750000,0.012657,-184.684906,-0.000022,0.000102,0.002593,0.056302,0.002868,0.025930,-184.684906,0.003538,0.000000
0.830000,0.058456,-184.640427,-0.000009,0.000129,0.003287,0.260027,0.013246,0.032868,-184.640427,0.004197,0.000000
0.910000,0.094582,-184.640427,-0.000004,0.000155,0.003946,0.420720,0.021432,0.039459,-184.640427,0.004865,0.000000
0.990000,0.093834,-184.729385,0.000022,0.000177,0.004501,0.417394,0.021263,0.045010,-184.729385,0.005533,0.000000
1.070000,0.158997,-184.729385,0.000047,0.000208,0.005281,0.707252,0.036029,0.052814,-184.729385,0.006201,0.000000
1.150000,0.164581,-184.729385,0.000060,0.000229,0.005828,0.732094,0.037295,0.058278,-184.729385,0.006868,0.000000
1.230000,0.193626,-184.773865,0.000112,0.000258,0.006565,0.861293,0.043876,0.065649,-184.773865,0.007536,0.000000
1.310000,0.224541,-184.684906,0.000125,0.000283,0.007189,0.998807,0.050882,0.071894,-184.684906,0.008195,0.000000
1.390000,0.238312,-184.729385,0.000160,0.000308,0.007814,1.060064,0.054002,0.078137,-184.729385,0.008863,0.000000
1.470000,0.327682,-184.773865,0.000168,0.000337,0.008560,1.457605,0.074254,0.085595,-184.773865,0.009531,0.000000
1.550000,0.364922,-184.729385,0.000190,0.000356,0.009045,1.623252,0.082692,0.090451,-184.729385,0.010199,0.000000
1.630000,0.431206,-184.773865,0.000237,0.000390,0.009912,1.918099,0.097713,0.099125,-184.773865,0.010866,0.000000
1.710000,0.400299,-184.773865,0.000263,-0.000000,-0.000000,1.780619,0.090709,-0.000000,-184.773865,0.000147,0.000000
1.790000,0.388008,-184.729385,0.000263,-0.000000,-0.000009,1.725946,0.087924,-0.000087,-184.729385,0.000147,0.000000
1.870000,0.364922,-184.773865,0.000263,-0.000001,-0.000017,1.623252,0.082692,-0.000172,-184.773865,0.000147,0.000000
1.950000,0.376091,-184.773865,0.000254,-0.000001,-0.000017,1.672936,0.085223,-0.000172,-184.773865,0.000147,0.000000
2.030000,0.371254,-184.729385,0.000272,-0.000001,-0.000017,1.651420,0.084127,-0.000172,-184.729385,0.000147,0.000000
2.110000,0.364548,-184.729385,0.000263,-0.000001,-0.000017,1.621589,0.082608,-0.000172,-184.729385,0.000147,0.000000
2.190000,0.363808,-184.773865,0.000267,-0.000001,-0.000026,1.618297,0.082440,-0.000259,-184.773865,0.000147,0.000000
2.270000,0.318375,-184.773865,0.000250,-0.000001,-0.000026,1.416201,0.072145,-0.000259,-184.773865,0.000260,0.000000
2.350000,0.354126,-184.729385,0.000267,-0.000001,-0.000026,1.575231,0.080246,-0.000259,-184.729385,0.000390,0.000000
2.430000,0.335876,-184.684906,0.000254,-0.000001,-0.000026,1.494053,0.076111,-0.000259,-184.684906,0.000529,0.000000
2.510000,0.355614,-184.773865,0.000254,-0.000001,-0.000017,1.581849,0.080583,-0.000172,-184.773865,0.000659,0.000000
2.590000,0.339600,-184.818344,0.000259,-0.000001,-0.000017,1.510615,0.076954,-0.000172,-184.818344,0.000798,0.000000
2.670000,0.356354,-184.818344,0.000259,-0.000001,-0.000017,1.585141,0.080751,-0.000172,-184.818344,0.000928,0.000000
2.750000,0.330666,-184.773865,0.000263,-0.000001,-0.000017,1.470874,0.074930,-0.000172,-184.773865,0.001058,0.000000
2.830000,0.321724,-184.729385,0.000254,-0.000000,-0.000009,1.431100,0.072904,-0.000087,-184.729385,0.001197,0.000000
2.910000,0.306084,-184.773865,0.000263,0.000010,0.000260,1.361528,0.069360,0.002602,-184.773865,0.001327,0.000000
2.990000,0.463226,-184.773865,0.000272,0.000019,0.000494,2.060534,0.104969,0.004943,-184.773865,0.001457,0.000000
3.070000,0.449821,-184.818344,0.000272,0.000026,0.000650,2.000906,0.101931,0.006504,-184.818344,0.001596,0.000000
3.150000,0.491158,-184.773865,0.000267,0.000030,0.000772,2.184778,0.111298,0.007719,-184.773865,0.001726,0.000000
3.230000,0.503075,-184.773865,0.000276,0.000037,0.000937,2.237788,0.113998,0.009366,-184.773865,0.001865,0.000000
3.310000,0.520203,-184.729385,0.000289,0.000042,0.001067,2.313977,0.117880,0.010668,-184.729385,0.001995,0.000000
3.390000,0.563766,-184.729385,0.000285,0.000051,0.001283,2.507759,0.127751,0.012835,-184.729385,0.002125,0.000000
3.470000,0.572334,-184.818344,0.000302,0.000055,0.001388,2.545870,0.129693,0.013875,-184.818344,0.002264,0.000000
3.550000,0.599518,-184.818344,0.000293,0.000062,0.001570,2.666789,0.135853,0.015698,-184.818344,0.002394,0.000000
3.630000,0.613297,-184.773865,0.000310,0.000065,0.001648,2.728079,0.138975,0.016478,-184.773865,0.002524,0.000000
3.710000,0.647552,-184.818344,0.000319,0.000070,0.001778,2.880457,0.146737,0.017778,-184.818344,0.002662,0.000000
3.790000,0.637871,-184.862839,0.000319,0.000074,0.001873,2.837391,0.144544,0.018733,-184.862839,0.002792,0.000000
3.870000,0.677711,-184.818344,0.000315,0.000081,0.002064,3.014611,0.153572,0.020641,-184.818344,0.002931,0.000000
3.950000,0.687393,-184.818344,0.000332,0.000084,0.002125,3.057678,0.155766,0.021247,-184.818344,0.003061,0.000000
4.030000,0.669151,-184.818344,0.000310,0.000086,0.002194,2.976534,0.151632,0.021941,-184.818344,0.003191,0.000000
4.110000,0.723892,-184.773865,0.000332,0.000094,0.002385,3.220033,0.164036,0.023849,-184.773865,0.003330,0.000000
4.190000,0.747345,-184.907318,0.000345,0.000099,0.002524,3.324357,0.169351,0.025236,-184.907318,0.003460,0.000000
4.270000,0.736923,-184.862839,0.000336,0.000104,0.002654,3.277998,0.166989,0.026538,-184.862839,0.003590,0.000000
4.350000,0.774902,-184.773865,0.000345,0.000109,0.002758,3.446938,0.175595,0.027579,-184.773865,0.003729,0.000000
4.430000,0.809158,-184.818344,0.000349,0.000114,0.002897,3.599316,0.183358,0.028966,-184.818344,0.003859,0.000000
4.510000,0.758148,-184.862839,0.000366,0.000114,0.002897,3.372411,0.171799,0.028966,-184.862839,0.003998,0.000000
4.590000,0.780487,-184.818344,0.000375,0.000125,0.003165,3.471780,0.176861,0.031655,-184.818344,0.004128,0.000000
4.670000,0.873207,-184.862839,0.000371,0.000134,0.003400,3.884219,0.197872,0.033996,-184.862839,0.004258,0.000000
4.750000,0.878792,-184.862839,0.000371,0.000138,0.003512,3.909061,0.199137,0.035124,-184.862839,0.004397,0.000000
4.830000,0.884384,-184.818344,0.000379,0.000143,0.003642,3.933937,0.200404,0.036424,-184.818344,0.004527,0.000000
4.910000,0.891083,-184.862839,0.000392,0.000148,0.003755,3.963734,0.201922,0.037552,-184.862839,0.004657,0.000000
4.990000,0.916031,-184.862839,0.000401,0.000152,0.003859,4.074709,0.207576,0.038593,-184.862839,0.004796,0.000000
5.070000,0.957367,-184.818344,0.000392,0.000160,0.004059,4.258581,0.216942,0.040587,-184.818344,0.004926,0.000000
5.150000,0.980453,-184.773865,0.000397,0.000163,0.004137,4.361275,0.222174,0.041367,-184.773865,0.005065,0.000000
5.230000,0.978592,-184.818344,0.000418,0.000167,0.004249,4.352994,0.221752,0.042495,-184.818344,0.005195,0.000000
5.310000,1.018066,-184.818344,0.000418,0.000174,0.004414,4.528585,0.230697,0.044141,-184.818344,0.005325,0.000000
5.390000,1.032211,-184.862839,0.000414,0.000176,0.004475,4.591505,0.233902,0.044749,-184.862839,0.005463,0.000000
5.470000,1.026627,-184.862839,0.000414,0.000182,0.004614,4.566663,0.232637,0.046136,-184.862839,0.005594,0.000000
5.550000,1.165894,-184.818344,0.000418,0.000190,0.004830,5.186153,0.264195,0.048305,-184.818344,0.005724,0.000000
5.630000,1.195686,-184.862839,0.000431,0.000196,0.004969,5.318678,0.270946,0.049692,-184.862839,0.005862,0.000000
5.710000,1.176697,-184.907318,0.000435,0.000198,0.005021,5.234209,0.266643,0.050212,-184.907318,0.005993,0.000000
5.790000,1.179672,-184.907318,0.000435,0.000202,0.005125,5.247444,0.267318,0.051253,-184.907318,0.006131,0.000000
5.870000,1.221375,-184.862839,0.000435,0.000208,0.005281,5.432945,0.276767,0.052814,-184.862839,0.006261,0.000000
5.950000,1.293243,-184.818344,0.000444,0.000214,0.005429,5.752634,0.293053,0.054289,-184.818344,0.006392,0.000000
6.030000,1.282822,-184.818344,0.000448,0.000217,0.005516,5.706276,0.290692,0.055155,-184.818344,0.006530,0.000000
6.110000,1.322289,-184.862839,0.000444,0.000223,0.005654,5.881833,0.299635,0.056543,-184.862839,0.006660,0.000000
6.190000,1.396393,-184.907318,0.000457,0.000229,0.005810,6.211465,0.316427,0.058104,-184.907318,0.006790,0.000000
6.270000,1.486877,-184.818344,0.000470,0.000240,0.006105,6.613961,0.336931,0.061052,-184.818344,0.006929,0.000000
6.350000,1.518158,-184.818344,0.000479,0.000248,0.006296,6.753104,0.344020,0.062962,-184.818344,0.007059,0.000000
6.430000,1.534546,-184.862839,0.000496,0.000253,0.006435,6.826001,0.347733,0.064349,-184.862839,0.007198,0.000000
6.510000,1.559494,-184.907318,0.000496,0.000258,0.006556,6.936976,0.353386,0.065562,-184.907318,0.007328,0.000000
6.590000,1.585930,-184.907318,0.000500,0.000263,0.006669,7.054568,0.359377,0.066690,-184.907318,0.007458,0.000000
6.670001,1.628380,-184.907318,0.000500,0.000267,0.006782,7.243395,0.368996,0.067818,-184.907318,0.007597,0.000000
6.750000,1.663383,-184.818344,0.000509,0.000272,0.006912,7.399099,0.376928,0.069118,-184.818344,0.007727,0.000000
6.830000,1.662270,-184.862839,0.000504,0.000276,0.007007,7.394145,0.376676,0.070072,-184.862839,0.007857,0.000000
6.910000,1.708443,-184.862839,0.000513,0.000280,0.007120,7.599533,0.387139,0.071200,-184.862839,0.007996,0.000000
6.990000,1.757591,-184.907318,0.000530,0.000285,0.007250,7.818156,0.398276,0.072500,-184.907318,0.008126,0.000000
7.070000,1.828346,-184.907318,0.000522,0.000292,0.007424,8.132891,0.414309,0.074235,-184.907318,0.008265,0.000000
7.150001,1.875633,-184.907318,0.000526,0.000297,0.007554,8.343233,0.425025,0.075535,-184.907318,0.008395,0.000000
7.230000,1.917717,-184.907318,0.000535,0.000303,0.007692,8.530431,0.434561,0.076924,-184.907318,0.008525,0.000000
7.310000,1.997772,-184.862839,0.000548,0.000308,0.007822,8.886535,0.452702,0.078224,-184.862839,0.008664,0.000000
7.390000,2.036133,-184.996277,0.000548,0.000313,0.007952,9.057171,0.461394,0.079524,-184.996277,0.008794,0.000000
7.470000,2.117310,-184.907318,0.000539,0.000319,0.008100,9.418263,0.479789,0.080999,-184.907318,0.008933,0.000000
7.550000,2.154541,-184.907318,0.000556,0.000323,0.008213,9.583878,0.488226,0.082127,-184.907318,0.009063,0.000000
7.630001,2.231995,-184.907318,0.000556,0.000328,0.008343,9.928408,0.505777,0.083427,-184.907318,0.009193,0.000000
7.710001,2.234978,-184.907318,0.000565,0.000332,0.008430,9.941677,0.506453,0.084295,-184.907318,0.009331,0.000000
7.790000,2.302002,-184.907318,0.000565,0.000336,0.008542,10.239816,0.521641,0.085421,-184.907318,0.009461,0.000000
7.870000,2.321365,-184.907318,0.000560,0.000340,0.008629,10.325949,0.526029,0.086290,-184.907318,0.009591,0.000000
7.950000,2.293442,-184.907318,0.000569,0.000341,0.008664,10.201738,0.519701,0.086636,-184.907318,0.009730,0.000000
8.030001,2.484093,-184.907318,0.000569,0.000350,0.008898,11.049796,0.562903,0.088977,-184.907318,0.009860,0.000000
8.110001,2.466965,-184.907318,0.000578,0.000352,0.008933,10.973607,0.559022,0.089325,-184.907318,0.009999,0.000000
8.190001,2.553726,-184.907318,0.000586,0.000360,0.009141,11.359542,0.578683,0.091405,-184.907318,0.010129,0.000000
8.270000,2.755928,-184.907318,0.000573,0.000369,0.009384,12.258980,0.624502,0.093835,-184.907318,0.010259,0.000000
8.350000,2.810661,-184.907318,0.000599,0.000376,0.009557,12.502446,0.636905,0.095569,-184.907318,0.010398,0.000000
8.430000,2.805450,-184.862839,0.000604,0.000382,0.009696,12.479267,0.635724,0.096956,-184.862839,0.010528,0.000000
8.510000,2.888863,-184.996277,0.000617,0.000387,0.009834,12.850303,0.654626,0.098343,-184.996277,0.010658,0.000000
8.590000,2.933174,-184.951797,0.000621,0.000391,0.009938,13.047410,0.664667,0.099384,-184.951797,0.010797,0.000000
8.670000,2.975250,-184.951797,0.000604,0.000395,0.010025,13.234574,0.674201,0.100252,-184.951797,0.010927,0.000000
8.750000,2.997971,-184.907318,0.000625,0.000397,0.010086,13.335639,0.679350,0.100858,-184.907318,0.011066,0.000000
8.830001,3.024780,-184.907318,0.000621,0.000403,0.010242,13.454895,0.685425,0.102419,-184.907318,0.011196,0.000000
8.910001,3.255646,-184.907318,0.000621,0.000411,0.010433,14.481835,0.737740,0.104327,-184.907318,0.011326,0.000000
8.990001,3.278732,-184.996277,0.000625,0.000416,0.010554,14.584530,0.742971,0.105542,-184.996277,0.011465,0.000000
9.070001,3.401619,-184.996277,0.000634,0.000422,0.010719,15.131157,0.770818,0.107190,-184.996277,0.011595,0.000000
9.150001,3.476837,-184.951797,0.000638,0.000428,0.010875,15.465744,0.787863,0.108751,-184.951797,0.011725,0.000000
9.230000,3.533813,-184.907318,0.000651,0.000433,0.010996,15.719188,0.800774,0.109964,-184.907318,0.011864,0.000000
9.310000,3.669724,-184.951797,0.000642,0.000441,0.011196,16.323746,0.831571,0.111959,-184.951797,0.011994,0.000000
9.390000,3.786278,-184.951797,0.000660,0.000446,0.011326,16.842205,0.857983,0.113259,-184.951797,0.012132,0.000000
9.470000,3.826492,-184.951797,0.000651,0.000451,0.011447,17.021088,0.867096,0.114474,-184.951797,0.012263,0.000000
9.550000,3.899483,-184.907318,0.000668,0.000455,0.011551,17.345766,0.883635,0.115515,-184.907318,0.012393,0.000000
9.630000,3.965393,-184.951797,0.000668,0.000459,0.011656,17.638948,0.898571,0.116556,-184.951797,0.012531,0.000000
9.710000,3.985870,-184.951797,0.000668,0.000462,0.011725,17.730038,0.903211,0.117248,-184.951797,0.012662,0.000000
9.790001,3.972092,-184.951797,0.000677,0.000463,0.011768,17.668747,0.900089,0.117684,-184.951797,0.012792,0.000000
9.870001,4.205574,-184.996277,0.000668,0.000471,0.011959,18.707327,0.952997,0.119591,-184.996277,0.012930,0.000000
9.950001,4.314301,-184.907318,0.000686,0.000476,0.012080,19.190968,0.977634,0.120804,-184.907318,0.013061,0.000000
10.030001,4.378349,-184.951797,0.000690,0.000480,0.012202,19.475870,0.992148,0.122019,-184.951797,0.013199,0.000000
10.110001,4.643112,-184.996277,0.000686,0.000491,0.012479,20.653595,1.052144,0.124794,-184.996277,0.013329,0.000000
10.190001,4.722794,-184.996277,0.000681,0.000497,0.012618,21.008036,1.070200,0.126181,-184.996277,0.013459,0.000000
10.270000,4.830788,-184.951797,0.000694,0.000502,0.012757,21.488417,1.094672,0.127570,-184.951797,0.013598,0.000000
10.350000,4.873604,-184.951797,0.000711,0.000506,0.012852,21.678873,1.104374,0.128524,-184.951797,0.013728,0.000000
10.430000,4.926483,-184.907318,0.000716,0.000510,0.012948,21.914091,1.116357,0.129477,-184.907318,0.013858,0.000000
10.510000,5.169273,-185.040756,0.000720,0.000519,0.013182,22.994076,1.171374,0.131818,-185.040756,0.013997,0.000000
10.590000,5.244492,-185.040756,0.000724,0.000522,0.013260,23.328663,1.188419,0.132600,-185.040756,0.014127,0.000000
10.670000,5.302208,-184.951797,0.000720,0.000526,0.013373,23.585400,1.201498,0.133726,-184.951797,0.014266,0.000000
10.750001,5.367744,-184.951797,0.000737,0.000531,0.013494,23.876921,1.216348,0.134941,-184.951797,0.014396,0.000000
10.830001,5.553558,-184.907318,0.000746,0.000538,0.013667,24.703461,1.258454,0.136674,-184.907318,0.014526,0.000000
10.910001,5.620956,-184.996277,0.000737,0.000541,0.013746,25.003263,1.273727,0.137456,-184.996277,0.014665,0.000000
10.990001,5.706978,-184.996277,0.000737,0.000546,0.013867,25.385906,1.293220,0.138669,-184.996277,0.014795,0.000000
11.070001,5.716660,-184.951797,0.000742,0.000549,0.013945,25.428972,1.295414,0.139451,-184.951797,0.014925,0.000000
11.150001,5.819809,-184.996277,0.000746,0.000554,0.014075,25.887804,1.318787,0.140751,-184.996277,0.015064,0.000000
11.230000,6.195900,-184.951797,0.000755,0.000563,0.014292,27.560740,1.404011,0.142920,-184.951797,0.015194,0.000000
11.310000,6.372032,-184.996277,0.000759,0.000571,0.014491,28.344215,1.443923,0.144914,-184.996277,0.015333,0.000000
11.390000,6.517632,-185.085236,0.000763,0.000575,0.014604,28.991873,1.476916,0.146042,-185.085236,0.015463,0.000000
11.470000,6.579819,-184.996277,0.000759,0.000579,0.014708,29.268496,1.491008,0.147081,-184.996277,0.015593,0.000000
11.550000,6.601044,-184.996277,0.000746,0.000582,0.014778,29.362909,1.495818,0.147776,-184.996277,0.015732,0.000000
11.630000,6.694511,-184.951797,0.000776,0.000587,0.014908,29.778673,1.516998,0.149076,-184.951797,0.015862,0.000000
11.710001,6.776802,-184.951797,0.000785,0.000591,0.015020,30.144722,1.535645,0.150204,-184.951797,0.015992,0.000000
11.790001,6.984589,-185.085236,0.000780,0.000595,0.015116,31.069002,1.582730,0.151157,-185.085236,0.016130,0.000000
11.870001,7.106728,-184.951797,0.000776,0.000602,0.015281,31.612303,1.610407,0.152806,-184.951797,0.016260,0.000000
11.950001,7.207268,-184.996277,0.000776,0.000604,0.015333,32.059528,1.633190,0.153326,-184.996277,0.016399,0.000000
12.030001,7.386002,-184.996277,0.000789,0.000611,0.015515,32.854576,1.673692,0.155147,-184.996277,0.016529,0.000000
12.110001,7.829872,-185.040756,0.000798,0.000621,0.015775,34.829010,1.774274,0.157749,-185.040756,0.016659,0.000000
12.190001,7.949776,-185.040756,0.000798,0.000628,0.015948,35.362370,1.801445,0.159484,-185.040756,0.016798,0.000000
12.270000,8.192566,-184.951797,0.000798,0.000636,0.016148,36.442352,1.856462,0.161477,-184.951797,0.016928,0.000000
12.350000,8.298317,-185.085236,0.000811,0.000640,0.016252,36.912758,1.880425,0.162518,-185.085236,0.017058,0.000000
12.430000,8.450989,-185.040756,0.000806,0.000646,0.016417,37.591877,1.915021,0.164166,-185.040756,0.017197,0.000000
12.510000,8.570518,-185.040756,0.000832,0.000650,0.016512,38.123569,1.942107,0.165120,-185.040756,0.017327,0.000000
12.590000,8.651329,-185.040756,0.000828,0.000655,0.016633,38.483032,1.960419,0.166335,-185.040756,0.017466,0.000000
12.670001,8.802879,-184.996277,0.000802,0.000660,0.016763,39.157162,1.994761,0.167635,-184.996277,0.017596,0.000000
12.750001,8.951462,-184.996277,0.000815,0.000665,0.016894,39.818092,2.028430,0.168935,-184.996277,0.017726,0.000000
12.830001,9.024445,-185.040756,0.000832,0.000667,0.016937,40.142735,2.044968,0.169370,-185.040756,0.017865,0.000000
12.910001,9.175255,-185.085236,0.000828,0.000673,0.017093,40.813572,2.079142,0.170930,-185.085236,0.017995,0.000000
12.990001,9.419899,-185.040756,0.000841,0.000679,0.017241,41.901802,2.134580,0.172406,-185.040756,0.018125,0.000000
13.070001,9.662689,-185.040756,0.000836,0.000685,0.017397,42.981789,2.189597,0.173965,-185.040756,0.018264,0.000000
13.150001,9.952393,-185.040756,0.000836,0.000693,0.017613,44.270454,2.255244,0.176134,-185.040756,0.018394,0.000000
13.230000,10.247314,-185.040756,0.000862,0.000699,0.017761,45.582333,2.322075,0.177608,-185.040756,0.018533,0.000000
13.310000,10.315086,-185.040756,0.000858,0.000703,0.017847,45.883797,2.337432,0.178475,-185.040756,0.018663,0.000000
13.390000,10.349342,-185.040756,0.000841,0.000706,0.017926,46.036175,2.345194,0.179256,-185.040756,0.018793,0.000000
13.470000,10.469246,-185.040756,0.000858,0.000711,0.018047,46.569530,2.372365,0.180469,-185.040756,0.018932,0.000000
13.550000,10.581703,-185.040756,0.000862,0.000714,0.018125,47.069767,2.397848,0.181251,-185.040756,0.019062,0.000000
13.630001,10.754860,-185.085236,0.000862,0.000718,0.018238,47.840008,2.437086,0.182377,-185.085236,0.019192,0.000000
13.710001,10.825233,-185.129715,0.000862,0.000721,0.018316,48.153042,2.453033,0.183159,-185.129715,0.019330,0.000000
13.790001,10.867317,-185.129715,0.000867,0.000724,0.018385,48.340240,2.462569,0.183853,-185.129715,0.019461,0.000000
13.870001,11.462738,-184.996277,0.000871,0.000734,0.018645,50.988804,2.597494,0.186453,-184.996277,0.019599,0.000000
13.950001,11.684669,-185.085236,0.000867,0.000739,0.018776,51.976006,2.647784,0.187755,-185.085236,0.019729,0.000000
14.030001,11.824310,-185.040756,0.000880,0.000745,0.018914,52.597160,2.679427,0.189143,-185.040756,0.019860,0.000000
14.110001,12.103218,-185.129715,0.000875,0.000753,0.019131,53.837803,2.742628,0.191311,-185.129715,0.019998,0.000000
14.190001,12.422340,-185.085236,0.000888,0.000759,0.019270,55.257328,2.814943,0.192698,-185.085236,0.020128,0.000000
14.270000,12.595123,-185.040756,0.000892,0.000764,0.019400,56.025906,2.854096,0.193999,-185.040756,0.020258,0.000000
14.350000,12.837540,-185.129715,0.000892,0.000770,0.019556,57.104229,2.909028,0.195560,-185.129715,0.020397,0.000000
14.430000,12.849457,-185.040756,0.000901,0.000772,0.019617,57.157238,2.911729,0.196167,-185.040756,0.020527,0.000000
14.510000,13.184959,-185.129715,0.000884,0.000781,0.019825,58.649628,2.987754,0.198249,-185.129715,0.020666,0.000000
14.590001,13.276566,-185.129715,0.000918,0.000783,0.019894,59.057114,3.008513,0.198942,-185.129715,0.020796,0.000000
14.670001,13.491798,-185.085236,0.000910,0.000788,0.020024,60.014515,3.057285,0.200244,-185.085236,0.020926,0.000000
14.750001,13.693253,-185.129715,0.000910,0.000794,0.020163,60.910629,3.102935,0.201631,-185.129715,0.021065,0.000000
14.830001,13.780754,-185.040756,0.000918,0.000797,0.020232,61.299854,3.122764,0.202323,-185.040756,0.021195,0.000000
14.910001,14.086472,-185.174194,0.000910,0.000805,0.020441,62.659756,3.192040,0.204405,-185.174194,0.021325,0.000000
14.990001,14.314369,-185.085236,0.000918,0.000810,0.020579,63.673492,3.243683,0.205792,-185.085236,0.021464,0.000000
15.070001,14.502785,-185.129715,0.000923,0.000815,0.020692,64.511612,3.286378,0.206920,-185.129715,0.021594,0.000000
15.150001,14.791000,-185.129715,0.000940,0.000819,0.020814,65.793655,3.351688,0.208135,-185.129715,0.021733,0.000000
15.230000,14.956711,-185.085236,0.000944,0.000824,0.020926,66.530769,3.389239,0.209261,-185.085236,0.021863,0.000000
15.310000,15.025597,-185.129715,0.000927,0.000829,0.021056,66.837189,3.404849,0.210563,-185.129715,0.021993,0.000000
15.390000,15.186836,-185.085236,0.000940,0.000834,0.021195,67.554420,3.441386,0.211950,-185.085236,0.022132,0.000000
15.470000,15.785240,-185.129715,0.000949,0.000842,0.021386,70.216255,3.576987,0.213858,-185.129715,0.022262,0.000000
15.550001,15.931953,-185.085236,0.000953,0.000846,0.021490,70.868866,3.610232,0.214899,-185.085236,0.022392,0.000000
15.630001,15.951317,-185.085236,0.000953,0.000848,0.021551,70.955002,3.614620,0.215506,-185.085236,0.022531,0.000000
15.710001,15.972542,-185.129715,0.000953,0.000850,0.021594,71.049416,3.619430,0.215940,-185.129715,0.022661,0.000000
15.790001,16.275650,-185.174194,0.000949,0.000857,0.021776,72.397705,3.688115,0.217760,-185.174194,0.022799,0.000000
15.870001,16.413803,-185.129715,0.000966,0.000862,0.021898,73.012245,3.719421,0.218975,-185.129715,0.022929,0.000000
15.950001,16.671860,-185.085236,0.000961,0.000869,0.022062,74.160133,3.777897,0.220623,-185.085236,0.023060,0.000000
16.030001,17.212914,-185.129715,0.000970,0.000876,0.022262,76.566864,3.900502,0.222618,-185.129715,0.023198,0.000000
16.110001,17.676888,-185.129715,0.000961,0.000885,0.022478,78.630722,4.005640,0.224785,-185.129715,0.023328,0.000000
16.190001,17.885788,-185.129715,0.000974,0.000890,0.022600,79.559959,4.052978,0.226000,-185.129715,0.023458,0.000000
16.270000,18.096550,-185.129715,0.000974,0.000895,0.022721,80.497475,4.100737,0.227213,-185.129715,0.023597,0.000000
16.350000,18.216827,-185.129715,0.000974,0.000899,0.022834,81.032494,4.127992,0.228341,-185.129715,0.023727,0.000000
16.430000,18.392220,-185.174194,0.000979,0.000904,0.022964,81.812675,4.167737,0.229641,-185.174194,0.023866,0.000000
16.510000,18.676338,-185.174194,0.000996,0.000909,0.023077,83.076500,4.232119,0.230769,-185.174194,0.023996,0.000000
16.590000,18.682671,-185.174194,0.000974,0.000913,0.023190,83.104668,4.233554,0.231897,-185.174194,0.024126,0.000000
16.670000,19.029716,-185.174194,0.000992,0.000918,0.023320,84.648407,4.312195,0.233197,-185.174194,0.024265,0.000000
16.750000,19.066208,-185.174194,0.000979,0.000920,0.023372,84.810730,4.320464,0.233717,-185.174194,0.024395,0.000000
16.830000,19.375656,-185.129715,0.000987,0.000929,0.023589,86.187225,4.390586,0.235886,-185.129715,0.024525,0.000000
16.910002,19.865326,-185.129715,0.001005,0.000936,0.023762,88.365379,4.501547,0.237619,-185.129715,0.024664,0.000000
16.990002,20.117790,-185.174194,0.000996,0.000941,0.023892,89.488403,4.558756,0.238921,-185.174194,0.024794,0.000000
17.070002,20.401909,-185.129715,0.001018,0.000946,0.024040,90.752220,4.623138,0.240396,-185.129715,0.024933,0.000000
17.150002,20.595543,-185.129715,0.001005,0.000952,0.024187,91.613548,4.667017,0.241870,-185.129715,0.025063,0.000000
17.230001,20.932915,-185.174194,0.001005,0.000958,0.024326,93.114258,4.743466,0.243257,-185.174194,0.025193,0.000000
17.310001,21.165276,-185.129715,0.001018,0.000962,0.024447,94.147850,4.796120,0.244472,-185.129715,0.025332,0.000000
17.390001,21.256134,-185.174194,0.001013,0.000966,0.024525,94.552010,4.816709,0.245252,-185.174194,0.025462,0.000000
17.470001,21.435242,-185.174194,0.001026,0.000969,0.024612,95.348717,4.857296,0.246118,-185.174194,0.025592,0.000000
17.550001,21.489983,-185.174194,0.001022,0.000972,0.024699,95.592216,4.869699,0.246987,-185.174194,0.025731,0.000000
17.630001,21.538765,-185.129715,0.001039,0.000977,0.024820,95.809212,4.880754,0.248200,-185.129715,0.025861,0.000000
17.710001,21.799423,-185.218674,0.001022,0.000982,0.024942,96.968674,4.939820,0.249415,-185.218674,0.025999,0.000000
17.790001,22.156532,-185.218674,0.001035,0.000987,0.025080,98.557175,5.020742,0.250802,-185.218674,0.026130,0.000000
17.870001,22.349792,-185.129715,0.001039,0.000989,0.025132,99.416840,5.064536,0.251323,-185.129715,0.026260,0.000000
17.950001,22.900902,-185.218674,0.001043,0.001000,0.025401,101.868301,5.189419,0.254010,-185.218674,0.026398,0.000000
18.030001,23.234177,-185.129715,0.001052,0.001005,0.025531,103.350777,5.264940,0.255312,-185.129715,0.026529,0.000000
18.110001,23.487015,-185.218674,0.001048,0.001010,0.025661,104.475456,5.322234,0.256612,-185.218674,0.026659,0.000000
18.190001,23.695175,-185.218674,0.001030,0.001016,0.025817,105.401405,5.369403,0.258173,-185.218674,0.026797,0.000000
18.270000,24.069038,-185.218674,0.001061,0.001023,0.025973,107.064430,5.454122,0.259735,-185.218674,0.026927,0.000000
18.350000,24.258575,-185.174194,0.001048,0.001026,0.026051,107.907532,5.497072,0.260514,-185.174194,0.027066,0.000000
18.430000,24.493164,-185.218674,0.001052,0.001032,0.026208,108.951035,5.550230,0.262076,-185.218674,0.027196,0.000000
18.510000,24.869637,-185.218674,0.001052,0.001038,0.026372,110.625671,5.635540,0.263724,-185.218674,0.027326,0.000000
18.590000,25.143700,-185.218674,0.001069,0.001044,0.026511,111.844765,5.697644,0.265111,-185.218674,0.027465,0.000000
18.670000,25.306801,-185.129715,0.001065,0.001049,0.026641,112.570274,5.734603,0.266411,-185.129715,0.027595,0.000000
18.750000,25.418510,-185.129715,0.001069,0.001052,0.026719,113.067184,5.759917,0.267193,-185.129715,0.027725,0.000000
18.830002,25.647148,-185.174194,0.001087,0.001060,0.026919,114.084213,5.811727,0.269187,-185.174194,0.027864,0.000000
18.910002,26.152832,-185.218674,0.001074,0.001065,0.027040,116.333611,5.926316,0.270400,-185.218674,0.027994,0.000000
18.990002,26.251137,-185.218674,0.001078,0.001067,0.027109,116.770889,5.948593,0.271095,-185.218674,0.028133,0.000000
19.070002,26.528557,-185.174194,0.001078,0.001075,0.027309,118.004913,6.011457,0.273090,-185.174194,0.028263,0.000000
19.150002,26.888268,-185.129715,0.001095,0.001081,0.027448,119.604988,6.092968,0.274477,-185.129715,0.028393,0.000000
19.230001,27.422623,-185.174194,0.001087,0.001088,0.027630,121.981918,6.214055,0.276299,-185.174194,0.028532,0.000000
19.310001,27.523163,-185.263168,0.001091,0.001090,0.027690,122.429146,6.236838,0.276905,-185.263168,0.028662,0.000000
19.390001,27.717537,-185.263168,0.001099,0.001095,0.027812,123.293762,6.280883,0.278120,-185.263168,0.028792,0.000000
19.470001,27.707489,-185.218674,0.001104,0.001096,0.027829,123.249069,6.278607,0.278294,-185.218674,0.028931,0.000000
19.550001,27.788666,-185.174194,0.001108,0.001099,0.027916,123.610161,6.297002,0.279161,-185.174194,0.029061,0.000000
19.630001,28.196037,-185.218674,0.001117,0.001109,0.028176,125.422241,6.389313,0.281763,-185.218674,0.029200,0.000000
19.710001,28.741936,-185.263168,0.001112,0.001114,0.028289,127.850517,6.513016,0.282889,-185.263168,0.029330,0.000000
19.790001,28.951958,-185.218674,0.001104,0.001119,0.028410,128.784744,6.560607,0.284104,-185.218674,0.029460,0.000000
19.870001,29.391724,-185.218674,0.001108,0.001126,0.028601,130.740921,6.660260,0.286011,-185.218674,0.029598,0.000000
19.950001,29.819214,-185.218674,0.001121,0.001133,0.028775,132.642487,6.757131,0.287747,-185.218674,0.029728,0.000000
20.030001,30.237015,-185.263168,0.001117,0.001140,0.028957,134.500961,6.851806,0.289567,-185.263168,0.029859,0.000000
20.110001,30.597466,-185.263168,0.001117,0.001145,0.029095,136.104324,6.933485,0.290954,-185.263168,0.029997,0.000000
20.190001,30.763176,-185.218674,0.001121,0.001151,0.029226,136.841446,6.971035,0.292256,-185.218674,0.030127,0.000000
20.270000,30.965370,-185.218674,0.001125,0.001154,0.029321,137.740845,7.016853,0.293210,-185.218674,0.030266,0.000000
20.350000,31.104637,-185.263168,0.001125,0.001160,0.029460,138.360336,7.048411,0.294597,-185.263168,0.030396,0.000000
20.430000,31.522072,-185.307648,0.001138,0.001166,0.029607,140.217178,7.143003,0.296072,-185.307648,0.030526,0.000000
20.510000,31.715332,-185.218674,0.001130,0.001170,0.029711,141.076843,7.186797,0.297112,-185.218674,0.030665,0.000000
20.590000,31.916412,-185.263168,0.001125,0.001175,0.029833,141.971298,7.232362,0.298325,-185.263168,0.030795,0.000000
20.670000,32.152122,-185.218674,0.001155,0.001179,0.029954,143.019791,7.285775,0.299540,-185.218674,0.030934,0.000000
20.750002,32.520775,-185.263168,0.001147,0.001186,0.030119,144.659637,7.369313,0.301189,-185.263168,0.031064,0.000000
20.830002,32.871918,-185.263168,0.001160,0.001191,0.030258,146.221588,7.448883,0.302576,-185.263168,0.031194,0.000000
20.910002,33.071510,-185.263168,0.001143,0.001196,0.030379,147.109421,7.494112,0.303789,-185.263168,0.031333,0.000000
20.990002,33.347069,-185.263168,0.001155,0.001202,0.030526,148.335175,7.556554,0.305263,-185.263168,0.031463,0.000000
21.070002,33.734337,-185.218674,0.001164,0.001206,0.030639,150.057831,7.644310,0.306391,-185.218674,0.031593,0.000000
21.150002,33.435318,-185.263168,0.001173,0.001197,0.030414,148.727722,7.576551,0.304137,-185.263168,0.030648,0.000000
21.230001,33.245041,-185.218674,0.001173,0.001197,0.030414,147.881332,7.533434,0.304137,-185.218674,0.030648,0.000000
21.310001,33.064064,-185.307648,0.001151,0.001197,0.030414,147.076309,7.492424,0.304137,-185.307648,0.030648,0.000000
21.390001,32.927406,-185.263168,0.001164,0.001197,0.030414,146.468414,7.461457,0.304137,-185.263168,0.030648,0.000000
21.470001,32.913628,-185.263168,0.001164,0.001197,0.030405,146.407135,7.458335,0.304050,-185.263168,0.030587,0.000000
21.550001,32.794098,-185.307648,0.001173,0.001196,0.030388,145.875427,7.431249,0.303876,-185.307648,0.030457,0.000000
21.630001,32.687599,-185.263168,0.001168,0.001196,0.030370,145.401703,7.407116,0.303704,-185.263168,0.030327,0.000000
21.710001,32.591522,-185.352127,0.001177,0.001195,0.030362,144.974335,7.385345,0.303617,-185.352127,0.030188,0.000000
21.790001,32.491356,-185.307648,0.001173,0.001191,0.030258,144.528763,7.362647,0.302576,-185.307648,0.030058,0.000000
21.870001,32.398636,-185.263168,0.001186,0.001186,0.030119,144.116333,7.341636,0.301189,-185.263168,0.029919,0.000000
21.950001,32.297348,-185.263168,0.001173,0.001181,0.029997,143.665787,7.318684,0.299974,-185.263168,0.029789,0.000000
22.030001,32.185638,-185.352127,0.001181,0.001176,0.029867,143.168869,7.293370,0.298674,-185.352127,0.029659,0.000000
22.110001,32.127548,-185.263168,0.001177,0.001172,0.029763,142.910477,7.280206,0.297633,-185.263168,0.029520,0.000000
22.190001,32.073555,-185.352127,0.001168,0.001167,0.029650,142.670303,7.267972,0.296505,-185.352127,0.029390,0.000000
22.270000,31.941734,-185.307648,0.001181,0.001163,0.029529,142.083923,7.238101,0.295290,-185.307648,0.029260,0.000000
22.350000,31.971527,-185.352127,0.001190,0.001159,0.029451,142.216461,7.244852,0.294510,-185.352127,0.029122,0.000000
22.430000,31.910828,-185.263168,0.001177,0.001158,0.029408,141.946457,7.231097,0.294077,-185.263168,0.028991,0.000000
22.510000,31.836349,-185.307648,0.001177,0.001153,0.029286,141.615158,7.214220,0.292862,-185.307648,0.028853,0.000000
22.590000,31.743629,-185.307648,0.001177,0.001149,0.029182,141.202713,7.193210,0.291821,-185.307648,0.028723,0.000000
22.670002,31.723526,-185.263168,0.001181,0.001143,0.029043,141.113297,7.188654,0.290434,-185.263168,0.028592,0.000000
22.750002,31.691498,-185.307648,0.001186,0.001139,0.028939,140.970825,7.181396,0.289393,-185.307648,0.028454,0.000000
22.830002,31.638992,-185.352127,0.001186,0.001135,0.028818,140.737274,7.169498,0.288180,-185.352127,0.028324,0.000000
22.910002,31.574203,-185.307648,0.001173,0.001130,0.028714,140.449066,7.154817,0.287139,-185.307648,0.028193,0.000000
22.990002,31.543297,-185.307648,0.001177,0.001124,0.028558,140.311584,7.147813,0.285578,-185.307648,0.028055,0.000000
23.070002,31.500847,-185.352127,0.001194,0.001118,0.028402,140.122772,7.138194,0.284017,-185.352127,0.027925,0.000000
23.150002,31.511269,-185.263168,0.001190,0.001107,0.028124,140.169128,7.140555,0.281242,-185.263168,0.027786,0.000000
23.230001,31.471802,-185.263168,0.001181,0.001103,0.028011,139.993561,7.131612,0.280114,-185.263168,0.027656,0.000000
23.310001,31.435677,-185.396606,0.001186,0.001098,0.027899,139.832870,7.123426,0.278987,-185.396606,0.027526,0.000000
23.390001,31.428604,-185.352127,0.001186,0.001094,0.027795,139.801407,7.121824,0.277946,-185.352127,0.027387,0.000000
23.470001,31.373123,-185.263168,0.001168,0.001087,0.027621,139.554626,7.109251,0.276212,-185.263168,0.027257,0.000000
23.550001,31.351524,-185.307648,0.001194,0.001083,0.027517,139.458542,7.104357,0.275171,-185.307648,0.027127,0.000000
23.630001,31.289337,-185.352127,0.001177,0.001077,0.027361,139.181931,7.090265,0.273610,-185.352127,0.026988,0.000000
23.710001,31.303864,-185.396606,0.001181,0.001074,0.027283,139.246536,7.093557,0.272830,-185.396606,0.026858,0.000000
23.790001,31.243538,-185.352127,0.001186,0.001072,0.027222,138.978195,7.079887,0.272223,-185.352127,0.026719,0.000000
23.870001,31.222679,-185.307648,0.001190,0.001065,0.027057,138.885406,7.075160,0.270575,-185.307648,0.026589,0.000000
23.950001,31.180603,-185.352127,0.001186,0.001060,0.026927,138.698242,7.065626,0.269274,-185.352127,0.026459,0.000000
24.030001,31.160500,-185.396606,0.001186,0.001055,0.026797,138.608826,7.061070,0.267972,-185.396606,0.026320,0.000000
24.110001,31.140762,-185.352127,0.001177,0.001050,0.026667,138.521027,7.056597,0.266672,-185.352127,0.026190,0.000000
24.190001,31.096077,-185.307648,0.001186,0.001044,0.026520,138.322266,7.046472,0.265198,-185.307648,0.026060,0.000000
24.270000,31.141136,-185.307648,0.001186,0.001037,0.026329,138.522690,7.056682,0.263291,-185.307648,0.025921,0.000000
24.350000,31.063683,-185.307648,0.001190,0.001035,0.026294,138.178162,7.039131,0.262942,-185.307648,0.025791,0.000000
24.430000,31.068893,-185.396606,0.001186,0.001033,0.026234,138.201340,7.040312,0.262337,-185.396606,0.025653,0.000000
24.510000,30.998138,-185.441086,0.001186,0.001026,0.026069,137.886612,7.024279,0.260688,-185.441086,0.025522,0.000000
24.590002,30.967979,-185.396606,0.001190,0.001021,0.025930,137.752457,7.017445,0.259301,-185.396606,0.025392,0.000000
24.670002,30.955688,-185.307648,0.001199,0.001015,0.025774,137.697784,7.014659,0.257740,-185.307648,0.025254,0.000000
24.750002,30.957550,-185.307648,0.001194,0.001012,0.025713,137.706055,7.015081,0.257133,-185.307648,0.025124,0.000000
24.830002,30.934837,-185.396606,0.001177,0.001008,0.025609,137.605026,7.009934,0.256092,-185.396606,0.024994,0.000000
24.910002,30.922180,-185.441086,0.001177,0.001005,0.025522,137.548721,7.007066,0.255225,-185.441086,0.024855,0.000000
24.990002,30.887917,-185.352127,0.001194,0.001000,0.025392,137.396317,6.999302,0.253925,-185.352127,0.024725,0.000000
25.070002,30.839142,-185.352127,0.001194,0.000997,0.025314,137.179352,6.988250,0.253143,-185.352127,0.024586,0.000000
25.150002,30.819405,-185.352127,0.001186,0.000989,0.025124,137.091553,6.983777,0.251236,-185.352127,0.024456,0.000000
25.230001,30.644386,-185.396606,0.001194,0.000977,0.024811,136.313034,6.944117,0.248113,-185.396606,0.024326,0.000000
25.310001,30.617577,-185.441086,0.001168,0.000971,0.024673,136.193787,6.938042,0.246726,-185.441086,0.024187,0.000000
25.390001,30.593376,-185.396606,0.001186,0.000969,0.024612,136.086136,6.932558,0.246118,-185.396606,0.024057,0.000000
25.470001,30.608643,-185.396606,0.001194,0.000966,0.024525,136.154037,6.936018,0.245252,-185.396606,0.023927,0.000000
25.550001,30.557999,-185.396606,0.001194,0.000960,0.024386,135.928772,6.924541,0.243865,-185.396606,0.023788,0.000000
25.630001,30.379257,-185.396606,0.001186,0.000954,0.024239,135.133682,6.884038,0.242390,-185.396606,0.023658,0.000000
25.710001,30.260475,-185.396606,0.001186,0.000951,0.024152,134.605316,6.857121,0.241524,-185.396606,0.023519,0.000000
25.790001,30.177063,-185.396606,0.001199,0.000947,0.024057,134.234283,6.838220,0.240568,-185.396606,0.023389,0.000000
25.870001,30.066841,-185.352127,0.001177,0.000944,0.023970,133.743988,6.813244,0.239701,-185.352127,0.023259,0.000000
25.950001,29.900017,-185.352127,0.001203,0.000940,0.023875,133.001923,6.775441,0.238747,-185.352127,0.023120,0.000000
26.030001,29.649406,-185.441086,0.001190,0.000929,0.023589,131.887146,6.718652,0.235886,-185.441086,0.022990,0.000000
26.110001,29.512375,-185.441086,0.001177,0.000926,0.023528,131.277603,6.687600,0.235279,-185.441086,0.022860,0.000000
26.190001,29.406624,-185.396606,0.001194,0.000921,0.023398,130.807190,6.663636,0.233978,-185.396606,0.022721,0.000000
26.270000,29.122871,-185.396606,0.001194,0.000914,0.023216,129.544998,6.599337,0.232156,-185.396606,0.022591,0.000000
26.350000,28.950836,-185.396606,0.001190,0.000910,0.023112,128.779755,6.560353,0.231115,-185.396606,0.022453,0.000000
26.430000,28.750130,-185.396606,0.001212,0.000906,0.023008,127.886963,6.514873,0.230076,-185.396606,0.022322,0.000000
26.510002,28.530060,-185.441086,0.001186,0.000901,0.022886,126.908043,6.465004,0.228861,-185.441086,0.022192,0.000000
26.590002,28.363235,-185.485565,0.001186,0.000900,0.022851,126.165970,6.427201,0.228515,-185.485565,0.022054,0.000000
26.670002,28.086563,-185.441086,0.001207,0.000892,0.022661,124.935272,6.364506,0.226607,-185.441086,0.021923,0.000000
26.750002,27.799835,-185.352127,0.001199,0.000888,0.022557,123.659843,6.299533,0.225566,-185.352127,0.021793,0.000000
26.830002,27.640091,-185.396606,0.001207,0.000884,0.022453,122.949265,6.263334,0.224526,-185.396606,0.021655,0.000000
26.910002,27.297874,-185.441086,0.001194,0.000879,0.022331,121.427010,6.185787,0.223311,-185.441086,0.021525,0.000000
26.990002,27.169037,-185.396606,0.001207,0.000876,0.022253,120.853912,6.156592,0.222531,-185.396606,0.021386,0.000000
27.070002,27.021950,-185.396606,0.001194,0.000876,0.022253,120.199638,6.123261,0.222531,-185.396606,0.021256,0.000000
27.150002,26.747513,-185.441086,0.001212,0.000870,0.022088,118.978882,6.061073,0.220883,-185.441086,0.021126,0.000000
27.230001,25.990852,-185.441086,0.001199,0.000856,0.021733,115.613083,5.889612,0.217327,-185.441086,0.020987,0.000000
27.310001,25.371964,-185.485565,0.001194,0.000847,0.021525,112.860130,5.749369,0.215245,-185.485565,0.020857,0.000000
27.390001,24.884903,-185.396606,0.001199,0.000842,0.021377,110.693573,5.638999,0.213771,-185.396606,0.020727,0.000000
27.470001,24.625732,-185.396606,0.001203,0.000840,0.021342,109.540726,5.580270,0.213425,-185.396606,0.020588,0.000000
27.550001,24.510300,-185.441086,0.001212,0.000838,0.021273,109.027260,5.554113,0.212730,-185.441086,0.020458,0.000000
27.630001,24.071640,-185.441086,0.001220,0.000832,0.021134,107.076004,5.454711,0.211343,-185.441086,0.020319,0.000000
27.710001,23.610275,-185.441086,0.001203,0.000825,0.020952,105.023750,5.350165,0.209522,-185.441086,0.020189,0.000000
27.790001,23.091560,-185.441086,0.001207,0.000820,0.020831,102.716393,5.232622,0.208307,-185.441086,0.020059,0.000000
27.870001,22.773178,-185.441086,0.001199,0.000817,0.020744,101.300156,5.160476,0.207441,-185.441086,0.019920,0.000000
27.950001,22.334152,-185.441086,0.001216,0.000811,0.020597,99.347267,5.060991,0.205966,-185.441086,0.019790,0.000000
28.030001,21.955818,-185.441086,0.001220,0.000806,0.020475,97.664360,4.975259,0.204751,-185.441086,0.019660,0.000000
28.110001,21.384972,-185.441086,0.001194,0.000800,0.020319,95.125107,4.845904,0.203192,-185.441086,0.019521,0.000000
28.190001,20.904243,-185.441086,0.001194,0.000795,0.020180,92.986717,4.736969,0.201803,-185.441086,0.019391,0.000000
28.270000,20.504684,-185.441086,0.001199,0.000790,0.020059,91.209389,4.646428,0.200590,-185.441086,0.019252,0.000000
28.350002,19.869049,-185.441086,0.001199,0.000783,0.019877,88.381943,4.502391,0.198769,-185.441086,0.019122,0.000000
28.430002,19.464653,-185.530045,0.001212,0.000779,0.019781,86.583099,4.410754,0.197814,-185.530045,0.018992,0.000000
28.510002,19.072540,-185.530045,0.001212,0.000775,0.019695,84.838898,4.321899,0.196947,-185.530045,0.018854,0.000000
28.590002,18.761612,-185.530045,0.001212,0.000771,0.019582,83.455818,4.251442,0.195819,-185.530045,0.018723,0.000000
28.670002,18.271942,-185.485565,0.001207,0.000767,0.019469,81.277657,4.140481,0.194693,-185.485565,0.018593,0.000000
28.750002,17.924889,-185.441086,0.001216,0.000761,0.019322,79.733887,4.061838,0.193219,-185.441086,0.018455,0.000000
28.830002,17.298187,-185.485565,0.001212,0.000756,0.019209,76.946182,3.919825,0.192091,-185.485565,0.018325,0.000000
28.910002,16.767929,-185.485565,0.001203,0.000750,0.019053,74.587471,3.799667,0.190530,-185.485565,0.018186,0.000000
28.990002,16.280869,-185.485565,0.001220,0.000746,0.018958,72.420921,3.689297,0.189576,-185.485565,0.018056,0.000000
29.070002,16.048874,-185.485565,0.001212,0.000742,0.018854,71.388954,3.636727,0.188535,-185.485565,0.017926,0.000000
29.150002,15.206940,-185.441086,0.001216,0.000733,0.018611,67.643845,3.445942,0.186107,-185.441086,0.017787,0.000000
29.230001,14.493477,-185.485565,0.001199,0.000724,0.018394,64.470207,3.284269,0.183938,-185.485565,0.017657,0.000000
29.310001,13.783737,-185.485565,0.001207,0.000719,0.018255,61.313126,3.123439,0.182551,-185.485565,0.017527,0.000000
29.390001,13.367424,-185.441086,0.001207,0.000715,0.018168,59.461273,3.029102,0.181684,-185.441086,0.017388,0.000000
29.470001,13.193153,-185.441086,0.001216,0.000714,0.018125,58.686077,2.989611,0.181251,-185.441086,0.017258,0.000000
29.550001,12.965263,-185.485565,0.001216,0.000711,0.018064,57.672371,2.937971,0.180644,-185.485565,0.017119,0.000000
29.630001,12.624916,-185.574524,0.001212,0.000707,0.017969,56.158432,2.860847,0.179690,-185.574524,0.016989,0.000000
29.710001,12.349358,-185.530045,0.001207,0.000704,0.017874,54.932686,2.798404,0.178736,-185.530045,0.016859,0.000000
29.790001,11.896927,-185.485565,0.001207,0.000699,0.017743,52.920174,2.695882,0.177434,-185.485565,0.016720,0.000000
29.870001,11.409492,-185.485565,0.001207,0.000694,0.017622,50.751957,2.585428,0.176221,-185.485565,0.016590,0.000000
29.950001,10.841248,-185.530045,0.001212,0.000689,0.017492,48.224277,2.456662,0.174919,-185.530045,0.016460,0.000000
30.030001,10.496803,-185.574524,0.001212,0.000683,0.017344,46.692112,2.378610,0.173445,-185.574524,0.016321,0.000000
30.110001,9.717430,-185.530045,0.001212,0.000675,0.017136,43.225288,2.202001,0.171365,-185.530045,0.016191,0.000000
30.190001,9.222176,-185.485565,0.001203,0.000670,0.017006,41.022285,2.089775,0.170063,-185.485565,0.016052,0.000000
30.270002,8.458435,-185.441086,0.001212,0.000660,0.016763,37.625000,1.916709,0.167635,-185.441086,0.015922,0.000000
30.350002,7.580383,-185.485565,0.001216,0.000653,0.016581,33.719231,1.717739,0.165814,-185.485565,0.015792,0.000000
30.430002,7.230354,-185.574524,0.001207,0.000649,0.016495,32.162224,1.638422,0.164948,-185.574524,0.015653,0.000000
30.510002,6.860588,-185.530045,0.001212,0.000645,0.016391,30.517420,1.554632,0.163907,-185.530045,0.015523,0.000000
30.590002,6.535881,-185.485565,0.001207,0.000641,0.016278,29.073051,1.481052,0.162779,-185.485565,0.015393,0.000000
30.670002,6.041367,-185.485565,0.001212,0.000636,0.016165,26.873341,1.368993,0.161651,-185.485565,0.015254,0.000000
30.750002,5.541267,-185.530045,0.001207,0.000631,0.016026,24.648788,1.255669,0.160264,-185.530045,0.015124,0.000000
30.830002,5.191986,-185.574524,0.001216,0.000626,0.015896,23.095108,1.176521,0.158964,-185.574524,0.014986,0.000000
30.910002,4.695984,-185.574524,0.001194,0.000621,0.015766,20.888779,1.064125,0.157662,-185.574524,0.014856,0.000000
30.990002,4.306114,-185.530045,0.001220,0.000618,0.015688,19.154552,0.975779,0.156882,-185.530045,0.014726,0.000000
31.070002,4.017151,-185.530045,0.001212,0.000613,0.015575,17.869179,0.910299,0.155754,-185.530045,0.014587,0.000000
31.150002,3.002434,-185.574524,0.001203,0.000598,0.015185,13.355493,0.680361,0.151852,-185.574524,0.014457,0.000000
31.230001,2.330307,-185.530045,0.001194,0.000593,0.015064,10.365724,0.528055,0.150637,-185.530045,0.014327,0.000000
31.310001,2.034637,-185.574524,0.001212,0.000589,0.014968,9.050519,0.461055,0.149683,-185.574524,0.014188,0.000000
31.390001,1.793343,-185.530045,0.001207,0.000586,0.014882,7.977186,0.406377,0.148816,-185.530045,0.014058,0.000000
31.470001,1.543854,-185.530045,0.001203,0.000581,0.014760,6.867404,0.349842,0.147601,-185.530045,0.013919,0.000000
31.550001,1.340912,-185.574524,0.001220,0.000579,0.014708,5.964674,0.303855,0.147081,-185.574524,0.013789,0.000000
31.630001,1.050835,-185.574524,0.001203,0.000573,0.014552,4.674346,0.238123,0.145522,-185.574524,0.013659,0.000000
31.710001,0.826294,-185.619003,0.001199,0.000569,0.014457,3.675539,0.187241,0.144566,-185.619003,0.013520,0.000000
31.790001,0.607338,-185.530045,0.001199,0.000565,0.014353,2.701574,0.137625,0.143527,-185.530045,0.013390,0.000000
31.870001,0.420036,-185.530045,0.001207,0.000560,0.014222,1.868415,0.095182,0.142225,-185.530045,0.013260,0.000000
31.950001,0.264381,-185.574524,0.001216,0.000554,0.014084,1.176027,0.059910,0.140838,-185.574524,0.013121,0.000000
32.030003,0.211502,-185.574524,0.001220,0.000554,0.014066,0.940808,0.047927,0.140664,-185.574524,0.013988,0.000000
32.100002,0.279648,-185.574524,0.001212,0.000554,0.014075,1.243936,0.063369,0.140751,-185.574524,0.013988,0.000000