File: PDMS and AD/AD Peeled Test 1-1 300N_02142024_161038.csv
Time (sec),S:Load (lbs),S:HL1 (DIM),S:LVDT (in),S:Position (in),Ch:Position (mm),Ch:Load (N),Ch:Stress (MPa),Ch:Strain (mm/mm),Ch:HL1 (DIM),Set Point (),Cycles ()
0.110000,-0.008568,-177.345551,-0.000017,-0.000000,-0.000000,-0.038112,-0.001941,-0.000000,-177.345551,0.000243,0.000000
0.330000,-0.011917,-177.434509,-0.000022,-0.000000,-0.000000,-0.053010,-0.002700,-0.000000,-177.434509,0.000243,0.000000
0.550000,0.023087,-177.390030,-0.000017,0.000106,0.002688,0.102694,0.005231,0.026884,-177.390030,0.003694,0.000000
0.770000,0.006699,-177.390030,0.000039,0.000240,0.006097,0.029797,0.001518,0.060965,-177.390030,0.007354,0.000000
0.990000,0.016380,-177.434509,0.000207,0.000390,0.009904,0.072863,0.003712,0.099037,-177.434509,0.011031,0.000000
1.210000,0.033508,-177.434509,0.000349,0.000535,0.013598,0.149052,0.007593,0.135980,-177.434509,0.014691,0.000000
1.430000,0.040955,-177.478989,0.000522,0.000676,0.017180,0.182175,0.009280,0.171796,-177.478989,0.018350,0.000000
1.650000,0.032768,-177.434509,0.000651,0.000816,0.020718,0.145760,0.007425,0.207179,-177.434509,0.022028,0.000000
1.870000,0.017128,-177.478989,0.000802,0.000959,0.024352,0.076189,0.003881,0.243516,-177.478989,0.025687,0.000000
2.090000,0.017128,-177.478989,0.000949,0.001112,0.028254,0.076189,0.003881,0.282542,-177.478989,0.029347,0.000000
2.310000,0.006699,-177.478989,0.001099,0.001250,0.031749,0.029797,0.001518,0.317490,-177.478989,0.033024,0.000000
2.530000,-0.018997,-177.434509,0.001237,0.001398,0.035521,-0.084504,-0.004305,0.355214,-177.434509,0.036684,0.000000
2.750000,0.024200,-177.523483,0.001393,0.001546,0.039259,0.107649,0.005484,0.392592,-177.523483,0.040343,0.000000
2.970000,0.045425,-177.523483,0.001539,0.001689,0.042893,0.202062,0.010294,0.428929,-177.523483,0.044020,0.000000
3.190000,0.045052,-177.523483,0.001677,0.001827,0.046397,0.200399,0.010209,0.463966,-177.523483,0.047680,0.000000
3.410000,0.039841,-177.478989,0.001841,0.001972,0.050100,0.177220,0.009028,0.500995,-177.478989,0.051340,0.000000
3.630000,0.037979,-177.478989,0.001996,0.002120,0.053837,0.168940,0.008606,0.538373,-177.478989,0.054999,0.000000
3.850000,0.001114,-177.478989,0.002164,0.002268,0.057601,0.004955,0.000252,0.576010,-177.478989,0.058676,0.000000
4.070000,0.002602,-177.567963,0.002289,0.002408,0.061157,0.011573,0.000590,0.611567,-177.567963,0.062336,0.000000
4.290000,-0.029419,-177.523483,0.002440,0.002551,0.064799,-0.130862,-0.006666,0.647991,-177.523483,0.065996,0.000000
4.510000,0.016754,-177.567963,0.002591,0.002695,0.068459,0.074526,0.003797,0.684587,-177.567963,0.069673,0.000000
4.730000,0.040215,-177.523483,0.002725,0.002839,0.072101,0.178883,0.009113,0.721011,-177.523483,0.073333,0.000000
4.950000,0.063675,-177.523483,0.002880,0.002985,0.075830,0.283240,0.014429,0.758302,-177.523483,0.076992,0.000000
5.170000,0.072983,-177.567963,0.003001,0.003131,0.079516,0.324644,0.016538,0.795159,-177.567963,0.080669,0.000000
5.390000,0.059952,-177.567963,0.003165,0.003279,0.083297,0.266679,0.013585,0.832970,-177.567963,0.084329,0.000000
5.610000,0.056229,-177.523483,0.003298,0.003419,0.086853,0.250117,0.012742,0.868526,-177.523483,0.087989,0.000000
5.830000,0.026436,-177.567963,0.003462,0.003564,0.090530,0.117593,0.005990,0.905296,-177.567963,0.091666,0.000000
6.050000,0.040955,-177.567963,0.003604,0.003709,0.094207,0.182175,0.009280,0.942066,-177.567963,0.095325,0.000000
6.270000,0.032021,-177.612442,0.003768,0.003853,0.097858,0.142435,0.007256,0.978577,-177.612442,0.098985,0.000000
6.490000,0.029785,-177.612442,0.003915,0.003990,0.101344,0.132491,0.006749,1.013440,-177.612442,0.102662,0.000000
6.710001,0.018990,-177.478989,0.004061,0.004139,0.105134,0.084470,0.004303,1.051338,-177.478989,0.106322,0.000000
6.930000,0.052132,-177.567963,0.004191,0.004290,0.108958,0.231893,0.011813,1.089582,-177.567963,0.109981,0.000000
7.150001,0.036491,-177.612442,0.004355,0.004427,0.112436,0.162322,0.008269,1.124358,-177.612442,0.113659,0.000000
7.370000,0.018242,-177.656921,0.004501,0.004574,0.116182,0.081144,0.004134,1.161821,-177.656921,0.117318,0.000000
7.590000,0.045052,-177.612442,0.004622,0.004720,0.119877,0.200399,0.010209,1.198765,-177.612442,0.120978,0.000000
7.810000,0.059204,-177.612442,0.004807,0.004861,0.123458,0.263353,0.013416,1.234582,-177.612442,0.124638,0.000000
8.030001,0.067398,-177.567963,0.004950,0.005005,0.127118,0.299802,0.015273,1.271180,-177.567963,0.128315,0.000000
8.250000,0.042450,-177.701401,0.005083,0.005148,0.130751,0.188827,0.009619,1.307515,-177.701401,0.131974,0.000000
8.470000,0.027184,-177.656921,0.005238,0.005298,0.134576,0.120918,0.006160,1.345761,-177.656921,0.135634,0.000000
8.690001,0.029045,-177.656921,0.005402,0.005439,0.138158,0.129199,0.006582,1.381577,-177.656921,0.139311,0.000000
8.910001,0.002975,-177.656921,0.005536,0.005584,0.141835,0.013236,0.000674,1.418348,-177.656921,0.142971,0.000000
9.130000,0.043564,-177.612442,0.005696,0.005727,0.145460,0.193782,0.009872,1.454598,-177.612442,0.146630,0.000000
9.350000,0.036491,-177.701401,0.005846,0.005872,0.149137,0.162322,0.008269,1.491368,-177.701401,0.150307,0.000000
9.570001,0.051384,-177.701401,0.005976,0.006015,0.152788,0.228567,0.011644,1.527877,-177.701401,0.153967,0.000000
9.790001,0.067398,-177.656921,0.006122,0.006157,0.156395,0.299802,0.015273,1.563955,-177.656921,0.157627,0.000000
10.010000,0.055855,-177.656921,0.006273,0.006303,0.160090,0.248455,0.012657,1.600899,-177.656921,0.161304,0.000000
10.230000,0.050636,-177.701401,0.006424,0.006454,0.163932,0.225241,0.011474,1.639316,-177.701401,0.164964,0.000000
10.450001,0.009682,-177.656921,0.006571,0.006596,0.167531,0.043066,0.002194,1.675306,-177.656921,0.168623,0.000000
10.670000,-0.007454,-177.745880,0.006713,0.006733,0.171017,-0.033157,-0.001689,1.710169,-177.745880,0.172300,0.000000
10.890000,0.007446,-177.745880,0.006868,0.006879,0.174737,0.033123,0.001687,1.747373,-177.745880,0.175960,0.000000
11.110001,0.058090,-177.701401,0.007032,0.007027,0.178484,0.258398,0.013163,1.784837,-177.701401,0.179620,0.000000
11.330001,0.062553,-177.656921,0.007166,0.007169,0.182083,0.278251,0.014175,1.820826,-177.656921,0.183297,0.000000
11.550000,0.075218,-177.745880,0.007278,0.007311,0.185708,0.334587,0.017045,1.857076,-177.745880,0.186956,0.000000
11.770000,0.069633,-177.745880,0.007455,0.007464,0.189593,0.309745,0.015779,1.895928,-177.745880,0.190616,0.000000
11.990001,0.070747,-177.745880,0.007601,0.007603,0.193105,0.314700,0.016032,1.931051,-177.745880,0.194276,0.000000
12.210001,0.051384,-177.790359,0.007756,0.007747,0.196773,0.228567,0.011644,1.967735,-177.790359,0.197953,0.000000
12.430000,0.049149,-177.701401,0.007903,0.007892,0.200450,0.218624,0.011137,2.004505,-177.701401,0.201613,0.000000
12.650001,0.053246,-177.701401,0.008050,0.008040,0.204205,0.236848,0.012066,2.042055,-177.701401,0.205272,0.000000
12.870001,0.058090,-177.790359,0.008183,0.008179,0.207735,0.258398,0.013163,2.077351,-177.790359,0.208949,0.000000
13.090000,0.066277,-177.790359,0.008330,0.008323,0.211412,0.294813,0.015018,2.114123,-177.790359,0.212609,0.000000
13.310000,0.060692,-177.745880,0.008502,0.008472,0.215185,0.269971,0.013753,2.151847,-177.745880,0.216269,0.000000
13.530001,0.063301,-177.745880,0.008623,0.008617,0.218870,0.281577,0.014344,2.188704,-177.745880,0.219946,0.000000
13.750001,0.039841,-177.745880,0.008778,0.008761,0.222539,0.177220,0.009028,2.225388,-177.745880,0.223605,0.000000
13.970000,0.056229,-177.790359,0.008929,0.008903,0.226138,0.250117,0.012742,2.261376,-177.790359,0.227265,0.000000
14.190001,0.061066,-177.790359,0.009067,0.009047,0.229806,0.271634,0.013838,2.298061,-177.790359,0.230942,0.000000
14.410001,0.062553,-177.790359,0.009218,0.009191,0.233440,0.278251,0.014175,2.334398,-177.790359,0.234602,0.000000
14.630001,0.071861,-177.745880,0.009360,0.009330,0.236978,0.319655,0.016284,2.369780,-177.745880,0.238262,0.000000
14.850000,0.057716,-177.790359,0.009490,0.009477,0.240707,0.256735,0.013079,2.407070,-177.790359,0.241939,0.000000
15.070001,0.052132,-177.834839,0.009653,0.009622,0.244393,0.231893,0.011813,2.443928,-177.834839,0.245598,0.000000
15.290001,0.020851,-177.879318,0.009800,0.009770,0.248148,0.092750,0.004725,2.481479,-177.879318,0.249258,0.000000
15.510001,0.064415,-177.790359,0.009947,0.009912,0.251764,0.286532,0.014597,2.517642,-177.790359,0.252918,0.000000
15.730000,0.056595,-177.790359,0.010098,0.010055,0.255407,0.251746,0.012825,2.554066,-177.790359,0.256595,0.000000
15.950001,0.073357,-177.923798,0.010244,0.010205,0.259196,0.326307,0.016623,2.591964,-177.923798,0.260254,0.000000
16.170000,0.071121,-177.879318,0.010374,0.010345,0.262752,0.316363,0.016116,2.627520,-177.879318,0.263914,0.000000
16.390001,0.077080,-177.879318,0.010511,0.010485,0.266325,0.342868,0.017467,2.663249,-177.879318,0.267591,0.000000
16.610001,0.064415,-177.879318,0.010658,0.010639,0.270236,0.286532,0.014597,2.702362,-177.879318,0.271251,0.000000
16.830000,0.067772,-177.879318,0.010796,0.010783,0.273878,0.301465,0.015357,2.738784,-177.879318,0.274911,0.000000
17.050001,0.035744,-177.834839,0.010951,0.010919,0.277330,0.158996,0.008100,2.773300,-177.834839,0.278588,0.000000
17.270000,0.029785,-177.879318,0.011111,0.011064,0.281024,0.132491,0.006749,2.810245,-177.879318,0.282247,0.000000
17.490002,0.074097,-177.923798,0.011266,0.011212,0.284797,0.329598,0.016791,2.847969,-177.923798,0.285907,0.000000
17.710001,0.081543,-177.879318,0.011395,0.011356,0.288431,0.362721,0.018478,2.884306,-177.879318,0.289584,0.000000
17.930000,0.105751,-177.879318,0.011542,0.011497,0.292029,0.470404,0.023964,2.920294,-177.879318,0.293244,0.000000
18.150002,0.110962,-177.834839,0.011680,0.011645,0.295793,0.493583,0.025144,2.957933,-177.834839,0.296903,0.000000
18.370001,0.083038,-177.968292,0.011826,0.011787,0.299401,0.369373,0.018817,2.994009,-177.968292,0.300580,0.000000
18.590000,0.049149,-177.968292,0.011999,0.011936,0.303182,0.218624,0.011137,3.031820,-177.968292,0.304240,0.000000
18.810001,0.061440,-177.968292,0.012133,0.012076,0.306738,0.273297,0.013922,3.067377,-177.968292,0.307900,0.000000
19.030001,0.067024,-177.879318,0.012266,0.012222,0.310432,0.298139,0.015188,3.104320,-177.879318,0.311577,0.000000
19.250000,0.084152,-177.879318,0.012413,0.012364,0.314040,0.374328,0.019069,3.140397,-177.879318,0.315237,0.000000
19.470001,0.086014,-177.968292,0.012559,0.012506,0.317656,0.382608,0.019491,3.176560,-177.968292,0.318896,0.000000
19.690001,0.106499,-177.923798,0.012710,0.012654,0.321420,0.473730,0.024133,3.214197,-177.923798,0.322556,0.000000
19.910002,0.090858,-177.923798,0.012861,0.012801,0.325140,0.404159,0.020589,3.251403,-177.923798,0.326233,0.000000
20.130001,0.090858,-177.968292,0.013021,0.012947,0.328861,0.404159,0.020589,3.288606,-177.968292,0.329893,0.000000
20.350000,0.061440,-177.923798,0.013146,0.013090,0.332477,0.273297,0.013922,3.324769,-177.923798,0.333552,0.000000
20.570002,0.088997,-178.012772,0.013301,0.013229,0.336015,0.395878,0.020167,3.360152,-178.012772,0.337229,0.000000
20.790001,0.089363,-178.012772,0.013456,0.013378,0.339796,0.397507,0.020250,3.397963,-178.012772,0.340889,0.000000
21.010000,0.080429,-178.057251,0.013590,0.013516,0.343300,0.357766,0.018225,3.432998,-178.057251,0.344549,0.000000
21.230001,0.098679,-177.923798,0.013736,0.013662,0.347020,0.438944,0.022361,3.470204,-177.923798,0.348226,0.000000
21.450001,0.059952,-177.968292,0.013879,0.013806,0.350671,0.266679,0.013585,3.506713,-177.968292,0.351885,0.000000
21.670000,0.063675,-177.968292,0.014021,0.013958,0.354531,0.283240,0.014429,3.545305,-177.968292,0.355545,0.000000
21.890001,0.086761,-178.057251,0.014176,0.014097,0.358051,0.385934,0.019660,3.580514,-178.057251,0.359222,0.000000
22.110001,0.065163,-178.057251,0.014323,0.014239,0.361668,0.289858,0.014766,3.616677,-178.057251,0.362882,0.000000
22.330002,0.086388,-177.968292,0.014474,0.014390,0.365510,0.384271,0.019576,3.655096,-177.968292,0.366542,0.000000
22.550001,0.091599,-177.968292,0.014616,0.014534,0.369152,0.407451,0.020757,3.691520,-177.968292,0.370219,0.000000
22.770000,0.109100,-178.012772,0.014763,0.014670,0.372612,0.485303,0.024722,3.726121,-178.012772,0.373878,0.000000
22.990002,0.086014,-178.012772,0.014901,0.014818,0.376385,0.382608,0.019491,3.763845,-178.012772,0.377538,0.000000
23.210001,0.083778,-178.057251,0.015064,0.014967,0.380157,0.372665,0.018984,3.801569,-178.057251,0.381215,0.000000
23.430000,0.069633,-178.012772,0.015211,0.015106,0.383695,0.309745,0.015779,3.836952,-178.012772,0.384875,0.000000
23.650002,0.046173,-178.012772,0.015340,0.015250,0.387338,0.205388,0.010463,3.873376,-178.012772,0.388534,0.000000
23.870001,0.067024,-178.057251,0.015513,0.015397,0.391075,0.298139,0.015188,3.910754,-178.057251,0.392194,0.000000
24.090002,0.110588,-178.101730,0.015651,0.015541,0.394752,0.491920,0.025060,3.947524,-178.101730,0.395871,0.000000
24.310001,0.106499,-178.057251,0.015793,0.015682,0.398334,0.473730,0.024133,3.983341,-178.057251,0.399531,0.000000
24.530001,0.115807,-178.057251,0.015944,0.015824,0.401924,0.515133,0.026242,4.019244,-178.057251,0.403190,0.000000
24.750002,0.099792,-178.101730,0.016078,0.015968,0.405575,0.443899,0.022613,4.055753,-178.101730,0.406868,0.000000
24.970001,0.099045,-178.057251,0.016241,0.016119,0.409426,0.440573,0.022444,4.094259,-178.057251,0.410527,0.000000
25.190001,0.060318,-178.101730,0.016375,0.016263,0.413077,0.268308,0.013668,4.130768,-178.101730,0.414187,0.000000
25.410002,0.061440,-178.146210,0.016539,0.016404,0.416658,0.273297,0.013922,4.166584,-178.146210,0.417864,0.000000
25.630001,0.062553,-178.190689,0.016668,0.016546,0.420275,0.278251,0.014175,4.202749,-178.190689,0.421524,0.000000
25.850000,0.068886,-178.101730,0.016815,0.016688,0.423874,0.306419,0.015610,4.238738,-178.101730,0.425183,0.000000
26.070002,0.116180,-178.146210,0.016970,0.016837,0.427664,0.516796,0.026327,4.276636,-178.146210,0.428860,0.000000
26.290001,0.102776,-178.146210,0.017095,0.016982,0.431349,0.457169,0.023289,4.313493,-178.146210,0.432520,0.000000
26.510002,0.116920,-178.146210,0.017255,0.017132,0.435148,0.520088,0.026495,4.351479,-178.146210,0.436180,0.000000
26.730001,0.100540,-178.146210,0.017406,0.017277,0.438833,0.447225,0.022783,4.388334,-178.146210,0.439857,0.000000
26.950001,0.109848,-178.101730,0.017526,0.017414,0.442311,0.488628,0.024892,4.423111,-178.101730,0.443516,0.000000
27.170002,0.096069,-178.190689,0.017690,0.017561,0.446057,0.427338,0.021770,4.460575,-178.190689,0.447176,0.000000
27.390001,0.102402,-178.190689,0.017841,0.017700,0.449587,0.455506,0.023205,4.495871,-178.190689,0.450853,0.000000
27.610001,0.101654,-178.190689,0.017992,0.017845,0.453273,0.452180,0.023035,4.532728,-178.190689,0.454513,0.000000
27.830002,0.093834,-178.146210,0.018126,0.017987,0.456881,0.417394,0.021263,4.568805,-178.146210,0.458173,0.000000
28.050001,0.088997,-178.190689,0.018277,0.018142,0.460809,0.395878,0.020167,4.608091,-178.190689,0.461832,0.000000
28.270000,0.121391,-178.190689,0.018423,0.018282,0.464365,0.539975,0.027508,4.643646,-178.190689,0.465509,0.000000
28.490002,0.091225,-178.190689,0.018570,0.018422,0.467929,0.405788,0.020672,4.679288,-178.190689,0.469169,0.000000
28.710001,0.096069,-178.235168,0.018699,0.018572,0.471727,0.427338,0.021770,4.717274,-178.235168,0.472829,0.000000
28.930002,0.105377,-178.190689,0.018846,0.018718,0.475439,0.468741,0.023879,4.754390,-178.190689,0.476506,0.000000
29.150002,0.122505,-178.190689,0.019001,0.018858,0.478995,0.544930,0.027760,4.789948,-178.190689,0.480165,0.000000
29.370001,0.117294,-178.190689,0.019135,0.019001,0.482620,0.521751,0.026579,4.826197,-178.190689,0.483825,0.000000
29.590002,0.115059,-178.279648,0.019290,0.019147,0.486323,0.511808,0.026073,4.863229,-178.279648,0.487502,0.000000
29.810001,0.094208,-178.279648,0.019432,0.019294,0.490069,0.419057,0.021348,4.900692,-178.279648,0.491162,0.000000
30.030001,0.080803,-178.235168,0.019587,0.019433,0.493599,0.359429,0.018310,4.935987,-178.235168,0.494822,0.000000
30.250002,0.070000,-178.235168,0.019704,0.019580,0.497337,0.311374,0.015862,4.973365,-178.235168,0.498499,0.000000
30.470001,0.109848,-178.146210,0.019859,0.019724,0.500996,0.488628,0.024892,5.009962,-178.146210,0.502158,0.000000
30.690001,0.112457,-178.279648,0.020010,0.019871,0.504717,0.500235,0.025483,5.047167,-178.279648,0.505818,0.000000
30.910002,0.120644,-178.279648,0.020152,0.020008,0.508203,0.536650,0.027338,5.082029,-178.279648,0.509495,0.000000
31.130001,0.121017,-178.235168,0.020294,0.020152,0.511854,0.538313,0.027423,5.118539,-178.235168,0.513155,0.000000
31.350002,0.134796,-178.324127,0.020424,0.020302,0.515670,0.599603,0.030545,5.156696,-178.324127,0.516814,0.000000
31.570002,0.098305,-178.235168,0.020587,0.020450,0.519425,0.437281,0.022276,5.194248,-178.235168,0.520474,0.000000
31.790001,0.086014,-178.279648,0.020743,0.020590,0.522980,0.382608,0.019491,5.229803,-178.279648,0.524151,0.000000
32.010002,0.070374,-178.324127,0.020868,0.020730,0.526536,0.313037,0.015947,5.265360,-178.324127,0.527811,0.000000
32.230003,0.098679,-178.279648,0.021027,0.020875,0.530213,0.438944,0.022361,5.302131,-178.279648,0.531471,0.000000
32.450001,0.125862,-178.279648,0.021178,0.021021,0.533933,0.559863,0.028521,5.339334,-178.279648,0.535148,0.000000
32.670002,0.142990,-178.235168,0.021308,0.021164,0.537567,0.636052,0.032402,5.375671,-178.235168,0.538807,0.000000
32.890003,0.136658,-178.324127,0.021450,0.021310,0.541279,0.607884,0.030967,5.412788,-178.324127,0.542467,0.000000
33.110001,0.124741,-178.324127,0.021614,0.021461,0.545121,0.554874,0.028267,5.451206,-178.324127,0.546144,0.000000
33.330002,0.119904,-178.279648,0.021765,0.021600,0.548633,0.533358,0.027171,5.486330,-178.279648,0.549804,0.000000
33.550003,0.105003,-178.324127,0.021898,0.021744,0.552293,0.467078,0.023794,5.522926,-178.324127,0.553463,0.000000
33.770000,0.117668,-178.324127,0.022036,0.021888,0.555944,0.523414,0.026664,5.559437,-178.324127,0.557140,0.000000
33.990002,0.120644,-178.368607,0.022191,0.022035,0.559681,0.536650,0.027338,5.596813,-178.368607,0.560800,0.000000
34.210003,0.118408,-178.324127,0.022321,0.022171,0.563142,0.526706,0.026832,5.631416,-178.324127,0.564460,0.000000
34.430000,0.102776,-178.368607,0.022485,0.022321,0.566957,0.457169,0.023289,5.669574,-178.368607,0.568137,0.000000
34.650002,0.140381,-178.413101,0.022631,0.022468,0.570678,0.624445,0.031811,5.706778,-178.413101,0.571797,0.000000
34.870003,0.146339,-178.324127,0.022773,0.022607,0.574225,0.650950,0.033161,5.742248,-178.324127,0.575456,0.000000
35.090000,0.111710,-178.413101,0.022916,0.022756,0.577997,0.496909,0.025314,5.779972,-178.413101,0.579133,0.000000
35.310001,0.158257,-178.413101,0.023062,0.022900,0.581665,0.703960,0.035861,5.816655,-178.413101,0.582793,0.000000
35.530003,0.197357,-178.324127,0.023205,0.023044,0.585317,0.877889,0.044722,5.853166,-178.324127,0.586453,0.000000
35.750000,0.215973,-178.368607,0.023343,0.023183,0.588855,0.960695,0.048940,5.888549,-178.368607,0.590112,0.000000
35.970001,0.307953,-178.368607,0.023489,0.023328,0.592532,1.369843,0.069783,5.925319,-178.368607,0.593789,0.000000
36.190002,0.455040,-178.413101,0.023644,0.023477,0.596304,2.024119,0.103114,5.963043,-178.413101,0.597449,0.000000
36.410000,0.630798,-178.457581,0.023774,-0.000000,-0.000000,2.805931,0.142941,-0.000000,-178.457581,0.000217,0.000000
36.630001,0.580154,-178.368607,0.023778,-0.000000,-0.000000,2.580656,0.131465,-0.000000,-178.368607,0.000217,0.000000
36.850002,0.579781,-178.368607,0.023791,-0.000000,-0.000000,2.578993,0.131380,-0.000000,-178.368607,0.000217,0.000000
37.070004,0.558182,-178.368607,0.023782,-0.000000,-0.000000,2.482917,0.126486,-0.000000,-178.368607,0.000512,0.000000
37.290001,0.567863,-178.457581,0.023778,0.000000,0.000009,2.525983,0.128680,0.000087,-178.457581,0.000876,0.000000
37.510002,0.581268,-178.502060,0.023787,0.000009,0.000234,2.585611,0.131717,0.002343,-178.502060,0.001240,0.000000
37.730003,0.724258,-178.457581,0.023787,0.000024,0.000616,3.221662,0.164119,0.006158,-178.457581,0.001613,0.000000
37.950001,0.768204,-178.413101,0.023787,0.000038,0.000963,3.417141,0.174077,0.009627,-178.413101,0.001977,0.000000
38.170002,0.790543,-178.413101,0.023804,0.000051,0.001292,3.516509,0.179140,0.012922,-178.413101,0.002342,0.000000
38.390003,0.818474,-178.502060,0.023813,0.000069,0.001752,3.640753,0.185469,0.017518,-178.502060,0.002706,0.000000
38.610001,0.840073,-178.502060,0.023843,0.000081,0.002064,3.736830,0.190363,0.020641,-178.502060,0.003079,0.000000
38.830002,0.912308,-178.457581,0.023856,0.000094,0.002385,4.058147,0.206732,0.023849,-178.457581,0.003443,0.000000
39.050003,0.992371,-178.413101,0.023856,0.000107,0.002723,4.414285,0.224874,0.027232,-178.413101,0.003807,0.000000
39.270000,1.060516,-178.502060,0.023860,0.000122,0.003105,4.717412,0.240316,0.031047,-178.502060,0.004180,0.000000
39.490002,1.136108,-178.635498,0.023890,0.000137,0.003478,5.053663,0.257446,0.034776,-178.635498,0.004544,0.000000
39.710003,1.237389,-178.502060,0.023925,0.000162,0.004111,5.504179,0.280396,0.041108,-178.502060,0.004909,0.000000
39.930000,1.306656,-178.546539,0.023942,0.000176,0.004466,5.812295,0.296092,0.044664,-178.546539,0.005273,0.000000
40.150002,1.367348,-178.457581,0.023938,0.000187,0.004744,6.082266,0.309845,0.047438,-178.457581,0.005646,0.000000
40.370003,1.432884,-178.546539,0.023950,0.000198,0.005039,6.373787,0.324696,0.050386,-178.546539,0.006010,0.000000
40.590000,1.507362,-178.546539,0.023963,0.000213,0.005420,6.705083,0.341573,0.054202,-178.546539,0.006374,0.000000
40.810001,1.662643,-178.546539,0.023985,0.000227,0.005767,7.395807,0.376760,0.057670,-178.546539,0.006738,0.000000
41.030003,1.746796,-178.546539,0.024007,0.000241,0.006123,7.770135,0.395830,0.061226,-178.546539,0.007111,0.000000
41.250004,1.862228,-178.546539,0.023998,0.000255,0.006478,8.283606,0.421987,0.064782,-178.546539,0.007476,0.000000
41.470001,2.005966,-178.546539,0.024024,0.000271,0.006886,8.922983,0.454558,0.068859,-178.546539,0.007840,0.000000
41.690002,2.173164,-178.591019,0.024024,0.000287,0.007285,9.666718,0.492446,0.072848,-178.591019,0.008213,0.000000
41.910004,2.277428,-178.591019,0.024041,0.000299,0.007606,10.130505,0.516073,0.076056,-178.591019,0.008577,0.000000
42.130001,2.422279,-178.457581,0.024058,0.000314,0.007987,10.774837,0.548896,0.079873,-178.457581,0.008941,0.000000
42.350002,2.532127,-178.502060,0.024063,0.000326,0.008273,11.263465,0.573788,0.082734,-178.502060,0.009305,0.000000
42.570004,2.736191,-178.591019,0.024088,0.000341,0.008664,12.171185,0.620030,0.086636,-178.591019,0.009678,0.000000
42.790001,2.999458,-178.635498,0.024101,0.000358,0.009097,13.342257,0.679687,0.090972,-178.635498,0.010042,0.000000
43.010002,3.158836,-178.591019,0.024101,0.000371,0.009436,14.051206,0.715803,0.094356,-178.591019,0.010407,0.000000
43.230003,3.316345,-178.546539,0.024110,0.000384,0.009748,14.751841,0.751495,0.097476,-178.546539,0.010780,0.000000
43.450001,3.571053,-178.635498,0.024127,0.000398,0.010103,15.884835,0.809212,0.101032,-178.635498,0.011144,0.000000
43.670002,3.905067,-178.591019,0.024149,0.000417,0.010580,17.370607,0.884901,0.105803,-178.591019,0.011508,0.000000
43.890003,4.019012,-178.591019,0.024153,0.000430,0.010910,17.877460,0.910721,0.109098,-178.591019,0.011872,0.000000
44.110001,4.233124,-178.635498,0.024170,0.000442,0.011231,18.829876,0.959240,0.112307,-178.635498,0.012245,0.000000
44.330002,4.582413,-178.635498,0.024179,0.000457,0.011612,20.383591,1.038390,0.116122,-178.635498,0.012610,0.000000
44.550003,4.897812,-178.591019,0.024188,0.000472,0.011994,21.786556,1.109860,0.119938,-178.591019,0.012974,0.000000
44.770000,5.280235,-178.591019,0.024209,0.000491,0.012462,23.487659,1.196518,0.124621,-178.591019,0.013347,0.000000
44.990002,5.439613,-178.679977,0.024218,0.000499,0.012679,24.196609,1.232634,0.126788,-178.679977,0.013711,0.000000
45.210003,5.883484,-178.679977,0.024235,0.000513,0.013034,26.171043,1.333217,0.130344,-178.679977,0.014075,0.000000
45.430000,6.261810,-178.635498,0.024248,0.000529,0.013442,27.853924,1.418947,0.134421,-178.635498,0.014439,0.000000
45.650002,6.900063,-178.679977,0.024248,0.000550,0.013980,30.693010,1.563577,0.139797,-178.679977,0.014812,0.000000
45.870003,7.183434,-178.724457,0.024265,0.000565,0.014344,31.953508,1.627789,0.143440,-178.724457,0.015176,0.000000
46.090004,7.498459,-178.679977,0.024291,0.000577,0.014665,33.354813,1.699175,0.146648,-178.679977,0.015541,0.000000
46.310001,7.979568,-178.679977,0.024291,0.000592,0.015046,35.494892,1.808196,0.150465,-178.679977,0.015914,0.000000
46.530003,8.462906,-178.679977,0.024287,0.000607,0.015411,37.644886,1.917722,0.154106,-178.679977,0.016278,0.000000
46.750004,8.803253,-178.679977,0.024304,0.000618,0.015706,39.158825,1.994846,0.157056,-178.679977,0.016642,0.000000
46.970001,9.156265,-178.724457,0.024317,0.000629,0.015966,40.729103,2.074839,0.159656,-178.724457,0.017006,0.000000
47.190002,9.968033,-178.768936,0.024339,0.000648,0.016451,44.340023,2.258789,0.164514,-178.768936,0.017379,0.000000
47.410004,10.344505,-178.724457,0.024343,0.000663,0.016833,46.014656,2.344098,0.168329,-178.724457,0.017744,0.000000
47.630001,11.117546,-178.724457,0.024343,0.000680,0.017284,49.453316,2.519272,0.172839,-178.724457,0.018108,0.000000
47.850002,11.537216,-178.679977,0.024373,0.000694,0.017622,51.320099,2.614371,0.176221,-178.679977,0.018481,0.000000
48.070004,11.955017,-178.768936,0.024369,0.000706,0.017934,53.178574,2.709045,0.179343,-178.768936,0.018845,0.000000
48.290001,12.600708,-178.724457,0.024373,0.000720,0.018298,56.050747,2.855361,0.182985,-178.724457,0.019209,0.000000
48.510002,13.216614,-178.724457,0.024399,0.000739,0.018758,58.790436,2.994927,0.187581,-178.724457,0.019573,0.000000
48.730003,13.914436,-178.679977,0.024403,0.000752,0.019096,61.894505,3.153056,0.190963,-178.679977,0.019946,0.000000
48.950001,14.046631,-178.768936,0.024412,0.000760,0.019296,62.482536,3.183012,0.192958,-178.768936,0.020311,0.000000
49.170002,14.600723,-178.724457,0.024416,0.000771,0.019582,64.947258,3.308571,0.195821,-178.724457,0.020675,0.000000
49.390003,15.319397,-178.857910,0.024420,0.000786,0.019972,68.144081,3.471425,0.199723,-178.857910,0.021048,0.000000
49.610001,16.165802,-178.724457,0.024442,0.000804,0.020432,71.909081,3.663223,0.204318,-178.724457,0.021412,0.000000
49.830002,16.887459,-178.768936,0.024455,0.000820,0.020822,75.119171,3.826753,0.208222,-178.768936,0.021776,0.000000
50.050003,17.252014,-178.857910,0.024451,0.000832,0.021126,76.740791,3.909362,0.211258,-178.857910,0.022140,0.000000
50.270004,18.016495,-178.857910,0.024455,0.000848,0.021533,80.141373,4.082596,0.215332,-178.857910,0.022513,0.000000
50.490002,18.865128,-178.768936,0.024481,0.000865,0.021967,83.916275,4.274899,0.219670,-178.768936,0.022877,0.000000
50.710003,19.474335,-178.768936,0.024485,0.000879,0.022331,86.626167,4.412947,0.223311,-178.768936,0.023242,0.000000
50.930004,19.580460,-178.724457,0.024489,0.000886,0.022505,87.098236,4.436996,0.225046,-178.724457,0.023615,0.000000
51.150002,20.474525,-178.813431,0.024494,0.000902,0.022904,91.075241,4.639594,0.229035,-178.813431,0.023979,0.000000
51.370003,21.475464,-178.857910,0.024511,0.000921,0.023398,95.527634,4.866409,0.233978,-178.857910,0.024343,0.000000
51.590004,22.314415,-178.857910,0.024528,0.000937,0.023788,99.259476,5.056519,0.237881,-178.857910,0.024707,0.000000
51.810001,22.760895,-178.813431,0.024524,0.000950,0.024126,101.245514,5.157692,0.241262,-178.813431,0.025080,0.000000
52.030003,23.367485,-178.857910,0.024537,0.000961,0.024421,103.943764,5.295148,0.244211,-178.857910,0.025445,0.000000
52.250004,24.002380,-178.813431,0.024537,0.000976,0.024785,106.767921,5.439017,0.247854,-178.813431,0.025809,0.000000
52.470001,25.099762,-178.857910,0.024545,0.000993,0.025228,111.649315,5.687687,0.252277,-178.857910,0.026182,0.000000
52.690002,25.518684,-178.857910,0.024554,0.001003,0.025479,113.512779,5.782617,0.254792,-178.857910,0.026546,0.000000
52.910004,26.190445,-178.857910,0.024563,0.001017,0.025835,116.500916,5.934840,0.258347,-178.857910,0.026910,0.000000
53.130001,27.374588,-178.857910,0.024571,0.001036,0.026312,121.768250,6.203170,0.263116,-178.857910,0.027274,0.000000
53.350002,28.535645,-178.857910,0.024567,0.001055,0.026806,126.932884,6.466269,0.268060,-178.857910,0.027647,0.000000
53.570004,28.928497,-178.857910,0.024584,0.001066,0.027066,128.680389,6.555291,0.270662,-178.857910,0.028011,0.000000
53.790001,29.620735,-178.902390,0.024602,0.001080,0.027439,131.759613,6.712155,0.274392,-178.902390,0.028376,0.000000
54.010002,30.195679,-178.857910,0.024602,0.001093,0.027769,134.317093,6.842439,0.277686,-178.857910,0.028740,0.000000
54.230003,30.815308,-178.946869,0.024602,0.001105,0.028072,137.073334,6.982849,0.280722,-178.946869,0.029113,0.000000
54.450001,31.800232,-178.902390,0.024614,0.001120,0.028436,141.454498,7.206035,0.284365,-178.902390,0.029477,0.000000
54.670002,32.137978,-178.946869,0.024619,0.001127,0.028619,142.956863,7.282570,0.286185,-178.946869,0.029841,0.000000
54.890003,32.997040,-178.902390,0.024636,0.001145,0.029087,146.778168,7.477236,0.290867,-178.902390,0.030214,0.000000
55.110004,34.021805,-178.946869,0.024640,0.001161,0.029494,151.336548,7.709451,0.294944,-178.946869,0.030578,0.000000
55.330002,35.606255,-178.902390,0.024640,0.001183,0.030049,158.384537,8.068493,0.300494,-178.902390,0.030943,0.000000
55.550003,36.012138,-178.902390,0.024658,0.001193,0.030301,160.189987,8.160467,0.303009,-178.902390,0.031307,0.000000
55.770004,36.882370,-178.946869,0.024649,0.001209,0.030700,164.060974,8.357665,0.306999,-178.946869,0.031680,0.000000
55.990002,37.639404,-178.946869,0.024675,0.001223,0.031055,167.428436,8.529211,0.310554,-178.946869,0.032044,0.000000
56.210003,38.102638,-178.857910,0.024679,0.001235,0.031368,169.488998,8.634181,0.313677,-178.857910,0.032408,0.000000
56.430004,39.629364,-178.946869,0.024688,0.001255,0.031879,176.280212,8.980143,0.318792,-178.946869,0.032781,0.000000
56.650002,40.056107,-179.035828,0.024683,0.001264,0.032096,178.178467,9.076843,0.320961,-179.035828,0.033145,0.000000
56.870003,40.649292,-178.991348,0.024696,0.001276,0.032408,180.817078,9.211262,0.324084,-178.991348,0.033510,0.000000
57.090004,41.893387,-178.991348,0.024701,0.001296,0.032911,186.351089,9.493177,0.329114,-178.991348,0.033874,0.000000
57.310001,42.711494,-178.991348,0.024705,0.001309,0.033241,189.990219,9.678563,0.332408,-178.991348,0.034247,0.000000
57.530003,43.490494,-178.991348,0.024709,0.001320,0.033518,193.455383,9.855087,0.335183,-178.991348,0.034611,0.000000
57.750004,44.346207,-178.991348,0.024718,0.001336,0.033935,197.261780,10.048994,0.339346,-178.991348,0.034975,0.000000
57.970001,44.934181,-179.035828,0.024731,0.001349,0.034256,199.877228,10.182231,0.342556,-179.035828,0.035348,0.000000
58.190002,45.859901,-178.946869,0.024731,0.001361,0.034559,203.995026,10.392002,0.345589,-178.946869,0.035712,0.000000
58.410004,47.128571,-178.991348,0.024744,0.001379,0.035019,209.638351,10.679487,0.350186,-178.991348,0.036077,0.000000
58.630001,48.027107,-178.991348,0.024735,0.001391,0.035331,213.635239,10.883099,0.353309,-178.991348,0.036441,0.000000
58.850002,48.703339,-179.080307,0.024757,0.001404,0.035669,216.643265,11.036335,0.356690,-179.080307,0.036814,0.000000
59.070004,49.770554,-179.035828,0.024752,0.001418,0.036007,221.390472,11.278168,0.360072,-179.035828,0.037178,0.000000
59.290001,50.878365,-179.035828,0.024770,0.001433,0.036397,226.318268,11.529202,0.363974,-179.035828,0.037542,0.000000
59.510002,51.854355,-178.946869,0.024757,0.001448,0.036788,230.659683,11.750364,0.367879,-178.946869,0.037915,0.000000
59.730003,52.972214,-179.035828,0.024774,0.001463,0.037169,235.632172,12.003675,0.371694,-179.035828,0.038279,0.000000
59.950005,53.774307,-179.080307,0.024774,0.001476,0.037499,239.200058,12.185431,0.374988,-179.080307,0.038644,0.000000
60.170002,54.402496,-179.080307,0.024791,0.001488,0.037802,241.994385,12.327782,0.378024,-179.080307,0.039008,0.000000
60.390003,55.459663,-179.035828,0.024800,0.001502,0.038141,246.696899,12.567339,0.381406,-179.035828,0.039381,0.000000
60.610004,56.654236,-179.080307,0.024813,0.001517,0.038531,252.010620,12.838034,0.385310,-179.080307,0.039745,0.000000
60.830002,58.050629,-179.080307,0.024800,0.001535,0.038990,258.222107,13.154461,0.389905,-179.080307,0.040109,0.000000
61.050003,59.085449,-179.124786,0.024800,0.001550,0.039363,262.825195,13.388954,0.393635,-179.124786,0.040482,0.000000
61.270004,60.875450,-179.080307,0.024813,0.001571,0.039910,270.787537,13.794574,0.399098,-179.080307,0.040846,0.000000
61.490002,61.560616,-179.080307,0.024830,0.001582,0.040179,273.835297,13.949835,0.401786,-179.080307,0.041211,0.000000
61.710003,62.502342,-179.080307,0.024834,0.001597,0.040569,278.024292,14.163233,0.405690,-179.080307,0.041575,0.000000
61.930004,63.334961,-179.213745,0.024834,0.001607,0.040829,281.727966,14.351907,0.408290,-179.213745,0.041948,0.000000
62.150002,64.362350,-179.169266,0.024843,0.001622,0.041193,286.298035,14.584718,0.411933,-179.169266,0.042312,0.000000
62.370003,65.498459,-179.080307,0.024834,0.001635,0.041531,291.351685,14.842163,0.415315,-179.080307,0.042676,0.000000
62.590004,66.532898,-179.124786,0.024852,0.001649,0.041887,295.953125,15.076571,0.418871,-179.124786,0.043049,0.000000
62.810001,67.172272,-179.169266,0.024865,0.001651,0.041930,298.797180,15.221455,0.419304,-179.169266,0.042164,0.000000
63.030003,66.771591,-179.169266,0.024860,0.001651,0.041930,297.014862,15.130659,0.419304,-179.169266,0.042164,0.000000
63.250004,66.545929,-179.124786,0.024865,0.001647,0.041835,296.011078,15.079523,0.418350,-179.124786,0.041930,0.000000
63.470001,66.269257,-179.169266,0.024882,0.001645,0.041792,294.780365,15.016829,0.417917,-179.169266,0.041930,0.000000
63.690002,66.049942,-179.169266,0.024873,0.001645,0.041774,293.804810,14.967131,0.417743,-179.169266,0.041930,0.000000
63.910004,65.850342,-179.124786,0.024873,0.001644,0.041766,292.916962,14.921901,0.417656,-179.124786,0.041930,0.000000
64.130005,65.675323,-179.258240,0.024869,0.001644,0.041757,292.138428,14.882241,0.417570,-179.258240,0.041930,0.000000
64.350006,65.514832,-179.213745,0.024869,0.001644,0.041757,291.424530,14.845873,0.417570,-179.213745,0.041930,0.000000
64.570000,65.374451,-179.213745,0.024882,0.001644,0.041757,290.800079,14.814062,0.417570,-179.213745,0.041930,0.000000
64.790001,65.245239,-179.124786,0.024873,0.001644,0.041748,290.225311,14.784782,0.417483,-179.124786,0.041930,0.000000
65.010002,65.142456,-179.213745,0.024877,0.001644,0.041748,289.768127,14.761492,0.417483,-179.213745,0.041930,0.000000
65.230003,65.034851,-179.213745,0.024882,0.001644,0.041748,289.289459,14.737107,0.417483,-179.213745,0.041930,0.000000
65.450005,64.941757,-179.213745,0.024882,0.001644,0.041748,288.875366,14.716012,0.417483,-179.213745,0.041930,0.000000
65.670006,64.858337,-179.169266,0.024873,0.001643,0.041740,288.504303,14.697109,0.417396,-179.169266,0.041930,0.000000
65.889999,64.776428,-179.169266,0.024882,0.001643,0.041740,288.139954,14.678548,0.417396,-179.169266,0.041930,0.000000
66.110001,64.709015,-179.258240,0.024877,0.001643,0.041740,287.840088,14.663272,0.417396,-179.258240,0.041930,0.000000
66.330002,64.626724,-179.258240,0.024877,0.001643,0.041740,287.474030,14.644625,0.417396,-179.258240,0.041930,0.000000
66.550003,64.568268,-179.258240,0.024886,0.001643,0.041740,287.213989,14.631379,0.417396,-179.258240,0.041930,0.000000
66.770004,64.501236,-179.213745,0.024890,0.001643,0.041740,286.915833,14.616189,0.417396,-179.213745,0.041930,0.000000
66.990005,64.436066,-179.302719,0.024882,0.001643,0.041740,286.625946,14.601421,0.417396,-179.302719,0.041930,0.000000
67.210007,64.375000,-179.213745,0.024890,0.001643,0.041740,286.354309,14.587584,0.417396,-179.213745,0.041930,0.000000
67.430000,64.325485,-179.302719,0.024877,0.001643,0.041740,286.134064,14.576364,0.417396,-179.302719,0.041930,0.000000
67.650002,64.273712,-179.258240,0.024882,0.001643,0.041740,285.903748,14.564631,0.417396,-179.258240,0.041930,0.000000
67.870003,64.231644,-179.302719,0.024890,0.001643,0.041740,285.716614,14.555099,0.417396,-179.302719,0.041930,0.000000
68.090004,64.184723,-179.302719,0.024890,0.001643,0.041740,285.507904,14.544467,0.417396,-179.302719,0.041930,0.000000
68.310005,64.129990,-179.213745,0.024882,0.001643,0.041740,285.264435,14.532063,0.417396,-179.213745,0.041930,0.000000
68.530006,64.085297,-179.302719,0.024882,0.001643,0.041740,285.065643,14.521935,0.417396,-179.302719,0.041930,0.000000
68.750000,64.052902,-179.347198,0.024886,0.001643,0.041731,284.921539,14.514595,0.417309,-179.347198,0.041930,0.000000
68.970001,64.002625,-179.302719,0.024886,0.001643,0.041731,284.697906,14.503201,0.417309,-179.302719,0.041930,0.000000
69.190002,63.960556,-179.302719,0.024886,0.001643,0.041731,284.510773,14.493670,0.417309,-179.302719,0.041930,0.000000
69.410004,63.935974,-179.258240,0.024882,0.001643,0.041731,284.401428,14.488099,0.417309,-179.258240,0.041930,0.000000
69.630005,63.889801,-179.347198,0.024886,0.001643,0.041731,284.196014,14.477636,0.417309,-179.347198,0.041930,0.000000
69.850006,63.867828,-179.347198,0.024890,0.001643,0.041731,284.098297,14.472656,0.417309,-179.347198,0.041930,0.000000
70.070000,63.836182,-179.302719,0.024890,0.001643,0.041731,283.957520,14.465486,0.417309,-179.302719,0.041930,0.000000
70.290001,63.800430,-179.302719,0.024886,0.001643,0.041731,283.798492,14.457384,0.417309,-179.302719,0.041930,0.000000
70.510002,63.769531,-179.302719,0.024899,0.001643,0.041731,283.661041,14.450382,0.417309,-179.302719,0.041930,0.000000
70.730003,63.741226,-179.436157,0.024873,0.001643,0.041731,283.535126,14.443969,0.417309,-179.436157,0.041930,0.000000
70.950005,63.711060,-179.347198,0.024882,0.001643,0.041731,283.400940,14.437133,0.417309,-179.347198,0.041930,0.000000
71.170006,63.679779,-179.347198,0.024890,0.001643,0.041731,283.261810,14.430044,0.417309,-179.347198,0.041930,0.000000
71.390007,63.649246,-179.391678,0.024882,0.001643,0.041731,283.125977,14.423125,0.417309,-179.391678,0.041930,0.000000
71.610001,63.625046,-179.436157,0.024886,0.001643,0.041731,283.018341,14.417641,0.417309,-179.436157,0.041930,0.000000
71.830002,63.615356,-179.436157,0.024895,0.001643,0.041731,282.975250,14.415446,0.417309,-179.436157,0.041930,0.000000
72.050003,63.585953,-179.436157,0.024890,0.001643,0.041731,282.844452,14.408783,0.417309,-179.436157,0.041930,0.000000
72.270004,63.552811,-179.391678,0.024869,0.001643,0.041731,282.697021,14.401273,0.417309,-179.391678,0.041930,0.000000
72.490005,63.531204,-179.347198,0.024882,0.001643,0.041731,282.600922,14.396377,0.417309,-179.347198,0.041930,0.000000
72.710007,63.502533,-179.436157,0.024895,0.001643,0.041731,282.473389,14.389879,0.417309,-179.436157,0.041930,0.000000
72.930000,63.486526,-179.480637,0.024886,0.001643,0.041731,282.402161,14.386252,0.417309,-179.480637,0.041930,0.000000
73.150002,63.454498,-179.436157,0.024903,0.001643,0.041731,282.259705,14.378995,0.417309,-179.436157,0.041930,0.000000
73.370003,63.430664,-179.391678,0.024890,0.001643,0.041731,282.153687,14.373593,0.417309,-179.391678,0.041930,0.000000
73.590004,63.409821,-179.436157,0.024886,0.001643,0.041731,282.060974,14.368871,0.417309,-179.436157,0.041930,0.000000
73.810005,63.400131,-179.436157,0.024877,0.001643,0.041731,282.017883,14.366675,0.417309,-179.436157,0.041930,0.000000
74.030006,63.379272,-179.480637,0.024895,0.001643,0.041731,281.925079,14.361949,0.417309,-179.480637,0.041930,0.000000
74.250000,63.359909,-179.480637,0.024873,0.001643,0.041731,281.838959,14.357560,0.417309,-179.480637,0.041930,0.000000
74.470001,63.336090,-179.391678,0.024890,0.001643,0.041731,281.733002,14.352163,0.417309,-179.391678,0.041930,0.000000
74.690002,63.304428,-179.436157,0.024886,0.001643,0.041731,281.592163,14.344989,0.417309,-179.436157,0.041930,0.000000
74.910004,63.291031,-179.525116,0.024886,0.001643,0.041731,281.532562,14.341952,0.417309,-179.525116,0.041930,0.000000
75.130005,63.260498,-179.525116,0.024890,0.001643,0.041731,281.396759,14.335033,0.417309,-179.525116,0.041930,0.000000
75.350006,63.254913,-179.436157,0.024890,0.001643,0.041731,281.371918,14.333768,0.417309,-179.436157,0.041930,0.000000
75.570007,63.241135,-179.436157,0.024899,0.001643,0.041731,281.310608,14.330647,0.417309,-179.436157,0.041930,0.000000
75.790001,63.220276,-179.525116,0.024877,0.001643,0.041731,281.217834,14.325919,0.417309,-179.525116,0.041930,0.000000
76.010002,63.198685,-179.525116,0.024886,0.001643,0.041731,281.121796,14.321027,0.417309,-179.525116,0.041930,0.000000
76.230003,63.181183,-179.525116,0.024886,0.001643,0.041731,281.043945,14.317060,0.417309,-179.525116,0.041930,0.000000
76.450005,63.159210,-179.480637,0.024890,0.001643,0.041731,280.946198,14.312082,0.417309,-179.480637,0.041930,0.000000
76.670006,63.145798,-179.480637,0.024899,0.001643,0.041731,280.886536,14.309043,0.417309,-179.480637,0.041930,0.000000
76.890007,63.126442,-179.569595,0.024882,0.001643,0.041731,280.800446,14.304657,0.417309,-179.569595,0.041930,0.000000
77.110001,63.102608,-179.525116,0.024882,0.001643,0.041731,280.694427,14.299255,0.417309,-179.525116,0.041930,0.000000
77.330002,63.093300,-179.569595,0.024886,0.001643,0.041731,280.653015,14.297146,0.417309,-179.569595,0.041930,0.000000
77.550003,63.080261,-179.525116,0.024895,0.001643,0.041731,280.595001,14.294191,0.417309,-179.525116,0.041930,0.000000
77.770004,63.070213,-179.569595,0.024890,0.001643,0.041731,280.550323,14.291914,0.417309,-179.569595,0.041930,0.000000
77.990005,63.060532,-179.525116,0.024882,0.001643,0.041731,280.507263,14.289721,0.417309,-179.525116,0.041930,0.000000
78.210007,63.037445,-179.569595,0.024877,0.001643,0.041731,280.404572,14.284489,0.417309,-179.569595,0.041930,0.000000
78.430000,63.024780,-179.525116,0.024890,0.001643,0.041731,280.348236,14.281619,0.417309,-179.525116,0.041930,0.000000
78.650002,62.998344,-179.569595,0.024899,0.001643,0.041731,280.230621,14.275629,0.417309,-179.569595,0.041930,0.000000
78.870003,62.997597,-179.569595,0.024890,0.001643,0.041731,280.227295,14.275459,0.417309,-179.569595,0.041930,0.000000
79.090004,62.973022,-179.569595,0.024877,0.001643,0.041731,280.117981,14.269891,0.417309,-179.569595,0.041930,0.000000
79.310005,62.967438,-179.569595,0.024895,0.001643,0.041731,280.093140,14.268625,0.417309,-179.569595,0.041930,0.000000
79.530006,62.958130,-179.569595,0.024877,0.001643,0.041731,280.051758,14.266517,0.417309,-179.569595,0.041930,0.000000
79.750000,62.949562,-179.569595,0.024886,0.001643,0.041731,280.013641,14.264575,0.417309,-179.569595,0.041930,0.000000
79.970001,62.933548,-179.614075,0.024886,0.001643,0.041731,279.942413,14.260946,0.417309,-179.614075,0.041930,0.000000
80.190002,62.913071,-179.614075,0.024873,0.001643,0.041731,279.851318,14.256306,0.417309,-179.614075,0.041930,0.000000
80.410004,62.905251,-179.658554,0.024895,0.001643,0.041731,279.816528,14.254534,0.417309,-179.658554,0.041930,0.000000
80.630005,62.884399,-179.658554,0.024895,0.001643,0.041731,279.723785,14.249808,0.417309,-179.658554,0.041930,0.000000
80.850006,62.881042,-179.614075,0.024890,0.001643,0.041731,279.708832,14.249048,0.417309,-179.614075,0.041930,0.000000
81.070007,62.858704,-179.614075,0.024886,0.001643,0.041731,279.609467,14.243985,0.417309,-179.614075,0.041930,0.000000
81.290001,62.853119,-179.658554,0.024886,0.001643,0.041731,279.584625,14.242720,0.417309,-179.658554,0.041930,0.000000
81.510002,62.844925,-179.658554,0.024882,0.001643,0.041731,279.548187,14.240864,0.417309,-179.658554,0.041930,0.000000
81.730003,62.844551,-179.703049,0.024890,0.001643,0.041731,279.546539,14.240779,0.417309,-179.703049,0.041930,0.000000
81.950005,62.825935,-179.658554,0.024890,0.001643,0.041731,279.463715,14.236561,0.417309,-179.658554,0.041930,0.000000
82.170006,62.819229,-179.658554,0.024877,0.001643,0.041731,279.433899,14.235041,0.417309,-179.658554,0.041930,0.000000
82.390007,62.796516,-179.658554,0.024886,0.001643,0.041731,279.332855,14.229894,0.417309,-179.658554,0.041930,0.000000
82.610001,62.778267,-179.658554,0.024890,0.001643,0.041731,279.251678,14.225759,0.417309,-179.658554,0.041930,0.000000
82.830002,62.771942,-179.703049,0.024895,0.001643,0.041731,279.223541,14.224325,0.417309,-179.703049,0.041930,0.000000
83.050003,62.773804,-179.703049,0.024895,0.001643,0.041731,279.231812,14.224748,0.417309,-179.703049,0.041930,0.000000
83.270004,62.753693,-179.658554,0.024895,0.001643,0.041731,279.142365,14.220190,0.417309,-179.658554,0.041930,0.000000
83.490005,62.749222,-179.747528,0.024895,0.001643,0.041731,279.122467,14.219177,0.417309,-179.747528,0.041930,0.000000
83.710007,62.739540,-179.747528,0.024890,0.001643,0.041731,279.079407,14.216983,0.417309,-179.747528,0.041930,0.000000
83.930000,62.738052,-179.703049,0.024886,0.001643,0.041731,279.072784,14.216646,0.417309,-179.703049,0.041930,0.000000
84.150002,62.733215,-179.703049,0.024899,0.001643,0.041731,279.051270,14.215550,0.417309,-179.703049,0.041930,0.000000
84.370003,62.714966,-179.703049,0.024890,0.001643,0.041731,278.970093,14.211414,0.417309,-179.703049,0.041930,0.000000
84.590004,62.700813,-179.747528,0.024890,0.001643,0.041731,278.907135,14.208208,0.417309,-179.747528,0.041930,0.000000
84.810005,62.696724,-179.747528,0.024903,0.001643,0.041731,278.888947,14.207281,0.417309,-179.747528,0.041930,0.000000
85.030006,62.681824,-179.747528,0.024908,0.001643,0.041731,278.822662,14.203904,0.417309,-179.747528,0.041930,0.000000
85.250008,62.682945,-179.747528,0.024877,0.001643,0.041731,278.827667,14.204159,0.417309,-179.747528,0.041930,0.000000
85.470001,62.669167,-179.792007,0.024895,0.001643,0.041731,278.766388,14.201036,0.417309,-179.792007,0.041930,0.000000
85.690002,62.661720,-179.747528,0.024882,0.001643,0.041731,278.733246,14.199348,0.417309,-179.747528,0.041930,0.000000
85.910004,62.649429,-179.836487,0.024899,0.001643,0.041731,278.678589,14.196564,0.417309,-179.836487,0.041930,0.000000
86.130005,62.656876,-179.747528,0.024899,0.001643,0.041731,278.711700,14.198252,0.417309,-179.747528,0.041930,0.000000
86.350006,62.635651,-179.703049,0.024886,0.001643,0.041731,278.617279,14.193441,0.417309,-179.703049,0.041930,0.000000
86.570007,62.632301,-179.792007,0.024903,0.001643,0.041731,278.602386,14.192682,0.417309,-179.792007,0.041930,0.000000
86.790001,62.614799,-179.747528,0.024890,0.001643,0.041731,278.524536,14.188716,0.417309,-179.747528,0.041930,0.000000
87.010002,62.612190,-179.836487,0.024899,0.001643,0.041731,278.512939,14.188126,0.417309,-179.836487,0.041930,0.000000
87.230003,62.590965,-179.792007,0.024903,0.001643,0.041731,278.418518,14.183315,0.417309,-179.792007,0.041930,0.000000
87.450005,62.600273,-179.792007,0.024890,0.001643,0.041731,278.459930,14.185425,0.417309,-179.792007,0.041930,0.000000
87.670006,62.576447,-179.792007,0.024899,0.001643,0.041731,278.353943,14.180025,0.417309,-179.792007,0.041930,0.000000
87.890007,62.586502,-179.836487,0.024882,0.001643,0.041731,278.398651,14.182304,0.417309,-179.836487,0.041930,0.000000
88.110001,62.583519,-179.880966,0.024899,0.001643,0.041731,278.385406,14.181628,0.417309,-179.880966,0.041930,0.000000
88.330002,62.567879,-179.836487,0.024882,0.001643,0.041731,278.315826,14.178083,0.417309,-179.836487,0.041930,0.000000
88.550003,62.568626,-179.925446,0.024903,0.001643,0.041731,278.319153,14.178253,0.417309,-179.925446,0.041930,0.000000
88.770004,62.550751,-179.836487,0.024882,0.001643,0.041731,278.239624,14.174203,0.417309,-179.836487,0.041930,0.000000
88.990005,62.545540,-179.925446,0.024895,0.001643,0.041731,278.216461,14.173021,0.417309,-179.925446,0.041930,0.000000
89.210007,62.541443,-179.925446,0.024886,0.001643,0.041731,278.198242,14.172093,0.417309,-179.925446,0.041930,0.000000
89.430008,62.532135,-179.836487,0.024890,0.001643,0.041731,278.156830,14.169985,0.417309,-179.836487,0.041930,0.000000
89.650002,62.529900,-179.925446,0.024899,0.001643,0.041731,278.146881,14.169478,0.417309,-179.925446,0.041930,0.000000
89.870003,62.519844,-179.880966,0.024882,0.001643,0.041731,278.102142,14.167199,0.417309,-179.880966,0.041930,0.000000
90.090004,62.504951,-179.880966,0.024886,0.001643,0.041731,278.035919,14.163824,0.417309,-179.880966,0.041930,0.000000
90.310005,62.499733,-179.969925,0.024886,0.001643,0.041731,278.012695,14.162642,0.417309,-179.969925,0.041930,0.000000
90.530006,62.503090,-179.880966,0.024908,0.001643,0.041731,278.027618,14.163403,0.417309,-179.880966,0.041930,0.000000
90.750008,62.501595,-179.880966,0.024890,0.001643,0.041731,278.020966,14.163063,0.417309,-179.880966,0.041930,0.000000
90.970001,62.487823,-179.925446,0.024890,0.001643,0.041731,277.959717,14.159943,0.417309,-179.925446,0.041930,0.000000
91.190002,62.482979,-179.969925,0.024895,0.001643,0.041731,277.938171,14.158846,0.417309,-179.969925,0.041930,0.000000
91.410004,62.474411,-179.969925,0.024890,0.001643,0.041731,277.900055,14.156904,0.417309,-179.969925,0.041930,0.000000
91.630005,62.477768,-179.880966,0.024903,0.001643,0.041731,277.914978,14.157664,0.417309,-179.880966,0.041930,0.000000
91.850006,62.449837,-179.880966,0.024886,0.001643,0.041731,277.790741,14.151335,0.417309,-179.880966,0.041930,0.000000
92.070007,62.445740,-179.969925,0.024899,0.001643,0.041731,277.772522,14.150407,0.417309,-179.969925,0.041930,0.000000
92.290001,62.436806,-179.969925,0.024895,0.001643,0.041731,277.732788,14.148383,0.417309,-179.969925,0.041930,0.000000
92.510002,62.428986,-180.014404,0.024895,0.001643,0.041731,277.697998,14.146610,0.417309,-180.014404,0.041930,0.000000
92.730003,62.433083,-179.969925,0.024895,0.001643,0.041731,277.716217,14.147538,0.417309,-179.969925,0.041930,0.000000
92.950005,62.422279,-179.925446,0.024899,0.001643,0.041731,277.668152,14.145091,0.417309,-179.925446,0.041930,0.000000
93.170006,62.398453,-179.969925,0.024890,0.001643,0.041731,277.562195,14.139692,0.417309,-179.969925,0.041930,0.000000
93.200005,62.412231,-180.014404,0.024895,0.001643,0.041731,277.623474,14.142814,0.417309,-180.014404,0.041930,0.000000