File: PDMS and AD/PDMS0017 Test 1-2_02142024_151700.csv
Time (sec),S:Load (lbs),S:HL1 (DIM),S:LVDT (in),S:Position (in),Ch:Position (mm),Ch:Load (N),Ch:Stress (MPa),Ch:Strain (mm/mm),Ch:HL1 (DIM),Set Point (),Cycles ()
0.110000,-0.017502,-86.337524,-0.000004,-0.000000,-0.000000,-0.077852,-0.003966,-0.000000,-86.337524,0.000182,0.000000
0.530000,0.000740,-86.382004,-0.000022,0.000053,0.001344,0.003292,0.000168,0.013442,-86.382004,0.001709,0.000000
0.950000,-0.001122,-86.337524,0.000034,0.000169,0.004302,-0.004989,-0.000254,0.043015,-86.337524,0.005212,0.000000
1.370000,-0.007080,-86.337524,0.000177,0.000308,0.007831,-0.031494,-0.001604,0.078311,-86.337524,0.008707,0.000000
1.790000,-0.018250,-86.382004,0.000310,0.000448,0.011369,-0.081178,-0.004135,0.113694,-86.382004,0.012211,0.000000
2.210000,-0.010429,-86.382004,0.000444,0.000580,0.014726,-0.046392,-0.002363,0.147255,-86.382004,0.015705,0.000000
2.630000,-0.019737,-86.470970,0.000591,0.000718,0.018246,-0.087796,-0.004473,0.182464,-86.470970,0.019200,0.000000
3.050000,0.072609,-86.426491,0.000733,0.000850,0.021585,0.322981,0.016453,0.215853,-86.426491,0.022704,0.000000
3.470000,0.226768,-86.470970,0.000880,0.000988,0.025106,1.008717,0.051386,0.251062,-86.470970,0.026199,0.000000
3.890000,0.423012,-86.470970,0.000987,0.000002,0.000043,1.881650,0.095856,0.000433,-86.470970,0.000199,0.000000
4.310000,0.427109,-86.426491,0.000966,0.000001,0.000035,1.899875,0.096784,0.000346,-86.426491,0.000304,0.000000
4.730000,0.425247,-86.515450,0.000966,0.000001,0.000035,1.891594,0.096362,0.000346,-86.515450,0.001006,0.000000
5.150000,0.486687,-86.515450,0.001000,0.000034,0.000859,2.164891,0.110285,0.008586,-86.515450,0.001700,0.000000
5.570000,0.565628,-86.515450,0.001035,0.000065,0.001656,2.516039,0.128173,0.016565,-86.515450,0.002402,0.000000
5.990000,0.658722,-86.515450,0.001061,0.000089,0.002255,2.930141,0.149269,0.022549,-86.515450,0.003105,0.000000
6.410000,0.776764,-86.515450,0.001082,0.000120,0.003044,3.455219,0.176017,0.030440,-86.515450,0.003807,0.000000
6.830000,0.855705,-86.559929,0.001112,0.000143,0.003625,3.806367,0.193906,0.036250,-86.559929,0.004501,0.000000
7.250000,0.917892,-86.559929,0.001121,0.000169,0.004302,4.082990,0.207997,0.043015,-86.559929,0.005203,0.000000
7.670001,1.060143,-86.515450,0.001143,0.000198,0.005039,4.715749,0.240232,0.050386,-86.515450,0.005906,0.000000
8.090000,1.136475,-86.559929,0.001203,0.000223,0.005663,5.055292,0.257529,0.056630,-86.559929,0.006600,0.000000
8.510000,1.328621,-86.559929,0.001216,0.000258,0.006565,5.910001,0.301070,0.065649,-86.559929,0.007302,0.000000
8.930000,1.385223,-86.604408,0.001229,0.000280,0.007111,6.161781,0.313896,0.071112,-86.604408,0.008004,0.000000
9.350000,1.496185,-86.604408,0.001255,0.000310,0.007866,6.655365,0.339040,0.078658,-86.604408,0.008707,0.000000
9.770000,1.611626,-86.604408,0.001281,0.000338,0.008586,7.168869,0.365200,0.085857,-86.604408,0.009401,0.000000
10.190001,1.701363,-86.559929,0.001337,0.000359,0.009115,7.568039,0.385534,0.091146,-86.559929,0.010103,0.000000
10.610001,1.858879,-86.648895,0.001362,0.000391,0.009938,8.268707,0.421228,0.099384,-86.648895,0.010806,0.000000
11.030001,1.953087,-86.648895,0.001380,0.000419,0.010632,8.687764,0.442576,0.106321,-86.648895,0.011499,0.000000
11.450001,2.087891,-86.648895,0.001393,0.000445,0.011309,9.287401,0.473123,0.113087,-86.648895,0.012202,0.000000
11.870001,2.191780,-86.693375,0.001444,0.000473,0.012002,9.749525,0.496664,0.120025,-86.693375,0.012904,0.000000
12.290001,2.353394,-86.693375,0.001475,0.000503,0.012783,10.468417,0.533287,0.127829,-86.693375,0.013607,0.000000
12.710001,2.454300,-86.737854,0.001492,0.000533,0.013529,10.917272,0.556152,0.135287,-86.737854,0.014301,0.000000
13.130001,2.516861,-86.737854,0.001522,0.000555,0.014092,11.195557,0.570329,0.140925,-86.737854,0.015003,0.000000
13.550000,2.666931,-86.737854,0.001539,0.000583,0.014804,11.863102,0.604335,0.148037,-86.737854,0.015705,0.000000
13.970000,2.783112,-86.737854,0.001582,0.000605,0.015376,12.379899,0.630662,0.153759,-86.737854,0.016408,0.000000
14.390000,2.943230,-86.693375,0.001621,0.000642,0.016313,13.092139,0.666945,0.163125,-86.693375,0.017102,0.000000
14.810000,2.974136,-86.782333,0.001651,0.000667,0.016946,13.229619,0.673949,0.169455,-86.782333,0.017804,0.000000
15.230000,3.013237,-86.782333,0.001643,0.000690,0.017518,13.403547,0.682809,0.175180,-86.782333,0.018507,0.000000
15.650001,3.200165,-86.826813,0.001712,0.000718,0.018238,14.235044,0.725168,0.182377,-86.826813,0.019200,0.000000
16.070002,3.241867,-86.782333,0.001707,0.000739,0.018767,14.420545,0.734618,0.187668,-86.782333,0.019903,0.000000
16.490002,3.405716,-86.826813,0.001763,0.000779,0.019781,15.149381,0.771746,0.197814,-86.826813,0.020605,0.000000
16.910002,3.454124,-86.782333,0.001789,0.000803,0.020406,15.364713,0.782716,0.204059,-86.782333,0.021308,0.000000
17.330000,3.643288,-86.871300,0.001815,0.000833,0.021152,16.206152,0.825581,0.211517,-86.871300,0.022002,0.000000
17.750000,3.650360,-86.871300,0.001841,0.000853,0.021655,16.237612,0.827183,0.216547,-86.871300,0.022704,0.000000
18.170000,3.905807,-86.871300,0.001880,0.000891,0.022626,17.373899,0.885069,0.226259,-86.871300,0.023407,0.000000
18.590000,3.896873,-86.915779,0.001906,0.000915,0.023233,17.334160,0.883044,0.232330,-86.915779,0.024109,0.000000
19.010000,3.937088,-86.871300,0.001927,0.000941,0.023892,17.513042,0.892157,0.238921,-86.871300,0.024803,0.000000
19.430000,4.083061,-87.004738,0.001949,0.000967,0.024569,18.162363,0.925235,0.245685,-87.004738,0.025505,0.000000
19.850000,4.161255,-86.871300,0.001962,0.000992,0.025202,18.510185,0.942954,0.252015,-86.871300,0.026208,0.000000
20.270000,4.359360,-86.915779,0.002026,0.001030,0.026173,19.391401,0.987845,0.261729,-86.915779,0.026901,0.000000
20.690001,4.351166,-86.915779,0.002044,0.001052,0.026728,19.354952,0.985988,0.267280,-86.915779,0.027604,0.000000
21.110001,4.479637,-86.915779,0.002082,0.001081,0.027465,19.926422,1.015100,0.274651,-86.915779,0.028306,0.000000
21.530001,4.560440,-87.004738,0.002104,0.001104,0.028037,20.285851,1.033411,0.280374,-87.004738,0.029009,0.000000
21.950001,4.628212,-87.004738,0.002113,0.001130,0.028697,20.587315,1.048768,0.286965,-87.004738,0.029703,0.000000
22.370001,4.781258,-87.004738,0.002164,0.001162,0.029520,21.268097,1.083448,0.295205,-87.004738,0.030405,0.000000
22.790001,4.777161,-86.960258,0.002190,0.001184,0.030084,21.249872,1.082520,0.300840,-86.960258,0.031107,0.000000
23.210001,4.982712,-87.049225,0.002199,0.001218,0.030943,22.164209,1.129099,0.309427,-87.049225,0.031801,0.000000
23.630001,5.007660,-87.049225,0.002233,0.001241,0.031532,22.275185,1.134752,0.315323,-87.049225,0.032504,0.000000
24.050001,5.205765,-87.049225,0.002285,0.001276,0.032408,23.156399,1.179643,0.324084,-87.049225,0.033206,0.000000
24.470001,5.116020,-87.004738,0.002294,0.001296,0.032911,22.757195,1.159307,0.329112,-87.004738,0.033908,0.000000
24.890001,5.254173,-87.093704,0.002315,0.001324,0.033640,23.371731,1.190613,0.336398,-87.093704,0.034602,0.000000
25.310001,5.347633,-87.093704,0.002350,0.001353,0.034368,23.787460,1.211791,0.343682,-87.093704,0.035305,0.000000
25.730001,5.488770,-87.138184,0.002402,0.001380,0.035045,24.415266,1.243773,0.350445,-87.138184,0.036007,0.000000
26.150002,5.601219,-87.138184,0.002436,0.001414,0.035912,24.915468,1.269254,0.359118,-87.138184,0.036710,0.000000
26.570002,5.566963,-87.049225,0.002471,0.001436,0.036467,24.763088,1.261492,0.364669,-87.049225,0.037403,0.000000
26.990002,5.716286,-87.093704,0.002479,0.001469,0.037317,25.427309,1.295329,0.373168,-87.093704,0.038106,0.000000
27.410002,5.721497,-87.138184,0.002496,0.001490,0.037837,25.450487,1.296510,0.378370,-87.138184,0.038808,0.000000
27.830002,5.955719,-87.138184,0.002552,0.001526,0.038765,26.492361,1.349585,0.387651,-87.138184,0.039502,0.000000
28.250002,5.918854,-87.182663,0.002578,0.001547,0.039294,26.328377,1.341231,0.392940,-87.182663,0.040205,0.000000
28.670002,6.023117,-87.138184,0.002574,0.001576,0.040022,26.792162,1.364858,0.400224,-87.138184,0.040907,0.000000
29.090002,6.141533,-87.138184,0.002613,0.001606,0.040803,27.318903,1.391691,0.408031,-87.138184,0.041609,0.000000
29.510002,6.109512,-87.138184,0.002639,0.001626,0.041306,27.176468,1.384435,0.413061,-87.138184,0.042303,0.000000
29.930002,6.312828,-87.271629,0.002682,0.001661,0.042182,28.080862,1.430507,0.421819,-87.271629,0.043006,0.000000
30.350002,6.340752,-87.227142,0.002725,0.001686,0.042832,28.205072,1.436835,0.428323,-87.227142,0.043708,0.000000
30.770002,6.374641,-87.182663,0.002764,0.001715,0.043552,28.355822,1.444514,0.435520,-87.182663,0.044402,0.000000
31.190001,6.443901,-87.227142,0.002764,0.001741,0.044220,28.663904,1.460209,0.442199,-87.227142,0.045104,0.000000
31.610001,6.591362,-87.227142,0.002807,0.001770,0.044948,29.319843,1.493624,0.449483,-87.227142,0.045807,0.000000
32.030003,6.590988,-87.316109,0.002828,0.001796,0.045616,29.318180,1.493539,0.456161,-87.316109,0.046509,0.000000
32.450001,6.567154,-87.227142,0.002846,0.001821,0.046249,29.212160,1.488138,0.462491,-87.227142,0.047203,0.000000
32.870003,6.719460,-87.271629,0.002889,0.001851,0.047004,29.889648,1.522651,0.470037,-87.271629,0.047906,0.000000
33.290001,6.687805,-87.271629,0.002906,0.001875,0.047619,29.748842,1.515478,0.476195,-87.271629,0.048608,0.000000
33.710003,6.880325,-87.316109,0.002962,0.001910,0.048504,30.605215,1.559104,0.485040,-87.316109,0.049311,0.000000
34.130001,6.849045,-87.360588,0.002953,0.001936,0.049180,30.466072,1.552016,0.491804,-87.360588,0.050004,0.000000
34.550003,6.888512,-87.360588,0.002975,0.001959,0.049762,30.641630,1.560959,0.497615,-87.360588,0.050707,0.000000
34.970001,6.907135,-87.360588,0.003022,0.001984,0.050386,30.724470,1.565179,0.503858,-87.360588,0.051409,0.000000
35.390003,7.092949,-87.360588,0.003048,0.002012,0.051097,31.551012,1.607285,0.510970,-87.360588,0.052103,0.000000
35.810001,7.175240,-87.449547,0.003096,0.002049,0.052034,31.917059,1.625933,0.520336,-87.449547,0.052805,0.000000
36.230003,7.080658,-87.449547,0.003104,0.002072,0.052623,31.496340,1.604500,0.526233,-87.449547,0.053508,0.000000
36.650002,7.241898,-87.360588,0.003134,0.002098,0.053291,32.213570,1.641037,0.532911,-87.360588,0.054210,0.000000
37.070004,7.133163,-87.360588,0.003169,0.002120,0.053855,31.729897,1.616398,0.538547,-87.360588,0.054904,0.000000
37.490002,7.435158,-87.405067,0.003191,0.002156,0.054757,33.073235,1.684831,0.547566,-87.405067,0.055607,0.000000
37.910004,7.327545,-87.449547,0.003238,0.002182,0.055433,32.594547,1.660445,0.554332,-87.449547,0.056309,0.000000
38.330002,7.323074,-87.494034,0.003264,0.002206,0.056040,32.574661,1.659432,0.560401,-87.494034,0.057003,0.000000
38.750000,7.464577,-87.449547,0.003277,0.002237,0.056812,33.204094,1.691497,0.568120,-87.449547,0.057705,0.000000
39.170002,7.349136,-87.405067,0.003320,0.002252,0.057211,32.690590,1.665338,0.572110,-87.405067,0.058408,0.000000
39.590000,7.630653,-87.449547,0.003337,0.002296,0.058321,33.942841,1.729131,0.583209,-87.449547,0.059110,0.000000
40.010002,7.502556,-87.538513,0.003354,0.002319,0.058893,33.373035,1.700104,0.588933,-87.538513,0.059804,0.000000
40.430000,7.594162,-87.538513,0.003419,0.002345,0.059561,33.780521,1.720862,0.595612,-87.538513,0.060506,0.000000
40.850002,7.636238,-87.538513,0.003419,0.002372,0.060246,33.967682,1.730396,0.602463,-87.538513,0.061209,0.000000
41.270000,7.691353,-87.494034,0.003449,0.002396,0.060862,34.212845,1.742885,0.608619,-87.494034,0.061911,0.000000
41.690002,7.804176,-87.538513,0.003505,0.002435,0.061842,34.714710,1.768452,0.618420,-87.538513,0.062605,0.000000
42.110001,7.794868,-87.582993,0.003510,0.002459,0.062458,34.673306,1.766342,0.624576,-87.582993,0.063307,0.000000
42.530003,7.895035,-87.582993,0.003557,0.002485,0.063117,35.118870,1.789040,0.631167,-87.582993,0.064010,0.000000
42.950001,7.811256,-87.582993,0.003579,0.002506,0.063654,34.746204,1.770056,0.636544,-87.582993,0.064704,0.000000
43.370003,7.971375,-87.582993,0.003613,0.002536,0.064409,35.458447,1.806339,0.644089,-87.582993,0.065406,0.000000
43.790001,7.953873,-87.627472,0.003635,0.002563,0.065111,35.380592,1.802373,0.651114,-87.627472,0.066109,0.000000
44.210003,7.979195,-87.627472,0.003648,0.002589,0.065770,35.493229,1.808111,0.657705,-87.627472,0.066811,0.000000
44.630001,8.097237,-87.582993,0.003686,0.002620,0.066560,36.018307,1.834860,0.665596,-87.582993,0.067505,0.000000
45.050003,8.151604,-87.582993,0.003708,0.002649,0.067288,36.260143,1.847180,0.672881,-87.582993,0.068207,0.000000
45.470001,8.207085,-87.627472,0.003760,0.002681,0.068095,36.506935,1.859752,0.680946,-87.627472,0.068910,0.000000
45.890003,8.054413,-87.627472,0.003777,0.002703,0.068667,35.827816,1.825156,0.686669,-87.627472,0.069604,0.000000
46.310001,8.100586,-87.671951,0.003807,0.002733,0.069421,36.033207,1.835619,0.694214,-87.671951,0.070306,0.000000
46.730003,8.066330,-87.716438,0.003829,0.002756,0.070011,35.880829,1.827856,0.700111,-87.716438,0.071008,0.000000
47.150002,8.189209,-87.627472,0.003867,0.002787,0.070800,36.427422,1.855701,0.708004,-87.627472,0.071711,0.000000
47.570004,8.223839,-87.671951,0.003906,0.002816,0.071538,36.581463,1.863549,0.715375,-87.671951,0.072405,0.000000
47.990002,8.202988,-87.716438,0.003915,0.002841,0.072162,36.488712,1.858824,0.721619,-87.716438,0.073107,0.000000
48.410004,8.333694,-87.760918,0.003945,0.002872,0.072951,37.070126,1.888442,0.729510,-87.760918,0.073810,0.000000
48.830002,8.383217,-87.760918,0.003984,0.002899,0.073636,37.290413,1.899664,0.736361,-87.760918,0.074512,0.000000
49.250004,8.459923,-87.760918,0.003988,0.002929,0.074408,37.631615,1.917046,0.744080,-87.760918,0.075206,0.000000
49.670002,8.436096,-87.760918,0.004014,0.002954,0.075032,37.525631,1.911647,0.750323,-87.760918,0.075908,0.000000
50.090004,8.482269,-87.805397,0.004061,0.002981,0.075718,37.731018,1.922110,0.757176,-87.805397,0.076611,0.000000
50.510002,8.574615,-87.849876,0.004100,0.003011,0.076489,38.141796,1.943036,0.764893,-87.849876,0.077305,0.000000
50.930004,8.449875,-87.805397,0.004130,0.003030,0.076958,37.586922,1.914769,0.769577,-87.805397,0.078007,0.000000
51.350002,8.670692,-87.849876,0.004156,0.003064,0.077816,38.569168,1.964807,0.778161,-87.849876,0.078709,0.000000
51.770004,8.697128,-87.805397,0.004156,0.003092,0.078536,38.686760,1.970797,0.785360,-87.805397,0.079412,0.000000
52.190002,8.770485,-87.849876,0.004195,0.003121,0.079273,39.013065,1.987420,0.792731,-87.849876,0.080106,0.000000
52.610001,8.661751,-87.894356,0.004243,0.003143,0.079837,38.529392,1.962781,0.798369,-87.894356,0.080808,0.000000
53.030003,8.855011,-87.849876,0.004273,0.003175,0.080652,39.389057,2.006574,0.806520,-87.849876,0.081511,0.000000
53.450001,8.781281,-87.805397,0.004307,0.003197,0.081207,39.061085,1.989867,0.812070,-87.805397,0.082204,0.000000
53.870003,8.777557,-87.849876,0.004316,0.003225,0.081909,39.044525,1.989023,0.819095,-87.849876,0.082907,0.000000
54.290001,8.941032,-87.894356,0.004359,0.003256,0.082707,39.771698,2.026067,0.827073,-87.894356,0.083609,0.000000
54.710003,8.921669,-87.938843,0.004376,0.003280,0.083306,39.685566,2.021679,0.833057,-87.938843,0.084312,0.000000
55.130001,9.057587,-87.938843,0.004424,0.003315,0.084208,40.290157,2.052479,0.842077,-87.938843,0.085006,0.000000
55.550003,8.979759,-87.894356,0.004419,0.003340,0.084823,39.943962,2.034842,0.848235,-87.894356,0.085708,0.000000
55.970001,9.016251,-87.938843,0.004454,0.003363,0.085413,40.106285,2.043112,0.854132,-87.938843,0.086410,0.000000
56.390003,8.979759,-88.027802,0.004488,0.003384,0.085960,39.943962,2.034842,0.859595,-88.027802,0.087113,0.000000
56.810001,9.243027,-88.027802,0.004523,0.003418,0.086818,41.115036,2.094500,0.868179,-88.027802,0.087807,0.000000
57.230003,9.225525,-87.938843,0.004549,0.003451,0.087659,41.037186,2.090534,0.876593,-87.938843,0.088509,0.000000
57.650002,9.221428,-87.938843,0.004592,0.003477,0.088310,41.018959,2.089606,0.883096,-87.938843,0.089211,0.000000
58.070004,9.331276,-87.983322,0.004609,0.003502,0.088960,41.507587,2.114497,0.889600,-87.983322,0.089905,0.000000
58.490002,9.316010,-88.027802,0.004635,0.003527,0.089576,41.439678,2.111038,0.895758,-88.027802,0.090608,0.000000
58.910004,9.514114,-88.072281,0.004682,0.003563,0.090512,42.320896,2.155929,0.905124,-88.072281,0.091310,0.000000
59.330002,9.386391,-88.116760,0.004721,0.003589,0.091163,41.752750,2.126987,0.911628,-88.116760,0.092013,0.000000
59.750004,9.351761,-88.027802,0.004721,0.003613,0.091761,41.598709,2.119139,0.917612,-88.027802,0.092706,0.000000
60.170002,9.420647,-88.027802,0.004760,0.003639,0.092420,41.905128,2.134749,0.924203,-88.027802,0.093409,0.000000
60.590004,9.540550,-88.072281,0.004786,0.003665,0.093079,42.438488,2.161920,0.930795,-88.072281,0.094111,0.000000
61.010002,9.631035,-88.116760,0.004816,0.003701,0.094016,42.840984,2.182424,0.940160,-88.116760,0.094805,0.000000
61.430004,9.528633,-88.116760,0.004859,0.003723,0.094554,42.385475,2.159219,0.945537,-88.116760,0.095508,0.000000
61.850002,9.577415,-88.116760,0.004868,0.003749,0.095213,42.602470,2.170273,0.952128,-88.116760,0.096210,0.000000
62.270004,9.644073,-88.072281,0.004889,0.003776,0.095898,42.898983,2.185378,0.958979,-88.072281,0.096912,0.000000
62.690002,9.888718,-88.116760,0.004915,0.003809,0.096739,43.987213,2.240815,0.967391,-88.116760,0.097606,0.000000
63.110004,9.788551,-88.161247,0.004963,0.003840,0.097528,43.541653,2.218117,0.975282,-88.161247,0.098309,0.000000
63.530003,9.721153,-88.116760,0.005010,0.003860,0.098049,43.241848,2.202845,0.980487,-88.116760,0.099011,0.000000
63.950005,9.929680,-88.116760,0.005019,0.003891,0.098838,44.169422,2.250098,0.988378,-88.116760,0.099714,0.000000
64.370003,9.870102,-88.161247,0.005049,0.003913,0.099384,43.904408,2.236597,0.993842,-88.161247,0.100407,0.000000
64.790001,10.018677,-88.205727,0.005075,0.003943,0.100147,44.565300,2.270265,1.001472,-88.205727,0.101110,0.000000
65.210007,9.969154,-88.161247,0.005105,0.003970,0.100841,44.345013,2.259043,1.008410,-88.161247,0.101812,0.000000
65.630005,10.017189,-88.294685,0.005113,0.003995,0.101474,44.558681,2.269928,1.014742,-88.294685,0.102506,0.000000
66.050003,10.149384,-88.205727,0.005157,0.004026,0.102272,45.146713,2.299883,1.022720,-88.205727,0.103209,0.000000
66.470001,10.197792,-88.161247,0.005187,0.004054,0.102974,45.362045,2.310853,1.029745,-88.161247,0.103911,0.000000
66.889999,10.156082,-88.205727,0.005204,0.004084,0.103746,45.176510,2.301401,1.037462,-88.205727,0.104614,0.000000
67.310005,10.177307,-88.294685,0.005273,0.004107,0.104319,45.270924,2.306211,1.043187,-88.294685,0.105307,0.000000
67.730003,10.355301,-88.294685,0.005295,0.004141,0.105177,46.062679,2.346545,1.051771,-88.294685,0.106010,0.000000
68.150002,10.259232,-88.339172,0.005316,0.004163,0.105732,45.635342,2.324775,1.057322,-88.339172,0.106712,0.000000
68.570000,10.340408,-88.294685,0.005351,0.004191,0.106461,45.996433,2.343170,1.064606,-88.294685,0.107406,0.000000
68.990005,10.380997,-88.294685,0.005385,0.004223,0.107276,46.176979,2.352367,1.072758,-88.294685,0.108108,0.000000
69.410004,10.476692,-88.339172,0.005415,0.004249,0.107926,46.602654,2.374053,1.079263,-88.339172,0.108811,0.000000
69.830002,10.467384,-88.339172,0.005420,0.004275,0.108594,46.561253,2.371943,1.085941,-88.339172,0.109513,0.000000
70.250000,10.541862,-88.294685,0.005476,0.004303,0.109288,46.892548,2.388820,1.092879,-88.294685,0.110207,0.000000
70.670006,10.579468,-88.294685,0.005497,0.004332,0.110042,47.059822,2.397342,1.100422,-88.294685,0.110910,0.000000
71.090004,10.594368,-88.339172,0.005523,0.004358,0.110701,47.126102,2.400718,1.107014,-88.339172,0.111612,0.000000
71.510002,10.628250,-88.383652,0.005545,0.004384,0.111352,47.276817,2.408396,1.113518,-88.383652,0.112314,0.000000
71.930000,10.639420,-88.428131,0.005592,0.004412,0.112063,47.326500,2.410927,1.120630,-88.428131,0.113008,0.000000
72.350006,10.620804,-88.383652,0.005601,0.004432,0.112566,47.243694,2.406708,1.125660,-88.383652,0.113711,0.000000
72.770004,10.766777,-88.383652,0.005644,0.004465,0.113407,47.893017,2.439787,1.134072,-88.383652,0.114413,0.000000
73.190002,10.863594,-88.428131,0.005674,0.004496,0.114205,48.323681,2.461726,1.142050,-88.428131,0.115107,0.000000
73.610001,10.930244,-88.517090,0.005700,0.004527,0.114985,48.620155,2.476829,1.149855,-88.517090,0.115809,0.000000
74.030006,10.818909,-88.472610,0.005721,0.004549,0.115549,48.124908,2.451600,1.155492,-88.472610,0.116512,0.000000
74.450005,10.976044,-88.517090,0.005747,0.004579,0.116304,48.823879,2.487207,1.163038,-88.517090,0.117214,0.000000
74.870003,10.995041,-88.472610,0.005786,0.004606,0.116998,48.908386,2.491512,1.169975,-88.472610,0.117908,0.000000
75.290001,10.906784,-88.472610,0.005795,0.004629,0.117579,48.515797,2.471513,1.175785,-88.472610,0.118610,0.000000
75.710007,11.116432,-88.561577,0.005825,0.004663,0.118428,49.448360,2.519020,1.184284,-88.561577,0.119313,0.000000
76.130005,11.149200,-88.561577,0.005855,0.004689,0.119105,49.594120,2.526445,1.191048,-88.561577,0.120015,0.000000
76.550003,11.198723,-88.517090,0.005907,0.004721,0.119911,49.814407,2.537667,1.199113,-88.517090,0.120709,0.000000
76.970001,11.140266,-88.517090,0.005920,0.004744,0.120501,49.554379,2.524420,1.205010,-88.517090,0.121412,0.000000
77.390007,11.207664,-88.472610,0.005950,0.004770,0.121169,49.854183,2.539693,1.211689,-88.472610,0.122114,0.000000
77.810005,11.195374,-88.606056,0.005976,0.004790,0.121663,49.799507,2.536908,1.216632,-88.606056,0.122808,0.000000
78.230003,11.309692,-88.517090,0.006015,0.004824,0.122539,50.308025,2.562813,1.225390,-88.517090,0.123510,0.000000
78.650002,11.360710,-88.517090,0.006071,0.004857,0.123363,50.534962,2.574374,1.233630,-88.517090,0.124213,0.000000
79.070007,11.279533,-88.561577,0.006062,0.004878,0.123892,50.173870,2.555979,1.238919,-88.561577,0.124915,0.000000
79.490005,11.397942,-88.650536,0.006075,0.004904,0.124568,50.700577,2.582810,1.245683,-88.650536,0.125609,0.000000
79.910004,11.385284,-88.650536,0.006105,0.004930,0.125210,50.644276,2.579942,1.252100,-88.650536,0.126311,0.000000
80.330002,11.665306,-88.695015,0.006170,0.004970,0.126242,51.889874,2.643396,1.262421,-88.695015,0.127014,0.000000
80.750008,11.511520,-88.650536,0.006196,0.004992,0.126788,51.205799,2.608548,1.267885,-88.650536,0.127708,0.000000
81.170006,11.617645,-88.606056,0.006213,0.005018,0.127447,51.677868,2.632596,1.274474,-88.606056,0.128410,0.000000
81.590004,11.551361,-88.650536,0.006209,0.005043,0.128089,51.383018,2.617576,1.280894,-88.650536,0.129113,0.000000
82.010002,11.743881,-88.650536,0.006260,0.005069,0.128757,52.239391,2.661202,1.287570,-88.650536,0.129815,0.000000
82.430000,11.779625,-88.739494,0.006308,0.005105,0.129668,52.398388,2.669301,1.296677,-88.739494,0.130509,0.000000
82.850006,11.673874,-88.739494,0.006334,0.005127,0.130231,51.927986,2.645338,1.302312,-88.739494,0.131211,0.000000
83.270004,11.837341,-88.695015,0.006359,0.005155,0.130934,52.655125,2.682380,1.309337,-88.695015,0.131914,0.000000
83.690002,11.794151,-88.783981,0.006385,0.005177,0.131497,52.463005,2.672593,1.314975,-88.783981,0.132616,0.000000
84.110001,12.110664,-88.783981,0.006420,0.005218,0.132538,53.870926,2.744316,1.325381,-88.783981,0.133310,0.000000
84.530006,11.881660,-88.739494,0.006454,0.005241,0.133119,52.852264,2.692423,1.331191,-88.739494,0.134012,0.000000
84.950005,11.960602,-88.739494,0.006480,0.005267,0.133778,53.203415,2.710311,1.337783,-88.739494,0.134715,0.000000
85.370003,12.065979,-88.739494,0.006515,0.005296,0.134507,53.672153,2.734190,1.345067,-88.739494,0.135409,0.000000
85.790001,12.093910,-88.783981,0.006545,0.005319,0.135105,53.796398,2.740519,1.351050,-88.783981,0.136111,0.000000
86.210007,12.196312,-88.828461,0.006532,0.005348,0.135834,54.251904,2.763724,1.358336,-88.828461,0.136814,0.000000
86.630005,12.230942,-88.828461,0.006584,0.005374,0.136510,54.405945,2.771571,1.365100,-88.828461,0.137516,0.000000
87.050003,12.401863,-88.828461,0.006622,0.005406,0.137317,55.166241,2.810302,1.373166,-88.828461,0.138210,0.000000
87.470001,12.194824,-88.872940,0.006648,0.005427,0.137837,54.245289,2.763387,1.378370,-88.872940,0.138912,0.000000
87.890007,12.395905,-88.828461,0.006683,0.005459,0.138661,55.139736,2.808952,1.386608,-88.828461,0.139615,0.000000
88.310005,12.396645,-88.872940,0.006717,0.005487,0.139372,55.143028,2.809120,1.393719,-88.872940,0.140309,0.000000
88.730003,12.511337,-88.872940,0.006748,0.005514,0.140057,55.653206,2.835109,1.400570,-88.872940,0.141011,0.000000
89.150002,12.557144,-88.872940,0.006765,0.005544,0.140820,55.856968,2.845490,1.408202,-88.872940,0.141713,0.000000
89.570007,12.664009,-88.872940,0.006817,0.005571,0.141497,56.332325,2.869706,1.414966,-88.872940,0.142416,0.000000
89.990005,12.766411,-88.872940,0.006812,0.005601,0.142277,56.787830,2.892910,1.422770,-88.872940,0.143110,0.000000
90.410004,12.620071,-88.917419,0.006855,0.005626,0.142893,56.136883,2.859749,1.428928,-88.917419,0.143812,0.000000
90.830002,12.736252,-89.006386,0.006868,0.005654,0.143621,56.653679,2.886076,1.436212,-89.006386,0.144514,0.000000
91.250008,12.778328,-88.961899,0.006929,0.005681,0.144289,56.840843,2.895611,1.442891,-88.961899,0.145217,0.000000
91.670006,12.945152,-88.961899,0.006942,0.005710,0.145044,57.582912,2.933414,1.450436,-88.961899,0.145911,0.000000
92.090004,12.875893,-88.917419,0.006980,0.005735,0.145677,57.274830,2.917719,1.456766,-88.917419,0.146613,0.000000
92.510002,12.897118,-88.961899,0.006998,0.005764,0.146405,57.369244,2.922529,1.464050,-88.961899,0.147316,0.000000
92.930008,13.006592,-89.006386,0.007041,0.005789,0.147047,57.856209,2.947336,1.470468,-89.006386,0.148009,0.000000
93.350006,12.890785,-89.006386,0.007054,0.005815,0.147697,57.341076,2.921094,1.476972,-89.006386,0.148712,0.000000
93.770004,13.108253,-89.006386,0.007092,0.005843,0.148417,58.308422,2.970373,1.484171,-89.006386,0.149414,0.000000
94.190002,13.106018,-89.006386,0.007131,0.005872,0.149154,58.298481,2.969866,1.491542,-89.006386,0.150117,0.000000
94.610008,13.232620,-89.006386,0.007118,0.005901,0.149891,58.861633,2.998555,1.498913,-89.006386,0.150811,0.000000
95.030006,13.274704,-89.095345,0.007183,0.005931,0.150646,59.048832,3.008091,1.506458,-89.095345,0.151513,0.000000
95.450005,13.273582,-89.050865,0.007187,0.005953,0.151201,59.043842,3.007837,1.512009,-89.050865,0.152215,0.000000
95.870003,13.305237,-89.050865,0.007230,0.005983,0.151964,59.184650,3.015010,1.519639,-89.050865,0.152909,0.000000
96.290001,13.424026,-89.050865,0.007252,0.006010,0.152666,59.713051,3.041928,1.526664,-89.050865,0.153612,0.000000
96.710007,13.593826,-89.050865,0.007282,0.006039,0.153395,60.468361,3.080405,1.533950,-89.050865,0.154314,0.000000
97.130005,13.473175,-89.095345,0.007312,0.006064,0.154019,59.931675,3.053065,1.540193,-89.095345,0.155017,0.000000
97.550003,13.704422,-89.139824,0.007347,0.006096,0.154843,60.960312,3.105466,1.548433,-89.139824,0.155710,0.000000
97.970001,13.690643,-89.139824,0.007394,0.006126,0.155606,60.899021,3.102344,1.556063,-89.139824,0.156413,0.000000
98.390007,13.594940,-89.139824,0.007403,0.006148,0.156161,60.473312,3.080657,1.561614,-89.139824,0.157115,0.000000
98.810005,13.769958,-89.139824,0.007424,0.006175,0.156838,61.251835,3.120317,1.568377,-89.139824,0.157818,0.000000
99.230003,13.895821,-89.184303,0.007442,0.006199,0.157454,61.811699,3.148838,1.574535,-89.184303,0.158512,0.000000
99.650002,14.137489,-89.273270,0.007476,0.006236,0.158390,62.886692,3.203601,1.583901,-89.273270,0.159214,0.000000
100.070007,13.929337,-89.139824,0.007537,0.006261,0.159023,61.960785,3.156433,1.590231,-89.139824,0.159917,0.000000
100.490005,13.836983,-89.184303,0.007554,0.006282,0.159552,61.549973,3.135505,1.595523,-89.184303,0.160610,0.000000
100.910004,14.095413,-89.184303,0.007575,0.006312,0.160324,62.699528,3.194066,1.603240,-89.184303,0.161313,0.000000
101.330002,14.019073,-89.228790,0.007597,0.006335,0.160905,62.359955,3.176767,1.609052,-89.228790,0.162015,0.000000
101.750008,14.195580,-89.273270,0.007653,0.006371,0.161824,63.145092,3.216764,1.618243,-89.273270,0.162718,0.000000
102.170006,14.131531,-89.228790,0.007683,0.006397,0.162483,62.860188,3.202251,1.624835,-89.228790,0.163411,0.000000
102.590004,14.271545,-89.273270,0.007683,0.006423,0.163151,63.483006,3.233978,1.631511,-89.273270,0.164114,0.000000
103.010002,14.241753,-89.228790,0.007722,0.006446,0.163741,63.350479,3.227227,1.637410,-89.228790,0.164816,0.000000
103.430008,14.538910,-89.317749,0.007761,0.006481,0.164617,64.672302,3.294564,1.646168,-89.317749,0.165510,0.000000
103.850006,14.465919,-89.317749,0.007782,0.006509,0.165319,64.347626,3.278024,1.653193,-89.317749,0.166213,0.000000
104.270004,14.545982,-89.362228,0.007795,0.006536,0.166022,64.703758,3.296167,1.660218,-89.362228,0.166915,0.000000
104.690002,14.621948,-89.273270,0.007838,0.006560,0.166629,65.041672,3.313381,1.666289,-89.273270,0.167617,0.000000
105.110008,14.750412,-89.273270,0.007856,0.006588,0.167323,65.613106,3.342491,1.673226,-89.273270,0.168311,0.000000
105.530006,14.905693,-89.362228,0.007916,0.006624,0.168259,66.303833,3.377678,1.682592,-89.362228,0.169014,0.000000
105.950005,14.774620,-89.406715,0.007929,0.006650,0.168910,65.720795,3.347977,1.689096,-89.406715,0.169716,0.000000
106.370003,14.836060,-89.317749,0.007955,0.006673,0.169482,65.994087,3.361899,1.694819,-89.317749,0.170418,0.000000
106.790009,14.885582,-89.362228,0.008002,0.006701,0.170193,66.214378,3.373121,1.701931,-89.362228,0.171112,0.000000
107.210007,14.963783,-89.317749,0.008002,0.006726,0.170835,66.562233,3.390842,1.708348,-89.317749,0.171815,0.000000
107.630005,15.147362,-89.406715,0.008037,0.006756,0.171598,67.378830,3.432441,1.715981,-89.406715,0.172517,0.000000
108.050003,15.035278,-89.406715,0.008088,0.006779,0.172179,66.880257,3.407043,1.721790,-89.406715,0.173211,0.000000
108.470009,15.325356,-89.406715,0.008080,0.006812,0.173020,68.170586,3.472775,1.730202,-89.406715,0.173913,0.000000
108.890007,15.265404,-89.406715,0.008132,0.006836,0.173636,67.903908,3.459190,1.736360,-89.406715,0.174616,0.000000
109.310005,15.492554,-89.406715,0.008153,0.006868,0.174460,68.914322,3.510663,1.744598,-89.406715,0.175318,0.000000
109.730003,15.275459,-89.451195,0.008170,0.006889,0.174980,67.948639,3.461468,1.749802,-89.451195,0.176012,0.000000
110.150002,15.445259,-89.495674,0.008222,0.006920,0.175761,68.703941,3.499946,1.757607,-89.495674,0.176715,0.000000
110.570007,15.491806,-89.540154,0.008252,0.006948,0.176472,68.910995,3.510494,1.764719,-89.540154,0.177417,0.000000
110.990005,15.695122,-89.495674,0.008278,0.006976,0.177183,69.815392,3.556565,1.771829,-89.495674,0.178111,0.000000
111.410004,15.804230,-89.495674,0.008300,0.007007,0.177989,70.300728,3.581290,1.779894,-89.495674,0.178813,0.000000
111.830002,15.658630,-89.495674,0.008334,0.007030,0.178570,69.653069,3.548296,1.785704,-89.495674,0.179516,0.000000
112.250008,15.896950,-89.584633,0.008360,0.007060,0.179334,70.713165,3.602300,1.793336,-89.584633,0.180218,0.000000
112.670006,15.831787,-89.540154,0.008395,0.007083,0.179906,70.423309,3.587534,1.799061,-89.540154,0.180912,0.000000
113.090004,16.074196,-89.540154,0.008425,0.007114,0.180704,71.501595,3.642465,1.807039,-89.540154,0.181614,0.000000
113.510002,16.061165,-89.584633,0.008425,0.007141,0.181372,71.443626,3.639512,1.813716,-89.584633,0.182317,0.000000
113.930008,16.133408,-89.584633,0.008468,0.007168,0.182057,71.764984,3.655882,1.820567,-89.584633,0.183019,0.000000
114.350006,16.287193,-89.584633,0.008489,0.007197,0.182802,72.449051,3.690731,1.828025,-89.584633,0.183713,0.000000
114.770004,16.209740,-89.584633,0.008541,0.007219,0.183366,72.104523,3.673180,1.833662,-89.584633,0.184416,0.000000
115.190002,16.588074,-89.629120,0.008567,0.007252,0.184207,73.787437,3.758911,1.842074,-89.629120,0.185118,0.000000
115.610008,16.528496,-89.584633,0.008601,0.007279,0.184884,73.522423,3.745411,1.848838,-89.584633,0.185812,0.000000
116.030006,16.627541,-89.673599,0.008606,0.007308,0.185630,73.962997,3.767854,1.856296,-89.673599,0.186514,0.000000
116.450005,16.629036,-89.673599,0.008649,0.007334,0.186289,73.969643,3.768193,1.862888,-89.673599,0.187217,0.000000
116.870003,16.760483,-89.673599,0.008670,0.007363,0.187009,74.554352,3.797980,1.870086,-89.673599,0.187919,0.000000
117.290009,16.885223,-89.718079,0.008718,0.007388,0.187668,75.109222,3.826247,1.876678,-89.718079,0.188613,0.000000
117.710007,16.812241,-89.673599,0.008748,0.007414,0.188309,74.784584,3.809708,1.883095,-89.673599,0.189315,0.000000
118.130005,17.037155,-89.673599,0.008791,0.007443,0.189055,75.785049,3.860675,1.890553,-89.673599,0.190018,0.000000
118.550003,16.907944,-89.718079,0.008778,0.007465,0.189602,75.210289,3.831395,1.896017,-89.718079,0.190712,0.000000
118.970009,17.336166,-89.762558,0.008826,0.007503,0.190564,77.115120,3.928432,1.905642,-89.762558,0.191414,0.000000
119.390007,17.193924,-89.762558,0.008873,0.007529,0.191249,76.482391,3.896199,1.912492,-89.762558,0.192117,0.000000
119.810005,17.215149,-89.718079,0.008912,0.007552,0.191822,76.576805,3.901008,1.918217,-89.718079,0.192819,0.000000
120.230003,17.233025,-89.762558,0.008903,0.007576,0.192429,76.656319,3.905059,1.924288,-89.762558,0.193513,0.000000
120.650009,17.609863,-89.807037,0.008921,0.007606,0.193201,78.332581,3.990452,1.932005,-89.807037,0.194215,0.000000
121.070007,17.796417,-89.807037,0.008959,0.007639,0.194033,79.162415,4.032726,1.940332,-89.807037,0.194918,0.000000
121.490005,17.688057,-89.762558,0.008981,0.007666,0.194710,78.680405,4.008171,1.947096,-89.762558,0.195620,0.000000
121.910004,17.807968,-89.762558,0.009024,0.007692,0.195369,79.213799,4.035343,1.953687,-89.762558,0.196314,0.000000
122.330009,17.683968,-89.762558,0.009050,0.007715,0.195958,78.662216,4.007244,1.959584,-89.762558,0.197016,0.000000
122.750008,18.277153,-89.762558,0.009067,0.007749,0.196834,81.300835,4.141662,1.968342,-89.762558,0.197719,0.000000
123.170006,18.093948,-89.896004,0.009132,0.007776,0.197519,80.485901,4.100147,1.975193,-89.896004,0.198413,0.000000
123.590004,18.065277,-89.851524,0.009136,0.007800,0.198126,80.358368,4.093650,1.981264,-89.851524,0.199115,0.000000
124.010002,18.343063,-89.762558,0.009166,0.007831,0.198898,81.594025,4.156598,1.988983,-89.762558,0.199817,0.000000
124.430008,18.055962,-89.851524,0.009196,0.007846,0.199297,80.316925,4.091539,1.992972,-89.851524,0.200520,0.000000
124.850006,18.626808,-89.896004,0.009235,0.007887,0.200338,82.856178,4.220895,2.003379,-89.896004,0.201214,0.000000
125.270004,18.452538,-89.896004,0.009261,0.007913,0.200988,82.080986,4.181405,2.009883,-89.896004,0.201916,0.000000
125.690002,18.618622,-89.940483,0.009291,0.007940,0.201682,82.819763,4.219040,2.016821,-89.940483,0.202619,0.000000
126.110008,18.621597,-89.896004,0.009300,0.007964,0.202280,82.833000,4.219714,2.022805,-89.896004,0.203321,0.000000
126.530006,18.894547,-89.896004,0.009347,0.007993,0.203035,84.047142,4.281566,2.030348,-89.896004,0.204015,0.000000
126.950005,19.061745,-89.896004,0.009382,0.008029,0.203928,84.790878,4.319453,2.039283,-89.896004,0.204717,0.000000
127.370003,19.037537,-89.984962,0.009416,0.008053,0.204544,84.683189,4.313967,2.045439,-89.984962,0.205420,0.000000
127.790009,19.195053,-89.940483,0.009447,0.008079,0.205212,85.383858,4.349661,2.052117,-89.940483,0.206114,0.000000
128.210007,19.071053,-89.940483,0.009485,0.008100,0.205749,84.832275,4.321562,2.057493,-89.940483,0.206816,0.000000
128.630005,19.417732,-89.984962,0.009507,0.008129,0.206486,86.374390,4.400121,2.064865,-89.984962,0.207518,0.000000
129.050003,19.514175,-89.984962,0.009503,0.008160,0.207258,86.803391,4.421976,2.072584,-89.984962,0.208221,0.000000
129.470001,19.502632,-90.029442,0.009537,0.008183,0.207848,86.752037,4.419359,2.078481,-90.029442,0.208915,0.000000
129.889999,19.828461,-90.029442,0.009580,0.008219,0.208750,88.201401,4.493193,2.087500,-90.029442,0.209617,0.000000
130.310013,19.897346,-90.029442,0.009606,0.008244,0.209392,88.507820,4.508803,2.093917,-90.029442,0.210320,0.000000
130.730011,20.018738,-90.029442,0.009628,0.008274,0.210155,89.047791,4.536311,2.101548,-90.029442,0.211013,0.000000
131.150009,20.054489,-90.029442,0.009662,0.008297,0.210753,89.206825,4.544412,2.107532,-90.029442,0.211716,0.000000
131.570007,20.223175,-90.118408,0.009675,0.008326,0.211482,89.957176,4.582637,2.114818,-90.118408,0.212418,0.000000
131.990005,20.202316,-90.118408,0.009727,0.008351,0.212115,89.864388,4.577910,2.121148,-90.118408,0.213121,0.000000
132.410004,20.474525,-90.073929,0.009744,0.008382,0.212904,91.075241,4.639594,2.129039,-90.073929,0.213815,0.000000
132.830002,20.591820,-90.118408,0.009804,0.008410,0.213624,91.596992,4.666173,2.136238,-90.118408,0.214517,0.000000
133.250000,20.554214,-90.073929,0.009804,0.008435,0.214248,91.429710,4.657651,2.142481,-90.073929,0.215219,0.000000
133.670013,20.880035,-90.162888,0.009852,0.008465,0.215020,92.879036,4.731483,2.150199,-90.162888,0.215922,0.000000
134.090012,20.774284,-90.118408,0.009856,0.008489,0.215610,92.408630,4.707520,2.156098,-90.118408,0.216616,0.000000
134.510010,21.208839,-90.118408,0.009899,0.008524,0.216512,94.341629,4.805992,2.165115,-90.118408,0.217318,0.000000
134.930008,21.201393,-90.162888,0.009916,0.008548,0.217119,94.308510,4.804304,2.171186,-90.162888,0.218021,0.000000
135.350006,21.290016,-90.207367,0.009947,0.008574,0.217769,94.702721,4.824387,2.177691,-90.207367,0.218714,0.000000
135.770004,21.503761,-90.207367,0.009960,0.008603,0.218524,95.653511,4.872822,2.185236,-90.207367,0.219417,0.000000
136.190002,21.348854,-90.207367,0.010007,0.008621,0.218983,94.964447,4.837719,2.189832,-90.207367,0.220119,0.000000
136.610001,21.810966,-90.207367,0.010024,0.008657,0.219894,97.020027,4.942436,2.198937,-90.207367,0.220822,0.000000
137.030014,21.863846,-90.251846,0.010059,0.008685,0.220588,97.255241,4.954418,2.205877,-90.251846,0.221516,0.000000
137.450012,22.194885,-90.251846,0.010098,0.008715,0.221359,98.727783,5.029433,2.213594,-90.251846,0.222218,0.000000
137.870010,21.962898,-90.296333,0.010115,0.008736,0.221888,97.695854,4.976864,2.218883,-90.296333,0.222920,0.000000
138.290009,22.419052,-90.296333,0.010145,0.008769,0.222721,99.724922,5.080230,2.227210,-90.296333,0.223614,0.000000
138.710007,22.318512,-90.251846,0.010171,0.008790,0.223276,99.277702,5.057447,2.232759,-90.251846,0.224317,0.000000
139.130005,22.382561,-90.296333,0.010218,0.008818,0.223970,99.562599,5.071960,2.239698,-90.296333,0.225019,0.000000
139.550003,22.783607,-90.340813,0.010231,0.008848,0.224742,101.346550,5.162839,2.247416,-90.340813,0.225721,0.000000
139.970001,22.907974,-90.296333,0.010257,0.008875,0.225418,101.899757,5.191021,2.254179,-90.296333,0.226415,0.000000
140.389999,23.169380,-90.340813,0.010292,0.008906,0.226224,103.062553,5.250257,2.262245,-90.340813,0.227118,0.000000
140.810013,23.115761,-90.251846,0.010326,0.008932,0.226884,102.824036,5.238106,2.268836,-90.251846,0.227820,0.000000
141.230011,23.255775,-90.296333,0.010356,0.008957,0.227517,103.446854,5.269834,2.275167,-90.296333,0.228523,0.000000
141.650009,23.142197,-90.340813,0.010356,0.008977,0.228020,102.941635,5.244096,2.280197,-90.340813,0.229216,0.000000
142.070007,23.739113,-90.385292,0.010417,0.009011,0.228878,105.596848,5.379360,2.288783,-90.385292,0.229919,0.000000
142.490005,23.949501,-90.429771,0.010434,0.009045,0.229745,106.532700,5.427035,2.297454,-90.429771,0.230621,0.000000
142.910004,23.952110,-90.385292,0.010473,0.009071,0.230405,106.544312,5.427626,2.304045,-90.385292,0.231315,0.000000
143.330002,24.249634,-90.429771,0.010477,0.009097,0.231072,107.867760,5.495046,2.310724,-90.429771,0.232018,0.000000
143.750000,24.172554,-90.429771,0.010516,0.009121,0.231662,107.524887,5.477579,2.316621,-90.429771,0.232720,0.000000
144.170013,24.739677,-90.429771,0.010542,0.009156,0.232555,110.047585,5.606091,2.325553,-90.429771,0.233422,0.000000
144.590012,24.567642,-90.474251,0.010572,0.009180,0.233171,109.282333,5.567107,2.331711,-90.474251,0.234116,0.000000
145.010010,24.617912,-90.474251,0.010585,0.009206,0.233830,109.505943,5.578499,2.338300,-90.474251,0.234819,0.000000
145.430008,24.874847,-90.429771,0.010637,0.009232,0.234489,110.648849,5.636721,2.344892,-90.429771,0.235521,0.000000
145.850006,25.154877,-90.474251,0.010658,0.009258,0.235148,111.894478,5.700176,2.351483,-90.474251,0.236215,0.000000
146.270004,25.558151,-90.429771,0.010688,0.009294,0.236067,113.688332,5.791560,2.360675,-90.429771,0.236917,0.000000
146.690002,25.403244,-90.474251,0.010749,0.009316,0.236631,112.999275,5.756458,2.366313,-90.474251,0.237620,0.000000
147.110001,25.654594,-90.518738,0.010731,0.009344,0.237325,114.117332,5.813414,2.373250,-90.518738,0.238322,0.000000
147.530014,25.804665,-90.518738,0.010774,0.009370,0.237993,114.784882,5.847421,2.379929,-90.518738,0.239016,0.000000
147.950012,26.509567,-90.518738,0.010796,0.009405,0.238886,117.920448,6.007154,2.388861,-90.518738,0.239719,0.000000
148.370010,26.363220,-90.563217,0.010843,0.009432,0.239571,117.269463,5.973991,2.395712,-90.563217,0.240421,0.000000
148.790009,26.337158,-90.518738,0.010861,0.009454,0.240143,117.153534,5.968085,2.401434,-90.518738,0.241124,0.000000
149.210007,26.837250,-90.563217,0.010904,0.009485,0.240915,119.378052,6.081408,2.409154,-90.563217,0.241817,0.000000
149.630005,26.792198,-90.563217,0.010917,0.009506,0.241462,119.177650,6.071199,2.414617,-90.563217,0.242520,0.000000
150.050003,27.239784,-90.563217,0.010934,0.009537,0.242242,121.168610,6.172623,2.422422,-90.563217,0.243222,0.000000
150.470001,27.323944,-90.607697,0.010981,0.009564,0.242927,121.542976,6.191694,2.429272,-90.607697,0.243916,0.000000
150.890015,27.506409,-90.652176,0.010990,0.009591,0.243612,122.354614,6.233041,2.436125,-90.652176,0.244618,0.000000
151.310013,27.902237,-90.607697,0.011020,0.009620,0.244350,124.115349,6.322737,2.443496,-90.607697,0.245321,0.000000
151.730011,28.217636,-90.652176,0.011050,0.009649,0.245087,125.518311,6.394208,2.450867,-90.652176,0.246023,0.000000
152.150009,28.285034,-90.607697,0.011081,0.009675,0.245746,125.818115,6.409481,2.457458,-90.607697,0.246717,0.000000
152.570007,28.436218,-90.696663,0.011111,0.009701,0.246405,126.490616,6.443739,2.464048,-90.696663,0.247420,0.000000
152.990005,28.880463,-90.652176,0.011128,0.009731,0.247159,128.466721,6.544406,2.471593,-90.652176,0.248122,0.000000
153.410004,28.803375,-90.652176,0.011171,0.009755,0.247766,128.123810,6.526938,2.477664,-90.652176,0.248816,0.000000
153.830002,29.327682,-90.696663,0.011175,0.009786,0.248573,130.456055,6.645748,2.485730,-90.696663,0.249518,0.000000
154.250000,29.481842,-90.741142,0.011232,0.009815,0.249310,131.141785,6.680681,2.493101,-90.741142,0.250221,0.000000
154.670013,29.642334,-90.741142,0.011236,0.009840,0.249926,131.855682,6.717049,2.499259,-90.741142,0.250923,0.000000
155.090012,29.828896,-90.741142,0.011266,0.009865,0.250576,132.685547,6.759324,2.505763,-90.741142,0.251617,0.000000
155.510010,30.281700,-90.785622,0.011305,0.009894,0.251313,134.699722,6.861931,2.513134,-90.785622,0.252319,0.000000
155.930008,30.668594,-90.741142,0.011335,0.009926,0.252129,136.420715,6.949603,2.521285,-90.741142,0.253022,0.000000
156.350006,30.752747,-90.696663,0.011357,0.009952,0.252770,136.795044,6.968672,2.527702,-90.696663,0.253724,0.000000
156.770004,30.835419,-90.785622,0.011382,0.009978,0.253447,137.162796,6.987406,2.534468,-90.785622,0.254418,0.000000
157.190002,31.266251,-90.785622,0.011404,0.010006,0.254141,139.079224,7.085034,2.541406,-90.785622,0.255120,0.000000
157.610001,31.242790,-90.741142,0.011434,0.010026,0.254661,138.974869,7.079718,2.546608,-90.741142,0.255823,0.000000
158.030014,31.794273,-90.741142,0.011477,0.010060,0.255528,141.427994,7.204685,2.555281,-90.741142,0.256517,0.000000
158.450012,32.197556,-90.830101,0.011507,0.010089,0.256265,143.221878,7.296071,2.562652,-90.830101,0.257219,0.000000
158.870010,32.512207,-90.785622,0.011533,0.010119,0.257011,144.621521,7.367372,2.570110,-90.785622,0.257922,0.000000
159.290009,32.419861,-90.919067,0.011542,0.010141,0.257575,144.210739,7.346445,2.575748,-90.919067,0.258624,0.000000
159.710007,33.126625,-90.963547,0.011572,0.010173,0.258390,147.354584,7.506601,2.583899,-90.963547,0.259318,0.000000
160.130005,33.063690,-90.874580,0.011602,0.010198,0.259032,147.074646,7.492340,2.590316,-90.874580,0.260020,0.000000
160.550003,33.360100,-90.874580,0.011624,0.010223,0.259665,148.393143,7.559506,2.596648,-90.874580,0.260723,0.000000
160.970001,32.700630,-90.874580,0.011641,0.010223,0.259674,145.459671,7.410069,2.596735,-90.874580,0.259916,0.000000
161.390015,32.098877,-91.008026,0.011650,0.010217,0.259517,142.782928,7.273709,2.595174,-91.008026,0.259318,0.000000
161.810013,31.631546,-90.919067,0.011663,0.010192,0.258884,140.704147,7.167811,2.588842,-90.919067,0.258615,0.000000
162.230011,31.298645,-90.874580,0.011663,0.010172,0.258364,139.223328,7.092375,2.583639,-90.874580,0.257913,0.000000
162.650009,31.108734,-90.919067,0.011632,0.010139,0.257531,138.378555,7.049340,2.575315,-90.919067,0.257219,0.000000
163.070007,30.907654,-91.008026,0.011637,0.010114,0.256898,137.484116,7.003774,2.568982,-91.008026,0.256517,0.000000
163.490005,30.717743,-91.052505,0.011676,0.010089,0.256256,136.639343,6.960740,2.562565,-91.052505,0.255814,0.000000
163.910004,30.557251,-91.008026,0.011667,0.010064,0.255623,135.925446,6.924372,2.556235,-91.008026,0.255112,0.000000
164.330002,30.426552,-91.008026,0.011671,0.010039,0.254999,135.344055,6.894755,2.549992,-91.008026,0.254418,0.000000
164.750015,30.248184,-91.008026,0.011667,0.010007,0.254175,134.550644,6.854336,2.541752,-91.008026,0.253716,0.000000
165.170013,30.050827,-90.963547,0.011663,0.009981,0.253525,133.672760,6.809615,2.535248,-90.963547,0.253013,0.000000
165.590012,29.672127,-91.096985,0.011658,0.009958,0.252926,131.988205,6.723800,2.529264,-91.096985,0.252311,0.000000
166.010010,29.169044,-91.096985,0.011676,0.009935,0.252354,129.750397,6.609800,2.523541,-91.096985,0.251617,0.000000
166.430008,28.346107,-91.052505,0.011667,0.009908,0.251669,126.089783,6.423319,2.516690,-91.052505,0.250914,0.000000
166.850006,27.050995,-91.052505,0.011671,0.009876,0.250854,120.328835,6.129843,2.508538,-91.052505,0.250212,0.000000
167.270004,25.832222,-91.008026,0.011658,0.009851,0.250221,114.907463,5.853665,2.502207,-91.008026,0.249518,0.000000
167.690002,24.261925,-91.141472,0.011637,0.009825,0.249544,107.922432,5.497831,2.495442,-91.141472,0.248816,0.000000
168.110001,23.168640,-91.141472,0.011645,0.009809,0.249137,103.059258,5.250089,2.491365,-91.141472,0.248113,0.000000
168.530014,21.384972,-91.008026,0.011632,0.009780,0.248408,95.125107,4.845904,2.484082,-91.008026,0.247411,0.000000
168.950012,19.074402,-91.096985,0.011632,0.009743,0.247480,84.847176,4.322321,2.474803,-91.096985,0.246717,0.000000
169.370010,17.693649,-91.185951,0.011607,0.009721,0.246917,78.705284,4.009439,2.469165,-91.185951,0.246015,0.000000
169.790009,15.759918,-91.185951,0.011576,0.009688,0.246067,70.103615,3.571249,2.460666,-91.185951,0.245312,0.000000
170.210007,14.522148,-91.230431,0.011563,0.009665,0.245494,64.597740,3.290766,2.454943,-91.230431,0.244618,0.000000
170.630005,12.830086,-91.185951,0.011538,0.009634,0.244705,57.071072,2.907339,2.447052,-91.185951,0.243916,0.000000
171.050003,11.452682,-91.141472,0.011520,0.009611,0.244107,50.944077,2.595215,2.441068,-91.141472,0.243214,0.000000
171.470001,10.219757,-91.185951,0.011503,0.009583,0.243404,45.459751,2.315830,2.434043,-91.185951,0.242511,0.000000
171.890015,8.858368,-91.274910,0.011507,0.009556,0.242719,39.403988,2.007335,2.427193,-91.274910,0.241817,0.000000
172.310013,7.682785,-91.185951,0.011447,0.009528,0.241999,34.174736,1.740944,2.419994,-91.185951,0.241115,0.000000
172.730011,6.224571,-91.274910,0.011438,0.009495,0.241176,27.688276,1.410508,2.411756,-91.274910,0.240412,0.000000
173.150009,5.764320,-91.230431,0.011417,0.009476,0.240681,25.640978,1.306214,2.406811,-91.230431,0.239710,0.000000
173.570007,4.497513,-91.230431,0.011391,0.009447,0.239953,20.005936,1.019151,2.399527,-91.230431,0.239016,0.000000
173.990005,3.891289,-91.274910,0.011369,0.009423,0.239337,17.309317,0.881779,2.393371,-91.274910,0.238314,0.000000
174.410004,2.872475,-91.274910,0.011348,0.009394,0.238608,12.777406,0.650912,2.386085,-91.274910,0.237611,0.000000
174.830002,2.116936,-91.319389,0.011318,0.009364,0.237845,9.416600,0.479704,2.378454,-91.319389,0.236917,0.000000
175.250015,1.613113,-91.274910,0.011283,0.009340,0.237247,7.175487,0.365537,2.372471,-91.274910,0.236215,0.000000
175.670013,1.025513,-91.274910,0.011262,0.009307,0.236397,4.561708,0.232385,2.363971,-91.274910,0.235512,0.000000
176.090012,0.754051,-91.319389,0.011227,0.009280,0.235712,3.354187,0.170870,2.357119,-91.319389,0.234810,0.000000
176.510010,0.660210,-91.319389,0.011188,0.009255,0.235088,2.936759,0.149606,2.350876,-91.319389,0.234116,0.000000
176.930008,0.535843,-91.408356,0.011171,0.009231,0.234463,2.383548,0.121424,2.344633,-91.408356,0.233414,0.000000
177.350006,0.401413,-91.274910,0.011124,0.009199,0.233648,1.785574,0.090961,2.336480,-91.274910,0.232711,0.000000
177.770004,0.386520,-91.319389,0.011098,0.009172,0.232972,1.719329,0.087587,2.329716,-91.319389,0.232018,0.000000
178.190002,0.293800,-91.408356,0.011050,0.009141,0.232191,1.306889,0.066576,2.321910,-91.408356,0.231315,0.000000
178.610016,0.357101,-91.452835,0.011003,0.009113,0.231471,1.588467,0.080920,2.314713,-91.452835,0.230613,0.000000
179.030014,0.326195,-91.408356,0.010973,0.009086,0.230795,1.450987,0.073917,2.307948,-91.408356,0.229910,0.000000
179.450012,0.292679,-91.408356,0.010938,0.009054,0.229980,1.301901,0.066322,2.299797,-91.408356,0.229216,0.000000
179.870010,0.292305,-91.497314,0.010900,0.009031,0.229381,1.300238,0.066237,2.293813,-91.497314,0.228514,0.000000
180.290009,0.220444,-91.408356,0.010882,0.009000,0.228601,0.980583,0.049953,2.286006,-91.408356,0.227812,0.000000
180.400009,0.280396,-91.408356,0.010878,0.009002,0.228661,1.247262,0.063539,2.286614,-91.408356,0.228583,0.000000