File: PDMS and AD/PDMS0024 Test 1-3_02142024_164013.csv
Time (sec),S:Load (lbs),S:HL1 (DIM),S:LVDT (in),S:Position (in),Ch:Position (mm),Ch:Load (N),Ch:Stress (MPa),Ch:Strain (mm/mm),Ch:HL1 (DIM),Set Point (),Cycles ()
0.110000,-0.004463,-224.717758,-0.000026,-0.000000,-0.000000,-0.019853,-0.001011,-0.000000,-224.717758,0.000182,0.000000
0.910000,-0.001488,-224.717758,0.000009,0.000156,0.003963,-0.006618,-0.000337,0.039632,-224.717758,0.004926,0.000000
1.710000,-0.000740,-224.806732,0.000254,0.000417,0.010589,-0.003292,-0.000168,0.105888,-224.806732,0.011595,0.000000
2.510000,0.007446,-224.762253,0.000522,0.000674,0.017119,0.033123,0.001687,0.171189,-224.762253,0.018255,0.000000
3.310000,-0.004463,-224.717758,0.000819,0.000938,0.023823,-0.019853,-0.001011,0.238225,-224.717758,0.024924,0.000000
4.110000,-0.000374,-224.806732,0.001078,0.001202,0.030526,-0.001663,-0.000085,0.305263,-224.806732,0.031584,0.000000
4.910000,0.005219,-224.851212,0.001380,0.001466,0.037247,0.023213,0.001183,0.372473,-224.851212,0.038244,0.000000
5.710000,0.006332,-224.851212,0.001660,0.001733,0.044020,0.028168,0.001435,0.440202,-224.851212,0.044913,0.000000
6.510000,-0.010422,-224.851212,0.001906,0.001995,0.050672,-0.046358,-0.002362,0.506720,-224.851212,0.051574,0.000000
7.310000,-0.028297,-224.895691,0.002177,0.002250,0.057159,-0.125873,-0.006412,0.571587,-224.895691,0.058243,0.000000
8.110001,-0.027184,-224.895691,0.002453,0.002514,0.063862,-0.120918,-0.006160,0.638623,-224.895691,0.064903,0.000000
8.910001,-0.030159,-224.940170,0.002703,0.002778,0.070549,-0.134154,-0.006834,0.705487,-224.940170,0.071563,0.000000
9.710000,-0.004097,-224.984650,0.002992,0.003039,0.077183,-0.018224,-0.000928,0.771831,-224.984650,0.078232,0.000000
10.510000,-0.025696,-224.984650,0.003281,0.003299,0.083800,-0.114301,-0.005823,0.837998,-224.984650,0.084893,0.000000
11.310000,-0.014519,-224.984650,0.003510,0.003561,0.090460,-0.064583,-0.003290,0.904603,-224.984650,0.091562,0.000000
12.110001,0.002609,-224.984650,0.003833,0.003829,0.097259,0.011607,0.000591,0.972593,-224.984650,0.098222,0.000000
12.910001,0.003349,-225.029129,0.004092,0.004091,0.103920,0.014898,0.000759,1.039196,-225.029129,0.104891,0.000000
13.710001,0.005585,-225.029129,0.004355,0.004353,0.110554,0.024842,0.001266,1.105538,-225.029129,0.111551,0.000000
14.510000,0.015266,-225.073608,0.004600,0.004610,0.117101,0.067908,0.003459,1.171014,-225.073608,0.118211,0.000000
15.310000,0.005219,-225.073608,0.004919,0.004872,0.123744,0.023213,0.001183,1.237443,-225.073608,0.124880,0.000000
16.110001,-0.001862,-225.118088,0.005165,0.005134,0.130396,-0.008281,-0.000422,1.303959,-225.118088,0.131541,0.000000
16.910002,0.002235,-225.118088,0.005476,0.005401,0.137178,0.009944,0.000507,1.371776,-225.118088,0.138210,0.000000
17.710001,0.027184,-225.118088,0.005743,0.005665,0.143899,0.120918,0.006160,1.438987,-225.118088,0.144870,0.000000
18.510000,0.011169,-225.118088,0.006006,0.005929,0.150585,0.049684,0.002531,1.505851,-225.118088,0.151539,0.000000
19.310001,-0.002235,-225.251541,0.006252,0.006192,0.157280,-0.009944,-0.000507,1.572800,-225.251541,0.158199,0.000000
20.110001,-0.007820,-225.162567,0.006523,0.006446,0.163732,-0.034786,-0.001772,1.637321,-225.162567,0.164859,0.000000
20.910002,0.000374,-225.251541,0.006817,0.006712,0.170479,0.001663,0.000085,1.704790,-225.251541,0.171528,0.000000
21.710001,-0.008194,-225.251541,0.007080,0.006975,0.177174,-0.036449,-0.001857,1.771742,-225.251541,0.178189,0.000000
22.510000,-0.001488,-225.296021,0.007381,0.007237,0.183808,-0.006618,-0.000337,1.838083,-225.296021,0.184858,0.000000
23.310001,-0.004837,-225.340500,0.007627,0.007496,0.190391,-0.021516,-0.001096,1.903906,-225.340500,0.191518,0.000000
24.110001,0.006332,-225.340500,0.007920,0.007760,0.197112,0.028168,0.001435,1.971117,-225.340500,0.198178,0.000000
24.910002,0.035378,-225.340500,0.008183,0.008027,0.203885,0.157367,0.008017,2.038847,-225.340500,0.204847,0.000000
25.710001,0.104263,-225.384979,0.008464,0.008289,0.210536,0.463786,0.023626,2.105363,-225.384979,0.211507,0.000000
26.510002,0.449455,-225.429459,0.008709,-0.000000,-0.000000,1.999277,0.101848,-0.000000,-225.429459,0.000199,0.000000
27.310001,0.380936,-225.429459,0.008727,-0.000000,-0.000009,1.694486,0.086321,-0.000087,-225.429459,0.000754,0.000000
28.110001,0.501213,-225.473938,0.008718,0.000040,0.001006,2.229507,0.113577,0.010058,-225.473938,0.002090,0.000000
28.910002,0.612556,-225.473938,0.008813,0.000098,0.002489,2.724787,0.138807,0.024889,-225.473938,0.003426,0.000000
29.710001,0.681816,-225.473938,0.008847,0.000149,0.003781,3.032870,0.154502,0.037811,-225.473938,0.004752,0.000000
30.510002,0.793900,-225.518417,0.008912,0.000206,0.005221,3.531441,0.179900,0.052207,-225.518417,0.006088,0.000000
31.310001,0.873215,-225.518417,0.008977,0.000256,0.006495,3.884253,0.197873,0.064954,-225.518417,0.007423,0.000000
32.110001,0.987907,-225.562897,0.009015,0.000315,0.007996,4.394432,0.223863,0.079958,-225.562897,0.008759,0.000000
32.910000,1.051956,-225.607391,0.009046,0.000363,0.009210,4.679335,0.238377,0.092098,-225.607391,0.010086,0.000000
33.710003,1.137970,-225.607391,0.009127,0.000408,0.010372,5.061943,0.257868,0.103719,-225.607391,0.011421,0.000000
34.510002,1.245956,-225.651871,0.009171,0.000469,0.011916,5.542291,0.282338,0.119156,-225.651871,0.012757,0.000000
35.310001,1.346130,-225.607391,0.009231,0.000520,0.013208,5.987887,0.305038,0.132078,-225.607391,0.014092,0.000000
36.110001,1.432518,-225.740829,0.009257,0.000567,0.014405,6.372159,0.324613,0.144046,-225.740829,0.015419,0.000000
36.910000,1.498055,-225.696350,0.009339,0.000619,0.015723,6.663679,0.339464,0.157226,-225.696350,0.016755,0.000000
37.710003,1.633598,-225.740829,0.009360,0.000671,0.017032,7.266608,0.370179,0.170322,-225.740829,0.018090,0.000000
38.510002,1.730415,-225.785309,0.009451,0.000724,0.018394,7.697272,0.392118,0.183938,-225.785309,0.019426,0.000000
39.310001,1.846970,-225.740829,0.009481,0.000778,0.019773,8.215731,0.418529,0.197727,-225.740829,0.020761,0.000000
40.110001,1.991074,-225.829788,0.009567,0.000838,0.021273,8.856738,0.451184,0.212730,-225.829788,0.022088,0.000000
40.910004,2.059219,-225.785309,0.009576,0.000886,0.022496,9.159865,0.466626,0.224957,-225.785309,0.023424,0.000000
41.710003,2.227905,-225.874268,0.009649,0.000939,0.023857,9.910217,0.504851,0.238573,-225.874268,0.024759,0.000000
42.510002,2.316154,-225.829788,0.009731,0.000989,0.025132,10.302770,0.524848,0.251321,-225.829788,0.026095,0.000000
43.310001,2.424149,-225.874268,0.009740,0.001042,0.026459,10.783152,0.549320,0.264591,-225.874268,0.027422,0.000000
44.110001,2.544052,-225.874268,0.009813,0.001098,0.027881,11.316509,0.576490,0.278812,-225.874268,0.028757,0.000000
44.910004,2.676239,-225.918747,0.009869,0.001151,0.029225,11.904506,0.606444,0.292254,-225.918747,0.030093,0.000000
45.710003,2.789070,-225.918747,0.009942,0.001203,0.030544,12.406404,0.632012,0.305435,-225.918747,0.031428,0.000000
46.510002,2.857964,-225.963226,0.009981,0.001255,0.031888,12.712857,0.647624,0.318877,-225.963226,0.032755,0.000000
47.310001,2.988663,-226.007706,0.010033,0.001305,0.033137,13.294236,0.677241,0.331366,-226.007706,0.034091,0.000000
48.110001,3.098885,-226.007706,0.010085,0.001359,0.034516,13.784527,0.702217,0.345156,-226.007706,0.035426,0.000000
48.910004,3.240013,-226.052200,0.010123,0.001412,0.035860,14.412298,0.734197,0.358598,-226.052200,0.036762,0.000000
49.710003,3.337204,-226.052200,0.010171,0.001460,0.037091,14.844625,0.756221,0.370912,-226.052200,0.038089,0.000000
50.510002,3.394547,-226.141159,0.010223,0.001513,0.038435,15.099697,0.769215,0.384354,-226.141159,0.039424,0.000000
51.310001,3.559135,-226.096680,0.010296,0.001564,0.039728,15.831825,0.806512,0.397276,-226.096680,0.040760,0.000000
52.110001,3.651489,-226.141159,0.010352,0.001622,0.041211,16.242636,0.827439,0.412105,-226.141159,0.042095,0.000000
52.910004,3.746437,-226.141159,0.010391,0.001671,0.042451,16.664984,0.848955,0.424506,-226.141159,0.043422,0.000000
53.710003,3.895760,-226.230118,0.010468,0.001733,0.044012,17.329205,0.882792,0.440117,-226.230118,0.044758,0.000000
54.510002,3.937469,-226.185638,0.010516,0.001774,0.045061,17.514738,0.892243,0.450611,-226.185638,0.046093,0.000000
55.310001,4.065567,-226.185638,0.010546,0.001825,0.046362,18.084545,0.921271,0.463617,-226.185638,0.047429,0.000000
56.110004,4.180252,-226.230118,0.010593,0.001884,0.047853,18.594690,0.947259,0.478534,-226.230118,0.048755,0.000000
56.910004,4.298668,-226.230118,0.010675,0.001933,0.049093,19.121429,0.974092,0.490935,-226.230118,0.050091,0.000000
57.710003,4.416336,-226.274597,0.010710,0.001988,0.050490,19.644844,1.000756,0.504897,-226.274597,0.051427,0.000000
58.510002,4.496025,-226.274597,0.010774,0.002036,0.051721,19.999319,1.018814,0.517213,-226.274597,0.052762,0.000000
59.310001,4.606621,-226.274597,0.010822,0.002087,0.053014,20.491272,1.043875,0.530135,-226.274597,0.054089,0.000000
60.110004,4.674019,-226.319077,0.010856,0.002143,0.054427,20.791075,1.059148,0.544270,-226.319077,0.055424,0.000000
60.910004,4.816643,-226.363556,0.010951,0.002193,0.055702,21.425497,1.091467,0.557019,-226.363556,0.056760,0.000000
61.710003,4.906754,-226.363556,0.010990,0.002252,0.057202,21.826330,1.111886,0.572021,-226.363556,0.058095,0.000000
62.510002,5.071342,-226.319077,0.011059,0.002302,0.058477,22.558458,1.149183,0.584770,-226.319077,0.059422,0.000000
63.310001,5.134644,-226.452515,0.011115,0.002354,0.059804,22.840034,1.163527,0.598038,-226.452515,0.060758,0.000000
64.110001,5.211723,-226.408035,0.011154,0.002406,0.061122,23.182903,1.180993,0.611221,-226.408035,0.062093,0.000000
64.910004,5.310036,-226.408035,0.011197,0.002458,0.062431,23.620218,1.203271,0.624315,-226.408035,0.063429,0.000000
65.710007,5.390465,-226.497009,0.011257,0.002513,0.063836,23.977985,1.221497,0.638364,-226.497009,0.064764,0.000000
66.510002,5.536804,-226.452515,0.011318,0.002568,0.065224,24.628935,1.254658,0.652240,-226.452515,0.066091,0.000000
67.310005,5.617241,-226.497009,0.011382,0.002622,0.066594,24.986736,1.272885,0.665943,-226.497009,0.067427,0.000000
68.110001,5.673843,-226.497009,0.011430,0.002676,0.067964,25.238516,1.285711,0.679644,-226.497009,0.068762,0.000000
68.910004,5.766190,-226.541489,0.011460,0.002725,0.069205,25.649292,1.306637,0.692045,-226.541489,0.070098,0.000000
69.710007,5.752785,-226.541489,0.011533,0.002777,0.070540,25.589664,1.303600,0.705400,-226.541489,0.071425,0.000000
70.510002,5.811249,-226.585968,0.011576,0.002825,0.071763,25.849726,1.316848,0.717629,-226.585968,0.072760,0.000000
71.310005,5.958702,-226.585968,0.011628,0.002878,0.073098,26.505630,1.350261,0.730984,-226.585968,0.074096,0.000000
72.110001,6.036903,-226.630447,0.011701,0.002934,0.074512,26.853487,1.367982,0.745119,-226.630447,0.075431,0.000000
72.910004,6.131859,-226.585968,0.011745,0.002986,0.075856,27.275869,1.389499,0.758561,-226.585968,0.076758,0.000000
73.710007,6.105789,-226.674927,0.011770,0.003037,0.077148,27.159906,1.383592,0.771483,-226.674927,0.078094,0.000000
74.510002,6.215271,-226.674927,0.011831,0.003088,0.078432,27.646906,1.408401,0.784317,-226.674927,0.079429,0.000000
75.310005,6.239471,-226.630447,0.011891,0.003146,0.079915,27.754555,1.413885,0.799148,-226.630447,0.080765,0.000000
76.110001,6.302406,-226.719406,0.011947,0.003192,0.081068,28.034504,1.428146,0.810681,-226.719406,0.082092,0.000000
76.910004,6.442421,-226.763885,0.012033,0.003254,0.082647,28.657320,1.459873,0.826466,-226.763885,0.083427,0.000000
77.710007,6.346718,-226.763885,0.012081,0.003296,0.083713,28.231611,1.438187,0.837132,-226.763885,0.084763,0.000000
78.510002,6.491196,-226.763885,0.012107,0.003348,0.085031,28.874281,1.470926,0.850314,-226.763885,0.086098,0.000000
79.310005,6.557106,-226.763885,0.012167,0.003406,0.086506,29.167465,1.485862,0.865057,-226.763885,0.087425,0.000000
80.110001,6.551521,-226.808365,0.012227,0.003450,0.087624,29.142622,1.484596,0.876245,-226.808365,0.088761,0.000000
80.910004,6.734734,-226.808365,0.012288,0.003511,0.089168,29.957592,1.526112,0.891681,-226.808365,0.090096,0.000000
81.710007,6.722816,-226.808365,0.012348,0.003562,0.090486,29.904581,1.523412,0.904862,-226.808365,0.091432,0.000000
82.510002,6.799149,-226.897339,0.012370,0.003614,0.091805,30.244123,1.540709,0.918045,-226.897339,0.092758,0.000000
83.310005,6.803993,-226.852844,0.012447,0.003668,0.093157,30.265673,1.541807,0.931572,-226.852844,0.094094,0.000000
84.110001,6.821121,-226.897339,0.012503,0.003716,0.094380,30.341862,1.545688,0.943801,-226.897339,0.095430,0.000000
84.910004,6.920547,-226.941818,0.012542,0.003771,0.095794,30.784132,1.568218,0.957936,-226.941818,0.096765,0.000000
85.710007,7.008423,-226.941818,0.012615,0.003828,0.097242,31.175022,1.588131,0.972419,-226.941818,0.098092,0.000000
86.510002,7.053856,-226.941818,0.012654,0.003879,0.098525,31.377119,1.598427,0.985254,-226.941818,0.099427,0.000000
87.310005,7.009544,-226.941818,0.012697,0.003929,0.099792,31.180010,1.588385,0.997916,-226.941818,0.100763,0.000000
88.110001,7.064651,-226.941818,0.012771,0.003978,0.101040,31.425138,1.600873,1.010404,-226.941818,0.102098,0.000000
88.910004,7.113808,-226.986298,0.012835,0.004037,0.102541,31.643797,1.612012,1.025408,-226.986298,0.103425,0.000000
89.710007,7.099281,-227.119736,0.012883,0.004086,0.103772,31.579180,1.608720,1.037722,-227.119736,0.104761,0.000000
90.510002,7.257172,-227.030777,0.012926,0.004145,0.105290,32.281513,1.644499,1.052897,-227.030777,0.106096,0.000000
91.310005,7.284355,-227.119736,0.012978,0.004194,0.106530,32.402431,1.650658,1.065298,-227.119736,0.107432,0.000000
92.110001,7.219185,-227.119736,0.013029,0.004237,0.107623,32.112537,1.635891,1.076227,-227.119736,0.108767,0.000000
92.910004,7.332390,-227.119736,0.013107,0.004297,0.109132,32.616100,1.661543,1.091316,-227.119736,0.110094,0.000000
93.710007,7.320473,-227.164215,0.013146,0.004348,0.110432,32.563087,1.658843,1.104324,-227.164215,0.111430,0.000000
94.510002,7.442238,-227.253174,0.013193,0.004405,0.111889,33.104729,1.686435,1.118894,-227.253174,0.112765,0.000000
95.310005,7.446335,-227.208694,0.013254,0.004456,0.113182,33.122952,1.687364,1.131816,-227.208694,0.114101,0.000000
96.110008,7.516342,-227.297653,0.013323,0.004514,0.114647,33.434361,1.703227,1.146471,-227.297653,0.115428,0.000000
96.910004,7.427345,-227.208694,0.013366,0.004560,0.115818,33.038483,1.683061,1.158180,-227.208694,0.116763,0.000000
97.710007,7.514107,-227.297653,0.013409,0.004610,0.117101,33.424416,1.702721,1.171014,-227.297653,0.118099,0.000000
98.510002,7.507401,-227.297653,0.013495,0.004669,0.118584,33.394585,1.701201,1.185844,-227.297653,0.119434,0.000000
99.310005,7.610176,-227.386627,0.013521,0.004717,0.119807,33.851753,1.724491,1.198073,-227.386627,0.120761,0.000000
100.110008,7.580391,-227.342148,0.013581,0.004767,0.121082,33.719261,1.717741,1.210820,-227.342148,0.122097,0.000000
100.910004,7.552460,-227.342148,0.013646,0.004820,0.122418,33.595020,1.711412,1.224175,-227.342148,0.123432,0.000000
101.710007,7.693214,-227.342148,0.013672,0.004869,0.123684,34.221127,1.743307,1.236837,-227.342148,0.124768,0.000000
102.510002,7.599380,-227.431107,0.013745,0.004924,0.125063,33.803734,1.722044,1.250626,-227.431107,0.126095,0.000000
103.310005,7.657845,-227.386627,0.013780,0.004975,0.126363,34.063793,1.735292,1.263634,-227.386627,0.127430,0.000000
104.110008,7.778488,-227.431107,0.013862,0.005035,0.127898,34.600445,1.762631,1.278984,-227.431107,0.128766,0.000000
104.910004,7.697311,-227.520065,0.013887,0.005082,0.129078,34.239349,1.744236,1.290778,-227.520065,0.130101,0.000000
105.710007,7.817215,-227.520065,0.013956,0.005139,0.130526,34.772709,1.771406,1.305261,-227.520065,0.131428,0.000000
106.510002,7.772530,-227.609024,0.014012,0.005189,0.131792,34.573940,1.761280,1.317923,-227.609024,0.132764,0.000000
107.310005,7.795250,-227.564545,0.014051,0.005242,0.133136,34.675003,1.766429,1.331363,-227.564545,0.134099,0.000000
108.110008,7.875679,-227.520065,0.014120,0.005295,0.134489,35.032768,1.784654,1.344892,-227.520065,0.135435,0.000000
108.910004,7.922974,-227.653503,0.014172,0.005348,0.135851,35.243145,1.795372,1.358509,-227.653503,0.136762,0.000000
109.710007,7.950897,-227.564545,0.014202,0.005402,0.137212,35.367355,1.801699,1.372125,-227.564545,0.138097,0.000000
110.510002,7.872330,-227.697983,0.014288,0.005454,0.138522,35.017872,1.783895,1.385219,-227.697983,0.139433,0.000000
111.310005,7.978081,-227.653503,0.014331,0.005506,0.139849,35.488277,1.807859,1.398488,-227.653503,0.140768,0.000000
112.110008,7.949036,-227.653503,0.014400,0.005560,0.141236,35.359077,1.801277,1.412364,-227.653503,0.142095,0.000000
112.910004,7.971748,-227.697983,0.014448,0.005611,0.142520,35.460106,1.806424,1.425198,-227.697983,0.143430,0.000000
113.710007,8.017929,-227.742462,0.014491,0.005659,0.143743,35.665531,1.816889,1.437425,-227.742462,0.144766,0.000000
114.510002,7.989250,-227.786957,0.014521,0.005712,0.145087,35.537960,1.810390,1.450868,-227.786957,0.146101,0.000000
115.310005,8.024628,-227.786957,0.014590,0.005763,0.146370,35.695328,1.818407,1.463702,-227.786957,0.147428,0.000000
116.110008,8.038780,-227.786957,0.014642,0.005820,0.147819,35.758282,1.821614,1.478185,-227.786957,0.148764,0.000000
116.910004,8.011971,-227.786957,0.014707,0.005868,0.149041,35.639027,1.815539,1.490414,-227.786957,0.150099,0.000000
117.710007,8.114372,-227.786957,0.014793,0.005931,0.150654,36.094532,1.838743,1.506543,-227.786957,0.151435,0.000000
118.510002,8.007874,-227.831436,0.014806,0.005972,0.151695,35.620800,1.814610,1.516950,-227.831436,0.152770,0.000000
119.310005,8.197784,-227.831436,0.014853,0.006031,0.153187,36.465565,1.857645,1.531866,-227.831436,0.154097,0.000000
120.110008,8.054787,-227.875916,0.014922,0.006081,0.154470,35.829479,1.825241,1.544701,-227.875916,0.155433,0.000000
120.910004,8.106178,-227.875916,0.014974,0.006131,0.155736,36.058083,1.836886,1.557363,-227.875916,0.156768,0.000000
121.710007,8.172829,-227.964874,0.015017,0.006189,0.157193,36.354557,1.851990,1.571933,-227.964874,0.158104,0.000000
122.510002,8.291245,-227.964874,0.015073,0.006242,0.158555,36.881298,1.878823,1.585547,-227.964874,0.159431,0.000000
123.310005,8.192192,-228.009354,0.015133,0.006287,0.159691,36.440689,1.856377,1.596910,-228.009354,0.160766,0.000000
124.110008,8.204109,-227.964874,0.015177,0.006345,0.161156,36.493702,1.859078,1.611565,-227.964874,0.162102,0.000000
124.910004,8.287521,-228.009354,0.015233,0.006396,0.162449,36.864735,1.877979,1.624486,-228.009354,0.163437,0.000000
125.710007,8.219009,-228.009354,0.015297,0.006452,0.163888,36.559978,1.862454,1.638882,-228.009354,0.164764,0.000000
126.510010,8.287148,-228.009354,0.015345,0.006502,0.165154,36.863071,1.877895,1.651545,-228.009354,0.166100,0.000000
127.310005,8.228317,-228.053833,0.015396,0.006552,0.166412,36.601383,1.864563,1.664118,-228.053833,0.167435,0.000000
128.110001,8.269279,-228.053833,0.015440,0.006607,0.167808,36.783592,1.873846,1.678080,-228.053833,0.168771,0.000000
128.910004,8.351570,-228.009354,0.015496,0.006661,0.169187,37.149639,1.892493,1.691871,-228.009354,0.170098,0.000000
129.710007,8.304283,-228.053833,0.015565,0.006711,0.170453,36.939297,1.881777,1.704531,-228.053833,0.171433,0.000000
130.510010,8.380615,-228.098312,0.015608,0.006766,0.171867,37.278839,1.899075,1.718668,-228.098312,0.172769,0.000000
131.310013,8.430145,-228.142792,0.015677,0.006821,0.173246,37.499161,1.910298,1.732456,-228.142792,0.174104,0.000000
132.110001,8.406685,-228.187286,0.015711,0.006873,0.174564,37.394802,1.904982,1.745637,-228.187286,0.175431,0.000000
132.910004,8.453972,-228.276245,0.015780,0.006923,0.175856,37.605145,1.915697,1.758559,-228.276245,0.176767,0.000000
133.710007,8.396629,-228.187286,0.015832,0.006975,0.177157,37.350071,1.902703,1.771567,-228.187286,0.178102,0.000000
134.510010,8.363113,-228.187286,0.015884,0.007022,0.178371,37.200985,1.895109,1.783709,-228.187286,0.179438,0.000000
135.310013,8.513550,-228.187286,0.015948,0.007081,0.179845,37.870159,1.929198,1.798452,-228.187286,0.180764,0.000000
136.110001,8.518394,-228.320724,0.015991,0.007135,0.181224,37.891712,1.930296,1.812242,-228.320724,0.182100,0.000000
136.910004,8.541855,-228.276245,0.016026,0.007185,0.182508,37.996067,1.935612,1.825076,-228.276245,0.183435,0.000000
137.710007,8.453598,-228.276245,0.016082,0.007233,0.183722,37.603481,1.915613,1.837216,-228.276245,0.184771,0.000000
138.510010,8.530685,-228.320724,0.016142,0.007288,0.185118,37.946384,1.933081,1.851179,-228.320724,0.186098,0.000000
139.310013,8.486366,-228.320724,0.016224,0.007344,0.186540,37.749241,1.923038,1.865402,-228.320724,0.187433,0.000000
140.110001,8.524727,-228.365204,0.016246,0.007392,0.187746,37.919880,1.931731,1.877455,-228.365204,0.188769,0.000000
140.910004,8.592865,-228.365204,0.016310,0.007452,0.189281,38.222973,1.947171,1.892807,-228.365204,0.190104,0.000000
141.710007,8.528450,-228.498642,0.016345,0.007498,0.190460,37.936440,1.932574,1.904601,-228.498642,0.191431,0.000000
142.510010,8.564568,-228.454163,0.016397,0.007545,0.191639,38.097099,1.940759,1.916394,-228.454163,0.192767,0.000000
143.310013,8.577599,-228.454163,0.016461,0.007605,0.193157,38.155064,1.943712,1.931572,-228.454163,0.194102,0.000000
144.110001,8.570152,-228.498642,0.016513,0.007650,0.194310,38.121941,1.942024,1.943105,-228.498642,0.195438,0.000000
144.910004,8.698624,-228.498642,0.016548,0.007709,0.195802,38.693409,1.971136,1.958021,-228.498642,0.196765,0.000000
145.710007,8.713516,-228.498642,0.016642,0.007761,0.197138,38.759655,1.974511,1.971378,-228.498642,0.198100,0.000000
146.510010,8.738464,-228.543121,0.016703,0.007813,0.198438,38.870632,1.980164,1.984384,-228.543121,0.199436,0.000000
147.310013,8.656174,-228.543121,0.016729,0.007866,0.199800,38.504585,1.961517,1.998001,-228.543121,0.200771,0.000000
148.110001,8.766022,-228.587601,0.016789,0.007919,0.201153,38.993214,1.986409,2.011530,-228.587601,0.202107,0.000000
148.910004,8.763412,-228.676575,0.016836,0.007973,0.202523,38.981606,1.985818,2.025231,-228.676575,0.203434,0.000000
149.710007,8.826721,-228.721054,0.016910,0.008027,0.203893,39.263218,2.000164,2.038934,-228.721054,0.204769,0.000000
150.510010,8.830444,-228.721054,0.016957,0.008079,0.205194,39.279778,2.001007,2.051943,-228.721054,0.206105,0.000000
151.310013,8.821136,-228.721054,0.016996,0.008129,0.206486,39.238377,1.998898,2.064865,-228.721054,0.207440,0.000000
152.110001,8.783897,-228.632095,0.017052,0.008179,0.207752,39.072727,1.990460,2.077525,-228.632095,0.208767,0.000000
152.910004,8.806236,-228.810013,0.017117,0.008237,0.209210,39.172096,1.995522,2.092095,-228.810013,0.210103,0.000000
153.710007,8.837517,-228.721054,0.017134,0.008286,0.210467,39.311237,2.002610,2.104668,-228.721054,0.211438,0.000000
154.510010,8.953697,-228.854492,0.017207,0.008345,0.211967,39.828033,2.028937,2.119672,-228.854492,0.212774,0.000000
155.310013,8.855766,-228.810013,0.017259,0.008391,0.213121,39.392414,2.006745,2.131206,-228.810013,0.214101,0.000000
156.110001,8.855766,-228.810013,0.017293,0.008437,0.214291,39.392414,2.006745,2.142915,-228.810013,0.215436,0.000000
156.910004,8.972687,-228.854492,0.017371,0.008498,0.215844,39.912502,2.033240,2.158437,-228.854492,0.216772,0.000000
157.710007,8.920181,-228.810013,0.017423,0.008547,0.217092,39.678947,2.021342,2.170925,-228.810013,0.218107,0.000000
158.510010,9.015884,-228.898972,0.017470,0.008604,0.218532,40.104656,2.043029,2.185321,-228.898972,0.219434,0.000000
159.310013,9.093712,-228.810013,0.017522,0.008658,0.219911,40.450851,2.060664,2.199111,-228.810013,0.220770,0.000000
160.110001,9.092590,-228.898972,0.017591,0.008713,0.221299,40.445862,2.060410,2.212986,-228.898972,0.222105,0.000000
160.910004,8.971947,-228.943451,0.017651,0.008758,0.222461,39.909214,2.033072,2.224606,-228.943451,0.223441,0.000000
161.710007,9.138397,-228.898972,0.017694,0.008810,0.223779,40.649620,2.070790,2.237789,-228.898972,0.224767,0.000000
162.510010,9.058708,-228.943451,0.017759,0.008867,0.225227,40.295147,2.052733,2.252272,-228.943451,0.226103,0.000000
163.310013,9.168930,-228.943451,0.017811,0.008919,0.226537,40.785439,2.077709,2.265366,-228.943451,0.227438,0.000000
164.110001,9.202812,-228.987930,0.017858,0.008972,0.227881,40.936153,2.085387,2.278808,-228.987930,0.228774,0.000000
164.910004,9.050514,-228.987930,0.017901,0.009017,0.229043,40.258698,2.050876,2.290429,-228.987930,0.230101,0.000000
165.710007,9.176376,-229.032410,0.017970,0.009069,0.230344,40.818562,2.079396,2.303438,-229.032410,0.231436,0.000000
166.510010,9.147331,-229.076904,0.018005,0.009123,0.231731,40.689362,2.072815,2.317313,-229.076904,0.232772,0.000000
167.310013,9.193130,-229.121384,0.018061,0.009176,0.233067,40.893085,2.083193,2.330668,-229.121384,0.234107,0.000000
168.110001,9.253456,-229.121384,0.018126,0.009236,0.234585,41.161430,2.096863,2.345846,-229.121384,0.235434,0.000000
168.910004,9.232231,-229.121384,0.018173,0.009283,0.235781,41.067017,2.092053,2.357812,-229.121384,0.236770,0.000000
169.710007,9.342827,-229.076904,0.018225,0.009338,0.237177,41.558968,2.117115,2.371774,-229.076904,0.238105,0.000000
170.510010,9.308571,-229.165863,0.018285,0.009391,0.238522,41.406590,2.109352,2.385216,-229.165863,0.239441,0.000000
171.310013,9.310806,-229.254822,0.018354,0.009441,0.239797,41.416534,2.109859,2.397966,-229.254822,0.240768,0.000000
172.110001,9.331657,-229.121384,0.018393,0.009495,0.241175,41.509285,2.114584,2.411754,-229.121384,0.242103,0.000000
172.910004,9.421394,-229.299301,0.018432,0.009550,0.242563,41.908455,2.134918,2.425629,-229.299301,0.243439,0.000000
173.710007,9.399055,-229.210342,0.018492,0.009601,0.243855,41.809086,2.129856,2.438551,-229.210342,0.244774,0.000000
174.510010,9.398682,-229.254822,0.018544,0.009654,0.245217,41.807423,2.129772,2.452167,-229.254822,0.246110,0.000000
175.310013,9.456398,-229.254822,0.018600,0.009704,0.246483,42.064159,2.142850,2.464828,-229.254822,0.247437,0.000000
176.110016,9.447464,-229.343781,0.018652,0.009760,0.247905,42.024418,2.140826,2.479051,-229.343781,0.248772,0.000000
176.910004,9.468689,-229.343781,0.018725,0.009810,0.249171,42.118832,2.145636,2.491712,-229.343781,0.250108,0.000000
177.710007,9.616150,-229.343781,0.018746,0.009862,0.250498,42.774773,2.179051,2.504982,-229.343781,0.251443,0.000000
178.510010,9.519333,-229.388260,0.018820,0.009911,0.251747,42.344109,2.157112,2.517468,-229.388260,0.252770,0.000000
179.310013,9.535339,-229.388260,0.018876,0.009966,0.253135,42.415306,2.160739,2.531345,-229.388260,0.254106,0.000000
180.110016,9.550613,-229.521713,0.018919,0.010020,0.254496,42.483250,2.164200,2.544960,-229.521713,0.255441,0.000000
180.910004,9.511887,-229.477234,0.018979,0.010067,0.255693,42.310986,2.155424,2.556927,-229.477234,0.256777,0.000000
181.710007,9.665672,-229.521713,0.019027,0.010130,0.257314,42.995056,2.190273,2.573144,-229.521713,0.258104,0.000000
182.510010,9.591568,-229.477234,0.019083,0.010175,0.258451,42.665424,2.173481,2.584506,-229.477234,0.259439,0.000000
183.310013,9.826538,-229.521713,0.019143,0.010232,0.259881,43.710625,2.226725,2.598815,-229.521713,0.260775,0.000000
184.110016,9.649292,-229.566193,0.019182,0.010281,0.261148,42.922195,2.186561,2.611475,-229.566193,0.262110,0.000000
184.910004,9.576675,-229.566193,0.019216,0.010326,0.262292,42.599178,2.170106,2.622923,-229.566193,0.263437,0.000000
185.710007,9.697327,-229.610672,0.019307,0.010386,0.263801,43.135864,2.197446,2.638013,-229.610672,0.264773,0.000000
186.510010,9.818344,-229.610672,0.019337,0.010438,0.265120,43.674175,2.224869,2.651196,-229.610672,0.266108,0.000000
187.310013,9.673492,-229.655151,0.019385,0.010482,0.266238,43.029842,2.192045,2.662382,-229.655151,0.267444,0.000000
188.110016,9.777756,-229.655151,0.019454,0.010542,0.267756,43.493629,2.215671,2.677560,-229.655151,0.268770,0.000000
188.910004,9.825050,-229.744110,0.019501,0.010592,0.269031,43.704006,2.226388,2.690307,-229.744110,0.270106,0.000000
189.710007,9.852608,-229.744110,0.019557,0.010650,0.270522,43.826588,2.232633,2.705223,-229.744110,0.271441,0.000000
190.510010,9.924843,-229.699631,0.019622,0.010703,0.271849,44.147907,2.249002,2.718491,-229.699631,0.272777,0.000000
191.310013,9.904739,-229.744110,0.019669,0.010752,0.273098,44.058479,2.244446,2.730980,-229.744110,0.274104,0.000000
192.110016,10.045868,-229.744110,0.019730,0.010808,0.274520,44.686253,2.276426,2.745201,-229.744110,0.275439,0.000000
192.910004,10.034325,-229.788589,0.019751,0.010858,0.275804,44.634907,2.273810,2.758038,-229.788589,0.276775,0.000000
193.710007,10.019798,-229.788589,0.019824,0.010912,0.277157,44.570290,2.270519,2.771565,-229.788589,0.278110,0.000000
194.510010,10.063370,-229.833069,0.019885,0.010964,0.278475,44.764103,2.280392,2.784748,-229.833069,0.279437,0.000000
195.310013,10.128159,-229.877548,0.019928,0.011019,0.279888,45.052299,2.295074,2.798884,-229.877548,0.280773,0.000000
196.110016,10.109169,-229.877548,0.019988,0.011070,0.281181,44.967831,2.290771,2.811806,-229.877548,0.282108,0.000000
196.910004,10.178429,-229.877548,0.020027,0.011121,0.282481,45.275913,2.306465,2.824813,-229.877548,0.283444,0.000000
197.710007,10.089806,-229.966522,0.020087,0.011173,0.283791,44.881699,2.286383,2.837909,-229.966522,0.284771,0.000000
198.510010,10.117737,-229.966522,0.020143,0.011223,0.285074,45.005939,2.292712,2.850743,-229.966522,0.286106,0.000000
199.310013,10.252907,-229.966522,0.020182,0.011277,0.286445,45.607208,2.323342,2.864446,-229.966522,0.287442,0.000000
200.110016,10.296844,-229.966522,0.020243,0.011333,0.287849,45.802650,2.333298,2.878494,-229.966522,0.288777,0.000000
200.910004,10.325890,-229.966522,0.020320,0.011385,0.289168,45.931850,2.339880,2.891677,-229.966522,0.290113,0.000000
201.710007,10.176567,-230.011002,0.020346,0.011432,0.290382,45.267632,2.306043,2.903819,-230.011002,0.291440,0.000000
202.510010,10.325516,-230.055481,0.020419,0.011485,0.291709,45.930187,2.339795,2.917087,-230.055481,0.292775,0.000000
203.310013,10.322540,-230.099960,0.020471,0.011545,0.293235,45.916954,2.339121,2.932349,-230.099960,0.294111,0.000000
204.110016,10.341904,-230.099960,0.020514,0.011588,0.294328,46.003086,2.343509,2.943276,-230.099960,0.295446,0.000000
204.910004,10.457710,-230.099960,0.020566,0.011651,0.295932,46.518219,2.369751,2.959320,-230.099960,0.296773,0.000000
205.710007,10.414139,-230.144440,0.020605,0.011698,0.297129,46.324402,2.359878,2.971288,-230.144440,0.298109,0.000000
206.510010,10.562347,-230.188919,0.020665,0.011750,0.298438,46.983669,2.393462,2.984384,-230.188919,0.299444,0.000000
207.310013,10.578728,-230.233398,0.020721,0.011805,0.299852,47.056530,2.397174,2.998519,-230.233398,0.300780,0.000000
208.110016,10.523621,-230.188919,0.020790,0.011850,0.300988,46.811401,2.384686,3.009879,-230.188919,0.302107,0.000000
208.910004,10.564957,-230.233398,0.020829,0.011907,0.302427,46.995274,2.394053,3.024275,-230.233398,0.303442,0.000000
209.710007,10.657677,-230.233398,0.020868,0.011962,0.303824,47.407715,2.415064,3.038237,-230.233398,0.304778,0.000000
210.510010,10.687462,-230.277878,0.020915,0.012013,0.305125,47.540203,2.421813,3.051246,-230.277878,0.306113,0.000000
211.310013,10.516914,-230.277878,0.021006,0.012062,0.306365,46.781570,2.383167,3.063647,-230.277878,0.307440,0.000000
212.110016,10.816673,-230.322357,0.021036,0.012118,0.307787,48.114967,2.451093,3.077871,-230.322357,0.308776,0.000000
212.910004,10.800293,-230.277878,0.021092,0.012170,0.309123,48.042103,2.447381,3.091226,-230.277878,0.310111,0.000000
213.710007,10.832687,-230.322357,0.021139,0.012226,0.310545,48.186199,2.454722,3.105448,-230.322357,0.311447,0.000000
214.510010,10.851677,-230.322357,0.021187,0.012275,0.311785,48.270668,2.459025,3.117849,-230.322357,0.312773,0.000000
215.310013,10.812210,-230.366852,0.021256,0.012325,0.313060,48.095112,2.450082,3.130598,-230.366852,0.314109,0.000000
216.110016,10.885193,-230.411331,0.021299,0.012382,0.314491,48.419758,2.466620,3.144907,-230.411331,0.315445,0.000000
216.910004,10.944031,-230.411331,0.021377,0.012435,0.315861,48.681480,2.479953,3.158608,-230.411331,0.316780,0.000000
217.710007,10.971954,-230.500290,0.021394,0.012486,0.317153,48.805691,2.486280,3.171530,-230.500290,0.318107,0.000000
218.510010,11.148834,-230.455811,0.021450,0.012543,0.318601,49.592491,2.526362,3.186013,-230.455811,0.319442,0.000000
219.310013,11.161118,-230.455811,0.021536,0.012595,0.319911,49.647129,2.529145,3.199109,-230.455811,0.320778,0.000000
220.110016,11.009941,-230.455811,0.021571,0.012639,0.321021,48.974663,2.494888,3.210208,-230.455811,0.322113,0.000000
220.910004,11.235596,-230.500290,0.021614,0.012696,0.322478,49.978424,2.546022,3.224778,-230.500290,0.323440,0.000000
221.710007,11.121277,-230.500290,0.021670,0.012743,0.323675,49.469910,2.520117,3.236746,-230.500290,0.324776,0.000000
222.510010,11.279167,-230.589249,0.021717,0.012800,0.325132,50.172241,2.555896,3.251316,-230.589249,0.326111,0.000000
223.310013,11.444870,-230.544769,0.021777,0.012855,0.326510,50.909325,2.593445,3.265104,-230.544769,0.327447,0.000000
224.110016,11.442261,-230.589249,0.021842,0.012910,0.327924,50.897717,2.592853,3.279241,-230.589249,0.328774,0.000000
224.910004,11.223305,-230.633728,0.021877,0.012954,0.329043,49.923752,2.543237,3.290427,-230.633728,0.330109,0.000000
225.710007,11.475029,-230.722687,0.021933,0.013008,0.330404,51.043480,2.600279,3.304043,-230.722687,0.331445,0.000000
226.510010,11.437050,-230.633728,0.022002,0.013065,0.331853,50.874538,2.591672,3.318526,-230.633728,0.332780,0.000000
227.310013,11.513016,-230.633728,0.022075,0.013117,0.333162,51.212452,2.608887,3.331620,-230.633728,0.334116,0.000000
228.110016,11.776283,-230.678207,0.022101,0.013171,0.334532,52.383526,2.668544,3.345323,-230.678207,0.335443,0.000000
228.910004,11.484337,-230.722687,0.022157,0.013216,0.335677,51.084881,2.602388,3.356770,-230.722687,0.336778,0.000000
229.710007,11.738297,-230.767181,0.022217,0.013270,0.337065,52.214550,2.659936,3.370646,-230.767181,0.338114,0.000000
230.510010,11.683563,-230.767181,0.022273,0.013322,0.338391,51.971085,2.647533,3.383914,-230.767181,0.339449,0.000000
231.310013,11.727875,-230.767181,0.022312,0.013373,0.339675,52.168194,2.657574,3.396748,-230.767181,0.340776,0.000000
232.110016,11.945709,-230.811661,0.022364,0.013434,0.341219,53.137169,2.706936,3.412185,-230.811661,0.342112,0.000000
232.910004,11.921509,-230.811661,0.022420,0.013481,0.342407,53.029518,2.701452,3.424066,-230.811661,0.343447,0.000000
233.710007,12.119980,-230.856140,0.022476,0.013539,0.343898,53.912361,2.746427,3.438982,-230.856140,0.344783,0.000000
234.510010,12.011620,-230.900620,0.022528,0.013587,0.345104,53.430351,2.721872,3.451037,-230.900620,0.346110,0.000000
235.310013,12.072319,-230.856140,0.022575,0.013640,0.346448,53.700356,2.735626,3.464479,-230.856140,0.347445,0.000000
236.110016,12.081253,-230.945099,0.022631,0.013694,0.347827,53.740097,2.737651,3.478267,-230.945099,0.348781,0.000000
236.910004,12.220894,-230.945099,0.022670,0.013747,0.349171,54.361252,2.769294,3.491709,-230.945099,0.350116,0.000000
237.710007,12.302071,-230.856140,0.022730,0.013801,0.350541,54.722343,2.787689,3.505413,-230.856140,0.351443,0.000000
238.510010,12.367981,-230.900620,0.022804,0.013856,0.351946,55.015526,2.802625,3.519462,-230.900620,0.352779,0.000000
239.310013,12.335953,-230.945099,0.022829,0.013901,0.353082,54.873058,2.795367,3.530823,-230.945099,0.354114,0.000000
240.110016,12.465546,-231.034058,0.022881,0.013959,0.354556,55.449516,2.824733,3.545565,-231.034058,0.355450,0.000000
240.910019,12.429420,-231.034058,0.022946,0.014009,0.355840,55.288822,2.816547,3.558399,-231.034058,0.356777,0.000000
241.710007,12.638695,-231.034058,0.023011,0.014060,0.357123,56.219723,2.863969,3.571234,-231.034058,0.358112,0.000000
242.510010,12.766045,-231.078537,0.023049,0.014115,0.358511,56.786201,2.892827,3.585111,-231.078537,0.359448,0.000000
243.310013,12.834190,-231.123016,0.023110,0.014165,0.359803,57.089329,2.908269,3.598033,-231.123016,0.360783,0.000000
244.110016,12.735138,-231.167496,0.023149,0.014218,0.361130,56.648724,2.885823,3.611301,-231.167496,0.362110,0.000000
244.910019,12.677422,-231.123016,0.023213,0.014263,0.362275,56.391987,2.872745,3.622748,-231.123016,0.363445,0.000000
245.710007,12.935478,-231.167496,0.023261,0.014328,0.363931,57.539883,2.931221,3.639313,-231.167496,0.364781,0.000000
246.510010,13.039742,-231.167496,0.023317,0.014374,0.365102,58.003666,2.954848,3.651019,-231.167496,0.366117,0.000000
247.310013,13.251617,-231.211990,0.023364,0.014430,0.366516,58.946136,3.002860,3.665156,-231.211990,0.367443,0.000000
248.110016,13.012558,-231.211990,0.023416,0.014478,0.367730,57.882748,2.948688,3.677296,-231.211990,0.368779,0.000000
248.910019,13.178261,-231.211990,0.023472,0.014528,0.369005,58.619831,2.986237,3.690046,-231.211990,0.370114,0.000000
249.710007,13.228905,-231.211990,0.023532,0.014582,0.370383,58.845108,2.997713,3.703834,-231.211990,0.371450,0.000000
250.510010,13.337639,-231.256470,0.023588,0.014633,0.371684,59.328781,3.022352,3.716843,-231.256470,0.372777,0.000000
251.310013,13.574097,-231.300949,0.023623,0.014688,0.373063,60.380596,3.075934,3.730631,-231.300949,0.374112,0.000000
252.110016,13.478767,-231.300949,0.023675,0.014738,0.374347,59.956551,3.054332,3.743465,-231.300949,0.375448,0.000000
252.910019,13.484726,-231.345428,0.023756,0.014788,0.375613,59.983055,3.055683,3.756128,-231.345428,0.376783,0.000000
253.710007,13.660484,-231.389908,0.023808,0.014847,0.377122,60.764870,3.095510,3.771216,-231.389908,0.378119,0.000000
254.510010,13.845184,-231.300949,0.023834,0.014899,0.378440,61.586456,3.137364,3.784399,-231.300949,0.379446,0.000000
255.310013,13.905510,-231.434387,0.023903,0.014951,0.379749,61.854797,3.151034,3.797493,-231.434387,0.380781,0.000000
256.110016,14.103233,-231.478867,0.023959,0.015006,0.381154,62.734314,3.195838,3.811543,-231.478867,0.382117,0.000000
256.910004,14.212715,-231.478867,0.024011,0.015058,0.382481,63.221313,3.220647,3.824812,-231.478867,0.383452,0.000000
257.710022,14.232079,-231.478867,0.024063,0.015110,0.383791,63.307446,3.225035,3.837906,-231.478867,0.384779,0.000000
258.510010,14.316231,-231.478867,0.024123,0.015163,0.385152,63.681774,3.244104,3.851522,-231.478867,0.386115,0.000000
259.309998,14.498322,-231.523346,0.024170,0.015219,0.386574,64.491753,3.285367,3.865744,-231.523346,0.387450,0.000000
260.110016,14.525131,-231.478867,0.024231,0.015270,0.387849,64.611008,3.291442,3.878494,-231.478867,0.388786,0.000000
260.910004,14.869209,-231.567825,0.024270,0.015324,0.389237,66.141548,3.369411,3.892369,-231.567825,0.390113,0.000000
261.710022,14.708344,-231.612305,0.024343,0.015373,0.390486,65.425980,3.332958,3.904857,-231.612305,0.391448,0.000000
262.510010,14.756378,-231.612305,0.024364,0.015421,0.391700,65.639648,3.343843,3.916997,-231.612305,0.392784,0.000000
263.309998,15.070663,-231.656799,0.024433,0.015479,0.393157,67.037659,3.415061,3.931567,-231.656799,0.394119,0.000000
264.110016,15.112366,-231.656799,0.024476,0.015532,0.394501,67.223160,3.424511,3.945009,-231.656799,0.395446,0.000000
264.910004,15.339882,-231.701279,0.024533,0.015582,0.395793,68.235199,3.476067,3.957931,-231.701279,0.396782,0.000000
265.710022,15.193916,-231.701279,0.024580,0.015630,0.396990,67.585915,3.442991,3.969899,-231.701279,0.398117,0.000000
266.510010,15.445267,-231.701279,0.024636,0.015686,0.398412,68.703979,3.499948,3.984120,-231.701279,0.399453,0.000000
267.309998,15.603897,-231.745758,0.024701,0.015741,0.399826,69.409599,3.535894,3.998257,-231.745758,0.400780,0.000000
268.110016,15.568520,-231.745758,0.024731,0.015784,0.400910,69.252235,3.527877,4.009097,-231.745758,0.402115,0.000000
268.910004,16.014626,-231.790237,0.024800,0.015849,0.402557,71.236610,3.628966,4.025575,-231.790237,0.403451,0.000000
269.710022,16.121124,-231.834717,0.024852,0.015899,0.403823,71.710342,3.653099,4.038235,-231.834717,0.404786,0.000000
270.510010,16.261131,-231.879196,0.024908,0.015947,0.405046,72.333122,3.684825,4.050464,-231.879196,0.406113,0.000000
271.310028,16.359444,-231.834717,0.024951,0.016002,0.406451,72.770439,3.707103,4.064514,-231.834717,0.407449,0.000000
272.110016,16.554565,-231.879196,0.024994,0.016053,0.407735,73.638382,3.751318,4.077348,-231.879196,0.408784,0.000000
272.910004,16.649147,-231.879196,0.025059,0.016104,0.409036,74.059105,3.772751,4.090357,-231.879196,0.410120,0.000000
273.710022,16.969757,-231.923676,0.025119,0.016158,0.410423,75.485252,3.845402,4.104232,-231.923676,0.411446,0.000000
274.510010,17.203606,-231.879196,0.025171,0.016214,0.411845,76.525459,3.898393,4.118454,-231.879196,0.412782,0.000000
275.310028,16.952255,-231.879196,0.025205,0.016261,0.413033,75.407394,3.841436,4.130335,-231.879196,0.414117,0.000000
276.110016,17.376015,-231.968155,0.025283,0.016316,0.414430,77.292374,3.937461,4.144297,-231.968155,0.415453,0.000000
276.910004,17.602417,-231.968155,0.025322,0.016369,0.415783,78.299461,3.988765,4.157826,-231.968155,0.416780,0.000000
277.710022,17.872017,-232.012634,0.025369,0.016425,0.417188,79.498703,4.049857,4.171876,-232.012634,0.418115,0.000000
278.510010,17.959152,-231.968155,0.025434,0.016476,0.418497,79.886299,4.069602,4.184970,-231.968155,0.419451,0.000000
279.310028,18.218323,-232.057129,0.025481,0.016530,0.419867,81.039146,4.128331,4.198673,-232.057129,0.420786,0.000000
280.110016,18.472282,-232.012634,0.025533,0.016581,0.421159,82.168816,4.185879,4.211595,-232.012634,0.422122,0.000000
280.910004,18.576920,-232.101608,0.025580,0.016634,0.422504,82.634262,4.209590,4.225037,-232.101608,0.423449,0.000000
281.710022,18.706879,-232.057129,0.025636,0.016684,0.423761,83.212349,4.239039,4.237610,-232.057129,0.424784,0.000000
282.510010,19.159683,-232.101608,0.025688,0.016740,0.425192,85.226524,4.341646,4.251921,-232.101608,0.426120,0.000000
283.310028,19.311981,-232.146088,0.025740,0.016791,0.426493,85.903984,4.376157,4.264929,-232.146088,0.427455,0.000000
284.110016,19.592003,-232.057129,0.025787,0.016841,0.427759,87.149582,4.439611,4.277590,-232.057129,0.428782,0.000000
284.910004,19.714516,-232.146088,0.025848,0.016893,0.429077,87.694542,4.467373,4.290772,-232.146088,0.430118,0.000000
285.710022,19.808723,-232.190567,0.025908,0.016944,0.430378,88.113602,4.488721,4.303780,-232.190567,0.431453,0.000000
286.510010,20.315529,-232.146088,0.025951,0.017001,0.431826,90.367989,4.603565,4.318263,-232.146088,0.432789,0.000000
287.310028,20.580658,-232.279526,0.026016,0.017051,0.433101,91.547340,4.663644,4.331012,-232.279526,0.434116,0.000000
288.110016,20.972763,-232.235046,0.026063,0.017109,0.434575,93.291512,4.752496,4.345754,-232.235046,0.435451,0.000000
288.910004,20.840942,-232.279526,0.026115,0.017154,0.435711,92.705139,4.722625,4.357114,-232.279526,0.436787,0.000000
289.710022,21.323540,-232.235046,0.026154,0.017205,0.437012,94.851845,4.831983,4.370123,-232.235046,0.438122,0.000000
290.510010,21.612869,-232.324005,0.026231,0.017265,0.438521,96.138847,4.897546,4.385213,-232.324005,0.439449,0.000000
291.310028,22.003860,-232.412964,0.026279,0.017315,0.439805,97.878059,4.986146,4.398048,-232.412964,0.440785,0.000000
292.110016,22.529655,-232.368484,0.026326,0.017369,0.441175,100.216911,5.105293,4.411749,-232.368484,0.442120,0.000000
292.910004,22.423523,-232.324005,0.026374,0.017416,0.442354,99.744812,5.081243,4.423545,-232.324005,0.443456,0.000000
293.710022,22.958252,-232.457443,0.026421,0.017468,0.443699,102.123405,5.202414,4.436987,-232.457443,0.444783,0.000000
294.510010,23.188751,-232.412964,0.026486,0.017521,0.445025,103.148720,5.254646,4.450255,-232.412964,0.446118,0.000000
295.310028,23.539154,-232.412964,0.026524,0.017574,0.446378,104.707390,5.334048,4.463784,-232.412964,0.447454,0.000000
296.110016,24.067177,-232.457443,0.026581,0.017631,0.447827,107.056152,5.453700,4.478267,-232.457443,0.448789,0.000000
296.910004,24.550514,-232.501938,0.026637,0.017682,0.449110,109.206139,5.563226,4.491101,-232.501938,0.450116,0.000000
297.710022,25.039070,-232.501938,0.026684,0.017735,0.450463,111.379349,5.673934,4.504631,-232.501938,0.451452,0.000000
298.510010,25.207008,-232.546417,0.026736,0.017784,0.451703,112.126373,5.711989,4.517032,-232.546417,0.452787,0.000000
299.310028,25.618484,-232.546417,0.026787,0.017837,0.453065,113.956711,5.805232,4.530646,-232.546417,0.454123,0.000000
300.110016,26.103310,-232.590897,0.026835,0.017891,0.454435,116.113319,5.915094,4.544349,-232.590897,0.455449,0.000000
300.910004,26.709908,-232.590897,0.026878,0.017946,0.455831,118.811600,6.052552,4.558312,-232.590897,0.456785,0.000000
301.710022,27.315758,-232.635376,0.026930,0.017998,0.457149,121.506561,6.189839,4.571493,-232.635376,0.458121,0.000000
302.510010,27.815849,-232.679855,0.027003,0.018053,0.458537,123.731079,6.303161,4.585368,-232.679855,0.459456,0.000000
303.310028,27.956238,-232.679855,0.027038,0.018097,0.459664,124.355553,6.334974,4.596643,-232.679855,0.460783,0.000000
304.110016,28.776199,-232.679855,0.027089,0.018156,0.461156,128.002930,6.520780,4.611559,-232.679855,0.462118,0.000000
304.910004,29.273315,-232.724335,0.027145,0.018206,0.462439,130.214203,6.633428,4.624394,-232.724335,0.463454,0.000000
305.710022,29.948433,-232.724335,0.027188,0.018259,0.463775,133.217285,6.786412,4.637749,-232.724335,0.464789,0.000000
306.510010,30.791481,-232.768814,0.027240,0.018315,0.465188,136.967346,6.977449,4.651884,-232.768814,0.466125,0.000000
307.310028,31.133690,-232.724335,0.027292,0.018361,0.466377,138.489563,7.054995,4.663766,-232.724335,0.467452,0.000000
308.110016,31.665070,-232.813293,0.027344,0.018415,0.467729,140.853271,7.175407,4.677294,-232.813293,0.468787,0.000000
308.910004,32.176331,-232.813293,0.027395,0.018464,0.468987,143.127472,7.291261,4.689869,-232.813293,0.470123,0.000000
309.710022,33.277809,-232.813293,0.027456,0.018526,0.470548,148.027084,7.540859,4.705480,-232.813293,0.471458,0.000000
310.510010,33.548523,-232.857773,0.027507,0.018561,0.471450,149.231277,7.602204,4.714499,-232.857773,0.471658,0.000000
311.310028,31.716080,-232.902252,0.027499,0.018544,0.471025,141.080170,7.186966,4.710249,-232.902252,0.470825,0.000000
312.110016,30.822762,-232.946747,0.027512,0.018501,0.469932,137.106491,6.984538,4.699322,-232.946747,0.469499,0.000000
312.910004,30.308144,-232.946747,0.027499,0.018446,0.468519,134.817352,6.867923,4.685185,-232.946747,0.468163,0.000000
313.710022,29.927948,-232.946747,0.027507,0.018396,0.467252,133.126160,6.781770,4.672525,-232.946747,0.466827,0.000000
314.510010,29.582756,-232.946747,0.027507,0.018343,0.465900,131.590668,6.703548,4.658996,-232.946747,0.465492,0.000000
315.310028,29.126976,-232.991226,0.027503,0.018297,0.464746,129.563263,6.600267,4.647461,-232.991226,0.464165,0.000000
316.110016,27.848618,-232.991226,0.027516,0.018252,0.463593,123.876839,6.310587,4.635929,-232.991226,0.462830,0.000000
316.910004,25.638214,-232.991226,0.027512,0.018200,0.462275,114.044472,5.809702,4.622746,-232.991226,0.461494,0.000000
317.710022,22.332298,-233.035706,0.027503,0.018145,0.460878,99.339027,5.060571,4.608783,-233.035706,0.460159,0.000000
318.510010,19.241600,-233.035706,0.027499,0.018104,0.459838,85.590912,4.360209,4.598377,-233.035706,0.458832,0.000000
319.310028,15.290733,-232.991226,0.027469,0.018050,0.458476,68.016579,3.464930,4.584761,-232.991226,0.457496,0.000000
320.110016,10.991318,-233.080185,0.027421,0.017995,0.457080,48.891823,2.490668,4.570800,-233.080185,0.456161,0.000000
320.910004,7.558418,-233.124664,0.027395,0.017945,0.455805,33.621525,1.712762,4.558051,-233.124664,0.454825,0.000000
321.710022,4.247658,-233.124664,0.027352,0.017887,0.454340,18.894526,0.962533,4.543396,-233.124664,0.453490,0.000000
322.510010,2.201843,-233.124664,0.027309,0.017831,0.452908,9.794288,0.498945,4.529085,-233.124664,0.452163,0.000000
323.310028,1.617958,-233.124664,0.027266,0.017790,0.451868,7.197037,0.366635,4.518678,-233.124664,0.450827,0.000000
324.110016,1.378151,-233.124664,0.027188,0.017731,0.450376,6.130322,0.312293,4.503762,-233.124664,0.449492,0.000000
324.910004,1.308517,-233.213623,0.027128,0.017685,0.449197,5.820576,0.296514,4.491968,-233.213623,0.448156,0.000000
325.710022,1.115257,-233.213623,0.027055,0.017625,0.447671,4.960912,0.252721,4.476706,-233.213623,0.446829,0.000000
326.510010,0.964447,-233.169144,0.027016,0.017568,0.446222,4.290075,0.218547,4.462223,-233.169144,0.445494,0.000000
327.310028,0.841194,-233.213623,0.026964,0.017517,0.444921,3.741818,0.190617,4.449214,-233.213623,0.444158,0.000000
328.110016,0.795013,-233.347076,0.026887,0.017469,0.443725,3.536396,0.180153,4.437246,-233.347076,0.442823,0.000000
328.910004,0.747353,-233.258102,0.026856,0.017418,0.442415,3.324390,0.169353,4.424150,-233.258102,0.441496,0.000000
329.710022,0.620743,-233.302582,0.026792,0.017363,0.441027,2.761202,0.140662,4.410275,-233.302582,0.440160,0.000000
330.510010,0.583138,-233.302582,0.026714,0.017310,0.439666,2.593925,0.132141,4.396661,-233.302582,0.438825,0.000000
331.310028,0.504936,-233.302582,0.026680,0.017254,0.438252,2.246068,0.114420,4.382524,-233.302582,0.437489,0.000000
332.110016,0.428604,-233.391556,0.026641,0.017200,0.436882,1.906526,0.097123,4.368823,-233.391556,0.436162,0.000000
332.910004,0.398071,-233.391556,0.026585,0.017149,0.435581,1.770710,0.090204,4.355814,-233.391556,0.434827,0.000000
333.710022,0.412964,-233.436035,0.026507,0.017104,0.434437,1.836955,0.093579,4.344367,-233.436035,0.433491,0.000000
334.510010,0.370140,-233.436035,0.026451,0.017047,0.432988,1.646465,0.083875,4.329884,-233.436035,0.432156,0.000000
335.310028,0.364555,-233.436035,0.026412,0.016997,0.431714,1.621623,0.082609,4.317136,-233.436035,0.430829,0.000000
336.110016,0.311676,-233.480515,0.026374,0.016943,0.430343,1.386404,0.070627,4.303433,-233.480515,0.429493,0.000000
336.910004,0.321358,-233.569473,0.026313,0.016898,0.429216,1.429471,0.072821,4.292160,-233.569473,0.428158,0.000000
337.710022,0.273323,-233.524994,0.026266,0.016844,0.427846,1.215802,0.061936,4.278457,-233.524994,0.426822,0.000000
338.510010,0.286354,-233.569473,0.026197,0.016786,0.426363,1.273767,0.064889,4.263628,-233.569473,0.425496,0.000000
339.310028,0.268112,-233.524994,0.026145,0.016733,0.425027,1.192623,0.060755,4.250272,-233.524994,0.424160,0.000000
340.110016,0.251724,-233.569473,0.026089,0.016678,0.423631,1.119725,0.057042,4.236310,-233.569473,0.422824,0.000000
340.910004,0.241669,-233.613953,0.026029,0.016623,0.422218,1.074996,0.054763,4.222175,-233.613953,0.421489,0.000000
341.600006,0.270348,-233.613953,0.025994,0.016598,0.421602,1.202566,0.061262,4.216017,-233.613953,0.421463,0.000000