File: PDMS and AD/PDMS0017 Test 1-1_02142024_150515.csv
Time (sec),S:Load (lbs),S:HL1 (DIM),S:LVDT (in),S:Position (in),Ch:Position (mm),Ch:Load (N),Ch:Stress (MPa),Ch:Strain (mm/mm),Ch:HL1 (DIM),Set Point (),Cycles ()
0.110000,0.008934,-66.943832,-0.000004,-0.000000,-0.000000,0.039741,0.002024,-0.000000,-66.943832,0.000208,0.000000
0.580000,0.046173,-66.988312,0.000013,0.000050,0.001266,0.205388,0.010463,0.012660,-66.988312,0.001873,0.000000
1.050000,0.075592,-66.988312,0.000022,0.000183,0.004648,0.336250,0.017129,0.046482,-66.988312,0.005784,0.000000
1.520000,0.075592,-66.988312,0.000203,0.000342,0.008690,0.336250,0.017129,0.086896,-66.988312,0.009704,0.000000
1.990000,0.033508,-66.988312,0.000358,0.000494,0.012540,0.149052,0.007593,0.125401,-66.988312,0.013615,0.000000
2.460000,0.035744,-67.032791,0.000500,0.000647,0.016425,0.158996,0.008100,0.164251,-67.032791,0.017535,0.000000
2.930000,0.052872,-67.032791,0.000660,0.000789,0.020033,0.235185,0.011981,0.200329,-67.032791,0.021446,0.000000
3.400000,0.033882,-67.032791,0.000845,0.000954,0.024230,0.150715,0.007678,0.242303,-67.032791,0.025366,0.000000
3.870000,0.021599,-67.121758,0.001022,0.001111,0.028228,0.096076,0.004894,0.282281,-67.121758,0.029277,0.000000
4.340000,-0.000374,-67.032791,0.001164,0.001264,0.032113,-0.001663,-0.000085,0.321133,-67.032791,0.033189,0.000000
4.810000,0.036865,-67.121758,0.001328,0.001422,0.036129,0.163985,0.008354,0.361285,-67.121758,0.037109,0.000000
5.280000,0.072983,-67.121758,0.001483,0.001574,0.039970,0.324644,0.016538,0.399704,-67.121758,0.041020,0.000000
5.750000,0.077454,-67.121758,0.001669,0.001734,0.044055,0.344531,0.017551,0.440550,-67.121758,0.044940,0.000000
6.220000,0.048035,-67.077271,0.001828,0.001882,0.047810,0.213669,0.010885,0.478100,-67.077271,0.048851,0.000000
6.690001,0.045425,-67.166237,0.001966,0.002031,0.051583,0.202062,0.010294,0.515826,-67.166237,0.052771,0.000000
7.160000,0.054367,-67.255196,0.002147,0.002183,0.055459,0.241837,0.012320,0.554591,-67.255196,0.056682,0.000000
7.630001,0.049149,-67.166237,0.002294,0.002340,0.059431,0.218624,0.011137,0.594310,-67.166237,0.060602,0.000000
8.100000,0.044685,-67.166237,0.002458,0.002502,0.063542,0.198770,0.010126,0.635416,-67.166237,0.064513,0.000000
8.570001,0.005959,-67.121758,0.002643,0.002655,0.067427,0.026505,0.001350,0.674268,-67.121758,0.068424,0.000000
9.040000,0.033508,-67.255196,0.002790,0.002808,0.071329,0.149052,0.007593,0.713292,-67.255196,0.072344,0.000000
9.510000,0.056595,-67.255196,0.002936,0.002963,0.075249,0.251746,0.012825,0.752492,-67.255196,0.076255,0.000000
9.980000,0.071495,-67.255196,0.003117,0.003116,0.079152,0.318026,0.016201,0.791516,-67.255196,0.080175,0.000000
10.450001,0.060326,-67.210716,0.003277,0.003270,0.083046,0.268342,0.013670,0.830455,-67.210716,0.084086,0.000000
10.920000,0.042450,-67.210716,0.003419,0.003420,0.086879,0.188827,0.009619,0.868787,-67.210716,0.088006,0.000000
11.390000,0.063675,-67.344162,0.003579,0.003575,0.090816,0.283240,0.014429,0.908159,-67.344162,0.091917,0.000000
11.860001,0.062187,-67.299683,0.003751,0.003730,0.094736,0.276622,0.014092,0.947357,-67.299683,0.095837,0.000000
12.330001,0.058830,-67.255196,0.003923,0.003888,0.098760,0.261690,0.013331,0.987596,-67.255196,0.099748,0.000000
12.800000,0.086761,-67.299683,0.004087,0.004045,0.102732,0.385934,0.019660,1.027315,-67.299683,0.103659,0.000000
13.270000,0.235336,-67.344162,0.004230,0.004196,0.106573,1.046828,0.053328,1.065734,-67.344162,0.107579,0.000000
13.740001,0.414818,-67.344162,0.004350,0.000003,0.000069,1.845202,0.093999,0.000695,-67.344162,0.000252,0.000000
14.210001,0.411469,-67.344162,0.004346,0.000003,0.000069,1.830303,0.093240,0.000695,-67.344162,0.000529,0.000000
14.680000,0.394714,-67.255196,0.004355,0.000003,0.000069,1.755777,0.089444,0.000695,-67.255196,0.001310,0.000000
15.150001,0.517593,-67.388641,0.004350,0.000046,0.001162,2.302370,0.117288,0.011622,-67.388641,0.002099,0.000000
15.620001,0.621490,-67.388641,0.004402,0.000080,0.002038,2.764528,0.140832,0.020380,-67.388641,0.002879,0.000000
16.090000,0.720169,-67.433121,0.004432,0.000110,0.002784,3.203472,0.163193,0.027838,-67.433121,0.003660,0.000000
16.560001,0.827034,-67.433121,0.004484,0.000143,0.003634,3.678831,0.187409,0.036337,-67.433121,0.004449,0.000000
17.030001,0.890709,-67.433121,0.004506,0.000172,0.004380,3.962071,0.201838,0.043795,-67.433121,0.005229,0.000000
17.500000,1.006523,-67.433121,0.004518,0.000203,0.005160,4.477239,0.228081,0.051601,-67.433121,0.006010,0.000000
17.970001,1.108925,-67.477600,0.004536,0.000229,0.005810,4.932744,0.251286,0.058104,-67.477600,0.006799,0.000000
18.440001,1.248566,-67.522087,0.004583,0.000264,0.006704,5.553897,0.282929,0.067038,-67.522087,0.007580,0.000000
18.910002,1.326019,-67.477600,0.004626,0.000294,0.007458,5.898428,0.300480,0.074581,-67.477600,0.008360,0.000000
19.380001,1.453743,-67.477600,0.004656,0.000327,0.008299,6.466572,0.329423,0.082993,-67.477600,0.009149,0.000000
19.850000,1.527466,-67.477600,0.004669,0.000351,0.008924,6.794508,0.346129,0.089238,-67.477600,0.009930,0.000000
20.320002,1.707329,-67.566566,0.004725,0.000389,0.009878,7.594578,0.386886,0.098778,-67.566566,0.010710,0.000000
20.790001,1.765419,-67.566566,0.004730,0.000417,0.010589,7.852976,0.400050,0.105888,-67.566566,0.011499,0.000000
21.260000,1.950859,-67.566566,0.004790,0.000452,0.011482,8.677855,0.442071,0.114820,-67.566566,0.012280,0.000000
21.730001,2.007828,-67.566566,0.004777,0.000475,0.012055,8.931264,0.454980,0.120545,-67.566566,0.013061,0.000000
22.200001,2.167580,-67.611046,0.004820,0.000510,0.012948,9.641876,0.491181,0.129477,-67.611046,0.013850,0.000000
22.670002,2.231628,-67.611046,0.004885,0.000537,0.013642,9.926779,0.505694,0.136415,-67.611046,0.014630,0.000000
23.140001,2.411858,-67.611046,0.004915,0.000569,0.014448,10.728478,0.546535,0.144481,-67.611046,0.015411,0.000000
23.610001,2.513138,-67.611046,0.004954,0.000596,0.015142,11.178995,0.569485,0.151419,-67.611046,0.016200,0.000000
24.080002,2.733955,-67.611046,0.004997,0.000638,0.016200,12.161241,0.619523,0.161999,-67.611046,0.016980,0.000000
24.550001,2.782364,-67.611046,0.004997,0.000663,0.016833,12.376573,0.630493,0.168329,-67.611046,0.017761,0.000000
25.020000,2.888489,-67.700005,0.005006,0.000689,0.017509,12.848639,0.654541,0.175093,-67.700005,0.018550,0.000000
25.490002,2.972275,-67.655525,0.005057,0.000712,0.018073,13.221338,0.673527,0.180731,-67.655525,0.019331,0.000000
25.960001,3.268684,-67.655525,0.005101,0.000757,0.019227,14.539834,0.740694,0.192265,-67.655525,0.020111,0.000000
26.430000,3.341667,-67.655525,0.005122,0.000789,0.020042,14.864478,0.757233,0.200416,-67.655525,0.020900,0.000000
26.900002,3.480194,-67.744492,0.005165,0.000817,0.020761,15.480677,0.788623,0.207615,-67.744492,0.021681,0.000000
27.370001,3.560249,-67.744492,0.005191,0.000844,0.021447,15.836780,0.806764,0.214465,-67.744492,0.022461,0.000000
27.840002,3.859268,-67.700005,0.005208,0.000881,0.022383,17.166882,0.874523,0.223831,-67.700005,0.023250,0.000000
28.310001,3.884956,-67.655525,0.005256,0.000912,0.023155,17.281149,0.880344,0.231550,-67.655525,0.024031,0.000000
28.780001,4.001137,-67.744492,0.005273,0.000940,0.023875,17.797945,0.906671,0.238747,-67.744492,0.024811,0.000000
29.250002,4.168335,-67.788971,0.005303,0.000971,0.024664,18.541679,0.944558,0.246639,-67.788971,0.025601,0.000000
29.720001,4.302017,-67.833450,0.005316,0.000997,0.025332,19.136328,0.974851,0.253317,-67.833450,0.026381,0.000000
30.190001,4.455063,-67.700005,0.005376,0.001035,0.026294,19.817110,1.009532,0.262944,-67.700005,0.027162,0.000000
30.660002,4.565659,-67.833450,0.005389,0.001061,0.026962,20.309063,1.034593,0.269621,-67.833450,0.027951,0.000000
31.130001,4.707161,-67.877930,0.005428,0.001090,0.027682,20.938498,1.066658,0.276820,-67.877930,0.028731,0.000000
31.600002,4.851639,-67.877930,0.005476,0.001120,0.028454,21.581167,1.099397,0.284537,-67.877930,0.029512,0.000000
32.070000,5.040062,-67.877930,0.005510,0.001159,0.029451,22.419315,1.142094,0.294510,-67.877930,0.030301,0.000000
32.540001,5.101501,-67.833450,0.005506,0.001186,0.030136,22.692612,1.156017,0.301361,-67.833450,0.031081,0.000000
33.010002,5.314499,-67.877930,0.005540,0.001219,0.030969,23.640072,1.204283,0.309688,-67.877930,0.031862,0.000000
33.480003,5.432541,-67.922409,0.005570,0.001247,0.031671,24.165150,1.231031,0.316711,-67.922409,0.032651,0.000000
33.950001,5.611275,-67.877930,0.005631,0.001281,0.032538,24.960197,1.271533,0.325384,-67.877930,0.033432,0.000000
34.420002,5.739372,-67.877930,0.005665,0.001314,0.033371,25.530003,1.300560,0.333709,-67.877930,0.034212,0.000000
34.890003,5.866356,-67.922409,0.005687,0.001345,0.034160,26.094854,1.329335,0.341600,-67.922409,0.035001,0.000000
35.360001,5.997429,-67.922409,0.005704,0.001374,0.034897,26.677896,1.359037,0.348973,-67.922409,0.035782,0.000000
35.830002,6.109512,-68.011375,0.005752,0.001405,0.035678,27.176468,1.384435,0.356777,-68.011375,0.036562,0.000000
36.300003,6.168716,-67.966896,0.005790,0.001434,0.036415,27.439821,1.397851,0.364149,-67.966896,0.037351,0.000000
36.770000,6.370544,-68.011375,0.005821,0.001467,0.037265,28.337597,1.443586,0.372648,-68.011375,0.038132,0.000000
37.240002,6.476669,-67.966896,0.005829,0.001497,0.038028,28.809664,1.467634,0.380280,-67.966896,0.038913,0.000000
37.710003,6.660248,-68.011375,0.005855,0.001532,0.038921,29.626263,1.509234,0.389212,-68.011375,0.039702,0.000000
38.180000,6.689667,-68.055855,0.005920,0.001560,0.039624,29.757124,1.515900,0.396237,-68.055855,0.040482,0.000000
38.650002,6.864685,-68.011375,0.005933,0.001592,0.040439,30.535645,1.555560,0.404388,-68.011375,0.041263,0.000000
39.120003,6.964111,-68.055855,0.005941,0.001619,0.041124,30.977915,1.578090,0.411238,-68.055855,0.042052,0.000000
39.590000,7.152153,-68.055855,0.005989,0.001656,0.042052,31.814365,1.620701,0.420519,-68.055855,0.042832,0.000000
40.060001,7.195724,-68.100334,0.006015,0.001684,0.042763,32.008183,1.630574,0.427629,-68.100334,0.043613,0.000000
40.530003,7.324936,-68.100334,0.006062,0.001712,0.043491,32.582943,1.659854,0.434915,-68.100334,0.044402,0.000000
41.000004,7.403137,-68.055855,0.006105,0.001743,0.044263,32.930798,1.677575,0.442632,-68.055855,0.045183,0.000000
41.470001,7.473137,-68.100334,0.006127,0.001771,0.044983,33.242172,1.693437,0.449831,-68.100334,0.045963,0.000000
41.940002,7.598999,-68.100334,0.006135,0.001804,0.045816,33.802036,1.721958,0.458156,-68.100334,0.046752,0.000000
42.410004,7.717789,-68.144814,0.006191,0.001835,0.046613,34.330441,1.748876,0.466134,-68.144814,0.047533,0.000000
42.880001,7.761360,-68.189301,0.006204,0.001864,0.047342,34.524254,1.758749,0.473418,-68.189301,0.048313,0.000000
43.350002,7.982918,-68.100334,0.006247,0.001899,0.048244,35.509792,1.808955,0.482438,-68.100334,0.049102,0.000000
43.820004,7.941216,-68.100334,0.006273,0.001927,0.048955,35.324291,1.799505,0.489550,-68.100334,0.049883,0.000000
44.290001,8.001534,-68.233780,0.006312,0.001953,0.049614,35.592598,1.813173,0.496141,-68.233780,0.050663,0.000000
44.760002,8.144157,-68.233780,0.006329,0.001988,0.050507,36.227020,1.845492,0.505073,-68.233780,0.051453,0.000000
45.230003,8.347099,-68.233780,0.006390,0.002021,0.051340,37.129753,1.891480,0.513398,-68.233780,0.052233,0.000000
45.700001,8.345985,-68.189301,0.006433,0.002053,0.052146,37.124798,1.891227,0.521464,-68.189301,0.053014,0.000000
46.170002,8.339279,-68.233780,0.006446,0.002080,0.052823,37.094967,1.889708,0.528228,-68.233780,0.053803,0.000000
46.640003,8.431625,-68.278259,0.006485,0.002105,0.053473,37.505741,1.910634,0.534732,-68.278259,0.054583,0.000000
47.110001,8.694153,-68.233780,0.006536,0.002142,0.054410,38.673523,1.970123,0.544098,-68.233780,0.055364,0.000000
47.580002,8.707558,-68.278259,0.006554,0.002177,0.055303,38.733150,1.973161,0.553030,-68.278259,0.056153,0.000000
48.050003,8.693779,-68.278259,0.006575,0.002204,0.055988,38.671860,1.970038,0.559881,-68.278259,0.056933,0.000000
48.520000,8.791336,-68.322739,0.006601,0.002238,0.056838,39.105816,1.992145,0.568380,-68.322739,0.057714,0.000000
48.990002,8.838257,-68.322739,0.006631,0.002262,0.057454,39.314529,2.002778,0.574538,-68.322739,0.058503,0.000000
49.460003,8.992790,-68.322739,0.006670,0.002299,0.058399,40.001930,2.037795,0.583990,-68.322739,0.059284,0.000000
49.930004,8.971191,-68.367218,0.006730,0.002329,0.059154,39.905853,2.032901,0.591536,-68.367218,0.060064,0.000000
50.400002,9.195366,-68.322739,0.006722,0.002360,0.059951,40.903030,2.083700,0.599514,-68.322739,0.060853,0.000000
50.870003,9.213608,-68.411705,0.006756,0.002387,0.060628,40.984173,2.087833,0.606278,-68.411705,0.061634,0.000000
51.340004,9.352501,-68.367218,0.006808,0.002426,0.061625,41.602001,2.119307,0.616251,-68.367218,0.062414,0.000000
51.810001,9.199829,-68.411705,0.006834,0.002449,0.062206,40.922882,2.084711,0.622061,-68.411705,0.063203,0.000000
52.280003,9.279144,-68.411705,0.006851,0.002477,0.062926,41.275696,2.102684,0.629260,-68.411705,0.063984,0.000000
52.750004,9.349525,-68.411705,0.006903,0.002505,0.063628,41.588768,2.118633,0.636284,-68.411705,0.064764,0.000000
53.220001,9.628807,-68.500664,0.006942,0.002549,0.064756,42.831074,2.181919,0.647558,-68.500664,0.065554,0.000000
53.690002,9.527893,-68.456184,0.006954,0.002577,0.065467,42.382187,2.159051,0.654670,-68.456184,0.066334,0.000000
54.160004,9.618378,-68.500664,0.007011,0.002604,0.066152,42.784679,2.179555,0.661520,-68.500664,0.067115,0.000000
54.630001,9.547630,-68.456184,0.007023,0.002634,0.066898,42.469982,2.163524,0.668978,-68.456184,0.067904,0.000000
55.100002,9.784081,-68.500664,0.007058,0.002668,0.067765,43.521763,2.217104,0.677651,-68.500664,0.068684,0.000000
55.570004,9.798607,-68.589630,0.007080,0.002698,0.068537,43.586380,2.220396,0.685369,-68.589630,0.069465,0.000000
56.040001,9.881645,-68.500664,0.007123,0.002732,0.069404,43.955753,2.239213,0.694042,-68.500664,0.070254,0.000000
56.510002,9.928192,-68.545143,0.007157,0.002762,0.070150,44.162804,2.249760,0.701500,-68.545143,0.071035,0.000000
56.980003,9.973625,-68.545143,0.007183,0.002793,0.070948,44.364899,2.260056,0.709479,-68.545143,0.071815,0.000000
57.450005,10.026871,-68.589630,0.007230,0.002825,0.071763,44.601749,2.272121,0.717629,-68.589630,0.072604,0.000000
57.920002,9.988144,-68.589630,0.007248,0.002853,0.072465,44.429482,2.263346,0.724654,-68.589630,0.073385,0.000000
58.390003,10.073418,-68.545143,0.007278,0.002885,0.073281,44.808800,2.282669,0.732807,-68.545143,0.074165,0.000000
58.860004,10.184753,-68.589630,0.007321,0.002919,0.074131,45.304047,2.307898,0.741306,-68.589630,0.074954,0.000000
59.330002,10.146027,-68.634109,0.007351,0.002950,0.074928,45.131779,2.299123,0.749284,-68.634109,0.075735,0.000000
59.800003,10.160179,-68.634109,0.007360,0.002977,0.075613,45.194733,2.302330,0.756135,-68.634109,0.076515,0.000000
60.270004,10.121078,-68.723068,0.007416,0.003008,0.076394,45.020805,2.293469,0.763939,-68.723068,0.077305,0.000000
60.740002,10.273010,-68.634109,0.007442,0.003041,0.077253,45.696632,2.327898,0.772525,-68.634109,0.078085,0.000000
61.210003,10.188850,-68.589630,0.007463,0.003070,0.077981,45.322269,2.308826,0.779809,-68.589630,0.078865,0.000000
61.680004,10.174332,-68.678589,0.007480,0.003099,0.078727,45.257687,2.305537,0.787268,-68.678589,0.079655,0.000000
62.150002,10.237633,-68.678589,0.007537,0.003129,0.079481,45.539265,2.319881,0.794813,-68.678589,0.080435,0.000000
62.620003,10.208961,-68.723068,0.007562,0.003154,0.080114,45.411728,2.313384,0.801143,-68.723068,0.081216,0.000000
63.090004,10.397011,-68.723068,0.007606,0.003191,0.081042,46.248215,2.355996,0.810424,-68.723068,0.082005,0.000000
63.560001,10.410789,-68.767548,0.007627,0.003221,0.081805,46.309505,2.359118,0.818054,-68.767548,0.082785,0.000000
64.030006,10.494568,-68.767548,0.007657,0.003254,0.082655,46.682171,2.378103,0.826553,-68.767548,0.083566,0.000000
64.500000,10.469994,-68.723068,0.007675,0.003279,0.083297,46.572857,2.372535,0.832970,-68.723068,0.084355,0.000000
64.970001,10.601814,-68.723068,0.007731,0.003316,0.084234,47.159225,2.402405,0.842338,-68.723068,0.085136,0.000000
65.440002,10.483398,-68.723068,0.007743,0.003342,0.084893,46.632484,2.375572,0.848927,-68.723068,0.085916,0.000000
65.910004,10.686340,-68.812035,0.007752,0.003377,0.085777,47.535217,2.421559,0.857773,-68.812035,0.086705,0.000000
66.380005,10.625648,-68.856514,0.007812,0.003404,0.086463,47.265244,2.407806,0.864625,-68.856514,0.087486,0.000000
66.850006,10.823380,-68.767548,0.007856,0.003445,0.087494,48.144798,2.452613,0.874945,-68.767548,0.088266,0.000000
67.320000,10.723953,-68.767548,0.007890,0.003469,0.088110,47.702526,2.430083,0.881103,-68.767548,0.089056,0.000000
67.790001,10.783157,-68.812035,0.007907,0.003497,0.088813,47.965881,2.443498,0.888126,-68.812035,0.089836,0.000000
68.260002,10.709061,-68.900993,0.007950,0.003520,0.089402,47.636280,2.426708,0.894024,-68.900993,0.090616,0.000000
68.730003,10.999878,-68.900993,0.007981,0.003566,0.090573,48.929901,2.492608,0.905731,-68.900993,0.091406,0.000000
69.200005,10.903061,-68.900993,0.008024,0.003594,0.091276,48.499237,2.470669,0.912756,-68.900993,0.092186,0.000000
69.670006,11.064674,-68.900993,0.008041,0.003625,0.092073,49.218128,2.507291,0.920734,-68.900993,0.092967,0.000000
70.140007,10.997643,-68.900993,0.008071,0.003651,0.092733,48.919956,2.492101,0.927326,-68.900993,0.093756,0.000000
70.610001,11.190910,-68.945473,0.008123,0.003690,0.093721,49.779655,2.535897,0.937212,-68.945473,0.094536,0.000000
71.080002,11.075096,-68.900993,0.008149,0.003719,0.094458,49.264488,2.509653,0.944583,-68.900993,0.095317,0.000000
71.550003,11.173035,-68.945473,0.008166,0.003748,0.095195,49.700142,2.531846,0.951954,-68.945473,0.096106,0.000000
72.020004,11.084778,-68.945473,0.008201,0.003773,0.095837,49.307556,2.511847,0.958371,-68.945473,0.096886,0.000000
72.490005,11.386772,-68.989952,0.008248,0.003813,0.096852,50.650890,2.580279,0.968519,-68.989952,0.097667,0.000000
72.960007,11.134308,-69.078918,0.008278,0.003841,0.097554,49.527874,2.523070,0.975543,-69.078918,0.098456,0.000000
73.430000,11.117920,-69.034439,0.008300,0.003866,0.098205,49.454979,2.519357,0.982048,-69.034439,0.099237,0.000000
73.900002,11.300758,-68.989952,0.008317,0.003897,0.098977,50.268284,2.560788,0.989765,-68.989952,0.100017,0.000000
74.370003,11.467583,-68.989952,0.008382,0.003932,0.099870,51.010357,2.598591,0.998698,-68.989952,0.100806,0.000000
74.840004,11.357727,-69.078918,0.008399,0.003966,0.100728,50.521694,2.573698,1.007284,-69.078918,0.101587,0.000000
75.310005,11.297035,-69.078918,0.008451,0.003991,0.101379,50.251724,2.559945,1.013788,-69.078918,0.102367,0.000000
75.780006,11.494392,-69.078918,0.008485,0.004024,0.102220,51.129612,2.604666,1.022200,-69.078918,0.103157,0.000000
76.250000,11.612434,-69.034439,0.008489,0.004055,0.103009,51.654690,2.631415,1.030091,-69.034439,0.103937,0.000000
76.720001,11.561790,-69.078918,0.008528,0.004085,0.103764,51.429413,2.619939,1.037637,-69.078918,0.104718,0.000000
77.190002,11.565140,-69.167877,0.008558,0.004116,0.104535,51.444309,2.620698,1.045354,-69.167877,0.105507,0.000000
77.660004,11.697708,-69.078918,0.008606,0.004150,0.105411,52.034004,2.650738,1.054114,-69.078918,0.106287,0.000000
78.130005,11.704407,-69.123398,0.008640,0.004180,0.106166,52.063801,2.652256,1.061657,-69.123398,0.107068,0.000000
78.600006,11.552109,-69.123398,0.008662,0.004206,0.106834,51.386345,2.617745,1.068336,-69.123398,0.107857,0.000000
79.070007,11.728241,-69.167877,0.008714,0.004240,0.107692,52.169823,2.657657,1.076922,-69.167877,0.108637,0.000000
79.540001,11.793777,-69.212357,0.008735,0.004274,0.108551,52.461342,2.672508,1.085508,-69.212357,0.109418,0.000000
80.010002,11.855965,-69.212357,0.008770,0.004304,0.109331,52.737965,2.686600,1.093312,-69.212357,0.110207,0.000000
80.480003,11.902885,-69.123398,0.008808,0.004338,0.110181,52.946678,2.697232,1.101811,-69.123398,0.110988,0.000000
80.950005,11.861549,-69.212357,0.008826,0.004366,0.110901,52.762806,2.687865,1.109008,-69.212357,0.111768,0.000000
81.420006,11.915916,-69.256844,0.008852,0.004396,0.111664,53.004642,2.700185,1.116641,-69.256844,0.112557,0.000000
81.890007,11.903999,-69.256844,0.008903,0.004424,0.112367,52.951633,2.697485,1.123665,-69.256844,0.113338,0.000000
82.360001,12.023529,-69.256844,0.008938,0.004459,0.113260,53.483330,2.724571,1.132598,-69.256844,0.114118,0.000000
82.830002,11.956879,-69.256844,0.008964,0.004487,0.113979,53.186852,2.709467,1.139795,-69.256844,0.114908,0.000000
83.300003,12.022415,-69.212357,0.008985,0.004518,0.114760,53.478374,2.724318,1.147601,-69.212357,0.115688,0.000000
83.770004,12.016083,-69.301323,0.009015,0.004545,0.115436,53.450207,2.722883,1.154365,-69.301323,0.116468,0.000000
84.240005,12.213440,-69.301323,0.009046,0.004578,0.116269,54.328094,2.767605,1.162689,-69.301323,0.117249,0.000000
84.710007,12.190353,-69.301323,0.009084,0.004609,0.117058,54.225399,2.762373,1.170581,-69.301323,0.118038,0.000000
85.180000,12.345261,-69.256844,0.009119,0.004643,0.117934,54.914463,2.797476,1.179341,-69.256844,0.118819,0.000000
85.650002,12.105080,-69.345802,0.009140,0.004667,0.118550,53.846085,2.743050,1.185497,-69.345802,0.119599,0.000000
86.120003,12.315102,-69.390282,0.009175,0.004703,0.119452,54.780308,2.790642,1.194517,-69.390282,0.120388,0.000000
86.590004,12.271904,-69.345802,0.009218,0.004732,0.120197,54.588154,2.780853,1.201975,-69.345802,0.121169,0.000000
87.060005,12.340790,-69.345802,0.009244,0.004761,0.120917,54.894573,2.796463,1.209174,-69.345802,0.121949,0.000000
87.530006,12.330742,-69.345802,0.009278,0.004792,0.121715,54.849880,2.794186,1.217152,-69.345802,0.122738,0.000000
88.000008,12.574272,-69.434761,0.009317,0.004830,0.122686,55.933155,2.849371,1.226864,-69.434761,0.123519,0.000000
88.470001,12.385849,-69.390282,0.009343,0.004858,0.123389,55.095009,2.806674,1.233889,-69.390282,0.124300,0.000000
88.940002,12.322174,-69.390282,0.009360,0.004883,0.124039,54.811768,2.792245,1.240393,-69.390282,0.125089,0.000000
89.410004,12.349731,-69.390282,0.009399,0.004907,0.124638,54.934349,2.798489,1.246377,-69.390282,0.125869,0.000000
89.880005,12.718376,-69.479248,0.009434,0.004950,0.125722,56.574162,2.882025,1.257217,-69.479248,0.126650,0.000000
90.350006,12.603317,-69.479248,0.009481,0.004984,0.126598,56.062355,2.855953,1.265977,-69.479248,0.127439,0.000000
90.820007,12.573898,-69.390282,0.009516,0.005011,0.127292,55.931492,2.849286,1.272915,-69.390282,0.128219,0.000000
91.290001,12.541504,-69.479248,0.009541,0.005037,0.127950,55.787395,2.841945,1.279505,-69.479248,0.129000,0.000000
91.760002,12.896744,-69.523727,0.009554,0.005076,0.128922,57.367580,2.922444,1.289219,-69.523727,0.129789,0.000000
92.230003,12.750778,-69.523727,0.009589,0.005106,0.129685,56.718292,2.889368,1.296851,-69.523727,0.130570,0.000000
92.700005,12.652466,-69.568207,0.009636,0.005134,0.130396,56.280979,2.867090,1.303961,-69.568207,0.131350,0.000000
93.170006,12.723595,-69.523727,0.009675,0.005162,0.131125,56.597374,2.883208,1.311247,-69.523727,0.132139,0.000000
93.640007,12.796951,-69.523727,0.009684,0.005192,0.131879,56.923683,2.899831,1.318790,-69.523727,0.132920,0.000000
94.110008,12.928772,-69.568207,0.009727,0.005229,0.132824,57.510052,2.929702,1.328243,-69.568207,0.133700,0.000000
94.580002,12.868073,-69.612686,0.009761,0.005256,0.133510,57.240044,2.915947,1.335095,-69.612686,0.134489,0.000000
95.050003,12.992447,-69.612686,0.009813,0.005284,0.134212,57.793289,2.944130,1.342120,-69.612686,0.135270,0.000000
95.520004,13.029312,-69.568207,0.009856,0.005315,0.134992,57.957275,2.952484,1.349924,-69.568207,0.136051,0.000000
95.990005,13.149216,-69.568207,0.009856,0.005354,0.135990,58.490631,2.979655,1.359898,-69.568207,0.136840,0.000000
96.460007,13.042717,-69.612686,0.009908,0.005381,0.136675,58.016903,2.955522,1.366748,-69.612686,0.137620,0.000000
96.930008,13.240448,-69.657173,0.009908,0.005413,0.137499,58.896454,3.000328,1.374986,-69.657173,0.138401,0.000000
97.400002,13.163361,-69.657173,0.009960,0.005440,0.138166,58.553551,2.982860,1.381665,-69.657173,0.139190,0.000000
97.870003,13.254227,-69.657173,0.009998,0.005472,0.138982,58.957745,3.003451,1.389817,-69.657173,0.139970,0.000000
98.340004,13.267258,-69.701653,0.010020,0.005503,0.139788,59.015709,3.006403,1.397881,-69.701653,0.140751,0.000000
98.810005,13.382317,-69.701653,0.010046,0.005537,0.140629,59.527515,3.032476,1.406293,-69.701653,0.141540,0.000000
99.280006,13.358116,-69.746132,0.010089,0.005566,0.141384,59.419868,3.026992,1.413838,-69.746132,0.142320,0.000000
99.750008,13.448975,-69.701653,0.010128,0.005599,0.142216,59.824028,3.047581,1.422165,-69.701653,0.143101,0.000000
100.220001,13.391632,-69.701653,0.010141,0.005628,0.142945,59.568954,3.034587,1.429449,-69.701653,0.143890,0.000000
100.690002,13.569252,-69.701653,0.010167,0.005662,0.143803,60.359047,3.074836,1.438035,-69.701653,0.144671,0.000000
101.160004,13.539833,-69.746132,0.010218,0.005690,0.144532,60.228184,3.068170,1.445319,-69.746132,0.145451,0.000000
101.630005,13.700325,-69.790611,0.010240,0.005725,0.145425,60.942089,3.104538,1.454251,-69.790611,0.146240,0.000000
102.100006,13.577812,-69.746132,0.010279,0.005753,0.146128,60.397125,3.076776,1.461276,-69.746132,0.147021,0.000000
102.570007,13.651543,-69.790611,0.010313,0.005784,0.146917,60.725094,3.093484,1.469168,-69.790611,0.147801,0.000000
103.040009,13.605743,-69.790611,0.010330,0.005809,0.147550,60.521370,3.083106,1.475498,-69.790611,0.148590,0.000000
103.510002,13.682449,-69.835091,0.010361,0.005841,0.148356,60.862576,3.100487,1.483563,-69.835091,0.149371,0.000000
103.980003,13.901405,-69.790611,0.010421,0.005877,0.149284,61.836540,3.150103,1.492842,-69.790611,0.150152,0.000000
104.450005,13.789322,-69.835091,0.010412,0.005905,0.149978,61.337967,3.124705,1.499782,-69.835091,0.150941,0.000000
104.920006,13.901405,-69.835091,0.010468,0.005935,0.150741,61.836540,3.150103,1.507412,-69.835091,0.151721,0.000000
105.390007,13.930824,-69.879578,0.010494,0.005961,0.151418,61.967400,3.156770,1.514178,-69.879578,0.152502,0.000000
105.860008,14.028755,-69.924057,0.010529,0.005996,0.152294,62.403019,3.178962,1.522936,-69.924057,0.153291,0.000000
106.330002,14.013489,-69.924057,0.010555,0.006026,0.153048,62.335110,3.175502,1.530481,-69.924057,0.154071,0.000000
106.800003,14.044022,-69.924057,0.010611,0.006058,0.153881,62.470928,3.182421,1.538806,-69.924057,0.154852,0.000000
107.270004,14.293884,-69.924057,0.010632,0.006091,0.154722,63.582375,3.239041,1.547218,-69.924057,0.155641,0.000000
107.740005,14.067482,-69.924057,0.010645,0.006118,0.155398,62.575287,3.187737,1.553983,-69.924057,0.156422,0.000000
108.210007,14.112915,-69.968536,0.010701,0.006146,0.156118,62.777382,3.198032,1.561180,-69.968536,0.157202,0.000000
108.680008,14.257393,-69.968536,0.010740,0.006179,0.156951,63.420052,3.230772,1.569505,-69.968536,0.157991,0.000000
109.150002,14.437996,-69.968536,0.010740,0.006214,0.157844,64.223412,3.271697,1.578437,-69.968536,0.158772,0.000000
109.620003,14.412674,-70.013016,0.010805,0.006248,0.158702,64.110779,3.265959,1.587023,-70.013016,0.159552,0.000000
110.090004,14.307663,-70.013016,0.010826,0.006275,0.159379,63.643665,3.242163,1.593787,-70.013016,0.160341,0.000000
110.560005,14.382515,-70.013016,0.010856,0.006298,0.159977,63.976624,3.259125,1.599771,-70.013016,0.161122,0.000000
111.030006,14.570930,-70.013016,0.010869,0.006331,0.160801,64.814735,3.301820,1.608011,-70.013016,0.161902,0.000000
111.500008,14.654716,-70.057495,0.010912,0.006371,0.161824,65.187431,3.320806,1.618243,-70.057495,0.162692,0.000000
111.970009,14.552315,-70.101982,0.010964,0.006399,0.162536,64.731926,3.297602,1.625355,-70.101982,0.163472,0.000000
112.440002,14.638329,-70.101982,0.010986,0.006429,0.163307,65.114540,3.317093,1.633072,-70.101982,0.164253,0.000000
112.910004,14.687485,-70.101982,0.011007,0.006455,0.163966,65.333199,3.328232,1.639664,-70.101982,0.165042,0.000000
113.380005,14.885590,-70.101982,0.011055,0.006494,0.164955,66.214409,3.373123,1.649550,-70.101982,0.165822,0.000000
113.850006,14.773132,-70.057495,0.011068,0.006522,0.165649,65.714172,3.347640,1.656488,-70.057495,0.166603,0.000000
114.320007,14.998787,-70.101982,0.011111,0.006555,0.166499,66.717934,3.398774,1.664987,-70.101982,0.167392,0.000000
114.790009,14.664398,-70.101982,0.011128,0.006575,0.167010,65.230499,3.323000,1.670104,-70.101982,0.168173,0.000000
115.260002,15.127258,-70.146461,0.011175,0.006619,0.168120,67.289406,3.427886,1.681205,-70.146461,0.168953,0.000000
115.730003,14.911652,-70.101982,0.011201,0.006643,0.168736,66.330338,3.379029,1.687361,-70.101982,0.169742,0.000000
116.200005,14.915001,-70.146461,0.011249,0.006669,0.169395,66.345238,3.379787,1.693952,-70.146461,0.170523,0.000000
116.670006,15.056877,-70.235420,0.011244,0.006699,0.170167,66.976334,3.411937,1.701672,-70.235420,0.171303,0.000000
117.140007,15.374886,-70.279900,0.011309,0.006743,0.171277,68.390907,3.483999,1.712771,-70.279900,0.172092,0.000000
117.610008,15.219604,-70.235420,0.011344,0.006773,0.172032,67.700180,3.448812,1.720316,-70.235420,0.172873,0.000000
118.080002,15.381958,-70.190941,0.011382,0.006801,0.172734,68.422363,3.485602,1.727341,-70.190941,0.173653,0.000000
118.550003,15.232269,-70.235420,0.011395,0.006825,0.173358,67.756516,3.451682,1.733584,-70.235420,0.174443,0.000000
119.020004,15.505959,-70.279900,0.011426,0.006861,0.174278,68.973946,3.513700,1.742778,-70.279900,0.175223,0.000000
119.490005,15.529045,-70.324387,0.011477,0.006892,0.175067,69.076645,3.518932,1.750669,-70.324387,0.176003,0.000000
119.960007,15.578575,-70.279900,0.011507,0.006921,0.175795,69.296967,3.530156,1.757953,-70.279900,0.176793,0.000000
120.430008,15.485481,-70.324387,0.011507,0.006953,0.176602,68.882858,3.509060,1.766019,-70.324387,0.177573,0.000000
120.900009,15.683212,-70.324387,0.011563,0.006985,0.177426,69.762413,3.553867,1.774258,-70.324387,0.178354,0.000000
121.370003,15.833275,-70.324387,0.011598,0.007017,0.178241,70.429924,3.587871,1.782409,-70.324387,0.179143,0.000000
121.840004,15.769600,-70.324387,0.011645,0.007044,0.178917,70.146683,3.573442,1.789175,-70.324387,0.179923,0.000000
122.310005,15.859711,-70.368866,0.011654,0.007077,0.179759,70.547516,3.593862,1.797587,-70.368866,0.180704,0.000000
122.780006,16.021698,-70.324387,0.011697,0.007110,0.180582,71.268074,3.630569,1.805825,-70.324387,0.181493,0.000000
123.250008,15.989296,-70.413345,0.011740,0.007142,0.181415,71.123940,3.623226,1.814149,-70.413345,0.182274,0.000000
123.720009,15.994881,-70.457825,0.011749,0.007170,0.182117,71.148781,3.624492,1.821174,-70.457825,0.183054,0.000000
124.190002,16.141228,-70.368866,0.011792,0.007201,0.182915,71.799767,3.657655,1.829153,-70.368866,0.183843,0.000000
124.660004,16.414177,-70.413345,0.011831,0.007234,0.183739,73.013908,3.719506,1.837392,-70.413345,0.184624,0.000000
125.130005,16.326294,-70.413345,0.011835,0.007264,0.184511,72.622986,3.699591,1.845110,-70.413345,0.185404,0.000000
125.600006,16.246239,-70.413345,0.011900,0.007293,0.185231,72.266876,3.681450,1.852309,-70.413345,0.186193,0.000000
126.070007,16.391830,-70.413345,0.011913,0.007322,0.185968,72.914505,3.714442,1.859680,-70.413345,0.186974,0.000000
126.540009,16.348267,-70.457825,0.011939,0.007349,0.186653,72.720718,3.704570,1.866530,-70.457825,0.187754,0.000000
127.010010,16.582489,-70.413345,0.011969,0.007382,0.187512,73.762596,3.757646,1.875116,-70.413345,0.188544,0.000000
127.480003,16.761230,-70.457825,0.012008,0.007415,0.188353,74.557678,3.798149,1.883528,-70.457825,0.189324,0.000000
127.950005,16.754150,-70.546791,0.012033,0.007448,0.189177,74.526184,3.796545,1.891766,-70.546791,0.190105,0.000000
128.420013,16.703880,-70.502304,0.012072,0.007473,0.189810,74.302574,3.785153,1.898098,-70.502304,0.190894,0.000000
128.889999,16.897514,-70.546791,0.012111,0.007510,0.190746,75.163895,3.829032,1.907464,-70.546791,0.191674,0.000000
129.360001,16.809265,-70.546791,0.012158,0.007536,0.191414,74.771347,3.809034,1.914141,-70.546791,0.192455,0.000000
129.830002,16.952995,-70.591270,0.012154,0.007566,0.192186,75.410690,3.841604,1.921860,-70.591270,0.193244,0.000000
130.300003,17.130249,-70.635750,0.012202,0.007598,0.192993,76.199150,3.881770,1.929926,-70.635750,0.194025,0.000000
130.770004,17.314575,-70.591270,0.012232,0.007637,0.193990,77.019073,3.923539,1.939899,-70.591270,0.194805,0.000000
131.240005,17.206215,-70.546791,0.012279,0.007665,0.194684,76.537064,3.898984,1.946836,-70.546791,0.195594,0.000000
131.710007,17.124664,-70.591270,0.012292,0.007688,0.195282,76.174309,3.880504,1.952820,-70.591270,0.196375,0.000000
132.180008,17.184242,-70.635750,0.012314,0.007714,0.195941,76.439323,3.894005,1.959410,-70.635750,0.197155,0.000000
132.650009,17.666466,-70.635750,0.012340,0.007760,0.197103,78.584366,4.003278,1.971031,-70.635750,0.197944,0.000000
133.120010,17.541344,-70.680229,0.012387,0.007789,0.197840,78.027794,3.974925,1.978402,-70.680229,0.198725,0.000000
133.590012,17.681732,-70.635750,0.012417,0.007819,0.198595,78.652275,4.006738,1.985948,-70.635750,0.199505,0.000000
134.060013,17.603531,-70.635750,0.012434,0.007846,0.199280,78.304413,3.989017,1.992798,-70.635750,0.200295,0.000000
134.529999,18.024689,-70.724709,0.012473,0.007883,0.200225,80.177818,4.084453,2.002251,-70.724709,0.201075,0.000000
135.000000,17.853020,-70.680229,0.012512,0.007912,0.200953,79.414200,4.045552,2.009535,-70.680229,0.201855,0.000000
135.470001,17.959152,-70.724709,0.012538,0.007941,0.201691,79.886299,4.069602,2.016908,-70.724709,0.202645,0.000000
135.940002,17.970322,-70.635750,0.012577,0.007968,0.202393,79.935982,4.072133,2.023933,-70.635750,0.203425,0.000000
136.410004,18.361687,-70.680229,0.012603,0.008004,0.203304,81.676865,4.160818,2.033037,-70.680229,0.204206,0.000000
136.880005,18.116287,-70.813675,0.012654,0.008034,0.204067,80.585274,4.105209,2.040670,-70.813675,0.204995,0.000000
137.350006,18.104004,-70.813675,0.012667,0.008060,0.204726,80.530632,4.102426,2.047261,-70.813675,0.205775,0.000000
137.820007,18.345673,-70.769196,0.012710,0.008091,0.205524,81.605629,4.157189,2.055240,-70.769196,0.206556,0.000000
138.290009,18.699051,-70.813675,0.012736,0.008127,0.206426,83.177536,4.237266,2.064257,-70.813675,0.207345,0.000000
138.760010,18.621971,-70.813675,0.012766,0.008160,0.207276,82.834663,4.219799,2.072756,-70.813675,0.208126,0.000000
139.230011,18.463341,-70.813675,0.012801,0.008185,0.207909,82.129044,4.183853,2.079088,-70.813675,0.208906,0.000000
139.700012,18.816727,-70.813675,0.012835,0.008220,0.208776,83.700981,4.263931,2.087759,-70.813675,0.209695,0.000000
140.170013,18.905350,-70.858154,0.012861,0.008249,0.209513,84.095192,4.284013,2.095130,-70.858154,0.210476,0.000000
140.639999,19.014824,-70.813675,0.012904,0.008280,0.210302,84.582161,4.308821,2.103022,-70.813675,0.211256,0.000000
141.110001,19.002541,-70.947121,0.012913,0.008310,0.211065,84.527519,4.306037,2.110654,-70.947121,0.212045,0.000000
141.580002,19.256119,-70.991600,0.012982,0.008344,0.211950,85.655495,4.363499,2.119499,-70.991600,0.212826,0.000000
142.050003,19.349586,-70.858154,0.013004,0.008375,0.212731,86.071259,4.384679,2.127306,-70.858154,0.213606,0.000000
142.520004,19.187233,-70.902634,0.013034,0.008403,0.213424,85.349075,4.347889,2.134243,-70.902634,0.214396,0.000000
142.990005,19.463531,-70.902634,0.013055,0.008435,0.214239,86.578110,4.410500,2.142394,-70.902634,0.215176,0.000000
143.460007,19.605782,-70.991600,0.013073,0.008466,0.215037,87.210869,4.442734,2.150373,-70.991600,0.215957,0.000000
143.930008,19.771111,-70.947121,0.013133,0.008499,0.215870,87.946289,4.480197,2.158700,-70.947121,0.216746,0.000000
144.400009,19.918945,-70.947121,0.013163,0.008533,0.216728,88.603897,4.513697,2.167284,-70.947121,0.217526,0.000000
144.870010,19.783401,-70.947121,0.013189,0.008558,0.217370,88.000961,4.482983,2.173701,-70.947121,0.218307,0.000000
145.340012,20.043694,-70.991600,0.013215,0.008590,0.218185,89.158798,4.541966,2.181854,-70.991600,0.219096,0.000000
145.810013,19.968842,-71.036079,0.013258,0.008618,0.218888,88.825844,4.525004,2.188879,-71.036079,0.219876,0.000000
146.280014,20.374359,-70.991600,0.013305,0.008654,0.219807,90.629677,4.616896,2.198070,-70.991600,0.220657,0.000000
146.750000,20.265999,-71.036079,0.013323,0.008681,0.220501,90.147667,4.592341,2.205008,-71.036079,0.221446,0.000000
147.220001,20.521072,-71.036079,0.013344,0.008713,0.221316,91.282288,4.650141,2.213161,-71.036079,0.222227,0.000000
147.690002,20.536339,-71.036079,0.013396,0.008740,0.222001,91.350197,4.653601,2.220011,-71.036079,0.223007,0.000000
148.160004,20.857323,-70.991600,0.013409,0.008774,0.222860,92.778008,4.726337,2.228597,-70.991600,0.223796,0.000000
148.630005,20.838707,-71.036079,0.013435,0.008803,0.223597,92.695198,4.722118,2.235968,-71.036079,0.224577,0.000000
149.100006,21.070320,-71.036079,0.013473,0.008838,0.224473,93.725464,4.774603,2.244729,-71.036079,0.225357,0.000000
149.570007,20.954887,-71.125038,0.013495,0.008862,0.225088,93.211998,4.748446,2.250885,-71.125038,0.226147,0.000000
150.040009,21.326889,-71.125038,0.013521,0.008898,0.226008,94.866737,4.832742,2.260078,-71.125038,0.226927,0.000000
150.510010,21.387955,-71.125038,0.013573,0.008928,0.226762,95.138374,4.846580,2.267623,-71.125038,0.227707,0.000000
150.980011,21.459450,-71.080559,0.013607,0.008956,0.227482,95.456398,4.862781,2.274820,-71.080559,0.228497,0.000000
151.450012,21.482910,-71.080559,0.013633,0.008984,0.228193,95.560760,4.868097,2.281932,-71.080559,0.229277,0.000000
151.920013,21.899597,-71.125038,0.013663,0.009023,0.229182,97.414276,4.962520,2.291818,-71.125038,0.230058,0.000000
152.390015,21.878738,-71.169525,0.013711,0.009052,0.229919,97.321487,4.957793,2.299189,-71.169525,0.230847,0.000000
152.860001,21.802032,-71.214005,0.013728,0.009078,0.230578,96.980286,4.940411,2.305781,-71.214005,0.231627,0.000000
153.330002,21.932365,-71.258484,0.013758,0.009102,0.231202,97.560036,4.969945,2.312024,-71.258484,0.232408,0.000000
153.800003,22.649178,-71.169525,0.013793,0.009145,0.232278,100.748573,5.132377,2.322779,-71.169525,0.233197,0.000000
154.270004,22.525925,-71.258484,0.013827,0.009177,0.233102,100.200317,5.104447,2.331017,-71.258484,0.233977,0.000000
154.740005,22.415703,-71.258484,0.013831,0.009202,0.233735,99.710030,5.079471,2.337347,-71.258484,0.234758,0.000000
155.210007,22.671898,-71.214005,0.013874,0.009232,0.234498,100.849640,5.137526,2.344979,-71.214005,0.235547,0.000000
155.680008,22.854729,-71.214005,0.013918,0.009265,0.235322,101.662910,5.178956,2.353217,-71.214005,0.236328,0.000000
156.150009,23.142944,-71.214005,0.013948,0.009299,0.236198,102.944962,5.244266,2.361977,-71.214005,0.237108,0.000000
156.620010,22.994370,-71.302963,0.013961,0.009326,0.236874,102.284065,5.210598,2.368741,-71.302963,0.237897,0.000000
157.090012,23.350357,-71.347443,0.014004,0.009358,0.237689,103.867577,5.291266,2.376893,-71.347443,0.238678,0.000000
157.560013,23.412170,-71.258484,0.014025,0.009384,0.238357,104.142532,5.305274,2.383570,-71.258484,0.239458,0.000000
158.030014,23.929024,-71.302963,0.014060,0.009424,0.239380,106.441612,5.422394,2.393804,-71.302963,0.240248,0.000000
158.500000,23.746193,-71.347443,0.014073,0.009450,0.240031,105.628342,5.380964,2.400308,-71.347443,0.241028,0.000000
158.970001,24.178886,-71.391930,0.014137,0.009480,0.240785,107.553055,5.479014,2.407854,-71.391930,0.241809,0.000000
159.440002,24.240326,-71.391930,0.014159,0.009507,0.241479,107.826355,5.492936,2.414791,-71.391930,0.242598,0.000000
159.910004,24.723297,-71.302963,0.014198,0.009548,0.242528,109.974716,5.602379,2.425283,-71.302963,0.243378,0.000000
160.380005,24.636902,-71.391930,0.014224,0.009575,0.243196,109.590416,5.582802,2.431962,-71.391930,0.244159,0.000000
160.850006,24.993637,-71.391930,0.014250,0.009608,0.244055,111.177254,5.663639,2.440547,-71.391930,0.244948,0.000000
161.320007,25.025291,-71.436409,0.014288,0.009634,0.244705,111.318054,5.670812,2.447052,-71.436409,0.245728,0.000000
161.790009,25.240150,-71.436409,0.014306,0.009666,0.245529,112.273796,5.719500,2.455290,-71.436409,0.246509,0.000000
162.260010,25.386116,-71.391930,0.014340,0.009694,0.246231,112.923080,5.752576,2.462315,-71.391930,0.247298,0.000000
162.730011,25.702263,-71.436409,0.014383,0.009729,0.247125,114.329376,5.824216,2.471247,-71.436409,0.248079,0.000000
163.200012,25.887329,-71.525368,0.014405,0.009760,0.247897,115.152588,5.866152,2.478966,-71.525368,0.248859,0.000000
163.670013,26.152458,-71.436409,0.014457,0.009793,0.248738,116.331947,5.926231,2.487378,-71.436409,0.249648,0.000000
164.140015,26.242577,-71.480888,0.014469,0.009820,0.249432,116.732811,5.946653,2.494316,-71.480888,0.250429,0.000000
164.610001,26.778793,-71.480888,0.014504,0.009855,0.250307,119.118019,6.068161,2.503074,-71.480888,0.251209,0.000000
165.080002,26.775436,-71.480888,0.014534,0.009883,0.251036,119.103088,6.067400,2.510358,-71.480888,0.251998,0.000000
165.550003,27.066635,-71.569847,0.014569,0.009916,0.251877,120.398407,6.133387,2.518770,-71.569847,0.252779,0.000000
166.020004,27.125839,-71.525368,0.014625,0.009945,0.252614,120.661758,6.146803,2.526143,-71.525368,0.253560,0.000000
166.490005,27.371605,-71.569847,0.014633,0.009975,0.253377,121.754982,6.202495,2.533773,-71.569847,0.254349,0.000000
166.960007,27.525024,-71.614334,0.014668,0.010004,0.254097,122.437424,6.237260,2.540972,-71.614334,0.255129,0.000000
167.430008,27.976715,-71.614334,0.014676,0.010036,0.254912,124.446648,6.339614,2.549123,-71.614334,0.255910,0.000000
167.900009,28.284294,-71.658813,0.014741,0.010071,0.255814,125.814827,6.409312,2.558142,-71.658813,0.256699,0.000000
168.370010,28.268280,-71.569847,0.014758,0.010099,0.256508,125.743591,6.405684,2.565080,-71.569847,0.257479,0.000000
168.840012,28.566551,-71.614334,0.014789,0.010129,0.257280,127.070366,6.473273,2.572799,-71.614334,0.258260,0.000000
169.310013,28.882324,-71.569847,0.014806,0.010157,0.257991,128.474991,6.544828,2.579911,-71.569847,0.259049,0.000000
169.780014,29.062927,-71.703293,0.014836,0.010190,0.258815,129.278351,6.585753,2.588149,-71.703293,0.259830,0.000000
170.250015,29.382790,-71.703293,0.014875,0.010221,0.259604,130.701172,6.658236,2.596040,-71.703293,0.260610,0.000000
170.720001,29.651642,-71.658813,0.014931,0.010251,0.260385,131.897095,6.719158,2.603845,-71.658813,0.261399,0.000000
171.190002,30.169243,-71.658813,0.014944,0.010285,0.261243,134.199493,6.836448,2.612431,-71.658813,0.262180,0.000000
171.660004,30.226212,-71.703293,0.014970,0.010312,0.261937,134.452911,6.849357,2.619369,-71.703293,0.262960,0.000000
172.130005,30.191956,-71.747772,0.015004,0.010339,0.262605,134.300522,6.841595,2.626047,-71.747772,0.263749,0.000000
172.600006,30.816055,-71.792252,0.015034,0.010374,0.263489,137.076660,6.983018,2.634892,-71.792252,0.264530,0.000000
173.070007,31.199226,-71.703293,0.015064,0.010406,0.264322,138.781097,7.069846,2.643217,-71.703293,0.265310,0.000000
173.540009,31.572716,-71.747772,0.015099,0.010443,0.265241,140.442459,7.154480,2.652411,-71.747772,0.266099,0.000000
174.010010,31.494514,-71.747772,0.015112,0.010465,0.265822,140.094604,7.136759,2.658221,-71.747772,0.266880,0.000000
174.480011,31.766350,-71.792252,0.015159,0.010494,0.266542,141.303787,7.198358,2.665420,-71.792252,0.267661,0.000000
174.950012,32.394913,-71.792252,0.015177,0.010526,0.267366,144.099762,7.340792,2.673657,-71.792252,0.268450,0.000000
175.420013,32.833199,-71.836739,0.015211,0.010564,0.268328,146.049362,7.440109,2.683284,-71.836739,0.269230,0.000000
175.890015,32.968735,-71.836739,0.015233,0.010593,0.269066,146.652252,7.470822,2.690655,-71.836739,0.270011,0.000000
176.360016,33.297546,-71.836739,0.015289,0.010623,0.269820,148.114883,7.545332,2.698200,-71.836739,0.270800,0.000000
176.830002,33.461761,-71.836739,0.015302,0.010650,0.270514,148.845352,7.582543,2.705138,-71.836739,0.271580,0.000000
177.300003,32.978050,-71.836739,0.015310,0.010659,0.270730,146.693695,7.472933,2.707305,-71.836739,0.270939,0.000000
177.770004,32.185265,-71.881218,0.015327,0.010652,0.270566,143.167206,7.293285,2.705659,-71.881218,0.270366,0.000000
178.240005,31.699318,-71.925697,0.015323,0.010626,0.269898,141.005615,7.183168,2.698980,-71.925697,0.269586,0.000000
178.710007,31.287102,-71.925697,0.015315,0.010593,0.269057,139.171982,7.089758,2.690568,-71.925697,0.268805,0.000000
179.180008,31.096077,-71.970177,0.015340,0.010569,0.268441,138.322266,7.046472,2.684410,-71.970177,0.268016,0.000000
179.650009,30.851799,-71.970177,0.015349,0.010536,0.267609,137.235657,6.991117,2.676085,-71.970177,0.267236,0.000000
180.120010,30.735992,-71.970177,0.015323,0.010507,0.266880,136.720520,6.964876,2.668801,-71.970177,0.266455,0.000000
180.590012,30.550179,-72.059143,0.015319,0.010476,0.266091,135.893982,6.922770,2.660910,-72.059143,0.265666,0.000000
181.060013,30.380379,-71.970177,0.015332,0.010447,0.265354,135.138672,6.884292,2.653537,-71.970177,0.264885,0.000000
181.530014,30.225098,-71.970177,0.015353,0.010420,0.264669,134.447952,6.849105,2.646686,-71.970177,0.264105,0.000000
182.000015,29.651276,-72.014656,0.015323,0.010387,0.263836,131.895462,6.719075,2.638361,-72.014656,0.263316,0.000000
182.470001,28.933708,-71.970177,0.015323,0.010358,0.263099,128.703568,6.556472,2.630990,-71.970177,0.262535,0.000000
182.940002,28.161041,-72.014656,0.015349,0.010331,0.262414,125.266571,6.381383,2.624140,-72.014656,0.261755,0.000000
183.410004,26.824219,-72.103622,0.015349,0.010304,0.261729,119.320084,6.078455,2.617287,-72.103622,0.260966,0.000000
183.880005,25.295258,-72.103622,0.015336,0.010273,0.260931,112.518929,5.731987,2.609308,-72.103622,0.260185,0.000000
184.350006,23.415894,-72.059143,0.015332,0.010242,0.260159,104.159096,5.306118,2.601591,-72.059143,0.259405,0.000000
184.820007,21.783417,-72.103622,0.015340,0.010220,0.259578,96.897476,4.936193,2.595781,-72.103622,0.258615,0.000000
185.290009,19.316078,-72.148102,0.015310,0.010182,0.258624,85.922211,4.377086,2.586241,-72.148102,0.257835,0.000000
185.760010,17.683968,-72.148102,0.015310,0.010158,0.258026,78.662216,4.007244,2.580257,-72.148102,0.257054,0.000000
186.230011,15.453827,-72.192581,0.015293,0.010123,0.257115,68.742058,3.501887,2.571151,-72.192581,0.256265,0.000000
186.700012,13.688034,-72.103622,0.015284,0.010093,0.256361,60.887417,3.101753,2.563606,-72.103622,0.255485,0.000000
187.170013,11.662704,-72.148102,0.015246,0.010058,0.255476,51.878300,2.642807,2.554760,-72.148102,0.254704,0.000000
187.640015,10.026123,-72.237068,0.015228,0.010029,0.254739,44.598423,2.271952,2.547390,-72.237068,0.253915,0.000000
188.110016,8.404816,-72.237068,0.015198,0.009997,0.253932,37.386486,1.904559,2.539324,-72.237068,0.253135,0.000000
188.580002,7.049011,-72.148102,0.015194,0.009970,0.253239,31.355568,1.597329,2.532386,-72.148102,0.252354,0.000000
189.050003,5.401260,-72.192581,0.015168,0.009935,0.252345,24.026007,1.223943,2.523454,-72.192581,0.251565,0.000000
189.520004,4.229034,-72.237068,0.015142,0.009907,0.251626,18.811686,0.958313,2.516257,-72.237068,0.250784,0.000000
189.990005,2.776405,-72.281548,0.015116,0.009870,0.250698,12.350068,0.629142,2.506976,-72.281548,0.250004,0.000000
190.460007,2.081558,-72.326027,0.015082,0.009846,0.250099,9.259233,0.471688,2.500992,-72.326027,0.249215,0.000000
190.930008,1.122704,-72.326027,0.015052,0.009809,0.249154,4.994035,0.254408,2.491539,-72.326027,0.248434,0.000000
191.400009,0.951035,-72.237068,0.015047,0.009784,0.248504,4.230413,0.215508,2.485035,-72.237068,0.247654,0.000000
191.870010,0.609200,-72.237068,0.015000,0.009747,0.247567,2.709855,0.138047,2.475670,-72.237068,0.246864,0.000000
192.340012,0.564140,-72.326027,0.014935,0.009724,0.246995,2.509422,0.127836,2.469947,-72.326027,0.246084,0.000000
192.810013,0.390991,-72.326027,0.014926,0.009687,0.246041,1.739216,0.088600,2.460407,-72.326027,0.245304,0.000000
193.280014,0.472542,-72.281548,0.014914,0.009660,0.245364,2.101971,0.107080,2.453641,-72.281548,0.244514,0.000000
193.750015,0.485573,-72.326027,0.014853,0.009622,0.244410,2.159936,0.110032,2.444103,-72.326027,0.243734,0.000000
194.220016,0.530998,-72.281548,0.014832,0.009603,0.243907,2.361998,0.120326,2.439073,-72.281548,0.242953,0.000000
194.690002,0.407372,-72.370506,0.014789,0.009567,0.243005,1.812079,0.092312,2.430054,-72.370506,0.242164,0.000000
195.160004,0.446098,-72.370506,0.014780,0.009538,0.242277,1.984344,0.101087,2.422770,-72.370506,0.241384,0.000000
195.630005,0.446098,-72.370506,0.014728,0.009512,0.241600,1.984344,0.101087,2.416004,-72.370506,0.240603,0.000000
196.100006,0.428223,-72.370506,0.014707,0.009477,0.240716,1.904830,0.097037,2.407159,-72.370506,0.239814,0.000000
196.570007,0.440140,-72.414986,0.014663,0.009462,0.240343,1.957839,0.099737,2.403429,-72.414986,0.239034,0.000000
197.040009,0.356361,-72.503952,0.014633,0.009414,0.239120,1.585175,0.080753,2.391202,-72.503952,0.238253,0.000000
197.510010,0.379814,-72.459473,0.014607,0.009386,0.238409,1.689498,0.086067,2.384090,-72.459473,0.237464,0.000000
197.980011,0.374603,-72.459473,0.014564,0.009356,0.237646,1.666319,0.084886,2.376460,-72.459473,0.236683,0.000000
198.450012,0.298637,-72.414986,0.014538,0.009319,0.236701,1.328405,0.067672,2.367007,-72.414986,0.235903,0.000000
198.920013,0.294174,-72.503952,0.014487,0.009296,0.236111,1.308552,0.066661,2.361110,-72.503952,0.235114,0.000000
199.390015,0.283745,-72.503952,0.014452,0.009256,0.235105,1.262160,0.064297,2.351050,-72.503952,0.234333,0.000000
199.860016,0.318748,-72.548431,0.014439,0.009231,0.234463,1.417864,0.072229,2.344633,-72.548431,0.233553,0.000000
200.330017,0.263634,-72.503952,0.014405,0.009193,0.233492,1.172701,0.059740,2.334919,-72.503952,0.232763,0.000000
200.800003,0.234222,-72.548431,0.014362,0.009162,0.232720,1.041873,0.053076,2.327201,-72.548431,0.231983,0.000000
201.270004,0.247627,-72.592911,0.014353,0.009141,0.232174,1.101501,0.056113,2.321738,-72.592911,0.232078,0.000000
201.400009,0.266991,-72.503952,0.014340,0.009142,0.232208,1.187634,0.060501,2.322084,-72.503952,0.232078,0.000000