File: PDMS and AD/PDMS0017 Test 1-3_02142024_152054.csv
Time (sec),S:Load (lbs),S:HL1 (DIM),S:LVDT (in),S:Position (in),Ch:Position (mm),Ch:Load (N),Ch:Stress (MPa),Ch:Strain (mm/mm),Ch:HL1 (DIM),Set Point (),Cycles ()
0.110000,0.011917,-92.965187,-0.000004,-0.000000,-0.000000,0.053010,0.002700,-0.000000,-92.965187,0.000217,0.000000
0.570000,0.045059,-93.009666,-0.000017,0.000057,0.001448,0.200433,0.010211,0.014483,-93.009666,0.001891,0.000000
1.030000,0.017502,-93.009666,0.000026,0.000181,0.004596,0.077852,0.003966,0.045962,-93.009666,0.005724,0.000000
1.490000,0.025322,-93.054146,0.000155,0.000330,0.008377,0.112638,0.005738,0.083773,-93.054146,0.009557,0.000000
1.950000,0.007446,-93.009666,0.000315,0.000492,0.012497,0.033123,0.001687,0.124966,-93.009666,0.013390,0.000000
2.410000,-0.011543,-93.054146,0.000487,0.000641,0.016269,-0.051347,-0.002616,0.162692,-93.054146,0.017223,0.000000
2.870000,-0.005585,-93.054146,0.000647,0.000787,0.019990,-0.024842,-0.001266,0.199895,-93.054146,0.021047,0.000000
3.330000,0.016014,-93.054146,0.000780,0.000940,0.023866,0.071234,0.003629,0.238660,-93.054146,0.024881,0.000000
3.790000,0.033890,-93.054146,0.000940,0.001083,0.027517,0.150749,0.007680,0.275169,-93.054146,0.028714,0.000000
4.250000,0.029793,-93.143112,0.001091,0.001227,0.031177,0.132525,0.006751,0.311767,-93.143112,0.032547,0.000000
4.710000,0.030907,-93.054146,0.001263,0.001392,0.035348,0.137480,0.007004,0.353481,-93.054146,0.036380,0.000000
5.170000,-0.002235,-93.143112,0.001444,0.001543,0.039190,-0.009944,-0.000507,0.391899,-93.143112,0.040213,0.000000
5.630000,0.014526,-93.098633,0.001578,0.001695,0.043049,0.064617,0.003292,0.430490,-93.098633,0.044038,0.000000
6.090000,0.002983,-93.098633,0.001746,0.001843,0.046813,0.013269,0.000676,0.468127,-93.098633,0.047871,0.000000
6.550000,0.027557,-93.143112,0.001876,0.001993,0.050620,0.122581,0.006245,0.506199,-93.143112,0.051704,0.000000
7.010000,0.139641,-93.143112,0.002048,0.002149,0.054583,0.621153,0.031643,0.545831,-93.143112,0.055537,0.000000
7.470000,0.361946,-93.187592,0.002207,0.002296,0.058330,1.610017,0.082018,0.583296,-93.187592,0.059370,0.000000
7.930000,0.356361,-93.143112,0.002276,-0.000000,-0.000000,1.585175,0.080753,-0.000000,-93.143112,0.000225,0.000000
8.390000,0.442749,-93.232071,0.002264,-0.000000,-0.000000,1.969446,0.100328,-0.000000,-93.232071,0.000702,0.000000
8.850000,0.494141,-93.232071,0.002246,0.000023,0.000590,2.198047,0.111974,0.005897,-93.232071,0.001474,0.000000
9.310000,0.618881,-93.232071,0.002294,0.000052,0.001318,2.752921,0.140240,0.013181,-93.232071,0.002237,0.000000
9.770000,0.709000,-93.232071,0.002311,0.000088,0.002246,3.153788,0.160662,0.022461,-93.232071,0.003001,0.000000
10.230000,0.751076,-93.232071,0.002358,0.000113,0.002870,3.340952,0.170196,0.028705,-93.232071,0.003772,0.000000
10.690001,0.875824,-93.276558,0.002389,0.000146,0.003712,3.895860,0.198465,0.037117,-93.276558,0.004536,0.000000
11.150001,0.940987,-93.321037,0.002414,0.000167,0.004241,4.185718,0.213231,0.042408,-93.321037,0.005307,0.000000
11.610001,1.121216,-93.232071,0.002440,0.000208,0.005281,4.987417,0.254071,0.052814,-93.232071,0.006071,0.000000
12.070001,1.187866,-93.321037,0.002462,0.000234,0.005940,5.283893,0.269174,0.059404,-93.321037,0.006842,0.000000
12.530001,1.272400,-93.276558,0.002514,0.000263,0.006678,5.659917,0.288330,0.066777,-93.276558,0.007606,0.000000
12.990001,1.381500,-93.276558,0.002518,0.000292,0.007415,6.145220,0.313052,0.074148,-93.276558,0.008369,0.000000
13.450001,1.431770,-93.365517,0.002548,0.000311,0.007900,6.368833,0.324444,0.079004,-93.365517,0.009141,0.000000
13.910001,1.623917,-93.365517,0.002587,0.000354,0.008993,7.223542,0.367985,0.089931,-93.365517,0.009904,0.000000
14.370001,1.723343,-93.365517,0.002626,0.000385,0.009791,7.665812,0.390515,0.097910,-93.365517,0.010675,0.000000
14.830001,1.833939,-93.365517,0.002639,0.000416,0.010563,8.157766,0.415576,0.105629,-93.365517,0.011439,0.000000
15.290001,1.982513,-93.409996,0.002665,0.000448,0.011387,8.818660,0.449244,0.113867,-93.409996,0.012202,0.000000
15.750001,2.041718,-93.454475,0.002725,0.000472,0.011985,9.082013,0.462660,0.119851,-93.454475,0.012974,0.000000
16.210001,2.109123,-93.409996,0.002725,0.000502,0.012748,9.381848,0.477934,0.127483,-93.409996,0.013737,0.000000
16.670000,2.312431,-93.409996,0.002772,0.000535,0.013589,10.286208,0.524004,0.135895,-93.409996,0.014509,0.000000
17.130001,2.406647,-93.409996,0.002820,0.000565,0.014353,10.705299,0.545354,0.143525,-93.409996,0.015272,0.000000
17.590000,2.528786,-93.409996,0.002824,0.000600,0.015229,11.248601,0.573031,0.152285,-93.409996,0.016035,0.000000
18.050001,2.621132,-93.543442,0.002871,0.000626,0.015896,11.659377,0.593957,0.158962,-93.543442,0.016807,0.000000
18.510000,2.798012,-93.409996,0.002884,0.000658,0.016703,12.446178,0.634039,0.167027,-93.409996,0.017570,0.000000
18.970001,2.794655,-93.498962,0.002923,0.000679,0.017249,12.431246,0.633278,0.172491,-93.498962,0.018342,0.000000
19.430000,3.031487,-93.543442,0.002962,0.000719,0.018272,13.484726,0.686945,0.182723,-93.543442,0.019105,0.000000
19.890001,3.048988,-93.543442,0.002997,0.000748,0.019010,13.562577,0.690911,0.190096,-93.543442,0.019877,0.000000
20.350000,3.229958,-93.587921,0.003022,0.000776,0.019712,14.367569,0.731919,0.197121,-93.587921,0.020640,0.000000
20.810001,3.304810,-93.454475,0.003027,0.000805,0.020458,14.700527,0.748881,0.204579,-93.454475,0.021403,0.000000
21.270000,3.461205,-93.587921,0.003087,0.000839,0.021308,15.396207,0.784320,0.213076,-93.587921,0.022175,0.000000
21.730001,3.489502,-93.543442,0.003096,0.000868,0.022053,15.522079,0.790732,0.220534,-93.543442,0.022938,0.000000
22.190001,3.648506,-93.543442,0.003126,0.000897,0.022782,16.229366,0.826763,0.227820,-93.543442,0.023710,0.000000
22.650002,3.768036,-93.676880,0.003178,0.000925,0.023485,16.761061,0.853849,0.234845,-93.676880,0.024473,0.000000
23.110001,3.963905,-93.543442,0.003186,0.000960,0.024378,17.632332,0.898234,0.243778,-93.543442,0.025236,0.000000
23.570002,4.023483,-93.676880,0.003242,0.000989,0.025132,17.897348,0.911734,0.251323,-93.676880,0.026008,0.000000
24.030001,4.116203,-93.676880,0.003255,0.001018,0.025852,18.309786,0.932745,0.258520,-93.676880,0.026771,0.000000
24.490002,4.211533,-93.632401,0.003294,0.001045,0.026554,18.733833,0.954347,0.265544,-93.632401,0.027543,0.000000
24.950001,4.329201,-93.676880,0.003316,0.001072,0.027231,19.257246,0.981011,0.272308,-93.676880,0.028306,0.000000
25.410002,4.486343,-93.632401,0.003346,0.001112,0.028246,19.956251,1.016620,0.282455,-93.632401,0.029069,0.000000
25.870001,4.525818,-93.632401,0.003380,0.001138,0.028905,20.131844,1.025565,0.289047,-93.632401,0.029841,0.000000
26.330002,4.743652,-93.676880,0.003415,0.001170,0.029720,21.100819,1.074927,0.297198,-93.676880,0.030604,0.000000
26.790001,4.827438,-93.676880,0.003432,0.001195,0.030361,21.473518,1.093913,0.303615,-93.676880,0.031376,0.000000
27.250002,5.006180,-93.765846,0.003475,0.001232,0.031281,22.268600,1.134417,0.312808,-93.765846,0.032139,0.000000
27.710001,4.985321,-93.721367,0.003501,0.001255,0.031888,22.175816,1.129690,0.318879,-93.721367,0.032902,0.000000
28.170002,5.237045,-93.810326,0.003540,0.001294,0.032877,23.295542,1.186731,0.328765,-93.810326,0.033674,0.000000
28.630001,5.265724,-93.765846,0.003540,0.001319,0.033501,23.423111,1.193230,0.335009,-93.765846,0.034437,0.000000
29.090002,5.450790,-93.765846,0.003609,0.001351,0.034325,24.246326,1.235167,0.343248,-93.765846,0.035209,0.000000
29.550001,5.500313,-93.854805,0.003613,0.001379,0.035027,24.466614,1.246389,0.350273,-93.854805,0.035973,0.000000
30.010002,5.661926,-93.765846,0.003656,0.001412,0.035877,25.185507,1.283011,0.358770,-93.765846,0.036744,0.000000
30.470001,5.673096,-93.810326,0.003682,0.001436,0.036484,25.235189,1.285542,0.364841,-93.810326,0.037508,0.000000
30.930002,5.896149,-93.854805,0.003721,0.001472,0.037386,26.227379,1.336086,0.373861,-93.854805,0.038271,0.000000
31.390001,5.924446,-93.765846,0.003747,0.001504,0.038201,26.353252,1.342499,0.382013,-93.765846,0.039043,0.000000
31.850002,6.028343,-93.988251,0.003738,0.001533,0.038947,26.815411,1.366042,0.389471,-93.988251,0.039806,0.000000
32.310001,6.081589,-93.854805,0.003803,0.001560,0.039632,27.052258,1.378108,0.396322,-93.854805,0.040577,0.000000
32.770000,6.349327,-93.810326,0.003842,0.001595,0.040508,28.243217,1.438778,0.405080,-93.810326,0.041341,0.000000
33.230003,6.345970,-93.899284,0.003863,0.001623,0.041219,28.228285,1.438017,0.412192,-93.899284,0.042104,0.000000
33.690002,6.337784,-93.899284,0.003906,0.001650,0.041904,28.191870,1.436162,0.419043,-93.899284,0.042876,0.000000
34.150002,6.494179,-93.988251,0.003915,0.001683,0.042737,28.887550,1.471602,0.427370,-93.988251,0.043639,0.000000
34.610001,6.474815,-93.943771,0.003954,0.001706,0.043335,28.801416,1.467214,0.433353,-93.943771,0.044411,0.000000
35.070004,6.642380,-93.943771,0.003980,0.001740,0.044194,29.546782,1.505185,0.441938,-93.943771,0.045174,0.000000
35.530003,6.771599,-94.032730,0.004014,0.001774,0.045061,30.121576,1.534466,0.450611,-94.032730,0.045937,0.000000
35.990002,6.828568,-93.899284,0.004053,0.001807,0.045894,30.374985,1.547376,0.458936,-93.899284,0.046709,0.000000
36.450001,6.872139,-94.032730,0.004066,0.001831,0.046509,30.568800,1.557249,0.465094,-94.032730,0.047472,0.000000
36.910000,6.950706,-94.032730,0.004100,0.001864,0.047333,30.918287,1.575052,0.473331,-94.032730,0.048244,0.000000
37.370003,7.045288,-93.988251,0.004169,0.001893,0.048088,31.339006,1.596485,0.480877,-93.988251,0.049007,0.000000
37.830002,7.177109,-94.032730,0.004195,0.001924,0.048868,31.925375,1.626356,0.488681,-94.032730,0.049779,0.000000
38.290001,7.233337,-94.032730,0.004225,0.001953,0.049605,32.175491,1.639098,0.496052,-94.032730,0.050542,0.000000
38.750000,7.388992,-94.032730,0.004260,0.001987,0.050481,32.867878,1.674370,0.504812,-94.032730,0.051305,0.000000
39.210003,7.341324,-94.077209,0.004260,0.002015,0.051184,32.655838,1.663568,0.511837,-94.077209,0.052077,0.000000
39.670002,7.394203,-94.077209,0.004299,0.002040,0.051817,32.891060,1.675550,0.518167,-94.077209,0.052840,0.000000
40.130001,7.461601,-94.121689,0.004329,0.002068,0.052519,33.190861,1.690823,0.525192,-94.121689,0.053612,0.000000
40.590000,7.622093,-94.121689,0.004350,0.002101,0.053360,33.904762,1.727191,0.533604,-94.121689,0.054375,0.000000
41.050003,7.702156,-94.121689,0.004381,0.002138,0.054306,34.260902,1.745333,0.543057,-94.121689,0.055138,0.000000
41.510002,7.620979,-94.166176,0.004411,0.002159,0.054843,33.899811,1.726939,0.548433,-94.166176,0.055910,0.000000
41.970001,7.823921,-94.166176,0.004458,0.002194,0.055737,34.802540,1.772926,0.557366,-94.166176,0.056673,0.000000
42.430000,7.790405,-94.166176,0.004484,0.002217,0.056318,34.653454,1.765331,0.563175,-94.166176,0.057445,0.000000
42.890003,7.899513,-94.121689,0.004523,0.002253,0.057237,35.138790,1.790055,0.572369,-94.121689,0.058208,0.000000
43.350002,7.964302,-94.210655,0.004553,0.002282,0.057974,35.426987,1.804737,0.579740,-94.210655,0.058971,0.000000
43.810001,8.137459,-94.210655,0.004562,0.002315,0.058789,36.197224,1.843974,0.587893,-94.210655,0.059743,0.000000
44.270000,8.217514,-94.121689,0.004587,0.002342,0.059474,36.553329,1.862115,0.594743,-94.121689,0.060506,0.000000
44.730003,8.276726,-94.255135,0.004652,0.002378,0.060393,36.816715,1.875533,0.603935,-94.255135,0.061278,0.000000
45.190002,8.263695,-94.210655,0.004674,0.002404,0.061070,36.758751,1.872580,0.610700,-94.210655,0.062041,0.000000
45.650002,8.403702,-94.299614,0.004712,0.002435,0.061842,37.381531,1.904306,0.618418,-94.299614,0.062813,0.000000
46.110001,8.334068,-94.255135,0.004721,0.002458,0.062440,37.071789,1.888527,0.624402,-94.255135,0.063576,0.000000
46.570004,8.643143,-94.210655,0.004769,0.002501,0.063524,38.446617,1.958564,0.635244,-94.210655,0.064339,0.000000
47.030003,8.581696,-94.344101,0.004803,0.002530,0.064270,38.173290,1.944640,0.642702,-94.344101,0.065111,0.000000
47.490002,8.700485,-94.299614,0.004842,0.002559,0.064999,38.701691,1.971558,0.649986,-94.299614,0.065874,0.000000
47.950001,8.608879,-94.255135,0.004859,0.002582,0.065580,38.294209,1.950800,0.655796,-94.255135,0.066646,0.000000
48.410004,8.892258,-94.388580,0.004889,0.002618,0.066499,39.554737,2.015014,0.664989,-94.388580,0.067409,0.000000
48.870003,8.796928,-94.344101,0.004941,0.002647,0.067227,39.130692,1.993412,0.672273,-94.344101,0.068173,0.000000
49.330002,8.888535,-94.344101,0.004980,0.002678,0.068025,39.538177,2.014171,0.680252,-94.344101,0.068945,0.000000
49.790001,8.882950,-94.299614,0.004993,0.002705,0.068719,39.513336,2.012905,0.687189,-94.299614,0.069708,0.000000
50.250004,9.050140,-94.388580,0.005023,0.002739,0.069560,40.257034,2.050791,0.695601,-94.388580,0.070479,0.000000
50.710003,9.048279,-94.388580,0.005079,0.002768,0.070297,40.248753,2.050369,0.702972,-94.388580,0.071243,0.000000
51.170002,9.050888,-94.388580,0.005083,0.002796,0.071026,40.260361,2.050961,0.710258,-94.388580,0.072006,0.000000
51.630001,9.186058,-94.388580,0.005118,0.002829,0.071850,40.861626,2.081590,0.718496,-94.388580,0.072777,0.000000
52.090004,9.253082,-94.477539,0.005118,0.002859,0.072622,41.159767,2.096778,0.726215,-94.477539,0.073541,0.000000
52.550003,9.313034,-94.433060,0.005187,0.002892,0.073463,41.426445,2.110364,0.734627,-94.433060,0.074313,0.000000
53.010002,9.318253,-94.433060,0.005191,0.002921,0.074191,41.449657,2.111546,0.741911,-94.433060,0.075076,0.000000
53.470001,9.381554,-94.477539,0.005230,0.002951,0.074954,41.731236,2.125890,0.749544,-94.477539,0.075839,0.000000
53.930004,9.384903,-94.522018,0.005256,0.002975,0.075561,41.746132,2.126649,0.755613,-94.522018,0.076611,0.000000
54.390003,9.480232,-94.477539,0.005282,0.003010,0.076455,42.170177,2.148251,0.764547,-94.477539,0.077374,0.000000
54.850002,9.471298,-94.522018,0.005307,0.003039,0.077192,42.130440,2.146227,0.771918,-94.522018,0.078146,0.000000
55.310001,9.599388,-94.566505,0.005355,0.003071,0.078007,42.700211,2.175252,0.780069,-94.566505,0.078909,0.000000
55.770004,9.482841,-94.522018,0.005394,0.003096,0.078649,42.181786,2.148843,0.786486,-94.522018,0.079681,0.000000
56.230003,9.809410,-94.610985,0.005420,0.003131,0.079525,43.634434,2.222844,0.795246,-94.610985,0.080444,0.000000
56.690002,9.756531,-94.566505,0.005454,0.003162,0.080305,43.399216,2.210861,0.803051,-94.566505,0.081207,0.000000
57.150002,9.764351,-94.566505,0.005467,0.003193,0.081103,43.434002,2.212634,0.811029,-94.566505,0.081979,0.000000
57.610004,9.710358,-94.655464,0.005501,0.003219,0.081771,43.193829,2.200399,0.817708,-94.655464,0.082742,0.000000
58.070004,9.901756,-94.566505,0.005549,0.003254,0.082655,44.045212,2.243770,0.826553,-94.566505,0.083514,0.000000
58.530003,9.863777,-94.610985,0.005592,0.003282,0.083366,43.876270,2.235164,0.833665,-94.610985,0.084277,0.000000
58.990002,9.817978,-94.655464,0.005605,0.003308,0.084034,43.672546,2.224786,0.840341,-94.655464,0.085040,0.000000
59.450005,9.926338,-94.610985,0.005639,0.003340,0.084841,44.154556,2.249341,0.848407,-94.610985,0.085812,0.000000
59.910004,9.922981,-94.699944,0.005670,0.003370,0.085595,44.139626,2.248580,0.855952,-94.699944,0.086575,0.000000
60.370003,10.037300,-94.655464,0.005704,0.003407,0.086540,44.648140,2.274485,0.865405,-94.655464,0.087347,0.000000
60.830002,9.966179,-94.655464,0.005726,0.003430,0.087113,44.331779,2.258368,0.871128,-94.655464,0.088110,0.000000
61.290005,10.008255,-94.699944,0.005730,0.003456,0.087789,44.518940,2.267903,0.877893,-94.699944,0.088873,0.000000
61.750004,10.144920,-94.699944,0.005786,0.003486,0.088535,45.126858,2.298872,0.885351,-94.699944,0.089645,0.000000
62.210003,10.200027,-94.744423,0.005812,0.003524,0.089498,45.371986,2.311359,0.894976,-94.744423,0.090408,0.000000
62.670002,10.197052,-94.655464,0.005855,0.003554,0.090270,45.358753,2.310685,0.902696,-94.655464,0.091180,0.000000
63.130005,10.267426,-94.699944,0.005864,0.003582,0.090972,45.671791,2.326632,0.909720,-94.699944,0.091943,0.000000
63.590004,10.186996,-94.744423,0.005902,0.003607,0.091614,45.314022,2.308407,0.916138,-94.744423,0.092715,0.000000
64.050003,10.402969,-94.744423,0.005959,0.003648,0.092663,46.274719,2.357347,0.926631,-94.744423,0.093478,0.000000
64.510002,10.271896,-94.788910,0.005989,0.003672,0.093270,45.691677,2.327645,0.932700,-94.788910,0.094241,0.000000
64.970001,10.475212,-94.744423,0.005997,0.003705,0.094103,46.596069,2.373717,0.941027,-94.744423,0.095013,0.000000
65.430000,10.263702,-94.744423,0.006036,0.003726,0.094632,45.655228,2.325788,0.946316,-94.744423,0.095776,0.000000
65.889999,10.542236,-94.877869,0.006079,0.003767,0.095690,46.894211,2.388905,0.956897,-94.877869,0.096548,0.000000
66.350006,10.393661,-94.877869,0.006109,0.003794,0.096375,46.233315,2.355237,0.963748,-94.877869,0.097311,0.000000
66.810005,10.453987,-94.877869,0.006153,0.003823,0.097094,46.501656,2.368907,0.970945,-94.877869,0.098075,0.000000
67.270004,10.486382,-94.877869,0.006170,0.003851,0.097823,46.645756,2.376248,0.978231,-94.877869,0.098846,0.000000
67.730003,10.754860,-94.877869,0.006209,0.003887,0.098734,47.840008,2.437086,0.987337,-94.877869,0.099610,0.000000
68.190002,10.590271,-94.966827,0.006226,0.003918,0.099514,47.107880,2.399790,0.995142,-94.966827,0.100381,0.000000
68.650002,10.576500,-94.922348,0.006256,0.003944,0.100173,47.046623,2.396669,1.001733,-94.922348,0.101145,0.000000
69.110001,10.731033,-94.877869,0.006303,0.003977,0.101006,47.734020,2.431687,1.010058,-94.877869,0.101908,0.000000
69.570000,10.817047,-94.922348,0.006325,0.004006,0.101743,48.116631,2.451178,1.017429,-94.922348,0.102679,0.000000
70.030006,10.787262,-94.877869,0.006368,0.004037,0.102541,47.984138,2.444428,1.025408,-94.877869,0.103443,0.000000
70.490005,10.756355,-94.922348,0.006424,0.004063,0.103209,47.846657,2.437425,1.032086,-94.922348,0.104214,0.000000
70.950005,10.871414,-94.966827,0.006416,0.004100,0.104128,48.358467,2.463498,1.041278,-94.966827,0.104978,0.000000
71.410004,10.914986,-94.922348,0.006450,0.004127,0.104830,48.552280,2.473371,1.048302,-94.922348,0.105741,0.000000
71.870003,10.858009,-95.011314,0.006480,0.004156,0.105559,48.298840,2.460460,1.055586,-95.011314,0.106513,0.000000
72.330002,10.887054,-95.011314,0.006510,0.004185,0.106296,48.428036,2.467042,1.062958,-95.011314,0.107276,0.000000
72.790001,10.995789,-95.011314,0.006545,0.004217,0.107102,48.911709,2.491681,1.071023,-95.011314,0.108048,0.000000
73.250000,11.089996,-95.055794,0.006579,0.004248,0.107900,49.330769,2.513029,1.079002,-95.055794,0.108811,0.000000
73.710007,11.138031,-95.055794,0.006640,0.004282,0.108759,49.544437,2.523914,1.087588,-95.055794,0.109583,0.000000
74.170006,10.987221,-95.055794,0.006648,0.004307,0.109409,48.873600,2.489740,1.094092,-95.055794,0.110346,0.000000
74.630005,11.054993,-95.011314,0.006683,0.004340,0.110224,49.175064,2.505097,1.102243,-95.011314,0.111109,0.000000
75.090004,10.971581,-95.144753,0.006691,0.004362,0.110805,48.804028,2.486196,1.108055,-95.144753,0.111881,0.000000
75.550003,11.253845,-95.100273,0.006748,0.004403,0.111829,50.059605,2.550158,1.118287,-95.100273,0.112644,0.000000
76.010002,11.182716,-95.100273,0.006791,0.004429,0.112505,49.743206,2.534040,1.125052,-95.100273,0.113416,0.000000
76.470001,11.219215,-95.100273,0.006804,0.004460,0.113294,49.905563,2.542310,1.132944,-95.100273,0.114179,0.000000
76.930000,11.173409,-95.144753,0.006838,0.004487,0.113962,49.701805,2.531931,1.139621,-95.144753,0.114942,0.000000
77.390007,11.103035,-95.144753,0.006873,0.004509,0.114517,49.388767,2.515984,1.145171,-95.144753,0.115714,0.000000
77.850006,11.349915,-95.144753,0.006898,0.004549,0.115549,50.486942,2.571927,1.155491,-95.144753,0.116477,0.000000
78.310005,11.344330,-95.144753,0.006950,0.004579,0.116312,50.462101,2.570662,1.163123,-95.144753,0.117249,0.000000
78.770004,11.352524,-95.233719,0.006963,0.004611,0.117110,50.498547,2.572519,1.171101,-95.233719,0.118012,0.000000
79.230003,11.505569,-95.144753,0.007002,0.004642,0.117908,51.179329,2.607199,1.179080,-95.144753,0.118775,0.000000
79.690002,11.380074,-95.278198,0.007041,0.004667,0.118550,50.621094,2.578761,1.185497,-95.278198,0.119547,0.000000
80.150002,11.274323,-95.189232,0.007067,0.004695,0.119261,50.150692,2.554798,1.192609,-95.189232,0.120310,0.000000
80.610001,11.540565,-95.189232,0.007101,0.004730,0.120154,51.334999,2.615129,1.201541,-95.189232,0.121082,0.000000
81.070007,11.539452,-95.189232,0.007131,0.004761,0.120917,51.330044,2.614877,1.209172,-95.189232,0.121845,0.000000
81.530006,11.553604,-95.189232,0.007170,0.004793,0.121750,51.392998,2.618084,1.217499,-95.189232,0.122617,0.000000
81.990005,11.535728,-95.278198,0.007187,0.004821,0.122461,51.313484,2.614033,1.224608,-95.278198,0.123380,0.000000
82.450005,11.619888,-95.233719,0.007192,0.004852,0.123233,51.687843,2.633104,1.232328,-95.233719,0.124143,0.000000
82.910004,11.641853,-95.233719,0.007235,0.004875,0.123831,51.785549,2.638082,1.238312,-95.233719,0.124915,0.000000
83.370003,11.829903,-95.367157,0.007286,0.004916,0.124863,52.622036,2.680694,1.248631,-95.367157,0.125678,0.000000
83.830002,11.608711,-95.322678,0.007330,0.004944,0.125566,51.638126,2.630571,1.255656,-95.322678,0.126450,0.000000
84.290001,11.740532,-95.411636,0.007338,0.004973,0.126303,52.224495,2.660443,1.263027,-95.411636,0.127213,0.000000
84.750008,11.648560,-95.322678,0.007377,0.004998,0.126962,51.815380,2.639601,1.269618,-95.322678,0.127977,0.000000
85.210007,11.867142,-95.322678,0.007424,0.005035,0.127890,52.787682,2.689133,1.278897,-95.322678,0.128748,0.000000
85.670006,11.696968,-95.411636,0.007442,0.005062,0.128583,52.030712,2.650571,1.285835,-95.411636,0.129512,0.000000
86.130005,11.825432,-95.367157,0.007463,0.005092,0.129338,52.602146,2.679681,1.293380,-95.367157,0.130283,0.000000
86.590004,11.789688,-95.456123,0.007502,0.005120,0.130058,52.443153,2.671582,1.300579,-95.456123,0.131047,0.000000
87.050003,12.005287,-95.411636,0.007532,0.005152,0.130873,53.402184,2.720437,1.308730,-95.411636,0.131810,0.000000
87.510002,11.963211,-95.411636,0.007549,0.005185,0.131697,53.215019,2.710902,1.316969,-95.411636,0.132581,0.000000
87.970001,12.005287,-95.500603,0.007588,0.005215,0.132451,53.402184,2.720437,1.324515,-95.500603,0.133345,0.000000
88.430008,11.871239,-95.411636,0.007627,0.005238,0.133041,52.805908,2.690061,1.330411,-95.411636,0.134116,0.000000
88.890007,11.977364,-95.545082,0.007657,0.005268,0.133813,53.277973,2.714109,1.338129,-95.545082,0.134880,0.000000
89.350006,12.059280,-95.456123,0.007692,0.005307,0.134810,53.642357,2.732672,1.348102,-95.456123,0.135651,0.000000
89.810005,11.992256,-95.545082,0.007722,0.005334,0.135495,53.344219,2.717484,1.354953,-95.545082,0.136415,0.000000
90.270004,12.133385,-95.545082,0.007743,0.005366,0.136284,53.971992,2.749464,1.362844,-95.545082,0.137178,0.000000
90.730003,12.090561,-95.500603,0.007774,0.005390,0.136918,53.781502,2.739760,1.369176,-95.500603,0.137950,0.000000
91.190002,12.192963,-95.545082,0.007808,0.005424,0.137776,54.237007,2.762965,1.377760,-95.545082,0.138713,0.000000
91.650002,12.125191,-95.545082,0.007843,0.005451,0.138444,53.935543,2.747607,1.384439,-95.545082,0.139485,0.000000
92.110001,12.325531,-95.589561,0.007894,0.005487,0.139380,54.826698,2.793005,1.393805,-95.589561,0.140248,0.000000
92.570007,12.232063,-95.589561,0.007877,0.005514,0.140048,54.410934,2.771825,1.400483,-95.589561,0.141011,0.000000
93.030006,12.362396,-95.589561,0.007942,0.005546,0.140872,54.990685,2.801359,1.408721,-95.589561,0.141783,0.000000
93.490005,12.320320,-95.634048,0.007976,0.005574,0.141583,54.803520,2.791824,1.415833,-95.634048,0.142546,0.000000
93.950005,12.404472,-95.589561,0.008006,0.005607,0.142416,55.177849,2.810894,1.424158,-95.589561,0.143318,0.000000
94.410004,12.305794,-95.589561,0.008050,0.005632,0.143049,54.738903,2.788533,1.430488,-95.589561,0.144081,0.000000
94.870003,12.476341,-95.634048,0.008080,0.005667,0.143942,55.497540,2.827179,1.439420,-95.634048,0.144844,0.000000
95.330002,12.433891,-95.589561,0.008101,0.005700,0.144775,55.308712,2.817560,1.447747,-95.589561,0.145616,0.000000
95.790001,12.496078,-95.767487,0.008153,0.005727,0.145477,55.585335,2.831652,1.454772,-95.767487,0.146379,0.000000
96.250008,12.495705,-95.678528,0.008149,0.005756,0.146197,55.583672,2.831567,1.461969,-95.678528,0.147151,0.000000
96.710007,12.732536,-95.678528,0.008201,0.005788,0.147003,56.637150,2.885234,1.470034,-95.678528,0.147914,0.000000
97.170006,12.610771,-95.723007,0.008222,0.005817,0.147758,56.095512,2.857641,1.477579,-95.723007,0.148677,0.000000
97.630005,12.634224,-95.723007,0.008244,0.005847,0.148504,56.199837,2.862956,1.485038,-95.723007,0.149449,0.000000
98.090004,12.700882,-95.723007,0.008282,0.005878,0.149302,56.496346,2.878061,1.493016,-95.723007,0.150212,0.000000
98.550003,12.573906,-95.723007,0.008321,0.005901,0.149883,55.931526,2.849288,1.498826,-95.723007,0.150984,0.000000
99.010002,12.764931,-95.723007,0.008343,0.005936,0.150776,56.781246,2.892575,1.507758,-95.723007,0.151747,0.000000
99.470001,12.876266,-95.811966,0.008395,0.005968,0.151600,57.276493,2.917804,1.515996,-95.811966,0.152519,0.000000
99.930008,12.879623,-95.767487,0.008407,0.005999,0.152363,57.291428,2.918564,1.523628,-95.767487,0.153282,0.000000
100.390007,12.833817,-95.811966,0.008459,0.006027,0.153074,57.087666,2.908184,1.530740,-95.811966,0.154045,0.000000
100.850006,12.887070,-95.811966,0.008489,0.006058,0.153881,57.324551,2.920252,1.538806,-95.811966,0.154817,0.000000
101.310005,12.900848,-95.811966,0.008498,0.006088,0.154635,57.385841,2.923374,1.546349,-95.811966,0.155580,0.000000
101.770004,13.012558,-95.900932,0.008545,0.006119,0.155424,57.882748,2.948688,1.554242,-95.900932,0.156352,0.000000
102.230003,12.920952,-95.856453,0.008567,0.006145,0.156083,57.475266,2.927930,1.560832,-95.856453,0.157115,0.000000
102.690002,13.181984,-95.856453,0.008623,0.006182,0.157028,58.636395,2.987080,1.570285,-95.856453,0.157878,0.000000
103.150002,13.021492,-95.856453,0.008632,0.006211,0.157757,57.922489,2.950712,1.577571,-95.856453,0.158650,0.000000
103.610008,13.006973,-95.856453,0.008645,0.006235,0.158381,57.857906,2.947422,1.583814,-95.856453,0.159413,0.000000
104.070007,12.918716,-95.945412,0.008683,0.006257,0.158936,57.465321,2.927423,1.589364,-95.945412,0.160185,0.000000
104.530006,13.221458,-95.945412,0.008727,0.006298,0.159968,58.811985,2.996025,1.599684,-95.945412,0.160948,0.000000
104.990005,13.238586,-95.945412,0.008761,0.006332,0.160844,58.888172,2.999907,1.608444,-95.945412,0.161712,0.000000
105.450005,13.072510,-95.989891,0.008787,0.006355,0.161408,58.149429,2.962273,1.614080,-95.989891,0.162483,0.000000
105.910004,13.250130,-95.945412,0.008834,0.006390,0.162301,58.939522,3.002522,1.623012,-95.945412,0.163246,0.000000
106.370003,13.176773,-95.945412,0.008830,0.006414,0.162908,58.613213,2.985899,1.629083,-95.945412,0.164018,0.000000
106.830002,13.343224,-95.989891,0.008869,0.006452,0.163888,59.353622,3.023618,1.638882,-95.989891,0.164781,0.000000
107.290009,13.333168,-96.034370,0.008916,0.006478,0.164530,59.308895,3.021339,1.645300,-96.034370,0.165553,0.000000
107.750008,13.477280,-95.945412,0.008929,0.006510,0.165345,59.949936,3.053995,1.653452,-95.945412,0.166317,0.000000
108.210007,13.569626,-95.989891,0.008990,0.006537,0.166039,60.360710,3.074921,1.660390,-95.989891,0.167080,0.000000
108.670006,13.577446,-96.078857,0.009007,0.006573,0.166958,60.395496,3.076693,1.669583,-96.078857,0.167852,0.000000
109.130005,13.464615,-96.078857,0.009050,0.006600,0.167643,59.893597,3.051125,1.676434,-96.078857,0.168615,0.000000
109.590004,13.602394,-96.167816,0.009071,0.006629,0.168381,60.506470,3.082347,1.683805,-96.167816,0.169387,0.000000
110.050003,13.543190,-96.078857,0.009097,0.006656,0.169057,60.243118,3.068931,1.690569,-96.078857,0.170150,0.000000
110.510002,13.877953,-96.078857,0.009149,0.006697,0.170106,61.732216,3.144789,1.701062,-96.078857,0.170913,0.000000
110.970009,13.778900,-96.167816,0.009171,0.006726,0.170835,61.291611,3.122343,1.708348,-96.167816,0.171685,0.000000
111.430008,13.880554,-96.078857,0.009184,0.006754,0.171555,61.743790,3.145379,1.715545,-96.078857,0.172448,0.000000
111.890007,13.677246,-96.123337,0.009196,0.006778,0.172153,60.839428,3.099308,1.721529,-96.123337,0.173220,0.000000
112.350006,13.993011,-96.167816,0.009265,0.006814,0.173064,62.244022,3.170862,1.730636,-96.167816,0.173983,0.000000
112.810005,13.952423,-96.167816,0.009304,0.006843,0.173818,62.063477,3.161664,1.738181,-96.167816,0.174746,0.000000
113.270004,13.952423,-96.167816,0.009343,0.006872,0.174555,62.063477,3.161664,1.745552,-96.167816,0.175518,0.000000
113.730003,13.935669,-96.167816,0.009347,0.006901,0.175284,61.988953,3.157868,1.752836,-96.167816,0.176281,0.000000
114.190002,14.146805,-96.212296,0.009382,0.006934,0.176116,62.928131,3.205712,1.761161,-96.212296,0.177053,0.000000
114.650009,14.136749,-96.256775,0.009412,0.006962,0.176845,62.883400,3.203433,1.768447,-96.256775,0.177816,0.000000
115.110008,14.101746,-96.256775,0.009459,0.006991,0.177564,62.727695,3.195501,1.775644,-96.256775,0.178579,0.000000
115.570007,14.172127,-96.301262,0.009468,0.007022,0.178362,63.040768,3.211450,1.783622,-96.301262,0.179351,0.000000
116.030006,14.275642,-96.212296,0.009520,0.007054,0.179169,63.501228,3.234907,1.791688,-96.212296,0.180114,0.000000
116.490005,14.402252,-96.301262,0.009524,0.007087,0.180019,64.064415,3.263597,1.800187,-96.301262,0.180886,0.000000
116.950005,14.392197,-96.256775,0.009576,0.007117,0.180764,64.019691,3.261318,1.807645,-96.256775,0.181649,0.000000
117.410004,14.358315,-96.256775,0.009610,0.007145,0.181476,63.868973,3.253641,1.814757,-96.256775,0.182421,0.000000
117.870003,14.448425,-96.301262,0.009649,0.007171,0.182135,64.269806,3.274060,1.821346,-96.301262,0.183184,0.000000
118.330002,14.570938,-96.345741,0.009666,0.007205,0.183019,64.814774,3.301822,1.830194,-96.345741,0.183947,0.000000
118.790009,14.557533,-96.345741,0.009688,0.007235,0.183756,64.755142,3.298784,1.837565,-96.345741,0.184719,0.000000
119.250008,14.706856,-96.301262,0.009714,0.007267,0.184589,65.419365,3.332621,1.845889,-96.301262,0.185482,0.000000
119.710007,14.478958,-96.345741,0.009779,0.007289,0.185153,64.405624,3.280979,1.851527,-96.345741,0.186254,0.000000
120.170006,14.988365,-96.390221,0.009779,0.007327,0.186098,66.671577,3.396412,1.860980,-96.390221,0.187017,0.000000
120.630005,14.808136,-96.345741,0.009822,0.007355,0.186826,65.869881,3.355572,1.868264,-96.345741,0.187780,0.000000
121.090004,14.892670,-96.434700,0.009852,0.007387,0.187642,66.245903,3.374727,1.876417,-96.434700,0.188552,0.000000
121.550003,14.811859,-96.345741,0.009886,0.007414,0.188327,65.886436,3.356415,1.883267,-96.345741,0.189315,0.000000
122.010002,15.055763,-96.434700,0.009921,0.007448,0.189185,66.971382,3.411685,1.891853,-96.434700,0.190087,0.000000
122.470009,15.054276,-96.390221,0.009951,0.007478,0.189940,66.964760,3.411348,1.899398,-96.390221,0.190850,0.000000
122.930008,14.875534,-96.390221,0.009985,0.007499,0.190486,66.169678,3.370844,1.904862,-96.390221,0.191614,0.000000
123.390007,15.156677,-96.523666,0.010020,0.007536,0.191405,67.420265,3.434552,1.914054,-96.523666,0.192385,0.000000
123.850006,14.976074,-96.479179,0.010037,0.007564,0.192117,66.616905,3.393627,1.921165,-96.479179,0.193148,0.000000
124.310005,15.220726,-96.434700,0.010080,0.007600,0.193044,67.705170,3.449066,1.930444,-96.434700,0.193920,0.000000
124.770004,15.161888,-96.479179,0.010106,0.007626,0.193695,67.443443,3.435733,1.936948,-96.479179,0.194683,0.000000
125.230003,15.140663,-96.523666,0.010149,0.007652,0.194354,67.349030,3.430923,1.943540,-96.523666,0.195455,0.000000
125.690002,15.433350,-96.568146,0.010158,0.007682,0.195117,68.650970,3.497247,1.951170,-96.568146,0.196218,0.000000
126.150009,15.507454,-96.479179,0.010179,0.007720,0.196088,68.980598,3.514040,1.960884,-96.479179,0.196982,0.000000
126.610008,15.526443,-96.523666,0.010240,0.007750,0.196843,69.065071,3.518342,1.968429,-96.523666,0.197753,0.000000
127.070007,15.588631,-96.523666,0.010266,0.007778,0.197554,69.341690,3.532434,1.975539,-96.523666,0.198517,0.000000
127.530006,15.559212,-96.568146,0.010287,0.007805,0.198256,69.210831,3.525768,1.982564,-96.568146,0.199289,0.000000
127.990005,15.830673,-96.568146,0.010326,0.007844,0.199228,70.418350,3.587282,1.992278,-96.568146,0.200052,0.000000
128.450012,15.657150,-96.612625,0.010356,0.007867,0.199817,69.646484,3.547961,1.998175,-96.612625,0.200815,0.000000
128.910004,15.958023,-96.612625,0.010382,0.007901,0.200676,70.984833,3.616140,2.006761,-96.612625,0.201587,0.000000
129.370010,15.681351,-96.701584,0.010412,0.007921,0.201188,69.754135,3.553445,2.011876,-96.701584,0.202350,0.000000
129.830002,16.099899,-96.612625,0.010442,0.007961,0.202202,71.615929,3.648289,2.022023,-96.612625,0.203121,0.000000
130.290009,15.961372,-96.657104,0.010481,0.007990,0.202939,70.999733,3.616899,2.029394,-96.657104,0.203885,0.000000
130.750000,16.011276,-96.612625,0.010511,0.008018,0.203659,71.221710,3.628207,2.036593,-96.612625,0.204648,0.000000
131.210007,16.085373,-96.657104,0.010550,0.008045,0.204344,71.551315,3.644998,2.043444,-96.657104,0.205420,0.000000
131.670013,16.468544,-96.657104,0.010568,0.008084,0.205333,73.255745,3.731825,2.053330,-96.657104,0.206183,0.000000
132.130005,16.278633,-96.701584,0.010585,0.008113,0.206079,72.410980,3.688791,2.060788,-96.701584,0.206955,0.000000
132.590012,16.258530,-96.701584,0.010649,0.008140,0.206747,72.321548,3.684236,2.067467,-96.701584,0.207718,0.000000
133.050003,16.475624,-96.790550,0.010675,0.008172,0.207570,73.287239,3.733430,2.075705,-96.790550,0.208490,0.000000
133.510010,16.641701,-96.790550,0.010710,0.008201,0.208308,74.025986,3.771063,2.083076,-96.790550,0.209253,0.000000
133.970001,16.643562,-96.790550,0.010731,0.008232,0.209105,74.034264,3.771485,2.091054,-96.790550,0.210016,0.000000
134.430008,16.637230,-96.746071,0.010779,0.008259,0.209773,74.006096,3.770050,2.097733,-96.746071,0.210788,0.000000
134.889999,16.655479,-96.790550,0.010809,0.008293,0.210632,74.087273,3.774186,2.106317,-96.790550,0.211551,0.000000
135.350006,16.861771,-96.835030,0.010818,0.008323,0.211395,75.004898,3.820932,2.113949,-96.835030,0.212323,0.000000
135.810013,16.852089,-96.790550,0.010856,0.008351,0.212123,74.961838,3.818738,2.121233,-96.790550,0.213086,0.000000
136.270004,16.887093,-96.835030,0.010891,0.008380,0.212843,75.117538,3.826670,2.128432,-96.835030,0.213849,0.000000
136.730011,17.112381,-96.790550,0.010925,0.008412,0.213667,76.119675,3.877721,2.136670,-96.790550,0.214621,0.000000
137.190002,17.243080,-96.923996,0.010934,0.008443,0.214456,76.701050,3.907338,2.144563,-96.923996,0.215384,0.000000
137.650009,17.378250,-96.879509,0.010973,0.008477,0.215323,77.302315,3.937968,2.153234,-96.879509,0.216156,0.000000
138.110001,17.211800,-96.923996,0.011020,0.008503,0.215983,76.561905,3.900250,2.159826,-96.923996,0.216919,0.000000
138.570007,17.446770,-96.835030,0.011076,0.008536,0.216824,77.607109,3.953495,2.168238,-96.835030,0.217682,0.000000
139.030014,17.284790,-96.879509,0.011059,0.008558,0.217370,76.886589,3.916790,2.173701,-96.879509,0.218454,0.000000
139.490005,17.516777,-96.923996,0.011098,0.008594,0.218298,77.918518,3.969358,2.182980,-96.923996,0.219217,0.000000
139.950012,17.704826,-96.968475,0.011150,0.008625,0.219087,78.754997,4.011971,2.190871,-96.968475,0.219989,0.000000
140.410004,17.733124,-96.968475,0.011167,0.008655,0.219842,78.880875,4.018383,2.198416,-96.968475,0.220752,0.000000
140.870010,17.748016,-96.923996,0.011201,0.008682,0.220527,78.947121,4.021758,2.205267,-96.923996,0.221516,0.000000
141.330002,17.596466,-96.968475,0.011232,0.008703,0.221056,78.272987,3.987416,2.210558,-96.968475,0.222287,0.000000
141.790009,17.934952,-96.968475,0.011262,0.008743,0.222079,79.778648,4.064118,2.220791,-96.968475,0.223050,0.000000
142.250000,18.104752,-97.012955,0.011296,0.008774,0.222868,80.533958,4.102595,2.228683,-97.012955,0.223822,0.000000
142.710007,18.150925,-96.968475,0.011331,0.008804,0.223631,80.739342,4.113058,2.236315,-96.968475,0.224585,0.000000
143.170013,18.444351,-97.101913,0.011357,0.008836,0.224438,82.044571,4.179550,2.244380,-97.101913,0.225357,0.000000
143.630005,18.352753,-96.968475,0.011395,0.008862,0.225106,81.637123,4.158793,2.251057,-96.968475,0.226120,0.000000
144.090012,18.256676,-97.057434,0.011408,0.008890,0.225808,81.209747,4.137022,2.258082,-97.057434,0.226884,0.000000
144.550003,18.672989,-97.057434,0.011460,0.008926,0.226710,83.061600,4.231359,2.267101,-97.057434,0.227655,0.000000
145.010010,18.767944,-97.101913,0.011477,0.008955,0.227465,83.483986,4.252877,2.274646,-97.101913,0.228419,0.000000
145.470001,18.863274,-97.101913,0.011499,0.008988,0.228297,83.908035,4.274479,2.282971,-97.101913,0.229190,0.000000
145.930008,18.826782,-97.057434,0.011559,0.009016,0.229000,83.745712,4.266210,2.289996,-97.057434,0.229954,0.000000
146.389999,18.976845,-97.146400,0.011559,0.009045,0.229737,84.413223,4.300214,2.297367,-97.146400,0.230717,0.000000
146.850006,19.069565,-97.190880,0.011589,0.009070,0.230378,84.825661,4.321225,2.303784,-97.190880,0.231489,0.000000
147.310013,19.517159,-97.146400,0.011641,0.009111,0.231419,86.816658,4.422651,2.314191,-97.146400,0.232252,0.000000
147.770004,19.239372,-97.057434,0.011658,0.009137,0.232087,85.581001,4.359704,2.320869,-97.057434,0.233023,0.000000
148.230011,19.472099,-97.146400,0.011697,0.009167,0.232833,86.616226,4.412441,2.328327,-97.146400,0.233787,0.000000
148.690002,19.448273,-97.146400,0.011736,0.009194,0.233526,86.510239,4.407042,2.335265,-97.146400,0.234550,0.000000
149.150009,19.833679,-97.146400,0.011753,0.009230,0.234437,88.224609,4.494376,2.344372,-97.146400,0.235322,0.000000
149.610001,19.684731,-97.190880,0.011805,0.009258,0.235166,87.562057,4.460624,2.351655,-97.190880,0.236085,0.000000
150.070007,19.872406,-97.190880,0.011809,0.009285,0.235851,88.396873,4.503152,2.358506,-97.190880,0.236857,0.000000
150.530014,20.029175,-97.146400,0.011844,0.009316,0.236614,89.094223,4.538676,2.366138,-97.146400,0.237620,0.000000
150.990005,20.230255,-97.324318,0.011861,0.009347,0.237420,89.988670,4.584241,2.374204,-97.324318,0.238392,0.000000
151.450012,20.409363,-97.235359,0.011926,0.009380,0.238262,90.785378,4.624828,2.382616,-97.235359,0.239155,0.000000
151.910004,20.522194,-97.279839,0.011947,0.009410,0.239007,91.287277,4.650395,2.390074,-97.279839,0.239918,0.000000
152.370010,20.384041,-97.235359,0.011947,0.009433,0.239597,90.672745,4.619090,2.395971,-97.235359,0.240690,0.000000
152.830002,20.653641,-97.235359,0.012008,0.009466,0.240438,91.871979,4.680182,2.404383,-97.235359,0.241453,0.000000
153.290009,20.933662,-97.368805,0.012038,0.009503,0.241384,93.117584,4.743636,2.413836,-97.368805,0.242225,0.000000
153.750000,20.837593,-97.368805,0.012059,0.009531,0.242086,92.690247,4.721866,2.420861,-97.368805,0.242988,0.000000
154.210007,21.161926,-97.324318,0.012089,0.009561,0.242849,94.132950,4.795361,2.428493,-97.324318,0.243751,0.000000
154.670013,21.150009,-97.368805,0.012128,0.009586,0.243482,94.079941,4.792661,2.434823,-97.368805,0.244523,0.000000
155.130005,21.418869,-97.324318,0.012150,0.009619,0.244332,95.275887,4.853585,2.443322,-97.324318,0.245286,0.000000
155.590012,21.405464,-97.413284,0.012189,0.009646,0.245009,95.216263,4.850548,2.450085,-97.413284,0.246058,0.000000
156.050003,21.907043,-97.368805,0.012223,0.009683,0.245954,97.447395,4.964207,2.459538,-97.368805,0.246821,0.000000
156.510010,21.615852,-97.413284,0.012232,0.009704,0.246491,96.152115,4.898222,2.464915,-97.413284,0.247584,0.000000
156.970001,22.171806,-97.413284,0.012262,0.009742,0.247445,98.625122,5.024203,2.474455,-97.413284,0.248356,0.000000
157.430008,22.042221,-97.324318,0.012322,0.009769,0.248122,98.048698,4.994839,2.481220,-97.324318,0.249119,0.000000
157.890015,22.315536,-97.502243,0.012348,0.009800,0.248920,99.264465,5.056773,2.489199,-97.502243,0.249891,0.000000
158.350006,22.271973,-97.413284,0.012348,0.009827,0.249596,99.070679,5.046901,2.495962,-97.413284,0.250654,0.000000
158.810013,22.725517,-97.457764,0.012404,0.009861,0.250481,101.088150,5.149676,2.504807,-97.457764,0.251417,0.000000
159.270004,22.758293,-97.457764,0.012456,0.009893,0.251270,101.233940,5.157103,2.512699,-97.457764,0.252189,0.000000
159.730011,22.958252,-97.457764,0.012495,0.009922,0.252024,102.123405,5.202414,2.520244,-97.457764,0.252952,0.000000
160.190002,23.097145,-97.546722,0.012495,0.009950,0.252736,102.741234,5.233888,2.527356,-97.546722,0.253724,0.000000
160.650009,23.170876,-97.502243,0.012516,0.009977,0.253421,103.069199,5.250596,2.534207,-97.502243,0.254487,0.000000
161.110001,23.495590,-97.591209,0.012568,0.010011,0.254288,104.513603,5.324177,2.542880,-97.591209,0.255259,0.000000
161.570007,23.667252,-97.546722,0.012590,0.010042,0.255068,105.277191,5.363076,2.550684,-97.546722,0.256022,0.000000
162.030014,23.940941,-97.591209,0.012616,0.010073,0.255858,106.494621,5.425095,2.558576,-97.591209,0.256785,0.000000
162.490005,23.813217,-97.591209,0.012650,0.010095,0.256404,105.926483,5.396152,2.564039,-97.591209,0.257557,0.000000
162.950012,24.318161,-97.546722,0.012667,0.010130,0.257315,108.172585,5.510574,2.573146,-97.546722,0.258321,0.000000
163.410004,24.554985,-97.591209,0.012706,0.010164,0.258164,109.226028,5.564240,2.581645,-97.591209,0.259092,0.000000
163.870010,24.785858,-97.591209,0.012728,0.010194,0.258927,110.253006,5.616556,2.589275,-97.591209,0.259856,0.000000
164.330002,24.764259,-97.635689,0.012758,0.010221,0.259604,110.156929,5.611661,2.596040,-97.635689,0.260619,0.000000
164.790009,24.950073,-97.680168,0.012788,0.010251,0.260385,110.983467,5.653768,2.603845,-97.680168,0.261391,0.000000
165.250015,25.239037,-97.635689,0.012818,0.010283,0.261182,112.268845,5.719247,2.611824,-97.635689,0.262154,0.000000
165.710007,25.490761,-97.635689,0.012848,0.010311,0.261894,113.388565,5.776289,2.618935,-97.635689,0.262925,0.000000
166.170013,25.570076,-97.724648,0.012883,0.010339,0.262613,113.741379,5.794262,2.626132,-97.724648,0.263689,0.000000
166.630005,26.075012,-97.680168,0.012909,0.010376,0.263550,115.987450,5.908682,2.635498,-97.680168,0.264452,0.000000
167.090012,26.075386,-97.769127,0.012947,0.010405,0.264278,115.989113,5.908767,2.642784,-97.769127,0.265224,0.000000
167.550003,26.159538,-97.724648,0.012978,0.010431,0.264937,116.363441,5.927836,2.649374,-97.724648,0.265987,0.000000
168.010010,26.133102,-97.724648,0.012999,0.010453,0.265519,116.245842,5.921846,2.655185,-97.724648,0.266759,0.000000
168.470001,26.805603,-97.680168,0.013021,0.010490,0.266438,119.237274,6.074236,2.664377,-97.680168,0.267522,0.000000
168.930008,27.111320,-97.724648,0.013055,0.010527,0.267374,120.597176,6.143513,2.673743,-97.724648,0.268294,0.000000
169.390015,27.009293,-97.769127,0.013090,0.010550,0.267973,120.143333,6.120393,2.679726,-97.769127,0.269057,0.000000
169.850006,27.563011,-97.724648,0.013107,0.010583,0.268805,122.606400,6.245867,2.688053,-97.724648,0.269820,0.000000
170.310013,27.601738,-97.858093,0.013150,0.010612,0.269534,122.778664,6.254643,2.695337,-97.858093,0.270592,0.000000
170.770004,27.986771,-97.769127,0.013193,0.010644,0.270357,124.491371,6.341893,2.703575,-97.769127,0.271355,0.000000
171.230011,28.172211,-97.813614,0.013215,0.010673,0.271103,125.316254,6.383914,2.711033,-97.813614,0.272127,0.000000
171.690002,28.605652,-97.858093,0.013245,0.010704,0.271893,127.244293,6.482133,2.718927,-97.858093,0.272890,0.000000
172.150009,28.870041,-97.813614,0.013262,0.010731,0.272578,128.420349,6.542045,2.725777,-97.813614,0.273653,0.000000
172.610001,29.354866,-97.902573,0.013279,0.010768,0.273514,130.576965,6.651907,2.735143,-97.902573,0.274425,0.000000
173.070007,29.279274,-97.858093,0.013327,0.010795,0.274182,130.240723,6.634778,2.741822,-97.858093,0.275188,0.000000
173.530014,29.678833,-97.858093,0.013357,0.010824,0.274936,132.018036,6.725320,2.749365,-97.858093,0.275960,0.000000
173.990005,29.716438,-97.858093,0.013379,0.010849,0.275561,132.185318,6.733841,2.755610,-97.858093,0.276723,0.000000
174.450012,30.689819,-97.902573,0.013430,0.010892,0.276654,136.515137,6.954412,2.766537,-97.902573,0.277486,0.000000
174.910004,30.681633,-97.947052,0.013461,0.010921,0.277399,136.478714,6.952557,2.773995,-97.947052,0.278258,0.000000
175.370010,31.108368,-97.991531,0.013482,0.010950,0.278119,138.376938,7.049257,2.781192,-97.991531,0.279021,0.000000
175.830002,31.044693,-97.947052,0.013512,0.010973,0.278709,138.093689,7.034828,2.787091,-97.947052,0.279793,0.000000
176.290009,31.776779,-97.947052,0.013547,0.011008,0.279611,141.350174,7.200721,2.796108,-97.947052,0.280556,0.000000
176.750015,31.856094,-97.947052,0.013568,0.011035,0.280296,141.702988,7.218694,2.802961,-97.947052,0.281328,0.000000
177.210007,32.156601,-97.947052,0.013603,0.011064,0.281016,143.039703,7.286790,2.810158,-97.947052,0.282091,0.000000
177.670013,32.595627,-97.991531,0.013629,0.011097,0.281866,144.992584,7.386274,2.818657,-97.991531,0.282854,0.000000
178.130005,33.017525,-97.991531,0.013650,0.011128,0.282646,146.869278,7.481878,2.826461,-97.991531,0.283626,0.000000
178.590012,33.441284,-98.036018,0.013680,0.011158,0.283418,148.754257,7.577903,2.834180,-98.036018,0.284389,0.000000
179.050003,33.652420,-97.991531,0.013706,0.011175,0.283852,149.693436,7.625748,2.838516,-97.991531,0.284077,0.000000
179.510010,32.415771,-98.080498,0.013715,0.011174,0.283826,144.192551,7.345519,2.838257,-98.080498,0.283886,0.000000
179.970001,31.685547,-97.947052,0.013706,0.011155,0.283340,140.944351,7.180048,2.833399,-97.947052,0.283123,0.000000
180.430008,31.329185,-98.124977,0.013736,0.011130,0.282707,139.359177,7.099295,2.827069,-98.124977,0.282351,0.000000
180.890015,30.958679,-98.124977,0.013719,0.011098,0.281883,137.711090,7.015337,2.818831,-98.124977,0.281588,0.000000
181.350006,30.726685,-98.080498,0.013741,0.011074,0.281285,136.679123,6.962766,2.812847,-98.080498,0.280825,0.000000
181.810013,30.553909,-98.169456,0.013724,0.011049,0.280643,135.910583,6.923615,2.806430,-98.169456,0.280053,0.000000
182.270004,30.409798,-98.080498,0.013728,0.011012,0.279706,135.269531,6.890958,2.797062,-98.080498,0.279290,0.000000
182.730011,30.186378,-98.080498,0.013745,0.010984,0.278986,134.275711,6.840332,2.789865,-98.080498,0.278518,0.000000
183.190002,30.056419,-98.213943,0.013745,0.010960,0.278379,133.697632,6.810882,2.783794,-98.213943,0.277755,0.000000
183.650009,29.834480,-98.124977,0.013745,0.010933,0.277694,132.710403,6.760590,2.776943,-98.124977,0.276983,0.000000
184.110016,29.316139,-98.213943,0.013741,0.010901,0.276896,130.404694,6.643132,2.768965,-98.213943,0.276220,0.000000
184.570007,28.526711,-98.169456,0.013741,0.010869,0.276073,126.893143,6.464245,2.760727,-98.169456,0.275457,0.000000
185.030014,27.438263,-98.213943,0.013754,0.010842,0.275379,122.051491,6.217599,2.753787,-98.213943,0.274685,0.000000
185.490005,26.254868,-98.302902,0.013745,0.010818,0.274772,116.787483,5.949438,2.747718,-98.302902,0.273922,0.000000
185.950012,24.684570,-98.213943,0.013749,0.010787,0.273983,109.802452,5.593604,2.739827,-98.213943,0.273150,0.000000
186.410004,22.572479,-98.213943,0.013719,0.010756,0.273211,100.407402,5.114997,2.732107,-98.213943,0.272387,0.000000
186.870010,20.699066,-98.213943,0.013736,0.010725,0.272404,92.074043,4.690475,2.724042,-98.213943,0.271624,0.000000
187.330002,18.885986,-98.347382,0.013745,0.010702,0.271841,84.009064,4.279626,2.718406,-98.347382,0.270852,0.000000
187.790009,16.126709,-98.347382,0.013715,0.010665,0.270895,71.735184,3.654364,2.708953,-98.347382,0.270089,0.000000
188.250015,14.383263,-98.302902,0.013706,0.010638,0.270193,63.979946,3.259294,2.701929,-98.302902,0.269317,0.000000
188.710007,12.544861,-98.347382,0.013663,0.010610,0.269490,55.802326,2.842706,2.694904,-98.347382,0.268554,0.000000
189.170013,10.414139,-98.347382,0.013663,0.010578,0.268684,46.324402,2.359878,2.686838,-98.347382,0.267791,0.000000
189.630005,8.298691,-98.391861,0.013650,0.010544,0.267808,36.914421,1.880510,2.678080,-98.391861,0.267019,0.000000
190.090012,7.041191,-98.347382,0.013637,0.010520,0.267201,31.320782,1.595557,2.672009,-98.347382,0.266256,0.000000
190.550003,5.188271,-98.347382,0.013599,0.010486,0.266342,23.078581,1.175679,2.663423,-98.347382,0.265484,0.000000
191.010010,3.871185,-98.391861,0.013573,0.010458,0.265640,17.219893,0.877223,2.656398,-98.391861,0.264721,0.000000
191.470016,2.448349,-98.391861,0.013551,0.010425,0.264790,10.890800,0.554804,2.647899,-98.391861,0.263949,0.000000
191.930008,1.386719,-98.391861,0.013525,0.010394,0.264018,6.168433,0.314235,2.640182,-98.391861,0.263186,0.000000
192.390015,0.991631,-98.436348,0.013495,0.010373,0.263463,4.410993,0.224707,2.634631,-98.436348,0.262422,0.000000
192.850006,0.650162,-98.436348,0.013478,0.010338,0.262579,2.892064,0.147329,2.625786,-98.436348,0.261651,0.000000
193.310013,0.542549,-98.436348,0.013422,0.010305,0.261746,2.413379,0.122943,2.617461,-98.436348,0.260888,0.000000
193.770004,0.390991,-98.480827,0.013405,0.010269,0.260827,1.739216,0.088600,2.608268,-98.480827,0.260116,0.000000
194.230011,0.516113,-98.525307,0.013379,0.010248,0.260307,2.295787,0.116953,2.603065,-98.525307,0.259353,0.000000
194.690002,0.419296,-98.480827,0.013323,0.010210,0.259335,1.865123,0.095014,2.593351,-98.480827,0.258589,0.000000
195.150009,0.438660,-98.436348,0.013288,0.010182,0.258615,1.951256,0.099402,2.586154,-98.436348,0.257818,0.000000
195.610016,0.400299,-98.525307,0.013254,0.010150,0.257800,1.780619,0.090709,2.578002,-98.525307,0.257054,0.000000
196.070007,0.412590,-98.525307,0.013232,0.010126,0.257193,1.835292,0.093494,2.571931,-98.525307,0.256282,0.000000
196.530014,0.379448,-98.569786,0.013215,0.010104,0.256638,1.687869,0.085984,2.566380,-98.569786,0.255519,0.000000
196.990005,0.359344,-98.569786,0.013172,0.010067,0.255710,1.598444,0.081429,2.557101,-98.569786,0.254756,0.000000
197.450012,0.330299,-98.525307,0.013154,0.010034,0.254860,1.469245,0.074847,2.548603,-98.525307,0.253984,0.000000
197.910004,0.295296,-98.569786,0.013129,0.010008,0.254193,1.313541,0.066915,2.541926,-98.569786,0.253221,0.000000
198.370010,0.256935,-98.525307,0.013081,0.009979,0.253473,1.142905,0.058222,2.534727,-98.525307,0.252449,0.000000
198.830002,0.253960,-98.569786,0.013077,0.009943,0.252545,1.129669,0.057548,2.525449,-98.569786,0.251686,0.000000
199.290009,0.254707,-98.614265,0.013025,0.009916,0.251868,1.132995,0.057718,2.518683,-98.614265,0.250923,0.000000
199.600006,0.260292,-98.614265,0.012999,0.009903,0.251539,1.157837,0.058983,2.515388,-98.614265,0.251400,0.000000