File: PDMS and AD/PDMS0024 Test 1-2_02142024_163401.csv
Time (sec),S:Load (lbs),S:HL1 (DIM),S:LVDT (in),S:Position (in),Ch:Position (mm),Ch:Load (N),Ch:Stress (MPa),Ch:Strain (mm/mm),Ch:HL1 (DIM),Set Point (),Cycles ()
0.110000,0.001862,-214.887482,0.000000,-0.000000,-0.000000,0.008281,0.000422,-0.000000,-214.887482,-0.000147,0.000000
0.860000,0.004463,-214.931961,0.000013,0.000131,0.003339,0.019853,0.001011,0.033388,-214.931961,0.004197,0.000000
1.610000,-0.018623,-214.887482,0.000198,0.000370,0.009392,-0.082841,-0.004220,0.093922,-214.887482,0.010442,0.000000
2.360000,-0.009682,-214.976440,0.000479,0.000617,0.015662,-0.043066,-0.002194,0.156623,-214.976440,0.016694,0.000000
3.110000,-0.019363,-214.976440,0.000690,0.000864,0.021958,-0.086133,-0.004388,0.219583,-214.976440,0.022938,0.000000
3.860000,-0.025322,-215.020920,0.000957,0.001109,0.028168,-0.112638,-0.005738,0.281676,-215.020920,0.029191,0.000000
4.610000,-0.056229,-215.020920,0.001212,0.001353,0.034360,-0.250117,-0.012742,0.343597,-215.020920,0.035435,0.000000
5.360000,0.020103,-215.020920,0.001453,0.001600,0.040638,0.089425,0.004556,0.406382,-215.020920,0.041679,0.000000
6.110000,0.121391,-215.065399,0.001712,0.001850,0.046978,0.539975,0.027508,0.469777,-215.065399,0.047932,0.000000
6.860000,0.453171,-215.065399,0.001970,0.002076,0.052736,2.015804,0.102690,0.527361,-215.065399,0.054002,0.000000
7.610000,0.382797,-215.198837,0.001966,-0.000000,-0.000000,1.702767,0.086743,-0.000000,-215.198837,0.000512,0.000000
8.360001,0.484077,-215.154358,0.001970,0.000032,0.000815,2.153284,0.109694,0.008153,-215.154358,0.001761,0.000000
9.110001,0.573448,-215.065399,0.002026,0.000084,0.002142,2.550825,0.129945,0.021421,-215.065399,0.003009,0.000000
9.860001,0.661705,-215.109879,0.002057,0.000135,0.003417,2.943411,0.149944,0.034168,-215.109879,0.004258,0.000000
10.610001,0.710854,-215.198837,0.002139,0.000180,0.004579,3.162035,0.161082,0.045790,-215.198837,0.005507,0.000000
11.360001,0.793526,-215.154358,0.002169,0.000228,0.005784,3.529778,0.179815,0.057845,-215.154358,0.006756,0.000000
12.110001,0.888107,-215.198837,0.002225,0.000283,0.007189,3.950499,0.201248,0.071892,-215.198837,0.008004,0.000000
12.860001,0.945824,-215.287796,0.002281,0.000323,0.008213,4.207234,0.214327,0.082127,-215.287796,0.009262,0.000000
13.610001,1.048973,-215.243317,0.002302,0.000369,0.009383,4.666065,0.237701,0.093833,-215.243317,0.010511,0.000000
14.360001,1.132751,-215.243317,0.002393,0.000425,0.010797,5.038730,0.256685,0.107970,-215.243317,0.011759,0.000000
15.110001,1.258987,-215.332291,0.002414,0.000474,0.012037,5.600256,0.285291,0.120371,-215.332291,0.013008,0.000000
15.860001,1.362137,-215.332291,0.002483,0.000529,0.013433,6.059087,0.308665,0.134333,-215.332291,0.014257,0.000000
16.610001,1.406822,-215.287796,0.002531,0.000574,0.014578,6.257858,0.318790,0.145781,-215.287796,0.015506,0.000000
17.360001,1.550552,-215.376770,0.002557,0.000622,0.015810,6.897202,0.351360,0.158095,-215.376770,0.016755,0.000000
18.110001,1.582581,-215.376770,0.002613,0.000671,0.017032,7.039670,0.358618,0.170322,-215.376770,0.018012,0.000000
18.860001,1.712540,-215.376770,0.002665,0.000722,0.018342,7.617757,0.388067,0.183418,-215.376770,0.019261,0.000000
19.610001,1.829834,-215.465729,0.002708,0.000775,0.019686,8.139508,0.414646,0.196860,-215.465729,0.020510,0.000000
20.360001,1.861115,-215.421249,0.002764,0.000818,0.020779,8.278651,0.421735,0.207787,-215.421249,0.021759,0.000000
21.110001,2.008202,-215.421249,0.002833,0.000865,0.021967,8.932927,0.455065,0.219668,-215.421249,0.023007,0.000000
21.860001,2.117310,-215.421249,0.002863,0.000920,0.023363,9.418263,0.479789,0.233630,-215.421249,0.024256,0.000000
22.610001,2.204071,-215.510208,0.002910,0.000970,0.024629,9.804197,0.499450,0.246293,-215.510208,0.025505,0.000000
23.360001,2.335892,-215.465729,0.002953,0.001015,0.025791,10.390565,0.529321,0.257912,-215.465729,0.026763,0.000000
24.110001,2.410362,-215.554687,0.003005,0.001067,0.027109,10.721827,0.546196,0.271095,-215.554687,0.028011,0.000000
24.860001,2.531387,-215.510208,0.003100,0.001116,0.028358,11.260173,0.573621,0.283583,-215.510208,0.029260,0.000000
25.610001,2.633415,-215.554687,0.003113,0.001170,0.029711,11.714016,0.596740,0.297110,-215.554687,0.030509,0.000000
26.360001,2.713844,-215.554687,0.003156,0.001219,0.030969,12.071782,0.614966,0.309686,-215.554687,0.031758,0.000000
27.110001,2.839340,-215.643646,0.003225,0.001260,0.032009,12.630016,0.643404,0.320092,-215.643646,0.033007,0.000000
27.860001,2.911201,-215.599167,0.003251,0.001316,0.033414,12.949671,0.659688,0.334142,-215.599167,0.034255,0.000000
28.610001,3.037064,-215.599167,0.003316,0.001360,0.034550,13.509534,0.688208,0.345502,-215.599167,0.035513,0.000000
29.360001,3.142075,-215.643646,0.003359,0.001407,0.035730,13.976645,0.712004,0.357296,-215.643646,0.036762,0.000000
30.110001,3.246338,-215.688126,0.003415,0.001460,0.037091,14.440433,0.735631,0.370912,-215.688126,0.038011,0.000000
30.860001,3.318581,-215.688126,0.003449,0.001505,0.038219,14.761784,0.752001,0.382185,-215.688126,0.039259,0.000000
31.610001,3.424332,-215.732620,0.003514,0.001558,0.039563,15.232188,0.775965,0.395627,-215.732620,0.040508,0.000000
32.360001,3.499924,-215.777100,0.003553,0.001605,0.040768,15.568439,0.793094,0.407682,-215.777100,0.041757,0.000000
33.110001,3.685364,-215.732620,0.003630,0.001664,0.042269,16.393316,0.835115,0.422686,-215.732620,0.043014,0.000000
33.860001,3.710686,-215.777100,0.003665,0.001707,0.043353,16.505955,0.840853,0.433526,-215.777100,0.044263,0.000000
34.610001,3.826500,-215.821579,0.003708,0.001751,0.044480,17.021122,0.867097,0.444799,-215.821579,0.045512,0.000000
35.360001,3.940071,-215.821579,0.003773,0.001806,0.045868,17.526312,0.892833,0.458676,-215.821579,0.046761,0.000000
36.110001,4.043221,-215.866058,0.003807,0.001854,0.047090,17.985144,0.916207,0.470903,-215.866058,0.048010,0.000000
36.860001,4.126999,-215.821579,0.003833,0.001900,0.048252,18.357807,0.935191,0.482525,-215.821579,0.049258,0.000000
37.610001,4.213020,-215.866058,0.003928,0.001953,0.049597,18.740450,0.954684,0.495967,-215.866058,0.050507,0.000000
38.360001,4.293449,-215.866058,0.003975,0.001997,0.050733,19.098217,0.972910,0.507327,-215.866058,0.051765,0.000000
39.110001,4.456551,-215.910538,0.004031,0.002055,0.052190,19.823727,1.009869,0.521895,-215.910538,0.053014,0.000000
39.860001,4.477402,-215.910538,0.004070,0.002096,0.053248,19.916477,1.014594,0.532476,-215.910538,0.054262,0.000000
40.610001,4.625237,-215.910538,0.004109,0.002146,0.054505,20.574080,1.048094,0.545051,-215.910538,0.055511,0.000000
41.360001,4.668434,-216.043976,0.004161,0.002199,0.055867,20.766232,1.057882,0.558668,-216.043976,0.056760,0.000000
42.110001,4.838608,-216.043976,0.004204,0.002248,0.057098,21.523203,1.096444,0.570982,-216.043976,0.058009,0.000000
42.860001,4.957764,-216.043976,0.004273,0.002298,0.058364,22.053234,1.123445,0.583642,-216.043976,0.059257,0.000000
43.610001,4.994629,-215.999496,0.004337,0.002345,0.059570,22.217218,1.131799,0.595697,-215.999496,0.060515,0.000000
44.360001,5.078781,-216.043976,0.004355,0.002392,0.060749,22.591547,1.150868,0.607491,-216.043976,0.061764,0.000000
45.110001,5.197945,-216.088455,0.004428,0.002446,0.062128,23.121613,1.177871,0.621281,-216.088455,0.063013,0.000000
45.860001,5.301094,-216.132935,0.004484,0.002494,0.063342,23.580444,1.201245,0.633421,-216.132935,0.064261,0.000000
46.610001,5.373329,-216.132935,0.004506,0.002544,0.064608,23.901762,1.217614,0.646083,-216.132935,0.065510,0.000000
47.360001,5.406471,-216.132935,0.004544,0.002594,0.065883,24.049185,1.225124,0.658831,-216.132935,0.066759,0.000000
48.110001,5.483185,-216.132935,0.004635,0.002641,0.067080,24.390425,1.242507,0.670799,-216.132935,0.068008,0.000000
48.860001,5.684631,-216.221909,0.004656,0.002697,0.068494,25.286503,1.288156,0.684935,-216.221909,0.069265,0.000000
49.610001,5.703995,-216.221909,0.004717,0.002741,0.069630,25.372637,1.292544,0.696296,-216.221909,0.070514,0.000000
50.360001,5.695061,-216.221909,0.004756,0.002781,0.070636,25.332895,1.290519,0.706356,-216.221909,0.071763,0.000000
51.110001,5.834702,-216.221909,0.004816,0.002838,0.072075,25.954048,1.322162,0.720752,-216.221909,0.073012,0.000000
51.860001,5.886086,-216.310867,0.004859,0.002885,0.073289,26.182615,1.333806,0.732892,-216.310867,0.074261,0.000000
52.610001,6.027962,-216.221909,0.004907,0.002939,0.074660,26.813713,1.365956,0.746595,-216.221909,0.075509,0.000000
53.360004,6.007111,-216.310867,0.004971,0.002984,0.075787,26.720963,1.361231,0.757868,-216.310867,0.076767,0.000000
54.110004,6.125526,-216.310867,0.005019,0.003033,0.077027,27.247702,1.388064,0.770270,-216.310867,0.078016,0.000000
54.860004,6.160156,-216.355347,0.005057,0.003084,0.078337,27.401743,1.395911,0.783365,-216.355347,0.079264,0.000000
55.610004,6.280800,-216.399826,0.005096,0.003132,0.079551,27.938393,1.423250,0.795505,-216.399826,0.080513,0.000000
56.360004,6.359001,-216.399826,0.005174,0.003182,0.080825,28.286249,1.440970,0.808255,-216.399826,0.081762,0.000000
57.110004,6.350067,-216.355347,0.005191,0.003231,0.082074,28.246510,1.438946,0.820743,-216.355347,0.083011,0.000000
57.860004,6.420441,-216.355347,0.005256,0.003275,0.083193,28.559547,1.454893,0.831929,-216.355347,0.084260,0.000000
58.610004,6.553009,-216.444305,0.005316,0.003332,0.084633,29.149240,1.484933,0.846325,-216.444305,0.085517,0.000000
59.360004,6.607750,-216.444305,0.005372,0.003380,0.085847,29.392740,1.497337,0.858467,-216.444305,0.086766,0.000000
60.110004,6.651314,-216.444305,0.005424,0.003427,0.087035,29.586521,1.507209,0.870348,-216.444305,0.088015,0.000000
60.860004,6.648705,-216.488785,0.005476,0.003475,0.088275,29.574915,1.506618,0.882749,-216.488785,0.089264,0.000000
61.610004,6.747017,-216.488785,0.005536,0.003523,0.089489,30.012230,1.528896,0.894889,-216.488785,0.090512,0.000000
62.360004,6.874367,-216.533264,0.005579,0.003580,0.090937,30.578711,1.557754,0.909372,-216.533264,0.091761,0.000000
63.110004,6.758926,-216.533264,0.005627,0.003620,0.091961,30.065207,1.531595,0.919606,-216.533264,0.093010,0.000000
63.860004,6.956657,-216.577744,0.005683,0.003672,0.093270,30.944757,1.576401,0.932700,-216.577744,0.094267,0.000000
64.610001,6.987564,-216.622238,0.005739,0.003724,0.094580,31.082237,1.583405,0.945796,-216.622238,0.095516,0.000000
65.360001,7.094437,-216.622238,0.005777,0.003776,0.095915,31.557631,1.607622,0.959151,-216.622238,0.096765,0.000000
66.110001,7.150665,-216.666718,0.005816,0.003824,0.097129,31.807747,1.620364,0.971293,-216.666718,0.098014,0.000000
66.860001,7.121620,-216.666718,0.005885,0.003870,0.098291,31.678549,1.613782,0.982913,-216.666718,0.099263,0.000000
67.610001,7.167793,-216.622238,0.005915,0.003917,0.099497,31.883936,1.624245,0.994968,-216.622238,0.100511,0.000000
68.360001,7.288818,-216.666718,0.005980,0.003972,0.100893,32.422283,1.651670,1.008930,-216.666718,0.101760,0.000000
69.110001,7.327171,-216.711197,0.006045,0.004023,0.102194,32.592884,1.660361,1.021939,-216.711197,0.103018,0.000000
69.860001,7.298866,-216.711197,0.006092,0.004062,0.103174,32.466980,1.653947,1.031738,-216.711197,0.104266,0.000000
70.610001,7.365898,-216.711197,0.006148,0.004117,0.104579,32.765152,1.669136,1.045787,-216.711197,0.105515,0.000000
71.360001,7.413185,-216.755676,0.006183,0.004167,0.105845,32.975494,1.679852,1.058450,-216.755676,0.106764,0.000000
72.110001,7.501816,-216.755676,0.006239,0.004214,0.107042,33.369743,1.699936,1.070416,-216.755676,0.108013,0.000000
72.860001,7.544632,-216.844635,0.006269,0.004266,0.108351,33.560200,1.709638,1.083511,-216.844635,0.109262,0.000000
73.610001,7.548729,-216.889114,0.006334,0.004310,0.109470,33.578423,1.710566,1.094700,-216.889114,0.110511,0.000000
74.360001,7.599373,-216.844635,0.006407,0.004365,0.110883,33.803699,1.722042,1.108834,-216.844635,0.111768,0.000000
75.110001,7.605705,-216.889114,0.006446,0.004411,0.112037,33.831867,1.723477,1.120369,-216.889114,0.113017,0.000000
75.860001,7.696938,-216.889114,0.006497,0.004468,0.113494,34.237690,1.744151,1.134939,-216.889114,0.114266,0.000000
76.610001,7.642944,-216.933594,0.006541,0.004509,0.114517,33.997513,1.731916,1.145171,-216.933594,0.115514,0.000000
77.360001,7.749069,-216.978073,0.006597,0.004559,0.115809,34.469582,1.755964,1.158093,-216.978073,0.116763,0.000000
78.110001,7.756142,-216.978073,0.006653,0.004611,0.117110,34.501041,1.757567,1.171101,-216.978073,0.118012,0.000000
78.860001,7.804550,-217.067047,0.006700,0.004659,0.118333,34.716373,1.768536,1.183329,-217.067047,0.119270,0.000000
79.610001,7.834717,-217.067047,0.006748,0.004705,0.119495,34.850559,1.775372,1.194950,-217.067047,0.120518,0.000000
80.360001,7.779976,-216.978073,0.006795,0.004756,0.120813,34.607059,1.762968,1.208133,-216.978073,0.121767,0.000000
81.110001,7.821678,-217.111526,0.006829,0.004800,0.121923,34.792561,1.772418,1.219232,-217.111526,0.123016,0.000000
81.860001,7.911049,-217.022568,0.006911,0.004857,0.123363,35.190102,1.792669,1.233628,-217.022568,0.124265,0.000000
82.610001,7.843651,-217.156006,0.006920,0.004899,0.124447,34.890301,1.777397,1.244468,-217.156006,0.125514,0.000000
83.360001,7.934509,-217.067047,0.006980,0.004951,0.125756,35.294460,1.797986,1.257563,-217.067047,0.126762,0.000000
84.110001,7.921104,-217.200485,0.007045,0.005003,0.127066,35.234833,1.794948,1.270659,-217.200485,0.128020,0.000000
84.860001,8.010475,-217.200485,0.007101,0.005051,0.128306,35.632374,1.815200,1.283060,-217.200485,0.129269,0.000000
85.610001,8.036911,-217.200485,0.007136,0.005102,0.129581,35.749966,1.821190,1.295808,-217.200485,0.130517,0.000000
86.360001,8.075638,-217.244965,0.007183,0.005153,0.130882,35.922230,1.829966,1.308817,-217.244965,0.131766,0.000000
87.110001,8.059258,-217.244965,0.007222,0.005195,0.131966,35.849369,1.826254,1.319657,-217.244965,0.133015,0.000000
87.860001,8.121437,-217.289444,0.007295,0.005251,0.133388,36.125957,1.840344,1.333880,-217.289444,0.134264,0.000000
88.610001,8.172829,-217.244965,0.007368,0.005301,0.134645,36.354557,1.851990,1.346454,-217.244965,0.135513,0.000000
89.360001,8.209694,-217.244965,0.007416,0.005348,0.135851,36.518543,1.860343,1.358509,-217.244965,0.136770,0.000000
90.110001,8.147507,-217.289444,0.007442,0.005398,0.137100,36.241920,1.846251,1.370997,-217.289444,0.138019,0.000000
90.860001,8.156075,-217.333923,0.007519,0.005443,0.138244,36.280033,1.848193,1.382444,-217.333923,0.139268,0.000000
91.610001,8.241341,-217.422882,0.007562,0.005499,0.139675,36.659313,1.867514,1.396753,-217.422882,0.140516,0.000000
92.360001,8.168732,-217.378403,0.007606,0.005544,0.140829,36.336334,1.851061,1.408288,-217.378403,0.141765,0.000000
93.110001,8.203362,-217.333923,0.007644,0.005584,0.141835,36.490376,1.858908,1.418348,-217.333923,0.143014,0.000000
93.860008,8.240601,-217.422882,0.007687,0.005641,0.143283,36.656021,1.867347,1.432831,-217.422882,0.144263,0.000000
94.610008,8.238365,-217.422882,0.007769,0.005689,0.144497,36.646080,1.866840,1.444971,-217.422882,0.145521,0.000000
95.360008,8.354546,-217.467377,0.007812,0.005745,0.145911,37.162876,1.893167,1.459107,-217.467377,0.146769,0.000000
96.110008,8.273743,-217.467377,0.007864,0.005789,0.147038,36.803444,1.874857,1.470381,-217.467377,0.148018,0.000000
96.860008,8.358643,-217.467377,0.007916,0.005837,0.148261,37.181099,1.894096,1.482610,-217.467377,0.149267,0.000000
97.610008,8.295708,-217.511856,0.007963,0.005890,0.149605,36.901150,1.879834,1.496052,-217.511856,0.150516,0.000000
98.360008,8.344864,-217.467377,0.008011,0.005936,0.150767,37.119808,1.890973,1.507671,-217.467377,0.151764,0.000000
99.110008,8.488976,-217.556335,0.008067,0.005993,0.152215,37.760849,1.923629,1.522154,-217.556335,0.153022,0.000000
99.860008,8.305389,-217.511856,0.008123,0.006034,0.153273,36.944218,1.882028,1.532735,-217.511856,0.154271,0.000000
100.610008,8.356407,-217.600815,0.008157,0.006080,0.154444,37.171154,1.893589,1.544442,-217.600815,0.155520,0.000000
101.360008,8.452477,-217.600815,0.008209,0.006136,0.155849,37.598492,1.915359,1.558491,-217.600815,0.156768,0.000000
102.110008,8.500145,-217.600815,0.008269,0.006187,0.157159,37.810532,1.926160,1.571587,-217.600815,0.158017,0.000000
102.860008,8.489342,-217.600815,0.008334,0.006231,0.158277,37.762478,1.923712,1.582773,-217.600815,0.159266,0.000000
103.610008,8.383965,-217.645294,0.008347,0.006278,0.159465,37.293736,1.899834,1.594654,-217.645294,0.160515,0.000000
104.360008,8.441307,-217.600815,0.008395,0.006326,0.160671,37.548809,1.912827,1.606709,-217.600815,0.161772,0.000000
105.110008,8.535149,-217.689774,0.008455,0.006385,0.162189,37.966236,1.934092,1.621886,-217.689774,0.163021,0.000000
105.860008,8.560097,-217.734253,0.008485,0.006433,0.163394,38.077213,1.939746,1.633939,-217.734253,0.164270,0.000000
106.610008,8.577972,-217.689774,0.008558,0.006479,0.164565,38.156727,1.943796,1.645648,-217.689774,0.165519,0.000000
107.360008,8.560837,-217.734253,0.008619,0.006529,0.165840,38.080505,1.939913,1.658395,-217.734253,0.166767,0.000000
108.110008,8.538124,-217.823212,0.008675,0.006576,0.167036,37.979473,1.934767,1.670363,-217.823212,0.168016,0.000000
108.860008,8.625633,-217.778732,0.008714,0.006628,0.168355,38.368732,1.954596,1.683546,-217.778732,0.169265,0.000000
109.610008,8.558609,-217.823212,0.008765,0.006674,0.169525,38.070595,1.939409,1.695253,-217.823212,0.170523,0.000000
110.360008,8.579460,-217.823212,0.008800,0.006721,0.170705,38.163345,1.944133,1.707046,-217.823212,0.171771,0.000000
111.110008,8.612228,-217.867691,0.008864,0.006778,0.172170,38.309105,1.951559,1.721703,-217.867691,0.173020,0.000000
111.860008,8.631592,-217.867691,0.008903,0.006824,0.173324,38.395237,1.955947,1.733238,-217.867691,0.174269,0.000000
112.610008,8.729523,-217.912186,0.008942,0.006873,0.174581,38.830856,1.978138,1.745811,-217.912186,0.175518,0.000000
113.360008,8.634193,-217.956665,0.009020,0.006923,0.175847,38.406811,1.956536,1.758474,-217.956665,0.176767,0.000000
114.110008,8.585419,-217.956665,0.009037,0.006965,0.176905,38.189850,1.945484,1.769054,-217.956665,0.178015,0.000000
114.860008,8.745537,-217.956665,0.009106,0.007020,0.178319,38.902092,1.981767,1.783189,-217.956665,0.179273,0.000000
115.610008,8.740326,-218.001144,0.009184,0.007072,0.179628,38.878910,1.980586,1.796285,-218.001144,0.180522,0.000000
116.360008,8.825600,-218.001144,0.009209,0.007120,0.180860,39.258228,1.999910,1.808599,-218.001144,0.181771,0.000000
117.110008,8.717606,-217.956665,0.009278,0.007168,0.182065,38.777847,1.975438,1.820654,-217.956665,0.183019,0.000000
117.860008,8.693031,-218.001144,0.009326,0.007214,0.183228,38.668533,1.969869,1.832275,-218.001144,0.184268,0.000000
118.610008,8.807724,-218.045624,0.009356,0.007273,0.184728,39.178715,1.995859,1.847277,-218.045624,0.185517,0.000000
119.360008,8.760056,-218.001144,0.009412,0.007314,0.185768,38.966675,1.985057,1.857683,-218.001144,0.186774,0.000000
120.110008,8.802513,-218.090103,0.009438,0.007361,0.186965,39.155533,1.994678,1.869651,-218.090103,0.188023,0.000000
120.860008,8.786125,-218.090103,0.009524,0.007416,0.188379,39.082638,1.990964,1.883788,-218.090103,0.189272,0.000000
121.610008,8.890388,-218.134583,0.009559,0.007466,0.189636,39.546425,2.014591,1.896363,-218.134583,0.190521,0.000000
122.360008,8.865440,-218.134583,0.009602,0.007512,0.190807,39.435448,2.008938,1.908070,-218.134583,0.191770,0.000000
123.110008,8.782028,-218.223541,0.009671,0.007562,0.192073,39.064411,1.990036,1.920732,-218.223541,0.193018,0.000000
123.860008,8.820755,-218.179062,0.009701,0.007603,0.193105,39.236679,1.998812,1.931051,-218.179062,0.194267,0.000000
124.610008,8.865067,-218.179062,0.009744,0.007660,0.194571,39.433784,2.008853,1.945707,-218.179062,0.195525,0.000000
125.360008,8.875122,-218.223541,0.009822,0.007707,0.195750,39.478516,2.011132,1.957502,-218.223541,0.196773,0.000000
126.110008,8.951828,-218.223541,0.009865,0.007757,0.197034,39.819721,2.028513,1.970337,-218.223541,0.198022,0.000000
126.860008,8.938797,-218.312515,0.009912,0.007809,0.198352,39.761753,2.025560,1.983518,-218.312515,0.199271,0.000000
127.610008,8.912361,-218.356995,0.009960,0.007855,0.199523,39.644161,2.019570,1.995226,-218.356995,0.200520,0.000000
128.360001,9.006195,-218.268021,0.010024,0.007909,0.200893,40.061558,2.040833,2.008928,-218.268021,0.201769,0.000000
129.110001,8.978271,-218.312515,0.010054,0.007958,0.202124,39.937347,2.034505,2.021244,-218.312515,0.203018,0.000000
129.860001,9.037102,-218.356995,0.010106,0.008005,0.203330,40.199036,2.047837,2.033297,-218.356995,0.204275,0.000000
130.610001,8.999496,-218.356995,0.010149,0.008055,0.204596,40.031761,2.039315,2.045959,-218.356995,0.205524,0.000000
131.360001,9.046043,-218.401474,0.010184,0.008104,0.205836,40.238811,2.049863,2.058360,-218.401474,0.206773,0.000000
132.110001,9.124611,-218.401474,0.010257,0.008157,0.207180,40.588295,2.067666,2.071802,-218.401474,0.208021,0.000000
132.860001,9.092957,-218.445953,0.010313,0.008205,0.208403,40.447491,2.060493,2.084029,-218.445953,0.209270,0.000000
133.610001,9.129822,-218.445953,0.010374,0.008252,0.209591,40.611477,2.068847,2.095910,-218.445953,0.210519,0.000000
134.360001,9.087746,-218.490433,0.010425,0.008304,0.210927,40.424313,2.059313,2.109267,-218.490433,0.211768,0.000000
135.110001,9.178604,-218.445953,0.010468,0.008353,0.212158,40.828472,2.079901,2.121581,-218.445953,0.213025,0.000000
135.860001,9.246002,-218.445953,0.010507,0.008397,0.213294,41.128273,2.095174,2.132941,-218.445953,0.214274,0.000000
136.610001,9.184189,-218.534912,0.010568,0.008450,0.214621,40.853313,2.081167,2.146209,-218.534912,0.215523,0.000000
137.360001,9.110458,-218.534912,0.010606,0.008493,0.215722,40.525341,2.064460,2.157224,-218.534912,0.216772,0.000000
138.110001,9.203178,-218.623871,0.010658,0.008548,0.217119,40.937782,2.085470,2.171186,-218.623871,0.218021,0.000000
138.860001,9.182327,-218.623871,0.010710,0.008595,0.218307,40.845032,2.080745,2.183067,-218.623871,0.219269,0.000000
139.610001,9.313034,-218.668350,0.010774,0.008650,0.219720,41.426445,2.110364,2.197203,-218.668350,0.220518,0.000000
140.360001,9.207649,-218.623871,0.010818,0.008694,0.220839,40.957668,2.086483,2.208390,-218.623871,0.221776,0.000000
141.110001,9.192757,-218.712830,0.010839,0.008739,0.221975,40.891422,2.083108,2.219750,-218.712830,0.223024,0.000000
141.860001,9.302605,-218.668350,0.010895,0.008796,0.223406,41.380051,2.108001,2.234061,-218.668350,0.224273,0.000000
142.610001,9.251961,-218.712830,0.010960,0.008841,0.224559,41.154778,2.096524,2.245593,-218.712830,0.225522,0.000000
143.360001,9.260902,-218.712830,0.011007,0.008888,0.225747,41.194550,2.098550,2.257474,-218.712830,0.226771,0.000000
144.110001,9.289200,-218.668350,0.011076,0.008941,0.227109,41.320423,2.104963,2.271090,-218.668350,0.228020,0.000000
144.860001,9.275421,-218.712830,0.011102,0.008985,0.228210,41.259132,2.101840,2.282104,-218.712830,0.229277,0.000000
145.610001,9.451553,-218.757324,0.011145,0.009040,0.229624,42.042610,2.141752,2.296241,-218.757324,0.230526,0.000000
146.360001,9.364418,-218.801804,0.011214,0.009087,0.230803,41.655010,2.122008,2.308035,-218.801804,0.231775,0.000000
147.110001,9.371864,-218.801804,0.011240,0.009134,0.231992,41.688133,2.123695,2.319915,-218.801804,0.233023,0.000000
147.860001,9.369263,-218.846283,0.011292,0.009187,0.233353,41.676563,2.123105,2.333532,-218.846283,0.234272,0.000000
148.610001,9.331650,-218.846283,0.011365,0.009232,0.234498,41.509251,2.114582,2.344979,-218.846283,0.235521,0.000000
149.360001,9.498474,-218.890762,0.011395,0.009285,0.235833,42.251324,2.152385,2.358334,-218.890762,0.236770,0.000000
150.110001,9.519699,-218.890762,0.011451,0.009336,0.237143,42.345737,2.157195,2.371428,-218.890762,0.238027,0.000000
150.860001,9.419907,-218.935242,0.011507,0.009381,0.238279,41.901836,2.134581,2.382790,-218.935242,0.239276,0.000000
151.610001,9.577042,-218.935242,0.011555,0.009435,0.239649,42.600807,2.170189,2.396491,-218.935242,0.240525,0.000000
152.360001,9.419907,-218.935242,0.011594,0.009479,0.240759,41.901836,2.134581,2.407593,-218.935242,0.241774,0.000000
153.110001,9.542038,-218.979721,0.011632,0.009529,0.242025,42.445107,2.162257,2.420253,-218.979721,0.243023,0.000000
153.860001,9.521561,-218.979721,0.011693,0.009581,0.243370,42.354015,2.157616,2.433695,-218.979721,0.244271,0.000000
154.610001,9.575554,-219.068680,0.011753,0.009629,0.244584,42.594193,2.169852,2.445837,-219.068680,0.245520,0.000000
155.360001,9.718918,-219.024200,0.011801,0.009684,0.245971,43.231907,2.202338,2.459713,-219.024200,0.246778,0.000000
156.110001,9.564011,-219.068680,0.011874,0.009727,0.247064,42.542843,2.167236,2.470639,-219.068680,0.248026,0.000000
156.860001,9.597527,-219.068680,0.011904,0.009772,0.248200,42.691929,2.174831,2.482000,-219.068680,0.249275,0.000000
157.610001,9.677582,-219.113159,0.011952,0.009827,0.249596,43.048035,2.192971,2.495962,-219.113159,0.250524,0.000000
158.360001,9.674606,-219.202133,0.012012,0.009876,0.250854,43.034798,2.192297,2.508538,-219.202133,0.251773,0.000000
159.110001,9.821320,-219.157639,0.012077,0.009929,0.252189,43.687412,2.225543,2.521893,-219.157639,0.253022,0.000000
159.860001,9.722267,-219.157639,0.012094,0.009973,0.253325,43.246803,2.203097,2.533253,-219.157639,0.254271,0.000000
160.610001,9.684288,-219.246613,0.012163,0.010017,0.254444,43.077866,2.194491,2.544439,-219.246613,0.255528,0.000000
161.360001,9.758759,-219.157639,0.012193,0.010076,0.255936,43.409126,2.211366,2.559355,-219.157639,0.256777,0.000000
162.110001,9.701416,-219.202133,0.012262,0.010114,0.256890,43.154053,2.198372,2.568895,-219.202133,0.258026,0.000000
162.860001,9.673492,-219.202133,0.012301,0.010160,0.258060,43.029842,2.192045,2.580604,-219.202133,0.259274,0.000000
163.610001,9.792648,-219.335571,0.012344,0.010222,0.259630,43.559875,2.219046,2.596300,-219.335571,0.260523,0.000000
164.360001,9.840683,-219.335571,0.012421,0.010268,0.260801,43.773544,2.229931,2.608008,-219.335571,0.261772,0.000000
165.110001,10.046608,-219.291092,0.012456,0.010323,0.262197,44.689545,2.276594,2.621971,-219.291092,0.263030,0.000000
165.860001,9.809402,-219.246613,0.012529,0.010364,0.263246,43.634403,2.222842,2.632463,-219.246613,0.264278,0.000000
166.610001,9.984421,-219.380051,0.012551,0.010416,0.264556,44.412922,2.262502,2.645558,-219.380051,0.265527,0.000000
167.360001,9.787064,-219.335571,0.012607,0.010463,0.265770,43.535034,2.217780,2.657700,-219.335571,0.266776,0.000000
168.110001,9.951653,-219.380051,0.012641,0.010511,0.266975,44.267162,2.255077,2.669753,-219.380051,0.268025,0.000000
168.860001,10.027985,-219.380051,0.012710,0.010563,0.268294,44.606705,2.272374,2.682936,-219.380051,0.269274,0.000000
169.610001,9.863029,-219.380051,0.012753,0.010607,0.269430,43.872948,2.234994,2.694296,-219.380051,0.270522,0.000000
170.360001,9.990379,-219.424530,0.012805,0.010659,0.270739,44.439426,2.263852,2.707392,-219.424530,0.271780,0.000000
171.110001,10.046234,-219.424530,0.012866,0.010709,0.272014,44.687881,2.276509,2.720140,-219.424530,0.273029,0.000000
171.860001,10.120338,-219.469009,0.012896,0.010762,0.273349,45.017513,2.293301,2.733495,-219.469009,0.274278,0.000000
172.610001,10.208961,-219.513489,0.012969,0.010809,0.274555,45.411728,2.313384,2.745549,-219.513489,0.275526,0.000000
173.360001,10.117729,-219.469009,0.013008,0.010860,0.275838,45.005909,2.292710,2.758384,-219.469009,0.276775,0.000000
174.110016,10.175446,-219.513489,0.013068,0.010908,0.277070,45.262642,2.305789,2.770698,-219.513489,0.278024,0.000000
174.860016,10.273010,-219.557968,0.013111,0.010962,0.278431,45.696632,2.327898,2.784314,-219.557968,0.279273,0.000000
175.610016,10.229065,-219.557968,0.013172,0.011010,0.279663,45.501152,2.317939,2.796629,-219.557968,0.280530,0.000000
176.360016,10.168747,-219.557968,0.013219,0.011052,0.280712,45.232845,2.304271,2.807122,-219.557968,0.281779,0.000000
177.110016,10.277473,-219.602463,0.013258,0.011109,0.282161,45.716484,2.328909,2.821605,-219.602463,0.283028,0.000000
177.860016,10.266304,-219.602463,0.013305,0.011153,0.283297,45.666801,2.326378,2.832965,-219.602463,0.284277,0.000000
178.610016,10.452492,-219.691422,0.013370,0.011205,0.284597,46.495007,2.368569,2.845974,-219.691422,0.285525,0.000000
179.360016,10.409668,-219.646942,0.013417,0.011255,0.285872,46.304516,2.358864,2.858722,-219.646942,0.286774,0.000000
180.110016,10.449516,-219.646942,0.013469,0.011300,0.287008,46.481770,2.367894,2.870084,-219.646942,0.288023,0.000000
180.860016,10.449516,-219.735901,0.013530,0.011355,0.288413,46.481770,2.367894,2.884132,-219.735901,0.289280,0.000000
181.610016,10.491219,-219.735901,0.013551,0.011402,0.289610,46.667271,2.377344,2.896099,-219.735901,0.290529,0.000000
182.360016,10.565697,-219.780380,0.013620,0.011456,0.290980,46.998566,2.394221,2.909803,-219.780380,0.291778,0.000000
183.110016,10.428291,-219.735901,0.013650,0.011498,0.292038,46.387356,2.363085,2.920381,-219.735901,0.293027,0.000000
183.860016,10.376526,-219.780380,0.013698,0.011538,0.293062,46.157093,2.351354,2.930616,-219.780380,0.294276,0.000000
184.610016,10.575745,-219.824860,0.013758,0.011599,0.294623,47.043262,2.396498,2.946227,-219.824860,0.295524,0.000000
185.360016,10.643890,-219.824860,0.013810,0.011648,0.295854,47.346390,2.411940,2.958541,-219.824860,0.296773,0.000000
186.110016,10.713898,-219.780380,0.013862,0.011695,0.297060,47.657799,2.427804,2.970596,-219.780380,0.298031,0.000000
186.860016,10.600693,-219.824860,0.013918,0.011745,0.298326,47.154236,2.402151,2.983256,-219.824860,0.299280,0.000000
187.610016,10.560478,-219.913818,0.013961,0.011786,0.299366,46.975353,2.393039,2.993663,-219.913818,0.300528,0.000000
188.360016,10.719856,-219.913818,0.013995,0.011845,0.300858,47.684303,2.429154,3.008579,-219.913818,0.301777,0.000000
189.110016,10.639793,-219.913818,0.014047,0.011889,0.301968,47.328163,2.411012,3.019680,-219.913818,0.303026,0.000000
189.860016,10.729912,-219.958298,0.014094,0.011936,0.303173,47.729031,2.431433,3.031735,-219.958298,0.304275,0.000000
190.610016,10.759697,-220.002777,0.014159,0.011991,0.304578,47.861523,2.438182,3.045783,-220.002777,0.305532,0.000000
191.360016,10.825981,-220.002777,0.014198,0.012037,0.305749,48.156368,2.453202,3.057491,-220.002777,0.306781,0.000000
192.110016,10.866943,-220.002777,0.014250,0.012087,0.306998,48.338577,2.462484,3.069979,-220.002777,0.308030,0.000000
192.860016,10.878487,-220.002777,0.014293,0.012139,0.308325,48.389927,2.465101,3.083247,-220.002777,0.309279,0.000000
193.610016,10.925034,-220.091751,0.014362,0.012186,0.309530,48.596977,2.475648,3.095302,-220.091751,0.310528,0.000000
194.360016,11.037117,-220.091751,0.014400,0.012238,0.310848,49.095547,2.501046,3.108483,-220.091751,0.311776,0.000000
195.110016,11.125366,-220.047272,0.014439,0.012290,0.312175,49.488102,2.521044,3.121753,-220.047272,0.313025,0.000000
195.860016,11.212502,-220.091751,0.014504,0.012339,0.313407,49.875698,2.540789,3.134067,-220.091751,0.314283,0.000000
196.610016,11.109726,-220.136230,0.014538,0.012389,0.314673,49.418530,2.517500,3.146728,-220.136230,0.315531,0.000000
197.360016,11.063927,-220.136230,0.014582,0.012432,0.315783,49.214806,2.507122,3.157829,-220.136230,0.316780,0.000000
198.110016,11.279907,-220.180710,0.014642,0.012489,0.317231,50.175533,2.556064,3.172312,-220.180710,0.318029,0.000000
198.860016,11.149574,-220.180710,0.014694,0.012531,0.318281,49.595783,2.526530,3.182805,-220.180710,0.319278,0.000000
199.610016,11.128723,-220.269669,0.014737,0.012575,0.319417,49.503033,2.521805,3.194165,-220.269669,0.320527,0.000000
200.360016,11.295914,-220.180710,0.014776,0.012630,0.320813,50.246735,2.559691,3.208128,-220.180710,0.321775,0.000000
201.110016,11.281395,-220.225189,0.014823,0.012679,0.322044,50.182152,2.556401,3.220442,-220.225189,0.323033,0.000000
201.860016,11.413956,-220.269669,0.014896,0.012731,0.323371,50.771812,2.586439,3.233710,-220.269669,0.324282,0.000000
202.610016,11.341721,-220.269669,0.014935,0.012776,0.324507,50.450493,2.570071,3.245072,-220.269669,0.325530,0.000000
203.360016,11.538330,-220.314148,0.014974,0.012826,0.325782,51.325054,2.614623,3.257820,-220.314148,0.326779,0.000000
204.110016,11.461250,-220.314148,0.015052,0.012879,0.327126,50.982189,2.597156,3.271262,-220.314148,0.328028,0.000000
204.860016,11.511520,-220.358627,0.015095,0.012923,0.328254,51.205799,2.608548,3.282535,-220.358627,0.329277,0.000000
205.610016,11.793030,-220.314148,0.015138,0.012978,0.329650,52.458015,2.672339,3.296498,-220.314148,0.330526,0.000000
206.360016,11.593071,-220.358627,0.015177,0.013025,0.330829,51.568554,2.627028,3.308291,-220.358627,0.331783,0.000000
207.110016,11.450821,-220.403107,0.015237,0.013064,0.331835,50.935795,2.594793,3.318352,-220.403107,0.333032,0.000000
207.860016,11.677971,-220.447586,0.015280,0.013122,0.333292,51.946209,2.646266,3.332922,-220.447586,0.334281,0.000000
208.610016,11.699570,-220.447586,0.015332,0.013169,0.334480,52.042286,2.651160,3.344803,-220.447586,0.335530,0.000000
209.360016,11.817978,-220.447586,0.015396,0.013218,0.335746,52.568993,2.677992,3.357465,-220.447586,0.336778,0.000000
210.110016,11.806435,-220.492081,0.015440,0.013266,0.336960,52.517643,2.675376,3.369605,-220.492081,0.338027,0.000000
210.860016,11.912567,-220.492081,0.015487,0.013318,0.338270,52.989746,2.699426,3.382701,-220.492081,0.339285,0.000000
211.610016,12.105827,-220.492081,0.015543,0.013371,0.339623,53.849411,2.743220,3.396230,-220.492081,0.340533,0.000000
212.360016,11.806435,-220.492081,0.015573,0.013411,0.340629,52.517643,2.675376,3.406288,-220.492081,0.341782,0.000000
213.110016,12.047363,-220.536560,0.015655,0.013462,0.341947,53.589348,2.729971,3.419471,-220.536560,0.343031,0.000000
213.860016,12.151253,-220.581039,0.015681,0.013516,0.343317,54.051472,2.753513,3.433172,-220.581039,0.344280,0.000000
214.610016,12.281960,-220.581039,0.015746,0.013568,0.344618,54.632885,2.783132,3.446181,-220.581039,0.345529,0.000000
215.360016,12.359413,-220.581039,0.015776,0.013616,0.345841,54.977417,2.800683,3.458410,-220.581039,0.346778,0.000000
216.110016,12.222008,-220.581039,0.015832,0.013662,0.347012,54.366207,2.769547,3.470117,-220.581039,0.348035,0.000000
216.860016,12.340790,-220.669998,0.015871,0.013712,0.348295,54.894573,2.796463,3.482951,-220.669998,0.349284,0.000000
217.610016,12.438728,-220.625519,0.015935,0.013766,0.349648,55.330227,2.818656,3.496480,-220.625519,0.350533,0.000000
218.360016,12.474472,-220.714478,0.015991,0.013815,0.350897,55.489223,2.826756,3.508969,-220.714478,0.351781,0.000000
219.110016,12.565331,-220.714478,0.016022,0.013858,0.351998,55.893383,2.847345,3.519983,-220.714478,0.353030,0.000000
219.860016,12.610016,-220.758957,0.016104,0.013913,0.353386,56.092152,2.857470,3.533858,-220.758957,0.354279,0.000000
220.610016,12.621185,-220.758957,0.016121,0.013957,0.354513,56.141834,2.860002,3.545131,-220.758957,0.355528,0.000000
221.360016,12.872910,-220.847916,0.016198,0.014009,0.355840,57.261562,2.917043,3.558401,-220.847916,0.356785,0.000000
222.110016,12.889671,-220.847916,0.016241,0.014060,0.357115,57.336121,2.920841,3.571149,-220.847916,0.358034,0.000000
222.860016,12.792107,-220.847916,0.016289,0.014100,0.358138,56.902134,2.898733,3.581381,-220.847916,0.359283,0.000000
223.610016,12.916107,-220.847916,0.016345,0.014157,0.359586,57.453712,2.926832,3.595864,-220.847916,0.360532,0.000000
224.360016,12.934357,-220.847916,0.016379,0.014203,0.360749,57.534893,2.930967,3.607486,-220.847916,0.361780,0.000000
225.110016,13.090004,-220.847916,0.016457,0.014259,0.362171,58.227245,2.966237,3.621707,-220.847916,0.363029,0.000000
225.860016,12.977547,-220.892410,0.016461,0.014301,0.363246,57.727013,2.940754,3.632462,-220.892410,0.364278,0.000000
226.610016,13.365189,-220.936890,0.016517,0.014350,0.364495,59.451328,3.028595,3.644950,-220.936890,0.365536,0.000000
227.360016,13.399445,-220.981369,0.016586,0.014406,0.365917,59.603706,3.036358,3.659172,-220.981369,0.366784,0.000000
228.110016,13.509666,-220.936890,0.016638,0.014453,0.367097,60.093998,3.061334,3.670966,-220.936890,0.368033,0.000000
228.860016,13.509300,-220.981369,0.016681,0.014494,0.368146,60.092369,3.061251,3.681459,-220.981369,0.369282,0.000000
229.610016,13.518982,-221.025848,0.016720,0.014549,0.369533,60.135433,3.063445,3.695335,-221.025848,0.370531,0.000000
230.360016,13.552116,-221.025848,0.016763,0.014593,0.370661,60.282825,3.070954,3.706610,-221.025848,0.371780,0.000000
231.110016,13.658615,-221.070328,0.016819,0.014647,0.372022,60.756554,3.095087,3.720224,-221.070328,0.373028,0.000000
231.860016,13.548027,-221.114807,0.016871,0.014690,0.373115,60.264633,3.070027,3.731151,-221.114807,0.374286,0.000000
232.610016,13.674255,-221.114807,0.016918,0.014740,0.374399,60.826126,3.098630,3.743986,-221.114807,0.375535,0.000000
233.360016,13.791557,-221.159286,0.016974,0.014794,0.375778,61.347912,3.125211,3.757776,-221.159286,0.376783,0.000000
234.110016,14.112541,-221.159286,0.017013,0.014845,0.377052,62.775719,3.197948,3.770524,-221.159286,0.378032,0.000000
234.860016,14.217918,-221.114807,0.017069,0.014895,0.378345,63.244461,3.221826,3.783445,-221.114807,0.379281,0.000000
235.610016,14.104721,-221.248245,0.017117,0.014938,0.379437,62.740932,3.196175,3.794372,-221.248245,0.380530,0.000000
236.360016,14.212708,-221.203766,0.017173,0.014989,0.380721,63.221279,3.220646,3.807207,-221.203766,0.381787,0.000000
237.110016,14.469643,-221.292725,0.017212,0.015044,0.382108,64.364182,3.278868,3.821082,-221.292725,0.383036,0.000000
237.860016,14.524384,-221.248245,0.017281,0.015093,0.383357,64.607681,3.291272,3.833570,-221.248245,0.384285,0.000000
238.610016,14.813347,-221.248245,0.017337,0.015146,0.384710,65.893059,3.356752,3.847100,-221.248245,0.385534,0.000000
239.360016,14.696045,-221.248245,0.017401,0.015191,0.385863,65.371269,3.330171,3.858634,-221.248245,0.386783,0.000000
240.110016,14.887817,-221.292725,0.017431,0.015241,0.387129,66.224319,3.373628,3.871295,-221.292725,0.388031,0.000000
240.860016,14.951492,-221.337219,0.017475,0.015292,0.388413,66.507561,3.388057,3.884131,-221.337219,0.389280,0.000000
241.610016,15.086670,-221.337219,0.017526,0.015338,0.389584,67.108856,3.418688,3.895838,-221.337219,0.390538,0.000000
242.360016,15.018150,-221.337219,0.017578,0.015382,0.390703,66.804070,3.403162,3.907026,-221.337219,0.391787,0.000000
243.110016,15.253860,-221.381699,0.017600,0.015436,0.392081,67.852562,3.456574,3.920814,-221.381699,0.393035,0.000000
243.860016,15.184227,-221.426178,0.017673,0.015479,0.393174,67.542816,3.440795,3.931741,-221.426178,0.394284,0.000000
244.610016,15.585274,-221.426178,0.017725,0.015537,0.394631,69.326759,3.531673,3.946311,-221.426178,0.395533,0.000000
245.360016,15.730125,-221.470657,0.017781,0.015584,0.395836,69.971092,3.564497,3.958364,-221.470657,0.396782,0.000000
246.110016,15.758057,-221.515137,0.017811,0.015631,0.397033,70.095337,3.570827,3.970332,-221.515137,0.398031,0.000000
246.860016,15.832153,-221.515137,0.017884,0.015682,0.398334,70.424934,3.587617,3.983341,-221.515137,0.399288,0.000000
247.610016,15.924507,-221.515137,0.017910,0.015726,0.399435,70.835747,3.608545,3.994355,-221.515137,0.400537,0.000000
248.360016,16.475990,-221.515137,0.017979,0.015786,0.400962,73.288864,3.733513,4.009617,-221.515137,0.401786,0.000000
249.110016,16.162079,-221.559616,0.018018,0.015827,0.402002,71.892517,3.662380,4.020024,-221.559616,0.403035,0.000000
249.860016,16.293152,-221.604095,0.018044,0.015872,0.403147,72.475555,3.692081,4.031471,-221.604095,0.404283,0.000000
250.610016,16.581741,-221.559616,0.018108,0.015928,0.404570,73.759270,3.757476,4.045695,-221.559616,0.405532,0.000000
251.360016,16.886345,-221.648575,0.018164,0.015977,0.405827,75.114212,3.826500,4.058269,-221.648575,0.406781,0.000000
252.110016,16.842400,-221.604095,0.018212,0.016021,0.406937,74.918732,3.816542,4.069370,-221.604095,0.408038,0.000000
252.860016,16.983162,-221.648575,0.018238,0.016072,0.408229,75.544876,3.848440,4.082291,-221.648575,0.409287,0.000000
253.610016,17.233025,-221.693054,0.018311,0.016121,0.409478,76.656319,3.905059,4.094779,-221.693054,0.410536,0.000000
254.360016,17.486977,-221.737534,0.018354,0.016176,0.410883,77.785957,3.962605,4.108829,-221.737534,0.411785,0.000000
255.110016,17.516769,-221.693054,0.018406,0.016221,0.412002,77.918480,3.969357,4.120015,-221.693054,0.413033,0.000000
255.860016,17.733490,-221.648575,0.018453,0.016270,0.413259,78.882500,4.018466,4.132591,-221.648575,0.414282,0.000000
256.610016,17.924515,-221.693054,0.018492,0.016320,0.414525,79.732224,4.061753,4.145251,-221.693054,0.415540,0.000000
257.360016,18.102509,-221.782028,0.018561,0.016370,0.415809,80.523979,4.102087,4.158088,-221.782028,0.416789,0.000000
258.110016,18.279015,-221.826508,0.018613,0.016420,0.417066,81.309120,4.142084,4.170661,-221.826508,0.418037,0.000000
258.860016,18.392593,-221.826508,0.018660,0.016466,0.418246,81.814339,4.167821,4.182456,-221.826508,0.419286,0.000000
259.610016,18.518082,-221.782028,0.018703,0.016513,0.419442,82.372543,4.196258,4.194424,-221.782028,0.420535,0.000000
260.360016,18.878532,-221.826508,0.018755,0.016570,0.420873,83.975906,4.277936,4.208733,-221.826508,0.421784,0.000000
261.110016,18.972374,-221.870987,0.018785,0.016618,0.422087,84.393333,4.299201,4.220873,-221.870987,0.423033,0.000000
261.860016,19.629982,-221.915466,0.018841,0.016669,0.423397,87.318520,4.448217,4.233969,-221.915466,0.424290,0.000000
262.610016,19.497795,-221.959946,0.018893,0.016717,0.424620,86.730522,4.418263,4.246198,-221.959946,0.425539,0.000000
263.360016,19.418472,-221.915466,0.018949,0.016759,0.425669,86.377678,4.400289,4.256690,-221.915466,0.426788,0.000000
264.110016,20.040337,-221.959946,0.019001,0.016815,0.427109,89.143867,4.541205,4.271086,-221.959946,0.428037,0.000000
264.860016,20.304352,-221.959946,0.019044,0.016865,0.428366,90.318268,4.601032,4.283661,-221.959946,0.429285,0.000000
265.610016,20.486809,-222.048904,0.019070,0.016910,0.429520,91.129875,4.642377,4.295195,-222.048904,0.430534,0.000000
266.360016,20.516975,-222.048904,0.019130,0.016959,0.430768,91.264061,4.649213,4.307683,-222.048904,0.431783,0.000000
267.110016,20.796623,-222.048904,0.019186,0.017005,0.431939,92.508003,4.712582,4.319390,-222.048904,0.433040,0.000000
267.860016,21.356300,-222.093384,0.019225,0.017065,0.433448,94.997566,4.839406,4.334481,-222.093384,0.434289,0.000000
268.610016,21.094894,-221.959946,0.019285,0.017103,0.434411,93.834778,4.780171,4.344108,-221.959946,0.435538,0.000000
269.360016,21.651222,-222.048904,0.019324,0.017151,0.435633,96.309448,4.906237,4.356335,-222.048904,0.436787,0.000000
270.110016,21.954330,-222.048904,0.019385,0.017208,0.437073,97.657738,4.974923,4.370730,-222.048904,0.438036,0.000000
270.860016,22.401550,-222.182358,0.019423,0.017255,0.438287,99.647072,5.076264,4.382873,-222.182358,0.439285,0.000000
271.610016,22.772438,-222.137863,0.019467,0.017304,0.439519,101.296867,5.160308,4.395186,-222.137863,0.440533,0.000000
272.360016,22.753441,-222.182358,0.019527,0.017351,0.440724,101.212357,5.156003,4.407241,-222.182358,0.441791,0.000000
273.110016,23.398018,-222.182358,0.019570,0.017401,0.441981,104.079582,5.302067,4.419815,-222.182358,0.443040,0.000000
273.860016,23.605057,-222.137863,0.019609,0.017452,0.443274,105.000534,5.348982,4.432736,-222.137863,0.444288,0.000000
274.610016,24.095848,-222.226837,0.019661,0.017503,0.444566,107.183685,5.460197,4.445658,-222.226837,0.445537,0.000000
275.360016,24.280914,-222.226837,0.019704,0.017548,0.445719,108.006905,5.502134,4.457192,-222.226837,0.446786,0.000000
276.110016,24.538223,-222.226837,0.019755,0.017599,0.447003,109.151466,5.560441,4.470027,-222.226837,0.448035,0.000000
276.860016,24.875595,-222.315796,0.019798,0.017645,0.448191,110.652176,5.636890,4.481910,-222.315796,0.449284,0.000000
277.610016,25.373459,-222.315796,0.019850,0.017697,0.449492,112.866783,5.749708,4.494916,-222.315796,0.450541,0.000000
278.360016,25.908180,-222.315796,0.019889,0.017747,0.450784,115.245338,5.870877,4.507838,-222.315796,0.451790,0.000000
279.110016,26.113731,-222.315796,0.019945,0.017793,0.451946,116.159676,5.917456,4.519460,-222.315796,0.453039,0.000000
279.860016,26.571007,-222.315796,0.020005,0.017845,0.453264,118.193741,6.021076,4.532642,-222.315796,0.454287,0.000000
280.610016,27.214836,-222.315796,0.020040,0.017897,0.454591,121.057640,6.166970,4.545910,-222.315796,0.455536,0.000000
281.360016,27.935005,-222.449234,0.020096,0.017949,0.455909,124.261108,6.330163,4.559092,-222.449234,0.456785,0.000000
282.110016,28.248543,-222.404755,0.020143,0.017998,0.457158,125.655792,6.401211,4.571580,-222.404755,0.458043,0.000000
282.860016,28.561340,-222.404755,0.020182,0.018042,0.458268,127.047188,6.472093,4.582681,-222.404755,0.459291,0.000000
283.610016,29.184319,-222.449234,0.020234,0.018096,0.459630,129.818329,6.613261,4.596297,-222.449234,0.460540,0.000000
284.360016,29.731331,-222.493713,0.020277,0.018143,0.460835,132.251572,6.737216,4.608350,-222.493713,0.461789,0.000000
285.110016,30.288025,-222.449234,0.020320,0.018190,0.462015,134.727859,6.863364,4.620146,-222.449234,0.463038,0.000000
285.860016,30.796692,-222.449234,0.020368,0.018239,0.463281,136.990524,6.978630,4.632806,-222.449234,0.464287,0.000000
286.610016,31.070007,-222.538193,0.020402,0.018283,0.464399,138.206299,7.040564,4.643994,-222.538193,0.465535,0.000000
287.360016,32.031479,-222.538193,0.020454,0.018339,0.465822,142.483139,7.258437,4.658216,-222.538193,0.466793,0.000000
288.110016,32.436989,-222.582672,0.020497,0.018385,0.466966,144.286926,7.350327,4.669663,-222.582672,0.468042,0.000000
288.860016,33.642357,-222.582672,0.020557,0.018441,0.468397,149.648682,7.623467,4.683972,-222.582672,0.469290,0.000000
289.610016,31.759270,-222.582672,0.020566,0.018438,0.468319,141.272293,7.196753,4.683192,-222.582672,0.468120,0.000000
290.360016,30.732269,-222.582672,0.020579,0.018392,0.467157,136.703964,6.964032,4.671571,-222.582672,0.466871,0.000000
291.110016,30.223236,-222.671646,0.020579,0.018346,0.465978,134.439667,6.848683,4.659777,-222.671646,0.465622,0.000000
291.860016,29.760376,-222.671646,0.020575,0.018303,0.464902,132.380768,6.743798,4.649023,-222.671646,0.464373,0.000000
292.610016,29.458008,-222.627167,0.020587,0.018254,0.463645,131.035767,6.675280,4.636449,-222.627167,0.463116,0.000000
293.360016,29.175751,-222.671646,0.020575,0.018207,0.462457,129.780228,6.611320,4.624568,-222.671646,0.461867,0.000000
294.110016,28.377014,-222.760605,0.020596,0.018160,0.461251,126.227264,6.430323,4.612514,-222.760605,0.460618,0.000000
294.860016,26.881195,-222.716125,0.020592,0.018114,0.460107,119.573524,6.091366,4.601066,-222.716125,0.459369,0.000000
295.610016,24.451836,-222.716125,0.020587,0.018068,0.458919,108.767197,5.540865,4.589185,-222.716125,0.458121,0.000000
296.360016,21.389816,-222.716125,0.020592,0.018020,0.457713,95.146652,4.847002,4.577130,-222.716125,0.456872,0.000000
297.110016,17.793442,-222.760605,0.020557,0.017972,0.456482,79.149185,4.032052,4.564816,-222.760605,0.455614,0.000000
297.860016,14.059662,-222.760605,0.020544,0.017923,0.455250,62.540501,3.185965,4.552502,-222.760605,0.454365,0.000000
298.610016,10.552284,-222.805084,0.020514,0.017876,0.454053,46.938904,2.391182,4.540534,-222.805084,0.453117,0.000000
299.360016,7.051239,-222.760605,0.020484,0.017823,0.452700,31.365479,1.597834,4.527005,-222.760605,0.451868,0.000000
300.110016,4.061836,-222.760605,0.020445,0.017771,0.451391,18.067949,0.920425,4.513909,-222.760605,0.450619,0.000000
300.860016,2.486702,-222.849564,0.020406,0.017730,0.450342,11.061402,0.563495,4.503416,-222.849564,0.449370,0.000000
301.610016,1.614235,-222.849564,0.020368,0.017676,0.448963,7.180476,0.365791,4.489627,-222.849564,0.448122,0.000000
302.360016,1.468636,-222.894043,0.020307,0.017632,0.447853,6.532817,0.332798,4.478526,-222.894043,0.446864,0.000000
303.110016,1.293243,-222.938522,0.020243,0.017577,0.446465,5.752634,0.293053,4.464651,-222.938522,0.445615,0.000000
303.860016,1.132751,-222.983002,0.020187,0.017523,0.445086,5.038730,0.256685,4.450862,-222.983002,0.444366,0.000000
304.610016,1.010612,-222.938522,0.020130,0.017475,0.443855,4.495429,0.229008,4.438548,-222.938522,0.443118,0.000000
305.360016,0.934654,-223.027481,0.020083,0.017429,0.442701,4.157550,0.211796,4.427014,-223.027481,0.441869,0.000000
306.110016,0.850868,-223.027481,0.020031,0.017378,0.441409,3.784851,0.192810,4.414092,-223.027481,0.440620,0.000000
306.860016,0.743996,-223.027481,0.019975,0.017327,0.440100,3.309458,0.168592,4.400996,-223.027481,0.439371,0.000000
307.610016,0.698570,-223.027481,0.019932,0.017287,0.439094,3.107396,0.158298,4.390936,-223.027481,0.438114,0.000000
308.360016,0.600632,-223.071976,0.019898,0.017230,0.437637,2.671743,0.136105,4.376368,-223.071976,0.436865,0.000000
309.110016,0.577545,-223.116455,0.019855,0.017187,0.436544,2.569049,0.130874,4.365441,-223.116455,0.435616,0.000000
309.860016,0.475517,-223.071976,0.019781,0.017132,0.435148,2.115206,0.107754,4.351479,-223.071976,0.434367,0.000000
310.610016,0.457642,-223.071976,0.019751,0.017085,0.433960,2.035691,0.103703,4.339598,-223.071976,0.433119,0.000000
311.360016,0.420036,-223.116455,0.019695,0.017041,0.432841,1.868415,0.095182,4.328410,-223.116455,0.431870,0.000000
312.110016,0.385773,-223.116455,0.019648,0.016985,0.431419,1.716003,0.087417,4.314188,-223.116455,0.430621,0.000000
312.860016,0.383171,-223.160934,0.019613,0.016943,0.430343,1.704430,0.086828,4.303433,-223.160934,0.429363,0.000000
313.610016,0.314278,-223.249893,0.019570,0.016897,0.429181,1.397977,0.071216,4.291813,-223.249893,0.428115,0.000000
314.360016,0.315025,-223.205414,0.019510,0.016844,0.427828,1.401303,0.071386,4.278285,-223.205414,0.426866,0.000000
315.110016,0.290077,-223.249893,0.019467,0.016794,0.426562,1.290328,0.065732,4.265622,-223.249893,0.425617,0.000000
315.860016,0.278160,-223.338852,0.019423,0.016747,0.425366,1.237318,0.063032,4.253656,-223.338852,0.424368,0.000000
316.610016,0.249855,-223.338852,0.019350,0.016689,0.423909,1.111411,0.056618,4.239086,-223.338852,0.423119,0.000000
317.360016,0.259537,-223.294373,0.019316,0.016647,0.422833,1.154477,0.058812,4.228332,-223.294373,0.421871,0.000000
318.110016,0.246880,-223.338852,0.019277,0.016602,0.421680,1.098175,0.055944,4.216799,-223.338852,0.420613,0.000000
318.860016,0.249855,-223.294373,0.019208,0.016546,0.420258,1.111411,0.056618,4.202575,-223.294373,0.419364,0.000000
319.000000,0.269218,-223.294373,0.019191,0.016547,0.420284,1.197544,0.061006,4.202837,-223.294373,0.420162,0.000000