File: PDMS and AD/PDMS0024 Test 1-1_02142024_162238.csv
Time (sec),S:Load (lbs),S:HL1 (DIM),S:LVDT (in),S:Position (in),Ch:Position (mm),Ch:Load (N),Ch:Stress (MPa),Ch:Strain (mm/mm),Ch:HL1 (DIM),Set Point (),Cycles ()
0.110000,-0.001114,-196.783722,0.000026,-0.000000,-0.000000,-0.004955,-0.000252,-0.000000,-196.783722,-0.000174,0.000000
0.860000,-0.000748,-196.783722,0.000009,0.000141,0.003582,-0.003326,-0.000169,0.035816,-196.783722,0.004154,0.000000
1.610000,0.018250,-196.783722,0.000198,0.000364,0.009236,0.081178,0.004135,0.092359,-196.783722,0.010398,0.000000
2.360000,-0.002975,-196.828201,0.000470,0.000615,0.015619,-0.013236,-0.000674,0.156187,-196.828201,0.016651,0.000000
3.110000,0.014893,-196.828201,0.000711,0.000856,0.021733,0.066245,0.003375,0.217327,-196.828201,0.022895,0.000000
3.860000,0.001862,-196.872696,0.000953,0.001103,0.028020,0.008281,0.000422,0.280200,-196.872696,0.029139,0.000000
4.610000,0.026810,-196.872696,0.001233,0.001354,0.034403,0.119255,0.006075,0.344028,-196.872696,0.035391,0.000000
5.360000,0.272949,-196.872696,0.001444,0.001599,0.040621,1.214139,0.061851,0.406208,-196.872696,0.041635,0.000000
6.110000,0.336624,-196.961655,0.001561,-0.000006,-0.000147,1.497379,0.076280,-0.001474,-196.961655,0.000078,0.000000
6.860000,0.440887,-196.917175,0.001561,0.000009,0.000217,1.961165,0.099907,0.002169,-196.917175,0.001136,0.000000
7.610000,0.535103,-196.961655,0.001600,0.000049,0.001240,2.380256,0.121256,0.012401,-196.961655,0.002385,0.000000
8.360001,0.622978,-196.961655,0.001690,0.000106,0.002697,2.771146,0.141169,0.026971,-196.961655,0.003634,0.000000
9.110001,0.715324,-196.917175,0.001720,0.000153,0.003894,3.181922,0.162095,0.038939,-196.917175,0.004883,0.000000
9.860001,0.792412,-197.006134,0.001746,0.000203,0.005169,3.524824,0.179563,0.051687,-197.006134,0.006131,0.000000
10.610001,0.843796,-197.050613,0.001819,0.000249,0.006331,3.753391,0.191207,0.063308,-197.050613,0.007380,0.000000
11.360001,0.978966,-197.095093,0.001867,0.000300,0.007614,4.354657,0.221837,0.076143,-197.095093,0.008638,0.000000
12.110001,1.039291,-197.095093,0.001936,0.000350,0.008898,4.622999,0.235507,0.088977,-197.095093,0.009886,0.000000
12.860001,1.149139,-197.139572,0.001957,0.000396,0.010060,5.111628,0.260399,0.100599,-197.139572,0.011135,0.000000
13.610001,1.240372,-197.184052,0.002013,0.000445,0.011309,5.517449,0.281072,0.113087,-197.184052,0.012384,0.000000
14.360001,1.302559,-197.184052,0.002044,0.000496,0.012601,5.794071,0.295164,0.126009,-197.184052,0.013633,0.000000
15.110001,1.421349,-197.139572,0.002113,0.000542,0.013772,6.322474,0.322082,0.137715,-197.139572,0.014882,0.000000
15.860001,1.527100,-197.139572,0.002164,0.000596,0.015142,6.792878,0.346046,0.151419,-197.139572,0.016130,0.000000
16.610001,1.654823,-197.228531,0.002216,0.000649,0.016486,7.361022,0.374988,0.164861,-197.228531,0.017388,0.000000
17.360001,1.736000,-197.228531,0.002264,0.000692,0.017579,7.722114,0.393383,0.175788,-197.228531,0.018637,0.000000
18.110001,1.766167,-197.317505,0.002320,0.000738,0.018741,7.856302,0.400219,0.187407,-197.317505,0.019885,0.000000
18.860001,1.896866,-197.228531,0.002363,0.000784,0.019912,8.437680,0.429836,0.199116,-197.228531,0.021134,0.000000
19.610001,2.051773,-197.317505,0.002423,0.000849,0.021568,9.126742,0.464938,0.215678,-197.317505,0.022383,0.000000
20.360001,2.160881,-197.361984,0.002483,0.000899,0.022843,9.612079,0.489663,0.228428,-197.361984,0.023632,0.000000
21.110001,2.256203,-197.317505,0.002492,0.000938,0.023831,10.036091,0.511263,0.238314,-197.317505,0.024881,0.000000
21.860001,2.374992,-197.361984,0.002565,0.000993,0.025219,10.564494,0.538181,0.252189,-197.361984,0.026138,0.000000
22.610001,2.478882,-197.361984,0.002617,0.001042,0.026459,11.026617,0.561723,0.264591,-197.361984,0.027387,0.000000
23.360001,2.629326,-197.406464,0.002660,0.001095,0.027821,11.695826,0.595814,0.278207,-197.406464,0.028636,0.000000
24.110001,2.640869,-197.406464,0.002703,0.001137,0.028887,11.747172,0.598430,0.288873,-197.406464,0.029885,0.000000
24.860001,2.802475,-197.495422,0.002759,0.001185,0.030101,12.466031,0.635050,0.301015,-197.495422,0.031133,0.000000
25.610001,2.884773,-197.495422,0.002802,0.001242,0.031550,12.832112,0.653699,0.315497,-197.495422,0.032382,0.000000
26.360001,3.035210,-197.450943,0.002863,0.001289,0.032747,13.501287,0.687788,0.327465,-197.450943,0.033640,0.000000
27.110001,3.159210,-197.495422,0.002893,0.001338,0.033987,14.052869,0.715887,0.339867,-197.495422,0.034889,0.000000
27.860001,3.243736,-197.495422,0.002966,0.001387,0.035227,14.428860,0.735041,0.352268,-197.495422,0.036137,0.000000
28.610001,3.321564,-197.539902,0.003018,0.001431,0.036337,14.775053,0.752677,0.363367,-197.539902,0.037386,0.000000
29.360001,3.472748,-197.495422,0.003074,0.001484,0.037681,15.447554,0.786936,0.376809,-197.495422,0.038635,0.000000
30.110001,3.551689,-197.628860,0.003122,0.001532,0.038913,15.798702,0.804824,0.389125,-197.628860,0.039884,0.000000
30.860001,3.726334,-197.673340,0.003165,0.001584,0.040239,16.575560,0.844399,0.402393,-197.673340,0.041133,0.000000
31.610001,3.750908,-197.673340,0.003208,0.001631,0.041419,16.684872,0.849968,0.414187,-197.673340,0.042390,0.000000
32.360001,3.844002,-197.628860,0.003247,0.001677,0.042598,17.098974,0.871063,0.425980,-197.628860,0.043639,0.000000
33.110001,4.007103,-197.673340,0.003294,0.001733,0.044029,17.824484,0.908022,0.440291,-197.673340,0.044888,0.000000
33.860001,4.033165,-197.717834,0.003337,0.001778,0.045165,17.940414,0.913928,0.451652,-197.717834,0.046136,0.000000
34.610001,4.201103,-197.717834,0.003406,0.001825,0.046353,18.687441,0.951984,0.463532,-197.717834,0.047385,0.000000
35.360001,4.256218,-197.762314,0.003462,0.001874,0.047593,18.932604,0.964473,0.475934,-197.762314,0.048634,0.000000
36.110001,4.344101,-197.806793,0.003518,0.001918,0.048729,19.323526,0.984387,0.487294,-197.806793,0.049883,0.000000
36.860001,4.484856,-197.806793,0.003553,0.001972,0.050100,19.949635,1.016283,0.500997,-197.806793,0.051140,0.000000
37.610001,4.528793,-197.851273,0.003609,0.002019,0.051279,20.145079,1.026239,0.512791,-197.851273,0.052389,0.000000
38.360001,4.684448,-197.851273,0.003665,0.002068,0.052537,20.837467,1.061511,0.525366,-197.851273,0.053638,0.000000
39.110001,4.789825,-197.851273,0.003712,0.002122,0.053907,21.306208,1.085390,0.539067,-197.851273,0.054887,0.000000
39.860001,4.941383,-197.940231,0.003760,0.002171,0.055156,21.980371,1.119733,0.551556,-197.940231,0.056135,0.000000
40.610001,4.916435,-197.895752,0.003820,0.002209,0.056101,21.869396,1.114080,0.561009,-197.895752,0.057384,0.000000
41.360001,5.046021,-197.940231,0.003867,0.002270,0.057653,22.445820,1.143445,0.576532,-197.940231,0.058633,0.000000
42.110001,5.173370,-197.984711,0.003906,0.002318,0.058885,23.012300,1.172302,0.588846,-197.984711,0.059891,0.000000
42.860001,5.315620,-198.029190,0.003971,0.002374,0.060307,23.645061,1.204537,0.603068,-198.029190,0.061139,0.000000
43.610001,5.394188,-197.940231,0.004010,0.002423,0.061538,23.994547,1.222340,0.615384,-197.940231,0.062388,0.000000
44.360001,5.470528,-198.029190,0.004053,0.002465,0.062614,24.334122,1.239639,0.626137,-198.029190,0.063637,0.000000
45.110001,5.542763,-198.029190,0.004130,0.002519,0.063975,24.655439,1.256008,0.639753,-198.029190,0.064886,0.000000
45.860001,5.674583,-198.029190,0.004169,0.002568,0.065224,25.241808,1.285879,0.652241,-198.029190,0.066135,0.000000
46.610001,5.798584,-198.073669,0.004238,0.002622,0.066603,25.793390,1.313978,0.666030,-198.073669,0.067383,0.000000
47.360001,5.776985,-198.073669,0.004277,0.002666,0.067704,25.697313,1.309083,0.677044,-198.073669,0.068641,0.000000
48.110001,5.921471,-198.162643,0.004337,0.002715,0.068953,26.340017,1.341825,0.689532,-198.162643,0.069890,0.000000
48.860001,5.961311,-198.118149,0.004363,0.002768,0.070306,26.517237,1.350852,0.703059,-198.118149,0.071139,0.000000
49.610001,6.022751,-198.162643,0.004419,0.002810,0.071381,26.790533,1.364775,0.713814,-198.162643,0.072387,0.000000
50.360001,6.068924,-198.118149,0.004449,0.002856,0.072535,26.995922,1.375238,0.725349,-198.118149,0.073636,0.000000
51.110001,6.134094,-198.207123,0.004531,0.002909,0.073888,27.285814,1.390006,0.738876,-198.207123,0.074885,0.000000
51.860001,6.247292,-198.251602,0.004562,0.002957,0.075119,27.789341,1.415656,0.751192,-198.251602,0.076142,0.000000
52.610001,6.338150,-198.296082,0.004622,0.003009,0.076437,28.193499,1.436245,0.764373,-198.296082,0.077391,0.000000
53.360004,6.394005,-198.207123,0.004691,0.003057,0.077643,28.441954,1.448902,0.776428,-198.207123,0.078640,0.000000
54.110004,6.511307,-198.296082,0.004725,0.003108,0.078935,28.963739,1.475483,0.789349,-198.296082,0.079889,0.000000
54.860004,6.506088,-198.251602,0.004790,0.003155,0.080149,28.940525,1.474301,0.801489,-198.251602,0.081138,0.000000
55.610004,6.614456,-198.296082,0.004820,0.003200,0.081285,29.422571,1.498857,0.812852,-198.296082,0.082386,0.000000
56.360004,6.745155,-198.296082,0.004863,0.003258,0.082751,30.003950,1.528474,0.827507,-198.296082,0.083635,0.000000
57.110004,6.713875,-198.340561,0.004915,0.003304,0.083913,29.864807,1.521386,0.839128,-198.340561,0.084893,0.000000
57.860004,6.793938,-198.340561,0.004988,0.003349,0.085058,30.220943,1.539528,0.850576,-198.340561,0.086142,0.000000
58.610004,6.780899,-198.385040,0.005019,0.003399,0.086324,30.162945,1.536574,0.863236,-198.385040,0.087390,0.000000
59.360004,6.911606,-198.340561,0.005079,0.003450,0.087633,30.744358,1.566192,0.876332,-198.340561,0.088639,0.000000
60.110004,6.990173,-198.429520,0.005113,0.003502,0.088951,31.093843,1.583996,0.889513,-198.429520,0.089888,0.000000
60.860004,6.895966,-198.429520,0.005178,0.003545,0.090035,30.674788,1.562648,0.900355,-198.429520,0.091137,0.000000
61.610004,7.051987,-198.473999,0.005226,0.003597,0.091354,31.368803,1.598003,0.913535,-198.473999,0.092386,0.000000
62.360004,7.064278,-198.518478,0.005269,0.003651,0.092724,31.423477,1.600788,0.927239,-198.518478,0.093643,0.000000
63.110004,7.155884,-198.518478,0.005346,0.003702,0.094042,31.830961,1.621546,0.940420,-198.518478,0.094892,0.000000
63.860004,7.231102,-198.473999,0.005385,0.003750,0.095256,32.165546,1.638591,0.952562,-198.473999,0.096141,0.000000
64.610001,7.218811,-198.518478,0.005458,0.003796,0.096427,32.110874,1.635806,0.964268,-198.518478,0.097390,0.000000
65.360001,7.222534,-198.518478,0.005506,0.003843,0.097615,32.127438,1.636650,0.976149,-198.518478,0.098638,0.000000
66.110001,7.344299,-198.607452,0.005536,0.003901,0.099081,32.669075,1.664242,0.990806,-198.607452,0.099887,0.000000
66.860001,7.271317,-198.651932,0.005588,0.003940,0.100086,32.344433,1.647704,1.000864,-198.651932,0.101136,0.000000
67.610001,7.349144,-198.651932,0.005652,0.003989,0.101318,32.690624,1.665340,1.013180,-198.651932,0.102393,0.000000
68.360001,7.391220,-198.651932,0.005691,0.004046,0.102758,32.877789,1.674874,1.027576,-198.651932,0.103642,0.000000
69.110001,7.462341,-198.607452,0.005747,0.004094,0.103998,33.194153,1.690991,1.039977,-198.607452,0.104891,0.000000
69.860001,7.577034,-198.607452,0.005786,0.004147,0.105333,33.704330,1.716980,1.053332,-198.607452,0.106140,0.000000
70.610001,7.515968,-198.696411,0.005842,0.004190,0.106426,33.432697,1.703143,1.064260,-198.696411,0.107389,0.000000
71.360001,7.509262,-198.696411,0.005890,0.004235,0.107579,33.402866,1.701623,1.075794,-198.696411,0.108637,0.000000
72.110001,7.636986,-198.740891,0.005959,0.004291,0.108984,33.971008,1.730566,1.089844,-198.740891,0.109895,0.000000
72.860001,7.641083,-198.740891,0.005984,0.004339,0.110216,33.989235,1.731494,1.102158,-198.740891,0.111144,0.000000
73.610001,7.692841,-198.785370,0.006036,0.004389,0.111482,34.219463,1.743223,1.114818,-198.785370,0.112392,0.000000
74.360001,7.636612,-198.740891,0.006092,0.004436,0.112679,33.969345,1.730481,1.126786,-198.740891,0.113641,0.000000
75.110001,7.721886,-198.829849,0.006135,0.004484,0.113884,34.348663,1.749804,1.138841,-198.829849,0.114890,0.000000
75.860001,7.739388,-198.874329,0.006217,0.004538,0.115263,34.426514,1.753770,1.152629,-198.874329,0.116139,0.000000
76.610001,7.679436,-198.829849,0.006252,0.004579,0.116295,34.159836,1.740185,1.162951,-198.829849,0.117388,0.000000
77.360001,7.745720,-198.874329,0.006303,0.004628,0.117561,34.454681,1.755205,1.175611,-198.874329,0.118645,0.000000
78.110001,7.728966,-198.918808,0.006338,0.004681,0.118905,34.380157,1.751409,1.189053,-198.918808,0.119894,0.000000
78.860001,7.820564,-198.963287,0.006385,0.004728,0.120093,34.787609,1.772165,1.200934,-198.963287,0.121143,0.000000
79.610001,7.862648,-198.918808,0.006446,0.004782,0.121472,34.974804,1.781701,1.214722,-198.918808,0.122392,0.000000
80.360001,7.792641,-198.963287,0.006510,0.004827,0.122600,34.663399,1.765838,1.225997,-198.963287,0.123640,0.000000
81.110001,7.904724,-199.052261,0.006532,0.004875,0.123831,35.161968,1.791236,1.238312,-199.052261,0.124889,0.000000
81.860001,7.848495,-198.963287,0.006588,0.004925,0.125089,34.911850,1.778494,1.250887,-198.963287,0.126138,0.000000
82.610001,7.922966,-199.007782,0.006648,0.004975,0.126363,35.243114,1.795370,1.263634,-199.007782,0.127395,0.000000
83.360001,8.034309,-199.052261,0.006704,0.005034,0.127855,35.738392,1.820601,1.278551,-199.052261,0.128644,0.000000
84.110001,7.878654,-199.096741,0.006765,0.005072,0.128835,35.046005,1.785329,1.288350,-199.096741,0.129893,0.000000
84.860001,7.930046,-199.096741,0.006804,0.005119,0.130032,35.274609,1.796974,1.300318,-199.096741,0.131142,0.000000
85.610001,7.960205,-199.096741,0.006851,0.005173,0.131385,35.408760,1.803808,1.313847,-199.096741,0.132391,0.000000
86.360001,8.033562,-199.096741,0.006907,0.005228,0.132781,35.735065,1.820431,1.327809,-199.096741,0.133640,0.000000
87.110001,8.011597,-199.141220,0.006959,0.005270,0.133848,35.637363,1.815454,1.338477,-199.141220,0.134888,0.000000
87.860001,8.062981,-199.141220,0.007011,0.005324,0.135227,35.865929,1.827098,1.352265,-199.141220,0.136146,0.000000
88.610001,8.097984,-199.141220,0.007054,0.005373,0.136484,36.021633,1.835029,1.364841,-199.141220,0.137395,0.000000
89.360001,8.143044,-199.185699,0.007110,0.005427,0.137845,36.222065,1.845240,1.378455,-199.185699,0.138643,0.000000
90.110001,8.124794,-199.230179,0.007161,0.005475,0.139077,36.140888,1.841105,1.390769,-199.230179,0.139892,0.000000
90.860001,8.092026,-199.274658,0.007200,0.005516,0.140109,35.995129,1.833679,1.401091,-199.274658,0.141141,0.000000
91.610001,8.140808,-199.185699,0.007282,0.005572,0.141531,36.212124,1.844733,1.415312,-199.185699,0.142390,0.000000
92.360001,8.207092,-199.319138,0.007312,0.005621,0.142771,36.506969,1.859754,1.427714,-199.319138,0.143639,0.000000
93.110001,8.282684,-199.363617,0.007373,0.005668,0.143968,36.843220,1.876883,1.439681,-199.363617,0.144896,0.000000
93.860008,8.199638,-199.319138,0.007407,0.005715,0.145165,36.473812,1.858065,1.451649,-199.319138,0.146145,0.000000
94.610008,8.219749,-199.363617,0.007472,0.005763,0.146379,36.563271,1.862622,1.463791,-199.363617,0.147394,0.000000
95.360008,8.182510,-199.452591,0.007519,0.005811,0.147593,36.397625,1.854183,1.475931,-199.452591,0.148642,0.000000
96.110008,8.267044,-199.363617,0.007571,0.005863,0.148920,36.773647,1.873339,1.489201,-199.363617,0.149891,0.000000
96.860008,8.296089,-199.408096,0.007618,0.005914,0.150204,36.902847,1.879921,1.502036,-199.408096,0.151140,0.000000
97.610008,8.265549,-199.497070,0.007653,0.005961,0.151418,36.766998,1.873000,1.514176,-199.497070,0.152398,0.000000
98.360008,8.264061,-199.497070,0.007692,0.006006,0.152562,36.760380,1.872663,1.525623,-199.497070,0.153646,0.000000
99.110008,8.336304,-199.497070,0.007774,0.006063,0.154011,37.081730,1.889033,1.540106,-199.497070,0.154895,0.000000
99.860008,8.351570,-199.497070,0.007821,0.006110,0.155190,37.149639,1.892493,1.551900,-199.497070,0.156144,0.000000
100.610008,8.326622,-199.541550,0.007869,0.006157,0.156387,37.038666,1.886840,1.563867,-199.541550,0.157393,0.000000
101.360008,8.328110,-199.497070,0.007907,0.006207,0.157653,37.045280,1.887177,1.576530,-199.497070,0.158642,0.000000
102.110008,8.310982,-199.586029,0.007981,0.006252,0.158806,36.969093,1.883295,1.588064,-199.586029,0.159890,0.000000
102.860008,8.422318,-199.586029,0.008024,0.006309,0.160237,37.464340,1.908524,1.602373,-199.586029,0.161148,0.000000
103.610008,8.255127,-199.586029,0.008045,0.006348,0.161243,36.720638,1.870638,1.612433,-199.586029,0.162397,0.000000
104.360008,8.431633,-199.586029,0.008114,0.006400,0.162553,37.505775,1.910635,1.625527,-199.586029,0.163645,0.000000
105.110008,8.370560,-199.674988,0.008175,0.006456,0.163984,37.234108,1.896796,1.639838,-199.674988,0.164894,0.000000
105.860008,8.422691,-199.719467,0.008218,0.006503,0.165181,37.466003,1.908609,1.651806,-199.719467,0.166143,0.000000
106.610008,8.543716,-199.719467,0.008265,0.006558,0.166568,38.004349,1.936034,1.665681,-199.719467,0.167392,0.000000
107.360008,8.449501,-199.674988,0.008330,0.006604,0.167730,37.585258,1.914684,1.677301,-199.674988,0.168641,0.000000
108.110008,8.499405,-199.719467,0.008369,0.006652,0.168953,37.807240,1.925993,1.689530,-199.719467,0.169898,0.000000
108.860008,8.532913,-199.719467,0.008416,0.006704,0.170271,37.956295,1.933586,1.702711,-199.719467,0.171147,0.000000
109.610008,8.607765,-199.763947,0.008476,0.006752,0.171494,38.289253,1.950547,1.714940,-199.763947,0.172396,0.000000
110.360008,8.564568,-199.763947,0.008507,0.006799,0.172691,38.097099,1.940759,1.726907,-199.763947,0.173645,0.000000
111.110008,8.536270,-199.808426,0.008563,0.006851,0.174026,37.971226,1.934346,1.740263,-199.808426,0.174893,0.000000
111.860008,8.584679,-199.808426,0.008627,0.006898,0.175197,38.186558,1.945316,1.751969,-199.808426,0.176142,0.000000
112.610008,8.668083,-199.808426,0.008688,0.006954,0.176628,38.557560,1.964216,1.766278,-199.808426,0.177391,0.000000
113.360008,8.622284,-199.897400,0.008696,0.006996,0.177695,38.353836,1.953837,1.776946,-199.897400,0.178649,0.000000
114.110008,8.561584,-199.986359,0.008748,0.007040,0.178805,38.083828,1.940083,1.788047,-199.986359,0.179897,0.000000
114.860008,8.623772,-199.897400,0.008804,0.007096,0.180236,38.360451,1.954175,1.802356,-199.897400,0.181146,0.000000
115.610008,8.591003,-199.986359,0.008852,0.007141,0.181380,38.214691,1.946749,1.813803,-199.986359,0.182395,0.000000
116.360008,8.684471,-199.941879,0.008899,0.007193,0.182707,38.630459,1.967929,1.827071,-199.941879,0.183644,0.000000
117.110008,8.607765,-199.941879,0.008938,0.007237,0.183826,38.289253,1.950547,1.838259,-199.941879,0.184892,0.000000
117.860008,8.706444,-200.030838,0.009015,0.007288,0.185109,38.728195,1.972908,1.851094,-200.030838,0.186150,0.000000
118.610008,8.665482,-200.075317,0.009041,0.007340,0.186427,38.545986,1.963626,1.864275,-200.075317,0.187399,0.000000
119.360008,8.615211,-200.030838,0.009106,0.007379,0.187433,38.322376,1.952235,1.874335,-200.030838,0.188648,0.000000
120.110008,8.771980,-200.075317,0.009162,0.007436,0.188864,39.019718,1.987759,1.888644,-200.075317,0.189897,0.000000
120.860008,8.658035,-200.119797,0.009192,0.007485,0.190131,38.512863,1.961939,1.901306,-200.119797,0.191145,0.000000
121.610008,8.722084,-200.119797,0.009274,0.007534,0.191362,38.797768,1.976452,1.913620,-200.119797,0.192394,0.000000
122.360008,8.821877,-200.164276,0.009313,0.007589,0.192758,39.241665,1.999066,1.927583,-200.164276,0.193643,0.000000
123.110008,8.857994,-200.119797,0.009352,0.007637,0.193990,39.402325,2.007250,1.939897,-200.119797,0.194900,0.000000
123.860008,8.806984,-200.119797,0.009408,0.007683,0.195152,39.175423,1.995691,1.951518,-200.119797,0.196149,0.000000
124.610008,8.729156,-200.208755,0.009442,0.007731,0.196366,38.829227,1.978055,1.963658,-200.208755,0.197398,0.000000
125.360008,8.797302,-200.208755,0.009494,0.007778,0.197554,39.132355,1.993497,1.975541,-200.208755,0.198647,0.000000
126.110008,8.889648,-200.253235,0.009546,0.007837,0.199063,39.543133,2.014423,1.990630,-200.253235,0.199896,0.000000
126.860008,8.948112,-200.208755,0.009597,0.007886,0.200294,39.803192,2.027671,2.002944,-200.208755,0.201144,0.000000
127.610008,8.881828,-200.253235,0.009658,0.007927,0.201344,39.508347,2.012651,2.013437,-200.253235,0.202393,0.000000
128.360001,8.915710,-200.297729,0.009710,0.007983,0.202757,39.659061,2.020329,2.027574,-200.297729,0.203651,0.000000
129.110001,8.923164,-200.297729,0.009761,0.008034,0.204058,39.692219,2.022018,2.040583,-200.297729,0.204899,0.000000
129.860001,9.050140,-200.342209,0.009809,0.008084,0.205342,40.257034,2.050791,2.053417,-200.342209,0.206148,0.000000
130.610001,8.904915,-200.386688,0.009856,0.008128,0.206460,39.611038,2.017883,2.064603,-200.386688,0.207397,0.000000
131.360001,8.969337,-200.342209,0.009895,0.008177,0.207692,39.897606,2.032481,2.076920,-200.342209,0.208646,0.000000
132.110001,8.976410,-200.431168,0.009947,0.008230,0.209053,39.929066,2.034084,2.090534,-200.431168,0.209895,0.000000
132.860001,9.002846,-200.431168,0.010007,0.008278,0.210268,40.046658,2.040074,2.102676,-200.431168,0.211143,0.000000
133.610001,9.065407,-200.431168,0.010059,0.008327,0.211499,40.324944,2.054250,2.114990,-200.431168,0.212401,0.000000
134.360001,9.019981,-200.431168,0.010119,0.008376,0.212757,40.122883,2.043957,2.127565,-200.431168,0.213650,0.000000
135.110001,9.024818,-200.475647,0.010158,0.008422,0.213927,40.144398,2.045053,2.139272,-200.475647,0.214899,0.000000
135.860001,9.164459,-200.475647,0.010223,0.008475,0.215254,40.765553,2.076696,2.152542,-200.475647,0.216147,0.000000
136.610001,9.098549,-200.475647,0.010261,0.008522,0.216459,40.472366,2.061761,2.164595,-200.475647,0.217396,0.000000
137.360001,9.075462,-200.520126,0.010296,0.008565,0.217552,40.369671,2.056529,2.175522,-200.520126,0.218645,0.000000
138.110001,9.133179,-200.520126,0.010343,0.008620,0.218940,40.626408,2.069608,2.189399,-200.520126,0.219894,0.000000
138.860001,9.173027,-200.564606,0.010404,0.008668,0.220171,40.803661,2.078638,2.201713,-200.564606,0.221151,0.000000
139.610001,9.228508,-200.564606,0.010451,0.008722,0.221541,41.050453,2.091210,2.215415,-200.564606,0.222400,0.000000
140.360001,9.087753,-200.520126,0.010499,0.008763,0.222573,40.424347,2.059314,2.225734,-200.520126,0.223649,0.000000
141.110001,9.292183,-200.564606,0.010555,0.008815,0.223909,41.333694,2.105639,2.239091,-200.564606,0.224898,0.000000
141.860001,9.205048,-200.609085,0.010615,0.008865,0.225175,40.946098,2.085893,2.251751,-200.609085,0.226147,0.000000
142.610001,9.173767,-200.653564,0.010645,0.008911,0.226337,40.806953,2.078805,2.263373,-200.653564,0.227395,0.000000
143.360001,9.241539,-200.653564,0.010697,0.008961,0.227621,41.108418,2.094162,2.276207,-200.653564,0.228653,0.000000
144.110001,9.206161,-200.698044,0.010753,0.009012,0.228904,40.951050,2.086146,2.289042,-200.698044,0.229902,0.000000
144.860001,9.227760,-200.698044,0.010796,0.009057,0.230058,41.047127,2.091040,2.300576,-200.698044,0.231150,0.000000
145.610001,9.314522,-200.698044,0.010856,0.009112,0.231445,41.433064,2.110701,2.314452,-200.698044,0.232399,0.000000
146.360001,9.333145,-200.698044,0.010882,0.009158,0.232607,41.515903,2.114921,2.326073,-200.698044,0.233648,0.000000
147.110001,9.304100,-200.787018,0.010947,0.009206,0.233830,41.386703,2.108339,2.338300,-200.787018,0.234897,0.000000
147.860001,9.310059,-200.787018,0.011016,0.009261,0.235235,41.413208,2.109689,2.352350,-200.787018,0.236146,0.000000
148.610001,9.443367,-200.831497,0.011055,0.009310,0.236466,42.006195,2.139898,2.364664,-200.831497,0.237403,0.000000
149.360001,9.503693,-200.831497,0.011094,0.009364,0.237854,42.274536,2.153568,2.378540,-200.831497,0.238652,0.000000
150.110001,9.493263,-200.787018,0.011171,0.009413,0.239094,42.228146,2.151204,2.390941,-200.787018,0.239901,0.000000
150.860001,9.436661,-200.831497,0.011206,0.009454,0.240135,41.976364,2.138378,2.401347,-200.831497,0.241149,0.000000
151.610001,9.500336,-200.875977,0.011262,0.009509,0.241540,42.259605,2.152807,2.415397,-200.875977,0.242398,0.000000
152.360001,9.531242,-200.920456,0.011296,0.009556,0.242719,42.397083,2.159811,2.427191,-200.920456,0.243647,0.000000
153.110001,9.630669,-200.920456,0.011357,0.009609,0.244072,42.839355,2.182341,2.440720,-200.920456,0.244896,0.000000
153.860001,9.539436,-201.009415,0.011387,0.009656,0.245269,42.433533,2.161667,2.452688,-201.009415,0.246153,0.000000
154.610001,9.672745,-200.964935,0.011469,0.009706,0.246535,43.026516,2.191875,2.465350,-200.964935,0.247402,0.000000
155.360001,9.559174,-200.964935,0.011525,0.009755,0.247775,42.521328,2.166140,2.477751,-200.964935,0.248651,0.000000
156.110001,9.666420,-201.009415,0.011542,0.009803,0.249007,42.998383,2.190442,2.490065,-201.009415,0.249900,0.000000
156.860001,9.534225,-201.009415,0.011598,0.009843,0.250021,42.410355,2.160486,2.500213,-201.009415,0.251149,0.000000
157.610001,9.633652,-201.009415,0.011645,0.009899,0.251435,42.852623,2.183017,2.514347,-201.009415,0.252397,0.000000
158.360001,9.632904,-201.053894,0.011701,0.009946,0.252640,42.849297,2.182847,2.526402,-201.053894,0.253646,0.000000
159.110001,9.710358,-201.098373,0.011745,0.009999,0.253984,43.193829,2.200399,2.539844,-201.098373,0.254904,0.000000
159.860001,9.678329,-201.142868,0.011801,0.010044,0.255112,43.051361,2.193141,2.551118,-201.142868,0.256152,0.000000
160.610001,9.785202,-201.187347,0.011861,0.010095,0.256421,43.526752,2.217359,2.564213,-201.187347,0.257401,0.000000
161.360001,9.733444,-201.142868,0.011895,0.010146,0.257713,43.296524,2.205630,2.577135,-201.142868,0.258650,0.000000
162.110001,9.756157,-201.142868,0.011947,0.010189,0.258797,43.397552,2.210777,2.587975,-201.142868,0.259899,0.000000
162.860001,9.952400,-201.231827,0.011995,0.010248,0.260289,44.270489,2.255246,2.602891,-201.231827,0.261148,0.000000
163.610001,9.760628,-201.142868,0.012046,0.010291,0.261399,43.417442,2.211790,2.613992,-201.142868,0.262405,0.000000
164.360001,9.843292,-201.276306,0.012102,0.010337,0.262570,43.785152,2.230522,2.625699,-201.276306,0.263654,0.000000
165.110001,9.838829,-201.276306,0.012154,0.010390,0.263905,43.765297,2.229511,2.639054,-201.276306,0.264903,0.000000
165.860001,9.941597,-201.320786,0.012202,0.010443,0.265241,44.222431,2.252798,2.652411,-201.320786,0.266152,0.000000
166.610001,9.982933,-201.320786,0.012253,0.010491,0.266472,44.406303,2.262165,2.664725,-201.320786,0.267400,0.000000
167.360001,9.867500,-201.276306,0.012292,0.010536,0.267626,43.892834,2.236007,2.676260,-201.276306,0.268649,0.000000
168.110001,9.938622,-201.320786,0.012361,0.010582,0.268771,44.209198,2.252124,2.687707,-201.320786,0.269898,0.000000
168.860001,10.020912,-201.409744,0.012421,0.010642,0.270297,44.575245,2.270771,2.702970,-201.409744,0.271156,0.000000
169.610001,10.050331,-201.409744,0.012430,0.010688,0.271468,44.706104,2.277438,2.714676,-201.409744,0.272404,0.000000
170.360001,10.106934,-201.409744,0.012486,0.010734,0.272638,44.957886,2.290264,2.726385,-201.409744,0.273653,0.000000
171.110001,10.063370,-201.454224,0.012559,0.010785,0.273939,44.764103,2.280392,2.739393,-201.454224,0.274902,0.000000
171.860001,10.123322,-201.498703,0.012607,0.010836,0.275223,45.030785,2.293977,2.752228,-201.498703,0.276151,0.000000
172.610001,10.219765,-201.454224,0.012667,0.010888,0.276550,45.459785,2.315832,2.765496,-201.454224,0.277399,0.000000
173.360001,10.138588,-201.454224,0.012697,0.010931,0.277651,45.098690,2.297437,2.776510,-201.454224,0.278648,0.000000
174.110016,10.165771,-201.498703,0.012749,0.010979,0.278856,45.219608,2.303597,2.788565,-201.498703,0.279906,0.000000
174.860016,10.208588,-201.587677,0.012805,0.011034,0.280270,45.410065,2.313299,2.802700,-201.587677,0.281155,0.000000
175.610016,10.207848,-201.543182,0.012861,0.011082,0.281475,45.406773,2.313131,2.814754,-201.543182,0.282403,0.000000
176.360016,10.452492,-201.543182,0.012900,0.011135,0.282837,46.495007,2.368569,2.828371,-201.543182,0.283652,0.000000
177.110016,10.276733,-201.587677,0.012965,0.011180,0.283982,45.713192,2.328741,2.839818,-201.587677,0.284901,0.000000
177.860016,10.212318,-201.587677,0.013004,0.011222,0.285048,45.426662,2.314144,2.850484,-201.587677,0.286150,0.000000
178.610016,10.373924,-201.543182,0.013047,0.011277,0.286427,46.145519,2.350765,2.864272,-201.543182,0.287399,0.000000
179.360016,10.469994,-201.632156,0.013098,0.011328,0.287728,46.572857,2.372535,2.877281,-201.632156,0.288656,0.000000
180.110016,10.563087,-201.721115,0.013159,0.011376,0.288960,46.986961,2.393630,2.889597,-201.721115,0.289905,0.000000
180.860016,10.449142,-201.632156,0.013193,0.011424,0.290174,46.480106,2.367810,2.901737,-201.632156,0.291154,0.000000
181.610016,10.390678,-201.721115,0.013249,0.011471,0.291370,46.220047,2.354562,2.913705,-201.721115,0.292402,0.000000
182.360016,10.593994,-201.721115,0.013310,0.011527,0.292784,47.124439,2.400634,2.927841,-201.721115,0.293651,0.000000
183.110016,10.470741,-201.721115,0.013340,0.011568,0.293825,46.576183,2.372704,2.938248,-201.721115,0.294900,0.000000
183.860016,10.568672,-201.765594,0.013409,0.011616,0.295048,47.011803,2.394895,2.950475,-201.765594,0.296158,0.000000
184.610016,10.599579,-201.765594,0.013435,0.011671,0.296435,47.149281,2.401899,2.964350,-201.765594,0.297406,0.000000
185.360016,10.699005,-201.810074,0.013521,0.011721,0.297701,47.591553,2.424429,2.977013,-201.810074,0.298655,0.000000
186.110016,10.712784,-201.810074,0.013551,0.011768,0.298898,47.652843,2.427552,2.988981,-201.810074,0.299904,0.000000
186.860016,10.598465,-201.810074,0.013599,0.011815,0.300112,47.144325,2.401647,3.001121,-201.810074,0.301153,0.000000
187.610016,10.759331,-201.810074,0.013655,0.011866,0.301396,47.859894,2.438099,3.013957,-201.810074,0.302402,0.000000
188.360016,10.765663,-201.899033,0.013715,0.011917,0.302688,47.888062,2.439534,3.026879,-201.899033,0.303650,0.000000
189.110016,10.652458,-201.854553,0.013754,0.011955,0.303668,47.384502,2.413882,3.036678,-201.854553,0.304908,0.000000
189.860016,11.054619,-201.943512,0.013814,0.012019,0.305281,49.173401,2.505013,3.052807,-201.943512,0.306157,0.000000
190.610016,10.774597,-201.899033,0.013874,0.012064,0.306417,47.927803,2.441559,3.064170,-201.899033,0.307406,0.000000
191.360016,10.830826,-201.943512,0.013918,0.012111,0.307614,48.177917,2.454300,3.076136,-201.943512,0.308654,0.000000
192.110016,10.973442,-201.987991,0.013952,0.012165,0.308984,48.812309,2.486618,3.089839,-201.987991,0.309903,0.000000
192.860016,10.989830,-201.943512,0.014004,0.012216,0.310285,48.885204,2.490331,3.102847,-201.943512,0.311152,0.000000
193.610016,10.953712,-202.032486,0.014051,0.012258,0.311343,48.724548,2.482147,3.113426,-202.032486,0.312401,0.000000
194.360016,10.981636,-202.032486,0.014099,0.012311,0.312704,48.848759,2.488474,3.127042,-202.032486,0.313658,0.000000
195.110016,11.099678,-202.076965,0.014146,0.012362,0.313988,49.373833,2.515223,3.139877,-202.076965,0.314907,0.000000
195.860016,11.264641,-202.076965,0.014228,0.012417,0.315384,50.107624,2.552604,3.153839,-202.076965,0.316156,0.000000
196.610016,11.227776,-202.076965,0.014250,0.012462,0.316546,49.943642,2.544250,3.165461,-202.076965,0.317405,0.000000
197.360016,11.227402,-202.121445,0.014319,0.012507,0.317682,49.941978,2.544166,3.176821,-202.121445,0.318653,0.000000
198.110016,11.223679,-202.121445,0.014362,0.012561,0.319044,49.925415,2.543322,3.190438,-202.121445,0.319902,0.000000
198.860016,11.428108,-202.121445,0.014392,0.012611,0.320310,50.834763,2.589646,3.203098,-202.121445,0.321151,0.000000
199.610016,11.423645,-202.121445,0.014452,0.012653,0.321385,50.814911,2.588635,3.213853,-202.121445,0.322408,0.000000
200.360016,11.382683,-202.165924,0.014504,0.012702,0.322634,50.632702,2.579353,3.226339,-202.165924,0.323657,0.000000
201.110016,11.389755,-202.165924,0.014556,0.012749,0.323822,50.664162,2.580956,3.238222,-202.165924,0.324906,0.000000
201.860016,11.449707,-202.254883,0.014599,0.012801,0.325158,50.930840,2.594541,3.251577,-202.254883,0.326155,0.000000
202.610016,11.502960,-202.210403,0.014633,0.012849,0.326363,51.167721,2.606608,3.263630,-202.210403,0.327404,0.000000
203.360016,11.581154,-202.254883,0.014711,0.012902,0.327716,51.515545,2.624327,3.277159,-202.254883,0.328652,0.000000
204.110016,11.543175,-202.299362,0.014754,0.012950,0.328939,51.346607,2.615721,3.289388,-202.299362,0.329901,0.000000
204.860016,11.698456,-202.343842,0.014801,0.012996,0.330092,52.037331,2.650908,3.300920,-202.343842,0.331159,0.000000
205.610016,11.774414,-202.299362,0.014857,0.013051,0.331506,52.375210,2.668120,3.315057,-202.299362,0.332408,0.000000
206.360016,11.692123,-202.343842,0.014875,0.013097,0.332676,52.009163,2.649473,3.326764,-202.343842,0.333656,0.000000
207.110016,11.772552,-202.343842,0.014952,0.013142,0.333804,52.366928,2.667699,3.338039,-202.343842,0.334905,0.000000
207.860016,11.794525,-202.388321,0.014991,0.013195,0.335165,52.464668,2.672678,3.351653,-202.388321,0.336154,0.000000
208.610016,11.801971,-202.388321,0.015047,0.013243,0.336362,52.497791,2.674365,3.363621,-202.388321,0.337403,0.000000
209.360016,12.029861,-202.388321,0.015095,0.013297,0.337741,53.511497,2.726006,3.377411,-202.388321,0.338660,0.000000
210.110016,11.817986,-202.388321,0.015155,0.013338,0.338773,52.569027,2.677994,3.387731,-202.388321,0.339909,0.000000
210.860016,12.183281,-202.477295,0.015189,0.013393,0.340178,54.193939,2.760771,3.401780,-202.477295,0.341158,0.000000
211.610016,12.035080,-202.477295,0.015254,0.013445,0.341514,53.534710,2.727188,3.415135,-202.477295,0.342407,0.000000
212.360016,12.282707,-202.477295,0.015289,0.013495,0.342762,54.636211,2.783301,3.427624,-202.477295,0.343656,0.000000
213.110016,12.368721,-202.477295,0.015336,0.013543,0.344002,55.018818,2.802792,3.440025,-202.477295,0.344904,0.000000
213.860016,12.343033,-202.566254,0.015383,0.013592,0.345234,54.904552,2.796971,3.452339,-202.566254,0.346153,0.000000
214.610016,12.104713,-202.566254,0.015444,0.013637,0.346387,53.844456,2.742967,3.463873,-202.566254,0.347411,0.000000
215.360016,12.485649,-202.566254,0.015496,0.013691,0.347749,55.538940,2.829289,3.477488,-202.566254,0.348659,0.000000
216.110016,12.547089,-202.566254,0.015543,0.013741,0.349015,55.812237,2.843211,3.490150,-202.566254,0.349908,0.000000
216.860016,12.446922,-202.610733,0.015608,0.013784,0.350125,55.366676,2.820513,3.501251,-202.610733,0.351157,0.000000
217.610016,12.519531,-202.655212,0.015659,0.013840,0.351530,55.689655,2.836966,3.515299,-202.655212,0.352406,0.000000
218.360016,12.558632,-202.655212,0.015703,0.013886,0.352701,55.863586,2.845827,3.527007,-202.655212,0.353655,0.000000
219.110016,12.882225,-202.655212,0.015763,0.013942,0.354114,57.302998,2.919154,3.541142,-202.655212,0.354904,0.000000
219.860016,12.649864,-202.744171,0.015802,0.013986,0.355233,56.269405,2.866500,3.552330,-202.744171,0.356161,0.000000
220.610016,12.722481,-202.744171,0.015836,0.014029,0.356334,56.592422,2.882955,3.563344,-202.744171,0.357410,0.000000
221.360016,12.894890,-202.699692,0.015884,0.014081,0.357670,57.359333,2.922024,3.576699,-202.699692,0.358659,0.000000
222.110016,12.989471,-202.788651,0.015935,0.014131,0.358919,57.780056,2.943456,3.589187,-202.788651,0.359907,0.000000
222.860016,13.080704,-202.833130,0.015991,0.014181,0.360185,58.185875,2.964130,3.601848,-202.833130,0.361156,0.000000
223.610016,13.025963,-202.833130,0.016030,0.014228,0.361390,57.942375,2.951725,3.613903,-202.833130,0.362405,0.000000
224.360016,13.109375,-202.833130,0.016073,0.014273,0.362544,58.313412,2.970627,3.625437,-202.833130,0.363654,0.000000
225.110016,13.181984,-202.833130,0.016142,0.014328,0.363940,58.636395,2.987080,3.639400,-202.833130,0.364911,0.000000
225.860016,13.196884,-202.877625,0.016181,0.014371,0.365015,58.702671,2.990457,3.650153,-202.877625,0.366160,0.000000
226.610016,13.318649,-202.922104,0.016229,0.014420,0.366273,59.244312,3.018049,3.662728,-202.922104,0.367409,0.000000
227.360016,13.456795,-202.922104,0.016276,0.014476,0.367678,59.858814,3.049353,3.676778,-202.922104,0.368658,0.000000
228.110016,13.401314,-202.922104,0.016328,0.014520,0.368796,59.612022,3.036781,3.687964,-202.922104,0.369906,0.000000
228.860016,13.799004,-202.922104,0.016384,0.014575,0.370210,61.381035,3.126899,3.702100,-202.922104,0.371155,0.000000
229.610016,13.756187,-203.011063,0.016436,0.014623,0.371416,61.190578,3.117197,3.714155,-203.011063,0.372413,0.000000
230.360016,13.922264,-203.011063,0.016474,0.014672,0.372664,61.929325,3.154830,3.726642,-203.011063,0.373661,0.000000
231.110016,13.804596,-203.011063,0.016535,0.014721,0.373922,61.405910,3.128166,3.739217,-203.011063,0.374910,0.000000
231.860016,14.082382,-203.055542,0.016578,0.014767,0.375084,62.641563,3.191113,3.750839,-203.055542,0.376159,0.000000
232.610016,14.203033,-203.055542,0.016642,0.014824,0.376541,63.178249,3.218453,3.765407,-203.055542,0.377408,0.000000
233.360016,13.828796,-203.055542,0.016664,0.014862,0.377503,61.513557,3.133650,3.775033,-203.055542,0.378657,0.000000
234.110016,14.283463,-203.055542,0.016720,0.014919,0.378934,63.536015,3.236679,3.789342,-203.055542,0.379906,0.000000
234.860016,14.205635,-203.144501,0.016776,0.014966,0.380148,63.189819,3.219043,3.801484,-203.144501,0.381163,0.000000
235.610016,14.453636,-203.188980,0.016832,0.015021,0.381545,64.292984,3.275241,3.815447,-203.188980,0.382412,0.000000
236.360016,14.562370,-203.144501,0.016884,0.015065,0.382663,64.776657,3.299880,3.826633,-203.144501,0.383661,0.000000
237.110016,14.545242,-203.188980,0.016927,0.015117,0.383964,64.700470,3.295999,3.839642,-203.188980,0.384909,0.000000
237.860016,14.658813,-203.188980,0.016983,0.015164,0.385161,65.205658,3.321735,3.851609,-203.188980,0.386158,0.000000
238.610016,14.879257,-203.277939,0.017052,0.015219,0.386566,66.186241,3.371688,3.865659,-203.277939,0.387407,0.000000
239.360016,14.993950,-203.233459,0.017099,0.015268,0.387797,66.696419,3.397678,3.877973,-203.233459,0.388656,0.000000
240.110016,14.893410,-203.233459,0.017130,0.015312,0.388925,66.249199,3.374895,3.889246,-203.233459,0.389913,0.000000
240.860016,15.055016,-203.277939,0.017186,0.015364,0.390234,66.968056,3.411515,3.902342,-203.277939,0.391162,0.000000
241.610016,15.253120,-203.322433,0.017237,0.015412,0.391457,67.849266,3.456407,3.914571,-203.322433,0.392411,0.000000
242.360016,15.486969,-203.322433,0.017276,0.015459,0.392671,68.889481,3.509397,3.926711,-203.322433,0.393660,0.000000
243.110016,15.493301,-203.411392,0.017324,0.015508,0.393903,68.917648,3.510832,3.939025,-203.411392,0.394909,0.000000
243.860016,15.683586,-203.277939,0.017380,0.015556,0.395134,69.764076,3.553952,3.951341,-203.277939,0.396157,0.000000
244.610016,15.621773,-203.411392,0.017427,0.015607,0.396418,69.489113,3.539944,3.964176,-203.411392,0.397406,0.000000
245.360016,15.812050,-203.366913,0.017483,0.015654,0.397623,70.335510,3.583062,3.976231,-203.366913,0.398664,0.000000
246.110016,15.974403,-203.411392,0.017518,0.015704,0.398889,71.057693,3.619852,3.988891,-203.411392,0.399912,0.000000
246.860016,16.012390,-203.411392,0.017578,0.015752,0.400103,71.226669,3.628459,4.001033,-203.411392,0.401161,0.000000
247.610016,16.353485,-203.455872,0.017625,0.015801,0.401335,72.743935,3.705753,4.013348,-203.455872,0.402410,0.000000
248.360016,16.423119,-203.455872,0.017664,0.015854,0.402696,73.053680,3.721532,4.026964,-203.455872,0.403659,0.000000
249.110016,16.582489,-203.544830,0.017729,0.015903,0.403936,73.762596,3.757646,4.039365,-203.544830,0.404908,0.000000
249.860016,16.805916,-203.544830,0.017785,0.015951,0.405150,74.756447,3.808275,4.051505,-203.544830,0.406157,0.000000
250.610016,16.766441,-203.544830,0.017837,0.016000,0.406408,74.580856,3.799330,4.064080,-203.544830,0.407414,0.000000
251.360016,16.652496,-203.589310,0.017854,0.016042,0.407457,74.074005,3.773510,4.074574,-203.589310,0.408663,0.000000
252.110016,17.279198,-203.544830,0.017923,0.016100,0.408949,76.861710,3.915522,4.089490,-203.544830,0.409911,0.000000
252.860016,17.088173,-203.544830,0.017953,0.016142,0.410016,76.011986,3.872235,4.100156,-203.544830,0.411160,0.000000
253.610016,17.352554,-203.633789,0.018018,0.016190,0.411238,77.188019,3.932145,4.112385,-203.633789,0.412409,0.000000
254.360016,17.642632,-203.633789,0.018078,0.016249,0.412730,78.478348,3.997877,4.127301,-203.633789,0.413658,0.000000
255.110016,17.745041,-203.678268,0.018104,0.016295,0.413892,78.933884,4.021084,4.138921,-203.678268,0.414916,0.000000
255.860016,17.981125,-203.678268,0.018147,0.016344,0.415141,79.984039,4.074581,4.151409,-203.678268,0.416164,0.000000
256.610016,18.261894,-203.722763,0.018212,0.016398,0.416503,81.232964,4.138205,4.165025,-203.722763,0.417413,0.000000
257.360016,18.322212,-203.722763,0.018242,0.016442,0.417639,81.501274,4.151873,4.176385,-203.722763,0.418662,0.000000
258.110016,18.576546,-203.767242,0.018302,0.016496,0.419000,82.632599,4.209506,4.190002,-203.767242,0.419911,0.000000
258.860016,18.811882,-203.767242,0.018371,0.016545,0.420232,83.679428,4.262834,4.202316,-203.767242,0.421159,0.000000
259.610016,19.123558,-203.767242,0.018397,0.016594,0.421489,85.065834,4.333460,4.214891,-203.767242,0.422408,0.000000
260.360016,19.133240,-203.811722,0.018453,0.016644,0.422755,85.108902,4.335654,4.227551,-203.811722,0.423666,0.000000
261.110016,19.258362,-203.856201,0.018488,0.016688,0.423865,85.665474,4.364007,4.238653,-203.856201,0.424915,0.000000
261.860016,19.846336,-203.900681,0.018561,0.016745,0.425322,88.280914,4.497244,4.253223,-203.900681,0.426163,0.000000
262.610016,19.800537,-203.900681,0.018596,0.016790,0.426458,88.077187,4.486866,4.264583,-203.900681,0.427412,0.000000
263.360016,19.783035,-203.856201,0.018639,0.016831,0.427508,87.999336,4.482900,4.275077,-203.856201,0.428661,0.000000
264.110016,20.263390,-203.900681,0.018695,0.016886,0.428912,90.136055,4.591750,4.289124,-203.900681,0.429910,0.000000
264.860016,20.455162,-203.900681,0.018746,0.016935,0.430144,90.989105,4.635206,4.301440,-203.900681,0.431159,0.000000
265.610016,20.859558,-203.989639,0.018803,0.016986,0.431436,92.787949,4.726843,4.314362,-203.989639,0.432416,0.000000
266.360016,20.792534,-203.945160,0.018833,0.017028,0.432503,92.489807,4.711656,4.325028,-203.945160,0.433665,0.000000
267.110016,21.369713,-203.989639,0.018889,0.017082,0.433873,95.057228,4.842446,4.338731,-203.989639,0.434914,0.000000
267.860016,21.501900,-203.989639,0.018949,0.017133,0.435182,95.645226,4.872400,4.351825,-203.989639,0.436163,0.000000
268.610016,21.592766,-203.989639,0.018975,0.017178,0.436327,96.049416,4.892991,4.363272,-203.989639,0.437411,0.000000
269.360016,22.128609,-204.034119,0.019031,0.017228,0.437602,98.432968,5.014414,4.376022,-204.034119,0.438660,0.000000
270.110016,22.381821,-204.078598,0.019070,0.017280,0.438903,99.559311,5.071793,4.389029,-204.078598,0.439909,0.000000
270.860016,22.634285,-204.123077,0.019113,0.017326,0.440091,100.682327,5.129002,4.400911,-204.123077,0.441166,0.000000
271.610016,23.110924,-204.123077,0.019178,0.017379,0.441418,102.802521,5.237010,4.414179,-204.123077,0.442415,0.000000
272.360016,23.501175,-204.123077,0.019247,0.017429,0.442701,104.538445,5.325442,4.427014,-204.123077,0.443664,0.000000
273.110016,23.689217,-204.167572,0.019277,0.017474,0.443846,105.374901,5.368053,4.438461,-204.167572,0.444913,0.000000
273.860016,23.863861,-204.212051,0.019329,0.017523,0.445095,106.151756,5.407628,4.450949,-204.212051,0.446162,0.000000
274.610016,24.187454,-204.212051,0.019376,0.017571,0.446300,107.591171,5.480955,4.463004,-204.212051,0.447410,0.000000
275.360016,25.123222,-204.212051,0.019419,0.017630,0.447801,111.753677,5.693004,4.478008,-204.212051,0.448668,0.000000
276.110016,25.050240,-204.256531,0.019467,0.017672,0.448876,111.429031,5.676466,4.488760,-204.256531,0.449917,0.000000
276.860016,25.422615,-204.256531,0.019514,0.017719,0.450064,113.085442,5.760847,4.500641,-204.256531,0.451166,0.000000
277.610016,25.965157,-204.301010,0.019570,0.017772,0.451408,115.498787,5.883789,4.514083,-204.301010,0.452414,0.000000
278.360016,26.481644,-204.301010,0.019613,0.017825,0.452744,117.796234,6.000826,4.527438,-204.301010,0.453663,0.000000
279.110016,26.934448,-204.389969,0.019656,0.017872,0.453941,119.810410,6.103433,4.539406,-204.389969,0.454912,0.000000
279.860016,27.110947,-204.389969,0.019712,0.017920,0.455172,120.595512,6.143428,4.551720,-204.389969,0.456161,0.000000
280.610016,27.574181,-204.434448,0.019742,0.017967,0.456369,122.656082,6.248398,4.563688,-204.434448,0.457418,0.000000
281.360016,28.155083,-204.434448,0.019798,0.018021,0.457722,125.240067,6.380033,4.577217,-204.434448,0.458667,0.000000
282.110016,28.594109,-204.389969,0.019855,0.018069,0.458962,127.192947,6.479517,4.589619,-204.389969,0.459916,0.000000
282.860016,29.046913,-204.434448,0.019876,0.018116,0.460150,129.207123,6.582125,4.601499,-204.434448,0.461165,0.000000
283.610016,29.632286,-204.478928,0.019941,0.018167,0.461442,131.810989,6.714772,4.614421,-204.478928,0.462413,0.000000
284.360016,30.034447,-204.478928,0.019975,0.018212,0.462587,133.599884,6.805903,4.625868,-204.478928,0.463662,0.000000
285.110016,30.951225,-204.523407,0.020031,0.018264,0.463905,137.677933,7.013648,4.639051,-204.523407,0.464911,0.000000
285.860016,31.379456,-204.523407,0.020074,0.018311,0.465110,139.582794,7.110686,4.651104,-204.523407,0.466168,0.000000
286.610016,31.719429,-204.523407,0.020122,0.018355,0.466229,141.095062,7.187726,4.662292,-204.523407,0.467417,0.000000
287.360016,32.682014,-204.523407,0.020178,0.018411,0.467651,145.376862,7.405850,4.676514,-204.523407,0.468666,0.000000
288.110016,33.032417,-204.523407,0.020225,0.018456,0.468770,146.935532,7.485253,4.687702,-204.523407,0.469915,0.000000
288.860016,32.800804,-204.612381,0.020256,0.018483,0.469473,145.905258,7.432769,4.694727,-204.612381,0.469689,0.000000
289.610016,31.390625,-204.612381,0.020273,0.018458,0.468839,139.632477,7.113217,4.688395,-204.612381,0.468623,0.000000
290.360016,30.715515,-204.612381,0.020268,0.018416,0.467773,136.629440,6.960235,4.677729,-204.612381,0.467374,0.000000
291.110016,30.169991,-204.612381,0.020273,0.018373,0.466663,134.202820,6.836617,4.666628,-204.612381,0.466125,0.000000
291.860016,29.843048,-204.656860,0.020273,0.018321,0.465345,132.748505,6.762531,4.653447,-204.656860,0.464876,0.000000
292.610016,29.541054,-204.701340,0.020277,0.018271,0.464087,131.405167,6.694098,4.640872,-204.701340,0.463627,0.000000
293.360016,29.146713,-204.656860,0.020286,0.018227,0.462977,129.651062,6.604740,4.629771,-204.656860,0.462379,0.000000
294.110016,27.870964,-204.745819,0.020286,0.018178,0.461720,123.976242,6.315651,4.617197,-204.745819,0.461130,0.000000
294.860016,26.055275,-204.745819,0.020277,0.018133,0.460566,115.899651,5.904210,4.605663,-204.745819,0.459872,0.000000
295.610016,23.106453,-204.745819,0.020264,0.018083,0.459317,102.782639,5.235997,4.593174,-204.745819,0.458624,0.000000
296.360016,20.006081,-204.790298,0.020256,0.018038,0.458173,88.991493,4.533443,4.581727,-204.790298,0.457375,0.000000
297.110016,16.264114,-204.790298,0.020230,0.017992,0.456985,72.346397,3.685501,4.569846,-204.790298,0.456126,0.000000
297.860016,12.620819,-204.834778,0.020212,0.017944,0.455788,56.140205,2.859919,4.557878,-204.834778,0.454877,0.000000
298.610016,8.672928,-204.879257,0.020156,0.017889,0.454374,38.579109,1.965314,4.543742,-204.879257,0.453628,0.000000
299.360016,5.795975,-204.923737,0.020143,0.017841,0.453151,25.781784,1.313387,4.531515,-204.923737,0.452380,0.000000
300.110016,3.652977,-204.879257,0.020109,0.017801,0.452154,16.249252,0.827776,4.521542,-204.879257,0.451122,0.000000
300.860016,1.732651,-204.879257,0.020044,0.017743,0.450680,7.707215,0.392624,4.506799,-204.879257,0.449873,0.000000
301.610016,1.515556,-204.968216,0.019993,0.017695,0.449457,6.741531,0.343430,4.494570,-204.968216,0.448625,0.000000
302.360016,1.241119,-204.968216,0.019936,0.017641,0.448069,5.520775,0.281242,4.480695,-204.968216,0.447376,0.000000
303.110016,1.201645,-204.923737,0.019876,0.017600,0.447029,5.345183,0.272297,4.470288,-204.923737,0.446127,0.000000
303.860016,1.076157,-205.012711,0.019816,0.017547,0.445702,4.786983,0.243861,4.457020,-205.012711,0.444878,0.000000
304.610016,1.011360,-205.057190,0.019777,0.017509,0.444739,4.498755,0.229177,4.447393,-205.057190,0.443621,0.000000
305.360016,0.872467,-205.057190,0.019721,0.017445,0.443100,3.880927,0.197704,4.431003,-205.057190,0.442372,0.000000
306.110016,0.762245,-205.057190,0.019673,0.017398,0.441904,3.390636,0.172727,4.419035,-205.057190,0.441123,0.000000
306.860016,0.666916,-205.146149,0.019622,0.017350,0.440690,2.966590,0.151125,4.406895,-205.146149,0.439874,0.000000
307.610016,0.671387,-205.101669,0.019579,0.017307,0.439597,2.986477,0.152138,4.395968,-205.101669,0.438625,0.000000
308.360016,0.577919,-205.101669,0.019527,0.017251,0.438166,2.570712,0.130958,4.381658,-205.101669,0.437377,0.000000
309.110016,0.514992,-205.146149,0.019467,0.017196,0.436769,2.290798,0.116699,4.367695,-205.146149,0.436128,0.000000
309.860016,0.455040,-205.190628,0.019432,0.017152,0.435660,2.024119,0.103114,4.356596,-205.190628,0.434870,0.000000
310.610016,0.456902,-205.146149,0.019372,0.017109,0.434558,2.032400,0.103535,4.345582,-205.146149,0.433622,0.000000
311.360016,0.399925,-205.146149,0.019324,0.017051,0.433101,1.778956,0.090624,4.331012,-205.146149,0.432373,0.000000
312.110016,0.349289,-205.235107,0.019268,0.017003,0.431887,1.553715,0.079150,4.318871,-205.235107,0.431124,0.000000
312.860016,0.329178,-205.279587,0.019234,0.016964,0.430881,1.464256,0.074593,4.308812,-205.279587,0.429875,0.000000
313.610016,0.337746,-205.235107,0.019191,0.016912,0.429554,1.502368,0.076534,4.295542,-205.235107,0.428626,0.000000
314.360016,0.304230,-205.279587,0.019135,0.016863,0.428314,1.353281,0.068939,4.283141,-205.279587,0.427377,0.000000
315.110016,0.256195,-205.279587,0.019078,0.016807,0.426901,1.139613,0.058055,4.269006,-205.279587,0.426120,0.000000
315.860016,0.260658,-205.324066,0.019031,0.016757,0.425634,1.159466,0.059066,4.256343,-205.324066,0.424871,0.000000
316.500000,0.299385,-205.324066,0.018997,0.016732,0.424984,1.331731,0.067842,4.249839,-205.324066,0.424871,0.000000