File: Data/Compression Sample NH 10, 12, 15, 17 batch 3/AutoNoheating-17-3-3-240212_02122024_181307.csv
Time (sec),S:Load (lbs),S:HL1 (DIM),S:LVDT (in),S:Position (in),Ch:Position (mm),Ch:Load (N),Ch:Stress (MPa),Ch:Strain (mm/mm),Ch:HL1 (DIM),Set Point (),Cycles ()
0.110000,0.007446,-313.902069,-0.000009,0.000000,0.000009,0.033123,0.001687,0.000087,-313.902069,0.000217,0.000000
0.290000,0.018616,-313.857605,0.000017,-0.000000,-0.000000,0.082807,0.004218,-0.000000,-313.857605,0.000217,0.000000
0.470000,-0.026810,-313.902069,-0.000026,0.000078,0.001986,-0.119255,-0.006075,0.019859,-313.902069,0.002610,0.000000
0.650000,-0.002609,-313.857605,0.000022,0.000185,0.004700,-0.011607,-0.000591,0.047001,-313.857605,0.005611,0.000000
0.830000,-0.014526,-313.946564,0.000138,0.000298,0.007562,-0.064617,-0.003292,0.075622,-313.946564,0.008611,0.000000
1.010000,-0.000000,-313.946564,0.000250,0.000410,0.010424,-0.000000,-0.000000,0.104240,-313.946564,0.011612,0.000000
1.190000,0.040588,-313.902069,0.000358,0.000530,0.013468,0.180546,0.009197,0.134678,-313.902069,0.014613,0.000000
1.370000,0.103149,-313.946564,0.000539,0.000647,0.016442,0.458832,0.023374,0.164423,-313.946564,0.017613,0.000000
1.550000,0.702293,-313.902069,0.000621,0.000765,0.019443,3.123957,0.159142,0.194430,-313.902069,0.019426,0.000000
1.730000,0.704155,-313.902069,0.000629,-0.000000,-0.000008,3.132238,0.159564,-0.000083,-313.902069,0.000199,0.000000
1.910000,0.683304,-313.946564,0.000655,-0.000000,-0.000008,3.039487,0.154839,-0.000083,-313.946564,0.000199,0.000000
2.090000,0.590210,-313.991028,0.000591,-0.000000,-0.000008,2.625385,0.133743,-0.000083,-313.991028,0.000243,0.000000
2.270000,0.643829,-313.946564,0.000629,-0.000000,-0.000008,2.863896,0.145894,-0.000083,-313.946564,0.000538,0.000000
2.450000,0.642715,-313.946564,0.000664,-0.000000,-0.000000,2.858941,0.145641,-0.000000,-313.946564,0.000841,0.000000
2.630000,0.733574,-313.946564,0.000647,0.000009,0.000217,3.263100,0.166230,0.002169,-313.946564,0.001145,0.000000
2.810000,0.784218,-313.991028,0.000612,0.000012,0.000304,3.488375,0.177706,0.003035,-313.991028,0.001440,0.000000
2.990000,0.973755,-313.946564,0.000651,0.000030,0.000755,4.331478,0.220656,0.007547,-313.946564,0.001743,0.000000
3.170000,1.289528,-313.946564,0.000664,0.000048,0.001214,5.736106,0.292211,0.012142,-313.946564,0.002038,0.000000
3.350000,1.438103,-313.946564,0.000655,0.000059,0.001500,6.397000,0.325879,0.015003,-313.946564,0.002342,0.000000
3.530000,1.551300,-313.991028,0.000681,0.000065,0.001657,6.900527,0.351530,0.016566,-313.991028,0.002645,0.000000
3.710000,1.785896,-314.035522,0.000720,0.000079,0.002012,7.944064,0.404690,0.020121,-314.035522,0.002940,0.000000
3.890000,2.010437,-314.035522,0.000698,0.000091,0.002316,8.942870,0.455572,0.023156,-314.035522,0.003244,0.000000
4.070000,2.264023,-313.946564,0.000681,0.000105,0.002671,10.070876,0.513035,0.026714,-313.946564,0.003538,0.000000
4.250000,2.506065,-314.035522,0.000763,0.000119,0.003018,11.147535,0.567883,0.030181,-314.035522,0.003842,0.000000
4.430000,2.731354,-313.991028,0.000720,0.000130,0.003304,12.149669,0.618934,0.033042,-313.991028,0.004146,0.000000
4.610000,2.824074,-313.991028,0.000720,0.000136,0.003452,12.562108,0.639944,0.034518,-313.991028,0.004440,0.000000
4.790000,3.130905,-314.035522,0.000759,0.000149,0.003773,13.926962,0.709473,0.037728,-314.035522,0.004744,0.000000
4.970000,3.466789,-313.946564,0.000729,0.000165,0.004180,15.421049,0.785586,0.041800,-313.946564,0.005039,0.000000
5.150000,3.729309,-313.991028,0.000802,0.000179,0.004536,16.588795,0.845074,0.045358,-313.991028,0.005342,0.000000
5.330000,3.969490,-314.035522,0.000780,0.000192,0.004865,17.657173,0.899499,0.048655,-314.035522,0.005646,0.000000
5.510000,4.125885,-314.035522,0.000755,0.000202,0.005134,18.352854,0.934939,0.051342,-314.035522,0.005941,0.000000
5.690000,4.350426,-314.079987,0.000823,0.000213,0.005420,19.351660,0.985821,0.054203,-314.079987,0.006244,0.000000
5.870000,4.532890,-313.991028,0.000849,0.000221,0.005620,20.163303,1.027168,0.056198,-313.991028,0.006539,0.000000
6.050000,4.859459,-314.035522,0.000828,0.000237,0.006027,21.615953,1.101169,0.060274,-314.035522,0.006843,0.000000
6.230000,5.154755,-314.035522,0.000811,0.000251,0.006365,22.929493,1.168084,0.063654,-314.035522,0.007146,0.000000
6.410000,5.276886,-314.035522,0.000871,0.000258,0.006548,23.472761,1.195759,0.065479,-314.035522,0.007441,0.000000
6.590000,5.331627,-314.079987,0.000841,0.000263,0.006678,23.716261,1.208164,0.066777,-314.079987,0.007745,0.000000
6.770000,5.752411,-313.946564,0.000867,0.000282,0.007155,25.588001,1.303515,0.071546,-313.946564,0.008039,0.000000
6.950000,6.102440,-313.991028,0.000871,0.000294,0.007476,27.145008,1.382833,0.074755,-313.991028,0.008343,0.000000
7.130000,6.361984,-314.124481,0.000927,0.000308,0.007823,28.299519,1.441646,0.078226,-314.124481,0.008638,0.000000
7.310000,6.520615,-314.079987,0.000888,0.000319,0.008109,29.005142,1.477592,0.081088,-314.079987,0.008941,0.000000
7.490000,6.717224,-314.079987,0.000901,0.000332,0.008421,29.879705,1.522145,0.084210,-314.079987,0.009245,0.000000
7.670001,6.929482,-314.079987,0.000897,0.000342,0.008698,30.823874,1.570243,0.086984,-314.079987,0.009540,0.000000
7.850000,7.060181,-314.035522,0.000888,0.000351,0.008924,31.405252,1.599860,0.089240,-314.035522,0.009843,0.000000
8.030001,7.386009,-314.124481,0.000923,0.000366,0.009288,32.854610,1.673694,0.092881,-314.124481,0.010138,0.000000
8.210000,7.588577,-314.079987,0.000936,0.000379,0.009618,33.755676,1.719596,0.096178,-314.079987,0.010441,0.000000
8.390000,7.736778,-314.079987,0.000953,0.000387,0.009826,34.414909,1.753179,0.098260,-314.079987,0.010745,0.000000
8.570001,7.700661,-314.079987,0.000979,0.000396,0.010051,34.254250,1.744995,0.100512,-314.079987,0.011040,0.000000
8.750000,7.908821,-314.079987,0.000970,0.000405,0.010294,35.180195,1.792164,0.102942,-314.079987,0.011343,0.000000
8.930000,8.455833,-314.079987,0.001026,0.000426,0.010815,37.613426,1.916119,0.108146,-314.079987,0.011638,0.000000
9.110001,8.523605,-314.124481,0.001043,0.000435,0.011057,37.914890,1.931477,0.110572,-314.124481,0.011942,0.000000
9.290001,8.707184,-314.124481,0.000983,0.000448,0.011378,38.731487,1.973076,0.113782,-314.124481,0.012245,0.000000
9.470000,8.722076,-314.079987,0.000996,0.000457,0.011612,38.797733,1.976451,0.116124,-314.079987,0.012540,0.000000
9.650001,9.012154,-314.079987,0.001030,0.000473,0.012020,40.088062,2.042183,0.120201,-314.079987,0.012844,0.000000
9.830001,9.163338,-314.124481,0.001082,0.000486,0.012332,40.760563,2.076442,0.123319,-314.124481,0.013139,0.000000
10.010000,9.319740,-314.124481,0.001065,0.000498,0.012662,41.456276,2.111883,0.126616,-314.124481,0.013442,0.000000
10.190001,9.467941,-314.079987,0.001069,0.000510,0.012956,42.115505,2.145466,0.129565,-314.079987,0.013746,0.000000
10.370001,9.422882,-314.124481,0.001069,0.000517,0.013121,41.915073,2.135256,0.131215,-314.124481,0.014040,0.000000
10.550000,9.521935,-314.079987,0.001095,0.000528,0.013416,42.355679,2.157701,0.134163,-314.079987,0.014344,0.000000
10.730000,9.867126,-314.168945,0.001117,0.000544,0.013815,43.891171,2.235923,0.138152,-314.168945,0.014639,0.000000
10.910001,9.997086,-314.168945,0.001143,0.000556,0.014127,44.469257,2.265372,0.141271,-314.168945,0.014942,0.000000
11.090000,10.061874,-314.124481,0.001143,0.000567,0.014396,44.757454,2.280053,0.143962,-314.124481,0.015246,0.000000
11.270000,10.132996,-314.124481,0.001134,0.000578,0.014682,45.073814,2.296170,0.146824,-314.124481,0.015541,0.000000
11.450001,10.169121,-314.124481,0.001151,0.000588,0.014934,45.234509,2.304356,0.149337,-314.124481,0.015844,0.000000
11.630000,10.274872,-314.213440,0.001177,0.000600,0.015229,45.704914,2.328319,0.152285,-314.213440,0.016139,0.000000
11.810000,10.496803,-314.168945,0.001151,0.000613,0.015576,46.692112,2.378610,0.155756,-314.168945,0.016443,0.000000
11.990001,10.545959,-314.124481,0.001151,0.000625,0.015879,46.910770,2.389749,0.158791,-314.124481,0.016746,0.000000
12.170001,10.724327,-314.124481,0.001181,0.000638,0.016217,47.704189,2.430167,0.162171,-314.124481,0.017041,0.000000
12.350000,10.699379,-314.168945,0.001220,0.000645,0.016373,47.593216,2.424514,0.163735,-314.168945,0.017345,0.000000
12.530001,10.900085,-314.213440,0.001220,0.000660,0.016764,48.486000,2.469995,0.167637,-314.213440,0.017640,0.000000
12.710001,11.070633,-314.213440,0.001203,0.000674,0.017119,49.244637,2.508641,0.171191,-314.213440,0.017943,0.000000
12.890000,11.230377,-314.124481,0.001237,0.000688,0.017466,49.955212,2.544840,0.174662,-314.124481,0.018247,0.000000
13.070001,11.262405,-314.168945,0.001259,0.000699,0.017761,50.097683,2.552097,0.177610,-314.168945,0.018541,0.000000
13.250001,11.241180,-314.124481,0.001263,0.000709,0.018004,50.003269,2.547288,0.180036,-314.124481,0.018845,0.000000
13.430000,11.243042,-314.213440,0.001324,0.000719,0.018255,50.011547,2.547710,0.182553,-314.213440,0.019140,0.000000
13.610001,11.413589,-314.213440,0.001328,0.000731,0.018576,50.770180,2.586356,0.185763,-314.213440,0.019443,0.000000
13.790001,11.540939,-314.168945,0.001332,0.000744,0.018906,51.336662,2.615214,0.189056,-314.168945,0.019747,0.000000
13.970000,11.584877,-314.168945,0.001350,0.000753,0.019131,51.532108,2.625171,0.191311,-314.168945,0.020042,0.000000
14.150001,11.691750,-314.168945,0.001332,0.000765,0.019426,52.007500,2.649388,0.194260,-314.168945,0.020345,0.000000
14.330001,11.702179,-314.257904,0.001319,0.000776,0.019703,52.053890,2.651752,0.197034,-314.257904,0.020640,0.000000
14.510000,11.916290,-314.213440,0.001354,0.000789,0.020042,53.006306,2.700270,0.200418,-314.213440,0.020944,0.000000
14.690001,12.137482,-314.257904,0.001362,0.000805,0.020458,53.990215,2.750393,0.204581,-314.257904,0.021239,0.000000
14.870001,12.253662,-314.168945,0.001393,0.000819,0.020796,54.507011,2.776720,0.207961,-314.168945,0.021542,0.000000
15.050001,12.201157,-314.213440,0.001418,0.000829,0.021065,54.273457,2.764822,0.210652,-314.213440,0.021846,0.000000
15.230000,12.178070,-314.213440,0.001380,0.000839,0.021308,54.170761,2.759590,0.213078,-314.213440,0.022140,0.000000
15.410001,12.183655,-314.257904,0.001444,0.000849,0.021577,54.195602,2.760855,0.215766,-314.257904,0.022444,0.000000
15.590001,12.145302,-314.168945,0.001427,0.000856,0.021750,54.025002,2.752165,0.217503,-314.168945,0.022739,0.000000
15.770000,12.485649,-314.213440,0.001466,0.000873,0.022175,55.538940,2.829289,0.221749,-314.213440,0.023042,0.000000
15.950001,12.478943,-314.257904,0.001423,0.000884,0.022453,55.509109,2.827769,0.224528,-314.257904,0.023346,0.000000
16.130001,12.579117,-314.257904,0.001449,0.000894,0.022695,55.954708,2.850468,0.226954,-314.257904,0.023641,0.000000
16.310001,12.662895,-314.302399,0.001449,0.000905,0.022999,56.327370,2.869453,0.229989,-314.302399,0.023944,0.000000
16.490002,12.665504,-314.213440,0.001483,0.000916,0.023259,56.338978,2.870044,0.232593,-314.213440,0.024239,0.000000
16.670000,12.868073,-314.257904,0.001492,0.000931,0.023650,57.240044,2.915947,0.236495,-314.257904,0.024543,0.000000
16.850000,13.186081,-314.213440,0.001500,0.000947,0.024065,58.654617,2.988008,0.240655,-314.213440,0.024846,0.000000
17.030001,13.128738,-314.302399,0.001544,0.000958,0.024326,58.399544,2.975014,0.243259,-314.302399,0.025141,0.000000
17.210001,13.112350,-314.257904,0.001556,0.000969,0.024621,58.326649,2.971301,0.246207,-314.257904,0.025445,0.000000
17.390001,13.111977,-314.257904,0.001578,0.000978,0.024838,58.324986,2.971216,0.248376,-314.257904,0.025740,0.000000
17.570002,13.160759,-314.302399,0.001556,0.000989,0.025132,58.541981,2.982270,0.251325,-314.302399,0.026043,0.000000
17.750000,13.450096,-314.302399,0.001604,0.001003,0.025470,59.829014,3.047835,0.254705,-314.302399,0.026347,0.000000
17.930000,13.575951,-314.302399,0.001604,0.001016,0.025800,60.388844,3.076354,0.258001,-314.302399,0.026641,0.000000
18.110001,13.469452,-314.257904,0.001574,0.001024,0.026008,59.915115,3.052221,0.260083,-314.257904,0.026945,0.000000
18.290001,13.589363,-314.257904,0.001625,0.001034,0.026268,60.448505,3.079394,0.262683,-314.257904,0.027240,0.000000
18.470001,13.553986,-314.302399,0.001625,0.001047,0.026598,60.291138,3.071377,0.265980,-314.302399,0.027543,0.000000
18.650002,14.171005,-314.257904,0.001660,0.001068,0.027118,63.035778,3.211196,0.271184,-314.257904,0.027847,0.000000
18.830002,14.146805,-314.302399,0.001630,0.001079,0.027413,62.928131,3.205712,0.274132,-314.302399,0.028141,0.000000
19.010000,13.971786,-314.302399,0.001673,0.001087,0.027613,62.149609,3.166052,0.276127,-314.302399,0.028445,0.000000
19.190001,14.032852,-314.302399,0.001681,0.001099,0.027908,62.421246,3.179890,0.279075,-314.302399,0.028740,0.000000
19.370001,14.133392,-314.257904,0.001669,0.001110,0.028202,62.868469,3.202672,0.282024,-314.257904,0.029043,0.000000
19.550001,14.273033,-314.346893,0.001681,0.001123,0.028523,63.489624,3.234315,0.285233,-314.346893,0.029347,0.000000
19.730001,14.500931,-314.391357,0.001707,0.001136,0.028853,64.503365,3.285958,0.288526,-314.391357,0.029642,0.000000
19.910002,14.404854,-314.302399,0.001746,0.001146,0.029104,64.075989,3.264187,0.291043,-314.302399,0.029945,0.000000
20.090000,14.367615,-314.302399,0.001694,0.001152,0.029269,63.910343,3.255748,0.292690,-314.302399,0.030240,0.000000
20.270000,14.494225,-314.302399,0.001712,0.001164,0.029555,64.473534,3.284438,0.295551,-314.302399,0.030544,0.000000
20.450001,14.820793,-314.346893,0.001720,0.001181,0.030006,65.926178,3.358440,0.300063,-314.346893,0.030847,0.000000
20.630001,15.117950,-314.346893,0.001716,0.001197,0.030405,67.248001,3.425777,0.304052,-314.346893,0.031142,0.000000
20.810001,15.155190,-314.302399,0.001789,0.001209,0.030700,67.413651,3.434215,0.307000,-314.302399,0.031446,0.000000
20.990002,14.984642,-314.346893,0.001763,0.001218,0.030926,66.655014,3.395568,0.309256,-314.346893,0.031741,0.000000
21.170000,15.052040,-314.302399,0.001841,0.001227,0.031177,66.954819,3.410841,0.311769,-314.302399,0.032044,0.000000
21.350000,15.099327,-314.435852,0.001819,0.001238,0.031454,67.165161,3.421556,0.314544,-314.435852,0.032348,0.000000
21.530001,15.346588,-314.391357,0.001824,0.001253,0.031819,68.265030,3.477587,0.318189,-314.391357,0.032642,0.000000
21.710001,15.461647,-314.435852,0.001798,0.001265,0.032139,68.776840,3.503659,0.321394,-314.435852,0.032946,0.000000
21.890001,15.524208,-314.346893,0.001867,0.001275,0.032382,69.055130,3.517836,0.323824,-314.346893,0.033241,0.000000
22.070002,15.337646,-314.391357,0.001837,0.001283,0.032599,68.225258,3.475560,0.325993,-314.391357,0.033544,0.000000
22.250002,15.492928,-314.391357,0.001815,0.001293,0.032833,68.915985,3.510748,0.328332,-314.391357,0.033839,0.000000
22.430000,15.981483,-314.391357,0.001897,0.001311,0.033310,71.089188,3.621456,0.333105,-314.391357,0.034143,0.000000
22.610001,16.092072,-314.346893,0.001901,0.001323,0.033605,71.581108,3.646516,0.336053,-314.346893,0.034446,0.000000
22.790001,16.161705,-314.346893,0.001940,0.001335,0.033909,71.890854,3.662295,0.339089,-314.346893,0.034741,0.000000
22.970001,15.968819,-314.435852,0.001884,0.001340,0.034030,71.032852,3.618586,0.340300,-314.435852,0.035045,0.000000
23.150002,16.275658,-314.391357,0.001914,0.001355,0.034412,72.397743,3.688117,0.344115,-314.391357,0.035340,0.000000
23.330002,16.305817,-314.435852,0.001893,0.001365,0.034681,72.531898,3.694951,0.346806,-314.435852,0.035643,0.000000
23.510000,16.597382,-314.480316,0.001944,0.001380,0.035062,73.828842,3.761020,0.350621,-314.480316,0.035947,0.000000
23.690001,16.737770,-314.391357,0.001932,0.001393,0.035383,74.453323,3.792833,0.353831,-314.391357,0.036242,0.000000
23.870001,16.722504,-314.435852,0.001966,0.001402,0.035617,74.385414,3.789374,0.356170,-314.435852,0.036545,0.000000
24.050001,16.658081,-314.435852,0.001962,0.001411,0.035843,74.098846,3.774775,0.358426,-314.435852,0.036840,0.000000
24.230001,16.799210,-314.435852,0.002001,0.001422,0.036129,74.726616,3.806755,0.361287,-314.435852,0.037143,0.000000
24.410002,17.190201,-314.435852,0.001975,0.001440,0.036589,76.465836,3.895355,0.365886,-314.435852,0.037447,0.000000
24.590002,17.397614,-314.480316,0.001979,0.001453,0.036900,77.388451,3.942356,0.369005,-314.480316,0.037742,0.000000
24.770000,17.345482,-314.391357,0.002031,0.001461,0.037109,77.156555,3.930542,0.371086,-314.391357,0.038045,0.000000
24.950001,17.349579,-314.480316,0.002035,0.001473,0.037412,77.174782,3.931471,0.374122,-314.480316,0.038340,0.000000
25.130001,17.447510,-314.480316,0.001996,0.001483,0.037673,77.610397,3.953662,0.376726,-314.480316,0.038644,0.000000
25.310001,17.661995,-314.480316,0.002044,0.001495,0.037985,78.564476,4.002265,0.379848,-314.480316,0.038947,0.000000
25.490002,17.987076,-314.435852,0.002057,0.001511,0.038375,80.010506,4.075930,0.383750,-314.435852,0.039242,0.000000
25.670002,18.089111,-314.435852,0.002082,0.001524,0.038704,80.464386,4.099051,0.387043,-314.435852,0.039546,0.000000
25.850000,18.070114,-314.480316,0.002061,0.001533,0.038930,80.379883,4.094747,0.389299,-314.480316,0.039841,0.000000
26.030001,18.253700,-314.480316,0.002126,0.001546,0.039268,81.196510,4.136348,0.392683,-314.480316,0.040144,0.000000
26.210001,18.312531,-314.435852,0.002078,0.001556,0.039528,81.458206,4.149679,0.395283,-314.435852,0.040448,0.000000
26.390001,18.502068,-314.480316,0.002151,0.001570,0.039884,82.301308,4.192628,0.398837,-314.480316,0.040743,0.000000
26.570002,18.773155,-314.391357,0.002121,0.001585,0.040257,83.507164,4.254058,0.402569,-314.391357,0.041046,0.000000
26.750002,18.789543,-314.480316,0.002151,0.001595,0.040526,83.580063,4.257771,0.405256,-314.480316,0.041341,0.000000
26.930002,18.718788,-314.569275,0.002147,0.001606,0.040786,83.265327,4.241738,0.407856,-314.569275,0.041644,0.000000
27.110001,18.870346,-314.435852,0.002173,0.001617,0.041063,83.939491,4.276082,0.410635,-314.435852,0.041948,0.000000
27.290001,19.094513,-314.524811,0.002139,0.001631,0.041428,84.936638,4.326879,0.414276,-314.524811,0.042243,0.000000
27.470001,19.346611,-314.480316,0.002151,0.001643,0.041731,86.058022,4.384005,0.417311,-314.480316,0.042546,0.000000
27.650002,19.418480,-314.524811,0.002216,0.001653,0.041991,86.377716,4.400290,0.419911,-314.524811,0.042841,0.000000
27.830002,19.165268,-314.524811,0.002199,0.001659,0.042139,85.251373,4.342912,0.421387,-314.524811,0.043145,0.000000
28.010002,19.332458,-314.524811,0.002220,0.001672,0.042477,85.995071,4.380797,0.424767,-314.524811,0.043448,0.000000
28.190001,20.016884,-314.480316,0.002212,0.001690,0.042928,89.039543,4.535891,0.429279,-314.480316,0.043743,0.000000
28.370001,20.218704,-314.480316,0.002272,0.001703,0.043258,89.937286,4.581624,0.432576,-314.480316,0.044047,0.000000
28.550001,20.163223,-314.524811,0.002268,0.001713,0.043518,89.690498,4.569052,0.435176,-314.524811,0.044342,0.000000
28.730001,20.280891,-314.569275,0.002302,0.001726,0.043839,90.213913,4.595716,0.438385,-314.569275,0.044645,0.000000
28.910002,20.336746,-314.524811,0.002255,0.001737,0.044107,90.462364,4.608372,0.441073,-314.524811,0.044949,0.000000
29.090002,20.338242,-314.613770,0.002324,0.001744,0.044307,90.469017,4.608711,0.443067,-314.613770,0.045243,0.000000
29.270000,20.649918,-314.524811,0.002311,0.001759,0.044680,91.855423,4.679338,0.446795,-314.524811,0.045547,0.000000
29.450001,20.723640,-314.569275,0.002294,0.001771,0.044992,92.183357,4.696044,0.449918,-314.569275,0.045842,0.000000
29.630001,20.860306,-314.613770,0.002315,0.001783,0.045287,92.791275,4.727013,0.452866,-314.613770,0.046145,0.000000
29.810001,20.799980,-314.524811,0.002333,0.001789,0.045451,92.522934,4.713343,0.454513,-314.524811,0.046449,0.000000
29.990002,20.890091,-314.569275,0.002358,0.001800,0.045720,92.923767,4.733762,0.457204,-314.569275,0.046743,0.000000
30.170002,21.367477,-314.569275,0.002324,0.001815,0.046111,95.047287,4.841939,0.461106,-314.569275,0.047047,0.000000
30.350002,21.885445,-314.613770,0.002371,0.001832,0.046544,97.351318,4.959312,0.465440,-314.613770,0.047342,0.000000
30.530001,21.892517,-314.569275,0.002380,0.001843,0.046804,97.382782,4.960916,0.468044,-314.569275,0.047645,0.000000
30.710001,21.699257,-314.524811,0.002341,0.001850,0.046978,96.523117,4.917122,0.469777,-314.524811,0.047940,0.000000
30.890001,22.150948,-314.569275,0.002432,0.001866,0.047403,98.532333,5.019476,0.474028,-314.569275,0.048244,0.000000
31.070002,22.341599,-314.524811,0.002419,0.001878,0.047689,99.380394,5.062678,0.476889,-314.524811,0.048547,0.000000
31.250002,22.668175,-314.569275,0.002423,0.001892,0.048053,100.833076,5.136682,0.480530,-314.569275,0.048842,0.000000
31.430002,22.799622,-314.569275,0.002449,0.001903,0.048348,101.417786,5.166468,0.483479,-314.569275,0.049146,0.000000
31.610001,22.681953,-314.613770,0.002414,0.001911,0.048539,100.894371,5.139804,0.485386,-314.613770,0.049441,0.000000
31.790001,22.635033,-314.613770,0.002475,0.001920,0.048764,100.685654,5.129172,0.487642,-314.613770,0.049744,0.000000
31.970001,23.200294,-314.569275,0.002440,0.001938,0.049215,103.200066,5.257262,0.492154,-314.569275,0.050048,0.000000
32.150002,23.307533,-314.613770,0.002432,0.001947,0.049449,103.677086,5.281563,0.494493,-314.613770,0.050343,0.000000
32.330002,23.511223,-314.658234,0.002479,0.001960,0.049796,104.583145,5.327719,0.497963,-314.658234,0.050646,0.000000
32.510002,23.602455,-314.613770,0.002527,0.001970,0.050039,104.988960,5.348393,0.500390,-314.613770,0.050941,0.000000
32.690002,23.880989,-314.569275,0.002475,0.001982,0.050351,106.227943,5.411510,0.503512,-314.569275,0.051244,0.000000
32.870003,23.917480,-314.569275,0.002522,0.001992,0.050603,106.390266,5.419779,0.506029,-314.569275,0.051548,0.000000
33.050003,23.987862,-314.658234,0.002514,0.002004,0.050889,106.703339,5.435727,0.508891,-314.658234,0.051843,0.000000
33.230003,24.377731,-314.658234,0.002505,0.002017,0.051244,108.437561,5.524073,0.512444,-314.658234,0.052146,0.000000
33.410000,24.706543,-314.613770,0.002557,0.002028,0.051522,109.900192,5.598582,0.515219,-314.613770,0.052441,0.000000
33.590000,24.873360,-314.569275,0.002544,0.002042,0.051860,110.642227,5.636384,0.518603,-314.569275,0.052745,0.000000
33.770000,24.829422,-314.658234,0.002548,0.002050,0.052060,110.446785,5.626427,0.520597,-314.658234,0.053048,0.000000
33.950001,25.283714,-314.613770,0.002539,0.002064,0.052433,112.467575,5.729372,0.524325,-314.613770,0.053343,0.000000
34.130001,25.716042,-314.613770,0.002557,0.002079,0.052806,114.390663,5.827338,0.528057,-314.613770,0.053647,0.000000
34.310001,25.957336,-314.569275,0.002583,0.002092,0.053135,115.463997,5.882017,0.531350,-314.569275,0.053942,0.000000
34.490002,26.058998,-314.658234,0.002604,0.002103,0.053404,115.916214,5.905054,0.534041,-314.658234,0.054245,0.000000
34.670002,25.997185,-314.702728,0.002643,0.002112,0.053647,115.641251,5.891047,0.536467,-314.702728,0.054549,0.000000
34.850002,26.083572,-314.658234,0.002656,0.002122,0.053890,116.025528,5.910622,0.538897,-314.658234,0.054844,0.000000
35.030003,26.439934,-314.658234,0.002677,0.002135,0.054228,117.610703,5.991374,0.542277,-314.658234,0.055147,0.000000
35.210003,26.848801,-314.658234,0.002686,0.002148,0.054566,119.429428,6.084025,0.545661,-314.658234,0.055442,0.000000
35.390003,26.729637,-314.658234,0.002703,0.002156,0.054757,118.899361,6.057023,0.547568,-314.658234,0.055745,0.000000
35.570004,26.762039,-314.702728,0.002682,0.002163,0.054948,119.043495,6.064365,0.549476,-314.702728,0.056049,0.000000
35.750000,27.348152,-314.702728,0.002699,0.002179,0.055355,121.650658,6.197180,0.553552,-314.702728,0.056344,0.000000
35.930000,27.629662,-314.702728,0.002708,0.002193,0.055711,122.902870,6.260971,0.557106,-314.702728,0.056647,0.000000
36.110001,28.455956,-314.702728,0.002677,0.002212,0.056179,126.578415,6.448212,0.561792,-314.702728,0.056942,0.000000
36.290001,28.576607,-314.658234,0.002699,0.002222,0.056439,127.115097,6.475552,0.564392,-314.658234,0.057246,0.000000
36.470001,28.678635,-314.702728,0.002764,0.002234,0.056751,127.568939,6.498672,0.567515,-314.702728,0.057549,0.000000
36.650002,28.652199,-314.747223,0.002764,0.002243,0.056968,127.451347,6.492681,0.569683,-314.747223,0.057844,0.000000
36.830002,28.810081,-314.747223,0.002768,0.002253,0.057237,128.153641,6.528458,0.572371,-314.747223,0.058148,0.000000
37.010002,28.954567,-314.702728,0.002781,0.002264,0.057515,128.796341,6.561199,0.575145,-314.702728,0.058443,0.000000
37.190002,29.354492,-314.702728,0.002785,0.002276,0.057809,130.575302,6.651823,0.578094,-314.702728,0.058746,0.000000
37.370003,29.647179,-314.702728,0.002824,0.002288,0.058104,131.877243,6.718147,0.581042,-314.702728,0.059050,0.000000
37.550003,29.679573,-314.702728,0.002755,0.002296,0.058330,132.021332,6.725487,0.583298,-314.702728,0.059345,0.000000
37.730003,30.115250,-314.747223,0.002781,0.002309,0.058651,133.959320,6.824213,0.586507,-314.747223,0.059648,0.000000
37.910004,30.600075,-314.702728,0.002781,0.002324,0.059024,136.115936,6.934076,0.590235,-314.702728,0.059943,0.000000
38.090000,31.411850,-314.702728,0.002785,0.002342,0.059483,139.726883,7.118027,0.594830,-314.702728,0.060246,0.000000
38.270000,31.236832,-314.747223,0.002802,0.002348,0.059648,138.948364,7.078367,0.596481,-314.747223,0.060541,0.000000
38.450001,31.523193,-314.747223,0.002846,0.002361,0.059977,140.222168,7.143258,0.599773,-314.747223,0.060845,0.000000
38.630001,31.616280,-314.747223,0.002859,0.002372,0.060246,140.636230,7.164351,0.602464,-314.747223,0.061148,0.000000
38.810001,31.800980,-314.747223,0.002820,0.002383,0.060533,141.457825,7.206205,0.605326,-314.747223,0.061443,0.000000
38.990002,32.143562,-314.702728,0.002863,0.002395,0.060845,142.981705,7.283835,0.608448,-314.702728,0.061747,0.000000
39.170002,32.818298,-314.791687,0.002902,0.002410,0.061209,145.983078,7.436733,0.612089,-314.791687,0.062042,0.000000
39.350002,32.911018,-314.791687,0.002859,0.002418,0.061426,146.395523,7.457744,0.614258,-314.791687,0.062345,0.000000
39.530003,32.654457,-314.747223,0.002932,0.002423,0.061556,145.254272,7.399606,0.615560,-314.747223,0.062649,0.000000
39.710003,32.966507,-314.747223,0.002932,0.002436,0.061868,146.642349,7.470317,0.618679,-314.747223,0.062944,0.000000
39.890003,34.270927,-314.747223,0.002953,0.002459,0.062458,152.444702,7.765903,0.624576,-314.747223,0.063247,0.000000
40.070004,34.595634,-314.791687,0.002949,0.002471,0.062761,153.889069,7.839483,0.627611,-314.791687,0.063542,0.000000
40.250004,34.850708,-314.836182,0.002936,0.002482,0.063048,155.023697,7.897284,0.630476,-314.836182,0.063846,0.000000
40.430000,34.911034,-314.791687,0.002932,0.002492,0.063290,155.292038,7.910953,0.632903,-314.791687,0.064149,0.000000
40.610001,35.016045,-314.791687,0.002940,0.002502,0.063550,155.759140,7.934749,0.635503,-314.791687,0.064444,0.000000
40.790001,35.344475,-314.791687,0.002940,0.002512,0.063802,157.220078,8.009172,0.638020,-314.791687,0.064747,0.000000
40.970001,35.881065,-314.791687,0.002962,0.002526,0.064166,159.606949,8.130766,0.641661,-314.791687,0.065042,0.000000
41.150002,36.140984,-314.836182,0.002979,0.002536,0.064426,160.763123,8.189664,0.644265,-314.836182,0.065345,0.000000
41.330002,36.334984,-314.747223,0.002997,0.002547,0.064695,161.626083,8.233625,0.646952,-314.747223,0.065649,0.000000
41.510002,36.656342,-314.836182,0.003035,0.002559,0.064999,163.055557,8.306446,0.649988,-314.836182,0.065944,0.000000
41.690002,36.685387,-314.747223,0.003040,0.002567,0.065207,163.184753,8.313027,0.652069,-314.747223,0.066247,0.000000
41.870003,38.189400,-314.836182,0.003035,0.002590,0.065779,169.874939,8.653841,0.657792,-314.836182,0.066542,0.000000
42.050003,38.596779,-314.836182,0.003018,0.002602,0.066091,171.687042,8.746156,0.660915,-314.836182,0.066846,0.000000
42.230003,38.765091,-314.836182,0.003048,0.002613,0.066378,172.435730,8.784295,0.663776,-314.836182,0.067149,0.000000
42.410004,38.886856,-314.791687,0.003087,0.002622,0.066594,172.977371,8.811888,0.665945,-314.791687,0.067444,0.000000
42.590000,39.069321,-314.836182,0.003096,0.002631,0.066837,173.789017,8.853234,0.668371,-314.836182,0.067748,0.000000
42.770000,39.306145,-314.925140,0.003122,0.002645,0.067175,174.842468,8.906899,0.671755,-314.925140,0.068043,0.000000
42.950001,39.997643,-314.836182,0.003087,0.002657,0.067496,177.918396,9.063596,0.674964,-314.836182,0.068346,0.000000
43.130001,40.424751,-314.836182,0.003113,0.002668,0.067756,179.818268,9.160379,0.677564,-314.836182,0.068650,0.000000
43.310001,40.607590,-314.836182,0.003091,0.002677,0.067999,180.631577,9.201812,0.679994,-314.836182,0.068945,0.000000
43.490002,40.871597,-314.836182,0.003096,0.002687,0.068259,181.805939,9.261637,0.682594,-314.836182,0.069248,0.000000
43.670002,41.446915,-314.880646,0.003104,0.002704,0.068676,184.365082,9.392005,0.686758,-314.880646,0.069543,0.000000
43.850002,42.094475,-314.880646,0.003126,0.002715,0.068962,187.245575,9.538744,0.689619,-314.880646,0.069846,0.000000
44.030003,42.460144,-314.925140,0.003134,0.002726,0.069248,188.872147,9.621607,0.692481,-314.925140,0.070150,0.000000
44.210003,42.641487,-314.836182,0.003117,0.002736,0.069482,189.678802,9.662699,0.694823,-314.836182,0.070445,0.000000
44.390003,43.090195,-314.880646,0.003186,0.002749,0.069812,191.674759,9.764378,0.698120,-314.880646,0.070748,0.000000
44.570004,43.284203,-314.925140,0.003156,0.002759,0.070081,192.537750,9.808340,0.700807,-314.925140,0.071043,0.000000
44.750004,43.909042,-314.925140,0.003169,0.002772,0.070410,195.317169,9.949931,0.704104,-314.925140,0.071347,0.000000
44.930000,44.613571,-314.880646,0.003191,0.002785,0.070748,198.451080,10.109579,0.707484,-314.880646,0.071650,0.000000
45.110001,45.249580,-314.925140,0.003225,0.002798,0.071078,201.280182,10.253701,0.710781,-314.925140,0.071945,0.000000
45.290001,45.170639,-314.836182,0.003195,0.002804,0.071217,200.929031,10.235813,0.712166,-314.836182,0.072249,0.000000
45.470001,45.680420,-314.925140,0.003229,0.002817,0.071546,203.196655,10.351331,0.715463,-314.925140,0.072544,0.000000
45.650002,46.295952,-314.969604,0.003169,0.002830,0.071885,205.934677,10.490813,0.718846,-314.969604,0.072847,0.000000
45.830002,47.213478,-314.925140,0.003225,0.002845,0.072257,210.016037,10.698727,0.722574,-314.925140,0.073142,0.000000
46.010002,47.526642,-314.836182,0.003216,0.002857,0.072578,211.409058,10.769691,0.725784,-314.836182,0.073446,0.000000
46.190002,47.527756,-314.969604,0.003212,0.002863,0.072717,211.414017,10.769943,0.727169,-314.969604,0.073749,0.000000
46.370003,48.167122,-314.880646,0.003234,0.002876,0.073055,214.258057,10.914825,0.730553,-314.880646,0.074044,0.000000
46.550003,48.588646,-314.969604,0.003251,0.002888,0.073368,216.133087,11.010345,0.733675,-314.969604,0.074347,0.000000
46.730003,49.325943,-314.925140,0.003311,0.002902,0.073723,219.412750,11.177419,0.737229,-314.925140,0.074642,0.000000
46.910004,49.924721,-314.880646,0.003290,0.002914,0.074026,222.076248,11.313104,0.740265,-314.880646,0.074946,0.000000
47.090004,50.439339,-314.925140,0.003311,0.002926,0.074313,224.365387,11.429718,0.743126,-314.925140,0.075249,0.000000
47.270000,50.627762,-314.969604,0.003316,0.002934,0.074521,225.203537,11.472415,0.745208,-314.969604,0.075544,0.000000
47.450001,51.344200,-314.925140,0.003255,0.002949,0.074902,228.390411,11.634762,0.749023,-314.925140,0.075848,0.000000
47.630001,52.120598,-314.925140,0.003294,0.002962,0.075223,231.843994,11.810696,0.752233,-314.925140,0.076143,0.000000
47.810001,52.686981,-314.969604,0.003285,0.002975,0.075570,234.363403,11.939040,0.755704,-314.969604,0.076446,0.000000
47.990002,53.395607,-314.969604,0.003324,0.002988,0.075891,237.515518,12.099617,0.758909,-314.969604,0.076750,0.000000
48.170002,53.683823,-314.969604,0.003311,0.002999,0.076169,238.797577,12.164928,0.761687,-314.969604,0.077045,0.000000
48.350002,54.141464,-314.969604,0.003320,0.003010,0.076455,240.833267,12.268631,0.764549,-314.969604,0.077348,0.000000
48.530003,54.570808,-314.969604,0.003324,0.003019,0.076680,242.743073,12.365922,0.766801,-314.969604,0.077643,0.000000
48.710003,55.327103,-314.925140,0.003389,0.003034,0.077071,246.107239,12.537300,0.770707,-314.925140,0.077947,0.000000
48.890003,55.817886,-314.969604,0.003372,0.003044,0.077313,248.290359,12.648514,0.773133,-314.969604,0.078250,0.000000
49.070004,56.133659,-314.969604,0.003346,0.003053,0.077548,249.694992,12.720069,0.775476,-314.969604,0.078545,0.000000
49.250004,56.199570,-315.014099,0.003354,0.003060,0.077712,249.988174,12.735004,0.777122,-315.014099,0.078848,0.000000
49.430004,56.974106,-314.969604,0.003376,0.003072,0.078033,253.433487,12.910517,0.780332,-314.969604,0.079143,0.000000
49.610001,58.069252,-314.969604,0.003385,0.003089,0.078458,258.304932,13.158680,0.784582,-314.969604,0.079447,0.000000
49.790001,58.950287,-314.969604,0.003359,0.003105,0.078866,262.223969,13.358326,0.788659,-314.969604,0.079750,0.000000
49.970001,59.574379,-315.014099,0.003372,0.003116,0.079152,265.000061,13.499747,0.791520,-315.014099,0.080045,0.000000
50.150002,60.168312,-315.014099,0.003449,0.003128,0.079456,267.642029,13.634335,0.794555,-315.014099,0.080349,0.000000
50.330002,60.807304,-314.969604,0.003436,0.003140,0.079759,270.484406,13.779132,0.797591,-314.969604,0.080644,0.000000
50.510002,61.050095,-314.925140,0.003449,0.003147,0.079941,271.564392,13.834148,0.799411,-314.925140,0.080947,0.000000
50.690002,61.667114,-315.014099,0.003454,0.003162,0.080305,274.309021,13.973969,0.803053,-315.014099,0.081251,0.000000
50.870003,62.552986,-315.058563,0.003441,0.003174,0.080626,278.249573,14.174709,0.806262,-315.058563,0.081546,0.000000
51.050003,63.158836,-315.014099,0.003458,0.003184,0.080869,280.944550,14.311996,0.808688,-315.014099,0.081849,0.000000
51.230003,63.378166,-315.058563,0.003488,0.003194,0.081138,281.920166,14.361698,0.811379,-315.058563,0.082144,0.000000
51.410004,63.858147,-315.014099,0.003505,0.003205,0.081398,284.055237,14.470463,0.813980,-315.014099,0.082447,0.000000
51.590004,65.105980,-315.014099,0.003471,0.003222,0.081849,289.605865,14.753226,0.818491,-315.014099,0.082751,0.000000
51.770004,65.948647,-315.058563,0.003497,0.003233,0.082109,293.354218,14.944178,0.821091,-315.058563,0.083046,0.000000
51.950001,66.627861,-315.058563,0.003449,0.003245,0.082421,296.375519,15.098089,0.824214,-315.058563,0.083349,0.000000
52.130001,66.977150,-315.014099,0.003497,0.003254,0.082664,297.929230,15.177239,0.826640,-315.014099,0.083644,0.000000
52.310001,67.294411,-315.058563,0.003471,0.003254,0.082664,299.340485,15.249131,0.826640,-315.058563,0.082898,0.000000
52.490002,66.676262,-315.014099,0.003466,0.003254,0.082664,296.590820,15.109056,0.826640,-315.014099,0.082898,0.000000
52.670002,66.204475,-315.103058,0.003544,0.003253,0.082638,294.492218,15.002149,0.826383,-315.103058,0.082664,0.000000
52.850002,65.698418,-315.103058,0.003523,0.003252,0.082612,292.241150,14.887474,0.826121,-315.103058,0.082664,0.000000
53.030003,65.251198,-315.058563,0.003548,0.003252,0.082603,290.251831,14.786133,0.826034,-315.058563,0.082664,0.000000
53.210003,64.828560,-315.103058,0.003518,0.003252,0.082603,288.371826,14.690362,0.826034,-315.103058,0.082664,0.000000
53.390003,64.446877,-315.103058,0.003531,0.003252,0.082595,286.674011,14.603871,0.825947,-315.103058,0.082664,0.000000
53.570004,64.093864,-315.103058,0.003527,0.003252,0.082595,285.103760,14.523878,0.825947,-315.103058,0.082664,0.000000
53.750004,63.761330,-315.103058,0.003492,0.003252,0.082595,283.624573,14.448524,0.825947,-315.103058,0.082664,0.000000
53.930004,63.462700,-315.103058,0.003548,0.003251,0.082586,282.296173,14.380854,0.825860,-315.103058,0.082664,0.000000
54.110004,63.175591,-315.103058,0.003497,0.003251,0.082586,281.019073,14.315793,0.825860,-315.103058,0.082664,0.000000
54.290001,62.913071,-315.103058,0.003535,0.003251,0.082586,279.851318,14.256306,0.825860,-315.103058,0.082664,0.000000
54.470001,62.663956,-315.147552,0.003535,0.003251,0.082586,278.743195,14.199856,0.825860,-315.147552,0.082664,0.000000
54.650002,62.421539,-315.103058,0.003488,0.003251,0.082586,277.664886,14.144923,0.825860,-315.103058,0.082664,0.000000
54.830002,62.205933,-315.103058,0.003514,0.003251,0.082586,276.705811,14.096066,0.825860,-315.103058,0.082664,0.000000
55.010002,62.010437,-315.147552,0.003544,0.003251,0.082586,275.836212,14.051765,0.825860,-315.147552,0.082664,0.000000
55.190002,61.797813,-315.103058,0.003510,0.003251,0.082577,274.890411,14.003585,0.825773,-315.103058,0.082664,0.000000
55.370003,61.620193,-315.147552,0.003561,0.003251,0.082577,274.100311,13.963336,0.825773,-315.147552,0.082664,0.000000
55.550003,61.429169,-315.103058,0.003527,0.003251,0.082577,273.250580,13.920049,0.825773,-315.103058,0.082664,0.000000
55.730003,61.261971,-315.147552,0.003523,0.003251,0.082577,272.506866,13.882161,0.825773,-315.147552,0.082664,0.000000
55.910004,61.122330,-315.058563,0.003570,0.003251,0.082577,271.885712,13.850518,0.825773,-315.058563,0.082664,0.000000
56.090004,60.948807,-315.147552,0.003561,0.003251,0.082577,271.113831,13.811196,0.825773,-315.147552,0.082664,0.000000
56.270004,60.811028,-315.192017,0.003566,0.003251,0.082577,270.500946,13.779976,0.825773,-315.192017,0.082664,0.000000
56.450005,60.662453,-315.147552,0.003540,0.003251,0.082577,269.840057,13.746308,0.825773,-315.147552,0.082664,0.000000
56.630001,60.523560,-315.147552,0.003540,0.003251,0.082577,269.222229,13.714835,0.825773,-315.147552,0.082664,0.000000
56.810001,60.413338,-315.147552,0.003574,0.003251,0.082577,268.731934,13.689858,0.825773,-315.147552,0.082664,0.000000
56.990002,60.280769,-315.147552,0.003527,0.003251,0.082577,268.142242,13.659818,0.825773,-315.147552,0.082664,0.000000
57.170002,60.157143,-315.147552,0.003570,0.003251,0.082577,267.592346,13.631804,0.825773,-315.147552,0.082664,0.000000
57.350002,60.043571,-315.192017,0.003557,0.003251,0.082577,267.087158,13.606069,0.825773,-315.192017,0.082664,0.000000
57.530003,59.940048,-315.192017,0.003535,0.003251,0.082577,266.626648,13.582609,0.825773,-315.192017,0.082664,0.000000
57.710003,59.832062,-315.147552,0.003596,0.003251,0.082577,266.146301,13.558139,0.825773,-315.147552,0.082664,0.000000
57.890003,59.727798,-315.236511,0.003600,0.003251,0.082577,265.682526,13.534513,0.825773,-315.236511,0.082664,0.000000
58.070004,59.622040,-315.236511,0.003566,0.003251,0.082577,265.212067,13.510547,0.825773,-315.236511,0.082664,0.000000
58.250004,59.523735,-315.192017,0.003579,0.003251,0.082577,264.774811,13.488272,0.825773,-315.192017,0.082664,0.000000
58.430004,59.431015,-315.192017,0.003591,0.003251,0.082577,264.362366,13.467260,0.825773,-315.192017,0.082664,0.000000
58.610004,59.340530,-315.147552,0.003604,0.003251,0.082577,263.959869,13.446756,0.825773,-315.147552,0.082664,0.000000
58.790001,59.258606,-315.192017,0.003587,0.003251,0.082577,263.595459,13.428192,0.825773,-315.192017,0.082664,0.000000
58.970001,59.160301,-315.280975,0.003531,0.003251,0.082577,263.158173,13.405915,0.825773,-315.280975,0.082664,0.000000
59.150002,59.091415,-315.280975,0.003553,0.003251,0.082577,262.851746,13.390306,0.825773,-315.280975,0.082664,0.000000
59.330002,59.004280,-315.192017,0.003535,0.003251,0.082577,262.464142,13.370561,0.825773,-315.192017,0.082664,0.000000
59.510002,58.933525,-315.192017,0.003548,0.003251,0.082577,262.149414,13.354527,0.825773,-315.192017,0.082664,0.000000
59.690002,58.849747,-315.280975,0.003570,0.003251,0.082577,261.776733,13.335544,0.825773,-315.280975,0.082664,0.000000
59.870003,58.778618,-315.280975,0.003535,0.003251,0.082577,261.460358,13.319426,0.825773,-315.280975,0.082664,0.000000
60.050003,58.711220,-315.236511,0.003587,0.003251,0.082577,261.160553,13.304153,0.825773,-315.236511,0.082664,0.000000
60.230003,58.642334,-315.192017,0.003600,0.003251,0.082577,260.854126,13.288543,0.825773,-315.192017,0.082664,0.000000
60.410004,58.560036,-315.280975,0.003561,0.003251,0.082577,260.488037,13.269894,0.825773,-315.280975,0.082664,0.000000
60.590004,58.497108,-315.280975,0.003531,0.003251,0.082577,260.208130,13.255634,0.825773,-315.280975,0.082664,0.000000
60.770004,58.434547,-315.280975,0.003574,0.003251,0.082577,259.929840,13.241457,0.825773,-315.280975,0.082664,0.000000
60.950005,58.374969,-315.236511,0.003531,0.003251,0.082577,259.664825,13.227957,0.825773,-315.236511,0.082664,0.000000
61.130001,58.319481,-315.236511,0.003540,0.003251,0.082577,259.417999,13.215384,0.825773,-315.236511,0.082664,0.000000
61.310001,58.242401,-315.280975,0.003596,0.003251,0.082577,259.075134,13.197916,0.825773,-315.280975,0.082664,0.000000
61.490002,58.189896,-315.325470,0.003544,0.003251,0.082577,258.841583,13.186019,0.825773,-315.325470,0.082664,0.000000
61.670002,58.149307,-315.369934,0.003527,0.003251,0.082577,258.661041,13.176821,0.825773,-315.369934,0.082664,0.000000
61.850002,58.072601,-315.236511,0.003570,0.003251,0.082577,258.319824,13.159439,0.825773,-315.236511,0.082664,0.000000
62.030003,58.035362,-315.280975,0.003591,0.003251,0.082577,258.154175,13.151001,0.825773,-315.280975,0.082664,0.000000
62.210003,57.970573,-315.236511,0.003604,0.003251,0.082577,257.865997,13.136319,0.825773,-315.236511,0.082664,0.000000
62.390003,57.924400,-315.325470,0.003535,0.003251,0.082577,257.660614,13.125856,0.825773,-315.325470,0.082664,0.000000
62.570004,57.863701,-315.325470,0.003600,0.003251,0.082577,257.390594,13.112102,0.825773,-315.325470,0.082664,0.000000
62.750004,57.800026,-315.280975,0.003557,0.003251,0.082577,257.107361,13.097673,0.825773,-315.280975,0.082664,0.000000
62.930004,57.755714,-315.236511,0.003561,0.003251,0.082577,256.910248,13.087632,0.825773,-315.236511,0.082664,0.000000
63.110004,57.717361,-315.325470,0.003604,0.003251,0.082577,256.739655,13.078941,0.825773,-315.325470,0.082664,0.000000
63.290005,57.665596,-315.325470,0.003540,0.003251,0.082577,256.509369,13.067211,0.825773,-315.325470,0.082664,0.000000
63.470001,57.609367,-315.325470,0.003574,0.003251,0.082577,256.259277,13.054469,0.825773,-315.325470,0.082664,0.000000
63.650002,57.551277,-315.325470,0.003570,0.003251,0.082577,256.000854,13.041306,0.825773,-315.325470,0.082664,0.000000
63.830002,57.519257,-315.325470,0.003540,0.003251,0.082577,255.858429,13.034050,0.825773,-315.325470,0.082664,0.000000
64.010002,57.480156,-315.325470,0.003591,0.003251,0.082577,255.684509,13.025189,0.825773,-315.325470,0.082664,0.000000
64.190002,57.419090,-315.414429,0.003609,0.003251,0.082577,255.412872,13.011352,0.825773,-315.414429,0.082664,0.000000
64.370003,57.387810,-315.414429,0.003591,0.003251,0.082577,255.273727,13.004264,0.825773,-315.414429,0.082664,0.000000
64.550003,57.335304,-315.369934,0.003535,0.003251,0.082577,255.040176,12.992366,0.825773,-315.369934,0.082664,0.000000
64.730003,57.293228,-315.325470,0.003557,0.003251,0.082577,254.853012,12.982831,0.825773,-315.325470,0.082664,0.000000
64.910004,57.261574,-315.369934,0.003557,0.003251,0.082577,254.712204,12.975657,0.825773,-315.369934,0.082664,0.000000
65.090004,57.211678,-315.369934,0.003587,0.003251,0.082577,254.490250,12.964352,0.825773,-315.369934,0.082664,0.000000
65.270004,57.187469,-315.369934,0.003574,0.003251,0.082577,254.382568,12.958865,0.825773,-315.369934,0.082664,0.000000
65.450005,57.125656,-315.369934,0.003587,0.003251,0.082577,254.107605,12.944859,0.825773,-315.369934,0.082664,0.000000
65.630005,57.096245,-315.369934,0.003596,0.003251,0.082577,253.976776,12.938194,0.825773,-315.369934,0.082664,0.000000
65.810005,57.046341,-315.369934,0.003574,0.003251,0.082577,253.754791,12.926886,0.825773,-315.369934,0.082664,0.000000
65.990005,57.012459,-315.414429,0.003583,0.003251,0.082577,253.604080,12.919209,0.825773,-315.414429,0.082664,0.000000
66.170006,56.988998,-315.369934,0.003587,0.003251,0.082577,253.499725,12.913892,0.825773,-315.369934,0.082664,0.000000
66.350006,56.935379,-315.369934,0.003540,0.003251,0.082577,253.261215,12.901741,0.825773,-315.369934,0.082664,0.000000
66.530006,56.908195,-315.325470,0.003548,0.003251,0.082569,253.140289,12.895581,0.825686,-315.325470,0.082664,0.000000
66.710007,56.866859,-315.414429,0.003583,0.003251,0.082569,252.956421,12.886214,0.825686,-315.414429,0.082664,0.000000
66.889999,56.835579,-315.458893,0.003557,0.003251,0.082569,252.817276,12.879127,0.825686,-315.458893,0.082664,0.000000
67.070000,56.800201,-315.458893,0.003596,0.003251,0.082569,252.659912,12.871110,0.825686,-315.458893,0.082664,0.000000
67.250000,56.771904,-315.414429,0.003604,0.003251,0.082569,252.534042,12.864697,0.825686,-315.414429,0.082664,0.000000
67.430000,56.736900,-315.369934,0.003591,0.003251,0.082569,252.378342,12.856765,0.825686,-315.369934,0.082664,0.000000
67.610001,56.691475,-315.414429,0.003604,0.003251,0.082569,252.176270,12.846472,0.825686,-315.414429,0.082664,0.000000
67.790001,56.654610,-315.414429,0.003535,0.003251,0.082569,252.012283,12.838118,0.825686,-315.414429,0.082664,0.000000
67.970001,56.633385,-315.414429,0.003561,0.003251,0.082569,251.917877,12.833308,0.825686,-315.414429,0.082664,0.000000
68.150002,56.587952,-315.414429,0.003561,0.003251,0.082569,251.715775,12.823013,0.825686,-315.414429,0.082664,0.000000
68.330002,56.571198,-315.414429,0.003566,0.003251,0.082569,251.641251,12.819217,0.825686,-315.414429,0.082664,0.000000
68.510002,56.528374,-315.414429,0.003548,0.003251,0.082569,251.450760,12.809513,0.825686,-315.414429,0.082664,0.000000
68.690002,56.504166,-315.414429,0.003540,0.003251,0.082569,251.343079,12.804027,0.825686,-315.414429,0.082664,0.000000
68.870003,56.465439,-315.458893,0.003570,0.003251,0.082569,251.170822,12.795252,0.825686,-315.458893,0.082664,0.000000
69.050003,56.446075,-315.369934,0.003548,0.003251,0.082569,251.084686,12.790863,0.825686,-315.369934,0.082664,0.000000
69.230003,56.406609,-315.414429,0.003557,0.003251,0.082569,250.909134,12.781920,0.825686,-315.414429,0.082664,0.000000
69.410004,56.373093,-315.503387,0.003591,0.003251,0.082569,250.760040,12.774325,0.825686,-315.503387,0.082664,0.000000
69.590004,56.352615,-315.458893,0.003548,0.003251,0.082569,250.668945,12.769685,0.825686,-315.458893,0.082664,0.000000
69.770004,56.325432,-315.458893,0.003579,0.003251,0.082569,250.548035,12.763525,0.825686,-315.458893,0.082664,0.000000
69.950005,56.294525,-315.503387,0.003544,0.003251,0.082569,250.410553,12.756521,0.825686,-315.503387,0.082664,0.000000
70.130005,56.266220,-315.458893,0.003574,0.003251,0.082569,250.284653,12.750108,0.825686,-315.458893,0.082664,0.000000
70.310005,56.241646,-315.458893,0.003535,0.003251,0.082569,250.175339,12.744538,0.825686,-315.458893,0.082664,0.000000
70.490005,56.207390,-315.503387,0.003570,0.003251,0.082569,250.022964,12.736776,0.825686,-315.503387,0.082664,0.000000
70.670006,56.175362,-315.503387,0.003557,0.003251,0.082569,249.880493,12.729519,0.825686,-315.503387,0.082664,0.000000
70.850006,56.156372,-315.503387,0.003574,0.003251,0.082569,249.796021,12.725215,0.825686,-315.503387,0.082664,0.000000
71.030006,56.123978,-315.414429,0.003583,0.003251,0.082569,249.651917,12.717875,0.825686,-315.414429,0.082664,0.000000
71.210007,56.113548,-315.503387,0.003557,0.003251,0.082569,249.605530,12.715511,0.825686,-315.503387,0.082664,0.000000
71.390007,56.068863,-315.503387,0.003548,0.003251,0.082569,249.406754,12.705386,0.825686,-315.503387,0.082664,0.000000
71.570000,56.054718,-315.503387,0.003609,0.003251,0.082569,249.343842,12.702181,0.825686,-315.503387,0.082664,0.000000
71.750000,56.028648,-315.458893,0.003613,0.003251,0.082569,249.227875,12.696274,0.825686,-315.458893,0.082664,0.000000
71.930000,56.004074,-315.458893,0.003609,0.003251,0.082569,249.118561,12.690704,0.825686,-315.458893,0.082664,0.000000
72.110001,55.977264,-315.503387,0.003579,0.003251,0.082569,248.999313,12.684629,0.825686,-315.503387,0.082664,0.000000
72.290001,55.953056,-315.503387,0.003604,0.003251,0.082569,248.891632,12.679144,0.825686,-315.503387,0.082664,0.000000
72.470001,55.920288,-315.503387,0.003535,0.003251,0.082569,248.745865,12.671718,0.825686,-315.503387,0.082664,0.000000
72.650002,55.897202,-315.503387,0.003600,0.003251,0.082569,248.643173,12.666487,0.825686,-315.503387,0.082664,0.000000
72.830002,55.884171,-315.547852,0.003587,0.003251,0.082569,248.585205,12.663534,0.825686,-315.547852,0.082664,0.000000
73.010002,55.856239,-315.503387,0.003617,0.003251,0.082569,248.460968,12.657205,0.825686,-315.503387,0.082664,0.000000
73.190002,55.838364,-315.547852,0.003583,0.003251,0.082569,248.381439,12.653153,0.825686,-315.547852,0.082664,0.000000
73.370003,55.816025,-315.547852,0.003566,0.003251,0.082569,248.282074,12.648092,0.825686,-315.547852,0.082664,0.000000
73.550003,55.787727,-315.503387,0.003574,0.003251,0.082569,248.156204,12.641680,0.825686,-315.503387,0.082664,0.000000
73.730003,55.779907,-315.503387,0.003548,0.003251,0.082569,248.121414,12.639907,0.825686,-315.503387,0.082664,0.000000
73.910004,55.736710,-315.592346,0.003583,0.003251,0.082569,247.929260,12.630119,0.825686,-315.592346,0.082664,0.000000
74.090004,55.732613,-315.547852,0.003579,0.003251,0.082569,247.911041,12.629190,0.825686,-315.547852,0.082664,0.000000
74.270004,55.700958,-315.547852,0.003587,0.003251,0.082569,247.770233,12.622018,0.825686,-315.547852,0.082664,0.000000
74.450005,55.687553,-315.547852,0.003587,0.003251,0.082569,247.710602,12.618979,0.825686,-315.547852,0.082664,0.000000
74.630005,55.652550,-315.592346,0.003617,0.003251,0.082569,247.554901,12.611048,0.825686,-315.592346,0.082664,0.000000
74.810005,55.640266,-315.592346,0.003626,0.003251,0.082569,247.500259,12.608265,0.825686,-315.592346,0.082664,0.000000
74.990005,55.622017,-315.636841,0.003561,0.003251,0.082569,247.419083,12.604129,0.825686,-315.636841,0.082664,0.000000
75.170006,55.573235,-315.592346,0.003600,0.003251,0.082569,247.202087,12.593075,0.825686,-315.592346,0.082569,0.000000
75.300003,55.554245,-315.592346,0.003561,0.003251,0.082569,247.117630,12.588772,0.825686,-315.592346,0.082569,0.000000