File: Data/Compression Sample NH 10, 12, 15, 17 batch 3/AutoNoheating-17-3-1-240212_02122024_180801.csv
Time (sec),S:Load (lbs),S:HL1 (DIM),S:LVDT (in),S:Position (in),Ch:Position (mm),Ch:Load (N),Ch:Stress (MPa),Ch:Strain (mm/mm),Ch:HL1 (DIM),Set Point (),Cycles ()
0.110000,0.008186,-307.096497,0.000000,-0.000000,-0.000000,0.036415,0.001855,-0.000000,-307.096497,0.000191,0.000000
0.320000,0.006325,-307.140961,0.000056,-0.000000,-0.000000,0.028134,0.001433,-0.000000,-307.140961,0.000191,0.000000
0.530000,0.029411,-307.052002,0.000052,0.000102,0.002593,0.130828,0.006665,0.025930,-307.052002,0.003451,0.000000
0.740000,0.006325,-307.096497,0.000065,0.000228,0.005793,0.028134,0.001433,0.057928,-307.096497,0.006955,0.000000
0.950000,0.012283,-307.096497,0.000241,0.000370,0.009401,0.054639,0.002783,0.094005,-307.096497,0.010441,0.000000
1.160000,0.002975,-307.140961,0.000405,0.000510,0.012965,0.013236,0.000674,0.129648,-307.140961,0.013945,0.000000
1.370000,-0.010429,-307.140961,0.000492,0.000649,0.016477,-0.046392,-0.002363,0.164772,-307.140961,0.017448,0.000000
1.580000,-0.018997,-307.096497,0.000668,0.000785,0.019929,-0.084504,-0.004305,0.199286,-307.096497,0.020935,0.000000
1.790000,0.026436,-307.140961,0.000836,0.000916,0.023259,0.117593,0.005990,0.232589,-307.140961,0.024438,0.000000
2.000000,0.008560,-307.140961,0.000910,0.001055,0.026806,0.038078,0.001940,0.268058,-307.140961,0.027942,0.000000
2.210000,0.016380,-307.096497,0.001056,0.001196,0.030379,0.072863,0.003712,0.303787,-307.096497,0.031445,0.000000
2.420000,0.023087,-307.140961,0.001181,0.001334,0.033882,0.102694,0.005231,0.338824,-307.140961,0.034932,0.000000
2.630000,0.036118,-307.096497,0.001384,0.001473,0.037421,0.160659,0.008184,0.374205,-307.096497,0.038435,0.000000
2.840000,0.029411,-307.185455,0.001552,0.001605,0.040777,0.130828,0.006665,0.407769,-307.185455,0.041939,0.000000
3.050000,0.037979,-307.185455,0.001630,0.001738,0.044142,0.168940,0.008606,0.441417,-307.185455,0.045425,0.000000
3.260000,0.050636,-307.140961,0.001819,0.001878,0.047706,0.225241,0.011474,0.477060,-307.140961,0.048929,0.000000
3.470000,0.132187,-307.185455,0.001901,0.002020,0.051314,0.587997,0.029954,0.513137,-307.185455,0.052432,0.000000
3.680000,0.719795,-307.140961,0.002052,-0.000001,-0.000035,3.201809,0.163108,-0.000348,-307.140961,0.000182,0.000000
3.890000,0.670265,-307.140961,0.002074,-0.000001,-0.000035,2.981488,0.151884,-0.000348,-307.140961,0.000182,0.000000
4.100000,0.659470,-307.185455,0.002061,-0.000001,-0.000035,2.933467,0.149438,-0.000348,-307.185455,0.000182,0.000000
4.310000,0.640480,-307.140961,0.002095,-0.000001,-0.000035,2.848998,0.145135,-0.000348,-307.140961,0.000486,0.000000
4.520000,0.623344,-307.185455,0.002052,-0.000001,-0.000026,2.772774,0.141252,-0.000261,-307.185455,0.000832,0.000000
4.730000,0.636383,-307.140961,0.002074,-0.000001,-0.000026,2.830773,0.144206,-0.000261,-307.140961,0.001188,0.000000
4.940000,0.908958,-307.229919,0.002031,0.000027,0.000685,4.043249,0.205973,0.006851,-307.229919,0.001535,0.000000
5.150000,1.167381,-307.185455,0.002104,0.000046,0.001171,5.192771,0.264532,0.011707,-307.185455,0.001882,0.000000
5.360000,1.291382,-307.185455,0.002078,0.000057,0.001448,5.744353,0.292631,0.014481,-307.185455,0.002237,0.000000
5.570000,1.441452,-307.185455,0.002121,0.000071,0.001804,6.411899,0.326638,0.018039,-307.185455,0.002584,0.000000
5.780000,1.650726,-307.229919,0.002108,0.000081,0.002055,7.342797,0.374060,0.020552,-307.229919,0.002931,0.000000
5.990000,1.830582,-307.274414,0.002091,0.000095,0.002411,8.142834,0.414816,0.024106,-307.274414,0.003287,0.000000
6.200000,2.201088,-307.185455,0.002134,0.000112,0.002836,9.790928,0.498774,0.028356,-307.185455,0.003633,0.000000
6.410000,2.428986,-307.185455,0.002160,0.000124,0.003157,10.804667,0.550416,0.031566,-307.185455,0.003989,0.000000
6.620000,2.651665,-307.229919,0.002177,0.000135,0.003417,11.795194,0.600876,0.034166,-307.229919,0.004336,0.000000
6.830000,2.803963,-307.140961,0.002134,0.000143,0.003642,12.472649,0.635387,0.036422,-307.140961,0.004683,0.000000
7.040000,3.239639,-307.274414,0.002212,0.000165,0.004189,14.410635,0.734113,0.041887,-307.274414,0.005038,0.000000
7.250000,3.358055,-307.229919,0.002199,0.000175,0.004440,14.937375,0.760946,0.044401,-307.229919,0.005386,0.000000
7.460001,3.687225,-307.185455,0.002246,0.000188,0.004787,16.401598,0.835537,0.047871,-307.185455,0.005732,0.000000
7.670001,3.916237,-307.229919,0.002173,0.000202,0.005143,17.420292,0.887432,0.051425,-307.229919,0.006088,0.000000
7.880001,4.186951,-307.229919,0.002195,0.000215,0.005463,18.624487,0.948777,0.054635,-307.229919,0.006435,0.000000
8.090000,4.502724,-307.318878,0.002233,0.000230,0.005854,20.029116,1.020332,0.058537,-307.318878,0.006782,0.000000
8.300000,4.820732,-307.274414,0.002251,0.000244,0.006209,21.443687,1.092394,0.062091,-307.274414,0.007137,0.000000
8.510000,4.925369,-307.274414,0.002302,0.000253,0.006426,21.909136,1.116105,0.064260,-307.274414,0.007484,0.000000
8.720000,5.248589,-307.274414,0.002276,0.000267,0.006790,23.346888,1.189347,0.067901,-307.274414,0.007840,0.000000
8.930000,5.589684,-307.274414,0.002307,0.000284,0.007215,24.864155,1.266640,0.072151,-307.274414,0.008186,0.000000
9.140000,5.981415,-307.363373,0.002289,0.000302,0.007666,26.606663,1.355408,0.076663,-307.363373,0.008533,0.000000
9.350000,6.097595,-307.274414,0.002285,0.000310,0.007883,27.123459,1.381735,0.078828,-307.274414,0.008889,0.000000
9.560000,6.394379,-307.274414,0.002354,0.000325,0.008265,28.443617,1.448987,0.082647,-307.274414,0.009236,0.000000
9.770000,6.656525,-307.363373,0.002363,0.000339,0.008611,29.609701,1.508390,0.086114,-307.363373,0.009583,0.000000
9.980000,6.890007,-307.318878,0.002324,0.000353,0.008975,30.648281,1.561298,0.089755,-307.318878,0.009938,0.000000
10.190001,7.159973,-307.318878,0.002402,0.000368,0.009349,31.849152,1.622473,0.093487,-307.318878,0.010285,0.000000
10.400001,7.424728,-307.274414,0.002402,0.000382,0.009695,33.026840,1.682467,0.096954,-307.274414,0.010632,0.000000
10.610001,7.620972,-307.318878,0.002410,0.000394,0.009999,33.899776,1.726937,0.099989,-307.318878,0.010988,0.000000
10.820001,7.841789,-307.274414,0.002410,0.000409,0.010389,34.882019,1.776975,0.103892,-307.274414,0.011335,0.000000
11.030001,8.147881,-307.318878,0.002393,0.000425,0.010797,36.243584,1.846336,0.107968,-307.318878,0.011690,0.000000
11.240001,8.408165,-307.363373,0.002471,0.000439,0.011161,37.401386,1.905317,0.111613,-307.363373,0.012037,0.000000
11.450001,8.478546,-307.318878,0.002423,0.000451,0.011464,37.714458,1.921266,0.114644,-307.318878,0.012384,0.000000
11.660001,8.626747,-307.318878,0.002483,0.000465,0.011812,38.373688,1.954849,0.118115,-307.318878,0.012740,0.000000
11.870001,8.944382,-307.274414,0.002458,0.000482,0.012254,39.786598,2.026826,0.122540,-307.274414,0.013086,0.000000
12.080001,9.058701,-307.318878,0.002453,0.000496,0.012609,40.295113,2.052731,0.126094,-307.318878,0.013433,0.000000
12.290001,9.047531,-307.407867,0.002522,0.000505,0.012826,40.245430,2.050200,0.128263,-307.407867,0.013789,0.000000
12.500001,9.185310,-307.318878,0.002527,0.000516,0.013104,40.858299,2.081421,0.131037,-307.318878,0.014136,0.000000
12.710001,9.504433,-307.363373,0.002548,0.000532,0.013511,42.277828,2.153735,0.135113,-307.363373,0.014483,0.000000
12.920001,9.733070,-307.363373,0.002527,0.000551,0.013988,43.294861,2.205545,0.139882,-307.363373,0.014838,0.000000
13.130001,9.920372,-307.363373,0.002596,0.000564,0.014335,44.128017,2.247988,0.143353,-307.363373,0.015185,0.000000
13.340001,9.993729,-307.407867,0.002522,0.000578,0.014682,44.454327,2.264611,0.146820,-307.407867,0.015532,0.000000
13.550000,10.113632,-307.407867,0.002583,0.000591,0.015020,44.987682,2.291782,0.150204,-307.407867,0.015887,0.000000
13.760000,10.191460,-307.407867,0.002600,0.000606,0.015384,45.333878,2.309418,0.153845,-307.407867,0.016235,0.000000
13.970000,10.351204,-307.407867,0.002613,0.000619,0.015714,46.044456,2.345616,0.157141,-307.407867,0.016590,0.000000
14.180000,10.337425,-307.363373,0.002587,0.000631,0.016035,45.983166,2.342494,0.160351,-307.363373,0.016937,0.000000
14.390000,10.448395,-307.452332,0.002591,0.000643,0.016321,46.476780,2.367640,0.163212,-307.452332,0.017284,0.000000
14.600000,10.428291,-307.407867,0.002643,0.000650,0.016521,46.387356,2.363085,0.165207,-307.407867,0.017639,0.000000
14.810000,10.814812,-307.407867,0.002608,0.000673,0.017093,48.106686,2.450671,0.170930,-307.407867,0.017986,0.000000
15.020000,11.004349,-307.452332,0.002669,0.000686,0.017423,48.949787,2.493621,0.174226,-307.452332,0.018333,0.000000
15.230000,10.996529,-307.496826,0.002682,0.000698,0.017735,48.915001,2.491849,0.177345,-307.496826,0.018689,0.000000
15.440001,11.226280,-307.452332,0.002729,0.000717,0.018212,49.936989,2.543911,0.182118,-307.452332,0.019035,0.000000
15.650001,11.316765,-307.452332,0.002738,0.000731,0.018558,50.339485,2.564416,0.185585,-307.452332,0.019382,0.000000
15.860001,11.434441,-307.496826,0.002738,0.000745,0.018931,50.862930,2.591081,0.189313,-307.496826,0.019738,0.000000
16.070002,11.500717,-307.496826,0.002721,0.000759,0.019270,51.157745,2.606100,0.192697,-307.496826,0.020085,0.000000
16.280001,11.319000,-307.407867,0.002729,0.000765,0.019426,50.349426,2.564922,0.194256,-307.407867,0.020440,0.000000
16.490002,11.657486,-307.452332,0.002759,0.000784,0.019920,51.855087,2.641624,0.199199,-307.452332,0.020787,0.000000
16.700001,11.764359,-307.452332,0.002755,0.000799,0.020284,52.330479,2.665842,0.202844,-307.452332,0.021134,0.000000
16.910002,11.895432,-307.496826,0.002755,0.000814,0.020666,52.913521,2.695543,0.206659,-307.496826,0.021490,0.000000
17.120001,11.837341,-307.452332,0.002833,0.000822,0.020891,52.655125,2.682380,0.208915,-307.452332,0.021837,0.000000
17.330000,11.987785,-307.452332,0.002807,0.000838,0.021282,53.324333,2.716471,0.212817,-307.452332,0.022184,0.000000
17.540001,11.960602,-307.452332,0.002846,0.000849,0.021568,53.203415,2.710311,0.215678,-307.452332,0.022539,0.000000
17.750000,12.213814,-307.407867,0.002867,0.000868,0.022036,54.329758,2.767690,0.220360,-307.407867,0.022886,0.000000
17.960001,12.290154,-307.541290,0.002811,0.000878,0.022305,54.669334,2.784989,0.223048,-307.541290,0.023233,0.000000
18.170000,12.245834,-307.407867,0.002850,0.000890,0.022617,54.472191,2.774946,0.226170,-307.407867,0.023589,0.000000
18.380001,12.376541,-307.496826,0.002893,0.000902,0.022921,55.053604,2.804564,0.229206,-307.496826,0.023935,0.000000
18.590000,12.877754,-307.452332,0.002880,0.000926,0.023519,57.283112,2.918141,0.235190,-307.452332,0.024291,0.000000
18.800001,12.917595,-307.452332,0.002906,0.000940,0.023866,57.460331,2.927169,0.238660,-307.452332,0.024638,0.000000
19.010000,12.793228,-307.541290,0.002902,0.000951,0.024161,56.907120,2.898987,0.241609,-307.541290,0.024985,0.000000
19.220001,12.799187,-307.452332,0.002953,0.000963,0.024464,56.933624,2.900337,0.244644,-307.452332,0.025340,0.000000
19.430000,12.805885,-307.496826,0.002940,0.000974,0.024751,56.963425,2.901855,0.247506,-307.496826,0.025687,0.000000
19.640001,12.966751,-307.496826,0.002953,0.000990,0.025141,57.678989,2.938308,0.251408,-307.496826,0.026034,0.000000
19.850000,13.047554,-307.585785,0.002962,0.001000,0.025410,58.038418,2.956618,0.254095,-307.585785,0.026389,0.000000
20.060001,12.933609,-307.541290,0.003005,0.001008,0.025609,57.531567,2.930798,0.256090,-307.541290,0.026736,0.000000
20.270000,13.207306,-307.541290,0.003022,0.001027,0.026086,58.749031,2.992818,0.260859,-307.541290,0.027083,0.000000
20.480001,13.344337,-307.585785,0.003035,0.001040,0.026407,59.358578,3.023870,0.264068,-307.585785,0.027439,0.000000
20.690001,13.958382,-307.496826,0.003027,0.001066,0.027066,62.089981,3.163014,0.270662,-307.496826,0.027786,0.000000
20.900002,13.700325,-307.541290,0.003001,0.001074,0.027291,60.942089,3.104538,0.272914,-307.541290,0.028133,0.000000
21.110001,13.692879,-307.541290,0.003091,0.001087,0.027612,60.908966,3.102851,0.276123,-307.541290,0.028488,0.000000
21.320002,13.728622,-307.496826,0.003057,0.001100,0.027933,61.067963,3.110950,0.279333,-307.496826,0.028835,0.000000
21.530001,13.844063,-307.541290,0.003065,0.001114,0.028306,61.581467,3.137110,0.283061,-307.541290,0.029191,0.000000
21.740002,14.022057,-307.541290,0.003100,0.001127,0.028636,62.373222,3.177444,0.286358,-307.541290,0.029538,0.000000
21.950001,14.120361,-307.585785,0.003134,0.001142,0.029009,62.810505,3.199720,0.290086,-307.585785,0.029884,0.000000
22.160002,14.068604,-307.541290,0.003113,0.001153,0.029277,62.580273,3.187991,0.292773,-307.541290,0.030240,0.000000
22.370001,14.201538,-307.541290,0.003130,0.001166,0.029616,63.171597,3.218115,0.296157,-307.541290,0.030587,0.000000
22.580002,14.628273,-307.541290,0.003134,0.001187,0.030162,65.069809,3.314814,0.301618,-307.541290,0.030934,0.000000
22.790001,14.539650,-307.585785,0.003182,0.001198,0.030422,64.675591,3.294732,0.304222,-307.585785,0.031289,0.000000
23.000002,14.611145,-307.585785,0.003225,0.001213,0.030804,64.993622,3.310933,0.308037,-307.585785,0.031636,0.000000
23.210001,14.570930,-307.630249,0.003208,0.001224,0.031081,64.814735,3.301820,0.310812,-307.630249,0.031983,0.000000
23.420002,14.595139,-307.585785,0.003182,0.001234,0.031342,64.922417,3.307306,0.313416,-307.585785,0.032339,0.000000
23.630001,14.988731,-307.674744,0.003247,0.001251,0.031775,66.673210,3.396495,0.317750,-307.674744,0.032686,0.000000
23.840002,15.096352,-307.630249,0.003199,0.001267,0.032191,67.151924,3.420882,0.321913,-307.630249,0.033041,0.000000
24.050001,14.964157,-307.674744,0.003264,0.001274,0.032348,66.563896,3.390926,0.323476,-307.674744,0.033388,0.000000
24.260000,15.067307,-307.674744,0.003285,0.001287,0.032686,67.022728,3.414300,0.326856,-307.674744,0.033735,0.000000
24.470001,15.667938,-307.630249,0.003281,0.001310,0.033284,69.694473,3.550406,0.332840,-307.630249,0.034091,0.000000
24.680000,15.824333,-307.719208,0.003307,0.001327,0.033709,70.390152,3.585845,0.337090,-307.719208,0.034437,0.000000
24.890001,15.600914,-307.585785,0.003311,0.001337,0.033960,69.396332,3.535218,0.339603,-307.585785,0.034784,0.000000
25.100000,15.603889,-307.674744,0.003298,0.001349,0.034264,69.409569,3.535892,0.342639,-307.674744,0.035140,0.000000
25.310001,15.716721,-307.674744,0.003311,0.001361,0.034576,69.911469,3.561460,0.345762,-307.674744,0.035487,0.000000
25.520000,15.899559,-307.674744,0.003341,0.001377,0.034975,70.724770,3.602891,0.349751,-307.674744,0.035833,0.000000
25.730001,15.940887,-307.719208,0.003359,0.001390,0.035296,70.908607,3.612257,0.352960,-307.719208,0.036189,0.000000
25.940001,16.038452,-307.674744,0.003397,0.001400,0.035565,71.342598,3.634365,0.355648,-307.674744,0.036536,0.000000
26.150002,16.127823,-307.719208,0.003337,0.001413,0.035886,71.740143,3.654617,0.358857,-307.719208,0.036892,0.000000
26.360001,16.457367,-307.763702,0.003372,0.001432,0.036371,73.206024,3.729293,0.363713,-307.763702,0.037238,0.000000
26.570002,16.846130,-307.719208,0.003389,0.001450,0.036831,74.935333,3.817388,0.368308,-307.719208,0.037586,0.000000
26.780001,16.761223,-307.719208,0.003449,0.001463,0.037152,74.557640,3.798147,0.371518,-307.719208,0.037941,0.000000
26.990002,16.797722,-307.630249,0.003445,0.001475,0.037464,74.720001,3.806418,0.374640,-307.630249,0.038288,0.000000
27.200001,16.757874,-307.719208,0.003432,0.001486,0.037733,74.542747,3.797388,0.377328,-307.719208,0.038635,0.000000
27.410002,17.134346,-307.719208,0.003445,0.001503,0.038175,76.217377,3.882698,0.381752,-307.719208,0.038990,0.000000
27.620001,17.117958,-307.674744,0.003462,0.001516,0.038505,76.144478,3.878985,0.385049,-307.674744,0.039337,0.000000
27.830002,17.212914,-307.719208,0.003445,0.001527,0.038782,76.566864,3.900502,0.387823,-307.719208,0.039684,0.000000
28.040001,17.234512,-307.719208,0.003466,0.001538,0.039060,76.662941,3.905396,0.390597,-307.719208,0.040040,0.000000
28.250002,17.698486,-307.719208,0.003505,0.001557,0.039554,78.726799,4.010534,0.395540,-307.719208,0.040387,0.000000
28.460001,17.672424,-307.674744,0.003497,0.001568,0.039823,78.610870,4.004629,0.398228,-307.674744,0.040733,0.000000
28.670002,17.874619,-307.674744,0.003544,0.001583,0.040205,79.510277,4.050447,0.402047,-307.674744,0.041089,0.000000
28.880001,17.911858,-307.763702,0.003557,0.001595,0.040517,79.675919,4.058885,0.405165,-307.763702,0.041436,0.000000
29.090002,18.054474,-307.763702,0.003591,0.001609,0.040864,80.310310,4.091202,0.408636,-307.763702,0.041792,0.000000
29.300001,18.043304,-307.719208,0.003553,0.001621,0.041176,80.260628,4.088671,0.411759,-307.719208,0.042138,0.000000
29.510002,18.481216,-307.763702,0.003609,0.001637,0.041592,82.208557,4.187903,0.415922,-307.763702,0.042485,0.000000
29.720001,18.436905,-307.719208,0.003566,0.001647,0.041835,82.011452,4.177862,0.418348,-307.719208,0.042841,0.000000
29.930002,18.648407,-307.808167,0.003583,0.001663,0.042234,82.952255,4.225790,0.422338,-307.808167,0.043188,0.000000
30.140001,18.610054,-307.763702,0.003583,0.001673,0.042494,82.781654,4.217098,0.424938,-307.763702,0.043535,0.000000
30.350002,19.146271,-307.808167,0.003617,0.001693,0.043014,85.166862,4.338607,0.430142,-307.808167,0.043890,0.000000
30.560001,19.197289,-307.763702,0.003626,0.001707,0.043361,85.393806,4.350168,0.433613,-307.763702,0.044237,0.000000
30.770002,18.979073,-307.719208,0.003673,0.001714,0.043526,84.423134,4.300719,0.435259,-307.719208,0.044584,0.000000
30.980001,19.373421,-307.808167,0.003686,0.001731,0.043968,86.177277,4.390079,0.439684,-307.808167,0.044940,0.000000
31.190001,19.572639,-307.808167,0.003652,0.001745,0.044324,87.063446,4.435224,0.443238,-307.808167,0.045286,0.000000
31.400002,19.740578,-307.808167,0.003704,0.001759,0.044688,87.810478,4.473279,0.446879,-307.808167,0.045642,0.000000
31.610001,20.061188,-307.763702,0.003742,0.001775,0.045087,89.236618,4.545930,0.450868,-307.763702,0.045989,0.000000
31.820002,19.980759,-307.763702,0.003734,0.001788,0.045408,88.878853,4.527705,0.454078,-307.763702,0.046336,0.000000
32.030003,20.228386,-307.808167,0.003717,0.001802,0.045764,89.980354,4.583817,0.457635,-307.808167,0.046691,0.000000
32.240002,20.355362,-307.808167,0.003768,0.001815,0.046102,90.545174,4.612591,0.461015,-307.808167,0.047038,0.000000
32.450001,20.528519,-307.852661,0.003786,0.001829,0.046457,91.315414,4.651829,0.464573,-307.852661,0.047385,0.000000
32.660000,20.740028,-307.852661,0.003794,0.001844,0.046848,92.256256,4.699758,0.468475,-307.852661,0.047741,0.000000
32.870003,20.939621,-307.808167,0.003811,0.001859,0.047212,93.144089,4.744986,0.472116,-307.808167,0.048087,0.000000
33.080002,21.123199,-307.808167,0.003807,0.001874,0.047611,93.960686,4.786585,0.476106,-307.808167,0.048435,0.000000
33.290001,21.342522,-307.763702,0.003842,0.001888,0.047966,94.936279,4.836285,0.479660,-307.763702,0.048790,0.000000
33.500000,21.375290,-307.852661,0.003833,0.001900,0.048270,95.082039,4.843710,0.482695,-307.852661,0.049137,0.000000
33.710003,21.148148,-307.808167,0.003880,0.001908,0.048452,94.071655,4.792239,0.484520,-307.808167,0.049492,0.000000
33.920002,21.432266,-307.763702,0.003885,0.001922,0.048816,95.335480,4.856621,0.488161,-307.763702,0.049839,0.000000
34.130001,21.789368,-307.897156,0.003854,0.001938,0.049224,96.923950,4.937541,0.492237,-307.897156,0.050186,0.000000
34.340000,22.340858,-307.852661,0.003889,0.001955,0.049657,99.377098,5.062511,0.496571,-307.852661,0.050542,0.000000
34.550003,22.379951,-307.897156,0.003872,0.001969,0.050022,99.550995,5.071370,0.500216,-307.897156,0.050889,0.000000
34.760002,22.516991,-307.852661,0.003915,0.001983,0.050368,100.160576,5.102423,0.503682,-307.852661,0.051236,0.000000
34.970001,22.640984,-307.897156,0.003932,0.001997,0.050715,100.712128,5.130520,0.507153,-307.897156,0.051591,0.000000
35.180000,22.837227,-307.897156,0.003898,0.002012,0.051097,101.585060,5.174990,0.510968,-307.897156,0.051938,0.000000
35.390003,22.996979,-307.852661,0.003932,0.002025,0.051427,102.295670,5.211190,0.514265,-307.852661,0.052285,0.000000
35.600002,22.965698,-307.941620,0.003923,0.002034,0.051669,102.156525,5.204102,0.516691,-307.941620,0.052640,0.000000
35.810001,23.109802,-307.941620,0.003928,0.002046,0.051973,102.797531,5.236756,0.519727,-307.941620,0.052987,0.000000
36.020000,23.088577,-307.852661,0.003992,0.002055,0.052198,102.703117,5.231946,0.521982,-307.852661,0.053334,0.000000
36.230003,24.085419,-307.897156,0.003975,0.002080,0.052840,107.137291,5.457834,0.528398,-307.897156,0.053690,0.000000
36.440002,23.991951,-307.897156,0.003980,0.002091,0.053109,106.721527,5.436654,0.531089,-307.897156,0.054037,0.000000
36.650002,24.117813,-307.986115,0.004031,0.002104,0.053430,107.281387,5.465175,0.534298,-307.986115,0.054392,0.000000
36.860001,24.505829,-307.941620,0.004018,0.002120,0.053846,109.007370,5.553100,0.538458,-307.941620,0.054739,0.000000
37.070004,24.877083,-307.897156,0.004018,0.002135,0.054228,110.658791,5.637228,0.542277,-307.897156,0.055086,0.000000
37.280003,25.170517,-307.897156,0.004014,0.002151,0.054627,111.964050,5.703721,0.546266,-307.897156,0.055442,0.000000
37.490002,25.010391,-307.897156,0.004079,0.002159,0.054843,111.251778,5.667436,0.548431,-307.897156,0.055789,0.000000
37.700001,25.222649,-307.941620,0.004074,0.002174,0.055225,112.195946,5.715534,0.552246,-307.941620,0.056135,0.000000
37.910004,25.694069,-307.941620,0.004135,0.002191,0.055641,114.292923,5.822359,0.556410,-307.941620,0.056491,0.000000
38.120003,25.936485,-307.941620,0.004100,0.002204,0.055988,115.371246,5.877292,0.559881,-307.941620,0.056838,0.000000
38.330002,25.893661,-307.941620,0.004165,0.002214,0.056248,115.180756,5.867588,0.562481,-307.941620,0.057185,0.000000
38.540001,26.267151,-307.897156,0.004178,0.002230,0.056647,116.842125,5.952222,0.566470,-307.897156,0.057540,0.000000
38.750000,26.289864,-308.030579,0.004156,0.002241,0.056933,116.943153,5.957368,0.569331,-308.030579,0.057887,0.000000
38.960003,26.385193,-307.986115,0.004195,0.002253,0.057237,117.367203,5.978971,0.572367,-307.986115,0.058243,0.000000
39.170002,26.864807,-307.986115,0.004148,0.002268,0.057610,119.500633,6.087652,0.576099,-307.986115,0.058590,0.000000
39.380001,27.103500,-307.986115,0.004169,0.002283,0.058000,120.562393,6.141741,0.580001,-307.986115,0.058936,0.000000
39.590000,27.175369,-307.986115,0.004186,0.002291,0.058191,120.882080,6.158027,0.581909,-307.986115,0.059292,0.000000
39.800003,27.565613,-308.030579,0.004204,0.002308,0.058633,122.617973,6.246457,0.586329,-308.030579,0.059639,0.000000
40.010002,28.763535,-308.030579,0.004178,0.002333,0.059249,127.946594,6.517910,0.592487,-308.030579,0.059986,0.000000
40.220001,28.633575,-308.030579,0.004255,0.002342,0.059492,127.368507,6.488461,0.594917,-308.030579,0.060341,0.000000
40.430000,28.724808,-307.986115,0.004264,0.002355,0.059812,127.774330,6.509135,0.598123,-307.986115,0.060689,0.000000
40.640003,28.798538,-307.986115,0.004243,0.002367,0.060116,128.102295,6.525842,0.601159,-307.986115,0.061035,0.000000
40.850002,28.956421,-308.075073,0.004264,0.002379,0.060419,128.804596,6.561619,0.604194,-308.075073,0.061391,0.000000
41.060001,29.361191,-307.986115,0.004307,0.002393,0.060775,130.605103,6.653341,0.607752,-307.986115,0.061738,0.000000
41.270000,29.196602,-308.030579,0.004303,0.002400,0.060949,129.872971,6.616045,0.609485,-308.030579,0.062093,0.000000
41.480003,29.590950,-308.030579,0.004316,0.002414,0.061321,131.627121,6.705405,0.613214,-308.030579,0.062440,0.000000
41.690002,30.257866,-308.075073,0.004337,0.002431,0.061746,134.593704,6.856531,0.617464,-308.075073,0.062787,0.000000
41.900002,30.853661,-308.030579,0.004281,0.002452,0.062276,137.243942,6.991539,0.622755,-308.030579,0.063143,0.000000
42.110001,31.505684,-307.986115,0.004303,0.002467,0.062674,140.144287,7.139290,0.626745,-307.986115,0.063489,0.000000
42.320004,31.576813,-307.986115,0.004355,0.002481,0.063012,140.460678,7.155408,0.630124,-307.986115,0.063836,0.000000
42.530003,31.662079,-308.030579,0.004355,0.002491,0.063273,140.839966,7.174729,0.632728,-308.030579,0.064192,0.000000
42.740002,31.819595,-307.986115,0.004350,0.002504,0.063602,141.540634,7.210423,0.636021,-307.986115,0.064539,0.000000
42.950001,32.293625,-308.030579,0.004350,0.002520,0.064010,143.649216,7.317840,0.640098,-308.030579,0.064886,0.000000
43.160004,32.534180,-308.075073,0.004376,0.002534,0.064357,144.719254,7.372351,0.643568,-308.075073,0.065241,0.000000
43.370003,32.800797,-308.119537,0.004363,0.002544,0.064617,145.905228,7.432767,0.646169,-308.119537,0.065588,0.000000
43.580002,33.103912,-308.030579,0.004437,0.002557,0.064955,147.253555,7.501453,0.649552,-308.030579,0.065944,0.000000
43.790001,33.738060,-308.030579,0.004462,0.002573,0.065363,150.074387,7.645154,0.653629,-308.030579,0.066291,0.000000
44.000004,34.378540,-308.119537,0.004462,0.002591,0.065805,152.923386,7.790288,0.658049,-308.119537,0.066638,0.000000
44.210003,34.642555,-308.075073,0.004432,0.002604,0.066135,154.097778,7.850115,0.661346,-308.075073,0.066993,0.000000
44.420002,34.684258,-308.119537,0.004484,0.002616,0.066438,154.283279,7.859565,0.664382,-308.119537,0.067340,0.000000
44.630001,34.880501,-308.030579,0.004445,0.002628,0.066742,155.156219,7.904035,0.667417,-308.030579,0.067687,0.000000
44.840004,35.338516,-308.075073,0.004514,0.002641,0.067080,157.193573,8.007822,0.670797,-308.075073,0.068043,0.000000
45.050003,35.919418,-308.119537,0.004493,0.002656,0.067470,159.777557,8.139457,0.674699,-308.119537,0.068389,0.000000
45.260002,36.062035,-308.119537,0.004518,0.002667,0.067739,160.411942,8.171774,0.677390,-308.119537,0.068736,0.000000
45.470001,36.281738,-308.164032,0.004540,0.002681,0.068094,161.389236,8.221560,0.680944,-308.164032,0.069092,0.000000
45.680000,36.597137,-308.119537,0.004527,0.002692,0.068372,162.792191,8.293030,0.683719,-308.119537,0.069439,0.000000
45.890003,37.846069,-308.164032,0.004544,0.002715,0.068970,168.347717,8.576042,0.689703,-308.164032,0.069786,0.000000
46.100002,38.349144,-308.119537,0.004514,0.002729,0.069326,170.585510,8.690040,0.693260,-308.119537,0.070141,0.000000
46.310001,38.399788,-308.119537,0.004592,0.002740,0.069595,170.810791,8.701516,0.695948,-308.119537,0.070488,0.000000
46.520000,38.678322,-308.164032,0.004557,0.002754,0.069950,172.049774,8.764632,0.699502,-308.164032,0.070843,0.000000
46.730003,39.022026,-308.119537,0.004553,0.002765,0.070228,173.578644,8.842517,0.702280,-308.119537,0.071190,0.000000
46.940002,39.855392,-308.164032,0.004639,0.002782,0.070661,177.285645,9.031361,0.706613,-308.164032,0.071537,0.000000
47.150002,40.007324,-308.164032,0.004631,0.002793,0.070939,177.961472,9.065789,0.709392,-308.164032,0.071893,0.000000
47.360001,39.931732,-308.119537,0.004583,0.002804,0.071225,177.625214,9.048660,0.712253,-308.119537,0.072240,0.000000
47.570004,40.614288,-308.208496,0.004579,0.002817,0.071555,180.661377,9.203330,0.715546,-308.208496,0.072587,0.000000
47.780003,41.796570,-308.119537,0.004618,0.002839,0.072119,185.920425,9.471238,0.721185,-308.119537,0.072942,0.000000
47.990002,42.588608,-308.164032,0.004674,0.002856,0.072534,189.443588,9.650717,0.725345,-308.164032,0.073289,0.000000
48.200001,42.535355,-308.164032,0.004626,0.002865,0.072777,189.206711,9.638649,0.727775,-308.164032,0.073636,0.000000
48.410004,43.005295,-308.164032,0.004691,0.002878,0.073098,191.297104,9.745139,0.730984,-308.164032,0.073992,0.000000
48.620003,43.164299,-308.208496,0.004648,0.002892,0.073445,192.004395,9.781170,0.734451,-308.208496,0.074338,0.000000
48.830002,44.011070,-308.164032,0.004669,0.002907,0.073835,195.771011,9.973051,0.738354,-308.164032,0.074694,0.000000
49.040001,44.415092,-308.208496,0.004674,0.002921,0.074182,197.568192,10.064604,0.741824,-308.208496,0.075041,0.000000
49.250004,44.613571,-308.208496,0.004674,0.002931,0.074451,198.451080,10.109579,0.744512,-308.208496,0.075388,0.000000
49.460003,44.954292,-308.164032,0.004747,0.002941,0.074712,199.966675,10.186789,0.747116,-308.164032,0.075743,0.000000
49.670002,46.020020,-308.252991,0.004721,0.002960,0.075188,204.707275,10.428286,0.751885,-308.252991,0.076090,0.000000
49.880001,46.279564,-308.208496,0.004751,0.002973,0.075518,205.861786,10.487099,0.755177,-308.208496,0.076437,0.000000
50.090004,46.898445,-308.252991,0.004751,0.002985,0.075813,208.614700,10.627339,0.758126,-308.252991,0.076793,0.000000
50.300003,47.277519,-308.208496,0.004781,0.002998,0.076160,210.300903,10.713239,0.761597,-308.208496,0.077140,0.000000
50.510002,47.782829,-308.252991,0.004760,0.003012,0.076498,212.548645,10.827744,0.764980,-308.252991,0.077487,0.000000
50.720001,48.571144,-308.297485,0.004777,0.003027,0.076880,216.055237,11.006378,0.768795,-308.297485,0.077842,0.000000
50.930004,49.317009,-308.208496,0.004764,0.003042,0.077261,219.373016,11.175394,0.772611,-308.208496,0.078189,0.000000
51.140003,49.442871,-308.208496,0.004794,0.003051,0.077495,219.932877,11.203915,0.774953,-308.208496,0.078545,0.000000
51.350002,50.050949,-308.208496,0.004769,0.003065,0.077842,222.637741,11.341707,0.778420,-308.208496,0.078892,0.000000
51.560001,50.689568,-308.252991,0.004829,0.003081,0.078258,225.478455,11.486421,0.782584,-308.252991,0.079238,0.000000
51.770004,51.769447,-308.252991,0.004850,0.003099,0.078709,230.281998,11.731125,0.787092,-308.252991,0.079594,0.000000
51.980003,52.053574,-308.208496,0.004816,0.003107,0.078926,231.545853,11.795508,0.789260,-308.208496,0.079941,0.000000
52.190002,52.637077,-308.341949,0.004846,0.003123,0.079334,234.141418,11.927732,0.793337,-308.341949,0.080288,0.000000
52.400002,53.297668,-308.208496,0.004846,0.003136,0.079655,237.079865,12.077424,0.796546,-308.208496,0.080643,0.000000
52.610001,53.818245,-308.252991,0.004872,0.003151,0.080027,239.395508,12.195388,0.800274,-308.252991,0.080990,0.000000
52.820004,54.437500,-308.252991,0.004842,0.003163,0.080331,242.150101,12.335714,0.803310,-308.252991,0.081337,0.000000
53.030003,55.297676,-308.252991,0.004885,0.003178,0.080730,245.976349,12.530632,0.807299,-308.252991,0.081692,0.000000
53.240002,55.722183,-308.341949,0.004842,0.003190,0.081025,247.864655,12.626827,0.810248,-308.341949,0.082039,0.000000
53.450001,56.352982,-308.297485,0.004850,0.003202,0.081328,250.670578,12.769768,0.813283,-308.297485,0.082386,0.000000
53.660004,57.270134,-308.341949,0.004924,0.003220,0.081788,254.750275,12.977598,0.817878,-308.341949,0.082742,0.000000
53.870003,58.181702,-308.386444,0.004885,0.003235,0.082178,258.805145,13.184162,0.821780,-308.386444,0.083089,0.000000
54.080002,58.663185,-308.252991,0.004863,0.003247,0.082482,260.946869,13.293268,0.824816,-308.252991,0.083444,0.000000
54.290001,59.210197,-308.341949,0.004911,0.003260,0.082794,263.380127,13.417223,0.827938,-308.341949,0.083791,0.000000
54.500004,60.336250,-308.297485,0.004928,0.003278,0.083271,268.389038,13.672390,0.832711,-308.297485,0.084138,0.000000
54.710003,60.897789,-308.252991,0.004937,0.003291,0.083583,270.886902,13.799637,0.835830,-308.252991,0.084494,0.000000
54.920002,61.279472,-308.341949,0.004958,0.003300,0.083826,272.584717,13.886127,0.838260,-308.341949,0.084841,0.000000
55.130001,61.400116,-308.341949,0.004954,0.003310,0.084077,273.121368,13.913465,0.840773,-308.341949,0.085187,0.000000
55.340004,62.522453,-308.341949,0.004963,0.003328,0.084537,278.113770,14.167790,0.845371,-308.341949,0.085543,0.000000
55.550003,63.165535,-308.341949,0.004975,0.003339,0.084806,280.974335,14.313515,0.848059,-308.341949,0.085890,0.000000
55.760002,64.387299,-308.386444,0.004980,0.003357,0.085265,286.408997,14.590370,0.852654,-308.386444,0.086237,0.000000
55.970001,65.183426,-308.341949,0.004963,0.003373,0.085682,289.950348,14.770775,0.856817,-308.341949,0.086592,0.000000
56.180004,66.059250,-308.297485,0.004997,0.003387,0.086037,293.846222,14.969240,0.860375,-308.297485,0.086939,0.000000
56.390003,66.440552,-308.386444,0.005010,0.003396,0.086254,295.542328,15.055644,0.862544,-308.386444,0.087295,0.000000
56.600002,67.507034,-308.341949,0.005010,0.003409,0.086584,300.286285,15.297313,0.865836,-308.341949,0.087616,0.000000
56.810001,66.648712,-308.430908,0.005075,0.003404,0.086471,296.468292,15.102815,0.864708,-308.430908,0.086696,0.000000
57.020004,66.062225,-308.430908,0.005001,0.003403,0.086436,293.859467,14.969914,0.864364,-308.430908,0.086471,0.000000
57.230003,65.444458,-308.341949,0.005079,0.003400,0.086367,291.111481,14.829926,0.863668,-308.341949,0.086471,0.000000
57.440002,64.903778,-308.386444,0.005023,0.003399,0.086341,288.706421,14.707407,0.863410,-308.386444,0.086471,0.000000
57.650002,64.388779,-308.297485,0.005014,0.003399,0.086332,286.415588,14.590706,0.863323,-308.297485,0.086471,0.000000
57.860004,63.940079,-308.297485,0.005040,0.003399,0.086324,284.419678,14.489029,0.863236,-308.297485,0.086471,0.000000
58.070004,63.535309,-308.386444,0.005079,0.003398,0.086315,282.619171,14.397306,0.863149,-308.386444,0.086471,0.000000
58.280003,63.148781,-308.386444,0.005036,0.003398,0.086315,280.899811,14.309718,0.863149,-308.386444,0.086471,0.000000
58.490002,62.801353,-308.430908,0.005023,0.003398,0.086306,279.354370,14.230990,0.863062,-308.430908,0.086471,0.000000
58.700005,62.486702,-308.430908,0.005088,0.003398,0.086306,277.954742,14.159689,0.863062,-308.430908,0.086471,0.000000
58.910004,62.176514,-308.430908,0.005053,0.003398,0.086297,276.574951,14.089399,0.862975,-308.430908,0.086471,0.000000
59.120003,61.896118,-308.430908,0.005079,0.003398,0.086297,275.327698,14.025861,0.862975,-308.430908,0.086471,0.000000
59.330002,61.643280,-308.386444,0.005049,0.003398,0.086297,274.203003,13.968567,0.862975,-308.386444,0.086471,0.000000
59.540005,61.382248,-308.475403,0.005044,0.003398,0.086297,273.041870,13.909416,0.862975,-308.475403,0.086471,0.000000
59.750004,61.162918,-308.386444,0.005075,0.003398,0.086297,272.066254,13.859715,0.862975,-308.386444,0.086471,0.000000
59.960003,60.932045,-308.475403,0.005040,0.003398,0.086297,271.039276,13.807399,0.862975,-308.475403,0.086471,0.000000
60.170002,60.731339,-308.430908,0.005040,0.003398,0.086297,270.146484,13.761918,0.862975,-308.430908,0.086471,0.000000
60.380001,60.544411,-308.430908,0.005049,0.003397,0.086289,269.315002,13.719560,0.862888,-308.430908,0.086471,0.000000
60.590004,60.342583,-308.475403,0.005053,0.003397,0.086289,268.417206,13.673825,0.862888,-308.475403,0.086471,0.000000
60.800003,60.192886,-308.475403,0.005057,0.003397,0.086289,267.751343,13.639903,0.862888,-308.475403,0.086471,0.000000
61.010002,60.014519,-308.430908,0.005096,0.003397,0.086289,266.957916,13.599484,0.862888,-308.430908,0.086471,0.000000
61.220001,59.856262,-308.519867,0.005092,0.003397,0.086289,266.253937,13.563623,0.862888,-308.519867,0.086471,0.000000
61.430004,59.699120,-308.475403,0.005066,0.003397,0.086289,265.554932,13.528014,0.862888,-308.475403,0.086471,0.000000
61.640003,59.555756,-308.564362,0.005088,0.003397,0.086289,264.917236,13.495527,0.862888,-308.564362,0.086471,0.000000
61.850002,59.428032,-308.519867,0.005070,0.003397,0.086289,264.349091,13.466585,0.862888,-308.519867,0.086471,0.000000
62.060001,59.282806,-308.519867,0.005113,0.003397,0.086289,263.703094,13.433676,0.862888,-308.519867,0.086471,0.000000
62.270004,59.150246,-308.564362,0.005113,0.003397,0.086289,263.113434,13.403637,0.862888,-308.564362,0.086471,0.000000
62.480003,59.040024,-308.519867,0.005092,0.003397,0.086289,262.623138,13.378660,0.862888,-308.519867,0.086471,0.000000
62.690002,58.915649,-308.519867,0.005075,0.003397,0.086289,262.069885,13.350477,0.862888,-308.519867,0.086471,0.000000
62.900002,58.801331,-308.475403,0.005079,0.003397,0.086289,261.561371,13.324573,0.862888,-308.475403,0.086471,0.000000
63.110004,58.687759,-308.519867,0.005070,0.003397,0.086289,261.056183,13.298837,0.862888,-308.519867,0.086471,0.000000
63.320004,58.573814,-308.475403,0.005118,0.003397,0.086289,260.549347,13.273016,0.862888,-308.475403,0.086471,0.000000
63.530003,58.472527,-308.519867,0.005083,0.003397,0.086289,260.098785,13.250064,0.862888,-308.519867,0.086471,0.000000
63.740002,58.361931,-308.564362,0.005105,0.003397,0.086289,259.606842,13.225003,0.862888,-308.564362,0.086471,0.000000
63.950005,58.269211,-308.519867,0.005105,0.003397,0.086289,259.194397,13.203992,0.862888,-308.519867,0.086471,0.000000
64.160004,58.180962,-308.564362,0.005070,0.003397,0.086289,258.801849,13.183994,0.862888,-308.564362,0.086471,0.000000
64.370003,58.083771,-308.519867,0.005096,0.003397,0.086289,258.369507,13.161970,0.862888,-308.519867,0.086471,0.000000
64.580002,57.994026,-308.608826,0.005122,0.003397,0.086289,257.970306,13.141634,0.862888,-308.608826,0.086471,0.000000
64.790001,57.899071,-308.608826,0.005122,0.003397,0.086289,257.547943,13.120117,0.862888,-308.608826,0.086471,0.000000
65.000000,57.830559,-308.519867,0.005126,0.003397,0.086289,257.243164,13.104592,0.862888,-308.519867,0.086471,0.000000
65.210007,57.749382,-308.608826,0.005109,0.003397,0.086289,256.882080,13.086197,0.862888,-308.608826,0.086471,0.000000
65.420006,57.663734,-308.564362,0.005075,0.003397,0.086289,256.501099,13.066789,0.862888,-308.564362,0.086471,0.000000
65.630005,57.588516,-308.564362,0.005083,0.003397,0.086289,256.166504,13.049744,0.862888,-308.564362,0.086471,0.000000
65.840004,57.509201,-308.608826,0.005088,0.003397,0.086289,255.813705,13.031772,0.862888,-308.608826,0.086471,0.000000
66.050003,57.452225,-308.519867,0.005079,0.003397,0.086289,255.560257,13.018860,0.862888,-308.519867,0.086471,0.000000
66.260002,57.374031,-308.653320,0.005083,0.003397,0.086289,255.212433,13.001141,0.862888,-308.653320,0.086471,0.000000
66.470001,57.301788,-308.608826,0.005092,0.003397,0.086289,254.891083,12.984771,0.862888,-308.608826,0.086471,0.000000
66.680000,57.242584,-308.564362,0.005118,0.003397,0.086289,254.627731,12.971354,0.862888,-308.564362,0.086471,0.000000
66.889999,57.168480,-308.608826,0.005088,0.003397,0.086289,254.298096,12.954562,0.862888,-308.608826,0.086471,0.000000
67.100006,57.096985,-308.653320,0.005131,0.003397,0.086289,253.980072,12.938362,0.862888,-308.653320,0.086471,0.000000
67.310005,57.034424,-308.653320,0.005053,0.003397,0.086289,253.701782,12.924185,0.862888,-308.653320,0.086471,0.000000
67.520004,56.968887,-308.564362,0.005126,0.003397,0.086289,253.410263,12.909335,0.862888,-308.564362,0.086471,0.000000
67.730003,56.920853,-308.608826,0.005101,0.003397,0.086289,253.196594,12.898450,0.862888,-308.608826,0.086471,0.000000
67.940002,56.851593,-308.653320,0.005083,0.003397,0.086289,252.888519,12.882755,0.862888,-308.653320,0.086471,0.000000
68.150002,56.788284,-308.608826,0.005126,0.003397,0.086289,252.606903,12.868409,0.862888,-308.608826,0.086471,0.000000
68.360001,56.737640,-308.608826,0.005101,0.003397,0.086289,252.381622,12.856934,0.862888,-308.608826,0.086471,0.000000
68.570000,56.675827,-308.697815,0.005092,0.003397,0.086289,252.106674,12.842926,0.862888,-308.697815,0.086471,0.000000
68.780006,56.627792,-308.653320,0.005101,0.003397,0.086289,251.893005,12.832041,0.862888,-308.653320,0.086471,0.000000
68.990005,56.569328,-308.697815,0.005122,0.003397,0.086289,251.632935,12.818793,0.862888,-308.697815,0.086471,0.000000
69.200005,56.529861,-308.653320,0.005126,0.003397,0.086289,251.457382,12.809850,0.862888,-308.653320,0.086471,0.000000
69.410004,56.463203,-308.697815,0.005105,0.003397,0.086289,251.160873,12.794745,0.862888,-308.697815,0.086471,0.000000
69.620003,56.423737,-308.653320,0.005075,0.003397,0.086289,250.985321,12.785801,0.862888,-308.653320,0.086471,0.000000
69.830002,56.373466,-308.653320,0.005075,0.003397,0.086289,250.761703,12.774410,0.862888,-308.653320,0.086471,0.000000
70.040001,56.314255,-308.608826,0.005113,0.003397,0.086289,250.498322,12.760992,0.862888,-308.608826,0.086471,0.000000
70.250000,56.270691,-308.608826,0.005101,0.003397,0.086289,250.304535,12.751121,0.862888,-308.608826,0.086471,0.000000
70.460007,56.227867,-308.786774,0.005135,0.003397,0.086289,250.114044,12.741417,0.862888,-308.786774,0.086471,0.000000
70.670006,56.187653,-308.653320,0.005144,0.003397,0.086289,249.935165,12.732304,0.862888,-308.653320,0.086471,0.000000
70.880005,56.151901,-308.742279,0.005101,0.003397,0.086289,249.776138,12.724203,0.862888,-308.742279,0.086471,0.000000
71.090004,56.095299,-308.697815,0.005101,0.003397,0.086289,249.524353,12.711376,0.862888,-308.697815,0.086471,0.000000
71.300003,56.057693,-308.653320,0.005096,0.003397,0.086289,249.357071,12.702855,0.862888,-308.653320,0.086471,0.000000
71.510002,56.018967,-308.742279,0.005062,0.003397,0.086289,249.184814,12.694079,0.862888,-308.742279,0.086471,0.000000
71.720001,55.968697,-308.697815,0.005083,0.003397,0.086289,248.961197,12.682688,0.862888,-308.697815,0.086471,0.000000
71.930000,55.935181,-308.742279,0.005070,0.003397,0.086289,248.812103,12.675094,0.862888,-308.742279,0.086471,0.000000
72.140007,55.891243,-308.742279,0.005083,0.003397,0.086289,248.616669,12.665137,0.862888,-308.742279,0.086471,0.000000
72.350006,55.847672,-308.742279,0.005131,0.003397,0.086289,248.422852,12.655264,0.862888,-308.742279,0.086471,0.000000
72.560005,55.806709,-308.786774,0.005105,0.003397,0.086289,248.240646,12.645981,0.862888,-308.786774,0.086471,0.000000
72.770004,55.767616,-308.742279,0.005079,0.003397,0.086289,248.066742,12.637122,0.862888,-308.742279,0.086471,0.000000
72.980003,55.728142,-308.786774,0.005092,0.003397,0.086289,247.891159,12.628177,0.862888,-308.786774,0.086471,0.000000
73.190002,55.683456,-308.697815,0.005070,0.003397,0.086289,247.692383,12.618052,0.862888,-308.697815,0.086471,0.000000
73.400002,55.653297,-308.831238,0.005131,0.003397,0.086289,247.558228,12.611217,0.862888,-308.831238,0.086471,0.000000
73.610001,55.601532,-308.786774,0.005139,0.003397,0.086289,247.327972,12.599487,0.862888,-308.786774,0.086471,0.000000
73.820000,55.562065,-308.742279,0.005101,0.003397,0.086289,247.152405,12.590545,0.862888,-308.742279,0.086471,0.000000
74.030006,55.530037,-308.831238,0.005126,0.003397,0.086289,247.009933,12.583286,0.862888,-308.831238,0.086471,0.000000
74.240005,55.482002,-308.742279,0.005122,0.003397,0.086289,246.796265,12.572401,0.862888,-308.742279,0.086471,0.000000
74.450005,55.454819,-308.831238,0.005139,0.003397,0.086289,246.675354,12.566241,0.862888,-308.831238,0.086471,0.000000
74.660004,55.420937,-308.786774,0.005066,0.003397,0.086289,246.524643,12.558564,0.862888,-308.786774,0.086471,0.000000
74.870003,55.377739,-308.742279,0.005088,0.003397,0.086289,246.332489,12.548775,0.862888,-308.742279,0.086471,0.000000
75.080002,55.356140,-308.831238,0.005096,0.003397,0.086289,246.236404,12.543880,0.862888,-308.831238,0.086471,0.000000
75.290001,55.315552,-308.786774,0.005109,0.003397,0.086289,246.055862,12.534683,0.862888,-308.786774,0.086471,0.000000
75.500000,55.288368,-308.786774,0.005170,0.003397,0.086289,245.934952,12.528523,0.862888,-308.786774,0.086471,0.000000
75.710007,55.252998,-308.831238,0.005075,0.003397,0.086289,245.777618,12.520508,0.862888,-308.831238,0.086471,0.000000
75.920006,55.225815,-308.786774,0.005105,0.003397,0.086289,245.656693,12.514348,0.862888,-308.786774,0.086471,0.000000
76.130005,55.199745,-308.831238,0.005075,0.003397,0.086289,245.540726,12.508441,0.862888,-308.831238,0.086471,0.000000
76.340004,55.161018,-308.831238,0.005135,0.003397,0.086289,245.368469,12.499666,0.862888,-308.831238,0.086471,0.000000
76.550003,55.133835,-308.831238,0.005096,0.003397,0.086289,245.247543,12.493505,0.862888,-308.831238,0.086471,0.000000
76.760002,55.102554,-308.831238,0.005126,0.003397,0.086289,245.108398,12.486417,0.862888,-308.831238,0.086471,0.000000
76.970001,55.072769,-308.831238,0.005126,0.003397,0.086289,244.975906,12.479668,0.862888,-308.831238,0.086471,0.000000
77.180000,55.047821,-308.920197,0.005088,0.003397,0.086289,244.864944,12.474014,0.862888,-308.920197,0.086471,0.000000
77.390007,55.018776,-308.831238,0.005122,0.003397,0.086289,244.735733,12.467433,0.862888,-308.831238,0.086471,0.000000
77.600006,54.980789,-308.875732,0.005144,0.003397,0.086289,244.566772,12.458825,0.862888,-308.875732,0.086471,0.000000
77.810005,54.961426,-308.875732,0.005148,0.003397,0.086289,244.480637,12.454437,0.862888,-308.875732,0.086471,0.000000
78.020004,54.921585,-308.831238,0.005096,0.003397,0.086289,244.303406,12.445409,0.862888,-308.831238,0.086471,0.000000
78.230003,54.898125,-308.875732,0.005053,0.003397,0.086289,244.199051,12.440093,0.862888,-308.875732,0.086471,0.000000
78.440002,54.874664,-308.875732,0.005101,0.003397,0.086289,244.094696,12.434777,0.862888,-308.875732,0.086471,0.000000
78.650002,54.832962,-308.920197,0.005157,0.003397,0.086289,243.909195,12.425327,0.862888,-308.920197,0.086471,0.000000
78.860001,54.807266,-308.920197,0.005096,0.003397,0.086289,243.794891,12.419504,0.862888,-308.920197,0.086471,0.000000
79.070007,54.795349,-308.875732,0.005105,0.003397,0.086289,243.741882,12.416803,0.862888,-308.875732,0.086471,0.000000
79.280006,54.757736,-308.920197,0.005088,0.003397,0.086289,243.574570,12.408280,0.862888,-308.920197,0.086471,0.000000
79.490005,54.739120,-308.920197,0.005101,0.003397,0.086289,243.491776,12.404062,0.862888,-308.920197,0.086471,0.000000
79.700005,54.711563,-308.964691,0.005079,0.003397,0.086289,243.369186,12.397817,0.862888,-308.964691,0.086471,0.000000
79.910004,54.668739,-308.831238,0.005096,0.003397,0.086289,243.178696,12.388113,0.862888,-308.831238,0.086471,0.000000
80.120003,54.651237,-309.009155,0.005157,0.003397,0.086289,243.100845,12.384148,0.862888,-309.009155,0.086471,0.000000
80.330002,54.617729,-308.920197,0.005135,0.003397,0.086289,242.951797,12.376554,0.862888,-308.920197,0.086471,0.000000
80.540001,54.594643,-308.875732,0.005088,0.003397,0.086289,242.849106,12.371323,0.862888,-308.875732,0.086471,0.000000
80.750008,54.592781,-308.920197,0.005083,0.003397,0.086289,242.840820,12.370901,0.862888,-308.920197,0.086471,0.000000
80.960007,54.550697,-308.964691,0.005118,0.003397,0.086289,242.653625,12.361364,0.862888,-308.964691,0.086471,0.000000
81.170006,54.528732,-308.920197,0.005139,0.003397,0.086289,242.555908,12.356387,0.862888,-308.920197,0.086471,0.000000
81.380005,54.495590,-309.009155,0.005113,0.003397,0.086289,242.408493,12.348877,0.862888,-309.009155,0.086471,0.000000
81.590004,54.473244,-308.920197,0.005131,0.003397,0.086289,242.309097,12.343813,0.862888,-308.920197,0.086471,0.000000
81.800003,54.446808,-308.964691,0.005139,0.003397,0.086289,242.191498,12.337823,0.862888,-308.964691,0.086471,0.000000
82.010002,54.440475,-308.920197,0.005157,0.003397,0.086289,242.163330,12.336388,0.862888,-308.920197,0.086471,0.000000
82.220001,54.413292,-308.964691,0.005088,0.003397,0.086289,242.042404,12.330228,0.862888,-308.964691,0.086471,0.000000
82.430000,54.385742,-308.964691,0.005109,0.003397,0.086289,241.919861,12.323985,0.862888,-308.964691,0.086471,0.000000
82.640007,54.362282,-308.964691,0.005122,0.003397,0.086289,241.815506,12.318669,0.862888,-308.964691,0.086471,0.000000
82.850006,54.339569,-309.009155,0.005105,0.003397,0.086289,241.714478,12.313522,0.862888,-309.009155,0.086471,0.000000
83.060005,54.307915,-308.964691,0.005139,0.003397,0.086289,241.573669,12.306349,0.862888,-308.964691,0.086471,0.000000
83.270004,54.295998,-308.964691,0.005088,0.003397,0.086289,241.520660,12.303649,0.862888,-308.964691,0.086471,0.000000
83.480003,54.276634,-309.009155,0.005088,0.003397,0.086289,241.434525,12.299261,0.862888,-309.009155,0.086471,0.000000
83.690002,54.256523,-308.964691,0.005096,0.003397,0.086289,241.345062,12.294703,0.862888,-308.964691,0.086471,0.000000
83.900002,54.236794,-309.053650,0.005122,0.003397,0.086289,241.257309,12.290234,0.862888,-309.053650,0.086471,0.000000
84.110001,54.217796,-309.009155,0.005105,0.003397,0.086289,241.172806,12.285929,0.862888,-309.009155,0.086471,0.000000
84.320007,54.208488,-308.964691,0.005118,0.003397,0.086289,241.131393,12.283819,0.862888,-308.964691,0.086471,0.000000
84.530006,54.177208,-309.053650,0.005105,0.003397,0.086289,240.992264,12.276731,0.862888,-309.053650,0.086471,0.000000
84.740005,54.165298,-308.964691,0.005109,0.003397,0.086289,240.939285,12.274032,0.862888,-308.964691,0.086471,0.000000
84.950005,54.158966,-309.053650,0.005101,0.003397,0.086289,240.911118,12.272597,0.862888,-309.053650,0.086471,0.000000
85.160004,54.134392,-309.009155,0.005113,0.003397,0.086289,240.801804,12.267029,0.862888,-309.009155,0.086471,0.000000
85.370003,54.106461,-309.053650,0.005139,0.003397,0.086289,240.677551,12.260699,0.862888,-309.053650,0.086471,0.000000
85.580002,54.097527,-309.009155,0.005131,0.003397,0.086289,240.637817,12.258675,0.862888,-309.009155,0.086471,0.000000
85.790001,54.068108,-309.053650,0.005122,0.003397,0.086289,240.506958,12.252008,0.862888,-309.053650,0.086471,0.000000
86.000008,54.052841,-309.098114,0.005088,0.003397,0.086289,240.439041,12.248549,0.862888,-309.098114,0.086471,0.000000
86.210007,54.034218,-308.964691,0.005139,0.003397,0.086289,240.356201,12.244329,0.862888,-308.964691,0.086471,0.000000
86.420006,54.009644,-309.053650,0.005096,0.003397,0.086289,240.246887,12.238760,0.862888,-309.053650,0.086471,0.000000
86.630005,53.979851,-309.098114,0.005139,0.003397,0.086289,240.114365,12.232009,0.862888,-309.098114,0.086471,0.000000
86.840004,53.965706,-309.009155,0.005152,0.003397,0.086289,240.051453,12.228805,0.862888,-309.009155,0.086471,0.000000
87.050003,53.951553,-309.098114,0.005092,0.003397,0.086289,239.988495,12.225596,0.862888,-309.098114,0.086471,0.000000
87.100006,53.931076,-309.053650,0.005144,0.003397,0.086289,239.897415,12.220957,0.862888,-309.053650,0.086471,0.000000