File: Data/Compression Sample NH 10, 12, 15, 17 batch 3/AutoNoheating-12-3-4-240212_02122024_162658.csv
Time (sec),S:Load (lbs),S:HL1 (DIM),S:LVDT (in),S:Position (in),Ch:Position (mm),Ch:Load (N),Ch:Stress (MPa),Ch:Strain (mm/mm),Ch:HL1 (DIM),Set Point (),Cycles ()
0.110000,-0.007820,-160.220383,0.000034,-0.000000,-0.000000,-0.034786,-0.001772,-0.000000,-160.220383,0.000148,0.000000
0.350000,-0.010803,-160.220383,0.000017,0.000002,0.000052,-0.048055,-0.002448,0.000522,-160.220383,0.000459,0.000000
0.590000,0.027924,-160.264862,-0.000017,0.000142,0.003616,0.124210,0.006328,0.036165,-160.264862,0.004466,0.000000
0.830000,0.004837,-160.220383,0.000125,0.000295,0.007493,0.021516,0.001096,0.074930,-160.220383,0.008455,0.000000
1.070000,-0.012665,-160.264862,0.000302,0.000446,0.011326,-0.056336,-0.002870,0.113259,-160.264862,0.012462,0.000000
1.310000,-0.001122,-160.309341,0.000500,0.000601,0.015263,-0.004989,-0.000254,0.152633,-160.309341,0.016451,0.000000
1.550000,-0.008568,-160.175903,0.000629,0.000760,0.019313,-0.038112,-0.001941,0.193132,-160.175903,0.020458,0.000000
1.790000,-0.051018,-160.309341,0.000811,0.000923,0.023441,-0.226938,-0.011561,0.234410,-160.309341,0.024447,0.000000
2.030000,-0.043945,-160.264862,0.000974,0.001077,0.027344,-0.195479,-0.009958,0.273436,-160.264862,0.028454,0.000000
2.270000,0.009682,-160.309341,0.001138,0.001237,0.031420,0.043066,0.002194,0.314195,-160.309341,0.032443,0.000000
2.510000,0.018242,-160.309341,0.001306,0.001394,0.035409,0.081144,0.004134,0.354088,-160.309341,0.036450,0.000000
2.750000,0.026436,-160.309341,0.001436,0.001552,0.039424,0.117593,0.005990,0.394242,-160.309341,0.040439,0.000000
2.990000,-0.003731,-160.309341,0.001647,0.001707,0.043370,-0.016595,-0.000845,0.433700,-160.309341,0.044445,0.000000
3.230000,0.004463,-160.309341,0.001811,0.001863,0.047324,0.019853,0.001011,0.473244,-160.309341,0.048435,0.000000
3.470000,0.017868,-160.353836,0.001949,0.002018,0.051253,0.079481,0.004049,0.512532,-160.353836,0.052441,0.000000
3.710000,-0.016762,-160.309341,0.002113,0.002182,0.055416,-0.074560,-0.003798,0.554158,-160.309341,0.056431,0.000000
3.950000,-0.057350,-160.309341,0.002298,0.002335,0.059310,-0.255106,-0.012996,0.593097,-160.309341,0.060437,0.000000
4.190000,-0.001495,-160.353836,0.002458,0.002495,0.063377,-0.006652,-0.000339,0.633769,-160.353836,0.064426,0.000000
4.430000,0.033508,-160.309341,0.002591,0.002650,0.067323,0.149052,0.007593,0.673227,-160.309341,0.068433,0.000000
4.670000,0.012283,-160.353836,0.002772,0.002813,0.071442,0.054639,0.002783,0.714422,-160.353836,0.072439,0.000000
4.910000,-0.010803,-160.353836,0.002945,0.002968,0.075397,-0.048055,-0.002448,0.753966,-160.353836,0.076429,0.000000
5.150000,0.002602,-160.309341,0.003134,0.003125,0.079377,0.011573,0.000590,0.793772,-160.309341,0.080435,0.000000
5.390000,0.021225,-160.353836,0.003268,0.003275,0.083184,0.094413,0.004810,0.831844,-160.353836,0.084424,0.000000
5.630000,0.006699,-160.398315,0.003449,0.003437,0.087312,0.029797,0.001518,0.873122,-160.398315,0.088431,0.000000
5.870000,-0.048042,-160.353836,0.003574,0.003597,0.091362,-0.213703,-0.010887,0.913624,-160.353836,0.092420,0.000000
6.110000,-0.014153,-160.398315,0.003747,0.003752,0.095308,-0.062954,-0.003207,0.953082,-160.398315,0.096427,0.000000
6.350000,0.017502,-160.398315,0.003915,0.003910,0.099323,0.077852,0.003966,0.993232,-160.398315,0.100416,0.000000
6.590000,0.032768,-160.442795,0.004087,0.004068,0.103339,0.145760,0.007425,1.033386,-160.442795,0.104423,0.000000
6.830000,-0.005959,-160.398315,0.004268,0.004229,0.107415,-0.026505,-0.001350,1.074146,-160.398315,0.108412,0.000000
7.070000,0.011169,-160.398315,0.004415,0.004382,0.111300,0.049684,0.002531,1.112998,-160.398315,0.112419,0.000000
7.310000,0.026810,-160.442795,0.004613,0.004542,0.115376,0.119255,0.006075,1.153757,-160.442795,0.116408,0.000000
7.550000,0.007446,-160.442795,0.004738,0.004693,0.119200,0.033123,0.001687,1.192003,-160.442795,0.120414,0.000000
7.790000,0.013405,-160.487274,0.004915,0.004858,0.123397,0.059628,0.003038,1.233974,-160.487274,0.124403,0.000000
8.030001,-0.038727,-160.353836,0.005070,0.005010,0.127266,-0.172265,-0.008776,1.272656,-160.353836,0.128410,0.000000
8.270000,-0.003357,-160.442795,0.005247,0.005171,0.131342,-0.014932,-0.000761,1.313415,-160.442795,0.132399,0.000000
8.510000,0.033882,-160.442795,0.005407,0.005327,0.135296,0.150715,0.007678,1.352960,-160.442795,0.136406,0.000000
8.750000,0.020477,-160.442795,0.005579,0.005486,0.139337,0.091088,0.004640,1.393371,-160.442795,0.140395,0.000000
8.990001,-0.004845,-160.487274,0.005730,0.005643,0.143335,-0.021550,-0.001098,1.433351,-160.487274,0.144402,0.000000
9.230000,0.026436,-160.442795,0.005924,0.005801,0.147333,0.117593,0.005990,1.473331,-160.442795,0.148391,0.000000
9.470000,0.046913,-160.487274,0.006066,0.005953,0.151210,0.208680,0.010631,1.512096,-160.487274,0.152398,0.000000
9.710000,0.021965,-160.487274,0.006230,0.006119,0.155433,0.097705,0.004977,1.554328,-160.487274,0.156404,0.000000
9.950001,0.029785,-160.487274,0.006381,0.006270,0.159266,0.132491,0.006749,1.592661,-160.487274,0.160393,0.000000
10.190001,0.688515,-160.531754,0.006558,0.006429,0.163290,3.062666,0.156020,1.632898,-160.531754,0.164383,0.000000
10.430000,0.703407,-160.487274,0.006571,-0.000008,-0.000208,3.128912,0.159394,-0.002082,-160.487274,-0.000034,0.000000
10.670000,0.680321,-160.531754,0.006549,-0.000009,-0.000226,3.026218,0.154163,-0.002256,-160.531754,-0.000034,0.000000
10.910001,0.604729,-160.531754,0.006592,-0.000009,-0.000226,2.689968,0.137033,-0.002256,-160.531754,0.000252,0.000000
11.150001,0.602119,-160.531754,0.006566,-0.000009,-0.000217,2.678361,0.136442,-0.002169,-160.531754,0.000651,0.000000
11.390000,0.771927,-160.576233,0.006562,0.000011,0.000269,3.433702,0.174921,0.002687,-160.576233,0.001050,0.000000
11.630000,0.840073,-160.487274,0.006592,0.000017,0.000425,3.736830,0.190363,0.004250,-160.487274,0.001448,0.000000
11.870001,0.978592,-160.531754,0.006592,0.000035,0.000885,4.352994,0.221752,0.008845,-160.531754,0.001847,0.000000
12.110001,1.199036,-160.576233,0.006622,0.000056,0.001414,5.333577,0.271705,0.014137,-160.576233,0.002246,0.000000
12.350000,1.346870,-160.576233,0.006657,0.000072,0.001830,5.991179,0.305205,0.018300,-160.576233,0.002645,0.000000
12.590000,1.453735,-160.531754,0.006635,0.000086,0.002194,6.466538,0.329421,0.021941,-160.531754,0.003053,0.000000
12.830001,1.588539,-160.487274,0.006674,0.000099,0.002515,7.066175,0.359968,0.025151,-160.487274,0.003451,0.000000
13.070001,1.814568,-160.620712,0.006666,0.000116,0.002957,8.071600,0.411187,0.029571,-160.620712,0.003850,0.000000
13.310000,1.922554,-160.620712,0.006679,0.000128,0.003252,8.551948,0.435657,0.032520,-160.620712,0.004249,0.000000
13.550000,2.103531,-160.576233,0.006704,0.000144,0.003660,9.356973,0.476667,0.036596,-160.576233,0.004648,0.000000
13.790001,2.257690,-160.620712,0.006717,0.000160,0.004059,10.042708,0.511600,0.040585,-160.620712,0.005047,0.000000
14.030001,2.592827,-160.576233,0.006752,0.000187,0.004744,11.533470,0.587543,0.047436,-160.576233,0.005446,0.000000
14.270000,2.613678,-160.665192,0.006752,0.000198,0.005021,11.626221,0.592268,0.050214,-160.665192,0.005845,0.000000
14.510000,2.767471,-160.620712,0.006752,0.000214,0.005446,12.310328,0.627118,0.054461,-160.620712,0.006253,0.000000
14.750001,2.902267,-160.576233,0.006760,0.000228,0.005802,12.909930,0.657663,0.058019,-160.576233,0.006652,0.000000
14.990001,3.014351,-160.665192,0.006778,0.000240,0.006097,13.408503,0.683062,0.060967,-160.665192,0.007051,0.000000
15.230000,3.268311,-160.665192,0.006799,0.000257,0.006530,14.538172,0.740610,0.065305,-160.665192,0.007449,0.000000
15.470000,3.354698,-160.620712,0.006817,0.000270,0.006868,14.922442,0.760185,0.068684,-160.620712,0.007848,0.000000
15.710001,3.549080,-160.709671,0.006855,0.000287,0.007285,15.787096,0.804233,0.072848,-160.709671,0.008247,0.000000
15.950001,3.714409,-160.576233,0.006851,0.000305,0.007744,16.522516,0.841697,0.077443,-160.576233,0.008646,0.000000
16.190001,3.818306,-160.665192,0.006868,0.000320,0.008134,16.984673,0.865240,0.081345,-160.665192,0.009045,0.000000
16.430000,3.895012,-160.665192,0.006885,0.000336,0.008533,17.325878,0.882622,0.085334,-160.665192,0.009453,0.000000
16.670000,4.095352,-160.665192,0.006911,0.000353,0.008967,18.217037,0.928020,0.089672,-160.665192,0.009852,0.000000
16.910002,4.222702,-160.709671,0.006903,0.000371,0.009427,18.783516,0.956878,0.094267,-160.709671,0.010251,0.000000
17.150002,4.359734,-160.665192,0.006903,0.000387,0.009834,19.393063,0.987930,0.098343,-160.665192,0.010650,0.000000
17.390001,4.366806,-160.709671,0.006950,0.000397,0.010086,19.424524,0.989532,0.100860,-160.709671,0.011048,0.000000
17.630001,4.485596,-160.709671,0.006963,0.000413,0.010494,19.952927,1.016451,0.104936,-160.709671,0.011447,0.000000
17.870001,4.622253,-160.665192,0.006972,0.000430,0.010910,20.560810,1.047418,0.109096,-160.665192,0.011846,0.000000
18.110001,4.796898,-160.754150,0.006967,0.000447,0.011352,21.337667,1.086993,0.113520,-160.754150,0.012245,0.000000
18.350000,4.853500,-160.665192,0.006993,0.000464,0.011777,21.589447,1.099819,0.117771,-160.665192,0.012653,0.000000
18.590000,4.939514,-160.754150,0.007019,0.000480,0.012202,21.972055,1.119310,0.122021,-160.754150,0.013052,0.000000
18.830002,5.018463,-160.709671,0.007045,0.000496,0.012592,22.323238,1.137200,0.125923,-160.709671,0.013451,0.000000
19.070002,5.079529,-160.709671,0.007054,0.000511,0.012983,22.594873,1.151038,0.129826,-160.709671,0.013850,0.000000
19.310001,5.233322,-160.754150,0.007067,0.000528,0.013407,23.278980,1.185888,0.134072,-160.754150,0.014249,0.000000
19.550001,5.272789,-160.709671,0.007097,0.000542,0.013763,23.454536,1.194831,0.137630,-160.709671,0.014648,0.000000
19.790001,5.385994,-160.709671,0.007110,0.000560,0.014222,23.958097,1.220484,0.142225,-160.709671,0.015046,0.000000
20.030001,5.493607,-160.709671,0.007127,0.000578,0.014682,24.436783,1.244869,0.146824,-160.709671,0.015445,0.000000
20.270000,5.451530,-160.709671,0.007131,0.000592,0.015038,24.249619,1.235335,0.150378,-160.709671,0.015853,0.000000
20.510000,5.523026,-160.798645,0.007161,0.000606,0.015385,24.567644,1.251535,0.153848,-160.798645,0.016252,0.000000
20.750002,5.623940,-160.754150,0.007161,0.000624,0.015844,25.016533,1.274403,0.158443,-160.754150,0.016651,0.000000
20.990002,5.713676,-160.754150,0.007174,0.000638,0.016217,25.415703,1.294738,0.162171,-160.754150,0.017050,0.000000
21.230001,5.772888,-160.754150,0.007200,0.000653,0.016599,25.679089,1.308155,0.165987,-160.754150,0.017449,0.000000
21.470001,5.741982,-160.798645,0.007213,0.000664,0.016859,25.541609,1.301152,0.168591,-160.798645,0.017848,0.000000
21.710001,5.953117,-160.843124,0.007230,0.000684,0.017371,26.480789,1.348996,0.173708,-160.843124,0.018247,0.000000
21.950001,6.034294,-160.843124,0.007230,0.000700,0.017787,26.841881,1.367391,0.177867,-160.843124,0.018654,0.000000
22.190001,6.083817,-160.798645,0.007261,0.000718,0.018238,27.062168,1.378613,0.182379,-160.798645,0.019053,0.000000
22.430000,6.138184,-160.798645,0.007265,0.000732,0.018602,27.304005,1.390932,0.186020,-160.798645,0.019452,0.000000
22.670002,6.080093,-160.843124,0.007278,0.000742,0.018854,27.045607,1.377769,0.188537,-160.843124,0.019851,0.000000
22.910002,6.294579,-160.843124,0.007299,0.000765,0.019426,27.999683,1.426372,0.194260,-160.843124,0.020250,0.000000
23.150002,6.375389,-160.754150,0.007291,0.000781,0.019825,28.359146,1.444684,0.198249,-160.754150,0.020649,0.000000
23.390001,6.317299,-160.843124,0.007347,0.000791,0.020085,28.100748,1.431520,0.200849,-160.843124,0.021048,0.000000
23.630001,6.302773,-160.843124,0.007355,0.000804,0.020432,28.036133,1.428229,0.204320,-160.843124,0.021447,0.000000
23.870001,6.641258,-160.887604,0.007364,0.000827,0.020996,29.541792,1.504931,0.209956,-160.887604,0.021854,0.000000
24.110001,6.624878,-160.887604,0.007399,0.000841,0.021360,29.468929,1.501219,0.213597,-160.887604,0.022253,0.000000
24.350000,6.711639,-160.843124,0.007377,0.000859,0.021820,29.854862,1.520879,0.218195,-160.843124,0.022652,0.000000
24.590002,6.682220,-160.843124,0.007420,0.000872,0.022140,29.724001,1.514213,0.221405,-160.843124,0.023051,0.000000
24.830002,6.844574,-160.887604,0.007429,0.000890,0.022617,30.446186,1.551003,0.226174,-160.887604,0.023450,0.000000
25.070002,6.835266,-160.887604,0.007446,0.000903,0.022947,30.404781,1.548893,0.229467,-160.887604,0.023849,0.000000
25.310001,6.798775,-160.932083,0.007459,0.000916,0.023276,30.242460,1.540624,0.232763,-160.932083,0.024248,0.000000
25.550001,7.107094,-160.887604,0.007472,0.000939,0.023849,31.613932,1.610491,0.238486,-160.887604,0.024646,0.000000
25.790001,7.124596,-160.976562,0.007506,0.000954,0.024231,31.691784,1.614456,0.242305,-160.976562,0.025054,0.000000
26.030001,7.081779,-160.887604,0.007506,0.000967,0.024569,31.501328,1.604754,0.245685,-160.887604,0.025453,0.000000
26.270000,7.098160,-160.932083,0.007524,0.000983,0.024967,31.574192,1.608466,0.249674,-160.932083,0.025852,0.000000
26.510002,7.081032,-160.932083,0.007532,0.000995,0.025271,31.498003,1.604585,0.252710,-160.932083,0.026251,0.000000
26.750002,7.173752,-161.021042,0.007532,0.001011,0.025679,31.910442,1.625595,0.256786,-161.021042,0.026650,0.000000
26.990002,7.244133,-160.976562,0.007549,0.001026,0.026069,32.223515,1.641544,0.260688,-160.976562,0.027049,0.000000
27.230001,7.262001,-160.932083,0.007575,0.001040,0.026425,32.302994,1.645593,0.264246,-160.932083,0.027448,0.000000
27.470001,7.460106,-160.976562,0.007580,0.001060,0.026927,33.184208,1.690484,0.269273,-160.976562,0.027847,0.000000
27.710001,7.706619,-160.976562,0.007614,0.001082,0.027474,34.280754,1.746345,0.274738,-160.976562,0.028254,0.000000
27.950001,7.603470,-160.976562,0.007640,0.001094,0.027795,33.821922,1.722971,0.277948,-160.976562,0.028653,0.000000
28.190001,7.636986,-161.065521,0.007640,0.001109,0.028176,33.971008,1.730566,0.281763,-161.065521,0.029052,0.000000
28.430002,7.599747,-160.976562,0.007666,0.001122,0.028489,33.805363,1.722127,0.284885,-160.976562,0.029451,0.000000
28.670002,7.690231,-161.021042,0.007687,0.001137,0.028870,34.207859,1.742631,0.288700,-161.021042,0.029850,0.000000
28.910002,7.678314,-161.021042,0.007687,0.001148,0.029147,34.154846,1.739931,0.291475,-161.021042,0.030249,0.000000
29.150002,7.877167,-161.021042,0.007726,0.001168,0.029659,35.039387,1.784992,0.296592,-161.021042,0.030648,0.000000
29.390001,7.910301,-161.021042,0.007726,0.001183,0.030058,35.186779,1.792500,0.300581,-161.021042,0.031047,0.000000
29.630001,8.205971,-161.021042,0.007726,0.001208,0.030683,36.501980,1.859500,0.306826,-161.021042,0.031454,0.000000
29.870001,8.113251,-161.065521,0.007756,0.001221,0.031021,36.089542,1.838489,0.310206,-161.065521,0.031853,0.000000
30.110001,8.057388,-161.065521,0.007800,0.001234,0.031350,35.841053,1.825830,0.313503,-161.065521,0.032252,0.000000
30.350002,8.014198,-161.065521,0.007782,0.001246,0.031654,35.648933,1.816043,0.316538,-161.065521,0.032651,0.000000
30.590002,8.222725,-161.110001,0.007800,0.001263,0.032079,36.576508,1.863296,0.320789,-161.110001,0.033050,0.000000
30.830002,8.323265,-161.021042,0.007834,0.001279,0.032495,37.023731,1.886079,0.324948,-161.021042,0.033449,0.000000
31.070002,8.341141,-161.065521,0.007847,0.001294,0.032868,37.103249,1.890129,0.328680,-161.065521,0.033848,0.000000
31.310001,8.446892,-161.065521,0.007843,0.001311,0.033293,37.573650,1.914093,0.332927,-161.065521,0.034247,0.000000
31.550001,8.665100,-161.065521,0.007873,0.001333,0.033857,38.544289,1.963540,0.338566,-161.065521,0.034654,0.000000
31.790001,8.454338,-161.110001,0.007899,0.001341,0.034056,37.606773,1.915780,0.340561,-161.110001,0.035053,0.000000
32.030003,8.611855,-161.065521,0.007903,0.001360,0.034550,38.307442,1.951474,0.345504,-161.065521,0.035452,0.000000
32.270000,8.507591,-161.065521,0.007899,0.001372,0.034837,37.843655,1.927848,0.348366,-161.065521,0.035851,0.000000
32.510002,8.825966,-161.065521,0.007933,0.001392,0.035366,39.259857,1.999992,0.353657,-161.065521,0.036250,0.000000
32.750000,8.868050,-161.065521,0.007942,0.001409,0.035782,39.447056,2.009529,0.357816,-161.065521,0.036649,0.000000
32.990002,8.692657,-161.198959,0.007963,0.001415,0.035947,38.666870,1.969784,0.359467,-161.198959,0.037048,0.000000
33.230003,8.915710,-161.065521,0.007972,0.001437,0.036493,39.659061,2.020329,0.364928,-161.065521,0.037447,0.000000
33.470001,9.184937,-161.154480,0.008006,0.001459,0.037065,40.856640,2.081336,0.370655,-161.154480,0.037855,0.000000
33.710003,9.138390,-161.198959,0.008002,0.001474,0.037438,40.649586,2.070789,0.374383,-161.198959,0.038254,0.000000
33.950001,9.122749,-161.154480,0.007998,0.001487,0.037768,40.580017,2.067245,0.377676,-161.154480,0.038652,0.000000
34.190002,9.087746,-161.110001,0.008028,0.001501,0.038115,40.424313,2.059313,0.381146,-161.110001,0.039051,0.000000
34.430000,9.238556,-161.154480,0.008071,0.001517,0.038540,41.095150,2.093487,0.385397,-161.154480,0.039450,0.000000
34.670002,9.214355,-161.154480,0.008063,0.001530,0.038860,40.987499,2.088003,0.388603,-161.154480,0.039849,0.000000
34.910000,9.257545,-161.198959,0.008067,0.001544,0.039207,41.179619,2.097790,0.392073,-161.198959,0.040248,0.000000
35.150002,9.395325,-161.110001,0.008071,0.001561,0.039650,41.792492,2.129011,0.396498,-161.110001,0.040655,0.000000
35.390003,9.857811,-161.198959,0.008110,0.001588,0.040326,43.849731,2.233812,0.403262,-161.198959,0.041054,0.000000
35.630001,9.686150,-161.154480,0.008119,0.001599,0.040604,43.086143,2.194913,0.406036,-161.154480,0.041453,0.000000
35.870003,9.688385,-161.198959,0.008144,0.001615,0.041020,43.096088,2.195419,0.410199,-161.198959,0.041852,0.000000
36.110001,9.681679,-161.243454,0.008162,0.001627,0.041332,43.066257,2.193900,0.413322,-161.243454,0.042251,0.000000
36.350002,9.803818,-161.154480,0.008175,0.001646,0.041800,43.609558,2.221577,0.418004,-161.154480,0.042650,0.000000
36.590000,9.849617,-161.243454,0.008179,0.001661,0.042182,43.813286,2.231955,0.421819,-161.243454,0.043049,0.000000
36.830002,9.793022,-161.243454,0.008188,0.001670,0.042416,43.561539,2.219131,0.424162,-161.243454,0.043448,0.000000
37.070004,10.124802,-161.198959,0.008209,0.001693,0.043015,45.037369,2.294313,0.430146,-161.198959,0.043856,0.000000
37.310001,10.130760,-161.243454,0.008244,0.001706,0.043344,45.063873,2.295663,0.433439,-161.243454,0.044255,0.000000
37.550003,10.178795,-161.198959,0.008257,0.001721,0.043726,45.277542,2.306548,0.437258,-161.198959,0.044653,0.000000
37.790001,10.343758,-161.287933,0.008222,0.001739,0.044168,46.011333,2.343929,0.441678,-161.287933,0.045052,0.000000
38.030003,10.414879,-161.243454,0.008282,0.001753,0.044532,46.327694,2.360045,0.445319,-161.243454,0.045451,0.000000
38.270000,10.569420,-161.287933,0.008287,0.001772,0.045001,47.015129,2.395065,0.450005,-161.287933,0.045850,0.000000
38.510002,10.650223,-161.287933,0.008321,0.001787,0.045399,47.374557,2.413375,0.453994,-161.287933,0.046249,0.000000
38.750000,10.604050,-161.243454,0.008313,0.001799,0.045694,47.169170,2.402912,0.456943,-161.243454,0.046648,0.000000
38.990002,10.695648,-161.332413,0.008321,0.001816,0.046136,47.576618,2.423668,0.461364,-161.332413,0.047056,0.000000
39.230003,10.763054,-161.287933,0.008360,0.001830,0.046483,47.876453,2.438943,0.464834,-161.287933,0.047455,0.000000
39.470001,10.925407,-161.332413,0.008347,0.001846,0.046900,48.598640,2.475733,0.468998,-161.332413,0.047854,0.000000
39.710003,11.084404,-161.287933,0.008399,0.001865,0.047368,49.305893,2.511762,0.473680,-161.287933,0.048252,0.000000
39.950001,11.196495,-161.243454,0.008399,0.001880,0.047758,49.804497,2.537162,0.477582,-161.243454,0.048651,0.000000
40.190002,11.278786,-161.332413,0.008407,0.001897,0.048192,50.170544,2.555809,0.481919,-161.332413,0.049050,0.000000
40.430000,11.372993,-161.287933,0.008455,0.001912,0.048573,50.589603,2.577157,0.485734,-161.287933,0.049449,0.000000
40.670002,11.553596,-161.287933,0.008420,0.001929,0.049007,51.392963,2.618082,0.490068,-161.287933,0.049848,0.000000
40.910004,11.611313,-161.332413,0.008455,0.001945,0.049414,51.649700,2.631161,0.494145,-161.332413,0.050256,0.000000
41.150002,11.687279,-161.332413,0.008464,0.001961,0.049805,51.987614,2.648375,0.498047,-161.332413,0.050655,0.000000
41.390003,11.871231,-161.376892,0.008468,0.001978,0.050247,52.805874,2.690059,0.502471,-161.376892,0.051054,0.000000
41.630001,11.864899,-161.332413,0.008494,0.001993,0.050611,52.777706,2.688624,0.506112,-161.332413,0.051453,0.000000
41.870003,11.891342,-161.332413,0.008511,0.002008,0.050993,52.895332,2.694617,0.509928,-161.332413,0.051852,0.000000
42.110001,12.147903,-161.376892,0.008524,0.002025,0.051435,54.036572,2.752754,0.514352,-161.376892,0.052250,0.000000
42.350002,12.237648,-161.332413,0.008511,0.002040,0.051825,54.435776,2.773091,0.518254,-161.332413,0.052649,0.000000
42.590000,12.313240,-161.421371,0.008563,0.002055,0.052190,54.772026,2.790220,0.521895,-161.421371,0.053048,0.000000
42.830002,12.153114,-161.421371,0.008567,0.002063,0.052406,54.059753,2.753935,0.524064,-161.421371,0.053456,0.000000
43.070004,12.588417,-161.376892,0.008571,0.002084,0.052927,55.996075,2.852576,0.529268,-161.376892,0.053855,0.000000
43.310001,12.678162,-161.421371,0.008593,0.002099,0.053308,56.395279,2.872912,0.533084,-161.421371,0.054254,0.000000
43.550003,12.930634,-161.376892,0.008619,0.002118,0.053803,57.518330,2.930124,0.538027,-161.376892,0.054653,0.000000
43.790001,12.997658,-161.465851,0.008645,0.002133,0.054184,57.816471,2.945312,0.541842,-161.465851,0.055052,0.000000
44.030003,13.072876,-161.421371,0.008679,0.002150,0.054618,58.151058,2.962356,0.546179,-161.421371,0.055451,0.000000
44.270000,13.257576,-161.465851,0.008636,0.002164,0.054956,58.972645,3.004210,0.549563,-161.465851,0.055850,0.000000
44.510002,13.510788,-161.421371,0.008666,0.002183,0.055451,60.098988,3.061589,0.554506,-161.421371,0.056248,0.000000
44.750004,13.252357,-161.465851,0.008692,0.002190,0.055624,58.949429,3.003027,0.556240,-161.465851,0.056656,0.000000
44.990002,13.529030,-161.421371,0.008705,0.002209,0.056118,60.180130,3.065722,0.561183,-161.421371,0.057055,0.000000
45.230003,13.918533,-161.421371,0.008709,0.002226,0.056552,61.912727,3.153985,0.565520,-161.421371,0.057454,0.000000
45.470001,14.023544,-161.421371,0.008731,0.002244,0.056985,62.379841,3.177781,0.569854,-161.421371,0.057853,0.000000
45.710003,14.233932,-161.465851,0.008757,0.002259,0.057384,63.315693,3.225455,0.573843,-161.465851,0.058252,0.000000
45.950001,14.262978,-161.465851,0.008765,0.002274,0.057766,63.444893,3.232037,0.577658,-161.465851,0.058650,0.000000
46.190002,14.626785,-161.421371,0.008791,0.002293,0.058252,65.063187,3.314477,0.582518,-161.421371,0.059049,0.000000
46.430000,14.519173,-161.465851,0.008795,0.002305,0.058538,64.584503,3.290092,0.585379,-161.465851,0.059448,0.000000
46.670002,14.529228,-161.465851,0.008795,0.002317,0.058859,64.629234,3.292370,0.588585,-161.465851,0.059856,0.000000
46.910004,15.236359,-161.510330,0.008834,0.002340,0.059448,67.774712,3.452608,0.594482,-161.510330,0.060255,0.000000
47.150002,15.252747,-161.465851,0.008843,0.002355,0.059821,67.847603,3.456322,0.598214,-161.465851,0.060654,0.000000
47.390003,15.337646,-161.510330,0.008856,0.002371,0.060212,68.225258,3.475560,0.602116,-161.510330,0.061053,0.000000
47.630001,15.363708,-161.510330,0.008882,0.002383,0.060533,68.341187,3.481466,0.605326,-161.510330,0.061452,0.000000
47.870003,15.310463,-161.510330,0.008890,0.002394,0.060819,68.104340,3.469400,0.608187,-161.510330,0.061850,0.000000
48.110001,15.708900,-161.554810,0.008912,0.002414,0.061322,69.876678,3.559688,0.613217,-161.554810,0.062249,0.000000
48.350002,15.985573,-161.554810,0.008890,0.002429,0.061686,71.107376,3.622383,0.616858,-161.554810,0.062657,0.000000
48.590004,16.040314,-161.599289,0.008929,0.002442,0.062024,71.350876,3.634787,0.620242,-161.599289,0.063056,0.000000
48.830002,16.764206,-161.554810,0.008933,0.002465,0.062614,74.570915,3.798823,0.626139,-161.554810,0.063455,0.000000
49.070004,16.934380,-161.510330,0.008951,0.002482,0.063047,75.327881,3.837385,0.630473,-161.510330,0.063854,0.000000
49.310001,16.893417,-161.554810,0.008955,0.002496,0.063394,75.145676,3.828103,0.633943,-161.554810,0.064253,0.000000
49.550003,17.086304,-161.554810,0.008981,0.002511,0.063776,76.003677,3.871812,0.637759,-161.554810,0.064652,0.000000
49.790001,17.046837,-161.554810,0.009020,0.002524,0.064114,75.828117,3.862868,0.641142,-161.554810,0.065051,0.000000
50.030003,17.351067,-161.554810,0.009007,0.002539,0.064478,77.181396,3.931808,0.644783,-161.554810,0.065450,0.000000
50.270004,17.260574,-161.554810,0.009024,0.002550,0.064773,76.778870,3.911302,0.647732,-161.554810,0.065857,0.000000
50.510002,17.910370,-161.554810,0.009037,0.002569,0.065259,79.669304,4.058548,0.652588,-161.554810,0.066256,0.000000
50.750004,18.211617,-161.554810,0.009046,0.002587,0.065710,81.009315,4.126811,0.657099,-161.554810,0.066655,0.000000
50.990002,18.871460,-161.599289,0.009054,0.002609,0.066265,83.944443,4.276334,0.662648,-161.599289,0.067054,0.000000
51.230003,18.827522,-161.643784,0.009110,0.002623,0.066620,83.749001,4.266378,0.666202,-161.643784,0.067453,0.000000
51.470001,18.891945,-161.599289,0.009089,0.002636,0.066950,84.035568,4.280976,0.669499,-161.599289,0.067852,0.000000
51.710003,18.845024,-161.643784,0.009123,0.002647,0.067227,83.826851,4.270344,0.672273,-161.643784,0.068251,0.000000
51.950001,19.183510,-161.599289,0.009145,0.002664,0.067661,85.332512,4.347045,0.676611,-161.599289,0.068650,0.000000
52.190002,19.508217,-161.643784,0.009149,0.002678,0.068025,86.776886,4.420625,0.680252,-161.643784,0.069057,0.000000
52.430004,19.696640,-161.643784,0.009149,0.002692,0.068372,87.615028,4.463323,0.683722,-161.643784,0.069456,0.000000
52.670002,20.331535,-161.643784,0.009166,0.002714,0.068927,90.439186,4.607192,0.689271,-161.643784,0.069855,0.000000
52.910004,21.009254,-161.688263,0.009158,0.002733,0.069430,93.453835,4.760765,0.694301,-161.688263,0.070254,0.000000
53.150002,20.745613,-161.599289,0.009179,0.002743,0.069673,92.281097,4.701023,0.696731,-161.599289,0.070653,0.000000
53.390003,21.167137,-161.643784,0.009214,0.002761,0.070124,94.156128,4.796542,0.701239,-161.643784,0.071052,0.000000
53.630001,21.080002,-161.688263,0.009240,0.002772,0.070410,93.768532,4.776796,0.704100,-161.688263,0.071451,0.000000
53.870003,21.842247,-161.688263,0.009248,0.002793,0.070939,97.159164,4.949524,0.709392,-161.688263,0.071850,0.000000
54.110004,22.160629,-161.688263,0.009244,0.002808,0.071312,98.575401,5.021670,0.713120,-161.688263,0.072257,0.000000
54.350002,21.971832,-161.643784,0.009287,0.002820,0.071616,97.735588,4.978889,0.716155,-161.643784,0.072656,0.000000
54.590004,22.611938,-161.688263,0.009270,0.002837,0.072067,100.582924,5.123938,0.720667,-161.688263,0.073055,0.000000
54.830002,23.578995,-161.732742,0.009309,0.002860,0.072656,104.884605,5.343077,0.726564,-161.732742,0.073454,0.000000
55.070004,23.661285,-161.732742,0.009296,0.002874,0.072994,105.250656,5.361724,0.729944,-161.732742,0.073853,0.000000
55.310001,23.742462,-161.777222,0.009304,0.002888,0.073350,105.611748,5.380119,0.733501,-161.777222,0.074252,0.000000
55.550003,23.851196,-161.732742,0.009317,0.002902,0.073706,106.095421,5.404758,0.737055,-161.732742,0.074651,0.000000
55.790001,24.351295,-161.777222,0.009313,0.002916,0.074061,108.319969,5.518083,0.740613,-161.777222,0.075050,0.000000
56.030003,24.495033,-161.821701,0.009360,0.002928,0.074382,108.959351,5.550654,0.743819,-161.821701,0.075458,0.000000
56.270004,24.906128,-161.732742,0.009386,0.002947,0.074850,110.787987,5.643809,0.748505,-161.732742,0.075856,0.000000
56.510002,25.404366,-161.777222,0.009386,0.002960,0.075188,113.004265,5.756711,0.751885,-161.777222,0.076255,0.000000
56.750004,26.816025,-161.732742,0.009408,0.002989,0.075917,119.283638,6.076598,0.759170,-161.732742,0.076654,0.000000
56.990002,26.603027,-161.777222,0.009403,0.002999,0.076168,118.336174,6.028332,0.761684,-161.777222,0.077053,0.000000
57.230003,27.059189,-161.777222,0.009447,0.003017,0.076637,120.365280,6.131700,0.766369,-161.777222,0.077452,0.000000
57.470001,27.042427,-161.732742,0.009468,0.003027,0.076880,120.290726,6.127902,0.768795,-161.732742,0.077851,0.000000
57.710003,27.600243,-161.866180,0.009468,0.003046,0.077365,122.772011,6.254304,0.773651,-161.866180,0.078250,0.000000
57.950005,28.070549,-161.821701,0.009464,0.003061,0.077747,124.864037,6.360878,0.777470,-161.821701,0.078657,0.000000
58.190002,28.414253,-161.777222,0.009481,0.003075,0.078094,126.392914,6.438762,0.780937,-161.777222,0.079056,0.000000
58.430004,29.141495,-161.821701,0.009511,0.003092,0.078536,129.627838,6.603557,0.785362,-161.821701,0.079455,0.000000
58.670002,29.491898,-161.821701,0.009520,0.003109,0.078978,131.186508,6.682960,0.789783,-161.821701,0.079854,0.000000
58.910004,29.821815,-161.866180,0.009511,0.003121,0.079273,132.654068,6.757720,0.792731,-161.866180,0.080253,0.000000
59.150002,30.515175,-161.777222,0.009520,0.003139,0.079733,135.738281,6.914837,0.797330,-161.777222,0.080652,0.000000
59.390003,30.855896,-161.777222,0.009520,0.003153,0.080097,137.253876,6.992046,0.800971,-161.777222,0.081051,0.000000
59.630001,31.596542,-161.910660,0.009576,0.003172,0.080565,140.548447,7.159879,0.805653,-161.910660,0.081450,0.000000
59.870003,32.129784,-161.821701,0.009550,0.003188,0.080973,142.920410,7.280713,0.809729,-161.821701,0.081857,0.000000
60.110004,32.200905,-161.821701,0.009563,0.003200,0.081268,143.236786,7.296830,0.812678,-161.821701,0.082256,0.000000
60.350002,33.006348,-161.866180,0.009589,0.003218,0.081745,146.819565,7.479345,0.817446,-161.866180,0.082655,0.000000
60.590004,33.190674,-161.821701,0.009615,0.003232,0.082083,147.639496,7.521114,0.820830,-161.821701,0.083054,0.000000
60.830002,34.075058,-161.910660,0.009628,0.003250,0.082560,151.573425,7.721519,0.825599,-161.910660,0.083453,0.000000
61.070004,34.650002,-161.821701,0.009653,0.003266,0.082950,154.130905,7.851803,0.829501,-161.821701,0.083852,0.000000
61.310001,35.093864,-161.910660,0.009653,0.003279,0.083297,156.105301,7.952384,0.832972,-161.910660,0.084251,0.000000
61.550003,35.910477,-161.910660,0.009675,0.003299,0.083800,159.737778,8.137430,0.838002,-161.910660,0.084659,0.000000
61.790005,36.243752,-161.821701,0.009688,0.003311,0.084104,161.220261,8.212952,0.841038,-161.821701,0.085058,0.000000
62.030003,37.062225,-161.999619,0.009692,0.003329,0.084555,164.861008,8.398420,0.845546,-161.999619,0.085456,0.000000
62.270004,37.602539,-161.910660,0.009697,0.003345,0.084953,167.264450,8.520857,0.849535,-161.910660,0.085855,0.000000
62.510002,38.233337,-161.910660,0.009705,0.003361,0.085379,170.070374,8.663797,0.853785,-161.910660,0.086254,0.000000
62.750004,38.995956,-161.866180,0.009727,0.003378,0.085795,173.462677,8.836610,0.857949,-161.866180,0.086653,0.000000
62.990002,39.354179,-161.910660,0.009744,0.003392,0.086150,175.056137,8.917785,0.861503,-161.910660,0.087052,0.000000
63.230003,39.947739,-161.955139,0.009740,0.003407,0.086549,177.696411,9.052287,0.865492,-161.955139,0.087451,0.000000
63.470001,40.800476,-161.910660,0.009766,0.003426,0.087026,181.489578,9.245520,0.870261,-161.910660,0.087859,0.000000
63.710003,41.371696,-161.910660,0.009757,0.003441,0.087391,184.030502,9.374961,0.873906,-161.910660,0.088258,0.000000
63.950005,41.886314,-161.999619,0.009753,0.003455,0.087746,186.319626,9.491574,0.877460,-161.999619,0.088657,0.000000
64.190002,42.075478,-161.955139,0.009791,0.003464,0.087997,187.161072,9.534439,0.879973,-161.955139,0.089056,0.000000
64.430000,43.183289,-161.955139,0.009766,0.003483,0.088457,192.088867,9.785473,0.884572,-161.955139,0.089454,0.000000
64.670006,43.961174,-161.955139,0.009817,0.003499,0.088873,195.549072,9.961744,0.888735,-161.955139,0.089853,0.000000
64.910004,44.904762,-161.955139,0.009800,0.003517,0.089342,199.746353,10.175564,0.893417,-161.955139,0.090252,0.000000
65.150002,45.566101,-161.955139,0.009826,0.003532,0.089723,202.688141,10.325426,0.897232,-161.955139,0.090651,0.000000
65.389999,46.386810,-161.955139,0.009830,0.003550,0.090166,206.338837,10.511402,0.901657,-161.955139,0.091059,0.000000
65.630005,46.998611,-162.044098,0.009835,0.003562,0.090486,209.060272,10.650038,0.904862,-162.044098,0.091458,0.000000
65.870003,48.127647,-161.955139,0.009860,0.003582,0.090989,214.082474,10.905881,0.909893,-161.955139,0.091857,0.000000
66.110001,48.037903,-161.955139,0.009852,0.003589,0.091172,213.683258,10.885544,0.911717,-161.955139,0.092256,0.000000
66.350006,48.879097,-161.999619,0.009869,0.003609,0.091674,217.425079,11.076161,0.916743,-161.999619,0.092655,0.000000
66.590004,50.094894,-161.999619,0.009886,0.003625,0.092082,222.833221,11.351665,0.920820,-161.999619,0.093054,0.000000
66.830002,50.941292,-162.088593,0.009891,0.003643,0.092542,226.598190,11.543462,0.925418,-162.088593,0.093452,0.000000
67.070000,51.875946,-161.999619,0.009912,0.003658,0.092915,230.755737,11.755257,0.929146,-161.999619,0.093851,0.000000
67.310005,52.573402,-161.999619,0.009925,0.003675,0.093348,233.858170,11.913303,0.933484,-161.999619,0.094259,0.000000
67.550003,53.578064,-162.088593,0.009929,0.003692,0.093773,238.327133,12.140964,0.937730,-162.088593,0.094658,0.000000
67.790001,54.107208,-162.044098,0.009912,0.003703,0.094059,240.680878,12.260869,0.940592,-162.044098,0.095056,0.000000
68.030006,54.551071,-162.044098,0.009947,0.003716,0.094398,242.655289,12.361450,0.943976,-162.044098,0.095455,0.000000
68.270004,56.222656,-162.044098,0.009951,0.003740,0.095005,250.090866,12.740236,0.950046,-162.044098,0.095854,0.000000
68.510002,57.011337,-162.044098,0.009960,0.003754,0.095352,253.599091,12.918953,0.953517,-162.044098,0.096253,0.000000
68.750000,57.692780,-162.088593,0.009977,0.003770,0.095750,256.630310,13.073371,0.957503,-162.088593,0.096652,0.000000
68.990005,58.308311,-161.999619,0.009994,0.003782,0.096054,259.368317,13.212852,0.960538,-161.999619,0.097051,0.000000
69.230003,58.854210,-162.088593,0.009985,0.003795,0.096401,261.796600,13.336555,0.964009,-162.088593,0.097459,0.000000
69.470001,60.188049,-162.133072,0.009994,0.003815,0.096904,267.729828,13.638807,0.969039,-162.133072,0.097858,0.000000
69.710007,60.991631,-162.088593,0.010003,0.003827,0.097199,271.304321,13.820901,0.971988,-162.088593,0.098257,0.000000
69.950005,61.611252,-162.088593,0.009994,0.003841,0.097554,274.060547,13.961309,0.975542,-162.088593,0.098656,0.000000
70.190002,63.480194,-162.088593,0.010007,0.003865,0.098161,282.373993,14.384817,0.981613,-162.088593,0.099054,0.000000
70.430000,64.630829,-162.133072,0.009998,0.003881,0.098569,287.492279,14.645555,0.985689,-162.133072,0.099453,0.000000
70.670006,65.145065,-162.133072,0.010033,0.003893,0.098872,289.779724,14.762082,0.988724,-162.133072,0.099852,0.000000
70.910004,66.297195,-162.177551,0.010054,0.003910,0.099306,294.904663,15.023159,0.993062,-162.177551,0.100251,0.000000
71.150002,66.865051,-162.133072,0.010024,0.003923,0.099635,297.430603,15.151837,0.996355,-162.133072,0.100659,0.000000
71.390007,67.103745,-162.133072,0.010076,0.003922,0.099627,298.492371,15.205926,0.996271,-162.133072,0.099861,0.000000
71.630005,66.444656,-162.177551,0.010046,0.003922,0.099627,295.560608,15.056574,0.996271,-162.177551,0.099861,0.000000
71.870003,65.939346,-162.177551,0.010059,0.003918,0.099506,293.312866,14.942069,0.995056,-162.177551,0.099627,0.000000
72.110001,65.430313,-162.177551,0.010089,0.003917,0.099480,291.048584,14.826720,0.994795,-162.177551,0.099627,0.000000
72.350006,64.968185,-162.222031,0.010072,0.003916,0.099462,288.992920,14.722001,0.994621,-162.222031,0.099627,0.000000
72.590004,64.531403,-162.177551,0.010098,0.003915,0.099453,287.050018,14.623025,0.994534,-162.177551,0.099627,0.000000
72.830002,64.154190,-162.222031,0.010085,0.003915,0.099453,285.372101,14.537547,0.994534,-162.222031,0.099627,0.000000
73.070000,63.811981,-162.222031,0.010106,0.003915,0.099453,283.849884,14.460002,0.994534,-162.222031,0.099627,0.000000
73.310005,63.507370,-162.266510,0.010050,0.003915,0.099445,282.494904,14.390976,0.994447,-162.266510,0.099627,0.000000
73.550003,63.205750,-162.222031,0.010080,0.003915,0.099445,281.153229,14.322627,0.994447,-162.222031,0.099627,0.000000
73.790001,62.942490,-162.222031,0.010098,0.003915,0.099445,279.982178,14.262972,0.994447,-162.222031,0.099627,0.000000
74.030006,62.708267,-162.177551,0.010089,0.003915,0.099436,278.940308,14.209896,0.994360,-162.177551,0.099627,0.000000
74.270004,62.472183,-162.222031,0.010080,0.003915,0.099436,277.890137,14.156399,0.994360,-162.222031,0.099627,0.000000
74.510002,62.250244,-162.222031,0.010089,0.003915,0.099436,276.902924,14.106108,0.994360,-162.222031,0.099627,0.000000
74.750000,62.046188,-162.222031,0.010123,0.003915,0.099436,275.995239,14.059867,0.994360,-162.222031,0.099627,0.000000
74.990005,61.871170,-162.222031,0.010102,0.003915,0.099436,275.216705,14.020207,0.994360,-162.222031,0.099627,0.000000
75.230003,61.676422,-162.355469,0.010102,0.003915,0.099436,274.350433,13.976077,0.994360,-162.355469,0.099627,0.000000
75.470001,61.514809,-162.177551,0.010111,0.003915,0.099436,273.631531,13.939455,0.994360,-162.177551,0.099627,0.000000
75.710007,61.353943,-162.266510,0.010102,0.003915,0.099436,272.915955,13.903003,0.994360,-162.266510,0.099627,0.000000
75.950005,61.213188,-162.310989,0.010102,0.003915,0.099436,272.289856,13.871107,0.994360,-162.310989,0.099627,0.000000
76.190002,61.059029,-162.310989,0.010119,0.003915,0.099436,271.604126,13.836173,0.994360,-162.310989,0.099627,0.000000
76.430000,60.935768,-162.310989,0.010111,0.003915,0.099436,271.055847,13.808243,0.994360,-162.310989,0.099627,0.000000
76.670006,60.787941,-162.310989,0.010093,0.003914,0.099428,270.398254,13.774744,0.994277,-162.310989,0.099627,0.000000
76.910004,60.662453,-162.355469,0.010076,0.003914,0.099428,269.840057,13.746308,0.994277,-162.355469,0.099627,0.000000
77.150002,60.551109,-162.399948,0.010102,0.003914,0.099428,269.344788,13.721077,0.994277,-162.399948,0.099627,0.000000
77.390007,60.440514,-162.310989,0.010093,0.003914,0.099428,268.852844,13.696016,0.994277,-162.310989,0.099627,0.000000
77.630005,60.313164,-162.355469,0.010111,0.003914,0.099428,268.286346,13.667158,0.994277,-162.355469,0.099627,0.000000
77.870003,60.221191,-162.310989,0.010123,0.003914,0.099428,267.877228,13.646317,0.994277,-162.310989,0.099627,0.000000
78.110001,60.128838,-162.310989,0.010106,0.003914,0.099428,267.466431,13.625389,0.994277,-162.310989,0.099627,0.000000
78.350006,59.998138,-162.355469,0.010089,0.003914,0.099428,266.885040,13.595773,0.994277,-162.355469,0.099627,0.000000
78.590004,59.912117,-162.355469,0.010136,0.003914,0.099428,266.502411,13.576280,0.994277,-162.355469,0.099627,0.000000
78.830002,59.826843,-162.444427,0.010128,0.003914,0.099428,266.123077,13.556957,0.994277,-162.444427,0.099627,0.000000
79.070007,59.734123,-162.355469,0.010106,0.003914,0.099428,265.710663,13.535946,0.994277,-162.355469,0.099627,0.000000
79.310005,59.656670,-162.310989,0.010093,0.003914,0.099428,265.366119,13.518394,0.994277,-162.310989,0.099627,0.000000
79.550003,59.568420,-162.399948,0.010111,0.003914,0.099428,264.973572,13.498398,0.994277,-162.399948,0.099627,0.000000
79.790001,59.487244,-162.355469,0.010102,0.003914,0.099428,264.612488,13.480001,0.994277,-162.355469,0.099627,0.000000
80.030006,59.404205,-162.399948,0.010098,0.003914,0.099428,264.243103,13.461185,0.994277,-162.399948,0.099627,0.000000
80.270004,59.332336,-162.399948,0.010132,0.003914,0.099428,263.923401,13.444900,0.994277,-162.399948,0.099627,0.000000
80.510002,59.257858,-162.399948,0.010132,0.003914,0.099428,263.592133,13.428022,0.994277,-162.399948,0.099627,0.000000
80.750008,59.171844,-162.444427,0.010123,0.003914,0.099428,263.209503,13.408532,0.994277,-162.444427,0.099627,0.000000
80.990005,59.102585,-162.399948,0.010123,0.003914,0.099428,262.901428,13.392838,0.994277,-162.399948,0.099627,0.000000
81.230003,59.041885,-162.444427,0.010123,0.003914,0.099428,262.631409,13.379083,0.994277,-162.444427,0.099627,0.000000
81.470001,58.969643,-162.444427,0.010132,0.003914,0.099428,262.310059,13.362713,0.994277,-162.444427,0.099627,0.000000
81.710007,58.914536,-162.399948,0.010123,0.003914,0.099428,262.064941,13.350225,0.994277,-162.399948,0.099627,0.000000
81.950005,58.855698,-162.488907,0.010123,0.003914,0.099428,261.803223,13.336891,0.994277,-162.488907,0.099627,0.000000
82.190002,58.786438,-162.399948,0.010123,0.003914,0.099428,261.495148,13.321198,0.994277,-162.399948,0.099627,0.000000
82.430000,58.721642,-162.488907,0.010128,0.003914,0.099428,261.206909,13.306515,0.994277,-162.488907,0.099627,0.000000
82.670006,58.669144,-162.488907,0.010115,0.003914,0.099428,260.973389,13.294618,0.994277,-162.488907,0.099627,0.000000
82.910004,58.606209,-162.444427,0.010136,0.003914,0.099428,260.693451,13.280356,0.994277,-162.444427,0.099627,0.000000
83.150002,58.559662,-162.533401,0.010145,0.003914,0.099428,260.486389,13.269810,0.994277,-162.533401,0.099627,0.000000
83.390007,58.503433,-162.488907,0.010141,0.003914,0.099428,260.236267,13.257068,0.994277,-162.488907,0.099627,0.000000
83.630005,58.454651,-162.488907,0.010128,0.003914,0.099428,260.019287,13.246013,0.994277,-162.488907,0.099627,0.000000
83.870003,58.413322,-162.488907,0.010093,0.003914,0.099428,259.835449,13.236648,0.994277,-162.488907,0.099627,0.000000
84.110001,58.353737,-162.533401,0.010115,0.003914,0.099428,259.570374,13.223145,0.994277,-162.533401,0.099627,0.000000
84.350006,58.296021,-162.533401,0.010128,0.003914,0.099428,259.313660,13.210067,0.994277,-162.533401,0.099627,0.000000
84.590004,58.272194,-162.533401,0.010123,0.003914,0.099428,259.207672,13.204668,0.994277,-162.533401,0.099627,0.000000
84.830002,58.212242,-162.488907,0.010136,0.003914,0.099428,258.940979,13.191082,0.994277,-162.488907,0.099627,0.000000
85.070007,58.148193,-162.622360,0.010119,0.003914,0.099428,258.656097,13.176569,0.994277,-162.622360,0.099627,0.000000
85.310005,58.116539,-162.533401,0.010128,0.003914,0.099428,258.515289,13.169395,0.994277,-162.533401,0.099627,0.000000
85.550003,58.072975,-162.666840,0.010141,0.003914,0.099428,258.321503,13.159524,0.994277,-162.666840,0.099627,0.000000
85.790001,58.025307,-162.533401,0.010136,0.003914,0.099428,258.109467,13.148723,0.994277,-162.533401,0.099627,0.000000
86.030006,57.991791,-162.577881,0.010132,0.003914,0.099428,257.960358,13.141128,0.994277,-162.577881,0.099627,0.000000
86.270004,57.940033,-162.577881,0.010106,0.003914,0.099428,257.730133,13.129399,0.994277,-162.577881,0.099627,0.000000
86.510002,57.902428,-162.533401,0.010111,0.003914,0.099428,257.562866,13.120878,0.994277,-162.533401,0.099627,0.000000
86.750008,57.850662,-162.577881,0.010136,0.003914,0.099428,257.332611,13.109148,0.994277,-162.577881,0.099627,0.000000
86.990005,57.800026,-162.533401,0.010115,0.003914,0.099428,257.107361,13.097673,0.994277,-162.533401,0.099627,0.000000
87.230003,57.777306,-162.577881,0.010141,0.003914,0.099428,257.006287,13.092525,0.994277,-162.577881,0.099627,0.000000
87.470001,57.737465,-162.622360,0.010123,0.003914,0.099428,256.829071,13.083497,0.994277,-162.622360,0.099627,0.000000
87.710007,57.696503,-162.577881,0.010119,0.003914,0.099428,256.646851,13.074214,0.994277,-162.577881,0.099627,0.000000
87.950005,57.668945,-162.577881,0.010145,0.003914,0.099428,256.524292,13.067970,0.994277,-162.577881,0.099627,0.000000
88.190002,57.633202,-162.577881,0.010154,0.003914,0.099428,256.365295,13.059870,0.994277,-162.577881,0.099627,0.000000
88.430008,57.592239,-162.622360,0.010154,0.003914,0.099428,256.183075,13.050589,0.994277,-162.622360,0.099627,0.000000
88.670006,57.547928,-162.622360,0.010111,0.003914,0.099428,255.985962,13.040546,0.994277,-162.622360,0.099627,0.000000
88.910004,57.514038,-162.622360,0.010145,0.003914,0.099428,255.835220,13.032867,0.994277,-162.622360,0.099627,0.000000
89.150002,57.470848,-162.666840,0.010145,0.003914,0.099428,255.643097,13.023081,0.994277,-162.666840,0.099627,0.000000
89.390007,57.444031,-162.577881,0.010132,0.003914,0.099428,255.523804,13.017004,0.994277,-162.577881,0.099627,0.000000
89.630005,57.410149,-162.666840,0.010123,0.003914,0.099428,255.373093,13.009325,0.994277,-162.666840,0.099627,0.000000
89.870003,57.362854,-162.622360,0.010115,0.003914,0.099428,255.162720,12.998609,0.994277,-162.622360,0.099627,0.000000
90.110001,57.337906,-162.622360,0.010123,0.003914,0.099428,255.051743,12.992955,0.994277,-162.622360,0.099627,0.000000
90.350006,57.298065,-162.711319,0.010111,0.003914,0.099428,254.874527,12.983928,0.994277,-162.711319,0.099627,0.000000
90.590004,57.271629,-162.666840,0.010136,0.003914,0.099428,254.756927,12.977937,0.994277,-162.666840,0.099627,0.000000
90.830002,57.240723,-162.666840,0.010123,0.003914,0.099428,254.619446,12.970934,0.994277,-162.666840,0.099627,0.000000
91.070007,57.222847,-162.666840,0.010149,0.003914,0.099428,254.539932,12.966883,0.994277,-162.666840,0.099627,0.000000
91.310005,57.174812,-162.711319,0.010141,0.003914,0.099428,254.326263,12.955997,0.994277,-162.711319,0.099627,0.000000
91.550003,57.150604,-162.711319,0.010115,0.003914,0.099428,254.218582,12.950512,0.994277,-162.711319,0.099627,0.000000
91.790001,57.121933,-162.666840,0.010123,0.003914,0.099428,254.091049,12.944016,0.994277,-162.666840,0.099627,0.000000
92.030006,57.085815,-162.666840,0.010123,0.003914,0.099428,253.930389,12.935831,0.994277,-162.666840,0.099627,0.000000
92.270004,57.073524,-162.711319,0.010123,0.003914,0.099428,253.875717,12.933045,0.994277,-162.711319,0.099627,0.000000
92.510002,57.031448,-162.711319,0.010115,0.003914,0.099428,253.688553,12.923511,0.994277,-162.711319,0.099627,0.000000
92.750008,56.996819,-162.755798,0.010132,0.003914,0.099428,253.534515,12.915664,0.994277,-162.755798,0.099627,0.000000
92.990005,56.982292,-162.711319,0.010136,0.003914,0.099428,253.469894,12.912373,0.994277,-162.711319,0.099627,0.000000
93.230003,56.946548,-162.711319,0.010115,0.003914,0.099428,253.310898,12.904272,0.994277,-162.711319,0.099627,0.000000
93.470001,56.927185,-162.800278,0.010145,0.003914,0.099428,253.224762,12.899885,0.994277,-162.800278,0.099627,0.000000
93.710007,56.904465,-162.800278,0.010145,0.003914,0.099428,253.123703,12.894735,0.994277,-162.800278,0.099627,0.000000
93.950005,56.874306,-162.800278,0.010145,0.003914,0.099428,252.989548,12.887902,0.994277,-162.800278,0.099627,0.000000
94.190002,56.846748,-162.755798,0.010158,0.003914,0.099428,252.866959,12.881658,0.994277,-162.755798,0.099627,0.000000
94.430008,56.824036,-162.800278,0.010132,0.003914,0.099428,252.765930,12.876511,0.994277,-162.800278,0.099627,0.000000
94.670006,56.799461,-162.800278,0.010145,0.003914,0.099428,252.656616,12.870942,0.994277,-162.800278,0.099627,0.000000
94.910004,56.777489,-162.711319,0.010119,0.003914,0.099428,252.558884,12.865962,0.994277,-162.711319,0.099627,0.000000
95.150002,56.761848,-162.844757,0.010128,0.003914,0.099428,252.489319,12.862418,0.994277,-162.844757,0.099627,0.000000
95.390007,56.723122,-162.800278,0.010145,0.003914,0.099428,252.317047,12.853643,0.994277,-162.800278,0.099627,0.000000
95.630005,56.703758,-162.844757,0.010132,0.003914,0.099428,252.230911,12.849256,0.994277,-162.844757,0.099627,0.000000
95.870003,56.676575,-162.844757,0.010171,0.003914,0.099428,252.110001,12.843096,0.994277,-162.844757,0.099627,0.000000
96.110008,56.662422,-162.800278,0.010162,0.003914,0.099428,252.047043,12.839889,0.994277,-162.800278,0.099627,0.000000
96.350006,56.633751,-162.844757,0.010119,0.003914,0.099428,251.919510,12.833391,0.994277,-162.844757,0.099627,0.000000
96.590004,56.614761,-162.844757,0.010115,0.003914,0.099428,251.835037,12.829089,0.994277,-162.844757,0.099627,0.000000
96.830002,56.595024,-162.844757,0.010136,0.003914,0.099428,251.747238,12.824615,0.994277,-162.844757,0.099627,0.000000
97.070007,56.570450,-162.889236,0.010136,0.003914,0.099428,251.637924,12.819047,0.994277,-162.889236,0.099627,0.000000
97.310005,56.553696,-162.844757,0.010132,0.003914,0.099428,251.563400,12.815250,0.994277,-162.844757,0.099627,0.000000
97.550003,56.510498,-162.933731,0.010119,0.003914,0.099428,251.371246,12.805462,0.994277,-162.933731,0.099627,0.000000
97.790001,56.507149,-162.889236,0.010162,0.003914,0.099428,251.356354,12.804703,0.994277,-162.889236,0.099627,0.000000
98.030006,56.492622,-162.889236,0.010141,0.003914,0.099428,251.291733,12.801412,0.994277,-162.889236,0.099627,0.000000
98.270004,56.446075,-162.889236,0.010149,0.003914,0.099428,251.084686,12.790863,0.994277,-162.889236,0.099627,0.000000
98.510002,56.430435,-162.844757,0.010132,0.003914,0.099428,251.015106,12.787319,0.994277,-162.844757,0.099627,0.000000
98.750008,56.418518,-162.933731,0.010141,0.003914,0.099428,250.962097,12.784619,0.994277,-162.933731,0.099627,0.000000
98.990005,56.404373,-162.889236,0.010136,0.003914,0.099428,250.899185,12.781413,0.994277,-162.889236,0.099627,0.000000
99.230003,56.367134,-162.889236,0.010141,0.003914,0.099428,250.733536,12.772975,0.994277,-162.889236,0.099627,0.000000
99.470001,56.354843,-162.933731,0.010119,0.003914,0.099428,250.678864,12.770190,0.994277,-162.933731,0.099627,0.000000
99.710007,56.330643,-162.933731,0.010132,0.003914,0.099428,250.571213,12.764707,0.994277,-162.933731,0.099627,0.000000
99.950005,56.322449,-162.933731,0.010132,0.003914,0.099428,250.534760,12.762849,0.994277,-162.933731,0.099627,0.000000
100.190002,56.295265,-162.978210,0.010158,0.003914,0.099428,250.413849,12.756689,0.994277,-162.978210,0.099627,0.000000
100.430008,56.269943,-162.933731,0.010132,0.003914,0.099428,250.301208,12.750952,0.994277,-162.933731,0.099627,0.000000
100.670006,56.252068,-162.933731,0.010132,0.003914,0.099428,250.221695,12.746901,0.994277,-162.933731,0.099627,0.000000
100.910004,56.237175,-162.933731,0.010115,0.003914,0.099428,250.155441,12.743526,0.994277,-162.933731,0.099627,0.000000
101.150002,56.216324,-163.022690,0.010123,0.003914,0.099428,250.062698,12.738801,0.994277,-163.022690,0.099627,0.000000
101.390007,56.193977,-162.978210,0.010141,0.003914,0.099428,249.963303,12.733737,0.994277,-162.978210,0.099627,0.000000
101.630005,56.175362,-162.978210,0.010123,0.003914,0.099428,249.880493,12.729519,0.994277,-162.978210,0.099627,0.000000
101.800003,56.160095,-163.022690,0.010154,0.003914,0.099428,249.812576,12.726060,0.994277,-163.022690,0.099627,0.000000