File: Data/Compression Sample NH 10, 12, 15, 17 batch 3/AutoNoheating-15-3-4-240212_02122024_180316.csv
Time (sec),S:Load (lbs),S:HL1 (DIM),S:LVDT (in),S:Position (in),Ch:Position (mm),Ch:Load (N),Ch:Stress (MPa),Ch:Strain (mm/mm),Ch:HL1 (DIM),Set Point (),Cycles ()
0.110000,0.002983,-300.735718,0.000034,-0.000000,-0.000000,0.013269,0.000676,-0.000000,-300.735718,0.000165,0.000000
0.320000,-0.008186,-300.780182,0.000082,-0.000000,-0.000000,-0.036415,-0.001855,-0.000000,-300.780182,0.000165,0.000000
0.530000,-0.028297,-300.824677,0.000030,0.000109,0.002758,-0.125873,-0.006412,0.027581,-300.824677,0.003495,0.000000
0.740000,0.004845,-300.780182,0.000151,0.000237,0.006010,0.021550,0.001098,0.060100,-300.780182,0.006999,0.000000
0.950000,0.013039,-300.869141,0.000259,0.000370,0.009401,0.057999,0.002955,0.094009,-300.869141,0.010502,0.000000
1.160000,-0.008934,-300.780182,0.000461,0.000511,0.012991,-0.039741,-0.002024,0.129913,-300.780182,0.013989,0.000000
1.370000,-0.020851,-300.824677,0.000586,0.000647,0.016425,-0.092750,-0.004725,0.164253,-300.824677,0.017492,0.000000
1.580000,0.001869,-300.780182,0.000664,0.000783,0.019894,0.008315,0.000424,0.198942,-300.780182,0.020996,0.000000
1.790000,-0.009682,-300.869141,0.000815,0.000918,0.023311,-0.043066,-0.002194,0.233112,-300.869141,0.024482,0.000000
2.000000,0.002609,-300.869141,0.001005,0.001059,0.026893,0.011607,0.000591,0.268928,-300.869141,0.027986,0.000000
2.210000,-0.001114,-300.780182,0.001095,0.001196,0.030379,-0.004955,-0.000252,0.303791,-300.780182,0.031489,0.000000
2.420000,-0.009308,-300.869141,0.001285,0.001334,0.033874,-0.041403,-0.002109,0.338741,-300.869141,0.034975,0.000000
2.630000,0.009682,-300.824677,0.001423,0.001470,0.037325,0.043066,0.002194,0.373255,-300.824677,0.038479,0.000000
2.840000,0.032402,-300.869141,0.001565,0.001606,0.040794,0.144131,0.007342,0.407944,-300.869141,0.041982,0.000000
3.050000,0.014900,-300.913635,0.001716,0.001742,0.044237,0.066279,0.003376,0.442375,-300.913635,0.045486,0.000000
3.260000,0.032028,-300.780182,0.001802,0.001884,0.047854,0.142469,0.007258,0.478536,-300.780182,0.048972,0.000000
3.470000,0.027557,-300.913635,0.001979,0.002024,0.051401,0.122581,0.006245,0.514008,-300.913635,0.052476,0.000000
3.680000,0.016762,-300.869141,0.002121,0.002161,0.054878,0.074560,0.003798,0.548783,-300.869141,0.055980,0.000000
3.890000,-0.002228,-300.913635,0.002264,0.002297,0.058347,-0.009910,-0.000505,0.583472,-300.913635,0.059466,0.000000
4.100000,-0.011543,-300.913635,0.002410,0.002436,0.061877,-0.051347,-0.002616,0.618766,-300.913635,0.062969,0.000000
4.310000,-0.018616,-300.869141,0.002557,0.002572,0.065320,-0.082807,-0.004218,0.653197,-300.869141,0.066473,0.000000
4.520000,0.005219,-300.913635,0.002686,0.002714,0.068927,0.023213,0.001183,0.689271,-300.913635,0.069977,0.000000
4.730000,0.006706,-300.869141,0.002850,0.002850,0.072396,0.029831,0.001520,0.723960,-300.869141,0.073463,0.000000
4.940000,0.105385,-300.913635,0.002992,0.002989,0.075917,0.468775,0.023881,0.759170,-300.913635,0.076967,0.000000
5.150000,0.772675,-300.913635,0.003130,-0.000008,-0.000208,3.437028,0.175091,-0.002082,-300.913635,-0.000017,0.000000
5.360000,0.728737,-300.913635,0.003130,-0.000009,-0.000217,3.241584,0.165134,-0.002169,-300.913635,-0.000017,0.000000
5.570000,0.693733,-300.958130,0.003134,-0.000009,-0.000217,3.085880,0.157202,-0.002169,-300.958130,-0.000017,0.000000
5.780000,0.709747,-300.869141,0.003113,-0.000009,-0.000217,3.157114,0.160831,-0.002169,-300.869141,0.000234,0.000000
5.990000,0.641602,-300.913635,0.003143,-0.000009,-0.000217,2.853986,0.145389,-0.002169,-300.913635,0.000581,0.000000
6.200000,0.662827,-300.913635,0.003104,-0.000008,-0.000208,2.948400,0.150199,-0.002082,-300.913635,0.000936,0.000000
6.410000,0.654633,-300.958130,0.003143,-0.000008,-0.000208,2.911951,0.148342,-0.002082,-300.958130,0.001283,0.000000
6.620000,1.130157,-300.958130,0.003134,0.000029,0.000728,5.027192,0.256097,0.007282,-300.958130,0.001630,0.000000
6.830000,1.203140,-300.958130,0.003100,0.000040,0.001006,5.351835,0.272635,0.010060,-300.958130,0.001986,0.000000
7.040000,1.493217,-300.958130,0.003152,0.000060,0.001517,6.642163,0.338368,0.015174,-300.958130,0.002333,0.000000
7.250000,1.696533,-300.958130,0.003160,0.000070,0.001769,7.546556,0.384440,0.017691,-300.958130,0.002680,0.000000
7.460001,1.871178,-300.913635,0.003165,0.000086,0.002194,8.323414,0.424015,0.021941,-300.913635,0.003035,0.000000
7.670001,2.073372,-300.958130,0.003160,0.000098,0.002489,9.222818,0.469833,0.024889,-300.958130,0.003382,0.000000
7.880001,2.275948,-300.958130,0.003203,0.000112,0.002853,10.123920,0.515737,0.028531,-300.958130,0.003729,0.000000
8.090000,2.552986,-300.958130,0.003212,0.000126,0.003191,11.356250,0.578515,0.031914,-300.958130,0.004085,0.000000
8.300000,2.772690,-300.958130,0.003251,0.000141,0.003582,12.333540,0.628300,0.035816,-300.958130,0.004431,0.000000
8.510000,2.974144,-300.958130,0.003277,0.000152,0.003859,13.229653,0.673951,0.038591,-300.958130,0.004787,0.000000
8.720000,3.132027,-301.047089,0.003298,0.000164,0.004171,13.931951,0.709727,0.041713,-301.047089,0.005134,0.000000
8.930000,3.464554,-300.958130,0.003255,0.000181,0.004596,15.411105,0.785079,0.045964,-300.958130,0.005481,0.000000
9.140000,3.781448,-301.002594,0.003303,0.000199,0.005056,16.820723,0.856888,0.050559,-301.002594,0.005836,0.000000
9.350000,3.891670,-300.958130,0.003251,0.000209,0.005316,17.311014,0.881865,0.053159,-300.958130,0.006183,0.000000
9.560000,4.077484,-301.002594,0.003272,0.000223,0.005672,18.137556,0.923971,0.056717,-301.002594,0.006530,0.000000
9.770000,4.306488,-301.091553,0.003324,0.000237,0.006018,19.156216,0.975864,0.060184,-301.091553,0.006886,0.000000
9.980000,4.646095,-301.047089,0.003380,0.000254,0.006452,20.666864,1.052820,0.064521,-301.047089,0.007233,0.000000
10.190001,4.820366,-301.002594,0.003363,0.000266,0.006764,21.442059,1.092311,0.067644,-301.002594,0.007580,0.000000
10.400001,4.866539,-301.047089,0.003320,0.000275,0.006973,21.647446,1.102774,0.069725,-301.047089,0.007935,0.000000
10.610001,5.097038,-301.002594,0.003410,0.000289,0.007337,22.672758,1.155005,0.073366,-301.002594,0.008282,0.000000
10.820001,5.358818,-301.091553,0.003367,0.000303,0.007701,23.837214,1.214326,0.077007,-301.091553,0.008638,0.000000
11.030001,5.698418,-301.002594,0.003389,0.000321,0.008152,25.347828,1.291280,0.081519,-301.002594,0.008984,0.000000
11.240001,5.816460,-301.047089,0.003419,0.000333,0.008464,25.872904,1.318029,0.084642,-301.047089,0.009331,0.000000
11.450001,5.970253,-301.002594,0.003432,0.000348,0.008837,26.557013,1.352879,0.088370,-301.002594,0.009687,0.000000
11.660001,6.106537,-301.047089,0.003406,0.000360,0.009149,27.163233,1.383761,0.091492,-301.047089,0.010034,0.000000
11.870001,6.343742,-301.091553,0.003466,0.000377,0.009566,28.218376,1.437513,0.095656,-301.091553,0.010380,0.000000
12.080001,6.490829,-301.091553,0.003497,0.000388,0.009852,28.872652,1.470843,0.098517,-301.091553,0.010736,0.000000
12.290001,6.621155,-301.091553,0.003445,0.000399,0.010147,29.452368,1.500375,0.101465,-301.091553,0.011083,0.000000
12.500001,6.701591,-301.091553,0.003514,0.000413,0.010485,29.810167,1.518602,0.104845,-301.091553,0.011430,0.000000
12.710001,6.898201,-301.047089,0.003497,0.000426,0.010814,30.684731,1.563155,0.108142,-301.047089,0.011785,0.000000
12.920001,7.108223,-301.136047,0.003518,0.000443,0.011257,31.618956,1.610746,0.112567,-301.136047,0.012132,0.000000
13.130001,7.220306,-301.047089,0.003553,0.000456,0.011586,32.117527,1.636145,0.115859,-301.047089,0.012488,0.000000
13.340001,7.336487,-301.091553,0.003583,0.000469,0.011916,32.634323,1.662472,0.119156,-301.091553,0.012835,0.000000
13.550000,7.486549,-301.091553,0.003523,0.000483,0.012280,33.301834,1.696476,0.122797,-301.091553,0.013182,0.000000
13.760000,7.650398,-301.091553,0.003600,0.000500,0.012705,34.030670,1.733605,0.127048,-301.091553,0.013537,0.000000
13.970000,7.763969,-301.136047,0.003630,0.000514,0.013043,34.535862,1.759341,0.130431,-301.136047,0.013884,0.000000
14.180000,7.800835,-301.091553,0.003639,0.000526,0.013355,34.699844,1.767694,0.133550,-301.091553,0.014231,0.000000
14.390000,7.724869,-301.180511,0.003665,0.000534,0.013572,34.361931,1.750480,0.135719,-301.180511,0.014587,0.000000
14.600000,8.008621,-301.136047,0.003635,0.000552,0.014023,35.624126,1.814780,0.140230,-301.136047,0.014934,0.000000
14.810000,8.227943,-301.136047,0.003617,0.000568,0.014422,36.599720,1.864479,0.144220,-301.136047,0.015280,0.000000
15.020000,8.273003,-301.180511,0.003699,0.000579,0.014717,36.800152,1.874689,0.147168,-301.180511,0.015636,0.000000
15.230000,8.310242,-301.180511,0.003665,0.000595,0.015107,36.965801,1.883128,0.151070,-301.180511,0.015983,0.000000
15.440001,8.404076,-301.136047,0.003656,0.000607,0.015419,37.383194,1.904391,0.154193,-301.136047,0.016330,0.000000
15.650001,8.425674,-301.136047,0.003682,0.000619,0.015732,37.479271,1.909285,0.157315,-301.136047,0.016685,0.000000
15.860001,8.706070,-301.091553,0.003691,0.000638,0.016200,38.726532,1.972824,0.161997,-301.091553,0.017032,0.000000
16.070002,8.664742,-301.180511,0.003768,0.000649,0.016477,38.542694,1.963459,0.164772,-301.180511,0.017388,0.000000
16.280001,8.634949,-301.136047,0.003738,0.000657,0.016677,38.410172,1.956707,0.166766,-301.136047,0.017735,0.000000
16.490002,8.819275,-301.136047,0.003794,0.000672,0.017067,39.230095,1.998476,0.170668,-301.136047,0.018082,0.000000
16.700001,9.178986,-301.136047,0.003786,0.000696,0.017683,40.830166,2.079988,0.176827,-301.136047,0.018437,0.000000
16.910002,9.124992,-301.136047,0.003842,0.000707,0.017960,40.589993,2.067753,0.179601,-301.136047,0.018784,0.000000
17.120001,9.123505,-301.225006,0.003790,0.000720,0.018290,40.583374,2.067416,0.182897,-301.225006,0.019131,0.000000
17.330000,9.182709,-301.180511,0.003837,0.000733,0.018619,40.846729,2.080832,0.186194,-301.180511,0.019487,0.000000
17.540001,9.177498,-301.180511,0.003837,0.000744,0.018906,40.823551,2.079651,0.189056,-301.180511,0.019833,0.000000
17.750000,9.341339,-301.180511,0.003807,0.000759,0.019278,41.552353,2.116778,0.192784,-301.180511,0.020180,0.000000
17.960001,9.246384,-301.225006,0.003867,0.000766,0.019452,41.129971,2.095261,0.194517,-301.225006,0.020536,0.000000
18.170000,9.202446,-301.180511,0.003842,0.000777,0.019747,40.934525,2.085304,0.197466,-301.180511,0.020883,0.000000
18.380001,9.659348,-301.180511,0.003837,0.000797,0.020250,42.966923,2.188839,0.202496,-301.180511,0.021238,0.000000
18.590000,9.836967,-301.225006,0.003893,0.000818,0.020779,43.757015,2.229089,0.207787,-301.225006,0.021585,0.000000
18.800001,9.983681,-301.225006,0.003936,0.000834,0.021186,44.409630,2.262334,0.211863,-301.225006,0.021932,0.000000
19.010000,9.853348,-301.225006,0.003898,0.000845,0.021472,43.829880,2.232800,0.214725,-301.225006,0.022288,0.000000
19.220001,9.853348,-301.269470,0.003936,0.000857,0.021776,43.829880,2.232800,0.217760,-301.269470,0.022634,0.000000
19.430000,9.915169,-301.225006,0.003958,0.000870,0.022105,44.104874,2.246809,0.221053,-301.225006,0.022982,0.000000
19.640001,10.081245,-301.180511,0.003975,0.000886,0.022504,44.843620,2.284443,0.225042,-301.180511,0.023337,0.000000
19.850000,10.144920,-301.269470,0.003980,0.000899,0.022834,45.126858,2.298872,0.228339,-301.269470,0.023684,0.000000
20.060001,10.078262,-301.225006,0.004010,0.000908,0.023059,44.830349,2.283767,0.230595,-301.225006,0.024031,0.000000
20.270000,10.201523,-301.269470,0.004040,0.000924,0.023458,45.378639,2.311698,0.234584,-301.269470,0.024386,0.000000
20.480001,10.498299,-301.269470,0.004070,0.000939,0.023857,46.698765,2.378948,0.238573,-301.269470,0.024733,0.000000
20.690001,10.665871,-301.269470,0.004023,0.000957,0.024317,47.444160,2.416921,0.243168,-301.269470,0.025089,0.000000
20.900002,10.656189,-301.269470,0.004036,0.000969,0.024620,47.401096,2.414727,0.246204,-301.269470,0.025436,0.000000
21.110001,10.593628,-301.269470,0.004092,0.000983,0.024959,47.122810,2.400550,0.249587,-301.269470,0.025783,0.000000
21.320002,10.528465,-301.225006,0.004105,0.000992,0.025193,46.832954,2.385784,0.251926,-301.225006,0.026138,0.000000
21.530001,10.782051,-301.269470,0.004122,0.001010,0.025644,47.960960,2.443248,0.256438,-301.269470,0.026485,0.000000
21.740002,10.887054,-301.313965,0.004165,0.001023,0.025973,48.428036,2.467042,0.259735,-301.313965,0.026832,0.000000
21.950001,10.922806,-301.269470,0.004122,0.001034,0.026260,48.587067,2.475143,0.262596,-301.269470,0.027187,0.000000
22.160002,10.828224,-301.269470,0.004135,0.001047,0.026606,48.166348,2.453711,0.266063,-301.269470,0.027534,0.000000
22.370001,10.943283,-301.269470,0.004161,0.001057,0.026858,48.678154,2.479783,0.268580,-301.269470,0.027881,0.000000
22.580002,11.551743,-301.313965,0.004199,0.001084,0.027526,51.384716,2.617662,0.275256,-301.313965,0.028237,0.000000
22.790001,11.401672,-301.269470,0.004186,0.001095,0.027812,50.717171,2.583656,0.278118,-301.269470,0.028584,0.000000
23.000002,11.357735,-301.313965,0.004204,0.001107,0.028115,50.521729,2.573699,0.281153,-301.313965,0.028931,0.000000
23.210001,11.380447,-301.225006,0.004204,0.001120,0.028445,50.622757,2.578846,0.284450,-301.225006,0.029286,0.000000
23.420002,11.458649,-301.313965,0.004268,0.001133,0.028783,50.970615,2.596567,0.287830,-301.313965,0.029633,0.000000
23.630001,11.693245,-301.313965,0.004243,0.001149,0.029182,52.014153,2.649727,0.291819,-301.313965,0.029988,0.000000
23.840002,11.725639,-301.313965,0.004243,0.001159,0.029451,52.158249,2.657068,0.294510,-301.313965,0.030336,0.000000
24.050001,11.557327,-301.269470,0.004255,0.001166,0.029616,51.409561,2.618928,0.296157,-301.269470,0.030682,0.000000
24.260000,11.755432,-301.313965,0.004294,0.001182,0.030032,52.290775,2.663819,0.300320,-301.313965,0.031038,0.000000
24.470001,12.356812,-301.313965,0.004333,0.001208,0.030674,54.965843,2.800093,0.306735,-301.313965,0.031385,0.000000
24.680000,12.286430,-301.313965,0.004303,0.001220,0.030977,54.652771,2.784145,0.309771,-301.313965,0.031732,0.000000
24.890001,12.189987,-301.358429,0.004389,0.001232,0.031281,54.223770,2.762290,0.312806,-301.358429,0.032087,0.000000
25.100000,12.283455,-301.402924,0.004329,0.001245,0.031610,54.639538,2.783471,0.316103,-301.402924,0.032434,0.000000
25.310001,12.203018,-301.313965,0.004355,0.001255,0.031879,54.281734,2.765243,0.318790,-301.313965,0.032781,0.000000
25.520000,12.584702,-301.358429,0.004406,0.001275,0.032382,55.979549,2.851734,0.323820,-301.358429,0.033137,0.000000
25.730001,12.662155,-301.313965,0.004376,0.001287,0.032686,56.324078,2.869285,0.326856,-301.313965,0.033483,0.000000
25.940001,12.482674,-301.402924,0.004389,0.001293,0.032850,55.525707,2.828614,0.328502,-301.402924,0.033839,0.000000
26.150002,12.695671,-301.402924,0.004428,0.001309,0.033241,56.473164,2.876880,0.332408,-301.402924,0.034186,0.000000
26.360001,13.000275,-301.358429,0.004406,0.001327,0.033718,57.828110,2.945904,0.337177,-301.358429,0.034533,0.000000
26.570002,12.958191,-301.402924,0.004424,0.001338,0.033978,57.640911,2.936368,0.339778,-301.402924,0.034888,0.000000
26.780001,13.033783,-301.402924,0.004458,0.001351,0.034316,57.977161,2.953497,0.343161,-301.402924,0.035235,0.000000
26.990002,13.175285,-301.358429,0.004449,0.001364,0.034645,58.606598,2.985562,0.346454,-301.358429,0.035582,0.000000
27.200001,13.276573,-301.402924,0.004493,0.001377,0.034984,59.057148,3.008515,0.349838,-301.402924,0.035938,0.000000
27.410002,13.552872,-301.358429,0.004488,0.001395,0.035426,60.286182,3.071125,0.354262,-301.358429,0.036285,0.000000
27.620001,13.683205,-301.402924,0.004506,0.001408,0.035773,60.865932,3.100659,0.357729,-301.402924,0.036631,0.000000
27.830002,13.533508,-301.402924,0.004536,0.001417,0.035990,60.200050,3.066737,0.359898,-301.402924,0.036987,0.000000
28.040001,13.685066,-301.491882,0.004527,0.001431,0.036337,60.874214,3.101080,0.363365,-301.491882,0.037334,0.000000
28.250002,13.770340,-301.491882,0.004566,0.001444,0.036684,61.253532,3.120404,0.366836,-301.491882,0.037690,0.000000
28.460001,14.212341,-301.402924,0.004549,0.001464,0.037187,63.219650,3.220562,0.371866,-301.402924,0.038036,0.000000
28.670002,14.214951,-301.491882,0.004575,0.001475,0.037455,63.231258,3.221154,0.374553,-301.491882,0.038383,0.000000
28.880001,14.331505,-301.447418,0.004618,0.001490,0.037846,63.749718,3.247566,0.378455,-301.447418,0.038739,0.000000
29.090002,14.433159,-301.402924,0.004583,0.001503,0.038167,64.201897,3.270601,0.381665,-301.402924,0.039086,0.000000
29.300001,14.534073,-301.447418,0.004592,0.001518,0.038548,64.650787,3.293468,0.385480,-301.447418,0.039433,0.000000
29.510002,14.673340,-301.402924,0.004661,0.001531,0.038886,65.270279,3.325027,0.388864,-301.402924,0.039788,0.000000
29.720001,14.765686,-301.447418,0.004618,0.001545,0.039233,65.681053,3.345952,0.392331,-301.447418,0.040135,0.000000
29.930002,14.849846,-301.402924,0.004665,0.001557,0.039554,66.055412,3.365023,0.395540,-301.402924,0.040482,0.000000
30.140001,14.929909,-301.447418,0.004717,0.001568,0.039831,66.411552,3.383166,0.398315,-301.447418,0.040838,0.000000
30.350002,15.432236,-301.491882,0.004674,0.001590,0.040378,68.646011,3.496995,0.403780,-301.491882,0.041185,0.000000
30.560001,15.460167,-301.447418,0.004691,0.001602,0.040699,68.770256,3.503324,0.406990,-301.447418,0.041531,0.000000
30.770002,15.428886,-301.491882,0.004734,0.001614,0.041002,68.631111,3.496236,0.410021,-301.491882,0.041887,0.000000
30.980001,15.494049,-301.580841,0.004747,0.001627,0.041332,68.920975,3.511002,0.413318,-301.580841,0.042234,0.000000
31.190001,15.817268,-301.447418,0.004725,0.001646,0.041800,70.358727,3.584244,0.418000,-301.447418,0.042590,0.000000
31.400002,15.951698,-301.536377,0.004773,0.001657,0.042095,70.956696,3.614707,0.420952,-301.536377,0.042936,0.000000
31.610001,15.915199,-301.491882,0.004760,0.001669,0.042398,70.794342,3.606436,0.423984,-301.491882,0.043283,0.000000
31.820002,15.842216,-301.536377,0.004781,0.001678,0.042624,70.469696,3.589897,0.426240,-301.536377,0.043639,0.000000
32.030003,16.222038,-301.536377,0.004760,0.001695,0.043040,72.159233,3.675967,0.430403,-301.536377,0.043986,0.000000
32.240002,16.289810,-301.447418,0.004829,0.001707,0.043370,72.460693,3.691324,0.433700,-301.447418,0.044332,0.000000
32.450001,16.656227,-301.536377,0.004825,0.001726,0.043829,74.090599,3.774355,0.438295,-301.536377,0.044688,0.000000
32.660000,16.840179,-301.536377,0.004816,0.001740,0.044202,74.908859,3.816039,0.442023,-301.536377,0.045035,0.000000
32.870003,16.928429,-301.536377,0.004876,0.001754,0.044549,75.301414,3.836037,0.445493,-301.536377,0.045382,0.000000
33.080002,16.875175,-301.580841,0.004842,0.001763,0.044775,75.064529,3.823969,0.447749,-301.580841,0.045737,0.000000
33.290001,17.110893,-301.536377,0.004855,0.001780,0.045208,76.113052,3.877384,0.452083,-301.536377,0.046084,0.000000
33.500000,17.256485,-301.580841,0.004898,0.001794,0.045564,76.760681,3.910375,0.455641,-301.580841,0.046440,0.000000
33.710003,17.251648,-301.491882,0.004863,0.001804,0.045833,76.739166,3.909279,0.458328,-301.491882,0.046787,0.000000
33.920002,17.448631,-301.580841,0.004915,0.001818,0.046180,77.615387,3.953916,0.461795,-301.580841,0.047134,0.000000
34.130001,17.915215,-301.580841,0.004915,0.001836,0.046631,79.690857,4.059646,0.466307,-301.580841,0.047489,0.000000
34.340000,18.034744,-301.580841,0.004941,0.001847,0.046926,80.222549,4.086731,0.469255,-301.580841,0.047836,0.000000
34.550003,18.184067,-301.625336,0.004941,0.001860,0.047255,80.886772,4.120568,0.472552,-301.625336,0.048183,0.000000
34.760002,18.350891,-301.536377,0.004941,0.001877,0.047680,81.628838,4.158371,0.476798,-301.536377,0.048539,0.000000
34.970001,18.569473,-301.580841,0.004997,0.001890,0.048001,82.601143,4.207903,0.480008,-301.580841,0.048885,0.000000
35.180000,18.861038,-301.625336,0.005014,0.001906,0.048400,83.898087,4.273972,0.483997,-301.625336,0.049232,0.000000
35.390003,18.989136,-301.580841,0.005040,0.001920,0.048773,84.467896,4.302999,0.487725,-301.580841,0.049588,0.000000
35.600002,18.861786,-301.625336,0.005014,0.001928,0.048981,83.901413,4.274142,0.489807,-301.625336,0.049935,0.000000
35.810001,19.024513,-301.491882,0.004997,0.001941,0.049310,84.625259,4.311016,0.493104,-301.491882,0.050290,0.000000
36.020000,19.384224,-301.625336,0.005066,0.001957,0.049701,86.225334,4.392528,0.497006,-301.625336,0.050637,0.000000
36.230003,19.703346,-301.580841,0.005040,0.001973,0.050126,87.644859,4.464842,0.501256,-301.580841,0.050984,0.000000
36.440002,19.743195,-301.580841,0.005057,0.001984,0.050394,87.822113,4.473872,0.503944,-301.580841,0.051340,0.000000
36.650002,20.033272,-301.580841,0.005101,0.002000,0.050793,89.112442,4.539604,0.507933,-301.580841,0.051687,0.000000
36.860001,20.088753,-301.580841,0.005053,0.002011,0.051079,89.359238,4.552176,0.510794,-301.580841,0.052034,0.000000
37.070004,20.283875,-301.669800,0.005131,0.002024,0.051400,90.227180,4.596392,0.514004,-301.669800,0.052389,0.000000
37.280003,20.646568,-301.625336,0.005113,0.002040,0.051825,91.840523,4.678579,0.518254,-301.625336,0.052736,0.000000
37.490002,20.699074,-301.625336,0.005152,0.002051,0.052094,92.074081,4.690477,0.520942,-301.625336,0.053083,0.000000
37.700001,20.559433,-301.669800,0.005131,0.002063,0.052389,91.452927,4.658834,0.523890,-301.669800,0.053438,0.000000
37.910004,21.495949,-301.625336,0.005135,0.002084,0.052927,95.618759,4.871052,0.529268,-301.625336,0.053785,0.000000
38.120003,21.911888,-301.625336,0.005157,0.002101,0.053369,97.468948,4.965305,0.533689,-301.625336,0.054141,0.000000
38.330002,21.813957,-301.714294,0.005182,0.002111,0.053629,97.033325,4.943113,0.536293,-301.714294,0.054488,0.000000
38.540001,22.013550,-301.580841,0.005174,0.002126,0.054002,97.921158,4.988341,0.540021,-301.580841,0.054834,0.000000
38.750000,22.078339,-301.669800,0.005200,0.002136,0.054262,98.209358,5.003023,0.542621,-301.669800,0.055190,0.000000
38.960003,22.334534,-301.669800,0.005187,0.002151,0.054627,99.348969,5.061078,0.546266,-301.669800,0.055537,0.000000
39.170002,22.481621,-301.625336,0.005260,0.002163,0.054939,100.003242,5.094408,0.549385,-301.625336,0.055884,0.000000
39.380001,22.299904,-301.758759,0.005256,0.002169,0.055086,99.194923,5.053230,0.550861,-301.758759,0.056239,0.000000
39.590000,22.921021,-301.625336,0.005260,0.002188,0.055563,101.957794,5.193977,0.555630,-301.625336,0.056586,0.000000
39.800003,23.385742,-301.714294,0.005290,0.002203,0.055953,104.024979,5.299285,0.559532,-301.714294,0.056933,0.000000
40.010002,24.333801,-301.714294,0.005290,0.002226,0.056543,108.242157,5.514118,0.565429,-301.714294,0.057289,0.000000
40.220001,24.299171,-301.669800,0.005286,0.002237,0.056812,108.088112,5.506271,0.568120,-301.669800,0.057636,0.000000
40.430000,24.341621,-301.669800,0.005325,0.002250,0.057159,108.276939,5.515890,0.571587,-301.669800,0.057983,0.000000
40.640003,24.299911,-301.669800,0.005295,0.002262,0.057462,108.091408,5.506438,0.574623,-301.669800,0.058338,0.000000
40.850002,24.300285,-301.758759,0.005295,0.002270,0.057662,108.093071,5.506523,0.576617,-301.758759,0.058685,0.000000
41.060001,24.901299,-301.714294,0.005303,0.002289,0.058139,110.766510,5.642715,0.581386,-301.714294,0.059041,0.000000
41.270000,25.141472,-301.758759,0.005385,0.002302,0.058460,111.834854,5.697139,0.584596,-301.758759,0.059388,0.000000
41.480003,25.085991,-301.803253,0.005381,0.002310,0.058676,111.588058,5.684567,0.586765,-301.803253,0.059734,0.000000
41.690002,25.468048,-301.714294,0.005346,0.002324,0.059023,113.287537,5.771142,0.590232,-301.714294,0.060090,0.000000
41.900002,26.333443,-301.758759,0.005407,0.002347,0.059622,117.137001,5.967244,0.596216,-301.758759,0.060437,0.000000
42.110001,26.728523,-301.758759,0.005389,0.002361,0.059977,118.894409,6.056770,0.599773,-301.758759,0.060784,0.000000
42.320004,26.887154,-301.714294,0.005415,0.002374,0.060307,119.600029,6.092716,0.603066,-301.714294,0.061139,0.000000
42.530003,26.922531,-301.758759,0.005428,0.002387,0.060619,119.757401,6.100733,0.606189,-301.758759,0.061486,0.000000
42.740002,27.088608,-301.758759,0.005428,0.002397,0.060896,120.496147,6.138366,0.608963,-301.758759,0.061833,0.000000
42.950001,27.763351,-301.758759,0.005484,0.002414,0.061321,123.497559,6.291265,0.613214,-301.758759,0.062188,0.000000
43.160004,27.945442,-301.803253,0.005445,0.002426,0.061625,124.307533,6.332528,0.616249,-301.803253,0.062536,0.000000
43.370003,27.944321,-301.714294,0.005514,0.002435,0.061859,124.302544,6.332273,0.618592,-301.714294,0.062891,0.000000
43.580002,28.207962,-301.758759,0.005506,0.002447,0.062163,125.475281,6.392016,0.621627,-301.758759,0.063238,0.000000
43.790001,29.186554,-301.714294,0.005463,0.002472,0.062779,129.828278,6.613768,0.627785,-301.714294,0.063585,0.000000
44.000004,29.865395,-301.803253,0.005553,0.002487,0.063177,132.847916,6.767595,0.631775,-301.803253,0.063941,0.000000
44.210003,29.867630,-301.758759,0.005523,0.002497,0.063429,132.857849,6.768102,0.634288,-301.758759,0.064287,0.000000
44.420002,30.049713,-301.758759,0.005553,0.002511,0.063776,133.667801,6.809362,0.637759,-301.758759,0.064634,0.000000
44.630001,30.393044,-301.847748,0.005562,0.002524,0.064114,135.195007,6.887162,0.641138,-301.847748,0.064990,0.000000
44.840004,30.823509,-301.758759,0.005566,0.002538,0.064470,137.109818,6.984707,0.644696,-301.758759,0.065337,0.000000
45.050003,31.030174,-301.803253,0.005562,0.002549,0.064756,138.029114,7.031538,0.647558,-301.803253,0.065683,0.000000
45.260002,31.318764,-301.758759,0.005605,0.002562,0.065085,139.312820,7.096933,0.650851,-301.758759,0.066039,0.000000
45.470001,31.770447,-301.847748,0.005609,0.002575,0.065415,141.322006,7.199286,0.654147,-301.847748,0.066386,0.000000
45.680000,32.320442,-301.803253,0.005609,0.002594,0.065883,143.768509,7.323917,0.658829,-301.803253,0.066742,0.000000
45.890003,33.363091,-301.803253,0.005631,0.002613,0.066369,148.406433,7.560184,0.663685,-301.803253,0.067088,0.000000
46.100002,33.465858,-301.892212,0.005618,0.002624,0.066646,148.863571,7.583472,0.666463,-301.892212,0.067435,0.000000
46.310001,33.552254,-301.892212,0.005635,0.002635,0.066924,149.247879,7.603049,0.669238,-301.892212,0.067791,0.000000
46.520000,33.845306,-301.847748,0.005635,0.002648,0.067262,150.551437,7.669456,0.672617,-301.847748,0.068138,0.000000
46.730003,34.193108,-301.892212,0.005661,0.002661,0.067583,152.098541,7.748269,0.675827,-301.892212,0.068485,0.000000
46.940002,34.868591,-301.892212,0.005683,0.002677,0.067990,155.103241,7.901336,0.679903,-301.892212,0.068840,0.000000
47.150002,35.264420,-301.847748,0.005661,0.002690,0.068320,156.863968,7.991032,0.683200,-301.847748,0.069187,0.000000
47.360001,35.167229,-301.892212,0.005704,0.002698,0.068528,156.431641,7.969008,0.685282,-301.892212,0.069534,0.000000
47.570004,36.299240,-301.892212,0.005683,0.002719,0.069057,161.467087,8.225526,0.690569,-301.892212,0.069890,0.000000
47.780003,36.614647,-301.936707,0.005747,0.002731,0.069360,162.870087,8.296998,0.693605,-301.936707,0.070237,0.000000
47.990002,36.994461,-301.892212,0.005717,0.002745,0.069725,164.559586,8.383065,0.697250,-301.892212,0.070583,0.000000
48.200001,37.096123,-301.936707,0.005756,0.002756,0.069994,165.011795,8.406101,0.699937,-301.936707,0.070939,0.000000
48.410004,37.615952,-301.847748,0.005747,0.002769,0.070323,167.324112,8.523896,0.703233,-301.847748,0.071286,0.000000
48.620003,38.149559,-301.847748,0.005803,0.002783,0.070687,169.697708,8.644814,0.706875,-301.847748,0.071641,0.000000
48.830002,38.950905,-301.981171,0.005760,0.002800,0.071130,173.262283,8.826401,0.711299,-301.981171,0.071988,0.000000
49.040001,39.360146,-301.892212,0.005799,0.002810,0.071381,175.082672,8.919136,0.713812,-301.892212,0.072335,0.000000
49.250004,39.358284,-301.936707,0.005777,0.002821,0.071650,175.074387,8.918715,0.716500,-301.936707,0.072691,0.000000
49.460003,40.038239,-301.892212,0.005799,0.002835,0.071997,178.098984,9.072795,0.719970,-301.892212,0.073037,0.000000
49.670002,40.574455,-301.847748,0.005846,0.002851,0.072405,180.484192,9.194303,0.724047,-301.847748,0.073385,0.000000
49.880001,41.510223,-301.936707,0.005795,0.002867,0.072812,184.646698,9.406351,0.728123,-301.936707,0.073740,0.000000
50.090004,41.704971,-301.892212,0.005833,0.002877,0.073064,185.512970,9.450481,0.730636,-301.892212,0.074087,0.000000
50.300003,42.397217,-301.936707,0.005864,0.002894,0.073506,188.592239,9.607347,0.735061,-301.936707,0.074434,0.000000
50.510002,42.761765,-301.892212,0.005829,0.002907,0.073835,190.213821,9.689955,0.738354,-301.892212,0.074790,0.000000
50.720001,43.607422,-301.936707,0.005851,0.002922,0.074217,193.975494,9.881583,0.742172,-301.936707,0.075136,0.000000
50.930004,44.030441,-301.981171,0.005851,0.002935,0.074547,195.857178,9.977440,0.745465,-301.981171,0.075492,0.000000
51.140003,44.529419,-301.936707,0.005851,0.002948,0.074867,198.076752,10.090510,0.748675,-301.936707,0.075839,0.000000
51.350002,44.839981,-301.936707,0.005851,0.002959,0.075162,199.458191,10.160885,0.751623,-301.936707,0.076186,0.000000
51.560001,45.244377,-301.892212,0.005877,0.002973,0.075518,201.257034,10.252522,0.755177,-301.892212,0.076541,0.000000
51.770004,46.685829,-301.981171,0.005877,0.002994,0.076047,207.668945,10.579161,0.760469,-301.981171,0.076888,0.000000
51.980003,47.150925,-301.981171,0.005920,0.003006,0.076350,209.737793,10.684552,0.763504,-301.981171,0.077235,0.000000
52.190002,47.480843,-301.892212,0.005950,0.003018,0.076654,211.205338,10.759313,0.766540,-301.892212,0.077591,0.000000
52.400002,48.142548,-302.025665,0.005928,0.003032,0.077009,214.148743,10.909257,0.770094,-302.025665,0.077937,0.000000
52.610001,49.179604,-301.981171,0.005946,0.003050,0.077478,218.761795,11.144258,0.774779,-301.981171,0.078284,0.000000
52.820004,49.587357,-302.025665,0.005963,0.003062,0.077781,220.575577,11.236655,0.777815,-302.025665,0.078640,0.000000
53.030003,49.815247,-301.981171,0.005941,0.003071,0.078007,221.589279,11.288296,0.780067,-301.981171,0.078987,0.000000
53.240002,50.109795,-301.981171,0.005937,0.003082,0.078284,222.899506,11.355042,0.782845,-301.981171,0.079342,0.000000
53.450001,51.073120,-301.981171,0.005980,0.003096,0.078649,227.184586,11.573335,0.786486,-301.981171,0.079689,0.000000
53.660004,52.179443,-302.025665,0.005959,0.003117,0.079169,232.105759,11.824031,0.791690,-302.025665,0.080036,0.000000
53.870003,52.722359,-302.025665,0.006023,0.003127,0.079429,234.520767,11.947058,0.794290,-302.025665,0.080392,0.000000
54.080002,53.491684,-302.025665,0.006023,0.003143,0.079828,237.942902,12.121389,0.798280,-302.025665,0.080739,0.000000
54.290001,54.045769,-302.025665,0.006002,0.003155,0.080132,240.407593,12.246946,0.801315,-302.025665,0.081085,0.000000
54.500004,54.898872,-302.025665,0.006049,0.003172,0.080574,244.202377,12.440262,0.805740,-302.025665,0.081441,0.000000
54.710003,55.576591,-302.025665,0.006058,0.003185,0.080895,247.217026,12.593835,0.808946,-302.025665,0.081788,0.000000
54.920002,56.176483,-302.025665,0.006040,0.003196,0.081189,249.885483,12.729773,0.811894,-302.025665,0.082135,0.000000
55.130001,56.490395,-302.025665,0.006049,0.003207,0.081450,251.281830,12.800906,0.814498,-302.025665,0.082490,0.000000
55.340004,57.200882,-302.070129,0.006053,0.003221,0.081823,254.442230,12.961905,0.818226,-302.070129,0.082837,0.000000
55.550003,58.444977,-302.025665,0.006032,0.003240,0.082308,259.976227,13.243821,0.823082,-302.025665,0.083184,0.000000
55.760002,58.803574,-302.114624,0.006079,0.003251,0.082569,261.571350,13.325081,0.825686,-302.114624,0.083540,0.000000
55.970001,59.385963,-302.025665,0.006088,0.003264,0.082907,264.161957,13.457051,0.829066,-302.025665,0.083887,0.000000
56.180004,60.655006,-302.070129,0.006075,0.003280,0.083314,269.806946,13.744621,0.833142,-302.070129,0.084242,0.000000
56.390003,61.288414,-302.114624,0.006084,0.003294,0.083661,272.624481,13.888154,0.836613,-302.114624,0.084589,0.000000
56.600002,62.309464,-302.025665,0.006122,0.003310,0.084069,277.166351,14.119526,0.840690,-302.025665,0.084936,0.000000
56.810001,62.943237,-302.114624,0.006101,0.003321,0.084346,279.985504,14.263141,0.843464,-302.114624,0.085291,0.000000
57.020004,63.008400,-302.070129,0.006135,0.003329,0.084546,280.275360,14.277907,0.845459,-302.070129,0.085639,0.000000
57.230003,63.787781,-302.114624,0.006122,0.003344,0.084945,283.742218,14.454517,0.849448,-302.114624,0.085985,0.000000
57.440002,65.084381,-302.070129,0.006101,0.003361,0.085361,289.509796,14.748331,0.853611,-302.070129,0.086341,0.000000
57.650002,66.137451,-302.070129,0.006114,0.003376,0.085751,294.194061,14.986961,0.857513,-302.070129,0.086688,0.000000
57.860004,66.668457,-302.114624,0.006127,0.003389,0.086081,296.556122,15.107288,0.860806,-302.114624,0.087035,0.000000
58.070004,67.476501,-302.070129,0.006196,0.003393,0.086193,300.150482,15.290394,0.861934,-302.070129,0.086367,0.000000
58.280003,66.701599,-302.159088,0.006153,0.003391,0.086124,296.703522,15.114799,0.861242,-302.159088,0.086367,0.000000
58.490002,66.163895,-302.114624,0.006174,0.003390,0.086107,294.311707,14.992952,0.861067,-302.114624,0.086124,0.000000
58.700005,65.598999,-302.159088,0.006213,0.003389,0.086089,291.798920,14.864945,0.860893,-302.159088,0.086124,0.000000
58.910004,65.114548,-302.159088,0.006222,0.003389,0.086089,289.643982,14.755167,0.860893,-302.159088,0.086124,0.000000
59.120003,64.682587,-302.114624,0.006178,0.003389,0.086081,287.722504,14.657284,0.860806,-302.114624,0.086124,0.000000
59.330002,64.274094,-302.159088,0.006170,0.003389,0.086072,285.905457,14.564717,0.860719,-302.159088,0.086124,0.000000
59.540005,63.909546,-302.159088,0.006209,0.003389,0.086072,284.283844,14.482110,0.860719,-302.159088,0.086124,0.000000
59.750004,63.572174,-302.159088,0.006148,0.003389,0.086072,282.783142,14.405661,0.860719,-302.159088,0.086124,0.000000
59.960003,63.253052,-302.248077,0.006191,0.003389,0.086072,281.363617,14.333346,0.860719,-302.248077,0.086124,0.000000
60.170002,62.954041,-302.159088,0.006170,0.003388,0.086063,280.033569,14.265590,0.860632,-302.159088,0.086124,0.000000
60.380001,62.691887,-302.114624,0.006217,0.003388,0.086063,278.867432,14.206184,0.860632,-302.114624,0.086124,0.000000
60.590004,62.428619,-302.159088,0.006213,0.003388,0.086063,277.696381,14.146527,0.860632,-302.159088,0.086124,0.000000
60.800003,62.195885,-302.159088,0.006187,0.003388,0.086063,276.661102,14.093789,0.860632,-302.159088,0.086124,0.000000
61.010002,61.976562,-302.159088,0.006196,0.003388,0.086063,275.685516,14.044089,0.860632,-302.159088,0.086124,0.000000
61.220001,61.762444,-302.114624,0.006200,0.003388,0.086063,274.733063,13.995569,0.860632,-302.114624,0.086124,0.000000
61.430004,61.573654,-302.292542,0.006217,0.003388,0.086063,273.893280,13.952789,0.860632,-302.292542,0.086124,0.000000
61.640003,61.368103,-302.203583,0.006183,0.003388,0.086063,272.978943,13.906211,0.860632,-302.203583,0.086124,0.000000
61.850002,61.202400,-302.203583,0.006217,0.003388,0.086063,272.241882,13.868662,0.860632,-302.203583,0.086124,0.000000
62.060001,61.044884,-302.203583,0.006200,0.003388,0.086063,271.541199,13.832969,0.860632,-302.203583,0.086124,0.000000
62.270004,60.881409,-302.159088,0.006234,0.003388,0.086063,270.814026,13.795924,0.860632,-302.159088,0.086124,0.000000
62.480003,60.719803,-302.203583,0.006247,0.003388,0.086063,270.095184,13.759304,0.860632,-302.203583,0.086124,0.000000
62.690002,60.579788,-302.203583,0.006204,0.003388,0.086063,269.472351,13.727576,0.860632,-302.203583,0.086124,0.000000
62.900002,60.436798,-302.203583,0.006226,0.003388,0.086063,268.836304,13.695174,0.860632,-302.203583,0.086124,0.000000
63.110004,60.301628,-302.337036,0.006217,0.003388,0.086063,268.235046,13.664544,0.860632,-302.337036,0.086124,0.000000
63.320004,60.173904,-302.248077,0.006204,0.003388,0.086063,267.666901,13.635602,0.860632,-302.248077,0.086124,0.000000
63.530003,60.050278,-302.203583,0.006200,0.003388,0.086063,267.116974,13.607587,0.860632,-302.203583,0.086124,0.000000
63.740002,59.921432,-302.292542,0.006209,0.003388,0.086063,266.543854,13.578391,0.860632,-302.292542,0.086124,0.000000
63.950005,59.813446,-302.203583,0.006204,0.003388,0.086063,266.063507,13.553921,0.860632,-302.203583,0.086124,0.000000
64.160004,59.705833,-302.292542,0.006226,0.003388,0.086063,265.584808,13.529535,0.860632,-302.292542,0.086124,0.000000
64.370003,59.607529,-302.248077,0.006260,0.003388,0.086063,265.147522,13.507258,0.860632,-302.248077,0.086124,0.000000
64.580002,59.496185,-302.248077,0.006217,0.003388,0.086063,264.652252,13.482028,0.860632,-302.248077,0.086124,0.000000
64.790001,59.388947,-302.292542,0.006217,0.003388,0.086063,264.175232,13.457727,0.860632,-302.292542,0.086124,0.000000
65.000000,59.303299,-302.248077,0.006234,0.003388,0.086063,263.794250,13.438320,0.860632,-302.248077,0.086124,0.000000
65.210007,59.210205,-302.292542,0.006204,0.003388,0.086055,263.380157,13.417225,0.860549,-302.292542,0.086124,0.000000
65.420006,59.119720,-302.248077,0.006226,0.003388,0.086055,262.977661,13.396720,0.860549,-302.248077,0.086124,0.000000
65.630005,59.035187,-302.292542,0.006234,0.003388,0.086055,262.601624,13.377564,0.860549,-302.292542,0.086124,0.000000
65.840004,58.957733,-302.292542,0.006256,0.003388,0.086055,262.257080,13.360013,0.860549,-302.292542,0.086124,0.000000
66.050003,58.871719,-302.292542,0.006217,0.003388,0.086055,261.874481,13.340522,0.860549,-302.292542,0.086124,0.000000
66.260002,58.786446,-302.292542,0.006247,0.003388,0.086055,261.495178,13.321199,0.860549,-302.292542,0.086124,0.000000
66.470001,58.716438,-302.248077,0.006209,0.003388,0.086055,261.183777,13.305335,0.860549,-302.248077,0.086124,0.000000
66.680000,58.630791,-302.292542,0.006239,0.003388,0.086055,260.802795,13.285927,0.860549,-302.292542,0.086124,0.000000
66.889999,58.562279,-302.381500,0.006265,0.003388,0.086055,260.498016,13.270402,0.860549,-302.381500,0.086124,0.000000
67.100006,58.495995,-302.337036,0.006204,0.003388,0.086055,260.203186,13.255382,0.860549,-302.337036,0.086124,0.000000
67.310005,58.428970,-302.381500,0.006191,0.003388,0.086055,259.905029,13.240193,0.860549,-302.381500,0.086124,0.000000
67.520004,58.356354,-302.337036,0.006256,0.003388,0.086055,259.582031,13.223739,0.860549,-302.337036,0.086124,0.000000
67.730003,58.295654,-302.292542,0.006226,0.003388,0.086055,259.312012,13.209985,0.860549,-302.292542,0.086124,0.000000
67.940002,58.220062,-302.337036,0.006204,0.003388,0.086055,258.975769,13.192854,0.860549,-302.337036,0.086124,0.000000
68.150002,58.170914,-302.337036,0.006230,0.003388,0.086055,258.757141,13.181718,0.860549,-302.337036,0.086124,0.000000
68.360001,58.102020,-302.381500,0.006243,0.003388,0.086055,258.450684,13.166105,0.860549,-302.381500,0.086124,0.000000
68.570000,58.034996,-302.337036,0.006252,0.003388,0.086055,258.152557,13.150918,0.860549,-302.337036,0.086124,0.000000
68.780006,57.988075,-302.381500,0.006252,0.003388,0.086055,257.943848,13.140285,0.860549,-302.381500,0.086124,0.000000
68.990005,57.924774,-302.381500,0.006230,0.003388,0.086055,257.662262,13.125942,0.860549,-302.381500,0.086124,0.000000
69.200005,57.861847,-302.337036,0.006260,0.003388,0.086055,257.382355,13.111682,0.860549,-302.337036,0.086124,0.000000
69.410004,57.812691,-302.425995,0.006273,0.003388,0.086055,257.163696,13.100543,0.860549,-302.425995,0.086124,0.000000
69.620003,57.762047,-302.337036,0.006226,0.003388,0.086055,256.938416,13.089067,0.860549,-302.337036,0.086124,0.000000
69.830002,57.713264,-302.381500,0.006226,0.003388,0.086055,256.721436,13.078012,0.860549,-302.381500,0.086124,0.000000
70.040001,57.655174,-302.425995,0.006234,0.003388,0.086055,256.463013,13.064850,0.860549,-302.425995,0.086124,0.000000
70.250000,57.617195,-302.425995,0.006243,0.003388,0.086055,256.294098,13.056243,0.860549,-302.425995,0.086124,0.000000
70.460007,57.554260,-302.381500,0.006239,0.003388,0.086055,256.014130,13.041982,0.860549,-302.381500,0.086124,0.000000
70.670006,57.511444,-302.425995,0.006269,0.003388,0.086055,255.823685,13.032280,0.860549,-302.425995,0.086124,0.000000
70.880005,57.463402,-302.381500,0.006239,0.003388,0.086055,255.609970,13.021393,0.860549,-302.381500,0.086124,0.000000
71.090004,57.412392,-302.425995,0.006243,0.003388,0.086055,255.383072,13.009834,0.860549,-302.425995,0.086124,0.000000
71.300003,57.369194,-302.425995,0.006273,0.003388,0.086055,255.190918,13.000045,0.860549,-302.425995,0.086124,0.000000
71.510002,57.329353,-302.470459,0.006252,0.003388,0.086055,255.013702,12.991017,0.860549,-302.470459,0.086124,0.000000
71.720001,57.268654,-302.470459,0.006243,0.003388,0.086055,254.743698,12.977262,0.860549,-302.470459,0.086124,0.000000
71.930000,57.227318,-302.425995,0.006252,0.003388,0.086055,254.559830,12.967896,0.860549,-302.425995,0.086124,0.000000
72.140007,57.191200,-302.470459,0.006234,0.003388,0.086055,254.399170,12.959712,0.860549,-302.470459,0.086124,0.000000
72.350006,57.143906,-302.425995,0.006239,0.003388,0.086055,254.188782,12.948995,0.860549,-302.425995,0.086124,0.000000
72.560005,57.105927,-302.470459,0.006230,0.003388,0.086055,254.019852,12.940388,0.860549,-302.470459,0.086124,0.000000
72.770004,57.066086,-302.425995,0.006222,0.003388,0.086055,253.842621,12.931359,0.860549,-302.425995,0.086124,0.000000
72.980003,57.021400,-302.425995,0.006286,0.003388,0.086055,253.643860,12.921233,0.860549,-302.425995,0.086124,0.000000
73.190002,56.986397,-302.559418,0.006234,0.003388,0.086055,253.488159,12.913301,0.860549,-302.559418,0.086124,0.000000
73.400002,56.939850,-302.514954,0.006204,0.003388,0.086055,253.281097,12.902755,0.860549,-302.514954,0.086124,0.000000
73.610001,56.905220,-302.514954,0.006273,0.003388,0.086055,253.127060,12.894907,0.860549,-302.514954,0.086124,0.000000
73.820000,56.869469,-302.425995,0.006256,0.003388,0.086055,252.968033,12.886806,0.860549,-302.425995,0.086124,0.000000
74.030006,56.831116,-302.470459,0.006269,0.003388,0.086055,252.797424,12.878115,0.860549,-302.470459,0.086124,0.000000
74.240005,56.792015,-302.559418,0.006269,0.003388,0.086055,252.623505,12.869254,0.860549,-302.559418,0.086124,0.000000
74.450005,56.752922,-302.514954,0.006234,0.003388,0.086055,252.449600,12.860396,0.860549,-302.514954,0.086124,0.000000
74.660004,56.717171,-302.425995,0.006239,0.003388,0.086055,252.290573,12.852295,0.860549,-302.425995,0.086124,0.000000
74.870003,56.687752,-302.514954,0.006226,0.003388,0.086055,252.159714,12.845629,0.860549,-302.514954,0.086124,0.000000
75.080002,56.650887,-302.470459,0.006243,0.003388,0.086055,251.995728,12.837275,0.860549,-302.470459,0.086124,0.000000
75.290001,56.627800,-302.470459,0.006247,0.003388,0.086055,251.893036,12.832043,0.860549,-302.470459,0.086124,0.000000
75.500000,56.588333,-302.514954,0.006291,0.003388,0.086055,251.717484,12.823099,0.860549,-302.514954,0.086124,0.000000
75.710007,56.557426,-302.514954,0.006286,0.003388,0.086055,251.580002,12.816096,0.860549,-302.514954,0.086124,0.000000
75.920006,56.529495,-302.559418,0.006247,0.003388,0.086055,251.455750,12.809767,0.860549,-302.559418,0.086124,0.000000
76.130005,56.488907,-302.559418,0.006278,0.003388,0.086055,251.275208,12.800570,0.860549,-302.559418,0.086124,0.000000
76.340004,56.472153,-302.559418,0.006252,0.003388,0.086055,251.200684,12.796773,0.860549,-302.559418,0.086124,0.000000
76.550003,56.419647,-302.470459,0.006230,0.003388,0.086055,250.967133,12.784875,0.860549,-302.470459,0.086124,0.000000
76.760002,56.390228,-302.559418,0.006230,0.003388,0.086055,250.836258,12.778209,0.860549,-302.559418,0.086124,0.000000
76.970001,56.354111,-302.559418,0.006286,0.003388,0.086055,250.675598,12.770024,0.860549,-302.559418,0.086124,0.000000
77.180000,56.328041,-302.559418,0.006226,0.003388,0.086055,250.559647,12.764116,0.860549,-302.559418,0.086124,0.000000
77.390007,56.288567,-302.559418,0.006209,0.003388,0.086055,250.384048,12.755172,0.860549,-302.559418,0.086124,0.000000
77.600006,56.261383,-302.514954,0.006213,0.003388,0.086055,250.263138,12.749012,0.860549,-302.514954,0.086124,0.000000
77.810005,56.234947,-302.603912,0.006256,0.003388,0.086055,250.145538,12.743021,0.860549,-302.603912,0.086124,0.000000
78.020004,56.205528,-302.559418,0.006269,0.003388,0.086055,250.014679,12.736355,0.860549,-302.559418,0.086124,0.000000
78.230003,56.175743,-302.559418,0.006278,0.003388,0.086055,249.882187,12.729606,0.860549,-302.559418,0.086124,0.000000
78.440002,56.149300,-302.648376,0.006252,0.003388,0.086055,249.764557,12.723613,0.860549,-302.648376,0.086124,0.000000
78.650002,56.116531,-302.514954,0.006260,0.003388,0.086055,249.618805,12.716187,0.860549,-302.514954,0.086124,0.000000
78.860001,56.085625,-302.603912,0.006269,0.003388,0.086055,249.481323,12.709185,0.860549,-302.603912,0.086124,0.000000
79.070007,56.054718,-302.603912,0.006273,0.003388,0.086055,249.343842,12.702181,0.860549,-302.603912,0.086124,0.000000
79.280006,56.020836,-302.559418,0.006243,0.003388,0.086055,249.193130,12.694503,0.860549,-302.559418,0.086124,0.000000
79.490005,56.007057,-302.648376,0.006286,0.003388,0.086055,249.131836,12.691381,0.860549,-302.648376,0.086124,0.000000
79.700005,55.970192,-302.559418,0.006222,0.003388,0.086055,248.967850,12.683027,0.860549,-302.559418,0.086124,0.000000
79.910004,55.946732,-302.559418,0.006273,0.003388,0.086055,248.863495,12.677711,0.860549,-302.559418,0.086124,0.000000
80.120003,55.913963,-302.648376,0.006269,0.003388,0.086055,248.717728,12.670285,0.860549,-302.648376,0.086124,0.000000
80.330002,55.883057,-302.559418,0.006234,0.003388,0.086055,248.580246,12.663281,0.860549,-302.559418,0.086124,0.000000
80.540001,55.870026,-302.603912,0.006243,0.003388,0.086055,248.522293,12.660329,0.860549,-302.603912,0.086124,0.000000
80.750008,55.818260,-302.559418,0.006239,0.003388,0.086055,248.292023,12.648599,0.860549,-302.559418,0.086124,0.000000
80.960007,55.817894,-302.559418,0.006230,0.003388,0.086055,248.290390,12.648516,0.860549,-302.559418,0.086124,0.000000
81.170006,55.781395,-302.692871,0.006239,0.003388,0.086055,248.128036,12.640245,0.860549,-302.692871,0.086124,0.000000
81.380005,55.758682,-302.603912,0.006299,0.003388,0.086055,248.027008,12.635098,0.860549,-302.603912,0.086124,0.000000
81.590004,55.726662,-302.648376,0.006243,0.003388,0.086055,247.884567,12.627842,0.860549,-302.648376,0.086124,0.000000
81.800003,55.713257,-302.648376,0.006273,0.003388,0.086055,247.824951,12.624804,0.860549,-302.648376,0.086124,0.000000
82.010002,55.693893,-302.648376,0.006213,0.003388,0.086055,247.738815,12.620417,0.860549,-302.648376,0.086124,0.000000
82.220001,55.658142,-302.648376,0.006247,0.003388,0.086055,247.579788,12.612315,0.860549,-302.648376,0.086124,0.000000
82.430000,55.638779,-302.648376,0.006234,0.003388,0.086055,247.493652,12.607927,0.860549,-302.648376,0.086124,0.000000
82.640007,55.619415,-302.648376,0.006278,0.003388,0.086055,247.407516,12.603540,0.860549,-302.648376,0.086124,0.000000
82.850006,55.586273,-302.648376,0.006256,0.003388,0.086055,247.260086,12.596029,0.860549,-302.648376,0.086124,0.000000
83.060005,55.564308,-302.737366,0.006286,0.003388,0.086055,247.162384,12.591053,0.860549,-302.737366,0.086124,0.000000
83.270004,55.556488,-302.692871,0.006282,0.003388,0.086055,247.127594,12.589280,0.860549,-302.692871,0.086124,0.000000
83.480003,55.531540,-302.603912,0.006243,0.003388,0.086055,247.016632,12.583627,0.860549,-302.603912,0.086124,0.000000
83.690002,55.498772,-302.737366,0.006265,0.003388,0.086055,246.870865,12.576201,0.860549,-302.737366,0.086124,0.000000
83.900002,55.482010,-302.648376,0.006278,0.003388,0.086055,246.796310,12.572403,0.860549,-302.648376,0.086124,0.000000
84.110001,55.479034,-302.737366,0.006222,0.003388,0.086055,246.783066,12.571730,0.860549,-302.737366,0.086124,0.000000
84.320007,55.416100,-302.648376,0.006230,0.003388,0.086055,246.503128,12.557468,0.860549,-302.648376,0.086124,0.000000
84.530006,55.412376,-302.737366,0.006256,0.003388,0.086055,246.486557,12.556623,0.860549,-302.737366,0.086124,0.000000
84.740005,55.395622,-302.737366,0.006265,0.003388,0.086055,246.412033,12.552827,0.860549,-302.737366,0.086124,0.000000
84.950005,55.378120,-302.692871,0.006247,0.003388,0.086055,246.334183,12.548862,0.860549,-302.692871,0.086124,0.000000
85.160004,55.357269,-302.692871,0.006265,0.003388,0.086055,246.241425,12.544136,0.860549,-302.692871,0.086124,0.000000
85.370003,55.337532,-302.737366,0.006299,0.003388,0.086055,246.153641,12.539664,0.860549,-302.737366,0.086124,0.000000
85.580002,55.312210,-302.692871,0.006247,0.003388,0.086055,246.041000,12.533926,0.860549,-302.692871,0.086124,0.000000
85.790001,55.284653,-302.737366,0.006278,0.003388,0.086055,245.918411,12.527681,0.860549,-302.737366,0.086124,0.000000
86.000008,55.283913,-302.692871,0.006234,0.003388,0.086055,245.915131,12.527514,0.860549,-302.692871,0.086124,0.000000
86.210007,55.261192,-302.737366,0.006256,0.003388,0.086055,245.814056,12.522366,0.860549,-302.737366,0.086124,0.000000
86.420006,55.236618,-302.781830,0.006265,0.003388,0.086055,245.704742,12.516797,0.860549,-302.781830,0.086124,0.000000
86.630005,55.224701,-302.692871,0.006269,0.003388,0.086055,245.651733,12.514096,0.860549,-302.692871,0.086124,0.000000
86.840004,55.189697,-302.781830,0.006278,0.003388,0.086055,245.496033,12.506164,0.860549,-302.781830,0.086124,0.000000
87.050003,55.172195,-302.781830,0.006230,0.003388,0.086055,245.418182,12.502198,0.860549,-302.781830,0.086124,0.000000
87.260002,55.162140,-302.737366,0.006265,0.003388,0.086055,245.373459,12.499920,0.860549,-302.737366,0.086124,0.000000
87.470001,55.142036,-302.781830,0.006247,0.003388,0.086055,245.284027,12.495364,0.860549,-302.781830,0.086124,0.000000
87.680008,55.124161,-302.737366,0.006282,0.003388,0.086055,245.204514,12.491314,0.860549,-302.737366,0.086124,0.000000
87.890007,55.105545,-302.826324,0.006247,0.003388,0.086055,245.121704,12.487095,0.860549,-302.826324,0.086124,0.000000
88.100006,55.083199,-302.781830,0.006252,0.003388,0.086055,245.022308,12.482031,0.860549,-302.781830,0.086124,0.000000
88.310005,55.064583,-302.781830,0.006273,0.003388,0.086055,244.939499,12.477813,0.860549,-302.781830,0.086124,0.000000
88.500008,55.047821,-302.737366,0.006226,0.003388,0.086055,244.864944,12.474014,0.860549,-302.737366,0.086124,0.000000