File: Data/Compression Sample NH 10, 12, 15, 17 batch 3/AutoNoheating-10-3-2-240212_02122024_160815.csv
Time (sec),S:Load (lbs),S:HL1 (DIM),S:LVDT (in),S:Position (in),Ch:Position (mm),Ch:Load (N),Ch:Stress (MPa),Ch:Strain (mm/mm),Ch:HL1 (DIM),Set Point (),Cycles ()
0.110000,-0.001114,-129.884384,-0.000004,-0.000000,-0.000000,-0.004955,-0.000252,-0.000000,-129.884384,0.000191,0.000000
0.330000,-0.004097,-129.839890,-0.000022,-0.000000,-0.000000,-0.018224,-0.000928,-0.000000,-129.839890,0.000191,0.000000
0.550000,-0.004097,-129.839890,0.000009,0.000109,0.002775,-0.018224,-0.000928,0.027751,-129.839890,0.003729,0.000000
0.770000,0.271835,-129.884384,0.000103,0.000252,0.006409,1.209184,0.061599,0.064090,-129.884384,0.007406,0.000000
0.990000,0.715706,-129.884384,0.000164,-0.000009,-0.000226,3.183619,0.162181,-0.002256,-129.884384,-0.000017,0.000000
1.210000,0.653145,-129.839890,0.000181,-0.000009,-0.000234,2.905333,0.148005,-0.002343,-129.839890,-0.000017,0.000000
1.430000,0.629311,-129.839890,0.000181,-0.000009,-0.000234,2.799313,0.142604,-0.002343,-129.839890,-0.000017,0.000000
1.650000,0.611809,-129.839890,0.000172,-0.000009,-0.000226,2.721461,0.138638,-0.002256,-129.839890,0.000347,0.000000
1.870000,0.630058,-129.928864,0.000194,-0.000009,-0.000217,2.802639,0.142773,-0.002169,-129.928864,0.000711,0.000000
2.090000,0.681442,-129.973343,0.000172,0.000004,0.000104,3.031207,0.154417,0.001041,-129.973343,0.001084,0.000000
2.310000,0.827042,-129.884384,0.000207,0.000023,0.000581,3.678865,0.187410,0.005810,-129.884384,0.001448,0.000000
2.530000,0.980835,-129.884384,0.000229,0.000040,0.001023,4.362972,0.222260,0.010231,-129.884384,0.001812,0.000000
2.750000,1.048973,-129.839890,0.000203,0.000051,0.001301,4.666065,0.237701,0.013009,-129.839890,0.002177,0.000000
2.970000,1.152122,-129.884384,0.000229,0.000066,0.001682,5.124897,0.261075,0.016824,-129.884384,0.002550,0.000000
3.190000,1.250053,-129.928864,0.000237,0.000078,0.001977,5.560515,0.283266,0.019772,-129.928864,0.002914,0.000000
3.410000,1.322296,-129.884384,0.000267,0.000089,0.002255,5.881867,0.299637,0.022547,-129.884384,0.003278,0.000000
3.630000,1.577003,-129.884384,0.000267,0.000109,0.002766,7.014862,0.357354,0.027664,-129.884384,0.003642,0.000000
3.850000,1.670837,-129.973343,0.000263,0.000122,0.003104,7.432256,0.378617,0.031044,-129.973343,0.004015,0.000000
4.070000,1.720734,-129.973343,0.000319,0.000131,0.003321,7.654205,0.389924,0.033212,-129.973343,0.004380,0.000000
4.290000,1.871178,-129.973343,0.000306,0.000147,0.003738,8.323414,0.424015,0.037376,-129.973343,0.004744,0.000000
4.510000,2.094223,-129.973343,0.000349,0.000170,0.004319,9.315569,0.474558,0.043186,-129.973343,0.005116,0.000000
4.730000,2.161995,-129.973343,0.000349,0.000183,0.004648,9.617034,0.489915,0.046482,-129.973343,0.005481,0.000000
4.950000,2.267380,-129.928864,0.000336,0.000198,0.005030,10.085809,0.513796,0.050297,-129.928864,0.005845,0.000000
5.170000,2.345947,-130.017822,0.000375,0.000206,0.005238,10.435294,0.531599,0.052379,-130.017822,0.006209,0.000000
5.390000,2.564163,-130.017822,0.000371,0.000225,0.005724,11.405968,0.581048,0.057235,-130.017822,0.006582,0.000000
5.610000,2.697098,-129.973343,0.000388,0.000238,0.006036,11.997290,0.611171,0.060358,-129.973343,0.006946,0.000000
5.830000,2.709015,-129.973343,0.000410,0.000245,0.006218,12.050300,0.613872,0.062178,-129.973343,0.007311,0.000000
6.050000,2.850143,-129.973343,0.000427,0.000258,0.006556,12.678071,0.645852,0.065562,-129.973343,0.007683,0.000000
6.270000,3.079147,-130.017822,0.000444,0.000283,0.007180,13.696732,0.697745,0.071803,-130.017822,0.008048,0.000000
6.490000,3.171501,-130.017822,0.000466,0.000297,0.007536,14.107542,0.718672,0.075361,-130.017822,0.008412,0.000000
6.710001,3.203522,-129.973343,0.000470,0.000308,0.007822,14.249976,0.725928,0.078222,-129.973343,0.008776,0.000000
6.930000,3.247833,-130.017822,0.000474,0.000320,0.008134,14.447083,0.735970,0.081345,-130.017822,0.009149,0.000000
7.150001,3.425827,-130.017822,0.000487,0.000335,0.008516,15.238840,0.776303,0.085160,-130.017822,0.009513,0.000000
7.370000,3.515945,-130.106781,0.000513,0.000350,0.008889,15.639707,0.796725,0.088888,-130.106781,0.009877,0.000000
7.590000,3.631004,-130.062302,0.000543,0.000364,0.009253,16.151514,0.822797,0.092533,-130.062302,0.010251,0.000000
7.810000,3.619461,-130.017822,0.000556,0.000373,0.009470,16.100166,0.820182,0.094698,-130.017822,0.010615,0.000000
8.030001,3.772881,-129.973343,0.000548,0.000391,0.009938,16.782610,0.854947,0.099384,-129.973343,0.010979,0.000000
8.250000,4.078972,-130.062302,0.000578,0.000417,0.010580,18.144173,0.924308,0.105799,-130.062302,0.011343,0.000000
8.470000,4.045456,-130.151260,0.000595,0.000430,0.010918,17.995087,0.916713,0.109183,-130.151260,0.011716,0.000000
8.690001,4.101311,-130.062302,0.000604,0.000444,0.011282,18.243542,0.929370,0.112824,-130.062302,0.012080,0.000000
8.910001,4.155304,-130.106781,0.000642,0.000456,0.011586,18.483715,0.941605,0.115859,-130.106781,0.012445,0.000000
9.130000,4.249146,-130.062302,0.000621,0.000472,0.011994,18.901144,0.962870,0.119936,-130.062302,0.012818,0.000000
9.350000,4.269257,-130.062302,0.000629,0.000484,0.012288,18.990602,0.967427,0.122884,-130.062302,0.013182,0.000000
9.570001,4.395111,-130.151260,0.000677,0.000499,0.012679,19.550430,0.995946,0.126786,-130.151260,0.013546,0.000000
9.790001,4.412987,-130.062302,0.000690,0.000509,0.012922,19.629946,0.999997,0.129216,-130.062302,0.013910,0.000000
10.010000,4.598061,-130.106781,0.000681,0.000531,0.013476,20.453196,1.041935,0.134765,-130.106781,0.014283,0.000000
10.230000,4.703812,-130.062302,0.000716,0.000548,0.013919,20.923599,1.065899,0.139190,-130.062302,0.014647,0.000000
10.450001,4.682213,-130.151260,0.000733,0.000561,0.014257,20.827522,1.061005,0.142569,-130.151260,0.015012,0.000000
10.670000,4.716843,-130.106781,0.000759,0.000574,0.014569,20.981564,1.068852,0.145692,-130.106781,0.015384,0.000000
10.890000,4.750359,-130.195740,0.000737,0.000586,0.014890,21.130650,1.076447,0.148902,-130.195740,0.015749,0.000000
11.110001,4.859833,-130.106781,0.000772,0.000603,0.015315,21.617617,1.101254,0.153152,-130.106781,0.016113,0.000000
11.330001,4.963730,-130.062302,0.000793,0.000619,0.015723,22.079773,1.124797,0.157228,-130.062302,0.016477,0.000000
11.550000,4.958511,-130.195740,0.000798,0.000628,0.015948,22.056561,1.123615,0.159480,-130.195740,0.016850,0.000000
11.770000,4.959259,-130.151260,0.000802,0.000637,0.016182,22.059885,1.123784,0.161823,-130.151260,0.017214,0.000000
11.990001,5.191620,-130.195740,0.000828,0.000660,0.016763,23.093479,1.176438,0.167633,-130.195740,0.017579,0.000000
12.210001,5.253433,-130.195740,0.000849,0.000676,0.017180,23.368439,1.190445,0.171796,-130.195740,0.017951,0.000000
12.430000,5.245239,-130.151260,0.000867,0.000690,0.017535,23.331989,1.188588,0.175350,-130.151260,0.018315,0.000000
12.650001,5.285828,-130.240219,0.000880,0.000703,0.017856,23.512535,1.197786,0.178560,-130.240219,0.018680,0.000000
12.870001,5.340195,-130.195740,0.000880,0.000715,0.018168,23.754372,1.210105,0.181683,-130.195740,0.019044,0.000000
13.090000,5.424355,-130.195740,0.000918,0.000729,0.018515,24.128735,1.229176,0.185149,-130.195740,0.019417,0.000000
13.310000,5.549469,-130.195740,0.000931,0.000747,0.018966,24.685270,1.257528,0.189661,-130.195740,0.019781,0.000000
13.530001,5.488029,-130.151260,0.000936,0.000755,0.019166,24.411974,1.243605,0.191656,-130.151260,0.020145,0.000000
13.750001,5.609421,-130.195740,0.000940,0.000771,0.019582,24.951950,1.271113,0.195819,-130.195740,0.020518,0.000000
13.970000,5.745338,-130.284698,0.000940,0.000790,0.020059,25.556541,1.301912,0.200588,-130.284698,0.020883,0.000000
14.190001,5.835449,-130.240219,0.000979,0.000805,0.020449,25.957375,1.322332,0.204490,-130.240219,0.021247,0.000000
14.410001,5.841408,-130.195740,0.001000,0.000819,0.020804,25.983879,1.323682,0.208044,-130.195740,0.021611,0.000000
14.630001,5.879021,-130.151260,0.000987,0.000833,0.021152,26.151190,1.332205,0.211515,-130.151260,0.021984,0.000000
14.850000,5.908806,-130.240219,0.001013,0.000844,0.021438,26.283682,1.338955,0.214376,-130.240219,0.022348,0.000000
15.070001,6.099464,-130.284698,0.001022,0.000865,0.021967,27.131773,1.382158,0.219668,-130.284698,0.022712,0.000000
15.290001,6.076004,-130.240219,0.001056,0.000876,0.022253,27.027416,1.376842,0.222529,-130.240219,0.023086,0.000000
15.510001,5.943810,-130.240219,0.001056,0.000880,0.022357,26.439384,1.346886,0.223570,-130.240219,0.023450,0.000000
15.730000,6.121803,-130.240219,0.001074,0.000897,0.022773,27.231140,1.387221,0.227733,-130.240219,0.023814,0.000000
15.950001,6.320656,-130.284698,0.001082,0.000916,0.023259,28.115681,1.432281,0.232589,-130.284698,0.024178,0.000000
16.170000,6.317299,-130.284698,0.001117,0.000928,0.023571,28.100748,1.431520,0.235712,-130.284698,0.024551,0.000000
16.390001,6.329590,-130.240219,0.001121,0.000940,0.023866,28.155422,1.434306,0.238660,-130.240219,0.024915,0.000000
16.610001,6.432365,-130.329193,0.001121,0.000956,0.024291,28.612591,1.457595,0.242907,-130.329193,0.025279,0.000000
16.830000,6.420074,-130.284698,0.001143,0.000968,0.024586,28.557917,1.454810,0.245855,-130.284698,0.025644,0.000000
17.050001,6.613708,-130.284698,0.001160,0.000985,0.025028,29.419245,1.498688,0.250280,-130.284698,0.026017,0.000000
17.270000,6.589882,-130.329193,0.001173,0.000997,0.025332,29.313259,1.493289,0.253315,-130.329193,0.026381,0.000000
17.490002,6.620415,-130.329193,0.001186,0.001009,0.025618,29.449076,1.500207,0.256177,-130.329193,0.026745,0.000000
17.710001,6.732872,-130.329193,0.001216,0.001024,0.026017,29.949310,1.525691,0.260166,-130.329193,0.027118,0.000000
17.930000,6.938789,-130.284698,0.001199,0.001045,0.026554,30.865276,1.572352,0.265544,-130.284698,0.027482,0.000000
18.150002,7.044914,-130.284698,0.001246,0.001061,0.026953,31.337343,1.596400,0.269534,-130.284698,0.027847,0.000000
18.370001,7.058319,-130.329193,0.001250,0.001076,0.027335,31.396971,1.599438,0.273349,-130.329193,0.028211,0.000000
18.590000,7.058693,-130.373672,0.001250,0.001089,0.027664,31.398634,1.599523,0.276642,-130.373672,0.028584,0.000000
18.810001,7.069122,-130.329193,0.001263,0.001102,0.027985,31.445026,1.601886,0.279851,-130.329193,0.028948,0.000000
19.030001,7.217697,-130.418152,0.001319,0.001118,0.028393,32.105919,1.635554,0.283928,-130.418152,0.029312,0.000000
19.250000,6.931717,-130.373672,0.001281,0.001118,0.028401,30.833817,1.570750,0.284015,-130.373672,0.029685,0.000000
19.470001,7.328293,-130.418152,0.001319,0.001144,0.029060,32.597874,1.660615,0.290604,-130.418152,0.030049,0.000000
19.690001,7.495491,-130.373672,0.001350,0.001163,0.029538,33.341610,1.698503,0.295377,-130.373672,0.030414,0.000000
19.910002,7.515594,-130.373672,0.001367,0.001178,0.029919,33.431034,1.703058,0.299192,-130.373672,0.030778,0.000000
20.130001,7.633636,-130.418152,0.001354,0.001196,0.030379,33.956112,1.729807,0.303787,-130.418152,0.031150,0.000000
20.350000,7.507034,-130.373672,0.001401,0.001206,0.030622,33.392956,1.701118,0.306217,-130.373672,0.031515,0.000000
20.570002,7.644806,-130.462631,0.001393,0.001223,0.031055,34.005795,1.732338,0.310551,-130.462631,0.031879,0.000000
20.790001,7.686890,-130.373672,0.001436,0.001235,0.031376,34.192993,1.741874,0.313760,-130.373672,0.032252,0.000000
21.010000,7.777374,-130.373672,0.001431,0.001250,0.031749,34.595490,1.762378,0.317488,-130.373672,0.032616,0.000000
21.230001,7.883125,-130.373672,0.001466,0.001265,0.032131,35.065891,1.786342,0.321307,-130.373672,0.032980,0.000000
21.450001,7.749817,-130.329193,0.001462,0.001272,0.032321,34.472908,1.756134,0.323215,-130.329193,0.033345,0.000000
21.670000,7.983299,-130.462631,0.001466,0.001293,0.032850,35.511490,1.809041,0.328502,-130.462631,0.033718,0.000000
21.890001,8.180283,-130.418152,0.001500,0.001311,0.033301,36.387714,1.853679,0.333014,-130.418152,0.034082,0.000000
22.110001,8.110649,-130.418152,0.001509,0.001321,0.033561,36.077969,1.837899,0.335614,-130.418152,0.034446,0.000000
22.330002,8.112511,-130.373672,0.001492,0.001335,0.033900,36.086250,1.838321,0.338998,-130.373672,0.034819,0.000000
22.550001,8.025002,-130.418152,0.001518,0.001345,0.034151,35.696991,1.818491,0.341511,-130.418152,0.035183,0.000000
22.770000,8.065216,-130.551590,0.001531,0.001353,0.034359,35.875874,1.827604,0.343593,-130.551590,0.035547,0.000000
22.990002,8.431633,-130.507111,0.001556,0.001378,0.035001,37.505775,1.910635,0.350012,-130.507111,0.035912,0.000000
23.210001,8.584305,-130.418152,0.001595,0.001394,0.035418,38.184895,1.945231,0.354175,-130.418152,0.036285,0.000000
23.430000,8.564194,-130.418152,0.001600,0.001407,0.035747,38.095436,1.940674,0.357468,-130.418152,0.036649,0.000000
23.650002,8.646118,-130.507111,0.001587,0.001422,0.036120,38.459854,1.959238,0.361196,-130.507111,0.037013,0.000000
23.870001,8.801399,-130.462631,0.001604,0.001440,0.036588,39.150578,1.994426,0.365882,-130.462631,0.037386,0.000000
24.090002,8.727669,-130.507111,0.001634,0.001452,0.036892,38.822609,1.977718,0.368917,-130.507111,0.037750,0.000000
24.310001,8.756340,-130.418152,0.001643,0.001466,0.037238,38.950146,1.984215,0.372384,-130.418152,0.038114,0.000000
24.530001,8.764160,-130.507111,0.001677,0.001477,0.037525,38.984932,1.985987,0.375246,-130.507111,0.038479,0.000000
24.750002,8.883690,-130.551590,0.001660,0.001492,0.037906,39.516624,2.013073,0.379065,-130.551590,0.038852,0.000000
24.970001,9.091103,-130.507111,0.001694,0.001510,0.038349,40.439243,2.060073,0.383486,-130.507111,0.039216,0.000000
25.190001,9.128716,-130.551590,0.001686,0.001522,0.038652,40.606556,2.068597,0.386521,-130.551590,0.039580,0.000000
25.410002,9.000992,-130.462631,0.001720,0.001532,0.038903,40.038410,2.039654,0.389034,-130.462631,0.039953,0.000000
25.630001,9.334267,-130.507111,0.001738,0.001555,0.039485,41.520893,2.115175,0.394848,-130.507111,0.040317,0.000000
25.850000,9.514122,-130.507111,0.001746,0.001571,0.039909,42.320927,2.155931,0.399094,-130.507111,0.040682,0.000000
26.070002,9.413948,-130.596069,0.001759,0.001582,0.040187,41.875332,2.133231,0.401873,-130.596069,0.041046,0.000000
26.290001,9.507042,-130.551590,0.001772,0.001599,0.040603,42.289436,2.154327,0.406032,-130.551590,0.041418,0.000000
26.510002,9.378204,-130.551590,0.001772,0.001607,0.040820,41.716335,2.125131,0.408201,-130.551590,0.041783,0.000000
26.730001,9.693604,-130.640549,0.001807,0.001627,0.041323,43.119301,2.196602,0.413231,-130.640549,0.042147,0.000000
26.950001,9.693604,-130.551590,0.001824,0.001637,0.041592,43.119301,2.196602,0.415918,-130.551590,0.042520,0.000000
27.170002,9.725258,-130.551590,0.001824,0.001650,0.041904,43.260109,2.203775,0.419041,-130.551590,0.042884,0.000000
27.390001,9.700676,-130.596069,0.001841,0.001663,0.042234,43.150761,2.198205,0.422338,-130.596069,0.043248,0.000000
27.610001,10.121834,-130.596069,0.001854,0.001684,0.042780,45.024166,2.293640,0.427803,-130.596069,0.043613,0.000000
27.830002,10.094276,-130.596069,0.001867,0.001696,0.043066,44.901585,2.287396,0.430664,-130.596069,0.043985,0.000000
28.050001,10.067841,-130.596069,0.001884,0.001707,0.043370,44.783993,2.281405,0.433700,-130.596069,0.044350,0.000000
28.270000,10.116615,-130.640549,0.001906,0.001721,0.043725,45.000954,2.292458,0.437254,-130.640549,0.044714,0.000000
28.490002,10.304665,-130.685028,0.001914,0.001738,0.044150,45.837437,2.335070,0.441504,-130.685028,0.045087,0.000000
28.710001,10.439468,-130.596069,0.001957,0.001752,0.044506,46.437073,2.365618,0.445058,-130.596069,0.045451,0.000000
28.930002,10.387703,-130.596069,0.001940,0.001763,0.044775,46.206810,2.353887,0.447746,-130.596069,0.045815,0.000000
29.150002,10.302055,-130.596069,0.001970,0.001773,0.045035,45.825832,2.334479,0.450350,-130.596069,0.046180,0.000000
29.370001,10.804016,-130.685028,0.001966,0.001796,0.045625,48.058662,2.448225,0.456246,-130.685028,0.046553,0.000000
29.590002,10.914986,-130.640549,0.001996,0.001811,0.045997,48.552280,2.473371,0.459974,-130.640549,0.046917,0.000000
29.810001,11.009193,-130.640549,0.002005,0.001828,0.046440,48.971336,2.494719,0.464399,-130.640549,0.047281,0.000000
30.030001,11.047180,-130.640549,0.002026,0.001843,0.046804,49.140312,2.503327,0.468040,-130.640549,0.047645,0.000000
30.250002,11.012543,-130.685028,0.002039,0.001855,0.047108,48.986237,2.495478,0.471076,-130.685028,0.048018,0.000000
30.470001,11.222939,-130.685028,0.002065,0.001873,0.047584,49.922123,2.543154,0.475845,-130.685028,0.048382,0.000000
30.690001,11.210648,-130.685028,0.002078,0.001885,0.047871,49.867451,2.540369,0.478706,-130.685028,0.048747,0.000000
30.910002,11.342094,-130.685028,0.002078,0.001899,0.048244,50.452156,2.570155,0.482438,-130.685028,0.049120,0.000000
31.130001,11.369278,-130.685028,0.002100,0.001914,0.048625,50.573074,2.576315,0.486253,-130.685028,0.049484,0.000000
31.350002,11.562538,-130.729523,0.002091,0.001929,0.048989,51.432739,2.620109,0.489894,-130.729523,0.049848,0.000000
31.570002,11.783356,-130.729523,0.002126,0.001947,0.049466,52.414986,2.670146,0.494663,-130.729523,0.050212,0.000000
31.790001,11.725639,-130.729523,0.002143,0.001960,0.049796,52.158249,2.657068,0.497960,-130.729523,0.050585,0.000000
32.010002,11.724892,-130.640549,0.002169,0.001973,0.050108,52.154922,2.656898,0.501082,-130.640549,0.050949,0.000000
32.230003,11.792664,-130.729523,0.002151,0.001986,0.050455,52.456387,2.672256,0.504549,-130.729523,0.051314,0.000000
32.450001,12.040291,-130.774002,0.002182,0.002003,0.050871,53.557888,2.728369,0.508713,-130.774002,0.051687,0.000000
32.670002,12.216797,-130.729523,0.002216,0.002018,0.051261,54.343025,2.768366,0.512615,-130.729523,0.052051,0.000000
32.890003,12.109558,-130.729523,0.002229,0.002027,0.051478,53.866005,2.744065,0.514784,-130.729523,0.052415,0.000000
33.110001,12.100616,-130.729523,0.002225,0.002042,0.051860,53.826229,2.742039,0.518599,-130.729523,0.052779,0.000000
33.330002,12.569809,-130.729523,0.002229,0.002062,0.052363,55.913303,2.848359,0.523629,-130.729523,0.053152,0.000000
33.550003,12.674072,-130.774002,0.002246,0.002076,0.052736,56.377090,2.871986,0.527357,-130.774002,0.053517,0.000000
33.770000,12.717270,-130.774002,0.002285,0.002091,0.053109,56.569241,2.881774,0.531089,-130.774002,0.053881,0.000000
33.990002,12.738861,-130.685028,0.002315,0.002104,0.053447,56.665283,2.886667,0.534469,-130.685028,0.054253,0.000000
34.210003,12.760086,-130.818481,0.002311,0.002116,0.053742,56.759697,2.891477,0.537417,-130.818481,0.054618,0.000000
34.430000,12.898613,-130.774002,0.002324,0.002131,0.054115,57.375896,2.922868,0.541149,-130.774002,0.054982,0.000000
34.650002,13.123528,-130.818481,0.002320,0.002147,0.054531,58.376366,2.973834,0.545309,-130.818481,0.055346,0.000000
34.870003,12.940315,-130.729523,0.002333,0.002154,0.054713,57.561398,2.932317,0.547133,-130.729523,0.055719,0.000000
35.090000,13.257210,-130.774002,0.002337,0.002172,0.055164,58.971016,3.004127,0.551641,-130.774002,0.056083,0.000000
35.310001,13.634422,-130.729523,0.002363,0.002189,0.055607,60.648941,3.089604,0.556065,-130.729523,0.056448,0.000000
35.530003,13.795288,-130.774002,0.002376,0.002205,0.056014,61.364506,3.126057,0.560138,-130.774002,0.056820,0.000000
35.750000,13.866409,-130.818481,0.002397,0.002221,0.056421,61.680870,3.142173,0.564214,-130.818481,0.057185,0.000000
35.970001,13.913330,-130.862961,0.002436,0.002234,0.056742,61.889584,3.152806,0.567424,-130.862961,0.057549,0.000000
36.190002,13.919289,-130.818481,0.002423,0.002246,0.057037,61.916088,3.154156,0.570372,-130.818481,0.057913,0.000000
36.410000,14.307671,-130.729523,0.002453,0.002264,0.057497,63.643696,3.242165,0.574971,-130.729523,0.058286,0.000000
36.630001,14.274529,-130.907440,0.002453,0.002275,0.057775,63.496273,3.234654,0.577745,-130.907440,0.058650,0.000000
36.850002,14.065628,-130.818481,0.002453,0.002283,0.057991,62.567039,3.187317,0.579914,-130.818481,0.059014,0.000000
37.070004,14.243622,-130.818481,0.002471,0.002298,0.058364,63.358795,3.227651,0.583642,-130.818481,0.059388,0.000000
37.290001,14.794357,-130.862961,0.002514,0.002317,0.058850,65.808586,3.352449,0.588498,-130.862961,0.059752,0.000000
37.510002,14.811119,-130.862961,0.002522,0.002329,0.059162,65.883148,3.356247,0.591621,-130.862961,0.060116,0.000000
37.730003,14.775368,-130.862961,0.002514,0.002343,0.059500,65.724121,3.348146,0.595001,-130.862961,0.060480,0.000000
37.950001,15.061348,-130.907440,0.002544,0.002357,0.059865,66.996223,3.412950,0.598646,-130.907440,0.060853,0.000000
38.170002,15.094864,-130.951920,0.002548,0.002370,0.060203,67.145309,3.420545,0.602025,-130.951920,0.061217,0.000000
38.390003,15.591980,-130.862961,0.002561,0.002388,0.060662,69.356590,3.533193,0.606624,-130.862961,0.061581,0.000000
38.610001,15.395744,-130.862961,0.002561,0.002396,0.060862,68.483688,3.488726,0.608619,-130.862961,0.061955,0.000000
38.830002,15.461655,-130.862961,0.002565,0.002408,0.061157,68.776878,3.503661,0.611567,-130.862961,0.062319,0.000000
39.050003,15.892860,-130.907440,0.002591,0.002426,0.061625,70.694977,3.601374,0.616249,-130.907440,0.062683,0.000000
39.270000,16.273048,-130.951920,0.002587,0.002443,0.062059,72.386131,3.687526,0.620587,-130.951920,0.063047,0.000000
39.490002,16.501686,-130.907440,0.002652,0.002461,0.062509,73.403168,3.739336,0.625094,-130.907440,0.063420,0.000000
39.710003,16.620850,-130.862961,0.002652,0.002475,0.062865,73.933235,3.766338,0.628652,-130.862961,0.063784,0.000000
39.930000,16.678192,-130.951920,0.002669,0.002489,0.063212,74.188301,3.779332,0.632119,-130.951920,0.064149,0.000000
40.150002,16.771286,-130.907440,0.002660,0.002503,0.063576,74.602409,3.800428,0.635760,-130.907440,0.064521,0.000000
40.370003,17.004761,-131.040878,0.002686,0.002517,0.063932,75.640953,3.853334,0.639318,-131.040878,0.064886,0.000000
40.590000,17.055031,-130.907440,0.002690,0.002529,0.064235,75.864563,3.864725,0.642353,-130.907440,0.065250,0.000000
40.810001,17.212921,-130.951920,0.002703,0.002543,0.064582,76.566895,3.900504,0.645820,-130.951920,0.065614,0.000000
41.030003,17.628113,-130.907440,0.002712,0.002561,0.065051,78.413765,3.994587,0.650506,-130.907440,0.065987,0.000000
41.250004,17.995644,-130.996399,0.002755,0.002580,0.065536,80.048622,4.077871,0.655362,-130.996399,0.066351,0.000000
41.470001,18.292427,-130.996399,0.002733,0.002597,0.065961,81.368782,4.145123,0.659609,-130.996399,0.066716,0.000000
41.690002,18.102890,-130.951920,0.002790,0.002607,0.066213,80.525673,4.102174,0.662126,-130.951920,0.067080,0.000000
41.910004,18.433929,-130.907440,0.002811,0.002623,0.066620,81.998215,4.177188,0.666202,-130.907440,0.067453,0.000000
42.130001,18.494629,-130.951920,0.002798,0.002635,0.066932,82.268219,4.190943,0.669325,-130.951920,0.067817,0.000000
42.350002,18.697945,-130.996399,0.002794,0.002648,0.067253,83.172615,4.237015,0.672530,-130.996399,0.068181,0.000000
42.570004,19.034569,-131.040878,0.002820,0.002663,0.067652,84.669991,4.313295,0.676520,-131.040878,0.068554,0.000000
42.790001,18.894554,-130.996399,0.002833,0.002672,0.067869,84.047173,4.281567,0.678688,-130.996399,0.068918,0.000000
43.010002,19.761810,-130.951920,0.002871,0.002695,0.068450,87.904922,4.478090,0.684498,-130.951920,0.069283,0.000000
43.230003,20.072739,-130.996399,0.002854,0.002711,0.068849,89.288002,4.548547,0.688488,-130.996399,0.069647,0.000000
43.450001,19.933846,-130.996399,0.002876,0.002719,0.069066,88.670174,4.517074,0.690656,-130.996399,0.070020,0.000000
43.670002,20.117798,-130.996399,0.002906,0.002734,0.069456,89.488434,4.558758,0.694559,-130.996399,0.070384,0.000000
43.890003,20.069389,-131.040878,0.002902,0.002746,0.069742,89.273102,4.547789,0.697420,-131.040878,0.070748,0.000000
44.110001,20.226906,-131.040878,0.002923,0.002758,0.070063,89.973770,4.583482,0.700629,-131.040878,0.071121,0.000000
44.330002,21.345512,-130.996399,0.002932,0.002782,0.070661,94.949585,4.836962,0.706613,-130.996399,0.071485,0.000000
44.550003,21.434875,-131.040878,0.002949,0.002794,0.070974,95.347092,4.857212,0.709736,-131.040878,0.071849,0.000000
44.770000,21.553291,-131.085358,0.002940,0.002806,0.071277,95.873825,4.884046,0.712771,-131.085358,0.072214,0.000000
44.990002,21.844490,-130.996399,0.002966,0.002821,0.071641,97.169144,4.950032,0.716412,-130.996399,0.072587,0.000000
45.210003,22.468216,-131.085358,0.003005,0.002840,0.072144,99.943619,5.091371,0.721443,-131.085358,0.072951,0.000000
45.430000,22.420921,-131.085358,0.003001,0.002851,0.072413,99.733238,5.080654,0.724134,-131.085358,0.073315,0.000000
45.650002,22.606735,-131.085358,0.002988,0.002865,0.072769,100.559784,5.122759,0.727688,-131.085358,0.073688,0.000000
45.870003,22.726639,-131.129837,0.003027,0.002876,0.073046,101.093140,5.149930,0.730462,-131.129837,0.074052,0.000000
46.090004,22.921021,-131.085358,0.003048,0.002890,0.073411,101.957794,5.193977,0.734107,-131.085358,0.074416,0.000000
46.310001,23.832954,-131.040878,0.003031,0.002909,0.073888,106.014275,5.400625,0.738876,-131.040878,0.074781,0.000000
46.530003,23.993446,-131.085358,0.003061,0.002920,0.074174,106.728180,5.436993,0.741737,-131.085358,0.075154,0.000000
46.750004,23.982651,-131.174332,0.003044,0.002932,0.074469,106.680161,5.434546,0.744686,-131.174332,0.075518,0.000000
46.970001,25.069237,-131.129837,0.003100,0.002957,0.075102,111.513535,5.680770,0.751018,-131.129837,0.075882,0.000000
47.190002,25.421127,-131.129837,0.003113,0.002970,0.075431,113.078819,5.760509,0.754311,-131.129837,0.076255,0.000000
47.410004,25.325050,-131.129837,0.003130,0.002981,0.075726,112.651451,5.738738,0.757259,-131.129837,0.076619,0.000000
47.630001,25.832970,-131.040878,0.003126,0.002998,0.076142,114.910789,5.853835,0.761422,-131.040878,0.076984,0.000000
47.850002,25.698914,-131.174332,0.003147,0.003009,0.076420,114.314476,5.823457,0.764197,-131.174332,0.077348,0.000000
48.070004,26.503242,-131.174332,0.003134,0.003026,0.076853,117.892311,6.005721,0.768534,-131.174332,0.077721,0.000000
48.290001,26.695755,-131.174332,0.003165,0.003037,0.077148,118.748650,6.049345,0.771483,-131.174332,0.078085,0.000000
48.510002,26.950829,-131.174332,0.003169,0.003049,0.077443,119.883270,6.107145,0.774431,-131.174332,0.078449,0.000000
48.730003,27.144836,-131.174332,0.003169,0.003063,0.077807,120.746262,6.151108,0.778072,-131.174332,0.078822,0.000000
48.950001,27.992729,-131.174332,0.003199,0.003082,0.078276,124.517876,6.343243,0.782758,-131.174332,0.079186,0.000000
49.170002,28.172958,-131.174332,0.003203,0.003091,0.078518,125.319580,6.384083,0.785184,-131.174332,0.079551,0.000000
49.390003,28.498039,-131.218811,0.003199,0.003106,0.078900,126.765610,6.457748,0.788999,-131.218811,0.079915,0.000000
49.610001,28.935204,-131.174332,0.003234,0.003122,0.079308,128.710220,6.556811,0.793076,-131.174332,0.080287,0.000000
49.830002,29.678459,-131.174332,0.003242,0.003138,0.079706,132.016373,6.725235,0.797065,-131.174332,0.080652,0.000000
50.050003,30.021042,-131.174332,0.003234,0.003152,0.080062,133.540268,6.802865,0.800623,-131.174332,0.081016,0.000000
50.270004,30.114510,-131.263290,0.003251,0.003161,0.080296,133.956024,6.824046,0.802962,-131.263290,0.081389,0.000000
50.490002,30.256752,-131.218811,0.003277,0.003175,0.080635,134.588760,6.856278,0.806345,-131.218811,0.081753,0.000000
50.710003,31.475159,-131.218811,0.003285,0.003196,0.081189,140.008499,7.132373,0.811894,-131.218811,0.082117,0.000000
50.930004,31.939880,-131.218811,0.003333,0.003210,0.081528,142.075684,7.237680,0.815278,-131.218811,0.082482,0.000000
51.150002,32.586693,-131.263290,0.003311,0.003228,0.081987,144.952850,7.384250,0.819873,-131.263290,0.082855,0.000000
51.370003,33.041359,-131.263290,0.003324,0.003242,0.082334,146.975311,7.487279,0.823343,-131.263290,0.083219,0.000000
51.590004,33.232010,-131.218811,0.003350,0.003255,0.082672,147.823364,7.530481,0.826723,-131.218811,0.083583,0.000000
51.810001,33.852013,-131.174332,0.003359,0.003272,0.083106,150.581268,7.670976,0.831061,-131.174332,0.083956,0.000000
52.030003,34.109695,-131.218811,0.003346,0.003282,0.083375,151.727509,7.729368,0.833748,-131.218811,0.084320,0.000000
52.250004,34.724480,-131.307770,0.003359,0.003298,0.083765,154.462204,7.868680,0.837650,-131.307770,0.084684,0.000000
52.470001,34.956841,-131.263290,0.003380,0.003312,0.084130,155.495789,7.921333,0.841295,-131.263290,0.085049,0.000000
52.690002,35.911606,-131.352249,0.003389,0.003330,0.084589,159.742798,8.137686,0.845890,-131.352249,0.085422,0.000000
52.910004,36.785561,-131.263290,0.003428,0.003348,0.085031,163.630341,8.335728,0.850314,-131.263290,0.085786,0.000000
53.130001,37.054413,-131.307770,0.003423,0.003360,0.085335,164.826263,8.396650,0.853350,-131.307770,0.086150,0.000000
53.350002,37.291618,-131.307770,0.003432,0.003371,0.085630,165.881409,8.450401,0.856298,-131.307770,0.086523,0.000000
53.570004,37.722450,-131.352249,0.003449,0.003385,0.085968,167.797836,8.548030,0.859678,-131.352249,0.086887,0.000000
53.790001,38.590454,-131.307770,0.003466,0.003403,0.086436,171.658920,8.744721,0.864364,-131.307770,0.087251,0.000000
54.010002,39.178429,-131.263290,0.003458,0.003417,0.086783,174.274353,8.877959,0.867831,-131.263290,0.087616,0.000000
54.230003,39.427917,-131.352249,0.003466,0.003426,0.087009,175.384140,8.934494,0.870087,-131.352249,0.087989,0.000000
54.450001,39.798424,-131.352249,0.003471,0.003441,0.087399,177.032227,9.018452,0.873989,-131.352249,0.088353,0.000000
54.670002,40.895805,-131.352249,0.003479,0.003459,0.087858,181.913635,9.267122,0.878584,-131.352249,0.088717,0.000000
54.890003,41.701248,-131.352249,0.003484,0.003475,0.088275,185.496414,9.449637,0.882747,-131.352249,0.089081,0.000000
55.110004,42.366676,-131.307770,0.003540,0.003491,0.088665,188.456390,9.600426,0.886649,-131.307770,0.089454,0.000000
55.330002,42.819855,-131.307770,0.003518,0.003503,0.088977,190.472229,9.703118,0.889772,-131.307770,0.089819,0.000000
55.550003,43.137863,-131.352249,0.003505,0.003514,0.089246,191.886795,9.775180,0.892459,-131.352249,0.090183,0.000000
55.770004,43.971977,-131.396729,0.003535,0.003530,0.089654,195.597122,9.964192,0.896536,-131.396729,0.090556,0.000000
55.990002,44.653793,-131.396729,0.003561,0.003545,0.090035,198.629990,10.118694,0.900351,-131.396729,0.090920,0.000000
56.210003,44.822845,-131.352249,0.003548,0.003553,0.090235,199.381973,10.157002,0.902345,-131.352249,0.091284,0.000000
56.430004,45.618607,-131.396729,0.003557,0.003571,0.090703,202.921692,10.337324,0.907031,-131.396729,0.091648,0.000000
56.650002,46.827705,-131.352249,0.003566,0.003589,0.091154,208.300034,10.611310,0.911539,-131.352249,0.092021,0.000000
56.870003,47.675591,-131.396729,0.003596,0.003604,0.091553,212.071625,10.803443,0.915528,-131.396729,0.092386,0.000000
57.090004,48.406563,-131.441208,0.003587,0.003621,0.091969,215.323151,10.969084,0.919692,-131.441208,0.092750,0.000000
57.310001,48.893997,-131.396729,0.003604,0.003633,0.092273,217.491364,11.079537,0.922727,-131.396729,0.093122,0.000000
57.530003,49.385155,-131.396729,0.003622,0.003645,0.092585,219.676132,11.190837,0.925850,-131.396729,0.093487,0.000000
57.750004,50.471741,-131.396729,0.003617,0.003662,0.093018,224.509521,11.437060,0.930183,-131.396729,0.093851,0.000000
57.970001,50.955826,-131.396729,0.003617,0.003673,0.093296,226.662827,11.546756,0.932961,-131.396729,0.094215,0.000000
58.190002,50.993805,-131.396729,0.003639,0.003682,0.093513,226.831772,11.555361,0.935126,-131.396729,0.094588,0.000000
58.410004,51.887123,-131.441208,0.003669,0.003699,0.093955,230.805450,11.757790,0.939551,-131.441208,0.094952,0.000000
58.630001,53.038132,-131.396729,0.003665,0.003715,0.094371,235.925400,12.018613,0.943714,-131.396729,0.095317,0.000000
58.850002,53.686806,-131.441208,0.003656,0.003728,0.094684,238.810837,12.165604,0.946837,-131.441208,0.095690,0.000000
59.070004,54.230095,-131.485687,0.003665,0.003742,0.095048,241.227509,12.288715,0.950478,-131.485687,0.096054,0.000000
59.290001,55.105911,-131.485687,0.003691,0.003755,0.095377,245.123337,12.487179,0.953775,-131.485687,0.096418,0.000000
59.510002,55.541962,-131.396729,0.003678,0.003767,0.095672,247.062988,12.585989,0.956723,-131.396729,0.096782,0.000000
59.730003,57.065712,-131.441208,0.003717,0.003786,0.096175,253.840958,12.931275,0.961753,-131.441208,0.097155,0.000000
59.950005,57.317436,-131.485687,0.003704,0.003795,0.096383,254.960693,12.988317,0.963835,-131.485687,0.097519,0.000000
60.170002,57.960518,-131.530167,0.003717,0.003805,0.096652,257.821259,13.134041,0.966522,-131.530167,0.097884,0.000000
60.390003,59.079872,-131.574646,0.003729,0.003825,0.097147,262.800385,13.387691,0.971465,-131.574646,0.098257,0.000000
60.610004,60.494141,-131.485687,0.003725,0.003842,0.097597,269.091370,13.708169,0.975973,-131.485687,0.098621,0.000000
60.830002,61.556519,-131.485687,0.003747,0.003859,0.098031,273.817078,13.948906,0.980310,-131.485687,0.098985,0.000000
61.050003,62.399948,-131.485687,0.003755,0.003873,0.098386,277.568817,14.140031,0.983865,-131.485687,0.099349,0.000000
61.270004,63.139099,-131.574646,0.003751,0.003887,0.098734,280.856750,14.307525,0.987335,-131.574646,0.099722,0.000000
61.490002,63.800064,-131.530167,0.003786,0.003900,0.099054,283.796844,14.457301,0.990545,-131.530167,0.100086,0.000000
61.710003,64.821106,-131.485687,0.003781,0.003915,0.099445,288.338684,14.688673,0.994447,-131.485687,0.100451,0.000000
61.930004,65.589310,-131.485687,0.003768,0.003927,0.099757,291.755829,14.862750,0.997570,-131.485687,0.100824,0.000000
62.150002,66.365341,-131.530167,0.003777,0.003941,0.100095,295.207794,15.038601,1.000950,-131.530167,0.101188,0.000000
62.370003,67.347656,-131.574646,0.003786,0.003948,0.100269,299.577332,15.261197,1.002687,-131.574646,0.100494,0.000000
62.590004,66.691162,-131.574646,0.003811,0.003948,0.100269,296.657104,15.112432,1.002687,-131.574646,0.100494,0.000000
62.810001,66.143402,-131.574646,0.003798,0.003945,0.100208,294.220551,14.988309,1.002077,-131.574646,0.100269,0.000000
63.030003,65.611664,-131.530167,0.003803,0.003944,0.100173,291.855255,14.867816,1.001729,-131.530167,0.100269,0.000000
63.250004,65.164062,-131.574646,0.003798,0.003943,0.100156,289.864227,14.766387,1.001559,-131.574646,0.100269,0.000000
63.470001,64.768982,-131.619141,0.003811,0.003943,0.100147,288.106812,14.676862,1.001472,-131.619141,0.100269,0.000000
63.690002,64.408524,-131.574646,0.003833,0.003942,0.100138,286.503418,14.595181,1.001385,-131.574646,0.100269,0.000000
63.910004,64.083817,-131.485687,0.003837,0.003942,0.100130,285.059052,14.521601,1.001298,-131.485687,0.100269,0.000000
64.130005,63.787781,-131.574646,0.003820,0.003942,0.100121,283.742218,14.454517,1.001211,-131.574646,0.100269,0.000000
64.350006,63.517807,-131.619141,0.003820,0.003942,0.100121,282.541321,14.393341,1.001211,-131.619141,0.100269,0.000000
64.570000,63.254166,-131.574646,0.003807,0.003942,0.100121,281.368591,14.333598,1.001211,-131.574646,0.100269,0.000000
64.790001,63.024788,-131.619141,0.003837,0.003941,0.100112,280.348267,14.281621,1.001124,-131.619141,0.100269,0.000000
65.010002,62.822212,-131.574646,0.003811,0.003941,0.100112,279.447144,14.235717,1.001124,-131.574646,0.100269,0.000000
65.230003,62.621506,-131.574646,0.003816,0.003941,0.100112,278.554382,14.190236,1.001124,-131.574646,0.100269,0.000000
65.450005,62.429733,-131.619141,0.003829,0.003941,0.100112,277.701324,14.146779,1.001124,-131.619141,0.100269,0.000000
65.670006,62.232002,-131.619141,0.003824,0.003941,0.100112,276.821777,14.101973,1.001124,-131.619141,0.100269,0.000000
65.889999,62.069283,-131.619141,0.003820,0.003941,0.100112,276.097961,14.065101,1.001124,-131.619141,0.100269,0.000000
66.110001,61.932991,-131.619141,0.003820,0.003941,0.100112,275.491699,14.034216,1.001124,-131.619141,0.100269,0.000000
66.330002,61.776222,-131.619141,0.003824,0.003941,0.100112,274.794373,13.998693,1.001124,-131.619141,0.100269,0.000000
66.550003,61.646637,-131.708099,0.003846,0.003941,0.100112,274.217926,13.969327,1.001124,-131.708099,0.100269,0.000000
66.770004,61.512207,-131.663620,0.003829,0.003941,0.100104,273.619965,13.938866,1.001037,-131.663620,0.100269,0.000000
66.990005,61.367355,-131.663620,0.003837,0.003941,0.100104,272.975616,13.906042,1.001037,-131.663620,0.100269,0.000000
67.210007,61.263466,-131.663620,0.003829,0.003941,0.100104,272.513519,13.882500,1.001037,-131.663620,0.100269,0.000000
67.430000,61.137604,-131.619141,0.003854,0.003941,0.100104,271.953644,13.853979,1.001037,-131.619141,0.100269,0.000000
67.650002,61.033340,-131.708099,0.003837,0.003941,0.100104,271.489868,13.830352,1.001037,-131.708099,0.100269,0.000000
67.870003,60.919395,-131.708099,0.003842,0.003941,0.100104,270.983002,13.804532,1.001037,-131.708099,0.100269,0.000000
68.090004,60.817734,-131.708099,0.003837,0.003941,0.100104,270.530792,13.781496,1.001037,-131.708099,0.100269,0.000000
68.310005,60.717941,-131.663620,0.003842,0.003941,0.100104,270.086884,13.758883,1.001037,-131.663620,0.100269,0.000000
68.530006,60.611443,-131.663620,0.003846,0.003941,0.100104,269.613159,13.734749,1.001037,-131.663620,0.100269,0.000000
68.750000,60.533989,-131.663620,0.003842,0.003941,0.100104,269.268646,13.717198,1.001037,-131.663620,0.100269,0.000000
68.970001,60.440521,-131.663620,0.003850,0.003941,0.100104,268.852875,13.696018,1.001037,-131.663620,0.100269,0.000000
69.190002,60.370140,-131.752579,0.003863,0.003941,0.100104,268.539795,13.680069,1.001037,-131.752579,0.100269,0.000000
69.410004,60.279282,-131.708099,0.003854,0.003941,0.100104,268.135651,13.659480,1.001037,-131.708099,0.100269,0.000000
69.630005,60.189545,-131.663620,0.003833,0.003941,0.100104,267.736481,13.639145,1.001037,-131.663620,0.100269,0.000000
69.850006,60.121399,-131.752579,0.003854,0.003941,0.100104,267.433350,13.623704,1.001037,-131.752579,0.100269,0.000000
70.070000,60.042831,-131.708099,0.003859,0.003941,0.100104,267.083862,13.605900,1.001037,-131.708099,0.100269,0.000000
70.290001,59.984741,-131.797058,0.003867,0.003941,0.100104,266.825470,13.592736,1.001037,-131.797058,0.100269,0.000000
70.510002,59.921059,-131.708099,0.003850,0.003941,0.100104,266.542175,13.578305,1.001037,-131.708099,0.100269,0.000000
70.730003,59.846962,-131.752579,0.003854,0.003941,0.100104,266.212585,13.561516,1.001037,-131.752579,0.100269,0.000000
70.950005,59.779564,-131.752579,0.003850,0.003941,0.100104,265.912781,13.546244,1.001037,-131.752579,0.100269,0.000000
71.170006,59.698753,-131.797058,0.003846,0.003941,0.100104,265.553314,13.527931,1.001037,-131.797058,0.100269,0.000000
71.390007,59.648857,-131.752579,0.003863,0.003941,0.100104,265.331360,13.516624,1.001037,-131.752579,0.100269,0.000000
71.610001,59.587418,-131.797058,0.003842,0.003941,0.100104,265.058075,13.502703,1.001037,-131.797058,0.100269,0.000000
71.830002,59.534538,-131.797058,0.003859,0.003941,0.100104,264.822845,13.490719,1.001037,-131.797058,0.100269,0.000000
72.050003,59.474213,-131.841537,0.003842,0.003941,0.100104,264.554504,13.477050,1.001037,-131.841537,0.100269,0.000000
72.270004,59.406441,-131.797058,0.003859,0.003941,0.100104,264.253052,13.461692,1.001037,-131.797058,0.100269,0.000000
72.490005,59.363617,-131.752579,0.003867,0.003941,0.100104,264.062561,13.451987,1.001037,-131.752579,0.100269,0.000000
72.710007,59.295845,-131.841537,0.003833,0.003941,0.100104,263.761078,13.436630,1.001037,-131.841537,0.100269,0.000000
72.930000,59.249672,-131.797058,0.003846,0.003941,0.100104,263.555695,13.426167,1.001037,-131.797058,0.100269,0.000000
73.150002,59.210579,-131.841537,0.003829,0.003941,0.100104,263.381805,13.417309,1.001037,-131.841537,0.100269,0.000000
73.370003,59.166260,-131.841537,0.003842,0.003941,0.100104,263.184662,13.407267,1.001037,-131.841537,0.100269,0.000000
73.590004,59.104820,-131.841537,0.003842,0.003941,0.100104,262.911377,13.393344,1.001037,-131.841537,0.100269,0.000000
73.810005,59.057533,-131.841537,0.003863,0.003941,0.100104,262.701019,13.382628,1.001037,-131.841537,0.100269,0.000000
74.030006,59.004654,-131.797058,0.003837,0.003941,0.100104,262.465820,13.370646,1.001037,-131.797058,0.100269,0.000000
74.250000,58.957359,-131.841537,0.003859,0.003941,0.100104,262.255432,13.359929,1.001037,-131.841537,0.100269,0.000000
74.470001,58.914543,-131.886017,0.003850,0.003941,0.100104,262.064972,13.350226,1.001037,-131.886017,0.100269,0.000000
74.690002,58.873581,-131.841537,0.003863,0.003941,0.100104,261.882782,13.340944,1.001037,-131.841537,0.100269,0.000000
74.910004,58.821075,-131.886017,0.003846,0.003941,0.100104,261.649200,13.329046,1.001037,-131.886017,0.100269,0.000000
75.130005,58.795753,-131.841537,0.003872,0.003941,0.100104,261.536560,13.323308,1.001037,-131.841537,0.100269,0.000000
75.350006,58.742874,-131.930496,0.003859,0.003941,0.100095,261.301361,13.311326,1.000950,-131.930496,0.100269,0.000000
75.570007,58.700424,-131.974976,0.003837,0.003941,0.100095,261.112518,13.301706,1.000950,-131.974976,0.100269,0.000000
75.790001,58.661324,-131.930496,0.003863,0.003941,0.100095,260.938599,13.292846,1.000950,-131.930496,0.100269,0.000000
76.010002,58.633774,-131.930496,0.003837,0.003941,0.100095,260.816040,13.286603,1.000950,-131.930496,0.100269,0.000000
76.230003,58.593185,-131.886017,0.003842,0.003941,0.100095,260.635498,13.277406,1.000950,-131.886017,0.100269,0.000000
76.450005,58.547005,-131.886017,0.003859,0.003941,0.100095,260.430084,13.266940,1.000950,-131.886017,0.100269,0.000000
76.670006,58.506416,-131.974976,0.003854,0.003941,0.100095,260.249542,13.257743,1.000950,-131.974976,0.100269,0.000000
76.890007,58.477005,-131.930496,0.003850,0.003941,0.100095,260.118713,13.251079,1.000950,-131.930496,0.100269,0.000000
77.110001,58.431946,-131.930496,0.003867,0.003941,0.100095,259.918274,13.240869,1.000950,-131.930496,0.100269,0.000000
77.330002,58.412582,-131.930496,0.003850,0.003941,0.100095,259.832153,13.236481,1.000950,-131.930496,0.100269,0.000000
77.550003,58.355232,-131.930496,0.003854,0.003941,0.100095,259.577026,13.223485,1.000950,-131.930496,0.100269,0.000000
77.770004,58.335129,-131.974976,0.003842,0.003941,0.100095,259.487610,13.218929,1.000950,-131.974976,0.100269,0.000000
77.990005,58.288956,-131.974976,0.003867,0.003941,0.100095,259.282227,13.208467,1.000950,-131.974976,0.100269,0.000000
78.210007,58.252831,-131.974976,0.003859,0.003941,0.100095,259.121521,13.200280,1.000950,-131.974976,0.100269,0.000000
78.430000,58.234962,-131.974976,0.003846,0.003941,0.100095,259.042053,13.196232,1.000950,-131.974976,0.100269,0.000000
78.650002,58.199211,-131.974976,0.003850,0.003941,0.100095,258.883026,13.188129,1.000950,-131.974976,0.100269,0.000000
78.870003,58.159370,-132.019470,0.003854,0.003941,0.100095,258.705811,13.179101,1.000950,-132.019470,0.100269,0.000000
79.090004,58.123245,-131.974976,0.003872,0.003941,0.100095,258.545105,13.170916,1.000950,-131.974976,0.100269,0.000000
79.310005,58.095695,-131.974976,0.003876,0.003941,0.100095,258.422546,13.164673,1.000950,-131.974976,0.100269,0.000000
79.530006,58.057709,-131.974976,0.003863,0.003941,0.100095,258.253601,13.156065,1.000950,-131.974976,0.100269,0.000000
79.750000,58.021965,-131.974976,0.003850,0.003941,0.100095,258.094604,13.147965,1.000950,-131.974976,0.100269,0.000000
79.970001,58.005577,-132.108429,0.003854,0.003941,0.100095,258.021698,13.144251,1.000950,-132.108429,0.100269,0.000000
80.190002,57.979515,-132.019470,0.003867,0.003941,0.100095,257.905762,13.138346,1.000950,-132.019470,0.100269,0.000000
80.410004,57.934456,-132.019470,0.003863,0.003941,0.100095,257.705322,13.128135,1.000950,-132.019470,0.100269,0.000000
80.630005,57.922165,-131.974976,0.003854,0.003941,0.100095,257.650665,13.125350,1.000950,-131.974976,0.100269,0.000000
80.850006,57.877480,-132.063950,0.003854,0.003941,0.100095,257.451874,13.115224,1.000950,-132.063950,0.100269,0.000000
81.070007,57.848434,-132.108429,0.003846,0.003941,0.100095,257.322693,13.108643,1.000950,-132.108429,0.100269,0.000000
81.290001,57.826469,-132.019470,0.003863,0.003941,0.100095,257.224976,13.103665,1.000950,-132.019470,0.100269,0.000000
81.510002,57.808594,-132.063950,0.003863,0.003941,0.100095,257.145477,13.099614,1.000950,-132.063950,0.100269,0.000000
81.730003,57.761299,-132.019470,0.003863,0.003941,0.100095,256.935089,13.088898,1.000950,-132.019470,0.100269,0.000000
81.950005,57.744545,-132.108429,0.003854,0.003941,0.100095,256.860565,13.085101,1.000950,-132.108429,0.100269,0.000000
82.170006,57.720711,-132.108429,0.003872,0.003941,0.100095,256.754547,13.079700,1.000950,-132.108429,0.100269,0.000000
82.390007,57.680870,-132.063950,0.003876,0.003941,0.100095,256.577332,13.070671,1.000950,-132.063950,0.100269,0.000000
82.610001,57.662621,-132.108429,0.003872,0.003941,0.100095,256.496155,13.066536,1.000950,-132.108429,0.100269,0.000000
82.830002,57.645119,-132.063950,0.003850,0.003941,0.100095,256.418304,13.062571,1.000950,-132.063950,0.100269,0.000000
83.050003,57.606766,-132.063950,0.003876,0.003941,0.100095,256.247681,13.053879,1.000950,-132.063950,0.100269,0.000000
83.270004,57.582565,-132.152908,0.003863,0.003941,0.100095,256.140045,13.048396,1.000950,-132.152908,0.100269,0.000000
83.490005,57.566177,-132.152908,0.003863,0.003941,0.100095,256.067139,13.044682,1.000950,-132.152908,0.100269,0.000000
83.710007,57.543091,-132.019470,0.003859,0.003941,0.100095,255.964447,13.039451,1.000950,-132.019470,0.100269,0.000000
83.930000,57.500267,-132.108429,0.003842,0.003941,0.100095,255.773956,13.029747,1.000950,-132.108429,0.100269,0.000000
84.150002,57.493195,-132.108429,0.003859,0.003941,0.100095,255.742508,13.028144,1.000950,-132.108429,0.100269,0.000000
84.370003,57.467873,-132.241867,0.003859,0.003941,0.100095,255.629868,13.022407,1.000950,-132.241867,0.100269,0.000000
84.590004,57.445900,-132.108429,0.003854,0.003941,0.100095,255.532120,13.017426,1.000950,-132.108429,0.100269,0.000000
84.810005,57.416115,-132.152908,0.003876,0.003941,0.100095,255.399628,13.010677,1.000950,-132.152908,0.100269,0.000000
85.030006,57.383713,-132.108429,0.003850,0.003941,0.100095,255.255508,13.003335,1.000950,-132.108429,0.100269,0.000000
85.250008,57.368446,-132.152908,0.003867,0.003941,0.100095,255.187592,12.999875,1.000950,-132.152908,0.100269,0.000000
85.470001,57.329353,-132.152908,0.003867,0.003941,0.100095,255.013702,12.991017,1.000950,-132.152908,0.100269,0.000000
85.690002,57.323395,-132.197388,0.003846,0.003941,0.100095,254.987198,12.989667,1.000950,-132.197388,0.100269,0.000000
85.910004,57.295837,-132.197388,0.003876,0.003941,0.100095,254.864609,12.983422,1.000950,-132.197388,0.100269,0.000000
86.130005,57.285408,-132.152908,0.003854,0.003941,0.100095,254.818222,12.981058,1.000950,-132.152908,0.100269,0.000000
86.350006,57.257484,-132.197388,0.003867,0.003941,0.100095,254.694016,12.974731,1.000950,-132.197388,0.100269,0.000000
86.570007,57.218010,-132.241867,0.003850,0.003941,0.100095,254.518417,12.965786,1.000950,-132.241867,0.100269,0.000000
86.790001,57.215034,-132.241867,0.003859,0.003941,0.100095,254.505188,12.965113,1.000950,-132.241867,0.100269,0.000000
87.010002,57.191574,-132.152908,0.003863,0.003941,0.100095,254.400833,12.959796,1.000950,-132.152908,0.100269,0.000000
87.230003,57.177422,-132.152908,0.003854,0.003941,0.100095,254.337875,12.956589,1.000950,-132.152908,0.100269,0.000000
87.450005,57.166992,-132.197388,0.003863,0.003941,0.100095,254.291489,12.954226,1.000950,-132.197388,0.100269,0.000000
87.670006,57.128639,-132.241867,0.003893,0.003941,0.100095,254.120880,12.945535,1.000950,-132.241867,0.100269,0.000000
87.890007,57.110023,-132.241867,0.003867,0.003941,0.100095,254.038071,12.941316,1.000950,-132.241867,0.100269,0.000000
88.110001,57.072411,-132.197388,0.003859,0.003941,0.100095,253.870758,12.932794,1.000950,-132.197388,0.100269,0.000000
88.330002,57.070549,-132.286346,0.003859,0.003941,0.100095,253.862488,12.932371,1.000950,-132.286346,0.100269,0.000000
88.550003,57.044113,-132.286346,0.003863,0.003941,0.100095,253.744888,12.926381,1.000950,-132.286346,0.100269,0.000000
88.770004,57.034058,-132.286346,0.003854,0.003941,0.100095,253.700165,12.924103,1.000950,-132.286346,0.100269,0.000000
88.990005,57.010971,-132.197388,0.003880,0.003941,0.100095,253.597458,12.918871,1.000950,-132.197388,0.100269,0.000000
89.210007,56.996819,-132.241867,0.003867,0.003941,0.100095,253.534515,12.915664,1.000950,-132.241867,0.100269,0.000000
89.430008,56.969269,-132.241867,0.003876,0.003941,0.100095,253.411957,12.909421,1.000950,-132.241867,0.100269,0.000000
89.650002,56.944313,-132.241867,0.003846,0.003941,0.100095,253.300949,12.903766,1.000950,-132.241867,0.100269,0.000000
89.870003,56.934265,-132.286346,0.003867,0.003941,0.100095,253.256256,12.901489,1.000950,-132.286346,0.100269,0.000000
90.090004,56.909317,-132.330826,0.003898,0.003941,0.100095,253.145279,12.895836,1.000950,-132.330826,0.100269,0.000000
90.310005,56.907822,-132.286346,0.003859,0.003941,0.100095,253.138626,12.895496,1.000950,-132.286346,0.100269,0.000000
90.530006,56.887344,-132.286346,0.003863,0.003941,0.100095,253.047546,12.890857,1.000950,-132.286346,0.100269,0.000000
90.750008,56.867607,-132.330826,0.003859,0.003941,0.100095,252.959747,12.886384,1.000950,-132.330826,0.100269,0.000000
90.970001,56.848244,-132.330826,0.003859,0.003941,0.100095,252.873611,12.881996,1.000950,-132.330826,0.100269,0.000000
91.190002,56.823296,-132.286346,0.003885,0.003941,0.100095,252.762650,12.876343,1.000950,-132.286346,0.100269,0.000000
91.410004,56.816589,-132.286346,0.003867,0.003941,0.100095,252.732819,12.874823,1.000950,-132.286346,0.100269,0.000000
91.630005,56.798347,-132.330826,0.003863,0.003941,0.100095,252.651672,12.870689,1.000950,-132.330826,0.100269,0.000000
91.850006,56.780846,-132.375305,0.003872,0.003941,0.100095,252.573822,12.866723,1.000950,-132.375305,0.100269,0.000000
92.070007,56.758873,-132.375305,0.003863,0.003941,0.100095,252.476074,12.861745,1.000950,-132.375305,0.100269,0.000000
92.290001,56.752548,-132.330826,0.003876,0.003941,0.100095,252.447937,12.860312,1.000950,-132.330826,0.100269,0.000000
92.510002,56.730949,-132.375305,0.003859,0.003941,0.100095,252.351868,12.855417,1.000950,-132.375305,0.100269,0.000000
92.730003,56.714188,-132.330826,0.003863,0.003941,0.100095,252.277313,12.851619,1.000950,-132.330826,0.100269,0.000000
92.800003,56.704506,-132.330826,0.003880,0.003941,0.100095,252.234238,12.849424,1.000950,-132.330826,0.100269,0.000000