File: Data/Compression Sample NH 10, 12, 15, 17 batch 3/AutoNoheating-15-3-3-240212_02122024_180046.csv
Time (sec),S:Load (lbs),S:HL1 (DIM),S:LVDT (in),S:Position (in),Ch:Position (mm),Ch:Load (N),Ch:Stress (MPa),Ch:Strain (mm/mm),Ch:HL1 (DIM),Set Point (),Cycles ()
0.110000,0.003723,-297.399628,-0.000017,-0.000000,-0.000000,0.016561,0.000844,-0.000000,-297.399628,0.000191,0.000000
0.320000,0.002235,-297.399628,-0.000026,-0.000000,-0.000000,0.009944,0.000507,-0.000000,-297.399628,0.000191,0.000000
0.530000,0.029045,-297.488586,-0.000047,0.000112,0.002845,0.129199,0.006582,0.028447,-297.488586,0.003677,0.000000
0.740000,0.027184,-297.444122,0.000017,0.000242,0.006157,0.120918,0.006160,0.061573,-297.444122,0.007181,0.000000
0.950000,0.020851,-297.399628,0.000185,0.000379,0.009635,0.092750,0.004725,0.096352,-297.399628,0.010667,0.000000
1.160000,0.014526,-297.488586,0.000332,0.000513,0.013026,0.064617,0.003292,0.130257,-297.488586,0.014171,0.000000
1.370000,-0.013779,-297.399628,0.000453,0.000652,0.016573,-0.061291,-0.003122,0.165729,-297.399628,0.017674,0.000000
1.580000,-0.030533,-297.488586,0.000586,0.000789,0.020042,-0.135817,-0.006919,0.200418,-297.488586,0.021178,0.000000
1.790000,-0.022713,-297.444122,0.000724,0.000926,0.023511,-0.101031,-0.005147,0.235106,-297.444122,0.024664,0.000000
2.000000,-0.004837,-297.533081,0.000949,0.001066,0.027084,-0.021516,-0.001096,0.270836,-297.533081,0.028168,0.000000
2.210000,0.054741,-297.444122,0.001078,0.001206,0.030622,0.243500,0.012404,0.306221,-297.444122,0.031671,0.000000
2.420000,0.563026,-297.444122,0.001168,0.001339,0.034013,2.504467,0.127584,0.340126,-297.444122,0.035158,0.000000
2.630000,0.688889,-297.488586,0.001220,-0.000000,-0.000000,3.064329,0.156104,-0.000000,-297.488586,0.000217,0.000000
2.840000,0.679207,-297.444122,0.001212,-0.000000,-0.000000,3.021263,0.153910,-0.000000,-297.444122,0.000217,0.000000
3.050000,0.608833,-297.488586,0.001246,-0.000000,-0.000000,2.708226,0.137964,-0.000000,-297.488586,0.000312,0.000000
3.260000,0.644951,-297.488586,0.001194,-0.000000,-0.000000,2.868885,0.146148,-0.000000,-297.488586,0.000659,0.000000
3.470000,0.622978,-297.488586,0.001177,0.000001,0.000017,2.771146,0.141169,0.000174,-297.488586,0.001006,0.000000
3.680000,0.796135,-297.533081,0.001207,0.000019,0.000494,3.541385,0.180407,0.004943,-297.533081,0.001361,0.000000
3.890000,1.001686,-297.488586,0.001242,0.000036,0.000911,4.455722,0.226985,0.009106,-297.488586,0.001709,0.000000
4.100000,1.117867,-297.488586,0.001259,0.000046,0.001162,4.972518,0.253312,0.011620,-297.488586,0.002064,0.000000
4.310000,1.312241,-297.533081,0.001268,0.000061,0.001561,5.837138,0.297358,0.015609,-297.533081,0.002411,0.000000
4.520000,1.506622,-297.488586,0.001237,0.000075,0.001908,6.701791,0.341406,0.019080,-297.488586,0.002758,0.000000
4.730000,1.689079,-297.577576,0.001281,0.000085,0.002159,7.513400,0.382751,0.021593,-297.577576,0.003113,0.000000
4.940000,1.941177,-297.533081,0.001319,0.000102,0.002593,8.634789,0.439877,0.025930,-297.533081,0.003460,0.000000
5.150000,2.142632,-297.488586,0.001337,0.000115,0.002931,9.530901,0.485527,0.029310,-297.488586,0.003807,0.000000
5.360000,2.320999,-297.533081,0.001293,0.000126,0.003209,10.324320,0.525946,0.032088,-297.533081,0.004163,0.000000
5.570000,2.559319,-297.488586,0.001302,0.000141,0.003590,11.384418,0.579950,0.035904,-297.488586,0.004509,0.000000
5.780000,2.860565,-297.533081,0.001341,0.000159,0.004050,12.724429,0.648213,0.040498,-297.533081,0.004856,0.000000
5.990000,3.110428,-297.577576,0.001332,0.000175,0.004440,13.835875,0.704833,0.044401,-297.577576,0.005212,0.000000
6.200000,3.240387,-297.533081,0.001358,0.000186,0.004717,14.413961,0.734282,0.047175,-297.533081,0.005559,0.000000
6.410000,3.419495,-297.577576,0.001350,0.000199,0.005065,15.210671,0.774869,0.050646,-297.577576,0.005914,0.000000
6.620000,3.635475,-297.533081,0.001388,0.000211,0.005368,16.171402,0.823810,0.053681,-297.533081,0.006261,0.000000
6.830000,3.975822,-297.622040,0.001380,0.000230,0.005854,17.685341,0.900934,0.058537,-297.622040,0.006608,0.000000
7.040000,4.169083,-297.622040,0.001401,0.000242,0.006157,18.545006,0.944728,0.061573,-297.622040,0.006964,0.000000
7.250000,4.293083,-297.533081,0.001431,0.000251,0.006383,19.096588,0.972827,0.063828,-297.533081,0.007311,0.000000
7.460001,4.462143,-297.666534,0.001453,0.000264,0.006703,19.848602,1.011136,0.067034,-297.666534,0.007658,0.000000
7.670001,4.842331,-297.488586,0.001470,0.000282,0.007172,21.539764,1.097288,0.071720,-297.488586,0.008013,0.000000
7.880001,5.059052,-297.622040,0.001487,0.000298,0.007562,22.503784,1.146397,0.075622,-297.622040,0.008360,0.000000
8.090000,5.249336,-297.533081,0.001449,0.000310,0.007866,23.350214,1.189517,0.078658,-297.533081,0.008707,0.000000
8.300000,5.385254,-297.533081,0.001522,0.000323,0.008204,23.954805,1.220316,0.082038,-297.533081,0.009063,0.000000
8.510000,5.540901,-297.622040,0.001479,0.000335,0.008507,24.647160,1.255586,0.085073,-297.622040,0.009409,0.000000
8.720000,5.861519,-297.577576,0.001513,0.000353,0.008976,26.073338,1.328239,0.089759,-297.577576,0.009765,0.000000
8.930000,6.022751,-297.577576,0.001513,0.000366,0.009288,26.790533,1.364775,0.092878,-297.577576,0.010112,0.000000
9.140000,6.132607,-297.577576,0.001556,0.000377,0.009566,27.279196,1.389668,0.095656,-297.577576,0.010459,0.000000
9.350000,6.206703,-297.622040,0.001531,0.000387,0.009826,27.608795,1.406459,0.098256,-297.622040,0.010814,0.000000
9.560000,6.426033,-297.666534,0.001600,0.000403,0.010233,28.584423,1.456160,0.102332,-297.666534,0.011161,0.000000
9.770000,6.691536,-297.622040,0.001600,0.000419,0.010632,29.765438,1.516324,0.106321,-297.622040,0.011508,0.000000
9.980000,6.820374,-297.666534,0.001587,0.000433,0.011005,30.338537,1.545519,0.110050,-297.666534,0.011864,0.000000
10.190001,6.924263,-297.666534,0.001656,0.000446,0.011326,30.800659,1.569060,0.113259,-297.666534,0.012210,0.000000
10.400001,7.121254,-297.577576,0.001664,0.000460,0.011681,31.676920,1.613699,0.116813,-297.577576,0.012558,0.000000
10.610001,7.232964,-297.666534,0.001651,0.000476,0.012080,32.173828,1.639013,0.120802,-297.666534,0.012913,0.000000
10.820001,7.377815,-297.666534,0.001699,0.000490,0.012445,32.818161,1.671837,0.124447,-297.666534,0.013260,0.000000
11.030001,7.443352,-297.622040,0.001669,0.000501,0.012713,33.109684,1.686688,0.127135,-297.622040,0.013607,0.000000
11.240001,7.374466,-297.666534,0.001703,0.000510,0.012948,32.803265,1.671078,0.129477,-297.666534,0.013962,0.000000
11.450001,7.685768,-297.622040,0.001699,0.000529,0.013442,34.188004,1.741620,0.134421,-297.622040,0.014309,0.000000
11.660001,7.837326,-297.666534,0.001738,0.000543,0.013780,34.862167,1.775964,0.137800,-297.666534,0.014665,0.000000
11.870001,7.946426,-297.622040,0.001725,0.000556,0.014127,35.347469,1.800686,0.141271,-297.622040,0.015012,0.000000
12.080001,7.984039,-297.666534,0.001729,0.000569,0.014448,35.514782,1.809209,0.144481,-297.666534,0.015358,0.000000
12.290001,8.062607,-297.710999,0.001707,0.000582,0.014795,35.864265,1.827013,0.147948,-297.710999,0.015714,0.000000
12.500001,8.053673,-297.710999,0.001738,0.000593,0.015064,35.824524,1.824988,0.150635,-297.710999,0.016061,0.000000
12.710001,8.340775,-297.710999,0.001789,0.000610,0.015489,37.101620,1.890047,0.154885,-297.710999,0.016408,0.000000
12.920001,8.319916,-297.710999,0.001798,0.000622,0.015810,37.008835,1.885320,0.158095,-297.710999,0.016763,0.000000
13.130001,8.359764,-297.755493,0.001785,0.000633,0.016078,37.186089,1.894350,0.160782,-297.755493,0.017110,0.000000
13.340001,8.550041,-297.799957,0.001785,0.000648,0.016460,38.032482,1.937467,0.164598,-297.799957,0.017457,0.000000
13.550000,8.928001,-297.710999,0.001819,0.000673,0.017093,39.713734,2.023114,0.170930,-297.710999,0.017813,0.000000
13.760000,8.865814,-297.710999,0.001880,0.000684,0.017370,39.437111,2.009022,0.173704,-297.710999,0.018160,0.000000
13.970000,8.821503,-297.710999,0.001910,0.000695,0.017665,39.240005,1.998981,0.176652,-297.710999,0.018515,0.000000
14.180000,8.795441,-297.710999,0.001871,0.000706,0.017943,39.124073,1.993075,0.179427,-297.710999,0.018862,0.000000
14.390000,8.848312,-297.710999,0.001876,0.000718,0.018238,39.359261,2.005056,0.182375,-297.710999,0.019209,0.000000
14.600000,9.028168,-297.755493,0.001936,0.000732,0.018602,40.159294,2.045812,0.186020,-297.755493,0.019565,0.000000
14.810000,9.038223,-297.755493,0.001884,0.000743,0.018871,40.204025,2.048091,0.188707,-297.755493,0.019912,0.000000
15.020000,8.949226,-297.755493,0.001906,0.000751,0.019070,39.808147,2.027924,0.190702,-297.755493,0.020258,0.000000
15.230000,9.354744,-297.710999,0.001932,0.000772,0.019617,41.611980,2.119815,0.196167,-297.710999,0.020614,0.000000
15.440001,9.435173,-297.799957,0.001932,0.000787,0.019990,41.969746,2.138041,0.199895,-297.799957,0.020961,0.000000
15.650001,9.760254,-297.755493,0.001996,0.000809,0.020544,43.415779,2.211705,0.205444,-297.755493,0.021308,0.000000
15.860001,9.562897,-297.799957,0.001936,0.000819,0.020805,42.537888,2.166983,0.208048,-297.799957,0.021663,0.000000
16.070002,9.559921,-297.755493,0.001983,0.000832,0.021134,42.524654,2.166309,0.211341,-297.755493,0.022010,0.000000
16.280001,9.621735,-297.755493,0.002052,0.000845,0.021455,42.799614,2.180316,0.214551,-297.755493,0.022366,0.000000
16.490002,9.783340,-297.844452,0.002013,0.000860,0.021837,43.518471,2.216937,0.218366,-297.844452,0.022712,0.000000
16.700001,9.817230,-297.710999,0.002078,0.000872,0.022149,43.669220,2.224616,0.221488,-297.710999,0.023059,0.000000
16.910002,9.881279,-297.844452,0.002074,0.000885,0.022478,43.954124,2.239130,0.224785,-297.844452,0.023415,0.000000
17.120001,9.889839,-297.799957,0.002039,0.000898,0.022816,43.992203,2.241070,0.228165,-297.799957,0.023762,0.000000
17.330000,10.178055,-297.755493,0.002087,0.000915,0.023250,45.274250,2.306380,0.232502,-297.755493,0.024109,0.000000
17.540001,10.331474,-297.844452,0.002117,0.000932,0.023684,45.956692,2.341146,0.236840,-297.844452,0.024464,0.000000
17.750000,10.222366,-297.844452,0.002095,0.000943,0.023961,45.471355,2.316421,0.239614,-297.844452,0.024811,0.000000
17.960001,10.318817,-297.844452,0.002151,0.000956,0.024291,45.900391,2.338277,0.242911,-297.844452,0.025158,0.000000
18.170000,10.289398,-297.844452,0.002134,0.000967,0.024560,45.769527,2.331611,0.245598,-297.844452,0.025514,0.000000
18.380001,10.369827,-297.844452,0.002117,0.000982,0.024933,46.127296,2.349837,0.249326,-297.844452,0.025861,0.000000
18.590000,10.599586,-297.888916,0.002212,0.000998,0.025340,47.149315,2.401901,0.253403,-297.888916,0.026207,0.000000
18.800001,10.657303,-297.844452,0.002186,0.001010,0.025644,47.406052,2.414979,0.256438,-297.844452,0.026563,0.000000
19.010000,10.471863,-297.844452,0.002190,0.001016,0.025800,46.581173,2.372958,0.257997,-297.844452,0.026910,0.000000
19.220001,10.591393,-297.799957,0.002238,0.001031,0.026182,47.112865,2.400044,0.261816,-297.799957,0.027266,0.000000
19.430000,11.187187,-297.799957,0.002216,0.001056,0.026832,49.763096,2.535053,0.268319,-297.799957,0.027612,0.000000
19.640001,11.164474,-297.888916,0.002289,0.001069,0.027162,49.662064,2.529906,0.271615,-297.888916,0.027959,0.000000
19.850000,11.054993,-297.844452,0.002264,0.001083,0.027500,49.175064,2.505097,0.274995,-297.844452,0.028315,0.000000
20.060001,11.101913,-297.933411,0.002276,0.001095,0.027803,49.383778,2.515729,0.278031,-297.933411,0.028662,0.000000
20.270000,11.166336,-297.888916,0.002272,0.001107,0.028107,49.670345,2.530328,0.281066,-297.888916,0.029009,0.000000
20.480001,11.276558,-297.799957,0.002294,0.001120,0.028445,50.160633,2.555305,0.284450,-297.799957,0.029364,0.000000
20.690001,11.278793,-297.888916,0.002328,0.001135,0.028818,50.170578,2.555811,0.288178,-297.888916,0.029711,0.000000
20.900002,11.299644,-297.844452,0.002281,0.001142,0.029009,50.263329,2.560536,0.290086,-297.844452,0.030058,0.000000
21.110001,11.550995,-297.844452,0.002324,0.001159,0.029451,51.381390,2.617493,0.294510,-297.844452,0.030414,0.000000
21.320002,11.949806,-297.888916,0.002345,0.001182,0.030015,53.155392,2.707865,0.300146,-297.888916,0.030761,0.000000
21.530001,11.914803,-297.844452,0.002363,0.001193,0.030309,52.999687,2.699933,0.303094,-297.844452,0.031116,0.000000
21.740002,11.841446,-297.933411,0.002397,0.001207,0.030648,52.673382,2.683310,0.306478,-297.933411,0.031463,0.000000
21.950001,11.875702,-297.888916,0.002358,0.001220,0.030977,52.825760,2.691072,0.309771,-297.888916,0.031810,0.000000
22.160002,11.862297,-297.933411,0.002436,0.001229,0.031211,52.766132,2.688035,0.312114,-297.933411,0.032165,0.000000
22.370001,12.204132,-297.888916,0.002449,0.001247,0.031680,54.286690,2.765496,0.316796,-297.888916,0.032512,0.000000
22.580002,12.270416,-297.888916,0.002414,0.001261,0.032027,54.581539,2.780516,0.320266,-297.888916,0.032859,0.000000
22.790001,12.239510,-297.977905,0.002462,0.001271,0.032287,54.444057,2.773512,0.322867,-297.977905,0.033215,0.000000
23.000002,12.274139,-297.888916,0.002440,0.001284,0.032616,54.598099,2.781360,0.326163,-297.888916,0.033561,0.000000
23.210001,12.614487,-297.888916,0.002514,0.001302,0.033058,56.112038,2.858484,0.330584,-297.888916,0.033908,0.000000
23.420002,12.684494,-297.977905,0.002471,0.001313,0.033362,56.423447,2.874347,0.333620,-297.977905,0.034264,0.000000
23.630001,12.704231,-297.977905,0.002471,0.001326,0.033674,56.511242,2.878820,0.336742,-297.977905,0.034611,0.000000
23.840002,12.863983,-298.022369,0.002496,0.001340,0.034030,57.221855,2.915020,0.340300,-298.022369,0.034966,0.000000
24.050001,12.936966,-297.933411,0.002483,0.001353,0.034368,57.546497,2.931558,0.343680,-297.933411,0.035313,0.000000
24.260000,13.190926,-297.888916,0.002527,0.001371,0.034819,58.676167,2.989106,0.348191,-297.888916,0.035660,0.000000
24.470001,13.281784,-297.933411,0.002535,0.001384,0.035148,59.080326,3.009695,0.351484,-297.933411,0.036016,0.000000
24.680000,13.234863,-297.977905,0.002583,0.001394,0.035409,58.871613,2.999063,0.354088,-297.977905,0.036363,0.000000
24.890001,13.291092,-298.022369,0.002617,0.001407,0.035730,59.121731,3.011804,0.357298,-298.022369,0.036710,0.000000
25.100000,13.362587,-297.933411,0.002596,0.001418,0.036016,59.439754,3.028006,0.360159,-297.933411,0.037065,0.000000
25.310001,13.749855,-298.022369,0.002617,0.001436,0.036484,61.162411,3.115762,0.364841,-298.022369,0.037412,0.000000
25.520000,13.903275,-297.977905,0.002621,0.001451,0.036857,61.844852,3.150527,0.368569,-297.977905,0.037759,0.000000
25.730001,13.927475,-297.977905,0.002596,0.001464,0.037187,61.952503,3.156011,0.371866,-297.977905,0.038115,0.000000
25.940001,14.014610,-298.022369,0.002613,0.001478,0.037542,62.340099,3.175756,0.375420,-298.022369,0.038461,0.000000
26.150002,14.078659,-297.977905,0.002626,0.001492,0.037889,62.625004,3.190270,0.378891,-297.977905,0.038817,0.000000
26.360001,14.269310,-298.022369,0.002721,0.001505,0.038236,63.473061,3.233472,0.382358,-298.022369,0.039164,0.000000
26.570002,14.406715,-298.022369,0.002712,0.001519,0.038592,64.084274,3.264608,0.385915,-298.022369,0.039511,0.000000
26.780001,14.461082,-298.022369,0.002690,0.001532,0.038904,64.326111,3.276928,0.389038,-298.022369,0.039866,0.000000
26.990002,14.619713,-298.066864,0.002699,0.001546,0.039268,65.031731,3.312874,0.392679,-298.066864,0.040213,0.000000
27.200001,14.949265,-298.066864,0.002746,0.001565,0.039745,66.497650,3.387552,0.397448,-298.066864,0.040560,0.000000
27.410002,15.047943,-298.022369,0.002738,0.001578,0.040083,66.936592,3.409913,0.400832,-298.022369,0.040915,0.000000
27.620001,15.020020,-298.066864,0.002716,0.001590,0.040395,66.812386,3.403585,0.403954,-298.066864,0.041263,0.000000
27.830002,15.076614,-298.066864,0.002738,0.001602,0.040699,67.064133,3.416409,0.406990,-298.066864,0.041609,0.000000
28.040001,15.132103,-298.066864,0.002781,0.001616,0.041054,67.310959,3.428983,0.410544,-298.066864,0.041965,0.000000
28.250002,15.546921,-298.022369,0.002777,0.001634,0.041497,69.156158,3.522983,0.414968,-298.022369,0.042312,0.000000
28.460001,15.540962,-298.066864,0.002824,0.001645,0.041792,69.129654,3.521632,0.417917,-298.066864,0.042659,0.000000
28.670002,15.357384,-298.111328,0.002807,0.001653,0.041974,68.313057,3.480033,0.419737,-298.111328,0.043014,0.000000
28.880001,15.886902,-297.977905,0.002824,0.001673,0.042494,70.668472,3.600023,0.424942,-297.977905,0.043361,0.000000
29.090002,15.854500,-298.066864,0.002846,0.001682,0.042711,70.524338,3.592681,0.427106,-298.066864,0.043717,0.000000
29.300001,16.238045,-298.066864,0.002841,0.001701,0.043205,72.230431,3.679594,0.432050,-298.066864,0.044064,0.000000
29.510002,16.388855,-298.066864,0.002880,0.001717,0.043604,72.901268,3.713768,0.436039,-298.066864,0.044410,0.000000
29.720001,16.346031,-298.155823,0.002906,0.001728,0.043890,72.710777,3.704064,0.438904,-298.155823,0.044766,0.000000
29.930002,16.448441,-298.066864,0.002923,0.001740,0.044185,73.166321,3.727270,0.441852,-298.066864,0.045113,0.000000
30.140001,16.638718,-298.155823,0.002932,0.001754,0.044558,74.012711,3.770387,0.445581,-298.155823,0.045460,0.000000
30.350002,16.843521,-298.111328,0.002919,0.001768,0.044913,74.923721,3.816796,0.449135,-298.111328,0.045815,0.000000
30.560001,16.879646,-298.066864,0.002940,0.001781,0.045234,75.084419,3.824982,0.452344,-298.066864,0.046162,0.000000
30.770002,16.891930,-298.066864,0.002966,0.001790,0.045469,75.139053,3.827766,0.454687,-298.066864,0.046509,0.000000
30.980001,17.222603,-298.066864,0.003009,0.001809,0.045946,76.609962,3.902698,0.459456,-298.066864,0.046865,0.000000
31.190001,17.599815,-298.155823,0.002984,0.001823,0.046310,78.287888,3.988175,0.463097,-298.155823,0.047212,0.000000
31.400002,17.778923,-298.155823,0.002975,0.001838,0.046674,79.084602,4.028761,0.466742,-298.155823,0.047567,0.000000
31.610001,17.882446,-298.111328,0.002988,0.001851,0.047021,79.545097,4.052220,0.470209,-298.111328,0.047914,0.000000
31.820002,18.155396,-298.200287,0.003053,0.001867,0.047420,80.759232,4.114071,0.474198,-298.200287,0.048261,0.000000
32.030003,18.420891,-298.111328,0.003065,0.001882,0.047793,81.940216,4.174234,0.477926,-298.111328,0.048617,0.000000
32.240002,18.511749,-298.155823,0.003083,0.001896,0.048166,82.344376,4.194822,0.481658,-298.155823,0.048964,0.000000
32.450001,18.354240,-298.200287,0.003083,0.001904,0.048374,81.643738,4.159130,0.483736,-298.200287,0.049310,0.000000
32.660000,18.544525,-298.155823,0.003083,0.001917,0.048703,82.490166,4.202250,0.487033,-298.155823,0.049666,0.000000
32.870003,18.868111,-298.200287,0.003078,0.001934,0.049120,83.929550,4.275575,0.491196,-298.200287,0.050013,0.000000
33.080002,19.215538,-298.111328,0.003109,0.001949,0.049501,85.474983,4.354303,0.495011,-298.111328,0.050360,0.000000
33.290001,19.285172,-298.200287,0.003134,0.001961,0.049805,85.784729,4.370082,0.498047,-298.200287,0.050715,0.000000
33.500000,19.479546,-298.155823,0.003117,0.001974,0.050152,86.649345,4.414128,0.501518,-298.155823,0.051062,0.000000
33.710003,19.516785,-298.200287,0.003113,0.001986,0.050447,86.814995,4.422567,0.504466,-298.200287,0.051418,0.000000
33.920002,19.835541,-298.244781,0.003147,0.002000,0.050802,88.232895,4.494798,0.508020,-298.244781,0.051764,0.000000
34.130001,20.188171,-298.200287,0.003156,0.002016,0.051201,89.801468,4.574705,0.512009,-298.200287,0.052112,0.000000
34.340000,20.266373,-298.289246,0.003203,0.002027,0.051496,90.149330,4.592426,0.514958,-298.289246,0.052467,0.000000
34.550003,20.010925,-298.200287,0.003173,0.002033,0.051635,89.013039,4.534540,0.516347,-298.200287,0.052814,0.000000
34.760002,20.736305,-298.155823,0.003229,0.002056,0.052216,92.239693,4.698914,0.522157,-298.155823,0.053161,0.000000
34.970001,21.587547,-298.200287,0.003216,0.002079,0.052797,96.026207,4.891808,0.527966,-298.200287,0.053517,0.000000
35.180000,21.385353,-298.155823,0.003203,0.002089,0.053048,95.126801,4.845990,0.530480,-298.155823,0.053863,0.000000
35.390003,21.461685,-298.244781,0.003272,0.002101,0.053378,95.466347,4.863287,0.533776,-298.244781,0.054210,0.000000
35.600002,21.432274,-298.200287,0.003251,0.002111,0.053629,95.335518,4.856623,0.536293,-298.200287,0.054566,0.000000
35.810001,21.539513,-298.200287,0.003277,0.002124,0.053950,95.812538,4.880923,0.539499,-298.200287,0.054913,0.000000
36.020000,21.756607,-298.244781,0.003251,0.002135,0.054219,96.778221,4.930118,0.542190,-298.244781,0.055259,0.000000
36.230003,21.713036,-298.155823,0.003277,0.002144,0.054462,96.584404,4.920244,0.544616,-298.155823,0.055615,0.000000
36.440002,22.136429,-298.244781,0.003307,0.002162,0.054913,98.467751,5.016186,0.549128,-298.244781,0.055962,0.000000
36.650002,22.701691,-298.244781,0.003307,0.002177,0.055303,100.982162,5.144277,0.553030,-298.244781,0.056318,0.000000
36.860001,23.741348,-298.289246,0.003303,0.002201,0.055901,105.606789,5.379867,0.559014,-298.289246,0.056664,0.000000
37.070004,23.657944,-298.200287,0.003324,0.002212,0.056179,105.235786,5.360967,0.561788,-298.200287,0.057011,0.000000
37.280003,23.717522,-298.200287,0.003320,0.002225,0.056508,105.500809,5.374467,0.565085,-298.200287,0.057367,0.000000
37.490002,23.744331,-298.333740,0.003363,0.002236,0.056803,105.620064,5.380542,0.568033,-298.333740,0.057714,0.000000
37.700001,23.783806,-298.244781,0.003380,0.002247,0.057072,105.795654,5.389488,0.570721,-298.244781,0.058061,0.000000
37.910004,24.212776,-298.289246,0.003432,0.002263,0.057480,107.703804,5.486693,0.574797,-298.289246,0.058416,0.000000
38.120003,24.552376,-298.289246,0.003432,0.002277,0.057835,109.214424,5.563648,0.578351,-298.289246,0.058763,0.000000
38.330002,24.566528,-298.289246,0.003376,0.002286,0.058069,109.277374,5.566855,0.580694,-298.289246,0.059110,0.000000
38.540001,24.866661,-298.289246,0.003428,0.002299,0.058399,110.612434,5.634866,0.583990,-298.289246,0.059466,0.000000
38.750000,25.546989,-298.244781,0.003475,0.002318,0.058885,113.638687,5.789031,0.588846,-298.244781,0.059812,0.000000
38.960003,26.206459,-298.289246,0.003423,0.002336,0.059335,116.572151,5.938469,0.593354,-298.289246,0.060168,0.000000
39.170002,26.253380,-298.333740,0.003449,0.002347,0.059613,116.780869,5.949101,0.596129,-298.333740,0.060515,0.000000
39.380001,26.366577,-298.289246,0.003475,0.002360,0.059943,117.284393,5.974752,0.599425,-298.289246,0.060862,0.000000
39.590000,26.314445,-298.333740,0.003488,0.002370,0.060203,117.052498,5.962939,0.602029,-298.333740,0.061217,0.000000
39.800003,26.871140,-298.333740,0.003510,0.002387,0.060628,119.528801,6.089087,0.606276,-298.333740,0.061564,0.000000
40.010002,27.185051,-298.244781,0.003535,0.002401,0.060975,120.925148,6.160221,0.609747,-298.244781,0.061911,0.000000
40.220001,27.364166,-298.333740,0.003518,0.002412,0.061261,121.721893,6.200809,0.612608,-298.333740,0.062267,0.000000
40.430000,27.645676,-298.333740,0.003561,0.002424,0.061564,122.974106,6.264600,0.615643,-298.333740,0.062614,0.000000
40.640003,27.686264,-298.378235,0.003492,0.002436,0.061877,123.154655,6.273797,0.618766,-298.378235,0.062961,0.000000
40.850002,29.137772,-298.333740,0.003574,0.002461,0.062509,129.611282,6.602714,0.625094,-298.333740,0.063316,0.000000
41.060001,29.301620,-298.333740,0.003613,0.002473,0.062813,130.340118,6.639843,0.628130,-298.333740,0.063663,0.000000
41.270000,29.355988,-298.378235,0.003591,0.002485,0.063117,130.581955,6.652162,0.631165,-298.378235,0.064018,0.000000
41.480003,29.581642,-298.333740,0.003566,0.002497,0.063429,131.585709,6.703296,0.634288,-298.333740,0.064366,0.000000
41.690002,29.750702,-298.333740,0.003583,0.002511,0.063776,132.337738,6.741605,0.637759,-298.333740,0.064712,0.000000
41.900002,30.377029,-298.378235,0.003579,0.002524,0.064114,135.123779,6.883533,0.641138,-298.378235,0.065068,0.000000
42.110001,30.682373,-298.333740,0.003600,0.002537,0.064435,136.482010,6.952725,0.644348,-298.333740,0.065415,0.000000
42.320004,31.169067,-298.422699,0.003639,0.002553,0.064834,138.646942,7.063012,0.648337,-298.422699,0.065762,0.000000
42.530003,31.143372,-298.333740,0.003660,0.002562,0.065068,138.532639,7.057189,0.650680,-298.333740,0.066117,0.000000
42.740002,32.600838,-298.378235,0.003660,0.002587,0.065710,145.015762,7.387455,0.657096,-298.378235,0.066464,0.000000
42.950001,32.649620,-298.333740,0.003652,0.002598,0.065996,145.232758,7.398510,0.659957,-298.333740,0.066811,0.000000
43.160004,32.843994,-298.378235,0.003699,0.002611,0.066308,146.097382,7.442556,0.663080,-298.378235,0.067167,0.000000
43.370003,32.941933,-298.422699,0.003686,0.002622,0.066594,146.533035,7.464749,0.665941,-298.422699,0.067513,0.000000
43.580002,33.405907,-298.378235,0.003721,0.002636,0.066950,148.596893,7.569887,0.669499,-298.378235,0.067861,0.000000
43.790001,34.058304,-298.422699,0.003738,0.002651,0.067331,151.498901,7.717722,0.673314,-298.422699,0.068216,0.000000
44.000004,34.348381,-298.378235,0.003742,0.002665,0.067687,152.789230,7.783454,0.676868,-298.378235,0.068563,0.000000
44.210003,34.537178,-298.422699,0.003708,0.002675,0.067947,153.629044,7.826237,0.679472,-298.422699,0.068918,0.000000
44.420002,34.766930,-298.422699,0.003738,0.002691,0.068346,154.651031,7.878299,0.683461,-298.422699,0.069265,0.000000
44.630001,35.720573,-298.378235,0.003803,0.002705,0.068710,158.893051,8.094398,0.687102,-298.378235,0.069612,0.000000
44.840004,36.004692,-298.422699,0.003786,0.002717,0.069022,160.156876,8.158780,0.690225,-298.422699,0.069968,0.000000
45.050003,36.407227,-298.467194,0.003807,0.002731,0.069369,161.947433,8.249995,0.693692,-298.467194,0.070315,0.000000
45.260002,36.821678,-298.467194,0.003794,0.002744,0.069690,163.791000,8.343912,0.696901,-298.467194,0.070661,0.000000
45.470001,37.290871,-298.422699,0.003842,0.002758,0.070046,165.878082,8.450232,0.700459,-298.422699,0.071017,0.000000
45.680000,37.877731,-298.422699,0.003816,0.002773,0.070436,168.488571,8.583217,0.704361,-298.422699,0.071364,0.000000
45.890003,38.543533,-298.467194,0.003811,0.002788,0.070818,171.450195,8.734089,0.708177,-298.467194,0.071711,0.000000
46.100002,38.499962,-298.511658,0.003833,0.002796,0.071017,171.256378,8.724216,0.710171,-298.511658,0.072066,0.000000
46.310001,39.116241,-298.467194,0.003829,0.002813,0.071450,173.997726,8.863867,0.714505,-298.467194,0.072413,0.000000
46.520000,39.500153,-298.467194,0.003859,0.002824,0.071720,175.705460,8.950863,0.717196,-298.467194,0.072769,0.000000
46.730003,40.269852,-298.467194,0.003889,0.002842,0.072196,179.129242,9.125278,0.721965,-298.467194,0.073116,0.000000
46.940002,40.971771,-298.511658,0.003919,0.002855,0.072526,182.251541,9.284336,0.725262,-298.511658,0.073463,0.000000
47.150002,41.444313,-298.467194,0.003915,0.002869,0.072864,184.353516,9.391416,0.728642,-298.467194,0.073818,0.000000
47.360001,41.710930,-298.511658,0.003850,0.002880,0.073150,185.539490,9.451832,0.731503,-298.511658,0.074165,0.000000
47.570004,42.605370,-298.511658,0.003911,0.002897,0.073593,189.518143,9.654515,0.735927,-298.511658,0.074512,0.000000
47.780003,43.020935,-298.556152,0.003949,0.002910,0.073914,191.366684,9.748684,0.739137,-298.556152,0.074867,0.000000
47.990002,43.524757,-298.556152,0.003923,0.002922,0.074217,193.607788,9.862851,0.742172,-298.556152,0.075215,0.000000
48.200001,44.043472,-298.511658,0.003915,0.002935,0.074555,195.915146,9.980393,0.745552,-298.511658,0.075561,0.000000
48.410004,44.894341,-298.556152,0.003954,0.002951,0.074963,199.699997,10.173203,0.749629,-298.556152,0.075917,0.000000
48.620003,45.683769,-298.511658,0.003949,0.002969,0.075414,203.211548,10.352090,0.754140,-298.511658,0.076264,0.000000
48.830002,46.090775,-298.467194,0.003975,0.002980,0.075691,205.022003,10.444319,0.756915,-298.467194,0.076619,0.000000
49.040001,46.404686,-298.511658,0.003941,0.002992,0.075986,206.418350,10.515452,0.759863,-298.511658,0.076966,0.000000
49.250004,47.047028,-298.556152,0.004005,0.003007,0.076368,209.275635,10.661009,0.763678,-298.556152,0.077313,0.000000
49.460003,47.952263,-298.556152,0.003975,0.003024,0.076802,213.302322,10.866138,0.768016,-298.556152,0.077669,0.000000
49.670002,48.366341,-298.600616,0.004023,0.003035,0.077079,215.144226,10.959970,0.770790,-298.600616,0.078015,0.000000
49.880001,48.868301,-298.556152,0.004018,0.003047,0.077383,217.377060,11.073715,0.773826,-298.556152,0.078362,0.000000
50.090004,49.057465,-298.556152,0.004040,0.003056,0.077616,218.218506,11.116581,0.776165,-298.556152,0.078718,0.000000
50.300003,50.202141,-298.556152,0.004049,0.003074,0.078068,223.310272,11.375968,0.780676,-298.556152,0.079065,0.000000
50.510002,50.662392,-298.600616,0.004057,0.003090,0.078484,225.357574,11.480262,0.784840,-298.600616,0.079412,0.000000
50.720001,51.718811,-298.600616,0.004044,0.003104,0.078848,230.056763,11.719650,0.788481,-298.600616,0.079767,0.000000
50.930004,52.365250,-298.556152,0.004044,0.003118,0.079195,232.932266,11.866136,0.791951,-298.556152,0.080114,0.000000
51.140003,53.016159,-298.645111,0.004092,0.003131,0.079533,235.827652,12.013633,0.795331,-298.645111,0.080470,0.000000
51.350002,53.702438,-298.556152,0.004049,0.003148,0.079967,238.880371,12.169147,0.799669,-298.556152,0.080817,0.000000
51.560001,54.621826,-298.600616,0.004105,0.003162,0.080305,242.970016,12.377483,0.803049,-298.600616,0.081164,0.000000
51.770004,54.838921,-298.556152,0.004105,0.003172,0.080565,243.935699,12.426677,0.805653,-298.556152,0.081519,0.000000
51.980003,55.543449,-298.556152,0.004092,0.003183,0.080860,247.069595,12.586326,0.808601,-298.556152,0.081866,0.000000
52.190002,55.992905,-298.689575,0.004109,0.003196,0.081172,249.068878,12.688173,0.811724,-298.689575,0.082213,0.000000
52.400002,57.183754,-298.556152,0.004122,0.003212,0.081597,254.366043,12.958024,0.815970,-298.556152,0.082569,0.000000
52.610001,57.664482,-298.556152,0.004113,0.003225,0.081909,256.504425,13.066958,0.819093,-298.556152,0.082915,0.000000
52.820004,58.437904,-298.645111,0.004100,0.003240,0.082308,259.944794,13.242218,0.823082,-298.645111,0.083262,0.000000
53.030003,59.555016,-298.556152,0.004135,0.003257,0.082725,264.913940,13.495359,0.827246,-298.556152,0.083618,0.000000
53.240002,60.327690,-298.645111,0.004135,0.003270,0.083063,268.350983,13.670449,0.830629,-298.645111,0.083965,0.000000
53.450001,61.061638,-298.645111,0.004169,0.003286,0.083462,271.615723,13.836765,0.834619,-298.645111,0.084312,0.000000
53.660004,61.842873,-298.645111,0.004169,0.003298,0.083757,275.090851,14.013795,0.837567,-298.645111,0.084667,0.000000
53.870003,61.931496,-298.689575,0.004152,0.003304,0.083930,275.485046,14.033877,0.839300,-298.689575,0.085014,0.000000
54.080002,62.796890,-298.600616,0.004165,0.003321,0.084364,279.334534,14.229979,0.843638,-298.600616,0.085369,0.000000
54.290001,63.964279,-298.645111,0.004186,0.003338,0.084780,284.527313,14.494513,0.847798,-298.645111,0.085717,0.000000
54.500004,64.821487,-298.645111,0.004152,0.003352,0.085136,288.340363,14.688759,0.851355,-298.645111,0.086064,0.000000
54.710003,65.671234,-298.689575,0.004195,0.003365,0.085465,292.120239,14.881314,0.854652,-298.689575,0.086419,0.000000
54.920002,66.242462,-298.689575,0.004191,0.003377,0.085786,294.661194,15.010756,0.857858,-298.689575,0.086766,0.000000
55.130001,66.791702,-298.645111,0.004212,0.003388,0.086064,297.104340,15.135216,0.860636,-298.645111,0.087113,0.000000
55.340004,67.165192,-298.689575,0.004204,0.003387,0.086037,298.765686,15.219850,0.860375,-298.689575,0.086315,0.000000
55.550003,66.521729,-298.689575,0.004225,0.003387,0.086037,295.903412,15.074039,0.860375,-298.689575,0.086315,0.000000
55.760002,65.991852,-298.689575,0.004225,0.003383,0.085925,293.546417,14.953967,0.859247,-298.689575,0.086037,0.000000
55.970001,65.464569,-298.734070,0.004277,0.003382,0.085899,291.200958,14.834484,0.858986,-298.734070,0.086037,0.000000
56.180004,65.012131,-298.689575,0.004234,0.003381,0.085890,289.188416,14.731959,0.858899,-298.689575,0.086037,0.000000
56.390003,64.580933,-298.689575,0.004260,0.003381,0.085881,287.270325,14.634249,0.858812,-298.689575,0.086037,0.000000
56.600002,64.192551,-298.689575,0.004247,0.003381,0.085881,285.542725,14.546241,0.858812,-298.689575,0.086037,0.000000
56.810001,63.825760,-298.689575,0.004294,0.003381,0.085872,283.911163,14.463124,0.858725,-298.689575,0.086037,0.000000
57.020004,63.499939,-298.734070,0.004243,0.003381,0.085872,282.461823,14.389292,0.858725,-298.734070,0.086037,0.000000
57.230003,63.200546,-298.689575,0.004225,0.003381,0.085872,281.130066,14.321449,0.858725,-298.689575,0.086037,0.000000
57.440002,62.916794,-298.778534,0.004243,0.003381,0.085872,279.867889,14.257150,0.858725,-298.778534,0.086037,0.000000
57.650002,62.651665,-298.689575,0.004260,0.003381,0.085872,278.688538,14.197070,0.858725,-298.689575,0.086037,0.000000
57.860004,62.412605,-298.778534,0.004268,0.003380,0.085864,277.625122,14.142899,0.858641,-298.778534,0.086037,0.000000
58.070004,62.172798,-298.778534,0.004303,0.003380,0.085864,276.558411,14.088557,0.858641,-298.778534,0.086037,0.000000
58.280003,61.962036,-298.689575,0.004303,0.003380,0.085864,275.620911,14.040798,0.858641,-298.689575,0.086037,0.000000
58.490002,61.747917,-298.778534,0.004251,0.003380,0.085864,274.668457,13.992278,0.858641,-298.778534,0.086037,0.000000
58.700005,61.551308,-298.778534,0.004281,0.003380,0.085864,273.793884,13.947726,0.858641,-298.778534,0.086037,0.000000
58.910004,61.372940,-298.778534,0.004260,0.003380,0.085864,273.000458,13.907308,0.858641,-298.778534,0.086037,0.000000
59.120003,61.197182,-298.778534,0.004277,0.003380,0.085864,272.218658,13.867479,0.858641,-298.778534,0.086037,0.000000
59.330002,61.021423,-298.689575,0.004273,0.003380,0.085864,271.436859,13.827652,0.858641,-298.689575,0.086037,0.000000
59.540005,60.874336,-298.734070,0.004268,0.003380,0.085864,270.782562,13.794322,0.858641,-298.734070,0.086037,0.000000
59.750004,60.735069,-298.689575,0.004290,0.003380,0.085864,270.163086,13.762763,0.858641,-298.689575,0.086037,0.000000
59.960003,60.583138,-298.778534,0.004260,0.003380,0.085864,269.487244,13.728335,0.858641,-298.778534,0.086037,0.000000
60.170002,60.446480,-298.823029,0.004299,0.003380,0.085864,268.879364,13.697368,0.858641,-298.823029,0.086037,0.000000
60.380001,60.311310,-298.734070,0.004268,0.003380,0.085855,268.278107,13.666739,0.858554,-298.734070,0.086037,0.000000
60.590004,60.183586,-298.778534,0.004307,0.003380,0.085855,267.709961,13.637795,0.858554,-298.778534,0.086037,0.000000
60.800003,60.060699,-298.734070,0.004307,0.003380,0.085855,267.163330,13.609949,0.858554,-298.734070,0.086037,0.000000
61.010002,59.947868,-298.867523,0.004320,0.003380,0.085855,266.661438,13.584381,0.858554,-298.867523,0.086037,0.000000
61.220001,59.829460,-298.867523,0.004303,0.003380,0.085855,266.134735,13.557549,0.858554,-298.867523,0.086037,0.000000
61.430004,59.721466,-298.823029,0.004260,0.003380,0.085855,265.654358,13.533078,0.858554,-298.823029,0.086037,0.000000
61.640003,59.622047,-298.867523,0.004316,0.003380,0.085855,265.212128,13.510549,0.858554,-298.867523,0.086037,0.000000
61.850002,59.513687,-298.778534,0.004281,0.003380,0.085855,264.730103,13.485994,0.858554,-298.778534,0.086037,0.000000
62.060001,59.412025,-298.823029,0.004303,0.003380,0.085855,264.277893,13.462957,0.858554,-298.823029,0.086037,0.000000
62.270004,59.312233,-298.823029,0.004268,0.003380,0.085855,263.833984,13.440345,0.858554,-298.823029,0.086037,0.000000
62.480003,59.225471,-298.823029,0.004320,0.003380,0.085855,263.448059,13.420683,0.858554,-298.823029,0.086037,0.000000
62.690002,59.146896,-298.867523,0.004268,0.003380,0.085855,263.098541,13.402878,0.858554,-298.867523,0.086037,0.000000
62.900002,59.069069,-298.823029,0.004290,0.003380,0.085855,262.752350,13.385242,0.858554,-298.823029,0.086037,0.000000
63.110004,58.962944,-298.823029,0.004299,0.003380,0.085855,262.280273,13.361195,0.858554,-298.823029,0.086037,0.000000
63.320004,58.881393,-298.823029,0.004299,0.003380,0.085855,261.917511,13.342714,0.858554,-298.823029,0.086037,0.000000
63.530003,58.807297,-298.778534,0.004290,0.003380,0.085855,261.587921,13.325924,0.858554,-298.778534,0.086037,0.000000
63.740002,58.728722,-298.867523,0.004312,0.003380,0.085855,261.238403,13.308119,0.858554,-298.867523,0.086037,0.000000
63.950005,58.649406,-298.867523,0.004303,0.003380,0.085855,260.885590,13.290146,0.858554,-298.867523,0.086037,0.000000
64.160004,58.583870,-298.867523,0.004320,0.003380,0.085855,260.594055,13.275294,0.858554,-298.867523,0.086037,0.000000
64.370003,58.505302,-298.956482,0.004281,0.003380,0.085855,260.244568,13.257491,0.858554,-298.956482,0.086037,0.000000
64.580002,58.441994,-298.823029,0.004286,0.003380,0.085855,259.962982,13.243145,0.858554,-298.823029,0.086037,0.000000
64.790001,58.360817,-298.867523,0.004255,0.003380,0.085855,259.601868,13.224751,0.858554,-298.867523,0.086037,0.000000
65.000000,58.310547,-298.823029,0.004273,0.003380,0.085855,259.378265,13.213359,0.858554,-298.823029,0.086037,0.000000
65.210007,58.235329,-298.867523,0.004307,0.003380,0.085855,259.043671,13.196314,0.858554,-298.867523,0.086037,0.000000
65.420006,58.181335,-298.956482,0.004303,0.003380,0.085855,258.803497,13.184079,0.858554,-298.956482,0.086037,0.000000
65.630005,58.128456,-298.867523,0.004312,0.003380,0.085855,258.568298,13.172096,0.858554,-298.867523,0.086037,0.000000
65.840004,58.061058,-298.956482,0.004320,0.003380,0.085855,258.268494,13.156824,0.858554,-298.956482,0.086037,0.000000
66.050003,58.001854,-298.867523,0.004277,0.003380,0.085855,258.005127,13.143408,0.858554,-298.867523,0.086037,0.000000
66.260002,57.945625,-299.000946,0.004333,0.003380,0.085855,257.755005,13.130666,0.858554,-299.000946,0.086037,0.000000
66.470001,57.874870,-298.911987,0.004337,0.003380,0.085855,257.440277,13.114633,0.858554,-298.911987,0.086037,0.000000
66.680000,57.823486,-298.911987,0.004350,0.003380,0.085855,257.211700,13.102989,0.858554,-298.911987,0.086037,0.000000
66.889999,57.776192,-299.000946,0.004281,0.003380,0.085855,257.001343,13.092272,0.858554,-299.000946,0.086037,0.000000
67.100006,57.724808,-298.911987,0.004312,0.003380,0.085855,256.772766,13.080628,0.858554,-298.911987,0.086037,0.000000
67.310005,57.666344,-298.911987,0.004264,0.003380,0.085855,256.512695,13.067381,0.858554,-298.911987,0.086037,0.000000
67.520004,57.619057,-298.956482,0.004281,0.003380,0.085855,256.302368,13.056664,0.858554,-298.956482,0.086037,0.000000
67.730003,57.566551,-298.911987,0.004324,0.003380,0.085855,256.068817,13.044767,0.858554,-298.911987,0.086037,0.000000
67.940002,57.527824,-299.000946,0.004294,0.003380,0.085855,255.896545,13.035991,0.858554,-299.000946,0.086037,0.000000
68.150002,57.474945,-298.956482,0.004324,0.003380,0.085855,255.661331,13.024009,0.858554,-298.956482,0.086037,0.000000
68.360001,57.418716,-299.000946,0.004303,0.003380,0.085855,255.411209,13.011267,0.858554,-299.000946,0.086037,0.000000
68.570000,57.380363,-298.956482,0.004290,0.003380,0.085855,255.240601,13.002576,0.858554,-298.956482,0.086037,0.000000
68.780006,57.328232,-299.000946,0.004329,0.003380,0.085855,255.008713,12.990764,0.858554,-299.000946,0.086037,0.000000
68.990005,57.288383,-299.045441,0.004316,0.003380,0.085855,254.831451,12.981733,0.858554,-299.045441,0.086037,0.000000
69.200005,57.247795,-299.000946,0.004299,0.003380,0.085855,254.650909,12.972536,0.858554,-299.000946,0.086037,0.000000
69.410004,57.194550,-299.000946,0.004273,0.003380,0.085847,254.414062,12.960470,0.858467,-299.000946,0.086037,0.000000
69.620003,57.150978,-298.956482,0.004264,0.003380,0.085847,254.220245,12.950597,0.858467,-298.956482,0.086037,0.000000
69.830002,57.122307,-299.045441,0.004342,0.003380,0.085847,254.092712,12.944099,0.858467,-299.045441,0.086037,0.000000
70.040001,57.069435,-299.045441,0.004286,0.003380,0.085847,253.857529,12.932118,0.858467,-299.045441,0.086037,0.000000
70.250000,57.028473,-298.956482,0.004299,0.003380,0.085847,253.675323,12.922837,0.858467,-298.956482,0.086037,0.000000
70.460007,56.989372,-299.089905,0.004307,0.003380,0.085847,253.501389,12.913977,0.858467,-299.089905,0.086037,0.000000
70.670006,56.945061,-299.000946,0.004320,0.003380,0.085847,253.304276,12.903935,0.858467,-299.000946,0.086037,0.000000
70.880005,56.906334,-299.000946,0.004307,0.003380,0.085847,253.132019,12.895160,0.858467,-299.000946,0.086037,0.000000
71.090004,56.872444,-299.089905,0.004355,0.003380,0.085847,252.981262,12.887480,0.858467,-299.089905,0.086037,0.000000
71.300003,56.825531,-299.045441,0.004316,0.003380,0.085847,252.772583,12.876849,0.858467,-299.045441,0.086037,0.000000
71.510002,56.799461,-299.089905,0.004294,0.003380,0.085847,252.656616,12.870942,0.858467,-299.089905,0.086037,0.000000
71.720001,56.767807,-299.045441,0.004277,0.003380,0.085847,252.515823,12.863770,0.858467,-299.045441,0.086037,0.000000
71.930000,56.724243,-299.000946,0.004324,0.003380,0.085847,252.322037,12.853897,0.858467,-299.000946,0.086037,0.000000
72.140007,56.691101,-299.134399,0.004333,0.003380,0.085847,252.174606,12.846387,0.858467,-299.134399,0.086037,0.000000
72.350006,56.643440,-299.000946,0.004299,0.003380,0.085847,251.962601,12.835587,0.858467,-299.000946,0.086037,0.000000
72.560005,56.610298,-299.134399,0.004303,0.003380,0.085847,251.815186,12.828077,0.858467,-299.134399,0.086037,0.000000
72.770004,56.581253,-299.089905,0.004342,0.003380,0.085847,251.685989,12.821495,0.858467,-299.089905,0.086037,0.000000
72.980003,56.541779,-299.089905,0.004324,0.003380,0.085847,251.510391,12.812551,0.858467,-299.089905,0.086037,0.000000
73.190002,56.511993,-299.089905,0.004346,0.003380,0.085847,251.377899,12.805800,0.858467,-299.089905,0.086037,0.000000
73.400002,56.469910,-299.089905,0.004303,0.003380,0.085847,251.190704,12.796265,0.858467,-299.089905,0.086037,0.000000
73.610001,56.443848,-299.089905,0.004320,0.003380,0.085847,251.074768,12.790359,0.858467,-299.089905,0.086037,0.000000
73.820000,56.410706,-299.089905,0.004299,0.003380,0.085847,250.927353,12.782848,0.858467,-299.089905,0.086037,0.000000
74.030006,56.371605,-299.089905,0.004329,0.003380,0.085847,250.753418,12.773988,0.858467,-299.089905,0.086037,0.000000
74.240005,56.350006,-299.089905,0.004324,0.003380,0.085847,250.657349,12.769094,0.858467,-299.089905,0.086037,0.000000
74.450005,56.310539,-299.045441,0.004329,0.003380,0.085847,250.481781,12.760151,0.858467,-299.045441,0.086037,0.000000
74.660004,56.287079,-299.134399,0.004281,0.003380,0.085847,250.377426,12.754834,0.858467,-299.134399,0.086037,0.000000
74.870003,56.248726,-299.089905,0.004316,0.003380,0.085847,250.206833,12.746143,0.858467,-299.089905,0.086037,0.000000
75.080002,56.218559,-299.089905,0.004350,0.003380,0.085847,250.072647,12.739307,0.858467,-299.089905,0.086037,0.000000
75.290001,56.192863,-299.134399,0.004290,0.003380,0.085847,249.958344,12.733485,0.858467,-299.134399,0.086037,0.000000
75.500000,56.157120,-299.089905,0.004359,0.003380,0.085847,249.799347,12.725385,0.858467,-299.089905,0.086037,0.000000
75.710007,56.123230,-299.178864,0.004324,0.003380,0.085847,249.648590,12.717706,0.858467,-299.178864,0.086037,0.000000
75.920006,56.094559,-299.178864,0.004273,0.003380,0.085847,249.521057,12.711208,0.858467,-299.178864,0.086037,0.000000
76.130005,56.063652,-299.134399,0.004299,0.003380,0.085847,249.383575,12.704206,0.858467,-299.134399,0.086037,0.000000
76.340004,56.044662,-299.178864,0.004324,0.003380,0.085847,249.299103,12.699902,0.858467,-299.178864,0.086037,0.000000
76.550003,56.020088,-299.178864,0.004329,0.003380,0.085847,249.189804,12.694333,0.858467,-299.178864,0.086037,0.000000
76.760002,55.985458,-299.178864,0.004299,0.003380,0.085847,249.035751,12.686486,0.858467,-299.178864,0.086037,0.000000
76.970001,55.955666,-299.134399,0.004312,0.003380,0.085847,248.903229,12.679735,0.858467,-299.134399,0.086037,0.000000
77.180000,55.924385,-299.178864,0.004333,0.003380,0.085847,248.764084,12.672647,0.858467,-299.178864,0.086037,0.000000
77.390007,55.901672,-299.178864,0.004294,0.003380,0.085847,248.663055,12.667500,0.858467,-299.178864,0.086037,0.000000
77.600006,55.881935,-299.134399,0.004337,0.003380,0.085847,248.575256,12.663027,0.858467,-299.134399,0.086037,0.000000
77.810005,55.841347,-299.223358,0.004346,0.003380,0.085847,248.394714,12.653830,0.858467,-299.223358,0.086037,0.000000
78.020004,55.826828,-299.223358,0.004307,0.003380,0.085847,248.330139,12.650539,0.858467,-299.223358,0.086037,0.000000
78.230003,55.798523,-299.223358,0.004277,0.003380,0.085847,248.204224,12.644126,0.858467,-299.223358,0.086037,0.000000
78.440002,55.772835,-299.223358,0.004359,0.003380,0.085847,248.089966,12.638305,0.858467,-299.223358,0.086037,0.000000
78.650002,55.747513,-299.178864,0.004333,0.003380,0.085847,247.977325,12.632567,0.858467,-299.178864,0.086037,0.000000
78.860001,55.718834,-299.223358,0.004303,0.003380,0.085847,247.849747,12.626068,0.858467,-299.223358,0.086037,0.000000
79.070007,55.702454,-299.178864,0.004329,0.003380,0.085847,247.776886,12.622355,0.858467,-299.178864,0.086037,0.000000
79.280006,55.669685,-299.223358,0.004355,0.003380,0.085847,247.631134,12.614931,0.858467,-299.223358,0.086037,0.000000
79.490005,55.645851,-299.223358,0.004320,0.003380,0.085847,247.525101,12.609530,0.858467,-299.223358,0.086037,0.000000
79.700005,55.632072,-299.223358,0.004342,0.003380,0.085847,247.463821,12.606408,0.858467,-299.223358,0.086037,0.000000
79.910004,55.595207,-299.178864,0.004299,0.003380,0.085847,247.299835,12.598054,0.858467,-299.178864,0.086037,0.000000
80.120003,55.563927,-299.223358,0.004273,0.003380,0.085847,247.160690,12.590965,0.858467,-299.223358,0.086037,0.000000
80.330002,55.547173,-299.223358,0.004299,0.003380,0.085847,247.086166,12.587169,0.858467,-299.223358,0.086037,0.000000
80.540001,55.514404,-299.267853,0.004324,0.003380,0.085847,246.940399,12.579743,0.858467,-299.267853,0.086037,0.000000
80.750008,55.489830,-299.267853,0.004277,0.003380,0.085847,246.831085,12.574175,0.858467,-299.267853,0.086037,0.000000
80.960007,55.480888,-299.267853,0.004324,0.003380,0.085847,246.791321,12.572148,0.858467,-299.267853,0.086037,0.000000
81.170006,55.449242,-299.312317,0.004342,0.003380,0.085847,246.650543,12.564978,0.858467,-299.312317,0.086037,0.000000
81.380005,55.422798,-299.312317,0.004294,0.003380,0.085847,246.532913,12.558986,0.858467,-299.312317,0.086037,0.000000
81.590004,55.400459,-299.312317,0.004277,0.003380,0.085847,246.433548,12.553924,0.858467,-299.312317,0.086037,0.000000
81.800003,55.383331,-299.267853,0.004307,0.003380,0.085847,246.357361,12.550042,0.858467,-299.267853,0.086037,0.000000
82.010002,55.356888,-299.312317,0.004299,0.003380,0.085847,246.239731,12.544050,0.858467,-299.312317,0.086037,0.000000
82.220001,55.336411,-299.267853,0.004324,0.003380,0.085847,246.148651,12.539411,0.858467,-299.267853,0.086037,0.000000
82.430000,55.298798,-299.267853,0.004359,0.003380,0.085847,245.981339,12.530887,0.858467,-299.267853,0.086037,0.000000
82.640007,55.292847,-299.312317,0.004294,0.003380,0.085847,245.954865,12.529538,0.858467,-299.312317,0.086037,0.000000
82.850006,55.273483,-299.267853,0.004350,0.003380,0.085847,245.868729,12.525150,0.858467,-299.267853,0.086037,0.000000
83.060005,55.249275,-299.356812,0.004307,0.003380,0.085847,245.761047,12.519665,0.858467,-299.356812,0.086037,0.000000
83.270004,55.230659,-299.312317,0.004333,0.003380,0.085847,245.678238,12.515447,0.858467,-299.312317,0.086037,0.000000
83.480003,55.202354,-299.312317,0.004329,0.003380,0.085847,245.552338,12.509032,0.858467,-299.312317,0.086037,0.000000
83.690002,55.190437,-299.356812,0.004286,0.003380,0.085847,245.499329,12.506332,0.858467,-299.356812,0.086037,0.000000
83.900002,55.173309,-299.312317,0.004329,0.003380,0.085847,245.423141,12.502450,0.858467,-299.312317,0.086037,0.000000
84.110001,55.146126,-299.356812,0.004290,0.003380,0.085847,245.302216,12.496290,0.858467,-299.356812,0.086037,0.000000
84.320007,55.133095,-299.267853,0.004307,0.003380,0.085847,245.244247,12.493339,0.858467,-299.267853,0.086037,0.000000
84.530006,55.114845,-299.356812,0.004350,0.003380,0.085847,245.163071,12.489202,0.858467,-299.356812,0.086037,0.000000
84.740005,55.096230,-299.312317,0.004346,0.003380,0.085847,245.080276,12.484984,0.858467,-299.312317,0.086037,0.000000
84.950005,55.062714,-299.312317,0.004290,0.003380,0.085847,244.931183,12.477389,0.858467,-299.312317,0.086037,0.000000
85.160004,55.047447,-299.312317,0.004337,0.003380,0.085847,244.863281,12.473929,0.858467,-299.312317,0.086037,0.000000
85.370003,55.041489,-299.312317,0.004307,0.003380,0.085847,244.836777,12.472579,0.858467,-299.312317,0.086037,0.000000
85.580002,55.010216,-299.356812,0.004337,0.003380,0.085847,244.697662,12.465493,0.858467,-299.356812,0.086037,0.000000
85.790001,55.004623,-299.356812,0.004324,0.003380,0.085847,244.672791,12.464226,0.858467,-299.356812,0.086037,0.000000
85.800003,54.992340,-299.312317,0.004294,0.003380,0.085847,244.618149,12.461442,0.858467,-299.312317,0.086037,0.000000