File: Data/Compression Sample NH 10, 12, 15, 17 batch 3/AutoNoheating-10-3-1-240212_02122024_160514.csv
Time (sec),S:Load (lbs),S:HL1 (DIM),S:LVDT (in),S:Position (in),Ch:Position (mm),Ch:Load (N),Ch:Stress (MPa),Ch:Strain (mm/mm),Ch:HL1 (DIM),Set Point (),Cycles ()
0.110000,-0.002609,-124.946991,0.000022,-0.000000,-0.000000,-0.011607,-0.000591,-0.000000,-124.946991,0.000061,0.000000
0.360000,-0.007072,-124.946991,0.000022,-0.000000,-0.000000,-0.031460,-0.001603,-0.000000,-124.946991,0.000061,0.000000
0.610000,-0.046921,-124.991470,-0.000017,0.000124,0.003148,-0.208714,-0.010632,0.031479,-124.991470,0.003894,0.000000
0.860000,-0.011543,-124.946991,0.000034,0.000270,0.006851,-0.051347,-0.002616,0.068510,-124.946991,0.008057,0.000000
1.110000,0.018616,-124.946991,0.000211,0.000438,0.011126,0.082807,0.004218,0.111265,-124.946991,0.012219,0.000000
1.360000,0.015640,-124.946991,0.000405,0.000607,0.015411,0.069571,0.003544,0.154106,-124.946991,0.016382,0.000000
1.610000,-0.000000,-124.946991,0.000560,0.000768,0.019504,-0.000000,-0.000000,0.195039,-124.946991,0.020562,0.000000
1.860000,-0.021599,-124.991470,0.000733,0.000932,0.023667,-0.096076,-0.004894,0.236666,-124.991470,0.024724,0.000000
2.110000,-0.001862,-124.946991,0.000880,0.001093,0.027768,-0.008281,-0.000422,0.277683,-124.946991,0.028887,0.000000
2.360000,-0.046547,-124.991470,0.001069,0.001262,0.032052,-0.207051,-0.010548,0.320524,-124.991470,0.033050,0.000000
2.610000,-0.026436,-124.991470,0.001220,0.001420,0.036068,-0.117593,-0.005990,0.360678,-124.991470,0.037212,0.000000
2.860000,0.023087,-124.991470,0.001418,0.001580,0.040144,0.102694,0.005231,0.401437,-124.991470,0.041375,0.000000
3.110000,0.003723,-124.946991,0.001591,0.001757,0.044619,0.016561,0.000844,0.446186,-124.946991,0.045538,0.000000
3.360000,-0.017502,-124.991470,0.001742,0.001914,0.048608,-0.077852,-0.003966,0.486079,-124.991470,0.049718,0.000000
3.610000,-0.009682,-125.080437,0.001923,0.002082,0.052875,-0.043066,-0.002194,0.528746,-125.080437,0.053881,0.000000
3.860000,0.014153,-124.991470,0.002100,0.002239,0.056881,0.062954,0.003207,0.568813,-124.991470,0.058043,0.000000
4.110000,-0.025696,-125.035950,0.002259,0.002406,0.061113,-0.114301,-0.005823,0.611132,-125.035950,0.062206,0.000000
4.360000,-0.016754,-125.035950,0.002432,0.002574,0.065371,-0.074526,-0.003797,0.653712,-125.035950,0.066369,0.000000
4.610000,-0.005959,-125.035950,0.002608,0.002736,0.069491,-0.026505,-0.001350,0.694907,-125.035950,0.070531,0.000000
4.860000,-0.017128,-125.035950,0.002798,0.002902,0.073723,-0.076189,-0.003881,0.737226,-125.035950,0.074694,0.000000
5.110000,0.003723,-125.035950,0.002945,0.003059,0.077703,0.016561,0.000844,0.777031,-125.035950,0.078857,0.000000
5.360000,0.009682,-125.035950,0.003126,0.003228,0.081979,0.043066,0.002194,0.819786,-125.035950,0.083037,0.000000
5.610000,0.026810,-125.080437,0.003285,0.003392,0.086167,0.119255,0.006075,0.861673,-125.080437,0.087199,0.000000
5.860000,0.000374,-125.080437,0.003484,0.003557,0.090339,0.001663,0.000085,0.903386,-125.080437,0.091362,0.000000
6.110000,-0.004471,-125.035950,0.003648,0.003717,0.094423,-0.019887,-0.001013,0.944233,-125.035950,0.095525,0.000000
6.360000,0.014893,-125.080437,0.003829,0.003880,0.098560,0.066245,0.003375,0.985602,-125.080437,0.099687,0.000000
6.610000,-0.011917,-125.169395,0.003997,0.004051,0.102887,-0.053010,-0.002700,1.028875,-125.169395,0.103850,0.000000
6.860000,-0.033516,-125.080437,0.004161,0.004208,0.106885,-0.149086,-0.007595,1.068854,-125.080437,0.108013,0.000000
7.110000,0.010056,-125.080437,0.004329,0.004370,0.110996,0.044729,0.002279,1.109962,-125.080437,0.112193,0.000000
7.360000,0.015640,-125.124916,0.004497,0.004537,0.115237,0.069571,0.003544,1.152368,-125.124916,0.116356,0.000000
7.610000,-0.020111,-125.124916,0.004656,0.004704,0.119486,-0.089459,-0.004557,1.194861,-125.124916,0.120518,0.000000
7.860001,0.016014,-125.124916,0.004846,0.004866,0.123606,0.071234,0.003629,1.236056,-125.124916,0.124681,0.000000
8.110001,0.029793,-125.124916,0.005010,0.005023,0.127586,0.132525,0.006751,1.275862,-125.124916,0.128844,0.000000
8.360001,-0.009682,-125.169395,0.005195,0.005197,0.132009,-0.043066,-0.002194,1.320088,-125.169395,0.133006,0.000000
8.610001,-0.010056,-125.124916,0.005342,0.005361,0.136163,-0.044729,-0.002279,1.361631,-125.124916,0.137169,0.000000
8.860001,0.011169,-125.169395,0.005527,0.005524,0.140300,0.049684,0.002531,1.402996,-125.169395,0.141332,0.000000
9.110001,-0.000748,-125.124916,0.005717,0.005688,0.144471,-0.003326,-0.000169,1.444710,-125.124916,0.145512,0.000000
9.360001,-0.008934,-125.213875,0.005868,0.005849,0.148556,-0.039741,-0.002024,1.485556,-125.213875,0.149674,0.000000
9.610001,0.009682,-125.213875,0.006032,0.006015,0.152779,0.043066,0.002194,1.527792,-125.213875,0.153837,0.000000
9.860001,0.037613,-125.169395,0.006204,0.006179,0.156959,0.167311,0.008523,1.569592,-125.169395,0.158000,0.000000
10.110001,0.012657,-125.124916,0.006398,0.006345,0.161174,0.056302,0.002868,1.611737,-125.124916,0.162162,0.000000
10.360001,0.010429,-125.213875,0.006549,0.006502,0.165163,0.046392,0.002363,1.651630,-125.213875,0.166325,0.000000
10.610001,0.029793,-125.258362,0.006713,0.006667,0.169352,0.132525,0.006751,1.693517,-125.258362,0.170488,0.000000
10.860001,0.001862,-125.169395,0.006916,0.006838,0.173688,0.008281,0.000422,1.736877,-125.169395,0.174651,0.000000
11.110001,-0.053993,-125.213875,0.007088,0.006999,0.177764,-0.240174,-0.012235,1.777637,-125.213875,0.178831,0.000000
11.360001,0.012291,-125.258362,0.007243,0.007160,0.181857,0.054673,0.002785,1.818570,-125.258362,0.182993,0.000000
11.610001,0.023834,-125.213875,0.007386,0.007320,0.185924,0.106020,0.005401,1.859243,-125.213875,0.187156,0.000000
11.860001,-0.008934,-125.213875,0.007606,0.007493,0.190312,-0.039741,-0.002024,1.903125,-125.213875,0.191318,0.000000
12.110001,0.010056,-125.213875,0.007765,0.007654,0.194423,0.044729,0.002279,1.944232,-125.213875,0.195481,0.000000
12.360001,0.032394,-125.213875,0.007938,0.007812,0.198421,0.144098,0.007341,1.984212,-125.213875,0.199644,0.000000
12.610001,0.006706,-125.258362,0.008123,0.007982,0.202740,0.029831,0.001520,2.027398,-125.258362,0.203807,0.000000
12.860001,-0.028297,-125.258362,0.008274,0.008148,0.206963,-0.125873,-0.006412,2.069633,-125.258362,0.207986,0.000000
13.110001,0.012657,-125.258362,0.008446,0.008314,0.211178,0.056302,0.002868,2.111778,-125.258362,0.212149,0.000000
13.360001,-0.000000,-125.258362,0.008623,0.008469,0.215124,-0.000000,-0.000000,2.151240,-125.258362,0.216312,0.000000
13.610001,0.016388,-125.258362,0.008761,0.008635,0.219321,0.072897,0.003714,2.193214,-125.258362,0.220475,0.000000
13.860001,0.017502,-125.258362,0.008964,0.008801,0.223553,0.077852,0.003966,2.235533,-125.258362,0.224637,0.000000
14.110001,0.039474,-125.302841,0.009127,0.008964,0.227681,0.175591,0.008945,2.276811,-125.302841,0.228800,0.000000
14.360001,0.024574,-125.302841,0.009287,0.009131,0.231939,0.109312,0.005569,2.319395,-125.302841,0.232963,0.000000
14.610001,0.010796,-125.347321,0.009455,0.009289,0.235946,0.048021,0.002446,2.359458,-125.347321,0.237126,0.000000
14.860001,0.038353,-125.258362,0.009636,0.009455,0.240161,0.170603,0.008691,2.401607,-125.258362,0.241305,0.000000
15.110001,0.025696,-125.347321,0.009817,0.009623,0.244419,0.114301,0.005823,2.444187,-125.347321,0.245468,0.000000
15.360001,0.243156,-125.391800,0.009998,0.009786,0.248573,1.081614,0.055100,2.485726,-125.391800,0.249631,0.000000
15.610001,0.741020,-125.391800,0.010098,-0.000006,-0.000165,3.296222,0.167918,-0.001646,-125.391800,-0.000078,0.000000
15.860001,0.706017,-125.347321,0.010089,-0.000007,-0.000173,3.140518,0.159986,-0.001733,-125.347321,-0.000078,0.000000
16.110001,0.661705,-125.391800,0.010093,-0.000007,-0.000173,2.943411,0.149944,-0.001733,-125.391800,0.000061,0.000000
16.360001,0.688141,-125.347321,0.010072,-0.000007,-0.000173,3.061003,0.155935,-0.001733,-125.347321,0.000477,0.000000
16.610001,0.656120,-125.347321,0.010076,-0.000006,-0.000165,2.918569,0.148679,-0.001646,-125.347321,0.000893,0.000000
16.860001,0.843796,-125.302841,0.010119,0.000021,0.000529,3.753391,0.191207,0.005291,-125.302841,0.001310,0.000000
17.110001,0.924973,-125.436279,0.010119,0.000036,0.000911,4.114483,0.209602,0.009106,-125.436279,0.001726,0.000000
17.360001,1.040779,-125.436279,0.010123,0.000048,0.001223,4.629617,0.235844,0.012229,-125.436279,0.002142,0.000000
17.610001,1.211327,-125.391800,0.010128,0.000065,0.001657,5.388250,0.274491,0.016566,-125.391800,0.002559,0.000000
17.860001,1.306282,-125.391800,0.010149,0.000079,0.001995,5.810633,0.296008,0.019946,-125.391800,0.002975,0.000000
18.110001,1.442940,-125.436279,0.010158,0.000093,0.002359,6.418517,0.326975,0.023591,-125.436279,0.003391,0.000000
18.360001,1.556892,-125.480766,0.010192,0.000107,0.002715,6.925403,0.352797,0.027145,-125.480766,0.003807,0.000000
18.610001,1.786270,-125.436279,0.010197,0.000134,0.003408,7.945726,0.404775,0.034083,-125.436279,0.004224,0.000000
18.860001,1.866333,-125.436279,0.010205,0.000147,0.003729,8.301864,0.422917,0.037293,-125.436279,0.004640,0.000000
19.110001,1.979530,-125.436279,0.010253,0.000164,0.004154,8.805390,0.448568,0.041543,-125.436279,0.005056,0.000000
19.360001,2.110237,-125.525246,0.010257,0.000179,0.004553,9.386804,0.478187,0.045532,-125.525246,0.005472,0.000000
19.610001,2.278175,-125.436279,0.010266,0.000196,0.004969,10.133830,0.516242,0.049692,-125.436279,0.005889,0.000000
19.860001,2.334778,-125.480766,0.010300,0.000210,0.005334,10.385611,0.529068,0.053337,-125.480766,0.006305,0.000000
20.110001,2.479630,-125.480766,0.010305,0.000224,0.005698,11.029943,0.561892,0.056978,-125.480766,0.006730,0.000000
20.360001,2.753319,-125.436279,0.010330,0.000252,0.006392,12.247374,0.623911,0.063916,-125.436279,0.007146,0.000000
20.610001,2.812531,-125.480766,0.010356,0.000267,0.006790,12.510760,0.637329,0.067905,-125.480766,0.007562,0.000000
20.860001,2.864662,-125.480766,0.010356,0.000282,0.007155,12.742654,0.649142,0.071546,-125.480766,0.007979,0.000000
21.110001,2.964455,-125.525246,0.010378,0.000297,0.007536,13.186553,0.671755,0.075365,-125.525246,0.008395,0.000000
21.360001,3.095901,-125.480766,0.010378,0.000314,0.007970,13.771257,0.701541,0.079699,-125.480766,0.008811,0.000000
21.610001,3.215805,-125.480766,0.010404,0.000329,0.008351,14.304615,0.728712,0.083514,-125.480766,0.009228,0.000000
21.860001,3.348000,-125.525246,0.010430,0.000346,0.008794,14.892646,0.758668,0.087938,-125.525246,0.009644,0.000000
22.110001,3.448540,-125.525246,0.010438,0.000363,0.009219,15.339870,0.781450,0.092189,-125.525246,0.010060,0.000000
22.360001,3.601212,-125.569725,0.010455,0.000383,0.009722,16.018990,0.816046,0.097219,-125.569725,0.010476,0.000000
22.610001,3.691330,-125.569725,0.010473,0.000400,0.010173,16.419855,0.836467,0.101727,-125.569725,0.010893,0.000000
22.860001,3.656700,-125.525246,0.010503,0.000414,0.010520,16.265814,0.828620,0.105197,-125.525246,0.011309,0.000000
23.110001,3.725212,-125.525246,0.010499,0.000427,0.010858,16.570572,0.844145,0.108577,-125.525246,0.011725,0.000000
23.360001,3.857033,-125.525246,0.010524,0.000446,0.011326,17.156939,0.874016,0.113259,-125.525246,0.012141,0.000000
23.610001,3.953476,-125.569725,0.010524,0.000464,0.011786,17.585939,0.895870,0.117858,-125.569725,0.012558,0.000000
23.860001,3.986992,-125.614204,0.010559,0.000475,0.012063,17.735025,0.903465,0.120632,-125.614204,0.012974,0.000000
24.110001,4.154930,-125.525246,0.010593,0.000498,0.012644,18.482052,0.941521,0.126442,-125.525246,0.013390,0.000000
24.360001,4.210785,-125.614204,0.010585,0.000514,0.013061,18.730507,0.954177,0.130605,-125.614204,0.013807,0.000000
24.610001,4.241692,-125.525246,0.010606,0.000529,0.013442,18.867987,0.961181,0.134421,-125.525246,0.014222,0.000000
24.860001,4.264778,-125.569725,0.010637,0.000544,0.013815,18.970680,0.966413,0.138149,-125.569725,0.014639,0.000000
25.110001,4.299782,-125.614204,0.010628,0.000557,0.014145,19.126385,0.974344,0.141445,-125.614204,0.015064,0.000000
25.360001,4.395485,-125.569725,0.010637,0.000574,0.014578,19.552094,0.996031,0.145783,-125.569725,0.015480,0.000000
25.610001,4.517250,-125.614204,0.010675,0.000594,0.015090,20.093731,1.023623,0.150900,-125.614204,0.015897,0.000000
25.860001,4.459534,-125.614204,0.010680,0.000602,0.015298,19.836996,1.010545,0.152982,-125.614204,0.016313,0.000000
26.110001,4.628960,-125.614204,0.010697,0.000623,0.015827,20.590641,1.048937,0.158269,-125.614204,0.016729,0.000000
26.360001,4.733597,-125.703171,0.010731,0.000644,0.016356,21.056089,1.072648,0.163560,-125.703171,0.017145,0.000000
26.610001,4.753334,-125.658684,0.010749,0.000659,0.016746,21.143887,1.077121,0.167463,-125.658684,0.017562,0.000000
26.860001,4.784241,-125.614204,0.010731,0.000675,0.017136,21.281366,1.084124,0.171365,-125.614204,0.017978,0.000000
27.110001,4.785355,-125.658684,0.010774,0.000686,0.017431,21.286320,1.084377,0.174313,-125.658684,0.018394,0.000000
27.360001,4.954414,-125.703171,0.010792,0.000708,0.017978,22.038336,1.122686,0.179779,-125.703171,0.018810,0.000000
27.610001,4.935799,-125.658684,0.010822,0.000721,0.018316,21.955528,1.118468,0.183159,-125.658684,0.019227,0.000000
27.860001,4.927605,-125.703171,0.010822,0.000733,0.018611,21.919081,1.116611,0.186107,-125.703171,0.019643,0.000000
28.110001,5.137619,-125.703171,0.010835,0.000755,0.019183,22.853271,1.164201,0.191830,-125.703171,0.020059,0.000000
28.360001,5.194969,-125.747650,0.010856,0.000771,0.019574,23.108377,1.177197,0.195736,-125.747650,0.020475,0.000000
28.610001,5.183800,-125.658684,0.010865,0.000787,0.019990,23.058693,1.174666,0.199895,-125.658684,0.020891,0.000000
28.860001,5.239655,-125.747650,0.010869,0.000802,0.020380,23.307148,1.187323,0.203798,-125.747650,0.021308,0.000000
29.110001,5.301842,-125.703171,0.010878,0.000819,0.020814,23.583771,1.201414,0.208135,-125.703171,0.021724,0.000000
29.360001,5.372589,-125.747650,0.010925,0.000834,0.021195,23.898470,1.217446,0.211950,-125.747650,0.022140,0.000000
29.610001,5.366631,-125.792130,0.010934,0.000846,0.021499,23.871965,1.216096,0.214986,-125.792130,0.022557,0.000000
29.860001,5.534943,-125.747650,0.010925,0.000866,0.022002,24.620655,1.254236,0.220016,-125.747650,0.022973,0.000000
30.110001,5.616867,-125.747650,0.010977,0.000884,0.022453,24.985073,1.272800,0.224528,-125.747650,0.023389,0.000000
30.360001,5.680168,-125.792130,0.010981,0.000902,0.022904,25.266649,1.287145,0.229035,-125.792130,0.023814,0.000000
30.610001,5.674583,-125.703171,0.011016,0.000918,0.023329,25.241808,1.285879,0.233286,-125.703171,0.024231,0.000000
30.860001,5.743469,-125.703171,0.011025,0.000936,0.023762,25.548227,1.301489,0.237619,-125.703171,0.024647,0.000000
31.110001,5.845879,-125.792130,0.011055,0.000955,0.024256,26.003767,1.324695,0.242563,-125.792130,0.025063,0.000000
31.360001,5.768051,-125.792130,0.011046,0.000966,0.024534,25.657574,1.307059,0.245341,-125.792130,0.025479,0.000000
31.610001,5.926308,-125.747650,0.011076,0.000983,0.024976,26.361532,1.342921,0.249761,-125.747650,0.025895,0.000000
31.860001,6.023872,-125.792130,0.011094,0.001001,0.025436,26.795523,1.365029,0.254360,-125.792130,0.026312,0.000000
32.110001,6.085686,-125.792130,0.011098,0.001018,0.025869,27.070482,1.379036,0.258694,-125.792130,0.026728,0.000000
32.360001,6.189575,-125.836609,0.011137,0.001038,0.026372,27.532606,1.402578,0.263724,-125.836609,0.027144,0.000000
32.610001,6.108025,-125.792130,0.011132,0.001050,0.026676,27.169851,1.384098,0.266759,-125.792130,0.027560,0.000000
32.860001,6.211914,-125.836609,0.011167,0.001069,0.027144,27.631973,1.407640,0.271441,-125.836609,0.027977,0.000000
33.110001,6.359001,-125.792130,0.011197,0.001088,0.027638,28.286249,1.440970,0.276384,-125.792130,0.028393,0.000000
33.360001,6.381348,-125.836609,0.011180,0.001103,0.028012,28.385653,1.446034,0.280116,-125.836609,0.028809,0.000000
33.610001,6.361984,-125.792130,0.011201,0.001115,0.028333,28.299519,1.441646,0.283326,-125.792130,0.029226,0.000000
33.860001,6.415604,-125.836609,0.011219,0.001130,0.028705,28.538031,1.453797,0.287054,-125.836609,0.029642,0.000000
34.110001,6.613708,-125.836609,0.011249,0.001153,0.029286,29.419245,1.498688,0.292864,-125.836609,0.030058,0.000000
34.360001,6.634560,-125.836609,0.011270,0.001170,0.029720,29.511995,1.503413,0.297201,-125.836609,0.030474,0.000000
34.610001,6.535881,-125.836609,0.011288,0.001179,0.029954,29.073051,1.481052,0.299540,-125.836609,0.030891,0.000000
34.860001,6.649452,-125.836609,0.011275,0.001196,0.030388,29.578241,1.506787,0.303878,-125.836609,0.031307,0.000000
35.110001,6.824097,-125.881088,0.011296,0.001218,0.030925,30.355099,1.546362,0.309252,-125.881088,0.031723,0.000000
35.360001,6.929108,-125.925575,0.011322,0.001233,0.031324,30.822210,1.570158,0.313242,-125.925575,0.032148,0.000000
35.610001,6.885536,-125.925575,0.011335,0.001248,0.031689,30.628395,1.560285,0.316887,-125.925575,0.032564,0.000000
35.860001,6.995392,-125.925575,0.011357,0.001265,0.032122,31.117058,1.585178,0.321220,-125.925575,0.032981,0.000000
36.110001,7.131676,-125.970055,0.011369,0.001283,0.032599,31.723278,1.616061,0.325993,-125.970055,0.033397,0.000000
36.360001,7.069862,-125.925575,0.011391,0.001299,0.032990,31.448318,1.602054,0.329895,-125.925575,0.033813,0.000000
36.610001,7.170403,-125.881088,0.011417,0.001315,0.033405,31.895544,1.624836,0.334055,-125.881088,0.034229,0.000000
36.860001,6.981987,-125.925575,0.011430,0.001320,0.033536,31.057428,1.582141,0.335357,-125.925575,0.034646,0.000000
37.110001,7.440376,-125.881088,0.011430,0.001349,0.034264,33.096447,1.686013,0.342643,-125.881088,0.035062,0.000000
37.360001,7.452660,-125.925575,0.011460,0.001364,0.034637,33.151085,1.688797,0.346371,-125.925575,0.035478,0.000000
37.610001,7.296265,-125.970055,0.011469,0.001372,0.034837,32.455406,1.653357,0.348366,-125.970055,0.035894,0.000000
37.860001,7.492508,-125.925575,0.011482,0.001392,0.035366,33.328339,1.697827,0.353657,-125.925575,0.036311,0.000000
38.110001,7.746834,-125.925575,0.011507,0.001416,0.035955,34.459637,1.755458,0.359554,-125.925575,0.036727,0.000000
38.360001,7.681297,-125.970055,0.011520,0.001430,0.036311,34.168118,1.740607,0.363108,-125.970055,0.037143,0.000000
38.610001,7.731194,-125.970055,0.011529,0.001446,0.036718,34.390068,1.751914,0.367184,-125.970055,0.037560,0.000000
38.860001,7.790031,-125.970055,0.011559,0.001461,0.037100,34.651791,1.765246,0.370999,-125.970055,0.037976,0.000000
39.110001,7.779236,-125.970055,0.011576,0.001472,0.037395,34.603767,1.762800,0.373948,-125.970055,0.038392,0.000000
39.360001,7.835091,-126.014534,0.011576,0.001487,0.037768,34.852222,1.775457,0.377680,-126.014534,0.038808,0.000000
39.610001,7.930786,-125.970055,0.011607,0.001504,0.038201,35.277897,1.797142,0.382013,-125.970055,0.039225,0.000000
39.860001,8.269272,-126.014534,0.011624,0.001526,0.038765,36.783558,1.873844,0.387653,-126.014534,0.039641,0.000000
40.110001,8.271507,-126.059013,0.011650,0.001542,0.039173,36.793503,1.874350,0.391729,-126.059013,0.040057,0.000000
40.360001,8.309494,-126.014534,0.011645,0.001557,0.039554,36.962475,1.882958,0.395544,-126.014534,0.040482,0.000000
40.610001,8.313957,-125.970055,0.011680,0.001572,0.039919,36.982330,1.883970,0.399185,-125.970055,0.040898,0.000000
40.860001,8.493813,-126.059013,0.011671,0.001590,0.040395,37.782364,1.924725,0.403954,-126.059013,0.041315,0.000000
41.110001,8.550415,-126.103493,0.011710,0.001606,0.040786,38.034145,1.937552,0.407856,-126.103493,0.041731,0.000000
41.360001,8.592125,-126.059013,0.011732,0.001621,0.041167,38.219681,1.947003,0.411672,-126.059013,0.042147,0.000000
41.610001,8.720963,-126.059013,0.011723,0.001641,0.041670,38.792778,1.976198,0.416702,-126.059013,0.042563,0.000000
41.860001,8.913109,-126.059013,0.011766,0.001660,0.042156,39.647488,2.019739,0.421562,-126.059013,0.042980,0.000000
42.110001,8.896721,-126.059013,0.011766,0.001676,0.042581,39.574593,2.016026,0.425808,-126.059013,0.043396,0.000000
42.360001,8.882942,-126.059013,0.011779,0.001690,0.042928,39.513302,2.012903,0.429279,-126.059013,0.043812,0.000000
42.610001,8.978645,-126.059013,0.011818,0.001706,0.043327,39.939011,2.034590,0.433268,-126.059013,0.044229,0.000000
42.860001,9.132805,-126.103493,0.011818,0.001723,0.043769,40.624744,2.069523,0.437689,-126.103493,0.044645,0.000000
43.110001,9.266487,-126.147980,0.011857,0.001741,0.044220,41.219395,2.099816,0.442201,-126.147980,0.045061,0.000000
43.360001,9.201324,-126.059013,0.011839,0.001755,0.044575,40.929535,2.085050,0.445755,-126.059013,0.045477,0.000000
43.610001,9.537949,-126.103493,0.011883,0.001776,0.045113,42.426914,2.161330,0.451133,-126.103493,0.045894,0.000000
43.860001,9.702164,-126.147980,0.011895,0.001795,0.045581,43.157379,2.198542,0.455815,-126.147980,0.046310,0.000000
44.110001,9.611305,-126.103493,0.011908,0.001808,0.045929,42.753220,2.177953,0.459286,-126.103493,0.046726,0.000000
44.360001,9.620239,-126.103493,0.011917,0.001823,0.046301,42.792961,2.179977,0.463014,-126.103493,0.047142,0.000000
44.610001,9.793770,-126.103493,0.011947,0.001839,0.046709,43.564865,2.219300,0.467090,-126.103493,0.047559,0.000000
44.860001,9.987778,-126.147980,0.011977,0.001857,0.047177,44.427853,2.263263,0.471772,-126.147980,0.047975,0.000000
45.110001,10.045120,-126.103493,0.011964,0.001873,0.047576,44.682926,2.276257,0.475761,-126.103493,0.048391,0.000000
45.360001,10.167259,-126.192459,0.011973,0.001889,0.047992,45.226227,2.303934,0.479925,-126.192459,0.048808,0.000000
45.610001,10.363495,-126.147980,0.012008,0.001908,0.048452,46.099129,2.348402,0.484520,-126.147980,0.049232,0.000000
45.860001,10.499786,-126.192459,0.012012,0.001925,0.048894,46.705383,2.379286,0.488944,-126.192459,0.049649,0.000000
46.110001,10.500160,-126.236938,0.012033,0.001940,0.049285,46.707047,2.379370,0.492846,-126.236938,0.050065,0.000000
46.360001,10.470367,-126.192459,0.012051,0.001952,0.049588,46.574520,2.372619,0.495882,-126.192459,0.050481,0.000000
46.610001,10.671448,-126.192459,0.012081,0.001970,0.050030,47.468971,2.418185,0.500303,-126.192459,0.050898,0.000000
46.860001,10.835663,-126.236938,0.012085,0.001987,0.050481,48.199436,2.455396,0.504814,-126.236938,0.051314,0.000000
47.110001,10.839020,-126.236938,0.012111,0.002000,0.050811,48.214367,2.456157,0.508107,-126.236938,0.051730,0.000000
47.360001,11.083664,-126.192459,0.012107,0.002019,0.051271,49.302601,2.511594,0.512706,-126.192459,0.052146,0.000000
47.610001,11.314537,-126.236938,0.012163,0.002037,0.051730,50.329575,2.563911,0.517301,-126.236938,0.052563,0.000000
47.860001,11.440773,-126.281418,0.012158,0.002054,0.052164,50.891102,2.592516,0.521638,-126.281418,0.052979,0.000000
48.110001,11.514870,-126.236938,0.012180,0.002071,0.052598,51.220699,2.609307,0.525976,-126.236938,0.053395,0.000000
48.360001,11.479500,-126.236938,0.012215,0.002082,0.052892,51.063366,2.601292,0.528924,-126.236938,0.053811,0.000000
48.610001,11.802345,-126.236938,0.012197,0.002101,0.053369,52.499454,2.674450,0.533693,-126.236938,0.054228,0.000000
48.860001,11.911453,-126.236938,0.012210,0.002117,0.053768,52.984791,2.699174,0.537682,-126.236938,0.054644,0.000000
49.110001,11.612434,-126.236938,0.012215,0.002122,0.053907,51.654690,2.631415,0.539067,-126.236938,0.055060,0.000000
49.360001,12.317337,-126.236938,0.012249,0.002150,0.054618,54.790253,2.791148,0.546179,-126.236938,0.055477,0.000000
49.610001,12.395531,-126.281418,0.012284,0.002167,0.055052,55.138073,2.808867,0.550517,-126.281418,0.055893,0.000000
49.860001,12.364624,-126.236938,0.012292,0.002180,0.055373,55.000595,2.801864,0.553726,-126.236938,0.056309,0.000000
50.110001,12.631989,-126.236938,0.012309,0.002198,0.055823,56.189892,2.862450,0.558234,-126.236938,0.056725,0.000000
50.360001,12.591774,-126.325897,0.012296,0.002211,0.056153,56.011009,2.853337,0.561531,-126.325897,0.057142,0.000000
50.610001,12.929520,-126.325897,0.012327,0.002230,0.056639,57.513374,2.929871,0.566387,-126.325897,0.057567,0.000000
50.860001,12.944786,-126.281418,0.012348,0.002243,0.056968,57.581284,2.933330,0.569683,-126.281418,0.057983,0.000000
51.110001,13.229652,-126.325897,0.012361,0.002261,0.057419,58.848434,2.997882,0.574191,-126.325897,0.058399,0.000000
51.360001,13.646332,-126.325897,0.012404,0.002280,0.057905,60.701916,3.092303,0.579047,-126.325897,0.058815,0.000000
51.610001,13.837364,-126.325897,0.012413,0.002298,0.058373,61.551670,3.135592,0.583729,-126.325897,0.059232,0.000000
51.860001,13.853745,-126.281418,0.012417,0.002312,0.058729,61.624535,3.139303,0.587287,-126.281418,0.059648,0.000000
52.110001,14.043655,-126.370384,0.012430,0.002330,0.059179,62.469299,3.182338,0.591795,-126.370384,0.060064,0.000000
52.360001,14.335594,-126.370384,0.012443,0.002348,0.059648,63.767906,3.248492,0.596481,-126.370384,0.060480,0.000000
52.610001,14.292030,-126.370384,0.012452,0.002360,0.059943,63.574127,3.238620,0.599429,-126.370384,0.060897,0.000000
52.860001,14.567581,-126.370384,0.012486,0.002379,0.060428,64.799835,3.301061,0.604285,-126.370384,0.061313,0.000000
53.110004,14.814835,-126.370384,0.012508,0.002395,0.060845,65.899673,3.357090,0.608448,-126.370384,0.061729,0.000000
53.360004,15.067680,-126.370384,0.012512,0.002414,0.061304,67.024391,3.414385,0.613043,-126.370384,0.062146,0.000000
53.610004,15.542458,-126.414864,0.012525,0.002433,0.061807,69.136307,3.521971,0.618073,-126.414864,0.062562,0.000000
53.860004,15.396484,-126.370384,0.012568,0.002445,0.062111,68.486984,3.488893,0.621109,-126.370384,0.062978,0.000000
54.110004,15.700714,-126.414864,0.012564,0.002464,0.062588,69.840263,3.557833,0.625878,-126.414864,0.063394,0.000000
54.360004,15.769974,-126.414864,0.012559,0.002477,0.062926,70.148346,3.573527,0.629261,-126.414864,0.063811,0.000000
54.610004,16.154633,-126.370384,0.012581,0.002497,0.063412,71.859398,3.660692,0.634118,-126.370384,0.064227,0.000000
54.860004,16.165436,-126.459343,0.012611,0.002509,0.063724,71.907448,3.663140,0.637240,-126.459343,0.064643,0.000000
55.110004,16.486420,-126.414864,0.012616,0.002525,0.064132,73.335258,3.735876,0.641316,-126.414864,0.065059,0.000000
55.360004,17.071785,-126.414864,0.012641,0.002547,0.064695,75.939095,3.868522,0.646952,-126.414864,0.065476,0.000000
55.610004,17.314575,-126.414864,0.012667,0.002563,0.065103,77.019073,3.923539,0.651028,-126.414864,0.065901,0.000000
55.860004,17.289627,-126.459343,0.012676,0.002576,0.065441,76.908104,3.917886,0.654408,-126.459343,0.066317,0.000000
56.110004,17.599815,-126.414864,0.012659,0.002593,0.065857,78.287888,3.988175,0.658572,-126.414864,0.066733,0.000000
56.360004,17.744293,-126.459343,0.012710,0.002607,0.066213,78.930557,4.020915,0.662130,-126.459343,0.067149,0.000000
56.610004,18.491646,-126.459343,0.012710,0.002630,0.066803,82.254951,4.190267,0.668026,-126.459343,0.067566,0.000000
56.860004,18.398926,-126.414864,0.012719,0.002640,0.067054,81.842506,4.169256,0.670540,-126.414864,0.067982,0.000000
57.110004,18.776138,-126.459343,0.012745,0.002658,0.067522,83.520432,4.254734,0.675222,-126.459343,0.068398,0.000000
57.360004,19.302673,-126.503822,0.012736,0.002678,0.068017,85.862579,4.374048,0.680168,-126.503822,0.068814,0.000000
57.610004,19.514175,-126.503822,0.012788,0.002693,0.068407,86.803391,4.421976,0.684071,-126.503822,0.069231,0.000000
57.860004,19.447525,-126.503822,0.012801,0.002705,0.068719,86.506912,4.406872,0.687189,-126.503822,0.069647,0.000000
58.110004,19.668343,-126.459343,0.012818,0.002718,0.069031,87.489159,4.456910,0.690312,-126.459343,0.070063,0.000000
58.360004,20.500595,-126.503822,0.012835,0.002742,0.069638,91.191200,4.645501,0.696383,-126.503822,0.070480,0.000000
58.610004,20.626457,-126.548309,0.012831,0.002752,0.069907,91.751060,4.674022,0.699074,-126.548309,0.070896,0.000000
58.860004,20.868126,-126.503822,0.012848,0.002768,0.070306,92.826057,4.728785,0.703059,-126.503822,0.071312,0.000000
59.110004,21.083359,-126.459343,0.012857,0.002784,0.070705,93.783463,4.777557,0.707049,-126.459343,0.071728,0.000000
59.360004,22.218719,-126.548309,0.012896,0.002809,0.071355,98.833801,5.034834,0.713555,-126.548309,0.072145,0.000000
59.610004,22.260056,-126.592789,0.012900,0.002824,0.071720,99.017670,5.044200,0.717196,-126.592789,0.072561,0.000000
59.860004,22.703918,-126.548309,0.012904,0.002842,0.072179,100.992073,5.144781,0.721795,-126.548309,0.072977,0.000000
60.110004,22.418686,-126.548309,0.012930,0.002853,0.072466,99.723297,5.080147,0.724656,-126.548309,0.073393,0.000000
60.360004,23.136620,-126.592789,0.012947,0.002869,0.072865,102.916824,5.242833,0.728645,-126.592789,0.073810,0.000000
60.610004,23.483665,-126.548309,0.012956,0.002884,0.073246,104.460564,5.321475,0.732460,-126.548309,0.074226,0.000000
60.860004,23.705605,-126.592789,0.012978,0.002896,0.073558,105.447792,5.371767,0.735583,-126.592789,0.074651,0.000000
61.110004,24.366562,-126.592789,0.012969,0.002915,0.074044,108.387878,5.521542,0.740439,-126.592789,0.075067,0.000000
61.360004,25.243500,-126.592789,0.012995,0.002937,0.074607,112.288696,5.720259,0.746075,-126.592789,0.075483,0.000000
61.610004,25.364151,-126.592789,0.013012,0.002952,0.074980,112.825378,5.747599,0.749803,-126.592789,0.075900,0.000000
61.860004,25.787163,-126.592789,0.013034,0.002967,0.075362,114.707031,5.843454,0.753622,-126.592789,0.076316,0.000000
62.110004,26.091393,-126.548309,0.013029,0.002981,0.075718,116.060310,5.912394,0.757176,-126.548309,0.076732,0.000000
62.360004,26.778046,-126.681747,0.013042,0.003001,0.076238,119.114693,6.067992,0.762380,-126.681747,0.077149,0.000000
62.610004,27.129570,-126.637268,0.013068,0.003016,0.076611,120.678352,6.147648,0.766108,-126.637268,0.077565,0.000000
62.860004,26.996262,-126.637268,0.013073,0.003027,0.076880,120.085365,6.117441,0.768795,-126.637268,0.077981,0.000000
63.110004,28.477928,-126.592789,0.013085,0.003052,0.077530,126.676147,6.453191,0.775302,-126.592789,0.078397,0.000000
63.360004,28.964989,-126.637268,0.013111,0.003071,0.078007,128.842697,6.563560,0.780071,-126.637268,0.078814,0.000000
63.610004,29.281883,-126.637268,0.013120,0.003086,0.078380,130.252319,6.635369,0.783799,-126.637268,0.079230,0.000000
63.860004,29.437157,-126.681747,0.013133,0.003099,0.078718,130.943008,6.670555,0.787182,-126.681747,0.079646,0.000000
64.110001,30.184509,-126.681747,0.013154,0.003118,0.079186,134.267410,6.839908,0.791864,-126.681747,0.080062,0.000000
64.360001,30.563957,-126.681747,0.013142,0.003133,0.079568,135.955276,6.925892,0.795680,-126.681747,0.080479,0.000000
64.610001,31.070755,-126.637268,0.013167,0.003147,0.079932,138.209625,7.040734,0.799324,-126.637268,0.080895,0.000000
64.860001,31.835983,-126.726227,0.013163,0.003165,0.080401,141.613525,7.214137,0.804006,-126.726227,0.081311,0.000000
65.110001,32.725212,-126.592789,0.013180,0.003187,0.080947,145.569016,7.415639,0.809472,-126.592789,0.081728,0.000000
65.360001,33.212273,-126.726227,0.013219,0.003202,0.081329,147.735565,7.526009,0.813287,-126.726227,0.082144,0.000000
65.610001,33.551506,-126.681747,0.013219,0.003217,0.081710,149.244553,7.602880,0.817102,-126.681747,0.082560,0.000000
65.860001,33.860573,-126.681747,0.013228,0.003231,0.082074,150.619354,7.672915,0.820743,-126.681747,0.082985,0.000000
66.110001,34.831345,-126.726227,0.013241,0.003250,0.082560,154.937561,7.892895,0.825599,-126.726227,0.083401,0.000000
66.360001,35.532524,-126.770714,0.013245,0.003267,0.082976,158.056564,8.051785,0.829763,-126.770714,0.083818,0.000000
66.610001,35.512787,-126.726227,0.013254,0.003276,0.083219,157.968765,8.047313,0.832192,-126.726227,0.084234,0.000000
66.860001,36.772156,-126.726227,0.013271,0.003298,0.083774,163.570724,8.332690,0.837741,-126.726227,0.084650,0.000000
67.110001,37.439445,-126.770714,0.013310,0.003316,0.084225,166.538971,8.483900,0.842253,-126.770714,0.085066,0.000000
67.360001,38.126099,-126.726227,0.013301,0.003333,0.084667,169.593353,8.639498,0.846673,-126.726227,0.085483,0.000000
67.610001,38.632523,-126.770714,0.013310,0.003347,0.085014,171.846039,8.754255,0.850144,-126.770714,0.085899,0.000000
67.860001,39.409294,-126.770714,0.013327,0.003363,0.085430,175.301300,8.930274,0.854304,-126.770714,0.086315,0.000000
68.110001,40.186440,-126.770714,0.013340,0.003382,0.085899,178.758209,9.106378,0.858989,-126.770714,0.086731,0.000000
68.360001,40.676109,-126.770714,0.013340,0.003394,0.086211,180.936371,9.217339,0.862112,-126.770714,0.087148,0.000000
68.610001,41.061882,-126.770714,0.013357,0.003409,0.086584,182.652374,9.304755,0.865840,-126.770714,0.087564,0.000000
68.860001,42.242676,-126.815193,0.013336,0.003429,0.087104,187.904800,9.572328,0.871044,-126.815193,0.087980,0.000000
69.110001,43.185150,-126.815193,0.013370,0.003446,0.087538,192.097137,9.785895,0.875378,-126.815193,0.088397,0.000000
69.360001,43.958939,-126.726227,0.013396,0.003463,0.087963,195.539124,9.961238,0.879629,-126.726227,0.088813,0.000000
69.610001,44.606873,-126.815193,0.013400,0.003478,0.088344,198.421280,10.108062,0.883444,-126.815193,0.089229,0.000000
69.860001,45.137871,-126.859673,0.013396,0.003492,0.088700,200.783279,10.228388,0.887002,-126.859673,0.089645,0.000000
70.110001,46.175301,-126.770714,0.013413,0.003510,0.089151,205.397995,10.463472,0.891509,-126.770714,0.090062,0.000000
70.360001,46.358139,-126.815193,0.013448,0.003520,0.089420,206.211304,10.504905,0.894197,-126.815193,0.090478,0.000000
70.610001,47.205284,-126.859673,0.013409,0.003542,0.089966,209.979584,10.696870,0.899662,-126.859673,0.090894,0.000000
70.860001,48.691795,-126.904152,0.013461,0.003560,0.090417,216.591919,11.033718,0.904170,-126.904152,0.091319,0.000000
71.110001,49.298759,-126.904152,0.013461,0.003574,0.090781,219.291840,11.171259,0.907815,-126.904152,0.091735,0.000000
71.360001,50.090797,-126.815193,0.013456,0.003590,0.091180,222.815002,11.350738,0.911804,-126.815193,0.092152,0.000000
71.610001,50.618454,-126.904152,0.013478,0.003602,0.091501,225.162125,11.470305,0.915010,-126.904152,0.092568,0.000000
71.860001,52.091927,-126.859673,0.013486,0.003625,0.092065,231.716461,11.804199,0.920649,-126.859673,0.092984,0.000000
72.110001,52.403976,-126.859673,0.013508,0.003635,0.092334,233.104523,11.874911,0.923337,-126.859673,0.093400,0.000000
72.360001,53.164734,-126.904152,0.013517,0.003648,0.092663,236.488541,12.047301,0.926633,-126.904152,0.093817,0.000000
72.610001,54.390587,-126.904152,0.013525,0.003670,0.093209,241.941406,12.325084,0.932095,-126.904152,0.094233,0.000000
72.860001,55.768364,-126.859673,0.013542,0.003690,0.093730,248.070068,12.637292,0.937299,-126.859673,0.094649,0.000000
73.110001,56.939842,-126.904152,0.013538,0.003709,0.094198,253.281067,12.902753,0.941981,-126.904152,0.095066,0.000000
73.360001,57.463028,-126.904152,0.013555,0.003720,0.094493,255.608307,13.021309,0.944929,-126.904152,0.095482,0.000000
73.610001,58.493759,-126.904152,0.013555,0.003738,0.094944,260.193237,13.254875,0.949441,-126.904152,0.095898,0.000000
73.860001,59.778069,-126.948631,0.013568,0.003756,0.095404,265.906128,13.545904,0.954036,-126.948631,0.096314,0.000000
74.110001,60.369392,-126.948631,0.013590,0.003769,0.095725,268.536469,13.679899,0.957245,-126.948631,0.096731,0.000000
74.360001,61.305542,-126.948631,0.013594,0.003785,0.096132,272.700684,13.892035,0.961322,-126.948631,0.097147,0.000000
74.610001,62.360474,-126.948631,0.013581,0.003802,0.096566,277.393250,14.131085,0.965655,-126.948631,0.097563,0.000000
74.860001,63.936722,-126.948631,0.013603,0.003824,0.097129,284.404755,14.488269,0.971295,-126.948631,0.097979,0.000000
75.110001,64.869888,-126.904152,0.013607,0.003839,0.097520,288.555664,14.699726,0.975197,-126.904152,0.098396,0.000000
75.360001,65.892059,-126.948631,0.013620,0.003857,0.097970,293.102509,14.931354,0.979705,-126.948631,0.098812,0.000000
75.610001,66.649078,-126.948631,0.013616,0.003870,0.098300,296.469910,15.102897,0.983002,-126.948631,0.099228,0.000000
75.860001,67.526764,-126.993118,0.013655,0.003875,0.098422,300.374054,15.301784,0.984217,-126.993118,0.098673,0.000000
76.110001,66.830063,-126.993118,0.013672,0.003875,0.098422,297.274963,15.143909,0.984217,-126.993118,0.098673,0.000000
76.360001,66.204849,-127.037598,0.013646,0.003872,0.098352,294.493866,15.002234,0.983524,-127.037598,0.098422,0.000000
76.610001,65.675705,-126.993118,0.013650,0.003870,0.098309,292.140137,14.882328,0.983089,-126.993118,0.098422,0.000000
76.860001,65.231461,-127.037598,0.013668,0.003870,0.098291,290.164032,14.781660,0.982915,-127.037598,0.098422,0.000000
77.110001,64.826324,-126.993118,0.013676,0.003869,0.098274,288.361908,14.689856,0.982740,-126.993118,0.098422,0.000000
77.360001,64.470337,-127.082077,0.013655,0.003869,0.098265,286.778381,14.609187,0.982653,-127.082077,0.098422,0.000000
77.610001,64.153442,-126.993118,0.013676,0.003868,0.098257,285.368774,14.537378,0.982566,-126.993118,0.098422,0.000000
77.860001,63.855545,-127.037598,0.013659,0.003868,0.098248,284.043640,14.469872,0.982483,-127.037598,0.098422,0.000000
78.110001,63.602707,-126.993118,0.013672,0.003868,0.098240,282.918976,14.412579,0.982396,-126.993118,0.098422,0.000000
78.360001,63.352478,-127.082077,0.013668,0.003868,0.098240,281.805908,14.355877,0.982396,-127.082077,0.098422,0.000000
78.610001,63.138359,-127.082077,0.013663,0.003868,0.098240,280.853455,14.307357,0.982396,-127.082077,0.098422,0.000000
78.860001,62.928711,-127.082077,0.013676,0.003867,0.098231,279.920898,14.259851,0.982309,-127.082077,0.098422,0.000000
79.110001,62.745880,-127.037598,0.013680,0.003867,0.098231,279.107605,14.218420,0.982309,-127.037598,0.098422,0.000000
79.360001,62.562294,-127.082077,0.013680,0.003867,0.098231,278.290985,14.176818,0.982309,-127.082077,0.098422,0.000000
79.610001,62.405899,-127.037598,0.013672,0.003867,0.098231,277.595306,14.141378,0.982309,-127.037598,0.098422,0.000000
79.860001,62.233116,-127.082077,0.013685,0.003867,0.098222,276.826721,14.102225,0.982222,-127.082077,0.098422,0.000000
80.110001,62.109489,-127.126556,0.013689,0.003867,0.098222,276.276794,14.074211,0.982222,-127.126556,0.098422,0.000000
80.360001,61.970222,-127.082077,0.013693,0.003867,0.098222,275.657318,14.042653,0.982222,-127.082077,0.098422,0.000000
80.610001,61.833939,-127.126556,0.013685,0.003867,0.098222,275.051086,14.011770,0.982222,-127.126556,0.098422,0.000000
80.860001,61.698769,-127.126556,0.013668,0.003867,0.098222,274.449829,13.981141,0.982222,-127.126556,0.098422,0.000000
81.110001,61.581841,-127.126556,0.013698,0.003867,0.098222,273.929718,13.954645,0.982222,-127.126556,0.098422,0.000000
81.360001,61.470131,-127.126556,0.013680,0.003867,0.098222,273.432800,13.929331,0.982222,-127.126556,0.098422,0.000000
81.610001,61.368095,-127.126556,0.013693,0.003867,0.098222,272.978912,13.906209,0.982222,-127.126556,0.098422,0.000000
81.860001,61.259369,-127.082077,0.013689,0.003867,0.098222,272.495270,13.881572,0.982222,-127.082077,0.098422,0.000000
82.110001,61.159195,-127.171036,0.013680,0.003867,0.098222,272.049683,13.858871,0.982222,-127.171036,0.098422,0.000000
82.360001,61.059029,-127.126556,0.013689,0.003867,0.098222,271.604126,13.836173,0.982222,-127.126556,0.098422,0.000000
82.610001,60.942474,-127.171036,0.013715,0.003867,0.098213,271.085663,13.809762,0.982135,-127.171036,0.098422,0.000000
82.860001,60.870605,-127.171036,0.013689,0.003867,0.098213,270.765991,13.793477,0.982135,-127.171036,0.098422,0.000000
83.110001,60.785706,-127.171036,0.013672,0.003867,0.098213,270.388336,13.774238,0.982135,-127.171036,0.098422,0.000000
83.360001,60.699692,-127.171036,0.013702,0.003867,0.098213,270.005707,13.754747,0.982135,-127.171036,0.098422,0.000000
83.610001,60.618141,-127.260002,0.013715,0.003867,0.098213,269.642944,13.736267,0.982135,-127.260002,0.098422,0.000000
83.860001,60.532494,-127.215523,0.013702,0.003867,0.098213,269.261993,13.716860,0.982135,-127.215523,0.098422,0.000000
84.110001,60.459885,-127.215523,0.013702,0.003867,0.098213,268.938995,13.700406,0.982135,-127.215523,0.098422,0.000000
84.360001,60.385033,-127.215523,0.013693,0.003867,0.098213,268.606049,13.683444,0.982135,-127.215523,0.098422,0.000000
84.610001,60.324341,-127.260002,0.013706,0.003867,0.098213,268.336060,13.669691,0.982135,-127.260002,0.098422,0.000000
84.860001,60.247627,-127.215523,0.013680,0.003867,0.098213,267.994843,13.652308,0.982135,-127.215523,0.098422,0.000000
85.110001,60.183212,-127.215523,0.013689,0.003867,0.098213,267.708313,13.637711,0.982135,-127.215523,0.098422,0.000000
85.360001,60.112831,-127.215523,0.013702,0.003867,0.098213,267.395233,13.621762,0.982135,-127.215523,0.098422,0.000000
85.610001,60.061447,-127.215523,0.013676,0.003867,0.098213,267.166656,13.610118,0.982135,-127.215523,0.098422,0.000000
85.860001,59.994789,-127.260002,0.013685,0.003867,0.098213,266.870148,13.595014,0.982135,-127.260002,0.098422,0.000000
86.110001,59.931862,-127.260002,0.013698,0.003867,0.098213,266.590240,13.580754,0.982135,-127.260002,0.098422,0.000000
86.360001,59.883820,-127.260002,0.013706,0.003867,0.098213,266.376526,13.569867,0.982135,-127.260002,0.098422,0.000000
86.610001,59.827591,-127.260002,0.013702,0.003867,0.098213,266.126404,13.557126,0.982135,-127.260002,0.098422,0.000000
86.860001,59.785889,-127.304482,0.013702,0.003867,0.098213,265.940918,13.547676,0.982135,-127.304482,0.098422,0.000000
87.110001,59.719231,-127.260002,0.013685,0.003867,0.098213,265.644409,13.532571,0.982135,-127.260002,0.098422,0.000000
87.360001,59.667473,-127.260002,0.013711,0.003867,0.098213,265.414185,13.520843,0.982135,-127.260002,0.098422,0.000000
87.610001,59.624649,-127.348961,0.013706,0.003867,0.098213,265.223694,13.511139,0.982135,-127.348961,0.098422,0.000000
87.860001,59.572891,-127.260002,0.013702,0.003867,0.098213,264.993469,13.499411,0.982135,-127.260002,0.098422,0.000000
88.110001,59.528206,-127.348961,0.013680,0.003867,0.098213,264.794678,13.489285,0.982135,-127.348961,0.098422,0.000000
88.360001,59.486504,-127.348961,0.013702,0.003867,0.098213,264.609192,13.479835,0.982135,-127.348961,0.098422,0.000000
88.610001,59.433624,-127.348961,0.013715,0.003867,0.098213,264.373962,13.467853,0.982135,-127.348961,0.098422,0.000000
88.860001,59.381866,-127.304482,0.013702,0.003867,0.098213,264.143738,13.456123,0.982135,-127.304482,0.098422,0.000000
89.110001,59.345741,-127.393440,0.013702,0.003867,0.098213,263.983032,13.447937,0.982135,-127.393440,0.098422,0.000000
89.360001,59.302551,-127.348961,0.013706,0.003867,0.098213,263.790924,13.438150,0.982135,-127.348961,0.098422,0.000000
89.610001,59.271271,-127.348961,0.013689,0.003867,0.098213,263.651794,13.431062,0.982135,-127.348961,0.098422,0.000000
89.860001,59.219879,-127.348961,0.013719,0.003867,0.098213,263.423187,13.419416,0.982135,-127.348961,0.098422,0.000000
90.110001,59.116737,-127.393440,0.013698,0.003866,0.098205,262.964386,13.396045,0.982048,-127.393440,0.098422,0.000000
90.360001,59.076889,-127.437927,0.013728,0.003866,0.098205,262.787140,13.387014,0.982048,-127.437927,0.098422,0.000000
90.610001,59.032951,-127.348961,0.013702,0.003866,0.098205,262.591675,13.377058,0.982048,-127.348961,0.098422,0.000000
90.860001,59.002045,-127.393440,0.013693,0.003866,0.098205,262.454193,13.370054,0.982048,-127.393440,0.098422,0.000000
91.110001,58.980446,-127.393440,0.013693,0.003866,0.098205,262.358124,13.365160,0.982048,-127.393440,0.098422,0.000000
91.360001,58.930176,-127.393440,0.013693,0.003866,0.098205,262.134521,13.353768,0.982048,-127.393440,0.098422,0.000000
91.610001,58.901131,-127.437927,0.013685,0.003866,0.098205,262.005310,13.347187,0.982048,-127.437927,0.098422,0.000000
91.860001,58.863152,-127.437927,0.013702,0.003866,0.098205,261.836365,13.338581,0.982048,-127.437927,0.098422,0.000000
92.110001,58.832611,-127.437927,0.013693,0.003866,0.098205,261.700531,13.331660,0.982048,-127.437927,0.098422,0.000000
92.360001,58.797981,-127.437927,0.013702,0.003866,0.098205,261.546478,13.323813,0.982048,-127.437927,0.098422,0.000000
92.610001,58.751434,-127.482407,0.013689,0.003866,0.098205,261.339447,13.313265,0.982048,-127.482407,0.098422,0.000000
92.860001,58.742500,-127.393440,0.013698,0.003866,0.098205,261.299683,13.311240,0.982048,-127.393440,0.098422,0.000000
93.110001,58.698563,-127.437927,0.013711,0.003866,0.098205,261.104248,13.301284,0.982048,-127.437927,0.098422,0.000000
93.360008,58.671005,-127.482407,0.013702,0.003866,0.098205,260.981659,13.295040,0.982048,-127.482407,0.098422,0.000000
93.610008,58.639351,-127.482407,0.013719,0.003866,0.098205,260.840851,13.287868,0.982048,-127.482407,0.098422,0.000000
93.860008,58.593552,-127.393440,0.013702,0.003866,0.098205,260.637146,13.277489,0.982048,-127.393440,0.098422,0.000000
94.110008,58.581635,-127.526886,0.013702,0.003866,0.098205,260.584137,13.274788,0.982048,-127.526886,0.098422,0.000000
94.360008,58.548119,-127.482407,0.013698,0.003866,0.098205,260.435028,13.267193,0.982048,-127.482407,0.098422,0.000000
94.610008,58.523544,-127.482407,0.013711,0.003866,0.098205,260.325714,13.261625,0.982048,-127.482407,0.098422,0.000000
94.860008,58.486679,-127.482407,0.013689,0.003866,0.098205,260.161743,13.253271,0.982048,-127.482407,0.098422,0.000000
95.110008,58.467690,-127.526886,0.013719,0.003866,0.098205,260.077271,13.248968,0.982048,-127.526886,0.098422,0.000000
95.360008,58.436035,-127.482407,0.013715,0.003866,0.098205,259.936462,13.241796,0.982048,-127.482407,0.098422,0.000000
95.610008,58.417046,-127.526886,0.013689,0.003866,0.098205,259.851990,13.237492,0.982048,-127.526886,0.098422,0.000000
95.860008,58.379066,-127.526886,0.013702,0.003866,0.098205,259.683044,13.228886,0.982048,-127.526886,0.098422,0.000000
96.110008,58.345177,-127.571365,0.013711,0.003866,0.098205,259.532318,13.221207,0.982048,-127.571365,0.098422,0.000000
96.360008,58.325073,-127.482407,0.013706,0.003866,0.098205,259.442871,13.216651,0.982048,-127.482407,0.098422,0.000000
96.610008,58.300125,-127.571365,0.013719,0.003866,0.098205,259.331909,13.210998,0.982048,-127.571365,0.098422,0.000000
96.860008,58.278526,-127.526886,0.013732,0.003866,0.098205,259.235840,13.206102,0.982048,-127.526886,0.098422,0.000000
97.110008,58.249855,-127.571365,0.013706,0.003866,0.098205,259.108307,13.199606,0.982048,-127.571365,0.098422,0.000000
97.360008,58.230858,-127.571365,0.013680,0.003866,0.098205,259.023804,13.195301,0.982048,-127.571365,0.098422,0.000000
97.610008,58.199951,-127.615852,0.013719,0.003866,0.098205,258.886322,13.188297,0.982048,-127.615852,0.098422,0.000000
97.860008,58.187668,-127.615852,0.013719,0.003866,0.098205,258.831665,13.185514,0.982048,-127.615852,0.098422,0.000000
98.110008,58.156013,-127.526886,0.013728,0.003866,0.098205,258.690857,13.178341,0.982048,-127.526886,0.098422,0.000000
98.360008,58.123993,-127.571365,0.013698,0.003866,0.098205,258.548431,13.171085,0.982048,-127.571365,0.098422,0.000000
98.610008,58.105743,-127.571365,0.013702,0.003866,0.098205,258.467255,13.166950,0.982048,-127.571365,0.098422,0.000000
98.860008,58.101273,-127.571365,0.013715,0.003866,0.098205,258.447357,13.165936,0.982048,-127.571365,0.098422,0.000000
99.110008,58.048767,-127.660332,0.013702,0.003866,0.098205,258.213806,13.154038,0.982048,-127.660332,0.098422,0.000000
99.360008,58.033134,-127.660332,0.013693,0.003866,0.098205,258.144287,13.150496,0.982048,-127.660332,0.098422,0.000000
99.610008,58.012276,-127.615852,0.013715,0.003866,0.098205,258.051483,13.145769,0.982048,-127.615852,0.098422,0.000000
99.860008,57.988075,-127.704811,0.013698,0.003866,0.098205,257.943848,13.140285,0.982048,-127.704811,0.098422,0.000000
100.110008,57.976906,-127.660332,0.013732,0.003866,0.098205,257.894165,13.137754,0.982048,-127.660332,0.098422,0.000000
100.360008,57.938545,-127.660332,0.013736,0.003866,0.098205,257.723511,13.129063,0.982048,-127.660332,0.098422,0.000000
100.610008,57.924026,-127.704811,0.013702,0.003866,0.098205,257.658936,13.125772,0.982048,-127.704811,0.098422,0.000000
100.860008,57.904663,-127.660332,0.013728,0.003866,0.098205,257.572815,13.121385,0.982048,-127.660332,0.098422,0.000000
101.110008,57.883064,-127.660332,0.013728,0.003866,0.098205,257.476715,13.116489,0.982048,-127.660332,0.098422,0.000000
101.360008,57.848061,-127.615852,0.013702,0.003866,0.098205,257.321014,13.108558,0.982048,-127.615852,0.098422,0.000000
101.610008,57.822365,-127.660332,0.013706,0.003866,0.098205,257.206726,13.102735,0.982048,-127.660332,0.098422,0.000000
101.860008,57.806358,-127.704811,0.013685,0.003866,0.098205,257.135529,13.099108,0.982048,-127.704811,0.098422,0.000000
102.110008,57.791092,-127.660332,0.013698,0.003866,0.098205,257.067627,13.095649,0.982048,-127.660332,0.098422,0.000000
102.360008,57.766884,-127.793770,0.013719,0.003866,0.098205,256.959930,13.090163,0.982048,-127.793770,0.098422,0.000000
102.610008,57.741562,-127.749290,0.013702,0.003866,0.098205,256.847290,13.084424,0.982048,-127.749290,0.098422,0.000000
102.860008,57.715500,-127.749290,0.013711,0.003866,0.098205,256.731354,13.078519,0.982048,-127.749290,0.098422,0.000000
103.110008,57.691666,-127.660332,0.013693,0.003866,0.098205,256.625336,13.073118,0.982048,-127.660332,0.098422,0.000000
103.360008,57.678635,-127.749290,0.013724,0.003866,0.098205,256.567383,13.070165,0.982048,-127.749290,0.098422,0.000000
103.610008,57.663368,-127.704811,0.013698,0.003866,0.098205,256.499481,13.066706,0.982048,-127.704811,0.098422,0.000000
103.860008,57.633949,-127.749290,0.013724,0.003866,0.098205,256.368622,13.060040,0.982048,-127.749290,0.098422,0.000000
104.110008,57.625381,-127.749290,0.013732,0.003866,0.098205,256.330505,13.058098,0.982048,-127.749290,0.098422,0.000000
104.360008,57.600060,-127.749290,0.013724,0.003866,0.098205,256.217865,13.052361,0.982048,-127.749290,0.098422,0.000000
104.610008,57.597084,-127.749290,0.013728,0.003866,0.098205,256.204620,13.051686,0.982048,-127.749290,0.098422,0.000000
104.860008,57.559471,-127.749290,0.013711,0.003866,0.098205,256.037323,13.043162,0.982048,-127.749290,0.098422,0.000000
105.110008,57.539734,-127.838257,0.013732,0.003866,0.098205,255.949524,13.038691,0.982048,-127.838257,0.098422,0.000000
105.360008,57.530052,-127.793770,0.013715,0.003866,0.098205,255.906448,13.036496,0.982048,-127.793770,0.098422,0.000000
105.610008,57.493561,-127.838257,0.013689,0.003866,0.098205,255.744125,13.028228,0.982048,-127.838257,0.098422,0.000000
105.860008,57.491325,-127.793770,0.013732,0.003866,0.098205,255.734192,13.027720,0.982048,-127.793770,0.098422,0.000000
106.110008,57.463028,-127.793770,0.013728,0.003866,0.098205,255.608307,13.021309,0.982048,-127.793770,0.098422,0.000000
106.300003,57.463776,-127.882736,0.013724,0.003866,0.098205,255.611633,13.021478,0.982048,-127.882736,0.098422,0.000000