File: Data/Compression Sample NH 10, 12, 15, 17 batch 3/AutoNoheating-12-3-2-240212_02122024_162105.csv
Time (sec),S:Load (lbs),S:HL1 (DIM),S:LVDT (in),S:Position (in),Ch:Position (mm),Ch:Load (N),Ch:Stress (MPa),Ch:Strain (mm/mm),Ch:HL1 (DIM),Set Point (),Cycles ()
0.110000,-0.006332,-150.701462,-0.000030,-0.000000,-0.000009,-0.028168,-0.001435,-0.000087,-150.701462,-0.000208,0.000000
0.330000,0.019363,-150.701462,-0.000004,-0.000000,-0.000000,0.086133,0.004388,-0.000000,-150.701462,-0.000208,0.000000
0.550000,0.083412,-150.701462,-0.000009,0.000103,0.002610,0.371036,0.018901,0.026104,-150.701462,0.003417,0.000000
0.770000,0.085274,-150.745941,0.000039,0.000239,0.006062,0.379317,0.019323,0.060619,-150.745941,0.007077,0.000000
0.990000,0.072617,-150.834900,0.000203,0.000384,0.009756,0.323015,0.016455,0.097563,-150.834900,0.010754,0.000000
1.210000,0.081924,-150.745941,0.000354,0.000530,0.013459,0.364418,0.018564,0.134595,-150.745941,0.014413,0.000000
1.430000,0.025696,-150.701462,0.000500,0.000672,0.017076,0.114301,0.005823,0.170756,-150.701462,0.018073,0.000000
1.650000,0.033890,-150.701462,0.000621,0.000818,0.020779,0.150749,0.007680,0.207787,-150.701462,0.021750,0.000000
1.870000,0.071869,-150.790421,0.000785,0.000961,0.024413,0.319689,0.016286,0.244126,-150.790421,0.025410,0.000000
2.090000,0.076714,-150.790421,0.000936,0.001104,0.028046,0.341239,0.017384,0.280461,-150.790421,0.029070,0.000000
2.310000,0.099426,-150.745941,0.001087,0.001247,0.031663,0.442270,0.022530,0.316625,-150.745941,0.032747,0.000000
2.530000,0.100914,-150.745941,0.001212,0.001380,0.035062,0.448888,0.022867,0.350618,-150.745941,0.036406,0.000000
2.750000,0.075966,-150.790421,0.001380,0.001535,0.038999,0.337913,0.017214,0.389992,-150.790421,0.040066,0.000000
2.970000,0.077827,-150.834900,0.001544,0.001679,0.042659,0.346194,0.017636,0.426588,-150.834900,0.043725,0.000000
3.190000,0.062187,-150.834900,0.001694,0.001823,0.046293,0.276622,0.014092,0.462927,-150.834900,0.047402,0.000000
3.410000,0.055481,-150.790421,0.001841,0.001961,0.049805,0.246792,0.012572,0.498047,-150.790421,0.051062,0.000000
3.630000,0.515366,-150.790421,0.001988,0.002107,0.053525,2.292461,0.116784,0.535252,-150.790421,0.054722,0.000000
3.850000,0.726875,-150.834900,0.002005,-0.000000,-0.000000,3.233303,0.164712,-0.000000,-150.834900,0.000208,0.000000
4.070000,0.711235,-150.790421,0.001988,-0.000000,-0.000009,3.163732,0.161168,-0.000087,-150.790421,0.000208,0.000000
4.290000,0.690010,-150.879379,0.001996,-0.000000,-0.000009,3.069318,0.156359,-0.000087,-150.879379,0.000399,0.000000
4.510000,0.675110,-150.745941,0.001962,-0.000000,-0.000000,3.003039,0.152982,-0.000000,-150.745941,0.000763,0.000000
4.730000,0.680695,-150.745941,0.001983,-0.000000,-0.000000,3.027881,0.154248,-0.000000,-150.745941,0.001127,0.000000
4.950000,0.878426,-150.790421,0.002013,0.000024,0.000607,3.907432,0.199054,0.006071,-150.790421,0.001492,0.000000
5.170000,0.999451,-150.923874,0.002022,0.000037,0.000945,4.445779,0.226479,0.009451,-150.923874,0.001864,0.000000
5.390000,1.237396,-150.879379,0.002035,0.000059,0.001500,5.504213,0.280398,0.015003,-150.879379,0.002229,0.000000
5.610000,1.307030,-150.879379,0.002026,0.000070,0.001769,5.813959,0.296177,0.017691,-150.879379,0.002593,0.000000
5.830000,1.437729,-150.879379,0.002044,0.000084,0.002142,6.395338,0.325794,0.021419,-150.879379,0.002966,0.000000
6.050000,1.585564,-150.879379,0.002070,0.000100,0.002532,7.052939,0.359294,0.025321,-150.879379,0.003330,0.000000
6.270000,1.734886,-150.923874,0.002074,0.000112,0.002853,7.717159,0.393131,0.028531,-150.923874,0.003694,0.000000
6.490000,1.908409,-151.012833,0.002095,0.000127,0.003226,8.489028,0.432452,0.032259,-151.012833,0.004059,0.000000
6.710001,2.039856,-150.923874,0.002121,0.000139,0.003529,9.073732,0.462238,0.035294,-150.923874,0.004431,0.000000
6.930000,2.151199,-150.879379,0.002100,0.000151,0.003833,9.569013,0.487469,0.038330,-150.879379,0.004796,0.000000
7.150001,2.302383,-150.923874,0.002121,0.000165,0.004189,10.241513,0.521728,0.041887,-150.923874,0.005160,0.000000
7.370000,2.497879,-150.879379,0.002151,0.000184,0.004674,11.111121,0.566027,0.046743,-150.879379,0.005533,0.000000
7.590000,2.583519,-150.968353,0.002151,0.000194,0.004926,11.492066,0.585434,0.049257,-150.968353,0.005897,0.000000
7.810000,2.590225,-150.923874,0.002173,0.000205,0.005203,11.521897,0.586953,0.052031,-150.923874,0.006261,0.000000
8.030001,2.903389,-150.923874,0.002186,0.000225,0.005715,12.914919,0.657917,0.057148,-150.923874,0.006625,0.000000
8.250000,3.078033,-150.923874,0.002190,0.000242,0.006140,13.691776,0.697492,0.061399,-150.923874,0.006998,0.000000
8.470000,3.209854,-150.968353,0.002216,0.000257,0.006521,14.278144,0.727363,0.065214,-150.968353,0.007363,0.000000
8.690001,3.208359,-150.968353,0.002233,0.000264,0.006712,14.271493,0.727024,0.067121,-150.968353,0.007727,0.000000
8.910001,3.392311,-150.923874,0.002255,0.000278,0.007059,15.089753,0.768709,0.070592,-150.923874,0.008100,0.000000
9.130000,3.560257,-150.968353,0.002268,0.000295,0.007501,15.836814,0.806766,0.075013,-150.968353,0.008464,0.000000
9.350000,3.771393,-150.923874,0.002285,0.000314,0.007979,16.775993,0.854610,0.079786,-150.923874,0.008828,0.000000
9.570001,3.841393,-151.057312,0.002298,0.000326,0.008290,17.087368,0.870472,0.082904,-151.057312,0.009192,0.000000
9.790001,3.929276,-151.012833,0.002294,0.000341,0.008655,17.478291,0.890387,0.086549,-151.012833,0.009566,0.000000
10.010000,3.998535,-150.968353,0.002324,0.000355,0.009010,17.786373,0.906081,0.090103,-150.968353,0.009930,0.000000
10.230000,4.210793,-150.968353,0.002328,0.000372,0.009444,18.730541,0.954179,0.094441,-150.968353,0.010294,0.000000
10.450001,4.295319,-150.968353,0.002363,0.000385,0.009791,19.106531,0.973333,0.097908,-150.968353,0.010667,0.000000
10.670000,4.408150,-151.012833,0.002350,0.000399,0.010147,19.608429,0.998901,0.101465,-151.012833,0.011031,0.000000
10.890000,4.398834,-151.057312,0.002363,0.000409,0.010398,19.566992,0.996790,0.103979,-151.057312,0.011395,0.000000
11.110001,4.647583,-151.012833,0.002406,0.000431,0.010944,20.673481,1.053157,0.109444,-151.012833,0.011760,0.000000
11.330001,4.747749,-151.012833,0.002427,0.000447,0.011361,21.119043,1.075855,0.113607,-151.012833,0.012132,0.000000
11.550000,4.733231,-151.101791,0.002445,0.000461,0.011699,21.054461,1.072565,0.116987,-151.101791,0.012497,0.000000
11.770000,4.799141,-151.012833,0.002458,0.000474,0.012028,21.347645,1.087501,0.120284,-151.012833,0.012861,0.000000
11.990001,4.831909,-150.968353,0.002432,0.000484,0.012297,21.493406,1.094926,0.122971,-150.968353,0.013234,0.000000
12.210001,5.015488,-151.012833,0.002492,0.000503,0.012783,22.310003,1.136526,0.127827,-151.012833,0.013598,0.000000
12.430000,5.126083,-151.057312,0.002483,0.000519,0.013190,22.801958,1.161587,0.131904,-151.057312,0.013962,0.000000
12.650001,5.110069,-151.101791,0.002496,0.000528,0.013399,22.730724,1.157958,0.133985,-151.101791,0.014327,0.000000
12.870001,5.101135,-151.057312,0.002514,0.000538,0.013676,22.690983,1.155934,0.136760,-151.057312,0.014699,0.000000
13.090000,5.302216,-151.101791,0.002522,0.000559,0.014196,23.585432,1.201499,0.141964,-151.101791,0.015064,0.000000
13.310000,5.417648,-151.057312,0.002531,0.000576,0.014621,24.098904,1.227657,0.146214,-151.057312,0.015428,0.000000
13.530001,5.415039,-151.057312,0.002561,0.000589,0.014959,24.087297,1.227065,0.149594,-151.057312,0.015801,0.000000
13.750001,5.465683,-151.057312,0.002574,0.000601,0.015272,24.312572,1.238541,0.152717,-151.057312,0.016165,0.000000
13.970000,5.458237,-151.057312,0.002587,0.000611,0.015532,24.279449,1.236854,0.155321,-151.057312,0.016529,0.000000
14.190001,5.641075,-151.146271,0.002591,0.000633,0.016078,25.092756,1.278286,0.160782,-151.146271,0.016894,0.000000
14.410001,5.715919,-151.101791,0.002639,0.000648,0.016451,25.425680,1.295246,0.164510,-151.101791,0.017266,0.000000
14.630001,5.655594,-151.101791,0.002621,0.000656,0.016659,25.157337,1.281576,0.166592,-151.101791,0.017631,0.000000
14.850000,5.616493,-151.057312,0.002630,0.000664,0.016867,24.983410,1.272716,0.168674,-151.057312,0.017995,0.000000
15.070001,5.974342,-151.190750,0.002639,0.000688,0.017466,26.575203,1.353805,0.174658,-151.190750,0.018359,0.000000
15.290001,5.976204,-151.146271,0.002695,0.000701,0.017804,26.583483,1.354227,0.178041,-151.146271,0.018732,0.000000
15.510001,6.061111,-151.146271,0.002695,0.000718,0.018246,26.961170,1.373467,0.182462,-151.146271,0.019096,0.000000
15.730000,6.052917,-151.101791,0.002716,0.000731,0.018567,26.924721,1.371611,0.185672,-151.101791,0.019460,0.000000
15.950001,6.097603,-151.101791,0.002708,0.000746,0.018957,27.123491,1.381737,0.189574,-151.101791,0.019833,0.000000
16.170000,6.201492,-151.190750,0.002742,0.000764,0.019400,27.585615,1.405278,0.193999,-151.190750,0.020198,0.000000
16.390001,6.191437,-151.190750,0.002759,0.000774,0.019651,27.540886,1.403000,0.196512,-151.190750,0.020562,0.000000
16.610001,6.176544,-151.190750,0.002764,0.000785,0.019937,27.474640,1.399625,0.199373,-151.190750,0.020926,0.000000
16.830000,6.358261,-151.146271,0.002759,0.000803,0.020388,28.282957,1.440803,0.203885,-151.146271,0.021299,0.000000
17.050001,6.418587,-151.146271,0.002772,0.000819,0.020796,28.551300,1.454473,0.207961,-151.146271,0.021663,0.000000
17.270000,6.455826,-151.146271,0.002781,0.000831,0.021108,28.716948,1.462911,0.211084,-151.146271,0.022027,0.000000
17.490002,6.506462,-151.146271,0.002828,0.000847,0.021507,28.942188,1.474385,0.215073,-151.146271,0.022401,0.000000
17.710001,6.509445,-151.190750,0.002837,0.000858,0.021793,28.955458,1.475061,0.217934,-151.190750,0.022765,0.000000
17.930000,6.608864,-151.146271,0.002841,0.000874,0.022201,29.397694,1.497590,0.222011,-151.146271,0.023129,0.000000
18.150002,6.726913,-151.146271,0.002871,0.000888,0.022556,29.922806,1.524340,0.225565,-151.146271,0.023493,0.000000
18.370001,6.627487,-151.235229,0.002884,0.000899,0.022834,29.480536,1.501810,0.228339,-151.235229,0.023866,0.000000
18.590000,6.805855,-151.235229,0.002876,0.000914,0.023224,30.273954,1.542229,0.232241,-151.235229,0.024230,0.000000
18.810001,7.033371,-151.190750,0.002919,0.000935,0.023745,31.285997,1.593785,0.237445,-151.190750,0.024595,0.000000
19.030001,7.068001,-151.235229,0.002940,0.000950,0.024135,31.440039,1.601632,0.241348,-151.235229,0.024967,0.000000
19.250000,6.993530,-151.235229,0.002940,0.000961,0.024403,31.108776,1.584757,0.244035,-151.235229,0.025332,0.000000
19.470001,7.054970,-151.190750,0.002932,0.000976,0.024794,31.382072,1.598679,0.247941,-151.190750,0.025696,0.000000
19.690001,7.089226,-151.190750,0.002975,0.000990,0.025149,31.534451,1.606442,0.251495,-151.190750,0.026060,0.000000
19.910002,7.203171,-151.235229,0.002984,0.001007,0.025575,32.041306,1.632262,0.255745,-151.235229,0.026433,0.000000
20.130001,7.138756,-151.190750,0.002992,0.001015,0.025783,31.754772,1.617665,0.257827,-151.190750,0.026797,0.000000
20.350000,7.197220,-151.279709,0.003014,0.001028,0.026112,32.014832,1.630913,0.261120,-151.279709,0.027162,0.000000
20.570002,7.327171,-151.279709,0.003018,0.001044,0.026528,32.592884,1.660361,0.265283,-151.279709,0.027534,0.000000
20.790001,7.386009,-151.324188,0.003065,0.001059,0.026892,32.854610,1.673694,0.268924,-151.324188,0.027898,0.000000
21.010000,7.570709,-151.279709,0.003070,0.001077,0.027361,33.676197,1.715547,0.273610,-151.279709,0.028263,0.000000
21.230001,7.584854,-151.279709,0.003087,0.001092,0.027743,33.739117,1.718753,0.277425,-151.279709,0.028627,0.000000
21.450001,7.584854,-151.324188,0.003057,0.001105,0.028063,33.739117,1.718753,0.280635,-151.324188,0.029000,0.000000
21.670000,7.614647,-151.279709,0.003091,0.001117,0.028375,33.871639,1.725504,0.283754,-151.279709,0.029364,0.000000
21.890001,7.839561,-151.324188,0.003126,0.001137,0.028878,34.872112,1.776470,0.288784,-151.324188,0.029728,0.000000
22.110001,7.842911,-151.324188,0.003130,0.001150,0.029199,34.887009,1.777229,0.291993,-151.324188,0.030101,0.000000
22.330002,7.870094,-151.324188,0.003134,0.001163,0.029529,35.007927,1.783389,0.295290,-151.324188,0.030465,0.000000
22.550001,7.821312,-151.324188,0.003173,0.001174,0.029815,34.790932,1.772335,0.298151,-151.324188,0.030830,0.000000
22.770000,7.991859,-151.324188,0.003147,0.001190,0.030231,35.549564,1.810981,0.302315,-151.324188,0.031194,0.000000
22.990002,8.142296,-151.368683,0.003182,0.001208,0.030674,36.218742,1.845071,0.306735,-151.368683,0.031567,0.000000
23.210001,8.067078,-151.324188,0.003191,0.001219,0.030960,35.884155,1.828026,0.309601,-151.324188,0.031931,0.000000
23.430000,8.082344,-151.324188,0.003199,0.001231,0.031255,35.952061,1.831485,0.312549,-151.324188,0.032295,0.000000
23.650002,8.170227,-151.368683,0.003203,0.001244,0.031602,36.342983,1.851400,0.316016,-151.368683,0.032668,0.000000
23.870001,8.386200,-151.324188,0.003212,0.001262,0.032061,37.303680,1.900340,0.320611,-151.324188,0.033033,0.000000
24.090002,8.352318,-151.457642,0.003260,0.001275,0.032382,37.152966,1.892662,0.323820,-151.457642,0.033397,0.000000
24.310001,8.589516,-151.368683,0.003255,0.001292,0.032825,38.208073,1.946412,0.328245,-151.368683,0.033761,0.000000
24.530001,8.512810,-151.324188,0.003268,0.001305,0.033145,37.866871,1.929030,0.331455,-151.324188,0.034134,0.000000
24.750002,8.686707,-151.457642,0.003294,0.001321,0.033561,38.640400,1.968436,0.335614,-151.457642,0.034498,0.000000
24.970001,8.820389,-151.324188,0.003307,0.001338,0.033995,39.235050,1.998729,0.339952,-151.324188,0.034862,0.000000
25.190001,8.697876,-151.368683,0.003328,0.001350,0.034299,38.690086,1.970967,0.342987,-151.368683,0.035235,0.000000
25.410002,8.661385,-151.368683,0.003328,0.001361,0.034567,38.527763,1.962698,0.345674,-151.368683,0.035600,0.000000
25.630001,8.735863,-151.413162,0.003324,0.001376,0.034940,38.859058,1.979575,0.349403,-151.413162,0.035964,0.000000
25.850000,8.962265,-151.368683,0.003376,0.001391,0.035339,39.866146,2.030878,0.353392,-151.368683,0.036328,0.000000
26.070002,9.045670,-151.413162,0.003380,0.001407,0.035730,40.237148,2.049778,0.357298,-151.413162,0.036701,0.000000
26.290001,9.211754,-151.413162,0.003406,0.001423,0.036137,40.975929,2.087413,0.361370,-151.413162,0.037065,0.000000
26.510002,9.080307,-151.457642,0.003406,0.001432,0.036371,40.391224,2.057627,0.363713,-151.457642,0.037429,0.000000
26.730001,9.537949,-151.457642,0.003432,0.001458,0.037039,42.426914,2.161330,0.370390,-151.457642,0.037794,0.000000
26.950001,9.415810,-151.457642,0.003432,0.001470,0.037334,41.883614,2.133653,0.373338,-151.457642,0.038167,0.000000
27.170002,9.418793,-151.457642,0.003471,0.001483,0.037663,41.896881,2.134329,0.376635,-151.457642,0.038531,0.000000
27.390001,9.490662,-151.546600,0.003462,0.001499,0.038071,42.216572,2.150615,0.380711,-151.546600,0.038895,0.000000
27.610001,9.577797,-151.502121,0.003505,0.001514,0.038444,42.604168,2.170360,0.384439,-151.502121,0.039268,0.000000
27.830002,9.638863,-151.502121,0.003501,0.001526,0.038756,42.875801,2.184197,0.387562,-151.502121,0.039632,0.000000
28.050001,9.660835,-151.413162,0.003497,0.001538,0.039068,42.973541,2.189177,0.390684,-151.413162,0.039996,0.000000
28.270000,9.723389,-151.502121,0.003510,0.001552,0.039415,43.251793,2.203351,0.394151,-151.502121,0.040361,0.000000
28.490002,9.874947,-151.546600,0.003540,0.001567,0.039797,43.925957,2.237695,0.397970,-151.546600,0.040733,0.000000
28.710001,10.043259,-151.457642,0.003579,0.001583,0.040196,44.674644,2.275835,0.401960,-151.457642,0.041098,0.000000
28.930002,9.977722,-151.502121,0.003583,0.001593,0.040473,44.383125,2.260984,0.404734,-151.502121,0.041462,0.000000
29.150002,10.168007,-151.502121,0.003570,0.001610,0.040898,45.229553,2.304103,0.408984,-151.502121,0.041835,0.000000
29.370001,10.267799,-151.502121,0.003604,0.001623,0.041236,45.673454,2.326716,0.412364,-151.502121,0.042199,0.000000
29.590002,10.475952,-151.591080,0.003587,0.001641,0.041688,46.599361,2.373885,0.416876,-151.591080,0.042563,0.000000
29.810001,10.540375,-151.502121,0.003622,0.001656,0.042060,46.885929,2.388483,0.420604,-151.502121,0.042928,0.000000
30.030001,10.337433,-151.546600,0.003652,0.001664,0.042260,45.983196,2.342496,0.422599,-151.546600,0.043300,0.000000
30.250002,10.484146,-151.457642,0.003652,0.001678,0.042615,46.635811,2.375741,0.426153,-151.457642,0.043665,0.000000
30.470001,10.728424,-151.546600,0.003669,0.001695,0.043058,47.722412,2.431096,0.430577,-151.546600,0.044029,0.000000
30.690001,10.908279,-151.635559,0.003678,0.001713,0.043517,48.522449,2.471852,0.435172,-151.635559,0.044402,0.000000
30.910002,10.927643,-151.502121,0.003712,0.001727,0.043864,48.608582,2.476239,0.438643,-151.502121,0.044766,0.000000
31.130001,10.952591,-151.546600,0.003695,0.001740,0.044202,48.719559,2.481893,0.442023,-151.546600,0.045130,0.000000
31.350002,11.121651,-151.502121,0.003751,0.001757,0.044619,49.471573,2.520202,0.446186,-151.502121,0.045494,0.000000
31.570002,11.271713,-151.591080,0.003729,0.001773,0.045026,50.139084,2.554207,0.450262,-151.591080,0.045868,0.000000
31.790001,11.343208,-151.546600,0.003760,0.001787,0.045382,50.457111,2.570408,0.453820,-151.546600,0.046232,0.000000
32.010002,11.434441,-151.591080,0.003751,0.001801,0.045737,50.862930,2.591081,0.457374,-151.591080,0.046596,0.000000
32.230003,11.453804,-151.591080,0.003781,0.001814,0.046067,50.949066,2.595469,0.460671,-151.591080,0.046969,0.000000
32.450001,11.700691,-151.591080,0.003811,0.001830,0.046492,52.047276,2.651415,0.464918,-151.591080,0.047333,0.000000
32.670002,11.851875,-151.591080,0.003794,0.001847,0.046908,52.719776,2.685673,0.469081,-151.591080,0.047697,0.000000
32.890003,11.855965,-151.680038,0.003837,0.001860,0.047246,52.737965,2.686600,0.472465,-151.680038,0.048062,0.000000
33.110001,11.879799,-151.635559,0.003850,0.001872,0.047559,52.843987,2.692001,0.475587,-151.635559,0.048435,0.000000
33.330002,11.838837,-151.546600,0.003872,0.001885,0.047871,52.661777,2.682719,0.478706,-151.546600,0.048799,0.000000
33.550003,12.213074,-151.591080,0.003863,0.001904,0.048357,54.326466,2.767522,0.483566,-151.591080,0.049163,0.000000
33.770000,12.356064,-151.680038,0.003880,0.001919,0.048738,54.962517,2.799924,0.487381,-151.680038,0.049536,0.000000
33.990002,12.222755,-151.635559,0.003915,0.001927,0.048955,54.369530,2.769716,0.489550,-151.635559,0.049900,0.000000
34.210003,12.473732,-151.635559,0.003915,0.001943,0.049362,55.485931,2.826588,0.493622,-151.635559,0.050264,0.000000
34.430000,12.665878,-151.635559,0.003945,0.001960,0.049787,56.340641,2.870129,0.497873,-151.635559,0.050629,0.000000
34.650002,12.852066,-151.591080,0.003932,0.001975,0.050160,57.168846,2.912320,0.501601,-151.591080,0.051001,0.000000
34.870003,12.868446,-151.680038,0.003962,0.001989,0.050516,57.241707,2.916032,0.505159,-151.680038,0.051366,0.000000
35.090000,12.858765,-151.680038,0.003958,0.002000,0.050811,57.198643,2.913838,0.508107,-151.680038,0.051730,0.000000
35.310001,12.820038,-151.769012,0.003975,0.002013,0.051123,57.026375,2.905062,0.511230,-151.769012,0.052103,0.000000
35.530003,13.313431,-151.680038,0.004010,0.002033,0.051635,59.221096,3.016867,0.516347,-151.680038,0.052467,0.000000
35.750000,13.408760,-151.724518,0.004027,0.002047,0.051990,59.645145,3.038468,0.519901,-151.724518,0.052831,0.000000
35.970001,13.239334,-151.680038,0.004014,0.002055,0.052198,58.891499,3.000076,0.521982,-151.680038,0.053196,0.000000
36.190002,13.123154,-151.680038,0.004031,0.002063,0.052398,58.374702,2.973749,0.523977,-151.680038,0.053568,0.000000
36.410000,13.833267,-151.724518,0.004057,0.002089,0.053048,61.533447,3.134663,0.530480,-151.724518,0.053933,0.000000
36.630001,13.860825,-151.724518,0.004066,0.002100,0.053334,61.656029,3.140908,0.533345,-151.724518,0.054297,0.000000
36.850002,14.146431,-151.680038,0.004074,0.002119,0.053811,62.926468,3.205627,0.538114,-151.680038,0.054670,0.000000
37.070004,14.132278,-151.724518,0.004096,0.002130,0.054106,62.863514,3.202420,0.541062,-151.724518,0.055034,0.000000
37.290001,14.298729,-151.769012,0.004105,0.002146,0.054514,63.603924,3.240138,0.545138,-151.769012,0.055398,0.000000
37.510002,14.697166,-151.769012,0.004122,0.002166,0.055017,65.376259,3.330426,0.550169,-151.769012,0.055762,0.000000
37.730003,14.510612,-151.769012,0.004135,0.002174,0.055225,64.546425,3.288152,0.552250,-151.769012,0.056135,0.000000
37.950001,14.469276,-151.769012,0.004161,0.002186,0.055520,64.362556,3.278785,0.555199,-151.769012,0.056500,0.000000
38.170002,14.816704,-151.724518,0.004165,0.002203,0.055945,65.907990,3.357513,0.559445,-151.724518,0.056864,0.000000
38.390003,15.064331,-151.769012,0.004174,0.002219,0.056370,67.009491,3.413626,0.563696,-151.769012,0.057237,0.000000
38.610001,15.073265,-151.813492,0.004204,0.002229,0.056621,67.049232,3.415651,0.566213,-151.813492,0.057601,0.000000
38.830002,15.332062,-151.724518,0.004208,0.002246,0.057046,68.200417,3.474295,0.570459,-151.724518,0.057965,0.000000
39.050003,15.342491,-151.813492,0.004217,0.002258,0.057358,68.246811,3.476658,0.573582,-151.813492,0.058329,0.000000
39.270000,15.635551,-151.813492,0.004225,0.002273,0.057740,69.550407,3.543067,0.577397,-151.813492,0.058703,0.000000
39.490002,15.871262,-151.857971,0.004247,0.002287,0.058087,70.598900,3.596479,0.580868,-151.857971,0.059067,0.000000
39.710003,15.858231,-151.813492,0.004268,0.002301,0.058433,70.540932,3.593526,0.584335,-151.813492,0.059431,0.000000
39.930000,16.135269,-151.769012,0.004290,0.002314,0.058763,71.773262,3.656304,0.587631,-151.769012,0.059795,0.000000
40.150002,16.563873,-151.813492,0.004281,0.002334,0.059275,73.679787,3.753428,0.592749,-151.813492,0.060168,0.000000
40.370003,16.872200,-151.769012,0.004307,0.002349,0.059674,75.051292,3.823295,0.596738,-151.769012,0.060532,0.000000
40.590000,16.808525,-151.813492,0.004307,0.002361,0.059969,74.768051,3.808866,0.599686,-151.813492,0.060897,0.000000
40.810001,16.948906,-151.857971,0.004329,0.002376,0.060350,75.392502,3.840677,0.603501,-151.857971,0.061269,0.000000
41.030003,17.000290,-151.813492,0.004355,0.002388,0.060654,75.621063,3.852321,0.606537,-151.813492,0.061634,0.000000
41.250004,17.365219,-151.813492,0.004350,0.002406,0.061104,77.244354,3.935015,0.611045,-151.813492,0.061998,0.000000
41.470001,17.346603,-151.813492,0.004363,0.002415,0.061347,77.161545,3.930797,0.613475,-151.813492,0.062362,0.000000
41.690002,17.451607,-151.902451,0.004355,0.002428,0.061660,77.628624,3.954591,0.616597,-151.902451,0.062735,0.000000
41.910004,17.917076,-151.857971,0.004372,0.002446,0.062128,79.699135,4.060068,0.621279,-151.857971,0.063099,0.000000
42.130001,18.036980,-151.902451,0.004406,0.002459,0.062449,80.232491,4.087238,0.624489,-151.902451,0.063464,0.000000
42.350002,18.629051,-151.813492,0.004406,0.002479,0.062961,82.866158,4.221403,0.629606,-151.813492,0.063836,0.000000
42.570004,18.678207,-151.902451,0.004432,0.002492,0.063290,83.084816,4.232543,0.632899,-151.902451,0.064201,0.000000
42.790001,18.811516,-151.857971,0.004471,0.002505,0.063628,83.677803,4.262750,0.636283,-151.857971,0.064565,0.000000
43.010002,18.828644,-151.902451,0.004445,0.002517,0.063932,83.753990,4.266632,0.639318,-151.902451,0.064929,0.000000
43.230003,19.480293,-151.902451,0.004467,0.002537,0.064435,86.652672,4.414298,0.644348,-151.902451,0.065302,0.000000
43.450001,19.489227,-151.857971,0.004480,0.002548,0.064730,86.692413,4.416322,0.647297,-151.857971,0.065666,0.000000
43.670002,19.685844,-151.946930,0.004488,0.002562,0.065068,87.567009,4.460876,0.650680,-151.946930,0.066031,0.000000
43.890003,19.717499,-151.946930,0.004497,0.002573,0.065363,87.707817,4.468049,0.653629,-151.946930,0.066403,0.000000
44.110001,20.099548,-151.991409,0.004527,0.002589,0.065753,89.407257,4.554623,0.657531,-151.991409,0.066767,0.000000
44.330002,20.665932,-151.902451,0.004544,0.002606,0.066195,91.926659,4.682967,0.661952,-151.902451,0.067132,0.000000
44.550003,20.650291,-151.902451,0.004531,0.002618,0.066507,91.857086,4.679423,0.665074,-151.902451,0.067496,0.000000
44.770000,20.797005,-151.946930,0.004570,0.002631,0.066820,92.509697,4.712669,0.668197,-151.946930,0.067869,0.000000
44.990002,21.018936,-151.946930,0.004557,0.002643,0.067141,93.496895,4.762959,0.671406,-151.946930,0.068233,0.000000
45.210003,21.655319,-152.035889,0.004579,0.002661,0.067600,96.327667,4.907166,0.676001,-152.035889,0.068597,0.000000
45.430000,21.665749,-151.946930,0.004618,0.002675,0.067956,96.374062,4.909529,0.679559,-151.946930,0.068970,0.000000
45.650002,22.309204,-151.902451,0.004605,0.002691,0.068363,99.236298,5.055338,0.683632,-151.902451,0.069335,0.000000
45.870003,22.429855,-151.946930,0.004639,0.002704,0.068675,99.772980,5.082678,0.686754,-151.946930,0.069699,0.000000
46.090004,22.809677,-151.991409,0.004648,0.002720,0.069100,101.462509,5.168747,0.691005,-151.991409,0.070063,0.000000
46.310001,23.367493,-151.991409,0.004661,0.002737,0.069517,103.943802,5.295150,0.695168,-151.991409,0.070436,0.000000
46.530003,23.260246,-152.035889,0.004700,0.002750,0.069838,103.466743,5.270847,0.698377,-152.035889,0.070800,0.000000
46.750004,23.379410,-151.991409,0.004682,0.002759,0.070089,103.996811,5.297850,0.700891,-151.991409,0.071164,0.000000
46.970001,23.605812,-151.946930,0.004695,0.002773,0.070445,105.003899,5.349154,0.704448,-151.946930,0.071538,0.000000
47.190002,23.953606,-152.080368,0.004691,0.002786,0.070765,106.550957,5.427965,0.707654,-152.080368,0.071902,0.000000
47.410004,24.562057,-152.080368,0.004717,0.002804,0.071234,109.257492,5.565842,0.712340,-152.080368,0.072266,0.000000
47.630001,25.280739,-151.991409,0.004717,0.002821,0.071659,112.454346,5.728697,0.716587,-151.991409,0.072630,0.000000
47.850002,25.100510,-151.991409,0.004734,0.002832,0.071928,111.652641,5.687857,0.719278,-151.991409,0.073003,0.000000
48.070004,26.439560,-152.035889,0.004730,0.002857,0.072561,117.609039,5.991290,0.725606,-152.035889,0.073367,0.000000
48.290001,26.421318,-152.035889,0.004756,0.002868,0.072855,117.527893,5.987156,0.728554,-152.035889,0.073731,0.000000
48.510002,26.594841,-152.035889,0.004786,0.002882,0.073194,118.299759,6.026477,0.731938,-152.035889,0.074104,0.000000
48.730003,27.017487,-151.991409,0.004816,0.002898,0.073619,120.179779,6.122250,0.736189,-151.991409,0.074469,0.000000
48.950001,27.124725,-152.035889,0.004825,0.002911,0.073931,120.656807,6.146551,0.739307,-152.035889,0.074833,0.000000
49.170002,27.577164,-152.080368,0.004838,0.002923,0.074252,122.669350,6.249075,0.742517,-152.080368,0.075197,0.000000
49.390003,27.846390,-152.080368,0.004829,0.002936,0.074581,123.866928,6.310082,0.745814,-152.080368,0.075570,0.000000
49.610001,28.120453,-152.124847,0.004838,0.002951,0.074963,125.086021,6.372186,0.749629,-152.124847,0.075934,0.000000
49.830002,28.713272,-152.035889,0.004855,0.002967,0.075353,127.723015,6.506520,0.753531,-152.035889,0.076299,0.000000
50.050003,29.224167,-152.035889,0.004868,0.002981,0.075726,129.995590,6.622291,0.757259,-152.035889,0.076671,0.000000
50.270004,29.248741,-152.080368,0.004885,0.002993,0.076012,130.104904,6.627859,0.760124,-152.080368,0.077035,0.000000
50.490002,29.986038,-152.035889,0.004881,0.003009,0.076420,133.384567,6.794933,0.764197,-152.035889,0.077400,0.000000
50.710003,30.361763,-152.169327,0.004915,0.003023,0.076793,135.055862,6.880074,0.767929,-152.169327,0.077764,0.000000
50.930004,31.124008,-152.080368,0.004919,0.003041,0.077244,138.446503,7.052801,0.772436,-152.080368,0.078137,0.000000
51.150002,31.613304,-152.080368,0.004919,0.003055,0.077591,140.623001,7.163677,0.775907,-152.080368,0.078501,0.000000
51.370003,31.416321,-152.124847,0.004937,0.003063,0.077799,139.746780,7.119040,0.777989,-152.124847,0.078865,0.000000
51.590004,31.936523,-152.169327,0.004958,0.003078,0.078180,142.060745,7.236919,0.781804,-152.169327,0.079238,0.000000
51.810001,32.657066,-152.124847,0.004954,0.003094,0.078579,145.265884,7.400197,0.785793,-152.124847,0.079602,0.000000
52.030003,33.505333,-152.080368,0.004950,0.003112,0.079056,149.039169,7.592417,0.790562,-152.080368,0.079967,0.000000
52.250004,33.850151,-152.169327,0.004975,0.003127,0.079420,150.572998,7.670554,0.794203,-152.169327,0.080331,0.000000
52.470001,34.191986,-152.124847,0.005001,0.003140,0.079759,152.093552,7.748014,0.797587,-152.124847,0.080704,0.000000
52.690002,34.747192,-152.213821,0.004997,0.003155,0.080140,154.563232,7.873827,0.801402,-152.213821,0.081068,0.000000
52.910004,35.412247,-152.213821,0.005014,0.003172,0.080565,157.521545,8.024529,0.805653,-152.213821,0.081432,0.000000
53.130001,35.786858,-152.169327,0.005040,0.003183,0.080860,159.187897,8.109418,0.808601,-152.169327,0.081796,0.000000
53.350002,36.348770,-152.169327,0.005053,0.003199,0.081259,161.687408,8.236749,0.812590,-152.169327,0.082170,0.000000
53.570004,36.817215,-152.169327,0.005036,0.003213,0.081606,163.771149,8.342900,0.816057,-152.169327,0.082534,0.000000
53.790001,37.526955,-152.169327,0.005057,0.003229,0.082022,166.928238,8.503730,0.820221,-152.169327,0.082898,0.000000
54.010002,38.342079,-152.213821,0.005075,0.003246,0.082447,170.554092,8.688439,0.824471,-152.213821,0.083271,0.000000
54.230003,38.740517,-152.213821,0.005096,0.003259,0.082777,172.326431,8.778727,0.827768,-152.213821,0.083635,0.000000
54.450001,39.080116,-152.213821,0.005079,0.003271,0.083089,173.837036,8.855680,0.830887,-152.213821,0.083999,0.000000
54.670002,39.420097,-152.213821,0.005109,0.003285,0.083436,175.349350,8.932722,0.834357,-152.213821,0.084364,0.000000
54.890003,40.451195,-152.169327,0.005096,0.003302,0.083878,179.935898,9.166371,0.838778,-152.169327,0.084737,0.000000
55.110004,41.046989,-152.258301,0.005126,0.003317,0.084260,182.586121,9.301381,0.842597,-152.258301,0.085101,0.000000
55.330002,41.161682,-152.169327,0.005135,0.003325,0.084450,183.096313,9.327371,0.844505,-152.169327,0.085465,0.000000
55.550003,41.946266,-152.169327,0.005148,0.003342,0.084893,186.586304,9.505159,0.848925,-152.169327,0.085838,0.000000
55.770004,42.762886,-152.213821,0.005170,0.003360,0.085335,190.218811,9.690208,0.853350,-152.213821,0.086202,0.000000
55.990002,43.549706,-152.302780,0.005174,0.003373,0.085682,193.718765,9.868504,0.856817,-152.302780,0.086566,0.000000
56.210003,44.099701,-152.302780,0.005161,0.003388,0.086063,196.165268,9.993135,0.860632,-152.302780,0.086931,0.000000
56.430004,44.567398,-152.258301,0.005208,0.003401,0.086384,198.245682,10.099116,0.863842,-152.258301,0.087304,0.000000
56.650002,44.819870,-152.169327,0.005187,0.003413,0.086679,199.368744,10.156328,0.866790,-152.169327,0.087668,0.000000
56.870003,46.139557,-152.258301,0.005204,0.003431,0.087156,205.238998,10.455374,0.871563,-152.258301,0.088032,0.000000
57.090004,46.886909,-152.258301,0.005191,0.003446,0.087520,208.563385,10.624725,0.875204,-152.258301,0.088405,0.000000
57.310001,46.977768,-152.258301,0.005226,0.003454,0.087720,208.967545,10.645314,0.877199,-152.258301,0.088769,0.000000
57.530003,47.054848,-152.258301,0.005221,0.003461,0.087919,209.310410,10.662781,0.879193,-152.258301,0.089134,0.000000
57.750004,48.847076,-152.258301,0.005230,0.003488,0.088604,217.282654,11.068906,0.886044,-152.258301,0.089498,0.000000
57.970001,49.275307,-152.302780,0.005234,0.003498,0.088856,219.187515,11.165944,0.888557,-152.302780,0.089870,0.000000
58.190002,50.306030,-152.302780,0.005243,0.003517,0.089342,223.772400,11.399509,0.893417,-152.302780,0.090235,0.000000
58.410004,50.872780,-152.391739,0.005273,0.003531,0.089688,226.293427,11.527937,0.896884,-152.391739,0.090599,0.000000
58.630001,51.625343,-152.302780,0.005299,0.003547,0.090087,229.640991,11.698469,0.900873,-152.302780,0.090972,0.000000
58.850002,52.790497,-152.391739,0.005282,0.003564,0.090530,234.823853,11.962498,0.905298,-152.391739,0.091336,0.000000
59.070004,53.072388,-152.258301,0.005303,0.003573,0.090755,236.077774,12.026376,0.907550,-152.258301,0.091700,0.000000
59.290001,53.338257,-152.302780,0.005295,0.003582,0.090989,237.260422,12.086621,0.909893,-152.302780,0.092065,0.000000
59.510002,54.530968,-152.347260,0.005303,0.003601,0.091466,242.565857,12.356894,0.914662,-152.347260,0.092437,0.000000
59.730003,55.481262,-152.302780,0.005307,0.003618,0.091900,246.792984,12.572234,0.918999,-152.302780,0.092802,0.000000
59.950005,55.977264,-152.347260,0.005316,0.003628,0.092143,248.999313,12.684629,0.921425,-152.347260,0.093166,0.000000
60.170002,56.859039,-152.302780,0.005342,0.003644,0.092559,252.921646,12.884442,0.925588,-152.302780,0.093539,0.000000
60.390003,57.339401,-152.302780,0.005333,0.003656,0.092862,255.058395,12.993295,0.928624,-152.302780,0.093903,0.000000
60.610004,58.397682,-152.391739,0.005333,0.003672,0.093279,259.765869,13.233104,0.932787,-152.391739,0.094267,0.000000
60.830002,59.253769,-152.347260,0.005376,0.003685,0.093608,263.573914,13.427095,0.936084,-152.347260,0.094631,0.000000
61.050003,59.661514,-152.302780,0.005372,0.003696,0.093868,265.387665,13.519492,0.938684,-152.302780,0.095005,0.000000
61.270004,60.720917,-152.347260,0.005351,0.003711,0.094267,270.100128,13.759556,0.942674,-152.347260,0.095369,0.000000
61.490002,62.210403,-152.391739,0.005398,0.003733,0.094814,276.725708,14.097078,0.948139,-152.391739,0.095733,0.000000
61.710003,63.253792,-152.480698,0.005381,0.003748,0.095187,281.366913,14.333514,0.951867,-152.480698,0.096106,0.000000
61.930004,63.654091,-152.391739,0.005420,0.003758,0.095455,283.147552,14.424223,0.954554,-152.391739,0.096470,0.000000
62.150002,64.595818,-152.391739,0.005415,0.003774,0.095854,287.336548,14.637621,0.958544,-152.391739,0.096834,0.000000
62.370003,65.318977,-152.436218,0.005411,0.003786,0.096158,290.553314,14.801492,0.961579,-152.436218,0.097199,0.000000
62.590004,66.296074,-152.480698,0.005402,0.003801,0.096548,294.899658,15.022905,0.965481,-152.480698,0.097572,0.000000
62.810001,66.922035,-152.480698,0.005415,0.003813,0.096843,297.684082,15.164750,0.968430,-152.480698,0.097936,0.000000
63.030003,67.393089,-152.391739,0.005420,0.003812,0.096834,299.779419,15.271492,0.968343,-152.391739,0.097095,0.000000
63.250004,66.745155,-152.436218,0.005424,0.003812,0.096834,296.897278,15.124669,0.968343,-152.436218,0.097095,0.000000
63.470001,66.173195,-152.525177,0.005433,0.003811,0.096800,294.353058,14.995060,0.967998,-152.525177,0.096834,0.000000
63.690002,65.664528,-152.480698,0.005454,0.003810,0.096774,292.090393,14.879795,0.967737,-152.480698,0.096834,0.000000
63.910004,65.225883,-152.480698,0.005445,0.003810,0.096765,290.139221,14.780396,0.967650,-152.480698,0.096834,0.000000
64.130005,64.829674,-152.436218,0.005450,0.003810,0.096765,288.376801,14.690615,0.967650,-152.436218,0.096834,0.000000
64.350006,64.463264,-152.480698,0.005445,0.003810,0.096765,286.746918,14.607584,0.967650,-152.480698,0.096834,0.000000
64.570000,64.138176,-152.436218,0.005450,0.003809,0.096756,285.300842,14.533918,0.967563,-152.436218,0.096834,0.000000
64.790001,63.817192,-152.525177,0.005476,0.003809,0.096756,283.873047,14.461182,0.967563,-152.525177,0.096834,0.000000
65.010002,63.540154,-152.436218,0.005458,0.003809,0.096756,282.640717,14.398405,0.967563,-152.436218,0.096834,0.000000
65.230003,63.268684,-152.480698,0.005484,0.003809,0.096756,281.433167,14.336888,0.967563,-152.480698,0.096834,0.000000
65.450005,63.012497,-152.480698,0.005497,0.003809,0.096748,280.293579,14.278836,0.967476,-152.480698,0.096834,0.000000
65.670006,62.789070,-152.525177,0.005476,0.003809,0.096748,279.299744,14.228207,0.967476,-152.525177,0.096834,0.000000
65.889999,62.572350,-152.614136,0.005476,0.003809,0.096748,278.335724,14.179097,0.967476,-152.614136,0.096834,0.000000
66.110001,62.389893,-152.480698,0.005484,0.003809,0.096748,277.524109,14.137752,0.967476,-152.480698,0.096834,0.000000
66.330002,62.202583,-152.525177,0.005471,0.003809,0.096748,276.690918,14.095306,0.967476,-152.525177,0.096834,0.000000
66.550003,62.011185,-152.480698,0.005480,0.003809,0.096748,275.839539,14.051935,0.967476,-152.480698,0.096834,0.000000
66.770004,61.842133,-152.614136,0.005484,0.003809,0.096748,275.087555,14.013627,0.967476,-152.614136,0.096834,0.000000
66.990005,61.673447,-152.614136,0.005476,0.003809,0.096748,274.337189,13.975403,0.967476,-152.614136,0.096834,0.000000
67.210007,61.531197,-152.525177,0.005480,0.003809,0.096748,273.704437,13.943169,0.967476,-152.525177,0.096834,0.000000
67.430000,61.381508,-152.525177,0.005493,0.003809,0.096748,273.038574,13.909248,0.967476,-152.525177,0.096834,0.000000
67.650002,61.255272,-152.569656,0.005497,0.003809,0.096748,272.477051,13.880643,0.967476,-152.569656,0.096834,0.000000
67.870003,61.120102,-152.525177,0.005502,0.003809,0.096748,271.875793,13.850014,0.967476,-152.525177,0.096834,0.000000
68.090004,60.992004,-152.614136,0.005476,0.003809,0.096748,271.306000,13.820986,0.967476,-152.614136,0.096834,0.000000
68.310005,60.856461,-152.569656,0.005510,0.003809,0.096748,270.703064,13.790271,0.967476,-152.569656,0.096834,0.000000
68.530006,60.746239,-152.569656,0.005489,0.003809,0.096748,270.212769,13.765294,0.967476,-152.569656,0.096834,0.000000
68.750000,60.646072,-152.569656,0.005493,0.003809,0.096748,269.767212,13.742597,0.967476,-152.569656,0.096834,0.000000
68.970001,60.534729,-152.569656,0.005476,0.003809,0.096748,269.271912,13.717366,0.967476,-152.569656,0.096834,0.000000
69.190002,60.433075,-152.658630,0.005493,0.003809,0.096748,268.819733,13.694330,0.967476,-152.658630,0.096834,0.000000
69.410004,60.327690,-152.614136,0.005480,0.003809,0.096748,268.350983,13.670449,0.967476,-152.614136,0.096834,0.000000
69.630005,60.226036,-152.614136,0.005484,0.003809,0.096748,267.898773,13.647415,0.967476,-152.614136,0.096834,0.000000
69.850006,60.150818,-152.614136,0.005476,0.003809,0.096748,267.564209,13.630370,0.967476,-152.614136,0.096834,0.000000
70.070000,60.042458,-152.614136,0.005497,0.003809,0.096748,267.082184,13.605816,0.967476,-152.614136,0.096834,0.000000
70.290001,59.963142,-152.658630,0.005484,0.003809,0.096748,266.729370,13.587842,0.967476,-152.658630,0.096834,0.000000
70.510002,59.883453,-152.614136,0.005493,0.003809,0.096748,266.374908,13.569784,0.967476,-152.614136,0.096834,0.000000
70.730003,59.804504,-152.658630,0.005523,0.003809,0.096748,266.023712,13.551895,0.967476,-152.658630,0.096834,0.000000
70.950005,59.718491,-152.614136,0.005506,0.003809,0.096748,265.641113,13.532403,0.967476,-152.614136,0.096834,0.000000
71.170006,59.636940,-152.658630,0.005489,0.003809,0.096748,265.278351,13.513925,0.967476,-152.658630,0.096834,0.000000
71.390007,59.578850,-152.658630,0.005480,0.003809,0.096748,265.019958,13.500760,0.967476,-152.658630,0.096834,0.000000
71.610001,59.497299,-152.703110,0.005480,0.003809,0.096748,264.657196,13.482281,0.967476,-152.703110,0.096834,0.000000
71.830002,59.425804,-152.614136,0.005493,0.003809,0.096748,264.339172,13.466080,0.967476,-152.614136,0.096834,0.000000
72.050003,59.362503,-152.658630,0.005514,0.003809,0.096748,264.057587,13.451735,0.967476,-152.658630,0.096834,0.000000
72.270004,59.284302,-152.747589,0.005502,0.003809,0.096748,263.709747,13.434015,0.967476,-152.747589,0.096834,0.000000
72.490005,59.215790,-152.792068,0.005502,0.003809,0.096748,263.404999,13.418490,0.967476,-152.792068,0.096834,0.000000
72.710007,59.154716,-152.792068,0.005506,0.003809,0.096748,263.133331,13.404650,0.967476,-152.792068,0.096834,0.000000
72.930000,59.102959,-152.658630,0.005493,0.003809,0.096748,262.903076,13.392921,0.967476,-152.658630,0.096834,0.000000
73.150002,59.040398,-152.703110,0.005493,0.003809,0.096748,262.624817,13.378746,0.967476,-152.703110,0.096834,0.000000
73.370003,58.965553,-152.747589,0.005480,0.003809,0.096748,262.291870,13.361785,0.967476,-152.747589,0.096834,0.000000
73.590004,58.911560,-152.792068,0.005514,0.003809,0.096748,262.051697,13.349550,0.967476,-152.792068,0.096834,0.000000
73.810005,58.857941,-152.792068,0.005484,0.003809,0.096748,261.813202,13.337399,0.967476,-152.792068,0.096834,0.000000
74.030006,58.808784,-152.703110,0.005480,0.003809,0.096748,261.594543,13.326261,0.967476,-152.703110,0.096834,0.000000
74.250000,58.758514,-152.703110,0.005489,0.003809,0.096748,261.370911,13.314870,0.967476,-152.703110,0.096834,0.000000
74.470001,58.700424,-152.703110,0.005489,0.003809,0.096748,261.112518,13.301706,0.967476,-152.703110,0.096834,0.000000
74.690002,58.656853,-152.792068,0.005489,0.003809,0.096748,260.918701,13.291833,0.967476,-152.792068,0.096834,0.000000
74.910004,58.589081,-152.792068,0.005476,0.003809,0.096748,260.617249,13.276476,0.967476,-152.792068,0.096834,0.000000
75.130005,58.548866,-152.703110,0.005502,0.003809,0.096748,260.438354,13.267363,0.967476,-152.703110,0.096834,0.000000
75.350006,58.507164,-152.792068,0.005489,0.003809,0.096748,260.252869,13.257913,0.967476,-152.792068,0.096834,0.000000
75.570007,58.456146,-152.792068,0.005493,0.003809,0.096748,260.025940,13.246352,0.967476,-152.792068,0.096834,0.000000
75.790001,58.416679,-152.881027,0.005523,0.003809,0.096748,259.850372,13.237409,0.967476,-152.881027,0.096834,0.000000
76.010002,58.361565,-152.881027,0.005480,0.003809,0.096748,259.605194,13.224919,0.967476,-152.881027,0.096834,0.000000
76.230003,58.324699,-152.747589,0.005493,0.003809,0.096748,259.441223,13.216566,0.967476,-152.747589,0.096834,0.000000
76.450005,58.251343,-152.747589,0.005476,0.003809,0.096748,259.114899,13.199943,0.967476,-152.747589,0.096834,0.000000
76.670006,58.219688,-152.836548,0.005523,0.003809,0.096748,258.974121,13.192770,0.967476,-152.836548,0.096834,0.000000
76.890007,58.190277,-152.881027,0.005471,0.003809,0.096748,258.843292,13.186106,0.967476,-152.881027,0.096834,0.000000
77.110001,58.141121,-152.881027,0.005519,0.003809,0.096748,258.624634,13.174966,0.967476,-152.881027,0.096834,0.000000
77.330002,58.119148,-152.792068,0.005484,0.003809,0.096748,258.526886,13.169988,0.967476,-152.792068,0.096834,0.000000
77.550003,58.067390,-152.836548,0.005502,0.003809,0.096739,258.296661,13.158259,0.967389,-152.836548,0.096834,0.000000
77.770004,58.030899,-152.881027,0.005484,0.003809,0.096739,258.134338,13.149990,0.967389,-152.881027,0.096834,0.000000
77.990005,57.975418,-152.925507,0.005506,0.003809,0.096739,257.887543,13.137418,0.967389,-152.925507,0.096834,0.000000
78.210007,57.948601,-152.836548,0.005527,0.003809,0.096739,257.768250,13.131341,0.967389,-152.836548,0.096834,0.000000
78.430000,57.916206,-152.881027,0.005497,0.003809,0.096739,257.624146,13.124000,0.967389,-152.881027,0.096834,0.000000
78.650002,57.873009,-152.836548,0.005463,0.003809,0.096739,257.432007,13.114211,0.967389,-152.836548,0.096834,0.000000
78.870003,57.837265,-152.881027,0.005493,0.003809,0.096739,257.273010,13.106112,0.967389,-152.881027,0.096834,0.000000
79.090004,57.786995,-152.881027,0.005489,0.003809,0.096739,257.049377,13.094720,0.967389,-152.881027,0.096834,0.000000
79.310005,57.754967,-152.925507,0.005502,0.003809,0.096739,256.906921,13.087462,0.967389,-152.925507,0.096834,0.000000
79.530006,57.716240,-152.925507,0.005519,0.003809,0.096739,256.734650,13.078687,0.967389,-152.925507,0.096834,0.000000
79.750000,57.686455,-152.881027,0.005489,0.003809,0.096739,256.602173,13.071937,0.967389,-152.881027,0.096834,0.000000
79.970001,57.658150,-152.925507,0.005497,0.003809,0.096739,256.476257,13.065523,0.967389,-152.925507,0.096834,0.000000
80.190002,57.614960,-153.014465,0.005502,0.003809,0.096739,256.284149,13.055737,0.967389,-153.014465,0.096834,0.000000
80.410004,57.580696,-152.969986,0.005502,0.003809,0.096739,256.131714,13.047972,0.967389,-152.969986,0.096834,0.000000
80.630005,57.534157,-152.881027,0.005519,0.003809,0.096739,255.924713,13.037426,0.967389,-152.881027,0.096834,0.000000
80.850006,57.513672,-152.925507,0.005493,0.003809,0.096739,255.833588,13.032784,0.967389,-152.925507,0.096834,0.000000
81.070007,57.479790,-152.881027,0.005493,0.003809,0.096739,255.682877,13.025107,0.967389,-152.881027,0.096834,0.000000
81.290001,57.443665,-152.925507,0.005476,0.003809,0.096739,255.522186,13.016920,0.967389,-152.925507,0.096834,0.000000
81.510002,57.421326,-152.969986,0.005497,0.003809,0.096739,255.422806,13.011858,0.967389,-152.969986,0.096834,0.000000
81.730003,57.384834,-152.925507,0.005510,0.003809,0.096739,255.260498,13.003590,0.967389,-152.925507,0.096834,0.000000
81.950005,57.345734,-153.014465,0.005497,0.003809,0.096739,255.086563,12.994729,0.967389,-153.014465,0.096834,0.000000
82.170006,57.315201,-152.969986,0.005502,0.003809,0.096739,254.950745,12.987810,0.967389,-152.969986,0.096834,0.000000
82.390007,57.285034,-153.014465,0.005523,0.003809,0.096739,254.816559,12.980974,0.967389,-153.014465,0.096834,0.000000
82.610001,57.251892,-153.014465,0.005527,0.003809,0.096739,254.669128,12.973465,0.967389,-153.014465,0.096834,0.000000
82.830002,57.218384,-153.014465,0.005510,0.003809,0.096739,254.520081,12.965871,0.967389,-153.014465,0.096834,0.000000
83.050003,57.193802,-152.969986,0.005489,0.003809,0.096739,254.410736,12.960300,0.967389,-152.969986,0.096834,0.000000
83.270004,57.155075,-152.969986,0.005527,0.003809,0.096739,254.238464,12.951525,0.967389,-152.969986,0.096834,0.000000
83.490005,57.138695,-153.058960,0.005502,0.003809,0.096739,254.165604,12.947813,0.967389,-153.058960,0.096834,0.000000
83.710007,57.102203,-152.969986,0.005532,0.003809,0.096739,254.003281,12.939544,0.967389,-152.969986,0.096834,0.000000
83.930000,57.067574,-153.014465,0.005502,0.003809,0.096739,253.849243,12.931698,0.967389,-153.014465,0.096834,0.000000
84.150002,57.029587,-153.014465,0.005480,0.003809,0.096739,253.680267,12.923089,0.967389,-153.014465,0.096834,0.000000
84.370003,57.026611,-153.058960,0.005497,0.003809,0.096739,253.667038,12.922415,0.967389,-153.058960,0.096834,0.000000
84.590004,56.996078,-153.103439,0.005519,0.003809,0.096739,253.531219,12.915496,0.967389,-153.103439,0.096834,0.000000
84.810005,56.959579,-153.014465,0.005519,0.003809,0.096739,253.368866,12.907225,0.967389,-153.014465,0.096834,0.000000
85.030006,56.950645,-153.058960,0.005510,0.003809,0.096739,253.329117,12.905200,0.967389,-153.058960,0.096834,0.000000
85.250008,56.917877,-153.058960,0.005497,0.003809,0.096739,253.183365,12.897775,0.967389,-153.058960,0.096834,0.000000
85.470001,56.882126,-153.058960,0.005506,0.003809,0.096739,253.024338,12.889673,0.967389,-153.058960,0.096834,0.000000
85.690002,56.844894,-153.058960,0.005514,0.003809,0.096739,252.858719,12.881237,0.967389,-153.058960,0.096834,0.000000
85.910004,56.822548,-153.103439,0.005532,0.003809,0.096739,252.759323,12.876173,0.967389,-153.103439,0.096834,0.000000
86.130005,56.804306,-153.058960,0.005532,0.003809,0.096739,252.678177,12.872040,0.967389,-153.058960,0.096834,0.000000
86.350006,56.794250,-153.058960,0.005502,0.003809,0.096739,252.633438,12.869761,0.967389,-153.058960,0.096834,0.000000
86.570007,56.746216,-153.103439,0.005502,0.003809,0.096739,252.419769,12.858877,0.967389,-153.103439,0.096834,0.000000
86.790001,56.730576,-153.147919,0.005502,0.003809,0.096739,252.350204,12.855332,0.967389,-153.147919,0.096834,0.000000
87.010002,56.702644,-153.147919,0.005506,0.003809,0.096739,252.225952,12.849003,0.967389,-153.147919,0.096834,0.000000
87.230003,56.675461,-153.103439,0.005514,0.003809,0.096739,252.105042,12.842843,0.967389,-153.103439,0.096834,0.000000
87.450005,56.640457,-153.058960,0.005519,0.003809,0.096739,251.949341,12.834910,0.967389,-153.058960,0.096834,0.000000
87.670006,56.621094,-153.147919,0.005497,0.003809,0.096739,251.863205,12.830523,0.967389,-153.147919,0.096834,0.000000
87.890007,56.606575,-153.103439,0.005489,0.003809,0.096739,251.798615,12.827233,0.967389,-153.103439,0.096834,0.000000
88.110001,56.592422,-153.103439,0.005527,0.003809,0.096739,251.735672,12.824026,0.967389,-153.103439,0.096834,0.000000
88.330002,56.568588,-153.147919,0.005523,0.003809,0.096739,251.629654,12.818624,0.967389,-153.147919,0.096834,0.000000
88.550003,56.537315,-153.103439,0.005493,0.003809,0.096739,251.490540,12.811539,0.967389,-153.103439,0.096834,0.000000
88.770004,56.514221,-153.103439,0.005523,0.003809,0.096739,251.387817,12.806306,0.967389,-153.103439,0.096834,0.000000
88.990005,56.490768,-153.147919,0.005519,0.003809,0.096739,251.283493,12.800991,0.967389,-153.147919,0.096834,0.000000
89.210007,56.476990,-153.192398,0.005493,0.003809,0.096739,251.222198,12.797869,0.967389,-153.192398,0.096834,0.000000
89.430008,56.448318,-153.147919,0.005540,0.003809,0.096739,251.094666,12.791371,0.967389,-153.147919,0.096834,0.000000
89.650002,56.436401,-153.147919,0.005519,0.003809,0.096739,251.041656,12.788671,0.967389,-153.147919,0.096834,0.000000
89.870003,56.427460,-153.103439,0.005514,0.003809,0.096739,251.001877,12.786645,0.967389,-153.103439,0.096834,0.000000
90.090004,56.416290,-153.103439,0.005497,0.003809,0.096739,250.952194,12.784114,0.967389,-153.103439,0.096834,0.000000
90.310005,56.392830,-153.192398,0.005506,0.003809,0.096739,250.847839,12.778798,0.967389,-153.192398,0.096834,0.000000
90.530006,56.357086,-153.192398,0.005527,0.003809,0.096739,250.688843,12.770699,0.967389,-153.192398,0.096834,0.000000
90.750008,56.344421,-153.147919,0.005514,0.003809,0.096739,250.632507,12.767829,0.967389,-153.147919,0.096834,0.000000
90.970001,56.310913,-153.192398,0.005523,0.003809,0.096739,250.483444,12.760235,0.967389,-153.192398,0.096834,0.000000
91.190002,56.298248,-153.236877,0.005519,0.003809,0.096739,250.427109,12.757365,0.967389,-153.236877,0.096834,0.000000
91.410004,56.276649,-153.192398,0.005502,0.003809,0.096739,250.331039,12.752472,0.967389,-153.192398,0.096834,0.000000
91.630005,56.270691,-153.147919,0.005523,0.003809,0.096739,250.304535,12.751121,0.967389,-153.147919,0.096834,0.000000
91.850006,56.253189,-153.192398,0.005523,0.003809,0.096739,250.226685,12.747155,0.967389,-153.192398,0.096834,0.000000
92.070007,56.242767,-153.236877,0.005523,0.003809,0.096739,250.180328,12.744793,0.967389,-153.236877,0.096834,0.000000
92.290001,56.202919,-153.281357,0.005506,0.003809,0.096739,250.003067,12.735764,0.967389,-153.281357,0.096834,0.000000
92.510002,56.199570,-153.236877,0.005497,0.003809,0.096739,249.988174,12.735004,0.967389,-153.236877,0.096834,0.000000
92.730003,56.168663,-153.192398,0.005514,0.003809,0.096739,249.850693,12.728001,0.967389,-153.192398,0.096834,0.000000
92.950005,56.148926,-153.236877,0.005536,0.003809,0.096739,249.762894,12.723529,0.967389,-153.236877,0.096834,0.000000
93.170006,56.142601,-153.281357,0.005527,0.003809,0.096739,249.734756,12.722095,0.967389,-153.281357,0.096834,0.000000
93.390007,56.130310,-153.281357,0.005523,0.003809,0.096739,249.680084,12.719310,0.967389,-153.281357,0.096834,0.000000
93.500008,56.123978,-153.236877,0.005514,0.003809,0.096739,249.651917,12.717875,0.967389,-153.236877,0.096834,0.000000