File: Data/Compression Sample NH 10, 12, 15, 17 batch 3/AutoNoheating-10-3-4-240212_02122024_161307.csv
Time (sec),S:Load (lbs),S:HL1 (DIM),S:LVDT (in),S:Position (in),Ch:Position (mm),Ch:Load (N),Ch:Stress (MPa),Ch:Strain (mm/mm),Ch:HL1 (DIM),Set Point (),Cycles ()
0.110000,0.011169,-137.757507,0.000030,-0.000000,-0.000000,0.049684,0.002531,-0.000000,-137.757507,0.000243,0.000000
0.330000,0.006706,-137.801987,0.000000,-0.000000,-0.000000,0.029831,0.001520,-0.000000,-137.801987,0.000243,0.000000
0.550000,0.059212,-137.801987,-0.000004,0.000114,0.002897,0.263387,0.013418,0.028966,-137.801987,0.003833,0.000000
0.770000,0.048035,-137.757507,0.000142,0.000254,0.006461,0.213669,0.010885,0.064608,-137.757507,0.007493,0.000000
0.990000,0.005959,-137.890945,0.000293,0.000396,0.010069,0.026505,0.001350,0.100686,-137.890945,0.011153,0.000000
1.210000,0.018990,-137.801987,0.000410,0.000538,0.013676,0.084470,0.004303,0.136763,-137.801987,0.014830,0.000000
1.430000,0.051392,-137.801987,0.000591,0.000684,0.017371,0.228601,0.011646,0.173708,-137.801987,0.018490,0.000000
1.650000,0.058464,-137.846466,0.000707,0.000826,0.020987,0.260061,0.013248,0.209869,-137.846466,0.022149,0.000000
1.870000,0.099426,-137.801987,0.000862,0.000973,0.024707,0.442270,0.022530,0.247074,-137.801987,0.025826,0.000000
2.090000,0.090118,-137.846466,0.001022,0.001119,0.028411,0.400867,0.020421,0.284106,-137.846466,0.029486,0.000000
2.310000,0.074478,-137.846466,0.001168,0.001265,0.032122,0.331295,0.016877,0.321220,-137.846466,0.033145,0.000000
2.530000,0.069633,-137.801987,0.001358,0.001399,0.035539,0.309745,0.015779,0.355390,-137.801987,0.036822,0.000000
2.750000,0.047295,-137.846466,0.001487,0.001550,0.039364,0.210377,0.010717,0.393637,-137.846466,0.040482,0.000000
2.970000,0.055855,-137.801987,0.001625,0.001691,0.042962,0.248455,0.012657,0.429623,-137.801987,0.044142,0.000000
3.190000,0.079689,-137.846466,0.001768,0.001840,0.046735,0.354474,0.018058,0.467351,-137.846466,0.047819,0.000000
3.410000,0.105759,-137.890945,0.001919,0.001980,0.050282,0.470438,0.023965,0.502820,-137.890945,0.051479,0.000000
3.630000,0.487434,-137.890945,0.002074,0.002121,0.053864,2.168216,0.110454,0.538636,-137.890945,0.055138,0.000000
3.850000,0.681442,-137.890945,0.002100,-0.000001,-0.000035,3.031207,0.154417,-0.000348,-137.890945,0.000156,0.000000
4.070000,0.665062,-137.890945,0.002104,-0.000001,-0.000035,2.958343,0.150705,-0.000348,-137.890945,0.000156,0.000000
4.290000,0.660591,-137.890945,0.002104,-0.000001,-0.000035,2.938456,0.149692,-0.000348,-137.890945,0.000338,0.000000
4.510000,0.650536,-137.935425,0.002091,-0.000001,-0.000035,2.893727,0.147413,-0.000348,-137.935425,0.000711,0.000000
4.730000,0.637131,-137.890945,0.002091,-0.000001,-0.000035,2.834099,0.144376,-0.000348,-137.890945,0.001075,0.000000
4.950000,0.787193,-137.890945,0.002108,0.000023,0.000572,3.501611,0.178381,0.005723,-137.890945,0.001439,0.000000
5.170000,0.927582,-137.846466,0.002134,0.000035,0.000885,4.126090,0.210193,0.008845,-137.846466,0.001804,0.000000
5.390000,1.052330,-137.979904,0.002143,0.000050,0.001257,4.680998,0.238461,0.012573,-137.979904,0.002177,0.000000
5.610000,1.222504,-137.979904,0.002156,0.000068,0.001734,5.437968,0.277023,0.017342,-137.979904,0.002541,0.000000
5.830000,1.258995,-137.890945,0.002156,0.000073,0.001864,5.600290,0.285292,0.018644,-137.890945,0.002905,0.000000
6.050000,1.432892,-137.935425,0.002177,0.000088,0.002246,6.373821,0.324698,0.022460,-137.935425,0.003278,0.000000
6.270000,1.617584,-137.979904,0.002186,0.000106,0.002697,7.195374,0.366550,0.026971,-137.979904,0.003642,0.000000
6.490000,1.755737,-138.024384,0.002203,0.000124,0.003139,7.809910,0.397856,0.031392,-138.024384,0.004006,0.000000
6.710001,1.928146,-138.024384,0.002212,0.000139,0.003521,8.576823,0.436924,0.035207,-138.024384,0.004371,0.000000
6.930000,2.026451,-137.935425,0.002246,0.000153,0.003876,9.014105,0.459200,0.038765,-137.935425,0.004744,0.000000
7.150001,2.145615,-137.935425,0.002246,0.000167,0.004249,9.544170,0.486203,0.042493,-137.935425,0.005108,0.000000
7.370000,2.338127,-137.890945,0.002251,0.000183,0.004648,10.400509,0.529827,0.046482,-137.890945,0.005472,0.000000
7.590000,2.453194,-137.979904,0.002259,0.000195,0.004943,10.912351,0.555902,0.049431,-137.979904,0.005845,0.000000
7.810000,2.606979,-138.068878,0.002302,0.000208,0.005273,11.596423,0.590750,0.052727,-138.068878,0.006209,0.000000
8.030001,2.790558,-137.979904,0.002324,0.000226,0.005741,12.413021,0.632349,0.057409,-137.979904,0.006574,0.000000
8.250000,2.950310,-138.024384,0.002328,0.000243,0.006166,13.123633,0.668550,0.061660,-138.024384,0.006938,0.000000
8.470000,3.102234,-138.024384,0.002333,0.000259,0.006574,13.799425,0.702976,0.065736,-138.024384,0.007311,0.000000
8.690001,3.123459,-138.068878,0.002328,0.000271,0.006877,13.893839,0.707786,0.068772,-138.068878,0.007675,0.000000
8.910001,3.253792,-138.068878,0.002376,0.000284,0.007224,14.473589,0.737320,0.072239,-138.068878,0.008039,0.000000
9.130000,3.317093,-137.935425,0.002363,0.000294,0.007458,14.755166,0.751664,0.074581,-137.935425,0.008412,0.000000
9.350000,3.552063,-138.024384,0.002384,0.000314,0.007970,15.800365,0.804909,0.079699,-138.024384,0.008776,0.000000
9.570001,3.652977,-138.024384,0.002423,0.000328,0.008325,16.249252,0.827776,0.083253,-138.024384,0.009141,0.000000
9.790001,3.690216,-138.068878,0.002423,0.000337,0.008568,16.414902,0.836215,0.085682,-138.068878,0.009505,0.000000
10.010000,3.896133,-138.113358,0.002419,0.000357,0.009063,17.330868,0.882876,0.090626,-138.113358,0.009877,0.000000
10.230000,3.995560,-137.979904,0.002458,0.000372,0.009453,17.773138,0.905407,0.094528,-137.979904,0.010242,0.000000
10.450001,4.084930,-138.068878,0.002440,0.000387,0.009826,18.170677,0.925658,0.098256,-138.068878,0.010606,0.000000
10.670000,4.145996,-138.068878,0.002458,0.000401,0.010190,18.442312,0.939496,0.101897,-138.068878,0.010970,0.000000
10.890000,4.217865,-138.113358,0.002471,0.000413,0.010485,18.762001,0.955782,0.104845,-138.113358,0.011343,0.000000
11.110001,4.250259,-138.113358,0.002492,0.000423,0.010754,18.906097,0.963123,0.107536,-138.113358,0.011707,0.000000
11.330001,4.386551,-138.024384,0.002514,0.000441,0.011204,19.512352,0.994007,0.112044,-138.024384,0.012072,0.000000
11.550000,4.501610,-138.068878,0.002535,0.000456,0.011577,20.024160,1.020079,0.115772,-138.068878,0.012445,0.000000
11.770000,4.524696,-138.068878,0.002509,0.000468,0.011898,20.126854,1.025311,0.118982,-138.068878,0.012809,0.000000
11.990001,4.625237,-138.113358,0.002557,0.000483,0.012271,20.574080,1.048094,0.122710,-138.113358,0.013173,0.000000
12.210001,4.775681,-138.113358,0.002583,0.000500,0.012696,21.243288,1.082185,0.126961,-138.113358,0.013537,0.000000
12.430000,4.836372,-138.068878,0.002583,0.000516,0.013095,21.513258,1.095938,0.130950,-138.068878,0.013910,0.000000
12.650001,4.917183,-138.113358,0.002608,0.000531,0.013485,21.872723,1.114250,0.134852,-138.113358,0.014274,0.000000
12.870001,4.929840,-138.113358,0.002617,0.000543,0.013780,21.929024,1.117118,0.137800,-138.113358,0.014639,0.000000
13.090000,4.976387,-138.113358,0.002626,0.000557,0.014145,22.136076,1.127665,0.141445,-138.113358,0.015012,0.000000
13.310000,5.101135,-138.202316,0.002656,0.000572,0.014526,22.690983,1.155934,0.145260,-138.202316,0.015376,0.000000
13.530001,5.113419,-138.113358,0.002656,0.000584,0.014838,22.745623,1.158717,0.148383,-138.113358,0.015740,0.000000
13.750001,5.095543,-138.157837,0.002669,0.000593,0.015072,22.666107,1.154667,0.150722,-138.157837,0.016104,0.000000
13.970000,5.355461,-138.113358,0.002690,0.000614,0.015601,23.822281,1.213565,0.156013,-138.113358,0.016477,0.000000
14.190001,5.373337,-138.246796,0.002699,0.000628,0.015939,23.901796,1.217615,0.159393,-138.246796,0.016841,0.000000
14.410001,5.401268,-138.202316,0.002708,0.000641,0.016278,24.026039,1.223945,0.162777,-138.202316,0.017206,0.000000
14.630001,5.429565,-138.202316,0.002729,0.000653,0.016599,24.151913,1.230357,0.165987,-138.202316,0.017579,0.000000
14.850000,5.488770,-138.157837,0.002746,0.000667,0.016954,24.415266,1.243773,0.169541,-138.157837,0.017943,0.000000
15.070001,5.632133,-138.068878,0.002746,0.000685,0.017388,25.052980,1.276260,0.173878,-138.068878,0.018307,0.000000
15.290001,5.715546,-138.246796,0.002781,0.000700,0.017769,25.424017,1.295161,0.177693,-138.246796,0.018671,0.000000
15.510001,5.612030,-138.246796,0.002790,0.000709,0.018021,24.963556,1.271704,0.180210,-138.246796,0.019044,0.000000
15.730000,5.757256,-138.202316,0.002820,0.000723,0.018376,25.609552,1.304613,0.183764,-138.202316,0.019409,0.000000
15.950001,5.832100,-138.202316,0.002807,0.000739,0.018758,25.942476,1.321573,0.187579,-138.202316,0.019773,0.000000
16.170000,6.043610,-138.202316,0.002846,0.000759,0.019287,26.883318,1.369501,0.192871,-138.202316,0.020145,0.000000
16.390001,6.056641,-138.246796,0.002854,0.000774,0.019660,26.941282,1.372454,0.196599,-138.246796,0.020510,0.000000
16.610001,6.068558,-138.202316,0.002854,0.000787,0.019998,26.994293,1.375155,0.199982,-138.202316,0.020874,0.000000
16.830000,6.082336,-138.291275,0.002889,0.000800,0.020319,27.055584,1.378277,0.203188,-138.291275,0.021238,0.000000
17.050001,6.017914,-138.202316,0.002889,0.000808,0.020536,26.769018,1.363679,0.205357,-138.202316,0.021611,0.000000
17.270000,6.217506,-138.202316,0.002902,0.000827,0.020996,27.656849,1.408907,0.209956,-138.202316,0.021975,0.000000
17.490002,6.381348,-138.202316,0.002910,0.000844,0.021446,28.385653,1.446034,0.214464,-138.202316,0.022340,0.000000
17.710001,6.397362,-138.335754,0.002949,0.000858,0.021785,28.456886,1.449663,0.217847,-138.335754,0.022712,0.000000
17.930000,6.439438,-138.291275,0.002945,0.000872,0.022140,28.644051,1.459198,0.221401,-138.291275,0.023077,0.000000
18.150002,6.574982,-138.202316,0.002971,0.000890,0.022600,29.246979,1.489912,0.226000,-138.202316,0.023441,0.000000
18.370001,6.601418,-138.246796,0.002958,0.000905,0.022999,29.364573,1.495903,0.229989,-138.246796,0.023805,0.000000
18.590000,6.563812,-138.291275,0.002962,0.000916,0.023259,29.197294,1.487381,0.232589,-138.291275,0.024178,0.000000
18.810001,6.623390,-138.291275,0.002997,0.000929,0.023597,29.462311,1.500882,0.235969,-138.291275,0.024542,0.000000
19.030001,6.748878,-138.291275,0.003009,0.000943,0.023961,30.020512,1.529318,0.239614,-138.291275,0.024907,0.000000
19.250000,6.868042,-138.291275,0.003018,0.000961,0.024421,30.550577,1.556321,0.244209,-138.291275,0.025280,0.000000
19.470001,6.849419,-138.380234,0.003061,0.000973,0.024707,30.467735,1.552100,0.247070,-138.380234,0.025644,0.000000
19.690001,6.857986,-138.291275,0.003022,0.000987,0.025063,30.505848,1.554042,0.250628,-138.291275,0.026008,0.000000
19.910002,7.022949,-138.291275,0.003078,0.001004,0.025496,31.239639,1.591423,0.254962,-138.291275,0.026372,0.000000
20.130001,7.052734,-138.335754,0.003083,0.001017,0.025835,31.372129,1.598172,0.258346,-138.335754,0.026745,0.000000
20.350000,7.118271,-138.335754,0.003083,0.001034,0.026268,31.663651,1.613023,0.262683,-138.335754,0.027109,0.000000
20.570002,7.105614,-138.291275,0.003109,0.001044,0.026520,31.607347,1.610155,0.265196,-138.291275,0.027474,0.000000
20.790001,7.061676,-138.335754,0.003126,0.001055,0.026788,31.411903,1.600199,0.267884,-138.335754,0.027847,0.000000
21.010000,7.253075,-138.380234,0.003134,0.001072,0.027222,32.263287,1.643570,0.272221,-138.380234,0.028211,0.000000
21.230001,7.515594,-138.380234,0.003147,0.001093,0.027751,33.431034,1.703058,0.277512,-138.380234,0.028575,0.000000
21.450001,7.462715,-138.335754,0.003169,0.001103,0.028029,33.195816,1.691075,0.280287,-138.335754,0.028939,0.000000
21.670000,7.493622,-138.380234,0.003186,0.001117,0.028375,33.333294,1.698079,0.283754,-138.380234,0.029312,0.000000
21.890001,7.671249,-138.335754,0.003195,0.001136,0.028844,34.123421,1.738330,0.288439,-138.335754,0.029676,0.000000
22.110001,7.704018,-138.380234,0.003199,0.001152,0.029252,34.269180,1.745755,0.292516,-138.380234,0.030041,0.000000
22.330002,7.637733,-138.380234,0.003247,0.001165,0.029590,33.974335,1.730735,0.295896,-138.380234,0.030414,0.000000
22.550001,7.564377,-138.380234,0.003238,0.001174,0.029824,33.648029,1.714112,0.298238,-138.380234,0.030778,0.000000
22.770000,7.669388,-138.424713,0.003238,0.001189,0.030188,34.115139,1.737908,0.301879,-138.424713,0.031142,0.000000
22.990002,7.834717,-138.424713,0.003247,0.001206,0.030639,34.850559,1.775372,0.306391,-138.424713,0.031506,0.000000
23.210001,7.835091,-138.469208,0.003285,0.001217,0.030917,34.852222,1.775457,0.309165,-138.469208,0.031879,0.000000
23.430000,7.957603,-138.424713,0.003281,0.001231,0.031272,35.397186,1.803219,0.312719,-138.424713,0.032244,0.000000
23.650002,7.958344,-138.469208,0.003268,0.001247,0.031662,35.400478,1.803386,0.316622,-138.469208,0.032608,0.000000
23.870001,8.261833,-138.424713,0.003298,0.001268,0.032217,36.750469,1.872158,0.322174,-138.424713,0.032972,0.000000
24.090002,8.173950,-138.469208,0.003328,0.001280,0.032504,36.359547,1.852244,0.325035,-138.469208,0.033345,0.000000
24.310001,8.163521,-138.469208,0.003346,0.001294,0.032876,36.313152,1.849880,0.328764,-138.469208,0.033709,0.000000
24.530001,8.251404,-138.469208,0.003341,0.001309,0.033241,36.704079,1.869795,0.332408,-138.469208,0.034073,0.000000
24.750002,8.190331,-138.424713,0.003367,0.001320,0.033536,36.432411,1.855955,0.335357,-138.424713,0.034446,0.000000
24.970001,8.362740,-138.469208,0.003367,0.001336,0.033943,37.199322,1.895024,0.339429,-138.469208,0.034810,0.000000
25.190001,8.324387,-138.469208,0.003389,0.001347,0.034221,37.028721,1.886333,0.342207,-138.469208,0.035175,0.000000
25.410002,8.369072,-138.513687,0.003380,0.001361,0.034567,37.227489,1.896459,0.345674,-138.513687,0.035539,0.000000
25.630001,8.557495,-138.513687,0.003419,0.001378,0.035010,38.065639,1.939156,0.350099,-138.513687,0.035912,0.000000
25.850000,8.651329,-138.469208,0.003402,0.001394,0.035400,38.483032,1.960419,0.354001,-138.469208,0.036276,0.000000
26.070002,8.710541,-138.513687,0.003428,0.001407,0.035730,38.746422,1.973837,0.357298,-138.513687,0.036640,0.000000
26.290001,8.767136,-138.513687,0.003449,0.001422,0.036111,38.998165,1.986661,0.361113,-138.513687,0.037013,0.000000
26.510002,8.739952,-138.558167,0.003471,0.001434,0.036424,38.877247,1.980501,0.364236,-138.558167,0.037377,0.000000
26.730001,8.908638,-138.558167,0.003484,0.001452,0.036892,39.627602,2.018726,0.368917,-138.558167,0.037741,0.000000
26.950001,8.987587,-138.558167,0.003501,0.001468,0.037291,39.978783,2.036616,0.372907,-138.558167,0.038106,0.000000
27.170002,8.731392,-138.513687,0.003505,0.001474,0.037429,38.839172,1.978562,0.374292,-138.513687,0.038479,0.000000
27.390001,8.866936,-138.558167,0.003510,0.001488,0.037794,39.442101,2.009276,0.377937,-138.558167,0.038843,0.000000
27.610001,9.127220,-138.558167,0.003510,0.001508,0.038314,40.599903,2.068258,0.383141,-138.558167,0.039207,0.000000
27.830002,9.255318,-138.602646,0.003540,0.001523,0.038696,41.169708,2.097285,0.386956,-138.602646,0.039580,0.000000
28.050001,9.269096,-138.558167,0.003557,0.001537,0.039051,41.230999,2.100407,0.390510,-138.558167,0.039944,0.000000
28.270000,9.301125,-138.513687,0.003557,0.001552,0.039415,41.373470,2.107665,0.394151,-138.513687,0.040308,0.000000
28.490002,9.402779,-138.558167,0.003566,0.001568,0.039823,41.825649,2.130700,0.398228,-138.558167,0.040673,0.000000
28.710001,9.498482,-138.558167,0.003583,0.001584,0.040222,42.251358,2.152387,0.402217,-138.558167,0.041046,0.000000
28.930002,9.467575,-138.602646,0.003600,0.001594,0.040500,42.113876,2.145383,0.404995,-138.602646,0.041410,0.000000
29.150002,9.468689,-138.602646,0.003630,0.001606,0.040803,42.118832,2.145636,0.408031,-138.602646,0.041774,0.000000
29.370001,9.716316,-138.602646,0.003635,0.001626,0.041306,43.220333,2.201749,0.413057,-138.602646,0.042147,0.000000
29.590002,9.829521,-138.602646,0.003656,0.001642,0.041713,43.723892,2.227401,0.417133,-138.602646,0.042511,0.000000
29.810001,9.906601,-138.602646,0.003660,0.001658,0.042112,44.066761,2.244868,0.421123,-138.602646,0.042876,0.000000
30.030001,9.851112,-138.647125,0.003682,0.001671,0.042442,43.819935,2.232294,0.424419,-138.647125,0.043240,0.000000
30.250002,9.875320,-138.558167,0.003673,0.001684,0.042772,43.927620,2.237780,0.427716,-138.558167,0.043613,0.000000
30.470001,9.776642,-138.602646,0.003699,0.001695,0.043058,43.488674,2.215419,0.430577,-138.602646,0.043977,0.000000
30.690001,10.119598,-138.602646,0.003729,0.001714,0.043535,45.014221,2.293134,0.435346,-138.602646,0.044341,0.000000
30.910002,10.206360,-138.558167,0.003729,0.001729,0.043907,45.400158,2.312794,0.439074,-138.558167,0.044714,0.000000
31.130001,10.147522,-138.647125,0.003729,0.001739,0.044159,45.138432,2.299461,0.441591,-138.647125,0.045078,0.000000
31.350002,10.288651,-138.691605,0.003751,0.001755,0.044575,45.766205,2.331441,0.445755,-138.691605,0.045443,0.000000
31.570002,10.582085,-138.647125,0.003794,0.001772,0.045018,47.071465,2.397935,0.450175,-138.647125,0.045807,0.000000
31.790001,10.649483,-138.602646,0.003781,0.001787,0.045390,47.371265,2.413207,0.453904,-138.602646,0.046180,0.000000
32.010002,10.621178,-138.647125,0.003781,0.001801,0.045755,47.245358,2.406793,0.457548,-138.647125,0.046544,0.000000
32.230003,10.603683,-138.780563,0.003794,0.001813,0.046058,47.167542,2.402829,0.460584,-138.780563,0.046908,0.000000
32.450001,10.633842,-138.691605,0.003837,0.001828,0.046422,47.301693,2.409663,0.464225,-138.691605,0.047281,0.000000
32.670002,10.843857,-138.647125,0.003803,0.001844,0.046839,48.235886,2.457253,0.468388,-138.647125,0.047645,0.000000
32.890003,10.837158,-138.691605,0.003842,0.001855,0.047116,48.206089,2.455735,0.471163,-138.691605,0.048009,0.000000
33.110001,10.872536,-138.691605,0.003846,0.001867,0.047420,48.363453,2.463752,0.474198,-138.691605,0.048374,0.000000
33.330002,11.112717,-138.691605,0.003850,0.001884,0.047854,49.431831,2.518178,0.478536,-138.691605,0.048747,0.000000
33.550003,11.321243,-138.647125,0.003889,0.001901,0.048287,50.359406,2.565430,0.482869,-138.647125,0.049111,0.000000
33.770000,11.409866,-138.647125,0.003919,0.001914,0.048625,50.753620,2.585513,0.486253,-138.647125,0.049475,0.000000
33.990002,11.501472,-138.691605,0.003906,0.001930,0.049016,51.161106,2.606271,0.490155,-138.691605,0.049848,0.000000
34.210003,11.483597,-138.691605,0.003911,0.001943,0.049362,51.081589,2.602220,0.493622,-138.691605,0.050212,0.000000
34.430000,11.583763,-138.736084,0.003936,0.001957,0.049709,51.527153,2.624918,0.497093,-138.736084,0.050576,0.000000
34.650002,11.831764,-138.736084,0.003949,0.001975,0.050160,52.630318,2.681116,0.501601,-138.736084,0.050941,0.000000
34.870003,11.743515,-138.736084,0.003941,0.001985,0.050412,52.237762,2.661119,0.504118,-138.736084,0.051314,0.000000
35.090000,11.660843,-138.736084,0.003958,0.001995,0.050672,51.870018,2.642385,0.506718,-138.736084,0.051678,0.000000
35.310001,12.119606,-138.736084,0.003992,0.002014,0.051166,53.910702,2.746342,0.511661,-138.736084,0.052042,0.000000
35.530003,12.195946,-138.780563,0.004018,0.002029,0.051539,54.250275,2.763641,0.515393,-138.780563,0.052415,0.000000
35.750000,12.071198,-138.780563,0.004014,0.002038,0.051756,53.695370,2.735373,0.517558,-138.780563,0.052779,0.000000
35.970001,12.245468,-138.736084,0.004010,0.002052,0.052129,54.470562,2.774863,0.521290,-138.736084,0.053143,0.000000
36.190002,12.431282,-138.780563,0.004031,0.002068,0.052537,55.297104,2.816969,0.525366,-138.780563,0.053508,0.000000
36.410000,12.691948,-138.780563,0.004040,0.002085,0.052953,56.456604,2.876036,0.529526,-138.780563,0.053881,0.000000
36.630001,12.877762,-138.825043,0.004079,0.002098,0.053300,57.283146,2.918143,0.532996,-138.825043,0.054245,0.000000
36.850002,12.753014,-138.825043,0.004079,0.002109,0.053560,56.728237,2.889874,0.535597,-138.825043,0.054609,0.000000
37.070004,12.970482,-138.825043,0.004092,0.002124,0.053941,57.695583,2.939153,0.539412,-138.825043,0.054973,0.000000
37.290001,13.135811,-138.825043,0.004100,0.002141,0.054384,58.431004,2.976617,0.543836,-138.825043,0.055346,0.000000
37.510002,13.546165,-138.825043,0.004118,0.002160,0.054852,60.256355,3.069605,0.548518,-138.825043,0.055711,0.000000
37.730003,13.648941,-138.869522,0.004135,0.002173,0.055190,60.713524,3.092894,0.551902,-138.869522,0.056075,0.000000
37.950001,13.640007,-138.825043,0.004143,0.002186,0.055537,60.673782,3.090870,0.555369,-138.825043,0.056448,0.000000
38.170002,13.719696,-138.825043,0.004174,0.002199,0.055858,61.028255,3.108927,0.558579,-138.825043,0.056812,0.000000
38.390003,13.822098,-138.825043,0.004169,0.002215,0.056265,61.483761,3.132132,0.562655,-138.825043,0.057176,0.000000
38.610001,13.888748,-138.825043,0.004191,0.002225,0.056526,61.780239,3.147235,0.565255,-138.825043,0.057540,0.000000
38.830002,14.362778,-138.914017,0.004156,0.002243,0.056968,63.888824,3.254652,0.569680,-138.914017,0.057913,0.000000
39.050003,14.516197,-138.914017,0.004178,0.002259,0.057376,64.571274,3.289417,0.573756,-138.914017,0.058278,0.000000
39.270000,14.535934,-138.825043,0.004221,0.002270,0.057670,64.659065,3.293890,0.576704,-138.825043,0.058642,0.000000
39.490002,14.961182,-138.869522,0.004238,0.002290,0.058156,66.550659,3.390252,0.581560,-138.869522,0.059014,0.000000
39.710003,15.098587,-138.869522,0.004247,0.002306,0.058572,67.161873,3.421389,0.585724,-138.869522,0.059379,0.000000
39.930000,14.979431,-138.869522,0.004255,0.002316,0.058824,66.631836,3.394388,0.588237,-138.869522,0.059743,0.000000
40.150002,15.085182,-138.958496,0.004268,0.002329,0.059153,67.102242,3.418351,0.591534,-138.958496,0.060107,0.000000
40.370003,15.349564,-138.914017,0.004286,0.002344,0.059526,68.278267,3.478261,0.595262,-138.914017,0.060480,0.000000
40.590000,15.684326,-138.914017,0.004290,0.002360,0.059951,69.767365,3.554119,0.599512,-138.914017,0.060844,0.000000
40.810001,15.713745,-139.002975,0.004316,0.002372,0.060246,69.898232,3.560786,0.602461,-139.002975,0.061209,0.000000
41.030003,15.917061,-138.914017,0.004303,0.002388,0.060654,70.802620,3.606858,0.606537,-138.914017,0.061582,0.000000
41.250004,16.336723,-139.002975,0.004324,0.002404,0.061053,72.669373,3.701954,0.610526,-139.002975,0.061946,0.000000
41.470001,16.502808,-138.958496,0.004337,0.002418,0.061408,73.408157,3.739589,0.614080,-138.958496,0.062310,0.000000
41.690002,16.840172,-138.914017,0.004355,0.002435,0.061842,74.908829,3.816037,0.618418,-138.914017,0.062674,0.000000
41.910004,16.731812,-138.914017,0.004372,0.002444,0.062076,74.426811,3.791483,0.620761,-138.914017,0.063047,0.000000
42.130001,16.801071,-138.958496,0.004389,0.002455,0.062353,74.734894,3.807177,0.623535,-138.958496,0.063411,0.000000
42.350002,17.307503,-139.002975,0.004368,0.002473,0.062813,76.987617,3.921936,0.628130,-139.002975,0.063776,0.000000
42.570004,17.867546,-139.002975,0.004411,0.002492,0.063299,79.478813,4.048844,0.632986,-139.002975,0.064149,0.000000
42.790001,17.822121,-138.914017,0.004445,0.002503,0.063568,79.276749,4.038550,0.635677,-138.914017,0.064513,0.000000
43.010002,18.043312,-138.914017,0.004462,0.002517,0.063932,80.260658,4.088673,0.639318,-138.914017,0.064877,0.000000
43.230003,18.522179,-139.002975,0.004449,0.002535,0.064391,82.390762,4.197186,0.643913,-139.002975,0.065241,0.000000
43.450001,18.813751,-139.002975,0.004449,0.002550,0.064782,83.687744,4.263257,0.647815,-139.002975,0.065614,0.000000
43.670002,18.852104,-139.002975,0.004488,0.002563,0.065111,83.858345,4.271948,0.651112,-139.002975,0.065978,0.000000
43.890003,18.745979,-138.914017,0.004493,0.002572,0.065337,83.386284,4.247900,0.653368,-138.914017,0.066343,0.000000
44.110001,19.014458,-138.958496,0.004506,0.002587,0.065701,84.580536,4.308738,0.657009,-138.958496,0.066716,0.000000
44.330002,19.440453,-138.958496,0.004510,0.002602,0.066082,86.475449,4.405270,0.660824,-138.958496,0.067080,0.000000
44.550003,19.736488,-139.047455,0.004531,0.002615,0.066421,87.792282,4.472353,0.664207,-139.047455,0.067444,0.000000
44.770000,20.120033,-139.002975,0.004557,0.002630,0.066794,89.498375,4.559265,0.667936,-139.002975,0.067808,0.000000
44.990002,20.311806,-139.002975,0.004540,0.002642,0.067115,90.351425,4.602721,0.671145,-139.002975,0.068181,0.000000
45.210003,21.281464,-139.002975,0.004557,0.002668,0.067756,94.664680,4.822449,0.677564,-139.002975,0.068546,0.000000
45.430000,21.218529,-138.958496,0.004544,0.002678,0.068034,94.384727,4.808187,0.680339,-138.958496,0.068910,0.000000
45.650002,21.459084,-139.047455,0.004605,0.002693,0.068398,95.454773,4.862698,0.683980,-139.047455,0.069283,0.000000
45.870003,21.761078,-139.047455,0.004631,0.002708,0.068771,96.798111,4.931131,0.687708,-139.047455,0.069647,0.000000
46.090004,21.827362,-139.047455,0.004618,0.002720,0.069100,97.092957,4.946151,0.691005,-139.047455,0.070011,0.000000
46.310001,22.229897,-139.047455,0.004605,0.002733,0.069421,98.883522,5.037367,0.694214,-139.047455,0.070375,0.000000
46.530003,22.396713,-139.091934,0.004618,0.002746,0.069742,99.625557,5.075168,0.697424,-139.091934,0.070748,0.000000
46.750004,22.790688,-139.091934,0.004665,0.002760,0.070115,101.378044,5.164443,0.701152,-139.091934,0.071112,0.000000
46.970001,23.489258,-139.136414,0.004669,0.002779,0.070575,104.485435,5.322742,0.705747,-139.136414,0.071477,0.000000
47.190002,23.724594,-139.091934,0.004669,0.002792,0.070922,105.532265,5.376070,0.709217,-139.091934,0.071849,0.000000
47.410004,24.072021,-139.047455,0.004687,0.002806,0.071260,107.077698,5.454798,0.712597,-139.047455,0.072214,0.000000
47.630001,24.489449,-139.091934,0.004704,0.002821,0.071641,108.934509,5.549388,0.716412,-139.091934,0.072578,0.000000
47.850002,24.704308,-139.180893,0.004700,0.002835,0.072014,109.890251,5.598076,0.720144,-139.180893,0.072942,0.000000
48.070004,25.287071,-139.091934,0.004721,0.002852,0.072431,112.482513,5.730132,0.724308,-139.091934,0.073315,0.000000
48.290001,25.751793,-139.047455,0.004738,0.002866,0.072804,114.549698,5.835440,0.728036,-139.047455,0.073679,0.000000
48.510002,25.428947,-139.091934,0.004747,0.002873,0.072977,113.113609,5.762282,0.729769,-139.091934,0.074044,0.000000
48.730003,25.935371,-139.136414,0.004747,0.002889,0.073393,115.366295,5.877039,0.733933,-139.136414,0.074417,0.000000
48.950001,26.880081,-139.136414,0.004756,0.002908,0.073870,119.568573,6.091114,0.738702,-139.136414,0.074781,0.000000
49.170002,27.282616,-139.180893,0.004769,0.002923,0.074243,121.359138,6.182329,0.742430,-139.180893,0.075145,0.000000
49.390003,27.673607,-139.136414,0.004773,0.002938,0.074616,123.098351,6.270929,0.746162,-139.136414,0.075509,0.000000
49.610001,28.039276,-139.091934,0.004781,0.002951,0.074954,124.724930,6.353791,0.749542,-139.091934,0.075882,0.000000
49.830002,28.493195,-139.136414,0.004794,0.002967,0.075353,126.744057,6.456650,0.753531,-139.136414,0.076246,0.000000
50.050003,29.067024,-139.180893,0.004833,0.002983,0.075761,129.296585,6.586682,0.757607,-139.180893,0.076610,0.000000
50.270004,29.267731,-139.136414,0.004850,0.002993,0.076029,130.189362,6.632163,0.760295,-139.136414,0.076975,0.000000
50.490002,29.574944,-139.136414,0.004855,0.003005,0.076324,131.555923,6.701778,0.763243,-139.136414,0.077348,0.000000
50.710003,30.496193,-139.180893,0.004850,0.003025,0.076845,135.653839,6.910536,0.768447,-139.180893,0.077712,0.000000
50.930004,31.094963,-139.180893,0.004855,0.003041,0.077252,138.317307,7.046219,0.772524,-139.180893,0.078076,0.000000
51.150002,31.675117,-139.180893,0.004876,0.003057,0.077651,140.897964,7.177684,0.776513,-139.180893,0.078449,0.000000
51.370003,31.889610,-139.180893,0.004907,0.003070,0.077972,141.852066,7.226289,0.779722,-139.180893,0.078813,0.000000
51.590004,32.344276,-139.180893,0.004919,0.003083,0.078302,143.874527,7.329318,0.783015,-139.180893,0.079178,0.000000
51.810001,32.618713,-139.180893,0.004924,0.003097,0.078666,145.095291,7.391506,0.786660,-139.180893,0.079542,0.000000
52.030003,33.487831,-139.225372,0.004928,0.003113,0.079082,148.961319,7.588451,0.790824,-139.225372,0.079915,0.000000
52.250004,34.038940,-139.225372,0.004928,0.003128,0.079455,151.412766,7.713334,0.794552,-139.225372,0.080279,0.000000
52.470001,34.200920,-139.269852,0.004941,0.003138,0.079698,152.133286,7.750039,0.796978,-139.269852,0.080643,0.000000
52.690002,34.913269,-139.225372,0.004950,0.003154,0.080114,155.301971,7.911460,0.801141,-139.225372,0.081016,0.000000
52.910004,35.775688,-139.225372,0.004971,0.003171,0.080539,159.138214,8.106887,0.805392,-139.225372,0.081381,0.000000
53.130001,36.367760,-139.225372,0.004980,0.003186,0.080921,161.771881,8.241053,0.809207,-139.225372,0.081745,0.000000
53.350002,36.848488,-139.225372,0.004988,0.003200,0.081285,163.910263,8.349987,0.812848,-139.225372,0.082109,0.000000
53.570004,37.280815,-139.269852,0.004984,0.003212,0.081580,165.833344,8.447953,0.815800,-139.269852,0.082482,0.000000
53.790001,37.779793,-139.269852,0.005019,0.003227,0.081970,168.052917,8.561024,0.819702,-139.269852,0.082846,0.000000
54.010002,38.523796,-139.225372,0.005019,0.003243,0.082369,171.362396,8.729617,0.823692,-139.225372,0.083210,0.000000
54.230003,39.044373,-139.225372,0.005001,0.003255,0.082681,173.678040,8.847581,0.826810,-139.225372,0.083583,0.000000
54.450001,39.332214,-139.225372,0.005040,0.003266,0.082950,174.958435,8.912807,0.829501,-139.225372,0.083947,0.000000
54.670002,40.301872,-139.314346,0.005044,0.003282,0.083375,179.271683,9.132534,0.833748,-139.314346,0.084312,0.000000
54.890003,41.123329,-139.314346,0.005066,0.003300,0.083817,182.925705,9.318680,0.838173,-139.314346,0.084676,0.000000
55.110004,41.796951,-139.269852,0.005083,0.003314,0.084164,185.922119,9.471324,0.841643,-139.269852,0.085049,0.000000
55.330002,42.545792,-139.269852,0.005053,0.003329,0.084555,189.253128,9.641014,0.845546,-139.269852,0.085413,0.000000
55.550003,43.138237,-139.314346,0.005075,0.003343,0.084919,191.888458,9.775264,0.849187,-139.314346,0.085777,0.000000
55.770004,43.731049,-139.314346,0.005096,0.003358,0.085283,194.525421,9.909597,0.852828,-139.314346,0.086150,0.000000
55.990002,44.660866,-139.358826,0.005118,0.003374,0.085699,198.661453,10.120296,0.856991,-139.358826,0.086514,0.000000
56.210003,44.912964,-139.269852,0.005126,0.003385,0.085968,199.782837,10.177423,0.859678,-139.269852,0.086878,0.000000
56.430004,45.082764,-139.314346,0.005135,0.003393,0.086185,200.538147,10.215900,0.861847,-139.314346,0.087243,0.000000
56.650002,46.409523,-139.358826,0.005122,0.003413,0.086688,206.439865,10.516548,0.866877,-139.358826,0.087616,0.000000
56.870003,47.239548,-139.314346,0.005152,0.003428,0.087078,210.132004,10.704635,0.870779,-139.314346,0.087980,0.000000
57.090004,47.477493,-139.403305,0.005135,0.003437,0.087295,211.190445,10.758554,0.872948,-139.403305,0.088344,0.000000
57.310001,48.205109,-139.358826,0.005157,0.003451,0.087650,214.427032,10.923433,0.876502,-139.358826,0.088717,0.000000
57.530003,49.016876,-139.358826,0.005178,0.003467,0.088058,218.037949,11.107383,0.880579,-139.358826,0.089081,0.000000
57.750004,50.130646,-139.358826,0.005165,0.003485,0.088509,222.992249,11.359767,0.885090,-139.358826,0.089445,0.000000
57.970001,50.933105,-139.403305,0.005165,0.003497,0.088821,226.561768,11.541606,0.888213,-139.403305,0.089810,0.000000
58.190002,51.141266,-139.358826,0.005182,0.003507,0.089081,227.487717,11.588777,0.890813,-139.358826,0.090183,0.000000
58.410004,52.109802,-139.358826,0.005200,0.003521,0.089445,231.795975,11.808250,0.894454,-139.358826,0.090547,0.000000
58.630001,53.264160,-139.358826,0.005182,0.003543,0.089992,236.930817,12.069831,0.899919,-139.358826,0.090911,0.000000
58.850002,54.373825,-139.358826,0.005204,0.003557,0.090347,241.866852,12.321285,0.903473,-139.358826,0.091284,0.000000
59.070004,55.318169,-139.447784,0.005217,0.003572,0.090738,246.067505,12.535275,0.907376,-139.447784,0.091648,0.000000
59.290001,56.005562,-139.403305,0.005200,0.003585,0.091067,249.125183,12.691041,0.910672,-139.403305,0.092013,0.000000
59.510002,56.665779,-139.358826,0.005230,0.003597,0.091371,252.061981,12.840650,0.913708,-139.358826,0.092377,0.000000
59.730003,57.384087,-139.403305,0.005260,0.003614,0.091796,255.257172,13.003420,0.917958,-139.403305,0.092750,0.000000
59.950005,58.077820,-139.447784,0.005243,0.003623,0.092021,258.343048,13.160623,0.920214,-139.447784,0.093114,0.000000
60.170002,59.199776,-139.358826,0.005264,0.003641,0.092490,263.333740,13.414861,0.924896,-139.358826,0.093478,0.000000
60.390003,60.061447,-139.403305,0.005264,0.003657,0.092880,267.166656,13.610118,0.928798,-139.403305,0.093851,0.000000
60.610004,60.906731,-139.403305,0.005282,0.003669,0.093201,270.926666,13.801662,0.932008,-139.403305,0.094215,0.000000
60.830002,62.354889,-139.447784,0.005286,0.003688,0.093669,277.368408,14.129820,0.936690,-139.447784,0.094580,0.000000
61.050003,63.272034,-139.403305,0.005273,0.003703,0.094050,281.448059,14.337647,0.940505,-139.403305,0.094944,0.000000
61.270004,63.766174,-139.447784,0.005273,0.003713,0.094311,283.646118,14.449622,0.943109,-139.447784,0.095317,0.000000
61.490002,64.621140,-139.536743,0.005295,0.003726,0.094640,287.449188,14.643359,0.946402,-139.536743,0.095681,0.000000
61.710003,65.643677,-139.447784,0.005295,0.003743,0.095065,291.997650,14.875070,0.950652,-139.447784,0.096045,0.000000
61.930004,66.689682,-139.492264,0.005333,0.003758,0.095455,296.650513,15.112098,0.954554,-139.492264,0.096418,0.000000
62.150002,67.454895,-139.492264,0.005299,0.003766,0.095646,300.054352,15.285498,0.956462,-139.492264,0.096765,0.000000
62.370003,66.757080,-139.492264,0.005329,0.003759,0.095490,296.950317,15.127371,0.954903,-139.492264,0.095733,0.000000
62.590004,66.261826,-139.536743,0.005329,0.003759,0.095473,294.747314,15.015144,0.954728,-139.536743,0.095490,0.000000
62.810001,65.776245,-139.536743,0.005351,0.003758,0.095447,292.587341,14.905110,0.954467,-139.536743,0.095490,0.000000
63.030003,65.345413,-139.492264,0.005364,0.003757,0.095438,290.670929,14.807483,0.954380,-139.492264,0.095490,0.000000
63.250004,64.968201,-139.492264,0.005355,0.003757,0.095429,288.992981,14.722005,0.954293,-139.492264,0.095490,0.000000
63.470001,64.596573,-139.492264,0.005355,0.003757,0.095421,287.339905,14.637793,0.954206,-139.492264,0.095490,0.000000
63.690002,64.289734,-139.581223,0.005359,0.003757,0.095421,285.975006,14.568262,0.954206,-139.581223,0.095490,0.000000
63.910004,64.002258,-139.625702,0.005342,0.003757,0.095421,284.696259,14.503119,0.954206,-139.625702,0.095490,0.000000
64.130005,63.731171,-139.492264,0.005346,0.003756,0.095412,283.490417,14.441689,0.954119,-139.492264,0.095490,0.000000
64.350006,63.488754,-139.536743,0.005372,0.003756,0.095412,282.412079,14.386757,0.954119,-139.536743,0.095490,0.000000
64.570000,63.262726,-139.536743,0.005359,0.003756,0.095412,281.406647,14.335539,0.954119,-139.536743,0.095490,0.000000
64.790001,63.046753,-139.581223,0.005376,0.003756,0.095412,280.445953,14.286599,0.954119,-139.581223,0.095490,0.000000
65.010002,62.850143,-139.625702,0.005372,0.003756,0.095412,279.571411,14.242046,0.954119,-139.625702,0.095490,0.000000
65.230003,62.680710,-139.581223,0.005368,0.003756,0.095412,278.817719,14.203652,0.954119,-139.581223,0.095490,0.000000
65.450005,62.490807,-139.581223,0.005381,0.003756,0.095404,277.972992,14.160620,0.954036,-139.581223,0.095490,0.000000
65.670006,62.337761,-139.581223,0.005364,0.003756,0.095404,277.292206,14.125939,0.954036,-139.581223,0.095490,0.000000
65.889999,62.182854,-139.625702,0.005364,0.003756,0.095404,276.603149,14.090837,0.954036,-139.625702,0.095490,0.000000
66.110001,62.038002,-139.670181,0.005346,0.003756,0.095404,275.958801,14.058012,0.954036,-139.670181,0.095490,0.000000
66.330002,61.892403,-139.625702,0.005355,0.003756,0.095404,275.311157,14.025019,0.954036,-139.625702,0.095490,0.000000
66.550003,61.763191,-139.581223,0.005372,0.003756,0.095404,274.736389,13.995739,0.954036,-139.581223,0.095490,0.000000
66.770004,61.648499,-139.581223,0.005381,0.003756,0.095404,274.226227,13.969749,0.954036,-139.581223,0.095490,0.000000
66.990005,61.521515,-139.670181,0.005355,0.003756,0.095404,273.661377,13.940974,0.954036,-139.670181,0.095490,0.000000
67.210007,61.419861,-139.670181,0.005372,0.003756,0.095404,273.209198,13.917940,0.954036,-139.670181,0.095490,0.000000
67.430000,61.298470,-139.625702,0.005355,0.003756,0.095404,272.669220,13.890432,0.954036,-139.625702,0.095490,0.000000
67.650002,61.208725,-139.581223,0.005355,0.003756,0.095404,272.270020,13.870095,0.954036,-139.581223,0.095490,0.000000
67.870003,61.088074,-139.625702,0.005372,0.003756,0.095404,271.733337,13.842755,0.954036,-139.625702,0.095490,0.000000
68.090004,61.000938,-139.670181,0.005368,0.003756,0.095404,271.345734,13.823010,0.954036,-139.670181,0.095490,0.000000
68.310005,60.896301,-139.714661,0.005381,0.003756,0.095404,270.880280,13.799298,0.954036,-139.714661,0.095490,0.000000
68.530006,60.807678,-139.714661,0.005376,0.003756,0.095404,270.486053,13.779217,0.954036,-139.714661,0.095490,0.000000
68.750000,60.729851,-139.581223,0.005376,0.003756,0.095404,270.139862,13.761580,0.954036,-139.581223,0.095490,0.000000
68.970001,60.643837,-139.670181,0.005394,0.003756,0.095404,269.757263,13.742090,0.954036,-139.670181,0.095490,0.000000
69.190002,60.570107,-139.714661,0.005381,0.003756,0.095404,269.429291,13.725382,0.954036,-139.714661,0.095490,0.000000
69.410004,60.481110,-139.714661,0.005398,0.003756,0.095404,269.033417,13.705215,0.954036,-139.714661,0.095490,0.000000
69.630005,60.409615,-139.670181,0.005376,0.003756,0.095404,268.715393,13.689014,0.954036,-139.670181,0.095490,0.000000
69.850006,60.331413,-139.714661,0.005394,0.003756,0.095404,268.367523,13.671294,0.954036,-139.714661,0.095490,0.000000
70.070000,60.266251,-139.670181,0.005385,0.003756,0.095404,268.077667,13.656528,0.954036,-139.670181,0.095490,0.000000
70.290001,60.200714,-139.714661,0.005376,0.003756,0.095404,267.786163,13.641677,0.954036,-139.714661,0.095490,0.000000
70.510002,60.124748,-139.759155,0.005376,0.003756,0.095404,267.448242,13.624463,0.954036,-139.759155,0.095490,0.000000
70.730003,60.067032,-139.759155,0.005411,0.003756,0.095404,267.191498,13.611383,0.954036,-139.759155,0.095490,0.000000
70.950005,59.989578,-139.759155,0.005394,0.003756,0.095404,266.846985,13.593832,0.954036,-139.759155,0.095490,0.000000
71.170006,59.938934,-139.759155,0.005372,0.003756,0.095404,266.621704,13.582356,0.954036,-139.759155,0.095490,0.000000
71.390007,59.875259,-139.670181,0.005398,0.003756,0.095404,266.338470,13.567928,0.954036,-139.670181,0.095490,0.000000
71.610001,59.816422,-139.803635,0.005394,0.003756,0.095404,266.076721,13.554595,0.954036,-139.803635,0.095490,0.000000
71.830002,59.757591,-139.714661,0.005372,0.003756,0.095404,265.815033,13.541264,0.954036,-139.714661,0.095490,0.000000
72.050003,59.709557,-139.759155,0.005385,0.003756,0.095404,265.601379,13.530378,0.954036,-139.759155,0.095490,0.000000
72.270004,59.649605,-139.714661,0.005372,0.003756,0.095404,265.334686,13.516794,0.954036,-139.714661,0.095490,0.000000
72.490005,59.587791,-139.759155,0.005381,0.003756,0.095404,265.059723,13.502787,0.954036,-139.759155,0.095490,0.000000
72.710007,59.535652,-139.803635,0.005389,0.003756,0.095404,264.827820,13.490972,0.954036,-139.803635,0.095490,0.000000
72.930000,59.473839,-139.803635,0.005402,0.003756,0.095404,264.552856,13.476964,0.954036,-139.803635,0.095490,0.000000
73.150002,59.437347,-139.803635,0.005389,0.003756,0.095404,264.390533,13.468696,0.954036,-139.803635,0.095490,0.000000
73.370003,59.367340,-139.848114,0.005389,0.003756,0.095404,264.079132,13.452832,0.954036,-139.848114,0.095490,0.000000
73.590004,59.327499,-139.759155,0.005398,0.003756,0.095404,263.901886,13.443804,0.954036,-139.759155,0.095490,0.000000
73.810005,59.287659,-139.803635,0.005389,0.003756,0.095404,263.724670,13.434775,0.954036,-139.803635,0.095490,0.000000
74.030006,59.247070,-139.848114,0.005407,0.003756,0.095404,263.544128,13.425578,0.954036,-139.848114,0.095490,0.000000
74.250000,59.192329,-139.803635,0.005394,0.003756,0.095404,263.300629,13.413174,0.954036,-139.803635,0.095490,0.000000
74.470001,59.141685,-139.848114,0.005407,0.003756,0.095404,263.075348,13.401698,0.954036,-139.848114,0.095490,0.000000
74.690002,59.102585,-139.848114,0.005398,0.003756,0.095404,262.901428,13.392838,0.954036,-139.848114,0.095490,0.000000
74.910004,59.064232,-139.892593,0.005407,0.003756,0.095404,262.730835,13.384147,0.954036,-139.892593,0.095490,0.000000
75.130005,59.025131,-139.848114,0.005389,0.003756,0.095404,262.556885,13.375286,0.954036,-139.848114,0.095490,0.000000
75.350006,58.975609,-139.848114,0.005381,0.003756,0.095404,262.336609,13.364064,0.954036,-139.848114,0.095490,0.000000
75.570007,58.941353,-139.803635,0.005398,0.003756,0.095404,262.184235,13.356301,0.954036,-139.803635,0.095490,0.000000
75.790001,58.910072,-139.803635,0.005385,0.003756,0.095404,262.045074,13.349214,0.954036,-139.803635,0.095490,0.000000
76.010002,58.865761,-139.848114,0.005381,0.003756,0.095404,261.847992,13.339172,0.954036,-139.848114,0.095490,0.000000
76.230003,58.819214,-139.892593,0.005381,0.003756,0.095404,261.640930,13.328625,0.954036,-139.892593,0.095490,0.000000
76.450005,58.775642,-139.892593,0.005402,0.003756,0.095404,261.447113,13.318751,0.954036,-139.892593,0.095490,0.000000
76.670006,58.751808,-139.937073,0.005411,0.003756,0.095404,261.341095,13.313351,0.954036,-139.937073,0.095490,0.000000
76.890007,58.723511,-139.937073,0.005415,0.003756,0.095404,261.215210,13.306938,0.954036,-139.937073,0.095490,0.000000
77.110001,58.697075,-139.937073,0.005394,0.003756,0.095404,261.097626,13.300947,0.954036,-139.937073,0.095490,0.000000
77.330002,58.641960,-139.937073,0.005381,0.003756,0.095404,260.852478,13.288458,0.954036,-139.937073,0.095490,0.000000
77.550003,58.595039,-139.981552,0.005368,0.003756,0.095404,260.643738,13.277825,0.954036,-139.981552,0.095490,0.000000
77.770004,58.563019,-139.937073,0.005389,0.003756,0.095404,260.501312,13.270570,0.954036,-139.937073,0.095490,0.000000
77.990005,58.536949,-139.937073,0.005411,0.003756,0.095404,260.385345,13.264662,0.954036,-139.937073,0.095490,0.000000
78.210007,58.516846,-139.892593,0.005376,0.003756,0.095404,260.295929,13.260107,0.954036,-139.892593,0.095490,0.000000
78.430000,58.474770,-139.981552,0.005385,0.003756,0.095404,260.108765,13.250572,0.954036,-139.981552,0.095490,0.000000
78.650002,58.456520,-139.981552,0.005376,0.003756,0.095404,260.027588,13.246437,0.954036,-139.981552,0.095490,0.000000
78.870003,58.422638,-139.892593,0.005381,0.003756,0.095404,259.876862,13.238759,0.954036,-139.892593,0.095490,0.000000
79.090004,58.390610,-139.892593,0.005394,0.003756,0.095395,259.734406,13.231501,0.953949,-139.892593,0.095490,0.000000
79.310005,58.354492,-139.981552,0.005394,0.003756,0.095395,259.573730,13.223317,0.953949,-139.981552,0.095490,0.000000
79.530006,58.328423,-139.937073,0.005385,0.003756,0.095395,259.457794,13.217410,0.953949,-139.937073,0.095490,0.000000
79.750000,58.309433,-140.070511,0.005394,0.003756,0.095395,259.373322,13.213106,0.953949,-140.070511,0.095490,0.000000
79.970001,58.266609,-139.981552,0.005394,0.003756,0.095395,259.182831,13.203403,0.953949,-139.981552,0.095490,0.000000
80.190002,58.245758,-139.981552,0.005407,0.003756,0.095395,259.090057,13.198677,0.953949,-139.981552,0.095490,0.000000
80.410004,58.211502,-139.981552,0.005407,0.003756,0.095395,258.937683,13.190915,0.953949,-139.981552,0.095490,0.000000
80.630005,58.189156,-139.981552,0.005398,0.003756,0.095395,258.838287,13.185851,0.953949,-139.981552,0.095490,0.000000
80.850006,58.162346,-139.937073,0.005394,0.003756,0.095395,258.719025,13.179776,0.953949,-139.937073,0.095490,0.000000
81.070007,58.139259,-140.070511,0.005420,0.003756,0.095395,258.616333,13.174544,0.953949,-140.070511,0.095490,0.000000
81.290001,58.125854,-139.981552,0.005411,0.003756,0.095395,258.556702,13.171507,0.953949,-139.981552,0.095490,0.000000
81.510002,58.084518,-139.981552,0.005407,0.003756,0.095395,258.372833,13.162140,0.953949,-139.981552,0.095490,0.000000
81.730003,58.071114,-140.070511,0.005394,0.003756,0.095395,258.313202,13.159102,0.953949,-140.070511,0.095490,0.000000
81.950005,58.030899,-140.026031,0.005376,0.003756,0.095395,258.134338,13.149990,0.953949,-140.026031,0.095490,0.000000
82.170006,58.000740,-140.070511,0.005407,0.003756,0.095395,258.000183,13.143155,0.953949,-140.070511,0.095490,0.000000
82.390007,57.974670,-140.026031,0.005420,0.003756,0.095395,257.884216,13.137248,0.953949,-140.026031,0.095490,0.000000
82.610001,57.958282,-140.026031,0.005407,0.003756,0.095395,257.811310,13.133534,0.953949,-140.026031,0.095490,0.000000
82.830002,57.939293,-140.026031,0.005407,0.003756,0.095395,257.726837,13.129230,0.953949,-140.026031,0.095490,0.000000
83.050003,57.913605,-140.070511,0.005385,0.003756,0.095395,257.612579,13.123411,0.953949,-140.070511,0.095490,0.000000
83.270004,57.895355,-140.114990,0.005407,0.003756,0.095395,257.531403,13.119275,0.953949,-140.114990,0.095490,0.000000
83.490005,57.852905,-140.070511,0.005389,0.003756,0.095395,257.342590,13.109656,0.953949,-140.070511,0.095490,0.000000
83.710007,57.837265,-140.070511,0.005420,0.003756,0.095395,257.273010,13.106112,0.953949,-140.070511,0.095490,0.000000
83.930000,57.816788,-140.070511,0.005411,0.003756,0.095395,257.181915,13.101471,0.953949,-140.070511,0.095490,0.000000
84.150002,57.792206,-140.070511,0.005398,0.003756,0.095395,257.072571,13.095901,0.953949,-140.070511,0.095490,0.000000
84.370003,57.767258,-140.114990,0.005376,0.003756,0.095395,256.961609,13.090247,0.953949,-140.114990,0.095490,0.000000
84.590004,57.737473,-140.070511,0.005402,0.003756,0.095395,256.829102,13.083498,0.953949,-140.070511,0.095490,0.000000
84.810005,57.725182,-140.070511,0.005407,0.003756,0.095395,256.774445,13.080713,0.953949,-140.070511,0.095490,0.000000
85.030006,57.699486,-140.070511,0.005407,0.003756,0.095395,256.660126,13.074890,0.953949,-140.070511,0.095490,0.000000
85.250008,57.673790,-140.114990,0.005389,0.003756,0.095395,256.545837,13.069067,0.953949,-140.114990,0.095490,0.000000
85.470001,57.650337,-140.159470,0.005394,0.003756,0.095395,256.441498,13.063753,0.953949,-140.159470,0.095490,0.000000
85.690002,57.629478,-140.159470,0.005402,0.003756,0.095395,256.348724,13.059027,0.953949,-140.159470,0.095490,0.000000
85.910004,57.607513,-140.114990,0.005420,0.003756,0.095395,256.251007,13.054049,0.953949,-140.114990,0.095490,0.000000
86.130005,57.575485,-140.159470,0.005428,0.003756,0.095395,256.108551,13.046792,0.953949,-140.159470,0.095490,0.000000
86.350006,57.546066,-140.159470,0.005407,0.003756,0.095395,255.977692,13.040125,0.953949,-140.159470,0.095490,0.000000
86.570007,57.539742,-140.159470,0.005407,0.003756,0.095395,255.949554,13.038692,0.953949,-140.159470,0.095490,0.000000
86.790001,57.504738,-140.159470,0.005411,0.003756,0.095395,255.793854,13.030760,0.953949,-140.159470,0.095490,0.000000
87.010002,57.489098,-140.203964,0.005415,0.003756,0.095395,255.724274,13.027216,0.953949,-140.203964,0.095490,0.000000
87.230003,57.466385,-140.203964,0.005415,0.003756,0.095395,255.623245,13.022069,0.953949,-140.203964,0.095490,0.000000
87.450005,57.457817,-140.114990,0.005385,0.003756,0.095395,255.585129,13.020127,0.953949,-140.114990,0.095490,0.000000
87.670006,57.425049,-140.159470,0.005402,0.003756,0.095395,255.439377,13.012702,0.953949,-140.159470,0.095490,0.000000
87.890007,57.414253,-140.248444,0.005398,0.003756,0.095395,255.391357,13.010256,0.953949,-140.248444,0.095490,0.000000
88.110001,57.387070,-140.159470,0.005407,0.003756,0.095395,255.270432,13.004096,0.953949,-140.159470,0.095490,0.000000
88.330002,57.369934,-140.159470,0.005402,0.003756,0.095395,255.194214,13.000214,0.953949,-140.159470,0.095490,0.000000
88.550003,57.356903,-140.203964,0.005407,0.003756,0.095395,255.136246,12.997260,0.953949,-140.203964,0.095490,0.000000
88.770004,57.324135,-140.203964,0.005407,0.003756,0.095395,254.990494,12.989835,0.953949,-140.203964,0.095490,0.000000
88.990005,57.308495,-140.248444,0.005411,0.003756,0.095395,254.920914,12.986291,0.953949,-140.248444,0.095490,0.000000
89.210007,57.276848,-140.248444,0.005407,0.003756,0.095395,254.780151,12.979119,0.953949,-140.248444,0.095490,0.000000
89.430008,57.270889,-140.203964,0.005402,0.003756,0.095395,254.753632,12.977770,0.953949,-140.203964,0.095490,0.000000
89.650002,57.241844,-140.292923,0.005385,0.003756,0.095395,254.624435,12.971188,0.953949,-140.292923,0.095490,0.000000
89.870003,57.230301,-140.292923,0.005402,0.003756,0.095395,254.573090,12.968571,0.953949,-140.292923,0.095490,0.000000
90.090004,57.215775,-140.292923,0.005407,0.003756,0.095395,254.508469,12.965280,0.953949,-140.292923,0.095490,0.000000
90.310005,57.194923,-140.292923,0.005411,0.003756,0.095395,254.415726,12.960555,0.953949,-140.292923,0.095490,0.000000
90.530006,57.191200,-140.292923,0.005398,0.003756,0.095395,254.399170,12.959712,0.953949,-140.292923,0.095490,0.000000
90.750008,57.150986,-140.248444,0.005394,0.003756,0.095395,254.220276,12.950599,0.953949,-140.248444,0.095490,0.000000
90.970001,57.135712,-140.292923,0.005411,0.003756,0.095395,254.152344,12.947137,0.953949,-140.292923,0.095490,0.000000
91.190002,57.128265,-140.337402,0.005424,0.003756,0.095395,254.119217,12.945451,0.953949,-140.337402,0.095490,0.000000
91.410004,57.101082,-140.292923,0.005411,0.003756,0.095395,253.998291,12.939290,0.953949,-140.292923,0.095490,0.000000
91.630005,57.089172,-140.292923,0.005398,0.003756,0.095395,253.945328,12.936591,0.953949,-140.292923,0.095490,0.000000
91.850006,57.071671,-140.292923,0.005411,0.003756,0.095395,253.867462,12.932625,0.953949,-140.292923,0.095490,0.000000
92.070007,57.053421,-140.337402,0.005411,0.003756,0.095395,253.786285,12.928490,0.953949,-140.337402,0.095490,0.000000
92.290001,57.034805,-140.381882,0.005411,0.003756,0.095395,253.703491,12.924272,0.953949,-140.381882,0.095490,0.000000
92.510002,57.021027,-140.381882,0.005411,0.003756,0.095395,253.642197,12.921149,0.953949,-140.381882,0.095490,0.000000
92.700005,57.004639,-140.337402,0.005420,0.003756,0.095395,253.569290,12.917437,0.953949,-140.337402,0.095490,0.000000