File: Data/Compression Sample NH 10, 12, 15, 17 batch 3/AutoNoheating-10-3-3-240212_02122024_161038.csv
Time (sec),S:Load (lbs),S:HL1 (DIM),S:LVDT (in),S:Position (in),Ch:Position (mm),Ch:Load (N),Ch:Stress (MPa),Ch:Strain (mm/mm),Ch:HL1 (DIM),Set Point (),Cycles ()
0.110000,0.008934,-133.709732,-0.000004,-0.000000,-0.000000,0.039741,0.002024,-0.000000,-133.709732,0.000208,0.000000
0.340000,0.000366,-133.754227,-0.000017,-0.000000,-0.000000,0.001629,0.000083,-0.000000,-133.754227,0.000208,0.000000
0.570000,0.000366,-133.754227,-0.000022,0.000121,0.003079,0.001629,0.000083,0.030786,-133.754227,0.004042,0.000000
0.800000,0.021965,-133.709732,0.000121,0.000264,0.006704,0.097705,0.004977,0.067038,-133.709732,0.007874,0.000000
1.030000,-0.003357,-133.709732,0.000276,0.000411,0.010441,-0.014932,-0.000761,0.104414,-133.709732,0.011708,0.000000
1.260000,-0.005219,-133.754227,0.000435,0.000574,0.014587,-0.023213,-0.001183,0.145870,-133.754227,0.015541,0.000000
1.490000,-0.039474,-133.754227,0.000595,0.000719,0.018264,-0.175591,-0.008945,0.182640,-133.754227,0.019374,0.000000
1.720000,-0.017136,-133.798706,0.000776,0.000867,0.022028,-0.076223,-0.003883,0.220277,-133.798706,0.023207,0.000000
1.950000,0.016006,-133.798706,0.000923,0.001021,0.025922,0.071200,0.003627,0.259216,-133.798706,0.027040,0.000000
2.180000,0.019730,-133.798706,0.001048,0.001166,0.029616,0.087762,0.004471,0.296160,-133.798706,0.030873,0.000000
2.410000,0.021591,-133.798706,0.001233,0.001328,0.033735,0.096042,0.004893,0.337351,-133.798706,0.034706,0.000000
2.640000,-0.002609,-133.798706,0.001406,0.001476,0.037499,-0.011607,-0.000591,0.374988,-133.798706,0.038540,0.000000
2.870000,0.012283,-133.798706,0.001552,0.001627,0.041315,0.054639,0.002783,0.413148,-133.798706,0.042373,0.000000
3.100000,0.011169,-133.887665,0.001703,0.001776,0.045113,0.049684,0.002531,0.451133,-133.887665,0.046189,0.000000
3.330000,0.025322,-133.798706,0.001867,0.001923,0.048851,0.112638,0.005738,0.488509,-133.798706,0.050022,0.000000
3.560000,-0.011543,-133.754227,0.002039,0.002080,0.052823,-0.051347,-0.002616,0.528228,-133.754227,0.053855,0.000000
3.790000,-0.018997,-133.843185,0.002199,0.002233,0.056717,-0.084504,-0.004305,0.567167,-133.843185,0.057688,0.000000
4.020000,-0.036125,-133.843185,0.002350,0.002380,0.060455,-0.160693,-0.008186,0.604546,-133.843185,0.061521,0.000000
4.250000,0.023460,-133.843185,0.002475,0.002529,0.064244,0.104357,0.005316,0.642440,-133.843185,0.065354,0.000000
4.480000,0.016380,-133.887665,0.002643,0.002675,0.067947,0.072863,0.003712,0.679472,-133.887665,0.069187,0.000000
4.710000,0.046547,-133.798706,0.002807,0.002829,0.071859,0.207051,0.010548,0.718585,-133.798706,0.073020,0.000000
4.940000,0.019730,-133.887665,0.002988,0.002985,0.075822,0.087762,0.004471,0.758217,-133.887665,0.076854,0.000000
5.170000,0.005585,-133.843185,0.003109,0.003132,0.079542,0.024842,0.001266,0.795422,-133.843185,0.080687,0.000000
5.400000,0.004837,-133.887665,0.003285,0.003282,0.083366,0.021516,0.001096,0.833665,-133.887665,0.084520,0.000000
5.630000,0.022339,-133.843185,0.003410,0.003436,0.087269,0.099368,0.005062,0.872691,-133.843185,0.088353,0.000000
5.860000,0.045425,-133.843185,0.003592,0.003585,0.091050,0.202062,0.010294,0.910502,-133.843185,0.092186,0.000000
6.090000,0.262146,-133.887665,0.003768,0.003739,0.094979,1.166084,0.059403,0.949785,-133.887665,0.096002,0.000000
6.320000,0.628563,-133.843185,0.003846,-0.000000,-0.000009,2.795988,0.142434,-0.000087,-133.843185,0.000208,0.000000
6.550000,0.575310,-133.932144,0.003837,-0.000000,-0.000009,2.559106,0.130367,-0.000087,-133.932144,0.000208,0.000000
6.780000,0.532860,-133.932144,0.003829,-0.000000,-0.000009,2.370279,0.120748,-0.000087,-133.932144,0.000226,0.000000
7.010000,0.568985,-133.887665,0.003846,-0.000000,-0.000009,2.530972,0.128934,-0.000087,-133.887665,0.000607,0.000000
7.240000,0.555206,-133.887665,0.003837,-0.000000,-0.000000,2.469681,0.125812,-0.000000,-133.887665,0.000997,0.000000
7.470000,0.538818,-133.976624,0.003850,-0.000000,-0.000000,2.396784,0.122098,-0.000000,-133.976624,0.001379,0.000000
7.700000,0.788681,-133.976624,0.003876,0.000038,0.000954,3.508229,0.178718,0.009538,-133.976624,0.001760,0.000000
7.930000,0.873581,-133.887665,0.003863,0.000049,0.001249,3.885882,0.197956,0.012490,-133.887665,0.002142,0.000000
8.160001,0.943962,-133.932144,0.003885,0.000063,0.001596,4.198953,0.213905,0.015957,-133.932144,0.002524,0.000000
8.390000,1.068703,-133.887665,0.003889,0.000079,0.002012,4.753827,0.242171,0.020121,-133.887665,0.002914,0.000000
8.620001,1.145790,-133.932144,0.003928,0.000094,0.002376,5.096729,0.259640,0.023762,-133.932144,0.003296,0.000000
8.850000,1.333466,-133.976624,0.003928,0.000111,0.002819,5.931551,0.302168,0.028186,-133.976624,0.003677,0.000000
9.080001,1.365112,-133.976624,0.003941,0.000119,0.003018,6.072323,0.309339,0.030181,-133.976624,0.004059,0.000000
9.310000,1.566940,-133.932144,0.003971,0.000138,0.003495,6.970098,0.355074,0.034950,-133.932144,0.004440,0.000000
9.540001,1.721474,-134.021103,0.003984,0.000155,0.003929,7.657497,0.390092,0.039287,-134.021103,0.004831,0.000000
9.770000,1.866699,-133.976624,0.004010,0.000170,0.004328,8.303493,0.423000,0.043276,-133.976624,0.005212,0.000000
10.000000,1.977295,-133.976624,0.003992,0.000185,0.004709,8.795447,0.448061,0.047092,-133.976624,0.005594,0.000000
10.230000,2.113213,-134.021103,0.004027,0.000202,0.005126,9.400039,0.478861,0.051255,-134.021103,0.005975,0.000000
10.460000,2.232742,-133.976624,0.004036,0.000214,0.005437,9.931734,0.505947,0.054374,-133.976624,0.006357,0.000000
10.690001,2.447227,-133.932144,0.004027,0.000231,0.005871,10.885812,0.554550,0.058711,-133.932144,0.006747,0.000000
10.920000,2.526543,-134.065582,0.004083,0.000243,0.006175,11.238623,0.572523,0.061747,-134.065582,0.007128,0.000000
11.150001,2.661713,-134.110062,0.004053,0.000257,0.006539,11.839890,0.603153,0.065388,-134.110062,0.007510,0.000000
11.380000,2.901154,-134.065582,0.004113,0.000279,0.007077,12.904976,0.657411,0.070766,-134.065582,0.007892,0.000000
11.610001,3.070580,-133.976624,0.004122,0.000296,0.007527,13.658620,0.695803,0.075274,-133.976624,0.008273,0.000000
11.840000,3.184898,-134.021103,0.004161,0.000311,0.007892,14.167135,0.721708,0.078919,-134.021103,0.008664,0.000000
12.070001,3.240013,-134.065582,0.004165,0.000324,0.008230,14.412298,0.734197,0.082299,-134.065582,0.009045,0.000000
12.300000,3.353958,-134.065582,0.004161,0.000337,0.008568,14.919151,0.760018,0.085682,-134.065582,0.009427,0.000000
12.530001,3.528969,-134.110062,0.004169,0.000355,0.009019,15.697638,0.799676,0.090190,-134.110062,0.009808,0.000000
12.760000,3.715157,-134.065582,0.004182,0.000372,0.009461,16.525843,0.841866,0.094615,-134.065582,0.010199,0.000000
12.990001,3.710686,-134.021103,0.004221,0.000380,0.009652,16.505955,0.840853,0.096522,-134.021103,0.010580,0.000000
13.220000,3.864853,-134.065582,0.004225,0.000395,0.010025,17.191725,0.875788,0.100251,-134.065582,0.010962,0.000000
13.450001,4.039124,-134.110062,0.004234,0.000415,0.010545,17.966919,0.915278,0.105455,-134.110062,0.011343,0.000000
13.680000,4.147484,-134.065582,0.004247,0.000431,0.010944,18.448929,0.939833,0.109444,-134.065582,0.011725,0.000000
13.910001,4.209671,-134.065582,0.004260,0.000446,0.011326,18.725552,0.953925,0.113259,-134.065582,0.012115,0.000000
14.140000,4.287125,-134.110062,0.004277,0.000459,0.011656,19.070084,0.971476,0.116556,-134.110062,0.012497,0.000000
14.370001,4.360481,-134.021103,0.004329,0.000474,0.012037,19.396389,0.988099,0.120371,-134.021103,0.012878,0.000000
14.600000,4.478149,-134.199036,0.004316,0.000489,0.012427,19.919804,1.014763,0.124273,-134.199036,0.013260,0.000000
14.830001,4.598427,-134.199036,0.004320,0.000504,0.012800,20.454824,1.042018,0.128001,-134.199036,0.013642,0.000000
15.060000,4.578690,-134.154541,0.004333,0.000514,0.013043,20.367029,1.037546,0.130431,-134.154541,0.014032,0.000000
15.290001,4.768227,-134.110062,0.004359,0.000531,0.013477,21.210131,1.080496,0.134769,-134.110062,0.014413,0.000000
15.520000,4.918663,-134.110062,0.004372,0.000551,0.013988,21.879307,1.114585,0.139882,-134.110062,0.014795,0.000000
15.750001,4.956276,-134.154541,0.004376,0.000565,0.014361,22.046616,1.123108,0.143614,-134.154541,0.015176,0.000000
15.980000,5.009521,-134.154541,0.004385,0.000581,0.014769,22.283464,1.135174,0.147690,-134.154541,0.015558,0.000000
16.210001,5.028145,-134.154541,0.004432,0.000593,0.015073,22.366304,1.139394,0.150726,-134.154541,0.015948,0.000000
16.440001,5.179329,-134.199036,0.004432,0.000611,0.015532,23.038805,1.173653,0.155321,-134.199036,0.016330,0.000000
16.670000,5.248962,-134.154541,0.004467,0.000627,0.015914,23.348551,1.189432,0.159136,-134.154541,0.016711,0.000000
16.900002,5.158470,-134.199036,0.004449,0.000633,0.016078,22.946022,1.168926,0.160782,-134.199036,0.017093,0.000000
17.130001,5.380035,-134.243515,0.004488,0.000654,0.016616,23.931593,1.219133,0.166161,-134.243515,0.017474,0.000000
17.360001,5.450417,-134.199036,0.004506,0.000669,0.016980,24.244663,1.235082,0.169802,-134.199036,0.017865,0.000000
17.590000,5.526375,-134.154541,0.004518,0.000683,0.017336,24.582542,1.252294,0.173360,-134.154541,0.018247,0.000000
17.820002,5.565475,-134.199036,0.004523,0.000698,0.017717,24.756472,1.261155,0.177175,-134.199036,0.018628,0.000000
18.050001,5.581116,-134.199036,0.004553,0.000711,0.018056,24.826042,1.264699,0.180558,-134.199036,0.019010,0.000000
18.280001,5.699532,-134.199036,0.004583,0.000728,0.018498,25.352783,1.291532,0.184979,-134.199036,0.019391,0.000000
18.510000,5.793739,-134.243515,0.004566,0.000744,0.018906,25.771839,1.312880,0.189056,-134.243515,0.019781,0.000000
18.740002,5.773262,-134.199036,0.004579,0.000754,0.019157,25.680752,1.308240,0.191569,-134.199036,0.020163,0.000000
18.970001,5.818687,-134.243515,0.004605,0.000768,0.019504,25.882814,1.318533,0.195039,-134.243515,0.020545,0.000000
19.200001,6.079720,-134.243515,0.004605,0.000791,0.020085,27.043943,1.377684,0.200849,-134.243515,0.020926,0.000000
19.430000,6.172440,-134.243515,0.004648,0.000808,0.020519,27.456383,1.398695,0.205187,-134.243515,0.021308,0.000000
19.660002,6.085304,-134.287994,0.004648,0.000819,0.020814,27.068785,1.378950,0.208135,-134.287994,0.021698,0.000000
19.890001,6.174675,-134.199036,0.004661,0.000836,0.021239,27.466326,1.399201,0.212386,-134.199036,0.022080,0.000000
20.120001,6.165741,-134.199036,0.004700,0.000848,0.021533,27.426586,1.397177,0.215334,-134.199036,0.022461,0.000000
20.350000,6.314690,-134.243515,0.004708,0.000866,0.021984,28.089142,1.430929,0.219842,-134.243515,0.022843,0.000000
20.580002,6.238724,-134.332474,0.004730,0.000874,0.022192,27.751228,1.413715,0.221924,-134.332474,0.023224,0.000000
20.810001,6.415604,-134.243515,0.004717,0.000892,0.022661,28.538031,1.453797,0.226605,-134.243515,0.023615,0.000000
21.040001,6.576469,-134.332474,0.004760,0.000911,0.023129,29.253597,1.490249,0.231291,-134.332474,0.023996,0.000000
21.270000,6.647964,-134.243515,0.004760,0.000929,0.023589,29.571623,1.506450,0.235886,-134.243515,0.024378,0.000000
21.500002,6.634560,-134.287994,0.004773,0.000942,0.023935,29.511995,1.503413,0.239353,-134.287994,0.024759,0.000000
21.730001,6.621155,-134.332474,0.004799,0.000956,0.024282,29.452368,1.500375,0.242824,-134.332474,0.025149,0.000000
21.960001,6.685944,-134.287994,0.004794,0.000971,0.024664,29.740562,1.515056,0.246639,-134.287994,0.025531,0.000000
22.190001,6.746643,-134.287994,0.004807,0.000985,0.025011,30.010567,1.528811,0.250110,-134.287994,0.025913,0.000000
22.420002,6.904152,-134.332474,0.004820,0.001002,0.025453,30.711201,1.564503,0.254530,-134.332474,0.026294,0.000000
22.650002,6.941391,-134.287994,0.004868,0.001016,0.025809,30.876850,1.572942,0.258088,-134.287994,0.026676,0.000000
22.880001,6.836754,-134.376953,0.004868,0.001025,0.026043,30.411400,1.549231,0.260427,-134.376953,0.027066,0.000000
23.110001,7.172638,-134.332474,0.004889,0.001049,0.026650,31.905487,1.625343,0.266498,-134.332474,0.027448,0.000000
23.340002,7.161095,-134.332474,0.004907,0.001063,0.026988,31.854139,1.622727,0.269882,-134.332474,0.027829,0.000000
23.570002,7.221413,-134.287994,0.004924,0.001080,0.027439,32.122448,1.636396,0.274390,-134.287994,0.028211,0.000000
23.800001,7.147316,-134.376953,0.004928,0.001090,0.027682,31.792849,1.619605,0.276820,-134.376953,0.028593,0.000000
24.030001,7.168915,-134.421432,0.004924,0.001103,0.028011,31.888926,1.624499,0.280113,-134.421432,0.028983,0.000000
24.260000,7.425850,-134.376953,0.004941,0.001119,0.028428,33.031830,1.682722,0.284276,-134.376953,0.029364,0.000000
24.490002,7.543518,-134.376953,0.004980,0.001138,0.028904,33.555244,1.709386,0.289045,-134.376953,0.029746,0.000000
24.720001,7.502182,-134.332474,0.004993,0.001149,0.029191,33.371372,1.700019,0.291910,-134.332474,0.030127,0.000000
24.950001,7.492500,-134.421432,0.005010,0.001161,0.029495,33.328304,1.697825,0.294946,-134.421432,0.030509,0.000000
25.180000,7.785934,-134.465912,0.005006,0.001186,0.030127,34.633568,1.764318,0.301274,-134.465912,0.030899,0.000000
25.410002,7.759865,-134.421432,0.005027,0.001197,0.030396,34.517601,1.758410,0.303961,-134.421432,0.031281,0.000000
25.640001,7.773270,-134.421432,0.005053,0.001213,0.030821,34.577229,1.761448,0.308212,-134.421432,0.031663,0.000000
25.870001,7.776993,-134.376953,0.005066,0.001225,0.031116,34.593792,1.762292,0.311160,-134.376953,0.032044,0.000000
26.100000,7.883865,-134.465912,0.005044,0.001240,0.031498,35.069183,1.786509,0.314975,-134.465912,0.032426,0.000000
26.330002,8.018669,-134.421432,0.005088,0.001256,0.031905,35.668823,1.817056,0.319052,-134.421432,0.032816,0.000000
26.560001,7.993713,-134.465912,0.005113,0.001268,0.032209,35.557812,1.811401,0.322087,-134.465912,0.033197,0.000000
26.790001,8.154579,-134.465912,0.005118,0.001283,0.032599,36.273380,1.847854,0.325989,-134.465912,0.033579,0.000000
27.020000,8.471100,-134.376953,0.005152,0.001307,0.033206,37.681335,1.919579,0.332060,-134.376953,0.033961,0.000000
27.250002,8.452477,-134.376953,0.005174,0.001322,0.033579,37.598492,1.915359,0.335788,-134.376953,0.034342,0.000000
27.480001,8.335182,-134.510391,0.005165,0.001332,0.033831,37.076740,1.888779,0.338305,-134.510391,0.034732,0.000000
27.710001,8.512062,-134.465912,0.005178,0.001350,0.034299,37.863544,1.928861,0.342987,-134.465912,0.035114,0.000000
27.940001,8.285660,-134.421432,0.005195,0.001357,0.034464,36.856457,1.877557,0.344637,-134.421432,0.035496,0.000000
28.170002,8.688934,-134.421432,0.005217,0.001379,0.035027,38.650311,1.968941,0.350273,-134.421432,0.035877,0.000000
28.400002,8.693779,-134.510391,0.005217,0.001392,0.035357,38.671860,1.970038,0.353570,-134.510391,0.036259,0.000000
28.630001,8.688934,-134.510391,0.005238,0.001402,0.035617,38.650311,1.968941,0.356170,-134.510391,0.036649,0.000000
28.860001,8.981995,-134.554871,0.005247,0.001423,0.036146,39.953907,2.035349,0.361461,-134.554871,0.037031,0.000000
29.090002,9.146957,-134.510391,0.005260,0.001441,0.036597,40.687698,2.072730,0.365969,-134.510391,0.037412,0.000000
29.320002,9.053864,-134.554871,0.005290,0.001451,0.036849,40.273598,2.051635,0.368486,-134.554871,0.037794,0.000000
29.550001,9.130569,-134.554871,0.005303,0.001466,0.037239,40.614799,2.069016,0.372388,-134.554871,0.038175,0.000000
29.780001,9.147697,-134.510391,0.005333,0.001480,0.037603,40.690990,2.072898,0.376029,-134.510391,0.038565,0.000000
30.010002,9.429214,-134.554871,0.005333,0.001499,0.038062,41.943241,2.136691,0.380624,-134.554871,0.038947,0.000000
30.240002,9.472404,-134.554871,0.005355,0.001513,0.038436,42.135361,2.146477,0.384356,-134.554871,0.039329,0.000000
30.470001,9.320854,-134.510391,0.005346,0.001522,0.038652,41.461231,2.112136,0.386521,-134.510391,0.039710,0.000000
30.700001,9.672371,-134.554871,0.005394,0.001543,0.039190,43.024853,2.191791,0.391899,-134.554871,0.040101,0.000000
30.930002,9.763977,-134.599365,0.005402,0.001559,0.039589,43.432339,2.212549,0.395889,-134.599365,0.040482,0.000000
31.160002,9.882759,-134.643845,0.005394,0.001575,0.040014,43.960709,2.239465,0.400139,-134.643845,0.040864,0.000000
31.390001,9.925209,-134.554871,0.005415,0.001591,0.040404,44.149536,2.249084,0.404041,-134.554871,0.041245,0.000000
31.620001,10.004898,-134.510391,0.005415,0.001605,0.040768,44.504009,2.267142,0.407682,-134.510391,0.041627,0.000000
31.850002,10.025383,-134.554871,0.005441,0.001619,0.041124,44.595131,2.271784,0.411240,-134.554871,0.042017,0.000000
32.080002,10.081978,-134.599365,0.005454,0.001633,0.041479,44.846878,2.284609,0.414794,-134.599365,0.042399,0.000000
32.310001,10.207100,-134.643845,0.005476,0.001647,0.041844,45.403446,2.312962,0.418435,-134.643845,0.042780,0.000000
32.540001,10.496803,-134.643845,0.005484,0.001667,0.042329,46.692112,2.378610,0.423291,-134.643845,0.043162,0.000000
32.770000,10.577240,-134.554871,0.005514,0.001683,0.042745,47.049911,2.396837,0.427455,-134.554871,0.043543,0.000000
33.000000,10.731400,-134.599365,0.005510,0.001699,0.043162,47.735649,2.431770,0.431618,-134.599365,0.043934,0.000000
33.230003,10.639793,-134.643845,0.005536,0.001712,0.043474,47.328163,2.411012,0.434741,-134.643845,0.044315,0.000000
33.460003,10.743690,-134.643845,0.005566,0.001727,0.043856,47.790321,2.434555,0.438556,-134.643845,0.044697,0.000000
33.690002,10.786880,-134.599365,0.005570,0.001740,0.044185,47.982441,2.444342,0.441852,-134.599365,0.045078,0.000000
33.920002,11.050148,-134.643845,0.005570,0.001758,0.044662,49.153515,2.503999,0.446621,-134.643845,0.045460,0.000000
34.150002,11.235222,-134.643845,0.005605,0.001775,0.045078,49.976765,2.545938,0.450785,-134.643845,0.045850,0.000000
34.380001,11.094833,-134.688324,0.005605,0.001783,0.045287,49.352283,2.514125,0.452866,-134.688324,0.046232,0.000000
34.610001,11.378952,-134.732803,0.005614,0.001800,0.045720,50.616108,2.578507,0.457200,-134.732803,0.046613,0.000000
34.840000,11.566261,-134.688324,0.005639,0.001817,0.046145,51.449299,2.620952,0.461451,-134.688324,0.046995,0.000000
35.070004,11.688766,-134.688324,0.005661,0.001833,0.046570,51.994228,2.648712,0.465701,-134.688324,0.047377,0.000000
35.300003,11.745369,-134.688324,0.005683,0.001849,0.046960,52.246010,2.661539,0.469603,-134.688324,0.047767,0.000000
35.530003,11.726753,-134.732803,0.005691,0.001860,0.047246,52.163204,2.657320,0.472465,-134.732803,0.048148,0.000000
35.760002,11.917404,-134.732803,0.005687,0.001878,0.047689,53.011261,2.700522,0.476889,-134.732803,0.048530,0.000000
35.990002,12.150139,-134.732803,0.005721,0.001894,0.048105,54.046516,2.753261,0.481049,-134.732803,0.048911,0.000000
36.220001,12.052208,-134.732803,0.005726,0.001904,0.048365,53.610897,2.731069,0.483653,-134.732803,0.049293,0.000000
36.450001,12.230568,-134.688324,0.005756,0.001919,0.048738,54.404282,2.771486,0.487381,-134.688324,0.049684,0.000000
36.680000,12.562355,-134.732803,0.005752,0.001937,0.049206,55.880146,2.846670,0.492063,-134.732803,0.050065,0.000000
36.910000,12.690453,-134.777283,0.005769,0.001953,0.049597,56.449951,2.875698,0.495965,-134.777283,0.050447,0.000000
37.140003,12.786148,-134.732803,0.005786,0.001968,0.049987,56.875626,2.897382,0.499871,-134.732803,0.050828,0.000000
37.370003,12.915367,-134.777283,0.005786,0.001983,0.050377,57.450420,2.926664,0.503773,-134.777283,0.051210,0.000000
37.600002,12.890411,-134.688324,0.005825,0.001996,0.050707,57.339413,2.921009,0.507066,-134.688324,0.051600,0.000000
37.830002,13.249756,-134.821762,0.005833,0.002014,0.051166,58.937859,3.002438,0.511665,-134.821762,0.051981,0.000000
38.060001,13.246773,-134.821762,0.005851,0.002026,0.051453,58.924587,3.001761,0.514526,-134.821762,0.052363,0.000000
38.290001,13.233368,-134.777283,0.005851,0.002038,0.051765,58.864960,2.998724,0.517649,-134.777283,0.052745,0.000000
38.520000,13.644096,-134.732803,0.005881,0.002057,0.052259,60.691971,3.091796,0.522592,-134.732803,0.053126,0.000000
38.750000,13.762512,-134.732803,0.005898,0.002072,0.052623,61.218712,3.118630,0.526233,-134.732803,0.053517,0.000000
38.980003,13.869385,-134.821762,0.005890,0.002086,0.052979,61.694103,3.142848,0.529787,-134.821762,0.053898,0.000000
39.210003,14.071579,-134.866241,0.005911,0.002103,0.053404,62.593510,3.188665,0.534037,-134.866241,0.054280,0.000000
39.440002,14.065247,-134.777283,0.005907,0.002113,0.053681,62.565342,3.187231,0.536812,-134.777283,0.054661,0.000000
39.670002,14.484917,-134.821762,0.005954,0.002132,0.054158,64.432129,3.282329,0.541584,-134.821762,0.055052,0.000000
39.900002,14.528107,-134.777283,0.005941,0.002146,0.054496,64.624245,3.292116,0.544964,-134.777283,0.055433,0.000000
40.130001,14.371338,-134.821762,0.005980,0.002153,0.054696,63.926903,3.256592,0.546959,-134.821762,0.055815,0.000000
40.360001,14.648758,-134.866241,0.005976,0.002172,0.055164,65.160927,3.319456,0.551641,-134.866241,0.056196,0.000000
40.590000,15.294449,-134.821762,0.005967,0.002193,0.055702,68.033104,3.465772,0.557019,-134.821762,0.056578,0.000000
40.820004,15.494041,-134.821762,0.006015,0.002209,0.056118,68.920937,3.511000,0.561183,-134.821762,0.056968,0.000000
41.050003,15.592346,-134.866241,0.006028,0.002224,0.056500,69.358223,3.533276,0.564998,-134.866241,0.057349,0.000000
41.280003,15.670921,-134.866241,0.006062,0.002239,0.056864,69.707741,3.551081,0.568639,-134.866241,0.057731,0.000000
41.510002,15.632568,-134.910721,0.006045,0.002251,0.057176,69.537140,3.542391,0.571761,-134.910721,0.058113,0.000000
41.740002,15.984833,-134.910721,0.006075,0.002266,0.057549,71.104088,3.622215,0.575490,-134.910721,0.058494,0.000000
41.970001,15.981110,-134.866241,0.006084,0.002279,0.057879,71.087524,3.621371,0.578786,-134.866241,0.058885,0.000000
42.200001,16.310654,-134.866241,0.006088,0.002294,0.058269,72.553413,3.696047,0.582688,-134.866241,0.059266,0.000000
42.430000,16.690102,-134.866241,0.006140,0.002312,0.058720,74.241280,3.782031,0.587200,-134.866241,0.059648,0.000000
42.660004,17.135834,-134.955200,0.006122,0.002332,0.059232,76.223999,3.883035,0.592317,-134.955200,0.060030,0.000000
42.890003,17.268768,-134.866241,0.006131,0.002348,0.059648,76.815315,3.913159,0.596477,-134.866241,0.060411,0.000000
43.120003,17.186104,-134.821762,0.006178,0.002360,0.059934,76.447609,3.894427,0.599338,-134.821762,0.060801,0.000000
43.350002,17.315315,-134.866241,0.006174,0.002372,0.060246,77.022369,3.923707,0.602461,-134.866241,0.061183,0.000000
43.580002,17.570763,-134.910721,0.006196,0.002387,0.060619,78.158653,3.981592,0.606193,-134.910721,0.061564,0.000000
43.810001,17.906273,-134.955200,0.006191,0.002403,0.061027,79.651077,4.057620,0.610269,-134.955200,0.061946,0.000000
44.040001,17.992287,-134.999680,0.006217,0.002416,0.061356,80.033691,4.077110,0.613562,-134.999680,0.062327,0.000000
44.270000,18.358704,-134.866241,0.006239,0.002433,0.061807,81.663589,4.160142,0.618073,-134.866241,0.062718,0.000000
44.500004,18.969398,-134.999680,0.006222,0.002453,0.062310,84.380096,4.298527,0.623103,-134.999680,0.063099,0.000000
44.730003,18.989128,-134.999680,0.006265,0.002464,0.062588,84.467857,4.302998,0.625878,-134.999680,0.063481,0.000000
44.960003,19.291870,-134.955200,0.006247,0.002481,0.063021,85.814522,4.371600,0.630212,-134.955200,0.063863,0.000000
45.190002,19.230797,-134.999680,0.006278,0.002493,0.063325,85.542854,4.357760,0.633247,-134.999680,0.064244,0.000000
45.420002,19.230431,-134.999680,0.006282,0.002503,0.063568,85.541229,4.357678,0.635677,-134.999680,0.064634,0.000000
45.650002,20.131195,-134.955200,0.006299,0.002526,0.064149,89.548027,4.561794,0.641487,-134.955200,0.065016,0.000000
45.880001,20.479736,-134.999680,0.006334,0.002540,0.064521,91.098419,4.640775,0.645215,-134.999680,0.065398,0.000000
46.110001,20.293182,-134.999680,0.006321,0.002549,0.064756,90.268585,4.598501,0.647558,-134.999680,0.065779,0.000000
46.340004,20.392227,-135.044174,0.006351,0.002564,0.065137,90.709160,4.620944,0.651373,-135.044174,0.066161,0.000000
46.570004,21.535789,-134.999680,0.006368,0.002589,0.065762,95.795975,4.880080,0.657618,-134.999680,0.066551,0.000000
46.800003,21.618080,-134.910721,0.006372,0.002602,0.066100,96.162025,4.898727,0.660998,-134.910721,0.066932,0.000000
47.030003,21.727554,-134.999680,0.006398,0.002615,0.066429,96.648987,4.923534,0.664294,-134.999680,0.067314,0.000000
47.260002,21.869431,-135.044174,0.006403,0.002628,0.066750,97.280083,4.955684,0.667504,-135.044174,0.067695,0.000000
47.490002,22.280159,-134.955200,0.006416,0.002644,0.067158,99.107094,5.048756,0.671580,-134.955200,0.068086,0.000000
47.720001,22.551620,-134.999680,0.006437,0.002657,0.067488,100.314621,5.110270,0.674877,-134.999680,0.068468,0.000000
47.950001,22.617531,-135.088654,0.006441,0.002668,0.067756,100.607803,5.125206,0.677564,-135.088654,0.068849,0.000000
48.180004,23.320938,-135.088654,0.006459,0.002686,0.068225,103.736717,5.284600,0.682246,-135.088654,0.069231,0.000000
48.410004,24.203461,-135.044174,0.006454,0.002709,0.068806,107.662369,5.484583,0.688056,-135.044174,0.069612,0.000000
48.640003,24.449226,-135.044174,0.006489,0.002723,0.069161,108.755592,5.540274,0.691614,-135.044174,0.070002,0.000000
48.870003,24.629456,-135.044174,0.006515,0.002737,0.069525,109.557289,5.581114,0.695255,-135.044174,0.070384,0.000000
49.100002,24.864426,-135.044174,0.006506,0.002752,0.069898,110.602486,5.634359,0.698983,-135.044174,0.070766,0.000000
49.330002,25.072205,-135.044174,0.006523,0.002766,0.070245,111.526733,5.681443,0.702454,-135.044174,0.071147,0.000000
49.560001,25.530968,-135.088654,0.006523,0.002780,0.070601,113.567413,5.785400,0.706008,-135.088654,0.071529,0.000000
49.790001,25.820305,-135.088654,0.006541,0.002793,0.070939,114.854454,5.850965,0.709392,-135.088654,0.071919,0.000000
50.020004,26.047821,-135.088654,0.006554,0.002805,0.071251,115.866493,5.902521,0.712514,-135.088654,0.072301,0.000000
50.250004,26.689423,-135.044174,0.006588,0.002823,0.071711,118.720482,6.047909,0.717109,-135.044174,0.072682,0.000000
50.480003,27.513855,-135.133133,0.006571,0.002842,0.072196,122.387741,6.234729,0.721965,-135.133133,0.073064,0.000000
50.710003,27.555183,-135.088654,0.006605,0.002854,0.072483,122.571579,6.244093,0.724826,-135.088654,0.073446,0.000000
50.940002,27.778984,-135.133133,0.006614,0.002868,0.072847,123.567093,6.294808,0.728471,-135.133133,0.073836,0.000000
51.170002,28.336426,-135.177612,0.006618,0.002884,0.073263,126.046715,6.421126,0.732631,-135.177612,0.074217,0.000000
51.400002,29.029411,-135.133133,0.006635,0.002902,0.073714,129.129272,6.578159,0.737142,-135.133133,0.074599,0.000000
51.630001,29.212990,-135.177612,0.006640,0.002913,0.073992,129.945862,6.619758,0.739917,-135.177612,0.074980,0.000000
51.860001,29.406624,-135.177612,0.006670,0.002927,0.074356,130.807190,6.663636,0.743558,-135.177612,0.075362,0.000000
52.090004,30.322289,-135.177612,0.006653,0.002945,0.074816,134.880280,6.871129,0.748156,-135.177612,0.075752,0.000000
52.320004,30.739716,-135.177612,0.006679,0.002961,0.075197,136.737091,6.965719,0.751972,-135.177612,0.076134,0.000000
52.550003,31.445732,-135.133133,0.006691,0.002978,0.075640,139.877609,7.125705,0.756396,-135.133133,0.076515,0.000000
52.780003,31.834488,-135.222092,0.006687,0.002992,0.076004,141.606873,7.213798,0.760037,-135.222092,0.076897,0.000000
53.010002,32.055679,-135.222092,0.006717,0.003005,0.076325,142.590790,7.263921,0.763247,-135.222092,0.077278,0.000000
53.240002,32.808617,-135.177612,0.006713,0.003023,0.076793,145.940018,7.434539,0.767929,-135.177612,0.077669,0.000000
53.470001,32.983635,-135.177612,0.006739,0.003034,0.077062,146.718536,7.474198,0.770616,-135.177612,0.078050,0.000000
53.700001,33.513145,-135.222092,0.006769,0.003049,0.077435,149.073914,7.594187,0.774348,-135.222092,0.078432,0.000000
53.930004,34.465675,-135.177612,0.006752,0.003069,0.077955,153.310974,7.810033,0.779548,-135.177612,0.078814,0.000000
54.160004,35.094986,-135.222092,0.006782,0.003085,0.078371,156.110291,7.952638,0.783712,-135.222092,0.079195,0.000000
54.390003,35.696739,-135.177612,0.006769,0.003102,0.078788,158.787033,8.088997,0.787875,-135.177612,0.079585,0.000000
54.620003,35.927612,-135.222092,0.006795,0.003115,0.079117,159.813995,8.141314,0.791172,-135.222092,0.079967,0.000000
54.850002,36.387489,-135.222092,0.006825,0.003127,0.079438,161.859634,8.245522,0.794378,-135.222092,0.080348,0.000000
55.080002,36.880135,-135.266571,0.006829,0.003143,0.079837,164.051025,8.357158,0.798367,-135.266571,0.080730,0.000000
55.310001,37.727287,-135.311050,0.006851,0.003160,0.080270,167.819351,8.549126,0.802704,-135.311050,0.081112,0.000000
55.540001,38.372238,-135.266571,0.006838,0.003175,0.080643,170.688248,8.695273,0.806432,-135.266571,0.081502,0.000000
55.770004,38.379311,-135.266571,0.006860,0.003183,0.080860,170.719696,8.696876,0.808601,-135.266571,0.081884,0.000000
56.000004,39.612236,-135.266571,0.006881,0.003205,0.081398,176.204025,8.976261,0.813980,-135.266571,0.082265,0.000000
56.230003,40.126106,-135.266571,0.006864,0.003220,0.081788,178.489838,9.092706,0.817882,-135.266571,0.082647,0.000000
56.460003,40.843300,-135.266571,0.006868,0.003234,0.082144,181.680069,9.255223,0.821436,-135.266571,0.083037,0.000000
56.690002,41.466652,-135.311050,0.006868,0.003250,0.082543,184.452881,9.396478,0.825425,-135.311050,0.083418,0.000000
56.920002,41.758965,-135.266571,0.006924,0.003262,0.082846,185.753159,9.462716,0.828461,-135.266571,0.083800,0.000000
57.150002,42.594566,-135.266571,0.006920,0.003277,0.083245,189.470093,9.652066,0.832450,-135.266571,0.084182,0.000000
57.380001,43.483047,-135.266571,0.006916,0.003295,0.083696,193.422256,9.853399,0.836961,-135.266571,0.084563,0.000000
57.610004,43.710197,-135.266571,0.006946,0.003306,0.083974,194.432663,9.904872,0.839736,-135.266571,0.084953,0.000000
57.840004,44.354401,-135.400009,0.006967,0.003321,0.084355,197.298233,10.050851,0.843551,-135.400009,0.085335,0.000000
58.070004,45.489014,-135.355530,0.006937,0.003339,0.084806,202.345245,10.307959,0.848059,-135.355530,0.085717,0.000000
58.300003,46.191681,-135.311050,0.006972,0.003353,0.085170,205.470856,10.467184,0.851704,-135.311050,0.086098,0.000000
58.530003,47.070114,-135.266571,0.006976,0.003372,0.085647,209.378326,10.666241,0.856473,-135.266571,0.086480,0.000000
58.760002,47.712822,-135.355530,0.006985,0.003386,0.085994,212.237228,10.811880,0.859940,-135.355530,0.086870,0.000000
58.990002,48.252022,-135.355530,0.006976,0.003400,0.086350,214.635712,10.934065,0.863497,-135.355530,0.087252,0.000000
59.220001,49.099167,-135.400009,0.006980,0.003414,0.086723,218.404007,11.126030,0.867225,-135.400009,0.087633,0.000000
59.450005,49.585114,-135.311050,0.007015,0.003428,0.087078,220.565598,11.236147,0.870783,-135.311050,0.088015,0.000000
59.680004,50.042389,-135.355530,0.007011,0.003438,0.087330,222.599670,11.339767,0.873296,-135.355530,0.088396,0.000000
59.910004,51.254829,-135.400009,0.007015,0.003458,0.087833,227.992874,11.614511,0.878327,-135.400009,0.088786,0.000000
60.140003,52.204384,-135.311050,0.007041,0.003475,0.088275,232.216690,11.829682,0.882751,-135.311050,0.089168,0.000000
60.370003,52.581596,-135.400009,0.007049,0.003486,0.088535,233.894623,11.915160,0.885351,-135.400009,0.089550,0.000000
60.600002,53.570618,-135.400009,0.007041,0.003503,0.088969,238.294006,12.139276,0.889689,-135.400009,0.089931,0.000000
60.830002,53.911339,-135.400009,0.007075,0.003513,0.089238,239.809616,12.216484,0.892376,-135.400009,0.090313,0.000000
61.060001,55.350182,-135.400009,0.007045,0.003534,0.089758,246.209900,12.542530,0.897580,-135.400009,0.090703,0.000000
61.290005,55.885658,-135.400009,0.007075,0.003545,0.090053,248.591827,12.663872,0.900529,-135.400009,0.091085,0.000000
61.520004,56.134026,-135.400009,0.007075,0.003552,0.090226,249.696609,12.720153,0.902262,-135.400009,0.091466,0.000000
61.750004,57.436958,-135.400009,0.007097,0.003574,0.090772,255.492355,13.015401,0.907724,-135.400009,0.091848,0.000000
61.980003,59.007629,-135.444489,0.007127,0.003595,0.091310,262.479034,13.371320,0.913102,-135.444489,0.092230,0.000000
62.210003,60.093468,-135.400009,0.007118,0.003612,0.091744,267.309082,13.617374,0.917440,-135.400009,0.092620,0.000000
62.440002,60.976357,-135.444489,0.007101,0.003627,0.092117,271.236389,13.817440,0.921168,-135.444489,0.093001,0.000000
62.670002,61.603806,-135.355530,0.007114,0.003639,0.092429,274.027405,13.959621,0.924290,-135.355530,0.093383,0.000000
62.900002,62.169441,-135.444489,0.007144,0.003650,0.092706,276.543488,14.087797,0.927065,-135.444489,0.093764,0.000000
63.130005,63.146172,-135.444489,0.007153,0.003666,0.093105,280.888214,14.309127,0.931054,-135.444489,0.094146,0.000000
63.360004,63.820915,-135.444489,0.007136,0.003678,0.093418,283.889618,14.462027,0.934176,-135.444489,0.094536,0.000000
63.590004,64.941017,-135.444489,0.007157,0.003696,0.093886,288.872070,14.715845,0.938858,-135.444489,0.094918,0.000000
63.820004,66.353416,-135.444489,0.007161,0.003716,0.094380,295.154724,15.035899,0.943801,-135.444489,0.095299,0.000000
64.050003,67.319359,-135.444489,0.007183,0.003722,0.094528,299.451477,15.254786,0.945278,-135.444489,0.094719,0.000000
64.280006,66.611839,-135.533463,0.007157,0.003721,0.094510,296.304260,15.094459,0.945103,-135.533463,0.094719,0.000000
64.510002,66.001900,-135.577942,0.007183,0.003721,0.094502,293.591125,14.956244,0.945016,-135.577942,0.094510,0.000000
64.740005,65.485420,-135.444489,0.007179,0.003721,0.094502,291.293701,14.839208,0.945016,-135.444489,0.094510,0.000000
64.970001,65.015114,-135.488983,0.007196,0.003720,0.094493,289.201660,14.732635,0.944929,-135.488983,0.094510,0.000000
65.200005,64.604012,-135.488983,0.007217,0.003720,0.094493,287.372986,14.639479,0.944929,-135.488983,0.094510,0.000000
65.430000,64.228661,-135.533463,0.007217,0.003720,0.094493,285.703339,14.554423,0.944929,-135.533463,0.094510,0.000000
65.660004,63.891670,-135.577942,0.007196,0.003720,0.094493,284.204346,14.478060,0.944929,-135.577942,0.094510,0.000000
65.889999,63.571053,-135.533463,0.007217,0.003720,0.094493,282.778168,14.405406,0.944929,-135.533463,0.094510,0.000000
66.120003,63.295128,-135.488983,0.007226,0.003720,0.094493,281.550781,14.342881,0.944929,-135.488983,0.094510,0.000000
66.350006,63.059036,-135.533463,0.007217,0.003720,0.094493,280.500610,14.289382,0.944929,-135.533463,0.094510,0.000000
66.580002,62.805824,-135.577942,0.007222,0.003720,0.094493,279.374268,14.232003,0.944929,-135.577942,0.094510,0.000000
66.810005,62.577187,-135.577942,0.007239,0.003720,0.094484,278.357239,14.180194,0.944842,-135.577942,0.094510,0.000000
67.040001,62.375732,-135.533463,0.007217,0.003720,0.094484,277.461121,14.134542,0.944842,-135.533463,0.094510,0.000000
67.270004,62.193275,-135.533463,0.007200,0.003720,0.094484,276.649506,14.093198,0.944842,-135.533463,0.094510,0.000000
67.500000,61.995544,-135.577942,0.007235,0.003720,0.094484,275.769958,14.048391,0.944842,-135.577942,0.094510,0.000000
67.730003,61.830582,-135.666901,0.007235,0.003720,0.094484,275.036163,14.011010,0.944842,-135.666901,0.094510,0.000000
67.960007,61.681633,-135.622421,0.007209,0.003720,0.094484,274.373596,13.977259,0.944842,-135.622421,0.094510,0.000000
68.190002,61.531197,-135.533463,0.007226,0.003720,0.094484,273.704437,13.943169,0.944842,-135.533463,0.094510,0.000000
68.420006,61.381126,-135.577942,0.007230,0.003720,0.094484,273.036896,13.909162,0.944842,-135.577942,0.094510,0.000000
68.650002,61.250801,-135.622421,0.007235,0.003720,0.094484,272.457184,13.879630,0.944842,-135.622421,0.094510,0.000000
68.880005,61.116371,-135.666901,0.007243,0.003720,0.094484,271.859192,13.849167,0.944842,-135.666901,0.094510,0.000000
69.110001,60.992371,-135.622421,0.007205,0.003720,0.094484,271.307617,13.821069,0.944842,-135.622421,0.094510,0.000000
69.340004,60.886620,-135.622421,0.007243,0.003720,0.094484,270.837219,13.797106,0.944842,-135.622421,0.094510,0.000000
69.570000,60.776024,-135.577942,0.007239,0.003720,0.094484,270.345245,13.772043,0.944842,-135.577942,0.094510,0.000000
69.800003,60.662079,-135.622421,0.007243,0.003720,0.094484,269.838409,13.746223,0.944842,-135.622421,0.094510,0.000000
70.030006,60.554832,-135.666901,0.007239,0.003720,0.094484,269.361359,13.721922,0.944842,-135.666901,0.094510,0.000000
70.260002,60.476639,-135.666901,0.007243,0.003720,0.094484,269.013519,13.704203,0.944842,-135.666901,0.094510,0.000000
70.490005,60.383171,-135.666901,0.007226,0.003720,0.094484,268.597748,13.683022,0.944842,-135.666901,0.094510,0.000000
70.720001,60.261406,-135.622421,0.007230,0.003720,0.094484,268.056122,13.655430,0.944842,-135.622421,0.094510,0.000000
70.950005,60.180969,-135.622421,0.007230,0.003720,0.094484,267.698334,13.637203,0.944842,-135.622421,0.094510,0.000000
71.180000,60.112083,-135.755859,0.007239,0.003720,0.094484,267.391907,13.621593,0.944842,-135.755859,0.094510,0.000000
71.410004,60.016380,-135.711380,0.007217,0.003720,0.094484,266.966187,13.599906,0.944842,-135.711380,0.094510,0.000000
71.640007,59.950104,-135.755859,0.007239,0.003720,0.094484,266.671387,13.584888,0.944842,-135.755859,0.094510,0.000000
71.870003,59.870789,-135.666901,0.007226,0.003720,0.094484,266.318573,13.566915,0.944842,-135.666901,0.094510,0.000000
72.100006,59.794075,-135.666901,0.007243,0.003720,0.094484,265.977325,13.549531,0.944842,-135.666901,0.094510,0.000000
72.330002,59.715134,-135.755859,0.007252,0.003720,0.094484,265.626190,13.531643,0.944842,-135.755859,0.094510,0.000000
72.560005,59.645874,-135.755859,0.007230,0.003720,0.094484,265.318085,13.515947,0.944842,-135.755859,0.094510,0.000000
72.790001,59.583687,-135.666901,0.007243,0.003720,0.094484,265.041473,13.501856,0.944842,-135.666901,0.094510,0.000000
73.020004,59.501762,-135.755859,0.007252,0.003720,0.094484,264.677063,13.483292,0.944842,-135.755859,0.094510,0.000000
73.250000,59.444794,-135.711380,0.007235,0.003720,0.094484,264.423645,13.470384,0.944842,-135.711380,0.094510,0.000000
73.480003,59.399361,-135.711380,0.007261,0.003720,0.094484,264.221558,13.460088,0.944842,-135.711380,0.094510,0.000000
73.710007,59.322281,-135.755859,0.007230,0.003720,0.094484,263.878693,13.442620,0.944842,-135.755859,0.094510,0.000000
73.940002,59.258980,-135.800339,0.007252,0.003720,0.094484,263.597107,13.428277,0.944842,-135.800339,0.094510,0.000000
74.170006,59.204613,-135.755859,0.007235,0.003720,0.094484,263.355255,13.415957,0.944842,-135.755859,0.094510,0.000000
74.400002,59.145035,-135.755859,0.007256,0.003720,0.094484,263.090240,13.402456,0.944842,-135.755859,0.094510,0.000000
74.630005,59.096626,-135.800339,0.007252,0.003720,0.094484,262.874908,13.391487,0.944842,-135.800339,0.094510,0.000000
74.860001,59.050819,-135.800339,0.007235,0.003720,0.094484,262.671173,13.381107,0.944842,-135.800339,0.094510,0.000000
75.090004,58.990868,-135.755859,0.007248,0.003720,0.094484,262.404480,13.367521,0.944842,-135.755859,0.094510,0.000000
75.320007,58.935760,-135.755859,0.007256,0.003720,0.094484,262.159363,13.355034,0.944842,-135.755859,0.094510,0.000000
75.550003,58.896286,-135.800339,0.007261,0.003720,0.094484,261.983765,13.346089,0.944842,-135.800339,0.094510,0.000000
75.780006,58.847504,-135.844818,0.007243,0.003720,0.094484,261.766785,13.335035,0.944842,-135.844818,0.094510,0.000000
76.010002,58.796494,-135.889313,0.007230,0.003720,0.094484,261.539856,13.323476,0.944842,-135.889313,0.094510,0.000000
76.240005,58.758881,-135.800339,0.007265,0.003720,0.094484,261.372559,13.314953,0.944842,-135.800339,0.094510,0.000000
76.470001,58.698555,-135.800339,0.007252,0.003720,0.094484,261.104218,13.301283,0.944842,-135.800339,0.094510,0.000000
76.700005,58.637863,-135.844818,0.007261,0.003720,0.094484,260.834229,13.287529,0.944842,-135.844818,0.094510,0.000000
76.930000,58.625198,-135.889313,0.007252,0.003720,0.094484,260.777893,13.284659,0.944842,-135.889313,0.094510,0.000000
77.160004,58.574928,-135.844818,0.007226,0.003720,0.094484,260.554291,13.273269,0.944842,-135.844818,0.094510,0.000000
77.390007,58.520561,-135.844818,0.007252,0.003720,0.094484,260.312469,13.260949,0.944842,-135.844818,0.094510,0.000000
77.620003,58.477737,-135.800339,0.007256,0.003720,0.094484,260.121979,13.251245,0.944842,-135.800339,0.094510,0.000000
77.850006,58.443855,-135.889313,0.007252,0.003720,0.094484,259.971252,13.243567,0.944842,-135.889313,0.094510,0.000000
78.080002,58.407364,-135.844818,0.007256,0.003720,0.094484,259.808929,13.235298,0.944842,-135.844818,0.094510,0.000000
78.310005,58.361191,-135.889313,0.007252,0.003720,0.094484,259.603546,13.224834,0.944842,-135.889313,0.094510,0.000000
78.540001,58.323952,-135.844818,0.007239,0.003720,0.094484,259.437897,13.216396,0.944842,-135.844818,0.094510,0.000000
78.770004,58.282990,-135.889313,0.007248,0.003720,0.094484,259.255676,13.207114,0.944842,-135.889313,0.094510,0.000000
79.000000,58.237930,-135.889313,0.007274,0.003720,0.094484,259.055267,13.196903,0.944842,-135.889313,0.094510,0.000000
79.230003,58.204422,-135.889313,0.007261,0.003720,0.094484,258.906189,13.189310,0.944842,-135.889313,0.094510,0.000000
79.460007,58.177979,-135.933792,0.007256,0.003720,0.094484,258.788574,13.183318,0.944842,-135.933792,0.094510,0.000000
79.690002,58.139999,-135.844818,0.007248,0.003720,0.094484,258.619629,13.174712,0.944842,-135.844818,0.094510,0.000000
79.920006,58.111328,-135.889313,0.007295,0.003720,0.094484,258.492096,13.168216,0.944842,-135.889313,0.094510,0.000000
80.150002,58.093826,-135.889313,0.007265,0.003720,0.094484,258.414246,13.164249,0.944842,-135.889313,0.094510,0.000000
80.380005,58.062920,-135.933792,0.007252,0.003720,0.094484,258.276764,13.157246,0.944842,-135.933792,0.094510,0.000000
80.610001,58.003708,-135.978271,0.007243,0.003720,0.094484,258.013367,13.143828,0.944842,-135.978271,0.094510,0.000000
80.840004,57.971313,-135.978271,0.007243,0.003720,0.094484,257.869293,13.136487,0.944842,-135.978271,0.094510,0.000000
81.070007,57.964981,-135.933792,0.007252,0.003720,0.094484,257.841125,13.135052,0.944842,-135.933792,0.094510,0.000000
81.300003,57.926254,-135.933792,0.007252,0.003720,0.094484,257.668854,13.126277,0.944842,-135.933792,0.094510,0.000000
81.530006,57.896469,-136.022751,0.007274,0.003720,0.094484,257.536346,13.119527,0.944842,-136.022751,0.094510,0.000000
81.760002,57.862206,-135.933792,0.007252,0.003720,0.094484,257.383942,13.111763,0.944842,-135.933792,0.094510,0.000000
81.990005,57.831299,-135.978271,0.007261,0.003720,0.094484,257.246460,13.104759,0.944842,-135.978271,0.094510,0.000000
82.220001,57.790344,-136.022751,0.007261,0.003720,0.094484,257.064301,13.095479,0.944842,-136.022751,0.094510,0.000000
82.450005,57.786987,-136.022751,0.007243,0.003720,0.094484,257.049347,13.094719,0.944842,-136.022751,0.094510,0.000000
82.680000,57.753479,-136.022751,0.007239,0.003720,0.094484,256.900299,13.087126,0.944842,-136.022751,0.094510,0.000000
82.910004,57.707672,-135.978271,0.007222,0.003720,0.094484,256.696533,13.076745,0.944842,-135.978271,0.094510,0.000000
83.140007,57.690918,-135.933792,0.007252,0.003720,0.094484,256.622009,13.072948,0.944842,-135.933792,0.094510,0.000000
83.370003,57.661873,-135.933792,0.007243,0.003720,0.094484,256.492828,13.066367,0.944842,-135.933792,0.094510,0.000000
83.600006,57.639160,-135.978271,0.007261,0.003720,0.094484,256.391785,13.061220,0.944842,-135.978271,0.094510,0.000000
83.830002,57.595215,-136.022751,0.007248,0.003720,0.094484,256.196320,13.051262,0.944842,-136.022751,0.094510,0.000000
84.060005,57.582932,-136.022751,0.007252,0.003720,0.094484,256.141663,13.048478,0.944842,-136.022751,0.094510,0.000000
84.290001,57.564308,-135.978271,0.007239,0.003720,0.094484,256.058838,13.044259,0.944842,-135.978271,0.094510,0.000000
84.520004,57.525955,-135.978271,0.007269,0.003720,0.094484,255.888229,13.035568,0.944842,-135.978271,0.094510,0.000000
84.750008,57.493187,-136.022751,0.007261,0.003720,0.094484,255.742462,13.028142,0.944842,-136.022751,0.094510,0.000000
84.980003,57.469353,-136.111710,0.007261,0.003720,0.094484,255.636444,13.022741,0.944842,-136.111710,0.094510,0.000000
85.210007,57.451859,-136.022751,0.007243,0.003720,0.094484,255.558624,13.018778,0.944842,-136.022751,0.094510,0.000000
85.440002,57.428024,-136.067230,0.007252,0.003720,0.094484,255.452606,13.013376,0.944842,-136.067230,0.094510,0.000000
85.670006,57.397491,-136.067230,0.007265,0.003720,0.094484,255.316788,13.006457,0.944842,-136.067230,0.094510,0.000000
85.900002,57.381477,-136.067230,0.007243,0.003720,0.094484,255.245560,13.002829,0.944842,-136.067230,0.094510,0.000000
86.130005,57.344612,-136.067230,0.007261,0.003720,0.094484,255.081573,12.994474,0.944842,-136.067230,0.094510,0.000000
86.360001,57.319290,-136.111710,0.007256,0.003720,0.094484,254.968933,12.988737,0.944842,-136.111710,0.094510,0.000000
86.590004,57.304771,-136.067230,0.007239,0.003720,0.094484,254.904358,12.985447,0.944842,-136.067230,0.094510,0.000000
86.820007,57.263809,-136.111710,0.007248,0.003720,0.094484,254.722153,12.976165,0.944842,-136.111710,0.094510,0.000000
87.050003,57.235878,-136.067230,0.007261,0.003720,0.094484,254.597900,12.969835,0.944842,-136.067230,0.094510,0.000000
87.280006,57.228432,-136.156189,0.007265,0.003720,0.094484,254.564774,12.968148,0.944842,-136.156189,0.094510,0.000000
87.510002,57.216141,-136.156189,0.007261,0.003720,0.094484,254.510101,12.965363,0.944842,-136.156189,0.094510,0.000000
87.740005,57.187096,-136.111710,0.007252,0.003720,0.094484,254.380905,12.958781,0.944842,-136.111710,0.094510,0.000000
87.970001,57.144646,-136.111710,0.007274,0.003720,0.094484,254.192078,12.949162,0.944842,-136.111710,0.094510,0.000000
88.200005,57.129753,-136.156189,0.007248,0.003720,0.094484,254.125839,12.945787,0.944842,-136.156189,0.094510,0.000000
88.430008,57.114113,-136.156189,0.007252,0.003720,0.094484,254.056259,12.942243,0.944842,-136.156189,0.094510,0.000000
88.660004,57.091774,-136.156189,0.007252,0.003720,0.094484,253.956894,12.937181,0.944842,-136.156189,0.094510,0.000000
88.890007,57.051186,-136.156189,0.007248,0.003720,0.094484,253.776352,12.927983,0.944842,-136.156189,0.094510,0.000000
89.120003,57.049690,-136.156189,0.007248,0.003720,0.094484,253.769699,12.927645,0.944842,-136.156189,0.094510,0.000000
89.350006,57.024002,-136.156189,0.007269,0.003720,0.094484,253.655426,12.921824,0.944842,-136.156189,0.094510,0.000000
89.580002,56.997932,-136.156189,0.007261,0.003720,0.094484,253.539459,12.915916,0.944842,-136.156189,0.094510,0.000000
89.810005,56.977821,-136.200668,0.007252,0.003720,0.094484,253.450012,12.911359,0.944842,-136.200668,0.094510,0.000000
90.040001,56.973358,-136.200668,0.007243,0.003720,0.094484,253.430161,12.910348,0.944842,-136.200668,0.094510,0.000000
90.270004,56.936867,-136.111710,0.007252,0.003720,0.094484,253.267838,12.902079,0.944842,-136.111710,0.094510,0.000000
90.500008,56.922340,-136.200668,0.007269,0.003720,0.094484,253.203217,12.898787,0.944842,-136.200668,0.094510,0.000000
90.730003,56.907074,-136.200668,0.007265,0.003720,0.094484,253.135315,12.895328,0.944842,-136.200668,0.094510,0.000000
90.960007,56.898140,-136.200668,0.007252,0.003720,0.094484,253.095566,12.893303,0.944842,-136.200668,0.094510,0.000000
91.190002,56.867973,-136.156189,0.007269,0.003720,0.094484,252.961380,12.886467,0.944842,-136.156189,0.094510,0.000000
91.420006,56.844513,-136.200668,0.007252,0.003720,0.094484,252.857025,12.881151,0.944842,-136.200668,0.094510,0.000000
91.650002,56.832230,-136.245148,0.007248,0.003720,0.094484,252.802383,12.878367,0.944842,-136.245148,0.094510,0.000000
91.880005,56.812866,-136.200668,0.007256,0.003720,0.094484,252.716248,12.873980,0.944842,-136.200668,0.094510,0.000000
92.110001,56.793869,-136.289627,0.007256,0.003720,0.094484,252.631744,12.869675,0.944842,-136.289627,0.094510,0.000000
92.340004,56.775627,-136.245148,0.007261,0.003720,0.094484,252.550598,12.865541,0.944842,-136.245148,0.094510,0.000000
92.570007,56.766319,-136.200668,0.007278,0.003720,0.094484,252.509201,12.863431,0.944842,-136.200668,0.094510,0.000000
92.800003,56.738762,-136.289627,0.007282,0.003720,0.094484,252.386612,12.857187,0.944842,-136.289627,0.094510,0.000000
93.030006,56.726845,-136.289627,0.007256,0.003720,0.094484,252.333603,12.854486,0.944842,-136.289627,0.094510,0.000000
93.260002,56.711205,-136.245148,0.007256,0.003720,0.094484,252.264038,12.850943,0.944842,-136.245148,0.094510,0.000000
93.490005,56.688866,-136.289627,0.007274,0.003720,0.094484,252.164673,12.845881,0.944842,-136.289627,0.094510,0.000000
93.720001,56.662796,-136.289627,0.007252,0.003720,0.094484,252.048706,12.839972,0.944842,-136.289627,0.094510,0.000000
93.950005,56.649017,-136.289627,0.007278,0.003720,0.094484,251.987411,12.836851,0.944842,-136.289627,0.094510,0.000000
94.180008,56.644180,-136.334122,0.007256,0.003720,0.094484,251.965897,12.835755,0.944842,-136.334122,0.094510,0.000000
94.410004,56.612152,-136.334122,0.007261,0.003720,0.094484,251.823425,12.828497,0.944842,-136.334122,0.094510,0.000000
94.500008,56.609177,-136.289627,0.007265,0.003720,0.094484,251.810196,12.827824,0.944842,-136.289627,0.094510,0.000000