File: Data/Compression Sample NH 10, 12, 15, 17 batch 3/AutoNoheatingFS-15-3-1-240215_02152024_162737.csv
Time (sec),S:Load (lbs),S:HL1 (DIM),S:LVDT (in),S:Position (in),Ch:Position (mm),Ch:Load (N),Ch:Stress (MPa),Ch:Strain (mm/mm),Ch:HL1 (DIM),Set Point (),Cycles ()
0.010000,-0.014893,-29.223986,0.000009,-0.000000,-0.000000,-0.066245,-0.003375,-0.000000,-29.223986,0.000191,0.000000
0.280000,-0.022713,-29.268465,0.000009,-0.000000,-0.000000,-0.101031,-0.005147,-0.000000,-29.268465,0.000191,0.000000
0.550000,-0.019730,-29.312946,-0.000009,0.000101,0.002567,-0.087762,-0.004471,0.025669,-29.312946,0.003556,0.000000
0.820000,-0.031273,-29.179504,0.000134,0.000273,0.006938,-0.139109,-0.007087,0.069377,-29.179504,0.008048,0.000000
1.090000,-0.056229,-29.268465,0.000310,0.000446,0.011335,-0.250117,-0.012742,0.113346,-29.268465,0.012557,0.000000
1.360000,0.008568,-29.223986,0.000479,0.000620,0.015749,0.038112,0.001941,0.157486,-29.223986,0.017049,0.000000
1.630000,-0.026436,-29.312946,0.000681,0.000804,0.020432,-0.117593,-0.005990,0.204316,-29.312946,0.021559,0.000000
1.900000,-0.012283,-29.268465,0.000849,0.000979,0.024855,-0.054639,-0.002783,0.248546,-29.268465,0.026051,0.000000
2.170000,-0.017502,-29.223986,0.001035,0.001154,0.029303,-0.077852,-0.003966,0.293034,-29.223986,0.030544,0.000000
2.440000,-0.044685,-29.268465,0.001233,0.001331,0.033813,-0.198770,-0.010126,0.338131,-29.268465,0.035053,0.000000
2.710000,-0.018990,-29.268465,0.001397,0.001505,0.038227,-0.084470,-0.004303,0.382271,-29.268465,0.039545,0.000000
2.980000,-0.027550,-29.268465,0.001574,0.001690,0.042936,-0.122547,-0.006243,0.429362,-29.268465,0.044038,0.000000
3.250000,0.003723,-29.357428,0.001763,0.001866,0.047402,0.016561,0.000844,0.474024,-29.357428,0.048547,0.000000
3.520000,0.001495,-29.312946,0.001957,0.002037,0.051730,0.006652,0.000339,0.517301,-29.312946,0.053039,0.000000
3.790000,-0.023087,-29.268465,0.002147,0.002220,0.056387,-0.102694,-0.005231,0.563870,-29.268465,0.057532,0.000000
4.060000,0.002983,-29.268465,0.002311,0.002391,0.060740,0.013269,0.000676,0.607404,-29.268465,0.062041,0.000000
4.330000,0.005585,-29.357428,0.002492,0.002575,0.065406,0.024842,0.001266,0.654060,-29.357428,0.066534,0.000000
4.600000,-0.013405,-29.357428,0.002686,0.002751,0.069872,-0.059628,-0.003038,0.698722,-29.357428,0.071026,0.000000
4.870000,-0.031273,-29.312946,0.002867,0.002923,0.074234,-0.139109,-0.007087,0.742343,-29.312946,0.075535,0.000000
5.140000,-0.055855,-29.312946,0.003065,0.003103,0.078822,-0.248455,-0.012657,0.788220,-29.312946,0.080027,0.000000
5.410000,0.001495,-29.312946,0.003212,0.003281,0.083332,0.006652,0.000339,0.833317,-29.312946,0.084520,0.000000
5.680000,0.001122,-29.357428,0.003423,0.003462,0.087928,0.004989,0.000254,0.879280,-29.357428,0.089029,0.000000
5.950000,-0.002228,-29.446390,0.003591,0.003640,0.092446,-0.009910,-0.000505,0.924461,-29.446390,0.093521,0.000000
6.220000,-0.003723,-29.357428,0.003764,0.003804,0.096626,-0.016561,-0.000844,0.966261,-29.357428,0.098014,0.000000
6.490000,-0.031647,-29.268465,0.003980,0.003992,0.101387,-0.140772,-0.007171,1.013871,-29.268465,0.102523,0.000000
6.760000,-0.000366,-29.357428,0.004143,0.004166,0.105819,-0.001629,-0.000083,1.058189,-29.357428,0.107016,0.000000
7.030000,-0.020851,-29.401909,0.004324,0.004344,0.110346,-0.092750,-0.004725,1.103456,-29.401909,0.111508,0.000000
7.300000,-0.065536,-29.401909,0.004506,0.004517,0.114725,-0.291521,-0.014851,1.147251,-29.401909,0.116017,0.000000
7.570000,0.028305,-29.401909,0.004674,0.004695,0.119261,0.125907,0.006414,1.192609,-29.401909,0.120510,0.000000
7.840000,-0.023087,-29.312946,0.004872,0.004875,0.123822,-0.102694,-0.005231,1.238225,-29.312946,0.125002,0.000000
8.110001,0.001122,-29.357428,0.005057,0.005054,0.128367,0.004989,0.000254,1.283666,-29.357428,0.129512,0.000000
8.380000,0.004845,-29.401909,0.005221,0.005229,0.132807,0.021550,0.001098,1.328067,-29.401909,0.134003,0.000000
8.650001,-0.009682,-29.446390,0.005433,0.005408,0.137360,-0.043066,-0.002194,1.373599,-29.446390,0.138496,0.000000
8.920000,0.008194,-29.401909,0.005592,0.005579,0.141705,0.036449,0.001857,1.417046,-29.401909,0.143005,0.000000
9.190001,-0.027924,-29.446390,0.005795,0.005759,0.146284,-0.124210,-0.006328,1.462835,-29.446390,0.147498,0.000000
9.460000,-0.010422,-29.446390,0.005967,0.005929,0.150602,-0.046358,-0.002362,1.506025,-29.446390,0.151990,0.000000
9.730000,0.003357,-29.446390,0.006153,0.006117,0.155364,0.014932,0.000761,1.553635,-29.446390,0.156499,0.000000
10.000000,-0.011909,-29.490871,0.006342,0.006291,0.159786,-0.052976,-0.002699,1.597862,-29.490871,0.160992,0.000000
10.270000,0.025322,-29.490871,0.006528,0.006466,0.164244,0.112638,0.005738,1.642436,-29.490871,0.165484,0.000000
10.540001,0.011177,-29.446390,0.006722,0.006649,0.168892,0.049718,0.002533,1.688922,-29.446390,0.169994,0.000000
10.810000,0.012291,-29.446390,0.006890,0.006826,0.173393,0.054673,0.002785,1.733929,-29.446390,0.174486,0.000000
11.080001,-0.010796,-29.490871,0.007067,0.006995,0.177686,-0.048021,-0.002446,1.776857,-29.490871,0.178978,0.000000
11.350000,-0.049149,-29.490871,0.007252,0.007173,0.182204,-0.218624,-0.011137,1.822041,-29.490871,0.183488,0.000000
11.620001,-0.016380,-29.490871,0.007416,0.007349,0.186670,-0.072863,-0.003712,1.866703,-29.490871,0.187980,0.000000
11.890000,0.017136,-29.535351,0.007627,0.007534,0.191353,0.076223,0.003883,1.913533,-29.535351,0.192472,0.000000
12.160001,0.012291,-29.490871,0.007782,0.007710,0.195837,0.054673,0.002785,1.958369,-29.490871,0.196981,0.000000
12.430000,0.035751,-29.579832,0.007981,0.007887,0.200338,0.159030,0.008101,2.003375,-29.579832,0.201474,0.000000
12.700001,0.017136,-29.579832,0.008157,0.008064,0.204821,0.076223,0.003883,2.048211,-29.579832,0.205983,0.000000
12.970000,0.007454,-29.579832,0.008343,0.008241,0.209313,0.033157,0.001689,2.093134,-29.579832,0.210476,0.000000
13.240001,0.008568,-29.490871,0.008537,0.008421,0.213884,0.038112,0.001941,2.138837,-29.490871,0.214968,0.000000
13.510000,-0.024948,-29.579832,0.008683,0.008588,0.218142,-0.110975,-0.005653,2.181417,-29.579832,0.219477,0.000000
13.780001,0.000374,-29.579832,0.008877,0.008769,0.222729,0.001663,0.000085,2.227293,-29.579832,0.223970,0.000000
14.050000,-0.000366,-29.579832,0.009071,0.008947,0.227265,-0.001629,-0.000083,2.272651,-29.579832,0.228462,0.000000
14.320001,0.010429,-29.579832,0.009248,0.009128,0.231853,0.046392,0.002363,2.318528,-29.579832,0.232971,0.000000
14.590001,0.039848,-29.535351,0.009447,0.009306,0.236362,0.177254,0.009030,2.363621,-29.535351,0.237464,0.000000
14.860001,0.021225,-29.579832,0.009623,0.009483,0.240881,0.094413,0.004810,2.408806,-29.579832,0.241956,0.000000
15.130001,0.011543,-29.579832,0.009796,0.009654,0.245208,0.051347,0.002616,2.452078,-29.579832,0.246466,0.000000
15.400001,-0.013405,-29.668795,0.009981,0.009835,0.249804,-0.059628,-0.003038,2.498042,-29.668795,0.250958,0.000000
15.670001,-0.005585,-29.624313,0.010162,0.010008,0.254210,-0.024842,-0.001266,2.542098,-29.624313,0.255450,0.000000
15.940001,-0.010048,-29.579832,0.010343,0.010190,0.258832,-0.044695,-0.002277,2.588319,-29.579832,0.259959,0.000000
16.210001,0.012291,-29.624313,0.010520,0.010363,0.263220,0.054673,0.002785,2.632201,-29.624313,0.264452,0.000000
16.480001,0.046181,-29.624313,0.010714,0.010539,0.267686,0.205422,0.010465,2.676863,-29.624313,0.268944,0.000000
16.750000,0.011177,-29.624313,0.010891,0.010722,0.272335,0.049718,0.002533,2.723349,-29.624313,0.273453,0.000000
17.020000,0.023834,-29.668795,0.011068,0.010901,0.276896,0.106020,0.005401,2.768965,-29.668795,0.277946,0.000000
17.290001,0.014153,-29.579832,0.011249,0.011076,0.281319,0.062954,0.003207,2.813191,-29.579832,0.282438,0.000000
17.560001,-0.008934,-29.624313,0.011426,0.011249,0.285725,-0.039741,-0.002024,2.857248,-29.624313,0.286948,0.000000
17.830000,0.011917,-29.624313,0.011602,0.011423,0.290147,0.053010,0.002700,2.901474,-29.624313,0.291440,0.000000
18.100000,-0.008560,-29.668795,0.011788,0.011608,0.294839,-0.038078,-0.001940,2.948391,-29.668795,0.295932,0.000000
18.370001,0.014153,-29.624313,0.011969,0.011782,0.299262,0.062954,0.003207,2.992622,-29.624313,0.300442,0.000000
18.640001,0.038727,-29.624313,0.012146,0.011958,0.303746,0.172265,0.008776,3.037458,-29.624313,0.304934,0.000000
18.910002,0.012665,-29.668795,0.012340,0.012137,0.308290,0.056336,0.002870,3.082899,-29.668795,0.309426,0.000000
19.180000,0.040588,-29.668795,0.012503,0.012312,0.312722,0.180546,0.009197,3.127217,-29.668795,0.313935,0.000000
19.450001,0.005219,-29.713276,0.012710,0.012494,0.317344,0.023213,0.001183,3.173438,-29.713276,0.318428,0.000000
19.720001,0.008942,-29.668795,0.012883,0.012667,0.321732,0.039774,0.002026,3.217320,-29.668795,0.322920,0.000000
19.990002,-0.009682,-29.668795,0.013038,0.012840,0.326146,-0.043066,-0.002194,3.261463,-29.668795,0.327430,0.000000
20.260000,-0.018616,-29.713276,0.013232,0.013024,0.330803,-0.082807,-0.004218,3.308032,-29.713276,0.331922,0.000000
20.530001,0.038361,-29.757757,0.013430,0.013200,0.335287,0.170636,0.008693,3.352868,-29.757757,0.336414,0.000000
20.800001,0.037239,-29.757757,0.013599,0.013377,0.339770,0.165648,0.008438,3.397704,-29.757757,0.340924,0.000000
21.070002,0.021225,-29.757757,0.013784,0.013555,0.344288,0.094413,0.004810,3.442884,-29.757757,0.345416,0.000000
21.340000,0.023087,-29.668795,0.013961,0.013726,0.348633,0.102694,0.005231,3.486331,-29.668795,0.349908,0.000000
21.610001,0.009682,-29.713276,0.014146,0.013908,0.353256,0.043066,0.002194,3.532556,-29.713276,0.354418,0.000000
21.880001,0.017136,-29.757757,0.014314,0.014085,0.357757,0.076223,0.003883,3.577566,-29.757757,0.358910,0.000000
22.150002,0.007820,-29.757757,0.014500,0.014263,0.362275,0.034786,0.001772,3.622746,-29.757757,0.363402,0.000000
22.420002,-0.000000,-29.757757,0.014681,0.014438,0.366732,-0.000000,-0.000000,3.667321,-29.757757,0.367912,0.000000
22.690001,0.036865,-29.757757,0.014857,0.014612,0.371138,0.163985,0.008354,3.711377,-29.757757,0.372404,0.000000
22.960001,0.000748,-29.757757,0.015039,0.014796,0.375829,0.003326,0.000169,3.758295,-29.757757,0.376896,0.000000
23.230001,0.035378,-29.802237,0.015220,0.014972,0.380296,0.157367,0.008017,3.802957,-29.802237,0.381406,0.000000
23.500002,0.038361,-29.846718,0.015392,0.015148,0.384753,0.170636,0.008693,3.847531,-29.846718,0.385898,0.000000
23.770000,0.013405,-29.757757,0.015590,0.015323,0.389211,0.059628,0.003038,3.892106,-29.757757,0.390390,0.000000
24.040001,0.031281,-29.802237,0.015750,0.015497,0.393616,0.139143,0.007088,3.936162,-29.802237,0.394900,0.000000
24.310001,-0.007820,-29.757757,0.015948,0.015678,0.398221,-0.034786,-0.001772,3.982213,-29.757757,0.399392,0.000000
24.580002,0.037613,-29.891199,0.016129,0.015856,0.402748,0.167311,0.008523,4.027480,-29.891199,0.403902,0.000000
24.850000,0.029793,-29.846718,0.016293,0.016031,0.407197,0.132525,0.006751,4.071972,-29.846718,0.408394,0.000000
25.120001,0.006706,-29.802237,0.016487,0.016212,0.411793,0.029831,0.001520,4.117932,-29.802237,0.412886,0.000000
25.390001,0.046181,-29.802237,0.016677,0.016383,0.416121,0.205422,0.010465,4.161208,-29.802237,0.417396,0.000000
25.660002,0.021973,-29.802237,0.016849,0.016566,0.420786,0.097739,0.004979,4.207865,-29.802237,0.421888,0.000000
25.930000,0.020485,-29.891199,0.017022,0.016739,0.425175,0.091121,0.004642,4.251747,-29.891199,0.426380,0.000000
26.200001,0.007820,-29.891199,0.017216,0.016914,0.429623,0.034786,0.001772,4.296234,-29.891199,0.430889,0.000000
26.470001,-0.024574,-29.802237,0.017397,0.017092,0.434133,-0.109312,-0.005569,4.341331,-29.802237,0.435382,0.000000
26.740002,0.048782,-29.846718,0.017574,0.017271,0.438695,0.216995,0.011054,4.386947,-29.846718,0.439874,0.000000
27.010002,0.051392,-29.802237,0.017759,0.017451,0.443256,0.228601,0.011646,4.432562,-29.802237,0.444384,0.000000
27.280001,0.030167,-29.935680,0.017936,0.017630,0.447792,0.134188,0.006836,4.477921,-29.935680,0.448876,0.000000
27.550001,0.042084,-29.891199,0.018126,0.017798,0.452076,0.187198,0.009536,4.520758,-29.891199,0.453368,0.000000
27.820002,0.008568,-29.757757,0.018298,0.017981,0.456716,0.038112,0.001941,4.567157,-29.757757,0.457878,0.000000
28.090002,0.026070,-29.846718,0.018462,0.018152,0.461052,0.115964,0.005907,4.610517,-29.846718,0.462370,0.000000
28.360001,0.013779,-29.980162,0.018647,0.018337,0.465752,0.061291,0.003122,4.657521,-29.980162,0.466862,0.000000
28.630001,-0.024948,-29.935680,0.018820,0.018505,0.470028,-0.110975,-0.005653,4.700275,-29.935680,0.471372,0.000000
28.900002,0.039848,-29.891199,0.019018,0.018686,0.474633,0.177254,0.009030,4.746326,-29.891199,0.475864,0.000000
29.170002,0.024208,-29.891199,0.019208,0.018867,0.479220,0.107683,0.005486,4.792203,-29.891199,0.480356,0.000000
29.440001,0.042450,-29.846718,0.019380,0.019045,0.483738,0.188827,0.009619,4.837383,-29.846718,0.484866,0.000000
29.710001,0.056229,-29.891199,0.019557,0.019221,0.488213,0.250117,0.012742,4.882132,-29.891199,0.489358,0.000000
29.980001,0.013779,-29.980162,0.019734,0.019392,0.492558,0.061291,0.003122,4.925579,-29.980162,0.493850,0.000000
30.250002,0.032402,-29.935680,0.019915,0.019570,0.497076,0.144131,0.007342,4.970763,-29.935680,0.498360,0.000000
30.520002,-0.005585,-29.935680,0.020087,0.019750,0.501638,-0.024842,-0.001266,5.016379,-29.935680,0.502852,0.000000
30.790001,0.014900,-29.980162,0.020256,0.019923,0.506035,0.066279,0.003376,5.060348,-29.980162,0.507344,0.000000
31.060001,0.042450,-29.980162,0.020441,0.020106,0.510683,0.188827,0.009619,5.106830,-29.980162,0.511854,0.000000
31.330002,0.032028,-29.980162,0.020635,0.020283,0.515184,0.142469,0.007258,5.151840,-29.980162,0.516346,0.000000
31.600002,0.058464,-29.980162,0.020807,0.020456,0.519590,0.260061,0.013248,5.195896,-29.980162,0.520838,0.000000
31.870001,0.046181,-29.980162,0.020997,0.020637,0.524177,0.205422,0.010465,5.241773,-29.980162,0.525348,0.000000
32.140003,0.034630,-29.935680,0.021174,0.020814,0.528669,0.154041,0.007847,5.286692,-29.935680,0.529840,0.000000
32.410000,0.033516,-29.980162,0.021355,0.020988,0.533101,0.149086,0.007595,5.331009,-29.980162,0.534332,0.000000
32.680000,-0.012657,-29.980162,0.021532,0.021164,0.537558,-0.056302,-0.002868,5.375584,-29.980162,0.538842,0.000000
32.950001,0.046547,-29.980162,0.021696,0.021339,0.542016,0.207051,0.010548,5.420159,-29.980162,0.543334,0.000000
33.220001,0.086395,-29.980162,0.021890,0.021520,0.546612,0.384305,0.019577,5.466123,-29.980162,0.547826,0.000000
33.490002,0.166824,-30.024641,0.022049,0.021702,0.551226,0.742072,0.037803,5.512260,-30.024641,0.552336,0.000000
33.760002,0.666550,-30.069122,0.022161,-0.000000,-0.000000,2.964961,0.151042,-0.000000,-30.069122,0.000234,0.000000
34.030003,0.642342,-30.024641,0.022161,-0.000000,-0.000000,2.857278,0.145557,-0.000000,-30.024641,0.000234,0.000000
34.300003,0.757782,-30.069122,0.022170,-0.000000,-0.000000,3.370783,0.171716,-0.000000,-30.069122,0.000442,0.000000
34.570004,0.691872,-29.935680,0.022153,-0.000000,-0.000000,3.077599,0.156780,-0.000000,-29.935680,0.000893,0.000000
34.840000,0.891090,-30.024641,0.022170,0.000019,0.000494,3.963768,0.201924,0.004943,-30.024641,0.001344,0.000000
35.110001,1.124939,-30.069122,0.022183,0.000034,0.000867,5.003978,0.254915,0.008671,-30.069122,0.001795,0.000000
35.380001,1.326393,-30.069122,0.022204,0.000051,0.001301,5.900091,0.300565,0.013009,-30.069122,0.002246,0.000000
35.650002,1.542740,-30.113604,0.022209,0.000066,0.001682,6.862450,0.349590,0.016824,-30.113604,0.002688,0.000000
35.920002,1.737495,-30.113604,0.022230,0.000080,0.002038,7.728765,0.393722,0.020382,-30.113604,0.003139,0.000000
36.190002,2.230515,-30.069122,0.022247,0.000108,0.002740,9.921824,0.505442,0.027403,-30.069122,0.003590,0.000000
36.460003,2.466225,-30.113604,0.022256,0.000124,0.003139,10.970315,0.558855,0.031392,-30.113604,0.004041,0.000000
36.730003,2.760399,-30.069122,0.022286,0.000140,0.003564,12.278868,0.625515,0.035642,-30.069122,0.004492,0.000000
37.000000,3.110802,-30.113604,0.022299,0.000158,0.004024,13.837537,0.704918,0.040241,-30.113604,0.004943,0.000000
37.270000,3.454132,-30.113604,0.022303,0.000177,0.004501,15.364747,0.782718,0.045010,-30.113604,0.005394,0.000000
37.540001,3.680534,-30.113604,0.022316,0.000192,0.004874,16.371834,0.834021,0.048738,-30.113604,0.005845,0.000000
37.810001,3.781075,-30.158085,0.022338,0.000199,0.005065,16.819059,0.856804,0.050646,-30.158085,0.006296,0.000000
38.080002,4.343353,-30.113604,0.022360,0.000229,0.005828,19.320200,0.984218,0.058276,-30.113604,0.006738,0.000000
38.350002,4.424904,-30.158085,0.022372,0.000241,0.006114,19.682955,1.002698,0.061141,-30.158085,0.007189,0.000000
38.620003,4.773445,-30.069122,0.022385,0.000263,0.006686,21.233345,1.081678,0.066864,-30.069122,0.007640,0.000000
38.890003,4.920158,-30.069122,0.022394,0.000277,0.007024,21.885958,1.114924,0.070244,-30.069122,0.008091,0.000000
39.160004,5.314133,-30.202566,0.022424,0.000299,0.007606,23.638443,1.204200,0.076057,-30.202566,0.008542,0.000000
39.430000,5.439995,-30.158085,0.022441,0.000315,0.007996,24.198305,1.232720,0.079960,-30.158085,0.008993,0.000000
39.700001,5.597130,-30.202566,0.022450,0.000327,0.008317,24.897278,1.268328,0.083165,-30.202566,0.009444,0.000000
39.970001,5.881256,-30.202566,0.022467,0.000351,0.008915,26.161133,1.332712,0.089149,-30.202566,0.009895,0.000000
40.240002,6.047707,-30.158085,0.022480,0.000365,0.009271,26.901543,1.370430,0.092707,-30.158085,0.010346,0.000000
40.510002,6.230911,-30.158085,0.022497,0.000386,0.009817,27.716478,1.411945,0.098169,-30.158085,0.010788,0.000000
40.780003,6.321396,-30.202566,0.022523,0.000401,0.010190,28.118973,1.432449,0.101901,-30.202566,0.011239,0.000000
41.050003,6.488220,-30.158085,0.022536,0.000420,0.010676,28.861046,1.470252,0.106757,-30.158085,0.011690,0.000000
41.320004,6.702332,-30.202566,0.022554,0.000437,0.011100,29.813459,1.518770,0.111003,-30.202566,0.012141,0.000000
41.590000,6.822983,-30.247047,0.022571,0.000453,0.011499,30.350143,1.546110,0.114993,-30.247047,0.012592,0.000000
41.860001,7.148811,-30.247047,0.022588,0.000477,0.012106,31.799501,1.619944,0.121064,-30.247047,0.013043,0.000000
42.130001,7.217697,-30.202566,0.022614,0.000493,0.012531,32.105919,1.635554,0.125314,-30.202566,0.013494,0.000000
42.400002,7.249725,-30.202566,0.022623,0.000510,0.012948,32.248390,1.642811,0.129477,-30.202566,0.013945,0.000000
42.670002,7.369255,-30.158085,0.022644,0.000526,0.013364,32.780083,1.669897,0.133641,-30.158085,0.014396,0.000000
42.940002,7.641830,-30.291527,0.022661,0.000548,0.013919,33.992561,1.731664,0.139190,-30.291527,0.014847,0.000000
43.210003,7.534958,-30.202566,0.022679,0.000559,0.014188,33.517166,1.707446,0.141877,-30.202566,0.015289,0.000000
43.480003,7.808281,-30.247047,0.022683,0.000580,0.014743,34.732967,1.769382,0.147429,-30.247047,0.015740,0.000000
43.750004,7.941216,-30.247047,0.022704,0.000596,0.015142,35.324291,1.799505,0.151419,-30.247047,0.016191,0.000000
44.020000,8.061867,-30.247047,0.022726,0.000617,0.015671,35.860973,1.826845,0.156706,-30.247047,0.016642,0.000000
44.290001,8.097618,-30.291527,0.022748,0.000636,0.016157,36.020004,1.834946,0.161566,-30.291527,0.017093,0.000000
44.560001,8.036171,-30.291527,0.022756,0.000648,0.016468,35.746674,1.821022,0.164685,-30.291527,0.017544,0.000000
44.830002,8.153099,-30.291527,0.022778,0.000663,0.016850,36.266796,1.847519,0.168504,-30.291527,0.017995,0.000000
45.100002,8.511322,-30.291527,0.022782,0.000688,0.017466,37.860252,1.928693,0.174658,-30.291527,0.018446,0.000000
45.370003,8.316200,-30.336008,0.022804,0.000698,0.017726,36.992306,1.884478,0.177262,-30.336008,0.018897,0.000000
45.640003,8.687454,-30.336008,0.022825,0.000721,0.018325,38.643726,1.968605,0.183246,-30.336008,0.019339,0.000000
45.910004,8.853157,-30.380489,0.022855,0.000743,0.018871,39.380810,2.006154,0.188707,-30.380489,0.019790,0.000000
46.180000,8.811081,-30.336008,0.022864,0.000757,0.019235,39.193645,1.996619,0.192352,-30.336008,0.020241,0.000000
46.450001,8.758949,-30.291527,0.022873,0.000770,0.019565,38.961754,1.984806,0.195645,-30.291527,0.020692,0.000000
46.720001,8.805496,-30.291527,0.022890,0.000786,0.019963,39.168804,1.995354,0.199634,-30.291527,0.021143,0.000000
46.990002,9.207283,-30.380489,0.022903,0.000809,0.020553,40.956039,2.086400,0.205531,-30.380489,0.021594,0.000000
47.260002,9.115677,-30.380489,0.022924,0.000822,0.020874,40.548557,2.065642,0.208741,-30.380489,0.022045,0.000000
47.530003,9.277290,-30.380489,0.022950,0.000843,0.021412,41.267448,2.102264,0.214119,-30.380489,0.022496,0.000000
47.800003,9.391609,-30.336008,0.022959,0.000863,0.021915,41.775963,2.128169,0.219149,-30.336008,0.022947,0.000000
48.070004,9.502945,-30.336008,0.022989,0.000882,0.022401,42.271210,2.153398,0.224005,-30.336008,0.023389,0.000000
48.340004,9.505928,-30.424971,0.023002,0.000897,0.022791,42.284481,2.154074,0.227907,-30.424971,0.023840,0.000000
48.610001,9.516350,-30.380489,0.023024,0.000911,0.023129,42.330837,2.156436,0.231287,-30.380489,0.024291,0.000000
48.880001,9.605721,-30.336008,0.023036,0.000927,0.023545,42.728378,2.176687,0.235451,-30.336008,0.024742,0.000000
49.150002,9.818718,-30.380489,0.023058,0.000947,0.024057,43.675838,2.224953,0.240568,-30.380489,0.025193,0.000000
49.420002,10.018684,-30.380489,0.023071,0.000970,0.024629,44.565334,2.270266,0.246291,-30.380489,0.025644,0.000000
49.690002,10.283066,-30.380489,0.023097,0.000994,0.025245,45.741360,2.330176,0.252449,-30.380489,0.026095,0.000000
49.960003,10.130020,-30.469452,0.023110,0.001008,0.025601,45.060581,2.295496,0.256007,-30.469452,0.026546,0.000000
50.230003,10.235031,-30.424971,0.023123,0.001026,0.026051,45.527691,2.319291,0.260514,-30.424971,0.026997,0.000000
50.500004,10.131142,-30.424971,0.023153,0.001038,0.026355,45.065567,2.295750,0.263550,-30.424971,0.027448,0.000000
50.770004,10.444679,-30.424971,0.023144,0.001061,0.026962,46.460255,2.366798,0.269621,-30.424971,0.027890,0.000000
51.040001,10.594742,-30.469452,0.023183,0.001077,0.027352,47.127766,2.400803,0.273523,-30.469452,0.028341,0.000000
51.310001,10.595116,-30.424971,0.023192,0.001090,0.027682,47.129429,2.400887,0.276820,-30.424971,0.028792,0.000000
51.580002,10.899345,-30.424971,0.023209,0.001112,0.028246,48.482708,2.469827,0.282455,-30.424971,0.029243,0.000000
51.850002,10.953712,-30.469452,0.023239,0.001131,0.028731,48.724548,2.482147,0.287311,-30.469452,0.029694,0.000000
52.120003,11.095589,-30.424971,0.023230,0.001148,0.029156,49.355644,2.514297,0.291562,-30.424971,0.030145,0.000000
52.390003,11.058350,-30.469452,0.023248,0.001162,0.029503,49.189995,2.505858,0.295029,-30.469452,0.030596,0.000000
52.660004,11.349174,-30.513933,0.023274,0.001184,0.030076,50.483650,2.571760,0.300755,-30.513933,0.031047,0.000000
52.930004,11.452690,-30.469452,0.023295,0.001199,0.030466,50.944111,2.595217,0.304658,-30.469452,0.031498,0.000000
53.200001,11.456039,-30.424971,0.023304,0.001216,0.030890,50.959007,2.595976,0.308904,-30.424971,0.031940,0.000000
53.470001,11.793785,-30.513933,0.023321,0.001237,0.031428,52.461376,2.672510,0.314283,-30.513933,0.032391,0.000000
53.740002,11.971405,-30.513933,0.023343,0.001255,0.031888,53.251469,2.712759,0.318877,-30.513933,0.032842,0.000000
54.010002,11.995239,-30.513933,0.023355,0.001273,0.032330,53.357491,2.718160,0.323302,-30.513933,0.033293,0.000000
54.280003,12.046249,-30.513933,0.023381,0.001290,0.032764,53.584393,2.729719,0.327639,-30.513933,0.033744,0.000000
54.550003,12.370964,-30.558413,0.023394,0.001310,0.033284,55.028797,2.803300,0.332840,-30.558413,0.034195,0.000000
54.820004,12.376915,-30.469452,0.023416,0.001328,0.033744,55.055267,2.804649,0.337439,-30.469452,0.034646,0.000000
55.090004,12.319572,-30.513933,0.023424,0.001340,0.034039,54.800194,2.791655,0.340387,-30.513933,0.035097,0.000000
55.360004,12.536293,-30.558413,0.023437,0.001358,0.034489,55.764217,2.840765,0.344895,-30.558413,0.035548,0.000000
55.630001,12.879623,-30.513933,0.023468,0.001380,0.035062,57.291428,2.918564,0.350621,-30.513933,0.035999,0.000000
55.900002,13.067673,-30.513933,0.023493,0.001400,0.035548,58.127911,2.961177,0.355477,-30.513933,0.036441,0.000000
56.170002,13.124268,-30.513933,0.023489,0.001417,0.035990,58.379658,2.974001,0.359898,-30.513933,0.036892,0.000000
56.440002,13.186081,-30.602894,0.023524,0.001433,0.036397,58.654617,2.988008,0.363974,-30.602894,0.037343,0.000000
56.710003,13.297424,-30.602894,0.023524,0.001451,0.036857,59.149899,3.013239,0.368569,-30.602894,0.037794,0.000000
56.980003,13.377487,-30.558413,0.023571,0.001465,0.037213,59.506035,3.031382,0.372127,-30.558413,0.038245,0.000000
57.250004,13.563301,-30.602894,0.023567,0.001485,0.037707,60.332577,3.073488,0.377070,-30.602894,0.038696,0.000000
57.520004,14.056320,-30.602894,0.023584,0.001506,0.038262,62.525635,3.185208,0.382619,-30.602894,0.039146,0.000000
57.790001,14.070465,-30.602894,0.023593,0.001524,0.038713,62.588554,3.188413,0.387130,-30.602894,0.039598,0.000000
58.060001,14.163193,-30.602894,0.023618,0.001540,0.039112,63.001026,3.209425,0.391120,-30.602894,0.040048,0.000000
58.330002,14.357567,-30.558413,0.023644,0.001557,0.039545,63.865646,3.253471,0.395453,-30.558413,0.040491,0.000000
58.600002,14.564606,-30.647375,0.023653,0.001575,0.040014,64.786598,3.300387,0.400139,-30.647375,0.040942,0.000000
58.870003,14.576149,-30.647375,0.023666,0.001591,0.040404,64.837952,3.303003,0.404041,-30.647375,0.041393,0.000000
59.140003,14.527367,-30.647375,0.023670,0.001601,0.040664,64.620956,3.291948,0.406642,-30.647375,0.041844,0.000000
59.410004,15.249397,-30.602894,0.023700,0.001628,0.041358,67.832710,3.455563,0.413579,-30.602894,0.042295,0.000000
59.680004,15.345100,-30.647375,0.023718,0.001646,0.041809,68.258415,3.477249,0.418091,-30.647375,0.042745,0.000000
59.950005,15.471703,-30.602894,0.023731,0.001664,0.042269,68.821571,3.505938,0.422686,-30.602894,0.043197,0.000000
60.220001,15.506340,-30.647375,0.023748,0.001679,0.042659,68.975647,3.513787,0.426588,-30.647375,0.043647,0.000000
60.490002,15.833649,-30.736338,0.023769,0.001697,0.043101,70.431587,3.587956,0.431012,-30.736338,0.044099,0.000000
60.760002,15.940147,-30.691856,0.023782,0.001713,0.043518,70.905319,3.612089,0.435176,-30.691856,0.044541,0.000000
61.030003,15.930466,-30.647375,0.023808,0.001727,0.043864,70.862251,3.609895,0.438643,-30.647375,0.044992,0.000000
61.300003,16.499825,-30.647375,0.023804,0.001752,0.044506,73.394882,3.738914,0.445062,-30.647375,0.045443,0.000000
61.570004,16.486420,-30.647375,0.023825,0.001767,0.044879,73.335258,3.735876,0.448790,-30.647375,0.045894,0.000000
61.840004,16.841667,-30.691856,0.023847,0.001787,0.045391,74.915474,3.816376,0.453907,-30.691856,0.046345,0.000000
62.110004,16.804054,-30.780819,0.023869,0.001800,0.045720,74.748169,3.807853,0.457200,-30.780819,0.046796,0.000000
62.380001,17.326866,-30.691856,0.023899,0.001822,0.046267,77.073753,3.926324,0.462666,-30.691856,0.047246,0.000000
62.650002,17.403206,-30.691856,0.023899,0.001836,0.046639,77.413322,3.943623,0.466394,-30.691856,0.047697,0.000000
62.920002,17.546562,-30.691856,0.023903,0.001852,0.047030,78.051010,3.976108,0.470296,-30.691856,0.048148,0.000000
63.190002,18.064163,-30.780819,0.023933,0.001875,0.047628,80.353409,4.093398,0.476280,-30.780819,0.048599,0.000000
63.460003,18.311790,-30.780819,0.023946,0.001892,0.048062,81.454910,4.149511,0.480617,-30.780819,0.049042,0.000000
63.730003,18.422012,-30.736338,0.023963,0.001910,0.048521,81.945206,4.174488,0.485212,-30.736338,0.049492,0.000000
64.000000,18.537445,-30.736338,0.023976,0.001925,0.048886,82.458672,4.200645,0.488857,-30.736338,0.049944,0.000000
64.270004,19.080368,-30.691856,0.023989,0.001946,0.049441,84.873718,4.323673,0.494406,-30.691856,0.050394,0.000000
64.540001,18.884499,-30.780819,0.024007,0.001958,0.049735,84.002441,4.279289,0.497354,-30.780819,0.050846,0.000000
64.810005,19.488487,-30.780819,0.024019,0.001979,0.050256,86.689117,4.416154,0.502558,-30.780819,0.051296,0.000000
65.080002,19.806870,-30.780819,0.024041,0.001996,0.050707,88.105354,4.488301,0.507066,-30.780819,0.051747,0.000000
65.350006,20.163223,-30.736338,0.024071,0.002016,0.051218,89.690498,4.569052,0.512183,-30.736338,0.052198,0.000000
65.620003,20.404152,-30.780819,0.024080,0.002035,0.051695,90.762199,4.623647,0.516952,-30.780819,0.052649,0.000000
65.889999,20.391121,-30.825298,0.024080,0.002050,0.052077,90.704239,4.620694,0.520768,-30.825298,0.053091,0.000000
66.160004,20.505066,-30.736338,0.024110,0.002062,0.052380,91.211090,4.646514,0.523803,-30.736338,0.053543,0.000000
66.430000,21.139961,-30.780819,0.024127,0.002086,0.052987,94.035248,4.790384,0.529874,-30.780819,0.053993,0.000000
66.700005,21.258003,-30.780819,0.024140,0.002100,0.053334,94.560318,4.817132,0.533345,-30.780819,0.054445,0.000000
66.970001,21.861618,-30.780819,0.024157,0.002121,0.053863,97.245331,4.953914,0.538632,-30.780819,0.054895,0.000000
67.240005,22.377724,-30.825298,0.024170,0.002141,0.054375,99.541084,5.070865,0.543749,-30.825298,0.055347,0.000000
67.510002,22.416077,-30.869780,0.024183,0.002156,0.054765,99.711685,5.079556,0.547652,-30.869780,0.055797,0.000000
67.780006,22.531143,-30.780819,0.024196,0.002169,0.055095,100.223534,5.105630,0.550948,-30.780819,0.056248,0.000000
68.050003,22.744141,-30.869780,0.024205,0.002184,0.055476,101.170990,5.153896,0.554763,-30.869780,0.056699,0.000000
68.320000,23.523514,-30.825298,0.024226,0.002207,0.056049,104.637817,5.330504,0.560490,-30.825298,0.057142,0.000000
68.590004,23.583099,-30.914261,0.024235,0.002221,0.056404,104.902863,5.344007,0.564044,-30.914261,0.057592,0.000000
68.860001,24.121544,-30.825298,0.024261,0.002241,0.056934,107.297989,5.466020,0.569335,-30.825298,0.058043,0.000000
69.130005,24.496529,-30.914261,0.024270,0.002261,0.057437,108.966003,5.550993,0.574365,-30.914261,0.058494,0.000000
69.400002,24.890495,-30.825298,0.024282,0.002280,0.057905,110.718452,5.640267,0.579047,-30.825298,0.058945,0.000000
69.670006,25.247597,-30.869780,0.024308,0.002296,0.058312,112.306923,5.721188,0.583124,-30.869780,0.059396,0.000000
69.940002,25.387985,-30.869780,0.024317,0.002309,0.058650,112.931396,5.752999,0.586504,-30.869780,0.059847,0.000000
70.210007,25.866486,-30.869780,0.024343,0.002327,0.059110,115.059875,5.861429,0.591102,-30.869780,0.060298,0.000000
70.480003,26.394135,-30.869780,0.024356,0.002345,0.059552,117.406975,5.980997,0.595523,-30.869780,0.060749,0.000000
70.750000,26.965355,-30.914261,0.024360,0.002368,0.060142,119.947891,6.110436,0.601420,-30.914261,0.061200,0.000000
71.020004,27.723129,-30.869780,0.024369,0.002391,0.060732,123.318642,6.282151,0.607317,-30.869780,0.061642,0.000000
71.290001,27.887352,-31.003223,0.024399,0.002406,0.061122,124.049133,6.319365,0.611223,-31.003223,0.062093,0.000000
71.560005,28.349464,-30.914261,0.024412,0.002428,0.061660,126.104713,6.424080,0.616597,-30.914261,0.062544,0.000000
71.830002,28.233658,-30.914261,0.024429,0.002436,0.061868,125.589584,6.397838,0.618679,-30.914261,0.062995,0.000000
72.100006,28.919563,-30.958742,0.024442,0.002455,0.062353,128.640640,6.553267,0.623535,-30.958742,0.063446,0.000000
72.370003,29.647552,-30.958742,0.024455,0.002475,0.062874,131.878906,6.718231,0.628739,-30.958742,0.063897,0.000000
72.640007,29.822571,-31.003223,0.024468,0.002488,0.063186,132.657425,6.757891,0.631862,-31.003223,0.064348,0.000000
72.910004,30.738235,-30.869780,0.024489,0.002511,0.063776,136.730499,6.965384,0.637759,-30.869780,0.064799,0.000000
73.180000,31.261787,-31.003223,0.024507,0.002531,0.064288,139.059372,7.084023,0.642876,-31.003223,0.065250,0.000000
73.450005,31.710869,-30.958742,0.024498,0.002546,0.064678,141.056992,7.185785,0.646778,-30.958742,0.065693,0.000000
73.720001,31.901894,-30.958742,0.024515,0.002560,0.065033,141.906708,7.229072,0.650332,-30.958742,0.066143,0.000000
73.990005,32.823517,-30.958742,0.024550,0.002583,0.065597,146.006302,7.437915,0.655972,-30.958742,0.066594,0.000000
74.260002,33.303505,-31.003223,0.024558,0.002598,0.065987,148.141388,7.546682,0.659874,-31.003223,0.067045,0.000000
74.530006,33.627846,-30.958742,0.024576,0.002615,0.066412,149.584122,7.620179,0.664120,-30.958742,0.067496,0.000000
74.800003,34.479462,-30.958742,0.024576,0.002636,0.066950,153.372299,7.813158,0.669499,-30.958742,0.067947,0.000000
75.070007,35.077492,-31.003223,0.024597,0.002654,0.067418,156.032471,7.948673,0.674181,-31.003223,0.068398,0.000000
75.340004,35.733612,-31.003223,0.024614,0.002671,0.067852,158.951050,8.097352,0.678518,-31.003223,0.068849,0.000000
75.610001,36.198326,-31.003223,0.024627,0.002690,0.068320,161.018204,8.202658,0.683200,-31.003223,0.069300,0.000000
75.880005,37.048080,-30.958742,0.024632,0.002709,0.068814,164.798096,8.395215,0.688143,-30.958742,0.069742,0.000000
76.150002,37.447639,-31.003223,0.024645,0.002724,0.069187,166.575424,8.485757,0.691871,-31.003223,0.070193,0.000000
76.420006,37.871399,-31.092184,0.024649,0.002739,0.069560,168.460403,8.581781,0.695603,-31.092184,0.070644,0.000000
76.690002,38.574440,-31.047705,0.024675,0.002757,0.070020,171.587677,8.741093,0.700198,-31.047705,0.071095,0.000000
76.960007,39.633835,-31.047705,0.024688,0.002779,0.070583,176.300110,8.981155,0.705834,-31.047705,0.071546,0.000000
77.230003,40.398315,-31.047705,0.024701,0.002798,0.071069,179.700684,9.154388,0.710690,-31.047705,0.071997,0.000000
77.500000,41.099495,-31.047705,0.024709,0.002815,0.071511,182.819687,9.313278,0.715114,-31.047705,0.072448,0.000000
77.770004,41.636833,-31.092184,0.024727,0.002832,0.071936,185.209885,9.435041,0.719365,-31.092184,0.072899,0.000000
78.040001,42.129852,-31.136665,0.024739,0.002849,0.072353,187.402939,9.546762,0.723528,-31.136665,0.073350,0.000000
78.310005,42.626968,-31.092184,0.024757,0.002864,0.072734,189.614227,9.659409,0.727343,-31.092184,0.073801,0.000000
78.580002,43.397034,-31.092184,0.024761,0.002883,0.073229,193.039642,9.833909,0.732286,-31.092184,0.074243,0.000000
78.850006,44.716721,-31.047705,0.024774,0.002904,0.073757,198.909912,10.132954,0.737574,-31.047705,0.074694,0.000000
79.120003,45.486420,-31.136665,0.024778,0.002921,0.074182,202.333694,10.307370,0.741824,-31.136665,0.075145,0.000000
79.390007,46.309731,-31.136665,0.024800,0.002938,0.074634,205.995972,10.493935,0.746336,-31.136665,0.075596,0.000000
79.660004,47.131187,-31.047705,0.024817,0.002955,0.075067,209.649994,10.680079,0.750670,-31.047705,0.076047,0.000000
79.930000,48.057648,-31.047705,0.024826,0.002974,0.075544,213.771088,10.890018,0.755442,-31.047705,0.076498,0.000000
80.200005,48.447891,-31.136665,0.024826,0.002989,0.075908,215.506989,10.978449,0.759083,-31.136665,0.076949,0.000000
80.470001,48.875008,-31.181147,0.024834,0.002999,0.076186,217.406891,11.075234,0.761858,-31.181147,0.077400,0.000000
80.740005,50.520149,-31.136665,0.024852,0.003026,0.076871,224.724854,11.448030,0.768708,-31.136665,0.077851,0.000000
81.010002,50.982262,-31.136665,0.024860,0.003038,0.077174,226.780426,11.552746,0.771744,-31.136665,0.078293,0.000000
81.280006,52.353340,-31.136665,0.024873,0.003062,0.077773,232.879288,11.863436,0.777728,-31.136665,0.078744,0.000000
81.550003,52.827736,-31.181147,0.024877,0.003074,0.078085,234.989502,11.970937,0.780850,-31.181147,0.079195,0.000000
81.820007,54.236053,-31.225628,0.024886,0.003096,0.078631,241.254013,12.290065,0.786312,-31.225628,0.079646,0.000000
82.090004,55.058998,-31.181147,0.024903,0.003112,0.079039,244.914658,12.476547,0.790388,-31.181147,0.080097,0.000000
82.360001,55.567657,-31.136665,0.024916,0.003125,0.079368,247.177292,12.591811,0.793685,-31.136665,0.080548,0.000000
82.630005,57.094757,-31.181147,0.024916,0.003151,0.080027,253.970169,12.937857,0.800274,-31.181147,0.080999,0.000000
82.900002,57.817162,-31.225628,0.024921,0.003162,0.080322,257.183594,13.101556,0.803223,-31.225628,0.081450,0.000000
83.170006,58.996834,-31.270109,0.024946,0.003185,0.080904,262.431030,13.368874,0.809036,-31.270109,0.081901,0.000000
83.440002,59.584068,-31.225628,0.024951,0.003198,0.081224,265.043182,13.501944,0.812242,-31.225628,0.082343,0.000000
83.710007,60.588356,-31.181147,0.024959,0.003216,0.081693,269.510468,13.729517,0.816928,-31.181147,0.082794,0.000000
83.980003,61.891289,-31.181147,0.024964,0.003234,0.082144,275.306213,14.024766,0.821436,-31.181147,0.083245,0.000000
84.250008,62.822960,-31.225628,0.024972,0.003250,0.082560,279.450470,14.235886,0.825599,-31.225628,0.083696,0.000000
84.520004,64.224937,-31.270109,0.024985,0.003273,0.083132,285.686798,14.553578,0.831322,-31.270109,0.084147,0.000000
84.790001,65.612770,-31.225628,0.024998,0.003292,0.083609,291.860168,14.868067,0.836091,-31.225628,0.084598,0.000000
85.060005,66.375771,-31.225628,0.025007,0.003307,0.083999,295.254181,15.040965,0.839993,-31.225628,0.085049,0.000000
85.330002,67.360695,-31.225628,0.025011,0.003323,0.084407,299.635345,15.264152,0.844069,-31.225628,0.085500,0.000000
85.600006,67.019966,-31.270109,0.025015,0.003316,0.084234,298.119690,15.186941,0.842336,-31.270109,0.084502,0.000000
85.870003,66.294212,-31.314590,0.025024,0.003315,0.084199,294.891388,15.022483,0.841988,-31.314590,0.084234,0.000000
86.140007,65.684273,-31.225628,0.025041,0.003314,0.084164,292.178223,14.884269,0.841643,-31.225628,0.084234,0.000000
86.410004,65.172997,-31.270109,0.025037,0.003313,0.084156,289.903961,14.768412,0.841556,-31.270109,0.084234,0.000000
86.680000,64.723915,-31.225628,0.025041,0.003313,0.084147,287.906342,14.666649,0.841469,-31.225628,0.084234,0.000000
86.950005,64.344475,-31.359070,0.025037,0.003313,0.084147,286.218506,14.580667,0.841469,-31.359070,0.084234,0.000000
87.220001,63.985512,-31.314590,0.025054,0.003313,0.084138,284.621765,14.499324,0.841382,-31.314590,0.084234,0.000000
87.490005,63.686119,-31.314590,0.025054,0.003313,0.084138,283.290009,14.431481,0.841382,-31.314590,0.084234,0.000000
87.760002,63.388222,-31.270109,0.025046,0.003313,0.084138,281.964905,14.363976,0.841382,-31.270109,0.084234,0.000000
88.030006,63.135750,-31.314590,0.025050,0.003313,0.084138,280.841827,14.306766,0.841382,-31.314590,0.084234,0.000000
88.300003,62.897057,-31.314590,0.025050,0.003313,0.084138,279.780090,14.252676,0.841382,-31.314590,0.084234,0.000000
88.570007,62.687042,-31.403551,0.025063,0.003312,0.084130,278.845886,14.205087,0.841295,-31.403551,0.084234,0.000000
88.840004,62.477402,-31.314590,0.025067,0.003312,0.084130,277.913361,14.157581,0.841295,-31.314590,0.084234,0.000000
89.110001,62.294189,-31.314590,0.025050,0.003312,0.084130,277.098389,14.116065,0.841295,-31.314590,0.084234,0.000000
89.380005,62.120293,-31.359070,0.025050,0.003312,0.084130,276.324860,14.076659,0.841295,-31.359070,0.084234,0.000000
89.650002,61.973953,-31.359070,0.025059,0.003312,0.084130,275.673920,14.043499,0.841295,-31.359070,0.084234,0.000000
89.920006,61.823883,-31.403551,0.025067,0.003312,0.084130,275.006378,14.009492,0.841295,-31.403551,0.084234,0.000000
90.190002,61.677170,-31.359070,0.025076,0.003312,0.084130,274.353760,13.976247,0.841295,-31.359070,0.084234,0.000000
90.460007,61.544975,-31.314590,0.025076,0.003312,0.084130,273.765717,13.946291,0.841295,-31.314590,0.084234,0.000000
90.730003,61.418747,-31.359070,0.025063,0.003312,0.084130,273.204224,13.917687,0.841295,-31.359070,0.084234,0.000000
91.000008,61.305168,-31.448032,0.025059,0.003312,0.084130,272.699005,13.891950,0.841295,-31.448032,0.084234,0.000000
91.270004,61.185265,-31.448032,0.025071,0.003312,0.084130,272.165649,13.864779,0.841295,-31.448032,0.084234,0.000000
91.540001,61.080627,-31.359070,0.025076,0.003312,0.084130,271.700195,13.841068,0.841295,-31.359070,0.084234,0.000000
91.810005,60.974876,-31.403551,0.025067,0.003312,0.084130,271.229797,13.817104,0.841295,-31.403551,0.084234,0.000000
92.080002,60.879921,-31.359070,0.025067,0.003312,0.084130,270.807404,13.795588,0.841295,-31.359070,0.084234,0.000000
92.350006,60.778267,-31.448032,0.025059,0.003312,0.084130,270.355225,13.772552,0.841295,-31.448032,0.084234,0.000000
92.620003,60.685539,-31.492514,0.025076,0.003312,0.084130,269.942749,13.751540,0.841295,-31.492514,0.084234,0.000000
92.890007,60.606972,-31.492514,0.025076,0.003312,0.084130,269.593262,13.733736,0.841295,-31.492514,0.084234,0.000000
93.160004,60.523186,-31.403551,0.025067,0.003312,0.084130,269.220581,13.714749,0.841295,-31.403551,0.084234,0.000000
93.430008,60.442009,-31.403551,0.025063,0.003312,0.084130,268.859497,13.696355,0.841295,-31.403551,0.084234,0.000000
93.700005,60.372375,-31.536995,0.025071,0.003312,0.084130,268.549744,13.680575,0.841295,-31.536995,0.084234,0.000000
93.970001,60.292320,-31.536995,0.025080,0.003312,0.084130,268.193634,13.662436,0.841295,-31.536995,0.084234,0.000000
94.240005,60.215233,-31.448032,0.025067,0.003312,0.084130,267.850739,13.644966,0.841295,-31.448032,0.084234,0.000000
94.510002,60.136292,-31.492514,0.025071,0.003312,0.084130,267.499573,13.627078,0.841295,-31.492514,0.084234,0.000000
94.780006,60.059586,-31.492514,0.025067,0.003312,0.084130,267.158386,13.609696,0.841295,-31.492514,0.084234,0.000000
95.050003,60.016014,-31.536995,0.025071,0.003312,0.084130,266.964569,13.599823,0.841295,-31.536995,0.084234,0.000000
95.320007,59.942657,-31.536995,0.025084,0.003312,0.084130,266.638245,13.583200,0.841295,-31.536995,0.084234,0.000000
95.590004,59.885689,-31.536995,0.025080,0.003312,0.084121,266.384857,13.570292,0.841208,-31.536995,0.084234,0.000000
95.860008,59.828339,-31.492514,0.025071,0.003312,0.084121,266.129730,13.557296,0.841208,-31.492514,0.084234,0.000000
96.130005,59.759453,-31.581474,0.025063,0.003312,0.084121,265.823334,13.541686,0.841208,-31.581474,0.084234,0.000000
96.400002,59.701736,-31.536995,0.025080,0.003312,0.084121,265.566589,13.528606,0.841208,-31.536995,0.084234,0.000000
96.670006,59.649231,-31.581474,0.025076,0.003312,0.084121,265.333038,13.516709,0.841208,-31.581474,0.084234,0.000000
96.940002,59.587418,-31.536995,0.025084,0.003312,0.084121,265.058075,13.502703,0.841208,-31.536995,0.084234,0.000000
97.210007,59.541985,-31.536995,0.025076,0.003312,0.084121,264.855988,13.492407,0.841208,-31.536995,0.084234,0.000000
97.480003,59.495811,-31.581474,0.025067,0.003312,0.084121,264.650574,13.481944,0.841208,-31.581474,0.084234,0.000000
97.750008,59.452988,-31.581474,0.025076,0.003312,0.084121,264.460083,13.472239,0.841208,-31.581474,0.084234,0.000000
98.020004,59.399742,-31.581474,0.025076,0.003312,0.084121,264.223236,13.460174,0.841208,-31.581474,0.084234,0.000000
98.290001,59.357666,-31.581474,0.025080,0.003312,0.084121,264.036072,13.450640,0.841208,-31.581474,0.084234,0.000000
98.560005,59.314842,-31.581474,0.025076,0.003312,0.084121,263.845581,13.440935,0.841208,-31.581474,0.084234,0.000000
98.830002,59.267174,-31.581474,0.025080,0.003312,0.084121,263.633545,13.430133,0.841208,-31.581474,0.084234,0.000000
99.100006,59.222862,-31.581474,0.025080,0.003312,0.084121,263.436462,13.420093,0.841208,-31.581474,0.084234,0.000000
99.370003,59.196053,-31.536995,0.025089,0.003312,0.084121,263.317200,13.414017,0.841208,-31.536995,0.084234,0.000000
99.640007,59.129402,-31.581474,0.025089,0.003312,0.084121,263.020721,13.398914,0.841208,-31.581474,0.084234,0.000000
99.910004,59.099983,-31.536995,0.025084,0.003312,0.084121,262.889862,13.392248,0.841208,-31.536995,0.084234,0.000000
100.180008,59.057899,-31.581474,0.025084,0.003312,0.084121,262.702667,13.382711,0.841208,-31.581474,0.084234,0.000000
100.450005,59.024017,-31.670437,0.025084,0.003312,0.084121,262.551941,13.375033,0.841208,-31.670437,0.084234,0.000000
100.720001,58.998322,-31.670437,0.025089,0.003312,0.084121,262.437653,13.369210,0.841208,-31.670437,0.084234,0.000000
100.990005,58.946190,-31.581474,0.025080,0.003312,0.084121,262.205750,13.357398,0.841208,-31.581474,0.084234,0.000000
101.260002,58.906349,-31.581474,0.025076,0.003312,0.084121,262.028534,13.348370,0.841208,-31.581474,0.084234,0.000000
101.530006,58.864265,-31.670437,0.025080,0.003312,0.084121,261.841339,13.338834,0.841208,-31.670437,0.084234,0.000000
101.800003,58.837830,-31.670437,0.025080,0.003312,0.084121,261.723724,13.332843,0.841208,-31.670437,0.084234,0.000000
102.070007,58.812881,-31.670437,0.025080,0.003312,0.084121,261.612762,13.327189,0.841208,-31.670437,0.084234,0.000000
102.340004,58.774529,-31.670437,0.025080,0.003312,0.084121,261.442169,13.318499,0.841208,-31.670437,0.084234,0.000000
102.610008,58.728729,-31.670437,0.025071,0.003312,0.084121,261.238434,13.308120,0.841208,-31.670437,0.084234,0.000000
102.880005,58.706383,-31.714918,0.025080,0.003312,0.084121,261.139038,13.303056,0.841208,-31.714918,0.084234,0.000000
103.150002,58.681061,-31.714918,0.025093,0.003312,0.084121,261.026398,13.297318,0.841208,-31.714918,0.084234,0.000000
103.420006,58.638985,-31.670437,0.025089,0.003312,0.084121,260.839233,13.287784,0.841208,-31.670437,0.084234,0.000000
103.690002,58.616638,-31.670437,0.025093,0.003312,0.084121,260.739838,13.282720,0.841208,-31.670437,0.084234,0.000000
103.960007,58.588341,-31.714918,0.025084,0.003312,0.084121,260.613953,13.276307,0.841208,-31.714918,0.084234,0.000000
104.230003,58.551849,-31.714918,0.025089,0.003312,0.084121,260.451630,13.268039,0.841208,-31.714918,0.084234,0.000000
104.500008,58.514984,-31.759399,0.025089,0.003312,0.084121,260.287659,13.259685,0.841208,-31.759399,0.084234,0.000000
104.770004,58.489662,-31.759399,0.025076,0.003312,0.084121,260.175018,13.253946,0.841208,-31.759399,0.084234,0.000000
105.040009,58.466576,-31.670437,0.025089,0.003312,0.084121,260.072327,13.248715,0.841208,-31.670437,0.084234,0.000000
105.310005,58.439392,-31.759399,0.025080,0.003312,0.084121,259.951385,13.242556,0.841208,-31.759399,0.084234,0.000000
105.580002,58.404015,-31.759399,0.025076,0.003312,0.084121,259.794037,13.234539,0.841208,-31.759399,0.084234,0.000000
105.850006,58.379440,-31.759399,0.025089,0.003312,0.084121,259.684723,13.228970,0.841208,-31.759399,0.084234,0.000000
106.120003,58.359329,-31.714918,0.025084,0.003312,0.084121,259.595276,13.224413,0.841208,-31.714918,0.084234,0.000000
106.390007,58.325821,-31.759399,0.025084,0.003312,0.084121,259.446198,13.216821,0.841208,-31.759399,0.084234,0.000000
106.660004,58.291931,-31.759399,0.025084,0.003312,0.084121,259.295471,13.209140,0.841208,-31.759399,0.084234,0.000000
106.930008,58.257301,-31.759399,0.025080,0.003312,0.084121,259.141418,13.201294,0.841208,-31.759399,0.084234,0.000000
107.200005,58.241661,-31.803881,0.025080,0.003312,0.084121,259.071838,13.197749,0.841208,-31.803881,0.084234,0.000000
107.470009,58.223785,-31.848360,0.025089,0.003312,0.084121,258.992340,13.193699,0.841208,-31.848360,0.084234,0.000000
107.740005,58.191391,-31.803881,0.025093,0.003312,0.084121,258.848236,13.186357,0.841208,-31.803881,0.084234,0.000000
108.010002,58.158997,-31.803881,0.025084,0.003312,0.084121,258.704132,13.179017,0.841208,-31.803881,0.084234,0.000000
108.280006,58.138885,-31.848360,0.025080,0.003312,0.084121,258.614685,13.174459,0.841208,-31.848360,0.084234,0.000000
108.550003,58.116173,-31.848360,0.025089,0.003312,0.084121,258.513641,13.169313,0.841208,-31.848360,0.084234,0.000000
108.820007,58.091225,-31.892841,0.025089,0.003312,0.084121,258.402679,13.163660,0.841208,-31.892841,0.084234,0.000000
109.090004,58.072609,-31.803881,0.025089,0.003312,0.084121,258.319855,13.159441,0.841208,-31.803881,0.084234,0.000000
109.360008,58.043564,-31.848360,0.025089,0.003312,0.084121,258.190674,13.152860,0.841208,-31.848360,0.084234,0.000000
109.630005,58.017494,-31.892841,0.025089,0.003312,0.084121,258.074707,13.146952,0.841208,-31.892841,0.084234,0.000000
109.900002,58.008186,-31.892841,0.025097,0.003312,0.084121,258.033295,13.144843,0.841208,-31.892841,0.084234,0.000000
110.170006,57.985840,-31.892841,0.025093,0.003312,0.084121,257.933899,13.139779,0.841208,-31.892841,0.084234,0.000000
110.440002,57.959404,-31.892841,0.025093,0.003312,0.084121,257.816315,13.133788,0.841208,-31.892841,0.084234,0.000000
110.710007,57.934830,-31.848360,0.025093,0.003312,0.084121,257.707001,13.128221,0.841208,-31.848360,0.084234,0.000000
110.980003,57.925888,-31.892841,0.025080,0.003312,0.084121,257.667206,13.126194,0.841208,-31.892841,0.084234,0.000000
111.250008,57.893120,-31.848360,0.025097,0.003312,0.084121,257.521454,13.118768,0.841208,-31.848360,0.084234,0.000000
111.520004,57.878227,-31.848360,0.025093,0.003312,0.084121,257.455200,13.115394,0.841208,-31.848360,0.084234,0.000000
111.790009,57.854019,-31.892841,0.025084,0.003312,0.084121,257.347534,13.109908,0.841208,-31.892841,0.084234,0.000000
112.060005,57.846947,-31.937323,0.025084,0.003312,0.084121,257.316071,13.108305,0.841208,-31.937323,0.084234,0.000000
112.330002,57.828331,-31.937323,0.025097,0.003312,0.084121,257.233276,13.104087,0.841208,-31.937323,0.084234,0.000000
112.600006,57.797050,-31.937323,0.025089,0.003312,0.084121,257.094116,13.096999,0.841208,-31.937323,0.084234,0.000000
112.870003,57.789604,-31.892841,0.025097,0.003312,0.084121,257.061005,13.095311,0.841208,-31.892841,0.084234,0.000000
113.140007,57.771729,-31.848360,0.025097,0.003312,0.084121,256.981476,13.091261,0.841208,-31.848360,0.084234,0.000000
113.410004,57.757202,-31.892841,0.025084,0.003312,0.084121,256.916870,13.087969,0.841208,-31.892841,0.084234,0.000000
113.680008,57.740448,-31.981804,0.025089,0.003312,0.084121,256.842346,13.084173,0.841208,-31.981804,0.084234,0.000000
113.950005,57.702095,-31.937323,0.025102,0.003312,0.084121,256.671753,13.075481,0.841208,-31.937323,0.084234,0.000000
114.220009,57.706566,-31.981804,0.025089,0.003312,0.084121,256.691620,13.076494,0.841208,-31.981804,0.084234,0.000000
114.490005,57.697998,-31.937323,0.025097,0.003312,0.084121,256.653503,13.074553,0.841208,-31.937323,0.084234,0.000000
114.760002,57.662994,-31.937323,0.025093,0.003312,0.084121,256.497803,13.066622,0.841208,-31.937323,0.084234,0.000000
115.030006,57.661880,-32.070766,0.025093,0.003312,0.084121,256.492859,13.066369,0.841208,-32.070766,0.084234,0.000000
115.300003,57.631348,-31.981804,0.025093,0.003312,0.084121,256.357025,13.059449,0.841208,-31.981804,0.084234,0.000000
115.570007,57.616821,-32.026283,0.025089,0.003312,0.084121,256.292419,13.056158,0.841208,-32.026283,0.084234,0.000000
115.840004,57.607140,-32.026283,0.025089,0.003312,0.084121,256.249359,13.053965,0.841208,-32.026283,0.084234,0.000000
116.000008,57.588524,-32.026283,0.025097,0.003312,0.084121,256.166534,13.049746,0.841208,-32.026283,0.084234,0.000000