File: Data/Compression Sample NH 10, 12, 15, 17 batch 3/AutoNoheating-15-3-1-240212_02122024_175519.csv
Time (sec),S:Load (lbs),S:HL1 (DIM),S:LVDT (in),S:Position (in),Ch:Position (mm),Ch:Load (N),Ch:Stress (MPa),Ch:Strain (mm/mm),Ch:HL1 (DIM),Set Point (),Cycles ()
0.110000,-0.000748,-289.971313,-0.000052,-0.000000,-0.000000,-0.003326,-0.000169,-0.000000,-289.971313,0.000234,0.000000
0.330000,0.003349,-289.926849,-0.000078,-0.000000,-0.000000,0.014898,0.000759,-0.000000,-289.926849,0.000234,0.000000
0.550000,0.059578,-289.971313,-0.000043,0.000114,0.002905,0.265016,0.013501,0.029053,-289.971313,0.003842,0.000000
0.770000,0.072609,-290.060272,0.000082,0.000252,0.006409,0.322981,0.016453,0.064090,-290.060272,0.007502,0.000000
0.990000,0.078194,-290.015808,0.000224,0.000393,0.009982,0.347823,0.017719,0.099819,-290.015808,0.011179,0.000000
1.210000,0.072235,-290.015808,0.000336,0.000544,0.013815,0.321318,0.016369,0.138149,-290.015808,0.014838,0.000000
1.430000,0.092346,-289.971313,0.000565,0.000689,0.017492,0.410776,0.020926,0.174919,-289.971313,0.018498,0.000000
1.650000,0.066277,-290.015808,0.000698,0.000830,0.021082,0.294813,0.015018,0.210822,-290.015808,0.022175,0.000000
1.870000,0.062553,-290.015808,0.000832,0.000973,0.024716,0.278251,0.014175,0.247157,-290.015808,0.025835,0.000000
2.090000,0.069633,-290.060272,0.001018,0.001115,0.028332,0.309745,0.015779,0.283322,-290.060272,0.029494,0.000000
2.310000,0.090111,-290.015808,0.001164,0.001264,0.032113,0.400833,0.020419,0.321133,-290.015808,0.033154,0.000000
2.530000,0.094208,-290.015808,0.001246,0.001400,0.035565,0.419057,0.021348,0.355648,-290.015808,0.036831,0.000000
2.750000,0.083405,-290.060272,0.001431,0.001547,0.039285,0.371002,0.018900,0.392853,-290.060272,0.040491,0.000000
2.970000,0.067772,-290.015808,0.001600,0.001703,0.043248,0.301465,0.015357,0.432485,-290.015808,0.044150,0.000000
3.190000,0.027924,-290.104767,0.001776,0.001843,0.046804,0.124210,0.006328,0.468040,-290.104767,0.047827,0.000000
3.410000,0.033882,-290.015808,0.001888,0.001985,0.050429,0.150715,0.007678,0.504292,-290.015808,0.051487,0.000000
3.630000,0.084900,-290.060272,0.002026,0.002127,0.054020,0.377654,0.019239,0.540195,-290.060272,0.055147,0.000000
3.850000,0.081543,-290.060272,0.002186,0.002274,0.057748,0.362721,0.018478,0.577484,-290.060272,0.058824,0.000000
4.070000,0.100906,-290.104767,0.002350,0.002417,0.061382,0.448854,0.022866,0.613823,-290.104767,0.062484,0.000000
4.290000,0.106865,-290.060272,0.002445,0.002554,0.064869,0.475359,0.024216,0.648686,-290.060272,0.066143,0.000000
4.510000,0.100166,-290.015808,0.002643,0.002707,0.068762,0.445562,0.022698,0.687625,-290.015808,0.069820,0.000000
4.730000,0.083038,-290.060272,0.002811,0.002854,0.072491,0.369373,0.018817,0.724913,-290.060272,0.073480,0.000000
4.950000,0.047661,-290.060272,0.002893,0.002994,0.076047,0.212006,0.010800,0.760469,-290.060272,0.077140,0.000000
5.170000,0.058090,-290.104767,0.003096,0.003137,0.079672,0.258398,0.013163,0.796720,-290.104767,0.080817,0.000000
5.390000,0.064415,-290.104767,0.003186,0.003286,0.083462,0.286532,0.014597,0.834619,-290.104767,0.084477,0.000000
5.610000,0.075958,-290.104767,0.003385,0.003428,0.087078,0.337879,0.017212,0.870779,-290.104767,0.088136,0.000000
5.830000,0.123993,-290.104767,0.003501,0.003566,0.090573,0.551548,0.028097,0.905729,-290.104767,0.091813,0.000000
6.050000,0.106125,-290.104767,0.003635,0.003717,0.094424,0.472067,0.024048,0.944237,-290.104767,0.095473,0.000000
6.270000,0.119904,-290.193726,0.003842,0.003861,0.098066,0.533358,0.027171,0.980659,-290.193726,0.099132,0.000000
6.490000,0.099419,-290.104767,0.003949,0.004004,0.101699,0.442236,0.022529,1.016994,-290.104767,0.102792,0.000000
6.710001,0.085640,-290.104767,0.004143,0.004145,0.105273,0.380946,0.019406,1.052727,-290.104767,0.106469,0.000000
6.930000,0.091972,-290.104767,0.004286,0.004291,0.108984,0.409113,0.020841,1.089842,-290.104767,0.110129,0.000000
7.150001,0.097183,-290.149231,0.004411,0.004434,0.112627,0.432293,0.022022,1.126267,-290.149231,0.113789,0.000000
7.370000,0.121765,-290.149231,0.004592,0.004579,0.116295,0.541638,0.027592,1.162951,-290.149231,0.117466,0.000000
7.590000,0.135170,-290.104767,0.004751,0.004722,0.119937,0.601266,0.030630,1.199373,-290.104767,0.121125,0.000000
7.810000,0.224907,-290.149231,0.004868,0.004874,0.123796,1.000436,0.050965,1.237963,-290.149231,0.124785,0.000000
8.030001,0.739899,-290.149231,0.005057,-0.000005,-0.000139,3.291234,0.167663,-0.001389,-290.149231,0.000043,0.000000
8.250000,0.683670,-290.104767,0.005006,-0.000006,-0.000156,3.041116,0.154922,-0.001563,-290.104767,0.000043,0.000000
8.470000,0.650902,-290.193726,0.004975,-0.000006,-0.000156,2.895356,0.147496,-0.001563,-290.193726,0.000043,0.000000
8.690001,0.648300,-290.149231,0.005001,-0.000006,-0.000156,2.883783,0.146907,-0.001563,-290.149231,0.000338,0.000000
8.910001,0.644943,-290.193726,0.005053,-0.000006,-0.000148,2.868851,0.146146,-0.001476,-290.193726,0.000702,0.000000
9.130000,0.756287,-290.104767,0.005001,0.000010,0.000251,3.364131,0.171377,0.002513,-290.104767,0.001067,0.000000
9.350000,0.910072,-290.149231,0.004993,0.000024,0.000598,4.048204,0.206225,0.005984,-290.149231,0.001439,0.000000
9.570001,1.041893,-290.238220,0.005019,0.000039,0.000980,4.634572,0.236096,0.009799,-290.238220,0.001804,0.000000
9.790001,1.224358,-290.238220,0.005096,0.000052,0.001318,5.446215,0.277443,0.013183,-290.238220,0.002168,0.000000
10.010000,1.380753,-290.193726,0.005092,0.000066,0.001674,6.141894,0.312883,0.016737,-290.193726,0.002541,0.000000
10.230000,1.614235,-290.149231,0.005049,0.000082,0.002073,7.180476,0.365791,0.020726,-290.149231,0.002905,0.000000
10.450001,1.773979,-290.193726,0.005075,0.000095,0.002402,7.891054,0.401989,0.024023,-290.193726,0.003269,0.000000
10.670000,1.998146,-290.238220,0.005062,0.000107,0.002723,8.888198,0.452786,0.027229,-290.238220,0.003633,0.000000
10.890000,2.221947,-290.327179,0.005113,0.000124,0.003157,9.883713,0.503500,0.031566,-290.327179,0.004007,0.000000
11.110001,2.465103,-290.238220,0.005135,0.000141,0.003582,10.965326,0.558600,0.035816,-290.238220,0.004371,0.000000
11.330001,2.696716,-290.238220,0.005131,0.000156,0.003954,11.995593,0.611085,0.039545,-290.238220,0.004735,0.000000
11.550000,2.816994,-290.193726,0.005122,0.000168,0.004275,12.530614,0.638340,0.042754,-290.193726,0.005099,0.000000
11.770000,3.010254,-290.193726,0.005139,0.000180,0.004579,13.390278,0.682133,0.045790,-290.193726,0.005472,0.000000
11.990001,3.179687,-290.282684,0.005182,0.000195,0.004952,14.143956,0.720528,0.049518,-290.282684,0.005836,0.000000
12.210001,3.504768,-290.282684,0.005191,0.000211,0.005351,15.589989,0.794192,0.053507,-290.282684,0.006200,0.000000
12.430000,3.726700,-290.282684,0.005260,0.000226,0.005741,16.577188,0.844482,0.057409,-290.282684,0.006574,0.000000
12.650001,3.850700,-290.238220,0.005260,0.000235,0.005975,17.128771,0.872581,0.059752,-290.238220,0.006938,0.000000
12.870001,4.147850,-290.238220,0.005208,0.000253,0.006426,18.450558,0.939916,0.064260,-290.238220,0.007302,0.000000
13.090000,4.415588,-290.282684,0.005221,0.000270,0.006860,19.641518,1.000587,0.068597,-290.282684,0.007666,0.000000
13.310000,4.588745,-290.327179,0.005260,0.000283,0.007189,20.411758,1.039824,0.071894,-290.327179,0.008039,0.000000
13.530001,4.757797,-290.238220,0.005316,0.000297,0.007536,21.163738,1.078132,0.075361,-290.238220,0.008403,0.000000
13.750001,4.931694,-290.282684,0.005273,0.000309,0.007857,21.937271,1.117538,0.078571,-290.282684,0.008768,0.000000
13.970000,5.123100,-290.282684,0.005329,0.000325,0.008256,22.788689,1.160911,0.082560,-290.282684,0.009141,0.000000
14.190001,5.434402,-290.327179,0.005333,0.000341,0.008655,24.173429,1.231453,0.086549,-290.327179,0.009505,0.000000
14.410001,5.563240,-290.327179,0.005368,0.000354,0.008993,24.746529,1.260648,0.089929,-290.327179,0.009869,0.000000
14.630001,5.651497,-290.327179,0.005333,0.000364,0.009253,25.139114,1.280648,0.092533,-290.327179,0.010233,0.000000
14.850000,5.697670,-290.327179,0.005325,0.000376,0.009557,25.344501,1.291111,0.095569,-290.327179,0.010606,0.000000
15.070001,6.085304,-290.327179,0.005346,0.000394,0.010008,27.068785,1.378950,0.100076,-290.327179,0.010971,0.000000
15.290001,6.290482,-290.327179,0.005385,0.000412,0.010459,27.981459,1.425444,0.104588,-290.327179,0.011335,0.000000
15.510001,6.377617,-290.371643,0.005372,0.000424,0.010771,28.369057,1.445189,0.107711,-290.371643,0.011707,0.000000
15.730000,6.534386,-290.327179,0.005437,0.000439,0.011144,29.066399,1.480713,0.111439,-290.327179,0.012072,0.000000
15.950001,6.719460,-290.282684,0.005411,0.000457,0.011612,29.889648,1.522651,0.116121,-290.282684,0.012436,0.000000
16.170000,6.925377,-290.327179,0.005420,0.000472,0.011985,30.805614,1.569313,0.119849,-290.327179,0.012800,0.000000
16.390001,6.910484,-290.416138,0.005463,0.000482,0.012254,30.739370,1.565938,0.122540,-290.416138,0.013173,0.000000
16.610001,6.977882,-290.371643,0.005437,0.000494,0.012540,31.039171,1.581211,0.125401,-290.371643,0.013537,0.000000
16.830000,7.364037,-290.371643,0.005458,0.000516,0.013104,32.756870,1.668715,0.131037,-290.371643,0.013902,0.000000
17.050001,7.370361,-290.282684,0.005480,0.000528,0.013407,32.785004,1.670148,0.134072,-290.282684,0.014274,0.000000
17.270000,7.444092,-290.416138,0.005523,0.000541,0.013737,33.112972,1.686855,0.137369,-290.416138,0.014639,0.000000
17.490002,7.518570,-290.416138,0.005545,0.000556,0.014118,33.444271,1.703732,0.141184,-290.416138,0.015003,0.000000
17.710001,7.538307,-290.371643,0.005506,0.000566,0.014387,33.532066,1.708205,0.143871,-290.371643,0.015367,0.000000
17.930000,7.661934,-290.327179,0.005558,0.000581,0.014769,34.081985,1.736219,0.147687,-290.327179,0.015740,0.000000
18.150002,7.882378,-290.371643,0.005562,0.000597,0.015176,35.062569,1.786172,0.151763,-290.371643,0.016104,0.000000
18.370001,7.815353,-290.371643,0.005575,0.000608,0.015454,34.764427,1.770984,0.154537,-290.371643,0.016468,0.000000
18.590000,7.973610,-290.371643,0.005605,0.000621,0.015766,35.468388,1.806846,0.157660,-290.371643,0.016841,0.000000
18.810001,8.319168,-290.416138,0.005566,0.000644,0.016347,37.005508,1.885150,0.163470,-290.416138,0.017206,0.000000
19.030001,8.424179,-290.460602,0.005639,0.000659,0.016746,37.472622,1.908946,0.167459,-290.460602,0.017570,0.000000
19.250000,8.358269,-290.371643,0.005622,0.000672,0.017067,37.179436,1.894011,0.170668,-290.371643,0.017934,0.000000
19.470001,8.412636,-290.416138,0.005670,0.000685,0.017405,37.421272,1.906330,0.174052,-290.416138,0.018307,0.000000
19.690001,8.406677,-290.416138,0.005674,0.000697,0.017709,37.394768,1.904980,0.177088,-290.416138,0.018671,0.000000
19.910002,8.586533,-290.460602,0.005678,0.000713,0.018108,38.194805,1.945736,0.181077,-290.460602,0.019035,0.000000
20.130001,8.580948,-290.416138,0.005704,0.000724,0.018385,38.169964,1.944471,0.183851,-290.416138,0.019409,0.000000
20.350000,8.624512,-290.371643,0.005687,0.000738,0.018749,38.363743,1.954342,0.187492,-290.371643,0.019773,0.000000
20.570002,8.786499,-290.460602,0.005708,0.000754,0.019148,39.084301,1.991049,0.191482,-290.460602,0.020137,0.000000
20.790001,9.186424,-290.505096,0.005696,0.000777,0.019729,40.863255,2.081673,0.197291,-290.505096,0.020501,0.000000
21.010000,9.120514,-290.505096,0.005730,0.000790,0.020068,40.570072,2.066738,0.200675,-290.505096,0.020874,0.000000
21.230001,9.098915,-290.460602,0.005790,0.000803,0.020388,40.473995,2.061844,0.203885,-290.460602,0.021238,0.000000
21.450001,9.061310,-290.460602,0.005756,0.000814,0.020666,40.306721,2.053322,0.206659,-290.460602,0.021603,0.000000
21.670000,9.078064,-290.416138,0.005812,0.000825,0.020952,40.381245,2.057119,0.209520,-290.416138,0.021975,0.000000
21.890001,9.348404,-290.460602,0.005777,0.000844,0.021429,41.583778,2.118379,0.214289,-290.460602,0.022340,0.000000
22.110001,9.364792,-290.549561,0.005812,0.000855,0.021724,41.656673,2.122092,0.217238,-290.549561,0.022704,0.000000
22.330002,9.377083,-290.460602,0.005859,0.000868,0.022053,41.711349,2.124877,0.220534,-290.460602,0.023068,0.000000
22.550001,9.501083,-290.460602,0.005855,0.000884,0.022461,42.262928,2.152976,0.224611,-290.460602,0.023441,0.000000
22.770000,9.914413,-290.460602,0.005868,0.000909,0.023077,44.101513,2.246638,0.230769,-290.460602,0.023805,0.000000
22.990002,9.714073,-290.549561,0.005838,0.000919,0.023337,43.210354,2.201241,0.233369,-290.549561,0.024170,0.000000
23.210001,9.774399,-290.549561,0.005907,0.000932,0.023684,43.478699,2.214910,0.236840,-290.549561,0.024542,0.000000
23.430000,9.764717,-290.505096,0.005898,0.000944,0.023970,43.435631,2.212717,0.239701,-290.505096,0.024907,0.000000
23.650002,10.019798,-290.505096,0.005933,0.000961,0.024421,44.570290,2.270519,0.244209,-290.505096,0.025271,0.000000
23.870001,10.124062,-290.505096,0.005946,0.000975,0.024768,45.034077,2.294145,0.247680,-290.505096,0.025635,0.000000
24.090002,10.061127,-290.549561,0.005924,0.000986,0.025037,44.754128,2.279884,0.250367,-290.549561,0.026008,0.000000
24.310001,10.223854,-290.594055,0.005937,0.001001,0.025427,45.477974,2.316758,0.254269,-290.594055,0.026372,0.000000
24.530001,10.531059,-290.505096,0.006023,0.001023,0.025990,46.844490,2.386372,0.259905,-290.505096,0.026736,0.000000
24.750002,10.618942,-290.549561,0.006019,0.001038,0.026372,47.235413,2.406287,0.263724,-290.549561,0.027101,0.000000
24.970001,10.526596,-290.549561,0.005980,0.001050,0.026676,46.824638,2.385361,0.266759,-290.549561,0.027474,0.000000
25.190001,10.547073,-290.549561,0.006006,0.001063,0.026988,46.915726,2.390001,0.269878,-290.549561,0.027838,0.000000
25.410002,10.532555,-290.505096,0.006058,0.001074,0.027274,46.851143,2.386711,0.272743,-290.505096,0.028202,0.000000
25.630001,10.823006,-290.549561,0.006019,0.001093,0.027751,48.143135,2.452528,0.277512,-290.549561,0.028575,0.000000
25.850000,10.817413,-290.549561,0.006049,0.001104,0.028037,48.118259,2.451261,0.280374,-290.549561,0.028939,0.000000
26.070002,10.886307,-290.505096,0.006071,0.001117,0.028376,48.424709,2.466872,0.283757,-290.505096,0.029303,0.000000
26.290001,10.976418,-290.594055,0.006096,0.001130,0.028696,48.825542,2.487292,0.286963,-290.594055,0.029668,0.000000
26.510002,11.305595,-290.594055,0.006075,0.001152,0.029252,50.289799,2.561884,0.292516,-290.594055,0.030041,0.000000
26.730001,11.414330,-290.638519,0.006170,0.001168,0.029659,50.773472,2.586524,0.296592,-290.638519,0.030405,0.000000
26.950001,11.336128,-290.549561,0.006105,0.001179,0.029937,50.425617,2.568803,0.299366,-290.549561,0.030769,0.000000
27.170002,11.420662,-290.549561,0.006118,0.001193,0.030309,50.801643,2.587959,0.303094,-290.549561,0.031142,0.000000
27.390001,11.370766,-290.638519,0.006178,0.001204,0.030587,50.579693,2.576652,0.305869,-290.638519,0.031506,0.000000
27.610001,11.613548,-290.638519,0.006140,0.001222,0.031038,51.659641,2.631668,0.310380,-290.638519,0.031870,0.000000
27.830002,11.602753,-290.638519,0.006217,0.001233,0.031315,51.611622,2.629221,0.313155,-290.638519,0.032235,0.000000
28.050001,11.688026,-290.594055,0.006239,0.001246,0.031636,51.990936,2.648545,0.316364,-290.594055,0.032608,0.000000
28.270000,11.871979,-290.594055,0.006209,0.001262,0.032044,52.809200,2.690229,0.320441,-290.594055,0.032972,0.000000
28.490002,12.284935,-290.638519,0.006187,0.001284,0.032608,54.646122,2.783806,0.326076,-290.638519,0.033336,0.000000
28.710001,12.134499,-290.683014,0.006260,0.001293,0.032833,53.976944,2.749717,0.328332,-290.683014,0.033709,0.000000
28.930002,12.031723,-290.638519,0.006299,0.001302,0.033076,53.519775,2.726427,0.330758,-290.638519,0.034073,0.000000
29.150002,12.201149,-290.638519,0.006243,0.001317,0.033449,54.273422,2.764820,0.334486,-290.638519,0.034438,0.000000
29.370001,12.340424,-290.594055,0.006239,0.001333,0.033848,54.892944,2.796380,0.338476,-290.594055,0.034802,0.000000
29.590002,12.654327,-290.683014,0.006295,0.001351,0.034307,56.289261,2.867512,0.343074,-290.683014,0.035175,0.000000
29.810001,12.779816,-290.638519,0.006308,0.001366,0.034689,56.847458,2.895948,0.346889,-290.638519,0.035539,0.000000
30.030001,12.608154,-290.638519,0.006351,0.001374,0.034897,56.083870,2.857049,0.348971,-290.638519,0.035903,0.000000
30.250002,12.828598,-290.638519,0.006316,0.001390,0.035313,57.064453,2.907002,0.353134,-290.638519,0.036276,0.000000
30.470001,13.180122,-290.683014,0.006381,0.001409,0.035799,58.628113,2.986658,0.357991,-290.683014,0.036640,0.000000
30.690001,13.238953,-290.638519,0.006385,0.001423,0.036137,58.889801,2.999990,0.361370,-290.638519,0.037005,0.000000
30.910002,13.246773,-290.727509,0.006390,0.001436,0.036484,58.924587,3.001761,0.364841,-290.727509,0.037369,0.000000
31.130001,13.425888,-290.683014,0.006420,0.001451,0.036848,59.721333,3.042350,0.368482,-290.683014,0.037741,0.000000
31.350002,13.520470,-290.683014,0.006420,0.001465,0.037204,60.142052,3.063782,0.372040,-290.683014,0.038106,0.000000
31.570002,13.711868,-290.683014,0.006446,0.001480,0.037594,60.993435,3.107154,0.375942,-290.683014,0.038470,0.000000
31.790001,13.805702,-290.727509,0.006420,0.001495,0.037976,61.410831,3.128417,0.379757,-290.727509,0.038843,0.000000
32.010002,13.866776,-290.727509,0.006437,0.001507,0.038288,61.682499,3.142256,0.382880,-290.727509,0.039207,0.000000
32.230003,14.064133,-290.727509,0.006472,0.001523,0.038696,62.560387,3.186978,0.386956,-290.727509,0.039571,0.000000
32.450001,14.313622,-290.638519,0.006467,0.001541,0.039138,63.670170,3.243513,0.391377,-290.638519,0.039936,0.000000
32.670002,14.384369,-290.683014,0.006541,0.001554,0.039476,63.984867,3.259545,0.394761,-290.683014,0.040309,0.000000
32.890003,14.408951,-290.683014,0.006523,0.001567,0.039806,64.094215,3.265115,0.398057,-290.683014,0.040673,0.000000
33.110001,14.431290,-290.771973,0.006554,0.001579,0.040101,64.193581,3.270177,0.401006,-290.771973,0.041037,0.000000
33.330002,14.604073,-290.771973,0.006549,0.001596,0.040543,64.962158,3.309330,0.405427,-290.771973,0.041410,0.000000
33.550003,14.826378,-290.727509,0.006558,0.001611,0.040915,65.951019,3.359705,0.409155,-290.727509,0.041774,0.000000
33.770000,14.992081,-290.771973,0.006554,0.001625,0.041271,66.688103,3.397254,0.412713,-290.771973,0.042138,0.000000
33.990002,14.916496,-290.683014,0.006562,0.001634,0.041497,66.351891,3.380126,0.414968,-290.683014,0.042502,0.000000
34.210003,15.374886,-290.771973,0.006605,0.001655,0.042034,68.390907,3.483999,0.420343,-290.771973,0.042876,0.000000
34.430000,15.648201,-290.771973,0.006601,0.001670,0.042425,69.606674,3.545933,0.424245,-290.771973,0.043240,0.000000
34.650002,15.657516,-290.771973,0.006648,0.001683,0.042754,69.648109,3.548044,0.427542,-290.771973,0.043604,0.000000
34.870003,15.679482,-290.771973,0.006644,0.001697,0.043093,69.745819,3.553021,0.430925,-290.771973,0.043977,0.000000
35.090000,15.769226,-290.771973,0.006627,0.001708,0.043396,70.145020,3.573358,0.433957,-290.771973,0.044341,0.000000
35.310001,16.108826,-290.860931,0.006653,0.001727,0.043864,71.655632,3.650312,0.438643,-290.860931,0.044705,0.000000
35.530003,16.235809,-290.860931,0.006661,0.001740,0.044185,72.220490,3.679087,0.441852,-290.860931,0.045070,0.000000
35.750000,16.330391,-290.727509,0.006674,0.001753,0.044523,72.641205,3.700519,0.445232,-290.727509,0.045443,0.000000
35.970001,16.281235,-290.771973,0.006709,0.001764,0.044809,72.422546,3.689380,0.448094,-290.771973,0.045807,0.000000
36.190002,16.510246,-290.771973,0.006713,0.001780,0.045200,73.441246,3.741275,0.451996,-290.771973,0.046171,0.000000
36.410000,16.759735,-290.905426,0.006752,0.001792,0.045529,74.551025,3.797810,0.455293,-290.905426,0.046544,0.000000
36.630001,17.212914,-290.860931,0.006730,0.001814,0.046067,76.566864,3.900502,0.460671,-290.860931,0.046908,0.000000
36.850002,17.218498,-290.771973,0.006804,0.001825,0.046353,76.591705,3.901767,0.463532,-290.771973,0.047273,0.000000
37.070004,17.378616,-290.771973,0.006765,0.001841,0.046752,77.303947,3.938051,0.467522,-290.771973,0.047637,0.000000
37.290001,17.755829,-290.816467,0.006765,0.001857,0.047177,78.981873,4.023529,0.471768,-290.816467,0.048009,0.000000
37.510002,17.994896,-290.816467,0.006817,0.001873,0.047567,80.045296,4.077702,0.475674,-290.816467,0.048374,0.000000
37.730003,17.785622,-290.860931,0.006851,0.001882,0.047793,79.114395,4.030280,0.477926,-290.860931,0.048738,0.000000
37.950001,17.948349,-290.816467,0.006812,0.001895,0.048122,79.838242,4.067154,0.481223,-290.816467,0.049102,0.000000
38.170002,18.566856,-290.727509,0.006873,0.001916,0.048677,82.589500,4.207310,0.486772,-290.727509,0.049475,0.000000
38.390003,18.491272,-290.860931,0.006864,0.001928,0.048964,82.253288,4.190182,0.489637,-290.860931,0.049839,0.000000
38.610001,18.652130,-290.905426,0.006855,0.001942,0.049319,82.968819,4.226633,0.493191,-290.905426,0.050204,0.000000
38.830002,18.834969,-290.905426,0.006911,0.001955,0.049657,83.782127,4.268065,0.496574,-290.905426,0.050576,0.000000
39.050003,18.805176,-290.905426,0.006855,0.001966,0.049926,83.649597,4.261314,0.499262,-290.905426,0.050941,0.000000
39.270000,19.133614,-290.816467,0.006903,0.001982,0.050334,85.110565,4.335739,0.503338,-290.816467,0.051305,0.000000
39.490002,19.559235,-290.905426,0.006903,0.001999,0.050767,87.003822,4.432186,0.507672,-290.905426,0.051669,0.000000
39.710003,19.474701,-290.905426,0.006954,0.002008,0.051001,86.627800,4.413031,0.510015,-290.905426,0.052042,0.000000
39.930000,19.630730,-290.860931,0.006929,0.002020,0.051314,87.321846,4.448387,0.513137,-290.860931,0.052406,0.000000
40.150002,20.620125,-290.860931,0.006950,0.002045,0.051947,91.722893,4.672587,0.519469,-290.860931,0.052771,0.000000
40.370003,20.718803,-290.860931,0.006980,0.002059,0.052302,92.161842,4.694948,0.523023,-290.860931,0.053143,0.000000
40.590000,20.696457,-290.949890,0.006950,0.002072,0.052623,92.062439,4.689884,0.526233,-290.949890,0.053508,0.000000
40.810001,20.859932,-290.994385,0.007023,0.002085,0.052961,92.789612,4.726928,0.529613,-290.994385,0.053872,0.000000
41.030003,20.820457,-290.905426,0.006989,0.002096,0.053230,92.614021,4.717983,0.532304,-290.905426,0.054236,0.000000
41.250004,21.282204,-290.905426,0.007041,0.002113,0.053672,94.667969,4.822616,0.536725,-290.905426,0.054609,0.000000
41.470001,21.235657,-290.905426,0.007015,0.002123,0.053915,94.460922,4.812069,0.539155,-290.905426,0.054973,0.000000
41.690002,21.631485,-290.949890,0.007006,0.002138,0.054314,96.221649,4.901764,0.543144,-290.949890,0.055337,0.000000
41.910004,22.104401,-290.994385,0.007032,0.002155,0.054748,98.325287,5.008929,0.547477,-290.994385,0.055711,0.000000
42.130001,22.820847,-290.949890,0.007049,0.002177,0.055294,101.512192,5.171278,0.552943,-290.949890,0.056075,0.000000
42.350002,22.889359,-290.949890,0.007101,0.002190,0.055632,101.816956,5.186802,0.556323,-290.949890,0.056439,0.000000
42.570004,22.932556,-290.949890,0.007080,0.002203,0.055962,102.009102,5.196591,0.559619,-290.949890,0.056803,0.000000
42.790001,22.857704,-290.994385,0.007075,0.002213,0.056214,101.676147,5.179630,0.562136,-290.994385,0.057176,0.000000
43.010002,23.201035,-291.038849,0.007118,0.002229,0.056621,103.203354,5.257430,0.566213,-291.038849,0.057540,0.000000
43.230003,23.529465,-291.038849,0.007157,0.002244,0.056985,104.664284,5.331853,0.569854,-291.038849,0.057905,0.000000
43.450001,23.600220,-290.949890,0.007127,0.002253,0.057237,104.979019,5.347886,0.572367,-290.949890,0.058278,0.000000
43.670002,23.893272,-290.905426,0.007183,0.002268,0.057601,106.282585,5.414293,0.576012,-290.905426,0.058642,0.000000
43.890003,24.293579,-290.994385,0.007136,0.002284,0.058026,108.063240,5.505003,0.580258,-290.994385,0.059006,0.000000
44.110001,25.380157,-291.083344,0.007179,0.002308,0.058616,112.896576,5.751225,0.586155,-291.083344,0.059370,0.000000
44.330002,25.228233,-291.038849,0.007243,0.002317,0.058850,112.220787,5.716799,0.588498,-291.038849,0.059743,0.000000
44.550003,25.438995,-290.994385,0.007196,0.002331,0.059214,113.158302,5.764559,0.592139,-290.994385,0.060107,0.000000
44.770000,25.475487,-291.038849,0.007209,0.002342,0.059492,113.320625,5.772828,0.594917,-291.038849,0.060472,0.000000
44.990002,26.184486,-290.994385,0.007239,0.002362,0.059986,116.474411,5.933489,0.599860,-290.994385,0.060844,0.000000
45.210003,26.385193,-291.038849,0.007200,0.002374,0.060290,117.367203,5.978971,0.602896,-291.038849,0.061209,0.000000
45.430000,26.390778,-291.038849,0.007265,0.002384,0.060558,117.392044,5.980236,0.605583,-291.038849,0.061573,0.000000
45.650002,26.879700,-290.994385,0.007282,0.002400,0.060957,119.566879,6.091027,0.609572,-290.994385,0.061937,0.000000
45.870003,27.654610,-291.038849,0.007274,0.002421,0.061503,123.013847,6.266624,0.615034,-291.038849,0.062310,0.000000
46.090004,28.267166,-290.994385,0.007321,0.002438,0.061920,125.738632,6.405431,0.619197,-290.994385,0.062674,0.000000
46.310001,28.036293,-291.083344,0.007347,0.002447,0.062145,124.711662,6.353115,0.621453,-291.083344,0.063039,0.000000
46.530003,28.326744,-291.038849,0.007325,0.002461,0.062501,126.003654,6.418932,0.625007,-291.038849,0.063411,0.000000
46.750004,28.492821,-290.994385,0.007351,0.002472,0.062796,126.742393,6.456566,0.627956,-290.994385,0.063776,0.000000
46.970001,29.374596,-291.038849,0.007381,0.002492,0.063299,130.664734,6.656378,0.632986,-291.038849,0.064140,0.000000
47.190002,29.441254,-291.038849,0.007373,0.002501,0.063533,130.961243,6.671484,0.635329,-291.038849,0.064504,0.000000
47.410004,29.715691,-291.127838,0.007368,0.002516,0.063897,132.181992,6.733672,0.638970,-291.127838,0.064877,0.000000
47.630001,30.172592,-291.038849,0.007390,0.002529,0.064235,134.214386,6.837207,0.642353,-291.038849,0.065241,0.000000
47.850002,31.065544,-291.083344,0.007429,0.002551,0.064808,138.186447,7.039553,0.648076,-291.083344,0.065605,0.000000
48.070004,31.662453,-291.038849,0.007390,0.002567,0.065198,140.841629,7.174814,0.651978,-291.038849,0.065978,0.000000
48.290001,31.680328,-291.083344,0.007429,0.002577,0.065467,140.921143,7.178865,0.654670,-291.083344,0.066343,0.000000
48.510002,32.049721,-291.038849,0.007420,0.002592,0.065831,142.564285,7.262571,0.658311,-291.038849,0.066707,0.000000
48.730003,32.028122,-291.127838,0.007437,0.002602,0.066100,142.468201,7.257676,0.660998,-291.127838,0.067071,0.000000
48.950001,32.753510,-291.083344,0.007459,0.002620,0.066542,145.694885,7.422051,0.665422,-291.083344,0.067444,0.000000
49.170002,33.048050,-291.083344,0.007476,0.002630,0.066802,147.005066,7.488795,0.668023,-291.083344,0.067808,0.000000
49.390003,33.422287,-291.083344,0.007437,0.002644,0.067166,148.669754,7.573598,0.671664,-291.083344,0.068172,0.000000
49.610001,34.006165,-291.172302,0.007506,0.002660,0.067557,151.266968,7.705907,0.675570,-291.172302,0.068546,0.000000
49.830002,35.112862,-291.127838,0.007532,0.002683,0.068155,156.189804,7.956688,0.681554,-291.127838,0.068910,0.000000
50.050003,35.103180,-291.083344,0.007519,0.002691,0.068355,156.146744,7.954494,0.683548,-291.083344,0.069274,0.000000
50.270004,35.109131,-291.127838,0.007519,0.002702,0.068624,156.173218,7.955843,0.686236,-291.127838,0.069638,0.000000
50.490002,35.602898,-291.127838,0.007532,0.002716,0.068979,158.369598,8.067732,0.689790,-291.127838,0.070011,0.000000
50.710003,36.219551,-291.172302,0.007571,0.002733,0.069430,161.112610,8.207467,0.694301,-291.172302,0.070375,0.000000
50.930004,37.020523,-291.127838,0.007580,0.002750,0.069855,164.675507,8.388970,0.698548,-291.127838,0.070740,0.000000
51.150002,37.612968,-291.127838,0.007545,0.002764,0.070211,167.310837,8.523220,0.702106,-291.127838,0.071104,0.000000
51.370003,37.568283,-291.172302,0.007601,0.002773,0.070445,167.112076,8.513094,0.704448,-291.172302,0.071477,0.000000
51.590004,38.199081,-291.127838,0.007580,0.002790,0.070870,169.917999,8.656035,0.708695,-291.127838,0.071841,0.000000
51.810001,38.936378,-291.172302,0.007593,0.002807,0.071295,173.197662,8.823110,0.712946,-291.172302,0.072205,0.000000
52.030003,39.610748,-291.261261,0.007623,0.002822,0.071676,176.197403,8.975924,0.716761,-291.261261,0.072578,0.000000
52.250004,40.079193,-291.172302,0.007618,0.002836,0.072040,178.281158,9.082075,0.720402,-291.172302,0.072942,0.000000
52.470001,40.619499,-291.172302,0.007618,0.002849,0.072370,180.684555,9.204510,0.723698,-291.172302,0.073307,0.000000
52.690002,41.082359,-291.261261,0.007675,0.002863,0.072726,182.743454,9.309396,0.727256,-291.261261,0.073671,0.000000
52.910004,41.695656,-291.172302,0.007614,0.002878,0.073098,185.471542,9.448371,0.730984,-291.172302,0.074044,0.000000
53.130001,42.234856,-291.216797,0.007653,0.002893,0.073471,187.870026,9.570555,0.734712,-291.216797,0.074408,0.000000
53.350002,42.799370,-291.172302,0.007649,0.002905,0.073792,190.381104,9.698475,0.737922,-291.172302,0.074772,0.000000
53.570004,43.568695,-291.216797,0.007636,0.002922,0.074226,193.803238,9.872808,0.742260,-291.216797,0.075145,0.000000
53.790001,44.284019,-291.261261,0.007709,0.002938,0.074633,196.985153,10.034903,0.746332,-291.261261,0.075509,0.000000
54.010002,44.969185,-291.261261,0.007675,0.002953,0.075006,200.032928,10.190163,0.750064,-291.261261,0.075874,0.000000
54.230003,45.379539,-291.216797,0.007705,0.002966,0.075327,201.858276,10.283151,0.753270,-291.216797,0.076238,0.000000
54.450001,45.752655,-291.216797,0.007696,0.002978,0.075631,203.517975,10.367700,0.756305,-291.216797,0.076611,0.000000
54.670002,46.231903,-291.261261,0.007709,0.002994,0.076047,205.649780,10.476299,0.760469,-291.261261,0.076975,0.000000
54.890003,47.325554,-291.261261,0.007743,0.003010,0.076446,210.514572,10.724124,0.764458,-291.261261,0.077339,0.000000
55.110004,47.820442,-291.261261,0.007722,0.003023,0.076784,212.715958,10.836267,0.767842,-291.261261,0.077712,0.000000
55.330002,48.063599,-291.261261,0.007787,0.003033,0.077027,213.797562,10.891367,0.770268,-291.261261,0.078076,0.000000
55.550003,48.924896,-291.261261,0.007778,0.003050,0.077469,217.628815,11.086540,0.774692,-291.261261,0.078440,0.000000
55.770004,50.096008,-291.216797,0.007782,0.003068,0.077929,222.838181,11.351917,0.779287,-291.216797,0.078805,0.000000
55.990002,50.562218,-291.261261,0.007795,0.003080,0.078224,224.911972,11.457562,0.782236,-291.261261,0.079178,0.000000
56.210003,51.147591,-291.305756,0.007795,0.003094,0.078579,227.515839,11.590210,0.785793,-291.305756,0.079542,0.000000
56.430004,51.772804,-291.216797,0.007804,0.003107,0.078909,230.296936,11.731885,0.789086,-291.216797,0.079906,0.000000
56.650002,52.672829,-291.261261,0.007795,0.003125,0.079377,234.300446,11.935834,0.793772,-291.261261,0.080279,0.000000
56.870003,53.505821,-291.216797,0.007804,0.003138,0.079698,238.005783,12.124592,0.796982,-291.216797,0.080643,0.000000
57.090004,54.157104,-291.305756,0.007804,0.003152,0.080054,240.902832,12.272176,0.800536,-291.305756,0.081007,0.000000
57.310001,54.477341,-291.261261,0.007838,0.003162,0.080314,242.327316,12.344742,0.803136,-291.261261,0.081372,0.000000
57.530003,55.111496,-291.305756,0.007877,0.003178,0.080721,245.148178,12.488443,0.807212,-291.305756,0.081745,0.000000
57.750004,56.044289,-291.261261,0.007860,0.003193,0.081094,249.297440,12.699818,0.810940,-291.261261,0.082109,0.000000
57.970001,57.180397,-291.305756,0.007860,0.003211,0.081571,254.351105,12.957263,0.815713,-291.305756,0.082473,0.000000
58.190002,57.808960,-291.350220,0.007886,0.003223,0.081875,257.147095,13.099697,0.818748,-291.350220,0.082846,0.000000
58.410004,58.586098,-291.394714,0.007869,0.003239,0.082282,260.603973,13.275800,0.822825,-291.394714,0.083210,0.000000
58.630001,59.726303,-291.350220,0.007912,0.003257,0.082716,265.675873,13.534174,0.827159,-291.350220,0.083575,0.000000
58.850002,60.515732,-291.305756,0.007894,0.003271,0.083080,269.187408,13.713061,0.830800,-291.305756,0.083939,0.000000
59.070004,60.859062,-291.305756,0.007894,0.003279,0.083297,270.714630,13.790860,0.832968,-291.305756,0.084312,0.000000
59.290001,61.369209,-291.439178,0.007894,0.003292,0.083626,272.983887,13.906461,0.836265,-291.439178,0.084676,0.000000
59.510002,62.979355,-291.305756,0.007942,0.003314,0.084181,280.146149,14.271326,0.841814,-291.305756,0.085040,0.000000
59.730003,63.535675,-291.439178,0.007950,0.003326,0.084485,282.620789,14.397390,0.844849,-291.439178,0.085413,0.000000
59.950005,64.232391,-291.350220,0.007946,0.003338,0.084780,285.719940,14.555268,0.847798,-291.350220,0.085777,0.000000
60.170002,65.094421,-291.394714,0.007950,0.003353,0.085170,289.554443,14.750607,0.851700,-291.394714,0.086142,0.000000
60.390003,65.567337,-291.394714,0.007968,0.003364,0.085456,291.658081,14.857771,0.854565,-291.394714,0.086506,0.000000
60.610004,66.342621,-291.394714,0.007963,0.003379,0.085821,295.106720,15.033453,0.858206,-291.394714,0.086878,0.000000
60.830002,67.180084,-291.394714,0.007998,0.003381,0.085881,298.831940,15.223225,0.858812,-291.394714,0.086133,0.000000
61.050003,66.503860,-291.394714,0.007959,0.003381,0.085881,295.823944,15.069990,0.858812,-291.394714,0.086133,0.000000
61.270004,65.876038,-291.394714,0.007950,0.003377,0.085777,293.031250,14.927724,0.857771,-291.394714,0.085881,0.000000
61.490002,65.351730,-291.394714,0.008002,0.003376,0.085743,290.699005,14.808913,0.857426,-291.394714,0.085881,0.000000
61.710003,64.859833,-291.439178,0.007981,0.003375,0.085725,288.510956,14.697448,0.857252,-291.439178,0.085881,0.000000
61.930004,64.407394,-291.394714,0.008002,0.003375,0.085717,286.498413,14.594925,0.857165,-291.394714,0.085881,0.000000
62.150002,64.010452,-291.394714,0.007955,0.003374,0.085708,284.732727,14.504975,0.857078,-291.394714,0.085881,0.000000
62.370003,63.648499,-291.350220,0.008024,0.003374,0.085699,283.122650,14.422956,0.856991,-291.350220,0.085881,0.000000
62.590004,63.314117,-291.483673,0.008032,0.003374,0.085699,281.635254,14.347184,0.856991,-291.483673,0.085881,0.000000
62.810001,63.007652,-291.483673,0.008024,0.003374,0.085690,280.272034,14.277739,0.856904,-291.483673,0.085881,0.000000
63.030003,62.710495,-291.394714,0.008006,0.003374,0.085690,278.950226,14.210401,0.856904,-291.394714,0.085881,0.000000
63.250004,62.466591,-291.394714,0.008015,0.003374,0.085690,277.865265,14.155131,0.856904,-291.394714,0.085881,0.000000
63.470001,62.206306,-291.394714,0.007963,0.003374,0.085690,276.707458,14.096151,0.856904,-291.394714,0.085881,0.000000
63.690002,61.958305,-291.394714,0.008024,0.003373,0.085682,275.604309,14.039953,0.856817,-291.394714,0.085881,0.000000
63.910004,61.750893,-291.528168,0.008024,0.003373,0.085682,274.681702,13.992952,0.856817,-291.528168,0.085881,0.000000
64.130005,61.544975,-291.439178,0.008032,0.003373,0.085682,273.765717,13.946291,0.856817,-291.439178,0.085881,0.000000
64.350006,61.365120,-291.439178,0.008002,0.003373,0.085682,272.965698,13.905535,0.856817,-291.439178,0.085881,0.000000
64.570000,61.172600,-291.483673,0.008019,0.003373,0.085682,272.109314,13.861909,0.856817,-291.483673,0.085881,0.000000
64.790001,60.990135,-291.483673,0.008032,0.003373,0.085682,271.297668,13.820562,0.856817,-291.483673,0.085881,0.000000
65.010002,60.827042,-291.483673,0.008032,0.003373,0.085682,270.572205,13.783605,0.856817,-291.483673,0.085881,0.000000
65.230003,60.661331,-291.483673,0.008041,0.003373,0.085682,269.835083,13.746054,0.856817,-291.483673,0.085881,0.000000
65.450005,60.523552,-291.483673,0.007998,0.003373,0.085682,269.222198,13.714833,0.856817,-291.483673,0.085881,0.000000
65.670006,60.374603,-291.439178,0.008011,0.003373,0.085682,268.559662,13.681081,0.856817,-291.439178,0.085881,0.000000
65.889999,60.241669,-291.483673,0.008024,0.003373,0.085682,267.968323,13.650957,0.856817,-291.483673,0.085881,0.000000
66.110001,60.095329,-291.528168,0.008054,0.003373,0.085682,267.317383,13.617797,0.856817,-291.528168,0.085881,0.000000
66.330002,59.968346,-291.483673,0.007998,0.003373,0.085682,266.752533,13.589022,0.856817,-291.483673,0.085881,0.000000
66.550003,59.851791,-291.528168,0.008028,0.003373,0.085682,266.234070,13.562610,0.856817,-291.528168,0.085881,0.000000
66.770004,59.732262,-291.483673,0.007989,0.003373,0.085673,265.702362,13.535523,0.856730,-291.483673,0.085881,0.000000
66.990005,59.629486,-291.528168,0.008015,0.003373,0.085673,265.245209,13.512235,0.856730,-291.528168,0.085881,0.000000
67.210007,59.531181,-291.528168,0.008002,0.003373,0.085673,264.807922,13.489958,0.856730,-291.528168,0.085881,0.000000
67.430000,59.428780,-291.528168,0.008063,0.003373,0.085673,264.352417,13.466754,0.856730,-291.528168,0.085881,0.000000
67.650002,59.323769,-291.528168,0.008037,0.003373,0.085673,263.885315,13.442958,0.856730,-291.528168,0.085881,0.000000
67.870003,59.209450,-291.617126,0.008045,0.003373,0.085673,263.376801,13.417053,0.856730,-291.617126,0.085881,0.000000
68.090004,59.116356,-291.572632,0.008037,0.003373,0.085673,262.962677,13.395958,0.856730,-291.572632,0.085881,0.000000
68.310005,59.039650,-291.528168,0.007985,0.003373,0.085673,262.621490,13.378576,0.856730,-291.528168,0.085881,0.000000
68.530006,58.946182,-291.528168,0.008058,0.003373,0.085673,262.205719,13.357396,0.856730,-291.528168,0.085881,0.000000
68.750000,58.850487,-291.617126,0.008058,0.003373,0.085673,261.780029,13.335711,0.856730,-291.617126,0.085881,0.000000
68.970001,58.778618,-291.617126,0.008011,0.003373,0.085673,261.460358,13.319426,0.856730,-291.617126,0.085881,0.000000
69.190002,58.684410,-291.572632,0.008032,0.003373,0.085673,261.041290,13.298078,0.856730,-291.572632,0.085881,0.000000
69.410004,58.609558,-291.617126,0.008024,0.003373,0.085673,260.708344,13.281116,0.856730,-291.617126,0.085881,0.000000
69.630005,58.516098,-291.572632,0.008054,0.003373,0.085673,260.292603,13.259937,0.856730,-291.572632,0.085881,0.000000
69.850006,58.462471,-291.528168,0.008011,0.003373,0.085673,260.054047,13.247786,0.856730,-291.528168,0.085881,0.000000
70.070000,58.383156,-291.572632,0.008045,0.003373,0.085673,259.701233,13.229813,0.856730,-291.572632,0.085881,0.000000
70.290001,58.294907,-291.572632,0.008071,0.003373,0.085665,259.308685,13.209815,0.856647,-291.572632,0.085881,0.000000
70.510002,58.229744,-291.661591,0.008058,0.003373,0.085665,259.018829,13.195048,0.856647,-291.661591,0.085881,0.000000
70.730003,58.160851,-291.661591,0.008045,0.003373,0.085665,258.712372,13.179438,0.856647,-291.661591,0.085881,0.000000
70.950005,58.088242,-291.572632,0.008011,0.003373,0.085665,258.389404,13.162984,0.856647,-291.572632,0.085881,0.000000
71.170006,58.017113,-291.572632,0.008037,0.003373,0.085665,258.072998,13.146866,0.856647,-291.572632,0.085881,0.000000
71.390007,57.962379,-291.661591,0.007998,0.003373,0.085665,257.829529,13.134463,0.856647,-291.661591,0.085881,0.000000
71.610001,57.903168,-291.706085,0.008080,0.003373,0.085665,257.566162,13.121045,0.856647,-291.706085,0.085881,0.000000
71.830002,57.853645,-291.617126,0.008037,0.003373,0.085665,257.345856,13.109823,0.856647,-291.617126,0.085881,0.000000
72.050003,57.792946,-291.661591,0.008015,0.003373,0.085665,257.075867,13.096068,0.856647,-291.661591,0.085881,0.000000
72.270004,57.751244,-291.617126,0.008045,0.003373,0.085665,256.890350,13.086618,0.856647,-291.617126,0.085881,0.000000
72.490005,57.677139,-291.661591,0.008058,0.003373,0.085665,256.560730,13.069826,0.856647,-291.661591,0.085881,0.000000
72.710007,57.622398,-291.661591,0.008071,0.003373,0.085665,256.317230,13.057422,0.856647,-291.661591,0.085881,0.000000
72.930000,57.572502,-291.661591,0.008054,0.003373,0.085665,256.095276,13.046116,0.856647,-291.661591,0.085881,0.000000
73.150002,57.513298,-291.706085,0.008050,0.003373,0.085665,255.831924,13.032700,0.856647,-291.706085,0.085881,0.000000
73.370003,57.470100,-291.617126,0.008063,0.003373,0.085665,255.639771,13.022911,0.856647,-291.617126,0.085881,0.000000
73.590004,57.414246,-291.661591,0.008011,0.003373,0.085665,255.391327,13.010254,0.856647,-291.661591,0.085881,0.000000
73.810005,57.362114,-291.661591,0.008024,0.003373,0.085665,255.159424,12.998441,0.856647,-291.661591,0.085881,0.000000
74.030006,57.321899,-291.750549,0.008006,0.003373,0.085665,254.980545,12.989328,0.856647,-291.750549,0.085881,0.000000
74.250000,57.275719,-291.706085,0.008071,0.003373,0.085665,254.775116,12.978864,0.856647,-291.706085,0.085881,0.000000
74.470001,57.207581,-291.750549,0.008015,0.003373,0.085665,254.472031,12.963423,0.856647,-291.750549,0.085881,0.000000
74.690002,57.172577,-291.706085,0.008067,0.003373,0.085665,254.316330,12.955491,0.856647,-291.706085,0.085881,0.000000
74.910004,57.123795,-291.750549,0.008011,0.003373,0.085665,254.099335,12.944437,0.856647,-291.750549,0.085881,0.000000
75.130005,57.086555,-291.706085,0.008067,0.003373,0.085665,253.933685,12.935998,0.856647,-291.706085,0.085881,0.000000
75.350006,57.046341,-291.617126,0.008002,0.003373,0.085665,253.754791,12.926886,0.856647,-291.617126,0.085881,0.000000
75.570007,57.004639,-291.706085,0.008011,0.003373,0.085665,253.569290,12.917437,0.856647,-291.706085,0.085881,0.000000
75.790001,56.968513,-291.795044,0.008037,0.003373,0.085665,253.408600,12.909249,0.856647,-291.795044,0.085881,0.000000
76.010002,56.908562,-291.750549,0.008058,0.003373,0.085665,253.141922,12.895664,0.856647,-291.750549,0.085881,0.000000
76.230003,56.872070,-291.706085,0.008058,0.003373,0.085665,252.979599,12.887396,0.856647,-291.706085,0.085881,0.000000
76.450005,56.829247,-291.706085,0.008071,0.003373,0.085665,252.789108,12.877691,0.856647,-291.706085,0.085881,0.000000
76.670006,56.793503,-291.750549,0.008063,0.003373,0.085665,252.630112,12.869592,0.856647,-291.750549,0.085881,0.000000
76.890007,56.747696,-291.795044,0.008045,0.003373,0.085665,252.426361,12.859212,0.856647,-291.795044,0.085881,0.000000
77.110001,56.727219,-291.795044,0.008080,0.003373,0.085665,252.335266,12.854572,0.856647,-291.795044,0.085881,0.000000
77.330002,56.683647,-291.750549,0.008054,0.003373,0.085665,252.141449,12.844698,0.856647,-291.750549,0.085881,0.000000
77.550003,56.654602,-291.706085,0.008024,0.003373,0.085665,252.012253,12.838117,0.856647,-291.706085,0.085881,0.000000
77.770004,56.606194,-291.750549,0.008075,0.003373,0.085665,251.796921,12.827147,0.856647,-291.750549,0.085881,0.000000
77.990005,56.571190,-291.795044,0.008067,0.003373,0.085665,251.641220,12.819215,0.856647,-291.795044,0.085881,0.000000
78.210007,56.525017,-291.795044,0.008032,0.003373,0.085665,251.435837,12.808752,0.856647,-291.795044,0.085881,0.000000
78.430000,56.488152,-291.795044,0.008071,0.003373,0.085665,251.271851,12.800398,0.856647,-291.795044,0.085881,0.000000
78.650002,56.453148,-291.795044,0.008071,0.003373,0.085665,251.116150,12.792466,0.856647,-291.795044,0.085881,0.000000
78.870003,56.421127,-291.795044,0.008015,0.003373,0.085665,250.973709,12.785210,0.856647,-291.795044,0.085881,0.000000
79.090004,56.386124,-291.839508,0.008045,0.003373,0.085665,250.818008,12.777278,0.856647,-291.839508,0.085881,0.000000
79.310005,56.361176,-291.839508,0.008037,0.003373,0.085665,250.707031,12.771626,0.856647,-291.839508,0.085881,0.000000
79.530006,56.326546,-291.750549,0.008019,0.003373,0.085665,250.552994,12.763778,0.856647,-291.750549,0.085881,0.000000
79.750000,56.295639,-291.795044,0.008063,0.003373,0.085665,250.415512,12.756774,0.856647,-291.795044,0.085881,0.000000
79.970001,56.254303,-291.795044,0.008097,0.003373,0.085665,250.231644,12.747408,0.856647,-291.795044,0.085881,0.000000
80.190002,56.225258,-291.795044,0.008054,0.003373,0.085665,250.102432,12.740826,0.856647,-291.795044,0.085881,0.000000
80.410004,56.185417,-291.839508,0.008101,0.003373,0.085665,249.925217,12.731797,0.856647,-291.839508,0.085881,0.000000
80.630005,56.150787,-291.795044,0.008058,0.003373,0.085665,249.771179,12.723950,0.856647,-291.795044,0.085881,0.000000
80.850006,56.133286,-291.839508,0.008075,0.003373,0.085665,249.693329,12.719984,0.856647,-291.839508,0.085881,0.000000
81.070007,56.111313,-291.839508,0.008024,0.003373,0.085665,249.595581,12.715005,0.856647,-291.839508,0.085881,0.000000
81.290001,56.084503,-291.839508,0.008015,0.003373,0.085665,249.476334,12.708931,0.856647,-291.839508,0.085881,0.000000
81.510002,56.050987,-291.839508,0.008019,0.003373,0.085665,249.327240,12.701336,0.856647,-291.839508,0.085881,0.000000
81.730003,56.016357,-291.884003,0.008015,0.003373,0.085665,249.173203,12.693488,0.856647,-291.884003,0.085881,0.000000
81.950005,55.996994,-291.884003,0.008019,0.003373,0.085665,249.087067,12.689100,0.856647,-291.884003,0.085881,0.000000
82.170006,55.957153,-291.839508,0.008041,0.003373,0.085665,248.909851,12.680072,0.856647,-291.839508,0.085881,0.000000
82.390007,55.934067,-291.884003,0.008080,0.003373,0.085665,248.807159,12.674841,0.856647,-291.884003,0.085881,0.000000
82.610001,55.898315,-291.972961,0.008054,0.003373,0.085665,248.648132,12.666739,0.856647,-291.972961,0.085881,0.000000
82.830002,55.865547,-291.795044,0.008097,0.003373,0.085665,248.502365,12.659314,0.856647,-291.795044,0.085881,0.000000
83.050003,55.837250,-291.884003,0.008019,0.003373,0.085665,248.376495,12.652902,0.856647,-291.884003,0.085881,0.000000
83.270004,55.811554,-291.884003,0.008080,0.003373,0.085665,248.262192,12.647079,0.856647,-291.884003,0.085881,0.000000
83.490005,55.786980,-291.972961,0.008071,0.003373,0.085665,248.152878,12.641511,0.856647,-291.972961,0.085881,0.000000
83.710007,55.768356,-291.928467,0.008067,0.003373,0.085665,248.070038,12.637290,0.856647,-291.928467,0.085881,0.000000
83.930000,55.729630,-291.884003,0.008084,0.003373,0.085665,247.897766,12.628515,0.856647,-291.884003,0.085881,0.000000
84.150002,55.709152,-291.928467,0.008032,0.003373,0.085665,247.806686,12.623874,0.856647,-291.928467,0.085881,0.000000
84.370003,55.684204,-291.928467,0.008097,0.003373,0.085665,247.695709,12.618220,0.856647,-291.928467,0.085881,0.000000
84.590004,55.645851,-291.972961,0.008050,0.003373,0.085665,247.525101,12.609530,0.856647,-291.972961,0.085881,0.000000
84.810005,55.611214,-291.972961,0.008028,0.003373,0.085665,247.371033,12.601681,0.856647,-291.972961,0.085881,0.000000
85.030006,55.600792,-291.884003,0.008041,0.003373,0.085665,247.324677,12.599319,0.856647,-291.884003,0.085881,0.000000
85.250008,55.567276,-291.928467,0.008024,0.003373,0.085665,247.175583,12.591724,0.856647,-291.928467,0.085881,0.000000
85.470001,55.540466,-291.928467,0.008032,0.003373,0.085665,247.056335,12.585649,0.856647,-291.928467,0.085881,0.000000
85.690002,55.514030,-292.017456,0.008019,0.003373,0.085665,246.938736,12.579659,0.856647,-292.017456,0.085881,0.000000
85.910004,55.482750,-291.972961,0.008071,0.003373,0.085665,246.799591,12.572571,0.856647,-291.972961,0.085881,0.000000
86.130005,55.464500,-291.972961,0.008054,0.003373,0.085665,246.718414,12.568436,0.856647,-291.972961,0.085881,0.000000
86.350006,55.428383,-291.884003,0.008041,0.003373,0.085665,246.557755,12.560251,0.856647,-291.884003,0.085881,0.000000
86.570007,55.417587,-291.928467,0.008084,0.003373,0.085665,246.509735,12.557805,0.856647,-291.928467,0.085881,0.000000
86.790001,55.391518,-292.017456,0.008063,0.003373,0.085665,246.393784,12.551898,0.856647,-292.017456,0.085881,0.000000
87.010002,55.382210,-292.061920,0.008058,0.003373,0.085665,246.352371,12.549788,0.856647,-292.061920,0.085881,0.000000
87.230003,55.341621,-291.928467,0.008080,0.003373,0.085665,246.171829,12.540590,0.856647,-291.928467,0.085881,0.000000
87.450005,55.323746,-292.017456,0.008041,0.003373,0.085665,246.092316,12.536540,0.856647,-292.017456,0.085881,0.000000
87.670006,55.311455,-291.928467,0.008071,0.003373,0.085665,246.037643,12.533754,0.856647,-291.928467,0.085881,0.000000
87.890007,55.282784,-291.972961,0.008045,0.003373,0.085665,245.910095,12.527258,0.856647,-291.972961,0.085881,0.000000
88.110001,55.249641,-292.061920,0.008071,0.003373,0.085665,245.762680,12.519748,0.856647,-292.061920,0.085881,0.000000
88.330002,55.234001,-292.061920,0.008084,0.003373,0.085665,245.693115,12.516203,0.856647,-292.061920,0.085881,0.000000
88.550003,55.204590,-292.017456,0.008088,0.003373,0.085665,245.562286,12.509539,0.856647,-292.017456,0.085881,0.000000
88.770004,55.174423,-292.017456,0.008041,0.003373,0.085665,245.428085,12.502703,0.856647,-292.017456,0.085881,0.000000
88.990005,55.151337,-292.017456,0.008080,0.003373,0.085665,245.325394,12.497472,0.856647,-292.017456,0.085881,0.000000
89.210007,55.131973,-292.061920,0.008097,0.003373,0.085665,245.239258,12.493084,0.856647,-292.061920,0.085881,0.000000
89.430008,55.117455,-292.061920,0.008063,0.003373,0.085665,245.174683,12.489794,0.856647,-292.061920,0.085881,0.000000
89.650002,55.092133,-291.972961,0.008080,0.003373,0.085665,245.062042,12.484056,0.856647,-291.972961,0.085881,0.000000
89.870003,55.070160,-292.061920,0.008093,0.003373,0.085665,244.964310,12.479077,0.856647,-292.061920,0.085881,0.000000
90.090004,55.075371,-292.061920,0.008084,0.003373,0.085665,244.987488,12.480257,0.856647,-292.061920,0.085881,0.000000
90.310005,55.047073,-292.061920,0.008067,0.003373,0.085665,244.861618,12.473845,0.856647,-292.061920,0.085881,0.000000
90.530006,55.028824,-292.061920,0.008067,0.003373,0.085665,244.780441,12.469709,0.856647,-292.061920,0.085881,0.000000
90.750008,55.013184,-292.017456,0.008080,0.003373,0.085665,244.710861,12.466166,0.856647,-292.017456,0.085881,0.000000
90.970001,54.980049,-292.106415,0.008071,0.003373,0.085665,244.563477,12.458656,0.856647,-292.106415,0.085881,0.000000
91.190002,54.960686,-292.150879,0.008058,0.003373,0.085665,244.477341,12.454269,0.856647,-292.150879,0.085881,0.000000
91.200005,54.961426,-292.061920,0.008101,0.003373,0.085665,244.480637,12.454437,0.856647,-292.061920,0.085881,0.000000