File: Data/Compression Sample NH 10, 12, 15, 17 batch 3/AutoNoheating-17-3-4-240212_02122024_181657.csv
Time (sec),S:Load (lbs),S:HL1 (DIM),S:LVDT (in),S:Position (in),Ch:Position (mm),Ch:Load (N),Ch:Stress (MPa),Ch:Strain (mm/mm),Ch:HL1 (DIM),Set Point (),Cycles ()
0.110000,0.010796,-318.883942,-0.000034,-0.000000,-0.000000,0.048021,0.002446,-0.000000,-318.883942,0.000217,0.000000
0.330000,0.005585,-318.839447,0.000026,-0.000000,-0.000000,0.024842,0.001266,-0.000000,-318.839447,0.000269,0.000000
0.550000,-0.007820,-318.928406,0.000013,0.000113,0.002879,-0.034786,-0.001772,0.028792,-318.928406,0.003946,0.000000
0.770000,0.002975,-318.928406,0.000129,0.000254,0.006461,0.013236,0.000674,0.064608,-318.928406,0.007606,0.000000
0.990000,-0.002983,-318.928406,0.000272,0.000392,0.009956,-0.013269,-0.000676,0.099558,-318.928406,0.011265,0.000000
1.210000,-0.002609,-318.883942,0.000392,0.000544,0.013815,-0.011607,-0.000591,0.138149,-318.883942,0.014925,0.000000
1.430000,0.013031,-318.883942,0.000591,0.000686,0.017431,0.057965,0.002953,0.174313,-318.883942,0.018602,0.000000
1.650000,0.000366,-318.883942,0.000737,0.000831,0.021108,0.001629,0.000083,0.211084,-318.883942,0.022262,0.000000
1.870000,-0.006706,-318.972900,0.000884,0.000977,0.024820,-0.029831,-0.001520,0.248202,-318.972900,0.025922,0.000000
2.090000,0.008560,-318.972900,0.001052,0.001122,0.028497,0.038078,0.001940,0.284972,-318.972900,0.029599,0.000000
2.310000,0.013031,-318.928406,0.001177,0.001267,0.032192,0.057965,0.002953,0.321917,-318.928406,0.033258,0.000000
2.530000,0.005585,-318.928406,0.001293,0.001407,0.035738,0.024842,0.001266,0.357385,-318.928406,0.036918,0.000000
2.750000,0.018990,-318.928406,0.001462,0.001555,0.039493,0.084470,0.004303,0.394935,-318.928406,0.040595,0.000000
2.970000,-0.015266,-319.017395,0.001669,0.001702,0.043240,-0.067908,-0.003459,0.432398,-319.017395,0.044255,0.000000
3.190000,-0.046921,-318.928406,0.001763,0.001846,0.046882,-0.208714,-0.010632,0.468824,-318.928406,0.047914,0.000000
3.410000,-0.050644,-318.928406,0.001949,0.001988,0.050490,-0.225275,-0.011476,0.504901,-318.928406,0.051591,0.000000
3.630000,0.005959,-318.972900,0.002061,0.002132,0.054150,0.026505,0.001350,0.541497,-318.972900,0.055251,0.000000
3.850000,0.014893,-319.017395,0.002242,0.002277,0.057835,0.066245,0.003375,0.578355,-319.017395,0.058911,0.000000
4.070000,0.023087,-319.017395,0.002384,0.002416,0.061365,0.102694,0.005231,0.613649,-319.017395,0.062588,0.000000
4.290000,0.023460,-318.972900,0.002561,0.002560,0.065024,0.104357,0.005316,0.650245,-318.972900,0.066247,0.000000
4.510000,0.010796,-318.928406,0.002725,0.002712,0.068893,0.048021,0.002446,0.688927,-318.928406,0.069907,0.000000
4.730000,0.003723,-318.972900,0.002811,0.002855,0.072509,0.016561,0.000844,0.725087,-318.972900,0.073584,0.000000
4.950000,-0.032402,-319.061859,0.003018,0.002997,0.076134,-0.144131,-0.007342,0.761339,-319.061859,0.077244,0.000000
5.170000,-0.025322,-318.972900,0.003122,0.003141,0.079794,-0.112638,-0.005738,0.797935,-318.972900,0.080904,0.000000
5.390000,0.001114,-319.061859,0.003264,0.003285,0.083444,0.004955,0.000252,0.834444,-319.061859,0.084563,0.000000
5.610000,0.024200,-319.017395,0.003475,0.003431,0.087148,0.107649,0.005484,0.871476,-319.017395,0.088240,0.000000
5.830000,0.036865,-319.017395,0.003604,0.003569,0.090651,0.163985,0.008354,0.906513,-319.017395,0.091900,0.000000
6.050000,0.028297,-319.017395,0.003751,0.003722,0.094528,0.125873,0.006412,0.945278,-319.017395,0.095560,0.000000
6.270000,0.035370,-319.061859,0.003880,0.003866,0.098205,0.157333,0.008015,0.982048,-319.061859,0.099237,0.000000
6.490000,0.008560,-319.017395,0.004083,0.004006,0.101743,0.038078,0.001940,1.017429,-319.017395,0.102897,0.000000
6.710001,-0.005219,-318.972900,0.004152,0.004149,0.105385,-0.023213,-0.001183,1.053855,-318.972900,0.106556,0.000000
6.930000,0.012657,-318.972900,0.004333,0.004295,0.109088,0.056302,0.002868,1.090882,-318.972900,0.110233,0.000000
7.150001,0.017502,-319.017395,0.004458,0.004440,0.112783,0.077852,0.003966,1.127827,-319.017395,0.113893,0.000000
7.370000,0.025322,-319.061859,0.004626,0.004581,0.116347,0.112638,0.005738,1.163469,-319.061859,0.117552,0.000000
7.590000,0.003723,-319.106354,0.004825,0.004727,0.120076,0.016561,0.000844,1.200762,-319.106354,0.121229,0.000000
7.810000,0.032021,-319.061859,0.004958,0.004873,0.123771,0.142435,0.007256,1.237706,-319.061859,0.124889,0.000000
8.030001,0.010422,-319.017395,0.005101,0.005017,0.127430,0.046358,0.002362,1.274302,-319.017395,0.128549,0.000000
8.250000,-0.009315,-319.061859,0.005247,0.005162,0.131116,-0.041437,-0.002111,1.311159,-319.061859,0.132226,0.000000
8.470000,0.016754,-319.061859,0.005376,0.005306,0.134767,0.074526,0.003797,1.347669,-319.061859,0.135886,0.000000
8.690001,0.018616,-319.106354,0.005583,0.005455,0.138557,0.082807,0.004218,1.385567,-319.106354,0.139545,0.000000
8.910001,0.032021,-319.061859,0.005674,0.005593,0.142060,0.142435,0.007256,1.420604,-319.061859,0.143222,0.000000
9.130000,0.026436,-319.150818,0.005833,0.005737,0.145720,0.117593,0.005990,1.457200,-319.150818,0.146882,0.000000
9.350000,0.020103,-319.106354,0.005993,0.005884,0.149449,0.089425,0.004556,1.494492,-319.106354,0.150542,0.000000
9.570001,0.030533,-319.106354,0.006165,0.006034,0.153265,0.135817,0.006919,1.532648,-319.106354,0.154202,0.000000
9.790001,0.007446,-319.106354,0.006321,0.006176,0.156881,0.033123,0.001687,1.568812,-319.106354,0.157879,0.000000
10.010000,0.126602,-319.106354,0.006437,0.006314,0.160385,0.563155,0.028688,1.603849,-319.106354,0.161538,0.000000
10.230000,0.744743,-319.106354,0.006532,-0.000000,-0.000008,3.312784,0.168761,-0.000083,-319.106354,0.000208,0.000000
10.450001,0.716446,-319.150818,0.006515,-0.000000,-0.000008,3.186911,0.162349,-0.000083,-319.150818,0.000208,0.000000
10.670000,0.694847,-319.150818,0.006545,-0.000000,-0.000008,3.090834,0.157455,-0.000083,-319.150818,0.000208,0.000000
10.890000,0.665802,-319.150818,0.006545,-0.000000,-0.000000,2.961635,0.150873,-0.000000,-319.150818,0.000538,0.000000
11.110001,0.688515,-319.106354,0.006571,-0.000000,-0.000000,3.062666,0.156020,-0.000000,-319.106354,0.000902,0.000000
11.330001,0.665802,-319.150818,0.006549,-0.000000,-0.000000,2.961635,0.150873,-0.000000,-319.150818,0.001266,0.000000
11.550000,0.957367,-319.106354,0.006545,0.000027,0.000677,4.258581,0.216942,0.006767,-319.106354,0.001639,0.000000
11.770000,1.241486,-319.150818,0.006597,0.000043,0.001101,5.522404,0.281325,0.011014,-319.150818,0.002003,0.000000
11.990001,1.494331,-319.150818,0.006558,0.000058,0.001475,6.647118,0.338620,0.014746,-319.150818,0.002368,0.000000
12.210001,1.724083,-319.239777,0.006592,0.000073,0.001847,7.669104,0.390683,0.018474,-319.239777,0.002732,0.000000
12.430000,2.020866,-319.195312,0.006644,0.000089,0.002255,8.989263,0.457935,0.022550,-319.195312,0.003105,0.000000
12.650001,2.304611,-319.150818,0.006618,0.000105,0.002663,10.251423,0.522232,0.026627,-319.150818,0.003469,0.000000
12.870001,2.608467,-319.195312,0.006640,0.000120,0.003035,11.603041,0.591087,0.030355,-319.195312,0.003833,0.000000
13.090000,2.874710,-319.195312,0.006670,0.000133,0.003382,12.787349,0.651419,0.033822,-319.195312,0.004197,0.000000
13.310000,3.081383,-319.195312,0.006648,0.000146,0.003721,13.706675,0.698251,0.037206,-319.195312,0.004570,0.000000
13.530001,3.375557,-319.195312,0.006687,0.000161,0.004085,15.015227,0.764912,0.040847,-319.195312,0.004935,0.000000
13.750001,3.714043,-319.195312,0.006709,0.000177,0.004492,16.520887,0.841614,0.044923,-319.195312,0.005299,0.000000
13.970000,3.960922,-319.195312,0.006713,0.000187,0.004753,17.619062,0.897558,0.047527,-319.195312,0.005672,0.000000
14.190001,4.208176,-319.239777,0.006730,0.000200,0.005082,18.718901,0.953586,0.050820,-319.239777,0.006036,0.000000
14.410001,4.556717,-319.239777,0.006696,0.000215,0.005472,20.269289,1.032567,0.054722,-319.239777,0.006400,0.000000
14.630001,4.892227,-319.195312,0.006704,0.000232,0.005897,21.761713,1.108595,0.058972,-319.195312,0.006764,0.000000
14.850000,5.299973,-319.195312,0.006782,0.000249,0.006331,23.575455,1.200991,0.063310,-319.195312,0.007138,0.000000
15.070001,5.485413,-319.150818,0.006782,0.000261,0.006635,24.400333,1.243012,0.066345,-319.150818,0.007502,0.000000
15.290001,5.777725,-319.195312,0.006756,0.000276,0.007016,25.700605,1.309251,0.070161,-319.195312,0.007866,0.000000
15.510001,6.007858,-319.239777,0.006812,0.000290,0.007363,26.724289,1.361400,0.073628,-319.239777,0.008239,0.000000
15.730000,6.282669,-319.239777,0.006842,0.000301,0.007641,27.946709,1.423673,0.076406,-319.239777,0.008603,0.000000
15.950001,6.606255,-319.195312,0.006808,0.000318,0.008083,29.386087,1.496999,0.080826,-319.195312,0.008967,0.000000
16.170000,6.776428,-319.195312,0.006834,0.000329,0.008351,30.143059,1.535561,0.083514,-319.195312,0.009332,0.000000
16.390001,7.028526,-319.284271,0.006812,0.000343,0.008716,31.264446,1.592687,0.087159,-319.284271,0.009704,0.000000
16.610001,7.340950,-319.284271,0.006842,0.000357,0.009063,32.654175,1.663483,0.090626,-319.284271,0.010069,0.000000
16.830000,7.745346,-319.284271,0.006860,0.000376,0.009557,34.453018,1.755121,0.095569,-319.284271,0.010433,0.000000
17.050001,7.867859,-319.239777,0.006933,0.000389,0.009869,34.997986,1.782882,0.098691,-319.239777,0.010806,0.000000
17.270000,8.093513,-319.195312,0.006937,0.000403,0.010242,36.001747,1.834016,0.102419,-319.195312,0.011170,0.000000
17.490002,8.384338,-319.284271,0.006942,0.000421,0.010684,37.295399,1.899918,0.106844,-319.284271,0.011534,0.000000
17.710001,8.630844,-319.284271,0.006946,0.000436,0.011066,38.391911,1.955777,0.110659,-319.284271,0.011899,0.000000
17.930000,8.721703,-319.328735,0.006946,0.000449,0.011396,38.796070,1.976366,0.113956,-319.328735,0.012271,0.000000
18.150002,8.789848,-319.284271,0.006980,0.000458,0.011638,39.099197,1.991808,0.116382,-319.284271,0.012635,0.000000
18.370001,9.225899,-319.284271,0.006959,0.000479,0.012176,41.038849,2.090619,0.121760,-319.284271,0.013000,0.000000
18.590000,9.284729,-319.284271,0.006950,0.000491,0.012471,41.300537,2.103950,0.124709,-319.284271,0.013373,0.000000
18.810001,9.534966,-319.328735,0.006976,0.000507,0.012878,42.413647,2.160654,0.128785,-319.328735,0.013737,0.000000
19.030001,9.523422,-319.417725,0.007041,0.000517,0.013121,42.362297,2.158038,0.131215,-319.417725,0.014101,0.000000
19.250000,9.765091,-319.328735,0.007032,0.000533,0.013529,43.437294,2.212801,0.135287,-319.328735,0.014465,0.000000
19.470001,9.784454,-319.284271,0.007036,0.000544,0.013815,43.523426,2.217189,0.138152,-319.284271,0.014838,0.000000
19.690001,10.179916,-319.284271,0.007084,0.000564,0.014335,45.282528,2.306802,0.143353,-319.284271,0.015203,0.000000
19.910002,10.147888,-319.373230,0.007071,0.000576,0.014639,45.140060,2.299544,0.146388,-319.373230,0.015567,0.000000
20.130001,10.238380,-319.328735,0.007054,0.000586,0.014882,45.542591,2.320050,0.148818,-319.328735,0.015940,0.000000
20.350000,10.615593,-319.328735,0.007088,0.000607,0.015419,47.220516,2.405528,0.154193,-319.328735,0.016304,0.000000
20.570002,10.794327,-319.284271,0.007118,0.000625,0.015870,48.015564,2.446029,0.158704,-319.284271,0.016668,0.000000
20.790001,10.825981,-319.373230,0.007140,0.000638,0.016208,48.156368,2.453202,0.162084,-319.373230,0.017032,0.000000
21.010000,10.840874,-319.328735,0.007144,0.000651,0.016529,48.222614,2.456577,0.165294,-319.328735,0.017405,0.000000
21.230001,10.886307,-319.328735,0.007179,0.000662,0.016824,48.424709,2.466872,0.168242,-319.328735,0.017770,0.000000
21.450001,11.052010,-319.373230,0.007209,0.000678,0.017214,49.161793,2.504421,0.172145,-319.373230,0.018134,0.000000
21.670000,11.205803,-319.373230,0.007157,0.000691,0.017544,49.845901,2.539271,0.175441,-319.373230,0.018507,0.000000
21.890001,11.284370,-319.328735,0.007161,0.000702,0.017839,50.195385,2.557075,0.178390,-319.328735,0.018871,0.000000
22.110001,11.292938,-319.373230,0.007179,0.000717,0.018203,50.233498,2.559016,0.182031,-319.373230,0.019235,0.000000
22.330002,11.713348,-319.417725,0.007235,0.000736,0.018689,52.103577,2.654283,0.186891,-319.417725,0.019599,0.000000
22.550001,11.975494,-319.328735,0.007217,0.000755,0.019175,53.269661,2.713686,0.191747,-319.328735,0.019973,0.000000
22.770000,11.902138,-319.373230,0.007304,0.000767,0.019487,52.943352,2.697063,0.194869,-319.373230,0.020337,0.000000
22.990002,11.896927,-319.373230,0.007308,0.000781,0.019825,52.920174,2.695882,0.198249,-319.373230,0.020701,0.000000
23.210001,11.956131,-319.373230,0.007299,0.000794,0.020172,53.183525,2.709298,0.201720,-319.373230,0.021074,0.000000
23.430000,11.837349,-319.373230,0.007317,0.000806,0.020467,52.655159,2.682381,0.204668,-319.373230,0.021438,0.000000
23.650002,12.233925,-319.417725,0.007338,0.000821,0.020848,54.419216,2.772247,0.208483,-319.417725,0.021802,0.000000
23.870001,12.309143,-319.373230,0.007330,0.000836,0.021230,54.753803,2.789292,0.212299,-319.373230,0.022167,0.000000
24.090002,12.258125,-319.373230,0.007364,0.000846,0.021490,54.526863,2.777731,0.214899,-319.373230,0.022539,0.000000
24.310001,12.591400,-319.417725,0.007364,0.000867,0.022019,56.009346,2.853252,0.220190,-319.417725,0.022904,0.000000
24.530001,12.899353,-319.462189,0.007407,0.000885,0.022478,57.379189,2.923035,0.224785,-319.462189,0.023268,0.000000
24.750002,12.805145,-319.462189,0.007386,0.000897,0.022782,56.960133,2.901687,0.227820,-319.462189,0.023641,0.000000
24.970001,12.826736,-319.506683,0.007394,0.000911,0.023129,57.056171,2.906580,0.231291,-319.506683,0.024005,0.000000
25.190001,12.795830,-319.417725,0.007416,0.000921,0.023389,56.918694,2.899576,0.233891,-319.417725,0.024369,0.000000
25.410002,13.031914,-319.462189,0.007424,0.000937,0.023805,57.968849,2.953074,0.238055,-319.462189,0.024734,0.000000
25.630001,13.237465,-319.551147,0.007450,0.000953,0.024196,58.883186,2.999652,0.241957,-319.551147,0.025106,0.000000
25.850000,13.184959,-319.462189,0.007446,0.000964,0.024482,58.649628,2.987754,0.244818,-319.462189,0.025470,0.000000
26.070002,13.259064,-319.506683,0.007502,0.000978,0.024829,58.979259,3.004547,0.248289,-319.506683,0.025835,0.000000
26.290001,13.867523,-319.417725,0.007480,0.001001,0.025427,61.685825,3.142426,0.254273,-319.417725,0.026199,0.000000
26.510002,13.927101,-319.462189,0.007506,0.001017,0.025835,61.950840,3.155926,0.258349,-319.462189,0.026572,0.000000
26.730001,13.719315,-319.506683,0.007489,0.001027,0.026086,61.026558,3.108841,0.260863,-319.506683,0.026936,0.000000
26.950001,13.719688,-319.506683,0.007545,0.001040,0.026425,61.028221,3.108926,0.264246,-319.506683,0.027300,0.000000
27.170002,13.863052,-319.506683,0.007571,0.001054,0.026780,61.665936,3.141413,0.267800,-319.506683,0.027673,0.000000
27.390001,13.946838,-319.506683,0.007575,0.001068,0.027118,62.038635,3.160399,0.271184,-319.506683,0.028038,0.000000
27.610001,14.152382,-319.506683,0.007558,0.001083,0.027517,62.952938,3.206976,0.275173,-319.506683,0.028402,0.000000
27.830002,14.109932,-319.506683,0.007571,0.001094,0.027777,62.764111,3.197356,0.277773,-319.506683,0.028766,0.000000
28.050001,14.289421,-319.551147,0.007636,0.001108,0.028150,63.562519,3.238029,0.281502,-319.551147,0.029139,0.000000
28.270000,14.742966,-319.551147,0.007662,0.001130,0.028697,65.579987,3.340804,0.286967,-319.551147,0.029503,0.000000
28.490002,14.891914,-319.506683,0.007636,0.001147,0.029139,66.242546,3.374556,0.291388,-319.506683,0.029867,0.000000
28.710001,14.782066,-319.506683,0.007662,0.001159,0.029442,65.753914,3.349664,0.294423,-319.506683,0.030240,0.000000
28.930002,14.796219,-319.506683,0.007692,0.001173,0.029798,65.816872,3.352871,0.297981,-319.506683,0.030605,0.000000
29.150002,14.783928,-319.551147,0.007644,0.001183,0.030058,65.762199,3.350086,0.300581,-319.551147,0.030969,0.000000
29.370001,15.144386,-319.551147,0.007731,0.001201,0.030518,67.365593,3.431767,0.305180,-319.551147,0.031333,0.000000
29.590002,15.247162,-319.551147,0.007731,0.001216,0.030882,67.822762,3.455056,0.308821,-319.551147,0.031706,0.000000
29.810001,14.969002,-319.462189,0.007731,0.001221,0.031021,66.585442,3.392024,0.310210,-319.462189,0.032070,0.000000
30.030001,15.282539,-319.595642,0.007705,0.001240,0.031507,67.980133,3.463073,0.315066,-319.595642,0.032434,0.000000
30.250002,15.599052,-319.595642,0.007748,0.001254,0.031862,69.388054,3.534796,0.318620,-319.595642,0.032807,0.000000
30.470001,15.737206,-319.551147,0.007756,0.001269,0.032244,70.002586,3.566102,0.322435,-319.551147,0.033172,0.000000
30.690001,15.712624,-319.551147,0.007774,0.001283,0.032582,69.893242,3.560531,0.325819,-319.551147,0.033536,0.000000
30.910002,15.949455,-319.551147,0.007778,0.001297,0.032955,70.946724,3.614198,0.329547,-319.551147,0.033900,0.000000
31.130001,16.092072,-319.595642,0.007787,0.001312,0.033328,71.581108,3.646516,0.333275,-319.595642,0.034273,0.000000
31.350002,16.159843,-319.640106,0.007787,0.001325,0.033666,71.882576,3.661873,0.336659,-319.640106,0.034637,0.000000
31.570002,16.426834,-319.595642,0.007864,0.001341,0.034074,73.070206,3.722374,0.340735,-319.595642,0.035002,0.000000
31.790001,16.380287,-319.551147,0.007860,0.001354,0.034403,72.863159,3.711826,0.344032,-319.551147,0.035374,0.000000
32.010002,16.658081,-319.595642,0.007847,0.001370,0.034793,74.098846,3.774775,0.347934,-319.595642,0.035738,0.000000
32.230003,17.036781,-319.595642,0.007912,0.001388,0.035244,75.783386,3.860590,0.352442,-319.595642,0.036103,0.000000
32.450001,17.078491,-319.595642,0.007916,0.001402,0.035600,75.968925,3.870041,0.356000,-319.595642,0.036467,0.000000
32.670002,16.773888,-319.684601,0.007937,0.001411,0.035851,74.613976,3.801017,0.358513,-319.684601,0.036840,0.000000
32.890003,17.041626,-319.595642,0.007890,0.001424,0.036181,75.804939,3.861688,0.361809,-319.595642,0.037204,0.000000
33.110001,17.397614,-319.551147,0.007907,0.001442,0.036632,77.388451,3.942356,0.366317,-319.551147,0.037568,0.000000
33.330002,17.594223,-319.640106,0.007925,0.001458,0.037039,78.263016,3.986908,0.370394,-319.640106,0.037941,0.000000
33.550003,17.682846,-319.640106,0.007950,0.001472,0.037386,78.657227,4.006990,0.373864,-319.640106,0.038305,0.000000
33.770000,17.940903,-319.684601,0.007989,0.001488,0.037794,79.805122,4.065467,0.377937,-319.684601,0.038670,0.000000
33.990002,18.037346,-319.640106,0.007972,0.001503,0.038184,80.234123,4.087321,0.381843,-319.640106,0.039034,0.000000
34.210003,18.250343,-319.595642,0.008032,0.001518,0.038557,81.181580,4.135587,0.385571,-319.595642,0.039407,0.000000
34.430000,18.341202,-319.640106,0.008002,0.001532,0.038904,81.585739,4.156176,0.389038,-319.640106,0.039771,0.000000
34.650002,18.364662,-319.684601,0.008063,0.001546,0.039277,81.690094,4.161492,0.392770,-319.684601,0.040135,0.000000
34.870003,18.521057,-319.684601,0.008019,0.001560,0.039624,82.385780,4.196931,0.396237,-319.684601,0.040508,0.000000
35.090000,18.850609,-319.640106,0.008080,0.001577,0.040049,83.851692,4.271609,0.400487,-319.640106,0.040872,0.000000
35.310001,18.766083,-319.595642,0.008041,0.001586,0.040291,83.475708,4.252455,0.402913,-319.595642,0.041237,0.000000
35.530003,18.820450,-319.684601,0.008080,0.001599,0.040621,83.717545,4.264775,0.406210,-319.684601,0.041601,0.000000
35.750000,19.169357,-319.684601,0.008050,0.001616,0.041055,85.269562,4.343838,0.410548,-319.684601,0.041974,0.000000
35.970001,19.511200,-319.684601,0.008132,0.001632,0.041445,86.790154,4.421301,0.414450,-319.684601,0.042338,0.000000
36.190002,19.778564,-319.729065,0.008114,0.001648,0.041861,87.979446,4.481887,0.418613,-319.729065,0.042702,0.000000
36.410000,19.826973,-319.729065,0.008114,0.001662,0.042217,88.194778,4.492857,0.422167,-319.729065,0.043075,0.000000
36.630001,19.910751,-319.640106,0.008170,0.001675,0.042555,88.567444,4.511841,0.425551,-319.640106,0.043440,0.000000
36.850002,20.051514,-319.684601,0.008140,0.001690,0.042937,89.193588,4.543738,0.429366,-319.684601,0.043804,0.000000
37.070004,20.310310,-319.773560,0.008196,0.001705,0.043309,90.344772,4.602382,0.433094,-319.773560,0.044168,0.000000
37.290001,20.284988,-319.729065,0.008213,0.001717,0.043604,90.232132,4.596644,0.436043,-319.729065,0.044541,0.000000
37.510002,20.354248,-319.684601,0.008170,0.001730,0.043943,90.540215,4.612339,0.439426,-319.684601,0.044905,0.000000
37.730003,20.565758,-319.729065,0.008239,0.001742,0.044237,91.481056,4.660267,0.442375,-319.729065,0.045269,0.000000
37.950001,20.795135,-319.773560,0.008218,0.001758,0.044645,92.501381,4.712245,0.446451,-319.773560,0.045642,0.000000
38.170002,21.312737,-319.773560,0.008265,0.001776,0.045113,94.803787,4.829535,0.451133,-319.773560,0.046007,0.000000
38.390003,21.357048,-319.773560,0.008274,0.001788,0.045408,95.000893,4.839576,0.454081,-319.773560,0.046371,0.000000
38.610001,21.599838,-319.729065,0.008287,0.001805,0.045842,96.080879,4.894593,0.458419,-319.729065,0.046735,0.000000
38.830002,21.916725,-319.729065,0.008291,0.001821,0.046241,97.490463,4.966401,0.462408,-319.729065,0.047108,0.000000
39.050003,22.166588,-319.773560,0.008274,0.001836,0.046631,98.601906,5.023021,0.466310,-319.773560,0.047472,0.000000
39.270000,22.241806,-319.773560,0.008274,0.001851,0.047004,98.936493,5.040065,0.470039,-319.773560,0.047836,0.000000
39.490002,22.099930,-319.773560,0.008334,0.001858,0.047195,98.305397,5.007915,0.471946,-319.773560,0.048201,0.000000
39.710003,22.857712,-319.729065,0.008317,0.001880,0.047758,101.676178,5.179632,0.477582,-319.729065,0.048573,0.000000
39.930000,22.760521,-319.773560,0.008317,0.001891,0.048036,101.243851,5.157608,0.480356,-319.773560,0.048938,0.000000
40.150002,23.143692,-319.773560,0.008351,0.001907,0.048426,102.948280,5.244435,0.484262,-319.773560,0.049302,0.000000
40.370003,23.183533,-319.773560,0.008356,0.001919,0.048747,103.125504,5.253464,0.487468,-319.773560,0.049675,0.000000
40.590000,23.379402,-319.773560,0.008382,0.001933,0.049094,103.996773,5.297848,0.490939,-319.773560,0.050039,0.000000
40.810001,23.345886,-319.773560,0.008382,0.001943,0.049363,103.847687,5.290254,0.493626,-319.773560,0.050403,0.000000
41.030003,23.958443,-319.773560,0.008395,0.001960,0.049788,106.572479,5.429061,0.497876,-319.773560,0.050768,0.000000
41.250004,24.138298,-319.729065,0.008429,0.001978,0.050230,107.372513,5.469817,0.502297,-319.729065,0.051140,0.000000
41.470001,24.128616,-319.818024,0.008459,0.001984,0.050403,107.329445,5.467623,0.504034,-319.818024,0.051505,0.000000
41.690002,24.880440,-319.818024,0.008451,0.002007,0.050976,110.673721,5.637988,0.509757,-319.818024,0.051869,0.000000
41.910004,25.292282,-319.818024,0.008476,0.002025,0.051444,112.505692,5.731313,0.514439,-319.818024,0.052242,0.000000
42.130001,25.403992,-319.818024,0.008515,0.002038,0.051756,113.002602,5.756627,0.517562,-319.818024,0.052606,0.000000
42.350002,25.456123,-319.818024,0.008502,0.002050,0.052068,113.234489,5.768440,0.520684,-319.818024,0.052970,0.000000
42.570004,25.525009,-319.907013,0.008502,0.002062,0.052372,113.540909,5.784050,0.523720,-319.907013,0.053334,0.000000
42.790001,25.847488,-319.862518,0.008545,0.002078,0.052788,114.975372,5.857124,0.527883,-319.862518,0.053707,0.000000
43.010002,26.042984,-319.818024,0.008558,0.002089,0.053066,115.844978,5.901424,0.530657,-319.818024,0.054072,0.000000
43.230003,26.247040,-319.818024,0.008563,0.002102,0.053395,116.752663,5.947664,0.533954,-319.818024,0.054436,0.000000
43.450001,26.579201,-319.773560,0.008545,0.002117,0.053760,118.230186,6.022933,0.537595,-319.773560,0.054809,0.000000
43.670002,27.261383,-319.907013,0.008563,0.002135,0.054219,121.264687,6.177517,0.542190,-319.907013,0.055173,0.000000
43.890003,27.901497,-319.907013,0.008601,0.002155,0.054739,124.112061,6.322569,0.547394,-319.907013,0.055537,0.000000
44.110001,27.983040,-319.862518,0.008601,0.002168,0.055069,124.474777,6.341047,0.550691,-319.862518,0.055901,0.000000
44.330002,28.010223,-319.862518,0.008658,0.002181,0.055390,124.595695,6.347207,0.553900,-319.862518,0.056275,0.000000
44.550003,28.191948,-319.862518,0.008645,0.002193,0.055711,125.404045,6.388387,0.557106,-319.862518,0.056639,0.000000
44.770000,28.373665,-319.951477,0.008645,0.002207,0.056058,126.212364,6.429564,0.560577,-319.951477,0.057003,0.000000
44.990002,28.751251,-319.907013,0.008653,0.002222,0.056448,127.891953,6.515127,0.564479,-319.907013,0.057376,0.000000
45.210003,28.989563,-319.907013,0.008701,0.002235,0.056778,128.952011,6.569129,0.567776,-319.907013,0.057740,0.000000
45.430000,29.071487,-319.818024,0.008670,0.002247,0.057081,129.316437,6.587693,0.570811,-319.818024,0.058104,0.000000
45.650002,29.873581,-319.907013,0.008679,0.002265,0.057541,132.884323,6.769450,0.575406,-319.907013,0.058469,0.000000
45.870003,30.714394,-319.907013,0.008675,0.002285,0.058044,136.624451,6.959981,0.580436,-319.907013,0.058841,0.000000
46.090004,30.706200,-319.951477,0.008683,0.002296,0.058321,136.587997,6.958124,0.583211,-319.951477,0.059206,0.000000
46.310001,30.913239,-319.951477,0.008696,0.002309,0.058651,137.508957,7.005040,0.586507,-319.951477,0.059570,0.000000
46.530003,31.015648,-319.818024,0.008757,0.002321,0.058963,137.964493,7.028246,0.589630,-319.818024,0.059943,0.000000
46.750004,31.481483,-319.907013,0.008748,0.002338,0.059379,140.036636,7.133806,0.593789,-319.907013,0.060307,0.000000
46.970001,31.923119,-319.951477,0.008791,0.002351,0.059709,142.001129,7.233882,0.597086,-319.951477,0.060671,0.000000
47.190002,31.939125,-319.951477,0.008813,0.002363,0.060012,142.072327,7.237509,0.600122,-319.951477,0.061036,0.000000
47.410004,32.230698,-319.951477,0.008817,0.002376,0.060351,143.369308,7.303581,0.603505,-319.951477,0.061408,0.000000
47.630001,33.499741,-319.951477,0.008804,0.002399,0.060940,149.014282,7.591150,0.609402,-319.951477,0.061773,0.000000
47.850002,34.067612,-319.951477,0.008808,0.002416,0.061357,151.540298,7.719831,0.613566,-319.951477,0.062137,0.000000
48.070004,34.053459,-319.951477,0.008860,0.002425,0.061599,151.477356,7.716624,0.615992,-319.951477,0.062510,0.000000
48.290001,34.173737,-319.951477,0.008808,0.002439,0.061955,152.012375,7.743879,0.619549,-319.951477,0.062874,0.000000
48.510002,34.649628,-319.995972,0.008903,0.002452,0.062293,154.129242,7.851718,0.622929,-319.995972,0.063238,0.000000
48.730003,34.811234,-319.995972,0.008852,0.002466,0.062631,154.848099,7.888339,0.626313,-319.995972,0.063603,0.000000
48.950001,35.469223,-319.951477,0.008886,0.002481,0.063022,157.774979,8.037440,0.630215,-319.951477,0.063975,0.000000
49.170002,35.635674,-319.995972,0.008895,0.002492,0.063299,158.515396,8.075159,0.632990,-319.995972,0.064340,0.000000
49.390003,36.038208,-320.040436,0.008886,0.002507,0.063672,160.305954,8.166374,0.636718,-320.040436,0.064704,0.000000
49.610001,37.218254,-319.995972,0.008895,0.002529,0.064244,165.555069,8.433777,0.642444,-319.995972,0.065077,0.000000
49.830002,37.850914,-320.040436,0.008942,0.002547,0.064686,168.369278,8.577140,0.646865,-320.040436,0.065441,0.000000
50.050003,37.942146,-319.951477,0.008951,0.002558,0.064964,168.775101,8.597814,0.649639,-319.951477,0.065805,0.000000
50.270004,38.313026,-319.995972,0.008959,0.002571,0.065311,170.424850,8.681855,0.653110,-319.995972,0.066169,0.000000
50.490002,38.286964,-319.995972,0.008977,0.002582,0.065580,170.308929,8.675950,0.655797,-319.995972,0.066542,0.000000
50.710003,39.140068,-320.084930,0.008990,0.002600,0.066039,174.103714,8.869266,0.660392,-320.084930,0.066907,0.000000
50.930004,39.707932,-319.995972,0.008998,0.002614,0.066404,176.629700,8.997946,0.664037,-319.995972,0.067271,0.000000
51.150002,39.364983,-319.995972,0.008985,0.002619,0.066516,175.104187,8.920233,0.665165,-319.995972,0.067644,0.000000
51.370003,40.110840,-320.040436,0.008990,0.002640,0.067045,178.421921,9.089246,0.670453,-320.040436,0.068008,0.000000
51.590004,41.051079,-320.040436,0.008998,0.002655,0.067444,182.604324,9.302307,0.674442,-320.040436,0.068372,0.000000
51.810001,41.452126,-320.084930,0.009076,0.002668,0.067765,184.388260,9.393186,0.677651,-320.084930,0.068736,0.000000
52.030003,41.668472,-320.040436,0.009089,0.002681,0.068086,185.350616,9.442211,0.680861,-320.040436,0.069110,0.000000
52.250004,42.379333,-319.995972,0.009071,0.002696,0.068485,188.512695,9.603294,0.684850,-319.995972,0.069474,0.000000
52.470001,43.008644,-320.040436,0.009041,0.002714,0.068927,191.311996,9.745898,0.689271,-320.040436,0.069838,0.000000
52.690002,43.439476,-320.084930,0.009106,0.002727,0.069265,193.228439,9.843526,0.692655,-320.084930,0.070202,0.000000
52.910004,44.226677,-320.129395,0.009054,0.002740,0.069595,196.730087,10.021909,0.695951,-320.129395,0.070575,0.000000
53.130001,44.389404,-320.040436,0.009119,0.002753,0.069933,197.453934,10.058783,0.699331,-320.040436,0.070939,0.000000
53.350002,45.127441,-319.995972,0.009145,0.002769,0.070341,200.736877,10.226025,0.703408,-319.995972,0.071304,0.000000
53.570004,46.228920,-320.084930,0.009119,0.002786,0.070775,205.636505,10.475623,0.707745,-320.084930,0.071676,0.000000
53.790001,46.759552,-320.084930,0.009136,0.002800,0.071130,207.996872,10.595865,0.711299,-320.084930,0.072041,0.000000
54.010002,46.834396,-320.084930,0.009136,0.002813,0.071460,208.329803,10.612825,0.714596,-320.084930,0.072405,0.000000
54.230003,47.231720,-320.040436,0.009140,0.002824,0.071737,210.097183,10.702861,0.717370,-320.040436,0.072769,0.000000
54.450001,48.236382,-320.084930,0.009153,0.002844,0.072249,214.566147,10.930520,0.722487,-320.084930,0.073142,0.000000
54.670002,48.796432,-319.995972,0.009188,0.002855,0.072517,217.057373,11.057429,0.725175,-319.995972,0.073506,0.000000
54.890003,49.319984,-320.173889,0.009205,0.002870,0.072899,219.386246,11.176067,0.728990,-320.173889,0.073871,0.000000
55.110004,50.269905,-320.173889,0.009158,0.002886,0.073315,223.611710,11.391323,0.733153,-320.173889,0.074243,0.000000
55.330002,50.906296,-320.173889,0.009158,0.002901,0.073697,226.442520,11.535531,0.736968,-320.173889,0.074607,0.000000
55.550003,51.650665,-320.084930,0.009231,0.002916,0.074079,229.753632,11.704208,0.740787,-320.084930,0.074972,0.000000
55.770004,52.288910,-320.218353,0.009179,0.002930,0.074425,232.592682,11.848836,0.744254,-320.218353,0.075336,0.000000
55.990002,52.663147,-320.129395,0.009265,0.002944,0.074781,234.257370,11.933640,0.747812,-320.129395,0.075709,0.000000
56.210003,53.337509,-320.173889,0.009274,0.002958,0.075145,237.257095,12.086452,0.751453,-320.173889,0.076073,0.000000
56.430004,54.205139,-320.129395,0.009257,0.002975,0.075570,241.116501,12.283060,0.755704,-320.129395,0.076437,0.000000
56.650002,54.545860,-320.129395,0.009261,0.002985,0.075830,242.632111,12.360269,0.758304,-320.129395,0.076810,0.000000
56.870003,55.016541,-320.173889,0.009257,0.002997,0.076125,244.725800,12.466927,0.761252,-320.173889,0.077175,0.000000
57.090004,55.786232,-320.218353,0.009296,0.003013,0.076524,248.149551,12.641341,0.765241,-320.218353,0.077539,0.000000
57.310001,56.722008,-320.218353,0.009265,0.003030,0.076958,252.312088,12.853391,0.769579,-320.218353,0.077903,0.000000
57.530003,57.871521,-320.173889,0.009287,0.003047,0.077383,257.425385,13.113873,0.773826,-320.173889,0.078276,0.000000
57.750004,58.299744,-320.173889,0.009283,0.003058,0.077669,259.330200,13.210911,0.776691,-320.173889,0.078640,0.000000
57.970001,59.129395,-320.173889,0.009321,0.003073,0.078059,263.020691,13.398912,0.780593,-320.173889,0.079004,0.000000
58.190002,59.582573,-320.218353,0.009278,0.003087,0.078415,265.036530,13.501604,0.784147,-320.218353,0.079377,0.000000
58.410004,60.271088,-320.262848,0.009300,0.003098,0.078692,268.099182,13.657623,0.786921,-320.262848,0.079742,0.000000
58.630001,61.151001,-320.173889,0.009373,0.003114,0.079100,272.013245,13.857015,0.790998,-320.173889,0.080106,0.000000
58.850002,61.730042,-320.173889,0.009356,0.003128,0.079456,274.588928,13.988228,0.794555,-320.173889,0.080470,0.000000
59.070004,62.433456,-320.129395,0.009343,0.003141,0.079785,277.717896,14.147624,0.797848,-320.129395,0.080843,0.000000
59.290001,63.196815,-320.173889,0.009395,0.003154,0.080123,281.113464,14.320603,0.801232,-320.173889,0.081207,0.000000
59.510002,64.515022,-320.262848,0.009352,0.003174,0.080626,286.977142,14.619313,0.806262,-320.262848,0.081571,0.000000
59.730003,65.029259,-320.262848,0.009386,0.003186,0.080921,289.264587,14.735841,0.809211,-320.262848,0.081944,0.000000
59.950005,65.999672,-320.218353,0.009425,0.003204,0.081372,293.581207,14.955739,0.813718,-320.218353,0.082309,0.000000
60.170002,67.064644,-320.218353,0.009408,0.003219,0.081771,298.318420,15.197065,0.817708,-320.218353,0.082673,0.000000
60.390003,66.936562,-320.262848,0.009412,0.003216,0.081684,297.748688,15.168042,0.816841,-320.262848,0.081918,0.000000
60.610004,66.207451,-320.262848,0.009412,0.003216,0.081684,294.505463,15.002823,0.816841,-320.262848,0.081918,0.000000
60.830002,65.667885,-320.307343,0.009399,0.003212,0.081597,292.105347,14.880556,0.815974,-320.307343,0.081684,0.000000
61.050003,65.104103,-320.218353,0.009412,0.003211,0.081571,289.597504,14.752801,0.815713,-320.218353,0.081684,0.000000
61.270004,64.585396,-320.262848,0.009438,0.003211,0.081563,287.290192,14.635260,0.815626,-320.262848,0.081684,0.000000
61.490002,64.131844,-320.262848,0.009481,0.003211,0.081554,285.272675,14.532483,0.815539,-320.262848,0.081684,0.000000
61.710003,63.721123,-320.307343,0.009455,0.003210,0.081546,283.445709,14.439413,0.815456,-320.307343,0.081684,0.000000
61.930004,63.342781,-320.262848,0.009408,0.003210,0.081537,281.762756,14.353680,0.815369,-320.262848,0.081684,0.000000
62.150002,62.997971,-320.262848,0.009429,0.003210,0.081537,280.228973,14.275544,0.815369,-320.262848,0.081684,0.000000
62.370003,62.678474,-320.262848,0.009459,0.003210,0.081537,278.807770,14.203146,0.815369,-320.262848,0.081684,0.000000
62.590004,62.382439,-320.262848,0.009399,0.003210,0.081537,277.490936,14.136063,0.815369,-320.262848,0.081684,0.000000
62.810001,62.101295,-320.351807,0.009455,0.003210,0.081528,276.240356,14.072354,0.815282,-320.351807,0.081684,0.000000
63.030003,61.854790,-320.351807,0.009455,0.003210,0.081528,275.143860,14.016496,0.815282,-320.351807,0.081684,0.000000
63.250004,61.610512,-320.262848,0.009464,0.003210,0.081528,274.057251,13.961142,0.815282,-320.262848,0.081684,0.000000
63.470001,61.391930,-320.307343,0.009464,0.003210,0.081528,273.084930,13.911611,0.815282,-320.307343,0.081684,0.000000
63.690002,61.180420,-320.351807,0.009464,0.003210,0.081528,272.144104,13.863681,0.815282,-320.351807,0.081684,0.000000
63.910004,60.990883,-320.307343,0.009434,0.003210,0.081528,271.300995,13.820732,0.815282,-320.307343,0.081684,0.000000
64.130005,60.792412,-320.351807,0.009447,0.003210,0.081528,270.418152,13.775758,0.815282,-320.351807,0.081684,0.000000
64.350006,60.613670,-320.351807,0.009477,0.003210,0.081528,269.623077,13.735254,0.815282,-320.351807,0.081684,0.000000
64.570000,60.459877,-320.262848,0.009425,0.003210,0.081528,268.938965,13.700404,0.815282,-320.262848,0.081684,0.000000
64.790001,60.290077,-320.351807,0.009455,0.003210,0.081528,268.183655,13.661927,0.815282,-320.351807,0.081684,0.000000
65.010002,60.144852,-320.307343,0.009472,0.003210,0.081528,267.537659,13.629019,0.815282,-320.307343,0.081684,0.000000
65.230003,59.989204,-320.396301,0.009451,0.003210,0.081528,266.845306,13.593748,0.815282,-320.396301,0.081684,0.000000
65.450005,59.858498,-320.396301,0.009468,0.003210,0.081528,266.263885,13.564130,0.815282,-320.396301,0.081684,0.000000
65.670006,59.725937,-320.307343,0.009511,0.003210,0.081528,265.674225,13.534091,0.815282,-320.307343,0.081684,0.000000
65.889999,59.597466,-320.351807,0.009503,0.003209,0.081519,265.102753,13.504978,0.815194,-320.351807,0.081684,0.000000
66.110001,59.482399,-320.351807,0.009447,0.003209,0.081519,264.590912,13.478905,0.815194,-320.351807,0.081684,0.000000
66.330002,59.358032,-320.396301,0.009485,0.003209,0.081519,264.037720,13.450722,0.815194,-320.396301,0.081684,0.000000
66.550003,59.253021,-320.396301,0.009503,0.003209,0.081519,263.570587,13.426927,0.815194,-320.396301,0.081684,0.000000
66.770004,59.134605,-320.396301,0.009447,0.003209,0.081519,263.043854,13.400093,0.815194,-320.396301,0.081684,0.000000
66.990005,59.031456,-320.307343,0.009481,0.003209,0.081519,262.585022,13.376719,0.815194,-320.307343,0.081684,0.000000
67.210007,58.935760,-320.351807,0.009490,0.003209,0.081519,262.159363,13.355034,0.815194,-320.351807,0.081684,0.000000
67.430000,58.837822,-320.485260,0.009481,0.003209,0.081519,261.723694,13.332841,0.815194,-320.485260,0.081684,0.000000
67.650002,58.746223,-320.396301,0.009490,0.003209,0.081519,261.316254,13.312085,0.815194,-320.396301,0.081684,0.000000
67.870003,58.656853,-320.440765,0.009451,0.003209,0.081519,260.918701,13.291833,0.815194,-320.440765,0.081684,0.000000
68.090004,58.554451,-320.351807,0.009494,0.003209,0.081519,260.463196,13.268628,0.815194,-320.351807,0.081684,0.000000
68.310005,58.482582,-320.351807,0.009464,0.003209,0.081519,260.143524,13.252342,0.815194,-320.351807,0.081684,0.000000
68.530006,58.383530,-320.485260,0.009438,0.003209,0.081519,259.702911,13.229897,0.815194,-320.485260,0.081684,0.000000
68.750000,58.325813,-320.440765,0.009442,0.003209,0.081519,259.446167,13.216819,0.815194,-320.440765,0.081684,0.000000
68.970001,58.236069,-320.440765,0.009447,0.003209,0.081519,259.046967,13.196482,0.815194,-320.440765,0.081684,0.000000
69.190002,58.157127,-320.440765,0.009429,0.003209,0.081519,258.695831,13.178593,0.815194,-320.440765,0.081684,0.000000
69.410004,58.083023,-320.440765,0.009459,0.003209,0.081519,258.366180,13.161800,0.815194,-320.440765,0.081684,0.000000
69.630005,58.001480,-320.440765,0.009490,0.003209,0.081519,258.003479,13.143323,0.815194,-320.440765,0.081684,0.000000
69.850006,57.925514,-320.485260,0.009455,0.003209,0.081519,257.665558,13.126109,0.815194,-320.485260,0.081684,0.000000
70.070000,57.874870,-320.485260,0.009498,0.003209,0.081519,257.440277,13.114633,0.815194,-320.485260,0.081684,0.000000
70.290001,57.800026,-320.440765,0.009459,0.003209,0.081519,257.107361,13.097673,0.815194,-320.440765,0.081684,0.000000
70.510002,57.728897,-320.440765,0.009516,0.003209,0.081519,256.790955,13.081554,0.815194,-320.440765,0.081684,0.000000
70.730003,57.663734,-320.485260,0.009455,0.003209,0.081519,256.501099,13.066789,0.815194,-320.485260,0.081684,0.000000
70.950005,57.590752,-320.529724,0.009498,0.003209,0.081519,256.176453,13.050251,0.815194,-320.529724,0.081684,0.000000
71.170006,57.544945,-320.485260,0.009490,0.003209,0.081519,255.972702,13.039870,0.815194,-320.485260,0.081684,0.000000
71.390007,57.483879,-320.396301,0.009516,0.003209,0.081519,255.701065,13.026033,0.815194,-320.396301,0.081684,0.000000
71.610001,57.410522,-320.485260,0.009516,0.003209,0.081519,255.374756,13.009411,0.815194,-320.485260,0.081684,0.000000
71.830002,57.362862,-320.529724,0.009481,0.003209,0.081519,255.162750,12.998610,0.815194,-320.529724,0.081684,0.000000
72.050003,57.305138,-320.485260,0.009503,0.003209,0.081519,254.905991,12.985530,0.815194,-320.485260,0.081684,0.000000
72.270004,57.263435,-320.529724,0.009472,0.003209,0.081519,254.720490,12.976080,0.815194,-320.529724,0.081684,0.000000
72.490005,57.213913,-320.485260,0.009481,0.003209,0.081519,254.500198,12.964858,0.815194,-320.485260,0.081684,0.000000
72.710007,57.153954,-320.485260,0.009511,0.003209,0.081519,254.233490,12.951271,0.815194,-320.485260,0.081684,0.000000
72.930000,57.107040,-320.485260,0.009516,0.003209,0.081519,254.024796,12.940640,0.815194,-320.485260,0.081684,0.000000
73.150002,57.050064,-320.529724,0.009459,0.003209,0.081519,253.771362,12.927730,0.815194,-320.529724,0.081684,0.000000
73.370003,57.005005,-320.485260,0.009481,0.003209,0.081519,253.570923,12.917519,0.815194,-320.485260,0.081684,0.000000
73.590004,56.961067,-320.529724,0.009455,0.003209,0.081519,253.375488,12.907562,0.815194,-320.529724,0.081684,0.000000
73.810005,56.916008,-320.485260,0.009498,0.003209,0.081519,253.175049,12.897352,0.815194,-320.485260,0.081684,0.000000
74.030006,56.873192,-320.485260,0.009494,0.003209,0.081519,252.984589,12.887650,0.815194,-320.485260,0.081684,0.000000
74.250000,56.824036,-320.574219,0.009459,0.003209,0.081519,252.765930,12.876511,0.815194,-320.574219,0.081684,0.000000
74.470001,56.768555,-320.529724,0.009468,0.003209,0.081519,252.519150,12.863938,0.815194,-320.529724,0.081684,0.000000
74.690002,56.742111,-320.485260,0.009507,0.003209,0.081519,252.401520,12.857946,0.815194,-320.485260,0.081684,0.000000
74.910004,56.693329,-320.574219,0.009511,0.003209,0.081519,252.184525,12.846891,0.815194,-320.574219,0.081684,0.000000
75.130005,56.651627,-320.574219,0.009464,0.003209,0.081519,251.999023,12.837441,0.815194,-320.574219,0.081684,0.000000
75.350006,56.623329,-320.574219,0.009516,0.003209,0.081519,251.873154,12.831030,0.815194,-320.574219,0.081684,0.000000
75.570007,56.563744,-320.574219,0.009459,0.003209,0.081519,251.608093,12.817528,0.815194,-320.574219,0.081684,0.000000
75.790001,56.530975,-320.618683,0.009507,0.003209,0.081519,251.462341,12.810102,0.815194,-320.618683,0.081684,0.000000
76.010002,56.494858,-320.529724,0.009524,0.003209,0.081519,251.301682,12.801918,0.815194,-320.529724,0.081684,0.000000
76.230003,56.464699,-320.618683,0.009511,0.003209,0.081519,251.167526,12.795084,0.815194,-320.618683,0.081684,0.000000
76.450005,56.431183,-320.618683,0.009494,0.003209,0.081519,251.018433,12.787489,0.815194,-320.618683,0.081684,0.000000
76.670006,56.379791,-320.574219,0.009524,0.003209,0.081519,250.789841,12.775843,0.815194,-320.574219,0.081684,0.000000
76.890007,56.339203,-320.663177,0.009520,0.003209,0.081519,250.609283,12.766645,0.815194,-320.663177,0.081684,0.000000
77.110001,56.317238,-320.574219,0.009498,0.003209,0.081519,250.511581,12.761669,0.815194,-320.574219,0.081684,0.000000
77.330002,56.277390,-320.529724,0.009459,0.003209,0.081519,250.334335,12.752639,0.815194,-320.529724,0.081684,0.000000
77.550003,56.238663,-320.618683,0.009511,0.003209,0.081519,250.162064,12.743863,0.815194,-320.618683,0.081684,0.000000
77.770004,56.199196,-320.618683,0.009485,0.003209,0.081519,249.986511,12.734921,0.815194,-320.618683,0.081684,0.000000
77.990005,56.163445,-320.574219,0.009472,0.003209,0.081519,249.827484,12.726819,0.815194,-320.574219,0.081684,0.000000
78.210007,56.132912,-320.618683,0.009503,0.003209,0.081519,249.691666,12.719900,0.815194,-320.618683,0.081684,0.000000
78.430000,56.095299,-320.574219,0.009464,0.003209,0.081519,249.524353,12.711376,0.815194,-320.574219,0.081684,0.000000
78.650002,56.069611,-320.663177,0.009503,0.003209,0.081519,249.410080,12.705555,0.815194,-320.663177,0.081684,0.000000
78.870003,56.040192,-320.618683,0.009528,0.003209,0.081519,249.279221,12.698889,0.815194,-320.618683,0.081684,0.000000
79.090004,56.005936,-320.663177,0.009516,0.003209,0.081519,249.126846,12.691127,0.815194,-320.663177,0.081684,0.000000
79.310005,55.976517,-320.663177,0.009468,0.003209,0.081519,248.995987,12.684460,0.815194,-320.663177,0.081684,0.000000
79.530006,55.942261,-320.618683,0.009477,0.003209,0.081519,248.843597,12.676698,0.815194,-320.618683,0.081684,0.000000
79.750000,55.906509,-320.663177,0.009520,0.003209,0.081519,248.684570,12.668596,0.815194,-320.663177,0.081684,0.000000
79.970001,55.871880,-320.707672,0.009485,0.003209,0.081519,248.530533,12.660748,0.815194,-320.707672,0.081684,0.000000
80.190002,55.858101,-320.707672,0.009481,0.003209,0.081519,248.469238,12.657626,0.815194,-320.707672,0.081684,0.000000
80.410004,55.818260,-320.663177,0.009468,0.003209,0.081519,248.292023,12.648599,0.815194,-320.663177,0.081684,0.000000
80.630005,55.792191,-320.663177,0.009498,0.003209,0.081519,248.176056,12.642691,0.815194,-320.663177,0.081684,0.000000
80.850006,55.763893,-320.663177,0.009451,0.003209,0.081519,248.050186,12.636279,0.815194,-320.663177,0.081684,0.000000
81.070007,55.725540,-320.707672,0.009451,0.003209,0.081519,247.879578,12.627588,0.815194,-320.707672,0.081684,0.000000
81.290001,55.703941,-320.752136,0.009511,0.003209,0.081519,247.783508,12.622694,0.815194,-320.752136,0.081684,0.000000
81.510002,55.668190,-320.663177,0.009468,0.003209,0.081519,247.624481,12.614593,0.815194,-320.663177,0.081684,0.000000
81.730003,55.650314,-320.663177,0.009498,0.003209,0.081519,247.544968,12.610541,0.815194,-320.663177,0.081684,0.000000
81.950005,55.627602,-320.752136,0.009455,0.003209,0.081519,247.443924,12.605395,0.815194,-320.752136,0.081684,0.000000
82.170006,55.601166,-320.707672,0.009498,0.003209,0.081519,247.326340,12.599404,0.815194,-320.707672,0.081684,0.000000
82.390007,55.568771,-320.707672,0.009528,0.003209,0.081519,247.182236,12.592063,0.815194,-320.707672,0.081684,0.000000
82.610001,55.544563,-320.663177,0.009464,0.003209,0.081519,247.074554,12.586578,0.815194,-320.663177,0.081684,0.000000
82.830002,55.535255,-320.707672,0.009442,0.003209,0.081519,247.033157,12.584469,0.815194,-320.707672,0.081684,0.000000
83.050003,55.509933,-320.707672,0.009511,0.003209,0.081519,246.920517,12.578731,0.815194,-320.707672,0.081684,0.000000
83.270004,55.493179,-320.752136,0.009516,0.003209,0.081519,246.845993,12.574934,0.815194,-320.752136,0.081684,0.000000
83.490005,55.457054,-320.707672,0.009520,0.003209,0.081519,246.685303,12.566748,0.815194,-320.707672,0.081684,0.000000
83.710007,55.425407,-320.707672,0.009459,0.003209,0.081519,246.544525,12.559577,0.815194,-320.707672,0.081684,0.000000
83.930000,55.406410,-320.796631,0.009516,0.003209,0.081519,246.460022,12.555272,0.815194,-320.796631,0.081684,0.000000
84.150002,55.378113,-320.752136,0.009503,0.003209,0.081519,246.334152,12.548860,0.815194,-320.752136,0.081684,0.000000
84.370003,55.352791,-320.841095,0.009528,0.003209,0.081519,246.221512,12.543121,0.815194,-320.841095,0.081684,0.000000
84.590004,55.340874,-320.841095,0.009524,0.003209,0.081519,246.168503,12.540421,0.815194,-320.841095,0.081684,0.000000
84.810005,55.334175,-320.796631,0.009524,0.003209,0.081519,246.138702,12.538903,0.815194,-320.796631,0.081684,0.000000
85.030006,55.303268,-320.796631,0.009516,0.003209,0.081519,246.001221,12.531899,0.815194,-320.796631,0.081684,0.000000
85.250008,55.277946,-320.752136,0.009511,0.003209,0.081519,245.888580,12.526162,0.815194,-320.752136,0.081684,0.000000
85.470001,55.249641,-320.796631,0.009464,0.003209,0.081519,245.762680,12.519748,0.815194,-320.796631,0.081684,0.000000
85.690002,55.228050,-320.796631,0.009464,0.003209,0.081519,245.666641,12.514854,0.815194,-320.796631,0.081684,0.000000
85.910004,55.193413,-320.796631,0.009528,0.003209,0.081519,245.512558,12.507006,0.815194,-320.796631,0.081684,0.000000
86.130005,55.187462,-320.752136,0.009490,0.003209,0.081519,245.486084,12.505657,0.815194,-320.752136,0.081684,0.000000
86.350006,55.171822,-320.752136,0.009464,0.003209,0.081519,245.416519,12.502113,0.815194,-320.752136,0.081684,0.000000
86.570007,55.151711,-320.796631,0.009511,0.003209,0.081519,245.327057,12.497556,0.815194,-320.796631,0.081684,0.000000
86.790001,55.127510,-320.841095,0.009490,0.003209,0.081519,245.219406,12.492073,0.815194,-320.841095,0.081684,0.000000
87.010002,55.092133,-320.841095,0.009520,0.003209,0.081519,245.062042,12.484056,0.815194,-320.841095,0.081684,0.000000
87.230003,55.073883,-320.707672,0.009498,0.003209,0.081519,244.980865,12.479920,0.815194,-320.707672,0.081684,0.000000
87.450005,55.053780,-320.885590,0.009533,0.003209,0.081519,244.891449,12.475365,0.815194,-320.885590,0.081684,0.000000
87.670006,55.030693,-320.841095,0.009485,0.003209,0.081519,244.788742,12.470134,0.815194,-320.841095,0.081684,0.000000
87.890007,55.008720,-320.885590,0.009481,0.003209,0.081519,244.691010,12.465155,0.815194,-320.885590,0.081684,0.000000
88.110001,55.001648,-320.841095,0.009507,0.003209,0.081519,244.659546,12.463552,0.815194,-320.841095,0.081684,0.000000
88.330002,54.984512,-320.841095,0.009533,0.003209,0.081519,244.583328,12.459668,0.815194,-320.841095,0.081684,0.000000
88.550003,54.961800,-320.841095,0.009451,0.003209,0.081519,244.482300,12.454521,0.815194,-320.841095,0.081684,0.000000
88.770004,54.943184,-320.885590,0.009520,0.003209,0.081519,244.399490,12.450304,0.815194,-320.885590,0.081684,0.000000
88.990005,54.929405,-320.885590,0.009503,0.003209,0.081519,244.338196,12.447181,0.815194,-320.885590,0.081684,0.000000
89.210007,54.904083,-320.841095,0.009464,0.003209,0.081519,244.225555,12.441443,0.815194,-320.841095,0.081684,0.000000
89.430008,54.879509,-320.885590,0.009507,0.003209,0.081519,244.116241,12.435875,0.815194,-320.885590,0.081684,0.000000
89.650002,54.856789,-320.841095,0.009455,0.003209,0.081519,244.015182,12.430726,0.815194,-320.841095,0.081684,0.000000
89.870003,54.834076,-320.885590,0.009524,0.003209,0.081519,243.914154,12.425580,0.815194,-320.885590,0.081684,0.000000
90.090004,54.821785,-320.885590,0.009490,0.003209,0.081519,243.859482,12.422794,0.815194,-320.885590,0.081684,0.000000
90.310005,54.805031,-320.930054,0.009520,0.003209,0.081519,243.784958,12.418998,0.815194,-320.930054,0.081684,0.000000
90.530006,54.791626,-320.885590,0.009533,0.003209,0.081519,243.725327,12.415960,0.815194,-320.885590,0.081684,0.000000
90.750008,54.773750,-320.930054,0.009472,0.003209,0.081519,243.645813,12.411909,0.815194,-320.930054,0.081684,0.000000
90.800003,54.759232,-320.885590,0.009472,0.003209,0.081519,243.581223,12.408619,0.815194,-320.885590,0.081684,0.000000