File: Data/Compression Sample NH 10, 12, 15, 17 batch 3/AutoNoheating-15-3-5-240215_02152024_163226.csv
Time (sec),S:Load (lbs),S:HL1 (DIM),S:LVDT (in),S:Position (in),Ch:Position (mm),Ch:Load (N),Ch:Stress (MPa),Ch:Strain (mm/mm),Ch:HL1 (DIM),Set Point (),Cycles ()
0.010000,0.000740,-36.118534,-0.000026,-0.000000,-0.000000,0.003292,0.000168,-0.000000,-36.118534,0.000174,0.000000
0.220000,-0.003357,-36.207493,-0.000022,-0.000000,-0.000000,-0.014932,-0.000761,-0.000000,-36.207493,0.000174,0.000000
0.430000,0.008186,-36.118534,-0.000017,0.000044,0.001128,0.036415,0.001855,0.011275,-36.118534,0.001717,0.000000
0.640000,-0.019363,-36.207493,0.000009,0.000166,0.004215,-0.086133,-0.004388,0.042149,-36.207493,0.005221,0.000000
0.850000,-0.000748,-36.163013,0.000121,0.000301,0.007641,-0.003326,-0.000169,0.076406,-36.163013,0.008725,0.000000
1.060000,-0.008942,-36.207493,0.000280,0.000438,0.011135,-0.039774,-0.002026,0.111352,-36.207493,0.012211,0.000000
1.270000,0.008186,-36.207493,0.000401,0.000569,0.014457,0.036415,0.001855,0.144568,-36.207493,0.015714,0.000000
1.480000,0.020103,-36.207493,0.000548,0.000709,0.018004,0.089425,0.004556,0.180036,-36.207493,0.019218,0.000000
1.690000,-0.004471,-36.207493,0.000677,0.000847,0.021525,-0.019887,-0.001013,0.215247,-36.207493,0.022704,0.000000
1.900000,-0.001122,-36.207493,0.000815,0.000988,0.025089,-0.004989,-0.000254,0.250889,-36.207493,0.026208,0.000000
2.110000,-0.026070,-36.163013,0.000953,0.001129,0.028688,-0.115964,-0.005907,0.286880,-36.163013,0.029711,0.000000
2.320000,-0.020485,-36.163013,0.001082,0.001265,0.032131,-0.091121,-0.004642,0.321307,-36.163013,0.033215,0.000000
2.530000,-0.044685,-36.163013,0.001229,0.001402,0.035608,-0.198770,-0.010126,0.356083,-36.163013,0.036701,0.000000
2.740000,-0.006706,-36.207493,0.001367,0.001537,0.039051,-0.029831,-0.001520,0.390514,-36.207493,0.040205,0.000000
2.950000,0.001862,-36.207493,0.001505,0.001675,0.042538,0.008281,0.000422,0.425377,-36.207493,0.043708,0.000000
3.160000,-0.010803,-36.207493,0.001660,0.001817,0.046162,-0.048055,-0.002448,0.461625,-36.207493,0.047195,0.000000
3.370000,0.001488,-36.251976,0.001794,0.001955,0.049666,0.006618,0.000337,0.496661,-36.251976,0.050698,0.000000
3.580000,0.018990,-36.207493,0.001940,0.002093,0.053152,0.084470,0.004303,0.531524,-36.207493,0.054202,0.000000
3.790000,0.010796,-36.296455,0.002074,0.002225,0.056517,0.048021,0.002446,0.565172,-36.296455,0.057705,0.000000
4.000000,0.028297,-36.251976,0.002199,0.002361,0.059977,0.125873,0.006412,0.599773,-36.251976,0.061192,0.000000
4.210000,-0.010429,-36.296455,0.002345,0.002497,0.063429,-0.046392,-0.002363,0.634292,-36.296455,0.064695,0.000000
4.420000,0.003723,-36.296455,0.002471,0.002640,0.067045,0.016561,0.000844,0.670453,-36.296455,0.068199,0.000000
4.630000,-0.007820,-36.296455,0.002630,0.002783,0.070697,-0.034786,-0.001772,0.706965,-36.296455,0.071685,0.000000
4.840000,0.030533,-36.296455,0.002764,0.002917,0.074096,0.135817,0.006919,0.740958,-36.296455,0.075188,0.000000
5.050000,0.430458,-36.296455,0.002902,0.003054,0.077582,1.914773,0.097543,0.775820,-36.296455,0.078692,0.000000
5.260000,0.682182,-36.251976,0.002940,-0.000011,-0.000277,3.034498,0.154585,-0.002774,-36.251976,-0.000061,0.000000
5.470000,0.652390,-36.296455,0.002936,-0.000011,-0.000277,2.901973,0.147834,-0.002774,-36.296455,-0.000061,0.000000
5.680000,0.670639,-36.251976,0.002936,-0.000011,-0.000277,2.983151,0.151969,-0.002774,-36.251976,0.000052,0.000000
5.890000,0.691490,-36.296455,0.002949,-0.000011,-0.000269,3.075902,0.156694,-0.002687,-36.296455,0.000399,0.000000
6.100000,0.659470,-36.296455,0.002928,-0.000011,-0.000269,2.933467,0.149438,-0.002687,-36.296455,0.000746,0.000000
6.310000,0.656487,-36.251976,0.002945,-0.000011,-0.000269,2.920198,0.148762,-0.002687,-36.251976,0.001101,0.000000
6.520000,1.055298,-36.340939,0.002945,0.000023,0.000572,4.694199,0.239134,0.005723,-36.340939,0.001448,0.000000
6.730000,1.182655,-36.296455,0.002971,0.000031,0.000798,5.260714,0.267994,0.007979,-36.296455,0.001804,0.000000
6.940001,1.540504,-36.385418,0.002984,0.000056,0.001414,6.852506,0.349083,0.014137,-36.385418,0.002151,0.000000
7.150001,1.762810,-36.340939,0.003009,0.000070,0.001769,7.841370,0.399458,0.017691,-36.340939,0.002498,0.000000
7.360000,1.933357,-36.296455,0.003005,0.000081,0.002055,8.600002,0.438105,0.020552,-36.296455,0.002853,0.000000
7.570000,2.102036,-36.340939,0.003022,0.000093,0.002359,9.350321,0.476328,0.023587,-36.340939,0.003200,0.000000
7.780000,2.352272,-36.296455,0.003035,0.000107,0.002723,10.463428,0.533032,0.027232,-36.296455,0.003547,0.000000
7.990000,2.673630,-36.340939,0.003048,0.000124,0.003157,11.892900,0.605853,0.031566,-36.340939,0.003903,0.000000
8.200001,2.881416,-36.340939,0.003057,0.000136,0.003460,12.817180,0.652938,0.034602,-36.340939,0.004249,0.000000
8.410001,3.096649,-36.340939,0.003065,0.000148,0.003755,13.774584,0.701711,0.037550,-36.340939,0.004596,0.000000
8.620001,3.290283,-36.385418,0.003083,0.000158,0.004024,14.635911,0.745589,0.040241,-36.385418,0.004952,0.000000
8.830001,3.725952,-36.385418,0.003087,0.000179,0.004553,16.573862,0.844313,0.045529,-36.385418,0.005299,0.000000
9.040000,3.999649,-36.385418,0.003117,0.000194,0.004926,17.791328,0.906333,0.049257,-36.385418,0.005654,0.000000
9.250000,4.192909,-36.385418,0.003122,0.000206,0.005221,18.650991,0.950127,0.052205,-36.385418,0.006001,0.000000
9.460000,4.388779,-36.429897,0.003139,0.000217,0.005524,19.522263,0.994511,0.055241,-36.429897,0.006348,0.000000
9.670000,4.551880,-36.429897,0.003134,0.000229,0.005819,20.247772,1.031471,0.058189,-36.429897,0.006704,0.000000
9.880000,4.803604,-36.385418,0.003139,0.000239,0.006071,21.367498,1.088512,0.060706,-36.385418,0.007051,0.000000
10.090000,5.272415,-36.429897,0.003165,0.000261,0.006617,23.452873,1.194746,0.066168,-36.429897,0.007398,0.000000
10.300000,5.381523,-36.385418,0.003173,0.000269,0.006842,23.938210,1.219471,0.068423,-36.385418,0.007753,0.000000
10.510000,5.460464,-36.429897,0.003186,0.000278,0.007051,24.289360,1.237359,0.070505,-36.429897,0.008100,0.000000
10.720000,5.631760,-36.474380,0.003178,0.000287,0.007293,25.051317,1.276175,0.072935,-36.474380,0.008447,0.000000
10.930000,6.317665,-36.385418,0.003212,0.000317,0.008048,28.102379,1.431603,0.080478,-36.385418,0.008802,0.000000
11.140000,6.405174,-36.429897,0.003212,0.000328,0.008325,28.491638,1.451433,0.083253,-36.429897,0.009149,0.000000
11.350000,6.474068,-36.429897,0.003234,0.000336,0.008525,28.798092,1.467045,0.085247,-36.429897,0.009496,0.000000
11.560000,6.770470,-36.474380,0.003242,0.000354,0.008985,30.116552,1.534210,0.089846,-36.474380,0.009852,0.000000
11.770000,6.852020,-36.474380,0.003260,0.000361,0.009175,30.479309,1.552690,0.091753,-36.474380,0.010198,0.000000
11.980000,7.313019,-36.429897,0.003285,0.000383,0.009722,32.529934,1.657154,0.097215,-36.429897,0.010554,0.000000
12.190001,7.493996,-36.518860,0.003285,0.000395,0.010025,33.334957,1.698164,0.100251,-36.518860,0.010901,0.000000
12.400001,7.553574,-36.474380,0.003294,0.000405,0.010277,33.599972,1.711664,0.102767,-36.474380,0.011248,0.000000
12.610001,7.638474,-36.429897,0.003311,0.000414,0.010528,33.977627,1.730903,0.105281,-36.429897,0.011603,0.000000
12.820001,7.950897,-36.429897,0.003311,0.000433,0.010988,35.367355,1.801699,0.109876,-36.429897,0.011950,0.000000
13.030001,8.213043,-36.429897,0.003346,0.000451,0.011447,36.533440,1.861102,0.114474,-36.429897,0.012297,0.000000
13.240001,8.249908,-36.518860,0.003341,0.000462,0.011734,36.697426,1.869456,0.117336,-36.518860,0.012653,0.000000
13.450001,8.440193,-36.474380,0.003363,0.000478,0.012132,37.543854,1.912575,0.121325,-36.474380,0.013000,0.000000
13.660001,8.505730,-36.518860,0.003376,0.000489,0.012410,37.835377,1.927426,0.124099,-36.518860,0.013347,0.000000
13.870001,8.757080,-36.474380,0.003393,0.000504,0.012800,38.953438,1.984383,0.128001,-36.474380,0.013702,0.000000
14.080001,8.924644,-36.474380,0.003402,0.000517,0.013130,39.698803,2.022353,0.131298,-36.474380,0.014049,0.000000
14.290001,8.923157,-36.563343,0.003415,0.000527,0.013381,39.692184,2.022016,0.133811,-36.563343,0.014405,0.000000
14.500001,9.044548,-36.474380,0.003432,0.000540,0.013711,40.232159,2.049524,0.137108,-36.474380,0.014752,0.000000
14.710001,9.498474,-36.563343,0.003445,0.000562,0.014274,42.251324,2.152385,0.142744,-36.563343,0.015098,0.000000
14.920001,9.479858,-36.474380,0.003445,0.000575,0.014595,42.168518,2.148167,0.145953,-36.474380,0.015454,0.000000
15.130001,9.514488,-36.518860,0.003471,0.000589,0.014951,42.322556,2.156014,0.149511,-36.518860,0.015801,0.000000
15.340001,9.581139,-36.563343,0.003484,0.000599,0.015220,42.619034,2.171117,0.152198,-36.563343,0.016148,0.000000
15.550001,9.640350,-36.518860,0.003492,0.000615,0.015610,42.882420,2.184535,0.156100,-36.518860,0.016503,0.000000
15.760001,9.927444,-36.518860,0.003510,0.000632,0.016052,44.159477,2.249591,0.160525,-36.518860,0.016850,0.000000
15.970001,9.971016,-36.518860,0.003518,0.000643,0.016330,44.353294,2.259465,0.163299,-36.518860,0.017197,0.000000
16.180000,9.990753,-36.518860,0.003540,0.000654,0.016616,44.441090,2.263937,0.166161,-36.518860,0.017552,0.000000
16.390001,10.054428,-36.607822,0.003535,0.000667,0.016946,44.724331,2.278366,0.169457,-36.607822,0.017900,0.000000
16.600000,10.088684,-36.563343,0.003557,0.000677,0.017206,44.876709,2.286128,0.172058,-36.563343,0.018255,0.000000
16.810001,10.468880,-36.607822,0.003566,0.000697,0.017700,46.567902,2.372282,0.177001,-36.607822,0.018602,0.000000
17.020000,10.443924,-36.607822,0.003583,0.000706,0.017943,46.456894,2.366627,0.179431,-36.607822,0.018949,0.000000
17.230001,10.623039,-36.563343,0.003609,0.000725,0.018420,47.253639,2.407215,0.184199,-36.563343,0.019304,0.000000
17.440001,10.582077,-36.652302,0.003609,0.000737,0.018723,47.071430,2.397933,0.187235,-36.652302,0.019651,0.000000
17.650002,10.618568,-36.563343,0.003626,0.000747,0.018984,47.233753,2.406202,0.189835,-36.563343,0.019998,0.000000
17.860001,10.900459,-36.652302,0.003648,0.000765,0.019443,48.487663,2.470079,0.194430,-36.652302,0.020354,0.000000
18.070002,10.982376,-36.607822,0.003648,0.000779,0.019790,48.852047,2.488642,0.197901,-36.607822,0.020701,0.000000
18.280001,10.872902,-36.607822,0.003665,0.000787,0.019990,48.365082,2.463835,0.199895,-36.607822,0.021047,0.000000
18.490002,10.976044,-36.652302,0.003669,0.000801,0.020337,48.823879,2.487207,0.203366,-36.652302,0.021403,0.000000
18.700001,11.399437,-36.607822,0.003695,0.000824,0.020918,50.707230,2.583149,0.209176,-36.607822,0.021750,0.000000
18.910002,11.443748,-36.696785,0.003699,0.000836,0.021238,50.904335,2.593190,0.212382,-36.696785,0.022097,0.000000
19.120001,11.337250,-36.607822,0.003708,0.000847,0.021516,50.430607,2.569057,0.215160,-36.607822,0.022452,0.000000
19.330002,11.377464,-36.607822,0.003734,0.000859,0.021811,50.609489,2.578170,0.218108,-36.607822,0.022799,0.000000
19.540001,11.411720,-36.652302,0.003742,0.000870,0.022106,50.761868,2.585933,0.221057,-36.652302,0.023155,0.000000
19.750000,11.785210,-36.607822,0.003751,0.000889,0.022583,52.423229,2.670567,0.225826,-36.607822,0.023502,0.000000
19.960001,11.863785,-36.652302,0.003764,0.000902,0.022904,52.772751,2.688372,0.229035,-36.652302,0.023849,0.000000
20.170000,11.842934,-36.652302,0.003777,0.000913,0.023190,52.680000,2.683647,0.231897,-36.652302,0.024204,0.000000
20.380001,11.930809,-36.607822,0.003798,0.000927,0.023545,53.070889,2.703560,0.235451,-36.607822,0.024551,0.000000
20.590000,12.066727,-36.696785,0.003811,0.000943,0.023944,53.675480,2.734359,0.239440,-36.696785,0.024898,0.000000
20.800001,12.398140,-36.607822,0.003829,0.000963,0.024456,55.149681,2.809459,0.244557,-36.607822,0.025254,0.000000
21.010000,12.318451,-36.741264,0.003842,0.000974,0.024733,54.795208,2.791401,0.247332,-36.741264,0.025601,0.000000
21.220001,12.229828,-36.696785,0.003846,0.000985,0.025011,54.400990,2.771319,0.250110,-36.696785,0.025947,0.000000
21.430000,12.382874,-36.652302,0.003876,0.001001,0.025427,55.081772,2.805999,0.254269,-36.652302,0.026303,0.000000
21.640001,12.590279,-36.696785,0.003880,0.001016,0.025817,56.004356,2.852998,0.258171,-36.696785,0.026650,0.000000
21.850000,12.657684,-36.696785,0.003902,0.001030,0.026164,56.304192,2.868272,0.261642,-36.696785,0.027005,0.000000
22.060001,12.487877,-36.652302,0.003902,0.001036,0.026320,55.548851,2.829793,0.263202,-36.652302,0.027352,0.000000
22.270000,12.853920,-36.696785,0.003902,0.001055,0.026797,57.177094,2.912740,0.267974,-36.696785,0.027699,0.000000
22.480001,13.026703,-36.741264,0.003936,0.001070,0.027170,57.945667,2.951893,0.271702,-36.741264,0.028055,0.000000
22.690001,13.241936,-36.652302,0.003954,0.001088,0.027647,58.903072,3.000665,0.276471,-36.652302,0.028401,0.000000
22.900002,13.102295,-36.652302,0.003958,0.001096,0.027847,58.281918,2.969023,0.278466,-36.652302,0.028749,0.000000
23.110001,13.181236,-36.741264,0.003984,0.001110,0.028202,58.633068,2.986911,0.282020,-36.741264,0.029104,0.000000
23.320002,13.192039,-36.696785,0.003980,0.001122,0.028506,58.681122,2.989359,0.285056,-36.696785,0.029451,0.000000
23.530001,13.593826,-36.696785,0.004005,0.001142,0.029009,60.468361,3.080405,0.290086,-36.696785,0.029798,0.000000
23.740002,13.498871,-36.785748,0.004018,0.001152,0.029269,60.045975,3.058888,0.292690,-36.785748,0.030153,0.000000
23.950001,13.569618,-36.652302,0.004018,0.001163,0.029538,60.360676,3.074919,0.295377,-36.652302,0.030500,0.000000
24.160002,13.434822,-36.741264,0.004031,0.001172,0.029772,59.761074,3.044374,0.297720,-36.741264,0.030856,0.000000
24.370001,13.797516,-36.785748,0.004053,0.001188,0.030180,61.374416,3.126562,0.301796,-36.785748,0.031203,0.000000
24.580002,14.260376,-36.741264,0.004066,0.001211,0.030752,63.433319,3.231447,0.307519,-36.741264,0.031550,0.000000
24.790001,14.238403,-36.785748,0.004074,0.001222,0.031038,63.335583,3.226468,0.310380,-36.785748,0.031905,0.000000
25.000002,14.159828,-36.741264,0.004087,0.001234,0.031333,62.986061,3.208663,0.313329,-36.741264,0.032252,0.000000
25.210001,14.356071,-36.785748,0.004100,0.001248,0.031688,63.858994,3.253132,0.316883,-36.785748,0.032599,0.000000
25.420002,14.471138,-36.785748,0.004122,0.001262,0.032053,64.370834,3.279207,0.320528,-36.785748,0.032955,0.000000
25.630001,14.636093,-36.785748,0.004130,0.001276,0.032399,65.104591,3.316586,0.323995,-36.785748,0.033301,0.000000
25.840002,14.764565,-36.785748,0.004135,0.001289,0.032747,65.676064,3.345698,0.327465,-36.785748,0.033648,0.000000
26.050001,14.589920,-36.785748,0.004143,0.001297,0.032946,64.899208,3.306123,0.329460,-36.785748,0.034004,0.000000
26.260002,14.911278,-36.830227,0.004161,0.001313,0.033354,66.328674,3.378944,0.333536,-36.830227,0.034351,0.000000
26.470001,15.377487,-36.785748,0.004182,0.001336,0.033935,68.402481,3.484588,0.339346,-36.785748,0.034706,0.000000
26.680002,15.284027,-36.741264,0.004204,0.001348,0.034238,67.986748,3.463410,0.342382,-36.741264,0.035053,0.000000
26.890001,15.272110,-36.830227,0.004199,0.001360,0.034533,67.933739,3.460710,0.345330,-36.830227,0.035400,0.000000
27.100000,15.329826,-36.830227,0.004221,0.001370,0.034810,68.190475,3.473788,0.348104,-36.830227,0.035756,0.000000
27.310001,15.462021,-36.830227,0.004234,0.001385,0.035175,68.778503,3.503744,0.351745,-36.830227,0.036103,0.000000
27.520000,15.860085,-36.785748,0.004247,0.001402,0.035600,70.549179,3.593946,0.355996,-36.785748,0.036449,0.000000
27.730001,15.775185,-36.830227,0.004255,0.001412,0.035877,70.171524,3.574708,0.358770,-36.830227,0.036805,0.000000
27.940001,15.796410,-36.874710,0.004273,0.001422,0.036129,70.265938,3.579518,0.361287,-36.874710,0.037152,0.000000
28.150002,16.096916,-36.874710,0.004277,0.001442,0.036614,71.602661,3.647613,0.366143,-36.874710,0.037499,0.000000
28.360001,16.498329,-36.919189,0.004303,0.001459,0.037056,73.388237,3.738575,0.370564,-36.919189,0.037854,0.000000
28.570002,16.533333,-36.785748,0.004307,0.001473,0.037412,73.543938,3.746507,0.374122,-36.785748,0.038201,0.000000
28.780001,16.531097,-36.874710,0.004337,0.001485,0.037716,73.533997,3.746000,0.377157,-36.874710,0.038548,0.000000
28.990002,16.507271,-36.830227,0.004337,0.001497,0.038028,73.428009,3.740601,0.380280,-36.830227,0.038904,0.000000
29.200001,16.576904,-36.830227,0.004355,0.001508,0.038314,73.737755,3.756380,0.383141,-36.830227,0.039250,0.000000
29.410002,17.074760,-36.919189,0.004350,0.001529,0.038826,75.952332,3.869196,0.388258,-36.919189,0.039606,0.000000
29.620001,16.959702,-36.874710,0.004385,0.001537,0.039034,75.440521,3.843123,0.390340,-36.874710,0.039953,0.000000
29.830002,17.069923,-36.919189,0.004385,0.001550,0.039363,75.930809,3.868100,0.393633,-36.919189,0.040300,0.000000
30.040001,17.639282,-36.919189,0.004406,0.001570,0.039875,78.463448,3.997119,0.398750,-36.919189,0.040655,0.000000
30.250002,17.714127,-36.919189,0.004415,0.001585,0.040248,78.796371,4.014078,0.402478,-36.919189,0.041003,0.000000
30.460001,17.778923,-36.919189,0.004428,0.001597,0.040569,79.084602,4.028761,0.405688,-36.919189,0.041349,0.000000
30.670002,17.718224,-36.874710,0.004441,0.001607,0.040820,78.814598,4.015007,0.408205,-36.874710,0.041705,0.000000
30.880001,17.832916,-36.963669,0.004458,0.001621,0.041185,79.324776,4.040997,0.411846,-36.963669,0.042052,0.000000
31.090002,17.900688,-36.874710,0.004458,0.001632,0.041453,79.626236,4.056354,0.414533,-36.874710,0.042399,0.000000
31.300001,18.376953,-36.919189,0.004467,0.001652,0.041965,81.744774,4.164277,0.419650,-36.919189,0.042754,0.000000
31.510002,18.526642,-36.963669,0.004493,0.001664,0.042277,82.410622,4.198197,0.422773,-36.963669,0.043101,0.000000
31.720001,18.405998,-36.963669,0.004497,0.001675,0.042537,81.873970,4.170859,0.425373,-36.963669,0.043457,0.000000
31.930002,18.335617,-36.963669,0.004510,0.001680,0.042676,81.560898,4.154910,0.426762,-36.963669,0.043804,0.000000
32.140003,19.108665,-36.874710,0.004514,0.001704,0.043283,84.999588,4.330085,0.432833,-36.874710,0.044150,0.000000
32.350002,19.537636,-36.963669,0.004540,0.001722,0.043743,86.907745,4.427292,0.437428,-36.963669,0.044506,0.000000
32.560001,19.371559,-36.963669,0.004557,0.001733,0.044012,86.168999,4.389658,0.440115,-36.963669,0.044853,0.000000
32.770000,19.491463,-36.919189,0.004562,0.001744,0.044307,86.702354,4.416828,0.443067,-36.919189,0.045200,0.000000
32.980003,19.577477,-36.919189,0.004587,0.001756,0.044602,87.084969,4.436320,0.446016,-36.919189,0.045555,0.000000
33.190002,19.438957,-36.919189,0.004596,0.001766,0.044862,86.468803,4.404931,0.448616,-36.919189,0.045902,0.000000
33.400002,20.171783,-37.008152,0.004605,0.001787,0.045399,89.728577,4.570992,0.453994,-37.008152,0.046249,0.000000
33.610001,20.276794,-37.052631,0.004618,0.001800,0.045720,90.195686,4.594788,0.457200,-37.052631,0.046605,0.000000
33.820004,20.216095,-36.963669,0.004622,0.001811,0.046006,89.925682,4.581032,0.460062,-36.963669,0.046952,0.000000
34.030003,20.613792,-37.008152,0.004639,0.001825,0.046362,91.694725,4.671152,0.463619,-37.008152,0.047307,0.000000
34.240002,20.998451,-36.963669,0.004648,0.001843,0.046821,93.405777,4.758317,0.468214,-36.963669,0.047654,0.000000
34.450001,20.903496,-37.008152,0.004669,0.001853,0.047073,92.983391,4.736800,0.470731,-37.008152,0.048001,0.000000
34.660000,21.338058,-37.052631,0.004665,0.001870,0.047506,94.916428,4.835273,0.475065,-37.052631,0.048357,0.000000
34.870003,21.285927,-37.008152,0.004687,0.001880,0.047749,94.684532,4.823460,0.477495,-37.008152,0.048703,0.000000
35.080002,21.288902,-37.052631,0.004704,0.001890,0.048018,94.697769,4.824134,0.480182,-37.052631,0.049050,0.000000
35.290001,21.797935,-37.008152,0.004717,0.001908,0.048469,96.962059,4.939483,0.484694,-37.008152,0.049406,0.000000
35.500000,21.879860,-36.963669,0.004730,0.001918,0.048729,97.326477,4.958047,0.487294,-36.963669,0.049753,0.000000
35.710003,22.160995,-37.008152,0.004738,0.001934,0.049128,98.577034,5.021753,0.491283,-37.008152,0.050100,0.000000
35.920002,22.223557,-37.052631,0.004743,0.001944,0.049371,98.855316,5.035930,0.493713,-37.052631,0.050455,0.000000
36.130001,23.186516,-37.008152,0.004764,0.001969,0.050004,103.138771,5.254139,0.500041,-37.008152,0.050802,0.000000
36.340000,22.984688,-37.008152,0.004777,0.001978,0.050238,102.240997,5.208405,0.502384,-37.008152,0.051149,0.000000
36.550003,23.100868,-37.008152,0.004803,0.001991,0.050576,102.757797,5.234732,0.505764,-37.008152,0.051504,0.000000
36.760002,23.174973,-37.008152,0.004807,0.002004,0.050897,103.087425,5.251524,0.508974,-37.008152,0.051852,0.000000
36.970001,23.669106,-37.097115,0.004812,0.002021,0.051322,105.285439,5.363496,0.513224,-37.097115,0.052207,0.000000
37.180000,23.918228,-37.052631,0.004829,0.002036,0.051713,106.393593,5.419948,0.517126,-37.052631,0.052554,0.000000
37.390003,23.955833,-37.052631,0.004842,0.002045,0.051956,106.560867,5.428470,0.519556,-37.052631,0.052901,0.000000
37.600002,24.031052,-37.097115,0.004846,0.002057,0.052250,106.895454,5.445514,0.522505,-37.097115,0.053257,0.000000
37.810001,24.258575,-37.097115,0.004868,0.002069,0.052554,107.907532,5.497072,0.525540,-37.097115,0.053603,0.000000
38.020000,24.674515,-37.008152,0.004872,0.002085,0.052953,109.757721,5.591325,0.529530,-37.008152,0.053950,0.000000
38.230003,25.402870,-37.097115,0.004881,0.002104,0.053447,112.997612,5.756373,0.534473,-37.097115,0.054306,0.000000
38.440002,25.545120,-37.052631,0.004902,0.002116,0.053751,113.630371,5.788607,0.537508,-37.052631,0.054652,0.000000
38.650002,25.489265,-37.052631,0.004919,0.002127,0.054020,113.381912,5.775950,0.540195,-37.052631,0.054999,0.000000
38.860001,25.713806,-37.141594,0.004911,0.002140,0.054349,114.380722,5.826831,0.543492,-37.141594,0.055355,0.000000
39.070004,26.057877,-37.097115,0.004932,0.002154,0.054722,115.911224,5.904799,0.547220,-37.097115,0.055702,0.000000
39.280003,26.421310,-37.097115,0.004954,0.002170,0.055112,117.527855,5.987154,0.551122,-37.097115,0.056057,0.000000
39.490002,26.627235,-37.052631,0.004941,0.002183,0.055450,118.443855,6.033818,0.554502,-37.052631,0.056404,0.000000
39.700001,26.634308,-37.097115,0.004967,0.002193,0.055702,118.475319,6.035420,0.557019,-37.097115,0.056751,0.000000
39.910004,27.268463,-37.186073,0.004984,0.002210,0.056136,121.296181,6.179122,0.561357,-37.186073,0.057107,0.000000
40.120003,27.914902,-37.141594,0.004984,0.002229,0.056613,124.171684,6.325607,0.566126,-37.141594,0.057454,0.000000
40.330002,27.822174,-37.141594,0.005014,0.002237,0.056821,123.759209,6.304595,0.568207,-37.141594,0.057801,0.000000
40.540001,27.881760,-37.141594,0.005019,0.002250,0.057141,124.024261,6.318097,0.571413,-37.141594,0.058156,0.000000
40.750004,28.238487,-37.186073,0.005027,0.002264,0.057497,125.611061,6.398933,0.574971,-37.186073,0.058503,0.000000
40.960003,28.462662,-37.230556,0.005036,0.002276,0.057801,126.608246,6.449731,0.578006,-37.230556,0.058850,0.000000
41.170002,29.093460,-37.097115,0.005040,0.002292,0.058217,129.414169,6.592672,0.582170,-37.097115,0.059206,0.000000
41.380001,29.303848,-37.186073,0.005062,0.002304,0.058521,130.350021,6.640347,0.585205,-37.186073,0.059552,0.000000
41.590000,29.518707,-37.141594,0.005066,0.002318,0.058876,131.305771,6.689035,0.588759,-37.141594,0.059908,0.000000
41.800003,29.942841,-37.230556,0.005088,0.002332,0.059231,133.192413,6.785145,0.592313,-37.230556,0.060255,0.000000
42.010002,30.422081,-37.275036,0.005088,0.002348,0.059639,135.324173,6.893742,0.596390,-37.275036,0.060602,0.000000
42.220001,31.129593,-37.186073,0.005109,0.002364,0.060055,138.471344,7.054067,0.600553,-37.186073,0.060957,0.000000
42.430000,31.335510,-37.186073,0.005122,0.002377,0.060385,139.387314,7.100728,0.603850,-37.186073,0.061304,0.000000
42.640003,31.334396,-37.275036,0.005122,0.002391,0.060723,139.382355,7.100476,0.607230,-37.275036,0.061651,0.000000
42.850002,32.043388,-37.186073,0.005152,0.002407,0.061131,142.536118,7.261136,0.611306,-37.186073,0.062007,0.000000
43.060001,32.256386,-37.230556,0.005152,0.002418,0.061408,143.483566,7.309402,0.614084,-37.230556,0.062353,0.000000
43.270000,32.521149,-37.186073,0.005174,0.002430,0.061720,144.661301,7.369398,0.617203,-37.186073,0.062701,0.000000
43.480003,32.467148,-37.230556,0.005174,0.002439,0.061963,144.421082,7.357161,0.619633,-37.230556,0.063056,0.000000
43.690002,33.405159,-37.186073,0.005174,0.002459,0.062449,148.593567,7.569717,0.624489,-37.186073,0.063403,0.000000
43.900002,34.056808,-37.275036,0.005204,0.002477,0.062917,151.492249,7.717383,0.629171,-37.275036,0.063750,0.000000
44.110001,34.573662,-37.275036,0.005221,0.002490,0.063255,153.791336,7.834504,0.632554,-37.275036,0.064105,0.000000
44.320004,34.431786,-37.230556,0.005226,0.002501,0.063515,153.160233,7.802354,0.635155,-37.230556,0.064452,0.000000
44.530003,35.057373,-37.275036,0.005234,0.002518,0.063958,155.942978,7.944114,0.639579,-37.275036,0.064808,0.000000
44.740002,35.387299,-37.230556,0.005247,0.002529,0.064244,157.410568,8.018877,0.642440,-37.230556,0.065155,0.000000
44.950001,35.936172,-37.275036,0.005269,0.002544,0.064608,159.852081,8.143253,0.646082,-37.275036,0.065501,0.000000
45.160004,35.910477,-37.275036,0.005273,0.002552,0.064816,159.737778,8.137430,0.648163,-37.275036,0.065857,0.000000
45.370003,36.206886,-37.230556,0.005282,0.002564,0.065137,161.056274,8.204597,0.651373,-37.230556,0.066204,0.000000
45.580002,36.874176,-37.319519,0.005290,0.002581,0.065545,164.024521,8.355807,0.655449,-37.319519,0.066551,0.000000
45.790001,37.751488,-37.275036,0.005299,0.002600,0.066039,167.927002,8.554609,0.660392,-37.275036,0.066906,0.000000
46.000004,38.336487,-37.319519,0.005312,0.002614,0.066395,170.529205,8.687172,0.663946,-37.319519,0.067253,0.000000
46.210003,38.307816,-37.275036,0.005325,0.002621,0.066577,170.401672,8.680676,0.665771,-37.275036,0.067600,0.000000
46.420002,38.816475,-37.275036,0.005338,0.002637,0.066967,172.664307,8.795938,0.669673,-37.275036,0.067956,0.000000
46.630001,39.154587,-37.363998,0.005346,0.002649,0.067297,174.168304,8.872556,0.672966,-37.363998,0.068303,0.000000
46.840004,39.977531,-37.230556,0.005355,0.002666,0.067713,177.828934,9.059038,0.677129,-37.230556,0.068658,0.000000
47.050003,40.293678,-37.319519,0.005359,0.002680,0.068060,179.235229,9.130678,0.680600,-37.319519,0.069005,0.000000
47.260002,40.592690,-37.363998,0.005376,0.002689,0.068294,180.565308,9.198435,0.682939,-37.363998,0.069352,0.000000
47.470001,40.947563,-37.319519,0.005394,0.002702,0.068624,182.143860,9.278851,0.686236,-37.319519,0.069708,0.000000
47.680004,42.283638,-37.319519,0.005389,0.002726,0.069239,188.087021,9.581609,0.692394,-37.319519,0.070055,0.000000
47.890003,42.835861,-37.275036,0.005411,0.002739,0.069560,190.543427,9.706745,0.695603,-37.275036,0.070401,0.000000
48.100002,43.023537,-37.319519,0.005424,0.002751,0.069872,191.378250,9.749272,0.698722,-37.319519,0.070757,0.000000
48.310001,43.359421,-37.408482,0.005424,0.002762,0.070159,192.872330,9.825385,0.701587,-37.408482,0.071104,0.000000
48.520000,43.773499,-37.319519,0.005433,0.002776,0.070505,194.714249,9.919217,0.705054,-37.319519,0.071451,0.000000
48.730003,44.105278,-37.408482,0.005441,0.002788,0.070818,196.190079,9.994399,0.708177,-37.408482,0.071806,0.000000
48.940002,44.955780,-37.452961,0.005458,0.002804,0.071234,199.973297,10.187125,0.712340,-37.452961,0.072153,0.000000
49.150002,45.139359,-37.408482,0.005471,0.002815,0.071494,200.789902,10.228724,0.714940,-37.408482,0.072509,0.000000
49.360001,45.518806,-37.363998,0.005471,0.002826,0.071789,202.477768,10.314709,0.717889,-37.363998,0.072855,0.000000
49.570004,46.907753,-37.408482,0.005484,0.002847,0.072309,208.656113,10.629449,0.723093,-37.408482,0.073203,0.000000
49.780003,47.690483,-37.408482,0.005497,0.002864,0.072743,212.137863,10.806818,0.727430,-37.408482,0.073558,0.000000
49.990002,48.104187,-37.363998,0.005506,0.002875,0.073020,213.978104,10.900564,0.730205,-37.363998,0.073905,0.000000
50.200001,48.569283,-37.363998,0.005514,0.002888,0.073350,216.046951,11.005957,0.733498,-37.363998,0.074252,0.000000
50.410004,48.942024,-37.408482,0.005510,0.002901,0.073697,217.705002,11.090421,0.736968,-37.408482,0.074607,0.000000
50.620003,49.850243,-37.408482,0.005527,0.002918,0.074113,221.744949,11.296226,0.741132,-37.408482,0.074954,0.000000
50.830002,50.380875,-37.408482,0.005536,0.002930,0.074425,224.105316,11.416470,0.744254,-37.408482,0.075301,0.000000
51.040001,50.732018,-37.363998,0.005549,0.002942,0.074738,225.667282,11.496039,0.747377,-37.363998,0.075657,0.000000
51.250004,51.061943,-37.408482,0.005562,0.002951,0.074954,227.134872,11.570802,0.749542,-37.408482,0.076004,0.000000
51.460003,52.335083,-37.452961,0.005570,0.002971,0.075475,232.798080,11.859299,0.754746,-37.452961,0.076359,0.000000
51.670002,53.279045,-37.408482,0.005583,0.002989,0.075908,236.997025,12.073204,0.759083,-37.408482,0.076706,0.000000
51.880001,53.712486,-37.452961,0.005601,0.003000,0.076212,238.925064,12.171423,0.762119,-37.452961,0.077053,0.000000
52.090004,54.110931,-37.452961,0.005601,0.003013,0.076532,240.697449,12.261712,0.765325,-37.452961,0.077409,0.000000
52.300003,54.490379,-37.452961,0.005618,0.003022,0.076758,242.385315,12.347697,0.767581,-37.452961,0.077755,0.000000
52.510002,55.047821,-37.497440,0.005609,0.003036,0.077114,244.864944,12.474014,0.771138,-37.497440,0.078102,0.000000
52.720001,56.459480,-37.452961,0.005622,0.003056,0.077634,251.144318,12.793900,0.776339,-37.452961,0.078458,0.000000
52.930004,56.739510,-37.452961,0.005627,0.003066,0.077877,252.389938,12.857357,0.778769,-37.452961,0.078805,0.000000
53.140003,56.992722,-37.408482,0.005635,0.003074,0.078076,253.516281,12.914736,0.780763,-37.408482,0.079152,0.000000
53.350002,57.220985,-37.452961,0.005648,0.003083,0.078319,254.531662,12.966460,0.783193,-37.452961,0.079507,0.000000
53.560001,59.041512,-37.497440,0.005652,0.003109,0.078961,262.629761,13.378998,0.789609,-37.497440,0.079854,0.000000
53.770004,59.902435,-37.452961,0.005665,0.003123,0.079325,266.459351,13.574086,0.793250,-37.452961,0.080201,0.000000
53.980003,60.278160,-37.541924,0.005683,0.003134,0.079603,268.130646,13.659226,0.796028,-37.541924,0.080557,0.000000
54.190002,60.993118,-37.497440,0.005678,0.003149,0.079976,271.310944,13.821239,0.799756,-37.497440,0.080904,0.000000
54.400002,61.390068,-37.586403,0.005696,0.003158,0.080210,273.076660,13.911188,0.802099,-37.586403,0.081259,0.000000
54.610004,62.497871,-37.497440,0.005691,0.003178,0.080730,278.004425,14.162220,0.807299,-37.497440,0.081606,0.000000
54.820004,63.597862,-37.452961,0.005691,0.003192,0.081068,282.897430,14.411482,0.810683,-37.452961,0.081953,0.000000
55.030003,64.032417,-37.541924,0.005713,0.003202,0.081320,284.830414,14.509953,0.813196,-37.541924,0.082308,0.000000
55.240002,64.389900,-37.541924,0.005717,0.003211,0.081571,286.420593,14.590960,0.815713,-37.541924,0.082655,0.000000
55.450001,65.409828,-37.541924,0.005726,0.003228,0.081996,290.957458,14.822079,0.819963,-37.541924,0.083002,0.000000
55.660004,66.528435,-37.541924,0.005739,0.003246,0.082447,295.933258,15.075560,0.824471,-37.541924,0.083358,0.000000
55.870003,67.117149,-37.541924,0.005743,0.003256,0.082707,298.552002,15.208963,0.827071,-37.541924,0.083704,0.000000
56.080002,67.173378,-37.541924,0.005760,0.003256,0.082699,298.802094,15.221705,0.826988,-37.541924,0.082941,0.000000
56.290001,66.532906,-37.497440,0.005760,0.003256,0.082699,295.953156,15.076572,0.826988,-37.497440,0.082941,0.000000
56.500004,66.020149,-37.541924,0.005764,0.003255,0.082673,293.672302,14.960380,0.826727,-37.541924,0.082699,0.000000
56.710003,65.521172,-37.586403,0.005756,0.003254,0.082664,291.452728,14.847310,0.826640,-37.586403,0.082699,0.000000
56.920002,65.071342,-37.497440,0.005773,0.003254,0.082655,289.451782,14.745378,0.826553,-37.497440,0.082699,0.000000
57.130001,64.682579,-37.586403,0.005769,0.003254,0.082647,287.722473,14.657282,0.826466,-37.586403,0.082699,0.000000
57.340004,64.318398,-37.541924,0.005773,0.003254,0.082647,286.102509,14.574757,0.826466,-37.541924,0.082699,0.000000
57.550003,63.997795,-37.541924,0.005773,0.003253,0.082638,284.676422,14.502108,0.826379,-37.541924,0.082699,0.000000
57.760002,63.695427,-37.630886,0.005769,0.003253,0.082638,283.331421,14.433590,0.826379,-37.630886,0.082699,0.000000
57.970001,63.444069,-37.586403,0.005786,0.003253,0.082638,282.213318,14.376632,0.826379,-37.586403,0.082699,0.000000
58.180004,63.200920,-37.630886,0.005790,0.003253,0.082638,281.131744,14.321533,0.826379,-37.630886,0.082699,0.000000
58.390003,62.959984,-37.630886,0.005782,0.003253,0.082629,280.059998,14.266936,0.826292,-37.630886,0.082699,0.000000
58.600002,62.742523,-37.630886,0.005790,0.003253,0.082629,279.092682,14.217659,0.826292,-37.630886,0.082699,0.000000
58.810001,62.548515,-37.630886,0.005786,0.003253,0.082629,278.229706,14.173697,0.826292,-37.630886,0.082699,0.000000
59.020004,62.367172,-37.586403,0.005795,0.003253,0.082629,277.423035,14.132604,0.826292,-37.586403,0.082699,0.000000
59.230003,62.193642,-37.675365,0.005795,0.003253,0.082629,276.651123,14.093281,0.826292,-37.675365,0.082699,0.000000
59.440002,62.037621,-37.630886,0.005795,0.003253,0.082629,275.957123,14.057925,0.826292,-37.630886,0.082699,0.000000
59.650002,61.877129,-37.630886,0.005803,0.003253,0.082629,275.243225,14.021558,0.826292,-37.630886,0.082699,0.000000
59.860004,61.746429,-37.675365,0.005786,0.003253,0.082629,274.661835,13.991940,0.826292,-37.675365,0.082699,0.000000
60.070004,61.597847,-37.630886,0.005799,0.003253,0.082629,274.000916,13.958272,0.826292,-37.630886,0.082699,0.000000
60.280003,61.484650,-37.764328,0.005799,0.003253,0.082629,273.497375,13.932621,0.826292,-37.764328,0.082699,0.000000
60.490002,61.347244,-37.630886,0.005795,0.003253,0.082629,272.886169,13.901484,0.826292,-37.630886,0.082699,0.000000
60.700005,61.230316,-37.630886,0.005799,0.003253,0.082629,272.366058,13.874989,0.826292,-37.630886,0.082699,0.000000
60.910004,61.104828,-37.719845,0.005795,0.003253,0.082629,271.807861,13.846552,0.826292,-37.719845,0.082699,0.000000
61.120003,61.008385,-37.675365,0.005799,0.003253,0.082629,271.378845,13.824697,0.826292,-37.675365,0.082699,0.000000
61.330002,60.899277,-37.630886,0.005803,0.003253,0.082629,270.893524,13.799973,0.826292,-37.630886,0.082699,0.000000
61.540005,60.797997,-37.675365,0.005803,0.003253,0.082629,270.442993,13.777023,0.826292,-37.675365,0.082699,0.000000
61.750004,60.716446,-37.675365,0.005803,0.003253,0.082629,270.080231,13.758543,0.826292,-37.675365,0.082699,0.000000
61.960003,60.617767,-37.719845,0.005790,0.003253,0.082629,269.641296,13.736183,0.826292,-37.719845,0.082699,0.000000
62.170002,60.536591,-37.675365,0.005803,0.003253,0.082620,269.280212,13.717787,0.826205,-37.675365,0.082699,0.000000
62.380001,60.446472,-37.719845,0.005808,0.003253,0.082620,268.879333,13.697367,0.826205,-37.719845,0.082699,0.000000
62.590004,60.360085,-37.719845,0.005808,0.003253,0.082620,268.495056,13.677791,0.826205,-37.719845,0.082699,0.000000
62.800003,60.283005,-37.719845,0.005799,0.003253,0.082620,268.152191,13.660324,0.826205,-37.719845,0.082699,0.000000
63.010002,60.211136,-37.764328,0.005795,0.003253,0.082620,267.832520,13.644039,0.826205,-37.764328,0.082699,0.000000
63.220001,60.133682,-37.719845,0.005816,0.003253,0.082620,267.487976,13.626488,0.826205,-37.719845,0.082699,0.000000
63.430004,60.067772,-37.764328,0.005803,0.003253,0.082620,267.194794,13.611551,0.826205,-37.764328,0.082699,0.000000
63.640003,60.003349,-37.719845,0.005808,0.003253,0.082620,266.908234,13.596953,0.826205,-37.719845,0.082699,0.000000
63.850002,59.931107,-37.764328,0.005812,0.003253,0.082620,266.586884,13.580583,0.826205,-37.764328,0.082699,0.000000
64.060005,59.866692,-37.808807,0.005808,0.003253,0.082620,266.300354,13.565987,0.826205,-37.808807,0.082699,0.000000
64.270004,59.810837,-37.630886,0.005812,0.003253,0.082620,266.051880,13.553329,0.826205,-37.630886,0.082699,0.000000
64.480003,59.748276,-37.764328,0.005812,0.003253,0.082620,265.773590,13.539153,0.826205,-37.764328,0.082699,0.000000
64.690002,59.678268,-37.764328,0.005803,0.003253,0.082620,265.462189,13.523289,0.826205,-37.764328,0.082699,0.000000
64.900002,59.625023,-37.764328,0.005803,0.003253,0.082620,265.225342,13.511224,0.826205,-37.764328,0.082699,0.000000
65.110001,59.571770,-37.808807,0.005812,0.003253,0.082620,264.988464,13.499156,0.826205,-37.808807,0.082699,0.000000
65.320000,59.503998,-37.808807,0.005816,0.003253,0.082620,264.687012,13.483798,0.826205,-37.808807,0.082699,0.000000
65.530006,59.461922,-37.808807,0.005812,0.003253,0.082620,264.499847,13.474264,0.826205,-37.808807,0.082699,0.000000
65.740005,59.412392,-37.808807,0.005808,0.003253,0.082620,264.279510,13.463040,0.826205,-37.808807,0.082699,0.000000
65.950005,59.363983,-37.764328,0.005812,0.003253,0.082620,264.064178,13.452071,0.826205,-37.764328,0.082699,0.000000
66.160004,59.306267,-37.764328,0.005808,0.003253,0.082620,263.807465,13.438992,0.826205,-37.764328,0.082699,0.000000
66.370003,59.249672,-37.764328,0.005803,0.003253,0.082620,263.555695,13.426167,0.826205,-37.764328,0.082699,0.000000
66.580002,59.208710,-37.808807,0.005816,0.003253,0.082620,263.373505,13.416885,0.826205,-37.808807,0.082699,0.000000
66.790001,59.159554,-37.808807,0.005808,0.003253,0.082620,263.154846,13.405746,0.826205,-37.808807,0.082699,0.000000
67.000000,59.115242,-37.764328,0.005812,0.003253,0.082620,262.957733,13.395705,0.826205,-37.764328,0.082699,0.000000
67.210007,59.063110,-37.808807,0.005803,0.003253,0.082620,262.725830,13.383892,0.826205,-37.808807,0.082699,0.000000
67.420006,59.025131,-37.808807,0.005821,0.003253,0.082620,262.556885,13.375286,0.826205,-37.808807,0.082699,0.000000
67.630005,58.973366,-37.897770,0.005821,0.003253,0.082620,262.326630,13.363556,0.826205,-37.897770,0.082699,0.000000
67.840004,58.927940,-37.853291,0.005803,0.003253,0.082620,262.124573,13.353262,0.826205,-37.853291,0.082699,0.000000
68.050003,58.900009,-37.853291,0.005816,0.003253,0.082620,262.000336,13.346933,0.826205,-37.853291,0.082699,0.000000
68.260002,58.865005,-37.897770,0.005808,0.003253,0.082620,261.844635,13.339001,0.826205,-37.897770,0.082699,0.000000
68.470001,58.815857,-37.853291,0.005812,0.003253,0.082620,261.626007,13.327864,0.826205,-37.853291,0.082699,0.000000
68.680000,58.796120,-37.853291,0.005812,0.003253,0.082620,261.538208,13.323391,0.826205,-37.853291,0.082699,0.000000
68.890007,58.748825,-37.853291,0.005816,0.003253,0.082620,261.327820,13.312674,0.826205,-37.853291,0.082699,0.000000
69.100006,58.708984,-37.853291,0.005812,0.003253,0.082620,261.150604,13.303646,0.826205,-37.853291,0.082699,0.000000
69.310005,58.668022,-37.897770,0.005816,0.003253,0.082620,260.968384,13.294364,0.826205,-37.897770,0.082699,0.000000
69.520004,58.641960,-37.808807,0.005808,0.003253,0.082620,260.852478,13.288458,0.826205,-37.808807,0.082699,0.000000
69.730003,58.605095,-37.942253,0.005808,0.003253,0.082620,260.688477,13.280105,0.826205,-37.942253,0.082699,0.000000
69.940002,58.568596,-37.897770,0.005808,0.003253,0.082620,260.526123,13.271834,0.826205,-37.897770,0.082699,0.000000
70.150002,58.539925,-37.942253,0.005825,0.003253,0.082620,260.398590,13.265336,0.826205,-37.942253,0.082699,0.000000
70.360001,58.508278,-37.897770,0.005825,0.003253,0.082620,260.257812,13.258165,0.826205,-37.897770,0.082699,0.000000
70.570000,58.479599,-37.897770,0.005825,0.003253,0.082620,260.130249,13.251666,0.826205,-37.897770,0.082699,0.000000
70.780006,58.444603,-37.897770,0.005816,0.003253,0.082620,259.974579,13.243736,0.826205,-37.897770,0.082699,0.000000
70.990005,58.402519,-37.942253,0.005816,0.003253,0.082620,259.787384,13.234200,0.826205,-37.942253,0.082699,0.000000
71.200005,58.377945,-37.897770,0.005833,0.003253,0.082620,259.678070,13.228631,0.826205,-37.897770,0.082699,0.000000
71.410004,58.351509,-37.897770,0.005816,0.003253,0.082620,259.560486,13.222641,0.826205,-37.897770,0.082699,0.000000
71.620003,58.318741,-37.897770,0.005821,0.003253,0.082620,259.414703,13.215216,0.826205,-37.897770,0.082699,0.000000
71.830002,58.283363,-37.986732,0.005833,0.003253,0.082620,259.257355,13.207199,0.826205,-37.986732,0.082699,0.000000
72.040001,58.254318,-37.897770,0.005821,0.003253,0.082620,259.128143,13.200617,0.826205,-37.897770,0.082699,0.000000
72.250000,58.218193,-37.942253,0.005833,0.003253,0.082620,258.967468,13.192431,0.826205,-37.942253,0.082699,0.000000
72.460007,58.200699,-37.986732,0.005821,0.003253,0.082620,258.889648,13.188467,0.826205,-37.986732,0.082699,0.000000
72.670006,58.159737,-37.986732,0.005825,0.003253,0.082620,258.707428,13.179185,0.826205,-37.986732,0.082699,0.000000
72.880005,58.137390,-37.986732,0.005821,0.003253,0.082620,258.608032,13.174121,0.826205,-37.986732,0.082699,0.000000
73.090004,58.109093,-37.986732,0.005825,0.003253,0.082620,258.482147,13.167709,0.826205,-37.986732,0.082699,0.000000
73.300003,58.076698,-37.986732,0.005838,0.003253,0.082620,258.338043,13.160368,0.826205,-37.986732,0.082699,0.000000
73.510002,58.054352,-38.031212,0.005821,0.003253,0.082620,258.238647,13.155304,0.826205,-38.031212,0.082699,0.000000
73.720001,58.029778,-37.986732,0.005821,0.003253,0.082620,258.129333,13.149735,0.826205,-37.986732,0.082699,0.000000
73.930000,58.003342,-37.942253,0.005829,0.003253,0.082620,258.011749,13.143744,0.826205,-37.942253,0.082699,0.000000
74.140007,57.971313,-37.986732,0.005833,0.003253,0.082620,257.869293,13.136487,0.826205,-37.986732,0.082699,0.000000
74.350006,57.944130,-37.986732,0.005821,0.003253,0.082620,257.748352,13.130328,0.826205,-37.986732,0.082699,0.000000
74.560005,57.931839,-37.986732,0.005829,0.003253,0.082620,257.693695,13.127542,0.826205,-37.986732,0.082699,0.000000
74.770004,57.893486,-37.986732,0.005825,0.003253,0.082620,257.523102,13.118852,0.826205,-37.986732,0.082699,0.000000
74.980003,57.862206,-38.031212,0.005829,0.003253,0.082620,257.383942,13.111763,0.826205,-38.031212,0.082699,0.000000
75.190002,57.840614,-37.986732,0.005825,0.003253,0.082620,257.287903,13.106871,0.826205,-37.986732,0.082699,0.000000
75.400002,57.818642,-38.075695,0.005833,0.003253,0.082620,257.190155,13.101892,0.826205,-38.075695,0.082699,0.000000
75.610001,57.784752,-38.031212,0.005829,0.003253,0.082620,257.039429,13.094212,0.826205,-38.031212,0.082699,0.000000
75.820007,57.769485,-38.075695,0.005833,0.003253,0.082620,256.971497,13.090753,0.826205,-38.075695,0.082699,0.000000
76.030006,57.734116,-38.120174,0.005833,0.003253,0.082620,256.814178,13.082738,0.826205,-38.120174,0.082699,0.000000
76.240005,57.713257,-38.031212,0.005825,0.003253,0.082620,256.721375,13.078011,0.826205,-38.031212,0.082699,0.000000
76.450005,57.708794,-38.031212,0.005833,0.003253,0.082620,256.701538,13.077000,0.826205,-38.031212,0.082699,0.000000
76.660004,57.669319,-38.120174,0.005829,0.003253,0.082620,256.525940,13.068054,0.826205,-38.120174,0.082699,0.000000
76.870003,57.662247,-38.075695,0.005825,0.003253,0.082620,256.494476,13.066452,0.826205,-38.075695,0.082699,0.000000
77.080002,57.622398,-38.031212,0.005829,0.003253,0.082620,256.317230,13.057422,0.826205,-38.031212,0.082699,0.000000
77.290001,57.616440,-38.120174,0.005825,0.003253,0.082620,256.290710,13.056072,0.826205,-38.120174,0.082699,0.000000
77.500000,57.587029,-38.075695,0.005842,0.003253,0.082620,256.159882,13.049407,0.826205,-38.075695,0.082699,0.000000
77.710007,57.572128,-38.120174,0.005829,0.003253,0.082620,256.093628,13.046031,0.826205,-38.120174,0.082699,0.000000
77.920006,57.543831,-38.075695,0.005825,0.003253,0.082620,255.967743,13.039618,0.826205,-38.075695,0.082699,0.000000
78.130005,57.521118,-38.075695,0.005833,0.003253,0.082620,255.866714,13.034472,0.826205,-38.075695,0.082699,0.000000
78.340004,57.494308,-38.120174,0.005816,0.003253,0.082620,255.747452,13.028397,0.826205,-38.120174,0.082699,0.000000
78.550003,57.470848,-38.120174,0.005833,0.003253,0.082620,255.643097,13.023081,0.826205,-38.120174,0.082699,0.000000
78.760002,57.461906,-38.075695,0.005829,0.003253,0.082620,255.603333,13.021054,0.826205,-38.075695,0.082699,0.000000
78.970001,57.446640,-38.031212,0.005833,0.003253,0.082620,255.535416,13.017594,0.826205,-38.031212,0.082699,0.000000
79.180000,57.419830,-38.120174,0.005821,0.003253,0.082620,255.416168,13.011519,0.826205,-38.120174,0.082699,0.000000
79.390007,57.403442,-38.075695,0.005829,0.003253,0.082620,255.343262,13.007807,0.826205,-38.075695,0.082699,0.000000
79.600006,57.380356,-38.120174,0.005829,0.003253,0.082620,255.240570,13.002575,0.826205,-38.120174,0.082699,0.000000
79.810005,57.362488,-38.120174,0.005825,0.003253,0.082620,255.161087,12.998526,0.826205,-38.120174,0.082699,0.000000
80.020004,57.352432,-38.120174,0.005833,0.003253,0.082620,255.116364,12.996246,0.826205,-38.120174,0.082699,0.000000
80.230003,57.327484,-38.164658,0.005833,0.003253,0.082620,255.005386,12.990594,0.826205,-38.164658,0.082699,0.000000
80.440002,57.301414,-38.120174,0.005829,0.003253,0.082620,254.889420,12.984687,0.826205,-38.120174,0.082699,0.000000
80.650002,57.284660,-38.164658,0.005829,0.003253,0.082620,254.814896,12.980889,0.826205,-38.164658,0.082699,0.000000
80.860001,57.269020,-38.164658,0.005833,0.003253,0.082620,254.745331,12.977345,0.826205,-38.164658,0.082699,0.000000
81.070007,57.255989,-38.164658,0.005829,0.003253,0.082620,254.687363,12.974392,0.826205,-38.164658,0.082699,0.000000
81.280006,57.225082,-38.209137,0.005833,0.003253,0.082620,254.549881,12.967389,0.826205,-38.209137,0.082699,0.000000
81.490005,57.197525,-38.209137,0.005825,0.003253,0.082620,254.427292,12.961144,0.826205,-38.209137,0.082699,0.000000
81.700005,57.193802,-38.209137,0.005833,0.003253,0.082620,254.410736,12.960300,0.826205,-38.209137,0.082699,0.000000
81.910004,57.167358,-38.209137,0.005825,0.003253,0.082620,254.293106,12.954309,0.826205,-38.209137,0.082699,0.000000
82.120003,57.153214,-38.164658,0.005829,0.003253,0.082620,254.230194,12.951103,0.826205,-38.164658,0.082699,0.000000
82.330002,57.137573,-38.164658,0.005821,0.003253,0.082620,254.160614,12.947559,0.826205,-38.164658,0.082699,0.000000
82.540001,57.117462,-38.164658,0.005825,0.003253,0.082620,254.071167,12.943002,0.826205,-38.164658,0.082699,0.000000
82.750008,57.090652,-38.209137,0.005829,0.003253,0.082620,253.951904,12.936927,0.826205,-38.209137,0.082699,0.000000
82.960007,57.080223,-38.253616,0.005825,0.003253,0.082620,253.905518,12.934564,0.826205,-38.253616,0.082699,0.000000
83.170006,57.062355,-38.253616,0.005825,0.003253,0.082620,253.826035,12.930514,0.826205,-38.253616,0.082699,0.000000
83.380005,57.034050,-38.209137,0.005838,0.003253,0.082620,253.700119,12.924101,0.826205,-38.209137,0.082699,0.000000
83.590004,57.032188,-38.209137,0.005833,0.003253,0.082620,253.691849,12.923678,0.826205,-38.209137,0.082699,0.000000
83.800003,57.012825,-38.209137,0.005838,0.003253,0.082620,253.605713,12.919291,0.826205,-38.209137,0.082699,0.000000
84.010002,57.000542,-38.298100,0.005825,0.003253,0.082620,253.551071,12.916508,0.826205,-38.298100,0.082699,0.000000
84.220001,56.986015,-38.209137,0.005838,0.003253,0.082620,253.486450,12.913216,0.826205,-38.209137,0.082699,0.000000
84.430000,56.958458,-38.253616,0.005833,0.003253,0.082620,253.363876,12.906971,0.826205,-38.253616,0.082699,0.000000
84.640007,56.956230,-38.253616,0.005838,0.003253,0.082620,253.353958,12.906466,0.826205,-38.253616,0.082699,0.000000
84.850006,56.936119,-38.253616,0.005833,0.003253,0.082620,253.264511,12.901910,0.826205,-38.253616,0.082699,0.000000
85.060005,56.921593,-38.253616,0.005829,0.003253,0.082620,253.199890,12.898618,0.826205,-38.253616,0.082699,0.000000
85.270004,56.907822,-38.253616,0.005833,0.003253,0.082620,253.138626,12.895496,0.826205,-38.253616,0.082699,0.000000
85.480003,56.888084,-38.342579,0.005833,0.003253,0.082620,253.050842,12.891025,0.826205,-38.342579,0.082699,0.000000
85.690002,56.881752,-38.298100,0.005825,0.003253,0.082620,253.022675,12.889589,0.826205,-38.298100,0.082699,0.000000
85.900002,56.864250,-38.298100,0.005842,0.003253,0.082620,252.944824,12.885624,0.826205,-38.298100,0.082699,0.000000
86.110001,56.847496,-38.298100,0.005825,0.003253,0.082620,252.870285,12.881827,0.826205,-38.298100,0.082699,0.000000
86.320007,56.834091,-38.298100,0.005825,0.003253,0.082620,252.810669,12.878789,0.826205,-38.298100,0.082699,0.000000
86.400002,56.827759,-38.342579,0.005838,0.003253,0.082620,252.782501,12.877354,0.826205,-38.342579,0.082699,0.000000