File: Data/Compression Sample NH 10, 12, 15, 17 batch 3/AutoNoheating-17-3-2-240212_02122024_181028.csv
Time (sec),S:Load (lbs),S:HL1 (DIM),S:LVDT (in),S:Position (in),Ch:Position (mm),Ch:Load (N),Ch:Stress (MPa),Ch:Strain (mm/mm),Ch:HL1 (DIM),Set Point (),Cycles ()
0.110000,-0.009682,-310.432556,-0.000017,-0.000000,-0.000000,-0.043066,-0.002194,-0.000000,-310.432556,0.000147,0.000000
0.330000,-0.005959,-310.477051,0.000017,0.000000,0.000009,-0.026505,-0.001350,0.000087,-310.477051,0.000286,0.000000
0.550000,-0.037987,-310.477051,0.000004,0.000124,0.003157,-0.168974,-0.008608,0.031566,-310.477051,0.003946,0.000000
0.770000,-0.002609,-310.432556,0.000099,0.000262,0.006652,-0.011607,-0.000591,0.066516,-310.432556,0.007623,0.000000
0.990000,-0.022346,-310.343597,0.000229,0.000400,0.010164,-0.099402,-0.005064,0.101636,-310.343597,0.011282,0.000000
1.210000,-0.031654,-310.432556,0.000401,0.000546,0.013875,-0.140806,-0.007173,0.138754,-310.432556,0.014942,0.000000
1.430000,-0.012291,-310.521515,0.000560,0.000691,0.017552,-0.054673,-0.002785,0.175525,-310.521515,0.018619,0.000000
1.650000,-0.001488,-310.432556,0.000720,0.000834,0.021195,-0.006618,-0.000337,0.211950,-310.432556,0.022279,0.000000
1.870000,0.004471,-310.477051,0.000875,0.000973,0.024716,0.019887,0.001013,0.247157,-310.477051,0.025939,0.000000
2.090000,-0.017502,-310.477051,0.001009,0.001119,0.028419,-0.077852,-0.003966,0.284189,-310.477051,0.029616,0.000000
2.310000,-0.025322,-310.432556,0.001194,0.001271,0.032278,-0.112638,-0.005738,0.322780,-310.432556,0.033275,0.000000
2.530000,-0.043198,-310.521515,0.001306,0.001416,0.035955,-0.192153,-0.009789,0.359550,-310.521515,0.036935,0.000000
2.750000,-0.070007,-310.432556,0.001414,0.001558,0.039563,-0.311408,-0.015864,0.395627,-310.432556,0.040595,0.000000
2.970000,-0.016014,-310.521515,0.001625,0.001701,0.043196,-0.071234,-0.003629,0.431962,-310.521515,0.044272,0.000000
3.190000,0.001488,-310.477051,0.001750,0.001844,0.046839,0.006618,0.000337,0.468388,-310.477051,0.047932,0.000000
3.410000,0.014519,-310.477051,0.001884,0.001985,0.050420,0.064583,0.003290,0.504205,-310.477051,0.051591,0.000000
3.630000,0.008934,-310.477051,0.001992,0.002127,0.054028,0.039741,0.002024,0.540279,-310.477051,0.055268,0.000000
3.850000,-0.002235,-310.477051,0.002238,0.002278,0.057861,-0.009944,-0.000507,0.578612,-310.477051,0.058928,0.000000
4.070000,-0.005585,-310.521515,0.002406,0.002425,0.061590,-0.024842,-0.001266,0.615901,-310.521515,0.062587,0.000000
4.290000,-0.050270,-310.477051,0.002475,0.002566,0.065180,-0.223612,-0.011391,0.651804,-310.477051,0.066264,0.000000
4.510000,-0.043938,-310.521515,0.002639,0.002710,0.068832,-0.195445,-0.009956,0.688317,-310.521515,0.069924,0.000000
4.730000,-0.019737,-310.521515,0.002807,0.002858,0.072587,-0.087796,-0.004473,0.725867,-310.521515,0.073584,0.000000
4.950000,0.010796,-310.566010,0.002958,0.002999,0.076177,0.048021,0.002446,0.761771,-310.566010,0.077261,0.000000
5.170000,0.022339,-310.521515,0.003100,0.003141,0.079793,0.099368,0.005062,0.797932,-310.521515,0.080921,0.000000
5.390000,0.021599,-310.477051,0.003238,0.003288,0.083514,0.096076,0.004894,0.835137,-310.477051,0.084580,0.000000
5.610000,0.017876,-310.477051,0.003393,0.003433,0.087199,0.079515,0.004051,0.871994,-310.477051,0.088257,0.000000
5.830000,0.007820,-310.566010,0.003587,0.003575,0.090816,0.034786,0.001772,0.908159,-310.566010,0.091917,0.000000
6.050000,-0.018623,-310.610474,0.003669,0.003718,0.094432,-0.082841,-0.004220,0.944320,-310.610474,0.095577,0.000000
6.270000,0.013031,-310.566010,0.003885,0.003863,0.098109,0.057965,0.002953,0.981090,-310.566010,0.099254,0.000000
6.490000,-0.005211,-310.521515,0.004010,0.004011,0.101873,-0.023179,-0.001181,1.018727,-310.521515,0.102914,0.000000
6.710001,0.018616,-310.566010,0.004109,0.004151,0.105429,0.082807,0.004218,1.054286,-310.566010,0.106573,0.000000
6.930000,-0.013031,-310.566010,0.004290,0.004299,0.109184,-0.057965,-0.002953,1.091836,-310.566010,0.110233,0.000000
7.150001,0.002975,-310.521515,0.004475,0.004443,0.112852,0.013236,0.000674,1.128519,-310.521515,0.113910,0.000000
7.370000,0.007820,-310.521515,0.004648,0.004583,0.116416,0.034786,0.001772,1.164162,-310.521515,0.117570,0.000000
7.590000,-0.013405,-310.566010,0.004781,0.004730,0.120154,-0.059628,-0.003038,1.201541,-310.566010,0.121229,0.000000
7.810000,0.014153,-310.566010,0.004894,0.004874,0.123788,0.062954,0.003207,1.237876,-310.566010,0.124906,0.000000
8.030001,0.016380,-310.654968,0.005032,0.005023,0.127577,0.072863,0.003712,1.275775,-310.654968,0.128566,0.000000
8.250000,0.018242,-310.610474,0.005161,0.005159,0.131029,0.081144,0.004134,1.310289,-310.610474,0.132226,0.000000
8.470000,0.026436,-310.610474,0.005376,0.005302,0.134680,0.117593,0.005990,1.346802,-310.610474,0.135903,0.000000
8.690001,0.005959,-310.566010,0.005553,0.005454,0.138522,0.026505,0.001350,1.385219,-310.566010,0.139562,0.000000
8.910001,0.026436,-310.610474,0.005683,0.005603,0.142320,0.117593,0.005990,1.423204,-310.610474,0.143222,0.000000
9.130000,0.064789,-310.610474,0.005777,0.005745,0.145911,0.288195,0.014681,1.459107,-310.610474,0.146899,0.000000
9.350000,0.787941,-310.654968,0.005902,0.005866,0.149007,3.504936,0.178550,1.490068,-310.654968,0.150229,0.000000
9.570001,0.691864,-310.654968,0.005911,-0.000000,-0.000000,3.077565,0.156779,-0.000000,-310.654968,0.000217,0.000000
9.790001,0.687401,-310.521515,0.005937,-0.000000,-0.000000,3.057712,0.155767,-0.000000,-310.521515,0.000217,0.000000
10.010000,0.691124,-310.610474,0.005920,-0.000000,-0.000000,3.074273,0.156611,-0.000000,-310.610474,0.000433,0.000000
10.230000,0.632660,-310.654968,0.005963,-0.000000,-0.000000,2.814212,0.143363,-0.000000,-310.654968,0.000807,0.000000
10.450001,0.631546,-310.654968,0.005933,0.000000,0.000009,2.809257,0.143110,0.000087,-310.654968,0.001171,0.000000
10.670000,0.670639,-310.654968,0.005967,0.000022,0.000546,2.983151,0.151969,0.005462,-310.654968,0.001535,0.000000
10.890000,1.138344,-310.654968,0.005967,0.000044,0.001127,5.063606,0.257952,0.011271,-310.654968,0.001899,0.000000
11.110001,1.241119,-310.654968,0.005997,0.000054,0.001361,5.520775,0.281242,0.013614,-310.654968,0.002272,0.000000
11.330001,1.451134,-310.654968,0.005959,0.000067,0.001709,6.454965,0.328832,0.017085,-310.654968,0.002636,0.000000
11.550000,1.701370,-310.743927,0.006028,0.000086,0.002177,7.568073,0.385536,0.021767,-310.743927,0.003001,0.000000
11.770000,1.894630,-310.699432,0.006010,0.000099,0.002523,8.427737,0.429329,0.025234,-310.699432,0.003373,0.000000
11.990001,2.130714,-310.699432,0.006010,0.000111,0.002810,9.477891,0.482827,0.028095,-310.699432,0.003738,0.000000
12.210001,2.387276,-310.654968,0.006028,0.000127,0.003226,10.619133,0.540964,0.032259,-310.654968,0.004102,0.000000
12.430000,2.623360,-310.654968,0.006084,0.000140,0.003547,11.669287,0.594462,0.035468,-310.654968,0.004466,0.000000
12.650001,2.949188,-310.699432,0.006092,0.000158,0.004006,13.118645,0.668296,0.040063,-310.699432,0.004839,0.000000
12.870001,3.194954,-310.610474,0.006114,0.000170,0.004319,14.211864,0.723987,0.043186,-310.610474,0.005203,0.000000
13.090000,3.488014,-310.699432,0.006122,0.000184,0.004674,15.515462,0.790395,0.046743,-310.699432,0.005568,0.000000
13.310000,3.753883,-310.654968,0.006127,0.000197,0.004995,16.698107,0.850642,0.049953,-310.654968,0.005940,0.000000
13.530001,4.119553,-310.699432,0.006144,0.000215,0.005455,18.324686,0.933504,0.054548,-310.699432,0.006304,0.000000
13.750001,4.473312,-310.788391,0.006127,0.000233,0.005906,19.898287,1.013667,0.059056,-310.788391,0.006669,0.000000
13.970000,4.666199,-310.743927,0.006178,0.000244,0.006200,20.756289,1.057376,0.062004,-310.743927,0.007033,0.000000
14.190001,4.907867,-310.699432,0.006187,0.000257,0.006530,21.831285,1.112139,0.065301,-310.699432,0.007406,0.000000
14.410001,5.200928,-310.699432,0.006196,0.000271,0.006885,23.134882,1.178547,0.068855,-310.699432,0.007770,0.000000
14.630001,5.562126,-310.743927,0.006222,0.000289,0.007328,24.741573,1.260396,0.073279,-310.743927,0.008134,0.000000
14.850000,5.834328,-310.699432,0.006217,0.000302,0.007683,25.952385,1.322078,0.076833,-310.699432,0.008507,0.000000
15.070001,5.969131,-310.699432,0.006243,0.000311,0.007909,26.552023,1.352625,0.079089,-310.699432,0.008872,0.000000
15.290001,6.289742,-310.699432,0.006226,0.000327,0.008299,27.978168,1.425276,0.082991,-310.699432,0.009236,0.000000
15.510001,6.620781,-310.743927,0.006234,0.000341,0.008672,29.450705,1.500290,0.086723,-310.743927,0.009600,0.000000
15.730000,6.933945,-310.788391,0.006243,0.000359,0.009114,30.843727,1.571254,0.091144,-310.788391,0.009973,0.000000
15.950001,7.151039,-310.743927,0.006234,0.000375,0.009513,31.809410,1.620449,0.095133,-310.743927,0.010337,0.000000
16.170000,7.361427,-310.743927,0.006260,0.000389,0.009869,32.745266,1.668123,0.098691,-310.743927,0.010701,0.000000
16.390001,7.563629,-310.788391,0.006316,0.000399,0.010147,33.644703,1.713943,0.101465,-310.788391,0.011074,0.000000
16.610001,7.816093,-310.743927,0.006291,0.000414,0.010519,34.767719,1.771152,0.105194,-310.743927,0.011439,0.000000
16.830000,8.057396,-310.788391,0.006299,0.000428,0.010875,35.841087,1.825832,0.108748,-310.788391,0.011803,0.000000
17.050001,8.233902,-310.832886,0.006308,0.000442,0.011239,36.626225,1.865829,0.112392,-310.832886,0.012167,0.000000
17.270000,8.328484,-310.743927,0.006347,0.000453,0.011517,37.046944,1.887261,0.115167,-310.743927,0.012540,0.000000
17.490002,8.640533,-310.743927,0.006364,0.000473,0.012002,38.435013,1.957973,0.120023,-310.743927,0.012904,0.000000
17.710001,8.919807,-310.788391,0.006368,0.000486,0.012341,39.677284,2.021257,0.123406,-310.788391,0.013268,0.000000
17.930000,9.013275,-310.832886,0.006372,0.000501,0.012713,40.093052,2.042437,0.127135,-310.832886,0.013642,0.000000
18.150002,9.304840,-310.832886,0.006411,0.000518,0.013147,41.389996,2.108507,0.131472,-310.832886,0.014006,0.000000
18.370001,9.432190,-310.788391,0.006441,0.000531,0.013485,41.956478,2.137365,0.134852,-310.788391,0.014370,0.000000
18.590000,9.698814,-310.788391,0.006450,0.000548,0.013910,43.142483,2.197783,0.139102,-310.788391,0.014734,0.000000
18.810001,9.724136,-310.832886,0.006454,0.000559,0.014196,43.255119,2.203521,0.141964,-310.832886,0.015107,0.000000
19.030001,9.607582,-310.832886,0.006459,0.000569,0.014448,42.736660,2.177109,0.144477,-310.832886,0.015471,0.000000
19.250000,10.087944,-310.877380,0.006480,0.000590,0.014977,44.873417,2.285961,0.149768,-310.877380,0.015836,0.000000
19.470001,10.157944,-310.877380,0.006489,0.000603,0.015315,45.184792,2.301823,0.153152,-310.877380,0.016208,0.000000
19.690001,10.300568,-310.788391,0.006510,0.000615,0.015619,45.819214,2.334142,0.156187,-310.788391,0.016573,0.000000
19.910002,10.483398,-310.877380,0.006536,0.000632,0.016061,46.632484,2.375572,0.160608,-310.877380,0.016937,0.000000
20.130001,10.534790,-310.832886,0.006497,0.000646,0.016408,46.861088,2.387218,0.164079,-310.832886,0.017301,0.000000
20.350000,10.677780,-310.877380,0.006519,0.000661,0.016781,47.497139,2.419620,0.167807,-310.877380,0.017674,0.000000
20.570002,10.872154,-310.832886,0.006575,0.000676,0.017171,48.361759,2.463665,0.171709,-310.832886,0.018038,0.000000
20.790001,10.910881,-310.877380,0.006545,0.000686,0.017431,48.534023,2.472441,0.174310,-310.877380,0.018403,0.000000
21.010000,10.768639,-310.832886,0.006588,0.000695,0.017665,47.901299,2.440208,0.176652,-310.832886,0.018767,0.000000
21.230001,11.428482,-310.877380,0.006605,0.000722,0.018333,50.836426,2.589731,0.183329,-310.877380,0.019139,0.000000
21.450001,11.540192,-310.921844,0.006610,0.000738,0.018749,51.333336,2.615045,0.187492,-310.921844,0.019504,0.000000
21.670000,11.454552,-310.832886,0.006666,0.000750,0.019061,50.952393,2.595639,0.190615,-310.832886,0.019868,0.000000
21.890001,11.476517,-310.832886,0.006640,0.000762,0.019365,51.050095,2.600616,0.193650,-310.832886,0.020241,0.000000
22.110001,11.527908,-310.921844,0.006657,0.000775,0.019695,51.278698,2.612262,0.196947,-310.921844,0.020605,0.000000
22.330002,11.682068,-310.877380,0.006696,0.000790,0.020068,51.964432,2.647195,0.200675,-310.877380,0.020969,0.000000
22.550001,11.720421,-310.921844,0.006661,0.000801,0.020345,52.135036,2.655885,0.203449,-310.921844,0.021334,0.000000
22.770000,11.833252,-310.921844,0.006640,0.000813,0.020657,52.636932,2.681453,0.206572,-310.921844,0.021706,0.000000
22.990002,12.048111,-310.877380,0.006704,0.000829,0.021056,53.592674,2.730141,0.210561,-310.877380,0.022071,0.000000
23.210001,12.264084,-310.877380,0.006752,0.000848,0.021533,54.553371,2.779081,0.215330,-310.877380,0.022435,0.000000
23.430000,12.535172,-310.966339,0.006752,0.000868,0.022045,55.759228,2.840510,0.220447,-310.966339,0.022808,0.000000
23.650002,12.394043,-310.921844,0.006730,0.000880,0.022348,55.131458,2.808530,0.223483,-310.921844,0.023172,0.000000
23.870001,12.377289,-310.877380,0.006782,0.000892,0.022669,55.056931,2.804734,0.226692,-310.877380,0.023536,0.000000
24.090002,12.510597,-310.921844,0.006765,0.000905,0.022999,55.649918,2.834942,0.229985,-310.921844,0.023900,0.000000
24.310001,12.694176,-310.877380,0.006855,0.000922,0.023424,56.466515,2.876541,0.234236,-310.877380,0.024274,0.000000
24.530001,12.859512,-310.966339,0.006821,0.000939,0.023840,57.201969,2.914007,0.238399,-310.966339,0.024638,0.000000
24.750002,12.754501,-310.966339,0.006834,0.000946,0.024031,56.734856,2.890211,0.240307,-310.966339,0.025002,0.000000
24.970001,12.854294,-310.921844,0.006873,0.000959,0.024369,57.178753,2.912825,0.243690,-310.921844,0.025375,0.000000
25.190001,13.154053,-310.921844,0.006864,0.000980,0.024881,58.512150,2.980751,0.248808,-310.921844,0.025739,0.000000
25.410002,13.351410,-311.010803,0.006838,0.000996,0.025288,59.390038,3.025473,0.252880,-311.010803,0.026103,0.000000
25.630001,13.279175,-310.966339,0.006894,0.001009,0.025618,59.068718,3.009104,0.256177,-310.966339,0.026468,0.000000
25.850000,13.271729,-310.921844,0.006933,0.001021,0.025921,59.035599,3.007416,0.259212,-310.921844,0.026841,0.000000
26.070002,13.367424,-310.966339,0.006942,0.001035,0.026294,59.461273,3.029102,0.262940,-310.966339,0.027205,0.000000
26.290001,13.649681,-310.921844,0.006907,0.001051,0.026693,60.716812,3.093062,0.266930,-310.921844,0.027569,0.000000
26.510002,13.758415,-310.921844,0.006998,0.001067,0.027092,61.200489,3.117702,0.270919,-310.921844,0.027942,0.000000
26.730001,13.597923,-310.966339,0.006972,0.001073,0.027266,60.486584,3.081334,0.272656,-310.966339,0.028306,0.000000
26.950001,13.712990,-311.010803,0.006985,0.001088,0.027630,60.998425,3.107408,0.276297,-311.010803,0.028670,0.000000
27.170002,14.398521,-310.877380,0.006993,0.001115,0.028315,64.047821,3.262752,0.283148,-310.877380,0.029035,0.000000
27.390001,14.375069,-310.966339,0.007019,0.001129,0.028670,63.943501,3.257437,0.286702,-310.966339,0.029407,0.000000
27.610001,14.252556,-310.966339,0.007019,0.001141,0.028982,63.398533,3.229676,0.289825,-310.966339,0.029772,0.000000
27.830002,14.260376,-311.055298,0.007054,0.001154,0.029303,63.433319,3.231447,0.293034,-311.055298,0.030136,0.000000
28.050001,14.391449,-311.055298,0.007032,0.001167,0.029642,64.016365,3.261149,0.296418,-311.055298,0.030509,0.000000
28.270000,14.696053,-311.010803,0.007071,0.001184,0.030075,65.371307,3.330173,0.300752,-311.010803,0.030873,0.000000
28.490002,14.675941,-311.055298,0.007054,0.001196,0.030370,65.281845,3.325616,0.303700,-311.055298,0.031237,0.000000
28.710001,14.810371,-311.055298,0.007067,0.001211,0.030760,65.879822,3.356078,0.307602,-311.055298,0.031602,0.000000
28.930002,14.802177,-311.099762,0.007110,0.001222,0.031029,65.843376,3.354221,0.310293,-311.099762,0.031974,0.000000
29.150002,15.351425,-311.010803,0.007157,0.001245,0.031619,68.286552,3.478683,0.316190,-311.010803,0.032339,0.000000
29.370001,15.414360,-311.010803,0.007170,0.001260,0.031992,68.566498,3.492944,0.319918,-311.010803,0.032703,0.000000
29.590002,15.256470,-311.055298,0.007157,0.001270,0.032261,67.864166,3.457165,0.322606,-311.055298,0.033076,0.000000
29.810001,15.261314,-311.010803,0.007127,0.001281,0.032547,67.885719,3.458263,0.325467,-311.010803,0.033440,0.000000
30.030001,15.493675,-311.055298,0.007213,0.001299,0.032989,68.919312,3.510917,0.329891,-311.055298,0.033804,0.000000
30.250002,15.727150,-311.055298,0.007170,0.001313,0.033353,69.957855,3.563823,0.333533,-311.055298,0.034169,0.000000
30.470001,15.705551,-311.010803,0.007205,0.001326,0.033683,69.861778,3.558929,0.336829,-311.010803,0.034541,0.000000
30.690001,15.789711,-311.055298,0.007252,0.001337,0.033952,70.236145,3.578000,0.339516,-311.055298,0.034906,0.000000
30.910002,16.203041,-311.099762,0.007235,0.001356,0.034455,72.074730,3.671662,0.344547,-311.099762,0.035270,0.000000
31.130001,16.212723,-311.099762,0.007261,0.001368,0.034749,72.117790,3.673855,0.347495,-311.099762,0.035643,0.000000
31.350002,16.391464,-311.144257,0.007235,0.001383,0.035123,72.912872,3.714359,0.351227,-311.144257,0.036007,0.000000
31.570002,16.524025,-311.055298,0.007299,0.001398,0.035504,73.502533,3.744398,0.355042,-311.055298,0.036371,0.000000
31.790001,16.585472,-311.055298,0.007248,0.001410,0.035816,73.775864,3.758322,0.358165,-311.055298,0.036735,0.000000
32.010002,16.907196,-311.099762,0.007256,0.001427,0.036241,75.206963,3.831225,0.362411,-311.099762,0.037109,0.000000
32.230003,17.084076,-311.099762,0.007308,0.001443,0.036657,75.993767,3.871307,0.366575,-311.099762,0.037473,0.000000
32.450001,17.021515,-311.099762,0.007325,0.001454,0.036944,75.715477,3.857130,0.369436,-311.099762,0.037837,0.000000
32.670002,17.064713,-311.099762,0.007373,0.001468,0.037282,75.907631,3.866919,0.372820,-311.099762,0.038210,0.000000
32.890003,17.299309,-311.099762,0.007338,0.001484,0.037681,76.951172,3.920079,0.376809,-311.099762,0.038574,0.000000
33.110001,17.538742,-311.144257,0.007355,0.001499,0.038080,78.016220,3.974336,0.380798,-311.144257,0.038938,0.000000
33.330002,17.495178,-311.188721,0.007351,0.001509,0.038331,77.822441,3.964464,0.383311,-311.188721,0.039303,0.000000
33.550003,17.713013,-311.188721,0.007420,0.001525,0.038747,78.791412,4.013826,0.387475,-311.188721,0.039676,0.000000
33.770000,17.828079,-311.099762,0.007403,0.001538,0.039077,79.303261,4.039900,0.390771,-311.099762,0.040040,0.000000
33.990002,18.170288,-311.099762,0.007407,0.001557,0.039545,80.825478,4.117446,0.395453,-311.099762,0.040404,0.000000
34.210003,18.261887,-311.233215,0.007463,0.001570,0.039875,81.232925,4.138203,0.398750,-311.233215,0.040768,0.000000
34.430000,18.399666,-311.188721,0.007472,0.001583,0.040213,81.845802,4.169424,0.402130,-311.188721,0.041141,0.000000
34.650002,18.425362,-311.144257,0.007429,0.001596,0.040543,81.960098,4.175247,0.405427,-311.144257,0.041505,0.000000
34.870003,18.713951,-311.144257,0.007493,0.001614,0.040985,83.243813,4.240642,0.409851,-311.144257,0.041870,0.000000
35.090000,19.018181,-311.233215,0.007485,0.001631,0.041436,84.597092,4.309581,0.414359,-311.233215,0.042242,0.000000
35.310001,19.054672,-311.188721,0.007463,0.001644,0.041766,84.759415,4.317851,0.417656,-311.188721,0.042607,0.000000
35.530003,19.144043,-311.233215,0.007554,0.001659,0.042130,85.156960,4.338102,0.421297,-311.233215,0.042971,0.000000
35.750000,19.232666,-311.188721,0.007567,0.001671,0.042442,85.551170,4.358184,0.424419,-311.188721,0.043335,0.000000
35.970001,19.574127,-311.144257,0.007562,0.001689,0.042893,87.070068,4.435561,0.428927,-311.144257,0.043708,0.000000
36.190002,19.637062,-311.188721,0.007571,0.001701,0.043214,87.350014,4.449822,0.432137,-311.188721,0.044072,0.000000
36.410000,19.561096,-311.233215,0.007584,0.001711,0.043448,87.012100,4.432608,0.434479,-311.233215,0.044437,0.000000
36.630001,19.844841,-311.233215,0.007567,0.001725,0.043821,88.274261,4.496905,0.438208,-311.233215,0.044809,0.000000
36.850002,20.081673,-311.188721,0.007558,0.001740,0.044194,89.327744,4.550572,0.441936,-311.188721,0.045174,0.000000
37.070004,20.469315,-311.144257,0.007580,0.001758,0.044662,91.052055,4.638413,0.446621,-311.144257,0.045538,0.000000
37.290001,20.684174,-311.188721,0.007601,0.001775,0.045087,92.007797,4.687101,0.450868,-311.188721,0.045902,0.000000
37.510002,20.764229,-311.277710,0.007631,0.001788,0.045408,92.363899,4.705241,0.454078,-311.277710,0.046275,0.000000
37.730003,20.751572,-311.188721,0.007683,0.001801,0.045737,92.307602,4.702374,0.457374,-311.188721,0.046639,0.000000
37.950001,21.042023,-311.188721,0.007675,0.001816,0.046119,93.599594,4.768190,0.461189,-311.188721,0.047003,0.000000
38.170002,21.102722,-311.233215,0.007649,0.001828,0.046431,93.869598,4.781945,0.464312,-311.233215,0.047376,0.000000
38.390003,21.325768,-311.277710,0.007679,0.001842,0.046778,94.861755,4.832488,0.467779,-311.277710,0.047741,0.000000
38.610001,21.282944,-311.277710,0.007683,0.001851,0.047021,94.671265,4.822784,0.470209,-311.277710,0.048105,0.000000
38.830002,21.736122,-311.188721,0.007718,0.001872,0.047559,96.687103,4.925476,0.475587,-311.188721,0.048469,0.000000
39.050003,22.161377,-311.233215,0.007769,0.001888,0.047949,98.578728,5.021840,0.479489,-311.233215,0.048842,0.000000
39.270000,22.261917,-311.277710,0.007713,0.001900,0.048261,99.025955,5.044622,0.482612,-311.277710,0.049206,0.000000
39.490002,22.571358,-311.322174,0.007739,0.001916,0.048668,100.402412,5.114743,0.486685,-311.322174,0.049570,0.000000
39.710003,22.639503,-311.322174,0.007739,0.001929,0.048998,100.705544,5.130185,0.489981,-311.322174,0.049944,0.000000
39.930000,23.097519,-311.322174,0.007804,0.001947,0.049466,102.742897,5.233973,0.494663,-311.322174,0.050308,0.000000
40.150002,23.056931,-311.277710,0.007804,0.001957,0.049718,102.562347,5.224775,0.497180,-311.277710,0.050672,0.000000
40.370003,22.904259,-311.277710,0.007817,0.001971,0.050056,101.883232,5.190179,0.500560,-311.277710,0.051036,0.000000
40.590000,23.724594,-311.322174,0.007817,0.001991,0.050559,105.532265,5.376070,0.505590,-311.322174,0.051409,0.000000
40.810001,23.812843,-311.277710,0.007830,0.002004,0.050897,105.924820,5.396067,0.508974,-311.277710,0.051773,0.000000
41.030003,23.826996,-311.277710,0.007847,0.002013,0.051140,105.987770,5.399275,0.511404,-311.277710,0.052138,0.000000
41.250004,24.253738,-311.277710,0.007847,0.002031,0.051591,107.886017,5.495975,0.515911,-311.277710,0.052510,0.000000
41.470001,24.364700,-311.322174,0.007860,0.002045,0.051938,108.379601,5.521120,0.519382,-311.322174,0.052875,0.000000
41.690002,24.621269,-311.322174,0.007886,0.002059,0.052302,109.520874,5.579259,0.523023,-311.322174,0.053239,0.000000
41.910004,25.055077,-311.322174,0.007877,0.002075,0.052701,111.450546,5.677562,0.527013,-311.322174,0.053603,0.000000
42.130001,25.062157,-311.277710,0.007929,0.002085,0.052953,111.482040,5.679166,0.529526,-311.277710,0.053976,0.000000
42.350002,24.904266,-311.322174,0.007886,0.002098,0.053282,110.779709,5.643387,0.532822,-311.322174,0.054340,0.000000
42.570004,26.162888,-311.411133,0.007929,0.002122,0.053889,116.378334,5.928595,0.538893,-311.411133,0.054705,0.000000
42.790001,26.468979,-311.411133,0.007955,0.002137,0.054288,117.739899,5.997956,0.542883,-311.411133,0.055077,0.000000
43.010002,26.407906,-311.366669,0.007950,0.002149,0.054583,117.468231,5.984117,0.545831,-311.366669,0.055442,0.000000
43.230003,26.501373,-311.366669,0.008002,0.002162,0.054913,117.883995,6.005297,0.549128,-311.366669,0.055806,0.000000
43.450001,26.650696,-311.366669,0.008011,0.002175,0.055242,118.548218,6.039134,0.552421,-311.366669,0.056170,0.000000
43.670002,26.948219,-311.322174,0.007972,0.002189,0.055598,119.871666,6.106554,0.555978,-311.322174,0.056543,0.000000
43.890003,27.000725,-311.455627,0.008032,0.002200,0.055875,120.105225,6.118452,0.558753,-311.455627,0.056907,0.000000
44.110001,27.233459,-311.411133,0.008032,0.002212,0.056196,121.140480,6.171190,0.561962,-311.411133,0.057272,0.000000
44.330002,27.733925,-311.366669,0.008058,0.002229,0.056621,123.366661,6.284597,0.566209,-311.366669,0.057644,0.000000
44.550003,28.473831,-311.366669,0.008067,0.002250,0.057150,126.657928,6.452262,0.571500,-311.366669,0.058008,0.000000
44.770000,29.121017,-311.366669,0.008058,0.002268,0.057610,129.536758,6.598917,0.576099,-311.366669,0.058373,0.000000
44.990002,29.058456,-311.411133,0.008067,0.002281,0.057939,129.258469,6.584741,0.579392,-311.411133,0.058737,0.000000
45.210003,29.092346,-311.411133,0.008119,0.002291,0.058200,129.409225,6.592420,0.581996,-311.411133,0.059110,0.000000
45.430000,29.268105,-311.366669,0.008088,0.002304,0.058529,130.191025,6.632247,0.585289,-311.366669,0.059474,0.000000
45.650002,29.742874,-311.322174,0.008110,0.002321,0.058945,132.302917,6.739831,0.589452,-311.322174,0.059838,0.000000
45.870003,30.117859,-311.411133,0.008093,0.002336,0.059327,133.970932,6.824805,0.593267,-311.411133,0.060211,0.000000
46.090004,30.035561,-311.455627,0.008170,0.002345,0.059552,133.604843,6.806155,0.595523,-311.455627,0.060576,0.000000
46.310001,30.410538,-311.455627,0.008149,0.002359,0.059925,135.272827,6.891127,0.599251,-311.455627,0.060940,0.000000
46.530003,31.148956,-311.411133,0.008196,0.002380,0.060446,138.557480,7.058455,0.604455,-311.411133,0.061304,0.000000
46.750004,31.718315,-311.411133,0.008157,0.002394,0.060810,141.090118,7.187473,0.608096,-311.411133,0.061677,0.000000
46.970001,31.834869,-311.455627,0.008196,0.002407,0.061148,141.608566,7.213884,0.611480,-311.455627,0.062041,0.000000
47.190002,31.957001,-311.500092,0.008226,0.002419,0.061452,142.151840,7.241560,0.614516,-311.500092,0.062405,0.000000
47.410004,32.293259,-311.500092,0.008222,0.002435,0.061842,143.647583,7.317757,0.618418,-311.500092,0.062770,0.000000
47.630001,32.874161,-311.411133,0.008201,0.002450,0.062223,146.231567,7.449391,0.622233,-311.411133,0.063143,0.000000
47.850002,33.190674,-311.411133,0.008226,0.002463,0.062553,147.639496,7.521114,0.625530,-311.411133,0.063507,0.000000
48.070004,33.114334,-311.455627,0.008235,0.002472,0.062779,147.299911,7.503816,0.627785,-311.455627,0.063871,0.000000
48.290001,33.379097,-311.544586,0.008287,0.002485,0.063125,148.477646,7.563811,0.631252,-311.544586,0.064244,0.000000
48.510002,35.036522,-311.544586,0.008257,0.002513,0.063828,155.850235,7.939390,0.638277,-311.544586,0.064608,0.000000
48.730003,35.326973,-311.455627,0.008308,0.002527,0.064192,157.142227,8.005206,0.641918,-311.455627,0.064972,0.000000
48.950001,35.378365,-311.411133,0.008317,0.002540,0.064504,157.370819,8.016852,0.645041,-311.411133,0.065337,0.000000
49.170002,35.607742,-311.500092,0.008295,0.002552,0.064816,158.391144,8.068830,0.648163,-311.500092,0.065710,0.000000
49.390003,35.977882,-311.544586,0.008282,0.002565,0.065146,160.037613,8.152704,0.651460,-311.544586,0.066074,0.000000
49.610001,36.770287,-311.500092,0.008321,0.002582,0.065588,163.562408,8.332266,0.655881,-311.500092,0.066438,0.000000
49.830002,36.883492,-311.500092,0.008330,0.002593,0.065866,164.065964,8.357919,0.658659,-311.500092,0.066811,0.000000
50.050003,37.312096,-311.500092,0.008343,0.002609,0.066264,165.972488,8.455042,0.662644,-311.500092,0.067175,0.000000
50.270004,37.433861,-311.500092,0.008356,0.002618,0.066507,166.514130,8.482635,0.665074,-311.500092,0.067540,0.000000
50.490002,38.968033,-311.589050,0.008403,0.002645,0.067184,173.338470,8.830282,0.671838,-311.589050,0.067904,0.000000
50.710003,39.318062,-311.544586,0.008403,0.002658,0.067522,174.895477,8.909600,0.675222,-311.544586,0.068276,0.000000
50.930004,39.361259,-311.500092,0.008442,0.002669,0.067791,175.087631,8.919389,0.677909,-311.500092,0.068641,0.000000
51.150002,39.589149,-311.544586,0.008438,0.002683,0.068138,176.101334,8.971029,0.681379,-311.544586,0.069005,0.000000
51.370003,40.098183,-311.589050,0.008390,0.002697,0.068493,178.365631,9.086378,0.684934,-311.589050,0.069378,0.000000
51.590004,40.817978,-311.589050,0.008429,0.002712,0.068875,181.567429,9.249486,0.688749,-311.589050,0.069742,0.000000
51.810001,41.060020,-311.544586,0.008459,0.002725,0.069213,182.644089,9.304334,0.692132,-311.544586,0.070106,0.000000
52.030003,41.385475,-311.544586,0.008459,0.002736,0.069491,184.091782,9.378082,0.694907,-311.544586,0.070471,0.000000
52.250004,42.362206,-311.544586,0.008446,0.002756,0.069994,188.436508,9.599413,0.699937,-311.544586,0.070843,0.000000
52.470001,42.558449,-311.633545,0.008476,0.002766,0.070254,189.309433,9.643882,0.702537,-311.633545,0.071208,0.000000
52.690002,43.238029,-311.589050,0.008476,0.002783,0.070696,192.332367,9.797877,0.706962,-311.589050,0.071572,0.000000
52.910004,43.717644,-311.589050,0.008528,0.002796,0.071026,194.465790,9.906560,0.710258,-311.589050,0.071945,0.000000
53.130001,44.216995,-311.589050,0.008494,0.002809,0.071355,196.687012,10.019714,0.713551,-311.589050,0.072309,0.000000
53.350002,45.000465,-311.589050,0.008537,0.002827,0.071798,200.172073,10.197251,0.717976,-311.589050,0.072673,0.000000
53.570004,45.712067,-311.589050,0.008532,0.002842,0.072188,203.337433,10.358502,0.721878,-311.589050,0.073037,0.000000
53.790001,45.945549,-311.633545,0.008515,0.002853,0.072457,204.376007,10.411410,0.724565,-311.633545,0.073411,0.000000
54.010002,46.365959,-311.589050,0.008580,0.002868,0.072847,206.246094,10.506677,0.728467,-311.589050,0.073775,0.000000
54.230003,47.119637,-311.589050,0.008532,0.002882,0.073211,209.598618,10.677463,0.732112,-311.589050,0.074139,0.000000
54.450001,47.808151,-311.633545,0.008554,0.002898,0.073610,212.661285,10.833482,0.736102,-311.633545,0.074512,0.000000
54.670002,48.071053,-311.633545,0.008584,0.002908,0.073853,213.830719,10.893056,0.738528,-311.633545,0.074876,0.000000
54.890003,48.767761,-311.678009,0.008606,0.002924,0.074278,216.929840,11.050933,0.742778,-311.678009,0.075240,0.000000
55.110004,49.176994,-311.589050,0.008632,0.002937,0.074590,218.750198,11.143666,0.745901,-311.589050,0.075605,0.000000
55.330002,50.278099,-311.544586,0.008636,0.002956,0.075084,223.648148,11.393180,0.750844,-311.544586,0.075978,0.000000
55.550003,50.584564,-311.633545,0.008649,0.002968,0.075379,225.011383,11.462626,0.753792,-311.633545,0.076342,0.000000
55.770004,51.397453,-311.678009,0.008636,0.002981,0.075726,228.627289,11.646830,0.757259,-311.678009,0.076706,0.000000
55.990002,51.869995,-311.633545,0.008666,0.002994,0.076047,230.729263,11.753909,0.760469,-311.633545,0.077079,0.000000
56.210003,52.718262,-311.589050,0.008614,0.003011,0.076489,234.502533,11.946129,0.764893,-311.589050,0.077443,0.000000
56.430004,53.721428,-311.633545,0.008640,0.003031,0.076975,238.964844,12.173450,0.769749,-311.633545,0.077807,0.000000
56.650002,54.202164,-311.678009,0.008653,0.003043,0.077287,241.103271,12.282386,0.772872,-311.678009,0.078172,0.000000
56.870003,54.697792,-311.722504,0.008649,0.003056,0.077625,243.307938,12.394696,0.776252,-311.722504,0.078545,0.000000
57.090004,55.279808,-311.722504,0.008722,0.003069,0.077964,245.896866,12.526584,0.779635,-311.722504,0.078909,0.000000
57.310001,56.317612,-311.633545,0.008670,0.003087,0.078406,250.513245,12.761753,0.784056,-311.633545,0.079273,0.000000
57.530003,56.842285,-311.722504,0.008714,0.003098,0.078692,252.847107,12.880646,0.786921,-311.722504,0.079646,0.000000
57.750004,57.159172,-311.678009,0.008696,0.003109,0.078961,254.256699,12.952454,0.789609,-311.678009,0.080010,0.000000
57.970001,57.926628,-311.722504,0.008696,0.003124,0.079342,257.670502,13.126362,0.793424,-311.722504,0.080375,0.000000
58.190002,58.832985,-311.678009,0.008718,0.003138,0.079715,261.702179,13.331745,0.797152,-311.678009,0.080739,0.000000
58.410004,59.822006,-311.678009,0.008722,0.003156,0.080175,266.101562,13.555861,0.801751,-311.678009,0.081111,0.000000
58.630001,60.591698,-311.678009,0.008731,0.003173,0.080600,269.525330,13.730274,0.805997,-311.678009,0.081476,0.000000
58.850002,61.455978,-311.678009,0.008778,0.003186,0.080929,273.369843,13.926124,0.809294,-311.678009,0.081840,0.000000
59.070004,61.900215,-311.766998,0.008787,0.003197,0.081198,275.345917,14.026789,0.811981,-311.766998,0.082213,0.000000
59.290001,62.764870,-311.722504,0.008748,0.003214,0.081641,279.192078,14.222723,0.816406,-311.722504,0.082577,0.000000
59.510002,63.432899,-311.722504,0.008787,0.003225,0.081918,282.163635,14.374100,0.819180,-311.722504,0.082941,0.000000
59.730003,64.219719,-311.722504,0.008795,0.003240,0.082300,285.663574,14.552397,0.822995,-311.722504,0.083306,0.000000
59.950005,64.608849,-311.766998,0.008748,0.003252,0.082594,287.394501,14.640574,0.825944,-311.766998,0.083678,0.000000
60.170002,66.021263,-311.766998,0.008787,0.003272,0.083115,293.677246,14.960632,0.831148,-311.766998,0.084043,0.000000
60.390003,66.777931,-311.722504,0.008821,0.003285,0.083436,297.043060,15.132095,0.834357,-311.722504,0.084407,0.000000
60.610004,67.485435,-311.766998,0.008808,0.003290,0.083557,300.190216,15.292418,0.835572,-311.766998,0.084728,0.000000
60.830002,66.735100,-311.722504,0.008808,0.003289,0.083540,296.852539,15.122390,0.835398,-311.722504,0.083757,0.000000
61.050003,66.036156,-311.766998,0.008808,0.003289,0.083531,293.743500,14.964006,0.835311,-311.766998,0.083540,0.000000
61.270004,65.450050,-311.811462,0.008869,0.003288,0.083514,291.136353,14.831194,0.835137,-311.811462,0.083540,0.000000
61.490002,64.928719,-311.766998,0.008869,0.003288,0.083505,288.817352,14.713058,0.835050,-311.766998,0.083540,0.000000
61.710003,64.453209,-311.766998,0.008804,0.003288,0.083505,286.702179,14.605307,0.835050,-311.766998,0.083540,0.000000
61.930004,64.005241,-311.766998,0.008813,0.003288,0.083505,284.709534,14.503796,0.835050,-311.766998,0.083540,0.000000
62.150002,63.611275,-311.766998,0.008873,0.003288,0.083505,282.957092,14.414521,0.835050,-311.766998,0.083540,0.000000
62.370003,63.235176,-311.766998,0.008847,0.003287,0.083496,281.284119,14.329295,0.834963,-311.766998,0.083540,0.000000
62.590004,62.911209,-311.766998,0.008882,0.003287,0.083496,279.843048,14.255884,0.834963,-311.766998,0.083540,0.000000
62.810001,62.604744,-311.811462,0.008856,0.003287,0.083496,278.479797,14.186438,0.834963,-311.811462,0.083540,0.000000
63.030003,62.311317,-311.722504,0.008864,0.003287,0.083496,277.174591,14.119946,0.834963,-311.722504,0.083540,0.000000
63.250004,62.045441,-311.811462,0.008882,0.003287,0.083496,275.991913,14.059697,0.834963,-311.811462,0.083540,0.000000
63.470001,61.789627,-311.855957,0.008839,0.003287,0.083496,274.853973,14.001730,0.834963,-311.855957,0.083540,0.000000
63.690002,61.559128,-311.855957,0.008860,0.003287,0.083496,273.828674,13.949497,0.834963,-311.855957,0.083540,0.000000
63.910004,61.341660,-311.766998,0.008877,0.003287,0.083496,272.861328,13.900219,0.834963,-311.766998,0.083540,0.000000
64.130005,61.135368,-311.855957,0.008903,0.003287,0.083496,271.943695,13.853472,0.834963,-311.855957,0.083540,0.000000
64.350006,60.952156,-311.855957,0.008826,0.003287,0.083496,271.128723,13.811955,0.834963,-311.855957,0.083540,0.000000
64.570000,60.749588,-311.900421,0.008860,0.003287,0.083496,270.227661,13.766053,0.834963,-311.900421,0.083540,0.000000
64.790001,60.583511,-311.855957,0.008860,0.003287,0.083496,269.488922,13.728420,0.834963,-311.855957,0.083540,0.000000
65.010002,60.430840,-311.855957,0.008882,0.003287,0.083496,268.809814,13.693824,0.834963,-311.855957,0.083540,0.000000
65.230003,60.278908,-311.855957,0.008912,0.003287,0.083496,268.133972,13.659396,0.834963,-311.855957,0.083540,0.000000
65.450005,60.126610,-311.855957,0.008869,0.003287,0.083496,267.456512,13.624885,0.834963,-311.855957,0.083540,0.000000
65.670006,59.969093,-311.855957,0.008864,0.003287,0.083496,266.755859,13.589190,0.834963,-311.855957,0.083540,0.000000
65.889999,59.836899,-311.855957,0.008877,0.003287,0.083496,266.167816,13.559236,0.834963,-311.855957,0.083540,0.000000
66.110001,59.711411,-311.811462,0.008908,0.003287,0.083496,265.609619,13.530799,0.834963,-311.811462,0.083540,0.000000
66.330002,59.582199,-311.900421,0.008921,0.003287,0.083496,265.034851,13.501519,0.834963,-311.900421,0.083540,0.000000
66.550003,59.460808,-311.900421,0.008890,0.003287,0.083488,264.494873,13.474011,0.834876,-311.900421,0.083540,0.000000
66.770004,59.356171,-311.855957,0.008864,0.003287,0.083488,264.029419,13.450301,0.834876,-311.855957,0.083540,0.000000
66.990005,59.225464,-311.855957,0.008860,0.003287,0.083488,263.448029,13.420682,0.834876,-311.855957,0.083540,0.000000
67.210007,59.126419,-311.944916,0.008860,0.003287,0.083488,263.007446,13.398238,0.834876,-311.944916,0.083540,0.000000
67.430000,59.013588,-311.989380,0.008873,0.003287,0.083488,262.505554,13.372670,0.834876,-311.989380,0.083540,0.000000
67.650002,58.922356,-311.989380,0.008864,0.003287,0.083488,262.099731,13.351997,0.834876,-311.989380,0.083540,0.000000
67.870003,58.851608,-311.900421,0.008895,0.003287,0.083488,261.785034,13.335965,0.834876,-311.900421,0.083540,0.000000
68.090004,58.735428,-311.944916,0.008864,0.003287,0.083488,261.268219,13.309638,0.834876,-311.944916,0.083540,0.000000
68.310005,58.646431,-311.944916,0.008903,0.003287,0.083488,260.872345,13.289472,0.834876,-311.944916,0.083540,0.000000
68.530006,58.564880,-311.944916,0.008890,0.003287,0.083488,260.509613,13.270991,0.834876,-311.944916,0.083540,0.000000
68.750000,58.468063,-311.944916,0.008882,0.003287,0.083488,260.078949,13.249052,0.834876,-311.944916,0.083540,0.000000
68.970001,58.390984,-311.944916,0.008882,0.003287,0.083488,259.736053,13.231586,0.834876,-311.944916,0.083540,0.000000
69.190002,58.316132,-311.989380,0.008912,0.003287,0.083488,259.403107,13.214624,0.834876,-311.989380,0.083540,0.000000
69.410004,58.231979,-311.900421,0.008933,0.003287,0.083488,259.028778,13.195555,0.834876,-311.900421,0.083540,0.000000
69.630005,58.157127,-311.944916,0.008903,0.003287,0.083488,258.695831,13.178593,0.834876,-311.944916,0.083540,0.000000
69.850006,58.088989,-311.989380,0.008938,0.003287,0.083488,258.392731,13.163154,0.834876,-311.989380,0.083540,0.000000
70.070000,58.015999,-311.989380,0.008873,0.003287,0.083488,258.068054,13.146613,0.834876,-311.989380,0.083540,0.000000
70.290001,57.955307,-311.989380,0.008929,0.003287,0.083488,257.798096,13.132860,0.834876,-311.989380,0.083540,0.000000
70.510002,57.878220,-311.944916,0.008908,0.003287,0.083488,257.455170,13.115392,0.834876,-311.944916,0.083540,0.000000
70.730003,57.799278,-311.989380,0.008890,0.003287,0.083488,257.104034,13.097504,0.834876,-311.989380,0.083540,0.000000
70.950005,57.748634,-312.033875,0.008916,0.003287,0.083488,256.878754,13.086028,0.834876,-312.033875,0.083540,0.000000
71.170006,57.684593,-311.989380,0.008933,0.003287,0.083488,256.593872,13.071516,0.834876,-311.989380,0.083540,0.000000
71.390007,57.634315,-311.900421,0.008882,0.003287,0.083488,256.370239,13.060122,0.834876,-311.900421,0.083540,0.000000
71.610001,57.567291,-311.989380,0.008903,0.003287,0.083488,256.072113,13.044934,0.834876,-311.989380,0.083540,0.000000
71.830002,57.500267,-312.033875,0.008916,0.003287,0.083488,255.773956,13.029747,0.834876,-312.033875,0.083540,0.000000
72.050003,57.449623,-312.033875,0.008908,0.003287,0.083488,255.548691,13.018271,0.834876,-312.033875,0.083540,0.000000
72.270004,57.394882,-311.989380,0.008895,0.003287,0.083488,255.305191,13.005866,0.834876,-311.989380,0.083540,0.000000
72.490005,57.330460,-311.989380,0.008886,0.003287,0.083488,255.018616,12.991268,0.834876,-311.989380,0.083540,0.000000
72.710007,57.277588,-311.989380,0.008925,0.003287,0.083488,254.783432,12.979287,0.834876,-311.989380,0.083540,0.000000
72.930000,57.222099,-311.989380,0.008925,0.003287,0.083488,254.536606,12.966713,0.834876,-311.989380,0.083540,0.000000
73.150002,57.168854,-312.122833,0.008933,0.003287,0.083488,254.299759,12.954648,0.834876,-312.122833,0.083540,0.000000
73.370003,57.133102,-312.033875,0.008933,0.003287,0.083488,254.140732,12.946547,0.834876,-312.033875,0.083540,0.000000
73.590004,57.077621,-312.078339,0.008890,0.003287,0.083488,253.893936,12.933974,0.834876,-312.078339,0.083540,0.000000
73.810005,57.028099,-312.078339,0.008899,0.003287,0.083488,253.673660,12.922751,0.834876,-312.078339,0.083540,0.000000
74.030006,56.975594,-312.078339,0.008929,0.003287,0.083488,253.440094,12.910854,0.834876,-312.078339,0.083540,0.000000
74.250000,56.927925,-312.078339,0.008895,0.003287,0.083488,253.228058,12.900052,0.834876,-312.078339,0.083540,0.000000
74.470001,56.883987,-312.078339,0.008925,0.003287,0.083488,253.032608,12.890096,0.834876,-312.078339,0.083540,0.000000
74.690002,56.846008,-312.078339,0.008860,0.003287,0.083488,252.863678,12.881489,0.834876,-312.078339,0.083540,0.000000
74.910004,56.807655,-312.078339,0.008946,0.003287,0.083488,252.693069,12.872799,0.834876,-312.078339,0.083540,0.000000
75.130005,56.757385,-312.078339,0.008864,0.003287,0.083488,252.469452,12.861408,0.834876,-312.078339,0.083540,0.000000
75.350006,56.704132,-312.122833,0.008933,0.003287,0.083488,252.232574,12.849339,0.834876,-312.122833,0.083540,0.000000
75.570007,56.674339,-312.122833,0.008882,0.003287,0.083488,252.100052,12.842589,0.834876,-312.122833,0.083540,0.000000
75.790001,56.624817,-312.033875,0.008946,0.003287,0.083488,251.879761,12.831367,0.834876,-312.033875,0.083540,0.000000
76.010002,56.588699,-312.122833,0.008938,0.003287,0.083488,251.719101,12.823182,0.834876,-312.122833,0.083540,0.000000
76.230003,56.557793,-312.122833,0.008903,0.003287,0.083488,251.581619,12.816179,0.834876,-312.122833,0.083540,0.000000
76.450005,56.506775,-312.078339,0.008882,0.003287,0.083488,251.354691,12.804618,0.834876,-312.078339,0.083540,0.000000
76.670006,56.463211,-312.122833,0.008903,0.003287,0.083488,251.160904,12.794746,0.834876,-312.122833,0.083540,0.000000
76.890007,56.426346,-312.078339,0.008921,0.003287,0.083488,250.996918,12.786393,0.834876,-312.078339,0.083540,0.000000
77.110001,56.379799,-312.122833,0.008860,0.003287,0.083488,250.789871,12.775845,0.834876,-312.122833,0.083540,0.000000
77.330002,56.357452,-312.122833,0.008903,0.003287,0.083488,250.690475,12.770781,0.834876,-312.122833,0.083540,0.000000
77.550003,56.315376,-312.167328,0.008890,0.003287,0.083488,250.503311,12.761247,0.834876,-312.167328,0.083540,0.000000
77.770004,56.272926,-312.122833,0.008925,0.003287,0.083488,250.314484,12.751627,0.834876,-312.122833,0.083540,0.000000
77.990005,56.234200,-312.167328,0.008946,0.003287,0.083488,250.142212,12.742852,0.834876,-312.167328,0.083540,0.000000
78.210007,56.192863,-312.167328,0.008869,0.003287,0.083488,249.958344,12.733485,0.834876,-312.167328,0.083540,0.000000
78.430000,56.173874,-312.211792,0.008916,0.003287,0.083488,249.873871,12.729181,0.834876,-312.211792,0.083540,0.000000
78.650002,56.131798,-312.167328,0.008886,0.003287,0.083488,249.686707,12.719647,0.834876,-312.167328,0.083540,0.000000
78.870003,56.087486,-312.167328,0.008890,0.003287,0.083488,249.489594,12.709606,0.834876,-312.167328,0.083540,0.000000
79.090004,56.050247,-312.167328,0.008912,0.003287,0.083488,249.323944,12.701167,0.834876,-312.167328,0.083540,0.000000
79.310005,56.023811,-312.211792,0.008912,0.003287,0.083488,249.206360,12.695177,0.834876,-312.211792,0.083540,0.000000
79.530006,56.001091,-312.256287,0.008886,0.003287,0.083488,249.105301,12.690028,0.834876,-312.256287,0.083540,0.000000
79.750000,55.941887,-312.211792,0.008938,0.003287,0.083488,248.841934,12.676613,0.834876,-312.211792,0.083540,0.000000
79.970001,55.932579,-312.122833,0.008903,0.003287,0.083488,248.800537,12.674503,0.834876,-312.122833,0.083540,0.000000
80.190002,55.887894,-312.211792,0.008942,0.003287,0.083488,248.601761,12.664378,0.834876,-312.211792,0.083540,0.000000
80.410004,55.861824,-312.167328,0.008908,0.003287,0.083488,248.485809,12.658470,0.834876,-312.167328,0.083540,0.000000
80.630005,55.827568,-312.256287,0.008925,0.003287,0.083488,248.333420,12.650708,0.834876,-312.256287,0.083540,0.000000
80.850006,55.783630,-312.167328,0.008899,0.003287,0.083488,248.137985,12.640752,0.834876,-312.167328,0.083540,0.000000
81.070007,55.780273,-312.167328,0.008873,0.003287,0.083488,248.123047,12.639991,0.834876,-312.167328,0.083540,0.000000
81.290001,55.744156,-312.211792,0.008951,0.003287,0.083488,247.962387,12.631806,0.834876,-312.211792,0.083540,0.000000
81.510002,55.725166,-312.256287,0.008933,0.003287,0.083488,247.877914,12.627503,0.834876,-312.256287,0.083540,0.000000
81.730003,55.684204,-312.211792,0.008929,0.003287,0.083488,247.695709,12.618220,0.834876,-312.211792,0.083540,0.000000
81.950005,55.642128,-312.211792,0.008912,0.003287,0.083488,247.508545,12.608686,0.834876,-312.211792,0.083540,0.000000
82.170006,55.614197,-312.167328,0.008946,0.003287,0.083488,247.384308,12.602357,0.834876,-312.167328,0.083540,0.000000
82.390007,55.576218,-312.211792,0.008890,0.003287,0.083488,247.215363,12.593751,0.834876,-312.211792,0.083540,0.000000
82.610001,55.576591,-312.256287,0.008921,0.003287,0.083488,247.217026,12.593835,0.834876,-312.256287,0.083540,0.000000
82.830002,55.552383,-312.300751,0.008903,0.003287,0.083488,247.109344,12.588350,0.834876,-312.300751,0.083540,0.000000
83.050003,55.528183,-312.256287,0.008921,0.003287,0.083488,247.001694,12.582866,0.834876,-312.256287,0.083540,0.000000
83.270004,55.489082,-312.300751,0.008946,0.003287,0.083488,246.827759,12.574006,0.834876,-312.300751,0.083540,0.000000
83.490005,55.448120,-312.300751,0.008938,0.003287,0.083488,246.645554,12.564724,0.834876,-312.300751,0.083540,0.000000
83.710007,55.438438,-312.300751,0.008933,0.003287,0.083488,246.602493,12.562530,0.834876,-312.300751,0.083540,0.000000
83.930000,55.415352,-312.345245,0.008912,0.003287,0.083488,246.499802,12.557299,0.834876,-312.345245,0.083540,0.000000
84.150002,55.387794,-312.300751,0.008886,0.003287,0.083488,246.377213,12.551053,0.834876,-312.300751,0.083540,0.000000
84.370003,55.365456,-312.256287,0.008925,0.003287,0.083488,246.277847,12.545992,0.834876,-312.256287,0.083540,0.000000
84.590004,55.337898,-312.300751,0.008916,0.003287,0.083488,246.155258,12.539747,0.834876,-312.300751,0.083540,0.000000
84.810005,55.312202,-312.345245,0.008912,0.003287,0.083488,246.040970,12.533924,0.834876,-312.345245,0.083540,0.000000
85.030006,55.272362,-312.345245,0.008916,0.003287,0.083488,245.863739,12.524897,0.834876,-312.345245,0.083540,0.000000
85.250008,55.254860,-312.345245,0.008951,0.003287,0.083488,245.785889,12.520930,0.834876,-312.345245,0.083540,0.000000
85.470001,55.244431,-312.300751,0.008903,0.003287,0.083488,245.739502,12.518567,0.834876,-312.300751,0.083540,0.000000
85.690002,55.205330,-312.256287,0.008921,0.003287,0.083488,245.565567,12.509706,0.834876,-312.256287,0.083540,0.000000
85.910004,55.188576,-312.300751,0.008916,0.003287,0.083488,245.491043,12.505910,0.834876,-312.300751,0.083540,0.000000
86.130005,55.159157,-312.345245,0.008946,0.003287,0.083488,245.360184,12.499244,0.834876,-312.345245,0.083540,0.000000
86.350006,55.126015,-312.300751,0.008882,0.003287,0.083488,245.212753,12.491734,0.834876,-312.300751,0.083540,0.000000
86.570007,55.101814,-312.345245,0.008938,0.003287,0.083488,245.105118,12.486250,0.834876,-312.345245,0.083540,0.000000
86.790001,55.085060,-312.345245,0.008933,0.003287,0.083488,245.030579,12.482453,0.834876,-312.345245,0.083540,0.000000
87.010002,55.062714,-312.345245,0.008895,0.003287,0.083488,244.931183,12.477389,0.834876,-312.345245,0.083540,0.000000
87.230003,55.026596,-312.389709,0.008929,0.003287,0.083488,244.770523,12.469205,0.834876,-312.389709,0.083540,0.000000
87.450005,55.011703,-312.345245,0.008929,0.003287,0.083488,244.704285,12.465831,0.834876,-312.345245,0.083540,0.000000
87.670006,54.989357,-312.300751,0.008925,0.003287,0.083488,244.604874,12.460767,0.834876,-312.300751,0.083540,0.000000
87.890007,54.959938,-312.345245,0.008921,0.003287,0.083488,244.474014,12.454101,0.834876,-312.345245,0.083540,0.000000
88.110001,54.948769,-312.389709,0.008895,0.003287,0.083488,244.424332,12.451570,0.834876,-312.389709,0.083540,0.000000
88.330002,54.921211,-312.434204,0.008933,0.003287,0.083488,244.301743,12.445324,0.834876,-312.434204,0.083540,0.000000
88.550003,54.910416,-312.345245,0.008921,0.003287,0.083488,244.253723,12.442879,0.834876,-312.345245,0.083540,0.000000
88.770004,54.878387,-312.434204,0.008908,0.003287,0.083488,244.111252,12.435620,0.834876,-312.434204,0.083540,0.000000
88.990005,54.851578,-312.434204,0.008903,0.003287,0.083488,243.992004,12.429545,0.834876,-312.434204,0.083540,0.000000
89.210007,54.840034,-312.345245,0.008908,0.003287,0.083488,243.940659,12.426929,0.834876,-312.345245,0.083540,0.000000
89.430008,54.807640,-312.389709,0.008916,0.003287,0.083488,243.796555,12.419589,0.834876,-312.389709,0.083540,0.000000
89.650002,54.807266,-312.434204,0.008916,0.003287,0.083488,243.794891,12.419504,0.834876,-312.434204,0.083540,0.000000
89.870003,54.783432,-312.389709,0.008929,0.003287,0.083488,243.688873,12.414103,0.834876,-312.389709,0.083540,0.000000
90.090004,54.742104,-312.478668,0.008929,0.003287,0.083488,243.505035,12.404738,0.834876,-312.478668,0.083540,0.000000
90.310005,54.719757,-312.478668,0.008903,0.003287,0.083488,243.405640,12.399674,0.834876,-312.478668,0.083540,0.000000
90.530006,54.695557,-312.345245,0.008890,0.003287,0.083488,243.297989,12.394190,0.834876,-312.345245,0.083540,0.000000
90.750008,54.699654,-312.389709,0.008912,0.003287,0.083488,243.316208,12.395119,0.834876,-312.389709,0.083540,0.000000
90.970001,54.681030,-312.478668,0.008895,0.003287,0.083488,243.233368,12.390899,0.834876,-312.478668,0.083540,0.000000
91.100006,54.667999,-312.434204,0.008959,0.003287,0.083488,243.175400,12.387946,0.834876,-312.434204,0.083540,0.000000