File: Data/Compression Sample NH 10, 12, 15, 17 batch 3/AutoNoheating-12-3-3-240212_02122024_162358.csv
Time (sec),S:Load (lbs),S:HL1 (DIM),S:LVDT (in),S:Position (in),Ch:Position (mm),Ch:Load (N),Ch:Stress (MPa),Ch:Strain (mm/mm),Ch:HL1 (DIM),Set Point (),Cycles ()
0.110000,-0.001862,-155.371964,-0.000022,-0.000000,-0.000000,-0.008281,-0.000422,-0.000000,-155.371964,0.000173,0.000000
0.350000,-0.023834,-155.416443,-0.000004,0.000002,0.000052,-0.106020,-0.005401,0.000519,-155.416443,0.000433,0.000000
0.590000,0.009308,-155.327484,0.000030,0.000138,0.003504,0.041403,0.002109,0.035037,-155.327484,0.004423,0.000000
0.830000,0.011169,-155.460922,0.000155,0.000296,0.007519,0.049684,0.002531,0.075187,-155.460922,0.008429,0.000000
1.070000,-0.013779,-155.371964,0.000315,0.000448,0.011378,-0.061291,-0.003122,0.113778,-155.371964,0.012436,0.000000
1.310000,-0.004837,-155.416443,0.000448,0.000602,0.015298,-0.021516,-0.001096,0.152978,-155.416443,0.016425,0.000000
1.550000,-0.002235,-155.460922,0.000634,0.000754,0.019148,-0.009944,-0.000507,0.191482,-155.460922,0.020432,0.000000
1.790000,-0.013779,-155.460922,0.000815,0.000918,0.023311,-0.061291,-0.003122,0.233108,-155.460922,0.024421,0.000000
2.030000,-0.075966,-155.505402,0.000953,0.001076,0.027335,-0.337913,-0.017214,0.273349,-155.505402,0.028428,0.000000
2.270000,-0.016014,-155.416443,0.001112,0.001235,0.031376,-0.071234,-0.003629,0.313760,-155.416443,0.032417,0.000000
2.510000,0.025696,-155.460922,0.001281,0.001386,0.035192,0.114301,0.005823,0.351920,-155.460922,0.036424,0.000000
2.750000,0.007072,-155.505402,0.001449,0.001553,0.039450,0.031460,0.001603,0.394500,-155.505402,0.040412,0.000000
2.990000,-0.001862,-155.505402,0.001621,0.001708,0.043396,-0.008281,-0.000422,0.433957,-155.505402,0.044419,0.000000
3.230000,0.007446,-155.460922,0.001768,0.001866,0.047394,0.033123,0.001687,0.473937,-155.460922,0.048408,0.000000
3.470000,0.005585,-155.460922,0.001949,0.002013,0.051140,0.024842,0.001266,0.511404,-155.460922,0.052415,0.000000
3.710000,-0.008194,-155.460922,0.002108,0.002174,0.055225,-0.036449,-0.001857,0.552250,-155.460922,0.056404,0.000000
3.950000,-0.053619,-155.505402,0.002268,0.002337,0.059370,-0.238511,-0.012150,0.593702,-155.505402,0.060411,0.000000
4.190000,-0.026810,-155.460922,0.002440,0.002491,0.063273,-0.119255,-0.006075,0.632728,-155.460922,0.064400,0.000000
4.430000,0.011169,-155.549881,0.002591,0.002650,0.067305,0.049684,0.002531,0.673053,-155.549881,0.068407,0.000000
4.670000,0.017876,-155.549881,0.002777,0.002807,0.071295,0.079515,0.004051,0.712946,-155.549881,0.072396,0.000000
4.910000,-0.010056,-155.505402,0.002936,0.002969,0.075422,-0.044729,-0.002279,0.754224,-155.505402,0.076403,0.000000
5.150000,-0.016754,-155.505402,0.003078,0.003120,0.079256,-0.074526,-0.003797,0.792557,-155.505402,0.080392,0.000000
5.390000,0.008568,-155.460922,0.003294,0.003284,0.083418,0.038112,0.001941,0.834183,-155.460922,0.084398,0.000000
5.630000,-0.010056,-155.505402,0.003423,0.003432,0.087182,-0.044729,-0.002279,0.871820,-155.505402,0.088405,0.000000
5.870000,-0.005585,-155.549881,0.003570,0.003597,0.091353,-0.024842,-0.001266,0.913534,-155.549881,0.092394,0.000000
6.110000,-0.045799,-155.505402,0.003768,0.003751,0.095273,-0.203725,-0.010378,0.952734,-155.505402,0.096401,0.000000
6.350000,-0.006699,-155.638855,0.003919,0.003909,0.099297,-0.029797,-0.001518,0.992971,-155.638855,0.100390,0.000000
6.590000,0.033890,-155.505402,0.004096,0.004066,0.103269,0.150749,0.007680,1.032694,-155.505402,0.104396,0.000000
6.830000,0.004845,-155.549881,0.004260,0.004227,0.107371,0.021550,0.001098,1.073710,-155.549881,0.108386,0.000000
7.070000,-0.015266,-155.594360,0.004411,0.004383,0.111326,-0.067908,-0.003459,1.113259,-155.594360,0.112392,0.000000
7.310000,0.004097,-155.594360,0.004605,0.004542,0.115358,0.018224,0.000928,1.153583,-155.594360,0.116382,0.000000
7.550000,0.030533,-155.638855,0.004751,0.004693,0.119200,0.135817,0.006919,1.192000,-155.638855,0.120388,0.000000
7.790000,-0.000748,-155.549881,0.004911,0.004859,0.123415,-0.003326,-0.000169,1.234148,-155.549881,0.124377,0.000000
8.030001,0.002235,-155.594360,0.005070,0.005011,0.127291,0.009944,0.000507,1.272913,-155.594360,0.128384,0.000000
8.270000,0.530258,-155.594360,0.005238,0.005170,0.131315,2.358706,0.120158,1.313154,-155.594360,0.132373,0.000000
8.510000,0.686279,-155.594360,0.005226,-0.000010,-0.000260,3.052723,0.155513,-0.002600,-155.594360,-0.000044,0.000000
8.750000,0.656120,-155.683334,0.005273,-0.000010,-0.000260,2.918569,0.148679,-0.002600,-155.683334,-0.000044,0.000000
8.990001,0.658730,-155.594360,0.005277,-0.000010,-0.000260,2.930175,0.149270,-0.002600,-155.594360,0.000191,0.000000
9.230000,0.615906,-155.638855,0.005251,-0.000010,-0.000260,2.739686,0.139566,-0.002600,-155.638855,0.000590,0.000000
9.470000,0.729851,-155.683334,0.005243,0.000008,0.000199,3.246538,0.165387,0.001995,-155.683334,0.000997,0.000000
9.710000,0.828529,-155.594360,0.005256,0.000017,0.000434,3.685483,0.187747,0.004337,-155.594360,0.001396,0.000000
9.950001,1.015831,-155.638855,0.005290,0.000038,0.000962,4.518642,0.230191,0.009625,-155.638855,0.001795,0.000000
10.190001,1.156219,-155.638855,0.005290,0.000054,0.001370,5.143121,0.262003,0.013701,-155.638855,0.002194,0.000000
10.430000,1.279846,-155.683334,0.005307,0.000070,0.001769,5.693040,0.290017,0.017691,-155.683334,0.002593,0.000000
10.670000,1.412033,-155.638855,0.005325,0.000084,0.002125,6.281037,0.319971,0.021248,-155.638855,0.002992,0.000000
10.910001,1.605301,-155.638855,0.005325,0.000100,0.002541,7.140735,0.363766,0.025408,-155.638855,0.003391,0.000000
11.150001,1.756485,-155.683334,0.005372,0.000113,0.002879,7.813235,0.398025,0.028792,-155.683334,0.003799,0.000000
11.390000,1.931870,-155.727814,0.005394,0.000128,0.003261,8.593385,0.437768,0.032607,-155.727814,0.004197,0.000000
11.630000,2.044327,-155.727814,0.005385,0.000142,0.003599,9.093619,0.463251,0.035991,-155.727814,0.004596,0.000000
11.870001,2.306473,-155.683334,0.005398,0.000166,0.004224,10.259704,0.522654,0.042236,-155.683334,0.004995,0.000000
12.110001,2.459892,-155.772293,0.005424,0.000181,0.004605,10.942147,0.557420,0.046051,-155.772293,0.005394,0.000000
12.350000,2.540329,-155.683334,0.005411,0.000196,0.004969,11.299948,0.575647,0.049692,-155.683334,0.005793,0.000000
12.590000,2.721298,-155.772293,0.005489,0.000212,0.005377,12.104939,0.616655,0.053768,-155.772293,0.006192,0.000000
12.830001,2.895943,-155.727814,0.005467,0.000225,0.005724,12.881797,0.656230,0.057235,-155.727814,0.006591,0.000000
13.070001,3.089951,-155.683334,0.005467,0.000241,0.006114,13.744786,0.700193,0.061141,-155.683334,0.006999,0.000000
13.310000,3.200172,-155.727814,0.005489,0.000254,0.006461,14.235078,0.725169,0.064608,-155.727814,0.007398,0.000000
13.550000,3.355820,-155.772293,0.005506,0.000270,0.006868,14.927431,0.760440,0.068684,-155.772293,0.007797,0.000000
13.790001,3.549454,-155.772293,0.005514,0.000288,0.007319,15.788759,0.804318,0.073192,-155.772293,0.008195,0.000000
14.030001,3.632866,-155.816772,0.005532,0.000303,0.007684,16.159794,0.823219,0.076837,-155.816772,0.008594,0.000000
14.270000,3.711067,-155.772293,0.005545,0.000312,0.007935,16.507652,0.840940,0.079350,-155.772293,0.008993,0.000000
14.510000,3.903580,-155.727814,0.005575,0.000336,0.008533,17.363989,0.884564,0.085334,-155.727814,0.009392,0.000000
14.750001,4.077110,-155.727814,0.005575,0.000352,0.008941,18.135893,0.923886,0.089411,-155.727814,0.009791,0.000000
14.990001,4.215630,-155.727814,0.005588,0.000370,0.009401,18.752056,0.955275,0.094005,-155.727814,0.010198,0.000000
15.230000,4.241692,-155.727814,0.005601,0.000381,0.009670,18.867987,0.961181,0.096696,-155.727814,0.010597,0.000000
15.470000,4.346703,-155.816772,0.005618,0.000394,0.010008,19.335098,0.984977,0.100076,-155.816772,0.010996,0.000000
15.710001,4.536613,-155.772293,0.005639,0.000413,0.010493,20.179865,1.028011,0.104932,-155.772293,0.011395,0.000000
15.950001,4.654655,-155.861252,0.005661,0.000431,0.010944,20.704941,1.054760,0.109444,-155.861252,0.011794,0.000000
16.190001,4.732109,-155.772293,0.005683,0.000448,0.011378,21.049473,1.072311,0.113782,-155.772293,0.012193,0.000000
16.430000,4.810310,-155.816772,0.005713,0.000464,0.011777,21.397329,1.090032,0.117771,-155.816772,0.012592,0.000000
16.670000,4.875847,-155.816772,0.005700,0.000477,0.012106,21.688850,1.104883,0.121064,-155.816772,0.012991,0.000000
16.910002,5.004684,-155.816772,0.005734,0.000494,0.012540,22.261948,1.134078,0.125401,-155.816772,0.013399,0.000000
17.150002,5.156990,-155.861252,0.005721,0.000510,0.012965,22.939438,1.168591,0.129652,-155.861252,0.013797,0.000000
17.390001,5.177467,-155.816772,0.005764,0.000523,0.013277,23.030525,1.173231,0.132774,-155.816772,0.014196,0.000000
17.630001,5.284714,-155.861252,0.005782,0.000542,0.013763,23.507582,1.197533,0.137630,-155.861252,0.014595,0.000000
17.870001,5.438499,-155.816772,0.005790,0.000561,0.014257,24.191654,1.232382,0.142573,-155.816772,0.014994,0.000000
18.110001,5.418388,-155.905731,0.005851,0.000576,0.014630,24.102196,1.227824,0.146301,-155.905731,0.015393,0.000000
18.350000,5.455254,-155.905731,0.005812,0.000588,0.014942,24.266180,1.236178,0.149424,-155.905731,0.015792,0.000000
18.590000,5.557289,-155.772293,0.005846,0.000607,0.015411,24.720057,1.259300,0.154106,-155.772293,0.016191,0.000000
18.830002,5.679428,-155.905731,0.005842,0.000623,0.015818,25.263357,1.286977,0.158182,-155.905731,0.016599,0.000000
19.070002,5.738258,-155.861252,0.005902,0.000638,0.016200,25.525047,1.300308,0.161997,-155.861252,0.016998,0.000000
19.310001,5.686127,-155.905731,0.005907,0.000646,0.016408,25.293156,1.288495,0.164079,-155.905731,0.017397,0.000000
19.550001,5.927422,-155.950211,0.005915,0.000668,0.016963,26.366488,1.343173,0.169628,-155.950211,0.017795,0.000000
19.790001,5.993706,-155.861252,0.005941,0.000685,0.017388,26.661335,1.358193,0.173878,-155.861252,0.018194,0.000000
20.030001,6.029083,-155.905731,0.005915,0.000702,0.017830,26.818701,1.366210,0.178303,-155.905731,0.018593,0.000000
20.270000,6.061104,-155.950211,0.005963,0.000715,0.018160,26.961136,1.373466,0.181595,-155.950211,0.018992,0.000000
20.510000,6.046211,-155.905731,0.005967,0.000725,0.018420,26.894892,1.370091,0.184199,-155.905731,0.019391,0.000000
20.750002,6.254738,-155.950211,0.005993,0.000748,0.018992,27.822464,1.417344,0.189922,-155.950211,0.019799,0.000000
20.990002,6.335915,-155.905731,0.006027,0.000763,0.019374,28.183556,1.435739,0.193737,-155.905731,0.020198,0.000000
21.230001,6.302032,-155.950211,0.006015,0.000773,0.019643,28.032841,1.428061,0.196428,-155.950211,0.020597,0.000000
21.470001,6.424911,-155.950211,0.006040,0.000789,0.020050,28.579433,1.455906,0.200501,-155.950211,0.020996,0.000000
21.710001,6.590248,-155.950211,0.006062,0.000808,0.020527,29.314888,1.493372,0.205274,-155.950211,0.021394,0.000000
21.950001,6.642380,-155.950211,0.006071,0.000825,0.020943,29.546782,1.505185,0.209433,-155.950211,0.021793,0.000000
22.190001,6.713875,-155.950211,0.006109,0.000842,0.021394,29.864807,1.521386,0.213945,-155.950211,0.022192,0.000000
22.430000,6.738083,-155.950211,0.006092,0.000856,0.021741,29.972490,1.526871,0.217412,-155.950211,0.022591,0.000000
22.670002,6.841225,-155.994690,0.006127,0.000874,0.022192,30.431288,1.550244,0.221924,-155.994690,0.022999,0.000000
22.910002,6.862823,-155.905731,0.006161,0.000886,0.022513,30.527363,1.555138,0.225133,-155.905731,0.023398,0.000000
23.150002,6.836761,-156.039169,0.006140,0.000899,0.022834,30.411434,1.549232,0.228339,-156.039169,0.023797,0.000000
23.390001,7.118645,-156.039169,0.006165,0.000919,0.023354,31.665314,1.613108,0.233543,-156.039169,0.024196,0.000000
23.630001,7.146576,-156.039169,0.006161,0.000934,0.023736,31.789557,1.619437,0.237358,-156.039169,0.024595,0.000000
23.870001,7.183067,-155.994690,0.006204,0.000949,0.024100,31.951880,1.627706,0.241003,-155.994690,0.024994,0.000000
24.110001,7.263870,-156.039169,0.006217,0.000967,0.024551,32.311310,1.646016,0.245511,-156.039169,0.025392,0.000000
24.350000,7.181946,-156.039169,0.006226,0.000976,0.024794,31.946890,1.627452,0.247941,-156.039169,0.025800,0.000000
24.590002,7.348770,-156.039169,0.006239,0.000995,0.025262,32.688961,1.665255,0.252623,-156.039169,0.026199,0.000000
24.830002,7.398666,-156.083664,0.006239,0.001008,0.025592,32.910912,1.676562,0.255919,-156.083664,0.026598,0.000000
25.070002,7.380798,-155.994690,0.006273,0.001017,0.025843,32.831432,1.672513,0.258433,-155.994690,0.026997,0.000000
25.310001,7.689865,-156.083664,0.006273,0.001044,0.026511,34.206230,1.742548,0.265109,-156.083664,0.027396,0.000000
25.550001,7.888336,-156.083664,0.006291,0.001065,0.027040,35.089073,1.787523,0.270400,-156.083664,0.027795,0.000000
25.790001,7.787796,-155.994690,0.006329,0.001075,0.027300,34.641846,1.764740,0.273004,-155.994690,0.028194,0.000000
26.030001,7.864510,-156.083664,0.006321,0.001092,0.027743,34.983086,1.782123,0.277425,-156.083664,0.028593,0.000000
26.270000,7.859665,-156.128143,0.006355,0.001106,0.028090,34.961536,1.781026,0.280896,-156.128143,0.029000,0.000000
26.510002,7.936745,-156.083664,0.006390,0.001121,0.028480,35.304405,1.798492,0.284798,-156.083664,0.029399,0.000000
26.750002,7.927063,-156.083664,0.006368,0.001131,0.028731,35.261337,1.796298,0.287311,-156.083664,0.029798,0.000000
26.990002,7.945686,-156.039169,0.006390,0.001144,0.029061,35.344177,1.800518,0.290608,-156.039169,0.030197,0.000000
27.230001,8.218262,-156.128143,0.006411,0.001165,0.029590,36.556652,1.862285,0.295896,-156.128143,0.030596,0.000000
27.470001,8.461044,-156.083664,0.006450,0.001187,0.030162,37.636604,1.917300,0.301622,-156.083664,0.030995,0.000000
27.710001,8.484505,-156.083664,0.006463,0.001204,0.030579,37.740963,1.922616,0.305785,-156.083664,0.031393,0.000000
27.950001,8.401466,-156.172623,0.006459,0.001217,0.030908,37.371590,1.903800,0.309078,-156.172623,0.031792,0.000000
28.190001,8.445038,-156.128143,0.006485,0.001230,0.031237,37.565403,1.913673,0.312375,-156.128143,0.032200,0.000000
28.430002,8.605904,-156.128143,0.006480,0.001247,0.031671,38.280972,1.950126,0.316712,-156.128143,0.032599,0.000000
28.670002,8.679626,-156.128143,0.006493,0.001263,0.032078,38.608906,1.966831,0.320785,-156.128143,0.032998,0.000000
28.910002,8.685585,-156.083664,0.006489,0.001277,0.032434,38.635410,1.968182,0.324343,-156.083664,0.033397,0.000000
29.150002,8.687447,-156.217102,0.006502,0.001289,0.032747,38.643692,1.968603,0.327465,-156.217102,0.033796,0.000000
29.390001,8.996147,-156.172623,0.006541,0.001312,0.033328,40.016861,2.038556,0.333275,-156.172623,0.034195,0.000000
29.630001,8.957420,-156.261581,0.006562,0.001326,0.033692,39.844597,2.029780,0.336916,-156.261581,0.034594,0.000000
29.870001,9.068756,-156.128143,0.006592,0.001345,0.034151,40.339844,2.055009,0.341515,-156.128143,0.034992,0.000000
30.110001,8.907898,-156.128143,0.006618,0.001352,0.034342,39.624310,2.018559,0.343422,-156.128143,0.035400,0.000000
30.350002,9.236702,-156.217102,0.006614,0.001372,0.034854,41.086903,2.093066,0.348540,-156.217102,0.035799,0.000000
30.590002,9.302979,-156.261581,0.006644,0.001388,0.035261,41.381714,2.108085,0.352612,-156.261581,0.036198,0.000000
30.830002,9.375221,-156.261581,0.006635,0.001404,0.035669,41.703068,2.124455,0.356688,-156.261581,0.036597,0.000000
31.070002,9.327934,-156.217102,0.006653,0.001416,0.035972,41.492725,2.113740,0.359724,-156.217102,0.036996,0.000000
31.310001,9.629921,-156.172623,0.006679,0.001439,0.036553,42.836029,2.182171,0.365534,-156.172623,0.037395,0.000000
31.550001,9.674606,-156.261581,0.006713,0.001455,0.036952,43.034798,2.192297,0.369523,-156.261581,0.037794,0.000000
31.790001,9.658966,-156.217102,0.006722,0.001470,0.037343,42.965225,2.188753,0.373429,-156.217102,0.038193,0.000000
32.030003,9.661575,-156.217102,0.006722,0.001484,0.037690,42.976833,2.189344,0.376896,-156.217102,0.038600,0.000000
32.270000,9.835846,-156.261581,0.006739,0.001500,0.038106,43.752029,2.228834,0.381059,-156.261581,0.038999,0.000000
32.510002,9.837708,-156.172623,0.006748,0.001514,0.038461,43.760307,2.229256,0.384613,-156.172623,0.039398,0.000000
32.750000,9.952774,-156.306061,0.006765,0.001530,0.038852,44.272152,2.255331,0.388516,-156.306061,0.039797,0.000000
32.990002,9.916649,-156.261581,0.006791,0.001544,0.039207,44.111458,2.247145,0.392073,-156.261581,0.040196,0.000000
33.230003,10.369087,-156.306061,0.006808,0.001567,0.039797,46.124004,2.349669,0.397970,-156.306061,0.040595,0.000000
33.470001,10.353813,-156.306061,0.006834,0.001582,0.040187,46.056061,2.346207,0.401873,-156.306061,0.040994,0.000000
33.710003,10.343765,-156.261581,0.006838,0.001597,0.040569,46.011364,2.343931,0.405688,-156.261581,0.041393,0.000000
33.950001,10.400360,-156.350540,0.006834,0.001613,0.040959,46.263111,2.356755,0.409590,-156.350540,0.041800,0.000000
34.190002,10.461060,-156.261581,0.006868,0.001628,0.041341,46.533115,2.370510,0.413405,-156.261581,0.042199,0.000000
34.430000,10.505371,-156.261581,0.006885,0.001642,0.041705,46.730225,2.380551,0.417050,-156.261581,0.042598,0.000000
34.670002,10.493828,-156.306061,0.006877,0.001654,0.042009,46.678879,2.377935,0.420085,-156.306061,0.042997,0.000000
34.910000,10.690811,-156.306061,0.006924,0.001673,0.042494,47.555103,2.422572,0.424942,-156.306061,0.043396,0.000000
35.150002,10.866943,-156.350540,0.006907,0.001690,0.042919,48.338577,2.462484,0.429188,-156.350540,0.043795,0.000000
35.390003,10.884445,-156.350540,0.006933,0.001702,0.043240,48.416431,2.466451,0.432398,-156.350540,0.044194,0.000000
35.630001,10.846092,-156.350540,0.006933,0.001718,0.043630,48.245827,2.457760,0.436300,-156.350540,0.044593,0.000000
35.870003,11.209160,-156.350540,0.006967,0.001735,0.044081,49.860832,2.540032,0.440812,-156.350540,0.045001,0.000000
36.110001,11.414703,-156.350540,0.006980,0.001755,0.044567,50.775135,2.586609,0.445668,-156.350540,0.045399,0.000000
36.350002,11.451942,-156.350540,0.006998,0.001769,0.044940,50.940784,2.595047,0.449396,-156.350540,0.045798,0.000000
36.590000,11.375237,-156.395020,0.007015,0.001782,0.045261,50.599579,2.577665,0.452605,-156.395020,0.046197,0.000000
36.830002,11.409492,-156.350540,0.007019,0.001797,0.045633,50.751957,2.585428,0.456333,-156.350540,0.046596,0.000000
37.070004,11.593071,-156.439499,0.007028,0.001813,0.046041,51.568554,2.627028,0.460410,-156.439499,0.046995,0.000000
37.310001,11.763245,-156.395020,0.007084,0.001831,0.046509,52.325527,2.665589,0.465092,-156.395020,0.047394,0.000000
37.550003,11.889107,-156.395020,0.007036,0.001848,0.046934,52.885387,2.694110,0.469342,-156.395020,0.047801,0.000000
37.790001,12.017578,-156.395020,0.007105,0.001864,0.047333,53.456856,2.723222,0.473331,-156.395020,0.048200,0.000000
38.030003,12.032471,-156.439499,0.007114,0.001879,0.047723,53.523102,2.726597,0.477234,-156.439499,0.048599,0.000000
38.270000,12.276375,-156.395020,0.007114,0.001897,0.048175,54.608044,2.781866,0.481745,-156.395020,0.048998,0.000000
38.510002,12.427933,-156.395020,0.007144,0.001913,0.048599,55.282207,2.816210,0.485992,-156.395020,0.049397,0.000000
38.750000,12.328880,-156.439499,0.007136,0.001927,0.048946,54.841599,2.793764,0.489463,-156.439499,0.049796,0.000000
38.990002,12.605179,-156.439499,0.007166,0.001945,0.049414,56.070637,2.856374,0.494145,-156.439499,0.050195,0.000000
39.230003,12.735886,-156.439499,0.007187,0.001962,0.049831,56.652050,2.885993,0.498308,-156.439499,0.050594,0.000000
39.470001,12.689339,-156.439499,0.007196,0.001975,0.050169,56.444996,2.875445,0.501692,-156.439499,0.051001,0.000000
39.710003,12.685982,-156.439499,0.007213,0.001989,0.050525,56.430065,2.874685,0.505246,-156.439499,0.051400,0.000000
39.950001,13.021492,-156.439499,0.007235,0.002008,0.051001,57.922489,2.950712,0.510015,-156.439499,0.051799,0.000000
40.190002,13.120544,-156.439499,0.007256,0.002023,0.051392,58.363098,2.973158,0.513917,-156.439499,0.052198,0.000000
40.430000,13.171562,-156.483978,0.007265,0.002036,0.051721,58.590034,2.984719,0.517213,-156.483978,0.052597,0.000000
40.670002,13.035645,-156.483978,0.007269,0.002047,0.051999,57.985443,2.953919,0.519988,-156.483978,0.052996,0.000000
40.910004,13.459030,-156.439499,0.007299,0.002067,0.052510,59.868755,3.049860,0.525105,-156.439499,0.053395,0.000000
41.150002,13.718575,-156.528473,0.007308,0.002088,0.053031,61.023266,3.108673,0.530309,-156.528473,0.053794,0.000000
41.390003,13.760277,-156.483978,0.007321,0.002103,0.053412,61.208767,3.118123,0.534124,-156.483978,0.054202,0.000000
41.630001,13.706284,-156.528473,0.007334,0.002114,0.053707,60.968594,3.105888,0.537073,-156.528473,0.054601,0.000000
41.870003,13.755814,-156.528473,0.007343,0.002131,0.054132,61.188915,3.117112,0.541323,-156.528473,0.054999,0.000000
42.110001,14.144196,-156.483978,0.007373,0.002148,0.054549,62.916523,3.205121,0.545487,-156.483978,0.055398,0.000000
42.350002,14.295006,-156.572952,0.007377,0.002166,0.055008,63.587360,3.239295,0.550081,-156.572952,0.055797,0.000000
42.590000,14.065254,-156.528473,0.007424,0.002173,0.055199,62.565376,3.187232,0.551989,-156.528473,0.056196,0.000000
42.830002,14.591789,-156.617432,0.007411,0.002195,0.055745,64.907516,3.306547,0.557454,-156.617432,0.056595,0.000000
43.070004,14.626045,-156.572952,0.007403,0.002209,0.056101,65.059898,3.314309,0.561009,-156.572952,0.056994,0.000000
43.310001,14.814095,-156.617432,0.007442,0.002226,0.056552,65.896385,3.356922,0.565516,-156.617432,0.057402,0.000000
43.550003,15.063957,-156.572952,0.007442,0.002243,0.056977,67.007828,3.413541,0.569767,-156.572952,0.057801,0.000000
43.790001,15.058746,-156.617432,0.007450,0.002257,0.057324,66.984650,3.412361,0.573237,-156.617432,0.058200,0.000000
44.030003,15.401695,-156.483978,0.007493,0.002277,0.057844,68.510162,3.490074,0.578438,-156.483978,0.058598,0.000000
44.270000,15.311211,-156.572952,0.007506,0.002289,0.058130,68.107666,3.469570,0.581303,-156.572952,0.058997,0.000000
44.510002,15.324989,-156.528473,0.007519,0.002301,0.058433,68.168961,3.472692,0.584335,-156.528473,0.059396,0.000000
44.750004,15.915573,-156.572952,0.007528,0.002323,0.059006,70.796005,3.606520,0.590061,-156.572952,0.059795,0.000000
44.990002,15.997864,-156.617432,0.007532,0.002338,0.059388,71.162048,3.625168,0.593877,-156.617432,0.060194,0.000000
45.230003,15.983719,-156.617432,0.007537,0.002352,0.059743,71.099129,3.621962,0.597431,-156.617432,0.060602,0.000000
45.470001,16.160965,-156.661911,0.007558,0.002366,0.060099,71.887566,3.662127,0.600988,-156.661911,0.061001,0.000000
45.710003,16.198578,-156.617432,0.007584,0.002380,0.060454,72.054871,3.670650,0.604542,-156.617432,0.061400,0.000000
45.950001,16.474876,-156.617432,0.007584,0.002398,0.060897,73.283913,3.733260,0.608967,-156.617432,0.061799,0.000000
46.190002,16.534081,-156.661911,0.007614,0.002411,0.061235,73.547264,3.746676,0.612347,-156.661911,0.062198,0.000000
46.430000,16.366516,-156.661911,0.007614,0.002417,0.061382,72.801903,3.708706,0.613823,-156.661911,0.062596,0.000000
46.670002,17.578217,-156.661911,0.007640,0.002448,0.062189,78.191811,3.983281,0.621889,-156.661911,0.062995,0.000000
46.910004,17.657158,-156.572952,0.007675,0.002464,0.062596,78.542961,4.001169,0.625965,-156.572952,0.063394,0.000000
47.150002,17.584175,-156.661911,0.007653,0.002477,0.062926,78.218315,3.984631,0.629258,-156.661911,0.063802,0.000000
47.390003,17.777061,-156.750870,0.007700,0.002494,0.063360,79.076317,4.028340,0.633595,-156.750870,0.064201,0.000000
47.630001,17.841110,-156.617432,0.007722,0.002508,0.063698,79.361221,4.042853,0.636979,-156.617432,0.064599,0.000000
47.870003,18.018730,-156.795349,0.007709,0.002521,0.064045,80.151314,4.083103,0.640446,-156.795349,0.064998,0.000000
48.110001,17.887283,-156.661911,0.007713,0.002531,0.064296,79.566612,4.053316,0.642963,-156.661911,0.065397,0.000000
48.350002,18.313652,-156.706390,0.007735,0.002549,0.064756,81.463196,4.149933,0.647558,-156.706390,0.065796,0.000000
48.590004,18.591812,-156.706390,0.007752,0.002564,0.065137,82.700508,4.212965,0.651373,-156.706390,0.066195,0.000000
48.830002,19.354431,-156.706390,0.007778,0.002589,0.065753,86.092812,4.385777,0.657531,-156.706390,0.066594,0.000000
49.070004,19.575249,-156.750870,0.007795,0.002605,0.066178,87.075058,4.435815,0.661781,-156.750870,0.067002,0.000000
49.310001,19.477318,-156.750870,0.007791,0.002618,0.066499,86.639435,4.413623,0.664987,-156.750870,0.067401,0.000000
49.550003,19.456459,-156.706390,0.007804,0.002630,0.066811,86.546654,4.408896,0.668110,-156.706390,0.067800,0.000000
49.790001,19.812447,-156.750870,0.007838,0.002648,0.067262,88.130165,4.489564,0.672621,-156.750870,0.068199,0.000000
50.030003,20.062683,-156.750870,0.007847,0.002664,0.067661,89.243271,4.546269,0.676611,-156.750870,0.068597,0.000000
50.270004,20.235092,-156.795349,0.007869,0.002675,0.067956,90.010185,4.585337,0.679559,-156.795349,0.068996,0.000000
50.510002,20.353882,-156.750870,0.007894,0.002690,0.068320,90.538589,4.612256,0.683200,-156.750870,0.069395,0.000000
50.750004,21.367477,-156.795349,0.007881,0.002716,0.068979,95.047287,4.841939,0.689790,-156.795349,0.069794,0.000000
50.990002,21.353699,-156.750870,0.007912,0.002728,0.069283,94.985992,4.838818,0.692825,-156.750870,0.070202,0.000000
51.230003,21.647125,-156.795349,0.007912,0.002744,0.069690,96.291222,4.905309,0.696901,-156.795349,0.070601,0.000000
51.470001,21.509720,-156.795349,0.007912,0.002754,0.069959,95.680016,4.874172,0.699592,-156.795349,0.071000,0.000000
51.710003,22.115944,-156.795349,0.007955,0.002774,0.070462,98.376633,5.011545,0.704623,-156.795349,0.071399,0.000000
51.950001,22.424271,-156.795349,0.007959,0.002789,0.070852,99.748138,5.081412,0.708525,-156.795349,0.071798,0.000000
52.190002,22.648064,-156.795349,0.007959,0.002805,0.071251,100.743622,5.132124,0.712514,-156.795349,0.072196,0.000000
52.430004,22.767601,-156.795349,0.007985,0.002817,0.071563,101.275345,5.159212,0.715633,-156.795349,0.072595,0.000000
52.670002,23.881363,-156.839828,0.008006,0.002843,0.072205,106.229607,5.411594,0.722052,-156.839828,0.073003,0.000000
52.910004,23.913017,-156.795349,0.008011,0.002857,0.072569,106.370415,5.418767,0.725693,-156.795349,0.073402,0.000000
53.150002,24.077972,-156.795349,0.008024,0.002869,0.072882,107.104172,5.456146,0.728816,-156.795349,0.073801,0.000000
53.390003,24.237350,-156.884308,0.008050,0.002883,0.073229,107.813118,5.492262,0.732286,-156.884308,0.074200,0.000000
53.630001,24.692390,-156.839828,0.008067,0.002899,0.073636,109.837242,5.595376,0.736363,-156.839828,0.074599,0.000000
53.870003,24.874107,-156.884308,0.008063,0.002913,0.073992,110.645554,5.636553,0.739917,-156.884308,0.074998,0.000000
54.110004,25.466553,-156.839828,0.008088,0.002932,0.074477,113.280884,5.770803,0.744773,-156.839828,0.075397,0.000000
54.350002,25.697800,-156.795349,0.008088,0.002944,0.074772,114.309525,5.823205,0.747721,-156.795349,0.075796,0.000000
54.590004,26.683838,-156.839828,0.008114,0.002967,0.075371,118.695641,6.046644,0.753705,-156.839828,0.076203,0.000000
54.830002,26.944870,-156.884308,0.008110,0.002981,0.075726,119.856766,6.105795,0.757263,-156.884308,0.076602,0.000000
55.070004,27.178719,-156.928802,0.008149,0.002996,0.076099,120.896980,6.158785,0.760991,-156.928802,0.077001,0.000000
55.310001,27.523163,-156.795349,0.008153,0.003011,0.076489,122.429146,6.236838,0.764893,-156.795349,0.077400,0.000000
55.550003,27.911552,-156.884308,0.008166,0.003028,0.076914,124.156784,6.324848,0.769144,-156.884308,0.077799,0.000000
55.790001,28.073158,-156.928802,0.008179,0.003042,0.077261,124.875648,6.361469,0.772611,-156.928802,0.078198,0.000000
56.030003,28.317436,-156.884308,0.008188,0.003053,0.077547,125.962250,6.416822,0.775472,-156.884308,0.078597,0.000000
56.270004,29.221184,-156.928802,0.008205,0.003074,0.078076,129.982315,6.621615,0.780763,-156.928802,0.078996,0.000000
56.510002,29.661331,-156.928802,0.008205,0.003091,0.078510,131.940186,6.721354,0.785101,-156.928802,0.079403,0.000000
56.750004,29.985664,-156.973282,0.008239,0.003104,0.078848,133.382904,6.794848,0.788481,-156.973282,0.079802,0.000000
56.990002,30.229195,-156.973282,0.008248,0.003121,0.079264,134.466171,6.850034,0.792644,-156.973282,0.080201,0.000000
57.230003,30.995911,-156.884308,0.008261,0.003136,0.079646,137.876694,7.023774,0.796459,-156.884308,0.080600,0.000000
57.470001,31.734329,-156.973282,0.008278,0.003155,0.080132,141.161346,7.191102,0.801315,-156.973282,0.080999,0.000000
57.710003,32.173729,-156.973282,0.008291,0.003169,0.080505,143.115891,7.290671,0.805047,-156.973282,0.081398,0.000000
57.950005,32.381134,-156.928802,0.008252,0.003181,0.080808,144.038483,7.337670,0.808083,-156.928802,0.081797,0.000000
58.190002,32.964645,-157.062241,0.008282,0.003201,0.081303,146.634064,7.469895,0.813026,-157.062241,0.082196,0.000000
58.430004,33.389153,-156.973282,0.008308,0.003215,0.081658,148.522369,7.566090,0.816580,-156.973282,0.082603,0.000000
58.670002,34.099266,-156.973282,0.008304,0.003233,0.082126,151.681107,7.727004,0.821262,-156.973282,0.083002,0.000000
58.910004,34.712189,-156.928802,0.008343,0.003248,0.082508,154.407532,7.865894,0.825077,-156.928802,0.083401,0.000000
59.150002,35.193665,-157.017761,0.008321,0.003263,0.082872,156.549240,7.974998,0.828722,-157.017761,0.083800,0.000000
59.390003,35.780151,-157.062241,0.008382,0.003280,0.083323,159.158066,8.107898,0.833229,-157.062241,0.084199,0.000000
59.630001,36.232956,-157.017761,0.008369,0.003295,0.083704,161.172241,8.210505,0.837045,-157.017761,0.084598,0.000000
59.870003,37.140060,-157.017761,0.008360,0.003313,0.084138,165.207245,8.416058,0.841382,-157.017761,0.084997,0.000000
60.110004,37.317680,-157.017761,0.008377,0.003327,0.084511,165.997330,8.456307,0.845110,-157.017761,0.085396,0.000000
60.350002,38.398300,-156.973282,0.008412,0.003346,0.084997,170.804169,8.701180,0.849966,-156.973282,0.085803,0.000000
60.590004,39.080864,-157.017761,0.008412,0.003363,0.085422,173.840363,8.855850,0.854217,-157.017761,0.086202,0.000000
60.830002,39.340782,-157.062241,0.008412,0.003375,0.085717,174.996536,8.914748,0.857165,-157.062241,0.086601,0.000000
61.070004,39.839386,-157.017761,0.008451,0.003390,0.086098,177.214447,9.027734,0.860980,-157.017761,0.087000,0.000000
61.310001,40.790428,-157.062241,0.008468,0.003409,0.086592,181.444885,9.243243,0.865923,-157.062241,0.087399,0.000000
61.550003,41.338188,-157.017761,0.008446,0.003424,0.086974,183.881439,9.367368,0.869742,-157.017761,0.087798,0.000000
61.790005,41.902702,-157.151199,0.008472,0.003438,0.087330,186.392532,9.495288,0.873296,-157.151199,0.088197,0.000000
62.030003,41.937706,-157.017761,0.008494,0.003446,0.087529,186.548233,9.503221,0.875291,-157.017761,0.088596,0.000000
62.270004,43.386978,-157.062241,0.008498,0.003471,0.088162,192.994919,9.831630,0.881623,-157.062241,0.089003,0.000000
62.510002,44.133957,-157.106720,0.008507,0.003487,0.088578,196.317642,10.000897,0.885783,-157.106720,0.089402,0.000000
62.750004,44.836998,-157.017761,0.008507,0.003502,0.088951,199.444931,10.160209,0.889515,-157.017761,0.089801,0.000000
62.990002,45.337463,-157.151199,0.008524,0.003515,0.089272,201.671112,10.273617,0.892720,-157.151199,0.090200,0.000000
63.230003,45.991722,-157.062241,0.008545,0.003533,0.089741,204.581390,10.421873,0.897406,-157.062241,0.090599,0.000000
63.470001,46.946114,-157.151199,0.008545,0.003548,0.090131,208.826736,10.638142,0.901308,-157.151199,0.090998,0.000000
63.710003,47.915024,-157.106720,0.008567,0.003566,0.090564,213.136673,10.857699,0.905642,-157.106720,0.091397,0.000000
63.950005,47.848373,-157.062241,0.008558,0.003572,0.090738,212.840195,10.842597,0.907379,-157.062241,0.091796,0.000000
64.190002,48.870537,-157.151199,0.008567,0.003593,0.091267,217.387009,11.074222,0.912667,-157.151199,0.092203,0.000000
64.430000,49.895676,-157.106720,0.008593,0.003609,0.091674,221.947052,11.306521,0.916743,-157.106720,0.092602,0.000000
64.670006,50.853790,-157.151199,0.008593,0.003628,0.092143,226.208954,11.523634,0.921429,-157.151199,0.093001,0.000000
64.910004,51.695724,-157.151199,0.008614,0.003642,0.092507,229.954071,11.714418,0.925070,-157.151199,0.093400,0.000000
65.150002,52.313866,-157.151199,0.008619,0.003658,0.092906,232.703690,11.854491,0.929059,-157.151199,0.093799,0.000000
65.389999,53.458160,-157.195679,0.008627,0.003676,0.093383,237.793777,12.113792,0.933828,-157.195679,0.094198,0.000000
65.630005,53.880806,-157.151199,0.008619,0.003688,0.093669,239.673798,12.209565,0.936690,-157.151199,0.094597,0.000000
65.870003,54.286324,-157.106720,0.008610,0.003699,0.093955,241.477631,12.301456,0.939551,-157.106720,0.095005,0.000000
66.110001,55.845070,-157.195679,0.008653,0.003722,0.094536,248.411270,12.654674,0.945365,-157.195679,0.095404,0.000000
66.350006,56.571198,-157.151199,0.008653,0.003737,0.094909,251.641251,12.819217,0.949093,-157.151199,0.095803,0.000000
66.590004,57.221359,-157.240158,0.008658,0.003751,0.095273,254.533325,12.966545,0.952734,-157.240158,0.096201,0.000000
66.830002,58.172401,-157.195679,0.008683,0.003765,0.095637,258.763763,13.182055,0.956375,-157.195679,0.096600,0.000000
67.070000,58.417046,-157.195679,0.008688,0.003776,0.095898,259.851990,13.237492,0.958979,-157.195679,0.096999,0.000000
67.310005,59.911751,-157.195679,0.008696,0.003797,0.096453,266.500763,13.576197,0.964527,-157.195679,0.097398,0.000000
67.550003,60.529144,-157.195679,0.008696,0.003811,0.096791,269.247070,13.716101,0.967911,-157.195679,0.097797,0.000000
67.790001,60.763741,-157.284637,0.008701,0.003816,0.096938,270.290619,13.769260,0.969384,-157.284637,0.098205,0.000000
68.030006,63.285072,-157.195679,0.008709,0.003848,0.097727,281.506073,14.340603,0.977275,-157.195679,0.098604,0.000000
68.270004,64.348198,-157.240158,0.008722,0.003863,0.098118,286.235077,14.581510,0.981181,-157.240158,0.099003,0.000000
68.510002,64.937294,-157.284637,0.008731,0.003876,0.098447,288.855499,14.715001,0.984474,-157.284637,0.099402,0.000000
68.750000,66.038017,-157.240158,0.008757,0.003893,0.098890,293.751770,14.964429,0.988898,-157.240158,0.099800,0.000000
68.990005,66.662117,-157.329117,0.008709,0.003906,0.099219,296.527893,15.105852,0.992191,-157.329117,0.100199,0.000000
69.230003,67.487663,-157.240158,0.008757,0.003920,0.099566,300.200134,15.292923,0.995662,-157.240158,0.100598,0.000000
69.470001,66.753716,-157.195679,0.008761,0.003911,0.099332,296.935364,15.126608,0.993319,-157.195679,0.099566,0.000000
69.710007,66.243568,-157.240158,0.008765,0.003908,0.099254,294.666107,15.011007,0.992540,-157.240158,0.099332,0.000000
69.950005,65.666023,-157.284637,0.008770,0.003905,0.099193,292.097046,14.880134,0.991934,-157.284637,0.099332,0.000000
70.190002,65.174126,-157.240158,0.008774,0.003904,0.099167,289.908997,14.768668,0.991673,-157.240158,0.099332,0.000000
70.430000,64.719078,-157.195679,0.008770,0.003904,0.099150,287.884827,14.665552,0.991499,-157.195679,0.099332,0.000000
70.670006,64.321007,-157.284637,0.008783,0.003903,0.099141,286.114136,14.575349,0.991412,-157.284637,0.099332,0.000000
70.910004,63.967262,-157.373611,0.008787,0.003903,0.099132,284.540588,14.495189,0.991325,-157.373611,0.099332,0.000000
71.150002,63.617607,-157.284637,0.008821,0.003903,0.099132,282.985260,14.415956,0.991325,-157.284637,0.099332,0.000000
71.390007,63.308159,-157.418091,0.008765,0.003903,0.099124,281.608765,14.345834,0.991238,-157.418091,0.099332,0.000000
71.630005,63.031860,-157.373611,0.008787,0.003903,0.099124,280.379730,14.283223,0.991238,-157.373611,0.099332,0.000000
71.870003,62.767471,-157.329117,0.008791,0.003903,0.099124,279.203644,14.223312,0.991238,-157.329117,0.099332,0.000000
72.110001,62.517982,-157.373611,0.008804,0.003903,0.099124,278.093872,14.166778,0.991238,-157.373611,0.099332,0.000000
72.350006,62.291580,-157.284637,0.008791,0.003903,0.099124,277.086792,14.115474,0.991238,-157.284637,0.099332,0.000000
72.590004,62.077469,-157.373611,0.008800,0.003903,0.099124,276.134369,14.066956,0.991238,-157.373611,0.099332,0.000000
72.830002,61.891655,-157.373611,0.008808,0.003903,0.099124,275.307831,14.024849,0.991238,-157.373611,0.099332,0.000000
73.070000,61.696907,-157.373611,0.008795,0.003903,0.099124,274.441559,13.980719,0.991238,-157.373611,0.099332,0.000000
73.310005,61.518539,-157.418091,0.008830,0.003903,0.099124,273.648132,13.940300,0.991238,-157.418091,0.099332,0.000000
73.550003,61.346504,-157.329117,0.008834,0.003903,0.099124,272.882874,13.901317,0.991238,-157.329117,0.099332,0.000000
73.790001,61.175583,-157.418091,0.008800,0.003903,0.099124,272.122589,13.862585,0.991238,-157.418091,0.099332,0.000000
74.030006,61.036690,-157.373611,0.008817,0.003903,0.099124,271.504761,13.831111,0.991238,-157.373611,0.099332,0.000000
74.270004,60.884384,-157.329117,0.008787,0.003903,0.099124,270.827271,13.796598,0.991238,-157.329117,0.099332,0.000000
74.510002,60.757408,-157.418091,0.008804,0.003903,0.099124,270.262451,13.767825,0.991238,-157.418091,0.099332,0.000000
74.750000,60.624100,-157.462570,0.008804,0.003903,0.099124,269.669464,13.737617,0.991238,-157.462570,0.099332,0.000000
74.990005,60.501961,-157.507050,0.008787,0.003903,0.099124,269.126160,13.709941,0.991238,-157.507050,0.099332,0.000000
75.230003,60.366417,-157.418091,0.008813,0.003903,0.099124,268.523224,13.679226,0.991238,-157.418091,0.099332,0.000000
75.470001,60.258804,-157.462570,0.008813,0.003903,0.099124,268.044556,13.654840,0.991238,-157.462570,0.099332,0.000000
75.710007,60.134804,-157.462570,0.008817,0.003903,0.099124,267.492981,13.626741,0.991238,-157.462570,0.099332,0.000000
75.950005,60.037613,-157.462570,0.008804,0.003903,0.099124,267.060638,13.604717,0.991238,-157.462570,0.099332,0.000000
76.190002,59.889412,-157.418091,0.008830,0.003902,0.099115,266.401398,13.571135,0.991150,-157.418091,0.099332,0.000000
76.430000,59.781418,-157.507050,0.008830,0.003902,0.099115,265.921021,13.546662,0.991150,-157.507050,0.099332,0.000000
76.670006,59.698380,-157.462570,0.008817,0.003902,0.099115,265.551666,13.527846,0.991150,-157.462570,0.099332,0.000000
76.910004,59.594490,-157.507050,0.008813,0.003902,0.099115,265.089539,13.504305,0.991150,-157.507050,0.099332,0.000000
77.150002,59.512192,-157.462570,0.008826,0.003902,0.099115,264.723450,13.485655,0.991150,-157.462570,0.099332,0.000000
77.390007,59.429901,-157.551529,0.008821,0.003902,0.099115,264.357391,13.467008,0.991150,-157.551529,0.099332,0.000000
77.630005,59.323776,-157.507050,0.008843,0.003902,0.099115,263.885345,13.442960,0.991150,-157.507050,0.099332,0.000000
77.870003,59.264565,-157.462570,0.008834,0.003902,0.099115,263.621948,13.429543,0.991150,-157.462570,0.099332,0.000000
78.110001,59.165520,-157.551529,0.008830,0.003902,0.099115,263.181366,13.407099,0.991150,-157.551529,0.099332,0.000000
78.350006,59.110405,-157.462570,0.008800,0.003902,0.099115,262.936218,13.394609,0.991150,-157.462570,0.099332,0.000000
78.590004,59.022522,-157.551529,0.008808,0.003902,0.099115,262.545288,13.374695,0.991150,-157.551529,0.099332,0.000000
78.830002,58.943207,-157.551529,0.008834,0.003902,0.099115,262.192474,13.356722,0.991150,-157.551529,0.099332,0.000000
79.070007,58.881393,-157.507050,0.008813,0.003902,0.099115,261.917511,13.342714,0.991150,-157.507050,0.099332,0.000000
79.310005,58.797615,-157.507050,0.008795,0.003902,0.099115,261.544861,13.323730,0.991150,-157.507050,0.099332,0.000000
79.550003,58.755165,-157.551529,0.008830,0.003902,0.099115,261.356018,13.314111,0.991150,-157.551529,0.099332,0.000000
79.790001,58.669518,-157.596008,0.008852,0.003902,0.099115,260.975037,13.294703,0.991150,-157.596008,0.099332,0.000000
80.030006,58.600624,-157.596008,0.008843,0.003902,0.099115,260.668610,13.279091,0.991150,-157.596008,0.099332,0.000000
80.270004,58.548866,-157.551529,0.008830,0.003902,0.099115,260.438354,13.267363,0.991150,-157.551529,0.099332,0.000000
80.510002,58.487053,-157.551529,0.008821,0.003902,0.099115,260.163391,13.253356,0.991150,-157.551529,0.099332,0.000000
80.750008,58.430824,-157.596008,0.008843,0.003902,0.099115,259.913300,13.240614,0.991150,-157.596008,0.099332,0.000000
80.990005,58.359703,-157.596008,0.008856,0.003902,0.099115,259.596924,13.224498,0.991150,-157.596008,0.099332,0.000000
81.230003,58.330658,-157.596008,0.008817,0.003902,0.099115,259.467712,13.217916,0.991150,-157.596008,0.099332,0.000000
81.470001,58.264374,-157.507050,0.008821,0.003902,0.099115,259.172882,13.202896,0.991150,-157.507050,0.099332,0.000000
81.710007,58.212616,-157.596008,0.008826,0.003902,0.099115,258.942657,13.191168,0.991150,-157.596008,0.099332,0.000000
81.950005,58.157875,-157.551529,0.008834,0.003902,0.099115,258.699158,13.178762,0.991150,-157.551529,0.099332,0.000000
82.190002,58.096809,-157.640488,0.008808,0.003902,0.099115,258.427521,13.164926,0.991150,-157.640488,0.099332,0.000000
82.430000,58.052124,-157.596008,0.008830,0.003902,0.099115,258.228760,13.154799,0.991150,-157.596008,0.099332,0.000000
82.670006,57.998871,-157.596008,0.008839,0.003902,0.099115,257.991852,13.142733,0.991150,-157.596008,0.099332,0.000000
82.910004,57.953445,-157.684967,0.008821,0.003902,0.099115,257.789795,13.132439,0.991150,-157.684967,0.099332,0.000000
83.150002,57.899818,-157.640488,0.008843,0.003902,0.099115,257.551270,13.120286,0.991150,-157.640488,0.099332,0.000000
83.390007,57.855507,-157.640488,0.008826,0.003902,0.099115,257.354156,13.110246,0.991150,-157.640488,0.099332,0.000000
83.630005,57.794441,-157.640488,0.008847,0.003902,0.099115,257.082520,13.096408,0.991150,-157.640488,0.099332,0.000000
83.870003,57.757576,-157.640488,0.008826,0.003902,0.099115,256.918518,13.088054,0.991150,-157.640488,0.099332,0.000000
84.110001,57.711403,-157.640488,0.008843,0.003902,0.099115,256.713135,13.077591,0.991150,-157.640488,0.099332,0.000000
84.350006,57.666718,-157.640488,0.008826,0.003902,0.099115,256.514374,13.067465,0.991150,-157.640488,0.099332,0.000000
84.590004,57.631714,-157.640488,0.008834,0.003902,0.099115,256.358673,13.059533,0.991150,-157.640488,0.099332,0.000000
84.830002,57.574738,-157.684967,0.008834,0.003902,0.099115,256.105225,13.046622,0.991150,-157.684967,0.099332,0.000000
85.070007,57.531174,-157.684967,0.008839,0.003902,0.099115,255.911438,13.036750,0.991150,-157.684967,0.099332,0.000000
85.310005,57.502129,-157.684967,0.008830,0.003902,0.099115,255.782242,13.030169,0.991150,-157.684967,0.099332,0.000000
85.550003,57.453720,-157.684967,0.008864,0.003902,0.099115,255.566910,13.019198,0.991150,-157.684967,0.099332,0.000000
85.790001,57.414993,-157.729446,0.008864,0.003902,0.099115,255.394638,13.010424,0.991150,-157.729446,0.099332,0.000000
86.030006,57.372169,-157.729446,0.008830,0.003902,0.099115,255.204163,13.000720,0.991150,-157.729446,0.099332,0.000000
86.270004,57.330833,-157.684967,0.008830,0.003902,0.099115,255.020279,12.991353,0.991150,-157.684967,0.099332,0.000000
86.510002,57.292480,-157.729446,0.008817,0.003902,0.099115,254.849686,12.982662,0.991150,-157.729446,0.099332,0.000000
86.750008,57.253380,-157.773926,0.008821,0.003902,0.099115,254.675751,12.973802,0.991150,-157.773926,0.099332,0.000000
86.990005,57.225830,-157.729446,0.008821,0.003902,0.099115,254.553207,12.967558,0.991150,-157.729446,0.099332,0.000000
87.230003,57.183746,-157.818420,0.008847,0.003902,0.099115,254.366013,12.958022,0.991150,-157.818420,0.099332,0.000000
87.470001,57.145767,-157.684967,0.008843,0.003902,0.099115,254.197067,12.949416,0.991150,-157.684967,0.099332,0.000000
87.710007,57.113373,-157.729446,0.008834,0.003902,0.099115,254.052963,12.942075,0.991150,-157.729446,0.099332,0.000000
87.950005,57.076134,-157.773926,0.008826,0.003902,0.099115,253.887329,12.933637,0.991150,-157.773926,0.099332,0.000000
88.190002,57.038895,-157.773926,0.008834,0.003902,0.099115,253.721680,12.925199,0.991150,-157.773926,0.099332,0.000000
88.430008,57.009483,-157.818420,0.008830,0.003902,0.099115,253.590851,12.918533,0.991150,-157.818420,0.099332,0.000000
88.670006,56.991982,-157.773926,0.008830,0.003902,0.099115,253.513000,12.914567,0.991150,-157.773926,0.099332,0.000000
88.910004,56.956230,-157.818420,0.008852,0.003902,0.099115,253.353958,12.906466,0.991150,-157.818420,0.099332,0.000000
89.150002,56.933144,-157.818420,0.008834,0.003902,0.099115,253.251266,12.901235,0.991150,-157.818420,0.099332,0.000000
89.390007,56.903725,-157.773926,0.008834,0.003902,0.099115,253.120407,12.894568,0.991150,-157.773926,0.099332,0.000000
89.630005,56.856064,-157.862900,0.008834,0.003902,0.099115,252.908401,12.883768,0.991150,-157.862900,0.099332,0.000000
89.870003,56.833717,-157.773926,0.008826,0.003902,0.099115,252.809006,12.878704,0.991150,-157.773926,0.099332,0.000000
90.110001,56.794624,-157.862900,0.008860,0.003902,0.099115,252.635101,12.869846,0.991150,-157.862900,0.099332,0.000000
90.350006,56.779724,-157.773926,0.008856,0.003902,0.099115,252.568832,12.866469,0.991150,-157.773926,0.099332,0.000000
90.590004,56.759247,-157.818420,0.008839,0.003902,0.099115,252.477737,12.861829,0.991150,-157.818420,0.099332,0.000000
90.830002,56.723869,-157.862900,0.008839,0.003902,0.099115,252.320374,12.853813,0.991150,-157.862900,0.099332,0.000000
91.070007,56.697433,-157.818420,0.008852,0.003902,0.099115,252.202774,12.847822,0.991150,-157.818420,0.099332,0.000000
91.310005,56.675835,-157.862900,0.008856,0.003902,0.099115,252.106705,12.842928,0.991150,-157.862900,0.099332,0.000000
91.550003,56.646790,-157.818420,0.008852,0.003902,0.099115,251.977509,12.836346,0.991150,-157.818420,0.099332,0.000000
91.790001,56.603966,-157.862900,0.008847,0.003902,0.099115,251.787018,12.826642,0.991150,-157.862900,0.099332,0.000000
92.030006,56.611038,-157.907379,0.008830,0.003902,0.099115,251.818481,12.828244,0.991150,-157.907379,0.099332,0.000000
92.270004,56.554070,-157.862900,0.008864,0.003902,0.099115,251.565063,12.815336,0.991150,-157.862900,0.099332,0.000000
92.510002,56.544388,-157.862900,0.008830,0.003902,0.099115,251.522003,12.813142,0.991150,-157.862900,0.099332,0.000000
92.750008,56.507149,-157.862900,0.008843,0.003902,0.099115,251.356354,12.804703,0.991150,-157.862900,0.099332,0.000000
92.990005,56.492630,-157.818420,0.008830,0.003902,0.099115,251.291763,12.801414,0.991150,-157.818420,0.099332,0.000000
93.230003,56.468796,-157.951859,0.008852,0.003902,0.099115,251.185745,12.796012,0.991150,-157.951859,0.099332,0.000000
93.470001,56.437141,-157.907379,0.008839,0.003902,0.099115,251.044937,12.788838,0.991150,-157.907379,0.099332,0.000000
93.710007,56.424858,-157.996338,0.008847,0.003902,0.099115,250.990311,12.786057,0.991150,-157.996338,0.099332,0.000000
93.950005,56.398788,-157.951859,0.008843,0.003902,0.099115,250.874344,12.780148,0.991150,-157.951859,0.099332,0.000000
94.190002,56.373466,-157.907379,0.008843,0.003902,0.099115,250.761703,12.774410,0.991150,-157.907379,0.099332,0.000000
94.430008,56.342560,-157.951859,0.008830,0.003902,0.099115,250.624222,12.767406,0.991150,-157.951859,0.099332,0.000000
94.670006,56.332504,-157.907379,0.008839,0.003902,0.099115,250.579498,12.765127,0.991150,-157.907379,0.099332,0.000000
94.910004,56.299736,-158.040817,0.008860,0.003902,0.099115,250.433731,12.757703,0.991150,-158.040817,0.099332,0.000000
95.150002,56.292664,-157.996338,0.008826,0.003902,0.099115,250.402267,12.756100,0.991150,-157.996338,0.099332,0.000000
95.390007,56.252815,-157.951859,0.008813,0.003902,0.099115,250.225021,12.747069,0.991150,-157.951859,0.099332,0.000000
95.630005,56.232338,-157.996338,0.008834,0.003902,0.099115,250.133926,12.742430,0.991150,-157.996338,0.099332,0.000000
95.870003,56.207390,-157.996338,0.008830,0.003902,0.099115,250.022964,12.736776,0.991150,-157.996338,0.099332,0.000000
96.110008,56.185417,-157.996338,0.008847,0.003902,0.099115,249.925217,12.731797,0.991150,-157.996338,0.099332,0.000000
96.350006,56.156746,-158.040817,0.008830,0.003902,0.099115,249.797684,12.725301,0.991150,-158.040817,0.099332,0.000000
96.590004,56.144455,-157.951859,0.008852,0.003902,0.099115,249.743011,12.722515,0.991150,-157.951859,0.099332,0.000000
96.830002,56.111687,-158.040817,0.008852,0.003902,0.099115,249.597244,12.715090,0.991150,-158.040817,0.099332,0.000000
97.070007,56.084503,-157.996338,0.008852,0.003902,0.099115,249.476334,12.708931,0.991150,-157.996338,0.099332,0.000000
97.310005,56.090096,-158.040817,0.008843,0.003902,0.099115,249.501205,12.710197,0.991150,-158.040817,0.099332,0.000000
97.550003,56.050995,-158.085297,0.008873,0.003902,0.099115,249.327271,12.701337,0.991150,-158.085297,0.099332,0.000000
97.790001,56.026047,-157.996338,0.008843,0.003902,0.099115,249.216309,12.695684,0.991150,-157.996338,0.099332,0.000000
98.030006,56.012642,-158.085297,0.008830,0.003902,0.099115,249.156677,12.692646,0.991150,-158.085297,0.099332,0.000000
98.270004,55.981735,-158.040817,0.008860,0.003902,0.099115,249.019196,12.685642,0.991150,-158.040817,0.099332,0.000000
98.510002,55.982101,-158.085297,0.008847,0.003902,0.099115,249.020828,12.685725,0.991150,-158.085297,0.099332,0.000000
98.750008,55.948959,-158.040817,0.008839,0.003902,0.099115,248.873398,12.678216,0.991150,-158.040817,0.099332,0.000000
98.990005,55.931465,-158.085297,0.008864,0.003902,0.099115,248.795578,12.674251,0.991150,-158.085297,0.099332,0.000000
99.230003,55.907257,-158.085297,0.008864,0.003902,0.099115,248.687897,12.668766,0.991150,-158.085297,0.099332,0.000000
99.470001,55.906509,-158.085297,0.008843,0.003902,0.099115,248.684570,12.668596,0.991150,-158.085297,0.099332,0.000000
99.710007,55.866295,-158.085297,0.008852,0.003902,0.099115,248.505692,12.659483,0.991150,-158.085297,0.099332,0.000000
99.800003,55.848419,-158.040817,0.008843,0.003902,0.099115,248.426178,12.655433,0.991150,-158.040817,0.099332,0.000000