File: Data/Compression Sample NH 10, 12, 15, 17 batch 3/AutoNoheating-15-3-2-240212_02122024_175755.csv
Time (sec),S:Load (lbs),S:HL1 (DIM),S:LVDT (in),S:Position (in),Ch:Position (mm),Ch:Load (N),Ch:Stress (MPa),Ch:Strain (mm/mm),Ch:HL1 (DIM),Set Point (),Cycles ()
0.110000,0.010056,-293.574280,0.000004,-0.000000,-0.000000,0.044729,0.002279,-0.000000,-293.574280,0.000208,0.000000
0.340000,-0.011169,-293.529785,-0.000078,0.000001,0.000017,-0.049684,-0.002531,0.000174,-293.529785,0.000330,0.000000
0.570000,-0.023460,-293.574280,-0.000052,0.000127,0.003226,-0.104357,-0.005316,0.032262,-293.574280,0.004163,0.000000
0.800000,0.001862,-293.574280,0.000065,0.000271,0.006895,0.008281,0.000422,0.068946,-293.574280,0.007996,0.000000
1.030000,0.010796,-293.574280,0.000216,0.000425,0.010788,0.048021,0.002446,0.107885,-293.574280,0.011829,0.000000
1.260000,0.034256,-293.663239,0.000440,0.000572,0.014535,0.152378,0.007763,0.145348,-293.663239,0.015662,0.000000
1.490000,0.019363,-293.618744,0.000543,0.000715,0.018169,0.086133,0.004388,0.181686,-293.618744,0.019478,0.000000
1.720000,0.021225,-293.574280,0.000694,0.000879,0.022331,0.094413,0.004810,0.223313,-293.574280,0.023311,0.000000
1.950000,-0.004097,-293.618744,0.000875,0.001025,0.026026,-0.018224,-0.000928,0.260257,-293.618744,0.027145,0.000000
2.180000,-0.004471,-293.663239,0.001065,0.001173,0.029807,-0.019887,-0.001013,0.298068,-293.663239,0.030977,0.000000
2.410000,-0.001488,-293.663239,0.001186,0.001328,0.033726,-0.006618,-0.000337,0.337264,-293.663239,0.034810,0.000000
2.640000,0.035004,-293.574280,0.001337,0.001475,0.037456,0.155704,0.007932,0.374557,-293.574280,0.038644,0.000000
2.870000,0.025322,-293.574280,0.001483,0.001631,0.041428,0.112638,0.005738,0.414276,-293.574280,0.042477,0.000000
3.100000,-0.009682,-293.574280,0.001673,0.001781,0.045243,-0.043066,-0.002194,0.452435,-293.574280,0.046310,0.000000
3.330000,0.001114,-293.707733,0.001798,0.001930,0.049033,0.004955,0.000252,0.490329,-293.707733,0.050143,0.000000
3.560000,0.017502,-293.707733,0.002026,0.002084,0.052944,0.077852,0.003966,0.529442,-293.707733,0.053976,0.000000
3.790000,0.033516,-293.618744,0.002104,0.002225,0.056526,0.149086,0.007595,0.565259,-293.618744,0.057809,0.000000
4.020000,0.013405,-293.663239,0.002259,0.002383,0.060533,0.059628,0.003038,0.605326,-293.663239,0.061643,0.000000
4.250000,0.007072,-293.663239,0.002492,0.002541,0.064531,0.031460,0.001603,0.645306,-293.663239,0.065476,0.000000
4.480000,-0.037239,-293.707733,0.002617,0.002684,0.068173,-0.165648,-0.008438,0.681728,-293.707733,0.069292,0.000000
4.710000,0.008194,-293.707733,0.002725,0.002838,0.072084,0.036449,0.001857,0.720841,-293.707733,0.073125,0.000000
4.940000,0.024948,-293.663239,0.002966,0.002987,0.075865,0.110975,0.005653,0.758652,-293.663239,0.076958,0.000000
5.170000,0.037613,-293.663239,0.003053,0.003135,0.079620,0.167311,0.008523,0.796202,-293.663239,0.080791,0.000000
5.400000,0.039841,-293.663239,0.003260,0.003295,0.083705,0.177220,0.009028,0.837048,-293.663239,0.084624,0.000000
5.630000,0.012291,-293.663239,0.003376,0.003441,0.087399,0.054673,0.002785,0.873993,-293.663239,0.088457,0.000000
5.860000,0.021973,-293.752197,0.003518,0.003594,0.091276,0.097739,0.004979,0.912758,-293.752197,0.092290,0.000000
6.090000,0.023460,-293.707733,0.003695,0.003741,0.095022,0.104357,0.005316,0.950221,-293.707733,0.096123,0.000000
6.320000,0.032394,-293.663239,0.003850,0.003885,0.098690,0.144098,0.007341,0.986904,-293.663239,0.099956,0.000000
6.550000,-0.004845,-293.663239,0.004010,0.004048,0.102810,-0.021550,-0.001098,1.028099,-293.663239,0.103790,0.000000
6.780000,-0.027184,-293.752197,0.004169,0.004197,0.106600,-0.120918,-0.006160,1.065997,-293.752197,0.107623,0.000000
7.010000,-0.021599,-293.707733,0.004320,0.004344,0.110337,-0.096076,-0.004894,1.103373,-293.707733,0.111456,0.000000
7.240000,0.035004,-293.707733,0.004480,0.004498,0.114240,0.155704,0.007932,1.142399,-293.707733,0.115272,0.000000
7.470000,0.061813,-293.707733,0.004708,0.004646,0.118004,0.274960,0.014007,1.180036,-293.707733,0.119105,0.000000
7.700000,0.055115,-293.752197,0.004794,0.004798,0.121880,0.245163,0.012489,1.218801,-293.752197,0.122938,0.000000
7.930000,0.032021,-293.752197,0.004980,0.004949,0.125705,0.142435,0.007256,1.257047,-293.752197,0.126771,0.000000
8.160001,0.002609,-293.752197,0.005144,0.005096,0.129451,0.011607,0.000591,1.294510,-293.752197,0.130604,0.000000
8.390000,0.025322,-293.752197,0.005290,0.005248,0.133301,0.112638,0.005738,1.333014,-293.752197,0.134438,0.000000
8.620001,0.030907,-293.663239,0.005467,0.005398,0.137109,0.137480,0.007004,1.371086,-293.663239,0.138271,0.000000
8.850000,0.013405,-293.796692,0.005588,0.005548,0.140924,0.059628,0.003038,1.409245,-293.796692,0.142104,0.000000
9.080001,0.012291,-293.752197,0.005760,0.005708,0.144992,0.054673,0.002785,1.449918,-293.752197,0.145937,0.000000
9.310000,0.023460,-293.752197,0.005963,0.005851,0.148617,0.104357,0.005316,1.486166,-293.752197,0.149770,0.000000
9.540001,0.013405,-293.752197,0.006053,0.006005,0.152519,0.059628,0.003038,1.525192,-293.752197,0.153603,0.000000
9.770000,0.041702,-293.707733,0.006213,0.006159,0.156430,0.185501,0.009450,1.564305,-293.707733,0.157436,0.000000
10.000000,0.046547,-293.796692,0.006394,0.006302,0.160073,0.207051,0.010548,1.600727,-293.796692,0.161269,0.000000
10.230000,0.040215,-293.841156,0.006528,0.006460,0.164079,0.178883,0.009113,1.640794,-293.841156,0.165085,0.000000
10.460000,0.039841,-293.841156,0.006722,0.006612,0.167938,0.177220,0.009028,1.679384,-293.841156,0.168918,0.000000
10.690001,0.002609,-293.796692,0.006847,0.006758,0.171642,0.011607,0.000591,1.716416,-293.796692,0.172752,0.000000
10.920000,0.038353,-293.796692,0.006993,0.006912,0.175570,0.170603,0.008691,1.755699,-293.796692,0.176585,0.000000
11.150001,0.071121,-293.752197,0.007161,0.007058,0.179264,0.316363,0.016116,1.792644,-293.752197,0.180418,0.000000
11.380000,0.118790,-293.796692,0.007312,0.007211,0.183167,0.528403,0.026918,1.831670,-293.796692,0.184251,0.000000
11.610001,0.729851,-293.841156,0.007455,0.000003,0.000087,3.246538,0.165387,0.000867,-293.841156,0.001136,0.000000
11.840000,0.685913,-293.796692,0.007524,-0.000006,-0.000147,3.051094,0.155430,-0.001472,-293.796692,0.000044,0.000000
12.070001,0.664314,-293.841156,0.007524,-0.000006,-0.000156,2.955018,0.150536,-0.001559,-293.841156,0.000044,0.000000
12.300000,0.647186,-293.841156,0.007493,-0.000006,-0.000156,2.878828,0.146655,-0.001559,-293.841156,0.000321,0.000000
12.530001,0.651276,-293.885651,0.007493,-0.000006,-0.000156,2.897019,0.147581,-0.001559,-293.885651,0.000702,0.000000
12.760000,0.642342,-293.841156,0.007480,-0.000006,-0.000147,2.857278,0.145557,-0.001472,-293.841156,0.001084,0.000000
12.990001,0.910820,-293.841156,0.007476,0.000026,0.000651,4.051530,0.206395,0.006506,-293.841156,0.001474,0.000000
13.220000,1.088448,-293.841156,0.007571,0.000039,0.000989,4.841657,0.246646,0.009886,-293.841156,0.001856,0.000000
13.450001,1.268677,-293.796692,0.007567,0.000053,0.001336,5.643356,0.287486,0.013357,-293.796692,0.002238,0.000000
13.680000,1.462677,-293.930115,0.007562,0.000069,0.001752,6.506312,0.331447,0.017516,-293.930115,0.002619,0.000000
13.910001,1.670090,-293.841156,0.007537,0.000084,0.002125,7.428930,0.378448,0.021248,-293.841156,0.003009,0.000000
14.140000,1.928886,-293.885651,0.007618,0.000101,0.002567,8.580115,0.437092,0.025669,-293.885651,0.003391,0.000000
14.370001,2.232376,-293.885651,0.007597,0.000121,0.003061,9.930105,0.505864,0.030612,-293.885651,0.003772,0.000000
14.600000,2.426010,-293.930115,0.007627,0.000135,0.003426,10.791432,0.549742,0.034257,-293.930115,0.004154,0.000000
14.830001,2.545914,-293.885651,0.007614,0.000147,0.003729,11.324790,0.576912,0.037293,-293.885651,0.004535,0.000000
15.060000,2.783859,-293.930115,0.007662,0.000160,0.004067,12.383224,0.630832,0.040672,-293.930115,0.004926,0.000000
15.290001,3.116386,-293.841156,0.007657,0.000179,0.004553,13.862379,0.706183,0.045529,-293.841156,0.005308,0.000000
15.520000,3.328636,-293.885651,0.007640,0.000193,0.004900,14.806513,0.754280,0.048999,-293.885651,0.005689,0.000000
15.750001,3.473862,-293.930115,0.007662,0.000203,0.005151,15.452509,0.787188,0.051512,-293.930115,0.006071,0.000000
15.980000,3.787773,-293.930115,0.007718,0.000221,0.005620,16.848856,0.858322,0.056198,-293.930115,0.006452,0.000000
16.210001,4.013802,-293.930115,0.007696,0.000235,0.005958,17.854280,0.909540,0.059578,-293.930115,0.006842,0.000000
16.440001,4.275208,-293.885651,0.007735,0.000251,0.006374,19.017073,0.968776,0.063741,-293.885651,0.007224,0.000000
16.670000,4.466606,-293.885651,0.007765,0.000268,0.006799,19.868456,1.012147,0.067992,-293.885651,0.007606,0.000000
16.900002,4.682213,-293.974609,0.007739,0.000281,0.007128,20.827522,1.061005,0.071285,-293.974609,0.007987,0.000000
17.130001,4.816635,-293.974609,0.007735,0.000291,0.007398,21.425463,1.091465,0.073976,-293.974609,0.008369,0.000000
17.360001,5.222893,-293.930115,0.007748,0.000314,0.007979,23.232588,1.183524,0.079786,-293.930115,0.008759,0.000000
17.590000,5.391579,-293.885651,0.007791,0.000327,0.008308,23.982941,1.221749,0.083082,-293.885651,0.009141,0.000000
17.820002,5.486908,-293.974609,0.007804,0.000337,0.008560,24.406986,1.243351,0.085595,-293.974609,0.009522,0.000000
18.050001,5.748314,-294.019073,0.007791,0.000354,0.008993,25.569777,1.302587,0.089933,-294.019073,0.009904,0.000000
18.280001,6.017914,-294.019073,0.007864,0.000371,0.009427,26.769018,1.363679,0.094267,-294.019073,0.010285,0.000000
18.510000,6.137444,-294.063568,0.007800,0.000385,0.009782,27.300713,1.390765,0.097824,-294.063568,0.010676,0.000000
18.740002,6.319534,-293.974609,0.007830,0.000400,0.010164,28.110693,1.432027,0.101640,-293.974609,0.011057,0.000000
18.970001,6.523964,-293.930115,0.007869,0.000417,0.010589,29.020041,1.478351,0.105890,-293.930115,0.011439,0.000000
19.200001,6.731750,-294.063568,0.007907,0.000433,0.011005,29.944323,1.525436,0.110050,-294.063568,0.011820,0.000000
19.430000,6.871391,-293.974609,0.007942,0.000448,0.011387,30.565475,1.557080,0.113869,-293.974609,0.012202,0.000000
19.660002,6.819260,-293.974609,0.007920,0.000456,0.011586,30.333582,1.545266,0.115863,-293.974609,0.012592,0.000000
19.890001,6.977516,-294.019073,0.007907,0.000470,0.011933,31.037542,1.581128,0.119330,-294.019073,0.012974,0.000000
20.120001,7.407608,-293.974609,0.007985,0.000495,0.012566,32.950687,1.678588,0.125662,-293.974609,0.013355,0.000000
20.350000,7.431068,-294.019073,0.007959,0.000507,0.012870,33.055042,1.683904,0.128698,-294.019073,0.013737,0.000000
20.580002,7.482079,-294.019073,0.008002,0.000522,0.013269,33.281948,1.695463,0.132687,-294.019073,0.014118,0.000000
20.810001,7.546501,-294.019073,0.008011,0.000534,0.013555,33.568512,1.710062,0.135548,-294.019073,0.014509,0.000000
21.040001,7.741249,-294.019073,0.008002,0.000551,0.013997,34.434795,1.754192,0.139969,-294.019073,0.014890,0.000000
21.270000,7.779976,-294.019073,0.008015,0.000564,0.014335,34.607059,1.762968,0.143353,-294.019073,0.015272,0.000000
21.500002,7.977333,-294.063568,0.008067,0.000578,0.014691,35.484951,1.807690,0.146907,-294.063568,0.015654,0.000000
21.730001,7.908073,-294.063568,0.008058,0.000591,0.015003,35.176868,1.791995,0.150029,-294.063568,0.016035,0.000000
21.960001,8.326622,-294.019073,0.008080,0.000611,0.015532,37.038666,1.886840,0.155321,-294.019073,0.016425,0.000000
22.190001,8.497169,-294.063568,0.008093,0.000632,0.016052,37.797298,1.925486,0.160525,-294.063568,0.016807,0.000000
22.420002,8.409286,-294.019073,0.008075,0.000645,0.016373,37.406376,1.905571,0.163731,-294.019073,0.017188,0.000000
22.650002,8.421951,-294.108063,0.008157,0.000658,0.016711,37.462711,1.908441,0.167114,-294.108063,0.017570,0.000000
22.880001,8.462906,-294.152527,0.008093,0.000669,0.016989,37.644886,1.917722,0.169889,-294.152527,0.017960,0.000000
23.110001,8.583931,-294.108063,0.008162,0.000684,0.017379,38.183231,1.945147,0.173791,-294.108063,0.018342,0.000000
23.340002,8.604782,-294.019073,0.008140,0.000694,0.017640,38.275982,1.949872,0.176395,-294.019073,0.018723,0.000000
23.570002,8.657661,-294.108063,0.008166,0.000708,0.017995,38.511200,1.961854,0.179949,-294.108063,0.019105,0.000000
23.800001,9.074715,-294.152527,0.008166,0.000731,0.018576,40.366348,2.056360,0.185759,-294.152527,0.019487,0.000000
24.030001,9.320114,-294.152527,0.008209,0.000752,0.019105,41.457939,2.111968,0.191050,-294.152527,0.019877,0.000000
24.260000,9.217339,-294.108063,0.008205,0.000765,0.019443,41.000771,2.088679,0.194434,-294.108063,0.020258,0.000000
24.490002,9.196114,-294.019073,0.008213,0.000778,0.019773,40.906357,2.083869,0.197727,-294.019073,0.020640,0.000000
24.720001,9.263138,-294.108063,0.008287,0.000794,0.020163,41.204494,2.099057,0.201629,-294.108063,0.021022,0.000000
24.950001,9.317879,-294.152527,0.008269,0.000807,0.020501,41.447994,2.111461,0.205013,-294.152527,0.021403,0.000000
25.180000,9.407990,-294.152527,0.008287,0.000820,0.020822,41.848827,2.131881,0.208222,-294.152527,0.021793,0.000000
25.410002,9.494751,-294.063568,0.008244,0.000836,0.021230,42.234760,2.151541,0.212299,-294.063568,0.022175,0.000000
25.640001,9.619125,-294.108063,0.008287,0.000849,0.021577,42.788006,2.179725,0.215766,-294.108063,0.022556,0.000000
25.870001,9.883141,-294.152527,0.008308,0.000871,0.022123,43.962406,2.239552,0.221231,-294.152527,0.022938,0.000000
26.100000,9.969528,-294.152527,0.008351,0.000887,0.022531,44.346676,2.259127,0.225307,-294.152527,0.023320,0.000000
26.330002,9.963196,-294.152527,0.008386,0.000902,0.022921,44.318508,2.257693,0.229209,-294.152527,0.023710,0.000000
26.560001,9.875320,-294.108063,0.008395,0.000912,0.023172,43.927620,2.237780,0.231723,-294.108063,0.024092,0.000000
26.790001,9.925957,-294.152527,0.008429,0.000925,0.023493,44.152863,2.249254,0.234932,-294.152527,0.024473,0.000000
27.020000,10.201889,-294.197021,0.008412,0.000943,0.023961,45.380268,2.311781,0.239614,-294.197021,0.024855,0.000000
27.250002,10.298706,-294.197021,0.008412,0.000960,0.024386,45.810932,2.333720,0.243865,-294.197021,0.025236,0.000000
27.480001,10.130768,-294.197021,0.008399,0.000968,0.024595,45.063908,2.295665,0.245946,-294.197021,0.025626,0.000000
27.710001,10.322906,-294.152527,0.008451,0.000985,0.025028,45.918583,2.339204,0.250280,-294.152527,0.026008,0.000000
27.940001,10.746666,-294.241486,0.008455,0.001009,0.025635,47.803558,2.435229,0.256351,-294.241486,0.026390,0.000000
28.170002,10.782417,-294.197021,0.008498,0.001024,0.026017,47.962589,2.443331,0.260170,-294.197021,0.026771,0.000000
28.400002,10.649849,-294.197021,0.008498,0.001036,0.026303,47.372894,2.413290,0.263031,-294.197021,0.027153,0.000000
28.630001,10.738480,-294.152527,0.008515,0.001052,0.026711,47.767143,2.433374,0.267108,-294.152527,0.027543,0.000000
28.860001,10.857262,-294.152527,0.008502,0.001067,0.027101,48.295513,2.460291,0.271010,-294.152527,0.027925,0.000000
29.090002,10.936577,-294.197021,0.008563,0.001079,0.027405,48.648323,2.478264,0.274045,-294.197021,0.028306,0.000000
29.320002,10.984612,-294.241486,0.008537,0.001092,0.027743,48.861992,2.489148,0.277425,-294.241486,0.028688,0.000000
29.550001,11.043823,-294.285980,0.008532,0.001105,0.028063,49.125378,2.502566,0.280635,-294.285980,0.029070,0.000000
29.780001,11.413216,-294.241486,0.008580,0.001126,0.028610,50.768520,2.586272,0.286096,-294.241486,0.029460,0.000000
30.010002,11.566635,-294.197021,0.008580,0.001144,0.029070,51.450962,2.621037,0.290695,-294.197021,0.029841,0.000000
30.240002,11.449333,-294.285980,0.008658,0.001157,0.029382,50.929176,2.594456,0.293818,-294.285980,0.030223,0.000000
30.470001,11.563286,-294.241486,0.008619,0.001172,0.029781,51.436066,2.620278,0.297807,-294.241486,0.030604,0.000000
30.700001,11.570358,-294.285980,0.008662,0.001186,0.030136,51.467525,2.621881,0.301361,-294.285980,0.030986,0.000000
30.930002,11.855225,-294.241486,0.008636,0.001203,0.030561,52.734673,2.686432,0.305611,-294.241486,0.031376,0.000000
31.160002,11.915543,-294.241486,0.008692,0.001217,0.030917,53.002979,2.700101,0.309165,-294.241486,0.031758,0.000000
31.390001,11.917038,-294.241486,0.008718,0.001229,0.031220,53.009632,2.700439,0.312201,-294.241486,0.032139,0.000000
31.620001,12.243233,-294.241486,0.008727,0.001249,0.031714,54.460621,2.774356,0.317144,-294.241486,0.032521,0.000000
31.850002,12.316963,-294.374939,0.008666,0.001263,0.032079,54.788589,2.791064,0.320789,-294.374939,0.032911,0.000000
32.080002,12.284195,-294.241486,0.008739,0.001274,0.032365,54.642830,2.783638,0.323650,-294.241486,0.033293,0.000000
32.310001,12.439102,-294.241486,0.008770,0.001290,0.032773,55.331890,2.818741,0.327726,-294.241486,0.033675,0.000000
32.540001,12.486023,-294.285980,0.008748,0.001302,0.033076,55.540604,2.829373,0.330762,-294.285980,0.034056,0.000000
32.770000,12.758972,-294.330444,0.008778,0.001321,0.033544,56.754742,2.891224,0.335444,-294.330444,0.034438,0.000000
33.000000,12.839401,-294.374939,0.008783,0.001336,0.033926,57.112511,2.909450,0.339259,-294.374939,0.034828,0.000000
33.230003,12.683754,-294.285980,0.008830,0.001344,0.034143,56.420155,2.874180,0.341428,-294.285980,0.035209,0.000000
33.460003,13.060219,-294.330444,0.008826,0.001365,0.034680,58.094753,2.959488,0.346802,-294.330444,0.035591,0.000000
33.690002,13.068413,-294.330444,0.008817,0.001378,0.034992,58.131203,2.961345,0.349925,-294.330444,0.035972,0.000000
33.920002,13.365189,-294.374939,0.008890,0.001396,0.035469,59.451328,3.028595,0.354694,-294.374939,0.036354,0.000000
34.150002,13.425148,-294.374939,0.008817,0.001412,0.035868,59.718040,3.042182,0.358683,-294.374939,0.036745,0.000000
34.380001,13.602768,-294.374939,0.008882,0.001428,0.036276,60.508133,3.082431,0.362759,-294.374939,0.037126,0.000000
34.610001,13.676865,-294.330444,0.008890,0.001443,0.036640,60.837730,3.099222,0.366404,-294.330444,0.037508,0.000000
34.840000,13.763260,-294.374939,0.008916,0.001455,0.036953,61.222038,3.118799,0.369527,-294.374939,0.037889,0.000000
35.070004,13.926361,-294.374939,0.008916,0.001472,0.037377,61.947548,3.155758,0.373774,-294.374939,0.038271,0.000000
35.300003,14.162445,-294.374939,0.008964,0.001489,0.037811,62.997704,3.209256,0.378111,-294.374939,0.038661,0.000000
35.530003,14.328896,-294.330444,0.008929,0.001505,0.038227,63.738110,3.246974,0.382274,-294.330444,0.039043,0.000000
35.760002,14.560509,-294.285980,0.008972,0.001522,0.038670,64.768379,3.299459,0.386695,-294.285980,0.039424,0.000000
35.990002,14.479706,-294.374939,0.009015,0.001534,0.038973,64.408951,3.281148,0.389731,-294.374939,0.039806,0.000000
36.220001,14.482681,-294.419403,0.008990,0.001548,0.039311,64.422180,3.281822,0.393114,-294.419403,0.040187,0.000000
36.450001,14.598114,-294.419403,0.009007,0.001561,0.039658,64.935654,3.307980,0.396581,-294.419403,0.040577,0.000000
36.680000,14.981285,-294.374939,0.009041,0.001580,0.040135,66.640083,3.394808,0.401354,-294.374939,0.040959,0.000000
36.910000,15.075500,-294.374939,0.009007,0.001594,0.040500,67.059174,3.416157,0.404995,-294.374939,0.041341,0.000000
37.140003,14.936234,-294.374939,0.009076,0.001604,0.040751,66.439682,3.384599,0.407508,-294.374939,0.041722,0.000000
37.370003,15.301903,-294.374939,0.009115,0.001621,0.041185,68.066261,3.467461,0.411846,-294.374939,0.042104,0.000000
37.600002,15.670547,-294.419403,0.009097,0.001642,0.041714,69.706078,3.550997,0.417137,-294.419403,0.042494,0.000000
37.830002,15.753960,-294.374939,0.009140,0.001655,0.042043,70.077110,3.569898,0.420430,-294.374939,0.042876,0.000000
38.060001,15.848541,-294.374939,0.009115,0.001670,0.042416,70.497833,3.591331,0.424162,-294.374939,0.043257,0.000000
38.290001,15.880569,-294.419403,0.009166,0.001683,0.042745,70.640305,3.598588,0.427455,-294.419403,0.043639,0.000000
38.520000,16.253685,-294.463898,0.009123,0.001702,0.043240,72.300003,3.683138,0.432398,-294.463898,0.044020,0.000000
38.750000,16.310287,-294.463898,0.009162,0.001715,0.043552,72.551781,3.695964,0.435520,-294.463898,0.044411,0.000000
38.980003,16.339706,-294.508362,0.009184,0.001727,0.043856,72.682648,3.702631,0.438556,-294.508362,0.044792,0.000000
39.210003,16.314011,-294.419403,0.009162,0.001740,0.044185,72.568344,3.696808,0.441852,-294.419403,0.045174,0.000000
39.440002,16.672234,-294.463898,0.009222,0.001757,0.044636,74.161797,3.777982,0.446360,-294.463898,0.045555,0.000000
39.670002,17.102325,-294.508362,0.009235,0.001775,0.045087,76.074944,3.875442,0.450872,-294.508362,0.045946,0.000000
39.900002,17.154823,-294.508362,0.009205,0.001788,0.045416,76.308464,3.887339,0.454165,-294.508362,0.046327,0.000000
40.130001,17.435226,-294.463898,0.009227,0.001806,0.045876,77.555763,3.950879,0.458763,-294.463898,0.046709,0.000000
40.360001,17.540230,-294.463898,0.009231,0.001820,0.046223,78.022842,3.974673,0.462230,-294.463898,0.047091,0.000000
40.590000,17.814301,-294.508362,0.009317,0.001837,0.046665,79.241966,4.036778,0.466655,-294.508362,0.047472,0.000000
40.820004,17.926758,-294.508362,0.009326,0.001851,0.047004,79.742203,4.062262,0.470039,-294.508362,0.047862,0.000000
41.050003,17.640404,-294.508362,0.009309,0.001859,0.047220,78.468437,3.997373,0.472203,-294.508362,0.048244,0.000000
41.280003,18.480103,-294.508362,0.009330,0.001882,0.047801,82.203598,4.187651,0.478013,-294.508362,0.048625,0.000000
41.510002,18.648415,-294.508362,0.009326,0.001896,0.048148,82.952293,4.225791,0.481484,-294.508362,0.049007,0.000000
41.740002,18.764221,-294.508362,0.009343,0.001910,0.048513,83.467422,4.252033,0.485125,-294.508362,0.049389,0.000000
41.970001,18.801460,-294.552856,0.009343,0.001924,0.048860,83.633072,4.260472,0.488596,-294.552856,0.049779,0.000000
42.200001,18.846146,-294.552856,0.009339,0.001936,0.049172,83.831841,4.270598,0.491718,-294.552856,0.050160,0.000000
42.430000,19.199524,-294.508362,0.009378,0.001951,0.049553,85.403748,4.350675,0.495534,-294.508362,0.050542,0.000000
42.660004,19.526840,-294.508362,0.009378,0.001967,0.049952,86.859726,4.424846,0.499523,-294.508362,0.050923,0.000000
42.890003,19.483643,-294.552856,0.009438,0.001978,0.050238,86.667572,4.415057,0.502384,-294.552856,0.051305,0.000000
43.120003,19.775215,-294.552856,0.009416,0.001994,0.050646,87.964554,4.481128,0.506461,-294.552856,0.051695,0.000000
43.350002,20.697952,-294.552856,0.009447,0.002021,0.051340,92.069092,4.690223,0.513398,-294.552856,0.052077,0.000000
43.580002,20.746735,-294.463898,0.009468,0.002033,0.051635,92.286087,4.701277,0.516347,-294.463898,0.052459,0.000000
43.810001,20.724388,-294.552856,0.009464,0.002046,0.051964,92.186684,4.696213,0.519643,-294.552856,0.052840,0.000000
44.040001,20.832748,-294.552856,0.009494,0.002059,0.052311,92.668694,4.720768,0.523110,-294.552856,0.053222,0.000000
44.270000,20.842056,-294.641815,0.009511,0.002072,0.052641,92.710098,4.722878,0.526407,-294.641815,0.053612,0.000000
44.500004,21.272896,-294.552856,0.009477,0.002089,0.053048,94.626564,4.820507,0.530483,-294.552856,0.053993,0.000000
44.730003,21.042023,-294.552856,0.009528,0.002095,0.053213,93.599594,4.768190,0.532130,-294.552856,0.054375,0.000000
44.960003,21.772621,-294.552856,0.009554,0.002115,0.053733,96.849457,4.933746,0.537334,-294.552856,0.054757,0.000000
45.190002,22.333412,-294.597351,0.009589,0.002134,0.054210,99.343979,5.060823,0.542103,-294.597351,0.055138,0.000000
45.420002,23.005913,-294.641815,0.009576,0.002156,0.054757,102.335411,5.213214,0.547568,-294.641815,0.055529,0.000000
45.650002,23.073685,-294.641815,0.009576,0.002170,0.055121,102.636879,5.228572,0.551209,-294.641815,0.055910,0.000000
45.880001,22.988785,-294.641815,0.009585,0.002182,0.055416,102.259224,5.209333,0.554158,-294.641815,0.056292,0.000000
46.110001,23.114273,-294.552856,0.009589,0.002195,0.055754,102.817421,5.237769,0.557542,-294.552856,0.056673,0.000000
46.340004,23.529846,-294.641815,0.009615,0.002211,0.056161,104.665985,5.331940,0.561614,-294.641815,0.057055,0.000000
46.570004,23.663895,-294.641815,0.009666,0.002225,0.056517,105.262260,5.362315,0.565172,-294.641815,0.057445,0.000000
46.800003,23.852318,-294.686310,0.009645,0.002236,0.056803,106.100410,5.405013,0.568033,-294.686310,0.057827,0.000000
47.030003,24.209053,-294.641815,0.009679,0.002251,0.057176,107.687248,5.485850,0.571761,-294.641815,0.058208,0.000000
47.260002,25.201797,-294.597351,0.009697,0.002276,0.057801,112.103195,5.710809,0.578006,-294.597351,0.058590,0.000000
47.490002,25.238289,-294.641815,0.009684,0.002288,0.058113,112.265518,5.719078,0.581129,-294.641815,0.058971,0.000000
47.720001,25.509750,-294.641815,0.009679,0.002304,0.058512,113.473038,5.780592,0.585118,-294.641815,0.059362,0.000000
47.950001,25.593529,-294.641815,0.009735,0.002316,0.058815,113.845703,5.799576,0.588154,-294.641815,0.059743,0.000000
48.180004,25.998672,-294.686310,0.009757,0.002332,0.059232,115.647873,5.891384,0.592317,-294.686310,0.060125,0.000000
48.410004,26.495415,-294.597351,0.009779,0.002348,0.059639,117.857491,6.003947,0.596390,-294.597351,0.060506,0.000000
48.640003,26.718468,-294.597351,0.009744,0.002361,0.059977,118.849678,6.054492,0.599773,-294.597351,0.060897,0.000000
48.870003,26.900932,-294.641815,0.009774,0.002374,0.060298,119.661324,6.095839,0.602983,-294.641815,0.061278,0.000000
49.100002,27.603600,-294.641815,0.009744,0.002394,0.060819,122.786942,6.255065,0.608187,-294.641815,0.061660,0.000000
49.330002,28.236633,-294.641815,0.009766,0.002412,0.061269,125.602821,6.398513,0.612695,-294.641815,0.062041,0.000000
49.560001,28.330093,-294.686310,0.009830,0.002423,0.061547,126.018547,6.419691,0.615469,-294.686310,0.062423,0.000000
49.790001,28.527451,-294.641815,0.009809,0.002438,0.061920,126.896439,6.464413,0.619201,-294.641815,0.062813,0.000000
50.020004,28.840622,-294.730774,0.009796,0.002452,0.062276,128.289490,6.535378,0.622755,-294.730774,0.063195,0.000000
50.250004,29.310555,-294.686310,0.009830,0.002467,0.062674,130.379852,6.641866,0.626745,-294.686310,0.063576,0.000000
50.480003,29.563393,-294.686310,0.009835,0.002482,0.063047,131.504532,6.699160,0.630473,-294.686310,0.063958,0.000000
50.710003,29.706017,-294.730774,0.009891,0.002492,0.063290,132.138962,6.731479,0.632903,-294.730774,0.064339,0.000000
50.940002,30.067963,-294.730774,0.009886,0.002505,0.063637,133.748978,6.813498,0.636370,-294.730774,0.064730,0.000000
51.170002,31.714592,-294.775269,0.009908,0.002536,0.064409,141.073547,7.186629,0.644091,-294.775269,0.065111,0.000000
51.400002,31.746986,-294.775269,0.009916,0.002547,0.064695,141.217651,7.193970,0.646952,-294.775269,0.065493,0.000000
51.630001,31.803589,-294.730774,0.009912,0.002561,0.065042,141.469421,7.206796,0.650419,-294.730774,0.065875,0.000000
51.860001,32.072067,-294.730774,0.009951,0.002572,0.065337,142.663681,7.267634,0.653368,-294.730774,0.066256,0.000000
52.090004,32.509605,-294.730774,0.009960,0.002587,0.065718,144.609940,7.366782,0.657183,-294.730774,0.066646,0.000000
52.320004,33.181366,-294.819733,0.009981,0.002603,0.066126,147.598083,7.519005,0.661259,-294.819733,0.067028,0.000000
52.550003,33.488571,-294.730774,0.009955,0.002617,0.066464,148.964600,7.588619,0.664643,-294.730774,0.067409,0.000000
52.780003,33.730614,-294.730774,0.010016,0.002632,0.066854,150.041260,7.643466,0.668545,-294.730774,0.067791,0.000000
53.010002,34.616119,-294.730774,0.010011,0.002650,0.067314,153.980194,7.844125,0.673140,-294.730774,0.068173,0.000000
53.240002,35.071526,-294.730774,0.010029,0.002665,0.067687,156.005936,7.947321,0.676872,-294.730774,0.068563,0.000000
53.470001,35.147491,-294.775269,0.009985,0.002674,0.067930,156.343857,7.964535,0.679298,-294.775269,0.068945,0.000000
53.700001,35.613327,-294.819733,0.010020,0.002689,0.068311,158.415985,8.070095,0.683113,-294.819733,0.069326,0.000000
53.930004,36.160347,-294.819733,0.009998,0.002706,0.068728,160.849258,8.194052,0.687276,-294.819733,0.069708,0.000000
54.160004,36.917747,-294.819733,0.010076,0.002723,0.069153,164.218338,8.365681,0.691527,-294.819733,0.070089,0.000000
54.390003,37.541847,-294.864227,0.010029,0.002738,0.069534,166.994476,8.507104,0.695342,-294.864227,0.070479,0.000000
54.620003,37.402954,-294.864227,0.010080,0.002747,0.069777,166.376648,8.475631,0.697772,-294.864227,0.070861,0.000000
54.850002,38.699928,-294.864227,0.010050,0.002769,0.070332,172.145874,8.769529,0.703321,-294.864227,0.071243,0.000000
55.080002,39.153847,-294.819733,0.010106,0.002784,0.070722,174.165009,8.872389,0.707223,-294.819733,0.071624,0.000000
55.310001,39.753738,-294.775269,0.010098,0.002801,0.071139,176.833466,9.008327,0.711386,-294.775269,0.072006,0.000000
55.540001,40.445610,-294.864227,0.010106,0.002816,0.071529,179.911057,9.165106,0.715288,-294.864227,0.072396,0.000000
55.770004,40.823196,-294.908691,0.010119,0.002828,0.071824,181.590652,9.250669,0.718237,-294.908691,0.072777,0.000000
56.000004,41.580597,-294.864227,0.010154,0.002846,0.072301,184.959732,9.422298,0.723006,-294.864227,0.073159,0.000000
56.230003,41.573524,-294.864227,0.010136,0.002854,0.072500,184.928268,9.420695,0.725000,-294.864227,0.073541,0.000000
56.460003,42.561798,-294.908691,0.010175,0.002874,0.073012,189.324341,9.644641,0.730118,-294.908691,0.073922,0.000000
56.690002,43.330376,-294.908691,0.010136,0.002891,0.073428,192.743134,9.818804,0.734281,-294.908691,0.074313,0.000000
56.920002,44.133209,-294.908691,0.010154,0.002908,0.073861,196.314316,10.000729,0.738615,-294.908691,0.074694,0.000000
57.150002,44.844818,-294.864227,0.010167,0.002924,0.074269,199.479721,10.161981,0.742691,-294.864227,0.075076,0.000000
57.380001,45.096169,-294.864227,0.010231,0.002937,0.074590,200.597778,10.218938,0.745901,-294.864227,0.075457,0.000000
57.610004,45.655846,-294.864227,0.010192,0.002951,0.074946,203.087341,10.345762,0.749458,-294.864227,0.075848,0.000000
57.840004,45.990234,-294.864227,0.010184,0.002961,0.075206,204.574783,10.421536,0.752059,-294.864227,0.076229,0.000000
58.070004,47.217575,-294.908691,0.010210,0.002983,0.075761,210.034271,10.699656,0.757607,-294.908691,0.076611,0.000000
58.300003,47.742989,-294.864227,0.010236,0.002996,0.076099,212.371414,10.818716,0.760991,-294.864227,0.076992,0.000000
58.530003,47.845390,-294.864227,0.010261,0.003006,0.076342,212.826920,10.841921,0.763421,-294.864227,0.077374,0.000000
58.760002,48.841118,-294.864227,0.010240,0.003022,0.076749,217.256149,11.067555,0.767493,-294.864227,0.077764,0.000000
58.990002,50.066597,-294.864227,0.010287,0.003043,0.077287,222.707352,11.345253,0.772872,-294.864227,0.078146,0.000000
59.220001,50.491470,-294.953186,0.010257,0.003054,0.077573,224.597275,11.441530,0.775733,-294.953186,0.078527,0.000000
59.450005,51.251480,-294.908691,0.010279,0.003071,0.078007,227.977966,11.613751,0.780071,-294.908691,0.078909,0.000000
59.680004,51.841698,-294.864227,0.010313,0.003085,0.078354,230.603394,11.747497,0.783538,-294.864227,0.079291,0.000000
59.910004,52.849335,-294.953186,0.010317,0.003100,0.078753,235.085587,11.975830,0.787527,-294.953186,0.079681,0.000000
60.140003,53.570618,-294.908691,0.010296,0.003118,0.079195,238.294006,12.139276,0.791951,-294.908691,0.080062,0.000000
60.370003,53.963097,-294.953186,0.010300,0.003129,0.079481,240.039841,12.228212,0.794813,-294.953186,0.080444,0.000000
60.600002,54.570808,-294.953186,0.010343,0.003142,0.079802,242.743073,12.365922,0.798022,-294.953186,0.080825,0.000000
60.830002,55.814163,-294.953186,0.010317,0.003160,0.080270,248.273804,12.647670,0.802704,-294.953186,0.081207,0.000000
61.060001,56.515717,-294.953186,0.010330,0.003175,0.080635,251.394470,12.806644,0.806345,-294.953186,0.081597,0.000000
61.290005,57.087677,-294.997681,0.010339,0.003188,0.080982,253.938675,12.936252,0.809816,-294.997681,0.081979,0.000000
61.520004,58.320602,-294.997681,0.010348,0.003207,0.081467,259.423004,13.215637,0.814672,-294.997681,0.082360,0.000000
61.750004,58.969650,-294.953186,0.010361,0.003222,0.081831,262.310120,13.362714,0.818313,-294.953186,0.082742,0.000000
61.980003,60.066658,-294.997681,0.010369,0.003240,0.082309,267.189850,13.611300,0.823086,-294.997681,0.083123,0.000000
62.210003,60.593567,-294.997681,0.010365,0.003250,0.082543,269.533661,13.730699,0.825425,-294.997681,0.083514,0.000000
62.440002,60.817734,-294.997681,0.010395,0.003260,0.082811,270.530792,13.781496,0.828112,-294.997681,0.083896,0.000000
62.670002,62.490799,-294.997681,0.010421,0.003283,0.083384,277.972961,14.160618,0.833839,-294.997681,0.084277,0.000000
62.900002,63.316345,-294.997681,0.010434,0.003298,0.083765,281.645172,14.347690,0.837654,-294.997681,0.084659,0.000000
63.130005,64.033539,-294.953186,0.010395,0.003311,0.084112,284.835419,14.510207,0.841121,-294.953186,0.085040,0.000000
63.360004,64.690399,-294.908691,0.010430,0.003324,0.084442,287.757263,14.659055,0.844418,-294.908691,0.085430,0.000000
63.590004,65.429932,-294.997681,0.010430,0.003338,0.084789,291.046875,14.826634,0.847888,-294.997681,0.085812,0.000000
63.820004,66.531418,-295.042145,0.010442,0.003355,0.085205,295.946533,15.076235,0.852048,-295.042145,0.086193,0.000000
64.050003,67.417282,-295.042145,0.010486,0.003367,0.085526,299.887054,15.276975,0.855258,-295.042145,0.086575,0.000000
64.280006,67.092575,-294.997681,0.010451,0.003361,0.085370,298.442688,15.203395,0.853698,-294.997681,0.085630,0.000000
64.510002,66.384323,-294.997681,0.010455,0.003360,0.085335,295.292206,15.042902,0.853350,-294.997681,0.085370,0.000000
64.740005,65.793381,-294.997681,0.010468,0.003358,0.085283,292.663574,14.908993,0.852831,-294.997681,0.085370,0.000000
64.970001,65.275406,-295.042145,0.010529,0.003357,0.085266,290.359497,14.791618,0.852657,-295.042145,0.085370,0.000000
65.200005,64.785736,-295.042145,0.010499,0.003357,0.085257,288.181335,14.680657,0.852570,-295.042145,0.085370,0.000000
65.430000,64.376862,-295.042145,0.010490,0.003357,0.085257,286.362579,14.588006,0.852570,-295.042145,0.085370,0.000000
65.660004,63.995193,-295.042145,0.010473,0.003356,0.085248,284.664825,14.501518,0.852483,-295.042145,0.085370,0.000000
65.889999,63.645905,-295.086639,0.010460,0.003356,0.085248,283.111115,14.422368,0.852483,-295.086639,0.085370,0.000000
66.120003,63.314117,-295.131104,0.010524,0.003356,0.085240,281.635254,14.347184,0.852396,-295.131104,0.085370,0.000000
66.350006,63.008026,-294.997681,0.010533,0.003356,0.085240,280.273712,14.277822,0.852396,-294.997681,0.085370,0.000000
66.580002,62.742157,-295.086639,0.010520,0.003356,0.085240,279.091064,14.217576,0.852396,-295.086639,0.085370,0.000000
66.810005,62.477394,-295.086639,0.010468,0.003356,0.085240,277.913330,14.157580,0.852396,-295.086639,0.085370,0.000000
67.040001,62.241684,-295.131104,0.010494,0.003356,0.085231,276.864838,14.104167,0.852309,-295.131104,0.085370,0.000000
67.270004,62.005600,-295.131104,0.010494,0.003356,0.085231,275.814697,14.050670,0.852309,-295.131104,0.085370,0.000000
67.500000,61.802284,-295.175598,0.010494,0.003356,0.085231,274.910278,14.004598,0.852309,-295.175598,0.085370,0.000000
67.730003,61.607536,-295.042145,0.010524,0.003356,0.085231,274.044006,13.960467,0.852309,-295.042145,0.085370,0.000000
67.960007,61.409805,-295.131104,0.010503,0.003356,0.085231,273.164459,13.915661,0.852309,-295.131104,0.085370,0.000000
68.190002,61.239258,-295.220062,0.010503,0.003356,0.085231,272.405823,13.877014,0.852309,-295.220062,0.085370,0.000000
68.420006,61.076157,-295.175598,0.010494,0.003356,0.085231,271.680328,13.840055,0.852309,-295.175598,0.085370,0.000000
68.650002,60.914551,-295.131104,0.010516,0.003356,0.085231,270.961456,13.803434,0.852309,-295.131104,0.085370,0.000000
68.880005,60.758156,-295.175598,0.010529,0.003356,0.085231,270.265778,13.767995,0.852309,-295.175598,0.085370,0.000000
69.110001,60.611435,-295.131104,0.010503,0.003356,0.085231,269.613129,13.734748,0.852309,-295.131104,0.085370,0.000000
69.340004,60.471428,-295.086639,0.010507,0.003356,0.085231,268.990356,13.703021,0.852309,-295.086639,0.085370,0.000000
69.570000,60.330666,-295.175598,0.010550,0.003356,0.085231,268.364197,13.671124,0.852309,-295.175598,0.085370,0.000000
69.800003,60.202942,-295.086639,0.010516,0.003356,0.085231,267.796051,13.642181,0.852309,-295.086639,0.085370,0.000000
70.030006,60.079689,-295.175598,0.010507,0.003356,0.085231,267.247803,13.614252,0.852309,-295.175598,0.085370,0.000000
70.260002,59.966492,-295.175598,0.010537,0.003355,0.085222,266.744263,13.588601,0.852222,-295.175598,0.085370,0.000000
70.490005,59.846954,-295.220062,0.010516,0.003355,0.085222,266.212555,13.561513,0.852222,-295.220062,0.085370,0.000000
70.720001,59.746788,-295.220062,0.010559,0.003355,0.085222,265.766998,13.538815,0.852222,-295.220062,0.085370,0.000000
70.950005,59.637688,-295.131104,0.010494,0.003355,0.085222,265.281677,13.514093,0.852222,-295.131104,0.085370,0.000000
71.180000,59.532677,-295.220062,0.010563,0.003355,0.085222,264.814575,13.490297,0.852222,-295.220062,0.085370,0.000000
71.410004,59.444054,-295.175598,0.010550,0.003355,0.085222,264.420349,13.470215,0.852222,-295.175598,0.085370,0.000000
71.640007,59.350960,-295.175598,0.010572,0.003355,0.085222,264.006256,13.449120,0.852222,-295.175598,0.085370,0.000000
71.870003,59.255630,-295.264557,0.010546,0.003355,0.085222,263.582214,13.427518,0.852222,-295.264557,0.085370,0.000000
72.100006,59.156204,-295.175598,0.010563,0.003355,0.085222,263.139954,13.404988,0.852222,-295.175598,0.085370,0.000000
72.330002,59.071304,-295.220062,0.010494,0.003355,0.085222,262.762299,13.385749,0.852222,-295.220062,0.085370,0.000000
72.560005,59.002792,-295.220062,0.010537,0.003355,0.085222,262.457520,13.370224,0.852222,-295.220062,0.085370,0.000000
72.790001,58.919380,-295.264557,0.010537,0.003355,0.085222,262.086487,13.351322,0.852222,-295.264557,0.085370,0.000000
73.020004,58.831123,-295.264557,0.010559,0.003355,0.085222,261.693909,13.331323,0.852222,-295.264557,0.085370,0.000000
73.250000,58.741013,-295.220062,0.010568,0.003355,0.085222,261.293060,13.310904,0.852222,-295.220062,0.085370,0.000000
73.480003,58.680313,-295.264557,0.010494,0.003355,0.085222,261.023071,13.297149,0.852222,-295.264557,0.085370,0.000000
73.710007,58.613663,-295.264557,0.010516,0.003355,0.085222,260.726593,13.282046,0.852222,-295.264557,0.085370,0.000000
73.940002,58.525406,-295.220062,0.010568,0.003355,0.085222,260.334015,13.262047,0.852222,-295.220062,0.085370,0.000000
74.170006,58.470299,-295.309021,0.010520,0.003355,0.085222,260.088867,13.249559,0.852222,-295.309021,0.085370,0.000000
74.400002,58.409599,-295.264557,0.010568,0.003355,0.085222,259.818878,13.235805,0.852222,-295.264557,0.085370,0.000000
74.630005,58.320976,-295.220062,0.010563,0.003355,0.085222,259.424652,13.215722,0.852222,-295.220062,0.085370,0.000000
74.860001,58.269218,-295.220062,0.010520,0.003355,0.085222,259.194427,13.203994,0.852222,-295.220062,0.085370,0.000000
75.090004,58.211128,-295.309021,0.010563,0.003355,0.085222,258.936035,13.190830,0.852222,-295.309021,0.085370,0.000000
75.320007,58.158623,-295.353516,0.010555,0.003355,0.085222,258.702484,13.178932,0.852222,-295.353516,0.085370,0.000000
75.550003,58.071487,-295.220062,0.010516,0.003355,0.085222,258.314880,13.159187,0.852222,-295.220062,0.085370,0.000000
75.780006,58.022331,-295.309021,0.010507,0.003355,0.085222,258.096222,13.148047,0.852222,-295.309021,0.085370,0.000000
76.010002,57.973183,-295.264557,0.010537,0.003355,0.085222,257.877594,13.136911,0.852222,-295.264557,0.085370,0.000000
76.240005,57.920677,-295.264557,0.010533,0.003355,0.085222,257.644043,13.125013,0.852222,-295.264557,0.085370,0.000000
76.470001,57.860725,-295.353516,0.010550,0.003355,0.085222,257.377350,13.111428,0.852222,-295.353516,0.085370,0.000000
76.700005,57.803749,-295.309021,0.010529,0.003355,0.085222,257.123932,13.098516,0.852222,-295.309021,0.085370,0.000000
76.930000,57.748268,-295.309021,0.010529,0.003355,0.085222,256.877136,13.085944,0.852222,-295.309021,0.085370,0.000000
77.160004,57.690918,-295.264557,0.010533,0.003355,0.085222,256.622009,13.072948,0.852222,-295.264557,0.085370,0.000000
77.390007,57.654800,-295.353516,0.010503,0.003355,0.085222,256.461365,13.064764,0.852222,-295.353516,0.085370,0.000000
77.620003,57.588890,-295.398010,0.010546,0.003355,0.085222,256.168182,13.049829,0.852222,-295.398010,0.085370,0.000000
77.850006,57.533409,-295.353516,0.010507,0.003355,0.085222,255.921387,13.037256,0.852222,-295.353516,0.085370,0.000000
78.080002,57.495796,-295.353516,0.010546,0.003355,0.085222,255.754074,13.028734,0.852222,-295.353516,0.085370,0.000000
78.310005,57.457817,-295.353516,0.010572,0.003355,0.085222,255.585129,13.020127,0.852222,-295.353516,0.085370,0.000000
78.540001,57.399727,-295.353516,0.010520,0.003355,0.085222,255.326736,13.006964,0.852222,-295.353516,0.085370,0.000000
78.770004,57.344238,-295.442474,0.010537,0.003355,0.085222,255.079910,12.994390,0.852222,-295.442474,0.085370,0.000000
79.000000,57.307747,-295.442474,0.010533,0.003355,0.085222,254.917587,12.986121,0.852222,-295.442474,0.085370,0.000000
79.230003,57.281685,-295.398010,0.010537,0.003355,0.085222,254.801666,12.980215,0.852222,-295.398010,0.085370,0.000000
79.460007,57.222473,-295.353516,0.010511,0.003355,0.085222,254.538269,12.966797,0.852222,-295.353516,0.085370,0.000000
79.690002,57.177048,-295.398010,0.010576,0.003355,0.085222,254.336212,12.956504,0.852222,-295.398010,0.085370,0.000000
79.920006,57.146141,-295.398010,0.010546,0.003355,0.085222,254.198730,12.949501,0.852222,-295.398010,0.085370,0.000000
80.150002,57.109650,-295.398010,0.010563,0.003355,0.085222,254.036407,12.941232,0.852222,-295.398010,0.085370,0.000000
80.380005,57.060493,-295.442474,0.010563,0.003355,0.085222,253.817749,12.930093,0.852222,-295.442474,0.085370,0.000000
80.610001,57.016556,-295.398010,0.010520,0.003355,0.085222,253.622314,12.920136,0.852222,-295.398010,0.085370,0.000000
80.840004,56.982666,-295.442474,0.010511,0.003355,0.085214,253.471558,12.912457,0.852135,-295.442474,0.085370,0.000000
81.070007,56.940216,-295.442474,0.010559,0.003355,0.085214,253.282730,12.902837,0.852135,-295.442474,0.085370,0.000000
81.300003,56.901115,-295.398010,0.010503,0.003355,0.085214,253.108795,12.893976,0.852135,-295.398010,0.085370,0.000000
81.530006,56.864250,-295.398010,0.010563,0.003355,0.085214,252.944824,12.885624,0.852135,-295.398010,0.085370,0.000000
81.760002,56.812492,-295.398010,0.010580,0.003355,0.085214,252.714584,12.873896,0.852135,-295.398010,0.085370,0.000000
81.990005,56.777122,-295.486969,0.010537,0.003355,0.085214,252.557251,12.865880,0.852135,-295.486969,0.085370,0.000000
82.220001,56.753288,-295.531433,0.010546,0.003355,0.085214,252.451233,12.860479,0.852135,-295.531433,0.085370,0.000000
82.450005,56.713814,-295.486969,0.010563,0.003355,0.085214,252.275650,12.851534,0.852135,-295.486969,0.085370,0.000000
82.680000,56.685890,-295.398010,0.010555,0.003355,0.085214,252.151428,12.845206,0.852135,-295.398010,0.085370,0.000000
82.910004,56.631149,-295.398010,0.010555,0.003355,0.085214,251.907928,12.832802,0.852135,-295.398010,0.085370,0.000000
83.140007,56.619232,-295.442474,0.010542,0.003355,0.085214,251.854919,12.830102,0.852135,-295.442474,0.085370,0.000000
83.370003,56.575294,-295.486969,0.010563,0.003355,0.085214,251.659485,12.820145,0.852135,-295.486969,0.085370,0.000000
83.600006,56.539543,-295.531433,0.010520,0.003355,0.085214,251.500443,12.812044,0.852135,-295.531433,0.085370,0.000000
83.830002,56.513107,-295.486969,0.010563,0.003355,0.085214,251.382858,12.806053,0.852135,-295.486969,0.085370,0.000000
84.060005,56.479218,-295.486969,0.010520,0.003355,0.085214,251.232101,12.798374,0.852135,-295.486969,0.085370,0.000000
84.290001,56.443848,-295.442474,0.010563,0.003355,0.085214,251.074768,12.790359,0.852135,-295.442474,0.085370,0.000000
84.520004,56.421127,-295.531433,0.010546,0.003355,0.085214,250.973709,12.785210,0.852135,-295.531433,0.085370,0.000000
84.750008,56.368996,-295.531433,0.010542,0.003355,0.085214,250.741821,12.773397,0.852135,-295.531433,0.085370,0.000000
84.980003,56.328781,-295.486969,0.010559,0.003355,0.085214,250.562927,12.764284,0.852135,-295.486969,0.085370,0.000000
85.210007,56.305695,-295.531433,0.010533,0.003355,0.085214,250.460236,12.759052,0.852135,-295.531433,0.085370,0.000000
85.440002,56.304947,-295.531433,0.010529,0.003355,0.085214,250.456909,12.758883,0.852135,-295.531433,0.085370,0.000000
85.670006,56.256172,-295.531433,0.010529,0.003355,0.085214,250.239944,12.747830,0.852135,-295.531433,0.085370,0.000000
85.900002,56.217072,-295.531433,0.010580,0.003355,0.085214,250.066025,12.738971,0.852135,-295.531433,0.085370,0.000000
86.130005,56.193611,-295.442474,0.010516,0.003355,0.085214,249.961670,12.733655,0.852135,-295.442474,0.085370,0.000000
86.360001,56.178345,-295.531433,0.010546,0.003355,0.085214,249.893753,12.730195,0.852135,-295.531433,0.085370,0.000000
86.590004,56.135521,-295.486969,0.010542,0.003355,0.085214,249.703262,12.720490,0.852135,-295.486969,0.085370,0.000000
86.820007,56.110199,-295.575928,0.010537,0.003355,0.085214,249.590637,12.714752,0.852135,-295.575928,0.085370,0.000000
87.050003,56.074455,-295.575928,0.010542,0.003355,0.085214,249.431641,12.706654,0.852135,-295.575928,0.085370,0.000000
87.280006,56.038704,-295.531433,0.010529,0.003355,0.085214,249.272598,12.698552,0.852135,-295.531433,0.085370,0.000000
87.510002,56.017105,-295.486969,0.010516,0.003355,0.085214,249.176529,12.693658,0.852135,-295.486969,0.085370,0.000000
87.740005,55.990669,-295.531433,0.010555,0.003355,0.085214,249.058929,12.687667,0.852135,-295.531433,0.085370,0.000000
87.970001,55.961624,-295.575928,0.010524,0.003355,0.085214,248.929733,12.681086,0.852135,-295.575928,0.085370,0.000000
88.200005,55.935188,-295.620392,0.010555,0.003355,0.085214,248.812149,12.675096,0.852135,-295.620392,0.085370,0.000000
88.430008,55.910606,-295.531433,0.010529,0.003355,0.085214,248.702805,12.669525,0.852135,-295.531433,0.085370,0.000000
88.660004,55.884911,-295.575928,0.010593,0.003355,0.085214,248.588501,12.663702,0.852135,-295.575928,0.085370,0.000000
88.890007,55.854752,-295.575928,0.010568,0.003355,0.085214,248.454346,12.656868,0.852135,-295.575928,0.085370,0.000000
89.120003,55.817146,-295.575928,0.010589,0.003355,0.085214,248.287064,12.648347,0.852135,-295.575928,0.085370,0.000000
89.350006,55.801132,-295.620392,0.010572,0.003355,0.085214,248.215836,12.644717,0.852135,-295.620392,0.085370,0.000000
89.580002,55.790703,-295.575928,0.010563,0.003355,0.085214,248.169434,12.642354,0.852135,-295.575928,0.085370,0.000000
89.810005,55.760170,-295.575928,0.010559,0.003355,0.085214,248.033630,12.635435,0.852135,-295.575928,0.085370,0.000000
90.040001,55.732239,-295.620392,0.010546,0.003355,0.085214,247.909378,12.629106,0.852135,-295.620392,0.085370,0.000000
90.270004,55.717346,-295.664886,0.010563,0.003355,0.085214,247.843140,12.625731,0.852135,-295.664886,0.085370,0.000000
90.500008,55.677505,-295.664886,0.010576,0.003355,0.085214,247.665909,12.616703,0.852135,-295.664886,0.085370,0.000000
90.730003,55.661865,-295.575928,0.010542,0.003355,0.085214,247.596344,12.613158,0.852135,-295.575928,0.085370,0.000000
90.960007,55.649948,-295.620392,0.010516,0.003355,0.085214,247.543335,12.610458,0.852135,-295.620392,0.085370,0.000000
91.190002,55.625740,-295.664886,0.010546,0.003355,0.085214,247.435654,12.604973,0.852135,-295.664886,0.085370,0.000000
91.420006,55.590736,-295.664886,0.010563,0.003355,0.085214,247.279953,12.597041,0.852135,-295.664886,0.085370,0.000000
91.650002,55.582924,-295.664886,0.010576,0.003355,0.085214,247.245193,12.595270,0.852135,-295.664886,0.085370,0.000000
91.880005,55.546425,-295.664886,0.010580,0.003355,0.085214,247.082840,12.587000,0.852135,-295.664886,0.085370,0.000000
92.110001,55.529671,-295.620392,0.010580,0.003355,0.085214,247.008316,12.583203,0.852135,-295.620392,0.085370,0.000000
92.340004,55.523338,-295.709351,0.010524,0.003355,0.085214,246.980148,12.581768,0.852135,-295.709351,0.085370,0.000000
92.570007,55.497650,-295.709351,0.010563,0.003355,0.085214,246.865875,12.575947,0.852135,-295.709351,0.085370,0.000000
92.800003,55.465248,-295.709351,0.010533,0.003355,0.085214,246.721741,12.568604,0.852135,-295.709351,0.085370,0.000000
93.030006,55.456314,-295.664886,0.010568,0.003355,0.085214,246.682007,12.566580,0.852135,-295.664886,0.085370,0.000000
93.260002,55.438065,-295.664886,0.010585,0.003355,0.085214,246.600830,12.562445,0.852135,-295.664886,0.085370,0.000000
93.490005,55.413864,-295.664886,0.010572,0.003355,0.085214,246.493179,12.556961,0.852135,-295.664886,0.085370,0.000000
93.720001,55.388542,-295.753845,0.010559,0.003355,0.085214,246.380539,12.551223,0.852135,-295.753845,0.085370,0.000000
93.950005,55.378860,-295.620392,0.010576,0.003355,0.085214,246.337479,12.549028,0.852135,-295.620392,0.085370,0.000000
94.180008,55.353165,-295.709351,0.010537,0.003355,0.085214,246.223175,12.543207,0.852135,-295.709351,0.085370,0.000000
94.410004,55.320396,-295.664886,0.010529,0.003355,0.085214,246.077408,12.535781,0.852135,-295.664886,0.085370,0.000000
94.600006,55.316299,-295.709351,0.010563,0.003355,0.085214,246.059189,12.534853,0.852135,-295.709351,0.085370,0.000000