File: Data/Compression Sample NH 10, 12, 15, 17 batch 3/AutoNoheating-12-3-1-240212_02122024_161808.csv
Time (sec),S:Load (lbs),S:HL1 (DIM),S:LVDT (in),S:Position (in),Ch:Position (mm),Ch:Load (N),Ch:Stress (MPa),Ch:Strain (mm/mm),Ch:HL1 (DIM),Set Point (),Cycles ()
0.110000,0.000374,-145.942001,0.000000,-0.000000,-0.000000,0.001663,0.000085,-0.000000,-145.942001,0.000061,0.000000
0.370000,0.002975,-145.853043,0.000039,0.000005,0.000130,0.013236,0.000674,0.001302,-145.853043,0.000685,0.000000
0.630000,0.001862,-145.942001,0.000022,0.000167,0.004249,0.008281,0.000422,0.042493,-145.942001,0.005021,0.000000
0.890000,-0.017128,-145.897522,0.000108,0.000332,0.008429,-0.076189,-0.003881,0.084293,-145.897522,0.009357,0.000000
1.150000,-0.053253,-145.853043,0.000267,0.000499,0.012670,-0.236882,-0.012067,0.126703,-145.853043,0.013693,0.000000
1.410000,0.005211,-145.986481,0.000466,0.000662,0.016816,0.023179,0.001181,0.168155,-145.986481,0.018012,0.000000
1.670000,0.013405,-145.942001,0.000673,0.000843,0.021403,0.059628,0.003038,0.214032,-145.942001,0.022348,0.000000
1.930000,0.001862,-145.986481,0.000823,0.001007,0.025566,0.008281,0.000422,0.255658,-145.986481,0.026685,0.000000
2.190000,0.027184,-146.030960,0.001000,0.001175,0.029841,0.120918,0.006160,0.298412,-146.030960,0.031003,0.000000
2.450000,0.007820,-145.942001,0.001181,0.001353,0.034377,0.034786,0.001772,0.343771,-145.942001,0.035340,0.000000
2.710000,-0.018250,-146.030960,0.001337,0.001517,0.038540,-0.081178,-0.004135,0.385397,-146.030960,0.039676,0.000000
2.970000,0.014519,-145.986481,0.001513,0.001692,0.042971,0.064583,0.003290,0.429710,-145.986481,0.044012,0.000000
3.230000,-0.009308,-145.986481,0.001729,0.001865,0.047377,-0.041403,-0.002109,0.473767,-145.986481,0.048330,0.000000
3.490000,0.002235,-146.030960,0.001910,0.002029,0.051539,0.009944,0.000507,0.515393,-146.030960,0.052667,0.000000
3.750000,0.030907,-145.986481,0.002031,0.002201,0.055901,0.137480,0.007004,0.559014,-145.986481,0.057003,0.000000
4.010000,0.021225,-146.075439,0.002259,0.002375,0.060333,0.094413,0.004810,0.603331,-146.075439,0.061339,0.000000
4.270000,0.006325,-145.986481,0.002440,0.002544,0.064626,0.028134,0.001433,0.646256,-145.986481,0.065658,0.000000
4.530000,0.018242,-146.030960,0.002600,0.002709,0.068797,0.081144,0.004134,0.687969,-146.030960,0.069994,0.000000
4.790000,0.001488,-146.075439,0.002794,0.002891,0.073419,0.006618,0.000337,0.734194,-146.075439,0.074330,0.000000
5.050000,0.001488,-146.030960,0.002966,0.003051,0.077504,0.006618,0.000337,0.775041,-146.030960,0.078666,0.000000
5.310000,0.014519,-146.119919,0.003143,0.003221,0.081814,0.064583,0.003290,0.818143,-146.119919,0.082985,0.000000
5.570000,0.004463,-146.030960,0.003328,0.003394,0.086220,0.019853,0.001011,0.862195,-146.030960,0.087321,0.000000
5.830000,0.013405,-146.075439,0.003484,0.003567,0.090599,0.059628,0.003038,0.905990,-146.075439,0.091657,0.000000
6.090000,0.041702,-146.119919,0.003682,0.003732,0.094788,0.185501,0.009450,0.947878,-146.119919,0.095976,0.000000
6.350000,0.007446,-146.075439,0.003854,0.003909,0.099289,0.033123,0.001687,0.992888,-146.075439,0.100312,0.000000
6.610000,0.004837,-146.119919,0.004040,0.004077,0.103564,0.021516,0.001096,1.035642,-146.119919,0.104648,0.000000
6.870000,0.004463,-146.075439,0.004212,0.004248,0.107891,0.019853,0.001011,1.078915,-146.075439,0.108984,0.000000
7.130000,-0.024582,-146.030960,0.004385,0.004422,0.112323,-0.109346,-0.005570,1.123232,-146.030960,0.113303,0.000000
7.390000,-0.011917,-146.119919,0.004583,0.004592,0.116642,-0.053010,-0.002700,1.166418,-146.119919,0.117639,0.000000
7.650001,0.028671,-146.119919,0.004730,0.004757,0.120822,0.127536,0.006497,1.208218,-146.119919,0.121975,0.000000
7.910000,-0.006706,-146.119919,0.004945,0.004931,0.125236,-0.029831,-0.001520,1.252361,-146.119919,0.126311,0.000000
8.170000,0.019737,-146.119919,0.005101,0.005104,0.129633,0.087796,0.004473,1.296330,-146.119919,0.130630,0.000000
8.430000,0.027550,-146.164398,0.005295,0.005267,0.133787,0.122547,0.006243,1.337870,-146.164398,0.134966,0.000000
8.690001,-0.003723,-146.164398,0.005480,0.005441,0.138210,-0.016561,-0.000844,1.382100,-146.164398,0.139303,0.000000
8.950001,0.018616,-146.119919,0.005644,0.005612,0.142555,0.082807,0.004218,1.425547,-146.119919,0.143639,0.000000
9.210000,0.000374,-146.208893,0.005829,0.005786,0.146969,0.001663,0.000085,1.469686,-146.208893,0.147958,0.000000
9.470000,-0.043945,-146.119919,0.005984,0.005954,0.151236,-0.195479,-0.009958,1.512357,-146.119919,0.152294,0.000000
9.730000,0.020477,-146.164398,0.006174,0.006125,0.155580,0.091088,0.004640,1.555804,-146.164398,0.156630,0.000000
9.990001,0.037979,-146.164398,0.006359,0.006293,0.159847,0.168940,0.008606,1.598471,-146.164398,0.160966,0.000000
10.250001,0.000374,-146.208893,0.006519,0.006466,0.164227,0.001663,0.000085,1.642266,-146.208893,0.165284,0.000000
10.510000,0.010422,-146.253372,0.006700,0.006638,0.168606,0.046358,0.002362,1.686061,-146.253372,0.169621,0.000000
10.770000,0.028297,-146.253372,0.006920,0.006811,0.172994,0.125873,0.006412,1.729943,-146.253372,0.173957,0.000000
11.030001,-0.000000,-146.253372,0.007105,0.006978,0.177252,-0.000000,-0.000000,1.772523,-146.253372,0.178276,0.000000
11.290001,0.014893,-146.253372,0.007269,0.007151,0.181623,0.066245,0.003375,1.816231,-146.253372,0.182612,0.000000
11.550000,0.010056,-146.119919,0.007455,0.007321,0.185959,0.044729,0.002279,1.859591,-146.119919,0.186948,0.000000
11.810000,-0.030167,-146.297852,0.007610,0.007491,0.190278,-0.134188,-0.006836,1.902780,-146.297852,0.191284,0.000000
12.070001,0.042450,-146.164398,0.007778,0.007657,0.194475,0.188827,0.009619,1.944755,-146.164398,0.195603,0.000000
12.330001,0.040215,-146.253372,0.007994,0.007833,0.198968,0.178883,0.009113,1.989678,-146.253372,0.199939,0.000000
12.590000,0.022339,-146.253372,0.008153,0.007998,0.203148,0.099368,0.005062,2.031478,-146.253372,0.204275,0.000000
12.850000,0.030533,-146.253372,0.008334,0.008169,0.207501,0.135817,0.006919,2.075012,-146.253372,0.208611,0.000000
13.110001,0.030159,-146.297852,0.008511,0.008346,0.211993,0.134154,0.006834,2.119935,-146.297852,0.212930,0.000000
13.370001,-0.017128,-146.164398,0.008688,0.008511,0.216191,-0.076189,-0.003881,2.161909,-146.164398,0.217266,0.000000
13.630001,0.036865,-146.297852,0.008877,0.008684,0.220579,0.163985,0.008354,2.205788,-146.297852,0.221602,0.000000
13.890000,0.027924,-146.253372,0.009028,0.008859,0.225019,0.124210,0.006328,2.250192,-146.253372,0.225939,0.000000
14.150001,0.028297,-146.253372,0.009231,0.009022,0.229156,0.125873,0.006412,2.291557,-146.253372,0.230257,0.000000
14.410001,0.052505,-146.342331,0.009390,0.009194,0.233526,0.233556,0.011898,2.335265,-146.342331,0.234593,0.000000
14.670001,0.030533,-146.297852,0.009572,0.009367,0.237932,0.135817,0.006919,2.379321,-146.297852,0.238929,0.000000
14.930000,0.026436,-146.297852,0.009766,0.009536,0.242216,0.117593,0.005990,2.422163,-146.297852,0.243265,0.000000
15.190001,0.033508,-146.386810,0.009929,0.009700,0.246379,0.149052,0.007593,2.463789,-146.386810,0.247584,0.000000
15.450001,0.019737,-146.297852,0.010128,0.009882,0.251001,0.087796,0.004473,2.510014,-146.297852,0.251920,0.000000
15.710001,0.013031,-146.386810,0.010283,0.010042,0.255069,0.057965,0.002953,2.550686,-146.386810,0.256257,0.000000
15.970001,0.037231,-146.342331,0.010477,0.010213,0.259405,0.165614,0.008437,2.594046,-146.342331,0.260575,0.000000
16.230001,0.040962,-146.342331,0.010649,0.010386,0.263810,0.182209,0.009282,2.638102,-146.342331,0.264912,0.000000
16.490002,0.026062,-146.431290,0.010852,0.010557,0.268155,0.115930,0.005906,2.681549,-146.431290,0.269248,0.000000
16.750000,0.065536,-146.342331,0.010994,0.010724,0.272387,0.291521,0.014851,2.723871,-146.342331,0.273584,0.000000
17.010000,0.035004,-146.386810,0.011171,0.010900,0.276862,0.155704,0.007932,2.768620,-146.386810,0.277903,0.000000
17.270000,0.034630,-146.297852,0.011369,0.011067,0.281111,0.154041,0.007847,2.811113,-146.297852,0.282238,0.000000
17.530001,0.029419,-146.342331,0.011542,0.011240,0.285491,0.130862,0.006666,2.854908,-146.342331,0.286575,0.000000
17.790001,-0.013779,-146.386810,0.011745,0.011414,0.289913,-0.061291,-0.003122,2.899135,-146.386810,0.290911,0.000000
18.050001,0.019363,-146.386810,0.011908,0.011582,0.294171,0.086133,0.004388,2.941715,-146.386810,0.295230,0.000000
18.310001,0.051384,-146.431290,0.012072,0.011749,0.298421,0.228567,0.011644,2.984212,-146.431290,0.299566,0.000000
18.570002,0.027924,-146.386810,0.012249,0.011922,0.302809,0.124210,0.006328,3.028094,-146.386810,0.303902,0.000000
18.830002,0.029419,-146.386810,0.012443,0.012096,0.307232,0.130862,0.006666,3.072320,-146.386810,0.308238,0.000000
19.090000,0.058090,-146.386810,0.012603,0.012259,0.311377,0.258398,0.013163,3.113773,-146.386810,0.312557,0.000000
19.350000,0.020851,-146.386810,0.012779,0.012433,0.315792,0.092750,0.004725,3.157916,-146.386810,0.316893,0.000000
19.610001,0.036118,-146.431290,0.012973,0.012604,0.320136,0.160659,0.008184,3.201363,-146.431290,0.321229,0.000000
19.870001,0.023087,-146.386810,0.013159,0.012776,0.324499,0.102694,0.005231,3.244987,-146.386810,0.325548,0.000000
20.130001,0.013031,-146.475769,0.013314,0.012945,0.328809,0.057965,0.002953,3.288086,-146.475769,0.329884,0.000000
20.390001,0.509407,-146.431290,0.013508,0.013116,0.333145,2.265956,0.115433,3.331450,-146.431290,0.334220,0.000000
20.650002,0.627449,-146.431290,0.013525,-0.000001,-0.000017,2.791033,0.142182,-0.000174,-146.431290,0.000191,0.000000
20.910002,0.593933,-146.520248,0.013512,-0.000001,-0.000017,2.641946,0.134587,-0.000174,-146.520248,0.000191,0.000000
21.170000,0.574196,-146.431290,0.013547,-0.000001,-0.000017,2.554151,0.130115,-0.000174,-146.431290,0.000503,0.000000
21.430000,0.596535,-146.520248,0.013512,0.000000,0.000009,2.653519,0.135177,0.000087,-146.520248,0.000936,0.000000
21.690001,0.680695,-146.475769,0.013547,0.000016,0.000416,3.027881,0.154248,0.004160,-146.475769,0.001370,0.000000
21.950001,0.867622,-146.431290,0.013594,0.000037,0.000945,3.859377,0.196606,0.009451,-146.431290,0.001804,0.000000
22.210001,0.971519,-146.520248,0.013577,0.000051,0.001283,4.321535,0.220149,0.012835,-146.520248,0.002237,0.000000
22.470001,1.124931,-146.475769,0.013547,0.000068,0.001726,5.003944,0.254913,0.017255,-146.475769,0.002671,0.000000
22.730001,1.307396,-146.520248,0.013590,0.000089,0.002272,5.815588,0.296260,0.022721,-146.520248,0.003104,0.000000
22.990002,1.475334,-146.520248,0.013616,0.000108,0.002732,6.562614,0.334316,0.027316,-146.520248,0.003538,0.000000
23.250002,1.577744,-146.520248,0.013650,0.000120,0.003044,7.018154,0.357522,0.030438,-146.520248,0.003972,0.000000
23.510000,1.743820,-146.564728,0.013633,0.000138,0.003503,7.756900,0.395155,0.035033,-146.564728,0.004405,0.000000
23.770000,1.922188,-146.520248,0.013685,0.000156,0.003963,8.550319,0.435574,0.039632,-146.520248,0.004839,0.000000
24.030001,2.099434,-146.564728,0.013676,0.000174,0.004423,9.338748,0.475739,0.044226,-146.564728,0.005273,0.000000
24.290001,2.235725,-146.520248,0.013728,0.000190,0.004830,9.945004,0.506623,0.048303,-146.520248,0.005706,0.000000
24.550001,2.393608,-146.520248,0.013715,0.000206,0.005238,10.647301,0.542399,0.052379,-146.520248,0.006140,0.000000
24.810001,2.587616,-146.609207,0.013741,0.000226,0.005741,11.510291,0.586362,0.057409,-146.609207,0.006574,0.000000
25.070002,2.738426,-146.564728,0.013741,0.000243,0.006183,12.181129,0.620536,0.061834,-146.564728,0.007007,0.000000
25.330002,2.859444,-146.609207,0.013745,0.000257,0.006530,12.719440,0.647959,0.065301,-146.609207,0.007441,0.000000
25.590002,3.060898,-146.653702,0.013810,0.000278,0.007059,13.615554,0.693609,0.070592,-146.653702,0.007874,0.000000
25.850000,3.224747,-146.564728,0.013810,0.000296,0.007527,14.344390,0.730738,0.075274,-146.564728,0.008308,0.000000
26.110001,3.280228,-146.609207,0.013827,0.000312,0.007935,14.591182,0.743310,0.079350,-146.609207,0.008742,0.000000
26.370001,3.403481,-146.609207,0.013849,0.000328,0.008325,15.139438,0.771240,0.083253,-146.609207,0.009175,0.000000
26.630001,3.575150,-146.564728,0.013866,0.000347,0.008802,15.903059,0.810140,0.088022,-146.564728,0.009609,0.000000
26.890001,3.736755,-146.653702,0.013857,0.000365,0.009262,16.621918,0.846761,0.092620,-146.653702,0.010042,0.000000
27.150002,3.817184,-146.653702,0.013883,0.000378,0.009600,16.979685,0.864986,0.096000,-146.653702,0.010476,0.000000
27.410002,3.826500,-146.653702,0.013905,0.000389,0.009886,17.021122,0.867097,0.098861,-146.653702,0.010910,0.000000
27.670002,4.081200,-146.653702,0.013931,0.000414,0.010519,18.154083,0.924813,0.105194,-146.653702,0.011343,0.000000
27.930002,4.155678,-146.698181,0.013931,0.000430,0.010918,18.485378,0.941690,0.109183,-146.698181,0.011777,0.000000
28.190001,4.221588,-146.653702,0.013969,0.000447,0.011360,18.778563,0.956626,0.113604,-146.653702,0.012210,0.000000
28.450001,4.294945,-146.698181,0.013965,0.000461,0.011716,19.104868,0.973248,0.117161,-146.698181,0.012644,0.000000
28.710001,4.459900,-146.698181,0.013995,0.000483,0.012280,19.838625,1.010628,0.122797,-146.698181,0.013078,0.000000
28.970001,4.528419,-146.698181,0.014008,0.000499,0.012670,20.143415,1.026155,0.126699,-146.698181,0.013511,0.000000
29.230001,4.508682,-146.698181,0.014025,0.000510,0.012948,20.055620,1.021682,0.129477,-146.698181,0.013936,0.000000
29.490002,4.705666,-146.698181,0.014017,0.000533,0.013529,20.931847,1.066319,0.135287,-146.698181,0.014370,0.000000
29.750002,4.768974,-146.698181,0.014047,0.000549,0.013936,21.213457,1.080665,0.139364,-146.698181,0.014803,0.000000
30.010002,4.834137,-146.742661,0.014064,0.000568,0.014422,21.503315,1.095431,0.144220,-146.742661,0.015237,0.000000
30.270002,4.891853,-146.698181,0.014090,0.000582,0.014786,21.760050,1.108510,0.147861,-146.698181,0.015671,0.000000
30.530001,4.964096,-146.742661,0.014116,0.000601,0.015263,22.081402,1.124880,0.152630,-146.742661,0.016104,0.000000
30.790001,5.123100,-146.742661,0.014133,0.000621,0.015766,22.788689,1.160911,0.157660,-146.742661,0.016538,0.000000
31.050001,5.044159,-146.787140,0.014142,0.000631,0.016018,22.437540,1.143023,0.160177,-146.787140,0.016971,0.000000
31.310001,5.243378,-146.787140,0.014146,0.000653,0.016590,23.323709,1.188166,0.165900,-146.787140,0.017405,0.000000
31.570002,5.272789,-146.831619,0.014172,0.000669,0.016980,23.454536,1.194831,0.169802,-146.831619,0.017839,0.000000
31.830002,5.278008,-146.742661,0.014198,0.000682,0.017327,23.477751,1.196014,0.173269,-146.742661,0.018272,0.000000
32.090000,5.351364,-146.831619,0.014206,0.000700,0.017787,23.804056,1.212636,0.177867,-146.831619,0.018706,0.000000
32.350002,5.353226,-146.742661,0.014224,0.000716,0.018194,23.812338,1.213058,0.181944,-146.742661,0.019139,0.000000
32.610001,5.517815,-146.876099,0.014237,0.000735,0.018680,24.544466,1.250355,0.186800,-146.876099,0.019573,0.000000
32.870003,5.454880,-146.787140,0.014237,0.000746,0.018949,24.264517,1.236093,0.189487,-146.787140,0.020007,0.000000
33.130001,5.623566,-146.787140,0.014297,0.000768,0.019512,25.014870,1.274318,0.195123,-146.787140,0.020440,0.000000
33.390003,5.837311,-146.876099,0.014301,0.000791,0.020094,25.965654,1.322754,0.200936,-146.876099,0.020874,0.000000
33.650002,5.765068,-146.831619,0.014319,0.000806,0.020466,25.644304,1.306383,0.204664,-146.831619,0.021307,0.000000
33.910000,5.802681,-146.831619,0.014331,0.000823,0.020900,25.811615,1.314906,0.209002,-146.831619,0.021741,0.000000
34.170002,5.838425,-146.831619,0.014366,0.000838,0.021282,25.970610,1.323006,0.212817,-146.831619,0.022175,0.000000
34.430000,5.941948,-146.831619,0.014396,0.000855,0.021715,26.431105,1.346465,0.217151,-146.831619,0.022608,0.000000
34.690002,5.943436,-146.831619,0.014396,0.000870,0.022088,26.437723,1.346802,0.220883,-146.831619,0.023042,0.000000
34.950001,6.057007,-146.876099,0.014396,0.000888,0.022556,26.942911,1.372537,0.225565,-146.876099,0.023476,0.000000
35.210003,6.147125,-146.831619,0.014409,0.000906,0.023007,27.343779,1.392958,0.230072,-146.831619,0.023909,0.000000
35.470001,6.299423,-146.876099,0.014435,0.000928,0.023562,28.021235,1.427470,0.235625,-146.876099,0.024343,0.000000
35.730003,6.301659,-146.920578,0.014452,0.000945,0.024013,28.031178,1.427976,0.240133,-146.920578,0.024777,0.000000
35.990002,6.263672,-146.920578,0.014461,0.000957,0.024317,27.862204,1.419368,0.243168,-146.920578,0.025210,0.000000
36.250000,6.338898,-146.920578,0.014474,0.000973,0.024716,28.196825,1.436415,0.247157,-146.920578,0.025644,0.000000
36.510002,6.466988,-146.965057,0.014513,0.000993,0.025210,28.766598,1.465440,0.252100,-146.965057,0.026077,0.000000
36.770000,6.577957,-146.876099,0.014504,0.001011,0.025670,29.260214,1.490586,0.256699,-146.876099,0.026511,0.000000
37.030003,6.580566,-146.920578,0.014543,0.001027,0.026077,29.271822,1.491178,0.260772,-146.920578,0.026945,0.000000
37.290001,6.626740,-146.876099,0.014538,0.001043,0.026485,29.477209,1.501641,0.264848,-146.876099,0.027378,0.000000
37.550003,6.718712,-146.965057,0.014586,0.001059,0.026910,29.886322,1.522482,0.269098,-146.965057,0.027812,0.000000
37.810001,6.767494,-146.965057,0.014599,0.001079,0.027395,30.103317,1.533536,0.273954,-146.965057,0.028246,0.000000
38.070004,6.678497,-146.965057,0.014586,0.001090,0.027682,29.707439,1.513369,0.276816,-146.965057,0.028679,0.000000
38.330002,6.791328,-146.965057,0.014620,0.001103,0.028029,30.209337,1.538937,0.280287,-146.965057,0.029104,0.000000
38.590000,7.214714,-146.965057,0.014646,0.001133,0.028774,32.092651,1.634878,0.287743,-146.965057,0.029538,0.000000
38.850002,7.116409,-146.965057,0.014659,0.001146,0.029104,31.655369,1.612601,0.291039,-146.965057,0.029971,0.000000
39.110001,7.069862,-146.965057,0.014681,0.001160,0.029468,31.448318,1.602054,0.294681,-146.965057,0.030405,0.000000
39.370003,7.368507,-147.054031,0.014685,0.001184,0.030075,32.776756,1.669728,0.300752,-147.054031,0.030839,0.000000
39.630001,7.377441,-146.965057,0.014715,0.001201,0.030518,32.816498,1.671752,0.305176,-146.965057,0.031272,0.000000
39.890003,7.284348,-147.009537,0.014724,0.001212,0.030795,32.402397,1.650657,0.307950,-147.009537,0.031706,0.000000
40.150002,7.310783,-147.054031,0.014750,0.001227,0.031177,32.519989,1.656647,0.311766,-147.054031,0.032139,0.000000
40.410004,7.628044,-147.009537,0.014771,0.001250,0.031758,33.931236,1.728539,0.317575,-147.009537,0.032573,0.000000
40.670002,7.479843,-146.965057,0.014784,0.001261,0.032035,33.272003,1.694957,0.320354,-146.965057,0.033007,0.000000
40.930000,7.587830,-147.009537,0.014776,0.001276,0.032408,33.752350,1.719427,0.324082,-147.009537,0.033440,0.000000
41.190002,8.041756,-147.054031,0.014801,0.001306,0.033162,35.771515,1.822288,0.331625,-147.054031,0.033874,0.000000
41.450001,7.930786,-147.009537,0.014823,0.001320,0.033536,35.277897,1.797142,0.335357,-147.009537,0.034307,0.000000
41.710003,7.912910,-147.009537,0.014836,0.001334,0.033891,35.198383,1.793091,0.338911,-147.009537,0.034741,0.000000
41.970001,7.949036,-147.054031,0.014840,0.001349,0.034273,35.359077,1.801277,0.342726,-147.054031,0.035175,0.000000
42.230003,8.151978,-147.054031,0.014857,0.001370,0.034802,36.261806,1.847265,0.348017,-147.054031,0.035608,0.000000
42.490002,8.181023,-147.054031,0.014896,0.001384,0.035148,36.391006,1.853846,0.351484,-147.054031,0.036042,0.000000
42.750004,8.261452,-147.054031,0.014901,0.001399,0.035530,36.748772,1.872072,0.355299,-147.054031,0.036475,0.000000
43.010002,8.438705,-147.098511,0.014931,0.001418,0.036007,37.537235,1.912238,0.360072,-147.098511,0.036909,0.000000
43.270000,8.571640,-147.054031,0.014922,0.001435,0.036458,38.128559,1.942361,0.364580,-147.054031,0.037343,0.000000
43.530003,8.468117,-147.054031,0.014961,0.001448,0.036779,37.668064,1.918903,0.367790,-147.054031,0.037776,0.000000
43.790001,8.665474,-147.142990,0.014974,0.001467,0.037256,38.545952,1.963624,0.372559,-147.142990,0.038210,0.000000
44.050003,8.737343,-147.098511,0.014987,0.001485,0.037715,38.865643,1.979910,0.377153,-147.098511,0.038643,0.000000
44.310001,9.033012,-147.142990,0.014978,0.001506,0.038262,40.180847,2.046910,0.382619,-147.142990,0.039077,0.000000
44.570004,8.977150,-147.142990,0.015008,0.001519,0.038574,39.932358,2.034251,0.385741,-147.142990,0.039511,0.000000
44.830002,9.091469,-147.098511,0.015052,0.001537,0.039051,40.440872,2.060156,0.390510,-147.098511,0.039944,0.000000
45.090004,9.278030,-147.142990,0.015069,0.001555,0.039493,41.270741,2.102432,0.394935,-147.142990,0.040378,0.000000
45.350002,9.356598,-147.142990,0.015064,0.001572,0.039936,41.620228,2.120235,0.399356,-147.142990,0.040811,0.000000
45.610001,9.448578,-147.187469,0.015082,0.001589,0.040352,42.029373,2.141078,0.403519,-147.187469,0.041245,0.000000
45.870003,9.507408,-147.098511,0.015116,0.001606,0.040794,42.291065,2.154409,0.407944,-147.098511,0.041679,0.000000
46.130001,9.718544,-147.098511,0.015129,0.001625,0.041271,43.230244,2.202254,0.412713,-147.098511,0.042112,0.000000
46.390003,9.811638,-147.187469,0.015142,0.001643,0.041722,43.644344,2.223349,0.417220,-147.187469,0.042546,0.000000
46.650002,9.807541,-147.142990,0.015151,0.001657,0.042095,43.626122,2.222420,0.420948,-147.142990,0.042980,0.000000
46.910004,10.045120,-147.231949,0.015185,0.001677,0.042607,44.682926,2.276257,0.426066,-147.231949,0.043413,0.000000
47.170002,10.190346,-147.142990,0.015194,0.001695,0.043058,45.328922,2.309165,0.430577,-147.142990,0.043847,0.000000
47.430004,10.219017,-147.142990,0.015228,0.001711,0.043465,45.456459,2.315662,0.434654,-147.142990,0.044272,0.000000
47.690002,10.241356,-147.231949,0.015220,0.001726,0.043847,45.555828,2.320724,0.438469,-147.231949,0.044705,0.000000
47.950001,10.457703,-147.231949,0.015246,0.001744,0.044298,46.518185,2.369749,0.442977,-147.231949,0.045139,0.000000
48.210003,10.676292,-147.231949,0.015271,0.001763,0.044783,47.490520,2.419282,0.447833,-147.231949,0.045572,0.000000
48.470001,10.662880,-147.231949,0.015271,0.001777,0.045130,47.430859,2.416243,0.451303,-147.231949,0.046006,0.000000
48.730003,10.604424,-147.276428,0.015276,0.001788,0.045416,47.170834,2.402997,0.454165,-147.276428,0.046440,0.000000
48.990002,11.071007,-147.276428,0.015302,0.001812,0.046032,49.246296,2.508726,0.460323,-147.276428,0.046873,0.000000
49.250004,11.155907,-147.276428,0.015332,0.001829,0.046457,49.623951,2.527965,0.464573,-147.276428,0.047307,0.000000
49.510002,11.225166,-147.276428,0.015332,0.001846,0.046891,49.932034,2.543659,0.468907,-147.276428,0.047741,0.000000
49.770000,11.262405,-147.231949,0.015340,0.001860,0.047246,50.097683,2.552097,0.472465,-147.231949,0.048174,0.000000
50.030003,11.633286,-147.231949,0.015383,0.001883,0.047836,51.747440,2.636140,0.478362,-147.231949,0.048608,0.000000
50.290001,11.668663,-147.276428,0.015405,0.001898,0.048200,51.904804,2.644157,0.482003,-147.276428,0.049042,0.000000
50.550003,11.578918,-147.276428,0.015414,0.001908,0.048469,51.505600,2.623820,0.484690,-147.276428,0.049475,0.000000
50.810001,12.032471,-147.320908,0.015414,0.001932,0.049067,53.523102,2.726597,0.490674,-147.320908,0.049909,0.000000
51.070004,12.176575,-147.276428,0.015418,0.001948,0.049484,54.164108,2.759251,0.494837,-147.276428,0.050343,0.000000
51.330002,12.351219,-147.320908,0.015470,0.001967,0.049952,54.940968,2.798826,0.499519,-147.320908,0.050776,0.000000
51.590004,12.408195,-147.320908,0.015457,0.001981,0.050308,55.194408,2.811737,0.503077,-147.320908,0.051210,0.000000
51.850002,12.620819,-147.276428,0.015483,0.002000,0.050802,56.140205,2.859919,0.508020,-147.276428,0.051643,0.000000
52.110001,12.915367,-147.320908,0.015504,0.002019,0.051279,57.450420,2.926664,0.512789,-147.320908,0.052077,0.000000
52.370003,12.831581,-147.365387,0.015530,0.002030,0.051574,57.077724,2.907678,0.515737,-147.365387,0.052510,0.000000
52.630001,13.260551,-147.320908,0.015526,0.002052,0.052112,58.985878,3.004884,0.521116,-147.320908,0.052944,0.000000
52.890003,13.298904,-147.409866,0.015534,0.002067,0.052510,59.156483,3.013575,0.525105,-147.409866,0.053378,0.000000
53.150002,13.363327,-147.276428,0.015556,0.002081,0.052857,59.443047,3.028173,0.528572,-147.276428,0.053811,0.000000
53.410004,13.604256,-147.365387,0.015586,0.002100,0.053351,60.514751,3.082768,0.533515,-147.365387,0.054245,0.000000
53.670002,13.680962,-147.365387,0.015586,0.002114,0.053707,60.855957,3.100150,0.537073,-147.365387,0.054678,0.000000
53.930004,14.089081,-147.320908,0.015634,0.002134,0.054202,62.671360,3.192631,0.542016,-147.320908,0.055112,0.000000
54.190002,13.975883,-147.365387,0.015616,0.002146,0.054514,62.167835,3.166980,0.545138,-147.365387,0.055546,0.000000
54.450001,14.469650,-147.409866,0.015638,0.002167,0.055043,64.364220,3.278869,0.550426,-147.409866,0.055979,0.000000
54.710003,14.948517,-147.409866,0.015668,0.002189,0.055607,66.494324,3.387382,0.556065,-147.409866,0.056413,0.000000
54.970001,14.964905,-147.365387,0.015668,0.002204,0.055988,66.567223,3.391096,0.559881,-147.365387,0.056846,0.000000
55.230003,15.098213,-147.365387,0.015685,0.002222,0.056439,67.160210,3.421304,0.564388,-147.365387,0.057280,0.000000
55.490002,15.246414,-147.409866,0.015711,0.002237,0.056829,67.819435,3.454887,0.568291,-147.409866,0.057714,0.000000
55.750004,15.475426,-147.454346,0.015724,0.002253,0.057237,68.838135,3.506782,0.572367,-147.454346,0.058147,0.000000
56.010002,15.597565,-147.409866,0.015759,0.002269,0.057627,69.381432,3.534459,0.576269,-147.409866,0.058581,0.000000
56.270004,15.915565,-147.365387,0.015772,0.002287,0.058078,70.795975,3.606519,0.580781,-147.365387,0.059006,0.000000
56.530003,16.233948,-147.409866,0.015784,0.002304,0.058529,72.212204,3.678665,0.585289,-147.409866,0.059440,0.000000
56.790001,16.765320,-147.454346,0.015789,0.002326,0.059084,74.575867,3.799076,0.590841,-147.454346,0.059873,0.000000
57.050003,16.935127,-147.454346,0.015819,0.002345,0.059552,75.331207,3.837554,0.595523,-147.454346,0.060307,0.000000
57.310001,16.833466,-147.498840,0.015823,0.002356,0.059838,74.878998,3.814518,0.598384,-147.498840,0.060740,0.000000
57.570004,17.056145,-147.498840,0.015841,0.002372,0.060237,75.869522,3.864978,0.602374,-147.498840,0.061174,0.000000
57.830002,17.391281,-147.454346,0.015866,0.002390,0.060706,77.360283,3.940921,0.607056,-147.454346,0.061607,0.000000
58.090004,17.802010,-147.543320,0.015884,0.002409,0.061183,79.187294,4.033993,0.611828,-147.543320,0.062041,0.000000
58.350002,18.023941,-147.498840,0.015879,0.002424,0.061573,80.174492,4.084283,0.615731,-147.498840,0.062475,0.000000
58.610004,18.270081,-147.543320,0.015897,0.002441,0.061989,81.269379,4.140059,0.619890,-147.543320,0.062908,0.000000
58.870003,18.629044,-147.498840,0.015944,0.002458,0.062431,82.866127,4.221402,0.624315,-147.498840,0.063342,0.000000
59.130001,18.919868,-147.543320,0.015940,0.002477,0.062908,84.159775,4.287303,0.629084,-147.543320,0.063775,0.000000
59.390003,18.827148,-147.543320,0.015927,0.002490,0.063238,83.747337,4.266293,0.632380,-147.543320,0.064209,0.000000
59.650002,19.209206,-147.498840,0.015957,0.002507,0.063680,85.446815,4.352868,0.636801,-147.498840,0.064643,0.000000
59.910004,20.197105,-147.543320,0.015974,0.002531,0.064278,89.841209,4.576730,0.642785,-147.543320,0.065076,0.000000
60.170002,20.170670,-147.543320,0.015983,0.002543,0.064599,89.723618,4.570739,0.645995,-147.543320,0.065510,0.000000
60.430004,20.343826,-147.543320,0.016004,0.002560,0.065024,90.493858,4.609977,0.650245,-147.543320,0.065944,0.000000
60.690002,21.185013,-147.632278,0.016030,0.002583,0.065597,94.235641,4.800592,0.655968,-147.632278,0.066377,0.000000
60.950005,21.390190,-147.543320,0.016030,0.002599,0.066022,95.148315,4.847086,0.660218,-147.543320,0.066811,0.000000
61.210003,21.260605,-147.543320,0.016039,0.002610,0.066299,94.571892,4.817722,0.662992,-147.543320,0.067245,0.000000
61.470001,21.412163,-147.543320,0.016056,0.002624,0.066646,95.246056,4.852066,0.666463,-147.543320,0.067678,0.000000
61.730003,22.395226,-147.543320,0.016095,0.002647,0.067245,99.618942,5.074831,0.672447,-147.543320,0.068112,0.000000
61.990002,22.298409,-147.587799,0.016086,0.002658,0.067505,99.188278,5.052891,0.675047,-147.587799,0.068546,0.000000
62.250004,22.697220,-147.632278,0.016112,0.002674,0.067930,100.962273,5.143263,0.679298,-147.632278,0.068979,0.000000
62.510002,23.971848,-147.676758,0.016138,0.002703,0.068658,106.632103,5.432098,0.686580,-147.676758,0.069413,0.000000
62.770004,24.155052,-147.543320,0.016138,0.002719,0.069057,107.447037,5.473613,0.690569,-147.543320,0.069846,0.000000
63.030003,24.286873,-147.543320,0.016177,0.002732,0.069404,108.033409,5.503484,0.694040,-147.543320,0.070280,0.000000
63.290005,24.553490,-147.676758,0.016160,0.002748,0.069794,109.219376,5.563900,0.697942,-147.676758,0.070714,0.000000
63.550003,25.026405,-147.587799,0.016177,0.002767,0.070271,111.323013,5.671065,0.702711,-147.587799,0.071147,0.000000
63.810001,25.425964,-147.676758,0.016194,0.002783,0.070679,113.100342,5.761606,0.706788,-147.676758,0.071581,0.000000
64.070000,25.692207,-147.676758,0.016194,0.002797,0.071043,114.284645,5.821938,0.710429,-147.676758,0.072014,0.000000
64.330002,26.173683,-147.632278,0.016246,0.002815,0.071494,116.426361,5.931041,0.714940,-147.632278,0.072448,0.000000
64.590004,26.625000,-147.676758,0.016250,0.002832,0.071928,118.433914,6.033311,0.719278,-147.676758,0.072882,0.000000
64.850006,26.950455,-147.676758,0.016250,0.002846,0.072283,119.881607,6.107060,0.722832,-147.676758,0.073315,0.000000
65.110001,27.657959,-147.721237,0.016263,0.002865,0.072769,123.028748,6.267383,0.727688,-147.721237,0.073749,0.000000
65.370003,28.240723,-147.676758,0.016293,0.002884,0.073263,125.621010,6.399439,0.732631,-147.676758,0.074174,0.000000
65.630005,29.059944,-147.587799,0.016310,0.002904,0.073766,129.265091,6.585077,0.737661,-147.587799,0.074607,0.000000
65.889999,29.109840,-147.765717,0.016323,0.002917,0.074087,129.487030,6.596384,0.740870,-147.765717,0.075041,0.000000
66.150002,29.621483,-147.676758,0.016323,0.002935,0.074547,131.762939,6.712324,0.745465,-147.676758,0.075475,0.000000
66.410004,30.460434,-147.765717,0.016332,0.002953,0.075015,135.494781,6.902433,0.750147,-147.765717,0.075908,0.000000
66.670006,30.951973,-147.721237,0.016362,0.002971,0.075475,137.681259,7.013817,0.754746,-147.721237,0.076342,0.000000
66.930000,31.523560,-147.676758,0.016362,0.002987,0.075882,140.223801,7.143341,0.758822,-147.676758,0.076775,0.000000
67.190002,31.912689,-147.810196,0.016375,0.003004,0.076299,141.954727,7.231519,0.762986,-147.810196,0.077209,0.000000
67.450005,32.671959,-147.721237,0.016414,0.003023,0.076784,145.332138,7.403572,0.767842,-147.721237,0.077643,0.000000
67.710007,33.085663,-147.810196,0.016405,0.003039,0.077200,147.172379,7.497318,0.772001,-147.810196,0.078076,0.000000
67.970001,33.497505,-147.676758,0.016440,0.003052,0.077530,149.004349,7.590643,0.775298,-147.676758,0.078510,0.000000
68.230003,34.441841,-147.765717,0.016410,0.003074,0.078076,153.204956,7.804633,0.780763,-147.765717,0.078943,0.000000
68.490005,35.265907,-147.810196,0.016457,0.003093,0.078571,156.870590,7.991369,0.785706,-147.810196,0.079377,0.000000
68.750000,35.652802,-147.765717,0.016457,0.003109,0.078978,158.591583,8.079041,0.789783,-147.765717,0.079811,0.000000
69.010002,36.085121,-147.810196,0.016470,0.003123,0.079316,160.514633,8.177006,0.793163,-147.810196,0.080244,0.000000
69.270004,36.906952,-147.765717,0.016492,0.003142,0.079811,164.170319,8.363235,0.798106,-147.765717,0.080678,0.000000
69.530006,37.605896,-147.810196,0.016492,0.003161,0.080287,167.279373,8.521618,0.802875,-147.810196,0.081111,0.000000
69.790001,38.186050,-147.854675,0.016504,0.003175,0.080652,169.860031,8.653083,0.806520,-147.854675,0.081545,0.000000
70.050003,38.375587,-147.810196,0.016539,0.003186,0.080921,170.703140,8.696033,0.809207,-147.810196,0.081979,0.000000
70.310005,39.777573,-147.854675,0.016539,0.003210,0.081536,176.939484,9.013727,0.815365,-147.854675,0.082412,0.000000
70.570000,40.410599,-147.810196,0.016539,0.003226,0.081953,179.755325,9.157172,0.819528,-147.810196,0.082846,0.000000
70.830002,41.112152,-147.810196,0.016565,0.003244,0.082386,182.875992,9.316147,0.823862,-147.810196,0.083279,0.000000
71.090004,41.587296,-147.854675,0.016543,0.003258,0.082759,184.989532,9.423817,0.827594,-147.854675,0.083713,0.000000
71.350006,42.597916,-147.854675,0.016561,0.003280,0.083306,189.484985,9.652825,0.833055,-147.854675,0.084147,0.000000
71.610001,43.293137,-147.854675,0.016569,0.003295,0.083696,192.577484,9.810365,0.836958,-147.854675,0.084580,0.000000
71.870003,43.673698,-147.854675,0.016604,0.003307,0.083991,194.270309,9.896602,0.839906,-147.854675,0.085014,0.000000
72.130005,44.771828,-147.854675,0.016617,0.003329,0.084555,199.155029,10.145441,0.845546,-147.854675,0.085448,0.000000
72.390007,45.747818,-147.943649,0.016617,0.003345,0.084962,203.496460,10.366604,0.849618,-147.943649,0.085881,0.000000
72.650002,46.616562,-147.810196,0.016642,0.003365,0.085474,207.360825,10.563464,0.854735,-147.810196,0.086315,0.000000
72.910004,47.297630,-147.988129,0.016660,0.003379,0.085821,210.390366,10.717796,0.858206,-147.988129,0.086748,0.000000
73.170006,48.018547,-147.899155,0.016638,0.003398,0.086306,213.597168,10.881158,0.863062,-147.899155,0.087182,0.000000
73.430000,49.068260,-147.943649,0.016677,0.003416,0.086774,218.266525,11.119026,0.867744,-147.943649,0.087616,0.000000
73.690002,49.500214,-147.943649,0.016660,0.003428,0.087078,220.187943,11.216908,0.870779,-147.943649,0.088049,0.000000
73.950005,50.578606,-147.899155,0.016686,0.003449,0.087607,224.984879,11.461276,0.876071,-147.899155,0.088483,0.000000
74.210007,51.576561,-147.943649,0.016694,0.003464,0.087989,229.423996,11.687416,0.879886,-147.943649,0.088917,0.000000
74.470001,52.296356,-147.943649,0.016703,0.003479,0.088361,232.625809,11.850524,0.883614,-147.943649,0.089341,0.000000
74.730003,53.286125,-147.899155,0.016746,0.003497,0.088830,237.028519,12.074809,0.888300,-147.899155,0.089775,0.000000
74.990005,53.735207,-147.943649,0.016711,0.003510,0.089151,239.026138,12.176572,0.891506,-147.943649,0.090209,0.000000
75.250000,55.030693,-147.988129,0.016729,0.003532,0.089706,244.788742,12.470134,0.897058,-147.988129,0.090642,0.000000
75.510002,55.645851,-148.032608,0.016767,0.003544,0.090018,247.525101,12.609530,0.900181,-148.032608,0.091076,0.000000
75.770004,56.740250,-147.943649,0.016746,0.003562,0.090469,252.393234,12.857524,0.904688,-147.943649,0.091510,0.000000
76.030006,58.373848,-147.988129,0.016785,0.003585,0.091059,259.659851,13.227703,0.910585,-147.988129,0.091943,0.000000
76.290001,59.408676,-148.032608,0.016789,0.003601,0.091466,264.263000,13.462198,0.914662,-148.032608,0.092377,0.000000
76.550003,60.234222,-147.943649,0.016785,0.003618,0.091909,267.935211,13.649270,0.919086,-147.943649,0.092811,0.000000
76.810005,61.175949,-147.988129,0.016836,0.003634,0.092299,272.124207,13.862668,0.922988,-147.988129,0.093244,0.000000
77.070007,62.033524,-147.943649,0.016806,0.003650,0.092698,275.938904,14.056997,0.926978,-147.943649,0.093678,0.000000
77.330002,63.064255,-148.032608,0.016836,0.003666,0.093114,280.523804,14.290565,0.931137,-148.032608,0.094111,0.000000
77.590004,64.154938,-148.032608,0.016824,0.003683,0.093556,285.375427,14.537717,0.935562,-148.032608,0.094545,0.000000
77.850006,65.237793,-147.943649,0.016836,0.003702,0.094033,290.192200,14.783095,0.940331,-147.943649,0.094979,0.000000
78.110001,66.862457,-148.032608,0.016836,0.003723,0.094562,297.419067,15.151250,0.945622,-148.032608,0.095412,0.000000
78.370003,67.353607,-148.077087,0.016836,0.003725,0.094623,299.603821,15.262546,0.946228,-148.077087,0.094840,0.000000
78.630005,66.588760,-148.077087,0.016862,0.003725,0.094623,296.201599,15.089229,0.946228,-148.077087,0.094840,0.000000
78.890007,65.933014,-148.121567,0.016854,0.003724,0.094597,293.284698,14.940635,0.945970,-148.121567,0.094623,0.000000
79.150002,65.374817,-148.032608,0.016871,0.003724,0.094588,290.801697,14.814145,0.945883,-148.032608,0.094623,0.000000
79.410004,64.872498,-148.121567,0.016893,0.003724,0.094588,288.567291,14.700318,0.945883,-148.121567,0.094623,0.000000
79.670006,64.421921,-148.121567,0.016875,0.003724,0.094588,286.563019,14.598216,0.945883,-148.121567,0.094623,0.000000
79.930000,64.014175,-148.032608,0.016875,0.003724,0.094588,284.749268,14.505819,0.945883,-148.032608,0.094623,0.000000
80.190002,63.655579,-148.121567,0.016880,0.003724,0.094580,283.154144,14.424560,0.945796,-148.121567,0.094623,0.000000
80.450005,63.332367,-148.077087,0.016905,0.003724,0.094580,281.716431,14.351319,0.945796,-148.077087,0.094623,0.000000
80.710007,63.022919,-148.166046,0.016888,0.003724,0.094580,280.339935,14.281198,0.945796,-148.166046,0.094623,0.000000
80.970001,62.751091,-148.121567,0.016901,0.003724,0.094580,279.130798,14.219600,0.945796,-148.121567,0.094623,0.000000
81.230003,62.507187,-148.121567,0.016901,0.003724,0.094580,278.045868,14.164330,0.945796,-148.121567,0.094623,0.000000
81.490005,62.258812,-148.166046,0.016901,0.003724,0.094580,276.941040,14.108048,0.945796,-148.166046,0.094623,0.000000
81.750008,62.040977,-148.121567,0.016901,0.003724,0.094580,275.972046,14.058686,0.945796,-148.121567,0.094623,0.000000
82.010002,61.843613,-148.210526,0.016914,0.003724,0.094580,275.094116,14.013964,0.945796,-148.210526,0.094623,0.000000
82.270004,61.654823,-148.121567,0.016910,0.003724,0.094580,274.254364,13.971183,0.945796,-148.121567,0.094623,0.000000
82.530006,61.462677,-148.166046,0.016905,0.003724,0.094580,273.399628,13.927642,0.945796,-148.166046,0.094623,0.000000
82.790001,61.307770,-148.166046,0.016893,0.003724,0.094580,272.710571,13.892539,0.945796,-148.166046,0.094623,0.000000
83.050003,61.150635,-148.166046,0.016901,0.003724,0.094580,272.011597,13.856932,0.945796,-148.166046,0.094623,0.000000
83.310005,61.002800,-148.166046,0.016905,0.003724,0.094580,271.354004,13.823432,0.945796,-148.166046,0.094623,0.000000
83.570007,60.849380,-148.166046,0.016918,0.003723,0.094571,270.671570,13.788667,0.945709,-148.166046,0.094623,0.000000
83.830002,60.719421,-148.210526,0.016905,0.003723,0.094571,270.093475,13.759217,0.945709,-148.210526,0.094623,0.000000
84.090004,60.597282,-148.210526,0.016918,0.003723,0.094571,269.550171,13.731540,0.945709,-148.210526,0.094623,0.000000
84.350006,60.465469,-148.210526,0.016893,0.003723,0.094571,268.963837,13.701672,0.945709,-148.210526,0.094623,0.000000
84.610001,60.335876,-148.299484,0.016923,0.003723,0.094571,268.387390,13.672305,0.945709,-148.299484,0.094623,0.000000
84.870003,60.241669,-148.210526,0.016914,0.003723,0.094571,267.968323,13.650957,0.945709,-148.210526,0.094623,0.000000
85.130005,60.121391,-148.210526,0.016914,0.003723,0.094571,267.433319,13.623702,0.945709,-148.210526,0.094623,0.000000
85.390007,60.017128,-148.299484,0.016918,0.003723,0.094571,266.969513,13.600076,0.945709,-148.299484,0.094623,0.000000
85.650002,59.907654,-148.255005,0.016901,0.003723,0.094571,266.482544,13.575269,0.945709,-148.255005,0.094623,0.000000
85.910004,59.821632,-148.299484,0.016897,0.003723,0.094571,266.099915,13.555776,0.945709,-148.299484,0.094623,0.000000
86.170006,59.726303,-148.255005,0.016901,0.003723,0.094571,265.675873,13.534174,0.945709,-148.255005,0.094623,0.000000
86.430000,59.630981,-148.210526,0.016923,0.003723,0.094571,265.251862,13.512573,0.945709,-148.210526,0.094623,0.000000
86.690002,59.552032,-148.299484,0.016927,0.003723,0.094571,264.900665,13.494683,0.945709,-148.299484,0.094623,0.000000
86.950005,59.466393,-148.255005,0.016927,0.003723,0.094571,264.519714,13.475277,0.945709,-148.255005,0.094623,0.000000
87.210007,59.381119,-148.299484,0.016918,0.003723,0.094571,264.140411,13.455954,0.945709,-148.299484,0.094623,0.000000
87.470001,59.293610,-148.299484,0.016905,0.003723,0.094571,263.751160,13.436124,0.945709,-148.299484,0.094623,0.000000
87.730003,59.228447,-148.299484,0.016918,0.003723,0.094571,263.461304,13.421358,0.945709,-148.299484,0.094623,0.000000
87.990005,59.154343,-148.388458,0.016927,0.003723,0.094571,263.131653,13.404566,0.945709,-148.388458,0.094623,0.000000
88.250008,59.076141,-148.343979,0.016918,0.003723,0.094571,262.783813,13.386845,0.945709,-148.343979,0.094623,0.000000
88.510002,59.013214,-148.388458,0.016901,0.003723,0.094571,262.503876,13.372585,0.945709,-148.388458,0.094623,0.000000
88.770004,58.946930,-148.343979,0.016923,0.003723,0.094571,262.209045,13.357565,0.945709,-148.343979,0.094623,0.000000
89.030006,58.884369,-148.388458,0.016914,0.003723,0.094571,261.930756,13.343390,0.945709,-148.388458,0.094623,0.000000
89.290001,58.803940,-148.388458,0.016905,0.003723,0.094571,261.572998,13.325163,0.945709,-148.388458,0.094623,0.000000
89.550003,58.755157,-148.343979,0.016905,0.003723,0.094571,261.355988,13.314109,0.945709,-148.343979,0.094623,0.000000
89.810005,58.691856,-148.388458,0.016936,0.003723,0.094571,261.074402,13.299765,0.945709,-148.388458,0.094623,0.000000
90.070007,58.626694,-148.388458,0.016923,0.003723,0.094571,260.784546,13.284998,0.945709,-148.388458,0.094623,0.000000
90.330002,58.582008,-148.343979,0.016944,0.003723,0.094571,260.585785,13.274873,0.945709,-148.343979,0.094623,0.000000
90.590004,58.514977,-148.432938,0.016918,0.003723,0.094571,260.287628,13.259684,0.945709,-148.432938,0.094623,0.000000
90.850006,58.471413,-148.388458,0.016914,0.003723,0.094571,260.093842,13.249811,0.945709,-148.388458,0.094623,0.000000
91.110001,58.402519,-148.477417,0.016910,0.003723,0.094571,259.787384,13.234200,0.945709,-148.477417,0.094623,0.000000
91.370003,58.351509,-148.388458,0.016927,0.003723,0.094571,259.560486,13.222641,0.945709,-148.388458,0.094623,0.000000
91.630005,58.300117,-148.343979,0.016940,0.003723,0.094571,259.331879,13.210996,0.945709,-148.343979,0.094623,0.000000
91.890007,58.251343,-148.432938,0.016927,0.003723,0.094571,259.114899,13.199943,0.945709,-148.432938,0.094623,0.000000
92.150002,58.207771,-148.388458,0.016927,0.003723,0.094571,258.921112,13.190069,0.945709,-148.388458,0.094623,0.000000
92.410004,58.148933,-148.521896,0.016940,0.003723,0.094571,258.659363,13.176737,0.945709,-148.521896,0.094623,0.000000
92.670006,58.107979,-148.388458,0.016914,0.003723,0.094571,258.477203,13.167457,0.945709,-148.388458,0.094623,0.000000
92.930008,58.058075,-148.477417,0.016927,0.003723,0.094571,258.255219,13.156148,0.945709,-148.477417,0.094623,0.000000
93.190002,58.010414,-148.477417,0.016927,0.003723,0.094571,258.043213,13.145348,0.945709,-148.477417,0.094623,0.000000
93.450005,57.963867,-148.432938,0.016927,0.003723,0.094571,257.836151,13.134800,0.945709,-148.432938,0.094623,0.000000
93.710007,57.920670,-148.477417,0.016931,0.003723,0.094571,257.644012,13.125011,0.945709,-148.477417,0.094623,0.000000
93.970001,57.880455,-148.477417,0.016914,0.003723,0.094571,257.465118,13.115898,0.945709,-148.477417,0.094623,0.000000
94.230003,57.827209,-148.477417,0.016927,0.003723,0.094571,257.228271,13.103833,0.945709,-148.477417,0.094623,0.000000
94.490005,57.792580,-148.566376,0.016931,0.003723,0.094571,257.074219,13.095985,0.945709,-148.566376,0.094623,0.000000
94.750008,57.751244,-148.477417,0.016918,0.003723,0.094571,256.890350,13.086618,0.945709,-148.477417,0.094623,0.000000
95.010002,57.718102,-148.521896,0.016931,0.003723,0.094571,256.742950,13.079109,0.945709,-148.521896,0.094623,0.000000
95.270004,57.666344,-148.521896,0.016931,0.003723,0.094571,256.512695,13.067381,0.945709,-148.521896,0.094623,0.000000
95.530006,57.634689,-148.521896,0.016953,0.003723,0.094571,256.371887,13.060207,0.945709,-148.521896,0.094623,0.000000
95.790001,57.591125,-148.521896,0.016953,0.003723,0.094571,256.178131,13.050336,0.945709,-148.521896,0.094623,0.000000
96.050003,57.566544,-148.521896,0.016914,0.003723,0.094571,256.068787,13.044765,0.945709,-148.521896,0.094623,0.000000
96.310005,57.519997,-148.566376,0.016944,0.003723,0.094571,255.861725,13.034217,0.945709,-148.566376,0.094623,0.000000
96.570007,57.478668,-148.566376,0.016901,0.003723,0.094571,255.677887,13.024852,0.945709,-148.566376,0.094623,0.000000
96.830002,57.452972,-148.521896,0.016914,0.003723,0.094571,255.563583,13.019030,0.945709,-148.521896,0.094623,0.000000
97.090004,57.412010,-148.610855,0.016936,0.003723,0.094571,255.381378,13.009748,0.945709,-148.610855,0.094623,0.000000
97.350006,57.376266,-148.566376,0.016931,0.003723,0.094571,255.222382,13.001648,0.945709,-148.566376,0.094623,0.000000
97.610008,57.328224,-148.566376,0.016927,0.003723,0.094571,255.008682,12.990762,0.945709,-148.566376,0.094623,0.000000
97.870003,57.314079,-148.566376,0.016931,0.003723,0.094571,254.945755,12.987556,0.945709,-148.566376,0.094623,0.000000
98.130005,57.269020,-148.566376,0.016944,0.003723,0.094571,254.745331,12.977345,0.945709,-148.566376,0.094623,0.000000
98.390007,57.233643,-148.610855,0.016944,0.003723,0.094571,254.587952,12.969329,0.945709,-148.610855,0.094623,0.000000
98.650002,57.210930,-148.610855,0.016931,0.003723,0.094571,254.486923,12.964182,0.945709,-148.610855,0.094623,0.000000
98.910004,57.175186,-148.610855,0.016927,0.003723,0.094571,254.327927,12.956082,0.945709,-148.610855,0.094623,0.000000
99.170006,57.142784,-148.610855,0.016936,0.003723,0.094571,254.183792,12.948739,0.945709,-148.610855,0.094623,0.000000
99.430008,57.099594,-148.566376,0.016944,0.003723,0.094571,253.991684,12.938952,0.945709,-148.566376,0.094623,0.000000
99.690002,57.078735,-148.655334,0.016940,0.003723,0.094571,253.898895,12.934226,0.945709,-148.655334,0.094623,0.000000
99.950005,57.050064,-148.610855,0.016944,0.003723,0.094571,253.771362,12.927730,0.945709,-148.610855,0.094623,0.000000
100.210007,57.025116,-148.655334,0.016931,0.003723,0.094571,253.660385,12.922076,0.945709,-148.655334,0.094623,0.000000
100.470001,56.995697,-148.655334,0.016931,0.003723,0.094571,253.529526,12.915410,0.945709,-148.655334,0.094623,0.000000
100.730003,56.974846,-148.610855,0.016927,0.003723,0.094571,253.436768,12.910685,0.945709,-148.610855,0.094623,0.000000
100.990005,56.934258,-148.655334,0.016918,0.003723,0.094571,253.256226,12.901487,0.945709,-148.655334,0.094623,0.000000
101.250008,56.902603,-148.655334,0.016927,0.003723,0.094571,253.115417,12.894315,0.945709,-148.655334,0.094623,0.000000
101.510002,56.872818,-148.744293,0.016944,0.003723,0.094571,252.982925,12.887565,0.945709,-148.744293,0.094623,0.000000
101.770004,56.858665,-148.655334,0.016923,0.003723,0.094571,252.919983,12.884358,0.945709,-148.655334,0.094623,0.000000
102.030006,56.821426,-148.655334,0.016966,0.003723,0.094571,252.754333,12.875918,0.945709,-148.655334,0.094623,0.000000
102.290009,56.785309,-148.744293,0.016936,0.003723,0.094571,252.593674,12.867735,0.945709,-148.744293,0.094623,0.000000
102.550003,56.776001,-148.699814,0.016927,0.003723,0.094571,252.552261,12.865625,0.945709,-148.699814,0.094623,0.000000
102.810005,56.726471,-148.699814,0.016931,0.003723,0.094571,252.331940,12.854403,0.945709,-148.699814,0.094623,0.000000
103.070007,56.708969,-148.744293,0.016936,0.003723,0.094571,252.254089,12.850436,0.945709,-148.744293,0.094623,0.000000
103.330002,56.689240,-148.699814,0.016931,0.003723,0.094571,252.166336,12.845965,0.945709,-148.699814,0.094623,0.000000
103.590004,56.648277,-148.744293,0.016940,0.003723,0.094571,251.984116,12.836682,0.945709,-148.744293,0.094623,0.000000
103.850006,56.624069,-148.744293,0.016923,0.003723,0.094571,251.876434,12.831198,0.945709,-148.744293,0.094623,0.000000
104.110008,56.606941,-148.788788,0.016927,0.003723,0.094571,251.800247,12.827316,0.945709,-148.788788,0.094623,0.000000
104.370003,56.576035,-148.788788,0.016931,0.003723,0.094571,251.662766,12.820312,0.945709,-148.788788,0.094623,0.000000
104.630005,56.552200,-148.744293,0.016940,0.003723,0.094571,251.556747,12.814912,0.945709,-148.744293,0.094623,0.000000
104.890007,56.527252,-148.833267,0.016953,0.003723,0.094571,251.445770,12.809258,0.945709,-148.833267,0.094623,0.000000
105.150002,56.501930,-148.788788,0.016940,0.003723,0.094571,251.333145,12.803520,0.945709,-148.788788,0.094623,0.000000
105.410004,56.496346,-148.788788,0.016931,0.003723,0.094571,251.308289,12.802255,0.945709,-148.788788,0.094623,0.000000
105.670006,56.465813,-148.744293,0.016953,0.003723,0.094571,251.172485,12.795336,0.945709,-148.744293,0.094623,0.000000
105.930008,56.446075,-148.788788,0.016918,0.003723,0.094571,251.084686,12.790863,0.945709,-148.788788,0.094623,0.000000
106.190002,56.411446,-148.833267,0.016918,0.003723,0.094571,250.930649,12.783017,0.945709,-148.833267,0.094623,0.000000
106.450005,56.410706,-148.788788,0.016936,0.003723,0.094571,250.927353,12.782848,0.945709,-148.788788,0.094623,0.000000
106.710007,56.370483,-148.877747,0.016936,0.003723,0.094571,250.748428,12.773734,0.945709,-148.877747,0.094623,0.000000
106.970009,56.368248,-148.833267,0.016936,0.003723,0.094571,250.738495,12.773228,0.945709,-148.833267,0.094623,0.000000
107.230003,56.340698,-148.833267,0.016944,0.003723,0.094571,250.615936,12.766985,0.945709,-148.833267,0.094623,0.000000
107.490005,56.319099,-148.833267,0.016953,0.003723,0.094571,250.519867,12.762090,0.945709,-148.833267,0.094623,0.000000
107.750008,56.299362,-148.833267,0.016927,0.003723,0.094571,250.432068,12.757618,0.945709,-148.833267,0.094623,0.000000
108.010002,56.263985,-148.922226,0.016940,0.003723,0.094571,250.274704,12.749601,0.945709,-148.922226,0.094623,0.000000
108.270004,56.256165,-148.833267,0.016940,0.003723,0.094571,250.239914,12.747828,0.945709,-148.833267,0.094623,0.000000
108.530006,56.228615,-148.833267,0.016949,0.003723,0.094571,250.117371,12.741587,0.945709,-148.833267,0.094623,0.000000
108.790009,56.226379,-148.877747,0.016923,0.003723,0.094571,250.107422,12.741080,0.945709,-148.877747,0.094623,0.000000
108.800003,56.231216,-148.833267,0.016931,0.003723,0.094571,250.128937,12.742176,0.945709,-148.833267,0.094623,0.000000