File: Data/compression 15/AutoNoHeating-17-15-reverse-shortpurge-4_08262024_193600.csv
Time (sec),S:Load (lbs),S:HL1 (DIM),S:LVDT (in),S:Position (in),Ch:Position (mm),Ch:Load (N),Ch:Stress (MPa),Ch:Strain (mm/mm),Ch:HL1 (DIM),Set Point (),Cycles ()
0.110000,0.015266,-105.464333,-0.011482,-0.006689,-0.169907,0.067908,0.003459,-1.699069,-105.464333,-0.169629,0.000000
0.530000,0.005585,-105.553299,-0.011477,-0.006580,-0.167123,0.024842,0.001266,-1.671231,-105.553299,-0.166299,0.000000
0.950000,0.046173,-105.553299,-0.011275,-0.006319,-0.160506,0.205388,0.010463,-1.605061,-105.553299,-0.159309,0.000000
1.370000,0.011543,-105.597778,-0.011003,-0.006047,-0.153594,0.051347,0.002616,-1.535943,-105.597778,-0.152302,0.000000
1.790000,-0.006332,-105.597778,-0.010705,-0.005771,-0.146587,-0.028168,-0.001435,-1.465872,-105.597778,-0.145312,0.000000
2.210000,-0.056229,-105.642258,-0.010434,-0.005494,-0.139554,-0.250117,-0.012742,-1.395540,-105.642258,-0.138323,0.000000
2.630000,0.004471,-105.686737,-0.010128,-0.005216,-0.132477,0.019887,0.001013,-1.324774,-105.686737,-0.131315,0.000000
3.050000,0.030167,-105.686737,-0.009865,-0.004939,-0.125453,0.134188,0.006836,-1.254529,-105.686737,-0.124325,0.000000
3.470000,0.040962,-105.775703,-0.009580,-0.004667,-0.118532,0.182209,0.009282,-1.185324,-105.775703,-0.117318,0.000000
3.890000,0.000748,-105.820183,-0.009296,-0.004394,-0.111603,0.003326,0.000169,-1.116033,-105.820183,-0.110328,0.000000
4.310000,-0.033516,-105.864662,-0.009011,-0.004120,-0.104639,-0.149086,-0.007595,-1.046395,-105.864662,-0.103339,0.000000
4.730000,0.006706,-105.820183,-0.008718,-0.003837,-0.097450,0.029831,0.001520,-0.974501,-105.820183,-0.096331,0.000000
5.150000,0.006332,-105.909142,-0.008451,-0.003562,-0.090469,0.028168,0.001435,-0.904690,-105.909142,-0.089342,0.000000
5.570000,0.021973,-105.953629,-0.008162,-0.003288,-0.083505,0.097739,0.004979,-0.835052,-105.953629,-0.082334,0.000000
5.990000,0.024948,-105.998108,-0.007869,-0.003014,-0.076550,0.110975,0.005653,-0.765500,-105.998108,-0.075345,0.000000
6.410000,0.000374,-106.042587,-0.007584,-0.002740,-0.069595,0.001663,0.000085,-0.695949,-106.042587,-0.068337,0.000000
6.830000,0.023834,-105.998108,-0.007295,-0.002464,-0.062588,0.106020,0.005401,-0.625877,-105.998108,-0.061348,0.000000
7.250000,-0.000000,-106.131546,-0.007011,-0.002182,-0.055424,-0.000000,-0.000000,-0.554244,-106.131546,-0.054358,0.000000
7.670001,-0.000374,-106.131546,-0.006722,-0.001917,-0.048686,-0.001663,-0.000085,-0.486861,-106.131546,-0.047351,0.000000
8.090000,0.017876,-106.176033,-0.006450,-0.001640,-0.041653,0.079515,0.004051,-0.416528,-106.176033,-0.040361,0.000000
8.510000,0.024208,-106.220512,-0.006157,-0.001362,-0.034585,0.107683,0.005486,-0.345850,-106.220512,-0.033354,0.000000
8.930000,0.029045,-106.264992,-0.005877,-0.001087,-0.027612,0.129199,0.006582,-0.276125,-106.264992,-0.026364,0.000000
9.350000,0.048782,-106.309471,-0.005605,-0.000812,-0.020623,0.216995,0.011054,-0.206226,-106.309471,-0.019356,0.000000
9.770000,0.036118,-106.353951,-0.005320,-0.000540,-0.013728,0.160659,0.008184,-0.137282,-106.353951,-0.012367,0.000000
10.190001,0.016388,-106.442917,-0.005044,-0.000264,-0.006712,0.072897,0.003714,-0.067123,-106.442917,-0.005377,0.000000
10.610001,0.076714,-106.487396,-0.004881,-0.000000,-0.000000,0.341239,0.017384,-0.000000,-106.487396,0.000217,0.000000
11.030001,0.099426,-106.442917,-0.004868,-0.000000,-0.000000,0.442270,0.022530,-0.000000,-106.442917,0.000321,0.000000
11.450001,0.085274,-106.442917,-0.004876,-0.000000,-0.000000,0.379317,0.019323,-0.000000,-106.442917,0.001023,0.000000
11.870001,0.121391,-106.576355,-0.004885,0.000020,0.000503,0.539975,0.027508,0.005030,-106.576355,0.001726,0.000000
12.290001,0.368652,-106.576355,-0.004829,0.000055,0.001405,1.639848,0.083538,0.014049,-106.576355,0.002428,0.000000
12.710001,0.654633,-106.531876,-0.004812,0.000085,0.002168,2.911951,0.148342,0.021681,-106.531876,0.003122,0.000000
13.130001,0.893326,-106.620842,-0.004786,0.000109,0.002775,3.973712,0.202431,0.027751,-106.620842,0.003824,0.000000
13.550000,1.274261,-106.665321,-0.004790,0.000135,0.003434,5.668198,0.288752,0.034342,-106.665321,0.004527,0.000000
13.970000,1.795212,-106.709801,-0.004743,0.000165,0.004180,7.985501,0.406801,0.041800,-106.709801,0.005221,0.000000
14.390000,2.174660,-106.843246,-0.004721,0.000192,0.004882,9.673369,0.492785,0.048825,-106.843246,0.005923,0.000000
14.810000,2.689278,-106.798767,-0.004691,0.000217,0.005516,11.962504,0.609399,0.055156,-106.798767,0.006626,0.000000
15.230000,3.232567,-106.798767,-0.004661,0.000245,0.006235,14.379175,0.732510,0.062354,-106.798767,0.007328,0.000000
15.650001,3.780701,-106.887726,-0.004652,0.000273,0.006929,16.817396,0.856719,0.069291,-106.887726,0.008022,0.000000
16.070002,4.455811,-106.887726,-0.004631,0.000298,0.007571,19.820435,1.009701,0.075709,-106.887726,0.008724,0.000000
16.490002,5.112679,-106.976685,-0.004596,0.000332,0.008429,22.742331,1.158549,0.084294,-106.976685,0.009427,0.000000
16.910002,5.769913,-107.021172,-0.004579,0.000364,0.009236,25.665854,1.307481,0.092360,-107.021172,0.010121,0.000000
17.330000,6.335175,-106.976685,-0.004553,0.000391,0.009930,28.180264,1.435571,0.099297,-106.976685,0.010823,0.000000
17.750000,6.621529,-107.021172,-0.004523,0.000409,0.010389,29.454031,1.500460,0.103894,-107.021172,0.011525,0.000000
18.170000,7.316750,-107.021172,-0.004510,0.000442,0.011222,32.546528,1.657999,0.112219,-107.021172,0.012228,0.000000
18.590000,7.883499,-107.154610,-0.004480,0.000470,0.011942,35.067554,1.786427,0.119417,-107.154610,0.012922,0.000000
19.010000,8.370934,-107.154610,-0.004441,0.000499,0.012670,37.235771,1.896881,0.126702,-107.154610,0.013624,0.000000
19.430000,8.814430,-107.199089,-0.004419,0.000525,0.013329,39.208546,1.997378,0.133293,-107.199089,0.014327,0.000000
19.850000,9.236328,-107.199089,-0.004398,0.000549,0.013954,41.085239,2.092982,0.139537,-107.199089,0.015029,0.000000
20.270000,9.926704,-107.243576,-0.004368,0.000580,0.014743,44.156185,2.249424,0.147428,-107.243576,0.015723,0.000000
20.690001,10.406693,-107.332535,-0.004333,0.000611,0.015515,46.291279,2.358190,0.155147,-107.332535,0.016425,0.000000
21.110001,10.893013,-107.332535,-0.004324,0.000640,0.016260,48.454540,2.468392,0.162605,-107.332535,0.017128,0.000000
21.530001,11.085899,-107.421494,-0.004290,0.000661,0.016781,49.312542,2.512101,0.167808,-107.421494,0.017821,0.000000
21.950001,11.517853,-107.421494,-0.004268,0.000687,0.017440,51.233967,2.609983,0.174399,-107.421494,0.018524,0.000000
22.370001,12.025398,-107.465981,-0.004238,0.000717,0.018212,53.491642,2.724994,0.182117,-107.465981,0.019226,0.000000
22.790001,12.722481,-107.465981,-0.004217,0.000749,0.019018,56.592422,2.882955,0.190183,-107.465981,0.019929,0.000000
23.210001,13.130226,-107.554939,-0.004178,0.000777,0.019747,58.406162,2.975352,0.197467,-107.554939,0.020623,0.000000
23.630001,13.498505,-107.599419,-0.004161,0.000801,0.020354,60.044346,3.058805,0.203538,-107.599419,0.021325,0.000000
24.050001,13.692513,-107.643898,-0.004135,0.000822,0.020874,60.907337,3.102768,0.208741,-107.643898,0.022028,0.000000
24.470001,14.716530,-107.643898,-0.004113,0.000860,0.021845,65.462395,3.334813,0.218454,-107.643898,0.022721,0.000000
24.890001,14.741112,-107.732864,-0.004083,0.000884,0.022452,65.571739,3.340384,0.224525,-107.732864,0.023424,0.000000
25.310001,15.147369,-107.688385,-0.004053,0.000911,0.023146,67.378860,3.432443,0.231463,-107.688385,0.024126,0.000000
25.730001,15.541710,-107.732864,-0.004027,0.000937,0.023797,69.132980,3.521802,0.237967,-107.732864,0.024829,0.000000
26.150002,15.630333,-107.732864,-0.004010,0.000956,0.024291,69.527191,3.541884,0.242910,-107.732864,0.025522,0.000000
26.570002,16.426468,-107.821823,-0.003980,0.000988,0.025089,73.068581,3.722291,0.250888,-107.821823,0.026225,0.000000
26.990002,16.775383,-107.910789,-0.003967,0.001017,0.025826,74.620628,3.801356,0.258260,-107.910789,0.026927,0.000000
27.410002,17.140678,-107.910789,-0.003928,0.001046,0.026563,76.245544,3.884133,0.265631,-107.910789,0.027630,0.000000
27.830002,17.436340,-107.910789,-0.003893,0.001073,0.027257,77.560715,3.951131,0.272569,-107.910789,0.028324,0.000000
28.250002,17.571884,-107.955269,-0.003876,0.001095,0.027803,78.163643,3.981846,0.278033,-107.955269,0.029026,0.000000
28.670002,18.212364,-107.955269,-0.003846,0.001130,0.028714,81.012642,4.126980,0.287138,-107.955269,0.029728,0.000000
29.090002,17.806480,-108.088715,-0.003803,0.001143,0.029043,79.207184,4.035006,0.290434,-108.088715,0.030422,0.000000
29.510002,18.879654,-108.133194,-0.003790,0.001187,0.030145,83.980896,4.278191,0.301448,-108.133194,0.031125,0.000000
29.930002,19.073288,-108.177673,-0.003747,0.001207,0.030648,84.842224,4.322069,0.306478,-108.177673,0.031827,0.000000
30.350002,19.669830,-108.222153,-0.003725,0.001241,0.031515,87.495773,4.457247,0.315150,-108.222153,0.032530,0.000000
30.770002,19.597595,-108.177673,-0.003695,0.001261,0.032035,87.174454,4.440879,0.320353,-108.177673,0.033223,0.000000
31.190001,19.946503,-108.311119,-0.003669,0.001293,0.032833,88.726479,4.519942,0.328332,-108.311119,0.033926,0.000000
31.610001,19.978897,-108.355598,-0.003652,0.001311,0.033310,88.870575,4.527283,0.333101,-108.355598,0.034628,0.000000
32.030003,20.799240,-108.311119,-0.003609,0.001351,0.034307,92.519638,4.713175,0.343074,-108.311119,0.035331,0.000000
32.450001,20.721413,-108.311119,-0.003583,0.001370,0.034802,92.173447,4.695539,0.348018,-108.311119,0.036025,0.000000
32.870003,20.732582,-108.400078,-0.003557,0.001393,0.035383,92.223129,4.698070,0.353828,-108.400078,0.036727,0.000000
33.290001,21.990082,-108.489037,-0.003510,0.001436,0.036467,97.816772,4.983024,0.364668,-108.489037,0.037429,0.000000
33.710003,21.814323,-108.489037,-0.003479,0.001457,0.037013,97.034958,4.943196,0.370132,-108.489037,0.038123,0.000000
34.130001,22.115204,-108.489037,-0.003436,0.001488,0.037785,98.373337,5.011377,0.377850,-108.489037,0.038826,0.000000
34.550003,22.245163,-108.578003,-0.003428,0.001515,0.038470,98.951424,5.040826,0.384701,-108.578003,0.039528,0.000000
34.970001,22.263779,-108.622482,-0.003406,0.001535,0.038999,99.034233,5.045044,0.389991,-108.622482,0.040231,0.000000
35.390003,23.133270,-108.622482,-0.003372,0.001571,0.039910,102.901924,5.242074,0.399097,-108.622482,0.040924,0.000000
35.810001,23.149651,-108.622482,-0.003324,0.001595,0.040508,102.974792,5.245786,0.405081,-108.622482,0.041627,0.000000
36.230003,23.320946,-108.711441,-0.003298,0.001621,0.041176,103.736748,5.284602,0.411759,-108.711441,0.042329,0.000000
36.650002,23.906685,-108.755928,-0.003255,0.001655,0.042026,106.342247,5.417332,0.420258,-108.755928,0.043023,0.000000
37.070004,23.949883,-108.800407,-0.003247,0.001678,0.042615,106.534401,5.427121,0.426155,-108.800407,0.043726,0.000000
37.490002,24.470833,-108.889366,-0.003208,0.001711,0.043465,108.851700,5.545170,0.434653,-108.889366,0.044428,0.000000
37.910004,25.018959,-108.889366,-0.003178,0.001740,0.044202,111.289886,5.669377,0.442025,-108.889366,0.045130,0.000000
38.330002,25.055458,-108.933846,-0.003143,0.001768,0.044896,111.452248,5.677648,0.448963,-108.933846,0.045824,0.000000
38.750000,25.293030,-108.933846,-0.003117,0.001795,0.045590,112.509018,5.731482,0.455901,-108.933846,0.046527,0.000000
39.170002,25.521667,-108.978333,-0.003096,0.001819,0.046214,113.526047,5.783292,0.462145,-108.978333,0.047229,0.000000
39.590000,25.863876,-109.156258,-0.003053,0.001847,0.046917,115.048271,5.860838,0.469169,-109.156258,0.047932,0.000000
40.010002,26.502869,-109.067291,-0.003027,0.001878,0.047697,117.890648,6.005636,0.476974,-109.067291,0.048625,0.000000
40.430000,26.546432,-109.156258,-0.002997,0.001902,0.048313,118.084427,6.015508,0.483131,-109.156258,0.049328,0.000000
40.850002,26.943756,-109.156258,-0.002966,0.001931,0.049050,119.851814,6.105542,0.490503,-109.156258,0.050030,0.000000
41.270000,27.040947,-109.111771,-0.002928,0.001954,0.049640,120.284142,6.127566,0.496400,-109.111771,0.050724,0.000000
41.690002,27.592056,-109.200737,-0.002915,0.001983,0.050368,122.735596,6.252449,0.503685,-109.200737,0.051426,0.000000
42.110001,28.356537,-109.289696,-0.002876,0.002016,0.051218,126.136177,6.425683,0.512183,-109.289696,0.052129,0.000000
42.530003,28.520752,-109.289696,-0.002833,0.002043,0.051886,126.866638,6.462894,0.518861,-109.289696,0.052831,0.000000
42.950001,28.753113,-109.334175,-0.002811,0.002069,0.052563,127.900230,6.515549,0.525626,-109.334175,0.053525,0.000000
43.370003,28.467133,-109.334175,-0.002790,0.002089,0.053066,126.628128,6.450745,0.530655,-109.334175,0.054228,0.000000
43.790001,30.280960,-109.423141,-0.002768,0.002128,0.054046,134.696442,6.861763,0.540455,-109.423141,0.054930,0.000000
44.210003,30.097008,-109.423141,-0.002721,0.002153,0.054687,133.878174,6.820079,0.546872,-109.423141,0.055624,0.000000
44.630001,30.526352,-109.467621,-0.002686,0.002180,0.055381,135.787994,6.917370,0.553810,-109.467621,0.056326,0.000000
45.050003,30.543106,-109.556580,-0.002643,0.002204,0.055971,135.862518,6.921167,0.559707,-109.556580,0.057029,0.000000
45.470001,30.145416,-109.556580,-0.002634,0.002221,0.056413,134.093506,6.831049,0.564130,-109.556580,0.057731,0.000000
45.890003,31.920143,-109.601067,-0.002583,0.002266,0.057566,141.987885,7.233208,0.575664,-109.601067,0.058425,0.000000
46.310001,31.872108,-109.690025,-0.002565,0.002288,0.058121,141.774216,7.222323,0.581215,-109.690025,0.059127,0.000000
46.730003,32.057549,-109.690025,-0.002514,0.002314,0.058763,142.599091,7.264345,0.587632,-109.690025,0.059830,0.000000
47.150002,32.443321,-109.645546,-0.002496,0.002340,0.059431,144.315094,7.351761,0.594310,-109.645546,0.060532,0.000000
47.570004,31.954399,-109.734505,-0.002466,0.002356,0.059830,142.140259,7.240970,0.598299,-109.734505,0.061226,0.000000
47.990002,33.328827,-109.823471,-0.002440,0.002390,0.060706,148.254028,7.552420,0.607058,-109.823471,0.061929,0.000000
48.410004,34.712189,-109.867950,-0.002414,0.002429,0.061703,154.407532,7.865894,0.617031,-109.867950,0.062631,0.000000
48.830002,34.927795,-109.867950,-0.002380,0.002453,0.062319,155.366592,7.914752,0.623188,-109.867950,0.063325,0.000000
49.250004,34.798210,-109.867950,-0.002341,0.002474,0.062831,154.790176,7.885387,0.628305,-109.867950,0.064027,0.000000
49.670002,35.840851,-110.045876,-0.002307,0.002509,0.063732,159.428070,8.121653,0.637324,-110.045876,0.064730,0.000000
50.090004,36.071350,-110.045876,-0.002276,0.002532,0.064322,160.453384,8.173884,0.643221,-110.045876,0.065432,0.000000
50.510002,35.673653,-110.045876,-0.002242,0.002555,0.064903,158.684326,8.083765,0.649032,-110.045876,0.066126,0.000000
50.930004,36.802315,-110.090355,-0.002212,0.002590,0.065788,163.704865,8.339524,0.657877,-110.090355,0.066828,0.000000
51.350002,37.672920,-110.090355,-0.002173,0.002613,0.066377,167.577515,8.536805,0.663775,-110.090355,0.067531,0.000000
51.770004,38.065773,-110.134834,-0.002160,0.002639,0.067037,169.325012,8.625828,0.670365,-110.134834,0.068225,0.000000
52.190002,37.893738,-110.179314,-0.002126,0.002660,0.067557,168.559769,8.586843,0.675569,-110.179314,0.068927,0.000000
52.610001,39.099854,-110.223793,-0.002082,0.002699,0.068554,173.924835,8.860154,0.685542,-110.223793,0.069630,0.000000
53.030003,40.065041,-110.223793,-0.002048,0.002727,0.069257,178.218201,9.078868,0.692566,-110.223793,0.070332,0.000000
53.450001,40.575569,-110.268280,-0.002001,0.002754,0.069942,180.489151,9.194555,0.699417,-110.268280,0.071026,0.000000
53.870003,40.847397,-110.312759,-0.001975,0.002782,0.070653,181.698303,9.256152,0.706529,-110.312759,0.071728,0.000000
54.290001,41.064865,-110.401718,-0.001944,0.002802,0.071173,182.665649,9.305431,0.711732,-110.401718,0.072431,0.000000
54.710003,42.534615,-110.446205,-0.001914,0.002838,0.072075,189.203415,9.638481,0.720751,-110.446205,0.073133,0.000000
55.130001,43.134140,-110.490685,-0.001880,0.002869,0.072882,191.870239,9.774335,0.728816,-110.490685,0.073827,0.000000
55.550003,43.377296,-110.490685,-0.001858,0.002892,0.073463,192.951859,9.829436,0.734627,-110.490685,0.074529,0.000000
55.970001,43.563858,-110.579643,-0.001815,0.002918,0.074113,193.781723,9.871712,0.741131,-110.579643,0.075232,0.000000
56.390003,44.110870,-110.535164,-0.001785,0.002942,0.074738,196.214951,9.995667,0.747375,-110.535164,0.075926,0.000000
56.810001,45.087234,-110.624123,-0.001759,0.002973,0.075518,200.558029,10.216913,0.755180,-110.624123,0.076628,0.000000
57.230003,45.010521,-110.579643,-0.001720,0.002997,0.076125,200.216797,10.199531,0.761251,-110.579643,0.077331,0.000000
57.650002,46.289619,-110.668610,-0.001690,0.003028,0.076906,205.906509,10.489378,0.769056,-110.668610,0.078033,0.000000
58.070004,46.950211,-110.713089,-0.001660,0.003055,0.077608,208.844971,10.639070,0.776080,-110.713089,0.078727,0.000000
58.490002,47.433922,-110.757568,-0.001630,0.003081,0.078250,210.996628,10.748681,0.782498,-110.757568,0.079429,0.000000
58.910004,48.904793,-110.891014,-0.001600,0.003118,0.079186,217.539383,11.081985,0.791864,-110.891014,0.080132,0.000000
59.330002,49.339355,-110.802048,-0.001565,0.003145,0.079880,219.472412,11.180458,0.798802,-110.802048,0.080825,0.000000
59.750004,49.733696,-110.846527,-0.001526,0.003170,0.080531,221.226532,11.269816,0.805306,-110.846527,0.081528,0.000000
60.170002,50.449020,-110.846527,-0.001496,0.003197,0.081216,224.408447,11.431911,0.812157,-110.846527,0.082230,0.000000
60.590004,50.807991,-110.935493,-0.001475,0.003223,0.081875,226.005234,11.513255,0.818748,-110.935493,0.082933,0.000000
61.010002,51.490547,-111.024452,-0.001427,0.003249,0.082517,229.041397,11.667924,0.825165,-111.024452,0.083627,0.000000
61.430004,52.552185,-110.979973,-0.001410,0.003282,0.083366,233.763794,11.908495,0.833664,-110.979973,0.084329,0.000000
61.850002,52.888809,-111.068932,-0.001371,0.003307,0.084008,235.261169,11.984776,0.840082,-111.068932,0.085031,0.000000
62.270004,53.657387,-111.068932,-0.001358,0.003335,0.084719,238.679977,12.158937,0.847193,-111.068932,0.085734,0.000000
62.690002,53.815643,-111.202377,-0.001319,0.003357,0.085257,239.383942,12.194799,0.852570,-111.202377,0.086428,0.000000
63.110004,55.450356,-111.157898,-0.001285,0.003391,0.086142,246.655502,12.565230,0.861415,-111.157898,0.087130,0.000000
63.530003,56.313515,-111.202377,-0.001237,0.003420,0.086861,250.495026,12.760824,0.868613,-111.202377,0.087833,0.000000
63.950005,56.977081,-111.202377,-0.001233,0.003445,0.087494,253.446716,12.911191,0.874944,-111.202377,0.088526,0.000000
64.370003,57.764282,-111.291336,-0.001216,0.003471,0.088162,256.948364,13.089574,0.881622,-111.291336,0.089229,0.000000
64.790001,57.823486,-111.335823,-0.001173,0.003489,0.088613,257.211700,13.102989,0.886131,-111.335823,0.089931,0.000000
65.210007,60.211510,-111.380302,-0.001147,0.003531,0.089680,267.834167,13.644123,0.896798,-111.380302,0.090634,0.000000
65.630005,60.974129,-111.380302,-0.001108,0.003556,0.090322,271.226471,13.816936,0.903216,-111.380302,0.091328,0.000000
66.050003,61.916977,-111.380302,-0.001099,0.003583,0.091015,275.420471,14.030587,0.910153,-111.380302,0.092030,0.000000
66.470001,62.497131,-111.469261,-0.001082,0.003606,0.091596,278.001129,14.162052,0.915964,-111.469261,0.092732,0.000000
66.889999,62.463623,-111.558228,-0.001052,0.003626,0.092091,277.852081,14.154460,0.920907,-111.558228,0.093426,0.000000
67.310005,65.616493,-111.602707,-0.001013,0.003668,0.093157,291.876740,14.868910,0.931574,-111.602707,0.094129,0.000000
67.730003,65.675697,-111.602707,-0.000987,0.003674,0.093331,292.140106,14.882326,0.933308,-111.602707,0.016390,0.000000
68.150002,66.401833,-111.602707,-0.000961,0.003602,0.091501,295.370117,15.046870,0.915010,-111.602707,294.500488,0.000000
68.570000,65.065758,-111.691666,-0.000957,0.003702,0.094042,289.426941,14.744112,0.940419,-111.691666,294.500488,0.000000
68.990005,65.753151,-111.736153,-0.000949,0.003723,0.094571,292.484619,14.899878,0.945710,-111.736153,294.500488,0.000000
69.410004,65.321205,-111.736153,-0.000931,0.003731,0.094779,290.563232,14.801996,0.947791,-111.736153,294.500488,0.000000
69.830002,65.038948,-111.736153,-0.000923,0.003741,0.095013,289.307678,14.738036,0.950132,-111.736153,294.500488,0.000000
70.250000,65.280617,-111.825111,-0.000905,0.003753,0.095325,290.382690,14.792799,0.953255,-111.825111,294.500488,0.000000
70.670006,65.648521,-111.780632,-0.000905,0.003767,0.095672,292.019196,14.876167,0.956723,-111.780632,294.500488,0.000000
71.090004,64.790947,-111.914070,-0.000897,0.003767,0.095681,288.204529,14.681838,0.956810,-111.914070,294.500488,0.000000
71.510002,66.388420,-111.958557,-0.000862,0.003742,0.095039,295.310455,15.043831,0.950393,-111.958557,294.500488,0.000000
71.930000,65.452660,-111.914070,-0.000867,0.003750,0.095247,291.147980,14.831784,0.952474,-111.914070,294.500488,0.000000
72.350006,64.969688,-112.003036,-0.000841,0.003789,0.096236,288.999603,14.722342,0.962360,-112.003036,294.500488,0.000000
72.770004,65.200935,-112.003036,-0.000862,0.003799,0.096505,290.028259,14.774743,0.965049,-112.003036,294.500488,0.000000
73.190002,65.346901,-112.091995,-0.000845,0.003814,0.096878,290.677521,14.807819,0.968778,-112.091995,294.500488,0.000000
73.610001,65.241524,-112.136475,-0.000836,0.003814,0.096878,290.208801,14.783940,0.968778,-112.136475,294.500488,0.000000
74.030006,65.608299,-112.136475,-0.000819,0.003824,0.097138,291.840302,14.867053,0.971379,-112.136475,294.500488,0.000000
74.450005,65.294762,-112.136475,-0.000824,0.003827,0.097207,290.445618,14.796005,0.972073,-112.136475,294.500488,0.000000
74.870003,65.135017,-112.225441,-0.000811,0.003831,0.097311,289.735016,14.759806,0.973114,-112.225441,294.500488,0.000000
75.290001,65.161079,-112.269920,-0.000811,0.003840,0.097528,289.850952,14.765712,0.975282,-112.269920,294.500488,0.000000
75.710007,65.068367,-112.314400,-0.000789,0.003841,0.097554,289.438538,14.744702,0.975542,-112.314400,294.500488,0.000000
76.130005,65.307808,-112.358879,-0.000802,0.003848,0.097728,290.503632,14.798961,0.977277,-112.358879,294.500488,0.000000
76.550003,65.209129,-112.358879,-0.000789,0.003851,0.097814,290.064697,14.776600,0.978144,-112.358879,294.500488,0.000000
76.970001,65.096672,-112.358879,-0.000789,0.003856,0.097944,289.564453,14.751117,0.979445,-112.358879,294.500488,0.000000
77.390007,65.063896,-112.492325,-0.000785,0.003857,0.097979,289.418671,14.743690,0.979792,-112.492325,294.500488,0.000000
77.810005,65.091454,-112.492325,-0.000785,0.003862,0.098083,289.541260,14.749934,0.980832,-112.492325,294.500488,0.000000
78.230003,65.030006,-112.536804,-0.000772,0.003865,0.098179,289.267914,14.736011,0.981786,-112.536804,294.500488,0.000000
78.650002,65.206139,-112.536804,-0.000763,0.003869,0.098283,290.051392,14.775923,0.982827,-112.536804,294.500488,0.000000
79.070007,64.993523,-112.581284,-0.000776,0.003871,0.098326,289.105621,14.727742,0.983260,-112.581284,294.500488,0.000000
79.490005,65.514839,-112.714729,-0.000776,0.003880,0.098543,291.424561,14.845875,0.985429,-112.714729,294.500488,0.000000
79.910004,65.269081,-112.714729,-0.000763,0.003880,0.098543,290.331360,14.790185,0.985429,-112.714729,294.500488,0.000000
80.330002,65.002449,-112.759209,-0.000746,0.003880,0.098543,289.145325,14.729765,0.985429,-112.759209,294.500488,0.000000
80.750008,65.893547,-112.714729,-0.000750,0.003893,0.098890,293.109131,14.931691,0.988898,-112.714729,294.500488,0.000000
81.170006,65.822044,-112.759209,-0.000755,0.003893,0.098890,292.791077,14.915488,0.988898,-112.759209,294.500488,0.000000
81.590004,65.557655,-112.803696,-0.000759,0.003893,0.098890,291.615021,14.855577,0.988898,-112.803696,294.500488,0.000000
82.010002,65.314873,-112.892654,-0.000759,0.003894,0.098898,290.535065,14.800561,0.988984,-112.892654,294.500488,0.000000
82.430000,65.079903,-112.937134,-0.000737,0.003895,0.098924,289.489868,14.747316,0.989244,-112.937134,294.500488,0.000000
82.850006,64.916817,-112.937134,-0.000729,0.003895,0.098933,288.764435,14.710361,0.989331,-112.937134,294.500488,0.000000
83.270004,65.751671,-113.026100,-0.000742,0.003906,0.099202,292.478027,14.899541,0.992019,-113.026100,294.500488,0.000000
83.690002,65.558403,-113.026100,-0.000733,0.003906,0.099202,291.618347,14.855746,0.992019,-113.026100,294.500488,0.000000
84.110001,65.324928,-113.159538,-0.000733,0.003906,0.099202,290.579803,14.802840,0.992019,-113.159538,294.500488,0.000000
84.530006,65.117149,-113.070580,-0.000724,0.003906,0.099202,289.655548,14.755756,0.992019,-113.070580,294.500488,0.000000
84.950005,65.822426,-113.070580,-0.000729,0.003915,0.099445,292.792786,14.915575,0.994448,-113.070580,294.500488,0.000000
85.370003,65.648888,-113.115059,-0.000711,0.003915,0.099445,292.020844,14.876251,0.994448,-113.115059,294.500488,0.000000
85.790001,65.499947,-113.159538,-0.000711,0.003915,0.099445,291.358307,14.842500,0.994448,-113.159538,294.500488,0.000000
86.210007,65.291786,-113.248505,-0.000742,0.003915,0.099445,290.432373,14.795330,0.994448,-113.248505,294.500488,0.000000
86.630005,65.126823,-113.292984,-0.000720,0.003915,0.099445,289.698578,14.757949,0.994448,-113.292984,294.500488,0.000000
87.050003,64.969307,-113.337463,-0.000720,0.003915,0.099445,288.997925,14.722256,0.994448,-113.337463,294.500488,0.000000
87.470001,65.868965,-113.337463,-0.000711,0.003926,0.099731,292.999786,14.926121,0.997310,-113.337463,294.500488,0.000000
87.890007,65.726341,-113.337463,-0.000716,0.003926,0.099731,292.365356,14.893802,0.997310,-113.337463,294.500488,0.000000
88.310005,65.535316,-113.426422,-0.000707,0.003926,0.099731,291.515656,14.850515,0.997310,-113.426422,294.500488,0.000000
88.730003,65.376320,-113.470909,-0.000703,0.003926,0.099731,290.808380,14.814486,0.997310,-113.470909,294.500488,0.000000
89.150002,65.242256,-113.470909,-0.000707,0.003926,0.099731,290.212036,14.784107,0.997310,-113.470909,294.500488,0.000000
89.570007,65.073586,-113.515388,-0.000703,0.003926,0.099731,289.461761,14.745886,0.997310,-113.515388,294.500488,0.000000
89.990005,64.966331,-113.559868,-0.000716,0.003926,0.099731,288.984680,14.721581,0.997310,-113.559868,294.500488,0.000000
90.410004,64.797279,-113.648827,-0.000711,0.003926,0.099731,288.232697,14.683273,0.997310,-113.648827,294.500488,0.000000
90.830002,64.668434,-113.648827,-0.000698,0.003926,0.099731,287.659576,14.654077,0.997310,-113.648827,294.500488,0.000000
91.250008,64.517632,-113.693314,-0.000703,0.003927,0.099740,286.988770,14.619905,0.997396,-113.693314,294.500488,0.000000
91.670006,66.344856,-113.648827,-0.000707,0.003936,0.099982,295.116669,15.033959,0.999824,-113.648827,294.500488,0.000000
92.090004,66.165001,-113.782272,-0.000703,0.003935,0.099956,294.316620,14.993203,0.999564,-113.782272,294.500488,0.000000
92.510002,66.005623,-113.782272,-0.000703,0.003935,0.099939,293.607666,14.957088,0.999391,-113.782272,294.500488,0.000000
92.930008,65.867104,-113.782272,-0.000694,0.003935,0.099939,292.991516,14.925699,0.999391,-113.782272,294.500488,0.000000
93.350006,65.737892,-113.871231,-0.000690,0.003935,0.099939,292.416748,14.896420,0.999391,-113.871231,294.500488,0.000000
93.770004,65.562874,-113.871231,-0.000694,0.003935,0.099948,291.638214,14.856759,0.999478,-113.871231,294.500488,0.000000
94.190002,65.433296,-113.915718,-0.000698,0.003935,0.099948,291.061829,14.827397,0.999478,-113.915718,294.500488,0.000000
94.610008,65.313011,-114.049156,-0.000681,0.003936,0.099965,290.526794,14.800140,0.999651,-114.049156,294.500488,0.000000
95.030006,65.200188,-113.960197,-0.000686,0.003939,0.100052,290.024933,14.774573,1.000518,-113.960197,294.500488,0.000000
95.450005,65.059059,-114.049156,-0.000690,0.003939,0.100061,289.397156,14.742594,1.000605,-114.049156,294.500488,0.000000
95.870003,65.005058,-114.049156,-0.000694,0.003943,0.100156,289.156952,14.730357,1.001559,-114.049156,294.500488,0.000000
96.290001,64.928352,-114.138123,-0.000690,0.003943,0.100156,288.815735,14.712975,1.001559,-114.138123,294.500488,0.000000
96.710007,64.838615,-114.138123,-0.000686,0.003943,0.100165,288.416565,14.692640,1.001646,-114.138123,294.500488,0.000000
97.130005,65.552818,-114.182602,-0.000677,0.003953,0.100416,291.593506,14.854481,1.004161,-114.182602,294.500488,0.000000
97.550003,65.536430,-114.182602,-0.000686,0.003953,0.100416,291.520599,14.850768,1.004161,-114.182602,294.500488,0.000000
97.970001,65.468300,-114.182602,-0.000677,0.003953,0.100416,291.217529,14.835329,1.004161,-114.182602,294.500488,0.000000
98.390007,65.360680,-114.271561,-0.000694,0.003953,0.100416,290.738831,14.810942,1.004161,-114.271561,294.500488,0.000000
98.810005,65.284706,-114.360527,-0.000673,0.003953,0.100416,290.400879,14.793726,1.004161,-114.360527,294.500488,0.000000
99.230003,65.233696,-114.360527,-0.000686,0.003953,0.100416,290.173981,14.782166,1.004161,-114.360527,294.500488,0.000000
99.650002,65.116035,-114.360527,-0.000690,0.003953,0.100416,289.650604,14.755505,1.004161,-114.360527,294.500488,0.000000
100.070007,65.032616,-114.360527,-0.000673,0.003953,0.100416,289.279510,14.736601,1.004161,-114.360527,294.500488,0.000000
100.490005,64.954796,-114.405006,-0.000681,0.003953,0.100416,288.933350,14.718967,1.004161,-114.405006,294.500488,0.000000
100.910004,64.889626,-114.538452,-0.000673,0.003953,0.100416,288.643463,14.704200,1.004161,-114.538452,294.500488,0.000000
101.330002,64.775673,-114.582932,-0.000690,0.003953,0.100416,288.136597,14.678377,1.004161,-114.582932,294.500488,0.000000
101.750008,64.714607,-114.582932,-0.000690,0.003953,0.100416,287.864960,14.664539,1.004161,-114.582932,294.500488,0.000000
102.170006,64.641258,-114.627411,-0.000681,0.003953,0.100416,287.538666,14.647919,1.004161,-114.627411,294.500488,0.000000
102.590004,64.554115,-114.627411,-0.000677,0.003953,0.100416,287.151031,14.628171,1.004161,-114.627411,294.500488,0.000000
103.010002,64.480019,-114.716370,-0.000686,0.003953,0.100416,286.821442,14.611381,1.004161,-114.716370,294.500488,0.000000
103.430008,64.415962,-114.716370,-0.000673,0.003954,0.100425,286.536499,14.596866,1.004247,-114.716370,294.500488,0.000000
103.850006,64.329582,-114.716370,-0.000660,0.003954,0.100425,286.152283,14.577291,1.004247,-114.716370,294.500488,0.000000
104.270004,64.246910,-114.760857,-0.000690,0.003954,0.100425,285.784515,14.558558,1.004247,-114.760857,294.500488,0.000000
104.690002,66.720589,-114.805336,-0.000655,0.003834,0.097389,296.787994,15.119102,0.973894,-114.805336,294.500488,0.000000
105.110008,66.626747,-114.894295,-0.000668,0.003834,0.097389,296.370575,15.097836,0.973894,-114.894295,294.500488,0.000000
105.530006,66.493065,-114.938774,-0.000664,0.003834,0.097389,295.775940,15.067544,0.973894,-114.938774,294.500488,0.000000
105.950005,66.419701,-114.938774,-0.000651,0.003835,0.097398,295.449585,15.050920,0.973981,-114.938774,294.500488,0.000000
106.370003,66.338905,-114.938774,-0.000660,0.003835,0.097398,295.090179,15.032611,0.973981,-114.938774,294.500488,0.000000
106.790009,66.258842,-114.983261,-0.000651,0.003835,0.097398,294.734039,15.014468,0.973981,-114.983261,294.500488,0.000000
107.210007,66.162773,-115.116699,-0.000655,0.003835,0.097398,294.306702,14.992699,0.973981,-115.116699,294.500488,0.000000
107.630005,66.096855,-115.072220,-0.000651,0.003835,0.097398,294.013489,14.977761,0.973981,-115.072220,294.500488,0.000000
108.050003,66.026482,-115.116699,-0.000651,0.003835,0.097398,293.700470,14.961815,0.973981,-115.116699,294.500488,0.000000
108.470009,65.923332,-115.116699,-0.000642,0.003835,0.097415,293.241638,14.938440,0.974155,-115.116699,294.500488,0.000000
108.890007,65.855934,-115.161179,-0.000642,0.003840,0.097537,292.941833,14.923168,0.975369,-115.161179,294.500488,0.000000
109.310005,65.822426,-115.250145,-0.000651,0.003842,0.097589,292.792786,14.915575,0.975889,-115.250145,294.500488,0.000000
109.730003,65.759117,-115.339104,-0.000634,0.003861,0.098075,292.511169,14.901229,0.980746,-115.339104,294.500488,0.000000
110.150002,65.650749,-115.294624,-0.000638,0.003878,0.098491,292.029114,14.876672,0.984908,-115.294624,294.500488,0.000000
110.570007,65.577019,-115.294624,-0.000651,0.003930,0.099818,291.701141,14.859965,0.998177,-115.294624,294.500488,0.000000
110.990005,65.531227,-115.383591,-0.000638,0.003933,0.099887,291.497467,14.849588,0.998871,-115.383591,294.500488,0.000000
111.410004,65.469414,-115.472549,-0.000647,0.003933,0.099887,291.222504,14.835581,0.998871,-115.472549,294.500488,0.000000
111.830002,65.382271,-115.472549,-0.000634,0.003935,0.099956,290.834869,14.815834,0.999564,-115.472549,294.500488,0.000000
112.250008,65.314125,-115.472549,-0.000621,0.003940,0.100078,290.531738,14.800392,1.000779,-115.472549,294.500488,0.000000
112.670006,65.272423,-115.472549,-0.000638,0.003940,0.100078,290.346252,14.790943,1.000779,-115.472549,294.500488,0.000000
113.090004,65.242638,-115.517029,-0.000642,0.003942,0.100139,290.213745,14.784193,1.001385,-115.517029,294.500488,0.000000
113.510002,65.187523,-115.605995,-0.000638,0.003943,0.100147,289.968597,14.771704,1.001472,-115.605995,294.500488,0.000000
113.930008,65.183434,-115.605995,-0.000642,0.003956,0.100477,289.950378,14.770777,1.004768,-115.605995,294.500488,0.000000
114.350006,65.205025,-115.650475,-0.000638,0.003964,0.100685,290.046448,14.775670,1.006849,-115.650475,294.500488,0.000000
114.770004,65.142845,-115.694954,-0.000647,0.003964,0.100694,289.769836,14.761580,1.006936,-115.694954,294.500488,0.000000
115.190002,65.082146,-115.783913,-0.000629,0.003964,0.100694,289.499847,14.747825,1.006936,-115.783913,294.500488,0.000000
115.610008,65.021812,-115.783913,-0.000638,0.003964,0.100694,289.231476,14.734154,1.006936,-115.783913,294.500488,0.000000
116.030006,64.969688,-115.783913,-0.000638,0.003964,0.100694,288.999603,14.722342,1.006936,-115.783913,294.500488,0.000000
116.450005,64.925743,-115.783913,-0.000638,0.003964,0.100694,288.804138,14.712383,1.006936,-115.783913,294.500488,0.000000
116.870003,65.742729,-115.828400,-0.000642,0.003981,0.101127,292.438263,14.897515,1.011272,-115.828400,294.500488,0.000000
117.290009,65.723747,-115.961838,-0.000638,0.003981,0.101127,292.353821,14.893213,1.011272,-115.961838,294.500488,0.000000
117.710007,65.661552,-115.961838,-0.000634,0.003981,0.101127,292.077179,14.879121,1.011272,-115.961838,294.500488,0.000000
118.130005,65.626930,-116.006317,-0.000638,0.003981,0.101127,291.923157,14.871275,1.011272,-116.006317,294.500488,0.000000
118.550003,65.608681,-116.006317,-0.000634,0.003981,0.101127,291.841980,14.867140,1.011272,-116.006317,294.500488,0.000000
118.970009,65.566597,-116.050804,-0.000642,0.003981,0.101127,291.654785,14.857604,1.011272,-116.050804,294.500488,0.000000
119.390007,65.540901,-116.139763,-0.000647,0.003981,0.101127,291.540497,14.851781,1.011272,-116.139763,294.500488,0.000000
119.810005,65.502174,-116.139763,-0.000629,0.003981,0.101127,291.368225,14.843005,1.011272,-116.139763,294.500488,0.000000
120.230003,65.456383,-116.184242,-0.000629,0.003981,0.101127,291.164520,14.832628,1.011272,-116.184242,294.500488,0.000000
120.650009,65.384132,-116.184242,-0.000647,0.003981,0.101127,290.843140,14.816257,1.011272,-116.184242,294.500488,0.000000
121.070007,65.343544,-116.228722,-0.000634,0.003981,0.101127,290.662598,14.807058,1.011272,-116.228722,294.500488,0.000000
121.490005,65.308174,-116.317688,-0.000642,0.003981,0.101127,290.505280,14.799045,1.011272,-116.317688,294.500488,0.000000
121.910004,65.272423,-116.362167,-0.000638,0.003981,0.101127,290.346252,14.790943,1.011272,-116.362167,294.500488,0.000000
122.330009,65.227745,-116.317688,-0.000634,0.003982,0.101136,290.147491,14.780818,1.011359,-116.317688,294.500488,0.000000
122.750008,65.189766,-116.317688,-0.000642,0.003982,0.101136,289.978577,14.772212,1.011359,-116.317688,294.500488,0.000000
123.170006,65.168541,-116.451126,-0.000642,0.003982,0.101145,289.884155,14.767403,1.011445,-116.451126,294.500488,0.000000
123.590004,65.109703,-116.495613,-0.000660,0.003983,0.101171,289.622437,14.754069,1.011706,-116.495613,294.500488,0.000000
124.010002,65.112312,-116.540092,-0.000634,0.003984,0.101188,289.634033,14.754661,1.011879,-116.540092,294.500488,0.000000
124.430008,65.136131,-116.540092,-0.000642,0.003984,0.101197,289.739990,14.760058,1.011966,-116.540092,294.500488,0.000000
124.850006,65.108208,-116.629051,-0.000625,0.003984,0.101197,289.615784,14.753730,1.011966,-116.629051,294.500488,0.000000
125.270004,65.080650,-116.629051,-0.000642,0.003984,0.101197,289.493195,14.747486,1.011966,-116.629051,294.500488,0.000000
125.690002,65.056816,-116.629051,-0.000651,0.003984,0.101197,289.387177,14.742085,1.011966,-116.629051,294.500488,0.000000
126.110008,65.026665,-116.762497,-0.000642,0.003984,0.101197,289.253052,14.735253,1.011966,-116.762497,294.500488,0.000000
126.530006,65.002083,-116.718018,-0.000638,0.003984,0.101197,289.143707,14.729683,1.011966,-116.718018,294.500488,0.000000
126.950005,65.531227,-116.718018,-0.000625,0.003992,0.101396,291.497467,14.849588,1.013960,-116.718018,294.500488,0.000000
127.370003,65.559898,-116.806976,-0.000642,0.003992,0.101396,291.625000,14.856086,1.013960,-116.806976,294.500488,0.000000
127.790009,65.549095,-116.895943,-0.000634,0.003992,0.101396,291.576935,14.853638,1.013960,-116.895943,294.500488,0.000000
128.210007,65.533089,-116.895943,-0.000634,0.003992,0.101396,291.505737,14.850011,1.013960,-116.895943,1681.640991,0.000000
128.630005,65.467171,-116.940422,-0.000634,0.003981,0.101110,291.212524,14.835073,1.011098,-116.940422,0.100910,0.000000
129.050003,65.353981,-116.940422,-0.000629,0.003958,0.100537,290.709015,14.809423,1.005375,-116.940422,0.100208,0.000000
129.470001,65.203529,-117.029381,-0.000629,0.003933,0.099887,290.039795,14.775331,0.998871,-117.029381,0.099514,0.000000
129.889999,65.163322,-117.073860,-0.000634,0.003912,0.099358,289.860931,14.766220,0.993580,-117.073860,0.098812,0.000000
130.310013,65.097404,-117.118347,-0.000625,0.003884,0.098647,289.567719,14.751283,0.986469,-117.118347,0.098109,0.000000
130.730011,65.053474,-117.118347,-0.000625,0.003855,0.097927,289.372314,14.741328,0.979271,-117.118347,0.097407,0.000000
131.150009,65.014000,-117.162827,-0.000621,0.003831,0.097303,289.196716,14.732384,0.973027,-117.162827,0.096713,0.000000
131.570007,64.904152,-117.162827,-0.000647,0.003800,0.096514,288.708099,14.707491,0.965135,-117.162827,0.096011,0.000000
131.990005,64.803978,-117.251785,-0.000617,0.003782,0.096063,288.262482,14.684792,0.960626,-117.251785,0.095308,0.000000
132.410004,64.049553,-117.251785,-0.000604,0.003749,0.095230,284.906647,14.513836,0.952300,-117.251785,0.094614,0.000000
132.830002,63.048988,-117.296265,-0.000599,0.003724,0.094588,280.455902,14.287106,0.945883,-117.296265,0.093912,0.000000
133.250000,61.651848,-117.340752,-0.000608,0.003698,0.093938,274.241119,13.970509,0.939379,-117.340752,0.093209,0.000000
133.670013,60.396210,-117.340752,-0.000617,0.003673,0.093287,268.655762,13.685976,0.932875,-117.340752,0.092507,0.000000
134.090012,58.222672,-117.429710,-0.000595,0.003646,0.092611,258.987366,13.193446,0.926110,-117.429710,0.091813,0.000000
134.510010,56.100517,-117.429710,-0.000591,0.003617,0.091883,249.547562,12.712559,0.918826,-117.429710,0.091111,0.000000
134.930008,54.208496,-117.474190,-0.000591,0.003596,0.091328,241.131439,12.283821,0.913275,-117.474190,0.090408,0.000000
135.350006,51.758286,-117.518669,-0.000604,0.003571,0.090694,230.232346,11.728596,0.906945,-117.518669,0.089706,0.000000
135.770004,49.208649,-117.607635,-0.000612,0.003543,0.090001,218.891006,11.150839,0.900007,-117.607635,0.089012,0.000000
136.190002,46.710777,-117.652115,-0.000604,0.003518,0.089359,207.779907,10.584813,0.893589,-117.652115,0.088310,0.000000
136.610001,43.305054,-117.652115,-0.000608,0.003489,0.088630,192.630493,9.813066,0.886305,-117.652115,0.087607,0.000000
137.030014,40.484337,-117.652115,-0.000595,0.003461,0.087911,180.083328,9.173882,0.879107,-117.652115,0.086913,0.000000
137.450012,37.065582,-117.696594,-0.000617,0.003430,0.087130,164.875946,8.399181,0.871302,-117.696594,0.086211,0.000000
137.870010,34.790764,-117.741081,-0.000608,0.003409,0.086592,154.757050,7.883700,0.865925,-117.741081,0.085508,0.000000
138.290009,31.042458,-117.741081,-0.000612,0.003376,0.085743,138.083740,7.034321,0.857426,-117.741081,0.084806,0.000000
138.710007,28.452240,-117.830040,-0.000617,0.003353,0.085162,126.561882,6.447370,0.851616,-117.830040,0.084112,0.000000
139.130005,25.436768,-117.830040,-0.000629,0.003324,0.084433,113.148392,5.764054,0.844331,-117.830040,0.083410,0.000000
139.550003,22.336388,-117.874519,-0.000634,0.003296,0.083713,99.357216,5.061498,0.837133,-117.874519,0.082707,0.000000
139.970001,19.831070,-117.963486,-0.000638,0.003273,0.083124,88.213005,4.493784,0.831236,-117.963486,0.082014,0.000000
140.389999,15.569267,-117.963486,-0.000634,0.003235,0.082170,69.255562,3.528047,0.821696,-117.963486,0.081311,0.000000
140.810013,13.647079,-117.963486,-0.000634,0.003217,0.081701,60.705242,3.092473,0.817013,-117.963486,0.080609,0.000000
141.230011,10.362381,-117.963486,-0.000638,0.003184,0.080886,46.094173,2.348149,0.808861,-117.963486,0.079906,0.000000
141.650009,7.921478,-118.007965,-0.000651,0.003164,0.080366,35.236496,1.795033,0.803658,-118.007965,0.079212,0.000000
142.070007,4.652794,-118.141403,-0.000647,0.003132,0.079542,20.696661,1.054338,0.795419,-118.141403,0.078510,0.000000
142.490005,1.692436,-118.096924,-0.000651,0.003102,0.078787,7.528332,0.383512,0.787875,-118.096924,0.077807,0.000000
142.910004,0.423019,-118.141403,-0.000664,0.003089,0.078449,1.881684,0.095858,0.784492,-118.141403,0.077105,0.000000
143.330002,-3.046005,-118.141403,-0.000677,0.003047,0.077400,-13.549308,-0.690235,0.773999,-118.141403,0.076411,0.000000
143.750000,-0.361572,-118.185890,-0.000737,0.003020,0.076715,-1.608354,-0.081933,0.767148,-118.185890,0.075709,0.000000
144.170013,-0.037239,-118.274849,-0.000815,0.002987,0.075874,-0.165648,-0.008438,0.758736,-118.274849,0.075006,0.000000
144.590012,0.013779,-118.363808,-0.000811,0.002963,0.075258,0.061291,0.003122,0.752578,-118.363808,0.074313,0.000000
145.010010,0.004097,-118.319328,-0.000858,0.002938,0.074625,0.018224,0.000928,0.746248,-118.319328,0.073610,0.000000
145.430008,0.029793,-118.319328,-0.000910,0.002912,0.073957,0.132525,0.006751,0.739570,-118.319328,0.072908,0.000000
145.850006,0.029045,-118.408295,-0.000957,0.002884,0.073263,0.129199,0.006582,0.732632,-118.408295,0.072205,0.000000
146.270004,0.016754,-118.452774,-0.001000,0.002854,0.072483,0.074526,0.003797,0.724827,-118.452774,0.071511,0.000000
146.690002,0.043198,-118.452774,-0.001056,0.002828,0.071824,0.192153,0.009789,0.718236,-118.452774,0.070809,0.000000
147.110001,0.048035,-118.452774,-0.001099,0.002799,0.071086,0.213669,0.010885,0.710865,-118.452774,0.070107,0.000000
147.530014,0.042824,-118.541733,-0.001164,0.002772,0.070410,0.190490,0.009704,0.704101,-118.541733,0.069404,0.000000
147.950012,0.035378,-118.630699,-0.001203,0.002744,0.069708,0.157367,0.008017,0.697076,-118.630699,0.068710,0.000000
148.370010,0.035751,-118.719658,-0.001250,0.002718,0.069040,0.159030,0.008101,0.690398,-118.719658,0.068008,0.000000
148.790009,0.011169,-118.675179,-0.001298,0.002688,0.068285,0.049684,0.002531,0.682853,-118.675179,0.067305,0.000000
149.210007,0.018623,-118.675179,-0.001358,0.002664,0.067678,0.082841,0.004220,0.676783,-118.675179,0.066612,0.000000
149.630005,0.036865,-118.719658,-0.001397,0.002644,0.067149,0.163985,0.008354,0.671493,-118.719658,0.065909,0.000000
150.050003,0.056229,-118.808617,-0.001466,0.002601,0.066074,0.250117,0.012742,0.660739,-118.808617,0.065207,0.000000
150.470001,0.010803,-118.808617,-0.001518,0.002579,0.065502,0.048055,0.002448,0.655016,-118.808617,0.064504,0.000000
150.890015,0.033142,-118.808617,-0.001552,0.002546,0.064669,0.147423,0.007510,0.646690,-118.808617,0.063810,0.000000
151.310013,0.033142,-118.808617,-0.001595,0.002524,0.064105,0.147423,0.007510,0.641053,-118.808617,0.063108,0.000000
151.730011,0.025322,-118.897583,-0.001638,0.002494,0.063360,0.112638,0.005738,0.633595,-118.897583,0.062406,0.000000
152.150009,0.021225,-118.986542,-0.001694,0.002466,0.062640,0.094413,0.004810,0.626397,-118.986542,0.061712,0.000000
152.570007,-0.010796,-118.986542,-0.001729,0.002444,0.062076,-0.048021,-0.002446,0.620760,-118.986542,0.061009,0.000000
152.990005,-0.011169,-119.031029,-0.001759,0.002413,0.061287,-0.049684,-0.002531,0.612868,-119.031029,0.060307,0.000000
153.410004,0.013405,-119.031029,-0.001815,0.002392,0.060749,0.059628,0.003038,0.607492,-119.031029,0.059604,0.000000
153.830002,0.001488,-119.075508,-0.001850,0.002353,0.059769,0.006618,0.000337,0.597692,-119.075508,0.058911,0.000000
154.250000,-0.017128,-119.164467,-0.001884,0.002330,0.059188,-0.076189,-0.003881,0.591882,-119.164467,0.058208,0.000000
154.670013,-0.000374,-119.208946,-0.001910,0.002312,0.058729,-0.001663,-0.000085,0.587285,-119.208946,0.057506,0.000000
155.090012,-0.017502,-119.164467,-0.001936,0.002286,0.058052,-0.077852,-0.003966,0.580521,-119.164467,0.056803,0.000000
155.510010,-0.016380,-119.253433,-0.002001,0.002241,0.056933,-0.072863,-0.003712,0.569334,-119.253433,0.056109,0.000000
155.930008,-0.031281,-119.297913,-0.002048,0.002212,0.056196,-0.139143,-0.007088,0.561962,-119.297913,0.055407,0.000000
156.350006,-0.024200,-119.297913,-0.002065,0.002197,0.055806,-0.107649,-0.005484,0.558060,-119.297913,0.054705,0.000000
156.770004,-0.012657,-119.386871,-0.002087,0.002164,0.054973,-0.056302,-0.002868,0.549734,-119.386871,0.054011,0.000000
157.190002,-0.004837,-119.386871,-0.002130,0.002141,0.054384,-0.021516,-0.001096,0.543837,-119.386871,0.053308,0.000000
157.610001,-0.002235,-119.431351,-0.002164,0.002108,0.053551,-0.009944,-0.000507,0.535512,-119.431351,0.052606,0.000000
158.030014,-0.033882,-119.431351,-0.002199,0.002083,0.052901,-0.150715,-0.007678,0.529008,-119.431351,0.051903,0.000000
158.450012,-0.007446,-119.564796,-0.002225,0.002053,0.052146,-0.033123,-0.001687,0.521463,-119.564796,0.051210,0.000000
158.870010,0.001488,-119.475838,-0.002242,0.002037,0.051747,0.006618,0.000337,0.517474,-119.475838,0.050507,0.000000
159.290009,-0.023460,-119.520317,-0.002285,0.002001,0.050837,-0.104357,-0.005316,0.508368,-119.520317,0.049805,0.000000
159.710007,0.008942,-119.609276,-0.002333,0.001967,0.049970,0.039774,0.002026,0.499695,-119.609276,0.049111,0.000000
160.130005,-0.020477,-119.698242,-0.002354,0.001946,0.049432,-0.091088,-0.004640,0.494319,-119.698242,0.048409,0.000000
160.550003,0.002983,-119.698242,-0.002380,0.001924,0.048868,0.013269,0.000676,0.488682,-119.698242,0.047706,0.000000
160.970001,-0.033142,-119.787201,-0.002410,0.001888,0.047949,-0.147423,-0.007510,0.479489,-119.787201,0.047004,0.000000
161.390015,-0.013779,-119.742722,-0.002462,0.001855,0.047108,-0.061291,-0.003122,0.471077,-119.742722,0.046310,0.000000
161.810013,-0.007446,-119.742722,-0.002492,0.001831,0.046509,-0.033123,-0.001687,0.465093,-119.742722,0.045607,0.000000
162.230011,0.019737,-119.831680,-0.002509,0.001814,0.046067,0.087796,0.004473,0.460670,-119.831680,0.044905,0.000000
162.650009,-0.011917,-119.920647,-0.002527,0.001781,0.045243,-0.053010,-0.002700,0.452432,-119.920647,0.044202,0.000000
163.070007,-0.011543,-119.876160,-0.002565,0.001754,0.044558,-0.051347,-0.002616,0.445581,-119.876160,0.043509,0.000000
163.490005,0.002235,-119.965126,-0.002608,0.001724,0.043786,0.009944,0.000507,0.437862,-119.965126,0.042806,0.000000
163.910004,0.017876,-119.965126,-0.002634,0.001701,0.043197,0.079515,0.004051,0.431965,-119.965126,0.042104,0.000000
164.330002,0.028305,-120.009605,-0.002669,0.001674,0.042511,0.125907,0.006414,0.425114,-120.009605,0.041410,0.000000
164.750015,0.021225,-120.143051,-0.002690,0.001642,0.041705,0.094413,0.004810,0.417049,-120.143051,0.040708,0.000000
165.170013,0.024948,-120.098564,-0.002729,0.001609,0.040881,0.110975,0.005653,0.408810,-120.098564,0.040005,0.000000
165.590012,0.001122,-120.143051,-0.002768,0.001581,0.040153,0.004989,0.000254,0.401525,-120.143051,0.039303,0.000000
166.010010,0.017502,-120.098564,-0.002777,0.001558,0.039563,0.077852,0.003966,0.395628,-120.098564,0.038609,0.000000
166.430008,0.046921,-120.232010,-0.002820,0.001527,0.038791,0.208714,0.010632,0.387910,-120.232010,0.037906,0.000000
166.850006,0.047295,-120.320976,-0.002837,0.001503,0.038167,0.210377,0.010717,0.381666,-120.320976,0.037204,0.000000
167.270004,-0.004471,-120.232010,-0.002871,0.001477,0.037525,-0.019887,-0.001013,0.375249,-120.232010,0.036510,0.000000
167.690002,0.006332,-120.320976,-0.002884,0.001446,0.036727,0.028168,0.001435,0.367270,-120.320976,0.035808,0.000000
168.110001,0.008942,-120.365456,-0.002919,0.001422,0.036111,0.039774,0.002026,0.361113,-120.365456,0.035105,0.000000
168.530014,0.014153,-120.454414,-0.002966,0.001392,0.035348,0.062954,0.003207,0.353481,-120.454414,0.034403,0.000000
168.950012,0.010056,-120.454414,-0.002984,0.001373,0.034880,0.044729,0.002279,0.348798,-120.454414,0.033709,0.000000
169.370010,0.020851,-120.454414,-0.003014,0.001337,0.033952,0.092750,0.004725,0.339519,-120.454414,0.033007,0.000000
169.790009,-0.007820,-120.454414,-0.003048,0.001315,0.033397,-0.034786,-0.001772,0.333969,-120.454414,0.032304,0.000000
170.210007,-0.017128,-120.498894,-0.003087,0.001284,0.032625,-0.076189,-0.003881,0.326250,-120.498894,0.031602,0.000000
170.630005,-0.015266,-120.676819,-0.003100,0.001257,0.031931,-0.067908,-0.003459,0.319312,-120.676819,0.030908,0.000000
171.050003,0.000374,-120.676819,-0.003117,0.001236,0.031385,0.001663,0.000085,0.313849,-120.676819,0.030205,0.000000
171.300003,0.013779,-120.632339,-0.003156,0.001218,0.030925,0.061291,0.003122,0.309253,-120.632339,0.030769,0.000000