File: Data/compression 15/AutoNoHeating-17-15-reverse-shortpurge-3_08262024_193217.csv
Time (sec),S:Load (lbs),S:HL1 (DIM),S:LVDT (in),S:Position (in),Ch:Position (mm),Ch:Load (N),Ch:Stress (MPa),Ch:Strain (mm/mm),Ch:HL1 (DIM),Set Point (),Cycles ()
0.110000,-0.018990,-84.380363,-0.013219,-0.008390,-0.213103,-0.084470,-0.004303,-2.131034,-84.380363,-0.212852,0.000000
0.460000,0.010429,-84.380363,-0.013245,-0.008321,-0.211360,0.046392,0.002363,-2.113603,-84.380363,-0.210666,0.000000
0.810000,0.036491,-84.380363,-0.013120,-0.008112,-0.206035,0.162322,0.008269,-2.060355,-84.380363,-0.204839,0.000000
1.160000,0.009308,-84.469330,-0.012861,-0.007878,-0.200104,0.041403,0.002109,-2.001037,-84.469330,-0.198994,0.000000
1.510000,-0.000000,-84.513809,-0.012624,-0.007646,-0.194215,-0.000000,-0.000000,-1.942152,-84.513809,-0.193166,0.000000
1.860000,0.017876,-84.558289,-0.012404,-0.007429,-0.188700,0.079515,0.004051,-1.886996,-84.558289,-0.187338,0.000000
2.210000,0.007446,-84.513809,-0.012158,-0.007196,-0.182776,0.033123,0.001687,-1.827765,-84.513809,-0.181510,0.000000
2.560000,-0.007446,-84.558289,-0.011943,-0.006966,-0.176940,-0.033123,-0.001687,-1.769401,-84.558289,-0.175683,0.000000
2.910000,0.023460,-84.602768,-0.011680,-0.006733,-0.171008,0.104357,0.005316,-1.710082,-84.602768,-0.169837,0.000000
3.260000,-0.006699,-84.736214,-0.011443,-0.006500,-0.165094,-0.029797,-0.001518,-1.650938,-84.736214,-0.164010,0.000000
3.610000,0.046547,-84.780693,-0.011201,-0.006280,-0.159500,0.207051,0.010548,-1.595001,-84.780693,-0.158182,0.000000
3.960000,0.010803,-84.825172,-0.010986,-0.006051,-0.153690,0.048055,0.002448,-1.536897,-84.825172,-0.152354,0.000000
4.310000,0.026436,-84.736214,-0.010736,-0.005816,-0.147715,0.117593,0.005990,-1.477146,-84.736214,-0.146526,0.000000
4.660000,-0.004837,-84.780693,-0.010503,-0.005593,-0.142060,-0.021516,-0.001096,-1.420602,-84.780693,-0.140699,0.000000
5.010000,-0.032021,-84.869652,-0.010261,-0.005354,-0.135990,-0.142435,-0.007256,-1.359897,-84.869652,-0.134854,0.000000
5.360000,0.008942,-84.914139,-0.010024,-0.005122,-0.130093,0.039774,0.002026,-1.300925,-84.914139,-0.129026,0.000000
5.710000,0.041710,-84.914139,-0.009800,-0.004903,-0.124525,0.185535,0.009452,-1.245249,-84.914139,-0.123198,0.000000
6.060000,0.037239,-85.047577,-0.009550,-0.004669,-0.118593,0.165648,0.008438,-1.185931,-85.047577,-0.117370,0.000000
6.410000,0.003723,-85.003098,-0.009330,-0.004442,-0.112835,0.016561,0.000844,-1.128347,-85.003098,-0.111543,0.000000
6.760000,-0.040962,-85.047577,-0.009093,-0.004214,-0.107024,-0.182209,-0.009282,-1.070243,-85.047577,-0.105697,0.000000
7.110000,-0.015640,-85.092056,-0.008864,-0.003975,-0.100954,-0.069571,-0.003544,-1.009537,-85.092056,-0.099870,0.000000
7.460001,0.030533,-85.092056,-0.008614,-0.003749,-0.095230,0.135817,0.006919,-0.952300,-85.092056,-0.094042,0.000000
7.810000,0.057716,-85.181023,-0.008364,-0.003520,-0.089411,0.256735,0.013079,-0.894110,-85.181023,-0.088214,0.000000
8.160001,0.044685,-85.181023,-0.008119,-0.003289,-0.083531,0.198770,0.010126,-0.835312,-85.181023,-0.082386,0.000000
8.510000,0.016388,-85.136543,-0.007912,-0.003065,-0.077851,0.072897,0.003714,-0.778509,-85.136543,-0.076559,0.000000
8.860001,-0.019363,-85.225502,-0.007670,-0.002831,-0.071902,-0.086133,-0.004388,-0.719017,-85.225502,-0.070714,0.000000
9.210000,-0.001862,-85.269981,-0.007429,-0.002603,-0.066117,-0.008281,-0.000422,-0.661173,-85.269981,-0.064886,0.000000
9.560000,0.042076,-85.269981,-0.007179,-0.002375,-0.060316,0.187164,0.009535,-0.603155,-85.269981,-0.059058,0.000000
9.910001,0.049156,-85.314461,-0.006946,-0.002141,-0.054375,0.218658,0.011139,-0.543750,-85.314461,-0.053230,0.000000
10.260000,0.016388,-85.403427,-0.006722,-0.001915,-0.048651,0.072897,0.003714,-0.486514,-85.403427,-0.047403,0.000000
10.610001,0.011917,-85.358948,-0.006485,-0.001682,-0.042720,0.053010,0.002700,-0.427195,-85.358948,-0.041557,0.000000
10.960001,0.002983,-85.447906,-0.006234,-0.001454,-0.036926,0.013269,0.000676,-0.369265,-85.447906,-0.035730,0.000000
11.310000,0.005959,-85.492386,-0.006015,-0.001228,-0.031185,0.026505,0.001350,-0.311854,-85.492386,-0.029902,0.000000
11.660001,0.051758,-85.536865,-0.005764,-0.000993,-0.025228,0.230230,0.011728,-0.252276,-85.536865,-0.024074,0.000000
12.010000,0.024948,-85.625832,-0.005523,-0.000762,-0.019365,0.110975,0.005653,-0.193651,-85.625832,-0.018246,0.000000
12.360001,0.034630,-85.581352,-0.005303,-0.000544,-0.013824,0.154041,0.007847,-0.138236,-85.581352,-0.012401,0.000000
12.710001,0.028305,-85.625832,-0.005066,-0.000309,-0.007840,0.125907,0.006414,-0.078397,-85.625832,-0.006574,0.000000
13.060000,0.043571,-85.714790,-0.004825,-0.000077,-0.001960,0.193816,0.009873,-0.019599,-85.714790,-0.000746,0.000000
13.410001,0.126984,-85.670311,-0.004751,-0.000005,-0.000121,0.564851,0.028775,-0.001214,-85.670311,0.000087,0.000000
13.760000,0.140388,-85.714790,-0.004743,-0.000005,-0.000121,0.624479,0.031812,-0.001214,-85.714790,0.000156,0.000000
14.110001,0.088997,-85.759277,-0.004747,-0.000005,-0.000121,0.395878,0.020167,-0.001214,-85.759277,0.000737,0.000000
14.460001,0.137032,-85.803757,-0.004734,0.000010,0.000243,0.609547,0.031052,0.002428,-85.803757,0.001318,0.000000
14.810000,0.275558,-85.803757,-0.004708,0.000037,0.000945,1.225745,0.062442,0.009453,-85.803757,0.001899,0.000000
15.160001,0.339607,-85.848236,-0.004691,0.000054,0.001362,1.510648,0.076956,0.013615,-85.848236,0.002489,0.000000
15.510001,0.535103,-85.892715,-0.004661,0.000082,0.002081,2.380256,0.121256,0.020813,-85.892715,0.003070,0.000000
15.860001,0.748100,-85.981682,-0.004644,0.000104,0.002654,3.327716,0.169522,0.026537,-85.981682,0.003651,0.000000
16.210001,0.977104,-85.937195,-0.004639,0.000122,0.003105,4.346376,0.221415,0.031047,-85.937195,0.004241,0.000000
16.560001,1.359161,-86.070641,-0.004600,0.000150,0.003798,6.045852,0.307990,0.037984,-86.070641,0.004822,0.000000
16.910002,1.620567,-86.070641,-0.004587,0.000164,0.004163,7.208643,0.367226,0.041627,-86.070641,0.005403,0.000000
17.260000,1.995171,-86.115120,-0.004566,0.000188,0.004787,8.874962,0.452112,0.047871,-86.115120,0.005984,0.000000
17.610001,2.637886,-86.159599,-0.004536,0.000224,0.005689,11.733903,0.597753,0.056890,-86.159599,0.006574,0.000000
17.960001,3.000206,-86.115120,-0.004518,0.000245,0.006227,13.345583,0.679856,0.062267,-86.115120,0.007155,0.000000
18.310001,3.525993,-86.159599,-0.004506,0.000266,0.006756,15.684402,0.799002,0.067557,-86.159599,0.007736,0.000000
18.660002,3.952736,-86.204086,-0.004480,0.000288,0.007311,17.582647,0.895703,0.073107,-86.204086,0.008317,0.000000
19.010000,4.530655,-86.248566,-0.004467,0.000313,0.007961,20.153360,1.026661,0.079611,-86.248566,0.008906,0.000000
19.360001,4.956650,-86.293045,-0.004454,0.000336,0.008525,22.048279,1.123193,0.085248,-86.293045,0.009487,0.000000
19.710001,5.384132,-86.293045,-0.004424,0.000360,0.009149,23.949818,1.220062,0.091492,-86.293045,0.010068,0.000000
20.060001,5.835823,-86.337524,-0.004415,0.000382,0.009713,25.959038,1.322416,0.097129,-86.337524,0.010658,0.000000
20.410002,6.218620,-86.382004,-0.004393,0.000403,0.010225,27.661804,1.409159,0.102246,-86.382004,0.011239,0.000000
20.760000,6.636795,-86.470970,-0.004389,0.000422,0.010719,29.521938,1.503919,0.107189,-86.470970,0.011820,0.000000
21.110001,7.205780,-86.515450,-0.004359,0.000449,0.011413,32.052910,1.632853,0.114127,-86.515450,0.012401,0.000000
21.460001,7.771042,-86.515450,-0.004316,0.000477,0.012106,34.567322,1.760943,0.121065,-86.515450,0.012991,0.000000
21.810001,8.080482,-86.559929,-0.004307,0.000499,0.012679,35.943783,1.831064,0.126788,-86.559929,0.013572,0.000000
22.160002,8.521370,-86.604408,-0.004277,0.000521,0.013234,37.904945,1.930970,0.132339,-86.604408,0.014153,0.000000
22.510000,8.963753,-86.648895,-0.004255,0.000540,0.013711,39.872765,2.031215,0.137108,-86.648895,0.014734,0.000000
22.860001,9.186432,-86.648895,-0.004243,0.000559,0.014196,40.863289,2.081675,0.141965,-86.648895,0.015324,0.000000
23.210001,10.075653,-86.693375,-0.004230,0.000592,0.015029,44.818745,2.283176,0.150290,-86.693375,0.015905,0.000000
23.560001,10.259232,-86.693375,-0.004195,0.000614,0.015584,45.635342,2.324775,0.155840,-86.693375,0.016486,0.000000
23.910002,10.560860,-86.737854,-0.004178,0.000636,0.016165,46.977051,2.393125,0.161651,-86.737854,0.017067,0.000000
24.260000,10.874023,-86.826813,-0.004165,0.000656,0.016659,48.370071,2.464089,0.166594,-86.826813,0.017657,0.000000
24.610001,11.220703,-86.826813,-0.004148,0.000678,0.017223,49.912182,2.542648,0.172231,-86.826813,0.018238,0.000000
24.960001,11.247887,-86.915779,-0.004122,0.000694,0.017622,50.033100,2.548808,0.176220,-86.915779,0.018819,0.000000
25.310001,12.402237,-86.915779,-0.004109,0.000730,0.018533,55.167904,2.810387,0.185326,-86.915779,0.019409,0.000000
25.660002,12.486771,-86.915779,-0.004079,0.000750,0.019044,55.543930,2.829543,0.190443,-86.915779,0.019990,0.000000
26.010002,12.810730,-87.004738,-0.004053,0.000771,0.019582,56.984974,2.902953,0.195820,-87.004738,0.020571,0.000000
26.360001,13.317902,-87.004738,-0.004036,0.000795,0.020189,59.240986,3.017880,0.201890,-87.004738,0.021152,0.000000
26.710001,13.431473,-87.049225,-0.004014,0.000812,0.020614,59.746174,3.043615,0.206140,-87.049225,0.021741,0.000000
27.060001,13.820976,-87.093704,-0.003997,0.000832,0.021143,61.478771,3.131878,0.211430,-87.093704,0.022322,0.000000
27.410002,14.027275,-87.182663,-0.003984,0.000850,0.021594,62.396435,3.178626,0.215939,-87.182663,0.022903,0.000000
27.760002,14.685257,-87.138184,-0.003949,0.000879,0.022322,65.323288,3.327727,0.223224,-87.138184,0.023484,0.000000
28.110001,15.207321,-87.227142,-0.003919,0.000908,0.023068,67.645546,3.446028,0.230682,-87.227142,0.024074,0.000000
28.460001,15.370422,-87.227142,-0.003893,0.000930,0.023632,68.371056,3.482988,0.236319,-87.227142,0.024655,0.000000
28.810001,15.327972,-87.271629,-0.003880,0.000946,0.024039,68.182228,3.473368,0.240395,-87.271629,0.025236,0.000000
29.160002,16.416412,-87.271629,-0.003854,0.000979,0.024872,73.023849,3.720012,0.248720,-87.271629,0.025826,0.000000
29.510002,16.415298,-87.316109,-0.003850,0.000998,0.025340,73.018898,3.719760,0.253403,-87.316109,0.026407,0.000000
29.860001,16.318855,-87.360588,-0.003824,0.001012,0.025713,72.589897,3.697905,0.257132,-87.360588,0.026988,0.000000
30.210001,17.323883,-87.316109,-0.003794,0.001046,0.026572,77.060478,3.925648,0.265718,-87.316109,0.027569,0.000000
30.560001,17.680244,-87.405067,-0.003773,0.001070,0.027179,78.645653,4.006401,0.271789,-87.405067,0.028159,0.000000
30.910002,17.890633,-87.449547,-0.003751,0.001093,0.027751,79.581505,4.054075,0.277512,-87.449547,0.028740,0.000000
31.260002,18.272690,-87.449547,-0.003738,0.001115,0.028324,81.280983,4.140651,0.283236,-87.449547,0.029321,0.000000
31.610001,17.939041,-87.538513,-0.003699,0.001127,0.028627,79.796837,4.065045,0.286271,-87.538513,0.029902,0.000000
31.960001,18.584740,-87.582993,-0.003704,0.001154,0.029304,82.669052,4.211362,0.293036,-87.582993,0.030492,0.000000
32.310001,19.033447,-87.627472,-0.003648,0.001181,0.029989,84.665001,4.313041,0.299887,-87.627472,0.031073,0.000000
32.660000,19.121696,-87.671951,-0.003635,0.001200,0.030474,85.057556,4.333038,0.304743,-87.671951,0.031654,0.000000
33.010002,19.552910,-87.716438,-0.003617,0.001229,0.031220,86.975685,4.430753,0.312201,-87.716438,0.032235,0.000000
33.360001,19.673927,-87.671951,-0.003591,0.001246,0.031636,87.514000,4.458176,0.316364,-87.671951,0.032824,0.000000
33.710003,20.057098,-87.760918,-0.003570,0.001269,0.032243,89.218430,4.545003,0.322435,-87.760918,0.033406,0.000000
34.060001,20.742264,-87.805397,-0.003540,0.001298,0.032981,92.266197,4.700264,0.329806,-87.805397,0.033987,0.000000
34.410000,20.773544,-87.805397,-0.003523,0.001322,0.033588,92.405342,4.707353,0.335877,-87.805397,0.034576,0.000000
34.760002,21.110916,-87.805397,-0.003505,0.001345,0.034169,93.906044,4.783802,0.341687,-87.805397,0.035157,0.000000
35.110001,21.336571,-87.894356,-0.003488,0.001369,0.034776,94.909805,4.834936,0.347758,-87.894356,0.035738,0.000000
35.460003,21.259491,-87.894356,-0.003449,0.001384,0.035157,94.566940,4.817470,0.351573,-87.894356,0.036319,0.000000
35.810001,21.663513,-87.938843,-0.003445,0.001410,0.035816,96.364120,4.909022,0.358164,-87.938843,0.036909,0.000000
36.160000,22.421295,-87.983322,-0.003410,0.001437,0.036510,99.734901,5.080738,0.365102,-87.983322,0.037490,0.000000
36.510002,22.121529,-88.027802,-0.003397,0.001452,0.036874,98.401474,5.012810,0.368744,-88.027802,0.038071,0.000000
36.860001,22.694984,-88.072281,-0.003376,0.001482,0.037638,100.952332,5.142757,0.376376,-88.072281,0.038652,0.000000
37.210003,22.919525,-88.072281,-0.003346,0.001504,0.038210,101.951141,5.193639,0.382100,-88.072281,0.039242,0.000000
37.560001,22.940376,-88.161247,-0.003328,0.001523,0.038678,102.043892,5.198363,0.386783,-88.161247,0.039823,0.000000
37.910004,23.538040,-88.161247,-0.003285,0.001548,0.039329,104.702431,5.333796,0.393287,-88.161247,0.040404,0.000000
38.260002,23.726082,-88.250206,-0.003281,0.001571,0.039892,105.538879,5.376407,0.398924,-88.250206,0.040994,0.000000
38.610001,23.665016,-88.250206,-0.003277,0.001593,0.040473,105.267250,5.362569,0.404734,-88.250206,0.041575,0.000000
38.960003,24.614563,-88.250206,-0.003234,0.001626,0.041297,109.491043,5.577740,0.412973,-88.250206,0.042156,0.000000
39.310001,24.624992,-88.250206,-0.003199,0.001645,0.041783,109.537437,5.580103,0.417829,-88.250206,0.042737,0.000000
39.660004,24.760536,-88.294685,-0.003178,0.001666,0.042312,110.140366,5.610817,0.423119,-88.294685,0.043327,0.000000
40.010002,25.011139,-88.339172,-0.003160,0.001689,0.042893,111.255104,5.667605,0.428930,-88.339172,0.043908,0.000000
40.360001,25.475121,-88.428131,-0.003139,0.001713,0.043509,113.318993,5.772745,0.435087,-88.428131,0.044489,0.000000
40.710003,25.815094,-88.428131,-0.003109,0.001736,0.044107,114.831276,5.849784,0.441071,-88.428131,0.045070,0.000000
41.060001,26.123421,-88.517090,-0.003083,0.001760,0.044705,116.202782,5.919652,0.447055,-88.517090,0.045659,0.000000
41.410004,26.323753,-88.517090,-0.003078,0.001781,0.045234,117.093903,5.965048,0.452345,-88.517090,0.046240,0.000000
41.760002,26.785126,-88.561577,-0.003048,0.001806,0.045876,119.146187,6.069596,0.458762,-88.561577,0.046822,0.000000
42.110001,26.664101,-88.561577,-0.003022,0.001823,0.046301,118.607841,6.042171,0.463012,-88.561577,0.047403,0.000000
42.460003,27.376823,-88.606056,-0.003009,0.001849,0.046960,121.778191,6.203677,0.469603,-88.606056,0.047992,0.000000
42.810001,27.989006,-88.650536,-0.002975,0.001877,0.047680,124.501320,6.342400,0.476801,-88.650536,0.048573,0.000000
43.160004,28.293602,-88.695015,-0.002953,0.001900,0.048261,125.856224,6.411422,0.482611,-88.695015,0.049154,0.000000
43.510002,28.450005,-88.695015,-0.002936,0.001920,0.048764,126.551941,6.446863,0.487641,-88.695015,0.049744,0.000000
43.860001,28.566185,-88.695015,-0.002902,0.001940,0.049284,127.068741,6.473190,0.492844,-88.695015,0.050325,0.000000
44.210003,28.611237,-88.739494,-0.002876,0.001959,0.049761,127.269135,6.483398,0.497614,-88.739494,0.050906,0.000000
44.560001,29.977104,-88.828461,-0.002867,0.001992,0.050594,133.344818,6.792909,0.505939,-88.828461,0.051487,0.000000
44.910004,30.283936,-88.828461,-0.002850,0.002014,0.051149,134.709671,6.862438,0.511490,-88.828461,0.052077,0.000000
45.260002,30.473846,-88.872940,-0.002807,0.002037,0.051739,135.554443,6.905472,0.517387,-88.872940,0.052658,0.000000
45.610001,30.568054,-88.828461,-0.002790,0.002055,0.052190,135.973495,6.926820,0.521896,-88.828461,0.053239,0.000000
45.960003,30.951973,-88.961899,-0.002781,0.002077,0.052762,137.681259,7.013817,0.527620,-88.961899,0.053820,0.000000
46.310001,30.384476,-88.961899,-0.002742,0.002092,0.053144,135.156891,6.885221,0.531436,-88.961899,0.054410,0.000000
46.660004,32.496201,-88.961899,-0.002734,0.002132,0.054141,144.550323,7.363744,0.541409,-88.961899,0.054991,0.000000
47.010002,32.597488,-89.006386,-0.002690,0.002152,0.054670,145.000870,7.386696,0.546699,-89.006386,0.055572,0.000000
47.360001,32.696907,-89.006386,-0.002690,0.002173,0.055182,145.443100,7.409225,0.551816,-89.006386,0.056153,0.000000
47.710003,33.229401,-89.095345,-0.002673,0.002194,0.055728,147.811752,7.529890,0.557279,-89.095345,0.056743,0.000000
48.060001,33.238342,-89.095345,-0.002652,0.002214,0.056248,147.851532,7.531916,0.562483,-89.095345,0.057324,0.000000
48.410004,33.274834,-89.139824,-0.002621,0.002227,0.056560,148.013855,7.540185,0.565605,-89.139824,0.057905,0.000000
48.760002,34.349503,-89.184303,-0.002587,0.002258,0.057341,152.794220,7.783709,0.573410,-89.184303,0.058494,0.000000
49.110001,34.917740,-89.273270,-0.002578,0.002278,0.057853,155.321869,7.912473,0.578526,-89.273270,0.059075,0.000000
49.460003,35.958519,-89.273270,-0.002552,0.002307,0.058598,159.951477,8.148317,0.585984,-89.273270,0.059656,0.000000
49.810001,36.371483,-89.317749,-0.002527,0.002329,0.059153,161.788437,8.241896,0.591535,-89.317749,0.060237,0.000000
50.160004,36.621719,-89.273270,-0.002514,0.002350,0.059682,162.901550,8.298600,0.596825,-89.273270,0.060827,0.000000
50.510002,37.125908,-89.362228,-0.002496,0.002376,0.060359,165.144287,8.412851,0.603589,-89.362228,0.061408,0.000000
50.860001,37.987206,-89.362228,-0.002479,0.002397,0.060888,168.975525,8.608024,0.608879,-89.362228,0.061989,0.000000
51.210003,37.688934,-89.406715,-0.002449,0.002409,0.061200,167.648758,8.540435,0.612001,-89.406715,0.062570,0.000000
51.560001,39.297585,-89.406715,-0.002440,0.002442,0.062033,174.804382,8.904961,0.620327,-89.406715,0.063160,0.000000
51.910004,40.182343,-89.406715,-0.002406,0.002468,0.062692,178.739990,9.105449,0.626917,-89.406715,0.063741,0.000000
52.260002,40.817612,-89.495674,-0.002393,0.002493,0.063325,181.565811,9.249403,0.633248,-89.495674,0.064322,0.000000
52.610001,41.331856,-89.584633,-0.002358,0.002514,0.063854,183.853271,9.365932,0.638538,-89.584633,0.064912,0.000000
52.960003,40.885750,-89.584633,-0.002337,0.002526,0.064149,181.868896,9.264843,0.641487,-89.584633,0.065493,0.000000
53.310001,41.989090,-89.584633,-0.002311,0.002553,0.064834,186.776794,9.514864,0.648338,-89.584633,0.066074,0.000000
53.660004,42.993752,-89.673599,-0.002307,0.002581,0.065554,191.245758,9.742524,0.655536,-89.673599,0.066655,0.000000
54.010002,43.524010,-89.673599,-0.002272,0.002603,0.066126,193.604462,9.862682,0.661260,-89.673599,0.067245,0.000000
54.360004,44.645599,-89.718079,-0.002259,0.002631,0.066820,198.593552,10.116838,0.668197,-89.718079,0.067826,0.000000
54.710003,45.125587,-89.673599,-0.002238,0.002650,0.067314,200.728638,10.225604,0.673141,-89.673599,0.068407,0.000000
55.060001,45.562004,-89.762558,-0.002212,0.002671,0.067843,202.669922,10.324498,0.678431,-89.762558,0.068988,0.000000
55.410004,46.864189,-89.851524,-0.002199,0.002697,0.068493,208.462326,10.619577,0.684935,-89.851524,0.069578,0.000000
55.760002,47.488663,-89.851524,-0.002169,0.002719,0.069066,211.240128,10.761085,0.690659,-89.851524,0.070159,0.000000
56.110004,48.304901,-89.896004,-0.002151,0.002745,0.069725,214.870926,10.946047,0.697249,-89.896004,0.070740,0.000000
56.460003,49.206787,-89.896004,-0.002121,0.002768,0.070297,218.882721,11.150417,0.702973,-89.896004,0.071321,0.000000
56.810001,49.225403,-89.896004,-0.002104,0.002783,0.070688,218.965530,11.154635,0.706876,-89.896004,0.071910,0.000000
57.160004,50.223740,-89.984962,-0.002091,0.002809,0.071338,223.406357,11.380862,0.713380,-89.984962,0.072491,0.000000
57.510002,51.698334,-89.984962,-0.002070,0.002836,0.072032,229.965668,11.715010,0.720318,-89.984962,0.073072,0.000000
57.860004,52.418869,-89.984962,-0.002057,0.002859,0.072630,233.170776,11.878285,0.726302,-89.984962,0.073662,0.000000
58.210003,53.150215,-90.029442,-0.002031,0.002879,0.073116,236.423965,12.044011,0.731158,-90.029442,0.074243,0.000000
58.560001,53.873734,-90.118408,-0.002013,0.002902,0.073723,239.642334,12.207963,0.737229,-90.118408,0.074824,0.000000
58.910004,54.414413,-90.162888,-0.001992,0.002921,0.074200,242.047394,12.330482,0.741998,-90.162888,0.075405,0.000000
59.260002,55.685326,-90.118408,-0.001966,0.002948,0.074868,247.700699,12.618475,0.748676,-90.118408,0.075995,0.000000
59.610004,56.104614,-90.162888,-0.001944,0.002968,0.075397,249.565796,12.713487,0.753966,-90.162888,0.076576,0.000000
59.960003,57.138695,-90.251846,-0.001919,0.002993,0.076021,254.165604,12.947813,0.760210,-90.251846,0.077157,0.000000
60.310001,59.405701,-90.296333,-0.001893,0.003024,0.076819,264.249756,13.461524,0.768189,-90.296333,0.077738,0.000000
60.660004,59.914734,-90.296333,-0.001893,0.003043,0.077296,266.514038,13.576873,0.772958,-90.296333,0.078328,0.000000
61.010002,60.774910,-90.340813,-0.001876,0.003065,0.077851,270.340302,13.771791,0.778509,-90.340813,0.078909,0.000000
61.360004,61.612007,-90.385292,-0.001841,0.003087,0.078415,274.063904,13.961481,0.784145,-90.385292,0.079490,0.000000
61.710003,62.802109,-90.429771,-0.001837,0.003113,0.079065,279.357727,14.231161,0.790650,-90.429771,0.080080,0.000000
62.060001,63.813835,-90.429771,-0.001802,0.003137,0.079672,283.858124,14.460422,0.796720,-90.429771,0.080661,0.000000
62.410004,64.921654,-90.474251,-0.001798,0.003160,0.080253,288.785950,14.711456,0.802531,-90.474251,0.081242,0.000000
62.760002,65.787788,-90.474251,-0.001768,0.003181,0.080799,292.638702,14.907725,0.807994,-90.474251,0.081823,0.000000
63.110004,65.273170,-90.563217,-0.001759,0.003181,0.080808,290.349548,14.791112,0.808081,-90.563217,0.014191,0.000000
63.460003,65.889076,-90.563217,-0.001729,0.003186,0.080912,293.089264,14.930678,0.809122,-90.563217,294.500488,0.000000
63.810001,65.414665,-90.607697,-0.001720,0.003211,0.081563,290.978973,14.823174,0.815626,-90.607697,294.500488,0.000000
64.160004,64.970055,-90.607697,-0.001716,0.003220,0.081797,289.001251,14.722425,0.817967,-90.607697,294.500488,0.000000
64.510002,65.840660,-90.652176,-0.001681,0.003235,0.082170,292.873871,14.919706,0.821696,-90.652176,294.500488,0.000000
64.860001,65.967278,-90.696663,-0.001690,0.003252,0.082603,293.437103,14.948399,0.826033,-90.696663,294.500488,0.000000
65.210007,64.927605,-90.696663,-0.001660,0.003245,0.082430,288.812408,14.712806,0.824298,-90.696663,294.500488,0.000000
65.560005,66.466255,-90.785622,-0.001634,0.003109,0.078970,295.656677,15.061468,0.789696,-90.785622,294.500488,0.000000
65.910004,65.380791,-90.830101,-0.001638,0.003173,0.080600,290.828278,14.815498,0.806000,-90.830101,294.500488,0.000000
66.260002,65.288811,-90.874580,-0.001621,0.003275,0.083184,290.419128,14.794656,0.831843,-90.874580,294.500488,0.000000
66.610001,65.271309,-90.830101,-0.001621,0.003284,0.083418,290.341278,14.790690,0.834184,-90.830101,294.500488,0.000000
66.960007,65.044899,-90.874580,-0.001621,0.003290,0.083557,289.334167,14.739385,0.835572,-90.874580,294.500488,0.000000
67.310005,65.268333,-90.963547,-0.001613,0.003299,0.083800,290.328033,14.790016,0.838000,-90.963547,294.500488,0.000000
67.660004,65.137627,-91.008026,-0.001591,0.003305,0.083956,289.746643,14.760398,0.839561,-91.008026,294.500488,0.000000
68.010002,65.186775,-91.052505,-0.001574,0.003314,0.084164,289.965271,14.771534,0.841643,-91.052505,294.500488,0.000000
68.360001,65.070595,-91.008026,-0.001569,0.003318,0.084286,289.448456,14.745208,0.842857,-91.008026,294.500488,0.000000
68.710007,65.284340,-91.096985,-0.001561,0.003327,0.084502,290.399261,14.793643,0.845025,-91.096985,294.500488,0.000000
69.060005,65.186775,-91.096985,-0.001552,0.003332,0.084633,289.965271,14.771534,0.846326,-91.096985,294.500488,0.000000
69.410004,65.133537,-91.185951,-0.001544,0.003338,0.084780,289.728455,14.759470,0.847800,-91.185951,294.500488,0.000000
69.760002,64.993141,-91.230431,-0.001535,0.003343,0.084910,289.103943,14.727656,0.849101,-91.230431,294.500488,0.000000
70.110001,65.208748,-91.230431,-0.001539,0.003352,0.085153,290.062988,14.776513,0.851529,-91.230431,294.500488,0.000000
70.460007,64.958519,-91.274910,-0.001513,0.003353,0.085162,288.949921,14.719810,0.851616,-91.274910,294.500488,0.000000
70.810005,64.959633,-91.319389,-0.001509,0.003358,0.085300,288.954865,14.720063,0.853003,-91.319389,294.500488,0.000000
71.160004,65.887962,-91.319389,-0.001505,0.003368,0.085543,293.084290,14.930426,0.855431,-91.319389,294.500488,0.000000
71.510002,65.319344,-91.363876,-0.001496,0.003368,0.085552,290.554962,14.801575,0.855518,-91.363876,294.500488,0.000000
71.860001,64.770088,-91.408356,-0.001496,0.003369,0.085560,288.111755,14.677113,0.855605,-91.408356,294.500488,0.000000
72.210007,66.564552,-91.452835,-0.001475,0.003332,0.084624,296.093903,15.083743,0.846239,-91.452835,294.500488,0.000000
72.560005,65.931145,-91.497314,-0.001462,0.003332,0.084633,293.276367,14.940211,0.846326,-91.497314,294.500488,0.000000
72.910004,65.467171,-91.541794,-0.001466,0.003356,0.085231,291.212524,14.835073,0.852309,-91.541794,294.500488,0.000000
73.260002,65.385994,-91.497314,-0.001462,0.003393,0.086194,290.851440,14.816678,0.861936,-91.497314,294.500488,0.000000
73.610001,65.306313,-91.586281,-0.001449,0.003397,0.086280,290.496979,14.798622,0.862803,-91.586281,294.500488,0.000000
73.960007,65.300346,-91.630760,-0.001453,0.003403,0.086428,290.470459,14.797271,0.864277,-91.630760,294.500488,0.000000
74.310005,65.270943,-91.630760,-0.001457,0.003406,0.086523,290.339661,14.790606,0.865231,-91.630760,294.500488,0.000000
74.660004,65.234444,-91.630760,-0.001449,0.003410,0.086610,290.177307,14.782336,0.866098,-91.630760,294.500488,0.000000
75.010002,65.361427,-91.675240,-0.001449,0.003417,0.086801,290.742157,14.811111,0.868006,-91.675240,294.500488,0.000000
75.360001,65.211357,-91.719719,-0.001440,0.003417,0.086801,290.074615,14.777104,0.868006,-91.719719,294.500488,0.000000
75.710007,65.367012,-91.808685,-0.001440,0.003423,0.086948,290.766998,14.812377,0.869480,-91.808685,294.500488,0.000000
76.060005,65.275032,-91.808685,-0.001431,0.003427,0.087043,290.357849,14.791533,0.870434,-91.808685,294.500488,0.000000
76.410004,65.249718,-91.853165,-0.001431,0.003430,0.087113,290.245239,14.785798,0.871128,-91.853165,294.500488,0.000000
76.760002,65.282112,-91.897644,-0.001436,0.003433,0.087208,290.389343,14.793138,0.872082,-91.897644,294.500488,0.000000
77.110001,65.312645,-91.897644,-0.001414,0.003437,0.087304,290.525146,14.800056,0.873036,-91.897644,294.500488,0.000000
77.460007,65.298485,-91.942123,-0.001414,0.003441,0.087390,290.462158,14.796848,0.873903,-91.942123,294.500488,0.000000
77.810005,65.235558,-91.986610,-0.001401,0.003443,0.087451,290.182251,14.782589,0.874510,-91.986610,294.500488,0.000000
78.160004,65.433662,-91.986610,-0.001406,0.003448,0.087581,291.063477,14.827479,0.875811,-91.986610,294.500488,0.000000
78.510002,65.172264,-92.031090,-0.001388,0.003449,0.087616,289.900696,14.768247,0.876158,-92.031090,294.500488,0.000000
78.860001,65.213585,-92.075569,-0.001388,0.003453,0.087694,290.084503,14.777609,0.876939,-92.075569,294.500488,0.000000
79.210007,65.000221,-92.120049,-0.001380,0.003453,0.087703,289.135437,14.729260,0.877025,-92.120049,294.500488,0.000000
79.560005,65.493248,-92.164528,-0.001375,0.003460,0.087893,291.328522,14.840981,0.878933,-92.164528,294.500488,0.000000
79.910004,65.246727,-92.120049,-0.001375,0.003460,0.087893,290.231934,14.785120,0.878933,-92.120049,294.500488,0.000000
80.260002,64.958885,-92.209015,-0.001375,0.003460,0.087893,288.951538,14.719894,0.878933,-92.209015,294.500488,0.000000
80.610001,64.682961,-92.253494,-0.001375,0.003460,0.087893,287.724182,14.657369,0.878933,-92.253494,294.500488,0.000000
80.960007,64.407402,-92.209015,-0.001371,0.003461,0.087902,286.498444,14.594926,0.879020,-92.209015,294.500488,0.000000
81.310005,66.465141,-92.253494,-0.001354,0.003426,0.087026,295.651703,15.061216,0.870261,-92.253494,294.500488,0.000000
81.660004,66.160164,-92.342453,-0.001354,0.003427,0.087035,294.295105,14.992107,0.870348,-92.342453,294.500488,0.000000
82.010002,65.815712,-92.386932,-0.001350,0.003430,0.087113,292.762909,14.914053,0.871128,-92.386932,294.500488,0.000000
82.360001,65.570702,-92.431419,-0.001337,0.003450,0.087633,291.673035,14.858533,0.876332,-92.431419,294.500488,0.000000
82.710007,65.369987,-92.431419,-0.001341,0.003463,0.087963,290.780212,14.813051,0.879627,-92.431419,294.500488,0.000000
83.060005,65.177467,-92.431419,-0.001358,0.003473,0.088214,289.923859,14.769425,0.882142,-92.431419,294.500488,0.000000
83.410004,65.320457,-92.475899,-0.001345,0.003484,0.088500,290.559906,14.801826,0.885004,-92.475899,294.500488,0.000000
83.760002,65.120872,-92.520378,-0.001337,0.003484,0.088500,289.672119,14.756600,0.885004,-92.520378,294.500488,0.000000
84.110001,64.907494,-92.564857,-0.001311,0.003485,0.088509,288.722961,14.708248,0.885091,-92.564857,294.500488,0.000000
84.460007,65.577019,-92.609337,-0.001332,0.003496,0.088804,291.701141,14.859965,0.888039,-92.609337,294.500488,0.000000
84.810005,65.467918,-92.653824,-0.001332,0.003496,0.088804,291.215851,14.835242,0.888039,-92.653824,294.500488,0.000000
85.160004,65.269814,-92.653824,-0.001328,0.003497,0.088813,290.334625,14.790351,0.888126,-92.653824,294.500488,0.000000
85.510002,65.070229,-92.653824,-0.001328,0.003497,0.088821,289.446838,14.745125,0.888213,-92.653824,294.500488,0.000000
85.860001,65.121620,-92.698303,-0.001324,0.003500,0.088899,289.675446,14.756769,0.888993,-92.698303,294.500488,0.000000
86.210007,64.962242,-92.742783,-0.001302,0.003500,0.088899,288.966492,14.720654,0.888993,-92.742783,294.500488,0.000000
86.560005,65.325676,-92.787262,-0.001306,0.003507,0.089090,290.583130,14.803010,0.890901,-92.787262,294.500488,0.000000
86.910004,65.229973,-92.831741,-0.001306,0.003507,0.089090,290.157410,14.781323,0.890901,-92.831741,294.500488,0.000000
87.260002,65.047508,-92.876228,-0.001306,0.003507,0.089090,289.345764,14.739976,0.890901,-92.876228,294.500488,0.000000
87.610001,65.560646,-92.876228,-0.001298,0.003516,0.089298,291.628326,14.856255,0.892982,-92.876228,294.500488,0.000000
87.960007,65.429939,-92.876228,-0.001293,0.003516,0.089298,291.046906,14.826636,0.892982,-92.876228,294.500488,0.000000
88.310005,65.244499,-92.965187,-0.001298,0.003516,0.089307,290.222015,14.784615,0.893069,-92.965187,294.500488,0.000000
88.660004,65.239662,-93.009666,-0.001285,0.003518,0.089368,290.200500,14.783519,0.893676,-93.009666,294.500488,0.000000
89.010002,65.292900,-93.098633,-0.001293,0.003521,0.089446,290.437317,14.795583,0.894457,-93.098633,294.500488,0.000000
89.360001,65.239281,-93.054146,-0.001302,0.003523,0.089480,290.198822,14.783432,0.894804,-93.054146,294.500488,0.000000
89.710007,65.238914,-93.054146,-0.001285,0.003525,0.089524,290.197174,14.783349,0.895237,-93.054146,294.500488,0.000000
90.060005,65.235939,-93.098633,-0.001281,0.003527,0.089584,290.183960,14.782675,0.895844,-93.098633,294.500488,0.000000
90.410004,65.296257,-93.143112,-0.001268,0.003529,0.089636,290.452271,14.796344,0.896365,-93.143112,294.500488,0.000000
90.760002,65.253441,-93.143112,-0.001293,0.003530,0.089671,290.261810,14.786641,0.896711,-93.143112,294.500488,0.000000
91.110001,65.220665,-93.232071,-0.001281,0.003532,0.089706,290.115997,14.779214,0.897058,-93.232071,294.500488,0.000000
91.460007,65.179329,-93.232071,-0.001268,0.003534,0.089758,289.932129,14.769847,0.897579,-93.232071,294.500488,0.000000
91.810005,65.163689,-93.232071,-0.001285,0.003535,0.089784,289.862549,14.766303,0.897839,-93.232071,294.500488,0.000000
92.160004,65.161827,-93.321037,-0.001285,0.003537,0.089827,289.854279,14.765881,0.898272,-93.321037,294.500488,0.000000
92.510002,65.215828,-93.365517,-0.001268,0.003539,0.089888,290.094482,14.778117,0.898879,-93.365517,294.500488,0.000000
92.860001,65.119011,-93.276558,-0.001268,0.003540,0.089905,289.663818,14.756179,0.899053,-93.276558,294.500488,0.000000
93.210007,65.148430,-93.409996,-0.001268,0.003542,0.089966,289.794678,14.762845,0.899660,-93.409996,294.500488,0.000000
93.560005,65.251579,-93.409996,-0.001263,0.003544,0.090018,290.253510,14.786219,0.900180,-93.409996,294.500488,0.000000
93.910004,65.143578,-93.454475,-0.001259,0.003544,0.090018,289.773102,14.761745,0.900180,-93.454475,294.500488,0.000000
94.260002,65.126457,-93.498962,-0.001255,0.003547,0.090087,289.696960,14.757866,0.900874,-93.498962,294.500488,0.000000
94.610008,65.224022,-93.498962,-0.001255,0.003549,0.090139,290.130951,14.779975,0.901394,-93.498962,294.500488,0.000000
94.960007,65.127937,-93.632401,-0.001259,0.003549,0.090139,289.703522,14.758202,0.901394,-93.632401,294.500488,0.000000
95.310005,65.099648,-93.587921,-0.001263,0.003550,0.090174,289.577698,14.751791,0.901741,-93.587921,294.500488,0.000000
95.660004,65.192741,-93.676880,-0.001263,0.003553,0.090244,289.991791,14.772886,0.902435,-93.676880,294.500488,0.000000
96.010002,65.161079,-93.676880,-0.001242,0.003558,0.090365,289.850952,14.765712,0.903649,-93.676880,294.500488,0.000000
96.360008,65.402748,-93.632401,-0.001263,0.003558,0.090365,290.925964,14.820475,0.903649,-93.632401,294.500488,0.000000
96.710007,65.289558,-93.676880,-0.001237,0.003558,0.090365,290.422455,14.794826,0.903649,-93.676880,294.500488,0.000000
97.060005,65.258644,-93.765846,-0.001237,0.003559,0.090408,290.284943,14.787820,0.904083,-93.765846,294.500488,0.000000
97.410004,65.225136,-93.810326,-0.001229,0.003560,0.090434,290.135895,14.780228,0.904343,-93.810326,294.500488,0.000000
97.760002,65.221779,-93.854805,-0.001237,0.003561,0.090460,290.120972,14.779467,0.904603,-93.854805,294.500488,0.000000
98.110008,65.226997,-93.899284,-0.001246,0.003564,0.090521,290.144165,14.780648,0.905210,-93.899284,294.500488,0.000000
98.460007,65.154015,-93.899284,-0.001250,0.003564,0.090521,289.819519,14.764111,0.905210,-93.899284,294.500488,0.000000
98.810005,65.105980,-93.943771,-0.001224,0.003567,0.090608,289.605865,14.753226,0.906077,-93.943771,294.500488,0.000000
99.160004,65.216942,-93.988251,-0.001224,0.003567,0.090608,290.099457,14.778370,0.906077,-93.988251,294.500488,0.000000
99.510002,65.102623,-94.032730,-0.001224,0.003567,0.090608,289.590942,14.752465,0.906077,-94.032730,294.500488,0.000000
99.860008,65.446327,-94.077209,-0.001233,0.003573,0.090746,291.119812,14.830349,0.907465,-94.077209,294.500488,0.000000
100.210007,65.369621,-94.077209,-0.001224,0.003572,0.090738,290.778595,14.812967,0.907378,-94.077209,294.500488,0.000000
100.560005,65.289558,-94.077209,-0.001216,0.003572,0.090738,290.422455,14.794826,0.907378,-94.077209,294.500488,0.000000
100.910004,65.170021,-94.166176,-0.001216,0.003573,0.090746,289.890747,14.767738,0.907465,-94.166176,294.500488,0.000000
101.260002,65.175240,-94.166176,-0.001229,0.003575,0.090799,289.913940,14.768920,0.907985,-94.166176,294.500488,0.000000
101.610008,65.159599,-94.210655,-0.001212,0.003576,0.090842,289.844360,14.765376,0.908419,-94.210655,294.500488,0.000000
101.960007,65.158104,-94.299614,-0.001216,0.003577,0.090851,289.837708,14.765038,0.908506,-94.299614,294.500488,0.000000
102.310005,65.055336,-94.299614,-0.001216,0.003577,0.090851,289.380585,14.741750,0.908506,-94.299614,294.500488,0.000000
102.660004,65.349876,-94.344101,-0.001212,0.003582,0.090981,290.690765,14.808494,0.909806,-94.344101,294.500488,0.000000
103.010002,65.305565,-94.344101,-0.001207,0.003582,0.090981,290.493652,14.798452,0.909806,-94.344101,294.500488,0.000000
103.360008,65.247856,-94.344101,-0.001212,0.003582,0.090981,290.236969,14.785376,0.909806,-94.344101,294.500488,0.000000
103.710007,65.196831,-94.477539,-0.001212,0.003584,0.091033,290.009979,14.773812,0.910327,-94.477539,294.500488,0.000000
104.060005,65.216576,-94.477539,-0.001212,0.003585,0.091067,290.097809,14.778287,0.910674,-94.477539,294.500488,0.000000
104.410004,65.196831,-94.433060,-0.001212,0.003585,0.091067,290.009979,14.773812,0.910674,-94.433060,294.500488,0.000000
104.760002,65.317116,-94.566505,-0.001203,0.003588,0.091145,290.545044,14.801069,0.911454,-94.566505,294.500488,0.000000
105.110008,65.276894,-94.477539,-0.001207,0.003588,0.091145,290.366119,14.791956,0.911454,-94.477539,294.500488,0.000000
105.460007,65.240776,-94.610985,-0.001207,0.003589,0.091171,290.205475,14.783772,0.911714,-94.610985,294.500488,0.000000
105.810005,65.165184,-94.610985,-0.001194,0.003590,0.091180,289.869202,14.766642,0.911801,-94.610985,294.500488,0.000000
106.160004,65.206886,-94.610985,-0.001203,0.003591,0.091215,290.054718,14.776092,0.912148,-94.610985,294.500488,0.000000
106.510002,65.206520,-94.699944,-0.001190,0.003593,0.091258,290.053101,14.776009,0.912582,-94.699944,294.500488,0.000000
106.860008,65.213219,-94.744423,-0.001199,0.003594,0.091275,290.082886,14.777527,0.912755,-94.744423,294.500488,0.000000
107.210007,65.155128,-94.833389,-0.001190,0.003594,0.091293,289.824493,14.764363,0.912928,-94.833389,294.500488,0.000000
107.560005,65.197945,-94.788910,-0.001186,0.003597,0.091371,290.014954,14.774065,0.913709,-94.788910,294.500488,0.000000
107.910004,65.256783,-94.877869,-0.001190,0.003597,0.091371,290.276672,14.787398,0.913709,-94.877869,294.500488,0.000000
108.260002,65.203529,-94.788910,-0.001177,0.003597,0.091371,290.039795,14.775331,0.913709,-94.788910,294.500488,0.000000
108.610008,65.117149,-94.877869,-0.001186,0.003597,0.091371,289.655548,14.755756,0.913709,-94.877869,294.500488,0.000000
108.960007,65.068367,-94.966827,-0.001177,0.003598,0.091397,289.438538,14.744702,0.913969,-94.966827,294.500488,0.000000
109.310005,65.016228,-94.966827,-0.001181,0.003599,0.091414,289.206635,14.732888,0.914143,-94.966827,294.500488,0.000000
109.660004,65.252693,-94.922348,-0.001186,0.003604,0.091536,290.258484,14.786471,0.915357,-94.922348,294.500488,0.000000
110.010002,65.278389,-95.055794,-0.001190,0.003604,0.091536,290.372772,14.792295,0.915357,-95.055794,294.500488,0.000000
110.360008,65.238533,-95.055794,-0.001177,0.003604,0.091536,290.195496,14.783262,0.915357,-95.055794,294.500488,0.000000
110.710007,65.153267,-95.144753,-0.001177,0.003604,0.091536,289.816193,14.763942,0.915357,-95.144753,294.500488,0.000000
111.060005,65.151405,-95.144753,-0.001181,0.003605,0.091579,289.807922,14.763519,0.915790,-95.144753,294.500488,0.000000
111.410004,65.095543,-95.144753,-0.001173,0.003605,0.091579,289.559448,14.750860,0.915790,-95.144753,294.500488,0.000000
111.760002,65.020332,-95.233719,-0.001181,0.003605,0.091579,289.224884,14.733818,0.915790,-95.233719,294.500488,0.000000
112.110008,64.955162,-95.278198,-0.001168,0.003605,0.091579,288.934998,14.719049,0.915790,-95.278198,294.500488,0.000000
112.460007,65.018837,-95.278198,-0.001168,0.003608,0.091640,289.218231,14.733479,0.916397,-95.278198,294.500488,0.000000
112.810005,65.405357,-95.322678,-0.001177,0.003615,0.091813,290.937561,14.821066,0.918132,-95.322678,294.500488,0.000000
113.160004,65.491386,-95.322678,-0.001173,0.003614,0.091805,291.320251,14.840561,0.918045,-95.322678,294.500488,0.000000
113.510002,65.452660,-95.322678,-0.001177,0.003614,0.091805,291.147980,14.831784,0.918045,-95.322678,294.500488,0.000000
113.860008,65.367760,-95.367157,-0.001164,0.003614,0.091805,290.770325,14.812547,0.918045,-95.367157,294.500488,0.000000
114.210007,65.301476,-95.456123,-0.001173,0.003614,0.091805,290.475464,14.797526,0.918045,-95.456123,294.500488,0.000000
114.560005,65.236671,-95.500603,-0.001164,0.003615,0.091813,290.187195,14.782842,0.918132,-95.500603,294.500488,0.000000
114.910004,65.156242,-95.500603,-0.001173,0.003615,0.091813,289.829437,14.764615,0.918132,-95.500603,294.500488,0.000000
115.260002,65.205025,-95.634048,-0.001164,0.003617,0.091883,290.046448,14.775670,0.918826,-95.634048,294.500488,0.000000
115.610008,65.204659,-95.634048,-0.001168,0.003617,0.091883,290.044800,14.775586,0.918826,-95.634048,294.500488,0.000000
115.960007,65.141716,-95.634048,-0.001151,0.003618,0.091900,289.764832,14.761324,0.918999,-95.634048,294.500488,0.000000
116.310005,65.082512,-95.678528,-0.001138,0.003618,0.091900,289.501465,14.747909,0.918999,-95.678528,294.500488,0.000000
116.660004,65.039696,-95.678528,-0.001155,0.003618,0.091900,289.311005,14.738206,0.918999,-95.678528,294.500488,0.000000
117.010002,65.038200,-95.767487,-0.001147,0.003620,0.091952,289.304352,14.737866,0.919519,-95.767487,294.500488,0.000000
117.360008,65.041557,-95.767487,-0.001143,0.003620,0.091961,289.319305,14.738627,0.919606,-95.767487,294.500488,0.000000
117.710007,65.006172,-95.723007,-0.001151,0.003620,0.091961,289.161896,14.730610,0.919606,-95.723007,294.500488,0.000000
118.060005,64.961128,-95.811966,-0.001164,0.003621,0.091978,288.961517,14.720403,0.919780,-95.811966,294.500488,0.000000
118.410004,64.901543,-95.811966,-0.001147,0.003621,0.091978,288.696472,14.706901,0.919780,-95.811966,294.500488,0.000000
118.760002,65.330894,-95.900932,-0.001147,0.003627,0.092134,290.606323,14.804193,0.921341,-95.900932,294.500488,0.000000
119.110008,65.308540,-95.989891,-0.001143,0.003627,0.092134,290.506897,14.799127,0.921341,-95.989891,294.500488,0.000000
119.460007,65.264977,-95.945412,-0.001147,0.003627,0.092134,290.313110,14.789255,0.921341,-95.945412,294.500488,0.000000
119.810005,65.225502,-95.989891,-0.001147,0.003627,0.092134,290.137512,14.780310,0.921341,-95.989891,294.500488,0.000000
120.160004,65.141716,-96.034370,-0.001147,0.003627,0.092134,289.764832,14.761324,0.921341,-96.034370,294.500488,0.000000
120.510002,65.064262,-96.078857,-0.001151,0.003627,0.092134,289.420288,14.743773,0.921341,-96.078857,294.500488,0.000000
120.860008,65.014000,-96.123337,-0.001143,0.003627,0.092134,289.196716,14.732384,0.921341,-96.123337,294.500488,0.000000
121.210007,64.933937,-96.123337,-0.001143,0.003627,0.092134,288.840576,14.714240,0.921341,-96.123337,294.500488,0.000000
121.560005,64.857231,-96.123337,-0.001147,0.003627,0.092134,288.499359,14.696858,0.921341,-96.123337,294.500488,0.000000
121.910004,64.786110,-96.212296,-0.001134,0.003627,0.092134,288.183014,14.680742,0.921341,-96.212296,294.500488,0.000000
122.260002,64.707542,-96.256775,-0.001134,0.003627,0.092134,287.833527,14.662939,0.921341,-96.256775,294.500488,0.000000
122.610008,64.658012,-96.256775,-0.001138,0.003627,0.092134,287.613190,14.651715,0.921341,-96.256775,294.500488,0.000000
122.960007,64.576088,-96.301262,-0.001125,0.003627,0.092134,287.248779,14.633151,0.921341,-96.301262,294.500488,0.000000
123.310005,64.485603,-96.301262,-0.001134,0.003627,0.092134,286.846283,14.612646,0.921341,-96.301262,294.500488,0.000000
123.660004,64.406654,-96.301262,-0.001134,0.003624,0.092056,286.495117,14.594756,0.920560,-96.301262,0.092091,0.000000
124.010002,64.261055,-96.434700,-0.001130,0.003612,0.091735,285.847443,14.561763,0.917351,-96.434700,0.091510,0.000000
124.360008,64.133705,-96.390221,-0.001138,0.003593,0.091258,285.280975,14.532906,0.912582,-96.390221,0.090929,0.000000
124.710007,63.961296,-96.434700,-0.001121,0.003576,0.090842,284.514069,14.493837,0.908419,-96.434700,0.090339,0.000000
125.060005,63.867088,-96.479179,-0.001112,0.003551,0.090183,284.095001,14.472489,0.901828,-96.479179,0.089758,0.000000
125.410004,63.768410,-96.523666,-0.001130,0.003532,0.089714,283.656067,14.450129,0.897145,-96.523666,0.089177,0.000000
125.760010,63.744576,-96.523666,-0.001108,0.003504,0.089003,283.550018,14.444728,0.890034,-96.523666,0.088596,0.000000
126.110008,63.637703,-96.612625,-0.001117,0.003481,0.088414,283.074646,14.420510,0.884137,-96.612625,0.088006,0.000000
126.460007,63.518181,-96.568146,-0.001121,0.003462,0.087937,282.542969,14.393425,0.879367,-96.568146,0.087425,0.000000
126.810005,63.456734,-96.657104,-0.001130,0.003444,0.087477,282.269653,14.379502,0.874771,-96.657104,0.086844,0.000000
127.160004,63.196449,-96.701584,-0.001117,0.003422,0.086931,281.111847,14.320520,0.869307,-96.701584,0.086254,0.000000
127.510010,62.878815,-96.746071,-0.001121,0.003399,0.086341,279.698944,14.248543,0.863410,-96.746071,0.085673,0.000000
127.860008,62.026451,-96.746071,-0.001112,0.003377,0.085777,275.907440,14.055394,0.857773,-96.746071,0.085092,0.000000
128.210007,61.110046,-96.835030,-0.001099,0.003355,0.085222,271.831055,13.847734,0.852223,-96.835030,0.084511,0.000000
128.560013,60.261780,-96.879509,-0.001108,0.003336,0.084745,268.057770,13.655515,0.847453,-96.879509,0.083921,0.000000
128.910004,58.787186,-96.879509,-0.001104,0.003311,0.084095,261.498474,13.321366,0.840949,-96.879509,0.083340,0.000000
129.260010,57.763161,-96.923996,-0.001095,0.003297,0.083748,256.943359,13.089319,0.837480,-96.923996,0.082759,0.000000
129.610001,56.010406,-96.968475,-0.001087,0.003276,0.083202,249.146729,12.692140,0.832016,-96.968475,0.082178,0.000000
129.960007,54.044647,-97.012955,-0.001087,0.003248,0.082499,240.402603,12.246693,0.824992,-97.012955,0.081589,0.000000
130.310013,52.009636,-97.012955,-0.001082,0.003227,0.081962,231.350418,11.785552,0.819615,-97.012955,0.081008,0.000000
130.660004,50.199905,-97.057434,-0.001082,0.003209,0.081502,223.300339,11.375462,0.815019,-97.057434,0.080427,0.000000
131.010010,48.147385,-97.146400,-0.001091,0.003188,0.080982,214.170258,10.910354,0.809815,-97.146400,0.079845,0.000000
131.360001,45.130051,-97.101913,-0.001091,0.003159,0.080227,200.748489,10.226616,0.802271,-97.101913,0.079256,0.000000
131.710007,43.267822,-97.146400,-0.001087,0.003143,0.079837,192.464890,9.804629,0.798368,-97.146400,0.078675,0.000000
132.060013,39.527336,-97.146400,-0.001104,0.003107,0.078918,175.826370,8.957023,0.789175,-97.146400,0.078094,0.000000
132.410004,37.718353,-97.190880,-0.001078,0.003091,0.078510,167.779617,8.547101,0.785099,-97.190880,0.077504,0.000000
132.760010,36.291046,-97.146400,-0.001099,0.003078,0.078189,161.430634,8.223668,0.781891,-97.146400,0.076923,0.000000
133.110001,32.625046,-97.235359,-0.001104,0.003040,0.077226,145.123459,7.392941,0.772265,-97.235359,0.076342,0.000000
133.460007,31.184334,-97.324318,-0.001104,0.003030,0.076966,138.714844,7.066471,0.769663,-97.324318,0.075761,0.000000
133.810013,28.218018,-97.368805,-0.001117,0.003002,0.076246,125.520012,6.394294,0.762465,-97.368805,0.075171,0.000000
134.160004,25.513474,-97.368805,-0.001108,0.002974,0.075544,113.489601,5.781436,0.755440,-97.368805,0.074590,0.000000
134.510010,24.196762,-97.413284,-0.001121,0.002964,0.075284,107.632576,5.483065,0.752839,-97.413284,0.074009,0.000000
134.860001,20.381065,-97.413284,-0.001125,0.002927,0.074347,90.659508,4.618415,0.743473,-97.413284,0.073428,0.000000
135.210007,18.121880,-97.502243,-0.001125,0.002906,0.073801,80.610146,4.106476,0.738009,-97.502243,0.072838,0.000000
135.560013,16.110695,-97.502243,-0.001130,0.002883,0.073237,71.663948,3.650736,0.732372,-97.502243,0.072257,0.000000
135.910004,12.920952,-97.546722,-0.001134,0.002856,0.072552,57.475266,2.927930,0.725521,-97.546722,0.071676,0.000000
136.260010,10.962273,-97.546722,-0.001143,0.002838,0.072075,48.762623,2.484087,0.720751,-97.546722,0.071095,0.000000
136.610001,8.841614,-97.591209,-0.001151,0.002817,0.071563,39.329464,2.003538,0.715635,-97.591209,0.070505,0.000000
136.960007,6.041748,-97.635689,-0.001155,0.002789,0.070835,26.875038,1.369080,0.708350,-97.635689,0.069924,0.000000
137.310013,4.454323,-97.680168,-0.001147,0.002770,0.070358,19.813818,1.009364,0.703580,-97.680168,0.069343,0.000000
137.660004,1.844734,-97.680168,-0.001181,0.002746,0.069760,8.205788,0.418023,0.697596,-97.680168,0.068754,0.000000
138.010010,-0.721657,-97.724648,-0.001194,0.002720,0.069092,-3.210090,-0.163530,0.690919,-97.724648,0.068173,0.000000
138.360001,-2.535854,-97.769127,-0.001190,0.002700,0.068572,-11.280044,-0.574633,0.685715,-97.769127,0.067592,0.000000
138.710007,-4.044334,-97.769127,-0.001194,0.002684,0.068173,-17.990097,-0.916459,0.681726,-97.769127,0.067011,0.000000
139.060013,-6.373898,-97.858093,-0.001194,0.002653,0.067392,-28.352512,-1.444346,0.673921,-97.858093,0.066421,0.000000
139.410004,-0.144852,-97.858093,-0.001311,0.002632,0.066863,-0.644332,-0.032824,0.668631,-97.858093,0.065840,0.000000
139.760010,-0.055107,-97.858093,-0.001345,0.002606,0.066195,-0.245129,-0.012487,0.661953,-97.858093,0.065259,0.000000
140.110001,-0.011169,-97.947052,-0.001367,0.002586,0.065692,-0.049684,-0.002531,0.656923,-97.947052,0.064678,0.000000
140.460007,-0.049896,-97.947052,-0.001414,0.002563,0.065103,-0.221950,-0.011307,0.651026,-97.947052,0.064088,0.000000
140.810013,-0.015266,-97.947052,-0.001457,0.002541,0.064530,-0.067908,-0.003459,0.645303,-97.947052,0.063507,0.000000
141.160004,-0.005959,-97.991531,-0.001487,0.002516,0.063915,-0.026505,-0.001350,0.639145,-97.991531,0.062926,0.000000
141.510010,-0.000374,-98.080498,-0.001526,0.002501,0.063524,-0.001663,-0.000085,0.635243,-98.080498,0.062336,0.000000
141.860001,0.026070,-98.080498,-0.001552,0.002465,0.062622,0.115964,0.005907,0.626224,-98.080498,0.061755,0.000000
142.210007,-0.007072,-98.169456,-0.001591,0.002448,0.062180,-0.031460,-0.001603,0.621801,-98.169456,0.061174,0.000000
142.560013,-0.008194,-98.124977,-0.001625,0.002422,0.061521,-0.036449,-0.001857,0.615210,-98.124977,0.060593,0.000000
142.910004,0.025696,-98.169456,-0.001677,0.002399,0.060940,0.114301,0.005823,0.609399,-98.169456,0.060003,0.000000
143.260010,0.023460,-98.169456,-0.001712,0.002376,0.060359,0.104357,0.005316,0.603589,-98.169456,0.059422,0.000000
143.610001,-0.008194,-98.258423,-0.001725,0.002355,0.059813,-0.036449,-0.001857,0.598126,-98.258423,0.058841,0.000000
143.960007,0.010803,-98.302902,-0.001763,0.002330,0.059179,0.048055,0.002448,0.591795,-98.302902,0.058260,0.000000
144.310013,-0.024200,-98.302902,-0.001794,0.002310,0.058668,-0.107649,-0.005484,0.586678,-98.302902,0.057671,0.000000
144.660004,0.005211,-98.347382,-0.001837,0.002293,0.058234,0.023179,0.001181,0.582342,-98.347382,0.057089,0.000000
145.010010,-0.009682,-98.347382,-0.001854,0.002267,0.057575,-0.043066,-0.002194,0.575751,-98.347382,0.056508,0.000000
145.360001,-0.011169,-98.391861,-0.001893,0.002250,0.057159,-0.049684,-0.002531,0.571588,-98.391861,0.055927,0.000000
145.710007,-0.005585,-98.436348,-0.001919,0.002214,0.056231,-0.024842,-0.001266,0.562309,-98.436348,0.055338,0.000000
146.060013,-0.016014,-98.436348,-0.001949,0.002193,0.055693,-0.071234,-0.003629,0.556932,-98.436348,0.054757,0.000000
146.410004,-0.000740,-98.480827,-0.001970,0.002178,0.055320,-0.003292,-0.000168,0.553203,-98.480827,0.054176,0.000000
146.760010,-0.015640,-98.525307,-0.002013,0.002151,0.054644,-0.069571,-0.003544,0.546439,-98.525307,0.053586,0.000000
147.100006,0.024208,-98.614265,-0.002039,0.002142,0.054418,0.107683,0.005486,0.544184,-98.614265,0.054340,0.000000