File: Data/compression 15/AutoNoHeating-17-15-reverse-longpurge-2re_08262024_190939.csv
Time (sec),S:Load (lbs),S:HL1 (DIM),S:LVDT (in),S:Position (in),Ch:Position (mm),Ch:Load (N),Ch:Stress (MPa),Ch:Strain (mm/mm),Ch:HL1 (DIM),Set Point (),Cycles ()
0.210000,-0.056976,-80.021233,-0.005402,-0.005403,-0.137238,-0.253443,-0.012911,-1.372385,-80.021233,-0.137004,0.000000
0.550000,0.025688,-80.110191,-0.005402,-0.005329,-0.135357,0.114267,0.005821,-1.353566,-80.110191,-0.134645,0.000000
0.890000,0.015640,-80.110191,-0.005277,-0.005126,-0.130188,0.069571,0.003544,-1.301879,-80.110191,-0.128991,0.000000
1.230000,0.002228,-80.154671,-0.005040,-0.004898,-0.124421,0.009910,0.000505,-1.244209,-80.154671,-0.123319,0.000000
1.570000,0.102768,-80.243637,-0.004889,-0.000003,-0.000069,0.457135,0.023288,-0.000694,-80.243637,0.000147,0.000000
1.910000,0.098305,-80.199158,-0.004889,-0.000003,-0.000069,0.437281,0.022276,-0.000694,-80.199158,0.000147,0.000000
2.250000,0.130325,-80.243637,-0.004889,-0.000002,-0.000061,0.579716,0.029532,-0.000607,-80.243637,0.000590,0.000000
2.590000,0.118408,-80.332596,-0.004885,-0.000002,-0.000061,0.526706,0.026832,-0.000607,-80.332596,0.001153,0.000000
2.930000,0.233101,-80.332596,-0.004872,0.000025,0.000642,1.036885,0.052821,0.006418,-80.332596,0.001726,0.000000
3.270000,0.402161,-80.377075,-0.004868,0.000050,0.001266,1.788900,0.091131,0.012662,-80.377075,0.002289,0.000000
3.610000,0.643082,-80.421562,-0.004829,0.000072,0.001821,2.860570,0.145724,0.018212,-80.421562,0.002853,0.000000
3.950000,0.960342,-80.466042,-0.004816,0.000097,0.002463,4.271816,0.217617,0.024629,-80.466042,0.003426,0.000000
4.290000,1.218399,-80.466042,-0.004790,0.000117,0.002983,5.419710,0.276093,0.029833,-80.466042,0.003989,0.000000
4.630000,1.574387,-80.555000,-0.004777,0.000137,0.003486,7.003222,0.356761,0.034863,-80.555000,0.004553,0.000000
4.970000,2.182098,-80.643967,-0.004751,0.000165,0.004197,9.706458,0.494471,0.041974,-80.643967,0.005125,0.000000
5.310000,2.420044,-80.599480,-0.004730,0.000180,0.004579,10.764894,0.548390,0.045790,-80.599480,0.005689,0.000000
5.650000,3.036324,-80.732925,-0.004725,0.000208,0.005290,13.506242,0.688041,0.052901,-80.732925,0.006253,0.000000
5.990000,3.418373,-80.777405,-0.004682,0.000231,0.005862,15.205683,0.774614,0.058624,-80.777405,0.006825,0.000000
6.330000,3.719627,-80.732925,-0.004661,0.000248,0.006305,16.545729,0.842880,0.063047,-80.732925,0.007389,0.000000
6.670001,4.382072,-80.821892,-0.004669,0.000271,0.006877,19.492432,0.992992,0.068771,-80.821892,0.007952,0.000000
7.010000,4.707161,-80.866371,-0.004639,0.000289,0.007337,20.938498,1.066658,0.073367,-80.866371,0.008525,0.000000
7.350000,5.431046,-80.866371,-0.004605,0.000316,0.008031,24.158497,1.230693,0.080305,-80.866371,0.009089,0.000000
7.690001,6.077858,-80.955330,-0.004587,0.000340,0.008646,27.035662,1.377262,0.086462,-80.955330,0.009661,0.000000
8.030001,6.414482,-80.999809,-0.004583,0.000361,0.009167,28.533041,1.453542,0.091666,-80.999809,0.010225,0.000000
8.370001,6.577209,-81.088776,-0.004557,0.000375,0.009522,29.256889,1.490417,0.095221,-81.088776,0.010788,0.000000
8.710000,7.416168,-80.999809,-0.004540,0.000405,0.010294,32.988762,1.680528,0.102940,-80.999809,0.011361,0.000000
9.050000,7.935257,-81.177734,-0.004518,0.000429,0.010892,35.297787,1.798155,0.108924,-81.177734,0.011924,0.000000
9.390000,8.031326,-81.177734,-0.004510,0.000441,0.011205,35.725124,1.819925,0.112046,-81.177734,0.012488,0.000000
9.730000,8.790596,-81.133255,-0.004484,0.000473,0.012020,39.102524,1.991978,0.120197,-81.133255,0.013060,0.000000
10.070001,9.200951,-81.311180,-0.004467,0.000496,0.012592,40.927872,2.084965,0.125921,-81.311180,0.013624,0.000000
10.410001,9.655243,-81.266701,-0.004445,0.000515,0.013078,42.948666,2.187909,0.130778,-81.266701,0.014188,0.000000
10.750001,10.303169,-81.400139,-0.004419,0.000539,0.013694,45.830788,2.334732,0.136935,-81.400139,0.014760,0.000000
11.090000,10.489357,-81.400139,-0.004402,0.000558,0.014170,46.658989,2.376922,0.141705,-81.400139,0.015324,0.000000
11.430000,11.069138,-81.400139,-0.004398,0.000584,0.014830,49.237984,2.508302,0.148296,-81.400139,0.015888,0.000000
11.770000,11.713348,-81.533585,-0.004363,0.000611,0.015532,52.103577,2.654283,0.155320,-81.533585,0.016460,0.000000
12.110001,11.744995,-81.489105,-0.004342,0.000627,0.015922,52.244347,2.661454,0.159223,-81.489105,0.017024,0.000000
12.450001,12.248070,-81.578064,-0.004337,0.000649,0.016495,54.482136,2.775452,0.164946,-81.578064,0.017587,0.000000
12.790001,12.967125,-81.667023,-0.004299,0.000675,0.017145,57.680653,2.938393,0.171451,-81.667023,0.018160,0.000000
13.130001,13.099686,-81.622543,-0.004294,0.000695,0.017657,58.270313,2.968431,0.176567,-81.622543,0.018723,0.000000
13.470000,13.910339,-81.711510,-0.004260,0.000722,0.018333,61.876278,3.152128,0.183332,-81.711510,0.019287,0.000000
13.810000,14.083870,-81.755989,-0.004230,0.000742,0.018853,62.648182,3.191451,0.188535,-81.755989,0.019859,0.000000
14.150001,14.347511,-81.800468,-0.004234,0.000761,0.019330,63.820919,3.251193,0.193305,-81.800468,0.020423,0.000000
14.490001,15.031929,-81.889427,-0.004195,0.000788,0.020024,66.865356,3.406284,0.200242,-81.889427,0.020987,0.000000
14.830001,15.267265,-81.755989,-0.004186,0.000808,0.020527,67.912186,3.459612,0.205272,-81.755989,0.021559,0.000000
15.170001,15.721931,-81.978394,-0.004161,0.000829,0.021065,69.934647,3.562641,0.210649,-81.978394,0.022123,0.000000
15.510001,15.551758,-81.933914,-0.004148,0.000839,0.021308,69.177673,3.524079,0.213077,-81.933914,0.022695,0.000000
15.850000,16.704254,-82.067352,-0.004122,0.000877,0.022270,74.304230,3.785238,0.222704,-82.067352,0.023259,0.000000
16.190001,16.887085,-82.111839,-0.004105,0.000898,0.022808,75.117508,3.826668,0.228080,-82.111839,0.023823,0.000000
16.530001,17.261322,-82.067352,-0.004079,0.000919,0.023337,76.782196,3.911472,0.233370,-82.067352,0.024395,0.000000
16.870001,17.530922,-82.156319,-0.004057,0.000939,0.023857,77.981438,3.972564,0.238574,-82.156319,0.024959,0.000000
17.210001,17.890633,-82.111839,-0.004036,0.000959,0.024352,79.581505,4.054075,0.243517,-82.111839,0.025522,0.000000
17.550001,17.975159,-82.245277,-0.004031,0.000974,0.024733,79.957497,4.073229,0.247333,-82.245277,0.026095,0.000000
17.890001,18.516220,-82.245277,-0.004010,0.000998,0.025340,82.364258,4.195835,0.253403,-82.245277,0.026659,0.000000
18.230001,19.737228,-82.334244,-0.003984,0.001037,0.026329,87.795578,4.472520,0.263290,-82.334244,0.027222,0.000000
18.570002,19.399483,-82.378723,-0.003962,0.001053,0.026754,86.293205,4.395986,0.267539,-82.378723,0.027795,0.000000
18.910002,19.507103,-82.467682,-0.003941,0.001070,0.027179,86.771927,4.420372,0.271789,-82.467682,0.028358,0.000000
19.250000,20.145348,-82.423203,-0.003919,0.001095,0.027803,89.610985,4.565001,0.278033,-82.423203,0.028922,0.000000
19.590000,20.532990,-82.467682,-0.003885,0.001120,0.028436,91.335297,4.652842,0.284363,-82.467682,0.029494,0.000000
19.930000,19.970329,-82.512161,-0.003876,0.001131,0.028740,88.832458,4.525342,0.287399,-82.512161,0.030058,0.000000
20.270000,21.136978,-82.645607,-0.003867,0.001163,0.029529,94.021973,4.789708,0.295290,-82.645607,0.030622,0.000000
20.610001,21.593132,-82.601128,-0.003820,0.001187,0.030145,96.051048,4.893074,0.301448,-82.601128,0.031194,0.000000
20.950001,21.591270,-82.601128,-0.003820,0.001204,0.030578,96.042770,4.892652,0.305784,-82.601128,0.031758,0.000000
21.290001,22.407135,-82.734566,-0.003773,0.001236,0.031402,99.671913,5.077529,0.314022,-82.734566,0.032322,0.000000
21.630001,22.319633,-82.734566,-0.003760,0.001256,0.031897,99.282692,5.057701,0.318966,-82.734566,0.032894,0.000000
21.970001,22.284996,-82.823532,-0.003729,0.001273,0.032322,99.128616,5.049852,0.323215,-82.823532,0.033458,0.000000
22.310001,21.435989,-82.823532,-0.003734,0.001273,0.032339,95.352043,4.857465,0.323389,-82.823532,0.034021,0.000000
22.650002,22.995483,-82.956970,-0.003704,0.001312,0.033336,102.289017,5.210851,0.333362,-82.956970,0.034594,0.000000
22.990002,23.856415,-82.912491,-0.003678,0.001347,0.034212,106.118629,5.405941,0.342121,-82.912491,0.035157,0.000000
23.330002,23.994560,-82.956970,-0.003648,0.001369,0.034776,106.733131,5.437245,0.347758,-82.956970,0.035721,0.000000
23.670002,23.787895,-83.045937,-0.003630,0.001383,0.035140,105.813843,5.390414,0.351400,-83.045937,0.036293,0.000000
24.010000,23.659424,-83.001457,-0.003617,0.001396,0.035461,105.242371,5.361302,0.354609,-83.001457,0.036857,0.000000
24.350000,24.963478,-83.134895,-0.003613,0.001434,0.036423,111.043098,5.656805,0.364235,-83.134895,0.037429,0.000000
24.690001,25.036087,-83.134895,-0.003570,0.001452,0.036892,111.366074,5.673258,0.368918,-83.134895,0.037993,0.000000
25.030001,25.710823,-83.179375,-0.003553,0.001482,0.037655,114.367455,5.826156,0.376549,-83.179375,0.038557,0.000000
25.370001,25.592415,-83.312820,-0.003527,0.001502,0.038141,113.840744,5.799324,0.381406,-83.312820,0.039129,0.000000
25.710001,25.521660,-83.268341,-0.003510,0.001520,0.038609,113.526016,5.783290,0.386089,-83.268341,0.039693,0.000000
26.050001,25.761093,-83.357300,-0.003501,0.001539,0.039103,114.591064,5.837547,0.391032,-83.357300,0.040257,0.000000
26.390001,26.613831,-83.401787,-0.003454,0.001569,0.039849,118.384232,6.030780,0.398490,-83.401787,0.040829,0.000000
26.730001,26.358009,-83.401787,-0.003449,0.001583,0.040213,117.246284,5.972810,0.402133,-83.401787,0.041393,0.000000
27.070002,27.149673,-83.490746,-0.003419,0.001613,0.040976,120.767776,6.152204,0.409764,-83.490746,0.041956,0.000000
27.410002,27.288193,-83.490746,-0.003402,0.001635,0.041540,121.383942,6.183593,0.415401,-83.490746,0.042529,0.000000
27.750002,27.399910,-83.579704,-0.003393,0.001655,0.042043,121.880890,6.208909,0.420431,-83.579704,0.043092,0.000000
28.090002,27.424110,-83.624191,-0.003367,0.001673,0.042503,121.988533,6.214392,0.425027,-83.624191,0.043656,0.000000
28.430002,27.805794,-83.624191,-0.003341,0.001695,0.043049,123.686348,6.300883,0.430491,-83.624191,0.044229,0.000000
28.770000,27.966660,-83.713150,-0.003316,0.001715,0.043552,124.401917,6.337336,0.435521,-83.713150,0.044792,0.000000
29.110001,28.744919,-83.757629,-0.003307,0.001743,0.044263,127.863785,6.513691,0.442632,-83.757629,0.045356,0.000000
29.450001,29.061432,-83.757629,-0.003272,0.001767,0.044879,129.271698,6.585415,0.448789,-83.757629,0.045928,0.000000
29.790001,28.847321,-83.802109,-0.003264,0.001784,0.045304,128.319290,6.536896,0.453039,-83.802109,0.046492,0.000000
30.130001,29.754044,-83.846596,-0.003229,0.001809,0.045937,132.352600,6.742363,0.459369,-83.846596,0.047056,0.000000
30.470001,30.042259,-83.891075,-0.003216,0.001832,0.046535,133.634644,6.807673,0.465353,-83.891075,0.047628,0.000000
30.810001,30.674553,-83.846596,-0.003191,0.001858,0.047194,136.447220,6.950953,0.471944,-83.846596,0.048192,0.000000
31.150002,31.248375,-83.980034,-0.003173,0.001884,0.047854,138.999710,7.080983,0.478535,-83.980034,0.048755,0.000000
31.490002,30.951965,-83.980034,-0.003139,0.001899,0.048226,137.681213,7.013815,0.482264,-83.980034,0.049328,0.000000
31.830002,31.038361,-84.069000,-0.003147,0.001921,0.048781,138.065521,7.033393,0.487814,-84.069000,0.049891,0.000000
32.170002,32.016953,-84.157959,-0.003096,0.001947,0.049458,142.418518,7.255145,0.494579,-84.157959,0.050464,0.000000
32.510002,31.829277,-84.113480,-0.003096,0.001965,0.049909,141.583694,7.212617,0.499088,-84.113480,0.051028,0.000000
32.850002,32.874901,-84.246918,-0.003078,0.001993,0.050611,146.234863,7.449559,0.506113,-84.246918,0.051591,0.000000
33.190002,33.271477,-84.246918,-0.003035,0.002017,0.051236,147.998917,7.539424,0.512357,-84.246918,0.052164,0.000000
33.530003,32.924049,-84.246918,-0.003022,0.002036,0.051704,146.453491,7.460696,0.517040,-84.246918,0.052727,0.000000
33.870003,33.331429,-84.380363,-0.003014,0.002053,0.052146,148.265594,7.553010,0.521463,-84.380363,0.053291,0.000000
34.210003,33.992386,-84.380363,-0.002975,0.002077,0.052745,151.205688,7.702785,0.527447,-84.380363,0.053863,0.000000
34.550003,35.023491,-84.424843,-0.002962,0.002105,0.053464,155.792267,7.936436,0.534645,-84.424843,0.054427,0.000000
34.890003,35.123657,-84.424843,-0.002945,0.002127,0.054028,156.237823,7.959135,0.540282,-84.424843,0.054991,0.000000
35.230003,35.515396,-84.469330,-0.002940,0.002148,0.054566,157.980377,8.047904,0.545658,-84.469330,0.055563,0.000000
35.570004,35.639397,-84.558289,-0.002910,0.002167,0.055043,158.531952,8.076002,0.550428,-84.558289,0.056127,0.000000
35.910000,36.191246,-84.558289,-0.002880,0.002190,0.055615,160.986710,8.201054,0.556152,-84.558289,0.056691,0.000000
36.250000,36.544632,-84.602768,-0.002871,0.002209,0.056110,162.558640,8.281132,0.561095,-84.602768,0.057263,0.000000
36.590000,36.758003,-84.647247,-0.002846,0.002228,0.056586,163.507767,8.329482,0.565865,-84.647247,0.057827,0.000000
36.930000,37.922035,-84.602768,-0.002824,0.002258,0.057350,168.685638,8.593256,0.573496,-84.602768,0.058390,0.000000
37.270000,38.271324,-84.825172,-0.002807,0.002281,0.057948,170.239349,8.672406,0.579480,-84.825172,0.058963,0.000000
37.610001,38.811264,-84.780693,-0.002790,0.002302,0.058477,172.641129,8.794759,0.584770,-84.780693,0.059526,0.000000
37.950001,38.941223,-84.869652,-0.002777,0.002323,0.059006,173.219208,8.824207,0.590060,-84.869652,0.060090,0.000000
38.290001,39.583191,-84.869652,-0.002764,0.002345,0.059561,176.074829,8.969680,0.595611,-84.869652,0.060662,0.000000
38.630001,39.611862,-84.914139,-0.002738,0.002358,0.059891,176.202362,8.976176,0.598906,-84.914139,0.061226,0.000000
38.970001,40.745361,-85.003098,-0.002721,0.002386,0.060593,181.244415,9.233030,0.605931,-85.003098,0.061790,0.000000
39.310001,41.551926,-85.003098,-0.002695,0.002416,0.061365,184.832199,9.415801,0.613649,-85.003098,0.062362,0.000000
39.650002,42.575203,-85.092056,-0.002677,0.002439,0.061955,189.383957,9.647679,0.619546,-85.092056,0.062926,0.000000
39.990002,42.759155,-85.181023,-0.002652,0.002454,0.062336,190.202225,9.689363,0.623362,-85.181023,0.063490,0.000000
40.330002,43.166901,-85.136543,-0.002621,0.002475,0.062857,192.015961,9.781760,0.628565,-85.136543,0.064062,0.000000
40.670002,44.447861,-85.225502,-0.002621,0.002504,0.063602,197.713959,10.072029,0.636023,-85.225502,0.064626,0.000000
41.010002,44.792305,-85.225502,-0.002596,0.002525,0.064123,199.246124,10.150081,0.641227,-85.225502,0.065198,0.000000
41.350002,45.255165,-85.358948,-0.002578,0.002545,0.064643,201.305023,10.254967,0.646430,-85.358948,0.065762,0.000000
41.690002,46.000656,-85.314461,-0.002557,0.002568,0.065215,204.621140,10.423898,0.652154,-85.314461,0.066325,0.000000
42.030003,46.500381,-85.358948,-0.002535,0.002588,0.065736,206.844025,10.537137,0.657357,-85.358948,0.066898,0.000000
42.370003,47.735916,-85.403427,-0.002527,0.002617,0.066482,212.339966,10.817114,0.664815,-85.403427,0.067461,0.000000
42.710003,48.786751,-85.403427,-0.002505,0.002642,0.067097,217.014313,11.055236,0.670973,-85.403427,0.068025,0.000000
43.050003,48.974792,-85.447906,-0.002492,0.002661,0.067583,217.850754,11.097846,0.675829,-85.447906,0.068598,0.000000
43.390003,49.322220,-85.625832,-0.002470,0.002678,0.068034,219.396194,11.176575,0.680339,-85.625832,0.069161,0.000000
43.730003,50.234901,-85.581352,-0.002458,0.002703,0.068658,223.456009,11.383391,0.686583,-85.581352,0.069725,0.000000
44.070004,50.099731,-85.581352,-0.002449,0.002721,0.069118,222.854736,11.352762,0.691179,-85.581352,0.070297,0.000000
44.410004,52.360405,-85.670311,-0.002414,0.002753,0.069916,232.910721,11.865038,0.699157,-85.670311,0.070861,0.000000
44.750004,52.593880,-85.759277,-0.002414,0.002768,0.070306,233.949265,11.917944,0.703060,-85.759277,0.071425,0.000000
45.090004,52.258377,-85.848236,-0.002376,0.002783,0.070696,232.456863,11.841918,0.706962,-85.848236,0.071997,0.000000
45.430000,53.181862,-85.759277,-0.002354,0.002802,0.071165,236.564743,12.051182,0.711645,-85.759277,0.072561,0.000000
45.770000,55.027336,-85.937195,-0.002350,0.002833,0.071954,244.773819,12.469373,0.719537,-85.937195,0.073124,0.000000
46.110001,55.907997,-85.892715,-0.002337,0.002859,0.072621,248.691193,12.668933,0.726215,-85.892715,0.073697,0.000000
46.450001,57.377754,-85.937195,-0.002302,0.002885,0.073281,255.229004,13.001986,0.732806,-85.937195,0.074261,0.000000
46.790001,57.953072,-86.026161,-0.002289,0.002905,0.073792,257.788147,13.132354,0.737922,-86.026161,0.074824,0.000000
47.130001,58.479599,-85.981682,-0.002272,0.002923,0.074252,260.130249,13.251666,0.742519,-85.981682,0.075397,0.000000
47.470001,59.533043,-86.070641,-0.002272,0.002947,0.074850,264.816193,13.490380,0.748503,-86.070641,0.075960,0.000000
47.810001,60.602501,-86.115120,-0.002238,0.002969,0.075423,269.573395,13.732723,0.754226,-86.115120,0.076524,0.000000
48.150002,60.554092,-86.159599,-0.002229,0.002982,0.075735,269.358063,13.721753,0.757348,-86.159599,0.077096,0.000000
48.490002,62.723160,-86.204086,-0.002203,0.003016,0.076611,279.006561,14.213271,0.766107,-86.204086,0.077660,0.000000
48.830002,63.265327,-86.204086,-0.002190,0.003037,0.077148,281.418243,14.336128,0.771484,-86.204086,0.078232,0.000000
49.170002,64.349678,-86.248566,-0.002177,0.003057,0.077660,286.241669,14.581845,0.776601,-86.248566,0.078796,0.000000
49.510002,65.266090,-86.293045,-0.002156,0.003080,0.078232,290.318085,14.789508,0.782324,-86.293045,0.079360,0.000000
49.850002,65.728584,-86.337524,-0.002143,0.003093,0.078571,292.375336,14.894310,0.785707,-86.337524,0.079932,0.000000
50.190002,65.499199,-86.382004,-0.002126,0.003099,0.078709,291.354980,14.842331,0.787094,-86.382004,0.013824,0.000000
50.530003,65.130913,-86.426491,-0.002108,0.003111,0.079030,289.716766,14.758876,0.790303,-86.426491,294.500488,0.000000
50.870003,64.905632,-86.515450,-0.002104,0.003122,0.079308,288.714661,14.707827,0.793078,-86.515450,294.500488,0.000000
51.210003,64.718330,-86.515450,-0.002117,0.003129,0.079473,287.881500,14.665382,0.794726,-86.515450,294.500488,0.000000
51.550003,65.280983,-86.559929,-0.002095,0.003138,0.079715,290.384308,14.792882,0.797154,-86.559929,294.500488,0.000000
51.890003,65.797096,-86.604408,-0.002061,0.003151,0.080028,292.680115,14.909836,0.800276,-86.604408,294.500488,0.000000
52.230003,64.760780,-86.648895,-0.002070,0.003151,0.080045,288.070343,14.675002,0.800449,-86.648895,294.500488,0.000000
52.570004,65.235924,-86.693375,-0.002057,0.003165,0.080383,290.183868,14.782672,0.803832,-86.693375,294.500488,0.000000
52.910004,65.763206,-86.693375,-0.002044,0.003182,0.080825,292.529358,14.902155,0.808254,-86.693375,294.500488,0.000000
53.250004,65.006172,-86.826813,-0.002048,0.003182,0.080825,289.161896,14.730610,0.808254,-86.826813,294.500488,0.000000
53.590004,65.966148,-86.871300,-0.002018,0.003190,0.081034,293.432068,14.948143,0.810336,-86.871300,294.500488,0.000000
53.930004,65.114540,-86.871300,-0.002022,0.003191,0.081042,289.643951,14.755165,0.810422,-86.871300,294.500488,0.000000
54.270004,65.363655,-86.915779,-0.002022,0.003205,0.081406,290.752045,14.811616,0.814065,-86.915779,294.500488,0.000000
54.610004,64.707909,-86.915779,-0.002009,0.003205,0.081406,287.835144,14.663021,0.814065,-86.915779,294.500488,0.000000
54.950001,64.112846,-86.960258,-0.002005,0.003205,0.081415,285.188171,14.528178,0.814151,-86.960258,294.500488,0.000000
55.290001,64.759666,-87.049225,-0.001966,0.003121,0.079264,288.065369,14.674750,0.792644,-87.049225,294.500488,0.000000
55.630001,65.500313,-87.093704,-0.001975,0.003211,0.081571,291.359955,14.842584,0.815713,-87.093704,294.500488,0.000000
55.970001,65.334984,-87.182663,-0.001983,0.003229,0.082014,290.624512,14.805119,0.820135,-87.182663,294.500488,0.000000
56.310001,64.986809,-87.182663,-0.001975,0.003231,0.082066,289.075775,14.726221,0.820656,-87.182663,294.500488,0.000000
56.650002,64.574593,-87.271629,-0.001979,0.003231,0.082066,287.242126,14.632812,0.820656,-87.271629,294.500488,0.000000
56.990002,66.206703,-87.227142,-0.001962,0.003207,0.081459,294.502136,15.002653,0.814585,-87.227142,294.500488,0.000000
57.330002,65.658577,-87.271629,-0.001966,0.003208,0.081476,292.063934,14.878446,0.814759,-87.271629,294.500488,0.000000
57.670002,65.219170,-87.405067,-0.001949,0.003226,0.081953,290.109344,14.778874,0.819528,-87.405067,294.500488,0.000000
58.010002,65.230339,-87.405067,-0.001944,0.003256,0.082699,290.159027,14.781406,0.826986,-87.405067,294.500488,0.000000
58.350002,65.337593,-87.405067,-0.001949,0.003263,0.082872,290.636139,14.805711,0.828721,-87.405067,294.500488,0.000000
58.690002,65.257896,-87.494034,-0.001949,0.003267,0.082976,290.281616,14.787651,0.829762,-87.494034,294.500488,0.000000
59.030003,65.669746,-87.494034,-0.001927,0.003277,0.083228,292.113617,14.880977,0.832277,-87.494034,294.500488,0.000000
59.370003,65.418388,-87.494034,-0.001927,0.003276,0.083219,290.995514,14.824019,0.832190,-87.494034,294.500488,0.000000
59.710003,65.286949,-87.582993,-0.001944,0.003280,0.083306,290.410858,14.794234,0.833057,-87.582993,294.500488,0.000000
60.050003,65.329399,-87.627472,-0.001923,0.003284,0.083418,290.599670,14.803853,0.834184,-87.627472,294.500488,0.000000
60.390003,65.306679,-87.627472,-0.001936,0.003287,0.083496,290.498627,14.798705,0.834965,-87.627472,294.500488,0.000000
60.730003,65.137627,-87.671951,-0.001919,0.003290,0.083557,289.746643,14.760398,0.835572,-87.671951,294.500488,0.000000
61.070004,65.319710,-87.760918,-0.001919,0.003295,0.083687,290.556580,14.801658,0.836873,-87.760918,294.500488,0.000000
61.410004,65.075066,-87.805397,-0.001893,0.003295,0.083696,289.468353,14.746221,0.836960,-87.805397,294.500488,0.000000
61.750004,65.090324,-87.760918,-0.001901,0.003299,0.083783,289.536224,14.749679,0.837827,-87.760918,294.500488,0.000000
62.090004,65.130547,-87.849876,-0.001914,0.003304,0.083921,289.715149,14.758793,0.839214,-87.849876,294.500488,0.000000
62.430004,65.333122,-87.938843,-0.001901,0.003309,0.084043,290.616241,14.804697,0.840428,-87.938843,294.500488,0.000000
62.770004,65.232582,-87.983322,-0.001901,0.003308,0.084034,290.169006,14.781914,0.840342,-87.983322,294.500488,0.000000
63.110004,65.136513,-87.983322,-0.001906,0.003311,0.084104,289.741669,14.760145,0.841036,-87.983322,294.500488,0.000000
63.450005,65.106712,-88.072281,-0.001910,0.003316,0.084216,289.609131,14.753392,0.842163,-88.072281,294.500488,0.000000
63.790005,65.041924,-88.161247,-0.001897,0.003316,0.084216,289.320923,14.738711,0.842163,-88.161247,294.500488,0.000000
64.130005,64.932442,-88.116760,-0.001880,0.003317,0.084242,288.833923,14.713902,0.842423,-88.116760,294.500488,0.000000
64.470001,65.549095,-88.116760,-0.001880,0.003325,0.084459,291.576935,14.853638,0.844591,-88.116760,294.500488,0.000000
64.810005,65.314125,-88.205727,-0.001876,0.003325,0.084459,290.531738,14.800392,0.844591,-88.205727,294.500488,0.000000
65.150002,65.071342,-88.250206,-0.001880,0.003326,0.084468,289.451782,14.745378,0.844678,-88.250206,294.500488,0.000000
65.490005,64.853874,-88.383652,-0.001876,0.003326,0.084468,288.484436,14.696098,0.844678,-88.383652,294.500488,0.000000
65.830002,64.617790,-88.383652,-0.001871,0.003326,0.084468,287.434296,14.642601,0.844678,-88.383652,294.500488,0.000000
66.170006,64.384315,-88.428131,-0.001884,0.003326,0.084476,286.395752,14.589694,0.844765,-88.428131,294.500488,0.000000
66.510002,66.729149,-88.472610,-0.001850,0.003277,0.083236,296.826080,15.121041,0.832363,-88.472610,294.500488,0.000000
66.850006,66.414116,-88.472610,-0.001858,0.003277,0.083245,295.424744,15.049654,0.832450,-88.472610,294.500488,0.000000
67.190002,66.150475,-88.561577,-0.001863,0.003277,0.083245,294.252014,14.989912,0.832450,-88.561577,294.500488,0.000000
67.530006,65.812737,-88.561577,-0.001845,0.003278,0.083262,292.749664,14.913380,0.832623,-88.561577,294.500488,0.000000
67.870003,65.601967,-88.650536,-0.001841,0.003297,0.083739,291.812134,14.865618,0.837393,-88.650536,294.500488,0.000000
68.210007,65.426949,-88.695015,-0.001854,0.003311,0.084104,291.033600,14.825958,0.841036,-88.695015,294.500488,0.000000
68.550003,65.276512,-88.606056,-0.001850,0.003327,0.084511,290.364441,14.791869,0.845111,-88.606056,294.500488,0.000000
68.890007,65.111183,-88.783981,-0.001850,0.003336,0.084728,289.628998,14.754405,0.847280,-88.783981,294.500488,0.000000
69.230003,65.078789,-88.739494,-0.001845,0.003346,0.084979,289.484924,14.747064,0.849795,-88.739494,294.500488,0.000000
69.570000,65.285088,-88.828461,-0.001854,0.003352,0.085144,290.402588,14.793813,0.851442,-88.828461,294.500488,0.000000
69.910004,65.165184,-88.872940,-0.001841,0.003352,0.085153,289.869202,14.766642,0.851529,-88.872940,294.500488,0.000000
70.250000,65.018089,-88.872940,-0.001841,0.003354,0.085179,289.214905,14.733310,0.851789,-88.872940,294.500488,0.000000
70.590004,65.263481,-89.006386,-0.001841,0.003358,0.085300,290.306458,14.788917,0.853003,-89.006386,294.500488,0.000000
70.930000,65.102623,-89.006386,-0.001841,0.003358,0.085300,289.590942,14.752465,0.853003,-89.006386,294.500488,0.000000
71.270004,65.011757,-89.050865,-0.001841,0.003360,0.085352,289.186737,14.731875,0.853524,-89.050865,294.500488,0.000000
71.610001,64.948830,-89.095345,-0.001824,0.003364,0.085448,288.906830,14.717615,0.854478,-89.095345,294.500488,0.000000
71.950005,65.281731,-89.139824,-0.001832,0.003366,0.085500,290.387634,14.793052,0.854998,-89.139824,294.500488,0.000000
72.290001,65.183052,-89.228790,-0.001828,0.003367,0.085534,289.948700,14.770691,0.855345,-89.228790,294.500488,0.000000
72.630005,65.115654,-89.228790,-0.001819,0.003370,0.085595,289.648895,14.755418,0.855952,-89.228790,294.500488,0.000000
72.970001,65.325294,-89.317749,-0.001832,0.003372,0.085656,290.581421,14.802923,0.856559,-89.317749,294.500488,0.000000
73.310005,65.244865,-89.362228,-0.001824,0.003373,0.085665,290.223663,14.784698,0.856646,-89.362228,294.500488,0.000000
73.650002,65.140602,-89.362228,-0.001815,0.003374,0.085691,289.759857,14.761071,0.856906,-89.362228,294.500488,0.000000
73.990005,65.059059,-89.451195,-0.001819,0.003375,0.085717,289.397156,14.742594,0.857166,-89.451195,294.500488,0.000000
74.330002,64.978249,-89.451195,-0.001819,0.003375,0.085717,289.037689,14.724281,0.857166,-89.451195,294.500488,0.000000
74.670006,65.827263,-89.495674,-0.001837,0.003387,0.086037,292.814301,14.916672,0.860375,-89.495674,294.500488,0.000000
75.010002,65.762093,-89.540154,-0.001815,0.003385,0.085985,292.524384,14.901904,0.859854,-89.540154,294.500488,0.000000
75.350006,65.613518,-89.584633,-0.001807,0.003385,0.085985,291.863495,14.868236,0.859854,-89.584633,294.500488,0.000000
75.690002,65.524895,-89.584633,-0.001815,0.003385,0.085985,291.469299,14.848153,0.859854,-89.584633,294.500488,0.000000
76.030006,65.375572,-89.629120,-0.001802,0.003385,0.085985,290.805084,14.814316,0.859854,-89.629120,294.500488,0.000000
76.370003,65.253059,-89.762558,-0.001811,0.003385,0.085985,290.260101,14.786554,0.859854,-89.762558,294.500488,0.000000
76.710007,65.109322,-89.807037,-0.001794,0.003387,0.086020,289.620728,14.753983,0.860201,-89.807037,294.500488,0.000000
77.050003,65.012505,-89.851524,-0.001807,0.003387,0.086020,289.190063,14.732044,0.860201,-89.851524,294.500488,0.000000
77.390007,66.021263,-89.851524,-0.001798,0.003393,0.086194,293.677246,14.960632,0.861936,-89.851524,294.500488,0.000000
77.730003,65.852211,-89.851524,-0.001815,0.003391,0.086133,292.925262,14.922324,0.861329,-89.851524,294.500488,0.000000
78.070007,65.701027,-89.940483,-0.001807,0.003391,0.086133,292.252777,14.888065,0.861329,-89.940483,294.500488,0.000000
78.410004,65.543877,-89.984962,-0.001802,0.003391,0.086133,291.553711,14.852454,0.861329,-89.984962,294.500488,0.000000
78.750000,65.389717,-89.984962,-0.001798,0.003391,0.086133,290.867981,14.817522,0.861329,-89.984962,294.500488,0.000000
79.090004,65.269066,-90.029442,-0.001798,0.003391,0.086133,290.331299,14.790182,0.861329,-90.029442,294.500488,0.000000
79.430000,65.107094,-90.029442,-0.001798,0.003391,0.086142,289.610809,14.753479,0.861415,-90.029442,294.500488,0.000000
79.770004,64.976387,-90.118408,-0.001798,0.003391,0.086142,289.029419,14.723860,0.861415,-90.118408,294.500488,0.000000
80.110001,66.324379,-90.118408,-0.001785,0.003402,0.086410,295.025574,15.029319,0.864104,-90.118408,294.500488,0.000000
80.450005,66.145256,-90.118408,-0.001781,0.003401,0.086393,294.228790,14.988729,0.863930,-90.118408,294.500488,0.000000
80.790001,66.003395,-90.296333,-0.001776,0.003401,0.086393,293.597778,14.956583,0.863930,-90.296333,294.500488,0.000000
81.130005,65.864861,-90.296333,-0.001768,0.003401,0.086393,292.981537,14.925191,0.863930,-90.296333,294.500488,0.000000
81.470001,65.765816,-90.340813,-0.001781,0.003401,0.086393,292.540955,14.902747,0.863930,-90.340813,294.500488,0.000000
81.810005,65.589317,-90.340813,-0.001781,0.003401,0.086393,291.755859,14.862752,0.863930,-90.340813,294.500488,0.000000
82.150002,65.499565,-90.296333,-0.001781,0.003401,0.086393,291.356628,14.842414,0.863930,-90.296333,294.500488,0.000000
82.490005,65.332741,-90.474251,-0.001776,0.003401,0.086393,290.614532,14.804610,0.863930,-90.474251,294.500488,0.000000
82.830002,65.244499,-90.385292,-0.001781,0.003402,0.086402,290.222015,14.784615,0.864017,-90.385292,294.500488,0.000000
83.170006,65.096657,-90.518738,-0.001794,0.003402,0.086402,289.564392,14.751113,0.864017,-90.518738,294.500488,0.000000
83.510002,64.990913,-90.518738,-0.001772,0.003402,0.086402,289.094025,14.727151,0.864017,-90.518738,294.500488,0.000000
83.850006,64.872124,-90.563217,-0.001772,0.003402,0.086402,288.565613,14.700233,0.864017,-90.563217,294.500488,0.000000
84.190002,64.741783,-90.696663,-0.001781,0.003402,0.086402,287.985840,14.670697,0.864017,-90.696663,294.500488,0.000000
84.530006,64.670662,-90.696663,-0.001776,0.003402,0.086410,287.669464,14.654581,0.864104,-90.696663,294.500488,0.000000
84.870003,66.789101,-90.696663,-0.001772,0.003422,0.086922,297.092743,15.134626,0.869220,-90.696663,294.500488,0.000000
85.210007,66.374641,-90.741142,-0.001763,0.003387,0.086037,295.249146,15.040709,0.860375,-90.741142,294.500488,0.000000
85.550003,66.243935,-90.785622,-0.001768,0.003387,0.086037,294.667725,15.011090,0.860375,-90.785622,294.500488,0.000000
85.890007,66.097603,-90.874580,-0.001763,0.003387,0.086037,294.016815,14.977931,0.860375,-90.874580,294.500488,0.000000
86.230003,65.982170,-90.874580,-0.001755,0.003387,0.086037,293.503357,14.951773,0.860375,-90.874580,294.500488,0.000000
86.570007,65.833214,-90.919067,-0.001763,0.003388,0.086046,292.840759,14.918019,0.860461,-90.919067,294.500488,0.000000
86.910004,65.813850,-91.008026,-0.001759,0.003388,0.086063,292.754639,14.913632,0.860635,-91.008026,294.500488,0.000000
87.250008,65.652245,-90.963547,-0.001755,0.003389,0.086081,292.035767,14.877011,0.860808,-90.963547,294.500488,0.000000
87.590004,65.589684,-91.052505,-0.001763,0.003402,0.086419,291.757477,14.862835,0.864190,-91.052505,294.500488,0.000000
87.930008,65.537926,-91.096985,-0.001759,0.003406,0.086523,291.527252,14.851107,0.865231,-91.096985,294.500488,0.000000
88.270004,65.455635,-91.185951,-0.001763,0.003411,0.086645,291.161194,14.832459,0.866445,-91.185951,294.500488,0.000000
88.610001,65.394554,-91.141472,-0.001750,0.003416,0.086766,290.889496,14.818618,0.867659,-91.141472,294.500488,0.000000
88.950005,65.307426,-91.141472,-0.001759,0.003418,0.086827,290.501953,14.798875,0.868266,-91.141472,294.500488,0.000000
89.290001,65.249336,-91.185951,-0.001746,0.003420,0.086879,290.243530,14.785711,0.868787,-91.185951,294.500488,0.000000
89.630005,65.140236,-91.274910,-0.001750,0.003421,0.086896,289.758240,14.760988,0.868960,-91.274910,294.500488,0.000000
89.970001,65.057930,-91.319389,-0.001750,0.003423,0.086957,289.392120,14.742338,0.869567,-91.319389,294.500488,0.000000
90.310005,65.037453,-91.363876,-0.001750,0.003424,0.086974,289.301025,14.737697,0.869741,-91.363876,294.500488,0.000000
90.650002,64.978996,-91.319389,-0.001794,0.003424,0.086974,289.041016,14.724450,0.869741,-91.319389,294.500488,0.000000
90.990005,65.795982,-91.408356,-0.001750,0.003435,0.087260,292.675140,14.909583,0.872603,-91.408356,294.500488,0.000000
91.330002,65.676079,-91.452835,-0.001755,0.003435,0.087260,292.141785,14.882412,0.872603,-91.452835,294.500488,0.000000
91.670006,65.599739,-91.541794,-0.001763,0.003435,0.087260,291.802216,14.865113,0.872603,-91.541794,294.500488,0.000000
92.010002,65.557289,-91.586281,-0.001755,0.003435,0.087260,291.613373,14.855494,0.872603,-91.586281,294.500488,0.000000
92.350006,65.503670,-91.586281,-0.001755,0.003435,0.087260,291.374878,14.843344,0.872603,-91.586281,294.500488,0.000000
92.690002,65.408333,-91.675240,-0.001759,0.003435,0.087260,290.950806,14.821740,0.872603,-91.675240,294.500488,0.000000
93.030006,65.330879,-91.630760,-0.001742,0.003435,0.087260,290.606262,14.804189,0.872603,-91.630760,294.500488,0.000000
93.370003,65.272789,-91.719719,-0.001750,0.003435,0.087260,290.347870,14.791025,0.872603,-91.719719,294.500488,0.000000
93.710007,65.225502,-91.764198,-0.001738,0.003435,0.087260,290.137512,14.780310,0.872603,-91.764198,294.500488,0.000000
94.050003,65.107460,-91.808685,-0.001750,0.003435,0.087260,289.612457,14.753561,0.872603,-91.808685,294.500488,0.000000
94.390007,65.036339,-91.897644,-0.001755,0.003436,0.087286,289.296082,14.737446,0.872863,-91.897644,294.500488,0.000000
94.730003,65.193474,-91.853165,-0.001746,0.003439,0.087356,289.995056,14.773052,0.873556,-91.853165,294.500488,0.000000
95.070007,65.129433,-91.986610,-0.001755,0.003439,0.087356,289.710175,14.758540,0.873556,-91.986610,294.500488,0.000000
95.410004,65.076546,-91.986610,-0.001738,0.003439,0.087356,289.474945,14.746555,0.873556,-91.986610,294.500488,0.000000
95.750008,65.021812,-91.986610,-0.001742,0.003439,0.087356,289.231476,14.734154,0.873556,-91.986610,294.500488,0.000000
96.090004,65.162193,-92.075569,-0.001750,0.003442,0.087434,289.855927,14.765965,0.874337,-92.075569,294.500488,0.000000
96.430008,65.123100,-92.075569,-0.001746,0.003442,0.087434,289.682007,14.757106,0.874337,-92.075569,294.500488,0.000000
96.770004,65.059059,-92.120049,-0.001742,0.003442,0.087434,289.397156,14.742594,0.874337,-92.120049,294.500488,0.000000
97.110008,65.164436,-92.164528,-0.001750,0.003446,0.087529,289.865875,14.766473,0.875291,-92.164528,294.500488,0.000000
97.450005,65.237785,-92.209015,-0.001755,0.003446,0.087529,290.192169,14.783093,0.875291,-92.209015,294.500488,0.000000
97.790001,65.216194,-92.253494,-0.001742,0.003446,0.087529,290.096130,14.778201,0.875291,-92.253494,294.500488,0.000000
98.130005,65.165184,-92.297974,-0.001738,0.003446,0.087529,289.869202,14.766642,0.875291,-92.297974,294.500488,0.000000
98.470001,65.103371,-92.386932,-0.001746,0.003446,0.087529,289.594269,14.752634,0.875291,-92.386932,294.500488,0.000000
98.810005,65.051979,-92.342453,-0.001750,0.003446,0.087529,289.365662,14.740989,0.875291,-92.342453,294.500488,0.000000
99.150002,65.003197,-92.520378,-0.001742,0.003447,0.087555,289.148651,14.729935,0.875551,-92.520378,294.500488,0.000000
99.490005,64.996117,-92.564857,-0.001738,0.003447,0.087555,289.117157,14.728331,0.875551,-92.564857,294.500488,0.000000
99.830002,64.958504,-92.475899,-0.001738,0.003447,0.087555,288.949860,14.719808,0.875551,-92.475899,294.500488,0.000000
100.170006,64.894463,-92.520378,-0.001746,0.003447,0.087555,288.664978,14.705296,0.875551,-92.520378,294.500488,0.000000
100.510002,64.859093,-92.609337,-0.001746,0.003453,0.087694,288.507660,14.697281,0.876939,-92.609337,294.500488,0.000000
100.850006,65.473137,-92.653824,-0.001725,0.003455,0.087763,291.239044,14.836425,0.877632,-92.653824,294.500488,0.000000
101.190002,65.445946,-92.698303,-0.001746,0.003455,0.087755,291.118103,14.830263,0.877546,-92.698303,294.500488,0.000000
101.530006,65.397911,-92.698303,-0.001742,0.003455,0.087755,290.904449,14.819378,0.877546,-92.698303,294.500488,0.000000
101.870003,65.342796,-92.831741,-0.001729,0.003455,0.087755,290.659271,14.806889,0.877546,-92.831741,294.500488,0.000000
102.210007,65.301460,-92.787262,-0.001729,0.003455,0.087755,290.475403,14.797522,0.877546,-92.787262,294.500488,0.000000
102.550003,65.259758,-92.787262,-0.001750,0.003455,0.087763,290.289886,14.788073,0.877632,-92.787262,294.500488,0.000000
102.890007,65.224754,-92.876228,-0.001725,0.003455,0.087763,290.134186,14.780140,0.877632,-92.876228,294.500488,0.000000
103.230003,65.172630,-92.965187,-0.001725,0.003455,0.087763,289.902344,14.768330,0.877632,-92.965187,294.500488,0.000000
103.570007,65.105232,-93.009666,-0.001733,0.003455,0.087763,289.602539,14.753057,0.877632,-93.009666,294.500488,0.000000
103.910004,65.047874,-93.009666,-0.001725,0.003456,0.087772,289.347382,14.740059,0.877719,-93.009666,294.500488,0.000000
104.250008,65.017723,-92.965187,-0.001746,0.003456,0.087781,289.213287,14.733227,0.877806,-92.965187,294.500488,0.000000
104.590004,65.187889,-93.098633,-0.001729,0.003459,0.087859,289.970215,14.771787,0.878586,-93.098633,294.500488,0.000000
104.930008,65.175972,-93.143112,-0.001729,0.003459,0.087859,289.917206,14.769087,0.878586,-93.143112,294.500488,0.000000
105.270004,65.134270,-93.143112,-0.001725,0.003460,0.087876,289.731689,14.759637,0.878760,-93.143112,294.500488,0.000000
105.610008,65.208000,-93.232071,-0.001720,0.003461,0.087902,290.059662,14.776343,0.879020,-93.232071,294.500488,0.000000
105.950005,65.175972,-93.276558,-0.001733,0.003461,0.087902,289.917206,14.769087,0.879020,-93.276558,294.500488,0.000000
106.290009,65.133904,-93.365517,-0.001716,0.003461,0.087902,289.730072,14.759553,0.879020,-93.365517,294.500488,0.000000
106.630005,65.257530,-93.276558,-0.001729,0.003463,0.087954,290.279999,14.787567,0.879540,-93.276558,294.500488,0.000000
106.970009,65.252678,-93.409996,-0.001733,0.003463,0.087954,290.258423,14.786469,0.879540,-93.409996,294.500488,0.000000
107.310005,65.224007,-93.409996,-0.001716,0.003463,0.087954,290.130859,14.779972,0.879540,-93.409996,294.500488,0.000000
107.650002,65.182686,-93.454475,-0.001729,0.003463,0.087963,289.947083,14.770608,0.879627,-93.454475,294.500488,0.000000
107.990005,65.142830,-93.543442,-0.001725,0.003463,0.087963,289.769775,14.761576,0.879627,-93.543442,294.500488,0.000000
108.330002,65.089592,-93.543442,-0.001720,0.003463,0.087963,289.532959,14.749513,0.879627,-93.543442,294.500488,0.000000
108.670006,65.404610,-93.632401,-0.001716,0.003468,0.088084,290.934235,14.820896,0.880841,-93.632401,294.500488,0.000000
109.010002,65.408714,-93.632401,-0.001725,0.003468,0.088084,290.952484,14.821827,0.880841,-93.632401,294.500488,0.000000
109.350006,65.373711,-93.721367,-0.001733,0.003468,0.088084,290.796783,14.813894,0.880841,-93.721367,294.500488,0.000000
109.690002,65.308174,-93.765846,-0.001707,0.003468,0.088075,290.505280,14.799045,0.880754,-93.765846,294.500488,0.000000
110.030006,65.290672,-93.721367,-0.001703,0.003468,0.088075,290.427429,14.795078,0.880754,-93.721367,294.500488,0.000000
110.370003,65.233696,-93.854805,-0.001716,0.003468,0.088075,290.173981,14.782166,0.880754,-93.854805,294.500488,0.000000
110.710007,65.127571,-93.810326,-0.001703,0.003460,0.087876,289.701904,14.758119,0.878760,-93.810326,0.088058,0.000000
111.050003,64.961861,-93.943771,-0.001707,0.003453,0.087711,288.964783,14.720568,0.877112,-93.943771,0.087494,0.000000
111.390007,64.917549,-93.988251,-0.001720,0.003439,0.087338,288.767670,14.710527,0.873383,-93.988251,0.086931,0.000000
111.730003,64.766747,-93.988251,-0.001703,0.003419,0.086835,288.096863,14.676355,0.868353,-93.988251,0.086358,0.000000
112.070007,64.740669,-94.077209,-0.001707,0.003394,0.086211,287.980865,14.670445,0.862109,-94.077209,0.085795,0.000000
112.410004,64.720940,-94.032730,-0.001712,0.003372,0.085647,287.893127,14.665975,0.856472,-94.032730,0.085222,0.000000
112.750008,64.579063,-94.166176,-0.001707,0.003352,0.085144,287.262024,14.633824,0.851442,-94.166176,0.084659,0.000000
113.090004,64.564537,-94.121689,-0.001707,0.003336,0.084745,287.197418,14.630533,0.847453,-94.121689,0.084095,0.000000
113.430008,64.424522,-94.210655,-0.001703,0.003311,0.084095,286.574585,14.598805,0.840949,-94.210655,0.083523,0.000000
113.770004,64.369041,-94.299614,-0.001720,0.003289,0.083549,286.327789,14.586234,0.835485,-94.299614,0.082959,0.000000
114.110008,64.346336,-94.255135,-0.001694,0.003270,0.083046,286.226807,14.581088,0.830455,-94.255135,0.082395,0.000000
114.450005,63.922203,-94.344101,-0.001703,0.003241,0.082326,284.340149,14.484979,0.823257,-94.344101,0.081823,0.000000
114.790009,63.412041,-94.344101,-0.001703,0.003222,0.081840,282.070831,14.369374,0.818401,-94.344101,0.081259,0.000000
115.130005,62.891472,-94.388580,-0.001699,0.003211,0.081563,279.755249,14.251410,0.815626,-94.388580,0.080695,0.000000
115.470009,61.476830,-94.477539,-0.001694,0.003181,0.080791,273.462585,13.930848,0.807907,-94.477539,0.080123,0.000000
115.810005,60.430832,-94.433060,-0.001694,0.003163,0.080331,268.809753,13.693822,0.803311,-94.433060,0.079559,0.000000
116.150009,59.261955,-94.566505,-0.001690,0.003145,0.079889,263.610352,13.428951,0.798888,-94.566505,0.078996,0.000000
116.490005,57.590378,-94.522018,-0.001694,0.003120,0.079256,256.174805,13.050166,0.792558,-94.522018,0.078423,0.000000
116.830002,55.971672,-94.522018,-0.001681,0.003100,0.078735,248.974426,12.683362,0.787354,-94.522018,0.077860,0.000000
117.170006,54.055817,-94.699944,-0.001690,0.003077,0.078163,240.452286,12.249224,0.781631,-94.699944,0.077296,0.000000
117.510002,52.216667,-94.699944,-0.001703,0.003055,0.077608,232.271332,11.832466,0.776080,-94.699944,0.076723,0.000000
117.850006,50.140320,-94.699944,-0.001699,0.003036,0.077114,223.035278,11.361959,0.771137,-94.699944,0.076160,0.000000
118.190002,47.871452,-94.788910,-0.001686,0.003011,0.076481,212.942856,10.847826,0.764806,-94.788910,0.075596,0.000000
118.530006,45.325172,-94.788910,-0.001681,0.002989,0.075908,201.616440,10.270831,0.759083,-94.788910,0.075024,0.000000
118.870003,43.358299,-94.922348,-0.001712,0.002970,0.075440,192.867340,9.825131,0.754400,-94.922348,0.074460,0.000000
119.210007,40.881279,-94.877869,-0.001707,0.002944,0.074790,181.849014,9.263830,0.747895,-94.877869,0.073896,0.000000
119.550003,38.415054,-94.922348,-0.001707,0.002922,0.074226,170.878693,8.704976,0.742258,-94.922348,0.073324,0.000000
119.890007,35.921280,-95.011314,-0.001703,0.002899,0.073627,159.785828,8.139878,0.736275,-95.011314,0.072760,0.000000
120.230003,34.018829,-95.011314,-0.001720,0.002882,0.073194,151.323303,7.708777,0.731939,-95.011314,0.072188,0.000000
120.570007,31.891464,-95.144753,-0.001720,0.002861,0.072665,141.860321,7.226709,0.726648,-95.144753,0.071624,0.000000
120.910004,29.260651,-95.100273,-0.001725,0.002835,0.072006,130.157867,6.630558,0.720058,-95.100273,0.071060,0.000000
121.250008,26.986946,-95.233719,-0.001738,0.002813,0.071459,120.043930,6.115329,0.714594,-95.233719,0.070488,0.000000
121.590004,24.622009,-95.189232,-0.001742,0.002792,0.070904,109.524170,5.579427,0.709044,-95.189232,0.069924,0.000000
121.930008,22.691261,-95.189232,-0.001725,0.002772,0.070419,100.935768,5.141913,0.704187,-95.189232,0.069361,0.000000
122.270004,19.758453,-95.278198,-0.001738,0.002745,0.069725,87.889992,4.477330,0.697250,-95.278198,0.068788,0.000000
122.610008,17.268394,-95.322678,-0.001742,0.002723,0.069153,76.813652,3.913074,0.691526,-95.322678,0.068225,0.000000
122.950005,15.770340,-95.367157,-0.001768,0.002708,0.068788,70.149979,3.573610,0.687883,-95.367157,0.067661,0.000000
123.290009,14.459221,-95.411636,-0.001755,0.002696,0.068485,64.317825,3.276506,0.684848,-95.411636,0.067089,0.000000
123.630005,11.385284,-95.367157,-0.001763,0.002662,0.067609,50.644276,2.579942,0.676089,-95.367157,0.066525,0.000000
123.970009,9.444107,-95.500603,-0.001768,0.002647,0.067227,42.009487,2.140065,0.672273,-95.500603,0.065961,0.000000
124.310005,5.840286,-95.500603,-0.001776,0.002608,0.066239,25.978891,1.323428,0.662387,-95.500603,0.065389,0.000000
124.650009,4.216743,-95.634048,-0.001794,0.002592,0.065831,18.757011,0.955528,0.658311,-95.634048,0.064825,0.000000
124.990005,2.964081,-95.589561,-0.001789,0.002578,0.065484,13.184890,0.671670,0.654842,-95.589561,0.064261,0.000000
125.330009,0.865387,-95.634048,-0.001798,0.002557,0.064955,3.849433,0.196099,0.649552,-95.634048,0.063689,0.000000
125.670006,-2.081566,-95.723007,-0.001807,0.002525,0.064140,-9.259268,-0.471690,0.641400,-95.723007,0.063125,0.000000
126.010010,-3.832462,-95.723007,-0.001819,0.002503,0.063568,-17.047644,-0.868448,0.635677,-95.723007,0.062562,0.000000
126.350006,-0.445358,-95.767487,-0.001888,0.002480,0.062987,-1.981053,-0.100920,0.629866,-95.767487,0.061989,0.000000
126.690002,-0.048409,-95.811966,-0.001901,0.002463,0.062553,-0.215332,-0.010970,0.625530,-95.811966,0.061426,0.000000
127.030006,-0.065170,-95.856453,-0.001927,0.002433,0.061807,-0.289892,-0.014768,0.618072,-95.856453,0.060862,0.000000
127.370003,-0.074478,-95.900932,-0.001970,0.002410,0.061209,-0.331295,-0.016877,0.612088,-95.900932,0.060290,0.000000
127.710007,-0.040588,-95.900932,-0.001983,0.002401,0.060975,-0.180546,-0.009197,0.609746,-95.900932,0.059726,0.000000
128.050003,-0.074852,-95.989891,-0.002005,0.002369,0.060177,-0.332958,-0.016962,0.601768,-95.989891,0.059162,0.000000
128.389999,-0.047668,-95.989891,-0.002039,0.002345,0.059561,-0.212040,-0.010802,0.595611,-95.989891,0.058590,0.000000
128.730011,-0.054367,-96.078857,-0.002074,0.002320,0.058937,-0.241837,-0.012320,0.589367,-96.078857,0.058026,0.000000
129.070007,-0.055862,-96.123337,-0.002074,0.002315,0.058807,-0.248488,-0.012659,0.588066,-96.123337,0.057454,0.000000
129.410004,-0.061073,-96.167816,-0.002139,0.002279,0.057879,-0.271668,-0.013839,0.578786,-96.167816,0.056890,0.000000
129.750000,-0.054741,-96.212296,-0.002173,0.002257,0.057332,-0.243500,-0.012404,0.573323,-96.212296,0.056326,0.000000
130.090012,-0.046547,-96.212296,-0.002195,0.002230,0.056630,-0.207051,-0.010548,0.566298,-96.212296,0.055754,0.000000
130.430008,-0.047295,-96.301262,-0.002225,0.002209,0.056101,-0.210377,-0.010717,0.561008,-96.301262,0.055190,0.000000
130.770004,-0.040222,-96.256775,-0.002259,0.002185,0.055502,-0.178917,-0.009114,0.555024,-96.256775,0.054627,0.000000
131.110001,-0.047295,-96.345741,-0.002281,0.002168,0.055069,-0.210377,-0.010717,0.550688,-96.345741,0.054054,0.000000
131.450012,-0.061073,-96.345741,-0.002302,0.002147,0.054540,-0.271668,-0.013839,0.545398,-96.345741,0.053490,0.000000
131.790009,-0.039474,-96.345741,-0.002324,0.002121,0.053881,-0.175591,-0.008945,0.538807,-96.345741,0.052927,0.000000
132.130005,-0.024956,-96.479179,-0.002376,0.002096,0.053239,-0.111009,-0.005655,0.532390,-96.479179,0.052354,0.000000
132.470001,-0.030540,-96.479179,-0.002380,0.002076,0.052736,-0.135851,-0.006921,0.527360,-96.479179,0.051791,0.000000
132.810013,-0.031281,-96.479179,-0.002427,0.002056,0.052224,-0.139143,-0.007088,0.522243,-96.479179,0.051227,0.000000
133.150009,-0.034264,-96.612625,-0.002445,0.002033,0.051626,-0.152412,-0.007764,0.516259,-96.612625,0.050655,0.000000
133.490005,-0.030907,-96.568146,-0.002458,0.002017,0.051236,-0.137480,-0.007004,0.512357,-96.568146,0.050091,0.000000
133.830002,0.002602,-96.701584,-0.002488,0.001984,0.050403,0.011573,0.000590,0.504032,-96.701584,0.049527,0.000000
134.170013,-0.012665,-96.746071,-0.002505,0.001963,0.049848,-0.056336,-0.002870,0.498481,-96.746071,0.048955,0.000000
134.510010,-0.008194,-96.657104,-0.002535,0.001940,0.049267,-0.036449,-0.001857,0.492671,-96.657104,0.048391,0.000000
134.850006,-0.031654,-96.835030,-0.002557,0.001922,0.048807,-0.140806,-0.007173,0.488075,-96.835030,0.047827,0.000000
135.190002,-0.032768,-96.746071,-0.002561,0.001899,0.048244,-0.145760,-0.007425,0.482438,-96.746071,0.047255,0.000000
135.530014,-0.047668,-96.923996,-0.002596,0.001877,0.047671,-0.212040,-0.010802,0.476714,-96.923996,0.046691,0.000000
135.870010,-0.037239,-96.879509,-0.002634,0.001847,0.046926,-0.165648,-0.008438,0.469256,-96.879509,0.046128,0.000000
136.210007,-0.001495,-96.968475,-0.002656,0.001828,0.046440,-0.006652,-0.000339,0.464399,-96.968475,0.045555,0.000000
136.550003,-0.011917,-97.012955,-0.002665,0.001814,0.046067,-0.053010,-0.002700,0.460670,-97.012955,0.044992,0.000000
136.889999,-0.023460,-97.012955,-0.002690,0.001784,0.045304,-0.104357,-0.005316,0.453039,-97.012955,0.044419,0.000000
137.230011,-0.013405,-97.101913,-0.002725,0.001764,0.044810,-0.059628,-0.003038,0.448096,-97.101913,0.043856,0.000000
137.570007,-0.026817,-97.101913,-0.002725,0.001741,0.044229,-0.119289,-0.006077,0.442285,-97.101913,0.043292,0.000000
137.910004,-0.005219,-97.146400,-0.002768,0.001716,0.043578,-0.023213,-0.001183,0.435781,-97.146400,0.042720,0.000000
138.250000,0.019730,-97.235359,-0.002785,0.001697,0.043092,0.087762,0.004471,0.430924,-97.235359,0.042156,0.000000
138.590012,0.035370,-97.235359,-0.002811,0.001674,0.042520,0.157333,0.008015,0.425201,-97.235359,0.041592,0.000000
138.930008,0.026062,-97.324318,-0.002824,0.001651,0.041930,0.115930,0.005906,0.419304,-97.324318,0.041020,0.000000
139.270004,0.008934,-97.324318,-0.002833,0.001631,0.041427,0.039741,0.002024,0.414274,-97.324318,0.040456,0.000000
139.610001,0.004837,-97.413284,-0.002876,0.001606,0.040786,0.021516,0.001096,0.407856,-97.413284,0.039892,0.000000
139.950012,-0.018623,-97.457764,-0.002910,0.001582,0.040187,-0.082841,-0.004220,0.401872,-97.457764,0.039320,0.000000
140.290009,0.039093,-97.413284,-0.002949,0.001560,0.039632,0.173894,0.008859,0.396322,-97.413284,0.038756,0.000000
140.630005,0.032021,-97.502243,-0.002953,0.001543,0.039181,0.142435,0.007256,0.391813,-97.502243,0.038193,0.000000
140.970001,0.033882,-97.502243,-0.002966,0.001514,0.038453,0.150715,0.007678,0.384528,-97.502243,0.037620,0.000000
141.310013,0.019363,-97.546722,-0.002988,0.001495,0.037984,0.086133,0.004388,0.379845,-97.546722,0.037057,0.000000
141.650009,-0.009682,-97.546722,-0.003022,0.001473,0.037412,-0.043066,-0.002194,0.374121,-97.546722,0.036493,0.000000
141.990005,-0.007820,-97.635689,-0.003035,0.001450,0.036840,-0.034786,-0.001772,0.368398,-97.635689,0.035920,0.000000
142.330002,-0.011177,-97.724648,-0.003070,0.001432,0.036380,-0.049718,-0.002533,0.363801,-97.724648,0.036276,0.000000
142.400009,-0.004471,-97.724648,-0.003048,0.001432,0.036380,-0.019887,-0.001013,0.363801,-97.724648,0.036276,0.000000