File: Data/compression 15/AutoNoHeating-17-15-reverse-shortpurge-1_08262024_191951.csv
Time (sec),S:Load (lbs),S:HL1 (DIM),S:LVDT (in),S:Position (in),Ch:Position (mm),Ch:Load (N),Ch:Stress (MPa),Ch:Strain (mm/mm),Ch:HL1 (DIM),Set Point (),Cycles ()
0.210000,-0.088631,-147.810196,-0.010141,-0.005028,-0.127708,-0.394249,-0.020084,-1.277077,-147.810196,-0.127924,0.000000
0.570000,-0.022346,-147.854675,-0.010145,-0.004964,-0.126086,-0.099402,-0.005064,-1.260859,-147.854675,-0.125305,0.000000
0.930000,-0.039101,-147.854675,-0.010050,-0.004747,-0.120570,-0.173928,-0.008860,-1.205704,-147.854675,-0.119304,0.000000
1.290000,-0.029045,-147.899155,-0.009835,-0.004504,-0.114413,-0.129199,-0.006582,-1.144131,-147.899155,-0.113303,0.000000
1.650000,-0.033516,-147.899155,-0.009589,-0.004268,-0.108403,-0.149086,-0.007595,-1.084032,-147.899155,-0.107319,0.000000
2.010000,-0.030540,-147.988129,-0.009343,-0.004031,-0.102385,-0.135851,-0.006921,-1.023847,-147.988129,-0.101318,0.000000
2.370000,-0.046921,-148.032608,-0.009093,-0.003801,-0.096557,-0.208714,-0.010632,-0.965569,-148.032608,-0.095317,0.000000
2.730000,0.008560,-148.032608,-0.008856,-0.003565,-0.090547,0.038078,0.001940,-0.905470,-148.032608,-0.089316,0.000000
3.090000,-0.019737,-148.121567,-0.008623,-0.003333,-0.084659,-0.087796,-0.004473,-0.846586,-148.121567,-0.083332,0.000000
3.450000,-0.007820,-148.077087,-0.008364,-0.003089,-0.078458,-0.034786,-0.001772,-0.784579,-148.077087,-0.077331,0.000000
3.810000,-0.040222,-148.210526,-0.008114,-0.002854,-0.072500,-0.178917,-0.009114,-0.725001,-148.210526,-0.071329,0.000000
4.170000,-0.074104,-148.121567,-0.007877,-0.002613,-0.066377,-0.329632,-0.016792,-0.663775,-148.121567,-0.065328,0.000000
4.530000,-0.036865,-148.166046,-0.007623,-0.002378,-0.060411,-0.163985,-0.008354,-0.604109,-148.166046,-0.059327,0.000000
4.890000,-0.014900,-148.299484,-0.007403,-0.002151,-0.054627,-0.066279,-0.003376,-0.546265,-148.299484,-0.053343,0.000000
5.250000,0.013405,-148.299484,-0.007148,-0.001913,-0.048599,0.059628,0.003038,-0.485993,-148.299484,-0.047342,0.000000
5.610000,-0.010429,-148.388458,-0.006907,-0.001675,-0.042546,-0.046392,-0.002363,-0.425461,-148.388458,-0.041341,0.000000
5.970000,-0.033142,-148.343979,-0.006653,-0.001438,-0.036536,-0.147423,-0.007510,-0.365362,-148.343979,-0.035339,0.000000
6.330000,-0.045807,-148.388458,-0.006403,-0.001203,-0.030544,-0.203759,-0.010380,-0.305437,-148.388458,-0.029338,0.000000
6.690001,-0.088257,-148.388458,-0.006165,-0.000961,-0.024404,-0.392586,-0.019999,-0.244037,-148.388458,-0.023354,0.000000
7.050000,-0.008942,-148.477417,-0.005924,-0.000731,-0.018576,-0.039774,-0.002026,-0.185760,-148.477417,-0.017353,0.000000
7.410000,0.016006,-148.521896,-0.005687,-0.000494,-0.012549,0.071200,0.003627,-0.125488,-148.521896,-0.011352,0.000000
7.770000,0.013405,-148.521896,-0.005445,-0.000260,-0.006600,0.059628,0.003038,-0.065996,-148.521896,-0.005351,0.000000
8.130000,-0.005219,-148.566376,-0.005191,-0.000024,-0.000616,-0.023213,-0.001183,-0.006157,-148.566376,0.000650,0.000000
8.490001,-0.007080,-148.610855,-0.004963,0.000211,0.005359,-0.031494,-0.001604,0.053595,-148.610855,0.006634,0.000000
8.850000,0.205917,-148.610855,-0.004700,0.000442,0.011222,0.915966,0.046662,0.112219,-148.610855,0.012393,0.000000
9.210000,0.151176,-148.699814,-0.004695,-0.000000,-0.000000,0.672466,0.034257,-0.000000,-148.699814,0.000243,0.000000
9.570001,0.119156,-148.699814,-0.004700,-0.000000,-0.000000,0.530032,0.027001,-0.000000,-148.699814,0.000529,0.000000
9.930000,0.110962,-148.744293,-0.004687,0.000000,0.000009,0.493583,0.025144,0.000087,-148.744293,0.001136,0.000000
10.290001,0.291565,-148.788788,-0.004704,0.000029,0.000746,1.296946,0.066070,0.007458,-148.788788,0.001734,0.000000
10.650001,0.494133,-148.833267,-0.004687,0.000053,0.001336,2.198013,0.111972,0.013355,-148.833267,0.002333,0.000000
11.010000,0.699310,-148.833267,-0.004652,0.000073,0.001865,3.110687,0.158466,0.018645,-148.833267,0.002931,0.000000
11.370001,0.970772,-148.833267,-0.004631,0.000098,0.002480,4.318209,0.219980,0.024803,-148.833267,0.003530,0.000000
11.730000,1.396767,-148.922226,-0.004600,0.000125,0.003165,6.213129,0.316512,0.031654,-148.922226,0.004137,0.000000
12.090000,1.725197,-148.966705,-0.004596,0.000145,0.003694,7.674059,0.390935,0.036944,-148.966705,0.004735,0.000000
12.450001,2.337753,-148.966705,-0.004562,0.000172,0.004371,10.398846,0.529742,0.043708,-148.966705,0.005333,0.000000
12.810000,2.718315,-149.055664,-0.004549,0.000194,0.004917,12.091670,0.615979,0.049172,-149.055664,0.005932,0.000000
13.170001,2.936157,-149.011185,-0.004531,0.000207,0.005247,13.060679,0.665343,0.052467,-149.011185,0.006530,0.000000
13.530001,3.776596,-149.144623,-0.004506,0.000246,0.006253,16.799139,0.855789,0.062527,-149.144623,0.007137,0.000000
13.890000,4.063698,-149.100143,-0.004480,0.000265,0.006738,18.076231,0.920847,0.067383,-149.100143,0.007736,0.000000
14.250001,4.655769,-149.144623,-0.004454,0.000290,0.007354,20.709896,1.055012,0.073541,-149.144623,0.008334,0.000000
14.610001,5.011383,-149.144623,-0.004437,0.000311,0.007900,22.291744,1.135596,0.079004,-149.144623,0.008932,0.000000
14.970000,5.681656,-149.233597,-0.004441,0.000338,0.008594,25.273268,1.287482,0.085942,-149.233597,0.009531,0.000000
15.330001,6.135208,-149.278076,-0.004415,0.000364,0.009253,27.290770,1.390258,0.092533,-149.278076,0.010129,0.000000
15.690001,6.474068,-149.233597,-0.004389,0.000385,0.009791,28.798092,1.467045,0.097910,-149.233597,0.010736,0.000000
16.050001,6.946602,-149.322556,-0.004359,0.000408,0.010363,30.900028,1.574123,0.103634,-149.322556,0.011335,0.000000
16.410000,7.187531,-149.322556,-0.004346,0.000426,0.010814,31.971733,1.628718,0.108143,-149.322556,0.011933,0.000000
16.770000,7.607567,-149.367035,-0.004324,0.000446,0.011335,33.840149,1.723899,0.113346,-149.367035,0.012531,0.000000
17.130001,8.468491,-149.455994,-0.004303,0.000484,0.012297,37.669727,1.918987,0.122973,-149.455994,0.013130,0.000000
17.490002,8.662872,-149.455994,-0.004286,0.000506,0.012861,38.534382,1.963035,0.128610,-149.455994,0.013737,0.000000
17.850000,9.031517,-149.500473,-0.004247,0.000529,0.013442,40.174194,2.046571,0.134420,-149.500473,0.014335,0.000000
18.210001,9.566620,-149.500473,-0.004238,0.000554,0.014084,42.554451,2.167827,0.140837,-149.500473,0.014934,0.000000
18.570002,9.698067,-149.544952,-0.004217,0.000573,0.014543,43.139156,2.197613,0.145434,-149.544952,0.015532,0.000000
18.930000,10.133743,-149.589432,-0.004204,0.000593,0.015064,45.077141,2.296339,0.150637,-149.589432,0.016130,0.000000
19.290001,10.773476,-149.633926,-0.004186,0.000624,0.015862,47.922813,2.441305,0.158616,-149.633926,0.016737,0.000000
19.650002,10.974930,-149.722885,-0.004156,0.000646,0.016408,48.818928,2.486955,0.164079,-149.722885,0.017336,0.000000
20.010000,11.291817,-149.678406,-0.004139,0.000669,0.016998,50.228508,2.558762,0.169976,-149.678406,0.017934,0.000000
20.370001,11.438164,-149.678406,-0.004117,0.000686,0.017423,50.879494,2.591925,0.174226,-149.678406,0.018533,0.000000
20.730001,11.829895,-149.767365,-0.004096,0.000711,0.018064,52.622002,2.680693,0.180643,-149.767365,0.019131,0.000000
21.090000,12.379517,-149.767365,-0.004087,0.000741,0.018819,55.066841,2.805239,0.188188,-149.767365,0.019738,0.000000
21.450001,12.708694,-149.856323,-0.004083,0.000764,0.019409,56.531097,2.879831,0.194085,-149.856323,0.020336,0.000000
21.810001,13.005478,-149.811844,-0.004040,0.000788,0.020007,57.851254,2.947083,0.200069,-149.811844,0.020935,0.000000
22.170002,13.393860,-149.900803,-0.004018,0.000810,0.020579,59.578865,3.035092,0.205793,-149.900803,0.021533,0.000000
22.530001,13.246773,-149.945282,-0.003997,0.000823,0.020900,58.924587,3.001761,0.209001,-149.945282,0.022132,0.000000
22.890001,13.939758,-149.945282,-0.003988,0.000853,0.021672,62.007141,3.158794,0.216720,-149.945282,0.022730,0.000000
23.250002,14.438736,-150.034241,-0.003949,0.000885,0.022470,64.226707,3.271864,0.224698,-150.034241,0.023337,0.000000
23.610001,14.419746,-150.034241,-0.003936,0.000902,0.022921,64.142235,3.267561,0.229208,-150.034241,0.023935,0.000000
23.970001,14.734032,-150.123215,-0.003902,0.000925,0.023493,65.540245,3.338779,0.234931,-150.123215,0.024534,0.000000
24.330002,15.076241,-150.123215,-0.003902,0.000951,0.024152,67.062469,3.416325,0.241522,-150.123215,0.025132,0.000000
24.690001,15.582298,-150.123215,-0.003863,0.000975,0.024777,69.313522,3.530999,0.247766,-150.123215,0.025731,0.000000
25.050001,16.013878,-150.256653,-0.003867,0.001004,0.025514,71.233284,3.628797,0.255138,-150.256653,0.026338,0.000000
25.410002,15.953926,-150.212173,-0.003820,0.001024,0.026008,70.966606,3.615211,0.260081,-150.212173,0.026936,0.000000
25.770000,15.971428,-150.256653,-0.003807,0.001044,0.026528,71.044456,3.619177,0.265284,-150.256653,0.027534,0.000000
26.130001,15.968071,-150.256653,-0.003798,0.001064,0.027031,71.029526,3.618417,0.270314,-150.256653,0.028133,0.000000
26.490002,16.380661,-150.256653,-0.003786,0.001087,0.027604,72.864822,3.711911,0.276038,-150.256653,0.028731,0.000000
26.850000,17.218124,-150.345612,-0.003760,0.001121,0.028462,76.590042,3.901683,0.284624,-150.345612,0.029338,0.000000
27.210001,17.205093,-150.345612,-0.003738,0.001143,0.029043,76.532074,3.898730,0.290434,-150.345612,0.029937,0.000000
27.570002,17.054283,-150.390091,-0.003738,0.001160,0.029468,75.861237,3.864556,0.294683,-150.390091,0.030535,0.000000
27.930002,17.265793,-150.479065,-0.003704,0.001181,0.029997,76.802086,3.912485,0.299973,-150.479065,0.031133,0.000000
28.290001,17.927498,-150.479065,-0.003669,0.001213,0.030804,79.745491,4.062429,0.308039,-150.479065,0.031732,0.000000
28.650002,18.181458,-150.523544,-0.003660,0.001239,0.031472,80.875160,4.119977,0.314716,-150.523544,0.032339,0.000000
29.010002,18.286461,-150.479065,-0.003643,0.001263,0.032070,81.342239,4.143771,0.320700,-150.479065,0.032937,0.000000
29.370001,18.045914,-150.612503,-0.003635,0.001280,0.032504,80.272232,4.089262,0.325036,-150.612503,0.033536,0.000000
29.730001,18.094688,-150.568024,-0.003622,0.001296,0.032911,80.489197,4.100315,0.329112,-150.568024,0.034134,0.000000
30.090002,18.925079,-150.656982,-0.003600,0.001330,0.033787,84.182961,4.288484,0.337871,-150.656982,0.034732,0.000000
30.450001,18.842789,-150.701462,-0.003579,0.001346,0.034186,83.816910,4.269837,0.341860,-150.701462,0.035339,0.000000
30.810001,19.627747,-150.612503,-0.003553,0.001381,0.035071,87.308578,4.447711,0.350706,-150.612503,0.035938,0.000000
31.170002,19.457573,-150.745941,-0.003544,0.001402,0.035617,86.551605,4.409149,0.356170,-150.745941,0.036536,0.000000
31.530001,19.396881,-150.745941,-0.003535,0.001422,0.036129,86.281639,4.395396,0.361286,-150.745941,0.037135,0.000000
31.890001,19.652328,-150.834900,-0.003523,0.001445,0.036701,87.417923,4.453281,0.367010,-150.834900,0.037733,0.000000
32.250000,19.712280,-150.879379,-0.003497,0.001464,0.037187,87.684601,4.466867,0.371866,-150.879379,0.038331,0.000000
32.610001,19.748398,-150.879379,-0.003475,0.001487,0.037759,87.845261,4.475051,0.377590,-150.879379,0.038938,0.000000
32.970001,20.580276,-150.968353,-0.003466,0.001519,0.038574,91.545639,4.663558,0.385742,-150.968353,0.039537,0.000000
33.330002,20.290199,-150.879379,-0.003432,0.001537,0.039043,90.255318,4.597825,0.390425,-150.879379,0.040135,0.000000
33.690002,20.650284,-150.968353,-0.003415,0.001561,0.039658,91.857048,4.679421,0.396582,-150.968353,0.040734,0.000000
34.050003,21.014839,-151.057312,-0.003402,0.001588,0.040335,93.478676,4.762031,0.403347,-151.057312,0.041332,0.000000
34.410000,20.782104,-151.012833,-0.003385,0.001605,0.040768,92.443420,4.709292,0.407683,-151.012833,0.041939,0.000000
34.770000,21.694420,-151.146271,-0.003380,0.001638,0.041609,96.501602,4.916026,0.416095,-151.146271,0.042537,0.000000
35.130001,21.649734,-151.012833,-0.003359,0.001661,0.042191,96.302826,4.905900,0.421905,-151.012833,0.043136,0.000000
35.490002,21.767029,-151.101791,-0.003328,0.001684,0.042780,96.824577,4.932479,0.427802,-151.101791,0.043734,0.000000
35.850002,21.875015,-151.279709,-0.003337,0.001705,0.043318,97.304924,4.956950,0.433179,-151.279709,0.044333,0.000000
36.210003,21.949867,-151.190750,-0.003303,0.001728,0.043882,97.637886,4.973911,0.438816,-151.190750,0.044940,0.000000
36.570004,22.473419,-151.279709,-0.003294,0.001758,0.044645,99.966759,5.092550,0.446448,-151.279709,0.045538,0.000000
36.930000,22.589226,-151.279709,-0.003277,0.001782,0.045252,100.481895,5.118792,0.452518,-151.279709,0.046136,0.000000
37.290001,22.565025,-151.324188,-0.003255,0.001804,0.045816,100.374245,5.113308,0.458155,-151.324188,0.046735,0.000000
37.650002,22.420540,-151.413162,-0.003242,0.001820,0.046240,99.731544,5.080567,0.462405,-151.413162,0.047333,0.000000
38.010002,22.825310,-151.368683,-0.003221,0.001846,0.046882,101.532051,5.172289,0.468822,-151.368683,0.047940,0.000000
38.370003,23.358551,-151.457642,-0.003212,0.001876,0.047654,103.904022,5.293124,0.476541,-151.457642,0.048539,0.000000
38.730003,23.762947,-151.413162,-0.003186,0.001900,0.048270,105.702866,5.384761,0.482698,-151.413162,0.049137,0.000000
39.090000,23.482178,-151.546600,-0.003191,0.001920,0.048773,104.453941,5.321137,0.487728,-151.546600,0.049735,0.000000
39.450001,23.722733,-151.546600,-0.003169,0.001945,0.049415,105.523987,5.375648,0.494145,-151.546600,0.050334,0.000000
39.810001,23.905190,-151.591080,-0.003152,0.001967,0.049970,106.335594,5.416994,0.499695,-151.591080,0.050932,0.000000
40.170002,24.091377,-151.635559,-0.003130,0.001989,0.050525,107.163795,5.459184,0.505246,-151.635559,0.051539,0.000000
40.530003,24.175903,-151.591080,-0.003104,0.002010,0.051054,107.539787,5.478338,0.510536,-151.591080,0.052138,0.000000
40.890003,24.786972,-151.680038,-0.003091,0.002040,0.051825,110.257957,5.616808,0.518254,-151.680038,0.052736,0.000000
41.250004,24.954163,-151.724518,-0.003078,0.002064,0.052432,111.001656,5.654694,0.524325,-151.724518,0.053334,0.000000
41.610001,24.605621,-151.680038,-0.003061,0.002084,0.052927,109.451271,5.575714,0.529268,-151.680038,0.053933,0.000000
41.970001,24.761276,-151.857971,-0.003065,0.002104,0.053430,110.143661,5.610985,0.534298,-151.857971,0.054540,0.000000
42.330002,25.417023,-151.813492,-0.003035,0.002133,0.054184,113.060562,5.759580,0.541843,-151.813492,0.055138,0.000000
42.690002,25.670609,-151.857971,-0.003031,0.002157,0.054791,114.188568,5.817043,0.547913,-151.857971,0.055737,0.000000
43.050003,25.701515,-151.813492,-0.003009,0.002180,0.055381,114.326050,5.824047,0.553810,-151.813492,0.056335,0.000000
43.410004,26.138680,-151.902451,-0.002997,0.002206,0.056040,116.270653,5.923110,0.560401,-151.902451,0.056933,0.000000
43.770000,25.749550,-152.035889,-0.002979,0.002221,0.056422,114.539719,5.834931,0.564217,-152.035889,0.057540,0.000000
44.130001,26.275345,-151.902451,-0.002958,0.002250,0.057159,116.878571,5.954078,0.571589,-151.902451,0.058139,0.000000
44.490002,26.769112,-152.124847,-0.002945,0.002277,0.057835,119.074959,6.065968,0.578353,-152.124847,0.058737,0.000000
44.850002,26.499138,-152.080368,-0.002945,0.002297,0.058347,117.874054,6.004790,0.583469,-152.080368,0.059336,0.000000
45.210003,26.956039,-152.035889,-0.002928,0.002321,0.058963,119.906448,6.108326,0.589627,-152.035889,0.059934,0.000000
45.570004,26.757195,-152.213821,-0.002910,0.002341,0.059466,119.021942,6.063267,0.594657,-152.213821,0.060541,0.000000
45.930000,27.749565,-152.169327,-0.002893,0.002372,0.060238,123.436234,6.288141,0.602375,-152.169327,0.061139,0.000000
46.290001,28.144653,-152.213821,-0.002880,0.002395,0.060845,125.193672,6.377670,0.608446,-152.213821,0.061738,0.000000
46.650002,28.129013,-152.213821,-0.002867,0.002419,0.061443,125.124100,6.374125,0.614429,-152.213821,0.062336,0.000000
47.010002,27.822548,-152.302780,-0.002854,0.002439,0.061946,123.760872,6.304679,0.619459,-152.302780,0.062935,0.000000
47.370003,27.546997,-152.302780,-0.002837,0.002455,0.062345,122.535164,6.242239,0.623449,-152.302780,0.063533,0.000000
47.730003,28.154709,-152.302780,-0.002828,0.002481,0.063013,125.238403,6.379948,0.630126,-152.302780,0.064140,0.000000
48.090004,29.342575,-152.436218,-0.002824,0.002515,0.063889,130.522293,6.649122,0.638885,-152.436218,0.064738,0.000000
48.450001,29.253578,-152.436218,-0.002811,0.002537,0.064444,130.126419,6.628956,0.644435,-152.436218,0.065337,0.000000
48.810001,28.851418,-152.436218,-0.002785,0.002555,0.064886,128.337509,6.537825,0.648858,-152.436218,0.065935,0.000000
49.170002,29.226021,-152.480698,-0.002772,0.002578,0.065476,130.003830,6.622711,0.654755,-152.480698,0.066534,0.000000
49.530003,29.608452,-152.436218,-0.002755,0.002602,0.066083,131.704971,6.709371,0.660826,-152.436218,0.067141,0.000000
49.890003,30.333458,-152.614136,-0.002742,0.002632,0.066854,134.929962,6.873660,0.668544,-152.614136,0.067739,0.000000
50.250004,30.458572,-152.569656,-0.002712,0.002655,0.067427,135.486496,6.902011,0.674268,-152.569656,0.068337,0.000000
50.610001,30.349472,-152.614136,-0.002712,0.002675,0.067956,135.001190,6.877289,0.679558,-152.614136,0.068936,0.000000
50.970001,30.473839,-152.658630,-0.002703,0.002694,0.068433,135.554398,6.905470,0.684328,-152.658630,0.069534,0.000000
51.330002,30.886055,-152.658630,-0.002690,0.002719,0.069066,137.388031,6.998880,0.690659,-152.658630,0.070141,0.000000
51.690002,31.669899,-152.747589,-0.002677,0.002744,0.069699,140.874741,7.176501,0.696989,-152.747589,0.070740,0.000000
52.050003,32.364746,-152.703110,-0.002656,0.002770,0.070367,143.965576,7.333956,0.703667,-152.703110,0.071338,0.000000
52.410004,32.715897,-152.792068,-0.002643,0.002796,0.071008,145.527573,7.413528,0.710084,-152.792068,0.071936,0.000000
52.770004,32.557640,-152.792068,-0.002626,0.002815,0.071494,144.823624,7.377667,0.714941,-152.792068,0.072535,0.000000
53.130001,33.148964,-152.836548,-0.002596,0.002837,0.072049,147.453949,7.511662,0.720491,-152.836548,0.073142,0.000000
53.490002,33.611450,-152.881027,-0.002600,0.002860,0.072647,149.511200,7.616464,0.726475,-152.881027,0.073740,0.000000
53.850002,33.897064,-152.925507,-0.002583,0.002883,0.073229,150.781677,7.681184,0.732285,-152.925507,0.074339,0.000000
54.210003,35.043228,-152.969986,-0.002570,0.002913,0.073983,155.880066,7.940909,0.739830,-152.969986,0.074937,0.000000
54.570004,35.372032,-153.014465,-0.002552,0.002934,0.074521,157.342651,8.015417,0.745207,-153.014465,0.075535,0.000000
54.930004,34.947151,-153.014465,-0.002522,0.002949,0.074894,155.452698,7.919138,0.748936,-153.014465,0.076134,0.000000
55.290001,36.704002,-153.103439,-0.002522,0.002982,0.075735,163.267563,8.317245,0.757348,-153.103439,0.076741,0.000000
55.650002,36.891678,-153.014465,-0.002518,0.003003,0.076273,164.102386,8.359774,0.762725,-153.014465,0.077339,0.000000
56.010002,38.164825,-153.147919,-0.002501,0.003031,0.076984,169.765625,8.648273,0.769836,-153.147919,0.077938,0.000000
56.370003,39.034309,-153.147919,-0.002462,0.003055,0.077608,173.633286,8.845301,0.776080,-153.147919,0.078536,0.000000
56.730003,38.897652,-153.192398,-0.002466,0.003074,0.078068,173.025391,8.814334,0.780677,-153.192398,0.079134,0.000000
57.090004,39.568298,-153.236877,-0.002458,0.003097,0.078675,176.008575,8.966305,0.786747,-153.236877,0.079741,0.000000
57.450005,40.505554,-153.192398,-0.002445,0.003121,0.079264,180.177704,9.178690,0.792644,-153.192398,0.080340,0.000000
57.810001,41.880356,-153.325836,-0.002436,0.003150,0.080019,186.293121,9.490224,0.800189,-153.325836,0.080938,0.000000
58.170002,42.467216,-153.281357,-0.002402,0.003174,0.080609,188.903610,9.623209,0.806086,-153.281357,0.081537,0.000000
58.530003,42.795273,-153.370316,-0.002380,0.003193,0.081112,190.362885,9.697548,0.811116,-153.370316,0.082135,0.000000
58.890003,43.465172,-153.370316,-0.002380,0.003213,0.081615,193.342743,9.849349,0.816146,-153.370316,0.082742,0.000000
59.250004,44.628464,-153.414795,-0.002376,0.003239,0.082274,198.517319,10.112955,0.822737,-153.414795,0.083340,0.000000
59.610004,46.111626,-153.503769,-0.002371,0.003269,0.083028,205.114761,10.449044,0.830282,-153.503769,0.083939,0.000000
59.970001,47.018723,-153.459274,-0.002354,0.003293,0.083653,209.149719,10.654594,0.836526,-153.459274,0.084537,0.000000
60.330002,47.635002,-153.592728,-0.002324,0.003314,0.084173,211.891068,10.794246,0.841729,-153.592728,0.085136,0.000000
60.690002,48.588272,-153.548248,-0.002324,0.003338,0.084789,216.131424,11.010260,0.847887,-153.548248,0.085743,0.000000
61.050003,49.207527,-153.681686,-0.002298,0.003356,0.085231,218.886017,11.150584,0.852310,-153.681686,0.086341,0.000000
61.410004,50.185379,-153.726166,-0.002294,0.003379,0.085838,223.235718,11.372169,0.858380,-153.726166,0.086939,0.000000
61.770004,51.464478,-153.637207,-0.002272,0.003404,0.086454,228.925430,11.662017,0.864537,-153.637207,0.087538,0.000000
62.130001,53.379593,-153.726166,-0.002259,0.003434,0.087234,237.444290,12.095988,0.872342,-153.726166,0.088136,0.000000
62.490002,54.263229,-153.726166,-0.002246,0.003455,0.087763,241.374893,12.296223,0.877632,-153.726166,0.088735,0.000000
62.850002,54.993454,-153.815125,-0.002238,0.003477,0.088318,244.623108,12.461695,0.883183,-153.815125,0.089342,0.000000
63.210003,56.108704,-153.859604,-0.002238,0.003497,0.088813,249.583984,12.714414,0.888126,-153.859604,0.089940,0.000000
63.570004,57.710281,-153.859604,-0.002220,0.003524,0.089506,256.708160,13.077337,0.895064,-153.859604,0.090538,0.000000
63.930004,59.197906,-153.948578,-0.002203,0.003551,0.090200,263.325439,13.414437,0.902002,-153.948578,0.091137,0.000000
64.290001,60.085274,-153.904083,-0.002195,0.003571,0.090703,267.272644,13.615518,0.907031,-153.904083,0.091735,0.000000
64.650002,62.006340,-153.948578,-0.002164,0.003601,0.091458,275.817963,14.050838,0.914576,-153.948578,0.092342,0.000000
65.010002,62.485954,-153.993057,-0.002186,0.003617,0.091883,277.951416,14.159519,0.918826,-153.993057,0.092941,0.000000
65.370003,63.714043,-153.993057,-0.002147,0.003636,0.092360,283.414215,14.437809,0.923595,-153.993057,0.093539,0.000000
65.730003,65.843269,-154.126495,-0.002156,0.003668,0.093166,292.885498,14.920299,0.931661,-154.126495,0.094137,0.000000
66.090004,65.453392,-154.082016,-0.002139,0.003667,0.093149,291.151215,14.831951,0.931487,-154.082016,0.016354,0.000000
66.450005,65.886833,-154.170975,-0.002147,0.003706,0.094137,293.079285,14.930170,0.941374,-154.170975,294.500488,0.000000
66.810005,66.069298,-154.170975,-0.002108,0.003565,0.090547,293.890900,14.971517,0.905470,-154.170975,294.500488,0.000000
67.170006,65.303703,-154.170975,-0.002095,0.003684,0.093574,290.485382,14.798031,0.935737,-154.170975,294.500488,0.000000
67.530006,65.259392,-154.259933,-0.002100,0.003699,0.093955,290.288269,14.787990,0.939552,-154.259933,294.500488,0.000000
67.890007,65.218803,-154.304413,-0.002104,0.003707,0.094155,290.107727,14.778792,0.941547,-154.304413,294.500488,0.000000
68.250000,65.620216,-154.393387,-0.002108,0.003717,0.094415,291.893311,14.869754,0.944149,-154.393387,294.500488,0.000000
68.610001,65.063148,-154.304413,-0.002108,0.003717,0.094415,289.415344,14.743520,0.944149,-154.304413,294.500488,0.000000
68.970001,64.523949,-154.393387,-0.002087,0.003717,0.094415,287.016846,14.621335,0.944149,-154.393387,294.500488,0.000000
69.330002,66.833778,-154.437866,-0.002070,0.003622,0.091995,297.291504,15.144751,0.919953,-154.437866,294.500488,0.000000
69.690002,66.182869,-154.482346,-0.002057,0.003621,0.091969,294.396118,14.997252,0.919693,-154.482346,294.500488,0.000000
70.050003,65.629524,-154.571304,-0.002070,0.003623,0.092021,291.934692,14.871863,0.920213,-154.571304,294.500488,0.000000
70.410004,65.276146,-154.526825,-0.002065,0.003722,0.094528,290.362793,14.791786,0.945276,-154.526825,294.500488,0.000000
70.770004,65.297005,-154.571304,-0.002052,0.003744,0.095091,290.455597,14.796514,0.950913,-154.571304,294.500488,0.000000
71.130005,65.200188,-154.615784,-0.002065,0.003747,0.095178,290.024933,14.774573,0.951780,-154.615784,294.500488,0.000000
71.490005,65.194588,-154.615784,-0.002061,0.003751,0.095273,290.000000,14.773304,0.952734,-154.615784,294.500488,0.000000
71.850006,65.319344,-154.704742,-0.002052,0.003758,0.095464,290.554962,14.801575,0.954642,-154.704742,294.500488,0.000000
72.210007,65.224007,-154.704742,-0.002070,0.003758,0.095464,290.130859,14.779972,0.954642,-154.704742,294.500488,0.000000
72.570000,64.992775,-154.660263,-0.002057,0.003759,0.095473,289.102295,14.727573,0.954729,-154.660263,294.500488,0.000000
72.930000,66.397728,-154.793716,-0.002052,0.003770,0.095768,295.351837,15.045940,0.957677,-154.793716,294.500488,0.000000
73.290001,66.025734,-154.793716,-0.002031,0.003770,0.095759,293.697144,14.961645,0.957591,-154.793716,294.500488,0.000000
73.650002,65.728203,-154.838196,-0.002044,0.003770,0.095759,292.373657,14.894223,0.957591,-154.838196,294.500488,0.000000
74.010002,65.403862,-154.838196,-0.002039,0.003770,0.095759,290.930908,14.820727,0.957591,-154.838196,294.500488,0.000000
74.370003,65.117516,-154.882675,-0.002035,0.003770,0.095768,289.657166,14.755840,0.957677,-154.882675,294.500488,0.000000
74.730003,64.862068,-154.882675,-0.002048,0.003770,0.095768,288.520874,14.697954,0.957677,-154.882675,294.500488,0.000000
75.090004,66.427147,-154.927155,-0.002009,0.003753,0.095334,295.482697,15.052607,0.953341,-154.927155,294.500488,0.000000
75.450005,66.155312,-155.016113,-0.002022,0.003753,0.095334,294.273529,14.991008,0.953341,-155.016113,294.500488,0.000000
75.810005,65.870827,-155.016113,-0.002031,0.003754,0.095343,293.008057,14.926542,0.953428,-155.016113,294.500488,0.000000
76.170006,65.650002,-155.060593,-0.002022,0.003754,0.095360,292.025787,14.876503,0.953601,-155.060593,294.500488,0.000000
76.530006,65.424721,-155.060593,-0.002026,0.003755,0.095369,291.023682,14.825454,0.953688,-155.060593,294.500488,0.000000
76.890007,65.298485,-155.105072,-0.002018,0.003773,0.095828,290.462158,14.796848,0.958284,-155.105072,294.500488,0.000000
77.250000,65.076927,-155.105072,-0.002022,0.003773,0.095828,289.476624,14.746643,0.958284,-155.105072,294.500488,0.000000
77.610001,66.043983,-155.238525,-0.002013,0.003794,0.096366,293.778320,14.965780,0.963661,-155.238525,294.500488,0.000000
77.970001,65.848488,-155.238525,-0.002031,0.003794,0.096357,292.908691,14.921480,0.963575,-155.238525,294.500488,0.000000
78.330002,65.628777,-155.283005,-0.002031,0.003794,0.096357,291.931366,14.871694,0.963575,-155.283005,294.500488,0.000000
78.690002,65.454140,-155.283005,-0.002013,0.003794,0.096357,291.154541,14.832120,0.963575,-155.283005,294.500488,0.000000
79.050003,65.278374,-155.371964,-0.002018,0.003794,0.096357,290.372711,14.792291,0.963575,-155.371964,294.500488,0.000000
79.410004,65.091820,-155.327484,-0.002022,0.003794,0.096357,289.542877,14.750017,0.963575,-155.327484,294.500488,0.000000
79.770004,64.930214,-155.371964,-0.002022,0.003794,0.096357,288.824005,14.713397,0.963575,-155.371964,294.500488,0.000000
80.130005,66.376503,-155.460922,-0.002009,0.003800,0.096522,295.257446,15.041130,0.965222,-155.460922,294.500488,0.000000
80.490005,66.173927,-155.460922,-0.002005,0.003800,0.096522,294.356323,14.995226,0.965222,-155.460922,294.500488,0.000000
80.850006,66.013817,-155.505402,-0.002013,0.003800,0.096522,293.644135,14.958945,0.965222,-155.505402,294.500488,0.000000
81.210007,65.835823,-155.505402,-0.002005,0.003800,0.096522,292.852356,14.918611,0.965222,-155.505402,294.500488,0.000000
81.570007,65.736763,-155.549881,-0.001996,0.003800,0.096522,292.411713,14.896164,0.965222,-155.549881,294.500488,0.000000
81.930000,65.557289,-155.594360,-0.002013,0.003800,0.096522,291.613373,14.855494,0.965222,-155.594360,294.500488,0.000000
82.290001,65.454506,-155.594360,-0.001996,0.003800,0.096522,291.156189,14.832203,0.965222,-155.594360,294.500488,0.000000
82.650002,65.402748,-155.683334,-0.002005,0.003813,0.096843,290.925964,14.820475,0.968431,-155.683334,294.500488,0.000000
83.010002,65.321571,-155.683334,-0.001996,0.003813,0.096860,290.564850,14.802079,0.968604,-155.683334,294.500488,0.000000
83.370003,65.349876,-155.772293,-0.001992,0.003815,0.096904,290.690765,14.808494,0.969038,-155.772293,294.500488,0.000000
83.730003,65.367378,-155.683334,-0.001996,0.003817,0.096947,290.768616,14.812459,0.969472,-155.683334,294.500488,0.000000
84.090004,65.311897,-155.772293,-0.001988,0.003817,0.096956,290.521820,14.799888,0.969558,-155.772293,294.500488,0.000000
84.450005,65.305565,-155.816772,-0.001996,0.003819,0.096991,290.493652,14.798452,0.969905,-155.816772,294.500488,0.000000
84.810005,65.263863,-155.816772,-0.002001,0.003819,0.097008,290.308167,14.789002,0.970079,-155.816772,294.500488,0.000000
85.170006,65.263481,-155.905731,-0.002009,0.003820,0.097025,290.306458,14.788917,0.970252,-155.905731,294.500488,0.000000
85.530006,65.257896,-155.905731,-0.001996,0.003821,0.097060,290.281616,14.787651,0.970599,-155.905731,294.500488,0.000000
85.890007,65.199059,-155.994690,-0.001996,0.003821,0.097060,290.019897,14.774318,0.970599,-155.994690,294.500488,0.000000
86.250008,65.330513,-155.994690,-0.001996,0.003826,0.097173,290.604645,14.804106,0.971726,-155.994690,294.500488,0.000000
86.610001,65.372597,-155.994690,-0.001992,0.003826,0.097173,290.791840,14.813643,0.971726,-155.994690,294.500488,0.000000
86.970001,65.340569,-156.083664,-0.001992,0.003826,0.097181,290.649353,14.806384,0.971813,-156.083664,294.500488,0.000000
87.330002,65.295509,-156.083664,-0.002005,0.003826,0.097181,290.448944,14.796174,0.971813,-156.083664,294.500488,0.000000
87.690002,65.220665,-156.128143,-0.001988,0.003826,0.097181,290.115997,14.779214,0.971813,-156.128143,294.500488,0.000000
88.050003,65.161461,-156.172623,-0.001992,0.003827,0.097199,289.852661,14.765799,0.971987,-156.172623,294.500488,0.000000
88.410004,65.407219,-156.172623,-0.001988,0.003831,0.097303,290.945831,14.821488,0.973027,-156.172623,294.500488,0.000000
88.770004,65.368492,-156.217102,-0.001988,0.003831,0.097303,290.773590,14.812712,0.973027,-156.217102,294.500488,0.000000
89.130005,65.318596,-156.217102,-0.001996,0.003831,0.097303,290.551636,14.801406,0.973027,-156.217102,294.500488,0.000000
89.490005,65.268318,-156.306061,-0.001996,0.003831,0.097303,290.327972,14.790012,0.973027,-156.306061,294.500488,0.000000
89.850006,65.203911,-156.350540,-0.001988,0.003831,0.097311,290.041473,14.775417,0.973114,-156.350540,294.500488,0.000000
90.210007,65.337593,-156.350540,-0.001992,0.003835,0.097398,290.636139,14.805711,0.973981,-156.350540,294.500488,0.000000
90.570007,65.333122,-156.395020,-0.001983,0.003835,0.097398,290.616241,14.804697,0.973981,-156.395020,294.500488,0.000000
90.930008,65.298485,-156.439499,-0.001983,0.003835,0.097398,290.462158,14.796848,0.973981,-156.439499,294.500488,0.000000
91.290001,65.253807,-156.439499,-0.001992,0.003835,0.097398,290.263428,14.786724,0.973981,-156.439499,294.500488,0.000000
91.650002,65.204643,-156.483978,-0.001996,0.003835,0.097415,290.044739,14.775583,0.974155,-156.483978,294.500488,0.000000
92.010002,65.191246,-156.528473,-0.001983,0.003836,0.097424,289.985138,14.772547,0.974241,-156.528473,294.500488,0.000000
92.370003,65.382271,-156.617432,-0.001983,0.003839,0.097520,290.834869,14.815834,0.975195,-156.617432,294.500488,0.000000
92.730003,65.398277,-156.572952,-0.002001,0.003839,0.097520,290.906067,14.819462,0.975195,-156.572952,294.500488,0.000000
93.090004,65.333488,-156.706390,-0.001975,0.003839,0.097520,290.617859,14.804780,0.975195,-156.706390,294.500488,0.000000
93.450005,65.298866,-156.661911,-0.001979,0.003839,0.097520,290.463867,14.796934,0.975195,-156.661911,294.500488,0.000000
93.810005,65.261253,-156.750870,-0.001983,0.003839,0.097520,290.296539,14.788412,0.975195,-156.750870,294.500488,0.000000
94.170006,65.211357,-156.795349,-0.001983,0.003839,0.097520,290.074615,14.777104,0.975195,-156.795349,294.500488,0.000000
94.530006,65.174858,-156.750870,-0.001966,0.003840,0.097528,289.912262,14.768834,0.975282,-156.750870,294.500488,0.000000
94.890007,65.310036,-156.839828,-0.001979,0.003843,0.097624,290.513550,14.799465,0.976236,-156.839828,294.500488,0.000000
95.250008,65.347267,-156.839828,-0.001983,0.003843,0.097624,290.679169,14.807902,0.976236,-156.839828,294.500488,0.000000
95.610008,65.307426,-156.928802,-0.001975,0.003843,0.097624,290.501953,14.798875,0.976236,-156.928802,294.500488,0.000000
95.970001,65.289177,-156.973282,-0.001975,0.003843,0.097624,290.420776,14.794740,0.976236,-156.973282,294.500488,0.000000
96.330002,65.255287,-156.884308,-0.001983,0.003843,0.097624,290.270020,14.787059,0.976236,-156.884308,294.500488,0.000000
96.690002,65.205391,-157.017761,-0.001983,0.003843,0.097624,290.048065,14.775753,0.976236,-157.017761,294.500488,0.000000
97.050003,65.142097,-157.017761,-0.001983,0.003843,0.097624,289.766510,14.761411,0.976236,-157.017761,294.500488,0.000000
97.410004,65.426949,-157.062241,-0.001983,0.003849,0.097754,291.033600,14.825958,0.977537,-157.062241,294.500488,0.000000
97.770004,65.450783,-157.106720,-0.001979,0.003848,0.097745,291.139618,14.831359,0.977450,-157.106720,294.500488,0.000000
98.130005,65.440727,-157.106720,-0.001966,0.003848,0.097745,291.094879,14.829081,0.977450,-157.106720,294.500488,0.000000
98.490005,65.381905,-157.195679,-0.001975,0.003848,0.097745,290.833252,14.815751,0.977450,-157.195679,294.500488,0.000000
98.850006,65.352852,-157.195679,-0.001975,0.003848,0.097745,290.704010,14.809168,0.977450,-157.195679,294.500488,0.000000
99.210007,65.301460,-157.195679,-0.001957,0.003848,0.097745,290.475403,14.797522,0.977450,-157.195679,294.500488,0.000000
99.570007,65.274284,-157.240158,-0.001975,0.003848,0.097745,290.354523,14.791364,0.977450,-157.240158,294.500488,0.000000
99.930008,65.226616,-157.240158,-0.001966,0.003848,0.097745,290.142487,14.780562,0.977450,-157.240158,294.500488,0.000000
100.290009,65.184166,-157.418091,-0.001975,0.003848,0.097745,289.953644,14.770943,0.977450,-157.418091,294.500488,0.000000
100.650002,65.118629,-157.284637,-0.001979,0.003848,0.097745,289.662140,14.756093,0.977450,-157.284637,294.500488,0.000000
101.010002,65.084740,-157.373611,-0.001966,0.003849,0.097754,289.511383,14.748413,0.977537,-157.373611,294.500488,0.000000
101.370003,65.054955,-157.418091,-0.001979,0.003849,0.097754,289.378876,14.741663,0.977537,-157.418091,294.500488,0.000000
101.730003,65.012138,-157.462570,-0.001962,0.003849,0.097754,289.188446,14.731961,0.977537,-157.462570,294.500488,0.000000
102.090004,64.967445,-157.507050,-0.001979,0.003849,0.097754,288.989624,14.721833,0.977537,-157.507050,294.500488,0.000000
102.450005,64.933937,-157.507050,-0.001962,0.003849,0.097754,288.840576,14.714240,0.977537,-157.507050,294.500488,0.000000
102.810005,64.894096,-157.596008,-0.001962,0.003849,0.097754,288.663361,14.705213,0.977537,-157.596008,294.500488,0.000000
103.170006,64.834511,-157.596008,-0.001983,0.003849,0.097762,288.398315,14.691710,0.977624,-157.596008,294.500488,0.000000
103.530006,64.795784,-157.596008,-0.001966,0.003849,0.097762,288.226044,14.682934,0.977624,-157.596008,294.500488,0.000000
103.890007,64.762276,-157.684967,-0.001975,0.003849,0.097762,288.076996,14.675342,0.977624,-157.684967,294.500488,0.000000
104.250008,64.715355,-157.684967,-0.001966,0.003849,0.097762,287.868286,14.664709,0.977624,-157.684967,294.500488,0.000000
104.610008,64.671410,-157.818420,-0.001966,0.003849,0.097762,287.672791,14.654751,0.977624,-157.818420,294.500488,0.000000
104.970001,64.644966,-157.773926,-0.001966,0.003849,0.097762,287.555176,14.648759,0.977624,-157.773926,294.500488,0.000000
105.330002,66.038017,-157.773926,-0.001949,0.003856,0.097936,293.751770,14.964429,0.979358,-157.773926,294.500488,0.000000
105.690002,65.970985,-157.818420,-0.001966,0.003855,0.097918,293.453613,14.949239,0.979185,-157.818420,294.500488,0.000000
106.050003,65.919228,-157.862900,-0.001979,0.003855,0.097918,293.223358,14.937510,0.979185,-157.862900,294.500488,0.000000
106.410004,65.842155,-157.907379,-0.001953,0.003855,0.097918,292.880524,14.920046,0.979185,-157.907379,294.500488,0.000000
106.770004,65.835442,-157.862900,-0.001953,0.003855,0.097918,292.850677,14.918525,0.979185,-157.862900,294.500488,0.000000
107.130005,65.767311,-157.951859,-0.001957,0.003855,0.097918,292.547607,14.903086,0.979185,-157.951859,294.500488,0.000000
107.490005,65.740120,-157.951859,-0.001957,0.003855,0.097918,292.426666,14.896924,0.979185,-157.951859,294.500488,0.000000
107.850006,65.658577,-158.040817,-0.001957,0.003855,0.097918,292.063934,14.878446,0.979185,-158.040817,294.500488,0.000000
108.210007,65.628777,-158.129776,-0.001953,0.003855,0.097927,291.931366,14.871694,0.979271,-158.129776,294.500488,0.000000
108.570007,65.590431,-158.085297,-0.001966,0.003855,0.097927,291.760803,14.863005,0.979271,-158.085297,294.500488,0.000000
108.930008,65.549461,-158.129776,-0.001957,0.003855,0.097927,291.578552,14.853720,0.979271,-158.129776,294.500488,0.000000
109.290009,65.523766,-158.218750,-0.001970,0.003855,0.097927,291.464264,14.847898,0.979271,-158.218750,294.500488,0.000000
109.650002,65.475365,-158.218750,-0.001949,0.003855,0.097927,291.248962,14.836929,0.979271,-158.218750,294.500488,0.000000
110.010002,65.435890,-158.263229,-0.001970,0.003855,0.097927,291.073364,14.827985,0.979271,-158.263229,294.500488,0.000000
110.370003,65.373711,-158.307709,-0.001957,0.003855,0.097927,290.796783,14.813894,0.979271,-158.307709,294.500488,0.000000
110.730003,65.337959,-158.307709,-0.001962,0.003855,0.097927,290.637756,14.805793,0.979271,-158.307709,294.500488,0.000000
111.090004,65.292900,-158.307709,-0.001970,0.003855,0.097927,290.437317,14.795583,0.979271,-158.307709,294.500488,0.000000
111.450005,65.272041,-158.352188,-0.001957,0.003855,0.097927,290.344543,14.790855,0.979271,-158.352188,294.500488,0.000000
111.810005,65.244865,-158.441147,-0.001944,0.003855,0.097927,290.223663,14.784698,0.979271,-158.441147,294.500488,0.000000
112.170006,65.206505,-158.485626,-0.001957,0.003855,0.097927,290.053009,14.776005,0.979271,-158.485626,294.500488,0.000000
112.530006,65.147682,-158.530106,-0.001966,0.003855,0.097927,289.791351,14.762676,0.979271,-158.530106,294.500488,0.000000
112.890007,65.107094,-158.530106,-0.001957,0.003855,0.097927,289.610809,14.753479,0.979271,-158.530106,294.500488,0.000000
113.250008,65.082878,-158.530106,-0.001949,0.003855,0.097927,289.503113,14.747991,0.979271,-158.530106,294.500488,0.000000
113.610008,65.055702,-158.619064,-0.001957,0.003859,0.098031,289.382202,14.741833,0.980312,-158.619064,294.500488,0.000000
113.970009,65.029259,-158.619064,-0.001936,0.003859,0.098031,289.264587,14.735841,0.980312,-158.619064,294.500488,0.000000
114.330002,65.011009,-158.663559,-0.001962,0.003859,0.098031,289.183411,14.731706,0.980312,-158.663559,294.500488,0.000000
114.690002,64.973778,-158.708038,-0.001953,0.003859,0.098031,289.017792,14.723269,0.980312,-158.708038,294.500488,0.000000
115.050003,64.929466,-158.752518,-0.001957,0.003859,0.098031,288.820679,14.713227,0.980312,-158.752518,294.500488,0.000000
115.410004,64.920525,-158.752518,-0.001975,0.003860,0.098040,288.780914,14.711201,0.980399,-158.752518,294.500488,0.000000
115.770004,65.746452,-158.752518,-0.001957,0.003871,0.098326,292.454834,14.898359,0.983261,-158.752518,294.500488,0.000000
116.130005,65.753151,-158.841476,-0.001936,0.003871,0.098326,292.484619,14.899878,0.983261,-158.841476,294.500488,0.000000
116.490005,65.768044,-158.841476,-0.001953,0.003871,0.098326,292.550873,14.903252,0.983261,-158.841476,294.500488,0.000000
116.850006,65.758369,-158.885956,-0.001944,0.003871,0.098326,292.507843,14.901059,0.983261,-158.885956,294.500488,0.000000
117.210007,65.745338,-159.019394,-0.001966,0.003871,0.098326,292.449860,14.898107,0.983261,-159.019394,294.500488,0.000000
117.570007,65.725227,-158.974915,-0.001957,0.003871,0.098326,292.360413,14.893550,0.983261,-158.974915,294.500488,0.000000
117.930008,65.687996,-159.063889,-0.001944,0.003871,0.098326,292.194794,14.885113,0.983261,-159.063889,294.500488,0.000000
118.290009,65.660057,-159.019394,-0.001949,0.003871,0.098326,292.070526,14.878782,0.983261,-159.019394,294.500488,0.000000
118.650009,65.635857,-159.063889,-0.001949,0.003871,0.098326,291.962860,14.873298,0.983261,-159.063889,294.500488,0.000000
119.010002,65.619850,-159.152847,-0.001957,0.003871,0.098326,291.891663,14.869671,0.983261,-159.152847,294.500488,0.000000
119.370003,65.589317,-159.108368,-0.001957,0.003871,0.098326,291.755859,14.862752,0.983261,-159.108368,294.500488,0.000000
119.730003,65.567345,-159.197327,-0.001953,0.003871,0.098326,291.658112,14.857773,0.983261,-159.197327,294.500488,0.000000
120.090004,65.555046,-159.197327,-0.001949,0.003871,0.098326,291.603394,14.854985,0.983261,-159.197327,294.500488,0.000000
120.450005,65.536812,-159.286285,-0.001944,0.003871,0.098326,291.522308,14.850854,0.983261,-159.286285,294.500488,0.000000
120.810005,65.521904,-159.286285,-0.001949,0.003871,0.098326,291.455994,14.847476,0.983261,-159.286285,294.500488,0.000000
121.170006,65.474251,-159.330765,-0.001962,0.003871,0.098326,291.244019,14.836677,0.983261,-159.330765,294.500488,0.000000
121.530006,65.457497,-159.375244,-0.001944,0.003871,0.098326,291.169495,14.832880,0.983261,-159.375244,294.500488,0.000000
121.890007,65.424721,-159.375244,-0.001949,0.003871,0.098326,291.023682,14.825454,0.983261,-159.375244,294.500488,0.000000
122.250008,65.377052,-159.375244,-0.001957,0.003871,0.098326,290.811646,14.814652,0.983261,-159.375244,294.500488,0.000000
122.610008,65.369240,-159.508698,-0.001953,0.003871,0.098326,290.776886,14.812881,0.983261,-159.508698,294.500488,0.000000
122.970009,65.337212,-159.508698,-0.001953,0.003871,0.098326,290.634430,14.805623,0.983261,-159.508698,294.500488,0.000000
123.330009,65.308540,-159.508698,-0.001944,0.003871,0.098326,290.506897,14.799127,0.983261,-159.508698,294.500488,0.000000
123.690002,65.289925,-159.553177,-0.001949,0.003871,0.098326,290.424103,14.794909,0.983261,-159.553177,294.500488,0.000000
124.050003,65.271309,-159.597656,-0.001962,0.003871,0.098326,290.341278,14.790690,0.983261,-159.597656,294.500488,0.000000
124.410004,65.250816,-159.642136,-0.001953,0.003871,0.098326,290.250122,14.786046,0.983261,-159.642136,294.500488,0.000000
124.770004,65.239281,-159.686615,-0.001944,0.003871,0.098326,290.198822,14.783432,0.983261,-159.686615,294.500488,0.000000
125.130005,65.182304,-159.686615,-0.001944,0.003871,0.098326,289.945374,14.770521,0.983261,-159.686615,294.500488,0.000000
125.490005,65.166298,-159.686615,-0.001953,0.003871,0.098326,289.874176,14.766894,0.983261,-159.686615,294.500488,0.000000
125.850006,65.150276,-159.731094,-0.001949,0.003871,0.098326,289.802917,14.763264,0.983261,-159.731094,294.500488,0.000000
126.210007,65.099648,-159.820053,-0.001944,0.003871,0.098326,289.577698,14.751791,0.983261,-159.820053,294.500488,0.000000
126.570007,65.076180,-159.820053,-0.001940,0.003871,0.098317,289.473297,14.746473,0.983174,-159.820053,0.098326,0.000000
126.930008,65.032234,-159.864532,-0.001944,0.003858,0.097997,289.277832,14.736515,0.979965,-159.864532,0.097797,0.000000
127.290009,64.919411,-159.864532,-0.001962,0.003841,0.097572,288.775970,14.710948,0.975716,-159.864532,0.097190,0.000000
127.650009,64.830040,-159.909012,-0.001944,0.003822,0.097077,288.378418,14.690697,0.970772,-159.909012,0.096592,0.000000
128.010010,64.799873,-160.042465,-0.001944,0.003809,0.096756,288.244232,14.683861,0.967564,-160.042465,0.095993,0.000000
128.370010,64.836006,-159.997986,-0.001932,0.003772,0.095802,288.404968,14.692049,0.958024,-159.997986,0.095395,0.000000
128.730011,64.761894,-159.997986,-0.001944,0.003755,0.095386,288.075287,14.675255,0.953862,-159.997986,0.094796,0.000000
129.090012,64.693382,-160.086945,-0.001949,0.003732,0.094788,287.770538,14.659730,0.947878,-160.086945,0.094189,0.000000
129.450012,64.643852,-160.086945,-0.001940,0.003704,0.094094,287.550201,14.648506,0.940940,-160.086945,0.093591,0.000000
129.810013,64.619652,-160.131424,-0.001927,0.003687,0.093643,287.442566,14.643023,0.936430,-160.131424,0.092993,0.000000
130.170013,64.554863,-160.175903,-0.001940,0.003663,0.093036,287.154358,14.628341,0.930360,-160.175903,0.092394,0.000000
130.529999,64.030937,-160.264862,-0.001932,0.003637,0.092377,284.823822,14.509618,0.923769,-160.264862,0.091796,0.000000
130.889999,63.369972,-160.220383,-0.001932,0.003620,0.091952,281.883728,14.359840,0.919519,-160.220383,0.091189,0.000000
131.250000,62.493034,-160.220383,-0.001923,0.003597,0.091354,277.982910,14.161124,0.913536,-160.220383,0.090590,0.000000
131.610001,61.153610,-160.353836,-0.001927,0.003573,0.090746,272.024841,13.857607,0.907465,-160.353836,0.089992,0.000000
131.970001,60.008194,-160.264862,-0.001910,0.003555,0.090296,266.929779,13.598051,0.902955,-160.264862,0.089394,0.000000
132.330002,58.401779,-160.398315,-0.001910,0.003531,0.089680,259.784088,13.234033,0.896798,-160.398315,0.088795,0.000000
132.690002,56.677322,-160.353836,-0.001914,0.003508,0.089107,252.113327,12.843265,0.891074,-160.353836,0.088197,0.000000
133.050003,54.643051,-160.398315,-0.001910,0.003485,0.088526,243.064438,12.382293,0.885264,-160.398315,0.087590,0.000000
133.410004,52.711929,-160.442795,-0.001910,0.003463,0.087954,234.474365,11.944695,0.879540,-160.442795,0.086991,0.000000
133.770004,50.351082,-160.442795,-0.001906,0.003440,0.087382,223.972794,11.409718,0.873817,-160.442795,0.086393,0.000000
134.130005,47.875549,-160.487274,-0.001910,0.003415,0.086740,212.961075,10.848755,0.867399,-160.487274,0.085795,0.000000
134.490005,44.768105,-160.531754,-0.001914,0.003388,0.086063,199.138474,10.144598,0.860635,-160.531754,0.085196,0.000000
134.850006,41.763062,-160.620712,-0.001914,0.003361,0.085370,185.771378,9.463645,0.853697,-160.620712,0.084589,0.000000
135.210007,39.801773,-160.620712,-0.001914,0.003344,0.084936,177.047134,9.019211,0.849361,-160.620712,0.083991,0.000000
135.570007,37.915337,-160.620712,-0.001919,0.003328,0.084520,168.655838,8.591738,0.845198,-160.620712,0.083392,0.000000
135.930008,35.053650,-160.754150,-0.001919,0.003300,0.083809,155.926422,7.943271,0.838087,-160.754150,0.082794,0.000000
136.290009,32.425072,-160.665192,-0.001897,0.003274,0.083167,144.233917,7.347626,0.831669,-160.665192,0.082196,0.000000
136.650009,29.645317,-160.709671,-0.001906,0.003251,0.082569,131.868958,6.717725,0.825686,-160.709671,0.081589,0.000000
137.010010,26.978378,-160.754150,-0.001910,0.003227,0.081962,120.005821,6.113388,0.819615,-160.754150,0.080990,0.000000
137.370010,24.465614,-160.754150,-0.001910,0.003203,0.081346,108.828491,5.543987,0.813458,-160.754150,0.080392,0.000000
137.730011,22.743759,-160.887604,-0.001923,0.003190,0.081016,101.169296,5.153810,0.810162,-160.887604,0.079793,0.000000
138.090012,19.039772,-160.843124,-0.001906,0.003153,0.080097,84.693138,4.314474,0.800970,-160.843124,0.079195,0.000000
138.450012,16.461098,-160.932083,-0.001906,0.003130,0.079499,73.222618,3.730138,0.794986,-160.932083,0.078588,0.000000
138.810013,13.959122,-160.932083,-0.001919,0.003107,0.078909,62.093273,3.163182,0.789089,-160.932083,0.077990,0.000000
139.170013,12.235413,-161.021042,-0.001914,0.003093,0.078553,54.425835,2.772584,0.785533,-161.021042,0.077391,0.000000
139.530014,8.989441,-161.065521,-0.001906,0.003062,0.077781,39.987030,2.037036,0.777815,-161.065521,0.076793,0.000000
139.889999,7.213226,-161.065521,-0.001919,0.003046,0.077357,32.086033,1.634540,0.773565,-161.065521,0.076194,0.000000
140.250000,3.327888,-161.065521,-0.001923,0.003008,0.076403,14.803187,0.754110,0.764026,-161.065521,0.075596,0.000000
140.610001,1.386337,-161.198959,-0.001932,0.002989,0.075908,6.166736,0.314149,0.759083,-161.198959,0.074989,0.000000
140.970001,-0.646439,-161.154480,-0.001914,0.002968,0.075397,-2.875503,-0.146485,0.753966,-161.154480,0.074391,0.000000
141.330002,-3.360291,-161.243454,-0.001927,0.002941,0.074711,-14.947319,-0.761453,0.747115,-161.243454,0.073792,0.000000
141.690002,-0.367905,-161.154480,-0.001983,0.002921,0.074191,-1.636522,-0.083368,0.741912,-161.154480,0.073194,0.000000
142.050003,-0.114319,-161.243454,-0.001979,0.002896,0.073549,-0.508516,-0.025905,0.735494,-161.243454,0.072595,0.000000
142.410004,-0.051765,-161.287933,-0.001979,0.002869,0.072882,-0.230264,-0.011730,0.728817,-161.287933,0.071988,0.000000
142.770004,-0.035751,-161.332413,-0.002018,0.002845,0.072257,-0.159030,-0.008101,0.722572,-161.332413,0.071390,0.000000
143.130005,-0.010429,-161.421371,-0.002001,0.002826,0.071772,-0.046392,-0.002363,0.717716,-161.421371,0.070792,0.000000
143.490005,-0.007820,-161.376892,-0.002048,0.002802,0.071165,-0.034786,-0.001772,0.711645,-161.376892,0.070193,0.000000
143.850006,-0.010429,-161.421371,-0.002065,0.002774,0.070471,-0.046392,-0.002363,0.704708,-161.421371,0.069595,0.000000
144.210007,-0.020485,-161.421371,-0.002070,0.002750,0.069855,-0.091121,-0.004642,0.698550,-161.421371,0.068988,0.000000
144.570007,0.015640,-161.554810,-0.002078,0.002730,0.069343,0.069571,0.003544,0.693434,-161.554810,0.068389,0.000000
144.930008,0.012283,-161.554810,-0.002091,0.002708,0.068780,0.054639,0.002783,0.687797,-161.554810,0.067791,0.000000
145.290009,-0.003723,-161.599289,-0.002108,0.002674,0.067930,-0.016561,-0.000844,0.679298,-161.599289,0.067193,0.000000
145.650009,-0.021599,-161.554810,-0.002130,0.002655,0.067427,-0.096076,-0.004894,0.674268,-161.554810,0.066594,0.000000
146.010010,-0.017502,-161.599289,-0.002156,0.002637,0.066976,-0.077852,-0.003966,0.669758,-161.599289,0.065987,0.000000
146.370010,-0.014900,-161.643784,-0.002143,0.002612,0.066343,-0.066279,-0.003376,0.663428,-161.643784,0.065389,0.000000
146.730011,-0.003357,-161.777222,-0.002160,0.002591,0.065805,-0.014932,-0.000761,0.658051,-161.777222,0.064790,0.000000
147.090012,0.004463,-161.732742,-0.002190,0.002575,0.065415,0.019853,0.001011,0.654148,-161.732742,0.065276,0.000000
147.100006,-0.004845,-161.732742,-0.002173,0.002575,0.065415,-0.021550,-0.001098,0.654148,-161.732742,0.065276,0.000000