File: Data/compression 15/AutoNoHeating-17-15-reverse-longpurge-1_08262024_185949.csv
Time (sec),S:Load (lbs),S:HL1 (DIM),S:LVDT (in),S:Position (in),Ch:Position (mm),Ch:Load (N),Ch:Stress (MPa),Ch:Strain (mm/mm),Ch:HL1 (DIM),Set Point (),Cycles ()
0.010000,-0.112823,-142.872818,-0.009080,-0.009659,-0.245329,-0.501864,-0.025566,-2.453293,-142.872818,-0.245026,0.000000
0.420000,-0.043938,-143.006256,-0.009071,-0.009652,-0.245165,-0.195445,-0.009956,-2.451647,-143.006256,-0.244453,0.000000
0.830000,-0.071869,-143.006256,-0.008998,-0.009410,-0.239025,-0.319689,-0.016286,-2.390248,-143.006256,-0.237637,0.000000
1.240000,-0.022713,-143.050735,-0.008722,-0.009138,-0.232095,-0.101031,-0.005147,-2.320954,-143.050735,-0.230803,0.000000
1.650000,-0.016754,-143.139694,-0.008438,-0.008871,-0.225322,-0.074526,-0.003797,-2.253224,-143.139694,-0.223970,0.000000
2.060000,-0.026810,-143.184189,-0.008162,-0.008594,-0.218281,-0.119255,-0.006075,-2.182806,-143.184189,-0.217136,0.000000
2.470000,-0.067772,-143.228668,-0.007881,-0.008321,-0.211360,-0.301465,-0.015357,-2.113603,-143.228668,-0.210302,0.000000
2.880000,-0.088623,-143.317627,-0.007618,-0.008060,-0.204726,-0.394215,-0.020082,-2.047257,-143.317627,-0.203486,0.000000
3.290000,-0.092720,-143.317627,-0.007334,-0.007790,-0.197875,-0.412439,-0.021011,-1.978747,-143.317627,-0.196652,0.000000
3.700000,-0.048775,-143.451065,-0.007071,-0.007523,-0.191093,-0.216961,-0.011053,-1.910929,-143.451065,-0.189818,0.000000
4.110000,-0.034256,-143.451065,-0.006778,-0.007250,-0.184138,-0.152378,-0.007763,-1.841378,-143.451065,-0.182985,0.000000
4.520000,-0.049149,-143.540024,-0.006515,-0.006988,-0.177486,-0.218624,-0.011137,-1.774862,-143.540024,-0.176151,0.000000
4.930000,-0.026062,-143.584503,-0.006230,-0.006714,-0.170540,-0.115930,-0.005906,-1.705398,-143.584503,-0.169317,0.000000
5.340000,-0.065163,-143.673477,-0.005963,-0.006445,-0.163706,-0.289858,-0.014766,-1.637062,-143.673477,-0.162501,0.000000
5.750000,-0.020103,-143.806915,-0.005683,-0.006171,-0.156734,-0.089425,-0.004556,-1.567336,-143.806915,-0.155667,0.000000
6.160000,0.003357,-143.762436,-0.005424,-0.005908,-0.150065,0.014932,0.000761,-1.500646,-143.762436,-0.148833,0.000000
6.570000,-0.046547,-143.851395,-0.005139,-0.005638,-0.143205,-0.207051,-0.010548,-1.432049,-143.851395,-0.141999,0.000000
6.980000,-0.066277,-143.940353,-0.004881,-0.005374,-0.136501,-0.294813,-0.015018,-1.365011,-143.940353,-0.135166,0.000000
7.390000,0.083038,-143.984833,-0.004605,-0.005109,-0.129780,0.369373,0.018817,-1.297803,-143.984833,-0.128349,0.000000
7.800000,0.057350,-143.984833,-0.004596,-0.000010,-0.000260,0.255106,0.012996,-0.002604,-143.984833,-0.000044,0.000000
8.210000,0.117676,-144.073807,-0.004587,-0.000010,-0.000260,0.523448,0.026666,-0.002604,-144.073807,0.000433,0.000000
8.620001,0.086021,-144.162766,-0.004579,-0.000010,-0.000252,0.382642,0.019493,-0.002517,-144.162766,0.001118,0.000000
9.030001,0.257683,-144.207245,-0.004587,0.000029,0.000746,1.146230,0.058392,0.007456,-144.207245,0.001795,0.000000
9.440001,0.471054,-144.251724,-0.004531,0.000058,0.001466,2.095353,0.106742,0.014655,-144.251724,0.002480,0.000000
9.850000,0.699318,-144.296204,-0.004531,0.000085,0.002168,3.110722,0.158468,0.021680,-144.296204,0.003165,0.000000
10.260000,0.874702,-144.385162,-0.004501,0.000108,0.002740,3.890871,0.198210,0.027403,-144.385162,0.003850,0.000000
10.670000,1.283195,-144.429642,-0.004462,0.000136,0.003460,5.707939,0.290776,0.034602,-144.429642,0.004535,0.000000
11.080001,1.696907,-144.518616,-0.004462,0.000163,0.004137,7.548220,0.384525,0.041365,-144.518616,0.005212,0.000000
11.490001,2.115448,-144.563095,-0.004428,0.000189,0.004813,9.409983,0.479367,0.048129,-144.563095,0.005897,0.000000
11.900001,2.609215,-144.652054,-0.004419,0.000216,0.005490,11.606367,0.591256,0.054896,-144.652054,0.006582,0.000000
12.310000,3.009148,-144.696533,-0.004398,0.000241,0.006114,13.385357,0.681883,0.061137,-144.696533,0.007267,0.000000
12.720000,3.577011,-144.829971,-0.004359,0.000265,0.006738,15.911340,0.810562,0.067382,-144.829971,0.007952,0.000000
13.130001,4.296432,-144.829971,-0.004350,0.000297,0.007545,19.111486,0.973586,0.075448,-144.829971,0.008629,0.000000
13.540001,5.176353,-144.874451,-0.004312,0.000335,0.008499,23.025570,1.172979,0.084986,-144.874451,0.009314,0.000000
13.950001,5.552444,-144.963425,-0.004299,0.000357,0.009080,24.698507,1.258202,0.090796,-144.963425,0.009999,0.000000
14.360001,6.029457,-145.007904,-0.004281,0.000380,0.009661,26.820364,1.366295,0.096609,-145.007904,0.010684,0.000000
14.770000,6.533653,-145.141342,-0.004243,0.000402,0.010207,29.063141,1.480547,0.102071,-145.141342,0.011369,0.000000
15.180000,7.606453,-145.185822,-0.004243,0.000438,0.011135,33.835194,1.723647,0.111352,-145.185822,0.012046,0.000000
15.590001,8.048462,-145.185822,-0.004199,0.000466,0.011846,35.801346,1.823807,0.118463,-145.185822,0.012731,0.000000
16.000000,8.446899,-145.230301,-0.004169,0.000489,0.012427,37.573685,1.914095,0.124273,-145.230301,0.013416,0.000000
16.410000,9.151802,-145.230301,-0.004161,0.000519,0.013173,40.709248,2.073828,0.131729,-145.230301,0.014101,0.000000
16.820002,9.510025,-145.408234,-0.004143,0.000542,0.013763,42.302704,2.155002,0.137626,-145.408234,0.014786,0.000000
17.230001,10.259605,-145.497192,-0.004126,0.000570,0.014483,45.637005,2.324860,0.144825,-145.497192,0.015462,0.000000
17.640001,10.507233,-145.541672,-0.004083,0.000595,0.015107,46.738506,2.380973,0.151070,-145.541672,0.016147,0.000000
18.050001,11.094841,-145.630630,-0.004057,0.000621,0.015775,49.352318,2.514127,0.157747,-145.630630,0.016833,0.000000
18.460001,11.699203,-145.630630,-0.004061,0.000651,0.016538,52.040657,2.651078,0.165377,-145.630630,0.017518,0.000000
18.870001,11.810539,-145.675110,-0.004027,0.000671,0.017041,52.535904,2.676306,0.170407,-145.675110,0.018203,0.000000
19.280001,12.731789,-145.764084,-0.003997,0.000701,0.017804,56.633823,2.885065,0.178041,-145.764084,0.018879,0.000000
19.690001,13.371529,-145.764084,-0.003975,0.000734,0.018654,59.479530,3.030032,0.186539,-145.764084,0.019565,0.000000
20.100000,13.449722,-145.897522,-0.003967,0.000753,0.019131,59.827354,3.047751,0.191308,-145.897522,0.020250,0.000000
20.510000,14.131912,-145.897522,-0.003932,0.000783,0.019885,62.861885,3.202337,0.198855,-145.897522,0.020935,0.000000
20.920000,14.551201,-146.075439,-0.003911,0.000806,0.020475,64.726974,3.297349,0.204751,-146.075439,0.021620,0.000000
21.330002,15.040497,-146.075439,-0.003885,0.000834,0.021195,66.903473,3.408225,0.211950,-146.075439,0.022296,0.000000
21.740002,15.545067,-146.075439,-0.003850,0.000863,0.021932,69.147911,3.522562,0.219320,-146.075439,0.022982,0.000000
22.150002,15.800514,-146.164398,-0.003850,0.000890,0.022617,70.284195,3.580448,0.226170,-146.164398,0.023667,0.000000
22.560001,16.134903,-146.208893,-0.003824,0.000912,0.023164,71.771629,3.656221,0.231636,-146.208893,0.024352,0.000000
22.970001,17.049820,-146.297852,-0.003781,0.000945,0.024013,75.841385,3.863544,0.240133,-146.297852,0.025037,0.000000
23.380001,17.535019,-146.342331,-0.003764,0.000979,0.024855,77.999657,3.973492,0.248546,-146.342331,0.025713,0.000000
23.790001,17.541725,-146.386810,-0.003742,0.000998,0.025358,78.029488,3.975012,0.253577,-146.386810,0.026398,0.000000
24.200001,18.237686,-146.475769,-0.003721,0.001029,0.026129,81.125282,4.132719,0.261294,-146.475769,0.027083,0.000000
24.610001,18.415680,-146.520248,-0.003712,0.001052,0.026719,81.917038,4.173052,0.267191,-146.520248,0.027769,0.000000
25.020000,18.531494,-146.609207,-0.003691,0.001070,0.027170,82.432205,4.199297,0.271702,-146.609207,0.028454,0.000000
25.430000,19.367470,-146.653702,-0.003660,0.001106,0.028089,86.150810,4.388731,0.280892,-146.653702,0.029130,0.000000
25.840002,19.488113,-146.698181,-0.003635,0.001129,0.028688,86.687454,4.416070,0.286876,-146.698181,0.029815,0.000000
26.250002,19.844101,-146.876099,-0.003626,0.001161,0.029494,88.270973,4.496737,0.294942,-146.876099,0.030500,0.000000
26.660002,20.319626,-146.831619,-0.003596,0.001189,0.030188,90.386208,4.604493,0.301879,-146.831619,0.031185,0.000000
27.070002,21.031227,-146.876099,-0.003557,0.001220,0.030977,93.551567,4.765744,0.309771,-146.876099,0.031870,0.000000
27.480001,20.827538,-146.965057,-0.003561,0.001242,0.031550,92.645515,4.719587,0.315497,-146.965057,0.032547,0.000000
27.890001,20.991013,-147.009537,-0.003523,0.001264,0.032096,93.372688,4.756631,0.320959,-147.009537,0.033232,0.000000
28.300001,21.420731,-147.142990,-0.003505,0.001291,0.032781,95.284172,4.854007,0.327810,-147.142990,0.033917,0.000000
28.710001,21.942795,-147.098511,-0.003479,0.001319,0.033492,97.606422,4.972308,0.334922,-147.098511,0.034602,0.000000
29.120001,22.428368,-147.231949,-0.003462,0.001350,0.034281,99.766365,5.082341,0.342813,-147.231949,0.035287,0.000000
29.530001,22.292824,-147.276428,-0.003445,0.001373,0.034871,99.163429,5.051626,0.348710,-147.276428,0.035964,0.000000
29.940001,21.918587,-147.276428,-0.003445,0.001384,0.035166,97.498741,4.966823,0.351658,-147.276428,0.036649,0.000000
30.350002,23.482185,-147.454346,-0.003415,0.001429,0.036302,104.453979,5.321139,0.363021,-147.454346,0.037334,0.000000
30.760002,23.511230,-147.409866,-0.003385,0.001453,0.036900,104.583176,5.327721,0.369005,-147.409866,0.038019,0.000000
31.170002,23.914505,-147.543320,-0.003359,0.001481,0.037629,106.377029,5.419104,0.376287,-147.543320,0.038704,0.000000
31.580002,23.970734,-147.587799,-0.003350,0.001508,0.038305,106.627151,5.431846,0.383054,-147.587799,0.039381,0.000000
31.990002,24.353905,-147.632278,-0.003324,0.001535,0.038999,108.331581,5.518674,0.389992,-147.632278,0.040066,0.000000
32.400002,24.656647,-147.721237,-0.003311,0.001562,0.039684,109.678246,5.587276,0.396842,-147.721237,0.040751,0.000000
32.810001,24.914330,-147.765717,-0.003285,0.001588,0.040334,110.824471,5.645668,0.403345,-147.765717,0.041436,0.000000
33.220001,25.392456,-147.854675,-0.003260,0.001616,0.041046,112.951286,5.754013,0.410457,-147.854675,0.042121,0.000000
33.630001,25.319466,-147.854675,-0.003255,0.001640,0.041644,112.626610,5.737473,0.416441,-147.854675,0.042797,0.000000
34.040001,25.652740,-147.943649,-0.003225,0.001664,0.042260,114.109085,5.812994,0.422599,-147.943649,0.043483,0.000000
34.450001,26.291733,-147.988129,-0.003212,0.001696,0.043084,116.951469,5.957792,0.430838,-147.988129,0.044168,0.000000
34.860001,27.187660,-148.032608,-0.003195,0.001733,0.044012,120.936752,6.160812,0.440115,-148.032608,0.044853,0.000000
35.270000,27.007057,-148.121567,-0.003173,0.001757,0.044619,120.133392,6.119887,0.446186,-148.121567,0.045538,0.000000
35.680000,26.936310,-148.166046,-0.003143,0.001781,0.045234,119.818687,6.103855,0.452344,-148.166046,0.046214,0.000000
36.090000,26.892738,-148.255005,-0.003134,0.001800,0.045711,119.624878,6.093982,0.457113,-148.255005,0.046899,0.000000
36.500000,28.230301,-148.343979,-0.003117,0.001837,0.046648,125.574654,6.397078,0.466481,-148.343979,0.047584,0.000000
36.910000,28.524849,-148.388458,-0.003100,0.001865,0.047368,126.884865,6.463823,0.473676,-148.388458,0.048270,0.000000
37.320004,28.511070,-148.477417,-0.003087,0.001887,0.047940,126.823578,6.460701,0.479402,-148.477417,0.048955,0.000000
37.730003,28.952705,-148.477417,-0.003048,0.001916,0.048660,128.788071,6.560777,0.486597,-148.477417,0.049631,0.000000
38.140003,29.104637,-148.566376,-0.003040,0.001941,0.049293,129.463898,6.595205,0.492930,-148.566376,0.050316,0.000000
38.550003,28.432129,-148.655334,-0.003022,0.001956,0.049683,126.472427,6.442812,0.496832,-148.655334,0.051001,0.000000
38.960003,30.376289,-148.610855,-0.003001,0.001998,0.050758,135.120483,6.883366,0.507585,-148.610855,0.051687,0.000000
39.370003,30.137222,-148.744293,-0.002979,0.002020,0.051305,134.057053,6.829192,0.513050,-148.744293,0.052372,0.000000
39.780003,30.601570,-148.788788,-0.002966,0.002050,0.052059,136.122589,6.934415,0.520593,-148.788788,0.053048,0.000000
40.190002,30.870049,-148.833267,-0.002936,0.002072,0.052640,137.316833,6.995253,0.526403,-148.833267,0.053733,0.000000
40.600002,31.338867,-148.877747,-0.002932,0.002102,0.053386,139.402237,7.101489,0.533863,-148.877747,0.054418,0.000000
41.010002,32.056427,-148.966705,-0.002897,0.002133,0.054175,142.594116,7.264091,0.541755,-148.966705,0.055104,0.000000
41.420002,31.744011,-149.011185,-0.002893,0.002151,0.054644,141.204407,7.193295,0.546437,-149.011185,0.055789,0.000000
41.830002,32.483543,-149.100143,-0.002880,0.002181,0.055407,144.494019,7.360876,0.554071,-149.100143,0.056465,0.000000
42.240002,32.732658,-149.100143,-0.002859,0.002205,0.056005,145.602142,7.417326,0.560055,-149.100143,0.057150,0.000000
42.650002,33.267387,-149.233597,-0.002846,0.002233,0.056708,147.980728,7.538497,0.567079,-149.233597,0.057835,0.000000
43.060001,33.955154,-149.233597,-0.002833,0.002263,0.057480,151.040070,7.694348,0.574797,-149.233597,0.058520,0.000000
43.470001,34.525261,-149.322556,-0.002807,0.002290,0.058165,153.576035,7.823536,0.581648,-149.322556,0.059205,0.000000
43.880001,34.381897,-149.367035,-0.002807,0.002311,0.058711,152.938309,7.791049,0.587109,-149.367035,0.059882,0.000000
44.290001,35.516891,-149.455994,-0.002785,0.002346,0.059578,157.987030,8.048243,0.595784,-149.455994,0.060567,0.000000
44.700001,36.303337,-149.544952,-0.002768,0.002377,0.060385,161.485306,8.226454,0.603850,-149.544952,0.061252,0.000000
45.110001,36.060181,-149.455994,-0.002746,0.002399,0.060931,160.403702,8.171354,0.609311,-149.455994,0.061937,0.000000
45.520000,36.820564,-149.633926,-0.002746,0.002428,0.061660,163.786057,8.343659,0.616597,-149.633926,0.062622,0.000000
45.930000,36.810509,-149.678406,-0.002725,0.002451,0.062258,163.741318,8.341381,0.622581,-149.678406,0.063299,0.000000
46.340004,36.737526,-149.722885,-0.002712,0.002469,0.062700,163.416672,8.324842,0.627002,-149.722885,0.063984,0.000000
46.750004,38.105995,-149.767365,-0.002686,0.002505,0.063620,169.503937,8.634942,0.636195,-149.767365,0.064669,0.000000
47.160004,38.243774,-149.856323,-0.002673,0.002528,0.064201,170.116806,8.666163,0.642005,-149.856323,0.065354,0.000000
47.570004,39.156830,-149.989761,-0.002652,0.002559,0.064990,174.178284,8.873064,0.649897,-149.989761,0.066039,0.000000
47.980003,39.379883,-149.989761,-0.002647,0.002586,0.065683,175.170471,8.923609,0.656834,-149.989761,0.066716,0.000000
48.390003,40.681694,-150.034241,-0.002626,0.002618,0.066507,180.961212,9.218604,0.665074,-150.034241,0.067401,0.000000
48.800003,40.484337,-150.123215,-0.002630,0.002641,0.067071,180.083328,9.173882,0.670710,-150.123215,0.068086,0.000000
49.210003,40.612808,-150.123215,-0.002608,0.002663,0.067644,180.654800,9.202993,0.676436,-150.123215,0.068771,0.000000
49.620003,41.213066,-150.212173,-0.002596,0.002689,0.068303,183.324875,9.339015,0.683026,-150.212173,0.069456,0.000000
50.030003,41.903076,-150.256653,-0.002587,0.002716,0.068988,186.394196,9.495373,0.689877,-150.256653,0.070133,0.000000
50.440002,42.728996,-150.345612,-0.002583,0.002748,0.069803,190.068069,9.682529,0.698029,-150.345612,0.070818,0.000000
50.850002,42.696976,-150.390091,-0.002548,0.002771,0.070393,189.925629,9.675273,0.703926,-150.390091,0.071503,0.000000
51.260002,42.607231,-150.390091,-0.002548,0.002791,0.070887,189.526428,9.654936,0.708869,-150.390091,0.072188,0.000000
51.670002,43.163925,-150.479065,-0.002527,0.002822,0.071667,192.002731,9.781085,0.716674,-150.479065,0.072873,0.000000
52.080002,44.791939,-150.523544,-0.002518,0.002852,0.072431,199.244492,10.149999,0.724308,-150.523544,0.073549,0.000000
52.490002,45.438011,-150.612503,-0.002492,0.002880,0.073150,202.118362,10.296400,0.731503,-150.612503,0.074234,0.000000
52.900002,45.629036,-150.701462,-0.002479,0.002906,0.073801,202.968094,10.339687,0.738009,-150.701462,0.074919,0.000000
53.310001,46.241959,-150.745941,-0.002475,0.002933,0.074503,205.694504,10.478578,0.745034,-150.745941,0.075605,0.000000
53.720001,46.972183,-150.834900,-0.002449,0.002961,0.075206,208.942703,10.644049,0.752059,-150.834900,0.076290,0.000000
54.130001,47.420891,-150.834900,-0.002449,0.002986,0.075839,210.938660,10.745728,0.758387,-150.834900,0.076966,0.000000
54.540001,48.136963,-150.879379,-0.002427,0.003013,0.076532,214.123901,10.907991,0.765325,-150.879379,0.077651,0.000000
54.950001,48.215530,-150.968353,-0.002414,0.003036,0.077122,214.473389,10.925795,0.771222,-150.968353,0.078336,0.000000
55.360004,49.123009,-151.012833,-0.002419,0.003067,0.077894,218.510056,11.131433,0.778943,-151.012833,0.079021,0.000000
55.770004,49.972015,-151.101791,-0.002384,0.003094,0.078579,222.286621,11.323821,0.785793,-151.101791,0.079706,0.000000
56.180004,51.622742,-151.146271,-0.002384,0.003131,0.079524,229.629425,11.697881,0.795244,-151.146271,0.080383,0.000000
56.590004,51.625717,-151.190750,-0.002363,0.003154,0.080114,229.642654,11.698555,0.801141,-151.190750,0.081068,0.000000
57.000004,51.938889,-151.279709,-0.002358,0.003179,0.080739,231.035721,11.769521,0.807386,-151.279709,0.081753,0.000000
57.410004,52.142944,-151.279709,-0.002345,0.003195,0.081164,231.943405,11.815760,0.811637,-151.279709,0.082438,0.000000
57.820004,54.002205,-151.368683,-0.002324,0.003234,0.082135,240.213806,12.237075,0.821349,-151.368683,0.083123,0.000000
58.230003,54.962921,-151.457642,-0.002315,0.003262,0.082846,244.487289,12.454776,0.828461,-151.457642,0.083800,0.000000
58.640003,55.735596,-151.502121,-0.002298,0.003286,0.083462,247.924316,12.629867,0.834619,-151.502121,0.084485,0.000000
59.050003,56.700409,-151.591080,-0.002294,0.003314,0.084164,252.216019,12.848496,0.841643,-151.591080,0.085170,0.000000
59.460003,57.030334,-151.591080,-0.002285,0.003337,0.084754,253.683594,12.923258,0.847540,-151.591080,0.085855,0.000000
59.870003,57.101830,-151.635559,-0.002264,0.003352,0.085153,254.001617,12.939460,0.851529,-151.635559,0.086540,0.000000
60.280003,59.167381,-151.680038,-0.002259,0.003391,0.086142,263.189667,13.407520,0.861416,-151.680038,0.087217,0.000000
60.690002,60.650909,-151.769012,-0.002246,0.003418,0.086809,269.788727,13.743692,0.868092,-151.769012,0.087902,0.000000
61.100002,61.964272,-151.813492,-0.002238,0.003447,0.087564,275.630859,14.041305,0.875635,-151.813492,0.088587,0.000000
61.510002,62.905624,-151.857971,-0.002207,0.003471,0.088162,279.818207,14.254619,0.881619,-151.857971,0.089272,0.000000
61.920002,64.379471,-151.991409,-0.002199,0.003498,0.088856,286.374176,14.588596,0.888557,-151.991409,0.089957,0.000000
62.330002,66.103928,-152.035889,-0.002190,0.003531,0.089688,294.044952,14.979364,0.896884,-152.035889,0.090633,0.000000
62.740002,65.062408,-152.035889,-0.002169,0.003526,0.089558,289.412048,14.743353,0.895582,-152.035889,0.015731,0.000000
63.150002,65.855942,-152.213821,-0.002160,0.003417,0.086792,292.941864,14.923169,0.867918,-152.213821,294.500458,0.000000
63.560001,65.710342,-152.258301,-0.002160,0.003560,0.090434,292.294189,14.890177,0.904340,-152.258301,294.500458,0.000000
63.970001,64.684830,-152.258301,-0.002151,0.003580,0.090929,287.732483,14.657792,0.909287,-152.258301,294.500458,0.000000
64.380005,65.555801,-152.347260,-0.002139,0.003572,0.090738,291.606781,14.855157,0.907376,-152.347260,294.500458,0.000000
64.790001,65.512985,-152.302780,-0.002117,0.003590,0.091197,291.416321,14.845455,0.911974,-152.302780,294.500458,0.000000
65.200005,65.279129,-152.525177,-0.002113,0.003596,0.091345,290.376068,14.792462,0.913447,-152.525177,294.500458,0.000000
65.610001,65.218811,-152.525177,-0.002121,0.003603,0.091527,290.107758,14.778794,0.915271,-152.525177,294.500458,0.000000
66.020004,65.575912,-152.569656,-0.002113,0.003610,0.091683,291.696228,14.859715,0.916830,-152.569656,294.500458,0.000000
66.430000,65.906204,-152.614136,-0.002117,0.003620,0.091952,293.165436,14.934560,0.919518,-152.614136,294.500458,0.000000
66.840004,65.185669,-152.614136,-0.002091,0.003620,0.091960,289.960327,14.771283,0.919605,-152.614136,294.500458,0.000000
67.250000,66.612961,-152.747589,-0.002095,0.003535,0.089784,296.309235,15.094713,0.897838,-152.747589,294.500458,0.000000
67.660004,65.922592,-152.747589,-0.002091,0.003540,0.089923,293.238342,14.938272,0.899227,-152.747589,294.500458,0.000000
68.070000,65.463074,-152.881027,-0.002078,0.003622,0.092004,291.194305,14.834145,0.920040,-152.881027,294.500458,0.000000
68.480003,65.893921,-152.925507,-0.002091,0.003647,0.092628,293.110809,14.931776,0.926281,-152.925507,294.500458,0.000000
68.890007,65.336105,-152.925507,-0.002074,0.003647,0.092628,290.629517,14.805373,0.926281,-152.925507,294.500458,0.000000
69.300003,65.495850,-153.058960,-0.002074,0.003657,0.092880,291.340088,14.841572,0.928798,-153.058960,294.500458,0.000000
69.710007,65.352859,-153.058960,-0.002074,0.003660,0.092975,290.704041,14.809170,0.929752,-153.058960,294.500458,0.000000
70.120003,65.434402,-153.147919,-0.002052,0.003666,0.093105,291.066772,14.827648,0.931054,-153.147919,294.500458,0.000000
70.530006,65.456757,-153.192398,-0.002078,0.003670,0.093218,291.166199,14.832713,0.932182,-153.192398,294.500458,0.000000
70.940002,65.313385,-153.236877,-0.002061,0.003672,0.093279,290.528442,14.800224,0.932787,-153.236877,294.500458,0.000000
71.350006,65.539795,-153.325836,-0.002061,0.003679,0.093443,291.535553,14.851530,0.934434,-153.325836,294.500458,0.000000
71.760002,65.353226,-153.325836,-0.002061,0.003679,0.093443,290.705658,14.809253,0.934434,-153.325836,294.500458,0.000000
72.170006,65.503677,-153.414795,-0.002052,0.003684,0.093565,291.374908,14.843346,0.935649,-153.414795,294.500458,0.000000
72.580002,65.251953,-153.459274,-0.002044,0.003684,0.093574,290.255188,14.786304,0.935736,-153.459274,294.500458,0.000000
72.990005,65.889450,-153.503769,-0.002035,0.003692,0.093782,293.090912,14.930763,0.937818,-153.503769,294.500458,0.000000
73.400002,65.585587,-153.637207,-0.002044,0.003692,0.093782,291.739258,14.861906,0.937818,-153.637207,294.500458,0.000000
73.810005,65.336105,-153.681686,-0.002061,0.003692,0.093782,290.629517,14.805373,0.937818,-153.681686,294.500458,0.000000
74.220001,65.064270,-153.726166,-0.002048,0.003692,0.093782,289.420319,14.743774,0.937818,-153.726166,294.500458,0.000000
74.630005,64.817017,-153.770645,-0.002048,0.003692,0.093782,288.320496,14.687746,0.937818,-153.770645,294.500458,0.000000
75.040001,66.769363,-153.770645,-0.002035,0.003645,0.092594,297.004974,15.130154,0.925937,-153.770645,294.500458,0.000000
75.450005,66.353790,-153.948578,-0.002035,0.003636,0.092342,295.156403,15.035984,0.923420,-153.948578,294.500458,0.000000
75.860001,66.082336,-153.993057,-0.002035,0.003636,0.092342,293.948914,14.974472,0.923420,-153.993057,294.500458,0.000000
76.270004,65.859665,-154.037537,-0.002026,0.003639,0.092420,292.958435,14.924013,0.924203,-154.037537,294.500458,0.000000
76.680000,65.628036,-154.037537,-0.002022,0.003668,0.093175,291.928101,14.871526,0.931747,-154.037537,294.500458,0.000000
77.090004,65.496964,-154.082016,-0.002031,0.003688,0.093686,291.345032,14.841825,0.936864,-154.082016,294.500458,0.000000
77.500000,65.374084,-154.170975,-0.002013,0.003697,0.093903,290.798462,14.813979,0.939032,-154.170975,294.500458,0.000000
77.910004,65.260513,-154.259933,-0.002022,0.003705,0.094111,290.293274,14.788243,0.941114,-154.259933,294.500458,0.000000
78.320007,65.063522,-154.259933,-0.002022,0.003706,0.094120,289.416992,14.743606,0.941197,-154.259933,294.500458,0.000000
78.730003,65.721130,-154.348907,-0.002035,0.003714,0.094337,292.342194,14.892621,0.943366,-154.348907,294.500458,0.000000
79.140007,65.525635,-154.348907,-0.002009,0.003714,0.094337,291.472595,14.848321,0.943366,-154.348907,294.500458,0.000000
79.550003,65.336853,-154.437866,-0.002013,0.003714,0.094337,290.632843,14.805542,0.943366,-154.437866,294.500458,0.000000
79.960007,65.183060,-154.482346,-0.002018,0.003714,0.094337,289.948730,14.770692,0.943366,-154.482346,294.500458,0.000000
80.370003,65.015869,-154.526825,-0.002018,0.003714,0.094337,289.205017,14.732806,0.943366,-154.526825,294.500458,0.000000
80.780006,64.845322,-154.704742,-0.002005,0.003714,0.094345,288.446411,14.694160,0.943453,-154.704742,294.500458,0.000000
81.190002,66.792450,-154.704742,-0.002001,0.003611,0.091718,297.107666,15.135386,0.917178,-154.704742,294.500458,0.000000
81.600006,66.578705,-154.749222,-0.002009,0.003604,0.091535,296.156860,15.086949,0.915354,-154.749222,294.500458,0.000000
82.010002,66.360504,-154.793716,-0.002013,0.003604,0.091544,295.186279,15.037505,0.915441,-154.793716,294.500458,0.000000
82.420006,66.200745,-154.882675,-0.001996,0.003604,0.091544,294.475616,15.001304,0.915441,-154.882675,294.500458,0.000000
82.830002,66.046219,-155.016113,-0.002022,0.003604,0.091544,293.788269,14.966287,0.915441,-155.016113,294.500458,0.000000
83.240005,65.919235,-154.971634,-0.002009,0.003605,0.091570,293.223389,14.937511,0.915702,-154.971634,294.500458,0.000000
83.650002,65.763962,-155.060593,-0.001996,0.003627,0.092134,292.532715,14.902327,0.921338,-155.060593,294.500458,0.000000
84.060005,65.663040,-155.149551,-0.001992,0.003694,0.093816,292.083801,14.879457,0.938162,-155.149551,294.500458,0.000000
84.470001,65.538666,-155.060593,-0.001992,0.003697,0.093903,291.530548,14.851274,0.939032,-155.060593,294.500458,0.000000
84.880005,65.449677,-155.238525,-0.001996,0.003705,0.094103,291.134705,14.831108,0.941027,-155.238525,294.500458,0.000000
85.290001,65.323441,-155.149551,-0.001996,0.003705,0.094111,290.573181,14.802504,0.941114,-155.149551,294.500458,0.000000
85.700005,65.624313,-155.327484,-0.002001,0.003736,0.094892,291.911530,14.870682,0.948919,-155.327484,294.500458,0.000000
86.110001,65.559525,-155.371964,-0.002005,0.003736,0.094892,291.623322,14.856000,0.948919,-155.371964,294.500458,0.000000
86.520004,65.471649,-155.371964,-0.001992,0.003736,0.094892,291.232452,14.836088,0.948919,-155.371964,294.500458,0.000000
86.930008,65.619476,-155.549881,-0.001988,0.003740,0.094987,291.890015,14.869586,0.949872,-155.549881,294.500458,0.000000
87.340004,65.542404,-155.549881,-0.002005,0.003740,0.095005,291.547180,14.852121,0.950046,-155.549881,294.500458,0.000000
87.750008,65.493622,-155.638855,-0.001988,0.003741,0.095013,291.330170,14.841067,0.950130,-155.638855,294.500458,0.000000
88.160004,65.488770,-155.683334,-0.002005,0.003742,0.095048,291.308594,14.839967,0.950478,-155.683334,294.500458,0.000000
88.570007,65.435898,-155.683334,-0.001983,0.003742,0.095048,291.073425,14.827986,0.950478,-155.683334,294.500458,0.000000
88.980003,65.540161,-155.905731,-0.001992,0.003746,0.095143,291.537201,14.851613,0.951432,-155.905731,294.500458,0.000000
89.390007,65.540527,-155.861252,-0.001996,0.003746,0.095143,291.538818,14.851695,0.951432,-155.861252,294.500458,0.000000
89.800003,65.478714,-155.905731,-0.001979,0.003746,0.095143,291.263855,14.837688,0.951432,-155.905731,294.500458,0.000000
90.210007,65.423233,-155.950211,-0.002009,0.003746,0.095143,291.017090,14.825116,0.951432,-155.950211,294.500458,0.000000
90.620003,65.359940,-155.994690,-0.001983,0.003746,0.095161,290.735535,14.810775,0.951606,-155.994690,294.500458,0.000000
91.030006,65.774017,-156.172623,-0.002005,0.003752,0.095308,292.577454,14.904605,0.953078,-156.172623,294.500458,0.000000
91.440002,65.735291,-156.128143,-0.001983,0.003752,0.095308,292.405182,14.895830,0.953078,-156.128143,294.500458,0.000000
91.850006,65.689117,-156.172623,-0.001996,0.003752,0.095308,292.199799,14.885367,0.953078,-156.172623,294.500458,0.000000
92.260002,65.641083,-156.217102,-0.001996,0.003752,0.095308,291.986115,14.874482,0.953078,-156.217102,294.500458,0.000000
92.670006,65.558029,-156.306061,-0.001992,0.003752,0.095308,291.616669,14.855662,0.953078,-156.306061,294.500458,0.000000
93.080002,65.486542,-156.395020,-0.001992,0.003752,0.095308,291.298676,14.839462,0.953078,-156.395020,294.500458,0.000000
93.490005,65.432541,-156.395020,-0.001988,0.003752,0.095308,291.058472,14.827226,0.953078,-156.395020,294.500458,0.000000
93.900002,65.375946,-156.483978,-0.001988,0.003752,0.095308,290.806732,14.814402,0.953078,-156.483978,294.500458,0.000000
94.310005,65.286942,-156.572952,-0.001996,0.003753,0.095317,290.410828,14.794232,0.953165,-156.572952,294.500458,0.000000
94.720001,65.226990,-156.572952,-0.001992,0.003753,0.095317,290.144135,14.780647,0.953165,-156.572952,294.500458,0.000000
95.130005,65.157364,-156.617432,-0.001983,0.003753,0.095317,289.834442,14.764870,0.953165,-156.617432,294.500458,0.000000
95.540001,66.360870,-156.706390,-0.002001,0.003751,0.095265,295.187897,15.037589,0.952647,-156.706390,294.500458,0.000000
95.950005,66.293472,-156.795349,-0.001970,0.003751,0.095265,294.888092,15.022316,0.952647,-156.795349,294.500458,0.000000
96.360008,66.194427,-156.839828,-0.001975,0.003751,0.095265,294.447510,14.999871,0.952647,-156.839828,294.500458,0.000000
96.770004,66.118454,-156.884308,-0.001988,0.003751,0.095265,294.109558,14.982656,0.952647,-156.884308,294.500458,0.000000
97.180008,66.051804,-156.973282,-0.001970,0.003751,0.095265,293.813110,14.967552,0.952647,-156.973282,294.500458,0.000000
97.590004,65.935623,-156.928802,-0.001983,0.003751,0.095265,293.296295,14.941226,0.952647,-156.928802,294.500458,0.000000
98.000008,65.909561,-156.973282,-0.001996,0.003751,0.095265,293.180359,14.935320,0.952647,-156.973282,294.500458,0.000000
98.410004,65.859665,-157.106720,-0.001970,0.003751,0.095265,292.958435,14.924013,0.952647,-157.106720,294.500458,0.000000
98.820007,65.756516,-157.195679,-0.001992,0.003751,0.095265,292.499603,14.900640,0.952647,-157.195679,294.500458,0.000000
99.230003,65.692841,-157.195679,-0.001988,0.003751,0.095265,292.216339,14.886210,0.952647,-157.195679,294.500458,0.000000
99.640007,65.651123,-157.284637,-0.001979,0.003751,0.095265,292.030792,14.876758,0.952647,-157.284637,294.500458,0.000000
100.050003,65.554687,-157.329117,-0.001988,0.003751,0.095265,291.601807,14.854904,0.952647,-157.329117,294.500458,0.000000
100.460007,65.491379,-157.373611,-0.001966,0.003751,0.095265,291.320190,14.840559,0.952647,-157.373611,294.500458,0.000000
100.870003,65.448181,-157.373611,-0.001979,0.003751,0.095265,291.128052,14.830770,0.952647,-157.373611,294.500458,0.000000
101.280006,65.389359,-157.507050,-0.001966,0.003751,0.095265,290.866394,14.817441,0.952647,-157.507050,294.500458,0.000000
101.690002,65.311157,-157.551529,-0.001979,0.003751,0.095273,290.518524,14.799720,0.952734,-157.551529,294.500458,0.000000
102.100006,66.084946,-157.596008,-0.001975,0.003766,0.095664,293.960510,14.975062,0.956636,-157.596008,294.500458,0.000000
102.510002,66.027969,-157.684967,-0.001983,0.003766,0.095664,293.707062,14.962152,0.956636,-157.684967,294.500458,0.000000
102.920006,65.932266,-157.729446,-0.001975,0.003766,0.095664,293.281372,14.940465,0.956636,-157.729446,294.500458,0.000000
103.330002,65.914398,-157.818420,-0.001979,0.003766,0.095664,293.201874,14.936416,0.956636,-157.818420,294.500458,0.000000
103.740005,65.855194,-157.862900,-0.001979,0.003766,0.095664,292.938538,14.923000,0.956636,-157.862900,294.500458,0.000000
104.150002,65.784805,-157.862900,-0.001975,0.003766,0.095664,292.625427,14.907050,0.956636,-157.862900,294.500458,0.000000
104.560005,65.710709,-157.996338,-0.001979,0.003766,0.095664,292.295837,14.890260,0.956636,-157.996338,294.500458,0.000000
104.970001,65.695068,-157.996338,-0.001970,0.003766,0.095664,292.226257,14.886715,0.956636,-157.996338,294.500458,0.000000
105.380005,65.635483,-158.085297,-0.001975,0.003766,0.095664,291.961212,14.873213,0.956636,-158.085297,294.500458,0.000000
105.790009,65.559891,-158.129776,-0.001979,0.003766,0.095664,291.624969,14.856084,0.956636,-158.129776,294.500458,0.000000
106.200005,65.499939,-158.129776,-0.001975,0.003766,0.095664,291.358276,14.842498,0.956636,-158.129776,294.500458,0.000000
106.610008,65.468674,-158.218750,-0.001979,0.003766,0.095664,291.219208,14.835413,0.956636,-158.218750,294.500458,0.000000
107.020004,65.419510,-158.218750,-0.001970,0.003766,0.095664,291.000519,14.824273,0.956636,-158.218750,294.500458,0.000000
107.430008,65.370361,-158.352188,-0.001983,0.003766,0.095664,290.781891,14.813136,0.956636,-158.352188,294.500458,0.000000
107.840004,65.766937,-158.396667,-0.001975,0.003779,0.095985,292.545959,14.903001,0.959846,-158.396667,294.500458,0.000000
108.250008,65.849228,-158.352188,-0.001966,0.003777,0.095924,292.911987,14.921648,0.959236,-158.352188,294.500458,0.000000
108.660004,65.831726,-158.485626,-0.001970,0.003777,0.095924,292.834137,14.917682,0.959236,-158.485626,294.500458,0.000000
109.070007,65.751297,-158.530106,-0.001975,0.003777,0.095924,292.476379,14.899457,0.959236,-158.530106,294.500458,0.000000
109.480003,65.720398,-158.619064,-0.001979,0.003777,0.095924,292.338928,14.892454,0.959236,-158.619064,294.500458,0.000000
109.890007,65.702896,-158.663559,-0.001988,0.003777,0.095924,292.261078,14.888489,0.959236,-158.663559,294.500458,0.000000
110.300003,65.671234,-158.663559,-0.001962,0.003777,0.095924,292.120239,14.881314,0.959236,-158.663559,294.500458,0.000000
110.710007,65.638840,-158.752518,-0.001975,0.003777,0.095924,291.976135,14.873974,0.959236,-158.752518,294.500458,0.000000
111.120003,65.596756,-158.796997,-0.001957,0.003777,0.095924,291.788940,14.864437,0.959236,-158.796997,294.500458,0.000000
111.530006,65.540527,-158.841476,-0.001975,0.003777,0.095924,291.538818,14.851695,0.959236,-158.841476,294.500458,0.000000
111.940002,65.512985,-158.841476,-0.001975,0.003777,0.095924,291.416321,14.845455,0.959236,-158.841476,294.500458,0.000000
112.350006,65.473129,-158.885956,-0.001966,0.003777,0.095924,291.239014,14.836423,0.959236,-158.885956,294.500458,0.000000
112.760002,65.438873,-159.019394,-0.001970,0.003777,0.095924,291.086639,14.828661,0.959236,-159.019394,294.500458,0.000000
113.170006,65.404999,-159.063889,-0.001962,0.003777,0.095924,290.935974,14.820985,0.959236,-159.063889,294.500458,0.000000
113.580002,65.356949,-159.108368,-0.001962,0.003777,0.095924,290.722229,14.810097,0.959236,-159.108368,294.500458,0.000000
113.990005,65.307053,-159.152847,-0.001975,0.003777,0.095924,290.500275,14.798789,0.959236,-159.152847,294.500458,0.000000
114.400009,65.274292,-159.286285,-0.001957,0.003777,0.095924,290.354553,14.791366,0.959236,-159.286285,294.500458,0.000000
114.810005,65.244492,-159.330765,-0.001975,0.003777,0.095924,290.221985,14.784614,0.959236,-159.330765,294.500458,0.000000
115.220009,65.220673,-159.330765,-0.001970,0.003777,0.095924,290.116028,14.779216,0.959236,-159.330765,294.500458,0.000000
115.630005,65.174118,-159.419724,-0.001966,0.003777,0.095924,289.908966,14.768666,0.959236,-159.419724,294.500458,0.000000
116.040009,65.128693,-159.464203,-0.001975,0.003777,0.095932,289.706879,14.758373,0.959323,-159.464203,294.500458,0.000000
116.450005,65.089218,-159.553177,-0.001953,0.003777,0.095932,289.531311,14.749428,0.959323,-159.553177,294.500458,0.000000
116.860008,65.049744,-159.642136,-0.001975,0.003777,0.095932,289.355713,14.740482,0.959323,-159.642136,294.500458,0.000000
117.270004,65.020706,-159.642136,-0.001970,0.003777,0.095932,289.226532,14.733903,0.959323,-159.642136,294.500458,0.000000
117.680008,64.986816,-159.686615,-0.001953,0.003777,0.095932,289.075806,14.726223,0.959323,-159.686615,294.500458,0.000000
118.090004,64.953674,-159.775574,-0.001970,0.003777,0.095932,288.928375,14.718713,0.959323,-159.775574,294.500458,0.000000
118.500008,64.905640,-159.775574,-0.001957,0.003777,0.095932,288.714691,14.707828,0.959323,-159.775574,294.500458,0.000000
118.910004,64.873611,-159.909012,-0.001966,0.003777,0.095932,288.572235,14.700571,0.959323,-159.909012,294.500458,0.000000
119.320007,66.747772,-159.864532,-0.001957,0.003710,0.094224,296.908905,15.125261,0.942238,-159.864532,294.500458,0.000000
119.730003,66.619293,-159.953506,-0.001975,0.003692,0.093782,296.337402,15.096148,0.937818,-159.953506,294.500458,0.000000
120.140007,66.565674,-159.953506,-0.001966,0.003692,0.093782,296.098907,15.083998,0.937818,-159.953506,294.500458,0.000000
120.550003,66.565674,-160.042465,-0.001957,0.003692,0.093782,296.098907,15.083998,0.937818,-160.042465,294.500458,0.000000
120.960007,66.504242,-160.131424,-0.001962,0.003692,0.093782,295.825653,15.070077,0.937818,-160.131424,294.500458,0.000000
121.370003,66.389542,-160.086945,-0.001957,0.003693,0.093790,295.315430,15.044086,0.937905,-160.086945,294.500458,0.000000
121.780006,66.379120,-160.309341,-0.001970,0.003693,0.093790,295.269073,15.041724,0.937905,-160.309341,294.500458,0.000000
122.190002,66.359756,-160.264862,-0.001962,0.003693,0.093790,295.182953,15.037336,0.937905,-160.264862,294.500458,0.000000
122.600006,66.340012,-160.353836,-0.001957,0.003693,0.093790,295.095123,15.032862,0.937905,-160.353836,294.500458,0.000000
123.010002,66.287521,-160.442795,-0.001962,0.003693,0.093790,294.861633,15.020967,0.937905,-160.442795,1681.640747,0.000000
123.420006,66.241333,-160.487274,-0.001962,0.003693,0.093790,294.656158,15.010501,0.937905,-160.487274,0.093392,0.000000
123.830009,66.181015,-160.576233,-0.001975,0.003672,0.093270,294.387848,14.996832,0.932700,-160.576233,0.092715,0.000000
124.240005,66.183990,-160.620712,-0.001962,0.003657,0.092897,294.401093,14.997506,0.928972,-160.620712,0.092030,0.000000
124.650009,66.098343,-160.620712,-0.001957,0.003619,0.091926,294.020111,14.978099,0.919256,-160.620712,0.091345,0.000000
125.060005,65.960205,-160.709671,-0.001957,0.003597,0.091362,293.405640,14.946796,0.913621,-160.709671,0.090660,0.000000
125.470009,65.678680,-160.709671,-0.001949,0.003569,0.090642,292.153351,14.883001,0.906422,-160.709671,0.089975,0.000000
125.880005,64.573105,-160.798645,-0.001953,0.003542,0.089966,287.235504,14.632475,0.899658,-160.798645,0.089298,0.000000
126.290009,63.920349,-160.887604,-0.001953,0.003525,0.089541,284.331909,14.484558,0.895408,-160.887604,0.088613,0.000000
126.700005,62.560814,-160.887604,-0.001932,0.003495,0.088769,278.284393,14.176483,0.887690,-160.887604,0.087928,0.000000
127.110008,61.081749,-160.976562,-0.001936,0.003470,0.088145,271.705200,13.841323,0.881449,-160.976562,0.087243,0.000000
127.520004,59.314842,-160.976562,-0.001940,0.003448,0.087572,263.845581,13.440935,0.875723,-160.976562,0.086558,0.000000
127.930008,57.398239,-161.154480,-0.001936,0.003426,0.087017,255.320114,13.006627,0.870174,-161.154480,0.085881,0.000000
128.340012,54.878395,-161.154480,-0.001940,0.003394,0.086211,244.111298,12.435622,0.862108,-161.154480,0.085196,0.000000
128.750000,51.890480,-161.198959,-0.001927,0.003364,0.085448,230.820389,11.758552,0.854478,-161.198959,0.084511,0.000000
129.160004,49.180725,-161.287933,-0.001940,0.003337,0.084754,218.766785,11.144512,0.847540,-161.287933,0.083826,0.000000
129.570007,46.758812,-161.287933,-0.001927,0.003317,0.084251,207.993576,10.595698,0.842510,-161.287933,0.083141,0.000000
129.980011,44.782257,-161.421371,-0.001923,0.003300,0.083817,199.201431,10.147804,0.838173,-161.421371,0.082465,0.000000
130.389999,41.271530,-161.421371,-0.001923,0.003265,0.082924,183.584930,9.352262,0.829240,-161.421371,0.081779,0.000000
130.800003,37.774208,-161.510330,-0.001923,0.003233,0.082117,168.028076,8.559758,0.821175,-161.510330,0.081094,0.000000
131.210007,35.453957,-161.510330,-0.001927,0.003213,0.081614,157.707077,8.033981,0.816144,-161.510330,0.080409,0.000000
131.620010,32.102234,-161.554810,-0.001923,0.003181,0.080790,142.797867,7.274470,0.807905,-161.554810,0.079724,0.000000
132.029999,29.920876,-161.643784,-0.001919,0.003156,0.080175,133.094696,6.780168,0.801751,-161.643784,0.079048,0.000000
132.440002,26.470840,-161.643784,-0.001944,0.003129,0.079473,117.748177,5.998378,0.794726,-161.643784,0.078362,0.000000
132.850006,23.067360,-161.688263,-0.001914,0.003098,0.078683,102.608742,5.227139,0.786834,-161.688263,0.077677,0.000000
133.260010,20.088005,-161.821701,-0.001936,0.003071,0.077998,89.355911,4.552007,0.779984,-161.821701,0.076992,0.000000
133.670013,19.364487,-161.821701,-0.001927,0.003065,0.077859,86.137535,4.388055,0.778595,-161.821701,0.076307,0.000000
134.080002,15.329086,-161.955139,-0.001914,0.003022,0.076758,68.187180,3.473620,0.767581,-161.955139,0.075631,0.000000
134.490005,11.077713,-161.955139,-0.001932,0.002985,0.075830,49.276127,2.510246,0.758300,-161.955139,0.074945,0.000000
134.900009,8.814056,-161.999619,-0.001940,0.002965,0.075301,39.206882,1.997294,0.753012,-161.999619,0.074260,0.000000
135.310013,7.046776,-162.088593,-0.001932,0.002940,0.074677,31.345625,1.596822,0.746767,-162.088593,0.073575,0.000000
135.720001,3.514450,-162.044098,-0.001932,0.002914,0.074026,15.633055,0.796386,0.740261,-162.044098,0.072890,0.000000
136.130005,1.229202,-162.222031,-0.001927,0.002886,0.073298,5.467765,0.278541,0.732979,-162.222031,0.072214,0.000000
136.540009,-2.156780,-162.222031,-0.001936,0.002854,0.072483,-9.593838,-0.488733,0.724826,-162.222031,0.071529,0.000000
136.950012,-0.367905,-162.266510,-0.001927,0.002832,0.071936,-1.636522,-0.083368,0.719361,-162.266510,0.070843,0.000000
137.360001,-0.141129,-162.355469,-0.001940,0.002808,0.071329,-0.627771,-0.031980,0.713294,-162.355469,0.070158,0.000000
137.770004,-0.058456,-162.355469,-0.001932,0.002781,0.070644,-0.260027,-0.013246,0.706439,-162.355469,0.069473,0.000000
138.180008,-0.092720,-162.488907,-0.001927,0.002748,0.069803,-0.412439,-0.021011,0.698029,-162.488907,0.068797,0.000000
138.590012,-0.097183,-162.533401,-0.001932,0.002719,0.069074,-0.432293,-0.022022,0.690743,-162.533401,0.068112,0.000000
139.000000,-0.045799,-162.533401,-0.001919,0.002693,0.068407,-0.203725,-0.010378,0.684067,-162.533401,0.067427,0.000000
139.410004,-0.023087,-162.666840,-0.001923,0.002680,0.068060,-0.102694,-0.005231,0.680596,-162.666840,0.066742,0.000000
139.820007,-0.041328,-162.711319,-0.001923,0.002646,0.067210,-0.183838,-0.009365,0.672099,-162.711319,0.066057,0.000000
140.230011,-0.086388,-162.755798,-0.001927,0.002611,0.066317,-0.384271,-0.019576,0.663167,-162.755798,0.065380,0.000000
140.639999,-0.067398,-162.800278,-0.001940,0.002585,0.065658,-0.299802,-0.015273,0.656577,-162.800278,0.064695,0.000000
141.050003,-0.068512,-162.844757,-0.001923,0.002560,0.065033,-0.304756,-0.015525,0.650332,-162.844757,0.064010,0.000000
141.460007,-0.073357,-162.933731,-0.001953,0.002537,0.064435,-0.326307,-0.016623,0.644348,-162.933731,0.063325,0.000000
141.870010,-0.053993,-162.933731,-0.001932,0.002513,0.063836,-0.240174,-0.012235,0.638364,-162.933731,0.062640,0.000000
142.280014,-0.065910,-163.022690,-0.001940,0.002474,0.062830,-0.293184,-0.014935,0.628304,-163.022690,0.061963,0.000000
142.690002,-0.080429,-163.111649,-0.001953,0.002457,0.062414,-0.357766,-0.018225,0.624141,-163.111649,0.061278,0.000000
143.100006,-0.100166,-163.111649,-0.001957,0.002429,0.061694,-0.445562,-0.022698,0.616942,-163.111649,0.060593,0.000000
143.510010,-0.091972,-163.111649,-0.001962,0.002407,0.061139,-0.409113,-0.020841,0.611393,-163.111649,0.059908,0.000000
143.920013,-0.081551,-163.200607,-0.001979,0.002388,0.060662,-0.362755,-0.018480,0.606624,-163.200607,0.059223,0.000000
144.330002,-0.068138,-163.334045,-0.001992,0.002342,0.059483,-0.303093,-0.015440,0.594830,-163.334045,0.058546,0.000000
144.740005,-0.102776,-163.378540,-0.002013,0.002324,0.059032,-0.457169,-0.023289,0.590319,-163.378540,0.057861,0.000000
145.150009,-0.087875,-163.423019,-0.002013,0.002303,0.058494,-0.390889,-0.019913,0.584944,-163.423019,0.057176,0.000000
145.560013,-0.093834,-163.511978,-0.002052,0.002265,0.057532,-0.417394,-0.021263,0.575315,-163.511978,0.056491,0.000000
145.970001,-0.086761,-163.511978,-0.002070,0.002239,0.056864,-0.385934,-0.019660,0.568639,-163.511978,0.055806,0.000000
146.380005,-0.105751,-163.556458,-0.002117,0.002210,0.056135,-0.470404,-0.023964,0.561353,-163.556458,0.055129,0.000000
146.790009,-0.089737,-163.600937,-0.002173,0.002178,0.055329,-0.399170,-0.020335,0.553287,-163.600937,0.054444,0.000000
147.200012,-0.093834,-163.689896,-0.002156,0.002155,0.054748,-0.417394,-0.021263,0.547477,-163.689896,0.053759,0.000000
147.610001,-0.097931,-163.823349,-0.002160,0.002139,0.054340,-0.435618,-0.022191,0.543401,-163.823349,0.053074,0.000000
148.020004,-0.125862,-163.778854,-0.002182,0.002103,0.053412,-0.559863,-0.028521,0.534124,-163.778854,0.052389,0.000000
148.430008,-0.115807,-163.867828,-0.002177,0.002078,0.052779,-0.515133,-0.026242,0.527792,-163.867828,0.051713,0.000000
148.840012,-0.096443,-163.867828,-0.002225,0.002054,0.052172,-0.429001,-0.021854,0.521721,-163.867828,0.051028,0.000000
149.250000,-0.093094,-163.956787,-0.002242,0.002027,0.051496,-0.414102,-0.021095,0.514958,-163.956787,0.050343,0.000000
149.660004,-0.110222,-164.045746,-0.002272,0.002004,0.050906,-0.490291,-0.024977,0.509061,-164.045746,0.049657,0.000000
150.070007,-0.108734,-164.090225,-0.002311,0.001964,0.049883,-0.483674,-0.024640,0.498826,-164.090225,0.048972,0.000000
150.480011,-0.096443,-164.134705,-0.002328,0.001937,0.049189,-0.429001,-0.021854,0.491889,-164.134705,0.048296,0.000000
150.890015,-0.095322,-164.134705,-0.002345,0.001918,0.048729,-0.424012,-0.021600,0.487294,-164.134705,0.047611,0.000000
151.300003,-0.089371,-164.223679,-0.002358,0.001901,0.048287,-0.397541,-0.020252,0.482869,-164.223679,0.046926,0.000000
151.710007,-0.096069,-164.268158,-0.002393,0.001865,0.047368,-0.427338,-0.021770,0.473676,-164.268158,0.046240,0.000000
152.120010,-0.099419,-164.312637,-0.002419,0.001830,0.046492,-0.442236,-0.022529,0.464918,-164.312637,0.045555,0.000000
152.530014,-0.112823,-164.401596,-0.002432,0.001807,0.045902,-0.501864,-0.025566,0.459021,-164.401596,0.044870,0.000000
152.940002,-0.115059,-164.401596,-0.002466,0.001778,0.045156,-0.511808,-0.026073,0.451564,-164.401596,0.044194,0.000000
153.350006,-0.095695,-164.490555,-0.002488,0.001756,0.044610,-0.425675,-0.021685,0.446099,-164.490555,0.043509,0.000000
153.760010,-0.098305,-164.579514,-0.002518,0.001727,0.043864,-0.437281,-0.022276,0.438643,-164.579514,0.042823,0.000000
154.170013,-0.097931,-164.579514,-0.002531,0.001698,0.043127,-0.435618,-0.022191,0.431270,-164.579514,0.042138,0.000000
154.580002,-0.099792,-164.623993,-0.002552,0.001670,0.042425,-0.443899,-0.022613,0.424245,-164.623993,0.041453,0.000000
154.990005,-0.099419,-164.712967,-0.002591,0.001652,0.041956,-0.442236,-0.022529,0.419563,-164.712967,0.040777,0.000000
155.400009,-0.083778,-164.801926,-0.002604,0.001623,0.041236,-0.372665,-0.018984,0.412364,-164.801926,0.040092,0.000000
155.810013,-0.090858,-164.890884,-0.002643,0.001584,0.040239,-0.404159,-0.020589,0.402391,-164.890884,0.039407,0.000000
156.220001,-0.096069,-164.801926,-0.002656,0.001565,0.039754,-0.427338,-0.021770,0.397535,-164.801926,0.038721,0.000000
156.630005,-0.053619,-164.935364,-0.002677,0.001542,0.039155,-0.238511,-0.012150,0.391551,-164.935364,0.038036,0.000000
157.040009,-0.068886,-164.979843,-0.002716,0.001516,0.038496,-0.306419,-0.015610,0.384962,-164.979843,0.037360,0.000000
157.450012,-0.108734,-165.024323,-0.002725,0.001496,0.038002,-0.483674,-0.024640,0.380019,-165.024323,0.036675,0.000000
157.860001,-0.069260,-165.157776,-0.002768,0.001453,0.036909,-0.308082,-0.015694,0.369092,-165.157776,0.035990,0.000000
158.270004,-0.071121,-165.113297,-0.002785,0.001430,0.036328,-0.316363,-0.016116,0.363278,-165.113297,0.035305,0.000000
158.680008,-0.063675,-165.291214,-0.002807,0.001405,0.035695,-0.283240,-0.014429,0.356950,-165.291214,0.034620,0.000000
159.090012,-0.074097,-165.246735,-0.002837,0.001376,0.034940,-0.329598,-0.016791,0.349403,-165.246735,0.033943,0.000000
159.500000,-0.059204,-165.291214,-0.002846,0.001366,0.034689,-0.263353,-0.013416,0.346889,-165.291214,0.033258,0.000000
159.910004,-0.064789,-165.335693,-0.002889,0.001319,0.033492,-0.288195,-0.014681,0.334922,-165.335693,0.032573,0.000000
160.320007,-0.040588,-165.424652,-0.002906,0.001294,0.032876,-0.180546,-0.009197,0.328764,-165.424652,0.031888,0.000000
160.730011,-0.048775,-165.513626,-0.002923,0.001279,0.032477,-0.216961,-0.011053,0.324774,-165.513626,0.031203,0.000000
161.140015,-0.053993,-165.469131,-0.002975,0.001248,0.031688,-0.240174,-0.012235,0.316883,-165.469131,0.030526,0.000000
161.550003,-0.082291,-165.558105,-0.002988,0.001211,0.030769,-0.366047,-0.018647,0.307689,-165.558105,0.029841,0.000000
161.960007,-0.071869,-165.647064,-0.003027,0.001186,0.030127,-0.319689,-0.016286,0.301274,-165.647064,0.029156,0.000000
162.370010,-0.060692,-165.602585,-0.003048,0.001161,0.029485,-0.269971,-0.013753,0.294855,-165.602585,0.028471,0.000000
162.780014,-0.078194,-165.736023,-0.003065,0.001132,0.028757,-0.347823,-0.017719,0.287573,-165.736023,0.027786,0.000000
163.190002,-0.068138,-165.780502,-0.003104,0.001105,0.028072,-0.303093,-0.015440,0.280718,-165.780502,0.027109,0.000000
163.600006,-0.074097,-165.824982,-0.003104,0.001105,0.028072,-0.329598,-0.016791,0.280718,-165.824982,0.026424,0.000000
164.010010,-0.078941,-165.913940,-0.003156,0.001058,0.026875,-0.351149,-0.017888,0.268754,-165.913940,0.025739,0.000000
164.420013,-0.102402,-165.913940,-0.003182,0.001027,0.026095,-0.455506,-0.023205,0.260946,-165.913940,0.025054,0.000000
164.830002,-0.094582,-165.958435,-0.003191,0.001006,0.025540,-0.420720,-0.021432,0.255397,-165.958435,0.024369,0.000000
165.240005,-0.096443,-166.002914,-0.003216,0.000987,0.025072,-0.429001,-0.021854,0.250715,-166.002914,0.023693,0.000000
165.650009,-0.070374,-166.136353,-0.003255,0.000942,0.023935,-0.313037,-0.015947,0.239353,-166.136353,0.023007,0.000000
166.060013,-0.085274,-166.180832,-0.003281,0.000922,0.023424,-0.379317,-0.019323,0.234236,-166.180832,0.022322,0.000000
166.470001,-0.076706,-166.136353,-0.003303,0.000889,0.022583,-0.341205,-0.017382,0.225826,-166.136353,0.021637,0.000000
166.700012,-0.071495,-166.269791,-0.003311,0.000890,0.022608,-0.318026,-0.016201,0.226083,-166.269791,0.022539,0.000000