File: Data/compression 15/AutoNoHeating-17-15-reverse-shortpurge-2re_08262024_192857.csv
Time (sec),S:Load (lbs),S:HL1 (DIM),S:LVDT (in),S:Position (in),Ch:Position (mm),Ch:Load (N),Ch:Stress (MPa),Ch:Strain (mm/mm),Ch:HL1 (DIM),Set Point (),Cycles ()
0.110000,0.021973,-63.518799,-0.008537,-0.008414,-0.213728,0.097739,0.004979,-2.137278,-63.518799,-0.213502,0.000000
0.460000,0.062561,-63.607761,-0.008550,-0.008366,-0.212488,0.278285,0.014177,-2.124876,-63.607761,-0.211803,0.000000
0.810000,0.009308,-63.607761,-0.008420,-0.008159,-0.207241,0.041403,0.002109,-2.072409,-63.607761,-0.205975,0.000000
1.160000,0.015266,-63.652241,-0.008166,-0.007929,-0.201404,0.067908,0.003459,-2.014045,-63.652241,-0.200130,0.000000
1.510000,0.003349,-63.652241,-0.007920,-0.007697,-0.195499,0.014898,0.000759,-1.954987,-63.652241,-0.194302,0.000000
1.860000,0.006332,-63.652241,-0.007692,-0.007467,-0.189662,0.028168,0.001435,-1.896623,-63.652241,-0.188474,0.000000
2.210000,0.027557,-63.785683,-0.007463,-0.007241,-0.183913,0.122581,0.006245,-1.839126,-63.785683,-0.182646,0.000000
2.560000,0.030167,-63.830166,-0.007230,-0.007009,-0.178024,0.134188,0.006836,-1.780241,-63.830166,-0.176819,0.000000
2.910000,0.023087,-63.874645,-0.006989,-0.006779,-0.172188,0.102694,0.005231,-1.721877,-63.874645,-0.170974,0.000000
3.260000,0.027557,-63.874645,-0.006743,-0.006549,-0.166334,0.122581,0.006245,-1.663339,-63.874645,-0.165146,0.000000
3.610000,0.011917,-63.919128,-0.006515,-0.006324,-0.160636,0.053010,0.002700,-1.606362,-63.919128,-0.159318,0.000000
3.960000,0.018250,-63.919128,-0.006265,-0.006089,-0.154670,0.081178,0.004135,-1.546697,-63.919128,-0.153490,0.000000
4.310000,0.005211,-64.008087,-0.006053,-0.005865,-0.148963,0.023179,0.001181,-1.489634,-64.008087,-0.147663,0.000000
4.660000,0.031281,-64.052567,-0.005799,-0.005629,-0.142980,0.139143,0.007088,-1.429795,-64.052567,-0.141835,0.000000
5.010000,0.018990,-64.052567,-0.005558,-0.005399,-0.137126,0.084470,0.004303,-1.371257,-64.052567,-0.135990,0.000000
5.360000,0.052132,-64.141533,-0.005342,-0.005178,-0.131515,0.231893,0.011813,-1.315148,-64.141533,-0.130162,0.000000
5.710000,0.037987,-64.141533,-0.005083,-0.004944,-0.125574,0.168974,0.008608,-1.255743,-64.141533,-0.124334,0.000000
6.060000,0.039848,-64.141533,-0.004881,-0.004716,-0.119790,0.177254,0.009030,-1.197899,-64.141533,-0.118506,0.000000
6.410000,0.150436,-64.186012,-0.004738,-0.000000,-0.000009,0.669175,0.034089,-0.000087,-64.186012,0.000173,0.000000
6.760000,0.138153,-64.274971,-0.004730,-0.000000,-0.000009,0.614536,0.031306,-0.000087,-64.274971,0.000173,0.000000
7.110000,0.124748,-64.274971,-0.004743,-0.000000,-0.000009,0.554908,0.028268,-0.000087,-64.274971,0.000694,0.000000
7.460001,0.110596,-64.274971,-0.004734,-0.000000,-0.000000,0.491954,0.025061,-0.000000,-64.274971,0.001283,0.000000
7.810000,0.250977,-64.363937,-0.004712,0.000034,0.000867,1.116400,0.056872,0.008672,-64.363937,0.001865,0.000000
8.160001,0.469933,-64.363937,-0.004691,0.000058,0.001474,2.090364,0.106488,0.014743,-64.363937,0.002446,0.000000
8.510000,0.661705,-64.452896,-0.004669,0.000082,0.002090,2.943411,0.149944,0.020900,-64.452896,0.003027,0.000000
8.860001,0.892578,-64.497375,-0.004652,0.000102,0.002584,3.970386,0.202261,0.025843,-64.497375,0.003616,0.000000
9.210000,1.195686,-64.497375,-0.004635,0.000119,0.003018,5.318678,0.270946,0.030179,-64.497375,0.004197,0.000000
9.560000,1.660034,-64.586342,-0.004618,0.000147,0.003729,7.384201,0.376169,0.037291,-64.586342,0.004778,0.000000
9.910001,2.107628,-64.630821,-0.004583,0.000174,0.004414,9.375197,0.477595,0.044142,-64.630821,0.005359,0.000000
10.260000,2.544792,-64.630821,-0.004583,0.000198,0.005039,11.319801,0.576658,0.050386,-64.630821,0.005949,0.000000
10.610001,2.971161,-64.675301,-0.004562,0.000222,0.005637,13.216384,0.673275,0.056370,-64.675301,0.006530,0.000000
10.960001,3.387848,-64.719788,-0.004523,0.000244,0.006209,15.069901,0.767697,0.062093,-64.719788,0.007111,0.000000
11.310000,3.753143,-64.764267,-0.004518,0.000261,0.006626,16.694815,0.850474,0.066256,-64.764267,0.007701,0.000000
11.660001,4.335533,-64.808746,-0.004506,0.000286,0.007259,19.285414,0.982446,0.072587,-64.808746,0.008282,0.000000
12.010000,4.777168,-64.853226,-0.004475,0.000309,0.007840,21.249907,1.082522,0.078397,-64.853226,0.008863,0.000000
12.360001,5.253433,-64.853226,-0.004471,0.000335,0.008516,23.368439,1.190445,0.085162,-64.853226,0.009444,0.000000
12.710001,5.663040,-64.897705,-0.004437,0.000358,0.009097,25.190460,1.283263,0.090972,-64.897705,0.010034,0.000000
13.060000,6.063339,-64.942192,-0.004406,0.000379,0.009635,26.971081,1.373972,0.096349,-64.942192,0.010615,0.000000
13.410001,6.683342,-64.897705,-0.004389,0.000404,0.010251,29.728991,1.514467,0.102506,-64.897705,0.011196,0.000000
13.760000,6.892616,-65.031151,-0.004381,0.000422,0.010710,30.659889,1.561889,0.107102,-65.031151,0.011777,0.000000
14.110001,7.520065,-65.075630,-0.004350,0.000449,0.011404,33.450920,1.704071,0.114040,-65.075630,0.012367,0.000000
14.460001,8.062981,-65.075630,-0.004333,0.000476,0.012080,35.865929,1.827098,0.120805,-65.075630,0.012948,0.000000
14.810000,8.330719,-65.075630,-0.004312,0.000496,0.012592,37.056889,1.887768,0.125921,-65.075630,0.013529,0.000000
15.160001,8.690804,-65.164597,-0.004290,0.000516,0.013112,38.658627,1.969364,0.131125,-65.164597,0.014118,0.000000
15.510001,9.000244,-65.253555,-0.004286,0.000533,0.013546,40.035084,2.039485,0.135461,-65.253555,0.014699,0.000000
15.860001,9.752060,-65.209076,-0.004255,0.000565,0.014361,43.379330,2.209848,0.143613,-65.209076,0.015281,0.000000
16.210001,9.982559,-65.253555,-0.004238,0.000588,0.014925,44.404640,2.262080,0.149250,-65.253555,0.015862,0.000000
16.560001,10.325890,-65.298035,-0.004199,0.000609,0.015480,45.931850,2.339880,0.154800,-65.298035,0.016451,0.000000
16.910002,10.495316,-65.298035,-0.004182,0.000628,0.015940,46.685493,2.378273,0.159396,-65.298035,0.017032,0.000000
17.260000,10.915352,-65.342514,-0.004156,0.000650,0.016503,48.553909,2.473454,0.165033,-65.342514,0.017613,0.000000
17.610001,11.380821,-65.431480,-0.004152,0.000676,0.017171,50.624420,2.578931,0.171711,-65.431480,0.018194,0.000000
17.960001,11.499611,-65.475960,-0.004135,0.000689,0.017509,51.152824,2.605849,0.175093,-65.475960,0.018784,0.000000
18.310001,12.268181,-65.475960,-0.004113,0.000725,0.018420,54.571594,2.780010,0.184199,-65.475960,0.019365,0.000000
18.660002,12.637207,-65.520439,-0.004096,0.000743,0.018862,56.213104,2.863632,0.188622,-65.520439,0.019946,0.000000
19.010000,12.970482,-65.564919,-0.004070,0.000767,0.019487,57.695583,2.939153,0.194866,-65.564919,0.020527,0.000000
19.360001,13.447487,-65.698364,-0.004049,0.000791,0.020094,59.817410,3.047244,0.200936,-65.698364,0.021117,0.000000
19.710001,13.317528,-65.698364,-0.004023,0.000804,0.020423,59.239323,3.017795,0.204232,-65.698364,0.021698,0.000000
20.060001,14.147545,-65.787323,-0.004001,0.000837,0.021256,62.931423,3.205880,0.212557,-65.787323,0.022279,0.000000
20.410002,14.407089,-65.742844,-0.003975,0.000861,0.021871,64.085930,3.264693,0.218714,-65.742844,0.022869,0.000000
20.760000,14.361290,-65.742844,-0.003975,0.000876,0.022244,63.882210,3.254315,0.222443,-65.742844,0.023450,0.000000
21.110001,15.176041,-65.831810,-0.003949,0.000905,0.022981,67.506401,3.438940,0.229815,-65.831810,0.024031,0.000000
21.460001,15.164871,-65.831810,-0.003919,0.000920,0.023363,67.456718,3.436409,0.233631,-65.831810,0.024612,0.000000
21.810001,15.947594,-65.876289,-0.003893,0.000952,0.024187,70.938438,3.613776,0.241869,-65.876289,0.025202,0.000000
22.160002,16.351990,-66.009735,-0.003863,0.000978,0.024837,72.737282,3.705414,0.248373,-66.009735,0.025783,0.000000
22.510000,16.196716,-66.054214,-0.003850,0.000994,0.025236,72.046593,3.670228,0.252363,-66.054214,0.026364,0.000000
22.860001,16.477112,-66.054214,-0.003842,0.001015,0.025783,73.293854,3.733767,0.257826,-66.054214,0.026945,0.000000
23.210001,16.611168,-66.054214,-0.003816,0.001038,0.026364,73.890167,3.764144,0.263637,-66.054214,0.027534,0.000000
23.560001,17.511559,-66.098694,-0.003781,0.001063,0.027005,77.895302,3.968176,0.270054,-66.098694,0.028115,0.000000
23.910002,18.092087,-66.143173,-0.003768,0.001094,0.027786,80.477623,4.099725,0.277859,-66.143173,0.028696,0.000000
24.260000,18.149437,-66.232140,-0.003742,0.001114,0.028298,80.732727,4.112721,0.282976,-66.232140,0.029286,0.000000
24.610001,17.811317,-66.187653,-0.003738,0.001130,0.028696,79.228699,4.036102,0.286965,-66.187653,0.029867,0.000000
24.960001,18.518829,-66.232140,-0.003699,0.001155,0.029347,82.375870,4.196427,0.293469,-66.232140,0.030448,0.000000
25.310001,18.511757,-66.365578,-0.003678,0.001171,0.029737,82.344406,4.194824,0.297372,-66.365578,0.031029,0.000000
25.660002,19.558868,-66.365578,-0.003665,0.001209,0.030708,87.002190,4.432103,0.307085,-66.365578,0.031619,0.000000
26.010002,19.570412,-66.410057,-0.003639,0.001230,0.031246,87.053535,4.434719,0.312461,-66.410057,0.032200,0.000000
26.360001,19.422203,-66.410057,-0.003613,0.001248,0.031697,86.394272,4.401134,0.316971,-66.410057,0.032781,0.000000
26.710001,19.469864,-66.454544,-0.003604,0.001264,0.032113,86.606277,4.411934,0.321134,-66.454544,0.033362,0.000000
27.060001,20.117050,-66.543503,-0.003570,0.001292,0.032807,89.485107,4.558589,0.328071,-66.543503,0.033952,0.000000
27.410002,20.879295,-66.543503,-0.003561,0.001320,0.033536,92.875748,4.731316,0.335356,-66.543503,0.034533,0.000000
27.760002,21.152245,-66.587982,-0.003544,0.001347,0.034212,94.089882,4.793167,0.342121,-66.587982,0.035114,0.000000
28.110001,21.089691,-66.632462,-0.003501,0.001368,0.034750,93.811630,4.778993,0.347497,-66.632462,0.035695,0.000000
28.460001,21.025642,-66.676949,-0.003484,0.001384,0.035149,93.526726,4.764479,0.351487,-66.676949,0.036285,0.000000
28.810001,21.268425,-66.676949,-0.003484,0.001404,0.035652,94.606682,4.819494,0.356516,-66.676949,0.036866,0.000000
29.160002,21.377533,-66.765907,-0.003458,0.001423,0.036146,95.092018,4.844218,0.361460,-66.765907,0.037447,0.000000
29.510002,22.370277,-66.810387,-0.003441,0.001457,0.037013,99.507965,5.069177,0.370132,-66.810387,0.038037,0.000000
29.860001,22.509918,-66.810387,-0.003410,0.001481,0.037620,100.129120,5.100821,0.376202,-66.810387,0.038618,0.000000
30.210001,22.508057,-66.854866,-0.003389,0.001500,0.038106,100.120834,5.100399,0.381059,-66.854866,0.039199,0.000000
30.560001,22.502838,-66.899353,-0.003367,0.001517,0.038540,100.097626,5.099216,0.385395,-66.899353,0.039780,0.000000
30.910002,23.161942,-66.943832,-0.003363,0.001545,0.039251,103.029465,5.248571,0.392506,-66.943832,0.040369,0.000000
31.260002,23.745445,-67.032791,-0.003328,0.001574,0.039979,105.625015,5.380795,0.399791,-67.032791,0.040950,0.000000
31.610001,24.073509,-66.988312,-0.003311,0.001599,0.040612,107.084320,5.455135,0.406122,-66.988312,0.041531,0.000000
31.960001,24.225433,-67.077271,-0.003294,0.001622,0.041202,107.760109,5.489562,0.412019,-67.077271,0.042112,0.000000
32.310001,24.450722,-67.032791,-0.003260,0.001645,0.041783,108.762245,5.540613,0.417829,-67.032791,0.042702,0.000000
32.660000,24.333427,-67.121758,-0.003242,0.001663,0.042251,108.240494,5.514033,0.422512,-67.121758,0.043283,0.000000
33.010002,24.630203,-67.077271,-0.003221,0.001687,0.042850,109.560616,5.581284,0.428496,-67.077271,0.043864,0.000000
33.360001,25.236053,-67.255196,-0.003203,0.001711,0.043457,112.255569,5.718572,0.434567,-67.255196,0.044454,0.000000
33.710003,25.770782,-67.255196,-0.003186,0.001737,0.044124,114.634163,5.839743,0.441244,-67.255196,0.045035,0.000000
34.060001,25.883614,-67.299683,-0.003160,0.001758,0.044662,115.136063,5.865311,0.446621,-67.299683,0.045616,0.000000
34.410000,26.013573,-67.299683,-0.003139,0.001781,0.045226,115.714149,5.894760,0.452258,-67.299683,0.046197,0.000000
34.760002,26.495789,-67.388641,-0.003122,0.001803,0.045807,117.859154,6.004032,0.458069,-67.388641,0.046787,0.000000
35.110001,26.435837,-67.388641,-0.003109,0.001821,0.046249,117.592476,5.990447,0.462491,-67.388641,0.047368,0.000000
35.460003,27.247986,-67.433121,-0.003091,0.001850,0.046995,121.205093,6.174482,0.469950,-67.433121,0.047949,0.000000
35.810001,27.824791,-67.477600,-0.003057,0.001876,0.047645,123.770851,6.305188,0.476454,-67.477600,0.048530,0.000000
36.160000,27.928307,-67.522087,-0.003040,0.001898,0.048200,124.231316,6.328645,0.482004,-67.522087,0.049120,0.000000
36.510002,27.910065,-67.566566,-0.003018,0.001916,0.048660,124.150169,6.324511,0.486600,-67.566566,0.049701,0.000000
36.860001,27.925331,-67.566566,-0.003001,0.001932,0.049068,124.218079,6.327971,0.490676,-67.566566,0.050282,0.000000
37.210003,29.128464,-67.611046,-0.002984,0.001964,0.049883,129.569885,6.600604,0.498828,-67.611046,0.050863,0.000000
37.560001,29.258049,-67.611046,-0.002966,0.001987,0.050464,130.146301,6.629969,0.504639,-67.611046,0.051452,0.000000
37.910004,29.674736,-67.700005,-0.002940,0.002010,0.051054,131.999817,6.724391,0.510536,-67.700005,0.052034,0.000000
38.260002,29.999069,-67.744492,-0.002915,0.002033,0.051643,133.442520,6.797886,0.516433,-67.744492,0.052615,0.000000
38.610001,30.337929,-67.744492,-0.002897,0.002056,0.052216,134.949844,6.874673,0.522157,-67.744492,0.053204,0.000000
38.960003,30.702484,-67.788971,-0.002884,0.002076,0.052719,136.571472,6.957282,0.527187,-67.788971,0.053785,0.000000
39.310001,30.367722,-67.833450,-0.002863,0.002087,0.053022,135.082367,6.881424,0.530222,-67.833450,0.054366,0.000000
39.660004,32.197556,-67.833450,-0.002850,0.002127,0.054028,143.221878,7.296071,0.540282,-67.833450,0.054947,0.000000
40.010002,31.916420,-67.922409,-0.002833,0.002141,0.054392,141.971329,7.232364,0.543924,-67.922409,0.055537,0.000000
40.360001,32.467155,-67.966896,-0.002824,0.002167,0.055051,144.421127,7.357163,0.550515,-67.966896,0.056118,0.000000
40.710003,33.140778,-68.011375,-0.002790,0.002191,0.055659,147.417542,7.509808,0.556585,-68.011375,0.056699,0.000000
41.060001,32.698029,-68.055855,-0.002764,0.002203,0.055953,145.448090,7.409479,0.559534,-68.055855,0.057280,0.000000
41.410004,34.026283,-68.100334,-0.002755,0.002233,0.056725,151.356461,7.710466,0.567252,-68.100334,0.057870,0.000000
41.760002,33.947708,-68.055855,-0.002738,0.002250,0.057141,151.006943,7.692660,0.571415,-68.055855,0.058451,0.000000
42.110001,34.946037,-68.100334,-0.002729,0.002281,0.057939,155.447739,7.918885,0.579394,-68.100334,0.059032,0.000000
42.460003,35.868408,-68.189301,-0.002712,0.002304,0.058520,159.550644,8.127897,0.585204,-68.189301,0.059622,0.000000
42.810001,35.930222,-68.189301,-0.002677,0.002327,0.059101,159.825607,8.141905,0.591014,-68.189301,0.060203,0.000000
43.160004,36.882004,-68.278259,-0.002677,0.002351,0.059717,164.059341,8.357582,0.597172,-68.278259,0.060784,0.000000
43.510002,37.922783,-68.367218,-0.002643,0.002377,0.060385,168.688965,8.593426,0.603849,-68.367218,0.061365,0.000000
43.860001,37.735855,-68.322739,-0.002634,0.002393,0.060775,167.857468,8.551067,0.607752,-68.322739,0.061955,0.000000
44.210003,38.167809,-68.367218,-0.002613,0.002416,0.061365,169.778885,8.648949,0.613649,-68.367218,0.062536,0.000000
44.560001,39.603676,-68.411705,-0.002608,0.002445,0.062093,176.165955,8.974321,0.620934,-68.411705,0.063117,0.000000
44.910004,39.820770,-68.456184,-0.002591,0.002462,0.062527,177.131638,9.023516,0.625270,-68.456184,0.063698,0.000000
45.260002,41.109177,-68.456184,-0.002557,0.002493,0.063325,182.862747,9.315473,0.633248,-68.456184,0.064287,0.000000
45.610001,41.429787,-68.456184,-0.002535,0.002513,0.063828,184.288895,9.388124,0.638278,-68.456184,0.064868,0.000000
45.960003,41.334091,-68.545143,-0.002531,0.002528,0.064218,183.863220,9.366439,0.642181,-68.545143,0.065450,0.000000
46.310001,42.491798,-68.589630,-0.002514,0.002558,0.064964,189.012955,9.628779,0.649639,-68.589630,0.066031,0.000000
46.660004,42.446365,-68.589630,-0.002509,0.002569,0.065259,188.810867,9.618484,0.652587,-68.589630,0.066620,0.000000
47.010002,44.514893,-68.634109,-0.002479,0.002609,0.066256,198.012131,10.087218,0.662560,-68.634109,0.067201,0.000000
47.360001,44.991531,-68.767548,-0.002466,0.002630,0.066794,200.132324,10.195227,0.667937,-68.767548,0.067782,0.000000
47.710003,45.066376,-68.678589,-0.002449,0.002648,0.067253,200.465256,10.212187,0.672534,-68.678589,0.068372,0.000000
48.060001,45.518440,-68.767548,-0.002436,0.002666,0.067704,202.476135,10.314627,0.677043,-68.767548,0.068953,0.000000
48.410004,46.544701,-68.767548,-0.002414,0.002690,0.068329,207.041168,10.547179,0.683287,-68.767548,0.069534,0.000000
48.760002,47.913536,-68.767548,-0.002410,0.002719,0.069057,213.130051,10.857363,0.690572,-68.767548,0.070115,0.000000
49.110001,48.948364,-68.812035,-0.002406,0.002746,0.069751,217.733200,11.091858,0.697510,-68.812035,0.070705,0.000000
49.460003,49.513626,-68.900993,-0.002367,0.002768,0.070297,220.247604,11.219948,0.702973,-68.900993,0.071286,0.000000
49.810001,49.791786,-68.989952,-0.002376,0.002784,0.070714,221.484924,11.282980,0.707136,-68.989952,0.071867,0.000000
50.160004,50.657555,-69.034439,-0.002345,0.002806,0.071277,225.336060,11.479166,0.712773,-69.034439,0.072448,0.000000
50.510002,51.019493,-69.034439,-0.002333,0.002832,0.071928,226.946045,11.561182,0.719277,-69.034439,0.073038,0.000000
50.860001,52.813591,-69.034439,-0.002324,0.002855,0.072517,234.926590,11.967731,0.725174,-69.034439,0.073619,0.000000
51.210003,53.781013,-69.078918,-0.002294,0.002880,0.073142,239.229889,12.186952,0.731418,-69.078918,0.074200,0.000000
51.560001,54.289299,-69.167877,-0.002294,0.002899,0.073636,241.490860,12.302132,0.736361,-69.167877,0.074781,0.000000
51.910004,54.705612,-69.167877,-0.002268,0.002916,0.074061,243.342712,12.396469,0.740611,-69.167877,0.075371,0.000000
52.260002,56.212975,-69.212357,-0.002255,0.002944,0.074772,250.047806,12.738042,0.747722,-69.212357,0.075952,0.000000
52.610001,57.701347,-69.256844,-0.002246,0.002974,0.075535,256.668427,13.075313,0.755354,-69.256844,0.076533,0.000000
52.960003,58.751808,-69.256844,-0.002242,0.002996,0.076108,261.341095,13.313351,0.761077,-69.256844,0.077122,0.000000
53.310001,59.830574,-69.345802,-0.002225,0.003021,0.076732,266.139679,13.557802,0.767321,-69.345802,0.077703,0.000000
53.660004,60.565636,-69.345802,-0.002212,0.003043,0.077304,269.409393,13.724369,0.773045,-69.345802,0.078284,0.000000
54.010002,61.308151,-69.434761,-0.002199,0.003061,0.077747,272.712280,13.892626,0.777468,-69.434761,0.078866,0.000000
54.360004,62.348557,-69.434761,-0.002182,0.003085,0.078363,277.340240,14.128385,0.783625,-69.434761,0.079455,0.000000
54.710003,63.670845,-69.434761,-0.002177,0.003110,0.079004,283.222076,14.428020,0.790043,-69.434761,0.080036,0.000000
55.060001,64.859840,-69.479248,-0.002164,0.003136,0.079663,288.510986,14.697450,0.796634,-69.479248,0.080617,0.000000
55.410004,65.878273,-69.523727,-0.002151,0.003157,0.080192,293.041199,14.928230,0.801924,-69.523727,0.081198,0.000000
55.760002,65.566597,-69.568207,-0.002156,0.003159,0.080227,291.654785,14.857604,0.802271,-69.568207,0.014092,0.000000
56.110004,66.206337,-69.657173,-0.002108,0.003159,0.080227,294.500488,15.002570,0.802271,-69.657173,294.500488,0.000000
56.460003,65.269447,-69.657173,-0.002113,0.003186,0.080912,290.333008,14.790268,0.809122,-69.657173,294.500488,0.000000
56.810001,65.106712,-69.657173,-0.002113,0.003195,0.081164,289.609131,14.753392,0.811637,-69.657173,294.500488,0.000000
57.160004,65.341316,-69.746132,-0.002100,0.003207,0.081467,290.652679,14.806554,0.814672,-69.746132,294.500488,0.000000
57.510002,64.955910,-69.746132,-0.002100,0.003216,0.081675,288.938324,14.719219,0.816753,-69.746132,294.500488,0.000000
57.860004,64.732491,-69.790611,-0.002095,0.003230,0.082048,287.944489,14.668591,0.820482,-69.790611,294.500488,0.000000
58.210003,65.257896,-69.835091,-0.002070,0.003231,0.082074,290.281616,14.787651,0.820742,-69.835091,294.500488,0.000000
58.560001,66.561211,-69.835091,-0.002065,0.003202,0.081328,296.079041,15.082986,0.813284,-69.835091,294.500488,0.000000
58.910004,65.525642,-69.968536,-0.002070,0.003215,0.081649,291.472626,14.848323,0.816493,-69.968536,294.500488,0.000000
59.260002,65.282845,-69.924057,-0.002057,0.003258,0.082742,290.392609,14.793304,0.827420,-69.924057,294.500488,0.000000
59.610004,65.194221,-70.013016,-0.002057,0.003266,0.082967,289.998383,14.773222,0.829675,-70.013016,294.500488,0.000000
59.960003,65.265343,-70.013016,-0.002048,0.003275,0.083176,290.314758,14.789338,0.831756,-70.013016,294.500488,0.000000
60.310001,65.135765,-70.013016,-0.002039,0.003282,0.083358,289.738342,14.759975,0.833577,-70.013016,294.500488,0.000000
60.660004,65.386375,-70.101982,-0.002039,0.003290,0.083557,290.853119,14.816764,0.835572,-70.101982,294.500488,0.000000
61.010002,65.461220,-70.190941,-0.002048,0.003297,0.083739,291.186035,14.833725,0.837393,-70.190941,294.500488,0.000000
61.360004,65.246727,-70.190941,-0.002031,0.003301,0.083852,290.231934,14.785120,0.838521,-70.190941,294.500488,0.000000
61.710003,65.253441,-70.190941,-0.002031,0.003307,0.084008,290.261810,14.786641,0.840082,-70.190941,294.500488,0.000000
62.060001,65.068733,-70.235420,-0.002013,0.003312,0.084130,289.440186,14.744785,0.841296,-70.235420,294.500488,0.000000
62.410004,64.967079,-70.279900,-0.002026,0.003316,0.084216,288.988007,14.721750,0.842163,-70.279900,294.500488,0.000000
62.760002,65.572563,-70.324387,-0.002009,0.003324,0.084433,291.681335,14.858955,0.844331,-70.324387,294.500488,0.000000
63.110004,65.001335,-70.324387,-0.002013,0.003328,0.084520,289.140381,14.729513,0.845198,-70.324387,294.500488,0.000000
63.460003,65.089211,-70.413345,-0.002022,0.003333,0.084650,289.531281,14.749426,0.846499,-70.413345,294.500488,0.000000
63.810001,65.480583,-70.413345,-0.002001,0.003342,0.084884,291.272186,14.838112,0.848841,-70.413345,294.500488,0.000000
64.160004,65.075813,-70.502304,-0.002005,0.003342,0.084884,289.471680,14.746390,0.848841,-70.502304,294.500488,0.000000
64.510002,64.975639,-70.546791,-0.001988,0.003346,0.084988,289.026093,14.723690,0.849881,-70.546791,294.500488,0.000000
64.860001,65.502922,-70.635750,-0.001996,0.003356,0.085231,291.371552,14.843175,0.852309,-70.635750,294.500488,0.000000
65.210007,65.108574,-70.591270,-0.001996,0.003359,0.085326,289.617401,14.753814,0.853263,-70.591270,294.500488,0.000000
65.560005,65.233696,-70.591270,-0.001996,0.003362,0.085387,290.173981,14.782166,0.853870,-70.591270,294.500488,0.000000
65.910004,65.293648,-70.680229,-0.001996,0.003367,0.085526,290.440643,14.795753,0.855258,-70.680229,294.500488,0.000000
66.260002,65.444466,-70.680229,-0.001983,0.003373,0.085673,291.111511,14.829928,0.856732,-70.680229,294.500488,0.000000
66.610001,65.193489,-70.724709,-0.001988,0.003375,0.085725,289.995117,14.773055,0.857253,-70.724709,294.500488,0.000000
66.960007,65.119759,-70.724709,-0.001979,0.003379,0.085821,289.667145,14.756349,0.858207,-70.724709,294.500488,0.000000
67.310005,65.222160,-70.769196,-0.001966,0.003384,0.085951,290.122650,14.779552,0.859507,-70.769196,294.500488,0.000000
67.660004,65.271675,-70.813675,-0.001970,0.003388,0.086046,290.342926,14.790773,0.860461,-70.813675,294.500488,0.000000
68.010002,65.156990,-70.858154,-0.001975,0.003392,0.086150,289.832764,14.764785,0.861502,-70.858154,294.500488,0.000000
68.360001,65.270943,-70.947121,-0.001966,0.003395,0.086246,290.339661,14.790606,0.862456,-70.947121,294.500488,0.000000
68.710007,65.228493,-70.991600,-0.001975,0.003398,0.086315,290.150818,14.780988,0.863150,-70.991600,294.500488,0.000000
69.060005,65.255669,-70.947121,-0.001975,0.003402,0.086402,290.271698,14.787147,0.864017,-70.947121,294.500488,0.000000
69.410004,65.197945,-71.036079,-0.001962,0.003404,0.086471,290.014954,14.774065,0.864711,-71.036079,294.500488,0.000000
69.760002,65.356956,-71.125038,-0.001966,0.003410,0.086619,290.722260,14.810098,0.866185,-71.125038,294.500488,0.000000
70.110001,65.187523,-71.080559,-0.001962,0.003411,0.086636,289.968597,14.771704,0.866359,-71.080559,294.500488,0.000000
70.460007,65.390846,-71.169525,-0.001944,0.003416,0.086766,290.873016,14.817778,0.867659,-71.169525,294.500488,0.000000
70.810005,65.233696,-71.169525,-0.001949,0.003418,0.086818,290.173981,14.782166,0.868180,-71.169525,294.500488,0.000000
71.160004,65.282845,-71.214005,-0.001944,0.003422,0.086922,290.392609,14.793304,0.869220,-71.214005,294.500488,0.000000
71.510002,65.155495,-71.214005,-0.001932,0.003423,0.086948,289.826111,14.764446,0.869480,-71.214005,294.500488,0.000000
71.860001,65.313011,-71.258484,-0.001949,0.003428,0.087078,290.526794,14.800140,0.870781,-71.258484,294.500488,0.000000
72.210007,65.168907,-71.347443,-0.001957,0.003429,0.087104,289.885773,14.767486,0.871042,-71.347443,294.500488,0.000000
72.560005,65.139854,-71.347443,-0.001944,0.003431,0.087148,289.756531,14.760902,0.871475,-71.347443,294.500488,0.000000
72.910004,65.285454,-71.302963,-0.001936,0.003435,0.087252,290.404205,14.793895,0.872516,-71.302963,294.500488,0.000000
73.260002,65.138741,-71.391930,-0.001949,0.003439,0.087338,289.751587,14.760650,0.873383,-71.391930,294.500488,0.000000
73.610001,65.162575,-71.480888,-0.001940,0.003439,0.087356,289.857605,14.766050,0.873556,-71.480888,294.500488,0.000000
73.960007,65.298866,-71.480888,-0.001940,0.003444,0.087468,290.463867,14.796934,0.874684,-71.480888,294.500488,0.000000
74.310005,65.097786,-71.525368,-0.001927,0.003444,0.087468,289.569427,14.751369,0.874684,-71.525368,294.500488,0.000000
74.660004,65.066872,-71.658813,-0.001944,0.003446,0.087538,289.431915,14.744364,0.875378,-71.658813,294.500488,0.000000
75.010002,65.295143,-71.614334,-0.001936,0.003451,0.087659,290.447296,14.796091,0.876592,-71.614334,294.500488,0.000000
75.360001,65.213966,-71.703293,-0.001940,0.003454,0.087720,290.086212,14.777697,0.877199,-71.703293,294.500488,0.000000
75.710007,65.188637,-71.703293,-0.001940,0.003455,0.087755,289.973541,14.771956,0.877546,-71.703293,294.500488,0.000000
76.060005,65.266838,-71.747772,-0.001927,0.003458,0.087833,290.321381,14.789678,0.878326,-71.747772,294.500488,0.000000
76.410004,65.242256,-71.792252,-0.001927,0.003460,0.087876,290.212036,14.784107,0.878760,-71.792252,294.500488,0.000000
76.760002,65.157356,-71.792252,-0.001919,0.003461,0.087911,289.834381,14.764868,0.879107,-71.792252,294.500488,0.000000
77.110001,65.095177,-71.836739,-0.001932,0.003464,0.087980,289.557800,14.750778,0.879800,-71.836739,294.500488,0.000000
77.460007,65.025536,-71.925697,-0.001927,0.003464,0.087980,289.248016,14.734997,0.879800,-71.925697,294.500488,0.000000
77.810005,65.340569,-71.970177,-0.001919,0.003470,0.088127,290.649353,14.806384,0.881275,-71.970177,294.500488,0.000000
78.160004,65.199440,-71.970177,-0.001919,0.003470,0.088127,290.021606,14.774405,0.881275,-71.970177,294.500488,0.000000
78.510002,65.117897,-72.059143,-0.001910,0.003471,0.088171,289.658875,14.755926,0.881708,-72.059143,294.500488,0.000000
78.860001,65.074699,-72.014656,-0.001910,0.003473,0.088223,289.466705,14.746138,0.882229,-72.014656,294.500488,0.000000
79.210007,65.333488,-72.103622,-0.001914,0.003478,0.088336,290.617859,14.804780,0.883356,-72.103622,294.500488,0.000000
79.560005,65.193489,-72.059143,-0.001906,0.003478,0.088336,289.995117,14.773055,0.883356,-72.059143,294.500488,0.000000
79.910004,65.058678,-72.192581,-0.001914,0.003480,0.088388,289.395447,14.742507,0.883876,-72.192581,294.500488,0.000000
80.260002,65.179329,-72.192581,-0.001901,0.003482,0.088431,289.932129,14.769847,0.884310,-72.192581,294.500488,0.000000
80.610001,65.012505,-72.237068,-0.001914,0.003482,0.088431,289.190063,14.732044,0.884310,-72.237068,294.500488,0.000000
80.960007,65.145073,-72.326027,-0.001923,0.003486,0.088552,289.779755,14.762084,0.885524,-72.326027,294.500488,0.000000
81.310005,65.050117,-72.370506,-0.001901,0.003486,0.088552,289.357361,14.740567,0.885524,-72.370506,294.500488,0.000000
81.660004,64.914207,-72.370506,-0.001893,0.003486,0.088552,288.752808,14.709770,0.885524,-72.370506,294.500488,0.000000
82.010002,64.745140,-72.370506,-0.001914,0.003486,0.088552,288.000763,14.671458,0.885524,-72.370506,294.500488,0.000000
82.360001,65.671242,-72.459473,-0.001901,0.003498,0.088847,292.120270,14.881316,0.888473,-72.459473,294.500488,0.000000
82.710007,65.566978,-72.459473,-0.001893,0.003498,0.088847,291.656494,14.857690,0.888473,-72.459473,294.500488,0.000000
83.060005,65.428444,-72.503952,-0.001901,0.003498,0.088847,291.040253,14.826298,0.888473,-72.503952,294.500488,0.000000
83.410004,65.264610,-72.548431,-0.001897,0.003498,0.088856,290.311493,14.789172,0.888559,-72.548431,294.500488,0.000000
83.760002,65.117516,-72.503952,-0.001901,0.003499,0.088865,289.657166,14.755840,0.888646,-72.503952,294.500488,0.000000
84.110001,64.974525,-72.592911,-0.001901,0.003499,0.088865,289.021118,14.723438,0.888646,-72.592911,294.500488,0.000000
84.460007,64.812920,-72.637390,-0.001901,0.003499,0.088865,288.302277,14.686818,0.888646,-72.637390,294.500488,0.000000
84.810005,64.648323,-72.681877,-0.001897,0.003499,0.088865,287.570099,14.649519,0.888646,-72.681877,294.500488,0.000000
85.160004,66.062233,-72.726357,-0.001901,0.003506,0.089055,293.859497,14.969916,0.890554,-72.726357,294.500488,0.000000
85.510002,65.825768,-72.770836,-0.001897,0.003506,0.089047,292.807648,14.916332,0.890467,-72.770836,294.500488,0.000000
85.860001,65.710701,-72.770836,-0.001893,0.003506,0.089047,292.295807,14.890258,0.890467,-72.770836,294.500488,0.000000
86.210007,65.523399,-72.815315,-0.001880,0.003506,0.089055,291.462646,14.847815,0.890554,-72.815315,294.500488,0.000000
86.560005,65.319710,-72.859795,-0.001893,0.003506,0.089055,290.556580,14.801658,0.890554,-72.859795,294.500488,0.000000
86.910004,65.153633,-72.859795,-0.001871,0.003506,0.089055,289.817841,14.764025,0.890554,-72.859795,294.500488,0.000000
87.260002,65.775505,-72.948761,-0.001871,0.003520,0.089402,292.584045,14.904942,0.894023,-72.948761,294.500488,0.000000
87.610001,65.611290,-72.948761,-0.001893,0.003520,0.089402,291.853607,14.867730,0.894023,-72.948761,294.500488,0.000000
87.960007,65.479469,-73.037720,-0.001888,0.003520,0.089402,291.267212,14.837860,0.894023,-73.037720,294.500488,0.000000
88.310005,65.312645,-73.037720,-0.001880,0.003520,0.089402,290.525146,14.800056,0.894023,-73.037720,294.500488,0.000000
88.660004,65.178963,-73.082199,-0.001893,0.003520,0.089411,289.930511,14.769765,0.894110,-73.082199,294.500488,0.000000
89.010002,65.019218,-73.126686,-0.001884,0.003520,0.089411,289.219940,14.733565,0.894110,-73.126686,294.500488,0.000000
89.360001,64.893715,-73.171165,-0.001880,0.003520,0.089411,288.661652,14.705127,0.894110,-73.171165,294.500488,0.000000
89.710007,64.743660,-73.215645,-0.001876,0.003520,0.089411,287.994171,14.671123,0.894110,-73.215645,294.500488,0.000000
90.060005,64.599541,-73.260124,-0.001888,0.003520,0.089411,287.353119,14.638466,0.894110,-73.260124,294.500488,0.000000
90.410004,64.462883,-73.349091,-0.001880,0.003520,0.089411,286.745239,14.607498,0.894110,-73.349091,294.500488,0.000000
90.760002,66.376137,-73.304604,-0.001876,0.003505,0.089038,295.255798,15.041047,0.890381,-73.304604,294.500488,0.000000
91.110001,66.192558,-73.349091,-0.001863,0.003505,0.089038,294.439209,14.999449,0.890381,-73.349091,294.500488,0.000000
91.460007,66.031700,-73.393570,-0.001880,0.003505,0.089038,293.723663,14.962997,0.890381,-73.393570,294.500488,0.000000
91.810005,65.829124,-73.482529,-0.001867,0.003506,0.089047,292.822571,14.917092,0.890467,-73.482529,294.500488,0.000000
92.160004,65.753532,-73.438049,-0.001863,0.003506,0.089047,292.486328,14.899963,0.890467,-73.438049,294.500488,0.000000
92.510002,65.576286,-73.482529,-0.001863,0.003508,0.089107,291.697876,14.859798,0.891074,-73.482529,294.500488,0.000000
92.860001,65.440361,-73.527016,-0.001871,0.003509,0.089133,291.093262,14.828998,0.891335,-73.527016,294.500488,0.000000
93.210007,65.359566,-73.571495,-0.001867,0.003526,0.089558,290.733856,14.810689,0.895584,-73.571495,294.500488,0.000000
93.560005,65.259758,-73.660454,-0.001867,0.003528,0.089610,290.289886,14.788073,0.896104,-73.660454,294.500488,0.000000
93.910004,65.181572,-73.704933,-0.001863,0.003534,0.089767,289.942108,14.770355,0.897665,-73.704933,294.500488,0.000000
94.260002,65.197945,-73.704933,-0.001867,0.003539,0.089897,290.014954,14.774065,0.898966,-73.704933,294.500488,0.000000
94.610008,65.136513,-73.704933,-0.001876,0.003540,0.089905,289.741669,14.760145,0.899053,-73.704933,294.500488,0.000000
94.960007,65.031502,-73.838379,-0.001867,0.003540,0.089914,289.274567,14.736349,0.899140,-73.838379,294.500488,0.000000
95.310005,65.136879,-73.749420,-0.001871,0.003544,0.090009,289.743317,14.760228,0.900094,-73.749420,294.500488,0.000000
95.660004,65.093315,-73.838379,-0.001876,0.003544,0.090009,289.549530,14.750356,0.900094,-73.838379,294.500488,0.000000
96.010002,65.063530,-73.838379,-0.001863,0.003545,0.090044,289.417023,14.743607,0.900440,-73.838379,294.500488,0.000000
96.360008,65.081032,-73.838379,-0.001884,0.003547,0.090096,289.494873,14.747572,0.900961,-73.838379,294.500488,0.000000
96.710007,65.034859,-73.927338,-0.001880,0.003547,0.090105,289.289490,14.737109,0.901048,-73.927338,294.500488,0.000000
97.060005,65.523399,-73.971825,-0.001858,0.003554,0.090261,291.462646,14.847815,0.902609,-73.971825,294.500488,0.000000
97.410004,65.424355,-74.016304,-0.001863,0.003553,0.090252,291.022064,14.825371,0.902522,-74.016304,294.500488,0.000000
97.760002,65.317848,-74.060783,-0.001863,0.003553,0.090252,290.548309,14.801236,0.902522,-74.060783,294.500488,0.000000
98.110008,65.236305,-74.105263,-0.001863,0.003554,0.090261,290.185577,14.782759,0.902609,-74.105263,294.500488,0.000000
98.460007,65.140236,-74.060783,-0.001871,0.003554,0.090270,289.758240,14.760988,0.902695,-74.060783,294.500488,0.000000
98.810005,65.245613,-74.194229,-0.001871,0.003557,0.090339,290.226990,14.784867,0.903389,-74.194229,294.500488,0.000000
99.160004,65.186409,-74.149742,-0.001867,0.003557,0.090339,289.963623,14.771451,0.903389,-74.149742,294.500488,0.000000
99.510002,65.145821,-74.194229,-0.001858,0.003559,0.090400,289.783081,14.762254,0.903996,-74.194229,294.500488,0.000000
99.860008,65.173744,-74.283188,-0.001863,0.003559,0.090408,289.907288,14.768581,0.904083,-74.283188,294.500488,0.000000
100.210007,65.130928,-74.238708,-0.001871,0.003561,0.090452,289.716827,14.758880,0.904516,-74.238708,294.500488,0.000000
100.560005,65.213585,-74.327667,-0.001858,0.003562,0.090478,290.084503,14.777609,0.904777,-74.327667,294.500488,0.000000
100.910004,65.210991,-74.327667,-0.001858,0.003564,0.090521,290.072968,14.777021,0.905210,-74.327667,294.500488,0.000000
101.260002,65.204659,-74.416634,-0.001854,0.003564,0.090521,290.044800,14.775586,0.905210,-74.416634,294.500488,0.000000
101.610008,65.181190,-74.461113,-0.001863,0.003566,0.090573,289.940430,14.770268,0.905730,-74.461113,294.500488,0.000000
101.960007,65.221413,-74.461113,-0.001863,0.003566,0.090573,290.119324,14.779383,0.905730,-74.461113,294.500488,0.000000
102.310005,65.171883,-74.505592,-0.001854,0.003567,0.090608,289.899017,14.768160,0.906077,-74.505592,294.500488,0.000000
102.660004,65.161461,-74.550072,-0.001867,0.003567,0.090608,289.852661,14.765799,0.906077,-74.550072,294.500488,0.000000
103.010002,65.098900,-74.550072,-0.001854,0.003568,0.090625,289.574371,14.751621,0.906251,-74.550072,294.500488,0.000000
103.360008,65.186775,-74.594559,-0.001845,0.003570,0.090686,289.965271,14.771534,0.906858,-74.594559,294.500488,0.000000
103.710007,65.147301,-74.639038,-0.001858,0.003570,0.090686,289.789673,14.762589,0.906858,-74.639038,294.500488,0.000000
104.060005,65.077675,-74.639038,-0.001850,0.003570,0.090686,289.479950,14.746812,0.906858,-74.639038,294.500488,0.000000
104.410004,65.264229,-74.639038,-0.001863,0.003574,0.090781,290.309784,14.789085,0.907812,-74.639038,294.500488,0.000000
104.760002,65.263115,-74.683517,-0.001863,0.003574,0.090781,290.304840,14.788833,0.907812,-74.683517,294.500488,0.000000
105.110008,65.199440,-74.772476,-0.001850,0.003574,0.090781,290.021606,14.774405,0.907812,-74.772476,294.500488,0.000000
105.460007,65.129066,-74.816963,-0.001841,0.003574,0.090781,289.708557,14.758457,0.907812,-74.816963,294.500488,0.000000
105.810005,65.387489,-74.861443,-0.001850,0.003579,0.090903,290.858093,14.817017,0.909026,-74.861443,294.500488,0.000000
106.160004,65.363289,-74.905922,-0.001850,0.003579,0.090903,290.750427,14.811533,0.909026,-74.905922,294.500488,0.000000
106.510002,65.292534,-74.861443,-0.001850,0.003579,0.090903,290.435699,14.795500,0.909026,-74.861443,294.500488,0.000000
106.860008,65.245613,-74.994881,-0.001845,0.003579,0.090903,290.226990,14.784867,0.909026,-74.994881,294.500488,0.000000
107.210007,65.195351,-75.083847,-0.001854,0.003580,0.090920,290.003418,14.773478,0.909199,-75.083847,294.500488,0.000000
107.560005,65.310402,-74.994881,-0.001841,0.003583,0.090998,290.515167,14.799548,0.909980,-74.994881,294.500488,0.000000
107.910004,65.295891,-75.039368,-0.001854,0.003583,0.090998,290.450623,14.796261,0.909980,-75.039368,294.500488,0.000000
108.260002,65.232216,-75.128326,-0.001841,0.003583,0.090998,290.167389,14.781832,0.909980,-75.128326,294.500488,0.000000
108.610008,65.177849,-75.172806,-0.001845,0.003583,0.091007,289.925537,14.769512,0.910067,-75.172806,294.500488,0.000000
108.960007,65.262001,-75.128326,-0.001850,0.003585,0.091059,290.299866,14.788581,0.910587,-75.128326,294.500488,0.000000
109.310005,65.228859,-75.217285,-0.001854,0.003586,0.091076,290.152466,14.781071,0.910760,-75.217285,294.500488,0.000000
109.660004,65.187889,-75.261772,-0.001845,0.003586,0.091076,289.970215,14.771787,0.910760,-75.261772,294.500488,0.000000
110.010002,65.149178,-75.306252,-0.001850,0.003587,0.091119,289.798004,14.763015,0.911194,-75.306252,294.500488,0.000000
110.360008,65.181572,-75.350731,-0.001850,0.003588,0.091128,289.942108,14.770355,0.911281,-75.350731,294.500488,0.000000
110.710007,65.172997,-75.350731,-0.001845,0.003589,0.091171,289.903961,14.768412,0.911714,-75.350731,294.500488,0.000000
111.060005,65.198692,-75.395210,-0.001832,0.003589,0.091171,290.018280,14.774235,0.911714,-75.395210,294.500488,0.000000
111.410004,65.131294,-75.439690,-0.001837,0.003589,0.091171,289.718475,14.758963,0.911714,-75.439690,294.500488,0.000000
111.760002,65.082893,-75.484177,-0.001828,0.003589,0.091171,289.503174,14.747994,0.911714,-75.484177,294.500488,0.000000
112.110008,65.111565,-75.484177,-0.001863,0.003592,0.091232,289.630707,14.754492,0.912321,-75.484177,294.500488,0.000000
112.460007,65.130928,-75.573135,-0.001850,0.003592,0.091241,289.716827,14.758880,0.912408,-75.573135,294.500488,0.000000
112.810005,65.075447,-75.573135,-0.001832,0.003592,0.091249,289.470032,14.746306,0.912495,-75.573135,294.500488,0.000000
113.160004,65.062782,-75.617615,-0.001845,0.003593,0.091267,289.413696,14.743437,0.912668,-75.617615,294.500488,0.000000
113.510002,65.036720,-75.662094,-0.001837,0.003593,0.091267,289.297791,14.737532,0.912668,-75.662094,294.500488,0.000000
113.860008,65.214333,-75.706581,-0.001828,0.003596,0.091345,290.087830,14.777779,0.913449,-75.706581,294.500488,0.000000
114.210007,65.187157,-75.751060,-0.001824,0.003596,0.091345,289.966949,14.771621,0.913449,-75.751060,294.500488,0.000000
114.560005,65.145821,-75.795540,-0.001850,0.003596,0.091345,289.783081,14.762254,0.913449,-75.795540,294.500488,0.000000
114.910004,65.084373,-75.840019,-0.001832,0.003597,0.091362,289.509766,14.748329,0.913622,-75.840019,294.500488,0.000000
115.260002,65.047890,-75.840019,-0.001832,0.003597,0.091362,289.347473,14.740063,0.913622,-75.840019,294.500488,0.000000
115.610008,65.054222,-75.884506,-0.001841,0.003599,0.091406,289.375641,14.741497,0.914056,-75.884506,294.500488,0.000000
115.960007,65.042671,-75.884506,-0.001841,0.003599,0.091406,289.324249,14.738880,0.914056,-75.884506,294.500488,0.000000
116.310005,65.002083,-76.017944,-0.001845,0.003595,0.091319,289.143707,14.729683,0.913189,-76.017944,0.091414,0.000000
116.660004,64.850899,-75.973465,-0.001832,0.003586,0.091093,288.471191,14.695423,0.910934,-75.973465,0.090894,0.000000
117.010002,64.721321,-76.062424,-0.001824,0.003570,0.090677,287.894806,14.666060,0.906771,-76.062424,0.090313,0.000000
117.360008,64.536247,-76.106911,-0.001815,0.003548,0.090113,287.071564,14.624123,0.901134,-76.106911,0.089723,0.000000
117.710007,64.376869,-76.062424,-0.001828,0.003528,0.089619,286.362610,14.588008,0.896191,-76.062424,0.089142,0.000000
118.060005,64.346336,-76.151390,-0.001815,0.003511,0.089168,286.226807,14.581088,0.891681,-76.151390,0.088561,0.000000
118.410004,64.281548,-76.151390,-0.001824,0.003479,0.088370,285.938599,14.566407,0.883703,-76.151390,0.087971,0.000000
118.760002,64.130363,-76.240349,-0.001832,0.003459,0.087850,285.266113,14.532148,0.878500,-76.240349,0.087390,0.000000
119.110008,64.043221,-76.195869,-0.001824,0.003439,0.087338,284.878479,14.512402,0.873383,-76.195869,0.086809,0.000000
119.460007,63.969490,-76.284828,-0.001819,0.003423,0.086939,284.550507,14.495694,0.869394,-76.284828,0.086228,0.000000
119.810005,63.774742,-76.329315,-0.001819,0.003396,0.086254,283.684235,14.451564,0.862543,-76.329315,0.085639,0.000000
120.160004,63.552437,-76.329315,-0.001815,0.003376,0.085760,282.695343,14.401188,0.857600,-76.329315,0.085057,0.000000
120.510002,62.774925,-76.373795,-0.001811,0.003351,0.085118,279.236816,14.225001,0.851182,-76.373795,0.084476,0.000000
120.860008,61.984749,-76.418274,-0.001819,0.003333,0.084650,275.721924,14.045944,0.846499,-76.418274,0.083895,0.000000
121.210007,60.835983,-76.418274,-0.001798,0.003308,0.084026,270.611969,13.785631,0.840255,-76.418274,0.083306,0.000000
121.560005,59.571404,-76.507233,-0.001785,0.003287,0.083488,264.986847,13.499073,0.834878,-76.507233,0.082725,0.000000
121.910004,58.411461,-76.507233,-0.001794,0.003269,0.083037,259.827148,13.236226,0.830369,-76.507233,0.082144,0.000000
122.260002,56.689240,-76.551720,-0.001794,0.003244,0.082404,252.166336,12.845965,0.824038,-76.551720,0.081563,0.000000
122.610008,54.831848,-76.640678,-0.001794,0.003222,0.081831,243.904236,12.425075,0.818314,-76.640678,0.080973,0.000000
122.960007,53.013550,-76.596199,-0.001781,0.003201,0.081311,235.816040,12.013042,0.813111,-76.596199,0.080392,0.000000
123.310005,51.257072,-76.685158,-0.001798,0.003184,0.080869,228.002838,11.615019,0.808688,-76.685158,0.079811,0.000000
123.660004,49.030281,-76.729637,-0.001789,0.003158,0.080210,218.097580,11.110421,0.802097,-76.729637,0.079221,0.000000
124.010002,46.497406,-76.774124,-0.001781,0.003138,0.079707,206.830795,10.536463,0.797067,-76.774124,0.078640,0.000000
124.360008,43.490868,-76.774124,-0.001794,0.003106,0.078900,193.457047,9.855171,0.789002,-76.774124,0.078059,0.000000
124.710007,41.192589,-76.863083,-0.001794,0.003088,0.078423,183.233780,9.334373,0.784232,-76.863083,0.077478,0.000000
125.060005,39.688950,-76.863083,-0.001789,0.003075,0.078094,176.545258,8.993645,0.780937,-76.863083,0.076888,0.000000
125.410004,36.329773,-76.907562,-0.001811,0.003039,0.077200,161.602905,8.232444,0.772004,-76.907562,0.076307,0.000000
125.760010,34.647766,-76.818604,-0.001794,0.003027,0.076897,154.120956,7.851296,0.768969,-76.818604,0.075726,0.000000
126.110008,31.878433,-76.907562,-0.001794,0.002998,0.076142,141.802353,7.223756,0.761424,-76.907562,0.075145,0.000000
126.460007,29.287468,-77.041008,-0.001794,0.002975,0.075570,130.277161,6.636635,0.755700,-77.041008,0.074555,0.000000
126.810005,27.281494,-76.996529,-0.001794,0.002957,0.075102,121.354149,6.182075,0.751018,-76.996529,0.073974,0.000000
127.160004,24.514771,-76.996529,-0.001802,0.002928,0.074373,109.047142,5.555126,0.743733,-76.996529,0.073393,0.000000
127.510010,21.850815,-77.174454,-0.001789,0.002904,0.073766,97.197281,4.951466,0.737662,-77.174454,0.072804,0.000000
127.860008,19.880966,-77.218933,-0.001785,0.002888,0.073350,88.434952,4.505091,0.733500,-77.218933,0.072223,0.000000
128.210007,16.633507,-77.129967,-0.001789,0.002856,0.072535,73.989532,3.769207,0.725348,-77.129967,0.071642,0.000000
128.560013,14.647644,-77.174454,-0.001798,0.002838,0.072075,65.155975,3.319204,0.720751,-77.174454,0.071060,0.000000
128.910004,12.363884,-77.263412,-0.001794,0.002814,0.071468,54.997303,2.801696,0.714681,-77.263412,0.070471,0.000000
129.260010,10.183640,-77.263412,-0.001807,0.002793,0.070939,45.299091,2.307646,0.709391,-77.263412,0.069890,0.000000
129.610001,7.672363,-77.263412,-0.001798,0.002770,0.070349,34.128376,1.738582,0.703494,-77.263412,0.069309,0.000000
129.960007,6.030571,-77.396858,-0.001819,0.002754,0.069950,26.825319,1.366547,0.699504,-77.396858,0.068728,0.000000
130.310013,2.960732,-77.396858,-0.001807,0.002721,0.069118,13.169991,0.670911,0.691179,-77.396858,0.068138,0.000000
130.660004,0.713837,-77.485817,-0.001811,0.002700,0.068572,3.175304,0.161758,0.685715,-77.485817,0.067557,0.000000
131.010010,-1.258617,-77.485817,-0.001828,0.002677,0.067999,-5.598610,-0.285207,0.679992,-77.485817,0.066976,0.000000
131.360001,-3.255280,-77.530296,-0.001828,0.002658,0.067514,-14.480206,-0.737657,0.675135,-77.530296,0.066395,0.000000
131.710007,-5.336098,-77.530296,-0.001832,0.002634,0.066915,-23.736149,-1.209177,0.669151,-77.530296,0.065805,0.000000
132.060013,-0.327690,-77.530296,-0.001901,0.002607,0.066213,-1.457639,-0.074256,0.662127,-77.530296,0.065224,0.000000
132.410004,-0.020103,-77.574776,-0.001893,0.002583,0.065614,-0.089425,-0.004556,0.656143,-77.574776,0.064643,0.000000
132.760010,-0.055107,-77.619263,-0.001901,0.002563,0.065094,-0.245129,-0.012487,0.650940,-77.619263,0.064053,0.000000
133.110001,-0.041702,-77.663742,-0.001944,0.002534,0.064365,-0.185501,-0.009450,0.643655,-77.663742,0.063472,0.000000
133.460007,-0.029419,-77.663742,-0.001962,0.002515,0.063880,-0.130862,-0.006666,0.638798,-77.663742,0.062891,0.000000
133.810013,-0.020477,-77.797180,-0.001970,0.002497,0.063429,-0.091088,-0.004640,0.634289,-77.797180,0.062310,0.000000
134.160004,0.010429,-77.797180,-0.001992,0.002464,0.062579,0.046392,0.002363,0.625790,-77.797180,0.061720,0.000000
134.510010,-0.011543,-77.841667,-0.001996,0.002449,0.062206,-0.051347,-0.002616,0.622061,-77.841667,0.061139,0.000000
134.860001,-0.001114,-77.841667,-0.002022,0.002420,0.061469,-0.004955,-0.000252,0.614690,-77.841667,0.060558,0.000000
135.210007,0.015640,-77.841667,-0.002022,0.002397,0.060879,0.069571,0.003544,0.608792,-77.841667,0.059977,0.000000
135.560013,0.001862,-77.930626,-0.002048,0.002380,0.060446,0.008281,0.000422,0.604456,-77.930626,0.059388,0.000000
135.910004,-0.011169,-77.930626,-0.002078,0.002352,0.059752,-0.049684,-0.002531,0.597519,-77.930626,0.058807,0.000000
136.260010,-0.008934,-78.019585,-0.002104,0.002328,0.059119,-0.039741,-0.002024,0.591188,-78.019585,0.058226,0.000000
136.610001,-0.024200,-78.019585,-0.002100,0.002307,0.058598,-0.107649,-0.005484,0.585984,-78.019585,0.057636,0.000000
136.960007,-0.005585,-78.064072,-0.002121,0.002294,0.058260,-0.024842,-0.001266,0.582602,-78.064072,0.057055,0.000000
137.310013,-0.005959,-78.108551,-0.002126,0.002267,0.057584,-0.026505,-0.001350,0.575838,-78.108551,0.056474,0.000000
137.660004,-0.014893,-78.108551,-0.002156,0.002242,0.056959,-0.066245,-0.003375,0.569594,-78.108551,0.055893,0.000000
138.010010,-0.017128,-78.153030,-0.002177,0.002212,0.056188,-0.076189,-0.003881,0.561876,-78.153030,0.055303,0.000000
138.360001,-0.025696,-78.241989,-0.002190,0.002193,0.055711,-0.114301,-0.005823,0.557106,-78.241989,0.054722,0.000000
138.710007,-0.014893,-78.241989,-0.002225,0.002168,0.055060,-0.066245,-0.003375,0.550602,-78.241989,0.054141,0.000000
139.060013,-0.000000,-78.286476,-0.002242,0.002145,0.054488,-0.000000,-0.000000,0.544878,-78.286476,0.053560,0.000000
139.410004,-0.023087,-78.330956,-0.002268,0.002126,0.053993,-0.102694,-0.005231,0.539935,-78.330956,0.052970,0.000000
139.760010,-0.029045,-78.286476,-0.002285,0.002097,0.053256,-0.129199,-0.006582,0.532563,-78.286476,0.052389,0.000000
140.110001,-0.039467,-78.375435,-0.002315,0.002071,0.052615,-0.175557,-0.008943,0.526146,-78.375435,0.051808,0.000000
140.460007,-0.014893,-78.419914,-0.002320,0.002051,0.052103,-0.066245,-0.003375,0.521029,-78.419914,0.051227,0.000000
140.810013,-0.009682,-78.464401,-0.002350,0.002031,0.051591,-0.043066,-0.002194,0.515913,-78.464401,0.050637,0.000000
141.160004,-0.017502,-78.464401,-0.002384,0.002007,0.050976,-0.077852,-0.003966,0.509755,-78.464401,0.050056,0.000000
141.510010,-0.010796,-78.553360,-0.002402,0.001993,0.050620,-0.048021,-0.002446,0.506200,-78.553360,0.049475,0.000000
141.860001,-0.018616,-78.553360,-0.002436,0.001962,0.049822,-0.082807,-0.004218,0.498221,-78.553360,0.048886,0.000000
142.210007,-0.020103,-78.597839,-0.002436,0.001942,0.049328,-0.089425,-0.004556,0.493278,-78.597839,0.048304,0.000000
142.560013,0.001862,-78.597839,-0.002466,0.001926,0.048912,0.008281,0.000422,0.489115,-78.597839,0.047723,0.000000
142.910004,0.006332,-78.686806,-0.002492,0.001894,0.048114,0.028168,0.001435,0.481137,-78.686806,0.047142,0.000000
143.260010,-0.008934,-78.597839,-0.002509,0.001875,0.047628,-0.039741,-0.002024,0.476280,-78.597839,0.046553,0.000000
143.610001,-0.006699,-78.731285,-0.002518,0.001846,0.046882,-0.029797,-0.001518,0.468822,-78.731285,0.045972,0.000000
143.960007,0.016014,-78.775764,-0.002557,0.001823,0.046301,0.071234,0.003629,0.463012,-78.775764,0.045391,0.000000
144.310013,-0.019737,-78.775764,-0.002574,0.001803,0.045807,-0.087796,-0.004473,0.458069,-78.775764,0.044810,0.000000
144.660004,0.010429,-78.775764,-0.002613,0.001787,0.045382,0.046392,0.002363,0.453819,-78.775764,0.044220,0.000000
145.010010,-0.014519,-78.864723,-0.002643,0.001754,0.044549,-0.064583,-0.003290,0.445494,-78.864723,0.043639,0.000000
145.300003,0.016388,-78.909210,-0.002626,0.001746,0.044350,0.072897,0.003714,0.443499,-78.909210,0.044289,0.000000