File: Data/compression 15/AutoNoHeating-17-15-reverse-longpurge-3_08262024_191247.csv
Time (sec),S:Load (lbs),S:HL1 (DIM),S:LVDT (in),S:Position (in),Ch:Position (mm),Ch:Load (N),Ch:Stress (MPa),Ch:Strain (mm/mm),Ch:HL1 (DIM),Set Point (),Cycles ()
0.210000,-0.006332,-103.062363,-0.012805,-0.007801,-0.198144,-0.028168,-0.001435,-1.981437,-103.062363,-0.197866,0.000000
0.590000,-0.009315,-103.062363,-0.012840,-0.007705,-0.195707,-0.041437,-0.002111,-1.957068,-103.062363,-0.194900,0.000000
0.970000,-0.012291,-103.062363,-0.012641,-0.007471,-0.189775,-0.054673,-0.002785,-1.897750,-103.062363,-0.188570,0.000000
1.350000,-0.040962,-103.106842,-0.012391,-0.007227,-0.183574,-0.182209,-0.009282,-1.835743,-103.106842,-0.182239,0.000000
1.730000,-0.034264,-103.151329,-0.012115,-0.006981,-0.177313,-0.152412,-0.007764,-1.773130,-103.151329,-0.175908,0.000000
2.110000,-0.056976,-103.284767,-0.011874,-0.006729,-0.170913,-0.253443,-0.012911,-1.709128,-103.284767,-0.169577,0.000000
2.490000,-0.028305,-103.240288,-0.011637,-0.006477,-0.164513,-0.125907,-0.006414,-1.645127,-103.240288,-0.163247,0.000000
2.870000,-0.031654,-103.284767,-0.011374,-0.006225,-0.158104,-0.140806,-0.007173,-1.581039,-103.284767,-0.156916,0.000000
3.250000,-0.010803,-103.329247,-0.011094,-0.005980,-0.151895,-0.048055,-0.002448,-1.518946,-103.329247,-0.150585,0.000000
3.630000,-0.046181,-103.373734,-0.010843,-0.005724,-0.145390,-0.205422,-0.010465,-1.453904,-103.373734,-0.144254,0.000000
4.010000,-0.063309,-103.462692,-0.010576,-0.005479,-0.139164,-0.281611,-0.014346,-1.391637,-103.462692,-0.137924,0.000000
4.390000,-0.070381,-103.462692,-0.010322,-0.005228,-0.132790,-0.313071,-0.015949,-1.327896,-103.462692,-0.131593,0.000000
4.770000,-0.017136,-103.462692,-0.010067,-0.004976,-0.126398,-0.076223,-0.003883,-1.263981,-103.462692,-0.125262,0.000000
5.150000,-0.003357,-103.596138,-0.009817,-0.004732,-0.120180,-0.014932,-0.000761,-1.201801,-103.596138,-0.118931,0.000000
5.530000,-0.013039,-103.640617,-0.009550,-0.004477,-0.113711,-0.057999,-0.002955,-1.137106,-103.640617,-0.112601,0.000000
5.910000,-0.029045,-103.640617,-0.009283,-0.004228,-0.107397,-0.129199,-0.006582,-1.073972,-103.640617,-0.106270,0.000000
6.290000,-0.036865,-103.729576,-0.009046,-0.003980,-0.101101,-0.163985,-0.008354,-1.011012,-103.729576,-0.099939,0.000000
6.670001,0.003723,-103.729576,-0.008783,-0.003734,-0.094831,0.016561,0.000844,-0.948311,-103.729576,-0.093608,0.000000
7.050000,0.022339,-103.685097,-0.008511,-0.003479,-0.088370,0.099368,0.005062,-0.883703,-103.685097,-0.087278,0.000000
7.430000,0.007820,-103.774055,-0.008257,-0.003234,-0.082135,0.034786,0.001772,-0.821350,-103.774055,-0.080947,0.000000
7.810000,-0.016762,-103.907501,-0.008024,-0.002985,-0.075830,-0.074560,-0.003798,-0.758302,-103.907501,-0.074616,0.000000
8.190001,-0.019737,-103.907501,-0.007765,-0.002735,-0.069465,-0.087796,-0.004473,-0.694648,-103.907501,-0.068285,0.000000
8.570001,-0.021973,-103.907501,-0.007502,-0.002489,-0.063221,-0.097739,-0.004979,-0.632207,-103.907501,-0.061955,0.000000
8.950001,0.007820,-103.951981,-0.007239,-0.002237,-0.056812,0.034786,0.001772,-0.568119,-103.951981,-0.055624,0.000000
9.330001,0.029045,-104.040947,-0.006976,-0.001988,-0.050499,0.129199,0.006582,-0.504986,-104.040947,-0.049293,0.000000
9.710000,0.011543,-104.129906,-0.006722,-0.001740,-0.044185,0.051347,0.002616,-0.441851,-104.129906,-0.042962,0.000000
10.090000,-0.023087,-104.174385,-0.006480,-0.001493,-0.037924,-0.102694,-0.005231,-0.379238,-104.174385,-0.036632,0.000000
10.470000,-0.030540,-104.174385,-0.006204,-0.001243,-0.031567,-0.135851,-0.006921,-0.315670,-104.174385,-0.030301,0.000000
10.850000,-0.015640,-104.218872,-0.005967,-0.000996,-0.025297,-0.069571,-0.003544,-0.252970,-104.218872,-0.023970,0.000000
11.230000,-0.006706,-104.263351,-0.005687,-0.000744,-0.018906,-0.029831,-0.001520,-0.189055,-104.263351,-0.017639,0.000000
11.610001,0.008934,-104.396790,-0.005424,-0.000490,-0.012445,0.039741,0.002024,-0.124447,-104.396790,-0.011309,0.000000
11.990001,-0.013779,-104.396790,-0.005182,-0.000245,-0.006218,-0.061291,-0.003122,-0.062180,-104.396790,-0.004978,0.000000
12.370001,0.157509,-104.352310,-0.004967,-0.000006,-0.000147,0.700634,0.035692,-0.001474,-104.352310,-0.000000,0.000000
12.750001,0.151924,-104.396790,-0.004963,-0.000006,-0.000165,0.675792,0.034427,-0.001648,-104.396790,-0.000000,0.000000
13.130001,0.150810,-104.530235,-0.004971,-0.000006,-0.000165,0.670837,0.034174,-0.001648,-104.530235,0.000512,0.000000
13.510000,0.122131,-104.530235,-0.004958,-0.000006,-0.000156,0.543267,0.027675,-0.001561,-104.530235,0.001145,0.000000
13.890000,0.140007,-104.530235,-0.004971,-0.000006,-0.000147,0.622782,0.031726,-0.001474,-104.530235,0.001778,0.000000
14.270000,0.521317,-104.663681,-0.004928,0.000054,0.001370,2.318932,0.118132,0.013702,-104.663681,0.002411,0.000000
14.650001,0.859802,-104.619194,-0.004919,0.000083,0.002099,3.824591,0.194834,0.020987,-104.619194,0.003044,0.000000
15.030001,1.049339,-104.708160,-0.004876,0.000104,0.002654,4.667694,0.237784,0.026537,-104.708160,0.003677,0.000000
15.410001,1.723335,-104.708160,-0.004846,0.000136,0.003443,7.665778,0.390513,0.034429,-104.708160,0.004310,0.000000
15.790001,2.124008,-104.797119,-0.004833,0.000157,0.003989,9.448060,0.481307,0.039892,-104.797119,0.004943,0.000000
16.170000,2.563782,-104.841599,-0.004803,0.000176,0.004466,11.404271,0.580961,0.044662,-104.841599,0.005576,0.000000
16.550001,3.207985,-104.841599,-0.004786,0.000203,0.005169,14.269830,0.726940,0.051687,-104.841599,0.006209,0.000000
16.930000,3.812721,-104.886086,-0.004769,0.000229,0.005828,16.959831,0.863975,0.058278,-104.886086,0.006842,0.000000
17.310001,4.380959,-104.975044,-0.004738,0.000255,0.006470,19.487476,0.992739,0.064695,-104.975044,0.007475,0.000000
17.690001,4.721306,-105.019524,-0.004725,0.000278,0.007068,21.001417,1.069863,0.070679,-105.019524,0.008109,0.000000
18.070002,5.312637,-105.108490,-0.004691,0.000303,0.007692,23.631790,1.203861,0.076923,-105.108490,0.008742,0.000000
18.450001,5.810867,-105.108490,-0.004687,0.000322,0.008178,25.848028,1.316761,0.081779,-105.108490,0.009375,0.000000
18.830002,6.439804,-105.064003,-0.004665,0.000348,0.008828,28.645679,1.459280,0.088284,-105.064003,0.010008,0.000000
19.210001,6.964478,-105.197449,-0.004631,0.000377,0.009583,30.979544,1.578173,0.095828,-105.197449,0.010641,0.000000
19.590000,7.588577,-105.241928,-0.004600,0.000404,0.010259,33.755676,1.719596,0.102593,-105.241928,0.011274,0.000000
19.970001,7.889450,-105.330894,-0.004592,0.000421,0.010684,35.094028,1.787775,0.106842,-105.330894,0.011907,0.000000
20.350000,8.528069,-105.330894,-0.004575,0.000452,0.011491,37.934742,1.932488,0.114907,-105.330894,0.012540,0.000000
20.730001,9.263138,-105.375374,-0.004544,0.000478,0.012141,41.204494,2.099057,0.121412,-105.375374,0.013173,0.000000
21.110001,9.755035,-105.419853,-0.004518,0.000505,0.012826,43.392563,2.210523,0.128263,-105.419853,0.013806,0.000000
21.490002,10.423820,-105.419853,-0.004510,0.000535,0.013581,46.367470,2.362072,0.135808,-105.419853,0.014439,0.000000
21.870001,10.461426,-105.553299,-0.004488,0.000549,0.013954,46.534744,2.370593,0.139537,-105.553299,0.015072,0.000000
22.250002,10.965996,-105.553299,-0.004480,0.000573,0.014552,48.779186,2.484930,0.145520,-105.553299,0.015714,0.000000
22.630001,11.746483,-105.597778,-0.004432,0.000605,0.015359,52.250965,2.661791,0.153586,-105.597778,0.016347,0.000000
23.010000,12.422714,-105.642258,-0.004398,0.000634,0.016113,55.258991,2.815027,0.161131,-105.642258,0.016980,0.000000
23.390001,12.686356,-105.686737,-0.004389,0.000657,0.016685,56.431728,2.874769,0.166854,-105.686737,0.017613,0.000000
23.770000,12.989464,-105.775703,-0.004372,0.000679,0.017249,57.780022,2.943455,0.172491,-105.775703,0.018246,0.000000
24.150002,13.390511,-105.820183,-0.004359,0.000700,0.017778,59.563965,3.034333,0.177781,-105.820183,0.018880,0.000000
24.530001,14.019073,-105.820183,-0.004333,0.000724,0.018394,62.359955,3.176767,0.183939,-105.820183,0.019513,0.000000
24.910002,14.861382,-105.864662,-0.004307,0.000758,0.019252,66.106728,3.367637,0.192524,-105.864662,0.020146,0.000000
25.290001,15.092995,-105.909142,-0.004264,0.000784,0.019903,67.136993,3.420122,0.199028,-105.909142,0.020779,0.000000
25.670002,15.287750,-105.998108,-0.004251,0.000805,0.020458,68.003311,3.464254,0.204579,-105.998108,0.021412,0.000000
26.050001,15.942749,-106.042587,-0.004225,0.000833,0.021152,70.916893,3.612679,0.211516,-106.042587,0.022045,0.000000
26.430000,16.163193,-106.042587,-0.004217,0.000854,0.021689,71.897469,3.662632,0.216893,-106.042587,0.022678,0.000000
26.810001,16.669998,-106.042587,-0.004191,0.000878,0.022296,74.151855,3.777476,0.222964,-106.042587,0.023311,0.000000
27.190001,17.460541,-106.087067,-0.004165,0.000907,0.023042,77.668365,3.956615,0.230422,-106.087067,0.023944,0.000000
27.570002,17.610237,-106.176033,-0.004139,0.000930,0.023615,78.334244,3.990537,0.236146,-106.176033,0.024577,0.000000
27.950001,17.912231,-106.220512,-0.004117,0.000953,0.024204,79.677582,4.058969,0.242043,-106.220512,0.025210,0.000000
28.330002,18.312157,-106.176033,-0.004113,0.000979,0.024872,81.456543,4.149594,0.248720,-106.176033,0.025843,0.000000
28.710001,18.920616,-106.264992,-0.004053,0.001007,0.025574,84.163101,4.287473,0.255745,-106.264992,0.026476,0.000000
29.090002,18.461853,-106.309471,-0.004053,0.001018,0.025861,82.122421,4.183516,0.258607,-106.309471,0.027109,0.000000
29.470001,19.276978,-106.353951,-0.004010,0.001046,0.026563,85.748276,4.368226,0.265631,-106.353951,0.027743,0.000000
29.850002,20.102150,-106.442917,-0.003997,0.001083,0.027508,89.418831,4.555212,0.275084,-106.442917,0.028376,0.000000
30.230001,20.089493,-106.442917,-0.003971,0.001102,0.028003,89.362526,4.552344,0.280027,-106.442917,0.029009,0.000000
30.610001,20.542297,-106.487396,-0.003941,0.001129,0.028670,91.376701,4.654951,0.286705,-106.487396,0.029642,0.000000
30.990002,21.017815,-106.487396,-0.003911,0.001154,0.029304,93.491905,4.762705,0.293036,-106.487396,0.030275,0.000000
31.370001,21.070694,-106.620842,-0.003889,0.001177,0.029885,93.727127,4.774688,0.298846,-106.620842,0.030908,0.000000
31.750002,21.403595,-106.665321,-0.003876,0.001201,0.030518,95.207947,4.850124,0.305177,-106.665321,0.031541,0.000000
32.130001,21.639305,-106.665321,-0.003846,0.001225,0.031107,96.256439,4.903537,0.311074,-106.665321,0.032174,0.000000
32.510002,22.413467,-106.709801,-0.003816,0.001255,0.031879,99.700081,5.078964,0.318792,-106.709801,0.032807,0.000000
32.890003,22.699074,-106.709801,-0.003786,0.001282,0.032556,100.970520,5.143684,0.325557,-106.709801,0.033440,0.000000
33.270000,22.839462,-106.754280,-0.003764,0.001305,0.033145,101.595001,5.175496,0.331454,-106.754280,0.034082,0.000000
33.650002,22.842072,-106.887726,-0.003755,0.001325,0.033657,101.606606,5.176087,0.336570,-106.887726,0.034715,0.000000
34.030003,22.616783,-106.932205,-0.003721,0.001338,0.033987,100.604477,5.125036,0.339866,-106.932205,0.035348,0.000000
34.410000,23.171249,-106.932205,-0.003695,0.001363,0.034611,103.070862,5.250680,0.346110,-106.932205,0.035981,0.000000
34.790001,24.495773,-106.976685,-0.003669,0.001402,0.035617,108.962639,5.550821,0.356170,-106.976685,0.036614,0.000000
35.170002,24.168083,-107.021172,-0.003622,0.001423,0.036137,107.505005,5.476566,0.361373,-107.021172,0.037247,0.000000
35.550003,24.421669,-107.110130,-0.003622,0.001448,0.036770,108.633011,5.534029,0.367704,-107.110130,0.037880,0.000000
35.930000,24.261925,-107.154610,-0.003591,0.001461,0.037109,107.922432,5.497831,0.371086,-107.154610,0.038513,0.000000
36.310001,25.433411,-107.154610,-0.003557,0.001502,0.038141,113.133461,5.763293,0.381406,-107.154610,0.039147,0.000000
36.690002,25.782318,-107.154610,-0.003527,0.001530,0.038860,114.685478,5.842357,0.388604,-107.154610,0.039780,0.000000
37.070004,25.816208,-107.199089,-0.003510,0.001553,0.039459,114.836227,5.850037,0.394588,-107.199089,0.040413,0.000000
37.450001,25.552940,-107.288055,-0.003497,0.001571,0.039910,113.665154,5.790379,0.399097,-107.288055,0.041046,0.000000
37.830002,26.240341,-107.421494,-0.003462,0.001599,0.040603,116.722870,5.946146,0.406035,-107.421494,0.041679,0.000000
38.210003,26.526321,-107.377014,-0.003445,0.001621,0.041185,117.994972,6.010951,0.411846,-107.377014,0.042312,0.000000
38.590000,27.241646,-107.377014,-0.003402,0.001653,0.041991,121.176895,6.173045,0.419911,-107.377014,0.042945,0.000000
38.970001,27.290428,-107.421494,-0.003363,0.001677,0.042598,121.393890,6.184099,0.425981,-107.421494,0.043578,0.000000
39.350002,27.358574,-107.510460,-0.003363,0.001699,0.043144,121.697014,6.199541,0.431445,-107.510460,0.044211,0.000000
39.730003,27.633385,-107.554939,-0.003337,0.001720,0.043700,122.919434,6.261815,0.436995,-107.554939,0.044844,0.000000
40.110001,28.084702,-107.599419,-0.003307,0.001746,0.044350,124.926994,6.364084,0.443499,-107.599419,0.045477,0.000000
40.490002,28.191200,-107.599419,-0.003277,0.001768,0.044896,125.400719,6.388217,0.448963,-107.599419,0.046110,0.000000
40.870003,28.981003,-107.643898,-0.003247,0.001801,0.045746,128.913940,6.567189,0.457462,-107.643898,0.046743,0.000000
41.250004,28.834656,-107.688385,-0.003221,0.001821,0.046258,128.262955,6.534026,0.462578,-107.688385,0.047377,0.000000
41.630001,28.650703,-107.777344,-0.003203,0.001837,0.046657,127.444695,6.492342,0.466567,-107.777344,0.048010,0.000000
42.010002,30.015076,-107.866310,-0.003182,0.001876,0.047645,133.513718,6.801513,0.476454,-107.866310,0.048643,0.000000
42.390003,29.454659,-107.866310,-0.003165,0.001887,0.047932,131.020859,6.674521,0.479316,-107.866310,0.049276,0.000000
42.770000,31.168686,-107.866310,-0.003117,0.001930,0.049033,138.645233,7.062925,0.490329,-107.866310,0.049909,0.000000
43.150002,30.751259,-107.955269,-0.003091,0.001948,0.049467,136.788437,6.968335,0.494666,-107.955269,0.050542,0.000000
43.530003,31.104645,-107.999748,-0.003065,0.001971,0.050056,138.360367,7.048413,0.500563,-107.999748,0.051175,0.000000
43.910004,31.701927,-108.088715,-0.003057,0.002001,0.050819,141.017212,7.183759,0.508194,-108.088715,0.051808,0.000000
44.290001,32.352463,-108.088715,-0.003018,0.002028,0.051513,143.910934,7.331173,0.515132,-108.088715,0.052450,0.000000
44.670002,32.761696,-108.088715,-0.002997,0.002053,0.052155,145.731308,7.423906,0.521550,-108.088715,0.053083,0.000000
45.050003,32.827980,-108.177673,-0.002962,0.002076,0.052719,146.026154,7.438927,0.527187,-108.177673,0.053716,0.000000
45.430000,33.033157,-108.222153,-0.002940,0.002097,0.053256,146.938828,7.485420,0.532563,-108.222153,0.054349,0.000000
45.810001,33.670288,-108.311119,-0.002919,0.002123,0.053915,149.772919,7.629796,0.539154,-108.311119,0.054982,0.000000
46.190002,33.802849,-108.311119,-0.002889,0.002143,0.054436,150.362579,7.659835,0.544358,-108.311119,0.055615,0.000000
46.570004,35.023117,-108.311119,-0.002854,0.002179,0.055355,155.790604,7.936352,0.553550,-108.311119,0.056248,0.000000
46.950001,34.954231,-108.400078,-0.002846,0.002199,0.055867,155.484192,7.920742,0.558667,-108.400078,0.056881,0.000000
47.330002,35.576836,-108.444557,-0.002807,0.002227,0.056569,158.253662,8.061826,0.565691,-108.444557,0.057514,0.000000
47.710003,35.269997,-108.489037,-0.002794,0.002240,0.056907,156.888779,7.992295,0.569073,-108.489037,0.058147,0.000000
48.090004,36.482819,-108.578003,-0.002781,0.002273,0.057740,162.283676,8.267125,0.577399,-108.578003,0.058781,0.000000
48.470001,36.011765,-108.578003,-0.002733,0.002286,0.058061,160.188324,8.160382,0.580608,-108.578003,0.059414,0.000000
48.850002,37.696754,-108.622482,-0.002703,0.002326,0.059084,167.683533,8.542207,0.590841,-108.622482,0.060047,0.000000
49.230003,37.884056,-108.622482,-0.002669,0.002350,0.059700,168.516693,8.584649,0.596998,-108.622482,0.060680,0.000000
49.610001,38.415802,-108.711441,-0.002656,0.002374,0.060298,170.882019,8.705146,0.602982,-108.711441,0.061313,0.000000
49.990002,38.543900,-108.755928,-0.002647,0.002398,0.060914,171.451828,8.734173,0.609139,-108.755928,0.061946,0.000000
50.370003,38.540916,-108.800407,-0.002604,0.002416,0.061374,171.438553,8.733497,0.613736,-108.800407,0.062579,0.000000
50.750004,39.008247,-108.844887,-0.002587,0.002437,0.061911,173.517349,8.839396,0.619112,-108.844887,0.063212,0.000000
51.130001,40.914421,-108.889366,-0.002544,0.002474,0.062839,181.996429,9.271340,0.628392,-108.889366,0.063845,0.000000
51.510002,40.841438,-108.889366,-0.002535,0.002495,0.063368,181.671783,9.254803,0.633682,-108.889366,0.064478,0.000000
51.890003,41.563469,-108.978333,-0.002514,0.002521,0.064027,184.883545,9.418416,0.640273,-108.978333,0.065111,0.000000
52.270004,42.925980,-108.889366,-0.002488,0.002552,0.064816,190.944290,9.727166,0.648165,-108.889366,0.065744,0.000000
52.650002,43.193710,-109.067291,-0.002436,0.002574,0.065389,192.135223,9.787834,0.653888,-109.067291,0.066377,0.000000
53.030003,43.404106,-109.111771,-0.002440,0.002594,0.065892,193.071106,9.835511,0.658918,-109.111771,0.067011,0.000000
53.410004,43.874039,-109.156258,-0.002414,0.002618,0.066508,195.161469,9.941999,0.665075,-109.156258,0.067644,0.000000
53.790001,44.822098,-109.200737,-0.002384,0.002649,0.067279,199.378647,10.156833,0.672794,-109.200737,0.068277,0.000000
54.170002,46.225197,-109.200737,-0.002363,0.002677,0.068008,205.619949,10.474779,0.680078,-109.200737,0.068910,0.000000
54.550003,46.645981,-109.156258,-0.002341,0.002702,0.068641,207.491684,10.570130,0.686409,-109.156258,0.069543,0.000000
54.930004,46.612465,-109.245216,-0.002311,0.002722,0.069127,207.342606,10.562536,0.691266,-109.245216,0.070176,0.000000
55.310001,46.729393,-109.334175,-0.002276,0.002742,0.069638,207.862717,10.589032,0.696382,-109.334175,0.070818,0.000000
55.690002,47.272682,-109.423141,-0.002251,0.002760,0.070107,210.279388,10.712143,0.701065,-109.423141,0.071451,0.000000
56.070004,49.532234,-109.378662,-0.002233,0.002800,0.071130,220.330383,11.224164,0.711299,-109.378662,0.072084,0.000000
56.450005,49.586975,-109.423141,-0.002212,0.002821,0.071659,220.573883,11.236569,0.716589,-109.423141,0.072717,0.000000
56.830002,49.713585,-109.512100,-0.002177,0.002840,0.072127,221.137070,11.265260,0.721272,-109.512100,0.073350,0.000000
57.210003,50.235275,-109.556580,-0.002151,0.002861,0.072674,223.457672,11.383476,0.726735,-109.556580,0.073983,0.000000
57.590004,51.811905,-109.645546,-0.002143,0.002896,0.073558,230.470871,11.740746,0.735581,-109.645546,0.074616,0.000000
57.970001,53.164734,-109.690025,-0.002104,0.002926,0.074330,236.488541,12.047301,0.743299,-109.690025,0.075249,0.000000
58.350002,53.772446,-109.690025,-0.002091,0.002949,0.074911,239.191788,12.185011,0.749110,-109.690025,0.075882,0.000000
58.730003,53.253357,-109.734505,-0.002074,0.002961,0.075206,236.882767,12.067384,0.752058,-109.734505,0.076515,0.000000
59.110004,54.843010,-109.778984,-0.002031,0.002993,0.076021,243.953888,12.427603,0.760210,-109.778984,0.077148,0.000000
59.490002,55.813042,-109.823471,-0.002005,0.003020,0.076715,248.268814,12.647416,0.767148,-109.823471,0.077781,0.000000
59.870003,56.984528,-109.867950,-0.001983,0.003048,0.077409,253.479843,12.912879,0.774086,-109.867950,0.078415,0.000000
60.250004,57.702835,-109.912430,-0.001962,0.003073,0.078059,256.675018,13.075649,0.780590,-109.912430,0.079048,0.000000
60.630001,57.938171,-109.956909,-0.001936,0.003091,0.078510,257.721863,13.128977,0.785099,-109.956909,0.079681,0.000000
61.010002,58.889214,-110.045876,-0.001914,0.003119,0.079230,261.952301,13.344486,0.792297,-110.045876,0.080314,0.000000
61.390003,59.955315,-110.090355,-0.001876,0.003142,0.079819,266.694550,13.586068,0.798195,-110.090355,0.080947,0.000000
61.770004,60.590584,-110.134834,-0.001854,0.003166,0.080409,269.520386,13.730022,0.804092,-110.134834,0.081580,0.000000
62.150002,61.422089,-110.134834,-0.001828,0.003195,0.081155,273.219086,13.918444,0.811550,-110.134834,0.082213,0.000000
62.530003,62.424141,-110.179314,-0.001807,0.003216,0.081693,277.676453,14.145513,0.816927,-110.179314,0.082846,0.000000
62.910004,62.734329,-110.223793,-0.001789,0.003234,0.082152,279.056244,14.215803,0.821523,-110.223793,0.083479,0.000000
63.290005,64.529533,-110.268280,-0.001755,0.003269,0.083037,287.041687,14.622601,0.830369,-110.268280,0.084112,0.000000
63.670002,64.726158,-110.312759,-0.001733,0.003286,0.083453,287.916321,14.667156,0.834531,-110.312759,0.084745,0.000000
64.050003,65.441856,-110.312759,-0.001716,0.003302,0.083878,291.099915,14.829336,0.838781,-110.312759,0.014732,0.000000
64.430000,66.325493,-110.357239,-0.001660,0.003125,0.079386,295.030518,15.029572,0.793858,-110.357239,294.500488,0.000000
64.810005,65.801186,-110.446205,-0.001656,0.003332,0.084624,292.698303,14.910762,0.846239,-110.446205,294.500488,0.000000
65.190002,65.133904,-110.446205,-0.001643,0.003370,0.085587,289.730072,14.759553,0.855865,-110.446205,294.500488,0.000000
65.570000,65.552071,-110.535164,-0.001621,0.003233,0.082126,291.590179,14.854312,0.821263,-110.535164,294.500488,0.000000
65.950005,65.019203,-110.535164,-0.001595,0.003369,0.085578,289.219849,14.733562,0.855778,-110.535164,294.500488,0.000000
66.330002,64.988670,-110.535164,-0.001595,0.003383,0.085916,289.084045,14.726644,0.859160,-110.535164,294.500488,0.000000
66.710007,65.872688,-110.624123,-0.001556,0.003374,0.085708,293.016357,14.926965,0.857079,-110.624123,294.500488,0.000000
67.090004,66.202232,-110.668610,-0.001552,0.003416,0.086757,294.482239,15.001640,0.867573,-110.668610,294.500488,0.000000
67.470001,64.825203,-110.713089,-0.001544,0.003413,0.086697,288.356903,14.689601,0.866966,-110.713089,294.500488,0.000000
67.850006,65.536430,-110.846527,-0.001526,0.003409,0.086601,291.520599,14.850768,0.866012,-110.846527,294.500488,0.000000
68.230003,65.174492,-110.802048,-0.001505,0.003443,0.087460,289.910614,14.768751,0.874597,-110.802048,294.500488,0.000000
68.610001,65.293282,-110.846527,-0.001492,0.003456,0.087781,290.439026,14.795669,0.877806,-110.846527,294.500488,0.000000
68.990005,65.168159,-110.846527,-0.001470,0.003464,0.087997,289.882446,14.767316,0.879974,-110.846527,294.500488,0.000000
69.370003,65.158852,-110.979973,-0.001457,0.003474,0.088232,289.841034,14.765207,0.882315,-110.979973,294.500488,0.000000
69.750000,65.469032,-111.024452,-0.001444,0.003485,0.088526,291.220795,14.835495,0.885264,-111.024452,294.500488,0.000000
70.130005,65.109322,-111.024452,-0.001444,0.003491,0.088683,289.620728,14.753983,0.886825,-111.024452,294.500488,0.000000
70.510002,65.053459,-111.068932,-0.001427,0.003502,0.088943,289.372253,14.741324,0.889427,-111.068932,294.500488,0.000000
70.890007,65.346153,-111.157898,-0.001401,0.003510,0.089159,290.674194,14.807650,0.891595,-111.157898,294.500488,0.000000
71.270004,65.304451,-111.202377,-0.001418,0.003518,0.089368,290.488708,14.798200,0.893676,-111.202377,294.500488,0.000000
71.650002,65.086601,-111.157898,-0.001410,0.003524,0.089498,289.519653,14.748835,0.894977,-111.157898,294.500488,0.000000
72.030006,66.029457,-111.246857,-0.001380,0.003534,0.089775,293.713684,14.962488,0.897752,-111.246857,294.500488,0.000000
72.410004,65.189384,-111.202377,-0.001380,0.003535,0.089784,289.976868,14.772126,0.897839,-111.202377,294.500488,0.000000
72.790001,65.285454,-111.335823,-0.001362,0.003547,0.090087,290.404205,14.793895,0.900874,-111.335823,294.500488,0.000000
73.170006,65.219170,-111.469261,-0.001354,0.003554,0.090278,290.109344,14.778874,0.902782,-111.469261,294.500488,0.000000
73.550003,65.361046,-111.469261,-0.001350,0.003562,0.090486,290.740448,14.811025,0.904863,-111.469261,294.500488,0.000000
73.930000,65.201302,-111.469261,-0.001341,0.003567,0.090608,290.029877,14.774826,0.906077,-111.469261,294.500488,0.000000
74.310005,65.298119,-111.469261,-0.001341,0.003575,0.090816,290.460541,14.796765,0.908159,-111.469261,294.500488,0.000000
74.690002,65.229591,-111.558228,-0.001328,0.003583,0.090998,290.155701,14.781238,0.909980,-111.558228,294.500488,0.000000
75.070007,65.255669,-111.558228,-0.001306,0.003588,0.091137,290.271698,14.787147,0.911367,-111.558228,294.500488,0.000000
75.450005,65.204277,-111.647186,-0.001306,0.003594,0.091275,290.043121,14.775500,0.912755,-111.647186,294.500488,0.000000
75.830002,65.289925,-111.691666,-0.001285,0.003601,0.091458,290.424103,14.794909,0.914576,-111.691666,294.500488,0.000000
76.210007,65.410942,-111.647186,-0.001281,0.003607,0.091622,290.962402,14.822331,0.916224,-111.647186,294.500488,0.000000
76.590004,65.302956,-111.736153,-0.001285,0.003612,0.091735,290.482056,14.797861,0.917351,-111.736153,294.500488,0.000000
76.970001,65.312630,-111.914070,-0.001285,0.003617,0.091874,290.525085,14.800053,0.918739,-111.914070,294.500488,0.000000
77.350006,65.314873,-111.914070,-0.001272,0.003622,0.091995,290.535065,14.800561,0.919953,-111.914070,294.500488,0.000000
77.730003,65.301094,-111.914070,-0.001276,0.003627,0.092134,290.473785,14.797440,0.921341,-111.914070,294.500488,0.000000
78.110001,65.400139,-111.914070,-0.001255,0.003633,0.092273,290.914337,14.819883,0.922728,-111.914070,294.500488,0.000000
78.490005,65.258644,-112.003036,-0.001242,0.003637,0.092377,290.284943,14.787820,0.923769,-112.003036,294.500488,0.000000
78.870003,65.104851,-112.003036,-0.001242,0.003642,0.092498,289.600830,14.752970,0.924983,-112.003036,294.500488,0.000000
79.250000,65.081017,-112.136475,-0.001242,0.003643,0.092542,289.494812,14.747569,0.925417,-112.136475,294.500488,0.000000
79.630005,65.107460,-112.003036,-0.001220,0.003648,0.092654,289.612457,14.753561,0.926544,-112.003036,294.500488,0.000000
80.010002,65.101128,-112.136475,-0.001233,0.003652,0.092767,289.584290,14.752126,0.927671,-112.136475,294.500488,0.000000
80.390007,65.103737,-112.136475,-0.001216,0.003657,0.092880,289.595886,14.752718,0.928799,-112.136475,294.500488,0.000000
80.770004,65.670113,-112.180962,-0.001203,0.003668,0.093157,292.115265,14.881061,0.931574,-112.180962,294.500488,0.000000
81.150002,65.424721,-112.314400,-0.001207,0.003668,0.093157,291.023682,14.825454,0.931574,-112.314400,294.500488,0.000000
81.530006,65.050865,-112.269920,-0.001203,0.003668,0.093157,289.360687,14.740736,0.931574,-112.269920,294.500488,0.000000
81.910004,64.700081,-112.358879,-0.001194,0.003668,0.093175,287.800323,14.661247,0.931747,-112.358879,294.500488,0.000000
82.290001,65.946419,-112.358879,-0.001168,0.003679,0.093435,293.344330,14.943672,0.934349,-112.358879,294.500488,0.000000
82.670006,65.536812,-112.447845,-0.001177,0.003679,0.093444,291.522308,14.850854,0.934436,-112.447845,294.500488,0.000000
83.050003,65.088844,-112.492325,-0.001186,0.003680,0.093470,289.529633,14.749343,0.934696,-112.492325,294.500488,0.000000
83.430000,65.782951,-112.492325,-0.001186,0.003694,0.093816,292.617187,14.906630,0.938165,-112.492325,294.500488,0.000000
83.810005,65.474998,-112.536804,-0.001155,0.003694,0.093816,291.247345,14.836846,0.938165,-112.536804,294.500488,0.000000
84.190002,65.130547,-112.581284,-0.001160,0.003694,0.093816,289.715149,14.758793,0.938165,-112.581284,294.500488,0.000000
84.570007,66.205589,-112.714729,-0.001155,0.003710,0.094241,294.497162,15.002400,0.942414,-112.714729,294.500488,0.000000
84.950005,65.862633,-112.759209,-0.001155,0.003699,0.093955,292.971619,14.924685,0.939552,-112.759209,294.500488,0.000000
85.330002,65.462334,-112.670250,-0.001155,0.003699,0.093955,291.191010,14.833977,0.939552,-112.670250,294.500488,0.000000
85.710007,65.053459,-112.759209,-0.001147,0.003699,0.093964,289.372253,14.741324,0.939639,-112.759209,294.500488,0.000000
86.090004,66.211540,-112.803696,-0.001134,0.003710,0.094241,294.523651,15.003750,0.942414,-112.803696,294.500488,0.000000
86.470001,65.844017,-112.848175,-0.001134,0.003710,0.094233,292.888824,14.920467,0.942327,-112.848175,294.500488,0.000000
86.850006,65.501060,-112.937134,-0.001138,0.003710,0.094233,291.363281,14.842752,0.942327,-112.937134,294.500488,0.000000
87.230003,65.134270,-112.892654,-0.001134,0.003710,0.094241,289.731689,14.759637,0.942414,-112.892654,294.500488,0.000000
87.610001,64.793175,-112.937134,-0.001143,0.003710,0.094241,288.214447,14.682343,0.942414,-112.937134,294.500488,0.000000
87.990005,66.284523,-113.026100,-0.001117,0.003712,0.094276,294.848297,15.020288,0.942761,-113.026100,294.500488,0.000000
88.370003,65.912529,-113.070580,-0.001121,0.003712,0.094276,293.193573,14.935992,0.942761,-113.070580,294.500488,0.000000
88.750008,65.605324,-113.115059,-0.001104,0.003712,0.094285,291.827057,14.866379,0.942848,-113.115059,294.500488,0.000000
89.130005,65.308540,-113.159538,-0.001095,0.003712,0.094285,290.506897,14.799127,0.942848,-113.159538,294.500488,0.000000
89.510002,65.302956,-113.159538,-0.001112,0.003736,0.094883,290.482056,14.797861,0.948832,-113.159538,294.500488,0.000000
89.890007,65.206139,-113.204018,-0.001108,0.003738,0.094935,290.051392,14.775923,0.949352,-113.204018,294.500488,0.000000
90.270004,65.463448,-113.337463,-0.001104,0.003743,0.095083,291.195953,14.834229,0.950826,-113.337463,294.500488,0.000000
90.650002,65.263481,-113.337463,-0.001104,0.003744,0.095100,290.306458,14.788917,0.951000,-113.337463,294.500488,0.000000
91.030006,65.374077,-113.337463,-0.001108,0.003749,0.095230,290.798431,14.813977,0.952300,-113.337463,294.500488,0.000000
91.410004,65.256035,-113.381943,-0.001108,0.003749,0.095230,290.273346,14.787229,0.952300,-113.381943,294.500488,0.000000
91.790001,65.185661,-113.426422,-0.001095,0.003752,0.095291,289.960297,14.771281,0.952908,-113.426422,294.500488,0.000000
92.170006,65.378914,-113.426422,-0.001078,0.003757,0.095421,290.819946,14.815073,0.954208,-113.426422,294.500488,0.000000
92.550003,65.308540,-113.559868,-0.001091,0.003757,0.095421,290.506897,14.799127,0.954208,-113.559868,294.500488,0.000000
92.930008,65.106712,-113.604347,-0.001095,0.003757,0.095430,289.609131,14.753392,0.954295,-113.604347,294.500488,0.000000
93.310005,65.275398,-113.604347,-0.001086,0.003762,0.095542,290.359467,14.791616,0.955423,-113.604347,294.500488,0.000000
93.690002,65.191246,-113.604347,-0.001082,0.003763,0.095568,289.985138,14.772547,0.955683,-113.604347,294.500488,0.000000
94.070007,65.111549,-113.648827,-0.001082,0.003764,0.095603,289.630646,14.754488,0.956030,-113.648827,294.500488,0.000000
94.450005,65.259010,-113.737793,-0.001091,0.003768,0.095698,290.286591,14.787904,0.956984,-113.737793,294.500488,0.000000
94.830002,65.219917,-113.782272,-0.001069,0.003769,0.095733,290.112671,14.779044,0.957330,-113.782272,294.500488,0.000000
95.210007,65.168159,-113.826752,-0.001082,0.003771,0.095785,289.882446,14.767316,0.957851,-113.826752,294.500488,0.000000
95.590004,65.149544,-113.871231,-0.001065,0.003773,0.095837,289.799652,14.763098,0.958371,-113.871231,294.500488,0.000000
95.970001,65.244118,-113.871231,-0.001061,0.003776,0.095898,290.220337,14.784528,0.958978,-113.871231,294.500488,0.000000
96.350006,65.111549,-114.004677,-0.001069,0.003776,0.095898,289.630646,14.754488,0.958978,-114.004677,294.500488,0.000000
96.730003,65.230339,-114.049156,-0.001056,0.003779,0.095976,290.159027,14.781406,0.959759,-114.049156,294.500488,0.000000
97.110008,65.181938,-113.960197,-0.001056,0.003780,0.096011,289.943756,14.770438,0.960106,-113.960197,294.500488,0.000000
97.490005,65.059425,-114.049156,-0.001052,0.003781,0.096028,289.398773,14.742677,0.960279,-114.049156,294.500488,0.000000
97.870003,65.096657,-114.138123,-0.001056,0.003783,0.096080,289.564392,14.751113,0.960799,-114.138123,294.500488,0.000000
98.250008,65.040428,-114.182602,-0.001052,0.003784,0.096115,289.314270,14.738372,0.961146,-114.182602,294.500488,0.000000
98.630005,65.262367,-114.271561,-0.001052,0.003788,0.096219,290.301514,14.788664,0.962187,-114.271561,294.500488,0.000000
99.010002,65.180077,-114.271561,-0.001056,0.003788,0.096227,289.935455,14.770016,0.962274,-114.271561,294.500488,0.000000
99.390007,65.134270,-114.316048,-0.001039,0.003791,0.096279,289.731689,14.759637,0.962794,-114.316048,294.500488,0.000000
99.770004,65.164055,-114.316048,-0.001039,0.003792,0.096323,289.864197,14.766386,0.963228,-114.316048,294.500488,0.000000
100.150002,65.092934,-114.449486,-0.001043,0.003796,0.096409,289.547821,14.750270,0.964095,-114.449486,294.500488,0.000000
100.530006,65.530098,-114.449486,-0.001048,0.003798,0.096479,291.492432,14.849333,0.964789,-114.449486,294.500488,0.000000
100.910004,65.410942,-114.449486,-0.001043,0.003798,0.096479,290.962402,14.822331,0.964789,-114.449486,294.500488,0.000000
101.290009,65.302589,-114.493965,-0.001026,0.003799,0.096488,290.480438,14.797779,0.964875,-114.493965,294.500488,0.000000
101.670006,65.257896,-114.582932,-0.001035,0.003800,0.096531,290.281616,14.787651,0.965309,-114.582932,294.500488,0.000000
102.050003,65.295143,-114.627411,-0.001043,0.003803,0.096600,290.447296,14.796091,0.966003,-114.627411,294.500488,0.000000
102.430008,65.280617,-114.671890,-0.001030,0.003804,0.096609,290.382690,14.792799,0.966089,-114.671890,294.500488,0.000000
102.810005,65.185280,-114.671890,-0.001026,0.003804,0.096618,289.958618,14.771195,0.966176,-114.671890,294.500488,0.000000
103.190002,65.076927,-114.671890,-0.001026,0.003804,0.096626,289.476624,14.746643,0.966263,-114.671890,294.500488,0.000000
103.570007,65.025917,-114.760857,-0.001026,0.003806,0.096661,289.249725,14.735084,0.966610,-114.760857,294.500488,0.000000
103.950005,65.288811,-114.805336,-0.001030,0.003810,0.096765,290.419128,14.794656,0.967650,-114.805336,294.500488,0.000000
104.330002,65.225502,-114.894295,-0.001022,0.003810,0.096765,290.137512,14.780310,0.967650,-114.894295,294.500488,0.000000
104.710007,65.109688,-114.849815,-0.001030,0.003810,0.096765,289.622345,14.754066,0.967650,-114.849815,294.500488,0.000000
105.090004,64.992775,-114.894295,-0.001013,0.003810,0.096765,289.102295,14.727573,0.967650,-114.894295,294.500488,0.000000
105.470001,64.895958,-114.938774,-0.001026,0.003810,0.096765,288.671631,14.705635,0.967650,-114.938774,294.500488,0.000000
105.850006,65.771400,-115.027740,-0.001009,0.003821,0.097051,292.565796,14.904013,0.970512,-115.027740,294.500488,0.000000
106.230003,65.760979,-115.072220,-0.001026,0.003821,0.097051,292.519440,14.901651,0.970512,-115.072220,294.500488,0.000000
106.610008,65.632881,-115.072220,-0.001018,0.003821,0.097051,291.949646,14.872623,0.970512,-115.072220,294.500488,0.000000
106.990005,65.561012,-115.072220,-0.001009,0.003821,0.097051,291.629944,14.856339,0.970512,-115.072220,294.500488,0.000000
107.370003,65.461586,-115.205666,-0.001000,0.003821,0.097051,291.187683,14.833807,0.970512,-115.205666,294.500488,0.000000
107.750008,65.329765,-115.250145,-0.001018,0.003821,0.097051,290.601318,14.803937,0.970512,-115.250145,294.500488,0.000000
108.130005,65.221779,-115.250145,-0.001000,0.003821,0.097051,290.120972,14.779467,0.970512,-115.250145,294.500488,0.000000
108.510002,65.103737,-115.250145,-0.001013,0.003821,0.097051,289.595886,14.752718,0.970512,-115.250145,294.500488,0.000000
108.890007,64.990166,-115.339104,-0.000992,0.003821,0.097060,289.090698,14.726981,0.970599,-115.339104,294.500488,0.000000
109.270004,64.888878,-115.383591,-0.001005,0.003821,0.097060,288.640137,14.704030,0.970599,-115.383591,294.500488,0.000000
109.650002,64.757805,-115.472549,-0.001000,0.003821,0.097060,288.057098,14.674329,0.970599,-115.472549,294.500488,0.000000
110.030006,64.681465,-115.561508,-0.001000,0.003821,0.097060,287.717529,14.657030,0.970599,-115.561508,294.500488,0.000000
110.410004,64.565651,-115.517029,-0.001000,0.003821,0.097060,287.202362,14.630786,0.970599,-115.517029,294.500488,0.000000
110.790009,64.453575,-115.517029,-0.001009,0.003821,0.097060,286.703827,14.605389,0.970599,-115.517029,294.500488,0.000000
111.170006,64.358620,-115.605995,-0.000996,0.003821,0.097060,286.281433,14.583872,0.970599,-115.605995,294.500488,0.000000
111.550003,65.674583,-115.650475,-0.001000,0.003859,0.098031,292.135132,14.882073,0.980312,-115.650475,294.500488,0.000000
111.930008,66.691902,-115.739433,-0.000983,0.003723,0.094554,296.660400,15.112601,0.945536,-115.739433,294.500488,0.000000
112.310005,66.576469,-115.739433,-0.000996,0.003723,0.094554,296.146912,15.086443,0.945536,-115.739433,294.500488,0.000000
112.690002,66.401833,-115.739433,-0.000983,0.003723,0.094562,295.370117,15.046870,0.945623,-115.739433,294.500488,0.000000
113.070007,66.298302,-115.872879,-0.000987,0.003723,0.094562,294.909576,15.023410,0.945623,-115.872879,294.500488,0.000000
113.450005,66.166115,-115.917358,-0.000970,0.003723,0.094562,294.321564,14.993456,0.945623,-115.917358,294.500488,0.000000
113.830002,66.070412,-115.917358,-0.000983,0.003723,0.094562,293.895874,14.971769,0.945623,-115.917358,294.500488,0.000000
114.210007,65.901726,-115.917358,-0.000983,0.003724,0.094580,293.145508,14.933545,0.945796,-115.917358,294.500488,0.000000
114.590004,65.840294,-115.917358,-0.000979,0.003736,0.094883,292.872253,14.919623,0.948832,-115.917358,294.500488,0.000000
114.970009,65.763206,-116.006317,-0.000974,0.003748,0.095204,292.529358,14.902155,0.952040,-116.006317,294.500488,0.000000
115.350006,65.621330,-116.095284,-0.000987,0.003787,0.096201,291.898254,14.870006,0.962013,-116.095284,294.500488,0.000000
115.730003,65.552818,-116.095284,-0.000987,0.003804,0.096618,291.593506,14.854481,0.966176,-116.095284,294.500488,0.000000
116.110008,65.464561,-116.139763,-0.000983,0.003804,0.096626,291.200928,14.834482,0.966263,-116.139763,294.500488,0.000000
116.490005,65.356575,-116.228722,-0.000983,0.003806,0.096661,290.720551,14.810012,0.966610,-116.228722,294.500488,0.000000
116.870003,65.267586,-116.228722,-0.000961,0.003806,0.096661,290.324707,14.789846,0.966610,-116.228722,294.500488,0.000000
117.250008,65.264595,-116.317688,-0.000970,0.003820,0.097017,290.311432,14.789169,0.970165,-116.317688,294.500488,0.000000
117.630005,65.258644,-116.273209,-0.000979,0.003832,0.097337,290.284943,14.787820,0.973374,-116.273209,294.500488,0.000000
118.010002,65.200188,-116.362167,-0.000974,0.003835,0.097407,290.024933,14.774573,0.974068,-116.362167,294.500488,0.000000
118.390007,65.088097,-116.317688,-0.000961,0.003835,0.097407,289.526306,14.749174,0.974068,-116.317688,294.500488,0.000000
118.770004,64.994255,-116.406647,-0.000979,0.003835,0.097407,289.108887,14.727909,0.974068,-116.406647,294.500488,0.000000
119.150009,64.908241,-116.495613,-0.000970,0.003835,0.097407,288.726288,14.708417,0.974068,-116.495613,294.500488,0.000000
119.530006,65.786293,-116.584572,-0.000974,0.003852,0.097849,292.632050,14.907387,0.978491,-116.584572,294.500488,0.000000
119.910004,65.771767,-116.584572,-0.000974,0.003851,0.097814,292.567444,14.904096,0.978144,-116.584572,294.500488,0.000000
120.290009,65.722618,-116.540092,-0.000961,0.003851,0.097814,292.348816,14.892958,0.978144,-116.540092,294.500488,0.000000
120.670006,65.596764,-116.629051,-0.000953,0.003851,0.097814,291.788971,14.864439,0.978144,-116.629051,294.500488,0.000000
121.050003,65.556908,-116.718018,-0.000966,0.003851,0.097814,291.611694,14.855408,0.978144,-116.718018,294.500488,0.000000
121.430008,65.490639,-116.762497,-0.000966,0.003851,0.097814,291.316925,14.840391,0.978144,-116.762497,294.500488,0.000000
121.810005,65.390831,-116.718018,-0.000974,0.003851,0.097823,290.872955,14.817774,0.978231,-116.718018,294.500488,0.000000
122.190002,65.319710,-116.806976,-0.000953,0.003852,0.097840,290.556580,14.801658,0.978404,-116.806976,294.500488,0.000000
122.570007,65.278008,-116.851456,-0.000970,0.003852,0.097840,290.371094,14.792209,0.978404,-116.851456,294.500488,0.000000
122.950005,65.222145,-116.895943,-0.000953,0.003852,0.097849,290.122589,14.779550,0.978491,-116.895943,294.500488,0.000000
123.330009,65.137993,-116.940422,-0.000961,0.003852,0.097849,289.748260,14.760480,0.978491,-116.940422,294.500488,0.000000
123.710007,65.082878,-116.940422,-0.000961,0.003853,0.097858,289.503113,14.747991,0.978577,-116.940422,294.500488,0.000000
124.090004,65.145439,-116.984901,-0.000953,0.003856,0.097944,289.781372,14.762168,0.979445,-116.984901,294.500488,0.000000
124.470009,65.184547,-116.984901,-0.000949,0.003856,0.097944,289.955353,14.771029,0.979445,-116.984901,1681.640991,0.000000
124.850006,65.100761,-117.162827,-0.000961,0.003847,0.097702,289.582642,14.752044,0.977016,-117.162827,0.097684,0.000000
125.230003,64.976387,-117.162827,-0.000957,0.003834,0.097389,289.029419,14.723860,0.973894,-117.162827,0.097051,0.000000
125.610008,64.765999,-117.162827,-0.000949,0.003813,0.096852,288.093536,14.676186,0.968518,-117.162827,0.096418,0.000000
125.990005,64.640877,-117.207306,-0.000944,0.003792,0.096305,287.536987,14.647833,0.963054,-117.207306,0.095785,0.000000
126.370003,64.564171,-117.207306,-0.000940,0.003765,0.095629,287.195770,14.630450,0.956290,-117.207306,0.095143,0.000000
126.750008,64.527672,-117.296265,-0.000944,0.003737,0.094918,287.033417,14.622180,0.949179,-117.296265,0.094510,0.000000
127.130005,64.422295,-117.385231,-0.000957,0.003723,0.094562,286.564667,14.598301,0.945623,-117.385231,0.093877,0.000000
127.510010,64.311333,-117.340752,-0.000944,0.003695,0.093851,286.071106,14.573156,0.938512,-117.340752,0.093244,0.000000
127.890007,64.175041,-117.385231,-0.000957,0.003667,0.093131,285.464844,14.542273,0.931314,-117.385231,0.092611,0.000000
128.270004,63.954597,-117.518669,-0.000940,0.003640,0.092464,284.484253,14.492319,0.924636,-117.518669,0.091978,0.000000
128.650009,63.664513,-117.518669,-0.000949,0.003623,0.092030,283.193909,14.426584,0.920300,-117.518669,0.091345,0.000000
129.029999,62.525803,-117.607635,-0.000927,0.003598,0.091388,278.128662,14.168550,0.913882,-117.607635,0.090712,0.000000
129.410004,61.624657,-117.607635,-0.000936,0.003578,0.090885,274.120178,13.964347,0.908853,-117.607635,0.090079,0.000000
129.790009,60.316147,-117.607635,-0.000936,0.003554,0.090270,268.299622,13.667834,0.902695,-117.607635,0.089446,0.000000
130.170013,58.890701,-117.652115,-0.000927,0.003530,0.089671,261.958923,13.344824,0.896711,-117.652115,0.088813,0.000000
130.550003,57.172951,-117.785561,-0.000927,0.003506,0.089064,254.317993,12.955576,0.890641,-117.785561,0.088180,0.000000
130.930008,55.183731,-117.785561,-0.000936,0.003481,0.088422,245.469498,12.504812,0.884223,-117.785561,0.087546,0.000000
131.310013,53.545296,-117.830040,-0.000927,0.003463,0.087963,238.181366,12.133537,0.879627,-117.830040,0.086913,0.000000
131.690002,50.958054,-117.830040,-0.000927,0.003435,0.087260,226.672745,11.547260,0.872603,-117.830040,0.086280,0.000000
132.070007,48.524971,-117.785561,-0.000918,0.003410,0.086610,215.849854,10.995915,0.866098,-117.785561,0.085647,0.000000
132.450012,45.952995,-117.963486,-0.000927,0.003386,0.086003,204.409134,10.413098,0.860028,-117.963486,0.085014,0.000000
132.830002,44.493668,-118.007965,-0.000910,0.003371,0.085621,197.917725,10.082410,0.856212,-118.007965,0.084381,0.000000
133.210007,41.175079,-118.007965,-0.000940,0.003344,0.084927,183.155899,9.330406,0.849274,-118.007965,0.083748,0.000000
133.590012,39.119217,-118.052444,-0.000940,0.003324,0.084442,174.010971,8.864541,0.844418,-118.052444,0.083115,0.000000
133.970001,35.091637,-118.052444,-0.000936,0.003284,0.083410,156.095398,7.951879,0.834098,-118.052444,0.082482,0.000000
134.350006,32.969482,-118.096924,-0.000957,0.003264,0.082907,146.655579,7.470992,0.829068,-118.096924,0.081849,0.000000
134.730011,29.873581,-118.274849,-0.000936,0.003233,0.082118,132.884323,6.769450,0.821176,-118.274849,0.081216,0.000000
135.110001,27.738770,-118.274849,-0.000953,0.003215,0.081658,123.388206,6.285695,0.816580,-118.274849,0.080583,0.000000
135.490005,25.014862,-118.230370,-0.000957,0.003188,0.080973,111.271667,5.668448,0.809729,-118.230370,0.079950,0.000000
135.870010,22.039604,-118.319328,-0.000966,0.003159,0.080236,98.037056,4.994246,0.802357,-118.319328,0.079316,0.000000
136.250000,19.604660,-118.363808,-0.000974,0.003135,0.079620,87.205887,4.442480,0.796200,-118.363808,0.078683,0.000000
136.630005,17.122803,-118.408295,-0.000979,0.003111,0.079013,76.166031,3.880083,0.790129,-118.408295,0.078050,0.000000
137.010010,14.610031,-118.408295,-0.000992,0.003086,0.078380,64.988663,3.310680,0.783799,-118.408295,0.077417,0.000000
137.389999,11.810532,-118.408295,-0.001000,0.003059,0.077703,52.535870,2.676305,0.777034,-118.408295,0.076775,0.000000
137.770004,9.237068,-118.497253,-0.000987,0.003034,0.077070,41.088531,2.093149,0.770703,-118.497253,0.076142,0.000000
138.150009,7.141357,-118.541733,-0.001009,0.003014,0.076550,31.766344,1.618255,0.765500,-118.541733,0.075509,0.000000
138.530014,4.866905,-118.586212,-0.001013,0.002991,0.075969,21.649076,1.102857,0.759690,-118.586212,0.074876,0.000000
138.910004,1.805634,-118.630699,-0.001030,0.002956,0.075084,8.031859,0.409162,0.750844,-118.630699,0.074243,0.000000
139.290009,-0.262527,-118.630699,-0.001048,0.002934,0.074521,-1.167781,-0.059490,0.745207,-118.630699,0.073610,0.000000
139.670013,-2.007462,-118.675179,-0.001056,0.002912,0.073957,-8.929635,-0.454897,0.739570,-118.675179,0.072977,0.000000
140.050003,-3.612762,-118.764137,-0.001056,0.002886,0.073315,-16.070370,-0.818664,0.733153,-118.764137,0.072344,0.000000
140.430008,-0.290085,-118.808617,-0.001134,0.002862,0.072691,-1.290362,-0.065734,0.726909,-118.808617,0.071711,0.000000
140.810013,-0.070755,-118.853104,-0.001164,0.002838,0.072075,-0.314734,-0.016033,0.720751,-118.853104,0.071078,0.000000
141.190002,0.013031,-118.808617,-0.001216,0.002820,0.071615,0.057965,0.002953,0.716155,-118.808617,0.070445,0.000000
141.570007,-0.004097,-118.897583,-0.001255,0.002784,0.070714,-0.018224,-0.000928,0.707136,-118.897583,0.069812,0.000000
141.950012,0.010048,-118.897583,-0.001281,0.002767,0.070271,0.044695,0.002277,0.702713,-118.897583,0.069179,0.000000
142.330002,0.030159,-119.031029,-0.001328,0.002746,0.069742,0.134154,0.006834,0.697423,-119.031029,0.068546,0.000000
142.710007,-0.005592,-119.031029,-0.001388,0.002713,0.068910,-0.024876,-0.001267,0.689098,-119.031029,0.067912,0.000000
143.090012,0.008560,-119.031029,-0.001414,0.002696,0.068476,0.038078,0.001940,0.684761,-119.031029,0.067279,0.000000
143.470001,0.004089,-119.075508,-0.001479,0.002656,0.067470,0.018190,0.000927,0.674702,-119.075508,0.066646,0.000000
143.850006,0.010048,-119.119987,-0.001500,0.002641,0.067071,0.044695,0.002277,0.670712,-119.119987,0.066013,0.000000
144.230011,0.015266,-119.208946,-0.001522,0.002627,0.066733,0.067908,0.003459,0.667330,-119.208946,0.065380,0.000000
144.610001,-0.001495,-119.253433,-0.001604,0.002583,0.065606,-0.006652,-0.000339,0.656056,-119.253433,0.064747,0.000000
144.990005,0.009308,-119.342392,-0.001638,0.002570,0.065285,0.041403,0.002109,0.652847,-119.342392,0.064114,0.000000
145.370010,-0.037239,-119.297913,-0.001677,0.002540,0.064504,-0.165648,-0.008438,0.645042,-119.297913,0.063481,0.000000
145.750000,-0.033142,-119.297913,-0.001712,0.002514,0.063863,-0.147423,-0.007510,0.638625,-119.297913,0.062848,0.000000
146.130005,-0.027184,-119.386871,-0.001763,0.002485,0.063108,-0.120918,-0.006160,0.631080,-119.386871,0.062215,0.000000
146.510010,-0.042824,-119.475838,-0.001794,0.002470,0.062744,-0.190490,-0.009704,0.627438,-119.475838,0.061582,0.000000
146.889999,-0.036125,-119.475838,-0.001841,0.002445,0.062093,-0.160693,-0.008186,0.620934,-119.475838,0.060949,0.000000
147.270004,-0.036125,-119.520317,-0.001884,0.002413,0.061287,-0.160693,-0.008186,0.612868,-119.520317,0.060316,0.000000
147.650009,-0.037613,-119.564796,-0.001919,0.002388,0.060662,-0.167311,-0.008523,0.606624,-119.564796,0.059682,0.000000
148.030014,-0.041336,-119.609276,-0.001944,0.002365,0.060073,-0.183872,-0.009367,0.600727,-119.609276,0.059049,0.000000
148.410004,-0.035004,-119.698242,-0.002005,0.002334,0.059292,-0.155704,-0.007932,0.592922,-119.698242,0.058408,0.000000
148.790009,-0.027184,-119.698242,-0.002035,0.002319,0.058911,-0.120918,-0.006160,0.589106,-119.698242,0.057775,0.000000
149.170013,-0.031281,-119.698242,-0.002082,0.002286,0.058061,-0.139143,-0.007088,0.580608,-119.698242,0.057141,0.000000
149.550003,-0.042084,-119.742722,-0.002117,0.002260,0.057393,-0.187198,-0.009536,0.573930,-119.742722,0.056508,0.000000
149.930008,-0.025696,-119.831680,-0.002126,0.002235,0.056769,-0.114301,-0.005823,0.567686,-119.831680,0.055875,0.000000
150.310013,-0.037987,-119.876160,-0.002156,0.002212,0.056188,-0.168974,-0.008608,0.561876,-119.876160,0.055242,0.000000
150.690002,-0.037239,-119.965126,-0.002186,0.002188,0.055563,-0.165648,-0.008438,0.555632,-119.965126,0.054609,0.000000
151.070007,-0.045433,-119.876160,-0.002229,0.002162,0.054913,-0.202096,-0.010295,0.549127,-119.876160,0.053976,0.000000
151.450012,-0.031281,-119.965126,-0.002246,0.002136,0.054262,-0.139143,-0.007088,0.542623,-119.965126,0.053343,0.000000
151.830002,-0.023087,-119.965126,-0.002281,0.002111,0.053621,-0.102694,-0.005231,0.536206,-119.965126,0.052710,0.000000
152.210007,-0.045433,-120.098564,-0.002307,0.002087,0.053014,-0.202096,-0.010295,0.530135,-120.098564,0.052077,0.000000
152.590012,-0.042450,-120.143051,-0.002324,0.002075,0.052693,-0.188827,-0.009619,0.526926,-120.143051,0.051444,0.000000
152.970001,-0.033142,-120.143051,-0.002371,0.002036,0.051704,-0.147423,-0.007510,0.517040,-120.143051,0.050811,0.000000
153.350006,-0.011917,-120.098564,-0.002393,0.002011,0.051080,-0.053010,-0.002700,0.510796,-120.098564,0.050178,0.000000
153.730011,-0.028305,-120.187531,-0.002419,0.001987,0.050473,-0.125907,-0.006414,0.504725,-120.187531,0.049545,0.000000
154.110001,-0.037987,-120.232010,-0.002449,0.001962,0.049831,-0.168974,-0.008608,0.498308,-120.232010,0.048912,0.000000
154.490005,-0.059212,-120.320976,-0.002483,0.001938,0.049232,-0.263387,-0.013418,0.492324,-120.320976,0.048278,0.000000
154.870010,-0.026817,-120.320976,-0.002509,0.001924,0.048877,-0.119289,-0.006077,0.488768,-120.320976,0.047645,0.000000
155.250000,-0.016762,-120.320976,-0.002557,0.001885,0.047871,-0.074560,-0.003798,0.478709,-120.320976,0.047012,0.000000
155.630005,-0.016388,-120.365456,-0.002565,0.001866,0.047385,-0.072897,-0.003714,0.473852,-120.365456,0.046379,0.000000
156.010010,-0.029045,-120.454414,-0.002596,0.001839,0.046700,-0.129199,-0.006582,0.467001,-120.454414,0.045746,0.000000
156.390015,-0.024582,-120.498894,-0.002660,0.001816,0.046128,-0.109346,-0.005570,0.461277,-120.498894,0.045113,0.000000
156.770004,-0.013039,-120.543381,-0.002665,0.001788,0.045425,-0.057999,-0.002955,0.454253,-120.543381,0.044480,0.000000
157.150009,-0.019363,-120.498894,-0.002703,0.001759,0.044688,-0.086133,-0.004388,0.446881,-120.498894,0.043847,0.000000
157.530014,-0.005219,-120.587860,-0.002729,0.001732,0.043994,-0.023213,-0.001183,0.439944,-120.587860,0.043890,0.000000
157.700012,-0.008194,-120.632339,-0.002721,0.001732,0.044003,-0.036449,-0.001857,0.440030,-120.632339,0.043890,0.000000