File: Data/compression 15/AutoNoHeating-17-15-reverse-longpurge-4_08262024_191610.csv
Time (sec),S:Load (lbs),S:HL1 (DIM),S:LVDT (in),S:Position (in),Ch:Position (mm),Ch:Load (N),Ch:Stress (MPa),Ch:Strain (mm/mm),Ch:HL1 (DIM),Set Point (),Cycles ()
0.210000,-0.005959,-125.480766,-0.009826,-0.004826,-0.122582,-0.026505,-0.001350,-1.225824,-125.480766,-0.122374,0.000000
0.580000,0.014519,-125.480766,-0.009813,-0.004737,-0.120310,0.064583,0.003290,-1.203102,-125.480766,-0.119582,0.000000
0.950000,-0.007454,-125.480766,-0.009675,-0.004509,-0.114535,-0.033157,-0.001689,-1.145345,-125.480766,-0.113424,0.000000
1.320000,-0.022346,-125.525246,-0.009421,-0.004269,-0.108429,-0.099402,-0.005064,-1.084292,-125.525246,-0.107250,0.000000
1.690000,-0.072243,-125.658684,-0.009179,-0.004029,-0.102333,-0.321352,-0.016370,-1.023326,-125.658684,-0.101092,0.000000
2.060000,-0.050270,-125.658684,-0.008925,-0.003782,-0.096071,-0.223612,-0.011391,-0.960713,-125.658684,-0.094935,0.000000
2.430000,-0.013779,-125.658684,-0.008670,-0.003538,-0.089862,-0.061291,-0.003122,-0.898619,-125.658684,-0.088761,0.000000
2.800000,0.018990,-125.747650,-0.008429,-0.003306,-0.083982,0.084470,0.004303,-0.839821,-125.747650,-0.082603,0.000000
3.170000,-0.000748,-125.836609,-0.008183,-0.003058,-0.077677,-0.003326,-0.000169,-0.776774,-125.836609,-0.076446,0.000000
3.540000,-0.028679,-125.881088,-0.007929,-0.002817,-0.071546,-0.127570,-0.006499,-0.715461,-125.881088,-0.070271,0.000000
3.910000,-0.017876,-125.836609,-0.007675,-0.002571,-0.065302,-0.079515,-0.004051,-0.653021,-125.836609,-0.064114,0.000000
4.280000,-0.011177,-125.881088,-0.007420,-0.002331,-0.059205,-0.049718,-0.002533,-0.592055,-125.881088,-0.057939,0.000000
4.650000,0.007446,-125.925575,-0.007157,-0.002088,-0.053040,0.033123,0.001687,-0.530395,-125.925575,-0.051782,0.000000
5.020000,-0.002235,-126.014534,-0.006890,-0.001840,-0.046743,-0.009944,-0.000507,-0.467435,-126.014534,-0.045625,0.000000
5.390000,-0.039474,-126.014534,-0.006657,-0.001603,-0.040708,-0.175591,-0.008945,-0.407076,-126.014534,-0.039450,0.000000
5.760000,-0.034637,-126.059013,-0.006394,-0.001359,-0.034507,-0.154075,-0.007849,-0.345069,-126.059013,-0.033293,0.000000
6.130000,-0.075226,-126.059013,-0.006157,-0.001111,-0.028211,-0.334621,-0.017046,-0.282109,-126.059013,-0.027118,0.000000
6.500000,-0.007080,-126.147980,-0.005924,-0.000872,-0.022149,-0.031494,-0.001604,-0.221489,-126.147980,-0.020961,0.000000
6.870000,0.026062,-126.192459,-0.005657,-0.000625,-0.015870,0.115930,0.005906,-0.158702,-126.192459,-0.014804,0.000000
7.240000,0.030159,-126.236938,-0.005424,-0.000388,-0.009860,0.134154,0.006834,-0.098604,-126.236938,-0.008629,0.000000
7.610000,0.145966,-126.281418,-0.005152,-0.000001,-0.000017,0.649287,0.033076,-0.000173,-126.281418,0.001240,0.000000
7.980000,0.123253,-126.192459,-0.005148,-0.000009,-0.000225,0.548256,0.027929,-0.002255,-126.192459,-0.000026,0.000000
8.350000,0.121017,-126.325897,-0.005165,-0.000009,-0.000225,0.538313,0.027423,-0.002255,-126.325897,0.000295,0.000000
8.720000,0.113571,-126.414864,-0.005152,-0.000005,-0.000121,0.505190,0.025736,-0.001214,-126.414864,0.000919,0.000000
9.090000,0.212250,-126.370384,-0.005122,0.000022,0.000564,0.944134,0.048096,0.005637,-126.370384,0.001535,0.000000
9.460000,0.379448,-126.414864,-0.005109,0.000049,0.001249,1.687869,0.085984,0.012488,-126.414864,0.002151,0.000000
9.830001,0.536217,-126.459343,-0.005092,0.000070,0.001786,2.385211,0.121508,0.017865,-126.459343,0.002766,0.000000
10.200001,0.747345,-126.503822,-0.005070,0.000093,0.002350,3.324357,0.169351,0.023502,-126.503822,0.003382,0.000000
10.570001,1.014709,-126.592789,-0.005057,0.000116,0.002949,4.513653,0.229936,0.029486,-126.592789,0.003998,0.000000
10.940001,1.357292,-126.548309,-0.005036,0.000146,0.003703,6.037537,0.307567,0.037031,-126.548309,0.004614,0.000000
11.310000,1.590027,-126.548309,-0.004997,0.000168,0.004267,7.072793,0.360305,0.042667,-126.548309,0.005229,0.000000
11.680000,1.933357,-126.592789,-0.004988,0.000188,0.004787,8.600002,0.438105,0.047871,-126.592789,0.005854,0.000000
12.050000,2.370522,-126.726227,-0.004975,0.000212,0.005394,10.544606,0.537168,0.053941,-126.726227,0.006470,0.000000
12.420001,2.972649,-126.815193,-0.004937,0.000238,0.006053,13.223001,0.673612,0.060532,-126.815193,0.007085,0.000000
12.790001,3.264214,-126.726227,-0.004915,0.000263,0.006669,14.519947,0.739681,0.066690,-126.726227,0.007701,0.000000
13.160001,3.994064,-126.770714,-0.004889,0.000290,0.007363,17.766485,0.905068,0.073627,-126.770714,0.008317,0.000000
13.530001,4.412613,-126.815193,-0.004859,0.000313,0.007952,19.628283,0.999912,0.079525,-126.815193,0.008932,0.000000
13.900001,4.916428,-126.859673,-0.004859,0.000334,0.008473,21.869362,1.114078,0.084728,-126.859673,0.009548,0.000000
14.270000,5.260872,-126.948631,-0.004842,0.000349,0.008872,23.401527,1.192131,0.088717,-126.948631,0.010164,0.000000
14.640000,6.113609,-126.904152,-0.004825,0.000384,0.009748,27.194693,1.385364,0.097476,-126.904152,0.010780,0.000000
15.010001,6.742546,-126.948631,-0.004794,0.000414,0.010511,29.992342,1.527883,0.105108,-126.948631,0.011404,0.000000
15.380001,7.168541,-126.993118,-0.004764,0.000436,0.011083,31.887262,1.624415,0.110831,-126.993118,0.012020,0.000000
15.750001,7.462715,-127.037598,-0.004760,0.000452,0.011473,33.195816,1.691075,0.114734,-127.037598,0.012635,0.000000
16.120001,8.080482,-127.126556,-0.004725,0.000478,0.012132,35.943783,1.831064,0.121325,-127.126556,0.013251,0.000000
16.490002,8.587654,-127.126556,-0.004708,0.000503,0.012783,38.199795,1.945990,0.127829,-127.126556,0.013867,0.000000
16.860001,8.984970,-127.171036,-0.004695,0.000522,0.013251,39.967144,2.036023,0.132512,-127.171036,0.014483,0.000000
17.230001,9.823181,-127.215523,-0.004674,0.000558,0.014170,43.695694,2.225965,0.141705,-127.215523,0.015098,0.000000
17.600000,10.016075,-127.260002,-0.004644,0.000578,0.014682,44.553726,2.269675,0.146821,-127.260002,0.015714,0.000000
17.970001,10.230560,-127.260002,-0.004622,0.000592,0.015029,45.507805,2.318278,0.150290,-127.260002,0.016330,0.000000
18.340000,11.168938,-127.260002,-0.004605,0.000626,0.015896,49.681915,2.530918,0.158963,-127.260002,0.016954,0.000000
18.710001,11.247505,-127.304482,-0.004587,0.000641,0.016278,50.031403,2.548721,0.162778,-127.304482,0.017570,0.000000
19.080002,12.388832,-127.348961,-0.004540,0.000681,0.017310,55.108276,2.807349,0.173098,-127.348961,0.018186,0.000000
19.450001,12.380264,-127.437927,-0.004523,0.000700,0.017769,55.070168,2.805408,0.177695,-127.437927,0.018801,0.000000
19.820002,12.875893,-127.437927,-0.004497,0.000726,0.018446,57.274830,2.917719,0.184459,-127.437927,0.019417,0.000000
20.190001,13.447853,-127.482407,-0.004488,0.000750,0.019044,59.819038,3.047327,0.190443,-127.482407,0.020033,0.000000
20.560001,14.000458,-127.437927,-0.004458,0.000777,0.019729,62.277145,3.172549,0.197294,-127.437927,0.020649,0.000000
20.930000,14.322556,-127.615852,-0.004445,0.000801,0.020345,63.709908,3.245538,0.203451,-127.615852,0.021264,0.000000
21.300001,14.657318,-127.660332,-0.004419,0.000825,0.020961,65.199005,3.321396,0.209608,-127.660332,0.021880,0.000000
21.670000,15.041237,-127.615852,-0.004381,0.000848,0.021533,66.906761,3.408393,0.215332,-127.615852,0.022505,0.000000
22.040001,15.340256,-127.660332,-0.004381,0.000870,0.022106,68.236862,3.476152,0.221056,-127.660332,0.023120,0.000000
22.410002,15.803108,-127.749290,-0.004355,0.000895,0.022730,70.295738,3.581036,0.227300,-127.749290,0.023736,0.000000
22.780001,16.498703,-127.838257,-0.004333,0.000924,0.023467,73.389893,3.738660,0.234671,-127.838257,0.024352,0.000000
23.150002,16.687866,-127.838257,-0.004303,0.000949,0.024100,74.231339,3.781524,0.241002,-127.838257,0.024967,0.000000
23.520000,16.959702,-127.838257,-0.004273,0.000969,0.024621,75.440521,3.843123,0.246205,-127.838257,0.025583,0.000000
23.890001,17.363350,-127.838257,-0.004255,0.000993,0.025228,77.236038,3.934591,0.252276,-127.838257,0.026199,0.000000
24.260000,17.582306,-127.971695,-0.004238,0.001013,0.025731,78.209999,3.984208,0.257306,-127.971695,0.026815,0.000000
24.630001,17.877968,-127.971695,-0.004217,0.001036,0.026312,79.525169,4.051206,0.263116,-127.971695,0.027430,0.000000
25.000002,18.965668,-127.971695,-0.004178,0.001070,0.027188,84.363503,4.297681,0.271875,-127.971695,0.028055,0.000000
25.370001,19.020409,-128.060654,-0.004152,0.001093,0.027751,84.607002,4.310086,0.277512,-128.060654,0.028670,0.000000
25.740002,19.071426,-128.105133,-0.004130,0.001113,0.028272,84.833939,4.321647,0.282716,-128.105133,0.029286,0.000000
26.110001,19.312721,-128.105133,-0.004117,0.001136,0.028861,85.907272,4.376325,0.288613,-128.105133,0.029902,0.000000
26.480001,19.876869,-128.194107,-0.004083,0.001162,0.029503,88.416733,4.504163,0.295030,-128.194107,0.030518,0.000000
26.850000,20.300629,-128.283066,-0.004053,0.001189,0.030205,90.301704,4.600188,0.302055,-128.283066,0.031133,0.000000
27.220001,20.283127,-128.283066,-0.004031,0.001212,0.030778,90.223854,4.596222,0.307778,-128.283066,0.031749,0.000000
27.590002,20.845032,-128.238586,-0.003988,0.001239,0.031463,92.723335,4.723552,0.314629,-128.238586,0.032365,0.000000
27.960001,20.310684,-128.372025,-0.003988,0.001249,0.031714,90.346436,4.602467,0.317144,-128.372025,0.032981,0.000000
28.330002,20.749336,-128.372025,-0.003954,0.001279,0.032495,92.297661,4.701867,0.324949,-128.372025,0.033605,0.000000
28.700001,21.787140,-128.416504,-0.003919,0.001312,0.033319,96.914040,4.937037,0.333188,-128.416504,0.034221,0.000000
29.070002,21.564087,-128.460983,-0.003885,0.001330,0.033770,95.921852,4.886492,0.337698,-128.460983,0.034836,0.000000
29.440001,21.884323,-128.505463,-0.003876,0.001356,0.034438,97.346329,4.959058,0.344375,-128.505463,0.035452,0.000000
29.810001,22.083916,-128.505463,-0.003850,0.001378,0.034993,98.234161,5.004287,0.349926,-128.505463,0.036068,0.000000
30.180002,23.019318,-128.594437,-0.003829,0.001409,0.035790,102.395042,5.216252,0.357904,-128.594437,0.036684,0.000000
30.550001,23.195076,-128.594437,-0.003786,0.001434,0.036415,103.176849,5.256080,0.364148,-128.594437,0.037299,0.000000
30.920002,23.169754,-128.594437,-0.003755,0.001457,0.037013,103.064217,5.250341,0.370132,-128.594437,0.037915,0.000000
31.290001,22.980591,-128.683395,-0.003742,0.001477,0.037525,102.222771,5.207477,0.375249,-128.683395,0.038531,0.000000
31.660002,22.909470,-128.727875,-0.003717,0.001491,0.037872,101.906410,5.191360,0.378717,-128.727875,0.039155,0.000000
32.030003,23.333229,-128.727875,-0.003695,0.001515,0.038470,103.791389,5.287385,0.384701,-128.727875,0.039771,0.000000
32.400002,24.630203,-128.772354,-0.003635,0.001556,0.039511,109.560616,5.581284,0.395108,-128.772354,0.040387,0.000000
32.770000,24.362465,-128.816833,-0.003630,0.001577,0.040066,108.369659,5.520614,0.400658,-128.816833,0.041002,0.000000
33.140003,24.142769,-128.861313,-0.003617,0.001595,0.040517,107.392403,5.470830,0.405168,-128.861313,0.041618,0.000000
33.510002,24.369537,-128.950272,-0.003579,0.001614,0.040985,108.401115,5.522216,0.409851,-128.950272,0.042234,0.000000
33.880001,25.633003,-128.994751,-0.003553,0.001649,0.041878,114.021294,5.808522,0.418783,-128.994751,0.042850,0.000000
34.250000,25.832588,-128.950272,-0.003514,0.001677,0.042607,114.909088,5.853748,0.426068,-128.950272,0.043465,0.000000
34.620003,25.783066,-128.994751,-0.003497,0.001702,0.043231,114.688805,5.842526,0.432312,-128.994751,0.044081,0.000000
34.990002,25.350739,-129.083725,-0.003475,0.001718,0.043630,112.765717,5.744559,0.436301,-129.083725,0.044705,0.000000
35.360001,25.698540,-129.128204,-0.003449,0.001743,0.044263,114.312813,5.823372,0.442632,-129.128204,0.045321,0.000000
35.730003,25.446442,-129.217163,-0.003406,0.001755,0.044575,113.191429,5.766246,0.445754,-129.217163,0.045937,0.000000
36.100002,26.916939,-129.128204,-0.003380,0.001797,0.045633,119.732521,6.099465,0.456334,-129.128204,0.046553,0.000000
36.470001,27.059929,-129.217163,-0.003350,0.001822,0.046284,120.368576,6.131867,0.462838,-129.217163,0.047168,0.000000
36.840000,26.789215,-129.217163,-0.003324,0.001842,0.046778,119.164383,6.070523,0.467782,-129.217163,0.047784,0.000000
37.210003,27.051369,-129.395081,-0.003316,0.001864,0.047333,120.330498,6.129928,0.473332,-129.395081,0.048400,0.000000
37.580002,27.294151,-129.395081,-0.003290,0.001887,0.047923,121.410446,6.184943,0.479229,-129.395081,0.049016,0.000000
37.950001,27.067009,-129.395081,-0.003234,0.001902,0.048322,120.400070,6.133471,0.483218,-129.395081,0.049640,0.000000
38.320004,28.495796,-129.395081,-0.003225,0.001941,0.049293,126.755630,6.457240,0.492931,-129.395081,0.050256,0.000000
38.690002,28.532295,-129.439575,-0.003178,0.001965,0.049900,126.917992,6.465510,0.499002,-129.439575,0.050871,0.000000
39.060001,28.617935,-129.573013,-0.003160,0.001988,0.050499,127.298935,6.484917,0.504986,-129.573013,0.051487,0.000000
39.430000,28.509575,-129.484055,-0.003139,0.002006,0.050950,126.816925,6.460362,0.509495,-129.484055,0.052103,0.000000
39.800003,28.727417,-129.528534,-0.003100,0.002030,0.051574,127.785934,6.509726,0.515739,-129.528534,0.052719,0.000000
40.170002,29.590950,-129.573013,-0.003083,0.002059,0.052311,131.627121,6.705405,0.523111,-129.573013,0.053334,0.000000
40.540001,30.096626,-129.661972,-0.003044,0.002089,0.053066,133.876480,6.819993,0.530655,-129.661972,0.053950,0.000000
40.910004,29.549240,-129.750931,-0.003018,0.002104,0.053447,131.441589,6.695953,0.534471,-129.750931,0.054566,0.000000
41.280003,29.660583,-129.795410,-0.003001,0.002129,0.054072,131.936859,6.721184,0.540715,-129.795410,0.055190,0.000000
41.650002,30.470490,-129.795410,-0.002962,0.002156,0.054765,135.539505,6.904712,0.547653,-129.795410,0.055806,0.000000
42.020000,30.976173,-129.795410,-0.002932,0.002185,0.055502,137.788895,7.019301,0.555024,-129.795410,0.056422,0.000000
42.390003,31.269974,-129.839890,-0.002906,0.002209,0.056118,139.095795,7.085877,0.561182,-129.839890,0.057037,0.000000
42.760002,31.210770,-129.928864,-0.002876,0.002230,0.056639,138.832443,7.072462,0.566385,-129.928864,0.057653,0.000000
43.130001,31.418182,-129.928864,-0.002854,0.002253,0.057220,139.755051,7.119462,0.572196,-129.928864,0.058269,0.000000
43.500004,32.033340,-129.973343,-0.002837,0.002278,0.057861,142.491409,7.258859,0.578613,-129.973343,0.058885,0.000000
43.870003,32.714783,-130.017822,-0.002807,0.002307,0.058598,145.522629,7.413276,0.585984,-130.017822,0.059500,0.000000
44.240002,32.954956,-130.017822,-0.002772,0.002333,0.059249,146.590973,7.467700,0.592489,-130.017822,0.060116,0.000000
44.610001,32.727066,-130.151260,-0.002733,0.002352,0.059743,145.577255,7.416059,0.597432,-130.151260,0.060740,0.000000
44.980003,33.140770,-130.106781,-0.002703,0.002376,0.060359,147.417511,7.509806,0.603589,-130.106781,0.061356,0.000000
45.350002,33.396591,-130.151260,-0.002682,0.002401,0.060992,148.555450,7.567776,0.609920,-130.151260,0.061972,0.000000
45.720001,33.542564,-130.240219,-0.002656,0.002425,0.061590,149.204773,7.600853,0.615904,-130.240219,0.062588,0.000000
46.090004,33.329941,-130.284698,-0.002630,0.002442,0.062024,148.258987,7.552673,0.620240,-130.284698,0.063203,0.000000
46.460003,34.728195,-130.329193,-0.002591,0.002475,0.062874,154.478729,7.869522,0.628739,-130.329193,0.063819,0.000000
46.830002,34.961678,-130.329193,-0.002561,0.002499,0.063481,155.517303,7.922429,0.634809,-130.329193,0.064435,0.000000
47.200001,34.840279,-130.329193,-0.002535,0.002519,0.063993,154.977295,7.894920,0.639926,-130.329193,0.065051,0.000000
47.570004,34.862251,-130.418152,-0.002505,0.002541,0.064530,155.075043,7.899899,0.645303,-130.418152,0.065666,0.000000
47.940002,35.702324,-130.462631,-0.002488,0.002569,0.065259,158.811874,8.090262,0.652587,-130.462631,0.066291,0.000000
48.310001,36.018097,-130.462631,-0.002466,0.002593,0.065866,160.216492,8.161818,0.658658,-130.462631,0.066906,0.000000
48.680004,36.579636,-130.507111,-0.002427,0.002623,0.066620,162.714340,8.289063,0.666203,-130.507111,0.067522,0.000000
49.050003,36.908813,-130.507111,-0.002389,0.002644,0.067158,164.178604,8.363656,0.671580,-130.507111,0.068138,0.000000
49.420002,36.286575,-130.551590,-0.002363,0.002657,0.067479,161.410751,8.222655,0.674788,-130.551590,0.068754,0.000000
49.790001,37.499390,-130.685028,-0.002333,0.002693,0.068398,166.805618,8.497483,0.683981,-130.685028,0.069369,0.000000
50.160004,38.288078,-130.685028,-0.002302,0.002720,0.069092,170.313873,8.676203,0.690919,-130.685028,0.069985,0.000000
50.530003,37.871765,-130.729523,-0.002285,0.002736,0.069499,168.462021,8.581864,0.694995,-130.729523,0.070601,0.000000
50.900002,38.224777,-130.774002,-0.002264,0.002762,0.070150,170.032303,8.661859,0.701499,-130.774002,0.071217,0.000000
51.270004,38.764343,-130.774002,-0.002233,0.002786,0.070774,172.432404,8.784125,0.707743,-130.774002,0.071841,0.000000
51.640003,39.875504,-130.907440,-0.002195,0.002816,0.071529,177.375092,9.035918,0.715288,-130.907440,0.072457,0.000000
52.010002,40.387512,-130.862961,-0.002160,0.002843,0.072214,179.652634,9.151941,0.722139,-130.862961,0.073072,0.000000
52.380001,40.076958,-130.951920,-0.002121,0.002863,0.072717,178.271210,9.081568,0.727169,-130.951920,0.073688,0.000000
52.750004,40.432945,-130.951920,-0.002091,0.002886,0.073307,179.854721,9.162236,0.733066,-130.951920,0.074304,0.000000
53.120003,39.017929,-130.951920,-0.002065,0.002890,0.073393,173.560410,8.841589,0.733933,-130.951920,0.074920,0.000000
53.490002,39.614471,-130.951920,-0.002035,0.002914,0.074026,176.213974,8.976768,0.740264,-130.951920,0.075535,0.000000
53.860004,42.183464,-131.129837,-0.002018,0.002962,0.075232,187.641418,9.558909,0.752318,-131.129837,0.076151,0.000000
54.230003,41.994675,-131.129837,-0.001988,0.002982,0.075735,186.801636,9.516129,0.757348,-131.129837,0.076767,0.000000
54.600002,42.118675,-131.129837,-0.001944,0.003005,0.076316,187.353226,9.544229,0.763159,-131.129837,0.077391,0.000000
54.970001,42.749847,-131.174332,-0.001936,0.003031,0.076984,190.160812,9.687254,0.769836,-131.174332,0.078007,0.000000
55.340004,43.141579,-131.218811,-0.001901,0.003055,0.077591,191.903320,9.776021,0.775907,-131.218811,0.078623,0.000000
55.710003,43.949257,-131.263290,-0.001867,0.003084,0.078328,195.496063,9.959044,0.783278,-131.263290,0.079238,0.000000
56.080002,44.083313,-131.307770,-0.001828,0.003106,0.078892,196.092377,9.989421,0.788915,-131.307770,0.079854,0.000000
56.450005,43.770149,-131.263290,-0.001794,0.003124,0.079351,194.699341,9.918458,0.793512,-131.263290,0.080470,0.000000
56.820004,44.381584,-131.396729,-0.001785,0.003150,0.080019,197.419144,10.057011,0.800189,-131.396729,0.081086,0.000000
57.190002,45.105476,-131.396729,-0.001755,0.003176,0.080669,200.639175,10.221046,0.806693,-131.396729,0.081701,0.000000
57.560001,45.886711,-131.485687,-0.001716,0.003202,0.081337,204.114288,10.398078,0.813371,-131.485687,0.082317,0.000000
57.930004,46.308983,-131.530167,-0.001694,0.003227,0.081961,205.992645,10.493765,0.819615,-131.530167,0.082941,0.000000
58.300003,46.093750,-131.530167,-0.001669,0.003245,0.082412,205.035248,10.444993,0.824125,-131.530167,0.083557,0.000000
58.670002,47.044792,-131.530167,-0.001630,0.003272,0.083098,209.265686,10.660501,0.830976,-131.530167,0.084173,0.000000
59.040001,47.157990,-131.663620,-0.001617,0.003291,0.083592,209.769211,10.686153,0.835919,-131.663620,0.084789,0.000000
59.410004,47.977951,-131.663620,-0.001600,0.003318,0.084268,213.416580,10.871959,0.842683,-131.663620,0.085404,0.000000
59.780003,49.024696,-131.708099,-0.001556,0.003348,0.085040,218.072739,11.109156,0.850402,-131.708099,0.086020,0.000000
60.150002,49.371742,-131.663620,-0.001535,0.003370,0.085587,219.616470,11.187798,0.855865,-131.663620,0.086636,0.000000
60.520004,49.519951,-131.797058,-0.001522,0.003388,0.086055,220.275742,11.221381,0.860548,-131.797058,0.087252,0.000000
60.890003,50.820274,-131.708099,-0.001500,0.003420,0.086861,226.059875,11.516039,0.868613,-131.708099,0.087876,0.000000
61.260002,51.001991,-131.841537,-0.001466,0.003437,0.087312,226.868195,11.557217,0.873123,-131.841537,0.088492,0.000000
61.630001,52.263214,-131.841537,-0.001436,0.003470,0.088127,232.478394,11.843014,0.881275,-131.841537,0.089107,0.000000
62.000004,53.050041,-131.886017,-0.001418,0.003493,0.088717,235.978363,12.021312,0.887172,-131.886017,0.089723,0.000000
62.370003,53.604874,-131.886017,-0.001397,0.003516,0.089307,238.446381,12.147038,0.893069,-131.886017,0.090339,0.000000
62.740002,54.035713,-131.930496,-0.001371,0.003540,0.089905,240.362854,12.244668,0.899053,-131.930496,0.090955,0.000000
63.110004,55.055267,-132.019470,-0.001345,0.003566,0.090582,244.898056,12.475701,0.905817,-132.019470,0.091570,0.000000
63.480003,56.202919,-132.019470,-0.001315,0.003591,0.091215,250.003067,12.735764,0.912148,-132.019470,0.092186,0.000000
63.850002,57.118584,-132.108429,-0.001302,0.003616,0.091857,254.076157,12.943256,0.918565,-132.108429,0.092802,0.000000
64.220001,57.962753,-132.063950,-0.001276,0.003640,0.092455,257.831207,13.134547,0.924549,-132.063950,0.093426,0.000000
64.590004,57.998497,-132.197388,-0.001255,0.003655,0.092828,257.990204,13.142647,0.928278,-132.197388,0.094042,0.000000
64.960007,59.260094,-132.241867,-0.001233,0.003684,0.093582,263.602051,13.428529,0.935823,-132.241867,0.094658,0.000000
65.330002,60.910080,-132.241867,-0.001212,0.003714,0.094337,270.941559,13.802422,0.943368,-132.241867,0.095273,0.000000
65.700005,61.963150,-132.241867,-0.001207,0.003738,0.094944,275.625854,14.041050,0.949439,-132.241867,0.095889,0.000000
66.070000,62.741035,-132.241867,-0.001186,0.003760,0.095499,279.086060,14.217321,0.954989,-132.241867,0.096505,0.000000
66.440002,63.942680,-132.330826,-0.001164,0.003786,0.096158,284.431244,14.489618,0.961580,-132.330826,0.097121,0.000000
66.810005,64.709770,-132.419785,-0.001143,0.003805,0.096644,287.843445,14.663444,0.966436,-132.419785,0.097736,0.000000
67.180000,65.402000,-132.464279,-0.001121,0.003823,0.097112,290.922638,14.820305,0.971119,-132.464279,0.098352,0.000000
67.550003,66.662117,-132.464279,-0.001112,0.003844,0.097650,296.527893,15.105852,0.976496,-132.464279,0.098942,0.000000
67.920006,65.204643,-132.464279,-0.001091,0.003841,0.097554,290.044739,14.775583,0.975542,-132.464279,294.500488,0.000000
68.290001,66.563438,-132.553238,-0.001078,0.003779,0.095985,296.088959,15.083491,0.959845,-132.553238,294.500488,0.000000
68.660004,65.363655,-132.642197,-0.001069,0.003830,0.097294,290.752045,14.811616,0.972941,-132.642197,294.500488,0.000000
69.030006,65.551704,-132.686676,-0.001056,0.003868,0.098248,291.588531,14.854228,0.982480,-132.686676,294.500488,0.000000
69.400002,64.550758,-132.642197,-0.001039,0.003872,0.098361,287.136108,14.627411,0.983607,-132.642197,294.500488,0.000000
69.770004,65.853691,-132.642197,-0.001048,0.003834,0.097389,292.931854,14.922660,0.973894,-132.642197,294.500488,0.000000
70.140007,65.261620,-132.731155,-0.001043,0.003890,0.098812,290.298187,14.788494,0.988117,-132.731155,294.500488,0.000000
70.510002,65.241508,-132.775635,-0.001018,0.003903,0.099133,290.208710,14.783937,0.991326,-132.775635,294.500488,0.000000
70.880005,65.216560,-132.775635,-0.001022,0.003910,0.099315,290.097748,14.778284,0.993147,-132.775635,294.500488,0.000000
71.250000,65.251945,-132.820114,-0.001013,0.003916,0.099471,290.255157,14.786302,0.994708,-132.820114,294.500488,0.000000
71.620003,65.220665,-132.864594,-0.001009,0.003922,0.099627,290.115997,14.779214,0.996269,-132.864594,294.500488,0.000000
71.990005,65.492500,-132.998047,-0.000996,0.003931,0.099835,291.325195,14.840813,0.998350,-132.998047,294.500488,0.000000
72.360001,65.100761,-132.953568,-0.001000,0.003932,0.099870,289.582642,14.752044,0.998697,-132.953568,294.500488,0.000000
72.730003,65.027031,-133.087006,-0.000979,0.003936,0.099965,289.254669,14.735335,0.999651,-133.087006,294.500488,0.000000
73.100006,65.487282,-132.998047,-0.000974,0.003945,0.100208,291.301971,14.839630,1.002079,-132.998047,294.500488,0.000000
73.470001,65.136513,-133.087006,-0.000970,0.003946,0.100234,289.741669,14.760145,1.002339,-133.087006,294.500488,0.000000
73.840004,65.408333,-133.087006,-0.000961,0.003952,0.100390,290.950806,14.821740,1.003900,-133.087006,294.500488,0.000000
74.210007,65.161461,-133.220444,-0.000970,0.003956,0.100485,289.852661,14.765799,1.004854,-133.220444,294.500488,0.000000
74.580002,65.181938,-133.175964,-0.000953,0.003958,0.100537,289.943756,14.770438,1.005375,-133.175964,294.500488,0.000000
74.950005,65.605690,-133.220444,-0.000957,0.003967,0.100754,291.828674,14.866462,1.007543,-133.220444,294.500488,0.000000
75.320007,65.336845,-133.264923,-0.000940,0.003966,0.100746,290.632812,14.805541,1.007456,-133.264923,294.500488,0.000000
75.690002,65.036705,-133.353897,-0.000949,0.003966,0.100746,289.297699,14.737528,1.007456,-133.353897,294.500488,0.000000
76.060005,64.736198,-133.353897,-0.000970,0.003966,0.100746,287.960999,14.669432,1.007456,-133.353897,294.500488,0.000000
76.430000,64.453941,-133.353897,-0.000944,0.003966,0.100746,286.705444,14.605472,1.007456,-133.353897,294.500488,0.000000
76.800003,64.198494,-133.487335,-0.000944,0.003967,0.100763,285.569153,14.547587,1.007630,-133.487335,294.500488,0.000000
77.170006,66.023491,-133.442856,-0.000918,0.003791,0.096279,293.687164,14.961137,0.962794,-133.442856,294.500488,0.000000
77.540001,65.734169,-133.487335,-0.000927,0.003808,0.096730,292.400177,14.895576,0.967304,-133.487335,294.500488,0.000000
77.910004,65.411690,-133.531815,-0.000914,0.003918,0.099514,290.965729,14.822501,0.995142,-133.531815,294.500488,0.000000
78.280006,65.276894,-133.576294,-0.000914,0.003960,0.100581,290.366119,14.791956,1.005808,-133.576294,294.500488,0.000000
78.650002,65.380409,-133.576294,-0.000927,0.003982,0.101145,290.826599,14.815413,1.011445,-133.576294,294.500488,0.000000
79.020004,65.317101,-133.665253,-0.000914,0.003987,0.101266,290.544983,14.801066,1.012659,-133.665253,294.500488,0.000000
79.390007,65.204643,-133.665253,-0.000918,0.003988,0.101292,290.044739,14.775583,1.012920,-133.665253,294.500488,0.000000
79.760002,65.200920,-133.709732,-0.000927,0.003991,0.101379,290.028168,14.774739,1.013787,-133.709732,294.500488,0.000000
80.130005,65.162193,-133.754227,-0.000923,0.003994,0.101457,289.855927,14.765965,1.014567,-133.754227,294.500488,0.000000
80.500008,65.250450,-133.798706,-0.000914,0.003998,0.101543,290.248505,14.785963,1.015435,-133.798706,294.500488,0.000000
80.870003,65.169273,-133.798706,-0.000927,0.004000,0.101604,289.887421,14.767569,1.016042,-133.798706,294.500488,0.000000
81.240005,65.283226,-133.887665,-0.000918,0.004002,0.101656,290.394287,14.793390,1.016562,-133.887665,294.500488,0.000000
81.610001,65.212090,-133.932144,-0.000910,0.004004,0.101700,290.077850,14.777270,1.016996,-133.932144,294.500488,0.000000
81.980003,65.130547,-133.976624,-0.000914,0.004005,0.101717,289.715149,14.758793,1.017169,-133.976624,294.500488,0.000000
82.350006,65.440727,-133.976624,-0.000897,0.004010,0.101847,291.094879,14.829081,1.018470,-133.976624,294.500488,0.000000
82.720001,65.337593,-134.110062,-0.000910,0.004010,0.101847,290.636139,14.805711,1.018470,-134.110062,294.500488,0.000000
83.090004,65.238914,-134.110062,-0.000918,0.004010,0.101864,290.197174,14.783349,1.018643,-134.110062,294.500488,0.000000
83.460007,65.199806,-134.154541,-0.000905,0.004012,0.101899,290.023224,14.774487,1.018990,-134.154541,294.500488,0.000000
83.830002,65.447060,-134.154541,-0.000888,0.004017,0.102020,291.123047,14.830516,1.020204,-134.154541,294.500488,0.000000
84.200005,65.400520,-134.243515,-0.000884,0.004017,0.102020,290.916046,14.819970,1.020204,-134.243515,294.500488,0.000000
84.570007,65.282845,-134.243515,-0.000888,0.004017,0.102020,290.392609,14.793304,1.020204,-134.243515,294.500488,0.000000
84.940002,65.651131,-134.243515,-0.000901,0.004023,0.102185,292.030823,14.876760,1.021852,-134.243515,294.500488,0.000000
85.310005,65.612404,-134.332474,-0.000888,0.004023,0.102185,291.858551,14.867983,1.021852,-134.332474,294.500488,0.000000
85.680000,65.520424,-134.376953,-0.000905,0.004023,0.102185,291.449402,14.847140,1.021852,-134.376953,294.500488,0.000000
86.050003,65.387108,-134.376953,-0.000901,0.004023,0.102185,290.856384,14.816931,1.021852,-134.376953,294.500488,0.000000
86.420006,65.286949,-134.465912,-0.000897,0.004023,0.102185,290.410858,14.794234,1.021852,-134.465912,294.500488,0.000000
86.790001,65.225868,-134.421432,-0.000888,0.004026,0.102263,290.139160,14.780393,1.022632,-134.421432,294.500488,0.000000
87.160004,65.344292,-134.510391,-0.000892,0.004027,0.102298,290.665924,14.807228,1.022979,-134.510391,294.500488,0.000000
87.530006,65.360680,-134.554871,-0.000880,0.004029,0.102324,290.738831,14.810942,1.023240,-134.554871,294.500488,0.000000
87.900002,65.437004,-134.599365,-0.000884,0.004031,0.102385,291.078339,14.828237,1.023847,-134.599365,294.500488,0.000000
88.270004,65.383385,-134.643845,-0.000871,0.004031,0.102385,290.839813,14.816087,1.023847,-134.643845,294.500488,0.000000
88.640007,65.337212,-134.643845,-0.000875,0.004031,0.102393,290.634430,14.805623,1.023933,-134.643845,294.500488,0.000000
89.010002,65.289543,-134.688324,-0.000875,0.004032,0.102411,290.422394,14.794822,1.024107,-134.688324,294.500488,0.000000
89.380005,65.476479,-134.732803,-0.000884,0.004035,0.102497,291.253937,14.837182,1.024974,-134.732803,294.500488,0.000000
89.750008,65.443718,-134.866241,-0.000884,0.004035,0.102497,291.108185,14.829759,1.024974,-134.866241,294.500488,0.000000
90.120003,65.345772,-134.777283,-0.000871,0.004035,0.102497,290.672516,14.807564,1.024974,-134.777283,294.500488,0.000000
90.490005,65.282478,-134.821762,-0.000871,0.004036,0.102506,290.390961,14.793221,1.025061,-134.821762,294.500488,0.000000
90.860001,65.278755,-134.866241,-0.000888,0.004037,0.102549,290.374420,14.792377,1.025494,-134.866241,294.500488,0.000000
91.230003,65.299980,-134.910721,-0.000884,0.004038,0.102575,290.468811,14.797187,1.025755,-134.910721,294.500488,0.000000
91.600006,65.238533,-134.955200,-0.000875,0.004038,0.102575,290.195496,14.783262,1.025755,-134.955200,294.500488,0.000000
91.970001,65.168526,-134.999680,-0.000867,0.004038,0.102575,289.884094,14.767399,1.025755,-134.999680,294.500488,0.000000
92.340004,65.381905,-134.999680,-0.000875,0.004043,0.102697,290.833252,14.815751,1.026969,-134.999680,294.500488,0.000000
92.710007,65.418388,-135.044174,-0.000862,0.004043,0.102697,290.995514,14.824019,1.026969,-135.044174,294.500488,0.000000
93.080002,65.363655,-135.088654,-0.000875,0.004043,0.102697,290.752045,14.811616,1.026969,-135.088654,294.500488,0.000000
93.450005,65.302589,-135.133133,-0.000862,0.004043,0.102697,290.480438,14.797779,1.026969,-135.133133,294.500488,0.000000
93.820007,65.236671,-135.177612,-0.000858,0.004043,0.102697,290.187195,14.782842,1.026969,-135.177612,294.500488,0.000000
94.190002,65.162575,-135.222092,-0.000867,0.004043,0.102697,289.857605,14.766050,1.026969,-135.222092,294.500488,0.000000
94.560005,65.098900,-135.222092,-0.000875,0.004044,0.102706,289.574371,14.751621,1.027055,-135.222092,294.500488,0.000000
94.930008,65.019951,-135.311050,-0.000862,0.004044,0.102706,289.223175,14.733731,1.027055,-135.311050,294.500488,0.000000
95.300003,65.075066,-135.400009,-0.000862,0.004046,0.102758,289.468353,14.746221,1.027576,-135.400009,294.500488,0.000000
95.670006,65.039314,-135.444489,-0.000849,0.004046,0.102758,289.309326,14.738119,1.027576,-135.444489,294.500488,0.000000
96.040001,64.980110,-135.355530,-0.000862,0.004046,0.102758,289.045959,14.724703,1.027576,-135.355530,294.500488,0.000000
96.410004,64.922768,-135.444489,-0.000862,0.004046,0.102758,288.790894,14.711709,1.027576,-135.444489,294.500488,0.000000
96.780006,64.869148,-135.444489,-0.000867,0.004050,0.102879,288.552368,14.699559,1.028790,-135.444489,294.500488,0.000000
97.150002,65.747566,-135.533463,-0.000862,0.004056,0.103018,292.459778,14.898612,1.030177,-135.533463,294.500488,0.000000
97.520004,65.757622,-135.577942,-0.000849,0.004056,0.103018,292.504517,14.900890,1.030177,-135.577942,294.500488,0.000000
97.890007,65.683525,-135.577942,-0.000854,0.004056,0.103018,292.174927,14.884100,1.030177,-135.577942,294.500488,0.000000
98.260002,65.620216,-135.622421,-0.000858,0.004056,0.103018,291.893311,14.869754,1.030177,-135.622421,294.500488,0.000000
98.630005,65.579262,-135.711380,-0.000854,0.004056,0.103018,291.711121,14.860474,1.030177,-135.711380,294.500488,0.000000
99.000008,65.533455,-135.800339,-0.000871,0.004056,0.103018,291.507355,14.850093,1.030177,-135.800339,294.500488,0.000000
99.370003,65.466805,-135.755859,-0.000849,0.004056,0.103026,291.210876,14.834991,1.030264,-135.755859,294.500488,0.000000
99.740005,65.414299,-135.755859,-0.000841,0.004056,0.103026,290.977325,14.823092,1.030264,-135.755859,294.500488,0.000000
100.110008,65.346519,-135.844818,-0.000849,0.004056,0.103026,290.675842,14.807734,1.030264,-135.844818,294.500488,0.000000
100.480003,65.282478,-135.844818,-0.000849,0.004056,0.103026,290.390961,14.793221,1.030264,-135.844818,294.500488,0.000000
100.850006,65.234810,-135.933792,-0.000875,0.004056,0.103035,290.178925,14.782419,1.030351,-135.933792,294.500488,0.000000
101.220001,65.189751,-135.978271,-0.000854,0.004056,0.103035,289.978485,14.772208,1.030351,-135.978271,294.500488,0.000000
101.590004,65.135765,-135.978271,-0.000849,0.004057,0.103044,289.738342,14.759975,1.030438,-135.978271,294.500488,0.000000
101.960007,65.090706,-136.022751,-0.000841,0.004057,0.103044,289.537933,14.749764,1.030438,-136.022751,294.500488,0.000000
102.330002,65.054588,-136.111710,-0.000858,0.004057,0.103044,289.377258,14.741581,1.030438,-136.111710,294.500488,0.000000
102.700005,65.004692,-136.111710,-0.000849,0.004057,0.103044,289.155304,14.730273,1.030438,-136.111710,294.500488,0.000000
103.070007,64.943245,-136.156189,-0.000849,0.004057,0.103044,288.881989,14.716350,1.030438,-136.156189,294.500488,0.000000
103.440002,64.891853,-136.156189,-0.000841,0.004057,0.103044,288.653381,14.704704,1.030438,-136.156189,294.500488,0.000000
103.810005,64.835258,-136.156189,-0.000858,0.004057,0.103044,288.401642,14.691880,1.030438,-136.156189,294.500488,0.000000
104.180008,64.787971,-136.245148,-0.000854,0.004057,0.103044,288.191284,14.681164,1.030438,-136.245148,294.500488,0.000000
104.550003,66.010094,-136.289627,-0.000841,0.004068,0.103321,293.627563,14.958100,1.033213,-136.289627,294.500488,0.000000
104.920006,65.940086,-136.378601,-0.000849,0.004068,0.103321,293.316162,14.942237,1.033213,-136.378601,294.500488,0.000000
105.290009,65.845131,-136.378601,-0.000841,0.004068,0.103321,292.893768,14.920719,1.033213,-136.378601,294.500488,0.000000
105.660004,65.833580,-136.423080,-0.000836,0.004068,0.103321,292.842377,14.918102,1.033213,-136.423080,294.500488,0.000000
106.030006,65.758369,-136.423080,-0.000845,0.004068,0.103321,292.507843,14.901059,1.033213,-136.423080,294.500488,0.000000
106.400002,65.703255,-136.467560,-0.000845,0.004068,0.103321,292.262665,14.888570,1.033213,-136.467560,294.500488,0.000000
106.770004,65.644417,-136.600998,-0.000841,0.004068,0.103321,292.000946,14.875237,1.033213,-136.600998,294.500488,0.000000
107.140007,65.588188,-136.556519,-0.000836,0.004068,0.103321,291.750824,14.862496,1.033213,-136.556519,294.500488,0.000000
107.510002,65.548729,-136.600998,-0.000836,0.004068,0.103321,291.575317,14.853555,1.033213,-136.600998,294.500488,0.000000
107.880005,65.508125,-136.600998,-0.000828,0.004068,0.103321,291.394684,14.844353,1.033213,-136.600998,294.500488,0.000000
108.250008,65.466423,-136.645477,-0.000845,0.004068,0.103330,291.209198,14.834903,1.033299,-136.645477,294.500488,0.000000
108.620003,65.402000,-136.689957,-0.000841,0.004068,0.103330,290.922638,14.820305,1.033299,-136.689957,294.500488,0.000000
108.990005,65.369606,-136.689957,-0.000832,0.004068,0.103339,290.778534,14.812964,1.033386,-136.689957,294.500488,0.000000
109.360008,65.332741,-136.778931,-0.000845,0.004068,0.103339,290.614532,14.804610,1.033386,-136.778931,294.500488,0.000000
109.730003,65.297005,-136.867889,-0.000845,0.004068,0.103339,290.455597,14.796514,1.033386,-136.867889,294.500488,0.000000
110.100006,65.259010,-136.823410,-0.000845,0.004068,0.103339,290.286591,14.787904,1.033386,-136.823410,294.500488,0.000000
110.470009,65.212090,-136.912369,-0.000845,0.004068,0.103339,290.077850,14.777270,1.033386,-136.912369,294.500488,0.000000
110.840004,65.179695,-136.912369,-0.000832,0.004068,0.103339,289.933777,14.769930,1.033386,-136.912369,294.500488,0.000000
111.210007,65.135765,-136.912369,-0.000832,0.004068,0.103339,289.738342,14.759975,1.033386,-136.912369,294.500488,0.000000
111.580002,65.087730,-137.001328,-0.000832,0.004068,0.103339,289.524689,14.749090,1.033386,-137.001328,294.500488,0.000000
111.950005,65.047508,-136.956848,-0.000849,0.004068,0.103339,289.345764,14.739976,1.033386,-136.956848,294.500488,0.000000
112.320007,64.999840,-137.090286,-0.000841,0.004068,0.103339,289.133728,14.729175,1.033386,-137.090286,294.500488,0.000000
112.690002,64.961861,-137.179260,-0.000836,0.004069,0.103347,288.964783,14.720568,1.033473,-137.179260,294.500488,0.000000
113.060005,64.942131,-137.179260,-0.000823,0.004069,0.103347,288.877014,14.716098,1.033473,-137.179260,294.500488,0.000000
113.430008,65.873055,-137.134766,-0.000841,0.004081,0.103668,293.017975,14.927048,1.036682,-137.134766,294.500488,0.000000
113.800003,65.898384,-137.179260,-0.000845,0.004081,0.103668,293.130646,14.932788,1.036682,-137.179260,294.500488,0.000000
114.170006,65.911034,-137.312698,-0.000828,0.004081,0.103668,293.186920,14.935654,1.036682,-137.312698,294.500488,0.000000
114.540009,65.876778,-137.312698,-0.000836,0.004081,0.103668,293.034546,14.927892,1.036682,-137.312698,294.500488,0.000000
114.910004,65.882744,-137.268219,-0.000819,0.004081,0.103668,293.061096,14.929243,1.036682,-137.268219,294.500488,0.000000
115.280006,65.869713,-137.357178,-0.000823,0.004081,0.103668,293.003113,14.926290,1.036682,-137.357178,294.500488,0.000000
115.650009,65.862999,-137.312698,-0.000832,0.004081,0.103668,292.973267,14.924768,1.036682,-137.312698,294.500488,0.000000
116.020004,65.834709,-137.490616,-0.000823,0.004081,0.103668,292.847412,14.918358,1.036682,-137.490616,294.500488,0.000000
116.390007,65.775124,-137.490616,-0.000832,0.004081,0.103668,292.582367,14.904856,1.036682,-137.490616,294.500488,0.000000
116.760002,65.756874,-137.535095,-0.000828,0.004081,0.103668,292.501190,14.900721,1.036682,-137.535095,294.500488,0.000000
117.130005,65.731178,-137.535095,-0.000828,0.004081,0.103668,292.386871,14.894898,1.036682,-137.535095,294.500488,0.000000
117.500008,65.671227,-137.579575,-0.000841,0.004081,0.103668,292.120209,14.881313,1.036682,-137.579575,294.500488,0.000000
117.870003,65.648521,-137.579575,-0.000828,0.004081,0.103668,292.019196,14.876167,1.036682,-137.579575,294.500488,0.000000
118.240005,65.592659,-137.668549,-0.000828,0.004081,0.103668,291.770721,14.863509,1.036682,-137.668549,294.500488,0.000000
118.610008,65.571434,-137.668549,-0.000811,0.004081,0.103668,291.676300,14.858700,1.036682,-137.668549,294.500488,0.000000
118.980003,65.548729,-137.757507,-0.000823,0.004081,0.103668,291.575317,14.853555,1.036682,-137.757507,294.500488,0.000000
119.350006,65.516319,-137.713028,-0.000828,0.004081,0.103668,291.431152,14.846210,1.036682,-137.713028,294.500488,0.000000
119.720009,65.488029,-137.757507,-0.000841,0.004081,0.103668,291.305298,14.839800,1.036682,-137.757507,294.500488,0.000000
120.090004,65.441856,-137.846466,-0.000828,0.004081,0.103668,291.099915,14.829336,1.036682,-137.846466,294.500488,0.000000
120.460007,65.404991,-137.890945,-0.000823,0.004081,0.103668,290.935944,14.820983,1.036682,-137.890945,294.500488,0.000000
120.830009,65.383018,-137.846466,-0.000811,0.004081,0.103668,290.838196,14.816004,1.036682,-137.846466,294.500488,0.000000
121.200005,65.337959,-137.935425,-0.000836,0.004081,0.103668,290.637756,14.805793,1.036682,-137.935425,294.500488,0.000000
121.570007,65.302589,-137.979904,-0.000828,0.004081,0.103668,290.480438,14.797779,1.036682,-137.979904,294.500488,0.000000
121.940002,65.277260,-138.024384,-0.000836,0.004081,0.103668,290.367767,14.792039,1.036682,-138.024384,294.500488,0.000000
122.310005,65.254555,-138.024384,-0.000823,0.004081,0.103668,290.266754,14.786894,1.036682,-138.024384,294.500488,0.000000
122.680008,65.228477,-138.068878,-0.000819,0.004081,0.103668,290.150757,14.780985,1.036682,-138.068878,294.500488,0.000000
123.050003,65.191246,-138.024384,-0.000832,0.004081,0.103668,289.985138,14.772547,1.036682,-138.024384,294.500488,0.000000
123.420006,65.154381,-138.113358,-0.000828,0.004081,0.103668,289.821167,14.764194,1.036682,-138.113358,294.500488,0.000000
123.790009,65.120491,-138.157837,-0.000828,0.004081,0.103668,289.670410,14.756514,1.036682,-138.157837,294.500488,0.000000
124.160004,65.098518,-138.246796,-0.000815,0.004082,0.103677,289.572662,14.751535,1.036768,-138.246796,294.500488,0.000000
124.530006,65.063896,-138.157837,-0.000819,0.004082,0.103677,289.418671,14.743690,1.036768,-138.157837,294.500488,0.000000
124.900009,65.031868,-138.246796,-0.000823,0.004082,0.103677,289.276184,14.736432,1.036768,-138.246796,294.500488,0.000000
125.270004,65.018837,-138.291275,-0.000811,0.004082,0.103677,289.218231,14.733479,1.036768,-138.291275,294.500488,0.000000
125.640007,64.995369,-138.335754,-0.000811,0.004082,0.103677,289.113831,14.728161,1.036768,-138.335754,294.500488,0.000000
126.010010,64.958138,-138.424713,-0.000828,0.004082,0.103677,288.948212,14.719725,1.036768,-138.424713,294.500488,0.000000
126.380005,64.938026,-138.424713,-0.000823,0.004082,0.103677,288.858765,14.715167,1.036768,-138.424713,294.500488,0.000000
126.750008,64.911217,-138.424713,-0.000811,0.004082,0.103677,288.739502,14.709092,1.036768,-138.424713,294.500488,0.000000
127.120003,64.871376,-138.469208,-0.000819,0.004082,0.103677,288.562286,14.700065,1.036768,-138.469208,294.500488,0.000000
127.490005,64.834511,-138.513687,-0.000819,0.004082,0.103677,288.398315,14.691710,1.036768,-138.513687,294.500488,0.000000
127.860008,64.802116,-138.602646,-0.000811,0.004082,0.103677,288.254211,14.684369,1.036768,-138.602646,294.500488,0.000000
128.230011,64.782005,-138.602646,-0.000828,0.004082,0.103677,288.164764,14.679812,1.036768,-138.602646,1681.640991,0.000000
128.600006,64.600655,-138.602646,-0.000811,0.004071,0.103408,287.358063,14.638718,1.034080,-138.602646,0.103191,0.000000
128.970001,64.590233,-138.691605,-0.000815,0.004052,0.102931,287.311707,14.636355,1.029310,-138.691605,0.102567,0.000000
129.340012,64.474434,-138.647125,-0.000815,0.004035,0.102480,286.796600,14.610115,1.024801,-138.647125,0.101951,0.000000
129.710007,64.455070,-138.825043,-0.000823,0.004007,0.101769,286.710480,14.605727,1.017689,-138.825043,0.101335,0.000000
130.080002,64.401817,-138.869522,-0.000811,0.003988,0.101292,286.473602,14.593660,1.012920,-138.869522,0.100720,0.000000
130.450012,64.340370,-138.736084,-0.000819,0.003962,0.100624,286.200256,14.579737,1.006242,-138.736084,0.100104,0.000000
130.820007,64.293831,-138.825043,-0.000811,0.003938,0.100034,285.993256,14.569191,1.000345,-138.825043,0.099488,0.000000
131.190002,64.306862,-138.869522,-0.000802,0.003920,0.099566,286.051208,14.572143,0.995662,-138.869522,0.098872,0.000000
131.560013,64.190681,-139.002975,-0.000819,0.003889,0.098768,285.534424,14.545816,0.987683,-139.002975,0.098257,0.000000
131.930008,64.108757,-139.002975,-0.000806,0.003876,0.098439,285.169983,14.527252,0.984388,-139.002975,0.097641,0.000000
132.300003,63.552803,-139.047455,-0.000802,0.003845,0.097658,282.696991,14.401271,0.976583,-139.047455,0.097017,0.000000
132.670013,62.677361,-139.002975,-0.000802,0.003820,0.097034,278.802826,14.202893,0.970339,-139.002975,0.096401,0.000000
133.040009,61.529709,-139.091934,-0.000802,0.003794,0.096375,273.697815,13.942831,0.963748,-139.091934,0.095785,0.000000
133.410004,60.602127,-139.136414,-0.000806,0.003778,0.095959,269.571716,13.732638,0.959585,-139.136414,0.095169,0.000000
133.779999,59.353188,-139.225372,-0.000793,0.003759,0.095482,264.016174,13.449625,0.954815,-139.225372,0.094554,0.000000
134.150009,57.642883,-139.180893,-0.000793,0.003735,0.094866,256.408356,13.062064,0.948658,-139.180893,0.093938,0.000000
134.520004,55.769478,-139.180893,-0.000793,0.003710,0.094241,248.075027,12.637545,0.942414,-139.180893,0.093322,0.000000
134.889999,54.116890,-139.269852,-0.000798,0.003693,0.093808,240.723953,12.263062,0.938078,-139.269852,0.092706,0.000000
135.260010,51.520706,-139.358826,-0.000793,0.003664,0.093071,229.175552,11.674759,0.930707,-139.358826,0.092091,0.000000
135.630005,49.070869,-139.358826,-0.000785,0.003638,0.092412,218.278122,11.119618,0.924116,-139.358826,0.091466,0.000000
136.000000,46.938293,-139.358826,-0.000793,0.003621,0.091969,208.791962,10.636370,0.919693,-139.358826,0.090851,0.000000
136.370010,43.774239,-139.358826,-0.000772,0.003589,0.091163,194.717545,9.919384,0.911628,-139.358826,0.090235,0.000000
136.740005,41.125931,-139.492264,-0.000793,0.003565,0.090538,182.937271,9.319269,0.905384,-139.492264,0.089619,0.000000
137.110001,38.757637,-139.492264,-0.000802,0.003544,0.090018,172.402573,8.782606,0.900180,-139.492264,0.089003,0.000000
137.480011,36.823540,-139.536743,-0.000793,0.003526,0.089558,163.799286,8.344333,0.895584,-139.536743,0.088388,0.000000
137.850006,33.592461,-139.625702,-0.000802,0.003497,0.088813,149.426727,7.612160,0.888126,-139.625702,0.087772,0.000000
138.220001,31.785339,-139.581223,-0.000806,0.003480,0.088396,141.388245,7.202661,0.883963,-139.581223,0.087156,0.000000
138.590012,27.694084,-139.714661,-0.000806,0.003440,0.087382,123.189438,6.275569,0.873817,-139.714661,0.086540,0.000000
138.960007,25.608047,-139.670181,-0.000815,0.003420,0.086879,113.910286,5.802866,0.868787,-139.670181,0.085916,0.000000
139.330002,23.671341,-139.759155,-0.000823,0.003403,0.086445,105.295380,5.364002,0.864451,-139.759155,0.085300,0.000000
139.700012,20.866257,-139.892593,-0.000811,0.003373,0.085673,92.817749,4.728362,0.856732,-139.892593,0.084685,0.000000
140.070007,18.428711,-139.759155,-0.000823,0.003353,0.085170,81.974998,4.176006,0.851702,-139.759155,0.084069,0.000000
140.440002,14.808876,-139.848114,-0.000823,0.003320,0.084320,65.873169,3.355739,0.843204,-139.848114,0.083453,0.000000
140.810013,12.514320,-139.892593,-0.000828,0.003299,0.083783,55.666477,2.835786,0.837827,-139.892593,0.082837,0.000000
141.180008,10.102089,-139.981552,-0.000841,0.003275,0.083184,44.936337,2.289166,0.831843,-139.981552,0.082222,0.000000
141.550003,7.797104,-139.937073,-0.000836,0.003253,0.082621,34.683250,1.766849,0.826206,-139.937073,0.081606,0.000000
141.920013,5.407959,-140.026031,-0.000845,0.003226,0.081953,24.055803,1.225461,0.819528,-140.026031,0.080990,0.000000
142.290009,2.549629,-140.070511,-0.000862,0.003198,0.081242,11.341317,0.577754,0.812417,-140.070511,0.080366,0.000000
142.660004,0.466583,-140.070511,-0.000849,0.003177,0.080704,2.075466,0.105729,0.807040,-140.070511,0.079750,0.000000
143.030014,-1.229950,-140.159470,-0.000871,0.003158,0.080210,-5.471091,-0.278711,0.802097,-140.159470,0.079134,0.000000
143.400009,-1.371078,-140.159470,-0.000905,0.003130,0.079490,-6.098862,-0.310691,0.794899,-140.159470,0.078519,0.000000
143.770004,-0.213371,-140.203964,-0.000949,0.003100,0.078735,-0.949123,-0.048351,0.787354,-140.203964,0.077903,0.000000
144.139999,-0.058464,-140.203964,-0.000979,0.003079,0.078198,-0.260061,-0.013248,0.781977,-140.203964,0.077287,0.000000
144.510010,-0.025322,-140.248444,-0.001026,0.003053,0.077547,-0.112638,-0.005738,0.775473,-140.248444,0.076671,0.000000
144.880005,0.023453,-140.337402,-0.001074,0.003032,0.077001,0.104323,0.005314,0.770010,-140.337402,0.076056,0.000000
145.250000,-0.016388,-140.337402,-0.001099,0.003008,0.076411,-0.072897,-0.003714,0.764113,-140.337402,0.075431,0.000000
145.620010,0.000740,-140.426361,-0.001134,0.002983,0.075778,0.003292,0.000168,0.757782,-140.426361,0.074816,0.000000
145.990005,0.030159,-140.426361,-0.001186,0.002965,0.075310,0.134154,0.006834,0.753099,-140.426361,0.074200,0.000000
146.360001,0.014519,-140.426361,-0.001233,0.002931,0.074451,0.064583,0.003290,0.744513,-140.426361,0.073584,0.000000
146.730011,-0.005959,-140.426361,-0.001263,0.002912,0.073957,-0.026505,-0.001350,0.739570,-140.426361,0.072968,0.000000
147.100006,0.004463,-140.515320,-0.001319,0.002887,0.073341,0.019853,0.001011,0.733413,-140.515320,0.072353,0.000000
147.470001,-0.006332,-140.604294,-0.001350,0.002864,0.072743,-0.028168,-0.001435,0.727429,-140.604294,0.071737,0.000000
147.840012,0.003349,-140.604294,-0.001384,0.002852,0.072448,0.014898,0.000759,0.724480,-140.604294,0.071121,0.000000
148.210007,0.017502,-140.648773,-0.001466,0.002808,0.071321,0.077852,0.003966,0.713206,-140.648773,0.070505,0.000000
148.580002,0.020103,-140.648773,-0.001505,0.002794,0.070956,0.089425,0.004556,0.709564,-140.648773,0.069881,0.000000
148.950012,0.013771,-140.782211,-0.001548,0.002778,0.070557,0.061257,0.003121,0.705575,-140.782211,0.069265,0.000000
149.320007,-0.004097,-140.737732,-0.001582,0.002737,0.069508,-0.018224,-0.000928,0.695081,-140.737732,0.068650,0.000000
149.690002,0.002228,-140.782211,-0.001617,0.002722,0.069135,0.009910,0.000505,0.691352,-140.782211,0.068034,0.000000
150.060013,-0.020111,-140.782211,-0.001677,0.002692,0.068389,-0.089459,-0.004557,0.683894,-140.782211,0.067418,0.000000
150.430008,-0.035751,-140.826691,-0.001716,0.002668,0.067765,-0.159030,-0.008101,0.677650,-140.826691,0.066802,0.000000
150.800003,-0.027184,-140.915649,-0.001772,0.002642,0.067097,-0.120918,-0.006160,0.670973,-140.915649,0.066187,0.000000
151.170013,-0.029045,-141.004608,-0.001781,0.002634,0.066898,-0.129199,-0.006582,0.668978,-141.004608,0.065571,0.000000
151.540009,-0.019363,-140.960129,-0.001841,0.002604,0.066135,-0.086133,-0.004388,0.661346,-140.960129,0.064955,0.000000
151.910004,-0.040588,-141.004608,-0.001863,0.002577,0.065467,-0.180546,-0.009197,0.654669,-141.004608,0.064331,0.000000
152.280014,-0.042450,-141.049103,-0.001927,0.002546,0.064669,-0.188827,-0.009619,0.646690,-141.049103,0.063715,0.000000
152.650009,-0.041336,-141.138062,-0.001957,0.002521,0.064027,-0.183872,-0.009367,0.640273,-141.138062,0.063099,0.000000
153.020004,-0.039101,-141.182541,-0.001979,0.002499,0.063472,-0.173928,-0.008860,0.634723,-141.182541,0.062484,0.000000
153.390015,-0.052879,-141.138062,-0.002018,0.002477,0.062909,-0.235219,-0.011983,0.629085,-141.138062,0.061868,0.000000
153.600006,-0.005219,-141.271500,-0.002018,0.002479,0.062978,-0.023213,-0.001183,0.629779,-141.271500,0.062909,0.000000