File: Data/compression 20/AutoNoHeating-17-20-reverse-2-4_09112024_171452.csv
Time (sec),S:Load (lbs),S:HL1 (DIM),S:LVDT (in),S:Position (in),Ch:Position (mm),Ch:Load (N),Ch:Stress (MPa),Ch:Strain (mm/mm),Ch:HL1 (DIM),Set Point (),Cycles ()
0.110000,-0.055115,-212.796875,-0.009852,-0.005650,-0.143509,-0.245163,-0.012489,-1.435085,-212.796875,-0.143292,0.000000
0.470000,-0.092720,-212.930313,-0.009860,-0.005573,-0.141549,-0.412439,-0.021011,-1.415486,-212.930313,-0.141020,0.000000
0.830000,-0.016762,-212.841354,-0.009809,-0.005364,-0.136241,-0.074560,-0.003798,-1.362412,-212.841354,-0.135018,0.000000
1.190000,-0.051018,-212.974792,-0.009567,-0.005134,-0.130405,-0.226938,-0.011561,-1.304047,-212.974792,-0.129017,0.000000
1.550000,-0.053627,-212.930313,-0.009322,-0.004893,-0.124291,-0.238545,-0.012152,-1.242908,-212.930313,-0.123016,0.000000
1.910000,-0.088623,-213.019272,-0.009076,-0.004660,-0.118376,-0.394215,-0.020082,-1.183763,-213.019272,-0.117015,0.000000
2.270000,-0.054367,-212.974792,-0.008826,-0.004417,-0.112193,-0.241837,-0.012320,-1.121930,-212.974792,-0.111031,0.000000
2.630000,-0.064796,-213.019272,-0.008558,-0.004178,-0.106122,-0.288229,-0.014683,-1.061224,-213.019272,-0.105030,0.000000
2.990000,-0.058090,-213.063751,-0.008326,-0.003940,-0.100078,-0.258398,-0.013163,-1.000779,-213.063751,-0.099028,0.000000
3.350000,-0.054741,-213.063751,-0.008097,-0.003709,-0.094198,-0.243500,-0.012404,-0.941981,-213.063751,-0.093027,0.000000
3.710000,-0.070007,-213.108231,-0.007838,-0.003471,-0.088171,-0.311408,-0.015864,-0.881708,-213.108231,-0.087026,0.000000
4.070000,-0.068893,-213.108231,-0.007606,-0.003238,-0.082248,-0.306453,-0.015611,-0.822477,-213.108231,-0.081042,0.000000
4.430000,-0.036865,-213.108231,-0.007364,-0.003004,-0.076290,-0.163985,-0.008354,-0.762898,-213.108231,-0.075041,0.000000
4.790000,-0.033516,-213.197205,-0.007114,-0.002765,-0.070237,-0.149086,-0.007595,-0.702366,-213.197205,-0.069040,0.000000
5.150000,-0.049896,-213.152710,-0.006881,-0.002525,-0.064123,-0.221950,-0.011307,-0.641227,-213.152710,-0.063039,0.000000
5.510000,-0.082298,-213.197205,-0.006627,-0.002289,-0.058147,-0.366081,-0.018649,-0.581475,-213.197205,-0.057055,0.000000
5.870000,-0.088257,-213.241684,-0.006377,-0.002053,-0.052146,-0.392586,-0.019999,-0.521463,-213.241684,-0.051054,0.000000
6.230000,-0.081924,-213.286163,-0.006140,-0.001826,-0.046388,-0.364418,-0.018564,-0.463879,-213.286163,-0.045052,0.000000
6.590000,-0.029419,-213.241684,-0.005920,-0.001588,-0.040335,-0.130862,-0.006666,-0.403347,-213.241684,-0.039051,0.000000
6.950000,-0.035004,-213.241684,-0.005678,-0.001352,-0.034342,-0.155704,-0.007932,-0.343421,-213.241684,-0.033050,0.000000
7.310000,-0.045433,-213.330643,-0.005424,-0.001110,-0.028185,-0.202096,-0.010295,-0.281848,-213.330643,-0.027066,0.000000
7.670001,-0.065170,-213.330643,-0.005182,-0.000878,-0.022314,-0.289892,-0.014768,-0.223137,-213.330643,-0.021065,0.000000
8.030001,-0.078941,-213.330643,-0.004958,-0.000641,-0.016269,-0.351149,-0.017888,-0.162692,-213.330643,-0.015064,0.000000
8.390000,-0.074852,-213.375122,-0.004734,-0.000405,-0.010277,-0.332958,-0.016962,-0.102766,-213.375122,-0.009063,0.000000
8.750000,-0.008194,-213.330643,-0.004475,-0.000167,-0.004249,-0.036449,-0.001857,-0.042494,-213.330643,-0.003061,0.000000
9.110001,0.089371,-213.464081,-0.004260,-0.000000,-0.000000,0.397541,0.020252,-0.000000,-213.464081,0.000217,0.000000
9.470000,0.075218,-213.375122,-0.004260,-0.000000,-0.000000,0.334587,0.017045,-0.000000,-213.375122,0.000217,0.000000
9.830001,0.109100,-213.419601,-0.004268,-0.000000,-0.000000,0.485303,0.024722,-0.000000,-213.419601,0.000616,0.000000
10.190001,0.105011,-213.508560,-0.004264,0.000001,0.000017,0.467112,0.023796,0.000173,-213.508560,0.001223,0.000000
10.550000,0.269966,-213.419601,-0.004251,0.000032,0.000824,1.200869,0.061175,0.008239,-213.419601,0.001821,0.000000
10.910001,0.409607,-213.508560,-0.004225,0.000048,0.001223,1.822023,0.092818,0.012228,-213.508560,0.002420,0.000000
11.270000,0.644203,-213.508560,-0.004212,0.000074,0.001891,2.865559,0.145979,0.018906,-213.508560,0.003018,0.000000
11.630000,0.989021,-213.508560,-0.004186,0.000107,0.002714,4.399386,0.224115,0.027144,-213.508560,0.003616,0.000000
11.990001,1.347244,-213.597534,-0.004165,0.000132,0.003365,5.992842,0.305290,0.033648,-213.597534,0.004215,0.000000
12.350000,1.630989,-213.597534,-0.004143,0.000149,0.003781,7.255002,0.369587,0.037811,-213.597534,0.004822,0.000000
12.710001,1.983627,-213.642014,-0.004122,0.000172,0.004371,8.823615,0.449496,0.043708,-213.642014,0.005420,0.000000
13.070001,2.506065,-213.642014,-0.004109,0.000198,0.005039,11.147535,0.567883,0.050386,-213.642014,0.006019,0.000000
13.430000,2.922005,-213.730972,-0.004066,0.000225,0.005715,12.997726,0.662136,0.057150,-213.730972,0.006617,0.000000
13.790001,3.369598,-213.686493,-0.004061,0.000250,0.006339,14.988722,0.763562,0.063394,-213.686493,0.007215,0.000000
14.150001,3.603821,-213.686493,-0.004040,0.000266,0.006756,16.030596,0.816637,0.067557,-213.686493,0.007822,0.000000
14.510000,4.071518,-213.775452,-0.004031,0.000289,0.007345,18.111017,0.922619,0.073454,-213.775452,0.008421,0.000000
14.870001,4.716095,-213.730972,-0.004001,0.000317,0.008057,20.978239,1.068682,0.080565,-213.730972,0.009019,0.000000
15.230000,5.114906,-213.819931,-0.003967,0.000342,0.008681,22.752239,1.159054,0.086809,-213.819931,0.009618,0.000000
15.590001,5.340561,-213.775452,-0.003958,0.000360,0.009141,23.756001,1.210188,0.091406,-213.775452,0.010216,0.000000
15.950001,5.966896,-213.775452,-0.003945,0.000392,0.009956,26.542080,1.352118,0.099558,-213.775452,0.010823,0.000000
16.310001,6.187714,-213.864410,-0.003923,0.000409,0.010398,27.524324,1.402156,0.103980,-213.864410,0.011421,0.000000
16.670000,6.477417,-213.819931,-0.003902,0.000428,0.010884,28.812990,1.467804,0.108837,-213.819931,0.012020,0.000000
17.030001,7.126465,-213.908890,-0.003872,0.000460,0.011673,31.700098,1.614880,0.116729,-213.908890,0.012618,0.000000
17.390001,7.191254,-213.864410,-0.003859,0.000481,0.012211,31.988295,1.629561,0.122105,-213.864410,0.013217,0.000000
17.750000,7.646667,-213.864410,-0.003837,0.000506,0.012852,34.014076,1.732760,0.128523,-213.864410,0.013824,0.000000
18.110001,7.464577,-213.953369,-0.003820,0.000514,0.013043,33.204094,1.691497,0.130431,-213.953369,0.014422,0.000000
18.470001,8.116600,-213.908890,-0.003803,0.000548,0.013919,36.104439,1.839248,0.139190,-213.908890,0.015020,0.000000
18.830002,8.674789,-213.997849,-0.003764,0.000579,0.014717,38.587391,1.965735,0.147168,-213.997849,0.015619,0.000000
19.190001,8.576851,-213.953369,-0.003760,0.000598,0.015185,38.151737,1.943542,0.151851,-213.953369,0.016217,0.000000
19.550001,8.564194,-214.086823,-0.003729,0.000611,0.015532,38.095436,1.940674,0.155320,-214.086823,0.016816,0.000000
19.910002,8.735115,-214.042343,-0.003725,0.000630,0.016009,38.855732,1.979405,0.160090,-214.042343,0.017423,0.000000
20.270000,9.216965,-214.086823,-0.003695,0.000660,0.016772,40.999107,2.088594,0.167721,-214.086823,0.018021,0.000000
20.630001,9.841805,-214.086823,-0.003656,0.000700,0.017769,43.778534,2.230185,0.177695,-214.086823,0.018619,0.000000
20.990002,9.561409,-214.086823,-0.003635,0.000717,0.018212,42.531273,2.166646,0.182117,-214.086823,0.019218,0.000000
21.350000,9.662315,-214.131302,-0.003635,0.000739,0.018767,42.980125,2.189512,0.187668,-214.131302,0.019816,0.000000
21.710001,10.095390,-214.175781,-0.003609,0.000765,0.019435,44.906540,2.287648,0.194345,-214.175781,0.020423,0.000000
22.070002,9.990379,-214.220261,-0.003561,0.000780,0.019807,44.439426,2.263852,0.198074,-214.220261,0.021022,0.000000
22.430000,10.336311,-214.264740,-0.003557,0.000810,0.020571,45.978210,2.342242,0.205706,-214.264740,0.021620,0.000000
22.790001,10.459938,-214.220261,-0.003523,0.000835,0.021212,46.528130,2.370256,0.212123,-214.220261,0.022218,0.000000
23.150002,10.603676,-214.264740,-0.003492,0.000859,0.021819,47.167507,2.402827,0.218194,-214.264740,0.022817,0.000000
23.510000,10.699745,-214.309219,-0.003488,0.000879,0.022331,47.594845,2.424597,0.223311,-214.309219,0.023424,0.000000
23.870001,10.752625,-214.264740,-0.003462,0.000897,0.022791,47.830063,2.436579,0.227907,-214.264740,0.024022,0.000000
24.230001,11.065422,-214.353699,-0.003441,0.000927,0.023545,49.221455,2.507460,0.235452,-214.353699,0.024621,0.000000
24.590002,11.230751,-214.309219,-0.003423,0.000952,0.024170,49.956875,2.544925,0.241696,-214.309219,0.025219,0.000000
24.950001,11.477638,-214.398178,-0.003393,0.000978,0.024846,51.055084,2.600870,0.248460,-214.398178,0.025817,0.000000
25.310001,11.420288,-214.398178,-0.003372,0.000998,0.025358,50.799980,2.587874,0.253577,-214.398178,0.026424,0.000000
25.670002,11.546524,-214.353699,-0.003350,0.001019,0.025878,51.361504,2.616480,0.258780,-214.353699,0.027023,0.000000
26.030001,11.824310,-214.531631,-0.003324,0.001045,0.026537,52.597160,2.679427,0.265371,-214.531631,0.027621,0.000000
26.390001,12.248444,-214.487152,-0.003303,0.001075,0.027309,54.483799,2.775537,0.273089,-214.487152,0.028220,0.000000
26.750002,12.342285,-214.531631,-0.003268,0.001101,0.027959,54.901226,2.796802,0.279594,-214.531631,0.028818,0.000000
27.110001,12.197800,-214.531631,-0.003260,0.001119,0.028419,54.258522,2.764061,0.284190,-214.531631,0.029416,0.000000
27.470001,12.587303,-214.442657,-0.003234,0.001147,0.029130,55.991119,2.852324,0.291301,-214.442657,0.030023,0.000000
27.830002,12.451385,-214.576111,-0.003208,0.001162,0.029512,55.386528,2.821524,0.295117,-214.576111,0.030622,0.000000
28.190001,12.919464,-214.487152,-0.003182,0.001192,0.030284,57.468647,2.927592,0.302835,-214.487152,0.031220,0.000000
28.550001,12.770142,-214.620590,-0.003169,0.001205,0.030613,56.804428,2.893755,0.306131,-214.620590,0.031819,0.000000
28.910002,13.428864,-214.620590,-0.003165,0.001239,0.031480,59.734570,3.043024,0.314803,-214.620590,0.032417,0.000000
29.270000,13.567764,-214.665070,-0.003113,0.001264,0.032113,60.352428,3.074499,0.321134,-214.665070,0.033024,0.000000
29.630001,13.477272,-214.709549,-0.003113,0.001282,0.032564,59.949902,3.053993,0.325643,-214.709549,0.033622,0.000000
29.990002,13.784851,-214.620590,-0.003083,0.001307,0.033197,61.318081,3.123692,0.331974,-214.620590,0.034221,0.000000
30.350002,14.037697,-214.620590,-0.003057,0.001332,0.033839,62.442795,3.180988,0.338391,-214.620590,0.034819,0.000000
30.710001,14.001945,-214.665070,-0.003031,0.001350,0.034281,62.283764,3.172886,0.342814,-214.665070,0.035417,0.000000
31.070002,14.540024,-214.754028,-0.003018,0.001379,0.035027,64.677254,3.294816,0.350272,-214.754028,0.036025,0.000000
31.430002,14.663284,-214.842987,-0.003009,0.001403,0.035643,65.225548,3.322748,0.356430,-214.842987,0.036623,0.000000
31.790001,14.799194,-214.754028,-0.002958,0.001425,0.036189,65.830101,3.353545,0.361893,-214.754028,0.037221,0.000000
32.150002,14.992828,-214.842987,-0.002949,0.001447,0.036744,66.691429,3.397424,0.367444,-214.842987,0.037820,0.000000
32.510002,15.034912,-214.798508,-0.002936,0.001464,0.037187,66.878632,3.406960,0.371866,-214.798508,0.038418,0.000000
32.870003,15.895088,-214.798508,-0.002902,0.001502,0.038141,70.704880,3.601879,0.381406,-214.798508,0.039025,0.000000
33.230003,15.866791,-214.842987,-0.002876,0.001524,0.038713,70.579010,3.595466,0.387130,-214.842987,0.039624,0.000000
33.590000,15.727898,-214.887482,-0.002846,0.001541,0.039147,69.961182,3.563993,0.391466,-214.887482,0.040222,0.000000
33.950001,15.869026,-215.020920,-0.002846,0.001563,0.039702,70.588951,3.595973,0.397016,-215.020920,0.040820,0.000000
34.310001,16.510994,-214.931961,-0.002815,0.001590,0.040387,73.444572,3.741445,0.403867,-214.931961,0.041419,0.000000
34.670002,16.834587,-214.931961,-0.002781,0.001619,0.041115,74.883980,3.814772,0.411152,-214.931961,0.042017,0.000000
35.030003,17.077370,-214.931961,-0.002777,0.001644,0.041757,75.963936,3.869787,0.417569,-214.931961,0.042624,0.000000
35.390003,16.860275,-214.976440,-0.002755,0.001660,0.042156,74.998253,3.820593,0.421558,-214.976440,0.043223,0.000000
35.750000,17.152962,-215.020920,-0.002725,0.001683,0.042737,76.300186,3.886917,0.427369,-215.020920,0.043821,0.000000
36.110001,17.827332,-215.020920,-0.002708,0.001712,0.043483,79.299934,4.039731,0.434827,-215.020920,0.044419,0.000000
36.470001,17.687691,-215.020920,-0.002682,0.001731,0.043968,78.678780,4.008088,0.439683,-215.020920,0.045018,0.000000
36.830002,18.304337,-215.065399,-0.002665,0.001758,0.044645,81.421753,4.147822,0.446448,-215.065399,0.045625,0.000000
37.190002,18.631279,-215.065399,-0.002639,0.001784,0.045313,82.876068,4.221908,0.453125,-215.065399,0.046223,0.000000
37.550003,18.483452,-215.154358,-0.002617,0.001802,0.045772,82.218498,4.188410,0.457722,-215.154358,0.046822,0.000000
37.910004,18.637985,-215.154358,-0.002613,0.001822,0.046275,82.905899,4.223428,0.462752,-215.154358,0.047420,0.000000
38.270000,19.639664,-215.243317,-0.002583,0.001853,0.047056,87.361588,4.450411,0.470557,-215.243317,0.048018,0.000000
38.630001,19.825478,-215.154358,-0.002565,0.001875,0.047637,88.188126,4.492517,0.476367,-215.154358,0.048625,0.000000
38.990002,20.073853,-215.198837,-0.002531,0.001900,0.048252,89.292953,4.548800,0.482524,-215.198837,0.049224,0.000000
39.350002,19.796432,-215.287796,-0.002527,0.001911,0.048547,88.058929,4.485936,0.485473,-215.287796,0.049822,0.000000
39.710003,20.762741,-215.243317,-0.002509,0.001942,0.049328,92.357285,4.704905,0.493278,-215.243317,0.050421,0.000000
40.070004,20.745987,-215.332291,-0.002475,0.001960,0.049787,92.282761,4.701108,0.497874,-215.332291,0.051019,0.000000
40.430000,21.594620,-215.198837,-0.002462,0.001993,0.050620,96.057663,4.893411,0.506200,-215.198837,0.051626,0.000000
40.790001,21.512703,-215.243317,-0.002436,0.002009,0.051019,95.693283,4.874848,0.510189,-215.243317,0.052224,0.000000
41.150002,21.729424,-215.376770,-0.002432,0.002029,0.051531,96.657303,4.923958,0.515305,-215.376770,0.052823,0.000000
41.510002,22.747490,-215.376770,-0.002393,0.002062,0.052372,101.185890,5.154655,0.523718,-215.376770,0.053421,0.000000
41.870003,23.328392,-215.376770,-0.002389,0.002089,0.053066,103.769867,5.286289,0.530655,-215.376770,0.054019,0.000000
42.230003,23.775604,-215.332291,-0.002363,0.002114,0.053707,105.759171,5.387629,0.537073,-215.332291,0.054627,0.000000
42.590000,23.551811,-215.376770,-0.002328,0.002133,0.054184,104.763687,5.336917,0.541843,-215.376770,0.055225,0.000000
42.950001,23.512711,-215.421249,-0.002324,0.002152,0.054661,104.589760,5.328056,0.546612,-215.421249,0.055823,0.000000
43.310001,24.588493,-215.421249,-0.002302,0.002178,0.055312,109.375084,5.571832,0.553117,-215.421249,0.056422,0.000000
43.670002,24.867775,-215.465729,-0.002289,0.002199,0.055849,110.617386,5.635118,0.558493,-215.465729,0.057020,0.000000
44.030003,25.895149,-215.510208,-0.002246,0.002231,0.056673,115.187378,5.867925,0.566732,-215.510208,0.057618,0.000000
44.390003,26.152458,-215.510208,-0.002238,0.002254,0.057263,116.331947,5.926231,0.572629,-215.510208,0.058226,0.000000
44.750004,26.485359,-215.554687,-0.002225,0.002275,0.057792,117.812759,6.001668,0.577919,-215.554687,0.058824,0.000000
45.110001,26.245552,-215.554687,-0.002190,0.002287,0.058078,116.746048,5.947327,0.580781,-215.554687,0.059422,0.000000
45.470001,27.522789,-215.554687,-0.002182,0.002319,0.058893,122.427483,6.236753,0.588933,-215.554687,0.060021,0.000000
45.830002,27.201805,-215.554687,-0.002156,0.002331,0.059205,120.999672,6.164017,0.592055,-215.554687,0.060619,0.000000
46.190002,29.075584,-215.554687,-0.002126,0.002374,0.060290,129.334656,6.588622,0.602895,-215.554687,0.061226,0.000000
46.550003,29.197723,-215.554687,-0.002126,0.002391,0.060732,129.877960,6.616299,0.607318,-215.554687,0.061825,0.000000
46.910004,30.077271,-215.599167,-0.002100,0.002417,0.061391,133.790375,6.815607,0.613909,-215.599167,0.062423,0.000000
47.270000,30.543480,-215.688126,-0.002074,0.002440,0.061972,135.864182,6.921251,0.619720,-215.688126,0.063021,0.000000
47.630001,30.752007,-215.688126,-0.002052,0.002462,0.062536,136.791763,6.968504,0.625356,-215.688126,0.063620,0.000000
47.990002,32.308525,-215.688126,-0.002022,0.002493,0.063333,143.715500,7.321216,0.633335,-215.688126,0.064227,0.000000
48.350002,32.645523,-215.732620,-0.002009,0.002515,0.063880,145.214539,7.397581,0.638798,-215.732620,0.064825,0.000000
48.710003,33.151199,-215.688126,-0.001996,0.002539,0.064478,147.463898,7.512169,0.644782,-215.688126,0.065424,0.000000
49.070004,33.546661,-215.777100,-0.001979,0.002557,0.064955,149.223007,7.601782,0.649552,-215.777100,0.066022,0.000000
49.430004,34.276512,-215.777100,-0.001944,0.002580,0.065536,152.469543,7.767169,0.655362,-215.777100,0.066620,0.000000
49.790001,35.074875,-215.821579,-0.001932,0.002604,0.066135,156.020828,7.948080,0.661346,-215.821579,0.067227,0.000000
50.150002,35.376869,-215.821579,-0.001919,0.002621,0.066577,157.364166,8.016513,0.665769,-215.821579,0.067826,0.000000
50.510002,36.884979,-215.821579,-0.001884,0.002654,0.067418,164.072586,8.358255,0.674181,-215.821579,0.068424,0.000000
50.870003,37.853897,-215.910538,-0.001884,0.002680,0.068060,168.382538,8.577816,0.680599,-215.910538,0.069022,0.000000
51.230003,38.052368,-215.910538,-0.001863,0.002697,0.068493,169.265381,8.622789,0.684935,-215.910538,0.069621,0.000000
51.590004,39.669212,-215.910538,-0.001845,0.002729,0.069309,176.457474,8.989172,0.693087,-215.910538,0.070219,0.000000
51.950001,39.850182,-215.910538,-0.001832,0.002747,0.069786,177.262466,9.030180,0.697856,-215.910538,0.070826,0.000000
52.310001,41.031349,-215.999496,-0.001802,0.002773,0.070436,182.516556,9.297837,0.704361,-215.999496,0.071425,0.000000
52.670002,41.873657,-216.043976,-0.001794,0.002795,0.071000,186.263336,9.488707,0.709998,-216.043976,0.072023,0.000000
53.030003,41.779068,-215.999496,-0.001781,0.002807,0.071295,185.842575,9.467272,0.712946,-215.999496,0.072621,0.000000
53.390003,43.118866,-215.999496,-0.001768,0.002834,0.071988,191.802292,9.770875,0.719884,-215.999496,0.073220,0.000000
53.750004,44.390144,-215.999496,-0.001746,0.002862,0.072700,197.457230,10.058950,0.726995,-215.999496,0.073827,0.000000
54.110004,44.542450,-216.043976,-0.001746,0.002873,0.072977,198.134720,10.093463,0.729770,-216.043976,0.074425,0.000000
54.470001,47.397430,-216.088455,-0.001716,0.002917,0.074104,210.834305,10.740411,0.741044,-216.088455,0.075024,0.000000
54.830002,47.834969,-216.088455,-0.001707,0.002935,0.074538,212.780563,10.839560,0.745380,-216.088455,0.075622,0.000000
55.190002,48.154457,-216.132935,-0.001677,0.002951,0.074946,214.201721,10.911956,0.749456,-216.132935,0.076220,0.000000
55.550003,49.437653,-216.132935,-0.001673,0.002976,0.075579,219.909668,11.202732,0.755787,-216.132935,0.076828,0.000000
55.910004,51.551239,-216.221909,-0.001664,0.003011,0.076489,229.311371,11.681677,0.764893,-216.221909,0.077426,0.000000
56.270004,52.220764,-216.221909,-0.001634,0.003031,0.076975,232.289566,11.833394,0.769750,-216.221909,0.078024,0.000000
56.630001,53.589981,-216.221909,-0.001625,0.003056,0.077625,238.380142,12.143663,0.776254,-216.221909,0.078623,0.000000
56.990002,53.952301,-216.310867,-0.001604,0.003077,0.078154,239.991821,12.225766,0.781544,-216.310867,0.079221,0.000000
57.350002,54.648636,-216.221909,-0.001595,0.003090,0.078484,243.089279,12.383557,0.784839,-216.221909,0.079828,0.000000
57.710003,55.635796,-216.310867,-0.001574,0.003111,0.079022,247.480377,12.607251,0.790216,-216.310867,0.080427,0.000000
58.070004,58.406250,-216.310867,-0.001574,0.003152,0.080062,259.803986,13.235045,0.800623,-216.310867,0.081025,0.000000
58.430004,59.976913,-216.310867,-0.001548,0.003177,0.080704,266.790649,13.590962,0.807040,-216.310867,0.081623,0.000000
58.790001,60.597656,-216.355347,-0.001544,0.003195,0.081146,269.551849,13.731626,0.811463,-216.355347,0.082222,0.000000
59.150002,61.335701,-216.355347,-0.001535,0.003213,0.081615,272.834839,13.898869,0.816146,-216.355347,0.082820,0.000000
59.510002,63.521896,-216.444305,-0.001509,0.003244,0.082404,282.559509,14.394268,0.824038,-216.444305,0.083427,0.000000
59.870003,64.804352,-216.399826,-0.001492,0.003268,0.083002,288.264160,14.684876,0.830022,-216.399826,0.084025,0.000000
60.230003,65.533081,-216.399826,-0.001483,0.003287,0.083496,291.505707,14.850009,0.834965,-216.399826,0.084624,0.000000
60.590004,65.580002,-216.488785,-0.001470,0.003286,0.083453,291.714417,14.860641,0.834531,-216.488785,0.014662,0.000000
60.950005,64.489700,-216.444305,-0.001466,0.003285,0.083427,286.864502,14.613575,0.834271,-216.444305,294.500458,0.000000
61.310001,66.142654,-216.488785,-0.001444,0.003220,0.081779,294.217224,14.988139,0.817794,-216.488785,294.500458,0.000000
61.670002,65.321945,-216.577744,-0.001436,0.003288,0.083514,290.566528,14.802165,0.835138,-216.577744,294.500458,0.000000
62.030003,64.928345,-216.488785,-0.001436,0.003309,0.084060,288.815704,14.712973,0.840602,-216.488785,294.500458,0.000000
62.390003,65.934875,-216.622238,-0.001440,0.003316,0.084225,293.292969,14.941056,0.842250,-216.622238,294.500458,0.000000
62.750004,65.259384,-216.577744,-0.001436,0.003316,0.084225,290.288239,14.787988,0.842250,-216.577744,294.500458,0.000000
63.110004,64.685928,-216.622238,-0.001431,0.003317,0.084260,287.737366,14.658041,0.842596,-216.622238,294.500458,0.000000
63.470001,65.781448,-216.666718,-0.001427,0.003332,0.084624,292.610504,14.906289,0.846239,-216.666718,294.500458,0.000000
63.830002,65.256790,-216.622238,-0.001418,0.003332,0.084624,290.276703,14.787400,0.846239,-216.622238,294.500458,0.000000
64.190002,65.057938,-216.666718,-0.001418,0.003342,0.084875,289.392151,14.742340,0.848754,-216.666718,294.500458,0.000000
64.550003,65.438507,-216.711197,-0.001410,0.003350,0.085101,291.085022,14.828578,0.851009,-216.711197,294.500458,0.000000
64.910004,65.148056,-216.755676,-0.001410,0.003351,0.085110,289.793030,14.762760,0.851095,-216.755676,294.500458,0.000000
65.270004,64.981598,-216.711197,-0.001406,0.003352,0.085153,289.052582,14.725040,0.851529,-216.711197,294.500458,0.000000
65.630005,65.749802,-216.755676,-0.001401,0.003364,0.085439,292.469727,14.899118,0.854391,-216.755676,294.500458,0.000000
65.990005,65.511856,-216.755676,-0.001388,0.003364,0.085439,291.411285,14.845199,0.854391,-216.755676,294.500458,0.000000
66.350006,65.252319,-216.800156,-0.001393,0.003364,0.085439,290.256805,14.786387,0.854391,-216.800156,294.500458,0.000000
66.710007,64.989426,-216.800156,-0.001388,0.003364,0.085439,289.087402,14.726814,0.854391,-216.800156,294.500458,0.000000
67.070000,64.753342,-216.844635,-0.001388,0.003364,0.085439,288.037262,14.673317,0.854391,-216.844635,294.500458,0.000000
67.430000,64.502731,-216.889114,-0.001380,0.003364,0.085439,286.922485,14.616529,0.854391,-216.889114,294.500458,0.000000
67.790001,64.294205,-216.889114,-0.001397,0.003364,0.085439,285.994904,14.569275,0.854391,-216.889114,294.500458,0.000000
68.150002,64.075623,-216.889114,-0.001384,0.003364,0.085439,285.022614,14.519743,0.854391,-216.889114,294.500458,0.000000
68.510002,66.029449,-216.933594,-0.001345,0.003166,0.080409,293.713654,14.962486,0.804092,-216.933594,294.500458,0.000000
68.870003,65.807892,-216.889114,-0.001341,0.003187,0.080938,292.728119,14.912281,0.809382,-216.889114,294.500458,0.000000
69.230003,65.574051,-216.978073,-0.001345,0.003224,0.081892,291.687958,14.859292,0.818921,-216.978073,294.500458,0.000000
69.590004,65.368866,-216.933594,-0.001345,0.003335,0.084711,290.775238,14.812798,0.847106,-216.933594,294.500458,0.000000
69.950005,65.281357,-217.067047,-0.001345,0.003358,0.085300,290.385986,14.792967,0.853003,-217.067047,294.500458,0.000000
70.310005,65.066498,-216.978073,-0.001350,0.003359,0.085309,289.430237,14.744279,0.853090,-216.978073,294.500458,0.000000
70.670006,65.456009,-217.022568,-0.001354,0.003381,0.085873,291.162872,14.832543,0.858727,-217.022568,294.500458,0.000000
71.030006,65.275024,-217.156006,-0.001354,0.003381,0.085873,290.357819,14.791532,0.858727,-217.156006,294.500458,0.000000
71.390007,65.192734,-217.067047,-0.001345,0.003385,0.085968,289.991760,14.772885,0.859681,-217.067047,294.500458,0.000000
71.750000,65.171509,-217.200485,-0.001350,0.003386,0.085994,289.897339,14.768075,0.859941,-217.200485,294.500458,0.000000
72.110001,65.222153,-217.111526,-0.001358,0.003389,0.086072,290.122620,14.779552,0.860721,-217.111526,294.500458,0.000000
72.470001,65.088470,-217.156006,-0.001341,0.003389,0.086081,289.527985,14.749258,0.860808,-217.156006,294.500458,0.000000
72.830002,65.397537,-217.200485,-0.001350,0.003395,0.086228,290.902771,14.819294,0.862283,-217.200485,294.500458,0.000000
73.190002,65.303329,-217.244965,-0.001350,0.003395,0.086228,290.483704,14.797946,0.862283,-217.244965,294.500458,0.000000
73.550003,65.218063,-217.289444,-0.001350,0.003395,0.086228,290.104431,14.778625,0.862283,-217.289444,294.500458,0.000000
73.910004,65.083252,-217.289444,-0.001362,0.003395,0.086246,289.504761,14.748075,0.862456,-217.289444,294.500458,0.000000
74.270004,65.032242,-217.333923,-0.001354,0.003397,0.086272,289.277863,14.736517,0.862716,-217.333923,294.500458,0.000000
74.630005,64.942123,-217.289444,-0.001345,0.003397,0.086272,288.876984,14.716096,0.862716,-217.289444,294.500458,0.000000
74.990005,65.064270,-217.333923,-0.001341,0.003402,0.086419,289.420319,14.743774,0.864190,-217.333923,294.500458,0.000000
75.350006,65.248962,-217.333923,-0.001362,0.003402,0.086419,290.241882,14.785626,0.864190,-217.333923,294.500458,0.000000
75.710007,65.182312,-217.333923,-0.001345,0.003402,0.086419,289.945404,14.770522,0.864190,-217.333923,294.500458,0.000000
76.070007,65.097412,-217.378403,-0.001362,0.003403,0.086428,289.567749,14.751285,0.864277,-217.378403,294.500458,0.000000
76.430000,65.045654,-217.467377,-0.001345,0.003404,0.086454,289.337524,14.739556,0.864537,-217.467377,294.500458,0.000000
76.790001,64.989792,-217.422882,-0.001350,0.003404,0.086454,289.089020,14.726897,0.864537,-217.422882,294.500458,0.000000
77.150002,64.919418,-217.422882,-0.001354,0.003404,0.086454,288.776001,14.710950,0.864537,-217.422882,294.500458,0.000000
77.510002,64.814774,-217.422882,-0.001345,0.003404,0.086454,288.310516,14.687238,0.864537,-217.422882,294.500458,0.000000
77.870003,64.738815,-217.467377,-0.001350,0.003404,0.086454,287.972626,14.670026,0.864537,-217.467377,294.500458,0.000000
78.230003,65.077667,-217.511856,-0.001350,0.003409,0.086592,289.479919,14.746810,0.865925,-217.511856,294.500458,0.000000
78.590004,65.050110,-217.511856,-0.001341,0.003409,0.086592,289.357330,14.740566,0.865925,-217.511856,294.500458,0.000000
78.950005,64.986435,-217.556335,-0.001350,0.003409,0.086592,289.074097,14.726136,0.865925,-217.556335,294.500458,0.000000
79.310005,64.932449,-217.556335,-0.001341,0.003409,0.086592,288.833954,14.713903,0.865925,-217.556335,294.500458,0.000000
79.670006,64.832275,-217.556335,-0.001350,0.003409,0.086592,288.388367,14.691204,0.865925,-217.556335,294.500458,0.000000
80.030006,64.771210,-217.511856,-0.001345,0.003409,0.086592,288.116730,14.677366,0.865925,-217.511856,294.500458,0.000000
80.390007,64.710510,-217.645294,-0.001328,0.003409,0.086592,287.846741,14.663610,0.865925,-217.645294,294.500458,0.000000
80.750008,64.694504,-217.645294,-0.001341,0.003418,0.086809,287.775513,14.659984,0.868093,-217.645294,294.500458,0.000000
81.110001,65.908432,-217.600815,-0.001324,0.003423,0.086957,293.175354,14.935064,0.869567,-217.600815,294.500458,0.000000
81.470001,65.896515,-217.734253,-0.001350,0.003423,0.086948,293.122345,14.932364,0.869480,-217.734253,294.500458,0.000000
81.830002,65.844757,-217.689774,-0.001345,0.003423,0.086948,292.892120,14.920635,0.869480,-217.689774,294.500458,0.000000
82.190002,65.756882,-217.734253,-0.001337,0.003423,0.086948,292.501221,14.900723,0.869480,-217.734253,294.500458,0.000000
82.550003,65.752411,-217.734253,-0.001337,0.003423,0.086948,292.481323,14.899710,0.869480,-217.734253,294.500458,0.000000
82.910004,65.619843,-217.689774,-0.001337,0.003423,0.086948,291.891632,14.869669,0.869480,-217.689774,294.500458,0.000000
83.270004,65.584839,-217.823212,-0.001341,0.003423,0.086948,291.735931,14.861737,0.869480,-217.823212,294.500458,0.000000
83.630005,65.518936,-217.778732,-0.001345,0.003423,0.086948,291.442780,14.846803,0.869480,-217.778732,294.500458,0.000000
83.990005,65.469040,-217.867691,-0.001337,0.003423,0.086948,291.220825,14.835497,0.869480,-217.867691,294.500458,0.000000
84.350006,65.382278,-217.867691,-0.001350,0.003423,0.086948,290.834900,14.815836,0.869480,-217.867691,294.500458,0.000000
84.710007,65.332367,-217.823212,-0.001328,0.003423,0.086948,290.612885,14.804526,0.869480,-217.823212,294.500458,0.000000
85.070007,65.267578,-217.912186,-0.001341,0.003423,0.086948,290.324677,14.789845,0.869480,-217.912186,294.500458,0.000000
85.430000,65.224014,-217.912186,-0.001341,0.003423,0.086948,290.130920,14.779973,0.869480,-217.912186,294.500458,0.000000
85.790001,65.129059,-217.956665,-0.001341,0.003423,0.086948,289.708527,14.758455,0.869480,-217.956665,294.500458,0.000000
86.150002,65.073196,-218.001144,-0.001332,0.003423,0.086948,289.460022,14.745797,0.869480,-218.001144,294.500458,0.000000
86.510002,65.020325,-217.956665,-0.001319,0.003423,0.086948,289.224854,14.733816,0.869480,-217.956665,294.500458,0.000000
86.870003,64.971924,-218.001144,-0.001328,0.003423,0.086957,289.009552,14.722848,0.869567,-218.001144,294.500458,0.000000
87.230003,64.913086,-218.001144,-0.001332,0.003423,0.086957,288.747833,14.709516,0.869567,-218.001144,294.500458,0.000000
87.590004,64.846436,-218.045624,-0.001328,0.003423,0.086957,288.451355,14.694413,0.869567,-218.045624,294.500458,0.000000
87.950005,65.005798,-218.090103,-0.001328,0.003427,0.087043,289.160248,14.730524,0.870434,-218.090103,294.500458,0.000000
88.310005,64.987183,-218.090103,-0.001337,0.003427,0.087043,289.077423,14.726306,0.870434,-218.090103,294.500458,0.000000
88.670006,64.968933,-218.090103,-0.001332,0.003427,0.087043,288.996246,14.722170,0.870434,-218.090103,294.500458,0.000000
89.030006,64.918671,-218.134583,-0.001328,0.003427,0.087043,288.772675,14.710781,0.870434,-218.134583,294.500458,0.000000
89.390007,64.878448,-218.179062,-0.001328,0.003427,0.087043,288.593750,14.701667,0.870434,-218.179062,294.500458,0.000000
89.750008,64.830048,-218.179062,-0.001337,0.003427,0.087043,288.378448,14.690699,0.870434,-218.179062,294.500458,0.000000
90.110001,64.789459,-218.223541,-0.001328,0.003427,0.087043,288.197906,14.681501,0.870434,-218.223541,294.500458,0.000000
90.470001,64.741043,-218.179062,-0.001319,0.003427,0.087052,287.982544,14.670530,0.870521,-218.179062,294.500458,0.000000
90.830002,64.691895,-218.268021,-0.001328,0.003427,0.087052,287.763916,14.659393,0.870521,-218.268021,294.500458,0.000000
91.190002,64.659119,-218.268021,-0.001337,0.003427,0.087052,287.618134,14.651966,0.870521,-218.268021,294.500458,0.000000
91.550003,64.604752,-218.223541,-0.001337,0.003427,0.087052,287.376282,14.639646,0.870521,-218.223541,294.500458,0.000000
91.910004,65.636597,-218.312515,-0.001332,0.003440,0.087364,291.966156,14.873466,0.873643,-218.312515,294.500458,0.000000
92.270004,65.682404,-218.268021,-0.001319,0.003440,0.087364,292.169922,14.883845,0.873643,-218.268021,294.500458,0.000000
92.630005,65.678314,-218.312515,-0.001319,0.003440,0.087364,292.151733,14.882918,0.873643,-218.312515,294.500458,0.000000
92.990005,65.660812,-218.401474,-0.001341,0.003440,0.087364,292.073883,14.878952,0.873643,-218.401474,294.500458,0.000000
93.350006,65.652237,-218.356995,-0.001315,0.003440,0.087364,292.035736,14.877009,0.873643,-218.356995,294.500458,0.000000
93.710007,65.605316,-218.490433,-0.001319,0.003440,0.087364,291.827026,14.866377,0.873643,-218.490433,294.500458,0.000000
94.070007,65.578888,-218.356995,-0.001319,0.003440,0.087364,291.709473,14.860388,0.873643,-218.356995,294.500458,0.000000
94.430008,65.556549,-218.534912,-0.001302,0.003440,0.087364,291.610107,14.855327,0.873643,-218.534912,294.500458,0.000000
94.790001,65.529358,-218.445953,-0.001324,0.003440,0.087364,291.489136,14.849164,0.873643,-218.445953,294.500458,0.000000
95.150002,65.492493,-218.445953,-0.001311,0.003440,0.087364,291.325165,14.840812,0.873643,-218.445953,294.500458,0.000000
95.510002,65.458237,-218.490433,-0.001319,0.003440,0.087364,291.172791,14.833049,0.873643,-218.490433,294.500458,0.000000
95.870003,65.396057,-218.490433,-0.001319,0.003440,0.087364,290.896179,14.818958,0.873643,-218.490433,294.500458,0.000000
96.230003,65.349136,-218.579391,-0.001319,0.003440,0.087364,290.687469,14.808326,0.873643,-218.579391,294.500458,0.000000
96.590004,65.326416,-218.579391,-0.001332,0.003440,0.087364,290.586426,14.803178,0.873643,-218.579391,294.500458,0.000000
96.950005,65.286575,-218.623871,-0.001324,0.003440,0.087364,290.409180,14.794149,0.873643,-218.623871,294.500458,0.000000
97.310005,65.256042,-218.668350,-0.001324,0.003440,0.087364,290.273376,14.787230,0.873643,-218.668350,294.500458,0.000000
97.670006,65.226242,-218.579391,-0.001319,0.003440,0.087364,290.140808,14.780478,0.873643,-218.579391,294.500458,0.000000
98.030006,65.174118,-218.712830,-0.001315,0.003440,0.087364,289.908966,14.768666,0.873643,-218.712830,294.500458,0.000000
98.390007,65.137253,-218.668350,-0.001319,0.003440,0.087364,289.744965,14.760312,0.873643,-218.668350,294.500458,0.000000
98.750008,65.082520,-218.712830,-0.001337,0.003440,0.087364,289.501495,14.747910,0.873643,-218.712830,294.500458,0.000000
99.110008,65.069107,-218.712830,-0.001319,0.003440,0.087364,289.441833,14.744871,0.873643,-218.712830,294.500458,0.000000
99.470001,65.041183,-218.757324,-0.001319,0.003440,0.087364,289.317627,14.738543,0.873643,-218.757324,294.500458,0.000000
99.830002,65.002075,-218.757324,-0.001311,0.003440,0.087364,289.143677,14.729681,0.873643,-218.757324,294.500458,0.000000
100.190002,64.979736,-218.757324,-0.001315,0.003440,0.087364,289.044312,14.724619,0.873643,-218.757324,294.500458,0.000000
100.550003,64.942871,-218.890762,-0.001324,0.003440,0.087364,288.880310,14.716265,0.873643,-218.890762,294.500458,0.000000
100.910004,64.907120,-218.846283,-0.001328,0.003440,0.087364,288.721283,14.708163,0.873643,-218.846283,294.500458,0.000000
101.270004,64.854614,-218.890762,-0.001311,0.003440,0.087364,288.487732,14.696266,0.873643,-218.890762,294.500458,0.000000
101.630005,64.816635,-218.979721,-0.001324,0.003440,0.087364,288.318787,14.687659,0.873643,-218.979721,294.500458,0.000000
101.990005,64.794296,-218.890762,-0.001315,0.003440,0.087364,288.219421,14.682597,0.873643,-218.890762,294.500458,0.000000
102.350006,64.741791,-218.935242,-0.001324,0.003440,0.087364,287.985870,14.670699,0.873643,-218.935242,294.500458,0.000000
102.710007,64.728012,-218.979721,-0.001324,0.003440,0.087364,287.924591,14.667577,0.873643,-218.979721,294.500458,0.000000
103.070007,64.699341,-218.979721,-0.001311,0.003440,0.087364,287.797028,14.661080,0.873643,-218.979721,294.500458,0.000000
103.430008,64.675888,-219.024200,-0.001306,0.003440,0.087364,287.692719,14.655766,0.873643,-219.024200,294.500458,0.000000
103.790009,64.634171,-219.024200,-0.001302,0.003440,0.087364,287.507141,14.646313,0.873643,-219.024200,294.500458,0.000000
104.150002,64.606995,-219.113159,-0.001319,0.003440,0.087373,287.386261,14.640154,0.873730,-219.113159,294.500458,0.000000
104.510002,64.574966,-219.068680,-0.001324,0.003440,0.087373,287.243805,14.632896,0.873730,-219.068680,294.500458,0.000000
104.870003,66.059998,-219.113159,-0.001315,0.003446,0.087538,293.849548,14.969410,0.875378,-219.113159,294.500458,0.000000
105.230003,66.004883,-219.068680,-0.001324,0.003446,0.087529,293.604370,14.956921,0.875291,-219.068680,294.500458,0.000000
105.590004,65.946793,-219.113159,-0.001302,0.003446,0.087529,293.345978,14.943757,0.875291,-219.113159,294.500458,0.000000
105.950005,65.920715,-219.113159,-0.001311,0.003446,0.087529,293.229980,14.937848,0.875291,-219.113159,294.500458,0.000000
106.310005,65.896149,-219.113159,-0.001315,0.003446,0.087529,293.120697,14.932281,0.875291,-219.113159,294.500458,0.000000
106.670006,65.844391,-219.246613,-0.001298,0.003446,0.087529,292.890472,14.920552,0.875291,-219.246613,294.500458,0.000000
107.030006,65.841782,-219.202133,-0.001324,0.003446,0.087529,292.878876,14.919961,0.875291,-219.202133,294.500458,0.000000
107.390007,65.778473,-219.202133,-0.001315,0.003446,0.087529,292.597260,14.905615,0.875291,-219.202133,294.500458,0.000000
107.750008,65.758362,-219.291092,-0.001328,0.003446,0.087529,292.507812,14.901057,0.875291,-219.291092,294.500458,0.000000
108.110008,65.720764,-219.291092,-0.001315,0.003446,0.087529,292.340546,14.892538,0.875291,-219.291092,294.500458,0.000000
108.470009,65.660065,-219.380051,-0.001311,0.003446,0.087529,292.070557,14.878783,0.875291,-219.380051,294.500458,0.000000
108.830002,65.635117,-219.335571,-0.001311,0.003446,0.087529,291.959595,14.873131,0.875291,-219.335571,294.500458,0.000000
109.190002,65.585953,-219.424530,-0.001298,0.003446,0.087529,291.740875,14.861990,0.875291,-219.424530,294.500458,0.000000
109.550003,65.577393,-219.335571,-0.001298,0.003446,0.087529,291.702820,14.860049,0.875291,-219.335571,294.500458,0.000000
109.910004,65.541641,-219.424530,-0.001306,0.003446,0.087529,291.543793,14.851948,0.875291,-219.424530,294.500458,0.000000
110.270004,65.529358,-219.424530,-0.001306,0.003446,0.087529,291.489136,14.849164,0.875291,-219.424530,294.500458,0.000000
110.630005,65.496964,-219.424530,-0.001302,0.003446,0.087529,291.345032,14.841825,0.875291,-219.424530,294.500458,0.000000
110.990005,65.464935,-219.469009,-0.001311,0.003446,0.087529,291.202576,14.834566,0.875291,-219.469009,294.500458,0.000000
111.350006,65.406845,-219.469009,-0.001298,0.003446,0.087529,290.944183,14.821403,0.875291,-219.469009,294.500458,0.000000
111.710007,65.381149,-219.513489,-0.001302,0.003446,0.087529,290.829865,14.815579,0.875291,-219.513489,294.500458,0.000000
112.070007,65.343552,-219.557968,-0.001306,0.003446,0.087529,290.662628,14.807060,0.875291,-219.557968,294.500458,0.000000
112.430008,65.322693,-219.513489,-0.001302,0.003446,0.087529,290.569855,14.802334,0.875291,-219.513489,294.500458,0.000000
112.790009,65.298492,-219.646942,-0.001302,0.003446,0.087529,290.462189,14.796850,0.875291,-219.646942,294.500458,0.000000
113.150009,65.273911,-219.602463,-0.001315,0.003446,0.087529,290.352844,14.791280,0.875291,-219.602463,294.500458,0.000000
113.510002,65.250824,-219.646942,-0.001298,0.003446,0.087529,290.250153,14.786048,0.875291,-219.646942,294.500458,0.000000
113.870003,65.200180,-219.646942,-0.001311,0.003446,0.087529,290.024872,14.774571,0.875291,-219.646942,294.500458,0.000000
114.230003,65.183426,-219.646942,-0.001293,0.003446,0.087529,289.950348,14.770775,0.875291,-219.646942,294.500458,0.000000
114.590004,65.141724,-219.735901,-0.001293,0.003446,0.087538,289.764862,14.761325,0.875378,-219.735901,294.500458,0.000000
114.950005,65.120117,-219.691422,-0.001293,0.003446,0.087538,289.668762,14.756430,0.875378,-219.691422,294.500458,0.000000
115.310005,65.073196,-219.735901,-0.001306,0.003446,0.087538,289.460022,14.745797,0.875378,-219.735901,294.500458,0.000000
115.670006,65.045654,-219.735901,-0.001302,0.003446,0.087538,289.337524,14.739556,0.875378,-219.735901,294.500458,0.000000
116.030006,65.023300,-219.780380,-0.001298,0.003446,0.087538,289.238098,14.734490,0.875378,-219.780380,294.500458,0.000000
116.390007,65.003571,-219.824860,-0.001315,0.003446,0.087538,289.150330,14.730020,0.875378,-219.824860,294.500458,0.000000
116.750008,64.986816,-219.780380,-0.001302,0.003446,0.087538,289.075806,14.726223,0.875378,-219.780380,294.500458,0.000000
117.110008,64.948837,-219.824860,-0.001293,0.003446,0.087538,288.906860,14.717617,0.875378,-219.824860,294.500458,0.000000
117.470009,64.935059,-219.824860,-0.001306,0.003446,0.087538,288.845581,14.714494,0.875378,-219.824860,294.500458,0.000000
117.830002,64.889252,-219.780380,-0.001302,0.003446,0.087538,288.641815,14.704115,0.875378,-219.780380,294.500458,0.000000
118.190002,64.879562,-219.869339,-0.001302,0.003446,0.087538,288.598694,14.701919,0.875378,-219.869339,294.500458,0.000000
118.550003,64.853134,-219.913818,-0.001298,0.003446,0.087538,288.481140,14.695930,0.875378,-219.913818,294.500458,0.000000
118.910004,64.815521,-219.913818,-0.001311,0.003446,0.087538,288.313843,14.687407,0.875378,-219.913818,294.500458,0.000000
119.270004,64.803604,-219.913818,-0.001298,0.003446,0.087538,288.260834,14.684707,0.875378,-219.913818,294.500458,0.000000
119.630005,64.779404,-219.958298,-0.001306,0.003446,0.087538,288.153168,14.679223,0.875378,-219.958298,294.500458,0.000000
119.990005,64.756683,-219.958298,-0.001302,0.003446,0.087538,288.052124,14.674074,0.875378,-219.958298,294.500458,0.000000
120.350006,64.740295,-219.958298,-0.001298,0.003446,0.087538,287.979218,14.670361,0.875378,-219.958298,294.500458,0.000000
120.710007,65.984772,-220.091751,-0.001302,0.003459,0.087850,293.514923,14.952363,0.878500,-220.091751,294.500458,0.000000
121.070007,65.924072,-220.002777,-0.001302,0.003459,0.087850,293.244934,14.938608,0.878500,-220.002777,0.087850,0.000000
121.430008,65.819443,-220.047272,-0.001306,0.003447,0.087546,292.779510,14.914899,0.875464,-220.047272,0.087260,0.000000
121.790009,65.752045,-220.091751,-0.001306,0.003429,0.087095,292.479706,14.899627,0.870955,-220.091751,0.086662,0.000000
122.150009,65.697296,-220.091751,-0.001285,0.003408,0.086575,292.236176,14.887220,0.865751,-220.091751,0.086063,0.000000
122.510002,65.651505,-220.091751,-0.001298,0.003386,0.086003,292.032471,14.876843,0.860028,-220.091751,0.085456,0.000000
122.870003,65.619476,-220.136230,-0.001281,0.003359,0.085326,291.890015,14.869586,0.853263,-220.136230,0.084858,0.000000
123.230003,65.595276,-220.180710,-0.001298,0.003339,0.084806,291.782349,14.864102,0.848060,-220.180710,0.084260,0.000000
123.590004,65.563248,-220.180710,-0.001289,0.003316,0.084234,291.639893,14.856845,0.842336,-220.180710,0.083661,0.000000
123.950005,65.491379,-220.225189,-0.001285,0.003292,0.083609,291.320190,14.840559,0.836092,-220.225189,0.083063,0.000000
124.310005,65.486908,-220.225189,-0.001293,0.003271,0.083080,291.300323,14.839546,0.830802,-220.225189,0.082456,0.000000
124.670006,65.295883,-220.225189,-0.001293,0.003246,0.082438,290.450592,14.796259,0.824385,-220.225189,0.081857,0.000000
125.030006,64.719452,-220.269669,-0.001302,0.003223,0.081857,287.886505,14.665637,0.818574,-220.269669,0.081259,0.000000
125.390007,64.003006,-220.269669,-0.001285,0.003201,0.081294,284.699585,14.503288,0.812937,-220.269669,0.080661,0.000000
125.750008,63.019943,-220.314148,-0.001285,0.003181,0.080791,280.326721,14.280523,0.807907,-220.314148,0.080062,0.000000
126.110008,61.877502,-220.269669,-0.001272,0.003160,0.080270,275.244873,14.021643,0.802704,-220.269669,0.079455,0.000000
126.470009,60.932419,-220.358627,-0.001276,0.003145,0.079889,271.040924,13.807484,0.798888,-220.358627,0.078857,0.000000
126.830009,58.914909,-220.358627,-0.001259,0.003115,0.079126,262.066620,13.350309,0.791257,-220.358627,0.078258,0.000000
127.190002,57.480530,-220.358627,-0.001263,0.003096,0.078640,255.686172,13.025274,0.786400,-220.358627,0.077660,0.000000
127.550003,55.826820,-220.447586,-0.001276,0.003075,0.078094,248.330093,12.650538,0.780937,-220.447586,0.077062,0.000000
127.910004,54.457611,-220.403107,-0.001268,0.003055,0.077608,242.239548,12.340271,0.776080,-220.403107,0.076463,0.000000
128.270004,51.251854,-220.492081,-0.001259,0.003031,0.076984,227.979630,11.613836,0.769836,-220.492081,0.075856,0.000000
128.630005,48.482895,-220.492081,-0.001259,0.003003,0.076272,215.662689,10.986381,0.762725,-220.492081,0.075258,0.000000
128.990005,46.044228,-220.447586,-0.001268,0.002981,0.075709,204.814957,10.433771,0.757088,-220.447586,0.074659,0.000000
129.350006,43.619705,-220.581039,-0.001276,0.002957,0.075119,194.030136,9.884367,0.751191,-220.581039,0.074061,0.000000
129.710007,40.825798,-220.581039,-0.001268,0.002931,0.074443,181.602219,9.251258,0.744426,-220.581039,0.073463,0.000000
130.070007,38.734550,-220.581039,-0.001268,0.002915,0.074044,172.299881,8.777374,0.740437,-220.581039,0.072856,0.000000
130.430008,36.224022,-220.581039,-0.001281,0.002886,0.073315,161.132492,8.208481,0.733153,-220.581039,0.072257,0.000000
130.790009,32.711060,-220.625519,-0.001263,0.002858,0.072595,145.506058,7.412432,0.725955,-220.625519,0.071659,0.000000
131.150009,30.236641,-220.669998,-0.001272,0.002836,0.072032,134.499298,6.851721,0.720318,-220.669998,0.071060,0.000000
131.510010,27.616257,-220.625519,-0.001259,0.002812,0.071433,122.843246,6.257933,0.714334,-220.625519,0.070462,0.000000
131.870010,26.861084,-220.669998,-0.001263,0.002807,0.071286,119.484070,6.086809,0.712859,-220.669998,0.069855,0.000000
132.230011,23.237900,-220.714478,-0.001268,0.002772,0.070410,103.367340,5.265783,0.704101,-220.714478,0.069257,0.000000
132.590012,20.003471,-220.758957,-0.001259,0.002741,0.069630,88.979881,4.532851,0.696295,-220.758957,0.068658,0.000000
132.950012,17.375641,-220.758957,-0.001259,0.002717,0.069005,77.290710,3.937376,0.690051,-220.758957,0.068060,0.000000
133.310013,15.162636,-220.714478,-0.001259,0.002694,0.068424,67.446770,3.435902,0.684241,-220.714478,0.067461,0.000000
133.670013,12.998032,-220.803436,-0.001276,0.002675,0.067938,57.818130,2.945396,0.679385,-220.803436,0.066854,0.000000
134.029999,10.074165,-220.714478,-0.001263,0.002652,0.067349,44.812126,2.282839,0.673487,-220.714478,0.066256,0.000000
134.389999,7.014008,-220.892410,-0.001276,0.002623,0.066612,31.199863,1.589397,0.666116,-220.892410,0.065658,0.000000
134.750000,4.537727,-220.803436,-0.001276,0.002597,0.065970,20.184820,1.028264,0.659699,-220.803436,0.065059,0.000000
135.110001,2.489311,-220.847916,-0.001263,0.002577,0.065467,11.073009,0.564086,0.654669,-220.847916,0.064461,0.000000
135.470001,1.022530,-220.892410,-0.001281,0.002563,0.065103,4.548439,0.231709,0.651026,-220.892410,0.063854,0.000000
135.830002,-1.785900,-220.936890,-0.001259,0.002537,0.064452,-7.944080,-0.404691,0.644522,-220.936890,0.063255,0.000000
136.190002,-0.505684,-220.981369,-0.001293,0.002509,0.063724,-2.249394,-0.114590,0.637237,-220.981369,0.062657,0.000000
136.550003,-0.304230,-220.936890,-0.001293,0.002483,0.063073,-1.353281,-0.068939,0.630733,-220.936890,0.062059,0.000000
136.910004,-0.155281,-220.936890,-0.001281,0.002457,0.062414,-0.690725,-0.035187,0.624142,-220.936890,0.061460,0.000000
137.270004,-0.118042,-220.981369,-0.001302,0.002430,0.061729,-0.525077,-0.026749,0.617291,-220.981369,0.060862,0.000000
137.630005,-0.113945,-220.981369,-0.001324,0.002409,0.061183,-0.506853,-0.025820,0.611828,-220.981369,0.060255,0.000000
137.990005,-0.083786,-221.025848,-0.001350,0.002391,0.060732,-0.372699,-0.018986,0.607318,-221.025848,0.059656,0.000000
138.350006,-0.090858,-221.025848,-0.001367,0.002371,0.060220,-0.404159,-0.020589,0.602202,-221.025848,0.059058,0.000000
138.710007,-0.087509,-221.070328,-0.001393,0.002337,0.059370,-0.389260,-0.019830,0.593703,-221.070328,0.058460,0.000000
139.070007,-0.067032,-221.025848,-0.001423,0.002319,0.058893,-0.298173,-0.015190,0.588933,-221.025848,0.057861,0.000000
139.430008,-0.042824,-221.114807,-0.001440,0.002302,0.058477,-0.190490,-0.009704,0.584770,-221.114807,0.057254,0.000000
139.790009,-0.072990,-221.203766,-0.001470,0.002272,0.057697,-0.324678,-0.016540,0.576965,-221.203766,0.056656,0.000000
140.150009,-0.083412,-221.114807,-0.001496,0.002248,0.057089,-0.371036,-0.018901,0.570895,-221.114807,0.056057,0.000000
140.510010,-0.100914,-221.159286,-0.001531,0.002221,0.056422,-0.448888,-0.022867,0.564217,-221.159286,0.055459,0.000000
140.870010,-0.100166,-221.159286,-0.001552,0.002198,0.055841,-0.445562,-0.022698,0.558407,-221.159286,0.054861,0.000000
141.230011,-0.075218,-221.203766,-0.001565,0.002175,0.055234,-0.334587,-0.017045,0.552336,-221.203766,0.054254,0.000000
141.590012,-0.080437,-221.248245,-0.001600,0.002151,0.054635,-0.357800,-0.018227,0.546352,-221.248245,0.053655,0.000000
141.950012,-0.088257,-221.203766,-0.001625,0.002129,0.054089,-0.392586,-0.019999,0.540889,-221.203766,0.053057,0.000000
142.310013,-0.079689,-221.337219,-0.001647,0.002104,0.053447,-0.354474,-0.018058,0.534471,-221.337219,0.052458,0.000000
142.670013,-0.075218,-221.337219,-0.001677,0.002077,0.052762,-0.334587,-0.017045,0.527620,-221.337219,0.051860,0.000000
143.030014,-0.089745,-221.337219,-0.001686,0.002055,0.052190,-0.399204,-0.020336,0.521896,-221.337219,0.051253,0.000000
143.389999,-0.080063,-221.381699,-0.001716,0.002041,0.051834,-0.356137,-0.018143,0.518341,-221.381699,0.050655,0.000000
143.750000,-0.096443,-221.337219,-0.001738,0.002017,0.051227,-0.429001,-0.021854,0.512270,-221.337219,0.050056,0.000000
144.110001,-0.094955,-221.426178,-0.001763,0.001997,0.050715,-0.422383,-0.021517,0.507154,-221.426178,0.049458,0.000000
144.470001,-0.067772,-221.381699,-0.001798,0.001958,0.049735,-0.301465,-0.015357,0.497354,-221.381699,0.048859,0.000000
144.830002,-0.105385,-221.515137,-0.001815,0.001938,0.049232,-0.468775,-0.023881,0.492324,-221.515137,0.048261,0.000000
145.190002,-0.100540,-221.426178,-0.001832,0.001916,0.048677,-0.447225,-0.022783,0.486774,-221.426178,0.047654,0.000000
145.550003,-0.081551,-221.470657,-0.001863,0.001892,0.048044,-0.362755,-0.018480,0.480443,-221.470657,0.047056,0.000000
145.910004,-0.083412,-221.515137,-0.001901,0.001872,0.047559,-0.371036,-0.018901,0.475587,-221.515137,0.046457,0.000000
146.270004,-0.090485,-221.470657,-0.001923,0.001842,0.046787,-0.402496,-0.020504,0.467868,-221.470657,0.045859,0.000000
146.630005,-0.100914,-221.559616,-0.001936,0.001820,0.046232,-0.448888,-0.022867,0.462318,-221.559616,0.045261,0.000000
146.990005,-0.112083,-221.559616,-0.001966,0.001794,0.045564,-0.498572,-0.025398,0.455640,-221.559616,0.044653,0.000000
147.350006,-0.125862,-221.604095,-0.001983,0.001777,0.045148,-0.559863,-0.028521,0.451478,-221.604095,0.044055,0.000000
147.710007,-0.077827,-221.559616,-0.002026,0.001748,0.044393,-0.346194,-0.017636,0.443933,-221.559616,0.044289,0.000000
147.900009,-0.078941,-221.604095,-0.002026,0.001748,0.044393,-0.351149,-0.017888,0.443933,-221.604095,0.044289,0.000000