File: Data/compression 20/AutoNoHeating-17-20-reverse-2-2_09112024_170840.csv
Time (sec),S:Load (lbs),S:HL1 (DIM),S:LVDT (in),S:Position (in),Ch:Position (mm),Ch:Load (N),Ch:Stress (MPa),Ch:Strain (mm/mm),Ch:HL1 (DIM),Set Point (),Cycles ()
0.110000,-0.054367,-190.245026,-0.010727,-0.006228,-0.158199,-0.241837,-0.012320,-1.581993,-190.245026,-0.157878,0.000000
0.460000,-0.067032,-190.289505,-0.010723,-0.006154,-0.156317,-0.298173,-0.015190,-1.563174,-190.289505,-0.155710,0.000000
0.810000,-0.087509,-190.289505,-0.010649,-0.005951,-0.151166,-0.389260,-0.019830,-1.511661,-190.289505,-0.149865,0.000000
1.160000,-0.129959,-190.333984,-0.010417,-0.005720,-0.145286,-0.578087,-0.029449,-1.452863,-190.333984,-0.144038,0.000000
1.510000,-0.046173,-190.378464,-0.010192,-0.005487,-0.139380,-0.205388,-0.010463,-1.393805,-190.378464,-0.138210,0.000000
1.860000,-0.037239,-190.378464,-0.009964,-0.005260,-0.133605,-0.165648,-0.008438,-1.336048,-190.378464,-0.132382,0.000000
2.210000,-0.050270,-190.378464,-0.009710,-0.005033,-0.127846,-0.223612,-0.011391,-1.278464,-190.378464,-0.126554,0.000000
2.560000,-0.067398,-190.422958,-0.009481,-0.004808,-0.122123,-0.299802,-0.015273,-1.221227,-190.422958,-0.120726,0.000000
2.910000,-0.105011,-190.422958,-0.009257,-0.004574,-0.116182,-0.467112,-0.023796,-1.161822,-190.422958,-0.114881,0.000000
3.260000,-0.087883,-190.467438,-0.009020,-0.004344,-0.110346,-0.390923,-0.019915,-1.103458,-190.467438,-0.109054,0.000000
3.610000,-0.046547,-190.422958,-0.008770,-0.004112,-0.104440,-0.207051,-0.010548,-1.044400,-190.422958,-0.103226,0.000000
3.960000,-0.020851,-190.422958,-0.008545,-0.003885,-0.098690,-0.092750,-0.004725,-0.986903,-190.422958,-0.097398,0.000000
4.310000,-0.039848,-190.511917,-0.008313,-0.003653,-0.092776,-0.177254,-0.009030,-0.927758,-190.511917,-0.091570,0.000000
4.660000,-0.069633,-190.511917,-0.008080,-0.003424,-0.086965,-0.309745,-0.015779,-0.869654,-190.511917,-0.085725,0.000000
5.010000,-0.089745,-190.511917,-0.007843,-0.003191,-0.081051,-0.399204,-0.020336,-0.810509,-190.511917,-0.079898,0.000000
5.360000,-0.084160,-190.600876,-0.007597,-0.002970,-0.075440,-0.374362,-0.019071,-0.754400,-190.600876,-0.074070,0.000000
5.710000,-0.027184,-190.600876,-0.007355,-0.002738,-0.069534,-0.120918,-0.006160,-0.695342,-190.600876,-0.068242,0.000000
6.060000,-0.042824,-190.645355,-0.007131,-0.002508,-0.063706,-0.190490,-0.009704,-0.637064,-190.645355,-0.062414,0.000000
6.410000,-0.045433,-190.645355,-0.006873,-0.002272,-0.057714,-0.202096,-0.010295,-0.577139,-190.645355,-0.056586,0.000000
6.760000,-0.080803,-190.689835,-0.006657,-0.002047,-0.051982,-0.359429,-0.018310,-0.519815,-190.689835,-0.050741,0.000000
7.110000,-0.053993,-190.645355,-0.006411,-0.001812,-0.046015,-0.240174,-0.012235,-0.460150,-190.645355,-0.044914,0.000000
7.460001,-0.058464,-190.734314,-0.006191,-0.001587,-0.040309,-0.260061,-0.013248,-0.403086,-190.734314,-0.039086,0.000000
7.810000,-0.041336,-190.778793,-0.005950,-0.001360,-0.034542,-0.183872,-0.009367,-0.345416,-190.778793,-0.033258,0.000000
8.160001,-0.038727,-190.778793,-0.005691,-0.001124,-0.028549,-0.172265,-0.008776,-0.285491,-190.778793,-0.027430,0.000000
8.510000,-0.050644,-190.778793,-0.005467,-0.000896,-0.022756,-0.225275,-0.011476,-0.227560,-190.778793,-0.021585,0.000000
8.860001,-0.046547,-190.823273,-0.005247,-0.000675,-0.017136,-0.207051,-0.010548,-0.171364,-190.823273,-0.015757,0.000000
9.210000,-0.042450,-190.778793,-0.005010,-0.000444,-0.011283,-0.188827,-0.009619,-0.112826,-190.778793,-0.009930,0.000000
9.560000,-0.053627,-190.867767,-0.004781,-0.000213,-0.005420,-0.238545,-0.012152,-0.054202,-190.867767,-0.004102,0.000000
9.910001,-0.051758,-190.778793,-0.004544,0.000019,0.000486,-0.230230,-0.011728,0.004856,-190.778793,0.001726,0.000000
10.260000,0.091972,-190.867767,-0.004398,-0.000008,-0.000191,0.409113,0.020841,-0.001908,-190.867767,0.000026,0.000000
10.610001,0.057343,-190.912247,-0.004398,-0.000008,-0.000191,0.255072,0.012994,-0.001908,-190.912247,0.000043,0.000000
10.960001,0.102402,-190.956726,-0.004406,-0.000007,-0.000182,0.455506,0.023205,-0.001821,-190.956726,0.000624,0.000000
11.310000,0.198845,-190.912247,-0.004411,0.000012,0.000304,0.884506,0.045059,0.003035,-190.912247,0.001214,0.000000
11.660001,0.297523,-190.956726,-0.004393,0.000028,0.000702,1.323451,0.067420,0.007025,-190.956726,0.001795,0.000000
12.010000,0.571220,-191.001205,-0.004363,0.000057,0.001457,2.540915,0.129440,0.014569,-191.001205,0.002376,0.000000
12.360001,0.808792,-190.956726,-0.004346,0.000078,0.001986,3.597687,0.183275,0.019859,-190.956726,0.002966,0.000000
12.710001,0.958488,-191.001205,-0.004329,0.000092,0.002342,4.263570,0.217197,0.023415,-191.001205,0.003547,0.000000
13.060000,1.341660,-191.090164,-0.004294,0.000121,0.003070,5.968000,0.304024,0.030700,-191.090164,0.004128,0.000000
13.410001,1.669342,-191.090164,-0.004281,0.000142,0.003616,7.425604,0.378278,0.036163,-191.090164,0.004709,0.000000
13.760000,2.061821,-191.090164,-0.004251,0.000166,0.004206,9.171438,0.467215,0.042060,-191.090164,0.005299,0.000000
14.110001,2.444992,-191.090164,-0.004230,0.000192,0.004882,10.875868,0.554043,0.048825,-191.090164,0.005880,0.000000
14.460001,2.686668,-191.090164,-0.004225,0.000212,0.005377,11.950898,0.608808,0.053768,-191.090164,0.006461,0.000000
14.810000,3.315605,-191.134644,-0.004182,0.000242,0.006149,14.748549,0.751327,0.061486,-191.134644,0.007042,0.000000
15.160001,3.657440,-191.134644,-0.004191,0.000263,0.006686,16.269106,0.828788,0.066863,-191.134644,0.007632,0.000000
15.510001,3.994064,-191.223602,-0.004143,0.000283,0.007189,17.766485,0.905068,0.071893,-191.223602,0.008213,0.000000
15.860001,4.335159,-191.223602,-0.004139,0.000304,0.007710,19.283752,0.982361,0.077096,-191.223602,0.008794,0.000000
16.210001,4.913826,-191.223602,-0.004109,0.000333,0.008447,21.857790,1.113489,0.084468,-191.223602,0.009383,0.000000
16.560001,5.228477,-191.268097,-0.004079,0.000356,0.009036,23.257429,1.184790,0.090365,-191.268097,0.009964,0.000000
16.910002,5.529732,-191.223602,-0.004070,0.000378,0.009592,24.597475,1.253055,0.095915,-191.223602,0.010545,0.000000
17.260000,5.852203,-191.312576,-0.004049,0.000399,0.010129,26.031900,1.326128,0.101292,-191.312576,0.011127,0.000000
17.610001,6.235001,-191.312576,-0.004040,0.000420,0.010667,27.734669,1.412871,0.106669,-191.312576,0.011716,0.000000
17.960001,6.382088,-191.357056,-0.004005,0.000437,0.011100,28.388945,1.446202,0.111005,-191.357056,0.012297,0.000000
18.310001,6.941765,-191.312576,-0.003997,0.000468,0.011898,30.878511,1.573026,0.118983,-191.312576,0.012878,0.000000
18.660002,6.849045,-191.357056,-0.003967,0.000482,0.012254,30.466072,1.552016,0.122539,-191.357056,0.013459,0.000000
19.010000,7.529739,-191.401535,-0.003949,0.000518,0.013147,33.493954,1.706263,0.131471,-191.401535,0.014049,0.000000
19.360001,7.517456,-191.401535,-0.003923,0.000534,0.013572,33.439316,1.703480,0.135721,-191.401535,0.014630,0.000000
19.710001,7.673477,-191.446014,-0.003902,0.000553,0.014040,34.133331,1.738835,0.140404,-191.446014,0.015211,0.000000
20.060001,7.895782,-191.490494,-0.003893,0.000578,0.014691,35.122196,1.789210,0.146908,-191.490494,0.015792,0.000000
20.410002,8.364975,-191.490494,-0.003863,0.000605,0.015376,37.209267,1.895530,0.153759,-191.490494,0.016382,0.000000
20.760000,8.242836,-191.490494,-0.003837,0.000619,0.015714,36.665966,1.867853,0.157141,-191.490494,0.016963,0.000000
21.110001,8.474075,-191.534973,-0.003824,0.000641,0.016286,37.694569,1.920253,0.162865,-191.534973,0.017544,0.000000
21.460001,8.998009,-191.534973,-0.003803,0.000673,0.017084,40.025143,2.038978,0.170843,-191.534973,0.018134,0.000000
21.810001,9.049019,-191.534973,-0.003781,0.000693,0.017613,40.252045,2.050537,0.176134,-191.534973,0.018715,0.000000
22.160002,9.323830,-191.579453,-0.003747,0.000721,0.018316,41.474464,2.112810,0.183158,-191.579453,0.019296,0.000000
22.510000,9.205421,-191.623932,-0.003725,0.000737,0.018723,40.947762,2.085978,0.187234,-191.623932,0.019877,0.000000
22.860001,9.082909,-191.623932,-0.003717,0.000750,0.019044,40.402794,2.058217,0.190443,-191.623932,0.020467,0.000000
23.210001,9.751312,-191.623932,-0.003682,0.000787,0.019990,43.376003,2.209679,0.199896,-191.623932,0.021048,0.000000
23.560001,9.742378,-191.668411,-0.003660,0.000806,0.020484,43.336262,2.207654,0.204839,-191.668411,0.021629,0.000000
23.910002,10.103577,-191.712906,-0.003639,0.000838,0.021273,44.942955,2.289503,0.212730,-191.712906,0.022210,0.000000
24.260000,9.956490,-191.712906,-0.003617,0.000857,0.021759,44.288677,2.256173,0.217587,-191.712906,0.022799,0.000000
24.610001,9.968407,-191.757385,-0.003600,0.000877,0.022270,44.341686,2.258873,0.222704,-191.757385,0.023380,0.000000
24.960001,10.375038,-191.712906,-0.003591,0.000902,0.022921,46.150475,2.351017,0.229208,-191.712906,0.023961,0.000000
25.310001,10.527710,-191.801865,-0.003548,0.000926,0.023510,46.829594,2.385613,0.235105,-191.801865,0.024542,0.000000
25.660002,10.695656,-191.757385,-0.003540,0.000950,0.024126,47.576653,2.423670,0.241262,-191.757385,0.025132,0.000000
26.010002,10.862106,-191.846344,-0.003510,0.000975,0.024759,48.317062,2.461388,0.247593,-191.846344,0.025713,0.000000
26.360001,10.907906,-191.801865,-0.003475,0.000996,0.025306,48.520786,2.471767,0.253056,-191.801865,0.026294,0.000000
26.710001,10.965996,-191.846344,-0.003458,0.001019,0.025878,48.779186,2.484930,0.258780,-191.846344,0.026884,0.000000
27.060001,11.022224,-191.935303,-0.003441,0.001034,0.026268,49.029305,2.497672,0.262683,-191.935303,0.027465,0.000000
27.410002,11.395340,-191.935303,-0.003423,0.001063,0.027005,50.689003,2.582221,0.270054,-191.935303,0.028046,0.000000
27.760002,11.312675,-191.935303,-0.003393,0.001079,0.027404,50.321293,2.563489,0.274043,-191.935303,0.028627,0.000000
28.110001,11.730103,-191.935303,-0.003363,0.001110,0.028202,52.178101,2.658079,0.282022,-191.935303,0.029217,0.000000
28.460001,11.667175,-191.979782,-0.003350,0.001130,0.028696,51.898190,2.643820,0.286965,-191.979782,0.029798,0.000000
28.810001,11.985924,-191.979782,-0.003320,0.001156,0.029364,53.316051,2.716049,0.293643,-191.979782,0.030379,0.000000
29.160002,12.122581,-192.068741,-0.003311,0.001179,0.029937,53.923935,2.747016,0.299366,-192.068741,0.030960,0.000000
29.510002,12.153488,-192.024261,-0.003294,0.001198,0.030431,54.061417,2.754020,0.304309,-192.024261,0.031550,0.000000
29.860001,12.149765,-192.068741,-0.003264,0.001214,0.030847,54.044853,2.753176,0.308472,-192.068741,0.032131,0.000000
30.210001,12.732903,-192.113220,-0.003229,0.001253,0.031836,56.638779,2.885317,0.318359,-192.113220,0.032712,0.000000
30.560001,12.651352,-192.113220,-0.003208,0.001270,0.032261,56.276024,2.866838,0.322608,-192.113220,0.033301,0.000000
30.910002,12.624542,-192.157715,-0.003186,0.001286,0.032668,56.156769,2.860762,0.326684,-192.157715,0.033883,0.000000
31.260002,13.063942,-192.157715,-0.003173,0.001316,0.033414,58.111317,2.960332,0.334142,-192.157715,0.034464,0.000000
31.610001,13.342102,-192.202194,-0.003152,0.001341,0.034056,59.348633,3.023364,0.340560,-192.202194,0.035045,0.000000
31.960001,13.543930,-192.202194,-0.003122,0.001365,0.034663,60.246410,3.069098,0.346630,-192.202194,0.035634,0.000000
32.310001,13.689903,-192.157715,-0.003100,0.001389,0.035270,60.895733,3.102176,0.352701,-192.157715,0.036215,0.000000
32.660000,13.948700,-192.246674,-0.003074,0.001413,0.035894,62.046917,3.160821,0.358945,-192.246674,0.036796,0.000000
33.010002,13.816505,-192.291153,-0.003070,0.001431,0.036337,61.458885,3.130865,0.363368,-192.291153,0.037377,0.000000
33.360001,14.429062,-192.291153,-0.003044,0.001459,0.037057,64.183670,3.269672,0.370566,-192.291153,0.037967,0.000000
33.710003,14.269684,-192.291153,-0.003001,0.001477,0.037508,63.474724,3.233557,0.375075,-192.291153,0.038548,0.000000
34.060001,14.410065,-192.291153,-0.002997,0.001497,0.038019,64.099167,3.265367,0.380192,-192.291153,0.039129,0.000000
34.410000,14.960434,-192.335632,-0.002975,0.001526,0.038765,66.547333,3.390083,0.387650,-192.335632,0.039710,0.000000
34.760002,14.751534,-192.335632,-0.002940,0.001542,0.039155,65.618095,3.342745,0.391552,-192.335632,0.040300,0.000000
35.110001,15.135452,-192.424591,-0.002932,0.001569,0.039858,67.325851,3.429743,0.398577,-192.424591,0.040881,0.000000
35.460003,15.311951,-192.469070,-0.002906,0.001587,0.040317,68.110962,3.469738,0.403173,-192.469070,0.041462,0.000000
35.810001,15.653419,-192.424591,-0.002884,0.001614,0.040994,69.629890,3.547116,0.409938,-192.424591,0.042052,0.000000
36.160000,16.136757,-192.513550,-0.002871,0.001641,0.041679,71.779877,3.656641,0.416789,-192.513550,0.042633,0.000000
36.510002,16.120750,-192.513550,-0.002824,0.001662,0.042225,71.708679,3.653014,0.422252,-192.513550,0.043214,0.000000
36.860001,16.262993,-192.513550,-0.002815,0.001683,0.042754,72.341408,3.685247,0.427542,-192.513550,0.043795,0.000000
37.210003,16.340446,-192.469070,-0.002802,0.001702,0.043240,72.685936,3.702798,0.432399,-192.469070,0.044385,0.000000
37.560001,17.022636,-192.558044,-0.002772,0.001734,0.044038,75.720467,3.857384,0.440377,-192.558044,0.044966,0.000000
37.910004,17.153336,-192.558044,-0.002746,0.001756,0.044610,76.301849,3.887001,0.446101,-192.558044,0.045547,0.000000
38.260002,17.443039,-192.602524,-0.002729,0.001781,0.045243,77.590515,3.952649,0.452432,-192.602524,0.046128,0.000000
38.610001,17.301170,-192.647003,-0.002703,0.001799,0.045694,76.959450,3.920501,0.456941,-192.647003,0.046717,0.000000
38.960003,17.611351,-192.691483,-0.002699,0.001819,0.046206,78.339203,3.990789,0.462058,-192.691483,0.047298,0.000000
39.310001,17.612473,-192.691483,-0.002665,0.001836,0.046622,78.344193,3.991043,0.466221,-192.691483,0.047880,0.000000
39.660004,18.603355,-192.691483,-0.002673,0.001869,0.047481,82.751862,4.215581,0.474806,-192.691483,0.048469,0.000000
40.010002,18.874069,-192.735962,-0.002621,0.001893,0.048088,83.956055,4.276925,0.480877,-192.735962,0.049050,0.000000
40.360001,19.140312,-192.780441,-0.002608,0.001916,0.048677,85.140358,4.337256,0.486774,-192.780441,0.049631,0.000000
40.710003,18.983917,-192.780441,-0.002591,0.001935,0.049146,84.444679,4.301817,0.491457,-192.780441,0.050212,0.000000
41.060001,19.162285,-192.869400,-0.002557,0.001955,0.049649,85.238098,4.342236,0.496487,-192.869400,0.050802,0.000000
41.410004,19.499657,-192.869400,-0.002565,0.001980,0.050290,86.738808,4.418685,0.502904,-192.869400,0.051383,0.000000
41.760002,20.711723,-192.780441,-0.002539,0.002011,0.051071,92.130348,4.693344,0.510709,-192.780441,0.051964,0.000000
42.110001,20.223923,-192.869400,-0.002509,0.002023,0.051392,89.960503,4.582806,0.513918,-192.869400,0.052545,0.000000
42.460003,20.653267,-192.913879,-0.002492,0.002047,0.051982,91.870323,4.680097,0.519815,-192.913879,0.053135,0.000000
42.810001,21.314598,-192.913879,-0.002462,0.002074,0.052675,94.812065,4.829957,0.526753,-192.913879,0.053716,0.000000
43.160004,21.756607,-192.958359,-0.002449,0.002097,0.053265,96.778221,4.930118,0.532650,-192.958359,0.054297,0.000000
43.510002,22.054504,-193.002853,-0.002419,0.002121,0.053872,98.103333,4.997622,0.538721,-193.002853,0.054878,0.000000
43.860001,21.930878,-193.002853,-0.002406,0.002140,0.054349,97.553413,4.969608,0.543490,-193.002853,0.055468,0.000000
44.210003,21.524612,-193.002853,-0.002393,0.002147,0.054540,95.746262,4.877547,0.545398,-193.002853,0.056049,0.000000
44.560001,23.048737,-193.091812,-0.002358,0.002185,0.055511,102.525902,5.222919,0.555111,-193.091812,0.056630,0.000000
44.910004,23.274765,-193.091812,-0.002350,0.002208,0.056083,103.531326,5.274137,0.560835,-193.091812,0.057220,0.000000
45.260002,24.156914,-193.091812,-0.002315,0.002240,0.056890,107.455322,5.474035,0.568900,-193.091812,0.057801,0.000000
45.610001,24.070526,-193.091812,-0.002298,0.002258,0.057341,107.071045,5.454459,0.573410,-193.091812,0.058382,0.000000
45.960003,24.186707,-193.091812,-0.002289,0.002275,0.057792,107.587845,5.480786,0.577919,-193.091812,0.058963,0.000000
46.310001,25.217804,-193.136292,-0.002259,0.002304,0.058512,112.174393,5.714436,0.585117,-193.136292,0.059552,0.000000
46.660004,25.625557,-193.136292,-0.002255,0.002327,0.059101,113.988167,5.806834,0.591014,-193.136292,0.060133,0.000000
47.010002,26.247047,-193.225250,-0.002225,0.002350,0.059691,116.752701,5.947666,0.596911,-193.225250,0.060714,0.000000
47.360001,26.856621,-193.180771,-0.002203,0.002375,0.060333,119.464218,6.085797,0.603329,-193.180771,0.061296,0.000000
47.710003,27.078178,-193.269730,-0.002182,0.002395,0.060836,120.449753,6.136003,0.608359,-193.269730,0.061885,0.000000
48.060001,27.617004,-193.225250,-0.002160,0.002418,0.061417,122.846573,6.258103,0.614169,-193.225250,0.062466,0.000000
48.410004,27.583115,-193.269730,-0.002147,0.002433,0.061790,122.695824,6.250423,0.617898,-193.269730,0.063047,0.000000
48.760002,28.695763,-193.269730,-0.002121,0.002463,0.062553,127.645126,6.502553,0.625530,-193.269730,0.063637,0.000000
49.110001,28.705444,-193.314209,-0.002117,0.002478,0.062935,127.688194,6.504746,0.629346,-193.314209,0.064218,0.000000
49.460003,30.034073,-193.314209,-0.002078,0.002512,0.063810,133.598236,6.805818,0.638105,-193.314209,0.064799,0.000000
49.810001,30.216164,-193.358688,-0.002057,0.002529,0.064227,134.408203,6.847081,0.642267,-193.358688,0.065380,0.000000
50.160004,31.100922,-193.314209,-0.002057,0.002555,0.064886,138.343811,7.047570,0.648858,-193.314209,0.065970,0.000000
50.510002,31.717567,-193.403168,-0.002031,0.002577,0.065467,141.086792,7.187304,0.654669,-193.403168,0.066551,0.000000
50.860001,32.198303,-193.447662,-0.002013,0.002599,0.066022,143.225204,7.296240,0.660219,-193.447662,0.067132,0.000000
51.210003,32.210960,-193.492142,-0.001996,0.002612,0.066351,143.281509,7.299108,0.663514,-193.492142,0.067713,0.000000
51.560001,34.200172,-193.447662,-0.001979,0.002653,0.067375,152.129959,7.749870,0.673748,-193.447662,0.068303,0.000000
51.910004,34.225494,-193.447662,-0.001953,0.002669,0.067782,152.242599,7.755608,0.677824,-193.447662,0.068884,0.000000
52.260002,34.408707,-193.492142,-0.001932,0.002685,0.068190,153.057571,7.797124,0.681900,-193.492142,0.069465,0.000000
52.610001,35.613701,-193.492142,-0.001927,0.002715,0.068953,158.417648,8.070180,0.689531,-193.492142,0.070046,0.000000
52.960003,36.579636,-193.447662,-0.001906,0.002738,0.069534,162.714340,8.289063,0.695342,-193.447662,0.070636,0.000000
53.310001,37.472214,-193.581100,-0.001880,0.002765,0.070219,166.684738,8.491325,0.702193,-193.581100,0.071217,0.000000
53.660004,38.427719,-193.581100,-0.001867,0.002789,0.070844,170.935028,8.707846,0.708437,-193.581100,0.071798,0.000000
54.010002,39.188477,-193.625580,-0.001841,0.002813,0.071451,174.319046,8.880236,0.714507,-193.625580,0.072387,0.000000
54.360004,39.450630,-193.625580,-0.001828,0.002830,0.071893,175.485168,8.939641,0.718930,-193.625580,0.072968,0.000000
54.710003,40.826546,-193.625580,-0.001815,0.002858,0.072587,181.605545,9.251428,0.725868,-193.625580,0.073549,0.000000
55.060001,41.169868,-193.670059,-0.001802,0.002876,0.073046,183.132721,9.329226,0.730464,-193.670059,0.074130,0.000000
55.410004,41.482666,-193.759018,-0.001785,0.002897,0.073593,184.524109,9.400107,0.735928,-193.759018,0.074720,0.000000
55.760002,43.328888,-193.759018,-0.001776,0.002928,0.074365,192.736526,9.818466,0.743646,-193.759018,0.075301,0.000000
56.110004,43.510979,-193.759018,-0.001746,0.002939,0.074659,193.546494,9.859729,0.746595,-193.759018,0.075882,0.000000
56.460003,44.709267,-193.759018,-0.001729,0.002967,0.075371,198.876755,10.131264,0.753706,-193.759018,0.076463,0.000000
56.810001,45.622704,-193.759018,-0.001720,0.002986,0.075839,202.939926,10.338253,0.758389,-193.759018,0.077053,0.000000
57.160004,46.820992,-193.803497,-0.001694,0.003012,0.076515,208.270172,10.609788,0.765153,-193.803497,0.077634,0.000000
57.510002,48.381233,-193.847992,-0.001681,0.003040,0.077218,215.210480,10.963345,0.772178,-193.847992,0.078215,0.000000
57.860004,49.162476,-193.847992,-0.001677,0.003061,0.077747,218.685608,11.140376,0.777468,-193.847992,0.078796,0.000000
58.210003,50.013718,-193.892471,-0.001677,0.003082,0.078284,222.472122,11.333270,0.782845,-193.892471,0.079386,0.000000
58.560001,50.795326,-193.936951,-0.001638,0.003101,0.078761,225.948898,11.510386,0.787614,-193.936951,0.079967,0.000000
58.910004,52.736877,-193.892471,-0.001630,0.003133,0.079568,234.585342,11.950347,0.795680,-193.892471,0.080548,0.000000
59.260002,53.730362,-193.936951,-0.001608,0.003155,0.080140,239.004593,12.175474,0.801403,-193.936951,0.081138,0.000000
59.610004,55.059738,-193.936951,-0.001587,0.003180,0.080782,244.917953,12.476714,0.807821,-193.936951,0.081719,0.000000
59.960003,55.595581,-193.936951,-0.001587,0.003196,0.081172,247.301498,12.598139,0.811723,-193.936951,0.082300,0.000000
60.310001,56.661682,-193.981430,-0.001565,0.003218,0.081745,252.043747,12.839721,0.817447,-193.981430,0.082881,0.000000
60.660004,57.229179,-193.981430,-0.001556,0.003234,0.082152,254.568100,12.968317,0.821523,-193.981430,0.083470,0.000000
61.010002,59.503258,-194.025909,-0.001539,0.003268,0.083011,264.683716,13.483631,0.830108,-194.025909,0.084052,0.000000
61.360004,60.327690,-194.070389,-0.001544,0.003292,0.083618,268.350983,13.670449,0.836179,-194.070389,0.084633,0.000000
61.710003,62.212639,-194.025909,-0.001513,0.003316,0.084234,276.735626,14.097586,0.842336,-194.025909,0.085214,0.000000
62.060001,63.050850,-194.114868,-0.001509,0.003334,0.084685,280.464203,14.287526,0.846846,-194.114868,0.085803,0.000000
62.410004,63.896500,-194.114868,-0.001505,0.003353,0.085170,284.225830,14.479154,0.851702,-194.114868,0.086384,0.000000
62.760002,64.707901,-194.114868,-0.001475,0.003378,0.085803,287.835114,14.663020,0.858033,-194.114868,0.086965,0.000000
63.110004,65.833954,-194.159348,-0.001483,0.003384,0.085951,292.844055,14.918187,0.859507,-194.159348,0.015093,0.000000
63.460003,64.904526,-194.203827,-0.001462,0.003384,0.085959,288.709747,14.707576,0.859594,-194.203827,294.500458,0.000000
63.810001,65.540527,-194.203827,-0.001431,0.003394,0.086202,291.538818,14.851695,0.862022,-194.203827,294.500458,0.000000
64.160004,65.486542,-194.203827,-0.001457,0.003409,0.086601,291.298676,14.839462,0.866012,-194.203827,294.500458,0.000000
64.510002,65.036713,-194.248306,-0.001440,0.003412,0.086662,289.297760,14.737530,0.866619,-194.248306,294.500458,0.000000
64.860001,64.893341,-194.248306,-0.001440,0.003419,0.086835,288.660004,14.705041,0.868353,-194.248306,294.500458,0.000000
65.210007,65.157730,-194.337280,-0.001431,0.003426,0.087009,289.836060,14.764953,0.870088,-194.337280,294.500458,0.000000
65.560005,64.858337,-194.292801,-0.001431,0.003428,0.087061,288.504303,14.697109,0.870608,-194.292801,294.500458,0.000000
65.910004,65.291412,-194.337280,-0.001410,0.003436,0.087278,290.430695,14.795246,0.872776,-194.337280,294.500458,0.000000
66.260002,64.871002,-194.292801,-0.001418,0.003436,0.087278,288.560638,14.699979,0.872776,-194.292801,294.500458,0.000000
66.610001,65.544250,-194.337280,-0.001414,0.003447,0.087555,291.555389,14.852540,0.875551,-194.337280,294.500458,0.000000
66.960007,65.203537,-194.337280,-0.001397,0.003447,0.087555,290.039825,14.775332,0.875551,-194.337280,294.500458,0.000000
67.310005,64.828552,-194.426239,-0.001401,0.003447,0.087555,288.371796,14.690360,0.875551,-194.426239,294.500458,0.000000
67.660004,64.480011,-194.515198,-0.001401,0.003447,0.087555,286.821411,14.611379,0.875551,-194.515198,294.500458,0.000000
68.010002,64.175034,-194.470718,-0.001393,0.003447,0.087564,285.464813,14.542271,0.875638,-194.470718,294.500458,0.000000
68.360001,66.388794,-194.559677,-0.001362,0.003264,0.082915,295.312103,15.043916,0.829154,-194.559677,294.500458,0.000000
68.710007,66.070038,-194.470718,-0.001354,0.003265,0.082924,293.894196,14.971685,0.829241,-194.470718,294.500458,0.000000
69.060005,65.772141,-194.515198,-0.001362,0.003277,0.083236,292.569092,14.904180,0.832363,-194.515198,294.500458,0.000000
69.410004,65.453766,-194.515198,-0.001354,0.003371,0.085613,291.152893,14.832035,0.856125,-194.515198,294.500458,0.000000
69.760002,65.216568,-194.515198,-0.001367,0.003436,0.087278,290.097778,14.778286,0.872776,-194.515198,294.500458,0.000000
70.110001,65.077301,-194.604156,-0.001362,0.003457,0.087807,289.478302,14.746727,0.878066,-194.604156,294.500458,0.000000
70.460007,65.289917,-194.648636,-0.001362,0.003467,0.088058,290.424042,14.794907,0.880581,-194.648636,294.500458,0.000000
70.810005,65.167419,-194.648636,-0.001345,0.003471,0.088153,289.879150,14.767148,0.881535,-194.648636,294.500458,0.000000
71.160004,65.155502,-194.648636,-0.001371,0.003473,0.088223,289.826141,14.764448,0.882229,-194.648636,294.500458,0.000000
71.510002,65.091446,-194.693115,-0.001367,0.003474,0.088249,289.541199,14.749933,0.882489,-194.693115,294.500458,0.000000
71.860001,65.185654,-194.737610,-0.001362,0.003477,0.088327,289.960266,14.771280,0.883269,-194.737610,294.500458,0.000000
72.210007,65.068741,-194.693115,-0.001367,0.003478,0.088336,289.440216,14.744787,0.883356,-194.693115,294.500458,0.000000
72.560005,65.429932,-194.737610,-0.001367,0.003485,0.088509,291.046875,14.826634,0.885091,-194.737610,294.500458,0.000000
72.910004,65.378922,-194.782089,-0.001354,0.003485,0.088509,290.819977,14.815075,0.885091,-194.782089,294.500458,0.000000
73.260002,65.261627,-194.782089,-0.001354,0.003485,0.088518,290.298218,14.788496,0.885177,-194.782089,294.500458,0.000000
73.610001,65.123474,-194.915527,-0.001358,0.003485,0.088526,289.683685,14.757190,0.885264,-194.915527,294.500458,0.000000
73.960007,65.283218,-194.826569,-0.001350,0.003489,0.088622,290.394257,14.793388,0.886218,-194.826569,294.500458,0.000000
74.310005,65.209122,-194.826569,-0.001345,0.003489,0.088622,290.064667,14.776598,0.886218,-194.826569,294.500458,0.000000
74.660004,65.143951,-194.915527,-0.001341,0.003490,0.088656,289.774780,14.761830,0.886565,-194.915527,294.500458,0.000000
75.010002,65.018829,-194.871048,-0.001337,0.003490,0.088656,289.218201,14.733478,0.886565,-194.871048,294.500458,0.000000
75.360001,65.506638,-194.915527,-0.001341,0.003497,0.088813,291.388092,14.844016,0.888126,-194.915527,294.500458,0.000000
75.710007,65.384506,-194.960007,-0.001337,0.003497,0.088813,290.844818,14.816340,0.888126,-194.960007,294.500458,0.000000
76.060005,65.283966,-194.915527,-0.001354,0.003497,0.088813,290.397583,14.793558,0.888126,-194.915527,294.500458,0.000000
76.410004,65.154755,-194.960007,-0.001345,0.003497,0.088813,289.822815,14.764278,0.888126,-194.960007,294.500458,0.000000
76.760002,65.038193,-195.004486,-0.001328,0.003497,0.088813,289.304321,14.737865,0.888126,-195.004486,294.500458,0.000000
77.110001,64.939514,-195.004486,-0.001337,0.003497,0.088821,288.865387,14.715504,0.888213,-195.004486,294.500458,0.000000
77.460007,66.022003,-195.048965,-0.001337,0.003506,0.089064,293.680542,14.960800,0.890641,-195.048965,294.500458,0.000000
77.810005,65.864868,-195.048965,-0.001345,0.003505,0.089029,292.981567,14.925193,0.890294,-195.048965,294.500458,0.000000
78.160004,65.743103,-195.093445,-0.001337,0.003505,0.089029,292.439941,14.897600,0.890294,-195.093445,294.500458,0.000000
78.510002,65.583359,-195.137939,-0.001337,0.003505,0.089029,291.729340,14.861402,0.890294,-195.137939,294.500458,0.000000
78.860001,65.477600,-195.137939,-0.001324,0.003505,0.089029,291.258911,14.837436,0.890294,-195.137939,294.500458,0.000000
79.210007,65.351364,-195.182419,-0.001328,0.003505,0.089038,290.697388,14.808831,0.890381,-195.182419,294.500458,0.000000
79.560005,65.259384,-195.182419,-0.001345,0.003505,0.089038,290.288239,14.787988,0.890381,-195.182419,294.500458,0.000000
79.910004,65.139862,-195.226898,-0.001319,0.003505,0.089038,289.756592,14.760904,0.890381,-195.226898,294.500458,0.000000
80.260002,65.029266,-195.226898,-0.001328,0.003505,0.089038,289.264618,14.735842,0.890381,-195.226898,294.500458,0.000000
80.610001,65.159225,-195.271378,-0.001315,0.003517,0.089342,289.842712,14.765291,0.893416,-195.271378,294.500458,0.000000
80.960007,65.742355,-195.271378,-0.001319,0.003517,0.089324,292.436615,14.897430,0.893242,-195.271378,294.500458,0.000000
81.310005,65.658951,-195.360336,-0.001328,0.003517,0.089324,292.065613,14.878531,0.893242,-195.360336,294.500458,0.000000
81.660004,65.604584,-195.360336,-0.001324,0.003517,0.089324,291.823761,14.866211,0.893242,-195.360336,294.500458,0.000000
82.010002,65.532333,-195.315857,-0.001319,0.003517,0.089324,291.502380,14.849839,0.893242,-195.315857,294.500458,0.000000
82.360001,65.464935,-195.360336,-0.001332,0.003517,0.089324,291.202576,14.834566,0.893242,-195.360336,294.500458,0.000000
82.710007,65.362167,-195.404816,-0.001319,0.003517,0.089324,290.745453,14.811279,0.893242,-195.404816,294.500458,0.000000
83.060005,65.298492,-195.404816,-0.001328,0.003517,0.089324,290.462189,14.796850,0.893242,-195.404816,294.500458,0.000000
83.410004,65.221786,-195.449295,-0.001319,0.003517,0.089324,290.121002,14.779469,0.893242,-195.449295,294.500458,0.000000
83.760002,65.139114,-195.404816,-0.001332,0.003517,0.089324,289.753265,14.760735,0.893242,-195.404816,294.500458,0.000000
84.110001,65.060913,-195.493774,-0.001324,0.003517,0.089324,289.405396,14.743013,0.893242,-195.493774,294.500458,0.000000
84.460007,64.991287,-195.538254,-0.001311,0.003517,0.089324,289.095673,14.727236,0.893242,-195.538254,294.500458,0.000000
84.810005,64.926117,-195.493774,-0.001328,0.003517,0.089324,288.805786,14.712468,0.893242,-195.493774,294.500458,0.000000
85.160004,65.819443,-195.582748,-0.001315,0.003527,0.089593,292.779510,14.914899,0.895931,-195.582748,294.500458,0.000000
85.510002,65.781830,-195.582748,-0.001315,0.003527,0.089593,292.612183,14.906376,0.895931,-195.582748,294.500458,0.000000
85.860001,65.757629,-195.627228,-0.001319,0.003527,0.089593,292.504547,14.900892,0.895931,-195.627228,294.500458,0.000000
86.210007,65.673096,-195.627228,-0.001324,0.003527,0.089593,292.128510,14.881736,0.895931,-195.627228,294.500458,0.000000
86.560005,65.600479,-195.582748,-0.001328,0.003527,0.089593,291.805511,14.865281,0.895931,-195.582748,294.500458,0.000000
86.910004,65.577393,-195.671707,-0.001324,0.003527,0.089593,291.702820,14.860049,0.895931,-195.671707,294.500458,0.000000
87.260002,65.534943,-195.671707,-0.001319,0.003527,0.089593,291.513977,14.850430,0.895931,-195.671707,294.500458,0.000000
87.610001,65.457489,-195.760666,-0.001319,0.003527,0.089593,291.169464,14.832879,0.895931,-195.760666,294.500458,0.000000
87.960007,65.381897,-195.716187,-0.001324,0.003527,0.089593,290.833191,14.815749,0.895931,-195.716187,294.500458,0.000000
88.310005,65.321579,-195.760666,-0.001337,0.003527,0.089593,290.564880,14.802081,0.895931,-195.760666,294.500458,0.000000
88.660004,65.272415,-195.716187,-0.001319,0.003527,0.089593,290.346191,14.790941,0.895931,-195.716187,294.500458,0.000000
89.010002,65.228485,-195.805145,-0.001324,0.003527,0.089593,290.150787,14.780987,0.895931,-195.805145,294.500458,0.000000
89.360001,65.154373,-195.805145,-0.001311,0.003527,0.089593,289.821136,14.764193,0.895931,-195.805145,294.500458,0.000000
89.710007,65.075439,-195.849625,-0.001315,0.003527,0.089593,289.470001,14.746305,0.895931,-195.849625,294.500458,0.000000
90.060005,65.031876,-195.894104,-0.001311,0.003527,0.089593,289.276245,14.736434,0.895931,-195.894104,294.500458,0.000000
90.410004,64.981598,-195.849625,-0.001324,0.003527,0.089593,289.052582,14.725040,0.895931,-195.849625,294.500458,0.000000
90.760002,64.927231,-195.938583,-0.001306,0.003527,0.089593,288.810760,14.712721,0.895931,-195.938583,294.500458,0.000000
91.110001,64.856476,-195.938583,-0.001315,0.003527,0.089593,288.496002,14.696687,0.895931,-195.938583,294.500458,0.000000
91.460007,64.789825,-195.938583,-0.001315,0.003528,0.089602,288.199524,14.681584,0.896018,-195.938583,294.500458,0.000000
91.810005,64.744766,-195.938583,-0.001298,0.003528,0.089602,287.999115,14.671373,0.896018,-195.938583,294.500458,0.000000
92.160004,64.690033,-196.072037,-0.001319,0.003528,0.089602,287.755646,14.658971,0.896018,-196.072037,294.500458,0.000000
92.510002,64.643112,-196.027557,-0.001311,0.003528,0.089602,287.546936,14.648339,0.896018,-196.027557,294.500458,0.000000
92.860001,64.595078,-196.027557,-0.001315,0.003528,0.089602,287.333252,14.637454,0.896018,-196.027557,294.500458,0.000000
93.210007,64.531036,-196.027557,-0.001302,0.003528,0.089602,287.048401,14.622942,0.896018,-196.027557,294.500458,0.000000
93.560005,64.488571,-196.027557,-0.001302,0.003528,0.089602,286.859497,14.613319,0.896018,-196.027557,294.500458,0.000000
93.910004,66.310974,-196.116516,-0.001302,0.003537,0.089836,294.965942,15.026281,0.898359,-196.116516,294.500458,0.000000
94.260002,66.210434,-196.160995,-0.001311,0.003537,0.089836,294.518707,15.003499,0.898359,-196.160995,294.500458,0.000000
94.610008,66.151962,-196.116516,-0.001293,0.003537,0.089827,294.258636,14.990250,0.898272,-196.116516,294.500458,0.000000
94.960007,66.092010,-196.116516,-0.001298,0.003537,0.089827,293.991943,14.976664,0.898272,-196.116516,294.500458,0.000000
95.310005,66.022385,-196.160995,-0.001306,0.003537,0.089827,293.682220,14.960886,0.898272,-196.160995,294.500458,0.000000
95.660004,65.970627,-196.205475,-0.001306,0.003537,0.089827,293.451996,14.949158,0.898272,-196.205475,294.500458,0.000000
96.010002,65.902100,-196.205475,-0.001293,0.003537,0.089827,293.147186,14.933629,0.898272,-196.205475,294.500458,0.000000
96.360008,65.849594,-196.205475,-0.001306,0.003537,0.089827,292.913635,14.921731,0.898272,-196.205475,294.500458,0.000000
96.710007,65.834335,-196.205475,-0.001293,0.003537,0.089827,292.845764,14.918274,0.898272,-196.205475,294.500458,0.000000
97.060005,65.770660,-196.294434,-0.001298,0.003537,0.089827,292.562500,14.903845,0.898272,-196.294434,294.500458,0.000000
97.410004,65.737885,-196.294434,-0.001289,0.003537,0.089827,292.416718,14.896418,0.898272,-196.294434,294.500458,0.000000
97.760002,65.650757,-196.294434,-0.001298,0.003537,0.089827,292.029144,14.876674,0.898272,-196.294434,294.500458,0.000000
98.110008,65.581863,-196.338913,-0.001285,0.003537,0.089827,291.722687,14.861063,0.898272,-196.338913,294.500458,0.000000
98.460007,65.558029,-196.383392,-0.001298,0.003537,0.089827,291.616669,14.855662,0.898272,-196.383392,294.500458,0.000000
98.810005,65.537918,-196.427887,-0.001298,0.003537,0.089836,291.527222,14.851105,0.898359,-196.427887,294.500458,0.000000
99.160004,65.482071,-196.427887,-0.001298,0.003537,0.089836,291.278809,14.838449,0.898359,-196.427887,294.500458,0.000000
99.510002,65.398285,-196.383392,-0.001302,0.003537,0.089836,290.906097,14.819464,0.898359,-196.383392,294.500458,0.000000
99.860008,65.366257,-196.427887,-0.001298,0.003537,0.089836,290.763641,14.812205,0.898359,-196.427887,294.500458,0.000000
100.210007,65.306305,-196.472366,-0.001306,0.003537,0.089836,290.496948,14.798620,0.898359,-196.472366,294.500458,0.000000
100.560005,65.282104,-196.427887,-0.001298,0.003537,0.089836,290.389313,14.793136,0.898359,-196.427887,294.500458,0.000000
100.910004,65.241150,-196.472366,-0.001298,0.003537,0.089836,290.207123,14.783856,0.898359,-196.472366,294.500458,0.000000
101.260002,65.193481,-196.516846,-0.001289,0.003537,0.089836,289.995087,14.773054,0.898359,-196.516846,294.500458,0.000000
101.610008,65.146561,-196.561325,-0.001298,0.003537,0.089836,289.786377,14.762422,0.898359,-196.561325,294.500458,0.000000
101.960007,65.093307,-196.561325,-0.001289,0.003538,0.089862,289.549500,14.750354,0.898619,-196.561325,294.500458,0.000000
102.310005,65.042664,-196.605804,-0.001281,0.003538,0.089862,289.324219,14.738878,0.898619,-196.605804,294.500458,0.000000
102.660004,65.023300,-196.605804,-0.001285,0.003538,0.089862,289.238098,14.734490,0.898619,-196.605804,294.500458,0.000000
103.010002,64.980484,-196.605804,-0.001289,0.003538,0.089871,289.047638,14.724789,0.898706,-196.605804,294.500458,0.000000
103.360008,65.115646,-196.650284,-0.001289,0.003546,0.090070,289.648865,14.755416,0.900701,-196.650284,294.500458,0.000000
103.710007,65.164810,-196.650284,-0.001302,0.003546,0.090070,289.867554,14.766557,0.900701,-196.650284,294.500458,0.000000
104.060005,65.122360,-196.694763,-0.001281,0.003546,0.090070,289.678711,14.756938,0.900701,-196.694763,294.500458,0.000000
104.410004,65.106720,-196.694763,-0.001293,0.003546,0.090070,289.609161,14.753393,0.900701,-196.694763,294.500458,0.000000
104.760002,65.072083,-196.739243,-0.001289,0.003546,0.090070,289.455078,14.745544,0.900701,-196.739243,294.500458,0.000000
105.110008,65.047516,-196.783722,-0.001293,0.003546,0.090070,289.345795,14.739977,0.900701,-196.783722,294.500458,0.000000
105.460007,65.040070,-196.739243,-0.001289,0.003546,0.090070,289.312683,14.738291,0.900701,-196.739243,294.500458,0.000000
105.810005,65.001343,-196.828201,-0.001285,0.003546,0.090070,289.140411,14.729514,0.900701,-196.828201,294.500458,0.000000
106.160004,64.976013,-196.783722,-0.001285,0.003546,0.090070,289.027740,14.723775,0.900701,-196.783722,294.500458,0.000000
106.510002,64.964478,-196.828201,-0.001285,0.003546,0.090070,288.976440,14.721162,0.900701,-196.828201,294.500458,0.000000
106.860008,64.930588,-196.828201,-0.001281,0.003546,0.090070,288.825684,14.713481,0.900701,-196.828201,294.500458,0.000000
107.210007,64.901917,-196.828201,-0.001285,0.003546,0.090070,288.698151,14.706985,0.900701,-196.828201,294.500458,0.000000
107.560005,64.856110,-196.917175,-0.001285,0.003546,0.090079,288.494385,14.696605,0.900787,-196.917175,294.500458,0.000000
107.910004,64.856857,-196.872696,-0.001289,0.003547,0.090105,288.497711,14.696774,0.901048,-196.872696,294.500458,0.000000
108.260002,64.849777,-196.917175,-0.001289,0.003547,0.090105,288.466217,14.695169,0.901048,-196.917175,294.500458,0.000000
108.610008,64.824081,-196.961655,-0.001285,0.003547,0.090105,288.351929,14.689347,0.901048,-196.961655,294.500458,0.000000
108.960007,64.796906,-196.961655,-0.001289,0.003547,0.090105,288.231018,14.683188,0.901048,-196.961655,294.500458,0.000000
109.310005,64.779770,-196.961655,-0.001289,0.003547,0.090105,288.154816,14.679305,0.901048,-196.961655,294.500458,0.000000
109.660004,64.756317,-197.006134,-0.001293,0.003547,0.090105,288.050476,14.673991,0.901048,-197.006134,294.500458,0.000000
110.010002,65.710327,-197.006134,-0.001289,0.003560,0.090417,292.294128,14.890173,0.904170,-197.006134,294.500458,0.000000
110.360008,65.771027,-197.006134,-0.001281,0.003560,0.090417,292.564148,14.903927,0.904170,-197.006134,294.500458,0.000000
110.710007,65.782578,-197.095093,-0.001285,0.003560,0.090417,292.615509,14.906546,0.904170,-197.095093,294.500458,0.000000
111.060005,65.796722,-197.095093,-0.001281,0.003560,0.090417,292.678436,14.909750,0.904170,-197.095093,294.500458,0.000000
111.410004,65.802307,-197.139572,-0.001293,0.003560,0.090417,292.703278,14.911016,0.904170,-197.139572,294.500458,0.000000
111.760002,65.801193,-197.139572,-0.001298,0.003560,0.090417,292.698334,14.910763,0.904170,-197.139572,294.500458,0.000000
112.110008,65.753159,-197.228531,-0.001281,0.003560,0.090417,292.484650,14.899879,0.904170,-197.228531,294.500458,0.000000
112.460007,65.764694,-197.184052,-0.001281,0.003560,0.090417,292.535980,14.902493,0.904170,-197.184052,294.500458,0.000000
112.810005,65.766190,-197.184052,-0.001276,0.003560,0.090417,292.542633,14.902831,0.904170,-197.184052,294.500458,0.000000
113.160004,65.674957,-197.184052,-0.001285,0.003560,0.090417,292.136810,14.882158,0.904170,-197.184052,294.500458,0.000000
113.510002,65.659683,-197.317505,-0.001281,0.003560,0.090417,292.068848,14.878696,0.904170,-197.317505,294.500458,0.000000
113.860008,65.621338,-197.273026,-0.001276,0.003560,0.090417,291.898285,14.870008,0.904170,-197.273026,294.500458,0.000000
114.210007,65.585587,-197.273026,-0.001281,0.003560,0.090417,291.739258,14.861906,0.904170,-197.273026,294.500458,0.000000
114.560005,65.573303,-197.317505,-0.001285,0.003560,0.090417,291.684631,14.859122,0.904170,-197.317505,294.500458,0.000000
114.910004,65.571060,-197.317505,-0.001302,0.003560,0.090417,291.674652,14.858614,0.904170,-197.317505,294.500458,0.000000
115.260002,65.550964,-197.317505,-0.001276,0.003560,0.090417,291.585266,14.854061,0.904170,-197.317505,294.500458,0.000000
115.610008,65.533829,-197.361984,-0.001281,0.003560,0.090417,291.509033,14.850178,0.904170,-197.361984,294.500458,0.000000
115.960007,65.510742,-197.361984,-0.001276,0.003560,0.090417,291.406342,14.844947,0.904170,-197.361984,294.500458,0.000000
116.310005,65.471649,-197.406464,-0.001289,0.003560,0.090417,291.232452,14.836088,0.904170,-197.406464,294.500458,0.000000
116.660004,65.453400,-197.495422,-0.001285,0.003560,0.090417,291.151276,14.831953,0.904170,-197.495422,294.500458,0.000000
117.010002,65.400894,-197.495422,-0.001272,0.003560,0.090417,290.917694,14.820054,0.904170,-197.495422,294.500458,0.000000
117.360008,65.381149,-197.495422,-0.001289,0.003560,0.090417,290.829865,14.815579,0.904170,-197.495422,294.500458,0.000000
117.710007,65.352478,-197.539902,-0.001276,0.003560,0.090417,290.702332,14.809083,0.904170,-197.539902,294.500458,0.000000
118.060005,65.334976,-197.584381,-0.001268,0.003560,0.090417,290.624481,14.805117,0.904170,-197.584381,294.500458,0.000000
118.410004,65.312271,-197.584381,-0.001281,0.003560,0.090417,290.523499,14.799972,0.904170,-197.584381,294.500458,0.000000
118.760002,65.300354,-197.628860,-0.001285,0.003560,0.090417,290.470490,14.797272,0.904170,-197.628860,294.500458,0.000000
119.110008,65.280991,-197.628860,-0.001293,0.003560,0.090417,290.384338,14.792884,0.904170,-197.628860,294.500458,0.000000
119.460007,65.270187,-197.628860,-0.001285,0.003560,0.090417,290.336304,14.790436,0.904170,-197.628860,294.500458,0.000000
119.810005,65.248215,-197.717834,-0.001293,0.003560,0.090417,290.238556,14.785457,0.904170,-197.717834,294.500458,0.000000
120.160004,65.219925,-197.717834,-0.001289,0.003560,0.090426,290.112701,14.779046,0.904256,-197.717834,294.500458,0.000000
120.510002,65.194595,-197.762314,-0.001285,0.003560,0.090426,290.000031,14.773306,0.904256,-197.762314,294.500458,0.000000
120.860008,65.165176,-197.806793,-0.001281,0.003560,0.090426,289.869171,14.766640,0.904256,-197.806793,294.500458,0.000000
121.210007,65.136139,-197.806793,-0.001289,0.003560,0.090434,289.740021,14.760059,0.904343,-197.806793,294.500458,0.000000
121.560005,65.116394,-197.806793,-0.001281,0.003560,0.090434,289.652191,14.755586,0.904343,-197.806793,294.500458,0.000000
121.910004,65.101883,-197.762314,-0.001276,0.003560,0.090434,289.587646,14.752297,0.904343,-197.762314,294.500458,0.000000
122.260002,65.071335,-197.895752,-0.001293,0.003560,0.090434,289.451752,14.745376,0.904343,-197.895752,294.500458,0.000000
122.610008,65.060165,-197.851273,-0.001281,0.003560,0.090434,289.402069,14.742845,0.904343,-197.851273,294.500458,0.000000
122.960007,65.040802,-197.895752,-0.001281,0.003560,0.090434,289.315948,14.738456,0.904343,-197.895752,294.500458,0.000000
123.310005,65.020325,-197.940231,-0.001276,0.003560,0.090434,289.224854,14.733816,0.904343,-197.940231,294.500458,0.000000
123.660004,65.013626,-197.940231,-0.001293,0.003555,0.090304,289.195038,14.732298,0.903042,-197.940231,0.090434,0.000000
124.010002,64.938782,-197.984711,-0.001276,0.003547,0.090087,288.862122,14.715339,0.900874,-197.984711,0.089888,0.000000
124.360008,64.908249,-197.940231,-0.001281,0.003534,0.089758,288.726318,14.708420,0.897579,-197.940231,0.089307,0.000000
124.710007,64.802490,-198.029190,-0.001276,0.003511,0.089177,288.255859,14.684454,0.891768,-198.029190,0.088717,0.000000
125.060005,64.770096,-197.984711,-0.001272,0.003488,0.088604,288.111786,14.677114,0.886045,-197.984711,0.088136,0.000000
125.410004,64.740677,-197.984711,-0.001272,0.003469,0.088101,287.980927,14.670446,0.881015,-197.984711,0.087555,0.000000
125.760010,64.742905,-198.073669,-0.001268,0.003448,0.087581,287.990814,14.670952,0.875811,-198.073669,0.086974,0.000000
126.110008,64.674393,-198.073669,-0.001268,0.003423,0.086939,287.686066,14.655427,0.869394,-198.073669,0.086384,0.000000
126.460007,64.677750,-198.073669,-0.001276,0.003404,0.086471,287.700989,14.656187,0.864711,-198.073669,0.085803,0.000000
126.810005,64.591354,-198.118149,-0.001276,0.003375,0.085717,287.316681,14.636610,0.857166,-198.118149,0.085222,0.000000
127.160004,64.559326,-198.118149,-0.001276,0.003355,0.085214,287.174225,14.629353,0.852136,-198.118149,0.084633,0.000000
127.510010,64.319153,-198.162643,-0.001272,0.003333,0.084659,286.105896,14.574928,0.846586,-198.162643,0.084052,0.000000
127.860008,63.661911,-198.162643,-0.001268,0.003314,0.084164,283.182312,14.425995,0.841643,-198.162643,0.083470,0.000000
128.210007,62.943604,-198.162643,-0.001259,0.003292,0.083609,279.987122,14.263225,0.836092,-198.162643,0.082889,0.000000
128.560013,62.338875,-198.207123,-0.001255,0.003275,0.083193,277.297150,14.126191,0.831930,-198.207123,0.082300,0.000000
128.910004,60.688148,-198.251602,-0.001259,0.003246,0.082447,269.954376,13.752131,0.824471,-198.251602,0.081719,0.000000
129.260010,59.530441,-198.251602,-0.001250,0.003229,0.082022,264.804626,13.489791,0.820222,-198.251602,0.081138,0.000000
129.610001,57.716988,-198.296082,-0.001246,0.003206,0.081432,256.737976,13.078856,0.814325,-198.296082,0.080557,0.000000
129.960007,56.362297,-198.296082,-0.001250,0.003190,0.081034,250.712021,12.771879,0.810336,-198.296082,0.079967,0.000000
130.310013,54.453514,-198.296082,-0.001255,0.003169,0.080487,242.221329,12.339343,0.804872,-198.296082,0.079386,0.000000
130.660004,52.872047,-198.385040,-0.001242,0.003153,0.080088,235.186615,11.980977,0.800883,-198.385040,0.078805,0.000000
131.010010,49.398926,-198.385040,-0.001246,0.003116,0.079143,219.737396,11.193956,0.791430,-198.385040,0.078224,0.000000
131.360001,47.465202,-198.385040,-0.001242,0.003099,0.078709,211.135757,10.755769,0.787094,-198.385040,0.077634,0.000000
131.710007,44.979614,-198.429520,-0.001246,0.003071,0.077998,200.079315,10.192526,0.779983,-198.429520,0.077053,0.000000
132.060013,42.470940,-198.429520,-0.001255,0.003053,0.077539,188.920181,9.624052,0.775387,-198.429520,0.076472,0.000000
132.410004,40.277290,-198.385040,-0.001242,0.003033,0.077036,179.162338,9.126965,0.770357,-198.385040,0.075882,0.000000
132.760010,36.926315,-198.473999,-0.001237,0.002999,0.076186,164.256454,8.367622,0.761858,-198.473999,0.075301,0.000000
133.110001,34.358063,-198.473999,-0.001250,0.002977,0.075622,152.832291,7.785648,0.756221,-198.473999,0.074720,0.000000
133.460007,31.935776,-198.518478,-0.001250,0.002953,0.075006,142.057419,7.236750,0.750064,-198.518478,0.074139,0.000000
133.810013,30.603798,-198.518478,-0.001237,0.002944,0.074781,136.132492,6.934920,0.747809,-198.518478,0.073549,0.000000
134.160004,27.596146,-198.518478,-0.001255,0.002915,0.074044,122.753784,6.253376,0.740437,-198.518478,0.072968,0.000000
134.510010,25.667259,-198.562973,-0.001242,0.002898,0.073610,114.173668,5.816284,0.736101,-198.562973,0.072387,0.000000
134.860001,22.028809,-198.562973,-0.001233,0.002862,0.072691,97.989037,4.991799,0.726909,-198.562973,0.071806,0.000000
135.210007,19.882080,-198.651932,-0.001250,0.002843,0.072223,88.439911,4.505344,0.722226,-198.651932,0.071217,0.000000
135.560013,17.237862,-198.651932,-0.001242,0.002820,0.071615,76.677841,3.906155,0.716155,-198.651932,0.070636,0.000000
135.910004,16.815224,-198.651932,-0.001237,0.002817,0.071555,74.797852,3.810384,0.715548,-198.651932,0.070054,0.000000
136.260010,12.362022,-198.651932,-0.001237,0.002776,0.070523,54.989021,2.801275,0.705228,-198.651932,0.069473,0.000000
136.610001,9.385277,-198.651932,-0.001255,0.002747,0.069777,41.747795,2.126734,0.697770,-198.651932,0.068884,0.000000
136.960007,6.924637,-198.651932,-0.001246,0.002724,0.069187,30.802322,1.569145,0.691873,-198.651932,0.068303,0.000000
137.310013,4.872490,-198.696411,-0.001237,0.002705,0.068710,21.673918,1.104122,0.687103,-198.696411,0.067722,0.000000
137.660004,2.442017,-198.696411,-0.001242,0.002681,0.068103,10.862633,0.553369,0.681032,-198.696411,0.067132,0.000000
138.010010,-0.015640,-198.785370,-0.001233,0.002657,0.067479,-0.069571,-0.003544,0.674788,-198.785370,0.066551,0.000000
138.360001,-1.833935,-198.829849,-0.001246,0.002636,0.066959,-8.157749,-0.415576,0.669585,-198.829849,0.065970,0.000000
138.710007,-4.321011,-198.785370,-0.001246,0.002612,0.066334,-19.220816,-0.979155,0.663341,-198.785370,0.065389,0.000000
139.060013,-0.272949,-198.829849,-0.001272,0.002590,0.065796,-1.214139,-0.061851,0.657964,-198.829849,0.064799,0.000000
139.410004,-0.097939,-198.918808,-0.001285,0.002564,0.065137,-0.435652,-0.022193,0.651373,-198.918808,0.064218,0.000000
139.760010,-0.072243,-198.874329,-0.001293,0.002545,0.064634,-0.321352,-0.016370,0.646343,-198.874329,0.063637,0.000000
140.110001,-0.116180,-198.918808,-0.001324,0.002521,0.064027,-0.516796,-0.026327,0.640273,-198.918808,0.063056,0.000000
140.460007,-0.093468,-198.918808,-0.001358,0.002496,0.063394,-0.415765,-0.021180,0.633942,-198.918808,0.062466,0.000000
140.810013,-0.087509,-198.918808,-0.001380,0.002472,0.062787,-0.389260,-0.019830,0.627871,-198.918808,0.061885,0.000000
141.160004,-0.085648,-198.963287,-0.001397,0.002450,0.062232,-0.380979,-0.019408,0.622321,-198.963287,0.061304,0.000000
141.510010,-0.061440,-199.007782,-0.001423,0.002431,0.061738,-0.273297,-0.013922,0.617378,-199.007782,0.060714,0.000000
141.860001,-0.074478,-199.052261,-0.001457,0.002408,0.061157,-0.331295,-0.016877,0.611568,-199.052261,0.060133,0.000000
142.210007,-0.078201,-199.007782,-0.001475,0.002393,0.060784,-0.347857,-0.017721,0.607839,-199.007782,0.059552,0.000000
142.560013,-0.092354,-199.141220,-0.001509,0.002357,0.059873,-0.410810,-0.020928,0.598733,-199.141220,0.058971,0.000000
142.910004,-0.087883,-199.096741,-0.001518,0.002336,0.059336,-0.390923,-0.019915,0.593356,-199.096741,0.058382,0.000000
143.260010,-0.084900,-199.096741,-0.001544,0.002312,0.058737,-0.377654,-0.019239,0.587372,-199.096741,0.057801,0.000000
143.610001,-0.068520,-199.096741,-0.001569,0.002290,0.058165,-0.304790,-0.015527,0.581648,-199.096741,0.057220,0.000000
143.960007,-0.097191,-199.096741,-0.001595,0.002272,0.057697,-0.432327,-0.022024,0.576965,-199.096741,0.056639,0.000000
144.200012,-0.070381,-199.230179,-0.001591,0.002266,0.057558,-0.313071,-0.015949,0.575578,-199.230179,0.057454,0.000000