File: Data/compression 20/AutoNoHeating-17-20-reverse-1-3_09112024_165529.csv
Time (sec),S:Load (lbs),S:HL1 (DIM),S:LVDT (in),S:Position (in),Ch:Position (mm),Ch:Load (N),Ch:Stress (MPa),Ch:Strain (mm/mm),Ch:HL1 (DIM),Set Point (),Cycles ()
0.110000,-0.061073,-137.846466,-0.010421,-0.005809,-0.147550,-0.271668,-0.013839,-1.475498,-137.846466,-0.147732,0.000000
0.510000,-0.093094,-137.979904,-0.010438,-0.005731,-0.145572,-0.414102,-0.021095,-1.455725,-137.979904,-0.144731,0.000000
0.910000,-0.045433,-137.979904,-0.010369,-0.005486,-0.139346,-0.202096,-0.010295,-1.393458,-137.979904,-0.138071,0.000000
1.310000,-0.028305,-137.979904,-0.010093,-0.005221,-0.132625,-0.125907,-0.006414,-1.326248,-137.979904,-0.131411,0.000000
1.710000,-0.004845,-138.068878,-0.009839,-0.004966,-0.126129,-0.021550,-0.001098,-1.261293,-138.068878,-0.124750,0.000000
2.110000,-0.033890,-138.113358,-0.009554,-0.004701,-0.119408,-0.150749,-0.007680,-1.194083,-138.113358,-0.118073,0.000000
2.510000,-0.059578,-138.113358,-0.009287,-0.004430,-0.112523,-0.265016,-0.013501,-1.125225,-138.113358,-0.111412,0.000000
2.910000,-0.085648,-138.113358,-0.009024,-0.004174,-0.106010,-0.380979,-0.019408,-1.060097,-138.113358,-0.104752,0.000000
3.310000,-0.048409,-138.157837,-0.008744,-0.003911,-0.099341,-0.215332,-0.010970,-0.993407,-138.157837,-0.098092,0.000000
3.710000,-0.065536,-138.246796,-0.008485,-0.003651,-0.092724,-0.291521,-0.014851,-0.927238,-138.246796,-0.091432,0.000000
4.110000,-0.029419,-138.246796,-0.008201,-0.003388,-0.086046,-0.130862,-0.006666,-0.860461,-138.246796,-0.084754,0.000000
4.510000,-0.064796,-138.246796,-0.007933,-0.003126,-0.079395,-0.288229,-0.014683,-0.793945,-138.246796,-0.078094,0.000000
4.910000,-0.081924,-138.291275,-0.007670,-0.002862,-0.072700,-0.364418,-0.018564,-0.726995,-138.291275,-0.071433,0.000000
5.310000,-0.038727,-138.335754,-0.007394,-0.002596,-0.065944,-0.172265,-0.008776,-0.659438,-138.335754,-0.064773,0.000000
5.710000,-0.036491,-138.335754,-0.007136,-0.002340,-0.059448,-0.162322,-0.008269,-0.594483,-138.335754,-0.058095,0.000000
6.110000,-0.031654,-138.380234,-0.006855,-0.002077,-0.052753,-0.140806,-0.007173,-0.527533,-138.380234,-0.051435,0.000000
6.510000,-0.041710,-138.380234,-0.006575,-0.001816,-0.046119,-0.185535,-0.009452,-0.461191,-138.380234,-0.044775,0.000000
6.910000,-0.037239,-138.380234,-0.006308,-0.001550,-0.039372,-0.165648,-0.008438,-0.393720,-138.380234,-0.038115,0.000000
7.310000,-0.036125,-138.513687,-0.006049,-0.001290,-0.032755,-0.160693,-0.008186,-0.327551,-138.513687,-0.031454,0.000000
7.710001,-0.023460,-138.513687,-0.005777,-0.001026,-0.026060,-0.104357,-0.005316,-0.260601,-138.513687,-0.024777,0.000000
8.110001,0.007072,-138.513687,-0.005510,-0.000767,-0.019487,0.031460,0.001603,-0.194866,-138.513687,-0.018116,0.000000
8.510000,-0.019363,-138.513687,-0.005247,-0.000503,-0.012766,-0.086133,-0.004388,-0.127656,-138.513687,-0.011456,0.000000
8.910001,-0.036865,-138.602646,-0.004967,-0.000232,-0.005897,-0.163985,-0.008354,-0.058971,-138.602646,-0.004796,0.000000
9.310000,-0.062935,-138.602646,-0.004708,0.000025,0.000633,-0.279948,-0.014261,0.006331,-138.602646,0.001865,0.000000
9.710000,0.139267,-138.647125,-0.004462,-0.000000,-0.000000,0.619490,0.031558,-0.000000,-138.647125,0.000130,0.000000
10.110001,0.112457,-138.602646,-0.004445,-0.000000,-0.000009,0.500235,0.025483,-0.000087,-138.602646,0.000130,0.000000
10.510000,0.138145,-138.736084,-0.004449,-0.000000,-0.000009,0.614502,0.031304,-0.000087,-138.736084,0.000642,0.000000
10.910001,0.121017,-138.691605,-0.004467,-0.000000,-0.000000,0.538313,0.027423,-0.000000,-138.691605,0.001310,0.000000
11.310000,0.282257,-138.691605,-0.004428,0.000040,0.001006,1.255542,0.063960,0.010060,-138.691605,0.001977,0.000000
11.710001,0.455040,-138.736084,-0.004411,0.000067,0.001708,2.024119,0.103114,0.017084,-138.736084,0.002645,0.000000
12.110001,0.595795,-138.736084,-0.004372,0.000084,0.002133,2.650227,0.135009,0.021334,-138.736084,0.003313,0.000000
12.510000,0.881401,-138.825043,-0.004368,0.000114,0.002888,3.920668,0.199728,0.028879,-138.825043,0.003981,0.000000
12.910001,1.209839,-138.825043,-0.004346,0.000142,0.003616,5.381632,0.274153,0.036163,-138.825043,0.004648,0.000000
13.310000,1.543480,-138.914017,-0.004320,0.000167,0.004232,6.865742,0.349758,0.042321,-138.914017,0.005307,0.000000
13.710001,1.904312,-138.914017,-0.004294,0.000190,0.004830,8.470803,0.431523,0.048304,-138.914017,0.005975,0.000000
14.110001,2.328819,-138.914017,-0.004260,0.000220,0.005585,10.359105,0.527718,0.055849,-138.914017,0.006643,0.000000
14.510000,2.843803,-138.914017,-0.004230,0.000249,0.006322,12.649869,0.644415,0.063221,-138.914017,0.007311,0.000000
14.910001,3.088829,-139.002975,-0.004212,0.000270,0.006851,13.739798,0.699939,0.068511,-139.002975,0.007978,0.000000
15.310000,3.643661,-139.047455,-0.004191,0.000296,0.007510,16.207815,0.825665,0.075102,-139.047455,0.008646,0.000000
15.710001,4.110992,-139.047455,-0.004178,0.000325,0.008247,18.286608,0.931564,0.082473,-139.047455,0.009314,0.000000
16.110001,4.518738,-139.047455,-0.004165,0.000350,0.008880,20.100349,1.023961,0.088804,-139.047455,0.009982,0.000000
16.510000,4.972664,-139.136414,-0.004135,0.000375,0.009531,22.119514,1.126822,0.095308,-139.136414,0.010641,0.000000
16.910002,5.376686,-139.136414,-0.004105,0.000398,0.010121,23.916695,1.218374,0.101205,-139.136414,0.011309,0.000000
17.310001,5.814224,-139.180893,-0.004083,0.000429,0.010892,25.862961,1.317522,0.108924,-139.180893,0.011976,0.000000
17.710001,6.317299,-139.180893,-0.004053,0.000458,0.011629,28.100748,1.431520,0.116295,-139.180893,0.012644,0.000000
18.110001,6.617805,-139.225372,-0.004044,0.000482,0.012237,29.437469,1.499616,0.122366,-139.225372,0.013312,0.000000
18.510000,6.802124,-139.225372,-0.004018,0.000501,0.012731,30.257359,1.541383,0.127309,-139.225372,0.013980,0.000000
18.910002,7.325684,-139.314346,-0.004001,0.000535,0.013589,32.586269,1.660024,0.135894,-139.314346,0.014647,0.000000
19.310001,7.543144,-139.358826,-0.003988,0.000557,0.014136,33.553581,1.709301,0.141358,-139.358826,0.015315,0.000000
19.710001,8.068192,-139.358826,-0.003936,0.000591,0.015012,35.889107,1.828278,0.150117,-139.358826,0.015983,0.000000
20.110001,8.161659,-139.403305,-0.003923,0.000614,0.015593,36.304874,1.849458,0.155927,-139.403305,0.016642,0.000000
20.510000,8.433861,-139.403305,-0.003885,0.000641,0.016286,37.515686,1.911140,0.162865,-139.403305,0.017310,0.000000
20.910002,8.622658,-139.447784,-0.003850,0.000667,0.016937,38.355499,1.953922,0.169369,-139.447784,0.017978,0.000000
21.310001,8.716866,-139.447784,-0.003850,0.000688,0.017475,38.774555,1.975270,0.174746,-139.447784,0.018645,0.000000
21.710001,8.957047,-139.447784,-0.003820,0.000714,0.018134,39.842934,2.029696,0.181337,-139.447784,0.019313,0.000000
22.110001,9.351387,-139.492264,-0.003790,0.000744,0.018888,41.597046,2.119055,0.188882,-139.492264,0.019981,0.000000
22.510000,9.583000,-139.581223,-0.003760,0.000772,0.019599,42.627316,2.171539,0.195993,-139.581223,0.020649,0.000000
22.910002,9.737167,-139.536743,-0.003734,0.000800,0.020319,43.313084,2.206474,0.203191,-139.536743,0.021316,0.000000
23.310001,9.703278,-139.581223,-0.003725,0.000820,0.020831,43.162334,2.198794,0.208308,-139.581223,0.021975,0.000000
23.710001,10.030220,-139.625702,-0.003691,0.000850,0.021594,44.616646,2.272880,0.215939,-139.625702,0.022643,0.000000
24.110001,10.118477,-139.581223,-0.003678,0.000875,0.022227,45.009232,2.292880,0.222270,-139.581223,0.023311,0.000000
24.510000,10.554893,-139.714661,-0.003630,0.000908,0.023060,46.950512,2.391773,0.230595,-139.714661,0.023979,0.000000
24.910002,10.461800,-139.714661,-0.003617,0.000930,0.023632,46.536407,2.370678,0.236319,-139.714661,0.024647,0.000000
25.310001,10.693047,-139.759155,-0.003609,0.000956,0.024274,47.565048,2.423079,0.242736,-139.759155,0.025314,0.000000
25.710001,10.885559,-139.759155,-0.003574,0.000980,0.024889,48.421387,2.466703,0.248894,-139.759155,0.025982,0.000000
26.110001,10.887421,-139.803635,-0.003527,0.000999,0.025375,48.429665,2.467125,0.253750,-139.803635,0.026650,0.000000
26.510002,11.465347,-139.848114,-0.003514,0.001040,0.026424,51.000412,2.598085,0.264244,-139.848114,0.027309,0.000000
26.910002,11.413216,-139.803635,-0.003479,0.001065,0.027040,50.768520,2.586272,0.270401,-139.803635,0.027977,0.000000
27.310001,11.580040,-139.892593,-0.003458,0.001088,0.027630,51.510590,2.624074,0.276298,-139.892593,0.028644,0.000000
27.710001,11.734573,-139.937073,-0.003445,0.001115,0.028315,52.197990,2.659092,0.283149,-139.937073,0.029312,0.000000
28.110001,11.849266,-139.848114,-0.003415,0.001135,0.028835,52.708168,2.685082,0.288353,-139.848114,0.029980,0.000000
28.510002,12.114761,-139.892593,-0.003393,0.001161,0.029494,53.889149,2.745244,0.294943,-139.892593,0.030648,0.000000
28.910002,12.305420,-139.937073,-0.003359,0.001190,0.030231,54.737240,2.788448,0.302315,-139.937073,0.031316,0.000000
29.310001,12.642044,-140.026031,-0.003341,0.001219,0.030951,56.234619,2.864728,0.309513,-140.026031,0.031983,0.000000
29.710001,12.805511,-140.070511,-0.003320,0.001244,0.031602,56.961761,2.901770,0.316017,-140.070511,0.032642,0.000000
30.110001,13.165970,-140.070511,-0.003285,0.001274,0.032348,58.565159,2.983451,0.323475,-140.070511,0.033310,0.000000
30.510002,13.392372,-140.070511,-0.003268,0.001305,0.033154,59.572247,3.034755,0.331540,-140.070511,0.033978,0.000000
30.910002,13.158897,-140.070511,-0.003247,0.001325,0.033666,58.533699,2.981849,0.336657,-140.070511,0.034646,0.000000
31.310001,13.541321,-140.114990,-0.003212,0.001353,0.034368,60.234802,3.068507,0.343682,-140.114990,0.035313,0.000000
31.710001,13.625481,-140.114990,-0.003191,0.001375,0.034923,60.609165,3.087578,0.349232,-140.114990,0.035981,0.000000
32.110001,13.965080,-140.159470,-0.003165,0.001400,0.035565,62.119778,3.164532,0.355649,-140.159470,0.036649,0.000000
32.510002,14.235794,-140.159470,-0.003143,0.001430,0.036328,63.323975,3.225877,0.363281,-140.159470,0.037317,0.000000
32.910000,14.392937,-140.248444,-0.003113,0.001455,0.036961,64.022980,3.261486,0.369612,-140.248444,0.037984,0.000000
33.310001,14.621948,-140.248444,-0.003087,0.001482,0.037646,65.041672,3.313381,0.376463,-140.248444,0.038644,0.000000
33.710003,14.746323,-140.292923,-0.003061,0.001506,0.038262,65.594917,3.341565,0.382620,-140.292923,0.039311,0.000000
34.110001,15.185722,-140.337402,-0.003053,0.001535,0.038990,67.549469,3.441134,0.389905,-140.337402,0.039979,0.000000
34.510002,14.868462,-140.381882,-0.003009,0.001551,0.039389,66.138222,3.369241,0.393894,-140.381882,0.040647,0.000000
34.910000,15.369675,-140.337402,-0.002988,0.001582,0.040187,68.367729,3.482818,0.401872,-140.337402,0.041315,0.000000
35.310001,15.462021,-140.381882,-0.002979,0.001604,0.040742,68.778503,3.503744,0.407423,-140.381882,0.041982,0.000000
35.710003,15.979614,-140.381882,-0.002936,0.001636,0.041549,71.080872,3.621032,0.415488,-140.381882,0.042650,0.000000
36.110001,16.112930,-140.381882,-0.002906,0.001663,0.042234,71.673897,3.651242,0.422339,-140.381882,0.043318,0.000000
36.510002,15.685074,-140.470840,-0.002889,0.001674,0.042511,69.770691,3.554289,0.425114,-140.470840,0.043977,0.000000
36.910000,16.640205,-140.470840,-0.002863,0.001714,0.043543,74.019333,3.770724,0.435434,-140.470840,0.044645,0.000000
37.310001,16.927681,-140.559799,-0.002837,0.001743,0.044281,75.298088,3.835867,0.442805,-140.559799,0.045313,0.000000
37.710003,17.066948,-140.559799,-0.002820,0.001765,0.044836,75.917580,3.867426,0.448356,-140.559799,0.045980,0.000000
38.110001,17.513046,-140.559799,-0.002815,0.001794,0.045555,77.901924,3.968513,0.455554,-140.559799,0.046648,0.000000
38.510002,17.791580,-140.648773,-0.002777,0.001820,0.046223,79.140900,4.031630,0.462231,-140.648773,0.047316,0.000000
38.910004,18.110336,-140.648773,-0.002734,0.001849,0.046960,80.558800,4.103861,0.469603,-140.648773,0.047984,0.000000
39.310001,17.743919,-140.648773,-0.002725,0.001864,0.047342,78.928894,4.020830,0.473419,-140.648773,0.048651,0.000000
39.710003,18.408974,-140.737732,-0.002686,0.001897,0.048183,81.887207,4.171533,0.481831,-140.737732,0.049310,0.000000
40.110001,18.960457,-140.737732,-0.002677,0.001923,0.048851,84.340324,4.296501,0.488508,-140.737732,0.049978,0.000000
40.510002,19.079620,-140.737732,-0.002656,0.001949,0.049493,84.870392,4.323503,0.494926,-140.737732,0.050646,0.000000
40.910004,19.892509,-140.826691,-0.002626,0.001982,0.050351,88.486298,4.507707,0.503511,-140.826691,0.051314,0.000000
41.310001,19.904053,-140.826691,-0.002604,0.002007,0.050976,88.537651,4.510323,0.509755,-140.826691,0.051982,0.000000
41.710003,20.114815,-140.826691,-0.002561,0.002031,0.051583,89.475166,4.558082,0.515826,-140.826691,0.052649,0.000000
42.110001,20.701302,-140.871170,-0.002552,0.002059,0.052294,92.083992,4.690982,0.522937,-140.871170,0.053317,0.000000
42.510002,20.573578,-140.871170,-0.002522,0.002080,0.052831,91.515846,4.662039,0.528314,-140.871170,0.053985,0.000000
42.910004,21.036812,-140.915649,-0.002501,0.002106,0.053482,93.576416,4.767010,0.534818,-140.915649,0.054644,0.000000
43.310001,21.578613,-140.915649,-0.002479,0.002134,0.054193,95.986465,4.889784,0.541929,-140.915649,0.055312,0.000000
43.710003,22.082428,-141.004608,-0.002445,0.002161,0.054878,98.227547,5.003950,0.548780,-141.004608,0.055979,0.000000
44.110001,22.343094,-141.049103,-0.002432,0.002188,0.055563,99.387047,5.063017,0.555632,-141.049103,0.056647,0.000000
44.510002,22.472679,-141.049103,-0.002410,0.002212,0.056196,99.963470,5.092382,0.561962,-141.049103,0.057315,0.000000
44.910004,23.398766,-141.049103,-0.002380,0.002242,0.056959,104.082909,5.302236,0.569594,-141.049103,0.057983,0.000000
45.310001,23.797203,-141.093582,-0.002354,0.002268,0.057601,105.855247,5.392523,0.576011,-141.093582,0.058650,0.000000
45.710003,24.712868,-141.138062,-0.002333,0.002298,0.058373,109.928329,5.600016,0.583730,-141.138062,0.059318,0.000000
46.110001,24.680847,-141.182541,-0.002315,0.002323,0.059015,109.785889,5.592760,0.590147,-141.182541,0.059986,0.000000
46.510002,24.719574,-141.182541,-0.002298,0.002342,0.059483,109.958160,5.601536,0.594830,-141.182541,0.060645,0.000000
46.910004,25.704498,-141.227020,-0.002272,0.002375,0.060324,114.339317,5.824723,0.603242,-141.227020,0.061313,0.000000
47.310001,26.059364,-141.271500,-0.002242,0.002395,0.060827,115.917839,5.905137,0.608272,-141.271500,0.061981,0.000000
47.710003,27.398422,-141.271500,-0.002216,0.002430,0.061729,121.874268,6.208571,0.617291,-141.271500,0.062648,0.000000
48.110001,27.585350,-141.271500,-0.002190,0.002456,0.062388,122.705765,6.250929,0.623882,-141.271500,0.063316,0.000000
48.510002,27.694824,-141.315979,-0.002186,0.002476,0.062883,123.192734,6.275737,0.628825,-141.315979,0.063984,0.000000
48.910004,28.227318,-141.315979,-0.002156,0.002500,0.063490,125.561378,6.396402,0.634896,-141.315979,0.064652,0.000000
49.310001,28.855141,-141.360458,-0.002134,0.002526,0.064149,128.354080,6.538669,0.641487,-141.360458,0.065319,0.000000
49.710003,28.979141,-141.360458,-0.002108,0.002544,0.064608,128.905655,6.566767,0.646083,-141.360458,0.065979,0.000000
50.110001,30.833931,-141.493912,-0.002104,0.002583,0.065606,137.156174,6.987069,0.656056,-141.493912,0.066646,0.000000
50.510002,31.306839,-141.449417,-0.002061,0.002607,0.066221,139.259781,7.094231,0.662214,-141.449417,0.067314,0.000000
50.910004,32.015465,-141.493912,-0.002048,0.002634,0.066915,142.411896,7.254808,0.669151,-141.493912,0.067982,0.000000
51.310001,32.666374,-141.493912,-0.002035,0.002660,0.067566,145.307297,7.402306,0.675656,-141.493912,0.068650,0.000000
51.710003,34.289169,-141.538391,-0.002009,0.002695,0.068441,152.525848,7.770037,0.684415,-141.538391,0.069317,0.000000
52.110001,34.578880,-141.538391,-0.001988,0.002718,0.069031,153.814545,7.835686,0.690312,-141.538391,0.069985,0.000000
52.510002,35.208931,-141.627350,-0.001957,0.002744,0.069690,156.617142,7.978458,0.696903,-141.627350,0.070653,0.000000
52.910004,35.420441,-141.582870,-0.001932,0.002762,0.070159,157.557983,8.026387,0.701586,-141.582870,0.071312,0.000000
53.310001,35.901917,-141.671829,-0.001914,0.002785,0.070740,159.699707,8.135490,0.707396,-141.671829,0.071980,0.000000
53.710003,37.229797,-141.627350,-0.001906,0.002817,0.071555,165.606415,8.436393,0.715548,-141.627350,0.072647,0.000000
54.110004,38.717422,-141.716309,-0.001867,0.002847,0.072318,172.223694,8.773493,0.723180,-141.716309,0.073315,0.000000
54.510002,39.733627,-141.716309,-0.001858,0.002875,0.073020,176.744003,9.003769,0.730204,-141.716309,0.073983,0.000000
54.910004,40.052010,-141.760788,-0.001841,0.002893,0.073471,178.160233,9.075915,0.734714,-141.760788,0.074651,0.000000
55.310001,41.237267,-141.849747,-0.001819,0.002922,0.074226,183.432526,9.344498,0.742258,-141.849747,0.075319,0.000000
55.710003,42.119423,-141.805267,-0.001807,0.002945,0.074807,187.356552,9.544397,0.748069,-141.805267,0.075986,0.000000
56.110004,42.946457,-141.849747,-0.001781,0.002969,0.075414,191.035385,9.731806,0.754139,-141.849747,0.076645,0.000000
56.510002,44.230026,-141.938721,-0.001772,0.002997,0.076134,196.744980,10.022667,0.761337,-141.938721,0.077313,0.000000
56.910004,45.594772,-141.894241,-0.001746,0.003027,0.076897,202.815674,10.331923,0.768969,-141.894241,0.077981,0.000000
57.310001,47.111076,-141.894241,-0.001738,0.003057,0.077651,209.560532,10.675522,0.776514,-141.894241,0.078649,0.000000
57.710003,47.609306,-141.938721,-0.001707,0.003075,0.078102,211.776764,10.788424,0.781024,-141.938721,0.079316,0.000000
58.110004,49.083527,-141.983200,-0.001703,0.003108,0.078935,218.334427,11.122486,0.789349,-141.983200,0.079984,0.000000
58.510002,50.440453,-141.983200,-0.001677,0.003134,0.079611,224.370346,11.429970,0.796113,-141.983200,0.080652,0.000000
58.910004,51.112213,-142.072159,-0.001656,0.003155,0.080132,227.358475,11.582193,0.801317,-142.072159,0.081320,0.000000
59.310001,52.895882,-142.027679,-0.001651,0.003182,0.080825,235.292633,11.986378,0.808254,-142.027679,0.081988,0.000000
59.710003,53.425018,-142.116638,-0.001625,0.003207,0.081459,237.646347,12.106282,0.814585,-142.116638,0.082647,0.000000
60.110004,55.676758,-142.116638,-0.001608,0.003238,0.082256,247.662582,12.616534,0.822564,-142.116638,0.083314,0.000000
60.510002,56.474754,-142.161118,-0.001587,0.003257,0.082716,251.212250,12.797362,0.827160,-142.161118,0.083982,0.000000
60.910004,58.067757,-142.205597,-0.001582,0.003288,0.083514,258.298279,13.158342,0.835138,-142.205597,0.084650,0.000000
61.310001,59.483894,-142.205597,-0.001574,0.003312,0.084112,264.597565,13.479243,0.841122,-142.205597,0.085318,0.000000
61.710003,61.134247,-142.205597,-0.001556,0.003341,0.084867,271.938721,13.853218,0.848667,-142.205597,0.085985,0.000000
62.110004,62.569000,-142.339050,-0.001544,0.003366,0.085491,278.320801,14.178338,0.854911,-142.339050,0.086653,0.000000
62.510002,64.517990,-142.294556,-0.001518,0.003397,0.086289,286.990356,14.619986,0.862890,-142.294556,0.087321,0.000000
62.910004,65.305557,-142.383530,-0.001522,0.003417,0.086801,290.493622,14.798450,0.868006,-142.383530,0.087980,0.000000
63.310001,65.768799,-142.383530,-0.001483,0.003427,0.087035,292.554230,14.903423,0.870348,-142.383530,0.015276,0.000000
63.710003,64.613693,-142.383530,-0.001483,0.003427,0.087052,287.416077,14.641672,0.870521,-142.383530,294.500458,0.000000
64.110001,65.765076,-142.428009,-0.001457,0.003408,0.086558,292.537659,14.902579,0.865578,-142.428009,294.500458,0.000000
64.510002,65.050491,-142.472488,-0.001457,0.003448,0.087572,289.359039,14.740652,0.875724,-142.472488,294.500458,0.000000
64.910004,65.628784,-142.561447,-0.001453,0.003461,0.087919,291.931427,14.871696,0.879193,-142.561447,294.500458,0.000000
65.310005,64.986069,-142.516968,-0.001457,0.003461,0.087919,289.072479,14.726054,0.879193,-142.516968,294.500458,0.000000
65.710007,66.127396,-142.516968,-0.001440,0.003469,0.088110,294.149353,14.984682,0.881101,-142.516968,294.500458,0.000000
66.110001,65.460464,-142.561447,-0.001440,0.003469,0.088101,291.182678,14.833553,0.881015,-142.561447,294.500458,0.000000
66.510002,65.031494,-142.605927,-0.001427,0.003479,0.088362,289.274536,14.736347,0.883616,-142.605927,294.500458,0.000000
66.910004,64.981979,-142.650406,-0.001436,0.003485,0.088518,289.054291,14.725127,0.885177,-142.650406,294.500458,0.000000
67.310005,65.143204,-142.650406,-0.001423,0.003491,0.088665,289.771454,14.761662,0.886652,-142.650406,294.500458,0.000000
67.710007,65.332001,-142.694885,-0.001423,0.003497,0.088830,290.611267,14.804443,0.888299,-142.694885,294.500458,0.000000
68.110001,65.015488,-142.739365,-0.001414,0.003497,0.088830,289.203339,14.732720,0.888299,-142.739365,294.500458,0.000000
68.510002,65.245605,-142.783859,-0.001410,0.003504,0.088995,290.226959,14.784865,0.889947,-142.783859,294.500458,0.000000
68.910004,64.996124,-142.783859,-0.001414,0.003504,0.089003,289.117187,14.728333,0.890034,-142.783859,294.500458,0.000000
69.310005,64.926483,-142.828339,-0.001397,0.003506,0.089064,288.807434,14.712552,0.890641,-142.828339,294.500458,0.000000
69.710007,65.474991,-142.828339,-0.001401,0.003514,0.089264,291.247314,14.836845,0.892635,-142.828339,294.500458,0.000000
70.110001,65.208374,-142.872818,-0.001397,0.003514,0.089264,290.061340,14.776429,0.892635,-142.872818,294.500458,0.000000
70.510002,64.945847,-142.917297,-0.001401,0.003514,0.089264,288.893555,14.716939,0.892635,-142.917297,294.500458,0.000000
70.910004,64.691528,-142.917297,-0.001406,0.003514,0.089264,287.762299,14.659310,0.892635,-142.917297,294.500458,0.000000
71.310005,64.449112,-142.961777,-0.001401,0.003514,0.089264,286.683960,14.604378,0.892635,-142.961777,294.500458,0.000000
71.710007,64.208557,-142.917297,-0.001397,0.003514,0.089264,285.613922,14.549868,0.892635,-142.917297,294.500458,0.000000
72.110001,63.999649,-143.050735,-0.001380,0.003515,0.089272,284.684662,14.502528,0.892722,-143.050735,294.500458,0.000000
72.510002,65.574783,-143.006256,-0.001362,0.003314,0.084173,291.691193,14.859459,0.841729,-143.006256,294.500458,0.000000
72.910004,65.338699,-143.050735,-0.001345,0.003476,0.088284,290.641052,14.805962,0.882836,-143.050735,294.500458,0.000000
73.310005,65.216202,-143.095215,-0.001362,0.003498,0.088847,290.096161,14.778203,0.888473,-143.095215,294.500458,0.000000
73.710007,65.090698,-143.139694,-0.001358,0.003509,0.089125,289.537872,14.749763,0.891248,-143.139694,294.500458,0.000000
74.110001,64.871750,-143.184189,-0.001350,0.003509,0.089125,288.563965,14.700149,0.891248,-143.184189,294.500458,0.000000
74.510002,65.413559,-143.184189,-0.001354,0.003528,0.089619,290.974030,14.822924,0.896191,-143.184189,294.500458,0.000000
74.910004,65.254181,-143.184189,-0.001345,0.003528,0.089619,290.265106,14.786808,0.896191,-143.184189,294.500458,0.000000
75.310005,65.115280,-143.228668,-0.001345,0.003530,0.089671,289.647247,14.755334,0.896711,-143.228668,294.500458,0.000000
75.710007,64.997238,-143.317627,-0.001345,0.003530,0.089671,289.122162,14.728585,0.896711,-143.317627,294.500458,0.000000
76.110001,65.460098,-143.273148,-0.001345,0.003539,0.089897,291.181061,14.833470,0.898966,-143.273148,294.500458,0.000000
76.510002,65.324188,-143.362106,-0.001350,0.003539,0.089897,290.576508,14.802672,0.898966,-143.362106,294.500458,0.000000
76.910004,65.186783,-143.362106,-0.001350,0.003539,0.089897,289.965302,14.771536,0.898966,-143.362106,294.500458,0.000000
77.310005,65.066132,-143.362106,-0.001345,0.003540,0.089923,289.428619,14.744196,0.899226,-143.362106,294.500458,0.000000
77.710007,65.202042,-143.451065,-0.001337,0.003548,0.090131,290.033173,14.774994,0.901308,-143.451065,294.500458,0.000000
78.110001,65.511108,-143.451065,-0.001341,0.003549,0.090139,291.407959,14.845029,0.901394,-143.451065,294.500458,0.000000
78.510002,65.406845,-143.406586,-0.001354,0.003549,0.090139,290.944183,14.821403,0.901394,-143.406586,294.500458,0.000000
78.910004,65.312271,-143.451065,-0.001350,0.003549,0.090139,290.523499,14.799972,0.901394,-143.451065,294.500458,0.000000
79.310005,65.216934,-143.540024,-0.001358,0.003549,0.090139,290.099426,14.778368,0.901394,-143.540024,294.500458,0.000000
79.710007,65.135757,-143.495544,-0.001341,0.003550,0.090174,289.738312,14.759974,0.901741,-143.495544,294.500458,0.000000
80.110001,65.073578,-143.584503,-0.001341,0.003550,0.090174,289.461731,14.745884,0.901741,-143.584503,294.500458,0.000000
80.510002,64.985703,-143.540024,-0.001354,0.003550,0.090174,289.070831,14.725970,0.901741,-143.540024,294.500458,0.000000
80.910004,65.681656,-143.584503,-0.001337,0.003559,0.090408,292.166595,14.883677,0.904083,-143.584503,294.500458,0.000000
81.310005,65.638840,-143.628998,-0.001337,0.003559,0.090408,291.976135,14.873974,0.904083,-143.628998,294.500458,0.000000
81.710007,65.571442,-143.673477,-0.001345,0.003559,0.090408,291.676331,14.858701,0.904083,-143.673477,294.500458,0.000000
82.110001,65.499191,-143.717957,-0.001350,0.003559,0.090408,291.354950,14.842328,0.904083,-143.717957,294.500458,0.000000
82.510002,65.399399,-143.717957,-0.001341,0.003559,0.090408,290.911041,14.819715,0.904083,-143.717957,294.500458,0.000000
82.910004,65.328644,-143.762436,-0.001341,0.003559,0.090408,290.596313,14.803682,0.904083,-143.762436,294.500458,0.000000
83.310005,65.246735,-143.806915,-0.001350,0.003559,0.090408,290.231964,14.785122,0.904083,-143.806915,294.500458,0.000000
83.710007,65.146927,-143.806915,-0.001332,0.003559,0.090408,289.787994,14.762505,0.904083,-143.806915,294.500458,0.000000
84.110001,65.060913,-143.851395,-0.001350,0.003559,0.090408,289.405396,14.743013,0.904083,-143.851395,294.500458,0.000000
84.510002,64.989426,-143.895874,-0.001337,0.003559,0.090408,289.087402,14.726814,0.904083,-143.895874,294.500458,0.000000
84.910004,64.901535,-143.851395,-0.001345,0.003559,0.090408,288.696442,14.706899,0.904083,-143.851395,294.500458,0.000000
85.310005,64.800629,-143.895874,-0.001341,0.003559,0.090408,288.247589,14.684032,0.904083,-143.895874,294.500458,0.000000
85.710007,66.285278,-143.940353,-0.001337,0.003572,0.090720,294.851654,15.020458,0.907205,-143.940353,294.500458,0.000000
86.110001,66.139679,-143.940353,-0.001337,0.003571,0.090703,294.203979,14.987466,0.907031,-143.940353,294.500458,0.000000
86.510002,66.045471,-144.029312,-0.001354,0.003571,0.090703,293.784943,14.966118,0.907031,-144.029312,294.500458,0.000000
86.910004,65.911407,-144.118286,-0.001341,0.003571,0.090703,293.188568,14.935738,0.907031,-144.118286,294.500458,0.000000
87.310005,65.881989,-143.984833,-0.001337,0.003571,0.090703,293.057709,14.929071,0.907031,-143.984833,294.500458,0.000000
87.710007,65.792252,-144.118286,-0.001319,0.003571,0.090703,292.658539,14.908737,0.907031,-144.118286,294.500458,0.000000
88.110001,65.696182,-144.118286,-0.001341,0.003571,0.090703,292.231201,14.886968,0.907031,-144.118286,294.500458,0.000000
88.510002,65.608673,-144.162766,-0.001341,0.003571,0.090703,291.841949,14.867138,0.907031,-144.162766,294.500458,0.000000
88.910004,65.543884,-144.162766,-0.001328,0.003571,0.090703,291.553772,14.852456,0.907031,-144.162766,294.500458,0.000000
89.310005,65.485413,-144.207245,-0.001328,0.003571,0.090703,291.293671,14.839207,0.907031,-144.207245,294.500458,0.000000
89.710007,65.391586,-144.207245,-0.001328,0.003571,0.090703,290.876312,14.817945,0.907031,-144.207245,294.500458,0.000000
90.110001,65.308914,-144.296204,-0.001332,0.003571,0.090703,290.508545,14.799212,0.907031,-144.296204,294.500458,0.000000
90.510002,65.265350,-144.251724,-0.001324,0.003571,0.090703,290.314789,14.789339,0.907031,-144.251724,294.500458,0.000000
90.910004,65.190125,-144.296204,-0.001328,0.003571,0.090703,289.980164,14.772293,0.907031,-144.296204,294.500458,0.000000
91.310005,65.095551,-144.296204,-0.001332,0.003571,0.090703,289.559479,14.750862,0.907031,-144.296204,294.500458,0.000000
91.710007,65.038574,-144.385162,-0.001337,0.003572,0.090729,289.306030,14.737952,0.907292,-144.385162,294.500458,0.000000
92.110001,64.986069,-144.429642,-0.001337,0.003572,0.090729,289.072479,14.726054,0.907292,-144.429642,294.500458,0.000000
92.510002,64.927612,-144.429642,-0.001324,0.003572,0.090738,288.812439,14.712808,0.907378,-144.429642,294.500458,0.000000
92.910004,64.859467,-144.474136,-0.001328,0.003572,0.090738,288.509308,14.697365,0.907378,-144.474136,294.500458,0.000000
93.310005,66.089783,-144.474136,-0.001328,0.003583,0.090998,293.982025,14.976159,0.909980,-144.474136,294.500458,0.000000
93.710007,65.996307,-144.518616,-0.001332,0.003582,0.090981,293.566223,14.954977,0.909806,-144.518616,294.500458,0.000000
94.110008,65.895035,-144.518616,-0.001337,0.003582,0.090981,293.115753,14.932029,0.909806,-144.518616,294.500458,0.000000
94.510002,65.870453,-144.563095,-0.001324,0.003582,0.090981,293.006409,14.926458,0.909806,-144.563095,294.500458,0.000000
94.910004,65.824646,-144.563095,-0.001328,0.003582,0.090981,292.802643,14.916078,0.909806,-144.563095,294.500458,0.000000
95.310005,65.758362,-144.563095,-0.001328,0.003582,0.090981,292.507812,14.901057,0.909806,-144.563095,294.500458,0.000000
95.710007,65.653732,-144.563095,-0.001319,0.003582,0.090981,292.042389,14.877348,0.909806,-144.563095,294.500458,0.000000
96.110008,65.605698,-144.652054,-0.001319,0.003582,0.090981,291.828705,14.866464,0.909806,-144.652054,294.500458,0.000000
96.510002,65.553192,-144.652054,-0.001324,0.003582,0.090981,291.595154,14.854566,0.909806,-144.652054,294.500458,0.000000
96.910004,65.504776,-144.696533,-0.001337,0.003582,0.090981,291.379791,14.843594,0.909806,-144.696533,294.500458,0.000000
97.310005,65.454514,-144.696533,-0.001319,0.003582,0.090981,291.156219,14.832205,0.909806,-144.696533,294.500458,0.000000
97.710007,65.378174,-144.785492,-0.001306,0.003582,0.090989,290.816650,14.814906,0.909893,-144.785492,294.500458,0.000000
98.110008,65.321579,-144.785492,-0.001324,0.003582,0.090989,290.564880,14.802081,0.909893,-144.785492,294.500458,0.000000
98.510002,65.285828,-144.829971,-0.001328,0.003582,0.090989,290.405853,14.793981,0.909893,-144.829971,294.500458,0.000000
98.910004,65.243378,-144.829971,-0.001315,0.003582,0.090989,290.217041,14.784361,0.909893,-144.829971,294.500458,0.000000
99.310005,65.159592,-144.829971,-0.001332,0.003583,0.091015,289.844330,14.765374,0.910153,-144.829971,294.500458,0.000000
99.710007,65.146194,-144.874451,-0.001319,0.003585,0.091050,289.784760,14.762339,0.910500,-144.874451,294.500458,0.000000
100.110008,65.124588,-144.918945,-0.001319,0.003585,0.091059,289.688629,14.757442,0.910587,-144.918945,294.500458,0.000000
100.510002,65.084381,-144.918945,-0.001324,0.003586,0.091076,289.509796,14.748331,0.910760,-144.918945,294.500458,0.000000
100.910004,65.067993,-145.007904,-0.001315,0.003586,0.091076,289.436890,14.744618,0.910760,-145.007904,294.500458,0.000000
101.310005,65.051239,-145.007904,-0.001306,0.003586,0.091076,289.362366,14.740822,0.910760,-145.007904,294.500458,0.000000
101.710007,65.503296,-145.007904,-0.001319,0.003592,0.091249,291.373199,14.843259,0.912495,-145.007904,294.500458,0.000000
102.110008,65.518188,-145.052383,-0.001328,0.003592,0.091249,291.439453,14.846633,0.912495,-145.052383,294.500458,0.000000
102.510002,65.517822,-145.141342,-0.001319,0.003592,0.091249,291.437836,14.846551,0.912495,-145.141342,294.500458,0.000000
102.910004,65.500320,-145.096863,-0.001319,0.003592,0.091249,291.359985,14.842586,0.912495,-145.096863,294.500458,0.000000
103.310005,65.480576,-145.052383,-0.001319,0.003592,0.091249,291.272156,14.838111,0.912495,-145.052383,294.500458,0.000000
103.710007,65.427704,-145.185822,-0.001311,0.003592,0.091249,291.036957,14.826130,0.912495,-145.185822,294.500458,0.000000
104.110008,65.386734,-145.141342,-0.001311,0.003592,0.091249,290.854706,14.816845,0.912495,-145.141342,294.500458,0.000000
104.510002,65.346527,-145.185822,-0.001324,0.003592,0.091249,290.675873,14.807735,0.912495,-145.185822,294.500458,0.000000
104.910004,65.328278,-145.141342,-0.001311,0.003592,0.091249,290.594696,14.803599,0.912495,-145.141342,294.500458,0.000000
105.310005,65.292526,-145.274780,-0.001311,0.003592,0.091249,290.435669,14.795499,0.912495,-145.274780,294.500458,0.000000
105.710007,65.263489,-145.274780,-0.001306,0.003592,0.091249,290.306488,14.788918,0.912495,-145.274780,294.500458,0.000000
106.110008,65.245987,-145.274780,-0.001311,0.003592,0.091249,290.228638,14.784952,0.912495,-145.274780,294.500458,0.000000
106.510002,65.189377,-145.408234,-0.001306,0.003592,0.091249,289.976837,14.772124,0.912495,-145.408234,294.500458,0.000000
106.910004,65.155869,-145.363754,-0.001311,0.003592,0.091249,289.827789,14.764531,0.912495,-145.363754,294.500458,0.000000
107.310005,65.290665,-145.408234,-0.001315,0.003596,0.091336,290.427368,14.795076,0.913362,-145.408234,294.500458,0.000000
107.710007,65.291779,-145.408234,-0.001311,0.003596,0.091336,290.432343,14.795329,0.913362,-145.408234,294.500458,0.000000
108.110008,65.298111,-145.452713,-0.001315,0.003596,0.091336,290.460510,14.796764,0.913362,-145.452713,294.500458,0.000000
108.510002,65.263107,-145.452713,-0.001306,0.003596,0.091336,290.304810,14.788831,0.913362,-145.452713,294.500458,0.000000
108.910004,65.253799,-145.541672,-0.001306,0.003596,0.091336,290.263397,14.786722,0.913362,-145.541672,294.500458,0.000000
109.310005,65.232208,-145.497192,-0.001298,0.003596,0.091336,290.167358,14.781830,0.913362,-145.497192,294.500458,0.000000
109.710007,65.184921,-145.586151,-0.001315,0.003596,0.091345,289.957001,14.771114,0.913449,-145.586151,294.500458,0.000000
110.110008,65.177094,-145.630630,-0.001306,0.003596,0.091345,289.922180,14.769341,0.913449,-145.630630,294.500458,0.000000
110.510002,65.148788,-145.630630,-0.001311,0.003596,0.091345,289.796295,14.762927,0.913449,-145.630630,294.500458,0.000000
110.910004,65.205765,-145.586151,-0.001319,0.003598,0.091397,290.049713,14.775837,0.913969,-145.586151,294.500458,0.000000
111.310005,65.225128,-145.675110,-0.001298,0.003598,0.091397,290.135864,14.780226,0.913969,-145.675110,294.500458,0.000000
111.710007,65.206512,-145.719589,-0.001311,0.003598,0.091397,290.053040,14.776007,0.913969,-145.719589,294.500458,0.000000
112.110008,65.180069,-145.764084,-0.001311,0.003598,0.091397,289.935425,14.770015,0.913969,-145.764084,294.500458,0.000000
112.510002,65.145447,-145.764084,-0.001298,0.003598,0.091397,289.781433,14.762170,0.913969,-145.764084,294.500458,0.000000
112.910004,65.193481,-145.808563,-0.001293,0.003600,0.091440,289.995087,14.773054,0.914403,-145.808563,294.500458,0.000000
113.310005,65.211731,-145.853043,-0.001311,0.003600,0.091440,290.076263,14.777190,0.914403,-145.853043,294.500458,0.000000
113.710007,65.196091,-145.808563,-0.001298,0.003600,0.091440,290.006683,14.773645,0.914403,-145.808563,294.500458,0.000000
114.110008,65.201294,-145.897522,-0.001298,0.003600,0.091440,290.029846,14.774824,0.914403,-145.897522,294.500458,0.000000
114.510002,65.156616,-145.897522,-0.001311,0.003600,0.091440,289.831116,14.764701,0.914403,-145.897522,294.500458,0.000000
114.910004,65.132782,-145.897522,-0.001311,0.003600,0.091440,289.725098,14.759299,0.914403,-145.897522,294.500458,0.000000
115.310005,65.131668,-145.986481,-0.001293,0.003601,0.091466,289.720123,14.759047,0.914663,-145.986481,294.500458,0.000000
115.710007,65.132034,-145.986481,-0.001302,0.003601,0.091475,289.721771,14.759130,0.914750,-145.986481,294.500458,0.000000
116.110008,65.123474,-146.030960,-0.001306,0.003601,0.091475,289.683685,14.757190,0.914750,-146.030960,294.500458,0.000000
116.510002,65.117508,-146.030960,-0.001302,0.003601,0.091475,289.657135,14.755838,0.914750,-146.030960,294.500458,0.000000
116.910004,65.103363,-146.030960,-0.001293,0.003601,0.091475,289.594208,14.752633,0.914750,-146.030960,294.500458,0.000000
117.310005,65.070221,-146.119919,-0.001311,0.003601,0.091475,289.446808,14.745123,0.914750,-146.119919,294.500458,0.000000
117.710007,65.055328,-146.208893,-0.001302,0.003601,0.091475,289.380554,14.741748,0.914750,-146.208893,294.500458,0.000000
118.110008,65.047134,-146.119919,-0.001289,0.003602,0.091484,289.344116,14.739891,0.914836,-146.119919,294.500458,0.000000
118.510002,65.010651,-146.208893,-0.001298,0.003602,0.091492,289.181824,14.731625,0.914923,-146.208893,294.500458,0.000000
118.910004,65.019958,-146.208893,-0.001293,0.003602,0.091492,289.223206,14.733733,0.914923,-146.208893,294.500458,0.000000
119.310005,65.006546,-146.297852,-0.001311,0.003602,0.091492,289.163544,14.730694,0.914923,-146.297852,294.500458,0.000000
119.710007,64.990540,-146.253372,-0.001302,0.003602,0.091501,289.092346,14.727067,0.915010,-146.253372,294.500458,0.000000
120.110008,64.968567,-146.297852,-0.001293,0.003602,0.091501,288.994629,14.722088,0.915010,-146.297852,294.500458,0.000000
120.510002,65.292908,-146.342331,-0.001302,0.003608,0.091631,290.437347,14.795585,0.916311,-146.342331,294.500458,0.000000
120.910004,65.351364,-146.342331,-0.001311,0.003608,0.091631,290.697388,14.808831,0.916311,-146.342331,294.500458,0.000000
121.310005,65.326050,-146.386810,-0.001293,0.003608,0.091631,290.584778,14.803094,0.916311,-146.386810,294.500458,0.000000
121.710007,65.332748,-146.475769,-0.001302,0.003608,0.091631,290.614594,14.804612,0.916311,-146.475769,294.500458,0.000000
122.110008,65.328644,-146.475769,-0.001311,0.003608,0.091631,290.596313,14.803682,0.916311,-146.475769,294.500458,0.000000
122.510002,65.315613,-146.431290,-0.001289,0.003608,0.091631,290.538361,14.800730,0.916311,-146.431290,294.500458,0.000000
122.910004,65.306305,-146.520248,-0.001306,0.003608,0.091631,290.496948,14.798620,0.916311,-146.520248,294.500458,0.000000
123.310005,65.284714,-146.564728,-0.001306,0.003608,0.091631,290.400909,14.793728,0.916311,-146.564728,294.500458,0.000000
123.710007,65.265350,-146.564728,-0.001298,0.003608,0.091631,290.314789,14.789339,0.916311,-146.564728,1681.640747,0.000000
124.110008,65.203156,-146.609207,-0.001302,0.003598,0.091380,290.038116,14.775247,0.913796,-146.609207,0.091180,0.000000
124.510002,65.147675,-146.698181,-0.001293,0.003578,0.090877,289.791321,14.762674,0.908766,-146.698181,0.090512,0.000000
124.910004,65.125702,-146.698181,-0.001298,0.003553,0.090252,289.693604,14.757695,0.902522,-146.698181,0.089845,0.000000
125.310005,65.003204,-146.742661,-0.001281,0.003530,0.089662,289.148682,14.729937,0.896625,-146.742661,0.089177,0.000000
125.710007,64.958511,-146.698181,-0.001281,0.003505,0.089021,288.949890,14.719809,0.890207,-146.698181,0.088509,0.000000
126.110008,64.942505,-146.742661,-0.001289,0.003480,0.088388,288.878693,14.716182,0.883876,-146.742661,0.087841,0.000000
126.510010,64.925369,-146.787140,-0.001281,0.003456,0.087789,288.802460,14.712299,0.877893,-146.787140,0.087174,0.000000
126.910004,64.832657,-146.742661,-0.001302,0.003426,0.087009,288.390076,14.691290,0.870088,-146.742661,0.086514,0.000000
127.310005,64.819611,-146.876099,-0.001293,0.003404,0.086471,288.332031,14.688334,0.864711,-146.876099,0.085847,0.000000
127.710007,64.607361,-146.876099,-0.001276,0.003377,0.085786,287.387909,14.640238,0.857860,-146.876099,0.085179,0.000000
128.110001,63.949005,-146.965057,-0.001285,0.003355,0.085205,284.459381,14.491052,0.852049,-146.965057,0.084511,0.000000
128.510010,63.010262,-146.876099,-0.001281,0.003331,0.084615,280.283630,14.278329,0.846152,-146.876099,0.083843,0.000000
128.910004,61.634712,-146.965057,-0.001272,0.003303,0.083895,274.164886,13.966625,0.838954,-146.965057,0.083176,0.000000
129.310013,60.555954,-147.054031,-0.001255,0.003284,0.083418,269.366333,13.722176,0.834184,-147.054031,0.082508,0.000000
129.710007,58.765961,-146.965057,-0.001268,0.003261,0.082820,261.404053,13.316557,0.828201,-146.965057,0.081840,0.000000
130.110001,56.459480,-147.054031,-0.001246,0.003233,0.082118,251.144318,12.793900,0.821176,-147.054031,0.081172,0.000000
130.510010,54.469528,-147.098511,-0.001268,0.003207,0.081450,242.292557,12.342972,0.814498,-147.098511,0.080513,0.000000
130.910004,51.389259,-147.009537,-0.001263,0.003180,0.080782,228.590836,11.644972,0.807821,-147.009537,0.079845,0.000000
131.310013,49.365791,-147.098511,-0.001263,0.003158,0.080201,219.590012,11.186448,0.802010,-147.098511,0.079178,0.000000
131.710007,46.539856,-147.142990,-0.001255,0.003132,0.079559,207.019623,10.546082,0.795593,-147.142990,0.078510,0.000000
132.110001,43.748177,-147.142990,-0.001263,0.003108,0.078952,194.601608,9.913479,0.789522,-147.142990,0.077842,0.000000
132.510010,41.508354,-147.187469,-0.001263,0.003083,0.078319,184.638382,9.405927,0.783192,-147.187469,0.077174,0.000000
132.910004,37.229797,-147.187469,-0.001255,0.003047,0.077400,165.606415,8.436393,0.773999,-147.187469,0.076507,0.000000
133.310013,34.341675,-147.231949,-0.001263,0.003021,0.076723,152.759399,7.781935,0.767235,-147.231949,0.075839,0.000000
133.710007,33.427505,-147.276428,-0.001276,0.003014,0.076567,148.692978,7.574781,0.765674,-147.276428,0.075180,0.000000
134.110001,29.677711,-147.276428,-0.001259,0.002978,0.075648,132.013062,6.725066,0.756481,-147.276428,0.074512,0.000000
134.510010,26.715485,-147.320908,-0.001272,0.002948,0.074868,118.836411,6.053815,0.748676,-147.320908,0.073844,0.000000
134.910004,23.274391,-147.320908,-0.001268,0.002917,0.074104,103.529663,5.274053,0.741044,-147.320908,0.073177,0.000000
135.310013,20.792160,-147.409866,-0.001250,0.002892,0.073445,92.488144,4.711571,0.734453,-147.409866,0.072509,0.000000
135.710007,18.083519,-147.409866,-0.001268,0.002870,0.072908,80.439507,4.097784,0.729077,-147.409866,0.071841,0.000000
136.110001,15.852264,-147.365387,-0.001263,0.002851,0.072422,70.514397,3.592175,0.724220,-147.365387,0.071173,0.000000
136.510010,12.173225,-147.454346,-0.001250,0.002814,0.071468,54.149212,2.758492,0.714681,-147.454346,0.070505,0.000000
136.910004,8.795807,-147.454346,-0.001272,0.002784,0.070714,39.125702,1.993158,0.707136,-147.454346,0.069846,0.000000
137.310013,6.904900,-147.543320,-0.001272,0.002768,0.070306,30.714527,1.564673,0.703060,-147.543320,0.069179,0.000000
137.710007,4.002258,-147.498840,-0.001259,0.002741,0.069621,17.802935,0.906925,0.696209,-147.498840,0.068511,0.000000
138.110001,1.021416,-147.543320,-0.001268,0.002711,0.068849,4.543484,0.231456,0.688491,-147.543320,0.067843,0.000000
138.510010,-1.775101,-147.543320,-0.001255,0.002683,0.068147,-7.896042,-0.402244,0.681466,-147.543320,0.067175,0.000000
138.910004,-3.982525,-147.587799,-0.001276,0.002661,0.067592,-17.715155,-0.902453,0.675916,-147.587799,0.066508,0.000000
139.310013,-0.169434,-147.632278,-0.001293,0.002628,0.066742,-0.753678,-0.038394,0.667417,-147.632278,0.065840,0.000000
139.710007,-0.052132,-147.676758,-0.001285,0.002606,0.066204,-0.231893,-0.011813,0.662040,-147.676758,0.065172,0.000000
140.110001,-0.073730,-147.676758,-0.001319,0.002582,0.065580,-0.327969,-0.016708,0.655796,-147.676758,0.064513,0.000000
140.510010,-0.078575,-147.721237,-0.001367,0.002548,0.064712,-0.349520,-0.017805,0.647124,-147.721237,0.063845,0.000000
140.910004,-0.063309,-147.765717,-0.001380,0.002527,0.064183,-0.281611,-0.014346,0.641834,-147.765717,0.063177,0.000000
141.310013,-0.040962,-147.810196,-0.001414,0.002503,0.063568,-0.182209,-0.009282,0.635677,-147.810196,0.062510,0.000000
141.710007,-0.040962,-147.854675,-0.001427,0.002476,0.062891,-0.182209,-0.009282,0.628912,-147.854675,0.061842,0.000000
142.110001,-0.058464,-147.810196,-0.001457,0.002455,0.062345,-0.260061,-0.013248,0.623449,-147.810196,0.061174,0.000000
142.510010,-0.090858,-147.899155,-0.001496,0.002420,0.061460,-0.404159,-0.020589,0.614603,-147.899155,0.060506,0.000000
142.910004,-0.061813,-147.899155,-0.001500,0.002397,0.060888,-0.274960,-0.014007,0.608879,-147.899155,0.059839,0.000000
143.310013,-0.058838,-147.899155,-0.001548,0.002373,0.060272,-0.261724,-0.013333,0.602722,-147.899155,0.059171,0.000000
143.710007,-0.063675,-147.899155,-0.001574,0.002350,0.059700,-0.283240,-0.014429,0.596998,-147.899155,0.058512,0.000000
144.110001,-0.067398,-147.988129,-0.001608,0.002319,0.058902,-0.299802,-0.015273,0.589020,-147.988129,0.057844,0.000000
144.510010,-0.060699,-147.988129,-0.001634,0.002287,0.058078,-0.270005,-0.013755,0.580781,-147.988129,0.057176,0.000000
144.910004,-0.088257,-148.032608,-0.001660,0.002263,0.057480,-0.392586,-0.019999,0.574797,-148.032608,0.056508,0.000000
145.310013,-0.064049,-148.032608,-0.001673,0.002242,0.056951,-0.284903,-0.014514,0.569507,-148.032608,0.055841,0.000000
145.710007,-0.090118,-148.077087,-0.001699,0.002213,0.056214,-0.400867,-0.020421,0.562136,-148.077087,0.055173,0.000000
146.110001,-0.090858,-148.121567,-0.001733,0.002190,0.055615,-0.404159,-0.020589,0.556152,-148.121567,0.054505,0.000000
146.510010,-0.052132,-148.121567,-0.001768,0.002155,0.054731,-0.231893,-0.011813,0.547306,-148.121567,0.053837,0.000000
146.910004,-0.069633,-148.166046,-0.001789,0.002137,0.054280,-0.309745,-0.015779,0.542797,-148.166046,0.053178,0.000000
147.310013,-0.074478,-148.210526,-0.001837,0.002107,0.053508,-0.331295,-0.016877,0.535078,-148.210526,0.052511,0.000000
147.710007,-0.060699,-148.166046,-0.001837,0.002082,0.052892,-0.270005,-0.013755,0.528921,-148.166046,0.051843,0.000000
148.110001,-0.077080,-148.210526,-0.001884,0.002050,0.052077,-0.342868,-0.017467,0.520769,-148.210526,0.051175,0.000000
148.510010,-0.078201,-148.299484,-0.001901,0.002024,0.051418,-0.347857,-0.017721,0.514178,-148.299484,0.050507,0.000000
148.910004,-0.083412,-148.255005,-0.001932,0.001999,0.050776,-0.371036,-0.018901,0.507761,-148.255005,0.049839,0.000000
149.310013,-0.109482,-148.388458,-0.001970,0.001978,0.050238,-0.486999,-0.024809,0.502384,-148.388458,0.049172,0.000000
149.710007,-0.085648,-148.299484,-0.001983,0.001956,0.049675,-0.380979,-0.019408,0.496747,-148.299484,0.048504,0.000000
150.110001,-0.080063,-148.388458,-0.002026,0.001918,0.048712,-0.356137,-0.018143,0.487121,-148.388458,0.047845,0.000000
150.510010,-0.087135,-148.432938,-0.002035,0.001894,0.048096,-0.387597,-0.019745,0.480963,-148.432938,0.047177,0.000000
150.910004,-0.080437,-148.432938,-0.002065,0.001872,0.047541,-0.357800,-0.018227,0.475413,-148.432938,0.046509,0.000000
151.310013,-0.103523,-148.432938,-0.002087,0.001846,0.046900,-0.460494,-0.023459,0.468996,-148.432938,0.045842,0.000000
151.710007,-0.098679,-148.432938,-0.002117,0.001824,0.046319,-0.438944,-0.022361,0.463185,-148.432938,0.045174,0.000000
152.110001,-0.121025,-148.477417,-0.002164,0.001786,0.045356,-0.538346,-0.027425,0.453559,-148.477417,0.044506,0.000000
152.510010,-0.109848,-148.521896,-0.002177,0.001765,0.044827,-0.488628,-0.024892,0.448269,-148.521896,0.043838,0.000000
152.910004,-0.098305,-148.610855,-0.002203,0.001745,0.044333,-0.437281,-0.022276,0.443326,-148.610855,0.043170,0.000000
153.310013,-0.115440,-148.655334,-0.002220,0.001727,0.043873,-0.513504,-0.026159,0.438729,-148.655334,0.042511,0.000000
153.710007,-0.084534,-148.655334,-0.002246,0.001691,0.042962,-0.376025,-0.019156,0.429624,-148.655334,0.041844,0.000000
154.110001,-0.087883,-148.610855,-0.002285,0.001655,0.042034,-0.390923,-0.019915,0.420344,-148.610855,0.041176,0.000000
154.510010,-0.087883,-148.744293,-0.002315,0.001631,0.041419,-0.390923,-0.019915,0.414187,-148.744293,0.040508,0.000000
154.910004,-0.051758,-148.744293,-0.002324,0.001614,0.040994,-0.230230,-0.011728,0.409938,-148.744293,0.039840,0.000000
155.310013,-0.098305,-148.744293,-0.002371,0.001578,0.040092,-0.437281,-0.022276,0.400918,-148.744293,0.039173,0.000000
155.710007,-0.079315,-148.744293,-0.002384,0.001562,0.039667,-0.352812,-0.017973,0.396669,-148.744293,0.038505,0.000000
156.110001,-0.081177,-148.833267,-0.002427,0.001523,0.038696,-0.361092,-0.018395,0.386956,-148.833267,0.037837,0.000000
156.510010,-0.088997,-148.788788,-0.002436,0.001502,0.038158,-0.395878,-0.020167,0.381579,-148.788788,0.037169,0.000000
156.910004,-0.095329,-148.877747,-0.002466,0.001474,0.037438,-0.424046,-0.021602,0.374381,-148.877747,0.036510,0.000000
157.310013,-0.099426,-148.877747,-0.002501,0.001446,0.036736,-0.442270,-0.022530,0.367357,-148.877747,0.035842,0.000000
157.710007,-0.091232,-148.966705,-0.002527,0.001428,0.036267,-0.405822,-0.020674,0.362674,-148.966705,0.035175,0.000000
158.110001,-0.086761,-148.966705,-0.002561,0.001391,0.035339,-0.385934,-0.019660,0.353394,-148.966705,0.034507,0.000000
158.510010,-0.062935,-148.966705,-0.002578,0.001369,0.034776,-0.279948,-0.014261,0.347758,-148.966705,0.033839,0.000000
158.910004,-0.077827,-148.966705,-0.002626,0.001342,0.034091,-0.346194,-0.017636,0.340906,-148.966705,0.033171,0.000000
159.310013,-0.075966,-149.055664,-0.002643,0.001314,0.033388,-0.337913,-0.017214,0.333882,-149.055664,0.032504,0.000000
159.710007,-0.078201,-149.055664,-0.002665,0.001290,0.032772,-0.347857,-0.017721,0.327725,-149.055664,0.031836,0.000000
160.110001,-0.069633,-149.100143,-0.002708,0.001263,0.032087,-0.309745,-0.015779,0.320874,-149.100143,0.031177,0.000000
160.510010,-0.066658,-149.100143,-0.002734,0.001235,0.031359,-0.296510,-0.015105,0.313589,-149.100143,0.030509,0.000000
160.910004,-0.065910,-149.189117,-0.002755,0.001214,0.030847,-0.293184,-0.014935,0.308472,-149.189117,0.029841,0.000000
161.310013,-0.066658,-149.189117,-0.002785,0.001186,0.030136,-0.296510,-0.015105,0.301361,-149.189117,0.029173,0.000000
161.710007,-0.055115,-149.233597,-0.002841,0.001157,0.029382,-0.245163,-0.012489,0.293816,-149.233597,0.028506,0.000000
162.110001,-0.053253,-149.233597,-0.002850,0.001131,0.028740,-0.236882,-0.012067,0.287399,-149.233597,0.027838,0.000000
162.510010,-0.039474,-149.278076,-0.002867,0.001108,0.028141,-0.175591,-0.008945,0.281415,-149.278076,0.027170,0.000000
162.910004,-0.029419,-149.278076,-0.002893,0.001088,0.027647,-0.130862,-0.006666,0.276472,-149.278076,0.026502,0.000000
163.310013,-0.051018,-149.233597,-0.002923,0.001062,0.026971,-0.226938,-0.011561,0.269707,-149.233597,0.026858,0.000000
163.400009,-0.061813,-149.278076,-0.002923,0.001062,0.026971,-0.274960,-0.014007,0.269707,-149.278076,0.026858,0.000000