File: Data/compression 20/AutoNoHeating-17-20-reverse-2-1_09112024_170520.csv
Time (sec),S:Load (lbs),S:HL1 (DIM),S:LVDT (in),S:Position (in),Ch:Position (mm),Ch:Load (N),Ch:Stress (MPa),Ch:Strain (mm/mm),Ch:HL1 (DIM),Set Point (),Cycles ()
0.110000,-0.033890,-177.523483,-0.010611,-0.006263,-0.159084,-0.150749,-0.007680,-1.590839,-177.523483,-0.158815,0.000000
0.470000,-0.067398,-177.523483,-0.010628,-0.006191,-0.157263,-0.299802,-0.015273,-1.572627,-177.523483,-0.156560,0.000000
0.830000,-0.092354,-177.478989,-0.010529,-0.005981,-0.151921,-0.410810,-0.020928,-1.519206,-177.478989,-0.150559,0.000000
1.190000,-0.103523,-177.523483,-0.010274,-0.005738,-0.145746,-0.460494,-0.023459,-1.457460,-177.523483,-0.144558,0.000000
1.550000,-0.070381,-177.567963,-0.010050,-0.005509,-0.139927,-0.313071,-0.015949,-1.399269,-177.567963,-0.138557,0.000000
1.910000,-0.027931,-177.567963,-0.009796,-0.005268,-0.133796,-0.124244,-0.006329,-1.337956,-177.567963,-0.132555,0.000000
2.270000,-0.049896,-177.656921,-0.009554,-0.005037,-0.127950,-0.221950,-0.011307,-1.279505,-177.656921,-0.126572,0.000000
2.630000,-0.064049,-177.612442,-0.009300,-0.004797,-0.121845,-0.284903,-0.014514,-1.218452,-177.612442,-0.120570,0.000000
2.990000,-0.077080,-177.656921,-0.009076,-0.004565,-0.115939,-0.342868,-0.017467,-1.159394,-177.656921,-0.114569,0.000000
3.350000,-0.081177,-177.701401,-0.008843,-0.004325,-0.109851,-0.361092,-0.018395,-1.098515,-177.701401,-0.108568,0.000000
3.710000,-0.063309,-177.701401,-0.008593,-0.004085,-0.103764,-0.281611,-0.014346,-1.037636,-177.701401,-0.102567,0.000000
4.070000,-0.046547,-177.745880,-0.008338,-0.003847,-0.097710,-0.207051,-0.010548,-0.977103,-177.745880,-0.096583,0.000000
4.430000,-0.058838,-177.745880,-0.008101,-0.003616,-0.091848,-0.261724,-0.013333,-0.918479,-177.745880,-0.090582,0.000000
4.790000,-0.067032,-177.790359,-0.007864,-0.003383,-0.085925,-0.298173,-0.015190,-0.859247,-177.790359,-0.084581,0.000000
5.150000,-0.053993,-177.790359,-0.007623,-0.003141,-0.079776,-0.240174,-0.012235,-0.797761,-177.790359,-0.078579,0.000000
5.510000,-0.058464,-177.790359,-0.007381,-0.002909,-0.073879,-0.260061,-0.013248,-0.738790,-177.790359,-0.072578,0.000000
5.870000,-0.044312,-177.879318,-0.007140,-0.002669,-0.067782,-0.197107,-0.010041,-0.677824,-177.879318,-0.066594,0.000000
6.230000,-0.047668,-177.923798,-0.006881,-0.002431,-0.061746,-0.212040,-0.010802,-0.617465,-177.923798,-0.060593,0.000000
6.590000,-0.074478,-177.834839,-0.006627,-0.002198,-0.055841,-0.331295,-0.016877,-0.558407,-177.834839,-0.054592,0.000000
6.950000,-0.068520,-177.968292,-0.006403,-0.001961,-0.049813,-0.304790,-0.015527,-0.498134,-177.968292,-0.048591,0.000000
7.310000,-0.081924,-177.968292,-0.006170,-0.001729,-0.043908,-0.364418,-0.018564,-0.439076,-177.968292,-0.042607,0.000000
7.670001,-0.020851,-177.968292,-0.005933,-0.001491,-0.037872,-0.092750,-0.004725,-0.378717,-177.968292,-0.036606,0.000000
8.030001,-0.046921,-177.968292,-0.005678,-0.001257,-0.031931,-0.208714,-0.010632,-0.319312,-177.968292,-0.030604,0.000000
8.390000,-0.032768,-178.012772,-0.005428,-0.001013,-0.025722,-0.145760,-0.007425,-0.257219,-178.012772,-0.024603,0.000000
8.750000,-0.062935,-178.057251,-0.005204,-0.000784,-0.019920,-0.279948,-0.014261,-0.199202,-178.057251,-0.018602,0.000000
9.110001,-0.056602,-178.057251,-0.004945,-0.000544,-0.013824,-0.251780,-0.012826,-0.138236,-178.057251,-0.012618,0.000000
9.470000,-0.061440,-178.057251,-0.004725,-0.000310,-0.007883,-0.273297,-0.013922,-0.078831,-178.057251,-0.006617,0.000000
9.830001,0.060692,-178.101730,-0.004527,0.000005,0.000121,0.269971,0.013753,0.001214,-178.101730,0.000347,0.000000
10.190001,0.027557,-178.146210,-0.004523,0.000005,0.000121,0.122581,0.006245,0.001214,-178.146210,0.000347,0.000000
10.550000,0.103516,-178.190689,-0.004531,0.000005,0.000121,0.460460,0.023457,0.001214,-178.190689,0.000859,0.000000
10.910001,0.067772,-178.101730,-0.004540,0.000005,0.000130,0.301465,0.015357,0.001301,-178.101730,0.001457,0.000000
11.270000,0.265503,-178.146210,-0.004510,0.000038,0.000971,1.181016,0.060164,0.009713,-178.146210,0.002055,0.000000
11.630000,0.412956,-178.235168,-0.004493,0.000059,0.001492,1.836921,0.093577,0.014916,-178.235168,0.002654,0.000000
11.990001,0.620369,-178.190689,-0.004462,0.000088,0.002237,2.759539,0.140578,0.022374,-178.190689,0.003261,0.000000
12.350000,0.849380,-178.324127,-0.004449,0.000113,0.002879,3.778233,0.192472,0.028792,-178.324127,0.003859,0.000000
12.710001,1.079880,-178.235168,-0.004437,0.000138,0.003512,4.803545,0.244704,0.035123,-178.235168,0.004458,0.000000
13.070001,1.341286,-178.324127,-0.004402,0.000160,0.004059,5.966337,0.303940,0.040586,-178.324127,0.005056,0.000000
13.430000,1.679398,-178.368607,-0.004381,0.000183,0.004640,7.470334,0.380557,0.046397,-178.368607,0.005654,0.000000
13.790001,2.071136,-178.324127,-0.004363,0.000208,0.005281,9.212875,0.469326,0.052814,-178.324127,0.006261,0.000000
14.150001,2.309456,-178.413101,-0.004350,0.000225,0.005706,10.272973,0.523330,0.057063,-178.413101,0.006860,0.000000
14.510000,2.771194,-178.413101,-0.004324,0.000254,0.006443,12.326889,0.627962,0.064435,-178.413101,0.007458,0.000000
14.870001,3.079887,-178.457581,-0.004307,0.000275,0.006990,13.700024,0.697912,0.069898,-178.457581,0.008057,0.000000
15.230000,3.533813,-178.457581,-0.004273,0.000299,0.007606,15.719188,0.800774,0.076056,-178.457581,0.008655,0.000000
15.590001,3.928528,-178.457581,-0.004247,0.000326,0.008282,17.474964,0.890217,0.082820,-178.457581,0.009262,0.000000
15.950001,4.192543,-178.591019,-0.004238,0.000343,0.008716,18.649363,0.950044,0.087156,-178.591019,0.009860,0.000000
16.310001,4.786102,-178.502060,-0.004225,0.000376,0.009548,21.289646,1.084546,0.095482,-178.502060,0.010459,0.000000
16.670000,5.077667,-178.546539,-0.004186,0.000398,0.010121,22.586592,1.150616,0.101205,-178.546539,0.011057,0.000000
17.030001,5.346893,-178.546539,-0.004174,0.000420,0.010658,23.784170,1.211623,0.106582,-178.546539,0.011656,0.000000
17.390001,5.494354,-178.591019,-0.004148,0.000434,0.011022,24.440109,1.245039,0.110224,-178.591019,0.012254,0.000000
17.750000,6.131485,-178.635498,-0.004130,0.000469,0.011916,27.274208,1.389414,0.119157,-178.635498,0.012861,0.000000
18.110001,6.430496,-178.635498,-0.004118,0.000493,0.012531,28.604277,1.457171,0.125314,-178.635498,0.013459,0.000000
18.470001,6.611847,-178.679977,-0.004083,0.000516,0.013104,29.410963,1.498266,0.131038,-178.679977,0.014058,0.000000
18.830002,6.861336,-178.679977,-0.004061,0.000537,0.013650,30.520746,1.554801,0.136501,-178.679977,0.014656,0.000000
19.190001,7.085876,-178.679977,-0.004040,0.000558,0.014179,31.519552,1.605683,0.141791,-178.679977,0.015255,0.000000
19.550001,7.139122,-178.768936,-0.004018,0.000574,0.014587,31.756401,1.617748,0.145867,-178.768936,0.015862,0.000000
19.910002,7.709229,-178.857910,-0.004010,0.000611,0.015515,34.292362,1.746936,0.155147,-178.857910,0.016460,0.000000
20.270000,7.950150,-178.813431,-0.003980,0.000634,0.016096,35.364033,1.801530,0.160957,-178.813431,0.017058,0.000000
20.630001,8.136337,-178.813431,-0.003941,0.000659,0.016746,36.192234,1.843720,0.167461,-178.813431,0.017657,0.000000
20.990002,8.085693,-178.813431,-0.003923,0.000676,0.017180,35.966961,1.832244,0.171797,-178.813431,0.018255,0.000000
21.350000,8.204483,-178.946869,-0.003902,0.000697,0.017700,36.495365,1.859162,0.177001,-178.946869,0.018862,0.000000
21.710001,8.359016,-178.857910,-0.003893,0.000715,0.018160,37.182762,1.894180,0.181597,-178.857910,0.019461,0.000000
22.070002,8.845703,-178.857910,-0.003863,0.000751,0.019070,39.347652,2.004465,0.190703,-178.857910,0.020059,0.000000
22.430000,8.967102,-178.946869,-0.003833,0.000774,0.019651,39.887661,2.031974,0.196513,-178.946869,0.020657,0.000000
22.790001,9.037102,-178.946869,-0.003803,0.000794,0.020172,40.199036,2.047837,0.201717,-178.946869,0.021256,0.000000
23.150002,9.206909,-179.035828,-0.003790,0.000817,0.020761,40.954376,2.086315,0.207614,-179.035828,0.021863,0.000000
23.510000,9.529755,-178.991348,-0.003764,0.000846,0.021499,42.390465,2.159473,0.214985,-178.991348,0.022461,0.000000
23.870001,9.599762,-179.035828,-0.003729,0.000870,0.022097,42.701874,2.175337,0.220969,-179.035828,0.023060,0.000000
24.230001,9.503685,-179.035828,-0.003729,0.000886,0.022513,42.274502,2.153566,0.225132,-179.035828,0.023658,0.000000
24.590002,9.977722,-179.035828,-0.003699,0.000917,0.023285,44.383125,2.260984,0.232850,-179.035828,0.024256,0.000000
24.950001,9.985909,-179.035828,-0.003678,0.000939,0.023840,44.419540,2.262839,0.238400,-179.035828,0.024855,0.000000
25.310001,9.962448,-179.080307,-0.003648,0.000958,0.024334,44.315182,2.257523,0.243344,-179.080307,0.025462,0.000000
25.670002,10.410416,-179.124786,-0.003630,0.000990,0.025150,46.307842,2.359034,0.251495,-179.124786,0.026060,0.000000
26.030001,10.116241,-179.124786,-0.003609,0.001000,0.025401,44.999290,2.292373,0.254010,-179.124786,0.026659,0.000000
26.390001,10.080864,-179.124786,-0.003583,0.001016,0.025809,44.841923,2.284357,0.258086,-179.124786,0.027257,0.000000
26.750002,10.970467,-179.258240,-0.003561,0.001054,0.026780,48.799072,2.485943,0.267799,-179.258240,0.027855,0.000000
27.110001,10.894127,-179.213745,-0.003544,0.001080,0.027430,48.459496,2.468644,0.274303,-179.213745,0.028462,0.000000
27.470001,11.383797,-179.258240,-0.003501,0.001106,0.028089,50.637657,2.579605,0.280894,-179.258240,0.029061,0.000000
27.830002,11.317886,-179.302719,-0.003488,0.001132,0.028749,50.344471,2.564670,0.287485,-179.302719,0.029659,0.000000
28.190001,11.229263,-179.302719,-0.003462,0.001149,0.029182,49.950256,2.544587,0.291821,-179.302719,0.030258,0.000000
28.550001,11.072868,-179.347198,-0.003441,0.001162,0.029512,49.254578,2.509148,0.295117,-179.347198,0.030856,0.000000
28.910002,11.673134,-179.347198,-0.003423,0.001197,0.030405,51.924694,2.645170,0.304049,-179.347198,0.031463,0.000000
29.270000,11.788193,-179.347198,-0.003402,0.001218,0.030925,52.436501,2.671242,0.309253,-179.347198,0.032061,0.000000
29.630001,12.005661,-179.391678,-0.003385,0.001245,0.031619,53.403847,2.720522,0.316191,-179.391678,0.032660,0.000000
29.990002,12.045502,-179.391678,-0.003359,0.001267,0.032183,53.581066,2.729550,0.321827,-179.391678,0.033258,0.000000
30.350002,12.299835,-179.436157,-0.003341,0.001293,0.032833,54.712399,2.787183,0.328332,-179.436157,0.033856,0.000000
30.710001,12.183655,-179.391678,-0.003311,0.001307,0.033189,54.195602,2.760855,0.331887,-179.391678,0.034464,0.000000
31.070002,12.691566,-179.525116,-0.003294,0.001337,0.033969,56.454906,2.875950,0.339692,-179.525116,0.035062,0.000000
31.430002,13.246773,-179.525116,-0.003268,0.001371,0.034819,58.924587,3.001761,0.348191,-179.525116,0.035660,0.000000
31.790001,13.138786,-179.525116,-0.003234,0.001392,0.035365,58.444241,2.977292,0.353655,-179.525116,0.036259,0.000000
32.150002,12.909409,-179.569595,-0.003225,0.001409,0.035782,57.423916,2.925314,0.357817,-179.569595,0.036857,0.000000
32.510002,13.193901,-179.569595,-0.003199,0.001434,0.036415,58.689404,2.989781,0.364148,-179.569595,0.037455,0.000000
32.870003,13.545418,-179.614075,-0.003169,0.001457,0.037005,60.253029,3.069436,0.370045,-179.614075,0.038063,0.000000
33.230003,13.732719,-179.658554,-0.003160,0.001482,0.037646,61.086185,3.111879,0.376463,-179.658554,0.038661,0.000000
33.590000,14.011627,-179.614075,-0.003139,0.001507,0.038288,62.326832,3.175080,0.382880,-179.614075,0.039259,0.000000
33.950001,14.127808,-179.703049,-0.003100,0.001529,0.038834,62.843628,3.201407,0.388344,-179.703049,0.039858,0.000000
34.310001,14.465553,-179.614075,-0.003087,0.001556,0.039511,64.345993,3.277941,0.395108,-179.614075,0.040456,0.000000
34.670002,14.394798,-179.703049,-0.003057,0.001574,0.039988,64.031258,3.261908,0.399878,-179.703049,0.041063,0.000000
35.030003,14.982780,-179.747528,-0.003040,0.001605,0.040760,66.646736,3.395146,0.407596,-179.747528,0.041662,0.000000
35.390003,14.640198,-179.747528,-0.003022,0.001620,0.041150,65.122849,3.317516,0.411499,-179.747528,0.042260,0.000000
35.750000,15.359245,-179.792007,-0.002997,0.001648,0.041870,68.321335,3.480455,0.418697,-179.792007,0.042858,0.000000
36.110001,15.436325,-179.747528,-0.002966,0.001673,0.042485,68.664200,3.497921,0.424854,-179.747528,0.043457,0.000000
36.470001,15.592354,-179.836487,-0.002936,0.001693,0.043014,69.358253,3.533278,0.430144,-179.836487,0.044064,0.000000
36.830002,16.055954,-179.925446,-0.002919,0.001721,0.043708,71.420448,3.638331,0.437082,-179.925446,0.044662,0.000000
37.190002,15.905891,-179.836487,-0.002902,0.001738,0.044142,70.752937,3.604326,0.441418,-179.836487,0.045261,0.000000
37.550003,16.411942,-179.925446,-0.002876,0.001768,0.044905,73.003960,3.718999,0.449049,-179.925446,0.045859,0.000000
37.910004,16.601852,-179.925446,-0.002850,0.001793,0.045547,73.848724,3.762033,0.455467,-179.925446,0.046457,0.000000
38.270000,16.566475,-180.014404,-0.002820,0.001813,0.046050,73.691360,3.754017,0.460497,-180.014404,0.047064,0.000000
38.630001,16.716171,-180.014404,-0.002815,0.001832,0.046544,74.357246,3.787939,0.465440,-180.014404,0.047663,0.000000
38.990002,17.418091,-179.969925,-0.002781,0.001864,0.047351,77.479538,3.946996,0.473505,-179.969925,0.048261,0.000000
39.350002,17.566299,-180.058884,-0.002764,0.001888,0.047949,78.138802,3.980580,0.479489,-180.058884,0.048859,0.000000
39.710003,17.480278,-180.014404,-0.002751,0.001908,0.048452,77.756157,3.961087,0.484519,-180.014404,0.049458,0.000000
40.070004,17.835152,-180.103378,-0.002712,0.001933,0.049094,79.334717,4.041503,0.490936,-180.103378,0.050056,0.000000
40.430000,17.990433,-180.147858,-0.002695,0.001953,0.049605,80.025444,4.076690,0.496053,-180.147858,0.050663,0.000000
40.790001,18.087990,-180.147858,-0.002682,0.001971,0.050074,80.459396,4.098797,0.500736,-180.147858,0.051262,0.000000
41.150002,18.282738,-180.192337,-0.002665,0.001995,0.050663,81.325676,4.142928,0.506633,-180.192337,0.051860,0.000000
41.510002,19.215538,-180.103378,-0.002634,0.002028,0.051513,85.474983,4.354303,0.515132,-180.103378,0.052458,0.000000
41.870003,19.606529,-180.147858,-0.002608,0.002053,0.052146,87.214195,4.442903,0.521463,-180.147858,0.053057,0.000000
42.230003,19.374908,-180.236816,-0.002600,0.002070,0.052580,86.183899,4.390417,0.525799,-180.236816,0.053664,0.000000
42.590000,19.561096,-180.192337,-0.002570,0.002091,0.053118,87.012100,4.432608,0.531176,-180.192337,0.054262,0.000000
42.950001,20.314407,-180.281296,-0.002544,0.002120,0.053837,90.362999,4.603311,0.538374,-180.281296,0.054861,0.000000
43.310001,20.862541,-180.281296,-0.002531,0.002146,0.054496,92.801216,4.727519,0.544965,-180.281296,0.055459,0.000000
43.670002,20.914299,-180.325775,-0.002509,0.002165,0.054999,93.031448,4.739248,0.549995,-180.325775,0.056057,0.000000
44.030003,20.848389,-180.325775,-0.002501,0.002182,0.055424,92.738266,4.724312,0.554244,-180.325775,0.056665,0.000000
44.390003,21.693298,-180.325775,-0.002475,0.002213,0.056205,96.496613,4.915771,0.562049,-180.325775,0.057263,0.000000
44.750004,22.054131,-180.370255,-0.002445,0.002239,0.056881,98.101669,4.997538,0.568813,-180.370255,0.057861,0.000000
45.110001,22.435814,-180.370255,-0.002427,0.002261,0.057428,99.799484,5.084028,0.574277,-180.370255,0.058460,0.000000
45.470001,22.402672,-180.459213,-0.002402,0.002281,0.057939,99.652061,5.076518,0.579394,-180.459213,0.059058,0.000000
45.830002,22.903511,-180.503693,-0.002389,0.002305,0.058546,101.879906,5.190010,0.585464,-180.503693,0.059665,0.000000
46.190002,23.572662,-180.414734,-0.002367,0.002331,0.059197,104.856438,5.341642,0.591968,-180.414734,0.060264,0.000000
46.550003,23.620697,-180.503693,-0.002350,0.002349,0.059674,105.070107,5.352526,0.596738,-180.503693,0.060862,0.000000
46.910004,24.726646,-180.503693,-0.002320,0.002380,0.060454,109.989616,5.603138,0.604543,-180.503693,0.061460,0.000000
47.270000,24.638023,-180.548187,-0.002294,0.002399,0.060931,109.595398,5.583055,0.609313,-180.548187,0.062059,0.000000
47.630001,24.528542,-180.592667,-0.002276,0.002415,0.061339,109.108398,5.558247,0.613389,-180.592667,0.062657,0.000000
47.990002,24.793671,-180.548187,-0.002264,0.002440,0.061981,110.287758,5.618326,0.619806,-180.548187,0.063264,0.000000
48.350002,26.328590,-180.592667,-0.002238,0.002468,0.062692,117.115417,5.966144,0.626917,-180.592667,0.063862,0.000000
48.710003,25.984146,-180.637146,-0.002212,0.002481,0.063021,115.583252,5.888092,0.630213,-180.637146,0.064461,0.000000
49.070004,27.786804,-180.637146,-0.002186,0.002523,0.064088,123.601875,6.296580,0.640880,-180.637146,0.065059,0.000000
49.430004,27.729462,-180.726105,-0.002182,0.002544,0.064608,123.346809,6.283586,0.646083,-180.726105,0.065658,0.000000
49.790001,27.903358,-180.681625,-0.002160,0.002559,0.065007,124.120338,6.322991,0.650072,-180.681625,0.066265,0.000000
50.150002,29.208893,-180.726105,-0.002130,0.002591,0.065822,129.927643,6.618830,0.658224,-180.726105,0.066863,0.000000
50.510002,28.979141,-180.726105,-0.002104,0.002605,0.066169,128.905655,6.566767,0.661693,-180.726105,0.067461,0.000000
50.870003,30.439583,-180.770584,-0.002095,0.002639,0.067019,135.402023,6.897708,0.670192,-180.770584,0.068060,0.000000
51.230003,30.868927,-180.770584,-0.002074,0.002662,0.067609,137.311844,6.994999,0.676089,-180.770584,0.068658,0.000000
51.590004,31.231995,-180.770584,-0.002052,0.002681,0.068095,138.926849,7.077271,0.680946,-180.770584,0.069265,0.000000
51.950001,31.924980,-180.859543,-0.002048,0.002708,0.068771,142.009399,7.234304,0.687710,-180.859543,0.069864,0.000000
52.310001,32.053078,-180.904022,-0.002026,0.002719,0.069075,142.579208,7.263331,0.690745,-180.904022,0.070462,0.000000
52.670002,34.354340,-180.859543,-0.001996,0.002766,0.070245,152.815735,7.784804,0.702453,-180.859543,0.071060,0.000000
53.030003,34.750916,-180.904022,-0.001996,0.002786,0.070757,154.579788,7.874670,0.707569,-180.904022,0.071659,0.000000
53.390003,34.954231,-180.859543,-0.001966,0.002805,0.071251,155.484192,7.920742,0.712513,-180.859543,0.072266,0.000000
53.750004,35.415230,-180.992996,-0.001949,0.002823,0.071711,157.534805,8.025206,0.717109,-180.992996,0.072864,0.000000
54.110004,36.197205,-180.948502,-0.001923,0.002848,0.072335,161.013214,8.202404,0.723353,-180.948502,0.073463,0.000000
54.470001,37.448006,-181.037476,-0.001897,0.002874,0.072994,166.577042,8.485839,0.729944,-181.037476,0.074061,0.000000
54.830002,38.218071,-181.126434,-0.001893,0.002899,0.073645,170.002472,8.660339,0.736448,-181.126434,0.074659,0.000000
55.190002,39.207466,-180.992996,-0.001880,0.002925,0.074287,174.403519,8.884539,0.742866,-180.992996,0.075258,0.000000
55.550003,40.189041,-181.126434,-0.001867,0.002950,0.074920,178.769791,9.106967,0.749196,-181.126434,0.075865,0.000000
55.910004,40.498856,-181.126434,-0.001850,0.002966,0.075345,180.147903,9.177172,0.753446,-181.126434,0.076463,0.000000
56.270004,41.393295,-181.081955,-0.001819,0.002991,0.075978,184.126572,9.379855,0.759776,-181.081955,0.077062,0.000000
56.630001,42.406891,-181.126434,-0.001815,0.003016,0.076602,188.635269,9.609539,0.766020,-181.126434,0.077660,0.000000
56.990002,41.902328,-181.170914,-0.001794,0.003022,0.076758,186.390869,9.495203,0.767581,-181.170914,0.078258,0.000000
57.350002,44.838860,-181.170914,-0.001781,0.003067,0.077894,199.453201,10.160631,0.778942,-181.170914,0.078865,0.000000
57.710003,44.960991,-181.126434,-0.001755,0.003084,0.078328,199.996475,10.188307,0.783278,-181.126434,0.079464,0.000000
58.070004,46.309731,-181.215393,-0.001742,0.003107,0.078926,205.995972,10.493935,0.789262,-181.215393,0.080062,0.000000
58.430004,47.432060,-181.304352,-0.001725,0.003132,0.079542,210.988342,10.748259,0.795419,-181.304352,0.080661,0.000000
58.790001,48.334312,-181.304352,-0.001716,0.003154,0.080106,215.001755,10.952712,0.801056,-181.304352,0.081259,0.000000
59.150002,49.891205,-181.304352,-0.001694,0.003186,0.080912,221.927170,11.305509,0.809122,-181.304352,0.081866,0.000000
59.510002,50.910759,-181.304352,-0.001681,0.003207,0.081459,226.462372,11.536543,0.814585,-181.304352,0.082464,0.000000
59.870003,51.896057,-181.393326,-0.001664,0.003229,0.082022,230.845184,11.759814,0.820222,-181.393326,0.083063,0.000000
60.230003,53.309586,-181.393326,-0.001647,0.003254,0.082664,237.132874,12.080125,0.826640,-181.393326,0.083661,0.000000
60.590004,54.140350,-181.348831,-0.001634,0.003272,0.083115,240.828308,12.268378,0.831149,-181.348831,0.084260,0.000000
60.950005,55.627975,-181.437805,-0.001613,0.003300,0.083817,247.445587,12.605479,0.838174,-181.437805,0.084867,0.000000
61.310001,57.162521,-181.393326,-0.001604,0.003328,0.084520,254.271591,12.953213,0.845198,-181.393326,0.085465,0.000000
61.670002,57.201248,-181.437805,-0.001595,0.003340,0.084841,254.443863,12.961988,0.848407,-181.437805,0.086063,0.000000
62.030003,58.707123,-181.482285,-0.001582,0.003364,0.085456,261.142334,13.303225,0.854564,-181.482285,0.086662,0.000000
62.390003,60.351891,-181.482285,-0.001552,0.003393,0.086194,268.458618,13.675934,0.861936,-181.482285,0.087260,0.000000
62.750004,61.814575,-181.526764,-0.001544,0.003418,0.086818,274.964966,14.007383,0.868180,-181.526764,0.087867,0.000000
63.110004,63.478333,-181.571243,-0.001526,0.003443,0.087460,282.365723,14.384396,0.874597,-181.571243,0.088466,0.000000
63.470001,64.732117,-181.571243,-0.001505,0.003465,0.088015,287.942841,14.668508,0.880147,-181.571243,0.089064,0.000000
63.830002,65.747940,-181.660202,-0.001505,0.003485,0.088526,292.461456,14.898696,0.885264,-181.660202,0.089662,0.000000
64.190002,66.017914,-181.615723,-0.001483,0.003491,0.088674,293.662354,14.959873,0.886738,-181.615723,0.088891,0.000000
64.550003,64.958145,-181.615723,-0.001483,0.003492,0.088691,288.948273,14.719727,0.886912,-181.615723,294.500458,0.000000
64.910004,65.491745,-181.660202,-0.001487,0.003509,0.089116,291.321838,14.840642,0.891161,-181.660202,294.500458,0.000000
65.270004,64.749619,-181.660202,-0.001462,0.003509,0.089116,288.020691,14.672473,0.891161,-181.660202,294.500458,0.000000
65.630005,66.172073,-181.704681,-0.001444,0.003493,0.088726,294.348083,14.994805,0.887259,-181.704681,294.500458,0.000000
65.990005,65.426590,-181.704681,-0.001444,0.003494,0.088752,291.032013,14.825877,0.887519,-181.704681,294.500458,0.000000
66.350006,65.043411,-181.793640,-0.001453,0.003526,0.089567,289.327545,14.739048,0.895671,-181.793640,294.500458,0.000000
66.710007,65.215073,-181.793640,-0.001449,0.003535,0.089801,290.091125,14.777947,0.898012,-181.793640,294.500458,0.000000
67.070000,65.316360,-181.793640,-0.001423,0.003542,0.089957,290.541687,14.800900,0.899573,-181.793640,294.500458,0.000000
67.430000,65.143585,-181.927094,-0.001431,0.003546,0.090061,289.773132,14.761747,0.900614,-181.927094,294.500458,0.000000
67.790001,65.035965,-181.882614,-0.001423,0.003548,0.090131,289.294434,14.737360,0.901308,-181.882614,294.500458,0.000000
68.150002,65.035965,-181.882614,-0.001423,0.003553,0.090252,289.294434,14.737360,0.902522,-181.882614,294.500458,0.000000
68.510002,65.240768,-181.882614,-0.001423,0.003561,0.090452,290.205444,14.783769,0.904516,-181.882614,294.500458,0.000000
68.870003,65.168533,-181.927094,-0.001414,0.003561,0.090452,289.884125,14.767401,0.904516,-181.927094,294.500458,0.000000
69.230003,65.061661,-182.016052,-0.001410,0.003564,0.090530,289.408722,14.743183,0.905297,-182.016052,294.500458,0.000000
69.590004,65.296631,-181.927094,-0.001418,0.003569,0.090660,290.453918,14.796428,0.906598,-181.927094,294.500458,0.000000
69.950005,65.149170,-181.971573,-0.001406,0.003571,0.090712,289.797974,14.763013,0.907118,-181.971573,294.500458,0.000000
70.310005,64.985321,-182.060532,-0.001401,0.003572,0.090720,289.069153,14.725884,0.907205,-182.060532,294.500458,0.000000
70.670006,65.008041,-182.016052,-0.001397,0.003575,0.090807,289.170197,14.731032,0.908072,-182.016052,294.500458,0.000000
71.030006,65.216934,-182.105011,-0.001406,0.003583,0.090998,290.099426,14.778368,0.909980,-182.105011,294.500458,0.000000
71.390007,65.225128,-182.105011,-0.001397,0.003582,0.090972,290.135864,14.780226,0.909720,-182.105011,294.500458,0.000000
71.750000,65.024429,-182.105011,-0.001397,0.003582,0.090981,289.243103,14.734746,0.909806,-182.105011,294.500458,0.000000
72.110001,64.817749,-182.149490,-0.001401,0.003582,0.090981,288.323761,14.687912,0.909806,-182.149490,294.500458,0.000000
72.470001,64.619278,-182.105011,-0.001388,0.003582,0.090981,287.440918,14.642938,0.909806,-182.105011,294.500458,0.000000
72.830002,65.987000,-182.238449,-0.001401,0.003587,0.091111,293.524841,14.952868,0.911107,-182.238449,294.500458,0.000000
73.190002,65.743851,-182.193970,-0.001384,0.003587,0.091111,292.443268,14.897769,0.911107,-182.193970,294.500458,0.000000
73.550003,65.512970,-182.282944,-0.001380,0.003587,0.091111,291.416260,14.845451,0.911107,-182.282944,294.500458,0.000000
73.910004,65.270187,-182.238449,-0.001371,0.003587,0.091111,290.336304,14.790436,0.911107,-182.238449,294.500458,0.000000
74.270004,65.062027,-182.282944,-0.001384,0.003587,0.091111,289.410339,14.743266,0.911107,-182.282944,294.500458,0.000000
74.630005,64.868393,-182.327423,-0.001371,0.003587,0.091111,288.549011,14.699388,0.911107,-182.327423,294.500458,0.000000
74.990005,64.711258,-182.282944,-0.001371,0.003587,0.091111,287.850037,14.663780,0.911107,-182.282944,294.500458,0.000000
75.350006,66.328094,-182.371902,-0.001375,0.003592,0.091232,295.042114,15.030161,0.912321,-182.371902,294.500458,0.000000
75.710007,66.116211,-182.327423,-0.001371,0.003592,0.091232,294.099609,14.982148,0.912321,-182.327423,294.500458,0.000000
76.070007,65.916992,-182.416382,-0.001358,0.003592,0.091232,293.213440,14.937003,0.912321,-182.416382,294.500458,0.000000
76.430000,65.756882,-182.416382,-0.001367,0.003592,0.091232,292.501221,14.900723,0.912321,-182.416382,294.500458,0.000000
76.790001,65.586334,-182.371902,-0.001362,0.003592,0.091232,291.742584,14.862076,0.912321,-182.371902,294.500458,0.000000
77.150002,65.419144,-182.505341,-0.001362,0.003592,0.091232,290.998871,14.824189,0.912321,-182.505341,294.500458,0.000000
77.510002,65.270187,-182.505341,-0.001371,0.003592,0.091241,290.336304,14.790436,0.912408,-182.505341,294.500458,0.000000
77.870003,65.161453,-182.416382,-0.001350,0.003602,0.091501,289.852631,14.765797,0.915010,-182.416382,294.500458,0.000000
78.230003,65.313004,-182.594299,-0.001362,0.003612,0.091752,290.526764,14.800138,0.917525,-182.594299,294.500458,0.000000
78.590004,65.269821,-182.505341,-0.001358,0.003612,0.091752,290.334656,14.790353,0.917525,-182.505341,294.500458,0.000000
78.950005,65.191620,-182.638779,-0.001358,0.003613,0.091770,289.986816,14.772633,0.917698,-182.638779,294.500458,0.000000
79.310005,65.095551,-182.638779,-0.001367,0.003613,0.091778,289.559479,14.750862,0.917785,-182.638779,294.500458,0.000000
79.670006,65.006180,-182.594299,-0.001341,0.003613,0.091778,289.161926,14.730611,0.917785,-182.594299,294.500458,0.000000
80.030006,65.101501,-182.683273,-0.001358,0.003617,0.091865,289.585937,14.752212,0.918652,-182.683273,294.500458,0.000000
80.390007,65.029633,-182.638779,-0.001362,0.003617,0.091865,289.266266,14.735926,0.918652,-182.638779,294.500458,0.000000
80.750008,64.968201,-182.727753,-0.001354,0.003617,0.091865,288.992981,14.722005,0.918652,-182.727753,294.500458,0.000000
81.110001,65.615372,-182.727753,-0.001354,0.003626,0.092091,291.871765,14.868656,0.920907,-182.727753,294.500458,0.000000
81.470001,65.592667,-182.683273,-0.001354,0.003626,0.092091,291.770752,14.863511,0.920907,-182.683273,294.500458,0.000000
81.830002,65.522659,-182.772232,-0.001350,0.003626,0.092091,291.459351,14.847647,0.920907,-182.772232,294.500458,0.000000
82.190002,65.438126,-182.727753,-0.001354,0.003626,0.092091,291.083313,14.828491,0.920907,-182.727753,294.500458,0.000000
82.550003,65.330887,-182.727753,-0.001354,0.003626,0.092099,290.606293,14.804191,0.920994,-182.727753,294.500458,0.000000
82.910004,65.276154,-182.816711,-0.001345,0.003626,0.092099,290.362823,14.791788,0.920994,-182.816711,294.500458,0.000000
83.270004,65.200562,-182.816711,-0.001345,0.003626,0.092099,290.026581,14.774658,0.920994,-182.816711,294.500458,0.000000
83.630005,65.145447,-182.950150,-0.001350,0.003627,0.092125,289.781433,14.762170,0.921254,-182.950150,294.500458,0.000000
83.990005,65.270935,-182.861191,-0.001358,0.003631,0.092229,290.339630,14.790605,0.922294,-182.861191,294.500458,0.000000
84.350006,65.314133,-182.950150,-0.001354,0.003631,0.092229,290.531769,14.800394,0.922294,-182.950150,294.500458,0.000000
84.710007,65.276520,-182.905670,-0.001341,0.003631,0.092229,290.364471,14.791870,0.922294,-182.905670,294.500458,0.000000
85.070007,65.234436,-182.950150,-0.001345,0.003631,0.092229,290.177277,14.782334,0.922294,-182.950150,294.500458,0.000000
85.430000,65.162567,-182.950150,-0.001341,0.003631,0.092229,289.857574,14.766049,0.922294,-182.950150,294.500458,0.000000
85.790001,65.168152,-182.950150,-0.001350,0.003632,0.092264,289.882416,14.767315,0.922641,-182.950150,294.500458,0.000000
86.150002,65.108948,-183.039108,-0.001332,0.003632,0.092264,289.619049,14.753899,0.922641,-183.039108,294.500458,0.000000
86.510002,65.044159,-182.950150,-0.001350,0.003632,0.092264,289.330872,14.739217,0.922641,-182.950150,294.500458,0.000000
86.870003,65.496216,-182.994629,-0.001328,0.003639,0.092420,291.341705,14.841655,0.924202,-182.994629,294.500458,0.000000
87.230003,65.480957,-183.128082,-0.001345,0.003639,0.092420,291.273834,14.838197,0.924202,-183.128082,294.500458,0.000000
87.590004,65.439987,-183.083588,-0.001350,0.003639,0.092420,291.091614,14.828914,0.924202,-183.083588,294.500458,0.000000
87.950005,65.370361,-183.128082,-0.001332,0.003639,0.092420,290.781891,14.813136,0.924202,-183.128082,294.500458,0.000000
88.310005,65.331635,-183.128082,-0.001345,0.003639,0.092420,290.609619,14.804359,0.924202,-183.128082,294.500458,0.000000
88.670006,65.271683,-183.172562,-0.001341,0.003639,0.092420,290.342957,14.790774,0.924202,-183.172562,294.500458,0.000000
89.030006,65.221786,-183.217041,-0.001345,0.003639,0.092420,290.121002,14.779469,0.924202,-183.217041,294.500458,0.000000
89.390007,65.148056,-183.217041,-0.001350,0.003639,0.092429,289.793030,14.762760,0.924289,-183.217041,294.500458,0.000000
89.750008,65.276520,-183.217041,-0.001358,0.003642,0.092507,290.364471,14.791870,0.925070,-183.217041,294.500458,0.000000
90.110001,65.280243,-183.306000,-0.001350,0.003642,0.092507,290.381012,14.792715,0.925070,-183.306000,294.500458,0.000000
90.470001,65.241882,-183.217041,-0.001328,0.003642,0.092507,290.210388,14.784021,0.925070,-183.217041,294.500458,0.000000
90.830002,65.183792,-183.261520,-0.001341,0.003642,0.092507,289.951996,14.770859,0.925070,-183.261520,294.500458,0.000000
91.190002,65.138000,-183.306000,-0.001337,0.003642,0.092507,289.748291,14.760482,0.925070,-183.306000,294.500458,0.000000
91.550003,65.060547,-183.350479,-0.001337,0.003642,0.092507,289.403778,14.742930,0.925070,-183.350479,294.500458,0.000000
91.910004,65.546112,-183.394958,-0.001328,0.003650,0.092706,291.563660,14.852961,0.927064,-183.394958,294.500458,0.000000
92.270004,65.613144,-183.350479,-0.001337,0.003650,0.092698,291.861847,14.868151,0.926978,-183.350479,294.500458,0.000000
92.630005,65.607178,-183.439438,-0.001341,0.003650,0.092698,291.835297,14.866799,0.926978,-183.439438,294.500458,0.000000
92.990005,65.581116,-183.394958,-0.001337,0.003650,0.092698,291.719360,14.860893,0.926978,-183.394958,294.500458,0.000000
93.350006,65.550583,-183.483917,-0.001337,0.003650,0.092698,291.583557,14.853974,0.926978,-183.483917,294.500458,0.000000
93.710007,65.508133,-183.528397,-0.001337,0.003650,0.092698,291.394714,14.844355,0.926978,-183.528397,294.500458,0.000000
94.070007,65.465683,-183.572891,-0.001311,0.003650,0.092698,291.205902,14.834736,0.926978,-183.572891,294.500458,0.000000
94.430008,65.402756,-183.572891,-0.001319,0.003650,0.092698,290.925995,14.820477,0.926978,-183.572891,294.500458,0.000000
94.790001,65.362167,-183.483917,-0.001337,0.003650,0.092706,290.745453,14.811279,0.927064,-183.483917,294.500458,0.000000
95.150002,65.314499,-183.617371,-0.001328,0.003650,0.092706,290.533386,14.800477,0.927064,-183.617371,294.500458,0.000000
95.510002,65.269073,-183.572891,-0.001328,0.003650,0.092706,290.331329,14.790184,0.927064,-183.572891,294.500458,0.000000
95.870003,65.236679,-183.572891,-0.001341,0.003651,0.092724,290.187256,14.782843,0.927238,-183.572891,294.500458,0.000000
96.230003,65.203537,-183.661850,-0.001332,0.003651,0.092724,290.039825,14.775332,0.927238,-183.661850,294.500458,0.000000
96.590004,65.180450,-183.706329,-0.001337,0.003651,0.092724,289.937134,14.770102,0.927238,-183.706329,294.500458,0.000000
96.950005,65.121979,-183.661850,-0.001332,0.003651,0.092724,289.677032,14.756851,0.927238,-183.661850,294.500458,0.000000
97.310005,65.095917,-183.750809,-0.001332,0.003655,0.092837,289.561096,14.750946,0.928365,-183.750809,294.500458,0.000000
97.670006,65.430313,-183.706329,-0.001337,0.003656,0.092854,291.048584,14.826720,0.928539,-183.706329,294.500458,0.000000
98.030006,65.435898,-183.839767,-0.001337,0.003656,0.092854,291.073425,14.827986,0.928539,-183.839767,294.500458,0.000000
98.390007,65.383759,-183.750809,-0.001337,0.003656,0.092854,290.841492,14.816172,0.928539,-183.750809,294.500458,0.000000
98.750008,65.363647,-183.795288,-0.001328,0.003656,0.092854,290.752014,14.811614,0.928539,-183.795288,294.500458,0.000000
99.110008,65.321198,-183.795288,-0.001341,0.003656,0.092854,290.563202,14.801995,0.928539,-183.795288,294.500458,0.000000
99.470001,65.294769,-183.839767,-0.001337,0.003656,0.092854,290.445648,14.796006,0.928539,-183.839767,294.500458,0.000000
99.830002,65.264236,-183.839767,-0.001319,0.003656,0.092854,290.309814,14.789087,0.928539,-183.839767,294.500458,0.000000
100.190002,65.241150,-183.884247,-0.001337,0.003656,0.092854,290.207123,14.783856,0.928539,-183.884247,294.500458,0.000000
100.550003,65.208374,-183.884247,-0.001311,0.003656,0.092854,290.061340,14.776429,0.928539,-183.884247,294.500458,0.000000
100.910004,65.145813,-183.928726,-0.001324,0.003656,0.092854,289.783051,14.762252,0.928539,-183.928726,294.500458,0.000000
101.270004,65.236679,-183.973221,-0.001319,0.003659,0.092941,290.187256,14.782843,0.929406,-183.973221,294.500458,0.000000
101.630005,65.259018,-183.973221,-0.001328,0.003659,0.092941,290.286621,14.787905,0.929406,-183.973221,294.500458,0.000000
101.990005,65.258270,-184.017700,-0.001306,0.003659,0.092941,290.283295,14.787735,0.929406,-184.017700,294.500458,0.000000
102.350006,65.243378,-183.973221,-0.001311,0.003659,0.092941,290.217041,14.784361,0.929406,-183.973221,294.500458,0.000000
102.710007,65.197571,-184.017700,-0.001328,0.003659,0.092941,290.013275,14.773981,0.929406,-184.017700,294.500458,0.000000
103.070007,65.180069,-184.062180,-0.001311,0.003659,0.092941,289.935425,14.770015,0.929406,-184.062180,294.500458,0.000000
103.430008,65.132782,-184.106659,-0.001324,0.003659,0.092941,289.725098,14.759299,0.929406,-184.106659,294.500458,0.000000
103.790009,65.100388,-184.062180,-0.001319,0.003659,0.092941,289.580994,14.751959,0.929406,-184.062180,294.500458,0.000000
104.150002,65.401642,-184.151138,-0.001319,0.003665,0.093097,290.921021,14.820224,0.930967,-184.151138,294.500458,0.000000
104.510002,65.524139,-184.195618,-0.001328,0.003665,0.093088,291.465942,14.847982,0.930880,-184.195618,294.500458,0.000000
104.870003,65.526749,-184.106659,-0.001315,0.003665,0.093079,291.477539,14.848574,0.930793,-184.106659,294.500458,0.000000
105.230003,65.503662,-184.151138,-0.001311,0.003665,0.093079,291.374847,14.843342,0.930793,-184.151138,294.500458,0.000000
105.590004,65.501053,-184.195618,-0.001319,0.003665,0.093079,291.363220,14.842751,0.930793,-184.195618,294.500458,0.000000
105.950005,65.463821,-184.240097,-0.001315,0.003665,0.093079,291.197632,14.834314,0.930793,-184.240097,294.500458,0.000000
106.310005,65.433289,-184.284576,-0.001328,0.003665,0.093079,291.061798,14.827395,0.930793,-184.284576,294.500458,0.000000
106.670006,65.400894,-184.284576,-0.001324,0.003665,0.093088,290.917694,14.820054,0.930880,-184.284576,294.500458,0.000000
107.030006,65.364395,-184.373535,-0.001319,0.003665,0.093088,290.755341,14.811783,0.930880,-184.373535,294.500458,0.000000
107.390007,65.333862,-184.329056,-0.001315,0.003665,0.093088,290.619537,14.804865,0.930880,-184.329056,294.500458,0.000000
107.750008,65.314880,-184.418030,-0.001319,0.003665,0.093088,290.535095,14.800563,0.930880,-184.418030,294.500458,0.000000
108.110008,65.280991,-184.373535,-0.001319,0.003665,0.093088,290.384338,14.792884,0.930880,-184.373535,294.500458,0.000000
108.470009,65.273163,-184.418030,-0.001315,0.003665,0.093088,290.349518,14.791110,0.930880,-184.418030,294.500458,0.000000
108.830002,65.247467,-184.506989,-0.001332,0.003665,0.093088,290.235229,14.785287,0.930880,-184.506989,294.500458,0.000000
109.190002,65.231827,-184.462509,-0.001315,0.003666,0.093105,290.165649,14.781743,0.931053,-184.462509,294.500458,0.000000
109.550003,65.204651,-184.551468,-0.001328,0.003666,0.093105,290.044769,14.775585,0.931053,-184.551468,294.500458,0.000000
109.910004,65.184921,-184.462509,-0.001311,0.003666,0.093105,289.957001,14.771114,0.931053,-184.462509,294.500458,0.000000
110.270004,65.210602,-184.551468,-0.001311,0.003667,0.093140,290.071259,14.776934,0.931400,-184.551468,294.500458,0.000000
110.630005,65.194229,-184.595947,-0.001319,0.003667,0.093140,289.998413,14.773223,0.931400,-184.595947,294.500458,0.000000
110.990005,65.186035,-184.551468,-0.001311,0.003667,0.093149,289.961975,14.771367,0.931487,-184.551468,294.500458,0.000000
111.350006,65.260513,-184.684906,-0.001315,0.003669,0.093201,290.293274,14.788243,0.932007,-184.684906,294.500458,0.000000
111.710007,65.279495,-184.640427,-0.001311,0.003669,0.093201,290.377686,14.792545,0.932007,-184.640427,294.500458,0.000000
112.070007,65.274658,-184.595947,-0.001311,0.003669,0.093201,290.356171,14.791450,0.932007,-184.595947,294.500458,0.000000
112.430008,65.268692,-184.684906,-0.001315,0.003669,0.093201,290.329651,14.790096,0.932007,-184.684906,294.500458,0.000000
112.790009,65.252686,-184.640427,-0.001311,0.003669,0.093201,290.258453,14.786469,0.932007,-184.640427,294.500458,0.000000
113.150009,65.243744,-184.773865,-0.001324,0.003669,0.093201,290.218658,14.784444,0.932007,-184.773865,294.500458,0.000000
113.510002,65.218430,-184.773865,-0.001324,0.003669,0.093201,290.106049,14.778708,0.932007,-184.773865,294.500458,0.000000
113.870003,65.185287,-184.818344,-0.001315,0.003669,0.093201,289.958649,14.771197,0.932007,-184.818344,294.500458,0.000000
114.230003,65.165558,-184.729385,-0.001315,0.003669,0.093201,289.870880,14.766726,0.932007,-184.729385,294.500458,0.000000
114.590004,65.179703,-184.773865,-0.001315,0.003670,0.093227,289.933807,14.769932,0.932268,-184.773865,294.500458,0.000000
114.950005,65.158844,-184.862839,-0.001319,0.003670,0.093227,289.841003,14.765205,0.932268,-184.862839,294.500458,0.000000
115.310005,65.151779,-184.773865,-0.001315,0.003670,0.093227,289.809601,14.763604,0.932268,-184.773865,294.500458,0.000000
115.670006,65.122360,-184.862839,-0.001315,0.003671,0.093244,289.678711,14.756938,0.932441,-184.862839,294.500458,0.000000
116.030006,65.132416,-184.862839,-0.001319,0.003671,0.093244,289.723450,14.759216,0.932441,-184.862839,294.500458,0.000000
116.390007,65.132416,-184.907318,-0.001319,0.003672,0.093270,289.723450,14.759216,0.932701,-184.907318,294.500458,0.000000
116.750008,65.128693,-184.996277,-0.001311,0.003672,0.093270,289.706879,14.758373,0.932701,-184.996277,294.500458,0.000000
117.110008,65.120499,-184.907318,-0.001302,0.003672,0.093270,289.670441,14.756516,0.932701,-184.907318,294.500458,0.000000
117.470009,65.186783,-184.996277,-0.001315,0.003674,0.093313,289.965302,14.771536,0.933135,-184.996277,294.500458,0.000000
117.830002,65.211349,-184.996277,-0.001302,0.003674,0.093313,290.074585,14.777102,0.933135,-184.996277,294.500458,0.000000
118.190002,65.220657,-185.040756,-0.001315,0.003674,0.093313,290.115967,14.779213,0.933135,-185.040756,294.500458,0.000000
118.550003,65.224014,-185.040756,-0.001306,0.003674,0.093313,290.130920,14.779973,0.933135,-185.040756,294.500458,0.000000
118.910004,65.187515,-185.040756,-0.001302,0.003674,0.093313,289.968536,14.771702,0.933135,-185.040756,294.500458,0.000000
119.270004,65.175980,-185.129715,-0.001298,0.003674,0.093313,289.917236,14.769088,0.933135,-185.129715,294.500458,0.000000
119.630005,65.153641,-185.218674,-0.001315,0.003674,0.093313,289.817871,14.764026,0.933135,-185.218674,294.500458,0.000000
119.990005,65.126831,-185.129715,-0.001306,0.003674,0.093313,289.698608,14.757951,0.933135,-185.129715,294.500458,0.000000
120.350006,65.120865,-185.263168,-0.001311,0.003674,0.093331,289.672089,14.756599,0.933308,-185.263168,294.500458,0.000000
120.710007,65.120117,-185.174194,-0.001315,0.003674,0.093331,289.668762,14.756430,0.933308,-185.174194,294.500458,0.000000
121.070007,65.107834,-185.218674,-0.001306,0.003674,0.093331,289.614105,14.753646,0.933308,-185.218674,294.500458,0.000000
121.430008,65.079163,-185.263168,-0.001315,0.003675,0.093340,289.486572,14.747149,0.933395,-185.263168,294.500458,0.000000
121.790009,65.061295,-185.352127,-0.001293,0.003675,0.093340,289.407104,14.743100,0.933395,-185.352127,294.500458,0.000000
122.150009,65.050110,-185.352127,-0.001306,0.003675,0.093340,289.357330,14.740566,0.933395,-185.352127,294.500458,0.000000
122.510002,65.051239,-185.352127,-0.001302,0.003675,0.093348,289.362366,14.740822,0.933482,-185.352127,294.500458,0.000000
122.870003,65.051971,-185.352127,-0.001306,0.003676,0.093366,289.365631,14.740987,0.933655,-185.352127,294.500458,0.000000
123.230003,65.038574,-185.352127,-0.001315,0.003676,0.093366,289.306030,14.737952,0.933655,-185.352127,294.500458,0.000000
123.590004,65.061661,-185.307648,-0.001302,0.003676,0.093366,289.408722,14.743183,0.933655,-185.307648,294.500458,0.000000
123.950005,65.040070,-185.441086,-0.001315,0.003676,0.093366,289.312683,14.738291,0.933655,-185.441086,294.500458,0.000000
124.310005,65.040070,-185.441086,-0.001293,0.003676,0.093366,289.312683,14.738291,0.933655,-185.441086,294.500458,0.000000
124.670006,65.022186,-185.485565,-0.001306,0.003676,0.093374,289.233124,14.734238,0.933742,-185.485565,1681.640747,0.000000
125.030006,65.037079,-185.441086,-0.001311,0.003669,0.093183,289.299377,14.737613,0.931834,-185.441086,0.093105,0.000000
125.390007,64.970795,-185.441086,-0.001298,0.003655,0.092828,289.004517,14.722592,0.928278,-185.441086,0.092507,0.000000
125.750008,64.882919,-185.485565,-0.001302,0.003636,0.092351,288.613647,14.702680,0.923509,-185.485565,0.091909,0.000000
126.110008,64.819244,-185.530045,-0.001302,0.003615,0.091813,288.330414,14.688251,0.918132,-185.530045,0.091310,0.000000
126.470009,64.789078,-185.574524,-0.001285,0.003591,0.091215,288.196198,14.681415,0.912148,-185.574524,0.090703,0.000000
126.830009,64.749237,-185.574524,-0.001285,0.003567,0.090590,288.018982,14.672387,0.905904,-185.574524,0.090105,0.000000
127.190002,64.739929,-185.619003,-0.001281,0.003548,0.090113,287.977600,14.670278,0.901134,-185.619003,0.089506,0.000000
127.550003,64.665085,-185.619003,-0.001293,0.003520,0.089420,287.644653,14.653317,0.894196,-185.619003,0.088908,0.000000
127.910004,64.645721,-185.663483,-0.001289,0.003497,0.088813,287.558533,14.648930,0.888126,-185.663483,0.088310,0.000000
128.270004,64.601410,-185.752457,-0.001285,0.003476,0.088292,287.361420,14.638888,0.882922,-185.752457,0.087703,0.000000
128.630005,64.480759,-185.663483,-0.001293,0.003454,0.087720,286.824738,14.611548,0.877199,-185.663483,0.087104,0.000000
128.990005,64.153442,-185.663483,-0.001293,0.003432,0.087174,285.368774,14.537378,0.871735,-185.663483,0.086506,0.000000
129.350006,63.443695,-185.796936,-0.001289,0.003413,0.086679,282.211639,14.376547,0.866792,-185.796936,0.085907,0.000000
129.710007,62.309082,-185.841415,-0.001281,0.003385,0.085985,277.164642,14.119440,0.859854,-185.841415,0.085309,0.000000
130.070007,61.244843,-185.841415,-0.001281,0.003367,0.085517,272.430664,13.878280,0.855171,-185.841415,0.084711,0.000000
130.430008,60.001488,-185.796936,-0.001276,0.003345,0.084953,266.899933,13.596532,0.849534,-185.796936,0.084104,0.000000
130.790009,59.057152,-185.885895,-0.001263,0.003335,0.084711,262.699341,13.382542,0.847106,-185.885895,0.083505,0.000000
131.150009,56.632263,-185.930374,-0.001276,0.003305,0.083939,251.912888,12.833055,0.839388,-185.930374,0.082907,0.000000
131.510010,54.527618,-185.841415,-0.001263,0.003276,0.083219,242.550964,12.356135,0.832190,-185.841415,0.082308,0.000000
131.870010,52.061020,-185.974854,-0.001263,0.003253,0.082638,231.578979,11.797195,0.826379,-185.974854,0.081710,0.000000
132.230011,50.141068,-185.885895,-0.001263,0.003235,0.082170,223.038605,11.362128,0.821696,-185.885895,0.081103,0.000000
132.590012,47.633881,-185.974854,-0.001268,0.003209,0.081519,211.886078,10.793992,0.815192,-185.974854,0.080505,0.000000
132.950012,45.184044,-185.930374,-0.001268,0.003189,0.080990,200.988663,10.238851,0.809902,-185.930374,0.079906,0.000000
133.310013,42.869751,-186.019333,-0.001263,0.003169,0.080487,190.694183,9.714424,0.804872,-186.019333,0.079308,0.000000
133.670013,39.172836,-186.063812,-0.001268,0.003133,0.079577,174.249481,8.876692,0.795766,-186.063812,0.078709,0.000000
134.029999,36.817207,-186.108292,-0.001259,0.003111,0.079030,163.771118,8.342898,0.790303,-186.108292,0.078102,0.000000
134.389999,34.062767,-186.108292,-0.001250,0.003087,0.078406,151.518753,7.718733,0.784059,-186.108292,0.077504,0.000000
134.750000,32.269424,-186.108292,-0.001272,0.003067,0.077903,143.541565,7.312356,0.779029,-186.108292,0.076906,0.000000
135.110001,30.178925,-186.152786,-0.001268,0.003050,0.077478,134.242554,6.838642,0.774779,-186.152786,0.076307,0.000000
135.470001,27.121750,-186.197266,-0.001281,0.003019,0.076671,120.643570,6.145876,0.766714,-186.197266,0.075709,0.000000
135.830002,24.335281,-186.152786,-0.001263,0.002994,0.076056,108.248741,5.514453,0.760557,-186.152786,0.075102,0.000000
136.190002,21.704102,-186.286224,-0.001259,0.002966,0.075345,96.544662,4.918220,0.753446,-186.286224,0.074503,0.000000
136.550003,19.380119,-186.241745,-0.001272,0.002948,0.074868,86.207077,4.391598,0.748676,-186.241745,0.073905,0.000000
136.910004,18.459618,-186.241745,-0.001263,0.002938,0.074625,82.112480,4.183009,0.746248,-186.241745,0.073307,0.000000
137.270004,13.990776,-186.241745,-0.001272,0.002900,0.073662,62.234081,3.170355,0.736621,-186.241745,0.072708,0.000000
137.630005,11.247879,-186.241745,-0.001268,0.002873,0.072986,50.033066,2.548806,0.729857,-186.241745,0.072110,0.000000
137.990005,9.079926,-186.375183,-0.001255,0.002854,0.072500,40.389526,2.057541,0.725001,-186.375183,0.071503,0.000000
138.350006,6.241333,-186.286224,-0.001268,0.002825,0.071754,27.762836,1.414306,0.717543,-186.286224,0.070904,0.000000
138.710007,4.256584,-186.330704,-0.001255,0.002805,0.071243,18.934233,0.964556,0.712426,-186.330704,0.070306,0.000000
139.070007,1.714401,-186.375183,-0.001272,0.002786,0.070766,7.626038,0.388489,0.707656,-186.375183,0.069708,0.000000
139.430008,-0.901516,-186.375183,-0.001263,0.002758,0.070054,-4.010143,-0.204286,0.700545,-186.375183,0.069109,0.000000
139.790009,-3.188625,-186.508621,-0.001276,0.002735,0.069473,-14.183714,-0.722553,0.694735,-186.508621,0.068502,0.000000
140.150009,-0.343704,-186.375183,-0.001285,0.002708,0.068771,-1.528873,-0.077884,0.687710,-186.375183,0.067904,0.000000
140.510010,-0.146347,-186.464142,-0.001276,0.002689,0.068303,-0.650984,-0.033163,0.683027,-186.464142,0.067305,0.000000
140.870010,-0.132195,-186.508621,-0.001311,0.002664,0.067678,-0.588031,-0.029956,0.676783,-186.508621,0.066707,0.000000
141.230011,-0.066658,-186.508621,-0.001328,0.002651,0.067331,-0.296510,-0.015105,0.673314,-186.508621,0.066109,0.000000
141.590012,-0.090858,-186.508621,-0.001367,0.002614,0.066403,-0.404159,-0.020589,0.664035,-186.508621,0.065502,0.000000
141.950012,-0.069260,-186.553116,-0.001393,0.002596,0.065926,-0.308082,-0.015694,0.659265,-186.553116,0.064903,0.000000
142.310013,-0.042450,-186.597595,-0.001414,0.002576,0.065441,-0.188827,-0.009619,0.654409,-186.597595,0.064305,0.000000
142.670013,-0.077454,-186.642075,-0.001453,0.002550,0.064764,-0.344531,-0.017551,0.647644,-186.642075,0.063706,0.000000
143.030014,-0.085274,-186.597595,-0.001475,0.002523,0.064079,-0.379317,-0.019323,0.640793,-186.597595,0.063108,0.000000
143.389999,-0.087883,-186.686554,-0.001496,0.002498,0.063455,-0.390923,-0.019915,0.634549,-186.686554,0.062501,0.000000
143.750000,-0.097939,-186.686554,-0.001522,0.002476,0.062900,-0.435652,-0.022193,0.628999,-186.686554,0.061903,0.000000
144.110001,-0.063309,-186.731033,-0.001548,0.002450,0.062223,-0.281611,-0.014346,0.622234,-186.731033,0.061304,0.000000
144.470001,-0.083412,-186.731033,-0.001574,0.002426,0.061625,-0.371036,-0.018901,0.616251,-186.731033,0.060706,0.000000
144.830002,-0.068146,-186.686554,-0.001587,0.002406,0.061113,-0.303127,-0.015442,0.611134,-186.686554,0.060107,0.000000
145.190002,-0.081924,-186.775513,-0.001630,0.002380,0.060463,-0.364418,-0.018564,0.604630,-186.775513,0.059509,0.000000
145.550003,-0.058838,-186.731033,-0.001656,0.002354,0.059795,-0.261724,-0.013333,0.597952,-186.731033,0.058902,0.000000
145.910004,-0.093094,-186.819992,-0.001681,0.002331,0.059214,-0.414102,-0.021095,0.592142,-186.819992,0.058304,0.000000
146.270004,-0.083786,-186.819992,-0.001694,0.002316,0.058833,-0.372699,-0.018986,0.588326,-186.819992,0.057705,0.000000
146.630005,-0.094215,-186.864471,-0.001707,0.002292,0.058217,-0.419091,-0.021350,0.582169,-186.864471,0.057107,0.000000
146.990005,-0.079315,-186.908951,-0.001750,0.002271,0.057679,-0.352812,-0.017973,0.576792,-186.908951,0.056508,0.000000
147.350006,-0.068146,-186.908951,-0.001772,0.002238,0.056838,-0.303127,-0.015442,0.568380,-186.908951,0.055901,0.000000
147.710007,-0.091980,-186.908951,-0.001785,0.002218,0.056344,-0.409147,-0.020843,0.563437,-186.908951,0.055303,0.000000
148.070007,-0.088257,-186.908951,-0.001815,0.002193,0.055711,-0.392586,-0.019999,0.557106,-186.908951,0.054705,0.000000
148.430008,-0.097939,-186.997925,-0.001845,0.002168,0.055078,-0.435652,-0.022193,0.550775,-186.997925,0.054106,0.000000
148.790009,-0.092720,-186.997925,-0.001880,0.002148,0.054557,-0.412439,-0.021011,0.545572,-186.997925,0.053508,0.000000
149.150009,-0.072617,-187.042404,-0.001893,0.002122,0.053898,-0.323015,-0.016455,0.538981,-187.042404,0.053794,0.000000
149.300003,-0.063309,-187.042404,-0.001906,0.002122,0.053907,-0.281611,-0.014346,0.539067,-187.042404,0.053794,0.000000