File: Data/compression 20/AutoNoHeating-17-20-reverse-2-3_09112024_171142.csv
Time (sec),S:Load (lbs),S:HL1 (DIM),S:LVDT (in),S:Position (in),Ch:Position (mm),Ch:Load (N),Ch:Stress (MPa),Ch:Strain (mm/mm),Ch:HL1 (DIM),Set Point (),Cycles ()
0.110000,-0.043571,-201.409744,-0.009964,-0.005576,-0.141635,-0.193816,-0.009873,-1.416353,-201.409744,-0.141427,0.000000
0.470000,-0.031654,-201.454224,-0.009960,-0.005514,-0.140057,-0.140806,-0.007173,-1.400570,-201.454224,-0.139380,0.000000
0.830000,-0.027557,-201.454224,-0.009843,-0.005301,-0.134645,-0.122581,-0.006245,-1.346455,-201.454224,-0.133397,0.000000
1.190000,-0.045059,-201.454224,-0.009593,-0.005061,-0.128558,-0.200433,-0.010211,-1.285575,-201.454224,-0.127395,0.000000
1.550000,-0.081551,-201.543182,-0.009386,-0.004836,-0.122834,-0.362755,-0.018480,-1.228338,-201.543182,-0.121394,0.000000
1.910000,-0.113579,-201.498703,-0.009110,-0.004588,-0.116538,-0.505224,-0.025737,-1.165378,-201.498703,-0.115393,0.000000
2.270000,-0.083412,-201.587677,-0.008882,-0.004350,-0.110485,-0.371036,-0.018901,-1.104846,-201.587677,-0.109409,0.000000
2.630000,-0.046173,-201.543182,-0.008636,-0.004117,-0.104579,-0.205388,-0.010463,-1.045787,-201.543182,-0.103408,0.000000
2.990000,-0.033890,-201.587677,-0.008386,-0.003887,-0.098725,-0.150749,-0.007680,-0.987250,-201.587677,-0.097407,0.000000
3.350000,-0.039848,-201.632156,-0.008149,-0.003648,-0.092663,-0.177254,-0.009030,-0.926631,-201.632156,-0.091406,0.000000
3.710000,-0.065170,-201.587677,-0.007925,-0.003411,-0.086627,-0.289892,-0.014768,-0.866272,-201.587677,-0.085404,0.000000
4.070000,-0.085274,-201.587677,-0.007657,-0.003175,-0.080635,-0.379317,-0.019323,-0.806346,-201.587677,-0.079421,0.000000
4.430000,-0.096443,-201.632156,-0.007407,-0.002936,-0.074564,-0.429001,-0.021854,-0.745641,-201.632156,-0.073419,0.000000
4.790000,-0.035004,-201.676636,-0.007179,-0.002704,-0.068684,-0.155704,-0.007932,-0.686843,-201.676636,-0.067418,0.000000
5.150000,-0.009682,-201.765594,-0.006942,-0.002470,-0.062726,-0.043066,-0.002194,-0.627264,-201.765594,-0.061417,0.000000
5.510000,-0.036865,-201.676636,-0.006709,-0.002235,-0.056777,-0.163985,-0.008354,-0.567773,-201.676636,-0.055416,0.000000
5.870000,-0.033142,-201.765594,-0.006446,-0.001992,-0.050585,-0.147423,-0.007510,-0.505853,-201.765594,-0.049432,0.000000
6.230000,-0.064796,-201.721115,-0.006226,-0.001761,-0.044740,-0.288229,-0.014683,-0.447402,-201.721115,-0.043431,0.000000
6.590000,-0.083038,-201.765594,-0.005967,-0.001522,-0.038670,-0.369373,-0.018817,-0.386696,-201.765594,-0.037429,0.000000
6.950000,-0.056229,-201.854553,-0.005730,-0.001286,-0.032677,-0.250117,-0.012742,-0.326771,-201.854553,-0.031428,0.000000
7.310000,-0.008942,-201.810074,-0.005493,-0.001053,-0.026737,-0.039774,-0.002026,-0.267366,-201.810074,-0.025427,0.000000
7.670001,-0.027557,-201.810074,-0.005260,-0.000821,-0.020865,-0.122581,-0.006245,-0.208655,-201.810074,-0.019443,0.000000
8.030001,-0.043945,-201.854553,-0.005006,-0.000581,-0.014760,-0.195479,-0.009958,-0.147602,-201.854553,-0.013442,0.000000
8.390000,-0.052505,-201.899033,-0.004764,-0.000344,-0.008733,-0.233556,-0.011898,-0.087330,-201.899033,-0.007441,0.000000
8.750000,-0.004097,-201.943512,-0.004536,-0.000106,-0.002688,-0.018224,-0.000928,-0.026884,-201.943512,-0.001440,0.000000
9.110001,0.212997,-201.943512,-0.004290,-0.000004,-0.000113,0.947460,0.048266,-0.001127,-201.943512,-0.000017,0.000000
9.470000,0.138145,-201.987991,-0.004294,-0.000010,-0.000260,0.614502,0.031304,-0.002602,-201.987991,-0.000017,0.000000
9.830001,0.166824,-201.987991,-0.004299,-0.000010,-0.000260,0.742072,0.037803,-0.002602,-201.987991,0.000373,0.000000
10.190001,0.164215,-202.032486,-0.004299,-0.000010,-0.000260,0.730465,0.037212,-0.002602,-202.032486,0.000971,0.000000
10.550000,0.360458,-202.076965,-0.004268,0.000023,0.000581,1.603399,0.081681,0.005810,-202.076965,0.001570,0.000000
10.910001,0.585739,-202.076965,-0.004264,0.000045,0.001153,2.605498,0.132730,0.011534,-202.076965,0.002168,0.000000
11.270000,0.955879,-202.032486,-0.004243,0.000072,0.001830,4.251963,0.216605,0.018298,-202.032486,0.002766,0.000000
11.630000,1.175209,-202.032486,-0.004217,0.000091,0.002307,5.227591,0.266306,0.023068,-202.032486,0.003374,0.000000
11.990001,1.660408,-202.121445,-0.004186,0.000122,0.003105,7.385864,0.376254,0.031047,-202.121445,0.003972,0.000000
12.350000,1.972084,-202.210403,-0.004161,0.000144,0.003668,8.772268,0.446881,0.036684,-202.210403,0.004570,0.000000
12.710001,2.316528,-202.165924,-0.004143,0.000165,0.004197,10.304433,0.524933,0.041974,-202.165924,0.005169,0.000000
13.070001,2.644218,-202.254883,-0.004126,0.000181,0.004588,11.762071,0.599188,0.045876,-202.254883,0.005767,0.000000
13.430000,3.087708,-202.210403,-0.004100,0.000206,0.005221,13.734809,0.699685,0.052207,-202.210403,0.006374,0.000000
13.790001,3.667496,-202.254883,-0.004087,0.000238,0.006045,16.313835,0.831066,0.060446,-202.254883,0.006972,0.000000
14.150001,4.033165,-202.299362,-0.004070,0.000262,0.006660,17.940414,0.913928,0.066603,-202.299362,0.007571,0.000000
14.510000,4.356758,-202.299362,-0.004049,0.000281,0.007129,19.379827,0.987256,0.071286,-202.299362,0.008169,0.000000
14.870001,4.825577,-202.343842,-0.004018,0.000304,0.007718,21.465237,1.093491,0.077183,-202.343842,0.008768,0.000000
15.230000,5.108200,-202.299362,-0.004010,0.000321,0.008161,22.722408,1.157535,0.081606,-202.299362,0.009366,0.000000
15.590001,5.437378,-202.343842,-0.003971,0.000343,0.008707,24.186665,1.232127,0.087069,-202.343842,0.009973,0.000000
15.950001,6.109512,-202.388321,-0.003967,0.000380,0.009652,27.176468,1.384435,0.096522,-202.388321,0.010571,0.000000
16.310001,6.464012,-202.343842,-0.003923,0.000404,0.010259,28.753363,1.464766,0.102593,-202.343842,0.011170,0.000000
16.670000,6.543701,-202.477295,-0.003919,0.000421,0.010702,29.107836,1.482824,0.107016,-202.477295,0.011768,0.000000
17.030001,6.809204,-202.388321,-0.003893,0.000440,0.011170,30.288853,1.542988,0.111699,-202.388321,0.012367,0.000000
17.390001,7.370735,-202.477295,-0.003863,0.000471,0.011968,32.786667,1.670232,0.119677,-202.477295,0.012974,0.000000
17.750000,7.688370,-202.477295,-0.003863,0.000498,0.012653,34.199577,1.742210,0.126528,-202.477295,0.013572,0.000000
18.110001,7.695076,-202.477295,-0.003837,0.000515,0.013078,34.229408,1.743729,0.130778,-202.477295,0.014170,0.000000
18.470001,7.867111,-202.610733,-0.003816,0.000533,0.013537,34.994659,1.782713,0.135374,-202.610733,0.014769,0.000000
18.830002,8.349335,-202.521774,-0.003798,0.000563,0.014301,37.139694,1.891986,0.143006,-202.521774,0.015367,0.000000
19.190001,8.441307,-202.566254,-0.003760,0.000584,0.014830,37.548809,1.912827,0.148296,-202.566254,0.015974,0.000000
19.550001,8.726173,-202.610733,-0.003751,0.000613,0.015575,38.815956,1.977379,0.155754,-202.610733,0.016573,0.000000
19.910002,8.604034,-202.655212,-0.003721,0.000625,0.015888,38.272655,1.949702,0.158876,-202.655212,0.017171,0.000000
20.270000,9.324203,-202.610733,-0.003695,0.000661,0.016781,41.476128,2.112895,0.167808,-202.610733,0.017769,0.000000
20.630001,9.297768,-202.610733,-0.003678,0.000679,0.017249,41.358536,2.106904,0.172491,-202.610733,0.018368,0.000000
20.990002,9.603859,-202.655212,-0.003660,0.000710,0.018038,42.720097,2.176265,0.180383,-202.655212,0.018975,0.000000
21.350000,9.763977,-202.699692,-0.003626,0.000736,0.018706,43.432339,2.212549,0.187061,-202.699692,0.019573,0.000000
21.710001,9.642952,-202.699692,-0.003596,0.000754,0.019157,42.893993,2.185124,0.191570,-202.699692,0.020172,0.000000
22.070002,9.731583,-202.744171,-0.003587,0.000772,0.019608,43.288242,2.205208,0.196080,-202.744171,0.020770,0.000000
22.430000,10.166885,-202.699692,-0.003574,0.000799,0.020293,45.224564,2.303849,0.202931,-202.699692,0.021368,0.000000
22.790001,10.244339,-202.788651,-0.003544,0.000822,0.020891,45.569096,2.321400,0.208915,-202.788651,0.021967,0.000000
23.150002,10.588036,-202.788651,-0.003518,0.000853,0.021655,47.097935,2.399283,0.216546,-202.788651,0.022574,0.000000
23.510000,10.624527,-202.833130,-0.003497,0.000878,0.022305,47.260258,2.407552,0.223050,-202.833130,0.023172,0.000000
23.870001,10.573143,-202.877625,-0.003471,0.000896,0.022756,47.031689,2.395908,0.227560,-202.877625,0.023771,0.000000
24.230001,10.724327,-202.833130,-0.003445,0.000916,0.023268,47.704189,2.430167,0.232677,-202.833130,0.024369,0.000000
24.590002,10.986473,-202.877625,-0.003432,0.000941,0.023892,48.870274,2.489570,0.238921,-202.877625,0.024967,0.000000
24.950001,11.299637,-202.922104,-0.003406,0.000969,0.024621,50.263294,2.560534,0.246205,-202.922104,0.025574,0.000000
25.310001,11.280647,-202.922104,-0.003380,0.000990,0.025141,50.178825,2.556231,0.251409,-202.922104,0.026173,0.000000
25.670002,11.336876,-203.011063,-0.003359,0.001014,0.025765,50.428944,2.568973,0.257653,-203.011063,0.026771,0.000000
26.030001,11.614670,-202.922104,-0.003333,0.001039,0.026398,51.664631,2.631922,0.263983,-202.922104,0.027370,0.000000
26.390001,11.759148,-203.055542,-0.003328,0.001061,0.026962,52.307301,2.664661,0.269620,-203.055542,0.027968,0.000000
26.750002,12.123329,-202.966583,-0.003298,0.001088,0.027647,53.927261,2.747186,0.276472,-202.966583,0.028575,0.000000
27.110001,12.371704,-203.011063,-0.003255,0.001115,0.028315,55.032089,2.803468,0.283149,-203.011063,0.029173,0.000000
27.470001,12.299461,-203.100021,-0.003268,0.001137,0.028887,54.710735,2.787098,0.288873,-203.100021,0.029772,0.000000
27.830002,12.394417,-203.055542,-0.003216,0.001158,0.029425,55.133118,2.808615,0.294250,-203.055542,0.030370,0.000000
28.190001,12.439476,-203.100021,-0.003199,0.001178,0.029919,55.333553,2.818825,0.299193,-203.100021,0.030969,0.000000
28.550001,12.782799,-203.055542,-0.003173,0.001202,0.030535,56.860729,2.896624,0.305350,-203.055542,0.031576,0.000000
28.910002,12.863235,-203.188980,-0.003173,0.001225,0.031116,57.218529,2.914851,0.311161,-203.188980,0.032174,0.000000
29.270000,13.295555,-203.233459,-0.003134,0.001253,0.031819,59.141582,3.012816,0.318185,-203.233459,0.032772,0.000000
29.630001,13.366684,-203.144501,-0.003104,0.001276,0.032417,59.457981,3.028934,0.324169,-203.144501,0.033371,0.000000
29.990002,13.514137,-203.233459,-0.003083,0.001302,0.033059,60.113884,3.062347,0.330586,-203.233459,0.033969,0.000000
30.350002,13.526802,-203.188980,-0.003078,0.001319,0.033501,60.170219,3.065217,0.335009,-203.188980,0.034568,0.000000
30.710001,14.023918,-203.277939,-0.003044,0.001349,0.034273,62.381504,3.177865,0.342728,-203.277939,0.035175,0.000000
31.070002,13.919281,-203.277939,-0.003027,0.001365,0.034663,61.916054,3.154154,0.346630,-203.277939,0.035773,0.000000
31.430002,14.492737,-203.277939,-0.002997,0.001394,0.035409,64.466911,3.284101,0.354088,-203.277939,0.036371,0.000000
31.790001,14.612267,-203.322433,-0.002975,0.001418,0.036007,64.998611,3.311187,0.360072,-203.322433,0.036970,0.000000
32.150002,14.620834,-203.366913,-0.002971,0.001439,0.036545,65.036720,3.313128,0.365449,-203.366913,0.037568,0.000000
32.510002,14.676315,-203.366913,-0.002940,0.001456,0.036987,65.283508,3.325701,0.369872,-203.366913,0.038175,0.000000
32.870003,15.001022,-203.411392,-0.002915,0.001481,0.037612,66.727882,3.399280,0.376116,-203.411392,0.038774,0.000000
33.230003,14.752281,-203.322433,-0.002893,0.001498,0.038037,65.621422,3.342915,0.380365,-203.322433,0.039372,0.000000
33.590000,15.825455,-203.411392,-0.002867,0.001538,0.039060,70.395142,3.586099,0.390598,-203.411392,0.039970,0.000000
33.950001,15.762527,-203.411392,-0.002837,0.001557,0.039545,70.115227,3.571840,0.395455,-203.411392,0.040569,0.000000
34.310001,15.965469,-203.455872,-0.002828,0.001579,0.040109,71.017952,3.617827,0.401092,-203.455872,0.041176,0.000000
34.670002,16.067871,-203.455872,-0.002811,0.001598,0.040577,71.473457,3.641032,0.405775,-203.455872,0.041774,0.000000
35.030003,16.868843,-203.500351,-0.002777,0.001633,0.041471,75.036362,3.822534,0.414707,-203.500351,0.042373,0.000000
35.390003,16.721756,-203.544830,-0.002751,0.001652,0.041965,74.382088,3.789204,0.419651,-203.544830,0.042971,0.000000
35.750000,16.989494,-203.544830,-0.002721,0.001676,0.042581,75.573044,3.849874,0.425808,-203.544830,0.043569,0.000000
36.110001,16.986885,-203.544830,-0.002729,0.001697,0.043110,75.561440,3.849283,0.431098,-203.544830,0.044176,0.000000
36.470001,17.007362,-203.589310,-0.002695,0.001712,0.043491,75.652527,3.853924,0.434914,-203.589310,0.044775,0.000000
36.830002,17.636299,-203.589310,-0.002673,0.001739,0.044176,78.450180,3.996443,0.441765,-203.589310,0.045373,0.000000
37.190002,18.392967,-203.678268,-0.002647,0.001774,0.045052,81.816002,4.167906,0.450524,-203.678268,0.045972,0.000000
37.550003,18.349022,-203.633789,-0.002626,0.001793,0.045538,81.620529,4.157948,0.455380,-203.633789,0.046570,0.000000
37.910004,18.549736,-203.678268,-0.002600,0.001817,0.046154,82.513344,4.203430,0.461538,-203.678268,0.047177,0.000000
38.270000,18.561279,-203.767242,-0.002591,0.001836,0.046639,82.564697,4.206046,0.466394,-203.767242,0.047775,0.000000
38.630001,19.509712,-203.722763,-0.002561,0.001866,0.047403,86.783531,4.420964,0.474026,-203.722763,0.048374,0.000000
38.990002,19.946877,-203.767242,-0.002544,0.001893,0.048070,88.728142,4.520027,0.480703,-203.767242,0.048972,0.000000
39.350002,19.564072,-203.767242,-0.002535,0.001907,0.048435,87.025337,4.433282,0.484346,-203.767242,0.049571,0.000000
39.710003,20.076462,-203.811722,-0.002496,0.001931,0.049050,89.304565,4.549391,0.490503,-203.811722,0.050169,0.000000
40.070004,20.626823,-203.767242,-0.002492,0.001959,0.049753,91.752693,4.674105,0.497527,-203.767242,0.050776,0.000000
40.430000,21.032341,-203.811722,-0.002458,0.001981,0.050316,93.556526,4.765997,0.503164,-203.811722,0.051374,0.000000
40.790001,21.264702,-203.945160,-0.002436,0.002006,0.050941,94.590118,4.818650,0.509408,-203.945160,0.051973,0.000000
41.150002,21.335075,-203.900681,-0.002406,0.002023,0.051383,94.903152,4.834597,0.513831,-203.900681,0.052571,0.000000
41.510002,22.334526,-203.900681,-0.002397,0.002056,0.052224,99.348930,5.061076,0.522243,-203.900681,0.053170,0.000000
41.870003,22.569862,-203.900681,-0.002376,0.002077,0.052745,100.395760,5.114404,0.527447,-203.900681,0.053777,0.000000
42.230003,22.721046,-203.945160,-0.002354,0.002098,0.053282,101.068260,5.148663,0.532824,-203.945160,0.054375,0.000000
42.590000,23.686241,-203.989639,-0.002333,0.002129,0.054089,105.361664,5.367379,0.540889,-203.989639,0.054973,0.000000
42.950001,23.622192,-203.900681,-0.002307,0.002150,0.054601,105.076759,5.352865,0.546005,-203.900681,0.055572,0.000000
43.310001,23.373817,-204.034119,-0.002289,0.002162,0.054913,103.971931,5.296583,0.549127,-204.034119,0.056170,0.000000
43.670002,24.229530,-204.034119,-0.002268,0.002189,0.055607,107.778336,5.490490,0.556065,-204.034119,0.056777,0.000000
44.030003,24.948952,-204.123077,-0.002251,0.002215,0.056266,110.978477,5.653513,0.562656,-204.123077,0.057376,0.000000
44.390003,25.925316,-204.078598,-0.002225,0.002246,0.057055,115.321564,5.874761,0.570548,-204.078598,0.057974,0.000000
44.750004,26.184860,-204.034119,-0.002216,0.002269,0.057644,116.476074,5.933574,0.576445,-204.034119,0.058572,0.000000
45.110001,26.258957,-204.167572,-0.002199,0.002288,0.058104,116.805672,5.950365,0.581041,-204.167572,0.059171,0.000000
45.470001,26.567284,-204.167572,-0.002177,0.002307,0.058590,118.177177,6.020233,0.585898,-204.167572,0.059778,0.000000
45.830002,27.700043,-204.123077,-0.002147,0.002337,0.059353,123.215942,6.276919,0.593529,-204.123077,0.060376,0.000000
46.190002,27.646416,-204.167572,-0.002130,0.002352,0.059735,122.977402,6.264768,0.597345,-204.167572,0.060975,0.000000
46.550003,28.962387,-204.167572,-0.002108,0.002385,0.060576,128.831131,6.562971,0.605757,-204.167572,0.061573,0.000000
46.910004,29.415932,-204.256531,-0.002078,0.002409,0.061191,130.848602,6.665745,0.611914,-204.256531,0.062171,0.000000
47.270000,29.699310,-204.212051,-0.002074,0.002428,0.061677,132.109131,6.729959,0.616771,-204.212051,0.062770,0.000000
47.630001,29.958107,-204.301010,-0.002057,0.002447,0.062145,133.260315,6.788604,0.621454,-204.301010,0.063377,0.000000
47.990002,30.747536,-204.301010,-0.002026,0.002472,0.062796,136.771866,6.967491,0.627958,-204.301010,0.063975,0.000000
48.350002,31.805077,-204.301010,-0.002005,0.002505,0.063637,141.476044,7.207133,0.636370,-204.301010,0.064574,0.000000
48.710003,32.780319,-204.389969,-0.001996,0.002530,0.064253,145.814148,7.428126,0.642528,-204.389969,0.065172,0.000000
49.070004,32.908043,-204.389969,-0.001966,0.002548,0.064730,146.382278,7.457069,0.647297,-204.389969,0.065770,0.000000
49.430004,33.430107,-204.389969,-0.001936,0.002569,0.065250,148.704544,7.575371,0.652501,-204.389969,0.066377,0.000000
49.790001,34.208366,-204.434448,-0.001936,0.002594,0.065883,152.166412,7.751727,0.658831,-204.434448,0.066976,0.000000
50.150002,35.489700,-204.389969,-0.001910,0.002620,0.066560,157.866074,8.042081,0.665596,-204.389969,0.067574,0.000000
50.510002,35.970062,-204.478928,-0.001893,0.002645,0.067175,160.002823,8.150932,0.671753,-204.478928,0.068173,0.000000
50.870003,37.122551,-204.478928,-0.001884,0.002672,0.067860,165.129349,8.412090,0.678604,-204.478928,0.068771,0.000000
51.230003,37.922035,-204.478928,-0.001850,0.002695,0.068450,168.685638,8.593256,0.684501,-204.478928,0.069378,0.000000
51.590004,38.036354,-204.478928,-0.001850,0.002713,0.068901,169.194153,8.619161,0.689011,-204.478928,0.069976,0.000000
51.950001,38.986275,-204.523407,-0.001815,0.002737,0.069508,173.419617,8.834415,0.695081,-204.523407,0.070575,0.000000
52.310001,39.799911,-204.612381,-0.001819,0.002758,0.070063,177.038849,9.018789,0.700632,-204.612381,0.071173,0.000000
52.670002,39.776451,-204.612381,-0.001794,0.002772,0.070401,176.934494,9.013473,0.704014,-204.612381,0.071772,0.000000
53.030003,42.113464,-204.612381,-0.001772,0.002813,0.071451,187.330048,9.543048,0.714507,-204.612381,0.072379,0.000000
53.390003,42.055374,-204.612381,-0.001768,0.002827,0.071798,187.071640,9.529883,0.717976,-204.612381,0.072977,0.000000
53.750004,43.559387,-204.612381,-0.001738,0.002854,0.072500,193.761826,9.870698,0.725001,-204.612381,0.073575,0.000000
54.110004,44.666817,-204.745819,-0.001725,0.002878,0.073098,198.687927,10.121646,0.730985,-204.745819,0.074174,0.000000
54.470001,45.177711,-204.656860,-0.001703,0.002895,0.073541,200.960495,10.237415,0.735407,-204.656860,0.074772,0.000000
54.830002,47.075325,-204.745819,-0.001686,0.002931,0.074460,209.401505,10.667421,0.744600,-204.745819,0.075371,0.000000
55.190002,47.980560,-204.745819,-0.001677,0.002951,0.074963,213.428192,10.872550,0.749630,-204.745819,0.075978,0.000000
55.550003,48.524223,-204.790298,-0.001660,0.002971,0.075475,215.846527,10.995746,0.754747,-204.790298,0.076576,0.000000
55.910004,49.404884,-204.790298,-0.001643,0.002996,0.076090,219.763901,11.195307,0.760904,-204.790298,0.077174,0.000000
56.270004,51.158760,-204.834778,-0.001630,0.003022,0.076749,227.565536,11.592741,0.767495,-204.834778,0.077773,0.000000
56.630001,52.392059,-204.834778,-0.001608,0.003047,0.077383,233.051514,11.872211,0.773826,-204.834778,0.078371,0.000000
56.990002,53.813774,-204.879257,-0.001608,0.003073,0.078050,239.375626,12.194375,0.780503,-204.879257,0.078978,0.000000
57.350002,53.714355,-204.923737,-0.001582,0.003083,0.078302,238.933380,12.171847,0.783018,-204.923737,0.079577,0.000000
57.710003,55.269005,-204.879257,-0.001574,0.003110,0.078996,245.848816,12.524136,0.789956,-204.879257,0.080175,0.000000
58.070004,56.953995,-204.879257,-0.001548,0.003138,0.079698,253.344025,12.905959,0.796980,-204.879257,0.080773,0.000000
58.430004,58.429703,-205.012711,-0.001548,0.003165,0.080400,259.908295,13.240360,0.804005,-205.012711,0.081372,0.000000
58.790001,59.766525,-204.923737,-0.001531,0.003190,0.081025,265.854797,13.543288,0.810249,-204.923737,0.081979,0.000000
59.150002,61.015091,-205.012711,-0.001518,0.003212,0.081580,271.408691,13.826217,0.815799,-205.012711,0.082577,0.000000
59.510002,61.841759,-204.968216,-0.001500,0.003232,0.082092,275.085876,14.013543,0.820916,-204.968216,0.083176,0.000000
59.870003,62.373505,-204.968216,-0.001487,0.003246,0.082456,277.451202,14.134038,0.824558,-204.968216,0.083774,0.000000
60.230003,64.752213,-205.101669,-0.001483,0.003282,0.083358,288.032227,14.673061,0.833577,-205.101669,0.084372,0.000000
60.590004,65.904343,-205.057190,-0.001457,0.003302,0.083861,293.157166,14.934137,0.838607,-205.057190,0.084979,0.000000
60.950005,65.714432,-205.101669,-0.001453,0.003300,0.083817,292.312378,14.891103,0.838174,-205.101669,0.014726,0.000000
61.310001,65.489883,-205.146149,-0.001440,0.003315,0.084208,291.313538,14.840219,0.842076,-205.146149,294.500458,0.000000
61.670002,65.325302,-205.146149,-0.001431,0.003322,0.084372,290.581451,14.802925,0.843724,-205.146149,294.500458,0.000000
62.030003,65.250824,-205.190628,-0.001423,0.003330,0.084572,290.250153,14.786048,0.845719,-205.190628,294.500458,0.000000
62.390003,64.703812,-205.146149,-0.001427,0.003329,0.084546,287.816925,14.662094,0.845458,-205.146149,294.500458,0.000000
62.750004,66.174683,-205.324066,-0.001414,0.003321,0.084355,294.359680,14.995398,0.843550,-205.324066,294.500458,0.000000
63.110004,65.520798,-205.279587,-0.001393,0.003321,0.084355,291.451050,14.847225,0.843550,-205.279587,294.500458,0.000000
63.470001,64.916428,-205.235107,-0.001388,0.003321,0.084364,288.762695,14.710273,0.843637,-205.235107,294.500458,0.000000
63.830002,65.739746,-205.279587,-0.001393,0.003347,0.085014,292.424988,14.896840,0.850141,-205.279587,294.500458,0.000000
64.190002,65.180817,-205.235107,-0.001393,0.003347,0.085014,289.938751,14.770185,0.850141,-205.235107,294.500458,0.000000
64.550003,64.741791,-205.324066,-0.001384,0.003362,0.085396,287.985870,14.670699,0.853957,-205.324066,294.500458,0.000000
64.910004,65.670868,-205.324066,-0.001388,0.003364,0.085456,292.118622,14.881231,0.854564,-205.324066,294.500458,0.000000
65.270004,65.279877,-205.413025,-0.001375,0.003365,0.085465,290.379395,14.792631,0.854651,-205.413025,294.500458,0.000000
65.630005,64.887756,-205.368546,-0.001380,0.003365,0.085465,288.635162,14.703775,0.854651,-205.368546,294.500458,0.000000
65.990005,66.530670,-205.368546,-0.001375,0.003370,0.085587,295.943207,15.076066,0.855865,-205.368546,294.500458,0.000000
66.350006,66.017532,-205.457520,-0.001354,0.003362,0.085404,293.660645,14.959786,0.854044,-205.457520,294.500458,0.000000
66.710007,65.673843,-205.501999,-0.001371,0.003362,0.085404,292.131836,14.881906,0.854044,-205.501999,294.500458,0.000000
67.070000,65.354721,-205.457520,-0.001350,0.003364,0.085448,290.712311,14.809591,0.854477,-205.457520,294.500458,0.000000
67.430000,65.146927,-205.546478,-0.001367,0.003379,0.085838,289.787994,14.762505,0.858380,-205.546478,294.500458,0.000000
67.790001,65.563995,-205.413025,-0.001362,0.003391,0.086124,291.643219,14.857014,0.861242,-205.413025,294.500458,0.000000
68.150002,65.376694,-205.546478,-0.001358,0.003391,0.086133,290.810059,14.814571,0.861329,-205.546478,294.500458,0.000000
68.510002,65.254181,-205.546478,-0.001362,0.003393,0.086176,290.265106,14.786808,0.861762,-205.546478,294.500458,0.000000
68.870003,65.268692,-205.590958,-0.001350,0.003395,0.086246,290.329651,14.790096,0.862456,-205.590958,294.500458,0.000000
69.230003,65.227737,-205.635437,-0.001358,0.003397,0.086289,290.147461,14.780817,0.862890,-205.635437,294.500458,0.000000
69.590004,65.413925,-205.546478,-0.001341,0.003402,0.086419,290.975677,14.823008,0.864190,-205.546478,294.500458,0.000000
69.950005,65.358063,-205.635437,-0.001350,0.003402,0.086419,290.727173,14.810349,0.864190,-205.635437,294.500458,0.000000
70.310005,65.231094,-205.679916,-0.001341,0.003403,0.086428,290.162415,14.781577,0.864277,-205.679916,294.500458,0.000000
70.670006,65.217682,-205.724396,-0.001345,0.003405,0.086497,290.102753,14.778538,0.864971,-205.724396,294.500458,0.000000
71.030006,65.175232,-205.679916,-0.001358,0.003406,0.086514,289.913910,14.768919,0.865144,-205.679916,294.500458,0.000000
71.390007,65.540161,-205.724396,-0.001350,0.003413,0.086679,291.537201,14.851613,0.866792,-205.724396,294.500458,0.000000
71.750000,65.488022,-205.724396,-0.001328,0.003413,0.086679,291.305267,14.839798,0.866792,-205.724396,294.500458,0.000000
72.110001,65.353607,-205.724396,-0.001341,0.003413,0.086679,290.707367,14.809340,0.866792,-205.724396,294.500458,0.000000
72.470001,65.265350,-205.768875,-0.001337,0.003413,0.086688,290.314789,14.789339,0.866879,-205.768875,294.500458,0.000000
72.830002,65.175980,-205.768875,-0.001350,0.003414,0.086714,289.917236,14.769088,0.867139,-205.768875,294.500458,0.000000
73.190002,65.228851,-205.857849,-0.001337,0.003416,0.086766,290.152435,14.781069,0.867659,-205.857849,294.500458,0.000000
73.550003,65.133148,-205.857849,-0.001350,0.003416,0.086775,289.726715,14.759382,0.867746,-205.857849,294.500458,0.000000
73.910004,65.100021,-205.813354,-0.001337,0.003420,0.086861,289.579346,14.751876,0.868613,-205.813354,294.500458,0.000000
74.270004,65.223267,-205.902328,-0.001337,0.003420,0.086861,290.127594,14.779803,0.868613,-205.902328,294.500458,0.000000
74.630005,65.119385,-205.813354,-0.001345,0.003420,0.086861,289.665497,14.756263,0.868613,-205.813354,294.500458,0.000000
74.990005,65.092560,-205.902328,-0.001337,0.003421,0.086896,289.546173,14.750185,0.868960,-205.902328,294.500458,0.000000
75.350006,65.027405,-205.946808,-0.001337,0.003421,0.086896,289.256348,14.735421,0.868960,-205.946808,294.500458,0.000000
75.710007,64.960373,-205.946808,-0.001315,0.003421,0.086896,288.958160,14.720231,0.868960,-205.946808,294.500458,0.000000
76.070007,64.902283,-205.946808,-0.001341,0.003422,0.086931,288.699768,14.707067,0.869307,-205.946808,294.500458,0.000000
76.430000,64.822968,-205.991287,-0.001341,0.003422,0.086931,288.346954,14.689095,0.869307,-205.991287,294.500458,0.000000
76.790001,64.726532,-206.035767,-0.001328,0.003422,0.086931,287.917999,14.667242,0.869307,-206.035767,294.500458,0.000000
77.150002,65.460464,-206.035767,-0.001332,0.003431,0.087156,291.182678,14.833553,0.871562,-206.035767,294.500458,0.000000
77.510002,65.406845,-206.080246,-0.001319,0.003431,0.087156,290.944183,14.821403,0.871562,-206.080246,294.500458,0.000000
77.870003,65.347275,-206.080246,-0.001319,0.003431,0.087156,290.679199,14.807904,0.871562,-206.080246,294.500458,0.000000
78.230003,65.285828,-206.080246,-0.001315,0.003431,0.087156,290.405853,14.793981,0.871562,-206.080246,294.500458,0.000000
78.590004,65.198700,-206.213684,-0.001324,0.003431,0.087156,290.018311,14.774237,0.871562,-206.213684,294.500458,0.000000
78.950005,65.099274,-206.213684,-0.001324,0.003431,0.087156,289.576019,14.751707,0.871562,-206.213684,294.500458,0.000000
79.310005,65.038193,-206.213684,-0.001311,0.003432,0.087165,289.304321,14.737865,0.871649,-206.213684,294.500458,0.000000
79.670006,65.086243,-206.258163,-0.001328,0.003434,0.087226,289.518066,14.748754,0.872256,-206.258163,294.500458,0.000000
80.030006,65.048630,-206.258163,-0.001315,0.003434,0.087226,289.350769,14.740230,0.872256,-206.258163,294.500458,0.000000
80.390007,65.010269,-206.302658,-0.001324,0.003434,0.087226,289.180115,14.731537,0.872256,-206.302658,294.500458,0.000000
80.750008,64.941757,-206.302658,-0.001311,0.003434,0.087226,288.875366,14.716012,0.872256,-206.302658,294.500458,0.000000
81.110001,64.858337,-206.302658,-0.001315,0.003434,0.087226,288.504303,14.697109,0.872256,-206.302658,294.500458,0.000000
81.470001,64.773071,-206.347137,-0.001337,0.003434,0.087226,288.125000,14.677788,0.872256,-206.347137,294.500458,0.000000
81.830002,64.730255,-206.302658,-0.001315,0.003434,0.087226,287.934570,14.668085,0.872256,-206.302658,294.500458,0.000000
82.190002,66.268143,-206.391617,-0.001302,0.003443,0.087460,294.775421,15.016576,0.874597,-206.391617,294.500458,0.000000
82.550003,66.189941,-206.391617,-0.001324,0.003443,0.087451,294.427551,14.998855,0.874510,-206.391617,294.500458,0.000000
82.910004,66.066696,-206.436096,-0.001306,0.003443,0.087451,293.879333,14.970927,0.874510,-206.436096,294.500458,0.000000
83.270004,65.995575,-206.436096,-0.001311,0.003443,0.087442,293.562988,14.954811,0.874424,-206.436096,294.500458,0.000000
83.630005,65.893539,-206.436096,-0.001306,0.003443,0.087442,293.109100,14.931690,0.874424,-206.436096,294.500458,0.000000
83.990005,65.841400,-206.480576,-0.001306,0.003443,0.087442,292.877167,14.919874,0.874424,-206.480576,294.500458,0.000000
84.350006,65.775497,-206.569534,-0.001306,0.003443,0.087442,292.584015,14.904941,0.874424,-206.569534,294.500458,0.000000
84.710007,65.660065,-206.569534,-0.001311,0.003443,0.087451,292.070557,14.878783,0.874510,-206.569534,294.500458,0.000000
85.070007,65.583359,-206.569534,-0.001302,0.003443,0.087451,291.729340,14.861402,0.874510,-206.569534,294.500458,0.000000
85.430000,65.533829,-206.525055,-0.001298,0.003443,0.087451,291.509033,14.850178,0.874510,-206.525055,294.500458,0.000000
85.790001,65.465317,-206.614014,-0.001298,0.003443,0.087451,291.204285,14.834653,0.874510,-206.614014,294.500458,0.000000
86.150002,65.374832,-206.614014,-0.001319,0.003443,0.087451,290.801788,14.814149,0.874510,-206.614014,294.500458,0.000000
86.510002,65.316742,-206.658493,-0.001306,0.003443,0.087451,290.543365,14.800985,0.874510,-206.658493,294.500458,0.000000
86.870003,65.251572,-206.658493,-0.001302,0.003443,0.087451,290.253479,14.786218,0.874510,-206.658493,294.500458,0.000000
87.230003,65.189758,-206.658493,-0.001302,0.003443,0.087460,289.978516,14.772210,0.874597,-206.658493,294.500458,0.000000
87.590004,65.122360,-206.791946,-0.001306,0.003444,0.087468,289.678711,14.756938,0.874684,-206.791946,294.500458,0.000000
87.950005,65.038193,-206.658493,-0.001298,0.003444,0.087477,289.304321,14.737865,0.874771,-206.658493,294.500458,0.000000
88.310005,64.994629,-206.747467,-0.001293,0.003444,0.087477,289.110535,14.727993,0.874771,-206.747467,294.500458,0.000000
88.670006,64.950699,-206.747467,-0.001302,0.003444,0.087477,288.915131,14.718039,0.874771,-206.747467,294.500458,0.000000
89.030006,64.884781,-206.747467,-0.001302,0.003444,0.087477,288.621918,14.703102,0.874771,-206.747467,294.500458,0.000000
89.390007,65.879013,-206.836426,-0.001311,0.003459,0.087850,293.044495,14.928398,0.878500,-206.836426,294.500458,0.000000
89.750008,65.856674,-206.791946,-0.001302,0.003459,0.087850,292.945129,14.923336,0.878500,-206.791946,294.500458,0.000000
90.110001,65.890930,-206.880905,-0.001306,0.003459,0.087850,293.097504,14.931098,0.878500,-206.880905,294.500458,0.000000
90.470001,65.871201,-206.836426,-0.001302,0.003459,0.087850,293.009735,14.926628,0.878500,-206.836426,294.500458,0.000000
90.830002,65.830231,-206.880905,-0.001293,0.003459,0.087850,292.827484,14.917343,0.878500,-206.880905,294.500458,0.000000
91.190002,65.772141,-206.925385,-0.001298,0.003459,0.087850,292.569092,14.904180,0.878500,-206.925385,294.500458,0.000000
91.550003,65.738632,-206.880905,-0.001293,0.003459,0.087850,292.420044,14.896587,0.878500,-206.880905,294.500458,0.000000
91.910004,65.664154,-206.969864,-0.001311,0.003459,0.087850,292.088745,14.879709,0.878500,-206.969864,294.500458,0.000000
92.270004,65.609787,-206.969864,-0.001298,0.003459,0.087850,291.846893,14.867391,0.878500,-206.969864,294.500458,0.000000
92.630005,65.593781,-207.014343,-0.001293,0.003459,0.087850,291.775696,14.863764,0.878500,-207.014343,294.500458,0.000000
92.990005,65.545364,-207.014343,-0.001298,0.003459,0.087850,291.560333,14.852793,0.878500,-207.014343,294.500458,0.000000
93.350006,65.521545,-207.014343,-0.001289,0.003459,0.087850,291.454376,14.847394,0.878500,-207.014343,294.500458,0.000000
93.710007,65.474243,-207.103302,-0.001293,0.003459,0.087850,291.243988,14.836676,0.878500,-207.103302,294.500458,0.000000
94.070007,65.425842,-207.103302,-0.001298,0.003459,0.087850,291.028687,14.825707,0.878500,-207.103302,294.500458,0.000000
94.430008,65.361420,-207.147797,-0.001289,0.003459,0.087850,290.742126,14.811110,0.878500,-207.147797,294.500458,0.000000
94.790001,65.318222,-207.147797,-0.001298,0.003459,0.087850,290.549957,14.801320,0.878500,-207.147797,294.500458,0.000000
95.150002,65.285080,-207.147797,-0.001281,0.003459,0.087850,290.402527,14.793811,0.878500,-207.147797,294.500458,0.000000
95.510002,65.241882,-207.236755,-0.001289,0.003459,0.087850,290.210388,14.784021,0.878500,-207.236755,294.500458,0.000000
95.870003,65.216568,-207.192276,-0.001285,0.003459,0.087850,290.097778,14.778286,0.878500,-207.192276,294.500458,0.000000
96.230003,65.147308,-207.281235,-0.001281,0.003459,0.087850,289.789703,14.762590,0.878500,-207.281235,294.500458,0.000000
96.590004,65.123474,-207.281235,-0.001302,0.003459,0.087850,289.683685,14.757190,0.878500,-207.281235,294.500458,0.000000
96.950005,65.065750,-207.325714,-0.001272,0.003459,0.087850,289.426910,14.744110,0.878500,-207.325714,294.500458,0.000000
97.310005,65.032242,-207.281235,-0.001306,0.003459,0.087850,289.277863,14.736517,0.878500,-207.281235,294.500458,0.000000
97.670006,64.992767,-207.281235,-0.001298,0.003459,0.087850,289.102264,14.727571,0.878500,-207.281235,294.500458,0.000000
98.030006,64.967072,-207.370193,-0.001289,0.003459,0.087850,288.987976,14.721749,0.878500,-207.370193,294.500458,0.000000
98.390007,64.933929,-207.370193,-0.001289,0.003459,0.087850,288.840546,14.714238,0.878500,-207.370193,294.500458,0.000000
98.750008,64.886642,-207.414673,-0.001293,0.003459,0.087850,288.630188,14.703523,0.878500,-207.414673,294.500458,0.000000
99.110008,64.851639,-207.459152,-0.001289,0.003459,0.087850,288.474487,14.695591,0.878500,-207.459152,294.500458,0.000000
99.470001,64.796524,-207.459152,-0.001289,0.003459,0.087850,288.229340,14.683103,0.878500,-207.459152,294.500458,0.000000
99.830002,64.760406,-207.459152,-0.001281,0.003459,0.087850,288.068665,14.674918,0.878500,-207.459152,294.500458,0.000000
100.190002,64.720200,-207.459152,-0.001298,0.003459,0.087850,287.889832,14.665807,0.878500,-207.459152,294.500458,0.000000
100.550003,64.692261,-207.503632,-0.001289,0.003459,0.087850,287.765533,14.659475,0.878500,-207.503632,294.500458,0.000000
100.910004,64.648331,-207.503632,-0.001289,0.003459,0.087850,287.570129,14.649521,0.878500,-207.503632,294.500458,0.000000
101.270004,64.612946,-207.548111,-0.001285,0.003459,0.087859,287.412750,14.641503,0.878586,-207.548111,294.500458,0.000000
101.630005,64.580551,-207.592606,-0.001281,0.003459,0.087859,287.268646,14.634162,0.878586,-207.592606,294.500458,0.000000
101.990005,64.540710,-207.592606,-0.001293,0.003459,0.087859,287.091431,14.625134,0.878586,-207.592606,294.500458,0.000000
102.350006,64.517624,-207.592606,-0.001293,0.003459,0.087859,286.988739,14.619903,0.878586,-207.592606,294.500458,0.000000
102.710007,66.409653,-207.726044,-0.001302,0.003453,0.087694,295.404877,15.048642,0.876939,-207.726044,294.500458,0.000000
103.070007,66.360870,-207.681564,-0.001276,0.003453,0.087694,295.187897,15.037589,0.876939,-207.681564,294.500458,0.000000
103.430008,66.297562,-207.726044,-0.001276,0.003453,0.087694,294.906281,15.023242,0.876939,-207.726044,294.500458,0.000000
103.790009,66.271500,-207.681564,-0.001285,0.003453,0.087694,294.790344,15.017337,0.876939,-207.681564,294.500458,0.000000
104.150002,66.218628,-207.726044,-0.001272,0.003453,0.087694,294.555176,15.005356,0.876939,-207.726044,294.500458,0.000000
104.510002,66.185104,-207.726044,-0.001289,0.003453,0.087694,294.406036,14.997759,0.876939,-207.726044,294.500458,0.000000
104.870003,66.144150,-207.726044,-0.001281,0.003453,0.087694,294.223877,14.988479,0.876939,-207.726044,294.500458,0.000000
105.230003,66.096481,-207.815002,-0.001281,0.003453,0.087694,294.011841,14.977676,0.876939,-207.815002,294.500458,0.000000
105.590004,66.065201,-207.815002,-0.001281,0.003453,0.087694,293.872681,14.970588,0.876939,-207.815002,294.500458,0.000000
105.950005,66.012329,-207.815002,-0.001281,0.003453,0.087694,293.637512,14.958608,0.876939,-207.815002,294.500458,0.000000
106.310005,65.990723,-207.815002,-0.001268,0.003453,0.087694,293.541382,14.953712,0.876939,-207.815002,294.500458,0.000000
106.670006,65.926315,-207.859482,-0.001268,0.003453,0.087694,293.254883,14.939116,0.876939,-207.859482,294.500458,0.000000
107.030006,65.894653,-207.948441,-0.001272,0.003453,0.087694,293.114044,14.931941,0.876939,-207.948441,294.500458,0.000000
107.390007,65.895035,-207.948441,-0.001281,0.003453,0.087694,293.115753,14.932029,0.876939,-207.948441,294.500458,0.000000
107.750008,65.849594,-207.948441,-0.001272,0.003453,0.087694,292.913635,14.921731,0.876939,-207.948441,294.500458,0.000000
108.110008,65.848480,-207.948441,-0.001276,0.003453,0.087694,292.908661,14.921478,0.876939,-207.948441,294.500458,0.000000
108.470009,65.784805,-207.948441,-0.001263,0.003453,0.087694,292.625427,14.907050,0.876939,-207.948441,294.500458,0.000000
108.830002,65.778854,-208.037415,-0.001281,0.003453,0.087694,292.598969,14.905701,0.876939,-208.037415,294.500458,0.000000
109.190002,65.750549,-207.992920,-0.001272,0.003453,0.087694,292.473053,14.899287,0.876939,-207.992920,294.500458,0.000000
109.550003,65.676071,-208.081894,-0.001272,0.003453,0.087694,292.141754,14.882410,0.876939,-208.081894,294.500458,0.000000
109.910004,65.608673,-208.081894,-0.001285,0.003453,0.087694,291.841949,14.867138,0.876939,-208.081894,294.500458,0.000000
110.270004,65.597137,-208.081894,-0.001268,0.003453,0.087694,291.790649,14.864524,0.876939,-208.081894,294.500458,0.000000
110.630005,65.570328,-208.126373,-0.001276,0.003453,0.087694,291.671387,14.858449,0.876939,-208.126373,294.500458,0.000000
110.990005,65.550217,-208.081894,-0.001268,0.003453,0.087694,291.581940,14.853891,0.876939,-208.081894,294.500458,0.000000
111.350006,65.532333,-208.170853,-0.001276,0.003453,0.087694,291.502380,14.849839,0.876939,-208.170853,294.500458,0.000000
111.710007,65.493607,-208.170853,-0.001285,0.003453,0.087694,291.330109,14.841063,0.876939,-208.170853,294.500458,0.000000
112.070007,65.483551,-208.170853,-0.001259,0.003453,0.087694,291.285370,14.838785,0.876939,-208.170853,294.500458,0.000000
112.430008,65.412064,-208.259811,-0.001276,0.003453,0.087694,290.967377,14.822585,0.876939,-208.259811,294.500458,0.000000
112.790009,65.370728,-208.259811,-0.001272,0.003453,0.087694,290.783508,14.813218,0.876939,-208.259811,294.500458,0.000000
113.150009,65.335724,-208.259811,-0.001276,0.003453,0.087694,290.627808,14.805286,0.876939,-208.259811,294.500458,0.000000
113.510002,65.316742,-208.304291,-0.001289,0.003453,0.087694,290.543365,14.800985,0.876939,-208.304291,294.500458,0.000000
113.870003,65.299606,-208.348770,-0.001281,0.003453,0.087694,290.467163,14.797102,0.876939,-208.348770,294.500458,0.000000
114.230003,65.262375,-208.393250,-0.001276,0.003453,0.087694,290.301544,14.788666,0.876939,-208.393250,294.500458,0.000000
114.590004,65.261993,-208.304291,-0.001285,0.003453,0.087694,290.299835,14.788579,0.876939,-208.304291,294.500458,0.000000
114.950005,65.228485,-208.437744,-0.001263,0.003453,0.087703,290.150787,14.780987,0.877025,-208.437744,294.500458,0.000000
115.310005,65.202042,-208.393250,-0.001268,0.003453,0.087703,290.033173,14.774994,0.877025,-208.393250,294.500458,0.000000
115.670006,65.189758,-208.437744,-0.001268,0.003453,0.087703,289.978516,14.772210,0.877025,-208.437744,294.500458,0.000000
116.030006,65.121613,-208.437744,-0.001276,0.003453,0.087703,289.675415,14.756768,0.877025,-208.437744,294.500458,0.000000
116.390007,65.102249,-208.393250,-0.001289,0.003453,0.087703,289.589264,14.752380,0.877025,-208.393250,294.500458,0.000000
116.750008,65.069473,-208.526703,-0.001285,0.003453,0.087703,289.443481,14.744953,0.877025,-208.526703,294.500458,0.000000
117.110008,65.061295,-208.482224,-0.001276,0.003453,0.087703,289.407104,14.743100,0.877025,-208.482224,294.500458,0.000000
117.470009,65.034851,-208.615662,-0.001255,0.003453,0.087703,289.289459,14.737107,0.877025,-208.615662,294.500458,0.000000
117.830002,64.999466,-208.615662,-0.001281,0.003453,0.087703,289.132050,14.729090,0.877025,-208.615662,294.500458,0.000000
118.190002,64.976013,-208.571182,-0.001259,0.003453,0.087703,289.027740,14.723775,0.877025,-208.571182,294.500458,0.000000
118.550003,64.943985,-208.660141,-0.001272,0.003453,0.087703,288.885284,14.716517,0.877025,-208.660141,294.500458,0.000000
118.910004,64.936539,-208.615662,-0.001272,0.003453,0.087703,288.852142,14.714830,0.877025,-208.615662,294.500458,0.000000
119.270004,65.730820,-208.615662,-0.001272,0.003483,0.088466,292.385284,14.894817,0.884657,-208.615662,294.500458,0.000000
119.630005,65.728958,-208.704620,-0.001276,0.003481,0.088414,292.377014,14.894395,0.884137,-208.704620,294.500458,0.000000
119.990005,65.682037,-208.704620,-0.001272,0.003481,0.088414,292.168304,14.883762,0.884137,-208.704620,294.500458,0.000000
120.350006,65.654480,-208.749100,-0.001263,0.003481,0.088414,292.045715,14.877518,0.884137,-208.749100,294.500458,0.000000
120.710007,65.653732,-208.793579,-0.001276,0.003481,0.088414,292.042389,14.877348,0.884137,-208.793579,294.500458,0.000000
121.070007,65.613144,-208.793579,-0.001276,0.003481,0.088414,291.861847,14.868151,0.884137,-208.793579,294.500458,0.000000
121.430008,65.587814,-208.704620,-0.001268,0.003481,0.088414,291.749176,14.862411,0.884137,-208.704620,1681.640747,0.000000
121.790009,65.566223,-208.793579,-0.001268,0.003472,0.088180,291.653137,14.857518,0.881795,-208.793579,0.087971,0.000000
122.150009,65.448181,-208.793579,-0.001268,0.003454,0.087737,291.128052,14.830770,0.877372,-208.793579,0.087373,0.000000
122.510002,65.353226,-208.882553,-0.001272,0.003435,0.087243,290.705658,14.809253,0.872429,-208.882553,0.086775,0.000000
122.870003,65.313751,-208.927032,-0.001259,0.003413,0.086697,290.530090,14.800307,0.866966,-208.927032,0.086176,0.000000
123.230003,65.320084,-208.882553,-0.001272,0.003390,0.086116,290.558258,14.801743,0.861155,-208.882553,0.085578,0.000000
123.590004,65.291412,-208.838058,-0.001259,0.003365,0.085482,290.430695,14.795246,0.854824,-208.838058,0.084971,0.000000
123.950005,65.267578,-208.882553,-0.001268,0.003344,0.084936,290.324677,14.789845,0.849361,-208.882553,0.084372,0.000000
124.310005,65.195343,-208.838058,-0.001263,0.003317,0.084242,290.003357,14.773476,0.842423,-208.838058,0.083774,0.000000
124.670006,65.186783,-208.971512,-0.001263,0.003298,0.083774,289.965302,14.771536,0.837740,-208.971512,0.083176,0.000000
125.030006,65.163696,-209.015991,-0.001268,0.003277,0.083245,289.862610,14.766305,0.832450,-209.015991,0.082577,0.000000
125.390007,64.768234,-209.015991,-0.001255,0.003249,0.082525,288.103485,14.676692,0.825252,-209.015991,0.081970,0.000000
125.750008,64.274460,-209.015991,-0.001276,0.003233,0.082126,285.907074,14.564800,0.821263,-209.015991,0.081372,0.000000
126.110008,63.446686,-209.015991,-0.001246,0.003209,0.081519,282.224945,14.377225,0.815192,-209.015991,0.080773,0.000000
126.470009,62.392868,-209.060471,-0.001242,0.003187,0.080938,277.537354,14.138427,0.809382,-209.060471,0.080175,0.000000
126.830009,61.184517,-209.060471,-0.001242,0.003166,0.080409,272.162323,13.864610,0.804092,-209.060471,0.079577,0.000000
127.190002,60.132568,-209.104950,-0.001246,0.003151,0.080045,267.483032,13.626235,0.800449,-209.104950,0.078970,0.000000
127.550003,57.991798,-209.104950,-0.001237,0.003121,0.079264,257.960388,13.141129,0.792644,-209.104950,0.078371,0.000000
127.910004,56.459480,-209.149429,-0.001237,0.003101,0.078753,251.144318,12.793900,0.787528,-209.149429,0.077773,0.000000
128.270004,54.293022,-209.193909,-0.001237,0.003078,0.078189,241.507431,12.302975,0.781891,-209.193909,0.077174,0.000000
128.630005,51.928452,-209.149429,-0.001233,0.003054,0.077573,230.989288,11.767155,0.775733,-209.149429,0.076576,0.000000
128.990005,50.561852,-209.238388,-0.001233,0.003042,0.077278,224.910355,11.457479,0.772785,-209.238388,0.075969,0.000000
129.350006,46.928612,-209.193909,-0.001242,0.003006,0.076359,208.748886,10.634175,0.763592,-209.193909,0.075371,0.000000
129.710007,44.510048,-209.193909,-0.001233,0.002985,0.075813,197.990585,10.086121,0.758129,-209.193909,0.074772,0.000000
130.070007,42.855972,-209.327362,-0.001233,0.002971,0.075457,190.632889,9.711302,0.754573,-209.327362,0.074174,0.000000
130.430008,40.592323,-209.238388,-0.001237,0.002944,0.074781,180.563675,9.198352,0.747809,-209.238388,0.073575,0.000000
130.790009,37.303154,-209.327362,-0.001237,0.002916,0.074070,165.932709,8.453015,0.740698,-209.327362,0.072977,0.000000
131.150009,33.952545,-209.282867,-0.001233,0.002887,0.073324,151.028458,7.693757,0.733239,-209.282867,0.072370,0.000000
131.510010,31.305351,-209.327362,-0.001242,0.002862,0.072682,139.253159,7.093894,0.726822,-209.327362,0.071772,0.000000
131.870010,28.738586,-209.416321,-0.001233,0.002837,0.072049,127.835617,6.512257,0.720491,-209.416321,0.071173,0.000000
132.230011,27.341820,-209.371841,-0.001237,0.002827,0.071806,121.622490,6.195745,0.718063,-209.371841,0.070575,0.000000
132.590012,24.306610,-209.460800,-0.001242,0.002798,0.071069,108.121201,5.507957,0.710691,-209.460800,0.069976,0.000000
132.950012,21.705589,-209.416321,-0.001233,0.002774,0.070453,96.551285,4.918557,0.704534,-209.416321,0.069369,0.000000
133.310013,18.420891,-209.460800,-0.001229,0.002743,0.069664,81.940216,4.174234,0.696642,-209.460800,0.068771,0.000000
133.670013,16.382149,-209.460800,-0.001237,0.002724,0.069187,72.871437,3.712248,0.691873,-209.460800,0.068173,0.000000
134.029999,13.625481,-209.460800,-0.001233,0.002700,0.068572,60.609165,3.087578,0.685715,-209.460800,0.067574,0.000000
134.389999,12.089813,-209.505280,-0.001233,0.002686,0.068233,53.778175,2.739591,0.682333,-209.505280,0.066976,0.000000
134.750000,8.677391,-209.549759,-0.001233,0.002653,0.067375,38.598965,1.966325,0.673748,-209.549759,0.066369,0.000000
135.110001,5.596756,-209.549759,-0.001229,0.002624,0.066646,24.895615,1.268243,0.666463,-209.549759,0.065770,0.000000
135.470001,3.247459,-209.638718,-0.001229,0.002603,0.066109,14.445421,0.735885,0.661086,-209.638718,0.065172,0.000000
135.830002,0.861671,-209.594238,-0.001242,0.002578,0.065493,3.832906,0.195258,0.654929,-209.594238,0.064574,0.000000
136.190002,-1.523750,-209.683197,-0.001233,0.002553,0.064842,-6.777980,-0.345287,0.648425,-209.683197,0.063975,0.000000
136.550003,-3.515198,-209.638718,-0.001237,0.002536,0.064426,-15.636380,-0.796555,0.644262,-209.638718,0.063368,0.000000
136.910004,-0.364182,-209.638718,-0.001250,0.002511,0.063784,-1.619960,-0.082525,0.637845,-209.638718,0.062770,0.000000
137.270004,-0.192146,-209.772171,-0.001268,0.002484,0.063099,-0.854709,-0.043541,0.630993,-209.772171,0.062171,0.000000
137.630005,-0.141502,-209.683197,-0.001276,0.002461,0.062501,-0.629434,-0.032065,0.625010,-209.683197,0.061573,0.000000
137.990005,-0.126984,-209.772171,-0.001289,0.002439,0.061963,-0.564851,-0.028775,0.619633,-209.772171,0.060975,0.000000
138.350006,-0.085648,-209.772171,-0.001324,0.002416,0.061374,-0.380979,-0.019408,0.613736,-209.772171,0.060376,0.000000
138.710007,-0.077080,-209.816650,-0.001350,0.002401,0.060992,-0.342868,-0.017467,0.609920,-209.816650,0.059769,0.000000
139.070007,-0.100914,-209.772171,-0.001380,0.002364,0.060047,-0.448888,-0.022867,0.600467,-209.772171,0.059171,0.000000
139.430008,-0.067032,-209.816650,-0.001410,0.002345,0.059570,-0.298173,-0.015190,0.595697,-209.816650,0.058572,0.000000
139.790009,-0.043945,-209.905609,-0.001423,0.002327,0.059110,-0.195479,-0.009958,0.591101,-209.905609,0.057974,0.000000
140.150009,-0.055115,-209.816650,-0.001431,0.002303,0.058494,-0.245163,-0.012489,0.584944,-209.816650,0.057376,0.000000
140.510010,-0.071121,-209.905609,-0.001466,0.002276,0.057809,-0.316363,-0.016116,0.578093,-209.905609,0.056769,0.000000
140.870010,-0.104263,-209.994568,-0.001500,0.002249,0.057124,-0.463786,-0.023626,0.571242,-209.994568,0.056170,0.000000
141.230011,-0.086021,-209.905609,-0.001531,0.002225,0.056508,-0.382642,-0.019493,0.565084,-209.905609,0.055572,0.000000
141.590012,-0.060699,-209.994568,-0.001565,0.002203,0.055953,-0.270005,-0.013755,0.559534,-209.994568,0.054973,0.000000
141.950012,-0.081177,-209.950089,-0.001578,0.002180,0.055372,-0.361092,-0.018395,0.553724,-209.950089,0.054375,0.000000
142.310013,-0.061073,-210.039047,-0.001604,0.002154,0.054705,-0.271668,-0.013839,0.547046,-210.039047,0.053768,0.000000
142.670013,-0.070755,-209.994568,-0.001630,0.002144,0.054453,-0.314734,-0.016033,0.544531,-209.994568,0.053170,0.000000
143.030014,-0.062561,-210.039047,-0.001656,0.002105,0.053464,-0.278285,-0.014177,0.534645,-210.039047,0.052571,0.000000
143.389999,-0.099426,-210.039047,-0.001681,0.002086,0.052987,-0.442270,-0.022530,0.529875,-210.039047,0.051973,0.000000
143.750000,-0.079689,-209.994568,-0.001703,0.002063,0.052389,-0.354474,-0.018058,0.523891,-209.994568,0.051374,0.000000
144.110001,-0.100914,-210.128006,-0.001716,0.002038,0.051765,-0.448888,-0.022867,0.517647,-210.128006,0.050767,0.000000
144.470001,-0.100914,-210.039047,-0.001750,0.002017,0.051244,-0.448888,-0.022867,0.512444,-210.039047,0.050169,0.000000
144.830002,-0.079689,-210.083527,-0.001768,0.001991,0.050568,-0.354474,-0.018058,0.505679,-210.083527,0.049571,0.000000
145.190002,-0.088623,-210.128006,-0.001802,0.001968,0.049978,-0.394215,-0.020082,0.499782,-210.128006,0.048972,0.000000
145.550003,-0.067772,-210.172501,-0.001824,0.001949,0.049501,-0.301465,-0.015357,0.495012,-210.172501,0.048374,0.000000
145.900009,-0.072990,-210.216980,-0.001858,0.001927,0.048955,-0.324678,-0.016540,0.489549,-210.216980,0.048886,0.000000