File: Data/compression 20/AutoNoHeating-17-20-reverse-1-4_09112024_165849.csv
Time (sec),S:Load (lbs),S:HL1 (DIM),S:LVDT (in),S:Position (in),Ch:Position (mm),Ch:Load (N),Ch:Stress (MPa),Ch:Strain (mm/mm),Ch:HL1 (DIM),Set Point (),Cycles ()
0.110000,-0.033516,-151.813492,-0.012266,-0.007795,-0.198005,-0.149086,-0.007595,-1.980050,-151.813492,-0.197788,0.000000
0.470000,-0.055115,-151.813492,-0.012271,-0.007729,-0.196305,-0.245163,-0.012489,-1.963052,-151.813492,-0.195585,0.000000
0.830000,-0.056602,-151.813492,-0.012171,-0.007512,-0.190807,-0.251780,-0.012826,-1.908070,-151.813492,-0.189602,0.000000
1.190000,-0.075218,-151.946930,-0.011939,-0.007283,-0.184988,-0.334587,-0.017045,-1.849879,-151.946930,-0.183600,0.000000
1.550000,-0.073730,-151.902451,-0.011697,-0.007041,-0.178839,-0.327969,-0.016708,-1.788393,-151.902451,-0.177599,0.000000
1.910000,-0.076340,-151.902451,-0.011460,-0.006808,-0.172925,-0.339576,-0.017299,-1.729248,-151.902451,-0.171598,0.000000
2.270000,-0.074104,-151.991409,-0.011219,-0.006571,-0.166915,-0.329632,-0.016792,-1.669149,-151.991409,-0.165597,0.000000
2.630000,-0.052879,-151.946930,-0.010969,-0.006333,-0.160853,-0.235219,-0.011983,-1.608530,-151.946930,-0.159613,0.000000
2.990000,-0.065536,-151.991409,-0.010718,-0.006094,-0.154791,-0.291521,-0.014851,-1.547911,-151.991409,-0.153612,0.000000
3.350000,-0.059952,-151.991409,-0.010490,-0.005859,-0.148807,-0.266679,-0.013585,-1.488073,-151.991409,-0.147610,0.000000
3.710000,-0.056229,-152.080368,-0.010240,-0.005625,-0.142884,-0.250117,-0.012742,-1.428841,-152.080368,-0.141609,0.000000
4.070000,-0.059578,-152.080368,-0.010003,-0.005390,-0.136909,-0.265016,-0.013501,-1.369089,-152.080368,-0.135608,0.000000
4.430000,-0.064423,-152.080368,-0.009748,-0.005155,-0.130934,-0.286566,-0.014598,-1.309337,-152.080368,-0.129624,0.000000
4.790000,-0.075592,-152.169327,-0.009516,-0.004915,-0.124828,-0.336250,-0.017129,-1.248285,-152.169327,-0.123623,0.000000
5.150000,-0.068146,-152.169327,-0.009274,-0.004672,-0.118671,-0.303127,-0.015442,-1.186712,-152.169327,-0.117622,0.000000
5.510000,-0.075218,-152.169327,-0.009011,-0.004447,-0.112947,-0.334587,-0.017045,-1.129475,-152.169327,-0.111621,0.000000
5.870000,-0.037987,-152.169327,-0.008778,-0.004208,-0.106894,-0.168974,-0.008608,-1.068942,-152.169327,-0.105637,0.000000
6.230000,-0.039474,-152.213821,-0.008541,-0.003974,-0.100936,-0.175591,-0.008945,-1.009364,-152.213821,-0.099636,0.000000
6.590000,-0.048409,-152.302780,-0.008304,-0.003734,-0.094848,-0.215332,-0.010970,-0.948485,-152.302780,-0.093634,0.000000
6.950000,-0.063675,-152.213821,-0.008063,-0.003504,-0.088995,-0.283240,-0.014429,-0.889947,-152.213821,-0.087633,0.000000
7.310000,-0.083038,-152.302780,-0.007812,-0.003260,-0.082811,-0.369373,-0.018817,-0.828114,-152.302780,-0.081632,0.000000
7.670001,-0.067772,-152.302780,-0.007575,-0.003028,-0.076914,-0.301465,-0.015357,-0.769142,-152.302780,-0.075648,0.000000
8.030001,-0.033142,-152.347260,-0.007317,-0.002788,-0.070818,-0.147423,-0.007510,-0.708176,-152.347260,-0.069647,0.000000
8.390000,-0.008194,-152.391739,-0.007092,-0.002554,-0.064868,-0.036449,-0.001857,-0.648685,-152.391739,-0.063646,0.000000
8.750000,-0.048782,-152.391739,-0.006842,-0.002322,-0.058971,-0.216995,-0.011054,-0.589713,-152.391739,-0.057644,0.000000
9.110001,-0.052505,-152.525177,-0.006592,-0.002087,-0.053022,-0.233556,-0.011898,-0.530222,-152.525177,-0.051643,0.000000
9.470000,-0.092354,-152.436218,-0.006368,-0.001850,-0.046995,-0.410810,-0.020928,-0.469950,-152.436218,-0.045659,0.000000
9.830001,-0.114693,-152.436218,-0.006109,-0.001609,-0.040864,-0.510179,-0.025990,-0.408637,-152.436218,-0.039658,0.000000
10.190001,-0.033142,-152.525177,-0.005877,-0.001374,-0.034897,-0.147423,-0.007510,-0.348972,-152.525177,-0.033657,0.000000
10.550000,-0.007446,-152.480698,-0.005627,-0.001135,-0.028835,-0.033123,-0.001687,-0.288353,-152.480698,-0.027656,0.000000
10.910001,-0.022346,-152.525177,-0.005398,-0.000904,-0.022964,-0.099402,-0.005064,-0.229641,-152.525177,-0.021655,0.000000
11.270000,-0.043571,-152.525177,-0.005148,-0.000671,-0.017041,-0.193816,-0.009873,-0.170410,-152.525177,-0.015671,0.000000
11.630000,-0.059212,-152.614136,-0.004919,-0.000435,-0.011040,-0.263387,-0.013418,-0.110398,-152.614136,-0.009670,0.000000
11.990001,-0.090858,-152.614136,-0.004687,-0.000194,-0.004917,-0.404159,-0.020589,-0.049172,-152.614136,-0.003668,0.000000
12.350000,0.015266,-152.614136,-0.004437,0.000045,0.001136,0.067908,0.003459,0.011361,-152.614136,0.002333,0.000000
12.710001,0.125488,-152.703110,-0.004381,-0.000002,-0.000043,0.558200,0.028436,-0.000434,-152.703110,0.000147,0.000000
13.070001,0.130325,-152.658630,-0.004389,-0.000002,-0.000043,0.579716,0.029532,-0.000434,-152.658630,0.000364,0.000000
13.430000,0.118416,-152.703110,-0.004385,-0.000002,-0.000043,0.526740,0.026833,-0.000434,-152.703110,0.000963,0.000000
13.790001,0.115807,-152.703110,-0.004393,-0.000001,-0.000035,0.515133,0.026242,-0.000347,-152.703110,0.001570,0.000000
14.150001,0.423759,-152.792068,-0.004346,0.000050,0.001266,1.884976,0.096025,0.012661,-152.792068,0.002168,0.000000
14.510000,0.599144,-152.792068,-0.004333,0.000067,0.001700,2.665126,0.135768,0.016998,-152.792068,0.002766,0.000000
14.870001,0.755173,-152.747589,-0.004316,0.000083,0.002107,3.359176,0.171125,0.021074,-152.747589,0.003365,0.000000
15.230000,1.077644,-152.836548,-0.004286,0.000114,0.002897,4.793602,0.244198,0.028965,-152.836548,0.003963,0.000000
15.590001,1.493958,-152.747589,-0.004268,0.000140,0.003547,6.645455,0.338536,0.035470,-152.747589,0.004570,0.000000
15.950001,1.802650,-152.836548,-0.004247,0.000158,0.004015,8.018590,0.408486,0.040153,-152.836548,0.005169,0.000000
16.310001,2.232002,-152.925507,-0.004243,0.000185,0.004709,9.928442,0.505779,0.047090,-152.925507,0.005767,0.000000
16.670000,2.525055,-152.881027,-0.004208,0.000210,0.005333,11.232005,0.572186,0.053334,-152.881027,0.006365,0.000000
17.030001,3.044891,-152.969986,-0.004182,0.000236,0.005993,13.544353,0.689982,0.059925,-152.969986,0.006964,0.000000
17.390001,3.489502,-152.881027,-0.004161,0.000259,0.006591,15.522079,0.790732,0.065909,-152.881027,0.007562,0.000000
17.750000,3.731544,-153.014465,-0.004143,0.000275,0.006990,16.598740,0.845580,0.069898,-153.014465,0.008169,0.000000
18.110001,4.215996,-152.969986,-0.004130,0.000302,0.007666,18.753685,0.955358,0.076663,-152.969986,0.008768,0.000000
18.470001,4.487083,-153.058960,-0.004105,0.000319,0.008109,19.959543,1.016788,0.081086,-153.058960,0.009366,0.000000
18.830002,5.112671,-153.058960,-0.004092,0.000352,0.008932,22.742296,1.158548,0.089324,-153.058960,0.009964,0.000000
19.190001,5.551697,-153.058960,-0.004057,0.000379,0.009618,24.695181,1.258032,0.096175,-153.058960,0.010563,0.000000
19.550001,5.713310,-153.103439,-0.004044,0.000396,0.010068,25.414074,1.294655,0.100685,-153.103439,0.011170,0.000000
19.910002,6.066689,-153.147919,-0.004036,0.000414,0.010511,26.985979,1.374731,0.105108,-153.147919,0.011768,0.000000
20.270000,6.656158,-153.147919,-0.003997,0.000443,0.011248,29.608072,1.508307,0.112479,-153.147919,0.012367,0.000000
20.630001,6.818512,-153.236877,-0.003984,0.000463,0.011751,30.330256,1.545097,0.117509,-153.236877,0.012965,0.000000
20.990002,7.396805,-153.236877,-0.003954,0.000494,0.012549,32.902630,1.676140,0.125488,-153.236877,0.013563,0.000000
21.350000,7.566231,-153.281357,-0.003932,0.000518,0.013147,33.656277,1.714532,0.131471,-153.281357,0.014170,0.000000
21.710001,7.672729,-153.236877,-0.003932,0.000537,0.013650,34.130005,1.738665,0.136501,-153.236877,0.014769,0.000000
22.070002,8.062607,-153.236877,-0.003876,0.000562,0.014283,35.864265,1.827013,0.142832,-153.236877,0.015367,0.000000
22.430000,8.181396,-153.370316,-0.003872,0.000583,0.014821,36.392670,1.853931,0.148209,-153.370316,0.015966,0.000000
22.790001,8.161285,-153.281357,-0.003854,0.000600,0.015237,36.303211,1.849374,0.152372,-153.281357,0.016564,0.000000
23.150002,8.601799,-153.459274,-0.003833,0.000628,0.015940,38.262714,1.949196,0.159396,-153.459274,0.017171,0.000000
23.510000,9.006569,-153.325836,-0.003807,0.000658,0.016703,40.063221,2.040918,0.167028,-153.325836,0.017769,0.000000
23.870001,9.172646,-153.414795,-0.003777,0.000682,0.017327,40.801964,2.078551,0.173272,-153.414795,0.018368,0.000000
24.230001,9.402779,-153.503769,-0.003755,0.000707,0.017952,41.825649,2.130700,0.179516,-153.503769,0.018966,0.000000
24.590002,9.350273,-153.459274,-0.003729,0.000726,0.018429,41.592091,2.118802,0.184285,-153.459274,0.019565,0.000000
24.950001,9.578911,-153.503769,-0.003712,0.000750,0.019053,42.609123,2.170612,0.190529,-153.503769,0.020172,0.000000
25.310001,9.893188,-153.459274,-0.003695,0.000777,0.019747,44.007099,2.241828,0.197467,-153.459274,0.020770,0.000000
25.670002,9.736420,-153.637207,-0.003656,0.000797,0.020241,43.309757,2.206304,0.202410,-153.637207,0.021368,0.000000
26.030001,10.248802,-153.592728,-0.003639,0.000829,0.021048,45.588947,2.322412,0.210476,-153.592728,0.021967,0.000000
26.390001,10.277107,-153.548248,-0.003609,0.000852,0.021637,45.714855,2.328826,0.216373,-153.548248,0.022565,0.000000
26.750002,10.076401,-153.637207,-0.003613,0.000866,0.021993,44.822067,2.283345,0.219928,-153.637207,0.023164,0.000000
27.110001,10.569046,-153.637207,-0.003583,0.000896,0.022756,47.013466,2.394980,0.227560,-153.637207,0.023771,0.000000
27.470001,10.865829,-153.637207,-0.003540,0.000919,0.023354,48.333622,2.462232,0.233544,-153.637207,0.024369,0.000000
27.830002,11.129837,-153.726166,-0.003531,0.000950,0.024126,49.507988,2.522057,0.241262,-153.726166,0.024967,0.000000
28.190001,11.028557,-153.770645,-0.003505,0.000971,0.024673,49.057472,2.499107,0.246726,-153.770645,0.025566,0.000000
28.550001,11.002487,-153.770645,-0.003488,0.000991,0.025167,48.941505,2.493199,0.251669,-153.770645,0.026164,0.000000
28.910002,11.106377,-153.726166,-0.003466,0.001009,0.025618,49.403629,2.516741,0.256178,-153.726166,0.026771,0.000000
29.270000,11.642967,-153.815125,-0.003441,0.001040,0.026407,51.790504,2.638334,0.264070,-153.815125,0.027370,0.000000
29.630001,11.496254,-153.815125,-0.003415,0.001055,0.026806,51.137890,2.605088,0.268059,-153.815125,0.027968,0.000000
29.990002,11.853729,-153.904083,-0.003410,0.001085,0.027552,52.728020,2.686094,0.275518,-153.904083,0.028566,0.000000
30.350002,11.941238,-153.859604,-0.003372,0.001107,0.028124,53.117283,2.705923,0.281241,-153.859604,0.029165,0.000000
30.710001,12.051460,-153.859604,-0.003354,0.001130,0.028696,53.607574,2.730900,0.286965,-153.859604,0.029772,0.000000
31.070002,12.061516,-153.948578,-0.003337,0.001153,0.029278,53.652302,2.733179,0.292775,-153.948578,0.030370,0.000000
31.430002,12.291267,-153.904083,-0.003307,0.001174,0.029815,54.674290,2.785241,0.298152,-153.904083,0.030969,0.000000
31.790001,12.665878,-153.993057,-0.003285,0.001206,0.030630,56.340641,2.870129,0.306304,-153.993057,0.031567,0.000000
32.150002,12.877014,-153.948578,-0.003268,0.001232,0.031298,57.279819,2.917973,0.312982,-153.948578,0.032165,0.000000
32.510002,12.848335,-153.993057,-0.003225,0.001254,0.031853,57.152248,2.911474,0.318532,-153.993057,0.032772,0.000000
32.870003,13.011810,-154.082016,-0.003216,0.001274,0.032365,57.879421,2.948518,0.323649,-154.082016,0.033371,0.000000
33.230003,13.173790,-154.082016,-0.003203,0.001296,0.032929,58.599945,2.985224,0.329286,-154.082016,0.033969,0.000000
33.590000,13.569992,-154.126495,-0.003178,0.001322,0.033579,60.362339,3.075004,0.335790,-154.126495,0.034568,0.000000
33.950001,13.741287,-154.170975,-0.003156,0.001346,0.034195,61.124298,3.113820,0.341947,-154.170975,0.035166,0.000000
34.310001,13.913322,-154.126495,-0.003130,0.001370,0.034793,61.889549,3.152804,0.347931,-154.126495,0.035764,0.000000
34.670002,13.958008,-154.170975,-0.003104,0.001394,0.035400,62.088318,3.162930,0.354002,-154.170975,0.036371,0.000000
35.030003,13.904015,-154.170975,-0.003083,0.001408,0.035773,61.848145,3.150695,0.357731,-154.170975,0.036970,0.000000
35.390003,14.313622,-154.259933,-0.003074,0.001438,0.036536,63.670170,3.243513,0.365362,-154.259933,0.037568,0.000000
35.750000,14.586945,-154.215454,-0.003040,0.001463,0.037161,64.885971,3.305449,0.371606,-154.215454,0.038167,0.000000
36.110001,14.570930,-154.170975,-0.003018,0.001484,0.037698,64.814735,3.301820,0.376983,-154.170975,0.038765,0.000000
36.470001,14.956711,-154.304413,-0.003014,0.001507,0.038279,66.530769,3.389239,0.382793,-154.304413,0.039372,0.000000
36.830002,15.333176,-154.348907,-0.002962,0.001532,0.038921,68.205368,3.474547,0.389211,-154.348907,0.039970,0.000000
37.190002,15.595329,-154.348907,-0.002958,0.001556,0.039528,69.371490,3.533952,0.395281,-154.348907,0.040569,0.000000
37.550003,15.804977,-154.393387,-0.002923,0.001581,0.040161,70.304054,3.581459,0.401612,-154.393387,0.041167,0.000000
37.910004,15.590858,-154.348907,-0.002902,0.001595,0.040508,69.351601,3.532939,0.405081,-154.348907,0.041766,0.000000
38.270000,16.122978,-154.437866,-0.002884,0.001626,0.041297,71.718590,3.653519,0.412973,-154.437866,0.042373,0.000000
38.630001,16.300972,-154.393387,-0.002863,0.001650,0.041904,72.510345,3.693853,0.419043,-154.393387,0.042971,0.000000
38.990002,16.585838,-154.482346,-0.002820,0.001674,0.042511,73.777496,3.758405,0.425114,-154.482346,0.043569,0.000000
39.350002,16.759369,-154.482346,-0.002820,0.001698,0.043136,74.549393,3.797727,0.431358,-154.482346,0.044168,0.000000
39.710003,16.994705,-154.437866,-0.002794,0.001718,0.043630,75.596222,3.851055,0.436301,-154.437866,0.044766,0.000000
40.070004,17.282173,-154.571304,-0.002785,0.001745,0.044333,76.874947,3.916196,0.443326,-154.571304,0.045373,0.000000
40.430000,17.888397,-154.571304,-0.002751,0.001774,0.045070,79.571564,4.053569,0.450697,-154.571304,0.045972,0.000000
40.790001,17.533157,-154.660263,-0.002734,0.001790,0.045460,77.991379,3.973070,0.454600,-154.660263,0.046570,0.000000
41.150002,17.983727,-154.615784,-0.002703,0.001812,0.046032,79.995613,4.075171,0.460323,-154.615784,0.047168,0.000000
41.510002,18.133423,-154.571304,-0.002686,0.001837,0.046665,80.661491,4.109092,0.466654,-154.571304,0.047767,0.000000
41.870003,18.740387,-154.660263,-0.002665,0.001861,0.047272,83.361404,4.246632,0.472725,-154.660263,0.048365,0.000000
42.230003,18.357590,-154.660263,-0.002656,0.001873,0.047576,81.658638,4.159889,0.475760,-154.660263,0.048972,0.000000
42.590000,19.554390,-154.793716,-0.002626,0.001913,0.048599,86.982269,4.431088,0.485993,-154.793716,0.049571,0.000000
42.950001,19.620300,-154.749222,-0.002613,0.001934,0.049111,87.275452,4.446023,0.491110,-154.749222,0.050169,0.000000
43.310001,19.597214,-154.749222,-0.002570,0.001955,0.049657,87.172760,4.440792,0.496573,-154.749222,0.050767,0.000000
43.670002,20.287224,-154.704742,-0.002552,0.001981,0.050325,90.242081,4.597151,0.503251,-154.704742,0.051366,0.000000
44.030003,20.222801,-154.793716,-0.002548,0.002001,0.050819,89.955513,4.582552,0.508194,-154.793716,0.051973,0.000000
44.390003,20.586235,-154.838196,-0.002518,0.002021,0.051322,91.572144,4.664907,0.513224,-154.838196,0.052571,0.000000
44.750004,21.384232,-154.793716,-0.002505,0.002052,0.052120,95.121811,4.845736,0.521203,-154.793716,0.053170,0.000000
45.110001,21.553658,-154.882675,-0.002488,0.002074,0.052684,95.875458,4.884129,0.526840,-154.882675,0.053768,0.000000
45.470001,22.124138,-154.882675,-0.002449,0.002100,0.053352,98.413078,5.013401,0.533517,-154.882675,0.054366,0.000000
45.830002,22.477516,-154.927155,-0.002432,0.002124,0.053941,99.984985,5.093478,0.539414,-154.927155,0.054973,0.000000
46.190002,22.535233,-154.971634,-0.002406,0.002143,0.054436,100.241722,5.106557,0.544358,-154.971634,0.055572,0.000000
46.550003,22.999580,-154.882675,-0.002389,0.002168,0.055069,102.307243,5.211780,0.550688,-154.882675,0.056170,0.000000
46.910004,23.308281,-154.971634,-0.002358,0.002187,0.055554,103.680412,5.281732,0.555545,-154.971634,0.056769,0.000000
47.270000,24.362465,-155.016113,-0.002345,0.002221,0.056422,108.369659,5.520614,0.564217,-155.016113,0.057367,0.000000
47.630001,24.625359,-155.060593,-0.002328,0.002246,0.057037,109.539062,5.580186,0.570374,-155.060593,0.057974,0.000000
47.990002,24.449974,-155.060593,-0.002315,0.002262,0.057445,108.758919,5.540443,0.574450,-155.060593,0.058572,0.000000
48.350002,24.950073,-155.060593,-0.002281,0.002283,0.057983,110.983467,5.653768,0.579827,-155.060593,0.059171,0.000000
48.710003,25.789024,-155.105072,-0.002264,0.002314,0.058772,114.715309,5.843876,0.587719,-155.105072,0.059769,0.000000
49.070004,26.259705,-155.105072,-0.002246,0.002333,0.059249,116.808998,5.950534,0.592489,-155.105072,0.060368,0.000000
49.430004,27.163452,-155.149551,-0.002225,0.002363,0.060029,120.829071,6.155326,0.600294,-155.149551,0.060966,0.000000
49.790001,27.320969,-155.194031,-0.002203,0.002386,0.060602,121.529739,6.191020,0.606017,-155.194031,0.061573,0.000000
50.150002,27.652008,-155.194031,-0.002190,0.002406,0.061113,123.002274,6.266035,0.611134,-155.194031,0.062171,0.000000
50.510002,28.254875,-155.238525,-0.002151,0.002428,0.061677,125.683960,6.402646,0.616771,-155.238525,0.062770,0.000000
50.870003,28.501389,-155.283005,-0.002151,0.002451,0.062249,126.780510,6.458507,0.622495,-155.283005,0.063368,0.000000
51.230003,28.624641,-155.283005,-0.002134,0.002463,0.062570,127.328766,6.486436,0.625703,-155.283005,0.063967,0.000000
51.590004,30.234779,-155.327484,-0.002113,0.002501,0.063516,134.491013,6.851299,0.635156,-155.327484,0.064574,0.000000
51.950001,30.670082,-155.283005,-0.002095,0.002522,0.064053,136.427338,6.949940,0.640533,-155.283005,0.065172,0.000000
52.310001,30.895744,-155.327484,-0.002070,0.002545,0.064634,137.431137,7.001076,0.646343,-155.327484,0.065770,0.000000
52.670002,31.930565,-155.327484,-0.002052,0.002567,0.065198,142.034241,7.235569,0.651980,-155.327484,0.066369,0.000000
53.030003,32.719246,-155.371964,-0.002022,0.002595,0.065918,145.542480,7.414287,0.659178,-155.371964,0.066967,0.000000
53.390003,33.964462,-155.460922,-0.002001,0.002626,0.066690,151.081467,7.696457,0.666897,-155.460922,0.067574,0.000000
53.750004,33.949570,-155.416443,-0.001992,0.002643,0.067132,151.015228,7.693083,0.671319,-155.416443,0.068173,0.000000
54.110004,34.883850,-155.505402,-0.001966,0.002670,0.067808,155.171112,7.904793,0.678084,-155.505402,0.068771,0.000000
54.470001,35.187332,-155.460922,-0.001949,0.002690,0.068320,156.521072,7.973563,0.683200,-155.460922,0.069369,0.000000
54.830002,35.736580,-155.505402,-0.001936,0.002715,0.068953,158.964249,8.098024,0.689531,-155.505402,0.069968,0.000000
55.190002,36.836571,-155.505402,-0.001914,0.002736,0.069491,163.857254,8.347286,0.694908,-155.505402,0.070575,0.000000
55.550003,37.663239,-155.549881,-0.001897,0.002761,0.070141,167.534454,8.534612,0.701412,-155.549881,0.071173,0.000000
55.910004,38.715561,-155.594360,-0.001880,0.002786,0.070766,172.215424,8.773072,0.707656,-155.594360,0.071772,0.000000
56.270004,39.326996,-155.549881,-0.001863,0.002807,0.071286,174.935211,8.911625,0.712860,-155.549881,0.072370,0.000000
56.630001,40.152550,-155.638855,-0.001845,0.002831,0.071902,178.607468,9.098699,0.719017,-155.638855,0.072968,0.000000
56.990002,41.199287,-155.594360,-0.001824,0.002855,0.072509,183.263580,9.335892,0.725087,-155.594360,0.073567,0.000000
57.350002,41.240990,-155.727814,-0.001807,0.002869,0.072873,183.449081,9.345342,0.728730,-155.727814,0.074174,0.000000
57.710003,42.664948,-155.772293,-0.001811,0.002899,0.073636,189.783173,9.668015,0.736361,-155.772293,0.074772,0.000000
58.070004,43.775360,-155.727814,-0.001789,0.002923,0.074252,194.722534,9.919639,0.742519,-155.727814,0.075371,0.000000
58.430004,44.795288,-155.772293,-0.001768,0.002949,0.074902,199.259399,10.150758,0.749023,-155.772293,0.075969,0.000000
58.790001,45.888947,-155.727814,-0.001742,0.002970,0.075431,204.124222,10.398584,0.754313,-155.727814,0.076567,0.000000
59.150002,46.805725,-155.816772,-0.001729,0.002993,0.076030,208.202271,10.606329,0.760297,-155.816772,0.077174,0.000000
59.510002,48.129509,-155.816772,-0.001725,0.003021,0.076723,214.090744,10.906302,0.767235,-155.816772,0.077773,0.000000
59.870003,49.064911,-155.816772,-0.001699,0.003043,0.077287,218.251617,11.118267,0.772872,-155.816772,0.078371,0.000000
60.230003,50.019302,-155.905731,-0.001686,0.003067,0.077894,222.496964,11.334536,0.778942,-155.905731,0.078970,0.000000
60.590004,50.768143,-155.861252,-0.001673,0.003085,0.078354,225.827972,11.504225,0.783538,-155.861252,0.079568,0.000000
60.950005,52.397644,-155.950211,-0.001651,0.003113,0.079082,233.076355,11.873476,0.790823,-155.950211,0.080175,0.000000
61.310001,53.506569,-155.950211,-0.001634,0.003139,0.079724,238.009109,12.124762,0.797241,-155.950211,0.080773,0.000000
61.670002,54.992706,-155.950211,-0.001617,0.003165,0.080400,244.619781,12.461526,0.804005,-155.950211,0.081372,0.000000
62.030003,55.490196,-155.994690,-0.001608,0.003180,0.080765,246.832718,12.574259,0.807647,-155.994690,0.081970,0.000000
62.390003,56.902603,-155.950211,-0.001595,0.003206,0.081424,253.115417,12.894315,0.814238,-155.950211,0.082569,0.000000
62.750004,57.425789,-156.039169,-0.001582,0.003223,0.081875,255.442673,13.012870,0.818748,-156.039169,0.083176,0.000000
63.110004,58.490028,-156.039169,-0.001569,0.003244,0.082395,260.176636,13.254030,0.823951,-156.039169,0.083774,0.000000
63.470001,60.124748,-156.039169,-0.001556,0.003270,0.083063,267.448242,13.624463,0.830629,-156.039169,0.084372,0.000000
63.830002,62.564529,-156.128143,-0.001544,0.003305,0.083956,278.300934,14.177324,0.839561,-156.128143,0.084971,0.000000
64.190002,63.628403,-156.128143,-0.001531,0.003328,0.084520,283.033264,14.418402,0.845198,-156.128143,0.085569,0.000000
64.550003,64.169083,-156.217102,-0.001505,0.003343,0.084901,285.438324,14.540922,0.849014,-156.217102,0.086168,0.000000
64.910004,66.199631,-156.172623,-0.001505,0.003374,0.085691,294.470673,15.001051,0.856906,-156.172623,0.086775,0.000000
65.270004,65.159973,-156.217102,-0.001483,0.003366,0.085491,289.846039,14.765461,0.854911,-156.217102,290.323059,0.000000
65.630005,66.211548,-156.217102,-0.001475,0.003362,0.085404,294.523682,15.003752,0.854044,-156.217102,294.500458,0.000000
65.990005,65.263489,-156.217102,-0.001466,0.003363,0.085413,290.306488,14.788918,0.854131,-156.217102,294.500458,0.000000
66.350006,65.112305,-156.306061,-0.001475,0.003393,0.086176,289.634003,14.754659,0.861762,-156.306061,294.500458,0.000000
66.710007,64.822601,-156.217102,-0.001475,0.003397,0.086280,288.345337,14.689012,0.862803,-156.217102,294.500458,0.000000
67.070000,65.197205,-156.306061,-0.001462,0.003407,0.086540,290.011658,14.773898,0.865405,-156.306061,294.500458,0.000000
67.430000,65.306305,-156.395020,-0.001457,0.003415,0.086731,290.496948,14.798620,0.867312,-156.395020,294.500458,0.000000
67.790001,65.185654,-156.395020,-0.001440,0.003418,0.086818,289.960266,14.771280,0.868180,-156.395020,294.500458,0.000000
68.150002,64.737320,-156.395020,-0.001436,0.003418,0.086818,287.965973,14.669686,0.868180,-156.395020,294.500458,0.000000
68.510002,65.870087,-156.439499,-0.001427,0.003425,0.086983,293.004791,14.926375,0.869827,-156.439499,294.500458,0.000000
68.870003,65.320465,-156.483978,-0.001423,0.003425,0.086983,290.559937,14.801828,0.869827,-156.483978,294.500458,0.000000
69.230003,64.907120,-156.528473,-0.001423,0.003425,0.086983,288.721283,14.708163,0.869827,-156.528473,294.500458,0.000000
69.590004,64.479645,-156.528473,-0.001431,0.003425,0.086991,286.819794,14.611297,0.869914,-156.528473,294.500458,0.000000
69.950005,66.350815,-156.528473,-0.001410,0.003400,0.086367,295.143158,15.035310,0.863670,-156.528473,294.500458,0.000000
70.310005,65.900986,-156.528473,-0.001406,0.003400,0.086367,293.142212,14.933376,0.863670,-156.528473,294.500458,0.000000
70.670006,65.563248,-156.528473,-0.001397,0.003403,0.086428,291.639893,14.856845,0.864277,-156.528473,294.500458,0.000000
71.030006,65.258652,-156.617432,-0.001410,0.003422,0.086922,290.284973,14.787822,0.869220,-156.617432,294.500458,0.000000
71.390007,64.991653,-156.572952,-0.001397,0.003429,0.087095,289.097321,14.727320,0.870955,-156.572952,294.500458,0.000000
71.750000,65.243011,-156.706390,-0.001401,0.003448,0.087590,290.215424,14.784278,0.875898,-156.706390,294.500458,0.000000
72.110001,65.068741,-156.617432,-0.001393,0.003449,0.087616,289.440216,14.744787,0.876158,-156.617432,294.500458,0.000000
72.470001,65.266098,-156.706390,-0.001393,0.003455,0.087755,290.318115,14.789509,0.877546,-156.706390,294.500458,0.000000
72.830002,65.095551,-156.706390,-0.001388,0.003455,0.087755,289.559479,14.750862,0.877546,-156.706390,294.500458,0.000000
73.190002,65.294769,-156.750870,-0.001393,0.003460,0.087885,290.445648,14.796006,0.878847,-156.750870,294.500458,0.000000
73.550003,65.171143,-156.750870,-0.001393,0.003460,0.087893,289.895721,14.767992,0.878933,-156.750870,294.500458,0.000000
73.910004,65.037460,-156.839828,-0.001397,0.003462,0.087928,289.301086,14.737700,0.879280,-156.839828,294.500458,0.000000
74.270004,65.092560,-156.839828,-0.001393,0.003465,0.088015,289.546173,14.750185,0.880147,-156.839828,294.500458,0.000000
74.630005,65.246353,-156.795349,-0.001384,0.003470,0.088127,290.230286,14.785034,0.881275,-156.795349,294.500458,0.000000
74.990005,65.238159,-156.884308,-0.001388,0.003470,0.088127,290.193817,14.783178,0.881275,-156.884308,294.500458,0.000000
75.350006,65.103363,-156.928802,-0.001388,0.003470,0.088127,289.594208,14.752633,0.881275,-156.928802,294.500458,0.000000
75.710007,65.073196,-156.928802,-0.001367,0.003471,0.088171,289.460022,14.745797,0.881708,-156.928802,294.500458,0.000000
76.070007,64.980484,-156.973282,-0.001393,0.003472,0.088188,289.047638,14.724789,0.881882,-156.973282,294.500458,0.000000
76.430000,65.412811,-156.928802,-0.001375,0.003478,0.088344,290.970703,14.822755,0.883443,-156.928802,294.500458,0.000000
76.790001,65.316742,-157.017761,-0.001380,0.003478,0.088344,290.543365,14.800985,0.883443,-157.017761,294.500458,0.000000
77.150002,65.208008,-157.017761,-0.001380,0.003478,0.088353,290.059692,14.776345,0.883530,-157.017761,294.500458,0.000000
77.510002,65.066879,-157.062241,-0.001375,0.003478,0.088353,289.431946,14.744366,0.883530,-157.062241,294.500458,0.000000
77.870003,64.954422,-157.106720,-0.001384,0.003478,0.088353,288.931702,14.718883,0.883530,-157.106720,294.500458,0.000000
78.230003,64.926865,-157.106720,-0.001367,0.003480,0.088396,288.809113,14.712638,0.883963,-157.106720,294.500458,0.000000
78.590004,65.474243,-157.151199,-0.001371,0.003487,0.088570,291.243988,14.836676,0.885698,-157.151199,294.500458,0.000000
78.950005,65.394562,-157.151199,-0.001367,0.003487,0.088570,290.889526,14.818619,0.885698,-157.151199,294.500458,0.000000
79.310005,65.286194,-157.151199,-0.001354,0.003487,0.088570,290.407501,14.794064,0.885698,-157.151199,294.500458,0.000000
79.670006,65.217682,-157.151199,-0.001371,0.003487,0.088570,290.102753,14.778538,0.885698,-157.151199,294.500458,0.000000
80.030006,65.073944,-157.240158,-0.001371,0.003487,0.088570,289.463348,14.745967,0.885698,-157.240158,294.500458,0.000000
80.390007,64.995743,-157.284637,-0.001367,0.003487,0.088570,289.115509,14.728246,0.885698,-157.284637,294.500458,0.000000
80.750008,64.879562,-157.284637,-0.001380,0.003494,0.088752,288.598694,14.701919,0.887519,-157.284637,294.500458,0.000000
81.110001,65.832840,-157.284637,-0.001358,0.003498,0.088856,292.839111,14.917934,0.888559,-157.284637,294.500458,0.000000
81.470001,65.749802,-157.284637,-0.001371,0.003498,0.088856,292.469727,14.899118,0.888559,-157.284637,294.500458,0.000000
81.830002,65.656708,-157.284637,-0.001367,0.003498,0.088856,292.055634,14.878023,0.888559,-157.284637,294.500458,0.000000
82.190002,65.566223,-157.373611,-0.001367,0.003498,0.088856,291.653137,14.857518,0.888559,-157.373611,294.500458,0.000000
82.550003,65.508499,-157.373611,-0.001354,0.003498,0.088856,291.396362,14.844439,0.888559,-157.373611,294.500458,0.000000
82.910004,65.386734,-157.373611,-0.001358,0.003498,0.088856,290.854706,14.816845,0.888559,-157.373611,294.500458,0.000000
83.270004,65.302963,-157.418091,-0.001367,0.003498,0.088856,290.482086,14.797863,0.888559,-157.418091,294.500458,0.000000
83.630005,65.226242,-157.418091,-0.001362,0.003498,0.088856,290.140808,14.780478,0.888559,-157.418091,294.500458,0.000000
83.990005,65.120865,-157.507050,-0.001362,0.003498,0.088856,289.672089,14.756599,0.888559,-157.507050,294.500458,0.000000
84.350006,65.035217,-157.462570,-0.001367,0.003498,0.088856,289.291107,14.737191,0.888559,-157.462570,294.500458,0.000000
84.710007,65.044159,-157.507050,-0.001345,0.003502,0.088943,289.330872,14.739217,0.889427,-157.507050,294.500458,0.000000
85.070007,65.072083,-157.551529,-0.001350,0.003502,0.088943,289.455078,14.745544,0.889427,-157.551529,294.500458,0.000000
85.430000,65.027023,-157.551529,-0.001350,0.003502,0.088951,289.254639,14.735333,0.889513,-157.551529,294.500458,0.000000
85.790001,65.089218,-157.596008,-0.001354,0.003504,0.088995,289.531311,14.749428,0.889947,-157.596008,294.500458,0.000000
86.150002,65.046021,-157.596008,-0.001367,0.003504,0.088995,289.339142,14.739638,0.889947,-157.596008,294.500458,0.000000
86.510002,65.009155,-157.640488,-0.001345,0.003504,0.088995,289.175171,14.731285,0.889947,-157.640488,294.500458,0.000000
86.870003,64.941757,-157.640488,-0.001362,0.003504,0.088995,288.875366,14.716012,0.889947,-157.640488,294.500458,0.000000
87.230003,64.888885,-157.729446,-0.001350,0.003504,0.088995,288.640167,14.704031,0.889947,-157.729446,294.500458,0.000000
87.590004,65.601974,-157.773926,-0.001350,0.003513,0.089229,291.812164,14.865620,0.892289,-157.773926,294.500458,0.000000
87.950005,65.620590,-157.729446,-0.001362,0.003513,0.089229,291.894958,14.869839,0.892289,-157.729446,294.500458,0.000000
88.310005,65.560638,-157.818420,-0.001354,0.003513,0.089229,291.628296,14.856253,0.892289,-157.818420,294.500458,0.000000
88.670006,65.540527,-157.773926,-0.001350,0.003513,0.089229,291.538818,14.851695,0.892289,-157.773926,294.500458,0.000000
89.030006,65.483932,-157.818420,-0.001350,0.003513,0.089229,291.287079,14.838871,0.892289,-157.818420,294.500458,0.000000
89.390007,65.439240,-157.818420,-0.001341,0.003513,0.089229,291.088287,14.828744,0.892289,-157.818420,294.500458,0.000000
89.750008,65.353607,-157.907379,-0.001337,0.003513,0.089229,290.707367,14.809340,0.892289,-157.907379,294.500458,0.000000
90.110001,65.310410,-157.862900,-0.001341,0.003513,0.089229,290.515198,14.799551,0.892289,-157.862900,294.500458,0.000000
90.470001,65.250824,-157.907379,-0.001345,0.003513,0.089229,290.250153,14.786048,0.892289,-157.907379,294.500458,0.000000
90.830002,65.207626,-157.907379,-0.001345,0.003513,0.089229,290.058014,14.776259,0.892289,-157.907379,294.500458,0.000000
91.190002,65.127197,-158.040817,-0.001354,0.003513,0.089229,289.700256,14.758034,0.892289,-158.040817,294.500458,0.000000
91.550003,65.051605,-157.951859,-0.001350,0.003513,0.089229,289.363983,14.740905,0.892289,-157.951859,294.500458,0.000000
91.910004,65.004318,-158.085297,-0.001337,0.003513,0.089229,289.153656,14.730189,0.892289,-158.085297,294.500458,0.000000
92.270004,64.974152,-157.996338,-0.001337,0.003513,0.089229,289.019470,14.723353,0.892289,-157.996338,294.500458,0.000000
92.630005,64.914566,-158.040817,-0.001345,0.003513,0.089229,288.754425,14.709851,0.892289,-158.040817,294.500458,0.000000
92.990005,64.850159,-158.129776,-0.001345,0.003521,0.089437,288.467926,14.695256,0.894370,-158.129776,294.500458,0.000000
93.350006,65.767303,-158.129776,-0.001328,0.003524,0.089498,292.547577,14.903084,0.894977,-158.129776,294.500458,0.000000
93.710007,65.791138,-158.218750,-0.001341,0.003524,0.089498,292.653595,14.908484,0.894977,-158.218750,294.500458,0.000000
94.070007,65.746826,-158.129776,-0.001332,0.003524,0.089498,292.456482,14.898444,0.894977,-158.129776,294.500458,0.000000
94.430008,65.720764,-158.218750,-0.001328,0.003524,0.089498,292.340546,14.892538,0.894977,-158.218750,294.500458,0.000000
94.790001,65.643677,-158.263229,-0.001337,0.003524,0.089498,291.997650,14.875070,0.894977,-158.263229,294.500458,0.000000
95.150002,65.603088,-158.263229,-0.001341,0.003524,0.089498,291.817108,14.865872,0.894977,-158.263229,294.500458,0.000000
95.510002,65.562500,-158.263229,-0.001341,0.003524,0.089498,291.636566,14.856675,0.894977,-158.263229,294.500458,0.000000
95.870003,65.534576,-158.263229,-0.001350,0.003524,0.089498,291.512360,14.850348,0.894977,-158.263229,294.500458,0.000000
96.230003,65.498077,-158.307709,-0.001350,0.003524,0.089498,291.350006,14.842077,0.894977,-158.307709,294.500458,0.000000
96.590004,65.448547,-158.352188,-0.001345,0.003524,0.089498,291.129669,14.830853,0.894977,-158.352188,294.500458,0.000000
96.950005,65.392319,-158.352188,-0.001341,0.003524,0.089506,290.879547,14.818110,0.895064,-158.352188,294.500458,0.000000
97.310005,65.337585,-158.396667,-0.001315,0.003524,0.089506,290.636108,14.805709,0.895064,-158.396667,294.500458,0.000000
97.670006,65.299240,-158.352188,-0.001341,0.003524,0.089506,290.465515,14.797020,0.895064,-158.352188,294.500458,0.000000
98.030006,65.259018,-158.396667,-0.001341,0.003524,0.089506,290.286621,14.787905,0.895064,-158.396667,294.500458,0.000000
98.390007,65.216202,-158.396667,-0.001337,0.003524,0.089506,290.096161,14.778203,0.895064,-158.396667,294.500458,0.000000
98.750008,65.185654,-158.485626,-0.001328,0.003524,0.089506,289.960266,14.771280,0.895064,-158.485626,294.500458,0.000000
99.110008,65.116776,-158.530106,-0.001337,0.003524,0.089506,289.653870,14.755672,0.895064,-158.530106,294.500458,0.000000
99.470001,65.069855,-158.530106,-0.001332,0.003524,0.089506,289.445160,14.745040,0.895064,-158.530106,294.500458,0.000000
99.830002,65.035965,-158.619064,-0.001324,0.003524,0.089506,289.294434,14.737360,0.895064,-158.619064,294.500458,0.000000
100.190002,64.996124,-158.619064,-0.001345,0.003524,0.089506,289.117187,14.728333,0.895064,-158.619064,294.500458,0.000000
100.550003,64.951065,-158.574585,-0.001328,0.003524,0.089506,288.916779,14.718122,0.895064,-158.574585,294.500458,0.000000
100.910004,64.915695,-158.663559,-0.001337,0.003524,0.089506,288.759430,14.710107,0.895064,-158.663559,294.500458,0.000000
101.270004,64.866165,-158.708038,-0.001341,0.003524,0.089506,288.539124,14.698883,0.895064,-158.708038,294.500458,0.000000
101.630005,65.329773,-158.663559,-0.001319,0.003533,0.089732,290.601349,14.803939,0.897318,-158.663559,294.500458,0.000000
101.990005,65.489517,-158.663559,-0.001328,0.003533,0.089732,291.311920,14.840137,0.897318,-158.663559,294.500458,0.000000
102.350006,65.507767,-158.708038,-0.001341,0.003533,0.089732,291.393097,14.844272,0.897318,-158.708038,294.500458,0.000000
102.710007,65.483932,-158.796997,-0.001332,0.003533,0.089732,291.287079,14.838871,0.897318,-158.796997,294.500458,0.000000
103.070007,65.486542,-158.796997,-0.001328,0.003533,0.089732,291.298676,14.839462,0.897318,-158.796997,294.500458,0.000000
103.430008,65.460846,-158.796997,-0.001324,0.003533,0.089732,291.184387,14.833639,0.897318,-158.796997,294.500458,0.000000
103.790009,65.411682,-158.841476,-0.001328,0.003533,0.089732,290.965698,14.822499,0.897318,-158.841476,294.500458,0.000000
104.150002,65.359924,-158.885956,-0.001328,0.003533,0.089732,290.735474,14.810771,0.897318,-158.885956,294.500458,0.000000
104.510002,65.346527,-158.930435,-0.001337,0.003533,0.089732,290.675873,14.807735,0.897318,-158.930435,294.500458,0.000000
104.870003,65.312637,-158.841476,-0.001315,0.003533,0.089732,290.525116,14.800055,0.897318,-158.841476,294.500458,0.000000
105.230003,65.297379,-158.885956,-0.001328,0.003533,0.089732,290.457245,14.796597,0.897318,-158.885956,294.500458,0.000000
105.590004,65.269073,-158.930435,-0.001341,0.003533,0.089732,290.331329,14.790184,0.897318,-158.930435,294.500458,0.000000
105.950005,65.233322,-158.930435,-0.001324,0.003533,0.089732,290.172302,14.782083,0.897318,-158.930435,294.500458,0.000000
106.310005,65.197205,-158.930435,-0.001328,0.003533,0.089732,290.011658,14.773898,0.897318,-158.930435,294.500458,0.000000
106.670006,65.157730,-159.019394,-0.001328,0.003533,0.089732,289.836060,14.764953,0.897318,-159.019394,294.500458,0.000000
107.030006,65.117889,-158.974915,-0.001332,0.003533,0.089732,289.658844,14.755924,0.897318,-158.974915,294.500458,0.000000
107.390007,65.073944,-159.063889,-0.001332,0.003533,0.089732,289.463348,14.745967,0.897318,-159.063889,294.500458,0.000000
107.750008,65.064636,-159.108368,-0.001315,0.003533,0.089732,289.421967,14.743857,0.897318,-159.108368,294.500458,0.000000
108.110008,65.031494,-159.108368,-0.001324,0.003534,0.089758,289.274536,14.736347,0.897579,-159.108368,294.500458,0.000000
108.470009,65.032242,-159.063889,-0.001319,0.003534,0.089775,289.277863,14.736517,0.897752,-159.063889,294.500458,0.000000
108.830002,65.033737,-159.152847,-0.001319,0.003534,0.089775,289.284515,14.736856,0.897752,-159.152847,294.500458,0.000000
109.190002,65.015106,-159.152847,-0.001324,0.003534,0.089775,289.201630,14.732634,0.897752,-159.152847,294.500458,0.000000
109.550003,65.008041,-159.241806,-0.001315,0.003535,0.089784,289.170197,14.731032,0.897839,-159.241806,294.500458,0.000000
109.910004,64.980103,-159.241806,-0.001311,0.003535,0.089784,289.045929,14.724701,0.897839,-159.241806,294.500458,0.000000
110.270004,64.974899,-159.241806,-0.001337,0.003535,0.089784,289.022797,14.723523,0.897839,-159.241806,294.500458,0.000000
110.630005,64.948837,-159.330765,-0.001319,0.003535,0.089784,288.906860,14.717617,0.897839,-159.330765,294.500458,0.000000
110.990005,65.106339,-159.286285,-0.001315,0.003538,0.089862,289.607452,14.753307,0.898619,-159.286285,294.500458,0.000000
111.350006,65.126083,-159.330765,-0.001319,0.003538,0.089862,289.695282,14.757781,0.898619,-159.330765,294.500458,0.000000
111.710007,65.119751,-159.375244,-0.001311,0.003538,0.089862,289.667114,14.756347,0.898619,-159.375244,294.500458,0.000000
112.070007,65.079529,-159.419724,-0.001324,0.003538,0.089862,289.488190,14.747232,0.898619,-159.419724,294.500458,0.000000
112.430008,65.083252,-159.419724,-0.001319,0.003538,0.089862,289.504761,14.748075,0.898619,-159.419724,294.500458,0.000000
112.790009,65.075439,-159.419724,-0.001337,0.003538,0.089862,289.470001,14.746305,0.898619,-159.419724,294.500458,0.000000
113.150009,65.047134,-159.419724,-0.001324,0.003538,0.089862,289.344116,14.739891,0.898619,-159.419724,294.500458,0.000000
113.510002,65.022186,-159.508698,-0.001332,0.003538,0.089862,289.233124,14.734238,0.898619,-159.508698,294.500458,0.000000
113.870003,64.993881,-159.508698,-0.001319,0.003538,0.089862,289.107208,14.727824,0.898619,-159.508698,294.500458,0.000000
114.230003,64.976379,-159.553177,-0.001315,0.003538,0.089871,289.029358,14.723858,0.898706,-159.553177,294.500458,0.000000
114.590004,65.486542,-159.553177,-0.001324,0.003545,0.090044,291.298676,14.839462,0.900440,-159.553177,294.500458,0.000000
114.950005,65.520416,-159.553177,-0.001315,0.003545,0.090044,291.449371,14.847138,0.900440,-159.553177,294.500458,0.000000
115.310005,65.534195,-159.642136,-0.001332,0.003545,0.090044,291.510651,14.850261,0.900440,-159.642136,294.500458,0.000000
115.670006,65.529739,-159.597656,-0.001319,0.003545,0.090035,291.490845,14.849252,0.900354,-159.597656,294.500458,0.000000
116.030006,65.515579,-159.642136,-0.001302,0.003545,0.090035,291.427856,14.846043,0.900354,-159.642136,294.500458,0.000000
116.390007,65.501053,-159.642136,-0.001311,0.003545,0.090035,291.363220,14.842751,0.900354,-159.642136,294.500458,0.000000
116.750008,65.493988,-159.642136,-0.001311,0.003545,0.090035,291.331818,14.841150,0.900354,-159.642136,294.500458,0.000000
117.110008,65.466431,-159.775574,-0.001319,0.003545,0.090035,291.209229,14.834905,0.900354,-159.775574,294.500458,0.000000
117.470009,65.440369,-159.686615,-0.001315,0.003545,0.090035,291.093292,14.829000,0.900354,-159.686615,294.500458,0.000000
117.830002,65.409454,-159.820053,-0.001311,0.003545,0.090035,290.955780,14.821995,0.900354,-159.820053,294.500458,0.000000
118.190002,65.378174,-159.775574,-0.001306,0.003545,0.090035,290.816650,14.814906,0.900354,-159.775574,294.500458,0.000000
118.550003,65.355087,-159.731094,-0.001311,0.003545,0.090035,290.713959,14.809674,0.900354,-159.731094,294.500458,0.000000
118.910004,65.324921,-159.909012,-0.001319,0.003545,0.090035,290.579773,14.802838,0.900354,-159.909012,294.500458,0.000000
119.270004,65.318222,-159.909012,-0.001311,0.003545,0.090035,290.549957,14.801320,0.900354,-159.909012,294.500458,0.000000
119.630005,65.292160,-159.909012,-0.001315,0.003545,0.090035,290.434021,14.795415,0.900354,-159.909012,294.500458,0.000000
119.990005,65.256042,-159.997986,-0.001311,0.003545,0.090035,290.273376,14.787230,0.900354,-159.997986,294.500458,0.000000
120.350006,65.262741,-159.953506,-0.001302,0.003545,0.090044,290.303162,14.788749,0.900440,-159.953506,294.500458,0.000000
120.710007,65.219177,-159.997986,-0.001315,0.003545,0.090044,290.109375,14.778876,0.900440,-159.997986,294.500458,0.000000
121.070007,65.231461,-159.953506,-0.001311,0.003545,0.090044,290.164032,14.781660,0.900440,-159.953506,294.500458,0.000000
121.430008,65.184174,-159.997986,-0.001315,0.003545,0.090044,289.953674,14.770945,0.900440,-159.997986,294.500458,0.000000
121.790009,65.163315,-159.997986,-0.001306,0.003545,0.090044,289.860901,14.766218,0.900440,-159.997986,294.500458,0.000000
122.150009,65.138367,-159.997986,-0.001311,0.003545,0.090044,289.749939,14.760565,0.900440,-159.997986,294.500458,0.000000
122.510002,65.109695,-160.131424,-0.001324,0.003545,0.090044,289.622375,14.754068,0.900440,-160.131424,294.500458,0.000000
122.870003,65.097412,-160.086945,-0.001306,0.003545,0.090044,289.567749,14.751285,0.900440,-160.086945,294.500458,0.000000
123.230003,65.070221,-160.131424,-0.001306,0.003545,0.090044,289.446808,14.745123,0.900440,-160.131424,294.500458,0.000000
123.590004,65.040802,-160.175903,-0.001315,0.003545,0.090044,289.315948,14.738456,0.900440,-160.175903,294.500458,0.000000
123.950005,65.040802,-160.131424,-0.001311,0.003545,0.090044,289.315948,14.738456,0.900440,-160.131424,294.500458,0.000000
124.310005,65.014740,-160.309341,-0.001311,0.003545,0.090044,289.200012,14.732551,0.900440,-160.309341,294.500458,0.000000
124.670006,64.991653,-160.220383,-0.001319,0.003545,0.090044,289.097321,14.727320,0.900440,-160.220383,294.500458,0.000000
125.030006,64.973404,-160.175903,-0.001311,0.003545,0.090044,289.016144,14.723184,0.900440,-160.175903,294.500458,0.000000
125.390007,64.961487,-160.309341,-0.001311,0.003545,0.090044,288.963135,14.720484,0.900440,-160.309341,294.500458,0.000000
125.750008,64.919785,-160.220383,-0.001298,0.003537,0.089845,288.777618,14.711034,0.898446,-160.220383,0.089923,0.000000
126.110008,64.852753,-160.398315,-0.001319,0.003526,0.089567,288.479462,14.695844,0.895671,-160.398315,0.089316,0.000000
126.470009,64.783875,-160.398315,-0.001319,0.003513,0.089238,288.173065,14.680236,0.892375,-160.398315,0.088717,0.000000
126.830009,64.745880,-160.309341,-0.001306,0.003484,0.088500,288.004059,14.671626,0.885004,-160.309341,0.088119,0.000000
127.190002,64.700836,-160.353836,-0.001311,0.003465,0.088015,287.803680,14.661419,0.880147,-160.353836,0.087520,0.000000
127.550003,64.666565,-160.353836,-0.001298,0.003440,0.087382,287.651245,14.653653,0.873817,-160.353836,0.086922,0.000000
127.910004,64.642746,-160.487274,-0.001298,0.003417,0.086792,287.545288,14.648255,0.867919,-160.487274,0.086315,0.000000
128.270004,64.605133,-160.398315,-0.001306,0.003397,0.086289,287.377991,14.639732,0.862890,-160.398315,0.085717,0.000000
128.630005,64.586136,-160.531754,-0.001293,0.003374,0.085699,287.293488,14.635427,0.856992,-160.531754,0.085118,0.000000
128.990005,64.504211,-160.487274,-0.001311,0.003347,0.085005,286.929077,14.616863,0.850055,-160.487274,0.084520,0.000000
129.350006,64.469208,-160.487274,-0.001298,0.003329,0.084546,286.773346,14.608932,0.845458,-160.487274,0.083921,0.000000
129.710007,64.011948,-160.620712,-0.001311,0.003304,0.083913,284.739349,14.505315,0.839128,-160.620712,0.083323,0.000000
130.070007,63.311142,-160.620712,-0.001302,0.003285,0.083444,281.622040,14.346510,0.834445,-160.620712,0.082716,0.000000
130.430008,62.485962,-160.620712,-0.001289,0.003264,0.082915,277.951447,14.159521,0.829154,-160.620712,0.082118,0.000000
130.790009,61.219894,-160.665192,-0.001276,0.003237,0.082222,272.319702,13.872627,0.822217,-160.665192,0.081519,0.000000
131.150009,59.826851,-160.665192,-0.001272,0.003217,0.081719,266.123138,13.556958,0.817187,-160.665192,0.080921,0.000000
131.510010,58.678078,-160.709671,-0.001272,0.003201,0.081311,261.013123,13.296642,0.813111,-160.709671,0.080322,0.000000
131.870010,57.779541,-160.709671,-0.001285,0.003187,0.080938,257.016235,13.093031,0.809382,-160.709671,0.079715,0.000000
132.230011,54.675072,-160.709671,-0.001276,0.003152,0.080062,243.206863,12.389548,0.800623,-160.709671,0.079117,0.000000
132.590012,53.548645,-160.798645,-0.001268,0.003135,0.079629,238.196274,12.134296,0.796287,-160.798645,0.078519,0.000000
132.950012,49.881897,-160.709671,-0.001276,0.003103,0.078805,221.885757,11.303400,0.788048,-160.709671,0.077920,0.000000
133.310013,47.285339,-160.843124,-0.001263,0.003079,0.078206,210.335693,10.715011,0.782064,-160.843124,0.077322,0.000000
133.670013,45.168030,-160.843124,-0.001268,0.003060,0.077712,200.917435,10.235222,0.777121,-160.843124,0.076715,0.000000
134.029999,43.126312,-160.843124,-0.001281,0.003041,0.077244,191.835419,9.772563,0.772438,-160.843124,0.076116,0.000000
134.389999,40.969162,-160.887604,-0.001276,0.003022,0.076749,182.239929,9.283745,0.767495,-160.887604,0.075518,0.000000
134.750000,37.155693,-160.932083,-0.001272,0.002984,0.075796,165.276779,8.419600,0.757955,-160.932083,0.074920,0.000000
135.110001,34.410568,-160.932083,-0.001263,0.002961,0.075197,153.065857,7.797546,0.751971,-160.932083,0.074321,0.000000
135.470001,31.952904,-160.932083,-0.001268,0.002936,0.074573,142.133621,7.240632,0.745727,-160.932083,0.073714,0.000000
135.830002,30.455597,-160.976562,-0.001263,0.002924,0.074278,135.473267,6.901337,0.742779,-160.976562,0.073116,0.000000
136.190002,27.656471,-161.065521,-0.001276,0.002897,0.073593,123.022125,6.267046,0.735928,-161.065521,0.072517,0.000000
136.550003,25.059547,-161.021042,-0.001285,0.002874,0.073012,111.470436,5.678575,0.730117,-161.021042,0.071919,0.000000
136.910004,21.859383,-161.110001,-0.001276,0.002843,0.072223,97.235390,4.953407,0.722226,-161.110001,0.071321,0.000000
137.270004,19.497047,-161.065521,-0.001281,0.002821,0.071659,86.727196,4.418094,0.716589,-161.065521,0.070722,0.000000
137.630005,17.061729,-161.065521,-0.001272,0.002798,0.071069,75.894363,3.866243,0.710692,-161.065521,0.070115,0.000000
137.990005,14.541885,-161.154480,-0.001293,0.002776,0.070514,64.685539,3.295238,0.705141,-161.154480,0.069517,0.000000
138.350006,12.594009,-161.154480,-0.001272,0.002760,0.070107,56.020950,2.853843,0.701065,-161.154480,0.068918,0.000000
138.710007,9.067268,-161.154480,-0.001263,0.002725,0.069213,40.333225,2.054672,0.692133,-161.154480,0.068320,0.000000
139.070007,6.630836,-161.154480,-0.001285,0.002703,0.068667,29.495434,1.502569,0.686669,-161.154480,0.067722,0.000000
139.430008,5.020325,-161.243454,-0.001268,0.002689,0.068294,22.331520,1.137622,0.682940,-161.243454,0.067115,0.000000
139.790009,1.660034,-161.287933,-0.001272,0.002654,0.067409,7.384201,0.376169,0.674094,-161.287933,0.066516,0.000000
140.150009,-0.450203,-161.243454,-0.001276,0.002637,0.066976,-2.002603,-0.102017,0.669758,-161.243454,0.065918,0.000000
140.510010,-2.918655,-161.287933,-0.001263,0.002611,0.066308,-12.982827,-0.661377,0.663081,-161.287933,0.065319,0.000000
140.870010,-0.320244,-161.287933,-0.001306,0.002586,0.065675,-1.424516,-0.072568,0.656750,-161.287933,0.064721,0.000000
141.230011,-0.164963,-161.287933,-0.001285,0.002563,0.065103,-0.733791,-0.037381,0.651026,-161.287933,0.064114,0.000000
141.590012,-0.070381,-161.421371,-0.001302,0.002536,0.064426,-0.313071,-0.015949,0.644262,-161.421371,0.063516,0.000000
141.950012,-0.118042,-161.332413,-0.001315,0.002515,0.063871,-0.525077,-0.026749,0.638712,-161.332413,0.062917,0.000000
142.310013,-0.058464,-161.421371,-0.001362,0.002498,0.063438,-0.260061,-0.013248,0.634376,-161.421371,0.062319,0.000000
142.670013,-0.078941,-161.421371,-0.001388,0.002464,0.062588,-0.351149,-0.017888,0.625877,-161.421371,0.061720,0.000000
143.030014,-0.076714,-161.421371,-0.001397,0.002446,0.062137,-0.341239,-0.017384,0.621367,-161.421371,0.061113,0.000000
143.389999,-0.043571,-161.554810,-0.001436,0.002418,0.061426,-0.193816,-0.009873,0.614256,-161.554810,0.060515,0.000000
143.750000,-0.055855,-161.465851,-0.001462,0.002398,0.060905,-0.248455,-0.012657,0.609053,-161.465851,0.059917,0.000000
144.110001,-0.081177,-161.554810,-0.001483,0.002377,0.060376,-0.361092,-0.018395,0.603763,-161.554810,0.059318,0.000000
144.470001,-0.087135,-161.554810,-0.001509,0.002349,0.059656,-0.387597,-0.019745,0.596565,-161.554810,0.058720,0.000000
144.830002,-0.075218,-161.554810,-0.001531,0.002325,0.059058,-0.334587,-0.017045,0.590581,-161.554810,0.058121,0.000000
145.190002,-0.065170,-161.643784,-0.001552,0.002300,0.058416,-0.289892,-0.014768,0.584163,-161.643784,0.057514,0.000000
145.550003,-0.068146,-161.643784,-0.001578,0.002276,0.057809,-0.303127,-0.015442,0.578093,-161.643784,0.056916,0.000000
145.910004,-0.062187,-161.732742,-0.001613,0.002256,0.057298,-0.276622,-0.014092,0.572976,-161.732742,0.056318,0.000000
146.270004,-0.052879,-161.732742,-0.001625,0.002231,0.056665,-0.235219,-0.011983,0.566645,-161.732742,0.055719,0.000000
146.630005,-0.068146,-161.688263,-0.001651,0.002204,0.055971,-0.303127,-0.015442,0.559707,-161.688263,0.055121,0.000000
146.990005,-0.102402,-161.777222,-0.001677,0.002184,0.055468,-0.455506,-0.023205,0.554678,-161.777222,0.054514,0.000000
147.350006,-0.071121,-161.732742,-0.001707,0.002166,0.055025,-0.316363,-0.016116,0.550255,-161.732742,0.054930,0.000000
147.500000,-0.063309,-161.777222,-0.001703,0.002167,0.055034,-0.281611,-0.014346,0.550341,-161.777222,0.054930,0.000000