File: Data/compression 20/AutoNoHeating-17-20-reverse-1-1_09112024_164815.csv
Time (sec),S:Load (lbs),S:HL1 (DIM),S:LVDT (in),S:Position (in),Ch:Position (mm),Ch:Load (N),Ch:Stress (MPa),Ch:Strain (mm/mm),Ch:HL1 (DIM),Set Point (),Cycles ()
0.110000,-0.055115,-106.264992,-0.011546,-0.006678,-0.169621,-0.245163,-0.012489,-1.696207,-106.264992,-0.169430,0.000000
0.510000,-0.049156,-106.220512,-0.011542,-0.006590,-0.167375,-0.218658,-0.011139,-1.673746,-106.220512,-0.166551,0.000000
0.910000,-0.013031,-106.264992,-0.011374,-0.006346,-0.161191,-0.057965,-0.002953,-1.611912,-106.264992,-0.159890,0.000000
1.310000,-0.032394,-106.309471,-0.011106,-0.006084,-0.154540,-0.144098,-0.007341,-1.545396,-106.309471,-0.153230,0.000000
1.710000,-0.062187,-106.309471,-0.010843,-0.005820,-0.147827,-0.276622,-0.014092,-1.478273,-106.309471,-0.146570,0.000000
2.110000,-0.074104,-106.353951,-0.010563,-0.005559,-0.141210,-0.329632,-0.016792,-1.412104,-106.353951,-0.139910,0.000000
2.510000,-0.056976,-106.398437,-0.010300,-0.005299,-0.134602,-0.253443,-0.012911,-1.346021,-106.398437,-0.133232,0.000000
2.910000,-0.021973,-106.398437,-0.010029,-0.005030,-0.127751,-0.097739,-0.004979,-1.277510,-106.398437,-0.126572,0.000000
3.310000,0.001488,-106.487396,-0.009783,-0.004775,-0.121290,0.006618,0.000337,-1.212902,-106.487396,-0.119911,0.000000
3.710000,-0.052879,-106.442917,-0.009498,-0.004506,-0.114448,-0.235219,-0.011983,-1.144478,-106.442917,-0.113251,0.000000
4.110000,-0.079315,-106.531876,-0.009235,-0.004245,-0.107831,-0.352812,-0.017973,-1.078308,-106.531876,-0.106591,0.000000
4.510000,-0.115067,-106.620842,-0.008951,-0.003983,-0.101179,-0.511841,-0.026074,-1.011792,-106.620842,-0.099913,0.000000
4.910000,-0.023087,-106.620842,-0.008692,-0.003719,-0.094458,-0.102694,-0.005231,-0.944582,-106.620842,-0.093253,0.000000
5.310000,-0.038727,-106.665321,-0.008429,-0.003459,-0.087850,-0.172265,-0.008776,-0.878500,-106.665321,-0.086592,0.000000
5.710000,-0.030533,-106.665321,-0.008157,-0.003199,-0.081250,-0.135817,-0.006919,-0.812504,-106.665321,-0.079932,0.000000
6.110000,-0.032028,-106.665321,-0.007894,-0.002931,-0.074443,-0.142469,-0.007258,-0.744426,-106.665321,-0.073272,0.000000
6.510000,-0.052505,-106.754280,-0.007610,-0.002670,-0.067826,-0.233556,-0.011898,-0.678257,-106.754280,-0.066594,0.000000
6.910000,0.005211,-106.709801,-0.007338,-0.002409,-0.061191,0.023179,0.001181,-0.611915,-106.709801,-0.059934,0.000000
7.310000,0.005211,-106.754280,-0.007088,-0.002147,-0.054531,0.023179,0.001181,-0.545312,-106.754280,-0.053274,0.000000
7.710001,-0.008942,-106.798767,-0.006825,-0.001886,-0.047914,-0.039774,-0.002026,-0.479142,-106.798767,-0.046613,0.000000
8.110001,-0.027931,-106.843246,-0.006545,-0.001620,-0.041141,-0.124244,-0.006329,-0.411412,-106.843246,-0.039936,0.000000
8.510000,-0.046173,-106.843246,-0.006282,-0.001359,-0.034507,-0.205388,-0.010463,-0.345069,-106.843246,-0.033275,0.000000
8.910001,-0.047295,-106.887726,-0.006015,-0.001094,-0.027786,-0.210377,-0.010717,-0.277859,-106.887726,-0.026615,0.000000
9.310000,0.005211,-106.976685,-0.005747,-0.000832,-0.021126,0.023179,0.001181,-0.211256,-106.976685,-0.019955,0.000000
9.710000,0.020103,-106.932205,-0.005480,-0.000578,-0.014682,0.089425,0.004556,-0.146821,-106.932205,-0.013295,0.000000
10.110001,-0.035378,-106.932205,-0.005213,-0.000308,-0.007822,-0.157367,-0.008017,-0.078224,-106.932205,-0.006617,0.000000
10.510000,-0.036865,-107.110130,-0.004932,-0.000047,-0.001205,-0.163985,-0.008354,-0.012054,-107.110130,0.000043,0.000000
10.910001,0.029045,-107.021172,-0.004850,-0.000010,-0.000260,0.129199,0.006582,-0.002602,-107.021172,-0.000026,0.000000
11.310000,0.093094,-107.065651,-0.004876,-0.000010,-0.000260,0.414102,0.021095,-0.002602,-107.065651,0.000286,0.000000
11.710001,0.101280,-107.065651,-0.004868,-0.000010,-0.000251,0.450517,0.022950,-0.002515,-107.065651,0.000954,0.000000
12.110001,0.141869,-107.154610,-0.004855,0.000020,0.000503,0.631063,0.032148,0.005030,-107.154610,0.001613,0.000000
12.510000,0.255074,-107.154610,-0.004829,0.000053,0.001353,1.134624,0.057800,0.013529,-107.154610,0.002281,0.000000
12.910001,0.395088,-107.243576,-0.004803,0.000077,0.001960,1.757440,0.089528,0.019599,-107.243576,0.002949,0.000000
13.310000,0.582764,-107.243576,-0.004781,0.000101,0.002567,2.592262,0.132056,0.025670,-107.243576,0.003616,0.000000
13.710001,0.812515,-107.332535,-0.004760,0.000128,0.003261,3.614248,0.184119,0.032608,-107.332535,0.004284,0.000000
14.110001,1.044502,-107.288055,-0.004730,0.000156,0.003963,4.646178,0.236688,0.039632,-107.288055,0.004952,0.000000
14.510000,1.318939,-107.332535,-0.004712,0.000183,0.004640,5.866935,0.298876,0.046397,-107.332535,0.005620,0.000000
14.910001,1.586304,-107.377014,-0.004682,0.000204,0.005177,7.056231,0.359462,0.051773,-107.377014,0.006287,0.000000
15.310000,1.886810,-107.377014,-0.004669,0.000224,0.005698,8.392951,0.427557,0.056977,-107.377014,0.006946,0.000000
15.710001,2.379456,-107.421494,-0.004631,0.000256,0.006496,10.584347,0.539192,0.064955,-107.421494,0.007614,0.000000
16.110001,2.918655,-107.421494,-0.004613,0.000292,0.007406,12.982827,0.661377,0.074061,-107.421494,0.008282,0.000000
16.510000,3.214691,-107.465981,-0.004570,0.000318,0.008065,14.299661,0.728459,0.080652,-107.465981,0.008950,0.000000
16.910002,3.534561,-107.465981,-0.004553,0.000339,0.008603,15.722513,0.800943,0.086029,-107.465981,0.009618,0.000000
17.310001,3.911400,-107.554939,-0.004527,0.000364,0.009253,17.398775,0.886336,0.092533,-107.554939,0.010285,0.000000
17.710001,4.328827,-107.510460,-0.004514,0.000389,0.009886,19.255585,0.980926,0.098864,-107.510460,0.010953,0.000000
18.110001,4.547783,-107.599419,-0.004497,0.000409,0.010381,20.229549,1.030542,0.103807,-107.599419,0.011621,0.000000
18.510000,5.105598,-107.688385,-0.004462,0.000445,0.011291,22.710836,1.156945,0.112913,-107.688385,0.012280,0.000000
18.910002,5.446320,-107.643898,-0.004449,0.000472,0.011985,24.226439,1.234154,0.119851,-107.643898,0.012948,0.000000
19.310001,5.697296,-107.732864,-0.004424,0.000493,0.012523,25.342838,1.291026,0.125227,-107.732864,0.013615,0.000000
19.710001,6.224945,-107.777344,-0.004415,0.000525,0.013329,27.689939,1.410593,0.133293,-107.777344,0.014283,0.000000
20.110001,6.401451,-107.732864,-0.004385,0.000549,0.013936,28.475077,1.450590,0.139363,-107.732864,0.014951,0.000000
20.510000,6.279312,-107.777344,-0.004363,0.000567,0.014413,27.931776,1.422912,0.144133,-107.777344,0.015619,0.000000
20.910002,7.119759,-107.777344,-0.004324,0.000604,0.015333,31.670267,1.613360,0.153325,-107.777344,0.016286,0.000000
21.310001,7.280624,-107.821823,-0.004303,0.000627,0.015914,32.385834,1.649813,0.159136,-107.821823,0.016954,0.000000
21.710001,7.529373,-107.866310,-0.004286,0.000652,0.016573,33.492325,1.706180,0.165727,-107.866310,0.017622,0.000000
22.110001,7.747208,-107.910789,-0.004268,0.000679,0.017249,34.461300,1.755542,0.172491,-107.910789,0.018281,0.000000
22.510000,8.073402,-107.910789,-0.004243,0.000706,0.017943,35.912289,1.829459,0.179429,-107.910789,0.018949,0.000000
22.910002,8.116974,-107.910789,-0.004208,0.000731,0.018576,36.106102,1.839333,0.185760,-107.910789,0.019617,0.000000
23.310001,8.299438,-107.955269,-0.004186,0.000753,0.019131,36.917747,1.880680,0.191310,-107.955269,0.020284,0.000000
23.710001,8.481895,-108.044228,-0.004165,0.000777,0.019747,37.729355,1.922025,0.197467,-108.044228,0.020952,0.000000
24.110001,8.687820,-108.044228,-0.004135,0.000803,0.020388,38.645355,1.968688,0.203885,-108.044228,0.021620,0.000000
24.510000,9.035240,-107.999748,-0.004109,0.000835,0.021221,40.190754,2.047415,0.212210,-107.999748,0.022288,0.000000
24.910002,9.229248,-108.133194,-0.004087,0.000862,0.021889,41.053745,2.091377,0.218888,-108.133194,0.022955,0.000000
25.310001,9.431450,-108.133194,-0.004074,0.000887,0.022531,41.953186,2.137197,0.225305,-108.133194,0.023615,0.000000
25.710001,9.301491,-108.177673,-0.004027,0.000908,0.023051,41.375099,2.107748,0.230509,-108.177673,0.024282,0.000000
26.110001,9.684288,-108.177673,-0.004001,0.000940,0.023875,43.077866,2.194491,0.238747,-108.177673,0.024950,0.000000
26.510002,9.902870,-108.266632,-0.003980,0.000964,0.024490,44.050167,2.244022,0.244905,-108.266632,0.025618,0.000000
26.910002,10.100975,-108.266632,-0.003971,0.000994,0.025254,44.931381,2.288913,0.252536,-108.266632,0.026286,0.000000
27.310001,10.160179,-108.311119,-0.003932,0.001016,0.025800,45.194733,2.302330,0.258000,-108.311119,0.026953,0.000000
27.710001,10.454353,-108.355598,-0.003915,0.001046,0.026563,46.503284,2.368990,0.265631,-108.355598,0.027621,0.000000
28.110001,10.610008,-108.355598,-0.003880,0.001077,0.027344,47.195675,2.404262,0.273436,-108.355598,0.028289,0.000000
28.510002,10.583565,-108.400078,-0.003863,0.001095,0.027803,47.078049,2.398270,0.278033,-108.400078,0.028948,0.000000
28.910002,10.824867,-108.444557,-0.003850,0.001123,0.028523,48.151413,2.452950,0.285231,-108.444557,0.029616,0.000000
29.310001,11.083664,-108.400078,-0.003820,0.001148,0.029165,49.302601,2.511594,0.291648,-108.400078,0.030284,0.000000
29.710001,11.355125,-108.444557,-0.003786,0.001180,0.029971,50.510120,2.573108,0.299713,-108.444557,0.030951,0.000000
30.110001,11.453804,-108.444557,-0.003760,0.001205,0.030604,50.949066,2.595469,0.306044,-108.444557,0.031619,0.000000
30.510002,11.408005,-108.489037,-0.003729,0.001225,0.031125,50.745338,2.585091,0.311247,-108.489037,0.032287,0.000000
30.910002,11.726006,-108.533524,-0.003725,0.001259,0.031966,52.159878,2.657151,0.319659,-108.533524,0.032955,0.000000
31.310001,11.845535,-108.578003,-0.003695,0.001282,0.032556,52.691574,2.684237,0.325557,-108.578003,0.033622,0.000000
31.710001,12.220894,-108.578003,-0.003669,0.001312,0.033336,54.361252,2.769294,0.333362,-108.578003,0.034281,0.000000
32.110001,12.202271,-108.666962,-0.003643,0.001335,0.033900,54.278412,2.765074,0.338999,-108.666962,0.034949,0.000000
32.510002,12.402977,-108.666962,-0.003630,0.001359,0.034524,55.171196,2.810555,0.345243,-108.666962,0.035617,0.000000
32.910000,12.549324,-108.622482,-0.003604,0.001386,0.035192,55.822182,2.843717,0.351920,-108.622482,0.036285,0.000000
33.310001,12.825249,-108.755928,-0.003574,0.001414,0.035903,57.049557,2.906243,0.359031,-108.755928,0.036952,0.000000
33.710003,13.209915,-108.800407,-0.003540,0.001446,0.036727,58.760639,2.993409,0.367270,-108.800407,0.037620,0.000000
34.110001,12.956329,-108.800407,-0.003523,0.001466,0.037230,57.632633,2.935946,0.372300,-108.800407,0.038288,0.000000
34.510002,13.268745,-108.755928,-0.003492,0.001495,0.037967,59.022327,3.006741,0.379671,-108.755928,0.038956,0.000000
34.910000,13.595314,-108.844887,-0.003484,0.001522,0.038670,60.474976,3.080742,0.386696,-108.844887,0.039624,0.000000
35.310001,13.444504,-108.889366,-0.003454,0.001545,0.039242,59.804138,3.046568,0.392420,-108.889366,0.040283,0.000000
35.710003,13.811668,-108.933846,-0.003432,0.001571,0.039910,61.437370,3.129769,0.399097,-108.933846,0.040950,0.000000
36.110001,13.811295,-108.933846,-0.003410,0.001596,0.040534,61.435707,3.129684,0.405341,-108.933846,0.041618,0.000000
36.510002,14.156113,-108.933846,-0.003389,0.001622,0.041211,62.969536,3.207821,0.412106,-108.933846,0.042286,0.000000
36.910000,14.020569,-108.978333,-0.003363,0.001645,0.041774,62.366604,3.177106,0.417743,-108.978333,0.042954,0.000000
37.310001,14.784676,-109.022812,-0.003333,0.001682,0.042728,65.765518,3.350255,0.427282,-109.022812,0.043621,0.000000
37.710003,14.852448,-109.022812,-0.003307,0.001711,0.043465,66.066986,3.365613,0.434653,-109.022812,0.044289,0.000000
38.110001,14.660301,-109.067291,-0.003277,0.001733,0.044020,65.212280,3.322072,0.440204,-109.067291,0.044957,0.000000
38.510002,14.842766,-109.111771,-0.003255,0.001757,0.044619,66.023918,3.363419,0.446188,-109.111771,0.045616,0.000000
38.910004,14.990227,-109.111771,-0.003234,0.001783,0.045278,66.679855,3.396834,0.452779,-109.111771,0.046284,0.000000
39.310001,15.227798,-109.200737,-0.003199,0.001807,0.045902,67.736633,3.450669,0.459023,-109.200737,0.046952,0.000000
39.710003,15.587509,-109.200737,-0.003191,0.001835,0.046613,69.336700,3.532180,0.466134,-109.200737,0.047619,0.000000
40.110001,15.596817,-109.245216,-0.003169,0.001858,0.047203,69.378105,3.534289,0.472031,-109.245216,0.048287,0.000000
40.510002,15.975891,-109.245216,-0.003147,0.001888,0.047958,71.064316,3.620189,0.479576,-109.245216,0.048955,0.000000
40.910004,15.954666,-109.378662,-0.003130,0.001913,0.048599,70.969902,3.615379,0.485993,-109.378662,0.049623,0.000000
41.310001,16.311401,-109.334175,-0.003109,0.001941,0.049302,72.556740,3.696216,0.493018,-109.334175,0.050290,0.000000
41.710003,15.942383,-109.423141,-0.003078,0.001959,0.049753,70.915260,3.612596,0.497527,-109.423141,0.050950,0.000000
42.110001,16.759369,-109.423141,-0.003065,0.001992,0.050594,74.549393,3.797727,0.505939,-109.423141,0.051617,0.000000
42.510002,16.514343,-109.378662,-0.003040,0.002008,0.051002,73.459465,3.742204,0.510015,-109.378662,0.052285,0.000000
42.910004,17.106041,-109.467621,-0.003001,0.002041,0.051834,76.091469,3.876284,0.518341,-109.467621,0.052953,0.000000
43.310001,17.235634,-109.512100,-0.002984,0.002064,0.052432,76.667931,3.905650,0.524325,-109.512100,0.053621,0.000000
43.710003,16.977577,-109.512100,-0.002975,0.002086,0.052987,75.520035,3.847174,0.529875,-109.512100,0.054288,0.000000
44.110001,18.085381,-109.556580,-0.002928,0.002123,0.053933,80.447792,4.098206,0.539328,-109.556580,0.054956,0.000000
44.510002,18.222786,-109.601067,-0.002928,0.002149,0.054592,81.058998,4.129343,0.545919,-109.601067,0.055624,0.000000
44.910004,18.211243,-109.601067,-0.002893,0.002169,0.055095,81.007652,4.126726,0.550949,-109.601067,0.056283,0.000000
45.310001,18.292793,-109.645546,-0.002884,0.002191,0.055659,81.370407,4.145206,0.556585,-109.645546,0.056951,0.000000
45.710003,19.011101,-109.690025,-0.002850,0.002224,0.056482,84.565598,4.307977,0.564824,-109.690025,0.057618,0.000000
46.110001,19.303413,-109.690025,-0.002833,0.002255,0.057280,85.865868,4.374216,0.572803,-109.690025,0.058286,0.000000
46.510002,19.672066,-109.734505,-0.002820,0.002278,0.057870,87.505722,4.457754,0.578700,-109.734505,0.058954,0.000000
46.910004,19.756218,-109.734505,-0.002777,0.002303,0.058486,87.880043,4.476823,0.584857,-109.734505,0.059622,0.000000
47.310001,19.884689,-109.734505,-0.002772,0.002328,0.059127,88.451515,4.505935,0.591274,-109.734505,0.060290,0.000000
47.710003,20.543785,-109.823471,-0.002734,0.002356,0.059847,91.383324,4.655288,0.598472,-109.823471,0.060957,0.000000
48.110001,20.914673,-109.867950,-0.002729,0.002383,0.060524,93.033112,4.739333,0.605237,-109.867950,0.061616,0.000000
48.510002,21.380882,-109.867950,-0.002703,0.002413,0.061287,95.106911,4.844977,0.612868,-109.867950,0.062284,0.000000
48.910004,21.476204,-109.867950,-0.002660,0.002435,0.061859,95.530930,4.866578,0.618592,-109.867950,0.062952,0.000000
49.310001,22.029922,-109.912430,-0.002656,0.002463,0.062562,97.993988,4.992052,0.625617,-109.912430,0.063620,0.000000
49.710003,21.944283,-109.956909,-0.002626,0.002486,0.063134,97.613045,4.972645,0.631340,-109.956909,0.064287,0.000000
50.110001,22.503212,-110.001389,-0.002596,0.002512,0.063802,100.099289,5.099301,0.638018,-110.001389,0.064955,0.000000
50.510002,23.233803,-110.001389,-0.002578,0.002543,0.064591,103.349113,5.264855,0.645910,-110.001389,0.065623,0.000000
50.910004,23.689590,-110.045876,-0.002557,0.002571,0.065302,105.376564,5.368138,0.653021,-110.045876,0.066291,0.000000
51.310001,24.051537,-110.134834,-0.002527,0.002598,0.065996,106.986580,5.450156,0.659959,-110.134834,0.066958,0.000000
51.710003,24.081322,-110.134834,-0.002518,0.002619,0.066525,107.119072,5.456905,0.665249,-110.134834,0.067618,0.000000
52.110001,24.959007,-110.179314,-0.002488,0.002649,0.067279,111.023209,5.655792,0.672794,-110.179314,0.068285,0.000000
52.510002,25.294884,-110.179314,-0.002466,0.002673,0.067886,112.517265,5.731903,0.678864,-110.179314,0.068953,0.000000
52.910004,26.070168,-110.223793,-0.002436,0.002702,0.068632,115.965897,5.907585,0.686322,-110.223793,0.069621,0.000000
53.310001,26.285400,-110.268280,-0.002414,0.002729,0.069309,116.923302,5.956357,0.693087,-110.268280,0.070289,0.000000
53.710003,26.538612,-110.223793,-0.002397,0.002753,0.069933,118.049644,6.013736,0.699331,-110.223793,0.070956,0.000000
54.110004,26.909119,-110.268280,-0.002380,0.002771,0.070393,119.697739,6.097693,0.703927,-110.268280,0.071624,0.000000
54.510002,27.769676,-110.357239,-0.002350,0.002803,0.071191,123.525688,6.292698,0.711906,-110.357239,0.072292,0.000000
54.910004,29.080795,-110.357239,-0.002328,0.002836,0.072023,129.357834,6.589802,0.720231,-110.357239,0.072951,0.000000
55.310001,29.471420,-110.401718,-0.002302,0.002862,0.072691,131.095428,6.678319,0.726909,-110.401718,0.073619,0.000000
55.710003,29.636375,-110.401718,-0.002289,0.002884,0.073246,131.829178,6.715699,0.732459,-110.401718,0.074287,0.000000
56.110004,30.541618,-110.490685,-0.002264,0.002910,0.073914,135.855896,6.920830,0.739136,-110.490685,0.074954,0.000000
56.510002,31.164597,-110.490685,-0.002233,0.002936,0.074564,138.627045,7.061998,0.745641,-110.490685,0.075622,0.000000
56.910004,32.039673,-110.490685,-0.002216,0.002964,0.075275,142.519577,7.260294,0.752752,-110.490685,0.076290,0.000000
57.310001,32.515564,-110.535164,-0.002216,0.002987,0.075874,144.636459,7.368132,0.758736,-110.535164,0.076958,0.000000
57.710003,33.093483,-110.535164,-0.002190,0.003011,0.076481,147.207169,7.499091,0.764806,-110.535164,0.077625,0.000000
58.110004,34.048622,-110.624123,-0.002169,0.003040,0.077218,151.455841,7.715528,0.772178,-110.624123,0.078284,0.000000
58.510002,34.985878,-110.624123,-0.002156,0.003067,0.077912,155.624954,7.927913,0.779116,-110.624123,0.078952,0.000000
58.910004,36.425476,-110.668610,-0.002117,0.003100,0.078744,162.028610,8.254130,0.787441,-110.668610,0.079620,0.000000
59.310001,36.842529,-110.668610,-0.002087,0.003123,0.079325,163.883759,8.348636,0.793251,-110.668610,0.080288,0.000000
59.710003,37.729897,-110.757568,-0.002074,0.003149,0.079993,167.830963,8.549717,0.799929,-110.757568,0.080956,0.000000
60.110004,38.187538,-110.757568,-0.002057,0.003173,0.080583,169.866653,8.653420,0.805826,-110.757568,0.081623,0.000000
60.510002,39.371307,-110.846527,-0.002039,0.003200,0.081285,175.132324,8.921665,0.812851,-110.846527,0.082291,0.000000
60.910004,40.240799,-110.802048,-0.002013,0.003224,0.081892,179.000015,9.118695,0.818921,-110.802048,0.082959,0.000000
61.310001,41.201897,-110.846527,-0.001996,0.003251,0.082577,183.275192,9.336484,0.825772,-110.846527,0.083618,0.000000
61.710003,42.432961,-110.846527,-0.001983,0.003280,0.083314,188.751236,9.615446,0.833144,-110.846527,0.084286,0.000000
62.110004,43.091309,-110.891014,-0.001953,0.003301,0.083835,191.679718,9.764629,0.838347,-110.891014,0.084953,0.000000
62.510002,44.812790,-110.935493,-0.001940,0.003333,0.084650,199.337250,10.154724,0.846499,-110.935493,0.085621,0.000000
62.910004,45.155746,-110.935493,-0.001919,0.003352,0.085144,200.862793,10.232438,0.851442,-110.935493,0.086289,0.000000
63.310001,46.192055,-110.979973,-0.001901,0.003379,0.085838,205.472519,10.467269,0.858380,-110.979973,0.086957,0.000000
63.710003,47.480095,-111.024452,-0.001888,0.003404,0.086454,211.202011,10.759144,0.864537,-111.024452,0.087624,0.000000
64.110001,48.864578,-111.068932,-0.001867,0.003434,0.087217,217.360504,11.072871,0.872169,-111.068932,0.088292,0.000000
64.510002,50.341400,-111.068932,-0.001858,0.003461,0.087902,223.929733,11.407525,0.879020,-111.068932,0.088960,0.000000
64.910004,50.608398,-111.157898,-0.001841,0.003476,0.088284,225.117401,11.468027,0.882836,-111.157898,0.089619,0.000000
65.310005,52.715652,-111.202377,-0.001828,0.003514,0.089264,234.490936,11.945538,0.892635,-111.202377,0.090287,0.000000
65.710007,54.084122,-111.202377,-0.001798,0.003540,0.089905,240.578186,12.255637,0.899053,-111.202377,0.090955,0.000000
66.110001,55.220970,-111.202377,-0.001785,0.003563,0.090504,245.635147,12.513250,0.905037,-111.202377,0.091622,0.000000
66.510002,56.098282,-111.246857,-0.001768,0.003582,0.090989,249.537613,12.712052,0.909893,-111.246857,0.092290,0.000000
66.910004,57.837631,-111.291336,-0.001759,0.003616,0.091848,257.274628,13.106194,0.918479,-111.291336,0.092958,0.000000
67.310005,59.429901,-111.335823,-0.001733,0.003641,0.092472,264.357391,13.467008,0.924723,-111.335823,0.093626,0.000000
67.710007,60.303856,-111.335823,-0.001720,0.003660,0.092967,268.244934,13.665049,0.929666,-111.335823,0.094293,0.000000
68.110001,62.318390,-111.291336,-0.001707,0.003694,0.093816,277.206055,14.121549,0.938165,-111.291336,0.094953,0.000000
68.510002,63.958313,-111.424782,-0.001686,0.003719,0.094467,284.500793,14.493161,0.944669,-111.424782,0.095620,0.000000
68.910004,65.276520,-111.380302,-0.001681,0.003745,0.095135,290.364471,14.791870,0.951347,-111.380302,0.096288,0.000000
69.310005,66.030197,-111.424782,-0.001669,0.003753,0.095325,293.716980,14.962656,0.953254,-111.424782,0.016741,0.000000
69.710007,64.719818,-111.513741,-0.001651,0.003752,0.095308,287.888123,14.665721,0.953081,-111.513741,294.500458,0.000000
70.110001,66.197769,-111.469261,-0.001634,0.003714,0.094337,294.462372,15.000628,0.943368,-111.469261,294.500458,0.000000
70.510002,65.233322,-111.558228,-0.001608,0.003752,0.095299,290.172302,14.782083,0.952994,-111.558228,294.500458,0.000000
70.910004,65.527130,-111.513741,-0.001617,0.003786,0.096158,291.479218,14.848660,0.961580,-111.513741,294.500458,0.000000
71.310005,65.134644,-111.602707,-0.001613,0.003791,0.096279,289.733368,14.759721,0.962794,-111.602707,294.500458,0.000000
71.710007,65.239655,-111.602707,-0.001621,0.003798,0.096462,290.200470,14.783518,0.964615,-111.602707,294.500458,0.000000
72.110001,65.288055,-111.691666,-0.001591,0.003805,0.096652,290.415771,14.794485,0.966523,-111.691666,294.500458,0.000000
72.510002,65.136871,-111.691666,-0.001595,0.003809,0.096756,289.743286,14.760226,0.967564,-111.691666,294.500458,0.000000
72.910004,65.010269,-111.691666,-0.001587,0.003813,0.096852,289.180115,14.731537,0.968518,-111.691666,294.500458,0.000000
73.310005,65.054581,-111.736153,-0.001578,0.003818,0.096973,289.377228,14.741579,0.969732,-111.736153,294.500458,0.000000
73.710007,65.067993,-111.736153,-0.001578,0.003825,0.097147,289.436890,14.744618,0.971466,-111.736153,294.500458,0.000000
74.110001,65.425461,-111.825111,-0.001578,0.003833,0.097355,291.026978,14.825622,0.973548,-111.825111,294.500458,0.000000
74.510002,65.254181,-111.825111,-0.001574,0.003833,0.097346,290.265106,14.786808,0.973461,-111.825111,294.500458,0.000000
74.910004,65.415421,-111.914070,-0.001574,0.003840,0.097528,290.982330,14.823346,0.975282,-111.914070,294.500458,0.000000
75.310005,65.219177,-111.869591,-0.001578,0.003840,0.097546,290.109375,14.778876,0.975455,-111.869591,294.500458,0.000000
75.710007,65.078415,-111.869591,-0.001556,0.003843,0.097606,289.483246,14.746980,0.976062,-111.869591,294.500458,0.000000
76.110001,65.111191,-111.869591,-0.001556,0.003848,0.097745,289.629028,14.754407,0.977450,-111.869591,294.500458,0.000000
76.510002,65.106339,-111.958557,-0.001556,0.003849,0.097762,289.607452,14.753307,0.977624,-111.958557,294.500458,0.000000
76.910004,65.428818,-111.958557,-0.001556,0.003856,0.097936,291.041931,14.826382,0.979358,-111.958557,294.500458,0.000000
77.310005,65.286942,-112.003036,-0.001561,0.003856,0.097936,290.410828,14.794232,0.979358,-112.003036,294.500458,0.000000
77.710007,65.389725,-112.091995,-0.001539,0.003861,0.098066,290.868011,14.817523,0.980659,-112.091995,294.500458,0.000000
78.110001,65.245987,-112.091995,-0.001556,0.003861,0.098066,290.228638,14.784952,0.980659,-112.091995,294.500458,0.000000
78.510002,65.044525,-112.136475,-0.001544,0.003861,0.098075,289.332489,14.739301,0.980746,-112.136475,294.500458,0.000000
78.910004,65.289917,-112.136475,-0.001548,0.003867,0.098213,290.424042,14.794907,0.982133,-112.136475,294.500458,0.000000
79.310005,65.099274,-112.180962,-0.001539,0.003867,0.098222,289.576019,14.751707,0.982220,-112.180962,294.500458,0.000000
79.710007,65.367752,-112.180962,-0.001535,0.003872,0.098352,290.770294,14.812545,0.983521,-112.180962,294.500458,0.000000
80.110001,65.229965,-112.225441,-0.001539,0.003872,0.098352,290.157379,14.781322,0.983521,-112.225441,294.500458,0.000000
80.510002,65.146194,-112.269920,-0.001535,0.003876,0.098439,289.784760,14.762339,0.984388,-112.269920,294.500458,0.000000
80.910004,65.134277,-112.269920,-0.001526,0.003876,0.098439,289.731750,14.759639,0.984388,-112.269920,294.500458,0.000000
81.310005,65.246353,-112.358879,-0.001522,0.003879,0.098517,290.230286,14.785034,0.985168,-112.358879,294.500458,0.000000
81.710007,65.107468,-112.314400,-0.001518,0.003879,0.098517,289.612488,14.753563,0.985168,-112.314400,294.500458,0.000000
82.110001,64.998352,-112.358879,-0.001518,0.003880,0.098543,289.127106,14.728837,0.985429,-112.358879,294.500458,0.000000
82.510002,64.993515,-112.358879,-0.001526,0.003882,0.098595,289.105591,14.727740,0.985949,-112.358879,294.500458,0.000000
82.910004,64.953293,-112.447845,-0.001518,0.003883,0.098638,288.926666,14.718627,0.986382,-112.447845,294.500458,0.000000
83.310005,65.013992,-112.492325,-0.001513,0.003885,0.098682,289.196686,14.732382,0.986816,-112.492325,294.500458,0.000000
83.710007,64.937653,-112.492325,-0.001518,0.003885,0.098682,288.857117,14.715083,0.986816,-112.492325,294.500458,0.000000
84.110001,64.814407,-112.536804,-0.001518,0.003888,0.098751,288.308868,14.687155,0.987510,-112.536804,294.500458,0.000000
84.510002,65.362534,-112.536804,-0.001513,0.003892,0.098864,290.747070,14.811362,0.988637,-112.536804,294.500458,0.000000
84.910004,65.271683,-112.536804,-0.001522,0.003892,0.098864,290.342957,14.790774,0.988637,-112.536804,294.500458,0.000000
85.310005,65.156235,-112.581284,-0.001509,0.003892,0.098864,289.829407,14.764614,0.988637,-112.581284,294.500458,0.000000
85.710007,65.016235,-112.625771,-0.001505,0.003892,0.098864,289.206665,14.732890,0.988637,-112.625771,294.500458,0.000000
86.110001,64.923141,-112.670250,-0.001509,0.003892,0.098864,288.792542,14.711794,0.988637,-112.670250,294.500458,0.000000
86.510002,64.780151,-112.670250,-0.001513,0.003892,0.098864,288.156494,14.679393,0.988637,-112.670250,294.500458,0.000000
86.910004,64.660980,-112.714729,-0.001500,0.003893,0.098872,287.626404,14.652388,0.988724,-112.714729,294.500458,0.000000
87.310005,64.550400,-112.714729,-0.001526,0.003893,0.098872,287.134521,14.627330,0.988724,-112.714729,294.500458,0.000000
87.710007,66.030579,-112.803696,-0.001509,0.003899,0.099028,293.718689,14.962744,0.990285,-112.803696,294.500458,0.000000
88.110001,65.846619,-112.848175,-0.001500,0.003898,0.099020,292.900391,14.921058,0.990198,-112.848175,294.500458,0.000000
88.510002,65.762466,-112.803696,-0.001509,0.003898,0.099020,292.526062,14.901988,0.990198,-112.803696,294.500458,0.000000
88.910004,65.590424,-112.892654,-0.001505,0.003898,0.099020,291.760773,14.863003,0.990198,-112.892654,294.500458,0.000000
89.310005,65.493988,-112.892654,-0.001500,0.003899,0.099028,291.331818,14.841150,0.990285,-112.892654,294.500458,0.000000
89.710007,65.360306,-112.937134,-0.001500,0.003899,0.099028,290.737152,14.810857,0.990285,-112.937134,294.500458,0.000000
90.110001,65.241516,-112.981613,-0.001496,0.003899,0.099046,290.208771,14.783938,0.990458,-112.981613,294.500458,0.000000
90.510002,65.150650,-112.937134,-0.001496,0.003904,0.099159,289.804565,14.763348,0.991586,-112.937134,294.500458,0.000000
90.910004,65.062027,-113.026100,-0.001500,0.003904,0.099159,289.410339,14.743266,0.991586,-113.026100,294.500458,0.000000
91.310005,65.278748,-113.070580,-0.001487,0.003910,0.099306,290.374359,14.792376,0.993060,-113.070580,294.500458,0.000000
91.710007,65.244492,-113.070580,-0.001505,0.003910,0.099306,290.221985,14.784614,0.993060,-113.070580,294.500458,0.000000
92.110001,65.189758,-113.159538,-0.001483,0.003910,0.099306,289.978516,14.772210,0.993060,-113.159538,294.500458,0.000000
92.510002,65.085114,-113.159538,-0.001483,0.003910,0.099315,289.513031,14.748498,0.993147,-113.159538,294.500458,0.000000
92.910004,65.025162,-113.204018,-0.001487,0.003910,0.099315,289.246368,14.734913,0.993147,-113.204018,294.500458,0.000000
93.310005,64.952560,-113.248505,-0.001487,0.003910,0.099315,288.923431,14.718461,0.993147,-113.248505,294.500458,0.000000
93.710007,64.876221,-113.204018,-0.001496,0.003910,0.099315,288.583832,14.701161,0.993147,-113.204018,294.500458,0.000000
94.110008,64.800629,-113.204018,-0.001492,0.003910,0.099315,288.247589,14.684032,0.993147,-113.204018,294.500458,0.000000
94.510002,65.718155,-113.292984,-0.001492,0.003921,0.099601,292.328949,14.891947,0.996009,-113.292984,294.500458,0.000000
94.910004,65.669006,-113.292984,-0.001492,0.003921,0.099601,292.110321,14.880810,0.996009,-113.292984,294.500458,0.000000
95.310005,65.649643,-113.337463,-0.001479,0.003921,0.099601,292.024200,14.876421,0.996009,-113.337463,294.500458,0.000000
95.710007,65.580368,-113.426422,-0.001492,0.003921,0.099601,291.716034,14.860724,0.996009,-113.426422,294.500458,0.000000
96.110008,65.526382,-113.426422,-0.001470,0.003921,0.099601,291.475922,14.848491,0.996009,-113.426422,294.500458,0.000000
96.510002,65.484680,-113.426422,-0.001492,0.003921,0.099601,291.290405,14.839041,0.996009,-113.426422,294.500458,0.000000
96.910004,65.373337,-113.515388,-0.001496,0.003921,0.099601,290.795135,14.813809,0.996009,-113.515388,294.500458,0.000000
97.310005,65.334976,-113.515388,-0.001492,0.003921,0.099601,290.624481,14.805117,0.996009,-113.515388,294.500458,0.000000
97.710007,65.258270,-113.515388,-0.001483,0.003921,0.099601,290.283295,14.787735,0.996009,-113.515388,294.500458,0.000000
98.110008,65.187515,-113.604347,-0.001475,0.003921,0.099601,289.968536,14.771702,0.996009,-113.604347,294.500458,0.000000
98.510002,65.119003,-113.604347,-0.001487,0.003921,0.099601,289.663788,14.756177,0.996009,-113.604347,294.500458,0.000000
98.910004,65.043793,-113.648827,-0.001505,0.003921,0.099601,289.329254,14.739134,0.996009,-113.648827,294.500458,0.000000
99.310005,64.989044,-113.648827,-0.001483,0.003921,0.099601,289.085693,14.726727,0.996009,-113.648827,294.500458,0.000000
99.710007,64.927231,-113.693314,-0.001487,0.003921,0.099601,288.810760,14.712721,0.996009,-113.693314,294.500458,0.000000
100.110008,64.862442,-113.693314,-0.001492,0.003922,0.099610,288.522552,14.698040,0.996095,-113.693314,294.500458,0.000000
100.510002,64.794662,-113.737793,-0.001487,0.003922,0.099610,288.221039,14.682680,0.996095,-113.737793,294.500458,0.000000
100.910004,64.742905,-113.782272,-0.001475,0.003922,0.099610,287.990814,14.670952,0.996095,-113.782272,294.500458,0.000000
101.310005,64.691147,-113.826752,-0.001479,0.003922,0.099610,287.760590,14.659224,0.996095,-113.826752,294.500458,0.000000
101.710007,64.630447,-113.826752,-0.001475,0.003922,0.099610,287.490601,14.645469,0.996095,-113.826752,294.500458,0.000000
102.110008,64.541824,-113.871231,-0.001479,0.003922,0.099610,287.096375,14.625386,0.996095,-113.871231,294.500458,0.000000
102.510002,64.499374,-113.871231,-0.001470,0.003922,0.099610,286.907532,14.615767,0.996095,-113.871231,294.500458,0.000000
102.910004,64.444641,-113.915718,-0.001487,0.003922,0.099610,286.664093,14.603365,0.996095,-113.915718,294.500458,0.000000
103.310005,64.380585,-113.960197,-0.001475,0.003922,0.099610,286.379150,14.588849,0.996095,-113.960197,294.500458,0.000000
103.710007,64.330322,-114.004677,-0.001470,0.003922,0.099610,286.155579,14.577459,0.996095,-114.004677,294.500458,0.000000
104.110008,64.269623,-114.049156,-0.001466,0.003922,0.099610,285.885559,14.563704,0.996095,-114.049156,294.500458,0.000000
104.510002,64.205948,-114.049156,-0.001470,0.003922,0.099610,285.602325,14.549275,0.996095,-114.049156,294.500458,0.000000
104.910004,64.153442,-114.093643,-0.001492,0.003922,0.099610,285.368774,14.537378,0.996095,-114.093643,294.500458,0.000000
105.310005,64.094986,-114.138123,-0.001462,0.003922,0.099610,285.108734,14.524132,0.996095,-114.138123,294.500458,0.000000
105.710007,64.051407,-114.138123,-0.001466,0.003922,0.099610,284.914886,14.514256,0.996095,-114.138123,294.500458,0.000000
106.110008,64.010818,-114.182602,-0.001475,0.003922,0.099610,284.734344,14.505059,0.996095,-114.182602,294.500458,0.000000
106.510002,66.291611,-114.227081,-0.001427,0.003749,0.095230,294.879822,15.021894,0.952300,-114.227081,294.500458,0.000000
106.910004,66.220108,-114.271561,-0.001440,0.003749,0.095230,294.561737,15.005691,0.952300,-114.271561,294.500458,0.000000
107.310005,66.146378,-114.316048,-0.001431,0.003749,0.095230,294.233795,14.988984,0.952300,-114.316048,294.500458,0.000000
107.710007,66.078613,-114.316048,-0.001440,0.003749,0.095230,293.932343,14.973627,0.952300,-114.316048,294.500458,0.000000
108.110008,66.011948,-114.316048,-0.001431,0.003749,0.095230,293.635803,14.958521,0.952300,-114.316048,294.500458,0.000000
108.510002,65.958710,-114.449486,-0.001444,0.003751,0.095265,293.398987,14.946458,0.952647,-114.449486,294.500458,0.000000
108.910004,65.912537,-114.360527,-0.001449,0.003753,0.095317,293.193604,14.935994,0.953168,-114.360527,294.500458,0.000000
109.310005,65.854813,-114.405006,-0.001431,0.003753,0.095334,292.936829,14.922914,0.953341,-114.405006,294.500458,0.000000
109.710007,65.767303,-114.405006,-0.001436,0.003754,0.095360,292.547577,14.903084,0.953601,-114.405006,294.500458,0.000000
110.110008,65.763214,-114.449486,-0.001440,0.003757,0.095421,292.529388,14.902158,0.954208,-114.449486,294.500458,0.000000
110.510002,65.667877,-114.493965,-0.001436,0.003757,0.095421,292.105316,14.880554,0.954208,-114.493965,294.500458,0.000000
110.910004,65.613144,-114.493965,-0.001431,0.003770,0.095750,291.861847,14.868151,0.957504,-114.493965,294.500458,0.000000
111.310005,65.568085,-114.582932,-0.001427,0.003804,0.096618,291.661407,14.857941,0.966176,-114.582932,294.500458,0.000000
111.710007,65.512604,-114.627411,-0.001440,0.003877,0.098482,291.414612,14.845367,0.984821,-114.627411,294.500458,0.000000
112.110008,65.488022,-114.627411,-0.001444,0.003883,0.098621,291.305267,14.839798,0.986209,-114.627411,294.500458,0.000000
112.510002,65.435150,-114.671890,-0.001449,0.003889,0.098786,291.070099,14.827816,0.987857,-114.671890,294.500458,0.000000
112.910004,65.373337,-114.760857,-0.001431,0.003892,0.098846,290.795135,14.813809,0.988464,-114.760857,294.500458,0.000000
113.310005,65.369614,-114.760857,-0.001444,0.003901,0.099089,290.778564,14.812966,0.990892,-114.760857,294.500458,0.000000
113.710007,65.321579,-114.760857,-0.001436,0.003901,0.099098,290.564880,14.802081,0.990979,-114.760857,294.500458,0.000000
114.110008,65.291412,-114.760857,-0.001440,0.003901,0.099098,290.430695,14.795246,0.990979,-114.760857,294.500458,0.000000
114.510002,65.254181,-114.849815,-0.001431,0.003901,0.099098,290.265106,14.786808,0.990979,-114.849815,294.500458,0.000000
114.910004,65.216202,-114.894295,-0.001449,0.003901,0.099098,290.096161,14.778203,0.990979,-114.894295,294.500458,0.000000
115.310005,65.202042,-114.894295,-0.001444,0.003908,0.099254,290.033173,14.774994,0.992540,-114.894295,294.500458,0.000000
115.710007,65.167419,-114.894295,-0.001440,0.003911,0.099341,289.879150,14.767148,0.993407,-114.894295,294.500458,0.000000
116.110008,65.124969,-114.894295,-0.001431,0.003911,0.099341,289.690338,14.757528,0.993407,-114.894295,294.500458,0.000000
116.510002,65.060165,-115.027740,-0.001449,0.003911,0.099341,289.402069,14.742845,0.993407,-115.027740,294.500458,0.000000
116.910004,65.139114,-115.027740,-0.001449,0.003924,0.099670,289.753265,14.760735,0.996703,-115.027740,294.500458,0.000000
117.310005,65.107834,-115.072220,-0.001444,0.003925,0.099705,289.614105,14.753646,0.997049,-115.072220,294.500458,0.000000
117.710007,65.073944,-115.161179,-0.001449,0.003926,0.099714,289.463348,14.745967,0.997136,-115.161179,294.500458,0.000000
118.110008,65.049744,-115.072220,-0.001444,0.003926,0.099714,289.355713,14.740482,0.997136,-115.072220,294.500458,0.000000
118.510002,65.235931,-115.116699,-0.001436,0.003936,0.099965,290.183929,14.782673,0.999651,-115.116699,294.500458,0.000000
118.910004,65.287323,-115.116699,-0.001436,0.003936,0.099965,290.412506,14.794319,0.999651,-115.116699,294.500458,0.000000
119.310005,65.270935,-115.205666,-0.001431,0.003936,0.099965,290.339630,14.790605,0.999651,-115.205666,294.500458,0.000000
119.710007,65.235184,-115.250145,-0.001440,0.003936,0.099965,290.180603,14.782503,0.999651,-115.250145,294.500458,0.000000
120.110008,65.200180,-115.294624,-0.001453,0.003936,0.099965,290.024872,14.774571,0.999651,-115.294624,294.500458,0.000000
120.510002,65.176727,-115.339104,-0.001440,0.003937,0.099991,289.920563,14.769257,0.999911,-115.339104,294.500458,0.000000
120.910004,65.139862,-115.383591,-0.001440,0.003937,0.099991,289.756592,14.760904,0.999911,-115.383591,294.500458,0.000000
121.310005,65.117142,-115.339104,-0.001444,0.003937,0.099991,289.655518,14.755754,0.999911,-115.339104,294.500458,0.000000
121.710007,65.085495,-115.383591,-0.001431,0.003937,0.100008,289.514740,14.748584,1.000085,-115.383591,294.500458,0.000000
122.110008,65.075058,-115.428070,-0.001449,0.003937,0.100008,289.468323,14.746219,1.000085,-115.428070,294.500458,0.000000
122.510002,65.046021,-115.517029,-0.001453,0.003937,0.100008,289.339142,14.739638,1.000085,-115.517029,294.500458,0.000000
122.910004,65.270554,-115.472549,-0.001440,0.003943,0.100156,290.337921,14.790519,1.001559,-115.472549,294.500458,0.000000
123.310005,65.308914,-115.517029,-0.001440,0.003943,0.100156,290.508545,14.799212,1.001559,-115.517029,294.500458,0.000000
123.710007,65.298492,-115.517029,-0.001440,0.003943,0.100156,290.462189,14.796850,1.001559,-115.517029,294.500458,0.000000
124.110008,65.282852,-115.561508,-0.001453,0.003943,0.100156,290.392639,14.793305,1.001559,-115.561508,294.500458,0.000000
124.510002,65.273163,-115.605995,-0.001440,0.003943,0.100156,290.349518,14.791110,1.001559,-115.605995,294.500458,0.000000
124.910004,65.241150,-115.605995,-0.001431,0.003943,0.100156,290.207123,14.783856,1.001559,-115.605995,294.500458,0.000000
125.310005,65.219925,-115.605995,-0.001440,0.003943,0.100156,290.112701,14.779046,1.001559,-115.605995,294.500458,0.000000
125.710007,65.178207,-115.650475,-0.001444,0.003943,0.100156,289.927155,14.769593,1.001559,-115.650475,294.500458,0.000000
126.110008,65.151031,-115.650475,-0.001436,0.003943,0.100156,289.806274,14.763435,1.001559,-115.650475,294.500458,0.000000
126.510010,65.151779,-115.694954,-0.001449,0.003944,0.100173,289.809601,14.763604,1.001732,-115.694954,294.500458,0.000000
126.910004,65.124588,-115.694954,-0.001444,0.003944,0.100173,289.688629,14.757442,1.001732,-115.694954,294.500458,0.000000
127.310005,65.091080,-115.739433,-0.001453,0.003944,0.100173,289.539581,14.749849,1.001732,-115.739433,294.500458,0.000000
127.710007,65.074326,-115.828400,-0.001444,0.003944,0.100182,289.465057,14.746053,1.001819,-115.828400,294.500458,0.000000
128.110001,65.053467,-115.828400,-0.001444,0.003945,0.100199,289.372284,14.741326,1.001993,-115.828400,294.500458,0.000000
128.510010,65.050110,-115.828400,-0.001431,0.003945,0.100199,289.357330,14.740566,1.001993,-115.828400,294.500458,0.000000
128.910004,65.096664,-115.828400,-0.001436,0.003947,0.100243,289.564423,14.751115,1.002426,-115.828400,294.500458,0.000000
129.310013,65.075806,-115.917358,-0.001444,0.003947,0.100243,289.471649,14.746388,1.002426,-115.917358,294.500458,0.000000
129.710007,65.079163,-115.917358,-0.001449,0.003947,0.100243,289.486572,14.747149,1.002426,-115.917358,1681.640747,0.000000
130.110001,65.054214,-115.961838,-0.001449,0.003937,0.100008,289.375610,14.741495,1.000085,-115.961838,0.099939,0.000000
130.510010,65.021820,-116.050804,-0.001444,0.003921,0.099601,289.231506,14.734156,0.996009,-116.050804,0.099271,0.000000
130.910004,64.913834,-116.050804,-0.001440,0.003898,0.099011,288.751160,14.709685,0.990112,-116.050804,0.098604,0.000000
131.310013,64.806580,-116.050804,-0.001440,0.003877,0.098482,288.274078,14.685381,0.984821,-116.050804,0.097936,0.000000
131.710007,64.786102,-116.095284,-0.001444,0.003849,0.097771,288.182983,14.680740,0.977710,-116.095284,0.097268,0.000000
132.110001,64.736206,-116.095284,-0.001440,0.003824,0.097129,287.961029,14.669434,0.971293,-116.095284,0.096609,0.000000
132.510010,64.712753,-116.184242,-0.001431,0.003801,0.096557,287.856689,14.664120,0.965569,-116.184242,0.095941,0.000000
132.910004,64.605881,-116.139763,-0.001436,0.003780,0.096019,287.381317,14.639901,0.960192,-116.139763,0.095273,0.000000
133.310013,64.598801,-116.184242,-0.001444,0.003750,0.095239,287.349823,14.638297,0.952387,-116.184242,0.094606,0.000000
133.710007,64.456177,-116.184242,-0.001436,0.003721,0.094510,286.715393,14.605978,0.945103,-116.184242,0.093938,0.000000
134.110001,63.744949,-116.184242,-0.001440,0.003697,0.093903,283.551697,14.444812,0.939032,-116.184242,0.093270,0.000000
134.510010,62.969299,-116.228722,-0.001436,0.003678,0.093409,280.101440,14.269048,0.934089,-116.228722,0.092602,0.000000
134.910004,61.529335,-116.273209,-0.001418,0.003650,0.092715,273.696136,13.942747,0.927151,-116.273209,0.091935,0.000000
135.310013,60.262894,-116.273209,-0.001418,0.003630,0.092195,268.062744,13.655767,0.921948,-116.273209,0.091275,0.000000
135.710007,58.079300,-116.406647,-0.001410,0.003599,0.091423,258.349640,13.160957,0.914229,-116.406647,0.090608,0.000000
136.110001,56.038330,-116.406647,-0.001414,0.003573,0.090764,249.270935,12.698466,0.907638,-116.406647,0.089940,0.000000
136.510010,54.036087,-116.451126,-0.001414,0.003550,0.090174,240.364517,12.244752,0.901741,-116.451126,0.089272,0.000000
136.910004,52.452385,-116.451126,-0.001418,0.003537,0.089827,233.319855,11.885880,0.898272,-116.451126,0.088604,0.000000
137.310013,49.570969,-116.495613,-0.001418,0.003506,0.089047,220.502686,11.232943,0.890467,-116.495613,0.087937,0.000000
137.710007,46.138435,-116.584572,-0.001406,0.003474,0.088240,205.234009,10.455119,0.882402,-116.584572,0.087269,0.000000
138.110001,43.087585,-116.540092,-0.001410,0.003446,0.087529,191.663147,9.763786,0.875291,-116.540092,0.086601,0.000000
138.510010,40.208405,-116.584572,-0.001406,0.003420,0.086879,178.855911,9.111355,0.868787,-116.584572,0.085942,0.000000
138.910004,37.607758,-116.584572,-0.001418,0.003394,0.086220,167.287659,8.522039,0.862196,-116.584572,0.085274,0.000000
139.310013,35.412247,-116.629051,-0.001406,0.003376,0.085751,157.521545,8.024529,0.857513,-116.629051,0.084607,0.000000
139.710007,32.136116,-116.718018,-0.001431,0.003343,0.084919,142.948578,7.282148,0.849187,-116.718018,0.083939,0.000000
140.110001,29.335503,-116.673538,-0.001427,0.003318,0.084286,130.490829,6.647520,0.842857,-116.673538,0.083271,0.000000
140.510010,26.970192,-116.718018,-0.001427,0.003298,0.083774,119.969406,6.111533,0.837740,-116.718018,0.082603,0.000000
140.910004,23.781937,-116.806976,-0.001418,0.003267,0.082985,105.787338,5.389064,0.829848,-116.806976,0.081935,0.000000
141.310013,20.935150,-116.851456,-0.001414,0.003242,0.082352,93.124199,4.743973,0.823518,-116.851456,0.081268,0.000000
141.710007,17.454956,-116.762497,-0.001418,0.003209,0.081519,77.643524,3.955349,0.815192,-116.762497,0.080600,0.000000
142.110001,14.696793,-116.851456,-0.001414,0.003185,0.080903,65.374596,3.330341,0.809035,-116.851456,0.079941,0.000000
142.510010,12.097260,-116.895943,-0.001414,0.003162,0.080305,53.811298,2.741278,0.803051,-116.895943,0.079273,0.000000
142.910004,9.211746,-116.984901,-0.001423,0.003134,0.079611,40.975895,2.087411,0.796113,-116.984901,0.078605,0.000000
143.310013,7.227379,-116.984901,-0.001406,0.003113,0.079065,32.148987,1.637748,0.790650,-116.984901,0.077938,0.000000
143.710007,3.407951,-116.984901,-0.001418,0.003079,0.078206,15.159325,0.772253,0.782064,-116.984901,0.077270,0.000000
144.110001,0.945076,-117.029381,-0.001401,0.003055,0.077599,4.203908,0.214157,0.775994,-117.029381,0.076602,0.000000
144.510010,-1.501034,-117.073860,-0.001414,0.003031,0.076992,-6.676932,-0.340139,0.769923,-117.073860,0.075934,0.000000
144.910004,-3.339439,-117.073860,-0.001410,0.003008,0.076411,-14.854568,-0.756728,0.764113,-117.073860,0.075267,0.000000
145.310013,-0.143738,-117.073860,-0.001436,0.002984,0.075796,-0.639378,-0.032571,0.757955,-117.073860,0.074607,0.000000
145.710007,-0.073730,-117.118347,-0.001436,0.002945,0.074807,-0.327969,-0.016708,0.748069,-117.118347,0.073940,0.000000
146.110001,-0.053253,-117.207306,-0.001457,0.002926,0.074321,-0.236882,-0.012067,0.743212,-117.207306,0.073272,0.000000
146.510010,-0.016388,-117.207306,-0.001483,0.002906,0.073818,-0.072897,-0.003714,0.738182,-117.207306,0.072604,0.000000
146.910004,-0.039848,-117.207306,-0.001513,0.002871,0.072925,-0.177254,-0.009030,0.729250,-117.207306,0.071936,0.000000
147.310013,-0.052505,-117.207306,-0.001539,0.002849,0.072370,-0.233556,-0.011898,0.723700,-117.207306,0.071269,0.000000
147.710007,-0.070007,-117.340752,-0.001574,0.002814,0.071468,-0.311408,-0.015864,0.714681,-117.340752,0.070601,0.000000
148.110001,-0.031654,-117.385231,-0.001604,0.002789,0.070852,-0.140806,-0.007173,0.708523,-117.385231,0.069933,0.000000
148.510010,-0.068146,-117.340752,-0.001625,0.002769,0.070341,-0.303127,-0.015442,0.703407,-117.340752,0.069274,0.000000
148.910004,-0.039848,-117.429710,-0.001651,0.002739,0.069560,-0.177254,-0.009030,0.695602,-117.429710,0.068606,0.000000
149.310013,-0.068520,-117.429710,-0.001677,0.002713,0.068918,-0.304790,-0.015527,0.689184,-117.429710,0.067938,0.000000
149.710007,-0.058838,-117.429710,-0.001716,0.002682,0.068121,-0.261724,-0.013333,0.681206,-117.429710,0.067271,0.000000
150.110001,-0.090118,-117.518669,-0.001725,0.002661,0.067583,-0.400867,-0.020421,0.675829,-117.518669,0.066603,0.000000
150.510010,-0.077827,-117.518669,-0.001755,0.002639,0.067037,-0.346194,-0.017636,0.670365,-117.518669,0.065935,0.000000
150.910004,-0.074104,-117.563156,-0.001794,0.002611,0.066308,-0.329632,-0.016792,0.663081,-117.563156,0.065267,0.000000
151.310013,-0.057716,-117.652115,-0.001811,0.002594,0.065883,-0.256735,-0.013079,0.658831,-117.652115,0.064600,0.000000
151.710007,-0.039101,-117.607635,-0.001850,0.002552,0.064825,-0.173928,-0.008860,0.648251,-117.607635,0.063941,0.000000
152.110001,-0.047668,-117.563156,-0.001871,0.002535,0.064400,-0.212040,-0.010802,0.644002,-117.563156,0.063273,0.000000
152.510010,-0.052132,-117.652115,-0.001888,0.002501,0.063516,-0.231893,-0.011813,0.635156,-117.652115,0.062605,0.000000
152.910004,-0.059952,-117.696594,-0.001901,0.002486,0.063143,-0.266679,-0.013585,0.631427,-117.696594,0.061937,0.000000
153.310013,-0.066284,-117.741081,-0.001953,0.002448,0.062180,-0.294847,-0.015020,0.621801,-117.741081,0.061269,0.000000
153.710007,-0.086761,-117.652115,-0.001983,0.002424,0.061582,-0.385934,-0.019660,0.615817,-117.652115,0.060602,0.000000
154.110001,-0.066658,-117.785561,-0.002001,0.002403,0.061035,-0.296510,-0.015105,0.610353,-117.785561,0.059934,0.000000
154.510010,-0.071121,-117.785561,-0.002031,0.002380,0.060454,-0.316363,-0.016116,0.604543,-117.785561,0.059266,0.000000
154.910004,-0.091232,-117.830040,-0.002061,0.002349,0.059656,-0.405822,-0.020674,0.596565,-117.830040,0.058598,0.000000
155.310013,-0.085274,-117.874519,-0.002091,0.002315,0.058807,-0.379317,-0.019323,0.588066,-117.874519,0.057939,0.000000
155.710007,-0.107620,-117.874519,-0.002117,0.002293,0.058243,-0.478719,-0.024387,0.582429,-117.874519,0.057272,0.000000
156.110001,-0.063675,-117.918999,-0.002143,0.002275,0.057775,-0.283240,-0.014429,0.577746,-117.918999,0.056604,0.000000
156.510010,-0.074478,-118.007965,-0.002164,0.002239,0.056873,-0.331295,-0.016877,0.568727,-118.007965,0.055936,0.000000
156.910004,-0.123260,-117.963486,-0.002173,0.002219,0.056361,-0.548290,-0.027931,0.563610,-117.963486,0.055268,0.000000
157.310013,-0.096443,-118.007965,-0.002225,0.002184,0.055476,-0.429001,-0.021854,0.554764,-118.007965,0.054601,0.000000
157.710007,-0.084160,-118.052444,-0.002246,0.002160,0.054861,-0.374362,-0.019071,0.548607,-118.052444,0.053933,0.000000
158.110001,-0.077080,-118.141403,-0.002276,0.002135,0.054228,-0.342868,-0.017467,0.542276,-118.141403,0.053265,0.000000
158.510010,-0.081924,-118.185890,-0.002276,0.002120,0.053837,-0.364418,-0.018564,0.538374,-118.185890,0.052606,0.000000
158.910004,-0.077454,-118.185890,-0.002324,0.002080,0.052823,-0.344531,-0.017551,0.528227,-118.185890,0.051938,0.000000
159.310013,-0.087883,-118.141403,-0.002354,0.002051,0.052103,-0.390923,-0.019915,0.521029,-118.141403,0.051270,0.000000
159.710007,-0.068146,-118.230370,-0.002389,0.002022,0.051357,-0.303127,-0.015442,0.513571,-118.230370,0.050603,0.000000
160.110001,-0.051758,-118.230370,-0.002410,0.002012,0.051106,-0.230230,-0.011728,0.511056,-118.230370,0.049935,0.000000
160.510010,-0.083412,-118.230370,-0.002432,0.001982,0.050342,-0.371036,-0.018901,0.503425,-118.230370,0.049267,0.000000
160.910004,-0.089371,-118.319328,-0.002445,0.001951,0.049553,-0.397541,-0.020252,0.495533,-118.319328,0.048599,0.000000
161.310013,-0.070007,-118.319328,-0.002488,0.001923,0.048842,-0.311408,-0.015864,0.488422,-118.319328,0.047932,0.000000
161.710007,-0.065170,-118.319328,-0.002505,0.001900,0.048252,-0.289892,-0.014768,0.482524,-118.319328,0.047272,0.000000
162.110001,-0.103523,-118.363808,-0.002531,0.001875,0.047628,-0.460494,-0.023459,0.476280,-118.363808,0.046605,0.000000
162.510010,-0.101288,-118.408295,-0.002561,0.001846,0.046900,-0.450551,-0.022952,0.468996,-118.408295,0.045937,0.000000
162.910004,-0.087135,-118.497253,-0.002587,0.001815,0.046102,-0.387597,-0.019745,0.461017,-118.497253,0.045269,0.000000
163.310013,-0.062561,-118.452774,-0.002613,0.001791,0.045486,-0.278285,-0.014177,0.454860,-118.452774,0.044601,0.000000
163.710007,-0.058838,-118.497253,-0.002647,0.001764,0.044801,-0.261724,-0.013333,0.448009,-118.497253,0.043934,0.000000
164.110001,-0.083412,-118.541733,-0.002660,0.001746,0.044350,-0.371036,-0.018901,0.443499,-118.541733,0.043266,0.000000
164.510010,-0.087883,-118.541733,-0.002682,0.001718,0.043630,-0.390923,-0.019915,0.436301,-118.541733,0.042598,0.000000
164.910004,-0.054741,-118.675179,-0.002725,0.001687,0.042850,-0.243500,-0.012404,0.428496,-118.675179,0.041939,0.000000
165.310013,-0.057350,-118.630699,-0.002751,0.001662,0.042225,-0.255106,-0.012996,0.422252,-118.630699,0.041271,0.000000
165.600006,-0.046547,-118.675179,-0.002772,0.001649,0.041878,-0.207051,-0.010548,0.418783,-118.675179,0.041792,0.000000