File: Data/compression 20/AutoNoHeating-17-20-reverse-1-2_09112024_165150.csv
Time (sec),S:Load (lbs),S:HL1 (DIM),S:LVDT (in),S:Position (in),Ch:Position (mm),Ch:Load (N),Ch:Stress (MPa),Ch:Strain (mm/mm),Ch:HL1 (DIM),Set Point (),Cycles ()
0.110000,-0.029793,-122.367096,-0.009998,-0.005178,-0.131532,-0.132525,-0.006751,-1.315321,-122.367096,-0.131255,0.000000
0.520000,-0.027557,-122.233650,-0.010007,-0.005074,-0.128878,-0.122581,-0.006245,-1.288784,-122.233650,-0.127872,0.000000
0.930000,-0.012665,-122.322617,-0.009813,-0.004819,-0.122409,-0.056336,-0.002870,-1.224089,-122.322617,-0.121056,0.000000
1.340000,-0.035378,-122.411575,-0.009528,-0.004550,-0.115558,-0.157367,-0.008017,-1.155578,-122.411575,-0.114222,0.000000
1.750000,-0.043945,-122.367096,-0.009235,-0.004271,-0.108481,-0.195479,-0.009958,-1.084813,-122.367096,-0.107389,0.000000
2.160000,-0.117668,-122.411575,-0.008990,-0.004008,-0.101812,-0.523414,-0.026664,-1.018123,-122.411575,-0.100555,0.000000
2.570000,-0.042076,-122.411575,-0.008705,-0.003739,-0.094970,-0.187164,-0.009535,-0.949699,-122.411575,-0.093721,0.000000
2.980000,-0.045807,-122.500542,-0.008433,-0.003471,-0.088153,-0.203759,-0.010380,-0.881535,-122.500542,-0.086887,0.000000
3.390000,-0.035378,-122.589500,-0.008144,-0.003201,-0.081302,-0.157367,-0.008017,-0.813024,-122.589500,-0.080071,0.000000
3.800000,-0.033516,-122.545021,-0.007869,-0.002931,-0.074443,-0.149086,-0.007595,-0.744427,-122.545021,-0.073237,0.000000
4.210000,-0.038353,-122.589500,-0.007610,-0.002662,-0.067609,-0.170603,-0.008691,-0.676089,-122.589500,-0.066403,0.000000
4.620000,-0.033516,-122.589500,-0.007330,-0.002396,-0.060871,-0.149086,-0.007595,-0.608706,-122.589500,-0.059570,0.000000
5.030000,-0.005959,-122.633980,-0.007058,-0.002126,-0.054002,-0.026505,-0.001350,-0.540021,-122.633980,-0.052736,0.000000
5.440000,-0.020111,-122.678467,-0.006765,-0.001858,-0.047203,-0.089459,-0.004557,-0.472031,-122.678467,-0.045920,0.000000
5.850000,-0.047295,-122.633980,-0.006493,-0.001586,-0.040274,-0.210377,-0.010717,-0.402740,-122.633980,-0.039086,0.000000
6.260000,-0.083038,-122.767426,-0.006217,-0.001317,-0.033440,-0.369373,-0.018817,-0.334402,-122.767426,-0.032252,0.000000
6.670001,-0.069633,-122.722946,-0.005941,-0.001047,-0.026589,-0.309745,-0.015779,-0.265891,-122.722946,-0.025418,0.000000
7.080000,-0.030167,-122.811905,-0.005670,-0.000781,-0.019833,-0.134188,-0.006836,-0.198335,-122.811905,-0.018585,0.000000
7.490000,-0.019363,-122.811905,-0.005394,-0.000513,-0.013026,-0.086133,-0.004388,-0.130257,-122.811905,-0.011751,0.000000
7.900001,-0.022346,-122.811905,-0.005105,-0.000243,-0.006183,-0.099402,-0.005064,-0.061833,-122.811905,-0.004935,0.000000
8.310000,-0.039848,-122.900871,-0.004855,0.000026,0.000650,-0.177254,-0.009030,0.006504,-122.900871,0.001899,0.000000
8.720000,0.155281,-122.856384,-0.004704,-0.000000,-0.000009,0.690725,0.035187,-0.000087,-122.856384,0.000139,0.000000
9.130000,0.086388,-122.900871,-0.004704,-0.000000,-0.000009,0.384271,0.019576,-0.000087,-122.900871,0.000225,0.000000
9.540001,0.126236,-122.989830,-0.004704,-0.000000,-0.000000,0.561526,0.028605,-0.000000,-122.989830,0.000911,0.000000
9.950001,0.106125,-122.989830,-0.004695,0.000000,0.000009,0.472067,0.024048,0.000087,-122.989830,0.001596,0.000000
10.360001,0.217834,-123.078789,-0.004661,0.000049,0.001240,0.968976,0.049362,0.012401,-123.078789,0.002281,0.000000
10.770000,0.381683,-122.989830,-0.004639,0.000071,0.001804,1.697812,0.086491,0.018038,-122.989830,0.002966,0.000000
11.180000,0.554085,-123.123276,-0.004622,0.000101,0.002567,2.464692,0.125557,0.025670,-123.123276,0.003651,0.000000
11.590000,0.700806,-123.034309,-0.004592,0.000130,0.003295,3.117339,0.158805,0.032955,-123.034309,0.004327,0.000000
12.000001,0.949547,-123.167755,-0.004566,0.000164,0.004154,4.223795,0.215170,0.041540,-123.167755,0.005013,0.000000
12.410001,1.179672,-123.167755,-0.004536,0.000187,0.004752,5.247444,0.267318,0.047524,-123.167755,0.005698,0.000000
12.820001,1.484276,-123.212234,-0.004518,0.000212,0.005385,6.602388,0.336342,0.053855,-123.212234,0.006383,0.000000
13.230000,1.757599,-123.301193,-0.004493,0.000236,0.005993,7.818190,0.398278,0.059925,-123.301193,0.007068,0.000000
13.640000,2.130341,-123.212234,-0.004449,0.000265,0.006721,9.476228,0.482742,0.067210,-123.212234,0.007744,0.000000
14.050000,2.453186,-123.345680,-0.004428,0.000292,0.007423,10.912316,0.555900,0.074235,-123.345680,0.008429,0.000000
14.460001,2.853119,-123.345680,-0.004419,0.000319,0.008091,12.691307,0.646526,0.080912,-123.345680,0.009115,0.000000
14.870001,3.150642,-123.345680,-0.004385,0.000345,0.008768,14.014757,0.713946,0.087677,-123.345680,0.009800,0.000000
15.280001,3.717392,-123.390160,-0.004381,0.000375,0.009522,16.535786,0.842373,0.095221,-123.390160,0.010485,0.000000
15.690001,3.963905,-123.345680,-0.004337,0.000396,0.010068,17.632332,0.898234,0.100685,-123.345680,0.011161,0.000000
16.100000,4.296059,-123.479118,-0.004320,0.000418,0.010624,19.109823,0.973501,0.106235,-123.479118,0.011846,0.000000
16.510000,4.971916,-123.479118,-0.004294,0.000453,0.011517,22.116188,1.126652,0.115168,-123.479118,0.012531,0.000000
16.920000,5.349876,-123.523598,-0.004273,0.000479,0.012176,23.797440,1.212299,0.121758,-123.523598,0.013217,0.000000
17.330000,5.489883,-123.523598,-0.004255,0.000500,0.012705,24.420221,1.244025,0.127049,-123.523598,0.013902,0.000000
17.740002,5.899864,-123.523598,-0.004234,0.000526,0.013355,26.243906,1.336928,0.133553,-123.523598,0.014578,0.000000
18.150002,6.412994,-123.568085,-0.004208,0.000561,0.014257,28.526424,1.453205,0.142572,-123.568085,0.015263,0.000000
18.560001,6.777176,-123.612564,-0.004178,0.000588,0.014942,30.146383,1.535730,0.149423,-123.612564,0.015948,0.000000
18.970001,7.089226,-123.657043,-0.004148,0.000612,0.015549,31.534451,1.606442,0.155494,-123.657043,0.016633,0.000000
19.380001,7.357704,-123.746002,-0.004122,0.000636,0.016156,32.728703,1.667280,0.161564,-123.746002,0.017318,0.000000
19.790001,7.712952,-123.612564,-0.004096,0.000666,0.016928,34.308922,1.747780,0.169282,-123.612564,0.017995,0.000000
20.200001,7.667519,-123.746002,-0.004087,0.000681,0.017310,34.106827,1.737484,0.173098,-123.746002,0.018680,0.000000
20.610001,8.249908,-123.701523,-0.004040,0.000722,0.018333,36.697426,1.869456,0.183332,-123.701523,0.019365,0.000000
21.020000,8.427162,-123.834969,-0.004031,0.000744,0.018897,37.485889,1.909622,0.188968,-123.834969,0.020050,0.000000
21.430000,8.643509,-123.790489,-0.004005,0.000769,0.019539,38.448246,1.958647,0.195386,-123.790489,0.020735,0.000000
21.840000,8.878845,-123.834969,-0.003971,0.000797,0.020250,39.495075,2.011975,0.202497,-123.834969,0.021412,0.000000
22.250002,9.148071,-123.879448,-0.003958,0.000829,0.021065,40.692654,2.072983,0.210649,-123.879448,0.022097,0.000000
22.660002,9.438148,-123.923927,-0.003911,0.000858,0.021785,41.982983,2.138715,0.217847,-123.923927,0.022782,0.000000
23.070002,9.494003,-123.923927,-0.003902,0.000880,0.022348,42.231438,2.151372,0.223484,-123.923927,0.023467,0.000000
23.480001,9.473526,-123.968414,-0.003872,0.000901,0.022895,42.140347,2.146732,0.228948,-123.968414,0.024152,0.000000
23.890001,9.746849,-123.968414,-0.003850,0.000930,0.023632,43.356152,2.208668,0.236319,-123.968414,0.024829,0.000000
24.300001,9.830635,-124.057373,-0.003824,0.000956,0.024291,43.728848,2.227654,0.242910,-124.057373,0.025514,0.000000
24.710001,10.393288,-124.012894,-0.003798,0.000989,0.025115,46.231651,2.355153,0.251149,-124.012894,0.026199,0.000000
25.120001,10.635330,-124.146332,-0.003777,0.001019,0.025887,47.308311,2.410000,0.258867,-124.146332,0.026884,0.000000
25.530001,10.692673,-124.190819,-0.003738,0.001047,0.026606,47.563385,2.422994,0.266065,-124.190819,0.027569,0.000000
25.940001,10.743690,-124.235298,-0.003712,0.001068,0.027127,47.790321,2.434555,0.271268,-124.235298,0.028246,0.000000
26.350000,10.948120,-124.190819,-0.003695,0.001096,0.027847,48.699669,2.480879,0.278466,-124.190819,0.028931,0.000000
26.760002,11.177505,-124.190819,-0.003669,0.001122,0.028506,49.720028,2.532859,0.285057,-124.190819,0.029616,0.000000
27.170002,11.691376,-124.279778,-0.003626,0.001158,0.029416,52.005836,2.649304,0.294163,-124.279778,0.030301,0.000000
27.580002,11.651161,-124.279778,-0.003613,0.001181,0.030006,51.826954,2.640191,0.300060,-124.279778,0.030986,0.000000
27.990002,11.838089,-124.279778,-0.003591,0.001207,0.030656,52.658451,2.682549,0.306564,-124.279778,0.031662,0.000000
28.400002,12.017578,-124.279778,-0.003570,0.001231,0.031272,53.456856,2.723222,0.312722,-124.279778,0.032348,0.000000
28.810001,12.286430,-124.413223,-0.003548,0.001261,0.032018,54.652771,2.784145,0.320180,-124.413223,0.033033,0.000000
29.220001,12.616722,-124.413223,-0.003514,0.001292,0.032816,56.121983,2.858990,0.328158,-124.413223,0.033718,0.000000
29.630001,12.458839,-124.324257,-0.003492,0.001314,0.033371,55.419685,2.823213,0.333708,-124.324257,0.034403,0.000000
30.040001,12.785034,-124.502182,-0.003454,0.001339,0.034013,56.870674,2.897130,0.340126,-124.502182,0.035079,0.000000
30.450001,13.185707,-124.457703,-0.003432,0.001370,0.034793,58.652954,2.987924,0.347931,-124.457703,0.035764,0.000000
30.860001,13.188683,-124.502182,-0.003410,0.001393,0.035374,58.666191,2.988598,0.353741,-124.502182,0.036449,0.000000
31.270002,13.410995,-124.591141,-0.003389,0.001420,0.036068,59.655087,3.038975,0.360679,-124.591141,0.037135,0.000000
31.680002,13.521584,-124.546661,-0.003367,0.001448,0.036779,60.147007,3.064035,0.367790,-124.546661,0.037820,0.000000
32.090000,13.733467,-124.635628,-0.003328,0.001470,0.037334,61.089512,3.112048,0.373341,-124.635628,0.038496,0.000000
32.500000,14.018707,-124.635628,-0.003307,0.001499,0.038071,62.358326,3.176684,0.380712,-124.635628,0.039181,0.000000
32.910000,14.289795,-124.724586,-0.003285,0.001528,0.038817,63.564182,3.238114,0.388170,-124.724586,0.039866,0.000000
33.320000,14.608543,-124.680107,-0.003264,0.001563,0.039693,64.982048,3.310343,0.396929,-124.680107,0.040551,0.000000
33.730003,14.499809,-124.680107,-0.003242,0.001586,0.040283,64.498375,3.285704,0.402826,-124.680107,0.041237,0.000000
34.140003,14.693443,-124.813545,-0.003208,0.001611,0.040916,65.359703,3.329582,0.409157,-124.813545,0.041913,0.000000
34.550003,14.871437,-124.813545,-0.003195,0.001634,0.041514,66.151459,3.369916,0.415141,-124.813545,0.042598,0.000000
34.960003,15.225937,-124.902512,-0.003165,0.001663,0.042251,67.728348,3.450247,0.422512,-124.902512,0.043283,0.000000
35.370003,15.510803,-124.813545,-0.003139,0.001691,0.042954,68.995499,3.514798,0.429537,-124.813545,0.043968,0.000000
35.780003,15.702576,-124.858032,-0.003113,0.001717,0.043613,69.848549,3.558254,0.436128,-124.858032,0.044653,0.000000
36.190002,15.858223,-124.991470,-0.003091,0.001744,0.044307,70.540901,3.593525,0.443066,-124.991470,0.045330,0.000000
36.600002,16.289062,-124.946991,-0.003065,0.001773,0.045026,72.457367,3.691154,0.450264,-124.946991,0.046015,0.000000
37.010002,16.164314,-124.991470,-0.003053,0.001795,0.045599,71.902458,3.662886,0.455987,-124.991470,0.046700,0.000000
37.420002,16.198204,-124.991470,-0.003018,0.001817,0.046145,72.053207,3.670566,0.461451,-124.991470,0.047385,0.000000
37.830002,17.072906,-125.080437,-0.002984,0.001852,0.047038,75.944084,3.868776,0.470383,-125.080437,0.048070,0.000000
38.240002,17.215897,-125.080437,-0.002958,0.001878,0.047706,76.580132,3.901178,0.477061,-125.080437,0.048747,0.000000
38.650002,17.025238,-125.035950,-0.002940,0.001901,0.048296,75.732040,3.857974,0.482958,-125.035950,0.049432,0.000000
39.060001,17.271004,-125.124916,-0.002915,0.001924,0.048877,76.825264,3.913665,0.488768,-125.124916,0.050117,0.000000
39.470001,17.869034,-125.124916,-0.002889,0.001960,0.049787,79.485435,4.049181,0.497874,-125.124916,0.050802,0.000000
39.880001,18.136024,-125.258362,-0.002850,0.001986,0.050455,80.673065,4.109682,0.504552,-125.258362,0.051487,0.000000
40.290001,18.350143,-125.169395,-0.002841,0.002012,0.051106,81.625511,4.158202,0.511056,-125.169395,0.052164,0.000000
40.700001,18.204170,-125.258362,-0.002824,0.002031,0.051583,80.976196,4.125124,0.515826,-125.258362,0.052849,0.000000
41.110001,18.951149,-125.347321,-0.002802,0.002068,0.052519,84.298920,4.294392,0.525192,-125.347321,0.053534,0.000000
41.520000,18.760498,-125.258362,-0.002772,0.002091,0.053109,83.450867,4.251190,0.531089,-125.258362,0.054219,0.000000
41.930000,19.208084,-125.347321,-0.002746,0.002117,0.053777,85.441826,4.352614,0.537767,-125.347321,0.054904,0.000000
42.340000,19.551414,-125.302841,-0.002734,0.002143,0.054427,86.969032,4.430414,0.544271,-125.302841,0.055580,0.000000
42.750004,19.800529,-125.391800,-0.002708,0.002168,0.055060,88.077156,4.486864,0.550602,-125.391800,0.056266,0.000000
43.160004,20.203812,-125.436279,-0.002673,0.002196,0.055771,89.871040,4.578249,0.557713,-125.436279,0.056951,0.000000
43.570004,21.046494,-125.436279,-0.002652,0.002230,0.056639,93.619476,4.769204,0.566385,-125.436279,0.057636,0.000000
43.980003,21.283318,-125.525246,-0.002621,0.002258,0.057350,94.672928,4.822868,0.573496,-125.525246,0.058321,0.000000
44.390003,21.263954,-125.480766,-0.002604,0.002279,0.057879,94.586792,4.818481,0.578786,-125.480766,0.058997,0.000000
44.800003,21.218895,-125.525246,-0.002574,0.002305,0.058546,94.386360,4.808270,0.585464,-125.525246,0.059682,0.000000
45.210003,21.915977,-125.525246,-0.002552,0.002331,0.059214,97.487137,4.966232,0.592142,-125.525246,0.060368,0.000000
45.620003,22.151688,-125.614204,-0.002539,0.002354,0.059787,98.535629,5.019644,0.597865,-125.614204,0.061053,0.000000
46.030003,22.907982,-125.658684,-0.002518,0.002387,0.060636,101.899796,5.191023,0.606364,-125.658684,0.061738,0.000000
46.440002,23.669479,-125.658684,-0.002479,0.002418,0.061408,105.287102,5.363581,0.614083,-125.658684,0.062414,0.000000
46.850002,24.030312,-125.747650,-0.002466,0.002447,0.062154,106.892166,5.445347,0.621541,-125.747650,0.063099,0.000000
47.260002,23.953598,-125.703171,-0.002432,0.002466,0.062648,106.550926,5.427963,0.626484,-125.703171,0.063784,0.000000
47.670002,24.695366,-125.747650,-0.002406,0.002497,0.063429,109.850471,5.596050,0.634289,-125.747650,0.064470,0.000000
48.080002,25.000710,-125.792130,-0.002397,0.002520,0.064019,111.208710,5.665242,0.640186,-125.792130,0.065155,0.000000
48.490002,26.101074,-125.792130,-0.002363,0.002557,0.064955,116.103378,5.914588,0.649552,-125.792130,0.065831,0.000000
48.900002,26.248535,-125.881088,-0.002337,0.002580,0.065528,116.759315,5.948003,0.655276,-125.881088,0.066516,0.000000
49.310001,26.604897,-125.925575,-0.002315,0.002605,0.066161,118.344490,6.028756,0.661606,-125.925575,0.067201,0.000000
49.720001,27.081528,-125.881088,-0.002289,0.002631,0.066820,120.464653,6.136762,0.668197,-125.881088,0.067886,0.000000
50.130001,27.827766,-125.925575,-0.002268,0.002659,0.067540,123.784088,6.305862,0.675395,-125.925575,0.068572,0.000000
50.540001,28.738960,-125.925575,-0.002246,0.002690,0.068337,127.837280,6.512341,0.683374,-125.925575,0.069248,0.000000
50.950001,28.800400,-126.059013,-0.002233,0.002713,0.068918,128.110580,6.526264,0.689184,-126.059013,0.069933,0.000000
51.360001,29.472908,-125.970055,-0.002207,0.002738,0.069534,131.102036,6.678656,0.695342,-125.970055,0.070618,0.000000
51.770004,29.623344,-126.059013,-0.002182,0.002761,0.070141,131.771210,6.712746,0.701412,-126.059013,0.071303,0.000000
52.180004,30.863716,-126.059013,-0.002156,0.002791,0.070887,137.288666,6.993818,0.708870,-126.059013,0.071988,0.000000
52.590004,31.574203,-126.147980,-0.002130,0.002817,0.071563,140.449066,7.154817,0.715635,-126.147980,0.072665,0.000000
53.000004,32.031479,-126.192459,-0.002108,0.002844,0.072249,142.483139,7.258437,0.722486,-126.192459,0.073350,0.000000
53.410004,32.979164,-126.192459,-0.002100,0.002870,0.072899,146.698654,7.473186,0.728990,-126.192459,0.074035,0.000000
53.820004,33.823708,-126.192459,-0.002074,0.002897,0.073575,150.455368,7.664562,0.735754,-126.192459,0.074720,0.000000
54.230003,34.887573,-126.236938,-0.002048,0.002929,0.074399,155.187683,7.905637,0.743993,-126.236938,0.075405,0.000000
54.640003,35.999481,-126.281418,-0.002031,0.002960,0.075188,160.133698,8.157598,0.751885,-126.281418,0.076082,0.000000
55.050003,36.225136,-126.325897,-0.002013,0.002983,0.075770,161.137451,8.208733,0.757695,-126.325897,0.076767,0.000000
55.460003,36.988503,-126.325897,-0.001996,0.003008,0.076411,164.533081,8.381714,0.764113,-126.325897,0.077452,0.000000
55.870003,37.733620,-126.370384,-0.001966,0.003033,0.077036,167.847519,8.550561,0.770357,-126.370384,0.078137,0.000000
56.280003,38.883507,-126.414864,-0.001949,0.003062,0.077773,172.962479,8.811129,0.777728,-126.414864,0.078822,0.000000
56.690002,39.879227,-126.414864,-0.001914,0.003089,0.078467,177.391663,9.036761,0.784666,-126.414864,0.079499,0.000000
57.100002,40.832870,-126.503822,-0.001914,0.003116,0.079134,181.633682,9.252861,0.791343,-126.503822,0.080184,0.000000
57.510002,41.677040,-126.548309,-0.001897,0.003142,0.079819,185.388733,9.444153,0.798195,-126.548309,0.080869,0.000000
57.920002,43.132645,-126.503822,-0.001880,0.003173,0.080591,191.863586,9.773997,0.805913,-126.503822,0.081554,0.000000
58.330002,43.737747,-126.548309,-0.001850,0.003194,0.081120,194.555222,9.911116,0.811203,-126.548309,0.082239,0.000000
58.740002,44.709641,-126.592789,-0.001837,0.003220,0.081788,198.878418,10.131350,0.817881,-126.592789,0.082915,0.000000
59.150002,46.279938,-126.637268,-0.001819,0.003250,0.082543,205.863449,10.487185,0.825425,-126.637268,0.083601,0.000000
59.560001,47.330399,-126.637268,-0.001802,0.003276,0.083219,210.536133,10.725222,0.832190,-126.637268,0.084286,0.000000
59.970001,48.121323,-126.726227,-0.001785,0.003301,0.083852,214.054337,10.904448,0.838521,-126.726227,0.084971,0.000000
60.380001,49.457390,-126.681747,-0.001759,0.003324,0.084433,219.997452,11.207205,0.844331,-126.681747,0.085656,0.000000
60.790005,51.038483,-126.770714,-0.001742,0.003357,0.085266,227.030502,11.565485,0.852656,-126.770714,0.086332,0.000000
61.200005,52.040169,-126.815193,-0.001720,0.003383,0.085933,231.486237,11.792471,0.859334,-126.815193,0.087017,0.000000
61.610004,53.655891,-126.726227,-0.001712,0.003409,0.086584,238.673325,12.158599,0.865838,-126.726227,0.087703,0.000000
62.020004,54.787155,-126.815193,-0.001690,0.003433,0.087200,243.705444,12.414948,0.871995,-126.815193,0.088388,0.000000
62.430004,56.123604,-126.815193,-0.001673,0.003463,0.087963,249.650253,12.717790,0.879627,-126.815193,0.089073,0.000000
62.840004,57.761673,-126.948631,-0.001656,0.003493,0.088726,256.936768,13.088982,0.887259,-126.948631,0.089749,0.000000
63.250004,58.702652,-126.904152,-0.001647,0.003516,0.089298,261.122437,13.302211,0.892982,-126.904152,0.090434,0.000000
63.660004,60.534729,-126.904152,-0.001625,0.003541,0.089940,269.271912,13.717366,0.899400,-126.904152,0.091119,0.000000
64.070000,61.826485,-126.993118,-0.001604,0.003565,0.090556,275.017944,14.010081,0.905557,-126.993118,0.091805,0.000000
64.480003,63.477966,-126.948631,-0.001600,0.003594,0.091293,282.364105,14.384313,0.912928,-126.948631,0.092490,0.000000
64.889999,65.041183,-127.082077,-0.001569,0.003627,0.092134,289.317627,14.738543,0.921341,-127.082077,0.093166,0.000000
65.300003,65.369614,-126.993118,-0.001552,0.003629,0.092177,290.778564,14.812966,0.921774,-126.993118,0.016181,0.000000
65.710007,65.688370,-127.126556,-0.001539,0.003639,0.092420,292.196472,14.885198,0.924202,-127.126556,294.500458,0.000000
66.120003,64.523209,-127.082077,-0.001552,0.003639,0.092429,287.013580,14.621168,0.924289,-127.082077,294.500458,0.000000
66.530006,65.899124,-127.126556,-0.001505,0.003607,0.091622,293.133942,14.932955,0.916224,-127.126556,294.500458,0.000000
66.940002,65.161453,-127.171036,-0.001509,0.003658,0.092923,289.852631,14.765797,0.929232,-127.171036,294.500458,0.000000
67.350006,64.929474,-127.126556,-0.001513,0.003671,0.093253,288.820740,14.713228,0.932528,-127.126556,294.500458,0.000000
67.760002,64.943253,-127.215523,-0.001509,0.003676,0.093366,288.882019,14.716352,0.933655,-127.215523,294.500458,0.000000
68.170006,65.360306,-127.260002,-0.001500,0.003687,0.093652,290.737152,14.810857,0.936517,-127.260002,294.500458,0.000000
68.580002,64.841965,-127.260002,-0.001487,0.003687,0.093652,288.431458,14.693399,0.936517,-127.260002,294.500458,0.000000
68.990005,66.311340,-127.348961,-0.001479,0.003690,0.093721,294.967560,15.026364,0.937211,-127.348961,294.500458,0.000000
69.400002,65.725601,-127.304482,-0.001470,0.003690,0.093721,292.362061,14.893634,0.937211,-127.304482,294.500458,0.000000
69.810005,65.183426,-127.437927,-0.001466,0.003690,0.093730,289.950348,14.770775,0.937298,-127.437927,294.500458,0.000000
70.220001,65.817581,-127.393440,-0.001479,0.003714,0.094337,292.771210,14.914477,0.943368,-127.393440,294.500458,0.000000
70.630005,65.352478,-127.437927,-0.001462,0.003714,0.094337,290.702332,14.809083,0.943368,-127.437927,294.500458,0.000000
71.040001,65.453400,-127.482407,-0.001470,0.003722,0.094536,291.151276,14.831953,0.945363,-127.482407,294.500458,0.000000
71.450005,65.253799,-127.482407,-0.001466,0.003722,0.094536,290.263397,14.786722,0.945363,-127.482407,294.500458,0.000000
71.860001,65.284714,-127.571365,-0.001466,0.003726,0.094649,290.400909,14.793728,0.946490,-127.571365,294.500458,0.000000
72.270004,65.047882,-127.526886,-0.001462,0.003727,0.094658,289.347443,14.740061,0.946577,-127.526886,294.500458,0.000000
72.680000,65.038193,-127.571365,-0.001444,0.003730,0.094736,289.304321,14.737865,0.947357,-127.571365,294.500458,0.000000
73.090004,65.067245,-127.615852,-0.001453,0.003734,0.094848,289.433563,14.744449,0.948485,-127.615852,294.500458,0.000000
73.500000,64.960373,-127.615852,-0.001462,0.003735,0.094857,288.958160,14.720231,0.948571,-127.615852,294.500458,0.000000
73.910004,65.080658,-127.704811,-0.001453,0.003739,0.094979,289.493225,14.747488,0.949786,-127.704811,294.500458,0.000000
74.320007,64.930954,-127.615852,-0.001453,0.003739,0.094979,288.827301,14.713565,0.949786,-127.615852,294.500458,0.000000
74.730003,65.439240,-127.704811,-0.001444,0.003747,0.095169,291.088287,14.828744,0.951693,-127.704811,294.500458,0.000000
75.140007,65.269073,-127.749290,-0.001444,0.003747,0.095169,290.331329,14.790184,0.951693,-127.749290,294.500458,0.000000
75.550003,65.095551,-127.793770,-0.001440,0.003747,0.095178,289.559479,14.750862,0.951780,-127.793770,294.500458,0.000000
75.960007,65.000214,-127.838257,-0.001427,0.003749,0.095213,289.135376,14.729259,0.952127,-127.838257,294.500458,0.000000
76.370003,65.095169,-127.793770,-0.001436,0.003752,0.095308,289.557770,14.750776,0.953081,-127.793770,294.500458,0.000000
76.780006,64.976761,-127.838257,-0.001431,0.003752,0.095308,289.031067,14.723944,0.953081,-127.838257,294.500458,0.000000
77.190002,65.200562,-127.882736,-0.001440,0.003757,0.095421,290.026581,14.774658,0.954208,-127.882736,294.500458,0.000000
77.600006,65.058685,-127.882736,-0.001444,0.003757,0.095421,289.395477,14.742508,0.954208,-127.882736,294.500458,0.000000
78.010002,64.941010,-127.927216,-0.001427,0.003757,0.095421,288.872040,14.715843,0.954208,-127.927216,294.500458,0.000000
78.420006,64.783127,-127.971695,-0.001431,0.003757,0.095430,288.169739,14.680066,0.954295,-127.971695,294.500458,0.000000
78.830002,64.662842,-128.016174,-0.001418,0.003757,0.095430,287.634674,14.652809,0.954295,-128.016174,294.500458,0.000000
79.240005,65.860397,-128.060654,-0.001423,0.003762,0.095551,292.961670,14.924179,0.955509,-128.060654,294.500458,0.000000
79.650002,65.662674,-128.105133,-0.001414,0.003762,0.095551,292.082153,14.879375,0.955509,-128.105133,294.500458,0.000000
80.060005,65.527863,-128.149612,-0.001427,0.003762,0.095551,291.482483,14.848825,0.955509,-128.149612,294.500458,0.000000
80.470001,65.317108,-128.149612,-0.001414,0.003762,0.095551,290.545013,14.801068,0.955509,-128.149612,294.500458,0.000000
80.880005,65.190872,-128.194107,-0.001410,0.003762,0.095551,289.983490,14.772463,0.955509,-128.194107,294.500458,0.000000
81.290001,65.019577,-128.194107,-0.001410,0.003762,0.095551,289.221527,14.733647,0.955509,-128.194107,294.500458,0.000000
81.700005,64.889618,-128.327545,-0.001418,0.003762,0.095551,288.643433,14.704198,0.955509,-128.327545,294.500458,0.000000
82.110001,64.748489,-128.238586,-0.001418,0.003762,0.095551,288.015656,14.672217,0.955509,-128.238586,294.500458,0.000000
82.520004,64.630447,-128.283066,-0.001414,0.003762,0.095551,287.490601,14.645469,0.955509,-128.283066,294.500458,0.000000
82.930000,64.480011,-128.416504,-0.001406,0.003762,0.095551,286.821411,14.611379,0.955509,-128.416504,294.500458,0.000000
83.340004,64.370163,-128.283066,-0.001431,0.003762,0.095551,286.332794,14.586488,0.955509,-128.283066,294.500458,0.000000
83.750008,66.702332,-128.372025,-0.001397,0.003668,0.093175,296.706787,15.114964,0.931747,-128.372025,294.500458,0.000000
84.160004,66.592117,-128.372025,-0.001401,0.003668,0.093175,296.216522,15.089989,0.931747,-128.372025,294.500458,0.000000
84.570007,66.408157,-128.416504,-0.001388,0.003669,0.093201,295.398224,15.048304,0.932007,-128.416504,294.500458,0.000000
84.980003,66.283417,-128.505463,-0.001397,0.003669,0.093201,294.843353,15.020038,0.932007,-128.505463,294.500458,0.000000
85.390007,66.163879,-128.416504,-0.001388,0.003669,0.093201,294.311646,14.992949,0.932007,-128.416504,294.500458,0.000000
85.800003,66.040253,-128.549942,-0.001384,0.003669,0.093201,293.761719,14.964935,0.932007,-128.549942,294.500458,0.000000
86.210007,65.879013,-128.549942,-0.001397,0.003670,0.093218,293.044495,14.928398,0.932181,-128.549942,294.500458,0.000000
86.620003,65.861893,-128.549942,-0.001380,0.003676,0.093366,292.968323,14.924518,0.933655,-128.549942,294.500458,0.000000
87.030006,65.756882,-128.638916,-0.001388,0.003677,0.093400,292.501221,14.900723,0.934002,-128.638916,294.500458,0.000000
87.440002,65.580002,-128.549942,-0.001384,0.003728,0.094692,291.714417,14.860641,0.946924,-128.549942,294.500458,0.000000
87.850006,65.500320,-128.683395,-0.001380,0.003730,0.094736,291.359985,14.842586,0.947357,-128.683395,294.500458,0.000000
88.260002,65.400146,-128.683395,-0.001388,0.003749,0.095213,290.914368,14.819884,0.952127,-128.683395,294.500458,0.000000
88.670006,65.318970,-128.683395,-0.001375,0.003752,0.095308,290.553284,14.801490,0.953081,-128.683395,294.500458,0.000000
89.080002,65.235931,-128.772354,-0.001388,0.003752,0.095308,290.183929,14.782673,0.953081,-128.772354,294.500458,0.000000
89.490005,65.165924,-128.683395,-0.001380,0.003760,0.095516,289.872498,14.766809,0.955162,-128.683395,294.500458,0.000000
89.900002,65.138367,-128.816833,-0.001393,0.003773,0.095828,289.749939,14.760565,0.958284,-128.816833,294.500458,0.000000
90.310005,65.102249,-128.772354,-0.001384,0.003781,0.096045,289.589264,14.752380,0.960452,-128.772354,294.500458,0.000000
90.720001,65.145065,-128.861313,-0.001388,0.003785,0.096149,289.779724,14.762082,0.961493,-128.861313,294.500458,0.000000
91.130005,65.167038,-128.861313,-0.001406,0.003785,0.096149,289.877472,14.767062,0.961493,-128.861313,294.500458,0.000000
91.540001,65.254913,-128.861313,-0.001380,0.003788,0.096219,290.268341,14.786975,0.962187,-128.861313,294.500458,0.000000
91.950005,65.213959,-128.950272,-0.001384,0.003788,0.096219,290.086182,14.777695,0.962187,-128.950272,294.500458,0.000000
92.360001,65.176346,-128.905792,-0.001384,0.003788,0.096227,289.918854,14.769171,0.962274,-128.905792,294.500458,0.000000
92.770004,65.110809,-128.994751,-0.001380,0.003788,0.096227,289.627350,14.754320,0.962274,-128.994751,294.500458,0.000000
93.180008,65.176727,-128.994751,-0.001388,0.003791,0.096297,289.920563,14.769257,0.962967,-128.994751,294.500458,0.000000
93.590004,65.179337,-129.039246,-0.001384,0.003791,0.096297,289.932159,14.769849,0.962967,-129.039246,294.500458,0.000000
94.000008,65.155121,-129.083725,-0.001384,0.003792,0.096305,289.824463,14.764361,0.963054,-129.083725,294.500458,0.000000
94.410004,65.103363,-129.083725,-0.001388,0.003792,0.096305,289.594208,14.752633,0.963054,-129.083725,294.500458,0.000000
94.820007,65.041550,-129.172684,-0.001380,0.003792,0.096305,289.319275,14.738626,0.963054,-129.172684,294.500458,0.000000
95.230003,64.984573,-129.128204,-0.001397,0.003792,0.096305,289.065826,14.725715,0.963054,-129.128204,294.500458,0.000000
95.640007,65.597137,-129.083725,-0.001375,0.003800,0.096531,291.790649,14.864524,0.965309,-129.083725,294.500458,0.000000
96.050003,65.583359,-129.217163,-0.001380,0.003800,0.096531,291.729340,14.861402,0.965309,-129.217163,294.500458,0.000000
96.460007,65.580368,-129.261642,-0.001384,0.003800,0.096531,291.716034,14.860724,0.965309,-129.261642,294.500458,0.000000
96.870003,65.550217,-129.306122,-0.001384,0.003800,0.096531,291.581940,14.853891,0.965309,-129.306122,294.500458,0.000000
97.280006,65.499573,-129.350601,-0.001397,0.003800,0.096531,291.356659,14.842416,0.965309,-129.350601,294.500458,0.000000
97.690002,65.458603,-129.306122,-0.001367,0.003800,0.096531,291.174408,14.833131,0.965309,-129.306122,294.500458,0.000000
98.100006,65.383759,-129.350601,-0.001388,0.003800,0.096531,290.841492,14.816172,0.965309,-129.350601,294.500458,0.000000
98.510002,65.334976,-129.350601,-0.001384,0.003800,0.096531,290.624481,14.805117,0.965309,-129.350601,294.500458,0.000000
98.920006,65.272415,-129.484055,-0.001375,0.003801,0.096540,290.346191,14.790941,0.965396,-129.484055,294.500458,0.000000
99.330002,65.229233,-129.484055,-0.001384,0.003801,0.096540,290.154114,14.781156,0.965396,-129.484055,294.500458,0.000000
99.740005,65.187515,-129.439575,-0.001367,0.003801,0.096540,289.968536,14.771702,0.965396,-129.439575,294.500458,0.000000
100.150002,65.125702,-129.528534,-0.001388,0.003801,0.096540,289.693604,14.757695,0.965396,-129.528534,294.500458,0.000000
100.560005,65.076187,-129.528534,-0.001393,0.003801,0.096540,289.473328,14.746475,0.965396,-129.528534,294.500458,0.000000
100.970001,65.035599,-129.661972,-0.001375,0.003801,0.096540,289.292786,14.737277,0.965396,-129.661972,294.500458,0.000000
101.380005,65.490631,-129.617493,-0.001384,0.003808,0.096730,291.316864,14.840389,0.967304,-129.617493,294.500458,0.000000
101.790009,65.543884,-129.617493,-0.001375,0.003808,0.096730,291.553772,14.852456,0.967304,-129.617493,294.500458,0.000000
102.200005,65.535690,-129.661972,-0.001388,0.003808,0.096730,291.517303,14.850599,0.967304,-129.661972,294.500458,0.000000
102.610008,65.502914,-129.661972,-0.001384,0.003808,0.096730,291.371521,14.843173,0.967304,-129.661972,294.500458,0.000000
103.020004,65.486160,-129.750931,-0.001380,0.003808,0.096730,291.296997,14.839376,0.967304,-129.750931,294.500458,0.000000
103.430008,65.404984,-129.750931,-0.001362,0.003808,0.096730,290.935883,14.820981,0.967304,-129.750931,294.500458,0.000000
103.840004,65.371841,-129.750931,-0.001375,0.003808,0.096730,290.788483,14.813471,0.967304,-129.750931,294.500458,0.000000
104.250008,65.339447,-129.795410,-0.001384,0.003808,0.096730,290.644379,14.806130,0.967304,-129.795410,294.500458,0.000000
104.660004,65.292160,-129.839890,-0.001371,0.003808,0.096730,290.434021,14.795415,0.967304,-129.839890,294.500458,0.000000
105.070007,65.269440,-129.884384,-0.001384,0.003809,0.096739,290.332977,14.790266,0.967390,-129.884384,294.500458,0.000000
105.480003,65.229965,-129.884384,-0.001380,0.003809,0.096739,290.157379,14.781322,0.967390,-129.884384,294.500458,0.000000
105.890007,65.184921,-129.928864,-0.001371,0.003809,0.096739,289.957001,14.771114,0.967390,-129.928864,294.500458,0.000000
106.300003,65.143204,-129.973343,-0.001375,0.003809,0.096739,289.771454,14.761662,0.967390,-129.973343,294.500458,0.000000
106.710007,65.082520,-130.017822,-0.001362,0.003809,0.096748,289.501495,14.747910,0.967477,-130.017822,294.500458,0.000000
107.120003,65.056076,-130.017822,-0.001371,0.003809,0.096748,289.383881,14.741918,0.967477,-130.017822,294.500458,0.000000
107.530006,65.022186,-130.062302,-0.001367,0.003809,0.096748,289.233124,14.734238,0.967477,-130.062302,294.500458,0.000000
107.940002,64.970795,-130.106781,-0.001375,0.003809,0.096748,289.004517,14.722592,0.967477,-130.106781,294.500458,0.000000
108.350006,64.951431,-130.062302,-0.001375,0.003809,0.096748,288.918396,14.718204,0.967477,-130.062302,294.500458,0.000000
108.760002,64.903778,-130.151260,-0.001375,0.003809,0.096748,288.706421,14.707407,0.967477,-130.151260,294.500458,0.000000
109.170006,64.856857,-130.151260,-0.001375,0.003809,0.096748,288.497711,14.696774,0.967477,-130.151260,294.500458,0.000000
109.580002,64.818130,-130.195740,-0.001375,0.003809,0.096748,288.325439,14.687998,0.967477,-130.195740,294.500458,0.000000
109.990005,65.987747,-130.240219,-0.001375,0.003822,0.097077,293.528168,14.953037,0.970772,-130.240219,294.500458,0.000000
110.400002,65.937485,-130.240219,-0.001384,0.003821,0.097051,293.304596,14.941648,0.970512,-130.240219,294.500458,0.000000
110.810005,65.867477,-130.284698,-0.001350,0.003821,0.097051,292.993164,14.925783,0.970512,-130.284698,294.500458,0.000000
111.220009,65.874924,-130.329193,-0.001371,0.003821,0.097051,293.026306,14.927471,0.970512,-130.329193,294.500458,0.000000
111.630005,65.853699,-130.373672,-0.001367,0.003821,0.097051,292.931885,14.922662,0.970512,-130.373672,294.500458,0.000000
112.040009,65.819061,-130.373672,-0.001371,0.003821,0.097051,292.777802,14.914812,0.970512,-130.373672,294.500458,0.000000
112.450005,65.771027,-130.329193,-0.001362,0.003821,0.097051,292.564148,14.903927,0.970512,-130.329193,294.500458,0.000000
112.860008,65.750916,-130.418152,-0.001380,0.003821,0.097051,292.474670,14.899371,0.970512,-130.418152,294.500458,0.000000
113.270004,65.708099,-130.462631,-0.001367,0.003821,0.097051,292.284210,14.889668,0.970512,-130.462631,294.500458,0.000000
113.680008,65.665649,-130.462631,-0.001367,0.003821,0.097051,292.095398,14.880049,0.970512,-130.462631,294.500458,0.000000
114.090004,65.640320,-130.596069,-0.001367,0.003821,0.097051,291.982727,14.874309,0.970512,-130.596069,294.500458,0.000000
114.500008,65.590057,-130.507111,-0.001358,0.003821,0.097051,291.759155,14.862919,0.970512,-130.507111,294.500458,0.000000
114.910004,65.569580,-130.596069,-0.001371,0.003821,0.097051,291.668060,14.858279,0.970512,-130.596069,294.500458,0.000000
115.320007,65.552444,-130.596069,-0.001362,0.003821,0.097051,291.591827,14.854396,0.970512,-130.596069,294.500458,0.000000
115.730003,65.515961,-130.596069,-0.001367,0.003821,0.097051,291.429535,14.846128,0.970512,-130.596069,294.500458,0.000000
116.140007,65.487656,-130.685028,-0.001367,0.003821,0.097051,291.303650,14.839715,0.970512,-130.685028,294.500458,0.000000
116.550003,65.446320,-130.685028,-0.001367,0.003821,0.097051,291.119781,14.830348,0.970512,-130.685028,294.500458,0.000000
116.960007,65.399780,-130.729523,-0.001371,0.003821,0.097051,290.912750,14.819802,0.970512,-130.729523,294.500458,0.000000
117.370003,65.380783,-130.774002,-0.001358,0.003821,0.097051,290.828247,14.815497,0.970512,-130.774002,294.500458,0.000000
117.780006,65.332367,-130.774002,-0.001367,0.003821,0.097051,290.612885,14.804526,0.970512,-130.774002,294.500458,0.000000
118.190002,65.299973,-130.818481,-0.001362,0.003821,0.097051,290.468781,14.797185,0.970512,-130.818481,294.500458,0.000000
118.600006,65.285461,-130.774002,-0.001362,0.003821,0.097051,290.404236,14.793897,0.970512,-130.774002,294.500458,0.000000
119.010002,65.238907,-130.862961,-0.001371,0.003821,0.097051,290.197144,14.783348,0.970512,-130.862961,294.500458,0.000000
119.420006,65.213211,-130.862961,-0.001362,0.003821,0.097051,290.082855,14.777525,0.970512,-130.862961,294.500458,0.000000
119.830009,65.177841,-130.862961,-0.001375,0.003821,0.097051,289.925507,14.769509,0.970512,-130.862961,294.500458,0.000000
120.240005,65.119751,-130.907440,-0.001371,0.003821,0.097051,289.667114,14.756347,0.970512,-130.907440,294.500458,0.000000
120.650009,65.108582,-130.996399,-0.001375,0.003822,0.097086,289.617432,14.753816,0.970859,-130.996399,294.500458,0.000000
121.060005,65.100754,-131.040878,-0.001371,0.003823,0.097103,289.582611,14.752042,0.971033,-131.040878,294.500458,0.000000
121.470009,65.083633,-130.996399,-0.001362,0.003823,0.097103,289.506470,14.748162,0.971033,-130.996399,294.500458,0.000000
121.880005,65.090698,-131.040878,-0.001358,0.003823,0.097103,289.537872,14.749763,0.971033,-131.040878,294.500458,0.000000
122.290009,65.053101,-131.085358,-0.001354,0.003823,0.097103,289.370636,14.741242,0.971033,-131.085358,294.500458,0.000000
122.700005,65.032608,-131.085358,-0.001358,0.003823,0.097103,289.279480,14.736600,0.971033,-131.085358,294.500458,0.000000
123.110008,65.018097,-131.085358,-0.001375,0.003823,0.097103,289.214935,14.733311,0.971033,-131.085358,294.500458,0.000000
123.520004,65.002823,-131.174332,-0.001367,0.003823,0.097112,289.147003,14.729851,0.971119,-131.174332,294.500458,0.000000
123.930008,64.975647,-131.218811,-0.001350,0.003823,0.097112,289.026123,14.723693,0.971119,-131.218811,294.500458,0.000000
124.340004,64.952179,-131.263290,-0.001354,0.003823,0.097112,288.921722,14.718374,0.971119,-131.263290,294.500458,0.000000
124.750008,65.700653,-131.218811,-0.001367,0.003833,0.097363,292.251099,14.887981,0.973634,-131.218811,294.500458,0.000000
125.160004,65.770660,-131.218811,-0.001371,0.003833,0.097363,292.562500,14.903845,0.973634,-131.218811,294.500458,0.000000
125.570007,65.775497,-131.307770,-0.001354,0.003833,0.097363,292.584015,14.904941,0.973634,-131.307770,294.500458,0.000000
125.980003,65.744217,-131.352249,-0.001350,0.003830,0.097285,292.444885,14.897853,0.972854,-131.352249,0.097129,0.000000
126.390007,65.686508,-131.307770,-0.001354,0.003807,0.096704,292.188171,14.884775,0.967043,-131.307770,0.096444,0.000000
126.800003,65.527130,-131.396729,-0.001345,0.003789,0.096245,291.479218,14.848660,0.962447,-131.396729,0.095759,0.000000
127.210007,65.495850,-131.396729,-0.001341,0.003762,0.095560,291.340088,14.841572,0.955596,-131.396729,0.095074,0.000000
127.620003,65.441101,-131.441208,-0.001341,0.003738,0.094944,291.096558,14.829165,0.949439,-131.441208,0.094398,0.000000
128.029999,65.444458,-131.530167,-0.001337,0.003714,0.094345,291.111481,14.829926,0.943455,-131.530167,0.093712,0.000000
128.440002,65.364777,-131.441208,-0.001345,0.003683,0.093539,290.757050,14.811871,0.935390,-131.441208,0.093027,0.000000
128.850006,65.341309,-131.574646,-0.001337,0.003661,0.092984,290.652649,14.806552,0.929839,-131.574646,0.092342,0.000000
129.260010,65.201294,-131.574646,-0.001341,0.003631,0.092221,290.029846,14.774824,0.922208,-131.574646,0.091657,0.000000
129.670013,65.076553,-131.574646,-0.001332,0.003608,0.091631,289.474976,14.746557,0.916311,-131.574646,0.090981,0.000000
130.080002,64.484482,-131.619141,-0.001337,0.003587,0.091119,286.841309,14.612392,0.911194,-131.619141,0.090296,0.000000
130.490005,63.438492,-131.619141,-0.001324,0.003555,0.090296,282.188507,14.375367,0.902955,-131.619141,0.089610,0.000000
130.900009,62.466965,-131.752579,-0.001319,0.003538,0.089853,277.866943,14.155217,0.898533,-131.752579,0.088925,0.000000
131.310013,61.054558,-131.663620,-0.001315,0.003515,0.089290,271.584229,13.835160,0.892896,-131.663620,0.088240,0.000000
131.720001,58.801704,-131.708099,-0.001315,0.003484,0.088492,261.563049,13.324656,0.884917,-131.708099,0.087564,0.000000
132.130005,56.449432,-131.797058,-0.001315,0.003454,0.087737,251.099609,12.791624,0.877372,-131.797058,0.086879,0.000000
132.540009,54.268074,-131.797058,-0.001319,0.003431,0.087148,241.396454,12.297321,0.871475,-131.797058,0.086194,0.000000
132.950012,51.976120,-131.841537,-0.001306,0.003404,0.086454,231.201324,11.777957,0.864537,-131.841537,0.085508,0.000000
133.360001,49.519203,-131.797058,-0.001315,0.003384,0.085951,220.272415,11.221212,0.859507,-131.797058,0.084823,0.000000
133.770004,46.654541,-131.886017,-0.001311,0.003355,0.085222,207.529770,10.572070,0.852223,-131.886017,0.084147,0.000000
134.180008,43.318085,-131.886017,-0.001311,0.003322,0.084390,192.688461,9.816018,0.843897,-131.886017,0.083462,0.000000
134.590012,40.214737,-131.930496,-0.001306,0.003296,0.083713,178.884079,9.112790,0.837133,-131.930496,0.082777,0.000000
135.000000,37.260330,-132.019470,-0.001328,0.003268,0.083002,165.742233,8.443312,0.830022,-132.019470,0.082092,0.000000
135.410004,36.352486,-132.019470,-0.001332,0.003263,0.082881,161.703934,8.237591,0.828808,-132.019470,0.081406,0.000000
135.820007,32.256393,-132.108429,-0.001328,0.003224,0.081883,143.483597,7.309403,0.818834,-132.108429,0.080730,0.000000
136.230011,28.501389,-132.019470,-0.001315,0.003187,0.080947,126.780510,6.458507,0.809468,-132.019470,0.080045,0.000000
136.639999,25.791634,-132.063950,-0.001311,0.003162,0.080314,114.726913,5.844468,0.803138,-132.063950,0.079360,0.000000
137.050003,23.650490,-132.108429,-0.001311,0.003145,0.079889,105.202629,5.359277,0.798888,-132.108429,0.078675,0.000000
137.460007,20.590706,-132.152908,-0.001319,0.003117,0.079160,91.592033,4.665920,0.791604,-132.152908,0.077990,0.000000
137.870010,17.002525,-132.241867,-0.001328,0.003081,0.078250,75.631012,3.852827,0.782498,-132.241867,0.077313,0.000000
138.280014,13.646706,-132.286346,-0.001319,0.003052,0.077513,60.703579,3.092388,0.775126,-132.286346,0.076628,0.000000
138.690002,11.087387,-132.286346,-0.001302,0.003028,0.076906,49.319160,2.512438,0.769056,-132.286346,0.075943,0.000000
139.100006,8.117348,-132.286346,-0.001337,0.003000,0.076194,36.107765,1.839417,0.761944,-132.286346,0.075258,0.000000
139.510010,5.517815,-132.286346,-0.001311,0.002977,0.075622,24.544466,1.250355,0.756221,-132.286346,0.074573,0.000000
139.920013,3.063133,-132.330826,-0.001319,0.002954,0.075024,13.625497,0.694116,0.750237,-132.330826,0.073896,0.000000
140.330002,-0.496376,-132.375305,-0.001319,0.002918,0.074122,-2.207991,-0.112480,0.741218,-132.375305,0.073211,0.000000
140.740005,-2.757793,-132.419785,-0.001319,0.002894,0.073506,-12.267278,-0.624925,0.735061,-132.419785,0.072526,0.000000
141.150009,-0.262527,-132.419785,-0.001350,0.002874,0.073012,-1.167781,-0.059490,0.730117,-132.419785,0.071841,0.000000
141.560013,-0.059578,-132.419785,-0.001341,0.002844,0.072240,-0.265016,-0.013501,0.722399,-132.419785,0.071156,0.000000
141.970001,-0.061440,-132.508759,-0.001371,0.002810,0.071381,-0.273297,-0.013922,0.713813,-132.508759,0.070479,0.000000
142.380005,-0.063309,-132.553238,-0.001401,0.002784,0.070705,-0.281611,-0.014346,0.707049,-132.553238,0.069794,0.000000
142.790009,-0.021225,-132.597717,-0.001423,0.002758,0.070054,-0.094413,-0.004810,0.700545,-132.597717,0.069109,0.000000
143.200012,-0.034630,-132.597717,-0.001444,0.002733,0.069413,-0.154041,-0.007847,0.694127,-132.597717,0.068424,0.000000
143.610001,-0.052879,-132.553238,-0.001483,0.002707,0.068762,-0.235219,-0.011983,0.687623,-132.553238,0.067739,0.000000
144.020004,-0.059212,-132.597717,-0.001513,0.002676,0.067982,-0.263387,-0.013418,0.679818,-132.597717,0.067063,0.000000
144.430008,-0.084160,-132.642197,-0.001526,0.002653,0.067392,-0.374362,-0.019071,0.673921,-132.642197,0.066377,0.000000
144.840012,-0.062561,-132.731155,-0.001565,0.002630,0.066811,-0.278285,-0.014177,0.668111,-132.731155,0.065692,0.000000
145.250000,-0.056602,-132.731155,-0.001595,0.002603,0.066109,-0.251780,-0.012826,0.661086,-132.731155,0.065007,0.000000
145.660004,-0.055115,-132.775635,-0.001617,0.002578,0.065493,-0.245163,-0.012489,0.654929,-132.775635,0.064322,0.000000
146.070007,-0.056976,-132.775635,-0.001669,0.002539,0.064487,-0.253443,-0.012911,0.644869,-132.775635,0.063646,0.000000
146.480011,-0.085648,-132.820114,-0.001681,0.002519,0.063975,-0.380979,-0.019408,0.639752,-132.820114,0.062961,0.000000
146.889999,-0.084160,-132.864594,-0.001712,0.002490,0.063247,-0.374362,-0.019071,0.632468,-132.864594,0.062275,0.000000
147.300003,-0.070755,-132.820114,-0.001733,0.002468,0.062692,-0.314734,-0.016033,0.626917,-132.820114,0.061590,0.000000
147.710007,-0.068893,-132.864594,-0.001763,0.002440,0.061981,-0.306453,-0.015611,0.619806,-132.864594,0.060905,0.000000
148.120010,-0.052505,-132.909088,-0.001798,0.002403,0.061044,-0.233556,-0.011898,0.610440,-132.909088,0.060229,0.000000
148.530014,-0.066658,-132.909088,-0.001815,0.002388,0.060654,-0.296510,-0.015105,0.606538,-132.909088,0.059544,0.000000
148.940002,-0.079689,-132.998047,-0.001863,0.002357,0.059873,-0.354474,-0.018058,0.598733,-132.998047,0.058859,0.000000
149.350006,-0.082298,-132.953568,-0.001867,0.002329,0.059153,-0.366081,-0.018649,0.591535,-132.953568,0.058173,0.000000
149.760010,-0.072617,-133.042526,-0.001901,0.002309,0.058659,-0.323015,-0.016455,0.586591,-133.042526,0.057488,0.000000
150.170013,-0.067398,-133.042526,-0.001944,0.002273,0.057723,-0.299802,-0.015273,0.577225,-133.042526,0.056812,0.000000
150.580002,-0.091980,-133.087006,-0.001957,0.002250,0.057150,-0.409147,-0.020843,0.571502,-133.087006,0.056127,0.000000
150.990005,-0.072617,-133.131485,-0.001992,0.002229,0.056612,-0.323015,-0.016455,0.566125,-133.131485,0.055442,0.000000
151.400009,-0.074852,-133.131485,-0.002018,0.002197,0.055797,-0.332958,-0.016962,0.557973,-133.131485,0.054757,0.000000
151.810013,-0.087509,-133.175964,-0.002065,0.002164,0.054956,-0.389260,-0.019830,0.549561,-133.175964,0.054072,0.000000
152.220001,-0.113579,-133.175964,-0.002065,0.002141,0.054392,-0.505224,-0.025737,0.543924,-133.175964,0.053395,0.000000
152.630005,-0.083412,-133.220444,-0.002100,0.002121,0.053863,-0.371036,-0.018901,0.538634,-133.220444,0.052710,0.000000
153.040009,-0.086761,-133.220444,-0.002151,0.002085,0.052970,-0.385934,-0.019660,0.529701,-133.220444,0.052025,0.000000
153.450012,-0.109108,-133.264923,-0.002151,0.002059,0.052294,-0.485336,-0.024724,0.522937,-133.264923,0.051340,0.000000
153.860001,-0.102402,-133.353897,-0.002199,0.002031,0.051591,-0.455506,-0.023205,0.515913,-133.353897,0.050655,0.000000
154.270004,-0.072243,-133.309418,-0.002229,0.002002,0.050863,-0.321352,-0.016370,0.508628,-133.309418,0.049978,0.000000
154.680008,-0.110596,-133.353897,-0.002246,0.001984,0.050403,-0.491954,-0.025061,0.504032,-133.353897,0.049293,0.000000
155.090012,-0.097565,-133.442856,-0.002285,0.001954,0.049640,-0.433989,-0.022108,0.496400,-133.442856,0.048608,0.000000
155.500000,-0.084160,-133.442856,-0.002294,0.001922,0.048825,-0.374362,-0.019071,0.488248,-133.442856,0.047923,0.000000
155.910004,-0.074104,-133.531815,-0.002324,0.001894,0.048105,-0.329632,-0.016792,0.481050,-133.531815,0.047238,0.000000
156.320007,-0.078575,-133.487335,-0.002371,0.001868,0.047437,-0.349520,-0.017805,0.474372,-133.487335,0.046561,0.000000
156.730011,-0.070381,-133.531815,-0.002380,0.001843,0.046813,-0.313071,-0.015949,0.468128,-133.531815,0.045876,0.000000
157.140015,-0.089745,-133.531815,-0.002402,0.001824,0.046319,-0.399204,-0.020336,0.463185,-133.531815,0.045191,0.000000
157.550003,-0.068893,-133.531815,-0.002453,0.001786,0.045365,-0.306453,-0.015611,0.453646,-133.531815,0.044506,0.000000
157.960007,-0.067398,-133.620773,-0.002475,0.001761,0.044732,-0.299802,-0.015273,0.447315,-133.620773,0.043821,0.000000
158.370010,-0.062935,-133.620773,-0.002501,0.001735,0.044072,-0.279948,-0.014261,0.440724,-133.620773,0.043144,0.000000
158.780014,-0.089745,-133.754227,-0.002514,0.001718,0.043639,-0.399204,-0.020336,0.436388,-133.754227,0.042459,0.000000
159.190002,-0.112083,-133.709732,-0.002552,0.001686,0.042815,-0.498572,-0.025398,0.428149,-133.709732,0.041774,0.000000
159.600006,-0.090118,-133.754227,-0.002578,0.001650,0.041922,-0.400867,-0.020421,0.419217,-133.754227,0.041089,0.000000
160.010010,-0.078575,-133.754227,-0.002613,0.001627,0.041323,-0.349520,-0.017805,0.413233,-133.754227,0.040404,0.000000
160.420013,-0.064049,-133.798706,-0.002630,0.001603,0.040716,-0.284903,-0.014514,0.407162,-133.798706,0.039728,0.000000
160.830002,-0.081924,-133.843185,-0.002665,0.001571,0.039910,-0.364418,-0.018564,0.399097,-133.843185,0.039042,0.000000
161.240005,-0.074104,-133.798706,-0.002690,0.001546,0.039268,-0.329632,-0.016792,0.392680,-133.798706,0.038357,0.000000
161.650009,-0.060326,-133.843185,-0.002729,0.001518,0.038548,-0.268342,-0.013670,0.385482,-133.843185,0.037672,0.000000
162.060013,-0.046547,-133.887665,-0.002751,0.001489,0.037811,-0.207051,-0.010548,0.378110,-133.887665,0.036987,0.000000
162.470001,-0.039101,-133.932144,-0.002768,0.001468,0.037282,-0.173928,-0.008860,0.372820,-133.932144,0.036311,0.000000
162.880005,-0.053627,-134.021103,-0.002807,0.001444,0.036675,-0.238545,-0.012152,0.366750,-134.021103,0.035626,0.000000
163.290009,-0.052132,-133.976624,-0.002841,0.001410,0.035825,-0.231893,-0.011813,0.358251,-133.976624,0.034941,0.000000
163.700012,-0.061073,-134.065582,-0.002850,0.001384,0.035149,-0.271668,-0.013839,0.351487,-134.065582,0.034255,0.000000
164.110001,-0.016388,-134.065582,-0.002902,0.001360,0.034533,-0.072897,-0.003714,0.345329,-134.065582,0.033570,0.000000
164.520004,-0.027184,-134.065582,-0.002897,0.001338,0.033987,-0.120918,-0.006160,0.339866,-134.065582,0.032894,0.000000
164.930008,-0.065536,-134.110062,-0.002936,0.001308,0.033232,-0.291521,-0.014851,0.332321,-134.110062,0.032209,0.000000
165.340012,-0.060326,-134.110062,-0.002971,0.001277,0.032426,-0.268342,-0.013670,0.324256,-134.110062,0.031524,0.000000
165.750015,-0.049896,-134.154541,-0.002988,0.001251,0.031775,-0.221950,-0.011307,0.317752,-134.154541,0.030839,0.000000
166.160004,-0.045059,-134.199036,-0.003031,0.001225,0.031116,-0.200433,-0.010211,0.311161,-134.199036,0.030153,0.000000
166.570007,-0.064796,-134.243515,-0.003048,0.001200,0.030492,-0.288229,-0.014683,0.304917,-134.243515,0.029477,0.000000
166.980011,-0.064423,-134.243515,-0.003083,0.001172,0.029781,-0.286566,-0.014598,0.297805,-134.243515,0.028792,0.000000
167.390015,-0.050644,-134.199036,-0.003104,0.001140,0.028948,-0.225275,-0.011476,0.289480,-134.199036,0.028107,0.000000
167.800003,-0.079689,-134.332474,-0.003139,0.001118,0.028402,-0.354474,-0.018058,0.284016,-134.332474,0.027422,0.000000
168.210007,-0.062187,-134.287994,-0.003165,0.001091,0.027699,-0.276622,-0.014092,0.276992,-134.287994,0.026737,0.000000
168.620010,-0.076340,-134.287994,-0.003203,0.001063,0.026997,-0.339576,-0.017299,0.269967,-134.287994,0.026060,0.000000
169.030014,-0.054367,-134.376953,-0.003229,0.001045,0.026554,-0.241837,-0.012320,0.265545,-134.376953,0.025375,0.000000
169.440002,-0.061073,-134.376953,-0.003264,0.001004,0.025514,-0.271668,-0.013839,0.255138,-134.376953,0.024690,0.000000
169.850006,-0.072617,-134.465912,-0.003268,0.000989,0.025132,-0.323015,-0.016455,0.251322,-134.465912,0.024005,0.000000
170.260010,-0.058090,-134.599365,-0.003316,0.000960,0.024378,-0.258398,-0.013163,0.243777,-134.599365,0.024300,0.000000
170.300003,-0.058090,-134.510391,-0.003311,0.000960,0.024386,-0.258398,-0.013163,0.243864,-134.510391,0.024300,0.000000