File: Data/compression 14/AutoNoHeating-16-14-1-240726_07262024_170554.csv
Time (sec),S:Load (lbs),S:HL1 (DIM),S:LVDT (in),S:Position (in),Ch:Position (mm),Ch:Load (N),Ch:Stress (MPa),Ch:Strain (mm/mm),Ch:HL1 (DIM),Set Point (),Cycles ()
0.110000,-0.011917,-451.170288,-0.010731,-0.005733,-0.145625,-0.053010,-0.002700,-1.456246,-451.170288,-0.145416,0.000000
0.350000,-0.009682,-451.214783,-0.010740,-0.005733,-0.145625,-0.043066,-0.002194,-1.456246,-451.214783,-0.145416,0.000000
0.590000,-0.035378,-451.259247,-0.010706,-0.005637,-0.143187,-0.157367,-0.008017,-1.431871,-451.259247,-0.142485,0.000000
0.830000,-0.060326,-451.259247,-0.010654,-0.005497,-0.139623,-0.268342,-0.013670,-1.396233,-451.259247,-0.138479,0.000000
1.070000,-0.020485,-451.214783,-0.010468,-0.005341,-0.135669,-0.091121,-0.004642,-1.356688,-451.214783,-0.134489,0.000000
1.310000,-0.007820,-451.303741,-0.010309,-0.005190,-0.131818,-0.034786,-0.001772,-1.318181,-451.303741,-0.130483,0.000000
1.550000,-0.024948,-451.214783,-0.010128,-0.005026,-0.127664,-0.110975,-0.005653,-1.276638,-451.214783,-0.126493,0.000000
1.790000,-0.030533,-451.303741,-0.009964,-0.004868,-0.123658,-0.135817,-0.006919,-1.236578,-451.303741,-0.122487,0.000000
2.030000,-0.029045,-451.303741,-0.009787,-0.004705,-0.119504,-0.129199,-0.006582,-1.195035,-451.303741,-0.118497,0.000000
2.270000,-0.001122,-451.303741,-0.009653,-0.004565,-0.115939,-0.004989,-0.000254,-1.159389,-451.303741,-0.114491,0.000000
2.510000,-0.012665,-451.303741,-0.009481,-0.004385,-0.111386,-0.056336,-0.002870,-1.113864,-451.303741,-0.110502,0.000000
2.750000,-0.037613,-451.348206,-0.009326,-0.004234,-0.107545,-0.167311,-0.008523,-1.075448,-451.348206,-0.106495,0.000000
2.990000,-0.024574,-451.303741,-0.009175,-0.004081,-0.103651,-0.109312,-0.005569,-1.036509,-451.303741,-0.102489,0.000000
3.230000,-0.023460,-451.437164,-0.009020,-0.003937,-0.099991,-0.104357,-0.005316,-0.999909,-451.437164,-0.098500,0.000000
3.470000,-0.028671,-451.303741,-0.008839,-0.003760,-0.095507,-0.127536,-0.006497,-0.955073,-451.303741,-0.094493,0.000000
3.710000,-0.020485,-451.392700,-0.008688,-0.003611,-0.091726,-0.091121,-0.004642,-0.917262,-451.392700,-0.090504,0.000000
3.950000,-0.012665,-451.437164,-0.008498,-0.003448,-0.087572,-0.056336,-0.002870,-0.875719,-451.437164,-0.086497,0.000000
4.190000,0.005211,-451.348206,-0.008330,-0.003298,-0.083765,0.023179,0.001181,-0.837650,-451.348206,-0.082508,0.000000
4.430000,0.011543,-451.437164,-0.008175,-0.003142,-0.079802,0.051347,0.002616,-0.798022,-451.437164,-0.078501,0.000000
4.670000,-0.026436,-451.392700,-0.007998,-0.002974,-0.075543,-0.117593,-0.005990,-0.755435,-451.392700,-0.074512,0.000000
4.910000,-0.023460,-451.526123,-0.007864,-0.002820,-0.071633,-0.104357,-0.005316,-0.716329,-451.526123,-0.070505,0.000000
5.150000,-0.010429,-451.437164,-0.007657,-0.002661,-0.067600,-0.046392,-0.002363,-0.675997,-451.437164,-0.066516,0.000000
5.390000,-0.025696,-451.481659,-0.007515,-0.002507,-0.063672,-0.114301,-0.005823,-0.636718,-451.481659,-0.062509,0.000000
5.630000,-0.034630,-451.481659,-0.007321,-0.002346,-0.059595,-0.154041,-0.007847,-0.595954,-451.481659,-0.058521,0.000000
5.870000,-0.021973,-451.526123,-0.007183,-0.002194,-0.055736,-0.097739,-0.004979,-0.557364,-451.526123,-0.054514,0.000000
6.110000,-0.011169,-451.615082,-0.006989,-0.002033,-0.051643,-0.049684,-0.002531,-0.516434,-451.615082,-0.050525,0.000000
6.350000,0.018990,-451.481659,-0.006829,-0.001882,-0.047810,0.084470,0.004303,-0.478100,-451.481659,-0.046518,0.000000
6.590000,0.007072,-451.526123,-0.006674,-0.001714,-0.043526,0.031460,0.001603,-0.435255,-451.526123,-0.042529,0.000000
6.830000,-0.028671,-451.526123,-0.006497,-0.001560,-0.039632,-0.127536,-0.006497,-0.396316,-451.526123,-0.038522,0.000000
7.070000,-0.007446,-451.570618,-0.006359,-0.001404,-0.035651,-0.033123,-0.001687,-0.356514,-451.570618,-0.034533,0.000000
7.310000,-0.008942,-451.615082,-0.006191,-0.001245,-0.031627,-0.039774,-0.002026,-0.316273,-451.615082,-0.030526,0.000000
7.550000,-0.012665,-451.615082,-0.006019,-0.001080,-0.027430,-0.056336,-0.002870,-0.274299,-451.615082,-0.026519,0.000000
7.790000,-0.044685,-451.570618,-0.005846,-0.000933,-0.023710,-0.198770,-0.010126,-0.237101,-451.570618,-0.022530,0.000000
8.030001,-0.007820,-451.659576,-0.005700,-0.000771,-0.019591,-0.034786,-0.001772,-0.195906,-451.659576,-0.018524,0.000000
8.270000,0.028297,-451.615082,-0.005519,-0.000621,-0.015775,0.125873,0.006412,-0.157747,-451.615082,-0.014535,0.000000
8.510000,0.030533,-451.659576,-0.005342,-0.000461,-0.011707,0.135817,0.006919,-0.117074,-451.659576,-0.010528,0.000000
8.750000,0.003723,-451.570618,-0.005182,-0.000302,-0.007666,0.016561,0.000844,-0.076659,-451.570618,-0.006539,0.000000
8.990001,-0.013405,-451.659576,-0.005049,-0.000141,-0.003573,-0.059628,-0.003038,-0.035729,-451.659576,-0.002532,0.000000
9.230000,0.012657,-451.704071,-0.004872,0.000008,0.000208,0.056302,0.002868,0.002082,-451.704071,0.001457,0.000000
9.470000,0.513130,-451.659576,-0.004665,0.000179,0.004553,2.282517,0.116277,0.045532,-451.659576,0.005464,0.000000
9.710000,0.662079,-451.704071,-0.004631,-0.000009,-0.000226,2.945074,0.150029,-0.002256,-451.704071,-0.000017,0.000000
9.950001,0.638618,-451.659576,-0.004648,-0.000009,-0.000226,2.840717,0.144713,-0.002256,-451.659576,-0.000017,0.000000
10.190001,0.610687,-451.704071,-0.004656,-0.000009,-0.000226,2.716473,0.138384,-0.002256,-451.704071,0.000260,0.000000
10.430000,0.619255,-451.704071,-0.004665,-0.000009,-0.000226,2.754584,0.140325,-0.002256,-451.704071,0.000659,0.000000
10.670000,0.585739,-451.748535,-0.004656,-0.000009,-0.000217,2.605498,0.132730,-0.002173,-451.748535,0.001058,0.000000
10.910001,0.925720,-451.793030,-0.004644,0.000023,0.000581,4.117809,0.209771,0.005806,-451.793030,0.001457,0.000000
11.150001,1.080627,-451.748535,-0.004652,0.000038,0.000971,4.806871,0.244874,0.009712,-451.748535,0.001856,0.000000
11.390000,1.251167,-451.748535,-0.004631,0.000051,0.001283,5.565470,0.283519,0.012831,-451.748535,0.002263,0.000000
11.630000,1.302933,-451.793030,-0.004618,0.000057,0.001448,5.795734,0.295249,0.014481,-451.793030,0.002662,0.000000
11.870001,1.639183,-451.793030,-0.004570,0.000084,0.002133,7.291451,0.371444,0.021332,-451.793030,0.003061,0.000000
12.110001,1.990700,-451.837494,-0.004536,0.000107,0.002715,8.855075,0.451099,0.027145,-451.837494,0.003460,0.000000
12.350000,2.149330,-451.793030,-0.004540,0.000118,0.003009,9.560698,0.487045,0.030090,-451.793030,0.003859,0.000000
12.590000,2.353394,-451.837494,-0.004531,0.000131,0.003322,10.468417,0.533287,0.033216,-451.837494,0.004258,0.000000
12.830001,2.601021,-451.793030,-0.004514,0.000145,0.003677,11.569919,0.589400,0.036766,-451.793030,0.004657,0.000000
13.070001,2.991264,-451.793030,-0.004514,0.000165,0.004180,13.305808,0.677830,0.041800,-451.793030,0.005056,0.000000
13.310000,3.240387,-451.926453,-0.004493,0.000178,0.004518,14.413961,0.734282,0.045184,-451.926453,0.005463,0.000000
13.550000,3.385239,-451.926453,-0.004480,0.000188,0.004778,15.058293,0.767106,0.047781,-451.926453,0.005862,0.000000
13.790001,3.841019,-451.881989,-0.004471,0.000210,0.005334,17.085705,0.870387,0.053337,-451.881989,0.006261,0.000000
14.030001,4.339630,-451.881989,-0.004467,0.000231,0.005879,19.303638,0.983374,0.058795,-451.881989,0.006660,0.000000
14.270000,4.462883,-451.881989,-0.004424,0.000242,0.006148,19.851894,1.011304,0.061482,-451.881989,0.007059,0.000000
14.510000,4.732109,-451.926453,-0.004428,0.000256,0.006496,21.049473,1.072311,0.064956,-451.926453,0.007458,0.000000
14.750001,5.174484,-451.926453,-0.004424,0.000274,0.006963,23.017256,1.172555,0.069634,-451.926453,0.007857,0.000000
14.990001,5.472382,-451.926453,-0.004393,0.000290,0.007371,24.342369,1.240059,0.073715,-451.926453,0.008265,0.000000
15.230000,5.893539,-452.015411,-0.004372,0.000307,0.007788,26.215773,1.335495,0.077878,-452.015411,0.008664,0.000000
15.470000,5.855553,-451.970947,-0.004376,0.000311,0.007909,26.046799,1.326887,0.079089,-451.970947,0.009063,0.000000
15.710001,6.493805,-452.015411,-0.004359,0.000335,0.008508,28.885887,1.471517,0.085077,-452.015411,0.009461,0.000000
15.950001,7.058693,-451.970947,-0.004368,0.000358,0.009088,31.398634,1.599523,0.090883,-451.970947,0.009860,0.000000
16.190001,7.134285,-452.015411,-0.004303,0.000370,0.009392,31.734884,1.616652,0.093918,-452.015411,0.010259,0.000000
16.430000,7.177475,-452.015411,-0.004290,0.000376,0.009557,31.927004,1.626439,0.095569,-452.015411,0.010658,0.000000
16.670000,7.822052,-452.059906,-0.004324,0.000399,0.010147,34.794224,1.772502,0.101465,-452.059906,0.011057,0.000000
16.910002,8.083832,-452.059906,-0.004260,0.000415,0.010536,35.958679,1.831823,0.105364,-452.059906,0.011464,0.000000
17.150002,8.466629,-452.059906,-0.004238,0.000433,0.010988,37.661446,1.918566,0.109876,-452.059906,0.011863,0.000000
17.390001,8.449501,-452.104401,-0.004268,0.000441,0.011196,37.585258,1.914684,0.111957,-452.104401,0.012262,0.000000
17.630001,9.083282,-452.059906,-0.004238,0.000462,0.011742,40.404457,2.058301,0.117423,-452.059906,0.012661,0.000000
17.870001,9.633644,-452.104401,-0.004225,0.000484,0.012289,42.852589,2.183015,0.122888,-452.104401,0.013060,0.000000
18.110001,9.602737,-452.193359,-0.004199,0.000494,0.012548,42.715111,2.176011,0.125484,-452.193359,0.013459,0.000000
18.350000,9.800095,-452.059906,-0.004169,0.000508,0.012904,43.592999,2.220733,0.129042,-452.059906,0.013858,0.000000
18.590000,10.277481,-452.104401,-0.004169,0.000526,0.013373,45.716518,2.328911,0.133728,-452.104401,0.014257,0.000000
18.830002,10.430527,-452.148865,-0.004169,0.000540,0.013728,46.397301,2.363591,0.137278,-452.148865,0.014665,0.000000
19.070002,10.806618,-452.148865,-0.004143,0.000557,0.014153,48.070236,2.448815,0.141532,-452.148865,0.015064,0.000000
19.310001,10.998390,-452.193359,-0.004122,0.000572,0.014517,48.923283,2.492271,0.145173,-452.193359,0.015463,0.000000
19.550001,11.352516,-452.193359,-0.004126,0.000587,0.014899,50.498512,2.572517,0.148989,-452.193359,0.015862,0.000000
19.790001,11.906609,-452.193359,-0.004087,0.000609,0.015480,52.963242,2.698076,0.154802,-452.193359,0.016261,0.000000
20.030001,12.031723,-452.237823,-0.004079,0.000624,0.015862,53.519775,2.726427,0.158617,-452.237823,0.016660,0.000000
20.270000,12.064491,-452.193359,-0.004074,0.000638,0.016208,53.665539,2.733853,0.162084,-452.193359,0.017059,0.000000
20.510000,12.106941,-452.282318,-0.004057,0.000649,0.016485,53.854362,2.743472,0.164855,-452.282318,0.017457,0.000000
20.750002,12.750778,-452.193359,-0.004023,0.000670,0.017024,56.718292,2.889368,0.170237,-452.193359,0.017865,0.000000
20.990002,12.887810,-452.237823,-0.004027,0.000683,0.017336,57.327843,2.920419,0.173356,-452.237823,0.018264,0.000000
21.230001,13.094849,-452.237823,-0.004023,0.000698,0.017726,58.248795,2.967335,0.177262,-452.237823,0.018663,0.000000
21.470001,13.109001,-452.282318,-0.003988,0.000710,0.018030,58.311749,2.970542,0.180297,-452.282318,0.019061,0.000000
21.710001,13.537971,-452.326782,-0.003967,0.000727,0.018454,60.219906,3.067748,0.184544,-452.326782,0.019460,0.000000
21.950001,13.993385,-452.282318,-0.003928,0.000747,0.018984,62.245686,3.170947,0.189835,-452.282318,0.019859,0.000000
22.190001,13.834755,-452.371277,-0.003936,0.000757,0.019217,61.540062,3.135000,0.192174,-452.371277,0.020258,0.000000
22.430000,14.173615,-452.371277,-0.003906,0.000774,0.019669,63.047386,3.211787,0.196686,-452.371277,0.020657,0.000000
22.670002,14.292397,-452.415741,-0.003906,0.000789,0.020042,63.575756,3.238703,0.200418,-452.415741,0.021064,0.000000
22.910002,14.561249,-452.371277,-0.003876,0.000808,0.020519,64.771667,3.299626,0.205187,-452.371277,0.021463,0.000000
23.150002,14.885963,-452.371277,-0.003872,0.000823,0.020900,66.216072,3.373208,0.209002,-452.371277,0.021862,0.000000
23.390001,14.622322,-452.415741,-0.003859,0.000829,0.021064,65.043335,3.313466,0.210645,-452.415741,0.022261,0.000000
23.630001,15.093002,-452.415741,-0.003833,0.000853,0.021655,67.137024,3.420123,0.216549,-452.415741,0.022660,0.000000
23.870001,15.777046,-452.326782,-0.003820,0.000874,0.022210,70.179810,3.575130,0.222098,-452.326782,0.023059,0.000000
24.110001,15.494041,-452.460236,-0.003803,0.000885,0.022487,68.920937,3.511000,0.224868,-452.460236,0.023458,0.000000
24.350000,15.869026,-452.415741,-0.003773,0.000904,0.022973,70.588951,3.595973,0.229728,-452.415741,0.023857,0.000000
24.590002,16.147934,-452.504730,-0.003755,0.000925,0.023485,71.829597,3.659174,0.234845,-452.504730,0.024265,0.000000
24.830002,16.219795,-452.460236,-0.003747,0.000940,0.023866,72.149254,3.675458,0.238660,-452.460236,0.024664,0.000000
25.070002,16.003448,-452.504730,-0.003725,0.000949,0.024109,71.186897,3.626433,0.241090,-452.504730,0.025063,0.000000
25.310001,15.873863,-452.549194,-0.003704,0.000960,0.024378,70.610474,3.597069,0.243778,-452.549194,0.025462,0.000000
25.550001,16.882996,-452.504730,-0.003682,0.000987,0.025080,75.099312,3.825742,0.250802,-452.504730,0.025861,0.000000
25.790001,16.986511,-452.549194,-0.003665,0.001003,0.025479,75.559776,3.849198,0.254792,-452.549194,0.026260,0.000000
26.030001,16.776123,-452.504730,-0.003648,0.001014,0.025765,74.623924,3.801524,0.257653,-452.504730,0.026659,0.000000
26.270000,16.837563,-452.549194,-0.003635,0.001030,0.026155,74.897217,3.815446,0.261551,-452.549194,0.027057,0.000000
26.510002,17.047958,-452.638153,-0.003617,0.001047,0.026598,75.833107,3.863122,0.265980,-452.638153,0.027465,0.000000
26.750002,17.349953,-452.549194,-0.003579,0.001064,0.027031,77.176445,3.931555,0.270310,-452.549194,0.027864,0.000000
26.990002,17.126152,-452.682648,-0.003574,0.001073,0.027257,76.180931,3.880842,0.272565,-452.682648,0.028263,0.000000
27.230001,17.115356,-452.593689,-0.003566,0.001085,0.027569,76.132904,3.878395,0.275692,-452.593689,0.028661,0.000000
27.470001,17.804985,-452.638153,-0.003540,0.001108,0.028141,79.200531,4.034667,0.281415,-452.638153,0.029060,0.000000
27.710001,18.131561,-452.682648,-0.003501,0.001128,0.028653,80.653214,4.108671,0.286532,-452.682648,0.029459,0.000000
27.950001,18.036232,-452.682648,-0.003492,0.001140,0.028957,80.229164,4.087069,0.289567,-452.682648,0.029858,0.000000
28.190001,18.106239,-452.638153,-0.003449,0.001157,0.029399,80.540573,4.102932,0.293988,-452.638153,0.030266,0.000000
28.430002,17.903664,-452.682648,-0.003462,0.001166,0.029624,79.639473,4.057028,0.296244,-452.682648,0.030665,0.000000
28.670002,18.245880,-452.638153,-0.003454,0.001187,0.030144,81.161728,4.134575,0.301444,-452.638153,0.031064,0.000000
28.910002,18.260025,-452.727112,-0.003410,0.001199,0.030457,81.224648,4.137781,0.304570,-452.727112,0.031463,0.000000
29.150002,18.441002,-452.727112,-0.003397,0.001215,0.030856,82.029671,4.178791,0.308560,-452.727112,0.031862,0.000000
29.390001,18.588463,-452.727112,-0.003376,0.001230,0.031246,82.685616,4.212206,0.312458,-452.727112,0.032261,0.000000
29.630001,19.201759,-452.771606,-0.003363,0.001253,0.031836,85.413689,4.351181,0.318355,-452.771606,0.032660,0.000000
29.870001,19.073288,-452.727112,-0.003341,0.001266,0.032166,84.842224,4.322069,0.321656,-452.727112,0.033059,0.000000
30.110001,18.776505,-452.816071,-0.003328,0.001277,0.032434,83.522064,4.254817,0.324343,-452.816071,0.033466,0.000000
30.350002,19.200638,-452.771606,-0.003307,0.001295,0.032902,85.408699,4.350927,0.329021,-452.771606,0.033865,0.000000
30.590002,19.076637,-452.771606,-0.003311,0.001308,0.033215,84.857124,4.322828,0.332147,-452.771606,0.034264,0.000000
30.830002,19.623283,-452.771606,-0.003255,0.001328,0.033735,87.288727,4.446700,0.337348,-452.771606,0.034663,0.000000
31.070002,19.402840,-452.771606,-0.003285,0.001339,0.034021,86.308144,4.396747,0.340209,-452.771606,0.035062,0.000000
31.310001,20.104019,-452.816071,-0.003216,0.001364,0.034654,89.427147,4.555636,0.346545,-452.816071,0.035461,0.000000
31.550001,20.094337,-452.816071,-0.003221,0.001380,0.035053,89.384079,4.553442,0.350534,-452.816071,0.035860,0.000000
31.790001,20.123009,-452.905029,-0.003199,0.001395,0.035435,89.511612,4.559939,0.354349,-452.905029,0.036259,0.000000
32.030003,19.968102,-452.860565,-0.003156,0.001407,0.035729,88.822548,4.524837,0.357294,-452.860565,0.036667,0.000000
32.270000,19.953575,-452.816071,-0.003178,0.001420,0.036059,88.757935,4.521544,0.360595,-452.816071,0.037065,0.000000
32.510002,20.365051,-452.905029,-0.003122,0.001438,0.036527,90.588272,4.614787,0.365273,-452.905029,0.037464,0.000000
32.750000,20.493515,-452.816071,-0.003152,0.001452,0.036891,91.159706,4.643897,0.368914,-452.816071,0.037863,0.000000
32.990002,20.019485,-452.949524,-0.003113,0.001458,0.037031,89.051117,4.536480,0.370307,-452.949524,0.038262,0.000000
33.230003,20.955261,-452.905029,-0.003078,0.001488,0.037785,93.213661,4.748530,0.377846,-452.905029,0.038661,0.000000
33.470001,21.485146,-452.949524,-0.003065,0.001506,0.038262,95.570702,4.868604,0.382623,-452.949524,0.039060,0.000000
33.710003,21.349976,-452.949524,-0.003048,0.001521,0.038635,94.969437,4.837974,0.386347,-452.949524,0.039459,0.000000
33.950001,21.038673,-452.994019,-0.002988,0.001531,0.038895,93.584694,4.767432,0.388951,-452.994019,0.039866,0.000000
34.190002,21.287041,-453.082977,-0.002979,0.001548,0.039311,94.689484,4.823712,0.393114,-453.082977,0.040265,0.000000
34.430000,21.442322,-452.994019,-0.002984,0.001564,0.039736,95.380211,4.858900,0.397361,-452.994019,0.040664,0.000000
34.670002,21.435623,-453.038483,-0.002979,0.001579,0.040100,95.350410,4.857382,0.401002,-453.038483,0.041063,0.000000
34.910000,21.179054,-453.038483,-0.002906,0.001587,0.040308,94.209137,4.799242,0.403084,-453.038483,0.041462,0.000000
35.150002,21.771500,-452.949524,-0.002915,0.001611,0.040915,96.844467,4.933492,0.409155,-452.949524,0.041861,0.000000
35.390003,22.503212,-453.038483,-0.002902,0.001632,0.041462,100.099289,5.099301,0.414620,-453.038483,0.042260,0.000000
35.630001,22.292824,-453.038483,-0.002876,0.001646,0.041800,99.163429,5.051626,0.418004,-453.038483,0.042659,0.000000
35.870003,22.148338,-453.171936,-0.002859,0.001659,0.042139,98.520729,5.018885,0.421387,-453.171936,0.043066,0.000000
36.110001,22.377350,-453.082977,-0.002828,0.001675,0.042538,99.539421,5.070780,0.425377,-453.082977,0.043465,0.000000
36.350002,22.576942,-453.082977,-0.002828,0.001692,0.042988,100.427254,5.116008,0.429881,-453.082977,0.043864,0.000000
36.590000,22.654022,-453.127441,-0.002790,0.001706,0.043326,100.770126,5.133475,0.433264,-453.127441,0.044263,0.000000
36.830002,22.155785,-453.082977,-0.002811,0.001713,0.043500,98.553848,5.020572,0.434998,-453.082977,0.044662,0.000000
37.070004,22.939629,-453.216400,-0.002772,0.001737,0.044124,102.040565,5.198194,0.441243,-453.216400,0.045061,0.000000
37.310001,23.688843,-453.171936,-0.002738,0.001760,0.044697,105.373238,5.367969,0.446966,-453.171936,0.045460,0.000000
37.550003,23.304932,-453.216400,-0.002729,0.001770,0.044948,103.665512,5.280973,0.449479,-453.216400,0.045859,0.000000
37.790001,23.179070,-453.260895,-0.002686,0.001782,0.045269,103.105652,5.252452,0.452689,-453.260895,0.046267,0.000000
38.030003,23.512344,-453.171936,-0.002699,0.001800,0.045720,104.588135,5.327973,0.457200,-453.171936,0.046665,0.000000
38.270000,23.619209,-453.260895,-0.002677,0.001817,0.046154,105.063492,5.352190,0.461538,-453.260895,0.047064,0.000000
38.510002,23.943924,-453.216400,-0.002647,0.001834,0.046578,106.507896,5.425771,0.465784,-453.216400,0.047463,0.000000
38.750000,23.365257,-453.260895,-0.002617,0.001840,0.046726,103.933853,5.294643,0.467260,-453.260895,0.047862,0.000000
38.990002,24.186707,-453.260895,-0.002621,0.001865,0.047359,107.587845,5.480786,0.473589,-453.260895,0.048261,0.000000
39.230003,24.627594,-453.260895,-0.002574,0.001885,0.047880,109.549011,5.580693,0.478797,-453.260895,0.048660,0.000000
39.470001,24.199738,-453.349854,-0.002565,0.001895,0.048131,107.645805,5.483739,0.481310,-453.349854,0.049059,0.000000
39.710003,24.107391,-453.349854,-0.002544,0.001909,0.048478,107.235031,5.462813,0.484777,-453.349854,0.049466,0.000000
39.950001,24.505455,-453.305359,-0.002522,0.001926,0.048929,109.005707,5.553015,0.489289,-453.305359,0.049865,0.000000
40.190002,24.550140,-453.394348,-0.002505,0.001943,0.049345,109.204475,5.563141,0.493452,-453.394348,0.050264,0.000000
40.430000,24.802986,-453.305359,-0.002488,0.001958,0.049744,110.329193,5.620437,0.497441,-453.305359,0.050663,0.000000
40.670002,24.725906,-453.438812,-0.002483,0.001971,0.050065,109.986328,5.602971,0.500651,-453.438812,0.051062,0.000000
40.910004,24.951935,-453.349854,-0.002449,0.001987,0.050481,110.991753,5.654189,0.504814,-453.349854,0.051461,0.000000
41.150002,25.636726,-453.349854,-0.002414,0.002011,0.051071,114.037857,5.809365,0.510711,-453.349854,0.051860,0.000000
41.390003,25.530975,-453.438812,-0.002427,0.002025,0.051426,113.567451,5.785402,0.514261,-453.438812,0.052268,0.000000
41.630001,25.357071,-453.349854,-0.002384,0.002037,0.051747,112.793884,5.745994,0.517471,-453.349854,0.052667,0.000000
41.870003,25.024170,-453.483307,-0.002371,0.002049,0.052033,111.313065,5.670558,0.520332,-453.483307,0.053066,0.000000
42.110001,25.612152,-453.483307,-0.002341,0.002069,0.052554,113.928543,5.803797,0.525540,-453.483307,0.053465,0.000000
42.350002,25.406227,-453.483307,-0.002315,0.002081,0.052866,113.012543,5.757133,0.528659,-453.483307,0.053864,0.000000
42.590000,25.475861,-453.527771,-0.002294,0.002096,0.053247,113.322289,5.772913,0.532474,-453.527771,0.054263,0.000000
42.830002,25.410698,-453.483307,-0.002294,0.002109,0.053577,113.032433,5.758146,0.535775,-453.483307,0.054661,0.000000
43.070004,25.662048,-453.572266,-0.002276,0.002127,0.054020,114.150490,5.815103,0.540195,-453.572266,0.055060,0.000000
43.310001,26.376259,-453.483307,-0.002229,0.002150,0.054600,117.327461,5.976946,0.546001,-453.483307,0.055468,0.000000
43.550003,25.967392,-453.527771,-0.002220,0.002162,0.054904,115.508728,5.884295,0.549037,-453.527771,0.055867,0.000000
43.790001,25.899620,-453.616730,-0.002199,0.002174,0.055225,115.207260,5.868937,0.552246,-453.616730,0.056265,0.000000
44.030003,25.980423,-453.483307,-0.002182,0.002193,0.055693,115.566696,5.887248,0.556932,-453.483307,0.056664,0.000000
44.270000,26.309601,-453.616730,-0.002143,0.002210,0.056127,117.030952,5.961841,0.561270,-453.616730,0.057063,0.000000
44.510002,26.253746,-453.572266,-0.002130,0.002222,0.056439,116.782494,5.949184,0.564388,-453.572266,0.057462,0.000000
44.750004,25.628532,-453.572266,-0.002126,0.002228,0.056595,114.001404,5.807508,0.565948,-453.572266,0.057861,0.000000
44.990002,26.692398,-453.661224,-0.002095,0.002258,0.057349,118.733719,6.048584,0.573495,-453.661224,0.058260,0.000000
45.230003,27.164940,-453.661224,-0.002078,0.002273,0.057740,120.835686,6.155663,0.577401,-453.661224,0.058667,0.000000
45.470001,26.671547,-453.705688,-0.002065,0.002286,0.058052,118.640968,6.043859,0.580520,-453.705688,0.059066,0.000000
45.710003,27.020462,-453.661224,-0.002039,0.002305,0.058538,120.193016,6.122924,0.585379,-453.661224,0.059465,0.000000
45.950001,27.235695,-453.616730,-0.001992,0.002323,0.059006,121.150421,6.171697,0.590058,-453.616730,0.059864,0.000000
46.190002,27.344795,-453.705688,-0.001975,0.002340,0.059431,121.635727,6.196419,0.594312,-453.705688,0.060263,0.000000
46.430000,26.824966,-453.661224,-0.001953,0.002349,0.059673,119.323410,6.078625,0.596734,-453.661224,0.060662,0.000000
46.670002,26.778419,-453.750183,-0.001970,0.002364,0.060055,119.116356,6.068077,0.600549,-453.750183,0.061061,0.000000
46.910004,27.857185,-453.705688,-0.001923,0.002391,0.060723,123.914948,6.312529,0.607233,-453.705688,0.061460,0.000000
47.150002,27.598015,-453.750183,-0.001888,0.002404,0.061070,122.762100,6.253799,0.610700,-453.750183,0.061868,0.000000
47.390003,27.167175,-453.705688,-0.001863,0.002415,0.061330,120.845634,6.156170,0.613304,-453.705688,0.062267,0.000000
47.630001,27.060677,-453.661224,-0.001841,0.002430,0.061720,120.371902,6.132037,0.617203,-453.661224,0.062666,0.000000
47.870003,27.422623,-453.794678,-0.001828,0.002449,0.062197,121.981918,6.214055,0.621972,-453.794678,0.063065,0.000000
48.110001,27.599503,-453.794678,-0.001781,0.002465,0.062614,122.768723,6.254137,0.626135,-453.794678,0.063464,0.000000
48.350002,27.077438,-453.794678,-0.001776,0.002474,0.062847,120.446465,6.135835,0.628474,-453.794678,0.063863,0.000000
48.590004,27.298622,-453.839142,-0.001776,0.002492,0.063299,121.430336,6.185956,0.632986,-453.839142,0.064261,0.000000
48.830002,27.869469,-453.794678,-0.001746,0.002512,0.063793,123.969589,6.315312,0.637929,-453.794678,0.064660,0.000000
49.070004,28.240356,-453.883636,-0.001716,0.002530,0.064261,125.619377,6.399356,0.642615,-453.883636,0.065068,0.000000
49.310001,27.900009,-453.839142,-0.001686,0.002542,0.064565,124.105438,6.322232,0.645650,-453.839142,0.065467,0.000000
49.550003,27.873566,-453.839142,-0.001681,0.002558,0.064964,123.987816,6.316240,0.649639,-453.839142,0.065865,0.000000
49.790001,27.407730,-453.794678,-0.001656,0.002569,0.065250,121.915672,6.210680,0.652501,-453.794678,0.066264,0.000000
50.030003,28.012833,-453.883636,-0.001634,0.002588,0.065735,124.607300,6.347798,0.657353,-453.883636,0.066663,0.000000
50.270004,27.708603,-453.972595,-0.001638,0.002600,0.066031,123.254021,6.278860,0.660305,-453.972595,0.067062,0.000000
50.510002,28.049698,-453.883636,-0.001604,0.002617,0.066473,124.771286,6.356153,0.664726,-453.883636,0.067461,0.000000
50.750004,28.262321,-453.972595,-0.001582,0.002634,0.066906,125.717087,6.404334,0.669063,-453.972595,0.067860,0.000000
50.990002,28.840988,-453.928101,-0.001561,0.002654,0.067418,128.291122,6.535461,0.674181,-453.928101,0.068268,0.000000
51.230003,28.530434,-453.972595,-0.001548,0.002667,0.067730,126.909706,6.465089,0.677299,-453.972595,0.068667,0.000000
51.470001,28.132736,-453.928101,-0.001535,0.002679,0.068043,125.140663,6.374969,0.680426,-453.928101,0.069066,0.000000
51.710003,28.492447,-453.972595,-0.001522,0.002694,0.068432,126.740730,6.456481,0.684324,-453.972595,0.069465,0.000000
51.950001,28.427284,-454.017059,-0.001483,0.002710,0.068831,126.450874,6.441715,0.688313,-454.017059,0.069864,0.000000
52.190002,28.928497,-453.928101,-0.001462,0.002727,0.069274,128.680389,6.555291,0.692742,-453.928101,0.070263,0.000000
52.430004,28.938553,-454.017059,-0.001453,0.002742,0.069638,128.725113,6.557570,0.696383,-454.017059,0.070662,0.000000
52.670002,29.885124,-454.017059,-0.001423,0.002767,0.070289,132.935669,6.772066,0.702885,-454.017059,0.071061,0.000000
52.910004,29.855331,-454.061554,-0.001397,0.002781,0.070644,132.803146,6.765315,0.706443,-454.061554,0.071468,0.000000
53.150002,29.713463,-454.061554,-0.001371,0.002795,0.070999,132.172089,6.733167,0.709993,-454.061554,0.071867,0.000000
53.390003,29.410721,-454.061554,-0.001354,0.002807,0.071286,130.825424,6.664565,0.712862,-454.061554,0.072266,0.000000
53.630001,29.501579,-454.017059,-0.001350,0.002820,0.071633,131.229584,6.685153,0.716329,-454.017059,0.072665,0.000000
53.870003,29.714951,-454.106018,-0.001293,0.002837,0.072049,132.178696,6.733504,0.720493,-454.106018,0.073064,0.000000
54.110004,29.876930,-454.061554,-0.001311,0.002850,0.072387,132.899216,6.770209,0.723869,-454.061554,0.073463,0.000000
54.350002,29.507912,-454.150513,-0.001298,0.002859,0.072630,131.257751,6.686588,0.726299,-454.150513,0.073861,0.000000
54.590004,31.093475,-454.061554,-0.001263,0.002890,0.073410,138.310684,7.045882,0.734103,-454.061554,0.074269,0.000000
54.830002,31.587608,-454.106018,-0.001237,0.002906,0.073801,140.508698,7.157855,0.738009,-454.106018,0.074668,0.000000
55.070004,31.697830,-454.150513,-0.001233,0.002920,0.074165,140.998993,7.182831,0.741650,-454.150513,0.075067,0.000000
55.310001,31.430099,-454.106018,-0.001199,0.002933,0.074486,139.808060,7.122162,0.744860,-454.106018,0.075466,0.000000
55.550003,31.376846,-454.194977,-0.001199,0.002943,0.074764,139.571182,7.110095,0.747638,-454.194977,0.075864,0.000000
55.790001,32.416512,-454.194977,-0.001199,0.002967,0.075353,144.195847,7.345687,0.753535,-454.194977,0.076263,0.000000
56.030003,32.437363,-454.150513,-0.001147,0.002980,0.075683,144.288589,7.350411,0.756828,-454.150513,0.076662,0.000000
56.270004,32.040039,-454.194977,-0.001121,0.002989,0.075926,142.521210,7.260376,0.759257,-454.194977,0.077061,0.000000
56.510002,32.808990,-454.239471,-0.001125,0.003010,0.076446,145.941681,7.434623,0.764458,-454.239471,0.077469,0.000000
56.750004,34.248215,-454.239471,-0.001121,0.003033,0.077045,152.343674,7.760756,0.770446,-454.239471,0.077868,0.000000
56.990002,34.286194,-454.194977,-0.001087,0.003047,0.077382,152.512604,7.769362,0.773822,-454.194977,0.078267,0.000000
57.230003,34.277260,-454.283966,-0.001087,0.003060,0.077712,152.472870,7.767338,0.777122,-454.283966,0.078666,0.000000
57.470001,34.461578,-454.328430,-0.001043,0.003074,0.078067,153.292755,7.809105,0.780672,-454.328430,0.079065,0.000000
57.710003,35.044342,-454.239471,-0.001026,0.003093,0.078553,155.885025,7.941162,0.785532,-454.239471,0.079464,0.000000
57.950005,35.405548,-454.328430,-0.001026,0.003105,0.078874,157.491745,8.023012,0.788742,-454.328430,0.079863,0.000000
58.190002,35.152328,-454.283966,-0.001035,0.003118,0.079203,156.365372,7.965631,0.792035,-454.283966,0.080262,0.000000
58.430004,36.620598,-454.328430,-0.001005,0.003141,0.079785,162.896561,8.298347,0.797848,-454.328430,0.080669,0.000000
58.670002,37.449867,-454.328430,-0.000987,0.003160,0.080270,166.585327,8.486261,0.802701,-454.328430,0.081068,0.000000
58.910004,37.256981,-454.328430,-0.000949,0.003171,0.080548,165.727325,8.442553,0.805479,-454.328430,0.081467,0.000000
59.150002,37.366089,-454.372925,-0.000949,0.003185,0.080895,166.212662,8.467277,0.808946,-454.372925,0.081866,0.000000
59.390003,37.971939,-454.328430,-0.000940,0.003199,0.081259,168.907623,8.604565,0.812587,-454.328430,0.082265,0.000000
59.630001,38.797859,-454.372925,-0.000923,0.003221,0.081805,172.581497,8.791720,0.818052,-454.372925,0.082664,0.000000
59.870003,39.306519,-454.417389,-0.000888,0.003233,0.082118,174.844131,8.906985,0.821178,-454.417389,0.083063,0.000000
60.110004,38.851852,-454.372925,-0.000888,0.003238,0.082256,172.821671,8.803956,0.822564,-454.372925,0.083461,0.000000
60.350002,40.554710,-454.461884,-0.000867,0.003267,0.082985,180.396362,9.189829,0.829846,-454.461884,0.083869,0.000000
60.590004,41.340790,-454.417389,-0.000862,0.003285,0.083427,183.893021,9.367957,0.834267,-454.417389,0.084268,0.000000
60.830002,41.316582,-454.461884,-0.000871,0.003296,0.083714,183.785339,9.362472,0.837135,-454.461884,0.084667,0.000000
61.070004,41.802162,-454.506348,-0.000815,0.003311,0.084095,185.945297,9.472506,0.840951,-454.506348,0.085066,0.000000
61.310001,42.402794,-454.417389,-0.000849,0.003325,0.084459,188.617050,9.608611,0.844592,-454.417389,0.085465,0.000000
61.550003,43.174721,-454.461884,-0.000819,0.003345,0.084971,192.050751,9.783532,0.849709,-454.461884,0.085864,0.000000
61.790005,43.570183,-454.417389,-0.000789,0.003356,0.085248,193.809860,9.873145,0.852479,-454.417389,0.086263,0.000000
62.030003,43.996178,-454.506348,-0.000811,0.003370,0.085586,195.704773,9.969677,0.855863,-454.506348,0.086662,0.000000
62.270004,44.731987,-454.550842,-0.000776,0.003386,0.086011,198.977814,10.136414,0.860110,-454.550842,0.087069,0.000000
62.510002,46.244934,-454.461884,-0.000767,0.003411,0.086627,205.707733,10.479252,0.866272,-454.461884,0.087468,0.000000
62.750004,46.768860,-454.595306,-0.000772,0.003425,0.086983,208.038284,10.597976,0.869829,-454.595306,0.087867,0.000000
62.990002,47.042557,-454.595306,-0.000750,0.003436,0.087277,209.255737,10.659995,0.872774,-454.595306,0.088266,0.000000
63.230003,47.268959,-454.595306,-0.000733,0.003453,0.087702,210.262833,10.711299,0.877021,-454.595306,0.088665,0.000000
63.470001,48.483635,-454.639801,-0.000690,0.003468,0.088075,215.665985,10.986548,0.880753,-454.639801,0.089064,0.000000
63.710003,49.252960,-454.550842,-0.000694,0.003487,0.088561,219.088104,11.160880,0.885612,-454.550842,0.089463,0.000000
63.950005,49.536339,-454.639801,-0.000681,0.003497,0.088813,220.348633,11.225095,0.888126,-454.639801,0.089862,0.000000
64.190002,49.986908,-454.595306,-0.000668,0.003509,0.089116,222.352875,11.327195,0.891161,-454.595306,0.090270,0.000000
64.430000,50.969971,-454.639801,-0.000681,0.003529,0.089636,226.725754,11.549960,0.896362,-454.639801,0.090669,0.000000
64.670006,52.482544,-454.639801,-0.000612,0.003549,0.090140,233.454010,11.892715,0.901395,-454.639801,0.091068,0.000000
64.910004,52.798317,-454.639801,-0.000647,0.003563,0.090495,234.858643,11.964270,0.904946,-454.639801,0.091467,0.000000
65.150002,53.607483,-454.639801,-0.000651,0.003580,0.090928,238.457993,12.147630,0.909283,-454.639801,0.091865,0.000000
65.389999,54.729813,-454.639801,-0.000638,0.003596,0.091345,243.450363,12.401953,0.913447,-454.639801,0.092264,0.000000
65.630005,55.553871,-454.639801,-0.000638,0.003611,0.091726,247.115967,12.588687,0.917262,-454.639801,0.092663,0.000000
65.870003,55.909859,-454.728760,-0.000608,0.003621,0.091969,248.699478,12.669355,0.919692,-454.728760,0.093062,0.000000
66.110001,56.156746,-454.684296,-0.000612,0.003631,0.092238,249.797684,12.725301,0.922379,-454.684296,0.093469,0.000000
66.350006,58.192505,-454.728760,-0.000586,0.003660,0.092967,258.853180,13.186610,0.929669,-454.728760,0.093868,0.000000
66.590004,58.981560,-454.773254,-0.000582,0.003672,0.093270,262.363068,13.365413,0.932697,-454.773254,0.094267,0.000000
66.830002,59.416862,-454.728760,-0.000582,0.003688,0.093669,264.299408,13.464054,0.936686,-454.728760,0.094666,0.000000
67.070000,60.681068,-454.773254,-0.000556,0.003706,0.094137,269.922882,13.750526,0.941372,-454.773254,0.095065,0.000000
67.310005,61.876762,-454.728760,-0.000526,0.003725,0.094606,275.241577,14.021475,0.946057,-454.728760,0.095464,0.000000
67.550003,62.878067,-454.862213,-0.000543,0.003741,0.095030,279.695618,14.248373,0.950304,-454.862213,0.095863,0.000000
67.790001,63.011375,-454.773254,-0.000535,0.003750,0.095239,280.288605,14.278582,0.952386,-454.773254,0.096270,0.000000
68.030006,63.679413,-454.773254,-0.000530,0.003764,0.095603,283.260162,14.429961,0.956027,-454.773254,0.096669,0.000000
68.270004,65.827637,-454.862213,-0.000504,0.003791,0.096279,292.815948,14.916756,0.962794,-454.862213,0.097068,0.000000
68.510002,66.614822,-454.817719,-0.000522,0.003804,0.096626,296.317535,15.095135,0.966261,-454.817719,0.097467,0.000000
68.750000,66.990555,-454.862213,-0.000496,0.003813,0.096860,297.988861,15.180277,0.968600,-454.862213,0.097866,0.000000
68.990005,67.120880,-454.862213,-0.000496,0.003813,0.096860,298.568573,15.209809,0.968600,-454.862213,0.097112,0.000000
69.230003,66.396988,-454.862213,-0.000483,0.003813,0.096860,295.348541,15.045773,0.968600,-454.862213,0.096860,0.000000
69.470001,65.811249,-454.862213,-0.000466,0.003812,0.096834,292.743042,14.913042,0.968343,-454.862213,0.096860,0.000000
69.710007,65.227371,-454.862213,-0.000496,0.003812,0.096826,290.145844,14.780734,0.968259,-454.862213,0.096860,0.000000
69.950005,64.696732,-454.951172,-0.000479,0.003812,0.096817,287.785431,14.660489,0.968169,-454.951172,0.096860,0.000000
70.190002,64.226807,-454.906677,-0.000453,0.003812,0.096817,285.695099,14.554003,0.968169,-454.906677,0.096860,0.000000
70.430000,63.807877,-454.951172,-0.000453,0.003812,0.096817,283.831604,14.459071,0.968169,-454.951172,0.096860,0.000000
70.670006,63.402374,-454.995636,-0.000474,0.003812,0.096817,282.027832,14.367183,0.968169,-454.995636,0.096860,0.000000
70.910004,63.055321,-454.951172,-0.000453,0.003811,0.096809,280.484070,14.288540,0.968085,-454.951172,0.096860,0.000000
71.150002,62.704918,-454.995636,-0.000444,0.003811,0.096809,278.925415,14.209137,0.968085,-454.995636,0.096860,0.000000
71.390007,62.407021,-454.951172,-0.000444,0.003811,0.096809,277.600281,14.141633,0.968085,-454.951172,0.096860,0.000000
71.630005,62.114708,-454.995636,-0.000444,0.003811,0.096809,276.300018,14.075394,0.968085,-454.995636,0.096860,0.000000
71.870003,61.848457,-454.995636,-0.000423,0.003811,0.096809,275.115692,14.015060,0.968085,-454.995636,0.096860,0.000000
72.110001,61.609398,-454.995636,-0.000431,0.003811,0.096809,274.052277,13.960889,0.968085,-454.995636,0.096860,0.000000
72.350006,61.374054,-455.040131,-0.000444,0.003811,0.096809,273.005432,13.907559,0.968085,-455.040131,0.096860,0.000000
72.590004,61.156219,-454.995636,-0.000440,0.003811,0.096809,272.036438,13.858197,0.968085,-454.995636,0.096860,0.000000
72.830002,60.958488,-455.040131,-0.000435,0.003811,0.096809,271.156891,13.813391,0.968085,-455.040131,0.096860,0.000000
73.070000,60.755920,-455.129089,-0.000414,0.003811,0.096809,270.255829,13.767488,0.968085,-455.129089,0.096860,0.000000
73.310005,60.572708,-455.040131,-0.000423,0.003811,0.096809,269.440857,13.725971,0.968085,-455.040131,0.096860,0.000000
73.550003,60.387642,-455.129089,-0.000444,0.003811,0.096809,268.617645,13.684035,0.968085,-455.129089,0.096860,0.000000
73.790001,60.231987,-455.084625,-0.000401,0.003811,0.096809,267.925262,13.648763,0.968085,-455.084625,0.096860,0.000000
74.030006,60.066284,-455.084625,-0.000440,0.003811,0.096809,267.188171,13.611215,0.968085,-455.084625,0.096860,0.000000
74.270004,59.912865,-455.129089,-0.000401,0.003811,0.096809,266.505737,13.576449,0.968085,-455.129089,0.096860,0.000000
74.510002,59.767639,-455.173584,-0.000418,0.003811,0.096809,265.859741,13.543541,0.968085,-455.173584,0.096860,0.000000
74.750000,59.622040,-455.218048,-0.000453,0.003811,0.096809,265.212067,13.510547,0.968085,-455.218048,0.096860,0.000000
74.990005,59.501396,-455.173584,-0.000414,0.003811,0.096809,264.675415,13.483210,0.968085,-455.173584,0.096860,0.000000
75.230003,59.368454,-455.218048,-0.000431,0.003811,0.096809,264.084076,13.453084,0.968085,-455.218048,0.096860,0.000000
75.470001,59.244827,-455.218048,-0.000401,0.003811,0.096809,263.534149,13.425070,0.968085,-455.218048,0.096860,0.000000
75.710007,59.137962,-455.173584,-0.000405,0.003811,0.096809,263.058807,13.400853,0.968085,-455.173584,0.096860,0.000000
75.950005,59.014328,-455.218048,-0.000405,0.003811,0.096809,262.508850,13.372837,0.968085,-455.218048,0.096860,0.000000
76.190002,58.917885,-455.218048,-0.000431,0.003811,0.096809,262.079834,13.350983,0.968085,-455.218048,0.096860,0.000000
76.430000,58.813995,-455.218048,-0.000444,0.003811,0.096809,261.617706,13.327442,0.968085,-455.218048,0.096860,0.000000
76.670006,58.702652,-455.307007,-0.000423,0.003811,0.096809,261.122437,13.302211,0.968085,-455.307007,0.096860,0.000000
76.910004,58.610680,-455.218048,-0.000410,0.003811,0.096809,260.713318,13.281370,0.968085,-455.218048,0.096860,0.000000
77.150002,58.505669,-455.307007,-0.000405,0.003811,0.096809,260.246216,13.257574,0.968085,-455.307007,0.096860,0.000000
77.390007,58.423378,-455.262543,-0.000418,0.003811,0.096809,259.880157,13.238926,0.968085,-455.262543,0.096860,0.000000
77.630005,58.331398,-455.351501,-0.000401,0.003811,0.096809,259.471008,13.218083,0.968085,-455.351501,0.096860,0.000000
77.870003,58.235329,-455.307007,-0.000397,0.003811,0.096809,259.043671,13.196314,0.968085,-455.307007,0.096860,0.000000
78.110001,58.163460,-455.351501,-0.000423,0.003811,0.096809,258.723999,13.180028,0.968085,-455.351501,0.096860,0.000000
78.350006,58.062172,-455.351501,-0.000401,0.003811,0.096809,258.273437,13.157077,0.968085,-455.351501,0.096860,0.000000
78.590004,57.995895,-455.351501,-0.000427,0.003811,0.096809,257.978638,13.142057,0.968085,-455.351501,0.096860,0.000000
78.830002,57.919930,-455.484924,-0.000397,0.003811,0.096809,257.640717,13.124844,0.968085,-455.484924,0.096860,0.000000
79.070007,57.836143,-455.351501,-0.000435,0.003811,0.096809,257.268005,13.105858,0.968085,-455.351501,0.096860,0.000000
79.310005,57.764648,-455.351501,-0.000405,0.003811,0.096809,256.949982,13.089657,0.968085,-455.351501,0.096860,0.000000
79.550003,57.684593,-455.395966,-0.000414,0.003811,0.096809,256.593872,13.071516,0.968085,-455.395966,0.096860,0.000000
79.790001,57.633202,-455.395966,-0.000397,0.003811,0.096809,256.365295,13.059870,0.968085,-455.395966,0.096860,0.000000
80.030006,57.553513,-455.395966,-0.000397,0.003811,0.096809,256.010803,13.041812,0.968085,-455.395966,0.096860,0.000000
80.270004,57.489464,-455.440460,-0.000410,0.003811,0.096809,255.725906,13.027299,0.968085,-455.440460,0.096860,0.000000
80.510002,57.414993,-455.395966,-0.000410,0.003811,0.096809,255.394638,13.010424,0.968085,-455.395966,0.096860,0.000000
80.750008,57.366585,-455.484924,-0.000405,0.003811,0.096809,255.179321,12.999454,0.968085,-455.484924,0.096860,0.000000
80.990005,57.286522,-455.440460,-0.000401,0.003811,0.096809,254.823181,12.981311,0.968085,-455.440460,0.096860,0.000000
81.230003,57.232903,-455.529419,-0.000431,0.003811,0.096809,254.584671,12.969161,0.968085,-455.529419,0.096860,0.000000
81.470001,57.174065,-455.484924,-0.000397,0.003811,0.096809,254.322937,12.955828,0.968085,-455.484924,0.096860,0.000000
81.710007,57.121559,-455.529419,-0.000410,0.003811,0.096809,254.089386,12.943931,0.968085,-455.529419,0.096860,0.000000
81.950005,57.063103,-455.618378,-0.000401,0.003811,0.096809,253.829361,12.930684,0.968085,-455.618378,0.096860,0.000000
82.190002,57.015434,-455.529419,-0.000384,0.003811,0.096809,253.617325,12.919882,0.968085,-455.529419,0.096860,0.000000
82.430000,56.961067,-455.573914,-0.000414,0.003811,0.096809,253.375488,12.907562,0.968085,-455.573914,0.096860,0.000000
82.670006,56.902237,-455.573914,-0.000397,0.003811,0.096809,253.113785,12.894231,0.968085,-455.573914,0.096860,0.000000
82.910004,56.852341,-455.529419,-0.000392,0.003811,0.096809,252.891846,12.882924,0.968085,-455.529419,0.096860,0.000000
83.150002,56.802063,-455.662872,-0.000392,0.003811,0.096809,252.668198,12.871531,0.968085,-455.662872,0.096860,0.000000
83.390007,56.756264,-455.573914,-0.000410,0.003811,0.096809,252.464478,12.861153,0.968085,-455.573914,0.096860,0.000000
83.630005,56.704132,-455.662872,-0.000379,0.003811,0.096809,252.232574,12.849339,0.968085,-455.662872,0.096860,0.000000
83.870003,56.663918,-455.618378,-0.000392,0.003811,0.096809,252.053696,12.840227,0.968085,-455.618378,0.096860,0.000000
84.110001,56.610664,-455.573914,-0.000410,0.003811,0.096809,251.816818,12.828160,0.968085,-455.573914,0.096860,0.000000
84.350006,56.574173,-455.662872,-0.000418,0.003811,0.096809,251.654495,12.819890,0.968085,-455.662872,0.096860,0.000000
84.590004,56.533585,-455.662872,-0.000405,0.003811,0.096809,251.473938,12.810693,0.968085,-455.662872,0.096860,0.000000
84.830002,56.478104,-455.662872,-0.000397,0.003811,0.096809,251.227158,12.798121,0.968085,-455.662872,0.096860,0.000000
85.070007,56.446823,-455.707336,-0.000397,0.003811,0.096809,251.088013,12.791033,0.968085,-455.707336,0.096860,0.000000
85.310005,56.399162,-455.707336,-0.000388,0.003811,0.096809,250.876007,12.780233,0.968085,-455.707336,0.096860,0.000000
85.550003,56.363037,-455.707336,-0.000388,0.003811,0.096809,250.715317,12.772046,0.968085,-455.707336,0.096860,0.000000
85.790001,56.323944,-455.707336,-0.000388,0.003811,0.096809,250.541412,12.763188,0.968085,-455.707336,0.096860,0.000000
86.030006,56.283348,-455.707336,-0.000414,0.003811,0.096809,250.360840,12.753989,0.968085,-455.707336,0.096860,0.000000
86.270004,56.237175,-455.751831,-0.000388,0.003811,0.096809,250.155441,12.743526,0.968085,-455.751831,0.096860,0.000000
86.510002,56.211113,-455.796295,-0.000384,0.003811,0.096809,250.039520,12.737620,0.968085,-455.796295,0.096860,0.000000
86.750008,56.168289,-455.885254,-0.000392,0.003811,0.096809,249.849030,12.727916,0.968085,-455.885254,0.096860,0.000000
86.990005,56.135895,-455.751831,-0.000375,0.003811,0.096809,249.704926,12.720575,0.968085,-455.751831,0.096860,0.000000
87.230003,56.083389,-455.796295,-0.000414,0.003811,0.096809,249.471375,12.708678,0.968085,-455.796295,0.096860,0.000000
87.470001,56.055832,-455.885254,-0.000410,0.003811,0.096809,249.348801,12.702433,0.968085,-455.885254,0.096860,0.000000
87.710007,56.024178,-455.840790,-0.000397,0.003811,0.096809,249.207993,12.695260,0.968085,-455.840790,0.096860,0.000000
87.950005,55.975029,-455.885254,-0.000384,0.003811,0.096809,248.989365,12.684123,0.968085,-455.885254,0.096860,0.000000
88.190002,55.947098,-455.840790,-0.000379,0.003811,0.096809,248.865128,12.677794,0.968085,-455.840790,0.096860,0.000000
88.430008,55.887894,-455.885254,-0.000405,0.003811,0.096809,248.601761,12.664378,0.968085,-455.885254,0.096860,0.000000
88.670006,55.879700,-455.885254,-0.000379,0.003811,0.096809,248.565323,12.662520,0.968085,-455.885254,0.096860,0.000000
88.910004,55.837624,-455.885254,-0.000414,0.003811,0.096809,248.378159,12.652987,0.968085,-455.885254,0.096860,0.000000
89.150002,55.808578,-455.974243,-0.000384,0.003811,0.096809,248.248962,12.646404,0.968085,-455.974243,0.096860,0.000000
89.390007,55.771339,-455.929749,-0.000379,0.003811,0.096809,248.083313,12.637966,0.968085,-455.929749,0.096860,0.000000
89.630005,55.748627,-455.929749,-0.000397,0.003811,0.096809,247.982269,12.632820,0.968085,-455.929749,0.096860,0.000000
89.870003,55.718094,-455.974243,-0.000379,0.003811,0.096809,247.846466,12.625900,0.968085,-455.974243,0.096860,0.000000
90.110001,55.668938,-455.929749,-0.000379,0.003811,0.096809,247.627808,12.614762,0.968085,-455.929749,0.096860,0.000000
90.350006,55.651062,-455.929749,-0.000397,0.003811,0.096809,247.548294,12.610711,0.968085,-455.929749,0.096860,0.000000
90.590004,55.614944,-455.974243,-0.000414,0.003811,0.096809,247.387634,12.602527,0.968085,-455.974243,0.096860,0.000000
90.830002,55.586639,-456.063202,-0.000392,0.003811,0.096809,247.261719,12.596112,0.968085,-456.063202,0.096860,0.000000
91.070007,55.545685,-456.018707,-0.000375,0.003811,0.096809,247.079544,12.586832,0.968085,-456.018707,0.096860,0.000000
91.310005,55.529671,-455.974243,-0.000379,0.003811,0.096809,247.008316,12.583203,0.968085,-455.974243,0.096860,0.000000
91.550003,55.487961,-456.018707,-0.000397,0.003811,0.096809,246.822784,12.573752,0.968085,-456.018707,0.096860,0.000000
91.790001,55.477165,-455.974243,-0.000392,0.003811,0.096809,246.774750,12.571305,0.968085,-455.974243,0.096860,0.000000
92.030006,55.433968,-456.063202,-0.000397,0.003811,0.096809,246.582596,12.561516,0.968085,-456.063202,0.096860,0.000000
92.270004,55.417587,-456.063202,-0.000397,0.003811,0.096809,246.509735,12.557805,0.968085,-456.063202,0.096860,0.000000
92.510002,55.373276,-456.018707,-0.000392,0.003811,0.096809,246.312637,12.547763,0.968085,-456.018707,0.096860,0.000000
92.750008,55.351677,-456.107666,-0.000397,0.003811,0.096809,246.216553,12.542869,0.968085,-456.107666,0.096860,0.000000
92.990005,55.332314,-456.107666,-0.000388,0.003811,0.096809,246.130417,12.538482,0.968085,-456.107666,0.096860,0.000000
93.230003,55.298424,-456.107666,-0.000405,0.003811,0.096809,245.979675,12.530802,0.968085,-456.107666,0.096860,0.000000
93.470001,55.275711,-456.063202,-0.000392,0.003811,0.096809,245.878647,12.525656,0.968085,-456.063202,0.096860,0.000000
93.710007,55.256721,-456.107666,-0.000392,0.003811,0.096809,245.794174,12.521353,0.968085,-456.107666,0.096860,0.000000
93.950005,55.221718,-456.196625,-0.000379,0.003811,0.096809,245.638474,12.513420,0.968085,-456.196625,0.096860,0.000000
94.190002,55.199745,-456.152161,-0.000384,0.003811,0.096809,245.540726,12.508441,0.968085,-456.152161,0.096860,0.000000
94.430008,55.168098,-456.152161,-0.000375,0.003811,0.096809,245.399963,12.501270,0.968085,-456.152161,0.096860,0.000000
94.670006,55.147240,-456.152161,-0.000384,0.003811,0.096809,245.307175,12.496543,0.968085,-456.152161,0.096860,0.000000
94.910004,55.126762,-456.196625,-0.000371,0.003811,0.096809,245.216080,12.491903,0.968085,-456.196625,0.096860,0.000000
95.150002,55.088409,-456.285583,-0.000392,0.003811,0.096809,245.045486,12.483212,0.968085,-456.285583,0.096860,0.000000
95.390007,55.083199,-456.241119,-0.000379,0.003811,0.096809,245.022308,12.482031,0.968085,-456.241119,0.096860,0.000000
95.630005,55.056755,-456.285583,-0.000397,0.003811,0.096809,244.904678,12.476039,0.968085,-456.285583,0.096860,0.000000
95.870003,55.035904,-456.241119,-0.000371,0.003811,0.096809,244.811920,12.471313,0.968085,-456.241119,0.096860,0.000000
96.110008,55.003136,-456.285583,-0.000366,0.003811,0.096809,244.666168,12.463889,0.968085,-456.285583,0.096860,0.000000
96.350006,54.971855,-456.285583,-0.000392,0.003811,0.096809,244.527023,12.456800,0.968085,-456.285583,0.096860,0.000000
96.590004,54.955475,-456.285583,-0.000401,0.003811,0.096809,244.454163,12.453089,0.968085,-456.285583,0.096860,0.000000
96.830002,54.940948,-456.374573,-0.000379,0.003811,0.096809,244.389542,12.449798,0.968085,-456.374573,0.096860,0.000000
97.070007,54.907066,-456.374573,-0.000384,0.003811,0.096809,244.238831,12.442120,0.968085,-456.374573,0.096860,0.000000
97.310005,54.896637,-456.374573,-0.000379,0.003811,0.096809,244.192444,12.439755,0.968085,-456.374573,0.096860,0.000000
97.550003,54.866478,-456.374573,-0.000362,0.003811,0.096809,244.058289,12.432921,0.968085,-456.374573,0.096860,0.000000
97.790001,54.850464,-456.330078,-0.000392,0.003811,0.096809,243.987045,12.429293,0.968085,-456.330078,0.096860,0.000000
98.030006,54.824394,-456.374573,-0.000388,0.003811,0.096809,243.871078,12.423386,0.968085,-456.374573,0.096860,0.000000
98.270004,54.797211,-456.419037,-0.000375,0.003811,0.096809,243.750168,12.417226,0.968085,-456.419037,0.096860,0.000000
98.510002,54.771889,-456.419037,-0.000405,0.003811,0.096809,243.637527,12.411488,0.968085,-456.419037,0.096860,0.000000
98.750008,54.755508,-456.374573,-0.000388,0.003811,0.096809,243.564667,12.407776,0.968085,-456.374573,0.096860,0.000000
98.990005,54.739120,-456.419037,-0.000384,0.003811,0.096809,243.491776,12.404062,0.968085,-456.419037,0.096860,0.000000
99.230003,54.719391,-456.463531,-0.000366,0.003811,0.096809,243.404007,12.399590,0.968085,-456.463531,0.096860,0.000000
99.300003,54.715294,-456.463531,-0.000362,0.003811,0.096809,243.385788,12.398663,0.968085,-456.463531,0.096860,0.000000