File: Data/compression 14/AutoNoHeating-12-14-3-240726_07262024_164326.csv
Time (sec),S:Load (lbs),S:HL1 (DIM),S:LVDT (in),S:Position (in),Ch:Position (mm),Ch:Load (N),Ch:Stress (MPa),Ch:Strain (mm/mm),Ch:HL1 (DIM),Set Point (),Cycles ()
0.110000,-0.007820,-374.707520,-0.009934,-0.005350,-0.135886,-0.034786,-0.001772,-1.358861,-374.707520,-0.135669,0.000000
0.360000,0.006332,-374.752014,-0.009938,-0.005350,-0.135886,0.028168,0.001435,-1.358861,-374.752014,-0.135669,0.000000
0.610000,-0.001862,-374.796509,-0.009934,-0.005245,-0.133223,-0.008281,-0.000422,-1.332230,-374.796509,-0.132252,0.000000
0.860000,0.033516,-374.752014,-0.009839,-0.005095,-0.129425,0.149086,0.007595,-1.294252,-374.752014,-0.128089,0.000000
1.110000,0.023460,-374.752014,-0.009662,-0.004921,-0.125002,0.104357,0.005316,-1.250022,-374.752014,-0.123909,0.000000
1.360000,-0.018990,-374.796509,-0.009472,-0.004755,-0.120778,-0.084470,-0.004303,-1.207783,-374.796509,-0.119747,0.000000
1.610000,-0.010803,-374.796509,-0.009343,-0.004599,-0.116824,-0.048055,-0.002448,-1.168238,-374.796509,-0.115584,0.000000
1.860000,-0.016754,-374.796509,-0.009123,-0.004423,-0.112340,-0.074526,-0.003797,-1.123402,-374.796509,-0.111421,0.000000
2.110000,-0.058090,-374.840973,-0.008981,-0.004271,-0.108473,-0.258398,-0.013163,-1.084728,-374.840973,-0.107259,0.000000
2.360000,-0.016014,-374.929932,-0.008817,-0.004105,-0.104266,-0.071234,-0.003629,-1.042663,-374.929932,-0.103096,0.000000
2.610000,0.020477,-374.885468,-0.008658,-0.003943,-0.100148,0.091088,0.004640,-1.001476,-374.885468,-0.098933,0.000000
2.860000,0.005211,-374.929932,-0.008472,-0.003771,-0.095777,0.023179,0.001181,-0.957768,-374.929932,-0.094771,0.000000
3.110000,-0.000000,-374.929932,-0.008300,-0.003613,-0.091770,-0.000000,-0.000000,-0.917701,-374.929932,-0.090591,0.000000
3.360000,0.026810,-374.929932,-0.008132,-0.003451,-0.087668,0.119255,0.006075,-0.876680,-374.929932,-0.086428,0.000000
3.610000,0.000740,-374.929932,-0.007946,-0.003279,-0.083288,0.003292,0.000168,-0.832881,-374.929932,-0.082265,0.000000
3.860000,-0.040962,-374.974426,-0.007778,-0.003121,-0.079265,-0.182209,-0.009282,-0.792648,-374.974426,-0.078103,0.000000
4.110000,-0.002235,-374.974426,-0.007580,-0.002958,-0.075128,-0.009944,-0.000507,-0.751279,-374.974426,-0.073939,0.000000
4.360000,0.006699,-375.063385,-0.007433,-0.002797,-0.071052,0.029797,0.001518,-0.710516,-375.063385,-0.069777,0.000000
4.610000,0.020851,-375.018890,-0.007248,-0.002632,-0.066846,0.092750,0.004725,-0.668458,-375.018890,-0.065614,0.000000
4.860000,-0.012665,-375.018890,-0.007092,-0.002468,-0.062683,-0.056336,-0.002870,-0.626832,-375.018890,-0.061434,0.000000
5.110000,0.024948,-375.018890,-0.006911,-0.002305,-0.058546,0.110975,0.005653,-0.585463,-375.018890,-0.057272,0.000000
5.360000,0.021599,-375.063385,-0.006726,-0.002136,-0.054263,0.096076,0.004894,-0.542625,-375.063385,-0.053109,0.000000
5.610000,-0.014526,-375.063385,-0.006579,-0.001970,-0.050030,-0.064617,-0.003292,-0.500303,-375.063385,-0.048946,0.000000
5.860000,0.002235,-375.107849,-0.006385,-0.001808,-0.045920,0.009944,0.000507,-0.459199,-375.107849,-0.044784,0.000000
6.110000,-0.014893,-375.063385,-0.006222,-0.001636,-0.041549,-0.066245,-0.003375,-0.415491,-375.063385,-0.040621,0.000000
6.360000,-0.030907,-375.063385,-0.006036,-0.001482,-0.037646,-0.137480,-0.007004,-0.376461,-375.063385,-0.036458,0.000000
6.610000,-0.025696,-375.152344,-0.005877,-0.001319,-0.033493,-0.114301,-0.005823,-0.334925,-375.152344,-0.032296,0.000000
6.860000,0.029045,-375.152344,-0.005717,-0.001157,-0.029390,0.129199,0.006582,-0.293905,-375.152344,-0.028116,0.000000
7.110000,0.033882,-375.196808,-0.005527,-0.000983,-0.024967,0.150715,0.007678,-0.249674,-375.196808,-0.023953,0.000000
7.360000,0.012291,-375.196808,-0.005346,-0.000826,-0.020970,0.054673,0.002785,-0.209698,-375.196808,-0.019790,0.000000
7.610000,0.019737,-375.241302,-0.005195,-0.000659,-0.016746,0.087796,0.004473,-0.167459,-375.241302,-0.015628,0.000000
7.860001,-0.008194,-375.196808,-0.005001,-0.000494,-0.012558,-0.036449,-0.001857,-0.125575,-375.196808,-0.011465,0.000000
8.110001,0.007446,-375.241302,-0.004855,-0.000331,-0.008403,0.033123,0.001687,-0.084032,-375.241302,-0.007302,0.000000
8.360001,0.485199,-375.196808,-0.004682,-0.000166,-0.004206,2.158273,0.109948,-0.042058,-375.196808,-0.003139,0.000000
8.610001,0.700432,-375.241302,-0.004635,-0.000000,-0.000008,3.115676,0.158720,-0.000083,-375.241302,0.000173,0.000000
8.860001,0.657234,-375.241302,-0.004648,-0.000001,-0.000017,2.923524,0.148931,-0.000174,-375.241302,0.000173,0.000000
9.110001,0.646065,-375.241302,-0.004644,-0.000001,-0.000017,2.873840,0.146400,-0.000174,-375.241302,0.000391,0.000000
9.360001,0.624092,-375.285797,-0.004652,-0.000000,-0.000008,2.776100,0.141421,-0.000083,-375.285797,0.000807,0.000000
9.610001,0.769318,-375.285797,-0.004644,0.000018,0.000469,3.422096,0.174330,0.004686,-375.285797,0.001223,0.000000
9.860001,0.916779,-375.285797,-0.004622,0.000032,0.000815,4.078035,0.207745,0.008153,-375.285797,0.001640,0.000000
10.110001,1.050087,-375.374756,-0.004605,0.000045,0.001136,4.671020,0.237953,0.011362,-375.374756,0.002055,0.000000
10.360001,1.159943,-375.330261,-0.004631,0.000060,0.001527,5.159682,0.262847,0.015268,-375.330261,0.002472,0.000000
10.610001,1.331604,-375.330261,-0.004587,0.000075,0.001899,5.923270,0.301746,0.018993,-375.330261,0.002888,0.000000
10.860001,1.578110,-375.330261,-0.004592,0.000093,0.002350,7.019783,0.357605,0.023504,-375.330261,0.003304,0.000000
11.110001,1.714775,-375.330261,-0.004527,0.000106,0.002689,7.627700,0.388574,0.026888,-375.330261,0.003721,0.000000
11.360001,1.785896,-375.419220,-0.004553,0.000114,0.002888,7.944064,0.404690,0.028879,-375.419220,0.004137,0.000000
11.610001,2.248383,-375.374756,-0.004536,0.000144,0.003668,10.001306,0.509491,0.036683,-375.374756,0.004553,0.000000
11.860001,2.476646,-375.419220,-0.004497,0.000164,0.004154,11.016673,0.561216,0.041543,-375.419220,0.004970,0.000000
12.110001,2.648315,-375.463715,-0.004510,0.000178,0.004518,11.780295,0.600117,0.045184,-375.463715,0.005386,0.000000
12.360001,2.847534,-375.463715,-0.004467,0.000191,0.004848,12.666465,0.645260,0.048477,-375.463715,0.005802,0.000000
12.610001,2.990524,-375.463715,-0.004480,0.000203,0.005169,13.302516,0.677662,0.051687,-375.463715,0.006219,0.000000
12.860001,3.410187,-375.597137,-0.004458,0.000226,0.005741,15.169269,0.772759,0.057409,-375.597137,0.006634,0.000000
13.110001,3.478699,-375.508179,-0.004445,0.000235,0.005976,15.474025,0.788284,0.059756,-375.508179,0.007051,0.000000
13.360001,3.839531,-375.508179,-0.004428,0.000254,0.006461,17.079086,0.870050,0.064608,-375.508179,0.007476,0.000000
13.610001,4.129608,-375.597137,-0.004398,0.000272,0.006912,18.369415,0.935783,0.069120,-375.597137,0.007892,0.000000
13.860001,4.489693,-375.552673,-0.004381,0.000294,0.007459,19.971151,1.017379,0.074585,-375.552673,0.008308,0.000000
14.110001,4.439796,-375.597137,-0.004372,0.000303,0.007684,19.749201,1.006072,0.076841,-375.597137,0.008724,0.000000
14.360001,4.801743,-375.597137,-0.004363,0.000320,0.008117,21.359217,1.088090,0.081171,-375.597137,0.009141,0.000000
14.610001,4.990906,-375.641632,-0.004350,0.000332,0.008438,22.200657,1.130955,0.084380,-375.641632,0.009557,0.000000
14.860001,5.472382,-375.641632,-0.004333,0.000358,0.009106,24.342369,1.240059,0.091057,-375.641632,0.009973,0.000000
15.110001,5.421745,-375.641632,-0.004312,0.000366,0.009288,24.117128,1.228585,0.092881,-375.641632,0.010390,0.000000
15.360001,5.830605,-375.686127,-0.004303,0.000386,0.009808,25.935823,1.321234,0.098082,-375.686127,0.010806,0.000000
15.610001,6.279312,-375.641632,-0.004264,0.000408,0.010372,27.931776,1.422912,0.103721,-375.641632,0.011222,0.000000
15.860001,6.385811,-375.686127,-0.004251,0.000422,0.010719,28.405506,1.447045,0.107188,-375.686127,0.011639,0.000000
16.110001,6.604767,-375.730591,-0.004243,0.000437,0.011100,29.379471,1.496662,0.111003,-375.730591,0.012055,0.000000
16.360001,6.708290,-375.686127,-0.004247,0.000450,0.011421,29.839964,1.520120,0.114213,-375.686127,0.012471,0.000000
16.610001,7.046402,-375.775085,-0.004255,0.000466,0.011829,31.343962,1.596738,0.118293,-375.775085,0.012887,0.000000
16.860001,7.322334,-375.775085,-0.004221,0.000483,0.012263,32.571369,1.659265,0.122631,-375.775085,0.013303,0.000000
17.110001,7.570328,-375.775085,-0.004208,0.000498,0.012653,33.674500,1.715461,0.126529,-375.775085,0.013719,0.000000
17.360001,7.797478,-375.775085,-0.004186,0.000512,0.013009,34.684914,1.766934,0.130087,-375.775085,0.014136,0.000000
17.610001,8.396996,-375.775085,-0.004148,0.000541,0.013737,37.351700,1.902786,0.137369,-375.775085,0.014552,0.000000
17.860001,8.464767,-375.819550,-0.004156,0.000556,0.014118,37.653168,1.918144,0.141184,-375.819550,0.014969,0.000000
18.110001,8.500893,-375.908508,-0.004148,0.000568,0.014422,37.813858,1.926330,0.144220,-375.908508,0.015385,0.000000
18.360001,8.794693,-375.819550,-0.004130,0.000585,0.014856,39.120747,1.992906,0.148557,-375.819550,0.015801,0.000000
18.610001,9.149193,-375.819550,-0.004113,0.000604,0.015350,40.697643,2.073237,0.153500,-375.819550,0.016226,0.000000
18.860001,9.361069,-375.864044,-0.004096,0.000620,0.015741,41.640114,2.121248,0.157406,-375.864044,0.016642,0.000000
19.110001,9.297020,-375.908508,-0.004070,0.000627,0.015914,41.355209,2.106735,0.159140,-375.908508,0.017059,0.000000
19.360001,9.520073,-375.953003,-0.004027,0.000640,0.016261,42.347401,2.157279,0.162607,-375.953003,0.017475,0.000000
19.610001,10.119217,-375.908508,-0.004070,0.000667,0.016946,45.012524,2.293047,0.169457,-375.908508,0.017891,0.000000
19.860001,10.304665,-375.864044,-0.004031,0.000683,0.017336,45.837437,2.335070,0.173363,-375.864044,0.018308,0.000000
20.110001,10.513939,-375.908508,-0.004023,0.000700,0.017769,46.768337,2.382493,0.177693,-375.908508,0.018724,0.000000
20.360001,10.596603,-375.953003,-0.004001,0.000715,0.018168,47.136047,2.401225,0.181683,-375.953003,0.019140,0.000000
20.610001,10.910515,-375.953003,-0.003971,0.000732,0.018602,48.532394,2.472358,0.186020,-375.953003,0.019556,0.000000
20.860001,11.137283,-375.997467,-0.003932,0.000749,0.019018,49.541111,2.523745,0.190183,-375.997467,0.019972,0.000000
21.110001,11.113831,-375.997467,-0.003971,0.000759,0.019270,49.436787,2.518430,0.192697,-375.997467,0.020388,0.000000
21.360001,11.222931,-376.041962,-0.003954,0.000769,0.019539,49.922089,2.543153,0.195391,-376.041962,0.020805,0.000000
21.610001,12.200035,-376.041962,-0.003928,0.000802,0.020371,54.268467,2.764568,0.203711,-376.041962,0.021221,0.000000
21.860001,12.007896,-375.997467,-0.003889,0.000814,0.020666,53.413792,2.721028,0.206663,-375.997467,0.021637,0.000000
22.110001,12.274139,-376.086456,-0.003867,0.000833,0.021152,54.598099,2.781360,0.211515,-376.086456,0.022054,0.000000
22.360001,12.610390,-376.130920,-0.003885,0.000853,0.021663,56.093815,2.857555,0.216632,-376.130920,0.022470,0.000000
22.610001,12.741837,-376.041962,-0.003872,0.000869,0.022080,56.678520,2.887341,0.220796,-376.041962,0.022887,0.000000
22.860001,12.682632,-376.130920,-0.003850,0.000880,0.022340,56.415165,2.873926,0.223400,-376.130920,0.023303,0.000000
23.110001,12.862488,-376.175415,-0.003824,0.000894,0.022713,57.215202,2.914681,0.227132,-376.175415,0.023719,0.000000
23.360001,13.613190,-376.175415,-0.003794,0.000919,0.023354,60.554493,3.084793,0.233543,-376.175415,0.024135,0.000000
23.610001,13.529037,-376.130920,-0.003811,0.000933,0.023702,60.180164,3.065724,0.237018,-376.130920,0.024560,0.000000
23.860001,13.597176,-376.175415,-0.003786,0.000948,0.024083,60.483257,3.081164,0.240833,-376.175415,0.024977,0.000000
24.110001,13.914444,-376.219879,-0.003747,0.000965,0.024517,61.894539,3.153058,0.245170,-376.219879,0.025393,0.000000
24.360001,14.165794,-376.219879,-0.003755,0.000982,0.024950,63.012600,3.210015,0.249500,-376.219879,0.025809,0.000000
24.610001,14.306923,-376.264374,-0.003764,0.000997,0.025323,63.640373,3.241995,0.253232,-376.264374,0.026225,0.000000
24.860001,14.237289,-376.219879,-0.003747,0.001008,0.025592,63.330627,3.226216,0.255919,-376.219879,0.026641,0.000000
25.110001,14.627533,-376.308838,-0.003708,0.001024,0.026000,65.066513,3.314646,0.260000,-376.308838,0.027057,0.000000
25.360001,15.287003,-376.264374,-0.003717,0.001050,0.026676,67.999985,3.464084,0.266759,-376.264374,0.027474,0.000000
25.610001,15.344353,-376.308838,-0.003673,0.001066,0.027084,68.255089,3.477080,0.270840,-376.308838,0.027890,0.000000
25.860001,15.238968,-376.308838,-0.003686,0.001078,0.027387,67.786316,3.453199,0.273875,-376.308838,0.028306,0.000000
26.110001,15.298920,-376.308838,-0.003648,0.001092,0.027725,68.052994,3.466785,0.277251,-376.308838,0.028723,0.000000
26.360001,15.833649,-376.397797,-0.003656,0.001111,0.028211,70.431587,3.587956,0.282111,-376.397797,0.029139,0.000000
26.610001,15.958763,-376.353333,-0.003630,0.001125,0.028575,70.988121,3.616307,0.285752,-376.353333,0.029555,0.000000
26.860001,15.872749,-376.442291,-0.003630,0.001136,0.028844,70.605515,3.596816,0.288439,-376.442291,0.029972,0.000000
27.110001,16.101753,-376.397797,-0.003587,0.001151,0.029225,71.624176,3.648709,0.292254,-376.397797,0.030388,0.000000
27.360001,17.147003,-376.486755,-0.003561,0.001183,0.030041,76.273682,3.885566,0.300407,-376.486755,0.030804,0.000000
27.610001,16.921349,-376.486755,-0.003548,0.001194,0.030336,75.269920,3.834432,0.303359,-376.486755,0.031220,0.000000
27.860001,16.737396,-376.486755,-0.003553,0.001207,0.030665,74.451660,3.792748,0.306652,-376.486755,0.031636,0.000000
28.110001,17.030083,-376.486755,-0.003570,0.001224,0.031090,75.753593,3.859072,0.310899,-376.486755,0.032053,0.000000
28.360001,17.395378,-376.531250,-0.003531,0.001242,0.031541,77.378510,3.941849,0.315410,-376.531250,0.032469,0.000000
28.610001,17.667213,-376.486755,-0.003514,0.001258,0.031957,78.587692,4.003448,0.319574,-376.486755,0.032894,0.000000
28.860001,17.763657,-376.531250,-0.003497,0.001274,0.032348,79.016693,4.025302,0.323480,-376.531250,0.033310,0.000000
29.110001,18.225769,-376.531250,-0.003484,0.001296,0.032929,81.072273,4.130018,0.329286,-376.531250,0.033726,0.000000
29.360001,18.364288,-376.531250,-0.003475,0.001313,0.033354,81.688431,4.161407,0.333540,-376.531250,0.034143,0.000000
29.610001,18.216835,-376.531250,-0.003441,0.001325,0.033658,81.032532,4.127994,0.336576,-376.531250,0.034559,0.000000
29.860001,18.411209,-376.531250,-0.003423,0.001340,0.034039,81.897148,4.172040,0.340391,-376.531250,0.034975,0.000000
30.110001,18.449196,-376.575745,-0.003402,0.001353,0.034377,82.066124,4.180647,0.343767,-376.575745,0.035392,0.000000
30.360001,18.951523,-376.664703,-0.003428,0.001373,0.034880,84.300583,4.294477,0.348801,-376.664703,0.035808,0.000000
30.610001,18.931412,-376.620209,-0.003415,0.001384,0.035158,84.211128,4.289919,0.351579,-376.620209,0.036224,0.000000
30.860001,19.497421,-376.620209,-0.003406,0.001405,0.035686,86.728859,4.418179,0.356863,-376.620209,0.036641,0.000000
31.110001,19.887665,-376.620209,-0.003380,0.001423,0.036147,88.464752,4.506609,0.361465,-376.620209,0.037056,0.000000
31.360001,19.786385,-376.620209,-0.003372,0.001438,0.036536,88.014236,4.483659,0.365363,-376.620209,0.037473,0.000000
31.610001,19.783028,-376.709167,-0.003376,0.001451,0.036849,87.999306,4.482898,0.368490,-376.709167,0.037889,0.000000
31.860001,20.285362,-376.709167,-0.003333,0.001473,0.037404,90.233795,4.596729,0.374038,-376.709167,0.038305,0.000000
32.110001,19.949478,-376.709167,-0.003324,0.001483,0.037663,88.739708,4.520617,0.376635,-376.709167,0.038722,0.000000
32.360001,20.476761,-376.709167,-0.003320,0.001502,0.038158,91.085182,4.640100,0.381578,-376.709167,0.039138,0.000000
32.610001,20.273445,-376.709167,-0.003298,0.001510,0.038349,90.180786,4.594028,0.383486,-376.709167,0.039554,0.000000
32.860001,21.006271,-376.753662,-0.003303,0.001534,0.038956,93.440559,4.760089,0.389557,-376.753662,0.039971,0.000000
33.110001,21.605797,-376.753662,-0.003294,0.001557,0.039554,96.107384,4.895943,0.395544,-376.753662,0.040387,0.000000
33.360001,21.517914,-376.798126,-0.003264,0.001573,0.039944,95.716461,4.876029,0.399443,-376.798126,0.040803,0.000000
33.610001,21.346626,-376.753662,-0.003272,0.001586,0.040274,94.954536,4.837214,0.402743,-376.753662,0.041220,0.000000
33.860001,21.391304,-376.842621,-0.003247,0.001599,0.040621,95.153275,4.847339,0.406210,-376.842621,0.041644,0.000000
34.110001,21.791237,-376.798126,-0.003234,0.001618,0.041107,96.932266,4.937965,0.411070,-376.798126,0.042061,0.000000
34.360001,21.855659,-376.842621,-0.003225,0.001631,0.041436,97.218826,4.952563,0.414363,-376.842621,0.042477,0.000000
34.610001,22.048546,-376.753662,-0.003203,0.001650,0.041905,98.076828,4.996272,0.419048,-376.753662,0.042893,0.000000
34.860001,22.345695,-376.887085,-0.003182,0.001666,0.042312,99.398621,5.063607,0.423121,-376.887085,0.043310,0.000000
35.110001,22.881912,-376.887085,-0.003165,0.001688,0.042876,101.783829,5.185115,0.428760,-376.887085,0.043725,0.000000
35.360001,22.628326,-376.887085,-0.003165,0.001698,0.043127,100.655823,5.127652,0.431274,-376.887085,0.044142,0.000000
35.610001,22.549011,-376.887085,-0.003186,0.001712,0.043491,100.303009,5.109679,0.434915,-376.887085,0.044558,0.000000
35.860001,22.934418,-376.887085,-0.003143,0.001730,0.043943,102.017387,5.197013,0.439426,-376.887085,0.044974,0.000000
36.110001,23.586067,-376.976074,-0.003143,0.001752,0.044497,104.916069,5.344679,0.444975,-376.976074,0.045391,0.000000
36.360001,23.306046,-376.976074,-0.003104,0.001763,0.044784,103.670471,5.281225,0.447836,-376.976074,0.045807,0.000000
36.610001,23.306793,-376.976074,-0.003134,0.001777,0.045139,103.673798,5.281395,0.451394,-376.976074,0.046223,0.000000
36.860001,24.055260,-376.976074,-0.003100,0.001800,0.045729,107.003136,5.451000,0.457291,-376.976074,0.046640,0.000000
37.110001,24.070526,-376.976074,-0.003065,0.001818,0.046171,107.071045,5.454459,0.461712,-376.976074,0.047056,0.000000
37.360001,23.929398,-377.020538,-0.003061,0.001832,0.046535,106.443275,5.422479,0.465353,-377.020538,0.047472,0.000000
37.610001,23.759972,-377.065033,-0.003070,0.001845,0.046874,105.689629,5.384087,0.468737,-377.065033,0.047889,0.000000
37.860001,24.254478,-377.065033,-0.003065,0.001863,0.047325,107.889305,5.496144,0.473248,-377.065033,0.048304,0.000000
38.110001,24.260811,-377.109497,-0.003070,0.001878,0.047689,107.917473,5.497579,0.476889,-377.109497,0.048721,0.000000
38.360001,24.500618,-377.109497,-0.003018,0.001895,0.048131,108.984192,5.551919,0.481310,-377.109497,0.049137,0.000000
38.610001,24.493172,-377.109497,-0.003027,0.001908,0.048461,108.951073,5.550232,0.484610,-377.109497,0.049553,0.000000
38.860001,25.318344,-377.153992,-0.003005,0.001933,0.049102,112.621620,5.737218,0.491022,-377.153992,0.049979,0.000000
39.110001,25.393570,-377.153992,-0.003022,0.001951,0.049553,112.956238,5.754265,0.495534,-377.153992,0.050394,0.000000
39.360001,24.936668,-377.198456,-0.002997,0.001965,0.049909,110.923843,5.650730,0.499091,-377.198456,0.050811,0.000000
39.610001,24.809311,-377.109497,-0.002971,0.001977,0.050204,110.357330,5.621870,0.502036,-377.109497,0.051227,0.000000
39.860001,25.438622,-377.242950,-0.002975,0.001998,0.050742,113.156639,5.764474,0.507418,-377.242950,0.051643,0.000000
40.110001,25.209984,-377.242950,-0.002945,0.002011,0.051079,112.139610,5.712664,0.510794,-377.242950,0.052060,0.000000
40.360001,25.244247,-377.198456,-0.002940,0.002025,0.051435,112.292023,5.720428,0.514352,-377.198456,0.052476,0.000000
40.610001,25.265846,-377.198456,-0.002958,0.002038,0.051774,112.388100,5.725323,0.517736,-377.198456,0.052892,0.000000
40.860001,25.434158,-377.198456,-0.002932,0.002053,0.052155,113.136787,5.763463,0.521551,-377.198456,0.053309,0.000000
41.110001,26.124908,-377.287415,-0.002928,0.002078,0.052788,116.209396,5.919989,0.527879,-377.287415,0.053725,0.000000
41.360001,26.184113,-377.287415,-0.002923,0.002096,0.053239,116.472748,5.933405,0.532391,-377.287415,0.054141,0.000000
41.610001,26.075378,-377.287415,-0.002923,0.002109,0.053577,115.989075,5.908765,0.535775,-377.287415,0.054557,0.000000
41.860001,26.104797,-377.287415,-0.002902,0.002126,0.054011,116.119942,5.915431,0.540112,-377.287415,0.054973,0.000000
42.110001,26.217628,-377.331909,-0.002867,0.002144,0.054462,116.621834,5.941000,0.544616,-377.331909,0.055390,0.000000
42.360001,25.733917,-377.376404,-0.002884,0.002154,0.054722,114.470184,5.831389,0.547220,-377.376404,0.055806,0.000000
42.610001,25.825516,-377.420868,-0.002884,0.002167,0.055043,114.877632,5.852145,0.550430,-377.420868,0.056222,0.000000
42.860001,27.100891,-377.376404,-0.002889,0.002196,0.055771,120.550781,6.141150,0.557712,-377.376404,0.056639,0.000000
43.110001,26.677879,-377.420868,-0.002841,0.002209,0.056110,118.669136,6.045294,0.561096,-377.420868,0.057055,0.000000
43.360001,26.800758,-377.420868,-0.002841,0.002226,0.056552,119.215729,6.073138,0.565516,-377.420868,0.057471,0.000000
43.610001,26.747513,-377.465363,-0.002841,0.002242,0.056942,118.978882,6.061073,0.569422,-377.465363,0.057888,0.000000
43.860001,27.014130,-377.376404,-0.002846,0.002262,0.057445,120.164848,6.121489,0.574449,-377.376404,0.058312,0.000000
44.110001,26.802254,-377.465363,-0.002828,0.002275,0.057775,119.222382,6.073477,0.577749,-377.465363,0.058729,0.000000
44.360001,26.347954,-377.465363,-0.002824,0.002286,0.058069,117.201553,5.970531,0.580694,-377.465363,0.059145,0.000000
44.610001,27.546249,-377.465363,-0.002794,0.002314,0.058764,122.531837,6.242070,0.587635,-377.465363,0.059561,0.000000
44.860001,27.458374,-377.509827,-0.002785,0.002328,0.059136,122.140945,6.222157,0.591360,-377.509827,0.059978,0.000000
45.110001,27.127335,-377.554321,-0.002790,0.002341,0.059466,120.668411,6.147142,0.594660,-377.554321,0.060394,0.000000
45.360001,27.215210,-377.554321,-0.002794,0.002358,0.059900,121.059303,6.167055,0.598997,-377.554321,0.060810,0.000000
45.610001,27.526146,-377.598785,-0.002764,0.002376,0.060359,122.442413,6.237514,0.603592,-377.598785,0.061226,0.000000
45.860001,27.599503,-377.598785,-0.002755,0.002392,0.060758,122.768723,6.254137,0.607582,-377.598785,0.061642,0.000000
46.110001,27.338097,-377.598785,-0.002759,0.002404,0.061070,121.605927,6.194901,0.610700,-377.598785,0.062059,0.000000
46.360001,27.385017,-377.598785,-0.002759,0.002420,0.061461,121.814644,6.205534,0.614606,-377.598785,0.062475,0.000000
46.610001,28.392654,-377.643280,-0.002746,0.002442,0.062033,126.296837,6.433867,0.620329,-377.643280,0.062891,0.000000
46.860001,28.494682,-377.687744,-0.002729,0.002460,0.062492,126.750679,6.456987,0.624924,-377.687744,0.063308,0.000000
47.110001,28.130875,-377.643280,-0.002755,0.002472,0.062779,125.132378,6.374547,0.627785,-377.643280,0.063724,0.000000
47.360001,28.004272,-377.687744,-0.002695,0.002486,0.063152,124.569229,6.345859,0.631517,-377.687744,0.064140,0.000000
47.610001,28.391167,-377.643280,-0.002686,0.002504,0.063611,126.290215,6.433530,0.636112,-377.643280,0.064557,0.000000
47.860001,28.477554,-377.687744,-0.002682,0.002519,0.063984,126.674492,6.453106,0.639844,-377.687744,0.064973,0.000000
48.110001,28.379997,-377.732239,-0.002712,0.002532,0.064314,126.240532,6.430999,0.643137,-377.732239,0.065389,0.000000
48.360001,28.581444,-377.776703,-0.002690,0.002547,0.064704,127.136612,6.476647,0.647035,-377.776703,0.065805,0.000000
48.610001,29.700050,-377.732239,-0.002673,0.002576,0.065441,132.112427,6.730128,0.654408,-377.732239,0.066221,0.000000
48.860001,29.809158,-377.776703,-0.002656,0.002592,0.065840,132.597763,6.754852,0.658398,-377.776703,0.066638,0.000000
49.110001,29.386513,-377.776703,-0.002677,0.002603,0.066126,130.717743,6.659079,0.661259,-377.776703,0.067063,0.000000
49.360001,29.178360,-377.776703,-0.002639,0.002619,0.066516,129.791824,6.611911,0.665165,-377.776703,0.067479,0.000000
49.610001,29.411835,-377.821198,-0.002647,0.002634,0.066915,130.830368,6.664817,0.669154,-377.821198,0.067895,0.000000
49.860001,30.064980,-377.821198,-0.002647,0.002655,0.067445,133.735703,6.812821,0.674446,-377.821198,0.068311,0.000000
50.110001,29.715691,-377.821198,-0.002669,0.002667,0.067739,132.181992,6.733672,0.677390,-377.821198,0.068728,0.000000
50.360001,30.541618,-377.865692,-0.002652,0.002689,0.068303,135.855896,6.920830,0.683030,-377.865692,0.069144,0.000000
50.610001,30.727798,-377.865692,-0.002652,0.002707,0.068762,136.684067,6.963018,0.687625,-377.865692,0.069560,0.000000
50.860001,30.639549,-377.865692,-0.002626,0.002721,0.069118,136.291519,6.943021,0.691182,-377.865692,0.069977,0.000000
51.110001,30.435493,-377.910156,-0.002587,0.002734,0.069448,135.383835,6.896781,0.694475,-377.910156,0.070393,0.000000
51.360001,30.438843,-377.910156,-0.002596,0.002750,0.069838,135.398727,6.897541,0.698381,-377.910156,0.070809,0.000000
51.610001,31.013412,-377.865692,-0.002608,0.002767,0.070280,137.954544,7.027740,0.702802,-377.865692,0.071226,0.000000
51.860001,30.946388,-377.865692,-0.002604,0.002780,0.070601,137.656403,7.012552,0.706012,-377.865692,0.071642,0.000000
52.110001,30.862976,-377.954651,-0.002604,0.002794,0.070965,137.285370,6.993650,0.709653,-377.954651,0.072058,0.000000
52.360001,32.232933,-377.999115,-0.002604,0.002818,0.071590,143.379242,7.304087,0.715898,-377.999115,0.072474,0.000000
52.610001,32.102600,-377.954651,-0.002557,0.002834,0.071971,142.799500,7.274553,0.719713,-377.954651,0.072890,0.000000
52.860001,32.199791,-378.043610,-0.002591,0.002849,0.072361,143.231827,7.296577,0.723611,-378.043610,0.073307,0.000000
53.110004,32.180054,-378.043610,-0.002557,0.002865,0.072760,143.144028,7.292105,0.727601,-378.043610,0.073723,0.000000
53.360004,31.951416,-378.043610,-0.002561,0.002874,0.073003,142.126999,7.240294,0.730031,-378.043610,0.074139,0.000000
53.610004,32.776596,-378.088074,-0.002557,0.002896,0.073558,145.797577,7.427283,0.735579,-378.088074,0.074556,0.000000
53.860004,32.524498,-377.999115,-0.002539,0.002908,0.073871,144.676193,7.370157,0.738706,-377.999115,0.074972,0.000000
54.110004,33.062576,-378.043610,-0.002539,0.002926,0.074322,147.069687,7.492087,0.743217,-378.043610,0.075397,0.000000
54.360004,34.042290,-378.088074,-0.002539,0.002950,0.074929,151.427673,7.714093,0.749288,-378.088074,0.075813,0.000000
54.610004,34.135010,-378.088074,-0.002492,0.002966,0.075328,151.840103,7.735104,0.753277,-378.088074,0.076229,0.000000
54.860004,34.095169,-378.088074,-0.002518,0.002981,0.075709,151.662888,7.726076,0.757093,-378.088074,0.076646,0.000000
55.110004,33.860199,-378.132568,-0.002483,0.002993,0.076030,150.617691,7.672831,0.760302,-378.132568,0.077062,0.000000
55.360004,33.965584,-378.132568,-0.002496,0.003009,0.076437,151.086456,7.696711,0.764375,-378.132568,0.077478,0.000000
55.610004,34.878265,-378.132568,-0.002475,0.003029,0.076932,155.146271,7.903528,0.769318,-378.132568,0.077895,0.000000
55.860004,34.482803,-378.221527,-0.002453,0.003038,0.077166,153.387177,7.813915,0.771657,-378.221527,0.078311,0.000000
56.110004,34.926674,-378.132568,-0.002445,0.003056,0.077634,155.361603,7.914497,0.776343,-378.132568,0.078727,0.000000
56.360004,35.530663,-378.177032,-0.002475,0.003077,0.078163,158.048279,8.051363,0.781634,-378.177032,0.079143,0.000000
56.610004,36.039322,-378.221527,-0.002406,0.003095,0.078605,160.310913,8.166627,0.786055,-378.221527,0.079559,0.000000
56.860004,35.774193,-378.221527,-0.002410,0.003106,0.078892,159.131561,8.106547,0.788916,-378.221527,0.079976,0.000000
57.110004,35.948463,-378.221527,-0.002423,0.003125,0.079378,159.906754,8.146038,0.793776,-378.221527,0.080392,0.000000
57.360004,36.547615,-378.221527,-0.002423,0.003144,0.079845,162.571915,8.281808,0.798454,-378.221527,0.080808,0.000000
57.610004,37.127022,-378.266022,-0.002380,0.003160,0.080253,165.149246,8.413104,0.802534,-378.266022,0.081225,0.000000
57.860004,36.699539,-378.310486,-0.002380,0.003171,0.080540,163.247696,8.316235,0.805395,-378.310486,0.081641,0.000000
58.110004,37.638290,-378.266022,-0.002358,0.003194,0.081129,167.423477,8.528959,0.811292,-378.266022,0.082057,0.000000
58.360004,38.199455,-378.310486,-0.002363,0.003212,0.081589,169.919662,8.656120,0.815887,-378.310486,0.082474,0.000000
58.610004,38.082161,-378.354980,-0.002358,0.003226,0.081944,169.397919,8.629541,0.819445,-378.354980,0.082890,0.000000
58.860004,38.175995,-378.354980,-0.002350,0.003240,0.082291,169.815308,8.650804,0.822912,-378.354980,0.083306,0.000000
59.110004,38.410591,-378.354980,-0.002320,0.003257,0.082716,170.858841,8.703964,0.827159,-378.354980,0.083731,0.000000
59.360004,39.004898,-378.354980,-0.002307,0.003275,0.083194,173.502457,8.838636,0.831935,-378.354980,0.084147,0.000000
59.610004,38.871216,-378.399445,-0.002307,0.003286,0.083471,172.907806,8.808343,0.834706,-378.399445,0.084564,0.000000
59.860004,38.901009,-378.443939,-0.002315,0.003300,0.083809,173.040329,8.815095,0.838089,-378.443939,0.084980,0.000000
60.110004,40.261658,-378.443939,-0.002298,0.003324,0.084442,179.092804,9.123423,0.844418,-378.443939,0.085396,0.000000
60.360004,40.938629,-378.443939,-0.002268,0.003345,0.084963,182.104111,9.276826,0.849626,-378.443939,0.085812,0.000000
60.610004,40.933411,-378.443939,-0.002294,0.003358,0.085292,182.080902,9.275643,0.852919,-378.443939,0.086228,0.000000
60.860004,40.752441,-378.488403,-0.002246,0.003371,0.085621,181.275909,9.234635,0.856211,-378.488403,0.086645,0.000000
61.110004,40.933044,-378.488403,-0.002276,0.003386,0.086003,182.079269,9.275560,0.860027,-378.488403,0.087061,0.000000
61.360004,41.798439,-378.443939,-0.002242,0.003407,0.086549,185.928741,9.471663,0.865492,-378.443939,0.087477,0.000000
61.610004,41.867699,-378.532898,-0.002233,0.003421,0.086888,186.236832,9.487356,0.868876,-378.532898,0.087894,0.000000
61.860004,41.757103,-378.577362,-0.002233,0.003433,0.087199,185.744873,9.462295,0.871994,-378.577362,0.088310,0.000000
62.110004,41.528465,-378.577362,-0.002208,0.003444,0.087477,184.727844,9.410484,0.874772,-378.577362,0.088726,0.000000
62.360004,43.509117,-378.532898,-0.002208,0.003471,0.088171,193.538223,9.859306,0.881714,-378.532898,0.089143,0.000000
62.610004,43.437988,-378.577362,-0.002199,0.003486,0.088544,193.221817,9.843189,0.885438,-378.577362,0.089559,0.000000
62.860004,43.896385,-378.577362,-0.002182,0.003500,0.088908,195.260880,9.947063,0.889079,-378.577362,0.089975,0.000000
63.110004,44.110870,-378.621857,-0.002177,0.003515,0.089272,196.214951,9.995667,0.892720,-378.621857,0.090391,0.000000
63.360004,44.789703,-378.666351,-0.002173,0.003534,0.089766,199.234558,10.149491,0.897664,-378.666351,0.090807,0.000000
63.610004,44.892105,-378.621857,-0.002156,0.003549,0.090140,199.690063,10.172696,0.901395,-378.621857,0.091224,0.000000
63.860004,44.984825,-378.710815,-0.002169,0.003562,0.090469,200.102493,10.193707,0.904688,-378.710815,0.091640,0.000000
64.110001,46.071411,-378.666351,-0.002156,0.003587,0.091102,204.935867,10.439931,0.911024,-378.666351,0.092065,0.000000
64.360001,46.873871,-378.666351,-0.002121,0.003602,0.091492,208.505386,10.621771,0.914923,-378.666351,0.092481,0.000000
64.610001,47.166557,-378.755310,-0.002139,0.003620,0.091953,209.807327,10.688095,0.919525,-378.755310,0.092897,0.000000
64.860001,47.662926,-378.799774,-0.002143,0.003637,0.092368,212.015289,10.800573,0.923681,-378.799774,0.093314,0.000000
65.110001,48.289635,-378.710815,-0.002130,0.003656,0.092854,214.803024,10.942587,0.928541,-378.710815,0.093730,0.000000
65.360001,48.745041,-378.755310,-0.002104,0.003670,0.093227,216.828766,11.045784,0.932273,-378.755310,0.094146,0.000000
65.610001,48.522362,-378.755310,-0.002113,0.003681,0.093504,215.838242,10.995325,0.935043,-378.755310,0.094563,0.000000
65.860001,49.483833,-378.799774,-0.002061,0.003702,0.094043,220.115082,11.213197,0.940425,-378.799774,0.094979,0.000000
66.110001,50.628128,-378.799774,-0.002091,0.003724,0.094597,225.205154,11.472498,0.945974,-378.799774,0.095395,0.000000
66.360001,50.615471,-378.799774,-0.002052,0.003735,0.094874,225.148865,11.469630,0.948744,-378.799774,0.095812,0.000000
66.610001,51.192650,-378.844269,-0.002052,0.003752,0.095291,227.716278,11.600420,0.952908,-378.844269,0.096228,0.000000
66.860001,51.874092,-378.844269,-0.002057,0.003770,0.095768,230.747482,11.754837,0.957677,-378.844269,0.096644,0.000000
67.110001,52.495949,-378.888733,-0.002044,0.003786,0.096158,233.513641,11.895752,0.961583,-378.888733,0.097060,0.000000
67.360001,52.796455,-378.888733,-0.002061,0.003798,0.096470,234.850357,11.963848,0.964702,-378.888733,0.097476,0.000000
67.610001,52.759964,-378.888733,-0.002031,0.003807,0.096687,234.688034,11.955579,0.966874,-378.888733,0.097893,0.000000
67.860001,54.681778,-378.888733,-0.001988,0.003837,0.097459,243.236694,12.391068,0.974588,-378.888733,0.098309,0.000000
68.110001,55.682716,-378.888733,-0.002022,0.003855,0.097910,247.689087,12.617884,0.979099,-378.888733,0.098725,0.000000
68.360001,56.077805,-378.933228,-0.002009,0.003869,0.098266,249.446533,12.707413,0.982657,-378.933228,0.099142,0.000000
68.610001,56.309792,-378.933228,-0.002013,0.003880,0.098560,250.478470,12.759981,0.985602,-378.933228,0.099558,0.000000
68.860001,56.688492,-378.977692,-0.002005,0.003891,0.098838,252.163010,12.845796,0.988380,-378.977692,0.099974,0.000000
69.110001,57.931847,-379.066650,-0.001979,0.003913,0.099393,257.693726,13.127544,0.993929,-379.066650,0.100391,0.000000
69.360001,58.517960,-379.066650,-0.001966,0.003927,0.099749,260.300873,13.260360,0.997486,-379.066650,0.100815,0.000000
69.610001,58.996834,-379.066650,-0.001944,0.003939,0.100052,262.431030,13.368874,1.000522,-379.066650,0.101232,0.000000
69.860001,60.606598,-379.066650,-0.001944,0.003964,0.100685,269.591614,13.733652,1.006850,-379.066650,0.101648,0.000000
70.110001,62.148964,-379.111145,-0.001966,0.003985,0.101222,276.452393,14.083156,1.012225,-379.111145,0.102064,0.000000
70.360001,62.533623,-379.066650,-0.001927,0.003997,0.101518,278.163452,14.170321,1.015177,-379.066650,0.102481,0.000000
70.610001,63.213951,-379.111145,-0.001936,0.004012,0.101899,281.189697,14.324486,1.018992,-379.111145,0.102896,0.000000
70.860001,63.620575,-379.200104,-0.001914,0.004024,0.102211,282.998444,14.416628,1.022111,-379.200104,0.103312,0.000000
71.110001,65.197571,-379.155640,-0.001919,0.004048,0.102810,290.013275,14.773981,1.028099,-379.155640,0.103729,0.000000
71.360001,65.922211,-379.111145,-0.001906,0.004060,0.103122,293.236633,14.938187,1.031217,-379.111145,0.104145,0.000000
71.610001,67.522293,-379.244598,-0.001888,0.004084,0.103729,300.354156,15.300770,1.037288,-379.244598,0.104562,0.000000
71.860001,66.853149,-379.244598,-0.001880,0.004075,0.103503,297.377655,15.149140,1.035033,-379.244598,0.103729,0.000000
72.110001,66.142288,-379.200104,-0.001901,0.004074,0.103469,294.215607,14.988057,1.034692,-379.200104,0.103503,0.000000
72.360001,65.538666,-379.155640,-0.001888,0.004073,0.103443,291.530548,14.851274,1.034427,-379.155640,0.103503,0.000000
72.610001,64.990158,-379.289062,-0.001880,0.004072,0.103434,289.090668,14.726980,1.034344,-379.289062,0.103503,0.000000
72.860001,64.540710,-379.244598,-0.001901,0.004072,0.103417,287.091431,14.625134,1.034170,-379.244598,0.103503,0.000000
73.110001,64.147858,-379.244598,-0.001863,0.004072,0.103417,285.343933,14.536113,1.034170,-379.244598,0.103503,0.000000
73.360001,63.779587,-379.289062,-0.001867,0.004071,0.103408,283.705780,14.452661,1.034079,-379.289062,0.103503,0.000000
73.610001,63.461578,-379.333557,-0.001863,0.004071,0.103408,282.291199,14.380599,1.034079,-379.333557,0.103503,0.000000
73.860001,63.187508,-379.333557,-0.001867,0.004071,0.103408,281.072083,14.318494,1.034079,-379.333557,0.103503,0.000000
74.110001,62.930946,-379.289062,-0.001867,0.004071,0.103408,279.930817,14.260357,1.034079,-379.289062,0.103503,0.000000
74.360001,62.693001,-379.378021,-0.001863,0.004071,0.103408,278.872406,14.206437,1.034079,-379.378021,0.103503,0.000000
74.610001,62.486702,-379.378021,-0.001837,0.004071,0.103400,277.954742,14.159689,1.033996,-379.378021,0.103503,0.000000
74.860001,62.285995,-379.422516,-0.001863,0.004071,0.103400,277.061951,14.114208,1.033996,-379.422516,0.103503,0.000000
75.110001,62.099068,-379.333557,-0.001871,0.004071,0.103400,276.230438,14.071850,1.033996,-379.333557,0.103503,0.000000
75.360001,61.927773,-379.422516,-0.001845,0.004071,0.103400,275.468475,14.033034,1.033996,-379.422516,0.103503,0.000000
75.610001,61.771751,-379.422516,-0.001845,0.004071,0.103400,274.774475,13.997679,1.033996,-379.422516,0.103503,0.000000
75.860001,61.629128,-379.422516,-0.001832,0.004071,0.103400,274.140045,13.965360,1.033996,-379.422516,0.103503,0.000000
76.110001,61.476830,-379.422516,-0.001845,0.004071,0.103400,273.462585,13.930848,1.033996,-379.422516,0.103503,0.000000
76.360001,61.347244,-379.466980,-0.001863,0.004071,0.103400,272.886169,13.901484,1.033996,-379.466980,0.103503,0.000000
76.610001,61.225479,-379.466980,-0.001871,0.004071,0.103400,272.344543,13.873893,1.033996,-379.466980,0.103503,0.000000
76.860001,61.111160,-379.466980,-0.001863,0.004071,0.103400,271.836029,13.847987,1.033996,-379.466980,0.103503,0.000000
77.110001,61.010620,-379.555969,-0.001858,0.004071,0.103400,271.388794,13.825204,1.033996,-379.555969,0.103503,0.000000
77.360001,60.896301,-379.422516,-0.001845,0.004071,0.103400,270.880280,13.799298,1.033996,-379.422516,0.103503,0.000000
77.610001,60.790550,-379.511475,-0.001841,0.004071,0.103400,270.409882,13.775335,1.033996,-379.511475,0.103503,0.000000
77.860001,60.700432,-379.511475,-0.001824,0.004071,0.103400,270.009003,13.754914,1.033996,-379.511475,0.103503,0.000000
78.110001,60.615906,-379.511475,-0.001854,0.004071,0.103400,269.633026,13.735761,1.033996,-379.511475,0.103503,0.000000
78.360001,60.519089,-379.555969,-0.001841,0.004071,0.103400,269.202362,13.713821,1.033996,-379.555969,0.103503,0.000000
78.610001,60.435303,-379.644928,-0.001858,0.004071,0.103400,268.829651,13.694836,1.033996,-379.644928,0.103503,0.000000
78.860001,60.354874,-379.555969,-0.001841,0.004071,0.103400,268.471893,13.676610,1.033996,-379.555969,0.103503,0.000000
79.110001,60.276672,-379.644928,-0.001863,0.004071,0.103400,268.124023,13.658889,1.033996,-379.644928,0.103503,0.000000
79.360001,60.191399,-379.555969,-0.001837,0.004071,0.103400,267.744720,13.639565,1.033996,-379.555969,0.103503,0.000000
79.610001,60.136665,-379.600433,-0.001828,0.004071,0.103400,267.501251,13.627163,1.033996,-379.600433,0.103503,0.000000
79.860001,60.061813,-379.644928,-0.001841,0.004071,0.103400,267.168274,13.610202,1.033996,-379.644928,0.103503,0.000000
80.110001,59.986595,-379.733887,-0.001863,0.004071,0.103400,266.833710,13.593157,1.033996,-379.733887,0.103503,0.000000
80.360001,59.932976,-379.689392,-0.001828,0.004071,0.103400,266.595184,13.581006,1.033996,-379.689392,0.103503,0.000000
80.610001,59.866318,-379.689392,-0.001854,0.004071,0.103400,266.298676,13.565902,1.033996,-379.689392,0.103503,0.000000
80.860001,59.799667,-379.689392,-0.001841,0.004071,0.103400,266.002197,13.550797,1.033996,-379.689392,0.103503,0.000000
81.110001,59.738968,-379.644928,-0.001858,0.004071,0.103400,265.732208,13.537044,1.033996,-379.644928,0.103503,0.000000
81.360001,59.691307,-379.778351,-0.001811,0.004071,0.103400,265.520203,13.526243,1.033996,-379.778351,0.103503,0.000000
81.610001,59.641777,-379.778351,-0.001845,0.004071,0.103400,265.299866,13.515020,1.033996,-379.778351,0.103503,0.000000
81.860001,59.590393,-379.778351,-0.001850,0.004071,0.103400,265.071320,13.503376,1.033996,-379.778351,0.103503,0.000000
82.110001,59.528206,-379.867310,-0.001837,0.004071,0.103400,264.794678,13.489285,1.033996,-379.867310,0.103503,0.000000
82.360001,59.481659,-379.822845,-0.001824,0.004071,0.103400,264.587646,13.478736,1.033996,-379.822845,0.103503,0.000000
82.610001,59.434738,-379.867310,-0.001867,0.004071,0.103400,264.378906,13.468104,1.033996,-379.867310,0.103503,0.000000
82.860001,59.380371,-379.867310,-0.001828,0.004071,0.103400,264.137085,13.455784,1.033996,-379.867310,0.103503,0.000000
83.110001,59.341278,-379.867310,-0.001854,0.004071,0.103400,263.963196,13.446925,1.033996,-379.867310,0.103503,0.000000
83.360001,59.289513,-379.911804,-0.001845,0.004071,0.103400,263.732910,13.435195,1.033996,-379.911804,0.103503,0.000000
83.610001,59.239616,-379.867310,-0.001850,0.004071,0.103400,263.510986,13.423889,1.033996,-379.867310,0.103503,0.000000
83.860001,59.201637,-379.911804,-0.001854,0.004071,0.103400,263.342041,13.415282,1.033996,-379.911804,0.103503,0.000000
84.110001,59.163277,-379.956299,-0.001828,0.004071,0.103400,263.171387,13.406590,1.033996,-379.956299,0.103503,0.000000
84.360001,59.121948,-379.956299,-0.001854,0.004071,0.103400,262.987549,13.397224,1.033996,-379.956299,0.103503,0.000000
84.610001,59.085831,-380.000763,-0.001850,0.004071,0.103400,262.826904,13.389041,1.033996,-380.000763,0.103503,0.000000
84.860001,59.017685,-380.000763,-0.001845,0.004071,0.103400,262.523773,13.373598,1.033996,-380.000763,0.103503,0.000000
85.110001,59.001671,-380.000763,-0.001841,0.004071,0.103400,262.452545,13.369969,1.033996,-380.000763,0.103503,0.000000
85.360001,58.964806,-379.956299,-0.001841,0.004071,0.103400,262.288544,13.361616,1.033996,-379.956299,0.103503,0.000000
85.610001,58.916023,-380.089722,-0.001819,0.004071,0.103400,262.071564,13.350562,1.033996,-380.089722,0.103503,0.000000
85.860001,58.885490,-380.000763,-0.001824,0.004071,0.103400,261.935730,13.343643,1.033996,-380.000763,0.103503,0.000000
86.110001,58.841179,-380.089722,-0.001837,0.004071,0.103400,261.738647,13.333602,1.033996,-380.089722,0.103503,0.000000
86.360001,58.809898,-380.089722,-0.001850,0.004071,0.103400,261.599487,13.326513,1.033996,-380.089722,0.103503,0.000000
86.610001,58.779739,-380.089722,-0.001850,0.004071,0.103400,261.465332,13.319680,1.033996,-380.089722,0.103503,0.000000
86.860001,58.740639,-380.134216,-0.001824,0.004071,0.103400,261.291412,13.310820,1.033996,-380.134216,0.103503,0.000000
87.110001,58.709732,-380.134216,-0.001841,0.004071,0.103400,261.153931,13.303815,1.033996,-380.134216,0.103503,0.000000
87.360001,58.675476,-380.089722,-0.001819,0.004071,0.103400,261.001556,13.296053,1.033996,-380.089722,0.103503,0.000000
87.610001,58.647545,-380.178680,-0.001811,0.004071,0.103400,260.877319,13.289723,1.033996,-380.178680,0.103503,0.000000
87.860001,58.609192,-380.134216,-0.001850,0.004071,0.103400,260.706696,13.281033,1.033996,-380.134216,0.103503,0.000000
88.110001,58.578285,-380.223175,-0.001815,0.004071,0.103400,260.569214,13.274029,1.033996,-380.223175,0.103503,0.000000
88.360001,58.549614,-380.178680,-0.001832,0.004071,0.103400,260.441681,13.267532,1.033996,-380.178680,0.103503,0.000000
88.610001,58.522797,-380.223175,-0.001832,0.004071,0.103400,260.322388,13.261456,1.033996,-380.223175,0.103503,0.000000
88.860001,58.495247,-380.223175,-0.001863,0.004071,0.103400,260.199860,13.255212,1.033996,-380.223175,0.103503,0.000000
89.110001,58.462845,-380.267639,-0.001841,0.004071,0.103400,260.055725,13.247869,1.033996,-380.267639,0.103503,0.000000
89.360001,58.439392,-380.267639,-0.001858,0.004071,0.103400,259.951385,13.242556,1.033996,-380.267639,0.103503,0.000000
89.610001,58.395447,-380.312134,-0.001854,0.004071,0.103400,259.755920,13.232598,1.033996,-380.312134,0.103503,0.000000
89.860001,58.374596,-380.312134,-0.001837,0.004071,0.103400,259.663177,13.227873,1.033996,-380.312134,0.103503,0.000000
90.110001,58.345177,-380.356598,-0.001854,0.004071,0.103400,259.532318,13.221207,1.033996,-380.356598,0.103503,0.000000
90.360001,58.326561,-380.312134,-0.001828,0.004071,0.103400,259.449493,13.216988,1.033996,-380.312134,0.103503,0.000000
90.610001,58.299751,-380.401093,-0.001841,0.004071,0.103400,259.330231,13.210912,1.033996,-380.401093,0.103503,0.000000
90.860001,58.266235,-380.356598,-0.001837,0.004071,0.103400,259.181152,13.203319,1.033996,-380.356598,0.103503,0.000000
91.110001,58.236076,-380.312134,-0.001828,0.004071,0.103400,259.046997,13.196484,1.033996,-380.312134,0.103503,0.000000
91.360001,58.224159,-380.356598,-0.001832,0.004071,0.103400,258.993988,13.193783,1.033996,-380.356598,0.103503,0.000000
91.610001,58.205170,-380.445587,-0.001828,0.004071,0.103400,258.909515,13.189480,1.033996,-380.445587,0.103503,0.000000
91.860001,58.177986,-380.445587,-0.001837,0.004071,0.103400,258.788605,13.183320,1.033996,-380.445587,0.103503,0.000000
92.110001,58.154152,-380.401093,-0.001837,0.004071,0.103400,258.682587,13.177919,1.033996,-380.401093,0.103503,0.000000
92.360001,58.124359,-380.401093,-0.001824,0.004071,0.103400,258.550049,13.171168,1.033996,-380.401093,0.103503,0.000000
92.610001,58.087494,-380.445587,-0.001824,0.004071,0.103400,258.386078,13.162814,1.033996,-380.445587,0.103503,0.000000
92.860001,58.074089,-380.445587,-0.001832,0.004071,0.103400,258.326447,13.159777,1.033996,-380.445587,0.103503,0.000000
93.110001,58.053612,-380.534546,-0.001850,0.004071,0.103400,258.235352,13.155136,1.033996,-380.534546,0.103503,0.000000
93.360008,58.018234,-380.534546,-0.001837,0.004071,0.103400,258.078003,13.147120,1.033996,-380.534546,0.103503,0.000000
93.610008,58.011162,-380.534546,-0.001824,0.004071,0.103400,258.046539,13.145516,1.033996,-380.534546,0.103503,0.000000
93.860008,57.988815,-380.579010,-0.001807,0.004071,0.103400,257.947144,13.140453,1.033996,-380.579010,0.103503,0.000000
94.110008,57.964989,-380.534546,-0.001854,0.004071,0.103400,257.841156,13.135054,1.033996,-380.534546,0.103503,0.000000
94.360008,57.940781,-380.579010,-0.001845,0.004071,0.103400,257.733459,13.129569,1.033996,-380.579010,0.103503,0.000000
94.610008,57.927376,-380.623505,-0.001841,0.004071,0.103400,257.673828,13.126531,1.033996,-380.623505,0.103503,0.000000
94.860008,57.894234,-380.623505,-0.001832,0.004071,0.103400,257.526428,13.119020,1.033996,-380.623505,0.103503,0.000000
95.110008,57.885300,-380.667969,-0.001854,0.004071,0.103400,257.486664,13.116996,1.033996,-380.667969,0.103503,0.000000
95.360008,57.858116,-380.623505,-0.001871,0.004071,0.103400,257.365753,13.110836,1.033996,-380.623505,0.103503,0.000000
95.610008,57.844711,-380.667969,-0.001841,0.004071,0.103400,257.306122,13.107799,1.033996,-380.667969,0.103503,0.000000
95.860008,57.829811,-380.667969,-0.001854,0.004071,0.103400,257.239838,13.104423,1.033996,-380.667969,0.103503,0.000000
96.110008,57.804863,-380.712463,-0.001841,0.004071,0.103400,257.128876,13.098769,1.033996,-380.712463,0.103503,0.000000
96.360008,57.785133,-380.712463,-0.001832,0.004071,0.103400,257.041107,13.094298,1.033996,-380.712463,0.103503,0.000000
96.610008,57.771721,-380.667969,-0.001824,0.004071,0.103400,256.981445,13.091259,1.033996,-380.667969,0.103503,0.000000
96.860008,57.741188,-380.667969,-0.001819,0.004071,0.103400,256.845642,13.084340,1.033996,-380.667969,0.103503,0.000000
97.110008,57.730392,-380.756927,-0.001815,0.004071,0.103400,256.797607,13.081894,1.033996,-380.756927,0.103503,0.000000
97.360008,57.722946,-380.756927,-0.001841,0.004071,0.103400,256.764496,13.080207,1.033996,-380.756927,0.103503,0.000000
97.610008,57.699860,-380.756927,-0.001837,0.004071,0.103400,256.661804,13.074975,1.033996,-380.756927,0.103503,0.000000
97.860008,57.684593,-380.801422,-0.001815,0.004071,0.103400,256.593872,13.071516,1.033996,-380.801422,0.103503,0.000000
98.110008,57.662247,-380.801422,-0.001863,0.004071,0.103400,256.494476,13.066452,1.033996,-380.801422,0.103503,0.000000
98.360008,57.654053,-380.801422,-0.001854,0.004071,0.103400,256.458038,13.064595,1.033996,-380.801422,0.103503,0.000000
98.610008,57.623146,-380.845917,-0.001854,0.004071,0.103400,256.320557,13.057591,1.033996,-380.845917,0.103503,0.000000
98.860008,57.625755,-380.890381,-0.001845,0.004071,0.103400,256.332153,13.058183,1.033996,-380.890381,0.103503,0.000000
99.110008,57.601547,-380.845917,-0.001845,0.004071,0.103400,256.224487,13.052697,1.033996,-380.845917,0.103503,0.000000
99.360008,57.587029,-380.934875,-0.001819,0.004071,0.103400,256.159882,13.049407,1.033996,-380.934875,0.103503,0.000000
99.610008,57.566177,-380.890381,-0.001841,0.004071,0.103400,256.067139,13.044682,1.033996,-380.890381,0.103503,0.000000
99.860008,57.549789,-380.890381,-0.001819,0.004071,0.103400,255.994247,13.040969,1.033996,-380.890381,0.103503,0.000000
100.110008,57.553886,-380.934875,-0.001841,0.004071,0.103400,256.012482,13.041897,1.033996,-380.934875,0.103503,0.000000
100.360008,57.530426,-380.979340,-0.001858,0.004071,0.103400,255.908112,13.036581,1.033996,-380.979340,0.103503,0.000000
100.610008,57.506226,-380.979340,-0.001819,0.004071,0.103400,255.800461,13.031097,1.033996,-380.979340,0.103503,0.000000
100.860008,57.502869,-380.979340,-0.001845,0.004071,0.103400,255.785538,13.030336,1.033996,-380.979340,0.103503,0.000000
101.110008,57.473457,-380.934875,-0.001811,0.004071,0.103400,255.654709,13.023672,1.033996,-380.934875,0.103503,0.000000
101.360008,57.451859,-380.979340,-0.001811,0.004071,0.103400,255.558624,13.018778,1.033996,-380.979340,0.103503,0.000000
101.610008,57.450371,-381.023834,-0.001828,0.004071,0.103400,255.552017,13.018440,1.033996,-381.023834,0.103503,0.000000
101.860008,57.431747,-381.068298,-0.001832,0.004071,0.103400,255.469177,13.014220,1.033996,-381.068298,0.103503,0.000000
102.100006,57.418716,-381.112793,-0.001850,0.004071,0.103400,255.411209,13.011267,1.033996,-381.112793,0.103503,0.000000