File: Data/compression 14/AutoNoHeating-10-14-1-240726_07262024_161126.csv
Time (sec),S:Load (lbs),S:HL1 (DIM),S:LVDT (in),S:Position (in),Ch:Position (mm),Ch:Load (N),Ch:Stress (MPa),Ch:Strain (mm/mm),Ch:HL1 (DIM),Set Point (),Cycles ()
0.110000,0.017128,-227.609024,-0.007812,-0.007693,-0.195395,0.076189,0.003881,-1.953952,-227.609024,-0.195204,0.000000
0.360000,0.029785,-227.609024,-0.007817,-0.007693,-0.195395,0.132491,0.006749,-1.953952,-227.609024,-0.195204,0.000000
0.610000,0.026810,-227.653503,-0.007834,-0.007589,-0.192750,0.119255,0.006075,-1.927496,-227.653503,-0.191891,0.000000
0.860000,0.015640,-227.653503,-0.007756,-0.007436,-0.188865,0.069571,0.003544,-1.888647,-227.653503,-0.187729,0.000000
1.110000,-0.011917,-227.653503,-0.007606,-0.007271,-0.184685,-0.053010,-0.002700,-1.846847,-227.653503,-0.183548,0.000000
1.360000,0.026436,-227.697983,-0.007381,-0.007106,-0.180487,0.117593,0.005990,-1.804873,-227.697983,-0.179386,0.000000
1.610000,0.037605,-227.786957,-0.007274,-0.006948,-0.176481,0.167277,0.008521,-1.764806,-227.786957,-0.175223,0.000000
1.860000,0.045799,-227.742462,-0.007080,-0.006775,-0.172075,0.203725,0.010378,-1.720749,-227.742462,-0.171061,0.000000
2.110000,0.026436,-227.786957,-0.006920,-0.006614,-0.168008,0.117593,0.005990,-1.680077,-227.786957,-0.166898,0.000000
2.360000,0.048035,-227.831436,-0.006726,-0.006456,-0.163993,0.213669,0.010885,-1.639927,-227.831436,-0.162735,0.000000
2.610000,0.058830,-227.831436,-0.006579,-0.006291,-0.159795,0.261690,0.013331,-1.597952,-227.831436,-0.158573,0.000000
2.860000,0.025696,-227.875916,-0.006394,-0.006124,-0.155546,0.114301,0.005823,-1.555456,-227.875916,-0.154393,0.000000
3.110000,0.033142,-227.920395,-0.006243,-0.005960,-0.151392,0.147423,0.007510,-1.513920,-227.920395,-0.150230,0.000000
3.360000,0.033142,-227.920395,-0.006092,-0.005797,-0.147238,0.147423,0.007510,-1.472377,-227.920395,-0.146067,0.000000
3.610000,0.013779,-227.920395,-0.005868,-0.005631,-0.143023,0.061291,0.003122,-1.430229,-227.920395,-0.141905,0.000000
3.860000,-0.004471,-227.920395,-0.005739,-0.005465,-0.138817,-0.019887,-0.001013,-1.388171,-227.920395,-0.137741,0.000000
4.110000,0.048782,-227.964874,-0.005545,-0.005311,-0.134897,0.216995,0.011054,-1.348974,-227.964874,-0.133579,0.000000
4.360000,0.070007,-228.053833,-0.005376,-0.005137,-0.130483,0.311408,0.015864,-1.304827,-228.053833,-0.129416,0.000000
4.610000,0.037979,-228.053833,-0.005217,-0.004977,-0.126425,0.168940,0.008606,-1.264246,-228.053833,-0.125254,0.000000
4.860000,0.060326,-228.053833,-0.005010,-0.004811,-0.122201,0.268342,0.013670,-1.222014,-228.053833,-0.121073,0.000000
5.110000,0.044312,-228.098312,-0.004872,-0.004650,-0.118117,0.197107,0.010041,-1.181167,-228.098312,-0.116911,0.000000
5.360000,0.023087,-228.098312,-0.004700,-0.004483,-0.113859,0.102694,0.005231,-1.138587,-228.098312,-0.112748,0.000000
5.610000,0.088997,-228.098312,-0.004510,-0.004320,-0.109739,0.395878,0.020167,-1.097392,-228.098312,-0.108586,0.000000
5.860000,0.696335,-228.187286,-0.004363,-0.004165,-0.105802,3.097452,0.157792,-1.058022,-228.187286,-0.104493,0.000000
6.110000,0.607712,-228.231766,-0.004329,-0.000000,-0.000000,2.703237,0.137709,-0.000000,-228.231766,0.000226,0.000000
6.360000,0.583878,-228.231766,-0.004350,-0.000000,-0.000000,2.597217,0.132309,-0.000000,-228.231766,0.000226,0.000000
6.610000,0.612183,-228.187286,-0.004333,-0.000000,-0.000000,2.723124,0.138723,-0.000000,-228.187286,0.000607,0.000000
6.860000,0.603989,-228.276245,-0.004333,0.000000,0.000008,2.686676,0.136866,0.000083,-228.276245,0.001023,0.000000
7.110000,0.605850,-228.320724,-0.004359,0.000000,0.000008,2.694956,0.137288,0.000083,-228.320724,0.001440,0.000000
7.360000,0.577545,-228.320724,-0.004324,0.000001,0.000017,2.569049,0.130874,0.000174,-228.320724,0.001855,0.000000
7.610000,1.058655,-228.365204,-0.004273,0.000060,0.001535,4.709132,0.239895,0.015352,-228.365204,0.002281,0.000000
7.860001,1.121956,-228.320724,-0.004312,0.000071,0.001812,4.990709,0.254239,0.018122,-228.320724,0.002697,0.000000
8.110001,1.270531,-228.365204,-0.004260,0.000089,0.002254,5.651603,0.287906,0.022543,-228.365204,0.003113,0.000000
8.360001,1.425438,-228.409683,-0.004260,0.000105,0.002671,6.340664,0.323009,0.026706,-228.409683,0.003530,0.000000
8.610001,1.610138,-228.454163,-0.004273,0.000122,0.003087,7.162251,0.364862,0.030870,-228.454163,0.003945,0.000000
8.860001,1.690567,-228.454163,-0.004234,0.000132,0.003347,7.520018,0.383088,0.033474,-228.454163,0.004362,0.000000
9.110001,1.879364,-228.454163,-0.004247,0.000147,0.003737,8.359829,0.425870,0.037372,-228.454163,0.004778,0.000000
9.360001,2.115448,-228.498642,-0.004186,0.000173,0.004397,9.409983,0.479367,0.043965,-228.498642,0.005194,0.000000
9.610001,2.218224,-228.498642,-0.004186,0.000186,0.004735,9.867151,0.502657,0.047349,-228.498642,0.005611,0.000000
9.860001,2.334778,-228.543121,-0.004182,0.000200,0.005091,10.385611,0.529068,0.050907,-228.543121,0.006027,0.000000
10.110001,2.557083,-228.498642,-0.004161,0.000219,0.005558,11.374474,0.579443,0.055585,-228.498642,0.006443,0.000000
10.360001,2.773056,-228.543121,-0.004178,0.000239,0.006070,12.335169,0.628383,0.060702,-228.543121,0.006860,0.000000
10.610001,2.895195,-228.632095,-0.004122,0.000251,0.006383,12.878470,0.656061,0.063828,-228.632095,0.007276,0.000000
10.860001,2.910088,-228.632095,-0.004105,0.000259,0.006574,12.944716,0.659435,0.065736,-228.632095,0.007692,0.000000
11.110001,3.276505,-228.721054,-0.004100,0.000283,0.007181,14.574620,0.742467,0.071807,-228.721054,0.008109,0.000000
11.360001,3.483917,-228.721054,-0.004087,0.000302,0.007675,15.497238,0.789467,0.076750,-228.721054,0.008524,0.000000
11.610001,3.607544,-228.721054,-0.004083,0.000316,0.008022,16.047157,0.817481,0.080217,-228.721054,0.008941,0.000000
11.860001,3.794106,-228.721054,-0.004074,0.000332,0.008429,16.877024,0.859757,0.084290,-228.721054,0.009357,0.000000
12.110001,3.945282,-228.810013,-0.004053,0.000348,0.008845,17.549490,0.894014,0.088453,-228.810013,0.009773,0.000000
12.360001,4.200729,-228.721054,-0.004023,0.000368,0.009349,18.685778,0.951899,0.093487,-228.721054,0.010190,0.000000
12.610001,4.283401,-228.765533,-0.004014,0.000380,0.009661,19.053522,0.970633,0.096606,-228.765533,0.010614,0.000000
12.860001,4.196266,-228.898972,-0.003988,0.000387,0.009834,18.665924,0.950888,0.098339,-228.898972,0.011031,0.000000
13.110001,4.720940,-228.854492,-0.004010,0.000410,0.010406,20.999788,1.069780,0.104062,-228.854492,0.011447,0.000000
13.360001,4.945847,-228.898972,-0.003967,0.000435,0.011048,22.000225,1.120745,0.110481,-228.898972,0.011863,0.000000
13.610001,5.011757,-228.854492,-0.003954,0.000447,0.011352,22.293407,1.135680,0.113517,-228.854492,0.012280,0.000000
13.860001,5.079163,-228.943451,-0.003915,0.000461,0.011716,22.593245,1.150955,0.117158,-228.943451,0.012696,0.000000
14.110001,5.238533,-228.898972,-0.003936,0.000475,0.012054,23.302158,1.187069,0.120541,-228.898972,0.013112,0.000000
14.360001,5.642189,-228.943451,-0.003893,0.000500,0.012696,25.097710,1.278538,0.126961,-228.943451,0.013529,0.000000
14.610001,5.567337,-229.032410,-0.003889,0.000508,0.012904,24.764751,1.261577,0.129042,-229.032410,0.013945,0.000000
14.860001,5.699905,-228.987930,-0.003880,0.000523,0.013286,25.354446,1.291617,0.132857,-228.987930,0.014361,0.000000
15.110001,6.149361,-229.032410,-0.003872,0.000546,0.013858,27.353722,1.393465,0.138580,-229.032410,0.014778,0.000000
15.360001,6.302032,-229.121384,-0.003833,0.000565,0.014352,28.032841,1.428061,0.143523,-229.121384,0.015193,0.000000
15.610001,6.277824,-229.076904,-0.003811,0.000577,0.014648,27.925158,1.422575,0.146475,-229.076904,0.015610,0.000000
15.860001,6.358261,-229.121384,-0.003803,0.000590,0.014994,28.282957,1.440803,0.149942,-229.121384,0.016026,0.000000
16.110001,6.566040,-229.121384,-0.003816,0.000608,0.015445,29.207205,1.487886,0.154454,-229.121384,0.016442,0.000000
16.360001,6.780159,-229.210342,-0.003798,0.000623,0.015835,30.159653,1.536406,0.158352,-229.210342,0.016859,0.000000
16.610001,6.915703,-229.121384,-0.003764,0.000637,0.016182,30.762583,1.567121,0.161819,-229.121384,0.017275,0.000000
16.860001,7.124603,-229.210342,-0.003747,0.000654,0.016616,31.691818,1.614458,0.166157,-229.210342,0.017691,0.000000
17.110001,7.392708,-229.210342,-0.003738,0.000674,0.017119,32.884407,1.675212,0.171191,-229.210342,0.018108,0.000000
17.360001,7.425476,-229.254822,-0.003708,0.000692,0.017587,33.030167,1.682637,0.175869,-229.254822,0.018524,0.000000
17.610001,7.400902,-229.254822,-0.003691,0.000707,0.017960,32.920856,1.677068,0.179601,-229.254822,0.018940,0.000000
17.860001,7.699547,-229.299301,-0.003673,0.000726,0.018429,34.249294,1.744742,0.184287,-229.299301,0.019365,0.000000
18.110001,7.788544,-229.343781,-0.003660,0.000741,0.018818,34.645172,1.764909,0.188185,-229.343781,0.019781,0.000000
18.360001,7.916267,-229.388260,-0.003652,0.000757,0.019227,35.213318,1.793852,0.192265,-229.388260,0.020198,0.000000
18.610001,7.778862,-229.388260,-0.003613,0.000771,0.019573,34.602108,1.762715,0.195732,-229.388260,0.020614,0.000000
18.860001,8.323265,-229.388260,-0.003613,0.000792,0.020120,37.023731,1.886079,0.201197,-229.388260,0.021030,0.000000
19.110001,8.483757,-229.388260,-0.003587,0.000812,0.020622,37.737637,1.922447,0.206224,-229.388260,0.021446,0.000000
19.360001,8.344124,-229.477234,-0.003570,0.000823,0.020900,37.116516,1.890805,0.209002,-229.477234,0.021862,0.000000
19.610001,8.578712,-229.521713,-0.003531,0.000841,0.021368,38.160019,1.943964,0.213680,-229.521713,0.022279,0.000000
19.860001,8.636063,-229.477234,-0.003531,0.000856,0.021733,38.415127,1.956960,0.217329,-229.477234,0.022695,0.000000
20.110001,8.884064,-229.521713,-0.003527,0.000874,0.022201,39.518288,2.013158,0.222007,-229.521713,0.023111,0.000000
20.360001,8.868797,-229.521713,-0.003527,0.000888,0.022547,39.450382,2.009698,0.225474,-229.521713,0.023528,0.000000
20.610001,8.822250,-229.610672,-0.003479,0.000897,0.022790,39.243328,1.999151,0.227904,-229.610672,0.023944,0.000000
20.860001,9.313782,-229.566193,-0.003479,0.000923,0.023441,41.429771,2.110533,0.234406,-229.566193,0.024360,0.000000
21.110001,9.329788,-229.655151,-0.003449,0.000941,0.023892,41.500969,2.114160,0.238918,-229.655151,0.024777,0.000000
21.360001,9.387138,-229.655151,-0.003423,0.000954,0.024238,41.756077,2.127156,0.242385,-229.655151,0.025193,0.000000
21.610001,9.422508,-229.655151,-0.003410,0.000969,0.024612,41.913410,2.135171,0.246117,-229.655151,0.025609,0.000000
21.860001,9.603859,-229.699631,-0.003385,0.000986,0.025054,42.720097,2.176265,0.250537,-229.699631,0.026025,0.000000
22.110001,9.840683,-229.699631,-0.003372,0.001004,0.025497,43.773544,2.229931,0.254966,-229.699631,0.026441,0.000000
22.360001,9.854836,-229.744110,-0.003393,0.001017,0.025843,43.836498,2.233138,0.258433,-229.744110,0.026858,0.000000
22.610001,9.931175,-229.788589,-0.003346,0.001033,0.026233,44.176075,2.250437,0.262331,-229.788589,0.027274,0.000000
22.860001,10.153481,-229.833069,-0.003363,0.001050,0.026667,45.164936,2.300812,0.266669,-229.833069,0.027699,0.000000
23.110001,10.463669,-229.788589,-0.003311,0.001071,0.027213,46.544724,2.371101,0.272134,-229.788589,0.028115,0.000000
23.360001,10.385468,-229.788589,-0.003307,0.001086,0.027578,46.196865,2.353380,0.275775,-229.788589,0.028531,0.000000
23.610001,10.443932,-229.877548,-0.003277,0.001101,0.027976,46.456928,2.366629,0.279764,-229.877548,0.028948,0.000000
23.860001,10.659531,-229.922043,-0.003281,0.001120,0.028445,47.415962,2.415484,0.284450,-229.922043,0.029364,0.000000
24.110001,10.958176,-229.877548,-0.003234,0.001139,0.028922,48.744400,2.483158,0.289219,-229.877548,0.029780,0.000000
24.360001,10.701614,-229.877548,-0.003229,0.001148,0.029165,47.603157,2.425020,0.291649,-229.877548,0.030197,0.000000
24.610001,11.203194,-229.966522,-0.003195,0.001173,0.029789,49.834293,2.538680,0.297894,-229.966522,0.030613,0.000000
24.860001,11.230011,-229.966522,-0.003186,0.001189,0.030197,49.953583,2.544757,0.301966,-229.966522,0.031029,0.000000
25.110001,11.157768,-229.966522,-0.003147,0.001203,0.030561,49.632233,2.528386,0.305608,-229.966522,0.031446,0.000000
25.360001,11.107498,-230.055481,-0.003152,0.001216,0.030882,49.408619,2.516995,0.308817,-230.055481,0.031862,0.000000
25.610001,11.220695,-230.099960,-0.003113,0.001229,0.031220,49.912148,2.542646,0.312201,-230.099960,0.032278,0.000000
25.860001,11.663452,-230.055481,-0.003130,0.001250,0.031758,51.881626,2.642976,0.317575,-230.055481,0.032694,0.000000
26.110001,11.739044,-230.055481,-0.003126,0.001266,0.032156,52.217876,2.660105,0.321565,-230.055481,0.033110,0.000000
26.360001,11.529396,-230.099960,-0.003078,0.001275,0.032374,51.285316,2.612598,0.323737,-230.099960,0.033527,0.000000
26.610001,11.836227,-230.144440,-0.003078,0.001291,0.032798,52.650169,2.682127,0.327984,-230.144440,0.033943,0.000000
26.860001,12.360161,-230.188919,-0.003040,0.001320,0.033518,54.980740,2.800853,0.335183,-230.188919,0.034359,0.000000
27.110001,12.152374,-230.233398,-0.002997,0.001332,0.033830,54.056461,2.753767,0.338301,-230.233398,0.034776,0.000000
27.360001,12.218658,-230.188919,-0.003009,0.001350,0.034299,54.351307,2.768788,0.342987,-230.188919,0.035192,0.000000
27.610001,12.328506,-230.277878,-0.002975,0.001366,0.034698,54.839935,2.793679,0.346976,-230.277878,0.035608,0.000000
27.860001,12.371330,-230.233398,-0.002958,0.001381,0.035070,55.030426,2.803384,0.350701,-230.233398,0.036033,0.000000
28.110001,12.347122,-230.277878,-0.002906,0.001394,0.035400,54.922741,2.797898,0.354001,-230.277878,0.036449,0.000000
28.360001,12.484161,-230.322357,-0.002928,0.001407,0.035738,55.532322,2.828951,0.357385,-230.322357,0.036866,0.000000
28.610001,13.084419,-230.322357,-0.002906,0.001432,0.036380,58.202404,2.964972,0.363797,-230.322357,0.037282,0.000000
28.860001,13.250504,-230.366852,-0.002863,0.001454,0.036926,58.941185,3.002607,0.369262,-230.366852,0.037698,0.000000
29.110001,12.912018,-230.411331,-0.002893,0.001465,0.037212,57.435524,2.925905,0.372123,-230.411331,0.038115,0.000000
29.360001,12.952232,-230.366852,-0.002854,0.001480,0.037594,57.614407,2.935018,0.375938,-230.366852,0.038531,0.000000
29.610001,13.108253,-230.455811,-0.002802,0.001498,0.038053,58.308422,2.970373,0.380533,-230.455811,0.038947,0.000000
29.860001,13.340240,-230.411331,-0.002802,0.001516,0.038496,59.340355,3.022942,0.384962,-230.411331,0.039363,0.000000
30.110001,13.184959,-230.455811,-0.002794,0.001527,0.038791,58.649628,2.987754,0.387906,-230.455811,0.039779,0.000000
30.360001,13.248268,-230.544769,-0.002746,0.001541,0.039138,58.931240,3.002100,0.391381,-230.544769,0.040196,0.000000
30.610001,13.962479,-230.500290,-0.002742,0.001567,0.039814,62.108208,3.163943,0.398141,-230.500290,0.040612,0.000000
30.860001,13.747620,-230.500290,-0.002716,0.001581,0.040170,61.152466,3.115255,0.401698,-230.500290,0.041028,0.000000
31.110001,13.659363,-230.544769,-0.002703,0.001594,0.040491,60.759880,3.095256,0.404908,-230.544769,0.041445,0.000000
31.360001,13.878693,-230.678207,-0.002690,0.001613,0.040976,61.735508,3.144957,0.409760,-230.678207,0.041861,0.000000
31.610001,13.934547,-230.633728,-0.002647,0.001629,0.041375,61.983963,3.157614,0.413750,-230.633728,0.042277,0.000000
31.860001,14.045517,-230.678207,-0.002626,0.001647,0.041826,62.477581,3.182760,0.418261,-230.678207,0.042694,0.000000
32.110001,13.790810,-230.722687,-0.002634,0.001656,0.042052,61.344585,3.125042,0.420517,-230.722687,0.043110,0.000000
32.360001,13.919655,-230.722687,-0.002613,0.001671,0.042433,61.917717,3.154239,0.424332,-230.722687,0.043526,0.000000
32.610001,14.595512,-230.767181,-0.002591,0.001698,0.043118,64.924080,3.307390,0.431183,-230.767181,0.043942,0.000000
32.860001,14.260750,-230.722687,-0.002570,0.001708,0.043387,63.434982,3.231532,0.433870,-230.722687,0.044358,0.000000
33.110001,14.215691,-230.856140,-0.002531,0.001722,0.043751,63.234550,3.221322,0.437511,-230.856140,0.044784,0.000000
33.360001,14.481934,-230.811661,-0.002501,0.001742,0.044245,64.418861,3.281653,0.442454,-230.811661,0.045200,0.000000
33.610001,14.767174,-230.767181,-0.002522,0.001763,0.044775,65.687668,3.346289,0.447746,-230.767181,0.045616,0.000000
33.860001,14.625671,-230.856140,-0.002492,0.001776,0.045121,65.058235,3.314224,0.451212,-230.856140,0.046032,0.000000
34.110001,14.225372,-230.856140,-0.002471,0.001783,0.045278,63.277615,3.223516,0.452779,-230.856140,0.046448,0.000000
34.360001,14.552315,-230.945099,-0.002440,0.001801,0.045737,64.731926,3.297602,0.457374,-230.945099,0.046865,0.000000
34.610001,15.319031,-230.900620,-0.002406,0.001830,0.046475,68.142448,3.471342,0.464747,-230.900620,0.047281,0.000000
34.860001,15.038261,-230.945099,-0.002384,0.001843,0.046812,66.893524,3.407719,0.468123,-230.945099,0.047697,0.000000
35.110001,14.792496,-230.989578,-0.002371,0.001856,0.047142,65.800308,3.352027,0.471424,-230.989578,0.048114,0.000000
35.360001,14.839417,-230.989578,-0.002358,0.001870,0.047506,66.009018,3.362660,0.475065,-230.989578,0.048530,0.000000
35.610001,15.238968,-231.034058,-0.002328,0.001891,0.048044,67.786316,3.453199,0.480439,-231.034058,0.048946,0.000000
35.860001,15.028954,-231.034058,-0.002302,0.001903,0.048347,66.852127,3.405610,0.483475,-231.034058,0.049363,0.000000
36.110001,14.876648,-231.034058,-0.002272,0.001913,0.048599,66.174637,3.371097,0.485988,-231.034058,0.049779,0.000000
36.360001,14.993576,-231.078537,-0.002276,0.001929,0.048998,66.694756,3.397593,0.489977,-231.078537,0.050195,0.000000
36.610001,15.794548,-231.078537,-0.002246,0.001958,0.049727,70.257660,3.579096,0.497267,-231.078537,0.050611,0.000000
36.860001,15.479523,-231.167496,-0.002216,0.001971,0.050065,68.856354,3.507710,0.500651,-231.167496,0.051027,0.000000
37.110001,15.380096,-231.211990,-0.002199,0.001987,0.050472,68.414085,3.485180,0.504723,-231.211990,0.051444,0.000000
37.360001,15.183861,-231.123016,-0.002190,0.001998,0.050758,67.541183,3.440712,0.507585,-231.123016,0.051860,0.000000
37.610001,15.734222,-231.211990,-0.002182,0.002021,0.051322,69.989319,3.565426,0.513224,-231.211990,0.052276,0.000000
37.860001,15.659752,-231.256470,-0.002151,0.002033,0.051634,69.658058,3.548551,0.516343,-231.256470,0.052693,0.000000
38.110001,15.655655,-231.256470,-0.002134,0.002048,0.052007,69.639832,3.547622,0.520075,-231.256470,0.053117,0.000000
38.360001,16.133034,-231.300949,-0.002100,0.002069,0.052554,71.763321,3.655798,0.525540,-231.300949,0.053534,0.000000
38.610001,16.350128,-231.345428,-0.002095,0.002088,0.053039,72.729004,3.704992,0.530392,-231.345428,0.053950,0.000000
38.860001,15.935677,-231.345428,-0.002070,0.002099,0.053308,70.885429,3.611076,0.533080,-231.345428,0.054366,0.000000
39.110001,16.313637,-231.345428,-0.002048,0.002121,0.053864,72.566681,3.696723,0.538636,-231.345428,0.054783,0.000000
39.360001,16.204529,-231.389908,-0.002039,0.002136,0.054253,72.081345,3.671999,0.542534,-231.389908,0.055199,0.000000
39.610001,16.423111,-231.389908,-0.002022,0.002154,0.054713,73.053650,3.721530,0.547129,-231.389908,0.055615,0.000000
39.860001,16.203415,-231.434387,-0.001988,0.002166,0.055016,72.076385,3.671746,0.550165,-231.434387,0.056032,0.000000
40.110001,16.579140,-231.434387,-0.001975,0.002185,0.055502,73.747696,3.756887,0.555025,-231.434387,0.056448,0.000000
40.360001,16.795486,-231.478867,-0.001936,0.002204,0.055979,74.710052,3.805912,0.559794,-231.478867,0.056864,0.000000
40.610001,16.592545,-231.523346,-0.001919,0.002218,0.056326,73.807327,3.759924,0.563260,-231.523346,0.057280,0.000000
40.860001,16.696434,-231.523346,-0.001910,0.002236,0.056795,74.269447,3.783466,0.567946,-231.523346,0.057696,0.000000
41.110001,16.770912,-231.523346,-0.001910,0.002251,0.057184,74.600746,3.800343,0.571845,-231.523346,0.058113,0.000000
41.360001,16.879272,-231.612305,-0.001837,0.002269,0.057627,75.082756,3.824898,0.576273,-231.612305,0.058529,0.000000
41.610001,16.898262,-231.656799,-0.001858,0.002283,0.057982,75.167221,3.829201,0.579823,-231.656799,0.058945,0.000000
41.860001,16.634995,-231.612305,-0.001828,0.002293,0.058251,73.996155,3.769544,0.582510,-231.612305,0.059362,0.000000
42.110001,17.418465,-231.656799,-0.001819,0.002319,0.058893,77.481201,3.947080,0.588930,-231.656799,0.059778,0.000000
42.360001,17.449745,-231.656799,-0.001776,0.002335,0.059318,77.620346,3.954169,0.593184,-231.656799,0.060194,0.000000
42.610001,17.471718,-231.745758,-0.001772,0.002352,0.059751,77.718086,3.959148,0.597514,-231.745758,0.060611,0.000000
42.860001,17.386070,-231.701279,-0.001742,0.002367,0.060116,77.337105,3.939740,0.601162,-231.701279,0.061027,0.000000
43.110001,17.132858,-231.745758,-0.001750,0.002379,0.060428,76.210762,3.882361,0.604281,-231.745758,0.061452,0.000000
43.360001,17.444901,-231.745758,-0.001725,0.002397,0.060879,77.598793,3.953071,0.608793,-231.745758,0.061868,0.000000
43.610001,17.500389,-231.879196,-0.001703,0.002411,0.061243,77.845619,3.965645,0.612434,-231.879196,0.062284,0.000000
43.860001,17.603165,-231.834717,-0.001673,0.002425,0.061607,78.302788,3.988934,0.616075,-231.834717,0.062701,0.000000
44.110001,17.987076,-231.879196,-0.001651,0.002447,0.062145,80.010506,4.075930,0.621449,-231.879196,0.063116,0.000000
44.360001,18.412331,-231.879196,-0.001634,0.002469,0.062701,81.902138,4.172294,0.627006,-231.879196,0.063532,0.000000
44.610001,17.993408,-231.923676,-0.001621,0.002479,0.062978,80.038673,4.077364,0.629776,-231.923676,0.063949,0.000000
44.860001,18.160233,-231.923676,-0.001595,0.002498,0.063455,80.780746,4.115168,0.634545,-231.923676,0.064365,0.000000
45.110001,17.993782,-231.923676,-0.001591,0.002511,0.063775,80.040337,4.077449,0.637755,-231.923676,0.064782,0.000000
45.360001,18.236198,-231.968155,-0.001561,0.002531,0.064296,81.118660,4.132381,0.642963,-231.968155,0.065198,0.000000
45.610001,18.385887,-232.012634,-0.001522,0.002545,0.064643,81.784508,4.166301,0.646430,-232.012634,0.065614,0.000000
45.860001,18.614899,-232.057129,-0.001535,0.002564,0.065120,82.803207,4.218196,0.651199,-232.057129,0.066031,0.000000
46.110001,19.165268,-232.012634,-0.001500,0.002586,0.065684,85.251373,4.342912,0.656838,-232.012634,0.066447,0.000000
46.360001,18.706871,-232.101608,-0.001479,0.002597,0.065970,83.212318,4.239038,0.659700,-232.101608,0.066863,0.000000
46.610001,18.694214,-232.057129,-0.001487,0.002612,0.066342,83.156013,4.236169,0.663424,-232.057129,0.067280,0.000000
46.860001,18.527763,-232.146088,-0.001449,0.002624,0.066655,82.415611,4.198451,0.666550,-232.146088,0.067695,0.000000
47.110001,19.311607,-232.190567,-0.001418,0.002646,0.067218,85.902321,4.376072,0.672182,-232.190567,0.068111,0.000000
47.360001,19.242722,-232.190567,-0.001410,0.002660,0.067566,85.595901,4.360463,0.675657,-232.190567,0.068528,0.000000
47.610001,19.037170,-232.190567,-0.001401,0.002672,0.067860,84.681564,4.313885,0.678601,-232.190567,0.068944,0.000000
47.860001,19.220001,-232.235046,-0.001375,0.002688,0.068268,85.494835,4.355314,0.682682,-232.235046,0.069360,0.000000
48.110001,20.178490,-232.279526,-0.001345,0.002715,0.068953,89.758408,4.572511,0.689532,-232.279526,0.069777,0.000000
48.360001,19.897720,-232.279526,-0.001311,0.002730,0.069335,88.509483,4.508888,0.693347,-232.279526,0.070201,0.000000
48.610001,19.649719,-232.279526,-0.001306,0.002743,0.069673,87.406319,4.452690,0.696731,-232.279526,0.070618,0.000000
48.860001,19.792709,-232.324005,-0.001242,0.002760,0.070106,88.042366,4.485092,0.701061,-232.324005,0.071034,0.000000
49.110001,19.843727,-232.368484,-0.001259,0.002775,0.070497,88.269310,4.496653,0.704967,-232.368484,0.071450,0.000000
49.360001,19.906288,-232.368484,-0.001237,0.002790,0.070870,88.547592,4.510829,0.708699,-232.368484,0.071867,0.000000
49.610001,19.633713,-232.412964,-0.001255,0.002801,0.071147,87.335114,4.449063,0.711469,-232.412964,0.072283,0.000000
49.860001,20.186310,-232.457443,-0.001220,0.002823,0.071693,89.793190,4.574283,0.716935,-232.457443,0.072700,0.000000
50.110001,21.115005,-232.457443,-0.001181,0.002849,0.072361,93.924232,4.784729,0.723611,-232.457443,0.073116,0.000000
50.360001,20.721779,-232.501938,-0.001143,0.002862,0.072700,92.175079,4.695622,0.726995,-232.501938,0.073532,0.000000
50.610001,20.508041,-232.457443,-0.001121,0.002877,0.073081,91.224327,4.647189,0.730810,-232.457443,0.073949,0.000000
50.860001,20.513626,-232.590897,-0.001134,0.002892,0.073463,91.249168,4.648454,0.734625,-232.590897,0.074364,0.000000
51.110001,20.936638,-232.590897,-0.001091,0.002911,0.073939,93.130814,4.744310,0.739394,-232.590897,0.074780,0.000000
51.360001,20.823067,-232.546417,-0.001069,0.002924,0.074260,92.625626,4.718575,0.742604,-232.546417,0.075197,0.000000
51.610001,20.642464,-232.590897,-0.001035,0.002936,0.074564,91.822266,4.677649,0.745639,-232.590897,0.075613,0.000000
51.860001,21.576378,-232.590897,-0.001043,0.002961,0.075206,95.976524,4.889277,0.752059,-232.590897,0.076029,0.000000
52.110001,21.621437,-232.679855,-0.000996,0.002977,0.075622,96.176956,4.899487,0.756222,-232.679855,0.076446,0.000000
52.360001,21.240128,-232.679855,-0.000979,0.002989,0.075917,94.480804,4.813081,0.759167,-232.679855,0.076862,0.000000
52.610001,21.477699,-232.724335,-0.000961,0.003006,0.076359,95.537575,4.866916,0.763587,-232.724335,0.077278,0.000000
52.860001,21.704102,-232.724335,-0.000940,0.003024,0.076810,96.544662,4.918220,0.768099,-232.724335,0.077695,0.000000
53.110004,21.912254,-232.724335,-0.000931,0.003042,0.077269,97.470573,4.965388,0.772694,-232.724335,0.078111,0.000000
53.360004,21.558876,-232.724335,-0.000897,0.003053,0.077547,95.898666,4.885311,0.775472,-232.724335,0.078536,0.000000
53.610004,21.476952,-232.813293,-0.000888,0.003066,0.077868,95.534248,4.866747,0.778682,-232.813293,0.078952,0.000000
53.860004,22.527412,-232.857773,-0.000845,0.003090,0.078493,100.206932,5.104784,0.784927,-232.857773,0.079368,0.000000
54.110004,22.392616,-232.902252,-0.000854,0.003105,0.078865,99.607330,5.074239,0.788651,-232.902252,0.079785,0.000000
54.360004,22.190048,-232.857773,-0.000811,0.003119,0.079213,98.706261,5.028337,0.792126,-232.857773,0.080201,0.000000
54.610004,22.587364,-232.946747,-0.000772,0.003137,0.079689,100.473618,5.118370,0.796894,-232.946747,0.080618,0.000000
54.860004,22.801483,-232.902252,-0.000772,0.003156,0.080157,101.426064,5.166890,0.801573,-232.902252,0.081033,0.000000
55.110004,22.865158,-232.902252,-0.000776,0.003172,0.080556,101.709305,5.181319,0.805562,-232.902252,0.081449,0.000000
55.360004,22.442146,-233.035706,-0.000746,0.003181,0.080799,99.827652,5.085463,0.807992,-233.035706,0.081866,0.000000
55.610004,22.563164,-232.991226,-0.000707,0.003194,0.081138,100.365967,5.112886,0.811375,-232.991226,0.082282,0.000000
55.860004,23.963654,-233.080185,-0.000686,0.003224,0.081883,106.595657,5.430242,0.818832,-233.080185,0.082698,0.000000
56.110004,23.721245,-233.124664,-0.000655,0.003238,0.082247,105.517365,5.375311,0.822473,-233.124664,0.083115,0.000000
56.360004,23.294128,-233.124664,-0.000655,0.003250,0.082560,103.617455,5.278525,0.825599,-233.124664,0.083531,0.000000
56.610004,23.484039,-233.124664,-0.000591,0.003266,0.082967,104.462227,5.321559,0.829672,-233.124664,0.083947,0.000000
56.860004,24.093987,-233.124664,-0.000582,0.003285,0.083427,107.175407,5.459775,0.834267,-233.124664,0.084364,0.000000
57.110004,24.347946,-233.169144,-0.000578,0.003301,0.083835,108.305077,5.517323,0.838347,-233.169144,0.084780,0.000000
57.360004,23.948761,-233.169144,-0.000560,0.003310,0.084086,106.529411,5.426867,0.840860,-233.169144,0.085196,0.000000
57.610004,24.430237,-233.213623,-0.000535,0.003324,0.084433,108.671120,5.535971,0.844327,-233.213623,0.085612,0.000000
57.860004,25.757744,-233.213623,-0.000543,0.003353,0.085162,114.576164,5.836788,0.851617,-233.213623,0.086028,0.000000
58.110004,25.822540,-233.258102,-0.000517,0.003367,0.085534,114.864395,5.851471,0.855341,-233.258102,0.086445,0.000000
58.360004,25.886589,-233.302582,-0.000492,0.003383,0.085916,115.149300,5.865985,0.859156,-233.302582,0.086870,0.000000
58.610004,25.896645,-233.258102,-0.000470,0.003394,0.086219,115.194031,5.868264,0.862191,-233.258102,0.087286,0.000000
58.860004,26.402321,-233.347076,-0.000440,0.003413,0.086679,117.443390,5.982852,0.866794,-233.347076,0.087702,0.000000
59.110004,26.661865,-233.347076,-0.000444,0.003428,0.087069,118.597900,6.041665,0.870692,-233.347076,0.088118,0.000000
59.360004,26.465256,-233.302582,-0.000431,0.003435,0.087243,117.723335,5.997113,0.872426,-233.302582,0.088535,0.000000
59.610004,27.894051,-233.391556,-0.000388,0.003464,0.087988,124.078934,6.320882,0.879882,-233.391556,0.088951,0.000000
59.860004,28.712524,-233.436035,-0.000384,0.003484,0.088492,127.719688,6.506351,0.884916,-233.436035,0.089367,0.000000
60.110004,28.609375,-233.480515,-0.000392,0.003496,0.088786,127.260857,6.482977,0.887861,-233.480515,0.089784,0.000000
60.360004,29.128464,-233.524994,-0.000345,0.003515,0.089280,129.569885,6.600604,0.892804,-233.524994,0.090200,0.000000
60.610004,29.540680,-233.524994,-0.000354,0.003529,0.089628,131.403503,6.694014,0.896278,-233.524994,0.090616,0.000000
60.860004,30.337181,-233.524994,-0.000332,0.003550,0.090165,134.946518,6.874504,0.901653,-233.524994,0.091033,0.000000
61.110004,30.411659,-233.569473,-0.000315,0.003561,0.090451,135.277817,6.891381,0.904514,-233.569473,0.091449,0.000000
61.360004,30.942657,-233.524994,-0.000315,0.003578,0.090885,137.639816,7.011706,0.908852,-233.524994,0.091865,0.000000
61.610004,31.958862,-233.569473,-0.000289,0.003597,0.091362,142.160126,7.241982,0.913621,-233.569473,0.092281,0.000000
61.860004,32.670845,-233.613953,-0.000276,0.003615,0.091813,145.327179,7.403319,0.918132,-233.613953,0.092697,0.000000
62.110004,32.727814,-233.613953,-0.000229,0.003626,0.092099,145.580582,7.416229,0.920994,-233.613953,0.093114,0.000000
62.360004,33.453568,-233.658432,-0.000254,0.003645,0.092585,148.808899,7.580687,0.925846,-233.658432,0.093530,0.000000
62.610004,33.981224,-233.658432,-0.000233,0.003661,0.092993,151.156036,7.700255,0.929926,-233.658432,0.093946,0.000000
62.860004,34.899117,-233.747391,-0.000216,0.003678,0.093426,155.239029,7.908253,0.934263,-233.747391,0.094363,0.000000
63.110004,35.280052,-233.791885,-0.000190,0.003689,0.093712,156.933517,7.994574,0.937125,-233.791885,0.094779,0.000000
63.360004,36.260139,-233.747391,-0.000211,0.003708,0.094189,161.293152,8.216665,0.941894,-233.747391,0.095204,0.000000
63.610004,37.566795,-233.791885,-0.000207,0.003730,0.094753,167.105453,8.512757,0.947526,-233.791885,0.095620,0.000000
63.860004,38.090721,-233.836365,-0.000168,0.003745,0.095135,169.435989,8.631480,0.951348,-233.836365,0.096036,0.000000
64.110001,38.648911,-233.880844,-0.000168,0.003761,0.095525,171.918945,8.757968,0.955247,-233.880844,0.096453,0.000000
64.360001,39.023140,-233.925323,-0.000160,0.003774,0.095854,173.583603,8.842770,0.958540,-233.925323,0.096869,0.000000
64.610001,40.205795,-233.880844,-0.000164,0.003793,0.096348,178.844315,9.110764,0.963483,-233.880844,0.097285,0.000000
64.860001,40.589714,-233.969803,-0.000142,0.003802,0.096583,180.552063,9.197761,0.965829,-233.969803,0.097702,0.000000
65.110001,41.211205,-233.925323,-0.000125,0.003819,0.097008,183.316589,9.338593,0.970076,-233.925323,0.098118,0.000000
65.360001,42.437798,-233.969803,-0.000099,0.003839,0.097511,188.772751,9.616543,0.975110,-233.969803,0.098534,0.000000
65.610001,43.974953,-233.969803,-0.000121,0.003861,0.098066,195.610352,9.964867,0.980659,-233.969803,0.098950,0.000000
65.860001,44.529411,-234.058762,-0.000095,0.003874,0.098404,198.076721,10.090508,0.984042,-234.058762,0.099366,0.000000
66.110001,45.243622,-234.103241,-0.000099,0.003889,0.098768,201.253677,10.252351,0.987683,-234.103241,0.099783,0.000000
66.360001,46.040504,-234.103241,-0.000052,0.003905,0.099185,204.798386,10.432927,0.991847,-234.103241,0.100199,0.000000
66.610001,47.106232,-234.103241,-0.000069,0.003921,0.099592,209.538986,10.674425,0.995919,-234.103241,0.100615,0.000000
66.860001,48.339905,-234.103241,-0.000052,0.003940,0.100086,215.026642,10.953979,1.000862,-234.103241,0.101032,0.000000
67.110001,48.772598,-234.103241,-0.000022,0.003954,0.100425,216.951355,11.052029,1.004246,-234.103241,0.101448,0.000000
67.360001,50.703720,-234.147720,-0.000034,0.003978,0.101049,225.541412,11.489627,1.010491,-234.147720,0.101864,0.000000
67.610001,51.352020,-234.192200,-0.000034,0.003992,0.101405,228.425201,11.636534,1.014049,-234.192200,0.102281,0.000000
67.860001,52.148155,-234.192200,-0.000030,0.004005,0.101734,231.966583,11.816941,1.017342,-234.192200,0.102697,0.000000
68.110001,52.770393,-234.236694,-0.000034,0.004020,0.102107,234.734436,11.957942,1.021066,-234.236694,0.103113,0.000000
68.360001,53.670784,-234.281174,-0.000017,0.004035,0.102497,238.739578,12.161973,1.024972,-234.281174,0.103529,0.000000
68.610001,55.355774,-234.281174,0.000017,0.004055,0.102992,246.234787,12.543797,1.029915,-234.281174,0.103954,0.000000
68.860001,56.090462,-234.325653,0.000009,0.004067,0.103295,249.502838,12.710280,1.032951,-234.325653,0.104371,0.000000
69.110001,56.430069,-234.325653,-0.000004,0.004075,0.103512,251.013489,12.787236,1.035116,-234.325653,0.104787,0.000000
69.360001,59.312599,-234.370132,-0.000004,0.004109,0.104371,263.835632,13.440427,1.043707,-234.370132,0.105203,0.000000
69.610001,60.208160,-234.370132,0.000026,0.004122,0.104691,267.819275,13.643364,1.046910,-234.370132,0.105619,0.000000
69.860001,61.002426,-234.414612,0.000052,0.004134,0.105012,271.352356,13.823347,1.050119,-234.414612,0.106035,0.000000
70.110001,62.377602,-234.414612,0.000039,0.004155,0.105541,277.469421,14.134967,1.055410,-234.414612,0.106452,0.000000
70.360001,63.522278,-234.414612,0.000047,0.004169,0.105897,282.561218,14.394354,1.058968,-234.414612,0.106868,0.000000
70.610001,64.255096,-234.459091,0.000069,0.004180,0.106183,285.820953,14.560412,1.061830,-234.459091,0.107284,0.000000
70.860001,65.238907,-234.503571,0.000039,0.004194,0.106530,290.197144,14.783348,1.065297,-234.503571,0.107701,0.000000
71.110001,66.306503,-234.548050,0.000056,0.004209,0.106911,294.946045,15.025269,1.069112,-234.548050,0.108117,0.000000
71.360001,67.501450,-234.592529,0.000082,0.004216,0.107076,300.261444,15.296047,1.070762,-234.592529,0.107328,0.000000
71.610001,67.000977,-234.503571,0.000078,0.004215,0.107068,298.035217,15.182638,1.070679,-234.503571,0.107076,0.000000
71.860001,66.567535,-234.592529,0.000082,0.004214,0.107041,296.107178,15.084418,1.070414,-234.592529,0.107076,0.000000
72.110001,66.196274,-234.637024,0.000069,0.004214,0.107033,294.455719,15.000290,1.070331,-234.637024,0.107076,0.000000
72.360001,65.868225,-234.637024,0.000078,0.004214,0.107024,292.996490,14.925953,1.070240,-234.637024,0.107076,0.000000
72.610001,65.586334,-234.681503,0.000086,0.004214,0.107024,291.742584,14.862076,1.070240,-234.681503,0.107076,0.000000
72.860001,65.337967,-234.725983,0.000086,0.004214,0.107024,290.637787,14.805795,1.070240,-234.725983,0.107076,0.000000
73.110001,65.114166,-234.725983,0.000091,0.004214,0.107024,289.642273,14.755081,1.070240,-234.725983,0.107076,0.000000
73.360001,64.926117,-234.770462,0.000073,0.004214,0.107024,288.805786,14.712468,1.070240,-234.770462,0.107076,0.000000
73.610001,64.753342,-234.814941,0.000073,0.004214,0.107024,288.037262,14.673317,1.070240,-234.814941,0.107076,0.000000
73.860001,64.593582,-234.725983,0.000073,0.004214,0.107024,287.326599,14.637115,1.070240,-234.725983,0.107076,0.000000
74.110001,64.451340,-234.859421,0.000091,0.004214,0.107024,286.693878,14.604882,1.070240,-234.859421,0.107076,0.000000
74.360001,64.295685,-234.859421,0.000073,0.004214,0.107024,286.001495,14.569611,1.070240,-234.859421,0.107076,0.000000
74.610001,64.172440,-234.859421,0.000095,0.004214,0.107024,285.453278,14.541683,1.070240,-234.859421,0.107076,0.000000
74.860001,64.058868,-234.859421,0.000095,0.004214,0.107024,284.948090,14.515947,1.070240,-234.859421,0.107076,0.000000
75.110001,63.946411,-234.948380,0.000078,0.004214,0.107024,284.447845,14.490463,1.070240,-234.948380,0.107076,0.000000
75.360001,63.834686,-234.992859,0.000086,0.004214,0.107024,283.950867,14.465147,1.070240,-234.992859,0.107076,0.000000
75.610001,63.744949,-234.948380,0.000073,0.004214,0.107024,283.551697,14.444812,1.070240,-234.948380,0.107076,0.000000
75.860001,63.647766,-234.992859,0.000078,0.004214,0.107024,283.119415,14.422791,1.070240,-234.992859,0.107076,0.000000
76.110001,63.573288,-235.037338,0.000103,0.004214,0.107024,282.788116,14.405912,1.070240,-235.037338,0.107076,0.000000
76.360001,63.484665,-235.081833,0.000099,0.004214,0.107024,282.393890,14.385830,1.070240,-235.081833,0.107076,0.000000
76.610001,63.400879,-235.081833,0.000086,0.004214,0.107024,282.021210,14.366845,1.070240,-235.081833,0.107076,0.000000
76.860001,63.321564,-235.081833,0.000108,0.004214,0.107024,281.668396,14.348871,1.070240,-235.081833,0.107076,0.000000
77.110001,63.250443,-235.081833,0.000082,0.004214,0.107024,281.352020,14.332755,1.070240,-235.081833,0.107076,0.000000
77.360001,63.181549,-235.126312,0.000112,0.004214,0.107024,281.045563,14.317144,1.070240,-235.126312,0.107076,0.000000
77.610001,63.125694,-235.126312,0.000112,0.004214,0.107024,280.797119,14.304487,1.070240,-235.126312,0.107076,0.000000
77.860001,63.045639,-235.170792,0.000103,0.004214,0.107024,280.441010,14.286346,1.070240,-235.170792,0.107076,0.000000
78.110001,62.999832,-235.215271,0.000091,0.004214,0.107024,280.237244,14.275967,1.070240,-235.215271,0.107076,0.000000
78.360001,62.945099,-235.259750,0.000095,0.004214,0.107024,279.993774,14.263563,1.070240,-235.259750,0.107076,0.000000
78.610001,62.874718,-235.304230,0.000086,0.004214,0.107024,279.680725,14.247614,1.070240,-235.304230,0.107076,0.000000
78.860001,62.820724,-235.259750,0.000112,0.004214,0.107024,279.440552,14.235379,1.070240,-235.259750,0.107076,0.000000
79.110001,62.763374,-235.259750,0.000099,0.004214,0.107024,279.185425,14.222383,1.070240,-235.259750,0.107076,0.000000
79.360001,62.723907,-235.348709,0.000103,0.004214,0.107024,279.009888,14.213440,1.070240,-235.348709,0.107076,0.000000
79.610001,62.674751,-235.304230,0.000095,0.004214,0.107024,278.791229,14.202301,1.070240,-235.304230,0.107076,0.000000
79.860001,62.628952,-235.437668,0.000125,0.004214,0.107024,278.587494,14.191924,1.070240,-235.437668,0.107076,0.000000
80.110001,62.592461,-235.437668,0.000155,0.004214,0.107024,278.425171,14.183654,1.070240,-235.437668,0.107076,0.000000
80.360001,62.545540,-235.393188,0.000091,0.004214,0.107024,278.216461,14.173021,1.070240,-235.393188,0.107076,0.000000
80.610001,62.500854,-235.482162,0.000103,0.004214,0.107024,278.017700,14.162896,1.070240,-235.482162,0.107076,0.000000
80.860001,62.446114,-235.482162,0.000108,0.004214,0.107024,277.774200,14.150492,1.070240,-235.482162,0.107076,0.000000
81.110001,62.409248,-235.482162,0.000060,0.004214,0.107024,277.610199,14.142138,1.070240,-235.482162,0.107076,0.000000
81.360001,62.368660,-235.482162,0.000095,0.004214,0.107024,277.429657,14.132940,1.070240,-235.482162,0.107076,0.000000
81.610001,62.330307,-235.526642,0.000099,0.004214,0.107024,277.259064,14.124249,1.070240,-235.526642,0.107076,0.000000
81.860001,62.297539,-235.571121,0.000103,0.004214,0.107024,277.113281,14.116824,1.070240,-235.571121,0.107076,0.000000
82.110001,62.255836,-235.571121,0.000099,0.004214,0.107024,276.927795,14.107374,1.070240,-235.571121,0.107076,0.000000
82.360001,62.223434,-235.571121,0.000091,0.004214,0.107024,276.783661,14.100032,1.070240,-235.571121,0.107076,0.000000
82.610001,62.187691,-235.615601,0.000112,0.004214,0.107024,276.624664,14.091932,1.070240,-235.615601,0.107076,0.000000
82.860001,62.148216,-235.660080,0.000095,0.004214,0.107024,276.449066,14.082987,1.070240,-235.660080,0.107076,0.000000
83.110001,62.129227,-235.660080,0.000129,0.004214,0.107024,276.364594,14.078684,1.070240,-235.660080,0.107076,0.000000
83.360001,62.087891,-235.660080,0.000103,0.004214,0.107024,276.180725,14.069317,1.070240,-235.660080,0.107076,0.000000
83.610001,62.065178,-235.704559,0.000095,0.004214,0.107024,276.079712,14.064171,1.070240,-235.704559,0.107076,0.000000
83.860001,62.032410,-235.749039,0.000116,0.004214,0.107024,275.933929,14.056746,1.070240,-235.749039,0.107076,0.000000
84.110001,62.002251,-235.749039,0.000091,0.004214,0.107024,275.799774,14.049911,1.070240,-235.749039,0.107076,0.000000
84.360001,61.969109,-235.793518,0.000108,0.004214,0.107024,275.652374,14.042400,1.070240,-235.793518,0.107076,0.000000
84.610001,61.930008,-235.793518,0.000112,0.004214,0.107024,275.478424,14.033541,1.070240,-235.793518,0.107076,0.000000
84.860001,61.901711,-235.749039,0.000091,0.004214,0.107024,275.352570,14.027127,1.070240,-235.749039,0.107076,0.000000
85.110001,61.885696,-235.837997,0.000091,0.004214,0.107024,275.281311,14.023499,1.070240,-235.837997,0.107076,0.000000
85.360001,61.852180,-235.882477,0.000121,0.004214,0.107024,275.132233,14.015904,1.070240,-235.882477,0.107076,0.000000
85.610001,61.831329,-235.882477,0.000099,0.004214,0.107024,275.039490,14.011180,1.070240,-235.882477,0.107076,0.000000
85.860001,61.798561,-235.882477,0.000121,0.004214,0.107024,274.893738,14.003755,1.070240,-235.882477,0.107076,0.000000
86.110001,61.768028,-235.926971,0.000091,0.004214,0.107024,274.757904,13.996835,1.070240,-235.926971,0.107076,0.000000
86.360001,61.746803,-235.971451,0.000112,0.004214,0.107024,274.663513,13.992026,1.070240,-235.971451,0.107076,0.000000
86.610001,61.720734,-235.971451,0.000112,0.004214,0.107024,274.547546,13.986118,1.070240,-235.971451,0.107076,0.000000
86.860001,61.699135,-236.015930,0.000091,0.004214,0.107024,274.451447,13.981224,1.070240,-236.015930,0.107076,0.000000
87.110001,61.675308,-236.060410,0.000103,0.004214,0.107024,274.345459,13.975824,1.070240,-236.060410,0.107076,0.000000
87.360001,61.645142,-236.060410,0.000099,0.004214,0.107024,274.211273,13.968988,1.070240,-236.060410,0.107076,0.000000
87.610001,61.620941,-236.104889,0.000134,0.004214,0.107024,274.103638,13.963506,1.070240,-236.104889,0.107076,0.000000
87.860001,61.606415,-236.149368,0.000095,0.004214,0.107024,274.039032,13.960214,1.070240,-236.149368,0.107076,0.000000
88.110001,61.585190,-236.193848,0.000108,0.004214,0.107024,273.944611,13.955403,1.070240,-236.193848,0.107076,0.000000
88.360001,61.554657,-236.149368,0.000108,0.004214,0.107024,273.808777,13.948485,1.070240,-236.149368,0.107076,0.000000
88.610001,61.520027,-236.193848,0.000078,0.004214,0.107024,273.654755,13.940638,1.070240,-236.193848,0.107076,0.000000
88.860001,61.509224,-236.282806,0.000099,0.004214,0.107024,273.606689,13.938190,1.070240,-236.282806,0.107076,0.000000
89.110001,61.478691,-236.238327,0.000086,0.004214,0.107024,273.470886,13.931271,1.070240,-236.238327,0.107076,0.000000
89.360001,61.470497,-236.238327,0.000116,0.004214,0.107024,273.434418,13.929414,1.070240,-236.238327,0.107076,0.000000
89.610001,61.444061,-236.282806,0.000142,0.004214,0.107024,273.316833,13.923423,1.070240,-236.282806,0.107076,0.000000
89.860001,61.417625,-236.238327,0.000095,0.004214,0.107024,273.199249,13.917434,1.070240,-236.238327,0.107076,0.000000
90.110001,61.393417,-236.371780,0.000103,0.004214,0.107024,273.091553,13.911947,1.070240,-236.371780,0.107076,0.000000
90.360001,61.374054,-236.371780,0.000121,0.004214,0.107024,273.005432,13.907559,1.070240,-236.371780,0.107076,0.000000
90.610001,61.376289,-236.371780,0.000082,0.004214,0.107024,273.015381,13.908066,1.070240,-236.371780,0.107076,0.000000
90.860001,61.342407,-236.371780,0.000073,0.004214,0.107024,272.864655,13.900389,1.070240,-236.371780,0.107076,0.000000
91.110001,61.320061,-236.460739,0.000099,0.004214,0.107024,272.765259,13.895325,1.070240,-236.460739,0.107076,0.000000
91.360001,61.299210,-236.416260,0.000108,0.004214,0.107024,272.672516,13.890599,1.070240,-236.416260,0.107076,0.000000
91.610001,61.285805,-236.416260,0.000108,0.004214,0.107024,272.612885,13.887562,1.070240,-236.416260,0.107076,0.000000
91.860001,61.267929,-236.505219,0.000108,0.004214,0.107024,272.533356,13.883511,1.070240,-236.505219,0.107076,0.000000
92.110001,61.242233,-236.505219,0.000121,0.004214,0.107024,272.419067,13.877688,1.070240,-236.505219,0.107076,0.000000
92.360001,61.223244,-236.549698,0.000108,0.004214,0.107024,272.334595,13.873384,1.070240,-236.549698,0.107076,0.000000
92.610001,61.218407,-236.549698,0.000116,0.004214,0.107024,272.313080,13.872289,1.070240,-236.549698,0.107076,0.000000
92.860001,61.197548,-236.594177,0.000103,0.004214,0.107024,272.220276,13.867563,1.070240,-236.594177,0.107076,0.000000
93.110001,61.189362,-236.549698,0.000103,0.004214,0.107024,272.183868,13.865707,1.070240,-236.549698,0.107076,0.000000
93.360008,61.155472,-236.638657,0.000099,0.004214,0.107024,272.033112,13.858027,1.070240,-236.638657,0.107076,0.000000
93.610008,61.143188,-236.683136,0.000091,0.004214,0.107024,271.978485,13.855245,1.070240,-236.683136,0.107076,0.000000
93.860008,61.133507,-236.638657,0.000108,0.004214,0.107024,271.935425,13.853051,1.070240,-236.638657,0.107076,0.000000
94.110008,61.111534,-236.683136,0.000103,0.004214,0.107024,271.837677,13.848071,1.070240,-236.683136,0.107076,0.000000
94.360008,61.097008,-236.727615,0.000095,0.004214,0.107024,271.773071,13.844780,1.070240,-236.727615,0.107076,0.000000
94.610008,61.079506,-236.772110,0.000086,0.004214,0.107024,271.695221,13.840815,1.070240,-236.772110,0.107076,0.000000
94.860008,61.066475,-236.772110,0.000095,0.004214,0.107024,271.637238,13.837861,1.070240,-236.772110,0.107076,0.000000
95.110008,61.054558,-236.861069,0.000103,0.004214,0.107024,271.584229,13.835160,1.070240,-236.861069,0.107076,0.000000
95.360008,61.027374,-236.861069,0.000108,0.004214,0.107024,271.463318,13.829000,1.070240,-236.861069,0.107076,0.000000
95.610008,61.021416,-236.861069,0.000129,0.004214,0.107024,271.436829,13.827651,1.070240,-236.861069,0.107076,0.000000
95.860008,61.001686,-236.905548,0.000099,0.004214,0.107024,271.349060,13.823179,1.070240,-236.905548,0.107076,0.000000
96.110008,60.999451,-236.905548,0.000091,0.004214,0.107024,271.339111,13.822673,1.070240,-236.905548,0.107076,0.000000
96.360008,60.961838,-236.905548,0.000108,0.004214,0.107024,271.171783,13.814150,1.070240,-236.905548,0.107076,0.000000
96.610008,60.953644,-236.950027,0.000108,0.004214,0.107024,271.135345,13.812294,1.070240,-236.950027,0.107076,0.000000
96.860008,60.947693,-236.994507,0.000138,0.004214,0.107024,271.108887,13.810945,1.070240,-236.994507,0.107076,0.000000
97.110008,60.923485,-237.038986,0.000121,0.004214,0.107024,271.001190,13.805459,1.070240,-237.038986,0.107076,0.000000
97.360008,60.905235,-236.994507,0.000125,0.004214,0.107024,270.920013,13.801323,1.070240,-236.994507,0.107076,0.000000
97.610008,60.900772,-237.083466,0.000095,0.004214,0.107024,270.900177,13.800312,1.070240,-237.083466,0.107076,0.000000
97.860008,60.879921,-237.083466,0.000103,0.004214,0.107024,270.807404,13.795588,1.070240,-237.083466,0.107076,0.000000
98.110008,60.874702,-237.083466,0.000134,0.004214,0.107024,270.784210,13.794404,1.070240,-237.083466,0.107076,0.000000
98.360008,60.853851,-237.172424,0.000112,0.004214,0.107024,270.691437,13.789680,1.070240,-237.172424,0.107076,0.000000
98.610008,60.848640,-237.172424,0.000112,0.004214,0.107024,270.668274,13.788499,1.070240,-237.172424,0.107076,0.000000
98.860008,60.829277,-237.216919,0.000121,0.004214,0.107024,270.582153,13.784111,1.070240,-237.216919,0.107076,0.000000
99.110008,60.818100,-237.172424,0.000095,0.004214,0.107024,270.532410,13.781579,1.070240,-237.172424,0.107076,0.000000
99.360008,60.799858,-237.305878,0.000108,0.004214,0.107024,270.451263,13.777445,1.070240,-237.305878,0.107076,0.000000
99.610008,60.795761,-237.261398,0.000108,0.004214,0.107024,270.433044,13.776516,1.070240,-237.261398,0.107076,0.000000
99.860008,60.773788,-237.305878,0.000121,0.004214,0.107024,270.335327,13.771537,1.070240,-237.305878,0.107076,0.000000
100.110008,60.760384,-237.261398,0.000108,0.004214,0.107024,270.275696,13.768500,1.070240,-237.261398,0.107076,0.000000
100.360008,60.760757,-237.261398,0.000078,0.004214,0.107024,270.277344,13.768584,1.070240,-237.261398,0.107076,0.000000
100.610008,60.735435,-237.350357,0.000108,0.004214,0.107024,270.164703,13.762846,1.070240,-237.350357,0.107076,0.000000
100.860008,60.725014,-237.305878,0.000121,0.004214,0.107024,270.118347,13.760485,1.070240,-237.305878,0.107076,0.000000
101.110008,60.726875,-237.394836,0.000091,0.004214,0.107024,270.126617,13.760907,1.070240,-237.394836,0.107076,0.000000
101.360008,60.704155,-237.439316,0.000129,0.004214,0.107024,270.025574,13.755757,1.070240,-237.439316,0.107076,0.000000
101.610008,60.694107,-237.483795,0.000086,0.004214,0.107024,269.980865,13.753482,1.070240,-237.483795,0.107076,0.000000
101.700005,60.687775,-237.528275,0.000095,0.004214,0.107024,269.952698,13.752047,1.070240,-237.528275,0.107076,0.000000