File: Data/compression 14/AutoNoHeating-16-14-4-240726_07262024_171343.csv
Time (sec),S:Load (lbs),S:HL1 (DIM),S:LVDT (in),S:Position (in),Ch:Position (mm),Ch:Load (N),Ch:Stress (MPa),Ch:Strain (mm/mm),Ch:HL1 (DIM),Set Point (),Cycles ()
0.010000,-0.012665,-474.967590,-0.007640,-0.003289,-0.083540,-0.056336,-0.002870,-0.835402,-474.967590,-0.083358,0.000000
0.230000,-0.008194,-475.056549,-0.007631,-0.003289,-0.083540,-0.036449,-0.001857,-0.835402,-475.056549,-0.083358,0.000000
0.450000,-0.005585,-475.056549,-0.007618,-0.003218,-0.081736,-0.024842,-0.001266,-0.817363,-475.056549,-0.081138,0.000000
0.670000,-0.027184,-475.101044,-0.007610,-0.003088,-0.078432,-0.120918,-0.006160,-0.784321,-475.101044,-0.077461,0.000000
0.890000,-0.037987,-475.012085,-0.007446,-0.002943,-0.074746,-0.168974,-0.008608,-0.747464,-475.012085,-0.073801,0.000000
1.110000,-0.024948,-475.056549,-0.007304,-0.002801,-0.071156,-0.110975,-0.005653,-0.711560,-475.056549,-0.070142,0.000000
1.330000,-0.025322,-475.056549,-0.007127,-0.002667,-0.067731,-0.112638,-0.005738,-0.677307,-475.056549,-0.066464,0.000000
1.550000,-0.016754,-475.101044,-0.006998,-0.002517,-0.063941,-0.074526,-0.003797,-0.639405,-475.101044,-0.062804,0.000000
1.770000,-0.008194,-475.145508,-0.006838,-0.002369,-0.060168,-0.036449,-0.001857,-0.601685,-475.145508,-0.059145,0.000000
1.990000,-0.009682,-475.012085,-0.006679,-0.002230,-0.056639,-0.043066,-0.002194,-0.566387,-475.012085,-0.055485,0.000000
2.210000,0.017128,-475.101044,-0.006506,-0.002087,-0.053005,0.076189,0.003881,-0.530052,-475.101044,-0.051808,0.000000
2.430000,-0.021225,-475.101044,-0.006403,-0.001941,-0.049302,-0.094413,-0.004810,-0.493020,-475.101044,-0.048148,0.000000
2.650000,-0.016754,-475.145508,-0.006204,-0.001790,-0.045478,-0.074526,-0.003797,-0.454778,-475.145508,-0.044489,0.000000
2.870000,-0.066284,-475.145508,-0.006092,-0.001649,-0.041896,-0.294847,-0.015020,-0.418958,-475.145508,-0.040812,0.000000
3.090000,-0.070755,-475.145508,-0.005950,-0.001506,-0.038262,-0.314734,-0.016033,-0.382623,-475.145508,-0.037152,0.000000
3.310000,-0.024574,-475.101044,-0.005782,-0.001360,-0.034542,-0.109312,-0.005569,-0.345417,-475.101044,-0.033493,0.000000
3.530000,-0.008568,-475.190002,-0.005631,-0.001214,-0.030830,-0.038112,-0.001941,-0.308302,-475.190002,-0.029815,0.000000
3.750000,0.029419,-475.190002,-0.005484,-0.001078,-0.027370,0.130862,0.006666,-0.273701,-475.190002,-0.026156,0.000000
3.970000,0.014519,-475.234467,-0.005329,-0.000938,-0.023814,0.064583,0.003290,-0.238138,-475.234467,-0.022496,0.000000
4.190000,-0.005959,-475.190002,-0.005161,-0.000785,-0.019946,-0.026505,-0.001350,-0.199464,-475.190002,-0.018819,0.000000
4.410000,-0.030533,-475.190002,-0.004997,-0.000638,-0.016200,-0.135817,-0.006919,-0.162001,-475.190002,-0.015159,0.000000
4.630000,-0.024574,-475.234467,-0.004863,-0.000495,-0.012583,-0.109312,-0.005569,-0.125833,-475.234467,-0.011499,0.000000
4.850000,-0.049156,-475.278961,-0.004730,-0.000356,-0.009054,-0.218658,-0.011139,-0.090542,-475.278961,-0.007823,0.000000
5.070000,-0.018250,-475.278961,-0.004544,-0.000203,-0.005151,-0.081178,-0.004135,-0.051512,-475.278961,-0.004163,0.000000
5.290000,-0.000374,-475.190002,-0.004424,-0.000070,-0.001769,-0.001663,-0.000085,-0.017691,-475.190002,-0.000503,0.000000
5.510000,0.320236,-475.234467,-0.004268,0.000081,0.002047,1.424482,0.072567,0.020469,-475.234467,0.003174,0.000000
5.730000,0.664680,-475.278961,-0.004221,-0.000002,-0.000061,2.956646,0.150619,-0.000606,-475.278961,0.000121,0.000000
5.950000,0.644577,-475.323456,-0.004217,-0.000003,-0.000070,2.867222,0.146063,-0.000696,-475.323456,0.000121,0.000000
6.170000,0.578293,-475.323456,-0.004204,-0.000003,-0.000070,2.572375,0.131043,-0.000696,-475.323456,0.000243,0.000000
6.390000,0.633034,-475.278961,-0.004221,-0.000003,-0.000070,2.815875,0.143448,-0.000696,-475.278961,0.000607,0.000000
6.610000,0.599518,-475.278961,-0.004230,-0.000002,-0.000061,2.666789,0.135853,-0.000606,-475.278961,0.000971,0.000000
6.830000,0.736176,-475.323456,-0.004221,0.000015,0.000372,3.274672,0.166820,0.003724,-475.323456,0.001335,0.000000
7.050000,1.006149,-475.367920,-0.004217,0.000032,0.000824,4.475575,0.227997,0.008236,-475.367920,0.001709,0.000000
7.270000,1.226219,-475.367920,-0.004161,0.000050,0.001266,5.454495,0.277865,0.012657,-475.367920,0.002073,0.000000
7.490000,1.390434,-475.323456,-0.004174,0.000060,0.001535,6.184960,0.315077,0.015352,-475.323456,0.002437,0.000000
7.710001,1.583328,-475.323456,-0.004135,0.000074,0.001890,7.042996,0.358787,0.018902,-475.323456,0.002810,0.000000
7.930000,1.868561,-475.367920,-0.004135,0.000092,0.002333,8.311773,0.423422,0.023330,-475.367920,0.003174,0.000000
8.150001,2.165718,-475.456879,-0.004143,0.000109,0.002766,9.633595,0.490759,0.027660,-475.456879,0.003538,0.000000
8.370001,2.433083,-475.412415,-0.004100,0.000124,0.003139,10.822892,0.551344,0.031392,-475.412415,0.003902,0.000000
8.590000,2.502716,-475.412415,-0.004109,0.000131,0.003339,11.132637,0.567124,0.033390,-475.412415,0.004275,0.000000
8.810000,2.888123,-475.367920,-0.004122,0.000147,0.003746,12.847011,0.654458,0.037463,-475.367920,0.004640,0.000000
9.030001,3.094788,-475.456879,-0.004109,0.000161,0.004093,13.766303,0.701289,0.040930,-475.456879,0.005004,0.000000
9.250000,3.512589,-475.456879,-0.004066,0.000179,0.004536,15.624774,0.795964,0.045358,-475.456879,0.005368,0.000000
9.470000,3.593018,-475.501373,-0.004079,0.000185,0.004709,15.982540,0.814189,0.047092,-475.501373,0.005741,0.000000
9.690001,3.978798,-475.501373,-0.004014,0.000200,0.005091,17.698578,0.901608,0.050907,-475.501373,0.006105,0.000000
9.910001,4.467354,-475.412415,-0.004018,0.000223,0.005663,19.871782,1.012317,0.056630,-475.412415,0.006469,0.000000
10.130000,4.756310,-475.456879,-0.004014,0.000238,0.006044,21.157122,1.077795,0.060445,-475.456879,0.006842,0.000000
10.350000,4.918663,-475.501373,-0.004014,0.000248,0.006296,21.879307,1.114585,0.062958,-475.501373,0.007206,0.000000
10.570001,5.132782,-475.545837,-0.003980,0.000260,0.006608,22.831755,1.163105,0.066084,-475.545837,0.007571,0.000000
10.790001,5.484299,-475.501373,-0.003949,0.000276,0.007016,24.395378,1.242760,0.070157,-475.501373,0.007935,0.000000
11.010000,5.909920,-475.501373,-0.004001,0.000291,0.007380,26.288635,1.339207,0.073798,-475.501373,0.008308,0.000000
11.230000,6.243195,-475.590332,-0.003958,0.000308,0.007823,27.771116,1.414728,0.078226,-475.590332,0.008672,0.000000
11.450001,6.393265,-475.590332,-0.003941,0.000318,0.008074,28.438662,1.448735,0.080739,-475.590332,0.009036,0.000000
11.670001,6.645355,-475.590332,-0.003954,0.000330,0.008386,29.560017,1.505859,0.083858,-475.590332,0.009409,0.000000
11.890000,7.062416,-475.634796,-0.003915,0.000346,0.008785,31.415195,1.600366,0.087847,-475.634796,0.009773,0.000000
12.110001,7.510376,-475.590332,-0.003915,0.000364,0.009253,33.407822,1.701875,0.092533,-475.590332,0.010137,0.000000
12.330001,7.717789,-475.545837,-0.003885,0.000376,0.009539,34.330441,1.748876,0.095394,-475.545837,0.010502,0.000000
12.550000,7.963928,-475.679291,-0.003876,0.000391,0.009938,35.425323,1.804652,0.099384,-475.679291,0.010875,0.000000
12.770000,8.213043,-475.679291,-0.003876,0.000406,0.010302,36.533440,1.861102,0.103025,-475.679291,0.011239,0.000000
12.990001,8.595474,-475.634796,-0.003876,0.000420,0.010658,38.234577,1.947762,0.106583,-475.634796,0.011604,0.000000
13.210001,8.927628,-475.590332,-0.003863,0.000435,0.011040,39.712070,2.023029,0.110398,-475.590332,0.011976,0.000000
13.430000,8.945129,-475.634796,-0.003824,0.000444,0.011265,39.789925,2.026995,0.112654,-475.634796,0.012340,0.000000
13.650001,9.132431,-475.634796,-0.003824,0.000456,0.011595,40.623081,2.069438,0.115946,-475.634796,0.012704,0.000000
13.870001,9.756531,-475.679291,-0.003794,0.000480,0.012184,43.399216,2.210861,0.121843,-475.679291,0.013069,0.000000
14.090001,10.245827,-475.679291,-0.003786,0.000495,0.012575,45.575714,2.321738,0.125749,-475.679291,0.013442,0.000000
14.310000,10.172844,-475.723785,-0.003773,0.000505,0.012835,45.251068,2.305199,0.128346,-475.723785,0.013806,0.000000
14.530001,10.612984,-475.768250,-0.003764,0.000523,0.013277,47.208908,2.404937,0.132774,-475.768250,0.014171,0.000000
14.750001,10.908653,-475.723785,-0.003742,0.000539,0.013702,48.524113,2.471936,0.137021,-475.723785,0.014543,0.000000
14.970000,11.103401,-475.768250,-0.003747,0.000553,0.014049,49.390396,2.516067,0.140488,-475.768250,0.014907,0.000000
15.190001,11.351028,-475.812744,-0.003738,0.000567,0.014395,50.491898,2.572180,0.143955,-475.812744,0.015272,0.000000
15.410001,11.301506,-475.723785,-0.003729,0.000575,0.014613,50.271610,2.560958,0.146127,-475.723785,0.015636,0.000000
15.630001,11.643341,-475.768250,-0.003704,0.000590,0.014986,51.792168,2.638419,0.149859,-475.768250,0.016009,0.000000
15.850000,12.439842,-475.812744,-0.003669,0.000615,0.015627,55.335182,2.818908,0.156271,-475.812744,0.016373,0.000000
16.070002,12.458092,-475.768250,-0.003682,0.000627,0.015931,55.416359,2.823044,0.159306,-475.768250,0.016738,0.000000
16.290001,12.305794,-475.812744,-0.003635,0.000635,0.016130,54.738903,2.788533,0.161305,-475.812744,0.017110,0.000000
16.510000,12.675186,-475.768250,-0.003660,0.000652,0.016573,56.382046,2.872238,0.165725,-475.768250,0.017475,0.000000
16.730001,13.077347,-475.812744,-0.003609,0.000669,0.016997,58.170944,2.963369,0.169972,-475.812744,0.017839,0.000000
16.950001,13.275078,-475.812744,-0.003617,0.000683,0.017336,59.050495,3.008176,0.173356,-475.812744,0.018203,0.000000
17.170000,13.296303,-475.901703,-0.003587,0.000693,0.017604,59.144909,3.012985,0.176043,-475.901703,0.018576,0.000000
17.390001,13.160385,-475.901703,-0.003570,0.000699,0.017752,58.540318,2.982186,0.177519,-475.901703,0.018940,0.000000
17.610001,13.872360,-475.857208,-0.003592,0.000723,0.018376,61.707340,3.143522,0.183764,-475.857208,0.019304,0.000000
17.830000,14.374321,-475.901703,-0.003544,0.000742,0.018853,63.940174,3.257268,0.188533,-475.901703,0.019677,0.000000
18.050001,14.569443,-475.901703,-0.003531,0.000758,0.019252,64.808121,3.301483,0.192522,-475.901703,0.020042,0.000000
18.270000,14.392570,-475.946167,-0.003501,0.000767,0.019478,64.021355,3.261403,0.194778,-475.946167,0.020406,0.000000
18.490002,14.732170,-475.990662,-0.003540,0.000784,0.019902,65.531967,3.338357,0.199025,-475.990662,0.020770,0.000000
18.710001,14.903465,-475.857208,-0.003501,0.000797,0.020241,66.293922,3.377173,0.202409,-475.857208,0.021143,0.000000
18.930000,15.111618,-475.901703,-0.003492,0.000811,0.020588,67.219833,3.424342,0.205876,-475.901703,0.021507,0.000000
19.150002,15.060974,-475.946167,-0.003449,0.000820,0.020840,66.994560,3.412866,0.208396,-475.946167,0.021871,0.000000
19.370001,15.480637,-475.990662,-0.003475,0.000839,0.021299,68.861313,3.507962,0.212991,-475.990662,0.022245,0.000000
19.590000,15.785614,-475.990662,-0.003432,0.000855,0.021706,70.217918,3.577071,0.217064,-475.990662,0.022609,0.000000
19.810001,16.162079,-475.946167,-0.003441,0.000873,0.022183,71.892517,3.662380,0.221833,-475.946167,0.022973,0.000000
20.030001,16.066757,-475.990662,-0.003419,0.000885,0.022469,71.468506,3.640779,0.224694,-475.990662,0.023337,0.000000
20.250002,15.989670,-475.990662,-0.003389,0.000897,0.022782,71.125603,3.623311,0.227820,-475.990662,0.023710,0.000000
20.470001,16.073456,-476.035126,-0.003402,0.000908,0.023051,71.498299,3.642297,0.230508,-476.035126,0.024074,0.000000
20.690001,16.020950,-475.990662,-0.003380,0.000916,0.023276,71.264748,3.630399,0.232763,-475.990662,0.024438,0.000000
20.910002,16.823418,-476.035126,-0.003380,0.000942,0.023927,74.834297,3.812241,0.239266,-476.035126,0.024812,0.000000
21.130001,16.782455,-475.990662,-0.003320,0.000954,0.024230,74.652092,3.802959,0.242301,-475.990662,0.025176,0.000000
21.350000,17.151848,-476.035126,-0.003354,0.000972,0.024681,76.295227,3.886664,0.246813,-476.035126,0.025540,0.000000
21.570002,17.442673,-476.079620,-0.003333,0.000990,0.025141,77.588882,3.952566,0.251408,-476.079620,0.025904,0.000000
21.790001,17.365585,-476.035126,-0.003311,0.001002,0.025453,77.245979,3.935098,0.254527,-476.035126,0.026277,0.000000
22.010000,17.408409,-476.035126,-0.003281,0.001015,0.025783,77.436470,3.944802,0.257827,-476.035126,0.026641,0.000000
22.230001,17.389420,-476.079620,-0.003277,0.001027,0.026077,77.352005,3.940499,0.260772,-476.079620,0.027005,0.000000
22.450001,17.281059,-476.035126,-0.003251,0.001038,0.026372,76.869987,3.915944,0.263724,-476.035126,0.027369,0.000000
22.670002,18.188530,-476.124115,-0.003268,0.001061,0.026962,80.906624,4.121580,0.269621,-476.124115,0.027743,0.000000
22.890001,18.031761,-476.213074,-0.003260,0.001071,0.027196,80.209282,4.086055,0.271960,-476.213074,0.028107,0.000000
23.110001,17.625130,-476.079620,-0.003216,0.001076,0.027335,78.400490,3.993912,0.273345,-476.079620,0.028471,0.000000
23.330002,18.239174,-476.035126,-0.003212,0.001096,0.027829,81.131897,4.133056,0.278288,-476.035126,0.028844,0.000000
23.550001,18.925827,-476.124115,-0.003173,0.001120,0.028436,84.186287,4.288654,0.284359,-476.124115,0.029208,0.000000
23.770000,18.771294,-476.213074,-0.003165,0.001131,0.028722,83.498886,4.253636,0.287221,-476.213074,0.029572,0.000000
23.990002,18.646553,-476.168579,-0.003143,0.001141,0.028992,82.944008,4.225369,0.289915,-476.168579,0.029936,0.000000
24.210001,18.703896,-476.124115,-0.003139,0.001156,0.029356,83.199081,4.238363,0.293556,-476.124115,0.030309,0.000000
24.430000,18.722885,-476.168579,-0.003122,0.001168,0.029659,83.283554,4.242666,0.296592,-476.168579,0.030674,0.000000
24.650002,19.276978,-476.168579,-0.003122,0.001187,0.030162,85.748276,4.368226,0.301618,-476.168579,0.031038,0.000000
24.870001,19.146645,-476.213074,-0.003100,0.001198,0.030422,85.168526,4.338692,0.304222,-476.213074,0.031411,0.000000
25.090002,19.016319,-476.257538,-0.003096,0.001207,0.030648,84.588814,4.309160,0.306478,-476.257538,0.031775,0.000000
25.310001,19.650467,-476.257538,-0.003083,0.001229,0.031228,87.409645,4.452860,0.312284,-476.257538,0.032139,0.000000
25.530001,20.105881,-476.213074,-0.003048,0.001249,0.031714,89.435425,4.556057,0.317144,-476.213074,0.032503,0.000000
25.750002,20.086143,-476.257538,-0.003078,0.001263,0.032070,89.347626,4.551585,0.320702,-476.257538,0.032876,0.000000
25.970001,19.844841,-476.302032,-0.003048,0.001272,0.032321,88.274261,4.496905,0.323215,-476.302032,0.033240,0.000000
26.190001,19.745796,-476.346497,-0.003018,0.001284,0.032616,87.833687,4.474461,0.326160,-476.346497,0.033605,0.000000
26.410002,20.210144,-476.346497,-0.003014,0.001302,0.033067,89.899208,4.579684,0.330671,-476.346497,0.033978,0.000000
26.630001,20.592567,-476.257538,-0.002979,0.001319,0.033509,91.600311,4.666343,0.335092,-476.257538,0.034342,0.000000
26.850000,20.519958,-476.302032,-0.002979,0.001330,0.033787,91.277336,4.649889,0.337870,-476.302032,0.034706,0.000000
27.070002,20.670769,-476.302032,-0.002971,0.001344,0.034143,91.948174,4.684063,0.341428,-476.302032,0.035071,0.000000
27.290001,20.906853,-476.346497,-0.002928,0.001360,0.034533,92.998329,4.737560,0.345326,-476.346497,0.035443,0.000000
27.510002,21.288536,-476.390991,-0.002915,0.001379,0.035019,94.696136,4.824051,0.350186,-476.390991,0.035807,0.000000
27.730001,21.132507,-476.302032,-0.002936,0.001389,0.035279,94.002090,4.788695,0.352790,-476.302032,0.036172,0.000000
27.950001,20.984680,-476.390991,-0.002893,0.001400,0.035565,93.344521,4.755197,0.355651,-476.390991,0.036545,0.000000
28.170002,21.055801,-476.435455,-0.002884,0.001413,0.035903,93.660881,4.771313,0.359028,-476.435455,0.036909,0.000000
28.390001,21.610634,-476.479950,-0.002897,0.001432,0.036371,96.128899,4.897039,0.363713,-476.479950,0.037273,0.000000
28.610001,21.990456,-476.390991,-0.002867,0.001450,0.036822,97.818436,4.983109,0.368225,-476.390991,0.037638,0.000000
28.830002,21.845230,-476.390991,-0.002850,0.001460,0.037082,97.172440,4.950200,0.370821,-476.390991,0.038010,0.000000
29.050001,21.983383,-476.435455,-0.002815,0.001474,0.037438,97.786972,4.981506,0.374379,-476.435455,0.038374,0.000000
29.270000,22.331551,-476.435455,-0.002820,0.001492,0.037906,99.335701,5.060401,0.379065,-476.435455,0.038739,0.000000
29.490002,22.591461,-476.479950,-0.002824,0.001508,0.038314,100.491837,5.119298,0.383137,-476.479950,0.039112,0.000000
29.710001,22.637634,-476.390991,-0.002781,0.001522,0.038670,100.697227,5.129761,0.386695,-476.390991,0.039476,0.000000
29.930002,22.249626,-476.435455,-0.002742,0.001531,0.038895,98.971283,5.041838,0.388951,-476.435455,0.039841,0.000000
30.150002,22.657372,-476.435455,-0.002777,0.001547,0.039285,100.785019,5.134233,0.392849,-476.435455,0.040205,0.000000
30.370001,22.490547,-476.479950,-0.002777,0.001557,0.039554,100.042953,5.096431,0.395544,-476.479950,0.040577,0.000000
30.590002,23.205879,-476.479950,-0.002725,0.001578,0.040074,103.224907,5.258527,0.400745,-476.479950,0.040942,0.000000
30.810001,22.866646,-476.524414,-0.002716,0.001585,0.040256,101.715919,5.181656,0.402561,-476.524414,0.041306,0.000000
31.030001,23.441589,-476.479950,-0.002725,0.001605,0.040760,104.273399,5.311940,0.407595,-476.479950,0.041679,0.000000
31.250002,23.805397,-476.524414,-0.002699,0.001621,0.041176,105.891693,5.394380,0.411759,-476.524414,0.042043,0.000000
31.470001,23.990471,-476.524414,-0.002686,0.001637,0.041575,106.714943,5.436318,0.415748,-476.524414,0.042407,0.000000
31.690002,23.768532,-476.568909,-0.002652,0.001647,0.041844,105.727707,5.386026,0.418435,-476.568909,0.042772,0.000000
31.910002,23.748055,-476.613403,-0.002669,0.001660,0.042164,105.636620,5.381386,0.421645,-476.613403,0.043144,0.000000
32.130001,24.026962,-476.524414,-0.002626,0.001676,0.042563,106.877266,5.444588,0.425634,-476.524414,0.043509,0.000000
32.350002,24.279053,-476.613403,-0.002617,0.001689,0.042902,107.998619,5.501712,0.429018,-476.613403,0.043873,0.000000
32.570000,24.523331,-476.613403,-0.002600,0.001707,0.043361,109.085220,5.557066,0.433613,-476.613403,0.044245,0.000000
32.790001,24.420181,-476.613403,-0.002587,0.001716,0.043595,108.626389,5.533692,0.435952,-476.613403,0.044610,0.000000
33.010002,24.473061,-476.657867,-0.002583,0.001729,0.043908,108.861610,5.545675,0.439078,-476.657867,0.044974,0.000000
33.230003,24.826073,-476.613403,-0.002574,0.001745,0.044315,110.431885,5.625669,0.443151,-476.613403,0.045339,0.000000
33.450001,25.381653,-476.613403,-0.002552,0.001764,0.044801,112.903229,5.751565,0.448010,-476.613403,0.045712,0.000000
33.670002,25.304573,-476.657867,-0.002552,0.001778,0.045165,112.560364,5.734098,0.451652,-476.657867,0.046076,0.000000
33.890003,25.389473,-476.657867,-0.002544,0.001791,0.045486,112.938019,5.753337,0.454861,-476.657867,0.046440,0.000000
34.110001,25.254669,-476.657867,-0.002505,0.001802,0.045772,112.338379,5.722790,0.457722,-476.657867,0.046813,0.000000
34.330002,25.530228,-476.746826,-0.002527,0.001817,0.046154,113.564125,5.785233,0.461538,-476.746826,0.047177,0.000000
34.550003,25.804665,-476.746826,-0.002471,0.001834,0.046588,114.784882,5.847421,0.465875,-476.746826,0.047541,0.000000
34.770000,25.501930,-476.702362,-0.002488,0.001841,0.046769,113.438248,5.778820,0.467692,-476.702362,0.047905,0.000000
34.990002,25.432663,-476.702362,-0.002488,0.001855,0.047116,113.130135,5.763124,0.471159,-476.702362,0.048279,0.000000
35.210003,25.198814,-476.746826,-0.002475,0.001868,0.047437,112.089928,5.710133,0.474368,-476.746826,0.048643,0.000000
35.430000,26.997375,-476.702362,-0.002432,0.001894,0.048096,120.090324,6.117692,0.480962,-476.702362,0.049007,0.000000
35.650002,26.685699,-476.746826,-0.002423,0.001905,0.048382,118.703918,6.047066,0.483823,-476.746826,0.049371,0.000000
35.870003,27.034241,-476.746826,-0.002393,0.001921,0.048799,120.254311,6.126047,0.487987,-476.746826,0.049744,0.000000
36.090000,27.119888,-476.791321,-0.002410,0.001937,0.049206,120.635284,6.145455,0.492059,-476.791321,0.050108,0.000000
36.310001,27.344795,-476.880280,-0.002358,0.001953,0.049597,121.635727,6.196419,0.495965,-476.880280,0.050472,0.000000
36.530003,27.361931,-476.791321,-0.002337,0.001965,0.049917,121.711945,6.200302,0.499175,-476.791321,0.050846,0.000000
36.750000,26.985832,-476.702362,-0.002333,0.001974,0.050143,120.038979,6.115077,0.501430,-476.702362,0.051210,0.000000
36.970001,27.408104,-476.835785,-0.002311,0.001993,0.050620,121.917336,6.210765,0.506199,-476.835785,0.051574,0.000000
37.190002,28.311852,-476.791321,-0.002294,0.002015,0.051184,125.937408,6.415557,0.511839,-476.791321,0.051938,0.000000
37.410004,28.215775,-476.880280,-0.002285,0.002027,0.051487,125.510033,6.393785,0.514874,-476.880280,0.052311,0.000000
37.630001,27.940964,-476.835785,-0.002302,0.002039,0.051799,124.287613,6.331513,0.517993,-476.835785,0.052675,0.000000
37.850002,28.099594,-476.835785,-0.002281,0.002051,0.052103,124.993240,6.367459,0.521029,-476.835785,0.053039,0.000000
38.070004,28.471970,-476.880280,-0.002264,0.002069,0.052545,126.649643,6.451841,0.525449,-476.880280,0.053412,0.000000
38.290001,28.517769,-476.924744,-0.002264,0.002082,0.052892,126.853371,6.462219,0.528916,-476.924744,0.053777,0.000000
38.510002,28.260086,-476.924744,-0.002220,0.002092,0.053126,125.707138,6.403827,0.531263,-476.924744,0.054141,0.000000
38.730003,27.923836,-476.924744,-0.002225,0.002101,0.053378,124.211426,6.327632,0.533776,-476.924744,0.054505,0.000000
38.950001,29.018982,-476.880280,-0.002199,0.002125,0.053976,129.082886,6.575795,0.539764,-476.880280,0.054878,0.000000
39.170002,29.469185,-476.969238,-0.002195,0.002142,0.054418,131.085480,6.677813,0.544185,-476.969238,0.055242,0.000000
39.390003,29.700798,-476.924744,-0.002160,0.002157,0.054800,132.115753,6.730297,0.548000,-476.924744,0.055606,0.000000
39.610001,29.265495,-477.013733,-0.002130,0.002167,0.055051,130.179428,6.631656,0.550513,-477.013733,0.055979,0.000000
39.830002,29.582008,-477.013733,-0.002117,0.002183,0.055442,131.587341,6.703379,0.554419,-477.013733,0.056343,0.000000
40.050003,29.728355,-476.924744,-0.002091,0.002198,0.055823,132.238327,6.736542,0.558234,-476.924744,0.056708,0.000000
40.270000,29.752930,-476.924744,-0.002108,0.002210,0.056135,132.347641,6.742110,0.561353,-476.924744,0.057072,0.000000
40.490002,29.486687,-477.058197,-0.002091,0.002222,0.056431,131.163330,6.681779,0.564305,-477.058197,0.057445,0.000000
40.710003,29.957733,-477.013733,-0.002065,0.002237,0.056820,133.258652,6.788519,0.568204,-477.013733,0.057809,0.000000
40.930000,30.221748,-477.013733,-0.002048,0.002254,0.057246,134.433044,6.848346,0.572458,-477.013733,0.058173,0.000000
41.150002,30.848824,-477.013733,-0.002022,0.002273,0.057740,137.222427,6.990443,0.577401,-477.013733,0.058546,0.000000
41.370003,30.689072,-477.058197,-0.002048,0.002285,0.058044,136.511810,6.954243,0.580436,-477.058197,0.058910,0.000000
41.590000,30.507729,-477.058197,-0.002031,0.002297,0.058356,135.705154,6.913150,0.583555,-477.058197,0.059274,0.000000
41.810001,30.272018,-477.058197,-0.002018,0.002309,0.058659,134.656662,6.859737,0.586591,-477.058197,0.059639,0.000000
42.030003,30.152489,-477.058197,-0.001996,0.002324,0.059023,134.124969,6.832652,0.590232,-477.058197,0.060012,0.000000
42.250004,31.061821,-477.058197,-0.001962,0.002342,0.059483,138.169876,7.038709,0.594827,-477.058197,0.060376,0.000000
42.470001,30.873772,-477.102692,-0.001996,0.002352,0.059751,137.333389,6.996097,0.597514,-477.102692,0.060741,0.000000
42.690002,31.356369,-477.102692,-0.001962,0.002372,0.060246,139.480103,7.105454,0.602457,-477.102692,0.061113,0.000000
42.910004,31.880669,-477.102692,-0.001936,0.002390,0.060714,141.812302,7.224263,0.607143,-477.102692,0.061477,0.000000
43.130001,31.628571,-477.147156,-0.001919,0.002401,0.060992,140.690903,7.167137,0.609921,-477.147156,0.061841,0.000000
43.350002,31.539200,-477.102692,-0.001880,0.002414,0.061313,140.293365,7.146885,0.613130,-477.102692,0.062206,0.000000
43.570004,31.323967,-477.147156,-0.001867,0.002425,0.061599,139.335968,7.098113,0.615992,-477.147156,0.062579,0.000000
43.790001,31.098312,-477.102692,-0.001880,0.002438,0.061937,138.332199,7.046978,0.619368,-477.102692,0.062943,0.000000
44.010002,32.145798,-477.236115,-0.001880,0.002461,0.062501,142.991653,7.284342,0.625007,-477.236115,0.063308,0.000000
44.230003,31.690758,-477.236115,-0.001837,0.002470,0.062726,140.967529,7.181229,0.627263,-477.236115,0.063680,0.000000
44.450001,30.921432,-477.191650,-0.001841,0.002474,0.062847,137.545395,7.006897,0.628474,-477.191650,0.064044,0.000000
44.670002,31.699692,-477.191650,-0.001815,0.002494,0.063359,141.007278,7.183253,0.633591,-477.191650,0.064409,0.000000
44.890003,32.724464,-477.280609,-0.001798,0.002518,0.063966,145.565689,7.415470,0.639662,-477.280609,0.064773,0.000000
45.110001,32.457100,-477.280609,-0.001772,0.002530,0.064252,144.376389,7.354884,0.642524,-477.280609,0.065146,0.000000
45.330002,32.186386,-477.280609,-0.001759,0.002540,0.064513,143.172195,7.293540,0.645128,-477.280609,0.065510,0.000000
45.550003,32.144676,-477.280609,-0.001746,0.002554,0.064869,142.986664,7.284088,0.648686,-477.280609,0.065875,0.000000
45.770000,32.167397,-477.280609,-0.001750,0.002568,0.065233,143.087723,7.289236,0.652327,-477.280609,0.066247,0.000000
45.990002,32.735634,-477.236115,-0.001712,0.002586,0.065675,145.615372,7.418001,0.656747,-477.236115,0.066611,0.000000
46.210003,32.441833,-477.280609,-0.001725,0.002596,0.065926,144.308487,7.351425,0.659261,-477.280609,0.066976,0.000000
46.430000,32.227722,-477.369568,-0.001686,0.002605,0.066169,143.356064,7.302907,0.661690,-477.369568,0.067340,0.000000
46.650002,33.077469,-477.325073,-0.001660,0.002629,0.066785,147.135925,7.495461,0.667852,-477.325073,0.067713,0.000000
46.870003,33.728752,-477.280609,-0.001656,0.002647,0.067236,150.032990,7.643044,0.672356,-477.280609,0.068077,0.000000
47.090004,33.787956,-477.280609,-0.001630,0.002662,0.067609,150.296341,7.656460,0.676088,-477.280609,0.068441,0.000000
47.310001,33.395477,-477.369568,-0.001634,0.002671,0.067852,148.550507,7.567523,0.678518,-477.369568,0.068814,0.000000
47.530003,33.150833,-477.369568,-0.001625,0.002683,0.068155,147.462265,7.512086,0.681554,-477.369568,0.069179,0.000000
47.750004,33.761520,-477.369568,-0.001582,0.002701,0.068597,150.178741,7.650470,0.685974,-477.369568,0.069543,0.000000
47.970001,34.205391,-477.369568,-0.001548,0.002717,0.069022,152.153183,7.751052,0.690221,-477.369568,0.069907,0.000000
48.190002,34.220657,-477.414062,-0.001591,0.002729,0.069317,152.221085,7.754512,0.693173,-477.414062,0.070280,0.000000
48.410004,34.358437,-477.458527,-0.001548,0.002743,0.069664,152.833954,7.785733,0.696640,-477.458527,0.070644,0.000000
48.630001,34.779961,-477.414062,-0.001561,0.002758,0.070055,154.708984,7.881252,0.700546,-477.414062,0.071008,0.000000
48.850002,35.426399,-477.458527,-0.001548,0.002778,0.070566,157.584488,8.027737,0.705663,-477.458527,0.071373,0.000000
49.070004,35.284149,-477.458527,-0.001544,0.002789,0.070843,156.951736,7.995502,0.708434,-477.458527,0.071746,0.000000
49.290001,35.052162,-477.369568,-0.001518,0.002799,0.071095,155.919800,7.942933,0.710947,-477.369568,0.072110,0.000000
49.510002,35.077110,-477.458527,-0.001492,0.002812,0.071425,156.030777,7.948587,0.714248,-477.458527,0.072474,0.000000
49.730003,35.955536,-477.547485,-0.001500,0.002831,0.071902,159.938217,8.147641,0.719016,-477.547485,0.072847,0.000000
49.950001,36.676453,-477.503021,-0.001470,0.002849,0.072361,163.145004,8.311004,0.723611,-477.503021,0.073211,0.000000
50.170002,36.728584,-477.547485,-0.001457,0.002860,0.072656,163.376907,8.322816,0.726564,-477.547485,0.073575,0.000000
50.390003,36.885727,-477.458527,-0.001414,0.002873,0.072968,164.075912,8.358425,0.729682,-477.458527,0.073939,0.000000
50.610001,37.678879,-477.547485,-0.001453,0.002892,0.073463,167.604019,8.538157,0.734625,-477.547485,0.074313,0.000000
50.830002,38.145088,-477.547485,-0.001406,0.002908,0.073853,169.677826,8.643801,0.738531,-477.547485,0.074677,0.000000
51.050003,38.378197,-477.591980,-0.001393,0.002922,0.074208,170.714752,8.696624,0.742082,-477.591980,0.075041,0.000000
51.270004,38.334625,-477.503021,-0.001384,0.002931,0.074443,170.520935,8.686749,0.744428,-477.503021,0.075414,0.000000
51.490002,38.833977,-477.547485,-0.001384,0.002945,0.074807,172.742157,8.799905,0.748069,-477.547485,0.075778,0.000000
51.710003,38.968033,-477.547485,-0.001410,0.002960,0.075179,173.338470,8.830282,0.751794,-477.547485,0.076142,0.000000
51.930004,39.830818,-477.591980,-0.001375,0.002976,0.075578,177.176331,9.025792,0.755783,-477.591980,0.076506,0.000000
52.150002,39.660645,-477.636444,-0.001367,0.002983,0.075778,176.419357,8.987230,0.757781,-477.636444,0.076880,0.000000
52.370003,40.611687,-477.680939,-0.001350,0.003003,0.076272,180.649811,9.202740,0.762724,-477.680939,0.077244,0.000000
52.590004,41.533310,-477.591980,-0.001328,0.003020,0.076715,184.749390,9.411583,0.767145,-477.591980,0.077608,0.000000
52.810001,42.112343,-477.636444,-0.001306,0.003036,0.077123,187.325058,9.542793,0.771225,-477.636444,0.077981,0.000000
53.030003,42.269485,-477.769897,-0.001289,0.003048,0.077417,188.024063,9.578403,0.774170,-477.769897,0.078345,0.000000
53.250004,42.435936,-477.680939,-0.001281,0.003058,0.077686,188.764465,9.616120,0.776857,-477.680939,0.078709,0.000000
53.470001,43.128922,-477.680939,-0.001268,0.003076,0.078119,191.847031,9.773153,0.781195,-477.680939,0.079073,0.000000
53.690002,43.714661,-477.636444,-0.001285,0.003090,0.078484,194.452515,9.905884,0.784836,-477.636444,0.079446,0.000000
53.910004,44.476166,-477.680939,-0.001255,0.003106,0.078892,197.839859,10.078444,0.788916,-477.680939,0.079811,0.000000
54.130001,44.637405,-477.725403,-0.001272,0.003115,0.079117,198.557098,10.114981,0.791172,-477.725403,0.080175,0.000000
54.350002,44.950569,-477.725403,-0.001224,0.003127,0.079429,199.950119,10.185945,0.794290,-477.725403,0.080548,0.000000
54.570004,45.777237,-477.769897,-0.001237,0.003143,0.079837,203.627319,10.373270,0.798371,-477.769897,0.080912,0.000000
54.790001,46.896584,-477.769897,-0.001207,0.003163,0.080331,208.606415,10.626917,0.803314,-477.769897,0.081276,0.000000
55.010002,47.242897,-477.814362,-0.001212,0.003173,0.080591,210.146896,10.705394,0.805910,-477.814362,0.081640,0.000000
55.230003,47.970879,-477.769897,-0.001190,0.003189,0.081007,213.385132,10.870357,0.810073,-477.769897,0.082013,0.000000
55.450001,48.522736,-477.814362,-0.001186,0.003203,0.081363,215.839905,10.995409,0.813631,-477.814362,0.082377,0.000000
55.670002,49.186302,-477.769897,-0.001177,0.003219,0.081770,218.791595,11.145775,0.817704,-477.769897,0.082742,0.000000
55.890003,49.888229,-477.725403,-0.001173,0.003233,0.082126,221.913925,11.304834,0.821262,-477.725403,0.083115,0.000000
56.110004,50.027496,-477.858856,-0.001151,0.003240,0.082291,222.533417,11.336392,0.822912,-477.858856,0.083479,0.000000
56.330002,50.372681,-477.858856,-0.001173,0.003254,0.082664,224.068878,11.414612,0.826636,-477.858856,0.083843,0.000000
56.550003,51.562042,-477.903351,-0.001138,0.003278,0.083262,229.359421,11.684126,0.832624,-477.903351,0.084208,0.000000
56.770004,53.089882,-477.903351,-0.001147,0.003292,0.083626,236.155594,12.030339,0.836265,-477.903351,0.084580,0.000000
56.990002,53.332298,-477.814362,-0.001134,0.003303,0.083904,237.233917,12.085272,0.839043,-477.814362,0.084944,0.000000
57.210003,54.331375,-477.947815,-0.001147,0.003320,0.084320,241.678024,12.311666,0.843199,-477.947815,0.085308,0.000000
57.430004,55.129745,-477.947815,-0.001112,0.003337,0.084754,245.229355,12.492579,0.847536,-477.947815,0.085682,0.000000
57.650002,56.058815,-477.947815,-0.001112,0.003352,0.085144,249.362061,12.703110,0.851442,-477.947815,0.086046,0.000000
57.870003,56.674339,-477.903351,-0.001125,0.003364,0.085439,252.100052,12.842589,0.854387,-477.903351,0.086410,0.000000
58.090004,56.829247,-477.903351,-0.001082,0.003373,0.085664,252.789108,12.877691,0.856643,-477.903351,0.086775,0.000000
58.310001,57.747147,-477.992310,-0.001078,0.003391,0.086141,256.872131,13.085690,0.861412,-477.992310,0.087147,0.000000
58.530003,59.582947,-477.947815,-0.001043,0.003414,0.086713,265.038177,13.501688,0.867135,-477.947815,0.087511,0.000000
58.750004,60.234970,-477.992310,-0.001043,0.003426,0.087026,267.938538,13.649440,0.870261,-477.992310,0.087876,0.000000
58.970001,60.280396,-477.992310,-0.001043,0.003436,0.087277,268.140594,13.659733,0.872774,-477.992310,0.088249,0.000000
59.190002,61.382622,-477.947815,-0.001052,0.003450,0.087624,273.043549,13.909500,0.876241,-477.947815,0.088613,0.000000
59.410004,62.605865,-477.992310,-0.001030,0.003468,0.088093,278.484802,14.186691,0.880927,-477.992310,0.088978,0.000000
59.630001,63.363647,-477.992310,-0.001026,0.003481,0.088422,281.855591,14.358408,0.884220,-477.992310,0.089342,0.000000
59.850002,63.752777,-477.992310,-0.001022,0.003490,0.088648,283.586517,14.446586,0.886475,-477.992310,0.089714,0.000000
60.070004,63.928162,-477.992310,-0.001005,0.003499,0.088882,284.366669,14.486328,0.888822,-477.992310,0.090079,0.000000
60.290005,65.600479,-477.992310,-0.000987,0.003523,0.089489,291.805511,14.865281,0.894885,-477.992310,0.090443,0.000000
60.510002,67.304092,-478.036774,-0.000983,0.003542,0.089957,299.383545,15.251326,0.899571,-478.036774,0.090816,0.000000
60.730003,66.915329,-478.125732,-0.000983,0.003536,0.089827,297.654236,15.163230,0.898269,-478.125732,0.090000,0.000000
60.950005,66.249161,-478.081268,-0.000992,0.003536,0.089819,294.690979,15.012275,0.898186,-478.081268,0.089827,0.000000
61.170002,65.633255,-478.081268,-0.000979,0.003536,0.089819,291.951294,14.872708,0.898186,-478.081268,0.089827,0.000000
61.390003,65.062408,-478.036774,-0.000970,0.003536,0.089809,289.412048,14.743353,0.898095,-478.036774,0.089827,0.000000
61.610004,64.547409,-478.125732,-0.000974,0.003536,0.089809,287.121216,14.626652,0.898095,-478.125732,0.089827,0.000000
61.830002,64.068542,-478.125732,-0.000974,0.003536,0.089809,284.991119,14.518139,0.898095,-478.125732,0.089827,0.000000
62.050003,63.641434,-478.170227,-0.000974,0.003536,0.089809,283.091248,14.421355,0.898095,-478.170227,0.089827,0.000000
62.270004,63.242622,-478.125732,-0.000949,0.003536,0.089809,281.317230,14.330983,0.898095,-478.125732,0.089827,0.000000
62.490002,62.855728,-478.125732,-0.000944,0.003535,0.089801,279.596252,14.243312,0.898012,-478.125732,0.089827,0.000000
62.710003,62.501968,-478.170227,-0.000944,0.003535,0.089801,278.022644,14.163149,0.898012,-478.170227,0.089827,0.000000
62.930004,62.178383,-478.125732,-0.000944,0.003535,0.089801,276.583252,14.089824,0.898012,-478.125732,0.089827,0.000000
63.150002,61.875641,-478.259186,-0.000949,0.003535,0.089801,275.236603,14.021220,0.898012,-478.259186,0.089827,0.000000
63.370003,61.589661,-478.214691,-0.000927,0.003535,0.089801,273.964508,13.956417,0.898012,-478.214691,0.089827,0.000000
63.590004,61.315224,-478.214691,-0.000957,0.003535,0.089801,272.743744,13.894228,0.898012,-478.214691,0.089827,0.000000
63.810001,61.068336,-478.214691,-0.000970,0.003535,0.089801,271.645538,13.838284,0.898012,-478.214691,0.089827,0.000000
64.030006,60.824059,-478.259186,-0.000966,0.003535,0.089801,270.558929,13.782928,0.898012,-478.259186,0.089827,0.000000
64.250000,60.605476,-478.259186,-0.000944,0.003535,0.089801,269.586609,13.733397,0.898012,-478.259186,0.089827,0.000000
64.470001,60.395088,-478.348145,-0.000953,0.003535,0.089801,268.650757,13.685722,0.898012,-478.348145,0.089827,0.000000
64.690002,60.195122,-478.259186,-0.000940,0.003535,0.089801,267.761261,13.640409,0.898012,-478.259186,0.089827,0.000000
64.910004,60.005585,-478.303680,-0.000931,0.003535,0.089801,266.918182,13.597460,0.898012,-478.303680,0.089827,0.000000
65.130005,59.801903,-478.303680,-0.000923,0.003535,0.089801,266.012146,13.551305,0.898012,-478.303680,0.089827,0.000000
65.350006,59.633591,-478.348145,-0.000931,0.003535,0.089801,265.263458,13.513165,0.898012,-478.348145,0.089827,0.000000
65.570000,59.471977,-478.348145,-0.000936,0.003535,0.089801,264.544556,13.476542,0.898012,-478.348145,0.089827,0.000000
65.790001,59.309998,-478.303680,-0.000910,0.003535,0.089801,263.824036,13.439838,0.898012,-478.303680,0.089827,0.000000
66.010002,59.156578,-478.392639,-0.000936,0.003535,0.089801,263.141602,13.405072,0.898012,-478.392639,0.089827,0.000000
66.230003,59.000557,-478.348145,-0.000923,0.003535,0.089801,262.447571,13.369718,0.898012,-478.348145,0.089827,0.000000
66.450005,58.867241,-478.437103,-0.000940,0.003535,0.089801,261.854553,13.339507,0.898012,-478.437103,0.089827,0.000000
66.670006,58.739151,-478.392639,-0.000961,0.003535,0.089801,261.284790,13.310481,0.898012,-478.392639,0.089827,0.000000
66.889999,58.603607,-478.392639,-0.000897,0.003535,0.089801,260.681854,13.279767,0.898012,-478.392639,0.089827,0.000000
67.110001,58.487801,-478.392639,-0.000918,0.003535,0.089801,260.166718,13.253526,0.898012,-478.392639,0.089827,0.000000
67.330002,58.348900,-478.437103,-0.000910,0.003535,0.089801,259.548859,13.222050,0.898012,-478.437103,0.089827,0.000000
67.550003,58.241287,-478.481598,-0.000918,0.003535,0.089801,259.070190,13.197664,0.898012,-478.481598,0.089827,0.000000
67.770004,58.129204,-478.481598,-0.000927,0.003535,0.089801,258.571625,13.172266,0.898012,-478.481598,0.089827,0.000000
67.990005,58.022331,-478.392639,-0.000918,0.003535,0.089801,258.096222,13.148047,0.898012,-478.392639,0.089827,0.000000
68.210007,57.925514,-478.481598,-0.000927,0.003535,0.089801,257.665558,13.126109,0.898012,-478.481598,0.089827,0.000000
68.430000,57.814545,-478.437103,-0.000927,0.003535,0.089801,257.171936,13.100963,0.898012,-478.437103,0.089827,0.000000
68.650002,57.710655,-478.526062,-0.000910,0.003535,0.089801,256.709808,13.077421,0.898012,-478.526062,0.089827,0.000000
68.870003,57.617187,-478.526062,-0.000927,0.003535,0.089801,256.294037,13.056242,0.898012,-478.526062,0.089827,0.000000
69.090004,57.523354,-478.481598,-0.000914,0.003535,0.089801,255.876663,13.034978,0.898012,-478.481598,0.089827,0.000000
69.310005,57.437706,-478.526062,-0.000901,0.003535,0.089801,255.495682,13.015571,0.898012,-478.526062,0.089827,0.000000
69.530006,57.358765,-478.570557,-0.000940,0.003535,0.089801,255.144531,12.997682,0.898012,-478.570557,0.089827,0.000000
69.750000,57.247421,-478.570557,-0.000905,0.003535,0.089801,254.649246,12.972451,0.898012,-478.570557,0.089827,0.000000
69.970001,57.184494,-478.526062,-0.000931,0.003535,0.089801,254.369339,12.958192,0.898012,-478.526062,0.089827,0.000000
70.190002,57.099594,-478.526062,-0.000914,0.003535,0.089801,253.991684,12.938952,0.898012,-478.526062,0.089827,0.000000
70.410004,57.026237,-478.570557,-0.000923,0.003535,0.089801,253.665375,12.922330,0.898012,-478.570557,0.089827,0.000000
70.630005,56.957344,-478.570557,-0.000910,0.003535,0.089801,253.358917,12.906718,0.898012,-478.570557,0.089827,0.000000
70.850006,56.869469,-478.615021,-0.000923,0.003535,0.089801,252.968033,12.886806,0.898012,-478.615021,0.089827,0.000000
71.070000,56.799835,-478.570557,-0.000914,0.003535,0.089801,252.658279,12.871026,0.898012,-478.570557,0.089827,0.000000
71.290001,56.733925,-478.615021,-0.000914,0.003535,0.089801,252.365097,12.856091,0.898012,-478.615021,0.089827,0.000000
71.510002,56.660568,-478.570557,-0.000892,0.003535,0.089801,252.038788,12.839468,0.898012,-478.570557,0.089827,0.000000
71.730003,56.604340,-478.570557,-0.000918,0.003535,0.089801,251.788681,12.826727,0.898012,-478.570557,0.089827,0.000000
71.950005,56.541031,-478.659515,-0.000905,0.003535,0.089801,251.507065,12.812381,0.898012,-478.659515,0.089827,0.000000
72.170006,56.469162,-478.659515,-0.000931,0.003535,0.089801,251.187378,12.796095,0.898012,-478.659515,0.089827,0.000000
72.390007,56.412193,-478.615021,-0.000888,0.003535,0.089801,250.933975,12.783186,0.898012,-478.615021,0.089827,0.000000
72.610001,56.342186,-478.659515,-0.000918,0.003535,0.089801,250.622559,12.767322,0.898012,-478.659515,0.089827,0.000000
72.830002,56.282234,-478.659515,-0.000940,0.003535,0.089801,250.355881,12.753737,0.898012,-478.659515,0.089827,0.000000
73.050003,56.234200,-478.704010,-0.000888,0.003535,0.089801,250.142212,12.742852,0.898012,-478.704010,0.089827,0.000000
73.270004,56.166054,-478.659515,-0.000897,0.003535,0.089801,249.839081,12.727409,0.898012,-478.659515,0.089827,0.000000
73.490005,56.113922,-478.704010,-0.000914,0.003535,0.089801,249.607193,12.715597,0.898012,-478.704010,0.089827,0.000000
73.710007,56.059929,-478.704010,-0.000918,0.003535,0.089801,249.367020,12.703362,0.898012,-478.704010,0.089827,0.000000
73.930000,56.004074,-478.704010,-0.000923,0.003535,0.089801,249.118561,12.690704,0.898012,-478.704010,0.089827,0.000000
74.150002,55.960503,-478.748474,-0.000905,0.003535,0.089801,248.924744,12.680831,0.898012,-478.748474,0.089827,0.000000
74.370003,55.905396,-478.704010,-0.000884,0.003535,0.089801,248.679626,12.668344,0.898012,-478.704010,0.089827,0.000000
74.590004,55.859222,-478.704010,-0.000905,0.003535,0.089801,248.474228,12.657881,0.898012,-478.704010,0.089827,0.000000
74.810005,55.805229,-478.792969,-0.000892,0.003535,0.089801,248.234055,12.645646,0.898012,-478.792969,0.089827,0.000000
75.030006,55.749367,-478.792969,-0.000905,0.003535,0.089801,247.985565,12.632987,0.898012,-478.792969,0.089827,0.000000
75.250000,55.721443,-478.792969,-0.000897,0.003535,0.089801,247.861359,12.626659,0.898012,-478.792969,0.089827,0.000000
75.470001,55.657768,-478.792969,-0.000914,0.003535,0.089801,247.578125,12.612231,0.898012,-478.792969,0.089827,0.000000
75.690002,55.622765,-478.748474,-0.000888,0.003535,0.089801,247.422409,12.604299,0.898012,-478.748474,0.089827,0.000000
75.910004,55.577332,-478.792969,-0.000923,0.003535,0.089801,247.220322,12.594004,0.898012,-478.792969,0.089827,0.000000
76.130005,55.521477,-478.881927,-0.000914,0.003535,0.089801,246.971863,12.581347,0.898012,-478.881927,0.089827,0.000000
76.350006,55.479027,-478.881927,-0.000914,0.003535,0.089801,246.783035,12.571728,0.898012,-478.881927,0.089827,0.000000
76.570007,55.450729,-478.881927,-0.000918,0.003535,0.089801,246.657166,12.565314,0.898012,-478.881927,0.089827,0.000000
76.790001,55.406044,-478.837433,-0.000892,0.003535,0.089801,246.458389,12.555189,0.898012,-478.837433,0.089827,0.000000
77.010002,55.356148,-478.837433,-0.000888,0.003535,0.089801,246.236450,12.543882,0.898012,-478.837433,0.089827,0.000000
77.230003,55.314438,-478.837433,-0.000914,0.003535,0.089801,246.050903,12.534431,0.898012,-478.837433,0.089827,0.000000
77.450005,55.267891,-478.926392,-0.000927,0.003535,0.089801,245.843857,12.523884,0.898012,-478.926392,0.089827,0.000000
77.670006,55.234009,-478.881927,-0.000888,0.003535,0.089801,245.693146,12.516206,0.898012,-478.881927,0.089827,0.000000
77.890007,55.194534,-478.881927,-0.000884,0.003535,0.089801,245.517548,12.507260,0.898012,-478.881927,0.089827,0.000000
78.110001,55.152832,-478.926392,-0.000897,0.003535,0.089801,245.332047,12.497810,0.898012,-478.926392,0.089827,0.000000
78.330002,55.121925,-478.881927,-0.000910,0.003535,0.089801,245.194565,12.490807,0.898012,-478.881927,0.089827,0.000000
78.550003,55.076492,-478.970886,-0.000901,0.003535,0.089801,244.992477,12.480512,0.898012,-478.970886,0.089827,0.000000
78.770004,55.054153,-478.970886,-0.000910,0.003535,0.089801,244.893112,12.475449,0.898012,-478.970886,0.089827,0.000000
78.990005,55.007973,-479.015350,-0.000901,0.003535,0.089801,244.687683,12.464985,0.898012,-479.015350,0.089827,0.000000
79.210007,54.976700,-478.926392,-0.000901,0.003535,0.089801,244.548569,12.457899,0.898012,-478.926392,0.089827,0.000000
79.430000,54.939461,-479.015350,-0.000897,0.003535,0.089801,244.382919,12.449459,0.898012,-479.015350,0.089827,0.000000
79.650002,54.899246,-479.015350,-0.000888,0.003535,0.089801,244.204041,12.440348,0.898012,-479.015350,0.089827,0.000000
79.870003,54.876526,-479.059845,-0.000897,0.003535,0.089801,244.102982,12.435198,0.898012,-479.059845,0.089827,0.000000
80.090004,54.846367,-479.059845,-0.000897,0.003535,0.089801,243.968826,12.428364,0.898012,-479.059845,0.089827,0.000000
80.310005,54.802795,-479.015350,-0.000914,0.003535,0.089801,243.775009,12.418491,0.898012,-479.015350,0.089827,0.000000
80.530006,54.774872,-479.015350,-0.000897,0.003535,0.089801,243.650803,12.412164,0.898012,-479.015350,0.089827,0.000000
80.750008,54.736893,-479.104309,-0.000910,0.003535,0.089801,243.481857,12.403557,0.898012,-479.104309,0.089827,0.000000
80.970001,54.694069,-479.104309,-0.000884,0.003535,0.089801,243.291367,12.393853,0.898012,-479.104309,0.089827,0.000000
81.190002,54.673210,-479.059845,-0.000897,0.003535,0.089801,243.198578,12.389126,0.898012,-479.059845,0.089827,0.000000
81.410004,54.639702,-479.059845,-0.000867,0.003535,0.089801,243.049530,12.381534,0.898012,-479.059845,0.089827,0.000000
81.630005,54.614380,-479.059845,-0.000918,0.003535,0.089801,242.936890,12.375795,0.898012,-479.059845,0.089827,0.000000
81.850006,54.592033,-479.148804,-0.000884,0.003535,0.089801,242.837494,12.370731,0.898012,-479.148804,0.089827,0.000000
82.070007,54.552940,-479.104309,-0.000858,0.003535,0.089801,242.663605,12.361873,0.898012,-479.104309,0.089827,0.000000
82.290001,54.523895,-479.193298,-0.000888,0.003535,0.089801,242.534393,12.355290,0.898012,-479.193298,0.089827,0.000000
82.510002,54.496712,-479.148804,-0.000884,0.003535,0.089801,242.413483,12.349132,0.898012,-479.148804,0.089827,0.000000
82.730003,54.457237,-479.104309,-0.000892,0.003535,0.089801,242.237885,12.340186,0.898012,-479.104309,0.089827,0.000000
82.950005,54.440109,-479.148804,-0.000910,0.003535,0.089801,242.161697,12.336306,0.898012,-479.148804,0.089827,0.000000
83.170006,54.414040,-479.193298,-0.000905,0.003535,0.089801,242.045731,12.330398,0.898012,-479.193298,0.089827,0.000000
83.390007,54.377174,-479.237762,-0.000871,0.003535,0.089801,241.881760,12.322044,0.898012,-479.237762,0.089827,0.000000
83.610001,54.359306,-479.148804,-0.000914,0.003535,0.089801,241.802277,12.317995,0.898012,-479.148804,0.089827,0.000000
83.830002,54.330627,-479.237762,-0.000914,0.003535,0.089801,241.674698,12.311496,0.898012,-479.237762,0.089827,0.000000
84.050003,54.295998,-479.237762,-0.000875,0.003535,0.089801,241.520660,12.303649,0.898012,-479.237762,0.089827,0.000000
84.270004,54.258018,-479.237762,-0.000897,0.003535,0.089801,241.351715,12.295043,0.898012,-479.237762,0.089827,0.000000
84.490005,54.239029,-479.237762,-0.000888,0.003535,0.089801,241.267258,12.290740,0.898012,-479.237762,0.089827,0.000000
84.710007,54.230087,-479.237762,-0.000888,0.003535,0.089801,241.227478,12.288713,0.898012,-479.237762,0.089827,0.000000
84.930000,54.207375,-479.193298,-0.000880,0.003535,0.089801,241.126450,12.283566,0.898012,-479.193298,0.089827,0.000000
85.150002,54.168274,-479.237762,-0.000910,0.003535,0.089801,240.952515,12.274707,0.898012,-479.237762,0.089827,0.000000
85.370003,54.154869,-479.326721,-0.000880,0.003535,0.089801,240.892883,12.271668,0.898012,-479.326721,0.089827,0.000000
85.590004,54.120239,-479.326721,-0.000884,0.003535,0.089801,240.738846,12.263822,0.898012,-479.326721,0.089827,0.000000
85.810005,54.091568,-479.282257,-0.000897,0.003535,0.089801,240.611313,12.257325,0.898012,-479.282257,0.089827,0.000000
86.030006,54.072578,-479.326721,-0.000888,0.003535,0.089801,240.526840,12.253021,0.898012,-479.326721,0.089827,0.000000
86.250008,54.045395,-479.326721,-0.000867,0.003535,0.089801,240.405930,12.246862,0.898012,-479.326721,0.089827,0.000000
86.470001,54.027893,-479.371216,-0.000892,0.003535,0.089801,240.328064,12.242895,0.898012,-479.371216,0.089827,0.000000
86.690002,54.004059,-479.326721,-0.000884,0.003535,0.089801,240.222046,12.237494,0.898012,-479.326721,0.089827,0.000000
86.910004,53.972038,-479.237762,-0.000901,0.003535,0.089801,240.079620,12.230239,0.898012,-479.237762,0.089827,0.000000
87.130005,53.954163,-479.326721,-0.000880,0.003535,0.089801,240.000107,12.226188,0.898012,-479.326721,0.089827,0.000000
87.350006,53.922508,-479.371216,-0.000914,0.003535,0.089801,239.859299,12.219015,0.898012,-479.371216,0.089827,0.000000
87.570007,53.918045,-479.415680,-0.000910,0.003535,0.089801,239.839447,12.218003,0.898012,-479.415680,0.089827,0.000000
87.790001,53.899422,-479.460175,-0.000871,0.003535,0.089801,239.756607,12.213784,0.898012,-479.460175,0.089827,0.000000
88.010002,53.863678,-479.371216,-0.000910,0.003535,0.089801,239.597610,12.205684,0.898012,-479.371216,0.089827,0.000000
88.230003,53.839844,-479.415680,-0.000888,0.003535,0.089801,239.491592,12.200283,0.898012,-479.415680,0.089827,0.000000
88.450005,53.818245,-479.415680,-0.000888,0.003535,0.089801,239.395508,12.195388,0.898012,-479.415680,0.089827,0.000000
88.670006,53.791061,-479.415680,-0.000871,0.003535,0.089801,239.274597,12.189229,0.898012,-479.415680,0.089827,0.000000
88.890007,53.769463,-479.460175,-0.000854,0.003535,0.089801,239.178513,12.184335,0.898012,-479.460175,0.089827,0.000000
89.110001,53.770210,-479.460175,-0.000892,0.003535,0.089801,239.181839,12.184505,0.898012,-479.460175,0.089827,0.000000
89.330002,53.740791,-479.460175,-0.000875,0.003535,0.089801,239.050980,12.177837,0.898012,-479.460175,0.089827,0.000000
89.550003,53.729996,-479.504639,-0.000910,0.003535,0.089801,239.002960,12.175391,0.898012,-479.504639,0.089827,0.000000
89.770004,53.712494,-479.504639,-0.000871,0.003535,0.089801,238.925110,12.171425,0.898012,-479.504639,0.089827,0.000000
89.990005,53.687912,-479.504639,-0.000880,0.003535,0.089801,238.815765,12.165854,0.898012,-479.504639,0.089827,0.000000
90.210007,53.668182,-479.460175,-0.000880,0.003535,0.089801,238.727997,12.161385,0.898012,-479.460175,0.089827,0.000000
90.430008,53.646210,-479.504639,-0.000897,0.003535,0.089801,238.630264,12.156404,0.898012,-479.504639,0.089827,0.000000
90.650002,53.613068,-479.504639,-0.000880,0.003535,0.089801,238.482834,12.148895,0.898012,-479.504639,0.089827,0.000000
90.870003,53.606735,-479.549133,-0.000875,0.003535,0.089801,238.454666,12.147460,0.898012,-479.549133,0.089827,0.000000
91.000008,53.587746,-479.549133,-0.000910,0.003535,0.089801,238.370193,12.143157,0.898012,-479.549133,0.089827,0.000000