File: Data/compression 14/AutoNoHeating-10-14-3-240726_07262024_162317.csv
Time (sec),S:Load (lbs),S:HL1 (DIM),S:LVDT (in),S:Position (in),Ch:Position (mm),Ch:Load (N),Ch:Stress (MPa),Ch:Strain (mm/mm),Ch:HL1 (DIM),Set Point (),Cycles ()
0.110000,-0.002609,-290.193726,-0.012991,-0.008070,-0.204986,-0.011607,-0.000591,-2.049861,-290.193726,-0.204795,0.000000
0.380000,-0.008942,-290.149231,-0.012965,-0.008070,-0.204986,-0.039774,-0.002026,-2.049861,-290.149231,-0.204795,0.000000
0.650000,0.001114,-290.238220,-0.012995,-0.007944,-0.201777,0.004955,0.000252,-2.017773,-290.238220,-0.200719,0.000000
0.920000,-0.017502,-290.193726,-0.012831,-0.007772,-0.197397,-0.077852,-0.003966,-1.973974,-290.193726,-0.196227,0.000000
1.190000,0.008934,-290.282684,-0.012637,-0.007596,-0.192931,0.039741,0.002024,-1.929312,-290.282684,-0.191734,0.000000
1.460000,0.005959,-290.282684,-0.012447,-0.007411,-0.188231,0.026505,0.001350,-1.882312,-290.282684,-0.187225,0.000000
1.730000,-0.023460,-290.327179,-0.012284,-0.007241,-0.183921,-0.104357,-0.005316,-1.839209,-290.327179,-0.182733,0.000000
2.000000,-0.008194,-290.327179,-0.012115,-0.007078,-0.179776,-0.036449,-0.001857,-1.797757,-290.327179,-0.178241,0.000000
2.270000,-0.049156,-290.282684,-0.011891,-0.006887,-0.174936,-0.218658,-0.011139,-1.749363,-290.282684,-0.173731,0.000000
2.540000,0.008194,-290.371643,-0.011723,-0.006709,-0.170419,0.036449,0.001857,-1.704187,-290.371643,-0.169239,0.000000
2.810000,0.012291,-290.416138,-0.011512,-0.006528,-0.165822,0.054673,0.002785,-1.658223,-290.416138,-0.164747,0.000000
3.080000,-0.019737,-290.416138,-0.011357,-0.006358,-0.161486,-0.087796,-0.004473,-1.614856,-290.416138,-0.160237,0.000000
3.350000,0.017128,-290.416138,-0.011175,-0.006186,-0.157115,0.076189,0.003881,-1.571148,-290.416138,-0.155745,0.000000
3.620000,-0.023834,-290.416138,-0.010981,-0.005999,-0.152362,-0.106020,-0.005401,-1.523625,-290.416138,-0.151253,0.000000
3.890000,-0.000748,-290.505096,-0.010787,-0.005821,-0.147853,-0.003326,-0.000169,-1.478531,-290.505096,-0.146743,0.000000
4.160000,-0.005211,-290.505096,-0.010563,-0.005642,-0.143300,-0.023179,-0.001181,-1.432999,-290.505096,-0.142251,0.000000
4.430000,-0.061440,-290.549561,-0.010412,-0.005469,-0.138912,-0.273297,-0.013922,-1.389117,-290.549561,-0.137759,0.000000
4.700000,0.028297,-290.549561,-0.010248,-0.005294,-0.134472,0.125873,0.006412,-1.344720,-290.549561,-0.133249,0.000000
4.970000,-0.005585,-290.594055,-0.010063,-0.005113,-0.129867,-0.024842,-0.001266,-1.298666,-290.594055,-0.128757,0.000000
5.240000,0.004837,-290.594055,-0.009865,-0.004934,-0.125322,0.021516,0.001096,-1.253224,-290.594055,-0.124265,0.000000
5.510000,0.024948,-290.594055,-0.009710,-0.004769,-0.121142,0.110975,0.005653,-1.211424,-290.594055,-0.119755,0.000000
5.780000,-0.018990,-290.638519,-0.009511,-0.004581,-0.116364,-0.084470,-0.004303,-1.163643,-290.638519,-0.115263,0.000000
6.050000,0.011917,-290.638519,-0.009300,-0.004408,-0.111967,0.053010,0.002700,-1.119670,-290.638519,-0.110770,0.000000
6.320000,-0.020851,-290.638519,-0.009136,-0.004224,-0.107293,-0.092750,-0.004725,-1.072927,-290.638519,-0.106261,0.000000
6.590000,-0.024574,-290.683014,-0.008942,-0.004055,-0.103000,-0.109312,-0.005569,-1.029999,-290.683014,-0.101769,0.000000
6.860000,0.013405,-290.771973,-0.008752,-0.003881,-0.098578,0.059628,0.003038,-0.985776,-290.771973,-0.097276,0.000000
7.130000,0.005211,-290.727509,-0.008541,-0.003699,-0.093955,0.023179,0.001181,-0.939547,-290.727509,-0.092767,0.000000
7.400001,0.024200,-290.727509,-0.008403,-0.003525,-0.089523,0.107649,0.005484,-0.895234,-290.727509,-0.088275,0.000000
7.670001,0.033516,-290.771973,-0.008175,-0.003340,-0.084841,0.149086,0.007595,-0.848407,-290.771973,-0.083765,0.000000
7.940001,-0.008568,-290.771973,-0.008002,-0.003163,-0.080331,-0.038112,-0.001941,-0.803306,-290.771973,-0.079273,0.000000
8.210000,0.012291,-290.860931,-0.007808,-0.002997,-0.076117,0.054673,0.002785,-0.761165,-290.860931,-0.074780,0.000000
8.480000,-0.047295,-290.905426,-0.007666,-0.002812,-0.071425,-0.210377,-0.010717,-0.714248,-290.905426,-0.070271,0.000000
8.750000,-0.017876,-290.860931,-0.007450,-0.002641,-0.067089,-0.079515,-0.004051,-0.670888,-290.860931,-0.065779,0.000000
9.020000,0.026436,-290.816467,-0.007286,-0.002456,-0.062388,0.117593,0.005990,-0.623879,-290.816467,-0.061287,0.000000
9.290001,0.007820,-290.905426,-0.007067,-0.002283,-0.057982,0.034786,0.001772,-0.579823,-290.905426,-0.056777,0.000000
9.560000,0.043564,-290.949890,-0.006894,-0.002112,-0.053646,0.193782,0.009872,-0.536463,-290.949890,-0.052285,0.000000
9.830001,0.024574,-291.038849,-0.006696,-0.001926,-0.048929,0.109312,0.005569,-0.489289,-291.038849,-0.047793,0.000000
10.100000,0.014519,-290.949890,-0.006493,-0.001748,-0.044402,0.064583,0.003290,-0.444021,-290.949890,-0.043283,0.000000
10.370001,0.006332,-290.994385,-0.006325,-0.001574,-0.039970,0.028168,0.001435,-0.399700,-290.994385,-0.038791,0.000000
10.640000,-0.024574,-290.994385,-0.006165,-0.001396,-0.035469,-0.109312,-0.005569,-0.354690,-290.994385,-0.034299,0.000000
10.910001,0.012291,-291.038849,-0.005976,-0.001228,-0.031203,0.054673,0.002785,-0.312027,-291.038849,-0.029789,0.000000
11.180000,0.037239,-291.038849,-0.005769,-0.001046,-0.026563,0.165648,0.008438,-0.265631,-291.038849,-0.025297,0.000000
11.450001,0.026436,-291.083344,-0.005583,-0.000864,-0.021949,0.117593,0.005990,-0.219494,-291.083344,-0.020805,0.000000
11.720000,0.055107,-291.083344,-0.005437,-0.000690,-0.017535,0.245129,0.012487,-0.175354,-291.083344,-0.016295,0.000000
11.990001,0.039841,-291.083344,-0.005226,-0.000510,-0.012956,0.177220,0.009028,-0.129565,-291.083344,-0.011803,0.000000
12.260000,0.121017,-291.172302,-0.005044,-0.000340,-0.008629,0.538313,0.027423,-0.086288,-291.172302,-0.007311,0.000000
12.530001,0.408493,-291.261261,-0.004846,-0.000151,-0.003833,1.817068,0.092566,-0.038333,-291.261261,-0.002801,0.000000
12.800000,0.669151,-291.216797,-0.004747,-0.000002,-0.000051,2.976534,0.151632,-0.000515,-291.216797,0.000087,0.000000
13.070001,0.639366,-291.172302,-0.004725,-0.000002,-0.000061,2.844043,0.144882,-0.000606,-291.172302,0.000087,0.000000
13.340001,0.615906,-291.216797,-0.004734,-0.000002,-0.000061,2.739686,0.139566,-0.000606,-291.216797,0.000356,0.000000
13.610001,0.592819,-291.261261,-0.004730,-0.000002,-0.000043,2.636992,0.134335,-0.000431,-291.261261,0.000807,0.000000
13.880001,0.674736,-291.305756,-0.004725,0.000014,0.000365,3.001376,0.152897,0.003649,-291.305756,0.001258,0.000000
14.150001,0.808792,-291.305756,-0.004717,0.000033,0.000850,3.597687,0.183275,0.008501,-291.305756,0.001700,0.000000
14.420001,0.835228,-291.261261,-0.004721,0.000048,0.001223,3.715280,0.189265,0.012233,-291.261261,0.002151,0.000000
14.690001,0.956993,-291.350220,-0.004704,0.000064,0.001622,4.256918,0.216858,0.016222,-291.350220,0.002602,0.000000
14.960001,1.062004,-291.439178,-0.004687,0.000080,0.002029,4.724030,0.240654,0.020295,-291.439178,0.003053,0.000000
15.230000,1.140945,-291.394714,-0.004644,0.000095,0.002411,5.075179,0.258542,0.024110,-291.394714,0.003504,0.000000
15.500001,1.184517,-291.439178,-0.004656,0.000105,0.002671,5.268994,0.268415,0.026714,-291.439178,0.003955,0.000000
15.770000,1.513695,-291.394714,-0.004613,0.000139,0.003530,6.733251,0.343008,0.035298,-291.394714,0.004406,0.000000
16.040001,1.533058,-291.439178,-0.004618,0.000152,0.003851,6.819383,0.347396,0.038508,-291.439178,0.004857,0.000000
16.310001,1.675674,-291.483673,-0.004600,0.000171,0.004337,7.453772,0.379713,0.043367,-291.483673,0.005308,0.000000
16.580000,1.813454,-291.483673,-0.004570,0.000188,0.004770,8.066645,0.410934,0.047697,-291.483673,0.005759,0.000000
16.850000,1.930748,-291.483673,-0.004566,0.000204,0.005178,8.588396,0.437514,0.051777,-291.483673,0.006201,0.000000
17.120001,2.127365,-291.528168,-0.004540,0.000218,0.005534,9.462993,0.482068,0.055335,-291.528168,0.006652,0.000000
17.390001,2.320625,-291.572632,-0.004536,0.000234,0.005950,10.322657,0.525861,0.059499,-291.572632,0.007103,0.000000
17.660002,2.655762,-291.617126,-0.004518,0.000264,0.006704,11.813418,0.601804,0.067038,-291.617126,0.007554,0.000000
17.930000,2.768219,-291.617126,-0.004488,0.000284,0.007225,12.313653,0.627287,0.072246,-291.617126,0.008005,0.000000
18.200001,2.817368,-291.661591,-0.004493,0.000295,0.007502,12.532277,0.638425,0.075017,-291.661591,0.008455,0.000000
18.470001,3.002808,-291.617126,-0.004467,0.000314,0.007988,13.357156,0.680446,0.079876,-291.617126,0.008907,0.000000
18.740002,3.188255,-291.661591,-0.004462,0.000328,0.008343,14.182068,0.722469,0.083434,-291.661591,0.009358,0.000000
19.010000,3.521156,-291.706085,-0.004432,0.000350,0.008881,15.662886,0.797905,0.088809,-291.706085,0.009809,0.000000
19.280001,3.527855,-291.661591,-0.004415,0.000360,0.009141,15.692682,0.799423,0.091413,-291.661591,0.010251,0.000000
19.550001,3.825378,-291.750549,-0.004406,0.000381,0.009679,17.016132,0.866843,0.096787,-291.750549,0.010702,0.000000
19.820002,4.048431,-291.750549,-0.004381,0.000402,0.010199,18.008322,0.917388,0.101988,-291.750549,0.011153,0.000000
20.090000,4.115089,-291.795044,-0.004393,0.000415,0.010529,18.304832,0.932493,0.105288,-291.795044,0.011604,0.000000
20.360001,4.363457,-291.750549,-0.004372,0.000434,0.011031,19.409624,0.988773,0.110315,-291.750549,0.012055,0.000000
20.630001,4.649811,-291.795044,-0.004329,0.000458,0.011630,20.683392,1.053662,0.116302,-291.795044,0.012506,0.000000
20.900002,4.817383,-291.795044,-0.004299,0.000476,0.012081,21.428789,1.091635,0.120806,-291.795044,0.012956,0.000000
21.170000,4.807701,-291.839508,-0.004307,0.000485,0.012315,21.385723,1.089441,0.123153,-291.839508,0.013408,0.000000
21.440001,5.228851,-291.928467,-0.004273,0.000507,0.012878,23.259092,1.184875,0.128785,-291.928467,0.013859,0.000000
21.710001,5.430679,-291.972961,-0.004264,0.000527,0.013382,24.156868,1.230610,0.133819,-291.972961,0.014301,0.000000
21.980001,5.544624,-291.972961,-0.004264,0.000544,0.013816,24.663721,1.256430,0.138156,-291.972961,0.014752,0.000000
22.250002,5.672348,-292.017456,-0.004230,0.000559,0.014197,25.231865,1.285372,0.141971,-292.017456,0.015203,0.000000
22.520000,5.848106,-292.017456,-0.004217,0.000575,0.014604,26.013676,1.325200,0.146044,-292.017456,0.015654,0.000000
22.790001,6.054405,-292.017456,-0.004204,0.000593,0.015056,26.931339,1.371948,0.150556,-292.017456,0.016105,0.000000
23.060001,6.183617,-292.061920,-0.004186,0.000609,0.015472,27.506100,1.401228,0.154719,-292.061920,0.016556,0.000000
23.330002,6.507950,-292.061920,-0.004186,0.000628,0.015949,28.948807,1.474723,0.159488,-292.061920,0.017006,0.000000
23.600000,6.860962,-292.017456,-0.004165,0.000655,0.016642,30.519083,1.554716,0.166422,-292.017456,0.017457,0.000000
23.870001,6.814789,-292.061920,-0.004139,0.000669,0.016990,30.313694,1.544253,0.169896,-292.061920,0.017909,0.000000
24.140001,6.820374,-292.106415,-0.004122,0.000683,0.017354,30.338537,1.545519,0.173537,-292.106415,0.018360,0.000000
24.410002,7.111938,-292.106415,-0.004109,0.000703,0.017848,31.635483,1.611588,0.178481,-292.106415,0.018802,0.000000
24.680000,7.369995,-292.106415,-0.004061,0.000722,0.018351,32.783375,1.670065,0.183507,-292.106415,0.019253,0.000000
24.950001,7.383400,-292.195374,-0.004044,0.000736,0.018689,32.843002,1.673102,0.186891,-292.195374,0.019703,0.000000
25.220001,7.544266,-292.195374,-0.004096,0.000749,0.019027,33.558571,1.709555,0.190274,-292.195374,0.020155,0.000000
25.490002,8.059998,-292.239838,-0.004053,0.000779,0.019782,35.852661,1.826421,0.197821,-292.239838,0.020606,0.000000
25.760002,7.964302,-292.284332,-0.004027,0.000792,0.020111,35.426987,1.804737,0.201114,-292.284332,0.021057,0.000000
26.030001,8.093140,-292.239838,-0.003997,0.000810,0.020571,36.000084,1.833932,0.205709,-292.239838,0.021507,0.000000
26.300001,8.139313,-292.239838,-0.003975,0.000826,0.020979,36.205471,1.844395,0.209789,-292.239838,0.021958,0.000000
26.570002,8.477058,-292.239838,-0.003962,0.000846,0.021482,37.707840,1.920929,0.214815,-292.239838,0.022410,0.000000
26.840002,8.514671,-292.417786,-0.003967,0.000861,0.021880,37.875149,1.929452,0.218805,-292.417786,0.022852,0.000000
27.110001,8.376144,-292.373291,-0.003967,0.000868,0.022036,37.258949,1.898061,0.220364,-292.373291,0.023303,0.000000
27.380001,9.143974,-292.328796,-0.003932,0.000898,0.022817,40.674431,2.072054,0.228169,-292.328796,0.023754,0.000000
27.650002,9.062057,-292.373291,-0.003915,0.000916,0.023260,40.310043,2.053492,0.232597,-292.373291,0.024204,0.000000
27.920002,9.066521,-292.373291,-0.003906,0.000933,0.023710,40.329899,2.054503,0.237101,-292.373291,0.024656,0.000000
28.190001,9.247124,-292.417786,-0.003867,0.000951,0.024144,41.133259,2.095428,0.241438,-292.417786,0.025107,0.000000
28.460001,9.399422,-292.506744,-0.003863,0.000971,0.024673,41.810715,2.129939,0.246730,-292.506744,0.025557,0.000000
28.730001,9.429962,-292.462250,-0.003850,0.000984,0.025002,41.946568,2.136860,0.250023,-292.462250,0.026008,0.000000
29.000002,9.438148,-292.417786,-0.003816,0.000999,0.025366,41.982983,2.138715,0.253664,-292.417786,0.026459,0.000000
29.270000,9.991127,-292.551208,-0.003829,0.001024,0.026008,44.442753,2.264022,0.260083,-292.551208,0.026902,0.000000
29.540001,9.983307,-292.506744,-0.003811,0.001042,0.026477,44.407967,2.262249,0.264769,-292.506744,0.027353,0.000000
29.810001,9.937134,-292.640167,-0.003798,0.001058,0.026876,44.202579,2.251787,0.268758,-292.640167,0.027804,0.000000
30.080002,10.158318,-292.551208,-0.003790,0.001076,0.027335,45.186455,2.301908,0.273353,-292.551208,0.028254,0.000000
30.350002,10.321793,-292.640167,-0.003786,0.001096,0.027839,45.913628,2.338952,0.278387,-292.640167,0.028705,0.000000
30.620001,10.439087,-292.595703,-0.003760,0.001112,0.028238,46.435379,2.365531,0.282376,-292.595703,0.029157,0.000000
30.890001,10.242477,-292.684662,-0.003755,0.001120,0.028445,45.560814,2.320979,0.284450,-292.684662,0.029608,0.000000
31.160002,10.470741,-292.684662,-0.003721,0.001137,0.028888,46.576183,2.372704,0.288878,-292.684662,0.030058,0.000000
31.430002,11.104149,-292.684662,-0.003682,0.001169,0.029703,49.393723,2.516236,0.297031,-292.684662,0.030509,0.000000
31.700001,10.994667,-292.684662,-0.003691,0.001185,0.030093,48.906723,2.491427,0.300929,-292.684662,0.030960,0.000000
31.970001,10.915726,-292.773621,-0.003691,0.001198,0.030440,48.555573,2.473539,0.304396,-292.773621,0.031403,0.000000
32.240002,11.105637,-292.818115,-0.003669,0.001216,0.030882,49.400337,2.516573,0.308825,-292.818115,0.031854,0.000000
32.510002,11.327568,-292.773621,-0.003635,0.001236,0.031394,50.387539,2.566864,0.313942,-292.773621,0.032305,0.000000
32.780003,11.262779,-292.773621,-0.003639,0.001248,0.031698,50.099342,2.552182,0.316977,-292.773621,0.032755,0.000000
33.050003,11.307091,-292.818115,-0.003652,0.001260,0.032001,50.296452,2.562223,0.320013,-292.818115,0.033206,0.000000
33.320000,12.126678,-292.818115,-0.003613,0.001292,0.032825,53.942162,2.747945,0.328249,-292.818115,0.033658,0.000000
33.590000,11.866768,-292.862579,-0.003604,0.001306,0.033172,52.786018,2.689048,0.331716,-292.862579,0.034109,0.000000
33.860001,11.815750,-292.907074,-0.003574,0.001324,0.033623,52.559082,2.677487,0.336227,-292.907074,0.034559,0.000000
34.130001,11.965446,-292.862579,-0.003566,0.001341,0.034065,53.224964,2.711409,0.340648,-292.862579,0.035010,0.000000
34.400002,12.411171,-292.951538,-0.003553,0.001362,0.034594,55.207645,2.812412,0.345939,-292.951538,0.035452,0.000000
34.670002,12.126305,-292.996033,-0.003518,0.001372,0.034854,53.940498,2.747860,0.348543,-292.996033,0.035904,0.000000
34.940002,12.652840,-293.040497,-0.003514,0.001397,0.035479,56.282642,2.867174,0.354788,-293.040497,0.036355,0.000000
35.210003,12.692688,-293.040497,-0.003479,0.001415,0.035938,56.459896,2.876204,0.359383,-293.040497,0.036805,0.000000
35.480003,12.716148,-292.951538,-0.003479,0.001433,0.036398,56.564255,2.881520,0.363978,-292.951538,0.037256,0.000000
35.750000,12.586929,-293.040497,-0.003488,0.001447,0.036754,55.989456,2.852239,0.367536,-293.040497,0.037707,0.000000
36.020000,12.869560,-293.040497,-0.003436,0.001463,0.037161,57.246662,2.916284,0.371609,-293.040497,0.038159,0.000000
36.290001,13.034149,-293.129456,-0.003458,0.001478,0.037551,57.978790,2.953580,0.375515,-293.129456,0.038609,0.000000
36.560001,13.029312,-293.129456,-0.003428,0.001492,0.037906,57.957275,2.952484,0.379065,-293.129456,0.039060,0.000000
36.830002,13.260185,-293.084991,-0.003423,0.001512,0.038410,58.984249,3.004801,0.384099,-293.084991,0.039502,0.000000
37.100002,13.876457,-293.173950,-0.003397,0.001537,0.039034,61.725563,3.144450,0.390344,-293.173950,0.039953,0.000000
37.370003,13.612816,-293.218414,-0.003376,0.001551,0.039389,60.552830,3.084708,0.393894,-293.218414,0.040405,0.000000
37.640003,13.727509,-293.262909,-0.003389,0.001570,0.039867,61.063007,3.110698,0.398671,-293.262909,0.040856,0.000000
37.910004,13.798630,-293.173950,-0.003363,0.001586,0.040292,61.379372,3.126814,0.402917,-293.173950,0.041306,0.000000
38.180000,13.657875,-293.173950,-0.003346,0.001602,0.040682,60.753262,3.094919,0.406816,-293.173950,0.041757,0.000000
38.450001,13.942368,-293.218414,-0.003324,0.001620,0.041142,62.018749,3.159386,0.411418,-293.218414,0.042208,0.000000
38.720001,14.070465,-293.262909,-0.003341,0.001634,0.041506,62.588554,3.188413,0.415059,-293.262909,0.042660,0.000000
38.990002,14.728073,-293.307404,-0.003298,0.001662,0.042217,65.513741,3.337429,0.422167,-293.307404,0.043110,0.000000
39.260002,14.831223,-293.396362,-0.003251,0.001685,0.042789,65.972572,3.360803,0.427890,-293.396362,0.043561,0.000000
39.530003,14.402252,-293.307404,-0.003272,0.001696,0.043067,64.064415,3.263597,0.430668,-293.307404,0.044003,0.000000
39.800003,14.561249,-293.307404,-0.003260,0.001713,0.043509,64.771667,3.299626,0.435089,-293.307404,0.044454,0.000000
40.070004,14.585083,-293.440826,-0.003238,0.001728,0.043882,64.877693,3.305027,0.438821,-293.440826,0.044906,0.000000
40.340000,14.998787,-293.485321,-0.003234,0.001750,0.044454,66.717934,3.398774,0.444543,-293.485321,0.045356,0.000000
40.610001,14.712433,-293.440826,-0.003212,0.001760,0.044697,65.444168,3.333885,0.446973,-293.440826,0.045807,0.000000
40.880001,15.215141,-293.396362,-0.003186,0.001783,0.045278,67.680328,3.447800,0.452779,-293.396362,0.046258,0.000000
41.150002,15.275459,-293.440826,-0.003165,0.001800,0.045721,67.948639,3.461468,0.457208,-293.440826,0.046709,0.000000
41.420002,15.171570,-293.485321,-0.003191,0.001816,0.046120,67.486511,3.437927,0.461197,-293.485321,0.047160,0.000000
41.690002,15.340256,-293.485321,-0.003160,0.001836,0.046631,68.236862,3.476152,0.466314,-293.485321,0.047611,0.000000
41.960003,15.656769,-293.529785,-0.003173,0.001857,0.047169,69.644783,3.547874,0.471689,-293.529785,0.048053,0.000000
42.230003,15.613205,-293.485321,-0.003117,0.001875,0.047620,69.451004,3.538003,0.476200,-293.485321,0.048504,0.000000
42.500004,15.270622,-293.574280,-0.003122,0.001885,0.047871,67.927124,3.460372,0.478714,-293.574280,0.048955,0.000000
42.770000,15.746887,-293.618744,-0.003139,0.001907,0.048435,70.045654,3.568296,0.484345,-293.618744,0.049407,0.000000
43.040001,15.942383,-293.618744,-0.003096,0.001926,0.048921,70.915260,3.612596,0.489205,-293.618744,0.049857,0.000000
43.310001,15.916687,-293.618744,-0.003070,0.001943,0.049354,70.800957,3.606773,0.493543,-293.618744,0.050308,0.000000
43.580002,15.837372,-293.663239,-0.003091,0.001958,0.049736,70.448151,3.588800,0.497358,-293.663239,0.050759,0.000000
43.850002,15.905518,-293.707733,-0.003053,0.001976,0.050178,70.751274,3.604242,0.501779,-293.707733,0.051210,0.000000
44.120003,16.047394,-293.663239,-0.003065,0.001994,0.050646,71.382370,3.636391,0.506464,-293.663239,0.051661,0.000000
44.390003,16.074203,-293.663239,-0.003014,0.002008,0.051011,71.501625,3.642467,0.510105,-293.663239,0.052104,0.000000
44.660004,16.384758,-293.663239,-0.003014,0.002027,0.051479,72.883041,3.712839,0.514791,-293.663239,0.052554,0.000000
44.930000,16.887833,-293.707733,-0.003001,0.002054,0.052182,75.120834,3.826838,0.521816,-293.707733,0.053005,0.000000
45.200001,16.478226,-293.796692,-0.003009,0.002068,0.052519,73.298805,3.734019,0.525192,-293.796692,0.053456,0.000000
45.470001,16.241394,-293.885651,-0.002984,0.002084,0.052927,72.245331,3.680352,0.529272,-293.885651,0.053907,0.000000
45.740002,16.401520,-293.796692,-0.002975,0.002102,0.053396,72.957603,3.716638,0.533958,-293.796692,0.054358,0.000000
46.010002,16.679306,-293.841156,-0.002984,0.002121,0.053873,74.193260,3.779585,0.538727,-293.841156,0.054809,0.000000
46.280003,16.453278,-293.841156,-0.002940,0.002135,0.054219,73.187836,3.728366,0.542194,-293.841156,0.055260,0.000000
46.550003,16.466682,-293.885651,-0.002928,0.002149,0.054575,73.247459,3.731404,0.545752,-293.885651,0.055711,0.000000
46.820004,17.262070,-293.930115,-0.002902,0.002179,0.055338,76.785522,3.911641,0.553382,-293.930115,0.056162,0.000000
47.090004,16.882248,-293.930115,-0.002910,0.002191,0.055659,75.095993,3.825572,0.556592,-293.930115,0.056604,0.000000
47.360001,16.859535,-293.930115,-0.002867,0.002209,0.056110,74.994957,3.820425,0.561096,-293.930115,0.057055,0.000000
47.630001,16.645790,-293.930115,-0.002854,0.002225,0.056518,74.044174,3.771990,0.565176,-293.930115,0.057506,0.000000
47.900002,17.028961,-294.019073,-0.002880,0.002246,0.057047,75.748604,3.858818,0.570467,-294.019073,0.057957,0.000000
48.170002,16.946671,-294.063568,-0.002850,0.002261,0.057428,75.382553,3.840171,0.574282,-294.063568,0.058408,0.000000
48.440002,16.500198,-294.019073,-0.002841,0.002270,0.057662,73.396545,3.738998,0.576621,-294.019073,0.058859,0.000000
48.710003,17.616570,-294.063568,-0.002871,0.002299,0.058390,78.362411,3.991972,0.583903,-294.063568,0.059310,0.000000
48.980003,17.465759,-294.108063,-0.002833,0.002316,0.058816,77.691574,3.957798,0.588158,-294.108063,0.059761,0.000000
49.250004,17.391281,-294.108063,-0.002824,0.002333,0.059267,77.360283,3.940921,0.592669,-294.108063,0.060212,0.000000
49.520000,17.237495,-294.152527,-0.002811,0.002349,0.059657,76.676208,3.906072,0.596568,-294.152527,0.060654,0.000000
49.790001,17.533531,-294.152527,-0.002790,0.002372,0.060246,77.993042,3.973155,0.602464,-294.152527,0.061105,0.000000
50.060001,17.244942,-294.152527,-0.002790,0.002383,0.060524,76.709335,3.907760,0.605243,-294.152527,0.061556,0.000000
50.330002,17.332451,-294.197021,-0.002755,0.002402,0.061019,77.098595,3.927589,0.610186,-294.197021,0.062007,0.000000
50.600002,17.877228,-294.197021,-0.002772,0.002426,0.061626,79.521881,4.051038,0.616257,-294.197021,0.062458,0.000000
50.870003,17.696999,-294.285980,-0.002751,0.002442,0.062025,78.720184,4.010197,0.620246,-294.285980,0.062909,0.000000
51.140003,17.620667,-294.241486,-0.002725,0.002458,0.062441,78.380638,3.992900,0.624409,-294.241486,0.063360,0.000000
51.410004,17.712639,-294.285980,-0.002746,0.002476,0.062883,78.789749,4.013741,0.628830,-294.285980,0.063811,0.000000
51.680004,17.911858,-294.330444,-0.002708,0.002495,0.063368,79.675919,4.058885,0.633682,-294.330444,0.064261,0.000000
51.950001,17.939041,-294.330444,-0.002712,0.002511,0.063767,79.796837,4.065045,0.637672,-294.330444,0.064713,0.000000
52.220001,17.510445,-294.374939,-0.002699,0.002519,0.063993,77.890350,3.967923,0.639927,-294.374939,0.065155,0.000000
52.490002,18.573196,-294.374939,-0.002673,0.002549,0.064747,82.617706,4.208746,0.647474,-294.374939,0.065606,0.000000
52.760002,18.629791,-294.374939,-0.002665,0.002568,0.065233,82.869453,4.221571,0.652334,-294.374939,0.066057,0.000000
53.030003,18.448822,-294.374939,-0.002669,0.002585,0.065658,82.064461,4.180562,0.656581,-294.374939,0.066508,0.000000
53.300003,18.193375,-294.463898,-0.002660,0.002598,0.065996,80.928169,4.122678,0.659965,-294.463898,0.066959,0.000000
53.570004,18.416428,-294.463898,-0.002656,0.002617,0.066482,81.920364,4.173222,0.664817,-294.463898,0.067410,0.000000
53.840004,18.694214,-294.463898,-0.002604,0.002635,0.066925,83.156013,4.236169,0.669245,-294.463898,0.067861,0.000000
54.110004,18.627556,-294.463898,-0.002617,0.002648,0.067271,82.859505,4.221065,0.672712,-294.463898,0.068312,0.000000
54.380001,18.448074,-294.508362,-0.002578,0.002659,0.067540,82.061134,4.180393,0.675399,-294.508362,0.068762,0.000000
54.650002,19.599075,-294.552856,-0.002591,0.002692,0.068381,87.181038,4.441214,0.683809,-294.552856,0.069205,0.000000
54.920002,19.255005,-294.597351,-0.002574,0.002708,0.068772,85.650543,4.363247,0.687715,-294.597351,0.069656,0.000000
55.190002,19.282188,-294.597351,-0.002570,0.002724,0.069179,85.771461,4.369406,0.691788,-294.597351,0.070107,0.000000
55.460003,19.117973,-294.552856,-0.002583,0.002742,0.069638,85.040993,4.332195,0.696383,-294.552856,0.070558,0.000000
55.730003,19.651581,-294.597351,-0.002514,0.002761,0.070142,87.414597,4.453112,0.701417,-294.597351,0.071009,0.000000
56.000004,19.251656,-294.641815,-0.002535,0.002771,0.070385,85.635643,4.362488,0.703847,-294.641815,0.071460,0.000000
56.270004,20.120026,-294.641815,-0.002505,0.002799,0.071095,89.498344,4.559263,0.710955,-294.641815,0.071911,0.000000
56.540001,19.950226,-294.641815,-0.002501,0.002813,0.071460,88.743034,4.520786,0.714596,-294.641815,0.072362,0.000000
56.810001,20.063431,-294.641815,-0.002496,0.002833,0.071946,89.246597,4.546439,0.719456,-294.641815,0.072812,0.000000
57.080002,19.895485,-294.686310,-0.002475,0.002846,0.072292,88.499535,4.508381,0.722923,-294.686310,0.073255,0.000000
57.350002,20.033638,-294.775269,-0.002445,0.002862,0.072683,89.114075,4.539688,0.726829,-294.775269,0.073706,0.000000
57.620003,20.242912,-294.819733,-0.002419,0.002880,0.073151,90.044968,4.587110,0.731507,-294.819733,0.074157,0.000000
57.890003,20.206421,-294.775269,-0.002445,0.002895,0.073524,89.882652,4.578840,0.735239,-294.775269,0.074608,0.000000
58.160004,20.532990,-294.730774,-0.002397,0.002911,0.073940,91.335297,4.652842,0.739402,-294.730774,0.075059,0.000000
58.430004,21.356308,-294.775269,-0.002423,0.002936,0.074565,94.997604,4.839408,0.745647,-294.775269,0.075509,0.000000
58.700005,20.988770,-294.775269,-0.002402,0.002949,0.074911,93.362709,4.756123,0.749114,-294.775269,0.075961,0.000000
58.970001,21.172722,-294.908691,-0.002384,0.002968,0.075388,94.180969,4.797807,0.753883,-294.908691,0.076412,0.000000
59.240002,21.197670,-294.908691,-0.002358,0.002985,0.075813,94.291946,4.803461,0.758130,-294.908691,0.076863,0.000000
59.510002,20.973137,-294.864227,-0.002354,0.002998,0.076160,93.293175,4.752581,0.761604,-294.864227,0.077313,0.000000
59.780003,21.346626,-294.864227,-0.002367,0.003014,0.076568,94.954536,4.837214,0.765677,-294.864227,0.077756,0.000000
60.050003,21.631119,-294.953186,-0.002324,0.003033,0.077027,96.220024,4.901682,0.770272,-294.953186,0.078207,0.000000
60.320004,22.570984,-294.997681,-0.002333,0.003062,0.077774,100.400749,5.114658,0.777735,-294.997681,0.078658,0.000000
60.590004,22.760521,-294.997681,-0.002333,0.003084,0.078337,101.243851,5.157608,0.783367,-294.997681,0.079109,0.000000
60.860004,22.042961,-294.997681,-0.002272,0.003094,0.078597,98.051987,4.995007,0.785971,-294.997681,0.079560,0.000000
61.130001,22.204567,-295.042145,-0.002289,0.003111,0.079031,98.770844,5.031627,0.790309,-295.042145,0.080010,0.000000
61.400002,22.195259,-295.086639,-0.002251,0.003126,0.079412,98.729446,5.029518,0.794124,-295.086639,0.080462,0.000000
61.670002,22.723656,-295.175598,-0.002233,0.003147,0.079924,101.079872,5.149254,0.799241,-295.175598,0.080913,0.000000
61.940002,22.580666,-295.131104,-0.002229,0.003160,0.080271,100.443817,5.116852,0.802708,-295.131104,0.081363,0.000000
62.210003,23.105339,-295.175598,-0.002220,0.003180,0.080773,102.777679,5.235744,0.807734,-295.175598,0.081806,0.000000
62.480003,23.447174,-295.131104,-0.002220,0.003199,0.081259,104.298241,5.313205,0.812594,-295.131104,0.082256,0.000000
62.750004,23.468773,-295.220062,-0.002212,0.003217,0.081719,104.394318,5.318100,0.817189,-295.220062,0.082708,0.000000
63.020004,23.688103,-295.220062,-0.002199,0.003236,0.082205,105.369942,5.367801,0.822049,-295.220062,0.083159,0.000000
63.290005,24.105156,-295.220062,-0.002177,0.003255,0.082682,107.225090,5.462306,0.826818,-295.220062,0.083610,0.000000
63.560001,24.098831,-295.175598,-0.002182,0.003273,0.083124,107.196953,5.460874,0.831239,-295.175598,0.084060,0.000000
63.830002,23.745819,-295.264557,-0.002173,0.003282,0.083358,105.626678,5.380879,0.833578,-295.264557,0.084511,0.000000
64.100006,24.743034,-295.220062,-0.002160,0.003308,0.084035,110.062515,5.606852,0.840345,-295.220062,0.084963,0.000000
64.370003,24.860703,-295.309021,-0.002134,0.003325,0.084451,110.585930,5.633516,0.844508,-295.309021,0.085414,0.000000
64.639999,25.050987,-295.398010,-0.002100,0.003344,0.084928,111.432358,5.676635,0.849277,-295.398010,0.085856,0.000000
64.910004,24.929962,-295.353516,-0.002091,0.003358,0.085292,110.894012,5.649210,0.852919,-295.353516,0.086307,0.000000
65.180000,25.109444,-295.353516,-0.002087,0.003373,0.085665,111.692383,5.689881,0.856650,-295.353516,0.086757,0.000000
65.450005,25.658325,-295.398010,-0.002104,0.003393,0.086185,114.133934,5.814260,0.861851,-295.398010,0.087209,0.000000
65.720001,25.622574,-295.442474,-0.002057,0.003407,0.086532,113.974899,5.806158,0.865318,-295.442474,0.087660,0.000000
65.990005,26.310722,-295.442474,-0.002052,0.003427,0.087053,117.035934,5.962095,0.870526,-295.442474,0.088111,0.000000
66.260002,27.303841,-295.398010,-0.002013,0.003453,0.087712,121.453552,6.187139,0.877119,-295.398010,0.088561,0.000000
66.530006,26.986572,-295.442474,-0.002035,0.003466,0.088041,120.042267,6.115244,0.880412,-295.442474,0.089012,0.000000
66.800003,26.892738,-295.442474,-0.002022,0.003482,0.088448,119.624878,6.093982,0.884485,-295.442474,0.089464,0.000000
67.070000,27.086746,-295.575928,-0.002001,0.003497,0.088822,120.487862,6.137945,0.888216,-295.575928,0.089914,0.000000
67.340004,27.901497,-295.531433,-0.002001,0.003520,0.089403,124.112061,6.322569,0.894030,-295.531433,0.090357,0.000000
67.610001,27.791275,-295.531433,-0.001970,0.003532,0.089707,123.621765,6.297593,0.897066,-295.531433,0.090807,0.000000
67.880005,28.035919,-295.531433,-0.001962,0.003546,0.090079,124.709999,6.353030,0.900790,-295.531433,0.091258,0.000000
68.150002,29.581268,-295.620392,-0.001940,0.003578,0.090877,131.584061,6.703211,0.908768,-295.620392,0.091710,0.000000
68.420006,29.427109,-295.620392,-0.001962,0.003590,0.091198,130.898315,6.668278,0.911978,-295.620392,0.092161,0.000000
68.690002,29.774529,-295.709351,-0.001927,0.003608,0.091640,132.443710,6.747005,0.916399,-295.709351,0.092611,0.000000
68.960007,29.926826,-295.664886,-0.001893,0.003625,0.092065,133.121170,6.781516,0.920653,-295.664886,0.093062,0.000000
69.230003,30.725937,-295.709351,-0.001919,0.003645,0.092594,136.675797,6.962597,0.925937,-295.709351,0.093513,0.000000
69.500000,30.891273,-295.709351,-0.001880,0.003659,0.092949,137.411255,7.000062,0.929495,-295.709351,0.093965,0.000000
69.770004,30.933723,-295.798309,-0.001871,0.003671,0.093245,137.600067,7.009682,0.932447,-295.798309,0.094407,0.000000
70.040001,32.449654,-295.753845,-0.001845,0.003698,0.093921,144.343262,7.353197,0.939207,-295.753845,0.094858,0.000000
70.310005,32.729675,-295.798309,-0.001854,0.003715,0.094354,145.588867,7.416650,0.943544,-295.798309,0.095308,0.000000
70.580002,33.236473,-295.753845,-0.001850,0.003734,0.094840,147.843216,7.531492,0.948404,-295.753845,0.095759,0.000000
70.850006,33.682579,-295.842804,-0.001837,0.003750,0.095257,149.827591,7.632581,0.952567,-295.842804,0.096211,0.000000
71.120003,34.434769,-295.931763,-0.001845,0.003772,0.095820,153.173508,7.803030,0.958199,-295.931763,0.096662,0.000000
71.390007,34.413544,-295.887299,-0.001802,0.003781,0.096045,153.079086,7.798221,0.960455,-295.887299,0.097112,0.000000
71.660004,35.048065,-295.798309,-0.001811,0.003801,0.096557,155.901581,7.942005,0.965572,-295.798309,0.097563,0.000000
71.930000,36.254181,-295.887299,-0.001776,0.003827,0.097199,161.266647,8.215315,0.971991,-295.887299,0.098014,0.000000
72.200005,36.715553,-295.931763,-0.001763,0.003841,0.097555,163.318939,8.319863,0.975549,-295.931763,0.098456,0.000000
72.470001,37.109146,-296.065216,-0.001755,0.003857,0.097970,165.069733,8.409053,0.979705,-296.065216,0.098908,0.000000
72.740005,37.783890,-296.020721,-0.001725,0.003874,0.098404,168.071136,8.561952,0.984042,-296.020721,0.099358,0.000000
73.010002,38.641090,-295.976257,-0.001712,0.003893,0.098890,171.884155,8.756196,0.988902,-295.976257,0.099809,0.000000
73.280006,39.235023,-296.020721,-0.001716,0.003909,0.099289,174.526108,8.890783,0.992891,-296.020721,0.100260,0.000000
73.550003,39.195923,-295.976257,-0.001712,0.003918,0.099523,174.352173,8.881923,0.995231,-295.976257,0.100712,0.000000
73.820000,41.177315,-296.109680,-0.001712,0.003948,0.100278,183.165848,9.330914,1.002778,-296.109680,0.101162,0.000000
74.090004,42.197243,-296.109680,-0.001694,0.003967,0.100763,187.702713,9.562033,1.007630,-296.109680,0.101613,0.000000
74.360001,42.719688,-296.154175,-0.001694,0.003983,0.101179,190.026657,9.680420,1.011793,-296.154175,0.102064,0.000000
74.630005,43.099876,-296.109680,-0.001664,0.003996,0.101509,191.717819,9.766572,1.015094,-296.109680,0.102515,0.000000
74.900002,43.987244,-296.109680,-0.001651,0.004016,0.101995,195.665039,9.967652,1.019946,-296.109680,0.102957,0.000000
75.170006,44.953178,-296.198639,-0.001664,0.004033,0.102437,199.961731,10.186536,1.024374,-296.198639,0.103409,0.000000
75.440002,45.629776,-296.243134,-0.001630,0.004047,0.102784,202.971375,10.339855,1.027841,-296.243134,0.103859,0.000000
75.710007,45.973106,-296.287628,-0.001630,0.004058,0.103061,204.498596,10.417654,1.030612,-296.287628,0.104310,0.000000
75.980003,48.154465,-296.243134,-0.001621,0.004090,0.103894,214.201752,10.911958,1.038939,-296.243134,0.104761,0.000000
76.250000,48.820633,-296.243134,-0.001621,0.004104,0.104241,217.165024,11.062914,1.042405,-296.243134,0.105213,0.000000
76.520004,49.690872,-296.287628,-0.001600,0.004122,0.104701,221.036041,11.260113,1.047008,-296.287628,0.105663,0.000000
76.790001,50.776711,-296.332092,-0.001595,0.004141,0.105178,225.866089,11.506167,1.051777,-296.332092,0.106114,0.000000
77.060005,51.963089,-296.376587,-0.001595,0.004159,0.105646,231.143372,11.775004,1.056455,-296.376587,0.106565,0.000000
77.330002,52.338814,-296.332092,-0.001578,0.004170,0.105906,232.814667,11.860146,1.059059,-296.332092,0.107007,0.000000
77.600006,53.834259,-296.287628,-0.001595,0.004194,0.106539,239.466751,12.199018,1.065387,-296.287628,0.107458,0.000000
77.870003,55.193047,-296.421051,-0.001552,0.004212,0.106982,245.510925,12.506923,1.069816,-296.421051,0.107910,0.000000
78.140007,56.144829,-296.465546,-0.001569,0.004230,0.107441,249.744675,12.722600,1.074411,-296.465546,0.108360,0.000000
78.410004,56.817703,-296.421051,-0.001539,0.004244,0.107805,252.737762,12.875075,1.078052,-296.421051,0.108811,0.000000
78.680000,57.928490,-296.376587,-0.001513,0.004260,0.108204,257.678802,13.126783,1.082041,-296.376587,0.109262,0.000000
78.950005,59.014328,-296.510010,-0.001548,0.004278,0.108664,262.508850,13.372837,1.086636,-296.510010,0.109713,0.000000
79.220001,59.944145,-296.510010,-0.001535,0.004293,0.109045,266.644867,13.583537,1.090451,-296.510010,0.110164,0.000000
79.490005,61.099617,-296.465546,-0.001518,0.004311,0.109488,271.784668,13.845370,1.094879,-296.465546,0.110615,0.000000
79.760002,63.098885,-296.510010,-0.001518,0.004333,0.110069,280.677856,14.298411,1.100685,-296.510010,0.111057,0.000000
80.030006,63.854431,-296.554504,-0.001522,0.004346,0.110398,284.038696,14.469622,1.103978,-296.554504,0.111508,0.000000
80.300003,65.046387,-296.554504,-0.001492,0.004366,0.110901,289.340790,14.739721,1.109012,-296.554504,0.111959,0.000000
80.570007,66.347839,-296.687958,-0.001513,0.004383,0.111318,295.129944,15.034636,1.113176,-296.687958,0.112410,0.000000
80.840004,67.267960,-296.598969,-0.001500,0.004398,0.111699,299.222839,15.243137,1.116991,-296.598969,0.112861,0.000000
81.110001,67.111938,-296.643463,-0.001466,0.004392,0.111551,298.528809,15.207783,1.115515,-296.643463,0.111786,0.000000
81.380005,66.670685,-296.598969,-0.001470,0.004390,0.111499,296.566010,15.107793,1.114992,-296.598969,0.111551,0.000000
81.650002,66.213776,-296.643463,-0.001479,0.004388,0.111465,294.533569,15.004256,1.114652,-296.643463,0.111551,0.000000
81.920006,65.828003,-296.732422,-0.001444,0.004388,0.111448,292.817596,14.916839,1.114478,-296.732422,0.111551,0.000000
82.190002,65.498077,-296.821381,-0.001466,0.004388,0.111448,291.350006,14.842077,1.114478,-296.821381,0.111551,0.000000
82.460007,65.230347,-296.732422,-0.001431,0.004387,0.111439,290.159088,14.781407,1.114387,-296.732422,0.111551,0.000000
82.730003,64.949570,-296.776917,-0.001470,0.004387,0.111439,288.910126,14.717783,1.114387,-296.776917,0.111551,0.000000
83.000008,64.742172,-296.732422,-0.001462,0.004387,0.111439,287.987579,14.670786,1.114387,-296.732422,0.111551,0.000000
83.270004,64.519485,-296.865875,-0.001449,0.004387,0.111439,286.997009,14.620324,1.114387,-296.865875,0.111551,0.000000
83.540001,64.339996,-296.821381,-0.001444,0.004387,0.111430,286.198608,14.579652,1.114303,-296.821381,0.111551,0.000000
83.810005,64.166473,-296.821381,-0.001427,0.004387,0.111430,285.426727,14.540331,1.114303,-296.821381,0.111551,0.000000
84.080002,64.011566,-296.865875,-0.001444,0.004387,0.111430,284.737671,14.505228,1.114303,-296.865875,0.111551,0.000000
84.350006,63.879379,-296.910339,-0.001431,0.004387,0.111430,284.149658,14.475274,1.114303,-296.910339,0.111551,0.000000
84.620003,63.737503,-296.954834,-0.001449,0.004387,0.111430,283.518585,14.443124,1.114303,-296.954834,0.111551,0.000000
84.890007,63.620575,-296.954834,-0.001440,0.004387,0.111430,282.998444,14.416628,1.114303,-296.954834,0.111551,0.000000
85.160004,63.488754,-296.954834,-0.001449,0.004387,0.111421,282.412079,14.386757,1.114213,-296.954834,0.111551,0.000000
85.430000,63.405716,-296.954834,-0.001462,0.004387,0.111421,282.042725,14.367941,1.114213,-296.954834,0.111551,0.000000
85.700005,63.301453,-296.999298,-0.001431,0.004387,0.111421,281.578918,14.344314,1.114213,-296.999298,0.111551,0.000000
85.970001,63.197563,-297.043793,-0.001475,0.004387,0.111421,281.116791,14.320773,1.114213,-297.043793,0.111551,0.000000
86.240005,63.112663,-297.043793,-0.001444,0.004387,0.111421,280.739136,14.301534,1.114213,-297.043793,0.111551,0.000000
86.510002,63.017708,-297.043793,-0.001440,0.004387,0.111421,280.316772,14.280017,1.114213,-297.043793,0.111551,0.000000
86.780006,62.943604,-297.088287,-0.001431,0.004387,0.111421,279.987122,14.263225,1.114213,-297.088287,0.111551,0.000000
87.050003,62.851257,-297.043793,-0.001423,0.004387,0.111421,279.576355,14.242299,1.114213,-297.043793,0.111551,0.000000
87.320007,62.782738,-297.132751,-0.001423,0.004387,0.111421,279.271576,14.226772,1.114213,-297.132751,0.111551,0.000000
87.590004,62.723160,-297.132751,-0.001444,0.004387,0.111421,279.006561,14.213271,1.114213,-297.132751,0.111551,0.000000
87.860001,62.643845,-297.132751,-0.001444,0.004387,0.111421,278.653748,14.195298,1.114213,-297.132751,0.111551,0.000000
88.130005,62.586502,-297.221710,-0.001436,0.004387,0.111421,278.398651,14.182304,1.114213,-297.221710,0.111551,0.000000
88.400002,62.505325,-297.177246,-0.001440,0.004387,0.111421,278.037567,14.163910,1.114213,-297.177246,0.111551,0.000000
88.670006,62.458778,-297.266205,-0.001444,0.004387,0.111421,277.830536,14.153361,1.114213,-297.266205,0.111551,0.000000
88.940002,62.394730,-297.266205,-0.001431,0.004387,0.111421,277.545624,14.138847,1.114213,-297.266205,0.111551,0.000000
89.210007,62.337387,-297.266205,-0.001457,0.004387,0.111421,277.290558,14.125854,1.114213,-297.266205,0.111551,0.000000
89.480003,62.300522,-297.221710,-0.001418,0.004387,0.111421,277.126556,14.117499,1.114213,-297.221710,0.111551,0.000000
89.750008,62.230515,-297.310669,-0.001427,0.004387,0.111421,276.815155,14.101636,1.114213,-297.310669,0.111551,0.000000
90.020004,62.185081,-297.355164,-0.001431,0.004387,0.111421,276.613068,14.091341,1.114213,-297.355164,0.111551,0.000000
90.290001,62.133698,-297.310669,-0.001462,0.004387,0.111421,276.384491,14.079698,1.114213,-297.310669,0.111551,0.000000
90.560005,62.075981,-297.399628,-0.001423,0.004387,0.111421,276.127747,14.066619,1.114213,-297.399628,0.111551,0.000000
90.830002,62.043213,-297.355164,-0.001423,0.004387,0.111421,275.981995,14.059193,1.114213,-297.355164,0.111551,0.000000
91.100006,61.990334,-297.399628,-0.001449,0.004387,0.111421,275.746765,14.047210,1.114213,-297.399628,0.111551,0.000000
91.370003,61.947884,-297.444122,-0.001431,0.004387,0.111421,275.557953,14.037592,1.114213,-297.444122,0.111551,0.000000
91.640007,61.928146,-297.488586,-0.001444,0.004387,0.111421,275.470154,14.033118,1.114213,-297.488586,0.111551,0.000000
91.910004,61.871544,-297.488586,-0.001436,0.004387,0.111421,275.218384,14.020292,1.114213,-297.488586,0.111551,0.000000
92.180008,61.843246,-297.444122,-0.001418,0.004387,0.111421,275.092499,14.013880,1.114213,-297.444122,0.111551,0.000000
92.450005,61.798187,-297.533081,-0.001449,0.004387,0.111421,274.892059,14.003669,1.114213,-297.533081,0.111551,0.000000
92.720001,61.757599,-297.577576,-0.001449,0.004387,0.111421,274.711517,13.994472,1.114213,-297.577576,0.111551,0.000000
92.990005,61.727440,-297.577576,-0.001410,0.004387,0.111421,274.577362,13.987638,1.114213,-297.577576,0.111551,0.000000
93.260002,61.675308,-297.533081,-0.001423,0.004387,0.111421,274.345459,13.975824,1.114213,-297.533081,0.111551,0.000000
93.530006,61.657059,-297.577576,-0.001440,0.004387,0.111421,274.264282,13.971689,1.114213,-297.577576,0.111551,0.000000
93.800003,61.618332,-297.666534,-0.001457,0.004387,0.111421,274.092041,13.962914,1.114213,-297.666534,0.111551,0.000000
94.070007,61.575508,-297.710999,-0.001427,0.004387,0.111421,273.901550,13.953210,1.114213,-297.710999,0.111551,0.000000
94.340004,61.551308,-297.666534,-0.001410,0.004387,0.111421,273.793884,13.947726,1.114213,-297.666534,0.111551,0.000000
94.610008,61.504387,-297.622040,-0.001431,0.004387,0.111421,273.585175,13.937094,1.114213,-297.622040,0.111551,0.000000
94.880005,61.467148,-297.710999,-0.001418,0.004387,0.111421,273.419525,13.928656,1.114213,-297.710999,0.111551,0.000000
95.150002,61.460449,-297.755493,-0.001453,0.004387,0.111421,273.389740,13.927137,1.114213,-297.755493,0.111551,0.000000
95.420006,61.417625,-297.755493,-0.001431,0.004387,0.111421,273.199249,13.917434,1.114213,-297.755493,0.111551,0.000000
95.690002,61.397514,-297.755493,-0.001418,0.004387,0.111421,273.109772,13.912876,1.114213,-297.755493,0.111551,0.000000
95.960007,61.366982,-297.755493,-0.001431,0.004387,0.111421,272.973969,13.905956,1.114213,-297.755493,0.111551,0.000000
96.230003,61.340546,-297.755493,-0.001444,0.004387,0.111421,272.856384,13.899966,1.114213,-297.755493,0.111551,0.000000
96.500008,61.303680,-297.844452,-0.001414,0.004387,0.111421,272.692383,13.891612,1.114213,-297.844452,0.111551,0.000000
96.770004,61.275749,-297.933411,-0.001444,0.004387,0.111421,272.568146,13.885283,1.114213,-297.933411,0.111551,0.000000
97.040001,61.253036,-297.888916,-0.001423,0.004387,0.111421,272.467102,13.880136,1.114213,-297.888916,0.111551,0.000000
97.310005,61.238884,-297.888916,-0.001410,0.004387,0.111421,272.404175,13.876929,1.114213,-297.888916,0.111551,0.000000
97.580002,61.208351,-297.888916,-0.001418,0.004387,0.111421,272.268341,13.870010,1.114213,-297.888916,0.111551,0.000000
97.850006,61.178558,-297.933411,-0.001431,0.004387,0.111421,272.135834,13.863259,1.114213,-297.933411,0.111551,0.000000
98.120003,61.163666,-297.977905,-0.001418,0.004387,0.111421,272.069580,13.859884,1.114213,-297.977905,0.111551,0.000000
98.390007,61.133133,-298.022369,-0.001427,0.004387,0.111421,271.933746,13.852965,1.114213,-298.022369,0.111551,0.000000
98.660004,61.108551,-297.977905,-0.001431,0.004387,0.111421,271.824402,13.847395,1.114213,-297.977905,0.111551,0.000000
98.930008,61.076904,-298.022369,-0.001440,0.004387,0.111421,271.683624,13.840224,1.114213,-298.022369,0.111551,0.000000
99.200005,61.047112,-298.022369,-0.001414,0.004387,0.111421,271.551117,13.833473,1.114213,-298.022369,0.111551,0.000000
99.470001,61.040039,-298.066864,-0.001401,0.004387,0.111421,271.519653,13.831870,1.114213,-298.066864,0.111551,0.000000
99.740005,61.014343,-298.111328,-0.001397,0.004387,0.111421,271.405365,13.826048,1.114213,-298.111328,0.111551,0.000000
100.010002,61.006523,-298.066864,-0.001453,0.004387,0.111421,271.370575,13.824276,1.114213,-298.066864,0.111551,0.000000
100.280006,60.983810,-298.111328,-0.001431,0.004387,0.111421,271.269531,13.819129,1.114213,-298.111328,0.111551,0.000000
100.550003,60.956253,-298.111328,-0.001427,0.004387,0.111421,271.146942,13.812884,1.114213,-298.111328,0.111551,0.000000
100.820007,60.939125,-298.200287,-0.001457,0.004387,0.111421,271.070770,13.809004,1.114213,-298.200287,0.111551,0.000000
101.090004,60.911942,-298.200287,-0.001436,0.004387,0.111421,270.949860,13.802843,1.114213,-298.200287,0.111551,0.000000
101.360008,60.891464,-298.200287,-0.001393,0.004387,0.111421,270.858765,13.798203,1.114213,-298.200287,0.111551,0.000000
101.630005,60.887741,-298.244781,-0.001444,0.004387,0.111421,270.842194,13.797359,1.114213,-298.244781,0.111551,0.000000
101.900002,60.849380,-298.244781,-0.001410,0.004387,0.111421,270.671570,13.788667,1.114213,-298.244781,0.111551,0.000000
102.170006,60.837463,-298.289246,-0.001418,0.004387,0.111421,270.618561,13.785966,1.114213,-298.289246,0.111551,0.000000
102.440002,60.816612,-298.200287,-0.001431,0.004387,0.111421,270.525787,13.781241,1.114213,-298.200287,0.111551,0.000000
102.710007,60.779373,-298.289246,-0.001436,0.004387,0.111421,270.360168,13.772802,1.114213,-298.289246,0.111551,0.000000
102.980003,60.772301,-298.289246,-0.001423,0.004387,0.111421,270.328705,13.771200,1.114213,-298.289246,0.111551,0.000000
103.250008,60.749588,-298.378235,-0.001449,0.004387,0.111421,270.227661,13.766053,1.114213,-298.378235,0.111551,0.000000
103.520004,60.733574,-298.378235,-0.001423,0.004387,0.111421,270.156433,13.762424,1.114213,-298.378235,0.111551,0.000000
103.790009,60.711235,-298.378235,-0.001423,0.004387,0.111421,270.057068,13.757362,1.114213,-298.378235,0.111551,0.000000
104.060005,60.694473,-298.378235,-0.001431,0.004387,0.111421,269.982513,13.753565,1.114213,-298.378235,0.111551,0.000000
104.330002,60.678833,-298.467194,-0.001414,0.004387,0.111421,269.912933,13.750020,1.114213,-298.467194,0.111551,0.000000
104.600006,60.656494,-298.422699,-0.001457,0.004387,0.111421,269.813568,13.744958,1.114213,-298.422699,0.111551,0.000000
104.870003,60.634155,-298.467194,-0.001410,0.004387,0.111421,269.714203,13.739896,1.114213,-298.467194,0.111551,0.000000
105.140007,60.627449,-298.556152,-0.001418,0.004387,0.111421,269.684357,13.738376,1.114213,-298.556152,0.111551,0.000000
105.410004,60.599152,-298.556152,-0.001397,0.004387,0.111421,269.558502,13.731964,1.114213,-298.556152,0.111551,0.000000
105.680008,60.601753,-298.511658,-0.001453,0.004387,0.111421,269.570068,13.732553,1.114213,-298.511658,0.111551,0.000000
105.950005,60.577927,-298.600616,-0.001427,0.004387,0.111421,269.464081,13.727155,1.114213,-298.600616,0.111551,0.000000
106.220009,60.555580,-298.600616,-0.001423,0.004387,0.111421,269.364685,13.722091,1.114213,-298.600616,0.111551,0.000000
106.490005,60.542549,-298.600616,-0.001423,0.004387,0.111421,269.306702,13.719138,1.114213,-298.600616,0.111551,0.000000
106.760002,60.520203,-298.600616,-0.001436,0.004387,0.111421,269.207306,13.714074,1.114213,-298.600616,0.111551,0.000000
107.030006,60.507919,-298.645111,-0.001414,0.004387,0.111421,269.152679,13.711290,1.114213,-298.645111,0.111551,0.000000
107.300003,60.502335,-298.734070,-0.001449,0.004387,0.111421,269.127838,13.710025,1.114213,-298.734070,0.111551,0.000000
107.570007,60.481110,-298.689575,-0.001449,0.004387,0.111421,269.033417,13.705215,1.114213,-298.689575,0.111551,0.000000
107.840004,60.465096,-298.734070,-0.001410,0.004387,0.111421,268.962189,13.701587,1.114213,-298.734070,0.111551,0.000000
108.110008,60.436424,-298.734070,-0.001427,0.004387,0.111421,268.834656,13.695089,1.114213,-298.734070,0.111551,0.000000
108.380005,60.421898,-298.778534,-0.001436,0.004387,0.111421,268.770020,13.691797,1.114213,-298.778534,0.111551,0.000000
108.650002,60.411842,-298.778534,-0.001449,0.004387,0.111421,268.725281,13.689519,1.114213,-298.778534,0.111551,0.000000
108.920006,60.393227,-298.823029,-0.001423,0.004387,0.111421,268.642487,13.685301,1.114213,-298.823029,0.111551,0.000000
109.190002,60.388756,-298.778534,-0.001444,0.004387,0.111421,268.622589,13.684288,1.114213,-298.778534,0.111551,0.000000
109.460007,60.379448,-298.823029,-0.001414,0.004387,0.111421,268.581207,13.682178,1.114213,-298.823029,0.111551,0.000000
109.730003,60.347054,-298.911987,-0.001436,0.004387,0.111421,268.437103,13.674838,1.114213,-298.911987,0.111551,0.000000
110.000008,60.350777,-298.867523,-0.001436,0.004387,0.111421,268.453674,13.675681,1.114213,-298.867523,0.111551,0.000000
110.270004,60.328430,-298.911987,-0.001406,0.004387,0.111421,268.354248,13.670618,1.114213,-298.911987,0.111551,0.000000
110.540009,60.317635,-298.911987,-0.001414,0.004387,0.111421,268.306244,13.668171,1.114213,-298.911987,0.111551,0.000000
110.810005,60.303482,-298.867523,-0.001440,0.004387,0.111421,268.243286,13.664965,1.114213,-298.867523,0.111551,0.000000
111.080002,60.281517,-298.911987,-0.001423,0.004387,0.111421,268.145569,13.659986,1.114213,-298.911987,0.111551,0.000000
111.350006,60.276299,-298.956482,-0.001431,0.004387,0.111421,268.122375,13.658805,1.114213,-298.956482,0.111551,0.000000
111.400002,60.273323,-299.000946,-0.001397,0.004387,0.111421,268.109131,13.658131,1.114213,-299.000946,0.111551,0.000000