File: Data/compression 14/AutoNoHeating-14-14-4-240726_07262024_170144.csv
Time (sec),S:Load (lbs),S:HL1 (DIM),S:LVDT (in),S:Position (in),Ch:Position (mm),Ch:Load (N),Ch:Stress (MPa),Ch:Strain (mm/mm),Ch:HL1 (DIM),Set Point (),Cycles ()
0.110000,-0.002235,-438.137360,-0.009188,-0.004196,-0.106574,-0.009944,-0.000507,-1.065736,-438.137360,-0.106426,0.000000
0.340000,-0.006332,-438.137360,-0.009162,-0.004196,-0.106574,-0.028168,-0.001435,-1.065736,-438.137360,-0.106426,0.000000
0.570000,-0.000000,-438.137360,-0.009209,-0.004111,-0.104414,-0.000000,-0.000000,-1.044139,-438.137360,-0.103633,0.000000
0.800000,-0.013405,-438.226318,-0.009140,-0.003975,-0.100963,-0.059628,-0.003038,-1.009628,-438.226318,-0.099800,0.000000
1.030000,-0.023834,-438.181854,-0.008938,-0.003821,-0.097042,-0.106020,-0.005401,-0.970424,-438.181854,-0.095968,0.000000
1.260000,-0.026070,-438.226318,-0.008783,-0.003668,-0.093166,-0.115964,-0.005907,-0.931659,-438.226318,-0.092134,0.000000
1.490000,-0.033890,-438.226318,-0.008658,-0.003526,-0.089550,-0.150749,-0.007680,-0.895499,-438.226318,-0.088301,0.000000
1.720000,-0.012665,-438.181854,-0.008485,-0.003366,-0.085500,-0.056336,-0.002870,-0.855000,-438.181854,-0.084468,0.000000
1.950000,0.007446,-438.270813,-0.008330,-0.003218,-0.081727,0.033123,0.001687,-0.817272,-438.270813,-0.080635,0.000000
2.180000,0.008194,-438.315277,-0.008188,-0.003078,-0.078181,0.036449,0.001857,-0.781808,-438.315277,-0.076802,0.000000
2.410000,-0.008568,-438.315277,-0.008002,-0.002908,-0.073853,-0.038112,-0.001941,-0.738531,-438.315277,-0.072968,0.000000
2.640000,-0.039101,-438.226318,-0.007856,-0.002765,-0.070220,-0.173928,-0.008860,-0.702196,-438.226318,-0.069136,0.000000
2.870000,-0.036491,-438.270813,-0.007692,-0.002618,-0.066499,-0.162322,-0.008269,-0.664991,-438.270813,-0.065302,0.000000
3.100000,-0.003349,-438.315277,-0.007524,-0.002460,-0.062483,-0.014898,-0.000759,-0.624833,-438.315277,-0.061469,0.000000
3.330000,-0.005211,-438.315277,-0.007368,-0.002320,-0.058937,-0.023179,-0.001181,-0.589369,-438.315277,-0.057653,0.000000
3.560000,-0.008194,-438.359772,-0.007209,-0.002157,-0.054783,-0.036449,-0.001857,-0.547826,-438.359772,-0.053820,0.000000
3.790000,0.001488,-438.359772,-0.007028,-0.002013,-0.051132,0.006618,0.000337,-0.511317,-438.359772,-0.049987,0.000000
4.020000,-0.019363,-438.315277,-0.006873,-0.001863,-0.047316,-0.086133,-0.004388,-0.473157,-438.315277,-0.046154,0.000000
4.250000,0.001114,-438.359772,-0.006722,-0.001709,-0.043404,0.004955,0.000252,-0.434044,-438.359772,-0.042320,0.000000
4.480000,0.028297,-438.448730,-0.006575,-0.001563,-0.039701,0.125873,0.006412,-0.397013,-438.448730,-0.038488,0.000000
4.710000,-0.008942,-438.359772,-0.006416,-0.001409,-0.035782,-0.039774,-0.002026,-0.357816,-438.359772,-0.034654,0.000000
4.940000,-0.003723,-438.404266,-0.006239,-0.001251,-0.031784,-0.016561,-0.000844,-0.317840,-438.404266,-0.030821,0.000000
5.170000,-0.062561,-438.359772,-0.006101,-0.001106,-0.028089,-0.278285,-0.014177,-0.280892,-438.359772,-0.026988,0.000000
5.400000,-0.050644,-438.448730,-0.005941,-0.000953,-0.024195,-0.225275,-0.011476,-0.241953,-438.448730,-0.023155,0.000000
5.630000,0.011543,-438.493225,-0.005790,-0.000806,-0.020484,0.051347,0.002616,-0.204839,-438.493225,-0.019322,0.000000
5.860000,0.024200,-438.537689,-0.005631,-0.000658,-0.016703,0.107649,0.005484,-0.167027,-438.537689,-0.015489,0.000000
6.090000,0.019737,-438.448730,-0.005476,-0.000498,-0.012645,0.087796,0.004473,-0.126446,-438.448730,-0.011655,0.000000
6.320000,0.006332,-438.493225,-0.005282,-0.000353,-0.008975,0.028168,0.001435,-0.089755,-438.493225,-0.007840,0.000000
6.550000,0.018990,-438.493225,-0.005135,-0.000201,-0.005099,0.084470,0.004303,-0.050990,-438.493225,-0.004007,0.000000
6.780000,0.036118,-438.582184,-0.004997,-0.000048,-0.001214,0.160659,0.008184,-0.012142,-438.582184,-0.000173,0.000000
7.010000,0.736549,-438.582184,-0.004846,0.000088,0.002238,3.276335,0.166904,0.022376,-438.582184,0.003486,0.000000
7.240000,0.569359,-438.537689,-0.004850,-0.000000,-0.000000,2.532634,0.129019,-0.000000,-438.537689,0.000235,0.000000
7.470000,0.553345,-438.493225,-0.004838,-0.000000,-0.000000,2.461400,0.125390,-0.000000,-438.493225,0.000235,0.000000
7.700000,0.635269,-438.537689,-0.004842,-0.000000,-0.000000,2.825818,0.143954,-0.000000,-438.537689,0.000443,0.000000
7.930000,0.595047,-438.537689,-0.004820,0.000000,0.000009,2.646901,0.134840,0.000091,-438.537689,0.000824,0.000000
8.160001,0.709000,-438.626648,-0.004842,0.000012,0.000304,3.153788,0.160662,0.003035,-438.626648,0.001214,0.000000
8.390000,0.899277,-438.582184,-0.004803,0.000027,0.000685,4.000183,0.203779,0.006851,-438.582184,0.001596,0.000000
8.620001,1.156586,-438.493225,-0.004825,0.000049,0.001241,5.144750,0.262086,0.012407,-438.493225,0.001977,0.000000
8.850000,1.306656,-438.626648,-0.004820,0.000062,0.001570,5.812295,0.296092,0.015700,-438.626648,0.002359,0.000000
9.080001,1.420227,-438.626648,-0.004799,0.000070,0.001786,6.317485,0.321828,0.017865,-438.626648,0.002740,0.000000
9.310000,1.599709,-438.671143,-0.004781,0.000085,0.002160,7.115859,0.362499,0.021597,-438.671143,0.003131,0.000000
9.540001,1.740097,-438.626648,-0.004773,0.000099,0.002524,7.740338,0.394312,0.025238,-438.626648,0.003512,0.000000
9.770000,2.258812,-438.626648,-0.004743,0.000122,0.003105,10.047697,0.511854,0.031051,-438.626648,0.003894,0.000000
10.000000,2.332542,-438.671143,-0.004725,0.000131,0.003331,10.375667,0.528562,0.033307,-438.671143,0.004275,0.000000
10.230000,2.731354,-438.715607,-0.004708,0.000152,0.003868,12.149669,0.618934,0.038682,-438.715607,0.004666,0.000000
10.460000,3.026642,-438.715607,-0.004712,0.000170,0.004319,13.463176,0.685847,0.043193,-438.715607,0.005048,0.000000
10.690001,3.206871,-438.671143,-0.004695,0.000183,0.004649,14.264874,0.726687,0.046486,-438.671143,0.005429,0.000000
10.920000,3.389336,-438.715607,-0.004687,0.000195,0.004943,15.076518,0.768034,0.049431,-438.715607,0.005811,0.000000
11.150001,3.585945,-438.760101,-0.004661,0.000207,0.005264,15.951080,0.812587,0.052640,-438.760101,0.006192,0.000000
11.380000,3.854057,-438.804596,-0.004656,0.000218,0.005542,17.143703,0.873342,0.055418,-438.804596,0.006583,0.000000
11.610001,4.431229,-438.804596,-0.004639,0.000244,0.006209,19.711090,1.004131,0.062095,-438.804596,0.006964,0.000000
11.840000,4.453949,-438.760101,-0.004635,0.000251,0.006375,19.812155,1.009279,0.063745,-438.760101,0.007346,0.000000
12.070001,4.830040,-438.804596,-0.004596,0.000269,0.006825,21.485090,1.094503,0.068249,-438.804596,0.007727,0.000000
12.300000,5.312637,-438.804596,-0.004600,0.000288,0.007311,23.631790,1.203861,0.073109,-438.804596,0.008109,0.000000
12.530001,5.529358,-438.804596,-0.004566,0.000304,0.007718,24.595812,1.252970,0.077182,-438.804596,0.008499,0.000000
12.760000,5.712936,-438.893555,-0.004553,0.000317,0.008057,25.412411,1.294570,0.080565,-438.893555,0.008881,0.000000
12.990001,5.822418,-438.849060,-0.004549,0.000326,0.008282,25.899410,1.319379,0.082821,-438.849060,0.009262,0.000000
13.220000,6.112862,-438.849060,-0.004549,0.000340,0.008638,27.191366,1.385194,0.086379,-438.849060,0.009644,0.000000
13.450001,6.629349,-438.849060,-0.004510,0.000360,0.009150,29.488815,1.502232,0.091496,-438.849060,0.010025,0.000000
13.680000,6.837128,-438.893555,-0.004527,0.000372,0.009461,30.413063,1.549315,0.094615,-438.893555,0.010415,0.000000
13.910001,6.912720,-438.893555,-0.004506,0.000383,0.009722,30.749313,1.566445,0.097219,-438.893555,0.010797,0.000000
14.140000,7.269829,-438.938019,-0.004488,0.000397,0.010086,32.337814,1.647367,0.100860,-438.938019,0.011179,0.000000
14.370001,7.890945,-438.849060,-0.004480,0.000424,0.010763,35.100677,1.788114,0.107627,-438.849060,0.011561,0.000000
14.600000,7.936745,-438.982513,-0.004441,0.000434,0.011031,35.304405,1.798492,0.110315,-438.982513,0.011942,0.000000
14.830001,8.093513,-438.938019,-0.004454,0.000448,0.011387,36.001747,1.834016,0.113872,-438.938019,0.012332,0.000000
15.060000,8.373909,-438.938019,-0.004454,0.000464,0.011777,37.249008,1.897555,0.117771,-438.938019,0.012713,0.000000
15.290001,8.742935,-438.938019,-0.004406,0.000480,0.012193,38.890518,1.981177,0.121934,-438.938019,0.013095,0.000000
15.520000,9.224785,-438.938019,-0.004385,0.000497,0.012635,41.033894,2.090366,0.126355,-438.938019,0.013477,0.000000
15.750001,9.135788,-438.982513,-0.004402,0.000505,0.012826,40.638016,2.070199,0.128263,-438.982513,0.013859,0.000000
15.980000,9.532738,-439.026978,-0.004389,0.000523,0.013277,42.403736,2.160149,0.132774,-439.026978,0.014249,0.000000
16.210001,10.077141,-439.071472,-0.004363,0.000544,0.013824,44.825359,2.283513,0.138240,-439.071472,0.014630,0.000000
16.440001,10.235031,-438.982513,-0.004359,0.000559,0.014205,45.527691,2.319291,0.142055,-438.982513,0.015012,0.000000
16.670000,10.233910,-438.982513,-0.004324,0.000570,0.014483,45.522705,2.319037,0.144825,-438.982513,0.015393,0.000000
16.900002,10.403343,-439.026978,-0.004329,0.000583,0.014813,46.276382,2.357431,0.148126,-439.026978,0.015775,0.000000
17.130001,10.768265,-439.160431,-0.004312,0.000596,0.015151,47.899635,2.440124,0.151509,-439.160431,0.016165,0.000000
17.360001,11.297035,-439.115936,-0.004290,0.000620,0.015741,50.251724,2.559945,0.157406,-439.115936,0.016547,0.000000
17.590000,11.424011,-439.071472,-0.004273,0.000630,0.016009,50.816540,2.588718,0.160093,-439.071472,0.016928,0.000000
17.820002,11.272087,-439.071472,-0.004268,0.000636,0.016165,50.140747,2.554291,0.161653,-439.071472,0.017310,0.000000
18.050001,12.147530,-439.115936,-0.004277,0.000663,0.016842,54.034912,2.752670,0.168420,-439.115936,0.017691,0.000000
18.280001,12.393303,-439.160431,-0.004221,0.000679,0.017258,55.128166,2.808362,0.172584,-439.160431,0.018082,0.000000
18.510000,12.309143,-439.160431,-0.004217,0.000690,0.017535,54.753803,2.789292,0.175354,-439.160431,0.018463,0.000000
18.740002,12.416016,-439.115936,-0.004225,0.000702,0.017839,55.229195,2.813509,0.178390,-439.115936,0.018845,0.000000
18.970001,12.904938,-439.160431,-0.004178,0.000721,0.018325,57.404030,2.924301,0.183249,-439.160431,0.019227,0.000000
19.200001,12.986862,-439.160431,-0.004191,0.000734,0.018646,57.768448,2.942865,0.186459,-439.160431,0.019617,0.000000
19.430000,13.284012,-439.204926,-0.004191,0.000750,0.019045,59.090237,3.010200,0.190448,-439.204926,0.019999,0.000000
19.660002,13.443764,-439.249390,-0.004148,0.000762,0.019357,59.800846,3.046400,0.193567,-439.249390,0.020380,0.000000
19.890001,13.621010,-439.249390,-0.004148,0.000778,0.019773,60.589279,3.086565,0.197730,-439.249390,0.020762,0.000000
20.120001,14.336708,-439.249390,-0.004109,0.000800,0.020320,63.772861,3.248744,0.203196,-439.249390,0.021143,0.000000
20.350000,14.464066,-439.249390,-0.004113,0.000815,0.020692,64.339378,3.277604,0.206920,-439.249390,0.021534,0.000000
20.580002,14.519920,-439.293884,-0.004096,0.000828,0.021030,64.587830,3.290261,0.210304,-439.293884,0.021915,0.000000
20.810001,14.591042,-439.293884,-0.004083,0.000840,0.021334,64.904198,3.306377,0.213339,-439.293884,0.022297,0.000000
21.040001,14.890800,-439.338348,-0.004044,0.000857,0.021759,66.237587,3.374304,0.217586,-439.338348,0.022678,0.000000
21.270000,15.288864,-439.293884,-0.004036,0.000874,0.022201,68.008263,3.464506,0.222014,-439.293884,0.023060,0.000000
21.500002,15.483620,-439.293884,-0.004023,0.000889,0.022583,68.874580,3.508638,0.225830,-439.293884,0.023450,0.000000
21.730001,15.278816,-439.338348,-0.004044,0.000895,0.022721,67.963570,3.462229,0.227215,-439.338348,0.023831,0.000000
21.960001,15.552879,-439.338348,-0.004036,0.000910,0.023120,69.182663,3.524333,0.231204,-439.338348,0.024213,0.000000
22.190001,16.113297,-439.338348,-0.004001,0.000930,0.023615,71.675522,3.651325,0.236147,-439.338348,0.024595,0.000000
22.420002,16.450294,-439.293884,-0.003984,0.000947,0.024048,73.174568,3.727690,0.240485,-439.293884,0.024977,0.000000
22.650002,16.551582,-439.338348,-0.003958,0.000962,0.024447,73.625114,3.750642,0.244474,-439.338348,0.025366,0.000000
22.880001,16.849480,-439.382843,-0.003954,0.000977,0.024820,74.950226,3.818147,0.248198,-439.382843,0.025748,0.000000
23.110001,17.091896,-439.427307,-0.003949,0.000994,0.025245,76.028549,3.873079,0.252452,-439.427307,0.026129,0.000000
23.340002,17.040138,-439.382843,-0.003928,0.001005,0.025522,75.798317,3.861351,0.255223,-439.382843,0.026511,0.000000
23.570002,17.227066,-439.427307,-0.003915,0.001018,0.025870,76.629814,3.903709,0.258698,-439.427307,0.026893,0.000000
23.800001,17.178658,-439.382843,-0.003898,0.001028,0.026121,76.414482,3.892740,0.261211,-439.382843,0.027283,0.000000
24.030001,17.357399,-439.471802,-0.003893,0.001047,0.026598,77.209564,3.933243,0.265980,-439.471802,0.027665,0.000000
24.260000,18.400040,-439.471802,-0.003880,0.001070,0.027170,81.847466,4.169509,0.271702,-439.471802,0.028046,0.000000
24.490002,18.209755,-439.471802,-0.003850,0.001081,0.027456,81.001038,4.126390,0.274564,-439.471802,0.028428,0.000000
24.720001,18.533348,-439.471802,-0.003820,0.001099,0.027925,82.440453,4.199717,0.279250,-439.471802,0.028809,0.000000
24.950001,18.851357,-439.516266,-0.003842,0.001119,0.028410,83.855019,4.271779,0.284102,-439.516266,0.029200,0.000000
25.180000,19.111267,-439.560760,-0.003794,0.001135,0.028827,85.011162,4.330675,0.288265,-439.560760,0.029581,0.000000
25.410002,18.898643,-439.560760,-0.003786,0.001143,0.029044,84.065361,4.282494,0.290438,-439.560760,0.029963,0.000000
25.640001,18.766457,-439.516266,-0.003794,0.001153,0.029278,83.477371,4.252540,0.292777,-439.516266,0.030344,0.000000
25.870001,19.446777,-439.516266,-0.003773,0.001176,0.029859,86.503586,4.406703,0.298590,-439.516266,0.030726,0.000000
26.100000,20.062683,-439.560760,-0.003760,0.001195,0.030362,89.243271,4.546269,0.303617,-439.560760,0.031116,0.000000
26.330002,19.900703,-439.560760,-0.003734,0.001206,0.030630,88.522751,4.509564,0.306304,-439.560760,0.031498,0.000000
26.560001,20.052628,-439.605225,-0.003755,0.001221,0.031012,89.198540,4.543990,0.310119,-439.605225,0.031879,0.000000
26.790001,20.086143,-439.605225,-0.003712,0.001232,0.031298,89.347626,4.551585,0.312981,-439.605225,0.032261,0.000000
27.020000,20.598152,-439.560760,-0.003708,0.001252,0.031801,91.625160,4.667608,0.318014,-439.560760,0.032652,0.000000
27.250002,20.628319,-439.516266,-0.003695,0.001264,0.032105,91.759346,4.674444,0.321050,-439.516266,0.033033,0.000000
27.480001,20.420158,-439.649719,-0.003704,0.001271,0.032296,90.833405,4.627274,0.322958,-439.649719,0.033415,0.000000
27.710001,21.071442,-439.649719,-0.003669,0.001292,0.032816,93.730453,4.774857,0.328158,-439.649719,0.033796,0.000000
27.940001,21.789375,-439.649719,-0.003648,0.001314,0.033388,96.923981,4.937543,0.333881,-439.649719,0.034178,0.000000
28.170002,21.811340,-439.649719,-0.003626,0.001328,0.033726,97.021690,4.942520,0.337264,-439.649719,0.034567,0.000000
28.400002,21.679527,-439.694214,-0.003630,0.001339,0.034013,96.435356,4.912651,0.340126,-439.694214,0.034950,0.000000
28.630001,21.900711,-439.694214,-0.003600,0.001355,0.034421,97.419228,4.962772,0.344206,-439.694214,0.035331,0.000000
28.860001,21.900711,-439.694214,-0.003600,0.001366,0.034689,97.419228,4.962772,0.346893,-439.694214,0.035713,0.000000
29.090002,22.438416,-439.694214,-0.003548,0.001386,0.035192,99.811058,5.084618,0.351920,-439.694214,0.036094,0.000000
29.320002,22.309204,-439.649719,-0.003579,0.001396,0.035461,99.236298,5.055338,0.354614,-439.649719,0.036484,0.000000
29.550001,22.746368,-439.738678,-0.003540,0.001414,0.035904,101.180901,5.154401,0.359035,-439.738678,0.036866,0.000000
29.780001,23.117256,-439.783173,-0.003553,0.001430,0.036328,102.830688,5.238445,0.363282,-439.783173,0.037248,0.000000
30.010002,23.661293,-439.783173,-0.003535,0.001451,0.036849,105.250687,5.361726,0.368490,-439.783173,0.037629,0.000000
30.240002,23.542877,-439.783173,-0.003501,0.001462,0.037135,104.723946,5.334892,0.371351,-439.783173,0.038011,0.000000
30.470001,23.334351,-439.783173,-0.003527,0.001473,0.037421,103.796379,5.287640,0.374213,-439.783173,0.038401,0.000000
30.700001,23.734276,-439.783173,-0.003466,0.001490,0.037846,105.575333,5.378264,0.378459,-439.783173,0.038782,0.000000
30.930002,23.466537,-439.783173,-0.003479,0.001502,0.038149,104.384369,5.317594,0.381495,-439.783173,0.039164,0.000000
31.160002,24.479767,-439.827637,-0.003449,0.001522,0.038652,108.891441,5.547194,0.386521,-439.827637,0.039545,0.000000
31.390001,24.217613,-439.783173,-0.003454,0.001530,0.038852,107.725327,5.487790,0.388519,-439.783173,0.039928,0.000000
31.620001,25.141472,-439.783173,-0.003432,0.001555,0.039494,111.834854,5.697139,0.394939,-439.783173,0.040317,0.000000
31.850002,25.376434,-439.872131,-0.003406,0.001571,0.039910,112.880020,5.750382,0.399102,-439.872131,0.040699,0.000000
32.080002,25.371971,-439.916595,-0.003385,0.001586,0.040274,112.860161,5.749371,0.402743,-439.916595,0.041080,0.000000
32.310001,25.224884,-439.916595,-0.003410,0.001597,0.040569,112.205887,5.716041,0.405688,-439.916595,0.041462,0.000000
32.540001,25.359680,-439.872131,-0.003389,0.001610,0.040899,112.805489,5.746586,0.408988,-439.872131,0.041844,0.000000
32.770000,25.128441,-439.872131,-0.003346,0.001622,0.041193,111.776886,5.694186,0.411933,-439.872131,0.042234,0.000000
33.000000,26.267525,-439.916595,-0.003363,0.001644,0.041766,116.843788,5.952306,0.417656,-439.916595,0.042616,0.000000
33.230003,25.847488,-439.916595,-0.003324,0.001651,0.041948,114.975372,5.857124,0.419480,-439.916595,0.042997,0.000000
33.460003,26.373650,-439.961090,-0.003294,0.001669,0.042399,117.315849,5.976355,0.423992,-439.961090,0.043379,0.000000
33.690002,27.083389,-439.961090,-0.003268,0.001691,0.042945,120.472931,6.137184,0.429449,-439.961090,0.043760,0.000000
33.920002,27.163826,-439.872131,-0.003281,0.001705,0.043301,120.830734,6.155411,0.433007,-439.872131,0.044151,0.000000
34.150002,27.179092,-440.005554,-0.003294,0.001717,0.043613,120.898643,6.158870,0.436133,-440.005554,0.044532,0.000000
34.380001,27.039078,-440.050049,-0.003268,0.001732,0.043995,120.275826,6.127143,0.439949,-440.050049,0.044914,0.000000
34.610001,26.992165,-440.050049,-0.003268,0.001741,0.044211,120.067146,6.116512,0.442114,-440.050049,0.045295,0.000000
34.840000,27.968147,-440.050049,-0.003221,0.001763,0.044793,124.408531,6.337673,0.447927,-440.050049,0.045677,0.000000
35.070004,27.977089,-439.916595,-0.003216,0.001776,0.045113,124.448303,6.339699,0.451129,-439.916595,0.046067,0.000000
35.300003,27.593544,-440.005554,-0.003216,0.001783,0.045287,122.742210,6.252787,0.452870,-440.005554,0.046449,0.000000
35.530003,28.656296,-440.094543,-0.003208,0.001809,0.045946,127.469566,6.493609,0.459456,-440.094543,0.046831,0.000000
35.760002,29.074844,-440.094543,-0.003178,0.001826,0.046379,129.331360,6.588454,0.463793,-440.094543,0.047212,0.000000
35.990002,29.148567,-440.050049,-0.003182,0.001840,0.046735,129.659302,6.605160,0.467351,-440.050049,0.047602,0.000000
36.220001,28.912857,-440.094543,-0.003169,0.001849,0.046961,128.610809,6.551747,0.469607,-440.094543,0.047984,0.000000
36.450001,29.202568,-440.094543,-0.003109,0.001865,0.047368,129.899506,6.617396,0.473680,-440.094543,0.048366,0.000000
36.680000,29.456154,-440.139008,-0.003100,0.001880,0.047759,131.027512,6.674860,0.477586,-440.139008,0.048747,0.000000
36.910000,29.896294,-440.183502,-0.003083,0.001898,0.048201,132.985352,6.774597,0.482006,-440.183502,0.049129,0.000000
37.140003,29.582008,-440.139008,-0.003100,0.001906,0.048417,131.587341,6.703379,0.484171,-440.139008,0.049519,0.000000
37.370003,30.350960,-440.094543,-0.003074,0.001927,0.048946,135.007812,6.877625,0.489463,-440.094543,0.049900,0.000000
37.600002,31.181351,-440.139008,-0.003070,0.001949,0.049501,138.701569,7.065795,0.495011,-440.139008,0.050282,0.000000
37.830002,31.171669,-440.227966,-0.003053,0.001961,0.049805,138.658508,7.063601,0.498047,-440.227966,0.050664,0.000000
38.060001,30.900581,-440.183502,-0.003040,0.001970,0.050039,137.452652,7.002172,0.500393,-440.183502,0.051045,0.000000
38.290001,31.030167,-440.227966,-0.003040,0.001985,0.050412,138.029068,7.031537,0.504118,-440.227966,0.051435,0.000000
38.520000,31.230133,-440.183502,-0.002992,0.001998,0.050759,138.918564,7.076849,0.507592,-440.183502,0.051817,0.000000
38.750000,32.205750,-440.227966,-0.003005,0.002020,0.051314,143.258331,7.297927,0.513141,-440.227966,0.052198,0.000000
38.980003,31.950676,-440.227966,-0.003005,0.002030,0.051565,142.123703,7.240127,0.515654,-440.227966,0.052580,0.000000
39.210003,31.478508,-440.272461,-0.002975,0.002039,0.051782,140.023392,7.133132,0.517819,-440.272461,0.052962,0.000000
39.440002,33.024971,-440.316925,-0.002940,0.002066,0.052476,146.902405,7.483565,0.524761,-440.316925,0.053352,0.000000
39.670002,33.316536,-440.272461,-0.002958,0.002082,0.052892,148.199356,7.549635,0.528924,-440.272461,0.053733,0.000000
39.900002,33.184715,-440.272461,-0.002945,0.002094,0.053179,147.612991,7.519764,0.531785,-440.272461,0.054115,0.000000
40.130001,33.176147,-440.316925,-0.002902,0.002108,0.053543,147.574875,7.517823,0.535426,-440.316925,0.054496,0.000000
40.360001,33.656509,-440.316925,-0.002910,0.002124,0.053942,149.711624,7.626674,0.539416,-440.316925,0.054878,0.000000
40.590000,33.877701,-440.361420,-0.002897,0.002140,0.054350,150.695541,7.676797,0.543496,-440.361420,0.055269,0.000000
40.820004,34.224754,-440.316925,-0.002902,0.002153,0.054679,152.239304,7.755440,0.546789,-440.316925,0.055650,0.000000
41.050003,34.262733,-440.272461,-0.002884,0.002165,0.055000,152.408249,7.764046,0.549998,-440.272461,0.056032,0.000000
41.280003,34.890182,-440.361420,-0.002871,0.002183,0.055459,155.199280,7.906228,0.554593,-440.361420,0.056413,0.000000
41.510002,35.615562,-440.450378,-0.002841,0.002204,0.055979,158.425934,8.070601,0.559794,-440.450378,0.056795,0.000000
41.740002,35.738075,-440.405884,-0.002833,0.002218,0.056327,158.970901,8.098364,0.563268,-440.405884,0.057185,0.000000
41.970001,35.707909,-440.405884,-0.002811,0.002232,0.056682,158.836716,8.091528,0.566818,-440.405884,0.057567,0.000000
42.200001,35.629715,-440.405884,-0.002802,0.002242,0.056951,158.488892,8.073809,0.569506,-440.405884,0.057948,0.000000
42.430000,36.055336,-440.450378,-0.002777,0.002261,0.057428,160.382141,8.170256,0.574282,-440.450378,0.058330,0.000000
42.660004,36.690231,-440.494873,-0.002790,0.002276,0.057810,163.206299,8.314125,0.578097,-440.494873,0.058711,0.000000
42.890003,36.826889,-440.494873,-0.002807,0.002289,0.058139,163.814178,8.345092,0.581390,-440.494873,0.059102,0.000000
43.120003,36.237801,-440.450378,-0.002759,0.002296,0.058330,161.193787,8.211603,0.583298,-440.450378,0.059483,0.000000
43.350002,37.009727,-440.405884,-0.002725,0.002316,0.058833,164.627487,8.386524,0.588332,-440.405884,0.059865,0.000000
43.580002,37.750748,-440.494873,-0.002725,0.002337,0.059362,167.923706,8.554441,0.593615,-440.494873,0.060246,0.000000
43.810001,38.039337,-440.539337,-0.002738,0.002348,0.059648,169.207428,8.619838,0.596477,-440.539337,0.060628,0.000000
44.040001,38.306702,-440.539337,-0.002729,0.002365,0.060073,170.396713,8.680423,0.600731,-440.539337,0.061019,0.000000
44.270000,38.324944,-440.494873,-0.002695,0.002376,0.060359,170.477859,8.684557,0.603592,-440.494873,0.061400,0.000000
44.500004,38.792648,-440.494873,-0.002665,0.002393,0.060793,172.558319,8.790540,0.607930,-440.494873,0.061782,0.000000
44.730003,39.097992,-440.583832,-0.002677,0.002411,0.061243,173.916550,8.859732,0.612434,-440.583832,0.062163,0.000000
44.960003,38.861160,-440.628296,-0.002665,0.002418,0.061426,172.863068,8.806065,0.614258,-440.628296,0.062553,0.000000
45.190002,38.957977,-440.539337,-0.002647,0.002432,0.061773,173.293732,8.828004,0.617725,-440.539337,0.062934,0.000000
45.420002,40.145103,-440.583832,-0.002652,0.002457,0.062414,178.574341,9.097011,0.624144,-440.583832,0.063316,0.000000
45.650002,40.524925,-440.539337,-0.002634,0.002469,0.062701,180.263870,9.183080,0.627006,-440.539337,0.063698,0.000000
45.880001,40.638496,-440.672791,-0.002613,0.002486,0.063143,180.769058,9.208815,0.631426,-440.672791,0.064080,0.000000
46.110001,41.162048,-440.672791,-0.002630,0.002502,0.063551,183.097931,9.327454,0.635507,-440.672791,0.064470,0.000000
46.340004,41.480431,-440.628296,-0.002600,0.002519,0.063975,184.514175,9.399600,0.639753,-440.628296,0.064851,0.000000
46.570004,42.091118,-440.672791,-0.002574,0.002535,0.064401,187.230637,9.537984,0.644007,-440.672791,0.065233,0.000000
46.800003,41.836418,-440.628296,-0.002574,0.002545,0.064635,186.097687,9.480268,0.646347,-440.628296,0.065614,0.000000
47.030003,41.613739,-440.672791,-0.002535,0.002557,0.064947,185.107162,9.429808,0.649465,-440.672791,0.065996,0.000000
47.260002,43.213448,-440.761749,-0.002557,0.002584,0.065623,192.223022,9.792307,0.656233,-440.761749,0.066386,0.000000
47.490002,43.427567,-440.717255,-0.002544,0.002597,0.065953,193.175461,9.840828,0.659526,-440.717255,0.066768,0.000000
47.720001,43.222015,-440.717255,-0.002501,0.002609,0.066256,192.261124,9.794249,0.662561,-440.717255,0.067149,0.000000
47.950001,43.356445,-440.717255,-0.002535,0.002623,0.066612,192.859100,9.824711,0.666119,-440.717255,0.067531,0.000000
48.180004,43.815208,-440.717255,-0.002514,0.002640,0.067054,194.899780,9.928668,0.670540,-440.717255,0.067912,0.000000
48.410004,44.272102,-440.761749,-0.002518,0.002654,0.067410,196.932144,10.032202,0.674097,-440.761749,0.068303,0.000000
48.640003,44.273224,-440.761749,-0.002492,0.002665,0.067678,196.937134,10.032455,0.676785,-440.761749,0.068684,0.000000
48.870003,43.742966,-440.761749,-0.002449,0.002671,0.067834,194.578430,9.912297,0.678344,-440.761749,0.069066,0.000000
49.100002,44.767365,-440.761749,-0.002479,0.002695,0.068451,199.135178,10.144429,0.684506,-440.761749,0.069448,0.000000
49.330002,45.932144,-440.806213,-0.002449,0.002717,0.069014,204.316376,10.408373,0.690138,-440.806213,0.069829,0.000000
49.560001,46.253502,-440.895172,-0.002436,0.002732,0.069404,205.745850,10.481194,0.694044,-440.895172,0.070220,0.000000
49.790001,45.953369,-440.850708,-0.002445,0.002742,0.069656,204.410797,10.413182,0.696557,-440.850708,0.070601,0.000000
50.020004,46.329460,-440.761749,-0.002427,0.002758,0.070046,206.083725,10.498406,0.700463,-440.761749,0.070983,0.000000
50.250004,46.584908,-440.850708,-0.002402,0.002774,0.070471,207.220016,10.556291,0.704710,-440.850708,0.071364,0.000000
50.480003,46.940155,-440.895172,-0.002389,0.002787,0.070783,208.800232,10.636791,0.707828,-440.895172,0.071746,0.000000
50.710003,46.973297,-440.850708,-0.002376,0.002798,0.071069,208.947662,10.644301,0.710690,-440.850708,0.072136,0.000000
50.940002,47.522545,-440.895172,-0.002376,0.002815,0.071494,211.390839,10.768763,0.714944,-440.895172,0.072518,0.000000
51.170002,48.144783,-440.895172,-0.002345,0.002835,0.071997,214.158691,10.909763,0.719970,-440.895172,0.072899,0.000000
51.400002,48.994530,-440.895172,-0.002345,0.002853,0.072457,217.938553,11.102320,0.724573,-440.895172,0.073281,0.000000
51.630001,48.898087,-440.984161,-0.002337,0.002864,0.072743,217.509552,11.080465,0.727434,-440.984161,0.073662,0.000000
51.860001,48.787865,-440.984161,-0.002315,0.002877,0.073064,217.019257,11.055489,0.730636,-440.984161,0.074053,0.000000
52.090004,49.103264,-440.984161,-0.002311,0.002889,0.073385,218.422226,11.126959,0.733846,-440.984161,0.074434,0.000000
52.320004,49.716560,-440.939667,-0.002285,0.002909,0.073896,221.150299,11.265933,0.738963,-440.939667,0.074816,0.000000
52.550003,50.097870,-440.939667,-0.002298,0.002922,0.074209,222.846451,11.352340,0.742089,-440.939667,0.075198,0.000000
52.780003,49.900887,-440.939667,-0.002285,0.002935,0.074547,221.970230,11.307703,0.745473,-440.939667,0.075579,0.000000
53.010002,51.260048,-441.028625,-0.002268,0.002958,0.075137,228.016083,11.615692,0.751370,-441.028625,0.075969,0.000000
53.240002,51.624969,-441.028625,-0.002259,0.002973,0.075509,229.639328,11.698385,0.755094,-441.028625,0.076350,0.000000
53.470001,51.930687,-440.984161,-0.002238,0.002988,0.075883,230.999237,11.767662,0.758826,-440.984161,0.076733,0.000000
53.700001,51.907234,-441.073120,-0.002264,0.003000,0.076204,230.894913,11.762347,0.762036,-441.073120,0.077114,0.000000
53.930004,51.646568,-441.117584,-0.002242,0.003009,0.076437,229.735413,11.703279,0.764375,-441.117584,0.077504,0.000000
54.160004,52.500420,-441.117584,-0.002225,0.003029,0.076932,233.533524,11.896765,0.769318,-441.117584,0.077886,0.000000
54.390003,52.923065,-441.073120,-0.002203,0.003045,0.077348,235.413559,11.992538,0.773481,-441.073120,0.078267,0.000000
54.620003,52.326897,-441.073120,-0.002220,0.003050,0.077469,232.761658,11.857445,0.774692,-441.073120,0.078649,0.000000
54.850002,53.145370,-441.117584,-0.002199,0.003070,0.077981,236.402420,12.042912,0.779809,-441.117584,0.079030,0.000000
55.080002,54.288551,-441.162079,-0.002203,0.003093,0.078571,241.487534,12.301962,0.785706,-441.162079,0.079421,0.000000
55.310001,54.341431,-441.206543,-0.002190,0.003106,0.078892,241.722763,12.313944,0.788916,-441.206543,0.079802,0.000000
55.540001,54.326164,-441.206543,-0.002186,0.003116,0.079143,241.654846,12.310484,0.791429,-441.206543,0.080184,0.000000
55.770004,54.812111,-441.162079,-0.002169,0.003136,0.079646,243.816452,12.420602,0.796463,-441.162079,0.080565,0.000000
56.000004,54.468033,-441.117584,-0.002151,0.003144,0.079845,242.285904,12.342633,0.798454,-441.117584,0.080947,0.000000
56.230003,55.437325,-441.162079,-0.002134,0.003162,0.080314,246.597534,12.562278,0.803140,-441.162079,0.081337,0.000000
56.460003,55.568024,-441.251038,-0.002147,0.003176,0.080661,247.178909,12.591894,0.806607,-441.251038,0.081719,0.000000
56.690002,55.375511,-441.206543,-0.002108,0.003187,0.080956,246.322571,12.548269,0.809559,-441.206543,0.082100,0.000000
56.920002,56.746208,-441.162079,-0.002126,0.003212,0.081580,252.419739,12.858875,0.815804,-441.162079,0.082482,0.000000
57.150002,57.358391,-441.162079,-0.002113,0.003228,0.081997,255.142868,12.997597,0.819967,-441.162079,0.082863,0.000000
57.380001,57.516273,-441.206543,-0.002091,0.003242,0.082334,255.845169,13.033374,0.823343,-441.206543,0.083254,0.000000
57.610004,57.177422,-441.251038,-0.002082,0.003253,0.082620,254.337875,12.956589,0.826205,-441.251038,0.083636,0.000000
57.840004,57.384460,-441.206543,-0.002095,0.003266,0.082951,255.258835,13.003505,0.829505,-441.206543,0.084017,0.000000
58.070004,58.117661,-441.295502,-0.002074,0.003286,0.083462,258.520264,13.169650,0.834622,-441.295502,0.084399,0.000000
58.300003,58.351883,-441.251038,-0.002052,0.003297,0.083748,259.562134,13.222726,0.837484,-441.251038,0.084780,0.000000
58.530003,58.030525,-441.295502,-0.002070,0.003308,0.084025,258.132660,13.149905,0.840254,-441.295502,0.085171,0.000000
58.760002,59.167007,-441.384491,-0.002057,0.003332,0.084624,263.187988,13.407435,0.846242,-441.384491,0.085552,0.000000
58.990002,60.197731,-441.339996,-0.002035,0.003351,0.085119,267.772888,13.641001,0.851185,-441.339996,0.085934,0.000000
59.220001,59.972816,-441.295502,-0.002061,0.003360,0.085335,266.772400,13.590034,0.853350,-441.295502,0.086315,0.000000
59.450005,59.861855,-441.295502,-0.002022,0.003372,0.085656,266.278839,13.564890,0.856560,-441.295502,0.086697,0.000000
59.680004,59.932976,-441.428955,-0.002013,0.003386,0.086012,266.595184,13.581006,0.860117,-441.428955,0.087087,0.000000
59.910004,60.081551,-441.384491,-0.002013,0.003399,0.086324,267.256073,13.614674,0.863236,-441.384491,0.087469,0.000000
60.140003,61.233299,-441.428955,-0.001996,0.003421,0.086896,272.379333,13.875664,0.868959,-441.428955,0.087850,0.000000
60.370003,61.019928,-441.384491,-0.001979,0.003431,0.087148,271.430206,13.827313,0.871480,-441.384491,0.088232,0.000000
60.600002,60.961838,-441.384491,-0.001975,0.003444,0.087486,271.171783,13.814150,0.874856,-441.384491,0.088613,0.000000
60.830002,62.468834,-441.517914,-0.001979,0.003469,0.088102,277.875244,14.155640,0.881018,-441.517914,0.089003,0.000000
61.060001,62.957382,-441.473450,-0.001957,0.003483,0.088474,280.048431,14.266347,0.884742,-441.473450,0.089385,0.000000
61.290005,62.808060,-441.473450,-0.001944,0.003495,0.088769,279.384216,14.232510,0.887694,-441.473450,0.089767,0.000000
61.520004,63.099258,-441.428955,-0.001962,0.003510,0.089160,280.679504,14.298496,0.891600,-441.428955,0.090149,0.000000
61.750004,63.558014,-441.428955,-0.001949,0.003525,0.089524,282.720154,14.402452,0.895241,-441.428955,0.090530,0.000000
61.980003,64.080826,-441.517914,-0.001914,0.003542,0.089966,285.045746,14.520923,0.899662,-441.517914,0.090920,0.000000
62.210003,64.009338,-441.562408,-0.001936,0.003552,0.090218,284.727753,14.504723,0.902175,-441.562408,0.091302,0.000000
62.440002,64.191422,-441.562408,-0.001910,0.003565,0.090548,285.537689,14.545983,0.905476,-441.562408,0.091683,0.000000
62.670002,65.051605,-441.517914,-0.001897,0.003586,0.091076,289.363983,14.740905,0.910759,-441.517914,0.092065,0.000000
62.900002,66.144897,-441.517914,-0.001880,0.003605,0.091579,294.227203,14.988647,0.915793,-441.517914,0.092455,0.000000
63.130005,66.449127,-441.517914,-0.001867,0.003619,0.091926,295.580475,15.057588,0.919260,-441.517914,0.092837,0.000000
63.360004,66.548172,-441.606873,-0.001880,0.003631,0.092221,296.021057,15.080031,0.922212,-441.606873,0.093218,0.000000
63.590004,66.503479,-441.606873,-0.001850,0.003641,0.092490,295.822235,15.069903,0.924900,-441.606873,0.093600,0.000000
63.820004,67.477982,-441.606873,-0.001858,0.003652,0.092767,300.157043,15.290730,0.927670,-441.606873,0.093027,0.000000
64.050003,66.309860,-441.606873,-0.001837,0.003652,0.092767,294.960999,15.026029,0.927670,-441.606873,0.093027,0.000000
64.280006,65.089966,-441.651367,-0.001807,0.003650,0.092716,289.534637,14.749597,0.927155,-441.651367,0.092767,0.000000
64.510002,64.049927,-441.651367,-0.001850,0.003650,0.092698,284.908295,14.513922,0.926981,-441.651367,0.092767,0.000000
64.740005,63.119362,-441.651367,-0.001819,0.003649,0.092681,280.768951,14.303052,0.926807,-441.651367,0.092767,0.000000
64.970001,62.250992,-441.606873,-0.001850,0.003649,0.092681,276.906250,14.106277,0.926807,-441.606873,0.092767,0.000000
65.200005,61.450768,-441.651367,-0.001832,0.003648,0.092672,273.346680,13.924943,0.926716,-441.651367,0.092767,0.000000
65.430000,60.724640,-441.695831,-0.001850,0.003648,0.092672,270.116699,13.760401,0.926716,-441.695831,0.092767,0.000000
65.660004,60.043571,-441.740326,-0.001807,0.003648,0.092663,267.087158,13.606069,0.926633,-441.740326,0.092767,0.000000
65.889999,59.422455,-441.695831,-0.001811,0.003648,0.092663,264.324280,13.465321,0.926633,-441.695831,0.092767,0.000000
66.120003,58.859055,-441.695831,-0.001850,0.003648,0.092663,261.818146,13.337652,0.926633,-441.695831,0.092767,0.000000
66.350006,58.322464,-441.740326,-0.001794,0.003648,0.092663,259.431274,13.216060,0.926633,-441.740326,0.092767,0.000000
66.580002,57.828323,-441.740326,-0.001794,0.003648,0.092663,257.233215,13.104086,0.926633,-441.740326,0.092767,0.000000
66.810005,57.367699,-441.784821,-0.001789,0.003648,0.092663,255.184265,12.999706,0.926633,-441.784821,0.092767,0.000000
67.040001,56.933884,-441.784821,-0.001811,0.003648,0.092663,253.254562,12.901402,0.926633,-441.784821,0.092767,0.000000
67.270004,56.529488,-441.784821,-0.001807,0.003648,0.092663,251.455719,12.809766,0.926633,-441.784821,0.092767,0.000000
67.500000,56.152649,-441.829285,-0.001785,0.003648,0.092663,249.779465,12.724372,0.926633,-441.829285,0.092767,0.000000
67.730003,55.804108,-441.829285,-0.001794,0.003648,0.092663,248.229065,12.645391,0.926633,-441.829285,0.092767,0.000000
67.960007,55.464508,-441.873779,-0.001794,0.003648,0.092663,246.718460,12.568438,0.926633,-441.873779,0.092767,0.000000
68.190002,55.152832,-441.873779,-0.001772,0.003648,0.092663,245.332047,12.497810,0.926633,-441.873779,0.092767,0.000000
68.420006,54.848228,-441.918243,-0.001789,0.003648,0.092654,243.977112,12.428786,0.926542,-441.918243,0.092767,0.000000
68.650002,54.564110,-441.829285,-0.001785,0.003648,0.092654,242.713287,12.364404,0.926542,-441.829285,0.092767,0.000000
68.880005,54.283714,-441.918243,-0.001759,0.003648,0.092654,241.466019,12.300866,0.926542,-441.918243,0.092767,0.000000
69.110001,54.043907,-441.918243,-0.001785,0.003648,0.092654,240.399307,12.246524,0.926542,-441.918243,0.092767,0.000000
69.340004,53.805214,-441.918243,-0.001763,0.003648,0.092654,239.337540,12.192436,0.926542,-441.918243,0.092767,0.000000
69.570000,53.563171,-441.918243,-0.001798,0.003648,0.092654,238.260880,12.137588,0.926542,-441.918243,0.092767,0.000000
69.800003,53.348312,-441.873779,-0.001776,0.003648,0.092654,237.305145,12.088901,0.926542,-441.873779,0.092767,0.000000
70.030006,53.131592,-441.962738,-0.001759,0.003648,0.092654,236.341125,12.039790,0.926542,-441.962738,0.092767,0.000000
70.260002,52.940933,-442.007202,-0.001789,0.003648,0.092654,235.493027,11.996587,0.926542,-442.007202,0.092767,0.000000
70.490005,52.751030,-441.962738,-0.001772,0.003648,0.092654,234.648300,11.953554,0.926542,-441.962738,0.092767,0.000000
70.720001,52.552551,-441.962738,-0.001772,0.003648,0.092654,233.765427,11.908579,0.926542,-441.962738,0.092767,0.000000
70.950005,52.376793,-441.962738,-0.001781,0.003648,0.092654,232.983612,11.868751,0.926542,-441.962738,0.092767,0.000000
71.180000,52.212204,-442.051697,-0.001763,0.003648,0.092654,232.251480,11.831454,0.926542,-442.051697,0.092767,0.000000
71.410004,52.041283,-442.051697,-0.001768,0.003648,0.092654,231.491180,11.792724,0.926542,-442.051697,0.092767,0.000000
71.640007,51.888611,-442.007202,-0.001794,0.003648,0.092654,230.812073,11.758127,0.926542,-442.007202,0.092767,0.000000
71.870003,51.732216,-442.007202,-0.001772,0.003648,0.092654,230.116394,11.722688,0.926542,-442.007202,0.092767,0.000000
72.100006,51.575447,-442.051697,-0.001759,0.003648,0.092654,229.419052,11.687163,0.926542,-442.051697,0.092767,0.000000
72.330002,51.437668,-442.140656,-0.001772,0.003648,0.092654,228.806168,11.655942,0.926542,-442.140656,0.092767,0.000000
72.560005,51.294304,-442.140656,-0.001781,0.003648,0.092654,228.168457,11.623456,0.926542,-442.140656,0.092767,0.000000
72.790001,51.175888,-442.140656,-0.001755,0.003648,0.092654,227.641724,11.596622,0.926542,-442.140656,0.092767,0.000000
73.020004,51.038857,-442.051697,-0.001759,0.003648,0.092654,227.032166,11.565570,0.926542,-442.051697,0.092767,0.000000
73.250000,50.936455,-442.140656,-0.001763,0.003648,0.092654,226.576660,11.542365,0.926542,-442.140656,0.092767,0.000000
73.480003,50.803894,-442.096161,-0.001742,0.003648,0.092654,225.987015,11.512326,0.926542,-442.096161,0.092767,0.000000
73.710007,50.678032,-442.140656,-0.001785,0.003648,0.092654,225.427139,11.483806,0.926542,-442.140656,0.092767,0.000000
73.940002,50.573021,-442.185120,-0.001772,0.003648,0.092654,224.960037,11.460011,0.926542,-442.185120,0.092767,0.000000
74.170006,50.461678,-442.185120,-0.001759,0.003648,0.092654,224.464752,11.434780,0.926542,-442.185120,0.092767,0.000000
74.400002,50.352577,-442.140656,-0.001776,0.003648,0.092654,223.979446,11.410057,0.926542,-442.140656,0.092767,0.000000
74.630005,50.253899,-442.274109,-0.001768,0.003648,0.092654,223.540512,11.387696,0.926542,-442.274109,0.092767,0.000000
74.860001,50.148888,-442.229614,-0.001742,0.003648,0.092654,223.073395,11.363900,0.926542,-442.229614,0.092767,0.000000
75.090004,50.061752,-442.185120,-0.001794,0.003648,0.092654,222.685791,11.344155,0.926542,-442.185120,0.092767,0.000000
75.320007,49.968285,-442.229614,-0.001768,0.003648,0.092654,222.270035,11.322974,0.926542,-442.229614,0.092767,0.000000
75.550003,49.877052,-442.185120,-0.001772,0.003648,0.092654,221.864212,11.302301,0.926542,-442.185120,0.092767,0.000000
75.780006,49.778008,-442.229614,-0.001750,0.003648,0.092654,221.423630,11.279858,0.926542,-442.229614,0.092767,0.000000
76.010002,49.692360,-442.363068,-0.001807,0.003648,0.092654,221.042664,11.260449,0.926542,-442.363068,0.092767,0.000000
76.240005,49.592560,-442.274109,-0.001750,0.003648,0.092654,220.598724,11.237835,0.926542,-442.274109,0.092767,0.000000
76.470001,49.511017,-442.229614,-0.001759,0.003648,0.092654,220.236008,11.219357,0.926542,-442.229614,0.092767,0.000000
76.700005,49.441750,-442.274109,-0.001746,0.003648,0.092654,219.927887,11.203661,0.926542,-442.274109,0.092767,0.000000
76.930000,49.362434,-442.363068,-0.001776,0.003648,0.092654,219.575073,11.185687,0.926542,-442.363068,0.092767,0.000000
77.160004,49.283119,-442.363068,-0.001742,0.003648,0.092654,219.222260,11.167715,0.926542,-442.363068,0.092767,0.000000
77.390007,49.219070,-442.318573,-0.001789,0.003648,0.092654,218.937363,11.153201,0.926542,-442.318573,0.092767,0.000000
77.620003,49.129707,-442.318573,-0.001750,0.003648,0.092654,218.539856,11.132951,0.926542,-442.318573,0.092767,0.000000
77.850006,49.063797,-442.363068,-0.001746,0.003648,0.092654,218.246674,11.118015,0.926542,-442.363068,0.092767,0.000000
78.080002,48.981125,-442.407532,-0.001759,0.003648,0.092654,217.878922,11.099281,0.926542,-442.407532,0.092767,0.000000
78.310005,48.916336,-442.407532,-0.001759,0.003648,0.092654,217.590729,11.084600,0.926542,-442.407532,0.092767,0.000000
78.540001,48.855263,-442.407532,-0.001759,0.003648,0.092654,217.319061,11.070761,0.926542,-442.407532,0.092767,0.000000
78.770004,48.781540,-442.407532,-0.001742,0.003648,0.092654,216.991119,11.054054,0.926542,-442.407532,0.092767,0.000000
79.000000,48.724190,-442.407532,-0.001729,0.003648,0.092654,216.736023,11.041059,0.926542,-442.407532,0.092767,0.000000
79.230003,48.651581,-442.496490,-0.001772,0.003648,0.092654,216.413040,11.024606,0.926542,-442.496490,0.092767,0.000000
79.460007,48.586411,-442.452026,-0.001738,0.003648,0.092654,216.123154,11.009838,0.926542,-442.452026,0.092767,0.000000
79.690002,48.518639,-442.452026,-0.001738,0.003648,0.092654,215.821686,10.994480,0.926542,-442.452026,0.092767,0.000000
79.920006,48.471725,-442.407532,-0.001738,0.003648,0.092654,215.613007,10.983850,0.926542,-442.407532,0.092767,0.000000
80.150002,48.406929,-442.496490,-0.001755,0.003648,0.092654,215.324768,10.969167,0.926542,-442.496490,0.092767,0.000000
80.380005,48.346977,-442.496490,-0.001763,0.003648,0.092654,215.058090,10.955582,0.926542,-442.496490,0.092767,0.000000
80.610001,48.278458,-442.540985,-0.001772,0.003648,0.092654,214.753311,10.940055,0.926542,-442.540985,0.092767,0.000000
80.840004,48.239731,-442.496490,-0.001759,0.003648,0.092654,214.581039,10.931279,0.926542,-442.496490,0.092767,0.000000
81.070007,48.176430,-442.540985,-0.001768,0.003648,0.092654,214.299469,10.916935,0.926542,-442.540985,0.092767,0.000000
81.300003,48.128021,-442.540985,-0.001755,0.003648,0.092654,214.084137,10.905966,0.926542,-442.540985,0.092767,0.000000
81.530006,48.076263,-442.585449,-0.001742,0.003648,0.092654,213.853897,10.894237,0.926542,-442.585449,0.092767,0.000000
81.760002,48.002159,-442.585449,-0.001772,0.003648,0.092654,213.524261,10.877444,0.926542,-442.585449,0.092767,0.000000
81.990005,47.958595,-442.585449,-0.001781,0.003648,0.092654,213.330490,10.867574,0.926542,-442.585449,0.092767,0.000000
82.220001,47.919495,-442.585449,-0.001776,0.003648,0.092654,213.156555,10.858713,0.926542,-442.585449,0.092767,0.000000
82.450005,47.876297,-442.629944,-0.001746,0.003648,0.092654,212.964401,10.848924,0.926542,-442.629944,0.092767,0.000000
82.680000,47.810387,-442.674438,-0.001759,0.003648,0.092654,212.671219,10.833989,0.926542,-442.674438,0.092767,0.000000
82.910004,47.773521,-442.674438,-0.001733,0.003648,0.092654,212.507233,10.825635,0.926542,-442.674438,0.092767,0.000000
83.140007,47.715805,-442.629944,-0.001738,0.003648,0.092654,212.250504,10.812556,0.926542,-442.629944,0.092767,0.000000
83.370003,47.672607,-442.629944,-0.001750,0.003648,0.092654,212.058350,10.802767,0.926542,-442.629944,0.092767,0.000000
83.600006,47.631653,-442.718903,-0.001755,0.003648,0.092654,211.876175,10.793488,0.926542,-442.718903,0.092767,0.000000
83.830002,47.587341,-442.718903,-0.001772,0.003648,0.092654,211.679062,10.783445,0.926542,-442.718903,0.092767,0.000000
84.060005,47.528130,-442.718903,-0.001755,0.003648,0.092654,211.415680,10.770028,0.926542,-442.718903,0.092767,0.000000
84.290001,47.489777,-442.718903,-0.001750,0.003648,0.092654,211.245071,10.761336,0.926542,-442.718903,0.092767,0.000000
84.520004,47.464455,-442.674438,-0.001755,0.003648,0.092654,211.132446,10.755599,0.926542,-442.674438,0.092767,0.000000
84.750008,47.408226,-442.718903,-0.001755,0.003648,0.092654,210.882324,10.742858,0.926542,-442.718903,0.092767,0.000000
84.980003,47.363541,-442.763397,-0.001768,0.003648,0.092654,210.683548,10.732732,0.926542,-442.763397,0.092767,0.000000
85.210007,47.323326,-442.763397,-0.001750,0.003648,0.092654,210.504669,10.723619,0.926542,-442.763397,0.092767,0.000000
85.440002,47.288696,-442.718903,-0.001742,0.003648,0.092654,210.350632,10.715772,0.926542,-442.718903,0.092767,0.000000
85.670006,47.236191,-442.763397,-0.001738,0.003648,0.092654,210.117065,10.703875,0.926542,-442.763397,0.092767,0.000000
85.900002,47.201561,-442.763397,-0.001738,0.003648,0.092654,209.963028,10.696027,0.926542,-442.763397,0.092767,0.000000
86.130005,47.160599,-442.807861,-0.001772,0.003648,0.092654,209.780823,10.686744,0.926542,-442.807861,0.092767,0.000000
86.360001,47.121872,-442.852356,-0.001759,0.003648,0.092654,209.608551,10.677969,0.926542,-442.852356,0.092767,0.000000
86.590004,47.093575,-442.807861,-0.001759,0.003648,0.092654,209.482681,10.671556,0.926542,-442.807861,0.092767,0.000000
86.820007,47.053352,-442.807861,-0.001725,0.003648,0.092654,209.303772,10.662442,0.926542,-442.807861,0.092767,0.000000
87.050003,47.012398,-442.807861,-0.001742,0.003648,0.092654,209.121582,10.653162,0.926542,-442.807861,0.092767,0.000000
87.280006,46.975899,-442.941315,-0.001742,0.003648,0.092654,208.959229,10.644891,0.926542,-442.941315,0.092767,0.000000
87.510002,46.936806,-442.852356,-0.001768,0.003648,0.092654,208.785339,10.636032,0.926542,-442.852356,0.092767,0.000000
87.740005,46.904404,-442.852356,-0.001746,0.003648,0.092654,208.641205,10.628690,0.926542,-442.852356,0.092767,0.000000
87.970001,46.864189,-442.896820,-0.001755,0.003648,0.092654,208.462326,10.619577,0.926542,-442.896820,0.092767,0.000000
88.200005,46.837379,-442.985779,-0.001763,0.003648,0.092654,208.343063,10.613503,0.926542,-442.985779,0.092767,0.000000
88.430008,46.806847,-442.941315,-0.001759,0.003648,0.092654,208.207245,10.606584,0.926542,-442.941315,0.092767,0.000000
88.660004,46.770355,-443.030273,-0.001733,0.003648,0.092654,208.044937,10.598314,0.926542,-443.030273,0.092767,0.000000
88.890007,46.734230,-442.941315,-0.001738,0.003648,0.092654,207.884232,10.590128,0.926542,-442.941315,0.092767,0.000000
89.120003,46.698860,-442.941315,-0.001755,0.003648,0.092654,207.726898,10.582112,0.926542,-442.941315,0.092767,0.000000
89.350006,46.654175,-442.941315,-0.001746,0.003648,0.092654,207.528137,10.571987,0.926542,-442.941315,0.092767,0.000000
89.580002,46.639275,-442.941315,-0.001763,0.003648,0.092654,207.461853,10.568610,0.926542,-442.941315,0.092767,0.000000
89.810005,46.598686,-443.030273,-0.001738,0.003648,0.092654,207.281311,10.559413,0.926542,-443.030273,0.092767,0.000000
90.040001,46.562195,-442.941315,-0.001742,0.003648,0.092654,207.118988,10.551145,0.926542,-442.941315,0.092767,0.000000
90.270004,46.551773,-442.985779,-0.001738,0.003648,0.092654,207.072632,10.548783,0.926542,-442.985779,0.092767,0.000000
90.500008,46.508202,-443.074768,-0.001772,0.003648,0.092654,206.878815,10.538909,0.926542,-443.074768,0.092767,0.000000
90.730003,46.477295,-443.074768,-0.001750,0.003648,0.092654,206.741333,10.531905,0.926542,-443.074768,0.092767,0.000000
90.960007,46.444901,-443.119232,-0.001776,0.003648,0.092654,206.597229,10.524565,0.926542,-443.119232,0.092767,0.000000
91.190002,46.425163,-443.074768,-0.001738,0.003648,0.092654,206.509445,10.520093,0.926542,-443.074768,0.092767,0.000000
91.420006,46.385689,-443.119232,-0.001742,0.003648,0.092654,206.333847,10.511147,0.926542,-443.119232,0.092767,0.000000
91.650002,46.357391,-443.119232,-0.001742,0.003648,0.092654,206.207977,10.504735,0.926542,-443.119232,0.092767,0.000000
91.880005,46.323509,-443.074768,-0.001755,0.003648,0.092654,206.057266,10.497057,0.926542,-443.074768,0.092767,0.000000
92.110001,46.304512,-443.119232,-0.001720,0.003648,0.092654,205.972763,10.492752,0.926542,-443.119232,0.092767,0.000000
92.340004,46.270630,-443.074768,-0.001725,0.003648,0.092654,205.822037,10.485074,0.926542,-443.074768,0.092767,0.000000
92.570007,46.254242,-443.119232,-0.001759,0.003648,0.092654,205.749146,10.481361,0.926542,-443.119232,0.092767,0.000000
92.800003,46.216263,-443.208191,-0.001750,0.003648,0.092654,205.580200,10.472755,0.926542,-443.208191,0.092767,0.000000
93.030006,46.188705,-443.208191,-0.001759,0.003648,0.092654,205.457626,10.466510,0.926542,-443.208191,0.092767,0.000000
93.260002,46.152588,-443.163727,-0.001733,0.003648,0.092654,205.296967,10.458325,0.926542,-443.163727,0.092767,0.000000
93.490005,46.138435,-443.208191,-0.001733,0.003648,0.092654,205.234009,10.455119,0.926542,-443.208191,0.092767,0.000000
93.720001,46.112740,-443.163727,-0.001746,0.003648,0.092654,205.119705,10.449296,0.926542,-443.163727,0.092767,0.000000
93.950005,46.087425,-443.208191,-0.001738,0.003648,0.092654,205.007111,10.443560,0.926542,-443.208191,0.092767,0.000000
94.180008,46.058006,-443.252686,-0.001733,0.003648,0.092654,204.876251,10.436893,0.926542,-443.252686,0.092767,0.000000
94.300003,46.040504,-443.208191,-0.001768,0.003648,0.092654,204.798386,10.432927,0.926542,-443.208191,0.092767,0.000000