File: Data/compression 14/AutoNoHeating-12-14-1-240726_07262024_163326.csv
Time (sec),S:Load (lbs),S:HL1 (DIM),S:LVDT (in),S:Position (in),Ch:Position (mm),Ch:Load (N),Ch:Stress (MPa),Ch:Strain (mm/mm),Ch:HL1 (DIM),Set Point (),Cycles ()
0.110000,0.002235,-335.208435,-0.009477,-0.005034,-0.127872,0.009944,0.000507,-1.278719,-335.208435,-0.127699,0.000000
0.350000,-0.003723,-335.208435,-0.009503,-0.005034,-0.127872,-0.016561,-0.000844,-1.278719,-335.208435,-0.127699,0.000000
0.590000,0.011169,-335.297424,-0.009503,-0.004939,-0.125453,0.049684,0.002531,-1.254526,-335.297424,-0.124680,0.000000
0.830000,0.005959,-335.208435,-0.009399,-0.004798,-0.121871,0.026505,0.001350,-1.218714,-335.208435,-0.120675,0.000000
1.070000,-0.026070,-335.297424,-0.009253,-0.004638,-0.117812,-0.115964,-0.005907,-1.178124,-335.297424,-0.116685,0.000000
1.310000,-0.063301,-335.297424,-0.009089,-0.004481,-0.113823,-0.281577,-0.014344,-1.138232,-335.297424,-0.112679,0.000000
1.550000,-0.041710,-335.252930,-0.008903,-0.004328,-0.109921,-0.185535,-0.009452,-1.099209,-335.252930,-0.108689,0.000000
1.790000,0.020103,-335.297424,-0.008744,-0.004171,-0.105940,0.089425,0.004556,-1.059400,-335.297424,-0.104683,0.000000
2.030000,0.012291,-335.297424,-0.008580,-0.004006,-0.101752,0.054673,0.002785,-1.017516,-335.297424,-0.100693,0.000000
2.270000,-0.016014,-335.386383,-0.008407,-0.003850,-0.097797,-0.071234,-0.003629,-0.977971,-335.386383,-0.096687,0.000000
2.510000,0.002975,-335.386383,-0.008239,-0.003695,-0.093851,0.013236,0.000674,-0.938510,-335.386383,-0.092697,0.000000
2.750000,0.020851,-335.297424,-0.008063,-0.003538,-0.089870,0.092750,0.004725,-0.898701,-335.297424,-0.088691,0.000000
2.990000,-0.003349,-335.430847,-0.007933,-0.003378,-0.085812,-0.014898,-0.000759,-0.858119,-335.430847,-0.084701,0.000000
3.230000,-0.023087,-335.341888,-0.007739,-0.003217,-0.081701,-0.102694,-0.005231,-0.817015,-335.341888,-0.080695,0.000000
3.470000,-0.037613,-335.430847,-0.007601,-0.003069,-0.077946,-0.167311,-0.008523,-0.779461,-335.430847,-0.076706,0.000000
3.710000,-0.011543,-335.386383,-0.007412,-0.002912,-0.073965,-0.051347,-0.002616,-0.739652,-335.386383,-0.072700,0.000000
3.950000,0.024948,-335.475342,-0.007282,-0.002756,-0.069993,0.110975,0.005653,-0.699933,-335.475342,-0.068710,0.000000
4.190000,0.006699,-335.475342,-0.007084,-0.002589,-0.065762,0.029797,0.001518,-0.657618,-335.475342,-0.064704,0.000000
4.430000,-0.006706,-335.475342,-0.006920,-0.002436,-0.061885,-0.029831,-0.001520,-0.618853,-335.475342,-0.060697,0.000000
4.670000,0.017502,-335.608765,-0.006760,-0.002276,-0.057801,0.077852,0.003966,-0.578006,-335.608765,-0.056708,0.000000
4.910000,0.030159,-335.519806,-0.006584,-0.002124,-0.053942,0.134154,0.006834,-0.539416,-335.519806,-0.052701,0.000000
5.150000,0.005959,-335.564301,-0.006428,-0.001958,-0.049727,0.026505,0.001350,-0.497267,-335.564301,-0.048712,0.000000
5.390000,-0.023087,-335.564301,-0.006282,-0.001805,-0.045859,-0.102694,-0.005231,-0.458585,-335.564301,-0.044706,0.000000
5.630000,0.009682,-335.564301,-0.006122,-0.001650,-0.041921,0.043066,0.002194,-0.419215,-335.564301,-0.040716,0.000000
5.870000,-0.000000,-335.564301,-0.005941,-0.001496,-0.038002,-0.000000,-0.000000,-0.380019,-335.564301,-0.036710,0.000000
6.110000,0.030159,-335.653259,-0.005786,-0.001330,-0.033770,0.134154,0.006834,-0.337696,-335.653259,-0.032720,0.000000
6.350000,-0.002235,-335.608765,-0.005601,-0.001176,-0.029867,-0.009944,-0.000507,-0.298674,-335.608765,-0.028714,0.000000
6.590000,0.022713,-335.653259,-0.005424,-0.001015,-0.025791,0.101031,0.005147,-0.257910,-335.653259,-0.024724,0.000000
6.830000,0.037605,-335.697723,-0.005256,-0.000866,-0.021984,0.167277,0.008521,-0.219842,-335.697723,-0.020718,0.000000
7.070000,0.029419,-335.697723,-0.005096,-0.000699,-0.017760,0.130862,0.006666,-0.177602,-335.697723,-0.016728,0.000000
7.310000,-0.007446,-335.742218,-0.004945,-0.000543,-0.013788,-0.033123,-0.001687,-0.137884,-335.742218,-0.012722,0.000000
7.550000,0.002609,-335.653259,-0.004781,-0.000389,-0.009878,0.011607,0.000591,-0.098778,-335.653259,-0.008733,0.000000
7.790000,0.011169,-335.742218,-0.004622,-0.000238,-0.006053,0.049684,0.002531,-0.060528,-335.742218,-0.004727,0.000000
8.030001,0.128838,-335.653259,-0.004462,-0.000073,-0.001864,0.573098,0.029195,-0.018644,-335.653259,-0.000737,0.000000
8.270000,0.645691,-335.742218,-0.004363,-0.000003,-0.000086,2.872177,0.146316,-0.000863,-335.742218,0.000130,0.000000
8.510000,0.562653,-335.742218,-0.004329,-0.000004,-0.000095,2.502804,0.127499,-0.000954,-335.742218,0.000130,0.000000
8.750000,0.595421,-335.786713,-0.004337,-0.000004,-0.000095,2.648564,0.134924,-0.000954,-335.786713,0.000182,0.000000
8.990001,0.582016,-335.831177,-0.004363,-0.000004,-0.000095,2.588936,0.131887,-0.000954,-335.831177,0.000590,0.000000
9.230000,0.549995,-335.697723,-0.004359,-0.000003,-0.000086,2.446502,0.124631,-0.000863,-335.697723,0.000989,0.000000
9.470000,0.675858,-335.786713,-0.004355,0.000013,0.000321,3.006365,0.153151,0.003210,-335.786713,0.001388,0.000000
9.710000,0.951408,-335.920135,-0.004329,0.000039,0.000998,4.232076,0.215592,0.009977,-335.920135,0.001786,0.000000
9.950001,1.070946,-335.875671,-0.004294,0.000054,0.001379,4.763804,0.242680,0.013792,-335.875671,0.002185,0.000000
10.190001,1.163292,-335.920135,-0.004264,0.000066,0.001674,5.174581,0.263606,0.016744,-335.920135,0.002584,0.000000
10.430000,1.339798,-335.875671,-0.004247,0.000084,0.002125,5.959719,0.303603,0.021248,-335.875671,0.002983,0.000000
10.670000,1.574387,-335.920135,-0.004260,0.000103,0.002628,7.003222,0.356761,0.026282,-335.920135,0.003382,0.000000
10.910001,1.737114,-335.964630,-0.004247,0.000116,0.002958,7.727069,0.393636,0.029575,-335.964630,0.003790,0.000000
11.150001,1.855530,-335.920135,-0.004230,0.000127,0.003235,8.253809,0.420469,0.032353,-335.920135,0.004189,0.000000
11.390000,1.930374,-336.009094,-0.004230,0.000134,0.003409,8.586733,0.437429,0.034087,-336.009094,0.004588,0.000000
11.630000,2.373505,-336.009094,-0.004199,0.000164,0.004154,10.557876,0.537844,0.041543,-336.009094,0.004987,0.000000
11.870001,2.516861,-336.053589,-0.004182,0.000177,0.004493,11.195557,0.570329,0.044927,-336.053589,0.005386,0.000000
12.110001,2.711243,-336.009094,-0.004174,0.000191,0.004848,12.060210,0.614376,0.048485,-336.009094,0.005785,0.000000
12.350000,2.861305,-335.964630,-0.004143,0.000205,0.005195,12.727721,0.648381,0.051951,-335.964630,0.006184,0.000000
12.590000,3.105209,-336.053589,-0.004143,0.000220,0.005577,13.812661,0.703651,0.055767,-336.053589,0.006583,0.000000
12.830001,3.475349,-336.053589,-0.004126,0.000239,0.006079,15.459126,0.787525,0.060793,-336.053589,0.006990,0.000000
13.070001,3.616852,-336.098053,-0.004087,0.000252,0.006392,16.088560,0.819590,0.063919,-336.098053,0.007389,0.000000
13.310000,3.681274,-336.098053,-0.004118,0.000257,0.006530,16.375126,0.834189,0.065305,-336.098053,0.007788,0.000000
13.550000,4.393623,-336.142548,-0.004083,0.000293,0.007433,19.543814,0.995609,0.074328,-336.142548,0.008187,0.000000
13.790001,4.522087,-336.187042,-0.004061,0.000307,0.007788,20.115248,1.024720,0.077878,-336.187042,0.008586,0.000000
14.030001,4.642365,-336.142548,-0.004057,0.000319,0.008109,20.650269,1.051975,0.081088,-336.142548,0.008985,0.000000
14.270000,4.882545,-336.142548,-0.004066,0.000332,0.008438,21.718647,1.106401,0.084380,-336.142548,0.009384,0.000000
14.510000,5.330887,-336.142548,-0.004001,0.000353,0.008976,23.712969,1.207996,0.089763,-336.142548,0.009782,0.000000
14.750001,5.482437,-336.231506,-0.004014,0.000365,0.009280,24.387098,1.242338,0.092798,-336.231506,0.010190,0.000000
14.990001,5.669373,-336.231506,-0.004010,0.000379,0.009635,25.218628,1.284698,0.096348,-336.231506,0.010589,0.000000
15.230000,5.849602,-336.276001,-0.003975,0.000392,0.009947,26.020329,1.325539,0.099475,-336.276001,0.010988,0.000000
15.470000,6.103928,-336.276001,-0.003988,0.000405,0.010277,27.151627,1.383170,0.102767,-336.276001,0.011387,0.000000
15.710001,6.605888,-336.276001,-0.003945,0.000431,0.010936,29.384459,1.496916,0.109361,-336.276001,0.011786,0.000000
15.950001,6.716110,-336.320465,-0.003923,0.000445,0.011300,29.874750,1.521892,0.113002,-336.320465,0.012185,0.000000
16.190001,6.937302,-336.320465,-0.003936,0.000458,0.011639,30.858660,1.572015,0.116386,-336.320465,0.012584,0.000000
16.430000,7.129066,-336.276001,-0.003889,0.000472,0.011977,31.711672,1.615470,0.119769,-336.276001,0.012983,0.000000
16.670000,7.557297,-336.320465,-0.003872,0.000492,0.012489,33.616535,1.712508,0.124886,-336.320465,0.013390,0.000000
16.910002,7.678322,-336.320465,-0.003876,0.000504,0.012810,34.154881,1.739933,0.128096,-336.320465,0.013789,0.000000
17.150002,7.769180,-336.320465,-0.003867,0.000515,0.013078,34.559040,1.760522,0.130783,-336.320465,0.014188,0.000000
17.390001,7.858551,-336.409424,-0.003850,0.000524,0.013312,34.956581,1.780773,0.133122,-336.409424,0.014587,0.000000
17.630001,8.700111,-336.364960,-0.003820,0.000556,0.014127,38.700027,1.971473,0.141275,-336.364960,0.014986,0.000000
17.870001,8.635689,-336.453918,-0.003837,0.000568,0.014431,38.413464,1.956875,0.144310,-336.453918,0.015385,0.000000
18.110001,8.973427,-336.453918,-0.003781,0.000587,0.014908,39.915794,2.033408,0.149079,-336.453918,0.015784,0.000000
18.350000,9.115677,-336.498383,-0.003807,0.000601,0.015255,40.548557,2.065642,0.152546,-336.498383,0.016192,0.000000
18.590000,9.406502,-336.498383,-0.003768,0.000619,0.015732,41.842209,2.131544,0.157315,-336.498383,0.016591,0.000000
18.830002,9.438896,-336.453918,-0.003764,0.000630,0.015992,41.986309,2.138885,0.159919,-336.453918,0.016990,0.000000
19.070002,9.626945,-336.542877,-0.003747,0.000644,0.016356,42.822792,2.181497,0.163560,-336.542877,0.017389,0.000000
19.310001,10.275986,-336.542877,-0.003734,0.000667,0.016937,45.709866,2.328572,0.169374,-336.542877,0.017787,0.000000
19.550001,10.462547,-336.498383,-0.003682,0.000684,0.017379,46.539734,2.370847,0.173795,-336.498383,0.018186,0.000000
19.790001,10.442810,-336.631836,-0.003695,0.000695,0.017666,46.451939,2.366374,0.176656,-336.631836,0.018585,0.000000
20.030001,10.696022,-336.542877,-0.003669,0.000711,0.018065,47.578281,2.423753,0.180645,-336.542877,0.018984,0.000000
20.270000,10.927269,-336.587372,-0.003660,0.000728,0.018498,48.606918,2.476155,0.184983,-336.587372,0.019392,0.000000
20.510000,11.224792,-336.676331,-0.003622,0.000744,0.018906,49.930370,2.543574,0.189056,-336.676331,0.019790,0.000000
20.750002,11.261658,-336.587372,-0.003626,0.000756,0.019192,50.094357,2.551928,0.191917,-336.587372,0.020189,0.000000
20.990002,11.493645,-336.676331,-0.003604,0.000772,0.019617,51.126286,2.604497,0.196171,-336.676331,0.020588,0.000000
21.230001,11.947945,-336.631836,-0.003583,0.000793,0.020146,53.147114,2.707443,0.201462,-336.631836,0.020987,0.000000
21.470001,12.109177,-336.676331,-0.003574,0.000810,0.020563,53.864307,2.743979,0.205626,-336.676331,0.021386,0.000000
21.710001,12.150887,-336.720795,-0.003566,0.000821,0.020857,54.049843,2.753430,0.208570,-336.720795,0.021785,0.000000
21.950001,12.290154,-336.720795,-0.003527,0.000838,0.021282,54.669334,2.784989,0.212817,-336.720795,0.022184,0.000000
22.190001,12.374306,-336.765289,-0.003540,0.000849,0.021560,55.043659,2.804058,0.215595,-336.765289,0.022591,0.000000
22.430000,12.744446,-336.765289,-0.003514,0.000868,0.022045,56.690125,2.887933,0.220455,-336.765289,0.022990,0.000000
22.670002,12.881477,-336.854248,-0.003505,0.000882,0.022392,57.299671,2.918984,0.223922,-336.854248,0.023389,0.000000
22.910002,13.034523,-336.720795,-0.003492,0.000895,0.022721,57.980453,2.953665,0.227215,-336.720795,0.023788,0.000000
23.150002,13.075859,-336.720795,-0.003462,0.000905,0.022999,58.164326,2.963032,0.229993,-336.720795,0.024187,0.000000
23.390001,14.023544,-336.854248,-0.003445,0.000937,0.023797,62.379841,3.177781,0.237971,-336.854248,0.024586,0.000000
23.630001,13.875343,-336.765289,-0.003419,0.000950,0.024136,61.720608,3.144198,0.241355,-336.765289,0.024985,0.000000
23.870001,13.839966,-336.898712,-0.003410,0.000961,0.024422,61.563244,3.136181,0.244217,-336.898712,0.025384,0.000000
24.110001,14.071213,-336.943207,-0.003372,0.000978,0.024846,62.591881,3.188582,0.248463,-336.943207,0.025792,0.000000
24.350000,14.284576,-336.854248,-0.003380,0.000993,0.025220,63.540970,3.236931,0.252195,-336.854248,0.026191,0.000000
24.590002,14.725471,-336.943207,-0.003359,0.001013,0.025731,65.502167,3.336839,0.257312,-336.943207,0.026590,0.000000
24.830002,14.385864,-336.854248,-0.003354,0.001023,0.025983,63.991520,3.259883,0.259825,-336.854248,0.026989,0.000000
25.070002,15.242691,-336.943207,-0.003316,0.001048,0.026607,67.802879,3.454043,0.266071,-336.943207,0.027387,0.000000
25.310001,15.108269,-336.898712,-0.003307,0.001059,0.026893,67.204933,3.423583,0.268932,-336.898712,0.027786,0.000000
25.550001,15.390152,-336.987671,-0.003290,0.001077,0.027361,68.458817,3.487458,0.273610,-336.987671,0.028185,0.000000
25.790001,15.318657,-336.987671,-0.003255,0.001090,0.027682,68.140793,3.471257,0.276820,-336.987671,0.028584,0.000000
26.030001,15.261681,-337.032166,-0.003229,0.001098,0.027899,67.887344,3.458346,0.278992,-337.032166,0.028992,0.000000
26.270000,15.844078,-337.076660,-0.003251,0.001119,0.028411,70.477982,3.590319,0.284109,-337.076660,0.029390,0.000000
26.510002,15.907379,-336.987671,-0.003234,0.001131,0.028731,70.759560,3.604664,0.287311,-336.987671,0.029789,0.000000
26.750002,15.939400,-337.076660,-0.003212,0.001143,0.029026,70.901993,3.611920,0.290264,-337.076660,0.030188,0.000000
26.990002,17.088913,-337.165619,-0.003195,0.001173,0.029807,76.015282,3.872403,0.298068,-337.165619,0.030587,0.000000
27.230001,16.903847,-336.987671,-0.003173,0.001186,0.030136,75.192062,3.830467,0.301361,-336.987671,0.030986,0.000000
27.470001,16.833839,-337.076660,-0.003143,0.001200,0.030474,74.880661,3.814603,0.304745,-337.076660,0.031385,0.000000
27.710001,16.858047,-337.076660,-0.003130,0.001215,0.030873,74.988342,3.820088,0.308734,-337.076660,0.031784,0.000000
27.950001,16.991356,-337.165619,-0.003109,0.001229,0.031229,75.581329,3.850296,0.312292,-337.165619,0.032192,0.000000
28.190001,17.101952,-337.210083,-0.003100,0.001244,0.031593,76.073280,3.875357,0.315933,-337.210083,0.032591,0.000000
28.430002,17.282181,-337.121124,-0.003078,0.001256,0.031914,76.874977,3.916198,0.319142,-337.121124,0.032990,0.000000
28.670002,17.292976,-337.210083,-0.003078,0.001269,0.032226,76.923004,3.918645,0.322261,-337.210083,0.033389,0.000000
28.910002,18.114059,-337.210083,-0.003035,0.001294,0.032868,80.575363,4.104704,0.328680,-337.210083,0.033788,0.000000
29.150002,18.648041,-337.165619,-0.003018,0.001317,0.033449,82.950630,4.225707,0.334494,-337.165619,0.034187,0.000000
29.390001,18.546013,-337.254578,-0.002992,0.001331,0.033813,82.496788,4.202586,0.338135,-337.254578,0.034586,0.000000
29.630001,18.182945,-337.210083,-0.002988,0.001343,0.034100,80.881783,4.120314,0.340996,-337.210083,0.034985,0.000000
29.870001,18.419029,-337.343536,-0.002984,0.001357,0.034455,81.931931,4.173811,0.344554,-337.343536,0.035392,0.000000
30.110001,18.584366,-337.254578,-0.002971,0.001374,0.034889,82.667389,4.211277,0.348892,-337.254578,0.035791,0.000000
30.350002,18.941841,-337.299042,-0.002936,0.001390,0.035296,84.257515,4.292283,0.352964,-337.299042,0.036190,0.000000
30.590002,18.868858,-337.343536,-0.002923,0.001400,0.035565,83.932877,4.275744,0.355651,-337.343536,0.036589,0.000000
30.830002,18.805923,-337.299042,-0.002902,0.001410,0.035808,83.652924,4.261483,0.358081,-337.299042,0.036988,0.000000
31.070002,20.014648,-337.388000,-0.002893,0.001440,0.036589,89.029602,4.535384,0.365886,-337.388000,0.037386,0.000000
31.310001,19.997887,-337.388000,-0.002884,0.001455,0.036953,88.955040,4.531586,0.369527,-337.388000,0.037785,0.000000
31.550001,19.774467,-337.388000,-0.002867,0.001466,0.037230,87.961227,4.480958,0.372305,-337.388000,0.038193,0.000000
31.790001,20.038849,-337.432495,-0.002811,0.001484,0.037681,89.137253,4.540868,0.376809,-337.432495,0.038592,0.000000
32.030003,20.505806,-337.343536,-0.002785,0.001504,0.038202,91.214378,4.646682,0.382017,-337.343536,0.038990,0.000000
32.270000,20.379570,-337.432495,-0.002798,0.001517,0.038531,90.652855,4.618076,0.385310,-337.432495,0.039389,0.000000
32.510002,20.117424,-337.432495,-0.002777,0.001526,0.038766,89.486771,4.558673,0.387657,-337.432495,0.039788,0.000000
32.750000,20.095825,-337.476990,-0.002794,0.001539,0.039086,89.390694,4.553779,0.390859,-337.476990,0.040187,0.000000
32.990002,21.155220,-337.521454,-0.002751,0.001564,0.039737,94.103119,4.793841,0.397369,-337.521454,0.040586,0.000000
33.230003,21.122826,-337.476990,-0.002703,0.001578,0.040092,93.959023,4.786501,0.400919,-337.476990,0.040985,0.000000
33.470001,21.015587,-337.610413,-0.002712,0.001591,0.040413,93.482002,4.762200,0.404128,-337.610413,0.041393,0.000000
33.710003,21.354073,-337.565948,-0.002708,0.001609,0.040864,94.987656,4.838902,0.408640,-337.565948,0.041792,0.000000
33.950001,21.317581,-337.565948,-0.002695,0.001621,0.041168,94.825340,4.830633,0.411675,-337.565948,0.042191,0.000000
34.190002,21.724205,-337.610413,-0.002665,0.001639,0.041636,96.634087,4.922775,0.416361,-337.610413,0.042590,0.000000
34.430000,21.586060,-337.521454,-0.002647,0.001652,0.041965,96.019592,4.891471,0.419654,-337.521454,0.042989,0.000000
34.670002,21.632233,-337.610413,-0.002621,0.001662,0.042217,96.224976,4.901934,0.422167,-337.610413,0.043388,0.000000
34.910000,22.835739,-337.699371,-0.002596,0.001693,0.043015,101.578438,5.174653,0.430146,-337.699371,0.043787,0.000000
35.150002,22.623863,-337.610413,-0.002565,0.001707,0.043361,100.635971,5.126641,0.433613,-337.610413,0.044186,0.000000
35.390003,22.489807,-337.743866,-0.002544,0.001721,0.043709,100.039658,5.096263,0.437087,-337.743866,0.044593,0.000000
35.630001,22.305107,-337.699371,-0.002522,0.001732,0.044003,99.218071,5.054410,0.440032,-337.699371,0.044992,0.000000
35.870003,22.920639,-337.699371,-0.002514,0.001752,0.044507,101.956093,5.193891,0.445066,-337.699371,0.045391,0.000000
36.110001,22.942238,-337.699371,-0.002483,0.001768,0.044914,102.052170,5.198786,0.449138,-337.699371,0.045790,0.000000
36.350002,22.811539,-337.610413,-0.002492,0.001779,0.045174,101.470795,5.169168,0.451742,-337.610413,0.046189,0.000000
36.590000,22.825317,-337.743866,-0.002462,0.001791,0.045504,101.532082,5.172291,0.455035,-337.743866,0.046588,0.000000
36.830002,23.335091,-337.743866,-0.002449,0.001813,0.046050,103.799667,5.287807,0.460501,-337.743866,0.046986,0.000000
37.070004,23.879501,-337.788330,-0.002419,0.001832,0.046544,106.221329,5.411172,0.465444,-337.788330,0.047385,0.000000
37.310001,23.727570,-337.788330,-0.002376,0.001846,0.046891,105.545502,5.376744,0.468911,-337.788330,0.047793,0.000000
37.550003,23.977058,-337.788330,-0.002363,0.001864,0.047333,106.655281,5.433279,0.473331,-337.788330,0.048192,0.000000
37.790001,23.643791,-337.877319,-0.002341,0.001876,0.047646,105.172836,5.357759,0.476458,-337.877319,0.048591,0.000000
38.030003,24.058609,-337.788330,-0.002324,0.001892,0.048062,107.018036,5.451759,0.480621,-337.788330,0.048990,0.000000
38.270000,24.016907,-337.966278,-0.002311,0.001903,0.048348,106.832535,5.442309,0.483482,-337.966278,0.049389,0.000000
38.510002,23.889557,-337.877319,-0.002311,0.001914,0.048609,106.266060,5.413451,0.486086,-337.877319,0.049788,0.000000
38.750000,23.783798,-337.921783,-0.002289,0.001930,0.049024,105.795616,5.389486,0.490242,-337.921783,0.050187,0.000000
38.990002,25.357071,-337.921783,-0.002298,0.001957,0.049710,112.793884,5.745994,0.497101,-337.921783,0.050586,0.000000
39.230003,25.001457,-337.921783,-0.002220,0.001969,0.050022,111.212036,5.665411,0.500219,-337.921783,0.050993,0.000000
39.470001,25.382027,-338.010742,-0.002212,0.001987,0.050481,112.904892,5.751649,0.504814,-338.010742,0.051392,0.000000
39.710003,25.286697,-337.877319,-0.002216,0.002002,0.050855,112.480850,5.730047,0.508546,-337.877319,0.051791,0.000000
39.950001,25.746948,-337.921783,-0.002182,0.002021,0.051340,114.528145,5.834342,0.513398,-337.921783,0.052190,0.000000
40.190002,25.351112,-338.010742,-0.002156,0.002029,0.051540,112.767380,5.744644,0.515397,-338.010742,0.052589,0.000000
40.430000,25.536186,-338.010742,-0.002160,0.002046,0.051964,113.590630,5.786582,0.519643,-338.010742,0.052988,0.000000
40.670002,26.348328,-338.099701,-0.002134,0.002069,0.052546,117.203217,5.970616,0.525457,-338.099701,0.053387,0.000000
40.910004,26.477173,-338.055237,-0.002108,0.002084,0.052945,117.776344,5.999813,0.529446,-338.055237,0.053786,0.000000
41.150002,26.158417,-338.099701,-0.002108,0.002096,0.053239,116.358452,5.927582,0.532391,-338.099701,0.054193,0.000000
41.390003,26.413864,-338.144196,-0.002057,0.002114,0.053690,117.494736,5.985467,0.536902,-338.144196,0.054592,0.000000
41.630001,26.715118,-338.099701,-0.002057,0.002130,0.054098,118.834785,6.053732,0.540975,-338.099701,0.054991,0.000000
41.870003,26.814537,-338.144196,-0.002048,0.002143,0.054436,119.277016,6.076261,0.544359,-338.144196,0.055390,0.000000
42.110001,26.708038,-338.099701,-0.002009,0.002158,0.054809,118.803291,6.052128,0.548091,-338.099701,0.055789,0.000000
42.350002,27.058075,-338.144196,-0.002022,0.002175,0.055243,120.360329,6.131448,0.552428,-338.144196,0.056188,0.000000
42.590000,27.724991,-338.188660,-0.001975,0.002196,0.055772,123.326920,6.282573,0.557719,-338.188660,0.056586,0.000000
42.830002,27.838936,-338.144196,-0.001957,0.002211,0.056162,123.833771,6.308393,0.561618,-338.144196,0.056985,0.000000
43.070004,27.679932,-338.233154,-0.001949,0.002225,0.056526,123.126488,6.272362,0.565259,-338.233154,0.057393,0.000000
43.310001,27.866493,-338.233154,-0.001932,0.002240,0.056890,123.956352,6.314638,0.568900,-338.233154,0.057792,0.000000
43.550003,27.767815,-338.277618,-0.001927,0.002254,0.057246,123.517410,6.292277,0.572458,-338.277618,0.058191,0.000000
43.790001,28.211311,-338.277618,-0.001876,0.002270,0.057654,125.490181,6.392775,0.576538,-338.277618,0.058590,0.000000
44.030003,28.358025,-338.277618,-0.001867,0.002285,0.058044,126.142792,6.426020,0.580436,-338.277618,0.058989,0.000000
44.270000,28.110771,-338.366608,-0.001841,0.002295,0.058287,125.042953,6.369992,0.582866,-338.366608,0.059388,0.000000
44.510002,28.696136,-338.366608,-0.001850,0.002315,0.058807,127.646790,6.502638,0.588067,-338.366608,0.059787,0.000000
44.750004,29.667656,-338.322113,-0.001807,0.002338,0.059379,131.968323,6.722787,0.593789,-338.322113,0.060194,0.000000
44.990002,29.459503,-338.366608,-0.001781,0.002350,0.059692,131.042419,6.675619,0.596916,-338.366608,0.060593,0.000000
45.230003,29.148567,-338.366608,-0.001750,0.002362,0.059995,129.659302,6.605160,0.599951,-338.366608,0.060992,0.000000
45.470001,29.316879,-338.411072,-0.001755,0.002378,0.060394,130.407990,6.643300,0.603941,-338.411072,0.061391,0.000000
45.710003,29.435669,-338.411072,-0.001720,0.002395,0.060845,130.936401,6.670218,0.608452,-338.411072,0.061790,0.000000
45.950001,29.987152,-338.411072,-0.001699,0.002412,0.061261,133.389511,6.795186,0.612608,-338.411072,0.062189,0.000000
46.190002,30.137589,-338.500031,-0.001707,0.002430,0.061712,134.058685,6.829275,0.617120,-338.500031,0.062588,0.000000
46.430000,30.639549,-338.411072,-0.001681,0.002447,0.062163,136.291519,6.943021,0.621631,-338.411072,0.062987,0.000000
46.670002,30.372559,-338.455566,-0.001656,0.002461,0.062519,135.103882,6.882520,0.625189,-338.455566,0.063395,0.000000
46.910004,30.662636,-338.455566,-0.001638,0.002477,0.062909,136.394211,6.948253,0.629087,-338.455566,0.063794,0.000000
47.150002,30.538261,-338.544525,-0.001651,0.002490,0.063239,135.840973,6.920069,0.632388,-338.544525,0.064193,0.000000
47.390003,30.100723,-338.500031,-0.001582,0.002498,0.063446,133.894699,6.820921,0.634462,-338.500031,0.064592,0.000000
47.630001,30.855156,-338.500031,-0.001582,0.002518,0.063950,137.250595,6.991878,0.639496,-338.500031,0.064990,0.000000
47.870003,30.877495,-338.588989,-0.001556,0.002532,0.064314,137.349960,6.996941,0.643137,-338.588989,0.065389,0.000000
48.110001,30.831322,-338.500031,-0.001548,0.002543,0.064592,137.144562,6.986477,0.645915,-338.500031,0.065788,0.000000
48.350002,32.625786,-338.588989,-0.001548,0.002574,0.065380,145.126740,7.393109,0.653803,-338.588989,0.066187,0.000000
48.590004,32.515564,-338.633484,-0.001509,0.002588,0.065744,144.636459,7.368132,0.657444,-338.633484,0.066594,0.000000
48.830002,32.191597,-338.544525,-0.001479,0.002600,0.066031,143.195374,7.294720,0.660305,-338.544525,0.066993,0.000000
49.070004,32.314110,-338.633484,-0.001449,0.002615,0.066413,143.740341,7.322482,0.664128,-338.633484,0.067392,0.000000
49.310001,32.253784,-338.633484,-0.001462,0.002628,0.066742,143.472000,7.308812,0.667421,-338.633484,0.067791,0.000000
49.550003,32.233307,-338.722443,-0.001449,0.002641,0.067089,143.380905,7.304172,0.670888,-338.722443,0.068190,0.000000
49.790001,32.454865,-338.722443,-0.001427,0.002656,0.067462,144.366455,7.354377,0.674620,-338.722443,0.068589,0.000000
50.030003,32.680893,-338.633484,-0.001406,0.002673,0.067887,145.371872,7.405596,0.678866,-338.633484,0.068988,0.000000
50.270004,34.093307,-338.766937,-0.001362,0.002699,0.068563,151.654602,7.725654,0.685634,-338.766937,0.069387,0.000000
50.510002,34.469398,-338.677948,-0.001328,0.002718,0.069040,153.327545,7.810877,0.690403,-338.677948,0.069795,0.000000
50.750004,34.195335,-338.766937,-0.001341,0.002730,0.069344,152.108444,7.748774,0.693438,-338.766937,0.070194,0.000000
50.990002,33.765991,-338.766937,-0.001345,0.002742,0.069656,150.198624,7.651483,0.696557,-338.766937,0.070593,0.000000
51.230003,33.795410,-338.766937,-0.001311,0.002757,0.070029,150.329498,7.658149,0.700289,-338.766937,0.070992,0.000000
51.470001,34.206879,-338.855896,-0.001276,0.002775,0.070480,152.159790,7.751390,0.704800,-338.855896,0.071391,0.000000
51.710003,34.333488,-338.766937,-0.001250,0.002789,0.070835,152.722977,7.780080,0.708351,-338.766937,0.071790,0.000000
51.950001,34.193474,-338.855896,-0.001229,0.002799,0.071104,152.100174,7.748352,0.711038,-338.855896,0.072189,0.000000
52.190002,34.327156,-338.855896,-0.001233,0.002817,0.071564,152.694809,7.778645,0.715640,-338.855896,0.072587,0.000000
52.430004,35.542953,-338.900360,-0.001203,0.002840,0.072127,158.102951,8.054149,0.721272,-338.900360,0.072995,0.000000
52.670002,35.713493,-338.944855,-0.001194,0.002855,0.072518,158.861557,8.092793,0.725178,-338.944855,0.073394,0.000000
52.910004,35.415230,-338.900360,-0.001190,0.002867,0.072812,157.534805,8.025206,0.728123,-338.900360,0.073793,0.000000
53.150002,35.729881,-338.944855,-0.001147,0.002884,0.073246,158.934448,8.096507,0.732460,-338.944855,0.074192,0.000000
53.390003,36.346901,-339.033813,-0.001130,0.002903,0.073740,161.679092,8.236325,0.737404,-339.033813,0.074590,0.000000
53.630001,36.237053,-338.944855,-0.001138,0.002916,0.074070,161.190460,8.211433,0.740704,-338.944855,0.074989,0.000000
53.870003,35.840851,-338.989319,-0.001117,0.002925,0.074295,159.428070,8.121653,0.742952,-338.989319,0.075388,0.000000
54.110004,36.126457,-338.989319,-0.001065,0.002946,0.074816,160.698502,8.186372,0.748160,-338.989319,0.075787,0.000000
54.350002,37.238731,-339.033813,-0.001056,0.002965,0.075301,165.646149,8.438417,0.753012,-339.033813,0.076194,0.000000
54.590004,37.485992,-339.078278,-0.001065,0.002982,0.075744,166.746017,8.494447,0.757441,-339.078278,0.076593,0.000000
54.830002,37.078987,-338.989319,-0.001026,0.002994,0.076048,164.935577,8.402219,0.760476,-338.989319,0.076992,0.000000
55.070004,37.455086,-339.167267,-0.001009,0.003008,0.076412,166.608536,8.487444,0.764117,-339.167267,0.077391,0.000000
55.310001,37.480408,-339.078278,-0.000992,0.003024,0.076802,166.721176,8.493181,0.768016,-339.078278,0.077790,0.000000
55.550003,37.762665,-339.122772,-0.000983,0.003038,0.077166,167.976715,8.557142,0.771657,-339.122772,0.078189,0.000000
55.790001,37.768990,-339.167267,-0.000983,0.003051,0.077487,168.004852,8.558576,0.774866,-339.167267,0.078588,0.000000
56.030003,37.809952,-339.167267,-0.000961,0.003065,0.077860,168.187073,8.567857,0.778598,-339.167267,0.078987,0.000000
56.270004,39.551170,-339.256226,-0.000923,0.003093,0.078562,175.932388,8.962423,0.785623,-339.256226,0.079395,0.000000
56.510002,39.545586,-339.256226,-0.000931,0.003107,0.078926,175.907547,8.961158,0.789264,-339.256226,0.079794,0.000000
56.750004,39.364983,-339.167267,-0.000901,0.003120,0.079247,175.104187,8.920233,0.792474,-339.167267,0.080193,0.000000
56.990002,39.097244,-339.256226,-0.000858,0.003134,0.079594,173.913223,8.859562,0.795941,-339.256226,0.080592,0.000000
57.230003,40.054619,-339.211731,-0.000862,0.003153,0.080097,178.171844,9.076506,0.800975,-339.211731,0.080991,0.000000
57.470001,40.107864,-339.300690,-0.000845,0.003167,0.080452,178.408691,9.088573,0.804525,-339.300690,0.081390,0.000000
57.710003,39.838638,-339.256226,-0.000819,0.003177,0.080705,177.211121,9.027564,0.807046,-339.256226,0.081789,0.000000
57.950005,39.997643,-339.300690,-0.000824,0.003192,0.081069,177.918396,9.063596,0.810687,-339.300690,0.082196,0.000000
58.190002,40.914421,-339.300690,-0.000793,0.003217,0.081711,181.996429,9.271340,0.817106,-339.300690,0.082595,0.000000
58.430004,41.651718,-339.345184,-0.000776,0.003232,0.082083,185.276093,9.438415,0.820830,-339.345184,0.082994,0.000000
58.670002,41.780937,-339.345184,-0.000785,0.003249,0.082534,185.850891,9.467695,0.825342,-339.345184,0.083393,0.000000
58.910004,42.077339,-339.300690,-0.000759,0.003262,0.082863,187.169357,9.534862,0.828635,-339.300690,0.083792,0.000000
59.150002,42.118301,-339.389648,-0.000711,0.003280,0.083306,187.351562,9.544144,0.833063,-339.389648,0.084190,0.000000
59.390003,42.653404,-339.434143,-0.000716,0.003293,0.083644,189.731812,9.665400,0.836439,-339.434143,0.084589,0.000000
59.630001,42.478386,-339.345184,-0.000698,0.003304,0.083922,188.953293,9.625740,0.839217,-339.345184,0.084988,0.000000
59.870003,42.299278,-339.478607,-0.000673,0.003315,0.084190,188.156586,9.585153,0.841904,-339.478607,0.085396,0.000000
60.110004,43.674820,-339.434143,-0.000681,0.003340,0.084824,194.275299,9.896856,0.848240,-339.434143,0.085795,0.000000
60.350002,44.463875,-339.478607,-0.000655,0.003358,0.085301,197.785187,10.075658,0.853009,-339.478607,0.086194,0.000000
60.590004,44.513031,-339.478607,-0.000651,0.003372,0.085656,198.003845,10.086797,0.856560,-339.478607,0.086593,0.000000
60.830002,45.017220,-339.434143,-0.000625,0.003388,0.086055,200.246597,10.201048,0.860549,-339.434143,0.086992,0.000000
61.070004,45.457367,-339.523102,-0.000604,0.003404,0.086471,202.204468,10.300786,0.864712,-339.523102,0.087391,0.000000
61.310001,46.114235,-339.567566,-0.000591,0.003421,0.086905,205.126358,10.449635,0.869050,-339.567566,0.087790,0.000000
61.550003,45.753777,-339.567566,-0.000595,0.003428,0.087078,203.522964,10.367953,0.870783,-339.567566,0.088189,0.000000
61.790005,46.376381,-339.612061,-0.000578,0.003447,0.087547,206.292450,10.509038,0.875469,-339.612061,0.088596,0.000000
62.030003,47.688995,-339.567566,-0.000565,0.003470,0.088137,212.131241,10.806481,0.881366,-339.567566,0.088995,0.000000
62.270004,48.118713,-339.612061,-0.000560,0.003483,0.088475,214.042725,10.903856,0.884749,-339.612061,0.089394,0.000000
62.510002,48.154091,-339.612061,-0.000530,0.003497,0.088813,214.200089,10.911873,0.888126,-339.612061,0.089793,0.000000
62.750004,48.843353,-339.612061,-0.000530,0.003513,0.089238,217.266083,11.068062,0.892380,-339.612061,0.090192,0.000000
62.990002,49.538567,-339.612061,-0.000492,0.003530,0.089663,220.358551,11.225599,0.896626,-339.612061,0.090591,0.000000
63.230003,49.937752,-339.656555,-0.000492,0.003542,0.089975,222.134216,11.316056,0.899753,-339.656555,0.090990,0.000000
63.470001,50.436729,-339.745514,-0.000492,0.003557,0.090357,224.353775,11.429126,0.903568,-339.745514,0.091389,0.000000
63.710003,51.270844,-339.701019,-0.000466,0.003575,0.090799,228.064102,11.618139,0.907989,-339.701019,0.091796,0.000000
63.950005,52.491852,-339.701019,-0.000461,0.003596,0.091336,233.495422,11.894824,0.913363,-339.701019,0.092195,0.000000
64.190002,53.144249,-339.701019,-0.000453,0.003611,0.091710,236.397430,12.042659,0.917095,-339.701019,0.092594,0.000000
64.430000,53.607109,-339.701019,-0.000470,0.003625,0.092065,238.456329,12.147544,0.920653,-339.701019,0.092993,0.000000
64.670006,54.160454,-339.745514,-0.000405,0.003639,0.092420,240.917725,12.272934,0.924203,-339.745514,0.093392,0.000000
64.910004,54.636719,-339.789978,-0.000431,0.003655,0.092837,243.036270,12.380857,0.928367,-339.789978,0.093790,0.000000
65.150002,55.632820,-339.789978,-0.000427,0.003670,0.093210,247.467148,12.606578,0.932099,-339.789978,0.094189,0.000000
65.389999,56.285957,-339.789978,-0.000375,0.003684,0.093574,250.372437,12.754580,0.935740,-339.789978,0.094588,0.000000
65.630005,56.615135,-339.789978,-0.000401,0.003695,0.093852,251.836700,12.829173,0.938518,-339.789978,0.094996,0.000000
65.870003,58.002594,-339.789978,-0.000379,0.003718,0.094432,258.008423,13.143576,0.944324,-339.789978,0.095395,0.000000
66.110001,59.467880,-339.878937,-0.000366,0.003737,0.094927,264.526337,13.475615,0.949267,-339.878937,0.095794,0.000000
66.350006,59.918823,-339.878937,-0.000362,0.003749,0.095213,266.532227,13.577799,0.952128,-339.878937,0.096193,0.000000
66.590004,60.354874,-339.923431,-0.000371,0.003764,0.095612,268.471893,13.676610,0.956117,-339.923431,0.096592,0.000000
66.830002,61.158821,-339.878937,-0.000323,0.003776,0.095915,272.048035,13.858787,0.959153,-339.878937,0.096991,0.000000
67.070000,62.102043,-339.923431,-0.000345,0.003797,0.096444,276.243683,14.072524,0.964444,-339.923431,0.097390,0.000000
67.310005,63.282463,-339.923431,-0.000319,0.003810,0.096783,281.494446,14.340011,0.967828,-339.923431,0.097789,0.000000
67.550003,64.280792,-339.967896,-0.000332,0.003828,0.097242,285.935242,14.566236,0.972423,-339.967896,0.098196,0.000000
67.790001,65.541641,-339.967896,-0.000302,0.003847,0.097719,291.543793,14.851948,0.977192,-339.967896,0.098595,0.000000
68.030006,66.347458,-340.012390,-0.000306,0.003862,0.098092,295.128235,15.034550,0.980924,-340.012390,0.098994,0.000000
68.270004,67.186783,-340.012390,-0.000306,0.003876,0.098456,298.861725,15.224743,0.984565,-340.012390,0.099393,0.000000
68.510002,67.063538,-340.012390,-0.000259,0.003872,0.098361,298.313507,15.196815,0.983611,-340.012390,0.098578,0.000000
68.750000,66.384705,-339.967896,-0.000289,0.003872,0.098361,295.293915,15.042990,0.983611,-339.967896,0.098578,0.000000
68.990005,65.813110,-340.101349,-0.000285,0.003872,0.098344,292.751343,14.913464,0.983437,-340.101349,0.098361,0.000000
69.230003,65.288803,-340.056885,-0.000272,0.003871,0.098335,290.419098,14.794654,0.983354,-340.056885,0.098361,0.000000
69.470001,64.838974,-340.101349,-0.000254,0.003871,0.098335,288.418152,14.692721,0.983354,-340.101349,0.098361,0.000000
69.710007,64.453201,-340.101349,-0.000241,0.003871,0.098326,286.702148,14.605304,0.983263,-340.101349,0.098361,0.000000
69.950005,64.074875,-340.056885,-0.000267,0.003871,0.098326,285.019287,14.519574,0.983263,-340.056885,0.098361,0.000000
70.190002,63.779587,-340.101349,-0.000259,0.003871,0.098326,283.705780,14.452661,0.983263,-340.101349,0.098361,0.000000
70.430000,63.481308,-340.101349,-0.000246,0.003871,0.098326,282.378967,14.385070,0.983263,-340.101349,0.098361,0.000000
70.670006,63.211716,-340.190308,-0.000259,0.003871,0.098326,281.179749,14.323979,0.983263,-340.190308,0.098361,0.000000
70.910004,62.987175,-340.145844,-0.000237,0.003871,0.098326,280.180939,14.273098,0.983263,-340.145844,0.098361,0.000000
71.150002,62.753326,-340.234802,-0.000259,0.003871,0.098318,279.140747,14.220106,0.983179,-340.234802,0.098361,0.000000
71.390007,62.561920,-340.190308,-0.000229,0.003871,0.098318,278.289307,14.176734,0.983179,-340.190308,0.098361,0.000000
71.630005,62.370522,-340.234802,-0.000224,0.003871,0.098318,277.437927,14.133363,0.983179,-340.234802,0.098361,0.000000
71.870003,62.192162,-340.234802,-0.000233,0.003871,0.098318,276.644562,14.092945,0.983179,-340.234802,0.098361,0.000000
72.110001,62.030548,-340.234802,-0.000229,0.003871,0.098318,275.925659,14.056323,0.983179,-340.234802,0.098361,0.000000
72.350006,61.877129,-340.279266,-0.000254,0.003871,0.098318,275.243225,14.021558,0.983179,-340.279266,0.098361,0.000000
72.590004,61.741959,-340.279266,-0.000259,0.003871,0.098318,274.641937,13.990928,0.983179,-340.279266,0.098361,0.000000
72.830002,61.626526,-340.279266,-0.000220,0.003871,0.098318,274.128479,13.964770,0.983179,-340.279266,0.098361,0.000000
73.070000,61.478317,-340.368225,-0.000233,0.003871,0.098318,273.469208,13.931187,0.983179,-340.368225,0.098361,0.000000
73.310005,61.368469,-340.279266,-0.000224,0.003871,0.098318,272.980591,13.906294,0.983179,-340.279266,0.098361,0.000000
73.550003,61.245956,-340.368225,-0.000216,0.003871,0.098318,272.435608,13.878532,0.983179,-340.368225,0.098361,0.000000
73.790001,61.137230,-340.412720,-0.000254,0.003871,0.098318,271.951996,13.853894,0.983179,-340.412720,0.098361,0.000000
74.030006,61.051956,-340.368225,-0.000216,0.003871,0.098318,271.572662,13.834571,0.983179,-340.368225,0.098361,0.000000
74.270004,60.930931,-340.457214,-0.000237,0.003871,0.098318,271.034332,13.807146,0.983179,-340.457214,0.098361,0.000000
74.510002,60.870979,-340.457214,-0.000207,0.003871,0.098318,270.767639,13.793561,0.983179,-340.457214,0.098361,0.000000
74.750000,60.741768,-340.546173,-0.000211,0.003871,0.098318,270.192871,13.764281,0.983179,-340.546173,0.098361,0.000000
74.990005,60.678833,-340.546173,-0.000246,0.003871,0.098318,269.912933,13.750020,0.983179,-340.546173,0.098361,0.000000
75.230003,60.593567,-340.457214,-0.000233,0.003871,0.098318,269.533661,13.730699,0.983179,-340.457214,0.098361,0.000000
75.470001,60.521698,-340.457214,-0.000220,0.003871,0.098318,269.213959,13.714413,0.983179,-340.457214,0.098361,0.000000
75.710007,60.452431,-340.501678,-0.000250,0.003871,0.098318,268.905853,13.698716,0.983179,-340.501678,0.098361,0.000000
75.950005,60.367157,-340.590637,-0.000216,0.003871,0.098318,268.526520,13.679393,0.983179,-340.590637,0.098361,0.000000
76.190002,60.299385,-340.546173,-0.000229,0.003871,0.098318,268.225067,13.664036,0.983179,-340.546173,0.098361,0.000000
76.430000,60.231247,-340.546173,-0.000224,0.003871,0.098318,267.921967,13.648596,0.983179,-340.546173,0.098361,0.000000
76.670006,60.170547,-340.546173,-0.000224,0.003871,0.098318,267.651978,13.634840,0.983179,-340.546173,0.098361,0.000000
76.910004,60.102402,-340.590637,-0.000220,0.003871,0.098318,267.348846,13.619399,0.983179,-340.590637,0.098361,0.000000
77.150002,60.032768,-340.635132,-0.000233,0.003871,0.098318,267.039093,13.603620,0.983179,-340.635132,0.098361,0.000000
77.390007,59.986595,-340.679596,-0.000220,0.003871,0.098318,266.833710,13.593157,0.983179,-340.679596,0.098361,0.000000
77.630005,59.918083,-340.590637,-0.000216,0.003871,0.098318,266.528931,13.577632,0.983179,-340.590637,0.098361,0.000000
77.870003,59.865204,-340.679596,-0.000246,0.003871,0.098318,266.293732,13.565649,0.983179,-340.679596,0.098361,0.000000
78.110001,59.811211,-340.635132,-0.000220,0.003871,0.098318,266.053558,13.553414,0.983179,-340.635132,0.098361,0.000000
78.350006,59.750137,-340.635132,-0.000220,0.003871,0.098318,265.781891,13.539575,0.983179,-340.635132,0.098361,0.000000
78.590004,59.708435,-340.679596,-0.000207,0.003871,0.098318,265.596375,13.530125,0.983179,-340.679596,0.098361,0.000000
78.830002,59.661140,-340.635132,-0.000220,0.003871,0.098318,265.386017,13.519407,0.983179,-340.635132,0.098361,0.000000
79.070007,59.607895,-340.768555,-0.000237,0.003871,0.098318,265.149170,13.507342,0.983179,-340.768555,0.098361,0.000000
79.310005,59.568047,-340.724091,-0.000211,0.003871,0.098318,264.971893,13.498312,0.983179,-340.724091,0.098361,0.000000
79.550003,59.507729,-340.768555,-0.000250,0.003871,0.098318,264.703583,13.484645,0.983179,-340.768555,0.098361,0.000000
79.790001,59.472351,-340.768555,-0.000207,0.003871,0.098318,264.546234,13.476627,0.983179,-340.768555,0.098361,0.000000
80.030006,59.429901,-340.724091,-0.000211,0.003871,0.098318,264.357391,13.467008,0.983179,-340.724091,0.098361,0.000000
80.270004,59.391174,-340.857513,-0.000203,0.003871,0.098318,264.185150,13.458233,0.983179,-340.857513,0.098361,0.000000
80.510002,59.339783,-340.768555,-0.000224,0.003871,0.098318,263.956543,13.446587,0.983179,-340.768555,0.098361,0.000000
80.750008,59.306274,-340.857513,-0.000198,0.003871,0.098318,263.807495,13.438993,0.983179,-340.857513,0.098361,0.000000
80.990005,59.272758,-340.946503,-0.000203,0.003871,0.098318,263.658386,13.431398,0.983179,-340.946503,0.098361,0.000000
81.230003,59.220627,-340.813049,-0.000224,0.003871,0.098318,263.426514,13.419586,0.983179,-340.813049,0.098361,0.000000
81.470001,59.186737,-340.946503,-0.000224,0.003871,0.098318,263.275757,13.411906,0.983179,-340.946503,0.098361,0.000000
81.710007,59.142799,-340.902008,-0.000233,0.003871,0.098318,263.080322,13.401950,0.983179,-340.902008,0.098361,0.000000
81.950005,59.106682,-340.902008,-0.000211,0.003871,0.098318,262.919647,13.393766,0.983179,-340.902008,0.098361,0.000000
82.190002,59.072418,-340.990967,-0.000254,0.003871,0.098318,262.767242,13.386002,0.983179,-340.990967,0.098361,0.000000
82.430000,59.041512,-340.946503,-0.000220,0.003871,0.098318,262.629761,13.378998,0.983179,-340.946503,0.098361,0.000000
82.670006,59.007629,-341.035461,-0.000229,0.003871,0.098318,262.479034,13.371320,0.983179,-341.035461,0.098361,0.000000
82.910004,58.970390,-340.946503,-0.000203,0.003871,0.098318,262.313385,13.362882,0.983179,-340.946503,0.098361,0.000000
83.150002,58.936874,-340.946503,-0.000224,0.003871,0.098318,262.164307,13.355287,0.983179,-340.946503,0.098361,0.000000
83.390007,58.906342,-341.035461,-0.000211,0.003871,0.098318,262.028503,13.348368,0.983179,-341.035461,0.098361,0.000000
83.630005,58.866875,-340.946503,-0.000216,0.003871,0.098318,261.852936,13.339424,0.983179,-340.946503,0.098361,0.000000
83.870003,58.830750,-341.079926,-0.000198,0.003871,0.098318,261.692230,13.331239,0.983179,-341.079926,0.098361,0.000000
84.110001,58.800964,-341.035461,-0.000211,0.003871,0.098318,261.559753,13.324489,0.983179,-341.035461,0.098361,0.000000
84.350006,58.777130,-341.079926,-0.000198,0.003871,0.098318,261.453735,13.319088,0.983179,-341.079926,0.098361,0.000000
84.590004,58.738403,-341.079926,-0.000185,0.003871,0.098318,261.281464,13.310312,0.983179,-341.079926,0.098361,0.000000
84.830002,58.707123,-341.035461,-0.000216,0.003871,0.098318,261.142334,13.303225,0.983179,-341.035461,0.098361,0.000000
85.070007,58.689247,-341.168884,-0.000198,0.003871,0.098318,261.062805,13.299173,0.983179,-341.168884,0.098361,0.000000
85.310005,58.651268,-341.079926,-0.000237,0.003871,0.098318,260.893860,13.290567,0.983179,-341.079926,0.098361,0.000000
85.550003,58.636002,-341.168884,-0.000207,0.003871,0.098318,260.825958,13.287108,0.983179,-341.168884,0.098361,0.000000
85.790001,58.603973,-341.124420,-0.000237,0.003871,0.098318,260.683502,13.279850,0.983179,-341.124420,0.098361,0.000000
86.030006,58.584984,-341.168884,-0.000224,0.003871,0.098318,260.599030,13.275547,0.983179,-341.168884,0.098361,0.000000
86.270004,58.553703,-341.213379,-0.000220,0.003871,0.098318,260.459869,13.268458,0.983179,-341.213379,0.098361,0.000000
86.510002,58.539558,-341.213379,-0.000224,0.003871,0.098318,260.396973,13.265254,0.983179,-341.213379,0.098361,0.000000
86.750008,58.498222,-341.257843,-0.000237,0.003871,0.098318,260.213104,13.255887,0.983179,-341.257843,0.098361,0.000000
86.990005,58.481842,-341.346832,-0.000220,0.003871,0.098318,260.140228,13.252174,0.983179,-341.346832,0.098361,0.000000
87.230003,58.442741,-341.257843,-0.000198,0.003871,0.098318,259.966309,13.243315,0.983179,-341.257843,0.098361,0.000000
87.470001,58.420769,-341.346832,-0.000211,0.003871,0.098318,259.868561,13.238336,0.983179,-341.346832,0.098361,0.000000
87.710007,58.403267,-341.257843,-0.000194,0.003871,0.098318,259.790710,13.234369,0.983179,-341.257843,0.098361,0.000000
87.950005,58.377571,-341.302338,-0.000233,0.003871,0.098318,259.676392,13.228547,0.983179,-341.302338,0.098361,0.000000
88.190002,58.345177,-341.391296,-0.000203,0.003871,0.098318,259.532318,13.221207,0.983179,-341.391296,0.098361,0.000000
88.430008,58.331772,-341.346832,-0.000216,0.003871,0.098318,259.472687,13.218168,0.983179,-341.346832,0.098361,0.000000
88.670006,58.314270,-341.391296,-0.000220,0.003871,0.098318,259.394836,13.214202,0.983179,-341.391296,0.098361,0.000000
88.910004,58.283737,-341.391296,-0.000207,0.003871,0.098318,259.259003,13.207284,0.983179,-341.391296,0.098361,0.000000
89.150002,58.260651,-341.435791,-0.000220,0.003871,0.098318,259.156311,13.202052,0.983179,-341.435791,0.098361,0.000000
89.390007,58.231232,-341.480255,-0.000229,0.003871,0.098318,259.025452,13.195385,0.983179,-341.480255,0.098361,0.000000
89.630005,58.206284,-341.391296,-0.000211,0.003871,0.098318,258.914490,13.189733,0.983179,-341.391296,0.098361,0.000000
89.870003,58.175377,-341.480255,-0.000216,0.003871,0.098318,258.777008,13.182729,0.983179,-341.480255,0.098361,0.000000
90.110001,58.168304,-341.435791,-0.000207,0.003871,0.098318,258.745544,13.181126,0.983179,-341.435791,0.098361,0.000000
90.350006,58.144470,-341.435791,-0.000185,0.003871,0.098318,258.639526,13.175725,0.983179,-341.435791,0.098361,0.000000
90.590004,58.132927,-341.524750,-0.000203,0.003871,0.098318,258.588165,13.173110,0.983179,-341.524750,0.098361,0.000000
90.830002,58.110580,-341.524750,-0.000207,0.003871,0.098318,258.488770,13.168046,0.983179,-341.524750,0.098361,0.000000
91.070007,58.083031,-341.613708,-0.000216,0.003871,0.098318,258.366211,13.161802,0.983179,-341.613708,0.098361,0.000000
91.310005,58.072227,-341.524750,-0.000224,0.003871,0.098318,258.318176,13.159355,0.983179,-341.524750,0.098361,0.000000
91.550003,58.036850,-341.569214,-0.000211,0.003871,0.098318,258.160797,13.151338,0.983179,-341.569214,0.098361,0.000000
91.790001,58.032013,-341.613708,-0.000194,0.003871,0.098318,258.139282,13.150242,0.983179,-341.613708,0.098361,0.000000
92.030006,57.999992,-341.569214,-0.000198,0.003871,0.098318,257.996857,13.142986,0.983179,-341.569214,0.098361,0.000000
92.270004,57.998131,-341.613708,-0.000207,0.003871,0.098318,257.988556,13.142565,0.983179,-341.613708,0.098361,0.000000
92.510002,57.981743,-341.569214,-0.000190,0.003871,0.098318,257.915680,13.138850,0.983179,-341.569214,0.098361,0.000000
92.750008,57.967590,-341.658173,-0.000224,0.003871,0.098318,257.852722,13.135644,0.983179,-341.658173,0.098361,0.000000
92.990005,57.949722,-341.658173,-0.000220,0.003871,0.098318,257.773224,13.131595,0.983179,-341.658173,0.098361,0.000000
93.230003,57.929237,-341.658173,-0.000194,0.003871,0.098318,257.682129,13.126953,0.983179,-341.658173,0.098361,0.000000
93.470001,57.904663,-341.702667,-0.000194,0.003871,0.098318,257.572815,13.121385,0.983179,-341.702667,0.098361,0.000000
93.710007,57.892746,-341.658173,-0.000198,0.003871,0.098318,257.519806,13.118684,0.983179,-341.658173,0.098361,0.000000
93.950005,57.875992,-341.702667,-0.000207,0.003871,0.098318,257.445282,13.114887,0.983179,-341.702667,0.098361,0.000000
94.190002,57.859978,-341.836121,-0.000198,0.003871,0.098318,257.374023,13.111259,0.983179,-341.836121,0.098361,0.000000
94.430008,57.845825,-341.702667,-0.000224,0.003871,0.098318,257.311096,13.108051,0.983179,-341.702667,0.098361,0.000000
94.670006,57.824600,-341.836121,-0.000198,0.003871,0.098318,257.216675,13.103241,0.983179,-341.836121,0.098361,0.000000
94.910004,57.800400,-341.791626,-0.000194,0.003871,0.098318,257.109009,13.097758,0.983179,-341.791626,0.098361,0.000000
95.150002,57.797417,-341.836121,-0.000185,0.003871,0.098318,257.095764,13.097081,0.983179,-341.836121,0.098361,0.000000
95.390007,57.773216,-341.836121,-0.000207,0.003871,0.098318,256.988098,13.091599,0.983179,-341.836121,0.098361,0.000000
95.630005,57.755714,-341.791626,-0.000203,0.003871,0.098318,256.910248,13.087632,0.983179,-341.791626,0.098361,0.000000
95.870003,57.729271,-341.880585,-0.000185,0.003871,0.098318,256.792633,13.081640,0.983179,-341.880585,0.098361,0.000000
96.110008,57.721451,-341.836121,-0.000211,0.003871,0.098318,256.757843,13.079868,0.983179,-341.836121,0.098361,0.000000
96.350006,57.698364,-341.880585,-0.000203,0.003871,0.098318,256.655151,13.074636,0.983179,-341.880585,0.098361,0.000000
96.590004,57.681236,-342.014038,-0.000203,0.003871,0.098318,256.578949,13.070755,0.983179,-342.014038,0.098361,0.000000
96.830002,57.674911,-341.925079,-0.000224,0.003871,0.098318,256.550812,13.069322,0.983179,-341.925079,0.098361,0.000000
97.070007,57.665230,-341.925079,-0.000216,0.003871,0.098318,256.507751,13.067128,0.983179,-341.925079,0.098361,0.000000
97.310005,57.654427,-341.925079,-0.000211,0.003871,0.098318,256.459686,13.064680,0.983179,-341.925079,0.098361,0.000000
97.550003,57.632088,-342.014038,-0.000207,0.003871,0.098318,256.360321,13.059618,0.983179,-342.014038,0.098361,0.000000
97.790001,57.610863,-342.058502,-0.000211,0.003871,0.098318,256.265930,13.054808,0.983179,-342.058502,0.098361,0.000000
98.030006,57.601181,-341.969543,-0.000211,0.003871,0.098318,256.222839,13.052614,0.983179,-341.969543,0.098361,0.000000
98.270004,57.586281,-342.058502,-0.000207,0.003871,0.098318,256.156586,13.049237,0.983179,-342.058502,0.098361,0.000000
98.510002,57.567665,-342.014038,-0.000203,0.003871,0.098318,256.073761,13.045020,0.983179,-342.014038,0.098361,0.000000
98.750008,57.558357,-342.058502,-0.000203,0.003871,0.098318,256.032349,13.042910,0.983179,-342.058502,0.098361,0.000000
98.900002,57.550537,-342.147461,-0.000198,0.003871,0.098318,255.997574,13.041138,0.983179,-342.147461,0.098361,0.000000