File: Data/compression 14/AutoNoHeating-14-14-1-240726_07262024_165411.csv
Time (sec),S:Load (lbs),S:HL1 (DIM),S:LVDT (in),S:Position (in),Ch:Position (mm),Ch:Load (N),Ch:Stress (MPa),Ch:Strain (mm/mm),Ch:HL1 (DIM),Set Point (),Cycles ()
0.110000,0.013405,-413.005646,-0.005463,-0.005444,-0.138288,0.059628,0.003038,-1.382879,-413.005646,-0.138132,0.000000
0.340000,0.016754,-412.961151,-0.005445,-0.005444,-0.138288,0.074526,0.003797,-1.382879,-412.961151,-0.138132,0.000000
0.570000,0.028297,-413.050110,-0.005463,-0.005363,-0.136233,0.125873,0.006412,-1.362328,-413.050110,-0.135530,0.000000
0.800000,-0.000000,-413.050110,-0.005428,-0.005228,-0.132781,-0.000000,-0.000000,-1.327809,-413.050110,-0.131697,0.000000
1.030000,0.029785,-413.005646,-0.005256,-0.005090,-0.129295,0.132491,0.006749,-1.292950,-413.005646,-0.127864,0.000000
1.260000,0.019363,-413.050110,-0.005070,-0.004920,-0.124976,0.086133,0.004388,-1.249757,-413.050110,-0.124031,0.000000
1.490000,-0.015266,-413.005646,-0.004950,-0.004775,-0.121290,-0.067908,-0.003459,-1.212900,-413.005646,-0.120198,0.000000
1.720000,0.030907,-413.050110,-0.004769,-0.004629,-0.117579,0.137480,0.007004,-1.175785,-413.050110,-0.116364,0.000000
1.950000,0.824059,-413.139069,-0.004613,0.000001,0.000035,3.665596,0.186734,0.000348,-413.139069,0.000234,0.000000
2.180000,0.639366,-413.183563,-0.004626,-0.000000,-0.000000,2.844043,0.144882,-0.000000,-413.183563,0.000234,0.000000
2.410000,0.617393,-413.094604,-0.004626,-0.000000,-0.000000,2.746303,0.139903,-0.000000,-413.094604,0.000234,0.000000
2.640000,0.629311,-413.094604,-0.004631,-0.000000,-0.000000,2.799313,0.142604,-0.000000,-413.094604,0.000581,0.000000
2.870000,0.622978,-413.094604,-0.004618,-0.000000,-0.000000,2.771146,0.141169,-0.000000,-413.094604,0.000971,0.000000
3.100000,0.597656,-413.139069,-0.004631,0.000000,0.000008,2.658508,0.135431,0.000083,-413.139069,0.001353,0.000000
3.330000,1.010620,-413.228027,-0.004618,0.000032,0.000806,4.495463,0.229010,0.008062,-413.228027,0.001734,0.000000
3.560000,1.038918,-413.139069,-0.004613,0.000038,0.000963,4.621336,0.235422,0.009629,-413.139069,0.002116,0.000000
3.790000,1.326393,-413.139069,-0.004618,0.000059,0.001491,5.900091,0.300565,0.014912,-413.139069,0.002497,0.000000
4.020000,1.672325,-413.139069,-0.004544,0.000084,0.002142,7.438874,0.378954,0.021423,-413.139069,0.002888,0.000000
4.250000,1.827972,-413.272522,-0.004587,0.000097,0.002454,8.131227,0.414224,0.024541,-413.272522,0.003269,0.000000
4.480000,1.989960,-413.228027,-0.004562,0.000109,0.002758,8.851783,0.450931,0.027577,-413.228027,0.003651,0.000000
4.710000,2.211143,-413.228027,-0.004544,0.000123,0.003131,9.835657,0.501052,0.031309,-413.228027,0.004032,0.000000
4.940000,2.415581,-413.228027,-0.004497,0.000137,0.003478,10.745040,0.547378,0.034776,-413.228027,0.004423,0.000000
5.170000,2.771942,-413.183563,-0.004510,0.000154,0.003920,12.330215,0.628131,0.039196,-413.183563,0.004805,0.000000
5.400000,2.789444,-413.272522,-0.004480,0.000160,0.004076,12.408067,0.632097,0.040763,-413.272522,0.005186,0.000000
5.630000,3.024780,-413.361481,-0.004471,0.000174,0.004414,13.454895,0.685425,0.044139,-413.361481,0.005568,0.000000
5.860000,3.663773,-413.316986,-0.004458,0.000204,0.005186,16.297274,0.830223,0.051861,-413.316986,0.005949,0.000000
6.090000,3.793732,-413.316986,-0.004449,0.000218,0.005542,16.875360,0.859672,0.055418,-413.316986,0.006340,0.000000
6.320000,4.003746,-413.228027,-0.004441,0.000230,0.005845,17.809551,0.907262,0.058454,-413.228027,0.006721,0.000000
6.550000,4.224564,-413.405945,-0.004428,0.000242,0.006157,18.791798,0.957300,0.061573,-413.405945,0.007103,0.000000
6.780000,4.554489,-413.361481,-0.004406,0.000259,0.006582,20.259380,1.032062,0.065819,-413.361481,0.007484,0.000000
7.010000,4.937286,-413.361481,-0.004402,0.000278,0.007060,21.962147,1.118805,0.070596,-413.361481,0.007866,0.000000
7.240000,5.051605,-413.361481,-0.004359,0.000288,0.007311,22.470663,1.144710,0.073109,-413.361481,0.008256,0.000000
7.470000,5.221405,-413.405945,-0.004381,0.000300,0.007623,23.225969,1.183187,0.076228,-413.405945,0.008638,0.000000
7.700000,5.744965,-413.450439,-0.004368,0.000320,0.008134,25.554878,1.301828,0.081345,-413.450439,0.009019,0.000000
7.930000,6.097595,-413.450439,-0.004324,0.000341,0.008655,27.123459,1.381735,0.086545,-413.450439,0.009401,0.000000
8.160001,6.038765,-413.494934,-0.004324,0.000348,0.008829,26.861769,1.368404,0.088286,-413.494934,0.009782,0.000000
8.390000,6.232773,-413.450439,-0.004329,0.000361,0.009175,27.724758,1.412367,0.091753,-413.450439,0.010172,0.000000
8.620001,6.708290,-413.361481,-0.004277,0.000379,0.009617,29.839964,1.520120,0.096174,-413.361481,0.010554,0.000000
8.850000,6.833405,-413.539398,-0.004294,0.000392,0.009956,30.396502,1.548472,0.099558,-413.539398,0.010936,0.000000
9.080001,7.260887,-413.494934,-0.004268,0.000409,0.010398,32.298038,1.645341,0.103979,-413.494934,0.011318,0.000000
9.310000,7.287697,-413.405945,-0.004247,0.000419,0.010641,32.417294,1.651416,0.106409,-413.405945,0.011699,0.000000
9.540001,7.868233,-413.494934,-0.004260,0.000442,0.011231,34.999649,1.782967,0.112305,-413.494934,0.012089,0.000000
9.770000,8.263687,-413.494934,-0.004212,0.000461,0.011699,36.758717,1.872578,0.116991,-413.494934,0.012470,0.000000
10.000000,8.211555,-413.583893,-0.004199,0.000469,0.011925,36.526825,1.860765,0.119247,-413.583893,0.012852,0.000000
10.230000,8.470726,-413.583893,-0.004199,0.000486,0.012332,37.679672,1.919494,0.123319,-413.583893,0.013234,0.000000
10.460000,8.693031,-413.583893,-0.004156,0.000502,0.012739,38.668533,1.969869,0.127392,-413.583893,0.013616,0.000000
10.690001,8.967842,-413.583893,-0.004156,0.000514,0.013052,39.890953,2.032142,0.130518,-413.583893,0.014006,0.000000
10.920000,9.311172,-413.672852,-0.004139,0.000529,0.013433,41.418163,2.109942,0.134333,-413.672852,0.014387,0.000000
11.150001,9.412460,-413.628357,-0.004130,0.000542,0.013772,41.868713,2.132894,0.137717,-413.628357,0.014769,0.000000
11.380000,9.562149,-413.672852,-0.004100,0.000555,0.014093,42.534565,2.166814,0.140927,-413.672852,0.015150,0.000000
11.610001,10.255882,-413.717316,-0.004100,0.000579,0.014708,45.620441,2.324016,0.147081,-413.717316,0.015532,0.000000
11.840000,10.443558,-413.628357,-0.004118,0.000595,0.015107,46.455265,2.366544,0.151070,-413.628357,0.015922,0.000000
12.070001,10.503883,-413.628357,-0.004053,0.000609,0.015480,46.723606,2.380214,0.154802,-413.628357,0.016304,0.000000
12.300000,10.564949,-413.717316,-0.004057,0.000621,0.015784,46.995239,2.394052,0.157838,-413.717316,0.016685,0.000000
12.530001,10.856148,-413.806274,-0.004036,0.000637,0.016174,48.290558,2.460038,0.161736,-413.806274,0.017067,0.000000
12.760000,11.014030,-413.717316,-0.004018,0.000651,0.016529,48.992855,2.495815,0.165294,-413.717316,0.017457,0.000000
12.990001,11.428108,-413.761810,-0.004010,0.000669,0.016998,50.834763,2.589646,0.169980,-413.761810,0.017839,0.000000
13.220000,11.359222,-413.761810,-0.003971,0.000676,0.017162,50.528343,2.574037,0.171622,-413.761810,0.018220,0.000000
13.450001,11.612061,-413.761810,-0.003971,0.000690,0.017535,51.653027,2.631330,0.175354,-413.761810,0.018602,0.000000
13.680000,12.143440,-413.806274,-0.003949,0.000711,0.018055,54.016720,2.751743,0.180555,-413.806274,0.018984,0.000000
13.910001,12.392929,-413.806274,-0.003928,0.000727,0.018472,55.126503,2.808278,0.184718,-413.806274,0.019374,0.000000
14.140000,12.281212,-413.717316,-0.003919,0.000740,0.018793,54.629559,2.782963,0.187928,-413.717316,0.019756,0.000000
14.370001,12.764931,-413.806274,-0.003898,0.000759,0.019270,56.781246,2.892575,0.192697,-413.806274,0.020137,0.000000
14.600000,12.856529,-413.806274,-0.003923,0.000771,0.019591,57.188698,2.913331,0.195906,-413.806274,0.020519,0.000000
14.830001,13.083679,-413.895264,-0.003876,0.000786,0.019955,58.199112,2.964804,0.199547,-413.895264,0.020900,0.000000
15.060000,13.281036,-413.895264,-0.003876,0.000800,0.020328,59.077000,3.009526,0.203279,-413.895264,0.021290,0.000000
15.290001,13.087776,-413.850769,-0.003872,0.000808,0.020519,58.217335,2.965732,0.205187,-413.850769,0.021672,0.000000
15.520000,13.211777,-413.806274,-0.003846,0.000821,0.020848,58.768917,2.993831,0.208480,-413.806274,0.022054,0.000000
15.750001,14.246971,-413.850769,-0.003816,0.000850,0.021603,63.373692,3.228410,0.216027,-413.850769,0.022435,0.000000
15.980000,14.008652,-413.895264,-0.003807,0.000859,0.021819,62.313595,3.174406,0.218192,-413.895264,0.022817,0.000000
16.210001,14.235054,-413.895264,-0.003781,0.000877,0.022279,63.320683,3.225709,0.222786,-413.895264,0.023207,0.000000
16.440001,14.697914,-413.895264,-0.003786,0.000897,0.022790,65.379585,3.330595,0.227904,-413.895264,0.023588,0.000000
16.670000,14.664398,-413.939728,-0.003751,0.000911,0.023138,65.230499,3.323000,0.231378,-413.939728,0.023970,0.000000
16.900002,14.718765,-413.939728,-0.003725,0.000925,0.023485,65.472336,3.335320,0.234845,-413.939728,0.024352,0.000000
17.130001,14.436882,-414.028687,-0.003704,0.000932,0.023667,64.218460,3.271444,0.236669,-414.028687,0.024734,0.000000
17.360001,15.022621,-414.028687,-0.003699,0.000953,0.024195,66.823959,3.404175,0.241953,-414.028687,0.025123,0.000000
17.590000,15.630707,-414.028687,-0.003665,0.000974,0.024751,69.528854,3.541969,0.247509,-414.028687,0.025505,0.000000
17.820002,15.383080,-414.028687,-0.003652,0.000984,0.025002,68.427353,3.485856,0.250023,-414.028687,0.025886,0.000000
18.050001,15.454575,-414.073181,-0.003635,0.000998,0.025349,68.745384,3.502057,0.253490,-414.073181,0.026268,0.000000
18.280001,15.757683,-414.073181,-0.003652,0.001015,0.025783,70.093674,3.570742,0.257827,-414.073181,0.026650,0.000000
18.510000,16.010895,-414.073181,-0.003604,0.001032,0.026207,71.220016,3.628121,0.262074,-414.073181,0.027040,0.000000
18.740002,15.919670,-414.073181,-0.003604,0.001042,0.026468,70.814232,3.607449,0.264678,-414.073181,0.027422,0.000000
18.970001,15.986694,-414.028687,-0.003570,0.001054,0.026771,71.112366,3.622637,0.267713,-414.028687,0.027803,0.000000
19.200001,16.217194,-414.028687,-0.003548,0.001071,0.027196,72.137680,3.674869,0.271960,-414.028687,0.028185,0.000000
19.430000,16.938477,-414.117645,-0.003544,0.001093,0.027760,75.346107,3.838314,0.277599,-414.117645,0.028566,0.000000
19.660002,17.047585,-414.117645,-0.003527,0.001108,0.028150,75.831444,3.863038,0.281498,-414.117645,0.028957,0.000000
19.890001,16.885597,-414.117645,-0.003514,0.001120,0.028445,75.110886,3.826331,0.284450,-414.117645,0.029338,0.000000
20.120001,16.843147,-414.117645,-0.003510,0.001133,0.028766,74.922058,3.816712,0.287660,-414.117645,0.029720,0.000000
20.350000,17.192062,-414.162140,-0.003479,0.001149,0.029173,76.474113,3.895777,0.291732,-414.162140,0.030101,0.000000
20.580002,17.355164,-414.206604,-0.003445,0.001164,0.029564,77.199623,3.932736,0.295638,-414.206604,0.030483,0.000000
20.810001,17.272865,-414.295593,-0.003419,0.001174,0.029815,76.833542,3.914087,0.298151,-414.295593,0.030873,0.000000
21.040001,17.432617,-414.206604,-0.003393,0.001188,0.030171,77.544151,3.950288,0.301709,-414.206604,0.031255,0.000000
21.270000,17.826958,-414.251099,-0.003419,0.001208,0.030683,79.298271,4.039646,0.306826,-414.251099,0.031636,0.000000
21.500002,18.417915,-414.206604,-0.003406,0.001230,0.031246,81.926979,4.173559,0.312458,-414.206604,0.032018,0.000000
21.730001,18.253700,-414.206604,-0.003341,0.001242,0.031549,81.196510,4.136348,0.315494,-414.206604,0.032409,0.000000
21.960001,18.095810,-414.295593,-0.003328,0.001254,0.031845,80.494186,4.100569,0.318446,-414.295593,0.032790,0.000000
22.190001,18.079430,-414.251099,-0.003316,0.001266,0.032148,80.421318,4.096857,0.321481,-414.251099,0.033172,0.000000
22.420002,18.199333,-414.251099,-0.003303,0.001281,0.032530,80.954674,4.124028,0.325297,-414.251099,0.033553,0.000000
22.650002,18.953011,-414.251099,-0.003268,0.001302,0.033067,84.307205,4.294814,0.330671,-414.251099,0.033935,0.000000
22.880001,18.797363,-414.295593,-0.003294,0.001313,0.033345,83.614845,4.259543,0.333449,-414.295593,0.034324,0.000000
23.110001,19.274742,-414.384552,-0.003238,0.001334,0.033891,85.738335,4.367719,0.338915,-414.384552,0.034707,0.000000
23.340002,19.424065,-414.384552,-0.003234,0.001351,0.034324,86.402557,4.401556,0.343245,-414.384552,0.035088,0.000000
23.570002,19.341400,-414.384552,-0.003216,0.001365,0.034672,86.034843,4.382824,0.346719,-414.384552,0.035470,0.000000
23.800001,19.175316,-414.340057,-0.003195,0.001377,0.034966,85.296066,4.345189,0.349664,-414.340057,0.035851,0.000000
24.030001,19.144043,-414.340057,-0.003169,0.001387,0.035235,85.156960,4.338102,0.352351,-414.340057,0.036241,0.000000
24.260000,19.198776,-414.384552,-0.003165,0.001399,0.035539,85.400421,4.350505,0.355386,-414.384552,0.036623,0.000000
24.490002,19.732391,-414.429016,-0.003130,0.001420,0.036059,87.774063,4.471424,0.360595,-414.429016,0.037004,0.000000
24.720001,19.657166,-414.384552,-0.003130,0.001430,0.036328,87.439438,4.454377,0.363282,-414.384552,0.037386,0.000000
24.950001,19.609505,-414.384552,-0.003083,0.001442,0.036623,87.227432,4.443577,0.366226,-414.384552,0.037768,0.000000
25.180000,20.799980,-414.429016,-0.003070,0.001471,0.037360,92.522934,4.713343,0.373599,-414.429016,0.038158,0.000000
25.410002,20.800728,-414.473511,-0.003065,0.001486,0.037751,92.526260,4.713512,0.377505,-414.473511,0.038539,0.000000
25.640001,20.647682,-414.562469,-0.003053,0.001499,0.038080,91.845474,4.678832,0.380798,-414.562469,0.038921,0.000000
25.870001,20.422768,-414.473511,-0.003027,0.001511,0.038392,90.845009,4.627865,0.383917,-414.473511,0.039302,0.000000
26.100000,20.414574,-414.473511,-0.003018,0.001522,0.038670,90.808556,4.626009,0.386695,-414.473511,0.039685,0.000000
26.330002,20.507668,-414.562469,-0.002984,0.001537,0.039043,91.222664,4.647104,0.390427,-414.562469,0.040074,0.000000
26.560001,20.946320,-414.473511,-0.002962,0.001554,0.039476,93.173882,4.746504,0.394765,-414.473511,0.040456,0.000000
26.790001,20.683426,-414.606934,-0.002940,0.001563,0.039701,92.004471,4.686931,0.397013,-414.606934,0.040838,0.000000
27.020000,20.973503,-414.517975,-0.002979,0.001579,0.040100,93.294800,4.752664,0.401002,-414.517975,0.041219,0.000000
27.250002,22.227654,-414.562469,-0.002932,0.001608,0.040855,98.873543,5.036858,0.408549,-414.562469,0.041601,0.000000
27.480001,22.044075,-414.562469,-0.002880,0.001622,0.041202,98.056946,4.995259,0.412016,-414.562469,0.041991,0.000000
27.710001,21.709686,-414.562469,-0.002880,0.001633,0.041479,96.569511,4.919485,0.414794,-414.562469,0.042373,0.000000
27.940001,21.819534,-414.651428,-0.002859,0.001648,0.041861,97.058136,4.944377,0.418609,-414.651428,0.042754,0.000000
28.170002,21.806503,-414.606934,-0.002815,0.001661,0.042199,97.000168,4.941424,0.421993,-414.606934,0.043136,0.000000
28.400002,22.480125,-414.562469,-0.002837,0.001682,0.042719,99.996590,5.094069,0.427194,-414.562469,0.043517,0.000000
28.630001,22.012794,-414.562469,-0.002820,0.001688,0.042875,97.917801,4.988171,0.428753,-414.562469,0.043908,0.000000
28.860001,22.270103,-414.651428,-0.002768,0.001704,0.043283,99.062370,5.046478,0.432833,-414.651428,0.044289,0.000000
29.090002,23.213699,-414.740387,-0.002759,0.001729,0.043916,103.259689,5.260300,0.439161,-414.740387,0.044671,0.000000
29.320002,23.212952,-414.651428,-0.002721,0.001743,0.044263,103.256363,5.260130,0.442628,-414.651428,0.045052,0.000000
29.550001,22.557579,-414.651428,-0.002725,0.001749,0.044420,100.341125,5.111620,0.444195,-414.651428,0.045434,0.000000
29.780001,23.108315,-414.695892,-0.002695,0.001767,0.044870,102.790916,5.236419,0.448699,-414.695892,0.045824,0.000000
30.010002,23.111298,-414.740387,-0.002712,0.001780,0.045200,102.804184,5.237095,0.452000,-414.740387,0.046206,0.000000
30.240002,23.835564,-414.784882,-0.002669,0.001802,0.045763,106.025879,5.401216,0.457632,-414.784882,0.046588,0.000000
30.470001,23.700386,-414.784882,-0.002643,0.001814,0.046067,105.424583,5.370584,0.460667,-414.784882,0.046969,0.000000
30.700001,23.563354,-414.695892,-0.002617,0.001825,0.046362,104.815033,5.339532,0.463619,-414.695892,0.047359,0.000000
30.930002,24.209419,-414.740387,-0.002617,0.001847,0.046917,107.688873,5.485933,0.469168,-414.740387,0.047741,0.000000
31.160002,24.454819,-414.784882,-0.002596,0.001864,0.047333,108.780464,5.541541,0.473331,-414.784882,0.048123,0.000000
31.390001,24.242187,-414.784882,-0.002574,0.001875,0.047628,107.834633,5.493358,0.476284,-414.784882,0.048504,0.000000
31.620001,24.141647,-414.829346,-0.002557,0.001887,0.047932,107.387413,5.470576,0.479319,-414.829346,0.048886,0.000000
31.850002,24.558334,-414.784882,-0.002548,0.001904,0.048357,109.240929,5.564998,0.483566,-414.784882,0.049276,0.000000
32.080002,24.456306,-414.829346,-0.002527,0.001916,0.048660,108.787086,5.541878,0.486601,-414.829346,0.049657,0.000000
32.310001,24.741913,-414.829346,-0.002501,0.001932,0.049067,110.057526,5.606597,0.490674,-414.829346,0.050039,0.000000
32.540001,24.750854,-414.873840,-0.002501,0.001945,0.049415,110.097298,5.608624,0.494148,-414.873840,0.050421,0.000000
32.770000,25.238663,-414.873840,-0.002475,0.001963,0.049848,112.267181,5.719163,0.498478,-414.873840,0.050802,0.000000
33.000000,25.733917,-414.918304,-0.002427,0.001981,0.050316,114.470184,5.831389,0.503164,-414.918304,0.051192,0.000000
33.230003,25.777481,-414.829346,-0.002406,0.001997,0.050733,114.663963,5.841261,0.507327,-414.829346,0.051574,0.000000
33.460003,25.708221,-414.962799,-0.002384,0.002009,0.051036,114.355881,5.825566,0.510363,-414.962799,0.051955,0.000000
33.690002,25.545868,-414.918304,-0.002354,0.002022,0.051348,113.633698,5.788777,0.513482,-414.918304,0.052337,0.000000
33.920002,25.862755,-415.007263,-0.002363,0.002038,0.051774,115.043282,5.860584,0.517736,-415.007263,0.052718,0.000000
34.150002,26.209435,-414.962799,-0.002337,0.002057,0.052241,116.585388,5.939143,0.522414,-414.962799,0.053109,0.000000
34.380001,26.372536,-414.962799,-0.002341,0.002070,0.052571,117.310898,5.976102,0.525714,-414.962799,0.053490,0.000000
34.610001,25.712318,-415.051758,-0.002311,0.002075,0.052693,114.374107,5.826495,0.526926,-415.051758,0.053872,0.000000
34.840000,25.937973,-414.962799,-0.002311,0.002089,0.053066,115.377869,5.877628,0.530657,-414.962799,0.054253,0.000000
35.070004,27.137390,-415.007263,-0.002264,0.002118,0.053786,120.713142,6.149421,0.537856,-415.007263,0.054635,0.000000
35.300003,26.954178,-415.007263,-0.002212,0.002128,0.054045,119.898170,6.107904,0.540453,-415.007263,0.055026,0.000000
35.530003,27.169785,-415.051758,-0.002242,0.002146,0.054496,120.857239,6.156761,0.544964,-415.051758,0.055407,0.000000
35.760002,27.315010,-415.051758,-0.002199,0.002158,0.054826,121.503235,6.189670,0.548257,-415.051758,0.055789,0.000000
35.990002,27.423370,-415.096222,-0.002199,0.002174,0.055225,121.985245,6.214225,0.552246,-415.096222,0.056170,0.000000
36.220001,27.174622,-415.096222,-0.002169,0.002184,0.055485,120.878754,6.157857,0.554850,-415.096222,0.056552,0.000000
36.450001,27.257660,-415.051758,-0.002156,0.002199,0.055849,121.248123,6.176674,0.558492,-415.051758,0.056942,0.000000
36.680000,27.071480,-415.051758,-0.002151,0.002210,0.056127,120.419960,6.134485,0.561270,-415.051758,0.057324,0.000000
36.910000,27.172386,-415.140717,-0.002126,0.002227,0.056578,120.868813,6.157351,0.565781,-415.140717,0.057705,0.000000
37.140003,28.469734,-415.096222,-0.002078,0.002251,0.057168,126.639702,6.451334,0.571678,-415.096222,0.058087,0.000000
37.370003,28.040390,-415.185211,-0.002095,0.002260,0.057410,124.729881,6.354043,0.574100,-415.185211,0.058468,0.000000
37.600002,28.468994,-415.140717,-0.002039,0.002279,0.057896,126.636414,6.451166,0.578960,-415.140717,0.058859,0.000000
37.830002,28.886421,-415.185211,-0.002035,0.002299,0.058382,128.493225,6.545756,0.583820,-415.185211,0.059240,0.000000
38.060001,28.753487,-415.185211,-0.001983,0.002312,0.058720,127.901894,6.515633,0.587196,-415.185211,0.059622,0.000000
38.290001,28.545700,-415.185211,-0.002001,0.002324,0.059023,126.977615,6.468548,0.590232,-415.185211,0.060003,0.000000
38.520000,28.130501,-415.274170,-0.001983,0.002334,0.059292,125.130714,6.374463,0.592919,-415.274170,0.060385,0.000000
38.750000,29.313530,-415.274170,-0.001927,0.002361,0.059969,130.393097,6.642541,0.599686,-415.274170,0.060775,0.000000
38.980003,29.509773,-415.229675,-0.001940,0.002377,0.060368,131.266022,6.687010,0.603676,-415.229675,0.061157,0.000000
39.210003,29.032387,-415.229675,-0.001880,0.002386,0.060611,129.142502,6.578833,0.606106,-415.229675,0.061539,0.000000
39.440002,29.216713,-415.229675,-0.001880,0.002402,0.061009,129.962433,6.620602,0.610095,-415.229675,0.061920,0.000000
39.670002,29.433060,-415.363129,-0.001858,0.002419,0.061452,130.924789,6.669626,0.614516,-415.363129,0.062310,0.000000
39.900002,29.541420,-415.274170,-0.001832,0.002434,0.061816,131.406799,6.694181,0.618157,-415.274170,0.062691,0.000000
40.130001,29.272568,-415.318634,-0.001824,0.002444,0.062076,130.210892,6.633259,0.620761,-415.318634,0.063073,0.000000
40.360001,28.873016,-415.274170,-0.001798,0.002453,0.062302,128.433594,6.542719,0.623016,-415.274170,0.063455,0.000000
40.590000,29.389122,-415.318634,-0.001776,0.002471,0.062769,130.729340,6.659670,0.627695,-415.318634,0.063837,0.000000
40.820004,30.485016,-415.363129,-0.001763,0.002497,0.063420,135.604126,6.908003,0.634205,-415.363129,0.064227,0.000000
41.050003,30.294731,-415.363129,-0.001716,0.002511,0.063775,134.757690,6.864884,0.637755,-415.363129,0.064608,0.000000
41.280003,29.958481,-415.407593,-0.001703,0.002521,0.064036,133.261978,6.788689,0.640359,-415.407593,0.064990,0.000000
41.510002,29.811020,-415.363129,-0.001681,0.002534,0.064374,132.606033,6.755273,0.643743,-415.363129,0.065371,0.000000
41.740002,30.125305,-415.407593,-0.001660,0.002552,0.064825,134.004044,6.826492,0.648254,-415.407593,0.065753,0.000000
41.970001,30.201637,-415.407593,-0.001617,0.002566,0.065180,134.343597,6.843789,0.651804,-415.407593,0.066143,0.000000
42.200001,29.835968,-415.452087,-0.001634,0.002576,0.065441,132.717010,6.760927,0.654408,-415.452087,0.066525,0.000000
42.430000,30.079498,-415.496552,-0.001582,0.002593,0.065865,133.800293,6.816112,0.658655,-415.496552,0.066906,0.000000
42.660004,30.633217,-415.452087,-0.001578,0.002613,0.066360,136.263351,6.941586,0.663598,-415.452087,0.067288,0.000000
42.890003,31.204811,-415.363129,-0.001526,0.002633,0.066881,138.805939,7.071112,0.668806,-415.363129,0.067669,0.000000
43.120003,30.739716,-415.496552,-0.001535,0.002643,0.067124,136.737091,6.965719,0.671236,-415.496552,0.068060,0.000000
43.350002,30.337555,-415.496552,-0.001483,0.002656,0.067461,134.948181,6.874588,0.674612,-415.496552,0.068441,0.000000
43.580002,30.219513,-415.496552,-0.001487,0.002670,0.067817,134.423111,6.847839,0.678170,-415.496552,0.068823,0.000000
43.810001,30.286537,-415.496552,-0.001440,0.002685,0.068190,134.721252,6.863028,0.681902,-415.496552,0.069205,0.000000
44.040001,30.938934,-415.496552,-0.001436,0.002703,0.068658,137.623260,7.010863,0.686580,-415.496552,0.069586,0.000000
44.270000,30.429161,-415.585541,-0.001436,0.002712,0.068884,135.355667,6.895347,0.688836,-415.585541,0.069977,0.000000
44.500004,31.461006,-415.541046,-0.001358,0.002739,0.069560,139.945541,7.129166,0.695603,-415.541046,0.070358,0.000000
44.730003,31.506432,-415.585541,-0.001350,0.002754,0.069950,140.147614,7.139459,0.699502,-415.585541,0.070740,0.000000
44.960003,31.305351,-415.541046,-0.001337,0.002768,0.070306,139.253159,7.093894,0.703059,-415.541046,0.071121,0.000000
45.190002,30.849197,-415.541046,-0.001302,0.002780,0.070618,137.224091,6.990528,0.706178,-415.541046,0.071503,0.000000
45.420002,30.585182,-415.585541,-0.001328,0.002792,0.070905,136.049683,6.930701,0.709047,-415.585541,0.071893,0.000000
45.650002,30.481293,-415.630005,-0.001276,0.002810,0.071373,135.587555,6.907160,0.713725,-415.630005,0.072275,0.000000
45.880001,30.882339,-415.630005,-0.001250,0.002823,0.071703,137.371506,6.998038,0.717026,-415.630005,0.072656,0.000000
46.110001,30.426926,-415.585541,-0.001224,0.002832,0.071945,135.345718,6.894840,0.719448,-415.585541,0.073038,0.000000
46.340004,30.816429,-415.630005,-0.001203,0.002851,0.072405,137.078323,6.983103,0.724050,-415.630005,0.073419,0.000000
46.570004,31.853859,-415.674500,-0.001199,0.002874,0.073003,141.693039,7.218188,0.730031,-415.674500,0.073809,0.000000
46.800003,31.803215,-415.718964,-0.001147,0.002890,0.073394,141.467773,7.206712,0.733937,-415.718964,0.074192,0.000000
47.030003,31.240929,-415.674500,-0.001112,0.002898,0.073610,138.966599,7.079296,0.736102,-415.674500,0.074573,0.000000
47.260002,31.179489,-415.630005,-0.001104,0.002915,0.074052,138.693298,7.065373,0.740522,-415.630005,0.074955,0.000000
47.490002,30.608643,-415.718964,-0.001121,0.002922,0.074226,136.154037,6.936018,0.742256,-415.718964,0.075336,0.000000
47.720001,31.491913,-415.718964,-0.001065,0.002946,0.074824,140.083023,7.136169,0.748243,-415.718964,0.075726,0.000000
47.950001,31.065918,-415.807922,-0.001030,0.002955,0.075067,138.188110,7.039638,0.750673,-415.807922,0.076107,0.000000
48.180004,30.480919,-415.718964,-0.001035,0.002962,0.075232,135.585892,6.907075,0.752316,-415.718964,0.076489,0.000000
48.410004,31.789810,-415.763458,-0.001000,0.002992,0.075995,141.408142,7.203674,0.759946,-415.763458,0.076871,0.000000
48.640003,32.475349,-415.763458,-0.000970,0.003011,0.076489,144.457565,7.359019,0.764889,-415.763458,0.077261,0.000000
48.870003,32.237770,-415.763458,-0.000940,0.003025,0.076836,143.400757,7.305183,0.768364,-415.763458,0.077643,0.000000
49.100002,31.550003,-415.896881,-0.000940,0.003035,0.077096,140.341415,7.149333,0.770960,-415.896881,0.078024,0.000000
49.330002,31.491165,-415.852417,-0.000914,0.003047,0.077382,140.079697,7.136000,0.773822,-415.852417,0.078406,0.000000
49.560001,31.981583,-415.896881,-0.000892,0.003068,0.077938,142.261185,7.247130,0.779378,-415.896881,0.078787,0.000000
49.790001,32.247452,-415.852417,-0.000854,0.003082,0.078293,143.443832,7.307377,0.782928,-415.852417,0.079178,0.000000
50.020004,31.538086,-415.896881,-0.000845,0.003089,0.078467,140.288406,7.146633,0.784669,-415.896881,0.079559,0.000000
50.250004,31.827415,-415.985840,-0.000824,0.003106,0.078892,141.575409,7.212195,0.788916,-415.985840,0.079941,0.000000
50.480003,33.129974,-415.896881,-0.000785,0.003133,0.079568,147.369492,7.507360,0.795683,-415.896881,0.080322,0.000000
50.710003,32.844368,-415.941376,-0.000811,0.003143,0.079828,146.099045,7.442640,0.798280,-415.941376,0.080704,0.000000
50.940002,32.454491,-415.896881,-0.000767,0.003155,0.080141,144.364792,7.354293,0.801406,-415.896881,0.081094,0.000000
51.170002,32.566948,-415.896881,-0.000724,0.003169,0.080496,144.865021,7.379776,0.804956,-415.896881,0.081476,0.000000
51.400002,32.597115,-416.030334,-0.000720,0.003180,0.080764,144.999207,7.386611,0.807644,-416.030334,0.081857,0.000000
51.630001,33.724655,-416.030334,-0.000711,0.003204,0.081389,150.014755,7.642116,0.813889,-416.030334,0.082239,0.000000
51.860001,33.566772,-415.985840,-0.000677,0.003215,0.081667,149.312454,7.606339,0.816667,-415.985840,0.082620,0.000000
52.090004,33.758911,-416.030334,-0.000668,0.003231,0.082066,150.167130,7.649879,0.820656,-416.030334,0.083011,0.000000
52.320004,34.731926,-416.030334,-0.000651,0.003252,0.082595,154.495316,7.870367,0.825947,-416.030334,0.083393,0.000000
52.550003,34.800812,-416.074829,-0.000634,0.003265,0.082941,154.801743,7.885977,0.829414,-416.074829,0.083774,0.000000
52.780003,34.966515,-416.030334,-0.000604,0.003279,0.083288,155.538818,7.923525,0.832881,-416.030334,0.084156,0.000000
53.010002,34.925560,-416.074829,-0.000604,0.003291,0.083583,155.356644,7.914245,0.835833,-416.074829,0.084537,0.000000
53.240002,35.391769,-415.985840,-0.000599,0.003307,0.084008,157.430450,8.019890,0.840080,-415.985840,0.084928,0.000000
53.470001,36.126457,-416.074829,-0.000573,0.003324,0.084433,160.698502,8.186372,0.844334,-416.074829,0.085309,0.000000
53.700001,36.106720,-416.074829,-0.000552,0.003334,0.084676,160.610718,8.181900,0.846757,-416.074829,0.085691,0.000000
53.930004,36.329399,-416.119293,-0.000526,0.003346,0.084988,161.601242,8.232360,0.849883,-416.119293,0.086072,0.000000
54.160004,37.180641,-416.074829,-0.000517,0.003366,0.085508,165.387756,8.425254,0.855083,-416.074829,0.086454,0.000000
54.390003,37.965981,-416.074829,-0.000500,0.003386,0.085994,168.881119,8.603214,0.859943,-416.074829,0.086844,0.000000
54.620003,38.598640,-416.119293,-0.000483,0.003401,0.086384,171.695328,8.746576,0.863842,-416.119293,0.087226,0.000000
54.850002,38.834351,-416.163788,-0.000474,0.003414,0.086705,172.743820,8.799990,0.867051,-416.163788,0.087607,0.000000
55.080002,38.825417,-416.119293,-0.000453,0.003424,0.086966,172.704071,8.797965,0.869655,-416.119293,0.087989,0.000000
55.310001,39.334076,-416.119293,-0.000461,0.003443,0.087442,174.966705,8.913229,0.874424,-416.119293,0.088370,0.000000
55.540001,40.333893,-416.208252,-0.000423,0.003456,0.087789,179.414108,9.139791,0.877891,-416.208252,0.088760,0.000000
55.770004,40.740524,-416.208252,-0.000410,0.003470,0.088145,181.222900,9.231935,0.881449,-416.208252,0.089142,0.000000
56.000004,40.383789,-416.252747,-0.000423,0.003478,0.088344,179.636063,9.151097,0.883440,-416.252747,0.089523,0.000000
56.230003,40.974373,-416.297211,-0.000388,0.003491,0.088665,182.263107,9.284925,0.886649,-416.297211,0.089906,0.000000
56.460003,42.998222,-416.297211,-0.000375,0.003519,0.089377,191.265640,9.743537,0.893765,-416.297211,0.090295,0.000000
56.690002,43.028008,-416.297211,-0.000401,0.003529,0.089645,191.398132,9.750286,0.896452,-416.297211,0.090677,0.000000
56.920002,43.904572,-416.208252,-0.000336,0.003547,0.090087,195.297287,9.948918,0.900873,-416.208252,0.091059,0.000000
57.150002,44.288490,-416.386169,-0.000366,0.003560,0.090434,197.005051,10.035915,0.904340,-416.386169,0.091440,0.000000
57.380001,45.143829,-416.386169,-0.000323,0.003578,0.090877,200.809784,10.229737,0.908768,-416.386169,0.091822,0.000000
57.610004,45.857292,-416.341705,-0.000306,0.003593,0.091258,203.983429,10.391411,0.912584,-416.341705,0.092212,0.000000
57.840004,45.737762,-416.297211,-0.000315,0.003597,0.091371,203.451721,10.364326,0.913711,-416.297211,0.092594,0.000000
58.070004,46.332069,-416.386169,-0.000310,0.003615,0.091813,206.095337,10.498997,0.918132,-416.386169,0.092975,0.000000
58.300003,48.112755,-416.386169,-0.000280,0.003639,0.092429,214.016220,10.902506,0.924286,-416.386169,0.093357,0.000000
58.530003,48.577103,-416.430664,-0.000272,0.003650,0.092715,216.081741,11.007729,0.927148,-416.430664,0.093738,0.000000
58.760002,48.785629,-416.430664,-0.000259,0.003661,0.093001,217.009323,11.054982,0.930009,-416.430664,0.094129,0.000000
58.990002,49.986908,-416.430664,-0.000250,0.003683,0.093557,222.352875,11.327195,0.935565,-416.430664,0.094510,0.000000
59.220001,51.394470,-416.386169,-0.000233,0.003704,0.094077,228.614029,11.646153,0.940766,-416.386169,0.094892,0.000000
59.450005,51.820839,-416.430664,-0.000211,0.003715,0.094363,230.510605,11.742769,0.943627,-416.430664,0.095273,0.000000
59.680004,52.067352,-416.475159,-0.000229,0.003725,0.094623,231.607147,11.798631,0.946231,-416.475159,0.095655,0.000000
59.910004,52.623306,-416.519623,-0.000203,0.003740,0.094987,234.080154,11.924612,0.949872,-416.519623,0.096045,0.000000
60.140003,54.578255,-416.519623,-0.000211,0.003766,0.095664,242.776199,12.367609,0.956640,-416.519623,0.096427,0.000000
60.370003,55.092133,-416.475159,-0.000198,0.003778,0.095950,245.062042,12.484056,0.959501,-416.475159,0.096809,0.000000
60.600002,55.273102,-416.519623,-0.000168,0.003787,0.096192,245.867035,12.525064,0.961923,-416.519623,0.097190,0.000000
60.830002,56.023811,-416.564117,-0.000190,0.003802,0.096583,249.206360,12.695177,0.965829,-416.564117,0.097572,0.000000
61.060001,57.371796,-416.564117,-0.000177,0.003823,0.097103,255.202499,13.000634,0.971030,-416.564117,0.097962,0.000000
61.290005,58.085258,-416.475159,-0.000147,0.003836,0.097424,258.376129,13.162308,0.974240,-416.475159,0.098344,0.000000
61.520004,58.306824,-416.519623,-0.000147,0.003846,0.097693,259.361694,13.212516,0.976927,-416.519623,0.098725,0.000000
61.750004,58.764473,-416.564117,-0.000138,0.003854,0.097901,261.397430,13.316220,0.979008,-416.564117,0.099107,0.000000
61.980003,59.967232,-416.564117,-0.000125,0.003876,0.098447,266.747559,13.588769,0.984474,-416.564117,0.099488,0.000000
62.210003,62.042091,-416.653076,-0.000147,0.003899,0.099037,275.977020,14.058939,0.990371,-416.653076,0.099878,0.000000
62.440002,62.884026,-416.653076,-0.000091,0.003913,0.099384,279.722107,14.249724,0.993838,-416.653076,0.100260,0.000000
62.670002,63.284698,-416.608582,-0.000108,0.003924,0.099670,281.504395,14.340517,0.996699,-416.608582,0.100642,0.000000
62.900002,63.919968,-416.564117,-0.000078,0.003936,0.099973,284.330231,14.484472,0.999735,-416.564117,0.101023,0.000000
63.130005,65.064636,-416.608582,-0.000091,0.003954,0.100434,289.421967,14.743857,1.004337,-416.608582,0.101405,0.000000
63.360004,65.982910,-416.742035,-0.000065,0.003966,0.100746,293.506653,14.951941,1.007456,-416.742035,0.101795,0.000000
63.590004,66.623016,-416.653076,-0.000065,0.003980,0.101084,296.353973,15.096992,1.010839,-416.653076,0.102176,0.000000
63.820004,67.424728,-416.697540,-0.000043,0.003981,0.101119,299.920166,15.278662,1.011188,-416.697540,0.101387,0.000000
64.050003,66.769363,-416.742035,-0.000069,0.003981,0.101119,297.004974,15.130154,1.011188,-416.742035,0.101387,0.000000
64.280006,66.177292,-416.742035,-0.000030,0.003980,0.101084,294.371307,14.995989,1.010839,-416.742035,0.101119,0.000000
64.510002,65.669006,-416.742035,-0.000026,0.003979,0.101067,292.110321,14.880810,1.010665,-416.742035,0.101119,0.000000
64.740005,65.208374,-416.742035,-0.000022,0.003979,0.101057,290.061340,14.776429,1.010575,-416.742035,0.101119,0.000000
64.970001,64.800995,-416.697540,-0.000047,0.003978,0.101049,288.249207,14.684115,1.010491,-416.697540,0.101119,0.000000
65.200005,64.424896,-416.742035,-0.000026,0.003978,0.101049,286.576263,14.598890,1.010491,-416.742035,0.101119,0.000000
65.430000,64.089020,-416.786499,-0.000034,0.003978,0.101049,285.082184,14.522779,1.010491,-416.786499,0.101119,0.000000
65.660004,63.782196,-416.830994,-0.000039,0.003978,0.101049,283.717377,14.453252,1.010491,-416.830994,0.101119,0.000000
65.889999,63.493225,-416.786499,-0.000017,0.003978,0.101049,282.431976,14.387771,1.010491,-416.786499,0.101119,0.000000
66.120003,63.227356,-416.742035,-0.000034,0.003978,0.101041,281.249329,14.327523,1.010408,-416.742035,0.101119,0.000000
66.350006,62.997231,-416.786499,-0.000022,0.003978,0.101041,280.225677,14.275377,1.010408,-416.786499,0.101119,0.000000
66.580002,62.763008,-416.830994,-0.000030,0.003978,0.101041,279.183807,14.222301,1.010408,-416.830994,0.101119,0.000000
66.810005,62.559692,-416.875488,-0.000047,0.003978,0.101041,278.279419,14.176229,1.010408,-416.875488,0.101119,0.000000
67.040001,62.369034,-416.830994,-0.000009,0.003978,0.101041,277.431305,14.133025,1.010408,-416.830994,0.101119,0.000000
67.270004,62.173538,-416.875488,-0.000017,0.003978,0.101041,276.561707,14.088725,1.010408,-416.875488,0.101119,0.000000
67.500000,62.010811,-416.875488,-0.000004,0.003978,0.101041,275.837860,14.051851,1.010408,-416.875488,0.101119,0.000000
67.730003,61.853668,-417.008911,-0.000017,0.003978,0.101041,275.138855,14.016242,1.010408,-417.008911,0.101119,0.000000
67.960007,61.685730,-416.919952,-0.000030,0.003978,0.101041,274.391846,13.978186,1.010408,-416.919952,0.101119,0.000000
68.190002,61.524498,-417.008911,-0.000039,0.003978,0.101041,273.674622,13.941650,1.010408,-417.008911,0.101119,0.000000
68.420006,61.409431,-416.964447,-0.000013,0.003978,0.101041,273.162781,13.915576,1.010408,-416.964447,0.101119,0.000000
68.650002,61.270538,-416.964447,0.000000,0.003978,0.101041,272.544952,13.884103,1.010408,-416.964447,0.101119,0.000000
68.880005,61.142441,-416.964447,0.000000,0.003978,0.101041,271.975159,13.855076,1.010408,-416.964447,0.101119,0.000000
69.110001,61.018440,-417.008911,0.000004,0.003978,0.101041,271.423584,13.826976,1.010408,-417.008911,0.101119,0.000000
69.340004,60.911568,-416.964447,-0.000013,0.003978,0.101041,270.948181,13.802758,1.010408,-416.964447,0.101119,0.000000
69.570000,60.800606,-417.008911,0.000004,0.003978,0.101041,270.454590,13.777614,1.010408,-417.008911,0.101119,0.000000
69.800003,60.680695,-417.008911,0.000004,0.003978,0.101041,269.921204,13.750443,1.010408,-417.008911,0.101119,0.000000
70.030006,60.588348,-417.008911,0.000009,0.003978,0.101041,269.510437,13.729516,1.010408,-417.008911,0.101119,0.000000
70.260002,60.498978,-417.053406,-0.000034,0.003978,0.101041,269.112885,13.709265,1.010408,-417.053406,0.101119,0.000000
70.490005,60.393600,-417.053406,0.000004,0.003978,0.101041,268.644165,13.685386,1.010408,-417.053406,0.101119,0.000000
70.720001,60.301994,-417.053406,-0.000026,0.003978,0.101041,268.236664,13.664628,1.010408,-417.053406,0.101119,0.000000
70.950005,60.219330,-417.097870,0.000004,0.003978,0.101041,267.868958,13.645895,1.010408,-417.097870,0.101119,0.000000
71.180000,60.145973,-417.053406,0.000004,0.003978,0.101041,267.542664,13.629272,1.010408,-417.053406,0.101119,0.000000
71.410004,60.055115,-417.142365,0.000009,0.003978,0.101041,267.138489,13.608684,1.010408,-417.142365,0.101119,0.000000
71.640007,59.982498,-417.186829,0.000017,0.003978,0.101041,266.815491,13.592228,1.010408,-417.186829,0.101119,0.000000
71.870003,59.913612,-417.097870,-0.000017,0.003978,0.101041,266.509064,13.576619,1.010408,-417.097870,0.101119,0.000000
72.100006,59.835785,-417.142365,0.000013,0.003978,0.101041,266.162872,13.558983,1.010408,-417.142365,0.101119,0.000000
72.330002,59.751999,-417.142365,0.000009,0.003978,0.101041,265.790161,13.539996,1.010408,-417.142365,0.101119,0.000000
72.560005,59.690559,-417.186829,0.000009,0.003978,0.101041,265.516876,13.526073,1.010408,-417.186829,0.101119,0.000000
72.790001,59.640663,-417.186829,0.000034,0.003978,0.101041,265.294922,13.514768,1.010408,-417.186829,0.101119,0.000000
73.020004,59.559486,-417.231323,0.000013,0.003978,0.101041,264.933838,13.496373,1.010408,-417.231323,0.101119,0.000000
73.250000,59.488731,-417.186829,0.000022,0.003978,0.101041,264.619080,13.480340,1.010408,-417.186829,0.101119,0.000000
73.480003,59.429153,-417.231323,0.000000,0.003978,0.101041,264.354065,13.466839,1.010408,-417.231323,0.101119,0.000000
73.710007,59.381866,-417.231323,0.000000,0.003978,0.101041,264.143738,13.456123,1.010408,-417.231323,0.101119,0.000000
73.940002,59.311859,-417.275787,-0.000004,0.003978,0.101041,263.832336,13.440259,1.010408,-417.275787,0.101119,0.000000
74.170006,59.257492,-417.320282,-0.000013,0.003978,0.101041,263.590485,13.427939,1.010408,-417.320282,0.101119,0.000000
74.400002,59.199776,-417.275787,0.000009,0.003978,0.101041,263.333740,13.414861,1.010408,-417.275787,0.101119,0.000000
74.630005,59.154343,-417.275787,0.000017,0.003978,0.101041,263.131653,13.404566,1.010408,-417.275787,0.101119,0.000000
74.860001,59.089554,-417.364777,0.000043,0.003978,0.101041,262.843475,13.389884,1.010408,-417.364777,0.101119,0.000000
75.090004,59.030716,-417.364777,0.000009,0.003978,0.101041,262.581726,13.376552,1.010408,-417.364777,0.101119,0.000000
75.320007,58.990501,-417.320282,0.000009,0.003978,0.101041,262.402863,13.367438,1.010408,-417.320282,0.101119,0.000000
75.550003,58.939484,-417.364777,0.000022,0.003978,0.101041,262.175903,13.355878,1.010408,-417.364777,0.101119,0.000000
75.780006,58.888466,-417.364777,0.000017,0.003978,0.101041,261.948975,13.344316,1.010408,-417.364777,0.101119,0.000000
76.010002,58.844902,-417.409241,0.000022,0.003978,0.101041,261.755188,13.334446,1.010408,-417.409241,0.101119,0.000000
76.240005,58.803200,-417.453735,0.000030,0.003978,0.101041,261.569702,13.324995,1.010408,-417.453735,0.101119,0.000000
76.470001,58.742500,-417.409241,0.000004,0.003978,0.101041,261.299683,13.311240,1.010408,-417.409241,0.101119,0.000000
76.700005,58.709732,-417.409241,0.000000,0.003978,0.101041,261.153931,13.303815,1.010408,-417.409241,0.101119,0.000000
76.930000,58.670631,-417.409241,0.000009,0.003978,0.101041,260.980011,13.294954,1.010408,-417.409241,0.101119,0.000000
77.160004,58.616638,-417.453735,0.000022,0.003978,0.101041,260.739838,13.282720,1.010408,-417.453735,0.101119,0.000000
77.390007,58.572327,-417.409241,-0.000026,0.003978,0.101041,260.542725,13.272679,1.010408,-417.409241,0.101119,0.000000
77.620003,58.551102,-417.498199,0.000004,0.003978,0.101041,260.448303,13.267869,1.010408,-417.498199,0.101119,0.000000
77.850006,58.504929,-417.453735,0.000013,0.003978,0.101041,260.242920,13.257406,1.010408,-417.453735,0.101119,0.000000
78.080002,58.462845,-417.498199,0.000004,0.003978,0.101041,260.055725,13.247869,1.010408,-417.498199,0.101119,0.000000
78.310005,58.429337,-417.542694,0.000013,0.003978,0.101041,259.906677,13.240277,1.010408,-417.542694,0.101119,0.000000
78.540001,58.378319,-417.498199,0.000043,0.003978,0.101041,259.679718,13.228716,1.010408,-417.498199,0.101119,0.000000
78.770004,58.343689,-417.542694,0.000000,0.003978,0.101041,259.525696,13.220868,1.010408,-417.542694,0.101119,0.000000
79.000000,58.313156,-417.542694,0.000009,0.003978,0.101041,259.389862,13.213950,1.010408,-417.542694,0.101119,0.000000
79.230003,58.275169,-417.587158,0.000026,0.003978,0.101041,259.220886,13.205341,1.010408,-417.587158,0.101119,0.000000
79.460007,58.239426,-417.587158,0.000052,0.003978,0.101041,259.061890,13.197243,1.010408,-417.587158,0.101119,0.000000
79.690002,58.200325,-417.587158,0.000022,0.003978,0.101041,258.887970,13.188382,1.010408,-417.587158,0.101119,0.000000
79.920006,58.155640,-417.631653,0.000017,0.003978,0.101041,258.689209,13.178256,1.010408,-417.631653,0.101119,0.000000
80.150002,58.135902,-417.631653,0.000004,0.003978,0.101041,258.601410,13.173783,1.010408,-417.631653,0.101119,0.000000
80.380005,58.108353,-417.587158,0.000026,0.003978,0.101041,258.478851,13.167541,1.010408,-417.587158,0.101119,0.000000
80.610001,58.065155,-417.676117,0.000000,0.003978,0.101041,258.286713,13.157753,1.010408,-417.676117,0.101119,0.000000
80.840004,58.036110,-417.676117,0.000030,0.003978,0.101041,258.157501,13.151171,1.010408,-417.676117,0.101119,0.000000
81.070007,57.992172,-417.720612,0.000030,0.003978,0.101041,257.962067,13.141214,1.010408,-417.720612,0.101119,0.000000
81.300003,57.971687,-417.720612,0.000030,0.003978,0.101041,257.870941,13.136572,1.010408,-417.720612,0.101119,0.000000
81.530006,57.945625,-417.631653,0.000009,0.003978,0.101041,257.755005,13.130666,1.010408,-417.631653,0.101119,0.000000
81.760002,57.901680,-417.720612,0.000043,0.003978,0.101041,257.559540,13.120708,1.010408,-417.720612,0.101119,0.000000
81.990005,57.877106,-417.765106,0.000022,0.003978,0.101041,257.450226,13.115140,1.010408,-417.765106,0.101119,0.000000
82.220001,57.845451,-417.720612,0.000009,0.003978,0.101041,257.309418,13.107966,1.010408,-417.720612,0.101119,0.000000
82.450005,57.807472,-417.765106,0.000004,0.003978,0.101041,257.140472,13.099360,1.010408,-417.765106,0.101119,0.000000
82.680000,57.780289,-417.765106,0.000030,0.003978,0.101041,257.019562,13.093201,1.010408,-417.765106,0.101119,0.000000
82.910004,57.758690,-417.765106,0.000022,0.003978,0.101041,256.923492,13.088306,1.010408,-417.765106,0.101119,0.000000
83.140007,57.736351,-417.809570,0.000022,0.003978,0.101041,256.824127,13.083244,1.010408,-417.809570,0.101119,0.000000
83.370003,57.712517,-417.809570,0.000017,0.003978,0.101041,256.718109,13.077844,1.010408,-417.809570,0.101119,0.000000
83.600006,57.678635,-417.809570,0.000026,0.003978,0.101041,256.567383,13.070165,1.010408,-417.809570,0.101119,0.000000
83.830002,57.646606,-417.809570,0.000039,0.003978,0.101041,256.424927,13.062908,1.010408,-417.809570,0.101119,0.000000
84.060005,57.630592,-417.809570,0.000030,0.003978,0.101041,256.353668,13.059279,1.010408,-417.809570,0.101119,0.000000
84.290001,57.601181,-417.898529,0.000039,0.003978,0.101041,256.222839,13.052614,1.010408,-417.898529,0.101119,0.000000
84.520004,57.574738,-417.898529,0.000022,0.003978,0.101041,256.105225,13.046622,1.010408,-417.898529,0.101119,0.000000
84.750008,57.554260,-417.898529,0.000009,0.003978,0.101041,256.014130,13.041982,1.010408,-417.898529,0.101119,0.000000
84.980003,57.527077,-417.765106,0.000030,0.003978,0.101041,255.893219,13.035822,1.010408,-417.765106,0.101119,0.000000
85.210007,57.510323,-417.898529,0.000030,0.003978,0.101041,255.818695,13.032025,1.010408,-417.898529,0.101119,0.000000
85.440002,57.473457,-417.943024,0.000039,0.003978,0.101041,255.654709,13.023672,1.010408,-417.943024,0.101119,0.000000
85.670006,57.462654,-417.987488,0.000022,0.003978,0.101041,255.606659,13.021223,1.010408,-417.987488,0.101119,0.000000
85.900002,57.432121,-417.943024,0.000022,0.003978,0.101041,255.470840,13.014305,1.010408,-417.943024,0.101119,0.000000
86.130005,57.417595,-417.943024,0.000022,0.003978,0.101041,255.406219,13.011013,1.010408,-417.943024,0.101119,0.000000
86.360001,57.396004,-417.987488,0.000030,0.003978,0.101041,255.310181,13.006121,1.010408,-417.987488,0.101119,0.000000
86.590004,57.368073,-417.987488,0.000026,0.003978,0.101041,255.185928,12.999791,1.010408,-417.987488,0.101119,0.000000
86.820007,57.339775,-418.031982,0.000013,0.003978,0.101041,255.060059,12.993379,1.010408,-418.031982,0.101119,0.000000
87.050003,57.330460,-418.031982,0.000026,0.003978,0.101041,255.018616,12.991268,1.010408,-418.031982,0.101119,0.000000
87.280006,57.311096,-417.943024,0.000034,0.003978,0.101041,254.932495,12.986879,1.010408,-417.943024,0.101119,0.000000
87.510002,57.288383,-417.987488,0.000030,0.003978,0.101041,254.831451,12.981733,1.010408,-417.987488,0.101119,0.000000
87.740005,57.260460,-418.031982,0.000043,0.003978,0.101041,254.707245,12.975406,1.010408,-418.031982,0.101119,0.000000
87.970001,57.255615,-418.076447,0.000009,0.003978,0.101041,254.685699,12.974308,1.010408,-418.076447,0.101119,0.000000
88.200005,57.235878,-418.076447,0.000004,0.003978,0.101041,254.597900,12.969835,1.010408,-418.076447,0.101119,0.000000
88.430008,57.197525,-418.031982,0.000022,0.003978,0.101041,254.427292,12.961144,1.010408,-418.031982,0.101119,0.000000
88.660004,57.183746,-418.076447,0.000026,0.003978,0.101041,254.366013,12.958022,1.010408,-418.076447,0.101119,0.000000
88.890007,57.171829,-418.165436,0.000034,0.003978,0.101041,254.313004,12.955321,1.010408,-418.165436,0.101119,0.000000
89.120003,57.135712,-418.165436,0.000026,0.003978,0.101041,254.152344,12.947137,1.010408,-418.165436,0.101119,0.000000
89.350006,57.126404,-418.120941,0.000017,0.003978,0.101041,254.110931,12.945028,1.010408,-418.120941,0.101119,0.000000
89.580002,57.105179,-418.120941,0.000030,0.003978,0.101041,254.016525,12.940218,1.010408,-418.120941,0.101119,0.000000
89.810005,57.088791,-418.165436,0.000039,0.003978,0.101041,253.943619,12.936504,1.010408,-418.165436,0.101119,0.000000
90.040001,57.077248,-418.209900,0.000034,0.003978,0.101041,253.892273,12.933889,1.010408,-418.209900,0.101119,0.000000
90.270004,57.048576,-418.254395,0.000030,0.003978,0.101041,253.764740,12.927393,1.010408,-418.254395,0.101119,0.000000
90.500008,57.028099,-418.254395,0.000034,0.003978,0.101041,253.673660,12.922751,1.010408,-418.254395,0.101119,0.000000
90.730003,57.020279,-418.209900,0.000047,0.003978,0.101041,253.638870,12.920979,1.010408,-418.209900,0.101119,0.000000
90.960007,56.997559,-418.209900,0.000026,0.003978,0.101041,253.537796,12.915832,1.010408,-418.209900,0.101119,0.000000
91.190002,56.985275,-418.254395,0.000030,0.003978,0.101041,253.483170,12.913048,1.010408,-418.254395,0.101119,0.000000
91.420006,56.970383,-418.298859,0.000026,0.003978,0.101041,253.416916,12.909673,1.010408,-418.298859,0.101119,0.000000
91.650002,56.949524,-418.298859,0.000022,0.003978,0.101041,253.324127,12.904946,1.010408,-418.298859,0.101119,0.000000
91.880005,56.939842,-418.254395,0.000009,0.003978,0.101041,253.281067,12.902753,1.010408,-418.254395,0.101119,0.000000
92.110001,56.915268,-418.343353,0.000052,0.003978,0.101041,253.171753,12.897184,1.010408,-418.343353,0.101119,0.000000
92.340004,56.897766,-418.298859,0.000009,0.003978,0.101041,253.093903,12.893218,1.010408,-418.298859,0.101119,0.000000
92.570007,56.886223,-418.343353,0.000047,0.003978,0.101041,253.042557,12.890602,1.010408,-418.343353,0.101119,0.000000
92.800003,56.866859,-418.343353,0.000034,0.003978,0.101041,252.956421,12.886214,1.010408,-418.343353,0.101119,0.000000
93.030006,56.853081,-418.343353,0.000030,0.003978,0.101041,252.895126,12.883093,1.010408,-418.343353,0.101119,0.000000
93.260002,56.839676,-418.387817,0.000052,0.003978,0.101041,252.835510,12.880054,1.010408,-418.387817,0.101119,0.000000
93.490005,56.828506,-418.343353,0.000013,0.003978,0.101041,252.785828,12.877523,1.010408,-418.343353,0.101119,0.000000
93.720001,56.808769,-418.387817,0.000017,0.003978,0.101041,252.698029,12.873051,1.010408,-418.387817,0.101119,0.000000
93.950005,56.793503,-418.476776,0.000017,0.003978,0.101041,252.630112,12.869592,1.010408,-418.476776,0.101119,0.000000
94.180008,56.776001,-418.387817,0.000004,0.003978,0.101041,252.552261,12.865625,1.010408,-418.387817,0.101119,0.000000
94.300003,56.770790,-418.476776,0.000004,0.003978,0.101041,252.529083,12.864445,1.010408,-418.476776,0.101119,0.000000