File: Data/compression 14/AutoNoHeating-14-14-3-240726_07262024_165921.csv
Time (sec),S:Load (lbs),S:HL1 (DIM),S:LVDT (in),S:Position (in),Ch:Position (mm),Ch:Load (N),Ch:Stress (MPa),Ch:Strain (mm/mm),Ch:HL1 (DIM),Set Point (),Cycles ()
0.110000,-0.014153,-430.353210,-0.010253,-0.005216,-0.132477,-0.062954,-0.003207,-1.324774,-430.353210,-0.132269,0.000000
0.350000,-0.012665,-430.397675,-0.010244,-0.005216,-0.132477,-0.056336,-0.002870,-1.324774,-430.397675,-0.132269,0.000000
0.590000,-0.013779,-430.397675,-0.010270,-0.005130,-0.130300,-0.061291,-0.003122,-1.303003,-430.397675,-0.129512,0.000000
0.830000,0.012291,-430.442169,-0.010184,-0.004988,-0.126693,0.054673,0.002785,-1.266925,-430.442169,-0.125505,0.000000
1.070000,-0.001862,-430.442169,-0.009985,-0.004821,-0.122461,-0.008281,-0.000422,-1.224610,-430.442169,-0.121516,0.000000
1.310000,-0.030533,-430.397675,-0.009830,-0.004670,-0.118628,-0.135817,-0.006919,-1.186277,-430.397675,-0.117509,0.000000
1.550000,-0.014153,-430.486633,-0.009675,-0.004516,-0.114708,-0.062954,-0.003207,-1.147081,-430.486633,-0.113520,0.000000
1.790000,-0.011917,-430.442169,-0.009507,-0.004358,-0.110684,-0.053010,-0.002700,-1.106840,-430.442169,-0.109513,0.000000
2.030000,-0.014526,-430.486633,-0.009369,-0.004202,-0.106720,-0.064617,-0.003292,-1.067204,-430.486633,-0.105524,0.000000
2.270000,-0.037239,-430.531128,-0.009153,-0.004038,-0.102567,-0.165648,-0.008438,-1.025669,-430.531128,-0.101517,0.000000
2.510000,-0.058464,-430.442169,-0.009011,-0.003886,-0.098708,-0.260061,-0.013248,-0.987078,-430.442169,-0.097528,0.000000
2.750000,-0.017876,-430.486633,-0.008830,-0.003731,-0.094762,-0.079515,-0.004051,-0.947617,-430.486633,-0.093522,0.000000
2.990000,0.006332,-430.486633,-0.008675,-0.003571,-0.090703,0.028168,0.001435,-0.907027,-430.486633,-0.089532,0.000000
3.230000,0.001488,-430.531128,-0.008541,-0.003411,-0.086627,0.006618,0.000337,-0.866272,-430.531128,-0.085526,0.000000
3.470000,-0.019363,-430.531128,-0.008317,-0.003257,-0.082716,-0.086133,-0.004388,-0.827159,-430.531128,-0.081536,0.000000
3.710000,-0.004845,-430.531128,-0.008192,-0.003097,-0.078657,-0.021550,-0.001098,-0.786569,-430.531128,-0.077530,0.000000
3.950000,0.006332,-430.575592,-0.008015,-0.002945,-0.074798,0.028168,0.001435,-0.747979,-430.575592,-0.073541,0.000000
4.190000,-0.014893,-430.620087,-0.007838,-0.002775,-0.070497,-0.066245,-0.003375,-0.704967,-430.620087,-0.069534,0.000000
4.430000,-0.042076,-430.620087,-0.007722,-0.002627,-0.066724,-0.187164,-0.009535,-0.667239,-430.620087,-0.065545,0.000000
4.670000,-0.023834,-430.620087,-0.007541,-0.002463,-0.062570,-0.106020,-0.005401,-0.625704,-430.620087,-0.061538,0.000000
4.910000,-0.025696,-430.575592,-0.007364,-0.002320,-0.058928,-0.114301,-0.005823,-0.589278,-430.575592,-0.057549,0.000000
5.150000,0.004837,-430.664581,-0.007157,-0.002149,-0.054574,0.021516,0.001096,-0.545744,-430.664581,-0.053543,0.000000
5.390000,-0.008194,-430.620087,-0.007015,-0.001999,-0.050776,-0.036449,-0.001857,-0.507759,-430.620087,-0.049536,0.000000
5.630000,-0.011169,-430.664581,-0.006851,-0.001835,-0.046605,-0.049684,-0.002531,-0.466049,-430.664581,-0.045547,0.000000
5.870000,0.012291,-430.709045,-0.006709,-0.001686,-0.042815,0.054673,0.002785,-0.428147,-430.709045,-0.041540,0.000000
6.110000,0.010056,-430.709045,-0.006541,-0.001519,-0.038582,0.044729,0.002279,-0.385825,-430.709045,-0.037551,0.000000
6.350000,-0.018250,-430.753540,-0.006347,-0.001363,-0.034628,-0.081178,-0.004135,-0.346280,-430.753540,-0.033544,0.000000
6.590000,-0.026810,-430.709045,-0.006187,-0.001211,-0.030769,-0.119255,-0.006075,-0.307689,-430.709045,-0.029555,0.000000
6.830000,-0.002235,-430.753540,-0.006058,-0.001056,-0.026832,-0.009944,-0.000507,-0.268319,-430.753540,-0.025548,0.000000
7.070000,-0.000374,-430.753540,-0.005894,-0.000894,-0.022704,-0.001663,-0.000085,-0.227041,-430.753540,-0.021559,0.000000
7.310000,0.006699,-430.798004,-0.005696,-0.000741,-0.018810,0.029797,0.001518,-0.188102,-430.798004,-0.017553,0.000000
7.550000,0.003349,-430.798004,-0.005527,-0.000578,-0.014673,0.014898,0.000759,-0.146733,-430.798004,-0.013564,0.000000
7.790000,0.013779,-430.753540,-0.005368,-0.000420,-0.010676,0.061291,0.003122,-0.106757,-430.753540,-0.009557,0.000000
8.030001,0.028297,-430.842499,-0.005221,-0.000273,-0.006946,0.125873,0.006412,-0.069460,-430.842499,-0.005568,0.000000
8.270000,0.119156,-430.842499,-0.005066,-0.000101,-0.002558,0.530032,0.027001,-0.025578,-430.842499,-0.001561,0.000000
8.510000,0.777885,-430.798004,-0.004911,-0.000000,-0.000000,3.460207,0.176271,-0.000000,-430.798004,0.000121,0.000000
8.750000,0.716072,-430.886963,-0.004889,-0.000000,-0.000009,3.185248,0.162264,-0.000091,-430.886963,0.000121,0.000000
8.990001,0.695221,-430.842499,-0.004898,-0.000000,-0.000009,3.092497,0.157539,-0.000091,-430.842499,0.000121,0.000000
9.230000,0.662079,-430.886963,-0.004919,-0.000000,-0.000009,2.945074,0.150029,-0.000091,-430.886963,0.000512,0.000000
9.470000,0.684792,-430.931458,-0.004907,-0.000000,-0.000009,3.046105,0.155176,-0.000091,-430.931458,0.000911,0.000000
9.710000,0.892204,-430.931458,-0.004907,0.000019,0.000494,3.968723,0.202176,0.004943,-430.931458,0.001310,0.000000
9.950001,1.076157,-430.931458,-0.004907,0.000033,0.000850,4.786983,0.243861,0.008501,-430.931458,0.001709,0.000000
10.190001,1.223984,-430.931458,-0.004889,0.000045,0.001154,5.444551,0.277359,0.011536,-430.931458,0.002107,0.000000
10.430000,1.505127,-430.931458,-0.004872,0.000066,0.001665,6.695139,0.341067,0.016654,-430.931458,0.002506,0.000000
10.670000,1.657799,-430.931458,-0.004863,0.000078,0.001977,7.374257,0.375663,0.019772,-430.931458,0.002905,0.000000
10.910001,1.892769,-430.931458,-0.004829,0.000091,0.002316,8.419456,0.428908,0.023156,-430.931458,0.003304,0.000000
11.150001,2.139282,-431.064911,-0.004812,0.000109,0.002775,9.516003,0.484768,0.027751,-431.064911,0.003711,0.000000
11.390000,2.504578,-431.020416,-0.004794,0.000131,0.003330,11.140918,0.567545,0.033300,-431.020416,0.004110,0.000000
11.630000,2.661346,-431.020416,-0.004786,0.000142,0.003616,11.838261,0.603070,0.036161,-431.020416,0.004509,0.000000
11.870001,2.806946,-431.020416,-0.004760,0.000154,0.003911,12.485918,0.636063,0.039113,-431.020416,0.004908,0.000000
12.110001,3.124947,-430.975922,-0.004764,0.000171,0.004353,13.900456,0.708123,0.043534,-430.975922,0.005307,0.000000
12.350000,3.426567,-431.064911,-0.004743,0.000185,0.004692,15.242131,0.776471,0.046918,-431.064911,0.005706,0.000000
12.590000,3.804527,-431.064911,-0.004704,0.000205,0.005194,16.923382,0.862118,0.051944,-431.064911,0.006105,0.000000
12.830001,3.855919,-431.109375,-0.004747,0.000215,0.005463,17.151983,0.873764,0.054631,-431.109375,0.006504,0.000000
13.070001,4.432350,-431.064911,-0.004678,0.000240,0.006105,19.716078,1.004385,0.061050,-431.064911,0.006912,0.000000
13.310000,4.660614,-431.153870,-0.004678,0.000256,0.006504,20.731447,1.056110,0.065040,-431.153870,0.007311,0.000000
13.550000,4.918663,-431.109375,-0.004674,0.000271,0.006877,21.879307,1.114585,0.068772,-431.109375,0.007710,0.000000
13.790001,5.125710,-431.109375,-0.004682,0.000283,0.007181,22.800295,1.161502,0.071807,-431.109375,0.008109,0.000000
14.030001,5.425468,-431.153870,-0.004652,0.000298,0.007562,24.133690,1.229429,0.075622,-431.153870,0.008508,0.000000
14.270000,5.828743,-431.153870,-0.004652,0.000316,0.008022,25.927544,1.320812,0.080217,-431.153870,0.008907,0.000000
14.510000,6.001526,-431.109375,-0.004618,0.000329,0.008351,26.696121,1.359965,0.083510,-431.109375,0.009306,0.000000
14.750001,6.131859,-431.198334,-0.004600,0.000340,0.008629,27.275869,1.389499,0.086288,-431.198334,0.009704,0.000000
14.990001,6.810692,-431.153870,-0.004596,0.000367,0.009314,30.295471,1.543325,0.093139,-431.153870,0.010112,0.000000
15.230000,7.092949,-431.153870,-0.004583,0.000383,0.009722,31.551012,1.607285,0.097219,-431.153870,0.010511,0.000000
15.470000,7.175987,-431.153870,-0.004549,0.000396,0.010051,31.920385,1.626102,0.100512,-431.153870,0.010910,0.000000
15.710001,7.328659,-431.198334,-0.004544,0.000407,0.010329,32.599503,1.660698,0.103290,-431.198334,0.011309,0.000000
15.950001,7.582619,-431.287292,-0.004549,0.000419,0.010649,33.729172,1.718246,0.106492,-431.287292,0.011707,0.000000
16.190001,7.892433,-431.198334,-0.004523,0.000436,0.011066,35.107296,1.788451,0.110655,-431.198334,0.012106,0.000000
16.430000,8.302414,-431.287292,-0.004514,0.000452,0.011491,36.930981,1.881354,0.114909,-431.287292,0.012505,0.000000
16.670000,8.359016,-431.287292,-0.004501,0.000462,0.011725,37.182762,1.894180,0.117248,-431.287292,0.012904,0.000000
16.910002,9.155891,-431.198334,-0.004458,0.000490,0.012436,40.727440,2.074754,0.124357,-431.198334,0.013312,0.000000
17.150002,9.347290,-431.331787,-0.004488,0.000507,0.012887,41.578823,2.118126,0.128868,-431.331787,0.013711,0.000000
17.390001,9.393097,-431.287292,-0.004458,0.000520,0.013199,41.782581,2.128506,0.131994,-431.287292,0.014109,0.000000
17.630001,9.460495,-431.376251,-0.004458,0.000530,0.013468,42.082382,2.143779,0.134682,-431.376251,0.014508,0.000000
17.870001,9.842545,-431.331787,-0.004419,0.000547,0.013893,43.781826,2.230352,0.138928,-431.331787,0.014907,0.000000
18.110001,10.185875,-431.420746,-0.004424,0.000566,0.014379,45.309036,2.308152,0.143788,-431.420746,0.015306,0.000000
18.350000,10.509094,-431.331787,-0.004359,0.000581,0.014760,46.746784,2.381395,0.147603,-431.331787,0.015705,0.000000
18.590000,10.413765,-431.376251,-0.004402,0.000589,0.014951,46.322739,2.359793,0.149511,-431.376251,0.016104,0.000000
18.830002,11.024086,-431.376251,-0.004376,0.000613,0.015558,49.037582,2.498094,0.155582,-431.376251,0.016512,0.000000
19.070002,11.483597,-431.420746,-0.004333,0.000633,0.016078,51.081589,2.602220,0.160782,-431.420746,0.016911,0.000000
19.310001,11.460136,-431.376251,-0.004350,0.000644,0.016356,50.977234,2.596904,0.163560,-431.376251,0.017310,0.000000
19.550001,11.512268,-431.420746,-0.004290,0.000656,0.016668,51.209126,2.608717,0.166679,-431.420746,0.017709,0.000000
19.790001,12.077896,-431.465240,-0.004290,0.000675,0.017154,53.725166,2.736890,0.171539,-431.465240,0.018108,0.000000
20.030001,12.234299,-431.509705,-0.004264,0.000693,0.017596,54.420879,2.772332,0.175960,-431.509705,0.018507,0.000000
20.270000,12.611885,-431.420746,-0.004277,0.000709,0.018003,56.100468,2.857894,0.180032,-431.420746,0.018906,0.000000
20.510000,12.424950,-431.554199,-0.004260,0.000716,0.018186,55.268936,2.815534,0.181857,-431.554199,0.019304,0.000000
20.750002,13.285133,-431.509705,-0.004221,0.000742,0.018853,59.095226,3.010454,0.188533,-431.509705,0.019712,0.000000
20.990002,13.525314,-431.465240,-0.004217,0.000759,0.019279,60.163605,3.064880,0.192787,-431.465240,0.020111,0.000000
21.230001,13.465729,-431.554199,-0.004230,0.000771,0.019582,59.898552,3.051378,0.195815,-431.554199,0.020510,0.000000
21.470001,13.463501,-431.554199,-0.004169,0.000782,0.019868,59.888645,3.050873,0.198684,-431.554199,0.020909,0.000000
21.710001,13.946465,-431.554199,-0.004191,0.000802,0.020363,62.036972,3.160314,0.203627,-431.554199,0.021307,0.000000
21.950001,14.153877,-431.598663,-0.004186,0.000817,0.020753,62.959591,3.207314,0.207526,-431.598663,0.021706,0.000000
22.190001,14.396294,-431.509705,-0.004148,0.000833,0.021161,64.037910,3.262247,0.211606,-431.509705,0.022105,0.000000
22.430000,14.561249,-431.598663,-0.004143,0.000845,0.021472,64.771667,3.299626,0.214725,-431.598663,0.022513,0.000000
22.670002,15.052780,-431.554199,-0.004148,0.000866,0.021984,66.958107,3.411009,0.219842,-431.554199,0.022912,0.000000
22.910002,15.502609,-431.598663,-0.004083,0.000887,0.022522,68.959053,3.512941,0.225216,-431.598663,0.023311,0.000000
23.150002,15.533890,-431.643158,-0.004079,0.000901,0.022877,69.098190,3.520030,0.228774,-431.643158,0.023710,0.000000
23.390001,15.525322,-431.643158,-0.004061,0.000913,0.023198,69.060081,3.518088,0.231984,-431.643158,0.024109,0.000000
23.630001,15.513039,-431.687622,-0.004074,0.000924,0.023475,69.005440,3.515305,0.234754,-431.687622,0.024508,0.000000
23.870001,16.121117,-431.687622,-0.004027,0.000945,0.024005,71.710312,3.653097,0.240046,-431.687622,0.024907,0.000000
24.110001,16.254433,-431.687622,-0.004027,0.000961,0.024421,72.303329,3.683307,0.244209,-431.687622,0.025306,0.000000
24.350000,16.309540,-431.732117,-0.004044,0.000972,0.024699,72.548454,3.695795,0.246987,-431.732117,0.025713,0.000000
24.590002,16.420509,-431.732117,-0.004027,0.000985,0.025028,73.042076,3.720941,0.250280,-431.732117,0.026112,0.000000
24.830002,16.861771,-431.732117,-0.003980,0.001005,0.025531,75.004898,3.820932,0.255314,-431.732117,0.026511,0.000000
25.070002,17.379738,-431.776581,-0.003967,0.001025,0.026034,77.308937,3.938305,0.260340,-431.776581,0.026910,0.000000
25.310001,17.295952,-431.776581,-0.003967,0.001037,0.026338,76.936234,3.919319,0.263376,-431.776581,0.027309,0.000000
25.550001,17.371918,-431.732117,-0.003936,0.001051,0.026693,77.274147,3.936533,0.266934,-431.732117,0.027708,0.000000
25.790001,17.858986,-431.776581,-0.003902,0.001071,0.027213,79.440735,4.046904,0.272134,-431.776581,0.028107,0.000000
26.030001,17.937180,-431.776581,-0.003893,0.001083,0.027509,79.788559,4.064623,0.275086,-431.776581,0.028506,0.000000
26.270000,18.141609,-431.776581,-0.003889,0.001098,0.027890,80.697906,4.110947,0.278901,-431.776581,0.028914,0.000000
26.510002,18.062668,-431.865540,-0.003911,0.001108,0.028150,80.346756,4.093059,0.281498,-431.865540,0.029312,0.000000
26.750002,18.669640,-431.865540,-0.003872,0.001133,0.028783,83.046707,4.230601,0.287834,-431.865540,0.029711,0.000000
26.990002,19.204361,-431.865540,-0.003846,0.001150,0.029208,85.425262,4.351770,0.292080,-431.865540,0.030110,0.000000
27.230001,19.052063,-431.865540,-0.003798,0.001164,0.029555,84.747810,4.317259,0.295547,-431.865540,0.030509,0.000000
27.470001,19.368584,-431.865540,-0.003820,0.001181,0.030006,86.155762,4.388984,0.300059,-431.865540,0.030908,0.000000
27.710001,19.762550,-431.865540,-0.003794,0.001201,0.030500,87.908211,4.478258,0.305002,-431.865540,0.031307,0.000000
27.950001,19.851921,-431.865540,-0.003781,0.001217,0.030908,88.305756,4.498509,0.309082,-431.865540,0.031706,0.000000
28.190001,19.705208,-431.910034,-0.003738,0.001226,0.031133,87.653145,4.465264,0.311330,-431.910034,0.032113,0.000000
28.430002,19.799789,-431.954529,-0.003760,0.001240,0.031489,88.073860,4.486696,0.314888,-431.954529,0.032512,0.000000
28.670002,20.862907,-431.910034,-0.003738,0.001267,0.032183,92.802849,4.727602,0.321830,-431.910034,0.032911,0.000000
28.910002,20.731461,-431.998993,-0.003725,0.001279,0.032487,92.218140,4.697816,0.324865,-431.998993,0.033310,0.000000
29.150002,20.678215,-431.954529,-0.003712,0.001291,0.032790,91.981293,4.685750,0.327901,-431.954529,0.033709,0.000000
29.390001,20.837959,-431.998993,-0.003691,0.001307,0.033206,92.691872,4.721949,0.332056,-431.998993,0.034108,0.000000
29.630001,21.191345,-431.998993,-0.003643,0.001325,0.033666,94.263809,4.802028,0.336659,-431.998993,0.034507,0.000000
29.870001,21.506744,-432.043488,-0.003643,0.001341,0.034073,95.666779,4.873498,0.340731,-432.043488,0.034906,0.000000
30.110001,21.373436,-431.998993,-0.003626,0.001351,0.034324,95.073792,4.843290,0.343245,-431.998993,0.035313,0.000000
30.350002,21.730164,-432.087952,-0.003617,0.001368,0.034758,96.660599,4.924126,0.347582,-432.087952,0.035712,0.000000
30.590002,22.462997,-431.998993,-0.003600,0.001390,0.035296,99.920403,5.090188,0.352957,-431.998993,0.036111,0.000000
30.830002,22.565025,-432.087952,-0.003574,0.001405,0.035686,100.374245,5.113308,0.356863,-432.087952,0.036510,0.000000
31.070002,22.603752,-431.954529,-0.003566,0.001419,0.036033,100.546509,5.122084,0.360330,-431.954529,0.036909,0.000000
31.310001,22.682693,-432.087952,-0.003561,0.001433,0.036406,100.897659,5.139972,0.364061,-432.087952,0.037308,0.000000
31.550001,22.713226,-432.132446,-0.003540,0.001445,0.036710,101.033478,5.146891,0.367097,-432.132446,0.037707,0.000000
31.790001,23.272163,-432.087952,-0.003518,0.001465,0.037212,103.519753,5.273548,0.372123,-432.087952,0.038106,0.000000
32.030003,23.154488,-432.132446,-0.003510,0.001478,0.037542,102.996307,5.246881,0.375424,-432.132446,0.038514,0.000000
32.270000,23.364136,-432.132446,-0.003501,0.001493,0.037932,103.928864,5.294389,0.379322,-432.132446,0.038913,0.000000
32.510002,23.864235,-432.221405,-0.003479,0.001511,0.038383,106.153419,5.407713,0.383834,-432.221405,0.039311,0.000000
32.750000,24.395607,-432.176910,-0.003436,0.001531,0.038886,108.517082,5.528124,0.388860,-432.176910,0.039710,0.000000
32.990002,24.285759,-432.176910,-0.003449,0.001543,0.039190,108.028450,5.503232,0.391896,-432.176910,0.040109,0.000000
33.230003,24.248894,-432.221405,-0.003428,0.001557,0.039545,107.864464,5.494878,0.395453,-432.221405,0.040508,0.000000
33.470001,24.408272,-432.132446,-0.003415,0.001570,0.039875,108.573418,5.530993,0.398746,-432.132446,0.040907,0.000000
33.710003,24.866287,-432.221405,-0.003402,0.001590,0.040378,110.610771,5.634781,0.403780,-432.221405,0.041306,0.000000
33.950001,25.202911,-432.221405,-0.003380,0.001605,0.040760,112.108147,5.711061,0.407595,-432.221405,0.041713,0.000000
34.190002,25.233818,-432.265869,-0.003359,0.001619,0.041124,112.245628,5.718065,0.411236,-432.265869,0.042112,0.000000
34.430000,26.013191,-432.310364,-0.003354,0.001643,0.041740,115.712456,5.894673,0.417398,-432.310364,0.042511,0.000000
34.670002,26.034790,-432.310364,-0.003316,0.001658,0.042104,115.808533,5.899568,0.421039,-432.310364,0.042910,0.000000
34.910000,26.025108,-432.354858,-0.003298,0.001671,0.042442,115.765465,5.897374,0.424423,-432.354858,0.043309,0.000000
35.150002,25.875786,-432.265869,-0.003285,0.001682,0.042711,115.101242,5.863537,0.427110,-432.265869,0.043708,0.000000
35.390003,26.102936,-432.354858,-0.003281,0.001697,0.043093,116.111656,5.915009,0.430925,-432.354858,0.044107,0.000000
35.630001,26.561325,-432.310364,-0.003268,0.001715,0.043552,118.150673,6.018882,0.435520,-432.310364,0.044506,0.000000
35.870003,26.712509,-432.310364,-0.003251,0.001729,0.043916,118.823174,6.053141,0.439161,-432.310364,0.044914,0.000000
36.110001,26.913963,-432.399323,-0.003251,0.001745,0.044324,119.719292,6.098791,0.443241,-432.399323,0.045313,0.000000
36.350002,27.849739,-432.310364,-0.003225,0.001768,0.044896,123.881828,6.310841,0.448964,-432.310364,0.045712,0.000000
36.590000,27.903358,-432.354858,-0.003216,0.001782,0.045261,124.120338,6.322991,0.452605,-432.354858,0.046111,0.000000
36.830002,27.989746,-432.443817,-0.003178,0.001796,0.045616,124.504608,6.342567,0.456163,-432.443817,0.046510,0.000000
37.070004,27.778610,-432.310364,-0.003152,0.001807,0.045902,123.565430,6.294723,0.459024,-432.310364,0.046908,0.000000
37.310001,27.780472,-432.443817,-0.003139,0.001820,0.046232,123.573708,6.295145,0.462317,-432.443817,0.047307,0.000000
37.550003,28.402710,-432.399323,-0.003122,0.001841,0.046769,126.341560,6.436146,0.467692,-432.399323,0.047715,0.000000
37.790001,28.646614,-432.443817,-0.003104,0.001854,0.047090,127.426506,6.491416,0.470901,-432.443817,0.048114,0.000000
38.030003,28.227692,-432.443817,-0.003143,0.001861,0.047263,125.563042,6.396487,0.472635,-432.443817,0.048513,0.000000
38.270000,29.572327,-432.399323,-0.003104,0.001889,0.047992,131.544281,6.701185,0.479925,-432.399323,0.048911,0.000000
38.510002,29.909325,-432.532776,-0.003078,0.001907,0.048443,133.043320,6.777550,0.484429,-432.532776,0.049310,0.000000
38.750000,29.881027,-432.443817,-0.003040,0.001921,0.048790,132.917450,6.771138,0.487903,-432.443817,0.049709,0.000000
38.990002,29.749207,-432.488281,-0.003035,0.001934,0.049128,132.331085,6.741266,0.491279,-432.488281,0.050108,0.000000
39.230003,29.881401,-432.577240,-0.003031,0.001946,0.049431,132.919113,6.771223,0.494315,-432.577240,0.050507,0.000000
39.470001,30.834297,-432.488281,-0.002992,0.001971,0.050056,137.157806,6.987152,0.500560,-432.488281,0.050914,0.000000
39.710003,30.580345,-432.577240,-0.002997,0.001980,0.050282,136.028168,6.929605,0.502816,-432.577240,0.051313,0.000000
39.950001,30.291756,-432.577240,-0.002979,0.001991,0.050568,134.744461,6.864210,0.505677,-432.577240,0.051712,0.000000
40.190002,31.559685,-432.621735,-0.002984,0.002018,0.051262,140.384491,7.151526,0.512619,-432.621735,0.052111,0.000000
40.430000,31.965569,-432.621735,-0.002928,0.002034,0.051669,142.189957,7.243502,0.516691,-432.621735,0.052510,0.000000
40.670002,31.447601,-432.577240,-0.002915,0.002044,0.051912,139.885910,7.126129,0.519121,-432.577240,0.052909,0.000000
40.910004,31.635277,-432.666199,-0.002902,0.002057,0.052241,140.720734,7.168656,0.522414,-432.666199,0.053308,0.000000
41.150002,32.137978,-432.577240,-0.002897,0.002075,0.052693,142.956863,7.282570,0.526926,-432.577240,0.053707,0.000000
41.390003,32.747177,-432.666199,-0.002863,0.002096,0.053247,145.666718,7.420616,0.532474,-432.666199,0.054115,0.000000
41.630001,32.893524,-432.710693,-0.002854,0.002108,0.053551,146.317703,7.453779,0.535510,-432.710693,0.054514,0.000000
41.870003,32.329002,-432.666199,-0.002871,0.002114,0.053707,143.806580,7.325857,0.537069,-432.666199,0.054913,0.000000
42.110001,33.681091,-432.666199,-0.002854,0.002142,0.054418,149.820984,7.632245,0.544185,-432.666199,0.055312,0.000000
42.350002,34.016594,-432.710693,-0.002811,0.002160,0.054870,151.313370,7.708271,0.548696,-432.710693,0.055711,0.000000
42.590000,33.828918,-432.799652,-0.002785,0.002171,0.055156,150.478546,7.665742,0.551558,-432.799652,0.056110,0.000000
42.830002,33.712364,-432.710693,-0.002785,0.002185,0.055493,149.960083,7.639331,0.554934,-432.710693,0.056508,0.000000
43.070004,34.316353,-432.710693,-0.002777,0.002202,0.055936,152.646759,7.776197,0.559362,-432.710693,0.056907,0.000000
43.310001,34.663406,-432.710693,-0.002772,0.002221,0.056413,154.190536,7.854840,0.564131,-432.710693,0.057315,0.000000
43.550003,34.864861,-432.799652,-0.002755,0.002233,0.056717,155.086639,7.900490,0.567167,-432.799652,0.057714,0.000000
43.790001,34.856293,-432.844147,-0.002716,0.002245,0.057011,155.048538,7.898549,0.570111,-432.844147,0.058113,0.000000
44.030003,35.662857,-432.799652,-0.002725,0.002267,0.057583,158.636307,8.081319,0.575834,-432.799652,0.058511,0.000000
44.270000,36.463081,-432.844147,-0.002677,0.002288,0.058113,162.195892,8.262652,0.581125,-432.844147,0.058910,0.000000
44.510002,36.439995,-432.888611,-0.002673,0.002301,0.058433,162.093185,8.257421,0.584335,-432.888611,0.059309,0.000000
44.750004,36.295891,-432.844147,-0.002656,0.002313,0.058746,161.452179,8.224767,0.587461,-432.844147,0.059708,0.000000
44.990002,36.124222,-432.844147,-0.002604,0.002327,0.059110,160.688568,8.185865,0.591102,-432.844147,0.060107,0.000000
45.230003,36.912537,-432.844147,-0.002600,0.002344,0.059527,164.195160,8.364501,0.595266,-432.844147,0.060515,0.000000
45.470001,37.287514,-432.844147,-0.002587,0.002363,0.060029,165.863144,8.449471,0.600292,-432.844147,0.060914,0.000000
45.710003,37.074516,-432.933105,-0.002600,0.002371,0.060220,164.915680,8.401206,0.602199,-432.933105,0.061313,0.000000
45.950001,37.198143,-432.933105,-0.002565,0.002385,0.060576,165.465607,8.429220,0.605757,-432.933105,0.061712,0.000000
46.190002,38.068756,-432.977570,-0.002574,0.002409,0.061191,169.338287,8.626504,0.611912,-432.977570,0.062111,0.000000
46.430000,38.682053,-432.933105,-0.002570,0.002424,0.061582,172.066360,8.765479,0.615818,-432.933105,0.062510,0.000000
46.670002,38.784454,-432.888611,-0.002509,0.002441,0.061998,172.521866,8.788683,0.619981,-432.888611,0.062909,0.000000
46.910004,39.020538,-433.022064,-0.002522,0.002456,0.062371,173.572021,8.842180,0.623705,-433.022064,0.063308,0.000000
47.150002,39.326630,-432.977570,-0.002458,0.002471,0.062752,174.933578,8.911541,0.627520,-432.977570,0.063715,0.000000
47.390003,39.218636,-433.022064,-0.002483,0.002485,0.063125,174.453201,8.887070,0.631252,-433.022064,0.064114,0.000000
47.630001,39.435730,-433.066528,-0.002458,0.002497,0.063411,175.418884,8.936265,0.634114,-433.066528,0.064513,0.000000
47.870003,39.222366,-432.977570,-0.002453,0.002507,0.063672,174.469803,8.887916,0.636718,-432.977570,0.064912,0.000000
48.110001,40.131325,-433.066528,-0.002410,0.002534,0.064357,178.513046,9.093888,0.643568,-433.066528,0.065311,0.000000
48.350002,41.101730,-433.022064,-0.002397,0.002550,0.064773,182.829620,9.313785,0.647732,-433.022064,0.065710,0.000000
48.590004,41.233543,-433.066528,-0.002410,0.002566,0.065180,183.415955,9.343655,0.651804,-433.066528,0.066108,0.000000
48.830002,41.634590,-433.066528,-0.002376,0.002582,0.065588,185.199905,9.434533,0.655884,-433.066528,0.066507,0.000000
49.070004,42.190918,-433.022064,-0.002358,0.002600,0.066048,187.674576,9.560598,0.660479,-433.022064,0.066915,0.000000
49.310001,42.588608,-433.155487,-0.002315,0.002618,0.066490,189.443588,9.650717,0.664900,-433.155487,0.067314,0.000000
49.550003,42.100426,-433.066528,-0.002302,0.002624,0.066655,187.272049,9.540092,0.666550,-433.066528,0.067713,0.000000
49.790001,42.286240,-433.066528,-0.002311,0.002641,0.067071,188.098587,9.582199,0.670714,-433.066528,0.068112,0.000000
50.030003,43.768288,-433.155487,-0.002294,0.002667,0.067747,194.691071,9.918036,0.677473,-433.155487,0.068511,0.000000
50.270004,43.671844,-433.111023,-0.002276,0.002679,0.068051,194.262070,9.896181,0.680509,-433.111023,0.068910,0.000000
50.510002,43.669983,-433.199982,-0.002246,0.002693,0.068407,194.253784,9.895760,0.684067,-433.199982,0.069309,0.000000
50.750004,43.966019,-433.155487,-0.002220,0.002709,0.068814,195.570618,9.962842,0.688139,-433.155487,0.069716,0.000000
50.990002,44.431480,-433.199982,-0.002246,0.002725,0.069213,197.641098,10.068317,0.692129,-433.199982,0.070115,0.000000
51.230003,44.828430,-433.155487,-0.002216,0.002741,0.069629,199.406815,10.158268,0.696292,-433.155487,0.070514,0.000000
51.470001,44.521599,-433.199982,-0.002177,0.002750,0.069855,198.041962,10.088738,0.698548,-433.199982,0.070913,0.000000
51.710003,45.012009,-433.288940,-0.002169,0.002768,0.070298,200.223419,10.199867,0.702976,-433.288940,0.071312,0.000000
51.950001,46.060982,-433.155487,-0.002156,0.002791,0.070904,204.889481,10.437568,0.709040,-433.155487,0.071711,0.000000
52.190002,46.364838,-433.288940,-0.002139,0.002806,0.071260,206.241104,10.506422,0.712597,-433.288940,0.072110,0.000000
52.430004,46.345848,-433.244476,-0.002143,0.002818,0.071572,206.156631,10.502119,0.715724,-433.244476,0.072509,0.000000
52.670002,46.539108,-433.244476,-0.002095,0.002834,0.071980,207.016296,10.545913,0.719796,-433.244476,0.072916,0.000000
52.910004,46.931221,-433.288940,-0.002100,0.002851,0.072413,208.760498,10.634767,0.724134,-433.288940,0.073315,0.000000
53.150002,47.298752,-433.288940,-0.002061,0.002865,0.072769,210.395355,10.718050,0.727691,-433.288940,0.073714,0.000000
53.390003,47.313271,-433.377899,-0.002070,0.002879,0.073116,210.459946,10.721340,0.731158,-433.377899,0.074113,0.000000
53.630001,47.650642,-433.377899,-0.002031,0.002893,0.073488,211.960648,10.797791,0.734883,-433.377899,0.074512,0.000000
53.870003,48.200264,-433.333435,-0.002001,0.002911,0.073949,214.405487,10.922337,0.739485,-433.333435,0.074911,0.000000
54.110004,49.075714,-433.466858,-0.002031,0.002932,0.074478,218.299683,11.120716,0.744776,-433.466858,0.075310,0.000000
54.350002,48.955063,-433.288940,-0.001962,0.002944,0.074772,217.763000,11.093376,0.747721,-433.288940,0.075708,0.000000
54.590004,48.996765,-433.377899,-0.001957,0.002957,0.075119,217.948502,11.102826,0.751188,-433.377899,0.076117,0.000000
54.830002,49.029907,-433.333435,-0.001949,0.002968,0.075397,218.095917,11.110335,0.753966,-433.333435,0.076515,0.000000
55.070004,49.804817,-433.377899,-0.001944,0.002990,0.075943,221.542892,11.285933,0.759432,-433.377899,0.076914,0.000000
55.310001,50.039780,-433.466858,-0.001906,0.003003,0.076264,222.588058,11.339176,0.762641,-433.466858,0.077313,0.000000
55.550003,50.489983,-433.333435,-0.001867,0.003022,0.076767,224.590652,11.441194,0.767668,-433.333435,0.077712,0.000000
55.790001,51.717323,-433.511353,-0.001863,0.003045,0.077339,230.050140,11.719313,0.773390,-433.511353,0.078111,0.000000
56.030003,51.781738,-433.466858,-0.001867,0.003058,0.077686,230.336670,11.733910,0.776857,-433.466858,0.078510,0.000000
56.270004,51.751579,-433.422394,-0.001841,0.003070,0.077981,230.202515,11.727076,0.779809,-433.422394,0.078909,0.000000
56.510002,51.540817,-433.466858,-0.001798,0.003083,0.078302,229.264999,11.679316,0.783019,-433.466858,0.079316,0.000000
56.750004,51.801102,-433.466858,-0.001785,0.003096,0.078640,230.422806,11.738297,0.786403,-433.466858,0.079715,0.000000
56.990002,52.525742,-433.511353,-0.001794,0.003117,0.079169,233.646164,11.902503,0.791686,-433.511353,0.080114,0.000000
57.230003,52.358543,-433.511353,-0.001768,0.003127,0.079438,232.902435,11.864615,0.794381,-433.511353,0.080513,0.000000
57.470001,52.780075,-433.511353,-0.001750,0.003146,0.079906,234.777496,11.960135,0.799059,-433.511353,0.080912,0.000000
57.710003,54.017838,-433.555817,-0.001733,0.003167,0.080452,240.283340,12.240617,0.804525,-433.555817,0.081311,0.000000
57.950005,54.229347,-433.511353,-0.001694,0.003182,0.080817,241.224182,12.288546,0.808166,-433.511353,0.081710,0.000000
58.190002,54.252808,-433.644806,-0.001664,0.003194,0.081138,241.328537,12.293861,0.811375,-433.644806,0.082109,0.000000
58.430004,54.045769,-433.600311,-0.001656,0.003208,0.081484,240.407593,12.246946,0.814842,-433.600311,0.082517,0.000000
58.670002,53.999222,-433.600311,-0.001625,0.003218,0.081727,240.200531,12.236398,0.817272,-433.600311,0.082916,0.000000
58.910004,54.615494,-433.644806,-0.001600,0.003237,0.082231,242.941849,12.376048,0.822306,-433.644806,0.083315,0.000000
59.150002,55.025108,-433.600311,-0.001595,0.003252,0.082612,244.763901,12.468868,0.826121,-433.600311,0.083714,0.000000
59.390003,54.535439,-433.644806,-0.001617,0.003260,0.082794,242.585739,12.357907,0.827938,-433.644806,0.084112,0.000000
59.630001,56.163078,-433.644806,-0.001574,0.003289,0.083549,249.825851,12.726735,0.835485,-433.644806,0.084511,0.000000
59.870003,56.839302,-433.644806,-0.001535,0.003307,0.084008,252.833847,12.879970,0.840080,-433.644806,0.084910,0.000000
60.110004,56.827019,-433.689270,-0.001548,0.003321,0.084355,252.779205,12.877186,0.843547,-433.689270,0.085309,0.000000
60.350002,56.642319,-433.689270,-0.001479,0.003333,0.084667,251.957611,12.835333,0.846673,-433.689270,0.085717,0.000000
60.590004,56.710091,-433.778229,-0.001505,0.003347,0.085014,252.259079,12.850690,0.850140,-433.778229,0.086115,0.000000
60.830002,57.670441,-433.689270,-0.001483,0.003369,0.085578,256.530945,13.068309,0.855780,-433.689270,0.086514,0.000000
61.070004,57.462280,-433.733765,-0.001453,0.003378,0.085804,255.604996,13.021139,0.858036,-433.733765,0.086913,0.000000
61.310001,57.111877,-433.733765,-0.001440,0.003391,0.086133,254.046326,12.941736,0.861329,-433.733765,0.087312,0.000000
61.550003,58.701538,-433.733765,-0.001401,0.003418,0.086818,261.117493,13.301959,0.868179,-433.733765,0.087711,0.000000
61.790005,59.091042,-433.867187,-0.001380,0.003434,0.087234,262.850067,13.390222,0.872343,-433.867187,0.088110,0.000000
62.030003,58.393211,-433.778229,-0.001350,0.003439,0.087347,259.745972,13.232090,0.873470,-433.778229,0.088509,0.000000
62.270004,58.614029,-433.822723,-0.001315,0.003458,0.087824,260.728210,13.282128,0.878239,-433.822723,0.088916,0.000000
62.510002,59.156952,-433.822723,-0.001293,0.003475,0.088258,263.143250,13.405156,0.882577,-433.822723,0.089315,0.000000
62.750004,59.989578,-433.867187,-0.001311,0.003496,0.088804,266.846985,13.593832,0.888042,-433.867187,0.089714,0.000000
62.990002,59.963882,-433.867187,-0.001276,0.003507,0.089081,266.732666,13.588011,0.890813,-433.867187,0.090113,0.000000
63.230003,59.259727,-433.822723,-0.001276,0.003513,0.089237,263.600433,13.428447,0.892372,-433.822723,0.090512,0.000000
63.470001,60.892204,-433.911682,-0.001229,0.003543,0.089992,270.862061,13.798371,0.899919,-433.911682,0.090911,0.000000
63.710003,61.462677,-433.867187,-0.001190,0.003562,0.090478,273.399628,13.927642,0.904779,-433.867187,0.091310,0.000000
63.950005,61.283569,-433.867187,-0.001190,0.003573,0.090764,272.602936,13.887055,0.907641,-433.867187,0.091718,0.000000
64.190002,61.210213,-433.956146,-0.001186,0.003586,0.091093,272.276611,13.870433,0.910933,-433.956146,0.092117,0.000000
64.430000,61.622803,-433.911682,-0.001147,0.003604,0.091544,274.111908,13.963926,0.915445,-433.911682,0.092516,0.000000
64.670006,62.198112,-434.000641,-0.001147,0.003622,0.091987,276.671021,14.094294,0.919866,-434.000641,0.092915,0.000000
64.910004,62.072998,-433.911682,-0.001099,0.003632,0.092255,276.114471,14.065943,0.922553,-433.911682,0.093314,0.000000
65.150002,62.063690,-433.956146,-0.001091,0.003643,0.092533,276.073090,14.063833,0.925331,-433.956146,0.093712,0.000000
65.389999,62.993874,-434.045135,-0.001061,0.003666,0.093114,280.210754,14.274616,0.931137,-434.045135,0.094111,0.000000
65.630005,63.947144,-434.000641,-0.001048,0.003687,0.093643,284.451111,14.490630,0.936428,-434.000641,0.094510,0.000000
65.870003,64.033539,-434.000641,-0.001009,0.003700,0.093973,284.835419,14.510207,0.939729,-434.000641,0.094918,0.000000
66.110001,63.900604,-433.956146,-0.001005,0.003713,0.094320,284.244080,14.480084,0.943196,-433.956146,0.095317,0.000000
66.350006,64.113220,-434.000641,-0.000974,0.003728,0.094684,285.189850,14.528263,0.946837,-434.000641,0.095715,0.000000
66.590004,64.598434,-434.045135,-0.000953,0.003746,0.095143,287.348175,14.638215,0.951432,-434.045135,0.096114,0.000000
66.830002,65.171875,-434.045135,-0.000931,0.003763,0.095577,289.898987,14.768158,0.955769,-434.045135,0.096513,0.000000
67.070000,64.822220,-434.045135,-0.000923,0.003769,0.095742,288.343628,14.688925,0.957419,-434.045135,0.096912,0.000000
67.310005,64.993149,-434.134094,-0.000905,0.003785,0.096132,289.103973,14.727658,0.961318,-434.134094,0.097311,0.000000
67.550003,66.392899,-434.089600,-0.000897,0.003812,0.096817,295.330353,15.044846,0.968169,-434.089600,0.097710,0.000000
67.790001,66.688187,-434.134094,-0.000875,0.003823,0.097112,296.643860,15.111759,0.971121,-434.134094,0.098118,0.000000
68.030006,66.976028,-434.089600,-0.000841,0.003841,0.097554,297.924255,15.176985,0.975542,-434.089600,0.098517,0.000000
68.270004,67.301102,-434.178558,-0.000819,0.003854,0.097901,299.370239,15.250648,0.979008,-434.178558,0.098916,0.000000
68.510002,67.254929,-434.134094,-0.000802,0.003859,0.098014,299.164856,15.240185,0.980136,-434.134094,0.098239,0.000000
68.750000,65.880508,-434.223053,-0.000776,0.003859,0.098014,293.051147,14.928737,0.980136,-434.223053,0.098239,0.000000
68.990005,64.729874,-434.223053,-0.000737,0.003856,0.097945,287.932861,14.667999,0.979448,-434.223053,0.098014,0.000000
69.230003,63.589676,-434.223053,-0.000759,0.003855,0.097918,282.860992,14.409627,0.979183,-434.223053,0.098014,0.000000
69.470001,62.554108,-434.223053,-0.000724,0.003855,0.097910,278.254578,14.174963,0.979099,-434.223053,0.098014,0.000000
69.710007,61.609398,-434.267517,-0.000750,0.003854,0.097901,274.052277,13.960889,0.979008,-434.267517,0.098014,0.000000
69.950005,60.740654,-434.223053,-0.000733,0.003854,0.097901,270.187927,13.764029,0.979008,-434.223053,0.098014,0.000000
70.190002,59.936699,-434.223053,-0.000694,0.003854,0.097901,266.611755,13.581850,0.979008,-434.223053,0.098014,0.000000
70.430000,59.209084,-434.223053,-0.000686,0.003854,0.097893,263.375153,13.416970,0.978925,-434.223053,0.098014,0.000000
70.670006,58.545143,-434.312012,-0.000716,0.003854,0.097893,260.421814,13.266520,0.978925,-434.312012,0.098014,0.000000
70.910004,57.932220,-434.312012,-0.000694,0.003854,0.097893,257.695374,13.127628,0.978925,-434.312012,0.098014,0.000000
71.150002,57.360626,-434.312012,-0.000694,0.003854,0.097893,255.152802,12.998103,0.978925,-434.312012,0.098014,0.000000
71.390007,56.849358,-434.356476,-0.000681,0.003854,0.097893,252.878571,12.882248,0.978925,-434.356476,0.098014,0.000000
71.630005,56.357826,-434.356476,-0.000703,0.003854,0.097893,250.692139,12.770866,0.978925,-434.356476,0.098014,0.000000
71.870003,55.891991,-434.356476,-0.000698,0.003854,0.097893,248.619995,12.665306,0.978925,-434.356476,0.098014,0.000000
72.110001,55.470459,-434.356476,-0.000703,0.003854,0.097883,246.744919,12.569786,0.978834,-434.356476,0.098014,0.000000
72.350006,55.066811,-434.356476,-0.000686,0.003854,0.097883,244.949402,12.478318,0.978834,-434.356476,0.098014,0.000000
72.590004,54.705238,-434.445435,-0.000642,0.003854,0.097883,243.341049,12.396384,0.978834,-434.445435,0.098014,0.000000
72.830002,54.357811,-434.400970,-0.000651,0.003854,0.097883,241.795624,12.317657,0.978834,-434.400970,0.098014,0.000000
73.070000,54.029007,-434.400970,-0.000629,0.003854,0.097883,240.333023,12.243148,0.978834,-434.400970,0.098014,0.000000
73.310005,53.733719,-434.356476,-0.000629,0.003854,0.097883,239.019516,12.176234,0.978834,-434.356476,0.098014,0.000000
73.550003,53.437683,-434.489929,-0.000647,0.003854,0.097883,237.702682,12.109153,0.978834,-434.489929,0.098014,0.000000
73.790001,53.165848,-434.489929,-0.000647,0.003854,0.097883,236.493500,12.047554,0.978834,-434.489929,0.098014,0.000000
74.030006,52.901466,-434.534424,-0.000629,0.003854,0.097883,235.317474,11.987643,0.978834,-434.534424,0.098014,0.000000
74.270004,52.665009,-434.534424,-0.000642,0.003854,0.097883,234.265656,11.934062,0.978834,-434.534424,0.098014,0.000000
74.510002,52.416267,-434.489929,-0.000660,0.003854,0.097883,233.159195,11.877695,0.978834,-434.489929,0.098014,0.000000
74.750000,52.204758,-434.534424,-0.000651,0.003854,0.097883,232.218353,11.829767,0.978834,-434.534424,0.098014,0.000000
74.990005,51.989151,-434.489929,-0.000621,0.003854,0.097883,231.259293,11.780910,0.978834,-434.489929,0.098014,0.000000
75.230003,51.792915,-434.534424,-0.000612,0.003854,0.097883,230.386398,11.736443,0.978834,-434.534424,0.098014,0.000000
75.470001,51.598160,-434.578888,-0.000608,0.003854,0.097883,229.520081,11.692310,0.978834,-434.578888,0.098014,0.000000
75.710007,51.424637,-434.578888,-0.000629,0.003854,0.097883,228.748215,11.652989,0.978834,-434.578888,0.098014,0.000000
75.950005,51.255577,-434.623383,-0.000638,0.003854,0.097883,227.996201,11.614679,0.978834,-434.623383,0.098014,0.000000
76.190002,51.074982,-434.623383,-0.000591,0.003854,0.097883,227.192871,11.573756,0.978834,-434.623383,0.098014,0.000000
76.430000,50.913742,-434.578888,-0.000638,0.003854,0.097883,226.475632,11.537219,0.978834,-434.578888,0.098014,0.000000
76.670006,50.748779,-434.623383,-0.000617,0.003854,0.097883,225.741852,11.499838,0.978834,-434.623383,0.098014,0.000000
76.910004,50.615097,-434.534424,-0.000638,0.003854,0.097883,225.147202,11.469544,0.978834,-434.534424,0.098014,0.000000
77.150002,50.457214,-434.712341,-0.000595,0.003854,0.097883,224.444901,11.433768,0.978834,-434.712341,0.098014,0.000000
77.390007,50.331726,-434.712341,-0.000617,0.003854,0.097883,223.886703,11.405333,0.978834,-434.712341,0.098014,0.000000
77.630005,50.193199,-434.623383,-0.000582,0.003854,0.097883,223.270508,11.373941,0.978834,-434.623383,0.098014,0.000000
77.870003,50.058777,-434.712341,-0.000591,0.003854,0.097883,222.672562,11.343481,0.978834,-434.712341,0.098014,0.000000
78.110001,49.938126,-434.667847,-0.000608,0.003854,0.097883,222.135880,11.316141,0.978834,-434.667847,0.098014,0.000000
78.350006,49.830879,-434.845764,-0.000582,0.003854,0.097883,221.658829,11.291839,0.978834,-434.845764,0.098014,0.000000
78.590004,49.704277,-434.756805,-0.000591,0.003854,0.097883,221.095673,11.263150,0.978834,-434.756805,0.098014,0.000000
78.830002,49.602615,-434.756805,-0.000612,0.003854,0.097883,220.643448,11.240113,0.978834,-434.756805,0.098014,0.000000
79.070007,49.494255,-434.756805,-0.000578,0.003854,0.097883,220.161438,11.215559,0.978834,-434.756805,0.098014,0.000000
79.310005,49.385521,-434.756805,-0.000595,0.003854,0.097883,219.677765,11.190919,0.978834,-434.756805,0.098014,0.000000
79.550003,49.271210,-434.801300,-0.000599,0.003854,0.097883,219.169281,11.165015,0.978834,-434.801300,0.098014,0.000000
79.790001,49.177368,-434.756805,-0.000578,0.003854,0.097883,218.751862,11.143751,0.978834,-434.756805,0.098014,0.000000
80.030006,49.080925,-434.845764,-0.000617,0.003854,0.097883,218.322861,11.121897,0.978834,-434.845764,0.098014,0.000000
80.270004,48.984848,-434.845764,-0.000586,0.003854,0.097883,217.895493,11.100125,0.978834,-434.845764,0.098014,0.000000
80.510002,48.883942,-434.845764,-0.000608,0.003854,0.097883,217.446640,11.077259,0.978834,-434.845764,0.098014,0.000000
80.750008,48.798294,-434.890259,-0.000582,0.003854,0.097883,217.065659,11.057852,0.978834,-434.890259,0.098014,0.000000
80.990005,48.702217,-434.845764,-0.000565,0.003854,0.097883,216.638275,11.036080,0.978834,-434.845764,0.098014,0.000000
81.230003,48.631470,-434.890259,-0.000595,0.003854,0.097883,216.323578,11.020049,0.978834,-434.890259,0.098014,0.000000
81.470001,48.539124,-434.934753,-0.000599,0.003854,0.097883,215.912811,10.999123,0.978834,-434.934753,0.098014,0.000000
81.710007,48.465767,-434.890259,-0.000608,0.003854,0.097883,215.586502,10.982500,0.978834,-434.890259,0.098014,0.000000
81.950005,48.383095,-434.934753,-0.000578,0.003854,0.097883,215.218750,10.963766,0.978834,-434.934753,0.098014,0.000000
82.190002,48.316818,-434.890259,-0.000586,0.003854,0.097883,214.923935,10.948748,0.978834,-434.890259,0.098014,0.000000
82.430000,48.234894,-434.979218,-0.000578,0.003854,0.097883,214.559525,10.930183,0.978834,-434.979218,0.098014,0.000000
82.670006,48.176056,-434.934753,-0.000582,0.003854,0.097883,214.297806,10.916850,0.978834,-434.934753,0.098014,0.000000
82.910004,48.089668,-434.934753,-0.000595,0.003854,0.097883,213.913528,10.897274,0.978834,-434.934753,0.098014,0.000000
83.150002,48.034187,-435.023712,-0.000586,0.003854,0.097883,213.666733,10.884703,0.978834,-435.023712,0.098014,0.000000
83.390007,47.961945,-435.023712,-0.000565,0.003854,0.097883,213.345383,10.868332,0.978834,-435.023712,0.098014,0.000000
83.630005,47.906090,-435.023712,-0.000595,0.003854,0.097883,213.096924,10.855675,0.978834,-435.023712,0.098014,0.000000
83.870003,47.820068,-434.979218,-0.000591,0.003854,0.097883,212.714294,10.836182,0.978834,-434.979218,0.098014,0.000000
84.110001,47.767563,-434.979218,-0.000573,0.003854,0.097883,212.480728,10.824285,0.978834,-434.979218,0.098014,0.000000
84.350006,47.697929,-435.068176,-0.000612,0.003854,0.097883,212.170990,10.808506,0.978834,-435.068176,0.098014,0.000000
84.590004,47.645058,-435.023712,-0.000578,0.003854,0.097883,211.935806,10.796525,0.978834,-435.023712,0.098014,0.000000
84.830002,47.578773,-435.068176,-0.000617,0.003854,0.097883,211.640961,10.781505,0.978834,-435.068176,0.098014,0.000000
85.070007,47.532974,-435.068176,-0.000608,0.003854,0.097883,211.437225,10.771126,0.978834,-435.068176,0.098014,0.000000
85.310005,47.457008,-435.112671,-0.000569,0.003854,0.097883,211.099319,10.753912,0.978834,-435.112671,0.098014,0.000000
85.550003,47.411949,-435.157135,-0.000586,0.003854,0.097883,210.898880,10.743701,0.978834,-435.157135,0.098014,0.000000
85.790001,47.355721,-435.157135,-0.000565,0.003854,0.097883,210.648758,10.730960,0.978834,-435.157135,0.098014,0.000000
86.030006,47.296890,-435.157135,-0.000612,0.003854,0.097883,210.387070,10.717628,0.978834,-435.157135,0.098014,0.000000
86.270004,47.246986,-435.157135,-0.000591,0.003854,0.097883,210.165085,10.706320,0.978834,-435.157135,0.098014,0.000000
86.510002,47.186668,-435.157135,-0.000560,0.003854,0.097883,209.896790,10.692653,0.978834,-435.157135,0.098014,0.000000
86.750008,47.136024,-435.201630,-0.000586,0.003854,0.097883,209.671509,10.681176,0.978834,-435.201630,0.098014,0.000000
86.990005,47.095062,-435.112671,-0.000582,0.003854,0.097883,209.489304,10.671893,0.978834,-435.112671,0.098014,0.000000
87.230003,47.049263,-435.201630,-0.000586,0.003854,0.097883,209.285568,10.661515,0.978834,-435.201630,0.098014,0.000000
87.470001,47.007553,-435.157135,-0.000565,0.003854,0.097883,209.100037,10.652063,0.978834,-435.157135,0.098014,0.000000
87.710007,46.942017,-435.201630,-0.000578,0.003854,0.097883,208.808517,10.637213,0.978834,-435.201630,0.098014,0.000000
87.950005,46.892494,-435.201630,-0.000578,0.003854,0.097883,208.588226,10.625991,0.978834,-435.201630,0.098014,0.000000
88.190002,46.845573,-435.157135,-0.000582,0.003854,0.097883,208.379517,10.615358,0.978834,-435.157135,0.098014,0.000000
88.430008,46.796417,-435.246094,-0.000582,0.003854,0.097883,208.160858,10.604219,0.978834,-435.246094,0.098014,0.000000
88.670006,46.758438,-435.290588,-0.000569,0.003854,0.097883,207.991928,10.595613,0.978834,-435.290588,0.098014,0.000000
88.910004,46.710403,-435.290588,-0.000586,0.003854,0.097883,207.778259,10.584729,0.978834,-435.290588,0.098014,0.000000
89.150002,46.666092,-435.290588,-0.000552,0.003854,0.097883,207.581146,10.574687,0.978834,-435.290588,0.098014,0.000000
89.390007,46.620659,-435.246094,-0.000582,0.003854,0.097883,207.379044,10.564392,0.978834,-435.246094,0.098014,0.000000
89.630005,46.572250,-435.290588,-0.000591,0.003854,0.097883,207.163712,10.553423,0.978834,-435.290588,0.098014,0.000000
89.870003,46.527565,-435.290588,-0.000548,0.003854,0.097883,206.964951,10.543297,0.978834,-435.290588,0.098014,0.000000
90.110001,46.477669,-435.379547,-0.000573,0.003854,0.097883,206.742996,10.531991,0.978834,-435.379547,0.098014,0.000000
90.350006,46.446762,-435.335083,-0.000595,0.003854,0.097883,206.605515,10.524986,0.978834,-435.335083,0.098014,0.000000
90.590004,46.400963,-435.290588,-0.000552,0.003854,0.097883,206.401794,10.514608,0.978834,-435.290588,0.098014,0.000000
90.830002,46.356277,-435.468506,-0.000543,0.003854,0.097883,206.203018,10.504483,0.978834,-435.468506,0.098014,0.000000
91.070007,46.314941,-435.335083,-0.000591,0.003854,0.097883,206.019150,10.495116,0.978834,-435.335083,0.098014,0.000000
91.310005,46.264297,-435.290588,-0.000569,0.003854,0.097883,205.793869,10.483640,0.978834,-435.290588,0.098014,0.000000
91.550003,46.237114,-435.379547,-0.000573,0.003854,0.097883,205.672958,10.477479,0.978834,-435.379547,0.098014,0.000000
91.790001,46.198387,-435.424042,-0.000586,0.003854,0.097883,205.500687,10.468704,0.978834,-435.424042,0.098014,0.000000
92.030006,46.165993,-435.468506,-0.000552,0.003854,0.097883,205.356598,10.461364,0.978834,-435.468506,0.098014,0.000000
92.270004,46.117584,-435.424042,-0.000578,0.003854,0.097883,205.141266,10.450394,0.978834,-435.424042,0.098014,0.000000
92.510002,46.091888,-435.468506,-0.000552,0.003854,0.097883,205.026962,10.444571,0.978834,-435.468506,0.098014,0.000000
92.750008,46.050560,-435.513000,-0.000556,0.003854,0.097883,204.843124,10.435205,0.978834,-435.513000,0.098014,0.000000
92.990005,46.018906,-435.424042,-0.000560,0.003854,0.097883,204.702316,10.428033,0.978834,-435.424042,0.098014,0.000000
93.230003,45.990608,-435.468506,-0.000522,0.003854,0.097883,204.576447,10.421620,0.978834,-435.468506,0.098014,0.000000
93.470001,45.954109,-435.468506,-0.000552,0.003854,0.097883,204.414093,10.413350,0.978834,-435.468506,0.098014,0.000000
93.710007,45.914642,-435.513000,-0.000565,0.003854,0.097883,204.238525,10.404407,0.978834,-435.513000,0.098014,0.000000
93.950005,45.890808,-435.513000,-0.000565,0.003854,0.097883,204.132507,10.399006,0.978834,-435.513000,0.098014,0.000000
94.190002,45.844261,-435.513000,-0.000573,0.003854,0.097883,203.925461,10.388458,0.978834,-435.513000,0.098014,0.000000
94.430008,45.819687,-435.557465,-0.000569,0.003854,0.097883,203.816147,10.382890,0.978834,-435.557465,0.098014,0.000000
94.670006,45.779472,-435.557465,-0.000565,0.003854,0.097883,203.637268,10.373776,0.978834,-435.557465,0.098014,0.000000
94.910004,45.754150,-435.646423,-0.000569,0.003854,0.097883,203.524628,10.368039,0.978834,-435.646423,0.098014,0.000000
95.150002,45.723610,-435.601959,-0.000552,0.003854,0.097883,203.388779,10.361117,0.978834,-435.601959,0.098014,0.000000
95.390007,45.699409,-435.601959,-0.000569,0.003854,0.097883,203.281128,10.355635,0.978834,-435.601959,0.098014,0.000000
95.630005,45.644295,-435.690918,-0.000552,0.003854,0.097883,203.035965,10.343145,0.978834,-435.690918,0.098014,0.000000
95.870003,45.620842,-435.557465,-0.000565,0.003854,0.097883,202.931641,10.337831,0.978834,-435.557465,0.098014,0.000000
96.110008,45.594025,-435.690918,-0.000560,0.003854,0.097883,202.812347,10.331754,0.978834,-435.690918,0.098014,0.000000
96.350006,45.563118,-435.646423,-0.000569,0.003854,0.097883,202.674866,10.324750,0.978834,-435.646423,0.098014,0.000000
96.590004,45.534821,-435.690918,-0.000569,0.003854,0.097883,202.548996,10.318337,0.978834,-435.690918,0.098014,0.000000
96.830002,45.503166,-435.735382,-0.000595,0.003854,0.097883,202.408188,10.311165,0.978834,-435.735382,0.098014,0.000000
97.070007,45.481941,-435.601959,-0.000543,0.003854,0.097883,202.313782,10.306355,0.978834,-435.601959,0.098014,0.000000
97.310005,45.455132,-435.735382,-0.000573,0.003854,0.097883,202.194519,10.300280,0.978834,-435.735382,0.098014,0.000000
97.550003,45.422363,-435.735382,-0.000552,0.003854,0.097883,202.048767,10.292854,0.978834,-435.735382,0.098014,0.000000
97.790001,45.382896,-435.690918,-0.000560,0.003854,0.097883,201.873199,10.283911,0.978834,-435.690918,0.098014,0.000000
98.030006,45.351982,-435.779877,-0.000573,0.003854,0.097883,201.735687,10.276906,0.978834,-435.779877,0.098014,0.000000
98.270004,45.342300,-435.735382,-0.000560,0.003854,0.097883,201.692627,10.274713,0.978834,-435.735382,0.098014,0.000000
98.510002,45.306183,-435.779877,-0.000552,0.003854,0.097883,201.531967,10.266528,0.978834,-435.779877,0.098014,0.000000
98.750008,45.287941,-435.824371,-0.000539,0.003854,0.097883,201.450821,10.262395,0.978834,-435.824371,0.098014,0.000000
98.900002,45.285332,-435.779877,-0.000560,0.003854,0.097883,201.439209,10.261803,0.978834,-435.779877,0.098014,0.000000