File: Data/compression 14/AutoNoHeating-12-14-2-240726_07262024_164102.csv
Time (sec),S:Load (lbs),S:HL1 (DIM),S:LVDT (in),S:Position (in),Ch:Position (mm),Ch:Load (N),Ch:Stress (MPa),Ch:Strain (mm/mm),Ch:HL1 (DIM),Set Point (),Cycles ()
0.110000,-0.019737,-365.455505,-0.005812,-0.005565,-0.141341,-0.087796,-0.004473,-1.413409,-365.455505,-0.141090,0.000000
0.340000,-0.005585,-365.544464,-0.005821,-0.005565,-0.141341,-0.024842,-0.001266,-1.413409,-365.544464,-0.141090,0.000000
0.570000,-0.010803,-365.544464,-0.005816,-0.005485,-0.139311,-0.048055,-0.002448,-1.393114,-365.544464,-0.138574,0.000000
0.800000,0.011917,-365.633423,-0.005808,-0.005356,-0.136042,0.053010,0.002700,-1.360420,-365.633423,-0.134742,0.000000
1.030000,0.029045,-365.588928,-0.005631,-0.005199,-0.132044,0.129199,0.006582,-1.320444,-365.588928,-0.130926,0.000000
1.260000,0.056602,-365.633423,-0.005489,-0.005051,-0.128289,0.251780,0.012826,-1.282890,-365.633423,-0.127092,0.000000
1.490000,0.045799,-365.588928,-0.005351,-0.004905,-0.124586,0.203725,0.010378,-1.245859,-365.588928,-0.123259,0.000000
1.720000,0.040962,-365.633423,-0.005178,-0.004741,-0.120415,0.182209,0.009282,-1.204149,-365.633423,-0.119426,0.000000
1.950000,0.005959,-365.677887,-0.005001,-0.004592,-0.116634,0.026505,0.001350,-1.166338,-365.677887,-0.115593,0.000000
2.180000,0.021225,-365.677887,-0.004859,-0.004448,-0.112974,0.094413,0.004810,-1.129738,-365.677887,-0.111760,0.000000
2.410000,0.120277,-365.677887,-0.004691,-0.004297,-0.109150,0.535021,0.027255,-1.091496,-365.677887,-0.107926,0.000000
2.640000,0.592072,-365.677887,-0.004562,-0.004155,-0.105524,2.633666,0.134165,-1.055244,-365.677887,-0.104094,0.000000
2.870000,0.701180,-365.722382,-0.004514,-0.000000,-0.000009,3.119002,0.158890,-0.000091,-365.722382,0.000052,0.000000
3.100000,0.675484,-365.722382,-0.004514,-0.000001,-0.000017,3.004702,0.153067,-0.000174,-365.722382,0.000052,0.000000
3.330000,0.672874,-365.722382,-0.004557,-0.000001,-0.000017,2.993095,0.152476,-0.000174,-365.722382,0.000251,0.000000
3.560000,0.679955,-365.722382,-0.004531,-0.000001,-0.000017,3.024589,0.154080,-0.000174,-365.722382,0.000633,0.000000
3.790000,0.640480,-365.722382,-0.004523,-0.000000,-0.000000,2.848998,0.145135,-0.000000,-365.722382,0.001014,0.000000
4.020000,0.875816,-365.811340,-0.004501,0.000025,0.000625,3.895826,0.198463,0.006245,-365.811340,0.001396,0.000000
4.250000,0.999077,-365.855835,-0.004506,0.000035,0.000893,4.444116,0.226394,0.008932,-365.855835,0.001786,0.000000
4.480000,1.081367,-365.855835,-0.004497,0.000047,0.001188,4.810163,0.245041,0.011877,-365.855835,0.002168,0.000000
4.710000,1.221382,-365.811340,-0.004475,0.000062,0.001569,5.432979,0.276769,0.015692,-365.811340,0.002550,0.000000
4.940000,1.386345,-365.855835,-0.004471,0.000078,0.001977,6.166770,0.314150,0.019772,-365.855835,0.002931,0.000000
5.170000,1.607529,-365.900299,-0.004445,0.000092,0.002341,7.150645,0.364271,0.023413,-365.900299,0.003313,0.000000
5.400000,1.771378,-365.900299,-0.004449,0.000104,0.002645,7.879481,0.401400,0.026449,-365.900299,0.003703,0.000000
5.630000,2.061081,-365.900299,-0.004441,0.000126,0.003191,9.168146,0.467048,0.031914,-365.900299,0.004085,0.000000
5.860000,2.248756,-365.855835,-0.004424,0.000142,0.003608,10.002968,0.509575,0.036078,-365.855835,0.004466,0.000000
6.090000,2.444626,-365.944794,-0.004385,0.000158,0.004007,10.874239,0.553960,0.040067,-365.944794,0.004848,0.000000
6.320000,2.482231,-365.944794,-0.004398,0.000165,0.004188,11.041515,0.562482,0.041884,-365.944794,0.005229,0.000000
6.550000,2.709007,-365.989258,-0.004376,0.000180,0.004579,12.050266,0.613870,0.045790,-365.989258,0.005620,0.000000
6.780000,3.024406,-365.989258,-0.004359,0.000199,0.005047,13.453232,0.685340,0.050468,-365.989258,0.006001,0.000000
7.010000,3.295494,-365.944794,-0.004342,0.000216,0.005490,14.659090,0.746770,0.054896,-365.944794,0.006383,0.000000
7.240000,3.419495,-365.944794,-0.004316,0.000227,0.005767,15.210671,0.774869,0.057667,-365.944794,0.006764,0.000000
7.470000,3.641800,-366.033752,-0.004320,0.000242,0.006148,16.199535,0.825244,0.061482,-366.033752,0.007146,0.000000
7.700000,4.011566,-366.078217,-0.004329,0.000263,0.006686,17.844337,0.909034,0.066864,-366.078217,0.007536,0.000000
7.930000,4.237228,-366.122711,-0.004294,0.000278,0.007059,18.848133,0.960170,0.070588,-366.122711,0.007918,0.000000
8.160001,4.427132,-366.033752,-0.004277,0.000291,0.007389,19.692865,1.003202,0.073889,-366.033752,0.008300,0.000000
8.390000,4.488205,-366.122711,-0.004268,0.000301,0.007658,19.964533,1.017042,0.076576,-366.122711,0.008681,0.000000
8.620001,4.800621,-366.033752,-0.004260,0.000316,0.008030,21.354229,1.087836,0.080300,-366.033752,0.009063,0.000000
8.850000,5.221031,-366.167175,-0.004243,0.000334,0.008490,23.224306,1.183103,0.084903,-366.167175,0.009452,0.000000
9.080001,5.487656,-366.167175,-0.004238,0.000351,0.008924,24.410311,1.243520,0.089240,-366.167175,0.009834,0.000000
9.310000,5.465309,-366.122711,-0.004234,0.000358,0.009106,24.310909,1.238457,0.091057,-366.122711,0.010216,0.000000
9.540001,6.145264,-366.122711,-0.004186,0.000384,0.009756,27.335499,1.392537,0.097559,-366.122711,0.010598,0.000000
9.770000,6.246918,-366.122711,-0.004191,0.000400,0.010155,27.787678,1.415572,0.101549,-366.122711,0.010979,0.000000
10.000000,6.402573,-366.167175,-0.004174,0.000413,0.010493,28.480066,1.450844,0.104932,-366.167175,0.011369,0.000000
10.230000,6.534019,-366.167175,-0.004148,0.000426,0.010814,29.064770,1.480630,0.108142,-366.167175,0.011751,0.000000
10.460000,6.846809,-366.167175,-0.004130,0.000442,0.011221,30.456129,1.551509,0.112215,-366.167175,0.012132,0.000000
10.690001,7.117897,-366.167175,-0.004156,0.000458,0.011629,31.661987,1.612939,0.116295,-366.167175,0.012514,0.000000
10.920000,7.264610,-366.211670,-0.004113,0.000471,0.011968,32.314602,1.646184,0.119678,-366.211670,0.012896,0.000000
11.150001,7.465698,-366.300629,-0.004096,0.000483,0.012262,33.209084,1.691751,0.122623,-366.300629,0.013286,0.000000
11.380000,7.670868,-366.256165,-0.004100,0.000496,0.012601,34.121723,1.738243,0.126007,-366.256165,0.013667,0.000000
11.610001,7.938232,-366.256165,-0.004061,0.000513,0.013034,35.311020,1.798829,0.130344,-366.256165,0.014049,0.000000
11.840000,8.345985,-366.300629,-0.004040,0.000533,0.013529,37.124798,1.891227,0.135287,-366.300629,0.014430,0.000000
12.070001,8.418968,-366.300629,-0.004040,0.000545,0.013841,37.449440,1.907765,0.138406,-366.300629,0.014812,0.000000
12.300000,8.720589,-366.389587,-0.004031,0.000564,0.014335,38.791115,1.976114,0.143349,-366.389587,0.015202,0.000000
12.530001,8.768250,-366.389587,-0.004010,0.000573,0.014560,39.003120,1.986914,0.145605,-366.389587,0.015584,0.000000
12.760000,9.078064,-366.345123,-0.004005,0.000592,0.015029,40.381245,2.057119,0.150291,-366.345123,0.015965,0.000000
12.990001,9.394958,-366.389587,-0.003984,0.000606,0.015401,41.790863,2.128928,0.154015,-366.389587,0.016347,0.000000
13.220000,9.287338,-366.389587,-0.003997,0.000613,0.015567,41.312145,2.104541,0.155665,-366.389587,0.016738,0.000000
13.450001,9.496613,-366.434082,-0.003980,0.000625,0.015879,42.243042,2.151963,0.158791,-366.434082,0.017119,0.000000
13.680000,10.510582,-366.434082,-0.003962,0.000657,0.016685,46.753403,2.381732,0.166853,-366.434082,0.017501,0.000000
13.910001,10.296097,-366.434082,-0.003941,0.000667,0.016954,45.799328,2.333129,0.169541,-366.434082,0.017882,0.000000
14.140000,10.509094,-366.434082,-0.003941,0.000684,0.017370,46.746784,2.381395,0.173704,-366.434082,0.018264,0.000000
14.370001,10.697144,-366.478546,-0.003902,0.000700,0.017787,47.583271,2.424007,0.177867,-366.478546,0.018654,0.000000
14.600000,10.930244,-366.478546,-0.003876,0.000716,0.018186,48.620155,2.476829,0.181857,-366.478546,0.019036,0.000000
14.830001,11.078079,-366.478546,-0.003863,0.000730,0.018541,49.277756,2.510329,0.185414,-366.478546,0.019417,0.000000
15.060000,11.057968,-366.523041,-0.003842,0.000740,0.018793,49.188297,2.505771,0.187928,-366.523041,0.019799,0.000000
15.290001,11.485458,-366.478546,-0.003859,0.000759,0.019270,51.089870,2.602642,0.192697,-366.478546,0.020180,0.000000
15.520000,11.975868,-366.567505,-0.003824,0.000779,0.019799,53.271324,2.713771,0.197988,-366.567505,0.020570,0.000000
15.750001,11.890968,-366.612000,-0.003842,0.000790,0.020076,52.893669,2.694532,0.200758,-366.612000,0.020952,0.000000
15.980000,11.998581,-366.478546,-0.003837,0.000804,0.020432,53.372353,2.718917,0.204316,-366.478546,0.021334,0.000000
16.210001,12.289406,-366.612000,-0.003786,0.000821,0.020848,54.666008,2.784819,0.208480,-366.612000,0.021715,0.000000
16.440001,12.525116,-366.612000,-0.003790,0.000836,0.021239,55.714497,2.838232,0.212386,-366.612000,0.022097,0.000000
16.670000,12.648003,-366.612000,-0.003764,0.000850,0.021585,56.261124,2.866078,0.215853,-366.612000,0.022487,0.000000
16.900002,12.665504,-366.612000,-0.003760,0.000861,0.021871,56.338978,2.870044,0.218714,-366.612000,0.022868,0.000000
17.130001,12.867699,-366.700958,-0.003708,0.000875,0.022227,57.238384,2.915862,0.222272,-366.700958,0.023250,0.000000
17.360001,13.559944,-366.656494,-0.003729,0.000897,0.022773,60.317642,3.072727,0.227730,-366.656494,0.023632,0.000000
17.590000,13.703308,-366.656494,-0.003708,0.000914,0.023207,60.955360,3.105214,0.232067,-366.656494,0.024014,0.000000
17.820002,13.592339,-366.745453,-0.003708,0.000924,0.023458,60.461742,3.080068,0.234580,-366.745453,0.024403,0.000000
18.050001,13.937157,-366.745453,-0.003691,0.000942,0.023927,61.995567,3.158205,0.239266,-366.745453,0.024785,0.000000
18.280001,13.895081,-366.745453,-0.003678,0.000953,0.024204,61.808407,3.148670,0.242044,-366.745453,0.025167,0.000000
18.510000,14.224258,-366.700958,-0.003656,0.000969,0.024621,63.272663,3.223263,0.246207,-366.700958,0.025548,0.000000
18.740002,14.359428,-366.745453,-0.003643,0.000982,0.024950,63.873928,3.253893,0.249500,-366.745453,0.025930,0.000000
18.970001,14.416023,-366.700958,-0.003609,0.000996,0.025297,64.125671,3.266717,0.252967,-366.700958,0.026320,0.000000
19.200001,14.564232,-366.789917,-0.003609,0.001006,0.025548,64.784943,3.300302,0.255480,-366.789917,0.026702,0.000000
19.430000,15.518250,-366.878876,-0.003570,0.001036,0.026320,69.028618,3.516486,0.263202,-366.878876,0.027083,0.000000
19.660002,15.388664,-366.834412,-0.003561,0.001049,0.026649,68.452194,3.487121,0.266494,-366.834412,0.027465,0.000000
19.890001,15.296318,-366.834412,-0.003561,0.001061,0.026953,68.041420,3.466195,0.269530,-366.834412,0.027846,0.000000
20.120001,15.450478,-366.834412,-0.003548,0.001074,0.027291,68.727158,3.501128,0.272914,-366.834412,0.028237,0.000000
20.350000,15.735344,-366.834412,-0.003544,0.001089,0.027665,69.994308,3.565680,0.276646,-366.834412,0.028618,0.000000
20.580002,16.283104,-366.923370,-0.003535,0.001110,0.028202,72.430862,3.689804,0.282020,-366.923370,0.029000,0.000000
20.810001,16.006058,-366.878876,-0.003497,0.001117,0.028384,71.198502,3.627025,0.283844,-366.878876,0.029381,0.000000
21.040001,16.659569,-366.878876,-0.003479,0.001141,0.028974,74.105461,3.775112,0.289741,-366.878876,0.029772,0.000000
21.270000,16.744102,-366.923370,-0.003445,0.001156,0.029356,74.481491,3.794268,0.293556,-366.923370,0.030153,0.000000
21.500002,16.833466,-366.967834,-0.003479,0.001170,0.029728,74.878998,3.814518,0.297281,-366.967834,0.030535,0.000000
21.730001,16.795486,-366.923370,-0.003458,0.001182,0.030023,74.710052,3.805912,0.300233,-366.923370,0.030917,0.000000
21.960001,16.798836,-366.967834,-0.003432,0.001195,0.030344,74.724953,3.806671,0.303443,-366.967834,0.031298,0.000000
22.190001,16.913902,-366.967834,-0.003441,0.001208,0.030674,75.236794,3.832745,0.306735,-366.967834,0.031689,0.000000
22.420002,17.562943,-366.967834,-0.003393,0.001226,0.031150,78.123871,3.979820,0.311504,-366.967834,0.032070,0.000000
22.650002,17.539856,-367.056793,-0.003385,0.001237,0.031428,78.021179,3.974588,0.314283,-367.056793,0.032452,0.000000
22.880001,17.412132,-367.056793,-0.003385,0.001248,0.031697,77.453033,3.945646,0.316970,-367.056793,0.032833,0.000000
23.110001,18.484192,-367.056793,-0.003372,0.001276,0.032408,82.221794,4.188578,0.324078,-367.056793,0.033215,0.000000
23.340002,18.579521,-367.012329,-0.003328,0.001289,0.032738,82.645836,4.210180,0.327378,-367.012329,0.033605,0.000000
23.570002,18.573563,-367.101288,-0.003307,0.001303,0.033094,82.619331,4.208829,0.330936,-367.101288,0.033987,0.000000
23.800001,18.152039,-367.145782,-0.003316,0.001311,0.033301,80.744301,4.113311,0.333010,-367.145782,0.034368,0.000000
24.030001,18.687141,-367.145782,-0.003298,0.001328,0.033744,83.124557,4.234567,0.337439,-367.145782,0.034750,0.000000
24.260000,18.842789,-367.101288,-0.003298,0.001344,0.034134,83.816910,4.269837,0.341337,-367.101288,0.035131,0.000000
24.490002,19.135475,-367.145782,-0.003264,0.001359,0.034524,85.118843,4.336161,0.345243,-367.145782,0.035521,0.000000
24.720001,19.003654,-367.056793,-0.003277,0.001369,0.034767,84.532478,4.306290,0.347673,-367.056793,0.035903,0.000000
24.950001,19.812820,-367.190247,-0.003260,0.001393,0.035391,88.131828,4.489649,0.353910,-367.190247,0.036284,0.000000
25.180000,20.223923,-367.190247,-0.003221,0.001411,0.035851,89.960503,4.582806,0.358513,-367.190247,0.036667,0.000000
25.410002,20.247009,-367.101288,-0.003229,0.001428,0.036259,90.063194,4.588038,0.362585,-367.101288,0.037048,0.000000
25.640001,20.098801,-367.234741,-0.003191,0.001438,0.036536,89.403931,4.554453,0.365363,-367.234741,0.037438,0.000000
25.870001,19.991188,-367.234741,-0.003191,0.001449,0.036805,88.925247,4.530068,0.368051,-367.234741,0.037819,0.000000
26.100000,20.161736,-367.234741,-0.003169,0.001463,0.037169,89.683876,4.568715,0.371692,-367.234741,0.038201,0.000000
26.330002,20.846153,-367.323700,-0.003152,0.001486,0.037741,92.728317,4.723806,0.377415,-367.323700,0.038582,0.000000
26.560001,20.869614,-367.234741,-0.003139,0.001496,0.038010,92.832680,4.729122,0.380102,-367.234741,0.038964,0.000000
26.790001,20.956749,-367.234741,-0.003143,0.001509,0.038340,93.220276,4.748867,0.383402,-367.234741,0.039355,0.000000
27.020000,21.597229,-367.279205,-0.003126,0.001531,0.038895,96.069275,4.894002,0.388951,-367.279205,0.039736,0.000000
27.250002,21.685478,-367.323700,-0.003126,0.001546,0.039277,96.461823,4.914000,0.392766,-367.323700,0.040118,0.000000
27.480001,21.660164,-367.323700,-0.003087,0.001558,0.039580,96.349220,4.908263,0.395802,-367.323700,0.040499,0.000000
27.710001,21.456474,-367.412659,-0.003083,0.001570,0.039884,95.443161,4.862107,0.398837,-367.412659,0.040881,0.000000
27.940001,21.790863,-367.279205,-0.003074,0.001584,0.040230,96.930603,4.937880,0.402304,-367.279205,0.041271,0.000000
28.170002,22.372139,-367.323700,-0.003061,0.001604,0.040742,99.516243,5.069599,0.407421,-367.323700,0.041653,0.000000
28.400002,22.485710,-367.457123,-0.003057,0.001618,0.041089,100.021431,5.095335,0.410888,-367.457123,0.042034,0.000000
28.630001,22.522949,-367.368164,-0.003027,0.001631,0.041427,100.187080,5.103773,0.414272,-367.368164,0.042416,0.000000
28.860001,23.109062,-367.412659,-0.003005,0.001652,0.041956,102.794243,5.236588,0.419563,-367.412659,0.042797,0.000000
29.090002,23.338074,-367.368164,-0.002988,0.001669,0.042381,103.812935,5.288483,0.423810,-367.368164,0.043188,0.000000
29.320002,23.181305,-367.457123,-0.002988,0.001680,0.042676,103.115593,5.252959,0.426762,-367.457123,0.043569,0.000000
29.550001,23.108315,-367.546112,-0.002966,0.001692,0.042980,102.790916,5.236419,0.429798,-367.546112,0.043951,0.000000
29.780001,23.355942,-367.546112,-0.002962,0.001709,0.043396,103.892418,5.292532,0.433961,-367.546112,0.044332,0.000000
30.010002,23.476593,-367.546112,-0.002940,0.001721,0.043708,104.429100,5.319872,0.437080,-367.546112,0.044723,0.000000
30.240002,23.691826,-367.501617,-0.002923,0.001736,0.044099,105.386505,5.368645,0.440986,-367.501617,0.045105,0.000000
30.470001,24.155052,-367.546112,-0.002923,0.001753,0.044523,107.447037,5.473613,0.445232,-367.546112,0.045486,0.000000
30.700001,23.982277,-367.546112,-0.002889,0.001763,0.044792,106.678497,5.434462,0.447920,-367.546112,0.045868,0.000000
30.930002,24.937408,-367.635071,-0.002902,0.001788,0.045426,110.927132,5.650898,0.454256,-367.635071,0.046249,0.000000
31.160002,24.954910,-367.590576,-0.002876,0.001803,0.045790,111.004982,5.654863,0.457897,-367.590576,0.046639,0.000000
31.390001,24.928848,-367.546112,-0.002863,0.001816,0.046127,110.889053,5.648958,0.461273,-367.546112,0.047021,0.000000
31.620001,24.777290,-367.590576,-0.002854,0.001829,0.046448,110.214890,5.614614,0.464482,-367.590576,0.047403,0.000000
31.850002,24.952675,-367.635071,-0.002828,0.001843,0.046804,110.995041,5.654357,0.468040,-367.635071,0.047784,0.000000
32.080002,25.413300,-367.679535,-0.002815,0.001861,0.047263,113.043999,5.758736,0.472635,-367.679535,0.048166,0.000000
32.310001,25.500435,-367.635071,-0.002811,0.001874,0.047611,113.431602,5.778481,0.476110,-367.635071,0.048556,0.000000
32.540001,25.390961,-367.635071,-0.002772,0.001886,0.047914,112.944633,5.753674,0.479137,-367.635071,0.048937,0.000000
32.770000,25.505280,-367.635071,-0.002785,0.001899,0.048226,113.453148,5.779579,0.482264,-367.635071,0.049319,0.000000
33.000000,26.175179,-367.724030,-0.002781,0.001920,0.048773,116.433006,5.931380,0.487729,-367.724030,0.049701,0.000000
33.230003,26.445892,-367.724030,-0.002746,0.001935,0.049145,117.637207,5.992725,0.491453,-367.724030,0.050082,0.000000
33.460003,26.512177,-367.679535,-0.002742,0.001952,0.049579,117.932053,6.007745,0.495791,-367.679535,0.050472,0.000000
33.690002,26.704315,-367.724030,-0.002729,0.001965,0.049917,118.786728,6.051284,0.499175,-367.724030,0.050854,0.000000
33.920002,26.498398,-367.768494,-0.002716,0.001980,0.050299,117.870758,6.004622,0.502990,-367.768494,0.051235,0.000000
34.150002,26.720329,-367.768494,-0.002708,0.001992,0.050594,118.857964,6.054913,0.505942,-367.768494,0.051617,0.000000
34.380001,26.868904,-367.857452,-0.002721,0.002007,0.050976,119.518852,6.088581,0.509757,-367.857452,0.051998,0.000000
34.610001,26.594841,-367.768494,-0.002690,0.002015,0.051184,118.299759,6.026477,0.511839,-367.768494,0.052389,0.000000
34.840000,26.563560,-367.901947,-0.002673,0.002030,0.051565,118.160622,6.019389,0.515654,-367.901947,0.052771,0.000000
35.070004,28.200508,-367.857452,-0.002686,0.002058,0.052268,125.442123,6.390326,0.522679,-367.857452,0.053152,0.000000
35.300003,27.894051,-367.812988,-0.002665,0.002069,0.052545,124.078934,6.320882,0.525449,-367.812988,0.053534,0.000000
35.530003,28.182266,-367.857452,-0.002656,0.002087,0.053014,125.360985,6.386193,0.530135,-367.857452,0.053915,0.000000
35.760002,28.228813,-367.812988,-0.002639,0.002102,0.053386,125.568031,6.396740,0.533859,-367.812988,0.054306,0.000000
35.990002,28.466385,-367.857452,-0.002583,0.002119,0.053820,126.624802,6.450575,0.538197,-367.857452,0.054687,0.000000
36.220001,28.308495,-367.901947,-0.002621,0.002131,0.054123,125.922470,6.414796,0.541232,-367.901947,0.055069,0.000000
36.450001,28.008369,-367.946442,-0.002561,0.002143,0.054427,124.587448,6.346787,0.544268,-367.946442,0.055450,0.000000
36.680000,29.022339,-367.946442,-0.002587,0.002166,0.055026,129.097809,6.576556,0.550256,-367.946442,0.055832,0.000000
36.910000,29.227516,-367.990906,-0.002583,0.002182,0.055433,130.010483,6.623050,0.554328,-367.990906,0.056222,0.000000
37.140003,28.826469,-367.990906,-0.002574,0.002192,0.055667,128.226547,6.532172,0.556675,-367.990906,0.056604,0.000000
37.370003,29.017120,-367.990906,-0.002527,0.002209,0.056100,129.074600,6.575374,0.561005,-367.990906,0.056985,0.000000
37.600002,29.078194,-368.035400,-0.002531,0.002222,0.056448,129.346268,6.589213,0.564479,-368.035400,0.057367,0.000000
37.830002,29.289330,-368.035400,-0.002535,0.002239,0.056873,130.285446,6.637057,0.568726,-368.035400,0.057748,0.000000
38.060001,29.289703,-367.990906,-0.002496,0.002251,0.057176,130.287109,6.637142,0.571761,-367.990906,0.058139,0.000000
38.290001,29.118782,-368.035400,-0.002492,0.002264,0.057505,129.526810,6.598410,0.575054,-368.035400,0.058521,0.000000
38.520000,29.499344,-368.035400,-0.002505,0.002280,0.057922,131.219635,6.684647,0.579218,-368.035400,0.058902,0.000000
38.750000,30.192329,-368.124359,-0.002488,0.002302,0.058459,134.302185,6.841680,0.584592,-368.124359,0.059284,0.000000
38.980003,30.213928,-368.124359,-0.002475,0.002316,0.058824,134.398270,6.846574,0.588241,-368.124359,0.059673,0.000000
39.210003,29.975609,-368.079865,-0.002445,0.002328,0.059119,133.338165,6.792570,0.591185,-368.079865,0.060055,0.000000
39.440002,29.986412,-368.079865,-0.002453,0.002342,0.059483,133.386215,6.795018,0.594827,-368.079865,0.060437,0.000000
39.670002,29.784210,-368.124359,-0.002458,0.002357,0.059856,132.486786,6.749199,0.598558,-368.124359,0.060819,0.000000
39.900002,30.157700,-368.168823,-0.002423,0.002372,0.060237,134.148148,6.833832,0.602374,-368.168823,0.061200,0.000000
40.130001,30.375168,-368.213318,-0.002453,0.002387,0.060619,135.115494,6.883111,0.606189,-368.213318,0.061590,0.000000
40.360001,30.098495,-368.213318,-0.002445,0.002396,0.060853,133.884796,6.820416,0.608528,-368.213318,0.061972,0.000000
40.590000,30.669342,-368.168823,-0.002384,0.002417,0.061391,136.424042,6.949772,0.613910,-368.168823,0.062353,0.000000
40.820004,31.522446,-368.168823,-0.002384,0.002439,0.061954,140.218842,7.143088,0.619542,-368.168823,0.062735,0.000000
41.050003,31.121399,-368.302277,-0.002432,0.002451,0.062258,138.434891,7.052210,0.622577,-368.302277,0.063117,0.000000
41.280003,30.703224,-368.346741,-0.002376,0.002462,0.062536,136.574768,6.957450,0.625355,-368.346741,0.063507,0.000000
41.510002,30.750519,-368.257782,-0.002393,0.002476,0.062900,136.785141,6.968167,0.628997,-368.257782,0.063888,0.000000
41.740002,30.997772,-368.302277,-0.002350,0.002492,0.063290,137.884979,7.024196,0.632903,-368.302277,0.064270,0.000000
41.970001,31.636765,-368.302277,-0.002354,0.002512,0.063793,140.727356,7.168993,0.637929,-368.302277,0.064651,0.000000
42.200001,31.140022,-368.302277,-0.002371,0.002522,0.064053,138.517731,7.056430,0.640533,-368.302277,0.065033,0.000000
42.430000,31.941360,-368.435730,-0.002315,0.002543,0.064600,142.082260,7.238016,0.645998,-368.435730,0.065423,0.000000
42.660004,32.047119,-368.302277,-0.002324,0.002560,0.065024,142.552704,7.261981,0.650245,-368.302277,0.065805,0.000000
42.890003,32.044510,-368.346741,-0.002315,0.002574,0.065389,142.541092,7.261390,0.653886,-368.346741,0.066186,0.000000
43.120003,31.593941,-368.346741,-0.002320,0.002584,0.065623,140.536865,7.159289,0.656225,-368.346741,0.066568,0.000000
43.350002,31.489304,-368.346741,-0.002276,0.002595,0.065909,140.071411,7.135578,0.659094,-368.346741,0.066949,0.000000
43.580002,31.962959,-368.480194,-0.002289,0.002616,0.066455,142.178345,7.242910,0.664552,-368.480194,0.067340,0.000000
43.810001,32.381508,-368.435730,-0.002307,0.002629,0.066785,144.040146,7.337754,0.667852,-368.435730,0.067722,0.000000
44.040001,32.055313,-368.391235,-0.002285,0.002639,0.067019,142.589157,7.263838,0.670191,-368.391235,0.068103,0.000000
44.270000,32.111542,-368.435730,-0.002272,0.002653,0.067375,142.839279,7.276579,0.673749,-368.435730,0.068485,0.000000
44.500004,33.400688,-368.480194,-0.002242,0.002677,0.067999,148.573685,7.568704,0.679994,-368.480194,0.068866,0.000000
44.730003,33.475166,-368.524689,-0.002242,0.002691,0.068346,148.904984,7.585581,0.683461,-368.524689,0.069257,0.000000
44.960003,33.383194,-368.480194,-0.002255,0.002704,0.068675,148.495865,7.564740,0.686754,-368.480194,0.069638,0.000000
45.190002,33.323235,-368.346741,-0.002225,0.002716,0.068988,148.229156,7.551153,0.689880,-368.346741,0.070020,0.000000
45.420002,33.335899,-368.524689,-0.002242,0.002728,0.069292,148.285492,7.554023,0.692916,-368.524689,0.070401,0.000000
45.650002,33.813652,-368.524689,-0.002229,0.002746,0.069751,150.410629,7.662283,0.697511,-368.524689,0.070783,0.000000
45.880001,33.989410,-368.613647,-0.002186,0.002759,0.070080,151.192444,7.702111,0.700804,-368.613647,0.071173,0.000000
46.110001,34.175972,-368.569153,-0.002208,0.002774,0.070471,152.022308,7.744386,0.704710,-368.569153,0.071555,0.000000
46.340004,35.385437,-368.524689,-0.002186,0.002799,0.071095,157.402283,8.018455,0.710947,-368.524689,0.071936,0.000000
46.570004,35.545181,-368.613647,-0.002169,0.002815,0.071503,158.112869,8.054653,0.715027,-368.613647,0.072318,0.000000
46.800003,35.565666,-368.569153,-0.002156,0.002829,0.071867,158.203979,8.059295,0.718668,-368.569153,0.072700,0.000000
47.030003,35.184731,-368.658112,-0.002130,0.002839,0.072110,156.509491,7.972974,0.721098,-368.658112,0.073089,0.000000
47.260002,35.298302,-368.658112,-0.002147,0.002854,0.072482,157.014694,7.998710,0.724823,-368.658112,0.073472,0.000000
47.490002,35.294205,-368.613647,-0.002139,0.002868,0.072847,156.996460,7.997781,0.728471,-368.613647,0.073853,0.000000
47.720001,36.177849,-368.613647,-0.002095,0.002886,0.073315,160.927109,8.198018,0.733149,-368.613647,0.074235,0.000000
47.950001,36.232582,-368.658112,-0.002087,0.002901,0.073688,161.170578,8.210421,0.736881,-368.658112,0.074625,0.000000
48.180004,36.036346,-368.791565,-0.002100,0.002913,0.073983,160.297668,8.165953,0.739826,-368.791565,0.075006,0.000000
48.410004,36.904343,-368.747070,-0.002082,0.002933,0.074494,164.158722,8.362643,0.744943,-368.747070,0.075388,0.000000
48.640003,37.184738,-368.747070,-0.002057,0.002950,0.074928,165.405975,8.426182,0.749281,-368.747070,0.075769,0.000000
48.870003,36.875671,-368.747070,-0.002061,0.002959,0.075163,164.031174,8.356147,0.751627,-368.747070,0.076151,0.000000
49.100002,36.921844,-368.747070,-0.002031,0.002973,0.075509,164.236572,8.366610,0.755094,-368.747070,0.076541,0.000000
49.330002,36.973236,-368.836060,-0.002044,0.002985,0.075813,164.465164,8.378255,0.758130,-368.836060,0.076923,0.000000
49.560001,37.764526,-368.791565,-0.002022,0.003006,0.076342,167.985001,8.557564,0.763421,-368.791565,0.077304,0.000000
49.790001,37.784264,-368.747070,-0.001996,0.003019,0.076671,168.072800,8.562037,0.766714,-368.747070,0.077686,0.000000
50.020004,37.681114,-368.791565,-0.002005,0.003030,0.076966,167.613968,8.538663,0.769658,-368.791565,0.078067,0.000000
50.250004,38.858185,-368.836060,-0.001962,0.003056,0.077617,172.849838,8.805390,0.776168,-368.836060,0.078458,0.000000
50.480003,38.952766,-368.880524,-0.001932,0.003071,0.077998,173.270554,8.826823,0.779984,-368.880524,0.078839,0.000000
50.710003,38.780357,-368.880524,-0.001923,0.003083,0.078310,172.503647,8.787754,0.783102,-368.880524,0.079221,0.000000
50.940002,38.462349,-368.836060,-0.001888,0.003095,0.078614,171.089066,8.715693,0.786138,-368.836060,0.079602,0.000000
51.170002,38.631409,-368.880524,-0.001893,0.003107,0.078926,171.841095,8.754003,0.789264,-368.880524,0.079984,0.000000
51.400002,38.973991,-368.880524,-0.001901,0.003124,0.079351,173.364975,8.831634,0.793511,-368.880524,0.080375,0.000000
51.630001,38.949783,-368.969482,-0.001854,0.003136,0.079663,173.257294,8.826147,0.796630,-368.969482,0.080756,0.000000
51.860001,39.315453,-368.925018,-0.001845,0.003152,0.080054,174.883865,8.909008,0.800536,-368.925018,0.081138,0.000000
52.090004,39.200020,-369.013977,-0.001824,0.003165,0.080400,174.370392,8.882852,0.804003,-369.013977,0.081519,0.000000
52.320004,40.690628,-368.969482,-0.001832,0.003191,0.081050,181.000946,9.220629,0.810505,-368.969482,0.081901,0.000000
52.550003,40.650040,-369.013977,-0.001772,0.003205,0.081406,180.820404,9.211431,0.814063,-369.013977,0.082291,0.000000
52.780003,40.343948,-369.013977,-0.001763,0.003215,0.081667,179.458847,9.142070,0.816667,-369.013977,0.082673,0.000000
53.010002,40.217712,-369.058441,-0.001776,0.003229,0.082013,178.897324,9.113464,0.820134,-369.058441,0.083054,0.000000
53.240002,40.304474,-369.013977,-0.001759,0.003244,0.082404,179.283249,9.133124,0.824040,-369.013977,0.083436,0.000000
53.470001,40.961342,-369.058441,-0.001729,0.003264,0.082898,182.205154,9.281972,0.828983,-369.058441,0.083817,0.000000
53.700001,41.109177,-369.013977,-0.001716,0.003277,0.083236,182.862747,9.315473,0.832359,-369.013977,0.084208,0.000000
53.930004,40.812767,-369.102936,-0.001686,0.003286,0.083453,181.544250,9.248305,0.834531,-369.102936,0.084589,0.000000
54.160004,41.006401,-369.102936,-0.001686,0.003302,0.083860,182.405579,9.292184,0.838604,-369.102936,0.084971,0.000000
54.390003,41.973076,-369.058441,-0.001643,0.003324,0.084424,186.705566,9.511235,0.844244,-369.058441,0.085352,0.000000
54.620003,41.958183,-369.147400,-0.001638,0.003336,0.084736,186.639328,9.507860,0.847362,-369.147400,0.085734,0.000000
54.850002,42.346565,-369.058441,-0.001613,0.003352,0.085135,188.366928,9.595868,0.851352,-369.058441,0.086124,0.000000
55.080002,42.397209,-369.102936,-0.001582,0.003364,0.085448,188.592209,9.607346,0.854478,-369.102936,0.086505,0.000000
55.310001,42.636276,-369.191895,-0.001600,0.003380,0.085847,189.655624,9.661518,0.858467,-369.191895,0.086888,0.000000
55.540001,43.000824,-369.191895,-0.001578,0.003396,0.086254,191.277222,9.744126,0.862540,-369.191895,0.087269,0.000000
55.770004,42.941994,-369.147400,-0.001544,0.003408,0.086558,191.015533,9.730794,0.865575,-369.147400,0.087659,0.000000
56.000004,42.712608,-369.191895,-0.001556,0.003419,0.086853,189.995178,9.678815,0.868527,-369.191895,0.088040,0.000000
56.230003,43.839409,-369.280853,-0.001526,0.003443,0.087460,195.007431,9.934152,0.874598,-369.280853,0.088422,0.000000
56.460003,44.588997,-369.236389,-0.001509,0.003458,0.087824,198.341766,10.104011,0.878239,-369.236389,0.088803,0.000000
56.690002,44.784492,-369.236389,-0.001505,0.003475,0.088258,199.211365,10.148311,0.882577,-369.236389,0.089186,0.000000
56.920002,45.357574,-369.280853,-0.001483,0.003491,0.088674,201.760574,10.278173,0.886740,-369.280853,0.089576,0.000000
57.150002,45.698296,-369.236389,-0.001453,0.003506,0.089064,203.276169,10.355382,0.890639,-369.236389,0.089957,0.000000
57.380001,46.185730,-369.325348,-0.001479,0.003523,0.089480,205.444382,10.465837,0.894802,-369.325348,0.090339,0.000000
57.610004,46.146629,-369.369812,-0.001449,0.003532,0.089723,205.270462,10.456976,0.897232,-369.369812,0.090720,0.000000
57.840004,46.198013,-369.280853,-0.001431,0.003544,0.090009,205.499023,10.468619,0.900093,-369.280853,0.091102,0.000000
58.070004,47.554199,-369.280853,-0.001431,0.003569,0.090642,211.531647,10.775936,0.906422,-369.280853,0.091492,0.000000
58.300003,48.073654,-369.369812,-0.001371,0.003583,0.091006,213.842300,10.893645,0.910063,-369.369812,0.091874,0.000000
58.530003,48.024872,-369.325348,-0.001375,0.003595,0.091302,213.625305,10.882592,0.913015,-369.325348,0.092255,0.000000
58.760002,48.551781,-369.414307,-0.001375,0.003609,0.091666,215.969101,11.001991,0.916656,-369.414307,0.092637,0.000000
58.990002,49.131935,-369.325348,-0.001350,0.003625,0.092065,218.549759,11.133455,0.920645,-369.325348,0.093018,0.000000
59.220001,49.859558,-369.325348,-0.001341,0.003641,0.092489,221.786392,11.298338,0.924892,-369.325348,0.093409,0.000000
59.450005,50.292252,-369.369812,-0.001324,0.003654,0.092802,223.711105,11.396387,0.928018,-369.369812,0.093790,0.000000
59.680004,50.367096,-369.414307,-0.001311,0.003662,0.093018,224.044037,11.413346,0.930183,-369.414307,0.094172,0.000000
59.910004,51.728119,-369.458771,-0.001337,0.003687,0.093643,230.098160,11.721760,0.936428,-369.458771,0.094553,0.000000
60.140003,52.716393,-369.458771,-0.001311,0.003704,0.094085,234.494232,11.945705,0.940849,-369.458771,0.094935,0.000000
60.370003,53.416084,-369.414307,-0.001272,0.003719,0.094458,237.606613,12.104258,0.944581,-369.414307,0.095326,0.000000
60.600002,53.545670,-369.503265,-0.001272,0.003730,0.094753,238.183029,12.133622,0.947533,-369.503265,0.095707,0.000000
60.830002,54.052094,-369.503265,-0.001272,0.003743,0.095083,240.435715,12.248379,0.950826,-369.503265,0.096089,0.000000
61.060001,54.828865,-369.547729,-0.001250,0.003758,0.095447,243.890976,12.424398,0.954467,-369.547729,0.096470,0.000000
61.290005,55.575844,-369.503265,-0.001242,0.003772,0.095811,247.213699,12.593666,0.958108,-369.503265,0.096852,0.000000
61.520004,56.265106,-369.547729,-0.001246,0.003786,0.096175,250.279694,12.749855,0.961749,-369.547729,0.097242,0.000000
61.750004,56.836700,-369.547729,-0.001229,0.003802,0.096566,252.822266,12.879380,0.965655,-369.547729,0.097624,0.000000
61.980003,58.229744,-369.636688,-0.001224,0.003823,0.097095,259.018829,13.195048,0.970947,-369.636688,0.098005,0.000000
62.210003,59.530815,-369.592224,-0.001220,0.003840,0.097545,264.806305,13.489876,0.975451,-369.592224,0.098387,0.000000
62.440002,59.919197,-369.592224,-0.001203,0.003852,0.097840,266.533905,13.577885,0.978403,-369.592224,0.098768,0.000000
62.670002,60.349289,-369.592224,-0.001181,0.003866,0.098187,268.447052,13.675344,0.981870,-369.592224,0.099158,0.000000
62.900002,61.081001,-369.592224,-0.001212,0.003877,0.098482,271.701874,13.841153,0.984822,-369.592224,0.099540,0.000000
63.130005,61.938942,-369.681183,-0.001173,0.003895,0.098933,275.518188,14.035565,0.989334,-369.681183,0.099922,0.000000
63.360004,63.307411,-369.636688,-0.001155,0.003912,0.099366,281.605438,14.345665,0.993664,-369.636688,0.100304,0.000000
63.590004,63.792618,-369.636688,-0.001160,0.003925,0.099705,283.763733,14.455614,0.997047,-369.636688,0.100685,0.000000
63.820004,65.335724,-369.681183,-0.001155,0.003946,0.100226,290.627808,14.805286,1.002255,-369.681183,0.101075,0.000000
64.050003,66.381348,-369.725677,-0.001147,0.003962,0.100624,295.278992,15.042229,1.006245,-369.725677,0.101456,0.000000
64.280006,67.150299,-369.770142,-0.001130,0.003975,0.100962,298.699463,15.216475,1.009621,-369.770142,0.101838,0.000000
64.510002,67.562134,-369.770142,-0.001121,0.003979,0.101057,300.531372,15.309798,1.010575,-369.770142,0.101197,0.000000
64.740005,66.803619,-369.725677,-0.001108,0.003976,0.100979,297.157349,15.137917,1.009795,-369.725677,0.101197,0.000000
64.970001,66.230545,-369.770142,-0.001108,0.003975,0.100962,294.608185,15.008057,1.009621,-369.770142,0.100979,0.000000
65.200005,65.694321,-369.814636,-0.001134,0.003975,0.100954,292.222931,14.886546,1.009537,-369.814636,0.100979,0.000000
65.430000,65.235931,-369.770142,-0.001087,0.003975,0.100954,290.183929,14.782673,1.009537,-369.770142,0.100979,0.000000
65.660004,64.829666,-369.814636,-0.001121,0.003974,0.100945,288.376770,14.690613,1.009447,-369.814636,0.100979,0.000000
65.889999,64.461395,-369.814636,-0.001087,0.003974,0.100945,286.738617,14.607162,1.009447,-369.814636,0.100979,0.000000
66.120003,64.144501,-369.814636,-0.001074,0.003974,0.100945,285.328979,14.535352,1.009447,-369.814636,0.100979,0.000000
66.350006,63.851074,-369.859100,-0.001104,0.003974,0.100945,284.023773,14.468861,1.009447,-369.859100,0.100979,0.000000
66.580002,63.583710,-369.903595,-0.001112,0.003974,0.100945,282.834473,14.408275,1.009447,-369.903595,0.100979,0.000000
66.810005,63.339813,-369.948059,-0.001087,0.003974,0.100945,281.749573,14.353006,1.009447,-369.948059,0.100979,0.000000
67.040001,63.120110,-369.948059,-0.001099,0.003974,0.100945,280.772278,14.303222,1.009447,-369.948059,0.100979,0.000000
67.270004,62.912323,-369.859100,-0.001087,0.003974,0.100945,279.847992,14.256136,1.009447,-369.859100,0.100979,0.000000
67.500000,62.719810,-369.948059,-0.001056,0.003974,0.100945,278.991638,14.212513,1.009447,-369.948059,0.100979,0.000000
67.730003,62.556709,-369.992554,-0.001112,0.003974,0.100945,278.266144,14.175552,1.009447,-369.992554,0.100979,0.000000
67.960007,62.378716,-369.948059,-0.001065,0.003974,0.100945,277.474396,14.135219,1.009447,-369.948059,0.100979,0.000000
68.190002,62.220085,-369.948059,-0.001069,0.003974,0.100945,276.768768,14.099273,1.009447,-369.948059,0.100979,0.000000
68.420006,62.093849,-369.948059,-0.001087,0.003974,0.100945,276.207245,14.070667,1.009447,-369.948059,0.100979,0.000000
68.650002,61.967987,-369.992554,-0.001082,0.003974,0.100945,275.647369,14.042147,1.009447,-369.992554,0.100979,0.000000
68.880005,61.814575,-370.126007,-0.001082,0.003974,0.100945,274.964966,14.007383,1.009447,-370.126007,0.100979,0.000000
69.110001,61.694298,-370.081512,-0.001099,0.003974,0.100945,274.429932,13.980128,1.009447,-370.081512,0.100979,0.000000
69.340004,61.573647,-370.081512,-0.001074,0.003974,0.100945,273.893250,13.952787,1.009447,-370.081512,0.100979,0.000000
69.570000,61.465660,-369.992554,-0.001069,0.003974,0.100945,273.412903,13.928317,1.009447,-369.992554,0.100979,0.000000
69.800003,61.371452,-370.126007,-0.001087,0.003974,0.100945,272.993866,13.906969,1.009447,-370.126007,0.100979,0.000000
70.030006,61.276497,-370.170471,-0.001065,0.003974,0.100945,272.571472,13.885452,1.009447,-370.170471,0.100979,0.000000
70.260002,61.170364,-370.126007,-0.001091,0.003974,0.100945,272.099365,13.861403,1.009447,-370.126007,0.100979,0.000000
70.490005,61.082489,-370.126007,-0.001087,0.003974,0.100945,271.708496,13.841490,1.009447,-370.126007,0.100979,0.000000
70.720001,61.005409,-370.126007,-0.001078,0.003974,0.100945,271.365601,13.824023,1.009447,-370.126007,0.100979,0.000000
70.950005,60.927582,-370.170471,-0.001065,0.003974,0.100945,271.019409,13.806387,1.009447,-370.170471,0.100979,0.000000
71.180000,60.829277,-370.259430,-0.001074,0.003974,0.100945,270.582153,13.784111,1.009447,-370.259430,0.100979,0.000000
71.410004,60.754425,-370.214966,-0.001091,0.003974,0.100945,270.249176,13.767149,1.009447,-370.214966,0.100979,0.000000
71.640007,60.689262,-370.170471,-0.001082,0.003974,0.100945,269.959320,13.752383,1.009447,-370.170471,0.100979,0.000000
71.870003,60.620377,-370.259430,-0.001065,0.003974,0.100945,269.652893,13.736773,1.009447,-370.259430,0.100979,0.000000
72.100006,60.547760,-370.259430,-0.001069,0.003974,0.100945,269.329895,13.720318,1.009447,-370.259430,0.100979,0.000000
72.330002,60.482971,-370.259430,-0.001074,0.003974,0.100945,269.041687,13.705638,1.009447,-370.259430,0.100979,0.000000
72.560005,60.404770,-370.259430,-0.001082,0.003974,0.100945,268.693848,13.687917,1.009447,-370.259430,0.100979,0.000000
72.790001,60.349663,-370.214966,-0.001078,0.003974,0.100945,268.448700,13.675429,1.009447,-370.214966,0.100979,0.000000
73.020004,60.294174,-370.303925,-0.001082,0.003974,0.100945,268.201874,13.662855,1.009447,-370.303925,0.100979,0.000000
73.250000,60.228264,-370.348389,-0.001074,0.003974,0.100945,267.908691,13.647920,1.009447,-370.348389,0.100979,0.000000
73.480003,60.179115,-370.303925,-0.001074,0.003974,0.100936,267.690063,13.636783,1.009363,-370.303925,0.100979,0.000000
73.710007,60.115807,-370.348389,-0.001052,0.003974,0.100936,267.408478,13.622437,1.009363,-370.348389,0.100979,0.000000
73.940002,60.064049,-370.348389,-0.001065,0.003974,0.100936,267.178223,13.610708,1.009363,-370.348389,0.100979,0.000000
74.170006,60.010803,-370.392883,-0.001048,0.003974,0.100936,266.941376,13.598642,1.009363,-370.392883,0.100979,0.000000
74.400002,59.973938,-370.437347,-0.001065,0.003974,0.100936,266.777405,13.590289,1.009363,-370.437347,0.100979,0.000000
74.630005,59.917336,-370.437347,-0.001082,0.003974,0.100936,266.525635,13.577462,1.009363,-370.437347,0.100979,0.000000
74.860001,59.871162,-370.437347,-0.001048,0.003974,0.100936,266.320221,13.566999,1.009363,-370.437347,0.100979,0.000000
75.090004,59.830948,-370.437347,-0.001078,0.003974,0.100936,266.141357,13.557886,1.009363,-370.437347,0.100979,0.000000
75.320007,59.778809,-370.392883,-0.001095,0.003974,0.100936,265.909424,13.546072,1.009363,-370.392883,0.100979,0.000000
75.550003,59.731148,-370.481842,-0.001074,0.003974,0.100936,265.697418,13.535272,1.009363,-370.481842,0.100979,0.000000
75.780006,59.691673,-370.437347,-0.001069,0.003974,0.100936,265.521820,13.526326,1.009363,-370.437347,0.100979,0.000000
76.010002,59.652206,-370.481842,-0.001069,0.003974,0.100936,265.346252,13.517383,1.009363,-370.481842,0.100979,0.000000
76.240005,59.591507,-370.481842,-0.001039,0.003974,0.100936,265.076263,13.503629,1.009363,-370.481842,0.100979,0.000000
76.470001,59.576241,-370.526337,-0.001056,0.003974,0.100936,265.008362,13.500170,1.009363,-370.526337,0.100979,0.000000
76.700005,59.533791,-370.526337,-0.001056,0.003974,0.100936,264.819519,13.490550,1.009363,-370.526337,0.100979,0.000000
76.930000,59.479797,-370.526337,-0.001074,0.003974,0.100936,264.579346,13.478315,1.009363,-370.526337,0.100979,0.000000
77.160004,59.451866,-370.570801,-0.001048,0.003974,0.100936,264.455109,13.471986,1.009363,-370.570801,0.100979,0.000000
77.390007,59.417236,-370.570801,-0.001061,0.003974,0.100936,264.301056,13.464138,1.009363,-370.570801,0.100979,0.000000
77.620003,59.388565,-370.570801,-0.001078,0.003974,0.100936,264.173523,13.457641,1.009363,-370.570801,0.100979,0.000000
77.850006,59.343506,-370.615295,-0.001056,0.003974,0.100936,263.973083,13.447431,1.009363,-370.615295,0.100979,0.000000
78.080002,59.306274,-370.704254,-0.001078,0.003974,0.100936,263.807495,13.438993,1.009363,-370.704254,0.100979,0.000000
78.310005,59.263451,-370.615295,-0.001078,0.003974,0.100936,263.617004,13.429290,1.009363,-370.615295,0.100979,0.000000
78.540001,59.229561,-370.615295,-0.001061,0.003974,0.100936,263.466248,13.421611,1.009363,-370.615295,0.100979,0.000000
78.770004,59.215782,-370.615295,-0.001052,0.003974,0.100936,263.404968,13.418489,1.009363,-370.615295,0.100979,0.000000
79.000000,59.172958,-370.615295,-0.001074,0.003974,0.100936,263.214478,13.408785,1.009363,-370.615295,0.100979,0.000000
79.230003,59.143173,-370.659760,-0.001052,0.003974,0.100936,263.081970,13.402035,1.009363,-370.659760,0.100979,0.000000
79.460007,59.111145,-370.704254,-0.001087,0.003974,0.100936,262.939514,13.394777,1.009363,-370.704254,0.100979,0.000000
79.690002,59.074654,-370.748718,-0.001056,0.003974,0.100936,262.777191,13.386508,1.009363,-370.748718,0.100979,0.000000
79.920006,59.056786,-370.704254,-0.001061,0.003974,0.100936,262.697693,13.382459,1.009363,-370.704254,0.100979,0.000000
80.150002,59.019547,-370.748718,-0.001065,0.003974,0.100936,262.532043,13.374021,1.009363,-370.748718,0.100979,0.000000
80.380005,58.993103,-370.793213,-0.001069,0.003974,0.100936,262.414429,13.368028,1.009363,-370.793213,0.100979,0.000000
80.610001,58.971878,-370.837677,-0.001061,0.003974,0.100936,262.320007,13.363219,1.009363,-370.837677,0.100979,0.000000
80.840004,58.944328,-370.793213,-0.001056,0.003974,0.100936,262.197479,13.356976,1.009363,-370.793213,0.100979,0.000000
81.070007,58.917145,-370.793213,-0.001074,0.003974,0.100936,262.076538,13.350816,1.009363,-370.793213,0.100979,0.000000
81.300003,58.888100,-370.837677,-0.001056,0.003974,0.100936,261.947357,13.344234,1.009363,-370.837677,0.100979,0.000000
81.530006,58.848625,-370.837677,-0.001074,0.003974,0.100936,261.771759,13.335289,1.009363,-370.837677,0.100979,0.000000
81.760002,58.834846,-370.882172,-0.001087,0.003974,0.100936,261.710480,13.332168,1.009363,-370.882172,0.100979,0.000000
81.990005,58.804687,-370.837677,-0.001035,0.003974,0.100936,261.576324,13.325333,1.009363,-370.837677,0.100979,0.000000
82.220001,58.778992,-370.926636,-0.001082,0.003974,0.100936,261.462006,13.319510,1.009363,-370.926636,0.100979,0.000000
82.450005,58.754791,-370.882172,-0.001065,0.003974,0.100936,261.354370,13.314026,1.009363,-370.882172,0.100979,0.000000
82.680000,58.731697,-370.926636,-0.001078,0.003974,0.100936,261.251648,13.308793,1.009363,-370.926636,0.100979,0.000000
82.910004,58.692230,-370.971130,-0.001065,0.003974,0.100936,261.076080,13.299850,1.009363,-370.971130,0.100979,0.000000
83.140007,58.684784,-370.926636,-0.001082,0.003974,0.100936,261.042969,13.298162,1.009363,-370.926636,0.100979,0.000000
83.370003,58.658340,-370.926636,-0.001061,0.003974,0.100936,260.925323,13.292170,1.009363,-370.926636,0.100979,0.000000
83.600006,58.627068,-370.971130,-0.001052,0.003974,0.100936,260.786224,13.285084,1.009363,-370.971130,0.100979,0.000000
83.830002,58.612915,-370.971130,-0.001039,0.003974,0.100936,260.723267,13.281877,1.009363,-370.971130,0.100979,0.000000
84.060005,58.596901,-370.971130,-0.001087,0.003974,0.100936,260.652039,13.278248,1.009363,-370.971130,0.100979,0.000000
84.290001,58.566368,-371.060089,-0.001074,0.003974,0.100936,260.516205,13.271329,1.009363,-371.060089,0.100979,0.000000
84.520004,58.541046,-371.060089,-0.001048,0.003974,0.100936,260.403564,13.265591,1.009363,-371.060089,0.100979,0.000000
84.750008,58.530617,-371.060089,-0.001052,0.003974,0.100936,260.357178,13.263227,1.009363,-371.060089,0.100979,0.000000
84.980003,58.504555,-371.104584,-0.001069,0.003974,0.100936,260.241272,13.257322,1.009363,-371.104584,0.100979,0.000000
85.210007,58.488914,-371.060089,-0.001052,0.003974,0.100936,260.171692,13.253778,1.009363,-371.060089,0.100979,0.000000
85.440002,58.457634,-371.104584,-0.001074,0.003974,0.100936,260.032532,13.246690,1.009363,-371.104584,0.100979,0.000000
85.670006,58.443855,-371.060089,-0.001078,0.003974,0.100936,259.971252,13.243567,1.009363,-371.060089,0.100979,0.000000
85.900002,58.424866,-371.104584,-0.001061,0.003974,0.100936,259.886780,13.239264,1.009363,-371.104584,0.100979,0.000000
86.130005,58.395447,-371.149048,-0.001082,0.003974,0.100936,259.755920,13.232598,1.009363,-371.149048,0.100979,0.000000
86.360001,58.378693,-371.149048,-0.001039,0.003974,0.100936,259.681396,13.228801,1.009363,-371.149048,0.100979,0.000000
86.590004,58.360069,-371.149048,-0.001078,0.003974,0.100936,259.598541,13.224581,1.009363,-371.149048,0.100979,0.000000
86.820007,58.351883,-371.149048,-0.001056,0.003974,0.100936,259.562134,13.222726,1.009363,-371.149048,0.100979,0.000000
87.050003,58.331398,-371.149048,-0.001061,0.003974,0.100936,259.471008,13.218083,1.009363,-371.149048,0.100979,0.000000
87.280006,58.312782,-371.282501,-0.001078,0.003974,0.100936,259.388214,13.213865,1.009363,-371.282501,0.100979,0.000000
87.510002,58.283737,-371.238007,-0.001056,0.003974,0.100936,259.259003,13.207284,1.009363,-371.238007,0.100979,0.000000
87.740005,58.259529,-371.193542,-0.001056,0.003974,0.100936,259.151337,13.201798,1.009363,-371.193542,0.100979,0.000000
87.970001,58.258041,-371.282501,-0.001056,0.003974,0.100936,259.144714,13.201461,1.009363,-371.282501,0.100979,0.000000
88.200005,58.245758,-371.282501,-0.001056,0.003974,0.100936,259.090057,13.198677,1.009363,-371.282501,0.100979,0.000000
88.430008,58.222664,-371.326965,-0.001082,0.003974,0.100936,258.987335,13.193444,1.009363,-371.326965,0.100979,0.000000
88.660004,58.217827,-371.326965,-0.001056,0.003974,0.100936,258.965820,13.192348,1.009363,-371.326965,0.100979,0.000000
88.890007,58.179474,-371.326965,-0.001056,0.003974,0.100936,258.795227,13.183657,1.009363,-371.326965,0.100979,0.000000
89.120003,58.163086,-371.371460,-0.001069,0.003974,0.100936,258.722321,13.179944,1.009363,-371.371460,0.100979,0.000000
89.350006,58.151917,-371.371460,-0.001061,0.003974,0.100936,258.672638,13.177413,1.009363,-371.371460,0.100979,0.000000
89.580002,58.141861,-371.415955,-0.001043,0.003974,0.100936,258.627899,13.175135,1.009363,-371.415955,0.100979,0.000000
89.810005,58.117287,-371.415955,-0.001052,0.003974,0.100936,258.518616,13.169565,1.009363,-371.415955,0.100979,0.000000
90.040001,58.106491,-371.371460,-0.001061,0.003974,0.100936,258.470581,13.167119,1.009363,-371.371460,0.100979,0.000000
90.270004,58.090103,-371.415955,-0.001074,0.003974,0.100936,258.397675,13.163405,1.009363,-371.415955,0.100979,0.000000
90.500008,58.065529,-371.371460,-0.001043,0.003974,0.100936,258.288361,13.157837,1.009363,-371.371460,0.100979,0.000000
90.730003,58.053612,-371.460419,-0.001039,0.003974,0.100936,258.235352,13.155136,1.009363,-371.460419,0.100979,0.000000
90.960007,58.039085,-371.415955,-0.001043,0.003974,0.100936,258.170746,13.151844,1.009363,-371.415955,0.100979,0.000000
91.190002,58.026802,-371.460419,-0.001078,0.003974,0.100936,258.116119,13.149061,1.009363,-371.460419,0.100979,0.000000
91.420006,58.007439,-371.415955,-0.001052,0.003974,0.100936,258.029968,13.144673,1.009363,-371.415955,0.100979,0.000000
91.650002,57.980995,-371.460419,-0.001048,0.003974,0.100936,257.912354,13.138681,1.009363,-371.460419,0.100979,0.000000
91.880005,57.971687,-371.504913,-0.001043,0.003974,0.100936,257.870941,13.136572,1.009363,-371.504913,0.100979,0.000000
92.110001,57.967216,-371.504913,-0.001074,0.003974,0.100936,257.851044,13.135559,1.009363,-371.504913,0.100979,0.000000
92.340004,57.948975,-371.549377,-0.001065,0.003974,0.100936,257.769928,13.131425,1.009363,-371.549377,0.100979,0.000000
92.570007,57.938545,-371.549377,-0.001069,0.003974,0.100936,257.723511,13.129063,1.009363,-371.549377,0.100979,0.000000
92.800003,57.924026,-371.504913,-0.001039,0.003974,0.100936,257.658936,13.125772,1.009363,-371.504913,0.100979,0.000000
93.030006,57.894234,-371.638336,-0.001043,0.003974,0.100936,257.526428,13.119020,1.009363,-371.638336,0.100979,0.000000
93.260002,57.884178,-371.638336,-0.001065,0.003974,0.100936,257.481689,13.116742,1.009363,-371.638336,0.100979,0.000000
93.490005,57.870033,-371.549377,-0.001061,0.003974,0.100936,257.418762,13.113537,1.009363,-371.549377,0.100979,0.000000
93.720001,57.859230,-371.638336,-0.001052,0.003974,0.100936,257.370697,13.111089,1.009363,-371.638336,0.100979,0.000000
93.950005,57.852531,-371.638336,-0.001048,0.003974,0.100936,257.340912,13.109571,1.009363,-371.638336,0.100979,0.000000
94.180008,57.832794,-371.727295,-0.001065,0.003974,0.100936,257.253113,13.105099,1.009363,-371.727295,0.100979,0.000000
94.410004,57.812317,-371.682831,-0.001065,0.003974,0.100936,257.162018,13.100458,1.009363,-371.682831,0.100979,0.000000
94.640007,57.799652,-371.638336,-0.001056,0.003974,0.100936,257.105682,13.097589,1.009363,-371.638336,0.100979,0.000000
94.870003,57.784760,-371.682831,-0.001048,0.003974,0.100936,257.039459,13.094213,1.009363,-371.682831,0.100979,0.000000
95.000008,57.775818,-371.682831,-0.001039,0.003974,0.100936,256.999664,13.092188,1.009363,-371.682831,0.100979,0.000000