File: Data/compression 14/AutoNoHeating-12-14-4-240726_07262024_164611.csv
Time (sec),S:Load (lbs),S:HL1 (DIM),S:LVDT (in),S:Position (in),Ch:Position (mm),Ch:Load (N),Ch:Stress (MPa),Ch:Strain (mm/mm),Ch:HL1 (DIM),Set Point (),Cycles ()
0.110000,-0.018990,-384.804718,-0.010878,-0.006107,-0.155120,-0.084470,-0.004303,-1.551201,-384.804718,-0.154904,0.000000
0.360000,-0.018250,-384.804718,-0.010869,-0.006107,-0.155120,-0.081178,-0.004135,-1.551201,-384.804718,-0.154904,0.000000
0.610000,-0.007820,-384.849182,-0.010878,-0.006002,-0.152458,-0.034786,-0.001772,-1.524578,-384.849182,-0.151730,0.000000
0.860000,-0.004845,-384.849182,-0.010787,-0.005858,-0.148781,-0.021550,-0.001098,-1.487812,-384.849182,-0.147567,0.000000
1.110000,-0.019737,-384.849182,-0.010619,-0.005682,-0.144332,-0.087796,-0.004473,-1.443324,-384.849182,-0.143404,0.000000
1.360000,-0.061813,-384.849182,-0.010430,-0.005530,-0.140456,-0.274960,-0.014007,-1.404559,-384.849182,-0.139242,0.000000
1.610000,-0.033890,-384.849182,-0.010266,-0.005363,-0.136232,-0.150749,-0.007680,-1.362320,-384.849182,-0.135079,0.000000
1.860000,0.021225,-384.849182,-0.010102,-0.005202,-0.132139,0.094413,0.004810,-1.321390,-384.849182,-0.130899,0.000000
2.110000,0.021973,-384.893677,-0.009912,-0.005030,-0.127759,0.097739,0.004979,-1.277591,-384.893677,-0.126736,0.000000
2.360000,-0.012665,-384.893677,-0.009748,-0.004873,-0.123771,-0.056336,-0.002870,-1.237706,-384.893677,-0.122574,0.000000
2.610000,0.011169,-384.938141,-0.009567,-0.004710,-0.119634,0.049684,0.002531,-1.196337,-384.938141,-0.118410,0.000000
2.860000,-0.008942,-384.938141,-0.009421,-0.004538,-0.115254,-0.039774,-0.002026,-1.152538,-384.938141,-0.114248,0.000000
3.110000,-0.042824,-384.982635,-0.009209,-0.004380,-0.111247,-0.190490,-0.009704,-1.112471,-384.982635,-0.110085,0.000000
3.360000,-0.010429,-384.893677,-0.009076,-0.004215,-0.107067,-0.046392,-0.002363,-1.070671,-384.893677,-0.105923,0.000000
3.610000,0.014153,-384.982635,-0.008912,-0.004061,-0.103147,0.062954,0.003207,-1.031475,-384.982635,-0.101760,0.000000
3.860000,0.008934,-385.027100,-0.008701,-0.003886,-0.098708,0.039741,0.002024,-0.987078,-385.027100,-0.097580,0.000000
4.110000,-0.011543,-384.982635,-0.008554,-0.003723,-0.094571,-0.051347,-0.002616,-0.945709,-384.982635,-0.093417,0.000000
4.360000,0.025322,-385.071594,-0.008364,-0.003562,-0.090486,0.112638,0.005738,-0.904862,-385.071594,-0.089255,0.000000
4.610000,0.014519,-384.982635,-0.008192,-0.003401,-0.086392,0.064583,0.003290,-0.863925,-384.982635,-0.085092,0.000000
4.860000,-0.023460,-385.071594,-0.008015,-0.003230,-0.082031,-0.104357,-0.005316,-0.820308,-385.071594,-0.080929,0.000000
5.110000,-0.002235,-385.071594,-0.007877,-0.003068,-0.077920,-0.009944,-0.000507,-0.779204,-385.071594,-0.076767,0.000000
5.360000,-0.023834,-385.071594,-0.007675,-0.002895,-0.073523,-0.106020,-0.005401,-0.735231,-385.071594,-0.072604,0.000000
5.610000,-0.042824,-385.160553,-0.007541,-0.002738,-0.069543,-0.190490,-0.009704,-0.695429,-385.160553,-0.068424,0.000000
5.860000,-0.035378,-385.160553,-0.007355,-0.002575,-0.065397,-0.157367,-0.008017,-0.653969,-385.160553,-0.064261,0.000000
6.110000,0.016754,-385.160553,-0.007170,-0.002416,-0.061356,0.074526,0.003797,-0.613562,-385.160553,-0.060099,0.000000
6.360000,0.034630,-385.205048,-0.006963,-0.002243,-0.056968,0.154041,0.007847,-0.569680,-385.205048,-0.055936,0.000000
6.610000,-0.004097,-385.160553,-0.006829,-0.002084,-0.052926,-0.018224,-0.000928,-0.529265,-385.160553,-0.051773,0.000000
6.860000,0.005211,-385.205048,-0.006657,-0.001917,-0.048694,0.023179,0.001181,-0.486942,-385.205048,-0.047610,0.000000
7.110000,-0.005211,-385.160553,-0.006476,-0.001755,-0.044584,-0.023179,-0.001181,-0.445838,-385.160553,-0.043448,0.000000
7.360000,-0.027557,-385.249512,-0.006316,-0.001589,-0.040369,-0.122581,-0.006245,-0.403689,-385.249512,-0.039285,0.000000
7.610000,-0.016388,-385.294006,-0.006140,-0.001424,-0.036181,-0.072897,-0.003714,-0.361806,-385.294006,-0.035105,0.000000
7.860001,-0.021973,-385.249512,-0.005954,-0.001275,-0.032373,-0.097739,-0.004979,-0.323730,-385.249512,-0.030942,0.000000
8.110001,0.008560,-385.249512,-0.005799,-0.001095,-0.027811,0.038078,0.001940,-0.278114,-385.249512,-0.026780,0.000000
8.360001,0.003723,-385.249512,-0.005605,-0.000937,-0.023805,0.016561,0.000844,-0.238055,-385.249512,-0.022617,0.000000
8.610001,0.024574,-385.294006,-0.005424,-0.000771,-0.019573,0.109312,0.005569,-0.195732,-385.294006,-0.018454,0.000000
8.860001,0.032021,-385.294006,-0.005290,-0.000618,-0.015697,0.142435,0.007256,-0.156967,-385.294006,-0.014292,0.000000
9.110001,-0.014893,-385.382965,-0.005101,-0.000441,-0.011213,-0.066245,-0.003375,-0.112131,-385.382965,-0.010129,0.000000
9.360001,0.039841,-385.338470,-0.004924,-0.000279,-0.007085,0.177220,0.009028,-0.070853,-385.338470,-0.005967,0.000000
9.610001,0.349655,-385.382965,-0.004751,-0.000112,-0.002836,1.555344,0.079233,-0.028356,-385.382965,-0.001786,0.000000
9.860001,0.659843,-385.382965,-0.004669,-0.000003,-0.000070,2.935130,0.149523,-0.000696,-385.382965,0.000173,0.000000
10.110001,0.617767,-385.382965,-0.004687,-0.000003,-0.000070,2.747966,0.139988,-0.000696,-385.382965,0.000173,0.000000
10.360001,0.649414,-385.338470,-0.004682,-0.000003,-0.000070,2.888738,0.147159,-0.000696,-385.338470,0.000364,0.000000
10.610001,0.593933,-385.382965,-0.004674,-0.000003,-0.000070,2.641946,0.134587,-0.000696,-385.382965,0.000789,0.000000
10.860001,0.554459,-385.427429,-0.004652,0.000005,0.000139,2.466355,0.125642,0.001385,-385.427429,0.001205,0.000000
11.110001,0.869118,-385.471924,-0.004648,0.000027,0.000693,3.866029,0.196945,0.006934,-385.471924,0.001621,0.000000
11.360001,0.955505,-385.471924,-0.004674,0.000037,0.000945,4.250300,0.216521,0.009455,-385.471924,0.002038,0.000000
11.610001,1.133873,-385.516388,-0.004639,0.000058,0.001483,5.043719,0.256939,0.014829,-385.516388,0.002454,0.000000
11.860001,1.328995,-385.516388,-0.004618,0.000078,0.001977,5.911664,0.301154,0.019772,-385.516388,0.002870,0.000000
12.110001,1.490234,-385.560883,-0.004592,0.000094,0.002384,6.628893,0.337692,0.023845,-385.560883,0.003287,0.000000
12.360001,1.680145,-385.516388,-0.004562,0.000109,0.002758,7.473660,0.380726,0.027577,-385.516388,0.003703,0.000000
12.610001,1.885323,-385.560883,-0.004557,0.000129,0.003269,8.386333,0.427220,0.032694,-385.560883,0.004119,0.000000
12.860001,1.896866,-385.560883,-0.004553,0.000133,0.003391,8.437680,0.429836,0.033905,-385.560883,0.004536,0.000000
13.110001,2.289345,-385.605377,-0.004549,0.000157,0.003980,10.183515,0.518773,0.039802,-385.605377,0.004952,0.000000
13.360001,2.386162,-385.605377,-0.004536,0.000166,0.004223,10.614178,0.540712,0.042232,-385.605377,0.005368,0.000000
13.610001,2.672516,-385.694336,-0.004557,0.000184,0.004674,11.887944,0.605601,0.046743,-385.694336,0.005784,0.000000
13.860001,3.108192,-385.605377,-0.004527,0.000214,0.005437,13.825931,0.704326,0.054374,-385.605377,0.006200,0.000000
14.110001,3.215065,-385.694336,-0.004480,0.000226,0.005750,14.301323,0.728544,0.057500,-385.694336,0.006617,0.000000
14.360001,3.448540,-385.649841,-0.004437,0.000241,0.006132,15.339870,0.781450,0.061315,-385.649841,0.007033,0.000000
14.610001,3.652229,-385.738800,-0.004441,0.000256,0.006513,16.245928,0.827607,0.065130,-385.738800,0.007449,0.000000
14.860001,3.897247,-385.694336,-0.004467,0.000272,0.006920,17.335821,0.883129,0.069203,-385.694336,0.007866,0.000000
15.110001,4.285263,-385.738800,-0.004445,0.000289,0.007346,19.061802,0.971054,0.073457,-385.738800,0.008282,0.000000
15.360001,4.311699,-385.694336,-0.004393,0.000299,0.007597,19.179394,0.977045,0.075970,-385.694336,0.008698,0.000000
15.610001,4.675133,-385.738800,-0.004398,0.000316,0.008031,20.796030,1.059400,0.080308,-385.738800,0.009123,0.000000
15.860001,5.175232,-385.827759,-0.004406,0.000344,0.008750,23.020582,1.172724,0.087499,-385.827759,0.009539,0.000000
16.110001,5.185287,-385.827759,-0.004372,0.000354,0.009002,23.065311,1.175003,0.090020,-385.827759,0.009956,0.000000
16.360001,5.332001,-385.827759,-0.004355,0.000368,0.009357,23.717924,1.208249,0.093570,-385.827759,0.010372,0.000000
16.610001,5.758369,-385.783295,-0.004359,0.000386,0.009800,25.614506,1.304865,0.097998,-385.783295,0.010788,0.000000
16.860001,6.236122,-385.827759,-0.004294,0.000408,0.010372,27.739656,1.413126,0.103721,-385.827759,0.011205,0.000000
17.110001,6.211540,-385.872253,-0.004277,0.000420,0.010658,27.630310,1.407555,0.106583,-385.872253,0.011621,0.000000
17.360001,6.226067,-385.872253,-0.004281,0.000428,0.010875,27.694927,1.410847,0.108748,-385.872253,0.012037,0.000000
17.610001,6.991661,-385.916718,-0.004268,0.000458,0.011629,31.100462,1.584333,0.116295,-385.916718,0.012453,0.000000
17.860001,7.114174,-385.916718,-0.004268,0.000474,0.012046,31.645426,1.612095,0.120458,-385.916718,0.012869,0.000000
18.110001,7.271317,-385.916718,-0.004234,0.000490,0.012445,32.344433,1.647704,0.124447,-385.916718,0.013286,0.000000
18.360001,7.377441,-385.916718,-0.004238,0.000502,0.012748,32.816498,1.671752,0.127483,-385.916718,0.013702,0.000000
18.610001,7.617996,-385.961212,-0.004243,0.000514,0.013052,33.886539,1.726263,0.130518,-385.961212,0.014118,0.000000
18.860001,8.067451,-386.005707,-0.004204,0.000535,0.013581,35.885815,1.828111,0.135810,-386.005707,0.014535,0.000000
19.110001,8.301300,-386.005707,-0.004178,0.000552,0.014031,36.926025,1.881101,0.140314,-386.005707,0.014951,0.000000
19.360001,8.327362,-385.961212,-0.004143,0.000562,0.014283,37.041958,1.887007,0.142834,-385.961212,0.015367,0.000000
19.610001,8.947365,-386.005707,-0.004148,0.000587,0.014916,39.799866,2.027502,0.149163,-386.005707,0.015784,0.000000
19.860001,9.096687,-386.094666,-0.004156,0.000606,0.015385,40.464085,2.061339,0.153848,-386.094666,0.016200,0.000000
20.110001,9.124985,-386.005707,-0.004130,0.000618,0.015706,40.589958,2.067751,0.157058,-386.005707,0.016616,0.000000
20.360001,9.269096,-386.005707,-0.004126,0.000632,0.016061,41.230999,2.100407,0.160608,-386.005707,0.017032,0.000000
20.610001,9.564758,-386.094666,-0.004092,0.000651,0.016529,42.546169,2.167405,0.165294,-386.094666,0.017457,0.000000
20.860001,9.921494,-386.139130,-0.004096,0.000666,0.016919,44.133007,2.248242,0.169192,-386.139130,0.017874,0.000000
21.110001,10.122948,-386.094666,-0.004049,0.000683,0.017345,45.029121,2.293893,0.173447,-386.094666,0.018290,0.000000
21.360001,10.131134,-386.094666,-0.004049,0.000693,0.017604,45.065536,2.295748,0.176043,-386.094666,0.018706,0.000000
21.610001,10.118477,-386.094666,-0.004044,0.000702,0.017822,45.009232,2.292880,0.178216,-386.094666,0.019122,0.000000
21.860001,10.949608,-386.183624,-0.004036,0.000731,0.018576,48.706287,2.481217,0.185763,-386.183624,0.019538,0.000000
22.110001,10.957802,-386.183624,-0.003992,0.000746,0.018940,48.742737,2.483073,0.189404,-386.183624,0.019955,0.000000
22.360001,11.196495,-386.139130,-0.003988,0.000767,0.019469,49.804497,2.537162,0.194695,-386.139130,0.020371,0.000000
22.610001,11.355499,-386.183624,-0.003992,0.000782,0.019851,50.511784,2.573193,0.198510,-386.183624,0.020787,0.000000
22.860001,11.513382,-386.228088,-0.003949,0.000793,0.020155,51.214081,2.608970,0.201546,-386.228088,0.021204,0.000000
23.110001,11.649300,-386.183624,-0.003949,0.000808,0.020527,51.818672,2.639769,0.205270,-386.183624,0.021620,0.000000
23.360001,11.749840,-386.272583,-0.003954,0.000822,0.020891,52.265896,2.662552,0.208911,-386.272583,0.022036,0.000000
23.610001,12.438728,-386.272583,-0.003949,0.000847,0.021507,55.330227,2.818656,0.215073,-386.272583,0.022453,0.000000
23.860001,12.586563,-386.272583,-0.003911,0.000863,0.021932,55.987827,2.852156,0.219320,-386.272583,0.022868,0.000000
24.110001,12.634598,-386.228088,-0.003885,0.000879,0.022323,56.201496,2.863041,0.223226,-386.228088,0.023285,0.000000
24.360001,12.945152,-386.272583,-0.003880,0.000900,0.022852,57.582912,2.933414,0.228517,-386.272583,0.023701,0.000000
24.610001,13.132088,-386.317047,-0.003880,0.000917,0.023285,58.414444,2.975774,0.232847,-386.317047,0.024117,0.000000
24.860001,13.173050,-386.317047,-0.003842,0.000930,0.023623,58.596653,2.985056,0.236230,-386.317047,0.024534,0.000000
25.110001,12.968987,-386.361542,-0.003829,0.000940,0.023883,57.688934,2.938814,0.238834,-386.361542,0.024950,0.000000
25.360001,13.788582,-386.406036,-0.003794,0.000966,0.024525,61.334675,3.124537,0.245254,-386.406036,0.025366,0.000000
25.610001,14.081635,-386.406036,-0.003768,0.000985,0.025011,62.638237,3.190944,0.250106,-386.406036,0.025783,0.000000
25.860001,14.017960,-386.361542,-0.003781,0.000998,0.025341,62.355000,3.176515,0.253406,-386.361542,0.026207,0.000000
26.110001,14.061157,-386.450500,-0.003798,0.001011,0.025678,62.547150,3.186304,0.256782,-386.450500,0.026624,0.000000
26.360001,14.409325,-386.450500,-0.003768,0.001031,0.026190,64.095879,3.265200,0.261900,-386.450500,0.027040,0.000000
26.610001,14.652481,-386.450500,-0.003747,0.001048,0.026615,65.177490,3.320300,0.266154,-386.450500,0.027456,0.000000
26.860001,14.556412,-386.406036,-0.003742,0.001058,0.026875,64.750153,3.298530,0.268750,-386.406036,0.027873,0.000000
27.110001,14.640938,-386.494995,-0.003725,0.001072,0.027222,65.126144,3.317684,0.272225,-386.494995,0.028289,0.000000
27.360001,15.476913,-386.450500,-0.003699,0.001097,0.027873,68.844749,3.507119,0.278727,-386.450500,0.028705,0.000000
27.610001,15.576340,-386.494995,-0.003673,0.001115,0.028324,69.287018,3.529649,0.283239,-386.494995,0.029122,0.000000
27.860001,15.510056,-386.539459,-0.003686,0.001128,0.028661,68.992172,3.514629,0.286615,-386.539459,0.029537,0.000000
28.110001,15.481758,-386.583954,-0.003669,0.001142,0.029000,68.866302,3.508217,0.289999,-386.583954,0.029954,0.000000
28.360001,15.667572,-386.583954,-0.003652,0.001158,0.029408,69.692841,3.550323,0.294079,-386.583954,0.030370,0.000000
28.610001,15.934563,-386.494995,-0.003639,0.001173,0.029807,70.880478,3.610823,0.298068,-386.494995,0.030786,0.000000
28.860001,16.009781,-386.672913,-0.003639,0.001187,0.030153,71.215065,3.627868,0.301535,-386.672913,0.031203,0.000000
29.110001,16.347153,-386.628418,-0.003630,0.001204,0.030570,72.715767,3.704318,0.305698,-386.628418,0.031619,0.000000
29.360001,16.895279,-386.628418,-0.003592,0.001228,0.031194,75.153954,3.828525,0.311943,-386.628418,0.032035,0.000000
29.610001,17.043114,-386.672913,-0.003583,0.001246,0.031636,75.811554,3.862025,0.316364,-386.672913,0.032452,0.000000
29.860001,16.805168,-386.628418,-0.003579,0.001257,0.031931,74.753120,3.808106,0.319309,-386.628418,0.032868,0.000000
30.110001,16.871452,-386.672913,-0.003548,0.001271,0.032278,75.047966,3.823126,0.322783,-386.672913,0.033284,0.000000
30.360001,17.233772,-386.717377,-0.003566,0.001290,0.032755,76.659645,3.905229,0.327552,-386.717377,0.033701,0.000000
30.610001,17.674286,-386.672913,-0.003544,0.001309,0.033258,78.619148,4.005051,0.332579,-386.672913,0.034116,0.000000
30.860001,17.419952,-386.717377,-0.003535,0.001320,0.033518,77.487816,3.947418,0.335183,-386.717377,0.034542,0.000000
31.110001,18.140869,-386.761871,-0.003510,0.001345,0.034160,80.694618,4.110780,0.341602,-386.761871,0.034958,0.000000
31.360001,18.193748,-386.717377,-0.003466,0.001362,0.034594,80.929832,4.122762,0.345939,-386.717377,0.035374,0.000000
31.610001,18.197838,-386.761871,-0.003484,0.001377,0.034975,80.948029,4.123689,0.349755,-386.761871,0.035791,0.000000
31.860001,18.017616,-386.761871,-0.003488,0.001389,0.035270,80.146362,4.082850,0.352699,-386.761871,0.036206,0.000000
32.110001,18.131187,-386.761871,-0.003462,0.001404,0.035669,80.651550,4.108586,0.356688,-386.761871,0.036623,0.000000
32.360001,18.659210,-386.850830,-0.003445,0.001422,0.036128,83.000313,4.228238,0.361283,-386.850830,0.037039,0.000000
32.610001,18.569839,-386.850830,-0.003436,0.001435,0.036441,82.602768,4.207986,0.364410,-386.850830,0.037455,0.000000
32.860001,18.583618,-386.895325,-0.003419,0.001447,0.036745,82.664062,4.211108,0.367445,-386.895325,0.037872,0.000000
33.110001,19.454971,-386.895325,-0.003428,0.001474,0.037438,86.540031,4.408560,0.374379,-386.895325,0.038288,0.000000
33.360001,19.486626,-386.984283,-0.003397,0.001490,0.037837,86.680840,4.415732,0.378368,-386.984283,0.038704,0.000000
33.610001,19.583809,-386.984283,-0.003397,0.001506,0.038262,87.113136,4.437755,0.382623,-386.984283,0.039121,0.000000
33.860001,19.332458,-386.939789,-0.003402,0.001518,0.038548,85.995071,4.380797,0.385484,-386.939789,0.039537,0.000000
34.110001,19.338791,-386.984283,-0.003363,0.001531,0.038878,86.023239,4.382233,0.388777,-386.984283,0.039953,0.000000
34.360001,20.046669,-386.984283,-0.003363,0.001554,0.039459,89.172035,4.542640,0.394590,-386.984283,0.040370,0.000000
34.610001,19.820267,-386.984283,-0.003337,0.001565,0.039745,88.164948,4.491337,0.397452,-386.984283,0.040785,0.000000
34.860001,19.482529,-386.939789,-0.003328,0.001574,0.039979,86.662613,4.414804,0.399791,-386.939789,0.041202,0.000000
35.110001,20.830887,-387.028748,-0.003316,0.001606,0.040794,92.660416,4.720346,0.407944,-387.028748,0.041618,0.000000
35.360001,20.780991,-387.028748,-0.003311,0.001622,0.041202,92.438461,4.709040,0.412016,-387.028748,0.042034,0.000000
35.610001,20.555702,-387.028748,-0.003303,0.001637,0.041575,91.436333,4.657989,0.415748,-387.028748,0.042451,0.000000
35.860001,20.458885,-387.028748,-0.003290,0.001649,0.041896,91.005669,4.636050,0.418958,-387.028748,0.042875,0.000000
36.110001,20.555328,-387.117706,-0.003255,0.001665,0.042286,91.434669,4.657904,0.422856,-387.117706,0.043292,0.000000
36.360001,21.117989,-387.073242,-0.003221,0.001687,0.042850,93.937508,4.785405,0.428496,-387.073242,0.043708,0.000000
36.610001,20.684547,-387.117706,-0.003255,0.001695,0.043058,92.009460,4.687185,0.430577,-387.117706,0.044124,0.000000
36.860001,21.024147,-387.117706,-0.003255,0.001711,0.043465,93.520073,4.764140,0.434650,-387.117706,0.044541,0.000000
37.110001,21.650848,-387.206665,-0.003225,0.001735,0.044081,96.307785,4.906153,0.440812,-387.206665,0.044957,0.000000
37.360001,21.711922,-387.206665,-0.003221,0.001752,0.044488,96.579453,4.919991,0.444884,-387.206665,0.045373,0.000000
37.610001,21.449394,-387.162201,-0.003229,0.001764,0.044801,95.411674,4.860502,0.448010,-387.162201,0.045790,0.000000
37.860001,21.328377,-387.162201,-0.003199,0.001778,0.045173,94.873360,4.833079,0.451735,-387.162201,0.046206,0.000000
38.110001,21.294487,-387.251160,-0.003203,0.001794,0.045555,94.722610,4.825399,0.455550,-387.251160,0.046622,0.000000
38.360001,22.181480,-387.251160,-0.003156,0.001817,0.046154,98.668152,5.026395,0.461538,-387.251160,0.047038,0.000000
38.610001,21.622925,-387.206665,-0.003152,0.001825,0.046362,96.183571,4.899825,0.463619,-387.206665,0.047454,0.000000
38.860001,22.416077,-387.251160,-0.003134,0.001851,0.047012,99.711685,5.079556,0.470122,-387.251160,0.047871,0.000000
39.110001,22.542313,-387.251160,-0.003139,0.001868,0.047446,100.273216,5.108161,0.474459,-387.251160,0.048287,0.000000
39.360001,22.286865,-387.295654,-0.003134,0.001882,0.047802,99.136925,5.050276,0.478017,-387.295654,0.048703,0.000000
39.610001,22.020615,-387.251160,-0.003152,0.001894,0.048096,97.952583,4.989943,0.480962,-387.251160,0.049120,0.000000
39.860001,22.362457,-387.384613,-0.003122,0.001912,0.048573,99.473175,5.067405,0.485731,-387.384613,0.049536,0.000000
40.110001,22.598167,-387.295654,-0.003100,0.001932,0.049067,100.521667,5.120818,0.490674,-387.295654,0.049952,0.000000
40.360001,22.545288,-387.384613,-0.003091,0.001944,0.049388,100.286453,5.108835,0.493883,-387.384613,0.050369,0.000000
40.610001,22.471558,-387.340118,-0.003091,0.001958,0.049727,99.958481,5.092128,0.497267,-387.340118,0.050785,0.000000
40.860001,23.058418,-387.384613,-0.003065,0.001980,0.050299,102.568970,5.225112,0.502990,-387.384613,0.051201,0.000000
41.110001,23.277374,-387.384613,-0.003065,0.001998,0.050758,103.542931,5.274728,0.507585,-387.384613,0.051626,0.000000
41.360001,23.135872,-387.340118,-0.003048,0.002014,0.051157,102.913498,5.242663,0.511574,-387.340118,0.052042,0.000000
41.610001,22.842445,-387.429077,-0.003048,0.002027,0.051496,101.608269,5.176172,0.514958,-387.429077,0.052459,0.000000
41.860001,22.919151,-387.429077,-0.003027,0.002042,0.051869,101.949478,5.193554,0.518690,-387.429077,0.052875,0.000000
42.110001,23.192101,-387.473572,-0.003040,0.002062,0.052381,103.163612,5.255405,0.523807,-387.473572,0.053291,0.000000
42.360001,23.282585,-387.473572,-0.003031,0.002078,0.052788,103.566109,5.275909,0.527879,-387.473572,0.053707,0.000000
42.610001,22.535233,-387.473572,-0.003005,0.002084,0.052944,100.241722,5.106557,0.529439,-387.473572,0.054123,0.000000
42.860001,22.583641,-387.518036,-0.002992,0.002098,0.053300,100.457054,5.117526,0.532996,-387.518036,0.054540,0.000000
43.110001,23.848969,-387.518036,-0.003018,0.002127,0.054028,106.085510,5.404253,0.540279,-387.518036,0.054956,0.000000
43.360001,23.770767,-387.562531,-0.002997,0.002143,0.054427,105.737656,5.386533,0.544268,-387.562531,0.055372,0.000000
43.610001,23.578247,-387.518036,-0.003018,0.002158,0.054808,104.881279,5.342907,0.548083,-387.518036,0.055789,0.000000
43.860001,23.442337,-387.562531,-0.002962,0.002171,0.055147,104.276726,5.312109,0.551467,-387.562531,0.056205,0.000000
44.110001,23.816200,-387.518036,-0.002945,0.002192,0.055667,105.939751,5.396828,0.556675,-387.518036,0.056621,0.000000
44.360001,23.651978,-387.606995,-0.002945,0.002206,0.056040,105.209251,5.359615,0.560399,-387.606995,0.057038,0.000000
44.610001,23.078529,-387.606995,-0.002919,0.002215,0.056257,102.658424,5.229670,0.562572,-387.606995,0.057454,0.000000
44.860001,23.170876,-387.606995,-0.002902,0.002232,0.056682,103.069199,5.250596,0.566818,-387.606995,0.057870,0.000000
45.110001,24.548279,-387.695984,-0.002897,0.002260,0.057402,109.196198,5.562720,0.574017,-387.695984,0.058286,0.000000
45.360001,24.098831,-387.651489,-0.002919,0.002272,0.057714,107.196953,5.460874,0.577136,-387.651489,0.058702,0.000000
45.610001,24.180748,-387.695984,-0.002936,0.002291,0.058190,107.561340,5.479435,0.581905,-387.695984,0.059119,0.000000
45.860001,24.350922,-387.695984,-0.002893,0.002309,0.058659,108.318306,5.517998,0.586591,-387.695984,0.059535,0.000000
46.110001,24.424652,-387.695984,-0.002902,0.002326,0.059093,108.646278,5.534706,0.590928,-387.695984,0.059960,0.000000
46.360001,23.804657,-387.740448,-0.002859,0.002334,0.059292,105.888405,5.394212,0.592919,-387.740448,0.060376,0.000000
46.610001,24.394493,-387.740448,-0.002867,0.002357,0.059873,108.512123,5.527871,0.598733,-387.740448,0.060792,0.000000
46.860001,25.001457,-387.784943,-0.002837,0.002379,0.060437,111.212036,5.665411,0.604372,-387.784943,0.061209,0.000000
47.110001,24.759415,-387.829407,-0.002854,0.002394,0.060810,110.135376,5.610563,0.608096,-387.829407,0.061625,0.000000
47.360001,24.528175,-387.829407,-0.002833,0.002408,0.061174,109.106773,5.558164,0.611737,-387.829407,0.062041,0.000000
47.610001,24.604507,-387.829407,-0.002841,0.002424,0.061573,109.446312,5.575461,0.615727,-387.829407,0.062458,0.000000
47.860001,24.859581,-387.873901,-0.002837,0.002442,0.062024,110.580940,5.633262,0.620238,-387.873901,0.062874,0.000000
48.110001,24.743034,-387.784943,-0.002811,0.002455,0.062353,110.062515,5.606852,0.623531,-387.784943,0.063290,0.000000
48.360001,24.231018,-387.918365,-0.002833,0.002464,0.062596,107.784950,5.490827,0.625961,-387.918365,0.063707,0.000000
48.610001,25.316483,-387.918365,-0.002824,0.002490,0.063255,112.613342,5.736797,0.632554,-387.918365,0.064123,0.000000
48.860001,25.647896,-387.873901,-0.002811,0.002510,0.063750,114.087540,5.811896,0.637497,-387.873901,0.064539,0.000000
49.110001,25.526505,-387.918365,-0.002815,0.002525,0.064123,113.547562,5.784389,0.641229,-387.918365,0.064955,0.000000
49.360001,25.074074,-387.962860,-0.002759,0.002536,0.064417,111.535049,5.681867,0.644174,-387.962860,0.065371,0.000000
49.610001,25.009277,-387.962860,-0.002802,0.002551,0.064791,111.246819,5.667183,0.647906,-387.962860,0.065788,0.000000
49.860001,25.473251,-387.962860,-0.002781,0.002569,0.065250,113.310684,5.772321,0.652501,-387.962860,0.066204,0.000000
50.110001,25.422615,-388.007324,-0.002751,0.002583,0.065614,113.085442,5.760847,0.656142,-388.007324,0.066620,0.000000
50.360001,25.384254,-387.918365,-0.002742,0.002597,0.065970,112.914803,5.752154,0.659700,-387.918365,0.067037,0.000000
50.610001,25.937599,-387.962860,-0.002764,0.002617,0.066482,115.376205,5.877544,0.664817,-387.962860,0.067453,0.000000
50.860001,26.572495,-388.007324,-0.002738,0.002641,0.067080,118.200356,6.021413,0.670797,-388.007324,0.067869,0.000000
51.110001,26.155815,-387.962860,-0.002734,0.002654,0.067410,116.346878,5.926992,0.674097,-387.962860,0.068294,0.000000
51.360001,26.050430,-388.051819,-0.002716,0.002669,0.067800,115.878098,5.903112,0.677996,-388.051819,0.068710,0.000000
51.610001,25.754021,-388.051819,-0.002734,0.002680,0.068060,114.559608,5.835945,0.680600,-388.051819,0.069127,0.000000
51.860001,26.292473,-388.096283,-0.002721,0.002700,0.068589,116.954758,5.957960,0.685891,-388.096283,0.069543,0.000000
52.110001,26.196030,-388.096283,-0.002690,0.002714,0.068944,116.525757,5.936105,0.689441,-388.096283,0.069959,0.000000
52.360001,26.794807,-388.096283,-0.002721,0.002737,0.069525,119.189255,6.071790,0.695255,-388.096283,0.070376,0.000000
52.610001,27.210373,-388.096283,-0.002677,0.002757,0.070037,121.037781,6.165959,0.700372,-388.096283,0.070792,0.000000
52.860001,27.035728,-388.140778,-0.002677,0.002773,0.070427,120.260925,6.126384,0.704271,-388.140778,0.071208,0.000000
53.110004,26.656654,-388.140778,-0.002686,0.002784,0.070722,118.574722,6.040484,0.707223,-388.140778,0.071624,0.000000
53.360004,26.413498,-388.229736,-0.002656,0.002795,0.071000,117.493103,5.985384,0.710001,-388.229736,0.072040,0.000000
53.610004,27.322083,-388.229736,-0.002677,0.002818,0.071590,121.534691,6.191272,0.715898,-388.229736,0.072457,0.000000
53.860004,26.988808,-388.140778,-0.002673,0.002830,0.071884,120.052216,6.115751,0.718842,-388.140778,0.072873,0.000000
54.110004,26.788101,-388.229736,-0.002656,0.002841,0.072162,119.159424,6.070271,0.721621,-388.229736,0.073289,0.000000
54.360004,27.548485,-388.318695,-0.002630,0.002865,0.072769,122.541779,6.242576,0.727691,-388.318695,0.073706,0.000000
54.610004,27.984909,-388.229736,-0.002617,0.002884,0.073263,124.483093,6.341471,0.732635,-388.229736,0.074122,0.000000
54.860004,28.097733,-388.318695,-0.002643,0.002900,0.073662,124.984955,6.367037,0.736624,-388.318695,0.074538,0.000000
55.110004,27.684029,-388.318695,-0.002621,0.002913,0.073983,123.144707,6.273291,0.739833,-388.318695,0.074955,0.000000
55.360004,27.937988,-388.318695,-0.002626,0.002927,0.074356,124.274376,6.330839,0.743558,-388.318695,0.075371,0.000000
55.610004,28.037041,-388.318695,-0.002626,0.002946,0.074824,124.714989,6.353284,0.748243,-388.318695,0.075786,0.000000
55.860004,28.362862,-388.363190,-0.002621,0.002959,0.075163,126.164307,6.427116,0.751627,-388.363190,0.076203,0.000000
56.110004,27.785316,-388.318695,-0.002583,0.002969,0.075405,123.595261,6.296243,0.754049,-388.318695,0.076619,0.000000
56.360004,28.682732,-388.318695,-0.002583,0.002993,0.076029,127.587166,6.499600,0.760295,-388.318695,0.077045,0.000000
56.610004,29.662819,-388.407654,-0.002565,0.003018,0.076646,131.946808,6.721691,0.766456,-388.407654,0.077461,0.000000
56.860004,29.354118,-388.363190,-0.002587,0.003031,0.076992,130.573639,6.651738,0.769923,-388.363190,0.077876,0.000000
57.110004,29.107613,-388.407654,-0.002570,0.003045,0.077331,129.477127,6.595879,0.773307,-388.407654,0.078293,0.000000
57.360004,28.861099,-388.452148,-0.002552,0.003057,0.077652,128.380585,6.540019,0.776517,-388.452148,0.078709,0.000000
57.610004,29.596909,-388.452148,-0.002561,0.003079,0.078207,131.653625,6.706755,0.782065,-388.452148,0.079126,0.000000
57.860004,29.373856,-388.452148,-0.002527,0.003091,0.078510,130.661438,6.656211,0.785101,-388.452148,0.079542,0.000000
58.110004,29.506790,-388.496613,-0.002535,0.003107,0.078917,131.252762,6.686335,0.789173,-388.496613,0.079958,0.000000
58.360004,30.361389,-388.452148,-0.002539,0.003128,0.079446,135.054199,6.879989,0.794465,-388.452148,0.080375,0.000000
58.610004,30.753868,-388.496613,-0.002539,0.003148,0.079958,136.800034,6.968926,0.799582,-388.496613,0.080791,0.000000
58.860004,30.338303,-388.496613,-0.002518,0.003160,0.080262,134.951508,6.874758,0.802617,-388.496613,0.081207,0.000000
59.110004,30.239250,-388.496613,-0.002514,0.003172,0.080574,134.510910,6.852312,0.805736,-388.496613,0.081624,0.000000
59.360004,30.306274,-388.496613,-0.002492,0.003187,0.080938,134.809036,6.867500,0.809385,-388.496613,0.082040,0.000000
59.610004,31.224922,-388.541107,-0.002531,0.003212,0.081597,138.895386,7.075668,0.815970,-388.541107,0.082455,0.000000
59.860004,30.712166,-388.496613,-0.002505,0.003221,0.081814,136.614532,6.959476,0.818143,-388.496613,0.082872,0.000000
60.110004,31.258804,-388.585602,-0.002496,0.003242,0.082352,139.046112,7.083346,0.823517,-388.585602,0.083288,0.000000
60.360004,31.873962,-388.541107,-0.002475,0.003263,0.082889,141.782471,7.222743,0.828892,-388.541107,0.083704,0.000000
60.610004,31.702675,-388.674561,-0.002462,0.003276,0.083219,141.020538,7.183929,0.832192,-388.674561,0.084121,0.000000
60.860004,31.611816,-388.630066,-0.002488,0.003290,0.083574,140.616379,7.163340,0.835743,-388.630066,0.084537,0.000000
61.110004,31.363068,-388.630066,-0.002479,0.003306,0.083973,139.509888,7.106973,0.839732,-388.630066,0.084953,0.000000
61.360004,31.852737,-388.674561,-0.002453,0.003323,0.084407,141.688049,7.217934,0.844069,-388.674561,0.085378,0.000000
61.610004,31.964081,-388.674561,-0.002427,0.003336,0.084728,142.183334,7.243164,0.847279,-388.674561,0.085794,0.000000
61.860004,32.296982,-388.674561,-0.002453,0.003352,0.085144,143.664154,7.318601,0.851442,-388.674561,0.086211,0.000000
62.110004,32.539024,-388.674561,-0.002436,0.003370,0.085595,144.740814,7.373448,0.855954,-388.674561,0.086627,0.000000
62.360004,33.348930,-388.719025,-0.002453,0.003393,0.086176,148.343445,7.556975,0.861760,-388.719025,0.087044,0.000000
62.610004,33.639755,-388.763519,-0.002427,0.003409,0.086592,149.637100,7.622878,0.865923,-388.763519,0.087460,0.000000
62.860004,33.393242,-388.674561,-0.002453,0.003421,0.086896,148.540558,7.567017,0.868959,-388.674561,0.087876,0.000000
63.110004,33.546661,-388.763519,-0.002445,0.003438,0.087321,149.223007,7.601782,0.873206,-388.763519,0.088293,0.000000
63.360004,34.142456,-388.763519,-0.002432,0.003457,0.087807,151.873230,7.736791,0.878065,-388.763519,0.088709,0.000000
63.610004,34.222519,-388.807983,-0.002406,0.003470,0.088145,152.229370,7.754934,0.881449,-388.807983,0.089124,0.000000
63.860004,34.152512,-388.852478,-0.002432,0.003480,0.088396,151.917953,7.739070,0.883962,-388.852478,0.089541,0.000000
64.110001,34.353592,-388.807983,-0.002393,0.003493,0.088726,152.812408,7.784635,0.887255,-388.807983,0.089957,0.000000
64.360001,35.478531,-388.852478,-0.002397,0.003518,0.089367,157.816391,8.039550,0.893674,-388.852478,0.090373,0.000000
64.610001,36.067253,-388.807983,-0.002363,0.003535,0.089784,160.435150,8.172956,0.897838,-388.807983,0.090790,0.000000
64.860001,36.521545,-388.852478,-0.002402,0.003552,0.090226,162.455948,8.275901,0.902258,-388.852478,0.091206,0.000000
65.110001,36.762474,-388.852478,-0.002384,0.003565,0.090547,163.527649,8.330496,0.905468,-388.852478,0.091622,0.000000
65.360001,37.490456,-388.941437,-0.002354,0.003586,0.091085,166.765869,8.495459,0.910850,-388.941437,0.092039,0.000000
65.610001,37.996140,-388.941437,-0.002324,0.003602,0.091484,169.015274,8.610048,0.914839,-388.941437,0.092455,0.000000
65.860001,37.876984,-388.985931,-0.002337,0.003611,0.091726,168.485245,8.583047,0.917262,-388.985931,0.092871,0.000000
66.110001,38.152161,-388.941437,-0.002341,0.003623,0.092012,169.709290,8.645403,0.920123,-388.941437,0.093287,0.000000
66.360001,40.183830,-388.941437,-0.002345,0.003655,0.092828,178.746597,9.105785,0.928276,-388.941437,0.093712,0.000000
66.610001,40.392731,-388.985931,-0.002333,0.003668,0.093175,179.675842,9.153123,0.931750,-388.985931,0.094129,0.000000
66.860001,40.807182,-388.985931,-0.002315,0.003683,0.093547,181.519409,9.247040,0.935475,-388.985931,0.094545,0.000000
67.110001,41.788757,-389.074890,-0.002315,0.003703,0.094068,185.885681,9.469468,0.940683,-389.074890,0.094962,0.000000
67.360001,42.587120,-389.030396,-0.002294,0.003722,0.094536,189.436966,9.650380,0.945361,-389.030396,0.095377,0.000000
67.610001,42.599777,-389.030396,-0.002255,0.003731,0.094771,189.493271,9.653248,0.947707,-389.030396,0.095793,0.000000
67.860001,43.197441,-389.030396,-0.002294,0.003747,0.095178,192.151810,9.788680,0.951780,-389.030396,0.096210,0.000000
68.110001,44.739059,-389.030396,-0.002276,0.003772,0.095820,199.009277,10.138016,0.958199,-389.030396,0.096626,0.000000
68.360001,45.336716,-389.030396,-0.002233,0.003788,0.096210,201.667786,10.273447,0.962098,-389.030396,0.097042,0.000000
68.610001,45.773888,-389.074890,-0.002264,0.003802,0.096566,203.612427,10.372511,0.965655,-389.074890,0.097459,0.000000
68.860001,46.246056,-389.119354,-0.002242,0.003816,0.096921,205.712723,10.479506,0.969213,-389.119354,0.097875,0.000000
69.110001,47.387749,-389.119354,-0.002238,0.003835,0.097407,210.791229,10.738217,0.974065,-389.119354,0.098291,0.000000
69.360001,48.157814,-389.119354,-0.002242,0.003850,0.097780,214.216660,10.912717,0.977797,-389.119354,0.098708,0.000000
69.610001,48.267662,-389.119354,-0.002216,0.003858,0.098005,214.705276,10.937609,0.980053,-389.119354,0.099124,0.000000
69.860001,49.353874,-389.163849,-0.002190,0.003877,0.098473,219.537003,11.183748,0.984731,-389.163849,0.099540,0.000000
70.110001,51.075348,-389.163849,-0.002225,0.003902,0.099107,227.194489,11.573839,0.991067,-389.163849,0.099956,0.000000
70.360001,52.109428,-389.208313,-0.002164,0.003920,0.099557,231.794312,11.808165,0.995571,-389.208313,0.100372,0.000000
70.610001,52.232315,-389.208313,-0.002199,0.003930,0.099818,232.340942,11.836012,0.998175,-389.208313,0.100789,0.000000
70.860001,52.894760,-389.252808,-0.002199,0.003944,0.100173,235.287643,11.986124,1.001733,-389.252808,0.101205,0.000000
71.110001,54.084862,-389.252808,-0.002190,0.003963,0.100659,240.581482,12.255805,1.006585,-389.252808,0.101621,0.000000
71.360001,54.959564,-389.297272,-0.002169,0.003978,0.101041,244.472351,12.454015,1.010408,-389.297272,0.102038,0.000000
71.610001,55.544563,-389.297272,-0.002169,0.003989,0.101310,247.074554,12.586578,1.013095,-389.297272,0.102462,0.000000
71.860001,56.944313,-389.341766,-0.002156,0.004011,0.101873,253.300949,12.903766,1.018727,-389.341766,0.102879,0.000000
72.110001,58.662437,-389.341766,-0.002139,0.004033,0.102445,260.943542,13.293098,1.024450,-389.341766,0.103295,0.000000
72.360001,59.494316,-389.341766,-0.002126,0.004047,0.102792,264.643921,13.481606,1.027925,-389.341766,0.103711,0.000000
72.610001,60.060326,-389.386230,-0.002130,0.004059,0.103087,267.161682,13.609864,1.030869,-389.386230,0.104128,0.000000
72.860001,60.904869,-389.386230,-0.002126,0.004076,0.103521,270.918396,13.801241,1.035207,-389.386230,0.104544,0.000000
73.110001,62.049911,-389.386230,-0.002147,0.004092,0.103937,276.011780,14.060711,1.039370,-389.386230,0.104960,0.000000
73.360001,63.438492,-389.386230,-0.002104,0.004110,0.104406,282.188507,14.375367,1.044056,-389.386230,0.105377,0.000000
73.610001,64.468475,-389.430725,-0.002104,0.004129,0.104873,286.770111,14.608766,1.048734,-389.430725,0.105793,0.000000
73.860001,66.105423,-389.430725,-0.002100,0.004148,0.105368,294.051605,14.979703,1.053677,-389.430725,0.106209,0.000000
74.110001,67.045288,-389.475220,-0.002078,0.004163,0.105741,298.232330,15.192679,1.057409,-389.475220,0.106625,0.000000
74.360001,67.089600,-389.519684,-0.002087,0.004161,0.105698,298.429443,15.202721,1.056977,-389.519684,0.105897,0.000000
74.610001,66.460663,-389.430725,-0.002104,0.004161,0.105689,295.631805,15.060202,1.056887,-389.430725,0.105689,0.000000
74.860001,65.920731,-389.475220,-0.002082,0.004161,0.105680,293.230042,14.937851,1.056803,-389.475220,0.105689,0.000000
75.110001,65.448181,-389.519684,-0.002078,0.004161,0.105680,291.128052,14.830770,1.056803,-389.519684,0.105689,0.000000
75.360001,65.056076,-389.519684,-0.002078,0.004161,0.105680,289.383881,14.741918,1.056803,-389.519684,0.105689,0.000000
75.610001,64.712006,-389.564178,-0.002061,0.004161,0.105680,287.853363,14.663950,1.056803,-389.564178,0.105689,0.000000
75.860001,64.408890,-389.564178,-0.002044,0.004161,0.105680,286.505066,14.595263,1.056803,-389.564178,0.105689,0.000000
76.110001,64.113602,-389.608643,-0.002044,0.004161,0.105680,285.191559,14.528350,1.056803,-389.608643,0.105689,0.000000
76.360001,63.876022,-389.564178,-0.002057,0.004160,0.105671,284.134735,14.474514,1.056712,-389.564178,0.105689,0.000000
76.610001,63.650742,-389.608643,-0.002039,0.004160,0.105671,283.132629,14.423464,1.056712,-389.608643,0.105689,0.000000
76.860001,63.438492,-389.564178,-0.002052,0.004160,0.105671,282.188507,14.375367,1.056712,-389.564178,0.105689,0.000000
77.110001,63.268684,-389.653137,-0.002048,0.004160,0.105671,281.433167,14.336888,1.056712,-389.653137,0.105689,0.000000
77.360001,63.091812,-389.608643,-0.002052,0.004160,0.105671,280.646393,14.296809,1.056712,-389.608643,0.105689,0.000000
77.610001,62.932808,-389.608643,-0.002035,0.004160,0.105671,279.939117,14.260777,1.056712,-389.608643,0.105689,0.000000
77.860001,62.774918,-389.608643,-0.002039,0.004160,0.105671,279.236786,14.225000,1.056712,-389.608643,0.105689,0.000000
78.110001,62.649055,-389.653137,-0.002057,0.004160,0.105671,278.676910,14.196479,1.056712,-389.653137,0.105689,0.000000
78.360001,62.507187,-389.697601,-0.002070,0.004160,0.105671,278.045868,14.164330,1.056712,-389.697601,0.105689,0.000000
78.610001,62.383926,-389.697601,-0.002018,0.004160,0.105671,277.497559,14.136400,1.056712,-389.697601,0.105689,0.000000
78.860001,62.272591,-389.697601,-0.002057,0.004160,0.105671,277.002319,14.111171,1.056712,-389.697601,0.105689,0.000000
79.110001,62.167953,-389.742096,-0.002044,0.004160,0.105671,276.536865,14.087460,1.056712,-389.742096,0.105689,0.000000
79.360001,62.058105,-389.742096,-0.002022,0.004160,0.105671,276.048248,14.062568,1.056712,-389.742096,0.105689,0.000000
79.610001,61.957191,-389.786560,-0.002035,0.004160,0.105671,275.599365,14.039701,1.056712,-389.786560,0.105689,0.000000
79.860001,61.874527,-389.742096,-0.002057,0.004160,0.105671,275.231628,14.020968,1.056712,-389.742096,0.105689,0.000000
80.110001,61.776588,-389.742096,-0.002031,0.004160,0.105671,274.795990,13.998775,1.056712,-389.742096,0.105689,0.000000
80.360001,61.695038,-389.831055,-0.002035,0.004160,0.105671,274.433228,13.980295,1.056712,-389.831055,0.105689,0.000000
80.610001,61.623543,-389.831055,-0.002044,0.004160,0.105671,274.115204,13.964094,1.056712,-389.831055,0.105689,0.000000
80.860001,61.529335,-389.831055,-0.002035,0.004160,0.105671,273.696136,13.942747,1.056712,-389.831055,0.105689,0.000000
81.110001,61.464172,-389.875549,-0.002035,0.004160,0.105671,273.406281,13.927980,1.056712,-389.875549,0.105689,0.000000
81.360001,61.405334,-389.831055,-0.002039,0.004160,0.105671,273.144562,13.914648,1.056712,-389.831055,0.105689,0.000000
81.610001,61.323410,-389.875549,-0.002044,0.004160,0.105671,272.780151,13.896084,1.056712,-389.875549,0.105689,0.000000
81.860001,61.259361,-389.875549,-0.002057,0.004160,0.105671,272.495239,13.881570,1.056712,-389.875549,0.105689,0.000000
82.110001,61.191963,-389.920013,-0.002035,0.004160,0.105671,272.195435,13.866298,1.056712,-389.920013,0.105689,0.000000
82.360001,61.131638,-389.875549,-0.002044,0.004160,0.105671,271.927094,13.852627,1.056712,-389.875549,0.105689,0.000000
82.610001,61.075783,-389.920013,-0.002026,0.004160,0.105671,271.678650,13.839970,1.056712,-389.920013,0.105689,0.000000
82.860001,61.026634,-389.920013,-0.002048,0.004160,0.105671,271.460022,13.828834,1.056712,-389.920013,0.105689,0.000000
83.110001,60.963699,-390.008972,-0.002048,0.004160,0.105671,271.180084,13.814571,1.056712,-390.008972,0.105689,0.000000
83.360001,60.916039,-390.008972,-0.002035,0.004160,0.105671,270.968079,13.803772,1.056712,-390.008972,0.105689,0.000000
83.610001,60.837463,-390.008972,-0.002035,0.004160,0.105671,270.618561,13.785966,1.056712,-390.008972,0.105689,0.000000
83.860001,60.803207,-389.964508,-0.002035,0.004160,0.105671,270.466187,13.778204,1.056712,-389.964508,0.105689,0.000000
84.110001,60.751823,-390.008972,-0.002070,0.004160,0.105671,270.237610,13.766560,1.056712,-390.008972,0.105689,0.000000
84.360001,60.699692,-390.053467,-0.002018,0.004160,0.105671,270.005707,13.754747,1.056712,-390.053467,0.105689,0.000000
84.610001,60.669151,-390.053467,-0.001996,0.004160,0.105671,269.869873,13.747826,1.056712,-390.053467,0.105689,0.000000
84.860001,60.624474,-390.097931,-0.002018,0.004160,0.105671,269.671112,13.737702,1.056712,-390.097931,0.105689,0.000000
85.110001,60.576065,-390.053467,-0.002048,0.004160,0.105671,269.455780,13.726732,1.056712,-390.053467,0.105689,0.000000
85.360001,60.539200,-390.097931,-0.002044,0.004160,0.105671,269.291809,13.718379,1.056712,-390.097931,0.105689,0.000000
85.610001,60.479248,-390.142426,-0.002039,0.004160,0.105671,269.025146,13.704793,1.056712,-390.142426,0.105689,0.000000
85.860001,60.437912,-390.186890,-0.002026,0.004160,0.105671,268.841248,13.695426,1.056712,-390.186890,0.105689,0.000000
86.110001,60.412216,-390.142426,-0.002044,0.004160,0.105671,268.726959,13.689604,1.056712,-390.142426,0.105689,0.000000
86.360001,60.374611,-390.097931,-0.002057,0.004160,0.105671,268.559692,13.681082,1.056712,-390.097931,0.105689,0.000000
86.610001,60.341843,-390.186890,-0.002013,0.004160,0.105671,268.413910,13.673657,1.056712,-390.186890,0.105689,0.000000
86.860001,60.303856,-390.186890,-0.002022,0.004160,0.105671,268.244934,13.665049,1.056712,-390.186890,0.105689,0.000000
87.110001,60.260666,-390.275879,-0.002031,0.004160,0.105671,268.052826,13.655262,1.056712,-390.275879,0.105689,0.000000
87.360001,60.228264,-390.275879,-0.002018,0.004160,0.105671,267.908691,13.647920,1.056712,-390.275879,0.105689,0.000000
87.610001,60.199966,-390.231384,-0.002026,0.004160,0.105671,267.782837,13.641508,1.056712,-390.231384,0.105689,0.000000
87.860001,60.156395,-390.231384,-0.002001,0.004160,0.105671,267.589020,13.631634,1.056712,-390.231384,0.105689,0.000000
88.110001,60.112083,-390.275879,-0.002031,0.004160,0.105671,267.391907,13.621593,1.056712,-390.275879,0.105689,0.000000
88.360001,60.100540,-390.275879,-0.002018,0.004160,0.105671,267.340546,13.618977,1.056712,-390.275879,0.105689,0.000000
88.610001,60.061073,-390.275879,-0.002009,0.004160,0.105671,267.165009,13.610034,1.056712,-390.275879,0.105689,0.000000
88.860001,60.039474,-390.275879,-0.002022,0.004160,0.105671,267.068909,13.605140,1.056712,-390.275879,0.105689,0.000000
89.110001,60.005211,-390.320343,-0.002031,0.004160,0.105671,266.916504,13.597375,1.056712,-390.320343,0.105689,0.000000
89.360001,59.980263,-390.275879,-0.002013,0.004160,0.105671,266.805542,13.591722,1.056712,-390.275879,0.105689,0.000000
89.610001,59.946754,-390.364838,-0.002018,0.004160,0.105671,266.656494,13.584128,1.056712,-390.364838,0.105689,0.000000
89.860001,59.909142,-390.320343,-0.002018,0.004160,0.105671,266.489166,13.575605,1.056712,-390.320343,0.105689,0.000000
90.110001,59.890900,-390.409302,-0.002026,0.004160,0.105671,266.408020,13.571472,1.056712,-390.409302,0.105689,0.000000
90.360001,59.852539,-390.364838,-0.002031,0.004160,0.105671,266.237396,13.562778,1.056712,-390.364838,0.105689,0.000000
90.610001,59.848442,-390.364838,-0.002031,0.004160,0.105671,266.219177,13.561852,1.056712,-390.364838,0.105689,0.000000
90.860001,59.803764,-390.364838,-0.002009,0.004160,0.105671,266.020416,13.551726,1.056712,-390.364838,0.105689,0.000000
91.110001,59.785889,-390.409302,-0.002044,0.004160,0.105671,265.940918,13.547676,1.056712,-390.409302,0.105689,0.000000
91.360001,59.759819,-390.453796,-0.002026,0.004160,0.105671,265.824951,13.541769,1.056712,-390.453796,0.105689,0.000000
91.610001,59.736732,-390.498260,-0.002035,0.004160,0.105671,265.722260,13.536537,1.056712,-390.498260,0.105689,0.000000
91.860001,59.722214,-390.498260,-0.002018,0.004160,0.105671,265.657684,13.533247,1.056712,-390.498260,0.105689,0.000000
92.110001,59.673431,-390.542755,-0.002031,0.004160,0.105671,265.440674,13.522193,1.056712,-390.542755,0.105689,0.000000
92.360001,59.658165,-390.498260,-0.002026,0.004160,0.105671,265.372772,13.518733,1.056712,-390.498260,0.105689,0.000000
92.610001,59.632469,-390.542755,-0.002022,0.004160,0.105671,265.258484,13.512911,1.056712,-390.542755,0.105689,0.000000
92.860001,59.622414,-390.542755,-0.002048,0.004160,0.105671,265.213745,13.510633,1.056712,-390.542755,0.105689,0.000000
93.110001,59.601562,-390.498260,-0.002031,0.004160,0.105671,265.121002,13.505907,1.056712,-390.498260,0.105689,0.000000
93.360008,59.569542,-390.587219,-0.002035,0.004160,0.105671,264.978546,13.498652,1.056712,-390.587219,0.105689,0.000000
93.610008,59.551666,-390.587219,-0.002018,0.004160,0.105671,264.899048,13.494601,1.056712,-390.587219,0.105689,0.000000
93.860008,59.518524,-390.676178,-0.002013,0.004160,0.105671,264.751617,13.487090,1.056712,-390.676178,0.105689,0.000000
94.110008,59.511452,-390.631714,-0.002044,0.004160,0.105671,264.720154,13.485488,1.056712,-390.631714,0.105689,0.000000
94.360008,59.480545,-390.542755,-0.002026,0.004160,0.105671,264.582672,13.478484,1.056712,-390.542755,0.105689,0.000000
94.610008,59.463043,-390.631714,-0.002048,0.004160,0.105671,264.504822,13.474519,1.056712,-390.631714,0.105689,0.000000
94.860008,59.433998,-390.676178,-0.002018,0.004160,0.105671,264.375641,13.467937,1.056712,-390.676178,0.105689,0.000000
95.110008,59.415001,-390.676178,-0.002031,0.004160,0.105671,264.291138,13.463632,1.056712,-390.676178,0.105689,0.000000
95.360008,59.403831,-390.765167,-0.001996,0.004160,0.105671,264.241425,13.461101,1.056712,-390.765167,0.105689,0.000000
95.610008,59.378136,-390.676178,-0.002031,0.004160,0.105671,264.127136,13.455277,1.056712,-390.676178,0.105689,0.000000
95.860008,59.361382,-390.720673,-0.002031,0.004160,0.105671,264.052612,13.451481,1.056712,-390.720673,0.105689,0.000000
96.110008,59.336060,-390.765167,-0.002013,0.004160,0.105671,263.939972,13.445744,1.056712,-390.765167,0.105689,0.000000
96.360008,59.309998,-390.765167,-0.002044,0.004160,0.105671,263.824036,13.439838,1.056712,-390.765167,0.105689,0.000000
96.610008,59.289513,-390.720673,-0.002018,0.004160,0.105671,263.732910,13.435195,1.056712,-390.720673,0.105689,0.000000
96.860008,59.258980,-390.809631,-0.002013,0.004160,0.105671,263.597107,13.428277,1.056712,-390.809631,0.105689,0.000000
97.110008,59.265312,-390.809631,-0.002061,0.004160,0.105671,263.625275,13.429712,1.056712,-390.809631,0.105689,0.000000
97.360008,59.231049,-390.765167,-0.002018,0.004160,0.105671,263.472870,13.421947,1.056712,-390.765167,0.105689,0.000000
97.610008,59.223602,-390.898590,-0.002009,0.004160,0.105671,263.439728,13.420260,1.056712,-390.898590,0.105689,0.000000
97.860008,59.201263,-390.809631,-0.002026,0.004160,0.105671,263.340363,13.415198,1.056712,-390.809631,0.105689,0.000000
98.110008,59.171844,-390.765167,-0.002018,0.004160,0.105671,263.209503,13.408532,1.056712,-390.765167,0.105689,0.000000
98.360008,59.151733,-390.809631,-0.002031,0.004160,0.105671,263.120056,13.403975,1.056712,-390.809631,0.105689,0.000000
98.610008,59.141312,-390.898590,-0.002031,0.004160,0.105671,263.073700,13.401612,1.056712,-390.898590,0.105689,0.000000
98.860008,59.127533,-390.898590,-0.002026,0.004160,0.105671,263.012390,13.398490,1.056712,-390.898590,0.105689,0.000000
99.110008,59.110779,-390.898590,-0.002048,0.004160,0.105671,262.937866,13.394693,1.056712,-390.898590,0.105689,0.000000
99.360008,59.100349,-390.943085,-0.002022,0.004160,0.105671,262.891479,13.392331,1.056712,-390.943085,0.105689,0.000000
99.610008,59.084709,-390.898590,-0.002022,0.004160,0.105671,262.821899,13.388786,1.056712,-390.898590,0.105689,0.000000
99.860008,59.064232,-390.898590,-0.002022,0.004160,0.105671,262.730835,13.384147,1.056712,-390.898590,0.105689,0.000000
100.110008,59.034813,-390.898590,-0.002013,0.004160,0.105671,262.599976,13.377481,1.056712,-390.898590,0.105689,0.000000
100.360008,59.024757,-390.987549,-0.002031,0.004160,0.105671,262.555237,13.375201,1.056712,-390.987549,0.105689,0.000000
100.610008,59.019920,-390.943085,-0.002022,0.004160,0.105671,262.533722,13.374104,1.056712,-390.943085,0.105689,0.000000
100.860008,58.994225,-390.943085,-0.002039,0.004160,0.105671,262.419403,13.368282,1.056712,-390.943085,0.105689,0.000000
101.110008,58.981560,-390.987549,-0.002013,0.004160,0.105671,262.363068,13.365413,1.056712,-390.987549,0.105689,0.000000
101.360008,58.976723,-391.032043,-0.002009,0.004160,0.105671,262.341553,13.364317,1.056712,-391.032043,0.105689,0.000000
101.610008,58.951401,-391.076508,-0.002009,0.004160,0.105671,262.228912,13.358578,1.056712,-391.076508,0.105689,0.000000
101.860008,58.942833,-391.076508,-0.002035,0.004160,0.105671,262.190826,13.356637,1.056712,-391.076508,0.105689,0.000000
102.110008,58.909698,-391.032043,-0.002018,0.004160,0.105671,262.043427,13.349128,1.056712,-391.032043,0.105689,0.000000
102.360008,58.905228,-391.076508,-0.002001,0.004160,0.105671,262.023529,13.348115,1.056712,-391.076508,0.105689,0.000000
102.610008,58.882881,-391.121002,-0.002022,0.004160,0.105671,261.924133,13.343051,1.056712,-391.121002,0.105689,0.000000
102.860008,58.878418,-391.121002,-0.001992,0.004160,0.105671,261.904297,13.342040,1.056712,-391.121002,0.105689,0.000000
103.110008,58.863152,-391.076508,-0.001992,0.004160,0.105671,261.836365,13.338581,1.056712,-391.076508,0.105689,0.000000
103.360008,58.855331,-391.165497,-0.001992,0.004160,0.105671,261.801575,13.336809,1.056712,-391.165497,0.105689,0.000000
103.610008,58.845650,-391.165497,-0.002022,0.004160,0.105671,261.758514,13.334615,1.056712,-391.165497,0.105689,0.000000
103.860008,58.824791,-391.121002,-0.002035,0.004160,0.105671,261.665741,13.329888,1.056712,-391.121002,0.105689,0.000000
104.110008,58.801338,-391.165497,-0.002026,0.004160,0.105671,261.561401,13.324574,1.056712,-391.165497,0.105689,0.000000
104.360008,58.786812,-391.209961,-0.002013,0.004160,0.105671,261.496796,13.321282,1.056712,-391.209961,0.105689,0.000000
104.610008,58.780106,-391.209961,-0.002013,0.004160,0.105671,261.466980,13.319762,1.056712,-391.209961,0.105689,0.000000
104.700005,58.777130,-391.254456,-0.002039,0.004160,0.105671,261.453735,13.319088,1.056712,-391.254456,0.105689,0.000000