File: Data/compression 14/AutoNoHeating-10-14-5-240726_07262024_162844.csv
Time (sec),S:Load (lbs),S:HL1 (DIM),S:LVDT (in),S:Position (in),Ch:Position (mm),Ch:Load (N),Ch:Stress (MPa),Ch:Strain (mm/mm),Ch:HL1 (DIM),Set Point (),Cycles ()
0.210000,0.001862,-315.280975,-0.009240,-0.004553,-0.115653,0.008281,0.000422,-1.156528,-315.280975,-0.115454,0.000000
0.460000,-0.011543,-315.280975,-0.009235,-0.004524,-0.114907,-0.051347,-0.002616,-1.149071,-315.280975,-0.114413,0.000000
0.710000,-0.022346,-315.325470,-0.009231,-0.004380,-0.111256,-0.099402,-0.005064,-1.112562,-315.325470,-0.110250,0.000000
0.960000,-0.046921,-315.280975,-0.009046,-0.004227,-0.107354,-0.208714,-0.010632,-1.073540,-315.280975,-0.106088,0.000000
1.210000,-0.018250,-315.280975,-0.008873,-0.004065,-0.103252,-0.081178,-0.004135,-1.032519,-315.280975,-0.101908,0.000000
1.460000,-0.001122,-315.325470,-0.008714,-0.003892,-0.098846,-0.004989,-0.000254,-0.988463,-315.325470,-0.097745,0.000000
1.710000,0.001862,-315.414429,-0.008532,-0.003730,-0.094744,0.008281,0.000422,-0.947442,-315.414429,-0.093582,0.000000
1.960000,0.011543,-315.325470,-0.008360,-0.003563,-0.090504,0.051347,0.002616,-0.905037,-315.325470,-0.089420,0.000000
2.210000,0.009682,-315.369934,-0.008213,-0.003409,-0.086601,0.043066,0.002194,-0.866007,-315.369934,-0.085257,0.000000
2.460000,-0.007820,-315.458893,-0.008054,-0.003235,-0.082178,-0.034786,-0.001772,-0.821784,-315.458893,-0.081094,0.000000
2.710000,-0.004097,-315.414429,-0.007886,-0.003074,-0.078067,-0.018224,-0.000928,-0.780672,-315.414429,-0.076932,0.000000
2.960000,0.013031,-315.458893,-0.007696,-0.002909,-0.073896,0.057965,0.002953,-0.738963,-315.458893,-0.072768,0.000000
3.210000,-0.017128,-315.503387,-0.007511,-0.002740,-0.069594,-0.076189,-0.003881,-0.695944,-315.503387,-0.068588,0.000000
3.460000,-0.049156,-315.458893,-0.007317,-0.002580,-0.065527,-0.218658,-0.011139,-0.655271,-315.458893,-0.064426,0.000000
3.710000,0.002235,-315.503387,-0.007161,-0.002415,-0.061339,0.009944,0.000507,-0.613388,-315.503387,-0.060263,0.000000
3.960000,0.026436,-315.547852,-0.006980,-0.002252,-0.057211,0.117593,0.005990,-0.572110,-315.547852,-0.056100,0.000000
4.210000,-0.001122,-315.592346,-0.006812,-0.002087,-0.053014,-0.004989,-0.000254,-0.530135,-315.592346,-0.051938,0.000000
4.460000,0.001114,-315.547852,-0.006640,-0.001925,-0.048886,0.004955,0.000252,-0.488857,-315.547852,-0.047775,0.000000
4.710000,0.010796,-315.547852,-0.006441,-0.001765,-0.044835,0.048021,0.002446,-0.448351,-315.547852,-0.043613,0.000000
4.960000,-0.006706,-315.547852,-0.006316,-0.001592,-0.040439,-0.029831,-0.001520,-0.404386,-315.547852,-0.039433,0.000000
5.210000,-0.041336,-315.636841,-0.006127,-0.001438,-0.036519,-0.183872,-0.009367,-0.365189,-315.636841,-0.035270,0.000000
5.460000,-0.001862,-315.681305,-0.005941,-0.001275,-0.032382,-0.008281,-0.000422,-0.323820,-315.681305,-0.031107,0.000000
5.710000,0.026810,-315.636841,-0.005795,-0.001104,-0.028046,0.119255,0.006075,-0.280461,-315.636841,-0.026945,0.000000
5.960001,-0.002235,-315.681305,-0.005622,-0.000941,-0.023901,-0.009944,-0.000507,-0.239009,-315.681305,-0.022782,0.000000
6.210001,0.011917,-315.681305,-0.005433,-0.000774,-0.019669,0.053010,0.002700,-0.196686,-315.681305,-0.018619,0.000000
6.460001,0.029419,-315.725800,-0.005273,-0.000622,-0.015800,0.130862,0.006666,-0.158004,-315.725800,-0.014457,0.000000
6.710001,0.024574,-315.770264,-0.005096,-0.000447,-0.011343,0.109312,0.005569,-0.113433,-315.770264,-0.010294,0.000000
6.960001,-0.002609,-315.725800,-0.004915,-0.000284,-0.007224,-0.011607,-0.000591,-0.072239,-315.725800,-0.006114,0.000000
7.210001,0.008194,-315.725800,-0.004769,-0.000122,-0.003087,0.036449,0.001857,-0.030870,-315.725800,-0.001951,0.000000
7.460001,0.060699,-315.859222,-0.004596,0.000047,0.001197,0.270005,0.013755,0.011968,-315.859222,0.002212,0.000000
7.710001,0.429718,-315.770264,-0.004437,0.000206,0.005221,1.911481,0.097375,0.052209,-315.770264,0.006375,0.000000
7.960001,0.592819,-315.814758,-0.004372,-0.000000,-0.000008,2.636992,0.134335,-0.000083,-315.814758,0.000208,0.000000
8.210000,0.563774,-315.859222,-0.004402,-0.000000,-0.000008,2.507792,0.127753,-0.000083,-315.859222,0.000208,0.000000
8.460000,0.577179,-315.859222,-0.004393,-0.000000,-0.000008,2.567420,0.130791,-0.000083,-315.859222,0.000459,0.000000
8.710000,0.589088,-315.859222,-0.004368,-0.000000,-0.000008,2.620396,0.133489,-0.000083,-315.859222,0.000876,0.000000
8.960000,0.593185,-315.903717,-0.004372,-0.000000,-0.000008,2.638621,0.134418,-0.000083,-315.903717,0.001292,0.000000
9.210000,0.829269,-315.903717,-0.004346,0.000024,0.000616,3.688775,0.187915,0.006162,-315.903717,0.001709,0.000000
9.460000,0.989021,-315.948181,-0.004355,0.000046,0.001162,4.399386,0.224115,0.011620,-315.948181,0.002125,0.000000
9.710000,1.121216,-315.903717,-0.004320,0.000065,0.001648,4.987417,0.254071,0.016479,-315.903717,0.002541,0.000000
9.960000,1.243721,-315.948181,-0.004337,0.000081,0.002064,5.532347,0.281831,0.020643,-315.948181,0.002966,0.000000
10.210000,1.364372,-316.037170,-0.004290,0.000096,0.002446,6.069031,0.309171,0.024458,-316.037170,0.003382,0.000000
10.460000,1.570297,-315.992676,-0.004307,0.000119,0.003018,6.985031,0.355834,0.030181,-315.992676,0.003799,0.000000
10.710000,1.718498,-316.037170,-0.004268,0.000134,0.003391,7.644262,0.389417,0.033913,-316.037170,0.004215,0.000000
10.960001,1.788132,-315.992676,-0.004255,0.000142,0.003617,7.954007,0.405196,0.036168,-315.992676,0.004631,0.000000
11.210001,1.975060,-316.037170,-0.004251,0.000156,0.003954,8.785503,0.447555,0.039545,-316.037170,0.005048,0.000000
11.460001,2.285622,-316.081635,-0.004225,0.000183,0.004649,10.166953,0.517929,0.046486,-316.081635,0.005464,0.000000
11.710001,2.416695,-316.170593,-0.004199,0.000196,0.004987,10.749994,0.547631,0.049870,-316.170593,0.005880,0.000000
11.960001,2.553360,-316.081635,-0.004208,0.000210,0.005325,11.357912,0.578600,0.053246,-316.081635,0.006297,0.000000
12.210001,2.802101,-316.126129,-0.004174,0.000229,0.005811,12.464369,0.634965,0.058106,-316.126129,0.006712,0.000000
12.460001,2.926849,-316.126129,-0.004161,0.000242,0.006140,13.019277,0.663234,0.061399,-316.126129,0.007128,0.000000
12.710001,3.260864,-316.170593,-0.004161,0.000263,0.006669,14.505049,0.738922,0.066690,-316.170593,0.007545,0.000000
12.960001,3.249695,-316.215088,-0.004130,0.000271,0.006895,14.455364,0.736391,0.068946,-316.215088,0.007961,0.000000
13.210001,3.596375,-316.170593,-0.004113,0.000293,0.007432,15.997473,0.814950,0.074320,-316.170593,0.008377,0.000000
13.460001,3.899483,-316.215088,-0.004113,0.000315,0.007996,17.345766,0.883635,0.079960,-316.215088,0.008794,0.000000
13.710001,4.030190,-316.215088,-0.004070,0.000329,0.008369,17.927177,0.913254,0.083692,-316.215088,0.009210,0.000000
13.960001,4.150093,-316.259552,-0.004083,0.000342,0.008698,18.460535,0.940425,0.086984,-316.259552,0.009627,0.000000
14.210001,4.356384,-316.304047,-0.004049,0.000358,0.009097,19.378164,0.987171,0.090974,-316.304047,0.010043,0.000000
14.460001,4.643486,-316.259552,-0.004049,0.000379,0.009617,20.655258,1.052229,0.096174,-316.259552,0.010459,0.000000
14.710001,4.825577,-316.215088,-0.004014,0.000394,0.009999,21.465237,1.093491,0.099989,-316.215088,0.010876,0.000000
14.960001,4.900047,-316.259552,-0.004027,0.000406,0.010320,21.796499,1.110367,0.103199,-316.259552,0.011291,0.000000
15.210001,5.176720,-316.304047,-0.004014,0.000422,0.010719,23.027199,1.173061,0.107188,-316.304047,0.011717,0.000000
15.460001,5.554680,-316.348511,-0.003992,0.000445,0.011300,24.708450,1.258708,0.113002,-316.348511,0.012133,0.000000
15.710001,5.540154,-316.393005,-0.003971,0.000456,0.011595,24.643833,1.255417,0.115946,-316.393005,0.012549,0.000000
15.960001,5.731186,-316.393005,-0.003975,0.000474,0.012037,25.493587,1.298705,0.120375,-316.393005,0.012966,0.000000
16.210001,5.920349,-316.393005,-0.003936,0.000490,0.012436,26.335028,1.341570,0.124364,-316.393005,0.013381,0.000000
16.460001,6.192924,-316.348511,-0.003928,0.000508,0.012913,27.547504,1.403337,0.129133,-316.348511,0.013797,0.000000
16.710001,6.253624,-316.481964,-0.003932,0.000522,0.013260,27.817509,1.417091,0.132600,-316.481964,0.014214,0.000000
16.960001,6.362358,-316.481964,-0.003889,0.000533,0.013546,28.301182,1.441731,0.135461,-316.481964,0.014630,0.000000
17.210001,6.772339,-316.526459,-0.003876,0.000553,0.014058,30.124868,1.534634,0.140579,-316.526459,0.015046,0.000000
17.460001,6.922028,-316.526459,-0.003867,0.000574,0.014570,30.790716,1.568554,0.145696,-316.526459,0.015463,0.000000
17.710001,6.955170,-316.481964,-0.003846,0.000586,0.014891,30.938139,1.576064,0.148905,-316.481964,0.015879,0.000000
17.960001,7.234451,-316.526459,-0.003859,0.000607,0.015420,32.180447,1.639350,0.154197,-316.526459,0.016295,0.000000
18.210001,7.284348,-316.570923,-0.003833,0.000622,0.015792,32.402397,1.650657,0.157921,-316.570923,0.016712,0.000000
18.460001,7.555435,-316.526459,-0.003790,0.000641,0.016269,33.608253,1.712086,0.162690,-316.526459,0.017128,0.000000
18.710001,7.482452,-316.615417,-0.003786,0.000650,0.016512,33.283611,1.695548,0.165120,-316.615417,0.017545,0.000000
18.960001,7.656349,-316.570923,-0.003786,0.000664,0.016859,34.057140,1.734954,0.168587,-316.570923,0.017960,0.000000
19.210001,8.229431,-316.570923,-0.003790,0.000691,0.017561,36.606339,1.864816,0.175612,-316.570923,0.018376,0.000000
19.460001,8.106178,-316.615417,-0.003742,0.000705,0.017900,36.058083,1.836886,0.178995,-316.615417,0.018793,0.000000
19.710001,8.086441,-316.704376,-0.003721,0.000719,0.018255,35.970287,1.832414,0.182553,-316.704376,0.019209,0.000000
19.960001,8.390671,-316.704376,-0.003721,0.000737,0.018732,37.323566,1.901353,0.187322,-316.704376,0.019625,0.000000
20.210001,8.484131,-316.659882,-0.003725,0.000751,0.019088,37.739300,1.922531,0.190880,-316.659882,0.020050,0.000000
20.460001,8.699364,-316.704376,-0.003691,0.000770,0.019547,38.696701,1.971304,0.195475,-316.704376,0.020466,0.000000
20.710001,8.666595,-316.704376,-0.003682,0.000781,0.019842,38.550941,1.963879,0.198419,-316.704376,0.020883,0.000000
20.960001,8.894112,-316.793335,-0.003669,0.000799,0.020302,39.562984,2.015435,0.203022,-316.793335,0.021299,0.000000
21.210001,9.210258,-316.748840,-0.003682,0.000821,0.020865,40.969276,2.087075,0.208654,-316.748840,0.021715,0.000000
21.460001,9.288834,-316.793335,-0.003630,0.000839,0.021308,41.318794,2.104880,0.213082,-316.793335,0.022132,0.000000
21.710001,9.284737,-316.837830,-0.003643,0.000852,0.021646,41.300571,2.103951,0.216458,-316.837830,0.022548,0.000000
21.960001,9.416183,-316.882294,-0.003609,0.000867,0.022011,41.885277,2.133738,0.220107,-316.882294,0.022964,0.000000
22.210001,9.587845,-316.882294,-0.003630,0.000883,0.022426,42.648865,2.172637,0.224263,-316.882294,0.023381,0.000000
22.460001,9.714455,-316.837830,-0.003604,0.000898,0.022809,43.212051,2.201327,0.228085,-316.837830,0.023797,0.000000
22.710001,9.621361,-316.882294,-0.003566,0.000908,0.023068,42.797951,2.180232,0.230682,-316.882294,0.024213,0.000000
22.960001,9.767326,-316.926788,-0.003540,0.000922,0.023424,43.447239,2.213308,0.234240,-316.926788,0.024629,0.000000
23.210001,10.477814,-316.926788,-0.003574,0.000955,0.024265,46.607643,2.374306,0.242650,-316.926788,0.025045,0.000000
23.460001,10.154594,-316.926788,-0.003548,0.000966,0.024525,45.169891,2.301064,0.245254,-316.926788,0.025462,0.000000
23.710001,10.213806,-316.971252,-0.003523,0.000981,0.024924,45.433277,2.314481,0.249243,-316.971252,0.025878,0.000000
23.960001,10.341896,-316.971252,-0.003518,0.000998,0.025341,46.003052,2.343507,0.253406,-316.971252,0.026294,0.000000
24.210001,10.504997,-317.015747,-0.003484,0.001017,0.025835,46.728561,2.380466,0.258349,-317.015747,0.026711,0.000000
24.460001,10.605911,-317.060211,-0.003484,0.001031,0.026191,47.177448,2.403334,0.261907,-317.060211,0.027127,0.000000
24.710001,10.754486,-317.015747,-0.003492,0.001049,0.026641,47.838345,2.437001,0.266411,-317.015747,0.027543,0.000000
24.960001,10.964134,-317.104706,-0.003462,0.001070,0.027170,48.770905,2.484508,0.271702,-317.104706,0.027960,0.000000
25.210001,10.931740,-317.104706,-0.003441,0.001084,0.027543,48.626808,2.477168,0.275434,-317.104706,0.028384,0.000000
25.460001,10.964134,-317.060211,-0.003454,0.001100,0.027933,48.770905,2.484508,0.279333,-317.060211,0.028801,0.000000
25.710001,10.842369,-317.104706,-0.003428,0.001110,0.028185,48.229267,2.456916,0.281854,-317.104706,0.029217,0.000000
25.960001,10.999878,-317.149170,-0.003402,0.001124,0.028558,48.929901,2.492608,0.285578,-317.149170,0.029633,0.000000
26.210001,11.176758,-317.104706,-0.003410,0.001141,0.028983,49.716702,2.532689,0.289832,-317.104706,0.030050,0.000000
26.460001,11.209900,-317.193665,-0.003389,0.001153,0.029295,49.864124,2.540200,0.292951,-317.193665,0.030466,0.000000
26.710001,11.602005,-317.149170,-0.003385,0.001176,0.029859,51.608295,2.629052,0.298590,-317.149170,0.030882,0.000000
26.960001,11.931557,-317.149170,-0.003359,0.001200,0.030483,53.074215,2.703729,0.304828,-317.149170,0.031298,0.000000
27.210001,11.656746,-317.193665,-0.003367,0.001213,0.030813,51.851795,2.641456,0.308128,-317.193665,0.031714,0.000000
27.460001,11.455292,-317.282623,-0.003341,0.001225,0.031116,50.955681,2.595806,0.311164,-317.282623,0.032131,0.000000
27.710001,11.740532,-317.327118,-0.003307,0.001244,0.031602,52.224495,2.660443,0.316016,-317.327118,0.032547,0.000000
27.960001,11.660095,-317.282623,-0.003311,0.001258,0.031957,51.866695,2.642215,0.319574,-317.282623,0.032963,0.000000
28.210001,11.914055,-317.282623,-0.003316,0.001275,0.032374,52.996365,2.699764,0.323737,-317.282623,0.033380,0.000000
28.460001,11.677971,-317.327118,-0.003316,0.001284,0.032608,51.946209,2.646266,0.326076,-317.327118,0.033796,0.000000
28.710001,11.931557,-317.282623,-0.003303,0.001303,0.033102,53.074215,2.703729,0.331019,-317.282623,0.034212,0.000000
28.960001,12.599220,-317.282623,-0.003290,0.001334,0.033874,56.044132,2.855024,0.338741,-317.282623,0.034629,0.000000
29.210001,12.267441,-317.327118,-0.003268,0.001349,0.034256,54.568302,2.779842,0.342556,-317.327118,0.035045,0.000000
29.460001,12.023537,-317.327118,-0.003251,0.001361,0.034567,53.483364,2.724572,0.345674,-317.327118,0.035461,0.000000
29.710001,12.106201,-317.371582,-0.003251,0.001377,0.034966,53.851074,2.743304,0.349664,-317.371582,0.035877,0.000000
29.960001,12.126678,-317.416077,-0.003238,0.001393,0.035374,53.942162,2.747945,0.353744,-317.416077,0.036293,0.000000
30.210001,12.356804,-317.371582,-0.003221,0.001409,0.035782,54.965809,2.800092,0.357816,-317.371582,0.036710,0.000000
30.460001,12.105453,-317.460541,-0.003247,0.001418,0.036007,53.847748,2.743135,0.360072,-317.460541,0.037135,0.000000
30.710001,12.610764,-317.416077,-0.003229,0.001442,0.036614,56.095478,2.857640,0.366143,-317.416077,0.037551,0.000000
30.960001,12.648750,-317.460541,-0.003178,0.001459,0.037056,56.264450,2.866248,0.370564,-317.460541,0.037967,0.000000
31.210001,12.506874,-317.505035,-0.003191,0.001473,0.037421,55.633354,2.834098,0.374213,-317.505035,0.038383,0.000000
31.460001,12.595871,-317.549500,-0.003165,0.001491,0.037863,56.029232,2.854265,0.378633,-317.549500,0.038800,0.000000
31.710001,12.661034,-317.593994,-0.003182,0.001510,0.038358,56.319092,2.869031,0.383576,-317.593994,0.039216,0.000000
31.960001,12.659172,-317.505035,-0.003186,0.001528,0.038817,56.310810,2.868609,0.388171,-317.505035,0.039632,0.000000
32.210003,12.397766,-317.505035,-0.003147,0.001539,0.039103,55.148018,2.809374,0.391033,-317.505035,0.040049,0.000000
32.460003,12.218658,-317.549500,-0.003139,0.001550,0.039372,54.351307,2.768788,0.393720,-317.549500,0.040465,0.000000
32.710003,12.875153,-317.593994,-0.003134,0.001576,0.040023,57.271538,2.917552,0.400230,-317.593994,0.040881,0.000000
32.960003,12.786156,-317.682953,-0.003126,0.001592,0.040430,56.875660,2.897384,0.404302,-317.682953,0.041298,0.000000
33.210003,12.526978,-317.638458,-0.003130,0.001604,0.040742,55.722778,2.838654,0.407421,-317.638458,0.041714,0.000000
33.460003,12.568314,-317.638458,-0.003087,0.001621,0.041176,55.906651,2.848021,0.411759,-317.638458,0.042130,0.000000
33.710003,12.543365,-317.727448,-0.003091,0.001635,0.041532,55.795677,2.842367,0.415317,-317.727448,0.042546,0.000000
33.960003,12.711304,-317.727448,-0.003091,0.001655,0.042034,56.542702,2.880423,0.420343,-317.727448,0.042962,0.000000
34.210003,12.598480,-317.727448,-0.003065,0.001667,0.042347,56.040840,2.854856,0.423469,-317.727448,0.043379,0.000000
34.460003,12.609650,-317.727448,-0.003074,0.001680,0.042676,56.090523,2.857387,0.426762,-317.727448,0.043795,0.000000
34.710003,13.280663,-317.771912,-0.003061,0.001710,0.043439,59.075336,3.009441,0.434392,-317.771912,0.044211,0.000000
34.960003,12.925789,-317.771912,-0.003044,0.001725,0.043804,57.496780,2.929026,0.438041,-317.771912,0.044628,0.000000
35.210003,12.763435,-317.771912,-0.003014,0.001739,0.044177,56.774597,2.892236,0.441765,-317.771912,0.045044,0.000000
35.460003,12.601082,-317.771912,-0.003061,0.001753,0.044523,56.052410,2.855446,0.445232,-317.771912,0.045469,0.000000
35.710003,12.971596,-317.860870,-0.003040,0.001771,0.044983,57.700539,2.939406,0.449835,-317.860870,0.045885,0.000000
35.960003,12.982765,-317.816406,-0.003018,0.001787,0.045400,57.750225,2.941937,0.453998,-317.816406,0.046301,0.000000
36.210003,12.731789,-317.860870,-0.002992,0.001797,0.045651,56.633823,2.885065,0.456511,-317.860870,0.046718,0.000000
36.460003,12.875519,-317.860870,-0.003005,0.001811,0.046006,57.273167,2.917634,0.460062,-317.860870,0.047134,0.000000
36.710003,13.737564,-317.905365,-0.002997,0.001841,0.046770,61.107738,3.112977,0.467699,-317.905365,0.047550,0.000000
36.960003,13.256088,-317.949829,-0.002949,0.001854,0.047091,58.966026,3.003873,0.470909,-317.949829,0.047967,0.000000
37.210003,13.227043,-317.949829,-0.002949,0.001870,0.047498,58.836826,2.997291,0.474982,-317.949829,0.048383,0.000000
37.460003,13.143257,-317.994324,-0.002945,0.001884,0.047854,58.464127,2.978305,0.478539,-317.994324,0.048799,0.000000
37.710003,13.288483,-317.994324,-0.002945,0.001900,0.048261,59.110123,3.011213,0.482612,-317.994324,0.049215,0.000000
37.960003,13.337265,-317.949829,-0.002928,0.001917,0.048695,59.327118,3.022268,0.486949,-317.949829,0.049631,0.000000
38.210003,13.203957,-318.038788,-0.002915,0.001928,0.048981,58.734131,2.992059,0.489811,-318.038788,0.050048,0.000000
38.460003,13.272842,-318.038788,-0.002928,0.001940,0.049276,59.040550,3.007669,0.492763,-318.038788,0.050464,0.000000
38.710003,13.939758,-318.083282,-0.002902,0.001966,0.049935,62.007141,3.158794,0.499349,-318.083282,0.050880,0.000000
38.960003,13.765121,-318.083282,-0.002867,0.001981,0.050325,61.230320,3.119221,0.503255,-318.083282,0.051297,0.000000
39.210003,13.853371,-318.083282,-0.002897,0.002000,0.050811,61.622871,3.139219,0.508107,-318.083282,0.051713,0.000000
39.460003,13.771080,-318.127777,-0.002859,0.002015,0.051175,61.256824,3.120571,0.511748,-318.127777,0.052129,0.000000
39.710003,14.093552,-318.083282,-0.002871,0.002035,0.051696,62.691250,3.193644,0.516956,-318.083282,0.052546,0.000000
39.960003,13.791931,-318.172241,-0.002850,0.002046,0.051956,61.349575,3.125296,0.519560,-318.172241,0.052961,0.000000
40.210003,13.850021,-318.172241,-0.002854,0.002061,0.052338,61.607971,3.138460,0.523375,-318.172241,0.053378,0.000000
40.460003,14.611519,-318.216736,-0.002854,0.002085,0.052970,64.995285,3.311017,0.529704,-318.216736,0.053803,0.000000
40.710003,14.497200,-318.216736,-0.002837,0.002102,0.053387,64.486763,3.285112,0.533867,-318.216736,0.054219,0.000000
40.960003,14.206009,-318.216736,-0.002807,0.002113,0.053681,63.191483,3.219128,0.536812,-318.216736,0.054636,0.000000
41.210003,14.373207,-318.261200,-0.002790,0.002133,0.054167,63.935219,3.257015,0.541671,-318.261200,0.055051,0.000000
41.460003,14.517685,-318.172241,-0.002802,0.002148,0.054557,64.577888,3.289754,0.545570,-318.172241,0.055468,0.000000
41.710003,14.567955,-318.261200,-0.002772,0.002163,0.054939,64.801498,3.301146,0.549393,-318.261200,0.055884,0.000000
41.960003,14.461456,-318.305695,-0.002798,0.002175,0.055251,64.327774,3.277013,0.552511,-318.305695,0.056300,0.000000
42.210003,14.749672,-318.305695,-0.002772,0.002195,0.055745,65.609818,3.342323,0.557454,-318.305695,0.056717,0.000000
42.460003,15.226311,-318.350159,-0.002738,0.002218,0.056335,67.730011,3.450331,0.563351,-318.350159,0.057133,0.000000
42.710003,14.994690,-318.305695,-0.002755,0.002232,0.056699,66.699715,3.397845,0.566992,-318.305695,0.057549,0.000000
42.960003,14.856171,-318.394653,-0.002746,0.002247,0.057072,66.083549,3.366457,0.570724,-318.394653,0.057966,0.000000
43.210003,14.879631,-318.305695,-0.002742,0.002262,0.057445,66.187904,3.371773,0.574449,-318.305695,0.058382,0.000000
43.460003,15.154068,-318.350159,-0.002721,0.002280,0.057913,67.408661,3.433961,0.579134,-318.350159,0.058798,0.000000
43.710003,15.108269,-318.394653,-0.002703,0.002291,0.058200,67.204933,3.423583,0.581996,-318.394653,0.059215,0.000000
43.960003,15.068420,-318.439117,-0.002729,0.002305,0.058555,67.027679,3.414553,0.585554,-318.439117,0.059630,0.000000
44.210003,15.237854,-318.483612,-0.002703,0.002320,0.058937,67.781357,3.452947,0.589369,-318.483612,0.060047,0.000000
44.460003,15.941261,-318.439117,-0.002665,0.002346,0.059579,70.910271,3.612341,0.595788,-318.439117,0.060463,0.000000
44.710003,15.718956,-318.483612,-0.002695,0.002362,0.059995,69.921410,3.561966,0.599951,-318.483612,0.060879,0.000000
44.960003,15.610970,-318.483612,-0.002660,0.002378,0.060394,69.441063,3.537496,0.603941,-318.483612,0.061296,0.000000
45.210003,15.418083,-318.483612,-0.002652,0.002391,0.060741,68.583061,3.493788,0.607408,-318.483612,0.061712,0.000000
45.460003,15.722305,-318.528076,-0.002656,0.002408,0.061165,69.936310,3.562725,0.611654,-318.528076,0.062128,0.000000
45.710003,16.038826,-318.572571,-0.002647,0.002428,0.061677,71.344261,3.634450,0.616771,-318.572571,0.062553,0.000000
45.960003,15.648209,-318.572571,-0.002639,0.002436,0.061885,69.606705,3.545935,0.618853,-318.572571,0.062969,0.000000
46.210003,16.322571,-318.617065,-0.002630,0.002462,0.062536,72.606422,3.698748,0.625355,-318.617065,0.063386,0.000000
46.460003,16.227615,-318.661530,-0.002643,0.002479,0.062969,72.184036,3.677230,0.629693,-318.661530,0.063802,0.000000
46.710003,16.230225,-318.617065,-0.002587,0.002495,0.063368,72.195648,3.677822,0.633682,-318.617065,0.064218,0.000000
46.960003,16.057442,-318.661530,-0.002591,0.002508,0.063698,71.427071,3.638668,0.636983,-318.661530,0.064635,0.000000
47.210003,15.801254,-318.617065,-0.002621,0.002515,0.063889,70.287491,3.580616,0.638890,-318.617065,0.065051,0.000000
47.460003,16.433914,-318.750488,-0.002596,0.002537,0.064435,73.101700,3.723978,0.644348,-318.750488,0.065467,0.000000
47.710003,16.395561,-318.706024,-0.002578,0.002550,0.064782,72.931099,3.715287,0.647823,-318.706024,0.065884,0.000000
47.960003,16.416786,-318.750488,-0.002578,0.002562,0.065086,73.025513,3.720097,0.650858,-318.750488,0.066299,0.000000
48.210003,17.542839,-318.794983,-0.002548,0.002595,0.065900,78.034447,3.975264,0.659003,-318.794983,0.066716,0.000000
48.460003,17.066948,-318.750488,-0.002565,0.002609,0.066274,75.917580,3.867426,0.662735,-318.750488,0.067132,0.000000
48.710003,16.833839,-318.794983,-0.002548,0.002621,0.066585,74.880661,3.814603,0.665854,-318.794983,0.067548,0.000000
48.960003,17.182381,-318.794983,-0.002548,0.002641,0.067089,76.431046,3.893583,0.670888,-318.794983,0.067965,0.000000
49.210003,16.818947,-318.839447,-0.002544,0.002651,0.067340,74.814415,3.811228,0.673401,-318.839447,0.068381,0.000000
49.460003,17.166000,-318.839447,-0.002522,0.002669,0.067791,76.358185,3.889871,0.677913,-318.839447,0.068797,0.000000
49.710003,17.101578,-318.883942,-0.002522,0.002681,0.068103,76.071617,3.875273,0.681031,-318.883942,0.069214,0.000000
49.960003,17.171585,-318.883942,-0.002488,0.002695,0.068451,76.383026,3.891137,0.684506,-318.883942,0.069630,0.000000
50.210003,18.237686,-318.928406,-0.002514,0.002726,0.069239,81.125282,4.132719,0.692394,-318.928406,0.070046,0.000000
50.460003,18.037720,-318.883942,-0.002483,0.002745,0.069716,80.235786,4.087406,0.697163,-318.883942,0.070463,0.000000
50.710003,17.444901,-318.928406,-0.002496,0.002754,0.069951,77.598793,3.953071,0.699509,-318.928406,0.070887,0.000000
50.960003,17.664604,-318.972900,-0.002471,0.002772,0.070401,78.576080,4.002856,0.704013,-318.972900,0.071304,0.000000
51.210003,17.634071,-319.017395,-0.002471,0.002785,0.070749,78.440269,3.995938,0.707488,-319.017395,0.071720,0.000000
51.460003,17.855629,-319.061859,-0.002462,0.002803,0.071191,79.425804,4.046143,0.711908,-319.061859,0.072136,0.000000
51.710003,17.727531,-319.017395,-0.002462,0.002815,0.071494,78.855995,4.017116,0.714944,-319.017395,0.072553,0.000000
51.960003,17.891380,-319.061859,-0.002440,0.002829,0.071867,79.584831,4.054245,0.718668,-319.061859,0.072968,0.000000
52.210003,18.664421,-319.017395,-0.002453,0.002854,0.072483,83.023491,4.229418,0.724830,-319.017395,0.073385,0.000000
52.460003,18.473770,-319.106354,-0.002423,0.002869,0.072865,82.175430,4.186216,0.728645,-319.106354,0.073801,0.000000
52.710003,18.378441,-319.150818,-0.002410,0.002884,0.073263,81.751389,4.164614,0.732635,-319.150818,0.074217,0.000000
52.960003,18.643196,-319.150818,-0.002410,0.002902,0.073706,82.929077,4.224608,0.737055,-319.150818,0.074634,0.000000
53.210003,18.995094,-319.150818,-0.002414,0.002922,0.074226,84.494400,4.304350,0.742263,-319.150818,0.075050,0.000000
53.460003,18.748581,-319.195312,-0.002393,0.002935,0.074556,83.397850,4.248489,0.745556,-319.195312,0.075466,0.000000
53.710003,18.328918,-319.150818,-0.002389,0.002944,0.074781,81.531105,4.153392,0.747812,-319.150818,0.075883,0.000000
53.960003,19.277351,-319.239777,-0.002402,0.002968,0.075379,85.749939,4.368310,0.753792,-319.239777,0.076299,0.000000
54.210003,19.471352,-319.239777,-0.002371,0.002986,0.075848,86.612900,4.412271,0.758478,-319.239777,0.076715,0.000000
54.460003,19.424805,-319.239777,-0.002354,0.003001,0.076221,86.405846,4.401724,0.762210,-319.239777,0.077131,0.000000
54.710003,19.400230,-319.239777,-0.002384,0.003015,0.076585,86.296532,4.396155,0.765851,-319.239777,0.077547,0.000000
54.960003,19.654190,-319.239777,-0.002367,0.003033,0.077035,87.426201,4.453703,0.770355,-319.239777,0.077964,0.000000
55.210003,19.869797,-319.239777,-0.002358,0.003049,0.077434,88.385269,4.502560,0.774344,-319.239777,0.078380,0.000000
55.460003,19.759201,-319.284271,-0.002358,0.003061,0.077755,87.893318,4.477499,0.777554,-319.284271,0.078796,0.000000
55.710003,19.622910,-319.328735,-0.002341,0.003070,0.077973,87.287064,4.446615,0.779726,-319.328735,0.079221,0.000000
55.960003,21.262840,-319.373230,-0.002333,0.003103,0.078822,94.581841,4.818229,0.788220,-319.373230,0.079637,0.000000
56.210003,21.126175,-319.328735,-0.002315,0.003119,0.079213,93.973923,4.787260,0.792126,-319.328735,0.080054,0.000000
56.460003,20.967545,-319.462189,-0.002320,0.003132,0.079559,93.268295,4.751313,0.795592,-319.462189,0.080470,0.000000
56.710003,21.015587,-319.417725,-0.002311,0.003146,0.079907,93.482002,4.762200,0.799067,-319.417725,0.080886,0.000000
56.960003,21.767403,-319.417725,-0.002307,0.003168,0.080470,96.826241,4.932564,0.804699,-319.417725,0.081303,0.000000
57.210003,21.892891,-319.506683,-0.002294,0.003181,0.080808,97.384445,4.961000,0.808083,-319.506683,0.081719,0.000000
57.460003,21.844856,-319.506683,-0.002315,0.003193,0.081103,97.170776,4.950115,0.811035,-319.506683,0.082135,0.000000
57.710003,22.170685,-319.551147,-0.002276,0.003207,0.081459,98.620132,5.023949,0.814585,-319.551147,0.082552,0.000000
57.960003,23.072197,-319.506683,-0.002272,0.003230,0.082031,102.630257,5.228235,0.820308,-319.506683,0.082968,0.000000
58.210003,23.712303,-319.462189,-0.002281,0.003249,0.082517,105.477592,5.373284,0.825168,-319.462189,0.083384,0.000000
58.460003,23.783424,-319.551147,-0.002302,0.003265,0.082933,105.793953,5.389401,0.829331,-319.551147,0.083800,0.000000
58.710003,24.239212,-319.595642,-0.002281,0.003280,0.083323,107.821404,5.492684,0.833229,-319.595642,0.084216,0.000000
58.960003,24.629089,-319.595642,-0.002259,0.003297,0.083748,109.555664,5.581032,0.837484,-319.595642,0.084633,0.000000
59.210003,24.954536,-319.595642,-0.002242,0.003311,0.084095,111.003319,5.654779,0.840951,-319.595642,0.085049,0.000000
59.460003,24.988052,-319.595642,-0.002246,0.003322,0.084373,111.152405,5.662374,0.843729,-319.595642,0.085465,0.000000
59.710003,25.119873,-319.640106,-0.002242,0.003332,0.084633,111.738777,5.692245,0.846325,-319.640106,0.085882,0.000000
59.960003,26.705811,-319.684601,-0.002229,0.003362,0.085405,118.793381,6.051623,0.854046,-319.684601,0.086298,0.000000
60.210003,27.100151,-319.729065,-0.002208,0.003377,0.085786,120.547493,6.140982,0.857862,-319.729065,0.086714,0.000000
60.460003,27.496727,-319.729065,-0.002208,0.003394,0.086220,122.311554,6.230847,0.862199,-319.729065,0.087131,0.000000
60.710003,27.869843,-319.773560,-0.002190,0.003408,0.086576,123.971252,6.315397,0.865757,-319.773560,0.087547,0.000000
60.960003,28.580704,-319.729065,-0.002169,0.003429,0.087087,127.133316,6.476480,0.870866,-319.729065,0.087972,0.000000
61.210003,29.063293,-319.773560,-0.002173,0.003442,0.087434,129.279984,6.585836,0.874341,-319.773560,0.088388,0.000000
61.460003,29.191391,-319.773560,-0.002177,0.003454,0.087729,129.849792,6.614864,0.877286,-319.773560,0.088804,0.000000
61.710003,30.175575,-319.818024,-0.002156,0.003478,0.088336,134.227661,6.837883,0.883357,-319.818024,0.089221,0.000000
61.960003,31.365677,-319.818024,-0.002151,0.003498,0.088839,139.521500,7.107564,0.888391,-319.818024,0.089637,0.000000
62.210003,31.409241,-319.862518,-0.002151,0.003510,0.089143,139.715286,7.117435,0.891426,-319.862518,0.090053,0.000000
62.460003,32.203888,-319.818024,-0.002143,0.003526,0.089559,143.250046,7.297505,0.895589,-319.818024,0.090469,0.000000
62.710003,32.561737,-319.907013,-0.002139,0.003541,0.089940,144.841843,7.378595,0.899405,-319.907013,0.090885,0.000000
62.960003,33.542191,-319.862518,-0.002126,0.003559,0.090391,149.203110,7.600769,0.903909,-319.862518,0.091302,0.000000
63.210003,33.997604,-319.907013,-0.002108,0.003571,0.090694,151.228897,7.703967,0.906944,-319.907013,0.091718,0.000000
63.460003,34.635849,-319.951477,-0.002104,0.003587,0.091102,154.067947,7.848596,0.911024,-319.951477,0.092134,0.000000
63.710003,36.116776,-320.040436,-0.002113,0.003610,0.091700,160.655441,8.184178,0.917004,-320.040436,0.092551,0.000000
63.960003,36.864502,-319.995972,-0.002065,0.003627,0.092126,163.981491,8.353616,0.921259,-319.995972,0.092967,0.000000
64.210007,37.448006,-320.040436,-0.002074,0.003642,0.092507,166.577042,8.485839,0.925074,-320.040436,0.093383,0.000000
64.460007,38.083649,-320.040436,-0.002061,0.003656,0.092871,169.404526,8.629878,0.928715,-320.040436,0.093800,0.000000
64.710007,38.499214,-320.040436,-0.002065,0.003670,0.093227,171.253052,8.724047,0.932273,-320.040436,0.094216,0.000000
64.960007,39.456589,-320.040436,-0.002026,0.003687,0.093660,175.511673,8.940990,0.936603,-320.040436,0.094632,0.000000
65.210007,40.351395,-320.040436,-0.002035,0.003701,0.094016,179.491974,9.143757,0.940160,-320.040436,0.095048,0.000000
65.460007,40.730843,-320.084930,-0.002044,0.003712,0.094294,181.179840,9.229740,0.942938,-320.084930,0.095464,0.000000
65.710007,42.106384,-320.129395,-0.002013,0.003736,0.094901,187.298553,9.541444,0.949009,-320.129395,0.095880,0.000000
65.960007,43.830101,-320.084930,-0.002026,0.003757,0.095429,194.966034,9.932043,0.954293,-320.084930,0.096306,0.000000
66.210007,44.212898,-320.129395,-0.001988,0.003769,0.095725,196.668793,10.018786,0.957245,-320.129395,0.096721,0.000000
66.460007,44.962860,-320.173889,-0.001983,0.003785,0.096132,200.004791,10.188729,0.961318,-320.173889,0.097138,0.000000
66.710007,46.019653,-320.173889,-0.001992,0.003802,0.096566,204.705643,10.428203,0.965655,-320.173889,0.097554,0.000000
66.960007,47.190018,-320.173889,-0.001992,0.003822,0.097086,209.911682,10.693411,0.970863,-320.173889,0.097970,0.000000
67.210007,47.501694,-320.173889,-0.001966,0.003829,0.097268,211.298080,10.764038,0.972680,-320.173889,0.098387,0.000000
67.460007,49.275299,-320.218353,-0.001953,0.003856,0.097953,219.187485,11.165943,0.979531,-320.218353,0.098803,0.000000
67.710007,50.419228,-320.307343,-0.001949,0.003872,0.098361,224.275925,11.425160,0.983611,-320.307343,0.099220,0.000000
67.960007,51.161743,-320.262848,-0.001949,0.003888,0.098743,227.578796,11.593417,0.987426,-320.262848,0.099636,0.000000
68.210007,51.996231,-320.307343,-0.001949,0.003900,0.099064,231.290787,11.782515,0.990636,-320.307343,0.100052,0.000000
68.460007,52.643036,-320.351807,-0.001949,0.003913,0.099385,234.167923,11.929082,0.993845,-320.351807,0.100469,0.000000
68.710007,54.005920,-320.351807,-0.001914,0.003932,0.099879,240.230331,12.237916,0.998788,-320.351807,0.100885,0.000000
68.960007,54.754021,-320.440765,-0.001914,0.003945,0.100191,243.558044,12.407438,1.001907,-320.440765,0.101300,0.000000
69.210007,55.602654,-320.396301,-0.001906,0.003956,0.100494,247.332962,12.599742,1.004943,-320.396301,0.101717,0.000000
69.460007,57.442551,-320.440765,-0.001919,0.003984,0.101197,255.517227,13.016667,1.011967,-320.440765,0.102133,0.000000
69.710007,59.221741,-320.485260,-0.001893,0.004001,0.101630,263.431458,13.419838,1.016305,-320.485260,0.102549,0.000000
69.960007,60.032768,-320.485260,-0.001880,0.004015,0.101969,267.039093,13.603620,1.019689,-320.485260,0.102966,0.000000
70.210007,60.953644,-320.485260,-0.001884,0.004030,0.102368,271.135345,13.812294,1.023678,-320.485260,0.103382,0.000000
70.460007,62.246895,-320.485260,-0.001880,0.004046,0.102767,276.888031,14.105349,1.027667,-320.485260,0.103798,0.000000
70.710007,63.451157,-320.529724,-0.001871,0.004064,0.103226,282.244843,14.378238,1.032262,-320.529724,0.104215,0.000000
70.960007,64.539215,-320.529724,-0.001867,0.004076,0.103538,287.084778,14.624795,1.035381,-320.529724,0.104639,0.000000
71.210007,65.509247,-320.529724,-0.001871,0.004090,0.103885,291.399689,14.844607,1.038848,-320.529724,0.105056,0.000000
71.460007,67.571823,-320.574219,-0.001837,0.004115,0.104509,300.574493,15.311994,1.045093,-320.574219,0.105464,0.000000
71.710007,67.127213,-320.663177,-0.001841,0.004106,0.104301,298.596741,15.211245,1.043011,-320.663177,0.104527,0.000000
71.960007,66.675888,-320.618683,-0.001841,0.004105,0.104275,296.589172,15.108973,1.042754,-320.618683,0.104301,0.000000
72.210007,66.271866,-320.663177,-0.001828,0.004105,0.104258,294.791992,15.017419,1.042580,-320.663177,0.104301,0.000000
72.460007,65.914764,-320.707672,-0.001832,0.004104,0.104250,293.203522,14.936499,1.042496,-320.707672,0.104301,0.000000
72.710007,65.631393,-320.663177,-0.001845,0.004104,0.104250,291.943024,14.872286,1.042496,-320.663177,0.104301,0.000000
72.960007,65.370361,-320.707672,-0.001867,0.004104,0.104250,290.781891,14.813136,1.042496,-320.707672,0.104301,0.000000
73.210007,65.124222,-320.707672,-0.001819,0.004104,0.104250,289.687012,14.757360,1.042496,-320.707672,0.104301,0.000000
73.460007,64.925003,-320.752136,-0.001819,0.004104,0.104250,288.800842,14.712215,1.042496,-320.752136,0.104301,0.000000
73.710007,64.725037,-320.752136,-0.001807,0.004104,0.104250,287.911346,14.666903,1.042496,-320.752136,0.104301,0.000000
73.960007,64.569763,-320.752136,-0.001832,0.004104,0.104250,287.220642,14.631718,1.042496,-320.752136,0.104301,0.000000
74.210007,64.426758,-320.796631,-0.001837,0.004104,0.104250,286.584534,14.599312,1.042496,-320.796631,0.104301,0.000000
74.460007,64.277817,-320.841095,-0.001828,0.004104,0.104250,285.921997,14.565561,1.042496,-320.841095,0.104301,0.000000
74.710007,64.148972,-320.796631,-0.001819,0.004104,0.104250,285.348877,14.536366,1.042496,-320.796631,0.104301,0.000000
74.960007,64.028702,-320.841095,-0.001824,0.004104,0.104250,284.813904,14.509111,1.042496,-320.841095,0.104301,0.000000
75.210007,63.916245,-320.885590,-0.001807,0.004104,0.104250,284.313660,14.483628,1.042496,-320.885590,0.104301,0.000000
75.460007,63.814209,-320.841095,-0.001824,0.004104,0.104250,283.859772,14.460506,1.042496,-320.841095,0.104301,0.000000
75.710007,63.722229,-320.885590,-0.001807,0.004104,0.104250,283.450623,14.439664,1.042496,-320.885590,0.104301,0.000000
75.960007,63.623184,-320.930054,-0.001824,0.004104,0.104250,283.010071,14.417220,1.042496,-320.930054,0.104301,0.000000
76.210007,63.520782,-320.885590,-0.001832,0.004104,0.104250,282.554565,14.394015,1.042496,-320.885590,0.104301,0.000000
76.460007,63.451523,-320.974548,-0.001811,0.004104,0.104250,282.246460,14.378321,1.042496,-320.974548,0.104301,0.000000
76.710007,63.368851,-320.974548,-0.001824,0.004104,0.104250,281.878723,14.359587,1.042496,-320.974548,0.104301,0.000000
76.960007,63.310394,-320.974548,-0.001828,0.004104,0.104250,281.618713,14.346340,1.042496,-320.974548,0.104301,0.000000
77.210007,63.225494,-321.019012,-0.001802,0.004104,0.104250,281.241058,14.327102,1.042496,-321.019012,0.104301,0.000000
77.460007,63.157349,-321.063507,-0.001785,0.004104,0.104250,280.937927,14.311660,1.042496,-321.063507,0.104301,0.000000
77.710007,63.080269,-321.107971,-0.001785,0.004104,0.104250,280.595062,14.294193,1.042496,-321.107971,0.104301,0.000000
77.960007,63.034836,-321.063507,-0.001789,0.004104,0.104250,280.392944,14.283898,1.042496,-321.063507,0.104301,0.000000
78.210007,62.979729,-321.107971,-0.001802,0.004104,0.104250,280.147827,14.271411,1.042496,-321.107971,0.104301,0.000000
78.460007,62.917915,-321.107971,-0.001828,0.004104,0.104250,279.872864,14.257403,1.042496,-321.107971,0.104301,0.000000
78.710007,62.850883,-321.152466,-0.001785,0.004104,0.104250,279.574707,14.242213,1.042496,-321.152466,0.104301,0.000000
78.960007,62.795029,-321.152466,-0.001819,0.004104,0.104250,279.326233,14.229557,1.042496,-321.152466,0.104301,0.000000
79.210007,62.755928,-321.152466,-0.001824,0.004104,0.104250,279.152313,14.220696,1.042496,-321.152466,0.104301,0.000000
79.460007,62.707146,-321.152466,-0.001794,0.004104,0.104250,278.935303,14.209642,1.042496,-321.152466,0.104301,0.000000
79.710007,62.663582,-321.196960,-0.001785,0.004104,0.104250,278.741547,14.199771,1.042496,-321.196960,0.104301,0.000000
79.960007,62.621880,-321.241425,-0.001802,0.004104,0.104250,278.556030,14.190320,1.042496,-321.241425,0.104301,0.000000
80.210007,62.567879,-321.241425,-0.001828,0.004104,0.104250,278.315826,14.178083,1.042496,-321.241425,0.104301,0.000000
80.460007,62.526924,-321.285919,-0.001824,0.004104,0.104250,278.133636,14.168803,1.042496,-321.285919,0.104301,0.000000
80.710007,62.491547,-321.196960,-0.001789,0.004104,0.104250,277.976288,14.160787,1.042496,-321.196960,0.104301,0.000000
80.960007,62.450584,-321.241425,-0.001811,0.004104,0.104250,277.794067,14.151505,1.042496,-321.241425,0.104301,0.000000
81.210007,62.409248,-321.285919,-0.001794,0.004104,0.104250,277.610199,14.142138,1.042496,-321.285919,0.104301,0.000000
81.460007,62.366798,-321.330383,-0.001815,0.004104,0.104250,277.421387,14.132518,1.042496,-321.330383,0.104301,0.000000
81.710007,62.321373,-321.330383,-0.001794,0.004104,0.104250,277.219299,14.122225,1.042496,-321.330383,0.104301,0.000000
81.960007,62.300888,-321.285919,-0.001794,0.004104,0.104250,277.128204,14.117583,1.042496,-321.285919,0.104301,0.000000
82.210007,62.264771,-321.330383,-0.001807,0.004104,0.104250,276.967529,14.109399,1.042496,-321.330383,0.104301,0.000000
82.460007,62.213387,-321.419342,-0.001785,0.004104,0.104250,276.738953,14.097755,1.042496,-321.419342,0.104301,0.000000
82.710007,62.185455,-321.419342,-0.001802,0.004104,0.104250,276.614716,14.091426,1.042496,-321.419342,0.104301,0.000000
82.960007,62.166092,-321.419342,-0.001845,0.004104,0.104250,276.528595,14.087038,1.042496,-321.419342,0.104301,0.000000
83.210007,62.122154,-321.419342,-0.001807,0.004104,0.104250,276.333130,14.077082,1.042496,-321.419342,0.104301,0.000000
83.460007,62.096832,-321.463837,-0.001798,0.004104,0.104250,276.220520,14.071343,1.042496,-321.463837,0.104301,0.000000
83.710007,62.041718,-321.419342,-0.001811,0.004104,0.104250,275.975342,14.058854,1.042496,-321.419342,0.104301,0.000000
83.960007,62.022354,-321.508301,-0.001794,0.004104,0.104250,275.889221,14.054466,1.042496,-321.508301,0.104301,0.000000
84.210007,62.000015,-321.508301,-0.001789,0.004104,0.104250,275.789856,14.049404,1.042496,-321.508301,0.104301,0.000000
84.460007,61.976555,-321.552795,-0.001785,0.004104,0.104250,275.685486,14.044088,1.042496,-321.552795,0.104301,0.000000
84.710007,61.946762,-321.508301,-0.001811,0.004104,0.104250,275.552948,14.037336,1.042496,-321.508301,0.104301,0.000000
84.960007,61.906548,-321.552795,-0.001837,0.004104,0.104250,275.374084,14.028224,1.042496,-321.552795,0.104301,0.000000
85.210007,61.877129,-321.552795,-0.001807,0.004104,0.104250,275.243225,14.021558,1.042496,-321.552795,0.104301,0.000000
85.460007,61.862610,-321.597290,-0.001815,0.004104,0.104250,275.178619,14.018269,1.042496,-321.597290,0.104301,0.000000
85.710007,61.833565,-321.597290,-0.001807,0.004104,0.104250,275.049438,14.011686,1.042496,-321.597290,0.104301,0.000000
85.960007,61.797813,-321.508301,-0.001794,0.004104,0.104250,274.890411,14.003585,1.042496,-321.508301,0.104301,0.000000
86.210007,61.777336,-321.641754,-0.001785,0.004104,0.104250,274.799316,13.998944,1.042496,-321.641754,0.104301,0.000000
86.460007,61.760208,-321.641754,-0.001798,0.004104,0.104250,274.723114,13.995063,1.042496,-321.641754,0.104301,0.000000
86.710007,61.736374,-321.641754,-0.001772,0.004104,0.104250,274.617096,13.989662,1.042496,-321.641754,0.104301,0.000000
86.960007,61.699135,-321.730713,-0.001794,0.004104,0.104250,274.451447,13.981224,1.042496,-321.730713,0.104301,0.000000
87.210007,61.681633,-321.730713,-0.001815,0.004104,0.104250,274.373596,13.977259,1.042496,-321.730713,0.104301,0.000000
87.460007,61.673073,-321.686249,-0.001776,0.004104,0.104250,274.335541,13.975318,1.042496,-321.686249,0.104301,0.000000
87.710007,61.633598,-321.730713,-0.001789,0.004104,0.104250,274.159943,13.966373,1.042496,-321.730713,0.104301,0.000000
87.960007,61.617218,-321.819672,-0.001794,0.004104,0.104250,274.087067,13.962661,1.042496,-321.819672,0.104301,0.000000
88.210007,61.588913,-321.775208,-0.001811,0.004104,0.104250,273.961182,13.956247,1.042496,-321.775208,0.104301,0.000000
88.460007,61.579979,-321.819672,-0.001785,0.004104,0.104250,273.921417,13.954223,1.042496,-321.819672,0.104301,0.000000
88.710007,61.548698,-321.775208,-0.001785,0.004104,0.104250,273.782288,13.947134,1.042496,-321.775208,0.104301,0.000000
88.960007,61.524498,-321.819672,-0.001828,0.004104,0.104250,273.674622,13.941650,1.042496,-321.819672,0.104301,0.000000
89.210007,61.518539,-321.819672,-0.001811,0.004104,0.104250,273.648132,13.940300,1.042496,-321.819672,0.104301,0.000000
89.460007,61.501404,-321.864166,-0.001781,0.004104,0.104250,273.571899,13.936418,1.042496,-321.864166,0.104301,0.000000
89.710007,61.471619,-321.908630,-0.001789,0.004104,0.104250,273.439423,13.929668,1.042496,-321.908630,0.104301,0.000000
89.960007,61.455978,-321.953125,-0.001824,0.004104,0.104250,273.369843,13.926124,1.042496,-321.953125,0.104301,0.000000
90.210007,61.441452,-321.953125,-0.001789,0.004104,0.104250,273.305237,13.922832,1.042496,-321.953125,0.104301,0.000000
90.460007,61.423950,-321.908630,-0.001781,0.004104,0.104250,273.227386,13.918866,1.042496,-321.908630,0.104301,0.000000
90.710007,61.410919,-321.953125,-0.001789,0.004104,0.104250,273.169403,13.915914,1.042496,-321.953125,0.104301,0.000000
90.960007,61.387093,-321.997620,-0.001794,0.004104,0.104250,273.063416,13.910514,1.042496,-321.997620,0.104301,0.000000
91.210007,61.372192,-321.997620,-0.001815,0.004104,0.104250,272.997131,13.907138,1.042496,-321.997620,0.104301,0.000000
91.460007,61.360275,-322.042084,-0.001798,0.004104,0.104250,272.944122,13.904437,1.042496,-322.042084,0.104301,0.000000
91.710007,61.334953,-322.042084,-0.001811,0.004104,0.104250,272.831512,13.898699,1.042496,-322.042084,0.104301,0.000000
91.960007,61.324532,-322.042084,-0.001789,0.004104,0.104250,272.785126,13.896338,1.042496,-322.042084,0.104301,0.000000
92.210007,61.307030,-322.086578,-0.001819,0.004104,0.104250,272.707275,13.892371,1.042496,-322.086578,0.104301,0.000000
92.460007,61.293251,-322.086578,-0.001811,0.004104,0.104250,272.645996,13.889250,1.042496,-322.086578,0.104301,0.000000
92.710007,61.276123,-322.131042,-0.001798,0.004104,0.104250,272.569794,13.885368,1.042496,-322.131042,0.104301,0.000000
92.960007,61.266815,-322.175537,-0.001785,0.004104,0.104250,272.528412,13.883259,1.042496,-322.175537,0.104301,0.000000
93.210007,61.242981,-322.131042,-0.001789,0.004104,0.104250,272.422394,13.877858,1.042496,-322.131042,0.104301,0.000000
93.460007,61.228088,-322.175537,-0.001824,0.004104,0.104250,272.356140,13.874483,1.042496,-322.175537,0.104301,0.000000
93.710007,61.214310,-322.175537,-0.001811,0.004104,0.104250,272.294861,13.871362,1.042496,-322.175537,0.104301,0.000000
93.960007,61.209465,-322.220001,-0.001794,0.004104,0.104250,272.273285,13.870263,1.042496,-322.220001,0.104301,0.000000
94.210007,61.180046,-322.175537,-0.001824,0.004104,0.104250,272.142426,13.863597,1.042496,-322.175537,0.104301,0.000000
94.460007,61.177818,-322.220001,-0.001789,0.004104,0.104250,272.132538,13.863091,1.042496,-322.220001,0.104301,0.000000
94.710007,61.161057,-322.264496,-0.001807,0.004104,0.104250,272.057953,13.859293,1.042496,-322.264496,0.104301,0.000000
94.960007,61.143929,-322.220001,-0.001815,0.004104,0.104250,271.981781,13.855412,1.042496,-322.220001,0.104301,0.000000
95.210007,61.134995,-322.353455,-0.001794,0.004104,0.104250,271.942047,13.853388,1.042496,-322.353455,0.104301,0.000000
95.460007,61.121590,-322.308960,-0.001807,0.004104,0.104250,271.882416,13.850350,1.042496,-322.308960,0.104301,0.000000
95.710007,61.113022,-322.353455,-0.001763,0.004104,0.104250,271.844299,13.848409,1.042496,-322.353455,0.104301,0.000000
95.960007,61.093658,-322.353455,-0.001802,0.004104,0.104250,271.758179,13.844021,1.042496,-322.353455,0.104301,0.000000
96.210007,61.079506,-322.397919,-0.001819,0.004104,0.104250,271.695221,13.840815,1.042496,-322.397919,0.104301,0.000000
96.460007,61.059776,-322.353455,-0.001794,0.004104,0.104250,271.607452,13.836343,1.042496,-322.353455,0.104301,0.000000
96.710007,61.052322,-322.353455,-0.001789,0.004104,0.104250,271.574280,13.834654,1.042496,-322.353455,0.104301,0.000000
96.960007,61.044136,-322.442413,-0.001815,0.004104,0.104250,271.537872,13.832799,1.042496,-322.442413,0.104301,0.000000
97.210007,61.025887,-322.442413,-0.001798,0.004104,0.104250,271.456696,13.828664,1.042496,-322.442413,0.104301,0.000000
97.460007,61.007645,-322.486908,-0.001807,0.004104,0.104250,271.375549,13.824531,1.042496,-322.486908,0.104301,0.000000
97.710007,61.004662,-322.486908,-0.001807,0.004104,0.104250,271.362274,13.823853,1.042496,-322.486908,0.104301,0.000000
97.960007,60.986420,-322.397919,-0.001789,0.004104,0.104250,271.281158,13.819720,1.042496,-322.397919,0.104301,0.000000
98.210007,60.976364,-322.531372,-0.001802,0.004104,0.104250,271.236420,13.817442,1.042496,-322.531372,0.104301,0.000000
98.460007,60.968544,-322.531372,-0.001789,0.004104,0.104250,271.201630,13.815670,1.042496,-322.531372,0.104301,0.000000
98.710007,60.952904,-322.531372,-0.001794,0.004104,0.104250,271.132050,13.812125,1.042496,-322.531372,0.104301,0.000000
98.960007,60.935776,-322.531372,-0.001794,0.004104,0.104250,271.055878,13.808245,1.042496,-322.531372,0.104301,0.000000
99.210007,60.937263,-322.620331,-0.001807,0.004104,0.104250,271.062500,13.808581,1.042496,-322.620331,0.104301,0.000000
99.460007,60.926468,-322.531372,-0.001776,0.004104,0.104250,271.014465,13.806134,1.042496,-322.531372,0.104301,0.000000
99.710007,60.907471,-322.575867,-0.001802,0.004104,0.104250,270.929962,13.801829,1.042496,-322.575867,0.104301,0.000000
99.960007,60.903748,-322.620331,-0.001811,0.004104,0.104250,270.913391,13.800986,1.042496,-322.620331,0.104301,0.000000
100.210007,60.888107,-322.620331,-0.001807,0.004104,0.104250,270.843842,13.797442,1.042496,-322.620331,0.104301,0.000000
100.460007,60.874702,-322.575867,-0.001781,0.004104,0.104250,270.784210,13.794404,1.042496,-322.575867,0.104301,0.000000
100.710007,60.869492,-322.664825,-0.001789,0.004104,0.104250,270.761017,13.793224,1.042496,-322.664825,0.104301,0.000000
100.960007,60.852737,-322.709290,-0.001798,0.004104,0.104250,270.686493,13.789428,1.042496,-322.709290,0.104301,0.000000
101.210007,60.850128,-322.709290,-0.001794,0.004104,0.104250,270.674896,13.788836,1.042496,-322.709290,0.104301,0.000000
101.460007,60.825554,-322.709290,-0.001794,0.004104,0.104250,270.565582,13.783268,1.042496,-322.709290,0.104301,0.000000
101.710007,60.821457,-322.753784,-0.001781,0.004104,0.104250,270.547363,13.782339,1.042496,-322.753784,0.104301,0.000000
101.960007,60.812149,-322.709290,-0.001785,0.004104,0.104250,270.505951,13.780231,1.042496,-322.709290,0.104301,0.000000
102.000008,60.819595,-322.753784,-0.001802,0.004104,0.104250,270.539062,13.781917,1.042496,-322.753784,0.104301,0.000000