File: Data/compression 14/AutoNoHeating-14-14-2-240726_07262024_165653.csv
Time (sec),S:Load (lbs),S:HL1 (DIM),S:LVDT (in),S:Position (in),Ch:Position (mm),Ch:Load (N),Ch:Stress (MPa),Ch:Strain (mm/mm),Ch:HL1 (DIM),Set Point (),Cycles ()
0.110000,-0.020851,-422.168701,-0.010313,-0.005571,-0.141514,-0.092750,-0.004725,-1.415142,-422.168701,-0.141323,0.000000
0.360000,-0.011169,-422.213196,-0.010287,-0.005571,-0.141514,-0.049684,-0.002531,-1.415142,-422.213196,-0.141323,0.000000
0.610000,-0.080803,-422.213196,-0.010335,-0.005468,-0.138895,-0.359429,-0.018310,-1.388950,-422.213196,-0.138045,0.000000
0.860000,-0.043938,-422.213196,-0.010197,-0.005312,-0.134914,-0.195445,-0.009956,-1.349141,-422.213196,-0.133882,0.000000
1.110000,0.013779,-422.257660,-0.010020,-0.005152,-0.130864,0.061291,0.003122,-1.308643,-422.257660,-0.129720,0.000000
1.360000,-0.002609,-422.257660,-0.009852,-0.004982,-0.126537,-0.011607,-0.000591,-1.265366,-422.257660,-0.125557,0.000000
1.610000,-0.012665,-422.302155,-0.009684,-0.004825,-0.122556,-0.056336,-0.002870,-1.225564,-422.302155,-0.121377,0.000000
1.860000,-0.005585,-422.302155,-0.009528,-0.004661,-0.118385,-0.024842,-0.001266,-1.183847,-422.302155,-0.117214,0.000000
2.110000,-0.018250,-422.257660,-0.009326,-0.004491,-0.114066,-0.081178,-0.004135,-1.140661,-422.257660,-0.113052,0.000000
2.360000,-0.041710,-422.257660,-0.009205,-0.004334,-0.110086,-0.185535,-0.009452,-1.100859,-422.257660,-0.108889,0.000000
2.610000,-0.035004,-422.257660,-0.008998,-0.004162,-0.105706,-0.155704,-0.007932,-1.057061,-422.257660,-0.104727,0.000000
2.860000,-0.010803,-422.302155,-0.008869,-0.004013,-0.101942,-0.048055,-0.002448,-1.019424,-422.302155,-0.100563,0.000000
3.110000,-0.020111,-422.346619,-0.008645,-0.003839,-0.097519,-0.089459,-0.004557,-0.975193,-422.346619,-0.096401,0.000000
3.360000,-0.015266,-422.346619,-0.008459,-0.003674,-0.093314,-0.067908,-0.003459,-0.933136,-422.346619,-0.092220,0.000000
3.610000,0.005585,-422.391113,-0.008343,-0.003517,-0.089324,0.024842,0.001266,-0.893243,-422.391113,-0.088058,0.000000
3.860000,0.010422,-422.435577,-0.008149,-0.003352,-0.085144,0.046358,0.002362,-0.851442,-422.435577,-0.083895,0.000000
4.110000,-0.037987,-422.346619,-0.007933,-0.003181,-0.080808,-0.168974,-0.008608,-0.808083,-422.346619,-0.079733,0.000000
4.360000,-0.008568,-422.391113,-0.007795,-0.003019,-0.076671,-0.038112,-0.001941,-0.766714,-422.391113,-0.075570,0.000000
4.610000,-0.037239,-422.391113,-0.007601,-0.002848,-0.072335,-0.165648,-0.008438,-0.723354,-422.391113,-0.071407,0.000000
4.860000,-0.043938,-422.480072,-0.007459,-0.002689,-0.068303,-0.195445,-0.009956,-0.683030,-422.480072,-0.067245,0.000000
5.110000,-0.026810,-422.435577,-0.007282,-0.002526,-0.064166,-0.119255,-0.006075,-0.641661,-422.435577,-0.063082,0.000000
5.360000,0.023834,-422.435577,-0.007114,-0.002365,-0.060073,0.106020,0.005401,-0.600731,-422.435577,-0.058902,0.000000
5.610000,0.007446,-422.480072,-0.006916,-0.002193,-0.055702,0.033123,0.001687,-0.557015,-422.480072,-0.054739,0.000000
5.860000,-0.012291,-422.435577,-0.006748,-0.002036,-0.051704,-0.054673,-0.002785,-0.517039,-422.435577,-0.050577,0.000000
6.110000,0.012657,-422.480072,-0.006566,-0.001869,-0.047463,0.056302,0.002868,-0.474633,-422.480072,-0.046414,0.000000
6.360000,-0.007446,-422.480072,-0.006398,-0.001708,-0.043379,-0.033123,-0.001687,-0.433787,-422.480072,-0.042252,0.000000
6.610000,-0.043198,-422.569031,-0.006234,-0.001542,-0.039173,-0.192153,-0.009789,-0.391729,-422.569031,-0.038089,0.000000
6.860000,-0.027931,-422.524567,-0.006049,-0.001374,-0.034897,-0.124244,-0.006329,-0.348975,-422.524567,-0.033926,0.000000
7.110000,-0.010429,-422.569031,-0.005920,-0.001228,-0.031194,-0.046392,-0.002363,-0.311943,-422.569031,-0.029763,0.000000
7.360000,0.004097,-422.524567,-0.005734,-0.001047,-0.026589,0.018224,0.000928,-0.265889,-422.524567,-0.025583,0.000000
7.610000,-0.004097,-422.613525,-0.005570,-0.000887,-0.022539,-0.018224,-0.000928,-0.225390,-422.613525,-0.021420,0.000000
7.860001,0.006332,-422.569031,-0.005351,-0.000722,-0.018342,0.028168,0.001435,-0.183416,-422.569031,-0.017258,0.000000
8.110001,0.035378,-422.569031,-0.005221,-0.000569,-0.014465,0.157367,0.008017,-0.144651,-422.569031,-0.013095,0.000000
8.360001,0.081177,-422.657990,-0.005023,-0.000395,-0.010025,0.361092,0.018395,-0.100254,-422.657990,-0.008932,0.000000
8.610001,0.728363,-422.657990,-0.004889,0.000013,0.000330,3.239921,0.165049,0.003300,-422.657990,0.000486,0.000000
8.860001,0.679581,-422.613525,-0.004902,0.000013,0.000321,3.022926,0.153995,0.003210,-422.613525,0.000486,0.000000
9.110001,0.649788,-422.657990,-0.004902,0.000013,0.000321,2.890401,0.147244,0.003210,-422.657990,0.000607,0.000000
9.360001,0.641594,-422.657990,-0.004911,0.000013,0.000321,2.853952,0.145387,0.003210,-422.657990,0.001023,0.000000
9.610001,0.617767,-422.657990,-0.004881,0.000013,0.000321,2.747966,0.139988,0.003210,-422.657990,0.001440,0.000000
9.860001,0.935768,-422.702484,-0.004885,0.000039,0.000989,4.162505,0.212048,0.009886,-422.702484,0.001856,0.000000
10.110001,1.036682,-422.702484,-0.004863,0.000051,0.001292,4.611392,0.234916,0.012922,-422.702484,0.002272,0.000000
10.360001,1.292877,-422.657990,-0.004842,0.000069,0.001761,5.751005,0.292970,0.017607,-422.657990,0.002689,0.000000
10.610001,1.479805,-422.746948,-0.004846,0.000085,0.002151,6.582501,0.335329,0.021506,-422.746948,0.003105,0.000000
10.860001,1.646629,-422.657990,-0.004850,0.000099,0.002515,7.324573,0.373132,0.025154,-422.657990,0.003521,0.000000
11.110001,2.032410,-422.791443,-0.004816,0.000122,0.003096,9.040609,0.460551,0.030960,-422.791443,0.003937,0.000000
11.360001,2.262535,-422.835907,-0.004803,0.000140,0.003547,10.064259,0.512698,0.035472,-422.835907,0.004353,0.000000
11.610001,2.407761,-422.746948,-0.004777,0.000151,0.003842,10.710254,0.545606,0.038417,-422.746948,0.004770,0.000000
11.860001,2.616287,-422.746948,-0.004743,0.000166,0.004223,11.637827,0.592859,0.042232,-422.746948,0.005186,0.000000
12.110001,2.848274,-422.835907,-0.004756,0.000179,0.004536,12.669757,0.645428,0.045358,-422.835907,0.005602,0.000000
12.360001,3.338692,-422.880402,-0.004738,0.000200,0.005091,14.851242,0.756558,0.050907,-422.880402,0.006019,0.000000
12.610001,3.434021,-422.835907,-0.004730,0.000212,0.005394,15.275289,0.778160,0.053942,-422.835907,0.006435,0.000000
12.860001,3.994064,-422.835907,-0.004700,0.000239,0.006062,17.766485,0.905068,0.060619,-422.835907,0.006851,0.000000
13.110001,4.251373,-422.880402,-0.004691,0.000256,0.006504,18.911053,0.963375,0.065040,-422.880402,0.007268,0.000000
13.360001,4.486717,-422.924896,-0.004678,0.000271,0.006895,19.957914,1.016705,0.068946,-422.924896,0.007684,0.000000
13.610001,4.634171,-422.880402,-0.004691,0.000283,0.007190,20.613819,1.050118,0.071898,-422.880402,0.008109,0.000000
13.860001,4.941757,-422.880402,-0.004648,0.000297,0.007545,21.982035,1.119818,0.075448,-422.880402,0.008525,0.000000
14.110001,5.591919,-422.924896,-0.004635,0.000323,0.008212,24.874098,1.267147,0.082125,-422.924896,0.008941,0.000000
14.360001,5.603462,-422.924896,-0.004600,0.000334,0.008490,24.925446,1.269763,0.084903,-422.924896,0.009358,0.000000
14.610001,5.629898,-422.969360,-0.004631,0.000343,0.008724,25.043037,1.275753,0.087242,-422.969360,0.009774,0.000000
14.860001,6.132225,-422.969360,-0.004579,0.000365,0.009280,27.277500,1.389582,0.092798,-422.969360,0.010190,0.000000
15.110001,6.675522,-422.969360,-0.004562,0.000388,0.009843,29.694204,1.512695,0.098430,-422.969360,0.010606,0.000000
15.360001,6.803619,-422.969360,-0.004570,0.000403,0.010225,30.264011,1.541722,0.102245,-422.969360,0.011022,0.000000
15.610001,6.864311,-423.013855,-0.004527,0.000412,0.010468,30.533981,1.555475,0.104675,-423.013855,0.011439,0.000000
15.860001,7.113800,-423.013855,-0.004518,0.000425,0.010797,31.643763,1.612010,0.107968,-423.013855,0.011855,0.000000
16.110001,7.844025,-423.058319,-0.004501,0.000451,0.011456,34.891964,1.777481,0.114561,-423.058319,0.012271,0.000000
16.360001,7.813118,-423.058319,-0.004493,0.000460,0.011690,34.754486,1.770478,0.116900,-423.058319,0.012688,0.000000
16.610001,7.764709,-423.102814,-0.004488,0.000468,0.011881,34.539154,1.759508,0.118808,-423.102814,0.013104,0.000000
16.860001,8.729156,-423.058319,-0.004445,0.000500,0.012688,38.829227,1.978055,0.126877,-423.058319,0.013520,0.000000
17.110001,8.913849,-423.058319,-0.004415,0.000517,0.013130,39.650780,2.019907,0.131298,-423.058319,0.013937,0.000000
17.360001,9.042320,-423.102814,-0.004445,0.000531,0.013486,40.222248,2.049019,0.134856,-423.102814,0.014353,0.000000
17.610001,9.216591,-423.147278,-0.004424,0.000546,0.013867,40.997444,2.088510,0.138671,-423.147278,0.014769,0.000000
17.860001,9.358833,-423.147278,-0.004415,0.000560,0.014214,41.630169,2.120742,0.142138,-423.147278,0.015185,0.000000
18.110001,10.089058,-423.147278,-0.004372,0.000583,0.014821,44.878372,2.286213,0.148209,-423.147278,0.015601,0.000000
18.360001,9.944206,-423.147278,-0.004381,0.000591,0.015012,44.234039,2.253389,0.150117,-423.147278,0.016018,0.000000
18.610001,10.362007,-423.191772,-0.004363,0.000610,0.015498,46.092510,2.348064,0.154976,-423.191772,0.016443,0.000000
18.860001,10.849442,-423.191772,-0.004342,0.000632,0.016044,48.260727,2.458519,0.160442,-423.191772,0.016859,0.000000
19.110001,11.030785,-423.191772,-0.004329,0.000647,0.016443,49.067379,2.499612,0.164431,-423.191772,0.017275,0.000000
19.360001,11.057968,-423.280731,-0.004316,0.000660,0.016772,49.188297,2.505771,0.167724,-423.280731,0.017691,0.000000
19.610001,11.223679,-423.236237,-0.004324,0.000675,0.017145,49.925415,2.543322,0.171448,-423.236237,0.018108,0.000000
19.860001,11.368156,-423.236237,-0.004303,0.000686,0.017423,50.568085,2.576061,0.174226,-423.236237,0.018524,0.000000
20.110001,12.080879,-423.280731,-0.004247,0.000713,0.018099,53.738434,2.737566,0.180994,-423.280731,0.018940,0.000000
20.360001,11.890221,-423.236237,-0.004238,0.000720,0.018298,52.890343,2.694363,0.182985,-423.236237,0.019357,0.000000
20.610001,12.582092,-423.325226,-0.004247,0.000745,0.018923,55.967941,2.851143,0.189230,-423.325226,0.019773,0.000000
20.860001,12.916855,-423.280731,-0.004212,0.000764,0.019409,57.457039,2.927001,0.194089,-423.280731,0.020189,0.000000
21.110001,12.941803,-423.325226,-0.004186,0.000778,0.019756,57.568016,2.932655,0.197556,-423.325226,0.020606,0.000000
21.360001,12.910149,-423.325226,-0.004156,0.000789,0.020050,57.427208,2.925482,0.200501,-423.325226,0.021021,0.000000
21.610001,13.319763,-423.325226,-0.004165,0.000808,0.020527,59.249268,3.018301,0.205270,-423.325226,0.021438,0.000000
21.860001,13.565155,-423.369690,-0.004169,0.000826,0.020978,60.340824,3.073908,0.209782,-423.369690,0.021854,0.000000
22.110001,13.740173,-423.369690,-0.004126,0.000840,0.021334,61.119343,3.113568,0.213339,-423.369690,0.022270,0.000000
22.360001,13.875343,-423.369690,-0.004113,0.000852,0.021637,61.720608,3.144198,0.216375,-423.369690,0.022687,0.000000
22.610001,14.510979,-423.458649,-0.004118,0.000875,0.022235,64.548058,3.288235,0.222355,-423.458649,0.023103,0.000000
22.860001,14.835320,-423.369690,-0.004092,0.000896,0.022756,65.990799,3.361731,0.227563,-423.369690,0.023519,0.000000
23.110001,14.778343,-423.414185,-0.004066,0.000909,0.023077,65.737350,3.348820,0.230773,-423.414185,0.023936,0.000000
23.360001,14.761963,-423.414185,-0.004031,0.000923,0.023432,65.664490,3.345109,0.234323,-423.414185,0.024352,0.000000
23.610001,15.082199,-423.503143,-0.004053,0.000940,0.023866,67.088974,3.417675,0.238660,-423.503143,0.024777,0.000000
23.860001,15.419197,-423.458649,-0.004014,0.000958,0.024326,68.588013,3.494040,0.243255,-423.458649,0.025193,0.000000
24.110001,15.676506,-423.503143,-0.003980,0.000974,0.024742,69.732582,3.552347,0.247419,-423.503143,0.025609,0.000000
24.360001,15.374138,-423.458649,-0.003962,0.000980,0.024889,68.387581,3.483829,0.248895,-423.458649,0.026026,0.000000
24.610001,15.538361,-423.503143,-0.003962,0.000993,0.025219,69.118080,3.521043,0.252188,-423.503143,0.026442,0.000000
24.860001,16.605202,-423.547607,-0.003954,0.001024,0.026017,73.863625,3.762793,0.260166,-423.547607,0.026858,0.000000
25.110001,16.324806,-423.547607,-0.003932,0.001034,0.026269,72.616364,3.699254,0.262687,-423.547607,0.027275,0.000000
25.360001,16.629036,-423.503143,-0.003898,0.001053,0.026736,73.969643,3.768193,0.267365,-423.503143,0.027690,0.000000
25.610001,16.832352,-423.592102,-0.003898,0.001068,0.027135,74.874039,3.814265,0.271354,-423.592102,0.028107,0.000000
25.860001,16.960075,-423.547607,-0.003859,0.001086,0.027587,75.442184,3.843208,0.275866,-423.547607,0.028523,0.000000
26.110001,17.396126,-423.547607,-0.003863,0.001103,0.028020,77.381836,3.942019,0.280203,-423.547607,0.028939,0.000000
26.360001,17.079605,-423.592102,-0.003842,0.001111,0.028219,75.973877,3.870294,0.282194,-423.592102,0.029356,0.000000
26.610001,17.129501,-423.636566,-0.003842,0.001121,0.028480,76.195824,3.881600,0.284798,-423.636566,0.029772,0.000000
26.860001,18.317741,-423.592102,-0.003816,0.001154,0.029321,81.481384,4.150859,0.293208,-423.592102,0.030188,0.000000
27.110001,17.974792,-423.636566,-0.003790,0.001165,0.029581,79.955872,4.073146,0.295812,-423.636566,0.030605,0.000000
27.360001,18.385513,-423.636566,-0.003755,0.001185,0.030093,81.782845,4.166217,0.300929,-423.636566,0.031021,0.000000
27.610001,18.827896,-423.636566,-0.003747,0.001207,0.030648,83.750664,4.266462,0.306478,-423.636566,0.031437,0.000000
27.860001,18.839066,-423.681061,-0.003742,0.001221,0.031004,83.800346,4.268993,0.310036,-423.681061,0.031854,0.000000
28.110001,18.661819,-423.681061,-0.003742,0.001232,0.031281,83.011917,4.228829,0.312806,-423.681061,0.032269,0.000000
28.360001,18.808159,-423.681061,-0.003695,0.001246,0.031646,83.662872,4.261990,0.316455,-423.681061,0.032686,0.000000
28.610001,19.762550,-423.725525,-0.003691,0.001275,0.032374,87.908211,4.478258,0.323737,-423.725525,0.033102,0.000000
28.860001,19.546577,-423.681061,-0.003673,0.001285,0.032634,86.947517,4.429318,0.326341,-423.681061,0.033527,0.000000
29.110001,19.521996,-423.725525,-0.003639,0.001301,0.033041,86.838173,4.423748,0.330414,-423.725525,0.033944,0.000000
29.360001,19.845589,-423.725525,-0.003596,0.001317,0.033458,88.277588,4.497075,0.334577,-423.725525,0.034359,0.000000
29.610001,20.145721,-423.770020,-0.003600,0.001335,0.033917,89.612648,4.565085,0.339172,-423.770020,0.034776,0.000000
29.860001,20.243286,-423.814514,-0.003600,0.001348,0.034247,90.046631,4.587194,0.342472,-423.814514,0.035192,0.000000
30.110001,20.031403,-423.770020,-0.003548,0.001358,0.034481,89.104126,4.539181,0.344811,-423.770020,0.035608,0.000000
30.360001,20.454422,-423.770020,-0.003535,0.001375,0.034932,90.985817,4.635038,0.349323,-423.770020,0.036025,0.000000
30.610001,21.310127,-423.770020,-0.003535,0.001402,0.035617,94.792183,4.828944,0.356174,-423.770020,0.036441,0.000000
30.860001,21.339920,-423.858978,-0.003540,0.001419,0.036034,94.924706,4.835695,0.360337,-423.858978,0.036857,0.000000
31.110001,21.317947,-423.814514,-0.003484,0.001432,0.036380,94.826965,4.830716,0.363804,-423.814514,0.037274,0.000000
31.360001,21.345505,-423.814514,-0.003449,0.001446,0.036727,94.949547,4.836960,0.367271,-423.814514,0.037690,0.000000
31.610001,21.786026,-423.814514,-0.003454,0.001465,0.037204,96.909081,4.936784,0.372040,-423.814514,0.038106,0.000000
31.860001,21.784531,-423.858978,-0.003432,0.001477,0.037525,96.902435,4.936445,0.375250,-423.858978,0.038523,0.000000
32.110001,21.960289,-423.858978,-0.003415,0.001493,0.037924,97.684242,4.976273,0.379239,-423.858978,0.038938,0.000000
32.360001,22.750465,-423.903473,-0.003402,0.001517,0.038523,101.199127,5.155329,0.385227,-423.903473,0.039355,0.000000
32.610001,22.882660,-423.903473,-0.003385,0.001535,0.038982,101.787155,5.185285,0.389821,-423.903473,0.039771,0.000000
32.860001,22.805954,-423.903473,-0.003350,0.001547,0.039294,101.445953,5.167903,0.392940,-423.903473,0.040187,0.000000
33.110001,22.537094,-423.947937,-0.003354,0.001559,0.039607,100.250000,5.106978,0.396067,-423.947937,0.040604,0.000000
33.360001,22.930695,-423.903473,-0.003337,0.001575,0.040014,102.000824,5.196170,0.400139,-423.903473,0.041020,0.000000
33.610001,22.843933,-423.947937,-0.003294,0.001590,0.040378,101.614891,5.176509,0.403780,-423.947937,0.041436,0.000000
33.860001,23.513458,-423.947937,-0.003290,0.001609,0.040872,104.593086,5.328226,0.408723,-423.947937,0.041861,0.000000
34.110001,24.138298,-423.992432,-0.003307,0.001633,0.041479,107.372513,5.469817,0.414794,-423.992432,0.042277,0.000000
34.360001,24.429863,-423.992432,-0.003260,0.001652,0.041956,108.669456,5.535886,0.419563,-423.992432,0.042694,0.000000
34.610001,24.214264,-424.036896,-0.003212,0.001665,0.042286,107.710426,5.487031,0.422864,-424.036896,0.043110,0.000000
34.860001,24.228783,-424.036896,-0.003216,0.001679,0.042659,107.775009,5.490321,0.426588,-424.036896,0.043526,0.000000
35.110001,24.281662,-424.081390,-0.003199,0.001694,0.043032,108.010223,5.502303,0.430320,-424.081390,0.043943,0.000000
35.360001,24.570999,-424.125854,-0.003173,0.001714,0.043544,109.297264,5.567868,0.435437,-424.125854,0.044359,0.000000
35.610001,25.163437,-424.036896,-0.003152,0.001731,0.043968,111.932556,5.702116,0.439684,-424.036896,0.044775,0.000000
35.860001,24.487953,-424.081390,-0.003143,0.001735,0.044064,108.927856,5.549049,0.440637,-424.081390,0.045191,0.000000
36.110001,25.198441,-424.081390,-0.003117,0.001757,0.044628,112.088264,5.710048,0.446277,-424.081390,0.045607,0.000000
36.360001,25.863503,-424.036896,-0.003083,0.001781,0.045243,115.046608,5.860754,0.452431,-424.036896,0.046024,0.000000
36.610001,26.050056,-424.125854,-0.003126,0.001798,0.045669,115.876442,5.903027,0.456685,-424.125854,0.046440,0.000000
36.860001,25.514587,-424.125854,-0.003057,0.001805,0.045850,113.494553,5.781688,0.458502,-424.125854,0.046856,0.000000
37.110001,25.992714,-424.170349,-0.003040,0.001823,0.046310,115.621368,5.890033,0.463097,-424.170349,0.047273,0.000000
37.360001,25.956223,-424.125854,-0.003044,0.001840,0.046743,115.459045,5.881764,0.467435,-424.125854,0.047689,0.000000
37.610001,26.588135,-424.214844,-0.003022,0.001858,0.047195,118.269928,6.024958,0.471946,-424.214844,0.048105,0.000000
37.860001,26.155815,-424.170349,-0.003009,0.001865,0.047377,116.346878,5.926992,0.473770,-424.170349,0.048522,0.000000
38.110001,27.211113,-424.170349,-0.002958,0.001893,0.048079,121.041077,6.166126,0.480788,-424.170349,0.048938,0.000000
38.360001,27.690361,-424.259308,-0.002975,0.001913,0.048582,123.172874,6.274725,0.485822,-424.259308,0.049354,0.000000
38.610001,27.713074,-424.214844,-0.002962,0.001928,0.048964,123.273911,6.279872,0.489637,-424.214844,0.049770,0.000000
38.860001,27.415550,-424.259308,-0.002915,0.001940,0.049276,121.950455,6.212452,0.492755,-424.259308,0.050195,0.000000
39.110001,27.550720,-424.259308,-0.002906,0.001955,0.049649,122.551727,6.243083,0.496487,-424.259308,0.050612,0.000000
39.360001,28.423935,-424.259308,-0.002880,0.001979,0.050256,126.435974,6.440956,0.502558,-424.259308,0.051028,0.000000
39.610001,27.917877,-424.259308,-0.002867,0.001987,0.050481,124.184921,6.326282,0.504814,-424.259308,0.051444,0.000000
39.860001,28.066826,-424.303802,-0.002859,0.002003,0.050871,124.847473,6.360034,0.508713,-424.303802,0.051860,0.000000
40.110001,28.630974,-424.259308,-0.002820,0.002024,0.051418,127.356934,6.487872,0.514178,-424.259308,0.052276,0.000000
40.360001,29.121017,-424.303802,-0.002790,0.002043,0.051886,129.536758,6.598917,0.518864,-424.303802,0.052693,0.000000
40.610001,28.988075,-424.348267,-0.002798,0.002055,0.052207,128.945404,6.568791,0.522073,-424.348267,0.053109,0.000000
40.860001,28.953445,-424.392761,-0.002759,0.002069,0.052554,128.791351,6.560945,0.525540,-424.392761,0.053525,0.000000
41.110001,29.007812,-424.392761,-0.002738,0.002084,0.052927,129.033188,6.573264,0.529272,-424.392761,0.053942,0.000000
41.360001,29.922363,-424.392761,-0.002742,0.002107,0.053525,133.101318,6.780505,0.535252,-424.392761,0.054358,0.000000
41.610001,29.458015,-424.392761,-0.002695,0.002116,0.053742,131.035797,6.675282,0.537425,-424.392761,0.054774,0.000000
41.860001,30.240364,-424.481720,-0.002699,0.002139,0.054332,134.515854,6.852565,0.543322,-424.481720,0.055191,0.000000
42.110001,30.503258,-424.481720,-0.002669,0.002157,0.054783,135.685272,6.912137,0.547826,-424.481720,0.055607,0.000000
42.360001,30.724075,-424.526184,-0.002656,0.002174,0.055225,136.667511,6.962175,0.552254,-424.526184,0.056023,0.000000
42.610001,30.492088,-424.437225,-0.002626,0.002186,0.055520,135.635590,6.909606,0.555199,-424.437225,0.056439,0.000000
42.860001,30.696526,-424.481720,-0.002604,0.002204,0.055979,136.544968,6.955932,0.559794,-424.481720,0.056855,0.000000
43.110001,30.752007,-424.481720,-0.002587,0.002216,0.056292,136.791763,6.968504,0.562920,-424.481720,0.057272,0.000000
43.360001,31.140022,-424.526184,-0.002565,0.002234,0.056742,138.517731,7.056430,0.567424,-424.526184,0.057688,0.000000
43.610001,31.357857,-424.526184,-0.002570,0.002250,0.057150,139.486710,7.105792,0.571504,-424.526184,0.058104,0.000000
43.860001,31.687035,-424.570679,-0.002552,0.002268,0.057610,140.950974,7.180385,0.576099,-424.570679,0.058521,0.000000
44.110001,32.321556,-424.570679,-0.002496,0.002289,0.058147,143.773468,7.324170,0.581473,-424.570679,0.058945,0.000000
44.360001,32.384857,-424.570679,-0.002462,0.002304,0.058529,144.055038,7.338513,0.585289,-424.570679,0.059362,0.000000
44.610001,32.225853,-424.615173,-0.002471,0.002318,0.058885,143.347748,7.302483,0.588846,-424.615173,0.059778,0.000000
44.860001,31.976364,-424.615173,-0.002432,0.002329,0.059145,142.237976,7.245948,0.591450,-424.615173,0.060194,0.000000
45.110001,32.693932,-424.615173,-0.002419,0.002349,0.059674,145.429871,7.408551,0.596742,-424.615173,0.060611,0.000000
45.360001,32.639565,-424.659637,-0.002384,0.002366,0.060108,145.188034,7.396231,0.601079,-424.659637,0.061027,0.000000
45.610001,32.663025,-424.659637,-0.002376,0.002377,0.060377,145.292389,7.401547,0.603766,-424.659637,0.061443,0.000000
45.860001,32.673820,-424.704132,-0.002354,0.002390,0.060714,145.340408,7.403994,0.607143,-424.704132,0.061860,0.000000
46.110001,33.642365,-424.659637,-0.002354,0.002416,0.061374,149.648712,7.623469,0.613736,-424.659637,0.062276,0.000000
46.360001,33.700455,-424.748596,-0.002328,0.002430,0.061712,149.907104,7.636632,0.617120,-424.748596,0.062692,0.000000
46.610001,33.850143,-424.704132,-0.002333,0.002448,0.062171,150.572952,7.670552,0.621714,-424.704132,0.063108,0.000000
46.860001,33.967812,-424.748596,-0.002289,0.002461,0.062518,151.096375,7.697216,0.625181,-424.748596,0.063524,0.000000
47.110001,34.218048,-424.793091,-0.002268,0.002479,0.062961,152.209473,7.753921,0.629610,-424.793091,0.063941,0.000000
47.360001,34.323059,-424.748596,-0.002220,0.002496,0.063394,152.676590,7.777717,0.633940,-424.748596,0.064357,0.000000
47.610001,33.826683,-424.748596,-0.002212,0.002502,0.063542,150.468597,7.665236,0.635416,-424.748596,0.064773,0.000000
47.860001,34.078407,-424.793091,-0.002216,0.002519,0.063984,151.588333,7.722278,0.639844,-424.793091,0.065190,0.000000
48.110001,35.468849,-424.882050,-0.002195,0.002549,0.064747,157.773315,8.037356,0.647474,-424.882050,0.065606,0.000000
48.360001,35.451721,-424.793091,-0.002143,0.002561,0.065059,157.697128,8.033475,0.650593,-424.793091,0.066022,0.000000
48.610001,35.611839,-424.882050,-0.002143,0.002578,0.065493,158.409378,8.069758,0.654931,-424.882050,0.066439,0.000000
48.860001,35.944366,-424.837555,-0.002108,0.002597,0.065953,159.888535,8.145110,0.659526,-424.837555,0.066855,0.000000
49.110001,36.166306,-424.837555,-0.002082,0.002613,0.066377,160.875763,8.195402,0.663772,-424.837555,0.067280,0.000000
49.360001,36.040810,-424.882050,-0.002074,0.002626,0.066707,160.317535,8.166965,0.667073,-424.882050,0.067696,0.000000
49.610001,35.856491,-424.882050,-0.002052,0.002641,0.067071,159.497635,8.125197,0.670714,-424.882050,0.068112,0.000000
49.860001,37.045471,-424.926514,-0.002001,0.002667,0.067739,164.786484,8.394624,0.677390,-424.926514,0.068529,0.000000
50.110001,37.101326,-424.926514,-0.001996,0.002682,0.068121,165.034943,8.407281,0.681205,-424.926514,0.068945,0.000000
50.360001,36.598251,-424.926514,-0.001949,0.002693,0.068407,162.797150,8.293283,0.684067,-424.926514,0.069360,0.000000
50.610001,36.991852,-424.926514,-0.001962,0.002711,0.068858,164.547974,8.382473,0.688578,-424.926514,0.069777,0.000000
50.860001,37.449867,-425.015472,-0.001932,0.002730,0.069352,166.585327,8.486261,0.693521,-425.015472,0.070193,0.000000
51.110001,37.438324,-425.015472,-0.001923,0.002745,0.069725,166.533981,8.483645,0.697253,-425.015472,0.070609,0.000000
51.360001,37.161278,-425.015472,-0.001876,0.002756,0.069994,165.301620,8.420866,0.699941,-425.015472,0.071026,0.000000
51.610001,37.528816,-425.059967,-0.001876,0.002773,0.070445,166.936508,8.504151,0.704452,-425.059967,0.071442,0.000000
51.860001,38.319359,-425.015472,-0.001837,0.002797,0.071035,170.453018,8.683290,0.710349,-425.015472,0.071859,0.000000
52.110001,38.524536,-425.059967,-0.001850,0.002812,0.071416,171.365692,8.729784,0.714164,-425.059967,0.072275,0.000000
52.360001,38.262756,-425.104462,-0.001819,0.002824,0.071728,170.201248,8.670465,0.717283,-425.104462,0.072691,0.000000
52.610001,38.241158,-425.104462,-0.001768,0.002840,0.072136,170.105164,8.665570,0.721363,-425.104462,0.073108,0.000000
52.860001,38.630287,-425.104462,-0.001742,0.002859,0.072631,171.836105,8.753749,0.726306,-425.104462,0.073524,0.000000
53.110004,38.716682,-425.104462,-0.001716,0.002874,0.072995,172.220398,8.773326,0.729947,-425.104462,0.073939,0.000000
53.360004,38.586723,-425.148926,-0.001716,0.002885,0.073289,171.642319,8.743876,0.732892,-425.148926,0.074356,0.000000
53.610004,38.688011,-425.148926,-0.001694,0.002905,0.073783,172.092865,8.766829,0.737835,-425.148926,0.074772,0.000000
53.860004,39.907898,-425.148926,-0.001656,0.002929,0.074400,177.519196,9.043259,0.743997,-425.148926,0.075188,0.000000
54.110004,39.889282,-425.193420,-0.001617,0.002944,0.074790,177.436386,9.039041,0.747895,-425.193420,0.075614,0.000000
54.360004,39.393280,-425.193420,-0.001604,0.002955,0.075058,175.230057,8.926645,0.750583,-425.193420,0.076029,0.000000
54.610004,39.494942,-425.193420,-0.001600,0.002972,0.075501,175.682281,8.949681,0.755011,-425.193420,0.076446,0.000000
54.860004,39.254761,-425.193420,-0.001561,0.002983,0.075778,174.613892,8.895255,0.757781,-425.193420,0.076862,0.000000
55.110004,40.062805,-425.237885,-0.001531,0.003006,0.076359,178.208252,9.078362,0.763595,-425.237885,0.077278,0.000000
55.360004,39.916840,-425.237885,-0.001531,0.003021,0.076732,177.558975,9.045285,0.767319,-425.237885,0.077695,0.000000
55.610004,40.696213,-425.148926,-0.001487,0.003044,0.077313,181.025803,9.221894,0.773133,-425.148926,0.078111,0.000000
55.860004,40.699936,-425.282379,-0.001492,0.003059,0.077695,181.042358,9.222737,0.776948,-425.282379,0.078527,0.000000
56.110004,40.614662,-425.326843,-0.001453,0.003075,0.078094,180.663040,9.203414,0.780937,-425.326843,0.078944,0.000000
56.360004,40.163345,-425.237885,-0.001393,0.003086,0.078389,178.655487,9.101144,0.783890,-425.237885,0.079360,0.000000
56.610004,40.073982,-425.282379,-0.001362,0.003102,0.078788,178.257980,9.080894,0.787879,-425.282379,0.079777,0.000000
56.860004,41.070076,-425.371338,-0.001367,0.003126,0.079403,182.688828,9.306612,0.794033,-425.371338,0.080193,0.000000
57.110004,40.201706,-425.326843,-0.001332,0.003133,0.079586,178.826126,9.109837,0.795857,-425.326843,0.080608,0.000000
57.360004,40.420654,-425.326843,-0.001328,0.003152,0.080071,179.800049,9.159451,0.800710,-425.326843,0.081025,0.000000
57.610004,41.096512,-425.371338,-0.001319,0.003174,0.080608,182.806412,9.312603,0.806084,-425.371338,0.081441,0.000000
57.860004,41.106941,-425.371338,-0.001259,0.003190,0.081025,182.852814,9.314966,0.810248,-425.371338,0.081857,0.000000
58.110004,40.782234,-425.326843,-0.001242,0.003201,0.081303,181.408432,9.241386,0.813026,-425.326843,0.082274,0.000000
58.360004,41.104332,-425.415802,-0.001203,0.003222,0.081832,182.841202,9.314375,0.818317,-425.415802,0.082690,0.000000
58.610004,40.090736,-425.415802,-0.001186,0.003228,0.081996,178.332504,9.084691,0.819960,-425.415802,0.083106,0.000000
58.860004,41.106941,-425.371338,-0.001168,0.003251,0.082586,182.852814,9.314966,0.825864,-425.371338,0.083523,0.000000
59.110004,40.674988,-425.415802,-0.001130,0.003262,0.082855,180.931381,9.217084,0.828551,-425.415802,0.083939,0.000000
59.360004,40.874207,-425.460297,-0.001117,0.003282,0.083358,181.817551,9.262228,0.833578,-425.460297,0.084364,0.000000
59.610004,42.086281,-425.504791,-0.001087,0.003306,0.083974,187.209122,9.536888,0.839740,-425.504791,0.084780,0.000000
59.860004,41.743698,-425.504791,-0.001048,0.003319,0.084303,185.685242,9.459257,0.843032,-425.504791,0.085196,0.000000
60.110004,41.545593,-425.504791,-0.001022,0.003333,0.084650,184.804031,9.414367,0.846499,-425.504791,0.085613,0.000000
60.360004,41.574265,-425.504791,-0.001018,0.003349,0.085075,184.931564,9.420863,0.850746,-425.504791,0.086029,0.000000
60.610004,41.939194,-425.460297,-0.000992,0.003369,0.085561,186.554855,9.503557,0.855606,-425.460297,0.086445,0.000000
60.860004,42.196503,-425.504791,-0.000979,0.003384,0.085942,187.699417,9.561864,0.859421,-425.504791,0.086862,0.000000
61.110004,41.750031,-425.549255,-0.000944,0.003397,0.086271,185.713409,9.460692,0.862714,-425.549255,0.087277,0.000000
61.360004,42.117928,-425.549255,-0.000901,0.003412,0.086670,187.349899,9.544059,0.866703,-425.549255,0.087694,0.000000
61.610004,43.106583,-425.504791,-0.000892,0.003438,0.087321,191.747650,9.768091,0.873213,-425.504791,0.088110,0.000000
61.860004,42.652657,-425.593750,-0.000849,0.003449,0.087607,189.728485,9.665230,0.876074,-425.593750,0.088526,0.000000
62.110004,42.496635,-425.593750,-0.000841,0.003461,0.087919,189.034470,9.629875,0.879193,-425.593750,0.088943,0.000000
62.360004,42.846291,-425.593750,-0.000819,0.003479,0.088370,190.589813,9.709108,0.883705,-425.593750,0.089359,0.000000
62.610004,43.427940,-425.593750,-0.000811,0.003500,0.088908,193.177124,9.840912,0.889079,-425.593750,0.089775,0.000000
62.860004,43.457726,-425.638214,-0.000763,0.003513,0.089221,193.309616,9.847662,0.892206,-425.638214,0.090192,0.000000
63.110004,42.810913,-425.638214,-0.000767,0.003525,0.089524,190.432449,9.701092,0.895241,-425.638214,0.090608,0.000000
63.360004,44.190559,-425.682709,-0.000716,0.003549,0.090140,196.569427,10.013724,0.901395,-425.682709,0.091024,0.000000
63.610004,44.553246,-425.682709,-0.000707,0.003568,0.090616,198.182739,10.095910,0.906164,-425.682709,0.091440,0.000000
63.860004,44.533508,-425.682709,-0.000673,0.003582,0.090972,198.094940,10.091437,0.909722,-425.682709,0.091856,0.000000
64.110001,44.248276,-425.727173,-0.000668,0.003595,0.091302,196.826157,10.026802,0.913015,-425.727173,0.092273,0.000000
64.360001,44.600914,-425.727173,-0.000647,0.003613,0.091761,198.394775,10.106711,0.917610,-425.727173,0.092698,0.000000
64.610001,45.111061,-425.771667,-0.000647,0.003629,0.092169,200.664017,10.222312,0.921690,-425.771667,0.093114,0.000000
64.860001,45.063766,-425.771667,-0.000617,0.003642,0.092507,200.453644,10.211596,0.925074,-425.771667,0.093530,0.000000
65.110001,44.809067,-425.771667,-0.000608,0.003652,0.092750,199.320679,10.153879,0.927496,-425.771667,0.093946,0.000000
65.360001,46.457558,-425.771667,-0.000578,0.003681,0.093487,206.653534,10.527433,0.934869,-425.771667,0.094363,0.000000
65.610001,46.985954,-425.771667,-0.000552,0.003698,0.093929,209.003967,10.647169,0.939290,-425.771667,0.094779,0.000000
65.860001,47.033989,-425.816132,-0.000509,0.003711,0.094250,209.217636,10.658054,0.942499,-425.816132,0.095195,0.000000
66.110001,47.036598,-425.860626,-0.000509,0.003725,0.094606,209.229233,10.658646,0.946057,-425.860626,0.095612,0.000000
66.360001,47.756020,-425.860626,-0.000496,0.003745,0.095135,212.429382,10.821669,0.951348,-425.860626,0.096028,0.000000
66.610001,48.319794,-425.816132,-0.000466,0.003759,0.095482,214.937180,10.949422,0.954815,-425.816132,0.096444,0.000000
66.860001,48.569283,-425.816132,-0.000470,0.003775,0.095880,216.046951,11.005957,0.958805,-425.816132,0.096861,0.000000
67.110001,47.983543,-425.905121,-0.000418,0.003783,0.096080,213.441467,10.873226,0.960803,-425.905121,0.097277,0.000000
67.360001,49.618629,-425.905121,-0.000444,0.003806,0.096678,220.714691,11.243742,0.966783,-425.905121,0.097693,0.000000
67.610001,50.733513,-425.949585,-0.000410,0.003826,0.097173,225.673935,11.496379,0.971726,-425.949585,0.098109,0.000000
67.860001,50.464661,-425.905121,-0.000405,0.003838,0.097476,224.478027,11.435455,0.974762,-425.905121,0.098525,0.000000
68.110001,51.254463,-425.949585,-0.000354,0.003854,0.097884,227.991241,11.614427,0.978842,-425.949585,0.098942,0.000000
68.360001,52.329872,-425.994080,-0.000332,0.003875,0.098422,232.774902,11.858119,0.984217,-425.994080,0.099358,0.000000
68.610001,52.771133,-425.994080,-0.000354,0.003891,0.098838,234.737732,11.958110,0.988380,-425.994080,0.099774,0.000000
68.860001,53.158401,-425.994080,-0.000328,0.003901,0.099081,236.460373,12.045866,0.990810,-425.994080,0.100191,0.000000
69.110001,53.251495,-425.994080,-0.000315,0.003911,0.099341,236.874481,12.066961,0.993406,-425.994080,0.100607,0.000000
69.360001,55.153198,-425.994080,-0.000310,0.003942,0.100121,245.333679,12.497893,1.001211,-425.994080,0.101032,0.000000
69.610001,55.774689,-426.038544,-0.000306,0.003955,0.100469,248.098206,12.638725,1.004685,-426.038544,0.101448,0.000000
69.860001,56.101265,-426.083038,-0.000267,0.003971,0.100858,249.550888,12.712728,1.008584,-426.083038,0.101864,0.000000
70.110001,57.340515,-426.038544,-0.000280,0.003991,0.101362,255.063354,12.993546,1.013618,-426.038544,0.102281,0.000000
70.360001,58.422256,-426.083038,-0.000250,0.004008,0.101812,259.875183,13.238672,1.018122,-426.083038,0.102697,0.000000
70.610001,58.934273,-426.083038,-0.000220,0.004022,0.102151,262.152740,13.354697,1.021505,-426.083038,0.103113,0.000000
70.860001,59.176689,-426.083038,-0.000237,0.004034,0.102471,263.231049,13.409630,1.024715,-426.083038,0.103530,0.000000
71.110001,60.272575,-426.171997,-0.000229,0.004056,0.103018,268.105804,13.657961,1.030180,-426.171997,0.103946,0.000000
71.360001,61.986984,-426.127502,-0.000190,0.004077,0.103565,275.731873,14.046451,1.035646,-426.127502,0.104362,0.000000
71.610001,62.062202,-426.171997,-0.000198,0.004088,0.103824,276.066467,14.063496,1.038242,-426.171997,0.104778,0.000000
71.860001,62.957382,-426.171997,-0.000164,0.004103,0.104223,280.048431,14.266347,1.042231,-426.171997,0.105194,0.000000
72.110001,63.715164,-426.171997,-0.000177,0.004121,0.104666,283.419220,14.438063,1.046660,-426.171997,0.105611,0.000000
72.360001,64.734344,-426.216461,-0.000142,0.004136,0.105056,287.952759,14.669012,1.050558,-426.216461,0.106027,0.000000
72.610001,65.406845,-426.216461,-0.000155,0.004150,0.105420,290.944183,14.821403,1.054199,-426.216461,0.106443,0.000000
72.860001,65.978821,-426.216461,-0.000142,0.004165,0.105784,293.488464,14.951015,1.057840,-426.216461,0.106860,0.000000
73.110001,67.507401,-426.260956,-0.000121,0.004186,0.106313,300.287903,15.297396,1.063132,-426.260956,0.107276,0.000000
73.360001,66.796173,-426.260956,-0.000116,0.004177,0.106088,297.124207,15.136230,1.060876,-426.260956,0.106313,0.000000
73.610001,66.033173,-426.216461,-0.000116,0.004176,0.106062,293.730225,14.963331,1.060618,-426.216461,0.106088,0.000000
73.860001,65.364029,-426.305420,-0.000095,0.004175,0.106036,290.753723,14.811701,1.060361,-426.305420,0.106088,0.000000
74.110001,64.781631,-426.305420,-0.000082,0.004174,0.106027,288.163086,14.679728,1.060270,-426.305420,0.106088,0.000000
74.360001,64.253616,-426.349915,-0.000086,0.004174,0.106019,285.814362,14.560078,1.060187,-426.349915,0.106088,0.000000
74.610001,63.789261,-426.260956,-0.000112,0.004174,0.106019,283.748810,14.454854,1.060187,-426.260956,0.106088,0.000000
74.860001,63.357315,-426.394409,-0.000082,0.004174,0.106010,281.827423,14.356973,1.060096,-426.394409,0.106088,0.000000
75.110001,62.962967,-426.349915,-0.000069,0.004174,0.106010,280.073273,14.267612,1.060096,-426.349915,0.106088,0.000000
75.360001,62.593948,-426.394409,-0.000082,0.004174,0.106010,278.431793,14.183991,1.060096,-426.394409,0.106088,0.000000
75.610001,62.262535,-426.394409,-0.000082,0.004174,0.106010,276.957581,14.108892,1.060096,-426.394409,0.106088,0.000000
75.860001,61.967987,-426.438873,-0.000065,0.004174,0.106010,275.647369,14.042147,1.060096,-426.438873,0.106088,0.000000
76.110001,61.683128,-426.438873,-0.000065,0.004174,0.106010,274.380249,13.977597,1.060096,-426.438873,0.106088,0.000000
76.360001,61.445549,-426.394409,-0.000065,0.004174,0.106010,273.323456,13.923760,1.060096,-426.394409,0.106088,0.000000
76.610001,61.193825,-426.438873,-0.000082,0.004174,0.106010,272.203735,13.866718,1.060096,-426.438873,0.106088,0.000000
76.860001,60.973381,-426.483368,-0.000073,0.004174,0.106010,271.223145,13.816766,1.060096,-426.483368,0.106088,0.000000
77.110001,60.759270,-426.483368,-0.000069,0.004174,0.106010,270.270721,13.768248,1.060096,-426.483368,0.106088,0.000000
77.360001,60.549622,-426.527832,-0.000056,0.004174,0.106010,269.338165,13.720740,1.060096,-426.527832,0.106088,0.000000
77.610001,60.382057,-426.527832,-0.000052,0.004174,0.106010,268.592804,13.682770,1.060096,-426.527832,0.106088,0.000000
77.860001,60.198479,-426.527832,-0.000034,0.004173,0.106001,267.776215,13.641170,1.060013,-426.527832,0.106088,0.000000
78.110001,60.035004,-426.483368,-0.000056,0.004173,0.106001,267.049042,13.604126,1.060013,-426.483368,0.106088,0.000000
78.360001,59.874512,-426.572327,-0.000047,0.004173,0.106001,266.335144,13.567759,1.060013,-426.572327,0.106088,0.000000
78.610001,59.725937,-426.527832,-0.000039,0.004173,0.106001,265.674225,13.534091,1.060013,-426.527832,0.106088,0.000000
78.860001,59.563210,-426.572327,-0.000043,0.004173,0.106001,264.950378,13.497216,1.060013,-426.572327,0.106088,0.000000
79.110001,59.431763,-426.527832,-0.000052,0.004173,0.106001,264.365692,13.467430,1.060013,-426.527832,0.106088,0.000000
79.360001,59.311859,-426.616791,-0.000034,0.004173,0.106001,263.832336,13.440259,1.060013,-426.616791,0.106088,0.000000
79.610001,59.171844,-426.661285,-0.000056,0.004173,0.106001,263.209503,13.408532,1.060013,-426.661285,0.106088,0.000000
79.860001,59.067207,-426.661285,-0.000026,0.004173,0.106001,262.744049,13.384820,1.060013,-426.661285,0.106088,0.000000
80.110001,58.945816,-426.616791,-0.000047,0.004173,0.106001,262.204071,13.357312,1.060013,-426.616791,0.106088,0.000000
80.360001,58.841927,-426.661285,-0.000022,0.004173,0.106001,261.741974,13.333771,1.060013,-426.661285,0.106088,0.000000
80.610001,58.741379,-426.616791,-0.000073,0.004173,0.106001,261.294708,13.310987,1.060013,-426.616791,0.106088,0.000000
80.860001,58.646431,-426.661285,-0.000017,0.004173,0.106001,260.872345,13.289472,1.060013,-426.661285,0.106088,0.000000
81.110001,58.543282,-426.750244,-0.000069,0.004173,0.106001,260.413513,13.266097,1.060013,-426.750244,0.106088,0.000000
81.360001,58.436409,-426.750244,-0.000039,0.004173,0.106001,259.938141,13.241879,1.060013,-426.750244,0.106088,0.000000
81.610001,58.346298,-426.705750,-0.000022,0.004173,0.106001,259.537292,13.221460,1.060013,-426.705750,0.106088,0.000000
81.860001,58.252083,-426.750244,-0.000039,0.004173,0.106001,259.118195,13.200110,1.060013,-426.750244,0.106088,0.000000
82.110001,58.170906,-426.705750,-0.000034,0.004173,0.106001,258.757111,13.181716,1.060013,-426.705750,0.106088,0.000000
82.360001,58.100159,-426.750244,-0.000052,0.004173,0.106001,258.442413,13.165685,1.060013,-426.750244,0.106088,0.000000
82.610001,58.013023,-426.794739,-0.000039,0.004173,0.106001,258.054810,13.145939,1.060013,-426.794739,0.106088,0.000000
82.860001,57.940407,-426.839203,-0.000039,0.004173,0.106001,257.731812,13.129483,1.060013,-426.839203,0.106088,0.000000
83.110001,57.873009,-426.794739,-0.000043,0.004173,0.106001,257.432007,13.114211,1.060013,-426.794739,0.106088,0.000000
83.360001,57.800400,-426.883698,-0.000034,0.004173,0.106001,257.109009,13.097758,1.060013,-426.883698,0.106088,0.000000
83.610001,57.728157,-426.883698,-0.000056,0.004173,0.106001,256.787659,13.081388,1.060013,-426.883698,0.106088,0.000000
83.860001,57.646233,-426.839203,-0.000026,0.004173,0.106001,256.423248,13.062823,1.060013,-426.839203,0.106088,0.000000
84.110001,57.592239,-426.883698,-0.000026,0.004173,0.106001,256.183075,13.050589,1.060013,-426.883698,0.106088,0.000000
84.360001,57.528564,-426.883698,-0.000017,0.004173,0.106001,255.899841,13.036160,1.060013,-426.883698,0.106088,0.000000
84.610001,57.470100,-426.928162,-0.000052,0.004173,0.106001,255.639771,13.022911,1.060013,-426.928162,0.106088,0.000000
84.860001,57.410149,-426.839203,-0.000047,0.004173,0.106001,255.373093,13.009325,1.060013,-426.839203,0.106088,0.000000
85.110001,57.342751,-426.883698,-0.000030,0.004173,0.106001,255.073288,12.994054,1.060013,-426.883698,0.106088,0.000000
85.360001,57.277962,-426.928162,-0.000022,0.004173,0.106001,254.785095,12.979372,1.060013,-426.928162,0.106088,0.000000
85.610001,57.227318,-426.928162,-0.000047,0.004173,0.106001,254.559830,12.967896,1.060013,-426.928162,0.106088,0.000000
85.860001,57.182259,-426.883698,0.000004,0.004173,0.106001,254.359390,12.957685,1.060013,-426.883698,0.106088,0.000000
86.110001,57.112625,-426.928162,-0.000017,0.004173,0.106001,254.049652,12.941906,1.060013,-426.928162,0.106088,0.000000
86.360001,57.064964,-427.017120,-0.000026,0.004173,0.106001,253.837631,12.931106,1.060013,-427.017120,0.106088,0.000000
86.610001,57.000542,-427.017120,-0.000026,0.004173,0.106001,253.551071,12.916508,1.060013,-427.017120,0.106088,0.000000
86.860001,56.967773,-427.061615,-0.000017,0.004173,0.106001,253.405319,12.909082,1.060013,-427.061615,0.106088,0.000000
87.110001,56.910423,-427.017120,-0.000030,0.004173,0.106001,253.150208,12.896087,1.060013,-427.017120,0.106088,0.000000
87.360001,56.852341,-427.061615,-0.000009,0.004173,0.106001,252.891846,12.882924,1.060013,-427.061615,0.106088,0.000000
87.610001,56.805794,-427.061615,-0.000043,0.004173,0.106001,252.684784,12.872377,1.060013,-427.061615,0.106088,0.000000
87.860001,56.760735,-427.106079,-0.000026,0.004173,0.106001,252.484360,12.862165,1.060013,-427.106079,0.106088,0.000000
88.110001,56.726479,-427.061615,-0.000034,0.004173,0.106001,252.331985,12.854403,1.060013,-427.061615,0.106088,0.000000
88.360001,56.665031,-427.150574,-0.000026,0.004173,0.106001,252.058655,12.840480,1.060013,-427.150574,0.106088,0.000000
88.610001,56.615883,-427.061615,-0.000017,0.004173,0.106001,251.840027,12.829343,1.060013,-427.061615,0.106088,0.000000
88.860001,56.594284,-427.150574,-0.000030,0.004173,0.106001,251.743942,12.824448,1.060013,-427.150574,0.106088,0.000000
89.110001,56.538803,-427.150574,-0.000039,0.004173,0.106001,251.497162,12.811876,1.060013,-427.150574,0.106088,0.000000
89.360001,56.504539,-427.061615,-0.000026,0.004173,0.106001,251.344742,12.804111,1.060013,-427.061615,0.106088,0.000000
89.610001,56.444962,-427.239532,-0.000043,0.004173,0.106001,251.079727,12.790610,1.060013,-427.239532,0.106088,0.000000
89.860001,56.408470,-427.195068,-0.000009,0.004173,0.106001,250.917404,12.782342,1.060013,-427.195068,0.106088,0.000000
90.110001,56.377190,-427.195068,-0.000026,0.004173,0.106001,250.778259,12.775253,1.060013,-427.195068,0.106088,0.000000
90.360001,56.335114,-427.239532,-0.000022,0.004173,0.106001,250.591095,12.765719,1.060013,-427.239532,0.106088,0.000000
90.610001,56.293030,-427.195068,-0.000022,0.004173,0.106001,250.403900,12.756183,1.060013,-427.195068,0.106088,0.000000
90.860001,56.259521,-427.239532,-0.000022,0.004173,0.106001,250.254852,12.748590,1.060013,-427.239532,0.106088,0.000000
91.110001,56.220047,-427.284027,-0.000004,0.004173,0.106001,250.079254,12.739645,1.060013,-427.284027,0.106088,0.000000
91.360001,56.194351,-427.284027,-0.000004,0.004173,0.106001,249.964966,12.733822,1.060013,-427.284027,0.106088,0.000000
91.610001,56.148178,-427.284027,-0.000013,0.004173,0.106001,249.759567,12.723359,1.060013,-427.284027,0.106088,0.000000
91.860001,56.103127,-427.284027,-0.000017,0.004173,0.106001,249.559174,12.713150,1.060013,-427.284027,0.106088,0.000000
92.110001,56.082268,-427.372986,-0.000004,0.004173,0.106001,249.466385,12.708424,1.060013,-427.372986,0.106088,0.000000
92.360001,56.040939,-427.328491,-0.000017,0.004173,0.106001,249.282547,12.699059,1.060013,-427.328491,0.106088,0.000000
92.610001,56.021202,-427.328491,0.000004,0.004173,0.106001,249.194748,12.694586,1.060013,-427.328491,0.106088,0.000000
92.860001,55.971306,-427.328491,-0.000017,0.004173,0.106001,248.972809,12.683279,1.060013,-427.328491,0.106088,0.000000
93.110001,55.941139,-427.328491,-0.000030,0.004173,0.106001,248.838608,12.676443,1.060013,-427.328491,0.106088,0.000000
93.360008,55.908371,-427.328491,-0.000013,0.004173,0.106001,248.692856,12.669018,1.060013,-427.328491,0.106088,0.000000
93.610008,55.879700,-427.372986,-0.000026,0.004173,0.106001,248.565323,12.662520,1.060013,-427.372986,0.106088,0.000000
93.860008,55.856987,-427.417450,-0.000026,0.004173,0.106001,248.464294,12.657374,1.060013,-427.417450,0.106088,0.000000
94.110008,55.803734,-427.461945,-0.000017,0.004173,0.106001,248.227402,12.645308,1.060013,-427.461945,0.106088,0.000000
94.360008,55.790329,-427.506409,0.000000,0.004173,0.106001,248.167770,12.642269,1.060013,-427.506409,0.106088,0.000000
94.610008,55.756447,-427.417450,0.000000,0.004173,0.106001,248.017059,12.634592,1.060013,-427.417450,0.106088,0.000000
94.860008,55.730751,-427.417450,0.000009,0.004173,0.106001,247.902756,12.628769,1.060013,-427.417450,0.106088,0.000000
95.110008,55.692024,-427.506409,-0.000022,0.004173,0.106001,247.730499,12.619993,1.060013,-427.506409,0.106088,0.000000
95.360008,55.656273,-427.506409,-0.000004,0.004173,0.106001,247.571472,12.611892,1.060013,-427.506409,0.106088,0.000000
95.610008,55.630959,-427.461945,-0.000030,0.004173,0.106001,247.458862,12.606155,1.060013,-427.461945,0.106088,0.000000
95.860008,55.610100,-427.550903,-0.000013,0.004173,0.106001,247.366074,12.601428,1.060013,-427.550903,0.106088,0.000000
96.110008,55.575470,-427.506409,-0.000022,0.004173,0.106001,247.212036,12.593581,1.060013,-427.506409,0.106088,0.000000
96.360008,55.540466,-427.550903,-0.000026,0.004173,0.106001,247.056335,12.585649,1.060013,-427.550903,0.106088,0.000000
96.610008,55.524086,-427.550903,-0.000009,0.004173,0.106001,246.983475,12.581938,1.060013,-427.550903,0.106088,0.000000
96.860008,55.503601,-427.550903,-0.000026,0.004173,0.106001,246.892349,12.577295,1.060013,-427.550903,0.106088,0.000000
97.110008,55.468597,-427.595367,-0.000013,0.004173,0.106001,246.736649,12.569364,1.060013,-427.595367,0.106088,0.000000
97.360008,55.432480,-427.550903,0.000009,0.004173,0.106001,246.575989,12.561179,1.060013,-427.550903,0.106088,0.000000
97.610008,55.407906,-427.595367,-0.000030,0.004173,0.106001,246.466675,12.555611,1.060013,-427.595367,0.106088,0.000000
97.860008,55.394127,-427.595367,-0.000030,0.004173,0.106001,246.405380,12.552488,1.060013,-427.595367,0.106088,0.000000
98.110008,55.376999,-427.639862,0.000004,0.004173,0.106001,246.329193,12.548608,1.060013,-427.639862,0.106088,0.000000
98.360008,55.327469,-427.639862,-0.000034,0.004173,0.106001,246.108871,12.537384,1.060013,-427.639862,0.106088,0.000000
98.610008,55.312202,-427.639862,-0.000013,0.004173,0.106001,246.040970,12.533924,1.060013,-427.639862,0.106088,0.000000
98.860008,55.283531,-427.639862,-0.000013,0.004173,0.106001,245.913422,12.527428,1.060013,-427.639862,0.106088,0.000000
99.110008,55.263054,-427.684357,-0.000013,0.004173,0.106001,245.822342,12.522787,1.060013,-427.684357,0.106088,0.000000
99.360008,55.241455,-427.684357,-0.000026,0.004173,0.106001,245.726257,12.517893,1.060013,-427.684357,0.106088,0.000000
99.610008,55.209061,-427.728821,-0.000022,0.004173,0.106001,245.582169,12.510551,1.060013,-427.728821,0.106088,0.000000
99.860008,55.191925,-427.728821,-0.000013,0.004173,0.106001,245.505951,12.506669,1.060013,-427.728821,0.106088,0.000000
100.110008,55.158043,-427.684357,-0.000009,0.004173,0.106001,245.355225,12.498991,1.060013,-427.684357,0.106088,0.000000
100.360008,55.139053,-427.684357,-0.000022,0.004173,0.106001,245.270752,12.494688,1.060013,-427.684357,0.106088,0.000000
100.610008,55.111870,-427.773315,0.000009,0.004173,0.106001,245.149841,12.488528,1.060013,-427.773315,0.106088,0.000000
100.860008,55.103302,-427.773315,-0.000004,0.004173,0.106001,245.111725,12.486587,1.060013,-427.773315,0.106088,0.000000
101.110008,55.083199,-427.817780,0.000000,0.004173,0.106001,245.022308,12.482031,1.060013,-427.817780,0.106088,0.000000
101.360008,55.044098,-427.773315,-0.000022,0.004173,0.106001,244.848373,12.473170,1.060013,-427.773315,0.106088,0.000000
101.610008,55.015793,-427.817780,-0.000017,0.004173,0.106001,244.722473,12.466757,1.060013,-427.817780,0.106088,0.000000
101.860008,55.005371,-427.862274,-0.000039,0.004173,0.106001,244.676117,12.464396,1.060013,-427.862274,0.106088,0.000000
102.110008,54.988983,-427.773315,-0.000013,0.004173,0.106001,244.603210,12.460681,1.060013,-427.773315,0.106088,0.000000
102.360008,54.960312,-427.817780,-0.000022,0.004173,0.106001,244.475677,12.454185,1.060013,-427.817780,0.106088,0.000000
102.610008,54.939461,-427.951233,-0.000026,0.004173,0.106001,244.382919,12.449459,1.060013,-427.951233,0.106088,0.000000
102.860008,54.917488,-427.817780,-0.000009,0.004173,0.106001,244.285187,12.444481,1.060013,-427.817780,0.106088,0.000000
103.110008,54.892540,-427.906738,-0.000013,0.004173,0.106001,244.174210,12.438828,1.060013,-427.906738,0.106088,0.000000
103.360008,54.882111,-427.906738,-0.000009,0.004173,0.106001,244.127823,12.436463,1.060013,-427.906738,0.106088,0.000000
103.600006,54.857162,-427.906738,-0.000004,0.004173,0.106001,244.016846,12.430811,1.060013,-427.906738,0.106088,0.000000