File: Data/compression 14/AutoNoHeating-16-14-3-240726_07262024_171104.csv
Time (sec),S:Load (lbs),S:HL1 (DIM),S:LVDT (in),S:Position (in),Ch:Position (mm),Ch:Load (N),Ch:Stress (MPa),Ch:Strain (mm/mm),Ch:HL1 (DIM),Set Point (),Cycles ()
0.010000,-0.014526,-467.138947,-0.009343,-0.004849,-0.123164,-0.064617,-0.003292,-1.231635,-467.138947,-0.122955,0.000000
0.240000,-0.017128,-467.138947,-0.009317,-0.004849,-0.123164,-0.076189,-0.003881,-1.231635,-467.138947,-0.122955,0.000000
0.470000,-0.016754,-467.138947,-0.009360,-0.004780,-0.121420,-0.074526,-0.003797,-1.214202,-467.138947,-0.120805,0.000000
0.700000,-0.035751,-467.183441,-0.009274,-0.004648,-0.118064,-0.159030,-0.008101,-1.180637,-467.183441,-0.116971,0.000000
0.930000,-0.021225,-467.138947,-0.009110,-0.004496,-0.114205,-0.094413,-0.004810,-1.142047,-467.138947,-0.113138,0.000000
1.160000,-0.017876,-467.183441,-0.009037,-0.004360,-0.110745,-0.079515,-0.004051,-1.107445,-467.183441,-0.109305,0.000000
1.390000,-0.035378,-467.227905,-0.008804,-0.004190,-0.106418,-0.157367,-0.008017,-1.064176,-467.227905,-0.105472,0.000000
1.620000,-0.025696,-467.183441,-0.008640,-0.004048,-0.102827,-0.114301,-0.005823,-1.028273,-467.183441,-0.101639,0.000000
1.850000,-0.023087,-467.183441,-0.008498,-0.003895,-0.098942,-0.102694,-0.005231,-0.989417,-467.183441,-0.097805,0.000000
2.080000,-0.008568,-467.183441,-0.008343,-0.003742,-0.095057,-0.038112,-0.001941,-0.950569,-467.183441,-0.093990,0.000000
2.310000,-0.000748,-467.183441,-0.008192,-0.003601,-0.091457,-0.003326,-0.000169,-0.914574,-467.183441,-0.090157,0.000000
2.540000,-0.011917,-467.227905,-0.008037,-0.003443,-0.087460,-0.053010,-0.002700,-0.874598,-467.227905,-0.086324,0.000000
2.770000,-0.025696,-467.272400,-0.007847,-0.003285,-0.083445,-0.114301,-0.005823,-0.834448,-467.272400,-0.082490,0.000000
3.000000,-0.054367,-467.272400,-0.007705,-0.003144,-0.079854,-0.241837,-0.012320,-0.798545,-467.272400,-0.078658,0.000000
3.230000,-0.029793,-467.227905,-0.007541,-0.002986,-0.075856,-0.132525,-0.006751,-0.758561,-467.227905,-0.074824,0.000000
3.460000,-0.023460,-467.316864,-0.007360,-0.002845,-0.072257,-0.104357,-0.005316,-0.722574,-467.316864,-0.070991,0.000000
3.690000,0.006332,-467.316864,-0.007226,-0.002688,-0.068268,0.028168,0.001435,-0.682682,-467.316864,-0.067158,0.000000
3.920000,-0.008942,-467.272400,-0.007080,-0.002532,-0.064305,-0.039774,-0.002026,-0.643046,-467.272400,-0.063325,0.000000
4.150000,-0.037613,-467.316864,-0.006903,-0.002389,-0.060679,-0.167311,-0.008523,-0.606794,-467.316864,-0.059492,0.000000
4.380000,-0.009682,-467.227905,-0.006743,-0.002238,-0.056847,-0.043066,-0.002194,-0.568469,-467.227905,-0.055658,0.000000
4.610000,-0.002235,-467.316864,-0.006588,-0.002083,-0.052910,-0.009944,-0.000507,-0.529098,-467.316864,-0.051825,0.000000
4.840000,-0.000374,-467.361359,-0.006428,-0.001942,-0.049319,-0.001663,-0.000085,-0.493195,-467.361359,-0.047992,0.000000
5.070000,-0.023460,-467.405823,-0.006252,-0.001781,-0.045226,-0.104357,-0.005316,-0.452257,-467.405823,-0.044177,0.000000
5.300000,-0.052132,-467.316864,-0.006122,-0.001629,-0.041367,-0.231893,-0.011813,-0.413666,-467.316864,-0.040343,0.000000
5.530000,-0.054367,-467.316864,-0.005967,-0.001483,-0.037673,-0.241837,-0.012320,-0.376726,-467.316864,-0.036510,0.000000
5.760000,-0.021973,-467.361359,-0.005795,-0.001326,-0.033683,-0.097739,-0.004979,-0.336833,-467.361359,-0.032677,0.000000
5.990000,0.012657,-467.405823,-0.005618,-0.001179,-0.029937,0.056302,0.002868,-0.299370,-467.405823,-0.028844,0.000000
6.220000,0.010056,-467.316864,-0.005493,-0.001028,-0.026104,0.044729,0.002279,-0.261037,-467.316864,-0.025011,0.000000
6.450000,0.008194,-467.405823,-0.005351,-0.000878,-0.022313,0.036449,0.001857,-0.223135,-467.405823,-0.021178,0.000000
6.680000,-0.009308,-467.450317,-0.005174,-0.000729,-0.018515,-0.041403,-0.002109,-0.185149,-467.450317,-0.017345,0.000000
6.910000,-0.025322,-467.450317,-0.004980,-0.000572,-0.014526,-0.112638,-0.005738,-0.145257,-467.450317,-0.013511,0.000000
7.140000,-0.010803,-467.405823,-0.004876,-0.000430,-0.010927,-0.048055,-0.002448,-0.109270,-467.405823,-0.009678,0.000000
7.370000,-0.016014,-467.450317,-0.004708,-0.000271,-0.006885,-0.071234,-0.003629,-0.068855,-467.450317,-0.005845,0.000000
7.600000,0.006332,-467.405823,-0.004518,-0.000116,-0.002940,0.028168,0.001435,-0.029401,-467.405823,-0.002012,0.000000
7.830000,0.628563,-467.450317,-0.004342,0.000027,0.000685,2.795988,0.142434,0.006851,-467.450317,0.001804,0.000000
8.060000,0.731712,-467.450317,-0.004359,-0.000000,-0.000009,3.254819,0.165808,-0.000091,-467.450317,0.000191,0.000000
8.290000,0.698196,-467.494781,-0.004350,-0.000000,-0.000009,3.105733,0.158214,-0.000091,-467.494781,0.000191,0.000000
8.520000,0.711227,-467.583771,-0.004355,-0.000000,-0.000009,3.163697,0.161166,-0.000091,-467.583771,0.000425,0.000000
8.750000,0.628937,-467.450317,-0.004368,-0.000000,-0.000009,2.797651,0.142519,-0.000091,-467.450317,0.000806,0.000000
8.980000,0.650536,-467.539276,-0.004376,-0.000000,-0.000000,2.893727,0.147413,-0.000000,-467.539276,0.001197,0.000000
9.210000,1.010994,-467.494781,-0.004355,0.000030,0.000755,4.497126,0.229095,0.007547,-467.494781,0.001578,0.000000
9.440001,1.270531,-467.583771,-0.004324,0.000045,0.001154,5.651603,0.287906,0.011536,-467.583771,0.001960,0.000000
9.670000,1.441452,-467.539276,-0.004333,0.000056,0.001413,6.411899,0.326638,0.014133,-467.539276,0.002341,0.000000
9.900001,1.669716,-467.539276,-0.004312,0.000070,0.001777,7.427267,0.378363,0.017774,-467.539276,0.002723,0.000000
10.130000,2.004105,-467.494781,-0.004277,0.000091,0.002324,8.914702,0.454137,0.023239,-467.494781,0.003113,0.000000
10.360001,2.275566,-467.628235,-0.004290,0.000105,0.002662,10.122224,0.515651,0.026623,-467.628235,0.003495,0.000000
10.590000,2.440903,-467.628235,-0.004268,0.000115,0.002931,10.857677,0.553116,0.029310,-467.628235,0.003876,0.000000
10.820001,2.701561,-467.583771,-0.004260,0.000129,0.003269,12.017143,0.612182,0.032694,-467.583771,0.004258,0.000000
11.050000,2.892220,-467.628235,-0.004238,0.000142,0.003616,12.865235,0.655386,0.036161,-467.628235,0.004640,0.000000
11.280001,3.495461,-467.628235,-0.004251,0.000167,0.004232,15.548585,0.792083,0.042323,-467.628235,0.005030,0.000000
11.510000,3.661537,-467.717194,-0.004221,0.000177,0.004501,16.287331,0.829716,0.045010,-467.717194,0.005412,0.000000
11.740001,3.983269,-467.672729,-0.004199,0.000192,0.004865,17.718464,0.902622,0.048651,-467.672729,0.005793,0.000000
11.970000,4.417084,-467.672729,-0.004186,0.000210,0.005334,19.648170,1.000926,0.053337,-467.672729,0.006175,0.000000
12.200001,4.747749,-467.761688,-0.004165,0.000227,0.005767,21.119043,1.075855,0.057667,-467.761688,0.006556,0.000000
12.430000,5.025162,-467.717194,-0.004169,0.000240,0.006105,22.353035,1.138718,0.061050,-467.717194,0.006946,0.000000
12.660001,5.243004,-467.717194,-0.004152,0.000251,0.006383,23.322046,1.188082,0.063828,-467.717194,0.007328,0.000000
12.890000,5.619469,-467.717194,-0.004139,0.000266,0.006747,24.996645,1.273390,0.067470,-467.717194,0.007710,0.000000
13.120001,5.905457,-467.761688,-0.004152,0.000282,0.007172,26.268784,1.338196,0.071716,-467.761688,0.008091,0.000000
13.350000,6.241333,-467.717194,-0.004100,0.000296,0.007527,27.762836,1.414306,0.075274,-467.717194,0.008481,0.000000
13.580001,6.623016,-467.761688,-0.004070,0.000311,0.007909,29.460648,1.500797,0.079089,-467.761688,0.008863,0.000000
13.810000,6.989799,-467.850647,-0.004074,0.000327,0.008300,31.092180,1.583911,0.082995,-467.850647,0.009244,0.000000
14.040001,7.578896,-467.806152,-0.004074,0.000349,0.008863,33.712612,1.717402,0.088627,-467.806152,0.009626,0.000000
14.270000,7.758003,-467.806152,-0.004074,0.000363,0.009210,34.509323,1.757989,0.092102,-467.806152,0.010008,0.000000
14.500001,7.892059,-467.806152,-0.004049,0.000375,0.009530,35.105633,1.788366,0.095304,-467.806152,0.010398,0.000000
14.730000,8.080856,-467.761688,-0.004018,0.000385,0.009791,35.945446,1.831148,0.097908,-467.761688,0.010779,0.000000
14.960001,8.617073,-467.895111,-0.003997,0.000406,0.010302,38.330654,1.952657,0.103025,-467.895111,0.011161,0.000000
15.190001,9.043068,-467.850647,-0.003997,0.000420,0.010658,40.225574,2.049188,0.106583,-467.850647,0.011542,0.000000
15.420001,9.266487,-467.939606,-0.004010,0.000434,0.011022,41.219395,2.099816,0.110224,-467.939606,0.011924,0.000000
15.650001,9.128708,-467.850647,-0.003997,0.000438,0.011126,40.606522,2.068595,0.111261,-467.850647,0.012315,0.000000
15.880001,9.623222,-467.895111,-0.003945,0.000457,0.011620,42.806232,2.180653,0.116204,-467.895111,0.012696,0.000000
16.110001,10.163162,-467.939606,-0.003936,0.000477,0.012124,45.208004,2.303005,0.121238,-467.939606,0.013078,0.000000
16.340000,10.579475,-467.895111,-0.003936,0.000493,0.012514,47.059856,2.397343,0.125136,-467.895111,0.013459,0.000000
16.570002,10.822632,-467.939606,-0.003928,0.000509,0.012930,48.141472,2.452444,0.129300,-467.939606,0.013841,0.000000
16.800001,10.968231,-467.895111,-0.003902,0.000520,0.013208,48.789127,2.485437,0.132078,-467.895111,0.014231,0.000000
17.030001,11.370766,-467.984100,-0.003872,0.000537,0.013632,50.579693,2.576652,0.136324,-467.984100,0.014613,0.000000
17.260000,11.683182,-467.984100,-0.003876,0.000554,0.014075,51.969387,2.647447,0.140753,-467.984100,0.014994,0.000000
17.490002,11.685043,-467.984100,-0.003867,0.000562,0.014283,51.977669,2.647869,0.142834,-467.984100,0.015376,0.000000
17.720001,11.804207,-467.939606,-0.003859,0.000576,0.014621,52.507736,2.674871,0.146210,-467.939606,0.015757,0.000000
17.950001,12.888924,-467.939606,-0.003837,0.000601,0.015272,57.332794,2.920672,0.152721,-467.939606,0.016148,0.000000
18.180000,12.873657,-467.984100,-0.003829,0.000613,0.015567,57.264889,2.917212,0.155665,-467.984100,0.016529,0.000000
18.410002,12.811470,-468.073059,-0.003829,0.000625,0.015887,56.988266,2.903121,0.158875,-468.073059,0.016911,0.000000
18.640001,13.330185,-467.939606,-0.003798,0.000645,0.016382,59.295624,3.020663,0.163818,-467.939606,0.017292,0.000000
18.870001,13.681335,-467.984100,-0.003777,0.000661,0.016781,60.857620,3.100235,0.167807,-467.984100,0.017674,0.000000
19.100000,13.840714,-467.984100,-0.003807,0.000676,0.017171,61.566570,3.136350,0.171713,-467.984100,0.018065,0.000000
19.330002,13.920029,-468.073059,-0.003747,0.000688,0.017475,61.919380,3.154324,0.174749,-468.073059,0.018446,0.000000
19.560001,13.841454,-468.028564,-0.003742,0.000697,0.017700,61.569859,3.136518,0.176997,-468.028564,0.018828,0.000000
19.790001,14.819305,-468.073059,-0.003729,0.000723,0.018359,65.919563,3.358103,0.183590,-468.073059,0.019209,0.000000
20.020000,15.022621,-468.073059,-0.003725,0.000739,0.018775,66.823959,3.404175,0.187753,-468.073059,0.019591,0.000000
20.250002,14.984642,-468.028564,-0.003682,0.000751,0.019070,66.655014,3.395568,0.190698,-468.028564,0.019980,0.000000
20.480001,15.085548,-468.073059,-0.003669,0.000764,0.019417,67.103874,3.418434,0.194173,-468.073059,0.020362,0.000000
20.710001,15.444145,-468.206482,-0.003660,0.000781,0.019842,68.698990,3.499693,0.198419,-468.206482,0.020744,0.000000
20.940001,15.829926,-468.162018,-0.003660,0.000799,0.020293,70.415024,3.587112,0.202931,-468.162018,0.021126,0.000000
21.170000,15.785614,-468.117523,-0.003609,0.000809,0.020553,70.217918,3.577071,0.205535,-468.117523,0.021507,0.000000
21.400002,15.604263,-468.117523,-0.003609,0.000816,0.020735,69.411232,3.535977,0.207352,-468.117523,0.021897,0.000000
21.630001,16.090958,-468.206482,-0.003609,0.000837,0.021255,71.576157,3.646263,0.212552,-468.206482,0.022279,0.000000
21.860001,16.855064,-468.162018,-0.003604,0.000861,0.021862,74.975067,3.819412,0.218623,-468.162018,0.022660,0.000000
22.090000,16.954117,-468.162018,-0.003553,0.000877,0.022279,75.415680,3.841858,0.222786,-468.162018,0.023042,0.000000
22.320002,16.692711,-468.162018,-0.003523,0.000887,0.022522,74.252884,3.782622,0.225216,-468.162018,0.023432,0.000000
22.550001,16.955231,-468.250977,-0.003531,0.000902,0.022903,75.420631,3.842110,0.229032,-468.250977,0.023814,0.000000
22.780001,17.200996,-468.206482,-0.003514,0.000916,0.023276,76.513855,3.897801,0.232763,-468.206482,0.024195,0.000000
23.010000,17.357399,-468.295441,-0.003501,0.000931,0.023640,77.209564,3.933243,0.236405,-468.295441,0.024577,0.000000
23.240002,17.357765,-468.250977,-0.003484,0.000942,0.023927,77.211197,3.933326,0.239266,-468.250977,0.024958,0.000000
23.470001,17.702957,-468.250977,-0.003479,0.000959,0.024351,78.746689,4.011548,0.243513,-468.250977,0.025349,0.000000
23.700001,18.083153,-468.250977,-0.003479,0.000978,0.024837,80.437881,4.097701,0.248372,-468.250977,0.025730,0.000000
23.930000,18.360939,-468.295441,-0.003428,0.000996,0.025288,81.673538,4.160648,0.252884,-468.295441,0.026112,0.000000
24.160002,18.151291,-468.295441,-0.003423,0.001006,0.025540,80.740974,4.113142,0.255397,-468.295441,0.026494,0.000000
24.390001,18.108475,-468.250977,-0.003415,0.001020,0.025904,80.550522,4.103439,0.259038,-468.250977,0.026875,0.000000
24.620001,18.384026,-468.339935,-0.003402,0.001033,0.026233,81.776230,4.165880,0.262331,-468.339935,0.027266,0.000000
24.850000,17.983353,-468.295441,-0.003397,0.001045,0.026554,79.993950,4.075086,0.265541,-468.295441,0.027647,0.000000
25.080002,19.074036,-468.339935,-0.003372,0.001066,0.027075,84.845551,4.322238,0.270749,-468.339935,0.028029,0.000000
25.310001,19.077011,-468.473389,-0.003359,0.001079,0.027413,84.858780,4.322913,0.274132,-468.473389,0.028410,0.000000
25.540001,19.619934,-468.339935,-0.003307,0.001103,0.028020,87.273827,4.445940,0.280196,-468.339935,0.028792,0.000000
25.770000,19.563705,-468.339935,-0.003307,0.001117,0.028367,87.023705,4.433199,0.283670,-468.339935,0.029182,0.000000
26.000002,19.470985,-468.384399,-0.003264,0.001131,0.028722,86.611267,4.412189,0.287221,-468.384399,0.029564,0.000000
26.230001,19.434860,-468.428894,-0.003260,0.001144,0.029052,86.450577,4.404002,0.290521,-468.428894,0.029945,0.000000
26.460001,19.393532,-468.428894,-0.003277,0.001153,0.029286,86.266739,4.394637,0.292860,-468.428894,0.030327,0.000000
26.690001,20.241791,-468.428894,-0.003251,0.001178,0.029911,90.039986,4.586855,0.299105,-468.428894,0.030708,0.000000
26.920002,20.211258,-468.384399,-0.003247,0.001189,0.030197,89.904167,4.579937,0.301966,-468.384399,0.031099,0.000000
27.150002,19.648979,-468.428894,-0.003221,0.001192,0.030275,87.403023,4.452522,0.302746,-468.428894,0.031480,0.000000
27.380001,20.310310,-468.473389,-0.003225,0.001214,0.030829,90.344772,4.602382,0.308295,-468.473389,0.031862,0.000000
27.610001,21.118355,-468.517853,-0.003169,0.001239,0.031463,93.939133,4.785488,0.314631,-468.517853,0.032244,0.000000
27.840002,20.938873,-468.428894,-0.003160,0.001252,0.031792,93.140762,4.744816,0.317924,-468.428894,0.032625,0.000000
28.070002,20.643211,-468.517853,-0.003152,0.001260,0.032001,91.825592,4.677819,0.320005,-468.517853,0.033015,0.000000
28.300001,21.107933,-468.517853,-0.003130,0.001280,0.032521,93.892776,4.783126,0.325206,-468.517853,0.033396,0.000000
28.530001,20.555328,-468.562347,-0.003130,0.001285,0.032651,91.434669,4.657904,0.326508,-468.562347,0.033779,0.000000
28.760002,21.558876,-468.517853,-0.003096,0.001311,0.033301,95.898666,4.885311,0.333010,-468.517853,0.034160,0.000000
28.990002,21.230072,-468.517853,-0.003091,0.001319,0.033509,94.436073,4.810803,0.335092,-468.517853,0.034542,0.000000
29.220001,21.269173,-468.562347,-0.003044,0.001334,0.033891,94.610008,4.819664,0.338907,-468.562347,0.034932,0.000000
29.450001,22.248512,-468.562347,-0.003065,0.001358,0.034489,98.966324,5.041585,0.344895,-468.562347,0.035313,0.000000
29.680002,22.278297,-468.562347,-0.003022,0.001374,0.034888,99.098816,5.048335,0.348884,-468.562347,0.035695,0.000000
29.910002,22.252602,-468.606812,-0.003014,0.001388,0.035244,98.984512,5.042511,0.352442,-468.606812,0.036076,0.000000
30.140001,22.037743,-468.562347,-0.002988,0.001398,0.035513,98.028778,4.993824,0.355129,-468.562347,0.036458,0.000000
30.370001,21.871292,-468.651306,-0.002988,0.001409,0.035790,97.288368,4.956106,0.357900,-468.651306,0.036848,0.000000
30.600002,22.727379,-468.606812,-0.002966,0.001434,0.036432,101.096428,5.150098,0.364319,-468.606812,0.037230,0.000000
30.830002,22.781372,-468.606812,-0.002945,0.001447,0.036745,101.336601,5.162333,0.367445,-468.606812,0.037611,0.000000
31.060001,22.756050,-468.651306,-0.002940,0.001460,0.037091,101.223969,5.156595,0.370912,-468.651306,0.037993,0.000000
31.290001,23.127678,-468.606812,-0.002928,0.001477,0.037508,102.877052,5.240807,0.375076,-468.606812,0.038383,0.000000
31.520002,23.498932,-468.651306,-0.002884,0.001495,0.037984,104.528473,5.324934,0.379844,-468.651306,0.038765,0.000000
31.750002,23.212578,-468.695770,-0.002897,0.001504,0.038201,103.254700,5.260046,0.382009,-468.695770,0.039146,0.000000
31.980001,23.239761,-468.784729,-0.002897,0.001517,0.038531,103.375618,5.266205,0.385310,-468.784729,0.039528,0.000000
32.210003,23.451645,-468.695770,-0.002889,0.001535,0.038990,104.318123,5.314219,0.389905,-468.695770,0.039909,0.000000
32.440002,23.246468,-468.695770,-0.002871,0.001542,0.039155,103.405449,5.267725,0.391555,-468.695770,0.040300,0.000000
32.670002,24.269745,-468.740265,-0.002837,0.001569,0.039849,107.957214,5.499603,0.398489,-468.740265,0.040682,0.000000
32.900002,24.005363,-468.784729,-0.002798,0.001579,0.040109,106.781189,5.439693,0.401093,-468.784729,0.041063,0.000000
33.130001,24.121918,-468.829224,-0.002798,0.001594,0.040491,107.299652,5.466105,0.404908,-468.829224,0.041445,0.000000
33.360001,24.818626,-468.740265,-0.002781,0.001616,0.041046,110.398766,5.623981,0.410457,-468.740265,0.041826,0.000000
33.590000,24.722549,-468.740265,-0.002777,0.001628,0.041349,109.971390,5.602210,0.413492,-468.740265,0.042217,0.000000
33.820004,24.644722,-468.740265,-0.002772,0.001642,0.041696,109.625198,5.584574,0.416959,-468.740265,0.042598,0.000000
34.050003,24.508064,-468.784729,-0.002734,0.001653,0.041991,109.017311,5.553607,0.419911,-468.784729,0.042980,0.000000
34.280003,24.756065,-468.873718,-0.002729,0.001670,0.042407,110.120476,5.609804,0.424075,-468.873718,0.043361,0.000000
34.510002,25.269569,-468.873718,-0.002708,0.001686,0.042824,112.404655,5.726166,0.428238,-468.873718,0.043743,0.000000
34.740002,25.243874,-468.784729,-0.002682,0.001698,0.043136,112.290359,5.720344,0.431357,-468.784729,0.044133,0.000000
34.970001,25.274780,-468.829224,-0.002690,0.001710,0.043439,112.427841,5.727347,0.434392,-468.829224,0.044515,0.000000
35.200001,25.947655,-468.829224,-0.002669,0.001731,0.043959,115.420929,5.879823,0.439593,-468.829224,0.044896,0.000000
35.430000,26.473076,-468.873718,-0.002665,0.001752,0.044488,117.758125,5.998885,0.444884,-468.873718,0.045278,0.000000
35.660000,26.283165,-468.873718,-0.002621,0.001763,0.044792,116.913361,5.955850,0.447920,-468.873718,0.045659,0.000000
35.890003,26.100700,-468.873718,-0.002600,0.001775,0.045087,116.101715,5.914503,0.450872,-468.873718,0.046049,0.000000
36.120003,25.925690,-468.918182,-0.002574,0.001786,0.045356,115.323227,5.874846,0.453559,-468.918182,0.046431,0.000000
36.350002,26.651810,-468.962677,-0.002574,0.001806,0.045885,118.553169,6.039386,0.458850,-468.962677,0.046813,0.000000
36.580002,26.681229,-468.962677,-0.002561,0.001822,0.046275,118.684036,6.046053,0.462749,-468.962677,0.047195,0.000000
36.810001,26.713997,-468.918182,-0.002557,0.001834,0.046578,118.829796,6.053478,0.465784,-468.918182,0.047576,0.000000
37.040001,26.526695,-468.918182,-0.002496,0.001846,0.046891,117.996635,6.011035,0.468911,-468.918182,0.047966,0.000000
37.270000,26.761665,-468.962677,-0.002475,0.001861,0.047263,119.041832,6.064280,0.472635,-468.962677,0.048347,0.000000
37.500000,27.761856,-469.051636,-0.002492,0.001883,0.047836,123.490906,6.290926,0.478358,-469.051636,0.048729,0.000000
37.730003,27.459114,-469.096100,-0.002488,0.001896,0.048166,122.144241,6.222324,0.481658,-469.096100,0.049111,0.000000
37.960003,27.589821,-469.007141,-0.002466,0.001910,0.048521,122.725655,6.251943,0.485208,-469.007141,0.049493,0.000000
38.190002,27.392838,-468.962677,-0.002427,0.001924,0.048868,121.849426,6.207305,0.488683,-468.962677,0.049883,0.000000
38.420002,27.878410,-469.007141,-0.002458,0.001939,0.049250,124.009361,6.317338,0.492498,-469.007141,0.050264,0.000000
38.650002,27.967781,-469.096100,-0.002423,0.001957,0.049718,124.406906,6.337590,0.497176,-469.096100,0.050646,0.000000
38.880001,27.773399,-469.051636,-0.002423,0.001965,0.049917,123.542252,6.293542,0.499175,-469.051636,0.051027,0.000000
39.110001,27.742867,-469.051636,-0.002367,0.001976,0.050195,123.406433,6.286623,0.501953,-469.051636,0.051409,0.000000
39.340000,29.195488,-469.051636,-0.002341,0.002005,0.050923,129.868011,6.615792,0.509235,-469.051636,0.051799,0.000000
39.570004,29.113937,-469.096100,-0.002337,0.002018,0.051262,129.505264,6.597312,0.512619,-469.096100,0.052181,0.000000
39.800003,29.021965,-469.140594,-0.002341,0.002031,0.051583,129.096146,6.576471,0.515828,-469.140594,0.052562,0.000000
40.030003,29.185066,-469.140594,-0.002315,0.002045,0.051955,129.821655,6.613431,0.519553,-469.140594,0.052944,0.000000
40.260002,29.410721,-469.185059,-0.002320,0.002064,0.052415,130.825424,6.664565,0.524147,-469.185059,0.053334,0.000000
40.490002,29.586105,-469.051636,-0.002298,0.002078,0.052780,131.605576,6.704308,0.527796,-469.051636,0.053716,0.000000
40.720001,29.219322,-469.140594,-0.002259,0.002087,0.053022,129.974030,6.621193,0.530218,-469.140594,0.054098,0.000000
40.950001,29.458015,-469.185059,-0.002238,0.002104,0.053430,131.035797,6.675282,0.534298,-469.185059,0.054479,0.000000
41.180000,30.432137,-469.185059,-0.002233,0.002128,0.054063,135.368912,6.896021,0.540627,-469.185059,0.054861,0.000000
41.410004,30.373672,-469.229553,-0.002203,0.002142,0.054401,135.108841,6.882772,0.544011,-469.229553,0.055251,0.000000
41.640003,30.204620,-469.185059,-0.002186,0.002156,0.054765,134.356857,6.844465,0.547652,-469.185059,0.055633,0.000000
41.870003,30.307396,-469.229553,-0.002169,0.002169,0.055086,134.814026,6.867754,0.550861,-469.229553,0.056014,0.000000
42.100002,30.525230,-469.274048,-0.002182,0.002185,0.055511,135.783005,6.917116,0.555108,-469.274048,0.056396,0.000000
42.330002,30.754616,-469.229553,-0.002151,0.002201,0.055910,136.803360,6.969096,0.559097,-469.229553,0.056777,0.000000
42.560001,30.339790,-469.229553,-0.002091,0.002210,0.056127,134.958130,6.875095,0.561270,-469.229553,0.057167,0.000000
42.790001,29.747719,-469.274048,-0.002117,0.002218,0.056335,132.324463,6.740930,0.563351,-469.274048,0.057549,0.000000
43.020000,31.157150,-469.229553,-0.002100,0.002248,0.057089,138.593933,7.060311,0.570891,-469.229553,0.057931,0.000000
43.250004,31.710495,-469.318512,-0.002070,0.002264,0.057515,141.055328,7.185701,0.575145,-469.318512,0.058312,0.000000
43.480003,31.710495,-469.318512,-0.002039,0.002277,0.057844,141.055328,7.185701,0.578438,-469.318512,0.058694,0.000000
43.710003,31.376106,-469.229553,-0.002070,0.002289,0.058139,139.567886,7.109927,0.581390,-469.229553,0.059084,0.000000
43.940002,31.373497,-469.363007,-0.002031,0.002302,0.058459,139.556290,7.109336,0.584592,-469.363007,0.059465,0.000000
44.170002,31.708260,-469.363007,-0.002001,0.002319,0.058902,141.045380,7.185194,0.589020,-469.363007,0.059847,0.000000
44.400002,31.648308,-469.363007,-0.001988,0.002332,0.059240,140.778702,7.171609,0.592404,-469.363007,0.060229,0.000000
44.630001,31.601013,-469.363007,-0.001988,0.002346,0.059587,140.568329,7.160892,0.595871,-469.363007,0.060611,0.000000
44.860001,31.794647,-469.363007,-0.001962,0.002362,0.060003,141.429657,7.204770,0.600035,-469.363007,0.061000,0.000000
45.090004,32.694298,-469.318512,-0.001957,0.002384,0.060549,145.431503,7.408634,0.605492,-469.318512,0.061382,0.000000
45.320004,32.764305,-469.363007,-0.001901,0.002399,0.060922,145.742905,7.424498,0.609224,-469.363007,0.061763,0.000000
45.550003,32.496201,-469.451965,-0.001893,0.002410,0.061209,144.550323,7.363744,0.612086,-469.451965,0.062145,0.000000
45.780003,32.320808,-469.496429,-0.001901,0.002422,0.061512,143.770142,7.324000,0.615121,-469.496429,0.062527,0.000000
46.010002,31.994240,-469.407471,-0.001871,0.002431,0.061755,142.317490,7.249999,0.617551,-469.407471,0.062917,0.000000
46.240002,32.866341,-469.451965,-0.001828,0.002455,0.062345,146.196777,7.447619,0.623448,-469.451965,0.063299,0.000000
46.470001,32.683876,-469.451965,-0.001811,0.002466,0.062639,145.385147,7.406272,0.626393,-469.451965,0.063680,0.000000
46.700001,33.008209,-469.496429,-0.001811,0.002487,0.063160,146.827850,7.479767,0.631601,-469.496429,0.064062,0.000000
46.930004,33.808067,-469.540924,-0.001815,0.002507,0.063680,150.385788,7.661018,0.636801,-469.540924,0.064443,0.000000
47.160004,33.517990,-469.496429,-0.001781,0.002518,0.063958,149.095459,7.595285,0.639579,-469.496429,0.064834,0.000000
47.390003,33.381699,-469.496429,-0.001750,0.002532,0.064305,148.489212,7.564401,0.643046,-469.496429,0.065215,0.000000
47.620003,33.087524,-469.540924,-0.001733,0.002544,0.064626,147.180664,7.497740,0.646256,-469.540924,0.065597,0.000000
47.850002,32.922562,-469.496429,-0.001699,0.002557,0.064955,146.446869,7.460359,0.649549,-469.496429,0.065978,0.000000
48.080002,33.594322,-469.585388,-0.001699,0.002576,0.065423,149.435013,7.612582,0.654234,-469.585388,0.066369,0.000000
48.310001,33.405907,-469.540924,-0.001669,0.002588,0.065744,148.596893,7.569887,0.657444,-469.540924,0.066750,0.000000
48.540001,32.673820,-469.540924,-0.001664,0.002596,0.065926,145.340408,7.403994,0.659261,-469.540924,0.067132,0.000000
48.770000,33.375374,-469.629883,-0.001681,0.002616,0.066438,148.461075,7.562968,0.664378,-469.629883,0.067513,0.000000
49.000004,34.687614,-469.629883,-0.001634,0.002642,0.067097,154.298218,7.860326,0.670971,-469.629883,0.067895,0.000000
49.230003,34.345032,-469.629883,-0.001613,0.002653,0.067375,152.774338,7.782696,0.673749,-469.629883,0.068286,0.000000
49.460003,33.776047,-469.585388,-0.001604,0.002664,0.067661,150.243362,7.653762,0.676611,-469.585388,0.068667,0.000000
49.690002,34.290665,-469.585388,-0.001569,0.002679,0.068043,152.532501,7.770376,0.680426,-469.585388,0.069049,0.000000
49.920002,33.667686,-469.674377,-0.001569,0.002687,0.068242,149.761353,7.629207,0.682417,-469.674377,0.069430,0.000000
50.150002,34.740860,-469.718842,-0.001544,0.002711,0.068849,154.535065,7.872391,0.688488,-469.718842,0.069812,0.000000
50.380001,34.307793,-469.629883,-0.001531,0.002719,0.069074,152.608688,7.774257,0.690743,-469.629883,0.070201,0.000000
50.610001,34.862999,-469.674377,-0.001526,0.002739,0.069578,155.078369,7.900069,0.695777,-469.674377,0.070584,0.000000
50.840004,35.834892,-469.629883,-0.001470,0.002761,0.070141,159.401566,8.120302,0.701409,-469.629883,0.070965,0.000000
51.070004,35.939529,-469.763336,-0.001475,0.002778,0.070549,159.867004,8.144014,0.705489,-469.763336,0.071347,0.000000
51.300003,35.681847,-469.763336,-0.001470,0.002789,0.070835,158.720779,8.085622,0.708351,-469.763336,0.071728,0.000000
51.530003,35.465126,-469.763336,-0.001457,0.002801,0.071139,157.756760,8.036512,0.711386,-469.763336,0.072118,0.000000
51.760002,35.381340,-469.674377,-0.001453,0.002814,0.071477,157.384064,8.017527,0.714770,-469.674377,0.072500,0.000000
51.990002,36.552452,-469.807800,-0.001431,0.002835,0.072014,162.593430,8.282904,0.720144,-469.807800,0.072881,0.000000
52.220001,36.453400,-469.763336,-0.001410,0.002846,0.072291,162.152817,8.260458,0.722915,-469.763336,0.073263,0.000000
52.450001,36.646294,-469.807800,-0.001375,0.002860,0.072656,163.010849,8.304169,0.726564,-469.807800,0.073645,0.000000
52.680004,37.006744,-469.807800,-0.001384,0.002876,0.073046,164.614227,8.385849,0.730462,-469.807800,0.074035,0.000000
52.910004,37.919807,-469.763336,-0.001341,0.002898,0.073610,168.675720,8.592751,0.736102,-469.763336,0.074416,0.000000
53.140003,37.602913,-469.763336,-0.001324,0.002909,0.073879,167.266113,8.520942,0.738789,-469.763336,0.074798,0.000000
53.370003,37.440559,-469.807800,-0.001315,0.002920,0.074173,166.543930,8.484153,0.741733,-469.807800,0.075179,0.000000
53.600002,38.197594,-469.852295,-0.001328,0.002936,0.074572,169.911377,8.655698,0.745723,-469.852295,0.075561,0.000000
53.830002,37.862457,-469.852295,-0.001311,0.002948,0.074876,168.420624,8.579755,0.748758,-469.852295,0.075951,0.000000
54.060001,39.505363,-469.896759,-0.001276,0.002971,0.075466,175.728638,8.952044,0.754655,-469.896759,0.076333,0.000000
54.290001,39.214172,-469.852295,-0.001268,0.002981,0.075726,174.433350,8.886058,0.757259,-469.852295,0.076715,0.000000
54.520004,39.760071,-469.896759,-0.001259,0.002998,0.076160,176.861633,9.009761,0.761597,-469.896759,0.077096,0.000000
54.750004,40.899155,-469.896759,-0.001220,0.003019,0.076671,181.928528,9.267880,0.766714,-469.896759,0.077478,0.000000
54.980003,40.762497,-469.941254,-0.001216,0.003028,0.076914,181.320648,9.236915,0.769144,-469.941254,0.077868,0.000000
55.210003,41.114388,-469.896759,-0.001216,0.003042,0.077278,182.885925,9.316653,0.772785,-469.896759,0.078250,0.000000
55.440002,41.571289,-469.896759,-0.001181,0.003060,0.077721,184.918335,9.420188,0.777205,-469.896759,0.078631,0.000000
55.670002,41.914246,-469.941254,-0.001207,0.003071,0.077998,186.443878,9.497904,0.779984,-469.941254,0.079013,0.000000
55.900002,42.539459,-469.985718,-0.001164,0.003087,0.078415,189.224960,9.639579,0.784147,-469.985718,0.079394,0.000000
56.130001,42.763252,-469.985718,-0.001168,0.003099,0.078727,190.220444,9.690291,0.787266,-469.985718,0.079785,0.000000
56.360004,43.120361,-469.985718,-0.001143,0.003113,0.079082,191.808945,9.771214,0.790824,-469.985718,0.080166,0.000000
56.590004,44.466858,-469.941254,-0.001147,0.003135,0.079637,197.798462,10.076334,0.796372,-469.941254,0.080548,0.000000
56.820004,45.421623,-470.030212,-0.001134,0.003153,0.080097,202.045471,10.292687,0.800967,-470.030212,0.080929,0.000000
57.050003,45.545250,-470.030212,-0.001121,0.003165,0.080400,202.595383,10.320702,0.804003,-470.030212,0.081320,0.000000
57.280003,45.606689,-470.074677,-0.001108,0.003175,0.080643,202.868683,10.334623,0.806432,-470.074677,0.081701,0.000000
57.510002,45.922836,-469.985718,-0.001091,0.003192,0.081077,204.274979,10.406263,0.810770,-469.985718,0.082083,0.000000
57.740002,47.150543,-469.985718,-0.001061,0.003210,0.081528,209.736084,10.684465,0.815282,-469.985718,0.082465,0.000000
57.970001,47.845764,-470.030212,-0.001087,0.003225,0.081910,212.828583,10.842005,0.819097,-470.030212,0.082846,0.000000
58.200005,47.902740,-470.119171,-0.001061,0.003232,0.082100,213.082031,10.854917,0.821004,-470.119171,0.083236,0.000000
58.430004,48.309738,-470.208130,-0.001043,0.003246,0.082447,214.892441,10.947143,0.824471,-470.208130,0.083617,0.000000
58.660004,49.166939,-470.119171,-0.001013,0.003264,0.082916,218.705460,11.141387,0.829157,-470.119171,0.084000,0.000000
58.890003,50.708191,-470.074677,-0.001013,0.003285,0.083436,225.561295,11.490641,0.834357,-470.074677,0.084381,0.000000
59.120003,51.009071,-470.119171,-0.001009,0.003299,0.083800,226.899689,11.558821,0.837998,-470.119171,0.084763,0.000000
59.350002,51.497620,-470.163666,-0.000992,0.003309,0.084051,229.072845,11.669528,0.840512,-470.163666,0.085153,0.000000
59.580002,52.098633,-470.208130,-0.000987,0.003323,0.084415,231.746292,11.805719,0.844153,-470.208130,0.085534,0.000000
59.810001,53.257080,-470.163666,-0.000992,0.003343,0.084910,236.899323,12.068227,0.849096,-470.163666,0.085916,0.000000
60.040005,53.984322,-470.119171,-0.000966,0.003357,0.085274,240.134262,12.233022,0.852744,-470.119171,0.086298,0.000000
60.270004,53.664085,-470.208130,-0.000949,0.003367,0.085517,238.709778,12.160456,0.855167,-470.208130,0.086679,0.000000
60.500004,54.253922,-470.208130,-0.000931,0.003375,0.085725,241.333496,12.294114,0.857248,-470.208130,0.087069,0.000000
60.730003,56.716049,-470.252625,-0.000936,0.003408,0.086558,252.285583,12.852040,0.865575,-470.252625,0.087451,0.000000
60.960003,57.035172,-470.208130,-0.000944,0.003417,0.086792,253.705109,12.924355,0.867922,-470.208130,0.087832,0.000000
61.190002,57.809708,-470.252625,-0.000931,0.003433,0.087191,257.150421,13.099867,0.871911,-470.252625,0.088214,0.000000
61.420002,58.642700,-470.252625,-0.000910,0.003450,0.087642,260.855743,13.288627,0.876415,-470.252625,0.088595,0.000000
61.650002,59.725189,-470.297089,-0.000923,0.003465,0.088023,265.670898,13.533921,0.880230,-470.297089,0.088986,0.000000
61.880001,60.458389,-470.297089,-0.000884,0.003480,0.088388,268.932343,13.700068,0.883879,-470.297089,0.089367,0.000000
62.110004,60.728737,-470.252625,-0.000884,0.003490,0.088639,270.134918,13.761328,0.886392,-470.252625,0.089749,0.000000
62.340004,61.405708,-470.252625,-0.000892,0.003503,0.088978,273.146240,13.914733,0.889776,-470.252625,0.090130,0.000000
62.570004,63.624298,-470.297089,-0.000867,0.003532,0.089714,283.015015,14.417472,0.897141,-470.297089,0.090512,0.000000
62.800003,64.172440,-470.386047,-0.000858,0.003543,0.089992,285.453278,14.541683,0.899919,-470.386047,0.090903,0.000000
63.030003,64.920898,-470.341583,-0.000845,0.003558,0.090373,288.782593,14.711287,0.903735,-470.341583,0.091284,0.000000
63.260002,65.469406,-470.386047,-0.000854,0.003570,0.090685,291.222473,14.835580,0.906853,-470.386047,0.091666,0.000000
63.490002,66.698242,-470.341583,-0.000854,0.003587,0.091119,296.688599,15.114038,0.911191,-470.341583,0.092047,0.000000
63.720001,67.248230,-470.297089,-0.000828,0.003587,0.091119,299.135071,15.238667,0.911191,-470.297089,0.091397,0.000000
63.950005,66.478912,-470.386047,-0.000802,0.003587,0.091119,295.712982,15.064338,0.911191,-470.386047,0.091397,0.000000
64.180000,65.805664,-470.430542,-0.000819,0.003586,0.091076,292.718201,14.911777,0.910759,-470.430542,0.091119,0.000000
64.410004,65.210236,-470.386047,-0.000819,0.003585,0.091059,290.069611,14.776851,0.910585,-470.386047,0.091119,0.000000
64.639999,64.643860,-470.341583,-0.000819,0.003585,0.091050,287.550262,14.648508,0.910502,-470.341583,0.091119,0.000000
64.870003,64.122162,-470.430542,-0.000785,0.003585,0.091050,285.229614,14.530290,0.910502,-470.430542,0.091119,0.000000
65.100006,63.647018,-470.475006,-0.000789,0.003584,0.091041,283.116089,14.422621,0.910411,-470.475006,0.091119,0.000000
65.330002,63.232567,-470.475006,-0.000780,0.003584,0.091041,281.272491,14.328705,0.910411,-470.475006,0.091119,0.000000
65.560005,62.842690,-470.430542,-0.000789,0.003584,0.091041,279.538239,14.240357,0.910411,-470.430542,0.091119,0.000000
65.790001,62.482979,-470.475006,-0.000806,0.003584,0.091041,277.938171,14.158846,0.910411,-470.475006,0.091119,0.000000
66.020004,62.128479,-470.430542,-0.000776,0.003584,0.091033,276.361267,14.078514,0.910328,-470.430542,0.091119,0.000000
66.250000,61.810104,-470.475006,-0.000776,0.003584,0.091033,274.945068,14.006370,0.910328,-470.475006,0.091119,0.000000
66.480003,61.513321,-470.563995,-0.000763,0.003584,0.091033,273.624908,13.939118,0.910328,-470.563995,0.091119,0.000000
66.710007,61.241867,-470.563995,-0.000767,0.003584,0.091033,272.417419,13.877605,0.910328,-470.563995,0.091119,0.000000
66.940002,60.998329,-470.519501,-0.000780,0.003584,0.091033,271.334106,13.822418,0.910328,-470.519501,0.091119,0.000000
67.170006,60.757782,-470.519501,-0.000772,0.003584,0.091033,270.264099,13.767910,0.910328,-470.519501,0.091119,0.000000
67.400002,60.514618,-470.563995,-0.000759,0.003584,0.091033,269.182465,13.712809,0.910328,-470.563995,0.091119,0.000000
67.630005,60.293800,-470.608459,-0.000763,0.003584,0.091033,268.200226,13.662770,0.910328,-470.608459,0.091119,0.000000
67.860001,60.087509,-470.563995,-0.000755,0.003584,0.091033,267.282593,13.616025,0.910328,-470.563995,0.091119,0.000000
68.090004,59.896111,-470.563995,-0.000767,0.003584,0.091033,266.431213,13.572653,0.910328,-470.563995,0.091119,0.000000
68.320000,59.708061,-470.519501,-0.000755,0.003584,0.091033,265.594727,13.530040,0.910328,-470.519501,0.091119,0.000000
68.550003,59.545708,-470.563995,-0.000772,0.003584,0.091033,264.872528,13.493250,0.910328,-470.563995,0.091119,0.000000
68.780006,59.371811,-470.608459,-0.000750,0.003584,0.091033,264.098999,13.453845,0.910328,-470.608459,0.091119,0.000000
69.010002,59.206848,-470.652954,-0.000772,0.003584,0.091033,263.365204,13.416464,0.910328,-470.652954,0.091119,0.000000
69.240005,59.061249,-470.608459,-0.000772,0.003584,0.091033,262.717560,13.383471,0.910328,-470.608459,0.091119,0.000000
69.470001,58.924591,-470.608459,-0.000763,0.003584,0.091033,262.109680,13.352504,0.910328,-470.608459,0.091119,0.000000
69.700005,58.781601,-470.652954,-0.000785,0.003584,0.091033,261.473633,13.320101,0.910328,-470.652954,0.091119,0.000000
69.930000,58.634514,-470.697418,-0.000759,0.003584,0.091033,260.819336,13.286771,0.910328,-470.697418,0.091119,0.000000
70.160004,58.516472,-470.741913,-0.000742,0.003584,0.091033,260.294281,13.260022,0.910328,-470.741913,0.091119,0.000000
70.390007,58.387253,-470.652954,-0.000759,0.003584,0.091033,259.719482,13.230741,0.910328,-470.652954,0.091119,0.000000
70.620003,58.272194,-470.652954,-0.000716,0.003584,0.091033,259.207672,13.204668,0.910328,-470.652954,0.091119,0.000000
70.850006,58.167557,-470.697418,-0.000742,0.003584,0.091033,258.742218,13.180957,0.910328,-470.697418,0.091119,0.000000
71.080002,58.032761,-470.786377,-0.000742,0.003584,0.091033,258.142609,13.150412,0.910328,-470.786377,0.091119,0.000000
71.310005,57.918442,-470.741913,-0.000750,0.003584,0.091033,257.634094,13.124507,0.910328,-470.741913,0.091119,0.000000
71.540001,57.826836,-470.697418,-0.000755,0.003584,0.091033,257.226624,13.103748,0.910328,-470.697418,0.091119,0.000000
71.770004,57.732994,-470.697418,-0.000772,0.003584,0.091033,256.809174,13.082483,0.910328,-470.697418,0.091119,0.000000
72.000000,57.635811,-470.741913,-0.000776,0.003584,0.091033,256.376892,13.060461,0.910328,-470.741913,0.091119,0.000000
72.230003,57.544952,-470.830872,-0.000729,0.003584,0.091033,255.972733,13.039872,0.910328,-470.830872,0.091119,0.000000
72.460007,57.441803,-470.875336,-0.000742,0.003584,0.091033,255.513901,13.016499,0.910328,-470.875336,0.091119,0.000000
72.690002,57.353180,-470.786377,-0.000733,0.003584,0.091033,255.119690,12.996416,0.910328,-470.786377,0.091119,0.000000
72.920006,57.276100,-470.786377,-0.000746,0.003584,0.091033,254.776825,12.978950,0.910328,-470.786377,0.091119,0.000000
73.150002,57.200134,-470.830872,-0.000746,0.003584,0.091033,254.438904,12.961736,0.910328,-470.830872,0.091119,0.000000
73.380005,57.115601,-470.919830,-0.000737,0.003584,0.091033,254.062881,12.942580,0.910328,-470.919830,0.091119,0.000000
73.610001,57.019531,-470.875336,-0.000759,0.003584,0.091033,253.635544,12.920811,0.910328,-470.875336,0.091119,0.000000
73.840004,56.952881,-470.830872,-0.000742,0.003584,0.091033,253.339066,12.905706,0.910328,-470.830872,0.091119,0.000000
74.070007,56.882874,-470.830872,-0.000742,0.003584,0.091033,253.027664,12.889843,0.910328,-470.830872,0.091119,0.000000
74.300003,56.801323,-470.875336,-0.000742,0.003584,0.091033,252.664902,12.871365,0.910328,-470.875336,0.091119,0.000000
74.530006,56.734299,-470.964325,-0.000746,0.003584,0.091033,252.366760,12.856176,0.910328,-470.964325,0.091119,0.000000
74.760002,56.663918,-470.919830,-0.000737,0.003584,0.091033,252.053696,12.840227,0.910328,-470.919830,0.091119,0.000000
74.990005,56.592796,-470.875336,-0.000720,0.003584,0.091033,251.737335,12.824111,0.910328,-470.875336,0.091119,0.000000
75.220001,56.533585,-470.875336,-0.000742,0.003584,0.091033,251.473938,12.810693,0.910328,-470.875336,0.091119,0.000000
75.450005,56.471397,-470.919830,-0.000737,0.003584,0.091033,251.197327,12.796601,0.910328,-470.919830,0.091119,0.000000
75.680000,56.404747,-471.008789,-0.000737,0.003584,0.091033,250.900848,12.781499,0.910328,-471.008789,0.091119,0.000000
75.910004,56.326172,-471.053284,-0.000724,0.003584,0.091033,250.551331,12.763694,0.910328,-471.053284,0.091119,0.000000
76.140007,56.289307,-471.008789,-0.000729,0.003584,0.091033,250.387344,12.755340,0.910328,-471.008789,0.091119,0.000000
76.370003,56.219307,-470.964325,-0.000711,0.003584,0.091033,250.075974,12.739477,0.910328,-470.964325,0.091119,0.000000
76.600006,56.157120,-470.964325,-0.000733,0.003584,0.091033,249.799347,12.725385,0.910328,-470.964325,0.091119,0.000000
76.830002,56.113174,-471.053284,-0.000720,0.003584,0.091033,249.603867,12.715427,0.910328,-471.053284,0.091119,0.000000
77.060005,56.055458,-471.097748,-0.000724,0.003584,0.091033,249.347137,12.702349,0.910328,-471.097748,0.091119,0.000000
77.290001,55.990295,-471.008789,-0.000742,0.003584,0.091033,249.057266,12.687583,0.910328,-471.008789,0.091119,0.000000
77.520004,55.943748,-471.008789,-0.000759,0.003584,0.091033,248.850220,12.677034,0.910328,-471.008789,0.091119,0.000000
77.750000,55.899437,-471.008789,-0.000742,0.003584,0.091033,248.653107,12.666994,0.910328,-471.008789,0.091119,0.000000
77.980003,55.837997,-471.053284,-0.000707,0.003584,0.091033,248.379822,12.653071,0.910328,-471.053284,0.091119,0.000000
78.210007,55.801132,-471.097748,-0.000755,0.003584,0.091033,248.215836,12.644717,0.910328,-471.097748,0.091119,0.000000
78.440002,55.740059,-471.142242,-0.000746,0.003584,0.091033,247.944168,12.630877,0.910328,-471.142242,0.091119,0.000000
78.670006,55.686813,-471.053284,-0.000729,0.003584,0.091033,247.707321,12.618813,0.910328,-471.053284,0.091119,0.000000
78.900002,55.647339,-471.097748,-0.000750,0.003584,0.091033,247.531723,12.609867,0.910328,-471.097748,0.091119,0.000000
79.130005,55.613823,-471.142242,-0.000729,0.003584,0.091033,247.382645,12.602273,0.910328,-471.142242,0.091119,0.000000
79.360001,55.553505,-471.142242,-0.000720,0.003584,0.091033,247.114334,12.588604,0.910328,-471.142242,0.091119,0.000000
79.590004,55.499138,-471.142242,-0.000724,0.003584,0.091033,246.872498,12.576284,0.910328,-471.142242,0.091119,0.000000
79.820007,55.461151,-471.142242,-0.000720,0.003584,0.091033,246.703522,12.567677,0.910328,-471.142242,0.091119,0.000000
80.050003,55.413116,-471.142242,-0.000729,0.003584,0.091033,246.489853,12.556791,0.910328,-471.142242,0.091119,0.000000
80.280006,55.375137,-471.231201,-0.000720,0.003584,0.091033,246.320908,12.548185,0.910328,-471.231201,0.091119,0.000000
80.510002,55.344971,-471.275665,-0.000729,0.003584,0.091033,246.186722,12.541349,0.910328,-471.275665,0.091119,0.000000
80.740005,55.300659,-471.231201,-0.000724,0.003584,0.091033,245.989624,12.531308,0.910328,-471.231201,0.091119,0.000000
80.970001,55.246292,-471.275665,-0.000724,0.003584,0.091033,245.747787,12.518989,0.910328,-471.275665,0.091119,0.000000
81.200005,55.211662,-471.186707,-0.000733,0.003584,0.091033,245.593735,12.511142,0.910328,-471.186707,0.091119,0.000000
81.430000,55.181129,-471.275665,-0.000724,0.003584,0.091033,245.457916,12.504222,0.910328,-471.275665,0.091119,0.000000
81.660004,55.134209,-471.320160,-0.000720,0.003584,0.091033,245.249207,12.493590,0.910328,-471.320160,0.091119,0.000000
81.890007,55.104790,-471.320160,-0.000698,0.003584,0.091033,245.118347,12.486923,0.910328,-471.320160,0.091119,0.000000
82.120003,55.063835,-471.231201,-0.000750,0.003584,0.091033,244.936172,12.477643,0.910328,-471.231201,0.091119,0.000000
82.350006,55.022873,-471.186707,-0.000716,0.003584,0.091033,244.753967,12.468362,0.910328,-471.186707,0.091119,0.000000
82.580002,54.972603,-471.275665,-0.000720,0.003584,0.091033,244.530350,12.456970,0.910328,-471.275665,0.091119,0.000000
82.810005,54.945045,-471.320160,-0.000720,0.003584,0.091033,244.407776,12.450725,0.910328,-471.320160,0.091119,0.000000
83.040001,54.916748,-471.320160,-0.000703,0.003584,0.091033,244.281891,12.444313,0.910328,-471.320160,0.091119,0.000000
83.270004,54.876526,-471.364624,-0.000742,0.003584,0.091033,244.102982,12.435198,0.910328,-471.364624,0.091119,0.000000
83.500008,54.851952,-471.320160,-0.000729,0.003584,0.091033,243.993668,12.429629,0.910328,-471.320160,0.091119,0.000000
83.730003,54.811363,-471.364624,-0.000703,0.003584,0.091033,243.813126,12.420432,0.910328,-471.364624,0.091119,0.000000
83.960007,54.770027,-471.364624,-0.000737,0.003584,0.091033,243.629242,12.411066,0.910328,-471.364624,0.091119,0.000000
84.190002,54.735771,-471.364624,-0.000711,0.003584,0.091033,243.476868,12.403303,0.910328,-471.364624,0.091119,0.000000
84.420006,54.707100,-471.409119,-0.000707,0.003584,0.091033,243.349335,12.396807,0.910328,-471.409119,0.091119,0.000000
84.650002,54.678055,-471.409119,-0.000742,0.003584,0.091033,243.220139,12.390224,0.910328,-471.409119,0.091119,0.000000
84.880005,54.646400,-471.409119,-0.000716,0.003584,0.091033,243.079330,12.383051,0.910328,-471.409119,0.091119,0.000000
85.110001,54.626297,-471.498077,-0.000703,0.003584,0.091033,242.989899,12.378496,0.910328,-471.498077,0.091119,0.000000
85.340004,54.593155,-471.498077,-0.000746,0.003584,0.091033,242.842484,12.370986,0.910328,-471.498077,0.091119,0.000000
85.570007,54.552567,-471.453613,-0.000716,0.003584,0.091033,242.661942,12.361789,0.910328,-471.453613,0.091119,0.000000
85.800003,54.529846,-471.453613,-0.000707,0.003584,0.091033,242.560867,12.356640,0.910328,-471.453613,0.091119,0.000000
86.030006,54.493729,-471.498077,-0.000707,0.003584,0.091033,242.400208,12.348455,0.910328,-471.498077,0.091119,0.000000
86.260002,54.459846,-471.498077,-0.000720,0.003584,0.091033,242.249496,12.340777,0.910328,-471.498077,0.091119,0.000000
86.490005,54.434898,-471.498077,-0.000720,0.003584,0.091033,242.138519,12.335124,0.910328,-471.498077,0.091119,0.000000
86.720001,54.402496,-471.453613,-0.000729,0.003584,0.091033,241.994385,12.327782,0.910328,-471.453613,0.091119,0.000000
86.950005,54.382759,-471.498077,-0.000746,0.003584,0.091033,241.906601,12.323310,0.910328,-471.498077,0.091119,0.000000
87.180008,54.345528,-471.587036,-0.000716,0.003584,0.091033,241.740982,12.314873,0.910328,-471.587036,0.091119,0.000000
87.410004,54.325790,-471.587036,-0.000711,0.003584,0.091033,241.653183,12.310400,0.910328,-471.587036,0.091119,0.000000
87.640007,54.297493,-471.542572,-0.000737,0.003584,0.091033,241.527313,12.303988,0.910328,-471.542572,0.091119,0.000000
87.870003,54.277008,-471.587036,-0.000707,0.003584,0.091033,241.436188,12.299346,0.910328,-471.587036,0.091119,0.000000
88.100006,54.238281,-471.542572,-0.000724,0.003584,0.091033,241.263931,12.290570,0.910328,-471.542572,0.091119,0.000000
88.330002,54.216682,-471.542572,-0.000724,0.003584,0.091033,241.167847,12.285676,0.910328,-471.542572,0.091119,0.000000
88.560005,54.188011,-471.542572,-0.000733,0.003584,0.091033,241.040314,12.279179,0.910328,-471.542572,0.091119,0.000000
88.790001,54.158966,-471.631531,-0.000720,0.003584,0.091033,240.911118,12.272597,0.910328,-471.631531,0.091119,0.000000
89.020004,54.126945,-471.542572,-0.000720,0.003584,0.091033,240.768677,12.265341,0.910328,-471.542572,0.091119,0.000000
89.250008,54.108696,-471.542572,-0.000724,0.003584,0.091033,240.687500,12.261206,0.910328,-471.542572,0.091119,0.000000
89.480003,54.095665,-471.498077,-0.000716,0.003584,0.091033,240.629532,12.258252,0.910328,-471.498077,0.091119,0.000000
89.710007,54.069595,-471.587036,-0.000707,0.003584,0.091033,240.513565,12.252345,0.910328,-471.587036,0.091119,0.000000
89.940002,54.039436,-471.720490,-0.000724,0.003584,0.091033,240.379425,12.245511,0.910328,-471.720490,0.091119,0.000000
90.170006,54.007042,-471.675995,-0.000737,0.003584,0.091033,240.235321,12.238171,0.910328,-471.675995,0.091119,0.000000
90.400002,53.992516,-471.587036,-0.000729,0.003584,0.091033,240.170700,12.234879,0.910328,-471.587036,0.091119,0.000000
90.630005,53.969429,-471.675995,-0.000703,0.003584,0.091033,240.068008,12.229648,0.910328,-471.675995,0.091119,0.000000
90.860001,53.945969,-471.675995,-0.000698,0.003584,0.091033,239.963654,12.224331,0.910328,-471.675995,0.091119,0.000000
91.090004,53.923256,-471.764954,-0.000716,0.003584,0.091033,239.862625,12.219185,0.910328,-471.764954,0.091119,0.000000
91.320007,53.890114,-471.720490,-0.000711,0.003584,0.091033,239.715195,12.211674,0.910328,-471.720490,0.091119,0.000000
91.550003,53.861816,-471.720490,-0.000703,0.003584,0.091033,239.589325,12.205262,0.910328,-471.720490,0.091119,0.000000
91.780006,53.843567,-471.720490,-0.000686,0.003584,0.091033,239.508148,12.201127,0.910328,-471.720490,0.091119,0.000000
92.010002,53.826065,-471.764954,-0.000711,0.003584,0.091033,239.430298,12.197161,0.910328,-471.764954,0.091119,0.000000
92.240005,53.804840,-471.764954,-0.000733,0.003584,0.091033,239.335876,12.192350,0.910328,-471.764954,0.091119,0.000000
92.470001,53.782501,-471.764954,-0.000711,0.003584,0.091033,239.236511,12.187289,0.910328,-471.764954,0.091119,0.000000
92.700005,53.746002,-471.720490,-0.000716,0.003584,0.091033,239.074158,12.179018,0.910328,-471.720490,0.091119,0.000000
92.930008,53.737442,-471.720490,-0.000720,0.003584,0.091033,239.036087,12.177078,0.910328,-471.720490,0.091119,0.000000
93.160004,53.712494,-471.809448,-0.000711,0.003584,0.091033,238.925110,12.171425,0.910328,-471.809448,0.091119,0.000000
93.390007,53.700203,-471.853943,-0.000707,0.003584,0.091033,238.870438,12.168639,0.910328,-471.853943,0.091119,0.000000
93.620003,53.676369,-471.809448,-0.000711,0.003584,0.091033,238.764420,12.163239,0.910328,-471.809448,0.091119,0.000000
93.850006,53.646957,-471.809448,-0.000724,0.003584,0.091033,238.633591,12.156574,0.910328,-471.809448,0.091119,0.000000
94.080002,53.634293,-471.853943,-0.000716,0.003584,0.091033,238.577255,12.153705,0.910328,-471.853943,0.091119,0.000000
94.200005,53.613815,-471.809448,-0.000711,0.003584,0.091033,238.486160,12.149064,0.910328,-471.809448,0.091119,0.000000