File: Data/compression 14/AutoNoHeating-16-14-2-240726_07262024_170827.csv
Time (sec),S:Load (lbs),S:HL1 (DIM),S:LVDT (in),S:Position (in),Ch:Position (mm),Ch:Load (N),Ch:Stress (MPa),Ch:Strain (mm/mm),Ch:HL1 (DIM),Set Point (),Cycles ()
0.110000,-0.017876,-459.132385,-0.008567,-0.003874,-0.098395,-0.079515,-0.004051,-0.983952,-459.132385,-0.098144,0.000000
0.340000,-0.008942,-459.132385,-0.008563,-0.003874,-0.098395,-0.039774,-0.002026,-0.983952,-459.132385,-0.098144,0.000000
0.570000,-0.020111,-459.176849,-0.008550,-0.003788,-0.096227,-0.089459,-0.004557,-0.962272,-459.176849,-0.095577,0.000000
0.800000,-0.034630,-459.132385,-0.008528,-0.003655,-0.092828,-0.154041,-0.007847,-0.928276,-459.132385,-0.091744,0.000000
1.030000,-0.013031,-459.132385,-0.008343,-0.003502,-0.088951,-0.057965,-0.002953,-0.889511,-459.132385,-0.087911,0.000000
1.260000,0.007820,-459.132385,-0.008196,-0.003362,-0.085405,0.034786,0.001772,-0.854046,-459.132385,-0.084078,0.000000
1.490000,-0.013405,-459.221344,-0.007998,-0.003206,-0.081424,-0.059628,-0.003038,-0.814237,-459.221344,-0.080244,0.000000
1.720000,-0.029793,-459.176849,-0.007838,-0.003048,-0.077417,-0.132525,-0.006751,-0.774170,-459.176849,-0.076411,0.000000
1.950000,-0.046173,-459.132385,-0.007679,-0.002906,-0.073810,-0.205388,-0.010463,-0.738100,-459.132385,-0.072578,0.000000
2.180000,-0.026436,-459.176849,-0.007562,-0.002751,-0.069881,-0.117593,-0.005990,-0.698813,-459.176849,-0.068762,0.000000
2.410000,-0.015266,-459.176849,-0.007368,-0.002607,-0.066221,-0.067908,-0.003459,-0.662213,-459.176849,-0.064929,0.000000
2.640000,0.010056,-459.265808,-0.007213,-0.002450,-0.062241,0.044729,0.002279,-0.622411,-459.265808,-0.061096,0.000000
2.870000,-0.007446,-459.221344,-0.007058,-0.002294,-0.058269,-0.033123,-0.001687,-0.582692,-459.221344,-0.057263,0.000000
3.100000,-0.026436,-459.176849,-0.006920,-0.002148,-0.054549,-0.117593,-0.005990,-0.545487,-459.176849,-0.053430,0.000000
3.330000,-0.003349,-459.265808,-0.006752,-0.001999,-0.050785,-0.014898,-0.000759,-0.507850,-459.265808,-0.049597,0.000000
3.560000,-0.006332,-459.221344,-0.006588,-0.001845,-0.046856,-0.028168,-0.001435,-0.468562,-459.221344,-0.045764,0.000000
3.790000,-0.005585,-459.310303,-0.006420,-0.001705,-0.043301,-0.024842,-0.001266,-0.433007,-459.310303,-0.041931,0.000000
4.020000,-0.013779,-459.310303,-0.006265,-0.001544,-0.039216,-0.061291,-0.003122,-0.392161,-459.310303,-0.038097,0.000000
4.250000,-0.063301,-459.221344,-0.006101,-0.001390,-0.035305,-0.281577,-0.014344,-0.353047,-459.221344,-0.034264,0.000000
4.480000,-0.053253,-459.354767,-0.005959,-0.001241,-0.031515,-0.236882,-0.012067,-0.315153,-459.354767,-0.030431,0.000000
4.710000,-0.023087,-459.310303,-0.005786,-0.001088,-0.027639,-0.102694,-0.005231,-0.276388,-459.310303,-0.026598,0.000000
4.940000,0.018616,-459.354767,-0.005627,-0.000943,-0.023944,0.082807,0.004218,-0.239440,-459.354767,-0.022782,0.000000
5.170000,0.006699,-459.354767,-0.005506,-0.000793,-0.020137,0.029797,0.001518,-0.201372,-459.354767,-0.018949,0.000000
5.400000,0.013031,-459.310303,-0.005329,-0.000640,-0.016261,0.057965,0.002953,-0.162607,-459.310303,-0.015116,0.000000
5.630000,-0.001862,-459.310303,-0.005135,-0.000489,-0.012419,-0.008281,-0.000422,-0.124190,-459.310303,-0.011283,0.000000
5.860000,-0.014893,-459.443756,-0.004980,-0.000335,-0.008508,-0.066245,-0.003375,-0.085077,-459.443756,-0.007449,0.000000
6.090000,-0.009308,-459.399261,-0.004846,-0.000192,-0.004865,-0.041403,-0.002109,-0.048651,-459.399261,-0.003616,0.000000
6.320000,-0.013031,-459.443756,-0.004695,-0.000031,-0.000790,-0.057965,-0.002953,-0.007895,-459.443756,0.000216,0.000000
6.550000,0.051384,-459.399261,-0.004506,0.000122,0.003096,0.228567,0.011644,0.030960,-459.399261,0.004050,0.000000
6.780000,0.831505,-459.399261,-0.004376,0.000238,0.006044,3.698718,0.188422,0.060445,-459.399261,0.007189,0.000000
7.010000,0.764854,-459.488220,-0.004372,-0.000000,-0.000008,3.402242,0.173318,-0.000083,-459.488220,0.000130,0.000000
7.240000,0.738785,-459.443756,-0.004372,-0.000000,-0.000008,3.286279,0.167411,-0.000083,-459.443756,0.000130,0.000000
7.470000,0.750702,-459.488220,-0.004402,-0.000000,-0.000008,3.339289,0.170111,-0.000083,-459.488220,0.000425,0.000000
7.700000,0.718307,-459.443756,-0.004402,-0.000000,-0.000008,3.195191,0.162771,-0.000083,-459.443756,0.000806,0.000000
7.930000,0.715698,-459.443756,-0.004385,-0.000000,-0.000008,3.183585,0.162180,-0.000083,-459.443756,0.001188,0.000000
8.160001,0.698196,-459.488220,-0.004381,-0.000000,-0.000008,3.105733,0.158214,-0.000083,-459.488220,0.001570,0.000000
8.390000,1.304047,-459.577179,-0.004368,0.000043,0.001084,5.800689,0.295501,0.010840,-459.577179,0.001960,0.000000
8.620001,1.677162,-459.488220,-0.004355,0.000062,0.001578,7.460390,0.380050,0.015783,-459.488220,0.002341,0.000000
8.850000,1.801163,-459.577179,-0.004299,0.000071,0.001795,8.011971,0.408149,0.017948,-459.577179,0.002723,0.000000
9.080001,1.977669,-459.532715,-0.004303,0.000081,0.002047,8.797110,0.448146,0.020469,-459.532715,0.003104,0.000000
9.310000,2.434570,-459.488220,-0.004303,0.000102,0.002593,10.829510,0.551682,0.025927,-459.488220,0.003495,0.000000
9.540001,2.802849,-459.666138,-0.004268,0.000122,0.003104,12.467694,0.635135,0.031044,-459.666138,0.003876,0.000000
9.770000,2.930573,-459.621674,-0.004277,0.000132,0.003347,13.035837,0.664077,0.033474,-459.621674,0.004258,0.000000
10.000000,3.077660,-459.577179,-0.004277,0.000141,0.003590,13.690114,0.697408,0.035904,-459.577179,0.004640,0.000000
10.230000,3.599350,-459.577179,-0.004238,0.000161,0.004102,16.010708,0.815624,0.041021,-459.577179,0.005021,0.000000
10.460000,3.792236,-459.621674,-0.004251,0.000176,0.004458,16.868710,0.859333,0.044578,-459.621674,0.005412,0.000000
10.690001,4.331062,-459.710632,-0.004255,0.000197,0.004995,19.265528,0.981433,0.049953,-459.710632,0.005793,0.000000
10.920000,4.392136,-459.666138,-0.004243,0.000203,0.005151,19.537195,0.995272,0.051512,-459.666138,0.006175,0.000000
11.150001,4.790939,-459.666138,-0.004204,0.000219,0.005550,21.311163,1.085642,0.055502,-459.666138,0.006556,0.000000
11.380000,5.351364,-459.710632,-0.004186,0.000241,0.006114,23.804056,1.212636,0.061141,-459.710632,0.006938,0.000000
11.610001,5.620216,-459.666138,-0.004165,0.000254,0.006452,24.999971,1.273559,0.064525,-459.666138,0.007328,0.000000
11.840000,5.920349,-459.755096,-0.004165,0.000269,0.006825,26.335028,1.341570,0.068249,-459.755096,0.007710,0.000000
12.070001,6.161270,-459.755096,-0.004113,0.000282,0.007155,27.406698,1.396164,0.071550,-459.755096,0.008091,0.000000
12.300000,6.518005,-459.666138,-0.004135,0.000298,0.007562,28.993536,1.477001,0.075622,-459.666138,0.008473,0.000000
12.530001,6.933571,-459.710632,-0.004105,0.000312,0.007935,30.842064,1.571170,0.079354,-459.710632,0.008854,0.000000
12.760000,7.222908,-459.755096,-0.004126,0.000327,0.008300,32.129101,1.636734,0.082995,-459.755096,0.009245,0.000000
12.990001,7.348396,-459.755096,-0.004109,0.000336,0.008525,32.687298,1.665170,0.085251,-459.755096,0.009627,0.000000
13.220000,7.946053,-459.755096,-0.004070,0.000357,0.009063,35.345806,1.800601,0.090626,-459.755096,0.010008,0.000000
13.450001,8.428650,-459.710632,-0.004061,0.000377,0.009565,37.492508,1.909959,0.095652,-459.710632,0.010390,0.000000
13.680000,8.607391,-459.755096,-0.004053,0.000390,0.009904,38.287590,1.950463,0.099036,-459.755096,0.010771,0.000000
13.910001,8.787987,-459.888550,-0.004018,0.000403,0.010225,39.090916,1.991386,0.102245,-459.888550,0.011161,0.000000
14.140000,8.891510,-459.799591,-0.004023,0.000417,0.010589,39.551411,2.014845,0.105886,-459.799591,0.011542,0.000000
14.370001,9.509644,-459.844086,-0.003997,0.000433,0.010988,42.301006,2.154916,0.109876,-459.844086,0.011925,0.000000
14.600000,9.768448,-459.799591,-0.003975,0.000450,0.011430,43.452225,2.213562,0.114304,-459.799591,0.012306,0.000000
14.830001,9.969154,-459.799591,-0.003945,0.000460,0.011682,44.345013,2.259043,0.116817,-459.799591,0.012688,0.000000
15.060000,10.121086,-459.844086,-0.003984,0.000473,0.012011,45.020840,2.293471,0.120110,-459.844086,0.013078,0.000000
15.290001,10.457336,-459.933044,-0.003971,0.000487,0.012375,46.516556,2.369666,0.123751,-459.933044,0.013459,0.000000
15.520000,11.317146,-459.933044,-0.003928,0.000511,0.012991,50.341183,2.564502,0.129913,-459.933044,0.013841,0.000000
15.750001,11.220695,-459.844086,-0.003923,0.000522,0.013268,49.912148,2.542646,0.132683,-459.844086,0.014222,0.000000
15.980000,11.526413,-459.933044,-0.003911,0.000537,0.013632,51.272045,2.611923,0.136324,-459.933044,0.014604,0.000000
16.210001,11.710365,-459.933044,-0.003885,0.000550,0.013962,52.090305,2.653607,0.139625,-459.933044,0.014994,0.000000
16.440001,12.142319,-459.977509,-0.003893,0.000569,0.014457,54.011730,2.751489,0.144568,-459.977509,0.015376,0.000000
16.670000,12.440216,-459.977509,-0.003837,0.000585,0.014856,55.336845,2.818993,0.148557,-459.977509,0.015757,0.000000
16.900002,12.266319,-459.977509,-0.003863,0.000592,0.015037,54.563313,2.779588,0.150374,-459.977509,0.016139,0.000000
17.130001,12.569061,-459.977509,-0.003854,0.000603,0.015307,55.909977,2.848190,0.153069,-459.977509,0.016529,0.000000
17.360001,13.711868,-459.977509,-0.003811,0.000634,0.016105,60.993435,3.107154,0.161047,-459.977509,0.016911,0.000000
17.590000,13.603134,-460.022003,-0.003777,0.000644,0.016364,60.509762,3.082514,0.163644,-460.022003,0.017292,0.000000
17.820002,13.680222,-460.022003,-0.003807,0.000660,0.016763,60.852665,3.099983,0.167633,-460.022003,0.017674,0.000000
18.050001,13.975883,-459.977509,-0.003768,0.000676,0.017162,62.167835,3.166980,0.171622,-459.977509,0.018055,0.000000
18.280001,14.210480,-460.022003,-0.003777,0.000691,0.017544,63.211372,3.220141,0.175437,-460.022003,0.018446,0.000000
18.510000,14.387726,-460.022003,-0.003738,0.000704,0.017882,63.999802,3.260305,0.178821,-460.022003,0.018828,0.000000
18.740002,14.341179,-460.110962,-0.003738,0.000715,0.018160,63.792751,3.249758,0.181599,-460.110962,0.019209,0.000000
18.970001,14.634605,-460.110962,-0.003729,0.000729,0.018515,65.097977,3.316249,0.185149,-460.110962,0.019591,0.000000
19.200001,15.453087,-460.066467,-0.003721,0.000755,0.019174,68.738762,3.501719,0.191743,-460.066467,0.019972,0.000000
19.430000,15.427017,-460.022003,-0.003673,0.000768,0.019504,68.622803,3.495812,0.195036,-460.022003,0.020363,0.000000
19.660002,15.373398,-460.155426,-0.003669,0.000780,0.019825,68.384293,3.483662,0.198245,-460.155426,0.020744,0.000000
19.890001,15.570381,-460.110962,-0.003660,0.000794,0.020163,69.260513,3.528299,0.201629,-460.110962,0.021126,0.000000
20.120001,15.807213,-460.155426,-0.003652,0.000809,0.020553,70.313995,3.581966,0.205535,-460.155426,0.021507,0.000000
20.350000,16.112183,-460.155426,-0.003635,0.000826,0.020970,71.670570,3.651073,0.209698,-460.155426,0.021889,0.000000
20.580002,16.037338,-460.155426,-0.003609,0.000836,0.021239,71.337646,3.634113,0.212386,-460.155426,0.022279,0.000000
20.810001,16.194107,-460.199921,-0.003574,0.000851,0.021620,72.034988,3.669637,0.216201,-460.199921,0.022661,0.000000
21.040001,16.973106,-460.199921,-0.003566,0.000875,0.022218,75.500145,3.846161,0.222181,-460.199921,0.023042,0.000000
21.270000,17.113869,-460.199921,-0.003544,0.000890,0.022600,76.126289,3.878058,0.225996,-460.199921,0.023424,0.000000
21.500002,17.107536,-460.155426,-0.003527,0.000902,0.022912,76.098122,3.876623,0.229122,-460.155426,0.023805,0.000000
21.730001,16.994331,-460.110962,-0.003518,0.000914,0.023216,75.594559,3.850971,0.232158,-460.110962,0.024195,0.000000
21.960001,17.116096,-460.288879,-0.003501,0.000928,0.023562,76.136200,3.878563,0.235625,-460.288879,0.024577,0.000000
22.190001,17.438576,-460.288879,-0.003471,0.000944,0.023979,77.570656,3.951638,0.239788,-460.288879,0.024959,0.000000
22.420002,17.511185,-460.288879,-0.003458,0.000958,0.024335,77.893639,3.968091,0.243346,-460.288879,0.025341,0.000000
22.650002,17.529060,-460.244415,-0.003432,0.000969,0.024603,77.973152,3.972142,0.246033,-460.244415,0.025722,0.000000
22.880001,17.778549,-460.333374,-0.003428,0.000985,0.025020,79.082939,4.028677,0.250197,-460.333374,0.026112,0.000000
23.110001,18.259659,-460.244415,-0.003419,0.001008,0.025600,81.223022,4.137698,0.256003,-460.244415,0.026494,0.000000
23.340002,18.506912,-460.377838,-0.003380,0.001024,0.025999,82.322861,4.193727,0.259992,-460.377838,0.026875,0.000000
23.570002,18.358704,-460.333374,-0.003372,0.001036,0.026312,81.663589,4.160142,0.263118,-460.333374,0.027257,0.000000
23.800001,18.412331,-460.288879,-0.003380,0.001049,0.026650,81.902138,4.172294,0.266502,-460.288879,0.027639,0.000000
24.030001,18.317001,-460.288879,-0.003328,0.001058,0.026884,81.478088,4.150692,0.268841,-460.288879,0.028029,0.000000
24.260000,19.125793,-460.333374,-0.003333,0.001085,0.027552,85.075775,4.333967,0.275518,-460.333374,0.028410,0.000000
24.490002,18.821190,-460.333374,-0.003307,0.001093,0.027751,83.720833,4.264943,0.277508,-460.333374,0.028792,0.000000
24.720001,19.321289,-460.377838,-0.003285,0.001116,0.028341,85.945389,4.378267,0.283413,-460.377838,0.029173,0.000000
24.950001,19.733879,-460.377838,-0.003281,0.001136,0.028844,87.780678,4.471761,0.288439,-460.377838,0.029555,0.000000
25.180000,19.556259,-460.333374,-0.003242,0.001148,0.029156,86.990585,4.431512,0.291558,-460.333374,0.029945,0.000000
25.410002,19.350708,-460.466797,-0.003216,0.001158,0.029425,86.076248,4.384933,0.294253,-460.466797,0.030327,0.000000
25.640001,19.338417,-460.466797,-0.003221,0.001173,0.029789,86.021576,4.382148,0.297894,-460.466797,0.030708,0.000000
25.870001,19.469124,-460.466797,-0.003191,0.001185,0.030093,86.602989,4.411767,0.300929,-460.466797,0.031090,0.000000
26.100000,19.853035,-460.377838,-0.003191,0.001201,0.030518,88.310707,4.498762,0.305176,-460.377838,0.031480,0.000000
26.330002,19.966614,-460.466797,-0.003178,0.001214,0.030847,88.815933,4.524499,0.308469,-460.466797,0.031862,0.000000
26.560001,19.713394,-460.466797,-0.003156,0.001222,0.031047,87.689560,4.467119,0.310467,-460.466797,0.032244,0.000000
26.790001,20.932915,-460.511292,-0.003147,0.001253,0.031836,93.114258,4.743466,0.318355,-460.511292,0.032625,0.000000
27.020000,21.032341,-460.555756,-0.003143,0.001269,0.032226,93.556526,4.765997,0.322261,-460.555756,0.033007,0.000000
27.250002,20.793648,-460.511292,-0.003139,0.001280,0.032512,92.494766,4.711908,0.325122,-460.511292,0.033397,0.000000
27.480001,20.748596,-460.466797,-0.003057,0.001293,0.032851,92.294365,4.701699,0.328506,-460.466797,0.033779,0.000000
27.710001,20.811150,-460.555756,-0.003074,0.001308,0.033215,92.572617,4.715874,0.332147,-460.555756,0.034160,0.000000
27.940001,21.034203,-460.600250,-0.003074,0.001325,0.033648,93.564804,4.766418,0.336485,-460.600250,0.034542,0.000000
28.170002,21.247948,-460.555756,-0.003053,0.001338,0.033978,94.515594,4.814854,0.339778,-460.555756,0.034923,0.000000
28.400002,21.042770,-460.555756,-0.003018,0.001348,0.034229,93.602921,4.768360,0.342291,-460.555756,0.035313,0.000000
28.630001,21.531693,-460.644714,-0.003009,0.001367,0.034732,95.777748,4.879151,0.347325,-460.644714,0.035695,0.000000
28.860001,21.821396,-460.600250,-0.002958,0.001386,0.035192,97.066414,4.944799,0.351920,-460.600250,0.036077,0.000000
29.090002,21.929016,-460.644714,-0.002966,0.001400,0.035548,97.545135,4.969186,0.355477,-460.644714,0.036458,0.000000
29.320002,21.936836,-460.644714,-0.002953,0.001415,0.035938,97.579918,4.970958,0.359376,-460.644714,0.036840,0.000000
29.550001,21.961411,-460.644714,-0.002915,0.001428,0.036268,97.689232,4.976527,0.362676,-460.644714,0.037230,0.000000
29.780001,22.124512,-460.600250,-0.002910,0.001443,0.036649,98.414742,5.013486,0.366491,-460.600250,0.037611,0.000000
30.010002,22.716957,-460.644714,-0.002915,0.001464,0.037187,101.050072,5.147736,0.371866,-460.644714,0.037993,0.000000
30.240002,22.315910,-460.733704,-0.002889,0.001471,0.037360,99.266129,5.056858,0.373599,-460.733704,0.038375,0.000000
30.470001,22.554596,-460.733704,-0.002841,0.001488,0.037785,100.327850,5.110944,0.377854,-460.733704,0.038757,0.000000
30.700001,22.753448,-460.644714,-0.002859,0.001503,0.038175,101.212395,5.156005,0.381752,-460.644714,0.039146,0.000000
30.930002,23.365257,-460.733704,-0.002802,0.001524,0.038704,103.933853,5.294643,0.387043,-460.733704,0.039528,0.000000
31.160002,22.910957,-460.733704,-0.002802,0.001531,0.038878,101.913025,5.191697,0.388777,-460.733704,0.039909,0.000000
31.390001,23.052086,-460.733704,-0.002777,0.001548,0.039311,102.540802,5.223677,0.393114,-460.733704,0.040291,0.000000
31.620001,23.291893,-460.689209,-0.002764,0.001562,0.039684,103.607513,5.278018,0.396839,-460.689209,0.040673,0.000000
31.850002,24.022118,-460.689209,-0.002759,0.001585,0.040257,106.855713,5.443490,0.402569,-460.689209,0.041063,0.000000
32.080002,24.012810,-460.822662,-0.002746,0.001597,0.040569,106.814316,5.441381,0.405688,-460.822662,0.041445,0.000000
32.310001,23.407333,-460.822662,-0.002738,0.001602,0.040699,104.121017,5.304178,0.406990,-460.822662,0.041826,0.000000
32.540001,23.714165,-460.822662,-0.002725,0.001619,0.041133,105.485870,5.373707,0.411327,-460.822662,0.042208,0.000000
32.770000,24.587753,-460.867126,-0.002699,0.001645,0.041774,109.371788,5.571665,0.417739,-460.867126,0.042589,0.000000
33.000000,24.247032,-460.867126,-0.002682,0.001655,0.042026,107.856186,5.494456,0.420260,-460.867126,0.042980,0.000000
33.230003,24.369911,-460.867126,-0.002673,0.001670,0.042407,108.402779,5.522301,0.424075,-460.867126,0.043361,0.000000
33.460003,24.735954,-460.867126,-0.002613,0.001687,0.042850,110.031021,5.605247,0.428496,-460.867126,0.043743,0.000000
33.690002,24.598923,-460.911621,-0.002626,0.001698,0.043136,109.421471,5.574196,0.431357,-460.911621,0.044124,0.000000
33.920002,24.948212,-460.956085,-0.002583,0.001715,0.043569,110.975189,5.653346,0.435694,-460.956085,0.044506,0.000000
34.150002,24.896080,-460.911621,-0.002604,0.001729,0.043908,110.743294,5.641532,0.439078,-460.911621,0.044896,0.000000
34.380001,24.950447,-460.911621,-0.002587,0.001741,0.044220,110.985130,5.653852,0.442197,-460.911621,0.045278,0.000000
34.610001,25.700401,-460.911621,-0.002552,0.001763,0.044784,114.321098,5.823794,0.447836,-460.911621,0.045659,0.000000
34.840000,25.835571,-460.956085,-0.002509,0.001778,0.045156,114.922363,5.854424,0.451561,-460.956085,0.046041,0.000000
35.070004,25.721252,-461.000580,-0.002496,0.001794,0.045572,114.413849,5.828519,0.455724,-461.000580,0.046432,0.000000
35.300003,25.749184,-460.956085,-0.002488,0.001806,0.045868,114.538086,5.834848,0.458676,-460.956085,0.046813,0.000000
35.530003,25.860146,-460.911621,-0.002471,0.001822,0.046275,115.031670,5.859993,0.462749,-460.911621,0.047195,0.000000
35.760002,25.725723,-460.956085,-0.002479,0.001831,0.046518,114.433731,5.829532,0.465179,-460.956085,0.047576,0.000000
35.990002,26.350189,-461.045044,-0.002423,0.001853,0.047064,117.211494,5.971038,0.470644,-461.045044,0.047958,0.000000
36.220001,25.862755,-461.045044,-0.002423,0.001860,0.047238,115.043282,5.860584,0.472378,-461.045044,0.048347,0.000000
36.450001,25.872437,-461.000580,-0.002436,0.001873,0.047576,115.086342,5.862778,0.475761,-461.000580,0.048730,0.000000
36.680000,26.452225,-461.045044,-0.002376,0.001893,0.048070,117.665375,5.994160,0.480704,-461.045044,0.049111,0.000000
36.910000,27.102753,-461.089539,-0.002376,0.001912,0.048565,120.559067,6.141572,0.485647,-461.089539,0.049493,0.000000
37.140003,27.097916,-461.089539,-0.002337,0.001928,0.048981,120.537552,6.140475,0.489811,-461.089539,0.049874,0.000000
37.370003,27.229736,-461.134033,-0.002298,0.001943,0.049345,121.123917,6.170346,0.493452,-461.134033,0.050264,0.000000
37.600002,26.786240,-461.089539,-0.002315,0.001955,0.049649,119.151146,6.069849,0.496487,-461.089539,0.050646,0.000000
37.830002,26.575104,-461.045044,-0.002302,0.001962,0.049839,118.211967,6.022005,0.498395,-461.045044,0.051027,0.000000
38.060001,27.335114,-461.089539,-0.002259,0.001983,0.050377,121.592659,6.194225,0.503770,-461.089539,0.051409,0.000000
38.290001,27.050255,-461.178497,-0.002259,0.001994,0.050646,120.325546,6.129675,0.506457,-461.178497,0.051791,0.000000
38.520000,27.135155,-461.134033,-0.002251,0.002007,0.050976,120.703194,6.148914,0.509757,-461.134033,0.052181,0.000000
38.750000,28.608627,-461.134033,-0.002225,0.002035,0.051696,127.257530,6.482808,0.516956,-461.134033,0.052562,0.000000
38.980003,28.023262,-461.178497,-0.002229,0.002045,0.051955,124.653694,6.350162,0.519553,-461.178497,0.052944,0.000000
39.210003,28.376266,-461.178497,-0.002186,0.002063,0.052406,126.223938,6.430154,0.524064,-461.178497,0.053325,0.000000
39.440002,28.325630,-461.222992,-0.002177,0.002078,0.052780,125.998695,6.418680,0.527796,-461.222992,0.053707,0.000000
39.670002,28.503624,-461.222992,-0.002160,0.002094,0.053196,126.790451,6.459013,0.531959,-461.222992,0.054098,0.000000
39.900002,28.441811,-461.178497,-0.002143,0.002107,0.053525,126.515495,6.445006,0.535252,-461.178497,0.054479,0.000000
40.130001,28.074646,-461.178497,-0.002130,0.002116,0.053751,124.882263,6.361805,0.537508,-461.178497,0.054861,0.000000
40.360001,28.516655,-461.267456,-0.002113,0.002135,0.054219,126.848419,6.461967,0.542186,-461.267456,0.055242,0.000000
40.590000,29.417793,-461.267456,-0.002070,0.002159,0.054843,130.856873,6.666167,0.548431,-461.267456,0.055624,0.000000
40.820004,29.156761,-461.267456,-0.002057,0.002172,0.055173,129.695755,6.607017,0.551732,-461.267456,0.056014,0.000000
41.050003,28.921799,-461.222992,-0.002057,0.002185,0.055502,128.650589,6.553773,0.555025,-461.222992,0.056396,0.000000
41.280003,28.983612,-461.222992,-0.002035,0.002198,0.055823,128.925552,6.567780,0.558234,-461.222992,0.056777,0.000000
41.510002,29.221558,-461.222992,-0.002001,0.002215,0.056257,129.983978,6.621700,0.562572,-461.222992,0.057159,0.000000
41.740002,29.363426,-461.311951,-0.001979,0.002230,0.056639,130.615036,6.653847,0.566387,-461.311951,0.057540,0.000000
41.970001,28.887169,-461.356415,-0.001966,0.002238,0.056838,128.496552,6.545926,0.568378,-461.356415,0.057931,0.000000
42.200001,29.304970,-461.311951,-0.001962,0.002255,0.057281,130.355011,6.640601,0.572806,-461.311951,0.058312,0.000000
42.430000,30.014336,-461.311951,-0.001932,0.002278,0.057870,133.510437,6.801345,0.578703,-461.311951,0.058694,0.000000
42.660004,30.161049,-461.400909,-0.001901,0.002293,0.058252,134.163040,6.834591,0.582518,-461.400909,0.059075,0.000000
42.890003,29.843048,-461.356415,-0.001867,0.002304,0.058529,132.748505,6.762531,0.585289,-461.356415,0.059457,0.000000
43.120003,29.762985,-461.356415,-0.001871,0.002319,0.058902,132.392365,6.744389,0.589020,-461.356415,0.059848,0.000000
43.350002,29.405510,-461.311951,-0.001845,0.002330,0.059179,130.802246,6.663383,0.591791,-461.311951,0.060229,0.000000
43.580002,30.153229,-461.356415,-0.001819,0.002350,0.059700,134.128265,6.832819,0.596999,-461.356415,0.060611,0.000000
43.810001,29.797989,-461.356415,-0.001811,0.002360,0.059943,132.548080,6.752321,0.599429,-461.356415,0.060992,0.000000
44.040001,29.915657,-461.400909,-0.001819,0.002377,0.060368,133.071487,6.778985,0.603676,-461.400909,0.061382,0.000000
44.270000,30.267921,-461.489868,-0.001776,0.002392,0.060766,134.638443,6.858809,0.607665,-461.489868,0.061763,0.000000
44.500004,30.972824,-461.400909,-0.001755,0.002413,0.061296,137.774002,7.018542,0.612956,-461.400909,0.062146,0.000000
44.730003,30.896118,-461.489868,-0.001720,0.002427,0.061651,137.432800,7.001161,0.616514,-461.489868,0.062527,0.000000
44.960003,30.408676,-461.534363,-0.001690,0.002438,0.061928,135.264542,6.890705,0.619285,-461.534363,0.062909,0.000000
45.190002,30.501396,-461.578827,-0.001669,0.002454,0.062319,135.676987,6.911715,0.623191,-461.578827,0.063299,0.000000
45.420002,30.589279,-461.534363,-0.001673,0.002468,0.062683,136.067917,6.931630,0.626832,-461.534363,0.063680,0.000000
45.650002,31.194756,-461.445374,-0.001651,0.002488,0.063186,138.761200,7.068833,0.631858,-461.445374,0.064062,0.000000
45.880001,30.760941,-461.445374,-0.001638,0.002497,0.063429,136.831497,6.970529,0.634288,-461.445374,0.064444,0.000000
46.110001,31.663574,-461.578827,-0.001608,0.002521,0.064028,140.846619,7.175068,0.640276,-461.578827,0.064825,0.000000
46.340004,31.818855,-461.578827,-0.001595,0.002537,0.064444,141.537338,7.210256,0.644439,-461.578827,0.065215,0.000000
46.570004,31.589096,-461.578827,-0.001548,0.002550,0.064782,140.515320,7.158192,0.647815,-461.578827,0.065597,0.000000
46.800003,31.256569,-461.578827,-0.001561,0.002563,0.065094,139.036163,7.082840,0.650941,-461.578827,0.065978,0.000000
47.030003,30.979523,-461.534363,-0.001531,0.002575,0.065398,137.803802,7.020060,0.653977,-461.534363,0.066360,0.000000
47.260002,30.765038,-461.623322,-0.001513,0.002586,0.065675,136.849716,6.971457,0.656747,-461.623322,0.066741,0.000000
47.490002,31.488190,-461.623322,-0.001492,0.002606,0.066196,140.066467,7.135326,0.661955,-461.623322,0.067132,0.000000
47.720001,31.242050,-461.712280,-0.001492,0.002616,0.066438,138.971573,7.079550,0.664378,-461.712280,0.067513,0.000000
47.950001,30.862228,-461.623322,-0.001453,0.002627,0.066733,137.282043,6.993481,0.667330,-461.623322,0.067895,0.000000
48.180004,32.616104,-461.578827,-0.001436,0.002656,0.067461,145.083679,7.390915,0.674612,-461.578827,0.068276,0.000000
48.410004,32.750160,-461.667786,-0.001427,0.002671,0.067834,145.679993,7.421293,0.678344,-461.667786,0.068658,0.000000
48.640003,32.523758,-461.667786,-0.001401,0.002682,0.068121,144.672897,7.369988,0.681205,-461.667786,0.069049,0.000000
48.870003,32.343155,-461.712280,-0.001388,0.002695,0.068459,143.869537,7.329064,0.684589,-461.712280,0.069430,0.000000
49.100002,32.305916,-461.667786,-0.001388,0.002707,0.068753,143.703888,7.320625,0.687534,-461.667786,0.069812,0.000000
49.330002,32.743080,-461.623322,-0.001345,0.002725,0.069214,145.648499,7.419688,0.692136,-461.623322,0.070193,0.000000
49.560001,32.842506,-461.801239,-0.001324,0.002737,0.069517,146.090759,7.442218,0.695172,-461.801239,0.070575,0.000000
49.790001,32.607536,-461.756744,-0.001315,0.002746,0.069751,145.045563,7.388974,0.697511,-461.756744,0.070965,0.000000
50.020004,33.972656,-461.756744,-0.001324,0.002774,0.070471,151.117920,7.698314,0.704710,-461.756744,0.071347,0.000000
50.250004,34.494347,-461.667786,-0.001281,0.002792,0.070921,153.438522,7.816530,0.709214,-461.667786,0.071728,0.000000
50.480003,34.460464,-461.756744,-0.001255,0.002806,0.071260,153.287796,7.808853,0.712597,-461.756744,0.072110,0.000000
50.710003,34.235550,-461.756744,-0.001237,0.002814,0.071477,152.287338,7.757886,0.714770,-461.756744,0.072491,0.000000
50.940002,34.616859,-461.845703,-0.001216,0.002832,0.071927,153.983475,7.844293,0.719274,-461.845703,0.072882,0.000000
51.170002,34.751656,-461.845703,-0.001203,0.002845,0.072257,154.583084,7.874838,0.722574,-461.845703,0.073263,0.000000
51.400002,35.638649,-461.801239,-0.001190,0.002865,0.072777,158.528625,8.075833,0.727775,-461.801239,0.073645,0.000000
51.630001,35.043968,-461.801239,-0.001181,0.002870,0.072908,155.883362,7.941077,0.729077,-461.801239,0.074026,0.000000
51.860001,35.637535,-461.934662,-0.001173,0.002890,0.073402,158.523666,8.075581,0.734020,-461.934662,0.074408,0.000000
52.090004,36.086990,-461.934662,-0.001143,0.002906,0.073809,160.522949,8.177429,0.738092,-461.934662,0.074798,0.000000
52.320004,37.160164,-461.890198,-0.001134,0.002926,0.074330,165.296661,8.420613,0.743300,-461.890198,0.075180,0.000000
52.550003,36.798592,-461.801239,-0.001112,0.002934,0.074521,163.688309,8.338680,0.745208,-461.801239,0.075562,0.000000
52.780003,37.181763,-461.845703,-0.001091,0.002949,0.074911,165.392746,8.425508,0.749106,-461.845703,0.075943,0.000000
53.010002,37.368317,-461.934662,-0.001087,0.002963,0.075266,166.222580,8.467781,0.752664,-461.934662,0.076333,0.000000
53.240002,38.773285,-461.934662,-0.001048,0.002987,0.075865,172.472183,8.786152,0.758652,-461.934662,0.076715,0.000000
53.470001,38.854462,-461.934662,-0.001065,0.002998,0.076160,172.833282,8.804546,0.761597,-461.934662,0.077096,0.000000
53.700001,38.992981,-461.934662,-0.001056,0.003011,0.076472,173.449448,8.835936,0.764723,-461.934662,0.077478,0.000000
53.930004,39.783157,-461.979156,-0.001043,0.003030,0.076958,176.964325,9.014993,0.769575,-461.979156,0.077860,0.000000
54.160004,40.631790,-461.979156,-0.001009,0.003048,0.077417,180.739227,9.207295,0.774170,-461.979156,0.078250,0.000000
54.390003,40.513008,-462.023651,-0.001018,0.003058,0.077677,180.210861,9.180379,0.776774,-462.023651,0.078631,0.000000
54.620003,40.993736,-461.979156,-0.000992,0.003073,0.078042,182.349243,9.289313,0.780415,-461.979156,0.079013,0.000000
54.850002,41.545967,-462.023651,-0.000974,0.003087,0.078415,184.805695,9.414451,0.784147,-462.023651,0.079394,0.000000
55.080002,41.852798,-461.979156,-0.000961,0.003104,0.078839,186.170547,9.483980,0.788394,-461.979156,0.079776,0.000000
55.310001,42.492538,-462.068115,-0.000944,0.003118,0.079195,189.016251,9.628946,0.791951,-462.068115,0.080166,0.000000
55.540001,42.889114,-462.112610,-0.000961,0.003131,0.079516,190.780304,9.718812,0.795161,-462.112610,0.080548,0.000000
55.770004,43.082001,-462.068115,-0.000923,0.003141,0.079793,191.638306,9.762521,0.797932,-462.068115,0.080929,0.000000
56.000004,44.760658,-462.068115,-0.000927,0.003168,0.080470,199.105347,10.142910,0.804699,-462.068115,0.081311,0.000000
56.230003,45.312889,-462.068115,-0.000914,0.003182,0.080826,201.561798,10.268047,0.808257,-462.068115,0.081692,0.000000
56.460003,45.873306,-462.112610,-0.000888,0.003197,0.081198,204.054657,10.395041,0.811981,-462.112610,0.082083,0.000000
56.690002,45.931396,-462.112610,-0.000871,0.003207,0.081450,204.313049,10.408203,0.814502,-462.112610,0.082465,0.000000
56.920002,46.609116,-462.112610,-0.000880,0.003226,0.081953,207.327698,10.561777,0.819528,-462.112610,0.082846,0.000000
57.150002,47.615265,-462.112610,-0.000836,0.003241,0.082326,211.803284,10.789773,0.823260,-462.112610,0.083228,0.000000
57.380001,48.074402,-462.157074,-0.000845,0.003254,0.082664,213.845627,10.893815,0.826636,-462.157074,0.083609,0.000000
57.610004,47.682663,-462.157074,-0.000836,0.003260,0.082811,212.103073,10.805046,0.828112,-462.157074,0.084000,0.000000
57.840004,48.361504,-462.201569,-0.000828,0.003275,0.083175,215.122711,10.958873,0.831753,-462.201569,0.084381,0.000000
58.070004,49.650650,-462.201569,-0.000815,0.003295,0.083687,220.857117,11.250998,0.836871,-462.201569,0.084763,0.000000
58.300003,50.718620,-462.157074,-0.000793,0.003313,0.084147,225.607697,11.493003,0.841465,-462.157074,0.085144,0.000000
58.530003,51.538582,-462.201569,-0.000759,0.003329,0.084563,229.255066,11.678809,0.845629,-462.201569,0.085526,0.000000
58.760002,52.129906,-462.201569,-0.000793,0.003342,0.084876,231.885406,11.812806,0.848755,-462.201569,0.085916,0.000000
58.990002,52.946892,-462.290527,-0.000767,0.003359,0.085309,235.519531,11.997937,0.853093,-462.290527,0.086298,0.000000
59.220001,53.657379,-462.246033,-0.000763,0.003374,0.085708,238.679947,12.158936,0.857082,-462.246033,0.086679,0.000000
59.450005,53.971664,-462.246033,-0.000746,0.003382,0.085899,240.077957,12.230154,0.858989,-462.246033,0.087061,0.000000
59.680004,54.269562,-462.290527,-0.000742,0.003393,0.086185,241.403061,12.297658,0.861851,-462.290527,0.087442,0.000000
59.910004,54.742844,-462.334991,-0.000737,0.003411,0.086635,243.508331,12.404905,0.866355,-462.334991,0.087832,0.000000
60.140003,57.091400,-462.379486,-0.000707,0.003434,0.087225,253.955231,12.937097,0.872252,-462.379486,0.088215,0.000000
60.370003,57.337540,-462.334991,-0.000716,0.003446,0.087520,255.050110,12.992872,0.875204,-462.334991,0.088596,0.000000
60.600002,58.436409,-462.290527,-0.000694,0.003464,0.087997,259.938141,13.241879,0.879973,-462.290527,0.088978,0.000000
60.830002,59.471977,-462.246033,-0.000668,0.003482,0.088448,264.544556,13.476542,0.884485,-462.246033,0.089367,0.000000
61.060001,60.457275,-462.379486,-0.000673,0.003498,0.088838,268.927399,13.699815,0.888383,-462.379486,0.089749,0.000000
61.290005,60.791290,-462.379486,-0.000660,0.003507,0.089073,270.413177,13.775503,0.890730,-462.379486,0.090130,0.000000
61.520004,60.972267,-462.334991,-0.000660,0.003515,0.089289,271.218201,13.816513,0.892895,-462.334991,0.090512,0.000000
61.750004,62.580170,-462.334991,-0.000638,0.003542,0.089975,278.370483,14.180869,0.899745,-462.334991,0.090894,0.000000
61.980003,64.242813,-462.379486,-0.000664,0.003560,0.090417,285.766296,14.557630,0.904166,-462.379486,0.091284,0.000000
62.210003,64.781265,-462.468445,-0.000634,0.003572,0.090720,288.161469,14.679644,0.907201,-462.468445,0.091666,0.000000
62.440002,65.485794,-462.468445,-0.000621,0.003585,0.091068,291.295349,14.839293,0.910676,-462.468445,0.092047,0.000000
62.670002,66.065201,-462.468445,-0.000638,0.003598,0.091397,293.872681,14.970588,0.913969,-462.468445,0.092429,0.000000
62.900002,67.575180,-462.423981,-0.000608,0.003614,0.091787,300.589417,15.312755,0.917875,-462.423981,0.092794,0.000000
63.130005,66.834152,-462.468445,-0.000595,0.003608,0.091631,297.293152,15.144835,0.916308,-462.468445,0.091900,0.000000
63.360004,66.111374,-462.468445,-0.000578,0.003605,0.091579,294.078064,14.981051,0.915793,-462.468445,0.091631,0.000000
63.590004,65.504410,-462.557404,-0.000599,0.003604,0.091553,291.378174,14.843512,0.915528,-462.557404,0.091631,0.000000
63.820004,64.949203,-462.512939,-0.000586,0.003604,0.091544,288.908478,14.717700,0.915445,-462.512939,0.091631,0.000000
64.050003,64.429749,-462.512939,-0.000578,0.003604,0.091535,286.597839,14.599990,0.915354,-462.512939,0.091631,0.000000
64.280006,63.979172,-462.512939,-0.000565,0.003604,0.091535,284.593567,14.497888,0.915354,-462.512939,0.091631,0.000000
64.510002,63.543869,-462.557404,-0.000586,0.003604,0.091535,282.657257,14.399246,0.915354,-462.557404,0.091631,0.000000
64.740005,63.167770,-462.512939,-0.000560,0.003603,0.091527,280.984283,14.314021,0.915271,-462.512939,0.091631,0.000000
64.970001,62.814018,-462.601898,-0.000560,0.003603,0.091527,279.410706,14.233860,0.915271,-462.601898,0.091631,0.000000
65.200005,62.500854,-462.601898,-0.000578,0.003603,0.091527,278.017700,14.162896,0.915271,-462.601898,0.091631,0.000000
65.430000,62.188805,-462.601898,-0.000565,0.003603,0.091527,276.629608,14.092185,0.915271,-462.601898,0.091631,0.000000
65.660004,61.902451,-462.557404,-0.000560,0.003603,0.091527,275.355865,14.027296,0.915271,-462.557404,0.091631,0.000000
65.889999,61.631737,-462.601898,-0.000556,0.003603,0.091527,274.151672,13.965951,0.915271,-462.601898,0.091631,0.000000
66.120003,61.378525,-462.601898,-0.000556,0.003603,0.091527,273.025299,13.908573,0.915271,-462.601898,0.091631,0.000000
66.350006,61.162178,-462.646362,-0.000552,0.003603,0.091527,272.062958,13.859548,0.915271,-462.646362,0.091631,0.000000
66.580002,60.942474,-462.601898,-0.000535,0.003603,0.091518,271.085663,13.809762,0.915180,-462.601898,0.091631,0.000000
66.810005,60.747726,-462.646362,-0.000573,0.003603,0.091518,270.219391,13.765632,0.915180,-462.646362,0.091631,0.000000
67.040001,60.546646,-462.690857,-0.000543,0.003603,0.091518,269.324921,13.720066,0.915180,-462.690857,0.091631,0.000000
67.270004,60.347427,-462.735321,-0.000535,0.003603,0.091518,268.438751,13.674923,0.915180,-462.735321,0.091631,0.000000
67.500000,60.184700,-462.646362,-0.000560,0.003603,0.091518,267.714905,13.638048,0.915180,-462.646362,0.091631,0.000000
67.730003,60.019737,-462.735321,-0.000573,0.003603,0.091518,266.981140,13.600667,0.915180,-462.735321,0.091631,0.000000
67.960007,59.858871,-462.735321,-0.000543,0.003603,0.091518,266.265564,13.564214,0.915180,-462.735321,0.091631,0.000000
68.190002,59.713646,-462.779816,-0.000552,0.003603,0.091518,265.619568,13.531305,0.915180,-462.779816,0.091631,0.000000
68.420006,59.557625,-462.735321,-0.000552,0.003603,0.091518,264.925537,13.495951,0.915180,-462.735321,0.091631,0.000000
68.650002,59.427666,-462.735321,-0.000569,0.003603,0.091518,264.347473,13.466501,0.915180,-462.735321,0.091631,0.000000
68.880005,59.289886,-462.779816,-0.000517,0.003603,0.091518,263.734589,13.435281,0.915180,-462.779816,0.091631,0.000000
69.110001,59.159927,-462.824310,-0.000535,0.003603,0.091518,263.156494,13.405831,0.915180,-462.824310,0.091631,0.000000
69.340004,59.039284,-462.824310,-0.000535,0.003603,0.091518,262.619843,13.378493,0.915180,-462.824310,0.091631,0.000000
69.570000,58.929802,-462.779816,-0.000535,0.003603,0.091518,262.132843,13.353683,0.915180,-462.779816,0.091631,0.000000
69.800003,58.795006,-462.779816,-0.000543,0.003603,0.091518,261.533234,13.323138,0.915180,-462.779816,0.091631,0.000000
70.030006,58.704887,-462.824310,-0.000513,0.003603,0.091518,261.132385,13.302718,0.915180,-462.824310,0.091631,0.000000
70.260002,58.586479,-462.868774,-0.000530,0.003603,0.091518,260.605682,13.275887,0.915180,-462.868774,0.091631,0.000000
70.490005,58.476624,-462.824310,-0.000517,0.003603,0.091518,260.117004,13.250993,0.915180,-462.824310,0.091631,0.000000
70.720001,58.382416,-462.913269,-0.000530,0.003603,0.091518,259.697968,13.229645,0.915180,-462.913269,0.091631,0.000000
70.950005,58.295280,-462.868774,-0.000535,0.003603,0.091518,259.310364,13.209899,0.915180,-462.868774,0.091631,0.000000
71.180000,58.205536,-462.868774,-0.000496,0.003603,0.091518,258.911163,13.189563,0.915180,-462.868774,0.091631,0.000000
71.410004,58.108719,-462.913269,-0.000513,0.003603,0.091518,258.480499,13.167624,0.915180,-462.913269,0.091631,0.000000
71.640007,58.023445,-462.957733,-0.000522,0.003603,0.091518,258.101166,13.148300,0.915180,-462.957733,0.091631,0.000000
71.870003,57.934448,-462.957733,-0.000539,0.003603,0.091518,257.705292,13.128134,0.915180,-462.957733,0.091631,0.000000
72.100006,57.856628,-462.913269,-0.000539,0.003603,0.091518,257.359131,13.110499,0.915180,-462.913269,0.091631,0.000000
72.330002,57.776192,-462.913269,-0.000530,0.003603,0.091518,257.001343,13.092272,0.915180,-462.913269,0.091631,0.000000
72.560005,57.709541,-463.002228,-0.000522,0.003603,0.091518,256.704865,13.077169,0.915180,-463.002228,0.091631,0.000000
72.790001,57.629105,-462.957733,-0.000560,0.003603,0.091518,256.347046,13.058942,0.915180,-462.957733,0.091631,0.000000
73.020004,57.547554,-462.957733,-0.000539,0.003603,0.091518,255.984299,13.040462,0.915180,-462.957733,0.091631,0.000000
73.250000,57.483139,-462.913269,-0.000517,0.003603,0.091518,255.697769,13.025865,0.915180,-462.913269,0.091631,0.000000
73.480003,57.425049,-462.957733,-0.000504,0.003603,0.091518,255.439377,13.012702,0.915180,-462.957733,0.091631,0.000000
73.710007,57.356155,-462.957733,-0.000513,0.003603,0.091518,255.132919,12.997090,0.915180,-462.957733,0.091631,0.000000
73.940002,57.303650,-463.046692,-0.000530,0.003603,0.091518,254.899368,12.985193,0.915180,-463.046692,0.091631,0.000000
74.170006,57.213165,-463.002228,-0.000504,0.003603,0.091518,254.496872,12.964688,0.915180,-463.002228,0.091631,0.000000
74.400002,57.153961,-462.957733,-0.000522,0.003603,0.091518,254.233521,12.951272,0.915180,-462.957733,0.091631,0.000000
74.630005,57.100708,-463.002228,-0.000526,0.003603,0.091518,253.996628,12.939205,0.915180,-463.002228,0.091631,0.000000
74.860001,57.032936,-463.135651,-0.000539,0.003603,0.091518,253.695175,12.923848,0.915180,-463.135651,0.091631,0.000000
75.090004,56.974472,-463.046692,-0.000509,0.003603,0.091518,253.435104,12.910601,0.915180,-463.046692,0.091631,0.000000
75.320007,56.929420,-463.046692,-0.000526,0.003603,0.091518,253.234711,12.900392,0.915180,-463.046692,0.091631,0.000000
75.550003,56.859787,-463.091187,-0.000500,0.003603,0.091518,252.924957,12.884612,0.915180,-463.091187,0.091631,0.000000
75.780006,56.806160,-463.135651,-0.000496,0.003603,0.091518,252.686417,12.872460,0.915180,-463.135651,0.091631,0.000000
76.010002,56.758125,-463.135651,-0.000500,0.003603,0.091518,252.472748,12.861575,0.915180,-463.135651,0.091631,0.000000
76.240005,56.702271,-463.135651,-0.000517,0.003603,0.091518,252.224289,12.848918,0.915180,-463.135651,0.091631,0.000000
76.470001,56.658707,-463.135651,-0.000517,0.003603,0.091518,252.030518,12.839046,0.915180,-463.135651,0.091631,0.000000
76.700005,56.609924,-463.135651,-0.000513,0.003603,0.091518,251.813522,12.827992,0.915180,-463.135651,0.091631,0.000000
76.930000,56.546616,-463.135651,-0.000526,0.003603,0.091518,251.531906,12.813646,0.915180,-463.135651,0.091631,0.000000
77.160004,56.508636,-463.180145,-0.000496,0.003603,0.091518,251.362976,12.805040,0.915180,-463.180145,0.091631,0.000000
77.390007,56.453529,-463.269104,-0.000513,0.003603,0.091518,251.117844,12.792553,0.915180,-463.269104,0.091631,0.000000
77.620003,56.418526,-463.180145,-0.000513,0.003603,0.091518,250.962143,12.784621,0.915180,-463.180145,0.091631,0.000000
77.850006,56.362671,-463.224609,-0.000517,0.003603,0.091518,250.713684,12.771964,0.915180,-463.224609,0.091631,0.000000
78.080002,56.315376,-463.224609,-0.000535,0.003603,0.091518,250.503311,12.761247,0.915180,-463.224609,0.091631,0.000000
78.310005,56.273300,-463.269104,-0.000504,0.003603,0.091518,250.316147,12.751713,0.915180,-463.269104,0.091631,0.000000
78.540001,56.227493,-463.269104,-0.000526,0.003603,0.091518,250.112381,12.741332,0.915180,-463.269104,0.091631,0.000000
78.770004,56.193985,-463.224609,-0.000513,0.003603,0.091518,249.963333,12.733739,0.915180,-463.224609,0.091631,0.000000
79.000000,56.152275,-463.224609,-0.000509,0.003603,0.091518,249.777802,12.724288,0.915180,-463.224609,0.091631,0.000000
79.230003,56.100143,-463.269104,-0.000500,0.003603,0.091518,249.545898,12.712474,0.915180,-463.269104,0.091631,0.000000
79.460007,56.058067,-463.313599,-0.000496,0.003603,0.091518,249.358734,12.702940,0.915180,-463.313599,0.091631,0.000000
79.690002,56.031998,-463.269104,-0.000504,0.003603,0.091518,249.242767,12.697032,0.915180,-463.269104,0.091631,0.000000
79.920006,55.981728,-463.313599,-0.000496,0.003603,0.091518,249.019165,12.685640,0.915180,-463.313599,0.091631,0.000000
80.150002,55.956039,-463.313599,-0.000526,0.003603,0.091518,248.904892,12.679819,0.915180,-463.313599,0.091631,0.000000
80.380005,55.918427,-463.358063,-0.000513,0.003603,0.091518,248.737579,12.671297,0.915180,-463.358063,0.091631,0.000000
80.610001,55.870392,-463.358063,-0.000535,0.003603,0.091518,248.523911,12.660412,0.915180,-463.358063,0.091631,0.000000
80.840004,55.822357,-463.402557,-0.000479,0.003603,0.091518,248.310242,12.649527,0.915180,-463.402557,0.091631,0.000000
81.070007,55.799271,-463.313599,-0.000509,0.003603,0.091518,248.207550,12.644296,0.915180,-463.313599,0.091631,0.000000
81.300003,55.770226,-463.358063,-0.000513,0.003603,0.091518,248.078354,12.637714,0.915180,-463.358063,0.091631,0.000000
81.530006,55.733727,-463.447021,-0.000504,0.003603,0.091518,247.916000,12.629442,0.915180,-463.447021,0.091631,0.000000
81.760002,55.697609,-463.447021,-0.000513,0.003603,0.091518,247.755341,12.621259,0.915180,-463.447021,0.091631,0.000000
81.990005,55.645103,-463.447021,-0.000535,0.003603,0.091518,247.521790,12.609361,0.915180,-463.447021,0.091631,0.000000
82.220001,55.628349,-463.447021,-0.000513,0.003603,0.091518,247.447250,12.605564,0.915180,-463.447021,0.091631,0.000000
82.450005,55.586639,-463.447021,-0.000526,0.003603,0.091518,247.261719,12.596112,0.915180,-463.447021,0.091631,0.000000
82.680000,55.561691,-463.447021,-0.000539,0.003603,0.091518,247.150742,12.590459,0.915180,-463.447021,0.091631,0.000000
82.910004,55.528549,-463.447021,-0.000513,0.003603,0.091518,247.003326,12.582950,0.915180,-463.447021,0.091631,0.000000
83.140007,55.475304,-463.447021,-0.000535,0.003603,0.091518,246.766479,12.570883,0.915180,-463.447021,0.091631,0.000000
83.370003,55.460411,-463.491516,-0.000509,0.003603,0.091518,246.700226,12.567509,0.915180,-463.491516,0.091631,0.000000
83.600006,55.441788,-463.447021,-0.000509,0.003603,0.091518,246.617386,12.563289,0.915180,-463.447021,0.091631,0.000000
83.830002,55.397850,-463.491516,-0.000496,0.003603,0.091518,246.421951,12.553332,0.915180,-463.491516,0.091631,0.000000
84.060005,55.363594,-463.535980,-0.000479,0.003603,0.091518,246.269562,12.545569,0.915180,-463.535980,0.091631,0.000000
84.290001,55.340508,-463.535980,-0.000500,0.003603,0.091518,246.166870,12.540338,0.915180,-463.535980,0.091631,0.000000
84.520004,55.316299,-463.580475,-0.000522,0.003603,0.091518,246.059189,12.534853,0.915180,-463.580475,0.091631,0.000000
84.750008,55.285393,-463.535980,-0.000500,0.003603,0.091518,245.921707,12.527849,0.915180,-463.535980,0.091631,0.000000
84.980003,55.246666,-463.580475,-0.000487,0.003603,0.091518,245.749451,12.519073,0.915180,-463.580475,0.091631,0.000000
85.210007,55.221718,-463.580475,-0.000509,0.003603,0.091518,245.638474,12.513420,0.915180,-463.580475,0.091631,0.000000
85.440002,55.188950,-463.580475,-0.000492,0.003603,0.091518,245.492706,12.505995,0.915180,-463.580475,0.091631,0.000000
85.670006,55.168839,-463.580475,-0.000500,0.003603,0.091518,245.403244,12.501438,0.915180,-463.580475,0.091631,0.000000
85.900002,55.156921,-463.535980,-0.000509,0.003603,0.091518,245.350235,12.498737,0.915180,-463.535980,0.091631,0.000000
86.130005,55.117455,-463.580475,-0.000509,0.003603,0.091518,245.174683,12.489794,0.915180,-463.580475,0.091631,0.000000
86.360001,55.084312,-463.669434,-0.000500,0.003603,0.091518,245.027252,12.482284,0.915180,-463.669434,0.091631,0.000000
86.590004,55.059364,-463.624939,-0.000517,0.003603,0.091518,244.916290,12.476630,0.915180,-463.624939,0.091631,0.000000
86.820007,55.029198,-463.624939,-0.000513,0.003603,0.091518,244.782089,12.469794,0.915180,-463.624939,0.091631,0.000000
87.050003,55.007607,-463.624939,-0.000509,0.003603,0.091518,244.686050,12.464902,0.915180,-463.624939,0.091631,0.000000
87.280006,54.985260,-463.669434,-0.000500,0.003603,0.091518,244.586655,12.459838,0.915180,-463.669434,0.091631,0.000000
87.510002,54.947655,-463.669434,-0.000509,0.003603,0.091518,244.419373,12.451317,0.915180,-463.669434,0.091631,0.000000
87.740005,54.940575,-463.713928,-0.000509,0.003603,0.091518,244.387878,12.449712,0.915180,-463.713928,0.091631,0.000000
87.970001,54.915627,-463.713928,-0.000500,0.003603,0.091518,244.276901,12.444058,0.915180,-463.713928,0.091631,0.000000
88.200005,54.891426,-463.713928,-0.000504,0.003603,0.091518,244.169250,12.438576,0.915180,-463.713928,0.091631,0.000000
88.430008,54.866104,-463.758392,-0.000500,0.003603,0.091518,244.056625,12.432837,0.915180,-463.758392,0.091631,0.000000
88.660004,54.831474,-463.758392,-0.000513,0.003603,0.091518,243.902573,12.424990,0.915180,-463.758392,0.091631,0.000000
88.890007,54.811363,-463.713928,-0.000530,0.003603,0.091518,243.813126,12.420432,0.915180,-463.713928,0.091631,0.000000
89.120003,54.791626,-463.758392,-0.000513,0.003603,0.091518,243.725327,12.415960,0.915180,-463.758392,0.091631,0.000000
89.350006,54.773384,-463.713928,-0.000483,0.003603,0.091518,243.644180,12.411827,0.915180,-463.713928,0.091631,0.000000
89.580002,54.744705,-463.758392,-0.000500,0.003603,0.091518,243.516617,12.405328,0.915180,-463.758392,0.091631,0.000000
89.810005,54.727577,-463.802887,-0.000504,0.003603,0.091518,243.440414,12.401446,0.915180,-463.802887,0.091631,0.000000
90.040001,54.705238,-463.802887,-0.000500,0.003603,0.091518,243.341049,12.396384,0.915180,-463.802887,0.091631,0.000000
90.270004,54.683640,-463.758392,-0.000513,0.003603,0.091518,243.244980,12.391490,0.915180,-463.758392,0.091631,0.000000
90.500008,54.668373,-463.847351,-0.000517,0.003603,0.091518,243.177063,12.388030,0.915180,-463.847351,0.091631,0.000000
90.730003,54.626663,-463.802887,-0.000509,0.003603,0.091518,242.991531,12.378579,0.915180,-463.802887,0.091631,0.000000
90.960007,54.611397,-463.891846,-0.000483,0.003603,0.091518,242.923630,12.375119,0.915180,-463.891846,0.091631,0.000000
91.190002,54.584961,-463.847351,-0.000504,0.003603,0.091518,242.806030,12.369129,0.915180,-463.847351,0.091631,0.000000
91.420006,54.573418,-463.758392,-0.000479,0.003603,0.091518,242.754684,12.366513,0.915180,-463.758392,0.091631,0.000000
91.650002,54.555168,-463.847351,-0.000530,0.003603,0.091518,242.673508,12.362377,0.915180,-463.847351,0.091631,0.000000
91.880005,54.532082,-463.891846,-0.000504,0.003603,0.091518,242.570816,12.357146,0.915180,-463.891846,0.091631,0.000000
92.110001,54.517563,-463.980804,-0.000513,0.003603,0.091518,242.506226,12.353856,0.915180,-463.980804,0.091631,0.000000
92.340004,54.487030,-463.891846,-0.000526,0.003603,0.091518,242.370407,12.346938,0.915180,-463.891846,0.091631,0.000000
92.570007,54.461334,-463.936310,-0.000513,0.003603,0.091518,242.256119,12.341115,0.915180,-463.936310,0.091631,0.000000
92.800003,54.454262,-463.936310,-0.000509,0.003603,0.091518,242.224655,12.339512,0.915180,-463.936310,0.091631,0.000000
93.030006,54.423355,-463.936310,-0.000496,0.003603,0.091518,242.087173,12.332508,0.915180,-463.936310,0.091631,0.000000
93.260002,54.407341,-464.025269,-0.000504,0.003603,0.091518,242.015945,12.328880,0.915180,-464.025269,0.091631,0.000000
93.400002,54.399895,-463.936310,-0.000487,0.003603,0.091518,241.982819,12.327192,0.915180,-463.936310,0.091631,0.000000