File: Data/compression 14/AutoNoHeating-10-14-2-240726_07262024_162047.csv
Time (sec),S:Load (lbs),S:HL1 (DIM),S:LVDT (in),S:Position (in),Ch:Position (mm),Ch:Load (N),Ch:Stress (MPa),Ch:Strain (mm/mm),Ch:HL1 (DIM),Set Point (),Cycles ()
0.110000,0.022713,-278.050415,-0.006618,-0.006506,-0.165258,0.101031,0.005147,-1.652584,-278.050415,-0.165033,0.000000
0.360000,0.009682,-278.050415,-0.006631,-0.006506,-0.165258,0.043066,0.002194,-1.652584,-278.050415,-0.165033,0.000000
0.610000,0.027557,-278.094910,-0.006622,-0.006403,-0.162639,0.122581,0.006245,-1.626392,-278.094910,-0.161685,0.000000
0.860000,0.020851,-278.139374,-0.006532,-0.006245,-0.158616,0.092750,0.004725,-1.586159,-278.139374,-0.157523,0.000000
1.110000,0.024200,-278.094910,-0.006355,-0.006085,-0.154566,0.107649,0.005484,-1.545660,-278.094910,-0.153360,0.000000
1.360000,-0.025322,-278.139374,-0.006217,-0.005916,-0.150256,-0.112638,-0.005738,-1.502558,-278.139374,-0.149198,0.000000
1.610000,-0.013779,-278.183868,-0.006045,-0.005751,-0.146067,-0.061291,-0.003122,-1.460667,-278.183868,-0.145017,0.000000
1.860000,0.051018,-278.228363,-0.005846,-0.005593,-0.142060,0.226938,0.011561,-1.420600,-278.228363,-0.140855,0.000000
2.110000,0.036491,-278.183868,-0.005652,-0.005422,-0.137707,0.162322,0.008269,-1.377066,-278.183868,-0.136692,0.000000
2.360000,0.003723,-278.228363,-0.005519,-0.005268,-0.133804,0.016561,0.000844,-1.338044,-278.228363,-0.132530,0.000000
2.610000,0.039841,-278.228363,-0.005333,-0.005101,-0.129564,0.177220,0.009028,-1.295638,-278.228363,-0.128367,0.000000
2.860000,0.059204,-278.272827,-0.005187,-0.004935,-0.125340,0.263353,0.013416,-1.253398,-278.272827,-0.124204,0.000000
3.110000,0.032768,-278.272827,-0.005019,-0.004768,-0.121108,0.145760,0.007425,-1.211083,-278.272827,-0.120042,0.000000
3.360000,0.164963,-278.361786,-0.004820,-0.004607,-0.117024,0.733791,0.037381,-1.170237,-278.361786,-0.115862,0.000000
3.610000,0.655373,-278.361786,-0.004700,-0.000000,-0.000000,2.915243,0.148510,-0.000000,-278.361786,0.000226,0.000000
3.860000,0.602127,-278.361786,-0.004674,-0.000000,-0.000000,2.678395,0.136444,-0.000000,-278.361786,0.000226,0.000000
4.110000,0.664680,-278.406281,-0.004704,-0.000000,-0.000000,2.956646,0.150619,-0.000000,-278.406281,0.000278,0.000000
4.360000,0.628189,-278.361786,-0.004708,-0.000000,-0.000000,2.794325,0.142350,-0.000000,-278.361786,0.000694,0.000000
4.610000,0.592072,-278.406281,-0.004691,-0.000000,-0.000000,2.633666,0.134165,-0.000000,-278.406281,0.001110,0.000000
4.860000,0.591324,-278.450745,-0.004661,0.000000,0.000009,2.630340,0.133996,0.000091,-278.450745,0.001527,0.000000
5.110000,1.053444,-278.406281,-0.004687,0.000045,0.001145,4.685953,0.238714,0.011446,-278.406281,0.001942,0.000000
5.360000,1.134621,-278.539703,-0.004656,0.000061,0.001553,5.047045,0.257109,0.015526,-278.539703,0.002359,0.000000
5.610000,1.234039,-278.539703,-0.004609,0.000076,0.001934,5.489281,0.279637,0.019341,-278.539703,0.002775,0.000000
5.860000,1.385223,-278.495239,-0.004613,0.000090,0.002290,6.161781,0.313896,0.022899,-278.495239,0.003191,0.000000
6.110000,1.456345,-278.495239,-0.004622,0.000102,0.002593,6.478144,0.330012,0.025934,-278.495239,0.003608,0.000000
6.360000,1.690201,-278.539703,-0.004596,0.000125,0.003166,7.518389,0.383005,0.031657,-278.539703,0.004024,0.000000
6.610000,1.835793,-278.584198,-0.004570,0.000138,0.003512,8.166013,0.415997,0.035124,-278.584198,0.004440,0.000000
6.860000,2.010063,-278.628693,-0.004544,0.000153,0.003894,8.941208,0.455487,0.038939,-278.628693,0.004857,0.000000
7.110000,2.147469,-278.628693,-0.004553,0.000167,0.004232,9.552417,0.486623,0.042323,-278.628693,0.005281,0.000000
7.360000,2.431221,-278.717651,-0.004501,0.000190,0.004814,10.814611,0.550923,0.048136,-278.717651,0.005698,0.000000
7.610000,2.581657,-278.673157,-0.004527,0.000208,0.005291,11.483786,0.585012,0.052905,-278.673157,0.006114,0.000000
7.860001,2.713852,-278.717651,-0.004510,0.000222,0.005628,12.071816,0.614968,0.056281,-278.717651,0.006530,0.000000
8.110001,2.903763,-278.673157,-0.004501,0.000238,0.006054,12.916582,0.658002,0.060536,-278.673157,0.006947,0.000000
8.360001,3.054939,-278.717651,-0.004471,0.000253,0.006435,13.589048,0.692259,0.064351,-278.717651,0.007363,0.000000
8.610001,3.290657,-278.762115,-0.004449,0.000270,0.006860,14.637573,0.745674,0.068597,-278.762115,0.007779,0.000000
8.860001,3.406464,-278.762115,-0.004449,0.000285,0.007241,15.152707,0.771916,0.072413,-278.762115,0.008196,0.000000
9.110001,3.556526,-278.806610,-0.004432,0.000298,0.007562,15.820219,0.805920,0.075622,-278.806610,0.008611,0.000000
9.360001,3.930016,-278.851074,-0.004411,0.000322,0.008187,17.481583,0.890554,0.081867,-278.851074,0.009028,0.000000
9.610001,3.988853,-278.851074,-0.004389,0.000337,0.008551,17.743307,0.903887,0.085508,-278.851074,0.009444,0.000000
9.860001,4.087158,-278.895569,-0.004381,0.000350,0.008889,18.180588,0.926163,0.088892,-278.895569,0.009860,0.000000
10.110001,4.370537,-278.940033,-0.004389,0.000368,0.009358,19.441118,0.990378,0.093578,-278.940033,0.010277,0.000000
10.360001,4.555977,-278.940033,-0.004355,0.000385,0.009791,20.265997,1.032399,0.097908,-278.940033,0.010693,0.000000
10.610001,4.685562,-278.895569,-0.004350,0.000402,0.010207,20.842421,1.061764,0.102071,-278.895569,0.011109,0.000000
10.860001,4.715721,-278.984528,-0.004316,0.000413,0.010485,20.976576,1.068598,0.104849,-278.984528,0.011526,0.000000
11.110001,4.936913,-278.984528,-0.004316,0.000427,0.010841,21.960484,1.118720,0.108407,-278.984528,0.011942,0.000000
11.360001,5.399399,-278.940033,-0.004290,0.000454,0.011534,24.017725,1.223521,0.115341,-278.940033,0.012358,0.000000
11.610001,5.323433,-279.073486,-0.004290,0.000467,0.011855,23.679811,1.206307,0.118550,-279.073486,0.012774,0.000000
11.860001,5.425468,-279.073486,-0.004251,0.000480,0.012184,24.133690,1.229429,0.121843,-279.073486,0.013190,0.000000
12.110001,5.697296,-279.028992,-0.004225,0.000498,0.012653,25.342838,1.291026,0.126529,-279.028992,0.013616,0.000000
12.360001,5.997803,-279.117981,-0.004221,0.000520,0.013208,26.679560,1.359122,0.132078,-279.117981,0.014032,0.000000
12.610001,6.028709,-279.117981,-0.004212,0.000533,0.013546,26.817039,1.366125,0.135461,-279.117981,0.014448,0.000000
12.860001,5.988495,-279.117981,-0.004212,0.000541,0.013737,26.638155,1.357012,0.137369,-279.117981,0.014864,0.000000
13.110001,6.428635,-279.117981,-0.004212,0.000564,0.014318,28.595995,1.456749,0.143183,-279.117981,0.015280,0.000000
13.360001,6.694138,-279.162445,-0.004169,0.000586,0.014873,29.777012,1.516913,0.148731,-279.162445,0.015697,0.000000
13.610001,6.690788,-279.206940,-0.004139,0.000600,0.015237,29.762114,1.516154,0.152372,-279.206940,0.016113,0.000000
13.860001,6.699348,-279.251404,-0.004122,0.000612,0.015550,29.800190,1.518094,0.155499,-279.251404,0.016529,0.000000
14.110001,6.900063,-279.251404,-0.004139,0.000629,0.015983,30.693010,1.563577,0.159829,-279.251404,0.016946,0.000000
14.360001,7.186417,-279.251404,-0.004105,0.000649,0.016477,31.966778,1.628465,0.164772,-279.251404,0.017362,0.000000
14.610001,7.263123,-279.206940,-0.004118,0.000662,0.016816,32.307983,1.645847,0.168155,-279.206940,0.017778,0.000000
14.860001,7.158859,-279.340363,-0.004087,0.000672,0.017059,31.844196,1.622221,0.170585,-279.340363,0.018195,0.000000
15.110001,7.352119,-279.340363,-0.004070,0.000685,0.017388,32.703861,1.666014,0.173878,-279.340363,0.018611,0.000000
15.360001,7.905838,-279.295898,-0.004040,0.000716,0.018177,35.166924,1.791489,0.181773,-279.295898,0.019027,0.000000
15.610001,7.773277,-279.340363,-0.004036,0.000727,0.018454,34.577263,1.761450,0.184544,-279.340363,0.019443,0.000000
15.860001,7.902115,-279.340363,-0.004036,0.000745,0.018923,35.150364,1.790645,0.189230,-279.340363,0.019859,0.000000
16.110001,8.013451,-279.340363,-0.004010,0.000759,0.019279,35.645607,1.815874,0.192787,-279.340363,0.020276,0.000000
16.360001,8.230179,-279.384857,-0.003997,0.000778,0.019756,36.609665,1.864985,0.197556,-279.384857,0.020692,0.000000
16.610001,8.312843,-279.429321,-0.003971,0.000793,0.020145,36.977375,1.883717,0.201455,-279.429321,0.021108,0.000000
16.860001,8.299065,-279.473816,-0.003962,0.000802,0.020363,36.916084,1.880595,0.203627,-279.473816,0.021525,0.000000
17.110001,8.789482,-279.429321,-0.003954,0.000827,0.021005,39.097569,1.991725,0.210047,-279.429321,0.021941,0.000000
17.360001,8.896347,-279.473816,-0.003911,0.000844,0.021438,39.572929,2.015941,0.214376,-279.473816,0.022366,0.000000
17.610001,8.815918,-279.473816,-0.003906,0.000857,0.021776,39.215160,1.997716,0.217760,-279.473816,0.022782,0.000000
17.860001,9.021835,-279.562775,-0.003885,0.000877,0.022279,40.131126,2.044377,0.222794,-279.562775,0.023198,0.000000
18.110001,9.207649,-279.562775,-0.003876,0.000895,0.022739,40.957668,2.086483,0.227389,-279.562775,0.023615,0.000000
18.360001,9.225525,-279.518311,-0.003863,0.000911,0.023138,41.037186,2.090534,0.231378,-279.518311,0.024031,0.000000
18.610001,9.146957,-279.651733,-0.003820,0.000923,0.023450,40.687698,2.072730,0.234497,-279.651733,0.024447,0.000000
18.860001,9.480972,-279.607269,-0.003833,0.000939,0.023849,42.173470,2.148419,0.238486,-279.607269,0.024864,0.000000
19.110001,9.709610,-279.607269,-0.003803,0.000961,0.024404,43.190502,2.200229,0.244042,-279.607269,0.025280,0.000000
19.360001,9.719292,-279.651733,-0.003777,0.000976,0.024786,43.233570,2.202423,0.247858,-279.651733,0.025696,0.000000
19.610001,9.767700,-279.696228,-0.003803,0.000992,0.025185,43.448902,2.213392,0.251847,-279.696228,0.026112,0.000000
19.860001,9.941971,-279.696228,-0.003786,0.001008,0.025609,44.224094,2.252883,0.256094,-279.696228,0.026528,0.000000
20.110001,9.980324,-279.696228,-0.003742,0.001024,0.026000,44.394699,2.261574,0.260000,-279.696228,0.026945,0.000000
20.360001,10.151619,-279.740692,-0.003708,0.001041,0.026442,45.156658,2.300390,0.264420,-279.740692,0.027361,0.000000
20.610001,10.050331,-279.696228,-0.003712,0.001049,0.026650,44.706104,2.277438,0.266502,-279.696228,0.027777,0.000000
20.860001,10.369827,-279.740692,-0.003691,0.001071,0.027196,46.127296,2.349837,0.271960,-279.740692,0.028194,0.000000
21.110001,10.692299,-279.829651,-0.003708,0.001091,0.027717,47.561722,2.422910,0.277168,-279.829651,0.028610,0.000000
21.360001,10.786140,-279.829651,-0.003678,0.001109,0.028176,47.979149,2.444175,0.281763,-279.829651,0.029026,0.000000
21.610001,10.700119,-279.918640,-0.003652,0.001122,0.028497,47.596508,2.424681,0.284972,-279.918640,0.029443,0.000000
21.860001,10.778320,-279.874146,-0.003643,0.001137,0.028879,47.944363,2.442402,0.288787,-279.874146,0.029859,0.000000
22.110001,11.082176,-279.829651,-0.003596,0.001155,0.029338,49.295982,2.511257,0.293382,-279.829651,0.030275,0.000000
22.360001,11.097816,-279.918640,-0.003579,0.001169,0.029685,49.365555,2.514801,0.296849,-279.918640,0.030700,0.000000
22.610001,11.164467,-279.918640,-0.003583,0.001182,0.030032,49.662029,2.529904,0.300324,-279.918640,0.031116,0.000000
22.860001,11.529770,-279.918640,-0.003553,0.001205,0.030613,51.286980,2.612683,0.306130,-279.918640,0.031533,0.000000
23.110001,11.796387,-279.963104,-0.003540,0.001226,0.031151,52.472950,2.673100,0.311512,-279.963104,0.031949,0.000000
23.360001,11.600517,-279.963104,-0.003527,0.001238,0.031455,51.601677,2.628715,0.314547,-279.963104,0.032365,0.000000
23.610001,11.595680,-280.007599,-0.003510,0.001253,0.031827,51.580162,2.627619,0.318272,-280.007599,0.032781,0.000000
23.860001,11.820587,-280.007599,-0.003505,0.001270,0.032253,52.580597,2.678583,0.322526,-280.007599,0.033197,0.000000
24.110001,12.178810,-280.052063,-0.003497,0.001291,0.032790,54.174053,2.759758,0.327901,-280.052063,0.033614,0.000000
24.360001,12.156097,-280.052063,-0.003449,0.001303,0.033094,54.073021,2.754611,0.330936,-280.052063,0.034030,0.000000
24.610001,12.163918,-280.096558,-0.003441,0.001318,0.033483,54.107807,2.756383,0.334835,-280.096558,0.034446,0.000000
24.860001,12.720985,-280.141022,-0.003402,0.001344,0.034125,56.585770,2.882616,0.341254,-280.141022,0.034863,0.000000
25.110001,12.583580,-280.096558,-0.003406,0.001357,0.034472,55.974560,2.851480,0.344721,-280.096558,0.035279,0.000000
25.360001,12.509850,-280.141022,-0.003393,0.001369,0.034785,55.646591,2.834773,0.347847,-280.141022,0.035695,0.000000
25.610001,12.477829,-280.141022,-0.003372,0.001383,0.035131,55.504154,2.827517,0.351314,-280.141022,0.036112,0.000000
25.860001,12.964149,-280.229980,-0.003385,0.001404,0.035651,57.667416,2.937718,0.356514,-280.229980,0.036528,0.000000
26.110001,13.179008,-280.185516,-0.003346,0.001420,0.036068,58.623158,2.986406,0.360678,-280.185516,0.036944,0.000000
26.360001,12.985741,-280.229980,-0.003328,0.001431,0.036337,57.763458,2.942611,0.363373,-280.229980,0.037360,0.000000
26.610001,13.133575,-280.274475,-0.003316,0.001446,0.036727,58.421062,2.976111,0.367271,-280.274475,0.037776,0.000000
26.860001,13.651917,-280.318939,-0.003303,0.001471,0.037352,60.726757,3.093569,0.373516,-280.318939,0.038193,0.000000
27.110001,13.494774,-280.318939,-0.003260,0.001484,0.037690,60.027752,3.057959,0.376900,-280.318939,0.038609,0.000000
27.360001,13.387535,-280.318939,-0.003264,0.001498,0.038037,59.550732,3.033659,0.380367,-280.318939,0.039034,0.000000
27.610001,13.761398,-280.318939,-0.003260,0.001518,0.038548,61.213757,3.118377,0.385484,-280.318939,0.039450,0.000000
27.860001,13.900291,-280.318939,-0.003208,0.001534,0.038973,61.831585,3.149851,0.389731,-280.318939,0.039866,0.000000
28.110001,13.866776,-280.363434,-0.003238,0.001549,0.039355,61.682499,3.142256,0.393546,-280.363434,0.040283,0.000000
28.360001,13.896942,-280.363434,-0.003191,0.001562,0.039667,61.816685,3.149092,0.396672,-280.363434,0.040699,0.000000
28.610001,13.969925,-280.496887,-0.003169,0.001578,0.040074,62.141331,3.165630,0.400745,-280.496887,0.041115,0.000000
28.860001,14.631256,-280.407928,-0.003139,0.001604,0.040742,65.083076,3.315490,0.407421,-280.407928,0.041532,0.000000
29.110001,14.511726,-280.452393,-0.003156,0.001619,0.041133,64.551384,3.288404,0.411327,-280.452393,0.041948,0.000000
29.360001,14.234680,-280.496887,-0.003117,0.001630,0.041401,63.319019,3.225625,0.414015,-280.496887,0.042364,0.000000
29.610001,14.483055,-280.541351,-0.003109,0.001648,0.041853,64.423843,3.281907,0.418526,-280.541351,0.042781,0.000000
29.860001,14.717278,-280.496887,-0.003109,0.001665,0.042295,65.465721,3.334983,0.422947,-280.496887,0.043197,0.000000
30.110001,14.786537,-280.541351,-0.003061,0.001681,0.042685,65.773804,3.350677,0.426853,-280.541351,0.043613,0.000000
30.360001,14.751160,-280.585846,-0.003065,0.001693,0.043006,65.616432,3.342661,0.430062,-280.585846,0.044029,0.000000
30.610001,15.226685,-280.585846,-0.003040,0.001716,0.043587,67.731674,3.450416,0.435869,-280.585846,0.044445,0.000000
30.860001,15.331322,-280.630310,-0.003018,0.001733,0.044029,68.197128,3.474127,0.440289,-280.630310,0.044862,0.000000
31.110001,15.163376,-280.630310,-0.003018,0.001746,0.044342,67.450066,3.436070,0.443416,-280.630310,0.045278,0.000000
31.360001,15.158913,-280.674805,-0.002992,0.001762,0.044766,67.430214,3.435059,0.447662,-280.674805,0.045694,0.000000
31.610001,15.447495,-280.719269,-0.002979,0.001780,0.045200,68.713890,3.500452,0.452000,-280.719269,0.046111,0.000000
31.860001,15.661987,-280.674805,-0.002953,0.001798,0.045677,69.667999,3.549057,0.456769,-280.674805,0.046527,0.000000
32.110001,15.497398,-280.719269,-0.002923,0.001811,0.045990,68.935867,3.511761,0.459895,-280.719269,0.046943,0.000000
32.360001,15.464996,-280.763763,-0.002928,0.001824,0.046327,68.791740,3.504418,0.463271,-280.763763,0.047360,0.000000
32.610001,16.129311,-280.763763,-0.002915,0.001850,0.046978,71.746758,3.654954,0.469781,-280.763763,0.047784,0.000000
32.860001,15.937164,-280.763763,-0.002897,0.001862,0.047307,70.892044,3.611413,0.473074,-280.763763,0.048201,0.000000
33.110001,15.845566,-280.763763,-0.002867,0.001877,0.047672,70.484596,3.590657,0.476715,-280.763763,0.048617,0.000000
33.360001,15.980736,-280.808258,-0.002846,0.001894,0.048114,71.085861,3.621286,0.481136,-280.808258,0.049033,0.000000
33.610001,16.113297,-280.808258,-0.002859,0.001911,0.048547,71.675522,3.651325,0.485473,-280.808258,0.049450,0.000000
33.860001,16.283104,-280.897217,-0.002820,0.001929,0.048998,72.430862,3.689804,0.489985,-280.897217,0.049866,0.000000
34.110001,15.888756,-280.808258,-0.002807,0.001939,0.049241,70.676712,3.600444,0.492415,-280.808258,0.050282,0.000000
34.360001,16.018715,-280.852722,-0.002785,0.001956,0.049684,71.254799,3.629893,0.496836,-280.852722,0.050698,0.000000
34.610001,16.743355,-280.897217,-0.002764,0.001980,0.050299,74.478165,3.794099,0.502990,-280.897217,0.051114,0.000000
34.860001,16.550835,-280.897217,-0.002742,0.001995,0.050672,73.621788,3.750473,0.506722,-280.897217,0.051531,0.000000
35.110001,16.239906,-280.986176,-0.002751,0.002006,0.050958,72.238708,3.680015,0.509583,-280.986176,0.051947,0.000000
35.360001,16.195595,-280.986176,-0.002721,0.002020,0.051297,72.041603,3.669974,0.512967,-280.986176,0.052363,0.000000
35.610001,16.703514,-281.030640,-0.002695,0.002041,0.051852,74.300941,3.785070,0.518515,-281.030640,0.052780,0.000000
35.860001,16.707237,-281.075134,-0.002673,0.002058,0.052268,74.317505,3.785914,0.522679,-281.075134,0.053196,0.000000
36.110001,16.449554,-280.986176,-0.002686,0.002068,0.052528,73.171272,3.727522,0.525283,-280.986176,0.053612,0.000000
36.360001,16.514343,-281.030640,-0.002669,0.002081,0.052866,73.459465,3.742204,0.528659,-281.030640,0.054029,0.000000
36.610001,17.409531,-281.075134,-0.002626,0.002111,0.053630,77.441460,3.945056,0.536297,-281.075134,0.054445,0.000000
36.860001,16.919861,-281.075134,-0.002647,0.002123,0.053916,75.263298,3.834095,0.539158,-281.075134,0.054861,0.000000
37.110001,16.951141,-281.119598,-0.002621,0.002140,0.054358,75.402443,3.841184,0.543579,-281.119598,0.055277,0.000000
37.360001,16.752289,-281.164093,-0.002596,0.002153,0.054687,74.517899,3.796123,0.546872,-281.164093,0.055693,0.000000
37.610001,16.871452,-281.119598,-0.002574,0.002169,0.055086,75.047966,3.823126,0.550861,-281.119598,0.056119,0.000000
37.860001,16.595520,-281.208588,-0.002570,0.002178,0.055329,73.820557,3.760598,0.553291,-281.208588,0.056535,0.000000
38.110001,16.953369,-281.164093,-0.002578,0.002197,0.055815,75.412354,3.841688,0.558151,-281.164093,0.056951,0.000000
38.360001,16.238045,-281.208588,-0.002535,0.002197,0.055815,72.230431,3.679594,0.558151,-281.208588,0.057367,0.000000
38.610001,17.942764,-281.297546,-0.002522,0.002240,0.056907,79.813400,4.065888,0.569074,-281.297546,0.057783,0.000000
38.860001,17.448997,-281.253052,-0.002531,0.002254,0.057246,77.617020,3.953999,0.572458,-281.253052,0.058200,0.000000
39.110001,17.360748,-281.297546,-0.002492,0.002271,0.057688,77.224464,3.934002,0.576879,-281.297546,0.058616,0.000000
39.360001,17.387558,-281.342010,-0.002479,0.002289,0.058130,77.343719,3.940077,0.581299,-281.342010,0.059032,0.000000
39.610001,17.401337,-281.297546,-0.002496,0.002304,0.058512,77.405014,3.943199,0.585122,-281.297546,0.059449,0.000000
39.860001,17.066574,-281.342010,-0.002449,0.002314,0.058781,75.915916,3.867341,0.587809,-281.342010,0.059865,0.000000
40.110001,17.598694,-281.342010,-0.002432,0.002337,0.059353,78.282898,3.987921,0.593532,-281.342010,0.060281,0.000000
40.360001,17.686943,-281.342010,-0.002453,0.002353,0.059778,78.675453,4.007919,0.597779,-281.342010,0.060698,0.000000
40.610001,17.761795,-281.430969,-0.002406,0.002372,0.060255,79.008408,4.024880,0.602548,-281.430969,0.061113,0.000000
40.860001,17.464638,-281.430969,-0.002406,0.002386,0.060611,77.686592,3.957544,0.606106,-281.430969,0.061530,0.000000
41.110001,17.641518,-281.475464,-0.002410,0.002405,0.061087,78.473389,3.997625,0.610874,-281.475464,0.061946,0.000000
41.360001,17.694763,-281.475464,-0.002380,0.002420,0.061469,78.710236,4.009691,0.614690,-281.475464,0.062362,0.000000
41.610001,17.535019,-281.475464,-0.002354,0.002433,0.061807,77.999657,3.973492,0.618073,-281.475464,0.062779,0.000000
41.860001,17.514908,-281.519928,-0.002341,0.002447,0.062146,77.910202,3.968935,0.621457,-281.519928,0.063195,0.000000
42.110001,17.890633,-281.519928,-0.002315,0.002465,0.062605,79.581505,4.054075,0.626052,-281.519928,0.063611,0.000000
42.360001,18.241409,-281.519928,-0.002328,0.002488,0.063203,81.141838,4.133563,0.632032,-281.519928,0.064028,0.000000
42.610001,18.057831,-281.608887,-0.002302,0.002503,0.063576,80.325241,4.091963,0.635764,-281.608887,0.064452,0.000000
42.860001,17.982613,-281.564423,-0.002289,0.002518,0.063958,79.990654,4.074918,0.639579,-281.564423,0.064869,0.000000
43.110001,17.874619,-281.608887,-0.002272,0.002532,0.064322,79.510277,4.050447,0.643220,-281.608887,0.065285,0.000000
43.360001,18.292053,-281.608887,-0.002281,0.002551,0.064808,81.367119,4.145038,0.648080,-281.608887,0.065701,0.000000
43.610001,18.216461,-281.653381,-0.002246,0.002566,0.065164,81.030869,4.127909,0.651638,-281.653381,0.066118,0.000000
43.860001,18.088737,-281.697876,-0.002242,0.002578,0.065493,80.462723,4.098967,0.654931,-281.697876,0.066534,0.000000
44.110001,18.543777,-281.653381,-0.002233,0.002598,0.065979,82.486839,4.202080,0.659790,-281.653381,0.066950,0.000000
44.360001,19.041634,-281.697876,-0.002216,0.002620,0.066560,84.701416,4.314896,0.665596,-281.697876,0.067367,0.000000
44.610001,18.845398,-281.697876,-0.002177,0.002634,0.066915,83.828514,4.270428,0.669154,-281.697876,0.067782,0.000000
44.860001,18.532974,-281.831299,-0.002203,0.002646,0.067219,82.438789,4.199632,0.672190,-281.831299,0.068199,0.000000
45.110001,18.537819,-281.831299,-0.002186,0.002663,0.067644,82.460335,4.200730,0.676436,-281.831299,0.068615,0.000000
45.360001,18.909447,-281.786835,-0.002182,0.002680,0.068077,84.113419,4.284942,0.680774,-281.786835,0.069031,0.000000
45.610001,19.155586,-281.786835,-0.002151,0.002698,0.068537,85.208305,4.340718,0.685369,-281.786835,0.069448,0.000000
45.860001,18.683044,-281.875793,-0.002139,0.002708,0.068771,83.106331,4.233638,0.687708,-281.875793,0.069864,0.000000
46.110001,19.867187,-281.875793,-0.002130,0.002737,0.069517,88.373665,4.501969,0.695172,-281.875793,0.070280,0.000000
46.360001,19.680626,-281.875793,-0.002095,0.002752,0.069899,87.543793,4.459693,0.698987,-281.875793,0.070697,0.000000
46.610001,19.497047,-281.875793,-0.002104,0.002766,0.070245,86.727196,4.418094,0.702454,-281.875793,0.071113,0.000000
46.860001,19.392036,-281.875793,-0.002095,0.002779,0.070575,86.260086,4.394298,0.705747,-281.875793,0.071529,0.000000
47.110001,19.313843,-281.964752,-0.002082,0.002793,0.070948,85.912262,4.376579,0.709479,-281.964752,0.071946,0.000000
47.360001,20.140884,-281.920258,-0.002065,0.002815,0.071503,89.591125,4.563990,0.715027,-281.920258,0.072361,0.000000
47.610001,19.760689,-281.920258,-0.002065,0.002825,0.071754,87.899933,4.477836,0.717540,-281.920258,0.072777,0.000000
47.860001,19.549553,-282.053711,-0.002009,0.002837,0.072058,86.960754,4.429992,0.720576,-282.053711,0.073203,0.000000
48.110001,20.795509,-282.009216,-0.002009,0.002865,0.072760,92.503044,4.712330,0.727601,-282.009216,0.073619,0.000000
48.360001,20.511765,-282.009216,-0.001992,0.002879,0.073116,91.240883,4.648032,0.731158,-282.009216,0.074036,0.000000
48.610001,20.418297,-282.053711,-0.001957,0.002892,0.073463,90.825119,4.626852,0.734625,-282.053711,0.074451,0.000000
48.860001,20.794395,-282.053711,-0.001962,0.002912,0.073957,92.498093,4.712077,0.739568,-282.053711,0.074867,0.000000
49.110001,20.904617,-282.098206,-0.001932,0.002928,0.074382,92.988380,4.737054,0.743823,-282.098206,0.075284,0.000000
49.360001,20.813385,-282.098206,-0.001927,0.002942,0.074738,92.582558,4.716381,0.747380,-282.098206,0.075700,0.000000
49.610001,20.839081,-282.142670,-0.001927,0.002956,0.075093,92.696861,4.722203,0.750931,-282.142670,0.076117,0.000000
49.860001,20.683426,-282.187164,-0.001910,0.002967,0.075371,92.004471,4.686931,0.753709,-282.187164,0.076533,0.000000
50.110001,21.860497,-282.098206,-0.001863,0.002997,0.076134,97.240349,4.953660,0.761339,-282.098206,0.076949,0.000000
50.360001,21.701118,-282.187164,-0.001837,0.003014,0.076550,96.531395,4.917544,0.765503,-282.187164,0.077366,0.000000
50.610001,21.244965,-282.187164,-0.001828,0.003023,0.076793,94.502319,4.814178,0.767932,-282.187164,0.077782,0.000000
50.860001,21.543236,-282.276123,-0.001832,0.003042,0.077278,95.829102,4.881767,0.772785,-282.276123,0.078198,0.000000
51.110001,21.414024,-282.231628,-0.001824,0.003054,0.077574,95.254341,4.852487,0.775737,-282.231628,0.078615,0.000000
51.360001,21.834427,-282.276123,-0.001798,0.003074,0.078076,97.124382,4.947752,0.780763,-282.276123,0.079030,0.000000
51.610001,21.856026,-282.231628,-0.001768,0.003088,0.078440,97.220459,4.952646,0.784404,-282.231628,0.079446,0.000000
51.860001,22.006836,-282.276123,-0.001772,0.003105,0.078874,97.891296,4.986820,0.788742,-282.276123,0.079863,0.000000
52.110001,22.692749,-282.320587,-0.001738,0.003127,0.079429,100.942390,5.142250,0.794290,-282.320587,0.080279,0.000000
52.360001,22.294312,-282.365082,-0.001733,0.003138,0.079707,99.170052,5.051963,0.797069,-282.365082,0.080695,0.000000
52.610001,22.166962,-282.409546,-0.001720,0.003153,0.080080,98.603569,5.023105,0.800801,-282.409546,0.081112,0.000000
52.860001,22.756798,-282.409546,-0.001690,0.003173,0.080583,101.227295,5.156764,0.805827,-282.409546,0.081536,0.000000
53.110004,23.110924,-282.409546,-0.001660,0.003192,0.081077,102.802521,5.237010,0.810770,-282.409546,0.081953,0.000000
53.360004,23.069962,-282.409546,-0.001647,0.003206,0.081441,102.620316,5.227728,0.814411,-282.409546,0.082369,0.000000
53.610004,22.789940,-282.498535,-0.001647,0.003217,0.081701,101.374718,5.164274,0.817015,-282.498535,0.082785,0.000000
53.860004,23.618469,-282.498535,-0.001617,0.003241,0.082317,105.060196,5.352021,0.823169,-282.498535,0.083202,0.000000
54.110004,23.802048,-282.587494,-0.001613,0.003258,0.082760,105.876793,5.393621,0.827598,-282.587494,0.083618,0.000000
54.360004,23.726082,-282.542999,-0.001556,0.003274,0.083150,105.538879,5.376407,0.831496,-282.542999,0.084035,0.000000
54.610004,23.732040,-282.542999,-0.001574,0.003287,0.083488,105.565392,5.377758,0.834880,-282.542999,0.084451,0.000000
54.860004,23.755875,-282.587494,-0.001531,0.003302,0.083869,105.671410,5.383158,0.838695,-282.587494,0.084867,0.000000
55.110004,24.505829,-282.631958,-0.001544,0.003324,0.084424,109.007370,5.553100,0.844244,-282.631958,0.085283,0.000000
55.360004,24.177025,-282.587494,-0.001513,0.003333,0.084659,107.544777,5.478592,0.846590,-282.587494,0.085699,0.000000
55.610004,24.185966,-282.631958,-0.001496,0.003346,0.084997,107.584549,5.480618,0.849966,-282.631958,0.086115,0.000000
55.860004,25.312759,-282.676453,-0.001483,0.003373,0.085665,112.596779,5.735953,0.856650,-282.676453,0.086532,0.000000
56.110004,25.508629,-282.676453,-0.001466,0.003389,0.086081,113.468048,5.780338,0.860806,-282.676453,0.086948,0.000000
56.360004,25.375694,-282.720917,-0.001444,0.003402,0.086419,112.876724,5.750215,0.864190,-282.720917,0.087364,0.000000
56.610004,25.357445,-282.720917,-0.001453,0.003416,0.086766,112.795547,5.746079,0.867664,-282.720917,0.087781,0.000000
56.860004,26.124161,-282.765411,-0.001431,0.003438,0.087330,116.206070,5.919819,0.873296,-282.765411,0.088197,0.000000
57.110004,26.286888,-282.765411,-0.001410,0.003450,0.087642,116.929916,5.956694,0.876423,-282.765411,0.088613,0.000000
57.360004,26.225822,-282.809875,-0.001358,0.003464,0.087989,116.658287,5.942856,0.879890,-282.809875,0.089030,0.000000
57.610004,26.418335,-282.854370,-0.001375,0.003476,0.088301,117.514626,5.986480,0.883008,-282.854370,0.089446,0.000000
57.860004,27.763718,-282.854370,-0.001371,0.003504,0.088995,123.499184,6.291348,0.889950,-282.854370,0.089871,0.000000
58.110004,27.829628,-282.854370,-0.001306,0.003517,0.089333,123.792366,6.306284,0.893334,-282.854370,0.090287,0.000000
58.360004,27.916389,-282.898834,-0.001341,0.003533,0.089750,124.178299,6.325944,0.897497,-282.898834,0.090703,0.000000
58.610004,28.494308,-282.898834,-0.001302,0.003550,0.090174,126.749016,6.456903,0.901744,-282.898834,0.091120,0.000000
58.860004,28.714386,-282.943329,-0.001281,0.003567,0.090608,127.727966,6.506773,0.906081,-282.943329,0.091536,0.000000
59.110004,28.848808,-282.898834,-0.001255,0.003578,0.090885,128.325912,6.537233,0.908852,-282.898834,0.091952,0.000000
59.360004,29.141495,-282.943329,-0.001268,0.003591,0.091224,129.627838,6.603557,0.912235,-282.943329,0.092368,0.000000
59.610004,29.615524,-283.032288,-0.001242,0.003608,0.091648,131.736435,6.710974,0.916482,-283.032288,0.092784,0.000000
59.860004,30.470123,-283.076782,-0.001220,0.003628,0.092160,135.537872,6.904629,0.921599,-283.076782,0.093201,0.000000
60.110004,31.040222,-283.076782,-0.001177,0.003647,0.092638,138.073807,7.033814,0.926376,-283.076782,0.093617,0.000000
60.360004,31.707886,-282.987823,-0.001220,0.003667,0.093132,141.043716,7.185110,0.931319,-282.987823,0.094033,0.000000
60.610004,31.895561,-283.076782,-0.001207,0.003679,0.093452,141.878540,7.227637,0.934521,-283.076782,0.094450,0.000000
60.860004,32.696907,-283.076782,-0.001168,0.003700,0.093990,145.443100,7.409225,0.939903,-283.076782,0.094866,0.000000
61.110004,32.952728,-283.121246,-0.001168,0.003713,0.094302,146.581055,7.467195,0.943022,-283.121246,0.095282,0.000000
61.360004,33.109871,-283.121246,-0.001138,0.003724,0.094597,147.280060,7.502804,0.945974,-283.121246,0.095699,0.000000
61.610004,34.386734,-283.121246,-0.001121,0.003749,0.095230,152.959839,7.792145,0.952302,-283.121246,0.096115,0.000000
61.860004,35.227180,-283.165741,-0.001108,0.003768,0.095716,156.698318,7.982593,0.957162,-283.165741,0.096531,0.000000
62.110004,35.397728,-283.210205,-0.001087,0.003781,0.096028,157.456955,8.021239,0.960281,-283.210205,0.096947,0.000000
62.360004,35.958893,-283.254700,-0.001099,0.003796,0.096427,159.953140,8.148401,0.964270,-283.254700,0.097363,0.000000
62.610004,36.616501,-283.210205,-0.001099,0.003814,0.096886,162.878326,8.297418,0.968865,-283.210205,0.097780,0.000000
62.860004,37.291985,-283.299164,-0.001052,0.003830,0.097277,165.883026,8.450484,0.972771,-283.299164,0.098196,0.000000
63.110004,37.650208,-283.254700,-0.001056,0.003843,0.097624,167.476486,8.531659,0.976238,-283.254700,0.098621,0.000000
63.360004,37.709412,-283.432617,-0.001048,0.003851,0.097815,167.739838,8.545074,0.978146,-283.432617,0.099037,0.000000
63.610004,39.798050,-283.299164,-0.001030,0.003881,0.098587,177.030563,9.018367,0.985867,-283.299164,0.099453,0.000000
63.860004,40.473907,-283.343658,-0.001018,0.003897,0.098994,180.036926,9.171519,0.989939,-283.343658,0.099870,0.000000
64.110001,41.110664,-283.388153,-0.000992,0.003912,0.099375,182.869370,9.315809,0.993754,-283.388153,0.100286,0.000000
64.360001,41.405952,-283.343658,-0.000992,0.003925,0.099705,184.182877,9.382723,0.997047,-283.343658,0.100702,0.000000
64.610001,42.004730,-283.343658,-0.001005,0.003941,0.100113,186.846375,9.518408,1.001127,-283.343658,0.101119,0.000000
64.860001,43.171371,-283.432617,-0.000953,0.003959,0.100555,192.035858,9.782773,1.005548,-283.432617,0.101535,0.000000
65.110001,43.769028,-283.432617,-0.000987,0.003972,0.100885,194.694366,9.918204,1.008849,-283.432617,0.101951,0.000000
65.360001,44.816887,-283.432617,-0.000949,0.003990,0.101344,199.355469,10.155651,1.013443,-283.432617,0.102368,0.000000
65.610001,46.004013,-283.477112,-0.000957,0.004011,0.101873,204.636078,10.424659,1.018735,-283.477112,0.102784,0.000000
65.860001,47.149429,-283.477112,-0.000931,0.004029,0.102333,209.731140,10.684213,1.023330,-283.477112,0.103200,0.000000
66.110001,47.440994,-283.521576,-0.000914,0.004039,0.102593,211.028076,10.750283,1.025926,-283.521576,0.103616,0.000000
66.360001,48.334686,-283.566071,-0.000927,0.004056,0.103018,215.003418,10.952796,1.030180,-283.566071,0.104032,0.000000
66.610001,49.360573,-283.521576,-0.000880,0.004073,0.103443,219.566788,11.185266,1.034427,-283.521576,0.104449,0.000000
66.860001,50.739845,-283.610535,-0.000897,0.004095,0.104015,225.702103,11.497813,1.040150,-283.610535,0.104865,0.000000
67.110001,50.885437,-283.610535,-0.000888,0.004101,0.104172,226.349731,11.530805,1.041717,-283.610535,0.105281,0.000000
67.360001,52.598351,-283.610535,-0.000875,0.004129,0.104865,233.969147,11.918957,1.048651,-283.610535,0.105698,0.000000
67.610001,53.831276,-283.655029,-0.000880,0.004145,0.105281,239.453476,12.198341,1.052814,-283.655029,0.106114,0.000000
67.860001,54.599854,-283.655029,-0.000845,0.004160,0.105655,242.872284,12.372503,1.056546,-283.655029,0.106530,0.000000
68.110001,55.035904,-283.655029,-0.000845,0.004170,0.105906,244.811920,12.471313,1.059059,-283.655029,0.106955,0.000000
68.360001,55.942635,-283.699493,-0.000875,0.004188,0.106365,248.845261,12.676782,1.063654,-283.699493,0.107371,0.000000
68.610001,57.599319,-283.699493,-0.000854,0.004209,0.106903,256.214569,13.052193,1.069028,-283.699493,0.107788,0.000000
68.860001,58.364914,-283.788483,-0.000815,0.004221,0.107206,259.620117,13.225678,1.072064,-283.788483,0.108204,0.000000
69.110001,58.742126,-283.832947,-0.000858,0.004229,0.107406,261.298035,13.311156,1.074062,-283.832947,0.108620,0.000000
69.360001,61.030731,-283.788483,-0.000798,0.004260,0.108195,271.478241,13.829762,1.081950,-283.788483,0.109037,0.000000
69.610001,62.106514,-283.832947,-0.000819,0.004273,0.108533,276.263580,14.073538,1.085334,-283.832947,0.109452,0.000000
69.860001,63.006538,-283.877441,-0.000802,0.004287,0.108889,280.267090,14.277486,1.088892,-283.877441,0.109869,0.000000
70.110001,63.721115,-283.877441,-0.000819,0.004299,0.109193,283.445679,14.439411,1.091927,-283.877441,0.110285,0.000000
70.360001,65.359924,-283.921906,-0.000785,0.004321,0.109748,290.735474,14.810771,1.097476,-283.921906,0.110701,0.000000
70.610001,66.474075,-283.921906,-0.000798,0.004334,0.110086,295.691467,15.063240,1.100859,-283.921906,0.111118,0.000000
70.860001,67.455276,-283.877441,-0.000776,0.004349,0.110458,300.056061,15.285584,1.104584,-283.877441,0.111534,0.000000
71.110001,66.871384,-283.966400,-0.000776,0.004340,0.110242,297.458771,15.153273,1.102419,-283.966400,0.110458,0.000000
71.360001,66.466248,-283.966400,-0.000759,0.004340,0.110234,295.656647,15.061467,1.102336,-283.966400,0.110242,0.000000
71.610001,66.056641,-283.966400,-0.000746,0.004339,0.110216,293.834625,14.968649,1.102161,-283.966400,0.110242,0.000000
71.860001,65.715912,-284.010864,-0.000750,0.004339,0.110207,292.318970,14.891438,1.102071,-284.010864,0.110242,0.000000
72.110001,65.407227,-284.055359,-0.000746,0.004339,0.110199,290.945862,14.821489,1.101987,-284.055359,0.110242,0.000000
72.360001,65.150284,-284.055359,-0.000729,0.004339,0.110199,289.802948,14.763266,1.101987,-284.055359,0.110242,0.000000
72.610001,64.912338,-284.055359,-0.000746,0.004339,0.110199,288.744507,14.709346,1.101987,-284.055359,0.110242,0.000000
72.860001,64.712372,-284.099823,-0.000763,0.004339,0.110199,287.855011,14.664033,1.101987,-284.099823,0.110242,0.000000
73.110001,64.528793,-284.144318,-0.000746,0.004339,0.110199,287.038422,14.622434,1.101987,-284.144318,0.110242,0.000000
73.360001,64.339996,-284.099823,-0.000767,0.004339,0.110199,286.198608,14.579652,1.101987,-284.099823,0.110242,0.000000
73.610001,64.195526,-284.188782,-0.000755,0.004339,0.110199,285.555969,14.546914,1.101987,-284.188782,0.110242,0.000000
73.860001,64.056259,-284.099823,-0.000763,0.004339,0.110199,284.936462,14.515356,1.101987,-284.099823,0.110242,0.000000
74.110001,63.902100,-284.188782,-0.000737,0.004339,0.110199,284.250732,14.480423,1.101987,-284.188782,0.110242,0.000000
74.360001,63.774368,-284.188782,-0.000759,0.004339,0.110199,283.682556,14.451478,1.101987,-284.188782,0.110242,0.000000
74.610001,63.680161,-284.233276,-0.000729,0.004339,0.110199,283.263489,14.430130,1.101987,-284.233276,0.110242,0.000000
74.860001,63.558762,-284.233276,-0.000737,0.004339,0.110199,282.723480,14.402621,1.101987,-284.233276,0.110242,0.000000
75.110001,63.451523,-284.233276,-0.000729,0.004339,0.110199,282.246460,14.378321,1.101987,-284.233276,0.110242,0.000000
75.360001,63.361404,-284.322235,-0.000724,0.004339,0.110199,281.845612,14.357900,1.101987,-284.322235,0.110242,0.000000
75.610001,63.266449,-284.366730,-0.000724,0.004339,0.110199,281.423218,14.336382,1.101987,-284.366730,0.110242,0.000000
75.860001,63.184532,-284.366730,-0.000729,0.004339,0.110199,281.058838,14.317820,1.101987,-284.366730,0.110242,0.000000
76.110001,63.106705,-284.366730,-0.000742,0.004339,0.110199,280.712646,14.300183,1.101987,-284.366730,0.110242,0.000000
76.360001,63.026276,-284.322235,-0.000746,0.004339,0.110199,280.354889,14.281958,1.101987,-284.322235,0.110242,0.000000
76.610001,62.952171,-284.322235,-0.000729,0.004339,0.110199,280.025238,14.265165,1.101987,-284.322235,0.110242,0.000000
76.860001,62.873596,-284.411194,-0.000724,0.004339,0.110199,279.675720,14.247360,1.101987,-284.411194,0.110242,0.000000
77.110001,62.805824,-284.411194,-0.000742,0.004339,0.110199,279.374268,14.232003,1.101987,-284.411194,0.110242,0.000000
77.360001,62.748108,-284.455688,-0.000724,0.004339,0.110199,279.117523,14.218925,1.101987,-284.455688,0.110242,0.000000
77.610001,62.674377,-284.500153,-0.000720,0.004339,0.110199,278.789551,14.202217,1.101987,-284.500153,0.110242,0.000000
77.860001,62.615173,-284.411194,-0.000716,0.004339,0.110199,278.526215,14.188801,1.101987,-284.411194,0.110242,0.000000
78.110001,62.558945,-284.455688,-0.000746,0.004339,0.110199,278.276093,14.176059,1.101987,-284.455688,0.110242,0.000000
78.360001,62.506439,-284.544647,-0.000737,0.004339,0.110199,278.042542,14.164162,1.101987,-284.544647,0.110242,0.000000
78.610001,62.452820,-284.589111,-0.000711,0.004339,0.110199,277.804016,14.152011,1.101987,-284.589111,0.110242,0.000000
78.860001,62.393242,-284.544647,-0.000729,0.004339,0.110199,277.539001,14.138511,1.101987,-284.544647,0.110242,0.000000
79.110001,62.353394,-284.589111,-0.000729,0.004339,0.110199,277.361755,14.129480,1.101987,-284.589111,0.110242,0.000000
79.360001,62.294189,-284.589111,-0.000716,0.004339,0.110199,277.098389,14.116065,1.101987,-284.589111,0.110242,0.000000
79.610001,62.241684,-284.589111,-0.000759,0.004339,0.110199,276.864838,14.104167,1.101987,-284.589111,0.110242,0.000000
79.860001,62.192902,-284.633606,-0.000724,0.004339,0.110199,276.647858,14.093113,1.101987,-284.633606,0.110242,0.000000
80.110001,62.156410,-284.633606,-0.000724,0.004339,0.110199,276.485535,14.084844,1.101987,-284.633606,0.110242,0.000000
80.360001,62.101669,-284.722565,-0.000763,0.004339,0.110199,276.242035,14.072439,1.101987,-284.722565,0.110242,0.000000
80.610001,62.055496,-284.722565,-0.000733,0.004339,0.110199,276.036621,14.061976,1.101987,-284.722565,0.110242,0.000000
80.860001,62.027939,-284.767059,-0.000733,0.004339,0.110199,275.914062,14.055732,1.101987,-284.767059,0.110242,0.000000
81.110001,61.979530,-284.767059,-0.000755,0.004339,0.110199,275.698730,14.044763,1.101987,-284.767059,0.110242,0.000000
81.360001,61.934105,-284.767059,-0.000716,0.004339,0.110199,275.496643,14.034469,1.101987,-284.767059,0.110242,0.000000
81.610001,61.916603,-284.811523,-0.000703,0.004339,0.110199,275.418793,14.030503,1.101987,-284.811523,0.110242,0.000000
81.860001,61.861862,-284.767059,-0.000750,0.004339,0.110199,275.175293,14.018099,1.101987,-284.767059,0.110242,0.000000
82.110001,61.832443,-284.900482,-0.000711,0.004339,0.110199,275.044434,14.011432,1.101987,-284.900482,0.110242,0.000000
82.360001,61.787018,-284.811523,-0.000720,0.004339,0.110199,274.842377,14.001138,1.101987,-284.811523,0.110242,0.000000
82.610001,61.750153,-284.856018,-0.000711,0.004339,0.110199,274.678406,13.992785,1.101987,-284.856018,0.110242,0.000000
82.860001,61.720360,-284.856018,-0.000750,0.004339,0.110199,274.545868,13.986033,1.101987,-284.856018,0.110242,0.000000
83.110001,61.689453,-284.900482,-0.000733,0.004339,0.110199,274.408386,13.979030,1.101987,-284.900482,0.110242,0.000000
83.360001,61.663017,-284.989441,-0.000729,0.004339,0.110199,274.290802,13.973040,1.101987,-284.989441,0.110242,0.000000
83.610001,61.619446,-284.944977,-0.000729,0.004339,0.110199,274.096985,13.963166,1.101987,-284.944977,0.110242,0.000000
83.860001,61.605301,-284.989441,-0.000724,0.004339,0.110199,274.034058,13.959961,1.101987,-284.989441,0.110242,0.000000
84.110001,61.558006,-284.989441,-0.000716,0.004339,0.110199,273.823700,13.949244,1.101987,-284.989441,0.110242,0.000000
84.360001,61.526726,-285.033936,-0.000733,0.004339,0.110199,273.684540,13.942156,1.101987,-285.033936,0.110242,0.000000
84.610001,61.504013,-285.033936,-0.000716,0.004339,0.110199,273.583527,13.937008,1.101987,-285.033936,0.110242,0.000000
84.860001,61.480553,-285.033936,-0.000716,0.004339,0.110199,273.479156,13.931693,1.101987,-285.033936,0.110242,0.000000
85.110001,61.447411,-285.078430,-0.000733,0.004339,0.110199,273.331726,13.924182,1.101987,-285.078430,0.110242,0.000000
85.360001,61.418739,-285.122894,-0.000720,0.004339,0.110199,273.204193,13.917686,1.101987,-285.122894,0.110242,0.000000
85.610001,61.400124,-285.078430,-0.000724,0.004339,0.110199,273.121399,13.913466,1.101987,-285.078430,0.110242,0.000000
85.860001,61.365860,-285.167389,-0.000742,0.004339,0.110199,272.968964,13.905703,1.101987,-285.167389,0.110242,0.000000
86.110001,61.352455,-285.122894,-0.000733,0.004339,0.110199,272.909363,13.902664,1.101987,-285.122894,0.110242,0.000000
86.360001,61.317085,-285.167389,-0.000724,0.004339,0.110199,272.752014,13.894650,1.101987,-285.167389,0.110242,0.000000
86.610001,61.307770,-285.211853,-0.000733,0.004339,0.110199,272.710571,13.892539,1.101987,-285.211853,0.110242,0.000000
86.860001,61.273140,-285.167389,-0.000750,0.004339,0.110199,272.556549,13.884692,1.101987,-285.167389,0.110242,0.000000
87.110001,61.251175,-285.211853,-0.000720,0.004339,0.110199,272.458832,13.879714,1.101987,-285.211853,0.110242,0.000000
87.360001,61.218773,-285.300812,-0.000720,0.004339,0.110199,272.314697,13.872373,1.101987,-285.300812,0.110242,0.000000
87.610001,61.184891,-285.300812,-0.000698,0.004339,0.110199,272.164001,13.864694,1.101987,-285.300812,0.110242,0.000000
87.860001,61.177444,-285.345306,-0.000711,0.004339,0.110199,272.130859,13.863008,1.101987,-285.345306,0.110242,0.000000
88.110001,61.159943,-285.300812,-0.000755,0.004339,0.110199,272.053009,13.859041,1.101987,-285.300812,0.110242,0.000000
88.360001,61.144302,-285.389771,-0.000737,0.004339,0.110199,271.983429,13.855496,1.101987,-285.389771,0.110242,0.000000
88.610001,61.122704,-285.389771,-0.000733,0.004339,0.110199,271.887360,13.850602,1.101987,-285.389771,0.110242,0.000000
88.860001,61.098503,-285.389771,-0.000733,0.004339,0.110199,271.779724,13.845119,1.101987,-285.389771,0.110242,0.000000
89.110001,61.070946,-285.389771,-0.000742,0.004339,0.110199,271.657135,13.838874,1.101987,-285.389771,0.110242,0.000000
89.360001,61.058655,-285.434265,-0.000724,0.004339,0.110199,271.602448,13.836089,1.101987,-285.434265,0.110242,0.000000
89.610001,61.029610,-285.434265,-0.000755,0.004339,0.110199,271.473267,13.829507,1.101987,-285.434265,0.110242,0.000000
89.860001,61.008759,-285.434265,-0.000720,0.004339,0.110199,271.380524,13.824782,1.101987,-285.434265,0.110242,0.000000
90.110001,60.975243,-285.523224,-0.000742,0.004339,0.110199,271.231415,13.817187,1.101987,-285.523224,0.110242,0.000000
90.360001,60.969284,-285.478729,-0.000720,0.004339,0.110199,271.204926,13.815837,1.101987,-285.478729,0.110242,0.000000
90.610001,60.962585,-285.523224,-0.000755,0.004339,0.110199,271.175110,13.814320,1.101987,-285.523224,0.110242,0.000000
90.860001,60.943596,-285.523224,-0.000698,0.004339,0.110199,271.090668,13.810017,1.101987,-285.523224,0.110242,0.000000
91.110001,60.910454,-285.656677,-0.000733,0.004339,0.110199,270.943237,13.802506,1.101987,-285.656677,0.110242,0.000000
91.360001,60.893692,-285.612183,-0.000729,0.004339,0.110199,270.868683,13.798708,1.101987,-285.612183,0.110242,0.000000
91.610001,60.873589,-285.656677,-0.000729,0.004339,0.110199,270.779236,13.794152,1.101987,-285.656677,0.110242,0.000000
91.860001,60.854965,-285.656677,-0.000711,0.004339,0.110199,270.696411,13.789932,1.101987,-285.656677,0.110242,0.000000
92.110001,60.852364,-285.656677,-0.000724,0.004339,0.110199,270.684845,13.789342,1.101987,-285.656677,0.110242,0.000000
92.360001,60.816612,-285.701141,-0.000720,0.004339,0.110199,270.525787,13.781241,1.101987,-285.701141,0.110242,0.000000
92.610001,60.808418,-285.701141,-0.000733,0.004339,0.110199,270.489349,13.779385,1.101987,-285.701141,0.110242,0.000000
92.860001,60.775650,-285.745636,-0.000707,0.004339,0.110199,270.343597,13.771959,1.101987,-285.745636,0.110242,0.000000
93.110001,60.774162,-285.834595,-0.000724,0.004339,0.110199,270.336975,13.771623,1.101987,-285.834595,0.110242,0.000000
93.360008,60.762993,-285.790100,-0.000711,0.004339,0.110199,270.287292,13.769092,1.101987,-285.790100,0.110242,0.000000
93.610008,60.738419,-285.745636,-0.000707,0.004339,0.110199,270.177979,13.763522,1.101987,-285.745636,0.110242,0.000000
93.860008,60.715332,-285.790100,-0.000724,0.004339,0.110199,270.075287,13.758290,1.101987,-285.790100,0.110242,0.000000
94.110008,60.703415,-285.834595,-0.000737,0.004339,0.110199,270.022278,13.755590,1.101987,-285.834595,0.110242,0.000000
94.360008,60.692612,-285.790100,-0.000742,0.004339,0.110199,269.974213,13.753142,1.101987,-285.790100,0.110242,0.000000
94.610008,60.670647,-285.879059,-0.000703,0.004339,0.110199,269.876526,13.748165,1.101987,-285.879059,0.110242,0.000000
94.860008,60.662453,-285.879059,-0.000724,0.004339,0.110199,269.840057,13.746308,1.101987,-285.879059,0.110242,0.000000
95.110008,60.625214,-285.879059,-0.000737,0.004339,0.110199,269.674408,13.737869,1.101987,-285.879059,0.110242,0.000000
95.360008,60.612923,-285.968048,-0.000711,0.004339,0.110199,269.619751,13.735085,1.101987,-285.968048,0.110242,0.000000
95.610008,60.610695,-285.923553,-0.000720,0.004339,0.110199,269.609833,13.734579,1.101987,-285.923553,0.110242,0.000000
95.860008,60.599892,-286.012512,-0.000724,0.004339,0.110199,269.561768,13.732132,1.101987,-286.012512,0.110242,0.000000
96.110008,60.585373,-285.968048,-0.000729,0.004339,0.110199,269.497192,13.728842,1.101987,-285.968048,0.110242,0.000000
96.360008,60.560051,-285.968048,-0.000724,0.004339,0.110199,269.384552,13.723104,1.101987,-285.968048,0.110242,0.000000
96.610008,60.551483,-286.012512,-0.000720,0.004339,0.110199,269.346436,13.721163,1.101987,-286.012512,0.110242,0.000000
96.860008,60.538078,-286.057007,-0.000737,0.004339,0.110199,269.286835,13.718125,1.101987,-286.057007,0.110242,0.000000
97.110008,60.523560,-286.101471,-0.000724,0.004339,0.110199,269.222229,13.714835,1.101987,-286.101471,0.110242,0.000000
97.360008,60.519836,-286.101471,-0.000703,0.004339,0.110199,269.205688,13.713990,1.101987,-286.101471,0.110242,0.000000
97.610008,60.498238,-286.101471,-0.000720,0.004339,0.110199,269.109589,13.709096,1.101987,-286.101471,0.110242,0.000000
97.860008,60.481850,-286.190430,-0.000729,0.004339,0.110199,269.036713,13.705383,1.101987,-286.190430,0.110242,0.000000
98.110008,60.478127,-286.145966,-0.000703,0.004339,0.110199,269.020142,13.704539,1.101987,-286.145966,0.110242,0.000000
98.360008,60.466957,-286.145966,-0.000763,0.004339,0.110199,268.970459,13.702008,1.101987,-286.145966,0.110242,0.000000
98.610008,60.459885,-286.145966,-0.000720,0.004339,0.110199,268.938995,13.700406,1.101987,-286.145966,0.110242,0.000000
98.860008,60.442749,-286.234924,-0.000707,0.004339,0.110199,268.862762,13.696523,1.101987,-286.234924,0.110242,0.000000
99.110008,60.431953,-286.323883,-0.000733,0.004339,0.110199,268.814758,13.694077,1.101987,-286.323883,0.110242,0.000000
99.360008,60.418549,-286.279388,-0.000707,0.004339,0.110199,268.755127,13.691038,1.101987,-286.279388,0.110242,0.000000
99.610008,60.402908,-286.323883,-0.000724,0.004339,0.110199,268.685547,13.687494,1.101987,-286.323883,0.110242,0.000000
99.860008,60.390991,-286.279388,-0.000711,0.004339,0.110199,268.632538,13.684794,1.101987,-286.279388,0.110242,0.000000
100.110008,60.391739,-286.323883,-0.000711,0.004339,0.110199,268.635864,13.684963,1.101987,-286.323883,0.110242,0.000000
100.360008,60.367905,-286.323883,-0.000716,0.004339,0.110199,268.529846,13.679563,1.101987,-286.323883,0.110242,0.000000
100.610008,60.349289,-286.368378,-0.000724,0.004339,0.110199,268.447052,13.675344,1.101987,-286.368378,0.110242,0.000000
100.860008,60.325455,-286.368378,-0.000716,0.004339,0.110199,268.341034,13.669943,1.101987,-286.368378,0.110242,0.000000
101.110008,60.323219,-286.368378,-0.000742,0.004339,0.110199,268.331085,13.669436,1.101987,-286.368378,0.110242,0.000000
101.360008,60.326942,-286.412842,-0.000724,0.004339,0.110199,268.347656,13.670280,1.101987,-286.412842,0.110242,0.000000
101.400002,60.315025,-286.368378,-0.000737,0.004339,0.110199,268.294647,13.667580,1.101987,-286.368378,0.110242,0.000000