File: Data/compression 14/AutoNoHeating-10-14-4-240726_07262024_162600.csv
Time (sec),S:Load (lbs),S:HL1 (DIM),S:LVDT (in),S:Position (in),Ch:Position (mm),Ch:Load (N),Ch:Stress (MPa),Ch:Strain (mm/mm),Ch:HL1 (DIM),Set Point (),Cycles ()
0.110000,0.001114,-302.959747,-0.010831,-0.005969,-0.151625,0.004955,0.000252,-1.516252,-302.959747,-0.151434,0.000000
0.370000,-0.001862,-302.959747,-0.010856,-0.005969,-0.151625,-0.008281,-0.000422,-1.516252,-302.959747,-0.151434,0.000000
0.630000,-0.005959,-302.959747,-0.010848,-0.005861,-0.148877,-0.026505,-0.001350,-1.488766,-302.959747,-0.147809,0.000000
0.890000,-0.011917,-303.004242,-0.010723,-0.005689,-0.144497,-0.053010,-0.002700,-1.444967,-303.004242,-0.143473,0.000000
1.150000,-0.048035,-303.004242,-0.010550,-0.005529,-0.140439,-0.213669,-0.010885,-1.404385,-303.004242,-0.139137,0.000000
1.410000,-0.025322,-303.048706,-0.010361,-0.005366,-0.136293,-0.112638,-0.005738,-1.362926,-303.048706,-0.134801,0.000000
1.670000,0.004837,-303.048706,-0.010192,-0.005180,-0.131575,0.021516,0.001096,-1.315751,-303.048706,-0.130483,0.000000
1.930000,-0.023460,-303.093201,-0.009994,-0.005015,-0.127369,-0.104357,-0.005316,-1.273693,-303.093201,-0.126146,0.000000
2.190000,0.017876,-303.093201,-0.009856,-0.004849,-0.123154,0.079515,0.004051,-1.231544,-303.093201,-0.121810,0.000000
2.450000,0.031281,-303.093201,-0.009636,-0.004670,-0.118628,0.139143,0.007088,-1.186277,-303.093201,-0.117474,0.000000
2.710000,-0.012291,-303.182159,-0.009459,-0.004499,-0.114283,-0.054673,-0.002785,-1.142826,-303.182159,-0.113155,0.000000
2.970000,0.020477,-303.137695,-0.009287,-0.004335,-0.110120,0.091088,0.004640,-1.101200,-303.137695,-0.108819,0.000000
3.230000,-0.018623,-303.182159,-0.009127,-0.004153,-0.105489,-0.082841,-0.004220,-1.054888,-303.182159,-0.104483,0.000000
3.490000,-0.036865,-303.182159,-0.008925,-0.003989,-0.101326,-0.163985,-0.008354,-1.013262,-303.182159,-0.100147,0.000000
3.750000,0.024948,-303.182159,-0.008739,-0.003823,-0.097111,0.110975,0.005653,-0.971113,-303.182159,-0.095828,0.000000
4.010000,0.005211,-303.182159,-0.008601,-0.003645,-0.092594,0.023179,0.001181,-0.925937,-303.182159,-0.091492,0.000000
4.270000,0.004471,-303.226654,-0.008399,-0.003475,-0.088257,0.019887,0.001013,-0.882569,-303.226654,-0.087156,0.000000
4.530000,0.021599,-303.271118,-0.008201,-0.003315,-0.084207,0.096076,0.004894,-0.842071,-303.271118,-0.082837,0.000000
4.790000,-0.015640,-303.271118,-0.008063,-0.003132,-0.079550,-0.069571,-0.003544,-0.795502,-303.271118,-0.078501,0.000000
5.050000,-0.001488,-303.226654,-0.007869,-0.002965,-0.075310,-0.006618,-0.000337,-0.753096,-303.226654,-0.074165,0.000000
5.310000,0.000740,-303.315613,-0.007692,-0.002792,-0.070921,0.003292,0.000168,-0.709214,-303.315613,-0.069828,0.000000
5.570000,-0.021973,-303.271118,-0.007511,-0.002628,-0.066759,-0.097739,-0.004979,-0.667587,-303.271118,-0.065510,0.000000
5.830000,-0.000000,-303.404572,-0.007325,-0.002454,-0.062327,-0.000000,-0.000000,-0.623274,-303.404572,-0.061174,0.000000
6.090000,0.033882,-303.360077,-0.007153,-0.002292,-0.058216,0.150715,0.007678,-0.582162,-303.360077,-0.056838,0.000000
6.350000,-0.009308,-303.360077,-0.006963,-0.002112,-0.053655,-0.041403,-0.002109,-0.536547,-303.360077,-0.052502,0.000000
6.610000,0.023834,-303.449036,-0.006765,-0.001942,-0.049319,0.106020,0.005401,-0.493187,-303.449036,-0.048182,0.000000
6.870000,0.009308,-303.404572,-0.006579,-0.001773,-0.045026,0.041403,0.002109,-0.450259,-303.404572,-0.043846,0.000000
7.130000,-0.014526,-303.404572,-0.006411,-0.001599,-0.040620,-0.064617,-0.003292,-0.406202,-303.404572,-0.039511,0.000000
7.390000,-0.006332,-303.449036,-0.006239,-0.001427,-0.036241,-0.028168,-0.001435,-0.362411,-303.449036,-0.035175,0.000000
7.650001,-0.015640,-303.404572,-0.006062,-0.001262,-0.032044,-0.069571,-0.003544,-0.320437,-303.404572,-0.030855,0.000000
7.910000,-0.025322,-303.493530,-0.005894,-0.001090,-0.027699,-0.112638,-0.005738,-0.276986,-303.493530,-0.026519,0.000000
8.170000,0.022713,-303.493530,-0.005708,-0.000919,-0.023345,0.101031,0.005147,-0.233452,-303.493530,-0.022183,0.000000
8.430000,0.042450,-303.493530,-0.005549,-0.000752,-0.019105,0.188827,0.009619,-0.191046,-303.493530,-0.017847,0.000000
8.690001,0.010796,-303.538025,-0.005338,-0.000577,-0.014664,0.048021,0.002446,-0.146642,-303.538025,-0.013529,0.000000
8.950001,0.028297,-303.538025,-0.005178,-0.000407,-0.010328,0.125873,0.006412,-0.103282,-303.538025,-0.009192,0.000000
9.210000,0.043198,-303.671448,-0.005014,-0.000232,-0.005888,0.192153,0.009789,-0.058878,-303.671448,-0.004856,0.000000
9.470000,0.141876,-303.582489,-0.004786,-0.000067,-0.001691,0.631097,0.032150,-0.016911,-303.582489,-0.000537,0.000000
9.730000,0.618507,-303.626984,-0.004644,0.000101,0.002568,2.751258,0.140156,0.025677,-303.626984,0.003799,0.000000
9.990001,0.592072,-303.626984,-0.004631,-0.000000,-0.000000,2.633666,0.134165,-0.000000,-303.626984,0.000226,0.000000
10.250001,0.561165,-303.626984,-0.004626,-0.000000,-0.000000,2.496186,0.127162,-0.000000,-303.626984,0.000226,0.000000
10.510000,0.558929,-303.760406,-0.004600,-0.000000,-0.000000,2.486242,0.126655,-0.000000,-303.760406,0.000572,0.000000
10.770000,0.569359,-303.715942,-0.004605,0.000000,0.000009,2.532634,0.129019,0.000091,-303.715942,0.001006,0.000000
11.030001,0.559677,-303.760406,-0.004613,0.000001,0.000017,2.489568,0.126825,0.000174,-303.760406,0.001440,0.000000
11.290001,0.831879,-303.715942,-0.004579,0.000040,0.001006,3.700381,0.188506,0.010060,-303.715942,0.001874,0.000000
11.550000,0.849380,-303.760406,-0.004600,0.000049,0.001240,3.778233,0.192472,0.012399,-303.760406,0.002307,0.000000
11.810000,0.967796,-303.760406,-0.004570,0.000070,0.001778,4.304973,0.219306,0.017781,-303.760406,0.002740,0.000000
12.070001,1.044876,-303.804901,-0.004514,0.000085,0.002160,4.647841,0.236772,0.021597,-303.804901,0.003174,0.000000
12.330001,1.247078,-303.804901,-0.004523,0.000103,0.002619,5.547280,0.282592,0.026191,-303.804901,0.003608,0.000000
12.590000,1.296600,-303.893860,-0.004523,0.000113,0.002880,5.767566,0.293814,0.028795,-303.893860,0.004042,0.000000
12.850000,1.497681,-303.849365,-0.004531,0.000132,0.003356,6.662016,0.339379,0.033564,-303.849365,0.004475,0.000000
13.110001,1.752754,-303.938324,-0.004480,0.000159,0.004032,7.796640,0.397180,0.040324,-303.938324,0.004909,0.000000
13.370001,1.883835,-303.893860,-0.004458,0.000179,0.004544,8.379716,0.426883,0.045441,-303.893860,0.005342,0.000000
13.630001,1.916229,-303.938324,-0.004424,0.000189,0.004796,8.523813,0.434224,0.047962,-303.938324,0.005776,0.000000
13.890000,2.068153,-303.938324,-0.004445,0.000206,0.005221,9.199606,0.468650,0.052209,-303.938324,0.006209,0.000000
14.150001,2.328819,-303.938324,-0.004411,0.000224,0.005689,10.359105,0.527718,0.056895,-303.938324,0.006643,0.000000
14.410001,2.526543,-304.027313,-0.004376,0.000240,0.006097,11.238623,0.572523,0.060967,-304.027313,0.007077,0.000000
14.670001,2.615540,-304.027313,-0.004398,0.000254,0.006443,11.634501,0.592690,0.064434,-304.027313,0.007510,0.000000
14.930000,2.826675,-303.982819,-0.004368,0.000268,0.006817,12.573680,0.640534,0.068166,-303.982819,0.007944,0.000000
15.190001,3.075798,-304.071777,-0.004363,0.000292,0.007415,13.681833,0.696986,0.074146,-304.071777,0.008377,0.000000
15.450001,3.187508,-304.071777,-0.004333,0.000306,0.007762,14.178742,0.722300,0.077621,-304.071777,0.008811,0.000000
15.710001,3.359543,-304.116272,-0.004337,0.000323,0.008196,14.943993,0.761283,0.081958,-304.116272,0.009245,0.000000
15.970001,3.682388,-304.071777,-0.004299,0.000344,0.008733,16.380081,0.834441,0.087333,-304.071777,0.009679,0.000000
16.230001,3.887192,-304.116272,-0.004277,0.000363,0.009218,17.291092,0.880850,0.092185,-304.116272,0.010112,0.000000
16.490002,3.913261,-304.116272,-0.004294,0.000374,0.009505,17.407057,0.886758,0.095046,-304.116272,0.010545,0.000000
16.750000,4.049919,-304.160736,-0.004286,0.000385,0.009792,18.014940,0.917725,0.097915,-304.160736,0.010979,0.000000
17.010000,4.536987,-304.205231,-0.004273,0.000412,0.010459,20.181528,1.028096,0.104592,-304.205231,0.011413,0.000000
17.270000,4.602898,-304.205231,-0.004225,0.000428,0.010884,20.474710,1.043031,0.108838,-304.205231,0.011838,0.000000
17.530001,4.710884,-304.205231,-0.004208,0.000444,0.011283,20.955059,1.067502,0.112828,-304.205231,0.012271,0.000000
17.790001,4.968193,-304.294189,-0.004191,0.000461,0.011717,22.099627,1.125809,0.117165,-304.294189,0.012705,0.000000
18.050001,5.098526,-304.294189,-0.004182,0.000476,0.012098,22.679377,1.155342,0.120980,-304.294189,0.013139,0.000000
18.310001,5.340195,-304.294189,-0.004178,0.000495,0.012575,23.754372,1.210105,0.125749,-304.294189,0.013572,0.000000
18.570002,5.390465,-304.338654,-0.004178,0.000506,0.012853,23.977985,1.221497,0.128527,-304.338654,0.014006,0.000000
18.830002,5.706604,-304.294189,-0.004143,0.000522,0.013269,25.384243,1.293135,0.132691,-304.294189,0.014439,0.000000
19.090000,6.102066,-304.383148,-0.004109,0.000553,0.014050,27.143345,1.382748,0.140495,-304.383148,0.014873,0.000000
19.350000,6.090149,-304.338654,-0.004096,0.000568,0.014439,27.090336,1.380047,0.144394,-304.338654,0.015307,0.000000
19.610001,6.191437,-304.383148,-0.004092,0.000583,0.014803,27.540886,1.403000,0.148035,-304.383148,0.015741,0.000000
19.870001,6.423798,-304.427643,-0.004070,0.000601,0.015255,28.574478,1.455653,0.152546,-304.427643,0.016174,0.000000
20.130001,6.666214,-304.427643,-0.004049,0.000619,0.015714,29.652802,1.510586,0.157141,-304.427643,0.016607,0.000000
20.390001,6.792076,-304.472107,-0.004057,0.000633,0.016078,30.212664,1.539106,0.160782,-304.472107,0.017041,0.000000
20.650002,6.864685,-304.472107,-0.004044,0.000644,0.016356,30.535645,1.555560,0.163560,-304.472107,0.017475,0.000000
20.910002,7.269081,-304.516602,-0.004027,0.000669,0.016989,32.334488,1.647197,0.169889,-304.516602,0.017909,0.000000
21.170000,7.354355,-304.516602,-0.004014,0.000687,0.017440,32.713806,1.666521,0.174400,-304.516602,0.018342,0.000000
21.430000,7.532722,-304.516602,-0.003945,0.000705,0.017900,33.507221,1.706939,0.178995,-304.516602,0.018775,0.000000
21.690001,7.634010,-304.605560,-0.003980,0.000719,0.018255,33.957775,1.729891,0.182553,-304.605560,0.019209,0.000000
21.950001,7.800087,-304.561066,-0.003945,0.000735,0.018663,34.696518,1.767525,0.186626,-304.561066,0.019643,0.000000
22.210001,7.901741,-304.561066,-0.003915,0.000752,0.019105,35.148701,1.790560,0.191054,-304.561066,0.020077,0.000000
22.470001,7.957596,-304.650024,-0.003923,0.000764,0.019409,35.397156,1.803217,0.194089,-304.650024,0.020510,0.000000
22.730001,8.253632,-304.605560,-0.003915,0.000783,0.019886,36.713985,1.870300,0.198858,-304.605560,0.020943,0.000000
22.990002,8.534401,-304.694519,-0.003885,0.000806,0.020476,37.962910,1.933923,0.204755,-304.694519,0.021377,0.000000
23.250002,8.560844,-304.694519,-0.003876,0.000821,0.020857,38.080540,1.939915,0.208570,-304.694519,0.021811,0.000000
23.510000,8.779053,-304.694519,-0.003863,0.000842,0.021377,39.051178,1.989362,0.213771,-304.694519,0.022245,0.000000
23.770000,8.752243,-304.694519,-0.003837,0.000856,0.021741,38.931923,1.983287,0.217412,-304.694519,0.022678,0.000000
24.030001,9.050140,-304.694519,-0.003820,0.000876,0.022245,40.257034,2.050791,0.222446,-304.694519,0.023112,0.000000
24.290001,8.944016,-304.738983,-0.003803,0.000885,0.022478,39.784969,2.026743,0.224785,-304.738983,0.023545,0.000000
24.550001,9.166321,-304.738983,-0.003781,0.000903,0.022947,40.773830,2.077118,0.229471,-304.738983,0.023979,0.000000
24.810001,9.642212,-304.827972,-0.003764,0.000929,0.023606,42.890701,2.184957,0.236064,-304.827972,0.024413,0.000000
25.070002,9.513374,-304.827972,-0.003751,0.000943,0.023944,42.317604,2.155761,0.239440,-304.827972,0.024846,0.000000
25.330002,9.595665,-304.783478,-0.003734,0.000960,0.024395,42.683651,2.174409,0.243952,-304.783478,0.025280,0.000000
25.590002,9.707375,-304.827972,-0.003738,0.000975,0.024777,43.180557,2.199723,0.247767,-304.827972,0.025713,0.000000
25.850000,9.953888,-304.827972,-0.003699,0.000994,0.025245,44.277103,2.255583,0.252452,-304.827972,0.026147,0.000000
26.110001,9.977348,-304.827972,-0.003695,0.001008,0.025609,44.381462,2.260899,0.256094,-304.827972,0.026581,0.000000
26.370001,10.035812,-304.916931,-0.003708,0.001023,0.025991,44.641521,2.274148,0.259909,-304.916931,0.027005,0.000000
26.630001,10.535530,-304.872437,-0.003656,0.001047,0.026590,46.864380,2.387385,0.265896,-304.872437,0.027439,0.000000
26.890001,10.537766,-304.961395,-0.003652,0.001064,0.027023,46.874321,2.387892,0.270226,-304.961395,0.027873,0.000000
27.150002,10.575378,-304.961395,-0.003656,0.001080,0.027431,47.041634,2.396415,0.274306,-304.961395,0.028306,0.000000
27.410002,10.615593,-304.961395,-0.003622,0.001095,0.027812,47.220516,2.405528,0.278122,-304.961395,0.028740,0.000000
27.670002,10.592506,-304.961395,-0.003609,0.001111,0.028211,47.117821,2.400296,0.282111,-304.961395,0.029174,0.000000
27.930002,10.889656,-304.961395,-0.003596,0.001127,0.028618,48.439610,2.467631,0.286183,-304.961395,0.029607,0.000000
28.190001,10.937698,-305.094849,-0.003604,0.001142,0.029000,48.653313,2.478518,0.289999,-305.094849,0.030041,0.000000
28.450001,11.044937,-305.050354,-0.003579,0.001156,0.029373,49.130333,2.502819,0.293731,-305.050354,0.030474,0.000000
28.710001,11.626953,-305.050354,-0.003548,0.001183,0.030041,51.719269,2.634705,0.300407,-305.050354,0.030908,0.000000
28.970001,11.535728,-305.094849,-0.003548,0.001200,0.030474,51.313484,2.614033,0.304745,-305.094849,0.031342,0.000000
29.230001,11.396088,-305.094849,-0.003531,0.001213,0.030804,50.692329,2.582390,0.308037,-305.094849,0.031775,0.000000
29.490002,11.456039,-305.139313,-0.003501,0.001231,0.031255,50.959007,2.595976,0.312549,-305.139313,0.032209,0.000000
29.750002,11.625465,-305.183807,-0.003510,0.001245,0.031611,51.712654,2.634368,0.316107,-305.183807,0.032642,0.000000
30.010002,11.912567,-305.139313,-0.003488,0.001266,0.032166,52.989746,2.699426,0.321656,-305.139313,0.033076,0.000000
30.270002,11.902512,-305.183807,-0.003484,0.001281,0.032530,52.945015,2.697148,0.325297,-305.183807,0.033510,0.000000
30.530001,12.362389,-305.094849,-0.003449,0.001307,0.033189,54.990650,2.801357,0.331890,-305.094849,0.033944,0.000000
30.790001,12.192215,-305.272766,-0.003458,0.001320,0.033527,54.233681,2.762795,0.335274,-305.272766,0.034377,0.000000
31.050001,12.200783,-305.228271,-0.003441,0.001336,0.033926,54.271793,2.764737,0.339263,-305.228271,0.034810,0.000000
31.310001,12.036568,-305.228271,-0.003428,0.001345,0.034160,53.541328,2.727525,0.341602,-305.228271,0.035244,0.000000
31.570002,12.599594,-305.272766,-0.003423,0.001367,0.034724,56.045795,2.855109,0.347241,-305.272766,0.035678,0.000000
31.830002,12.600342,-305.317261,-0.003380,0.001381,0.035079,56.049118,2.855278,0.350792,-305.317261,0.036112,0.000000
32.090000,12.626778,-305.361725,-0.003402,0.001396,0.035452,56.166714,2.861269,0.354524,-305.361725,0.036545,0.000000
32.350002,12.842377,-305.361725,-0.003376,0.001412,0.035877,57.125744,2.910124,0.358770,-305.361725,0.036978,0.000000
32.610001,13.160759,-305.361725,-0.003376,0.001437,0.036502,58.541981,2.982270,0.365015,-305.361725,0.037412,0.000000
32.870003,12.833817,-305.450684,-0.003341,0.001448,0.036788,57.087666,2.908184,0.367877,-305.450684,0.037846,0.000000
33.130001,13.072136,-305.495178,-0.003328,0.001468,0.037291,58.147766,2.962188,0.372911,-305.495178,0.038280,0.000000
33.390003,13.042717,-305.450684,-0.003346,0.001482,0.037655,58.016903,2.955522,0.376552,-305.450684,0.038713,0.000000
33.650002,13.361465,-305.495178,-0.003303,0.001503,0.038167,59.434765,3.027751,0.381669,-305.495178,0.039146,0.000000
33.910000,13.068413,-305.406219,-0.003311,0.001512,0.038401,58.131203,2.961345,0.384008,-305.406219,0.039580,0.000000
34.170002,13.404289,-305.495178,-0.003307,0.001531,0.038887,59.625256,3.037455,0.388868,-305.495178,0.040014,0.000000
34.430000,13.893959,-305.495178,-0.003277,0.001556,0.039529,61.803417,3.148416,0.395287,-305.495178,0.040448,0.000000
34.690002,14.004929,-305.539642,-0.003247,0.001577,0.040066,62.297035,3.173562,0.400661,-305.539642,0.040881,0.000000
34.950001,13.540581,-305.584137,-0.003229,0.001588,0.040335,60.231510,3.068340,0.403349,-305.584137,0.041315,0.000000
35.210003,13.654152,-305.584137,-0.003247,0.001606,0.040803,60.736702,3.094075,0.408034,-305.584137,0.041748,0.000000
35.470001,13.860443,-305.584137,-0.003212,0.001623,0.041228,61.654331,3.140821,0.412281,-305.584137,0.042174,0.000000
35.730003,13.982216,-305.539642,-0.003182,0.001639,0.041627,62.196003,3.168415,0.416270,-305.539642,0.042607,0.000000
35.990002,13.931946,-305.673096,-0.003203,0.001653,0.041983,61.972389,3.157024,0.419828,-305.673096,0.043040,0.000000
36.250000,13.972534,-305.673096,-0.003195,0.001667,0.042347,62.152935,3.166222,0.423469,-305.673096,0.043474,0.000000
36.510002,14.340065,-305.673096,-0.003186,0.001690,0.042919,63.787796,3.249505,0.429192,-305.673096,0.043908,0.000000
36.770000,14.275269,-305.762054,-0.003186,0.001704,0.043275,63.499565,3.234822,0.432750,-305.762054,0.044342,0.000000
37.030003,14.359055,-305.673096,-0.003191,0.001721,0.043725,63.872265,3.253808,0.437254,-305.673096,0.044775,0.000000
37.290001,14.502045,-305.673096,-0.003126,0.001739,0.044159,64.508316,3.286210,0.441591,-305.673096,0.045208,0.000000
37.550003,14.774246,-305.717590,-0.003117,0.001761,0.044723,65.719131,3.347892,0.447231,-305.717590,0.045642,0.000000
37.810001,14.603333,-305.762054,-0.003126,0.001776,0.045105,64.958870,3.309162,0.451046,-305.762054,0.046076,0.000000
38.070004,14.330009,-305.806549,-0.003122,0.001786,0.045365,63.743065,3.247226,0.453650,-305.806549,0.046510,0.000000
38.330002,14.976822,-305.806549,-0.003087,0.001812,0.046015,66.620232,3.393796,0.460152,-305.806549,0.046943,0.000000
38.590000,14.868088,-305.851013,-0.003087,0.001828,0.046432,66.136559,3.369157,0.464316,-305.851013,0.047377,0.000000
38.850002,14.639076,-305.851013,-0.003083,0.001842,0.046787,65.117867,3.317262,0.467874,-305.851013,0.047810,0.000000
39.110001,14.868828,-305.806549,-0.003048,0.001860,0.047247,66.139847,3.369325,0.472468,-305.806549,0.048244,0.000000
39.370003,14.806648,-305.895508,-0.003070,0.001877,0.047663,65.863258,3.355234,0.476632,-305.895508,0.048678,0.000000
39.630001,14.913513,-305.895508,-0.003061,0.001893,0.048088,66.338623,3.379451,0.480878,-305.895508,0.049111,0.000000
39.890003,14.786911,-305.939972,-0.003027,0.001905,0.048391,65.775467,3.350762,0.483914,-305.939972,0.049545,0.000000
40.150002,14.967140,-305.939972,-0.003053,0.001921,0.048799,66.577164,3.391603,0.487987,-305.939972,0.049978,0.000000
40.410004,15.667572,-305.984467,-0.003009,0.001951,0.049553,69.692841,3.550323,0.495534,-305.984467,0.050412,0.000000
40.670002,15.271736,-305.984467,-0.003009,0.001967,0.049970,67.932076,3.460625,0.499697,-305.984467,0.050846,0.000000
40.930000,15.054276,-305.984467,-0.002997,0.001982,0.050334,66.964760,3.411348,0.503338,-305.984467,0.051279,0.000000
41.190002,15.006607,-306.028931,-0.002988,0.001997,0.050733,66.752724,3.400546,0.507327,-306.028931,0.051713,0.000000
41.450001,15.233757,-306.028931,-0.002949,0.002015,0.051184,67.763138,3.452019,0.511839,-306.028931,0.052147,0.000000
41.710003,15.241203,-306.073425,-0.002971,0.002031,0.051591,67.796257,3.453706,0.515911,-306.073425,0.052580,0.000000
41.970001,15.135078,-306.117920,-0.002966,0.002043,0.051904,67.324188,3.429658,0.519038,-306.117920,0.053014,0.000000
42.230003,15.123161,-306.117920,-0.002962,0.002059,0.052294,67.271179,3.426957,0.522936,-306.117920,0.053447,0.000000
42.490002,15.739807,-306.117920,-0.002928,0.002086,0.052979,70.014160,3.566691,0.529787,-306.117920,0.053881,0.000000
42.750004,15.687309,-306.162384,-0.002949,0.002104,0.053439,69.780640,3.554795,0.534389,-306.162384,0.054315,0.000000
43.010002,15.434090,-306.206879,-0.002910,0.002117,0.053768,68.654259,3.497415,0.537682,-306.206879,0.054748,0.000000
43.270000,15.471703,-306.162384,-0.002897,0.002133,0.054185,68.821571,3.505938,0.541846,-306.162384,0.055181,0.000000
43.530003,15.537613,-306.251343,-0.002889,0.002151,0.054644,69.114754,3.520874,0.546440,-306.251343,0.055615,0.000000
43.790001,15.362595,-306.295837,-0.002906,0.002163,0.054930,68.336235,3.481214,0.549302,-306.295837,0.056049,0.000000
44.050003,15.676506,-306.251343,-0.002893,0.002181,0.055399,69.732582,3.552347,0.553988,-306.251343,0.056483,0.000000
44.310001,16.073830,-306.295837,-0.002863,0.002205,0.055997,71.499962,3.642382,0.559968,-306.295837,0.056907,0.000000
44.570004,15.942383,-306.340302,-0.002871,0.002220,0.056378,70.915260,3.612596,0.563783,-306.340302,0.057341,0.000000
44.830002,16.074944,-306.251343,-0.002876,0.002240,0.056890,71.504921,3.642634,0.568900,-306.251343,0.057775,0.000000
45.090004,15.850403,-306.340302,-0.002876,0.002255,0.057281,70.506111,3.591753,0.572806,-306.340302,0.058209,0.000000
45.350002,16.126335,-306.340302,-0.002854,0.002275,0.057783,71.733521,3.654280,0.577832,-306.340302,0.058642,0.000000
45.610001,15.713371,-306.340302,-0.002833,0.002283,0.058000,69.896568,3.560701,0.580005,-306.340302,0.059075,0.000000
45.870003,16.057442,-306.429260,-0.002850,0.002304,0.058529,71.427071,3.638668,0.585289,-306.429260,0.059509,0.000000
46.130001,16.527748,-306.340302,-0.002824,0.002328,0.059128,73.519096,3.745241,0.591276,-306.340302,0.059943,0.000000
46.390003,16.195595,-306.518219,-0.002798,0.002342,0.059483,72.041603,3.669974,0.594834,-306.518219,0.060377,0.000000
46.650002,16.255173,-306.473755,-0.002828,0.002360,0.059951,72.306618,3.683475,0.599512,-306.473755,0.060810,0.000000
46.910004,16.185539,-306.473755,-0.002785,0.002374,0.060307,71.996872,3.667696,0.603070,-306.473755,0.061243,0.000000
47.170002,16.388481,-306.562714,-0.002785,0.002393,0.060776,72.899605,3.713683,0.607756,-306.562714,0.061677,0.000000
47.430004,16.347893,-306.518219,-0.002794,0.002407,0.061131,72.719055,3.704485,0.611306,-306.518219,0.062111,0.000000
47.690002,16.360931,-306.562714,-0.002755,0.002424,0.061564,72.777054,3.707440,0.615643,-306.562714,0.062545,0.000000
47.950001,16.937363,-306.562714,-0.002772,0.002446,0.062137,75.341148,3.838061,0.621366,-306.562714,0.062978,0.000000
48.210003,16.874054,-306.562714,-0.002734,0.002464,0.062579,75.059540,3.823715,0.625795,-306.562714,0.063411,0.000000
48.470001,16.781708,-306.607208,-0.002755,0.002479,0.062969,74.648766,3.802789,0.629693,-306.607208,0.063845,0.000000
48.730003,16.705376,-306.562714,-0.002755,0.002494,0.063351,74.309219,3.785492,0.633508,-306.562714,0.064279,0.000000
48.990002,16.811874,-306.651672,-0.002738,0.002511,0.063785,74.782951,3.809625,0.637846,-306.651672,0.064713,0.000000
49.250004,16.904961,-306.696167,-0.002725,0.002525,0.064140,75.197021,3.830719,0.641403,-306.696167,0.065146,0.000000
49.510002,16.881134,-306.696167,-0.002712,0.002541,0.064539,75.091034,3.825320,0.645393,-306.696167,0.065580,0.000000
49.770000,17.007736,-306.696167,-0.002716,0.002555,0.064903,75.654190,3.854008,0.649034,-306.696167,0.066013,0.000000
50.030003,17.868668,-306.651672,-0.002677,0.002585,0.065666,79.483803,4.049098,0.656664,-306.651672,0.066447,0.000000
50.290001,17.524590,-306.740631,-0.002677,0.002598,0.065996,77.953270,3.971129,0.659957,-306.740631,0.066881,0.000000
50.550003,17.183502,-306.785126,-0.002686,0.002613,0.066369,76.436035,3.893837,0.663689,-306.785126,0.067314,0.000000
50.810001,17.387184,-306.785126,-0.002660,0.002630,0.066811,77.342056,3.939992,0.668110,-306.785126,0.067748,0.000000
51.070004,17.306007,-306.829590,-0.002660,0.002646,0.067202,76.980965,3.921597,0.672016,-306.829590,0.068181,0.000000
51.330002,17.663116,-306.785126,-0.002652,0.002665,0.067678,78.569466,4.002520,0.676785,-306.785126,0.068615,0.000000
51.590004,17.441551,-306.918549,-0.002647,0.002679,0.068043,77.583893,3.952312,0.680426,-306.918549,0.069049,0.000000
51.850002,18.350517,-306.874084,-0.002634,0.002706,0.068728,81.627174,4.158287,0.687276,-306.874084,0.069482,0.000000
52.110001,18.052246,-306.874084,-0.002617,0.002720,0.069092,80.300400,4.090697,0.690917,-306.874084,0.069916,0.000000
52.370003,17.883186,-306.918549,-0.002591,0.002735,0.069473,79.548386,4.052388,0.694733,-306.918549,0.070350,0.000000
52.630001,17.561829,-306.874084,-0.002604,0.002745,0.069725,78.118912,3.979567,0.697253,-306.874084,0.070783,0.000000
52.890003,18.254066,-306.918549,-0.002596,0.002765,0.070237,81.198143,4.136431,0.702371,-306.918549,0.071217,0.000000
53.150002,18.201195,-306.963043,-0.002596,0.002779,0.070592,80.962959,4.124450,0.705921,-306.963043,0.071650,0.000000
53.410004,18.278275,-307.007538,-0.002591,0.002794,0.070974,81.305824,4.141916,0.709736,-307.007538,0.072075,0.000000
53.670002,18.535583,-307.007538,-0.002574,0.002811,0.071390,82.450394,4.200223,0.713899,-307.007538,0.072509,0.000000
53.930004,19.043129,-307.007538,-0.002548,0.002835,0.072006,84.708069,4.315235,0.720061,-307.007538,0.072942,0.000000
54.190002,18.652138,-307.052002,-0.002565,0.002849,0.072353,82.968849,4.226635,0.723528,-307.052002,0.073376,0.000000
54.450001,18.809647,-307.007538,-0.002561,0.002867,0.072821,83.669487,4.262327,0.728214,-307.007538,0.073810,0.000000
54.710003,18.697189,-307.096497,-0.002501,0.002881,0.073168,83.169250,4.236844,0.731681,-307.096497,0.074243,0.000000
54.970001,19.089302,-307.140961,-0.002535,0.002900,0.073662,84.913460,4.325698,0.736624,-307.140961,0.074677,0.000000
55.230003,18.760498,-307.096497,-0.002535,0.002910,0.073905,83.450867,4.251190,0.739054,-307.096497,0.075110,0.000000
55.490002,19.222237,-307.140961,-0.002552,0.002929,0.074400,85.504776,4.355821,0.743997,-307.140961,0.075544,0.000000
55.750004,19.853783,-307.140961,-0.002496,0.002954,0.075041,88.314034,4.498932,0.750408,-307.140961,0.075978,0.000000
56.010002,20.115929,-307.229919,-0.002518,0.002976,0.075587,89.480118,4.558334,0.755874,-307.229919,0.076412,0.000000
56.270004,19.379753,-307.229919,-0.002518,0.002987,0.075865,86.205444,4.391515,0.758652,-307.229919,0.076845,0.000000
56.530003,19.326874,-307.185455,-0.002509,0.003003,0.076272,85.970230,4.379532,0.762724,-307.185455,0.077278,0.000000
56.790001,19.748772,-307.318878,-0.002479,0.003021,0.076741,87.846924,4.475136,0.767410,-307.318878,0.077712,0.000000
57.050003,20.017250,-307.229919,-0.002496,0.003038,0.077166,89.041176,4.535974,0.771657,-307.229919,0.078146,0.000000
57.310001,19.915970,-307.274414,-0.002479,0.003051,0.077504,88.590660,4.513023,0.775041,-307.274414,0.078580,0.000000
57.570004,20.220200,-307.363373,-0.002483,0.003071,0.077998,89.943939,4.581963,0.779984,-307.363373,0.079013,0.000000
57.830002,20.658478,-307.363373,-0.002471,0.003091,0.078510,91.893501,4.681278,0.785101,-307.363373,0.079446,0.000000
58.090004,20.487930,-307.407867,-0.002432,0.003105,0.078866,91.134865,4.642631,0.788659,-307.407867,0.079880,0.000000
58.350002,20.430588,-307.318878,-0.002432,0.003120,0.079256,90.879791,4.629637,0.792557,-307.318878,0.080314,0.000000
58.610004,20.778381,-307.407867,-0.002440,0.003137,0.079681,92.426857,4.708448,0.796811,-307.407867,0.080748,0.000000
58.870003,21.398758,-307.407867,-0.002414,0.003160,0.080253,95.186432,4.849028,0.802534,-307.407867,0.081181,0.000000
59.130001,21.143677,-307.407867,-0.002419,0.003174,0.080608,94.051773,4.791226,0.806084,-307.407867,0.081614,0.000000
59.390003,21.026009,-307.496826,-0.002419,0.003186,0.080929,93.528358,4.764562,0.809294,-307.496826,0.082048,0.000000
59.650002,21.861244,-307.496826,-0.002402,0.003211,0.081563,97.243668,4.953829,0.815630,-307.496826,0.082482,0.000000
59.910004,21.879486,-307.541290,-0.002402,0.003227,0.081970,97.324814,4.957963,0.819702,-307.541290,0.082916,0.000000
60.170002,21.673195,-307.496826,-0.002376,0.003241,0.082326,96.407188,4.911216,0.823260,-307.496826,0.083349,0.000000
60.430004,22.014656,-307.541290,-0.002380,0.003259,0.082768,97.926079,4.988592,0.827681,-307.541290,0.083783,0.000000
60.690002,22.051895,-307.585785,-0.002371,0.003275,0.083184,98.091728,4.997031,0.831844,-307.585785,0.084216,0.000000
60.950005,22.328568,-307.541290,-0.002376,0.003290,0.083575,99.322426,5.059726,0.835750,-307.541290,0.084650,0.000000
61.210003,22.454430,-307.630249,-0.002341,0.003303,0.083904,99.882294,5.088246,0.839043,-307.630249,0.085084,0.000000
61.470001,22.840210,-307.630249,-0.002350,0.003320,0.084329,101.598328,5.175665,0.843290,-307.630249,0.085517,0.000000
61.730003,23.983017,-307.630249,-0.002311,0.003349,0.085075,106.681786,5.434629,0.850754,-307.630249,0.085951,0.000000
61.990002,23.824760,-307.674744,-0.002298,0.003366,0.085491,105.977829,5.398768,0.854909,-307.674744,0.086384,0.000000
62.250004,23.700386,-307.674744,-0.002298,0.003380,0.085847,105.424583,5.370584,0.858467,-307.674744,0.086818,0.000000
62.510002,24.089890,-307.674744,-0.002272,0.003399,0.086341,107.157181,5.458847,0.863410,-307.674744,0.087243,0.000000
62.770004,24.478271,-307.719208,-0.002255,0.003416,0.086757,108.884789,5.546855,0.867574,-307.719208,0.087676,0.000000
63.030003,24.628342,-307.674744,-0.002272,0.003430,0.087113,109.552338,5.580862,0.871131,-307.674744,0.088110,0.000000
63.290005,24.746010,-307.808167,-0.002281,0.003441,0.087399,110.075752,5.607526,0.873993,-307.808167,0.088544,0.000000
63.550003,25.300842,-307.763702,-0.002264,0.003463,0.087954,112.543770,5.733253,0.879541,-307.763702,0.088978,0.000000
63.810001,26.226562,-307.808167,-0.002238,0.003484,0.088492,116.661575,5.943024,0.884916,-307.808167,0.089411,0.000000
64.070000,26.622398,-307.808167,-0.002208,0.003502,0.088960,118.422340,6.032722,0.889602,-307.808167,0.089845,0.000000
64.330002,26.759430,-307.852661,-0.002216,0.003516,0.089307,119.031891,6.063774,0.893069,-307.852661,0.090278,0.000000
64.590004,27.118027,-307.897156,-0.002199,0.003532,0.089723,120.627007,6.145032,0.897232,-307.897156,0.090712,0.000000
64.850006,27.526520,-307.897156,-0.002199,0.003550,0.090183,122.444077,6.237598,0.901827,-307.897156,0.091146,0.000000
65.110001,27.618866,-307.941620,-0.002156,0.003561,0.090452,122.854851,6.258524,0.904522,-307.941620,0.091579,0.000000
65.370003,28.257858,-307.941620,-0.002151,0.003580,0.090920,125.697235,6.403322,0.909200,-307.941620,0.092013,0.000000
65.630005,29.419655,-307.986115,-0.002173,0.003604,0.091536,130.865158,6.666589,0.915362,-307.986115,0.092446,0.000000
65.889999,29.654251,-307.986115,-0.002164,0.003618,0.091900,131.908691,6.719749,0.919003,-307.986115,0.092880,0.000000
66.150002,30.356171,-307.986115,-0.002143,0.003639,0.092420,135.030991,6.878807,0.924203,-307.986115,0.093314,0.000000
66.410004,30.594864,-307.986115,-0.002160,0.003655,0.092828,136.092758,6.932895,0.928283,-307.986115,0.093747,0.000000
66.670006,31.492279,-308.030579,-0.002121,0.003674,0.093314,140.084656,7.136252,0.933136,-308.030579,0.094181,0.000000
66.930000,31.414833,-308.030579,-0.002108,0.003682,0.093522,139.740158,7.118703,0.935217,-308.030579,0.094615,0.000000
67.190002,32.188622,-308.119537,-0.002095,0.003702,0.094033,143.182144,7.294046,0.940334,-308.119537,0.095048,0.000000
67.450005,33.615547,-308.119537,-0.002074,0.003727,0.094675,149.529419,7.617392,0.946754,-308.119537,0.095482,0.000000
67.710007,33.812538,-308.119537,-0.002108,0.003740,0.095005,150.405685,7.662031,0.950046,-308.119537,0.095915,0.000000
67.970001,34.293640,-308.030579,-0.002065,0.003758,0.095447,152.545731,7.771050,0.954467,-308.030579,0.096349,0.000000
68.230003,34.918106,-308.208496,-0.002087,0.003772,0.095812,155.323486,7.912556,0.958116,-308.208496,0.096783,0.000000
68.490005,35.816269,-308.119537,-0.002082,0.003791,0.096279,159.318726,8.116082,0.962794,-308.119537,0.097217,0.000000
68.750000,36.383766,-308.164032,-0.002026,0.003805,0.096653,161.843079,8.244679,0.966526,-308.164032,0.097650,0.000000
69.010002,36.882744,-308.208496,-0.002048,0.003821,0.097052,164.062637,8.357749,0.970515,-308.208496,0.098083,0.000000
69.270004,38.456764,-308.208496,-0.002048,0.003845,0.097659,171.064224,8.714427,0.976586,-308.208496,0.098517,0.000000
69.530006,39.217522,-308.252991,-0.002001,0.003862,0.098092,174.448242,8.886817,0.980924,-308.252991,0.098951,0.000000
69.790001,39.887421,-308.252991,-0.002013,0.003877,0.098474,177.428116,9.038619,0.984739,-308.252991,0.099385,0.000000
70.050003,40.440018,-308.252991,-0.002009,0.003892,0.098855,179.886185,9.163838,0.988554,-308.252991,0.099818,0.000000
70.310005,40.737175,-308.297485,-0.002009,0.003902,0.099107,181.208008,9.231175,0.991067,-308.297485,0.100251,0.000000
70.570000,42.094101,-308.297485,-0.001983,0.003924,0.099662,187.243912,9.538660,0.996616,-308.297485,0.100685,0.000000
70.830002,42.703674,-308.341949,-0.001966,0.003938,0.100035,189.955429,9.676790,1.000348,-308.341949,0.101119,0.000000
71.090004,43.474113,-308.386444,-0.001979,0.003954,0.100425,193.382507,9.851375,1.004246,-308.386444,0.101553,0.000000
71.350006,45.245857,-308.341949,-0.001949,0.003981,0.101110,201.263626,10.252858,1.011097,-308.341949,0.101977,0.000000
71.610001,46.333191,-308.430908,-0.001975,0.003997,0.101518,206.100327,10.499251,1.015177,-308.430908,0.102411,0.000000
71.870003,46.819504,-308.386444,-0.001932,0.004009,0.101839,208.263550,10.609451,1.018387,-308.386444,0.102845,0.000000
72.130005,47.467064,-308.475403,-0.001953,0.004026,0.102272,211.144043,10.756190,1.022724,-308.475403,0.103278,0.000000
72.390007,48.717491,-308.475403,-0.001927,0.004046,0.102758,216.706223,11.039541,1.027576,-308.475403,0.103711,0.000000
72.650002,49.950783,-308.475403,-0.001932,0.004063,0.103200,222.192184,11.319009,1.031997,-308.475403,0.104145,0.000000
72.910004,50.325394,-308.475403,-0.001919,0.004076,0.103538,223.858536,11.403897,1.035381,-308.475403,0.104579,0.000000
73.170006,52.537285,-308.519867,-0.001910,0.004103,0.104223,233.697510,11.905119,1.042231,-308.519867,0.105013,0.000000
73.430000,53.365814,-308.564362,-0.001888,0.004118,0.104605,237.382996,12.092867,1.046047,-308.564362,0.105446,0.000000
73.690002,54.234932,-308.519867,-0.001893,0.004132,0.104943,241.249023,12.289811,1.049430,-308.519867,0.105879,0.000000
73.950005,54.567833,-308.564362,-0.001901,0.004142,0.105212,242.729843,12.365248,1.052118,-308.564362,0.106313,0.000000
74.210007,56.060303,-308.653320,-0.001871,0.004164,0.105758,249.368683,12.703446,1.057583,-308.653320,0.106747,0.000000
74.470001,57.029961,-308.564362,-0.001876,0.004177,0.106105,253.681931,12.923174,1.061050,-308.564362,0.107181,0.000000
74.730003,58.067764,-308.697815,-0.001893,0.004193,0.106496,258.298309,13.158343,1.064956,-308.697815,0.107614,0.000000
74.990005,59.261963,-308.653320,-0.001863,0.004209,0.106920,263.610382,13.428953,1.069203,-308.653320,0.108048,0.000000
75.250000,61.279846,-308.653320,-0.001871,0.004233,0.107527,272.586365,13.886211,1.075274,-308.653320,0.108481,0.000000
75.510002,61.864098,-308.742279,-0.001832,0.004245,0.107831,275.185242,14.018605,1.078309,-308.742279,0.108915,0.000000
75.770004,63.178574,-308.653320,-0.001828,0.004263,0.108273,281.032318,14.316469,1.082730,-308.653320,0.109349,0.000000
76.030006,64.348572,-308.786774,-0.001807,0.004278,0.108672,286.236755,14.581594,1.086719,-308.786774,0.109782,0.000000
76.290001,65.530853,-308.697815,-0.001824,0.004297,0.109150,291.495789,14.849504,1.091496,-308.697815,0.110216,0.000000
76.550003,66.587646,-308.786774,-0.001824,0.004309,0.109444,296.196655,15.088976,1.094440,-308.786774,0.110649,0.000000
76.810005,67.515228,-308.831238,-0.001832,0.004314,0.109574,300.322723,15.299170,1.095742,-308.831238,0.109817,0.000000
77.070007,66.961502,-308.786774,-0.001802,0.004314,0.109574,297.859650,15.173693,1.095742,-308.786774,0.109817,0.000000
77.330002,66.554871,-308.875732,-0.001807,0.004313,0.109548,296.050842,15.081549,1.095485,-308.875732,0.109574,0.000000
77.590004,66.181015,-308.831238,-0.001811,0.004312,0.109531,294.387848,14.996832,1.095311,-308.831238,0.109574,0.000000
77.850006,65.847366,-308.875732,-0.001802,0.004312,0.109522,292.903717,14.921227,1.095220,-308.875732,0.109574,0.000000
78.110001,65.553192,-308.875732,-0.001789,0.004312,0.109522,291.595154,14.854566,1.095220,-308.875732,0.109574,0.000000
78.370003,65.297379,-308.920197,-0.001768,0.004312,0.109514,290.457245,14.796597,1.095137,-308.920197,0.109574,0.000000
78.630005,65.066498,-309.009155,-0.001789,0.004312,0.109514,289.430237,14.744279,1.095137,-309.009155,0.109574,0.000000
78.890007,64.873978,-308.964691,-0.001755,0.004312,0.109514,288.573853,14.700653,1.095137,-308.964691,0.109574,0.000000
79.150002,64.688171,-309.009155,-0.001802,0.004312,0.109514,287.747345,14.658549,1.095137,-309.009155,0.109574,0.000000
79.410004,64.513153,-308.964691,-0.001789,0.004312,0.109514,286.968842,14.618890,1.095137,-308.964691,0.109574,0.000000
79.670006,64.368668,-309.009155,-0.001763,0.004312,0.109514,286.326141,14.586148,1.095137,-309.009155,0.109574,0.000000
79.930000,64.223816,-309.098114,-0.001785,0.004312,0.109514,285.681793,14.553325,1.095137,-309.098114,0.109574,0.000000
80.190002,64.096466,-309.053650,-0.001789,0.004312,0.109514,285.115326,14.524467,1.095137,-309.053650,0.109574,0.000000
80.450005,63.985504,-309.142609,-0.001785,0.004312,0.109514,284.621735,14.499322,1.095137,-309.142609,0.109574,0.000000
80.710007,63.862625,-309.053650,-0.001776,0.004312,0.109514,284.075134,14.471478,1.095137,-309.053650,0.109574,0.000000
80.970001,63.756866,-309.142609,-0.001759,0.004312,0.109514,283.604706,14.447513,1.095137,-309.142609,0.109574,0.000000
81.230003,63.648880,-309.142609,-0.001776,0.004312,0.109514,283.124359,14.423043,1.095137,-309.142609,0.109574,0.000000
81.490005,63.561005,-309.142609,-0.001785,0.004312,0.109514,282.733459,14.403130,1.095137,-309.142609,0.109574,0.000000
81.750008,63.477585,-309.142609,-0.001772,0.004312,0.109514,282.362396,14.384226,1.095137,-309.142609,0.109574,0.000000
82.010002,63.383011,-309.142609,-0.001785,0.004312,0.109514,281.941711,14.362796,1.095137,-309.142609,0.109574,0.000000
82.270004,63.315979,-309.231567,-0.001759,0.004312,0.109514,281.643555,14.347606,1.095137,-309.231567,0.109574,0.000000
82.530006,63.229958,-309.276062,-0.001759,0.004312,0.109514,281.260895,14.328114,1.095137,-309.276062,0.109574,0.000000
82.790001,63.156975,-309.231567,-0.001776,0.004312,0.109514,280.936249,14.311575,1.095137,-309.231567,0.109574,0.000000
83.050003,63.111549,-309.320526,-0.001807,0.004312,0.109514,280.734192,14.301281,1.095137,-309.320526,0.109574,0.000000
83.310005,63.023293,-309.276062,-0.001789,0.004312,0.109514,280.341614,14.281282,1.095137,-309.276062,0.109574,0.000000
83.570007,62.959618,-309.320526,-0.001763,0.004312,0.109514,280.058380,14.266853,1.095137,-309.320526,0.109574,0.000000
83.830002,62.913445,-309.409485,-0.001772,0.004312,0.109514,279.852966,14.256391,1.095137,-309.409485,0.109574,0.000000
84.090004,62.842690,-309.320526,-0.001772,0.004312,0.109514,279.538239,14.240357,1.095137,-309.320526,0.109574,0.000000
84.350006,62.780510,-309.453979,-0.001763,0.004312,0.109514,279.261658,14.226267,1.095137,-309.453979,0.109574,0.000000
84.610001,62.728745,-309.365021,-0.001798,0.004312,0.109514,279.031403,14.214537,1.095137,-309.365021,0.109574,0.000000
84.870003,62.694489,-309.365021,-0.001785,0.004312,0.109514,278.879028,14.206774,1.095137,-309.365021,0.109574,0.000000
85.130005,62.630066,-309.453979,-0.001772,0.004312,0.109514,278.592438,14.192176,1.095137,-309.453979,0.109574,0.000000
85.390007,62.582405,-309.409485,-0.001776,0.004312,0.109514,278.380432,14.181376,1.095137,-309.409485,0.109574,0.000000
85.650002,62.535858,-309.498444,-0.001789,0.004312,0.109514,278.173401,14.170828,1.095137,-309.498444,0.109574,0.000000
85.910004,62.496017,-309.453979,-0.001794,0.004312,0.109514,277.996155,14.161799,1.095137,-309.453979,0.109574,0.000000
86.170006,62.438667,-309.542938,-0.001768,0.004312,0.109514,277.741058,14.148804,1.095137,-309.542938,0.109574,0.000000
86.430000,62.411110,-309.542938,-0.001781,0.004312,0.109514,277.618469,14.142560,1.095137,-309.542938,0.109574,0.000000
86.690002,62.371269,-309.453979,-0.001759,0.004312,0.109514,277.441254,14.133532,1.095137,-309.453979,0.109574,0.000000
86.950005,62.315414,-309.631897,-0.001746,0.004312,0.109514,277.192810,14.120875,1.095137,-309.631897,0.109574,0.000000
87.210007,62.281158,-309.587433,-0.001794,0.004312,0.109514,277.040436,14.113112,1.095137,-309.587433,0.109574,0.000000
87.470001,62.253975,-309.676392,-0.001759,0.004312,0.109514,276.919525,14.106953,1.095137,-309.676392,0.109574,0.000000
87.730003,62.200722,-309.676392,-0.001768,0.004312,0.109514,276.682617,14.094886,1.095137,-309.676392,0.109574,0.000000
87.990005,62.161995,-309.631897,-0.001750,0.004312,0.109514,276.510376,14.086109,1.095137,-309.631897,0.109574,0.000000
88.250008,62.134438,-309.720856,-0.001798,0.004312,0.109514,276.387787,14.079865,1.095137,-309.720856,0.109574,0.000000
88.510002,62.095711,-309.720856,-0.001789,0.004312,0.109514,276.215515,14.071089,1.095137,-309.720856,0.109574,0.000000
88.770004,62.065926,-309.720856,-0.001768,0.004312,0.109514,276.083038,14.064341,1.095137,-309.720856,0.109574,0.000000
89.030006,62.025711,-309.765350,-0.001755,0.004312,0.109514,275.904144,14.055227,1.095137,-309.765350,0.109574,0.000000
89.290001,61.987350,-309.676392,-0.001759,0.004312,0.109514,275.733521,14.046535,1.095137,-309.676392,0.109574,0.000000
89.550003,61.965759,-309.898773,-0.001759,0.004312,0.109514,275.637451,14.041641,1.095137,-309.898773,0.109574,0.000000
89.810005,61.932243,-309.809814,-0.001750,0.004312,0.109514,275.488373,14.034047,1.095137,-309.809814,0.109574,0.000000
90.070007,61.899101,-309.854309,-0.001755,0.004312,0.109514,275.340942,14.026537,1.095137,-309.854309,0.109574,0.000000
90.330002,61.876762,-309.809814,-0.001759,0.004312,0.109514,275.241577,14.021475,1.095137,-309.809814,0.109574,0.000000
90.590004,61.845108,-309.809814,-0.001746,0.004312,0.109514,275.100769,14.014301,1.095137,-309.809814,0.109574,0.000000
90.850006,61.822762,-309.898773,-0.001763,0.004312,0.109514,275.001373,14.009238,1.095137,-309.898773,0.109574,0.000000
91.110001,61.794464,-309.854309,-0.001781,0.004312,0.109514,274.875519,14.002826,1.095137,-309.854309,0.109574,0.000000
91.370003,61.754250,-309.943268,-0.001755,0.004312,0.109514,274.696625,13.993712,1.095137,-309.943268,0.109574,0.000000
91.630005,61.736374,-309.943268,-0.001776,0.004312,0.109514,274.617096,13.989662,1.095137,-309.943268,0.109574,0.000000
91.890007,61.713661,-309.943268,-0.001759,0.004312,0.109514,274.516083,13.984515,1.095137,-309.943268,0.109574,0.000000
92.150002,61.683495,-309.943268,-0.001768,0.004312,0.109514,274.381897,13.977679,1.095137,-309.943268,0.109574,0.000000
92.410004,61.663017,-309.987762,-0.001755,0.004312,0.109514,274.290802,13.973040,1.095137,-309.987762,0.109574,0.000000
92.670006,61.641418,-310.076721,-0.001768,0.004312,0.109514,274.194733,13.968145,1.095137,-310.076721,0.109574,0.000000
92.930008,61.607536,-309.987762,-0.001781,0.004312,0.109514,274.044006,13.960467,1.095137,-309.987762,0.109574,0.000000
93.190002,61.590401,-310.032227,-0.001742,0.004312,0.109514,273.967773,13.956584,1.095137,-310.032227,0.109574,0.000000
93.450005,61.569923,-310.165680,-0.001776,0.004312,0.109514,273.876709,13.951944,1.095137,-310.165680,0.109574,0.000000
93.710007,61.533806,-310.032227,-0.001772,0.004312,0.109514,273.716034,13.943760,1.095137,-310.032227,0.109574,0.000000
93.970001,61.527100,-310.121185,-0.001763,0.004312,0.109514,273.686218,13.942240,1.095137,-310.121185,0.109574,0.000000
94.230003,61.487633,-310.165680,-0.001798,0.004312,0.109514,273.510651,13.933297,1.095137,-310.165680,0.109574,0.000000
94.490005,61.475716,-310.121185,-0.001768,0.004312,0.109514,273.457642,13.930596,1.095137,-310.121185,0.109574,0.000000
94.750008,61.458214,-310.210144,-0.001781,0.004312,0.109514,273.379791,13.926631,1.095137,-310.210144,0.109574,0.000000
95.010002,61.437729,-310.165680,-0.001746,0.004312,0.109514,273.288666,13.921988,1.095137,-310.165680,0.109574,0.000000
95.270004,61.417625,-310.165680,-0.001781,0.004312,0.109514,273.199249,13.917434,1.095137,-310.165680,0.109574,0.000000
95.530006,61.393044,-310.254639,-0.001755,0.004312,0.109514,273.089905,13.911863,1.095137,-310.254639,0.109574,0.000000
95.790001,61.368843,-310.254639,-0.001746,0.004312,0.109514,272.982239,13.906379,1.095137,-310.254639,0.109574,0.000000
96.050003,61.359161,-310.299103,-0.001781,0.004312,0.109514,272.939178,13.904184,1.095137,-310.299103,0.109574,0.000000
96.310005,61.323784,-310.254639,-0.001794,0.004312,0.109514,272.781799,13.896168,1.095137,-310.254639,0.109574,0.000000
96.570007,61.311501,-310.388062,-0.001750,0.004312,0.109514,272.727173,13.893385,1.095137,-310.388062,0.109574,0.000000
96.830002,61.302559,-310.254639,-0.001750,0.004312,0.109514,272.687408,13.891358,1.095137,-310.254639,0.109574,0.000000
97.090004,61.258995,-310.299103,-0.001768,0.004312,0.109514,272.493622,13.881486,1.095137,-310.299103,0.109574,0.000000
97.350006,61.260109,-310.388062,-0.001750,0.004312,0.109514,272.498566,13.881739,1.095137,-310.388062,0.109574,0.000000
97.610008,61.229950,-310.254639,-0.001768,0.004312,0.109514,272.364410,13.874905,1.095137,-310.254639,0.109574,0.000000
97.870003,61.208351,-310.432556,-0.001768,0.004312,0.109514,272.268341,13.870010,1.095137,-310.432556,0.109574,0.000000
98.130005,61.199783,-310.432556,-0.001768,0.004312,0.109514,272.230225,13.868070,1.095137,-310.432556,0.109574,0.000000
98.390007,61.184143,-310.388062,-0.001763,0.004312,0.109514,272.160675,13.864525,1.095137,-310.388062,0.109574,0.000000
98.650002,61.171486,-310.521515,-0.001772,0.004312,0.109514,272.104370,13.861656,1.095137,-310.521515,0.109574,0.000000
98.910004,61.131638,-310.432556,-0.001772,0.004312,0.109514,271.927094,13.852627,1.095137,-310.432556,0.109574,0.000000
99.170006,61.125313,-310.566010,-0.001755,0.004312,0.109514,271.898956,13.851193,1.095137,-310.566010,0.109574,0.000000
99.430008,61.111534,-310.477051,-0.001742,0.004312,0.109514,271.837677,13.848071,1.095137,-310.477051,0.109574,0.000000
99.690002,61.097382,-310.521515,-0.001759,0.004312,0.109514,271.774719,13.844864,1.095137,-310.521515,0.109574,0.000000
99.950005,61.069824,-310.566010,-0.001742,0.004312,0.109514,271.652161,13.838620,1.095137,-310.566010,0.109574,0.000000
100.210007,61.053818,-310.566010,-0.001755,0.004312,0.109514,271.580933,13.834993,1.095137,-310.566010,0.109574,0.000000
100.470001,61.028496,-310.566010,-0.001750,0.004312,0.109514,271.468292,13.829255,1.095137,-310.566010,0.109574,0.000000
100.730003,61.028496,-310.566010,-0.001750,0.004312,0.109514,271.468292,13.829255,1.095137,-310.566010,0.109574,0.000000
100.990005,61.008759,-310.610474,-0.001742,0.004312,0.109514,271.380524,13.824782,1.095137,-310.610474,0.109574,0.000000
101.250008,60.989021,-310.699432,-0.001776,0.004312,0.109514,271.292725,13.820310,1.095137,-310.699432,0.109574,0.000000
101.510002,60.977852,-310.654968,-0.001763,0.004312,0.109514,271.243042,13.817779,1.095137,-310.654968,0.109574,0.000000
101.770004,60.951042,-310.654968,-0.001776,0.004312,0.109514,271.123779,13.811704,1.095137,-310.654968,0.109574,0.000000
102.030006,60.951042,-310.743927,-0.001794,0.004312,0.109514,271.123779,13.811704,1.095137,-310.743927,0.109574,0.000000
102.290009,60.924599,-310.699432,-0.001763,0.004312,0.109514,271.006165,13.805712,1.095137,-310.699432,0.109574,0.000000
102.550003,60.911568,-310.743927,-0.001763,0.004312,0.109514,270.948181,13.802758,1.095137,-310.743927,0.109574,0.000000
102.810005,60.903374,-310.743927,-0.001763,0.004312,0.109514,270.911743,13.800902,1.095137,-310.743927,0.109574,0.000000
103.070007,60.879173,-310.832886,-0.001772,0.004312,0.109514,270.804077,13.795418,1.095137,-310.832886,0.109574,0.000000
103.330002,60.865395,-310.832886,-0.001768,0.004312,0.109514,270.742798,13.792295,1.095137,-310.832886,0.109574,0.000000
103.590004,60.854225,-310.832886,-0.001755,0.004312,0.109514,270.693115,13.789764,1.095137,-310.832886,0.109574,0.000000
103.850006,60.835602,-310.921844,-0.001750,0.004312,0.109514,270.610260,13.785544,1.095137,-310.921844,0.109574,0.000000
104.110008,60.828903,-310.877380,-0.001776,0.004312,0.109514,270.580475,13.784027,1.095137,-310.877380,0.109574,0.000000
104.370003,60.797623,-310.877380,-0.001772,0.004312,0.109514,270.441345,13.776938,1.095137,-310.877380,0.109574,0.000000
104.630005,60.794647,-310.921844,-0.001781,0.004312,0.109514,270.428101,13.776264,1.095137,-310.921844,0.109574,0.000000
104.890007,60.782730,-310.921844,-0.001776,0.004312,0.109514,270.375092,13.773563,1.095137,-310.921844,0.109574,0.000000
105.150002,60.760017,-310.966339,-0.001755,0.004312,0.109514,270.274048,13.768416,1.095137,-310.966339,0.109574,0.000000
105.410004,60.759270,-310.921844,-0.001789,0.004312,0.109514,270.270721,13.768248,1.095137,-310.921844,0.109574,0.000000
105.670006,60.730972,-311.055298,-0.001750,0.004312,0.109514,270.144867,13.761835,1.095137,-311.055298,0.109574,0.000000
105.930008,60.736923,-310.966339,-0.001763,0.004312,0.109514,270.171326,13.763184,1.095137,-310.966339,0.109574,0.000000
106.190002,60.711609,-311.010803,-0.001742,0.004312,0.109514,270.058716,13.757447,1.095137,-311.010803,0.109574,0.000000
106.450005,60.694473,-311.144257,-0.001768,0.004312,0.109514,269.982513,13.753565,1.095137,-311.144257,0.109574,0.000000
106.710007,60.704903,-311.010803,-0.001755,0.004312,0.109514,270.028900,13.755927,1.095137,-311.010803,0.109574,0.000000
106.970009,60.671013,-311.099762,-0.001789,0.004312,0.109514,269.878143,13.748248,1.095137,-311.099762,0.109574,0.000000
107.230003,60.669151,-311.099762,-0.001746,0.004312,0.109514,269.869873,13.747826,1.095137,-311.099762,0.109574,0.000000
107.300003,60.661331,-311.144257,-0.001776,0.004312,0.109514,269.835083,13.746054,1.095137,-311.144257,0.109574,0.000000