File: Data/compression 14/AutoNoHeating-12-14-5-240726_07262024_164850.csv
Time (sec),S:Load (lbs),S:HL1 (DIM),S:LVDT (in),S:Position (in),Ch:Position (mm),Ch:Load (N),Ch:Stress (MPa),Ch:Strain (mm/mm),Ch:HL1 (DIM),Set Point (),Cycles ()
0.110000,-0.026070,-394.412598,-0.011408,-0.006553,-0.166455,-0.115964,-0.005907,-1.664551,-394.412598,-0.166230,0.000000
0.370000,-0.039848,-394.457062,-0.011417,-0.006553,-0.166455,-0.177254,-0.009030,-1.664551,-394.457062,-0.166230,0.000000
0.630000,-0.009682,-394.457062,-0.011374,-0.006436,-0.163464,-0.043066,-0.002194,-1.634636,-394.457062,-0.162553,0.000000
0.890000,0.011917,-394.457062,-0.011275,-0.006281,-0.159535,0.053010,0.002700,-1.595348,-394.457062,-0.158234,0.000000
1.150000,-0.017128,-394.457062,-0.011106,-0.006101,-0.154965,-0.076189,-0.003881,-1.549650,-394.457062,-0.153898,0.000000
1.410000,-0.013779,-394.546051,-0.010934,-0.005931,-0.150637,-0.061291,-0.003122,-1.506373,-394.546051,-0.149562,0.000000
1.670000,-0.014526,-394.546051,-0.010727,-0.005762,-0.146353,-0.064617,-0.003292,-1.463528,-394.546051,-0.145226,0.000000
1.930000,-0.063675,-394.546051,-0.010550,-0.005591,-0.142017,-0.283240,-0.014429,-1.420168,-394.546051,-0.140907,0.000000
2.190000,-0.018250,-394.635010,-0.010391,-0.005425,-0.137785,-0.081178,-0.004135,-1.377846,-394.635010,-0.136570,0.000000
2.450000,0.001488,-394.546051,-0.010205,-0.005246,-0.133240,0.006618,0.000337,-1.332404,-394.546051,-0.132234,0.000000
2.710000,-0.020851,-394.590515,-0.010020,-0.005082,-0.129095,-0.092750,-0.004725,-1.290952,-394.590515,-0.127898,0.000000
2.970000,-0.006332,-394.635010,-0.009860,-0.004909,-0.124690,-0.028168,-0.001435,-1.246896,-394.635010,-0.123580,0.000000
3.230000,0.013405,-394.546051,-0.009697,-0.004748,-0.120588,0.059628,0.003038,-1.205875,-394.546051,-0.119244,0.000000
3.490000,-0.026070,-394.635010,-0.009464,-0.004566,-0.115983,-0.115964,-0.005907,-1.159828,-394.635010,-0.114907,0.000000
3.750000,-0.018623,-394.546051,-0.009309,-0.004400,-0.111768,-0.082841,-0.004220,-1.117679,-394.546051,-0.110571,0.000000
4.010000,-0.019737,-394.723969,-0.009132,-0.004221,-0.107224,-0.087796,-0.004473,-1.072238,-394.723969,-0.106253,0.000000
4.270000,-0.068520,-394.635010,-0.008942,-0.004057,-0.103044,-0.304790,-0.015527,-1.030438,-394.635010,-0.101917,0.000000
4.530000,0.007820,-394.679474,-0.008783,-0.003891,-0.098829,0.034786,0.001772,-0.988289,-394.679474,-0.097580,0.000000
4.790000,0.011169,-394.768433,-0.008593,-0.003711,-0.094250,0.049684,0.002531,-0.942499,-394.768433,-0.093244,0.000000
5.050000,-0.006706,-394.723969,-0.008429,-0.003546,-0.090079,-0.029831,-0.001520,-0.900790,-394.723969,-0.088925,0.000000
5.310000,0.002975,-394.723969,-0.008218,-0.003380,-0.085855,0.013236,0.000674,-0.858550,-394.723969,-0.084589,0.000000
5.570000,0.007820,-394.812927,-0.008067,-0.003196,-0.081190,0.034786,0.001772,-0.811898,-394.812927,-0.080253,0.000000
5.830000,-0.015640,-394.723969,-0.007838,-0.003035,-0.077079,-0.069571,-0.003544,-0.770794,-394.723969,-0.075934,0.000000
6.090000,0.007446,-394.768433,-0.007687,-0.002861,-0.072674,0.033123,0.001687,-0.726738,-394.768433,-0.071598,0.000000
6.350000,-0.019737,-394.812927,-0.007528,-0.002689,-0.068303,-0.087796,-0.004473,-0.683030,-394.812927,-0.067262,0.000000
6.610000,-0.032028,-394.812927,-0.007368,-0.002524,-0.064106,-0.142469,-0.007258,-0.641055,-394.812927,-0.062926,0.000000
6.870000,0.031654,-394.768433,-0.007161,-0.002353,-0.059778,0.140806,0.007173,-0.597779,-394.768433,-0.058607,0.000000
7.130000,0.020103,-394.812927,-0.006963,-0.002176,-0.055269,0.089425,0.004556,-0.552685,-394.812927,-0.054271,0.000000
7.390000,0.001114,-394.812927,-0.006825,-0.002012,-0.051106,0.004955,0.000252,-0.511059,-394.812927,-0.049935,0.000000
7.650001,0.013031,-394.857391,-0.006605,-0.001844,-0.046839,0.057965,0.002953,-0.468388,-394.857391,-0.045599,0.000000
7.910000,-0.003349,-394.946350,-0.006416,-0.001664,-0.042269,-0.014898,-0.000759,-0.422689,-394.946350,-0.041280,0.000000
8.170000,-0.011917,-394.946350,-0.006247,-0.001501,-0.038123,-0.053010,-0.002700,-0.381230,-394.946350,-0.036944,0.000000
8.430000,0.005585,-394.901886,-0.006079,-0.001336,-0.033926,0.024842,0.001266,-0.339255,-394.901886,-0.032608,0.000000
8.690001,-0.027557,-394.990845,-0.005894,-0.001154,-0.029321,-0.122581,-0.006245,-0.293208,-394.990845,-0.028272,0.000000
8.950001,0.004471,-394.901886,-0.005730,-0.000986,-0.025037,0.019887,0.001013,-0.250371,-394.901886,-0.023953,0.000000
9.210000,0.039101,-394.946350,-0.005519,-0.000819,-0.020813,0.173928,0.008860,-0.208131,-394.946350,-0.019616,0.000000
9.470000,0.018990,-394.990845,-0.005372,-0.000648,-0.016451,0.084470,0.004303,-0.164514,-394.990845,-0.015280,0.000000
9.730000,0.015266,-394.990845,-0.005170,-0.000470,-0.011933,0.067908,0.003459,-0.119330,-394.990845,-0.010944,0.000000
9.990001,0.021973,-395.035339,-0.004984,-0.000308,-0.007814,0.097739,0.004979,-0.078135,-395.035339,-0.006626,0.000000
10.250001,0.031281,-394.990845,-0.004833,-0.000134,-0.003400,0.139143,0.007088,-0.033996,-394.990845,-0.002290,0.000000
10.510000,0.721283,-394.990845,-0.004682,-0.000000,-0.000000,3.208427,0.163445,-0.000000,-394.990845,0.000226,0.000000
10.770000,0.657608,-395.124298,-0.004678,-0.000000,-0.000000,2.925187,0.149016,-0.000000,-395.124298,0.000226,0.000000
11.030001,0.638618,-395.035339,-0.004674,-0.000000,-0.000000,2.840717,0.144713,-0.000000,-395.035339,0.000304,0.000000
11.290001,0.664314,-395.124298,-0.004687,-0.000000,-0.000000,2.955018,0.150536,-0.000000,-395.124298,0.000737,0.000000
11.550000,0.642342,-395.079803,-0.004678,-0.000000,-0.000000,2.857278,0.145557,-0.000000,-395.079803,0.001171,0.000000
11.810000,0.761871,-395.124298,-0.004674,0.000027,0.000685,3.388973,0.172643,0.006851,-395.124298,0.001605,0.000000
12.070001,1.152489,-395.168762,-0.004652,0.000045,0.001136,5.126526,0.261158,0.011362,-395.168762,0.002038,0.000000
12.330001,1.253029,-395.168762,-0.004648,0.000055,0.001405,5.573751,0.283940,0.014050,-395.168762,0.002472,0.000000
12.590000,1.558746,-395.124298,-0.004609,0.000082,0.002073,6.933650,0.353217,0.020726,-395.124298,0.002905,0.000000
12.850000,1.817177,-395.124298,-0.004579,0.000100,0.002541,8.083206,0.411778,0.025412,-395.124298,0.003339,0.000000
13.110001,2.028313,-395.257721,-0.004592,0.000116,0.002948,9.022386,0.459622,0.029484,-395.257721,0.003773,0.000000
13.370001,2.153427,-395.213257,-0.004544,0.000128,0.003244,9.578922,0.487974,0.032437,-395.213257,0.004207,0.000000
13.630001,2.311317,-395.213257,-0.004553,0.000141,0.003590,10.281254,0.523752,0.035904,-395.213257,0.004640,0.000000
13.890000,2.771942,-395.302216,-0.004510,0.000164,0.004172,12.330215,0.628131,0.041717,-395.302216,0.005073,0.000000
14.150001,2.890724,-395.257721,-0.004531,0.000177,0.004501,12.858583,0.655047,0.045010,-395.257721,0.005507,0.000000
14.410001,2.916794,-395.302216,-0.004531,0.000183,0.004649,12.974547,0.660955,0.046486,-395.302216,0.005941,0.000000
14.670001,3.628395,-395.257721,-0.004510,0.000221,0.005602,16.139908,0.822206,0.056024,-395.257721,0.006375,0.000000
14.930000,3.755379,-395.257721,-0.004471,0.000235,0.005967,16.704760,0.850981,0.059665,-395.257721,0.006808,0.000000
15.190001,3.973213,-395.346680,-0.004471,0.000250,0.006340,17.673735,0.900343,0.063397,-395.346680,0.007241,0.000000
15.450001,4.271111,-395.346680,-0.004437,0.000265,0.006739,18.998848,0.967847,0.067386,-395.346680,0.007675,0.000000
15.710001,4.540337,-395.302216,-0.004449,0.000282,0.007172,20.196426,1.028855,0.071724,-395.302216,0.008109,0.000000
15.970001,4.871376,-395.346680,-0.004411,0.000301,0.007649,21.668962,1.103870,0.076493,-395.346680,0.008543,0.000000
16.230001,4.905632,-395.346680,-0.004402,0.000309,0.007857,21.821341,1.111632,0.078574,-395.346680,0.008976,0.000000
16.490002,5.448555,-395.435669,-0.004368,0.000336,0.008525,24.236383,1.234660,0.085251,-395.435669,0.009409,0.000000
16.750000,5.803055,-395.391174,-0.004355,0.000356,0.009054,25.813276,1.314991,0.090542,-395.391174,0.009843,0.000000
17.010000,5.854439,-395.435669,-0.004342,0.000367,0.009331,26.041843,1.326635,0.093313,-395.435669,0.010277,0.000000
17.270000,6.128876,-395.480133,-0.004355,0.000384,0.009748,27.262600,1.388823,0.097476,-395.480133,0.010710,0.000000
17.530001,6.386185,-395.435669,-0.004333,0.000398,0.010112,28.407167,1.447130,0.101117,-395.435669,0.011144,0.000000
17.790001,6.942513,-395.480133,-0.004324,0.000425,0.010788,30.881838,1.573196,0.107885,-395.480133,0.011577,0.000000
18.050001,6.818138,-395.435669,-0.004299,0.000433,0.010997,30.328592,1.545012,0.109966,-395.435669,0.012011,0.000000
18.310001,7.398666,-395.524628,-0.004273,0.000455,0.011551,32.910912,1.676562,0.115515,-395.524628,0.012445,0.000000
18.570002,7.683533,-395.524628,-0.004264,0.000475,0.012072,34.178059,1.741113,0.120715,-395.524628,0.012878,0.000000
18.830002,7.786308,-395.524628,-0.004251,0.000491,0.012462,34.635227,1.764403,0.124621,-395.524628,0.013303,0.000000
19.090000,7.918503,-395.524628,-0.004212,0.000504,0.012801,35.223259,1.794358,0.128005,-395.524628,0.013737,0.000000
19.350000,8.337044,-395.480133,-0.004191,0.000522,0.013260,37.085022,1.889201,0.132600,-395.480133,0.014171,0.000000
19.610001,8.428276,-395.569092,-0.004186,0.000536,0.013624,37.490845,1.909875,0.136241,-395.569092,0.014604,0.000000
19.870001,8.822250,-395.613586,-0.004186,0.000554,0.014084,39.243328,1.999151,0.140836,-395.613586,0.015038,0.000000
20.130001,8.952202,-395.569092,-0.004143,0.000568,0.014439,39.821384,2.028598,0.144394,-395.569092,0.015471,0.000000
20.390001,9.502945,-395.658051,-0.004169,0.000592,0.015038,42.271210,2.153398,0.150381,-395.658051,0.015905,0.000000
20.650002,9.797867,-395.569092,-0.004139,0.000614,0.015593,43.583088,2.220228,0.155930,-395.569092,0.016339,0.000000
20.910002,9.743866,-395.702545,-0.004109,0.000627,0.015914,43.342880,2.207992,0.159140,-395.702545,0.016772,0.000000
21.170000,9.848137,-395.658051,-0.004113,0.000640,0.016252,43.806702,2.231620,0.162516,-395.658051,0.017206,0.000000
21.430000,10.167625,-395.702545,-0.004079,0.000657,0.016677,45.227856,2.304017,0.166770,-395.702545,0.017640,0.000000
21.690001,10.539253,-395.702545,-0.004074,0.000677,0.017189,46.880939,2.388229,0.171887,-395.702545,0.018073,0.000000
21.950001,10.679268,-395.702545,-0.004083,0.000692,0.017588,47.503757,2.419957,0.175876,-395.702545,0.018507,0.000000
22.210001,10.655434,-395.658051,-0.004053,0.000704,0.017882,47.397736,2.414556,0.178821,-395.658051,0.018940,0.000000
22.470001,11.117920,-395.747009,-0.004036,0.000723,0.018359,49.454979,2.519357,0.183590,-395.747009,0.019374,0.000000
22.730001,11.582642,-395.702545,-0.004027,0.000743,0.018880,51.522163,2.624664,0.188798,-395.702545,0.019808,0.000000
22.990002,11.533119,-395.791504,-0.004014,0.000760,0.019296,51.301876,2.613442,0.192962,-395.791504,0.020241,0.000000
23.250002,11.813889,-395.791504,-0.004010,0.000776,0.019721,52.550800,2.677065,0.197208,-395.791504,0.020675,0.000000
23.510000,11.981453,-395.835999,-0.004001,0.000792,0.020120,53.296165,2.715036,0.201197,-395.835999,0.021108,0.000000
23.770000,12.166527,-395.791504,-0.003980,0.000811,0.020597,54.119415,2.756974,0.205966,-395.791504,0.021542,0.000000
24.030001,12.048111,-395.835999,-0.003967,0.000819,0.020805,53.592674,2.730141,0.208048,-395.835999,0.021976,0.000000
24.290001,12.314354,-395.880463,-0.003932,0.000835,0.021204,54.776981,2.790473,0.212037,-395.880463,0.022410,0.000000
24.550001,13.276566,-395.835999,-0.003923,0.000866,0.022002,59.057114,3.008513,0.220016,-395.835999,0.022843,0.000000
24.810001,12.877014,-395.969421,-0.003898,0.000875,0.022227,57.279819,2.917973,0.222272,-395.969421,0.023276,0.000000
25.070002,13.273956,-395.924957,-0.003893,0.000897,0.022774,59.045506,3.007921,0.227737,-395.924957,0.023710,0.000000
25.330002,13.592339,-395.924957,-0.003876,0.000919,0.023346,60.461742,3.080068,0.233460,-395.924957,0.024144,0.000000
25.590002,13.650803,-395.969421,-0.003850,0.000935,0.023753,60.721802,3.093316,0.237532,-395.969421,0.024578,0.000000
25.850000,13.457169,-395.924957,-0.003854,0.000945,0.024005,59.860474,3.049438,0.240053,-395.924957,0.025011,0.000000
26.110001,13.826935,-396.058380,-0.003837,0.000964,0.024482,61.505280,3.133228,0.244822,-396.058380,0.025444,0.000000
26.370001,14.480072,-396.058380,-0.003824,0.000990,0.025141,64.410576,3.281231,0.251408,-396.058380,0.025878,0.000000
26.630001,14.366875,-396.102875,-0.003807,0.001004,0.025514,63.907051,3.255580,0.255140,-396.102875,0.026312,0.000000
26.890001,14.295753,-396.058380,-0.003803,0.001018,0.025852,63.590687,3.239464,0.258523,-396.058380,0.026746,0.000000
27.150002,14.638702,-395.969421,-0.003777,0.001036,0.026320,65.116203,3.317177,0.263202,-395.969421,0.027179,0.000000
27.410002,14.846489,-396.102875,-0.003764,0.001053,0.026754,66.040482,3.364262,0.267539,-396.102875,0.027612,0.000000
27.670002,14.876282,-396.102875,-0.003725,0.001067,0.027101,66.173004,3.371014,0.271006,-396.102875,0.028046,0.000000
27.930002,14.541519,-396.102875,-0.003742,0.001073,0.027257,64.683907,3.295155,0.272573,-396.102875,0.028471,0.000000
28.190001,15.676132,-396.147339,-0.003760,0.001106,0.028081,69.730919,3.552262,0.280809,-396.147339,0.028904,0.000000
28.450001,15.801628,-396.102875,-0.003721,0.001125,0.028567,70.289154,3.580700,0.285669,-396.102875,0.029338,0.000000
28.710001,15.677628,-396.191833,-0.003704,0.001138,0.028914,69.737572,3.552601,0.289136,-396.191833,0.029772,0.000000
28.970001,15.590118,-396.147339,-0.003712,0.001151,0.029243,69.348312,3.532771,0.292429,-396.147339,0.030206,0.000000
29.230001,15.689537,-396.191833,-0.003682,0.001168,0.029659,69.790543,3.555300,0.296592,-396.191833,0.030639,0.000000
29.490002,16.142342,-396.280792,-0.003669,0.001186,0.030128,71.804718,3.657907,0.301278,-396.280792,0.031072,0.000000
29.750002,16.115906,-396.147339,-0.003643,0.001199,0.030449,71.687126,3.651917,0.304487,-396.147339,0.031506,0.000000
30.010002,16.381035,-396.236298,-0.003673,0.001216,0.030882,72.866486,3.711996,0.308817,-396.236298,0.031940,0.000000
30.270002,17.092636,-396.280792,-0.003643,0.001244,0.031593,76.031845,3.873247,0.315933,-396.280792,0.032374,0.000000
30.530001,16.849106,-396.280792,-0.003579,0.001257,0.031940,74.948563,3.818062,0.319400,-396.280792,0.032807,0.000000
30.790001,16.750053,-396.325287,-0.003604,0.001271,0.032296,74.507957,3.795616,0.322958,-396.325287,0.033241,0.000000
31.050001,16.766815,-396.325287,-0.003596,0.001286,0.032668,74.582520,3.799415,0.326682,-396.325287,0.033674,0.000000
31.310001,17.171951,-396.325287,-0.003596,0.001305,0.033137,76.384651,3.891220,0.331368,-396.325287,0.034108,0.000000
31.570002,17.430756,-396.325287,-0.003535,0.001323,0.033605,77.535873,3.949866,0.336053,-396.325287,0.034542,0.000000
31.830002,17.689926,-396.369751,-0.003548,0.001344,0.034125,78.688721,4.008595,0.341254,-396.369751,0.034975,0.000000
32.090000,17.809456,-396.414246,-0.003527,0.001363,0.034629,79.220413,4.035680,0.346288,-396.414246,0.035409,0.000000
32.350002,17.747269,-396.369751,-0.003523,0.001378,0.035010,78.943794,4.021588,0.350103,-396.369751,0.035842,0.000000
32.610001,17.685455,-396.369751,-0.003523,0.001394,0.035409,78.668831,4.007581,0.354092,-396.369751,0.036276,0.000000
32.870003,17.676147,-396.414246,-0.003523,0.001407,0.035738,78.627434,4.005472,0.357385,-396.414246,0.036710,0.000000
33.130001,18.226143,-396.414246,-0.003484,0.001428,0.036276,81.073936,4.130103,0.362759,-396.414246,0.037143,0.000000
33.390003,18.087990,-396.503204,-0.003505,0.001441,0.036606,80.459396,4.098797,0.366060,-396.503204,0.037577,0.000000
33.650002,17.981865,-396.503204,-0.003484,0.001452,0.036883,79.987328,4.074749,0.368830,-396.503204,0.038011,0.000000
33.910000,18.605965,-396.547668,-0.003454,0.001479,0.037560,82.763466,4.216172,0.375598,-396.547668,0.038444,0.000000
34.170002,18.918755,-396.547668,-0.003479,0.001499,0.038062,84.154823,4.287051,0.380624,-396.547668,0.038878,0.000000
34.430000,18.836830,-396.503204,-0.003441,0.001515,0.038479,83.790405,4.268486,0.384788,-396.503204,0.039311,0.000000
34.690002,18.494995,-396.547668,-0.003441,0.001526,0.038765,82.269844,4.191026,0.387649,-396.547668,0.039745,0.000000
34.950001,18.474144,-396.503204,-0.003423,0.001540,0.039112,82.177094,4.186301,0.391123,-396.503204,0.040179,0.000000
35.210003,19.129890,-396.592163,-0.003423,0.001563,0.039693,85.094002,4.334895,0.396930,-396.592163,0.040613,0.000000
35.470001,18.885612,-396.547668,-0.003397,0.001576,0.040022,84.007401,4.279541,0.400222,-396.547668,0.041046,0.000000
35.730003,18.470421,-396.636627,-0.003393,0.001586,0.040274,82.160538,4.185457,0.402743,-396.636627,0.041479,0.000000
35.990002,19.876495,-396.681122,-0.003393,0.001619,0.041133,88.415070,4.504078,0.411327,-396.681122,0.041913,0.000000
36.250000,19.507103,-396.636627,-0.003376,0.001634,0.041497,86.771927,4.420372,0.414968,-396.636627,0.042347,0.000000
36.510002,19.318314,-396.636627,-0.003372,0.001648,0.041870,85.932152,4.377592,0.418700,-396.636627,0.042781,0.000000
36.770000,19.301926,-396.681122,-0.003354,0.001664,0.042260,85.859253,4.373879,0.422599,-396.681122,0.043205,0.000000
37.030003,19.491463,-396.725616,-0.003341,0.001684,0.042763,86.702354,4.416828,0.427633,-396.725616,0.043639,0.000000
37.290001,19.690308,-396.681122,-0.003316,0.001700,0.043180,87.586861,4.461887,0.431796,-396.681122,0.044073,0.000000
37.550003,19.237129,-396.681122,-0.003324,0.001709,0.043404,85.571022,4.359196,0.434044,-396.681122,0.044506,0.000000
37.810001,19.964752,-396.770081,-0.003290,0.001735,0.044081,88.807655,4.524077,0.440812,-396.770081,0.044940,0.000000
38.070004,20.194504,-396.770081,-0.003281,0.001755,0.044575,89.829636,4.576140,0.445755,-396.770081,0.045373,0.000000
38.330002,19.765900,-396.770081,-0.003285,0.001767,0.044879,87.923111,4.479017,0.448790,-396.770081,0.045807,0.000000
38.590000,19.786751,-396.770081,-0.003264,0.001783,0.045278,88.015862,4.483742,0.452779,-396.770081,0.046241,0.000000
38.850002,19.855270,-396.725616,-0.003272,0.001798,0.045659,88.320656,4.499269,0.456595,-396.725616,0.046675,0.000000
39.110001,20.433189,-396.770081,-0.003290,0.001823,0.046292,90.891365,4.630227,0.462923,-396.770081,0.047108,0.000000
39.370003,19.949478,-396.814575,-0.003234,0.001832,0.046544,88.739708,4.520617,0.465444,-396.814575,0.047541,0.000000
39.630001,20.447342,-396.814575,-0.003221,0.001854,0.047099,90.954323,4.633434,0.470992,-396.814575,0.047975,0.000000
39.890003,20.656990,-396.903534,-0.003229,0.001874,0.047611,91.886879,4.680941,0.476110,-396.903534,0.048409,0.000000
40.150002,20.301003,-396.814575,-0.003208,0.001888,0.047967,90.303368,4.600273,0.479667,-396.814575,0.048843,0.000000
40.410004,20.194878,-396.903534,-0.003238,0.001903,0.048331,89.831299,4.576225,0.483308,-396.903534,0.049276,0.000000
40.670002,20.436920,-396.859039,-0.003186,0.001921,0.048781,90.907959,4.631073,0.487812,-396.859039,0.049709,0.000000
40.930000,20.426865,-396.947998,-0.003173,0.001937,0.049207,90.863235,4.628794,0.492067,-396.947998,0.050143,0.000000
41.190002,20.581772,-396.947998,-0.003195,0.001953,0.049606,91.552292,4.663896,0.496056,-396.947998,0.050577,0.000000
41.450001,20.513252,-396.903534,-0.003152,0.001967,0.049970,91.247505,4.648369,0.499697,-396.903534,0.051011,0.000000
41.710003,21.066223,-397.036957,-0.003165,0.001991,0.050568,93.707237,4.773674,0.505677,-397.036957,0.051444,0.000000
41.970001,21.278107,-396.992493,-0.003143,0.002012,0.051106,94.649742,4.821688,0.511059,-396.992493,0.051877,0.000000
42.230003,20.887115,-396.992493,-0.003143,0.002025,0.051435,92.910530,4.733088,0.514352,-396.992493,0.052311,0.000000
42.490002,20.660713,-397.036957,-0.003117,0.002039,0.051791,91.903442,4.681785,0.517910,-397.036957,0.052745,0.000000
42.750004,20.607094,-396.947998,-0.003143,0.002053,0.052155,91.664932,4.669634,0.521551,-396.947998,0.053179,0.000000
43.010002,21.165276,-397.081451,-0.003100,0.002075,0.052710,94.147850,4.796120,0.527100,-397.081451,0.053612,0.000000
43.270000,21.064735,-397.081451,-0.003113,0.002091,0.053101,93.700623,4.773337,0.531006,-397.081451,0.054045,0.000000
43.530003,20.655128,-397.036957,-0.003113,0.002103,0.053404,91.878601,4.680519,0.534041,-397.036957,0.054479,0.000000
43.790001,21.313484,-397.081451,-0.003078,0.002121,0.053864,94.807114,4.829704,0.538636,-397.081451,0.054913,0.000000
44.050003,21.809853,-397.170410,-0.003087,0.002143,0.054428,97.015068,4.942183,0.544275,-397.170410,0.055347,0.000000
44.310001,21.542122,-397.125946,-0.003074,0.002159,0.054843,95.824142,4.881515,0.548431,-397.125946,0.055780,0.000000
44.570004,21.562225,-397.125946,-0.003057,0.002175,0.055242,95.913567,4.886070,0.552421,-397.125946,0.056214,0.000000
44.830002,21.536903,-397.125946,-0.003057,0.002191,0.055658,95.800934,4.880332,0.556584,-397.125946,0.056647,0.000000
45.090004,21.618828,-397.214905,-0.003040,0.002210,0.056135,96.165352,4.898897,0.561353,-397.214905,0.057081,0.000000
45.350002,21.152992,-397.214905,-0.003027,0.002218,0.056335,94.093208,4.793336,0.563351,-397.214905,0.057515,0.000000
45.610001,21.303429,-397.259369,-0.003005,0.002233,0.056726,94.762383,4.827426,0.567257,-397.259369,0.057948,0.000000
45.870003,22.630562,-397.259369,-0.002979,0.002265,0.057532,100.665764,5.128159,0.575319,-397.259369,0.058373,0.000000
46.130001,22.088760,-397.259369,-0.002979,0.002277,0.057844,98.255714,5.005384,0.578438,-397.259369,0.058807,0.000000
46.390003,22.223930,-397.303864,-0.003009,0.002295,0.058295,98.856979,5.036015,0.582950,-397.303864,0.059240,0.000000
46.650002,22.487572,-397.214905,-0.003001,0.002317,0.058850,100.029716,5.095757,0.588498,-397.214905,0.059674,0.000000
46.910004,22.387779,-397.348328,-0.002988,0.002333,0.059266,99.585815,5.073143,0.592662,-397.348328,0.060108,0.000000
47.170002,21.898849,-397.259369,-0.002958,0.002344,0.059535,97.410950,4.962350,0.595349,-397.259369,0.060541,0.000000
47.430004,22.303993,-397.348328,-0.002958,0.002365,0.060073,99.213120,5.054157,0.600731,-397.348328,0.060975,0.000000
47.690002,22.997353,-397.348328,-0.002940,0.002389,0.060671,102.297333,5.211275,0.606711,-397.348328,0.061408,0.000000
47.950001,22.706154,-397.348328,-0.002906,0.002404,0.061062,101.002014,5.145288,0.610617,-397.348328,0.061842,0.000000
48.210003,22.385544,-397.437286,-0.002915,0.002417,0.061391,99.575874,5.072637,0.613910,-397.437286,0.062276,0.000000
48.470001,22.629822,-397.303864,-0.002923,0.002435,0.061842,100.662476,5.127991,0.618422,-397.303864,0.062709,0.000000
48.730003,22.847282,-397.437286,-0.002902,0.002453,0.062302,101.629791,5.177268,0.623016,-397.437286,0.063143,0.000000
48.990002,22.609337,-397.437286,-0.002910,0.002465,0.062605,100.571350,5.123349,0.626052,-397.437286,0.063576,0.000000
49.250004,22.466347,-397.392822,-0.002897,0.002480,0.063004,99.935303,5.090947,0.630041,-397.392822,0.064010,0.000000
49.510002,23.473244,-397.481781,-0.002897,0.002504,0.063611,104.414200,5.319113,0.636112,-397.481781,0.064444,0.000000
49.770000,23.624794,-397.481781,-0.002871,0.002524,0.064106,105.088333,5.353455,0.641055,-397.481781,0.064878,0.000000
50.030003,23.297852,-397.526245,-0.002859,0.002537,0.064435,103.634018,5.279369,0.644348,-397.526245,0.065311,0.000000
50.290001,23.084114,-397.526245,-0.002893,0.002551,0.064791,102.683266,5.230935,0.647906,-397.526245,0.065744,0.000000
50.550003,23.387222,-397.526245,-0.002867,0.002571,0.065311,104.031563,5.299621,0.653106,-397.526245,0.066178,0.000000
50.810001,23.475479,-397.615234,-0.002863,0.002585,0.065649,104.424149,5.319620,0.656490,-397.615234,0.066612,0.000000
51.070004,23.385361,-397.481781,-0.002859,0.002598,0.065978,104.023277,5.299198,0.659783,-397.481781,0.067046,0.000000
51.330002,23.595749,-397.570740,-0.002841,0.002618,0.066490,104.959137,5.346873,0.664900,-397.570740,0.067479,0.000000
51.590004,24.610466,-397.570740,-0.002833,0.002643,0.067141,109.472816,5.576811,0.671410,-397.570740,0.067912,0.000000
51.850002,24.250381,-397.570740,-0.002807,0.002657,0.067496,107.871086,5.495215,0.674960,-397.570740,0.068346,0.000000
52.110001,23.935356,-397.615234,-0.002833,0.002670,0.067826,106.469780,5.423829,0.678261,-397.615234,0.068780,0.000000
52.370003,23.855293,-397.615234,-0.002811,0.002685,0.068190,106.113647,5.405687,0.681902,-397.615234,0.069214,0.000000
52.630001,24.234741,-397.704193,-0.002815,0.002704,0.068693,107.801514,5.491671,0.686928,-397.704193,0.069647,0.000000
52.890003,24.543068,-397.659698,-0.002811,0.002722,0.069144,109.173019,5.561539,0.691440,-397.659698,0.070080,0.000000
53.150002,24.848785,-397.659698,-0.002768,0.002743,0.069664,110.532921,5.630816,0.696640,-397.659698,0.070514,0.000000
53.410004,25.121735,-397.704193,-0.002781,0.002763,0.070185,111.747055,5.692666,0.701848,-397.704193,0.070948,0.000000
53.670002,24.915443,-397.704193,-0.002768,0.002778,0.070549,110.829430,5.645920,0.705489,-397.704193,0.071382,0.000000
53.930004,24.738190,-397.704193,-0.002768,0.002793,0.070930,110.040962,5.605754,0.709304,-397.704193,0.071815,0.000000
54.190002,24.693878,-397.748657,-0.002742,0.002807,0.071286,109.843857,5.595713,0.712862,-397.748657,0.072248,0.000000
54.450001,25.367874,-397.748657,-0.002746,0.002827,0.071798,112.841942,5.748443,0.717979,-397.748657,0.072682,0.000000
54.710003,25.239777,-397.837616,-0.002759,0.002840,0.072145,112.272133,5.719415,0.721446,-397.837616,0.073116,0.000000
54.970001,24.906128,-397.748657,-0.002746,0.002851,0.072405,110.787987,5.643809,0.724050,-397.748657,0.073541,0.000000
55.230003,25.646408,-397.837616,-0.002725,0.002876,0.073055,114.080917,5.811559,0.730553,-397.837616,0.073974,0.000000
55.490002,26.235130,-397.793152,-0.002725,0.002896,0.073558,116.699692,5.944966,0.735579,-397.793152,0.074408,0.000000
55.750004,26.236618,-397.837616,-0.002708,0.002914,0.074009,116.706306,5.945302,0.740091,-397.837616,0.074842,0.000000
56.010002,25.845253,-397.882111,-0.002695,0.002926,0.074313,114.965424,5.856618,0.743126,-397.882111,0.075276,0.000000
56.270004,25.757744,-397.793152,-0.002686,0.002938,0.074634,114.576164,5.836788,0.746336,-397.793152,0.075709,0.000000
56.530003,26.562813,-397.926575,-0.002690,0.002961,0.075206,118.157295,6.019219,0.752059,-397.926575,0.076142,0.000000
56.790001,26.296196,-397.882111,-0.002695,0.002974,0.075544,116.971321,5.958803,0.755442,-397.882111,0.076576,0.000000
57.050003,25.707108,-397.926575,-0.002669,0.002982,0.075743,114.350929,5.825314,0.757433,-397.926575,0.077010,0.000000
57.310001,27.789780,-397.971069,-0.002669,0.003018,0.076663,123.615112,6.297254,0.766630,-397.971069,0.077443,0.000000
57.570004,27.429703,-397.926575,-0.002660,0.003033,0.077035,122.013412,6.215660,0.770355,-397.926575,0.077877,0.000000
57.830002,27.088608,-398.015564,-0.002647,0.003047,0.077391,120.496147,6.138366,0.773913,-398.015564,0.078311,0.000000
58.090004,26.880447,-397.926575,-0.002630,0.003063,0.077790,119.570198,6.091197,0.777902,-397.926575,0.078744,0.000000
58.350002,27.156006,-397.971069,-0.002634,0.003079,0.078207,120.795944,6.153639,0.782065,-397.971069,0.079178,0.000000
58.610004,27.768188,-398.015564,-0.002613,0.003098,0.078701,123.519073,6.292362,0.787008,-398.015564,0.079611,0.000000
58.870003,27.211113,-397.971069,-0.002604,0.003108,0.078935,121.041077,6.166126,0.789347,-397.971069,0.080045,0.000000
59.130001,28.222481,-398.060028,-0.002613,0.003134,0.079611,125.539864,6.395305,0.796115,-398.060028,0.080479,0.000000
59.390003,28.545326,-398.015564,-0.002591,0.003154,0.080123,126.975952,6.468463,0.801232,-398.015564,0.080912,0.000000
59.650002,28.194550,-398.104523,-0.002587,0.003167,0.080444,125.415619,6.388977,0.804442,-398.104523,0.081346,0.000000
59.910004,28.034431,-398.060028,-0.002604,0.003182,0.080817,124.703377,6.352693,0.808166,-398.060028,0.081779,0.000000
60.170002,28.133858,-398.193481,-0.002596,0.003196,0.081181,125.145653,6.375224,0.811815,-398.193481,0.082213,0.000000
60.430004,29.127716,-398.104523,-0.002583,0.003223,0.081857,129.566559,6.600435,0.818574,-398.104523,0.082647,0.000000
60.690002,28.545326,-398.104523,-0.002561,0.003231,0.082066,126.975952,6.468463,0.820656,-398.104523,0.083081,0.000000
60.950005,28.989197,-398.148987,-0.002561,0.003251,0.082586,128.950394,6.569046,0.825864,-398.148987,0.083514,0.000000
61.210003,29.626694,-398.148987,-0.002557,0.003273,0.083141,131.786118,6.713505,0.831413,-398.148987,0.083947,0.000000
61.470001,29.423012,-398.193481,-0.002548,0.003287,0.083480,130.880096,6.667350,0.834796,-398.193481,0.084381,0.000000
61.730003,29.368271,-398.237946,-0.002578,0.003301,0.083852,130.636597,6.654945,0.838521,-398.237946,0.084815,0.000000
61.990002,29.745857,-398.237946,-0.002539,0.003319,0.084303,132.316177,6.740508,0.843032,-398.237946,0.085249,0.000000
62.250004,29.882141,-398.282440,-0.002539,0.003336,0.084745,132.922409,6.771390,0.847453,-398.282440,0.085682,0.000000
62.510002,30.130142,-398.282440,-0.002544,0.003351,0.085109,134.025574,6.827588,0.851094,-398.282440,0.086115,0.000000
62.770004,30.261963,-398.237946,-0.002514,0.003365,0.085474,134.611938,6.857459,0.854735,-398.237946,0.086549,0.000000
63.030003,31.268860,-398.326904,-0.002535,0.003388,0.086055,139.090836,7.085625,0.860549,-398.326904,0.086983,0.000000
63.290005,31.933174,-398.282440,-0.002496,0.003410,0.086601,142.045853,7.236161,0.866014,-398.282440,0.087417,0.000000
63.550003,31.957748,-398.282440,-0.002527,0.003424,0.086957,142.155167,7.241729,0.869572,-398.282440,0.087850,0.000000
63.810001,31.921257,-398.282440,-0.002518,0.003437,0.087295,141.992844,7.233460,0.872948,-398.282440,0.088275,0.000000
64.070000,32.142448,-398.326904,-0.002505,0.003450,0.087642,142.976746,7.283583,0.876423,-398.326904,0.088709,0.000000
64.330002,33.160881,-398.415894,-0.002475,0.003473,0.088223,147.506973,7.514363,0.882229,-398.415894,0.089143,0.000000
64.590004,33.351913,-398.371399,-0.002483,0.003488,0.088604,148.356720,7.557652,0.886044,-398.371399,0.089576,0.000000
64.850006,33.300896,-398.415894,-0.002475,0.003500,0.088908,148.129776,7.546091,0.889079,-398.415894,0.090009,0.000000
65.110001,34.263107,-398.371399,-0.002483,0.003519,0.089377,152.409912,7.764131,0.893765,-398.371399,0.090443,0.000000
65.370003,35.456184,-398.460358,-0.002475,0.003541,0.089931,157.716980,8.034486,0.899314,-398.460358,0.090877,0.000000
65.630005,35.631203,-398.504852,-0.002475,0.003555,0.090305,158.495499,8.074146,0.903046,-398.504852,0.091311,0.000000
65.889999,36.453026,-398.415894,-0.002427,0.003573,0.090764,162.151154,8.260374,0.907641,-398.415894,0.091744,0.000000
66.150002,36.940834,-398.504852,-0.002419,0.003590,0.091198,164.321030,8.370913,0.911978,-398.504852,0.092177,0.000000
66.410004,37.528816,-398.415894,-0.002427,0.003607,0.091614,166.936508,8.504151,0.916141,-398.415894,0.092611,0.000000
66.670006,37.535141,-398.549316,-0.002393,0.003617,0.091865,166.964645,8.505585,0.918655,-398.549316,0.093045,0.000000
66.930000,38.100029,-398.504852,-0.002423,0.003632,0.092247,169.477386,8.633591,0.922470,-398.504852,0.093479,0.000000
67.190002,40.107864,-398.549316,-0.002389,0.003662,0.093010,178.408691,9.088573,0.930100,-398.549316,0.093912,0.000000
67.450005,40.386772,-398.593811,-0.002397,0.003676,0.093374,179.649338,9.151773,0.933741,-398.593811,0.094345,0.000000
67.710007,41.170616,-398.593811,-0.002397,0.003694,0.093817,183.136047,9.329395,0.938169,-398.593811,0.094779,0.000000
67.970001,42.253845,-398.593811,-0.002350,0.003716,0.094389,187.954483,9.574859,0.943892,-398.593811,0.095213,0.000000
68.230003,42.966568,-398.638275,-0.002350,0.003733,0.094814,191.124847,9.736363,0.948139,-398.638275,0.095647,0.000000
68.490005,42.959862,-398.638275,-0.002341,0.003742,0.095057,191.095016,9.734843,0.950569,-398.638275,0.096080,0.000000
68.750000,43.716896,-398.682770,-0.002337,0.003760,0.095516,194.462463,9.906390,0.955164,-398.682770,0.096513,0.000000
69.010002,45.580994,-398.638275,-0.002333,0.003787,0.096193,202.754379,10.328800,0.961931,-398.638275,0.096947,0.000000
69.270004,46.055397,-398.682770,-0.002324,0.003802,0.096566,204.864639,10.436302,0.965655,-398.682770,0.097381,0.000000
69.530006,46.321274,-398.727234,-0.002324,0.003813,0.096861,206.047318,10.496551,0.968608,-398.727234,0.097815,0.000000
69.790001,47.188156,-398.727234,-0.002289,0.003831,0.097311,209.903397,10.692989,0.973112,-398.727234,0.098248,0.000000
70.050003,48.405815,-398.727234,-0.002298,0.003851,0.097815,215.319824,10.968915,0.978146,-398.727234,0.098682,0.000000
70.310005,48.976662,-398.682770,-0.002276,0.003863,0.098109,217.859070,11.098270,0.981090,-398.682770,0.099115,0.000000
70.570000,48.890640,-398.771729,-0.002259,0.003872,0.098361,217.476425,11.078777,0.983611,-398.771729,0.099549,0.000000
70.830002,51.125252,-398.727234,-0.002268,0.003902,0.099098,227.416473,11.585147,0.990984,-398.727234,0.099983,0.000000
71.090004,52.489250,-398.771729,-0.002233,0.003922,0.099609,233.483841,11.894234,0.996094,-398.771729,0.100416,0.000000
71.350006,53.155792,-398.771729,-0.002251,0.003935,0.099957,236.448776,12.045275,0.999568,-398.771729,0.100850,0.000000
71.610001,53.519234,-398.771729,-0.002216,0.003947,0.100251,238.065445,12.127631,1.002513,-398.771729,0.101284,0.000000
71.870003,54.310898,-398.816193,-0.002208,0.003963,0.100659,241.586945,12.307026,1.006593,-398.816193,0.101717,0.000000
72.130005,55.791817,-398.816193,-0.002216,0.003983,0.101162,248.174393,12.642607,1.011619,-398.816193,0.102151,0.000000
72.390007,56.455017,-398.905182,-0.002233,0.003996,0.101500,251.124451,12.792890,1.015003,-398.905182,0.102584,0.000000
72.650002,57.607880,-398.860687,-0.002182,0.004015,0.101977,256.252655,13.054132,1.019772,-398.860687,0.103018,0.000000
72.910004,59.506981,-398.816193,-0.002186,0.004040,0.102610,264.700256,13.484475,1.026100,-398.816193,0.103443,0.000000
73.170006,60.528397,-398.905182,-0.002216,0.004055,0.102992,269.243744,13.715931,1.029915,-398.905182,0.103876,0.000000
73.430000,61.071320,-398.860687,-0.002190,0.004068,0.103322,271.658783,13.838959,1.033216,-398.860687,0.104310,0.000000
73.690002,61.825745,-398.860687,-0.002164,0.004081,0.103651,275.014648,14.009914,1.036509,-398.860687,0.104744,0.000000
73.950005,63.060158,-398.994141,-0.002177,0.004099,0.104119,280.505585,14.289637,1.041194,-398.994141,0.105177,0.000000
74.210007,64.763763,-398.905182,-0.002130,0.004120,0.104649,288.083618,14.675678,1.046486,-398.905182,0.105611,0.000000
74.470001,65.854065,-398.949646,-0.002151,0.004139,0.105125,292.933502,14.922744,1.051255,-398.949646,0.106044,0.000000
74.730003,67.469421,-398.905182,-0.002130,0.004158,0.105620,300.118988,15.288789,1.056198,-398.905182,0.106478,0.000000
74.990005,66.831924,-398.949646,-0.002130,0.004150,0.105403,297.283234,15.144331,1.054025,-398.949646,0.105620,0.000000
75.250000,66.237991,-398.949646,-0.002134,0.004149,0.105385,294.641296,15.009744,1.053851,-398.949646,0.105403,0.000000
75.510002,65.752045,-399.083099,-0.002139,0.004149,0.105377,292.479706,14.899627,1.053768,-399.083099,0.105403,0.000000
75.770004,65.295517,-399.083099,-0.002108,0.004148,0.105368,290.448975,14.796175,1.053677,-399.083099,0.105403,0.000000
76.030006,64.916428,-399.038605,-0.002100,0.004148,0.105368,288.762695,14.710273,1.053677,-399.038605,0.105403,0.000000
76.290001,64.581665,-399.127563,-0.002113,0.004148,0.105359,287.273590,14.634415,1.053594,-399.127563,0.105403,0.000000
76.550003,64.296066,-399.083099,-0.002108,0.004148,0.105359,286.003174,14.569697,1.053594,-399.083099,0.105403,0.000000
76.810005,64.022736,-399.127563,-0.002100,0.004148,0.105359,284.787354,14.507759,1.053594,-399.127563,0.105403,0.000000
77.070007,63.791122,-399.172058,-0.002100,0.004148,0.105359,283.757080,14.455275,1.053594,-399.172058,0.105403,0.000000
77.330002,63.588562,-399.083099,-0.002117,0.004148,0.105359,282.856049,14.409374,1.053594,-399.083099,0.105403,0.000000
77.590004,63.377426,-399.127563,-0.002095,0.004148,0.105359,281.916870,14.361530,1.053594,-399.127563,0.105403,0.000000
77.850006,63.208733,-399.083099,-0.002113,0.004148,0.105359,281.166473,14.323304,1.053594,-399.083099,0.105403,0.000000
78.110001,63.039680,-399.216522,-0.002117,0.004148,0.105359,280.414490,14.284995,1.053594,-399.216522,0.105403,0.000000
78.370003,62.890358,-399.261017,-0.002113,0.004148,0.105359,279.750275,14.251159,1.053594,-399.261017,0.105403,0.000000
78.630005,62.751091,-399.172058,-0.002100,0.004148,0.105359,279.130798,14.219600,1.053594,-399.172058,0.105403,0.000000
78.890007,62.602516,-399.261017,-0.002082,0.004148,0.105359,278.469910,14.185933,1.053594,-399.261017,0.105403,0.000000
79.150002,62.487450,-399.216522,-0.002100,0.004148,0.105359,277.958069,14.159859,1.053594,-399.216522,0.105403,0.000000
79.410004,62.360840,-399.261017,-0.002078,0.004148,0.105359,277.394867,14.131168,1.053594,-399.261017,0.105403,0.000000
79.670006,62.253975,-399.305511,-0.002074,0.004148,0.105359,276.919525,14.106953,1.053594,-399.305511,0.105403,0.000000
79.930000,62.138908,-399.305511,-0.002095,0.004148,0.105359,276.407684,14.080878,1.053594,-399.305511,0.105403,0.000000
80.190002,62.046188,-399.349976,-0.002130,0.004148,0.105359,275.995239,14.059867,1.053594,-399.349976,0.105403,0.000000
80.450005,61.957565,-399.305511,-0.002113,0.004148,0.105359,275.601013,14.039784,1.053594,-399.305511,0.105403,0.000000
80.710007,61.852180,-399.349976,-0.002100,0.004148,0.105359,275.132233,14.015904,1.053594,-399.349976,0.105403,0.000000
80.970001,61.776588,-399.349976,-0.002108,0.004148,0.105359,274.795990,13.998775,1.053594,-399.349976,0.105403,0.000000
81.230003,61.684242,-399.349976,-0.002108,0.004148,0.105359,274.385223,13.977849,1.053594,-399.349976,0.105403,0.000000
81.490005,61.615723,-399.438934,-0.002078,0.004148,0.105359,274.080414,13.962322,1.053594,-399.438934,0.105403,0.000000
81.750008,61.532310,-399.394470,-0.002100,0.004148,0.105359,273.709381,13.943421,1.053594,-399.394470,0.105403,0.000000
82.010002,61.467522,-399.394470,-0.002104,0.004148,0.105359,273.421204,13.928740,1.053594,-399.394470,0.105403,0.000000
82.270004,61.397514,-399.394470,-0.002082,0.004148,0.105359,273.109772,13.912876,1.053594,-399.394470,0.105403,0.000000
82.530006,61.333092,-399.438934,-0.002100,0.004148,0.105359,272.823212,13.898277,1.053594,-399.438934,0.105403,0.000000
82.790001,61.260483,-399.527893,-0.002104,0.004148,0.105359,272.500244,13.881824,1.053594,-399.527893,0.105403,0.000000
83.050003,61.195686,-399.438934,-0.002061,0.004148,0.105359,272.212006,13.867141,1.053594,-399.438934,0.105403,0.000000
83.310005,61.136482,-399.527893,-0.002126,0.004148,0.105359,271.948669,13.853724,1.053594,-399.527893,0.105403,0.000000
83.570007,61.074295,-399.483429,-0.002087,0.004148,0.105359,271.672028,13.839633,1.053594,-399.483429,0.105403,0.000000
83.830002,61.022537,-399.483429,-0.002108,0.004148,0.105359,271.441803,13.827905,1.053594,-399.483429,0.105403,0.000000
84.090004,60.975243,-399.572388,-0.002104,0.004148,0.105359,271.231415,13.817187,1.053594,-399.572388,0.105403,0.000000
84.350006,60.913803,-399.527893,-0.002070,0.004148,0.105359,270.958130,13.803265,1.053594,-399.527893,0.105403,0.000000
84.610001,60.862045,-399.616852,-0.002108,0.004148,0.105359,270.727905,13.791536,1.053594,-399.616852,0.105403,0.000000
84.870003,60.815125,-399.616852,-0.002108,0.004148,0.105359,270.519196,13.780904,1.053594,-399.616852,0.105403,0.000000
85.130005,60.763741,-399.616852,-0.002070,0.004148,0.105359,270.290619,13.769260,1.053594,-399.616852,0.105403,0.000000
85.390007,60.709000,-399.661346,-0.002082,0.004148,0.105359,270.047119,13.756856,1.053594,-399.661346,0.105403,0.000000
85.650002,60.670647,-399.616852,-0.002078,0.004148,0.105359,269.876526,13.748165,1.053594,-399.616852,0.105403,0.000000
85.910004,60.624474,-399.661346,-0.002087,0.004148,0.105359,269.671112,13.737702,1.053594,-399.661346,0.105403,0.000000
86.170006,60.586113,-399.661346,-0.002100,0.004148,0.105359,269.500488,13.729009,1.053594,-399.661346,0.105403,0.000000
86.430000,60.538078,-399.705841,-0.002074,0.004148,0.105359,269.286835,13.718125,1.053594,-399.705841,0.105403,0.000000
86.690002,60.509781,-399.705841,-0.002087,0.004148,0.105359,269.160950,13.711712,1.053594,-399.705841,0.105403,0.000000
86.950005,60.465096,-399.705841,-0.002078,0.004148,0.105359,268.962189,13.701587,1.053594,-399.705841,0.105403,0.000000
87.210007,60.425247,-399.750305,-0.002082,0.004148,0.105359,268.784912,13.692556,1.053594,-399.750305,0.105403,0.000000
87.470001,60.380936,-399.705841,-0.002095,0.004148,0.105359,268.587830,13.682516,1.053594,-399.705841,0.105403,0.000000
87.730003,60.354126,-399.750305,-0.002108,0.004148,0.105359,268.468567,13.676440,1.053594,-399.750305,0.105403,0.000000
87.990005,60.304230,-399.750305,-0.002095,0.004148,0.105359,268.246613,13.665134,1.053594,-399.750305,0.105403,0.000000
88.250008,60.281517,-399.750305,-0.002082,0.004148,0.105359,268.145569,13.659986,1.053594,-399.750305,0.105403,0.000000
88.510002,60.235710,-399.839264,-0.002104,0.004148,0.105359,267.941833,13.649607,1.053594,-399.839264,0.105403,0.000000
88.770004,60.217094,-399.839264,-0.002100,0.004148,0.105359,267.859009,13.645389,1.053594,-399.839264,0.105403,0.000000
89.030006,60.170547,-399.839264,-0.002082,0.004148,0.105359,267.651978,13.634840,1.053594,-399.839264,0.105403,0.000000
89.290001,60.133308,-399.839264,-0.002065,0.004148,0.105359,267.486328,13.626402,1.053594,-399.839264,0.105403,0.000000
89.550003,60.106499,-399.839264,-0.002082,0.004148,0.105359,267.367065,13.620327,1.053594,-399.839264,0.105403,0.000000
89.810005,60.076340,-399.883759,-0.002082,0.004148,0.105359,267.232910,13.613494,1.053594,-399.883759,0.105403,0.000000
90.070007,60.053619,-399.883759,-0.002082,0.004148,0.105359,267.131836,13.608344,1.053594,-399.883759,0.105403,0.000000
90.330002,60.014153,-399.972717,-0.002095,0.004148,0.105359,266.956268,13.599401,1.053594,-399.972717,0.105403,0.000000
90.590004,59.979897,-399.883759,-0.002078,0.004148,0.105359,266.803894,13.591639,1.053594,-399.883759,0.105403,0.000000
90.850006,59.950104,-399.883759,-0.002074,0.004148,0.105359,266.671387,13.584888,1.053594,-399.883759,0.105403,0.000000
91.110001,59.924782,-399.928223,-0.002065,0.004148,0.105359,266.558746,13.579150,1.053594,-399.928223,0.105403,0.000000
91.370003,59.901321,-400.017181,-0.002070,0.004148,0.105359,266.454376,13.573833,1.053594,-400.017181,0.105403,0.000000
91.630005,59.877121,-400.017181,-0.002100,0.004148,0.105359,266.346741,13.568349,1.053594,-400.017181,0.105403,0.000000
91.890007,59.840256,-400.017181,-0.002095,0.004148,0.105359,266.182739,13.559997,1.053594,-400.017181,0.105403,0.000000
92.150002,59.821632,-399.972717,-0.002078,0.004148,0.105359,266.099915,13.555776,1.053594,-399.972717,0.105403,0.000000
92.410004,59.784027,-400.061676,-0.002121,0.004148,0.105359,265.932648,13.547254,1.053594,-400.061676,0.105403,0.000000
92.670006,59.780304,-400.017181,-0.002070,0.004148,0.105359,265.916077,13.546411,1.053594,-400.017181,0.105403,0.000000
92.930008,59.735992,-400.106140,-0.002121,0.004148,0.105359,265.718964,13.536369,1.053594,-400.106140,0.105403,0.000000
93.190002,59.714020,-400.061676,-0.002070,0.004148,0.105359,265.621216,13.531390,1.053594,-400.061676,0.105403,0.000000
93.450005,59.694656,-400.150635,-0.002061,0.004148,0.105359,265.535095,13.527002,1.053594,-400.150635,0.105403,0.000000
93.710007,59.671570,-400.150635,-0.002082,0.004148,0.105359,265.432404,13.521770,1.053594,-400.150635,0.105403,0.000000
93.970001,59.648483,-400.150635,-0.002074,0.004148,0.105359,265.329712,13.516540,1.053594,-400.150635,0.105403,0.000000
94.230003,59.629494,-400.150635,-0.002082,0.004148,0.105359,265.245239,13.512237,1.053594,-400.150635,0.105403,0.000000
94.490005,59.611992,-400.150635,-0.002087,0.004148,0.105359,265.167389,13.508270,1.053594,-400.150635,0.105403,0.000000
94.750008,59.587410,-400.150635,-0.002082,0.004148,0.105359,265.058044,13.502700,1.053594,-400.150635,0.105403,0.000000
95.010002,59.567680,-400.195129,-0.002117,0.004148,0.105359,264.970276,13.498229,1.053594,-400.195129,0.105403,0.000000
95.270004,59.532303,-400.195129,-0.002091,0.004148,0.105359,264.812897,13.490212,1.053594,-400.195129,0.105403,0.000000
95.530006,59.519638,-400.239594,-0.002078,0.004148,0.105359,264.756561,13.487343,1.053594,-400.239594,0.105403,0.000000
95.790001,59.508469,-400.239594,-0.002070,0.004148,0.105359,264.706879,13.484812,1.053594,-400.239594,0.105403,0.000000
96.050003,59.476448,-400.239594,-0.002065,0.004148,0.105359,264.564453,13.477556,1.053594,-400.239594,0.105403,0.000000
96.310005,59.450378,-400.328552,-0.002082,0.004148,0.105359,264.448486,13.471648,1.053594,-400.328552,0.105403,0.000000
96.570007,59.426544,-400.239594,-0.002078,0.004148,0.105359,264.342468,13.466248,1.053594,-400.239594,0.105403,0.000000
96.830002,59.411652,-400.373047,-0.002082,0.004148,0.105359,264.276215,13.462873,1.053594,-400.373047,0.105403,0.000000
97.090004,59.403458,-400.284088,-0.002078,0.004148,0.105359,264.239777,13.461017,1.053594,-400.284088,0.105403,0.000000
97.350006,59.361008,-400.328552,-0.002087,0.004148,0.105359,264.050964,13.451397,1.053594,-400.328552,0.105403,0.000000
97.610008,59.356911,-400.417511,-0.002087,0.004148,0.105359,264.032715,13.450468,1.053594,-400.417511,0.105403,0.000000
97.870003,59.332710,-400.373047,-0.002074,0.004148,0.105359,263.925079,13.444984,1.053594,-400.373047,0.105403,0.000000
98.130005,59.322655,-400.373047,-0.002087,0.004148,0.105359,263.880341,13.442706,1.053594,-400.373047,0.105403,0.000000
98.390007,59.294357,-400.328552,-0.002100,0.004148,0.105359,263.754486,13.436294,1.053594,-400.328552,0.105403,0.000000
98.650002,59.289886,-400.373047,-0.002091,0.004148,0.105359,263.734589,13.435281,1.053594,-400.373047,0.105403,0.000000
98.910004,59.258606,-400.462006,-0.002100,0.004148,0.105359,263.595459,13.428192,1.053594,-400.462006,0.105403,0.000000
99.170006,59.249672,-400.462006,-0.002074,0.004148,0.105359,263.555695,13.426167,1.053594,-400.462006,0.105403,0.000000
99.430008,59.225838,-400.462006,-0.002087,0.004148,0.105359,263.449677,13.420767,1.053594,-400.462006,0.105403,0.000000
99.690002,59.221741,-400.417511,-0.002095,0.004148,0.105359,263.431458,13.419838,1.053594,-400.417511,0.105403,0.000000
99.950005,59.185997,-400.462006,-0.002082,0.004148,0.105359,263.272461,13.411738,1.053594,-400.462006,0.105403,0.000000
100.210007,59.173706,-400.550964,-0.002074,0.004148,0.105359,263.217804,13.408954,1.053594,-400.550964,0.105403,0.000000
100.470001,59.162910,-400.506470,-0.002087,0.004148,0.105359,263.169769,13.406507,1.053594,-400.506470,0.105403,0.000000
100.730003,59.144661,-400.550964,-0.002074,0.004148,0.105359,263.088593,13.402371,1.053594,-400.550964,0.105403,0.000000
100.990005,59.117104,-400.550964,-0.002095,0.004148,0.105359,262.966003,13.396128,1.053594,-400.550964,0.105403,0.000000
101.250008,59.092529,-400.550964,-0.002070,0.004148,0.105359,262.856689,13.390558,1.053594,-400.550964,0.105403,0.000000
101.510002,59.091042,-400.595459,-0.002104,0.004148,0.105359,262.850067,13.390222,1.053594,-400.595459,0.105403,0.000000
101.770004,59.067581,-400.550964,-0.002074,0.004148,0.105359,262.745728,13.384906,1.053594,-400.550964,0.105403,0.000000
102.030006,59.063484,-400.639923,-0.002104,0.004148,0.105359,262.727509,13.383977,1.053594,-400.639923,0.105403,0.000000
102.290009,59.032204,-400.595459,-0.002065,0.004148,0.105359,262.588348,13.376888,1.053594,-400.595459,0.105403,0.000000
102.550003,59.040024,-400.639923,-0.002074,0.004148,0.105359,262.623138,13.378660,1.053594,-400.639923,0.105403,0.000000
102.810005,59.016563,-400.684418,-0.002061,0.004148,0.105359,262.518799,13.373344,1.053594,-400.684418,0.105403,0.000000
103.070007,58.996834,-400.639923,-0.002087,0.004148,0.105359,262.431030,13.368874,1.053594,-400.639923,0.105403,0.000000
103.330002,58.975975,-400.684418,-0.002100,0.004148,0.105359,262.338226,13.364147,1.053594,-400.684418,0.105403,0.000000
103.590004,58.973740,-400.639923,-0.002108,0.004148,0.105359,262.328308,13.363640,1.053594,-400.639923,0.105403,0.000000
103.850006,58.943581,-400.684418,-0.002065,0.004148,0.105359,262.194153,13.356806,1.053594,-400.684418,0.105403,0.000000
104.110008,58.939484,-400.684418,-0.002100,0.004148,0.105359,262.175903,13.355878,1.053594,-400.684418,0.105403,0.000000
104.370003,58.908577,-400.728882,-0.002065,0.004148,0.105359,262.038452,13.348874,1.053594,-400.728882,0.105403,0.000000
104.630005,58.900017,-400.817841,-0.002057,0.004148,0.105359,262.000366,13.346935,1.053594,-400.817841,0.105403,0.000000
104.890007,58.886978,-400.728882,-0.002082,0.004148,0.105359,261.942352,13.343980,1.053594,-400.728882,0.105403,0.000000
105.150002,58.877670,-400.817841,-0.002095,0.004148,0.105359,261.900970,13.341871,1.053594,-400.817841,0.105403,0.000000
105.200005,58.876556,-400.817841,-0.002074,0.004148,0.105359,261.895996,13.341619,1.053594,-400.817841,0.105403,0.000000