File: Data/Automembrane/AutoNoheat15-1-3_12132023_190242.csv
Time (sec),S:Load (lbs),S:HL1 (DIM),S:LVDT (in),S:Position (in),Ch:Position (mm),Ch:Load (N),Ch:Stress (MPa),Ch:Strain (mm/mm),Ch:HL1 (DIM),Set Point (),Cycles ()
0.010000,0.003357,-1303.736694,-0.000009,-0.000000,-0.000000,0.014932,0.000761,-0.000000,-1303.736694,0.000173,0.000000
0.260000,0.004097,-1303.647705,-0.000043,-0.000000,-0.000000,0.018224,0.000928,-0.000000,-1303.647705,0.000173,0.000000
0.510000,-0.001114,-1303.736694,0.000004,0.000068,0.001717,-0.004955,-0.000252,0.017172,-1303.736694,0.002359,0.000000
0.760000,0.013779,-1303.781128,0.000026,0.000220,0.005585,0.061291,0.003122,0.055850,-1303.781128,0.006521,0.000000
1.010000,0.010056,-1303.736694,0.000229,0.000380,0.009661,0.044729,0.002279,0.096609,-1303.736694,0.010684,0.000000
1.260000,-0.013405,-1303.736694,0.000388,0.000548,0.013910,-0.059628,-0.003038,0.139102,-1303.736694,0.014864,0.000000
1.510000,-0.002228,-1303.736694,0.000526,0.000707,0.017969,-0.009910,-0.000505,0.179688,-1303.736694,0.019027,0.000000
1.760000,0.007454,-1303.736694,0.000698,0.000870,0.022106,0.033157,0.001689,0.221057,-1303.736694,0.023190,0.000000
2.010000,-0.008934,-1303.781128,0.000897,0.001037,0.026338,-0.039741,-0.002024,0.263376,-1303.781128,0.027352,0.000000
2.260000,-0.039467,-1303.736694,0.001078,0.001198,0.030440,-0.175557,-0.008943,0.304396,-1303.736694,0.031515,0.000000
2.510000,0.006706,-1303.736694,0.001220,0.001361,0.034567,0.029831,0.001520,0.345674,-1303.736694,0.035678,0.000000
2.760000,0.036125,-1303.736694,0.001401,0.001526,0.038765,0.160693,0.008186,0.387649,-1303.736694,0.039840,0.000000
3.010000,-0.018242,-1303.781128,0.001591,0.001693,0.042997,-0.081144,-0.004134,0.429968,-1303.781128,0.044020,0.000000
3.260000,0.004471,-1303.736694,0.001707,0.001857,0.047160,0.019887,0.001013,0.471598,-1303.736694,0.048183,0.000000
3.510000,0.012291,-1303.736694,0.001944,0.002010,0.051045,0.054673,0.002785,0.510450,-1303.736694,0.052345,0.000000
3.760000,0.001869,-1303.736694,0.002078,0.002183,0.055442,0.008315,0.000424,0.554415,-1303.736694,0.056508,0.000000
4.010000,-0.040215,-1303.692139,0.002281,0.002346,0.059596,-0.178883,-0.009113,0.595958,-1303.692139,0.060671,0.000000
4.260000,-0.003723,-1303.692139,0.002389,0.002509,0.063741,-0.016561,-0.000844,0.637410,-1303.692139,0.064834,0.000000
4.510000,0.015640,-1303.692139,0.002578,0.002672,0.067861,0.069571,0.003544,0.678605,-1303.692139,0.068996,0.000000
4.760000,-0.009308,-1303.692139,0.002738,0.002841,0.072170,-0.041403,-0.002109,0.721704,-1303.692139,0.073159,0.000000
5.010000,0.017502,-1303.781128,0.002979,0.003009,0.076420,0.077852,0.003966,0.764197,-1303.781128,0.077339,0.000000
5.260000,0.035004,-1303.692139,0.003113,0.003164,0.080366,0.155704,0.007932,0.803658,-1303.692139,0.081502,0.000000
5.510000,0.006332,-1303.736694,0.003281,0.003334,0.084676,0.028168,0.001435,0.846757,-1303.736694,0.085665,0.000000
5.760000,0.001122,-1303.692139,0.003479,0.003490,0.088648,0.004989,0.000254,0.886479,-1303.692139,0.089827,0.000000
6.010000,0.011917,-1303.736694,0.003652,0.003658,0.092906,0.053010,0.002700,0.929059,-1303.736694,0.093990,0.000000
6.260000,0.011917,-1303.736694,0.003803,0.003825,0.097147,0.053010,0.002700,0.971465,-1303.736694,0.098153,0.000000
6.510000,0.064423,-1303.736694,0.003962,0.003986,0.101249,0.286566,0.014598,1.012486,-1303.736694,0.102315,0.000000
6.760000,0.430092,-1303.692139,0.004096,0.004152,0.105455,1.913144,0.097460,1.054547,-1303.692139,0.106478,0.000000
7.010000,0.659103,-1303.736694,0.004212,-0.000011,-0.000269,2.931838,0.149355,-0.002687,-1303.736694,-0.000009,0.000000
7.260000,0.634529,-1303.736694,0.004251,-0.000011,-0.000269,2.822526,0.143786,-0.002687,-1303.736694,-0.000009,0.000000
7.510000,0.569359,-1303.736694,0.004212,-0.000011,-0.000269,2.532634,0.129019,-0.002687,-1303.736694,0.000052,0.000000
7.760000,0.605110,-1303.692139,0.004238,-0.000010,-0.000260,2.691664,0.137120,-0.002600,-1303.692139,0.000469,0.000000
8.010000,0.574203,-1303.692139,0.004230,0.000001,0.000035,2.554185,0.130116,0.000348,-1303.692139,0.000885,0.000000
8.260000,0.764854,-1303.736694,0.004238,0.000022,0.000547,3.402242,0.173318,0.005465,-1303.736694,0.001301,0.000000
8.510000,0.814011,-1303.647705,0.004286,0.000032,0.000824,3.620900,0.184457,0.008240,-1303.647705,0.001717,0.000000
8.760000,0.872475,-1303.736694,0.004337,0.000045,0.001145,3.880961,0.197706,0.011449,-1303.736694,0.002134,0.000000
9.010000,0.973389,-1303.692139,0.004277,0.000067,0.001691,4.329849,0.220573,0.016911,-1303.692139,0.002550,0.000000
9.260000,1.081375,-1303.692139,0.004312,0.000090,0.002281,4.810197,0.245043,0.022808,-1303.692139,0.002966,0.000000
9.510000,1.131271,-1303.736694,0.004342,0.000104,0.002654,5.032146,0.256350,0.026540,-1303.736694,0.003382,0.000000
9.760000,1.142067,-1303.692139,0.004381,0.000118,0.003001,5.080168,0.258796,0.030007,-1303.692139,0.003807,0.000000
10.010000,1.260857,-1303.692139,0.004372,0.000134,0.003400,5.608571,0.285714,0.033996,-1303.692139,0.004224,0.000000
10.260000,1.418373,-1303.736694,0.004398,0.000154,0.003920,6.309239,0.321408,0.039200,-1303.736694,0.004640,0.000000
10.510000,1.512581,-1303.736694,0.004428,0.000169,0.004293,6.728296,0.342756,0.042928,-1303.736694,0.005056,0.000000
10.760000,1.525612,-1303.781128,0.004445,0.000177,0.004484,6.786261,0.345709,0.044836,-1303.781128,0.005472,0.000000
11.010000,1.763184,-1303.781128,0.004445,0.000200,0.005082,7.843032,0.399543,0.050820,-1303.781128,0.005889,0.000000
11.260000,1.890541,-1303.736694,0.004432,0.000217,0.005507,8.409547,0.428403,0.055070,-1303.736694,0.006305,0.000000
11.510000,1.978416,-1303.736694,0.004506,0.000231,0.005862,8.800436,0.448316,0.058624,-1303.736694,0.006721,0.000000
11.760000,2.106514,-1303.736694,0.004493,0.000248,0.006287,9.370242,0.477343,0.062875,-1303.736694,0.007137,0.000000
12.010000,2.271477,-1303.736694,0.004536,0.000262,0.006643,10.104033,0.514724,0.066429,-1303.736694,0.007554,0.000000
12.260000,2.376488,-1303.692139,0.004493,0.000277,0.007033,10.571145,0.538520,0.070331,-1303.692139,0.007970,0.000000
12.510000,2.646454,-1303.781128,0.004510,0.000298,0.007562,11.772015,0.599695,0.075622,-1303.781128,0.008386,0.000000
12.760000,2.714226,-1303.781128,0.004531,0.000308,0.007831,12.073480,0.615052,0.078309,-1303.781128,0.008803,0.000000
13.010000,3.112289,-1303.736694,0.004549,0.000331,0.008412,13.844154,0.705255,0.084123,-1303.736694,0.009219,0.000000
13.260000,3.228844,-1303.781128,0.004562,0.000347,0.008820,14.362614,0.731666,0.088199,-1303.781128,0.009635,0.000000
13.510000,3.411682,-1303.736694,0.004557,0.000364,0.009236,15.175920,0.773098,0.092359,-1303.736694,0.010051,0.000000
13.760000,3.629143,-1303.692139,0.004644,0.000380,0.009652,16.143232,0.822376,0.096522,-1303.692139,0.010468,0.000000
14.010000,3.848099,-1303.781128,0.004639,0.000396,0.010060,17.117199,0.871992,0.100599,-1303.781128,0.010884,0.000000
14.260000,4.028702,-1303.692139,0.004631,0.000412,0.010476,17.920561,0.912917,0.104762,-1303.692139,0.011300,0.000000
14.510000,4.249146,-1303.736694,0.004652,0.000426,0.010832,18.901144,0.962870,0.108316,-1303.736694,0.011716,0.000000
14.760000,4.529167,-1303.781128,0.004652,0.000447,0.011361,20.146742,1.026324,0.113607,-1303.781128,0.012132,0.000000
15.010001,4.762650,-1303.781128,0.004682,0.000466,0.011846,21.185324,1.079232,0.118463,-1303.781128,0.012558,0.000000
15.260001,4.874359,-1303.781128,0.004678,0.000481,0.012219,21.682232,1.104545,0.122192,-1303.781128,0.012974,0.000000
15.510001,5.092941,-1303.781128,0.004764,0.000497,0.012627,22.654533,1.154077,0.126268,-1303.781128,0.013390,0.000000
15.760001,5.164810,-1303.736694,0.004751,0.000509,0.012939,22.974222,1.170363,0.129390,-1303.736694,0.013806,0.000000
16.010000,5.444458,-1303.736694,0.004790,0.000526,0.013364,24.218159,1.233732,0.133641,-1303.736694,0.014222,0.000000
16.260000,5.663040,-1303.736694,0.004760,0.000543,0.013789,25.190460,1.283263,0.137891,-1303.736694,0.014639,0.000000
16.510000,5.615753,-1303.736694,0.004764,0.000549,0.013936,24.980118,1.272548,0.139364,-1303.736694,0.015055,0.000000
16.760000,6.124413,-1303.736694,0.004773,0.000576,0.014630,27.242748,1.387812,0.146301,-1303.736694,0.015472,0.000000
17.010000,6.415611,-1303.781128,0.004820,0.000598,0.015185,28.538065,1.453798,0.151854,-1303.781128,0.015887,0.000000
17.260000,6.402206,-1303.736694,0.004846,0.000610,0.015506,28.478437,1.450761,0.155060,-1303.736694,0.016304,0.000000
17.510000,6.525833,-1303.736694,0.004816,0.000625,0.015870,29.028355,1.478775,0.158704,-1303.736694,0.016720,0.000000
17.760000,6.701965,-1303.736694,0.004838,0.000637,0.016174,29.811831,1.518687,0.161740,-1303.736694,0.017136,0.000000
18.010000,7.079918,-1303.647705,0.004842,0.000657,0.016677,31.493048,1.604332,0.166770,-1303.647705,0.017553,0.000000
18.260000,7.251213,-1303.736694,0.004894,0.000673,0.017084,32.255005,1.643148,0.170843,-1303.736694,0.017969,0.000000
18.510000,7.338348,-1303.736694,0.004919,0.000686,0.017423,32.642605,1.662894,0.174226,-1303.736694,0.018385,0.000000
18.760000,7.657097,-1303.781128,0.004902,0.000705,0.017900,34.060467,1.735123,0.178995,-1303.781128,0.018801,0.000000
19.010000,7.898026,-1303.736694,0.004937,0.000722,0.018351,35.132172,1.789718,0.183507,-1303.736694,0.019218,0.000000
19.260000,8.034683,-1303.736694,0.004971,0.000737,0.018715,35.740055,1.820685,0.187148,-1303.736694,0.019634,0.000000
19.510000,8.280823,-1303.692139,0.004963,0.000754,0.019157,36.834938,1.876461,0.191572,-1303.692139,0.020050,0.000000
19.760000,8.465889,-1303.781128,0.004997,0.000769,0.019539,37.658154,1.918398,0.195388,-1303.781128,0.020466,0.000000
20.010000,8.865074,-1303.692139,0.004975,0.000790,0.020059,39.433819,2.008855,0.200592,-1303.692139,0.020891,0.000000
20.260000,8.887421,-1303.736694,0.004988,0.000800,0.020328,39.533222,2.013918,0.203279,-1303.736694,0.021308,0.000000
20.510000,9.157387,-1303.781128,0.005032,0.000815,0.020701,40.734089,2.075094,0.207007,-1303.781128,0.021724,0.000000
20.760000,9.587852,-1303.736694,0.005049,0.000838,0.021273,42.648899,2.172638,0.212730,-1303.736694,0.022140,0.000000
21.010000,10.001183,-1303.692139,0.005079,0.000857,0.021759,44.487480,2.266300,0.217586,-1303.692139,0.022556,0.000000
21.260000,10.005280,-1303.647705,0.005053,0.000868,0.022045,44.505707,2.267229,0.220451,-1303.647705,0.022973,0.000000
21.510000,10.322914,-1303.647705,0.005101,0.000887,0.022539,45.918617,2.339206,0.225394,-1303.647705,0.023389,0.000000
21.760000,10.537025,-1303.647705,0.005075,0.000900,0.022851,46.871029,2.387724,0.228513,-1303.647705,0.023805,0.000000
22.010000,11.067657,-1303.692139,0.005131,0.000922,0.023415,49.231400,2.507967,0.234153,-1303.692139,0.024222,0.000000
22.260000,11.089256,-1303.692139,0.005113,0.000932,0.023684,49.327477,2.512861,0.236840,-1303.692139,0.024638,0.000000
22.510000,11.333900,-1303.692139,0.005157,0.000947,0.024065,50.415707,2.568299,0.240655,-1303.692139,0.025054,0.000000
22.760000,11.677231,-1303.692139,0.005161,0.000966,0.024542,51.942917,2.646098,0.245424,-1303.692139,0.025470,0.000000
23.010000,12.232063,-1303.692139,0.005200,0.000985,0.025028,54.410934,2.771825,0.250284,-1303.692139,0.025887,0.000000
23.260000,12.293510,-1303.647705,0.005226,0.001000,0.025392,54.684265,2.785749,0.253925,-1303.647705,0.026303,0.000000
23.510000,12.713547,-1303.736694,0.005178,0.001019,0.025887,56.552681,2.880931,0.258868,-1303.736694,0.026719,0.000000
23.760000,12.955215,-1303.692139,0.005230,0.001034,0.026268,57.627678,2.935694,0.262683,-1303.692139,0.027135,0.000000
24.010000,13.258324,-1303.647705,0.005230,0.001050,0.026667,58.975967,3.004379,0.266672,-1303.647705,0.027552,0.000000
24.260000,13.480629,-1303.692139,0.005256,0.001065,0.027040,59.964832,3.054754,0.270400,-1303.692139,0.027968,0.000000
24.510000,13.699211,-1303.692139,0.005277,0.001081,0.027448,60.937134,3.104285,0.274477,-1303.692139,0.028384,0.000000
24.760000,13.971046,-1303.647705,0.005282,0.001096,0.027829,62.146317,3.165884,0.278292,-1303.647705,0.028801,0.000000
25.010002,14.508377,-1303.603271,0.005282,0.001114,0.028298,64.536484,3.287645,0.282978,-1303.603271,0.029225,0.000000
25.260002,14.830482,-1303.558716,0.005303,0.001134,0.028801,65.969284,3.360635,0.288008,-1303.558716,0.029642,0.000000
25.510002,15.028214,-1303.647705,0.005329,0.001149,0.029182,66.848831,3.405442,0.291823,-1303.647705,0.030058,0.000000
25.760002,15.061722,-1303.647705,0.005359,0.001161,0.029486,66.997887,3.413035,0.294858,-1303.647705,0.030474,0.000000
26.010002,15.538734,-1303.647705,0.005359,0.001179,0.029954,69.119743,3.521127,0.299540,-1303.647705,0.030891,0.000000
26.260002,15.571877,-1303.692139,0.005385,0.001192,0.030266,69.267166,3.528638,0.302663,-1303.692139,0.031307,0.000000
26.510002,16.030640,-1303.647705,0.005368,0.001211,0.030761,71.307846,3.632595,0.307606,-1303.647705,0.031723,0.000000
26.760002,16.753410,-1303.603271,0.005372,0.001234,0.031350,74.522888,3.796377,0.313503,-1303.603271,0.032139,0.000000
27.010002,16.759743,-1303.558716,0.005402,0.001248,0.031689,74.551056,3.797812,0.316887,-1303.558716,0.032556,0.000000
27.260002,16.926941,-1303.558716,0.005450,0.001263,0.032088,75.294792,3.835700,0.320876,-1303.558716,0.032972,0.000000
27.510002,16.979813,-1303.647705,0.005445,0.001275,0.032391,75.529976,3.847681,0.323911,-1303.647705,0.033388,0.000000
27.760002,17.625511,-1303.647705,0.005467,0.001298,0.032981,78.402191,3.993998,0.329808,-1303.647705,0.033804,0.000000
28.010002,17.701843,-1303.647705,0.005514,0.001311,0.033301,78.741730,4.011295,0.333014,-1303.647705,0.034221,0.000000
28.260002,17.866432,-1303.647705,0.005523,0.001324,0.033631,79.473862,4.048592,0.336311,-1303.647705,0.034637,0.000000
28.510002,18.516228,-1303.647705,0.005484,0.001347,0.034212,82.364296,4.195837,0.342120,-1303.647705,0.035053,0.000000
28.760002,18.712090,-1303.647705,0.005523,0.001361,0.034577,83.235535,4.240220,0.345765,-1303.647705,0.035470,0.000000
29.010002,18.932167,-1303.603271,0.005540,0.001380,0.035053,84.214485,4.290091,0.350534,-1303.603271,0.035886,0.000000
29.260002,19.164894,-1303.603271,0.005532,0.001396,0.035470,85.249710,4.342827,0.354698,-1303.603271,0.036302,0.000000
29.510002,19.400978,-1303.603271,0.005562,0.001413,0.035886,86.299858,4.396324,0.358857,-1303.603271,0.036718,0.000000
29.760002,19.653824,-1303.603271,0.005558,0.001428,0.036259,87.424576,4.453620,0.362589,-1303.603271,0.037135,0.000000
30.010002,19.871658,-1303.692139,0.005575,0.001442,0.036632,88.393555,4.502982,0.366317,-1303.692139,0.037551,0.000000
30.260002,19.963264,-1303.647705,0.005583,0.001456,0.036987,88.801033,4.523740,0.369871,-1303.647705,0.037976,0.000000
30.510002,20.615288,-1303.603271,0.005609,0.001478,0.037534,91.701378,4.671491,0.375337,-1303.603271,0.038392,0.000000
30.760002,21.084846,-1303.558716,0.005639,0.001499,0.038080,93.790085,4.777894,0.380798,-1303.558716,0.038808,0.000000
31.010002,20.948563,-1303.558716,0.005627,0.001512,0.038401,93.183861,4.747012,0.384008,-1303.558716,0.039225,0.000000
31.260002,21.017448,-1303.603271,0.005687,0.001526,0.038757,93.490280,4.762622,0.387566,-1303.603271,0.039641,0.000000
31.510002,21.635963,-1303.603271,0.005678,0.001549,0.039338,96.241570,4.902779,0.393375,-1303.603271,0.040057,0.000000
31.760002,21.843742,-1303.647705,0.005657,0.001564,0.039728,97.165817,4.949863,0.397278,-1303.647705,0.040473,0.000000
32.010002,21.613617,-1303.603271,0.005691,0.001571,0.039910,96.142166,4.897716,0.399098,-1303.603271,0.040890,0.000000
32.260002,22.349052,-1303.647705,0.005696,0.001596,0.040534,99.413551,5.064368,0.405343,-1303.647705,0.041306,0.000000
32.510002,22.722916,-1303.647705,0.005747,0.001614,0.040985,101.076576,5.149086,0.409851,-1303.647705,0.041722,0.000000
32.760002,22.664452,-1303.603271,0.005769,0.001626,0.041289,100.816513,5.135838,0.412887,-1303.603271,0.042139,0.000000
33.010002,22.936287,-1303.603271,0.005739,0.001644,0.041748,102.025703,5.197437,0.417481,-1303.603271,0.042555,0.000000
33.260002,23.007782,-1303.647705,0.005773,0.001658,0.042113,102.343727,5.213638,0.421126,-1303.647705,0.042971,0.000000
33.510002,23.304932,-1303.558716,0.005808,0.001675,0.042546,103.665512,5.280973,0.425460,-1303.558716,0.043387,0.000000
33.760002,23.800934,-1303.514282,0.005808,0.001693,0.043006,105.871841,5.393369,0.430059,-1303.514282,0.043804,0.000000
34.010002,23.417015,-1303.558716,0.005777,0.001699,0.043162,104.164085,5.306372,0.431618,-1303.558716,0.044220,0.000000
34.260002,24.051910,-1303.603271,0.005868,0.001725,0.043812,106.988243,5.450241,0.438124,-1303.603271,0.044636,0.000000
34.510002,24.388535,-1303.558716,0.005898,0.001739,0.044159,108.485619,5.526521,0.441591,-1303.558716,0.045052,0.000000
34.760002,24.718460,-1303.558716,0.005864,0.001758,0.044645,109.953201,5.601283,0.446447,-1303.558716,0.045469,0.000000
35.010002,24.845070,-1303.514282,0.005868,0.001775,0.045078,110.516388,5.629973,0.450785,-1303.514282,0.045885,0.000000
35.260002,24.774315,-1303.603271,0.005864,0.001786,0.045356,110.201660,5.613940,0.453559,-1303.603271,0.046310,0.000000
35.510002,25.276276,-1303.603271,0.005885,0.001807,0.045894,112.434486,5.727686,0.458937,-1303.603271,0.046726,0.000000
35.760002,25.412560,-1303.514282,0.005898,0.001824,0.046319,113.040710,5.758568,0.463188,-1303.514282,0.047142,0.000000
36.010002,25.293777,-1303.603271,0.005941,0.001834,0.046596,112.512344,5.731652,0.465962,-1303.603271,0.047559,0.000000
36.260002,26.089165,-1303.603271,0.005954,0.001857,0.047168,116.050400,5.911890,0.471685,-1303.603271,0.047975,0.000000
36.510002,26.386314,-1303.514282,0.005989,0.001875,0.047619,117.372185,5.979225,0.476193,-1303.514282,0.048391,0.000000
36.760002,26.330460,-1303.603271,0.006002,0.001890,0.048010,117.123734,5.966568,0.480099,-1303.603271,0.048807,0.000000
37.010002,26.449989,-1303.558716,0.005997,0.001904,0.048357,117.655426,5.993653,0.483566,-1303.558716,0.049224,0.000000
37.260002,26.790337,-1303.558716,0.006040,0.001922,0.048816,119.169373,6.070777,0.488161,-1303.558716,0.049640,0.000000
37.510002,26.940033,-1303.514282,0.006010,0.001937,0.049189,119.835251,6.104699,0.491893,-1303.514282,0.050056,0.000000
37.760002,26.871887,-1303.514282,0.006075,0.001947,0.049458,119.532127,6.089257,0.494580,-1303.514282,0.050473,0.000000
38.010002,27.046158,-1303.603271,0.006062,0.001961,0.049813,120.307320,6.128747,0.498134,-1303.603271,0.050889,0.000000
38.260002,28.121201,-1303.514282,0.006105,0.001991,0.050559,125.089348,6.372355,0.505594,-1303.514282,0.051305,0.000000
38.510002,28.315948,-1303.558716,0.006092,0.002007,0.050984,125.955627,6.416486,0.509844,-1303.558716,0.051721,0.000000
38.760002,27.989006,-1303.514282,0.006114,0.002019,0.051279,124.501320,6.342400,0.512793,-1303.514282,0.052138,0.000000
39.010002,27.983795,-1303.558716,0.006140,0.002033,0.051643,124.478134,6.341219,0.516434,-1303.558716,0.052554,0.000000
39.260002,28.222488,-1303.558716,0.006135,0.002049,0.052042,125.539902,6.395307,0.520423,-1303.558716,0.052970,0.000000
39.510002,28.516289,-1303.603271,0.006114,0.002064,0.052415,126.846786,6.461883,0.524151,-1303.603271,0.053386,0.000000
39.760002,28.604164,-1303.514282,0.006183,0.002077,0.052762,127.237679,6.481796,0.527622,-1303.514282,0.053803,0.000000
40.010002,29.100166,-1303.603271,0.006187,0.002097,0.053265,129.444000,6.594192,0.532652,-1303.603271,0.054219,0.000000
40.260002,29.571960,-1303.514282,0.006213,0.002116,0.053742,131.542648,6.701102,0.537421,-1303.514282,0.054644,0.000000
40.510002,29.707878,-1303.603271,0.006183,0.002131,0.054132,132.147247,6.731902,0.541323,-1303.603271,0.055060,0.000000
40.760002,29.790543,-1303.558716,0.006200,0.002148,0.054549,132.514954,6.750634,0.545487,-1303.558716,0.055476,0.000000
41.010002,30.066101,-1303.558716,0.006222,0.002164,0.054965,133.740692,6.813076,0.549650,-1303.558716,0.055893,0.000000
41.260002,30.517792,-1303.558716,0.006234,0.002184,0.055468,135.749924,6.915431,0.554680,-1303.558716,0.056309,0.000000
41.510002,30.396027,-1303.558716,0.006226,0.002196,0.055780,135.208282,6.887838,0.557799,-1303.558716,0.056725,0.000000
41.760002,29.557068,-1303.603271,0.006273,0.002197,0.055815,131.476410,6.697727,0.558147,-1303.603271,0.057142,0.000000
42.010002,28.749016,-1303.558716,0.006256,0.002197,0.055815,127.882011,6.514620,0.558147,-1303.558716,0.057558,0.000000
42.260002,32.047119,-1303.603271,0.006308,0.002248,0.057107,142.552704,7.261981,0.571069,-1303.603271,0.057974,0.000000
42.510002,31.722786,-1303.514282,0.006325,0.002260,0.057402,141.110001,7.188486,0.574017,-1303.514282,0.058390,0.000000
42.760002,31.957756,-1303.603271,0.006278,0.002280,0.057905,142.155197,7.241731,0.579047,-1303.603271,0.058807,0.000000
43.010002,31.742149,-1303.558716,0.006303,0.002293,0.058234,141.196136,7.192874,0.582344,-1303.558716,0.059223,0.000000
43.260002,32.414658,-1303.558716,0.006403,0.002314,0.058781,144.187592,7.345266,0.587806,-1303.558716,0.059639,0.000000
43.510002,32.415024,-1303.558716,0.006390,0.002328,0.059136,144.189224,7.345349,0.591363,-1303.558716,0.060055,0.000000
43.760002,32.338692,-1303.603271,0.006394,0.002343,0.059500,143.849686,7.328052,0.595004,-1303.603271,0.060472,0.000000
44.010002,32.342415,-1303.558716,0.006428,0.002356,0.059839,143.866241,7.328896,0.598388,-1303.558716,0.060888,0.000000
44.260002,33.151955,-1303.558716,0.006459,0.002379,0.060420,147.467255,7.512341,0.604198,-1303.558716,0.061304,0.000000
44.510002,33.221588,-1303.514282,0.006454,0.002394,0.060801,147.777008,7.528120,0.608013,-1303.514282,0.061721,0.000000
44.760002,33.306488,-1303.558716,0.006407,0.002410,0.061209,148.154663,7.547358,0.612089,-1303.558716,0.062137,0.000000
45.010002,33.383568,-1303.558716,0.006433,0.002427,0.061651,148.497528,7.564825,0.616510,-1303.558716,0.062553,0.000000
45.260002,33.905258,-1303.514282,0.006472,0.002447,0.062145,150.818115,7.683042,0.621453,-1303.514282,0.062969,0.000000
45.510002,33.852013,-1303.558716,0.006463,0.002461,0.062510,150.581268,7.670976,0.625098,-1303.558716,0.063394,0.000000
45.760002,33.432724,-1303.603271,0.006480,0.002472,0.062779,148.716187,7.575963,0.627785,-1303.603271,0.063811,0.000000
46.010002,33.748863,-1303.558716,0.006510,0.002487,0.063160,150.122437,7.647602,0.631601,-1303.558716,0.064227,0.000000
46.260002,34.649635,-1303.558716,0.006571,0.002511,0.063767,154.129272,7.851719,0.637672,-1303.558716,0.064643,0.000000
46.510002,34.450043,-1303.558716,0.006554,0.002525,0.064131,153.241440,7.806491,0.641313,-1303.558716,0.065059,0.000000
46.760002,34.840660,-1303.514282,0.006528,0.002540,0.064522,154.979004,7.895006,0.645219,-1303.514282,0.065476,0.000000
47.010002,34.889069,-1303.558716,0.006562,0.002555,0.064895,155.194321,7.905976,0.648947,-1303.558716,0.065892,0.000000
47.260002,35.279312,-1303.558716,0.006584,0.002574,0.065380,156.930222,7.994406,0.653803,-1303.558716,0.066308,0.000000
47.510002,35.465500,-1303.514282,0.006610,0.002588,0.065736,157.758423,8.036597,0.657357,-1303.514282,0.066724,0.000000
47.760002,35.385445,-1303.558716,0.006605,0.002603,0.066126,157.402313,8.018456,0.661259,-1303.558716,0.067141,0.000000
48.010002,35.662117,-1303.603271,0.006610,0.002622,0.066594,158.633026,8.081151,0.665945,-1303.603271,0.067557,0.000000
48.260002,36.439255,-1303.558716,0.006679,0.002640,0.067063,162.089905,8.257253,0.670627,-1303.558716,0.067973,0.000000
48.510002,36.408722,-1303.603271,0.006648,0.002657,0.067496,161.954086,8.250334,0.674964,-1303.603271,0.068390,0.000000
48.760002,36.502930,-1303.558716,0.006666,0.002671,0.067852,162.373138,8.271682,0.678518,-1303.558716,0.068806,0.000000
49.010002,37.027603,-1303.647705,0.006687,0.002692,0.068381,164.707001,8.390574,0.683809,-1303.647705,0.069222,0.000000
49.260002,37.159424,-1303.603271,0.006730,0.002707,0.068754,165.293365,8.420445,0.687538,-1303.603271,0.069638,0.000000
49.510002,37.068192,-1303.603271,0.006730,0.002720,0.069083,164.887558,8.399772,0.690834,-1303.603271,0.070055,0.000000
49.760002,36.957970,-1303.558716,0.006713,0.002734,0.069456,164.397263,8.374796,0.694562,-1303.558716,0.070471,0.000000
50.010002,37.652817,-1303.603271,0.006739,0.002756,0.070002,167.488098,8.532250,0.700024,-1303.603271,0.070887,0.000000
50.260002,37.953697,-1303.603271,0.006799,0.002773,0.070427,168.826477,8.600430,0.704274,-1303.603271,0.071303,0.000000
50.510002,38.137276,-1303.603271,0.006821,0.002789,0.070835,169.643082,8.642031,0.708351,-1303.603271,0.071728,0.000000
50.760002,38.058334,-1303.603271,0.006817,0.002804,0.071225,169.291931,8.624143,0.712253,-1303.603271,0.072145,0.000000
51.010002,38.370750,-1303.558716,0.006829,0.002821,0.071650,170.681625,8.694937,0.716503,-1303.558716,0.072561,0.000000
51.260002,38.369637,-1303.603271,0.006868,0.002837,0.072058,170.676666,8.694684,0.720580,-1303.603271,0.072977,0.000000
51.510002,38.311546,-1303.558716,0.006864,0.002849,0.072370,170.418274,8.681520,0.723702,-1303.558716,0.073393,0.000000
51.760002,38.971764,-1303.647705,0.006868,0.002869,0.072882,173.355057,8.831128,0.728816,-1303.647705,0.073810,0.000000
52.010002,39.716133,-1303.603271,0.006907,0.002891,0.073437,176.666183,8.999804,0.734368,-1303.603271,0.074226,0.000000
52.260002,39.677780,-1303.603271,0.006920,0.002907,0.073827,176.495575,8.991114,0.738270,-1303.603271,0.074642,0.000000
52.510002,39.418983,-1303.647705,0.006950,0.002919,0.074148,175.344391,8.932469,0.741480,-1303.647705,0.075059,0.000000
52.760002,39.636444,-1303.603271,0.006920,0.002938,0.074625,176.311707,8.981747,0.746249,-1303.603271,0.075475,0.000000
53.010002,39.979774,-1303.603271,0.006907,0.002955,0.075050,177.838913,9.059546,0.750499,-1303.603271,0.075891,0.000000
53.260002,39.989082,-1303.603271,0.006954,0.002969,0.075414,177.880325,9.061655,0.754140,-1303.603271,0.076307,0.000000
53.510002,40.026695,-1303.603271,0.007002,0.002987,0.075882,178.047638,9.070179,0.758822,-1303.603271,0.076724,0.000000
53.760002,40.489548,-1303.647705,0.006954,0.003006,0.076342,180.106506,9.175063,0.763421,-1303.647705,0.077140,0.000000
54.010002,40.667175,-1303.558716,0.006972,0.003021,0.076724,180.896637,9.215314,0.767236,-1303.558716,0.077556,0.000000
54.260002,40.685417,-1303.603271,0.007054,0.003038,0.077157,180.977768,9.219447,0.771570,-1303.603271,0.077972,0.000000
54.510002,40.667915,-1303.647705,0.007054,0.003051,0.077504,180.899918,9.215481,0.775041,-1303.647705,0.078389,0.000000
54.760002,40.964325,-1303.647705,0.007049,0.003069,0.077947,182.218414,9.282648,0.779465,-1303.647705,0.078805,0.000000
55.010002,41.353455,-1303.647705,0.007054,0.003088,0.078423,183.949356,9.370828,0.784234,-1303.647705,0.079221,0.000000
55.260002,40.959488,-1303.558716,0.007110,0.003097,0.078675,182.196899,9.281552,0.786747,-1303.558716,0.079638,0.000000
55.510002,41.310257,-1303.647705,0.007045,0.003114,0.079100,183.757202,9.361038,0.790998,-1303.647705,0.080062,0.000000
55.760002,41.906425,-1303.603271,0.007114,0.003136,0.079646,186.409088,9.496132,0.796459,-1303.603271,0.080479,0.000000
56.010002,42.200974,-1303.603271,0.007123,0.003152,0.080054,187.719299,9.562878,0.800536,-1303.603271,0.080895,0.000000
56.260002,42.427750,-1303.558716,0.007114,0.003169,0.080487,188.728058,9.614265,0.804873,-1303.558716,0.081311,0.000000
56.510002,42.497009,-1303.603271,0.007136,0.003183,0.080860,189.036133,9.629959,0.808601,-1303.603271,0.081728,0.000000
56.760002,42.482491,-1303.603271,0.007166,0.003198,0.081225,188.971558,9.626671,0.812246,-1303.603271,0.082144,0.000000
57.010002,42.695114,-1303.603271,0.007153,0.003212,0.081580,189.917358,9.674851,0.815800,-1303.603271,0.082560,0.000000
57.260002,42.613937,-1303.603271,0.007157,0.003225,0.081910,189.556259,9.656456,0.819097,-1303.603271,0.082976,0.000000
57.510002,43.389587,-1303.603271,0.007179,0.003249,0.082525,193.006531,9.832221,0.825251,-1303.603271,0.083393,0.000000
57.760002,44.193542,-1303.603271,0.007217,0.003270,0.083054,196.582687,10.014400,0.830542,-1303.603271,0.083809,0.000000
58.010002,43.906067,-1303.603271,0.007196,0.003280,0.083306,195.303940,9.949257,0.833059,-1303.603271,0.084225,0.000000
58.260002,44.199867,-1303.647705,0.007286,0.003298,0.083757,196.610825,10.015833,0.837567,-1303.647705,0.084641,0.000000
58.510002,43.894524,-1303.558716,0.007274,0.003308,0.084025,195.252594,9.946641,0.840254,-1303.558716,0.085058,0.000000
58.760002,44.465370,-1303.558716,0.007274,0.003327,0.084511,197.791840,10.075996,0.845114,-1303.558716,0.085474,0.000000
59.010002,44.792313,-1303.603271,0.007330,0.003344,0.084927,199.246155,10.150083,0.849274,-1303.603271,0.085890,0.000000
59.260002,44.533142,-1303.558716,0.007308,0.003357,0.085266,198.093307,10.091354,0.852657,-1303.558716,0.086306,0.000000
59.510002,45.830864,-1303.603271,0.007330,0.003382,0.085890,203.865860,10.385423,0.858902,-1303.603271,0.086723,0.000000
59.760002,46.415115,-1303.647705,0.007312,0.003401,0.086385,206.464752,10.517816,0.863846,-1303.647705,0.087139,0.000000
60.010002,46.294090,-1303.647705,0.007386,0.003413,0.086697,205.926392,10.490391,0.866968,-1303.647705,0.087555,0.000000
60.260002,46.193176,-1303.558716,0.007338,0.003426,0.087026,205.477509,10.467523,0.870261,-1303.558716,0.087972,0.000000
60.510002,46.030083,-1303.603271,0.007347,0.003438,0.087321,204.752029,10.430566,0.873209,-1303.603271,0.088388,0.000000
60.760002,46.659019,-1303.603271,0.007386,0.003457,0.087798,207.549683,10.573085,0.877978,-1303.603271,0.088813,0.000000
61.010002,46.991920,-1303.603271,0.007394,0.003473,0.088214,209.030502,10.648521,0.882142,-1303.603271,0.089229,0.000000
61.260002,47.282745,-1303.603271,0.007446,0.003490,0.088639,210.324158,10.714423,0.886392,-1303.603271,0.089645,0.000000
61.510002,47.693840,-1303.692139,0.007381,0.003508,0.089099,212.152802,10.807578,0.890987,-1303.692139,0.090062,0.000000
61.760002,48.045357,-1303.603271,0.007437,0.003525,0.089532,213.716415,10.887234,0.895324,-1303.603271,0.090478,0.000000
62.010002,48.465767,-1303.692139,0.007463,0.003542,0.089957,215.586502,10.982500,0.899575,-1303.692139,0.090894,0.000000
62.260002,48.401352,-1303.603271,0.007493,0.003557,0.090356,215.299973,10.967903,0.903564,-1303.603271,0.091310,0.000000
62.510002,49.305840,-1303.647705,0.007489,0.003578,0.090877,219.323334,11.172863,0.908768,-1303.647705,0.091727,0.000000
62.760002,49.278656,-1303.603271,0.007524,0.003591,0.091215,219.202408,11.166703,0.912148,-1303.603271,0.092143,0.000000
63.010002,49.529640,-1303.647705,0.007472,0.003608,0.091631,220.318848,11.223577,0.916312,-1303.647705,0.092559,0.000000
63.260002,49.758270,-1303.603271,0.007493,0.003621,0.091970,221.335846,11.275386,0.919695,-1303.603271,0.092975,0.000000
63.510002,50.637444,-1303.647705,0.007554,0.003641,0.092481,225.246597,11.474608,0.924809,-1303.647705,0.093392,0.000000
63.760002,50.987473,-1303.603271,0.007575,0.003658,0.092906,226.803604,11.553926,0.929059,-1303.603271,0.093808,0.000000
64.010002,50.959175,-1303.647705,0.007558,0.003673,0.093296,226.677734,11.547515,0.932961,-1303.647705,0.094224,0.000000
64.260002,51.541939,-1303.647705,0.007567,0.003689,0.093704,229.269989,11.679570,0.937038,-1303.647705,0.094641,0.000000
64.510002,52.091560,-1303.647705,0.007562,0.003709,0.094198,231.714828,11.804116,0.941981,-1303.647705,0.095056,0.000000
64.760002,52.558517,-1303.647705,0.007593,0.003724,0.094580,233.791962,11.909930,0.945796,-1303.647705,0.095473,0.000000
65.010002,52.247208,-1303.603271,0.007627,0.003735,0.094866,232.407181,11.839387,0.948657,-1303.603271,0.095889,0.000000
65.260002,52.753639,-1303.736694,0.007627,0.003750,0.095239,234.659912,11.954145,0.952389,-1303.736694,0.096306,0.000000
65.510002,53.465240,-1303.647705,0.007644,0.003769,0.095742,237.825272,12.115396,0.957419,-1303.647705,0.096722,0.000000
65.760002,54.213341,-1303.692139,0.007614,0.003787,0.096184,241.152985,12.284919,0.961840,-1303.692139,0.097147,0.000000
66.010002,54.630768,-1303.647705,0.007653,0.003804,0.096618,243.009796,12.379509,0.966178,-1303.647705,0.097563,0.000000
66.260002,55.230286,-1303.603271,0.007670,0.003821,0.097043,245.676575,12.515362,0.970428,-1303.603271,0.097979,0.000000
66.510002,55.849915,-1303.647705,0.007653,0.003839,0.097502,248.432831,12.655772,0.975023,-1303.647705,0.098396,0.000000
66.760002,55.975403,-1303.692139,0.007696,0.003852,0.097832,248.991028,12.684207,0.978320,-1303.692139,0.098812,0.000000
67.010002,56.297134,-1303.647705,0.007683,0.003866,0.098196,250.422165,12.757113,0.981961,-1303.647705,0.099228,0.000000
67.260002,56.629288,-1303.603271,0.007705,0.003879,0.098534,251.899658,12.832379,0.985344,-1303.603271,0.099644,0.000000
67.510002,57.798912,-1303.692139,0.007731,0.003903,0.099141,257.102386,13.097421,0.991412,-1303.692139,0.100061,0.000000
67.760002,57.762047,-1303.692139,0.007769,0.003912,0.099367,256.938416,13.089067,0.993667,-1303.692139,0.100477,0.000000
68.010002,58.840065,-1303.692139,0.007748,0.003934,0.099922,261.733673,13.333349,0.999220,-1303.692139,0.100893,0.000000
68.260002,59.366226,-1303.692139,0.007782,0.003951,0.100355,264.074158,13.452579,1.003554,-1303.692139,0.101310,0.000000
68.510002,59.495811,-1303.692139,0.007778,0.003964,0.100694,264.650574,13.481944,1.006937,-1303.692139,0.101725,0.000000
68.760002,60.251358,-1303.647705,0.007748,0.003982,0.101136,268.011414,13.653152,1.011358,-1303.647705,0.102142,0.000000
69.010002,60.671768,-1303.736694,0.007769,0.003996,0.101492,269.881500,13.748420,1.014916,-1303.736694,0.102558,0.000000
69.260002,61.202026,-1303.692139,0.007774,0.004010,0.101847,272.240204,13.868578,1.018470,-1303.692139,0.102974,0.000000
69.510002,62.545914,-1303.692139,0.007795,0.004034,0.102463,278.218109,14.173107,1.024628,-1303.692139,0.103391,0.000000
69.760002,63.041168,-1303.692139,0.007830,0.004050,0.102862,280.421112,14.285334,1.028617,-1303.692139,0.103807,0.000000
70.010002,63.463440,-1303.692139,0.007825,0.004065,0.103261,282.299469,14.381021,1.032606,-1303.692139,0.104223,0.000000
70.260002,63.653717,-1303.736694,0.007856,0.004076,0.103538,283.145874,14.424139,1.035381,-1303.736694,0.104639,0.000000
70.510002,65.064651,-1303.736694,0.007860,0.004100,0.104128,289.422028,14.743861,1.041278,-1303.736694,0.105056,0.000000
70.760002,65.323822,-1303.647705,0.007886,0.004115,0.104509,290.574860,14.802589,1.045093,-1303.647705,0.105481,0.000000
71.010002,65.720764,-1303.647705,0.007877,0.004126,0.104796,292.340546,14.892538,1.047958,-1303.647705,0.105897,0.000000
71.260002,67.318619,-1303.736694,0.007907,0.004150,0.105411,299.448181,15.254617,1.054112,-1303.736694,0.106313,0.000000
71.510002,67.104507,-1303.692139,0.007886,0.004151,0.105429,298.495758,15.206099,1.054286,-1303.692139,0.105637,0.000000
71.760002,66.072281,-1303.692139,0.007877,0.004150,0.105420,293.904175,14.972193,1.054199,-1303.692139,0.105637,0.000000
72.010002,65.124222,-1303.736694,0.007925,0.004150,0.105411,289.687012,14.757360,1.054112,-1303.736694,0.105420,0.000000
72.260002,64.320267,-1303.647705,0.007925,0.004150,0.105411,286.110840,14.575181,1.054112,-1303.647705,0.105420,0.000000
72.510002,63.580002,-1303.692139,0.007886,0.004150,0.105403,282.817963,14.407434,1.054025,-1303.692139,0.105420,0.000000
72.760002,62.948448,-1303.692139,0.007925,0.004150,0.105403,280.008667,14.264322,1.054025,-1303.692139,0.105420,0.000000
73.010002,62.365318,-1303.736694,0.007920,0.004150,0.105403,277.414795,14.132183,1.054025,-1303.736694,0.105420,0.000000
73.260002,61.863358,-1303.692139,0.007925,0.004150,0.105403,275.181946,14.018437,1.054025,-1303.692139,0.105420,0.000000
73.510002,61.385979,-1303.647705,0.007903,0.004150,0.105403,273.058472,13.910261,1.054025,-1303.647705,0.105420,0.000000
73.760002,60.971527,-1303.736694,0.007925,0.004150,0.105403,271.214905,13.816345,1.054025,-1303.736694,0.105420,0.000000
74.010002,60.571228,-1303.692139,0.007955,0.004149,0.105394,269.434265,13.725636,1.053942,-1303.692139,0.105420,0.000000
74.260002,60.236092,-1303.692139,0.007989,0.004149,0.105394,267.943512,13.649693,1.053942,-1303.692139,0.105420,0.000000
74.510002,59.901329,-1303.736694,0.007981,0.004149,0.105394,266.454407,13.573835,1.053942,-1303.736694,0.105420,0.000000
74.760002,59.604172,-1303.692139,0.007938,0.004149,0.105394,265.132599,13.506498,1.053942,-1303.692139,0.105420,0.000000
75.010002,59.327873,-1303.647705,0.007907,0.004149,0.105394,263.903564,13.443888,1.053942,-1303.647705,0.105420,0.000000
75.260002,59.085091,-1303.736694,0.007985,0.004149,0.105394,262.823608,13.388872,1.053942,-1303.736694,0.105420,0.000000
75.510002,58.835968,-1303.692139,0.007942,0.004149,0.105394,261.715454,13.332421,1.053942,-1303.692139,0.105420,0.000000
75.760002,58.620369,-1303.692139,0.007942,0.004149,0.105394,260.756439,13.283566,1.053942,-1303.692139,0.105420,0.000000
76.010002,58.408485,-1303.692139,0.007959,0.004149,0.105394,259.813934,13.235552,1.053942,-1303.692139,0.105420,0.000000
76.260002,58.205544,-1303.692139,0.007981,0.004149,0.105394,258.911194,13.189564,1.053942,-1303.692139,0.105420,0.000000
76.510002,58.034248,-1303.692139,0.007981,0.004149,0.105394,258.149231,13.150748,1.053942,-1303.692139,0.105420,0.000000
76.760002,57.849930,-1303.647705,0.007929,0.004149,0.105394,257.329346,13.108981,1.053942,-1303.647705,0.105420,0.000000
77.010002,57.687202,-1303.692139,0.007955,0.004149,0.105394,256.605499,13.072106,1.053942,-1303.692139,0.105420,0.000000
77.260002,57.531174,-1303.692139,0.007989,0.004149,0.105394,255.911438,13.036750,1.053942,-1303.692139,0.105420,0.000000
77.510002,57.381485,-1303.692139,0.007946,0.004149,0.105394,255.245590,13.002831,1.053942,-1303.692139,0.105420,0.000000
77.760002,57.242218,-1303.647705,0.007963,0.004149,0.105394,254.626099,12.971272,1.053942,-1303.647705,0.105420,0.000000
78.010002,57.122681,-1303.736694,0.007976,0.004149,0.105394,254.094376,12.944185,1.053942,-1303.736694,0.105420,0.000000
78.260002,56.981186,-1303.692139,0.007963,0.004149,0.105394,253.464981,12.912122,1.053942,-1303.692139,0.105420,0.000000
78.510002,56.856064,-1303.736694,0.007972,0.004149,0.105394,252.908401,12.883768,1.053942,-1303.736694,0.105420,0.000000
78.760002,56.735046,-1303.692139,0.007950,0.004149,0.105394,252.370087,12.856345,1.053942,-1303.692139,0.105420,0.000000
79.010002,56.627060,-1303.647705,0.007925,0.004149,0.105394,251.889740,12.831876,1.053942,-1303.647705,0.105420,0.000000
79.260002,56.511993,-1303.692139,0.007929,0.004149,0.105394,251.377899,12.805800,1.053942,-1303.692139,0.105420,0.000000
79.510002,56.417038,-1303.736694,0.007933,0.004149,0.105394,250.955521,12.784284,1.053942,-1303.736694,0.105420,0.000000
79.760002,56.310913,-1303.736694,0.007959,0.004149,0.105394,250.483444,12.760235,1.053942,-1303.736694,0.105420,0.000000
80.010002,56.215584,-1303.647705,0.007942,0.004149,0.105394,250.059402,12.738633,1.053942,-1303.647705,0.105420,0.000000
80.260002,56.122490,-1303.692139,0.007963,0.004149,0.105394,249.645309,12.717538,1.053942,-1303.692139,0.105420,0.000000
80.510002,56.036842,-1303.692139,0.007976,0.004149,0.105394,249.264328,12.698130,1.053942,-1303.692139,0.105420,0.000000
80.760002,55.947479,-1303.647705,0.007972,0.004149,0.105394,248.866821,12.677880,1.053942,-1303.647705,0.105420,0.000000
81.010002,55.871887,-1303.692139,0.007968,0.004149,0.105394,248.530563,12.660750,1.053942,-1303.692139,0.105420,0.000000
81.260002,55.783257,-1303.692139,0.007942,0.004149,0.105394,248.136322,12.640666,1.053942,-1303.692139,0.105420,0.000000
81.510002,55.704689,-1303.647705,0.007950,0.004149,0.105394,247.786835,12.622864,1.053942,-1303.647705,0.105420,0.000000
81.760002,55.630219,-1303.692139,0.007938,0.004149,0.105394,247.455566,12.605988,1.053942,-1303.692139,0.105420,0.000000
82.010002,55.553131,-1303.603271,0.007985,0.004149,0.105394,247.112671,12.588520,1.053942,-1303.603271,0.105420,0.000000
82.260002,55.498764,-1303.692139,0.007976,0.004149,0.105394,246.870834,12.576200,1.053942,-1303.692139,0.105420,0.000000
82.510002,55.421310,-1303.692139,0.007929,0.004149,0.105394,246.526306,12.558648,1.053942,-1303.692139,0.105420,0.000000
82.760002,55.359871,-1303.736694,0.007950,0.004149,0.105394,246.253006,12.544726,1.053942,-1303.736694,0.105420,0.000000
83.010002,55.280182,-1303.692139,0.007938,0.004149,0.105394,245.898529,12.526669,1.053942,-1303.692139,0.105420,0.000000
83.260002,55.222839,-1303.647705,0.007985,0.004149,0.105394,245.643463,12.513675,1.053942,-1303.647705,0.105420,0.000000
83.510002,55.146133,-1303.736694,0.007950,0.004149,0.105394,245.302246,12.496292,1.053942,-1303.736694,0.105420,0.000000
83.760002,55.112244,-1303.647705,0.007963,0.004149,0.105394,245.151505,12.488613,1.053942,-1303.647705,0.105420,0.000000
84.010002,55.027344,-1303.603271,0.007933,0.004149,0.105394,244.773849,12.469375,1.053942,-1303.603271,0.105420,0.000000
84.260002,54.978188,-1303.647705,0.007972,0.004149,0.105394,244.555191,12.458236,1.053942,-1303.647705,0.105420,0.000000
84.510002,54.913399,-1303.603271,0.007976,0.004149,0.105394,244.266998,12.443554,1.053942,-1303.603271,0.105420,0.000000
84.760002,54.856796,-1303.647705,0.007959,0.004149,0.105394,244.015213,12.430728,1.053942,-1303.647705,0.105420,0.000000
85.010002,54.794235,-1303.603271,0.007994,0.004149,0.105394,243.736938,12.416551,1.053942,-1303.603271,0.105420,0.000000
85.260002,54.747322,-1303.692139,0.007968,0.004149,0.105394,243.528244,12.405920,1.053942,-1303.692139,0.105420,0.000000
85.510002,54.684013,-1303.647705,0.007968,0.004149,0.105394,243.246643,12.391575,1.053942,-1303.647705,0.105420,0.000000
85.760002,54.642685,-1303.692139,0.007981,0.004149,0.105394,243.062805,12.382209,1.053942,-1303.692139,0.105420,0.000000
86.010002,54.591293,-1303.647705,0.007998,0.004149,0.105394,242.834198,12.370564,1.053942,-1303.647705,0.105420,0.000000
86.260002,54.545494,-1303.647705,0.007989,0.004149,0.105394,242.630478,12.360186,1.053942,-1303.647705,0.105420,0.000000
86.510002,54.491501,-1303.603271,0.007955,0.004149,0.105394,242.390305,12.347951,1.053942,-1303.603271,0.105420,0.000000
86.760002,54.436020,-1303.692139,0.007968,0.004149,0.105394,242.143509,12.335378,1.053942,-1303.692139,0.105420,0.000000
87.010002,54.393936,-1303.647705,0.007994,0.004149,0.105394,241.956314,12.325842,1.053942,-1303.647705,0.105420,0.000000
87.260002,54.344788,-1303.692139,0.007976,0.004149,0.105394,241.737686,12.314705,1.053942,-1303.692139,0.105420,0.000000
87.510002,54.304939,-1303.603271,0.007998,0.004149,0.105394,241.560440,12.305676,1.053942,-1303.603271,0.105420,0.000000
87.760002,54.258026,-1303.603271,0.007963,0.004149,0.105394,241.351761,12.295045,1.053942,-1303.603271,0.105420,0.000000
88.010002,54.217064,-1303.603271,0.007959,0.004149,0.105394,241.169540,12.285762,1.053942,-1303.603271,0.105420,0.000000
88.260002,54.170143,-1303.692139,0.007985,0.004149,0.105394,240.960831,12.275130,1.053942,-1303.692139,0.105420,0.000000
88.510002,54.134766,-1303.692139,0.008011,0.004149,0.105394,240.803467,12.267113,1.053942,-1303.692139,0.105420,0.000000
88.760002,54.091202,-1303.603271,0.008011,0.004149,0.105394,240.609680,12.257241,1.053942,-1303.603271,0.105420,0.000000
89.010002,54.057312,-1303.603271,0.007963,0.004149,0.105394,240.458939,12.249562,1.053942,-1303.603271,0.105420,0.000000
89.260002,54.010025,-1303.692139,0.007972,0.004149,0.105394,240.248596,12.238847,1.053942,-1303.692139,0.105420,0.000000
89.510002,53.975761,-1303.603271,0.007968,0.004149,0.105394,240.096176,12.231083,1.053942,-1303.603271,0.105420,0.000000
89.760002,53.926613,-1303.603271,0.007994,0.004149,0.105394,239.877548,12.219945,1.053942,-1303.603271,0.105420,0.000000
90.010002,53.911346,-1303.603271,0.007955,0.004149,0.105394,239.809647,12.216485,1.053942,-1303.603271,0.105420,0.000000
90.260002,53.858467,-1303.603271,0.007950,0.004149,0.105394,239.574432,12.204503,1.053942,-1303.603271,0.105420,0.000000
90.510002,53.836868,-1303.692139,0.007946,0.004149,0.105394,239.478348,12.199609,1.053942,-1303.692139,0.105420,0.000000
90.760002,53.796280,-1303.603271,0.007985,0.004149,0.105394,239.297806,12.190412,1.053942,-1303.603271,0.105420,0.000000
91.010002,53.782501,-1303.603271,0.007972,0.004149,0.105394,239.236511,12.187289,1.053942,-1303.603271,0.105420,0.000000
91.260002,53.718452,-1303.603271,0.007976,0.004149,0.105394,238.951614,12.172776,1.053942,-1303.603271,0.105420,0.000000
91.510002,53.693130,-1303.603271,0.007968,0.004149,0.105394,238.838974,12.167037,1.053942,-1303.603271,0.105420,0.000000
91.760002,53.657761,-1303.558716,0.007994,0.004149,0.105394,238.681641,12.159022,1.053942,-1303.558716,0.105420,0.000000
92.010002,53.633926,-1303.647705,0.007942,0.004149,0.105394,238.575623,12.153621,1.053942,-1303.647705,0.105420,0.000000
92.260002,53.605255,-1303.647705,0.007994,0.004149,0.105394,238.448090,12.147124,1.053942,-1303.647705,0.105420,0.000000
92.510002,53.580307,-1303.647705,0.007963,0.004149,0.105394,238.337112,12.141472,1.053942,-1303.647705,0.105420,0.000000
92.760002,53.552002,-1303.647705,0.007963,0.004149,0.105394,238.211197,12.135056,1.053942,-1303.647705,0.105420,0.000000
93.010002,53.525192,-1303.603271,0.007963,0.004149,0.105394,238.091949,12.128983,1.053942,-1303.603271,0.105420,0.000000
93.260002,53.486092,-1303.692139,0.007976,0.004149,0.105394,237.918015,12.120122,1.053942,-1303.692139,0.105420,0.000000
93.510002,53.460030,-1303.647705,0.008006,0.004149,0.105394,237.802094,12.114216,1.053942,-1303.647705,0.105420,0.000000
93.760002,53.444016,-1303.647705,0.007998,0.004149,0.105394,237.730850,12.110587,1.053942,-1303.647705,0.105420,0.000000
94.010002,53.412361,-1303.647705,0.007985,0.004149,0.105394,237.590042,12.103414,1.053942,-1303.647705,0.105420,0.000000
94.260002,53.385185,-1303.558716,0.007959,0.004149,0.105394,237.469162,12.097256,1.053942,-1303.558716,0.105420,0.000000
94.510002,53.356140,-1303.603271,0.007994,0.004149,0.105394,237.339966,12.090674,1.053942,-1303.603271,0.105420,0.000000
94.760002,53.336403,-1303.692139,0.007950,0.004149,0.105394,237.252167,12.086201,1.053942,-1303.692139,0.105420,0.000000
95.010002,53.312943,-1303.603271,0.008006,0.004149,0.105394,237.147812,12.080886,1.053942,-1303.603271,0.105420,0.000000
95.260002,53.283897,-1303.647705,0.007963,0.004149,0.105394,237.018616,12.074304,1.053942,-1303.647705,0.105420,0.000000
95.510002,53.259689,-1303.647705,0.007972,0.004149,0.105394,236.910934,12.068818,1.053942,-1303.647705,0.105420,0.000000
95.760002,53.238098,-1303.603271,0.008011,0.004149,0.105394,236.814880,12.063926,1.053942,-1303.603271,0.105420,0.000000
96.010002,53.217987,-1303.647705,0.007998,0.004149,0.105394,236.725433,12.059368,1.053942,-1303.647705,0.105420,0.000000
96.260002,53.187080,-1303.603271,0.007938,0.004149,0.105394,236.587952,12.052365,1.053942,-1303.603271,0.105420,0.000000
96.510002,53.145744,-1303.647705,0.008019,0.004149,0.105394,236.404083,12.042998,1.053942,-1303.647705,0.105420,0.000000
96.760002,53.146118,-1303.603271,0.007994,0.004149,0.105394,236.405746,12.043082,1.053942,-1303.603271,0.105420,0.000000
97.010002,53.112976,-1303.603271,0.007976,0.004149,0.105394,236.258316,12.035573,1.053942,-1303.603271,0.105420,0.000000
97.260002,53.085793,-1303.692139,0.008019,0.004149,0.105394,236.137405,12.029412,1.053942,-1303.692139,0.105420,0.000000
97.510002,53.069778,-1303.647705,0.008024,0.004149,0.105394,236.066162,12.025784,1.053942,-1303.647705,0.105420,0.000000
97.760002,53.040367,-1303.603271,0.007950,0.004149,0.105394,235.935333,12.019119,1.053942,-1303.603271,0.105420,0.000000
98.010002,53.015419,-1303.603271,0.007976,0.004149,0.105394,235.824356,12.013466,1.053942,-1303.603271,0.105420,0.000000
98.260002,53.000145,-1303.647705,0.008002,0.004149,0.105394,235.756424,12.010004,1.053942,-1303.647705,0.105420,0.000000
98.510002,52.974083,-1303.647705,0.007976,0.004149,0.105394,235.640488,12.004099,1.053942,-1303.647705,0.105420,0.000000
98.760002,52.957695,-1303.603271,0.008015,0.004149,0.105394,235.567596,12.000385,1.053942,-1303.603271,0.105420,0.000000
99.010002,52.939453,-1303.558716,0.008015,0.004149,0.105394,235.486450,11.996251,1.053942,-1303.558716,0.105420,0.000000
99.260002,52.910408,-1303.603271,0.008002,0.004149,0.105394,235.357254,11.989670,1.053942,-1303.603271,0.105420,0.000000
99.510002,52.892159,-1303.603271,0.007976,0.004149,0.105394,235.276077,11.985535,1.053942,-1303.603271,0.105420,0.000000
99.760002,52.862740,-1303.647705,0.008015,0.004149,0.105394,235.145203,11.978868,1.053942,-1303.647705,0.105420,0.000000
100.010002,52.850830,-1303.647705,0.007998,0.004149,0.105394,235.092239,11.976169,1.053942,-1303.647705,0.105420,0.000000
100.260002,52.827744,-1303.603271,0.007959,0.004149,0.105394,234.989532,11.970938,1.053942,-1303.603271,0.105420,0.000000
100.510002,52.791245,-1303.647705,0.008006,0.004149,0.105394,234.827179,11.962667,1.053942,-1303.647705,0.105420,0.000000
100.760002,52.784546,-1303.647705,0.007981,0.004149,0.105394,234.797394,11.961149,1.053942,-1303.647705,0.105420,0.000000
101.010002,52.770767,-1303.647705,0.007998,0.004149,0.105394,234.736099,11.958027,1.053942,-1303.647705,0.105420,0.000000
101.260002,52.733902,-1303.647705,0.007950,0.004149,0.105394,234.572113,11.949673,1.053942,-1303.647705,0.105420,0.000000
101.510002,52.719749,-1303.603271,0.007959,0.004149,0.105394,234.509155,11.946466,1.053942,-1303.603271,0.105420,0.000000
101.760002,52.704109,-1303.603271,0.007998,0.004149,0.105394,234.439590,11.942923,1.053942,-1303.603271,0.105420,0.000000
101.900002,52.692940,-1303.692139,0.007963,0.004149,0.105394,234.389908,11.940391,1.053942,-1303.692139,0.105420,0.000000