File: Data/Automembrane/AutoNoheat10-1-4_12132023_185155.csv
Time (sec),S:Load (lbs),S:HL1 (DIM),S:LVDT (in),S:Position (in),Ch:Position (mm),Ch:Load (N),Ch:Stress (MPa),Ch:Strain (mm/mm),Ch:HL1 (DIM),Set Point (),Cycles ()
0.110000,-0.000748,-1305.338013,-0.000043,-0.000000,-0.000000,-0.003326,-0.000169,-0.000000,-1305.338013,0.000182,0.000000
0.360000,-0.006706,-1305.338013,-0.000039,-0.000000,-0.000000,-0.029831,-0.001520,-0.000000,-1305.338013,0.000182,0.000000
0.610000,-0.004845,-1305.338013,-0.000065,0.000116,0.002940,-0.021550,-0.001098,0.029397,-1305.338013,0.003946,0.000000
0.860000,-0.056976,-1305.293457,0.000086,0.000277,0.007042,-0.253443,-0.012911,0.070418,-1305.293457,0.008108,0.000000
1.110000,-0.001488,-1305.249023,0.000259,0.000439,0.011144,-0.006618,-0.000337,0.111439,-1305.249023,0.012271,0.000000
1.360000,0.024948,-1305.293457,0.000401,0.000599,0.015202,0.110975,0.005653,0.152024,-1305.293457,0.016434,0.000000
1.610000,0.008560,-1305.293457,0.000569,0.000773,0.019625,0.038078,0.001940,0.196251,-1305.293457,0.020596,0.000000
1.860000,-0.023460,-1305.293457,0.000746,0.000933,0.023692,-0.104357,-0.005316,0.236923,-1305.293457,0.024759,0.000000
2.110000,0.012657,-1305.338013,0.000974,0.001095,0.027812,0.056302,0.002868,0.278118,-1305.338013,0.028922,0.000000
2.360000,0.011543,-1305.293457,0.001069,0.001266,0.032148,0.051347,0.002616,0.321478,-1305.293457,0.033102,0.000000
2.610000,-0.001122,-1305.249023,0.001298,0.001423,0.036137,-0.004989,-0.000254,0.361370,-1305.249023,0.037265,0.000000
2.860000,0.010056,-1305.204590,0.001449,0.001592,0.040430,0.044729,0.002279,0.404299,-1305.204590,0.041427,0.000000
3.110000,0.026436,-1305.249023,0.001630,0.001750,0.044463,0.117593,0.005990,0.444627,-1305.249023,0.045590,0.000000
3.360000,0.040588,-1305.249023,0.001759,0.001918,0.048729,0.180546,0.009197,0.487294,-1305.249023,0.049752,0.000000
3.610000,0.067772,-1305.293457,0.001975,0.002079,0.052797,0.301465,0.015357,0.527966,-1305.293457,0.053915,0.000000
3.860000,0.163841,-1305.293457,0.002095,0.002242,0.056951,0.728802,0.037127,0.569506,-1305.293457,0.058078,0.000000
4.110000,0.256187,-1305.249023,0.002276,0.002412,0.061269,1.139579,0.058053,0.612695,-1305.249023,0.062241,0.000000
4.360000,0.352638,-1305.204590,0.002492,0.002576,0.065432,1.568613,0.079909,0.654321,-1305.204590,0.066421,0.000000
4.610000,0.500839,-1305.293457,0.002587,0.002737,0.069525,2.227844,0.113492,0.695255,-1305.293457,0.070583,0.000000
4.860000,0.670265,-1305.204590,0.002790,0.002895,0.073523,2.981488,0.151884,0.735231,-1305.204590,0.074746,0.000000
5.110000,0.573082,-1305.204590,0.002828,-0.000001,-0.000026,2.549196,0.129862,-0.000261,-1305.204590,0.000112,0.000000
5.360000,0.548134,-1305.293457,0.002790,-0.000001,-0.000026,2.438221,0.124209,-0.000261,-1305.293457,0.000112,0.000000
5.610000,0.520576,-1305.204590,0.002854,-0.000001,-0.000026,2.315640,0.117964,-0.000261,-1305.204590,0.000477,0.000000
5.860000,0.528770,-1305.249023,0.002772,0.000001,0.000034,2.352088,0.119821,0.000344,-1305.249023,0.000893,0.000000
6.110000,0.562279,-1305.249023,0.002841,0.000015,0.000382,2.501141,0.127414,0.003815,-1305.249023,0.001318,0.000000
6.360000,0.583878,-1305.160034,0.002850,0.000028,0.000702,2.597217,0.132309,0.007025,-1305.160034,0.001734,0.000000
6.610000,0.596542,-1305.249023,0.002863,0.000046,0.001162,2.653553,0.135178,0.011620,-1305.249023,0.002151,0.000000
6.860000,0.665802,-1305.115601,0.002846,0.000066,0.001665,2.961635,0.150873,0.016650,-1305.115601,0.002567,0.000000
7.110000,0.697083,-1305.160034,0.002854,0.000084,0.002133,3.100778,0.157961,0.021332,-1305.160034,0.002983,0.000000
7.360000,0.724632,-1305.115601,0.002846,0.000095,0.002419,3.223325,0.164204,0.024193,-1305.115601,0.003399,0.000000
7.610000,0.751450,-1305.160034,0.002932,0.000112,0.002836,3.342615,0.170281,0.028356,-1305.160034,0.003816,0.000000
7.860001,0.768944,-1305.160034,0.002884,0.000130,0.003295,3.420433,0.174245,0.032951,-1305.160034,0.004232,0.000000
8.110001,0.779373,-1305.115601,0.002915,0.000150,0.003816,3.466825,0.176608,0.038156,-1305.115601,0.004648,0.000000
8.360001,0.789803,-1305.115601,0.002997,0.000163,0.004137,3.513217,0.178972,0.041365,-1305.115601,0.005065,0.000000
8.610001,0.791290,-1305.115601,0.003018,0.000179,0.004553,3.519835,0.179309,0.045529,-1305.115601,0.005481,0.000000
8.860001,0.836349,-1305.160034,0.002984,0.000197,0.004995,3.720268,0.189520,0.049949,-1305.160034,0.005897,0.000000
9.110001,0.882149,-1305.115601,0.003005,0.000213,0.005420,3.923994,0.199898,0.054200,-1305.115601,0.006313,0.000000
9.360001,0.909706,-1305.115601,0.003005,0.000229,0.005819,4.046575,0.206142,0.058189,-1305.115601,0.006730,0.000000
9.610001,0.926460,-1305.115601,0.002997,0.000243,0.006166,4.121101,0.209939,0.061660,-1305.115601,0.007146,0.000000
9.860001,0.909332,-1305.071045,0.003027,0.000254,0.006461,4.044912,0.206058,0.064608,-1305.071045,0.007562,0.000000
10.110001,0.983063,-1305.115601,0.003048,0.000281,0.007128,4.372881,0.222765,0.071285,-1305.115601,0.007978,0.000000
10.360001,0.982689,-1305.115601,0.003083,0.000293,0.007432,4.371219,0.222680,0.074320,-1305.115601,0.008395,0.000000
10.610001,0.995346,-1305.115601,0.003109,0.000315,0.008004,4.427520,0.225549,0.080043,-1305.115601,0.008811,0.000000
10.860001,1.021416,-1305.071045,0.003130,0.000328,0.008343,4.543484,0.231456,0.083427,-1305.071045,0.009227,0.000000
11.110001,1.059395,-1305.071045,0.003147,0.000341,0.008663,4.712424,0.240062,0.086632,-1305.071045,0.009644,0.000000
11.360001,1.075783,-1305.115601,0.003104,0.000355,0.009010,4.785321,0.243776,0.090103,-1305.115601,0.010068,0.000000
11.610001,1.148392,-1305.071045,0.003195,0.000376,0.009557,5.108302,0.260229,0.095569,-1305.071045,0.010485,0.000000
11.860001,1.169991,-1305.071045,0.003143,0.000394,0.009999,5.204378,0.265124,0.099989,-1305.071045,0.010901,0.000000
12.110001,1.201645,-1305.071045,0.003221,0.000412,0.010458,5.345183,0.272297,0.104584,-1305.071045,0.011317,0.000000
12.360001,1.196060,-1305.115601,0.003225,0.000430,0.010910,5.320342,0.271031,0.109096,-1305.115601,0.011734,0.000000
12.610001,1.241119,-1305.071045,0.003251,0.000447,0.011352,5.520775,0.281242,0.113517,-1305.071045,0.012150,0.000000
12.860001,1.244469,-1305.071045,0.003264,0.000456,0.011586,5.535673,0.282001,0.115859,-1305.071045,0.012566,0.000000
13.110001,1.352455,-1305.071045,0.003268,0.000475,0.012072,6.016021,0.306471,0.120715,-1305.071045,0.012982,0.000000
13.360001,1.363998,-1305.071045,0.003320,0.000487,0.012366,6.067368,0.309086,0.123664,-1305.071045,0.013399,0.000000
13.610001,1.406822,-1305.071045,0.003290,0.000502,0.012757,6.257858,0.318790,0.127566,-1305.071045,0.013815,0.000000
13.860001,1.504379,-1305.071045,0.003303,0.000528,0.013416,6.691813,0.340897,0.134159,-1305.071045,0.014231,0.000000
14.110001,1.481667,-1305.071045,0.003346,0.000543,0.013789,6.590782,0.335750,0.137888,-1305.071045,0.014647,0.000000
14.360001,1.495071,-1305.071045,0.003328,0.000558,0.014170,6.650410,0.338788,0.141703,-1305.071045,0.015064,0.000000
14.610001,1.527840,-1305.115601,0.003380,0.000574,0.014569,6.796170,0.346213,0.145692,-1305.115601,0.015480,0.000000
14.860001,1.619820,-1305.160034,0.003341,0.000595,0.015107,7.205317,0.367056,0.151070,-1305.160034,0.015896,0.000000
15.110001,1.620560,-1305.071045,0.003393,0.000608,0.015445,7.208610,0.367224,0.154450,-1305.071045,0.016313,0.000000
15.360001,1.669342,-1305.071045,0.003419,0.000621,0.015783,7.425604,0.378278,0.157834,-1305.071045,0.016728,0.000000
15.610001,1.734512,-1305.115601,0.003445,0.000641,0.016278,7.715496,0.393046,0.162777,-1305.115601,0.017145,0.000000
15.860001,1.754616,-1305.071045,0.003462,0.000654,0.016616,7.804921,0.397602,0.166161,-1305.071045,0.017561,0.000000
16.110001,1.765045,-1305.071045,0.003458,0.000675,0.017145,7.851313,0.399965,0.171448,-1305.071045,0.017977,0.000000
16.360001,1.814194,-1305.071045,0.003488,0.000693,0.017596,8.069937,0.411102,0.175960,-1305.071045,0.018403,0.000000
16.610001,1.860001,-1305.071045,0.003449,0.000709,0.018004,8.273696,0.421482,0.180036,-1305.071045,0.018818,0.000000
16.860001,1.953835,-1305.115601,0.003514,0.000726,0.018437,8.691090,0.442745,0.184370,-1305.115601,0.019235,0.000000
17.110001,1.971336,-1305.071045,0.003544,0.000740,0.018793,8.768942,0.446711,0.187928,-1305.071045,0.019651,0.000000
17.360001,2.010437,-1305.115601,0.003510,0.000751,0.019070,8.942870,0.455572,0.190702,-1305.115601,0.020068,0.000000
17.610001,2.114326,-1305.071045,0.003579,0.000774,0.019669,9.404994,0.479113,0.196686,-1305.071045,0.020484,0.000000
17.860001,2.178375,-1305.071045,0.003544,0.000796,0.020206,9.689897,0.493627,0.202060,-1305.071045,0.020900,0.000000
18.110001,2.115074,-1305.115601,0.003591,0.000808,0.020536,9.408319,0.479283,0.205357,-1305.115601,0.021316,0.000000
18.360001,2.163857,-1305.160034,0.003561,0.000823,0.020909,9.625315,0.490337,0.209085,-1305.160034,0.021732,0.000000
18.610001,2.290092,-1305.115601,0.003604,0.000843,0.021412,10.186840,0.518942,0.214115,-1305.115601,0.022149,0.000000
18.860001,2.299400,-1305.071045,0.003600,0.000857,0.021776,10.228244,0.521052,0.217760,-1305.071045,0.022565,0.000000
19.110001,2.325089,-1305.071045,0.003617,0.000868,0.022036,10.342510,0.526873,0.220360,-1305.071045,0.022982,0.000000
19.360001,2.442764,-1305.115601,0.003669,0.000889,0.022583,10.865958,0.553538,0.225826,-1305.115601,0.023397,0.000000
19.610001,2.531387,-1305.160034,0.003673,0.000909,0.023094,11.260173,0.573621,0.230939,-1305.160034,0.023814,0.000000
19.860001,2.491913,-1305.160034,0.003682,0.000923,0.023432,11.084582,0.564676,0.234323,-1305.160034,0.024230,0.000000
20.110001,2.560806,-1305.160034,0.003686,0.000940,0.023883,11.391035,0.580287,0.238831,-1305.160034,0.024646,0.000000
20.360001,2.567879,-1305.160034,0.003721,0.000954,0.024230,11.422495,0.581890,0.242301,-1305.160034,0.025063,0.000000
20.610001,2.643845,-1305.160034,0.003704,0.000968,0.024586,11.760408,0.599104,0.245855,-1305.160034,0.025479,0.000000
20.860001,2.725021,-1305.115601,0.003764,0.000987,0.025072,12.121500,0.617499,0.250715,-1305.115601,0.025895,0.000000
21.110001,2.696716,-1305.115601,0.003764,0.000998,0.025340,11.995593,0.611085,0.253403,-1305.115601,0.026311,0.000000
21.360001,2.916046,-1305.249023,0.003768,0.001021,0.025939,12.971221,0.660785,0.259386,-1305.249023,0.026736,0.000000
21.610001,2.903389,-1305.115601,0.003833,0.001038,0.026355,12.914919,0.657917,0.263550,-1305.115601,0.027153,0.000000
21.860001,2.965202,-1305.160034,0.003824,0.001054,0.026771,13.189878,0.671924,0.267709,-1305.160034,0.027569,0.000000
22.110001,2.977119,-1305.115601,0.003863,0.001071,0.027205,13.242888,0.674625,0.272047,-1305.115601,0.027985,0.000000
22.360001,2.963707,-1305.115601,0.003867,0.001082,0.027491,13.183227,0.671586,0.274908,-1305.115601,0.028401,0.000000
22.610001,3.120110,-1305.071045,0.003889,0.001102,0.027994,13.878941,0.707027,0.279938,-1305.071045,0.028818,0.000000
22.860001,3.156227,-1305.115601,0.003850,0.001117,0.028375,14.039599,0.715211,0.283754,-1305.115601,0.029234,0.000000
23.110001,3.193092,-1305.160034,0.003859,0.001131,0.028731,14.203584,0.723565,0.287311,-1305.160034,0.029650,0.000000
23.360001,3.279114,-1305.115601,0.003867,0.001152,0.029251,14.586226,0.743058,0.292512,-1305.115601,0.030066,0.000000
23.610001,3.323051,-1305.115601,0.003919,0.001170,0.029711,14.781672,0.753014,0.297110,-1305.115601,0.030483,0.000000
23.860001,3.329010,-1305.071045,0.003902,0.001182,0.030023,14.808176,0.754364,0.300233,-1305.071045,0.030899,0.000000
24.110001,3.397522,-1305.160034,0.003932,0.001199,0.030465,15.112932,0.769890,0.304654,-1305.160034,0.031315,0.000000
24.360001,3.443695,-1305.160034,0.003923,0.001216,0.030882,15.318320,0.780352,0.308817,-1305.160034,0.031732,0.000000
24.610001,3.518921,-1305.160034,0.003928,0.001230,0.031255,15.652942,0.797399,0.312545,-1305.160034,0.032148,0.000000
24.860001,3.517426,-1305.115601,0.003992,0.001242,0.031549,15.646290,0.797060,0.315494,-1305.115601,0.032564,0.000000
25.110001,3.637329,-1305.115601,0.003980,0.001260,0.032001,16.179647,0.824231,0.320005,-1305.115601,0.032980,0.000000
25.360001,3.782188,-1305.115601,0.003988,0.001283,0.032590,16.824015,0.857056,0.325902,-1305.115601,0.033397,0.000000
25.610001,3.806015,-1305.160034,0.004027,0.001302,0.033067,16.930000,0.862455,0.330671,-1305.160034,0.033813,0.000000
25.860001,3.756119,-1305.160034,0.004057,0.001314,0.033379,16.708052,0.851149,0.333794,-1305.160034,0.034229,0.000000
26.110001,3.804901,-1305.204590,0.004079,0.001329,0.033761,16.925045,0.862203,0.337609,-1305.204590,0.034645,0.000000
26.360001,3.883842,-1305.204590,0.004057,0.001344,0.034142,17.276194,0.880091,0.341424,-1305.204590,0.035062,0.000000
26.610001,4.037262,-1305.071045,0.004061,0.001363,0.034611,17.958637,0.914857,0.346110,-1305.071045,0.035487,0.000000
26.860001,3.973961,-1305.115601,0.004083,0.001375,0.034915,17.677061,0.900512,0.349145,-1305.115601,0.035903,0.000000
27.110001,4.109497,-1305.115601,0.004126,0.001393,0.035374,18.279957,0.931225,0.353740,-1305.115601,0.036319,0.000000
27.360001,4.189186,-1305.115601,0.004165,0.001409,0.035782,18.634430,0.949283,0.357816,-1305.115601,0.036735,0.000000
27.610001,4.142639,-1305.071045,0.004143,0.001420,0.036068,18.427380,0.938735,0.360678,-1305.071045,0.037152,0.000000
27.860001,4.312073,-1305.071045,0.004191,0.001443,0.036649,19.181057,0.977130,0.366488,-1305.071045,0.037568,0.000000
28.110001,4.412239,-1305.115601,0.004204,0.001463,0.037152,19.626619,0.999828,0.371518,-1305.115601,0.037984,0.000000
28.360001,4.484856,-1305.160034,0.004208,0.001480,0.037603,19.949635,1.016283,0.376029,-1305.160034,0.038401,0.000000
28.610001,4.458038,-1305.204590,0.004199,0.001494,0.037941,19.830345,1.010206,0.379409,-1305.204590,0.038817,0.000000
28.860001,4.540337,-1305.160034,0.004204,0.001510,0.038349,20.196426,1.028855,0.383486,-1305.160034,0.039233,0.000000
29.110001,4.614067,-1305.115601,0.004268,0.001526,0.038765,20.524395,1.045563,0.387649,-1305.115601,0.039649,0.000000
29.360001,4.723167,-1305.160034,0.004234,0.001546,0.039268,21.009699,1.070285,0.392679,-1305.160034,0.040066,0.000000
29.610001,4.691521,-1305.115601,0.004264,0.001559,0.039606,20.868927,1.063114,0.396059,-1305.115601,0.040482,0.000000
29.860001,4.750351,-1305.160034,0.004247,0.001576,0.040022,21.130617,1.076445,0.400222,-1305.160034,0.040898,0.000000
30.110001,4.841583,-1305.160034,0.004299,0.001592,0.040430,21.536438,1.097118,0.404299,-1305.160034,0.041314,0.000000
30.360001,4.976387,-1305.160034,0.004329,0.001609,0.040881,22.136076,1.127665,0.408810,-1305.160034,0.041731,0.000000
30.610001,4.974525,-1305.115601,0.004320,0.001625,0.041263,22.127794,1.127244,0.412625,-1305.115601,0.042147,0.000000
30.860001,5.003937,-1305.115601,0.004359,0.001639,0.041635,22.258623,1.133908,0.416354,-1305.115601,0.042563,0.000000
31.110001,5.017715,-1305.115601,0.004342,0.001653,0.041974,22.319914,1.137031,0.419737,-1305.115601,0.042979,0.000000
31.360001,5.285080,-1305.160034,0.004359,0.001675,0.042537,23.509211,1.197616,0.425373,-1305.160034,0.043396,0.000000
31.610001,5.196083,-1305.115601,0.004329,0.001690,0.042928,23.113333,1.177449,0.429275,-1305.115601,0.043821,0.000000
31.860001,5.322319,-1305.204590,0.004389,0.001707,0.043353,23.674858,1.206055,0.433526,-1305.204590,0.044237,0.000000
32.110001,5.249702,-1305.115601,0.004406,0.001721,0.043708,23.351843,1.189600,0.437080,-1305.115601,0.044653,0.000000
32.360001,5.317474,-1305.160034,0.004432,0.001735,0.044072,23.653307,1.204957,0.440721,-1305.160034,0.045069,0.000000
32.610001,5.357323,-1305.160034,0.004389,0.001752,0.044497,23.830561,1.213987,0.444971,-1305.160034,0.045486,0.000000
32.860001,5.510368,-1305.160034,0.004415,0.001770,0.044948,24.511343,1.248667,0.449483,-1305.160034,0.045902,0.000000
33.110001,5.564362,-1305.115601,0.004484,0.001785,0.045347,24.751516,1.260902,0.453472,-1305.115601,0.046318,0.000000
33.360001,5.760597,-1305.204590,0.004471,0.001809,0.045954,25.624416,1.305370,0.459543,-1305.204590,0.046735,0.000000
33.610001,5.660057,-1305.115601,0.004488,0.001824,0.046327,25.177191,1.282587,0.463271,-1305.115601,0.047151,0.000000
33.860001,5.639206,-1305.160034,0.004471,0.001838,0.046674,25.084440,1.277862,0.466738,-1305.160034,0.047567,0.000000
34.110001,5.652985,-1305.115601,0.004510,0.001852,0.047030,25.145731,1.280985,0.470296,-1305.115601,0.047983,0.000000
34.360001,5.828743,-1305.071045,0.004501,0.001869,0.047463,25.927544,1.320812,0.474630,-1305.071045,0.048400,0.000000
34.610001,5.926682,-1305.115601,0.004540,0.001885,0.047879,26.363195,1.343005,0.478793,-1305.115601,0.048816,0.000000
34.860001,5.890556,-1305.071045,0.004506,0.001899,0.048235,26.202503,1.334819,0.482351,-1305.071045,0.049232,0.000000
35.110001,6.011581,-1305.115601,0.004549,0.001918,0.048729,26.740850,1.362244,0.487294,-1305.115601,0.049648,0.000000
35.360001,6.145630,-1305.115601,0.004579,0.001937,0.049189,27.337128,1.392620,0.491889,-1305.115601,0.050065,0.000000
35.610001,6.049934,-1305.160034,0.004596,0.001953,0.049597,26.911451,1.370935,0.495965,-1305.160034,0.050481,0.000000
35.860001,6.147125,-1305.115601,0.004570,0.001968,0.049987,27.343779,1.392958,0.499867,-1305.115601,0.050897,0.000000
36.110001,6.301285,-1305.160034,0.004626,0.001988,0.050490,28.029514,1.427892,0.504897,-1305.160034,0.051314,0.000000
36.360001,6.276337,-1305.071045,0.004626,0.002003,0.050889,27.918539,1.422238,0.508887,-1305.071045,0.051730,0.000000
36.610001,6.252129,-1305.071045,0.004631,0.002016,0.051210,27.810858,1.416753,0.512096,-1305.071045,0.052155,0.000000
36.860001,6.226440,-1305.071045,0.004613,0.002029,0.051548,27.696590,1.410932,0.515476,-1305.071045,0.052571,0.000000
37.110001,6.550034,-1305.115601,0.004708,0.002055,0.052190,29.136005,1.484259,0.521895,-1305.115601,0.052987,0.000000
37.360001,6.527313,-1305.115601,0.004669,0.002070,0.052571,29.034939,1.479110,0.525711,-1305.115601,0.053404,0.000000
37.610001,6.466621,-1305.204590,0.004691,0.002085,0.052961,28.764969,1.465357,0.529613,-1305.204590,0.053820,0.000000
37.860001,6.463264,-1305.115601,0.004717,0.002101,0.053378,28.750036,1.464597,0.533776,-1305.115601,0.054236,0.000000
38.110001,6.602165,-1305.071045,0.004743,0.002120,0.053855,29.367897,1.496072,0.538545,-1305.071045,0.054652,0.000000
38.360001,6.610725,-1305.071045,0.004756,0.002135,0.054219,29.405975,1.498012,0.542186,-1305.071045,0.055069,0.000000
38.610001,6.648712,-1305.071045,0.004756,0.002147,0.054540,29.574949,1.506620,0.545396,-1305.071045,0.055485,0.000000
38.860001,6.868034,-1305.026611,0.004777,0.002168,0.055060,30.550543,1.556319,0.550600,-1305.026611,0.055901,0.000000
39.110001,6.956657,-1305.026611,0.004790,0.002189,0.055589,30.944757,1.576401,0.555891,-1305.026611,0.056317,0.000000
39.360001,6.779411,-1305.071045,0.004760,0.002203,0.055962,30.156328,1.536237,0.559619,-1305.071045,0.056734,0.000000
39.610001,6.777924,-1305.115601,0.004816,0.002216,0.056283,30.149710,1.535899,0.562829,-1305.115601,0.057150,0.000000
39.860001,6.860214,-1305.115601,0.004773,0.002234,0.056742,30.515757,1.554547,0.567424,-1305.115601,0.057566,0.000000
40.110001,6.992035,-1305.115601,0.004816,0.002250,0.057159,31.102125,1.584418,0.571587,-1305.115601,0.057983,0.000000
40.360001,6.981979,-1305.026611,0.004842,0.002264,0.057514,31.057396,1.582139,0.575141,-1305.026611,0.058399,0.000000
40.610001,7.186790,-1305.071045,0.004876,0.002284,0.058017,31.968441,1.628550,0.580171,-1305.071045,0.058815,0.000000
40.860001,7.305199,-1305.071045,0.004842,0.002303,0.058494,32.495148,1.655382,0.584940,-1305.071045,0.059231,0.000000
41.110001,7.228867,-1305.071045,0.004907,0.002317,0.058841,32.155605,1.638085,0.588411,-1305.071045,0.059648,0.000000
41.360001,7.273918,-1305.026611,0.004907,0.002335,0.059301,32.356003,1.648293,0.593006,-1305.026611,0.060064,0.000000
41.610001,7.248230,-1305.115601,0.004937,0.002348,0.059639,32.241737,1.642472,0.596390,-1305.115601,0.060480,0.000000
41.860001,7.413193,-1305.071045,0.004911,0.002366,0.060098,32.975529,1.679854,0.600985,-1305.071045,0.060905,0.000000
42.110001,7.296265,-1305.071045,0.004954,0.002381,0.060480,32.455406,1.653357,0.604804,-1305.071045,0.061321,0.000000
42.360001,7.365150,-1305.071045,0.004958,0.002392,0.060766,32.761826,1.668967,0.607665,-1305.071045,0.061738,0.000000
42.610001,7.590439,-1305.071045,0.004954,0.002411,0.061243,33.763958,1.720018,0.612434,-1305.071045,0.062154,0.000000
42.860001,7.758377,-1305.071045,0.004975,0.002433,0.061807,34.510986,1.758073,0.618070,-1305.071045,0.062570,0.000000
43.110001,7.665283,-1305.026611,0.004945,0.002448,0.062188,34.096882,1.736978,0.621885,-1305.026611,0.062986,0.000000
43.360001,7.770294,-1305.071045,0.004958,0.002465,0.062622,34.563995,1.760774,0.626222,-1305.071045,0.063403,0.000000
43.610001,7.707367,-1305.071045,0.004971,0.002478,0.062952,34.284081,1.746514,0.629519,-1305.071045,0.063819,0.000000
43.860001,7.855942,-1305.071045,0.005014,0.002496,0.063403,34.944973,1.780182,0.634027,-1305.071045,0.064235,0.000000
44.110001,7.938606,-1305.071045,0.005053,0.002512,0.063802,35.312683,1.798914,0.638016,-1305.071045,0.064652,0.000000
44.360001,7.810883,-1305.026611,0.005027,0.002523,0.064096,34.744541,1.769971,0.640964,-1305.026611,0.065068,0.000000
44.610001,8.283798,-1305.115601,0.004993,0.002547,0.064704,36.848175,1.877136,0.647035,-1305.115601,0.065484,0.000000
44.860001,8.222725,-1305.026611,0.005019,0.002565,0.065146,36.576508,1.863296,0.651460,-1305.026611,0.065900,0.000000
45.110001,8.050316,-1304.937622,0.005088,0.002577,0.065450,35.809593,1.824228,0.654495,-1304.937622,0.066317,0.000000
45.360001,8.165756,-1305.071045,0.005105,0.002594,0.065892,36.323097,1.850387,0.658916,-1305.071045,0.066733,0.000000
45.610001,8.102081,-1305.026611,0.005118,0.002606,0.066186,36.039856,1.835958,0.661865,-1305.026611,0.067149,0.000000
45.860001,8.347847,-1305.115601,0.005092,0.002624,0.066646,37.133080,1.891649,0.666463,-1305.115601,0.067565,0.000000
46.110001,8.405937,-1305.026611,0.005135,0.002640,0.067062,37.391476,1.904813,0.670623,-1305.026611,0.067982,0.000000
46.360001,8.378754,-1304.982178,0.005096,0.002654,0.067418,37.270557,1.898653,0.674181,-1304.982178,0.068398,0.000000
46.610001,8.765648,-1305.071045,0.005105,0.002675,0.067947,38.991550,1.986324,0.679468,-1305.071045,0.068814,0.000000
46.860001,8.908638,-1305.071045,0.005157,0.002697,0.068502,39.627602,2.018726,0.685021,-1305.071045,0.069239,0.000000
47.110001,8.623398,-1305.026611,0.005157,0.002709,0.068797,38.358788,1.954090,0.687969,-1305.026611,0.069655,0.000000
47.360001,8.723564,-1305.071045,0.005195,0.002724,0.069187,38.804352,1.976788,0.691871,-1305.071045,0.070072,0.000000
47.610001,8.682236,-1305.026611,0.005178,0.002737,0.069508,38.620514,1.967423,0.695081,-1305.026611,0.070488,0.000000
47.860001,9.093330,-1305.071045,0.005217,0.002757,0.070029,40.449154,2.060578,0.700285,-1305.071045,0.070904,0.000000
48.110001,9.010666,-1305.026611,0.005200,0.002769,0.070332,40.081444,2.041846,0.703317,-1305.026611,0.071321,0.000000
48.360001,9.114189,-1305.071045,0.005217,0.002786,0.070765,40.541939,2.065305,0.707654,-1305.071045,0.071737,0.000000
48.610001,9.320480,-1305.026611,0.005234,0.002803,0.071208,41.459568,2.112051,0.712079,-1305.026611,0.072153,0.000000
48.860001,9.348778,-1305.026611,0.005269,0.002818,0.071589,41.585442,2.118463,0.715894,-1305.026611,0.072569,0.000000
49.110001,9.544647,-1305.026611,0.005238,0.002838,0.072084,42.456711,2.162848,0.720837,-1305.026611,0.072986,0.000000
49.360001,9.531242,-1305.026611,0.005256,0.002855,0.072509,42.397083,2.159811,0.725087,-1305.026611,0.073402,0.000000
49.610001,9.828026,-1305.026611,0.005238,0.002875,0.073029,43.717243,2.227063,0.730288,-1305.026611,0.073818,0.000000
49.860001,9.806801,-1305.071045,0.005329,0.002889,0.073393,43.622829,2.222253,0.733933,-1305.071045,0.074234,0.000000
50.110001,9.857071,-1305.026611,0.005333,0.002903,0.073740,43.846443,2.233644,0.737400,-1305.026611,0.074651,0.000000
50.360001,10.054802,-1305.071045,0.005307,0.002920,0.074165,44.725994,2.278451,0.741650,-1305.071045,0.075067,0.000000
50.610001,10.276360,-1305.071045,0.005295,0.002936,0.074581,45.711529,2.328656,0.745814,-1305.071045,0.075483,0.000000
50.860001,10.327003,-1305.071045,0.005346,0.002953,0.075006,45.936806,2.340132,0.750060,-1305.071045,0.075899,0.000000
51.110001,10.345619,-1305.026611,0.005346,0.002969,0.075414,46.019611,2.344351,0.754137,-1305.026611,0.076316,0.000000
51.360001,10.491966,-1305.115601,0.005364,0.002983,0.075769,46.670597,2.377513,0.757694,-1305.115601,0.076732,0.000000
51.610001,10.930992,-1305.071045,0.005372,0.003005,0.076316,48.623482,2.476998,0.763156,-1305.071045,0.077148,0.000000
51.860001,10.956688,-1305.160034,0.005372,0.003020,0.076706,48.737782,2.482821,0.767058,-1305.160034,0.077573,0.000000
52.110001,10.927269,-1305.026611,0.005359,0.003033,0.077027,48.606918,2.476155,0.770268,-1305.026611,0.077989,0.000000
52.360001,11.138779,-1305.071045,0.005454,0.003047,0.077383,49.547764,2.524083,0.773826,-1305.071045,0.078406,0.000000
52.610001,11.528275,-1305.115601,0.005428,0.003067,0.077903,51.280327,2.612344,0.779026,-1305.115601,0.078822,0.000000
52.860001,11.776276,-1305.071045,0.005445,0.003084,0.078345,52.383492,2.668542,0.783451,-1305.071045,0.079238,0.000000
53.110004,11.343208,-1305.071045,0.005415,0.003093,0.078553,50.457111,2.570408,0.785532,-1305.071045,0.079655,0.000000
53.360004,12.099121,-1305.115601,0.005454,0.003116,0.079152,53.819580,2.741700,0.791516,-1305.115601,0.080071,0.000000
53.610004,12.290894,-1305.071045,0.005441,0.003132,0.079559,54.672626,2.785156,0.795592,-1305.071045,0.080487,0.000000
53.860004,12.327019,-1305.071045,0.005480,0.003145,0.079889,54.833317,2.793342,0.798885,-1305.071045,0.080903,0.000000
54.110004,12.647255,-1305.115601,0.005493,0.003162,0.080322,56.257801,2.865909,0.803223,-1305.115601,0.081320,0.000000
54.360004,12.731789,-1305.026611,0.005480,0.003176,0.080669,56.633823,2.885065,0.806694,-1305.026611,0.081736,0.000000
54.610004,13.618774,-1305.115601,0.005549,0.003203,0.081346,60.579334,3.086058,0.813457,-1305.115601,0.082152,0.000000
54.860004,13.324226,-1305.115601,0.005506,0.003214,0.081641,59.269119,3.019313,0.816406,-1305.115601,0.082568,0.000000
55.110004,13.719688,-1305.160034,0.005566,0.003233,0.082117,61.028221,3.108926,0.821175,-1305.160034,0.082985,0.000000
55.360004,13.861938,-1305.115601,0.005558,0.003247,0.082482,61.660980,3.141160,0.824816,-1305.115601,0.083401,0.000000
55.610004,14.134514,-1305.071045,0.005579,0.003262,0.082855,62.873459,3.202927,0.828548,-1305.071045,0.083817,0.000000
55.860004,14.508377,-1305.071045,0.005618,0.003276,0.083219,64.536484,3.287645,0.832189,-1305.071045,0.084234,0.000000
56.110004,14.863617,-1305.071045,0.005592,0.003293,0.083653,66.116669,3.368144,0.836526,-1305.071045,0.084650,0.000000
56.360004,15.180504,-1305.115601,0.005570,0.003310,0.084077,67.526253,3.439951,0.840773,-1305.115601,0.085066,0.000000
56.610004,16.058563,-1305.115601,0.005661,0.003334,0.084676,71.432060,3.638922,0.846757,-1305.115601,0.085482,0.000000
56.860004,15.990044,-1305.115601,0.005635,0.003346,0.084988,71.127266,3.623396,0.849879,-1305.115601,0.085899,0.000000
57.110004,16.307304,-1305.204590,0.005639,0.003364,0.085447,72.538513,3.695288,0.854474,-1305.204590,0.086324,0.000000
57.360004,16.829002,-1305.115601,0.005627,0.003383,0.085916,74.859138,3.813507,0.859160,-1305.115601,0.086740,0.000000
57.610004,17.290741,-1305.115601,0.005644,0.003399,0.086324,76.913055,3.918138,0.863236,-1305.115601,0.087156,0.000000
57.860004,17.359261,-1305.071045,0.005657,0.003410,0.086610,77.217850,3.933665,0.866098,-1305.071045,0.087572,0.000000
58.110004,17.609489,-1305.115601,0.005678,0.003423,0.086948,78.330917,3.990367,0.869477,-1305.115601,0.087989,0.000000
58.360004,18.699425,-1305.115601,0.005713,0.003447,0.087555,83.179199,4.237350,0.875548,-1305.115601,0.088405,0.000000
58.610004,19.328362,-1305.115601,0.005713,0.003466,0.088040,85.976845,4.379869,0.880404,-1305.115601,0.088821,0.000000
58.860004,19.634079,-1305.115601,0.005700,0.003483,0.088465,87.336746,4.449146,0.884655,-1305.115601,0.089237,0.000000
59.110004,19.919319,-1305.115601,0.005721,0.003496,0.088786,88.605560,4.513782,0.887864,-1305.115601,0.089654,0.000000
59.360004,20.668159,-1305.071045,0.005786,0.003514,0.089246,91.936562,4.683472,0.892459,-1305.071045,0.090070,0.000000
59.610004,20.810776,-1305.115601,0.005764,0.003526,0.089549,92.570953,4.715789,0.895495,-1305.115601,0.090486,0.000000
59.860004,21.300446,-1305.160034,0.005773,0.003540,0.089905,94.749115,4.826750,0.899053,-1305.160034,0.090903,0.000000
60.110004,22.229889,-1305.115601,0.005756,0.003561,0.090443,98.883484,5.037364,0.904427,-1305.115601,0.091319,0.000000
60.360004,23.506752,-1305.204590,0.005799,0.003584,0.091024,104.563255,5.326706,0.910237,-1305.204590,0.091735,0.000000
60.610004,23.813965,-1305.115601,0.005838,0.003597,0.091371,105.929810,5.396321,0.913708,-1305.115601,0.092151,0.000000
60.860004,24.081696,-1305.160034,0.005851,0.003611,0.091726,107.120735,5.456990,0.917262,-1305.160034,0.092568,0.000000
61.110004,24.723297,-1305.160034,0.005851,0.003626,0.092108,109.974716,5.602379,0.921081,-1305.160034,0.092984,0.000000
61.360004,25.930153,-1305.204590,0.005898,0.003647,0.092646,115.343079,5.875857,0.926455,-1305.204590,0.093400,0.000000
61.610004,26.304390,-1305.160034,0.005868,0.003660,0.092975,117.007767,5.960660,0.929752,-1305.160034,0.093816,0.000000
61.860004,26.613457,-1305.160034,0.005902,0.003671,0.093235,118.382568,6.030695,0.932352,-1305.160034,0.094233,0.000000
62.110004,28.136086,-1305.160034,0.005902,0.003695,0.093860,125.155556,6.375728,0.938597,-1305.160034,0.094658,0.000000
62.360004,28.973557,-1305.160034,0.005924,0.003711,0.094250,128.880814,6.565502,0.942499,-1305.160034,0.095074,0.000000
62.610004,29.609566,-1305.115601,0.005924,0.003727,0.094675,131.709930,6.709624,0.946750,-1305.115601,0.095490,0.000000
62.860004,30.470490,-1305.160034,0.005946,0.003743,0.095074,135.539505,6.904712,0.950739,-1305.160034,0.095906,0.000000
63.110004,31.138901,-1305.204590,0.005933,0.003759,0.095490,138.512741,7.056176,0.954903,-1305.204590,0.096323,0.000000
63.360004,32.122337,-1305.160034,0.005967,0.003775,0.095898,142.887299,7.279026,0.958975,-1305.160034,0.096739,0.000000
63.610004,33.017151,-1305.204590,0.005976,0.003790,0.096271,146.867615,7.481793,0.962707,-1305.204590,0.097155,0.000000
63.860004,33.583153,-1305.249023,0.005989,0.003803,0.096600,149.385330,7.610051,0.966000,-1305.249023,0.097572,0.000000
64.110001,35.249146,-1305.204590,0.006015,0.003825,0.097164,156.796036,7.987570,0.971639,-1305.204590,0.097988,0.000000
64.360001,36.217690,-1305.204590,0.005993,0.003840,0.097545,161.104324,8.207046,0.975455,-1305.204590,0.098404,0.000000
64.610001,37.356033,-1305.204590,0.005993,0.003860,0.098048,166.167938,8.464997,0.980485,-1305.204590,0.098820,0.000000
64.860001,38.418411,-1305.204590,0.006032,0.003876,0.098447,170.893631,8.705736,0.984474,-1305.204590,0.099237,0.000000
65.110001,38.911430,-1305.249023,0.006036,0.003889,0.098768,173.086685,8.817456,0.987683,-1305.249023,0.099653,0.000000
65.360001,40.224045,-1305.204590,0.006062,0.003904,0.099159,178.925491,9.114899,0.991586,-1305.204590,0.100069,0.000000
65.610001,41.240623,-1305.249023,0.006023,0.003919,0.099540,183.447449,9.345259,0.995401,-1305.249023,0.100485,0.000000
65.860001,42.473549,-1305.293457,0.006053,0.003939,0.100052,188.931778,9.624644,1.000518,-1305.293457,0.100902,0.000000
66.110001,44.133957,-1305.204590,0.006084,0.003959,0.100555,196.317642,10.000897,1.005548,-1305.204590,0.101318,0.000000
66.360001,45.138985,-1305.249023,0.006045,0.003973,0.100902,200.788239,10.228641,1.009015,-1305.249023,0.101734,0.000000
66.610001,46.157051,-1305.249023,0.006135,0.003989,0.101309,205.316818,10.459337,1.013091,-1305.249023,0.102151,0.000000
66.860001,47.052986,-1305.293457,0.006127,0.004001,0.101630,209.302139,10.662359,1.016301,-1305.293457,0.102566,0.000000
67.110001,48.512314,-1305.338013,0.006131,0.004019,0.102081,215.793549,10.993048,1.020809,-1305.338013,0.102992,0.000000
67.360001,49.606712,-1305.249023,0.006118,0.004034,0.102454,220.661682,11.241042,1.024541,-1305.249023,0.103408,0.000000
67.610001,50.276985,-1305.293457,0.006144,0.004041,0.102636,223.643204,11.392927,1.026361,-1305.293457,0.103824,0.000000
67.860001,52.079269,-1305.249023,0.006122,0.004066,0.103286,231.660156,11.801332,1.032864,-1305.249023,0.104241,0.000000
68.110001,54.181305,-1305.249023,0.006157,0.004088,0.103842,241.010483,12.277658,1.038416,-1305.249023,0.104657,0.000000
68.360001,55.417587,-1305.249023,0.006178,0.004102,0.104180,246.509735,12.557805,1.041796,-1305.249023,0.105073,0.000000
68.610001,56.354843,-1305.293457,0.006148,0.004117,0.104570,250.678864,12.770190,1.045698,-1305.293457,0.105489,0.000000
68.860001,57.502495,-1305.293457,0.006183,0.004129,0.104873,255.783875,13.030252,1.048734,-1305.293457,0.105906,0.000000
69.110001,58.881020,-1305.204590,0.006209,0.004147,0.105325,261.915863,13.342630,1.053245,-1305.204590,0.106322,0.000000
69.360001,60.490417,-1305.249023,0.006204,0.004164,0.105775,269.074829,13.707324,1.057753,-1305.249023,0.106738,0.000000
69.610001,61.130150,-1305.293457,0.006222,0.004172,0.105957,271.920502,13.852290,1.059574,-1305.293457,0.107154,0.000000
69.860001,63.028877,-1305.204590,0.006200,0.004195,0.106547,280.366455,14.282548,1.065471,-1305.204590,0.107570,0.000000
70.110001,64.450592,-1305.293457,0.006234,0.004211,0.106963,286.690552,14.604712,1.069634,-1305.293457,0.107987,0.000000
70.360001,65.274658,-1305.293457,0.006200,0.004221,0.107215,290.356171,14.791450,1.072151,-1305.293457,0.108403,0.000000
70.610001,67.574432,-1305.249023,0.006260,0.004244,0.107805,300.586090,15.312586,1.078048,-1305.249023,0.107848,0.000000
70.860001,67.371109,-1305.293457,0.006265,0.004237,0.107631,299.681671,15.266512,1.076311,-1305.293457,0.107848,0.000000
71.110001,67.118271,-1305.249023,0.006282,0.004236,0.107605,298.556976,15.209218,1.076053,-1305.249023,0.107631,0.000000
71.360001,66.907883,-1305.204590,0.006295,0.004236,0.107588,297.621124,15.161543,1.075879,-1305.204590,0.107631,0.000000
71.610001,66.741806,-1305.249023,0.006295,0.004235,0.107579,296.882385,15.123910,1.075792,-1305.249023,0.107631,0.000000
71.860001,66.579071,-1305.293457,0.006243,0.004235,0.107579,296.158508,15.087033,1.075792,-1305.293457,0.107631,0.000000
72.110001,66.453583,-1305.204590,0.006247,0.004235,0.107570,295.600311,15.058598,1.075705,-1305.204590,0.107631,0.000000
72.360001,66.333679,-1305.338013,0.006260,0.004235,0.107570,295.066956,15.031426,1.075705,-1305.338013,0.107631,0.000000
72.610001,66.229797,-1305.249023,0.006273,0.004235,0.107570,294.604858,15.007887,1.075705,-1305.249023,0.107631,0.000000
72.860001,66.123672,-1305.249023,0.006286,0.004235,0.107570,294.132782,14.983838,1.075705,-1305.249023,0.107631,0.000000
73.110001,66.045471,-1305.293457,0.006247,0.004235,0.107562,293.784943,14.966118,1.075618,-1305.293457,0.107631,0.000000
73.360001,65.955719,-1305.338013,0.006269,0.004235,0.107562,293.385681,14.945780,1.075618,-1305.338013,0.107631,0.000000
73.610001,65.886841,-1305.293457,0.006282,0.004235,0.107562,293.079315,14.930172,1.075618,-1305.293457,0.107631,0.000000
73.860001,65.807526,-1305.293457,0.006286,0.004235,0.107562,292.726501,14.912198,1.075618,-1305.293457,0.107631,0.000000
74.110001,65.758743,-1305.293457,0.006260,0.004235,0.107562,292.509491,14.901145,1.075618,-1305.293457,0.107631,0.000000
74.360001,65.692825,-1305.293457,0.006252,0.004235,0.107562,292.216278,14.886208,1.075618,-1305.293457,0.107631,0.000000
74.610001,65.628784,-1305.293457,0.006291,0.004235,0.107562,291.931427,14.871696,1.075618,-1305.293457,0.107631,0.000000
74.860001,65.582611,-1305.249023,0.006247,0.004235,0.107562,291.726013,14.861233,1.075618,-1305.249023,0.107631,0.000000
75.110001,65.526001,-1305.338013,0.006286,0.004235,0.107562,291.474213,14.848404,1.075618,-1305.338013,0.107631,0.000000
75.360001,65.483185,-1305.293457,0.006265,0.004235,0.107562,291.283752,14.838701,1.075618,-1305.293457,0.107631,0.000000
75.610001,65.430679,-1305.338013,0.006273,0.004234,0.107553,291.050201,14.826804,1.075531,-1305.338013,0.107631,0.000000
75.860001,65.395309,-1305.293457,0.006256,0.004234,0.107553,290.892853,14.818789,1.075531,-1305.293457,0.107631,0.000000
76.110001,65.338333,-1305.293457,0.006316,0.004234,0.107553,290.639435,14.805878,1.075531,-1305.293457,0.107631,0.000000
76.360001,65.312271,-1305.382446,0.006282,0.004234,0.107553,290.523499,14.799972,1.075531,-1305.382446,0.107631,0.000000
76.610001,65.280991,-1305.338013,0.006278,0.004234,0.107553,290.384338,14.792884,1.075531,-1305.338013,0.107631,0.000000
76.860001,65.231827,-1305.338013,0.006291,0.004234,0.107553,290.165649,14.781743,1.075531,-1305.338013,0.107631,0.000000
77.110001,65.194229,-1305.293457,0.006303,0.004234,0.107553,289.998413,14.773223,1.075531,-1305.293457,0.107631,0.000000
77.360001,65.162949,-1305.338013,0.006256,0.004234,0.107553,289.859283,14.766135,1.075531,-1305.338013,0.107631,0.000000
77.610001,65.132782,-1305.338013,0.006278,0.004234,0.107553,289.725098,14.759299,1.075531,-1305.338013,0.107631,0.000000
77.860001,65.095917,-1305.249023,0.006260,0.004234,0.107553,289.561096,14.750946,1.075531,-1305.249023,0.107631,0.000000
78.110001,65.072830,-1305.338013,0.006303,0.004234,0.107553,289.458405,14.745714,1.075531,-1305.338013,0.107631,0.000000
78.360001,65.044525,-1305.293457,0.006316,0.004234,0.107553,289.332489,14.739301,1.075531,-1305.293457,0.107631,0.000000
78.610001,65.005432,-1305.293457,0.006299,0.004234,0.107553,289.158600,14.730441,1.075531,-1305.293457,0.107631,0.000000
78.860001,64.978622,-1305.382446,0.006239,0.004234,0.107553,289.039337,14.724366,1.075531,-1305.382446,0.107631,0.000000
79.110001,64.960739,-1305.338013,0.006299,0.004234,0.107553,288.959808,14.720314,1.075531,-1305.338013,0.107631,0.000000
79.360001,64.931702,-1305.382446,0.006286,0.004234,0.107553,288.830627,14.713734,1.075531,-1305.382446,0.107631,0.000000
79.610001,64.903778,-1305.382446,0.006273,0.004234,0.107553,288.706421,14.707407,1.075531,-1305.382446,0.107631,0.000000
79.860001,64.885529,-1305.249023,0.006291,0.004234,0.107553,288.625244,14.703271,1.075531,-1305.249023,0.107631,0.000000
80.110001,64.857605,-1305.382446,0.006286,0.004234,0.107553,288.501038,14.696943,1.075531,-1305.382446,0.107631,0.000000
80.360001,64.828552,-1305.382446,0.006312,0.004234,0.107553,288.371796,14.690360,1.075531,-1305.382446,0.107631,0.000000
80.610001,64.805466,-1305.427002,0.006308,0.004234,0.107553,288.269104,14.685128,1.075531,-1305.427002,0.107631,0.000000
80.860001,64.789459,-1305.382446,0.006265,0.004234,0.107553,288.197906,14.681501,1.075531,-1305.382446,0.107631,0.000000
81.110001,64.770462,-1305.382446,0.006295,0.004234,0.107553,288.113403,14.677197,1.075531,-1305.382446,0.107631,0.000000
81.360001,64.745880,-1305.382446,0.006282,0.004234,0.107553,288.004059,14.671626,1.075531,-1305.382446,0.107631,0.000000
81.610001,64.730621,-1305.382446,0.006278,0.004234,0.107553,287.936188,14.668168,1.075531,-1305.382446,0.107631,0.000000
81.860001,64.698227,-1305.427002,0.006273,0.004234,0.107553,287.792084,14.660829,1.075531,-1305.427002,0.107631,0.000000
82.110001,64.689285,-1305.382446,0.006265,0.004234,0.107553,287.752319,14.658802,1.075531,-1305.382446,0.107631,0.000000
82.360001,64.669922,-1305.427002,0.006308,0.004234,0.107553,287.666168,14.654413,1.075531,-1305.427002,0.107631,0.000000
82.610001,64.640137,-1305.382446,0.006308,0.004234,0.107553,287.533691,14.647664,1.075531,-1305.382446,0.107631,0.000000
82.860001,64.629333,-1305.382446,0.006286,0.004234,0.107553,287.485626,14.645216,1.075531,-1305.382446,0.107631,0.000000
83.110001,64.598434,-1305.338013,0.006303,0.004234,0.107553,287.348175,14.638215,1.075531,-1305.338013,0.107631,0.000000
83.360001,64.593582,-1305.338013,0.006282,0.004234,0.107553,287.326599,14.637115,1.075531,-1305.338013,0.107631,0.000000
83.610001,64.567154,-1305.382446,0.006260,0.004234,0.107553,287.209045,14.631126,1.075531,-1305.382446,0.107631,0.000000
83.860001,64.559708,-1305.382446,0.006286,0.004234,0.107553,287.175934,14.629438,1.075531,-1305.382446,0.107631,0.000000
84.110001,64.536987,-1305.382446,0.006291,0.004234,0.107553,287.074860,14.624290,1.075531,-1305.382446,0.107631,0.000000
84.360001,64.531403,-1305.427002,0.006273,0.004234,0.107553,287.050018,14.623025,1.075531,-1305.427002,0.107631,0.000000
84.610001,64.506821,-1305.382446,0.006291,0.004234,0.107553,286.940674,14.617455,1.075531,-1305.382446,0.107631,0.000000
84.860001,64.495651,-1305.382446,0.006303,0.004234,0.107553,286.890991,14.614923,1.075531,-1305.382446,0.107631,0.000000
85.110001,64.476669,-1305.382446,0.006252,0.004234,0.107553,286.806549,14.610621,1.075531,-1305.382446,0.107631,0.000000
85.360001,64.490067,-1305.382446,0.006291,0.004234,0.107553,286.866150,14.613658,1.075531,-1305.382446,0.107631,0.000000
85.610001,64.443146,-1305.382446,0.006252,0.004234,0.107544,286.657440,14.603026,1.075444,-1305.382446,0.107631,0.000000
85.860001,64.447983,-1305.427002,0.006252,0.004234,0.107544,286.678955,14.604122,1.075444,-1305.427002,0.107631,0.000000
86.110001,64.428253,-1305.382446,0.006312,0.004234,0.107544,286.591187,14.599650,1.075444,-1305.382446,0.107631,0.000000
86.360001,64.417450,-1305.427002,0.006316,0.004234,0.107544,286.543121,14.597203,1.075444,-1305.427002,0.107631,0.000000
86.610001,64.391388,-1305.427002,0.006265,0.004234,0.107544,286.427185,14.591296,1.075444,-1305.427002,0.107631,0.000000
86.860001,64.375748,-1305.427002,0.006286,0.004234,0.107544,286.357635,14.587753,1.075444,-1305.427002,0.107631,0.000000
87.110001,64.368301,-1305.427002,0.006334,0.004234,0.107544,286.324493,14.586065,1.075444,-1305.427002,0.107631,0.000000
87.360001,64.355637,-1305.382446,0.006269,0.004234,0.107544,286.268158,14.583196,1.075444,-1305.382446,0.107631,0.000000
87.610001,64.344101,-1305.427002,0.006273,0.004234,0.107544,286.216858,14.580582,1.075444,-1305.427002,0.107631,0.000000
87.860001,64.334793,-1305.427002,0.006316,0.004234,0.107544,286.175446,14.578472,1.075444,-1305.427002,0.107631,0.000000
88.110001,64.332184,-1305.427002,0.006256,0.004234,0.107544,286.163849,14.577882,1.075444,-1305.427002,0.107631,0.000000
88.360001,64.307236,-1305.382446,0.006291,0.004234,0.107544,286.052856,14.572228,1.075444,-1305.382446,0.107631,0.000000
88.610001,64.302399,-1305.382446,0.006316,0.004234,0.107544,286.031342,14.571132,1.075444,-1305.382446,0.107631,0.000000
88.860001,64.301270,-1305.471436,0.006260,0.004234,0.107544,286.026337,14.570876,1.075444,-1305.471436,0.107631,0.000000
89.110001,64.271484,-1305.471436,0.006312,0.004234,0.107544,285.893829,14.564127,1.075444,-1305.471436,0.107631,0.000000
89.360001,64.277451,-1305.427002,0.006273,0.004234,0.107544,285.920380,14.565478,1.075444,-1305.427002,0.107631,0.000000
89.610001,64.254349,-1305.427002,0.006316,0.004234,0.107544,285.817627,14.560243,1.075444,-1305.427002,0.107631,0.000000
89.860001,64.243561,-1305.427002,0.006312,0.004234,0.107544,285.769623,14.557799,1.075444,-1305.427002,0.107631,0.000000
90.110001,64.233505,-1305.427002,0.006291,0.004234,0.107544,285.724915,14.555520,1.075444,-1305.427002,0.107631,0.000000
90.360001,64.228668,-1305.515869,0.006286,0.004234,0.107544,285.703400,14.554424,1.075444,-1305.515869,0.107631,0.000000
90.610001,64.205582,-1305.382446,0.006273,0.004234,0.107544,285.600677,14.549192,1.075444,-1305.382446,0.107631,0.000000
90.860001,64.198868,-1305.471436,0.006256,0.004234,0.107544,285.570831,14.547671,1.075444,-1305.471436,0.107631,0.000000
91.110001,64.181366,-1305.471436,0.006308,0.004234,0.107544,285.492981,14.543705,1.075444,-1305.471436,0.107631,0.000000
91.360001,64.182861,-1305.471436,0.006273,0.004234,0.107544,285.499634,14.544044,1.075444,-1305.471436,0.107631,0.000000
91.610001,64.161636,-1305.471436,0.006256,0.004234,0.107544,285.405212,14.539235,1.075444,-1305.471436,0.107631,0.000000
91.860001,64.158661,-1305.427002,0.006303,0.004234,0.107544,285.391968,14.538560,1.075444,-1305.427002,0.107631,0.000000
92.110001,64.156799,-1305.427002,0.006265,0.004234,0.107544,285.383698,14.538138,1.075444,-1305.427002,0.107631,0.000000
92.360001,64.135941,-1305.427002,0.006256,0.004234,0.107544,285.290924,14.533412,1.075444,-1305.427002,0.107631,0.000000
92.610001,64.133713,-1305.471436,0.006312,0.004234,0.107544,285.281006,14.532907,1.075444,-1305.471436,0.107631,0.000000
92.860001,64.115463,-1305.427002,0.006282,0.004234,0.107544,285.199829,14.528771,1.075444,-1305.427002,0.107631,0.000000
93.110001,64.104660,-1305.427002,0.006278,0.004234,0.107544,285.151764,14.526323,1.075444,-1305.427002,0.107631,0.000000
93.360008,64.099075,-1305.427002,0.006260,0.004234,0.107544,285.126923,14.525058,1.075444,-1305.427002,0.107631,0.000000
93.610008,64.083817,-1305.427002,0.006329,0.004234,0.107544,285.059052,14.521601,1.075444,-1305.427002,0.107631,0.000000
93.860008,64.083435,-1305.471436,0.006265,0.004234,0.107544,285.057343,14.521514,1.075444,-1305.471436,0.107631,0.000000
94.110008,64.067795,-1305.427002,0.006308,0.004234,0.107544,284.987793,14.517969,1.075444,-1305.427002,0.107631,0.000000
94.360008,64.059982,-1305.382446,0.006316,0.004234,0.107544,284.953033,14.516200,1.075444,-1305.382446,0.107631,0.000000
94.610008,64.049927,-1305.471436,0.006260,0.004234,0.107544,284.908295,14.513922,1.075444,-1305.471436,0.107631,0.000000
94.860008,64.045822,-1305.427002,0.006256,0.004234,0.107544,284.890045,14.512991,1.075444,-1305.427002,0.107631,0.000000
95.110008,64.038376,-1305.471436,0.006316,0.004234,0.107544,284.856934,14.511303,1.075444,-1305.471436,0.107631,0.000000
95.360008,64.023117,-1305.382446,0.006299,0.004234,0.107544,284.789062,14.507846,1.075444,-1305.382446,0.107631,0.000000
95.610008,64.015289,-1305.382446,0.006269,0.004234,0.107544,284.754242,14.506072,1.075444,-1305.382446,0.107631,0.000000
95.860008,64.015289,-1305.427002,0.006334,0.004234,0.107544,284.754242,14.506072,1.075444,-1305.427002,0.107631,0.000000
96.110008,64.003006,-1305.382446,0.006325,0.004234,0.107544,284.699585,14.503288,1.075444,-1305.382446,0.107631,0.000000
96.360008,63.989594,-1305.427002,0.006252,0.004234,0.107544,284.639923,14.500249,1.075444,-1305.427002,0.107631,0.000000
96.610008,63.982895,-1305.382446,0.006299,0.004234,0.107544,284.610138,14.498732,1.075444,-1305.382446,0.107631,0.000000
96.860008,63.968750,-1305.427002,0.006286,0.004234,0.107544,284.547211,14.495525,1.075444,-1305.427002,0.107631,0.000000
97.110008,63.954590,-1305.471436,0.006312,0.004234,0.107544,284.484222,14.492317,1.075444,-1305.471436,0.107631,0.000000
97.360008,63.944916,-1305.471436,0.006329,0.004234,0.107544,284.441193,14.490125,1.075444,-1305.471436,0.107631,0.000000
97.610008,63.948273,-1305.427002,0.006291,0.004234,0.107544,284.456116,14.490886,1.075444,-1305.427002,0.107631,0.000000
97.860008,63.934494,-1305.382446,0.006303,0.004234,0.107544,284.394836,14.487763,1.075444,-1305.382446,0.107631,0.000000
98.110008,63.927780,-1305.471436,0.006291,0.004234,0.107544,284.364960,14.486242,1.075444,-1305.471436,0.107631,0.000000
98.360008,63.928909,-1305.427002,0.006286,0.004234,0.107544,284.369995,14.486498,1.075444,-1305.427002,0.107631,0.000000
98.610008,63.911774,-1305.427002,0.006278,0.004234,0.107544,284.293762,14.482615,1.075444,-1305.427002,0.107631,0.000000
98.860008,63.909164,-1305.427002,0.006282,0.004234,0.107544,284.282166,14.482023,1.075444,-1305.427002,0.107631,0.000000
99.110008,63.884598,-1305.382446,0.006286,0.004234,0.107544,284.172882,14.476457,1.075444,-1305.382446,0.107631,0.000000
99.360008,63.890182,-1305.471436,0.006291,0.004234,0.107544,284.197723,14.477722,1.075444,-1305.471436,0.107631,0.000000
99.610008,63.880127,-1305.427002,0.006329,0.004234,0.107544,284.152985,14.475443,1.075444,-1305.427002,0.107631,0.000000
99.860008,63.868576,-1305.427002,0.006269,0.004234,0.107544,284.101624,14.472826,1.075444,-1305.427002,0.107631,0.000000
100.110008,63.864853,-1305.382446,0.006316,0.004234,0.107544,284.085052,14.471983,1.075444,-1305.382446,0.107631,0.000000
100.360008,63.860382,-1305.382446,0.006316,0.004234,0.107544,284.065155,14.470969,1.075444,-1305.382446,0.107631,0.000000
100.610008,63.857407,-1305.427002,0.006316,0.004234,0.107544,284.051941,14.470295,1.075444,-1305.427002,0.107631,0.000000
100.860008,63.852188,-1305.382446,0.006278,0.004234,0.107544,284.028717,14.469112,1.075444,-1305.382446,0.107631,0.000000
101.100006,63.839157,-1305.338013,0.006282,0.004234,0.107544,283.970764,14.466160,1.075444,-1305.338013,0.107631,0.000000