File: Data/Automembrane/AutoHeating-10wt-1-1_12152023_180149.csv
Time (sec),S:Load (lbs),S:HL1 (DIM),S:LVDT (in),S:Position (in),Ch:Position (mm),Ch:Load (N),Ch:Stress (MPa),Ch:Strain (mm/mm),Ch:HL1 (DIM),Set Point (),Cycles ()
0.110000,0.017502,-250.205353,0.000017,-0.000000,-0.000000,0.077852,0.003966,-0.000000,-250.205353,0.000208,0.000000
0.370000,0.005219,-250.383270,0.000013,0.000005,0.000139,0.023213,0.001183,0.001385,-250.383270,0.000676,0.000000
0.630000,0.036865,-250.338791,0.000017,0.000156,0.003954,0.163985,0.008354,0.039545,-250.338791,0.005012,0.000000
0.890000,0.049896,-250.338791,0.000168,0.000323,0.008195,0.221950,0.011307,0.081951,-250.338791,0.009331,0.000000
1.150000,0.021973,-250.427750,0.000332,0.000499,0.012670,0.097739,0.004979,0.126699,-250.427750,0.013667,0.000000
1.410000,0.017502,-250.383270,0.000513,0.000667,0.016937,0.077852,0.003966,0.169370,-250.383270,0.018004,0.000000
1.670000,0.023460,-250.383270,0.000668,0.000830,0.021074,0.104357,0.005316,0.210735,-250.383270,0.022340,0.000000
1.930000,-0.017128,-250.383270,0.000849,0.001010,0.025653,-0.076189,-0.003881,0.256525,-250.383270,0.026659,0.000000
2.190000,0.034264,-250.383270,0.001035,0.001180,0.029963,0.152412,0.007764,0.299627,-250.383270,0.030995,0.000000
2.450000,0.050270,-250.383270,0.001207,0.001340,0.034039,0.223612,0.011391,0.340387,-250.383270,0.035331,0.000000
2.710000,0.024208,-250.383270,0.001384,0.001520,0.038600,0.107683,0.005486,0.386003,-250.383270,0.039649,0.000000
2.970000,0.046921,-250.472229,0.001556,0.001690,0.042928,0.208714,0.010632,0.429275,-250.472229,0.043986,0.000000
3.230000,0.039848,-250.383270,0.001703,0.001859,0.047220,0.177254,0.009030,0.472203,-250.383270,0.048322,0.000000
3.490000,0.020851,-250.383270,0.001884,0.002030,0.051565,0.092750,0.004725,0.515650,-250.383270,0.052658,0.000000
3.750000,0.045433,-250.427750,0.002052,0.002201,0.055910,0.202096,0.010295,0.559101,-250.427750,0.056977,0.000000
4.010000,0.033516,-250.427750,0.002233,0.002368,0.060142,0.149086,0.007595,0.601420,-250.427750,0.061313,0.000000
4.270000,0.039474,-250.472229,0.002449,0.002543,0.064599,0.175591,0.008945,0.645995,-250.472229,0.065649,0.000000
4.530000,0.048782,-250.472229,0.002591,0.002711,0.068858,0.216995,0.011054,0.688578,-250.472229,0.069985,0.000000
4.790000,0.077454,-250.472229,0.002755,0.002886,0.073315,0.344531,0.017551,0.733153,-250.472229,0.074304,0.000000
5.050000,0.053627,-250.427750,0.002919,0.003056,0.077616,0.238545,0.012152,0.776165,-250.427750,0.078640,0.000000
5.310000,0.051018,-250.427750,0.003130,0.003223,0.081857,0.226938,0.011561,0.818574,-250.427750,0.082976,0.000000
5.570000,0.052132,-250.516724,0.003285,0.003399,0.086324,0.231893,0.011813,0.863236,-250.516724,0.087312,0.000000
5.830000,0.021599,-250.472229,0.003492,0.003565,0.090556,0.096076,0.004894,0.905555,-250.472229,0.091631,0.000000
6.090000,0.061073,-250.516724,0.003648,0.003728,0.094692,0.271668,0.013839,0.946924,-250.516724,0.095967,0.000000
6.350000,0.081924,-250.472229,0.003811,0.003907,0.099228,0.364418,0.018564,0.992278,-250.472229,0.100303,0.000000
6.610000,0.052879,-250.427750,0.004010,0.004076,0.103529,0.235219,0.011983,1.035294,-250.427750,0.104622,0.000000
6.870000,0.099426,-250.516724,0.004182,0.004243,0.107779,0.442270,0.022530,1.077787,-250.516724,0.108958,0.000000
7.130000,0.107986,-250.561203,0.004350,0.004419,0.112245,0.480348,0.024470,1.122448,-250.561203,0.113294,0.000000
7.390000,0.080437,-250.472229,0.004531,0.004583,0.116416,0.357800,0.018227,1.164162,-250.472229,0.117630,0.000000
7.650001,0.128845,-250.605682,0.004734,0.004754,0.120753,0.573132,0.029197,1.207525,-250.605682,0.121949,0.000000
7.910000,0.118790,-250.561203,0.004907,0.004932,0.125271,0.528403,0.026918,1.252706,-250.561203,0.126285,0.000000
8.170000,0.105011,-250.605682,0.005109,0.005101,0.129572,0.467112,0.023796,1.295721,-250.605682,0.130622,0.000000
8.430000,0.222679,-250.561203,0.005277,0.005267,0.133778,0.990526,0.050460,1.337783,-250.561203,0.134958,0.000000
8.690001,0.246513,-250.605682,0.005445,0.005444,0.138271,1.096546,0.055861,1.382705,-250.605682,0.139277,0.000000
8.950001,0.317261,-250.605682,0.005635,0.005611,0.142529,1.411246,0.071892,1.425285,-250.605682,0.143613,0.000000
9.210000,0.465096,-250.561203,0.005829,0.005775,0.146691,2.068848,0.105392,1.466912,-250.561203,0.147949,0.000000
9.470000,0.651657,-250.650162,0.006019,0.005930,0.150620,2.898715,0.147668,1.506195,-250.650162,0.151799,0.000000
9.730000,0.548882,-250.605682,0.006028,-0.000000,-0.000009,2.441547,0.124378,-0.000087,-250.605682,0.000139,0.000000
9.990001,0.511269,-250.605682,0.006036,-0.000001,-0.000017,2.274236,0.115855,-0.000174,-250.605682,0.000156,0.000000
10.250001,0.502701,-250.650162,0.006045,-0.000000,-0.000009,2.236125,0.113914,-0.000087,-250.650162,0.000590,0.000000
10.510000,0.487434,-250.605682,0.006045,-0.000000,-0.000009,2.168216,0.110454,-0.000087,-250.605682,0.001023,0.000000
10.770000,0.548508,-250.605682,0.006053,0.000019,0.000486,2.439884,0.124294,0.004856,-250.605682,0.001457,0.000000
11.030001,0.565262,-250.650162,0.006036,0.000037,0.000945,2.514410,0.128090,0.009451,-250.650162,0.001891,0.000000
11.290001,0.608833,-250.605682,0.006049,0.000055,0.001388,2.708226,0.137964,0.013875,-250.605682,0.002324,0.000000
11.550000,0.672508,-250.605682,0.006096,0.000073,0.001856,2.991466,0.152393,0.018557,-250.605682,0.002758,0.000000
11.810000,0.697456,-250.605682,0.006101,0.000087,0.002220,3.102441,0.158046,0.022198,-250.605682,0.003191,0.000000
12.070001,0.734322,-250.739120,0.006114,0.000106,0.002697,3.266426,0.166400,0.026971,-250.739120,0.003625,0.000000
12.330001,0.767090,-250.694641,0.006140,0.000131,0.003330,3.412186,0.173825,0.033300,-250.694641,0.004059,0.000000
12.590000,0.764107,-250.739120,0.006178,0.000144,0.003651,3.398916,0.173149,0.036509,-250.739120,0.004492,0.000000
12.850000,0.789429,-250.694641,0.006183,0.000159,0.004050,3.511554,0.178887,0.040498,-250.694641,0.004926,0.000000
13.110001,0.780495,-250.694641,0.006204,0.000172,0.004380,3.471814,0.176863,0.043795,-250.694641,0.005359,0.000000
13.370001,0.858322,-250.694641,0.006196,0.000192,0.004865,3.818007,0.194499,0.048651,-250.694641,0.005784,0.000000
13.630001,0.861298,-250.694641,0.006234,0.000208,0.005290,3.831243,0.195173,0.052898,-250.694641,0.006218,0.000000
13.890000,0.882149,-250.739120,0.006252,0.000221,0.005619,3.923994,0.199898,0.056194,-250.739120,0.006652,0.000000
14.150001,0.919762,-250.739120,0.006265,0.000241,0.006122,4.091304,0.208421,0.061224,-250.739120,0.007085,0.000000
14.410001,0.958488,-250.739120,0.006295,0.000263,0.006686,4.263570,0.217197,0.066860,-250.739120,0.007519,0.000000
14.670001,0.951042,-250.828079,0.006299,0.000278,0.007059,4.230447,0.215509,0.070592,-250.828079,0.007952,0.000000
14.930000,0.947693,-250.694641,0.006351,0.000292,0.007423,4.215549,0.214750,0.074233,-250.694641,0.008386,0.000000
15.190001,1.017326,-250.694641,0.006342,0.000313,0.007952,4.525294,0.230529,0.079524,-250.694641,0.008820,0.000000
15.450001,1.054192,-250.739120,0.006364,0.000329,0.008351,4.689279,0.238883,0.083514,-250.739120,0.009253,0.000000
15.710001,1.033333,-250.783600,0.006390,0.000339,0.008620,4.596494,0.234157,0.086201,-250.783600,0.009687,0.000000
15.970001,1.119728,-250.783600,0.006416,0.000361,0.009158,4.980799,0.253734,0.091579,-250.783600,0.010120,0.000000
16.230001,1.145416,-250.739120,0.006441,0.000383,0.009730,5.095066,0.259555,0.097302,-250.739120,0.010554,0.000000
16.490002,1.151749,-250.739120,0.006472,0.000397,0.010077,5.123234,0.260990,0.100769,-250.739120,0.010988,0.000000
16.750000,1.158081,-250.828079,0.006454,0.000416,0.010554,5.151402,0.262425,0.105542,-250.828079,0.011421,0.000000
17.010000,1.146164,-250.783600,0.006489,0.000431,0.010953,5.098392,0.259724,0.109531,-250.783600,0.011855,0.000000
17.270000,1.232552,-250.828079,0.006515,0.000449,0.011413,5.482663,0.279300,0.114126,-250.828079,0.012288,0.000000
17.530001,1.229950,-250.828079,0.006532,0.000461,0.011707,5.471091,0.278711,0.117074,-250.828079,0.012722,0.000000
17.790001,1.285431,-250.783600,0.006549,0.000478,0.012150,5.717882,0.291283,0.121495,-250.783600,0.013156,0.000000
18.050001,1.324532,-250.828079,0.006571,0.000498,0.012661,5.891810,0.300143,0.126612,-250.828079,0.013589,0.000000
18.310001,1.329002,-250.783600,0.006575,0.000513,0.013026,5.911698,0.301156,0.130257,-250.783600,0.014023,0.000000
18.570002,1.335327,-250.917038,0.006618,0.000532,0.013511,5.939832,0.302589,0.135113,-250.917038,0.014456,0.000000
18.830002,1.380013,-250.828079,0.006618,0.000551,0.014006,6.138602,0.312715,0.140056,-250.828079,0.014890,0.000000
19.090000,1.441826,-250.828079,0.006670,0.000569,0.014448,6.413562,0.326722,0.144477,-250.828079,0.015324,0.000000
19.350000,1.466034,-250.872559,0.006666,0.000584,0.014838,6.521245,0.332208,0.148379,-250.872559,0.015757,0.000000
19.610001,1.444061,-250.783600,0.006700,0.000591,0.015020,6.423505,0.327229,0.150204,-250.783600,0.016191,0.000000
19.870001,1.512207,-250.872559,0.006691,0.000610,0.015506,6.726633,0.342671,0.155060,-250.872559,0.016625,0.000000
20.130001,1.626152,-250.872559,0.006756,0.000641,0.016269,7.233486,0.368491,0.162690,-250.872559,0.017058,0.000000
20.390001,1.552795,-250.872559,0.006778,0.000650,0.016503,6.907179,0.351868,0.165033,-250.872559,0.017492,0.000000
20.650002,1.607536,-250.917038,0.006778,0.000672,0.017058,7.150679,0.364273,0.170581,-250.917038,0.017925,0.000000
20.910002,1.645889,-250.828079,0.006782,0.000690,0.017526,7.321281,0.372964,0.175263,-250.828079,0.018359,0.000000
21.170000,1.698769,-250.917038,0.006838,0.000703,0.017856,7.556500,0.384946,0.178560,-250.917038,0.018793,0.000000
21.430000,1.711426,-250.872559,0.006873,0.000720,0.018281,7.612802,0.387815,0.182810,-250.872559,0.019226,0.000000
21.690001,1.734512,-250.872559,0.006860,0.000734,0.018645,7.715496,0.393046,0.186451,-250.872559,0.019660,0.000000
21.950001,1.823135,-250.961533,0.006898,0.000755,0.019166,8.109712,0.413128,0.191656,-250.961533,0.020094,0.000000
22.210001,1.836540,-250.917038,0.006929,0.000775,0.019695,8.169339,0.416166,0.196947,-250.917038,0.020527,0.000000
22.470001,1.824257,-250.961533,0.006924,0.000789,0.020050,8.114700,0.413383,0.200501,-250.961533,0.020952,0.000000
22.730001,1.877502,-250.961533,0.006946,0.000810,0.020571,8.351548,0.425448,0.205705,-250.961533,0.021386,0.000000
22.990002,1.923302,-250.917038,0.007006,0.000827,0.021013,8.555273,0.435826,0.210126,-250.917038,0.021819,0.000000
23.250002,1.925537,-251.006012,0.007002,0.000843,0.021403,8.565217,0.436333,0.214028,-251.006012,0.022253,0.000000
23.510000,1.947884,-250.917038,0.007006,0.000854,0.021681,8.664619,0.441397,0.216806,-250.917038,0.022687,0.000000
23.770000,2.030548,-250.961533,0.007028,0.000880,0.022340,9.032329,0.460129,0.223396,-250.961533,0.023120,0.000000
24.030001,2.026825,-250.917038,0.007075,0.000895,0.022730,9.015768,0.459285,0.227298,-250.917038,0.023554,0.000000
24.290001,2.027939,-250.961533,0.007084,0.000912,0.023155,9.020722,0.459538,0.231549,-250.961533,0.023987,0.000000
24.550001,2.033531,-251.050491,0.007114,0.000928,0.023571,9.045598,0.460805,0.235712,-251.050491,0.024421,0.000000
24.810001,2.092735,-250.961533,0.007123,0.000944,0.023987,9.308951,0.474221,0.239872,-250.961533,0.024855,0.000000
25.070002,2.131836,-251.050491,0.007161,0.000962,0.024430,9.482880,0.483081,0.244296,-251.050491,0.025288,0.000000
25.330002,2.130348,-251.006012,0.007183,0.000976,0.024785,9.476262,0.482744,0.247850,-251.006012,0.025722,0.000000
25.590002,2.175400,-251.006012,0.007209,0.000993,0.025210,9.676661,0.492953,0.252100,-251.006012,0.026156,0.000000
25.850000,2.246155,-251.050491,0.007209,0.001015,0.025782,9.991396,0.508986,0.257823,-251.050491,0.026589,0.000000
26.110001,2.250252,-251.050491,0.007239,0.001033,0.026251,10.009620,0.509914,0.262509,-251.050491,0.027023,0.000000
26.370001,2.194389,-251.094971,0.007269,0.001047,0.026606,9.761131,0.497256,0.266063,-251.094971,0.027456,0.000000
26.630001,2.228653,-251.050491,0.007269,0.001063,0.027005,9.913544,0.505020,0.270052,-251.050491,0.027890,0.000000
26.890001,2.284882,-251.094971,0.007334,0.001084,0.027543,10.163661,0.517762,0.275431,-251.094971,0.028324,0.000000
27.150002,2.301262,-251.139450,0.007330,0.001099,0.027925,10.236525,0.521473,0.279246,-251.139450,0.028757,0.000000
27.410002,2.288979,-251.006012,0.007334,0.001110,0.028202,10.181885,0.518690,0.282020,-251.006012,0.029191,0.000000
27.670002,2.391380,-251.094971,0.007373,0.001135,0.028835,10.637391,0.541894,0.288352,-251.094971,0.029624,0.000000
27.930002,2.404411,-251.094971,0.007420,0.001152,0.029269,10.695355,0.544847,0.292686,-251.094971,0.030058,0.000000
28.190001,2.365685,-251.094971,0.007420,0.001168,0.029668,10.523090,0.536072,0.296675,-251.094971,0.030491,0.000000
28.450001,2.382065,-251.139450,0.007455,0.001184,0.030066,10.595954,0.539784,0.300664,-251.139450,0.030925,0.000000
28.710001,2.383560,-251.094971,0.007463,0.001199,0.030457,10.602605,0.540122,0.304567,-251.094971,0.031359,0.000000
28.970001,2.432335,-251.139450,0.007489,0.001218,0.030934,10.819566,0.551175,0.309339,-251.139450,0.031792,0.000000
29.230001,2.434204,-251.139450,0.007511,0.001230,0.031237,10.827881,0.551599,0.312375,-251.139450,0.032226,0.000000
29.490002,2.472557,-251.094971,0.007528,0.001247,0.031680,10.998483,0.560289,0.316796,-251.094971,0.032659,0.000000
29.750002,2.550751,-251.094971,0.007541,0.001269,0.032243,11.346306,0.578008,0.322431,-251.094971,0.033093,0.000000
30.010002,2.527290,-251.139450,0.007593,0.001286,0.032668,11.241949,0.572692,0.326682,-251.139450,0.033527,0.000000
30.270002,2.533997,-251.183929,0.007606,0.001304,0.033111,11.271780,0.574212,0.331106,-251.183929,0.033960,0.000000
30.530001,2.521339,-251.183929,0.007627,0.001318,0.033475,11.215478,0.571344,0.334747,-251.183929,0.034394,0.000000
30.790001,2.578308,-251.139450,0.007666,0.001338,0.033995,11.468887,0.584253,0.339952,-251.139450,0.034827,0.000000
31.050001,2.582779,-251.183929,0.007679,0.001354,0.034403,11.488774,0.585266,0.344028,-251.183929,0.035261,0.000000
31.310001,2.525429,-251.228409,0.007675,0.001363,0.034628,11.233668,0.572270,0.346280,-251.228409,0.035695,0.000000
31.570002,2.641983,-251.183929,0.007713,0.001390,0.035296,11.752128,0.598682,0.352960,-251.183929,0.036120,0.000000
31.830002,2.640495,-251.272888,0.007761,0.001406,0.035721,11.745510,0.598345,0.357211,-251.272888,0.036553,0.000000
32.090000,2.611076,-251.183929,0.007782,0.001420,0.036059,11.614648,0.591678,0.360591,-251.183929,0.036987,0.000000
32.350002,2.614059,-251.228409,0.007800,0.001437,0.036493,11.627917,0.592354,0.364928,-251.228409,0.037421,0.000000
32.610001,2.660233,-251.183929,0.007817,0.001456,0.036978,11.833305,0.602817,0.369784,-251.183929,0.037854,0.000000
32.870003,2.684433,-251.228409,0.007860,0.001472,0.037377,11.940954,0.608301,0.373774,-251.228409,0.038288,0.000000
33.130001,2.677734,-251.228409,0.007864,0.001486,0.037733,11.911158,0.606783,0.377328,-251.228409,0.038721,0.000000
33.390003,2.744385,-251.228409,0.007894,0.001505,0.038227,12.207633,0.621886,0.382271,-251.228409,0.039155,0.000000
33.650002,2.793541,-251.272888,0.007899,0.001530,0.038860,12.426291,0.633025,0.388603,-251.272888,0.039589,0.000000
33.910000,2.717575,-251.228409,0.007955,0.001544,0.039207,12.088378,0.615811,0.392070,-251.228409,0.040022,0.000000
34.170002,2.726143,-251.272888,0.007955,0.001559,0.039598,12.126490,0.617753,0.395976,-251.272888,0.040456,0.000000
34.430000,2.673637,-251.272888,0.007994,0.001571,0.039909,11.892933,0.605855,0.399094,-251.272888,0.040890,0.000000
34.690002,2.767471,-251.228409,0.008002,0.001591,0.040404,12.310328,0.627118,0.404038,-251.228409,0.041323,0.000000
34.950001,2.743645,-251.317368,0.008024,0.001604,0.040742,12.204341,0.621719,0.407421,-251.317368,0.041757,0.000000
35.210003,2.773804,-251.272888,0.008032,0.001622,0.041193,12.338495,0.628553,0.411929,-251.272888,0.042190,0.000000
35.470001,2.822586,-251.317368,0.008080,0.001643,0.041739,12.555490,0.639607,0.417394,-251.317368,0.042624,0.000000
35.730003,2.869873,-251.317368,0.008088,0.001664,0.042269,12.765833,0.650322,0.422686,-251.317368,0.043058,0.000000
35.990002,2.819237,-251.317368,0.008136,0.001679,0.042659,12.540591,0.638848,0.426588,-251.317368,0.043491,0.000000
36.250000,2.795403,-251.317368,0.008162,0.001693,0.043014,12.434571,0.633447,0.430142,-251.317368,0.043925,0.000000
36.510002,2.898552,-251.361847,0.008153,0.001713,0.043500,12.893403,0.656821,0.434998,-251.361847,0.044359,0.000000
36.770000,2.907486,-251.317368,0.008179,0.001728,0.043881,12.933144,0.658846,0.438813,-251.317368,0.044792,0.000000
37.030003,2.842690,-251.361847,0.008213,0.001738,0.044150,12.644915,0.644163,0.441504,-251.361847,0.045226,0.000000
37.290001,2.954407,-251.361847,0.008231,0.001759,0.044671,13.141857,0.669478,0.446708,-251.361847,0.045659,0.000000
37.550003,3.046379,-251.361847,0.008248,0.001784,0.045304,13.550971,0.690319,0.453037,-251.361847,0.046093,0.000000
37.810001,2.964462,-251.317368,0.008278,0.001795,0.045599,13.186586,0.671757,0.455985,-251.317368,0.046527,0.000000
38.070004,2.970787,-251.406342,0.008308,0.001814,0.046084,13.214721,0.673190,0.460841,-251.406342,0.046960,0.000000
38.330002,2.896690,-251.450821,0.008313,0.001828,0.046431,12.885122,0.656399,0.464312,-251.450821,0.047394,0.000000
38.590000,3.025154,-251.361847,0.008351,0.001847,0.046917,13.456557,0.685510,0.469168,-251.361847,0.047827,0.000000
38.850002,2.973396,-251.450821,0.008369,0.001859,0.047229,13.226327,0.673781,0.472291,-251.450821,0.048261,0.000000
39.110001,3.044518,-251.361847,0.008382,0.001878,0.047689,13.542690,0.689898,0.476885,-251.361847,0.048695,0.000000
39.370003,3.091438,-251.361847,0.008438,0.001897,0.048174,13.751405,0.700530,0.481741,-251.361847,0.049128,0.000000
39.630001,3.088455,-251.361847,0.008438,0.001915,0.048634,13.738135,0.699854,0.486340,-251.361847,0.049562,0.000000
39.890003,3.055687,-251.406342,0.008472,0.001930,0.049024,13.592375,0.692429,0.490242,-251.406342,0.049995,0.000000
40.150002,3.125694,-251.450821,0.008507,0.001950,0.049527,13.903783,0.708292,0.495272,-251.450821,0.050429,0.000000
40.410004,3.162560,-251.450821,0.008502,0.001969,0.050004,14.067767,0.716646,0.500041,-251.450821,0.050854,0.000000
40.670002,3.141335,-251.495300,0.008558,0.001983,0.050360,13.973354,0.711837,0.503595,-251.495300,0.051288,0.000000
40.930000,3.049728,-251.495300,0.008537,0.001992,0.050594,13.565869,0.691078,0.505938,-251.495300,0.051721,0.000000
41.190002,3.124580,-251.406342,0.008589,0.002007,0.050984,13.898828,0.708040,0.509840,-251.406342,0.052155,0.000000
41.450001,3.353584,-251.539780,0.008593,0.002040,0.051817,14.917488,0.759933,0.518167,-251.539780,0.052588,0.000000
41.710003,3.205757,-251.406342,0.008640,0.002051,0.052085,14.259920,0.726435,0.520855,-251.406342,0.053022,0.000000
41.970001,3.246719,-251.495300,0.008666,0.002070,0.052580,14.442129,0.735717,0.525798,-251.495300,0.053456,0.000000
42.230003,3.261986,-251.539780,0.008679,0.002088,0.053039,14.510037,0.739177,0.530392,-251.539780,0.053889,0.000000
42.490002,3.298477,-251.539780,0.008692,0.002106,0.053482,14.672359,0.747446,0.534817,-251.539780,0.054323,0.000000
42.750004,3.294006,-251.584259,0.008714,0.002120,0.053837,14.652472,0.746433,0.538371,-251.584259,0.054756,0.000000
43.010002,3.304062,-251.539780,0.008748,0.002133,0.054184,14.697202,0.748711,0.541842,-251.539780,0.055190,0.000000
43.270000,3.434021,-251.539780,0.008739,0.002156,0.054756,15.275289,0.778160,0.547565,-251.539780,0.055624,0.000000
43.530003,3.405724,-251.584259,0.008787,0.002172,0.055164,15.149415,0.771748,0.551641,-251.584259,0.056057,0.000000
43.790001,3.380768,-251.495300,0.008817,0.002188,0.055580,15.038406,0.766093,0.555804,-251.495300,0.056491,0.000000
44.050003,3.469025,-251.539780,0.008834,0.002209,0.056101,15.430992,0.786092,0.561009,-251.539780,0.056924,0.000000
44.310001,3.499184,-251.539780,0.008860,0.002226,0.056534,15.565146,0.792926,0.565342,-251.539780,0.057358,0.000000
44.570004,3.467163,-251.539780,0.008873,0.002241,0.056924,15.422711,0.785670,0.569244,-251.539780,0.057792,0.000000
44.830002,3.453011,-251.495300,0.008903,0.002254,0.057254,15.359758,0.782463,0.572541,-251.495300,0.058225,0.000000
45.090004,3.610527,-251.584259,0.008912,0.002278,0.057861,16.060427,0.818157,0.578612,-251.584259,0.058659,0.000000
45.350002,3.574776,-251.673218,0.008946,0.002294,0.058260,15.901397,0.810056,0.582601,-251.673218,0.059093,0.000000
45.610001,3.561371,-251.584259,0.008990,0.002308,0.058633,15.841768,0.807018,0.586329,-251.584259,0.059526,0.000000
45.870003,3.558762,-251.628738,0.009002,0.002326,0.059075,15.830162,0.806427,0.590754,-251.628738,0.059960,0.000000
46.130001,3.645897,-251.584259,0.008990,0.002343,0.059517,16.217760,0.826172,0.595175,-251.584259,0.060393,0.000000
46.390003,3.668617,-251.628738,0.009020,0.002360,0.059951,16.318825,0.831321,0.599512,-251.628738,0.060827,0.000000
46.650002,3.610901,-251.628738,0.009063,0.002375,0.060315,16.062090,0.818242,0.603153,-251.628738,0.061261,0.000000
46.910004,3.671219,-251.584259,0.009076,0.002389,0.060688,16.330397,0.831910,0.606881,-251.584259,0.061694,0.000000
47.170002,3.744949,-251.628738,0.009067,0.002410,0.061226,16.658367,0.848618,0.612260,-251.628738,0.062128,0.000000
47.430004,3.835808,-251.628738,0.009149,0.002432,0.061773,17.062525,0.869206,0.617725,-251.628738,0.062562,0.000000
47.690002,3.744576,-251.628738,0.009149,0.002447,0.062145,16.656704,0.848533,0.621453,-251.628738,0.062995,0.000000
47.950001,3.787399,-251.673218,0.009166,0.002462,0.062527,16.847193,0.858237,0.625268,-251.673218,0.063429,0.000000
48.210003,3.870438,-251.628738,0.009184,0.002483,0.063065,17.216566,0.877054,0.630647,-251.628738,0.063863,0.000000
48.470001,3.884216,-251.673218,0.009205,0.002498,0.063437,17.277857,0.880176,0.634375,-251.673218,0.064296,0.000000
48.730003,3.809372,-251.717697,0.009231,0.002508,0.063715,16.944933,0.863216,0.637149,-251.717697,0.064730,0.000000
48.990002,4.027580,-251.628738,0.009278,0.002534,0.064357,17.915571,0.912663,0.643568,-251.628738,0.065163,0.000000
49.250004,4.020134,-251.762177,0.009291,0.002550,0.064773,17.882448,0.910975,0.647728,-251.762177,0.065597,0.000000
49.510002,3.973213,-251.717697,0.009300,0.002567,0.065207,17.673735,0.900343,0.652066,-251.717697,0.066022,0.000000
49.770000,4.006729,-251.673218,0.009330,0.002582,0.065588,17.822821,0.907938,0.655881,-251.673218,0.066455,0.000000
50.030003,4.005981,-251.762177,0.009339,0.002598,0.065987,17.819496,0.907768,0.659870,-251.762177,0.066889,0.000000
50.290001,4.122162,-251.673218,0.009369,0.002618,0.066499,18.336292,0.934095,0.664987,-251.673218,0.067323,0.000000
50.550003,4.061096,-251.762177,0.009390,0.002628,0.066759,18.064657,0.920258,0.667587,-251.762177,0.067756,0.000000
50.810001,4.156052,-251.717697,0.009412,0.002645,0.067175,18.487041,0.941775,0.671751,-251.717697,0.068190,0.000000
51.070004,4.348564,-251.717697,0.009455,0.002668,0.067765,19.343380,0.985399,0.677648,-251.717697,0.068624,0.000000
51.330002,4.311333,-251.762177,0.009438,0.002684,0.068181,19.177765,0.976962,0.681811,-251.762177,0.069057,0.000000
51.590004,4.311699,-251.762177,0.009490,0.002702,0.068632,19.179394,0.977045,0.686323,-251.762177,0.069491,0.000000
51.850002,4.277817,-251.806671,0.009494,0.002716,0.068996,19.028679,0.969367,0.689964,-251.806671,0.069924,0.000000
52.110001,4.435333,-251.762177,0.009537,0.002737,0.069517,19.729347,1.005061,0.695168,-251.762177,0.070358,0.000000
52.370003,4.428627,-251.762177,0.009567,0.002754,0.069941,19.699516,1.003541,0.699415,-251.762177,0.070792,0.000000
52.630001,4.332558,-251.806671,0.009567,0.002764,0.070211,19.272179,0.981772,0.702106,-251.806671,0.071225,0.000000
52.890003,4.597687,-251.762177,0.009597,0.002788,0.070826,20.451532,1.041851,0.708264,-251.762177,0.071659,0.000000
53.150002,4.574966,-251.762177,0.009602,0.002804,0.071234,20.350468,1.036702,0.712336,-251.762177,0.072092,0.000000
53.410004,4.518372,-251.806671,0.009636,0.002819,0.071598,20.098721,1.023878,0.715981,-251.806671,0.072526,0.000000
53.670002,4.590240,-251.851151,0.009675,0.002836,0.072023,20.418409,1.040163,0.720231,-251.851151,0.072960,0.000000
53.930004,4.733231,-251.762177,0.009636,0.002854,0.072500,21.054461,1.072565,0.725000,-251.762177,0.073393,0.000000
54.190002,4.791687,-251.851151,0.009697,0.002870,0.072908,21.314487,1.085812,0.729077,-251.851151,0.073827,0.000000
54.450001,4.784241,-251.895630,0.009714,0.002884,0.073263,21.281366,1.084124,0.732631,-251.895630,0.074260,0.000000
54.710003,4.978622,-251.895630,0.009718,0.002903,0.073749,22.146019,1.128172,0.737487,-251.895630,0.074694,0.000000
54.970001,5.133904,-251.851151,0.009774,0.002929,0.074391,22.836742,1.163359,0.743906,-251.851151,0.075128,0.000000
55.230003,4.992401,-251.851151,0.009766,0.002943,0.074755,22.207310,1.131294,0.747547,-251.851151,0.075561,0.000000
55.490002,5.005432,-251.851151,0.009787,0.002958,0.075128,22.265274,1.134247,0.751275,-251.851151,0.075995,0.000000
55.750004,4.962234,-251.895630,0.009848,0.002969,0.075422,22.073122,1.124458,0.754224,-251.895630,0.076428,0.000000
56.010002,5.167786,-251.851151,0.009852,0.002990,0.075934,22.987459,1.171037,0.759341,-251.851151,0.076862,0.000000
56.270004,5.162949,-251.851151,0.009852,0.003003,0.076281,22.965942,1.169941,0.762812,-251.851151,0.077296,0.000000
56.530003,5.248589,-251.940109,0.009873,0.003020,0.076697,23.346888,1.189347,0.766975,-251.940109,0.077729,0.000000
56.790001,5.544998,-251.895630,0.009916,0.003044,0.077322,24.665384,1.256515,0.773216,-251.895630,0.078163,0.000000
57.050003,5.614258,-251.940109,0.009947,0.003064,0.077816,24.973467,1.272209,0.778159,-251.940109,0.078596,0.000000
57.310001,5.570320,-251.851151,0.009951,0.003078,0.078189,24.778021,1.262253,0.781891,-251.851151,0.079030,0.000000
57.570004,5.614258,-251.940109,0.009960,0.003094,0.078588,24.973467,1.272209,0.785880,-251.940109,0.079464,0.000000
57.830002,5.805290,-251.940109,0.009994,0.003112,0.079048,25.823221,1.315498,0.790475,-251.940109,0.079897,0.000000
58.090004,5.841034,-251.895630,0.010042,0.003126,0.079403,25.982216,1.323597,0.794029,-251.895630,0.080331,0.000000
58.350002,5.801933,-251.940109,0.010007,0.003139,0.079724,25.808289,1.314737,0.797239,-251.940109,0.080765,0.000000
58.610004,6.089035,-251.940109,0.010037,0.003157,0.080192,27.085381,1.379795,0.801921,-251.940109,0.081189,0.000000
58.870003,6.364967,-251.940109,0.010080,0.003181,0.080790,28.312788,1.442322,0.807905,-251.940109,0.081623,0.000000
59.130001,6.227188,-251.984589,0.010102,0.003194,0.081138,27.699917,1.411101,0.811375,-251.984589,0.082057,0.000000
59.390003,6.488968,-251.984589,0.010132,0.003213,0.081614,28.864370,1.470421,0.816144,-251.984589,0.082490,0.000000
59.650002,6.480774,-251.940109,0.010141,0.003229,0.082005,28.827923,1.468564,0.820047,-251.940109,0.082924,0.000000
59.910004,6.690788,-251.984589,0.010167,0.003247,0.082473,29.762114,1.516154,0.824729,-251.984589,0.083358,0.000000
60.170002,6.636421,-252.029068,0.010175,0.003259,0.082768,29.520275,1.503834,0.827677,-252.029068,0.083791,0.000000
60.430004,6.876228,-251.984589,0.010179,0.003276,0.083210,30.586990,1.558176,0.832102,-251.984589,0.084225,0.000000
60.690002,7.116783,-251.984589,0.010214,0.003295,0.083696,31.657032,1.612686,0.836958,-251.984589,0.084658,0.000000
60.950005,7.328667,-252.073547,0.010231,0.003313,0.084156,32.599537,1.660700,0.841556,-252.073547,0.085092,0.000000
61.210003,7.342445,-251.984589,0.010257,0.003329,0.084555,32.660828,1.663822,0.845546,-251.984589,0.085526,0.000000
61.470001,7.604965,-252.029068,0.010287,0.003348,0.085040,33.828575,1.723310,0.850402,-252.029068,0.085959,0.000000
61.730003,7.715935,-252.029068,0.010305,0.003366,0.085500,34.322193,1.748456,0.854996,-252.029068,0.086393,0.000000
61.990002,7.918503,-252.029068,0.010317,0.003382,0.085899,35.223259,1.794358,0.858986,-252.029068,0.086827,0.000000
62.250004,7.784447,-252.073547,0.010317,0.003394,0.086202,34.626949,1.763981,0.862021,-252.073547,0.087260,0.000000
62.510002,8.078995,-252.073547,0.010348,0.003408,0.086558,35.937164,1.830726,0.865575,-252.073547,0.087694,0.000000
62.770004,8.978645,-252.118027,0.010386,0.003438,0.087330,39.939011,2.034590,0.873296,-252.118027,0.088127,0.000000
63.030003,8.608879,-252.073547,0.010386,0.003449,0.087607,38.294209,1.950800,0.876071,-252.073547,0.088561,0.000000
63.290005,9.033760,-252.073547,0.010399,0.003469,0.088101,40.184174,2.047079,0.881014,-252.073547,0.088995,0.000000
63.550003,9.218079,-252.162506,0.010451,0.003485,0.088509,41.004063,2.088846,0.885090,-252.162506,0.089428,0.000000
63.810001,9.384529,-252.073547,0.010468,0.003501,0.088917,41.744469,2.126565,0.889166,-252.073547,0.089862,0.000000
64.070000,9.608330,-252.073547,0.010468,0.003517,0.089341,42.739986,2.177279,0.893413,-252.073547,0.090295,0.000000
64.330002,9.695839,-252.118027,0.010486,0.003531,0.089697,43.129246,2.197109,0.896971,-252.118027,0.090729,0.000000
64.590004,10.328873,-252.118027,0.010511,0.003551,0.090191,45.945122,2.340556,0.901914,-252.118027,0.091163,0.000000
64.850006,10.710548,-252.162506,0.010520,0.003572,0.090738,47.642899,2.427045,0.907376,-252.162506,0.091596,0.000000
65.110001,10.815933,-252.118027,0.010520,0.003587,0.091111,48.111675,2.450926,0.911107,-252.118027,0.092030,0.000000
65.370003,11.387894,-252.206985,0.010559,0.003609,0.091666,50.655880,2.580534,0.916656,-252.206985,0.092463,0.000000
65.630005,11.743881,-252.118027,0.010568,0.003625,0.092065,52.239391,2.661202,0.920645,-252.118027,0.092897,0.000000
65.889999,11.886879,-252.162506,0.010606,0.003639,0.092437,52.875477,2.693605,0.924374,-252.162506,0.093331,0.000000
66.150002,12.101364,-252.251480,0.010615,0.003653,0.092784,53.829556,2.742208,0.927844,-252.251480,0.093764,0.000000
66.410004,12.968246,-252.118027,0.010637,0.003677,0.093400,57.685642,2.938647,0.934002,-252.118027,0.094198,0.000000
66.670006,13.209915,-252.206985,0.010645,0.003692,0.093782,58.760639,2.993409,0.937818,-252.206985,0.094631,0.000000
66.930000,13.537231,-252.162506,0.010662,0.003709,0.094198,60.216614,3.067580,0.941981,-252.162506,0.095065,0.000000
67.190002,13.823959,-252.206985,0.010671,0.003725,0.094614,61.492043,3.132554,0.946140,-252.206985,0.095499,0.000000
67.450005,14.402626,-252.206985,0.010697,0.003742,0.095039,64.066078,3.263682,0.950391,-252.206985,0.095924,0.000000
67.710007,14.950012,-252.162506,0.010714,0.003759,0.095473,66.500977,3.387721,0.954728,-252.162506,0.096357,0.000000
67.970001,15.155930,-252.251480,0.010723,0.003773,0.095837,67.416939,3.434383,0.958369,-252.251480,0.096791,0.000000
68.230003,15.529427,-252.206985,0.010757,0.003787,0.096201,69.078339,3.519018,0.962011,-252.206985,0.097224,0.000000
68.490005,16.485306,-252.295959,0.010762,0.003811,0.096799,73.330299,3.735624,0.967994,-252.295959,0.097658,0.000000
68.750000,17.431129,-252.295959,0.010779,0.003831,0.097311,77.537537,3.949950,0.973112,-252.295959,0.098092,0.000000
69.010002,17.575233,-252.251480,0.010800,0.003844,0.097632,78.178543,3.982605,0.976321,-252.251480,0.098525,0.000000
69.270004,18.143852,-252.295959,0.010818,0.003860,0.098048,80.707886,4.111456,0.980485,-252.295959,0.098959,0.000000
69.530006,19.063240,-252.206985,0.010822,0.003882,0.098595,84.797523,4.319792,0.985946,-252.206985,0.099392,0.000000
69.790001,19.515297,-252.251480,0.010843,0.003896,0.098959,86.808372,4.422229,0.989591,-252.251480,0.099826,0.000000
70.050003,19.739464,-252.251480,0.010839,0.003907,0.099228,87.805519,4.473026,0.992278,-252.251480,0.100260,0.000000
70.310005,21.072189,-252.295959,0.010874,0.003931,0.099844,93.733780,4.775027,0.998436,-252.295959,0.100693,0.000000
70.570000,21.953217,-252.340439,0.010887,0.003948,0.100277,97.652786,4.974670,1.002770,-252.340439,0.101127,0.000000
70.830002,22.500977,-252.295959,0.010908,0.003965,0.100702,100.089340,5.098794,1.007020,-252.295959,0.101561,0.000000
71.090004,23.262108,-252.295959,0.010921,0.003981,0.101110,103.475021,5.271269,1.011097,-252.295959,0.101994,0.000000
71.350006,23.746567,-252.295959,0.010900,0.003996,0.101491,105.630005,5.381049,1.014912,-252.295959,0.102428,0.000000
71.610001,24.880066,-252.340439,0.010934,0.004016,0.102003,110.672058,5.637903,1.020029,-252.340439,0.102861,0.000000
71.870003,25.524269,-252.340439,0.010968,0.004027,0.102280,113.537621,5.783882,1.022804,-252.340439,0.103295,0.000000
72.130005,26.365837,-252.295959,0.010960,0.004044,0.102714,117.281097,5.974584,1.027141,-252.295959,0.103729,0.000000
72.390007,27.869102,-252.340439,0.010986,0.004066,0.103286,123.967957,6.315229,1.032864,-252.340439,0.104162,0.000000
72.650002,28.758698,-252.340439,0.010977,0.004082,0.103694,127.925079,6.516814,1.036940,-252.340439,0.104596,0.000000
72.910004,29.732079,-252.340439,0.011007,0.004100,0.104145,132.254898,6.737385,1.041452,-252.340439,0.105030,0.000000
73.170006,30.532684,-252.473877,0.011016,0.004115,0.104518,135.816162,6.918805,1.045180,-252.473877,0.105463,0.000000
73.430000,31.908226,-252.340439,0.011037,0.004135,0.105038,141.934875,7.230507,1.050384,-252.340439,0.105897,0.000000
73.690002,32.724464,-252.340439,0.011037,0.004151,0.105437,145.565689,7.415470,1.054373,-252.340439,0.106331,0.000000
73.950005,33.159393,-252.429398,0.011055,0.004160,0.105663,147.500351,7.514026,1.056625,-252.429398,0.106764,0.000000
74.210007,35.152336,-252.429398,0.011081,0.004186,0.106331,156.365402,7.965633,1.063306,-252.429398,0.107198,0.000000
74.470001,36.094810,-252.429398,0.011106,0.004201,0.106703,160.557739,8.179201,1.067034,-252.429398,0.107631,0.000000
74.730003,37.057388,-252.340439,0.011089,0.004215,0.107050,164.839493,8.397325,1.070501,-252.340439,0.108065,0.000000
74.990005,38.166321,-252.518356,0.011124,0.004233,0.107510,169.772278,8.648612,1.075099,-252.518356,0.108499,0.000000
75.250000,39.064110,-252.384918,0.011128,0.004248,0.107909,173.765839,8.852054,1.079089,-252.384918,0.108932,0.000000
75.510002,40.930809,-252.429398,0.011150,0.004268,0.108412,182.069336,9.275054,1.084119,-252.429398,0.109366,0.000000
75.770004,41.982391,-252.429398,0.011158,0.004283,0.108785,186.747009,9.513346,1.087847,-252.429398,0.109799,0.000000
76.030006,43.319580,-252.429398,0.011158,0.004301,0.109253,192.695114,9.816358,1.092529,-252.429398,0.110233,0.000000
76.290001,45.429443,-252.473877,0.011188,0.004326,0.109886,202.080261,10.294459,1.098861,-252.473877,0.110667,0.000000
76.550003,46.510811,-252.473877,0.011197,0.004339,0.110207,206.890427,10.539500,1.102071,-252.473877,0.111092,0.000000
76.810005,47.595161,-252.429398,0.011214,0.004355,0.110615,211.713852,10.785217,1.106147,-252.429398,0.111525,0.000000
77.070007,48.670197,-252.518356,0.011223,0.004368,0.110944,216.495850,11.028824,1.109440,-252.518356,0.111959,0.000000
77.330002,50.181290,-252.518356,0.011219,0.004387,0.111430,223.217529,11.371243,1.114296,-252.518356,0.112392,0.000000
77.590004,51.339737,-252.473877,0.011214,0.004401,0.111785,228.370560,11.633750,1.117854,-252.473877,0.112826,0.000000
77.850006,52.352592,-252.473877,0.011227,0.004414,0.112106,232.875961,11.863267,1.121063,-252.473877,0.113260,0.000000
78.110001,54.310150,-252.518356,0.011249,0.004436,0.112679,241.583618,12.306856,1.126786,-252.518356,0.113693,0.000000
78.370003,56.222282,-252.518356,0.011262,0.004458,0.113242,250.089203,12.740151,1.132422,-252.518356,0.114127,0.000000
78.630005,57.216522,-252.473877,0.011288,0.004470,0.113528,254.511795,12.965449,1.135283,-252.473877,0.114560,0.000000
78.890007,58.505676,-252.518356,0.011305,0.004487,0.113962,260.246246,13.257576,1.139621,-252.518356,0.114994,0.000000
79.150002,60.113205,-252.473877,0.011309,0.004506,0.114465,267.396881,13.621846,1.144651,-252.473877,0.115428,0.000000
79.410004,61.492104,-252.562836,0.011322,0.004523,0.114890,273.530548,13.934310,1.148901,-252.562836,0.115861,0.000000
79.670006,62.539581,-252.562836,0.011309,0.004534,0.115176,278.189941,14.171672,1.151762,-252.562836,0.116295,0.000000
79.930000,63.450401,-252.562836,0.011318,0.004551,0.115584,282.241486,14.378067,1.155839,-252.562836,0.116728,0.000000
80.190002,65.844765,-252.607315,0.011335,0.004575,0.116199,292.892151,14.920637,1.161993,-252.607315,0.117162,0.000000
80.450005,67.287331,-252.562836,0.011352,0.004588,0.116538,299.308990,15.247527,1.165377,-252.562836,0.117596,0.000000
80.710007,67.342445,-252.518356,0.011357,0.004585,0.116451,299.554169,15.260016,1.164510,-252.518356,0.116642,0.000000
80.970001,67.066521,-252.607315,0.011404,0.004584,0.116442,298.326782,15.197492,1.164423,-252.607315,0.116442,0.000000
81.230003,66.846077,-252.562836,0.011369,0.004584,0.116434,297.346191,15.147537,1.164336,-252.562836,0.116442,0.000000
81.490005,66.639778,-252.607315,0.011369,0.004584,0.116425,296.428528,15.100790,1.164249,-252.607315,0.116442,0.000000
81.750008,66.465508,-252.607315,0.011365,0.004584,0.116425,295.653351,15.061299,1.164249,-252.607315,0.116442,0.000000
82.010002,66.302406,-252.651794,0.011391,0.004584,0.116425,294.927826,15.024340,1.164249,-252.651794,0.116442,0.000000
82.270004,66.179527,-252.651794,0.011374,0.004583,0.116416,294.381226,14.996495,1.164162,-252.651794,0.116442,0.000000
82.530006,66.052177,-252.651794,0.011374,0.004583,0.116416,293.814758,14.967638,1.164162,-252.651794,0.116442,0.000000
82.790001,65.931526,-252.651794,0.011387,0.004583,0.116416,293.278076,14.940297,1.164162,-252.651794,0.116442,0.000000
83.050003,65.828377,-252.562836,0.011387,0.004583,0.116416,292.819244,14.916924,1.164162,-252.562836,0.116442,0.000000
83.310005,65.745705,-252.696289,0.011391,0.004583,0.116416,292.451508,14.898190,1.164162,-252.696289,0.116442,0.000000
83.570007,65.641441,-252.607315,0.011382,0.004583,0.116416,291.987701,14.874563,1.164162,-252.607315,0.116442,0.000000
83.830002,65.571434,-252.696289,0.011395,0.004583,0.116416,291.676300,14.858700,1.164162,-252.696289,0.116442,0.000000
84.090004,65.493248,-252.696289,0.011382,0.004583,0.116416,291.328522,14.840981,1.164162,-252.696289,0.116442,0.000000
84.350006,65.420998,-252.696289,0.011378,0.004583,0.116407,291.007141,14.824610,1.164075,-252.696289,0.116442,0.000000
84.610001,65.345039,-252.696289,0.011391,0.004583,0.116407,290.669250,14.807397,1.164075,-252.696289,0.116442,0.000000
84.870003,65.292900,-252.651794,0.011387,0.004583,0.116407,290.437317,14.795583,1.164075,-252.651794,0.116442,0.000000
85.130005,65.240395,-252.740768,0.011391,0.004583,0.116407,290.203766,14.783685,1.164075,-252.740768,0.116442,0.000000
85.390007,65.173378,-252.740768,0.011404,0.004583,0.116407,289.905670,14.768499,1.164075,-252.740768,0.116442,0.000000
85.650002,65.113045,-252.696289,0.011400,0.004583,0.116407,289.637299,14.754827,1.164075,-252.696289,0.116442,0.000000
85.910004,65.080284,-252.740768,0.011417,0.004583,0.116407,289.491577,14.747403,1.164075,-252.740768,0.116442,0.000000
86.170006,65.015114,-252.740768,0.011400,0.004583,0.116407,289.201660,14.732635,1.164075,-252.740768,0.116442,0.000000
86.430000,64.969688,-252.740768,0.011408,0.004583,0.116407,288.999603,14.722342,1.164075,-252.740768,0.116442,0.000000
86.690002,64.919411,-252.785248,0.011400,0.004583,0.116407,288.775970,14.710948,1.164075,-252.785248,0.116442,0.000000
86.950005,64.877342,-252.740768,0.011395,0.004583,0.116407,288.588837,14.701416,1.164075,-252.740768,0.116442,0.000000
87.210007,64.849037,-252.740768,0.011417,0.004583,0.116407,288.462921,14.695002,1.164075,-252.740768,0.116442,0.000000
87.470001,64.802864,-252.785248,0.011391,0.004583,0.116407,288.257538,14.684539,1.164075,-252.785248,0.116442,0.000000
87.730003,64.760414,-252.785248,0.011408,0.004583,0.116407,288.068695,14.674920,1.164075,-252.785248,0.116442,0.000000
87.990005,64.719460,-252.829727,0.011387,0.004583,0.116407,287.886536,14.665640,1.164075,-252.829727,0.116442,0.000000
88.250008,64.684074,-252.785248,0.011408,0.004583,0.116407,287.729126,14.657620,1.164075,-252.785248,0.116442,0.000000
88.510002,64.655037,-252.829727,0.011417,0.004583,0.116407,287.599976,14.651041,1.164075,-252.829727,0.116442,0.000000
88.770004,64.604012,-252.829727,0.011395,0.004583,0.116407,287.372986,14.639479,1.164075,-252.829727,0.116442,0.000000
89.030006,64.595818,-252.829727,0.011400,0.004583,0.116407,287.336548,14.637621,1.164075,-252.829727,0.116442,0.000000
89.290001,64.563057,-252.874207,0.011382,0.004583,0.116407,287.190826,14.630198,1.164075,-252.874207,0.116442,0.000000
89.550003,64.517250,-252.785248,0.011430,0.004583,0.116407,286.987061,14.619818,1.164075,-252.785248,0.116442,0.000000
89.810005,64.494164,-252.874207,0.011391,0.004583,0.116407,286.884369,14.614587,1.164075,-252.874207,0.116442,0.000000
90.070007,64.466606,-252.740768,0.011408,0.004583,0.116407,286.761780,14.608341,1.164075,-252.740768,0.116442,0.000000
90.330002,64.437187,-252.874207,0.011382,0.004583,0.116407,286.630920,14.601675,1.164075,-252.874207,0.116442,0.000000
90.590004,64.407784,-252.874207,0.011382,0.004583,0.116407,286.500122,14.595013,1.164075,-252.874207,0.116442,0.000000
90.850006,64.392143,-252.829727,0.011395,0.004583,0.116407,286.430573,14.591468,1.164075,-252.829727,0.116442,0.000000
91.110001,64.358620,-252.874207,0.011404,0.004583,0.116407,286.281433,14.583872,1.164075,-252.874207,0.116442,0.000000
91.370003,64.321754,-252.874207,0.011408,0.004583,0.116407,286.117462,14.575518,1.164075,-252.874207,0.116442,0.000000
91.630005,64.300163,-252.918686,0.011413,0.004583,0.116407,286.021423,14.570625,1.164075,-252.918686,0.116442,0.000000
91.890007,64.281166,-252.829727,0.011417,0.004583,0.116399,285.936920,14.566320,1.163988,-252.829727,0.116442,0.000000
92.150002,64.248405,-252.874207,0.011395,0.004583,0.116399,285.791168,14.558897,1.163988,-252.874207,0.116442,0.000000
92.410004,64.233131,-252.874207,0.011404,0.004583,0.116399,285.723236,14.555436,1.163988,-252.874207,0.116442,0.000000
92.670006,64.195152,-252.829727,0.011426,0.004583,0.116399,285.554291,14.546829,1.163988,-252.829727,0.116442,0.000000
92.930008,64.176155,-252.963165,0.011395,0.004583,0.116399,285.469788,14.542524,1.163988,-252.963165,0.116442,0.000000
93.190002,64.163872,-252.963165,0.011395,0.004583,0.116399,285.415161,14.539742,1.163988,-252.963165,0.116442,0.000000
93.450005,64.126640,-252.963165,0.011404,0.004583,0.116399,285.249542,14.531304,1.163988,-252.963165,0.116442,0.000000
93.710007,64.117332,-253.007645,0.011400,0.004583,0.116399,285.208130,14.529196,1.163988,-253.007645,0.116442,0.000000
93.970001,64.085304,-252.918686,0.011408,0.004583,0.116399,285.065674,14.521937,1.163988,-252.918686,0.116442,0.000000
94.230003,64.059608,-252.963165,0.011400,0.004583,0.116399,284.951355,14.516114,1.163988,-252.963165,0.116442,0.000000
94.490005,64.027214,-252.963165,0.011400,0.004583,0.116399,284.807281,14.508774,1.163988,-252.963165,0.116442,0.000000
94.750008,64.013435,-253.007645,0.011408,0.004583,0.116399,284.745972,14.505651,1.163988,-253.007645,0.116442,0.000000
95.010002,64.007103,-253.007645,0.011417,0.004583,0.116399,284.717804,14.504216,1.163988,-253.007645,0.116442,0.000000
95.270004,63.979179,-252.963165,0.011395,0.004583,0.116399,284.593597,14.497890,1.163988,-252.963165,0.116442,0.000000
95.530006,63.966881,-253.096619,0.011413,0.004583,0.116399,284.538910,14.495103,1.163988,-253.096619,0.116442,0.000000
95.790001,63.945290,-253.007645,0.011404,0.004583,0.116399,284.442841,14.490210,1.163988,-253.007645,0.116442,0.000000
96.050003,63.926292,-253.007645,0.011404,0.004583,0.116399,284.358337,14.485905,1.163988,-253.007645,0.116442,0.000000
96.310005,63.895027,-253.007645,0.011395,0.004583,0.116399,284.219269,14.478821,1.163988,-253.007645,0.116442,0.000000
96.570007,63.896141,-253.052124,0.011408,0.004583,0.116399,284.224243,14.479073,1.163988,-253.052124,0.116442,0.000000
96.830002,63.872307,-253.096619,0.011387,0.004583,0.116399,284.118225,14.473671,1.163988,-253.096619,0.116442,0.000000
97.090004,63.848839,-253.007645,0.011421,0.004583,0.116399,284.013824,14.468354,1.163988,-253.007645,0.116442,0.000000
97.350006,63.827614,-253.096619,0.011382,0.004583,0.116399,283.919403,14.463545,1.163988,-253.096619,0.116442,0.000000
97.610008,63.805656,-253.141098,0.011400,0.004583,0.116399,283.821747,14.458569,1.163988,-253.141098,0.116442,0.000000
97.870003,63.799690,-253.007645,0.011391,0.004583,0.116399,283.795197,14.457216,1.163988,-253.007645,0.116442,0.000000
98.130005,63.782936,-253.141098,0.011404,0.004583,0.116399,283.720673,14.453420,1.163988,-253.141098,0.116442,0.000000
98.390007,63.760597,-253.141098,0.011408,0.004583,0.116399,283.621307,14.448358,1.163988,-253.141098,0.116442,0.000000
98.650002,63.750542,-253.096619,0.011374,0.004583,0.116399,283.576569,14.446079,1.163988,-253.096619,0.116442,0.000000
98.910004,63.744957,-253.052124,0.011400,0.004583,0.116399,283.551727,14.444814,1.163988,-253.052124,0.116442,0.000000
99.170006,63.729317,-253.052124,0.011434,0.004583,0.116399,283.482147,14.441270,1.163988,-253.052124,0.116442,0.000000
99.430008,63.705482,-253.141098,0.011430,0.004583,0.116399,283.376129,14.435868,1.163988,-253.141098,0.116442,0.000000
99.690002,63.686485,-253.096619,0.011400,0.004583,0.116399,283.291626,14.431563,1.163988,-253.096619,0.116442,0.000000
99.950005,63.676064,-253.141098,0.011395,0.004583,0.116399,283.245270,14.429202,1.163988,-253.141098,0.116442,0.000000
100.210007,63.671227,-253.141098,0.011413,0.004583,0.116399,283.223755,14.428105,1.163988,-253.141098,0.116442,0.000000
100.470001,63.652229,-253.141098,0.011404,0.004583,0.116399,283.139252,14.423801,1.163988,-253.141098,0.116442,0.000000
100.730003,63.633247,-253.185577,0.011382,0.004583,0.116399,283.054810,14.419500,1.163988,-253.185577,0.116442,0.000000
100.990005,63.625420,-253.185577,0.011430,0.004583,0.116399,283.019989,14.417727,1.163988,-253.185577,0.116442,0.000000
101.250008,63.624306,-253.185577,0.011443,0.004583,0.116399,283.015045,14.417474,1.163988,-253.185577,0.116442,0.000000
101.510002,63.602715,-253.141098,0.011400,0.004583,0.116399,282.919006,14.412581,1.163988,-253.141098,0.116442,0.000000
101.770004,63.591164,-253.230057,0.011408,0.004583,0.116399,282.867615,14.409964,1.163988,-253.230057,0.116442,0.000000
102.030006,63.576271,-253.230057,0.011426,0.004583,0.116399,282.801392,14.406589,1.163988,-253.230057,0.116442,0.000000
102.290009,63.581490,-253.185577,0.011408,0.004583,0.116399,282.824585,14.407772,1.163988,-253.185577,0.116442,0.000000
102.550003,63.553185,-253.230057,0.011417,0.004583,0.116399,282.698669,14.401357,1.163988,-253.230057,0.116442,0.000000
102.810005,63.537910,-253.185577,0.011391,0.004583,0.116399,282.630737,14.397897,1.163988,-253.185577,0.116442,0.000000
103.070007,63.527855,-253.230057,0.011430,0.004583,0.116399,282.585999,14.395617,1.163988,-253.230057,0.116442,0.000000
103.330002,63.520790,-253.230057,0.011395,0.004583,0.116399,282.554596,14.394017,1.163988,-253.230057,0.116442,0.000000
103.590004,63.513710,-253.230057,0.011417,0.004583,0.116399,282.523102,14.392412,1.163988,-253.230057,0.116442,0.000000
103.850006,63.508873,-253.230057,0.011400,0.004583,0.116399,282.501587,14.391316,1.163988,-253.230057,0.116442,0.000000
104.110008,63.502907,-253.230057,0.011421,0.004583,0.116399,282.475037,14.389965,1.163988,-253.230057,0.116442,0.000000
104.370003,63.473488,-253.230057,0.011404,0.004583,0.116399,282.344177,14.383298,1.163988,-253.230057,0.116442,0.000000
104.630005,63.467537,-253.230057,0.011387,0.004583,0.116399,282.317719,14.381949,1.163988,-253.230057,0.116442,0.000000
104.890007,63.468285,-253.274536,0.011404,0.004583,0.116399,282.321045,14.382119,1.163988,-253.274536,0.116442,0.000000
105.150002,63.455254,-253.363495,0.011413,0.004583,0.116399,282.263062,14.379166,1.163988,-253.363495,0.116442,0.000000
105.410004,63.444817,-253.274536,0.011400,0.004583,0.116399,282.216644,14.376801,1.163988,-253.274536,0.116442,0.000000
105.670006,63.425835,-253.230057,0.011426,0.004583,0.116399,282.132202,14.372499,1.163988,-253.230057,0.116442,0.000000
105.930008,63.418388,-253.363495,0.011413,0.004583,0.116399,282.099091,14.370811,1.163988,-253.363495,0.116442,0.000000
106.190002,63.431038,-253.274536,0.011426,0.004583,0.116399,282.155334,14.373679,1.163988,-253.274536,0.116442,0.000000
106.450005,63.393440,-253.274536,0.011413,0.004583,0.116399,281.988098,14.365159,1.163988,-253.274536,0.116442,0.000000
106.710007,63.397896,-253.274536,0.011430,0.004583,0.116399,282.007935,14.366168,1.163988,-253.274536,0.116442,0.000000
106.970009,63.387474,-253.319016,0.011413,0.004583,0.116399,281.961578,14.363807,1.163988,-253.319016,0.116442,0.000000
107.230003,63.373329,-253.407974,0.011400,0.004583,0.116399,281.898651,14.360601,1.163988,-253.407974,0.116442,0.000000
107.490005,63.373329,-253.319016,0.011413,0.004583,0.116399,281.898651,14.360601,1.163988,-253.319016,0.116442,0.000000
107.750008,63.358437,-253.363495,0.011391,0.004583,0.116399,281.832397,14.357227,1.163988,-253.363495,0.116442,0.000000
108.010002,63.348000,-253.319016,0.011417,0.004583,0.116399,281.785980,14.354862,1.163988,-253.319016,0.116442,0.000000
108.270004,63.338692,-253.363495,0.011413,0.004583,0.116399,281.744568,14.352753,1.163988,-253.363495,0.116442,0.000000
108.530006,63.332359,-253.363495,0.011404,0.004583,0.116399,281.716400,14.351318,1.163988,-253.363495,0.116442,0.000000
108.790009,63.308907,-253.319016,0.011404,0.004583,0.116399,281.612091,14.346004,1.163988,-253.319016,0.116442,0.000000
109.050003,63.308159,-253.363495,0.011421,0.004583,0.116399,281.608765,14.345834,1.163988,-253.363495,0.116442,0.000000
109.310005,63.307793,-253.363495,0.011417,0.004583,0.116399,281.607117,14.345751,1.163988,-253.363495,0.116442,0.000000
109.570007,63.289177,-253.363495,0.011400,0.004583,0.116399,281.524323,14.341532,1.163988,-253.363495,0.116442,0.000000
109.830002,63.285820,-253.407974,0.011417,0.004583,0.116399,281.509399,14.340772,1.163988,-253.407974,0.116442,0.000000
110.090004,63.277626,-253.407974,0.011408,0.004583,0.116399,281.472931,14.338915,1.163988,-253.407974,0.116442,0.000000
110.350006,63.264595,-253.452454,0.011417,0.004583,0.116399,281.414978,14.335962,1.163988,-253.452454,0.116442,0.000000
110.610008,63.255653,-253.407974,0.011430,0.004583,0.116399,281.375214,14.333937,1.163988,-253.407974,0.116442,0.000000
110.870003,63.251564,-253.363495,0.011408,0.004583,0.116399,281.356995,14.333010,1.163988,-253.363495,0.116442,0.000000
111.000008,63.231819,-253.452454,0.011413,0.004583,0.116399,281.269165,14.328535,1.163988,-253.452454,0.116442,0.000000