File: Data/Automembrane/AutoNoheat12-1-4_12132023_181753.csv
Time (sec),S:Load (lbs),S:HL1 (DIM),S:LVDT (in),S:Position (in),Ch:Position (mm),Ch:Load (N),Ch:Stress (MPa),Ch:Strain (mm/mm),Ch:HL1 (DIM),Set Point (),Cycles ()
0.210000,0.000374,-1303.514282,0.000004,-0.000000,-0.000000,0.001663,0.000085,-0.000000,-1303.514282,0.000330,0.000000
0.470000,-0.035378,-1303.514282,-0.000060,0.000037,0.000937,-0.157367,-0.008017,0.009368,-1303.514282,0.001648,0.000000
0.730000,-0.018990,-1303.514282,0.000043,0.000191,0.004856,-0.084470,-0.004303,0.048564,-1303.514282,0.005967,0.000000
0.990000,0.032028,-1303.469849,0.000194,0.000357,0.009071,0.142469,0.007258,0.090713,-1303.469849,0.010303,0.000000
1.250000,0.016754,-1303.514282,0.000371,0.000535,0.013590,0.074526,0.003797,0.135897,-1303.514282,0.014639,0.000000
1.510000,-0.002975,-1303.514282,0.000560,0.000705,0.017908,-0.013236,-0.000674,0.179082,-1303.514282,0.018975,0.000000
1.770000,0.017502,-1303.425293,0.000711,0.000870,0.022097,0.077852,0.003966,0.220970,-1303.425293,0.023294,0.000000
2.030000,-0.038353,-1303.514282,0.000875,0.001048,0.026615,-0.170603,-0.008691,0.266154,-1303.514282,0.027630,0.000000
2.290000,-0.014519,-1303.514282,0.001026,0.001214,0.030830,-0.064583,-0.003290,0.308299,-1303.514282,0.031966,0.000000
2.550000,0.019737,-1303.514282,0.001259,0.001378,0.035010,0.087796,0.004473,0.350099,-1303.514282,0.036302,0.000000
2.810000,-0.024948,-1303.558716,0.001375,0.001559,0.039598,-0.110975,-0.005653,0.395976,-1303.558716,0.040621,0.000000
3.070000,-0.004837,-1303.514282,0.001617,0.001730,0.043934,-0.021516,-0.001096,0.439339,-1303.514282,0.044957,0.000000
3.330000,0.009682,-1303.514282,0.001742,0.001892,0.048053,0.043066,0.002194,0.480530,-1303.514282,0.049293,0.000000
3.590000,0.001488,-1303.469849,0.001932,0.002065,0.052441,0.006618,0.000337,0.524412,-1303.469849,0.053629,0.000000
3.850000,-0.000374,-1303.514282,0.002164,0.002234,0.056743,-0.001663,-0.000085,0.567428,-1303.514282,0.057948,0.000000
4.110000,-0.009308,-1303.558716,0.002289,0.002407,0.061148,-0.041403,-0.002109,0.611484,-1303.558716,0.062284,0.000000
4.370000,-0.052879,-1303.514282,0.002453,0.002580,0.065528,-0.235219,-0.011983,0.655275,-1303.514282,0.066621,0.000000
4.630000,0.011543,-1303.558716,0.002682,0.002742,0.069656,0.051347,0.002616,0.696557,-1303.558716,0.070957,0.000000
4.890000,0.000374,-1303.514282,0.002833,0.002916,0.074070,0.001663,0.000085,0.740700,-1303.514282,0.075275,0.000000
5.150000,-0.013031,-1303.514282,0.003031,0.003093,0.078554,-0.057965,-0.002953,0.785536,-1303.514282,0.079611,0.000000
5.410000,0.008568,-1303.514282,0.003203,0.003265,0.082924,0.038112,0.001941,0.829244,-1303.514282,0.083947,0.000000
5.670000,0.033890,-1303.558716,0.003415,0.003433,0.087209,0.150749,0.007680,0.872085,-1303.558716,0.088266,0.000000
5.930000,0.024574,-1303.558716,0.003561,0.003598,0.091380,0.109312,0.005569,0.913799,-1303.558716,0.092602,0.000000
6.190000,0.075966,-1303.514282,0.003721,0.003775,0.095880,0.337913,0.017214,0.958805,-1303.514282,0.096939,0.000000
6.450000,0.146713,-1303.514282,0.003967,0.003945,0.100199,0.652613,0.033246,1.001994,-1303.514282,0.101275,0.000000
6.710001,0.243904,-1303.558716,0.004066,0.004111,0.104431,1.084940,0.055269,1.044313,-1303.558716,0.105594,0.000000
6.970000,0.437538,-1303.558716,0.004290,0.004284,0.108802,1.946267,0.099148,1.088021,-1303.558716,0.109930,0.000000
7.230000,0.666550,-1303.603271,0.004480,0.004457,0.113199,2.964961,0.151042,1.131990,-1303.603271,0.114266,0.000000
7.490000,0.560791,-1303.558716,0.004428,-0.000000,-0.000009,2.494523,0.127077,-0.000087,-1303.558716,0.000156,0.000000
7.750000,0.537338,-1303.514282,0.004493,-0.000000,-0.000009,2.390200,0.121763,-0.000087,-1303.514282,0.000156,0.000000
8.010000,0.522064,-1303.558716,0.004445,-0.000000,-0.000009,2.322258,0.118301,-0.000087,-1303.558716,0.000520,0.000000
8.270000,0.535469,-1303.514282,0.004497,-0.000000,-0.000009,2.381885,0.121339,-0.000087,-1303.514282,0.000954,0.000000
8.530001,0.510521,-1303.647705,0.004480,-0.000000,-0.000009,2.270911,0.115686,-0.000087,-1303.647705,0.001379,0.000000
8.790000,0.628197,-1303.603271,0.004480,0.000037,0.000945,2.794358,0.142351,0.009451,-1303.603271,0.001813,0.000000
9.050000,0.706764,-1303.558716,0.004497,0.000059,0.001500,3.143844,0.160155,0.015003,-1303.558716,0.002246,0.000000
9.310000,0.726501,-1303.603271,0.004484,0.000072,0.001838,3.231640,0.164628,0.018383,-1303.603271,0.002680,0.000000
9.570001,0.772301,-1303.558716,0.004562,0.000086,0.002194,3.435365,0.175006,0.021941,-1303.558716,0.003113,0.000000
9.830001,0.813263,-1303.558716,0.004587,0.000108,0.002749,3.617574,0.184288,0.027490,-1303.558716,0.003547,0.000000
10.090000,0.857574,-1303.603271,0.004596,0.000127,0.003226,3.814682,0.194329,0.032259,-1303.603271,0.003981,0.000000
10.350000,0.846031,-1303.514282,0.004605,0.000143,0.003625,3.763335,0.191713,0.036248,-1303.514282,0.004414,0.000000
10.610001,0.873215,-1303.603271,0.004605,0.000159,0.004041,3.884253,0.197873,0.040411,-1303.603271,0.004848,0.000000
10.870001,0.904121,-1303.558716,0.004600,0.000173,0.004397,4.021733,0.204877,0.043969,-1303.558716,0.005281,0.000000
11.130000,0.973381,-1303.603271,0.004678,0.000193,0.004908,4.329815,0.220571,0.049083,-1303.603271,0.005715,0.000000
11.390000,0.976730,-1303.603271,0.004639,0.000205,0.005195,4.344714,0.221330,0.051948,-1303.603271,0.006149,0.000000
11.650001,1.050461,-1303.558716,0.004695,0.000222,0.005628,4.672683,0.238038,0.056281,-1303.558716,0.006582,0.000000
11.910001,1.108551,-1303.558716,0.004734,0.000243,0.006175,4.931081,0.251201,0.061747,-1303.558716,0.007016,0.000000
12.170001,1.138718,-1303.514282,0.004738,0.000259,0.006591,5.065269,0.258037,0.065906,-1303.514282,0.007449,0.000000
12.430000,1.166275,-1303.603271,0.004760,0.000278,0.007068,5.187850,0.264282,0.070679,-1303.603271,0.007883,0.000000
12.690001,1.203880,-1303.603271,0.004708,0.000293,0.007441,5.355127,0.272803,0.074407,-1303.603271,0.008317,0.000000
12.950001,1.272026,-1303.558716,0.004794,0.000311,0.007909,5.658255,0.288245,0.079089,-1303.558716,0.008750,0.000000
13.210001,1.334953,-1303.647705,0.004769,0.000327,0.008308,5.938169,0.302505,0.083078,-1303.647705,0.009184,0.000000
13.470000,1.352455,-1303.647705,0.004799,0.000339,0.008620,6.016021,0.306471,0.086201,-1303.647705,0.009617,0.000000
13.730000,1.472359,-1303.603271,0.004850,0.000364,0.009236,6.549378,0.333641,0.092359,-1303.603271,0.010051,0.000000
13.990001,1.524124,-1303.603271,0.004825,0.000380,0.009661,6.779643,0.345371,0.096609,-1303.603271,0.010485,0.000000
14.250001,1.534920,-1303.558716,0.004833,0.000392,0.009947,6.827664,0.347818,0.099471,-1303.558716,0.010918,0.000000
14.510000,1.579605,-1303.603271,0.004876,0.000407,0.010346,7.026434,0.357944,0.103460,-1303.603271,0.011352,0.000000
14.770000,1.738983,-1303.558716,0.004894,0.000431,0.010953,7.735384,0.394059,0.109531,-1303.558716,0.011785,0.000000
15.030001,1.737862,-1303.603271,0.004919,0.000442,0.011239,7.730395,0.393805,0.112392,-1303.603271,0.012219,0.000000
15.290001,1.772125,-1303.647705,0.004950,0.000454,0.011525,7.882807,0.401569,0.115254,-1303.647705,0.012653,0.000000
15.550001,1.934479,-1303.558716,0.004911,0.000476,0.012080,8.604991,0.438359,0.120802,-1303.558716,0.013086,0.000000
15.810000,2.016029,-1303.603271,0.004988,0.000493,0.012514,8.967747,0.456839,0.125140,-1303.603271,0.013520,0.000000
16.070002,2.173538,-1303.647705,0.005014,0.000515,0.013086,9.668381,0.492531,0.130863,-1303.647705,0.013953,0.000000
16.330000,2.123268,-1303.558716,0.005001,0.000526,0.013364,9.444768,0.481139,0.133637,-1303.558716,0.014387,0.000000
16.590000,2.278549,-1303.647705,0.005027,0.000545,0.013841,10.135493,0.516327,0.138410,-1303.647705,0.014821,0.000000
16.850000,2.478882,-1303.558716,0.005027,0.000566,0.014370,11.026617,0.561723,0.143697,-1303.558716,0.015254,0.000000
17.110001,2.538094,-1303.647705,0.005019,0.000580,0.014726,11.290004,0.575140,0.147255,-1303.647705,0.015688,0.000000
17.370001,2.655762,-1303.647705,0.005023,0.000597,0.015176,11.813418,0.601804,0.151763,-1303.647705,0.016122,0.000000
17.630001,2.736565,-1303.603271,0.005079,0.000614,0.015601,12.172848,0.620114,0.156013,-1303.603271,0.016546,0.000000
17.890001,2.761887,-1303.692139,0.005122,0.000624,0.015844,12.285485,0.625852,0.158439,-1303.692139,0.016980,0.000000
18.150002,2.933182,-1303.603271,0.005118,0.000644,0.016347,13.047444,0.664668,0.163470,-1303.603271,0.017414,0.000000
18.410002,3.029625,-1303.647705,0.005135,0.000662,0.016807,13.476445,0.686523,0.168068,-1303.647705,0.017847,0.000000
18.670000,3.233315,-1303.647705,0.005131,0.000684,0.017379,14.382502,0.732680,0.173791,-1303.647705,0.018281,0.000000
18.930000,3.390450,-1303.603271,0.005178,0.000702,0.017822,15.081472,0.768287,0.178216,-1303.603271,0.018715,0.000000
19.190001,3.468651,-1303.692139,0.005165,0.000719,0.018272,15.429330,0.786008,0.182723,-1303.692139,0.019148,0.000000
19.450001,3.524132,-1303.647705,0.005208,0.000733,0.018611,15.676121,0.798580,0.186107,-1303.647705,0.019582,0.000000
19.710001,3.816071,-1303.647705,0.005230,0.000758,0.019252,16.974730,0.864734,0.192522,-1303.647705,0.020016,0.000000
19.970001,3.813469,-1303.558716,0.005195,0.000770,0.019565,16.963158,0.864144,0.195645,-1303.558716,0.020449,0.000000
20.230001,3.889801,-1303.647705,0.005204,0.000787,0.019981,17.302700,0.881442,0.199808,-1303.647705,0.020883,0.000000
20.490002,4.129608,-1303.647705,0.005226,0.000807,0.020501,18.369415,0.935783,0.205013,-1303.647705,0.021316,0.000000
20.750002,4.300156,-1303.692139,0.005290,0.000825,0.020961,19.128048,0.974429,0.209607,-1303.692139,0.021750,0.000000
21.010000,4.328835,-1303.647705,0.005307,0.000841,0.021368,19.255617,0.980928,0.213684,-1303.647705,0.022184,0.000000
21.270000,4.477409,-1303.603271,0.005329,0.000856,0.021732,19.916512,1.014596,0.217325,-1303.603271,0.022617,0.000000
21.530001,4.596939,-1303.647705,0.005359,0.000873,0.022184,20.448206,1.041681,0.221836,-1303.647705,0.023051,0.000000
21.790001,4.443520,-1303.692139,0.005364,0.000876,0.022244,19.765762,1.006916,0.222442,-1303.692139,0.023485,0.000000
22.050001,4.906006,-1303.603271,0.005411,0.000905,0.022999,21.823004,1.111717,0.229989,-1303.603271,0.023918,0.000000
22.310001,4.939896,-1303.692139,0.005368,0.000922,0.023415,21.973753,1.119396,0.234149,-1303.692139,0.024352,0.000000
22.570002,5.137253,-1303.647705,0.005420,0.000941,0.023892,22.851643,1.164118,0.238921,-1303.647705,0.024785,0.000000
22.830002,5.175606,-1303.603271,0.005415,0.000956,0.024274,23.022243,1.172809,0.242737,-1303.603271,0.025219,0.000000
23.090000,5.398659,-1303.692139,0.005415,0.000976,0.024785,24.014433,1.223354,0.247854,-1303.692139,0.025653,0.000000
23.350000,5.441483,-1303.647705,0.005411,0.000990,0.025149,24.204924,1.233058,0.251495,-1303.647705,0.026086,0.000000
23.610001,5.565483,-1303.647705,0.005497,0.001008,0.025592,24.756506,1.261157,0.255916,-1303.647705,0.026520,0.000000
23.870001,5.672348,-1303.692139,0.005437,0.001024,0.025999,25.231865,1.285372,0.259992,-1303.692139,0.026953,0.000000
24.130001,5.754272,-1303.647705,0.005458,0.001041,0.026442,25.596283,1.303937,0.264417,-1303.647705,0.027387,0.000000
24.390001,5.908432,-1303.647705,0.005506,0.001060,0.026927,26.282019,1.338870,0.269273,-1303.647705,0.027820,0.000000
24.650002,5.800072,-1303.603271,0.005553,0.001068,0.027118,25.800007,1.314315,0.271180,-1303.603271,0.028254,0.000000
24.910002,5.846992,-1303.647705,0.005553,0.001078,0.027378,26.008722,1.324947,0.273780,-1303.647705,0.028688,0.000000
25.170002,6.335175,-1303.736694,0.005527,0.001108,0.028133,28.180264,1.435571,0.281327,-1303.736694,0.029121,0.000000
25.430000,6.500877,-1303.603271,0.005592,0.001127,0.028618,28.917347,1.473120,0.286183,-1303.603271,0.029555,0.000000
25.690001,6.513168,-1303.692139,0.005588,0.001144,0.029069,28.972019,1.475905,0.290691,-1303.692139,0.029988,0.000000
25.950001,6.491943,-1303.647705,0.005558,0.001159,0.029442,28.877605,1.471095,0.294423,-1303.647705,0.030422,0.000000
26.210001,6.721321,-1303.736694,0.005592,0.001179,0.029945,29.897930,1.523073,0.299453,-1303.736694,0.030856,0.000000
26.470001,6.806229,-1303.736694,0.005648,0.001197,0.030396,30.275618,1.542313,0.303961,-1303.736694,0.031289,0.000000
26.730001,7.011772,-1303.647705,0.005627,0.001215,0.030856,31.189920,1.588890,0.308560,-1303.647705,0.031714,0.000000
26.990002,6.980865,-1303.647705,0.005661,0.001227,0.031159,31.052441,1.581887,0.311591,-1303.647705,0.032148,0.000000
27.250002,7.012894,-1303.647705,0.005635,0.001242,0.031550,31.194908,1.589144,0.315497,-1303.647705,0.032582,0.000000
27.510002,7.422501,-1303.692139,0.005713,0.001268,0.032200,33.016933,1.681963,0.322000,-1303.692139,0.033015,0.000000
27.770000,7.383400,-1303.692139,0.005670,0.001281,0.032538,32.843002,1.673102,0.325384,-1303.692139,0.033449,0.000000
28.030001,7.441864,-1303.647705,0.005743,0.001298,0.032980,33.103065,1.686350,0.329804,-1303.647705,0.033882,0.000000
28.290001,7.516708,-1303.736694,0.005769,0.001314,0.033388,33.435989,1.703310,0.333881,-1303.736694,0.034316,0.000000
28.550001,7.725616,-1303.692139,0.005730,0.001332,0.033839,34.365257,1.750650,0.338392,-1303.692139,0.034749,0.000000
28.810001,7.845886,-1303.692139,0.005752,0.001349,0.034273,34.900246,1.777903,0.342726,-1303.692139,0.035183,0.000000
29.070002,7.886848,-1303.736694,0.005743,0.001363,0.034620,35.082455,1.787185,0.346197,-1303.736694,0.035617,0.000000
29.330002,8.119209,-1303.692139,0.005803,0.001381,0.035070,36.116047,1.839839,0.350705,-1303.692139,0.036050,0.000000
29.590002,8.426788,-1303.692139,0.005795,0.001407,0.035747,37.484226,1.909538,0.357468,-1303.692139,0.036484,0.000000
29.850002,8.290131,-1303.603271,0.005816,0.001421,0.036094,36.876343,1.878570,0.360939,-1303.603271,0.036918,0.000000
30.110001,8.316566,-1303.692139,0.005894,0.001435,0.036458,36.993935,1.884561,0.364580,-1303.692139,0.037351,0.000000
30.370001,8.695267,-1303.692139,0.005907,0.001459,0.037056,38.678478,1.970376,0.370564,-1303.692139,0.037785,0.000000
30.630001,8.666595,-1303.692139,0.005859,0.001472,0.037377,38.550941,1.963879,0.373774,-1303.692139,0.038219,0.000000
30.890001,8.666595,-1303.736694,0.005941,0.001485,0.037716,38.550941,1.963879,0.377157,-1303.736694,0.038652,0.000000
31.150002,9.123123,-1303.736694,0.005881,0.001509,0.038331,40.581680,2.067329,0.383311,-1303.736694,0.039086,0.000000
31.410002,9.170044,-1303.736694,0.005902,0.001527,0.038782,40.790394,2.077962,0.387823,-1303.736694,0.039519,0.000000
31.670002,9.153290,-1303.736694,0.005954,0.001542,0.039173,40.715866,2.074165,0.391725,-1303.736694,0.039953,0.000000
31.930002,9.260529,-1303.647705,0.005946,0.001558,0.039571,41.192890,2.098466,0.395715,-1303.647705,0.040387,0.000000
32.190002,9.254578,-1303.736694,0.005950,0.001574,0.039970,41.166416,2.097117,0.399704,-1303.736694,0.040820,0.000000
32.450001,9.500343,-1303.692139,0.006006,0.001592,0.040439,42.259636,2.152809,0.404386,-1303.692139,0.041254,0.000000
32.710003,9.454163,-1303.692139,0.006002,0.001603,0.040716,42.054214,2.142344,0.407160,-1303.692139,0.041688,0.000000
32.970001,9.634766,-1303.736694,0.005984,0.001620,0.041150,42.857578,2.183269,0.411498,-1303.736694,0.042121,0.000000
33.230003,9.985542,-1303.736694,0.006019,0.001642,0.041696,44.417912,2.262756,0.416963,-1303.736694,0.042555,0.000000
33.490002,9.957985,-1303.692139,0.006062,0.001659,0.042130,44.295330,2.256512,0.421297,-1303.692139,0.042988,0.000000
33.750000,10.079010,-1303.781128,0.006027,0.001679,0.042650,44.833675,2.283936,0.426501,-1303.781128,0.043422,0.000000
34.010002,9.998199,-1303.647705,0.006122,0.001692,0.042971,44.474213,2.265624,0.429710,-1303.647705,0.043856,0.000000
34.270000,10.180290,-1303.736694,0.006114,0.001710,0.043439,45.284191,2.306887,0.434392,-1303.736694,0.044289,0.000000
34.530003,10.258865,-1303.736694,0.006131,0.001726,0.043838,45.633713,2.324692,0.438382,-1303.736694,0.044723,0.000000
34.790001,10.172096,-1303.692139,0.006127,0.001738,0.044150,45.247746,2.305030,0.441504,-1303.692139,0.045156,0.000000
35.050003,10.622673,-1303.736694,0.006148,0.001762,0.044758,47.252010,2.407132,0.447575,-1303.736694,0.045590,0.000000
35.310001,10.661400,-1303.736694,0.006140,0.001780,0.045200,47.424274,2.415908,0.451996,-1303.736694,0.046024,0.000000
35.570004,10.498299,-1303.781128,0.006187,0.001790,0.045477,46.698765,2.378948,0.454774,-1303.781128,0.046457,0.000000
35.830002,10.554527,-1303.692139,0.006204,0.001806,0.045876,46.948883,2.391690,0.458763,-1303.692139,0.046882,0.000000
36.090000,10.786514,-1303.781128,0.006196,0.001829,0.046457,47.980812,2.444259,0.464573,-1303.781128,0.047316,0.000000
36.350002,10.751511,-1303.781128,0.006178,0.001842,0.046778,47.825108,2.436327,0.467779,-1303.781128,0.047749,0.000000
36.610001,10.592880,-1303.736694,0.006213,0.001851,0.047021,47.119484,2.400381,0.470209,-1303.736694,0.048183,0.000000
36.870003,11.000626,-1303.781128,0.006260,0.001874,0.047593,48.933228,2.492777,0.475932,-1303.781128,0.048617,0.000000
37.130001,11.144737,-1303.736694,0.006282,0.001892,0.048044,49.574268,2.525434,0.480443,-1303.736694,0.049050,0.000000
37.390003,11.418060,-1303.736694,0.006273,0.001914,0.048608,50.790070,2.587369,0.486079,-1303.736694,0.049484,0.000000
37.650002,11.034515,-1303.781128,0.006312,0.001925,0.048885,49.083977,2.500457,0.488853,-1303.781128,0.049917,0.000000
37.910004,11.273209,-1303.736694,0.006265,0.001943,0.049362,50.145737,2.554546,0.493622,-1303.736694,0.050351,0.000000
38.170002,11.554344,-1303.781128,0.006282,0.001965,0.049917,51.396290,2.618252,0.499175,-1303.781128,0.050785,0.000000
38.430000,11.470566,-1303.736694,0.006312,0.001978,0.050238,51.023624,2.599267,0.502384,-1303.736694,0.051218,0.000000
38.690002,11.567009,-1303.781128,0.006334,0.001997,0.050715,51.452625,2.621122,0.507153,-1303.781128,0.051652,0.000000
38.950001,11.626587,-1303.781128,0.006355,0.002013,0.051132,51.717640,2.634622,0.511317,-1303.781128,0.052085,0.000000
39.210003,11.514877,-1303.736694,0.006334,0.002028,0.051504,51.220734,2.609308,0.515045,-1303.736694,0.052519,0.000000
39.470001,11.649673,-1303.825684,0.006377,0.002045,0.051947,51.820335,2.639854,0.519466,-1303.825684,0.052953,0.000000
39.730003,11.737923,-1303.781128,0.006385,0.002061,0.052354,52.212887,2.659851,0.523542,-1303.781128,0.053386,0.000000
39.990002,12.084976,-1303.781128,0.006411,0.002084,0.052944,53.756660,2.738495,0.529439,-1303.781128,0.053820,0.000000
40.250004,12.060402,-1303.781128,0.006407,0.002101,0.053369,53.647346,2.732926,0.533689,-1303.781128,0.054253,0.000000
40.510002,12.006035,-1303.736694,0.006446,0.002119,0.053811,53.405510,2.720606,0.538114,-1303.736694,0.054687,0.000000
40.770000,11.867882,-1303.781128,0.006446,0.002131,0.054124,52.790974,2.689300,0.541236,-1303.781128,0.055121,0.000000
41.030003,11.672386,-1303.781128,0.006428,0.002145,0.054479,51.921368,2.645000,0.544790,-1303.781128,0.055554,0.000000
41.290001,12.334839,-1303.781128,0.006519,0.002174,0.055216,54.868103,2.795115,0.552163,-1303.781128,0.055988,0.000000
41.550003,12.133385,-1303.825684,0.006467,0.002185,0.055511,53.971992,2.749464,0.555112,-1303.825684,0.056421,0.000000
41.810001,12.328506,-1303.692139,0.006515,0.002205,0.056014,54.839935,2.793679,0.560142,-1303.692139,0.056855,0.000000
42.070004,12.525864,-1303.825684,0.006489,0.002223,0.056474,55.717823,2.838401,0.564737,-1303.825684,0.057289,0.000000
42.330002,12.480438,-1303.825684,0.006545,0.002240,0.056899,55.515762,2.828108,0.568987,-1303.825684,0.057722,0.000000
42.590000,12.462936,-1303.736694,0.006536,0.002254,0.057263,55.437908,2.824142,0.572628,-1303.736694,0.058156,0.000000
42.850002,12.557892,-1303.781128,0.006571,0.002272,0.057697,55.860294,2.845659,0.576966,-1303.781128,0.058590,0.000000
43.110001,12.885208,-1303.781128,0.006541,0.002291,0.058200,57.316269,2.919830,0.581996,-1303.781128,0.059023,0.000000
43.370003,12.624176,-1303.781128,0.006588,0.002303,0.058494,56.155140,2.860679,0.584944,-1303.781128,0.059457,0.000000
43.630001,12.745941,-1303.781128,0.006549,0.002320,0.058936,56.696777,2.888271,0.589365,-1303.781128,0.059891,0.000000
43.890003,12.801048,-1303.736694,0.006601,0.002335,0.059309,56.941906,2.900759,0.593093,-1303.736694,0.060324,0.000000
44.150002,12.922440,-1303.825684,0.006631,0.002351,0.059726,57.481880,2.928267,0.597256,-1303.825684,0.060758,0.000000
44.410004,13.282524,-1303.692139,0.006627,0.002374,0.060307,59.083618,3.009863,0.603066,-1303.692139,0.061192,0.000000
44.670002,13.166344,-1303.825684,0.006635,0.002389,0.060671,58.566822,2.983536,0.606711,-1303.825684,0.061616,0.000000
44.930000,13.114212,-1303.825684,0.006661,0.002406,0.061122,58.334930,2.971723,0.611219,-1303.825684,0.062050,0.000000
45.190002,12.577255,-1303.736694,0.006670,0.002409,0.061200,55.946426,2.850047,0.611999,-1303.736694,0.062484,0.000000
45.450001,13.393120,-1303.870117,0.006670,0.002440,0.061972,59.575573,3.034925,0.619720,-1303.870117,0.062917,0.000000
45.710003,13.478394,-1303.781128,0.006648,0.002459,0.062458,59.954887,3.054248,0.624576,-1303.781128,0.063351,0.000000
45.970001,13.337639,-1303.781128,0.006666,0.002473,0.062813,59.328781,3.022352,0.628130,-1303.781128,0.063784,0.000000
46.230003,13.190552,-1303.781128,0.006687,0.002481,0.063030,58.674503,2.989022,0.630299,-1303.781128,0.064218,0.000000
46.490002,13.726395,-1303.781128,0.006735,0.002507,0.063672,61.058052,3.110445,0.636718,-1303.781128,0.064652,0.000000
46.750004,13.861191,-1303.825684,0.006748,0.002526,0.064149,61.657658,3.140991,0.641487,-1303.825684,0.065085,0.000000
47.010002,13.796776,-1303.736694,0.006700,0.002544,0.064608,61.371124,3.126394,0.646082,-1303.736694,0.065519,0.000000
47.270000,13.656387,-1303.781128,0.006786,0.002559,0.064998,60.746643,3.094582,0.649984,-1303.781128,0.065953,0.000000
47.530003,13.853745,-1303.781128,0.006748,0.002578,0.065475,61.624535,3.139303,0.654753,-1303.781128,0.066386,0.000000
47.790001,13.901413,-1303.781128,0.006782,0.002596,0.065935,61.836575,3.150105,0.659351,-1303.781128,0.066820,0.000000
48.050003,14.064140,-1303.870117,0.006812,0.002613,0.066369,62.560421,3.186980,0.663685,-1303.870117,0.067253,0.000000
48.310001,13.908859,-1303.736694,0.006778,0.002626,0.066689,61.869698,3.151793,0.666895,-1303.736694,0.067687,0.000000
48.570004,13.871994,-1303.692139,0.006799,0.002643,0.067123,61.705711,3.143439,0.671232,-1303.692139,0.068121,0.000000
48.830002,14.398155,-1303.870117,0.006873,0.002666,0.067722,64.046196,3.262669,0.677216,-1303.870117,0.068554,0.000000
49.090004,14.264847,-1303.781128,0.006890,0.002681,0.068094,63.453209,3.232460,0.680944,-1303.781128,0.068988,0.000000
49.350002,14.252182,-1303.781128,0.006847,0.002697,0.068502,63.396873,3.229591,0.685021,-1303.781128,0.069421,0.000000
49.610001,14.264847,-1303.825684,0.006877,0.002713,0.068910,63.453209,3.232460,0.689097,-1303.825684,0.069855,0.000000
49.870003,14.434273,-1303.781128,0.006924,0.002730,0.069352,64.206856,3.270853,0.693518,-1303.781128,0.070289,0.000000
50.130001,14.533325,-1303.870117,0.006868,0.002748,0.069812,64.647461,3.293298,0.698116,-1303.870117,0.070722,0.000000
50.390003,14.505768,-1303.781128,0.006898,0.002763,0.070176,64.524879,3.287054,0.701757,-1303.781128,0.071156,0.000000
50.650002,14.651741,-1303.825684,0.006911,0.002781,0.070627,65.174202,3.320132,0.706269,-1303.825684,0.071589,0.000000
50.910004,15.032677,-1303.781128,0.006916,0.002806,0.071260,66.868683,3.406453,0.712597,-1303.781128,0.072023,0.000000
51.170002,14.799942,-1303.781128,0.006954,0.002820,0.071624,65.833427,3.353715,0.716242,-1303.781128,0.072457,0.000000
51.430004,14.651741,-1303.825684,0.006924,0.002834,0.071980,65.174202,3.320132,0.719796,-1303.825684,0.072890,0.000000
51.690002,15.109756,-1303.736694,0.006985,0.002858,0.072587,67.211555,3.423920,0.725867,-1303.736694,0.073324,0.000000
51.950001,14.943306,-1303.736694,0.007006,0.002870,0.072890,66.471146,3.386202,0.728903,-1303.736694,0.073757,0.000000
52.210003,14.824524,-1303.825684,0.007023,0.002883,0.073237,65.942780,3.359285,0.732370,-1303.825684,0.074191,0.000000
52.470001,15.268761,-1303.825684,0.007036,0.002906,0.073818,67.918839,3.459951,0.738183,-1303.825684,0.074625,0.000000
52.730003,15.452339,-1303.870117,0.007019,0.002925,0.074304,68.735435,3.501550,0.743039,-1303.870117,0.075058,0.000000
52.990002,15.282539,-1303.781128,0.007011,0.002941,0.074694,67.980133,3.463073,0.746941,-1303.781128,0.075492,0.000000
53.250004,15.292969,-1303.825684,0.007041,0.002957,0.075119,68.026520,3.465436,0.751188,-1303.825684,0.075925,0.000000
53.510002,15.317543,-1303.825684,0.007075,0.002974,0.075544,68.135834,3.471005,0.755439,-1303.825684,0.076359,0.000000
53.770004,15.443405,-1303.825684,0.007067,0.002991,0.075960,68.695694,3.499526,0.759602,-1303.825684,0.076784,0.000000
54.030003,15.319031,-1303.914551,0.007101,0.003001,0.076238,68.142448,3.471342,0.762376,-1303.914551,0.077218,0.000000
54.290001,15.539474,-1303.825684,0.007118,0.003019,0.076671,69.123032,3.521295,0.766714,-1303.825684,0.077651,0.000000
54.550003,16.041061,-1303.825684,0.007114,0.003040,0.077218,71.354202,3.634956,0.772175,-1303.825684,0.078085,0.000000
54.810001,16.013878,-1303.870117,0.007144,0.003057,0.077660,71.233284,3.628797,0.776600,-1303.870117,0.078518,0.000000
55.070004,16.127083,-1303.825684,0.007110,0.003078,0.078180,71.736847,3.654449,0.781804,-1303.825684,0.078952,0.000000
55.330002,15.914459,-1303.870117,0.007174,0.003090,0.078493,70.791054,3.606268,0.784927,-1303.870117,0.079386,0.000000
55.590004,16.128571,-1303.736694,0.007183,0.003110,0.078987,71.743462,3.654786,0.789870,-1303.736694,0.079819,0.000000
55.850002,16.200066,-1303.825684,0.007192,0.003124,0.079351,72.061493,3.670987,0.793511,-1303.825684,0.080253,0.000000
56.110004,16.033241,-1303.825684,0.007213,0.003137,0.079672,71.319420,3.633184,0.796720,-1303.825684,0.080687,0.000000
56.370003,16.661804,-1303.825684,0.007192,0.003161,0.080296,74.115410,3.775619,0.802962,-1303.825684,0.081120,0.000000
56.630001,16.719154,-1303.825684,0.007243,0.003179,0.080739,74.370514,3.788615,0.807386,-1303.825684,0.081554,0.000000
56.890003,16.444717,-1303.825684,0.007243,0.003189,0.080999,73.149757,3.726426,0.809986,-1303.825684,0.081987,0.000000
57.150002,16.535576,-1303.825684,0.007261,0.003206,0.081432,73.553917,3.747015,0.814324,-1303.825684,0.082421,0.000000
57.410004,16.880020,-1303.870117,0.007248,0.003228,0.081996,75.086082,3.825067,0.819960,-1303.870117,0.082855,0.000000
57.670002,16.919113,-1303.736694,0.007278,0.003243,0.082369,75.259972,3.833926,0.823692,-1303.736694,0.083288,0.000000
57.930004,16.671120,-1303.870117,0.007282,0.003251,0.082569,74.156845,3.777730,0.825686,-1303.870117,0.083722,0.000000
58.190002,17.270638,-1303.825684,0.007278,0.003273,0.083132,76.823631,3.913582,0.831322,-1303.825684,0.084156,0.000000
58.450005,17.499275,-1303.914551,0.007282,0.003291,0.083592,77.840660,3.965392,0.835917,-1303.914551,0.084589,0.000000
58.710003,17.953194,-1303.870117,0.007286,0.003312,0.084130,79.859795,4.068252,0.841295,-1303.870117,0.085023,0.000000
58.970001,17.520126,-1303.781128,0.007321,0.003324,0.084442,77.933411,3.970117,0.844418,-1303.781128,0.085456,0.000000
59.230003,17.853775,-1303.870117,0.007347,0.003342,0.084884,79.417557,4.045723,0.848838,-1303.870117,0.085890,0.000000
59.490002,18.352379,-1303.870117,0.007343,0.003363,0.085430,81.635460,4.158709,0.854304,-1303.870117,0.086324,0.000000
59.750004,18.432068,-1303.825684,0.007343,0.003380,0.085855,81.989929,4.176766,0.858554,-1303.825684,0.086757,0.000000
60.010002,18.400414,-1303.870117,0.007347,0.003394,0.086220,81.849129,4.169593,0.862195,-1303.870117,0.087191,0.000000
60.270004,18.636497,-1303.781128,0.007351,0.003412,0.086670,82.899284,4.223091,0.866703,-1303.781128,0.087624,0.000000
60.530003,18.499840,-1303.825684,0.007390,0.003426,0.087017,82.291397,4.192123,0.870174,-1303.825684,0.088058,0.000000
60.790005,18.993973,-1303.825684,0.007386,0.003445,0.087494,84.489410,4.304096,0.874943,-1303.825684,0.088492,0.000000
61.050003,19.098244,-1303.870117,0.007420,0.003461,0.087919,84.953232,4.327724,0.879193,-1303.870117,0.088925,0.000000
61.310001,19.687706,-1303.914551,0.007416,0.003483,0.088465,87.575287,4.461298,0.884655,-1303.914551,0.089359,0.000000
61.570004,19.838890,-1303.781128,0.007472,0.003500,0.088891,88.247787,4.495557,0.888905,-1303.781128,0.089792,0.000000
61.830002,20.017258,-1303.825684,0.007472,0.003518,0.089350,89.041206,4.535975,0.893500,-1303.825684,0.090226,0.000000
62.090004,19.939804,-1303.914551,0.007446,0.003530,0.089671,88.696678,4.518425,0.896710,-1303.914551,0.090660,0.000000
62.350002,20.363937,-1303.825684,0.007524,0.003555,0.090287,90.583321,4.614534,0.902868,-1303.825684,0.091093,0.000000
62.610004,21.040161,-1303.914551,0.007489,0.003572,0.090729,93.591309,4.767768,0.907292,-1303.914551,0.091527,0.000000
62.870003,20.919518,-1303.825684,0.007532,0.003587,0.091119,93.054665,4.740430,0.911195,-1303.825684,0.091952,0.000000
63.130005,21.339180,-1303.914551,0.007558,0.003604,0.091544,94.921410,4.835527,0.915441,-1303.914551,0.092386,0.000000
63.390003,21.808365,-1303.914551,0.007567,0.003623,0.092030,97.008453,4.941846,0.920297,-1303.914551,0.092819,0.000000
63.650002,21.926781,-1303.825684,0.007558,0.003638,0.092412,97.535194,4.968679,0.924116,-1303.825684,0.093253,0.000000
63.910004,22.167709,-1303.825684,0.007614,0.003653,0.092784,98.606895,5.023275,0.927844,-1303.825684,0.093686,0.000000
64.170006,22.549385,-1303.781128,0.007606,0.003670,0.093218,100.304672,5.109764,0.932182,-1303.781128,0.094120,0.000000
64.430000,22.042587,-1303.870117,0.007618,0.003674,0.093331,98.050323,4.994922,0.933306,-1303.870117,0.094553,0.000000
64.690002,23.322433,-1303.914551,0.007593,0.003701,0.094007,103.743362,5.284939,0.940073,-1303.914551,0.094987,0.000000
64.950005,23.695923,-1303.825684,0.007593,0.003719,0.094458,105.404732,5.369573,0.944581,-1303.825684,0.095421,0.000000
65.210007,24.171440,-1303.959106,0.007644,0.003736,0.094883,107.519936,5.477327,0.948832,-1303.959106,0.095854,0.000000
65.470001,24.547539,-1303.914551,0.007640,0.003750,0.095247,109.192909,5.562551,0.952473,-1303.914551,0.096288,0.000000
65.730003,25.250954,-1303.914551,0.007666,0.003772,0.095811,112.321854,5.721948,0.958108,-1303.914551,0.096721,0.000000
65.990005,25.668381,-1303.914551,0.007657,0.003787,0.096193,114.178658,5.816538,0.961927,-1303.914551,0.097155,0.000000
66.250000,26.175926,-1303.870117,0.007722,0.003805,0.096644,116.436333,5.931550,0.966435,-1303.870117,0.097589,0.000000
66.510002,26.524467,-1303.870117,0.007679,0.003820,0.097034,117.986725,6.010530,0.970337,-1303.870117,0.098022,0.000000
66.770004,26.996262,-1303.914551,0.007666,0.003838,0.097494,120.085365,6.117441,0.974936,-1303.914551,0.098456,0.000000
67.030006,27.382408,-1303.825684,0.007748,0.003857,0.097970,121.803032,6.204942,0.979705,-1303.825684,0.098890,0.000000
67.290001,27.559662,-1303.959106,0.007700,0.003866,0.098187,122.591499,6.245109,0.981874,-1303.959106,0.099323,0.000000
67.550003,27.763718,-1303.870117,0.007752,0.003875,0.098421,123.499184,6.291348,0.984213,-1303.870117,0.099757,0.000000
67.810005,29.452431,-1303.914551,0.007756,0.003905,0.099185,131.010956,6.674016,0.991847,-1303.914551,0.100190,0.000000
68.070000,30.209831,-1303.914551,0.007791,0.003924,0.099662,134.380035,6.845645,0.996616,-1303.914551,0.100624,0.000000
68.330002,30.950859,-1303.870117,0.007769,0.003942,0.100121,137.676300,7.013565,1.001211,-1303.870117,0.101058,0.000000
68.590004,31.153427,-1303.914551,0.007795,0.003957,0.100520,138.577362,7.059467,1.005200,-1303.914551,0.101491,0.000000
68.850006,32.028877,-1303.870117,0.007782,0.003976,0.100988,142.471558,7.257847,1.009882,-1303.870117,0.101925,0.000000
69.110001,32.654831,-1303.959106,0.007804,0.003994,0.101448,145.255936,7.399691,1.014481,-1303.959106,0.102359,0.000000
69.370003,33.432716,-1303.914551,0.007851,0.004009,0.101838,148.716156,7.575962,1.018383,-1303.914551,0.102792,0.000000
69.630005,33.995003,-1303.870117,0.007825,0.004024,0.102211,151.217331,7.703378,1.022111,-1303.870117,0.103226,0.000000
69.890007,34.494720,-1303.914551,0.007843,0.004039,0.102601,153.440186,7.816615,1.026013,-1303.914551,0.103660,0.000000
70.150002,36.017357,-1303.825684,0.007886,0.004063,0.103208,160.213211,8.161650,1.032084,-1303.825684,0.104093,0.000000
70.410004,36.796730,-1303.914551,0.007916,0.004080,0.103633,163.680023,8.338259,1.036335,-1303.914551,0.104527,0.000000
70.670006,37.576851,-1303.959106,0.007920,0.004096,0.104032,167.150177,8.515037,1.040324,-1303.959106,0.104960,0.000000
70.930000,38.277657,-1303.914551,0.007933,0.004111,0.104423,170.267517,8.673841,1.044226,-1303.914551,0.105394,0.000000
71.190002,39.197044,-1303.959106,0.007903,0.004129,0.104865,174.357162,8.882177,1.048647,-1303.959106,0.105828,0.000000
71.450005,40.129837,-1303.959106,0.007981,0.004145,0.105290,178.506424,9.093551,1.052897,-1303.959106,0.106261,0.000000
71.710007,40.887245,-1303.914551,0.007937,0.004159,0.105628,181.875549,9.265182,1.056281,-1303.914551,0.106686,0.000000
71.970001,42.257942,-1303.914551,0.007925,0.004182,0.106218,187.972717,9.575787,1.062178,-1303.914551,0.107120,0.000000
72.230003,43.803665,-1303.914551,0.007972,0.004204,0.106773,194.848434,9.926052,1.067726,-1303.914551,0.107553,0.000000
72.490005,44.557716,-1303.959106,0.007981,0.004218,0.107137,198.202621,10.096923,1.071371,-1303.959106,0.107987,0.000000
72.750000,45.309914,-1303.959106,0.007959,0.004232,0.107493,201.548569,10.267373,1.074925,-1303.959106,0.108421,0.000000
73.010002,46.785622,-1303.959106,0.008011,0.004255,0.108082,208.112839,10.601773,1.080822,-1303.959106,0.108854,0.000000
73.270004,47.567604,-1304.003540,0.008015,0.004267,0.108394,211.591278,10.778974,1.083945,-1304.003540,0.109288,0.000000
73.530006,48.181274,-1303.870117,0.008011,0.004281,0.108741,214.321014,10.918033,1.087412,-1303.870117,0.109721,0.000000
73.790001,50.007385,-1304.003540,0.008015,0.004304,0.109314,222.443954,11.331835,1.093138,-1304.003540,0.110155,0.000000
74.050003,51.429482,-1303.959106,0.008028,0.004322,0.109791,228.769760,11.654087,1.097907,-1303.959106,0.110589,0.000000
74.310005,52.325035,-1303.959106,0.008088,0.004338,0.110190,232.753387,11.857022,1.101897,-1303.959106,0.111022,0.000000
74.570007,53.471199,-1303.959106,0.008045,0.004355,0.110615,237.851776,12.116747,1.106147,-1303.959106,0.111456,0.000000
74.830002,54.309776,-1303.914551,0.008127,0.004370,0.111005,241.581955,12.306771,1.110049,-1303.914551,0.111889,0.000000
75.090004,55.746391,-1303.914551,0.008127,0.004388,0.111447,247.972336,12.632313,1.114470,-1303.914551,0.112323,0.000000
75.350006,56.637108,-1303.914551,0.008123,0.004400,0.111759,251.934433,12.834151,1.117592,-1303.914551,0.112757,0.000000
75.610001,57.445900,-1304.003540,0.008080,0.004416,0.112176,255.532120,13.017426,1.121756,-1304.003540,0.113190,0.000000
75.870003,59.527092,-1304.003540,0.008114,0.004439,0.112739,264.789734,13.489032,1.127392,-1304.003540,0.113624,0.000000
76.130005,60.738792,-1303.959106,0.008149,0.004455,0.113147,270.179657,13.763607,1.131468,-1303.959106,0.114057,0.000000
76.390007,62.171677,-1303.959106,0.008170,0.004475,0.113676,276.553436,14.088304,1.136759,-1303.959106,0.114491,0.000000
76.650002,63.275757,-1303.914551,0.008192,0.004488,0.114006,281.464630,14.338491,1.140056,-1303.914551,0.114925,0.000000
76.910004,64.288620,-1303.914551,0.008192,0.004506,0.114448,285.970062,14.568009,1.144477,-1303.914551,0.115358,0.000000
77.170006,65.864502,-1303.959106,0.008192,0.004523,0.114873,292.979950,14.925110,1.148727,-1303.959106,0.115792,0.000000
77.430000,66.372040,-1303.959106,0.008170,0.004531,0.115090,295.237579,15.040119,1.150896,-1303.959106,0.116225,0.000000
77.690002,67.766571,-1304.003540,0.008162,0.004542,0.115376,301.440765,15.356125,1.153757,-1304.003540,0.115584,0.000000
77.950005,67.376709,-1303.914551,0.008201,0.004542,0.115367,299.706573,15.267780,1.153670,-1303.914551,0.115584,0.000000
78.210007,66.985336,-1303.914551,0.008239,0.004541,0.115341,297.965668,15.179094,1.153409,-1303.914551,0.115367,0.000000
78.470001,66.695633,-1304.003540,0.008205,0.004540,0.115315,296.677002,15.113446,1.153148,-1304.003540,0.115367,0.000000
78.730003,66.459915,-1303.959106,0.008192,0.004539,0.115298,295.628479,15.060033,1.152977,-1303.959106,0.115367,0.000000
78.990005,66.231277,-1304.003540,0.008205,0.004539,0.115289,294.611450,15.008222,1.152890,-1304.003540,0.115367,0.000000
79.250000,66.042114,-1303.959106,0.008231,0.004539,0.115280,293.769989,14.965357,1.152803,-1303.959106,0.115367,0.000000
79.510002,65.859650,-1303.959106,0.008179,0.004539,0.115280,292.958344,14.924009,1.152803,-1303.959106,0.115367,0.000000
79.770004,65.701767,-1304.048096,0.008188,0.004539,0.115280,292.256042,14.888233,1.152803,-1304.048096,0.115367,0.000000
80.030006,65.580002,-1303.959106,0.008231,0.004538,0.115272,291.714417,14.860641,1.152716,-1303.959106,0.115367,0.000000
80.290001,65.432175,-1304.003540,0.008252,0.004538,0.115272,291.056854,14.827143,1.152716,-1304.003540,0.115367,0.000000
80.550003,65.309296,-1303.959106,0.008213,0.004538,0.115272,290.510254,14.799298,1.152716,-1303.959106,0.115367,0.000000
80.810005,65.229980,-1303.959106,0.008183,0.004538,0.115272,290.157440,14.781325,1.152716,-1303.959106,0.115367,0.000000
81.070007,65.108215,-1303.959106,0.008239,0.004538,0.115272,289.615814,14.753733,1.152716,-1303.959106,0.115367,0.000000
81.330002,65.012512,-1303.914551,0.008188,0.004538,0.115263,289.190094,14.732045,1.152629,-1303.914551,0.115367,0.000000
81.590004,64.934311,-1303.959106,0.008235,0.004538,0.115263,288.842255,14.714326,1.152629,-1303.959106,0.115367,0.000000
81.850006,64.828934,-1303.959106,0.008192,0.004538,0.115263,288.373505,14.690447,1.152629,-1303.959106,0.115367,0.000000
82.110001,64.782761,-1303.959106,0.008252,0.004538,0.115263,288.168121,14.679983,1.152629,-1303.959106,0.115367,0.000000
82.370003,64.690781,-1303.959106,0.008261,0.004538,0.115263,287.758972,14.659141,1.152629,-1303.959106,0.115367,0.000000
82.630005,64.601410,-1303.959106,0.008192,0.004538,0.115263,287.361420,14.638888,1.152629,-1303.959106,0.115367,0.000000
82.890007,64.561935,-1304.003540,0.008213,0.004538,0.115263,287.185822,14.629944,1.152629,-1304.003540,0.115367,0.000000
83.150002,64.481506,-1303.959106,0.008222,0.004538,0.115263,286.828064,14.611718,1.152629,-1303.959106,0.115367,0.000000
83.410004,64.431229,-1304.003540,0.008244,0.004538,0.115263,286.604431,14.600326,1.152629,-1304.003540,0.115367,0.000000
83.670006,64.385803,-1303.959106,0.008213,0.004538,0.115263,286.402344,14.590031,1.152629,-1303.959106,0.115367,0.000000
83.930000,64.307983,-1304.003540,0.008226,0.004538,0.115263,286.056183,14.572397,1.152629,-1304.003540,0.115367,0.000000
84.190002,64.264786,-1303.914551,0.008201,0.004538,0.115263,285.864044,14.562609,1.152629,-1303.914551,0.115367,0.000000
84.450005,64.205200,-1303.959106,0.008226,0.004538,0.115263,285.598999,14.549107,1.152629,-1303.959106,0.115367,0.000000
84.710007,64.151215,-1303.959106,0.008196,0.004538,0.115263,285.358856,14.536873,1.152629,-1303.959106,0.115367,0.000000
84.970001,64.120300,-1304.048096,0.008239,0.004538,0.115263,285.221344,14.529867,1.152629,-1304.048096,0.115367,0.000000
85.230003,64.071518,-1303.914551,0.008201,0.004538,0.115263,285.004333,14.518814,1.152629,-1303.914551,0.115367,0.000000
85.490005,64.022003,-1303.914551,0.008196,0.004538,0.115263,284.784088,14.507593,1.152629,-1303.914551,0.115367,0.000000
85.750008,63.991470,-1304.003540,0.008231,0.004538,0.115263,284.648285,14.500675,1.152629,-1304.003540,0.115367,0.000000
86.010002,63.931137,-1303.959106,0.008196,0.004538,0.115263,284.379913,14.487003,1.152629,-1303.959106,0.115367,0.000000
86.270004,63.900970,-1304.003540,0.008222,0.004538,0.115263,284.245728,14.480167,1.152629,-1304.003540,0.115367,0.000000
86.530006,63.870438,-1303.959106,0.008222,0.004538,0.115263,284.109894,14.473248,1.152629,-1303.959106,0.115367,0.000000
86.790001,63.813477,-1304.003540,0.008196,0.004538,0.115263,283.856506,14.460340,1.152629,-1304.003540,0.115367,0.000000
87.050003,63.790009,-1304.003540,0.008196,0.004538,0.115263,283.752136,14.455023,1.152629,-1304.003540,0.115367,0.000000
87.310005,63.755753,-1304.048096,0.008252,0.004538,0.115263,283.599762,14.447260,1.152629,-1304.048096,0.115367,0.000000
87.570007,63.705109,-1304.048096,0.008231,0.004538,0.115263,283.374481,14.435784,1.152629,-1304.048096,0.115367,0.000000
87.830002,63.684631,-1303.959106,0.008196,0.004538,0.115263,283.283386,14.431144,1.152629,-1303.959106,0.115367,0.000000
88.090004,63.657074,-1304.003540,0.008235,0.004538,0.115254,283.160797,14.424899,1.152542,-1304.003540,0.115367,0.000000
88.350006,63.609787,-1304.048096,0.008183,0.004538,0.115254,282.950470,14.414184,1.152542,-1304.048096,0.115367,0.000000
88.610001,63.597870,-1304.003540,0.008244,0.004538,0.115254,282.897461,14.411483,1.152542,-1304.003540,0.115367,0.000000
88.870003,63.555038,-1304.048096,0.008213,0.004538,0.115254,282.706940,14.401777,1.152542,-1304.048096,0.115367,0.000000
89.130005,63.536804,-1303.914551,0.008218,0.004538,0.115254,282.625824,14.397646,1.152542,-1303.914551,0.115367,0.000000
89.390007,63.508118,-1303.959106,0.008218,0.004538,0.115254,282.498230,14.391145,1.152542,-1303.959106,0.115367,0.000000
89.650002,63.475723,-1303.959106,0.008205,0.004538,0.115254,282.354126,14.383804,1.152542,-1303.959106,0.115367,0.000000
89.910004,63.445572,-1303.914551,0.008244,0.004538,0.115254,282.220001,14.376972,1.152542,-1303.914551,0.115367,0.000000
90.170006,63.427322,-1304.048096,0.008261,0.004538,0.115254,282.138824,14.372836,1.152542,-1304.048096,0.115367,0.000000
90.430008,63.384491,-1304.003540,0.008213,0.004538,0.115254,281.948303,14.363131,1.152542,-1304.003540,0.115367,0.000000
90.690002,63.388596,-1303.959106,0.008226,0.004538,0.115254,281.966553,14.364061,1.152542,-1303.959106,0.115367,0.000000
90.950005,63.343536,-1304.092529,0.008196,0.004538,0.115254,281.766113,14.353850,1.152542,-1304.092529,0.115367,0.000000
91.210007,63.318588,-1303.959106,0.008252,0.004538,0.115254,281.655151,14.348198,1.152542,-1303.959106,0.115367,0.000000
91.470001,63.307419,-1304.048096,0.008201,0.004538,0.115254,281.605469,14.345667,1.152542,-1304.048096,0.115367,0.000000
91.730003,63.266449,-1304.048096,0.008231,0.004538,0.115254,281.423218,14.336382,1.152542,-1304.048096,0.115367,0.000000
91.990005,63.257141,-1304.003540,0.008209,0.004538,0.115254,281.381805,14.334273,1.152542,-1304.003540,0.115367,0.000000
92.250008,63.248581,-1304.003540,0.008226,0.004538,0.115254,281.343750,14.332333,1.152542,-1304.003540,0.115367,0.000000
92.510002,63.205765,-1304.003540,0.008231,0.004538,0.115254,281.153290,14.322631,1.152542,-1304.003540,0.115367,0.000000
92.770004,63.197189,-1304.048096,0.008252,0.004538,0.115254,281.115143,14.320687,1.152542,-1304.048096,0.115367,0.000000
93.030006,63.162186,-1304.048096,0.008196,0.004538,0.115254,280.959442,14.312756,1.152542,-1304.048096,0.115367,0.000000
93.290001,63.148788,-1303.959106,0.008244,0.004538,0.115254,280.899841,14.309720,1.152542,-1303.959106,0.115367,0.000000
93.550003,63.128677,-1304.003540,0.008183,0.004538,0.115254,280.810394,14.305163,1.152542,-1304.003540,0.115367,0.000000
93.810005,63.100006,-1304.048096,0.008269,0.004538,0.115254,280.682831,14.298666,1.152542,-1304.048096,0.115367,0.000000
94.070007,63.079895,-1304.003540,0.008205,0.004538,0.115254,280.593384,14.294108,1.152542,-1304.003540,0.115367,0.000000
94.330002,63.062393,-1304.048096,0.008222,0.004538,0.115254,280.515533,14.290143,1.152542,-1304.048096,0.115367,0.000000
94.590004,63.032234,-1304.003540,0.008278,0.004538,0.115254,280.381378,14.283309,1.152542,-1304.003540,0.115367,0.000000
94.850006,63.043404,-1304.092529,0.008209,0.004538,0.115254,280.431061,14.285840,1.152542,-1304.092529,0.115367,0.000000
95.110008,63.003929,-1304.048096,0.008205,0.004538,0.115254,280.255463,14.276894,1.152542,-1304.048096,0.115367,0.000000
95.370003,62.981964,-1304.048096,0.008257,0.004538,0.115254,280.157776,14.271917,1.152542,-1304.048096,0.115367,0.000000
95.630005,62.978981,-1304.092529,0.008188,0.004538,0.115254,280.144501,14.271241,1.152542,-1304.092529,0.115367,0.000000
95.890007,62.950684,-1304.003540,0.008218,0.004538,0.115254,280.018616,14.264829,1.152542,-1304.003540,0.115367,0.000000
96.150002,62.933182,-1304.092529,0.008226,0.004538,0.115254,279.940765,14.260863,1.152542,-1304.092529,0.115367,0.000000
96.410004,62.911957,-1304.003540,0.008222,0.004538,0.115254,279.846375,14.256054,1.152542,-1304.003540,0.115367,0.000000
96.670006,62.900414,-1304.048096,0.008265,0.004538,0.115254,279.795013,14.253437,1.152542,-1304.048096,0.115367,0.000000
96.930008,62.880676,-1304.048096,0.008248,0.004538,0.115254,279.707214,14.248965,1.152542,-1304.048096,0.115367,0.000000
97.190002,62.871368,-1303.959106,0.008248,0.004538,0.115254,279.665802,14.246856,1.152542,-1303.959106,0.115367,0.000000
97.450005,62.840462,-1304.092529,0.008239,0.004538,0.115254,279.528320,14.239852,1.152542,-1304.092529,0.115367,0.000000
97.710007,62.845673,-1304.048096,0.008257,0.004538,0.115254,279.551514,14.241034,1.152542,-1304.048096,0.115367,0.000000
97.970001,62.823708,-1304.048096,0.008209,0.004538,0.115254,279.453796,14.236055,1.152542,-1304.048096,0.115367,0.000000
98.230003,62.804344,-1304.092529,0.008192,0.004538,0.115254,279.367676,14.231668,1.152542,-1304.092529,0.115367,0.000000
98.490005,62.798386,-1304.048096,0.008257,0.004538,0.115254,279.341156,14.230318,1.152542,-1304.048096,0.115367,0.000000
98.750008,62.765984,-1304.136963,0.008244,0.004538,0.115254,279.197052,14.222976,1.152542,-1304.136963,0.115367,0.000000
99.010002,62.755936,-1304.048096,0.008257,0.004538,0.115254,279.152344,14.220698,1.152542,-1304.048096,0.115367,0.000000
99.270004,62.744019,-1304.048096,0.008226,0.004538,0.115254,279.099335,14.217998,1.152542,-1304.048096,0.115367,0.000000
99.530006,62.706032,-1304.092529,0.008209,0.004538,0.115254,278.930359,14.209390,1.152542,-1304.092529,0.115367,0.000000
99.790009,62.713852,-1304.003540,0.008213,0.004538,0.115254,278.965149,14.211162,1.152542,-1304.003540,0.115367,0.000000
100.050003,62.687042,-1304.136963,0.008239,0.004538,0.115254,278.845886,14.205087,1.152542,-1304.136963,0.115367,0.000000
100.310005,62.660606,-1304.092529,0.008239,0.004538,0.115254,278.728302,14.199097,1.152542,-1304.092529,0.115367,0.000000
100.570007,62.659859,-1304.181519,0.008269,0.004538,0.115254,278.724976,14.198927,1.152542,-1304.181519,0.115367,0.000000
100.830002,62.622993,-1304.136963,0.008196,0.004538,0.115254,278.560974,14.190573,1.152542,-1304.136963,0.115367,0.000000
101.090004,62.624115,-1304.092529,0.008218,0.004538,0.115254,278.565979,14.190826,1.152542,-1304.092529,0.115367,0.000000
101.350006,62.614433,-1304.136963,0.008205,0.004538,0.115254,278.522919,14.188634,1.152542,-1304.136963,0.115367,0.000000
101.610008,62.589111,-1304.003540,0.008175,0.004538,0.115254,278.410278,14.182895,1.152542,-1304.003540,0.115367,0.000000
101.870003,62.580544,-1304.092529,0.008257,0.004538,0.115254,278.372162,14.180954,1.152542,-1304.092529,0.115367,0.000000
102.130005,62.574211,-1304.092529,0.008201,0.004538,0.115254,278.343994,14.179519,1.152542,-1304.092529,0.115367,0.000000
102.390007,62.547028,-1304.092529,0.008252,0.004538,0.115254,278.223083,14.173359,1.152542,-1304.092529,0.115367,0.000000
102.650002,62.538094,-1304.092529,0.008244,0.004538,0.115254,278.183319,14.171334,1.152542,-1304.092529,0.115367,0.000000
102.910004,62.529900,-1304.048096,0.008201,0.004538,0.115254,278.146881,14.169478,1.152542,-1304.048096,0.115367,0.000000
103.170006,62.513145,-1304.092529,0.008196,0.004538,0.115254,278.072357,14.165682,1.152542,-1304.092529,0.115367,0.000000
103.430008,62.491547,-1304.092529,0.008226,0.004538,0.115254,277.976288,14.160787,1.152542,-1304.092529,0.115367,0.000000
103.690002,62.491547,-1304.092529,0.008205,0.004538,0.115254,277.976288,14.160787,1.152542,-1304.092529,0.115367,0.000000
103.950005,62.478889,-1304.092529,0.008231,0.004538,0.115254,277.919983,14.157919,1.152542,-1304.092529,0.115367,0.000000
104.210007,62.449844,-1304.092529,0.008188,0.004538,0.115254,277.790771,14.151337,1.152542,-1304.092529,0.115367,0.000000
104.470001,62.453941,-1304.048096,0.008218,0.004538,0.115254,277.809021,14.152266,1.152542,-1304.048096,0.115367,0.000000
104.730003,62.434204,-1304.136963,0.008209,0.004538,0.115254,277.721222,14.147793,1.152542,-1304.136963,0.115367,0.000000
104.990005,62.419304,-1304.048096,0.008201,0.004538,0.115254,277.654938,14.144416,1.152542,-1304.048096,0.115367,0.000000
105.250008,62.433083,-1304.136963,0.008201,0.004538,0.115254,277.716217,14.147538,1.152542,-1304.136963,0.115367,0.000000
105.510002,62.405533,-1304.092529,0.008213,0.004538,0.115254,277.593689,14.141296,1.152542,-1304.092529,0.115367,0.000000
105.770004,62.391754,-1304.092529,0.008209,0.004538,0.115254,277.532379,14.138174,1.152542,-1304.092529,0.115367,0.000000
106.030006,62.382072,-1304.092529,0.008257,0.004538,0.115254,277.489319,14.135980,1.152542,-1304.092529,0.115367,0.000000
106.290009,62.371269,-1304.092529,0.008222,0.004538,0.115254,277.441254,14.133532,1.152542,-1304.092529,0.115367,0.000000
106.550003,62.358612,-1304.136963,0.008244,0.004538,0.115254,277.384949,14.130663,1.152542,-1304.136963,0.115367,0.000000
106.810005,62.354889,-1304.136963,0.008257,0.004538,0.115254,277.368408,14.129820,1.152542,-1304.136963,0.115367,0.000000
107.070007,62.335526,-1304.092529,0.008252,0.004538,0.115254,277.282257,14.125432,1.152542,-1304.092529,0.115367,0.000000
107.330002,62.314674,-1304.092529,0.008235,0.004538,0.115254,277.189514,14.120707,1.152542,-1304.092529,0.115367,0.000000
107.590004,62.326218,-1304.092529,0.008213,0.004538,0.115254,277.240875,14.123322,1.152542,-1304.092529,0.115367,0.000000
107.850006,62.306107,-1304.092529,0.008235,0.004538,0.115254,277.151398,14.118765,1.152542,-1304.092529,0.115367,0.000000
108.110008,62.290466,-1304.136963,0.008244,0.004538,0.115254,277.081818,14.115221,1.152542,-1304.136963,0.115367,0.000000
108.200005,62.288979,-1304.136963,0.008196,0.004538,0.115254,277.075226,14.114884,1.152542,-1304.136963,0.115367,0.000000