File: Data/Automembrane/AutoHeating-10wt-1-3_12152023_180733.csv
Time (sec),S:Load (lbs),S:HL1 (DIM),S:LVDT (in),S:Position (in),Ch:Position (mm),Ch:Load (N),Ch:Stress (MPa),Ch:Strain (mm/mm),Ch:HL1 (DIM),Set Point (),Cycles ()
0.110000,-0.012291,-259.724274,-0.000009,-0.000000,-0.000000,-0.054673,-0.002785,-0.000000,-259.724274,0.000182,0.000000
0.370000,-0.006699,-259.724274,0.000000,0.000005,0.000130,-0.029797,-0.001518,0.001302,-259.724274,0.000668,0.000000
0.630000,-0.068512,-259.768768,-0.000009,0.000156,0.003972,-0.304756,-0.015525,0.039719,-259.768768,0.005004,0.000000
0.890000,0.003723,-259.768768,0.000185,0.000326,0.008282,0.016561,0.000844,0.082821,-259.768768,0.009323,0.000000
1.150000,0.011169,-259.857727,0.000328,0.000498,0.012653,0.049684,0.002531,0.126529,-259.857727,0.013659,0.000000
1.410000,-0.033142,-259.813232,0.000517,0.000667,0.016954,-0.147423,-0.007510,0.169544,-259.813232,0.017995,0.000000
1.670000,0.001862,-259.813232,0.000690,0.000836,0.021230,0.008281,0.000422,0.212299,-259.813232,0.022331,0.000000
1.930000,0.015640,-259.857727,0.000854,0.001009,0.025618,0.069571,0.003544,0.256181,-259.857727,0.026650,0.000000
2.190000,-0.023460,-259.857727,0.001035,0.001175,0.029833,-0.104357,-0.005316,0.298325,-259.857727,0.030986,0.000000
2.450000,-0.004837,-259.768768,0.001224,0.001345,0.034169,-0.021516,-0.001096,0.341689,-259.768768,0.035322,0.000000
2.710000,-0.008560,-259.857727,0.001388,0.001521,0.038644,-0.038078,-0.001940,0.386438,-259.857727,0.039641,0.000000
2.970000,-0.057716,-259.813232,0.001552,0.001690,0.042928,-0.256735,-0.013079,0.429279,-259.813232,0.043977,0.000000
3.230000,0.004845,-259.902191,0.001746,0.001856,0.047134,0.021550,0.001098,0.471337,-259.902191,0.048313,0.000000
3.490000,0.013779,-259.813232,0.001944,0.002036,0.051704,0.061291,0.003122,0.517039,-259.813232,0.052649,0.000000
3.750000,-0.019737,-259.813232,0.002108,0.002199,0.055850,-0.087796,-0.004473,0.558495,-259.813232,0.056968,0.000000
4.010000,0.015640,-259.946686,0.002281,0.002370,0.060194,0.069571,0.003544,0.601942,-259.946686,0.061304,0.000000
4.270000,0.003349,-259.857727,0.002458,0.002546,0.064660,0.014898,0.000759,0.646604,-259.857727,0.065640,0.000000
4.530000,-0.014893,-259.902191,0.002621,0.002708,0.068789,-0.066245,-0.003375,0.687886,-259.902191,0.069977,0.000000
4.790000,0.005211,-259.902191,0.002811,0.002874,0.073012,0.023179,0.001181,0.730118,-259.902191,0.074295,0.000000
5.050000,-0.004471,-259.902191,0.003018,0.003058,0.077669,-0.019887,-0.001013,0.776687,-259.902191,0.078632,0.000000
5.310000,-0.008194,-259.946686,0.003191,0.003225,0.081927,-0.036449,-0.001857,0.819271,-259.946686,0.082968,0.000000
5.570000,0.046547,-259.813232,0.003363,0.003390,0.086098,0.207051,0.010548,0.860984,-259.813232,0.087304,0.000000
5.830000,0.031281,-259.991150,0.003548,0.003569,0.090651,0.139143,0.007088,0.906513,-259.991150,0.091622,0.000000
6.090000,0.011917,-259.902191,0.003704,0.003737,0.094909,0.053010,0.002700,0.949093,-259.902191,0.095958,0.000000
6.350000,0.031654,-259.902191,0.003846,0.003900,0.099054,0.140806,0.007173,0.990545,-259.902191,0.100295,0.000000
6.610000,0.002235,-259.946686,0.004036,0.004078,0.103573,0.009944,0.000507,1.035729,-259.946686,0.104631,0.000000
6.870000,0.001122,-259.902191,0.004221,0.004247,0.107883,0.004989,0.000254,1.078831,-259.902191,0.108950,0.000000
7.130000,0.011543,-259.946686,0.004398,0.004410,0.112002,0.051347,0.002616,1.120022,-259.946686,0.113286,0.000000
7.390000,0.016388,-259.946686,0.004566,0.004590,0.116581,0.072897,0.003714,1.165812,-259.946686,0.117622,0.000000
7.650001,0.018250,-259.946686,0.004764,0.004761,0.120926,0.081178,0.004135,1.209259,-259.946686,0.121941,0.000000
7.910000,0.053993,-259.991150,0.004950,0.004927,0.125158,0.240174,0.012235,1.251582,-259.991150,0.126277,0.000000
8.170000,0.049530,-259.946686,0.005109,0.005101,0.129564,0.220321,0.011224,1.295638,-259.946686,0.130613,0.000000
8.430000,0.074104,-259.946686,0.005316,0.005270,0.133848,0.329632,0.016792,1.338479,-259.946686,0.134949,0.000000
8.690001,0.147835,-260.035645,0.005467,0.005434,0.138019,0.657602,0.033500,1.380192,-260.035645,0.139268,0.000000
8.950001,0.261032,-259.991150,0.005678,0.005610,0.142502,1.161129,0.059151,1.425024,-259.991150,0.143604,0.000000
9.210000,0.515366,-259.991150,0.005859,0.005783,0.146882,2.292461,0.116784,1.468819,-259.991150,0.147940,0.000000
9.470000,0.596169,-259.946686,0.005946,0.000003,0.000078,2.651890,0.135094,0.000783,-259.946686,0.000199,0.000000
9.730000,0.548882,-260.035645,0.005941,0.000003,0.000070,2.441547,0.124378,0.000696,-260.035645,0.000199,0.000000
9.990001,0.520576,-260.035645,0.005928,0.000003,0.000070,2.315640,0.117964,0.000696,-260.035645,0.000442,0.000000
10.250001,0.480362,-259.946686,0.005941,0.000003,0.000070,2.136757,0.108852,0.000696,-259.946686,0.000876,0.000000
10.510000,0.472916,-260.080109,0.005946,0.000003,0.000070,2.103634,0.107164,0.000696,-260.080109,0.001310,0.000000
10.770000,0.589470,-260.035645,0.005963,0.000038,0.000954,2.622093,0.133576,0.009542,-260.035645,0.001743,0.000000
11.030001,0.708252,-260.035645,0.005989,0.000056,0.001414,3.150462,0.160492,0.014137,-260.035645,0.002177,0.000000
11.290001,0.754425,-260.035645,0.006002,0.000070,0.001769,3.355850,0.170955,0.017694,-260.035645,0.002610,0.000000
11.550000,0.789429,-260.035645,0.005993,0.000082,0.002073,3.511554,0.178887,0.020730,-260.035645,0.003035,0.000000
11.810000,0.814751,-260.080109,0.006040,0.000096,0.002428,3.624192,0.184625,0.024284,-260.080109,0.003469,0.000000
12.070001,0.912315,-260.080109,0.006058,0.000123,0.003131,4.058181,0.206734,0.031309,-260.080109,0.003903,0.000000
12.330001,0.950668,-260.080109,0.006066,0.000137,0.003486,4.228784,0.215425,0.034863,-260.080109,0.004336,0.000000
12.590000,0.990143,-260.169098,0.006071,0.000154,0.003911,4.404375,0.224370,0.039113,-260.169098,0.004770,0.000000
12.850000,1.050095,-260.035645,0.006079,0.000172,0.004380,4.671054,0.237955,0.043795,-260.035645,0.005203,0.000000
13.110001,1.117119,-260.124603,0.006135,0.000191,0.004857,4.969193,0.253143,0.048568,-260.124603,0.005637,0.000000
13.370001,1.119728,-260.124603,0.006144,0.000199,0.005065,4.980799,0.253734,0.050646,-260.124603,0.006071,0.000000
13.630001,1.234047,-260.124603,0.006157,0.000220,0.005585,5.489315,0.279639,0.055850,-260.124603,0.006504,0.000000
13.890000,1.310753,-260.124603,0.006170,0.000239,0.006079,5.830520,0.297021,0.060793,-260.124603,0.006938,0.000000
14.150001,1.357674,-260.124603,0.006209,0.000259,0.006574,6.039234,0.307653,0.065736,-260.124603,0.007371,0.000000
14.410001,1.388580,-260.080109,0.006217,0.000275,0.006990,6.176714,0.314657,0.069899,-260.080109,0.007805,0.000000
14.670001,1.442200,-260.169098,0.006239,0.000291,0.007398,6.415225,0.326807,0.073976,-260.169098,0.008239,0.000000
14.930000,1.543488,-260.124603,0.006260,0.000311,0.007892,6.865776,0.349759,0.078919,-260.124603,0.008672,0.000000
15.190001,1.557632,-260.213562,0.006252,0.000321,0.008161,6.928695,0.352965,0.081606,-260.213562,0.009106,0.000000
15.450001,1.619820,-260.124603,0.006278,0.000337,0.008560,7.205317,0.367056,0.085595,-260.124603,0.009539,0.000000
15.710001,1.717010,-260.169098,0.006286,0.000356,0.009037,7.637644,0.389080,0.090368,-260.169098,0.009973,0.000000
15.970001,1.842499,-260.169098,0.006355,0.000381,0.009687,8.195844,0.417516,0.096871,-260.169098,0.010407,0.000000
16.230001,1.825745,-260.124603,0.006364,0.000395,0.010025,8.121318,0.413720,0.100254,-260.124603,0.010840,0.000000
16.490002,1.851067,-260.213562,0.006381,0.000412,0.010476,8.233955,0.419458,0.104762,-260.213562,0.011274,0.000000
16.750000,1.877502,-260.213562,0.006398,0.000424,0.010780,8.351548,0.425448,0.107798,-260.213562,0.011708,0.000000
17.010000,1.993683,-260.169098,0.006424,0.000446,0.011318,8.868344,0.451775,0.113176,-260.169098,0.012141,0.000000
17.270000,2.027939,-260.213562,0.006428,0.000462,0.011734,9.020722,0.459538,0.117336,-260.213562,0.012575,0.000000
17.530001,2.111725,-260.169098,0.006446,0.000479,0.012167,9.393421,0.478524,0.121673,-260.169098,0.013009,0.000000
17.790001,2.183220,-260.258057,0.006476,0.000500,0.012696,9.711447,0.494725,0.126964,-260.258057,0.013442,0.000000
18.050001,2.213013,-260.213562,0.006497,0.000516,0.013113,9.843972,0.501476,0.131128,-260.213562,0.013876,0.000000
18.310001,2.201096,-260.258057,0.006523,0.000531,0.013486,9.790962,0.498775,0.134856,-260.258057,0.014310,0.000000
18.570002,2.233864,-260.213562,0.006528,0.000545,0.013832,9.936723,0.506201,0.138323,-260.213562,0.014743,0.000000
18.830002,2.326958,-260.213562,0.006579,0.000564,0.014335,10.350824,0.527296,0.143353,-260.213562,0.015177,0.000000
19.090000,2.351532,-260.302521,0.006588,0.000579,0.014700,10.460136,0.532865,0.146998,-260.302521,0.015610,0.000000
19.350000,2.329933,-260.258057,0.006588,0.000590,0.014995,10.364060,0.527970,0.149946,-260.258057,0.016044,0.000000
19.610001,2.469574,-260.213562,0.006605,0.000614,0.015602,10.985213,0.559613,0.156017,-260.213562,0.016478,0.000000
19.870001,2.516495,-260.302521,0.006666,0.000635,0.016122,11.193928,0.570246,0.161218,-260.302521,0.016911,0.000000
20.130001,2.511284,-260.302521,0.006666,0.000649,0.016478,11.170749,0.569065,0.164775,-260.302521,0.017345,0.000000
20.390001,2.565651,-260.213562,0.006687,0.000668,0.016972,11.412585,0.581385,0.169718,-260.213562,0.017770,0.000000
20.650002,2.551498,-260.258057,0.006709,0.000680,0.017284,11.349631,0.578178,0.172841,-260.258057,0.018203,0.000000
20.910002,2.645706,-260.347015,0.006730,0.000703,0.017856,11.768689,0.599526,0.178564,-260.347015,0.018637,0.000000
21.170000,2.625969,-260.347015,0.006786,0.000716,0.018186,11.680893,0.595053,0.181860,-260.347015,0.019071,0.000000
21.430000,2.676987,-260.302521,0.006778,0.000731,0.018576,11.907831,0.606614,0.185763,-260.302521,0.019504,0.000000
21.690001,2.709755,-260.347015,0.006795,0.000750,0.019053,12.053592,0.614039,0.190532,-260.347015,0.019938,0.000000
21.950001,2.766731,-260.391479,0.006829,0.000771,0.019574,12.307035,0.626950,0.195736,-260.391479,0.020371,0.000000
22.210001,2.711990,-260.258057,0.006838,0.000784,0.019912,12.063536,0.614546,0.199116,-260.258057,0.020805,0.000000
22.470001,2.744759,-260.347015,0.006864,0.000799,0.020293,12.209296,0.621971,0.202931,-260.347015,0.021239,0.000000
22.730001,2.801735,-260.391479,0.006881,0.000817,0.020753,12.462739,0.634882,0.207530,-260.391479,0.021672,0.000000
22.990002,2.760025,-260.302521,0.006898,0.000831,0.021117,12.277205,0.625431,0.211171,-260.302521,0.022106,0.000000
23.250002,2.786835,-260.391479,0.006920,0.000847,0.021507,12.396460,0.631506,0.215073,-260.391479,0.022539,0.000000
23.510000,2.915306,-260.347015,0.006950,0.000871,0.022123,12.967929,0.660618,0.221231,-260.347015,0.022973,0.000000
23.770000,2.959991,-260.347015,0.006980,0.000892,0.022669,13.166699,0.670744,0.226692,-260.347015,0.023407,0.000000
24.030001,2.881050,-260.347015,0.006989,0.000904,0.022964,12.815551,0.652855,0.229641,-260.347015,0.023840,0.000000
24.290001,2.894455,-260.480438,0.007032,0.000920,0.023372,12.875178,0.655893,0.233717,-260.480438,0.024274,0.000000
24.550001,2.887749,-260.435974,0.007045,0.000936,0.023779,12.845347,0.654373,0.237794,-260.435974,0.024707,0.000000
24.810001,2.989410,-260.435974,0.007049,0.000954,0.024231,13.297562,0.677410,0.242305,-260.435974,0.025141,0.000000
25.070002,2.919403,-260.435974,0.007071,0.000965,0.024517,12.986154,0.661546,0.245167,-260.435974,0.025575,0.000000
25.330002,3.054947,-260.480438,0.007101,0.000987,0.025080,13.589083,0.692261,0.250802,-260.480438,0.026008,0.000000
25.590002,3.059044,-260.435974,0.007110,0.001008,0.025601,13.607306,0.693189,0.256007,-260.435974,0.026442,0.000000
25.850000,3.063507,-260.480438,0.007136,0.001025,0.026026,13.627160,0.694201,0.260257,-260.480438,0.026875,0.000000
26.110001,2.996857,-260.435974,0.007183,0.001038,0.026372,13.330685,0.679097,0.263724,-260.435974,0.027309,0.000000
26.370001,2.962593,-260.524933,0.007217,0.001053,0.026737,13.178272,0.671333,0.267369,-260.524933,0.027743,0.000000
26.630001,3.055321,-260.524933,0.007222,0.001073,0.027266,13.590745,0.692346,0.272656,-260.524933,0.028176,0.000000
26.890001,3.072075,-260.435974,0.007256,0.001088,0.027647,13.665272,0.696142,0.276471,-260.435974,0.028610,0.000000
27.150002,3.011002,-260.524933,0.007256,0.001100,0.027942,13.393604,0.682303,0.279420,-260.524933,0.029043,0.000000
27.410002,3.124207,-260.480438,0.007295,0.001122,0.028489,13.897164,0.707955,0.284885,-260.480438,0.029477,0.000000
27.670002,3.175591,-260.524933,0.007299,0.001143,0.029026,14.125732,0.719599,0.290264,-260.524933,0.029911,0.000000
27.930002,3.142822,-260.480438,0.007338,0.001157,0.029390,13.979972,0.712174,0.293905,-260.480438,0.030344,0.000000
28.190001,3.113777,-260.435974,0.007364,0.001175,0.029841,13.850773,0.705592,0.298412,-260.435974,0.030778,0.000000
28.450001,3.152878,-260.524933,0.007373,0.001191,0.030240,14.024701,0.714452,0.302402,-260.524933,0.031212,0.000000
28.710001,3.234055,-260.480438,0.007399,0.001212,0.030787,14.385793,0.732847,0.307867,-260.480438,0.031645,0.000000
28.970001,3.113037,-260.480438,0.007442,0.001222,0.031029,13.847481,0.705424,0.310293,-260.480438,0.032079,0.000000
29.230001,3.209480,-260.524933,0.007433,0.001243,0.031576,14.276482,0.727279,0.315759,-260.524933,0.032512,0.000000
29.490002,3.283211,-260.569397,0.007472,0.001265,0.032139,14.604451,0.743986,0.321394,-260.569397,0.032937,0.000000
29.750002,3.236664,-260.569397,0.007489,0.001280,0.032521,14.397400,0.733438,0.325210,-260.569397,0.033371,0.000000
30.010002,3.226608,-260.569397,0.007498,0.001296,0.032911,14.352671,0.731160,0.329112,-260.569397,0.033805,0.000000
30.270002,3.218788,-260.569397,0.007549,0.001313,0.033362,14.317884,0.729388,0.333623,-260.569397,0.034238,0.000000
30.530001,3.292145,-260.569397,0.007558,0.001329,0.033753,14.644192,0.746011,0.337526,-260.569397,0.034672,0.000000
30.790001,3.226982,-260.569397,0.007571,0.001343,0.034117,14.354333,0.731245,0.341167,-260.569397,0.035105,0.000000
31.050001,3.282089,-260.569397,0.007593,0.001359,0.034524,14.599463,0.743732,0.345243,-260.569397,0.035539,0.000000
31.310001,3.397156,-260.569397,0.007623,0.001381,0.035071,15.111303,0.769807,0.350708,-260.569397,0.035973,0.000000
31.570002,3.418007,-260.658386,0.007653,0.001403,0.035634,15.204054,0.774531,0.356344,-260.658386,0.036406,0.000000
31.830002,3.305176,-260.658386,0.007653,0.001417,0.035999,14.702156,0.748964,0.359985,-260.658386,0.036840,0.000000
32.090000,3.314491,-260.658386,0.007713,0.001435,0.036441,14.743593,0.751074,0.364410,-260.658386,0.037274,0.000000
32.350002,3.397530,-260.658386,0.007726,0.001454,0.036944,15.112967,0.769891,0.369440,-260.658386,0.037707,0.000000
32.610001,3.392685,-260.658386,0.007726,0.001468,0.037291,15.091416,0.768793,0.372907,-260.658386,0.038141,0.000000
32.870003,3.371460,-260.613892,0.007735,0.001482,0.037646,14.997003,0.763984,0.376465,-260.613892,0.038575,0.000000
33.130001,3.361778,-260.658386,0.007769,0.001496,0.037993,14.953937,0.761790,0.379932,-260.658386,0.039008,0.000000
33.390003,3.547966,-260.658386,0.007812,0.001522,0.038652,15.782141,0.803981,0.386525,-260.658386,0.039442,0.000000
33.650002,3.488762,-260.747345,0.007821,0.001535,0.038982,15.518788,0.790565,0.389818,-260.747345,0.039875,0.000000
33.910000,3.472374,-260.569397,0.007834,0.001552,0.039416,15.445890,0.786851,0.394155,-260.569397,0.040309,0.000000
34.170002,3.547218,-260.747345,0.007881,0.001570,0.039867,15.778815,0.803811,0.398667,-260.747345,0.040743,0.000000
34.430000,3.576263,-260.702850,0.007864,0.001589,0.040369,15.908014,0.810393,0.403693,-260.702850,0.041176,0.000000
34.690002,3.491737,-260.702850,0.007907,0.001598,0.040586,15.532023,0.791239,0.405862,-260.702850,0.041610,0.000000
34.950001,3.622810,-260.747345,0.007920,0.001618,0.041107,16.115065,0.820941,0.411066,-260.747345,0.042043,0.000000
35.210003,3.642921,-260.702850,0.007963,0.001638,0.041601,16.204523,0.825498,0.416009,-260.702850,0.042477,0.000000
35.470001,3.645157,-260.747345,0.007989,0.001657,0.042095,16.214468,0.826004,0.420952,-260.747345,0.042910,0.000000
35.730003,3.616112,-260.702850,0.007998,0.001672,0.042477,16.085268,0.819423,0.424767,-260.702850,0.043344,0.000000
35.990002,3.659302,-260.702850,0.008028,0.001689,0.042910,16.277388,0.829210,0.429105,-260.702850,0.043778,0.000000
36.250000,3.714790,-260.747345,0.008041,0.001710,0.043422,16.524212,0.841784,0.434222,-260.747345,0.044211,0.000000
36.510002,3.674576,-260.747345,0.008041,0.001720,0.043700,16.345329,0.832671,0.436996,-260.747345,0.044645,0.000000
36.770000,3.694679,-260.836304,0.008101,0.001736,0.044099,16.434753,0.837226,0.440986,-260.836304,0.045078,0.000000
37.030003,3.794846,-260.791809,0.008101,0.001755,0.044575,16.880316,0.859924,0.445755,-260.791809,0.045512,0.000000
37.290001,3.913261,-260.747345,0.008136,0.001780,0.045200,17.407057,0.886758,0.452000,-260.747345,0.045946,0.000000
37.550003,3.803787,-260.836304,0.008166,0.001794,0.045564,16.920090,0.861951,0.455641,-260.836304,0.046379,0.000000
37.810001,3.813843,-260.791809,0.008166,0.001811,0.045998,16.964821,0.864229,0.459978,-260.791809,0.046813,0.000000
38.070004,3.783302,-260.791809,0.008192,0.001825,0.046362,16.828970,0.857309,0.463619,-260.791809,0.047246,0.000000
38.330002,3.893524,-260.836304,0.008205,0.001844,0.046839,17.319260,0.882285,0.468388,-260.836304,0.047680,0.000000
38.590000,3.877892,-260.791809,0.008209,0.001860,0.047255,17.249723,0.878743,0.472552,-260.791809,0.048105,0.000000
38.850002,3.973961,-260.880768,0.008269,0.001878,0.047706,17.677061,0.900512,0.477063,-260.880768,0.048539,0.000000
39.110001,4.011566,-260.836304,0.008278,0.001898,0.048209,17.844337,0.909034,0.482093,-260.836304,0.048972,0.000000
39.370003,4.029816,-260.880768,0.008308,0.001916,0.048660,17.925516,0.913169,0.486601,-260.880768,0.049406,0.000000
39.630001,3.972099,-260.880768,0.008326,0.001930,0.049016,17.668779,0.900091,0.490159,-260.880768,0.049839,0.000000
39.890003,3.954224,-260.836304,0.008338,0.001943,0.049354,17.589266,0.896040,0.493539,-260.836304,0.050273,0.000000
40.150002,4.052155,-260.880768,0.008351,0.001963,0.049866,18.024883,0.918231,0.498656,-260.880768,0.050707,0.000000
40.410004,4.035027,-260.836304,0.008382,0.001977,0.050221,17.948694,0.914350,0.502210,-260.836304,0.051140,0.000000
40.670002,3.976570,-260.880768,0.008399,0.001989,0.050516,17.688667,0.901104,0.505159,-260.880768,0.051574,0.000000
40.930000,4.182861,-260.925262,0.008399,0.002013,0.051123,18.606297,0.947850,0.511230,-260.925262,0.052007,0.000000
41.190002,4.216743,-260.880768,0.008451,0.002034,0.051661,18.757011,0.955528,0.516608,-260.880768,0.052441,0.000000
41.450001,4.185837,-260.880768,0.008472,0.002048,0.052007,18.619532,0.948524,0.520075,-260.880768,0.052875,0.000000
41.710003,4.228287,-260.925262,0.008485,0.002067,0.052502,18.808359,0.958143,0.525022,-260.925262,0.053308,0.000000
41.970001,4.162384,-260.880768,0.008485,0.002079,0.052805,18.515209,0.943210,0.528053,-260.880768,0.053742,0.000000
42.230003,4.299416,-260.925262,0.008528,0.002102,0.053387,19.124756,0.974261,0.533867,-260.925262,0.054176,0.000000
42.490002,4.244675,-260.880768,0.008528,0.002115,0.053725,18.881256,0.961857,0.537247,-260.880768,0.054609,0.000000
42.750004,4.277069,-260.925262,0.008550,0.002133,0.054185,19.025354,0.969198,0.541846,-260.925262,0.055043,0.000000
43.010002,4.312073,-260.925262,0.008593,0.002149,0.054583,19.181057,0.977130,0.545835,-260.925262,0.055477,0.000000
43.270000,4.390274,-260.925262,0.008636,0.002169,0.055104,19.528913,0.994850,0.551035,-260.925262,0.055910,0.000000
43.530003,4.328087,-261.014221,0.008627,0.002185,0.055494,19.252293,0.980758,0.554938,-261.014221,0.056344,0.000000
43.790001,4.312447,-260.880768,0.008658,0.002197,0.055815,19.182720,0.977214,0.558147,-260.880768,0.056778,0.000000
44.050003,4.430115,-260.969727,0.008679,0.002217,0.056309,19.706135,1.003878,0.563090,-260.969727,0.057211,0.000000
44.310001,4.342979,-260.969727,0.008705,0.002231,0.056656,19.318537,0.984133,0.566561,-260.969727,0.057645,0.000000
44.570004,4.354149,-260.969727,0.008714,0.002242,0.056951,19.368221,0.986664,0.569509,-260.969727,0.058078,0.000000
44.830002,4.624123,-261.014221,0.008731,0.002270,0.057662,20.569124,1.047841,0.576621,-261.014221,0.058512,0.000000
45.090004,4.658752,-260.925262,0.008770,0.002291,0.058182,20.723166,1.055688,0.581822,-260.925262,0.058946,0.000000
45.350002,4.501984,-261.058716,0.008778,0.002302,0.058469,20.025824,1.020164,0.584687,-261.058716,0.059379,0.000000
45.610001,4.554863,-260.969727,0.008791,0.002319,0.058893,20.261042,1.032147,0.588933,-260.969727,0.059813,0.000000
45.870003,4.585022,-260.969727,0.008830,0.002337,0.059362,20.395197,1.038981,0.593619,-260.969727,0.060246,0.000000
46.130001,4.667686,-261.058716,0.008852,0.002352,0.059752,20.762907,1.057713,0.597521,-261.058716,0.060680,0.000000
46.390003,4.557838,-261.014221,0.008873,0.002364,0.060038,20.274279,1.032821,0.600383,-261.014221,0.061114,0.000000
46.650002,4.792061,-261.058716,0.008869,0.002386,0.060593,21.316151,1.085896,0.605931,-261.058716,0.061547,0.000000
46.910004,4.856483,-261.014221,0.008912,0.002406,0.061122,21.602716,1.100495,0.611223,-261.014221,0.061981,0.000000
47.170002,4.830788,-261.014221,0.008946,0.002423,0.061547,21.488417,1.094672,0.615473,-261.014221,0.062414,0.000000
47.430004,4.732483,-261.103180,0.008951,0.002437,0.061903,21.051136,1.072396,0.619027,-261.103180,0.062839,0.000000
47.690002,4.741051,-261.014221,0.008968,0.002453,0.062302,21.089247,1.074337,0.623016,-261.014221,0.063273,0.000000
47.950001,4.861694,-261.058716,0.008998,0.002472,0.062796,21.625896,1.101676,0.627959,-261.058716,0.063707,0.000000
48.210003,4.866165,-261.103180,0.009011,0.002486,0.063151,21.645784,1.102689,0.631514,-261.103180,0.064140,0.000000
48.470001,4.762276,-261.058716,0.009046,0.002499,0.063464,21.183661,1.079147,0.634636,-261.058716,0.064574,0.000000
48.730003,4.991280,-261.103180,0.009041,0.002520,0.064001,22.202320,1.131040,0.640014,-261.103180,0.065007,0.000000
48.990002,5.103737,-261.147675,0.009063,0.002541,0.064548,22.702555,1.156523,0.645476,-261.147675,0.065441,0.000000
49.250004,5.043411,-261.103180,0.009097,0.002556,0.064929,22.434214,1.142853,0.649295,-261.103180,0.065875,0.000000
49.510002,4.972290,-261.058716,0.009106,0.002573,0.065363,22.117851,1.126737,0.653629,-261.058716,0.066308,0.000000
49.770000,5.085495,-261.103180,0.009145,0.002589,0.065762,22.621412,1.152390,0.657618,-261.103180,0.066742,0.000000
50.030003,5.194221,-261.147675,0.009158,0.002609,0.066265,23.105051,1.177027,0.662648,-261.147675,0.067175,0.000000
50.290001,4.993889,-261.058716,0.009179,0.002618,0.066508,22.213926,1.131631,0.665078,-261.058716,0.067609,0.000000
50.550003,5.194969,-261.147675,0.009196,0.002640,0.067054,23.108377,1.177197,0.670540,-261.147675,0.068043,0.000000
50.810001,5.378548,-261.103180,0.009218,0.002663,0.067644,23.924974,1.218796,0.676436,-261.103180,0.068476,0.000000
51.070004,5.313759,-261.147675,0.009253,0.002678,0.068025,23.636780,1.204115,0.680252,-261.147675,0.068910,0.000000
51.330002,5.335350,-261.192139,0.009261,0.002694,0.068433,23.732822,1.209008,0.684328,-261.192139,0.069343,0.000000
51.590004,5.305939,-261.192139,0.009296,0.002711,0.068849,23.601994,1.202343,0.688491,-261.192139,0.069777,0.000000
51.850002,5.494354,-261.147675,0.009309,0.002727,0.069274,24.440109,1.245039,0.692742,-261.147675,0.070211,0.000000
52.110001,5.362534,-261.147675,0.009352,0.002740,0.069586,23.853741,1.215167,0.695864,-261.147675,0.070644,0.000000
52.370003,5.508133,-261.147675,0.009360,0.002758,0.070046,24.501398,1.248161,0.700459,-261.147675,0.071078,0.000000
52.630001,5.757248,-261.236633,0.009378,0.002779,0.070584,25.609518,1.304611,0.705837,-261.236633,0.071511,0.000000
52.890003,5.828751,-261.147675,0.009412,0.002802,0.071165,25.927578,1.320814,0.711647,-261.147675,0.071945,0.000000
53.150002,5.668625,-261.192139,0.009412,0.002816,0.071529,25.215303,1.284529,0.715288,-261.192139,0.072379,0.000000
53.410004,5.656708,-261.236633,0.009447,0.002832,0.071945,25.162292,1.281828,0.719452,-261.236633,0.072812,0.000000
53.670002,5.772148,-261.192139,0.009459,0.002851,0.072413,25.675797,1.307987,0.724134,-261.192139,0.073246,0.000000
53.930004,5.908066,-261.281097,0.009485,0.002866,0.072804,26.280390,1.338787,0.728036,-261.281097,0.073680,0.000000
54.190002,5.808266,-261.192139,0.009494,0.002877,0.073081,25.836456,1.316172,0.730814,-261.192139,0.074113,0.000000
54.450001,5.870453,-261.236633,0.009507,0.002892,0.073454,26.113079,1.330264,0.734542,-261.236633,0.074547,0.000000
54.710003,6.315437,-261.236633,0.009516,0.002918,0.074122,28.092468,1.431099,0.741219,-261.236633,0.074981,0.000000
54.970001,6.223831,-261.236633,0.009559,0.002933,0.074503,27.684984,1.410340,0.745034,-261.236633,0.075414,0.000000
55.230003,6.247665,-261.325592,0.009580,0.002951,0.074946,27.791004,1.415741,0.749458,-261.325592,0.075848,0.000000
55.490002,6.439438,-261.236633,0.009589,0.002969,0.075423,28.644051,1.459198,0.754227,-261.236633,0.076281,0.000000
55.750004,6.529182,-261.281097,0.009610,0.002989,0.075908,29.043255,1.479534,0.759083,-261.281097,0.076715,0.000000
56.010002,6.434967,-261.281097,0.009615,0.002999,0.076169,28.624163,1.458184,0.761687,-261.281097,0.077149,0.000000
56.270004,6.659882,-261.281097,0.009666,0.003017,0.076628,29.624634,1.509151,0.766282,-261.281097,0.077582,0.000000
56.530003,6.804733,-261.370056,0.009666,0.003036,0.077123,30.268965,1.541975,0.771225,-261.370056,0.078007,0.000000
56.790001,6.904907,-261.281097,0.009688,0.003056,0.077634,30.714561,1.564674,0.776343,-261.281097,0.078441,0.000000
57.050003,6.929855,-261.281097,0.009710,0.003073,0.078042,30.825537,1.570328,0.780419,-261.281097,0.078874,0.000000
57.310001,7.056831,-261.370056,0.009731,0.003088,0.078432,31.390354,1.599101,0.784321,-261.370056,0.079308,0.000000
57.570004,7.318237,-261.281097,0.009757,0.003108,0.078944,32.553146,1.658336,0.789438,-261.281097,0.079742,0.000000
57.830002,7.131676,-261.414551,0.009757,0.003117,0.079178,31.723278,1.616061,0.791777,-261.414551,0.080175,0.000000
58.090004,7.286217,-261.370056,0.009804,0.003135,0.079629,32.410709,1.651080,0.796289,-261.370056,0.080609,0.000000
58.350002,7.578522,-261.281097,0.009787,0.003153,0.080080,33.710949,1.717318,0.800797,-261.281097,0.081043,0.000000
58.610004,8.025002,-261.370056,0.009822,0.003178,0.080730,35.696991,1.818491,0.807303,-261.370056,0.081476,0.000000
58.870003,7.858925,-261.281097,0.009830,0.003192,0.081068,34.958244,1.780858,0.810683,-261.281097,0.081910,0.000000
59.130001,7.965790,-261.325592,0.009848,0.003210,0.081528,35.433601,1.805074,0.815282,-261.325592,0.082343,0.000000
59.390003,7.965050,-261.325592,0.009860,0.003222,0.081849,35.430309,1.804906,0.818487,-261.325592,0.082777,0.000000
59.650002,8.316940,-261.370056,0.009895,0.003243,0.082360,36.995598,1.884646,0.823605,-261.370056,0.083211,0.000000
59.910004,8.395882,-261.370056,0.009916,0.003259,0.082777,37.346748,1.902534,0.827768,-261.370056,0.083644,0.000000
60.170002,8.676651,-261.414551,0.009951,0.003276,0.083219,38.595673,1.966157,0.832192,-261.414551,0.084078,0.000000
60.430004,9.028542,-261.459045,0.009947,0.003296,0.083731,40.160957,2.045897,0.837310,-261.459045,0.084511,0.000000
60.690002,9.140625,-261.370056,0.009994,0.003314,0.084173,40.659531,2.071295,0.841730,-261.370056,0.084945,0.000000
60.950005,9.173767,-261.414551,0.010024,0.003328,0.084537,40.806953,2.078805,0.845371,-261.414551,0.085379,0.000000
61.210003,9.249733,-261.503510,0.010011,0.003342,0.084884,41.144867,2.096020,0.848842,-261.503510,0.085812,0.000000
61.470001,9.674606,-261.459045,0.010016,0.003363,0.085413,43.034798,2.192297,0.854133,-261.459045,0.086246,0.000000
61.730003,9.753181,-261.503510,0.010059,0.003377,0.085769,43.384319,2.210103,0.857687,-261.503510,0.086679,0.000000
61.990002,9.734932,-261.459045,0.010063,0.003388,0.086064,43.303139,2.205967,0.860636,-261.459045,0.087113,0.000000
62.250004,10.324776,-261.503510,0.010085,0.003413,0.086679,45.926895,2.339628,0.866794,-261.503510,0.087547,0.000000
62.510002,10.691185,-261.503510,0.010093,0.003433,0.087191,47.556767,2.422657,0.871911,-261.503510,0.087980,0.000000
62.770004,10.812584,-261.459045,0.010123,0.003446,0.087529,48.096775,2.450166,0.875291,-261.459045,0.088414,0.000000
63.030003,11.157394,-261.503510,0.010132,0.003467,0.088050,49.630569,2.528302,0.880495,-261.503510,0.088847,0.000000
63.290005,11.162239,-261.548004,0.010141,0.003478,0.088344,49.652119,2.529400,0.883444,-261.548004,0.089281,0.000000
63.550003,11.801971,-261.459045,0.010179,0.003502,0.088951,52.497791,2.674365,0.889515,-261.459045,0.089714,0.000000
63.810001,11.766228,-261.548004,0.010175,0.003514,0.089246,52.338795,2.666265,0.892463,-261.548004,0.090148,0.000000
64.070000,11.978851,-261.548004,0.010214,0.003527,0.089593,53.284592,2.714447,0.895934,-261.548004,0.090582,0.000000
64.330002,12.501289,-261.548004,0.010240,0.003547,0.090096,55.608513,2.832833,0.900964,-261.548004,0.091015,0.000000
64.590004,13.040855,-261.548004,0.010231,0.003567,0.090608,58.008621,2.955100,0.906077,-261.548004,0.091449,0.000000
64.850006,13.104904,-261.503510,0.010266,0.003581,0.090964,58.293526,2.969614,0.909635,-261.503510,0.091883,0.000000
65.110001,13.336151,-261.592468,0.010244,0.003595,0.091310,59.322163,3.022015,0.913102,-261.592468,0.092316,0.000000
65.370003,13.979233,-261.548004,0.010279,0.003615,0.091822,62.182732,3.167739,0.918219,-261.548004,0.092750,0.000000
65.630005,14.060783,-261.548004,0.010300,0.003626,0.092108,62.545486,3.186219,0.921081,-261.548004,0.093175,0.000000
65.889999,14.376556,-261.548004,0.010305,0.003643,0.092533,63.950115,3.257774,0.925331,-261.548004,0.093608,0.000000
66.150002,15.303017,-261.503510,0.010317,0.003667,0.093149,68.071220,3.467713,0.931489,-261.503510,0.094042,0.000000
66.410004,16.119263,-261.636963,0.010322,0.003689,0.093712,71.702065,3.652677,0.937125,-261.636963,0.094476,0.000000
66.670006,16.039574,-261.548004,0.010356,0.003700,0.093990,71.347588,3.634619,0.939899,-261.548004,0.094909,0.000000
66.930000,16.331139,-261.592468,0.010352,0.003716,0.094398,72.644531,3.700689,0.943976,-261.592468,0.095343,0.000000
67.190002,16.426094,-261.548004,0.010369,0.003726,0.094641,73.066917,3.722206,0.946405,-261.548004,0.095776,0.000000
67.450005,17.618431,-261.636963,0.010417,0.003751,0.095273,78.370697,3.992393,0.952734,-261.636963,0.096210,0.000000
67.710007,17.779297,-261.636963,0.010404,0.003762,0.095560,79.086266,4.028846,0.955599,-261.636963,0.096644,0.000000
67.970001,18.518829,-261.592468,0.010408,0.003783,0.096089,82.375870,4.196427,0.960886,-261.592468,0.097077,0.000000
68.230003,19.180534,-261.636963,0.010421,0.003804,0.096609,85.319275,4.346371,0.966091,-261.636963,0.097511,0.000000
68.490005,20.052628,-261.636963,0.010451,0.003821,0.097060,89.198540,4.543990,0.970602,-261.636963,0.097945,0.000000
68.750000,20.266373,-261.592468,0.010460,0.003835,0.097398,90.149330,4.592426,0.973982,-261.592468,0.098378,0.000000
69.010002,20.640976,-261.636963,0.010468,0.003850,0.097780,91.815643,4.677312,0.977797,-261.636963,0.098812,0.000000
69.270004,21.413651,-261.592468,0.010490,0.003866,0.098205,95.252678,4.852402,0.982048,-261.592468,0.099246,0.000000
69.530006,22.237709,-261.636963,0.010494,0.003885,0.098673,98.918274,5.039137,0.986730,-261.636963,0.099679,0.000000
69.790001,22.277931,-261.725922,0.010499,0.003895,0.098942,99.097191,5.048251,0.989421,-261.725922,0.100113,0.000000
70.050003,23.635971,-261.681427,0.010511,0.003919,0.099532,105.138054,5.355988,0.995318,-261.681427,0.100546,0.000000
70.310005,24.422791,-261.681427,0.010542,0.003939,0.100043,108.638000,5.534283,1.000435,-261.681427,0.100980,0.000000
70.570000,24.865173,-261.681427,0.010542,0.003953,0.100416,110.605812,5.634529,1.004163,-261.681427,0.101414,0.000000
70.830002,25.799454,-261.725922,0.010559,0.003969,0.100807,114.761703,5.846240,1.008065,-261.725922,0.101847,0.000000
71.090004,26.536751,-261.681427,0.010572,0.003987,0.101257,118.041367,6.013313,1.012573,-261.681427,0.102281,0.000000
71.350006,27.594666,-261.681427,0.010598,0.004005,0.101726,122.747200,6.253041,1.017259,-261.681427,0.102714,0.000000
71.610001,27.792023,-261.725922,0.010593,0.004015,0.101986,123.625092,6.297762,1.019859,-261.725922,0.103148,0.000000
71.870003,28.922173,-261.681427,0.010611,0.004037,0.102532,128.652252,6.553858,1.025324,-261.681427,0.103582,0.000000
72.130005,30.353943,-261.770386,0.010641,0.004059,0.103096,135.021088,6.878302,1.030960,-261.770386,0.104015,0.000000
72.390007,31.049164,-261.770386,0.010615,0.004073,0.103451,138.113571,7.035841,1.034514,-261.770386,0.104449,0.000000
72.650002,31.690384,-261.681427,0.010649,0.004091,0.103903,140.965866,7.181144,1.039026,-261.681427,0.104882,0.000000
72.910004,32.505882,-261.770386,0.010645,0.004104,0.104232,144.593384,7.365938,1.042318,-261.770386,0.105316,0.000000
73.170006,33.900421,-261.770386,0.010654,0.004125,0.104787,150.796600,7.681945,1.047871,-261.770386,0.105750,0.000000
73.430000,34.596382,-261.725922,0.010667,0.004138,0.105117,153.892395,7.839652,1.051167,-261.725922,0.106183,0.000000
73.690002,35.354904,-261.814880,0.010654,0.004153,0.105490,157.266464,8.011536,1.054896,-261.814880,0.106617,0.000000
73.950005,36.566605,-261.770386,0.010675,0.004172,0.105958,162.656387,8.286111,1.059578,-261.770386,0.107050,0.000000
74.210007,38.629173,-261.859344,0.010693,0.004199,0.106643,171.831146,8.753496,1.066428,-261.859344,0.107484,0.000000
74.470001,39.099106,-261.725922,0.010693,0.004212,0.106972,173.921509,8.859984,1.069725,-261.725922,0.107909,0.000000
74.730003,40.438904,-261.814880,0.010701,0.004230,0.107432,179.881226,9.163586,1.074320,-261.814880,0.108343,0.000000
74.990005,41.576134,-261.814880,0.010727,0.004246,0.107848,184.939880,9.421287,1.078483,-261.814880,0.108776,0.000000
75.250000,42.669418,-261.859344,0.010740,0.004263,0.108273,189.803055,9.669028,1.082734,-261.859344,0.109210,0.000000
75.510002,43.338943,-261.859344,0.010740,0.004276,0.108603,192.781250,9.820745,1.086026,-261.859344,0.109643,0.000000
75.770004,44.228912,-261.814880,0.010710,0.004287,0.108898,196.740021,10.022415,1.088979,-261.814880,0.110077,0.000000
76.030006,46.296326,-261.725922,0.010762,0.004314,0.109583,205.936340,10.490897,1.095829,-261.725922,0.110511,0.000000
76.290001,47.494995,-261.859344,0.010749,0.004330,0.109982,211.268295,10.762520,1.099819,-261.859344,0.110944,0.000000
76.550003,48.479172,-261.859344,0.010753,0.004345,0.110372,215.646133,10.985538,1.103721,-261.859344,0.111378,0.000000
76.810005,49.784706,-261.859344,0.010749,0.004366,0.110884,221.453430,11.281376,1.108838,-261.859344,0.111811,0.000000
77.070007,51.172913,-261.903839,0.010774,0.004380,0.111248,227.628479,11.595948,1.112479,-261.903839,0.112245,0.000000
77.330002,52.280724,-261.859344,0.010774,0.004395,0.111621,232.556274,11.846981,1.116207,-261.859344,0.112679,0.000000
77.590004,53.342354,-261.903839,0.010779,0.004412,0.112072,237.278641,12.087550,1.120719,-261.903839,0.113112,0.000000
77.850006,55.246300,-261.903839,0.010779,0.004432,0.112583,245.747818,12.518990,1.125832,-261.903839,0.113546,0.000000
78.110001,56.692963,-261.948334,0.010809,0.004449,0.113017,252.182892,12.846808,1.130170,-261.948334,0.113979,0.000000
78.370003,57.847321,-261.948334,0.010813,0.004464,0.113390,257.317719,13.108391,1.133898,-261.948334,0.114413,0.000000
78.630005,59.390427,-261.903839,0.010800,0.004484,0.113884,264.181824,13.458063,1.138841,-261.903839,0.114847,0.000000
78.890007,60.554092,-261.948334,0.010805,0.004501,0.114327,269.358063,13.721753,1.143265,-261.948334,0.115280,0.000000
79.150002,61.945274,-261.903839,0.010813,0.004515,0.114673,275.546356,14.037000,1.146732,-261.903839,0.115714,0.000000
79.410004,63.076912,-261.992798,0.010826,0.004530,0.115064,280.580109,14.293432,1.150638,-261.992798,0.116148,0.000000
79.670006,64.431236,-261.948334,0.010843,0.004549,0.115532,286.604462,14.600327,1.155320,-261.948334,0.116581,0.000000
79.930000,66.508705,-261.903839,0.010831,0.004570,0.116087,295.845490,15.071088,1.160869,-261.903839,0.117015,0.000000
80.190002,67.218437,-261.948334,0.010831,0.004571,0.116096,299.002533,15.231915,1.160956,-261.948334,0.116304,0.000000
80.450005,66.795433,-261.948334,0.010835,0.004570,0.116087,297.120911,15.136061,1.160869,-261.948334,0.116087,0.000000
80.710007,66.431618,-261.992798,0.010835,0.004570,0.116069,295.502594,15.053619,1.160695,-261.992798,0.116087,0.000000
80.970001,66.108772,-261.948334,0.010835,0.004569,0.116061,294.066498,14.980462,1.160608,-261.948334,0.116087,0.000000
81.230003,65.840660,-261.992798,0.010839,0.004569,0.116052,292.873871,14.919706,1.160524,-261.992798,0.116087,0.000000
81.490005,65.596382,-262.037292,0.010839,0.004569,0.116052,291.787292,14.864352,1.160524,-262.037292,0.116087,0.000000
81.750008,65.387856,-261.992798,0.010843,0.004569,0.116052,290.859711,14.817100,1.160524,-261.992798,0.116087,0.000000
82.010002,65.190132,-261.992798,0.010861,0.004569,0.116044,289.980194,14.772295,1.160437,-261.992798,0.116087,0.000000
82.270004,65.013634,-261.948334,0.010835,0.004569,0.116044,289.195099,14.732300,1.160437,-261.948334,0.116087,0.000000
82.530006,64.863182,-261.948334,0.010861,0.004569,0.116044,288.525848,14.698207,1.160437,-261.948334,0.116087,0.000000
82.790001,64.710884,-262.037292,0.010848,0.004569,0.116044,287.848389,14.663696,1.160437,-262.037292,0.116087,0.000000
83.050003,64.578316,-261.992798,0.010848,0.004569,0.116044,287.258698,14.633656,1.160437,-261.992798,0.116087,0.000000
83.310005,64.455437,-262.037292,0.010839,0.004568,0.116035,286.712097,14.605810,1.160350,-262.037292,0.116087,0.000000
83.570007,64.351555,-262.037292,0.010874,0.004568,0.116035,286.250000,14.582271,1.160350,-262.037292,0.116087,0.000000
83.830002,64.238350,-261.992798,0.010839,0.004568,0.116035,285.746460,14.556618,1.160350,-261.992798,0.116087,0.000000
84.090004,64.141899,-262.037292,0.010848,0.004568,0.116035,285.317413,14.534761,1.160350,-262.037292,0.116087,0.000000
84.350006,64.046196,-261.992798,0.010843,0.004568,0.116035,284.891693,14.513075,1.160350,-261.992798,0.116087,0.000000
84.610001,63.947899,-262.037292,0.010869,0.004568,0.116035,284.454468,14.490801,1.160350,-262.037292,0.116087,0.000000
84.870003,63.864113,-262.081757,0.010843,0.004568,0.116035,284.081757,14.471815,1.160350,-262.081757,0.116087,0.000000
85.130005,63.791496,-262.037292,0.010865,0.004568,0.116035,283.758759,14.455359,1.160350,-262.037292,0.116087,0.000000
85.390007,63.705482,-262.126251,0.010861,0.004568,0.116035,283.376129,14.435868,1.160350,-262.126251,0.116087,0.000000
85.650002,63.643669,-262.037292,0.010843,0.004568,0.116035,283.101166,14.421862,1.160350,-262.037292,0.116087,0.000000
85.910004,63.572548,-262.081757,0.010848,0.004568,0.116035,282.784821,14.405746,1.160350,-262.081757,0.116087,0.000000
86.170006,63.510353,-262.126251,0.010856,0.004568,0.116035,282.508148,14.391651,1.160350,-262.126251,0.116087,0.000000
86.430000,63.448921,-262.081757,0.010874,0.004568,0.116035,282.234894,14.377731,1.160350,-262.081757,0.116087,0.000000
86.690002,63.376305,-262.081757,0.010874,0.004568,0.116035,281.911896,14.361276,1.160350,-262.081757,0.116087,0.000000
86.950005,63.326408,-262.126251,0.010865,0.004568,0.116035,281.689941,14.349970,1.160350,-262.126251,0.116087,0.000000
87.210007,63.263481,-262.170715,0.010874,0.004568,0.116035,281.410004,14.335711,1.160350,-262.170715,0.116087,0.000000
87.470001,63.213951,-262.081757,0.010856,0.004568,0.116035,281.189697,14.324486,1.160350,-262.081757,0.116087,0.000000
87.730003,63.158836,-262.126251,0.010856,0.004568,0.116035,280.944550,14.311996,1.160350,-262.126251,0.116087,0.000000
87.990005,63.108940,-262.170715,0.010856,0.004568,0.116035,280.722595,14.300691,1.160350,-262.170715,0.116087,0.000000
88.250008,63.058296,-262.081757,0.010843,0.004568,0.116035,280.497314,14.289214,1.160350,-262.081757,0.116087,0.000000
88.510002,63.022552,-262.126251,0.010839,0.004568,0.116035,280.338318,14.281115,1.160350,-262.126251,0.116087,0.000000
88.770004,62.966698,-262.170715,0.010852,0.004568,0.116035,280.089874,14.268457,1.160350,-262.170715,0.116087,0.000000
89.030006,62.938766,-262.170715,0.010835,0.004568,0.116035,279.965607,14.262128,1.160350,-262.170715,0.116087,0.000000
89.290001,62.881050,-262.215210,0.010878,0.004568,0.116035,279.708893,14.249049,1.160350,-262.215210,0.116087,0.000000
89.550003,62.843811,-262.170715,0.010861,0.004568,0.116035,279.543243,14.240611,1.160350,-262.170715,0.116087,0.000000
89.810005,62.813652,-262.170715,0.010869,0.004568,0.116035,279.409088,14.233777,1.160350,-262.170715,0.116087,0.000000
90.070007,62.770454,-262.170715,0.010848,0.004568,0.116035,279.216919,14.223989,1.160350,-262.170715,0.116087,0.000000
90.330002,62.739548,-262.126251,0.010874,0.004568,0.116035,279.079437,14.216985,1.160350,-262.126251,0.116087,0.000000
90.590004,62.702309,-262.259674,0.010861,0.004568,0.116035,278.913788,14.208547,1.160350,-262.259674,0.116087,0.000000
90.850006,62.652412,-262.170715,0.010843,0.004568,0.116035,278.691864,14.197240,1.160350,-262.170715,0.116087,0.000000
91.110001,62.633423,-262.126251,0.010843,0.004568,0.116035,278.607391,14.192937,1.160350,-262.126251,0.116087,0.000000
91.370003,62.580917,-262.170715,0.010835,0.004568,0.116035,278.373810,14.181039,1.160350,-262.170715,0.116087,0.000000
91.630005,62.561180,-262.126251,0.010882,0.004568,0.116026,278.286041,14.176566,1.160263,-262.126251,0.116087,0.000000
91.890007,62.528412,-262.304169,0.010852,0.004568,0.116026,278.140259,14.169141,1.160263,-262.304169,0.116087,0.000000
92.150002,62.491920,-262.215210,0.010865,0.004568,0.116026,277.977936,14.160872,1.160263,-262.215210,0.116087,0.000000
92.410004,62.472557,-262.215210,0.010856,0.004568,0.116026,277.891815,14.156485,1.160263,-262.215210,0.116087,0.000000
92.670006,62.433083,-262.259674,0.010874,0.004568,0.116026,277.716217,14.147538,1.160263,-262.259674,0.116087,0.000000
92.930008,62.400314,-262.259674,0.010852,0.004568,0.116026,277.570465,14.140113,1.160263,-262.259674,0.116087,0.000000
93.190002,62.375366,-262.259674,0.010852,0.004568,0.116026,277.459473,14.134460,1.160263,-262.259674,0.116087,0.000000
93.450005,62.344833,-262.304169,0.010869,0.004568,0.116026,277.323669,14.127542,1.160263,-262.304169,0.116087,0.000000
93.710007,62.325470,-262.259674,0.010874,0.004568,0.116026,277.237549,14.123154,1.160263,-262.259674,0.116087,0.000000
93.970001,62.284882,-262.304169,0.010852,0.004568,0.116026,277.056976,14.113955,1.160263,-262.304169,0.116087,0.000000
94.230003,62.271851,-262.259674,0.010878,0.004568,0.116026,276.999023,14.111003,1.160263,-262.259674,0.116087,0.000000
94.490005,62.237587,-262.348663,0.010891,0.004568,0.116026,276.846619,14.103238,1.160263,-262.348663,0.116087,0.000000
94.750008,62.196632,-262.304169,0.010878,0.004568,0.116026,276.664429,14.093959,1.160263,-262.304169,0.116087,0.000000
95.010002,62.185829,-262.304169,0.010852,0.004568,0.116026,276.616394,14.091510,1.160263,-262.304169,0.116087,0.000000
95.270004,62.157906,-262.348663,0.010848,0.004568,0.116026,276.492187,14.085182,1.160263,-262.348663,0.116087,0.000000
95.530006,62.134445,-262.304169,0.010874,0.004568,0.116026,276.387817,14.079867,1.160263,-262.304169,0.116087,0.000000
95.790001,62.106514,-262.348663,0.010874,0.004568,0.116026,276.263580,14.073538,1.160263,-262.348663,0.116087,0.000000
96.050003,62.086777,-262.304169,0.010882,0.004568,0.116026,276.175781,14.069064,1.160263,-262.304169,0.116087,0.000000
96.310005,62.071884,-262.348663,0.010869,0.004568,0.116026,276.109528,14.065690,1.160263,-262.348663,0.116087,0.000000
96.570007,62.048050,-262.437622,0.010882,0.004568,0.116026,276.003510,14.060289,1.160263,-262.437622,0.116087,0.000000
96.830002,62.021988,-262.348663,0.010852,0.004568,0.116026,275.887573,14.054384,1.160263,-262.348663,0.116087,0.000000
97.090004,62.009697,-262.393127,0.010861,0.004568,0.116026,275.832916,14.051599,1.160263,-262.393127,0.116087,0.000000
97.350006,61.986610,-262.348663,0.010878,0.004568,0.116026,275.730225,14.046367,1.160263,-262.348663,0.116087,0.000000
97.610008,61.963524,-262.348663,0.010856,0.004568,0.116026,275.627533,14.041135,1.160263,-262.348663,0.116087,0.000000
97.870003,61.938202,-262.348663,0.010852,0.004568,0.116026,275.514893,14.035398,1.160263,-262.348663,0.116087,0.000000
98.130005,61.932243,-262.348663,0.010865,0.004568,0.116026,275.488373,14.034047,1.160263,-262.348663,0.116087,0.000000
98.390007,61.897240,-262.437622,0.010861,0.004568,0.116026,275.332672,14.026114,1.160263,-262.437622,0.116087,0.000000
98.650002,61.879738,-262.393127,0.010869,0.004568,0.116026,275.254822,14.022149,1.160263,-262.393127,0.116087,0.000000
98.910004,61.870056,-262.437622,0.010878,0.004568,0.116026,275.211761,14.019955,1.160263,-262.437622,0.116087,0.000000
99.170006,61.846230,-262.437622,0.010869,0.004568,0.116026,275.105774,14.014556,1.160263,-262.437622,0.116087,0.000000
99.430008,61.825005,-262.437622,0.010856,0.004568,0.116026,275.011353,14.009747,1.160263,-262.437622,0.116087,0.000000
99.690002,61.819412,-262.393127,0.010865,0.004568,0.116026,274.986481,14.008479,1.160263,-262.393127,0.116087,0.000000
99.950005,61.807503,-262.482086,0.010869,0.004568,0.116026,274.933502,14.005781,1.160263,-262.482086,0.116087,0.000000
100.210007,61.763931,-262.437622,0.010882,0.004568,0.116026,274.739685,13.995907,1.160263,-262.437622,0.116087,0.000000
100.470001,61.772865,-262.482086,0.010882,0.004568,0.116026,274.779419,13.997931,1.160263,-262.482086,0.116087,0.000000
100.730003,61.737122,-262.437622,0.010874,0.004568,0.116026,274.620422,13.989832,1.160263,-262.437622,0.116087,0.000000
100.990005,61.736374,-262.437622,0.010878,0.004568,0.116026,274.617096,13.989662,1.160263,-262.437622,0.116087,0.000000
101.250008,61.710312,-262.482086,0.010869,0.004568,0.116026,274.501190,13.983756,1.160263,-262.482086,0.116087,0.000000
101.510002,61.683502,-262.482086,0.010887,0.004568,0.116026,274.381927,13.977681,1.160263,-262.482086,0.116087,0.000000
101.770004,61.682007,-262.526581,0.010878,0.004568,0.116026,274.375275,13.977343,1.160263,-262.526581,0.116087,0.000000
102.030006,61.655571,-262.482086,0.010869,0.004568,0.116026,274.257690,13.971352,1.160263,-262.482086,0.116087,0.000000
102.290009,61.637695,-262.482086,0.010865,0.004568,0.116026,274.178162,13.967301,1.160263,-262.482086,0.116087,0.000000
102.550003,61.621689,-262.526581,0.010861,0.004568,0.116026,274.106964,13.963675,1.160263,-262.526581,0.116087,0.000000
102.810005,61.609772,-262.482086,0.010887,0.004568,0.116026,274.053955,13.960975,1.160263,-262.482086,0.116087,0.000000
103.070007,61.590034,-262.571045,0.010861,0.004568,0.116026,273.966156,13.956501,1.160263,-262.571045,0.116087,0.000000
103.330002,61.578117,-262.482086,0.010887,0.004568,0.116026,273.913147,13.953800,1.160263,-262.482086,0.116087,0.000000
103.590004,61.553917,-262.571045,0.010856,0.004568,0.116026,273.805511,13.948318,1.160263,-262.571045,0.116087,0.000000
103.850006,61.550194,-262.526581,0.010904,0.004568,0.116026,273.788940,13.947474,1.160263,-262.526581,0.116087,0.000000
104.110008,61.526733,-262.526581,0.010865,0.004568,0.116026,273.684570,13.942158,1.160263,-262.526581,0.116087,0.000000
104.370003,61.524872,-262.571045,0.010856,0.004568,0.116026,273.676300,13.941735,1.160263,-262.571045,0.116087,0.000000
104.630005,61.508484,-262.482086,0.010878,0.004568,0.116026,273.603394,13.938022,1.160263,-262.482086,0.116087,0.000000
104.890007,61.490982,-262.571045,0.010861,0.004568,0.116026,273.525543,13.934056,1.160263,-262.571045,0.116087,0.000000
105.150002,61.463058,-262.615540,0.010861,0.004568,0.116026,273.401337,13.927728,1.160263,-262.615540,0.116087,0.000000
105.410004,61.463425,-262.571045,0.010869,0.004568,0.116026,273.402954,13.927811,1.160263,-262.571045,0.116087,0.000000
105.670006,61.447784,-262.660004,0.010874,0.004568,0.116026,273.333405,13.924267,1.160263,-262.660004,0.116087,0.000000
105.930008,61.429543,-262.615540,0.010869,0.004568,0.116026,273.252258,13.920134,1.160263,-262.615540,0.116087,0.000000
106.190002,61.415390,-262.615540,0.010874,0.004568,0.116026,273.189301,13.916926,1.160263,-262.615540,0.116087,0.000000
106.450005,61.400871,-262.615540,0.010874,0.004568,0.116026,273.124725,13.913636,1.160263,-262.615540,0.116087,0.000000
106.710007,61.388954,-262.571045,0.010891,0.004568,0.116026,273.071716,13.910935,1.160263,-262.571045,0.116087,0.000000
106.970009,61.377785,-262.704498,0.010874,0.004568,0.116026,273.022034,13.908404,1.160263,-262.704498,0.116087,0.000000
107.230003,61.369217,-262.571045,0.010869,0.004568,0.116026,272.983917,13.906463,1.160263,-262.571045,0.116087,0.000000
107.490005,61.347618,-262.615540,0.010882,0.004568,0.116026,272.887848,13.901568,1.160263,-262.615540,0.116087,0.000000
107.750008,61.344269,-262.704498,0.010874,0.004568,0.116026,272.872925,13.900809,1.160263,-262.704498,0.116087,0.000000
108.010002,61.336449,-262.615540,0.010878,0.004568,0.116026,272.838165,13.899037,1.160263,-262.615540,0.116087,0.000000
108.270004,61.308891,-262.704498,0.010882,0.004568,0.116026,272.715576,13.892794,1.160263,-262.704498,0.116087,0.000000
108.530006,61.312241,-262.615540,0.010878,0.004568,0.116026,272.730469,13.893553,1.160263,-262.615540,0.116087,0.000000
108.790009,61.312241,-262.704498,0.010882,0.004568,0.116026,272.730469,13.893553,1.160263,-262.704498,0.116087,0.000000
109.050003,61.282082,-262.704498,0.010891,0.004568,0.116026,272.596313,13.886719,1.160263,-262.704498,0.116087,0.000000
109.310005,61.269791,-262.660004,0.010869,0.004568,0.116026,272.541626,13.883933,1.160263,-262.660004,0.116087,0.000000
109.570007,61.265701,-262.704498,0.010891,0.004568,0.116026,272.523437,13.883006,1.160263,-262.704498,0.116087,0.000000
109.830002,61.248199,-262.704498,0.010882,0.004568,0.116026,272.445587,13.879041,1.160263,-262.704498,0.116087,0.000000
110.090004,61.248566,-262.748993,0.010878,0.004568,0.116026,272.447235,13.879124,1.160263,-262.748993,0.116087,0.000000
110.350006,61.241867,-262.748993,0.010878,0.004568,0.116026,272.417419,13.877605,1.160263,-262.748993,0.116087,0.000000
110.600006,61.211334,-262.793457,0.010869,0.004568,0.116026,272.281616,13.870687,1.160263,-262.793457,0.116087,0.000000