File: Data/Automembrane/AutoHeating-15wt-1-1_12152023_164942.csv
Time (sec),S:Load (lbs),S:HL1 (DIM),S:LVDT (in),S:Position (in),Ch:Position (mm),Ch:Load (N),Ch:Stress (MPa),Ch:Strain (mm/mm),Ch:HL1 (DIM),Set Point (),Cycles ()
0.110000,-0.010429,-124.902512,0.000017,-0.000000,-0.000000,-0.046392,-0.002363,-0.000000,-124.902512,0.000208,0.000000
0.360000,-0.015266,-124.946991,0.000030,-0.000000,-0.000000,-0.067908,-0.003459,-0.000000,-124.946991,0.000399,0.000000
0.610000,-0.053619,-124.902512,0.000013,0.000138,0.003512,-0.238511,-0.012150,0.035124,-124.902512,0.004562,0.000000
0.860000,-0.000000,-124.946991,0.000168,0.000305,0.007736,-0.000000,-0.000000,0.077359,-124.946991,0.008725,0.000000
1.110000,0.035004,-124.991470,0.000319,0.000457,0.011604,0.155704,0.007932,0.116037,-124.991470,0.012887,0.000000
1.360000,0.008934,-124.946991,0.000500,0.000633,0.016070,0.039741,0.002024,0.160699,-124.946991,0.017067,0.000000
1.610000,-0.000748,-124.946991,0.000668,0.000791,0.020094,-0.003326,-0.000169,0.200936,-124.946991,0.021230,0.000000
1.860000,0.010796,-124.946991,0.000836,0.000955,0.024265,0.048021,0.002446,0.242650,-124.946991,0.025392,0.000000
2.110000,0.013779,-124.946991,0.001018,0.001125,0.028575,0.061291,0.003122,0.285752,-124.946991,0.029555,0.000000
2.360000,-0.016380,-124.991470,0.001190,0.001282,0.032564,-0.072863,-0.003712,0.325645,-124.991470,0.033718,0.000000
2.610000,0.008194,-124.946991,0.001354,0.001452,0.036875,0.036449,0.001857,0.368747,-124.946991,0.037880,0.000000
2.860000,0.005211,-124.902512,0.001505,0.001607,0.040812,0.023179,0.001181,0.408118,-124.902512,0.042043,0.000000
3.110000,-0.026436,-124.991470,0.001699,0.001778,0.045174,-0.117593,-0.005990,0.451739,-124.991470,0.046223,0.000000
3.360000,0.017128,-124.991470,0.001867,0.001939,0.049259,0.076189,0.003881,0.492585,-124.991470,0.050386,0.000000
3.610000,0.046921,-124.991470,0.002035,0.002102,0.053387,0.208714,0.010632,0.533867,-124.991470,0.054549,0.000000
3.860000,0.022346,-125.080437,0.002229,0.002273,0.057723,0.099402,0.005064,0.577227,-125.080437,0.058711,0.000000
4.110000,0.010429,-125.035950,0.002380,0.002435,0.061859,0.046392,0.002363,0.618592,-125.035950,0.062874,0.000000
4.360000,0.019737,-125.035950,0.002531,0.002597,0.065953,0.087796,0.004473,0.659526,-125.035950,0.067037,0.000000
4.610000,0.019363,-125.080437,0.002708,0.002757,0.070029,0.086133,0.004388,0.700285,-125.080437,0.071200,0.000000
4.860000,0.024208,-125.080437,0.002893,0.002922,0.074209,0.107683,0.005486,0.742085,-125.080437,0.075362,0.000000
5.110000,0.100166,-125.080437,0.003078,0.003091,0.078519,0.445562,0.022698,0.785188,-125.080437,0.079542,0.000000
5.360000,0.303108,-125.080437,0.003208,0.003249,0.082534,1.348293,0.068685,0.825342,-125.080437,0.083705,0.000000
5.610000,0.539192,-125.080437,0.003389,0.003421,0.086888,2.398447,0.122183,0.868876,-125.080437,0.087867,0.000000
5.860000,0.597656,-125.035950,0.003475,-0.000008,-0.000191,2.658508,0.135431,-0.001908,-125.035950,-0.000000,0.000000
6.110000,0.557442,-125.080437,0.003471,-0.000008,-0.000208,2.479625,0.126318,-0.002082,-125.080437,-0.000000,0.000000
6.360000,0.561539,-125.080437,0.003479,-0.000008,-0.000208,2.497849,0.127246,-0.002082,-125.080437,0.000234,0.000000
6.610000,0.498238,-125.124916,0.003479,-0.000008,-0.000199,2.216272,0.112902,-0.001995,-125.124916,0.000651,0.000000
6.860000,0.480736,-125.124916,0.003484,-0.000008,-0.000199,2.138420,0.108936,-0.001995,-125.124916,0.001067,0.000000
7.110000,0.697456,-125.124916,0.003505,0.000025,0.000633,3.102441,0.158046,0.006332,-125.124916,0.001483,0.000000
7.360000,0.752190,-125.124916,0.003497,0.000041,0.001041,3.345906,0.170449,0.010408,-125.124916,0.001899,0.000000
7.610000,0.812515,-125.124916,0.003523,0.000061,0.001561,3.614248,0.184119,0.015613,-125.124916,0.002316,0.000000
7.860001,0.811401,-125.124916,0.003540,0.000075,0.001899,3.609293,0.183866,0.018993,-125.124916,0.002732,0.000000
8.110001,0.873215,-125.124916,0.003570,0.000089,0.002264,3.884253,0.197873,0.022637,-125.124916,0.003148,0.000000
8.360001,0.903748,-125.213875,0.003570,0.000103,0.002619,4.020070,0.204792,0.026191,-125.213875,0.003564,0.000000
8.610001,1.000565,-125.213875,0.003596,0.000124,0.003157,4.450734,0.226731,0.031570,-125.213875,0.003989,0.000000
8.860001,1.040779,-125.124916,0.003604,0.000141,0.003573,4.629617,0.235844,0.035729,-125.124916,0.004406,0.000000
9.110001,1.119728,-125.169395,0.003613,0.000154,0.003911,4.980799,0.253734,0.039113,-125.169395,0.004822,0.000000
9.360001,1.178558,-125.169395,0.003639,0.000171,0.004345,5.242489,0.267065,0.043451,-125.169395,0.005238,0.000000
9.610001,1.222130,-125.169395,0.003643,0.000187,0.004753,5.436305,0.276939,0.047527,-125.169395,0.005654,0.000000
9.860001,1.251915,-125.213875,0.003669,0.000206,0.005221,5.568796,0.283688,0.052209,-125.213875,0.006071,0.000000
10.110001,1.305542,-125.258362,0.003682,0.000220,0.005585,5.807341,0.295840,0.055850,-125.258362,0.006487,0.000000
10.360001,1.419853,-125.258362,0.003686,0.000237,0.006027,6.315823,0.321743,0.060274,-125.258362,0.006903,0.000000
10.610001,1.477943,-125.302841,0.003717,0.000255,0.006487,6.574221,0.334907,0.064869,-125.302841,0.007320,0.000000
10.860001,1.485397,-125.258362,0.003738,0.000267,0.006782,6.607378,0.336596,0.067818,-125.258362,0.007736,0.000000
11.110001,1.532310,-125.213875,0.003751,0.000280,0.007120,6.816058,0.347227,0.071201,-125.213875,0.008152,0.000000
11.360001,1.687218,-125.258362,0.003786,0.000301,0.007649,7.505119,0.382329,0.076489,-125.258362,0.008568,0.000000
11.610001,1.730415,-125.302841,0.003777,0.000319,0.008109,7.697272,0.392118,0.081088,-125.302841,0.008985,0.000000
11.860001,1.785530,-125.258362,0.003781,0.000336,0.008542,7.942434,0.404607,0.085421,-125.258362,0.009401,0.000000
12.110001,1.861115,-125.302841,0.003803,0.000353,0.008976,8.278651,0.421735,0.089759,-125.302841,0.009817,0.000000
12.360001,1.944901,-125.347321,0.003829,0.000368,0.009357,8.651350,0.440721,0.093574,-125.347321,0.010233,0.000000
12.610001,2.023102,-125.302841,0.003837,0.000387,0.009834,8.999207,0.458441,0.098343,-125.302841,0.010650,0.000000
12.860001,1.980278,-125.302841,0.003863,0.000394,0.010017,8.808717,0.448737,0.100167,-125.302841,0.011066,0.000000
13.110001,2.208168,-125.347321,0.003880,0.000419,0.010650,9.822422,0.500378,0.106496,-125.347321,0.011482,0.000000
13.360001,2.258812,-125.347321,0.003898,0.000437,0.011109,10.047697,0.511854,0.111094,-125.347321,0.011899,0.000000
13.610001,2.302750,-125.391800,0.003898,0.000451,0.011465,10.243142,0.521811,0.114648,-125.391800,0.012323,0.000000
13.860001,2.372009,-125.391800,0.003919,0.000467,0.011864,10.551225,0.537505,0.118638,-125.391800,0.012740,0.000000
14.110001,2.376854,-125.347321,0.003923,0.000478,0.012150,10.572774,0.538603,0.121499,-125.347321,0.013156,0.000000
14.360001,2.507927,-125.347321,0.003941,0.000495,0.012584,11.155816,0.568304,0.125836,-125.347321,0.013572,0.000000
14.610001,2.594322,-125.302841,0.003975,0.000512,0.013000,11.540121,0.587882,0.130000,-125.302841,0.013989,0.000000
14.860001,2.634911,-125.347321,0.003988,0.000525,0.013338,11.720668,0.597079,0.133380,-125.347321,0.014405,0.000000
15.110001,2.883652,-125.302841,0.004014,0.000550,0.013962,12.827124,0.653445,0.139625,-125.302841,0.014821,0.000000
15.360001,2.985313,-125.391800,0.004049,0.000570,0.014465,13.279337,0.676482,0.144655,-125.391800,0.015237,0.000000
15.610001,2.985680,-125.391800,0.004044,0.000583,0.014812,13.280966,0.676565,0.148122,-125.391800,0.015654,0.000000
15.860001,3.063881,-125.436279,0.004049,0.000598,0.015185,13.628823,0.694285,0.151854,-125.436279,0.016070,0.000000
16.110001,3.123833,-125.391800,0.004049,0.000612,0.015541,13.895502,0.707871,0.155408,-125.391800,0.016486,0.000000
16.360001,3.352844,-125.391800,0.004083,0.000630,0.015992,14.914196,0.759765,0.159919,-125.391800,0.016902,0.000000
16.610001,3.391571,-125.436279,0.004092,0.000643,0.016339,15.086461,0.768541,0.163386,-125.436279,0.017319,0.000000
16.860001,3.502167,-125.480766,0.004117,0.000659,0.016729,15.578416,0.793602,0.167289,-125.480766,0.017735,0.000000
17.110001,3.607170,-125.436279,0.004113,0.000675,0.017145,16.045494,0.817396,0.171452,-125.436279,0.018151,0.000000
17.360001,3.799316,-125.436279,0.004139,0.000697,0.017700,16.900204,0.860937,0.177001,-125.436279,0.018568,0.000000
17.610001,3.842888,-125.525246,0.004169,0.000713,0.018116,17.094019,0.870811,0.181164,-125.525246,0.018984,0.000000
17.860001,3.900230,-125.525246,0.004182,0.000728,0.018481,17.349091,0.883805,0.184805,-125.525246,0.019400,0.000000
18.110001,4.091629,-125.480766,0.004182,0.000746,0.018940,18.200476,0.927176,0.189404,-125.480766,0.019816,0.000000
18.360001,4.171318,-125.525246,0.004204,0.000760,0.019296,18.554949,0.945234,0.192958,-125.525246,0.020233,0.000000
18.610001,4.249512,-125.480766,0.004221,0.000775,0.019686,18.902773,0.962953,0.196860,-125.480766,0.020649,0.000000
18.860001,4.411873,-125.525246,0.004251,0.000791,0.020094,19.624990,0.999745,0.200936,-125.525246,0.021074,0.000000
19.110001,4.585770,-125.525246,0.004273,0.000810,0.020571,20.398521,1.039150,0.205705,-125.525246,0.021490,0.000000
19.360001,4.655029,-125.436279,0.004281,0.000825,0.020961,20.706604,1.054845,0.209611,-125.436279,0.021906,0.000000
19.610001,4.696365,-125.569725,0.004286,0.000841,0.021368,20.890476,1.064212,0.213684,-125.569725,0.022323,0.000000
19.860001,4.942497,-125.525246,0.004303,0.000861,0.021863,21.985325,1.119986,0.218627,-125.525246,0.022739,0.000000
20.110001,5.113045,-125.614204,0.004329,0.000880,0.022349,22.743959,1.158633,0.223487,-125.614204,0.023155,0.000000
20.360001,5.099266,-125.525246,0.004363,0.000890,0.022617,22.682669,1.155510,0.226174,-125.525246,0.023571,0.000000
20.610001,5.063522,-125.569725,0.004350,0.000900,0.022860,22.523672,1.147411,0.228600,-125.569725,0.023988,0.000000
20.860001,5.360672,-125.614204,0.004363,0.000923,0.023441,23.845461,1.214746,0.234414,-125.614204,0.024404,0.000000
21.110001,5.539413,-125.569725,0.004389,0.000940,0.023875,24.640541,1.255249,0.238747,-125.569725,0.024820,0.000000
21.360001,5.695068,-125.569725,0.004415,0.000958,0.024335,25.332930,1.290521,0.243346,-125.569725,0.025237,0.000000
21.610001,5.828003,-125.614204,0.004406,0.000975,0.024777,25.924252,1.320644,0.247767,-125.614204,0.025653,0.000000
21.860001,5.926308,-125.658684,0.004458,0.000992,0.025184,26.361532,1.342921,0.251843,-125.658684,0.026069,0.000000
22.110001,6.078979,-125.525246,0.004458,0.001008,0.025601,27.040651,1.377517,0.256007,-125.525246,0.026485,0.000000
22.360001,6.112495,-125.703171,0.004480,0.001021,0.025930,27.189737,1.385111,0.259303,-125.703171,0.026902,0.000000
22.610001,6.275963,-125.614204,0.004501,0.001036,0.026321,27.916878,1.422154,0.263205,-125.614204,0.027318,0.000000
22.860001,6.294586,-125.614204,0.004518,0.001050,0.026667,27.999718,1.426374,0.266672,-125.614204,0.027734,0.000000
23.110001,6.756699,-125.703171,0.004506,0.001076,0.027318,30.055296,1.531090,0.273179,-125.703171,0.028150,0.000000
23.360001,6.674774,-125.658684,0.004531,0.001089,0.027673,29.690878,1.512525,0.276733,-125.658684,0.028566,0.000000
23.610001,6.853516,-125.658684,0.004566,0.001106,0.028098,30.485960,1.553029,0.280983,-125.658684,0.028983,0.000000
23.860001,6.982353,-125.703171,0.004596,0.001122,0.028497,31.059059,1.582224,0.284972,-125.703171,0.029408,0.000000
24.110001,7.136147,-125.703171,0.004570,0.001138,0.028896,31.743166,1.617074,0.288962,-125.703171,0.029824,0.000000
24.360001,7.298874,-125.703171,0.004600,0.001155,0.029347,32.467014,1.653949,0.293469,-125.703171,0.030240,0.000000
24.610001,7.362175,-125.614204,0.004600,0.001166,0.029624,32.748589,1.668293,0.296244,-125.614204,0.030657,0.000000
24.860001,7.661560,-125.747650,0.004635,0.001188,0.030180,34.080322,1.736134,0.301796,-125.747650,0.031073,0.000000
25.110001,7.840302,-125.747650,0.004656,0.001204,0.030587,34.875404,1.776638,0.305872,-125.747650,0.031489,0.000000
25.360001,7.808647,-125.703171,0.004691,0.001219,0.030960,34.734596,1.769465,0.309601,-125.703171,0.031906,0.000000
25.610001,7.971748,-125.747650,0.004669,0.001238,0.031454,35.460106,1.806424,0.314544,-125.747650,0.032321,0.000000
25.860001,8.023140,-125.703171,0.004717,0.001253,0.031818,35.688709,1.818069,0.318185,-125.703171,0.032738,0.000000
26.110001,8.405190,-125.703171,0.004730,0.001273,0.032330,37.388149,1.904643,0.323302,-125.703171,0.033154,0.000000
26.360001,8.414871,-125.703171,0.004721,0.001286,0.032660,37.431217,1.906837,0.326599,-125.703171,0.033571,0.000000
26.610001,8.548180,-125.792130,0.004756,0.001300,0.033024,38.024200,1.937045,0.330240,-125.792130,0.033987,0.000000
26.860001,8.820763,-125.703171,0.004760,0.001321,0.033562,39.236713,1.998813,0.335618,-125.703171,0.034403,0.000000
27.110001,9.009926,-125.792130,0.004794,0.001339,0.034021,40.078152,2.041678,0.340213,-125.792130,0.034819,0.000000
27.360001,9.040833,-125.747650,0.004794,0.001355,0.034412,40.215633,2.048682,0.344115,-125.747650,0.035235,0.000000
27.610001,9.117538,-125.792130,0.004838,0.001367,0.034732,40.556835,2.066064,0.347325,-125.792130,0.035652,0.000000
27.860001,9.428101,-125.747650,0.004859,0.001388,0.035253,41.938286,2.136438,0.352529,-125.747650,0.036068,0.000000
28.110001,9.417297,-125.836609,0.004855,0.001400,0.035548,41.890232,2.133990,0.355477,-125.836609,0.036484,0.000000
28.360001,9.602371,-125.836609,0.004855,0.001415,0.035929,42.713482,2.175928,0.359293,-125.836609,0.036900,0.000000
28.610001,9.705513,-125.792130,0.004868,0.001433,0.036389,43.172279,2.199301,0.363887,-125.792130,0.037317,0.000000
28.860001,10.265564,-125.836609,0.004894,0.001457,0.037013,45.663509,2.326210,0.370132,-125.836609,0.037742,0.000000
29.110001,10.191093,-125.881088,0.004919,0.001471,0.037369,45.332249,2.309335,0.373690,-125.881088,0.038158,0.000000
29.360001,10.138214,-125.836609,0.004950,0.001485,0.037724,45.097027,2.297352,0.377244,-125.836609,0.038574,0.000000
29.610001,10.265190,-125.881088,0.004950,0.001500,0.038106,45.661846,2.326125,0.381059,-125.881088,0.038990,0.000000
29.860001,10.630859,-125.881088,0.004975,0.001521,0.038644,47.288425,2.408987,0.386438,-125.881088,0.039407,0.000000
30.110001,10.625275,-125.836609,0.005001,0.001534,0.038973,47.263580,2.407722,0.389731,-125.836609,0.039823,0.000000
30.360001,10.574265,-125.836609,0.005001,0.001544,0.039207,47.036678,2.396163,0.392073,-125.836609,0.040239,0.000000
30.610001,11.122025,-125.881088,0.005019,0.001569,0.039841,49.473236,2.520287,0.398406,-125.881088,0.040656,0.000000
30.860001,11.230011,-125.836609,0.005049,0.001585,0.040248,49.953583,2.544757,0.402482,-125.836609,0.041072,0.000000
31.110001,11.226654,-125.881088,0.005070,0.001600,0.040647,49.938652,2.543996,0.406471,-125.881088,0.041488,0.000000
31.360001,11.405022,-125.881088,0.005079,0.001616,0.041055,50.732071,2.584415,0.410548,-125.881088,0.041904,0.000000
31.610001,11.431091,-125.925575,0.005088,0.001632,0.041445,50.848034,2.590322,0.414450,-125.925575,0.042321,0.000000
31.860001,11.637383,-125.970055,0.005113,0.001646,0.041818,51.765663,2.637069,0.418178,-125.970055,0.042737,0.000000
32.110001,11.846657,-125.881088,0.005144,0.001664,0.042269,52.696560,2.684491,0.422686,-125.881088,0.043153,0.000000
32.360001,11.874214,-125.925575,0.005152,0.001678,0.042616,52.819141,2.690735,0.426156,-125.925575,0.043569,0.000000
32.610001,12.316589,-125.925575,0.005165,0.001700,0.043171,54.786926,2.790979,0.431705,-125.925575,0.043986,0.000000
32.860001,12.405586,-125.881088,0.005200,0.001715,0.043569,55.182804,2.811146,0.435694,-125.881088,0.044402,0.000000
33.110001,12.409309,-125.925575,0.005195,0.001730,0.043951,55.199364,2.811990,0.439510,-125.925575,0.044818,0.000000
33.360001,12.693802,-125.970055,0.005226,0.001750,0.044454,56.464851,2.876457,0.444540,-125.970055,0.045234,0.000000
33.610001,12.634598,-126.014534,0.005247,0.001762,0.044758,56.201496,2.863041,0.447575,-126.014534,0.045651,0.000000
33.860001,12.905685,-125.970055,0.005260,0.001781,0.045243,57.407356,2.924470,0.452431,-125.970055,0.046067,0.000000
34.110001,12.854668,-126.014534,0.005277,0.001793,0.045530,57.180416,2.912909,0.455296,-126.014534,0.046492,0.000000
34.360001,12.974571,-125.970055,0.005277,0.001811,0.046007,57.713776,2.940080,0.460065,-125.970055,0.046908,0.000000
34.610001,13.408760,-125.970055,0.005295,0.001830,0.046483,59.645145,3.038468,0.464834,-125.970055,0.047324,0.000000
34.860001,13.464241,-126.014534,0.005342,0.001845,0.046874,59.891933,3.051041,0.468737,-126.014534,0.047741,0.000000
35.110001,13.529785,-126.014534,0.005342,0.001862,0.047299,60.183491,3.065893,0.472987,-126.014534,0.048157,0.000000
35.360001,13.511162,-126.014534,0.005364,0.001874,0.047594,60.100651,3.061673,0.475935,-126.014534,0.048573,0.000000
35.610001,13.787094,-126.014534,0.005385,0.001893,0.048070,61.328056,3.124200,0.480704,-126.014534,0.048990,0.000000
35.860001,13.867523,-126.059013,0.005407,0.001905,0.048391,61.685825,3.142426,0.483914,-126.059013,0.049406,0.000000
36.110001,13.883911,-126.014534,0.005402,0.001920,0.048756,61.758720,3.146139,0.487555,-126.014534,0.049822,0.000000
36.360001,14.369850,-126.059013,0.005411,0.001943,0.049354,63.920284,3.256255,0.493539,-126.059013,0.050238,0.000000
36.610001,14.640572,-126.059013,0.005445,0.001962,0.049831,65.124512,3.317601,0.498308,-126.059013,0.050655,0.000000
36.860001,14.655838,-126.103493,0.005467,0.001977,0.050221,65.192421,3.321060,0.502210,-126.103493,0.051071,0.000000
37.110001,14.662910,-126.014534,0.005480,0.001991,0.050577,65.223885,3.322663,0.505768,-126.014534,0.051487,0.000000
37.360001,14.572052,-126.059013,0.005514,0.002003,0.050872,64.819725,3.302074,0.508716,-126.059013,0.051903,0.000000
37.610001,14.807762,-126.103493,0.005523,0.002022,0.051366,65.868217,3.355487,0.513659,-126.103493,0.052320,0.000000
37.860001,15.101936,-126.059013,0.005545,0.002040,0.051825,67.176765,3.422148,0.518254,-126.059013,0.052736,0.000000
38.110001,14.956337,-126.059013,0.005549,0.002052,0.052120,66.529106,3.389154,0.521203,-126.059013,0.053152,0.000000
38.360001,15.477661,-126.103493,0.005575,0.002072,0.052641,68.848076,3.507288,0.526407,-126.103493,0.053569,0.000000
38.610001,15.684700,-126.103493,0.005605,0.002092,0.053144,69.769028,3.554204,0.531437,-126.103493,0.053985,0.000000
38.860001,15.644112,-126.103493,0.005627,0.002107,0.053517,69.588486,3.545006,0.535165,-126.103493,0.054401,0.000000
39.110001,15.692894,-126.147980,0.005631,0.002121,0.053864,69.805481,3.556061,0.538636,-126.147980,0.054826,0.000000
39.360001,15.892860,-126.147980,0.005631,0.002139,0.054323,70.694977,3.601374,0.543231,-126.147980,0.055242,0.000000
39.610001,16.102501,-126.192459,0.005687,0.002156,0.054757,71.627502,3.648879,0.547568,-126.192459,0.055659,0.000000
39.860001,16.150169,-126.192459,0.005704,0.002171,0.055138,71.839539,3.659681,0.551383,-126.192459,0.056075,0.000000
40.110001,16.060425,-126.147980,0.005704,0.002186,0.055529,71.440338,3.639344,0.555286,-126.147980,0.056491,0.000000
40.360001,16.595528,-126.236938,0.005721,0.002208,0.056075,73.820595,3.760600,0.560751,-126.236938,0.056907,0.000000
40.610001,16.754898,-126.192459,0.005760,0.002223,0.056465,74.529510,3.796714,0.564653,-126.192459,0.057324,0.000000
40.860001,16.345665,-126.192459,0.005769,0.002232,0.056691,72.709152,3.703981,0.566905,-126.192459,0.057740,0.000000
41.110001,16.675957,-126.192459,0.005795,0.002251,0.057176,74.178360,3.778826,0.571761,-126.192459,0.058156,0.000000
41.360001,16.917252,-126.192459,0.005799,0.002269,0.057636,75.251694,3.833504,0.576360,-126.192459,0.058572,0.000000
41.610001,17.238609,-126.236938,0.005838,0.002288,0.058113,76.681168,3.906325,0.581129,-126.236938,0.058989,0.000000
41.860001,16.875549,-126.236938,0.005838,0.002297,0.058338,75.066193,3.824054,0.583385,-126.236938,0.059405,0.000000
42.110001,17.071045,-126.192459,0.005851,0.002313,0.058755,75.935799,3.868354,0.587548,-126.192459,0.059821,0.000000
42.360001,17.364098,-126.236938,0.005877,0.002333,0.059249,77.239365,3.934761,0.592491,-126.236938,0.060238,0.000000
42.610001,17.756950,-126.236938,0.005894,0.002352,0.059743,78.986862,4.023782,0.597434,-126.236938,0.060654,0.000000
42.860001,17.593483,-126.281418,0.005924,0.002366,0.060108,78.259720,3.986740,0.601075,-126.281418,0.061070,0.000000
43.110001,17.931595,-126.281418,0.005950,0.002385,0.060584,79.763718,4.063357,0.605844,-126.281418,0.061486,0.000000
43.360001,18.028412,-126.281418,0.005950,0.002403,0.061044,80.194382,4.085297,0.610443,-126.281418,0.061903,0.000000
43.610001,18.039215,-126.236938,0.005989,0.002418,0.061408,80.242439,4.087745,0.614084,-126.236938,0.062319,0.000000
43.860001,18.054855,-126.236938,0.006015,0.002433,0.061807,80.312004,4.091289,0.618073,-126.236938,0.062735,0.000000
44.110001,17.877228,-126.236938,0.006015,0.002442,0.062033,79.521881,4.051038,0.620329,-126.236938,0.063160,0.000000
44.360001,18.642830,-126.325897,0.006036,0.002470,0.062727,82.927452,4.224526,0.627267,-126.325897,0.063576,0.000000
44.610001,18.454781,-126.281418,0.006049,0.002481,0.063013,82.090965,4.181913,0.630128,-126.281418,0.063993,0.000000
44.860001,18.777626,-126.281418,0.006088,0.002502,0.063559,83.527054,4.255071,0.635590,-126.281418,0.064409,0.000000
45.110001,18.735550,-126.325897,0.006127,0.002518,0.063958,83.339890,4.245536,0.639579,-126.325897,0.064825,0.000000
45.360001,18.658096,-126.370384,0.006140,0.002532,0.064314,82.995354,4.227985,0.643137,-126.370384,0.065241,0.000000
45.610001,18.928062,-126.370384,0.006148,0.002549,0.064738,84.196228,4.289160,0.647384,-126.370384,0.065658,0.000000
45.860001,18.541168,-126.325897,0.006183,0.002556,0.064921,82.475235,4.201489,0.649208,-126.325897,0.066074,0.000000
46.110001,18.471161,-126.325897,0.006187,0.002569,0.065250,82.163826,4.185625,0.652501,-126.325897,0.066490,0.000000
46.360001,19.504501,-126.414864,0.006209,0.002601,0.066057,86.760353,4.419783,0.660566,-126.414864,0.066907,0.000000
46.610001,19.494820,-126.325897,0.006239,0.002615,0.066421,86.717285,4.417590,0.664207,-126.325897,0.067323,0.000000
46.860001,19.412148,-126.370384,0.006243,0.002629,0.066785,86.349548,4.398855,0.667852,-126.370384,0.067739,0.000000
47.110001,19.437469,-126.370384,0.006278,0.002645,0.067175,86.462181,4.404593,0.671755,-126.370384,0.068155,0.000000
47.360001,19.949852,-126.370384,0.006299,0.002668,0.067765,88.741371,4.520701,0.677651,-126.370384,0.068572,0.000000
47.610001,19.726059,-126.414864,0.006308,0.002681,0.068095,87.745895,4.469989,0.680948,-126.414864,0.068988,0.000000
47.860001,19.788994,-126.414864,0.006342,0.002696,0.068468,88.025841,4.484250,0.684676,-126.414864,0.069404,0.000000
48.110001,20.172165,-126.459343,0.006347,0.002716,0.068997,89.730270,4.571078,0.689967,-126.459343,0.069820,0.000000
48.360001,20.189659,-126.459343,0.006377,0.002733,0.069430,89.808090,4.575042,0.694301,-126.459343,0.070237,0.000000
48.610001,20.089867,-126.459343,0.006407,0.002748,0.069812,89.364189,4.552429,0.698116,-126.459343,0.070653,0.000000
48.860001,20.128967,-126.503822,0.006424,0.002762,0.070167,89.538116,4.561289,0.701674,-126.503822,0.071069,0.000000
49.110001,20.371384,-126.503822,0.006428,0.002780,0.070601,90.616440,4.616221,0.706008,-126.503822,0.071486,0.000000
49.360001,20.423141,-126.459343,0.006454,0.002795,0.071000,90.846672,4.627950,0.709997,-126.459343,0.071910,0.000000
49.610001,20.462242,-126.414864,0.006489,0.002809,0.071355,91.020599,4.636810,0.713555,-126.414864,0.072327,0.000000
49.860001,20.422020,-126.503822,0.006497,0.002823,0.071711,90.841682,4.627696,0.717109,-126.503822,0.072743,0.000000
50.110001,21.167885,-126.503822,0.006510,0.002850,0.072388,94.159454,4.796711,0.723876,-126.503822,0.073159,0.000000
50.360001,21.281830,-126.459343,0.006545,0.002867,0.072821,94.666306,4.822532,0.728210,-126.459343,0.073576,0.000000
50.610001,20.990639,-126.503822,0.006554,0.002879,0.073125,93.371025,4.756546,0.731246,-126.503822,0.073992,0.000000
50.860001,20.969414,-126.592789,0.006588,0.002895,0.073523,93.276611,4.751737,0.735235,-126.592789,0.074408,0.000000
51.110001,21.416634,-126.548309,0.006601,0.002914,0.074026,95.265945,4.853079,0.740265,-126.548309,0.074824,0.000000
51.360001,21.361145,-126.548309,0.006648,0.002929,0.074408,95.019119,4.840505,0.744080,-126.548309,0.075241,0.000000
51.610001,21.171234,-126.548309,0.006648,0.002941,0.074694,94.174355,4.797470,0.746941,-126.548309,0.075657,0.000000
51.860001,21.777458,-126.592789,0.006666,0.002963,0.075258,96.870972,4.934843,0.752581,-126.592789,0.076073,0.000000
52.110001,22.069771,-126.592789,0.006700,0.002980,0.075700,98.171242,5.001081,0.757002,-126.592789,0.076489,0.000000
52.360001,21.910393,-126.592789,0.006713,0.002994,0.076039,97.462296,4.964966,0.760385,-126.592789,0.076906,0.000000
52.610001,22.037376,-126.592789,0.006735,0.003010,0.076455,98.027145,4.993741,0.764549,-126.592789,0.077322,0.000000
52.860001,21.970345,-126.592789,0.006730,0.003024,0.076819,97.728973,4.978551,0.768190,-126.592789,0.077738,0.000000
53.110004,22.311066,-126.592789,0.006756,0.003041,0.077253,99.244576,5.055760,0.772527,-126.592789,0.078155,0.000000
53.360004,22.292450,-126.592789,0.006791,0.003057,0.077643,99.161774,5.051541,0.776430,-126.592789,0.078571,0.000000
53.610004,22.391502,-126.592789,0.006804,0.003069,0.077964,99.602379,5.073987,0.779635,-126.592789,0.078987,0.000000
53.860004,22.762009,-126.681747,0.006821,0.003090,0.078493,101.250473,5.157945,0.784927,-126.681747,0.079403,0.000000
54.110004,22.657372,-126.681747,0.006847,0.003098,0.078692,100.785019,5.134233,0.786921,-126.681747,0.079820,0.000000
54.360004,23.425209,-126.637268,0.006868,0.003124,0.079351,104.200531,5.308228,0.793511,-126.637268,0.080245,0.000000
54.610004,23.571922,-126.637268,0.006890,0.003142,0.079811,104.853149,5.341474,0.798109,-126.637268,0.080661,0.000000
54.860004,23.338814,-126.592789,0.006907,0.003151,0.080037,103.816231,5.288651,0.800365,-126.592789,0.081077,0.000000
55.110004,23.964027,-126.637268,0.006924,0.003175,0.080635,106.597321,5.430326,0.806349,-126.637268,0.081493,0.000000
55.360004,24.072388,-126.637268,0.006942,0.003189,0.081008,107.079330,5.454881,0.810077,-126.637268,0.081910,0.000000
55.610004,23.982277,-126.637268,0.006967,0.003200,0.081276,106.678497,5.434462,0.812765,-126.637268,0.082326,0.000000
55.860004,24.725906,-126.681747,0.006972,0.003224,0.081901,109.986328,5.602971,0.819010,-126.681747,0.082742,0.000000
56.110004,24.961990,-126.681747,0.006998,0.003241,0.082317,111.036476,5.656468,0.823173,-126.681747,0.083158,0.000000
56.360004,24.871872,-126.681747,0.007011,0.003254,0.082664,110.635612,5.636047,0.826640,-126.681747,0.083575,0.000000
56.610004,25.096413,-126.681747,0.007028,0.003271,0.083072,111.634422,5.686928,0.830716,-126.681747,0.083991,0.000000
56.860004,24.951187,-126.726227,0.007041,0.003281,0.083349,110.988426,5.654020,0.833491,-126.726227,0.084407,0.000000
57.110004,25.879883,-126.681747,0.007067,0.003303,0.083887,115.119469,5.864465,0.838869,-126.681747,0.084823,0.000000
57.360004,25.839668,-126.726227,0.007084,0.003313,0.084156,114.940582,5.855353,0.841556,-126.726227,0.085240,0.000000
57.610004,26.212418,-126.770714,0.007092,0.003332,0.084641,116.598656,5.939819,0.846412,-126.770714,0.085656,0.000000
57.860004,26.934448,-126.726227,0.007131,0.003354,0.085188,119.810410,6.103433,0.851878,-126.726227,0.086072,0.000000
58.110004,27.365280,-126.770714,0.007140,0.003372,0.085639,121.726845,6.201061,0.856385,-126.770714,0.086489,0.000000
58.360004,27.323578,-126.770714,0.007179,0.003385,0.085986,121.541344,6.191611,0.859856,-126.770714,0.086905,0.000000
58.610004,27.619614,-126.770714,0.007161,0.003400,0.086358,122.858177,6.258694,0.863584,-126.770714,0.087321,0.000000
58.860004,27.650520,-126.815193,0.007187,0.003412,0.086653,122.995659,6.265697,0.866533,-126.815193,0.087737,0.000000
59.110004,28.388557,-126.815193,0.007200,0.003434,0.087217,126.278610,6.432939,0.872168,-126.815193,0.088154,0.000000
59.360004,28.255249,-126.726227,0.007235,0.003442,0.087425,125.685623,6.402731,0.874250,-126.726227,0.088579,0.000000
59.610004,29.075958,-126.815193,0.007252,0.003465,0.088015,129.336319,6.588706,0.880147,-126.815193,0.088995,0.000000
59.860004,29.697449,-126.859673,0.007274,0.003484,0.088492,132.100845,6.729538,0.884920,-126.859673,0.089411,0.000000
60.110004,29.973373,-126.815193,0.007295,0.003499,0.088865,133.328217,6.792063,0.888648,-126.815193,0.089827,0.000000
60.360004,30.265686,-126.859673,0.007308,0.003515,0.089272,134.628494,6.858303,0.892724,-126.859673,0.090244,0.000000
60.610004,30.597099,-126.859673,0.007308,0.003531,0.089680,136.102692,6.933402,0.896801,-126.859673,0.090660,0.000000
60.860004,31.222313,-126.859673,0.007347,0.003550,0.090174,138.883789,7.075078,0.901744,-126.859673,0.091076,0.000000
61.110004,31.444244,-126.904152,0.007338,0.003563,0.090504,139.870987,7.125368,0.905037,-126.904152,0.091492,0.000000
61.360004,31.573837,-126.859673,0.007368,0.003577,0.090859,140.447449,7.154734,0.908594,-126.859673,0.091909,0.000000
61.610004,32.449280,-126.859673,0.007390,0.003597,0.091371,144.341599,7.353112,0.913711,-126.859673,0.092325,0.000000
61.860004,32.814949,-126.859673,0.007386,0.003612,0.091753,145.968185,7.435974,0.917527,-126.859673,0.092741,0.000000
62.110004,33.012680,-126.859673,0.007420,0.003624,0.092056,146.847733,7.480780,0.920562,-126.859673,0.093158,0.000000
62.360004,33.913078,-126.904152,0.007437,0.003646,0.092620,150.852905,7.684813,0.926198,-126.904152,0.093574,0.000000
62.610004,34.427322,-126.859673,0.007442,0.003664,0.093054,153.140381,7.801342,0.930535,-126.859673,0.093990,0.000000
62.860004,35.177284,-126.904152,0.007459,0.003682,0.093513,156.476379,7.971286,0.935130,-126.904152,0.094406,0.000000
63.110004,35.131851,-126.904152,0.007476,0.003691,0.093756,156.274277,7.960991,0.937560,-126.904152,0.094823,0.000000
63.360004,35.611465,-126.904152,0.007498,0.003707,0.094146,158.407715,8.069674,0.941462,-126.904152,0.095239,0.000000
63.610004,36.249344,-126.904152,0.007511,0.003723,0.094563,161.245132,8.214218,0.945626,-126.904152,0.095655,0.000000
63.860004,37.086060,-126.948631,0.007532,0.003742,0.095057,164.967026,8.403821,0.950569,-126.948631,0.096071,0.000000
64.110001,37.616325,-126.948631,0.007541,0.003760,0.095499,167.325775,8.523981,0.954990,-126.948631,0.096488,0.000000
64.360001,38.439262,-126.904152,0.007549,0.003776,0.095915,170.986374,8.710462,0.959153,-126.904152,0.096904,0.000000
64.610001,38.883133,-126.993118,0.007584,0.003792,0.096314,172.960815,8.811044,0.963142,-126.993118,0.097329,0.000000
64.860001,39.920189,-126.948631,0.007610,0.003812,0.096835,177.573868,9.046044,0.968346,-126.948631,0.097745,0.000000
65.110001,40.052010,-126.993118,0.007606,0.003823,0.097095,178.160233,9.075915,0.970947,-126.993118,0.098161,0.000000
65.360001,40.630676,-126.993118,0.007631,0.003837,0.097459,180.734268,9.207043,0.974588,-126.993118,0.098578,0.000000
65.610001,41.485275,-127.037598,0.007636,0.003859,0.098023,184.535721,9.400698,0.980227,-127.037598,0.098994,0.000000
65.860001,42.777405,-126.993118,0.007644,0.003878,0.098500,190.283401,9.693499,0.984996,-126.993118,0.099410,0.000000
66.110001,43.191856,-126.948631,0.007679,0.003894,0.098907,192.126968,9.787415,0.989073,-126.948631,0.099827,0.000000
66.360001,43.813347,-126.993118,0.007683,0.003908,0.099263,194.891495,9.928246,0.992627,-126.993118,0.100243,0.000000
66.610001,44.390518,-126.993118,0.007687,0.003924,0.099662,197.458893,10.059035,0.996616,-126.993118,0.100659,0.000000
66.860001,45.375450,-127.037598,0.007709,0.003942,0.100130,201.840088,10.282224,1.001302,-127.037598,0.101075,0.000000
67.110001,45.942574,-126.993118,0.007722,0.003954,0.100434,204.362778,10.410736,1.004337,-126.993118,0.101492,0.000000
67.360001,46.308609,-127.082077,0.007743,0.003966,0.100737,205.990982,10.493681,1.007369,-127.082077,0.101908,0.000000
67.610001,47.642075,-127.037598,0.007761,0.003991,0.101370,211.922531,10.795849,1.013701,-127.037598,0.102324,0.000000
67.860001,48.754730,-127.082077,0.007769,0.004008,0.101813,216.871872,11.047979,1.018125,-127.082077,0.102740,0.000000
68.110001,49.224663,-127.082077,0.007782,0.004023,0.102185,218.962234,11.154469,1.021854,-127.082077,0.103157,0.000000
68.360001,50.225601,-127.082077,0.007808,0.004039,0.102584,223.414627,11.381285,1.025843,-127.082077,0.103573,0.000000
68.610001,51.391495,-127.082077,0.007795,0.004060,0.103113,228.600784,11.645479,1.031134,-127.082077,0.103989,0.000000
68.860001,52.128418,-127.082077,0.007812,0.004073,0.103443,231.878784,11.812469,1.034427,-127.082077,0.104406,0.000000
69.110001,52.821777,-127.126556,0.007851,0.004089,0.103850,234.962997,11.969585,1.038503,-127.126556,0.104822,0.000000
69.360001,54.173492,-127.126556,0.007843,0.004111,0.104414,240.975723,12.275889,1.044139,-127.126556,0.105238,0.000000
69.610001,55.190437,-127.126556,0.007864,0.004126,0.104804,245.499329,12.506332,1.048045,-127.126556,0.105663,0.000000
69.860001,55.916191,-127.171036,0.007873,0.004140,0.105151,248.727646,12.670791,1.051512,-127.171036,0.106079,0.000000
70.110001,56.747330,-127.082077,0.007886,0.004155,0.105541,252.424728,12.859129,1.055414,-127.082077,0.106496,0.000000
70.360001,57.346848,-127.171036,0.007907,0.004171,0.105940,255.091522,12.994981,1.059403,-127.171036,0.106912,0.000000
70.610001,58.723137,-127.126556,0.007925,0.004189,0.106392,261.213562,13.306853,1.063915,-127.126556,0.107328,0.000000
70.860001,59.033699,-127.126556,0.007942,0.004196,0.106591,262.595001,13.377228,1.065910,-127.126556,0.107744,0.000000
71.110001,60.044685,-127.126556,0.007933,0.004216,0.107077,267.092102,13.606319,1.070766,-127.126556,0.108161,0.000000
71.360001,61.539017,-127.215523,0.007938,0.004235,0.107562,273.739227,13.944941,1.075622,-127.215523,0.108577,0.000000
71.610001,63.251183,-127.171036,0.007955,0.004257,0.108134,281.355316,14.332923,1.081344,-127.171036,0.108993,0.000000
71.860001,64.047325,-127.215523,0.007981,0.004272,0.108507,284.896729,14.513331,1.085073,-127.215523,0.109409,0.000000
72.110001,64.907875,-127.171036,0.007994,0.004285,0.108837,288.724640,14.708335,1.088369,-127.171036,0.109826,0.000000
72.360001,65.763954,-127.215523,0.007998,0.004302,0.109262,292.532684,14.902325,1.092620,-127.215523,0.110242,0.000000
72.610001,67.400536,-127.260002,0.008011,0.004319,0.109713,299.812561,15.273180,1.097128,-127.260002,0.110658,0.000000
72.860001,66.976036,-127.215523,0.008045,0.004314,0.109583,297.924286,15.176987,1.095829,-127.215523,0.109799,0.000000
73.110001,66.507957,-127.215523,0.008028,0.004313,0.109557,295.842163,15.070918,1.095568,-127.215523,0.109583,0.000000
73.360001,66.029457,-127.215523,0.008041,0.004312,0.109531,293.713684,14.962488,1.095307,-127.215523,0.109583,0.000000
73.610001,65.617607,-127.260002,0.008032,0.004312,0.109522,291.881683,14.869163,1.095220,-127.260002,0.109583,0.000000
73.860001,65.245613,-127.260002,0.008050,0.004312,0.109513,290.226990,14.784867,1.095133,-127.260002,0.109583,0.000000
74.110001,64.902657,-127.260002,0.008032,0.004311,0.109505,288.701447,14.707152,1.095046,-127.260002,0.109583,0.000000
74.360001,64.619286,-127.260002,0.008045,0.004311,0.109505,287.440948,14.642940,1.095046,-127.260002,0.109583,0.000000
74.610001,64.356758,-127.304482,0.008041,0.004311,0.109505,286.273163,14.583450,1.095046,-127.304482,0.109583,0.000000
74.860001,64.121056,-127.260002,0.008045,0.004311,0.109505,285.224701,14.530039,1.095046,-127.260002,0.109583,0.000000
75.110001,63.883842,-127.348961,0.008058,0.004311,0.109505,284.169525,14.476286,1.095046,-127.348961,0.109583,0.000000
75.360001,63.677177,-127.304482,0.008054,0.004311,0.109496,283.250244,14.429455,1.094959,-127.304482,0.109583,0.000000
75.610001,63.477592,-127.260002,0.008054,0.004311,0.109496,282.362427,14.384228,1.094959,-127.260002,0.109583,0.000000
75.860001,63.311516,-127.348961,0.008054,0.004311,0.109496,281.623688,14.346594,1.094959,-127.348961,0.109583,0.000000
76.110001,63.124214,-127.348961,0.008045,0.004311,0.109496,280.790527,14.304152,1.094959,-127.348961,0.109583,0.000000
76.360001,62.994987,-127.348961,0.008041,0.004311,0.109496,280.215698,14.274869,1.094959,-127.348961,0.109583,0.000000
76.610001,62.817749,-127.348961,0.008058,0.004311,0.109496,279.427307,14.234706,1.094959,-127.348961,0.109583,0.000000
76.860001,62.693375,-127.348961,0.008071,0.004311,0.109496,278.874054,14.206522,1.094959,-127.348961,0.109583,0.000000
77.110001,62.554108,-127.348961,0.008054,0.004311,0.109496,278.254578,14.174963,1.094959,-127.348961,0.109583,0.000000
77.360001,62.445747,-127.393440,0.008058,0.004311,0.109496,277.772552,14.150409,1.094959,-127.393440,0.109583,0.000000
77.610001,62.307220,-127.304482,0.008063,0.004311,0.109496,277.156372,14.119018,1.094959,-127.304482,0.109583,0.000000
77.860001,62.211151,-127.393440,0.008075,0.004311,0.109496,276.729034,14.097248,1.094959,-127.393440,0.109583,0.000000
78.110001,62.088638,-127.393440,0.008067,0.004311,0.109496,276.184052,14.069487,1.094959,-127.393440,0.109583,0.000000
78.360001,62.002625,-127.393440,0.008080,0.004311,0.109496,275.801453,14.049995,1.094959,-127.393440,0.109583,0.000000
78.610001,61.886810,-127.482407,0.008075,0.004311,0.109487,275.286285,14.023751,1.094872,-127.482407,0.109583,0.000000
78.860001,61.807129,-127.437927,0.008075,0.004311,0.109487,274.931854,14.005695,1.094872,-127.437927,0.109583,0.000000
79.110001,61.712547,-127.393440,0.008080,0.004311,0.109487,274.511108,13.984263,1.094872,-127.393440,0.109583,0.000000
79.360001,61.616844,-127.482407,0.008067,0.004311,0.109487,274.085419,13.962577,1.094872,-127.482407,0.109583,0.000000
79.610001,61.542000,-127.437927,0.008063,0.004311,0.109487,273.752502,13.945617,1.094872,-127.437927,0.109583,0.000000
79.860001,61.458961,-127.482407,0.008071,0.004311,0.109487,273.383118,13.926800,1.094872,-127.482407,0.109583,0.000000
80.110001,61.369217,-127.437927,0.008071,0.004311,0.109487,272.983917,13.906463,1.094872,-127.437927,0.109583,0.000000
80.360001,61.301819,-127.482407,0.008063,0.004311,0.109487,272.684113,13.891191,1.094872,-127.482407,0.109583,0.000000
80.610001,61.248940,-127.526886,0.008063,0.004311,0.109487,272.448883,13.879208,1.094872,-127.526886,0.109583,0.000000
80.860001,61.158829,-127.526886,0.008071,0.004311,0.109487,272.048065,13.858788,1.094872,-127.526886,0.109583,0.000000
81.110001,61.099617,-127.437927,0.008063,0.004311,0.109487,271.784668,13.845370,1.094872,-127.437927,0.109583,0.000000
81.360001,61.027748,-127.526886,0.008063,0.004311,0.109487,271.464996,13.829086,1.094872,-127.526886,0.109583,0.000000
81.610001,60.964821,-127.437927,0.008075,0.004311,0.109487,271.185059,13.814825,1.094872,-127.437927,0.109583,0.000000
81.860001,60.891090,-127.482407,0.008088,0.004311,0.109487,270.857086,13.798119,1.094872,-127.482407,0.109583,0.000000
82.110001,60.852364,-127.482407,0.008067,0.004311,0.109487,270.684845,13.789342,1.094872,-127.482407,0.109583,0.000000
82.360001,60.787567,-127.437927,0.008075,0.004311,0.109487,270.396606,13.774660,1.094872,-127.437927,0.109583,0.000000
82.610001,60.730972,-127.615852,0.008088,0.004311,0.109487,270.144867,13.761835,1.094872,-127.615852,0.109583,0.000000
82.860001,60.681816,-127.526886,0.008084,0.004311,0.109487,269.926208,13.750696,1.094872,-127.526886,0.109583,0.000000
83.110001,60.625587,-127.571365,0.008084,0.004311,0.109487,269.676086,13.737955,1.094872,-127.571365,0.109583,0.000000
83.360001,60.573830,-127.571365,0.008075,0.004311,0.109487,269.445862,13.726226,1.094872,-127.571365,0.109583,0.000000
83.610001,60.525421,-127.526886,0.008080,0.004311,0.109487,269.230530,13.715256,1.094872,-127.526886,0.109583,0.000000
83.860001,60.475891,-127.615852,0.008080,0.004311,0.109487,269.010193,13.704033,1.094872,-127.615852,0.109583,0.000000
84.110001,60.423393,-127.526886,0.008084,0.004311,0.109487,268.776672,13.692137,1.094872,-127.526886,0.109583,0.000000
84.360001,60.386894,-127.571365,0.008080,0.004311,0.109487,268.614319,13.683866,1.094872,-127.571365,0.109583,0.000000
84.610001,60.338860,-127.571365,0.008075,0.004311,0.109487,268.400665,13.672980,1.094872,-127.571365,0.109583,0.000000
84.860001,60.288963,-127.615852,0.008084,0.004311,0.109487,268.178711,13.661674,1.094872,-127.615852,0.109583,0.000000
85.110001,60.239807,-127.615852,0.008080,0.004311,0.109487,267.960052,13.650536,1.094872,-127.615852,0.109583,0.000000
85.360001,60.192146,-127.615852,0.008058,0.004311,0.109487,267.748047,13.639735,1.094872,-127.615852,0.109583,0.000000
85.610001,60.158630,-127.660332,0.008071,0.004311,0.109487,267.598938,13.632140,1.094872,-127.660332,0.109583,0.000000
85.860001,60.106873,-127.615852,0.008093,0.004311,0.109487,267.368713,13.620412,1.094872,-127.615852,0.109583,0.000000
86.110001,60.080063,-127.704811,0.008084,0.004311,0.109487,267.249481,13.614337,1.094872,-127.704811,0.109583,0.000000
86.360001,60.034630,-127.660332,0.008080,0.004311,0.109487,267.047363,13.604042,1.094872,-127.660332,0.109583,0.000000
86.610001,59.995537,-127.615852,0.008067,0.004311,0.109487,266.873474,13.595183,1.094872,-127.615852,0.109583,0.000000
86.860001,59.939308,-127.660332,0.008093,0.004311,0.109487,266.623352,13.582441,1.094872,-127.660332,0.109583,0.000000
87.110001,59.917336,-127.660332,0.008075,0.004311,0.109487,266.525635,13.577462,1.094872,-127.660332,0.109583,0.000000
87.360001,59.877495,-127.704811,0.008088,0.004311,0.109487,266.348389,13.568435,1.094872,-127.704811,0.109583,0.000000
87.610001,59.836906,-127.704811,0.008101,0.004311,0.109487,266.167847,13.559237,1.094872,-127.704811,0.109583,0.000000
87.860001,59.800041,-127.704811,0.008097,0.004311,0.109487,266.003876,13.550883,1.094872,-127.704811,0.109583,0.000000
88.110001,59.760193,-127.793770,0.008101,0.004311,0.109487,265.826599,13.541853,1.094872,-127.793770,0.109583,0.000000
88.360001,59.730408,-127.704811,0.008075,0.004311,0.109487,265.694122,13.535104,1.094872,-127.704811,0.109583,0.000000
88.610001,59.692047,-127.793770,0.008067,0.004311,0.109487,265.523499,13.526412,1.094872,-127.793770,0.109583,0.000000
88.860001,59.665611,-127.793770,0.008084,0.004311,0.109487,265.405884,13.520421,1.094872,-127.793770,0.109583,0.000000
89.110001,59.622047,-127.749290,0.008084,0.004311,0.109487,265.212128,13.510549,1.094872,-127.749290,0.109583,0.000000
89.360001,59.606781,-127.704811,0.008071,0.004311,0.109487,265.144196,13.507090,1.094872,-127.704811,0.109583,0.000000
89.610001,59.555016,-127.793770,0.008088,0.004311,0.109487,264.913940,13.495359,1.094872,-127.793770,0.109583,0.000000
89.860001,59.536400,-127.793770,0.008071,0.004311,0.109487,264.831146,13.491141,1.094872,-127.793770,0.109583,0.000000
90.110001,59.504372,-127.793770,0.008084,0.004311,0.109487,264.688660,13.483884,1.094872,-127.793770,0.109583,0.000000
90.360001,59.462669,-127.793770,0.008067,0.004311,0.109487,264.503174,13.474433,1.094872,-127.793770,0.109583,0.000000
90.610001,59.450012,-127.793770,0.008075,0.004311,0.109487,264.446869,13.471565,1.094872,-127.793770,0.109583,0.000000
90.860001,59.412399,-127.793770,0.008075,0.004311,0.109487,264.279541,13.463042,1.094872,-127.793770,0.109583,0.000000
91.110001,59.387451,-127.749290,0.008101,0.004311,0.109487,264.168579,13.457388,1.094872,-127.749290,0.109583,0.000000
91.360001,59.340904,-127.838257,0.008097,0.004311,0.109487,263.961517,13.446841,1.094872,-127.838257,0.109583,0.000000
91.610001,59.330849,-127.838257,0.008080,0.004311,0.109487,263.916809,13.444562,1.094872,-127.838257,0.109583,0.000000
91.860001,59.286163,-127.838257,0.008088,0.004311,0.109487,263.718018,13.434437,1.094872,-127.838257,0.109583,0.000000
92.110001,59.284302,-127.838257,0.008080,0.004311,0.109487,263.709747,13.434015,1.094872,-127.838257,0.109583,0.000000
92.360001,59.253021,-127.838257,0.008075,0.004311,0.109487,263.570587,13.426927,1.094872,-127.838257,0.109583,0.000000
92.610001,59.221001,-127.882736,0.008093,0.004311,0.109487,263.428162,13.419670,1.094872,-127.882736,0.109583,0.000000
92.860001,59.197914,-127.882736,0.008088,0.004310,0.109479,263.325470,13.414439,1.094788,-127.882736,0.109583,0.000000
93.110001,59.156952,-127.882736,0.008097,0.004310,0.109479,263.143250,13.405156,1.094788,-127.882736,0.109583,0.000000
93.360008,59.147270,-127.882736,0.008088,0.004310,0.109479,263.100189,13.402964,1.094788,-127.882736,0.109583,0.000000
93.610008,59.115990,-127.838257,0.008084,0.004310,0.109479,262.961060,13.395875,1.094788,-127.838257,0.109583,0.000000
93.860008,59.095512,-127.927216,0.008088,0.004310,0.109479,262.869965,13.391234,1.094788,-127.927216,0.109583,0.000000
94.110008,59.065720,-127.882736,0.008088,0.004310,0.109479,262.737457,13.384483,1.094788,-127.882736,0.109583,0.000000
94.360008,59.042259,-127.927216,0.008097,0.004310,0.109479,262.633087,13.379167,1.094788,-127.927216,0.109583,0.000000
94.610008,59.013962,-127.927216,0.008093,0.004310,0.109479,262.507202,13.372755,1.094788,-127.927216,0.109583,0.000000
94.860008,58.981934,-127.882736,0.008097,0.004310,0.109479,262.364746,13.365498,1.094788,-127.882736,0.109583,0.000000
95.110008,58.978210,-127.927216,0.008097,0.004310,0.109479,262.348175,13.364654,1.094788,-127.927216,0.109583,0.000000
95.360008,58.954010,-127.971695,0.008080,0.004310,0.109479,262.240540,13.359170,1.094788,-127.971695,0.109583,0.000000
95.610008,58.935760,-128.016174,0.008075,0.004310,0.109479,262.159363,13.355034,1.094788,-128.016174,0.109583,0.000000
95.860008,58.903366,-127.971695,0.008088,0.004310,0.109479,262.015259,13.347693,1.094788,-127.971695,0.109583,0.000000
96.110008,58.889961,-128.016174,0.008088,0.004310,0.109479,261.955627,13.344656,1.094788,-128.016174,0.109583,0.000000
96.360008,58.863152,-127.971695,0.008071,0.004310,0.109479,261.836365,13.338581,1.094788,-127.971695,0.109583,0.000000
96.610008,58.852348,-127.971695,0.008101,0.004310,0.109479,261.788330,13.336133,1.094788,-127.971695,0.109583,0.000000
96.860008,58.814369,-128.016174,0.008093,0.004310,0.109479,261.619385,13.327526,1.094788,-128.016174,0.109583,0.000000
97.110008,58.799843,-128.016174,0.008080,0.004310,0.109479,261.554779,13.324234,1.094788,-128.016174,0.109583,0.000000
97.360008,58.778252,-128.016174,0.008088,0.004310,0.109479,261.458710,13.319342,1.094788,-128.016174,0.109583,0.000000
97.610008,58.744736,-128.016174,0.008075,0.004310,0.109479,261.309631,13.311747,1.094788,-128.016174,0.109583,0.000000
97.860008,58.746971,-127.971695,0.008088,0.004310,0.109479,261.319580,13.312254,1.094788,-127.971695,0.109583,0.000000
98.110008,58.716064,-128.060654,0.008097,0.004310,0.109479,261.182098,13.305250,1.094788,-128.060654,0.109583,0.000000
98.360008,58.703773,-128.060654,0.008088,0.004310,0.109479,261.127441,13.302465,1.094788,-128.060654,0.109583,0.000000
98.610008,58.672867,-128.105133,0.008075,0.004310,0.109479,260.989960,13.295462,1.094788,-128.105133,0.109583,0.000000
98.860008,58.662071,-128.105133,0.008101,0.004310,0.109479,260.941925,13.293015,1.094788,-128.105133,0.109583,0.000000
99.110008,58.636375,-128.060654,0.008101,0.004310,0.109479,260.827637,13.287192,1.094788,-128.060654,0.109583,0.000000
99.360008,58.607704,-128.105133,0.008106,0.004310,0.109479,260.700073,13.280695,1.094788,-128.105133,0.109583,0.000000
99.610008,58.607330,-128.060654,0.008084,0.004310,0.109479,260.698425,13.280611,1.094788,-128.060654,0.109583,0.000000
99.860008,58.568604,-128.105133,0.008080,0.004310,0.109479,260.526154,13.271835,1.094788,-128.105133,0.109583,0.000000
100.110008,58.563759,-128.149612,0.008088,0.004310,0.109479,260.504608,13.270737,1.094788,-128.149612,0.109583,0.000000
100.360008,58.516098,-128.060654,0.008093,0.004310,0.109479,260.292603,13.259937,1.094788,-128.060654,0.109583,0.000000
100.610008,58.514984,-128.105133,0.008088,0.004310,0.109479,260.287659,13.259685,1.094788,-128.105133,0.109583,0.000000
100.860008,58.487053,-128.105133,0.008097,0.004310,0.109479,260.163391,13.253356,1.094788,-128.105133,0.109583,0.000000
101.110008,58.488167,-128.149612,0.008097,0.004310,0.109479,260.168365,13.253608,1.094788,-128.149612,0.109583,0.000000
101.360008,58.459496,-128.149612,0.008088,0.004310,0.109479,260.040833,13.247111,1.094788,-128.149612,0.109583,0.000000
101.610008,58.428589,-128.149612,0.008088,0.004310,0.109479,259.903351,13.240108,1.094788,-128.149612,0.109583,0.000000
101.860008,58.421143,-128.105133,0.008101,0.004310,0.109479,259.870209,13.238420,1.094788,-128.105133,0.109583,0.000000
102.110008,58.392097,-128.194107,0.008088,0.004310,0.109479,259.741028,13.231839,1.094788,-128.194107,0.109583,0.000000
102.360008,58.383537,-128.238586,0.008088,0.004310,0.109479,259.702942,13.229898,1.094788,-128.238586,0.109583,0.000000
102.610008,58.364540,-128.194107,0.008097,0.004310,0.109479,259.618439,13.225594,1.094788,-128.194107,0.109583,0.000000
102.860008,58.347786,-128.194107,0.008101,0.004310,0.109479,259.543915,13.221797,1.094788,-128.194107,0.109583,0.000000
103.110008,58.322464,-128.194107,0.008093,0.004310,0.109479,259.431274,13.216060,1.094788,-128.194107,0.109583,0.000000
103.200005,58.338104,-128.238586,0.008084,0.004310,0.109479,259.500854,13.219603,1.094788,-128.238586,0.109583,0.000000