File: Data/Automembrane/AutoNoheat15-1-1_12132023_185751.csv
Time (sec),S:Load (lbs),S:HL1 (DIM),S:LVDT (in),S:Position (in),Ch:Position (mm),Ch:Load (N),Ch:Stress (MPa),Ch:Strain (mm/mm),Ch:HL1 (DIM),Set Point (),Cycles ()
0.010000,0.002235,-1304.136963,0.000034,-0.000000,-0.000009,0.009944,0.000507,-0.000087,-1304.136963,0.000208,0.000000
0.270000,0.010048,-1304.136963,0.000009,-0.000000,-0.000009,0.044695,0.002277,-0.000087,-1304.136963,0.000208,0.000000
0.530000,0.028297,-1304.092529,0.000026,0.000069,0.001760,0.125873,0.006412,0.017604,-1304.092529,0.002480,0.000000
0.790000,0.038727,-1304.092529,0.000065,0.000231,0.005880,0.172265,0.008776,0.058798,-1304.092529,0.006799,0.000000
1.050000,0.055481,-1304.136963,0.000280,0.000397,0.010095,0.246792,0.012572,0.100947,-1304.136963,0.011135,0.000000
1.310000,0.049522,-1304.092529,0.000440,0.000565,0.014361,0.220287,0.011222,0.143614,-1304.092529,0.015472,0.000000
1.570000,0.015640,-1304.136963,0.000595,0.000737,0.018715,0.069571,0.003544,0.187148,-1304.136963,0.019807,0.000000
1.830000,0.038727,-1304.136963,0.000793,0.000911,0.023129,0.172265,0.008776,0.231291,-1304.136963,0.024126,0.000000
2.090000,0.037231,-1304.181519,0.000961,0.001075,0.027309,0.165614,0.008437,0.273092,-1304.181519,0.028462,0.000000
2.350000,-0.007446,-1304.048096,0.001112,0.001250,0.031758,-0.033123,-0.001687,0.317579,-1304.048096,0.032798,0.000000
2.610000,0.058090,-1304.092529,0.001332,0.001418,0.036007,0.258398,0.013163,0.360072,-1304.092529,0.037135,0.000000
2.870000,0.070747,-1304.092529,0.001496,0.001584,0.040222,0.314700,0.016032,0.402221,-1304.092529,0.041453,0.000000
3.130000,0.042076,-1304.092529,0.001673,0.001761,0.044731,0.187164,0.009535,0.447314,-1304.092529,0.045790,0.000000
3.390000,0.059952,-1304.092529,0.001841,0.001931,0.049059,0.266679,0.013585,0.490591,-1304.092529,0.050126,0.000000
3.650000,0.061813,-1304.003540,0.001992,0.002101,0.053378,0.274960,0.014007,0.533780,-1304.003540,0.054462,0.000000
3.910000,0.021965,-1304.048096,0.002225,0.002271,0.057688,0.097705,0.004977,0.576879,-1304.048096,0.058781,0.000000
4.170000,0.053619,-1304.092529,0.002380,0.002446,0.062137,0.238511,0.012150,0.621366,-1304.092529,0.063117,0.000000
4.430000,0.037231,-1304.092529,0.002570,0.002615,0.066421,0.165614,0.008437,0.664207,-1304.092529,0.067453,0.000000
4.690000,0.039841,-1304.092529,0.002703,0.002783,0.070687,0.177220,0.009028,0.706875,-1304.092529,0.071772,0.000000
4.950000,0.058090,-1304.092529,0.002915,0.002952,0.074972,0.258398,0.013163,0.749716,-1304.092529,0.076108,0.000000
5.210000,0.078568,-1304.092529,0.003117,0.003130,0.079490,0.349486,0.017804,0.794900,-1304.092529,0.080444,0.000000
5.470000,0.057343,-1304.092529,0.003238,0.003299,0.083792,0.255072,0.012994,0.837915,-1304.092529,0.084780,0.000000
5.730000,0.049896,-1304.136963,0.003458,0.003462,0.087945,0.221950,0.011307,0.879454,-1304.136963,0.089099,0.000000
5.990000,0.051758,-1304.136963,0.003587,0.003637,0.092377,0.230230,0.011728,0.923768,-1304.136963,0.093435,0.000000
6.250000,0.004463,-1304.048096,0.003768,0.003809,0.096756,0.019853,0.001011,0.967563,-1304.048096,0.097771,0.000000
6.510000,0.054733,-1304.092529,0.003971,0.003977,0.101023,0.243466,0.012403,1.010230,-1304.092529,0.102107,0.000000
6.770000,0.071121,-1304.092529,0.004117,0.004150,0.105411,0.316363,0.016116,1.054112,-1304.092529,0.106426,0.000000
7.030000,0.038353,-1304.048096,0.004303,0.004320,0.109721,0.170603,0.008691,1.097215,-1304.048096,0.110762,0.000000
7.290000,0.089363,-1304.092529,0.004484,0.004486,0.113945,0.397507,0.020250,1.139450,-1304.092529,0.115098,0.000000
7.550000,0.086014,-1304.092529,0.004708,0.004662,0.118411,0.382608,0.019491,1.184112,-1304.092529,0.119434,0.000000
7.810000,0.059204,-1304.092529,0.004881,0.004829,0.122669,0.263353,0.013416,1.226692,-1304.092529,0.123753,0.000000
8.070001,0.111710,-1304.092529,0.004971,0.005001,0.127014,0.496909,0.025314,1.270139,-1304.092529,0.128089,0.000000
8.330000,0.119156,-1304.003540,0.005217,0.005177,0.131506,0.530032,0.027001,1.315062,-1304.003540,0.132426,0.000000
8.590000,0.229004,-1304.092529,0.005376,0.005345,0.135773,1.018660,0.051893,1.357729,-1304.092529,0.136744,0.000000
8.850000,0.702293,-1304.048096,0.005553,0.005504,0.139797,3.123957,0.159142,1.397970,-1304.048096,0.140942,0.000000
9.110001,0.610687,-1304.048096,0.005579,-0.000000,-0.000000,2.716473,0.138384,-0.000000,-1304.048096,0.000217,0.000000
9.370001,0.595047,-1304.048096,0.005566,-0.000000,-0.000000,2.646901,0.134840,-0.000000,-1304.048096,0.000217,0.000000
9.630000,0.596169,-1303.959106,0.005540,0.000000,0.000009,2.651890,0.135094,0.000087,-1303.959106,0.000642,0.000000
9.890000,0.557068,-1304.092529,0.005566,0.000000,0.000009,2.477962,0.126233,0.000087,-1304.092529,0.001075,0.000000
10.150001,0.704155,-1303.959106,0.005562,0.000023,0.000590,3.132238,0.159564,0.005897,-1303.959106,0.001509,0.000000
10.410001,0.789803,-1304.003540,0.005583,0.000045,0.001153,3.513217,0.178972,0.011533,-1304.003540,0.001942,0.000000
10.670000,0.849754,-1304.092529,0.005562,0.000059,0.001509,3.779896,0.192557,0.015090,-1304.092529,0.002376,0.000000
10.930000,0.894440,-1304.048096,0.005639,0.000075,0.001899,3.978667,0.202683,0.018993,-1304.048096,0.002810,0.000000
11.190001,0.965935,-1304.048096,0.005609,0.000091,0.002316,4.296692,0.218884,0.023156,-1304.048096,0.003243,0.000000
11.450001,1.087700,-1304.048096,0.005683,0.000111,0.002827,4.838331,0.246476,0.028273,-1304.048096,0.003677,0.000000
11.710001,1.120094,-1304.048096,0.005687,0.000122,0.003105,4.982428,0.253817,0.031047,-1304.048096,0.004111,0.000000
11.970000,1.265320,-1304.048096,0.005670,0.000140,0.003547,5.628424,0.286726,0.035468,-1304.048096,0.004544,0.000000
12.230000,1.466774,-1304.048096,0.005708,0.000165,0.004197,6.524537,0.332376,0.041974,-1304.048096,0.004978,0.000000
12.490001,1.525604,-1304.092529,0.005726,0.000181,0.004605,6.786227,0.345707,0.046051,-1304.092529,0.005412,0.000000
12.750001,1.636948,-1304.048096,0.005756,0.000198,0.005038,7.281507,0.370938,0.050385,-1304.048096,0.005845,0.000000
13.010000,1.780312,-1303.959106,0.005717,0.000215,0.005455,7.919221,0.403424,0.054548,-1303.959106,0.006270,0.000000
13.270000,1.880852,-1304.048096,0.005795,0.000231,0.005880,8.366446,0.426207,0.058798,-1304.048096,0.006704,0.000000
13.530001,2.031288,-1304.048096,0.005760,0.000243,0.006175,9.035621,0.460296,0.061747,-1304.048096,0.007137,0.000000
13.790001,2.177635,-1304.048096,0.005790,0.000257,0.006539,9.686605,0.493459,0.065388,-1304.048096,0.007571,0.000000
14.050000,2.462868,-1304.003540,0.005786,0.000281,0.007137,10.955383,0.558094,0.071372,-1304.003540,0.008005,0.000000
14.310000,2.663574,-1304.003540,0.005859,0.000303,0.007701,11.848170,0.603575,0.077011,-1304.003540,0.008438,0.000000
14.570001,2.741402,-1304.092529,0.005859,0.000318,0.008074,12.194364,0.621210,0.080739,-1304.092529,0.008872,0.000000
14.830001,2.917160,-1304.048096,0.005855,0.000332,0.008438,12.976176,0.661038,0.084380,-1304.048096,0.009305,0.000000
15.090001,3.090691,-1304.136963,0.005928,0.000348,0.008837,13.748078,0.700360,0.088370,-1304.136963,0.009739,0.000000
15.350000,3.348373,-1304.048096,0.005898,0.000367,0.009323,14.894309,0.758752,0.093226,-1304.048096,0.010173,0.000000
15.610001,3.527481,-1304.003540,0.005924,0.000383,0.009722,15.691019,0.799339,0.097215,-1304.003540,0.010606,0.000000
15.870001,3.776230,-1304.048096,0.005959,0.000401,0.010190,16.797510,0.855706,0.101901,-1304.048096,0.011040,0.000000
16.130001,4.024971,-1304.003540,0.005959,0.000421,0.010684,17.903965,0.912071,0.106844,-1304.003540,0.011474,0.000000
16.390001,4.175407,-1304.048096,0.005959,0.000435,0.011040,18.573139,0.946161,0.110398,-1304.048096,0.011907,0.000000
16.650002,4.393250,-1304.092529,0.005976,0.000453,0.011508,19.542150,0.995525,0.115080,-1304.092529,0.012341,0.000000
16.910002,4.533630,-1303.959106,0.006032,0.000467,0.011855,20.166595,1.027335,0.118550,-1303.959106,0.012774,0.000000
17.170000,4.804718,-1304.048096,0.006036,0.000483,0.012280,21.372454,1.088765,0.122801,-1304.048096,0.013208,0.000000
17.430000,5.032608,-1304.048096,0.006032,0.000502,0.012740,22.386158,1.140405,0.127396,-1304.048096,0.013642,0.000000
17.690001,5.073570,-1304.048096,0.006049,0.000515,0.013078,22.568367,1.149687,0.130779,-1304.048096,0.014075,0.000000
17.950001,5.624687,-1304.136963,0.006114,0.000539,0.013702,25.019857,1.274572,0.137021,-1304.136963,0.014509,0.000000
18.210001,5.691338,-1304.003540,0.006101,0.000555,0.014101,25.316334,1.289676,0.141010,-1304.003540,0.014942,0.000000
18.470001,5.842148,-1304.092529,0.006127,0.000570,0.014483,25.987171,1.323850,0.144825,-1304.092529,0.015376,0.000000
18.730001,6.112488,-1304.003540,0.006101,0.000591,0.015012,27.189703,1.385110,0.150117,-1304.003540,0.015810,0.000000
18.990002,6.196648,-1304.003540,0.006170,0.000602,0.015280,27.564066,1.404180,0.152804,-1304.003540,0.016243,0.000000
19.250000,6.554123,-1304.048096,0.006122,0.000624,0.015862,29.154196,1.485186,0.158617,-1304.048096,0.016677,0.000000
19.510000,6.703445,-1304.003540,0.006187,0.000637,0.016174,29.818415,1.519022,0.161736,-1304.003540,0.017110,0.000000
19.770000,7.071724,-1303.959106,0.006174,0.000659,0.016746,31.456598,1.602476,0.167463,-1303.959106,0.017544,0.000000
20.030001,7.350632,-1304.048096,0.006217,0.000678,0.017232,32.697243,1.665677,0.172319,-1304.048096,0.017977,0.000000
20.290001,7.430687,-1303.959106,0.006260,0.000693,0.017605,33.053345,1.683818,0.176047,-1303.959106,0.018411,0.000000
20.550001,7.647041,-1304.092529,0.006213,0.000708,0.017995,34.015739,1.732844,0.179949,-1304.092529,0.018845,0.000000
20.810001,7.762100,-1303.959106,0.006226,0.000721,0.018307,34.527546,1.758917,0.183072,-1303.959106,0.019278,0.000000
21.070002,8.227936,-1304.048096,0.006321,0.000744,0.018906,36.599686,1.864477,0.189056,-1304.048096,0.019712,0.000000
21.330002,8.308746,-1304.003540,0.006260,0.000757,0.019227,36.959148,1.882789,0.192265,-1304.003540,0.020145,0.000000
21.590000,8.417107,-1304.048096,0.006278,0.000767,0.019469,37.441162,1.907344,0.194691,-1304.048096,0.020579,0.000000
21.850000,9.160362,-1304.048096,0.006308,0.000797,0.020233,40.747326,2.075768,0.202325,-1304.048096,0.021004,0.000000
22.110001,9.304840,-1303.959106,0.006338,0.000815,0.020692,41.389996,2.108507,0.206920,-1303.959106,0.021438,0.000000
22.370001,9.278778,-1304.048096,0.006308,0.000826,0.020978,41.274067,2.102601,0.209782,-1304.048096,0.021871,0.000000
22.630001,9.531616,-1304.048096,0.006347,0.000841,0.021351,42.398746,2.159895,0.213510,-1304.048096,0.022305,0.000000
22.890001,9.899147,-1304.003540,0.006368,0.000859,0.021828,44.033604,2.243179,0.218282,-1304.003540,0.022739,0.000000
23.150002,10.192574,-1304.048096,0.006398,0.000876,0.022262,45.338833,2.309670,0.222616,-1304.048096,0.023172,0.000000
23.410002,10.382484,-1303.914551,0.006424,0.000891,0.022626,46.183598,2.352705,0.226261,-1303.914551,0.023606,0.000000
23.670002,10.602928,-1304.003540,0.006450,0.000906,0.023016,47.164181,2.402658,0.230163,-1304.003540,0.024039,0.000000
23.930000,11.124626,-1304.048096,0.006403,0.000929,0.023589,49.484810,2.520876,0.235886,-1304.048096,0.024473,0.000000
24.190001,11.073982,-1304.003540,0.006450,0.000942,0.023935,49.259533,2.509400,0.239353,-1304.003540,0.024907,0.000000
24.450001,11.590836,-1304.092529,0.006437,0.000962,0.024430,51.558613,2.626521,0.244296,-1304.092529,0.025340,0.000000
24.710001,11.918526,-1304.048096,0.006480,0.000981,0.024916,53.016251,2.700776,0.249156,-1304.048096,0.025774,0.000000
24.970001,12.231689,-1304.048096,0.006510,0.000999,0.025366,54.409271,2.771740,0.253664,-1304.048096,0.026208,0.000000
25.230001,12.397766,-1304.048096,0.006554,0.001015,0.025774,55.148018,2.809374,0.257740,-1304.048096,0.026641,0.000000
25.490002,12.728058,-1304.003540,0.006558,0.001030,0.026173,56.617229,2.884219,0.261729,-1304.003540,0.027075,0.000000
25.750002,12.917969,-1304.092529,0.006545,0.001045,0.026537,57.461994,2.927254,0.265370,-1304.092529,0.027508,0.000000
26.010002,13.516747,-1303.959106,0.006579,0.001070,0.027170,60.125492,3.062939,0.271702,-1303.959106,0.027942,0.000000
26.270000,13.435944,-1304.136963,0.006614,0.001080,0.027430,59.766064,3.044628,0.274303,-1304.136963,0.028376,0.000000
26.530001,13.860069,-1304.048096,0.006588,0.001100,0.027933,61.652668,3.140737,0.279333,-1304.048096,0.028809,0.000000
26.790001,14.366127,-1304.003540,0.006622,0.001122,0.028506,63.903725,3.255411,0.285056,-1304.003540,0.029243,0.000000
27.050001,14.568695,-1304.092529,0.006644,0.001137,0.028887,64.804794,3.301313,0.288875,-1304.092529,0.029677,0.000000
27.310001,14.621574,-1304.003540,0.006622,0.001150,0.029199,65.040009,3.313296,0.291993,-1304.003540,0.030110,0.000000
27.570002,14.906815,-1304.048096,0.006679,0.001166,0.029624,66.308823,3.377933,0.296244,-1304.048096,0.030544,0.000000
27.830002,15.617302,-1304.048096,0.006722,0.001191,0.030240,69.469231,3.538931,0.302402,-1304.048096,0.030977,0.000000
28.090002,15.648949,-1304.003540,0.006704,0.001204,0.030587,69.610001,3.546103,0.305869,-1304.003540,0.031411,0.000000
28.350002,15.787102,-1304.048096,0.006726,0.001222,0.031029,70.224533,3.577408,0.310293,-1304.048096,0.031845,0.000000
28.610001,16.175858,-1304.048096,0.006717,0.001238,0.031446,71.953812,3.665502,0.314457,-1304.048096,0.032278,0.000000
28.870001,16.395187,-1304.048096,0.006765,0.001255,0.031879,72.929436,3.715203,0.318790,-1304.048096,0.032712,0.000000
29.130001,16.465561,-1304.003540,0.006735,0.001267,0.032174,73.242470,3.731149,0.321743,-1304.003540,0.033145,0.000000
29.390001,16.878525,-1303.959106,0.006817,0.001285,0.032642,75.079430,3.824728,0.326424,-1303.959106,0.033579,0.000000
29.650002,17.204353,-1304.048096,0.006748,0.001303,0.033085,76.528786,3.898562,0.330845,-1304.048096,0.034013,0.000000
29.910002,17.676147,-1304.048096,0.006864,0.001325,0.033648,78.627434,4.005472,0.336485,-1304.048096,0.034446,0.000000
30.170002,17.620293,-1304.003540,0.006847,0.001338,0.033986,78.378975,3.992815,0.339865,-1304.003540,0.034880,0.000000
30.430002,17.982605,-1304.048096,0.006808,0.001358,0.034489,79.990623,4.074916,0.344895,-1304.048096,0.035313,0.000000
30.690001,18.035484,-1304.003540,0.006860,0.001369,0.034784,80.225838,4.086899,0.347843,-1304.003540,0.035747,0.000000
30.950001,18.403389,-1304.048096,0.006916,0.001389,0.035270,81.862366,4.170267,0.352699,-1304.048096,0.036172,0.000000
31.210001,18.472275,-1303.959106,0.006881,0.001400,0.035565,82.168785,4.185877,0.355648,-1303.959106,0.036606,0.000000
31.470001,18.736664,-1303.959106,0.006937,0.001417,0.035990,83.344841,4.245789,0.359898,-1303.959106,0.037039,0.000000
31.730001,19.613602,-1304.048096,0.006933,0.001443,0.036657,87.245659,4.444506,0.366575,-1304.048096,0.037473,0.000000
31.990002,19.516785,-1303.959106,0.006954,0.001458,0.037031,86.814995,4.422567,0.370307,-1303.959106,0.037906,0.000000
32.250000,19.641159,-1304.048096,0.006976,0.001473,0.037421,87.368240,4.450750,0.374209,-1304.048096,0.038340,0.000000
32.510002,19.686211,-1304.003540,0.007032,0.001489,0.037820,87.568642,4.460959,0.378198,-1304.003540,0.038774,0.000000
32.770000,20.206047,-1303.959106,0.007002,0.001509,0.038323,89.880989,4.578756,0.383228,-1303.959106,0.039207,0.000000
33.030003,20.159126,-1304.048096,0.007006,0.001520,0.038618,89.672272,4.568123,0.386177,-1304.048096,0.039641,0.000000
33.290001,20.462234,-1303.914551,0.007006,0.001537,0.039042,91.020561,4.636809,0.390423,-1303.914551,0.040074,0.000000
33.550003,21.259117,-1304.048096,0.007088,0.001563,0.039693,94.565277,4.817385,0.396930,-1304.048096,0.040508,0.000000
33.810001,21.455353,-1304.003540,0.007118,0.001580,0.040127,95.438179,4.861853,0.401267,-1304.003540,0.040942,0.000000
34.070004,21.517914,-1303.959106,0.007092,0.001597,0.040551,95.716461,4.876029,0.405514,-1303.959106,0.041375,0.000000
34.330002,21.569672,-1304.048096,0.007080,0.001613,0.040959,95.946693,4.887757,0.409590,-1304.048096,0.041809,0.000000
34.590000,21.594994,-1303.914551,0.007148,0.001628,0.041358,96.059326,4.893496,0.413579,-1303.914551,0.042242,0.000000
34.850002,21.733147,-1304.048096,0.007114,0.001642,0.041705,96.673866,4.924801,0.417050,-1304.048096,0.042676,0.000000
35.110001,21.904434,-1304.003540,0.007127,0.001656,0.042069,97.435791,4.963616,0.420691,-1304.003540,0.043110,0.000000
35.370003,22.568001,-1304.003540,0.007170,0.001680,0.042667,100.387482,5.113982,0.426675,-1304.003540,0.043543,0.000000
35.630001,23.159332,-1304.048096,0.007226,0.001702,0.043222,103.017853,5.247980,0.432224,-1304.048096,0.043977,0.000000
35.890003,22.966438,-1303.914551,0.007269,0.001718,0.043630,102.159821,5.204269,0.436300,-1303.914551,0.044410,0.000000
36.150002,22.916542,-1304.048096,0.007213,0.001731,0.043968,101.937874,5.192963,0.439684,-1304.048096,0.044844,0.000000
36.410000,23.119484,-1304.003540,0.007252,0.001749,0.044437,102.840599,5.238950,0.444366,-1304.003540,0.045278,0.000000
36.670002,23.401001,-1304.003540,0.007325,0.001766,0.044853,104.092850,5.302742,0.448529,-1304.003540,0.045711,0.000000
36.930000,23.545853,-1304.048096,0.007265,0.001781,0.045243,104.737183,5.335567,0.452431,-1304.048096,0.046145,0.000000
37.190002,23.916733,-1303.959106,0.007338,0.001800,0.045729,106.386940,5.419609,0.457287,-1303.959106,0.046579,0.000000
37.450001,24.402313,-1304.003540,0.007355,0.001822,0.046267,108.546913,5.529644,0.462666,-1304.003540,0.047012,0.000000
37.710003,24.311447,-1303.959106,0.007351,0.001834,0.046588,108.142715,5.509053,0.465875,-1303.959106,0.047446,0.000000
37.970001,24.553123,-1304.003540,0.007347,0.001852,0.047047,109.217751,5.563817,0.470470,-1304.003540,0.047880,0.000000
38.230003,24.560944,-1304.003540,0.007420,0.001868,0.047446,109.252533,5.565589,0.474459,-1304.003540,0.048313,0.000000
38.490002,24.804474,-1303.959106,0.007403,0.001886,0.047905,110.335808,5.620774,0.479054,-1303.959106,0.048747,0.000000
38.750000,24.987305,-1304.048096,0.007407,0.001901,0.048296,111.149086,5.662204,0.482956,-1304.048096,0.049181,0.000000
39.010002,24.785851,-1304.003540,0.007450,0.001913,0.048599,110.252968,5.616554,0.485992,-1304.003540,0.049614,0.000000
39.270000,25.670609,-1304.003540,0.007480,0.001938,0.049215,114.188568,5.817043,0.492150,-1304.003540,0.050048,0.000000
39.530003,25.915260,-1304.003540,0.007446,0.001955,0.049649,115.276833,5.872482,0.496487,-1304.003540,0.050481,0.000000
39.790001,25.906693,-1303.959106,0.007468,0.001969,0.050022,115.238724,5.870541,0.500216,-1303.959106,0.050915,0.000000
40.050003,26.249649,-1304.048096,0.007511,0.001990,0.050542,116.764267,5.948256,0.505420,-1304.048096,0.051340,0.000000
40.310001,26.004257,-1304.003540,0.007549,0.002000,0.050802,115.672714,5.892649,0.508020,-1304.003540,0.051773,0.000000
40.570004,26.370674,-1304.003540,0.007571,0.002022,0.051366,117.302620,5.975680,0.513659,-1304.003540,0.052207,0.000000
40.830002,26.536751,-1304.048096,0.007580,0.002035,0.051695,118.041367,6.013313,0.516952,-1304.048096,0.052641,0.000000
41.090000,26.850288,-1304.003540,0.007597,0.002056,0.052233,119.436050,6.084363,0.522331,-1304.003540,0.053074,0.000000
41.350002,27.413689,-1304.003540,0.007601,0.002077,0.052745,121.942177,6.212031,0.527448,-1304.003540,0.053508,0.000000
41.610001,27.379425,-1304.003540,0.007644,0.002092,0.053135,121.789764,6.204267,0.531350,-1304.003540,0.053942,0.000000
41.870003,27.381287,-1304.003540,0.007700,0.002107,0.053508,121.798042,6.204688,0.535078,-1304.003540,0.054375,0.000000
42.130001,27.264366,-1304.048096,0.007640,0.002120,0.053837,121.277954,6.178194,0.538375,-1304.048096,0.054809,0.000000
42.390003,27.812866,-1304.003540,0.007700,0.002142,0.054410,123.717812,6.302485,0.544098,-1304.003540,0.055242,0.000000
42.650002,27.741371,-1304.092529,0.007692,0.002155,0.054739,123.399780,6.286284,0.547394,-1304.092529,0.055676,0.000000
42.910004,27.594284,-1304.092529,0.007705,0.002169,0.055086,122.745506,6.252954,0.550861,-1304.092529,0.056110,0.000000
43.170002,28.642891,-1304.003540,0.007756,0.002193,0.055711,127.409943,6.490572,0.557106,-1304.003540,0.056543,0.000000
43.430000,28.984352,-1304.092529,0.007731,0.002213,0.056205,128.928833,6.567948,0.562049,-1304.092529,0.056977,0.000000
43.690002,28.622032,-1304.003540,0.007791,0.002224,0.056482,127.317162,6.485846,0.564824,-1304.003540,0.057410,0.000000
43.950001,28.662994,-1304.048096,0.007808,0.002239,0.056873,127.499367,6.495128,0.568726,-1304.048096,0.057844,0.000000
44.210003,28.822746,-1304.048096,0.007804,0.002256,0.057315,128.209976,6.531328,0.573150,-1304.048096,0.058278,0.000000
44.470001,29.177612,-1304.003540,0.007834,0.002274,0.057766,129.788498,6.611742,0.577658,-1304.003540,0.058711,0.000000
44.730003,29.223419,-1304.048096,0.007899,0.002289,0.058139,129.992264,6.622121,0.581386,-1304.048096,0.059145,0.000000
44.990002,29.322838,-1304.003540,0.007860,0.002305,0.058538,130.434494,6.644650,0.585376,-1304.003540,0.059578,0.000000
45.250004,29.910072,-1304.048096,0.007890,0.002327,0.059110,133.046646,6.777719,0.591102,-1304.048096,0.060012,0.000000
45.510002,29.846771,-1304.048096,0.007920,0.002342,0.059483,132.765076,6.763375,0.594830,-1304.048096,0.060446,0.000000
45.770000,30.152115,-1304.048096,0.007998,0.002360,0.059951,134.123306,6.832567,0.599512,-1304.048096,0.060879,0.000000
46.030003,30.516663,-1304.048096,0.008011,0.002380,0.060446,135.744888,6.915174,0.604455,-1304.048096,0.061313,0.000000
46.290001,30.746048,-1304.048096,0.007989,0.002398,0.060905,136.765259,6.967154,0.609054,-1304.048096,0.061746,0.000000
46.550003,30.502892,-1304.048096,0.008041,0.002411,0.061243,135.683640,6.912054,0.612434,-1304.048096,0.062180,0.000000
46.810001,30.740837,-1304.136963,0.008041,0.002428,0.061660,136.742065,6.965973,0.616597,-1304.136963,0.062614,0.000000
47.070004,30.833183,-1304.048096,0.008084,0.002444,0.062067,137.152847,6.986899,0.620674,-1304.048096,0.063047,0.000000
47.330002,31.550743,-1304.136963,0.008101,0.002468,0.062692,140.344711,7.149500,0.626919,-1304.136963,0.063481,0.000000
47.590004,31.164597,-1304.003540,0.008088,0.002479,0.062961,138.627045,7.061998,0.629606,-1304.003540,0.063914,0.000000
47.850002,31.423019,-1304.048096,0.008123,0.002498,0.063446,139.776566,7.120558,0.634462,-1304.048096,0.064348,0.000000
48.110001,31.676605,-1304.048096,0.008110,0.002516,0.063914,140.904572,7.178021,0.639144,-1304.048096,0.064782,0.000000
48.370003,32.157341,-1304.048096,0.008166,0.002535,0.064400,143.042999,7.286958,0.644004,-1304.048096,0.065215,0.000000
48.630001,31.871353,-1304.092529,0.008175,0.002547,0.064695,141.770859,7.222152,0.646952,-1304.092529,0.065649,0.000000
48.890003,31.999451,-1304.048096,0.008183,0.002562,0.065085,142.340668,7.251179,0.650854,-1304.048096,0.066074,0.000000
49.150002,32.938950,-1304.092529,0.008175,0.002588,0.065744,146.519760,7.464073,0.657444,-1304.092529,0.066507,0.000000
49.410004,32.816811,-1304.136963,0.008252,0.002602,0.066083,145.976471,7.436396,0.660828,-1304.136963,0.066941,0.000000
49.670002,32.419487,-1304.048096,0.008295,0.002617,0.066473,144.209076,7.346361,0.664730,-1304.048096,0.067375,0.000000
49.930004,33.052147,-1304.092529,0.008235,0.002636,0.066950,147.023285,7.489724,0.669499,-1304.092529,0.067808,0.000000
50.190002,33.344093,-1304.048096,0.008257,0.002656,0.067462,148.321930,7.555880,0.674616,-1304.048096,0.068242,0.000000
50.450001,32.994057,-1304.136963,0.008360,0.002666,0.067704,146.764893,7.476560,0.677042,-1304.136963,0.068676,0.000000
50.710003,33.224556,-1304.092529,0.008338,0.002683,0.068155,147.790207,7.528792,0.681554,-1304.092529,0.069109,0.000000
50.970001,33.178383,-1304.048096,0.008338,0.002696,0.068476,147.584824,7.518329,0.684763,-1304.048096,0.069543,0.000000
51.230003,34.250816,-1304.136963,0.008399,0.002723,0.069170,152.355240,7.761346,0.691701,-1304.136963,0.069976,0.000000
51.490002,33.924248,-1304.092529,0.008390,0.002736,0.069499,150.902588,7.687345,0.694994,-1304.092529,0.070410,0.000000
51.750004,34.038940,-1304.048096,0.008416,0.002755,0.069968,151.412766,7.713334,0.699679,-1304.048096,0.070844,0.000000
52.010002,34.130913,-1304.136963,0.008459,0.002768,0.070306,151.821884,7.734176,0.703059,-1304.136963,0.071277,0.000000
52.270004,34.383751,-1304.092529,0.008429,0.002788,0.070809,152.946564,7.791470,0.708090,-1304.092529,0.071711,0.000000
52.530003,34.229965,-1304.092529,0.008528,0.002799,0.071086,152.262497,7.756621,0.710864,-1304.092529,0.072145,0.000000
52.790001,34.419502,-1304.092529,0.008524,0.002819,0.071598,153.105591,7.799571,0.715981,-1304.092529,0.072578,0.000000
53.050003,35.467728,-1304.092529,0.008515,0.002842,0.072188,157.768326,8.037102,0.721878,-1304.092529,0.073012,0.000000
53.310001,35.213402,-1304.048096,0.008528,0.002856,0.072552,156.637039,7.979471,0.725523,-1304.048096,0.073446,0.000000
53.570004,35.271492,-1304.048096,0.008563,0.002871,0.072934,156.895432,7.992634,0.729338,-1304.048096,0.073879,0.000000
53.830002,35.122910,-1304.092529,0.008623,0.002885,0.073280,156.234497,7.958965,0.732805,-1304.092529,0.074313,0.000000
54.090004,35.731369,-1304.136963,0.008636,0.002907,0.073844,158.941071,8.096844,0.738444,-1304.136963,0.074746,0.000000
54.350002,35.476295,-1304.092529,0.008640,0.002920,0.074156,157.806442,8.039043,0.741563,-1304.092529,0.075180,0.000000
54.610004,35.646095,-1304.092529,0.008683,0.002937,0.074590,158.561752,8.077520,0.745901,-1304.092529,0.075613,0.000000
54.870003,36.532715,-1304.048096,0.008645,0.002962,0.075232,162.505630,8.278432,0.752320,-1304.048096,0.076047,0.000000
55.130001,36.672729,-1304.136963,0.008709,0.002978,0.075648,163.128448,8.310159,0.756479,-1304.136963,0.076481,0.000000
55.390003,36.675331,-1304.092529,0.008670,0.002995,0.076064,163.140015,8.310749,0.760643,-1304.092529,0.076914,0.000000
55.650002,36.619476,-1304.092529,0.008774,0.003011,0.076481,162.891571,8.298092,0.764806,-1304.092529,0.077348,0.000000
55.910004,36.414673,-1304.136963,0.008761,0.003026,0.076862,161.980560,8.251683,0.768621,-1304.136963,0.077781,0.000000
56.170002,36.466057,-1304.003540,0.008744,0.003040,0.077227,162.209122,8.263327,0.772266,-1304.003540,0.078215,0.000000
56.430004,36.440742,-1304.048096,0.008834,0.003055,0.077608,162.096512,8.257590,0.776081,-1304.048096,0.078649,0.000000
56.690002,37.023499,-1304.092529,0.008843,0.003078,0.078180,164.688751,8.389645,0.781804,-1304.092529,0.079082,0.000000
56.950005,37.805481,-1304.092529,0.008830,0.003100,0.078744,168.167175,8.566844,0.787440,-1304.092529,0.079516,0.000000
57.210003,37.515030,-1304.092529,0.008886,0.003115,0.079126,166.875183,8.501027,0.791255,-1304.092529,0.079949,0.000000
57.470001,37.312836,-1304.092529,0.008886,0.003129,0.079481,165.975784,8.455210,0.794813,-1304.092529,0.080383,0.000000
57.730003,37.233521,-1304.181519,0.008903,0.003147,0.079932,165.622971,8.437236,0.799321,-1304.181519,0.080817,0.000000
57.990002,37.567909,-1304.092529,0.008925,0.003163,0.080340,167.110413,8.513010,0.803397,-1304.092529,0.081242,0.000000
58.250004,37.453217,-1304.092529,0.008925,0.003180,0.080765,166.600235,8.487020,0.807647,-1304.092529,0.081675,0.000000
58.510002,37.523224,-1304.092529,0.009002,0.003198,0.081242,166.911636,8.502884,0.812416,-1304.092529,0.082109,0.000000
58.770004,38.163704,-1304.092529,0.009041,0.003220,0.081779,169.760635,8.648019,0.817795,-1304.092529,0.082543,0.000000
59.030003,38.021835,-1304.136963,0.009033,0.003232,0.082083,169.129578,8.615871,0.820830,-1304.136963,0.082976,0.000000
59.290001,38.170410,-1304.181519,0.009050,0.003251,0.082569,169.790466,8.649538,0.825686,-1304.181519,0.083410,0.000000
59.550003,37.959648,-1304.092529,0.009046,0.003266,0.082950,168.852951,8.601780,0.829501,-1304.092529,0.083843,0.000000
59.810001,38.140244,-1304.181519,0.009106,0.003285,0.083427,169.656281,8.642702,0.834270,-1304.181519,0.084277,0.000000
60.070004,38.234459,-1304.136963,0.009162,0.003301,0.083835,170.075363,8.664052,0.838347,-1304.136963,0.084710,0.000000
60.330002,37.927620,-1304.181519,0.009110,0.003312,0.084121,168.710480,8.594522,0.841208,-1304.181519,0.085144,0.000000
60.590004,38.728592,-1304.136963,0.009158,0.003336,0.084728,172.273376,8.776024,0.847279,-1304.136963,0.085578,0.000000
60.850002,38.194611,-1304.136963,0.009192,0.003348,0.085049,169.898117,8.655023,0.850489,-1304.136963,0.086011,0.000000
61.110004,39.059265,-1304.181519,0.009235,0.003367,0.085534,173.744293,8.850956,0.855345,-1304.181519,0.086445,0.000000
61.370003,39.383972,-1304.136963,0.009244,0.003388,0.086064,175.188660,8.924535,0.860636,-1304.136963,0.086879,0.000000
61.630001,39.102829,-1304.181519,0.009291,0.003401,0.086384,173.938065,8.860827,0.863842,-1304.181519,0.087312,0.000000
61.890003,39.452118,-1304.136963,0.009270,0.003420,0.086879,175.491791,8.939978,0.868789,-1304.136963,0.087746,0.000000
62.150002,39.580582,-1304.136963,0.009300,0.003434,0.087217,176.063217,8.969088,0.872168,-1304.136963,0.088179,0.000000
62.410004,40.120148,-1304.181519,0.009317,0.003457,0.087815,178.463333,9.091355,0.878152,-1304.181519,0.088613,0.000000
62.670002,40.579659,-1304.136963,0.009339,0.003476,0.088283,180.507339,9.195482,0.882834,-1304.136963,0.089047,0.000000
62.930004,40.527153,-1304.181519,0.009343,0.003490,0.088657,180.273773,9.183584,0.886566,-1304.181519,0.089480,0.000000
63.190002,40.529762,-1304.092529,0.009399,0.003506,0.089047,180.285385,9.184175,0.890468,-1304.092529,0.089914,0.000000
63.450005,40.270966,-1304.092529,0.009378,0.003518,0.089350,179.134201,9.125531,0.893504,-1304.092529,0.090348,0.000000
63.710003,40.884262,-1304.136963,0.009386,0.003539,0.089879,181.862274,9.264506,0.898791,-1304.136963,0.090781,0.000000
63.970001,40.927086,-1304.048096,0.009412,0.003554,0.090269,182.052765,9.274210,0.902694,-1304.048096,0.091215,0.000000
64.230003,40.761002,-1304.225952,0.009481,0.003568,0.090634,181.313995,9.236575,0.906339,-1304.225952,0.091649,0.000000
64.490005,41.778328,-1304.136963,0.009498,0.003592,0.091232,185.839279,9.467105,0.912322,-1304.136963,0.092082,0.000000
64.750000,42.342842,-1304.092529,0.009550,0.003611,0.091718,188.350372,9.595025,0.917178,-1304.092529,0.092516,0.000000
65.010002,41.937698,-1304.181519,0.009511,0.003622,0.091987,186.548203,9.503219,0.919866,-1304.181519,0.092949,0.000000
65.270004,42.006592,-1304.048096,0.009593,0.003638,0.092394,186.854660,9.518830,0.923942,-1304.048096,0.093383,0.000000
65.530006,41.926903,-1304.181519,0.009554,0.003654,0.092819,186.500183,9.500772,0.928192,-1304.181519,0.093817,0.000000
65.790001,42.494026,-1304.136963,0.009602,0.003671,0.093253,189.022873,9.629284,0.932526,-1304.136963,0.094250,0.000000
66.050003,42.644836,-1304.136963,0.009593,0.003687,0.093652,189.693710,9.663458,0.936516,-1304.136963,0.094684,0.000000
66.310005,42.863792,-1304.181519,0.009636,0.003703,0.094050,190.667679,9.713075,0.940505,-1304.181519,0.095117,0.000000
66.570000,43.637955,-1304.092529,0.009697,0.003726,0.094632,194.111313,9.888502,0.946318,-1304.092529,0.095551,0.000000
66.830002,43.642426,-1304.136963,0.009662,0.003741,0.095022,194.131210,9.889515,0.950221,-1304.136963,0.095985,0.000000
67.090004,44.053146,-1304.136963,0.009705,0.003759,0.095482,195.958176,9.982585,0.954815,-1304.136963,0.096410,0.000000
67.350006,44.420311,-1304.136963,0.009692,0.003777,0.095941,197.591415,10.065786,0.959410,-1304.136963,0.096843,0.000000
67.610001,44.924873,-1304.225952,0.009744,0.003796,0.096418,199.835815,10.180121,0.964183,-1304.225952,0.097277,0.000000
67.870003,44.726402,-1304.136963,0.009822,0.003808,0.096722,198.952972,10.135148,0.967219,-1304.136963,0.097710,0.000000
68.130005,44.795288,-1304.225952,0.009753,0.003823,0.097095,199.259399,10.150758,0.970947,-1304.225952,0.098144,0.000000
68.390007,45.445450,-1304.136963,0.009804,0.003844,0.097632,202.151459,10.298086,0.976321,-1304.136963,0.098578,0.000000
68.650002,46.462402,-1304.136963,0.009822,0.003867,0.098213,206.675095,10.528531,0.982135,-1304.136963,0.099011,0.000000
68.910004,46.090401,-1304.136963,0.009817,0.003877,0.098474,205.020340,10.444234,0.984735,-1304.136963,0.099445,0.000000
69.170006,46.556236,-1304.092529,0.009852,0.003896,0.098968,207.092484,10.549793,0.989678,-1304.092529,0.099878,0.000000
69.430000,46.956535,-1304.092529,0.009886,0.003916,0.099462,208.873108,10.640503,0.994621,-1304.092529,0.100312,0.000000
69.690002,47.640213,-1304.136963,0.009865,0.003934,0.099922,211.914246,10.795426,0.999216,-1304.136963,0.100746,0.000000
69.950005,47.278267,-1304.136963,0.009942,0.003943,0.100165,210.304230,10.713408,1.001646,-1304.136963,0.101179,0.000000
70.210007,47.857307,-1304.136963,0.009964,0.003961,0.100615,212.879929,10.844622,1.006154,-1304.136963,0.101613,0.000000
70.470001,48.985222,-1304.092529,0.009977,0.003986,0.101249,217.897156,11.100209,1.012486,-1304.092529,0.102046,0.000000
70.730003,49.252960,-1304.136963,0.009977,0.004000,0.101604,219.088104,11.160880,1.016040,-1304.136963,0.102480,0.000000
70.990005,48.772598,-1304.181519,0.009968,0.004012,0.101908,216.951355,11.052029,1.019075,-1304.181519,0.102914,0.000000
71.250000,50.002174,-1304.136963,0.010029,0.004032,0.102419,222.420776,11.330655,1.024193,-1304.136963,0.103347,0.000000
71.510002,50.545090,-1304.225952,0.010067,0.004049,0.102844,224.835785,11.453681,1.028443,-1304.225952,0.103781,0.000000
71.770004,50.747292,-1304.048096,0.010067,0.004063,0.103208,225.735229,11.499500,1.032084,-1304.048096,0.104214,0.000000
72.030006,51.258560,-1304.181519,0.010037,0.004080,0.103642,228.009460,11.615355,1.036422,-1304.181519,0.104648,0.000000
72.290001,51.614174,-1304.136963,0.010063,0.004094,0.103998,229.591309,11.695939,1.039976,-1304.136963,0.105082,0.000000
72.550003,53.163986,-1304.136963,0.010115,0.004121,0.104683,236.485214,12.047132,1.046830,-1304.136963,0.105515,0.000000
72.810005,53.193031,-1304.181519,0.010102,0.004134,0.104995,236.614426,12.053714,1.049949,-1304.181519,0.105949,0.000000
73.070000,53.754570,-1304.136963,0.010128,0.004151,0.105446,239.112274,12.180960,1.054460,-1304.136963,0.106382,0.000000
73.330002,54.317970,-1304.181519,0.010175,0.004167,0.105845,241.618393,12.308628,1.058450,-1304.181519,0.106816,0.000000
73.590004,54.825882,-1304.136963,0.010175,0.004183,0.106253,243.877701,12.423722,1.062526,-1304.136963,0.107250,0.000000
73.850006,55.295074,-1304.136963,0.010188,0.004197,0.106608,245.964783,12.530043,1.066080,-1304.136963,0.107683,0.000000
74.110001,55.840973,-1304.136963,0.010210,0.004215,0.107050,248.393051,12.653746,1.070505,-1304.136963,0.108117,0.000000
74.370003,57.477921,-1304.181519,0.010223,0.004241,0.107718,255.674561,13.024683,1.077181,-1304.181519,0.108551,0.000000
74.630005,57.815666,-1304.181519,0.010244,0.004252,0.108004,257.176941,13.101217,1.080042,-1304.181519,0.108984,0.000000
74.890007,58.343689,-1304.181519,0.010261,0.004269,0.108438,259.525696,13.220868,1.084380,-1304.181519,0.109418,0.000000
75.150002,58.792023,-1304.136963,0.010253,0.004284,0.108802,261.519989,13.322462,1.088021,-1304.136963,0.109852,0.000000
75.410004,59.951591,-1304.136963,0.010240,0.004305,0.109340,266.678009,13.585225,1.093399,-1304.136963,0.110285,0.000000
75.670006,60.354874,-1304.092529,0.010283,0.004318,0.109669,268.471893,13.676610,1.096692,-1304.092529,0.110719,0.000000
75.930000,61.073921,-1304.181519,0.010348,0.004334,0.110086,271.670380,13.839549,1.100856,-1304.181519,0.111152,0.000000
76.190002,62.533249,-1304.136963,0.010300,0.004359,0.110719,278.161774,14.170238,1.107188,-1304.136963,0.111577,0.000000
76.450005,63.496956,-1304.048096,0.010356,0.004377,0.111170,282.448578,14.388616,1.111696,-1304.048096,0.112011,0.000000
76.710007,64.245049,-1304.181519,0.010339,0.004393,0.111586,285.776245,14.558136,1.115859,-1304.181519,0.112444,0.000000
76.970001,64.899681,-1304.136963,0.010313,0.004409,0.111994,288.688202,14.706478,1.119935,-1304.136963,0.112878,0.000000
77.230003,65.404243,-1304.225952,0.010391,0.004421,0.112306,290.932617,14.820813,1.123058,-1304.225952,0.113312,0.000000
77.490005,66.197395,-1304.092529,0.010382,0.004437,0.112705,294.460724,15.000545,1.127047,-1304.092529,0.113745,0.000000
77.750000,66.951073,-1304.136963,0.010369,0.004453,0.113095,297.813232,15.171330,1.130949,-1304.136963,0.114179,0.000000
78.010002,67.092583,-1304.181519,0.010425,0.004453,0.113104,298.442719,15.203397,1.131036,-1304.181519,0.113355,0.000000
78.270004,66.237617,-1304.136963,0.010451,0.004453,0.113104,294.639648,15.009659,1.131036,-1304.136963,0.113355,0.000000
78.530006,65.508873,-1304.181519,0.010425,0.004451,0.113043,291.398010,14.844522,1.130427,-1304.181519,0.113104,0.000000
78.790001,64.871010,-1304.181519,0.010421,0.004450,0.113026,288.560669,14.699981,1.130257,-1304.181519,0.113104,0.000000
79.050003,64.325844,-1304.136963,0.010460,0.004449,0.113017,286.135651,14.576445,1.130170,-1304.136963,0.113104,0.000000
79.310005,63.825752,-1304.225952,0.010464,0.004449,0.113008,283.911133,14.463122,1.130083,-1304.225952,0.113104,0.000000
79.570007,63.379646,-1304.136963,0.010421,0.004449,0.113008,281.926758,14.362033,1.130083,-1304.136963,0.113104,0.000000
79.830002,62.978607,-1304.181519,0.010451,0.004449,0.113008,280.142822,14.271156,1.130083,-1304.181519,0.113104,0.000000
80.090004,62.630814,-1304.092529,0.010464,0.004449,0.113000,278.595764,14.192345,1.129996,-1304.092529,0.113104,0.000000
80.350006,62.310196,-1304.136963,0.010447,0.004449,0.113000,277.169586,14.119692,1.129996,-1304.136963,0.113104,0.000000
80.610001,62.022354,-1304.181519,0.010417,0.004449,0.113000,275.889221,14.054466,1.129996,-1304.181519,0.113104,0.000000
80.870003,61.754250,-1304.181519,0.010430,0.004449,0.113000,274.696625,13.993712,1.129996,-1304.181519,0.113104,0.000000
81.130005,61.512207,-1304.181519,0.010434,0.004449,0.113000,273.619965,13.938866,1.129996,-1304.181519,0.113104,0.000000
81.390007,61.278351,-1304.048096,0.010442,0.004449,0.113000,272.579712,13.885873,1.129996,-1304.048096,0.113104,0.000000
81.650002,61.064987,-1304.181519,0.010442,0.004449,0.113000,271.630615,13.837524,1.129996,-1304.181519,0.113104,0.000000
81.910004,60.872093,-1304.181519,0.010464,0.004448,0.112991,270.772583,13.793814,1.129908,-1304.181519,0.113104,0.000000
82.170006,60.678833,-1304.225952,0.010468,0.004448,0.112991,269.912933,13.750020,1.129908,-1304.225952,0.113104,0.000000
82.430000,60.513870,-1304.225952,0.010460,0.004448,0.112991,269.179138,13.712639,1.129908,-1304.225952,0.113104,0.000000
82.690002,60.349289,-1304.181519,0.010468,0.004448,0.112991,268.447052,13.675344,1.129908,-1304.181519,0.113104,0.000000
82.950005,60.193260,-1304.136963,0.010529,0.004448,0.112991,267.752991,13.639988,1.129908,-1304.136963,0.113104,0.000000
83.210007,60.061440,-1304.225952,0.010516,0.004448,0.112991,267.166626,13.610116,1.129908,-1304.225952,0.113104,0.000000
83.470001,59.913239,-1304.181519,0.010455,0.004448,0.112991,266.507385,13.576533,1.129908,-1304.181519,0.113104,0.000000
83.730003,59.785141,-1304.270508,0.010464,0.004448,0.112991,265.937592,13.547506,1.129908,-1304.270508,0.113104,0.000000
83.990005,59.671196,-1304.181519,0.010464,0.004448,0.112991,265.430725,13.521687,1.129908,-1304.181519,0.113104,0.000000
84.250008,59.554642,-1304.181519,0.010524,0.004448,0.112991,264.912262,13.495275,1.129908,-1304.181519,0.113104,0.000000
84.510002,59.439209,-1304.225952,0.010473,0.004448,0.112991,264.398804,13.469118,1.129908,-1304.225952,0.113104,0.000000
84.770004,59.318558,-1304.225952,0.010460,0.004448,0.112991,263.862122,13.441777,1.129908,-1304.225952,0.113104,0.000000
85.030006,59.234406,-1304.270508,0.010464,0.004448,0.112991,263.487793,13.422708,1.129908,-1304.270508,0.113104,0.000000
85.290001,59.130135,-1304.225952,0.010468,0.004448,0.112991,263.023987,13.399079,1.129908,-1304.225952,0.113104,0.000000
85.550003,59.033318,-1304.181519,0.010473,0.004448,0.112991,262.593323,13.377141,1.129908,-1304.181519,0.113104,0.000000
85.810005,58.943207,-1304.225952,0.010486,0.004448,0.112991,262.192474,13.356722,1.129908,-1304.225952,0.113104,0.000000
86.070007,58.855324,-1304.092529,0.010503,0.004448,0.112991,261.801544,13.336807,1.129908,-1304.092529,0.113104,0.000000
86.330002,58.778244,-1304.225952,0.010473,0.004448,0.112991,261.458679,13.319341,1.129908,-1304.225952,0.113104,0.000000
86.590004,58.685150,-1304.181519,0.010486,0.004448,0.112991,261.044586,13.298244,1.129908,-1304.181519,0.113104,0.000000
86.850006,58.608070,-1304.225952,0.010529,0.004448,0.112991,260.701721,13.280779,1.129908,-1304.225952,0.113104,0.000000
87.110001,58.539558,-1304.225952,0.010494,0.004448,0.112991,260.396973,13.265254,1.129908,-1304.225952,0.113104,0.000000
87.370003,58.456886,-1304.181519,0.010494,0.004448,0.112991,260.029205,13.246520,1.129908,-1304.181519,0.113104,0.000000
87.630005,58.397682,-1304.136963,0.010490,0.004448,0.112991,259.765869,13.233104,1.129908,-1304.136963,0.113104,0.000000
87.890007,58.319855,-1304.181519,0.010490,0.004448,0.112991,259.419678,13.215467,1.129908,-1304.181519,0.113104,0.000000
88.150002,58.255806,-1304.225952,0.010511,0.004448,0.112991,259.134766,13.200954,1.129908,-1304.225952,0.113104,0.000000
88.410004,58.197342,-1304.225952,0.010490,0.004448,0.112991,258.874695,13.187706,1.129908,-1304.225952,0.113104,0.000000
88.670006,58.126968,-1304.136963,0.010516,0.004448,0.112991,258.561676,13.171760,1.129908,-1304.136963,0.113104,0.000000
88.930008,58.060310,-1304.225952,0.010499,0.004448,0.112991,258.265167,13.156654,1.129908,-1304.225952,0.113104,0.000000
89.190002,58.009300,-1304.181519,0.010529,0.004448,0.112991,258.038269,13.145096,1.129908,-1304.181519,0.113104,0.000000
89.450005,57.948227,-1304.225952,0.010490,0.004448,0.112991,257.766602,13.131255,1.129908,-1304.225952,0.113104,0.000000
89.710007,57.896843,-1304.181519,0.010499,0.004448,0.112991,257.538025,13.119613,1.129908,-1304.181519,0.113104,0.000000
89.970001,57.837631,-1304.181519,0.010524,0.004448,0.112991,257.274628,13.106194,1.129908,-1304.181519,0.113104,0.000000
90.230003,57.784012,-1304.270508,0.010447,0.004448,0.112991,257.036133,13.094044,1.129908,-1304.270508,0.113104,0.000000
90.490005,57.730392,-1304.181519,0.010542,0.004448,0.112991,256.797607,13.081894,1.129908,-1304.181519,0.113104,0.000000
90.750008,57.681236,-1304.181519,0.010529,0.004448,0.112991,256.578949,13.070755,1.129908,-1304.181519,0.113104,0.000000
91.010002,57.632454,-1304.270508,0.010542,0.004448,0.112991,256.361969,13.059700,1.129908,-1304.270508,0.113104,0.000000
91.270004,57.575851,-1304.181519,0.010529,0.004448,0.112991,256.110168,13.046874,1.129908,-1304.181519,0.113104,0.000000
91.530006,57.544579,-1304.225952,0.010490,0.004448,0.112982,255.971069,13.039787,1.129821,-1304.225952,0.113104,0.000000
91.790001,57.495049,-1304.225952,0.010481,0.004448,0.112982,255.750748,13.028564,1.129821,-1304.225952,0.113104,0.000000
92.050003,57.445152,-1304.225952,0.010499,0.004448,0.112982,255.528793,13.017258,1.129821,-1304.225952,0.113104,0.000000
92.310005,57.398232,-1304.225952,0.010486,0.004448,0.112982,255.320084,13.006625,1.129821,-1304.225952,0.113104,0.000000
92.570007,57.358391,-1304.225952,0.010516,0.004448,0.112982,255.142868,12.997597,1.129821,-1304.225952,0.113104,0.000000
92.830002,57.318542,-1304.181519,0.010503,0.004448,0.112982,254.965607,12.988567,1.129821,-1304.181519,0.113104,0.000000
93.090004,57.260086,-1304.225952,0.010494,0.004448,0.112982,254.705582,12.975321,1.129821,-1304.225952,0.113104,0.000000
93.350006,57.229919,-1304.225952,0.010490,0.004448,0.112982,254.571396,12.968485,1.129821,-1304.225952,0.113104,0.000000
93.610008,57.186729,-1304.314941,0.010486,0.004448,0.112982,254.379272,12.958698,1.129821,-1304.314941,0.113104,0.000000
93.870003,57.146141,-1304.181519,0.010511,0.004448,0.112982,254.198730,12.949501,1.129821,-1304.181519,0.113104,0.000000
94.130005,57.118210,-1304.270508,0.010490,0.004448,0.112982,254.074493,12.943172,1.129821,-1304.270508,0.113104,0.000000
94.390007,57.067940,-1304.270508,0.010490,0.004448,0.112982,253.850876,12.931780,1.129821,-1304.270508,0.113104,0.000000
94.650002,57.038895,-1304.225952,0.010516,0.004448,0.112982,253.721680,12.925199,1.129821,-1304.225952,0.113104,0.000000
94.910004,56.997932,-1304.314941,0.010473,0.004448,0.112982,253.539459,12.915916,1.129821,-1304.314941,0.113104,0.000000
95.170006,56.956970,-1304.225952,0.010499,0.004448,0.112982,253.357254,12.906633,1.129821,-1304.225952,0.113104,0.000000
95.430008,56.923828,-1304.225952,0.010473,0.004448,0.112982,253.209839,12.899124,1.129821,-1304.225952,0.113104,0.000000
95.690002,56.912659,-1304.225952,0.010529,0.004448,0.112982,253.160156,12.896593,1.129821,-1304.225952,0.113104,0.000000
95.950005,56.869835,-1304.181519,0.010486,0.004448,0.112982,252.969666,12.886889,1.129821,-1304.181519,0.113104,0.000000
96.210007,56.848610,-1304.181519,0.010529,0.004448,0.112982,252.875244,12.882079,1.129821,-1304.181519,0.113104,0.000000
96.470001,56.788284,-1304.136963,0.010511,0.004448,0.112982,252.606903,12.868409,1.129821,-1304.136963,0.113104,0.000000
96.730003,56.766319,-1304.181519,0.010516,0.004448,0.112982,252.509201,12.863431,1.129821,-1304.181519,0.113104,0.000000
96.990005,56.734291,-1304.270508,0.010511,0.004448,0.112982,252.366730,12.856174,1.129821,-1304.270508,0.113104,0.000000
97.250008,56.702271,-1304.136963,0.010533,0.004448,0.112982,252.224289,12.848918,1.129821,-1304.136963,0.113104,0.000000
97.510002,56.676575,-1304.270508,0.010520,0.004448,0.112982,252.110001,12.843096,1.129821,-1304.270508,0.113104,0.000000
97.770004,56.647530,-1304.181519,0.010503,0.004448,0.112982,251.980789,12.836514,1.129821,-1304.181519,0.113104,0.000000
98.030006,56.611038,-1304.225952,0.010542,0.004448,0.112982,251.818481,12.828244,1.129821,-1304.225952,0.113104,0.000000
98.290001,56.585716,-1304.225952,0.010468,0.004448,0.112982,251.705841,12.822507,1.129821,-1304.225952,0.113104,0.000000
98.550003,56.557793,-1304.181519,0.010516,0.004448,0.112982,251.581619,12.816179,1.129821,-1304.181519,0.113104,0.000000
98.810005,56.525764,-1304.314941,0.010499,0.004448,0.112982,251.439163,12.808921,1.129821,-1304.314941,0.113104,0.000000
99.070007,56.499702,-1304.225952,0.010529,0.004448,0.112982,251.323227,12.803016,1.129821,-1304.225952,0.113104,0.000000
99.330002,56.476982,-1304.225952,0.010524,0.004448,0.112982,251.222168,12.797867,1.129821,-1304.225952,0.113104,0.000000
99.590004,56.441978,-1304.359375,0.010490,0.004448,0.112982,251.066452,12.789935,1.129821,-1304.359375,0.113104,0.000000
99.850006,56.417404,-1304.181519,0.010546,0.004448,0.112982,250.957153,12.784367,1.129821,-1304.181519,0.113104,0.000000
100.110008,56.388359,-1304.225952,0.010511,0.004448,0.112982,250.827942,12.777784,1.129821,-1304.225952,0.113104,0.000000
100.370003,56.364159,-1304.270508,0.010507,0.004448,0.112982,250.720306,12.772301,1.129821,-1304.270508,0.113104,0.000000
100.630005,56.348885,-1304.270508,0.010499,0.004448,0.112982,250.652359,12.768840,1.129821,-1304.270508,0.113104,0.000000
100.890007,56.310158,-1304.225952,0.010520,0.004448,0.112982,250.480087,12.760064,1.129821,-1304.225952,0.113104,0.000000
101.150002,56.289307,-1304.225952,0.010477,0.004448,0.112982,250.387344,12.755340,1.129821,-1304.225952,0.113104,0.000000
101.410004,56.275162,-1304.225952,0.010490,0.004448,0.112982,250.324417,12.752133,1.129821,-1304.225952,0.113104,0.000000
101.670006,56.243881,-1304.225952,0.010520,0.004448,0.112982,250.185272,12.745046,1.129821,-1304.225952,0.113104,0.000000
101.930008,56.231216,-1304.225952,0.010477,0.004448,0.112982,250.128937,12.742176,1.129821,-1304.225952,0.113104,0.000000
102.190002,56.199570,-1304.314941,0.010511,0.004448,0.112982,249.988174,12.735004,1.129821,-1304.314941,0.113104,0.000000
102.450005,56.177223,-1304.181519,0.010529,0.004448,0.112982,249.888763,12.729940,1.129821,-1304.181519,0.113104,0.000000
102.710007,56.163445,-1304.225952,0.010520,0.004448,0.112982,249.827484,12.726819,1.129821,-1304.225952,0.113104,0.000000
102.970001,56.143707,-1304.225952,0.010529,0.004448,0.112982,249.739685,12.722345,1.129821,-1304.225952,0.113104,0.000000
103.230003,56.103867,-1304.181519,0.010542,0.004448,0.112982,249.562469,12.713318,1.129821,-1304.181519,0.113104,0.000000
103.490005,56.088600,-1304.359375,0.010537,0.004448,0.112982,249.494553,12.709858,1.129821,-1304.359375,0.113104,0.000000
103.750008,56.063278,-1304.225952,0.010486,0.004448,0.112982,249.381912,12.704121,1.129821,-1304.225952,0.113104,0.000000
104.010002,56.045403,-1304.225952,0.010520,0.004448,0.112982,249.302399,12.700070,1.129821,-1304.225952,0.113104,0.000000
104.270004,56.026039,-1304.225952,0.010516,0.004448,0.112982,249.216263,12.695682,1.129821,-1304.225952,0.113104,0.000000
104.530006,55.999229,-1304.225952,0.010537,0.004448,0.112982,249.097015,12.689607,1.129821,-1304.225952,0.113104,0.000000
104.790009,55.995132,-1304.225952,0.010529,0.004448,0.112982,249.078796,12.688679,1.129821,-1304.225952,0.113104,0.000000
105.050003,55.964973,-1304.225952,0.010481,0.004448,0.112982,248.944641,12.681844,1.129821,-1304.225952,0.113104,0.000000
105.310005,55.945236,-1304.225952,0.010542,0.004448,0.112982,248.856842,12.677372,1.129821,-1304.225952,0.113104,0.000000
105.570007,55.913582,-1304.270508,0.010524,0.004448,0.112982,248.716034,12.670198,1.129821,-1304.270508,0.113104,0.000000
105.830002,55.905022,-1304.181519,0.010524,0.004448,0.112982,248.677963,12.668260,1.129821,-1304.181519,0.113104,0.000000
106.090004,55.885658,-1304.225952,0.010511,0.004448,0.112982,248.591827,12.663872,1.129821,-1304.225952,0.113104,0.000000
106.350006,55.859962,-1304.181519,0.010494,0.004448,0.112982,248.477524,12.658049,1.129821,-1304.181519,0.113104,0.000000
106.610008,55.843948,-1304.270508,0.010511,0.004448,0.112982,248.406296,12.654419,1.129821,-1304.270508,0.113104,0.000000
106.870003,55.819374,-1304.225952,0.010503,0.004448,0.112982,248.296982,12.648851,1.129821,-1304.225952,0.113104,0.000000
107.130005,55.804108,-1304.181519,0.010555,0.004448,0.112982,248.229065,12.645391,1.129821,-1304.181519,0.113104,0.000000
107.390007,55.789581,-1304.225952,0.010473,0.004448,0.112982,248.164459,12.642099,1.129821,-1304.225952,0.113104,0.000000
107.650002,55.751976,-1304.136963,0.010533,0.004448,0.112982,247.997177,12.633578,1.129821,-1304.136963,0.113104,0.000000
107.910004,55.741920,-1304.270508,0.010481,0.004448,0.112982,247.952438,12.631300,1.129821,-1304.270508,0.113104,0.000000
108.170006,55.714737,-1304.270508,0.010529,0.004448,0.112982,247.831528,12.625139,1.129821,-1304.270508,0.113104,0.000000
108.400002,55.705803,-1304.225952,0.010481,0.004448,0.112982,247.791794,12.623115,1.129821,-1304.225952,0.113104,0.000000