File: Data/Automembrane/AutoHeating-10wt-1-2_12152023_180445.csv
Time (sec),S:Load (lbs),S:HL1 (DIM),S:LVDT (in),S:Position (in),Ch:Position (mm),Ch:Load (N),Ch:Stress (MPa),Ch:Strain (mm/mm),Ch:HL1 (DIM),Set Point (),Cycles ()
0.110000,-0.002609,-255.187210,-0.000030,-0.000000,-0.000000,-0.011607,-0.000591,-0.000000,-255.187210,0.000199,0.000000
0.370000,0.000366,-255.142731,-0.000026,0.000004,0.000104,0.001629,0.000083,0.001041,-255.142731,0.000685,0.000000
0.630000,-0.019737,-255.231705,-0.000017,0.000157,0.003998,-0.087796,-0.004473,0.039976,-255.231705,0.005021,0.000000
0.890000,0.003723,-255.187210,0.000129,0.000331,0.008412,0.016561,0.000844,0.084119,-255.187210,0.009340,0.000000
1.150000,-0.008942,-255.187210,0.000289,0.000495,0.012575,-0.039774,-0.002026,0.125746,-255.187210,0.013676,0.000000
1.410000,-0.056602,-255.187210,0.000448,0.000668,0.016963,-0.251780,-0.012826,0.169628,-255.187210,0.018012,0.000000
1.670000,0.020103,-255.187210,0.000642,0.000837,0.021264,0.089425,0.004556,0.212643,-255.187210,0.022348,0.000000
1.930000,0.023453,-255.231705,0.000798,0.001004,0.025505,0.104323,0.005314,0.255049,-255.231705,0.026667,0.000000
2.190000,-0.002609,-255.231705,0.000970,0.001179,0.029937,-0.011607,-0.000591,0.299366,-255.231705,0.031003,0.000000
2.450000,0.021591,-255.276184,0.001160,0.001351,0.034325,0.096042,0.004893,0.343248,-255.276184,0.035339,0.000000
2.710000,0.011543,-255.231705,0.001350,0.001521,0.038626,0.051347,0.002616,0.386260,-255.231705,0.039676,0.000000
2.970000,-0.027184,-255.231705,0.001522,0.001689,0.042901,-0.120918,-0.006160,0.429014,-255.231705,0.043994,0.000000
3.230000,0.004837,-255.276184,0.001686,0.001859,0.047212,0.021516,0.001096,0.472116,-255.276184,0.048330,0.000000
3.490000,0.008560,-255.276184,0.001876,0.002034,0.051669,0.038078,0.001940,0.516691,-255.276184,0.052666,0.000000
3.750000,-0.006706,-255.320663,0.002035,0.002202,0.055918,-0.029831,-0.001520,0.559184,-255.320663,0.057003,0.000000
4.010000,0.028671,-255.276184,0.002225,0.002370,0.060186,0.127536,0.006497,0.601855,-255.276184,0.061321,0.000000
4.270000,0.040955,-255.231705,0.002410,0.002547,0.064686,0.182175,0.009280,0.646861,-255.231705,0.065657,0.000000
4.530000,0.016006,-255.320663,0.002600,0.002714,0.068927,0.071200,0.003627,0.689271,-255.320663,0.069994,0.000000
4.790000,0.023827,-255.231705,0.002751,0.002882,0.073194,0.105986,0.005399,0.731938,-255.231705,0.074312,0.000000
5.050000,0.012657,-255.365143,0.002919,0.003057,0.077660,0.056302,0.002868,0.776600,-255.365143,0.078649,0.000000
5.310000,-0.016762,-255.320663,0.003109,0.003226,0.081953,-0.074560,-0.003798,0.819528,-255.320663,0.082985,0.000000
5.570000,0.042450,-255.320663,0.003281,0.003392,0.086150,0.188827,0.009619,0.861499,-255.320663,0.087321,0.000000
5.830000,0.048035,-255.365143,0.003466,0.003569,0.090651,0.213669,0.010885,0.906509,-255.365143,0.091639,0.000000
6.090000,0.023453,-255.276184,0.003617,0.003736,0.094900,0.104323,0.005314,0.949002,-255.276184,0.095976,0.000000
6.350000,0.069260,-255.365143,0.003829,0.003901,0.099080,0.308082,0.015694,0.990802,-255.365143,0.100312,0.000000
6.610000,0.089363,-255.365143,0.003980,0.004078,0.103581,0.397507,0.020250,1.035812,-255.365143,0.104648,0.000000
6.870000,0.102402,-255.320663,0.004161,0.004244,0.107805,0.455506,0.023205,1.078048,-255.320663,0.108967,0.000000
7.130000,0.182083,-255.365143,0.004359,0.004413,0.112098,0.809946,0.041261,1.120976,-255.365143,0.113303,0.000000
7.390000,0.369019,-255.276184,0.004562,0.004592,0.116642,1.641477,0.083621,1.166418,-255.276184,0.117639,0.000000
7.650001,0.788307,-255.409622,0.004712,0.000018,0.000460,3.506566,0.178633,0.004599,-255.409622,0.000538,0.000000
7.910000,0.530258,-255.365143,0.004725,0.000012,0.000304,2.358706,0.120158,0.003035,-255.365143,0.000538,0.000000
8.170000,0.576057,-255.365143,0.004725,0.000012,0.000304,2.562431,0.130536,0.003035,-255.365143,0.000581,0.000000
8.430000,0.543663,-255.409622,0.004717,0.000012,0.000304,2.418334,0.123196,0.003035,-255.409622,0.001015,0.000000
8.690001,0.619995,-255.365143,0.004738,0.000031,0.000781,2.757876,0.140493,0.007808,-255.365143,0.001448,0.000000
8.950001,0.678459,-255.409622,0.004730,0.000042,0.001076,3.017937,0.153741,0.010757,-255.409622,0.001882,0.000000
9.210000,0.739899,-255.365143,0.004734,0.000054,0.001371,3.291234,0.167663,0.013705,-255.365143,0.002316,0.000000
9.470000,0.825546,-255.454102,0.004803,0.000075,0.001908,3.672213,0.187071,0.019080,-255.454102,0.002749,0.000000
9.730000,0.910820,-255.409622,0.004799,0.000098,0.002489,4.051530,0.206395,0.024889,-255.409622,0.003183,0.000000
9.990001,0.931671,-255.454102,0.004820,0.000111,0.002819,4.144280,0.211120,0.028186,-255.454102,0.003616,0.000000
10.250001,0.972633,-255.498581,0.004829,0.000128,0.003244,4.326489,0.220402,0.032437,-255.498581,0.004050,0.000000
10.510000,1.032959,-255.498581,0.004842,0.000148,0.003747,4.594831,0.234072,0.037467,-255.498581,0.004484,0.000000
10.770000,1.122330,-255.409622,0.004876,0.000164,0.004171,4.992372,0.254324,0.041713,-255.409622,0.004917,0.000000
11.030001,1.153976,-255.543060,0.004863,0.000177,0.004484,5.133143,0.261495,0.044836,-255.543060,0.005351,0.000000
11.290001,1.207970,-255.454102,0.004876,0.000188,0.004787,5.373317,0.273730,0.047871,-255.454102,0.005784,0.000000
11.550000,1.269417,-255.454102,0.004889,0.000207,0.005256,5.646648,0.287654,0.052557,-255.454102,0.006218,0.000000
11.810000,1.365486,-255.543060,0.004932,0.000231,0.005862,6.073986,0.309424,0.058624,-255.543060,0.006652,0.000000
12.070001,1.393417,-255.454102,0.004958,0.000242,0.006149,6.198230,0.315753,0.061489,-255.454102,0.007085,0.000000
12.330001,1.429161,-255.498581,0.004980,0.000260,0.006600,6.357226,0.323853,0.065997,-255.498581,0.007519,0.000000
12.590000,1.543106,-255.498581,0.004988,0.000284,0.007216,6.864079,0.349673,0.072155,-255.498581,0.007952,0.000000
12.850000,1.579971,-255.498581,0.004997,0.000297,0.007545,7.028063,0.358027,0.075452,-255.498581,0.008386,0.000000
13.110001,1.641045,-255.498581,0.005010,0.000311,0.007901,7.299731,0.371866,0.079006,-255.498581,0.008820,0.000000
13.370001,1.718498,-255.498581,0.005053,0.000330,0.008386,7.644262,0.389417,0.083862,-255.498581,0.009253,0.000000
13.630001,1.804512,-255.543060,0.005083,0.000352,0.008933,8.026871,0.408908,0.089327,-255.543060,0.009687,0.000000
13.890000,1.816803,-255.498581,0.005092,0.000366,0.009306,8.081543,0.411693,0.093055,-255.498581,0.010121,0.000000
14.150001,1.846588,-255.587540,0.005109,0.000382,0.009713,8.214034,0.418443,0.097132,-255.587540,0.010554,0.000000
14.410001,1.841751,-255.587540,0.005118,0.000393,0.009991,8.192518,0.417347,0.099906,-255.587540,0.010988,0.000000
14.670001,1.997406,-255.543060,0.005165,0.000419,0.010650,8.884906,0.452619,0.106496,-255.543060,0.011422,0.000000
14.930000,2.024582,-255.543060,0.005157,0.000432,0.010979,9.005790,0.458777,0.109792,-255.543060,0.011855,0.000000
15.190001,2.039482,-255.587540,0.005182,0.000443,0.011257,9.072069,0.462153,0.112567,-255.587540,0.012289,0.000000
15.450001,2.186943,-255.632019,0.005195,0.000470,0.011933,9.728008,0.495568,0.119330,-255.632019,0.012714,0.000000
15.710001,2.237579,-255.543060,0.005234,0.000488,0.012402,9.953250,0.507043,0.124016,-255.543060,0.013147,0.000000
15.970001,2.165344,-255.587540,0.005269,0.000503,0.012774,9.631932,0.490674,0.127744,-255.587540,0.013581,0.000000
16.230001,2.226784,-255.587540,0.005264,0.000519,0.013173,9.905229,0.504596,0.131733,-255.587540,0.014014,0.000000
16.490002,2.335892,-255.676514,0.005290,0.000539,0.013702,10.390565,0.529321,0.137025,-255.676514,0.014448,0.000000
16.750000,2.310196,-255.632019,0.005303,0.000553,0.014049,10.276265,0.523498,0.140492,-255.632019,0.014882,0.000000
17.010000,2.337379,-255.676514,0.005346,0.000564,0.014327,10.397183,0.529658,0.143266,-255.676514,0.015315,0.000000
17.270000,2.455795,-255.587540,0.005359,0.000586,0.014882,10.923923,0.556491,0.148818,-255.587540,0.015749,0.000000
17.530001,2.523193,-255.676514,0.005411,0.000607,0.015428,11.223724,0.571764,0.154280,-255.676514,0.016183,0.000000
17.790001,2.499359,-255.632019,0.005411,0.000621,0.015775,11.117704,0.566363,0.157751,-255.632019,0.016616,0.000000
18.050001,2.514252,-255.676514,0.005433,0.000637,0.016191,11.183950,0.569738,0.161914,-255.676514,0.017050,0.000000
18.310001,2.528778,-255.676514,0.005437,0.000652,0.016564,11.248567,0.573029,0.165642,-255.676514,0.017484,0.000000
18.570002,2.576073,-255.676514,0.005493,0.000668,0.016972,11.458943,0.583746,0.169718,-255.676514,0.017917,0.000000
18.830002,2.660599,-255.720993,0.005523,0.000688,0.017475,11.834934,0.602900,0.174749,-255.720993,0.018351,0.000000
19.090000,2.590965,-255.632019,0.005527,0.000699,0.017761,11.525189,0.587121,0.177610,-255.632019,0.018784,0.000000
19.350000,2.761139,-255.720993,0.005553,0.000725,0.018403,12.282159,0.625683,0.184025,-255.720993,0.019218,0.000000
19.610001,2.729485,-255.676514,0.005558,0.000739,0.018767,12.141354,0.618510,0.187670,-255.676514,0.019652,0.000000
19.870001,2.736565,-255.676514,0.005605,0.000757,0.019227,12.172848,0.620114,0.192265,-255.676514,0.020085,0.000000
20.130001,2.763000,-255.765472,0.005631,0.000775,0.019686,12.290440,0.626105,0.196860,-255.765472,0.020519,0.000000
20.390001,2.802475,-255.676514,0.005639,0.000792,0.020120,12.466031,0.635050,0.201197,-255.676514,0.020952,0.000000
20.650002,2.828163,-255.720993,0.005652,0.000810,0.020579,12.580298,0.640871,0.205792,-255.720993,0.021386,0.000000
20.910002,2.769699,-255.720993,0.005670,0.000820,0.020822,12.320237,0.627623,0.208222,-255.720993,0.021820,0.000000
21.170000,2.932800,-255.765472,0.005721,0.000845,0.021472,13.045747,0.664582,0.214725,-255.765472,0.022253,0.000000
21.430000,2.873970,-255.720993,0.005743,0.000860,0.021846,12.784058,0.651251,0.218457,-255.720993,0.022687,0.000000
21.690001,2.888863,-255.809952,0.005760,0.000876,0.022245,12.850303,0.654626,0.222446,-255.809952,0.023120,0.000000
21.950001,2.877693,-255.765472,0.005777,0.000893,0.022678,12.800618,0.652095,0.226780,-255.765472,0.023554,0.000000
22.210001,2.871361,-255.765472,0.005808,0.000910,0.023112,12.772450,0.650660,0.231117,-255.765472,0.023988,0.000000
22.470001,2.940247,-255.765472,0.005846,0.000926,0.023528,13.078870,0.666269,0.235280,-255.765472,0.024421,0.000000
22.730001,2.911949,-255.809952,0.005842,0.000943,0.023944,12.952997,0.659857,0.239444,-255.809952,0.024855,0.000000
22.990002,2.930199,-255.809952,0.005855,0.000957,0.024317,13.034175,0.663992,0.243172,-255.809952,0.025288,0.000000
23.250002,3.062386,-255.809952,0.005907,0.000983,0.024959,13.622171,0.693947,0.249587,-255.809952,0.025722,0.000000
23.510000,3.009514,-255.809952,0.005915,0.000999,0.025366,13.386986,0.681966,0.253664,-255.809952,0.026156,0.000000
23.770000,2.949928,-255.809952,0.005959,0.001014,0.025765,13.121937,0.668463,0.257653,-255.809952,0.026589,0.000000
24.030001,2.963707,-255.854431,0.005971,0.001028,0.026112,13.183227,0.671586,0.261124,-255.854431,0.027023,0.000000
24.290001,3.035202,-255.809952,0.005997,0.001048,0.026615,13.501253,0.687787,0.266154,-255.809952,0.027456,0.000000
24.550001,3.031479,-255.809952,0.006032,0.001065,0.027049,13.484692,0.686943,0.270488,-255.809952,0.027881,0.000000
24.810001,2.990150,-255.898911,0.006053,0.001075,0.027309,13.300854,0.677578,0.273092,-255.898911,0.028315,0.000000
25.070002,3.092918,-255.809952,0.006079,0.001098,0.027881,13.757988,0.700865,0.278814,-255.809952,0.028749,0.000000
25.330002,3.123833,-255.943390,0.006079,0.001119,0.028419,13.895502,0.707871,0.284193,-255.943390,0.029182,0.000000
25.590002,3.076912,-255.809952,0.006131,0.001132,0.028749,13.686788,0.697238,0.287485,-255.809952,0.029616,0.000000
25.850000,3.029991,-255.854431,0.006161,0.001148,0.029156,13.478074,0.686606,0.291562,-255.854431,0.030049,0.000000
26.110001,3.094788,-255.854431,0.006161,0.001168,0.029659,13.766303,0.701289,0.296592,-255.854431,0.030483,0.000000
26.370001,3.136490,-255.898911,0.006204,0.001186,0.030136,13.951804,0.710739,0.301361,-255.898911,0.030917,0.000000
26.630001,3.091431,-255.943390,0.006200,0.001197,0.030414,13.751370,0.700528,0.304139,-255.943390,0.031350,0.000000
26.890001,3.095528,-255.854431,0.006247,0.001215,0.030856,13.769595,0.701457,0.308560,-255.854431,0.031784,0.000000
27.150002,3.235542,-255.943390,0.006260,0.001238,0.031446,14.392411,0.733184,0.314457,-255.943390,0.032217,0.000000
27.410002,3.198677,-255.898911,0.006269,0.001255,0.031871,14.228426,0.724831,0.318707,-255.898911,0.032651,0.000000
27.670002,3.136490,-255.943390,0.006295,0.001270,0.032261,13.951804,0.710739,0.322609,-255.943390,0.033085,0.000000
27.930002,3.116379,-255.943390,0.006325,0.001285,0.032642,13.862345,0.706182,0.326424,-255.943390,0.033518,0.000000
28.190001,3.247086,-255.987869,0.006329,0.001305,0.033137,14.443758,0.735800,0.331368,-255.987869,0.033952,0.000000
28.450001,3.180428,-255.987869,0.006377,0.001317,0.033449,14.147248,0.720695,0.334490,-255.987869,0.034386,0.000000
28.710001,3.141701,-255.943390,0.006385,0.001330,0.033779,13.974983,0.711920,0.337787,-255.943390,0.034819,0.000000
28.970001,3.319695,-255.943390,0.006424,0.001357,0.034472,14.766739,0.752254,0.344724,-255.943390,0.035253,0.000000
29.230001,3.276871,-256.032349,0.006459,0.001374,0.034897,14.576249,0.742550,0.348971,-256.032349,0.035687,0.000000
29.490002,3.242989,-255.987869,0.006472,0.001388,0.035244,14.425533,0.734872,0.352442,-255.987869,0.036120,0.000000
29.750002,3.250809,-255.987869,0.006493,0.001406,0.035721,14.460320,0.736644,0.357211,-255.987869,0.036554,0.000000
30.010002,3.324913,-255.943390,0.006502,0.001425,0.036198,14.789951,0.753436,0.361980,-255.943390,0.036987,0.000000
30.270002,3.319321,-256.032349,0.006545,0.001442,0.036623,14.765076,0.752169,0.366230,-256.032349,0.037421,0.000000
30.530001,3.277992,-256.121307,0.006562,0.001452,0.036892,14.581238,0.742804,0.368917,-256.121307,0.037855,0.000000
30.790001,3.269051,-256.032349,0.006562,0.001468,0.037299,14.541463,0.740777,0.372994,-256.032349,0.038288,0.000000
31.050001,3.479820,-256.032349,0.006597,0.001497,0.038019,15.479013,0.788539,0.380193,-256.032349,0.038722,0.000000
31.310001,3.368851,-256.076843,0.006610,0.001509,0.038340,14.985396,0.763392,0.383402,-256.076843,0.039155,0.000000
31.570002,3.354324,-255.987869,0.006674,0.001528,0.038808,14.920780,0.760101,0.388084,-255.987869,0.039589,0.000000
31.830002,3.432899,-256.076843,0.006691,0.001548,0.039311,15.270300,0.777906,0.393114,-256.076843,0.040023,0.000000
32.090000,3.449654,-256.076843,0.006713,0.001563,0.039710,15.344826,0.781703,0.397104,-256.076843,0.040456,0.000000
32.350002,3.409065,-256.121307,0.006726,0.001575,0.040014,15.164280,0.772505,0.400139,-256.121307,0.040890,0.000000
32.610001,3.396408,-255.987869,0.006752,0.001588,0.040326,15.107978,0.769637,0.403262,-255.987869,0.041323,0.000000
32.870003,3.509605,-256.076843,0.006760,0.001610,0.040898,15.611505,0.795288,0.408984,-256.076843,0.041757,0.000000
33.130001,3.553177,-256.121307,0.006799,0.001630,0.041401,15.805320,0.805161,0.414015,-256.121307,0.042191,0.000000
33.390003,3.470879,-256.121307,0.006817,0.001643,0.041731,15.439240,0.786512,0.417311,-256.121307,0.042624,0.000000
33.650002,3.539398,-256.121307,0.006838,0.001663,0.042234,15.744029,0.802039,0.422341,-256.121307,0.043049,0.000000
33.910000,3.636955,-256.076843,0.006868,0.001683,0.042755,16.177984,0.824146,0.427546,-256.076843,0.043483,0.000000
34.170002,3.572906,-256.121307,0.006877,0.001696,0.043075,15.893082,0.809632,0.430751,-256.121307,0.043917,0.000000
34.430000,3.602325,-256.165802,0.006881,0.001710,0.043440,16.023943,0.816299,0.434396,-256.165802,0.044350,0.000000
34.690002,3.642914,-256.121307,0.006916,0.001729,0.043925,16.204491,0.825496,0.439252,-256.121307,0.044784,0.000000
34.950001,3.710686,-256.165802,0.006950,0.001751,0.044471,16.505955,0.840853,0.444714,-256.165802,0.045217,0.000000
35.210003,3.660416,-256.121307,0.006976,0.001765,0.044827,16.282343,0.829462,0.448272,-256.121307,0.045651,0.000000
35.470001,3.668983,-256.165802,0.007011,0.001782,0.045252,16.320454,0.831404,0.452518,-256.165802,0.046085,0.000000
35.730003,3.613869,-256.165802,0.007023,0.001793,0.045530,16.075291,0.818914,0.455296,-256.165802,0.046518,0.000000
35.990002,3.761703,-256.121307,0.007049,0.001818,0.046189,16.732893,0.852414,0.461886,-256.121307,0.046952,0.000000
36.250000,3.750908,-256.165802,0.007067,0.001832,0.046527,16.684872,0.849968,0.465270,-256.165802,0.047385,0.000000
36.510002,3.708450,-256.165802,0.007075,0.001842,0.046796,16.496012,0.840347,0.467957,-256.165802,0.047819,0.000000
36.770000,3.881607,-256.165802,0.007105,0.001869,0.047472,17.266251,0.879585,0.474720,-256.165802,0.048252,0.000000
37.030003,3.879745,-256.210266,0.007131,0.001887,0.047932,17.257969,0.879163,0.479315,-256.210266,0.048686,0.000000
37.290001,3.793358,-256.210266,0.007157,0.001902,0.048305,16.873699,0.859587,0.483047,-256.210266,0.049120,0.000000
37.550003,3.796707,-256.210266,0.007183,0.001918,0.048712,16.888597,0.860346,0.487124,-256.210266,0.049553,0.000000
37.810001,3.938210,-256.254761,0.007209,0.001939,0.049241,17.518030,0.892411,0.492411,-256.254761,0.049987,0.000000
38.070004,3.886818,-256.210266,0.007230,0.001952,0.049588,17.289429,0.880766,0.495882,-256.210266,0.050420,0.000000
38.330002,3.832451,-256.299225,0.007235,0.001963,0.049848,17.047592,0.868446,0.498482,-256.299225,0.050854,0.000000
38.590000,3.987358,-256.165802,0.007252,0.001985,0.050429,17.736654,0.903548,0.504292,-256.165802,0.051288,0.000000
38.850002,4.050667,-256.254761,0.007299,0.002007,0.050976,18.018267,0.917894,0.509757,-256.254761,0.051721,0.000000
39.110001,3.973953,-256.254761,0.007330,0.002020,0.051305,17.677027,0.900511,0.513054,-256.254761,0.052155,0.000000
39.370003,3.943794,-256.210266,0.007321,0.002037,0.051730,17.542873,0.893677,0.517301,-256.210266,0.052589,0.000000
39.630001,3.960922,-256.343719,0.007355,0.002051,0.052095,17.619062,0.897558,0.520945,-256.343719,0.053022,0.000000
39.890003,3.995552,-256.299225,0.007377,0.002067,0.052493,17.773104,0.905405,0.524935,-256.299225,0.053456,0.000000
40.150002,4.068909,-256.299225,0.007381,0.002086,0.052996,18.099409,0.922028,0.529965,-256.299225,0.053890,0.000000
40.410004,4.012306,-256.254761,0.007403,0.002100,0.053334,17.847630,0.909202,0.533345,-256.254761,0.054323,0.000000
40.670002,4.309464,-256.254761,0.007442,0.002125,0.053968,19.169451,0.976538,0.539677,-256.254761,0.054757,0.000000
40.930000,4.248764,-256.343719,0.007476,0.002140,0.054358,18.899446,0.962784,0.543579,-256.343719,0.055190,0.000000
41.190002,4.191795,-256.254761,0.007463,0.002156,0.054774,18.646036,0.949874,0.547742,-256.254761,0.055624,0.000000
41.450001,4.173920,-256.343719,0.007537,0.002174,0.055208,18.566523,0.945824,0.552076,-256.343719,0.056058,0.000000
41.710003,4.248390,-256.343719,0.007528,0.002191,0.055641,18.897783,0.962699,0.556414,-256.343719,0.056491,0.000000
41.970001,4.264404,-256.299225,0.007575,0.002209,0.056110,18.969017,0.966328,0.561096,-256.299225,0.056925,0.000000
42.230003,4.141151,-256.388214,0.007567,0.002219,0.056353,18.420761,0.938398,0.563525,-256.388214,0.057359,0.000000
42.490002,4.391388,-256.343719,0.007601,0.002244,0.057003,19.533869,0.995103,0.570028,-256.343719,0.057783,0.000000
42.750004,4.304253,-256.343719,0.007606,0.002260,0.057402,19.146273,0.975358,0.574017,-256.343719,0.058217,0.000000
43.010002,4.302757,-256.432678,0.007653,0.002275,0.057775,19.139620,0.975019,0.577745,-256.432678,0.058651,0.000000
43.270000,4.299782,-256.388214,0.007666,0.002292,0.058226,19.126385,0.974344,0.582257,-256.388214,0.059084,0.000000
43.530003,4.299408,-256.432678,0.007687,0.002308,0.058633,19.124722,0.974260,0.586333,-256.432678,0.059518,0.000000
43.790001,4.419685,-256.432678,0.007709,0.002325,0.059050,19.659742,1.001515,0.590497,-256.432678,0.059952,0.000000
44.050003,4.405533,-256.388214,0.007739,0.002343,0.059518,19.596788,0.998308,0.595179,-256.388214,0.060385,0.000000
44.310001,4.449104,-256.432678,0.007756,0.002358,0.059891,19.790604,1.008181,0.598907,-256.432678,0.060819,0.000000
44.570004,4.630074,-256.343719,0.007804,0.002381,0.060480,20.595596,1.049190,0.604804,-256.343719,0.061252,0.000000
44.830002,4.526184,-256.432678,0.007808,0.002397,0.060879,20.133472,1.025648,0.608793,-256.432678,0.061686,0.000000
45.090004,4.459900,-256.432678,0.007812,0.002413,0.061278,19.838625,1.010628,0.612782,-256.432678,0.062120,0.000000
45.350002,4.457298,-256.432678,0.007847,0.002427,0.061634,19.827053,1.010038,0.616340,-256.432678,0.062553,0.000000
45.610001,4.607361,-256.477173,0.007856,0.002446,0.062137,20.494564,1.044043,0.621370,-256.477173,0.062987,0.000000
45.870003,4.628960,-256.388214,0.007907,0.002464,0.062579,20.590641,1.048937,0.625791,-256.388214,0.063420,0.000000
46.130001,4.517616,-256.477173,0.007899,0.002474,0.062831,20.095362,1.023707,0.628308,-256.477173,0.063854,0.000000
46.390003,4.735085,-256.432678,0.007937,0.002496,0.063403,21.062708,1.072985,0.634030,-256.432678,0.064288,0.000000
46.650002,4.808441,-256.521637,0.007972,0.002518,0.063949,21.389015,1.089608,0.639492,-256.521637,0.064721,0.000000
46.910004,4.704178,-256.566132,0.007976,0.002531,0.064279,20.925228,1.065982,0.642789,-256.566132,0.065155,0.000000
47.170002,4.682579,-256.432678,0.007985,0.002547,0.064686,20.829151,1.061087,0.646865,-256.432678,0.065588,0.000000
47.430004,4.809929,-256.566132,0.008015,0.002567,0.065207,21.395632,1.089945,0.652069,-256.566132,0.066022,0.000000
47.690002,4.843445,-256.477173,0.008054,0.002585,0.065649,21.544718,1.097540,0.656490,-256.477173,0.066456,0.000000
47.950001,4.775299,-256.521637,0.008080,0.002595,0.065918,21.241590,1.082098,0.659181,-256.521637,0.066889,0.000000
48.210003,4.489693,-256.566132,0.008067,0.002595,0.065918,19.971151,1.017379,0.659181,-256.566132,0.067323,0.000000
48.470001,5.257896,-256.477173,0.008110,0.002637,0.066976,23.388292,1.191456,0.669760,-256.477173,0.067756,0.000000
48.730003,5.060913,-256.521637,0.008140,0.002654,0.067401,22.512066,1.146819,0.674010,-256.521637,0.068190,0.000000
48.990002,4.982712,-256.566132,0.008166,0.002670,0.067809,22.164209,1.129099,0.678087,-256.566132,0.068624,0.000000
49.250004,4.985321,-256.566132,0.008179,0.002686,0.068216,22.175816,1.129690,0.682163,-256.566132,0.069057,0.000000
49.510002,5.112671,-256.610596,0.008213,0.002704,0.068676,22.742296,1.158548,0.686758,-256.610596,0.069491,0.000000
49.770000,5.036705,-256.610596,0.008218,0.002716,0.068997,22.404383,1.141334,0.689967,-256.610596,0.069924,0.000000
50.030003,5.003563,-256.566132,0.008248,0.002731,0.069361,22.256960,1.133824,0.693609,-256.566132,0.070358,0.000000
50.290001,5.394928,-256.610596,0.008278,0.002757,0.070020,23.997839,1.222508,0.700198,-256.610596,0.070792,0.000000
50.550003,5.307793,-256.521637,0.008278,0.002773,0.070427,23.610241,1.202763,0.704274,-256.521637,0.071225,0.000000
50.810001,5.228104,-256.610596,0.008308,0.002786,0.070775,23.255766,1.184705,0.707745,-256.610596,0.071659,0.000000
51.070004,5.304817,-256.566132,0.008326,0.002805,0.071243,23.597006,1.202089,0.712427,-256.566132,0.072093,0.000000
51.330002,5.464561,-256.610596,0.008364,0.002823,0.071694,24.307583,1.238287,0.716939,-256.610596,0.072526,0.000000
51.590004,5.490631,-256.610596,0.008369,0.002839,0.072119,24.423548,1.244195,0.721185,-256.610596,0.072951,0.000000
51.850002,5.451157,-256.610596,0.008390,0.002851,0.072413,24.247955,1.235250,0.724134,-256.610596,0.073385,0.000000
52.110001,5.397163,-256.655090,0.008412,0.002866,0.072787,24.007782,1.223015,0.727866,-256.655090,0.073818,0.000000
52.370003,5.927795,-256.610596,0.008438,0.002896,0.073550,26.368151,1.343258,0.735496,-256.610596,0.074252,0.000000
52.630001,5.657822,-256.610596,0.008476,0.002908,0.073862,25.167248,1.282081,0.738618,-256.610596,0.074685,0.000000
52.890003,5.748306,-256.610596,0.008468,0.002926,0.074313,25.569744,1.302585,0.743126,-256.610596,0.075119,0.000000
53.150002,5.972107,-256.610596,0.008528,0.002945,0.074816,26.565258,1.353299,0.748156,-256.610596,0.075553,0.000000
53.410004,5.987747,-256.699554,0.008532,0.002961,0.075197,26.634830,1.356843,0.751972,-256.699554,0.075986,0.000000
53.670002,5.931892,-256.655090,0.008537,0.002973,0.075527,26.386375,1.344186,0.755268,-256.655090,0.076420,0.000000
53.930004,5.970619,-256.699554,0.008571,0.002986,0.075839,26.558641,1.352962,0.758391,-256.699554,0.076854,0.000000
54.190002,6.146751,-256.699554,0.008571,0.003005,0.076316,27.342115,1.392874,0.763160,-256.699554,0.077287,0.000000
54.450001,6.427521,-256.655090,0.008593,0.003029,0.076949,28.591040,1.456497,0.769492,-256.655090,0.077721,0.000000
54.710003,6.255478,-256.744049,0.008632,0.003041,0.077253,27.825756,1.417511,0.772527,-256.744049,0.078155,0.000000
54.970001,6.377617,-256.744049,0.008649,0.003061,0.077747,28.369057,1.445189,0.777470,-256.744049,0.078588,0.000000
55.230003,6.725784,-256.699554,0.008679,0.003082,0.078293,29.917782,1.524084,0.782932,-256.699554,0.079022,0.000000
55.490002,6.599182,-256.744049,0.008679,0.003095,0.078605,29.354628,1.495396,0.786055,-256.744049,0.079456,0.000000
55.750004,6.687431,-256.699554,0.008696,0.003109,0.078961,29.747181,1.515394,0.789609,-256.699554,0.079889,0.000000
56.010002,6.946602,-256.744049,0.008727,0.003130,0.079490,30.900028,1.574123,0.794900,-256.744049,0.080323,0.000000
56.270004,7.111191,-256.699554,0.008731,0.003150,0.080010,31.632156,1.611419,0.800104,-256.699554,0.080756,0.000000
56.530003,7.077682,-256.788544,0.008778,0.003164,0.080375,31.483105,1.603826,0.803745,-256.788544,0.081190,0.000000
56.790001,7.190140,-256.788544,0.008761,0.003180,0.080773,31.983339,1.629309,0.807734,-256.788544,0.081624,0.000000
57.050003,7.076561,-256.699554,0.008791,0.003193,0.081094,31.478115,1.603572,0.810944,-256.699554,0.082057,0.000000
57.310001,7.516335,-256.788544,0.008808,0.003216,0.081693,33.434326,1.703226,0.816928,-256.788544,0.082491,0.000000
57.570004,7.573677,-256.833008,0.008826,0.003230,0.082040,33.689400,1.716220,0.820399,-256.833008,0.082924,0.000000
57.830002,7.553947,-256.833008,0.008847,0.003241,0.082317,33.601635,1.711749,0.823173,-256.833008,0.083358,0.000000
58.090004,8.083084,-256.788544,0.008869,0.003267,0.082994,35.955353,1.831653,0.829937,-256.788544,0.083792,0.000000
58.350002,8.206711,-256.744049,0.008899,0.003287,0.083479,36.505272,1.859667,0.834793,-256.744049,0.084225,0.000000
58.610004,8.076752,-256.921967,0.008925,0.003300,0.083826,35.927185,1.830218,0.838263,-256.921967,0.084659,0.000000
58.870003,8.249908,-256.833008,0.008921,0.003316,0.084234,36.697426,1.869456,0.842336,-256.833008,0.085092,0.000000
59.130001,8.693779,-256.788544,0.008964,0.003338,0.084789,38.671860,1.970038,0.847888,-256.788544,0.085526,0.000000
59.390003,8.622650,-256.833008,0.008951,0.003350,0.085101,38.355465,1.953920,0.851011,-256.833008,0.085960,0.000000
59.650002,8.594727,-256.788544,0.008981,0.003361,0.085370,38.231255,1.947593,0.853698,-256.788544,0.086393,0.000000
59.910004,9.106361,-256.877502,0.008998,0.003384,0.085951,40.507118,2.063531,0.859508,-256.877502,0.086827,0.000000
60.170002,9.428467,-256.877502,0.009050,0.003405,0.086489,41.939915,2.136521,0.864886,-256.877502,0.087260,0.000000
60.430004,9.409477,-256.877502,0.009050,0.003418,0.086827,41.855446,2.132218,0.868266,-256.877502,0.087694,0.000000
60.690002,9.553955,-256.877502,0.009071,0.003435,0.087260,42.498116,2.164957,0.872604,-256.877502,0.088119,0.000000
60.950005,9.704765,-256.833008,0.009080,0.003449,0.087616,43.168953,2.199131,0.876158,-256.833008,0.088553,0.000000
61.210003,9.954254,-256.921967,0.009123,0.003465,0.088006,44.278732,2.255666,0.880064,-256.921967,0.088986,0.000000
61.470001,10.407433,-256.921967,0.009102,0.003486,0.088535,46.294571,2.358358,0.885351,-256.921967,0.089420,0.000000
61.730003,10.203377,-256.921967,0.009140,0.003496,0.088796,45.386887,2.312118,0.887955,-256.921967,0.089853,0.000000
61.990002,11.167816,-256.877502,0.009140,0.003523,0.089489,49.676926,2.530663,0.894893,-256.877502,0.090287,0.000000
62.250004,11.153297,-256.877502,0.009149,0.003537,0.089827,49.612347,2.527373,0.898273,-256.877502,0.090721,0.000000
62.510002,11.425125,-256.921967,0.009188,0.003556,0.090322,50.821495,2.588970,0.903216,-256.921967,0.091154,0.000000
62.770004,11.736801,-256.966461,0.009188,0.003572,0.090729,52.207897,2.659597,0.907292,-256.966461,0.091588,0.000000
63.030003,12.047363,-256.921967,0.009188,0.003590,0.091197,53.589348,2.729971,0.911974,-256.921967,0.092021,0.000000
63.290005,12.389198,-256.966461,0.009240,0.003608,0.091631,55.109905,2.807432,0.916312,-256.966461,0.092455,0.000000
63.550003,12.297226,-256.877502,0.009227,0.003617,0.091874,54.700794,2.786591,0.918742,-256.877502,0.092889,0.000000
63.810001,13.256454,-257.010925,0.009270,0.003642,0.092516,58.967655,3.003956,0.925157,-257.010925,0.093322,0.000000
64.070000,13.265022,-256.966461,0.009283,0.003657,0.092897,59.005768,3.005897,0.928972,-256.966461,0.093756,0.000000
64.330002,13.622498,-256.877502,0.009291,0.003673,0.093287,60.595894,3.086902,0.932874,-256.877502,0.094189,0.000000
64.590004,13.901405,-256.966461,0.009334,0.003689,0.093712,61.836540,3.150103,0.937125,-256.966461,0.094623,0.000000
64.850006,14.109192,-256.966461,0.009334,0.003704,0.094094,62.760818,3.197189,0.940940,-256.966461,0.095057,0.000000
65.110001,14.869202,-256.966461,0.009356,0.003723,0.094571,66.141510,3.369409,0.945713,-256.966461,0.095490,0.000000
65.370003,15.141777,-257.010925,0.009334,0.003740,0.094987,67.353989,3.431176,0.949872,-257.010925,0.095924,0.000000
65.630005,15.270248,-256.966461,0.009373,0.003753,0.095326,67.925461,3.460288,0.953256,-256.966461,0.096358,0.000000
65.889999,16.643555,-256.966461,0.009390,0.003779,0.095993,74.034225,3.771483,0.959933,-256.966461,0.096791,0.000000
66.150002,16.971985,-256.921967,0.009399,0.003797,0.096436,75.495163,3.845907,0.964357,-256.921967,0.097225,0.000000
66.410004,17.070663,-256.966461,0.009421,0.003810,0.096782,75.934105,3.868268,0.967824,-256.966461,0.097658,0.000000
66.670006,17.485863,-257.099884,0.009434,0.003825,0.097147,77.781006,3.962353,0.971469,-257.099884,0.098092,0.000000
66.930000,18.124855,-257.010925,0.009429,0.003843,0.097615,80.623383,4.107151,0.976151,-257.010925,0.098526,0.000000
67.190002,18.719902,-257.055420,0.009455,0.003861,0.098075,83.270287,4.241991,0.980746,-257.055420,0.098959,0.000000
67.450005,18.934761,-257.010925,0.009472,0.003871,0.098335,84.226021,4.290678,0.983350,-257.010925,0.099393,0.000000
67.710007,20.045547,-257.010925,0.009464,0.003894,0.098916,89.167046,4.542386,0.989160,-257.010925,0.099827,0.000000
67.970001,20.903122,-257.099884,0.009516,0.003916,0.099462,92.981728,4.736715,0.994621,-257.099884,0.100260,0.000000
68.230003,21.186501,-256.966461,0.009528,0.003928,0.099774,94.242264,4.800930,0.997744,-256.966461,0.100694,0.000000
68.490005,21.517166,-257.144379,0.009520,0.003945,0.100191,95.713135,4.875860,1.001907,-257.144379,0.101127,0.000000
68.750000,22.495758,-257.055420,0.009516,0.003964,0.100694,100.066132,5.097612,1.006937,-257.055420,0.101561,0.000000
69.010002,23.138107,-257.055420,0.009546,0.003981,0.101127,102.923439,5.243170,1.011275,-257.055420,0.101995,0.000000
69.270004,23.644157,-257.144379,0.009563,0.003994,0.101457,105.174461,5.357842,1.014568,-257.144379,0.102428,0.000000
69.530006,23.853806,-257.055420,0.009580,0.004007,0.101769,106.107025,5.405349,1.017690,-257.055420,0.102853,0.000000
69.790001,25.479958,-257.099884,0.009554,0.004033,0.102428,113.340515,5.773841,1.024283,-257.099884,0.103287,0.000000
70.050003,26.176292,-257.144379,0.009593,0.004048,0.102827,116.437965,5.931633,1.028273,-257.144379,0.103721,0.000000
70.310005,26.853264,-257.144379,0.009619,0.004066,0.103269,119.449280,6.085037,1.032694,-257.144379,0.104154,0.000000
70.570000,27.417778,-257.188873,0.009606,0.004080,0.103625,121.960365,6.212957,1.036247,-257.188873,0.104588,0.000000
70.830002,28.866684,-257.099884,0.009632,0.004103,0.104215,128.405426,6.541284,1.042148,-257.099884,0.105021,0.000000
71.090004,29.210381,-257.144379,0.009649,0.004115,0.104510,129.934265,6.619167,1.045097,-257.144379,0.105455,0.000000
71.350006,29.529503,-257.144379,0.009675,0.004125,0.104787,131.353790,6.691481,1.047871,-257.144379,0.105888,0.000000
71.610001,31.355247,-257.144379,0.009653,0.004153,0.105481,139.475113,7.105200,1.054809,-257.144379,0.106322,0.000000
71.870003,32.200157,-257.188873,0.009675,0.004168,0.105871,143.233459,7.296660,1.058711,-257.188873,0.106756,0.000000
72.130005,33.002251,-257.233337,0.009688,0.004183,0.106253,146.801346,7.478417,1.062526,-257.233337,0.107189,0.000000
72.390007,33.699333,-257.188873,0.009688,0.004200,0.106678,149.902115,7.636378,1.066776,-257.188873,0.107623,0.000000
72.650002,34.795967,-257.188873,0.009692,0.004218,0.107146,154.780197,7.884879,1.071458,-257.188873,0.108056,0.000000
72.910004,35.900055,-257.099884,0.009727,0.004235,0.107562,159.691422,8.135069,1.075622,-257.099884,0.108490,0.000000
73.170006,36.576653,-257.233337,0.009722,0.004248,0.107892,162.701080,8.288388,1.078918,-257.233337,0.108924,0.000000
73.430000,37.144524,-257.233337,0.009714,0.004258,0.108143,165.227097,8.417069,1.081432,-257.233337,0.109357,0.000000
73.690002,39.577972,-257.144379,0.009753,0.004290,0.108958,176.051620,8.968496,1.089584,-257.144379,0.109791,0.000000
73.950005,40.398315,-257.188873,0.009735,0.004302,0.109271,179.700684,9.154388,1.092707,-257.188873,0.110224,0.000000
74.210007,41.133751,-257.233337,0.009744,0.004319,0.109704,182.972061,9.321041,1.097040,-257.233337,0.110658,0.000000
74.470001,42.088882,-257.188873,0.009761,0.004333,0.110069,187.220703,9.537477,1.100685,-257.188873,0.111092,0.000000
74.730003,43.885582,-257.277832,0.009779,0.004355,0.110615,195.212814,9.944614,1.106147,-257.277832,0.111525,0.000000
74.990005,44.694374,-257.277832,0.009783,0.004369,0.110979,198.810501,10.127890,1.109792,-257.277832,0.111959,0.000000
75.250000,45.398529,-257.322296,0.009796,0.004383,0.111335,201.942749,10.287454,1.113346,-257.322296,0.112392,0.000000
75.510002,46.546928,-257.233337,0.009783,0.004398,0.111699,207.051071,10.547685,1.116987,-257.233337,0.112826,0.000000
75.770004,48.839622,-257.233337,0.009779,0.004425,0.112384,217.249496,11.067217,1.123837,-257.233337,0.113260,0.000000
76.030006,49.579155,-257.322296,0.009800,0.004436,0.112679,220.539093,11.234797,1.126786,-257.322296,0.113693,0.000000
76.290001,50.705208,-257.277832,0.009826,0.004452,0.113086,225.548035,11.489964,1.130862,-257.277832,0.114127,0.000000
76.550003,52.435997,-257.366791,0.009826,0.004475,0.113659,233.246964,11.882167,1.136589,-257.366791,0.114561,0.000000
76.810005,53.800743,-257.322296,0.009809,0.004491,0.114067,239.317657,12.191422,1.140665,-257.322296,0.114994,0.000000
77.070007,54.332489,-257.233337,0.009822,0.004503,0.114370,241.682983,12.311918,1.143697,-257.233337,0.115428,0.000000
77.330002,55.801872,-257.322296,0.009822,0.004522,0.114847,248.219131,12.644885,1.148470,-257.322296,0.115861,0.000000
77.590004,57.959023,-257.322296,0.009843,0.004544,0.115428,257.814606,13.133702,1.154279,-257.322296,0.116295,0.000000
77.850006,58.944695,-257.411255,0.009860,0.004557,0.115740,262.199097,13.357059,1.157402,-257.411255,0.116729,0.000000
78.110001,59.961273,-257.277832,0.009839,0.004573,0.116165,266.721069,13.587419,1.161649,-257.277832,0.117162,0.000000
78.370003,61.417618,-257.366791,0.009856,0.004588,0.116538,273.199219,13.917431,1.165380,-257.366791,0.117596,0.000000
78.630005,63.268677,-257.322296,0.009878,0.004611,0.117110,281.433136,14.336887,1.171103,-257.322296,0.118021,0.000000
78.890007,64.114716,-257.322296,0.009869,0.004621,0.117379,285.196503,14.528602,1.173791,-257.322296,0.118454,0.000000
79.150002,65.025162,-257.366791,0.009873,0.004634,0.117691,289.246368,14.734913,1.176913,-257.366791,0.118888,0.000000
79.410004,66.684082,-257.366791,0.009860,0.004654,0.118203,296.625610,15.110828,1.182030,-257.366791,0.119322,0.000000
79.670006,67.377808,-257.322296,0.009878,0.004655,0.118246,299.711456,15.268030,1.182462,-257.322296,0.118463,0.000000
79.930000,66.947357,-257.411255,0.009891,0.004654,0.118220,297.796722,15.170488,1.182204,-257.411255,0.118238,0.000000
80.190002,66.605881,-257.411255,0.009882,0.004653,0.118194,296.277740,15.093109,1.181943,-257.411255,0.118238,0.000000
80.450005,66.296066,-257.366791,0.009882,0.004653,0.118186,294.899628,15.022903,1.181856,-257.366791,0.118238,0.000000
80.710007,66.011581,-257.455750,0.009908,0.004653,0.118177,293.634186,14.958439,1.181769,-257.455750,0.118238,0.000000
80.970001,65.775497,-257.366791,0.009891,0.004652,0.118168,292.584015,14.904941,1.181682,-257.366791,0.118238,0.000000
81.230003,65.560638,-257.411255,0.009891,0.004652,0.118159,291.628296,14.856253,1.181595,-257.411255,0.118238,0.000000
81.490005,65.356949,-257.455750,0.009891,0.004652,0.118159,290.722229,14.810097,1.181595,-257.455750,0.118238,0.000000
81.750008,65.189758,-257.500214,0.009916,0.004652,0.118151,289.978516,14.772210,1.181508,-257.500214,0.118238,0.000000
82.010002,65.027023,-257.544708,0.009899,0.004652,0.118151,289.254639,14.735333,1.181508,-257.544708,0.118238,0.000000
82.270004,64.873230,-257.411255,0.009904,0.004652,0.118151,288.570526,14.700483,1.181508,-257.411255,0.118238,0.000000
82.530006,64.752213,-257.455750,0.009886,0.004652,0.118151,288.032227,14.673061,1.181508,-257.455750,0.118238,0.000000
82.790001,64.625977,-257.411255,0.009895,0.004651,0.118142,287.470703,14.644455,1.181425,-257.411255,0.118238,0.000000
83.050003,64.487091,-257.455750,0.009916,0.004651,0.118142,286.852905,14.612984,1.181425,-257.455750,0.118238,0.000000
83.310005,64.386169,-257.455750,0.009882,0.004651,0.118142,286.403992,14.590115,1.181425,-257.455750,0.118238,0.000000
83.570007,64.287125,-257.455750,0.009908,0.004651,0.118142,285.963409,14.567671,1.181425,-257.455750,0.118238,0.000000
83.830002,64.167221,-257.544708,0.009929,0.004651,0.118142,285.430054,14.540501,1.181425,-257.544708,0.118238,0.000000
84.090004,64.091248,-257.500214,0.009882,0.004651,0.118142,285.092102,14.523284,1.181425,-257.500214,0.118238,0.000000
84.350006,64.007477,-257.544708,0.009921,0.004651,0.118142,284.719482,14.504302,1.181425,-257.544708,0.118238,0.000000
84.610001,63.912140,-257.589172,0.009899,0.004651,0.118142,284.295410,14.482698,1.181425,-257.589172,0.118238,0.000000
84.870003,63.843994,-257.455750,0.009916,0.004651,0.118142,283.992279,14.467256,1.181425,-257.455750,0.118238,0.000000
85.130005,63.769150,-257.544708,0.009908,0.004651,0.118142,283.659332,14.450296,1.181425,-257.544708,0.118238,0.000000
85.390007,63.691696,-257.544708,0.009899,0.004651,0.118142,283.314819,14.432745,1.181425,-257.544708,0.118238,0.000000
85.650002,63.647018,-257.544708,0.009908,0.004651,0.118142,283.116089,14.422621,1.181425,-257.544708,0.118238,0.000000
85.910004,63.566589,-257.589172,0.009899,0.004651,0.118134,282.758301,14.404395,1.181338,-257.589172,0.118238,0.000000
86.170006,63.493225,-257.500214,0.009916,0.004651,0.118134,282.431976,14.387771,1.181338,-257.500214,0.118238,0.000000
86.430000,63.448914,-257.589172,0.009912,0.004651,0.118134,282.234863,14.377729,1.181338,-257.589172,0.118238,0.000000
86.690002,63.367371,-257.589172,0.009899,0.004651,0.118134,281.872131,14.359251,1.181338,-257.589172,0.118238,0.000000
86.950005,63.336090,-257.589172,0.009921,0.004651,0.118134,281.733002,14.352163,1.181338,-257.589172,0.118238,0.000000
87.210007,63.276138,-257.544708,0.009908,0.004651,0.118134,281.466309,14.338578,1.181338,-257.544708,0.118238,0.000000
87.470001,63.218781,-257.544708,0.009899,0.004651,0.118134,281.211182,14.325581,1.181338,-257.544708,0.118238,0.000000
87.730003,63.188248,-257.633667,0.009912,0.004651,0.118134,281.075378,14.318662,1.181338,-257.633667,0.118238,0.000000
87.990005,63.121231,-257.633667,0.009916,0.004651,0.118134,280.777252,14.303475,1.181338,-257.633667,0.118238,0.000000
88.250008,63.087341,-257.589172,0.009908,0.004651,0.118134,280.626495,14.295796,1.181338,-257.589172,0.118238,0.000000
88.510002,63.039673,-257.678162,0.009895,0.004651,0.118134,280.414459,14.284994,1.181338,-257.678162,0.118238,0.000000
88.770004,62.978233,-257.589172,0.009891,0.004651,0.118134,280.141174,14.271072,1.181338,-257.589172,0.118238,0.000000
89.030006,62.958122,-257.633667,0.009891,0.004651,0.118134,280.051727,14.266515,1.181338,-257.633667,0.118238,0.000000
89.290001,62.901894,-257.678162,0.009912,0.004651,0.118134,279.801605,14.253773,1.181338,-257.678162,0.118238,0.000000
89.550003,62.865036,-257.589172,0.009904,0.004651,0.118134,279.637634,14.245420,1.181338,-257.589172,0.118238,0.000000
89.810005,62.829659,-257.722626,0.009908,0.004651,0.118134,279.480286,14.237404,1.181338,-257.722626,0.118238,0.000000
90.070007,62.786087,-257.678162,0.009925,0.004651,0.118134,279.286469,14.227531,1.181338,-257.678162,0.118238,0.000000
90.330002,62.753693,-257.678162,0.009908,0.004651,0.118134,279.142365,14.220190,1.181338,-257.678162,0.118238,0.000000
90.590004,62.710495,-257.633667,0.009899,0.004651,0.118134,278.950226,14.210401,1.181338,-257.633667,0.118238,0.000000
90.850006,62.672142,-257.633667,0.009925,0.004651,0.118134,278.779602,14.201711,1.181338,-257.633667,0.118238,0.000000
91.110001,62.640495,-257.678162,0.009895,0.004651,0.118134,278.638824,14.194539,1.181338,-257.678162,0.118238,0.000000
91.370003,62.605492,-257.678162,0.009925,0.004651,0.118134,278.483124,14.186607,1.181338,-257.678162,0.118238,0.000000
91.630005,62.591713,-257.722626,0.009929,0.004651,0.118134,278.421844,14.183485,1.181338,-257.722626,0.118238,0.000000
91.890007,62.539581,-257.767120,0.009921,0.004651,0.118134,278.189941,14.171672,1.181338,-257.767120,0.118238,0.000000
92.150002,62.501595,-257.722626,0.009908,0.004651,0.118134,278.020966,14.163063,1.181338,-257.722626,0.118238,0.000000
92.410004,62.482605,-257.767120,0.009908,0.004651,0.118134,277.936493,14.158760,1.181338,-257.767120,0.118238,0.000000
92.670006,62.439407,-257.678162,0.009929,0.004651,0.118134,277.744354,14.148972,1.181338,-257.678162,0.118238,0.000000
92.930008,62.428612,-257.767120,0.009908,0.004651,0.118134,277.696320,14.146525,1.181338,-257.767120,0.118238,0.000000
93.190002,62.390633,-257.767120,0.009916,0.004651,0.118134,277.527405,14.137919,1.181338,-257.767120,0.118238,0.000000
93.450005,62.370522,-257.767120,0.009934,0.004651,0.118134,277.437927,14.133363,1.181338,-257.767120,0.118238,0.000000
93.710007,62.345947,-257.811584,0.009908,0.004651,0.118134,277.328613,14.127793,1.181338,-257.811584,0.118238,0.000000
93.970001,62.302750,-257.811584,0.009904,0.004651,0.118134,277.136475,14.118005,1.181338,-257.811584,0.118238,0.000000
94.230003,62.296791,-257.767120,0.009916,0.004651,0.118134,277.109955,14.116654,1.181338,-257.767120,0.118238,0.000000
94.490005,62.252106,-257.856079,0.009904,0.004651,0.118134,276.911194,14.106528,1.181338,-257.856079,0.118238,0.000000
94.750008,62.243172,-257.811584,0.009938,0.004651,0.118134,276.871460,14.104504,1.181338,-257.811584,0.118238,0.000000
95.010002,62.205185,-257.811584,0.009908,0.004651,0.118134,276.702484,14.095896,1.181338,-257.811584,0.118238,0.000000
95.270004,62.182846,-257.811584,0.009934,0.004651,0.118134,276.603119,14.090835,1.181338,-257.811584,0.118238,0.000000
95.530006,62.175774,-257.767120,0.009916,0.004651,0.118134,276.571655,14.089231,1.181338,-257.767120,0.118238,0.000000
95.790001,62.134811,-257.856079,0.009916,0.004651,0.118134,276.389435,14.079949,1.181338,-257.856079,0.118238,0.000000
96.050003,62.125504,-257.856079,0.009891,0.004651,0.118134,276.348053,14.077841,1.181338,-257.856079,0.118238,0.000000
96.310005,62.107254,-257.811584,0.009916,0.004651,0.118134,276.266876,14.073705,1.181338,-257.811584,0.118238,0.000000
96.570007,62.083794,-257.856079,0.009929,0.004651,0.118134,276.162506,14.068388,1.181338,-257.856079,0.118238,0.000000
96.830002,62.057732,-257.811584,0.009921,0.004651,0.118134,276.046570,14.062483,1.181338,-257.811584,0.118238,0.000000
97.090004,62.040230,-257.900543,0.009921,0.004651,0.118134,275.968719,14.058517,1.181338,-257.900543,0.118238,0.000000
97.350006,62.021606,-257.811584,0.009908,0.004651,0.118134,275.885895,14.054296,1.181338,-257.811584,0.118238,0.000000
97.610008,61.991447,-257.856079,0.009904,0.004651,0.118134,275.751740,14.047462,1.181338,-257.856079,0.118238,0.000000
97.870003,61.984001,-257.945038,0.009908,0.004651,0.118134,275.718597,14.045775,1.181338,-257.945038,0.118238,0.000000
98.130005,61.958305,-257.900543,0.009904,0.004651,0.118134,275.604309,14.039953,1.181338,-257.900543,0.118238,0.000000
98.390007,61.940804,-257.945038,0.009891,0.004651,0.118134,275.526459,14.035987,1.181338,-257.945038,0.118238,0.000000
98.650002,61.910645,-257.900543,0.009916,0.004651,0.118125,275.392303,14.029152,1.181251,-257.900543,0.118238,0.000000
98.910004,61.899841,-257.900543,0.009947,0.004651,0.118125,275.344238,14.026705,1.181251,-257.900543,0.118238,0.000000
99.170006,61.875267,-257.945038,0.009899,0.004651,0.118125,275.234924,14.021136,1.181251,-257.945038,0.118238,0.000000
99.430008,61.856651,-257.900543,0.009921,0.004651,0.118125,275.152130,14.016917,1.181251,-257.900543,0.118238,0.000000
99.690002,61.854042,-257.900543,0.009921,0.004651,0.118125,275.140533,14.016326,1.181251,-257.900543,0.118238,0.000000
99.950005,61.826111,-257.900543,0.009908,0.004651,0.118125,275.016266,14.009996,1.181251,-257.900543,0.118238,0.000000
100.210007,61.806007,-257.900543,0.009912,0.004651,0.118125,274.926849,14.005442,1.181251,-257.900543,0.118238,0.000000
100.470001,61.777702,-257.989502,0.009925,0.004651,0.118125,274.800934,13.999027,1.181251,-257.989502,0.118238,0.000000
100.730003,61.765785,-257.945038,0.009908,0.004651,0.118125,274.747925,13.996326,1.181251,-257.945038,0.118238,0.000000
100.990005,61.762810,-257.989502,0.009925,0.004651,0.118125,274.734711,13.995653,1.181251,-257.989502,0.118238,0.000000
101.250008,61.736000,-257.989502,0.009921,0.004651,0.118125,274.615448,13.989577,1.181251,-257.989502,0.118238,0.000000
101.510002,61.724831,-257.989502,0.009908,0.004651,0.118125,274.565765,13.987046,1.181251,-257.989502,0.118238,0.000000
101.770004,61.702858,-258.033997,0.009908,0.004651,0.118125,274.468018,13.982067,1.181251,-258.033997,0.118238,0.000000
102.030006,61.691315,-257.989502,0.009912,0.004651,0.118125,274.416687,13.979451,1.181251,-257.989502,0.118238,0.000000
102.290009,61.680519,-258.033997,0.009921,0.004651,0.118125,274.368652,13.977006,1.181251,-258.033997,0.118238,0.000000
102.550003,61.646629,-257.945038,0.009899,0.004651,0.118125,274.217896,13.969326,1.181251,-257.945038,0.118238,0.000000
102.810005,61.651840,-258.033997,0.009925,0.004651,0.118125,274.241089,13.970507,1.181251,-258.033997,0.118238,0.000000
103.070007,61.624290,-258.033997,0.009929,0.004651,0.118125,274.118530,13.964263,1.181251,-258.033997,0.118238,0.000000
103.330002,61.613113,-258.033997,0.009908,0.004651,0.118125,274.068817,13.961732,1.181251,-258.033997,0.118238,0.000000
103.590004,61.605293,-257.989502,0.009921,0.004651,0.118125,274.034027,13.959959,1.181251,-257.989502,0.118238,0.000000
103.850006,61.584442,-258.078491,0.009925,0.004651,0.118125,273.941284,13.955235,1.181251,-258.078491,0.118238,0.000000
104.110008,61.574760,-257.989502,0.009895,0.004651,0.118125,273.898224,13.953040,1.181251,-257.989502,0.118238,0.000000
104.370003,61.548698,-258.078491,0.009929,0.004651,0.118125,273.782288,13.947134,1.181251,-258.078491,0.118238,0.000000
104.630005,61.523750,-258.078491,0.009912,0.004651,0.118125,273.671295,13.941481,1.181251,-258.078491,0.118238,0.000000
104.890007,61.526352,-258.033997,0.009899,0.004651,0.118125,273.682892,13.942070,1.181251,-258.033997,0.118238,0.000000
105.150002,61.515182,-258.078491,0.009916,0.004651,0.118125,273.633209,13.939539,1.181251,-258.078491,0.118238,0.000000
105.410004,61.501404,-258.078491,0.009921,0.004651,0.118125,273.571899,13.936418,1.181251,-258.078491,0.118238,0.000000
105.670006,61.482040,-258.122955,0.009912,0.004651,0.118125,273.485779,13.932030,1.181251,-258.122955,0.118238,0.000000
105.930008,61.465660,-258.122955,0.009916,0.004651,0.118125,273.412903,13.928317,1.181251,-258.122955,0.118238,0.000000
106.190002,61.456345,-258.122955,0.009929,0.004651,0.118125,273.371460,13.926207,1.181251,-258.122955,0.118238,0.000000
106.450005,61.435493,-258.122955,0.009895,0.004651,0.118125,273.278717,13.921481,1.181251,-258.122955,0.118238,0.000000
106.710007,61.417618,-258.078491,0.009912,0.004651,0.118125,273.199219,13.917431,1.181251,-258.078491,0.118238,0.000000
106.970009,61.411293,-258.167450,0.009925,0.004651,0.118125,273.171082,13.915998,1.181251,-258.167450,0.118238,0.000000
107.230003,61.406075,-258.211914,0.009916,0.004651,0.118125,273.147858,13.914815,1.181251,-258.211914,0.118238,0.000000
107.490005,61.375542,-258.078491,0.009921,0.004651,0.118125,273.012054,13.907896,1.181251,-258.078491,0.118238,0.000000
107.750008,61.375916,-258.122955,0.009912,0.004651,0.118125,273.013702,13.907981,1.181251,-258.122955,0.118238,0.000000
108.010002,61.350967,-258.211914,0.009904,0.004651,0.118125,272.902740,13.902328,1.181251,-258.211914,0.118238,0.000000
108.270004,61.355438,-258.167450,0.009929,0.004651,0.118125,272.922607,13.903341,1.181251,-258.167450,0.118238,0.000000
108.530006,61.330856,-258.167450,0.009916,0.004651,0.118125,272.813263,13.897771,1.181251,-258.167450,0.118238,0.000000
108.790009,61.308144,-258.122955,0.009921,0.004651,0.118125,272.712250,13.892624,1.181251,-258.122955,0.118238,0.000000
109.050003,61.316711,-258.345367,0.009908,0.004651,0.118125,272.750366,13.894566,1.181251,-258.345367,0.118238,0.000000
109.310005,61.293991,-258.122955,0.009921,0.004651,0.118125,272.649292,13.889417,1.181251,-258.122955,0.118238,0.000000
109.570007,61.280212,-258.211914,0.009925,0.004651,0.118125,272.588013,13.886294,1.181251,-258.211914,0.118238,0.000000
109.830002,61.273888,-258.256409,0.009908,0.004651,0.118125,272.559875,13.884862,1.181251,-258.256409,0.118238,0.000000
110.000008,61.262711,-258.211914,0.009929,0.004651,0.118125,272.510132,13.882329,1.181251,-258.211914,0.118238,0.000000