File: Data/Automembrane/AutoNoheat12-1-2_12132023_180947.csv
Time (sec),S:Load (lbs),S:HL1 (DIM),S:LVDT (in),S:Position (in),Ch:Position (mm),Ch:Load (N),Ch:Stress (MPa),Ch:Strain (mm/mm),Ch:HL1 (DIM),Set Point (),Cycles ()
0.110000,-0.008934,-1300.623047,-0.000022,-0.000000,-0.000000,-0.039741,-0.002024,-0.000000,-1300.623047,0.000260,0.000000
0.430000,-0.032394,-1300.623047,0.000043,0.000015,0.000390,-0.144098,-0.007341,0.003902,-1300.623047,0.001093,0.000000
0.750000,-0.052132,-1300.578491,0.000099,0.000205,0.005212,-0.231893,-0.011813,0.052120,-1300.578491,0.006417,0.000000
1.070000,-0.017128,-1300.489624,0.000229,0.000412,0.010468,-0.076189,-0.003881,0.104675,-1300.489624,0.011742,0.000000
1.390000,-0.040962,-1300.534058,0.000556,0.000630,0.015992,-0.182209,-0.009282,0.159916,-1300.534058,0.017084,0.000000
1.710000,-0.050270,-1300.623047,0.000755,0.000835,0.021204,-0.223612,-0.011391,0.212037,-1300.623047,0.022409,0.000000
2.030000,-0.035370,-1300.623047,0.000927,0.001040,0.026416,-0.157333,-0.008015,0.264157,-1300.623047,0.027734,0.000000
2.350000,-0.023087,-1300.534058,0.001216,0.001260,0.032001,-0.102694,-0.005231,0.320007,-1300.534058,0.033076,0.000000
2.670000,-0.053993,-1300.534058,0.001436,0.001462,0.037143,-0.240174,-0.012235,0.371433,-1300.534058,0.038401,0.000000
2.990000,-0.001862,-1300.534058,0.001613,0.001671,0.042433,-0.008281,-0.000422,0.424334,-1300.534058,0.043743,0.000000
3.310000,-0.043564,-1300.623047,0.001850,0.001885,0.047888,-0.193782,-0.009872,0.478882,-1300.623047,0.049068,0.000000
3.630000,-0.020477,-1300.623047,0.002009,0.002096,0.053248,-0.091088,-0.004640,0.532476,-1300.623047,0.054392,0.000000
3.950000,-0.017128,-1300.578491,0.002233,0.002298,0.058382,-0.076189,-0.003881,0.583816,-1300.578491,0.059735,0.000000
4.270000,-0.069633,-1300.534058,0.002492,0.002514,0.063863,-0.309745,-0.015779,0.638625,-1300.534058,0.065059,0.000000
4.590000,-0.044685,-1300.623047,0.002686,0.002725,0.069213,-0.198770,-0.010126,0.692132,-1300.623047,0.070384,0.000000
4.910000,-0.023827,-1300.623047,0.002897,0.002929,0.074399,-0.105986,-0.005399,0.743993,-1300.623047,0.075726,0.000000
5.230000,-0.042450,-1300.578491,0.003182,0.003145,0.079889,-0.188827,-0.009619,0.798889,-1300.578491,0.081051,0.000000
5.550000,-0.013405,-1300.534058,0.003354,0.003361,0.085370,-0.059628,-0.003038,0.853696,-1300.534058,0.086393,0.000000
5.870000,-0.015266,-1300.578491,0.003583,0.003561,0.090460,-0.067908,-0.003459,0.904603,-1300.578491,0.091718,0.000000
6.190000,-0.059952,-1300.623047,0.003803,0.003771,0.095776,-0.266679,-0.013585,0.957764,-1300.623047,0.097043,0.000000
6.510000,-0.034256,-1300.667480,0.004053,0.003991,0.101370,-0.152378,-0.007763,1.013701,-1300.667480,0.102385,0.000000
6.830000,-0.027184,-1300.623047,0.004307,0.004194,0.106521,-0.120918,-0.006160,1.065213,-1300.623047,0.107709,0.000000
7.150001,-0.042076,-1300.623047,0.004462,0.004402,0.111811,-0.187164,-0.009535,1.118115,-1300.623047,0.113034,0.000000
7.470000,-0.008560,-1300.623047,0.004708,0.004612,0.117136,-0.038078,-0.001940,1.171363,-1300.623047,0.118376,0.000000
7.790000,-0.029045,-1300.578491,0.004919,0.004828,0.122626,-0.129199,-0.006582,1.226257,-1300.578491,0.123701,0.000000
8.110001,-0.027924,-1300.667480,0.005152,0.005034,0.127872,-0.124210,-0.006328,1.278725,-1300.667480,0.129026,0.000000
8.430000,-0.019363,-1300.667480,0.005407,0.005240,0.133102,-0.086133,-0.004388,1.331019,-1300.667480,0.134368,0.000000
8.750000,-0.031647,-1300.534058,0.005592,0.005457,0.138600,-0.140772,-0.007171,1.386000,-1300.534058,0.139693,0.000000
9.070001,-0.043190,-1300.667480,0.005816,0.005662,0.143812,-0.192119,-0.009787,1.438120,-1300.667480,0.145035,0.000000
9.390000,-0.007072,-1300.623047,0.005993,0.005869,0.149076,-0.031460,-0.001603,1.490760,-1300.623047,0.150359,0.000000
9.710000,-0.028671,-1300.667480,0.006278,0.006086,0.154574,-0.127536,-0.006497,1.545744,-1300.667480,0.155684,0.000000
10.030001,-0.010422,-1300.711914,0.006502,0.006297,0.159934,-0.046358,-0.002362,1.599338,-1300.711914,0.161026,0.000000
10.350000,-0.005211,-1300.667480,0.006691,0.006496,0.164998,-0.023179,-0.001181,1.649983,-1300.667480,0.166351,0.000000
10.670000,-0.041702,-1300.667480,0.006894,0.006714,0.170540,-0.185501,-0.009450,1.705398,-1300.667480,0.171676,0.000000
10.990001,-0.040588,-1300.667480,0.007148,0.006922,0.175813,-0.180546,-0.009197,1.758125,-1300.667480,0.177018,0.000000
11.310000,0.000374,-1300.667480,0.007390,0.007130,0.181111,0.001663,0.000085,1.811114,-1300.667480,0.182343,0.000000
11.630000,-0.033142,-1300.623047,0.007623,0.007343,0.186523,-0.147423,-0.007510,1.865230,-1300.623047,0.187668,0.000000
11.950001,0.002235,-1300.667480,0.007821,0.007559,0.191995,0.009944,0.000507,1.919952,-1300.667480,0.193010,0.000000
12.270000,-0.005959,-1300.667480,0.008011,0.007762,0.197155,-0.026505,-0.001350,1.971552,-1300.667480,0.198335,0.000000
12.590000,-0.046913,-1300.667480,0.008222,0.007969,0.202411,-0.208680,-0.010631,2.024105,-1300.667480,0.203677,0.000000
12.910001,-0.035004,-1300.711914,0.008438,0.008188,0.207978,-0.155704,-0.007932,2.079781,-1300.711914,0.209002,0.000000
13.230000,-0.014519,-1300.623047,0.008670,0.008391,0.213129,-0.064583,-0.003290,2.131293,-1300.623047,0.214326,0.000000
13.550000,-0.018242,-1300.711914,0.008929,0.008602,0.218480,-0.081144,-0.004134,2.184800,-1300.711914,0.219668,0.000000
13.870001,-0.007072,-1300.711914,0.009084,0.008810,0.223779,-0.031460,-0.001603,2.237789,-1300.711914,0.224993,0.000000
14.190001,-0.020477,-1300.800903,0.009326,0.009026,0.229260,-0.091088,-0.004640,2.292598,-1300.800903,0.230318,0.000000
14.510000,-0.026810,-1300.711914,0.009610,0.009234,0.234550,-0.119255,-0.006075,2.345500,-1300.711914,0.235660,0.000000
14.830001,-0.007446,-1300.623047,0.009809,0.009440,0.239779,-0.033123,-0.001687,2.397792,-1300.623047,0.240985,0.000000
15.150001,-0.016380,-1300.711914,0.009994,0.009656,0.245251,-0.072863,-0.003712,2.452513,-1300.711914,0.246327,0.000000
15.470000,-0.048775,-1300.756470,0.010201,0.009860,0.250446,-0.216961,-0.011053,2.504461,-1300.756470,0.251652,0.000000
15.790001,-0.004097,-1300.756470,0.010464,0.010067,0.255710,-0.018224,-0.000928,2.557101,-1300.756470,0.256976,0.000000
16.110001,-0.011543,-1300.756470,0.010654,0.010284,0.261226,-0.051347,-0.002616,2.612259,-1300.756470,0.262319,0.000000
16.430000,-0.011169,-1300.711914,0.010856,0.010496,0.266594,-0.049684,-0.002531,2.665940,-1300.711914,0.267643,0.000000
16.750000,-0.005585,-1300.623047,0.011115,0.010696,0.271676,-0.024842,-0.001266,2.716760,-1300.623047,0.272968,0.000000
17.070002,-0.016754,-1300.711914,0.011309,0.010913,0.277183,-0.074526,-0.003797,2.771826,-1300.711914,0.278310,0.000000
17.390001,-0.016006,-1300.889893,0.011503,0.011122,0.282499,-0.071200,-0.003627,2.824989,-1300.889893,0.283635,0.000000
17.710001,0.007446,-1300.667480,0.011732,0.011328,0.287737,0.033123,0.001687,2.877368,-1300.667480,0.288960,0.000000
18.030001,-0.030159,-1300.800903,0.012003,0.011542,0.293174,-0.134154,-0.006834,2.931742,-1300.800903,0.294302,0.000000
18.350000,0.013405,-1300.756470,0.012236,0.011756,0.298603,0.059628,0.003038,2.986032,-1300.756470,0.299627,0.000000
18.670000,0.008568,-1300.845459,0.012387,0.011958,0.303746,0.038112,0.001941,3.037458,-1300.845459,0.304969,0.000000
18.990002,-0.035004,-1300.845459,0.012607,0.012166,0.309018,-0.155704,-0.007932,3.090185,-1300.845459,0.310293,0.000000
19.310001,-0.021225,-1300.756470,0.012861,0.012386,0.314595,-0.094413,-0.004810,3.145948,-1300.756470,0.315618,0.000000
19.630001,-0.004097,-1300.756470,0.013085,0.012590,0.319798,-0.018224,-0.000928,3.197983,-1300.756470,0.320960,0.000000
19.950001,-0.016754,-1300.800903,0.013279,0.012799,0.325105,-0.074526,-0.003797,3.251055,-1300.800903,0.326285,0.000000
20.270000,0.013779,-1300.845459,0.013478,0.013009,0.330439,0.061291,0.003122,3.304391,-1300.845459,0.331610,0.000000
20.590000,0.002983,-1300.889893,0.013745,0.013222,0.335842,0.013269,0.000676,3.358417,-1300.889893,0.336952,0.000000
20.910002,-0.020103,-1300.845459,0.013939,0.013431,0.341158,-0.089425,-0.004556,3.411579,-1300.845459,0.342277,0.000000
21.230001,-0.006325,-1300.845459,0.014155,0.013638,0.346405,-0.028134,-0.001433,3.464046,-1300.845459,0.347601,0.000000
21.550001,-0.007820,-1300.845459,0.014409,0.013852,0.351851,-0.034786,-0.001772,3.518507,-1300.845459,0.352943,0.000000
21.870001,-0.043564,-1300.889893,0.014582,0.014058,0.357080,-0.193782,-0.009872,3.570802,-1300.889893,0.358268,0.000000
22.190001,0.005585,-1300.845459,0.014814,0.014264,0.362301,0.024842,0.001266,3.623008,-1300.845459,0.363610,0.000000
22.510000,0.004471,-1300.845459,0.015013,0.014482,0.367834,0.019887,0.001013,3.678339,-1300.845459,0.368935,0.000000
22.830002,0.011917,-1300.845459,0.015241,0.014692,0.373185,0.053010,0.002700,3.731846,-1300.845459,0.374260,0.000000
23.150002,0.010803,-1300.845459,0.015513,0.014893,0.378275,0.048055,0.002448,3.782753,-1300.845459,0.379602,0.000000
23.470001,-0.020103,-1300.889893,0.015690,0.015110,0.383799,-0.089425,-0.004556,3.837993,-1300.889893,0.384927,0.000000
23.790001,-0.018242,-1300.889893,0.015944,0.015317,0.389063,-0.081144,-0.004134,3.890634,-1300.889893,0.390251,0.000000
24.110001,0.017502,-1300.845459,0.016138,0.015525,0.394336,0.077852,0.003966,3.943361,-1300.845459,0.395594,0.000000
24.430000,-0.001114,-1300.889893,0.016349,0.015739,0.399765,-0.004955,-0.000252,3.997652,-1300.889893,0.400918,0.000000
24.750002,0.020485,-1300.889893,0.016621,0.015954,0.405229,0.091121,0.004642,4.052287,-1300.889893,0.406260,0.000000
25.070002,0.030907,-1300.934326,0.016806,0.016157,0.410389,0.137480,0.007004,4.103886,-1300.934326,0.411585,0.000000
25.390001,-0.029785,-1300.934326,0.016992,0.016363,0.415626,-0.132491,-0.006749,4.156265,-1300.934326,0.416910,0.000000
25.710001,-0.007072,-1300.845459,0.017250,0.016583,0.421211,-0.031460,-0.001603,4.212115,-1300.845459,0.422252,0.000000
26.030001,0.004097,-1300.845459,0.017483,0.016788,0.426415,0.018224,0.000928,4.264150,-1300.845459,0.427577,0.000000
26.350000,-0.007446,-1300.889893,0.017660,0.016997,0.431713,-0.033123,-0.001687,4.317134,-1300.889893,0.432902,0.000000
26.670002,0.035378,-1300.889893,0.017850,0.017207,0.437065,0.157367,0.008017,4.370646,-1300.889893,0.438244,0.000000
26.990002,0.020111,-1300.934326,0.018130,0.017419,0.442450,0.089459,0.004557,4.424500,-1300.934326,0.443568,0.000000
27.310001,0.022346,-1300.889893,0.018363,0.017628,0.447740,0.099402,0.005064,4.477398,-1300.889893,0.448893,0.000000
27.630001,0.026810,-1300.889893,0.018527,0.017835,0.453013,0.119255,0.006075,4.530126,-1300.889893,0.454235,0.000000
27.950001,0.077827,-1300.934326,0.018811,0.018050,0.458476,0.346194,0.017636,4.584761,-1300.934326,0.459560,0.000000
28.270000,0.118790,-1300.934326,0.018975,0.018256,0.463714,0.528403,0.026918,4.637144,-1300.934326,0.464902,0.000000
28.590002,0.371254,-1300.934326,0.019160,0.018462,0.468926,1.651420,0.084127,4.689261,-1300.934326,0.470227,0.000000
28.910002,0.671761,-1300.934326,0.019462,0.018679,0.474442,2.988140,0.152223,4.744419,-1300.934326,0.475552,0.000000
29.230001,0.585747,-1300.889893,0.019428,-0.000001,-0.000017,2.605532,0.132732,-0.000170,-1300.889893,0.000182,0.000000
29.550001,0.589844,-1300.934326,0.019458,-0.000001,-0.000026,2.623756,0.133661,-0.000257,-1300.934326,0.000312,0.000000
29.870001,0.550369,-1300.934326,0.019436,-0.000001,-0.000017,2.448165,0.124715,-0.000170,-1300.934326,0.000850,0.000000
30.190001,0.546646,-1300.934326,0.019454,-0.000001,-0.000017,2.431603,0.123872,-0.000170,-1300.934326,0.001379,0.000000
30.510002,0.698944,-1300.934326,0.019514,0.000035,0.000885,3.109059,0.158383,0.008849,-1300.934326,0.001917,0.000000
30.830002,0.789803,-1300.978882,0.019501,0.000064,0.001622,3.513217,0.178972,0.016218,-1300.978882,0.002446,0.000000
31.150002,0.789429,-1300.934326,0.019488,0.000083,0.002099,3.511554,0.178887,0.020987,-1300.934326,0.002983,0.000000
31.470001,0.820335,-1300.978882,0.019592,0.000104,0.002637,3.649034,0.185891,0.026366,-1300.978882,0.003512,0.000000
31.790001,0.900024,-1300.978882,0.019622,0.000126,0.003209,4.003509,0.203948,0.032088,-1300.978882,0.004050,0.000000
32.110001,0.912315,-1300.934326,0.019596,0.000142,0.003616,4.058181,0.206734,0.036165,-1300.934326,0.004579,0.000000
32.430000,0.975616,-1300.978882,0.019574,0.000158,0.004007,4.339759,0.221078,0.040067,-1300.978882,0.005117,0.000000
32.750000,1.050835,-1300.978882,0.019665,0.000184,0.004666,4.674346,0.238123,0.046660,-1300.978882,0.005646,0.000000
33.070000,1.114143,-1301.023315,0.019635,0.000208,0.005281,4.955957,0.252468,0.052814,-1301.023315,0.006183,0.000000
33.390003,1.168877,-1301.023315,0.019708,0.000229,0.005828,5.199423,0.264871,0.058280,-1301.023315,0.006713,0.000000
33.710003,1.253784,-1300.978882,0.019712,0.000250,0.006348,5.577111,0.284112,0.063484,-1300.978882,0.007250,0.000000
34.030003,1.279099,-1300.934326,0.019712,0.000266,0.006764,5.689714,0.289848,0.067644,-1300.934326,0.007779,0.000000
34.350002,1.366608,-1300.978882,0.019742,0.000286,0.007259,6.078975,0.309678,0.072587,-1300.978882,0.008317,0.000000
34.670002,1.452629,-1300.978882,0.019790,0.000313,0.007944,6.461617,0.329170,0.079441,-1300.978882,0.008846,0.000000
34.990002,1.505875,-1301.067871,0.019816,0.000329,0.008369,6.698465,0.341236,0.083688,-1301.067871,0.009384,0.000000
35.310001,1.539017,-1301.023315,0.019837,0.000347,0.008820,6.845888,0.348746,0.088199,-1301.023315,0.009913,0.000000
35.630001,1.717010,-1300.934326,0.019837,0.000374,0.009505,7.637644,0.389080,0.095050,-1300.934326,0.010450,0.000000
35.950001,1.751640,-1301.067871,0.019867,0.000392,0.009956,7.791685,0.396927,0.099558,-1301.067871,0.010979,0.000000
36.270000,1.874901,-1301.112305,0.019850,0.000412,0.010459,8.339975,0.424859,0.104588,-1301.112305,0.011517,0.000000
36.590000,1.992195,-1301.023315,0.019911,0.000438,0.011118,8.861727,0.451438,0.111181,-1301.023315,0.012046,0.000000
36.910000,2.087898,-1301.023315,0.019906,0.000457,0.011604,9.287436,0.473125,0.116037,-1301.023315,0.012584,0.000000
37.230003,2.159760,-1301.067871,0.019906,0.000474,0.012029,9.607090,0.489408,0.120288,-1301.067871,0.013113,0.000000
37.550003,2.283394,-1301.067871,0.019967,0.000496,0.012592,10.157043,0.517424,0.125923,-1301.067871,0.013650,0.000000
37.870003,2.426010,-1301.023315,0.019984,0.000518,0.013156,10.791432,0.549742,0.131559,-1301.023315,0.014179,0.000000
38.190002,2.537346,-1301.067871,0.019954,0.000539,0.013702,11.286678,0.574971,0.137025,-1301.067871,0.014717,0.000000
38.510002,2.664330,-1301.023315,0.019984,0.000558,0.014179,11.851530,0.603746,0.141794,-1301.023315,0.015246,0.000000
38.830002,2.816628,-1301.067871,0.020001,0.000581,0.014769,12.528985,0.638257,0.147690,-1301.067871,0.015784,0.000000
39.150002,2.889984,-1301.023315,0.020057,0.000601,0.015263,12.855291,0.654880,0.152633,-1301.023315,0.016313,0.000000
39.470001,3.084732,-1301.112305,0.020044,0.000626,0.015897,13.721574,0.699010,0.158966,-1301.112305,0.016850,0.000000
39.790001,3.263100,-1301.067871,0.020087,0.000650,0.016512,14.514993,0.739429,0.165120,-1301.067871,0.017379,0.000000
40.110001,3.357315,-1301.067871,0.020135,0.000668,0.016972,14.934083,0.760778,0.169718,-1301.067871,0.017917,0.000000
40.430000,3.555412,-1301.067871,0.020113,0.000692,0.017588,15.815264,0.805668,0.175876,-1301.067871,0.018446,0.000000
40.750004,3.578873,-1301.112305,0.020182,0.000710,0.018030,15.919621,0.810984,0.180297,-1301.112305,0.018984,0.000000
41.070004,3.777718,-1301.112305,0.020139,0.000731,0.018576,16.804127,0.856043,0.185763,-1301.112305,0.019513,0.000000
41.390003,4.011574,-1301.067871,0.020195,0.000755,0.019175,17.844372,0.909036,0.191747,-1301.067871,0.020050,0.000000
41.710003,4.103920,-1301.112305,0.020208,0.000773,0.019643,18.255148,0.929962,0.196428,-1301.112305,0.020580,0.000000
42.030003,4.249146,-1301.067871,0.020225,0.000795,0.020189,18.901144,0.962870,0.201890,-1301.067871,0.021117,0.000000
42.350002,4.367928,-1301.112305,0.020238,0.000812,0.020614,19.429512,0.989787,0.206141,-1301.112305,0.021646,0.000000
42.670002,4.150467,-1301.112305,0.020303,0.000812,0.020623,18.462198,0.940509,0.206228,-1301.112305,0.022184,0.000000
42.990002,4.742538,-1301.067871,0.020307,0.000856,0.021742,21.095865,1.074675,0.217416,-1301.067871,0.022713,0.000000
43.310001,4.860207,-1301.067871,0.020294,0.000878,0.022305,21.619278,1.101339,0.223051,-1301.067871,0.023251,0.000000
43.630001,4.944366,-1301.067871,0.020307,0.000894,0.022713,21.993641,1.120409,0.227128,-1301.067871,0.023779,0.000000
43.950001,4.686684,-1301.023315,0.020381,0.000894,0.022713,20.847410,1.062018,0.227128,-1301.023315,0.024317,0.000000
44.270000,5.439247,-1301.112305,0.020381,0.000937,0.023797,24.194979,1.232551,0.237968,-1301.112305,0.024846,0.000000
44.590004,5.410576,-1301.023315,0.020385,0.000959,0.024361,24.067444,1.226054,0.243607,-1301.023315,0.025384,0.000000
44.910004,5.542023,-1301.023315,0.020402,0.000983,0.024976,24.652147,1.255840,0.249761,-1301.023315,0.025913,0.000000
45.230003,5.377060,-1301.156738,0.020385,0.000990,0.025150,23.918358,1.218459,0.251499,-1301.156738,0.026451,0.000000
45.550003,5.852577,-1301.112305,0.020488,0.001019,0.025887,26.033564,1.326213,0.258868,-1301.112305,0.026979,0.000000
45.870003,6.058876,-1301.156738,0.020471,0.001042,0.026476,26.951227,1.372961,0.264765,-1301.156738,0.027517,0.000000
46.190002,5.993706,-1301.067871,0.020475,0.001060,0.026928,26.661335,1.358193,0.269276,-1301.067871,0.028046,0.000000
46.510002,6.273361,-1301.067871,0.020506,0.001087,0.027604,27.905304,1.421564,0.276040,-1301.067871,0.028584,0.000000
46.830002,6.349327,-1301.067871,0.020536,0.001108,0.028150,28.243217,1.438778,0.281502,-1301.067871,0.029113,0.000000
47.150002,6.467369,-1301.156738,0.020540,0.001130,0.028697,28.768295,1.465527,0.286967,-1301.156738,0.029650,0.000000
47.470001,6.645737,-1301.112305,0.020583,0.001153,0.029278,29.561714,1.505945,0.292777,-1301.112305,0.030180,0.000000
47.790001,6.690048,-1301.067871,0.020596,0.001170,0.029711,29.758821,1.515987,0.297114,-1301.067871,0.030717,0.000000
48.110001,6.966721,-1301.112305,0.020596,0.001193,0.030301,30.989521,1.578681,0.303011,-1301.112305,0.031246,0.000000
48.430004,7.077682,-1301.156738,0.020626,0.001214,0.030847,31.483105,1.603826,0.308473,-1301.156738,0.031784,0.000000
48.750004,7.141731,-1301.156738,0.020708,0.001235,0.031368,31.768007,1.618340,0.313677,-1301.156738,0.032313,0.000000
49.070004,7.159981,-1301.112305,0.020674,0.001253,0.031827,31.849186,1.622475,0.318272,-1301.112305,0.032851,0.000000
49.390003,7.372978,-1301.156738,0.020713,0.001276,0.032400,32.796646,1.670741,0.323998,-1301.156738,0.033380,0.000000
49.710003,7.490273,-1301.112305,0.020682,0.001295,0.032885,33.318398,1.697320,0.328854,-1301.112305,0.033917,0.000000
50.030003,7.734550,-1301.201294,0.020769,0.001319,0.033493,34.404999,1.752674,0.334925,-1301.201294,0.034446,0.000000
50.350002,7.927071,-1301.201294,0.020790,0.001343,0.034108,35.261372,1.796300,0.341083,-1301.201294,0.034984,0.000000
50.670002,7.858925,-1301.201294,0.020812,0.001362,0.034585,34.958244,1.780858,0.345852,-1301.201294,0.035513,0.000000
50.990002,7.917389,-1301.156738,0.020764,0.001378,0.035002,35.218304,1.794106,0.350016,-1301.156738,0.036051,0.000000
51.310001,8.211563,-1301.156738,0.020799,0.001405,0.035678,36.526855,1.860767,0.356779,-1301.156738,0.036580,0.000000
51.630001,8.284920,-1301.156738,0.020876,0.001421,0.036094,36.853165,1.877390,0.360943,-1301.156738,0.037117,0.000000
51.950001,8.639420,-1301.245728,0.020894,0.001447,0.036745,38.430058,1.957721,0.367445,-1301.245728,0.037646,0.000000
52.270004,8.677025,-1301.201294,0.020898,0.001467,0.037274,38.597336,1.966242,0.372736,-1301.201294,0.038184,0.000000
52.590004,8.818901,-1301.156738,0.020876,0.001490,0.037855,39.228432,1.998392,0.378546,-1301.156738,0.038722,0.000000
52.910004,8.779053,-1301.201294,0.020898,0.001508,0.038314,39.051178,1.989362,0.383141,-1301.201294,0.039251,0.000000
53.230003,9.061317,-1301.245728,0.020963,0.001530,0.038861,40.306751,2.053324,0.388607,-1301.245728,0.039788,0.000000
53.550003,9.032639,-1301.245728,0.020937,0.001547,0.039285,40.179184,2.046825,0.392853,-1301.245728,0.040317,0.000000
53.870003,9.413208,-1301.156738,0.020997,0.001572,0.039927,41.872040,2.133064,0.399272,-1301.156738,0.040855,0.000000
54.190002,9.555077,-1301.156738,0.021014,0.001593,0.040474,42.503105,2.165211,0.404738,-1301.156738,0.041384,0.000000
54.510002,9.654503,-1301.201294,0.021045,0.001617,0.041080,42.945374,2.187742,0.410805,-1301.201294,0.041922,0.000000
54.830002,9.501831,-1301.245728,0.021045,0.001633,0.041488,42.266254,2.153146,0.414881,-1301.245728,0.042451,0.000000
55.150002,9.709618,-1301.201294,0.021049,0.001655,0.042026,43.190536,2.200231,0.420260,-1301.201294,0.042988,0.000000
55.470001,9.731583,-1301.201294,0.021083,0.001673,0.042503,43.288242,2.205208,0.425029,-1301.201294,0.043518,0.000000
55.790001,10.158325,-1301.156738,0.021126,0.001697,0.043101,45.186489,2.301909,0.431012,-1301.156738,0.044055,0.000000
56.110004,10.036926,-1301.201294,0.021092,0.001715,0.043552,44.646477,2.274400,0.435524,-1301.201294,0.044584,0.000000
56.430004,10.135979,-1301.290283,0.021122,0.001737,0.044125,45.087086,2.296846,0.441247,-1301.290283,0.045122,0.000000
56.750004,10.042519,-1301.334717,0.021165,0.001753,0.044524,44.671352,2.275667,0.445236,-1301.334717,0.045651,0.000000
57.070004,10.473351,-1301.201294,0.021170,0.001778,0.045165,46.587791,2.373295,0.451652,-1301.201294,0.046189,0.000000
57.390003,10.522873,-1301.201294,0.021170,0.001797,0.045634,46.808075,2.384517,0.456337,-1301.201294,0.046718,0.000000
57.710003,10.890038,-1301.290283,0.021195,0.001826,0.046371,48.441307,2.467718,0.463706,-1301.290283,0.047255,0.000000
58.030003,10.661026,-1301.290283,0.021208,0.001842,0.046778,47.422611,2.415823,0.467783,-1301.290283,0.047784,0.000000
58.350002,10.701988,-1301.245728,0.021264,0.001860,0.047238,47.604820,2.425105,0.472381,-1301.245728,0.048322,0.000000
58.670002,10.833061,-1301.245728,0.021221,0.001880,0.047749,48.187862,2.454807,0.477495,-1301.245728,0.048851,0.000000
58.990002,11.230011,-1301.245728,0.021277,0.001907,0.048426,49.953583,2.544757,0.484262,-1301.245728,0.049389,0.000000
59.310001,11.093719,-1301.245728,0.021273,0.001926,0.048921,49.347328,2.513873,0.489205,-1301.245728,0.049918,0.000000
59.630001,11.191284,-1301.334717,0.021295,0.001949,0.049493,49.781319,2.535981,0.494928,-1301.334717,0.050455,0.000000
59.950005,10.964134,-1301.245728,0.021364,0.001962,0.049831,48.770905,2.484508,0.498308,-1301.245728,0.050984,0.000000
60.270004,11.323479,-1301.245728,0.021364,0.001985,0.050421,50.369350,2.565937,0.504209,-1301.245728,0.051522,0.000000
60.590004,11.480621,-1301.245728,0.021385,0.002010,0.051045,51.068356,2.601546,0.510450,-1301.245728,0.052051,0.000000
60.910004,11.759521,-1301.379150,0.021407,0.002036,0.051713,52.308964,2.664746,0.517130,-1301.379150,0.052589,0.000000
61.230003,11.616905,-1301.290283,0.021411,0.002054,0.052173,51.674576,2.632428,0.521725,-1301.290283,0.053118,0.000000
61.550003,11.729736,-1301.201294,0.021407,0.002077,0.052745,52.176472,2.657996,0.527448,-1301.201294,0.053655,0.000000
61.870003,11.947197,-1301.245728,0.021445,0.002100,0.053334,53.143787,2.707274,0.533345,-1301.245728,0.054185,0.000000
62.190002,11.802719,-1301.334717,0.021411,0.002117,0.053760,52.501118,2.674534,0.537595,-1301.334717,0.054722,0.000000
62.510002,11.703667,-1301.334717,0.021493,0.002135,0.054228,52.060509,2.652089,0.542277,-1301.334717,0.055251,0.000000
62.830002,12.178818,-1301.290283,0.021506,0.002160,0.054870,54.174088,2.759759,0.548696,-1301.290283,0.055789,0.000000
63.150002,12.227226,-1301.290283,0.021476,0.002181,0.055398,54.389420,2.770729,0.553984,-1301.290283,0.056318,0.000000
63.470001,12.177330,-1301.334717,0.021553,0.002199,0.055867,54.167469,2.759422,0.558669,-1301.334717,0.056856,0.000000
63.790005,11.953156,-1301.334717,0.021566,0.002210,0.056127,53.170292,2.708624,0.561270,-1301.334717,0.057385,0.000000
64.110001,12.805145,-1301.290283,0.021575,0.002241,0.056934,56.960133,2.901687,0.569335,-1301.290283,0.057922,0.000000
64.430000,12.608536,-1301.379150,0.021583,0.002261,0.057428,56.085567,2.857135,0.574278,-1301.379150,0.058451,0.000000
64.750000,12.443199,-1301.245728,0.021601,0.002277,0.057827,55.350113,2.819669,0.578268,-1301.245728,0.058989,0.000000
65.070000,12.814087,-1301.334717,0.021618,0.002306,0.058564,56.999905,2.903713,0.585641,-1301.334717,0.059518,0.000000
65.389999,12.695297,-1301.334717,0.021644,0.002322,0.058980,56.471504,2.876796,0.589800,-1301.334717,0.060056,0.000000
65.710007,12.925049,-1301.334717,0.021661,0.002347,0.059605,57.493488,2.928858,0.596045,-1301.334717,0.060584,0.000000
66.030006,13.045700,-1301.379150,0.021648,0.002369,0.060177,58.030170,2.956198,0.601768,-1301.379150,0.061122,0.000000
66.350006,12.890793,-1301.334717,0.021696,0.002385,0.060576,57.341110,2.921095,0.605757,-1301.334717,0.061651,0.000000
66.670006,12.955215,-1301.334717,0.021652,0.002404,0.061062,57.627678,2.935694,0.610617,-1301.334717,0.062189,0.000000
66.990005,12.835312,-1301.334717,0.021704,0.002414,0.061322,57.094318,2.908523,0.613217,-1301.334717,0.062718,0.000000
67.310005,13.925240,-1301.334717,0.021739,0.002448,0.062189,61.942558,3.155504,0.621889,-1301.334717,0.063255,0.000000
67.630005,13.918915,-1301.290283,0.021713,0.002475,0.062874,61.914425,3.154071,0.628739,-1301.290283,0.063785,0.000000
67.950005,13.467598,-1301.334717,0.021713,0.002492,0.063299,59.906868,3.051801,0.632990,-1301.334717,0.064322,0.000000
68.270004,13.641869,-1301.334717,0.021803,0.002514,0.063863,60.682064,3.091291,0.638625,-1301.334717,0.064851,0.000000
68.590004,13.777412,-1301.334717,0.021803,0.002535,0.064400,61.284992,3.122006,0.644004,-1301.334717,0.065389,0.000000
68.910004,13.780388,-1301.334717,0.021821,0.002558,0.064964,61.298225,3.122680,0.649639,-1301.334717,0.065918,0.000000
69.230003,13.735336,-1301.334717,0.021786,0.002576,0.065424,61.097828,3.112472,0.654238,-1301.334717,0.066456,0.000000
69.550003,13.996368,-1301.334717,0.021842,0.002599,0.066013,62.258957,3.171623,0.660135,-1301.334717,0.066985,0.000000
69.870003,14.079407,-1301.379150,0.021851,0.002620,0.066542,62.628330,3.190439,0.665422,-1301.379150,0.067523,0.000000
70.190002,14.250320,-1301.334717,0.021890,0.002642,0.067106,63.388592,3.229169,0.671062,-1301.334717,0.068051,0.000000
70.510002,14.528488,-1301.379150,0.021890,0.002664,0.067661,64.625946,3.292202,0.676611,-1301.379150,0.068589,0.000000
70.830002,14.579132,-1301.379150,0.021907,0.002685,0.068199,64.851219,3.303679,0.681989,-1301.379150,0.069118,0.000000
71.150002,14.342674,-1301.290283,0.021911,0.002700,0.068580,63.799400,3.250096,0.685804,-1301.290283,0.069656,0.000000
71.470001,14.787285,-1301.334717,0.021890,0.002726,0.069248,65.777130,3.350847,0.692481,-1301.334717,0.070185,0.000000
71.790001,14.950760,-1301.334717,0.021920,0.002750,0.069855,66.504303,3.387891,0.698552,-1301.334717,0.070722,0.000000
72.110001,14.764198,-1301.423706,0.021971,0.002767,0.070280,65.674431,3.345615,0.702802,-1301.423706,0.071251,0.000000
72.430000,15.062843,-1301.423706,0.021959,0.002791,0.070896,67.002876,3.413289,0.708960,-1301.423706,0.071789,0.000000
72.750000,15.344353,-1301.379150,0.021971,0.002814,0.071477,68.255089,3.477080,0.714770,-1301.379150,0.072318,0.000000
73.070000,15.060608,-1301.334717,0.021980,0.002828,0.071841,66.992928,3.412783,0.718411,-1301.334717,0.072856,0.000000
73.390007,15.631454,-1301.379150,0.021976,0.002855,0.072509,69.532181,3.542138,0.725087,-1301.379150,0.073385,0.000000
73.710007,15.487717,-1301.379150,0.022032,0.002875,0.073029,68.892807,3.509567,0.730292,-1301.379150,0.073922,0.000000
74.030006,15.647095,-1301.334717,0.022079,0.002896,0.073567,69.601753,3.545682,0.735670,-1301.334717,0.074452,0.000000
74.350006,15.693268,-1301.379150,0.022066,0.002917,0.074087,69.807144,3.556145,0.740874,-1301.379150,0.074989,0.000000
74.670006,15.758430,-1301.334717,0.022109,0.002936,0.074564,70.097000,3.570911,0.745643,-1301.334717,0.075518,0.000000
74.990005,15.681725,-1301.334717,0.022084,0.002953,0.074998,69.755798,3.553530,0.749977,-1301.334717,0.076056,0.000000
75.310005,16.250336,-1301.379150,0.022092,0.002976,0.075587,72.285103,3.682379,0.755874,-1301.379150,0.076585,0.000000
75.630005,16.446579,-1301.468140,0.022122,0.003000,0.076212,73.158035,3.726848,0.762119,-1301.468140,0.077123,0.000000
75.950005,16.527008,-1301.379150,0.022157,0.003024,0.076810,73.515800,3.745074,0.768103,-1301.379150,0.077652,0.000000
76.270004,16.375450,-1301.334717,0.022161,0.003041,0.077253,72.841637,3.710730,0.772527,-1301.334717,0.078189,0.000000
76.590004,16.563873,-1301.379150,0.022166,0.003062,0.077781,73.679787,3.753428,0.777815,-1301.379150,0.078718,0.000000
76.910004,16.523285,-1301.379150,0.022183,0.003078,0.078189,73.499245,3.744230,0.781891,-1301.379150,0.079256,0.000000
77.230003,17.056892,-1301.423706,0.022209,0.003105,0.078857,75.872849,3.865147,0.788572,-1301.423706,0.079785,0.000000
77.550003,17.023010,-1301.379150,0.022239,0.003123,0.079325,75.722130,3.857469,0.793253,-1301.379150,0.080323,0.000000
77.870003,17.109398,-1301.379150,0.022230,0.003142,0.079811,76.106400,3.877045,0.798109,-1301.379150,0.080852,0.000000
78.190002,17.434105,-1301.379150,0.022260,0.003164,0.080366,77.550774,3.950625,0.803658,-1301.379150,0.081389,0.000000
78.510002,17.051682,-1301.468140,0.022269,0.003176,0.080661,75.849670,3.863966,0.806607,-1301.468140,0.081918,0.000000
78.830002,17.761055,-1301.423706,0.022291,0.003204,0.081381,79.005119,4.024713,0.813805,-1301.423706,0.082456,0.000000
79.150002,18.152786,-1301.334717,0.022321,0.003229,0.082022,80.747627,4.113480,0.820225,-1301.334717,0.082985,0.000000
79.470001,17.935326,-1301.379150,0.022308,0.003247,0.082473,79.780312,4.064203,0.824732,-1301.379150,0.083523,0.000000
79.790001,17.966599,-1301.423706,0.022303,0.003268,0.083020,79.919418,4.071290,0.830198,-1301.423706,0.084052,0.000000
80.110001,17.926758,-1301.423706,0.022390,0.003284,0.083419,79.742203,4.062262,0.834187,-1301.423706,0.084589,0.000000
80.430000,18.732201,-1301.468140,0.022360,0.003311,0.084095,83.324989,4.244777,0.840951,-1301.468140,0.085119,0.000000
80.750008,18.780235,-1301.379150,0.022372,0.003332,0.084624,83.538658,4.255662,0.846242,-1301.379150,0.085656,0.000000
81.070007,18.923225,-1301.379150,0.022398,0.003351,0.085110,84.174713,4.288064,0.851098,-1301.379150,0.086185,0.000000
81.390007,19.187241,-1301.334717,0.022377,0.003373,0.085665,85.349106,4.347891,0.856647,-1301.334717,0.086723,0.000000
81.710007,19.368958,-1301.423706,0.022390,0.003395,0.086237,86.157425,4.389068,0.862369,-1301.423706,0.087252,0.000000
82.030006,19.859001,-1301.468140,0.022420,0.003419,0.086853,88.337250,4.500114,0.868527,-1301.468140,0.087789,0.000000
82.350006,19.784897,-1301.468140,0.022489,0.003440,0.087373,88.007614,4.483322,0.873732,-1301.468140,0.088318,0.000000
82.670006,19.992310,-1301.423706,0.022493,0.003460,0.087885,88.930237,4.530322,0.878849,-1301.423706,0.088856,0.000000
82.990005,20.486816,-1301.423706,0.022485,0.003482,0.088448,91.129913,4.642379,0.884485,-1301.423706,0.089385,0.000000
83.310005,20.770569,-1301.468140,0.022472,0.003504,0.088995,92.392105,4.706678,0.889950,-1301.468140,0.089923,0.000000
83.630005,20.897545,-1301.557129,0.022515,0.003526,0.089550,92.956924,4.735452,0.895499,-1301.557129,0.090452,0.000000
83.950005,21.173103,-1301.468140,0.022588,0.003545,0.090044,94.182671,4.797894,0.900442,-1301.468140,0.090990,0.000000
84.270004,21.558876,-1301.423706,0.022610,0.003566,0.090573,95.898666,4.885311,0.905733,-1301.423706,0.091518,0.000000
84.590004,22.018387,-1301.512573,0.022605,0.003587,0.091111,97.942673,4.989438,0.911107,-1301.512573,0.092056,0.000000
84.910004,21.870552,-1301.512573,0.022614,0.003605,0.091562,97.285072,4.955938,0.915619,-1301.512573,0.092585,0.000000
85.230003,21.518661,-1301.512573,0.022627,0.003609,0.091657,95.719788,4.876198,0.916573,-1301.512573,0.093123,0.000000
85.550003,23.442711,-1301.468140,0.022627,0.003649,0.092681,104.278389,5.312194,0.926807,-1301.468140,0.093652,0.000000
85.870003,23.504898,-1301.512573,0.022657,0.003668,0.093175,104.555008,5.326286,0.931750,-1301.512573,0.094189,0.000000
86.190002,24.087288,-1301.423706,0.022666,0.003690,0.093730,107.145607,5.458258,0.937299,-1301.423706,0.094719,0.000000
86.510002,23.267693,-1301.512573,0.022627,0.003691,0.093756,103.499863,5.272534,0.937560,-1301.512573,0.095256,0.000000
86.830002,22.489067,-1301.601562,0.022661,0.003692,0.093773,100.036369,5.096096,0.937734,-1301.601562,0.095785,0.000000
87.150002,26.095863,-1301.557129,0.022679,0.003755,0.095369,116.080200,5.913407,0.953691,-1301.557129,0.096323,0.000000
87.470001,26.136078,-1301.468140,0.022717,0.003774,0.095872,116.259079,5.922520,0.958721,-1301.468140,0.096852,0.000000
87.790001,25.978195,-1301.557129,0.022713,0.003787,0.096193,115.556786,5.886743,0.961927,-1301.557129,0.097390,0.000000
88.110001,26.707672,-1301.468140,0.022717,0.003812,0.096817,118.801659,6.052045,0.968172,-1301.468140,0.097919,0.000000
88.430008,27.971130,-1301.557129,0.022756,0.003836,0.097433,124.421799,6.338349,0.974330,-1301.557129,0.098456,0.000000
88.750008,28.306267,-1301.468140,0.022817,0.003854,0.097901,125.912560,6.414292,0.979012,-1301.468140,0.098985,0.000000
89.070007,29.277412,-1301.468140,0.022786,0.003880,0.098552,130.232437,6.634356,0.985519,-1301.468140,0.099523,0.000000
89.390007,29.412956,-1301.512573,0.022821,0.003898,0.099003,130.835358,6.665071,0.990026,-1301.512573,0.100052,0.000000
89.710007,30.129028,-1301.601562,0.022804,0.003919,0.099540,134.020615,6.827335,0.995405,-1301.601562,0.100590,0.000000
90.030006,31.315781,-1301.601562,0.022842,0.003944,0.100182,139.299545,7.096257,1.001820,-1301.601562,0.101119,0.000000
90.350006,31.687408,-1301.512573,0.022894,0.003960,0.100590,140.952637,7.180470,1.005896,-1301.512573,0.101656,0.000000
90.670006,32.346878,-1301.512573,0.022881,0.003983,0.101179,143.886093,7.329907,1.011793,-1301.512573,0.102185,0.000000
90.990005,33.444260,-1301.512573,0.022920,0.004005,0.101735,148.767502,7.578578,1.017346,-1301.512573,0.102723,0.000000
91.310005,34.305557,-1301.601562,0.022873,0.004027,0.102281,152.598740,7.773750,1.022807,-1301.601562,0.103252,0.000000
91.630005,34.946037,-1301.557129,0.022903,0.004044,0.102723,155.447739,7.918885,1.027232,-1301.557129,0.103790,0.000000
91.950005,36.090340,-1301.557129,0.022894,0.004068,0.103330,160.537842,8.178187,1.033303,-1301.557129,0.104319,0.000000
92.270004,37.041756,-1301.512573,0.022946,0.004088,0.103842,164.769958,8.393782,1.038416,-1301.512573,0.104856,0.000000
92.590004,37.720963,-1301.601562,0.022980,0.004108,0.104345,167.791214,8.547692,1.043446,-1301.601562,0.105385,0.000000
92.910004,39.317322,-1301.601562,0.022985,0.004133,0.104969,174.892181,8.909432,1.049691,-1301.601562,0.105923,0.000000
93.230003,40.323845,-1301.557129,0.022993,0.004153,0.105490,179.369415,9.137514,1.054896,-1301.557129,0.106452,0.000000
93.550003,41.007149,-1301.557129,0.023028,0.004171,0.105932,182.408905,9.292353,1.059316,-1301.557129,0.106990,0.000000
93.870003,42.467216,-1301.601562,0.022985,0.004195,0.106565,188.903610,9.623209,1.065649,-1301.601562,0.107519,0.000000
94.190002,43.441345,-1301.557129,0.023024,0.004214,0.107042,193.236755,9.843949,1.070418,-1301.557129,0.108056,0.000000
94.510002,44.079964,-1301.512573,0.023032,0.004231,0.107467,196.077469,9.988662,1.074668,-1301.512573,0.108586,0.000000
94.830002,46.299301,-1301.601562,0.023088,0.004260,0.108204,205.949585,10.491571,1.082041,-1301.601562,0.109123,0.000000
95.150002,47.292793,-1301.646118,0.023080,0.004280,0.108707,210.368851,10.716700,1.087067,-1301.646118,0.109652,0.000000
95.470001,48.546944,-1301.557129,0.023062,0.004300,0.109218,215.947586,11.000895,1.092184,-1301.557129,0.110190,0.000000
95.790001,49.958984,-1301.601562,0.023067,0.004323,0.109800,222.228668,11.320868,1.097998,-1301.601562,0.110719,0.000000
96.110008,50.793098,-1301.557129,0.023105,0.004336,0.110147,225.938980,11.509881,1.101465,-1301.557129,0.111257,0.000000
96.430008,51.762383,-1301.690552,0.023097,0.004353,0.110572,230.250580,11.729523,1.105715,-1301.690552,0.111786,0.000000
96.750008,53.732979,-1301.601562,0.023149,0.004381,0.111283,239.016220,12.176066,1.112827,-1301.601562,0.112323,0.000000
97.070007,55.447754,-1301.646118,0.023144,0.004405,0.111889,246.643921,12.564641,1.118894,-1301.646118,0.112852,0.000000
97.390007,56.932770,-1301.601562,0.023170,0.004425,0.112401,253.249603,12.901151,1.124012,-1301.601562,0.113390,0.000000
97.710007,58.280762,-1301.557129,0.023140,0.004447,0.112956,259.245789,13.206609,1.129564,-1301.557129,0.113919,0.000000
98.030006,59.464531,-1301.601562,0.023192,0.004463,0.113355,264.511444,13.474855,1.133553,-1301.601562,0.114457,0.000000
98.350006,60.690758,-1301.601562,0.023200,0.004481,0.113824,269.965973,13.752723,1.138235,-1301.601562,0.114985,0.000000
98.670006,62.799873,-1301.601562,0.023161,0.004509,0.114526,279.347778,14.230655,1.145260,-1301.601562,0.115523,0.000000
98.990005,64.048065,-1301.646118,0.023213,0.004526,0.114951,284.900024,14.513499,1.149511,-1301.646118,0.116052,0.000000
99.310005,65.598251,-1301.646118,0.023265,0.004545,0.115454,291.795593,14.864777,1.154541,-1301.646118,0.116590,0.000000
99.630005,67.557678,-1301.690552,0.023205,0.004560,0.115827,300.511566,15.308789,1.158269,-1301.690552,0.117084,0.000000
99.950005,66.908630,-1301.646118,0.023287,0.004557,0.115758,297.624451,15.161713,1.157576,-1301.646118,0.116035,0.000000
100.270004,66.516525,-1301.601562,0.023291,0.004553,0.115654,295.880280,15.072860,1.156535,-1301.601562,0.115758,0.000000
100.590004,66.148239,-1301.734985,0.023213,0.004552,0.115627,294.242065,14.989405,1.156274,-1301.734985,0.115758,0.000000
100.910004,65.852951,-1301.690552,0.023243,0.004552,0.115610,292.928558,14.922492,1.156100,-1301.690552,0.115758,0.000000
101.230003,65.603836,-1301.690552,0.023235,0.004551,0.115601,291.820435,14.866042,1.156013,-1301.690552,0.115758,0.000000
101.550003,65.372223,-1301.646118,0.023252,0.004551,0.115593,290.790161,14.813558,1.155926,-1301.646118,0.115758,0.000000
101.870003,65.195343,-1301.690552,0.023226,0.004551,0.115593,290.003357,14.773476,1.155926,-1301.690552,0.115758,0.000000
102.190002,65.017349,-1301.646118,0.023248,0.004551,0.115584,289.211609,14.733142,1.155839,-1301.646118,0.115758,0.000000
102.510002,64.864685,-1301.734985,0.023269,0.004551,0.115584,288.532532,14.698548,1.155839,-1301.734985,0.115758,0.000000
102.830002,64.712372,-1301.734985,0.023291,0.004550,0.115575,287.855011,14.664033,1.155752,-1301.734985,0.115758,0.000000
103.150002,64.590988,-1301.779541,0.023261,0.004550,0.115575,287.315063,14.636527,1.155752,-1301.779541,0.115758,0.000000
103.470001,64.470337,-1301.690552,0.023261,0.004550,0.115575,286.778381,14.609187,1.155752,-1301.690552,0.115758,0.000000
103.790009,64.368683,-1301.646118,0.023274,0.004550,0.115575,286.326202,14.586152,1.155752,-1301.646118,0.115758,0.000000
104.110008,64.262558,-1301.779541,0.023299,0.004550,0.115567,285.854126,14.562104,1.155668,-1301.779541,0.115758,0.000000
104.430008,64.163132,-1301.779541,0.023248,0.004550,0.115567,285.411865,14.539573,1.155668,-1301.779541,0.115758,0.000000
104.750008,64.080841,-1301.690552,0.023235,0.004550,0.115567,285.045807,14.520926,1.155668,-1301.690552,0.115758,0.000000
105.070007,64.003754,-1301.734985,0.023239,0.004550,0.115567,284.702911,14.503457,1.155668,-1301.734985,0.115758,0.000000
105.390007,63.916611,-1301.646118,0.023278,0.004550,0.115567,284.315277,14.483711,1.155668,-1301.646118,0.115758,0.000000
105.710007,63.837677,-1301.779541,0.023278,0.004550,0.115567,283.964172,14.465825,1.155668,-1301.779541,0.115758,0.000000
106.030006,63.787033,-1301.734985,0.023282,0.004550,0.115567,283.738892,14.454349,1.155668,-1301.734985,0.115758,0.000000
106.350006,63.705856,-1301.690552,0.023308,0.004550,0.115567,283.377808,14.435953,1.155668,-1301.690552,0.115758,0.000000
106.670006,63.646271,-1301.734985,0.023265,0.004550,0.115567,283.112762,14.422451,1.155668,-1301.734985,0.115758,0.000000
106.990005,63.599350,-1301.734985,0.023226,0.004550,0.115567,282.904053,14.411819,1.155668,-1301.734985,0.115758,0.000000
107.310005,63.533813,-1301.779541,0.023248,0.004550,0.115567,282.612518,14.396968,1.155668,-1301.779541,0.115758,0.000000
107.630005,63.488388,-1301.779541,0.023265,0.004550,0.115567,282.410461,14.386675,1.155668,-1301.779541,0.115758,0.000000
107.950005,63.435135,-1301.779541,0.023278,0.004550,0.115567,282.173584,14.374607,1.155668,-1301.779541,0.115758,0.000000
108.270004,63.387848,-1301.646118,0.023278,0.004550,0.115567,281.963226,14.363892,1.155668,-1301.646118,0.115758,0.000000
108.590004,63.333115,-1301.779541,0.023265,0.004550,0.115567,281.719757,14.351489,1.155668,-1301.779541,0.115758,0.000000
108.910004,63.294754,-1301.779541,0.023261,0.004550,0.115567,281.549133,14.342796,1.155668,-1301.779541,0.115758,0.000000
109.230003,63.247833,-1301.779541,0.023256,0.004550,0.115567,281.340424,14.332164,1.155668,-1301.779541,0.115758,0.000000
109.550003,63.208359,-1301.734985,0.023295,0.004550,0.115567,281.164825,14.323218,1.155668,-1301.734985,0.115758,0.000000
109.870003,63.154007,-1301.779541,0.023274,0.004550,0.115567,280.923065,14.310903,1.155668,-1301.779541,0.115758,0.000000
110.190002,63.127182,-1301.779541,0.023287,0.004550,0.115567,280.803741,14.304824,1.155668,-1301.779541,0.115758,0.000000
110.510002,63.076172,-1301.779541,0.023261,0.004550,0.115567,280.576813,14.293265,1.155668,-1301.779541,0.115758,0.000000
110.830002,63.046753,-1301.779541,0.023269,0.004550,0.115567,280.445953,14.286599,1.155668,-1301.779541,0.115758,0.000000
111.150002,63.006538,-1301.779541,0.023252,0.004550,0.115567,280.267090,14.277486,1.155668,-1301.779541,0.115758,0.000000
111.470009,62.985687,-1301.779541,0.023274,0.004550,0.115567,280.174316,14.272760,1.155668,-1301.779541,0.115758,0.000000
111.790009,62.944725,-1301.823975,0.023299,0.004550,0.115567,279.992126,14.263478,1.155668,-1301.823975,0.115758,0.000000
112.110008,62.917168,-1301.779541,0.023295,0.004550,0.115567,279.869537,14.257234,1.155668,-1301.779541,0.115758,0.000000
112.430008,62.875839,-1301.823975,0.023274,0.004550,0.115567,279.685699,14.247869,1.155668,-1301.823975,0.115758,0.000000
112.750008,62.848656,-1301.734985,0.023287,0.004550,0.115567,279.564789,14.241709,1.155668,-1301.734985,0.115758,0.000000
113.070007,62.813278,-1301.779541,0.023274,0.004550,0.115567,279.407410,14.233692,1.155668,-1301.779541,0.115758,0.000000
113.390007,62.789818,-1301.779541,0.023265,0.004550,0.115567,279.303070,14.228376,1.155668,-1301.779541,0.115758,0.000000
113.710007,62.754440,-1301.868530,0.023278,0.004550,0.115567,279.145691,14.220359,1.155668,-1301.868530,0.115758,0.000000
114.030006,62.719070,-1301.823975,0.023278,0.004550,0.115567,278.988373,14.212344,1.155668,-1301.823975,0.115758,0.000000
114.350006,62.682579,-1301.734985,0.023278,0.004550,0.115558,278.826050,14.204075,1.155581,-1301.734985,0.115758,0.000000
114.670006,62.669540,-1301.734985,0.023265,0.004550,0.115558,278.768036,14.201121,1.155581,-1301.734985,0.115758,0.000000
114.990005,62.636398,-1301.823975,0.023295,0.004550,0.115558,278.620605,14.193610,1.155581,-1301.823975,0.115758,0.000000
115.310005,62.618904,-1301.823975,0.023291,0.004550,0.115558,278.542786,14.189647,1.155581,-1301.823975,0.115758,0.000000
115.630005,62.582039,-1301.779541,0.023287,0.004550,0.115558,278.378815,14.181293,1.155581,-1301.779541,0.115758,0.000000
115.950005,62.559319,-1301.868530,0.023274,0.004550,0.115558,278.277740,14.176145,1.155581,-1301.868530,0.115758,0.000000
116.270004,62.538094,-1301.779541,0.023265,0.004550,0.115558,278.183319,14.171334,1.155581,-1301.779541,0.115758,0.000000
116.590004,62.523201,-1301.823975,0.023308,0.004550,0.115558,278.117096,14.167960,1.155581,-1301.823975,0.115758,0.000000
116.910004,62.494904,-1301.912964,0.023252,0.004550,0.115558,277.991211,14.161547,1.155581,-1301.912964,0.115758,0.000000
117.230003,62.473679,-1301.868530,0.023256,0.004550,0.115558,277.896790,14.156738,1.155581,-1301.868530,0.115758,0.000000
117.550003,62.451706,-1301.779541,0.023282,0.004550,0.115558,277.799072,14.151759,1.155581,-1301.779541,0.115758,0.000000
117.870003,62.423775,-1301.868530,0.023239,0.004550,0.115558,277.674805,14.145430,1.155581,-1301.868530,0.115758,0.000000
118.190002,62.404045,-1301.868530,0.023291,0.004550,0.115558,277.587067,14.140959,1.155581,-1301.868530,0.115758,0.000000
118.510002,62.394363,-1301.912964,0.023252,0.004550,0.115558,277.543976,14.138765,1.155581,-1301.912964,0.115758,0.000000
118.830002,62.364197,-1301.823975,0.023304,0.004550,0.115558,277.409790,14.131928,1.155581,-1301.823975,0.115758,0.000000
119.150009,62.340363,-1301.823975,0.023295,0.004550,0.115558,277.303772,14.126528,1.155581,-1301.823975,0.115758,0.000000
119.470009,62.325096,-1301.868530,0.023256,0.004550,0.115558,277.235870,14.123069,1.155581,-1301.868530,0.115758,0.000000
119.790009,62.313927,-1301.868530,0.023265,0.004550,0.115558,277.186188,14.120538,1.155581,-1301.868530,0.115758,0.000000
120.110008,62.302010,-1301.912964,0.023274,0.004550,0.115558,277.133179,14.117838,1.155581,-1301.912964,0.115758,0.000000
120.430008,62.267754,-1301.823975,0.023256,0.004550,0.115558,276.980804,14.110074,1.155581,-1301.823975,0.115758,0.000000
120.750008,62.265518,-1301.779541,0.023274,0.004550,0.115558,276.970856,14.109568,1.155581,-1301.779541,0.115758,0.000000
121.070007,62.229774,-1301.823975,0.023265,0.004550,0.115558,276.811859,14.101468,1.155581,-1301.823975,0.115758,0.000000
121.390007,62.207428,-1301.868530,0.023287,0.004550,0.115558,276.712463,14.096405,1.155581,-1301.868530,0.115758,0.000000
121.710007,62.200729,-1301.868530,0.023295,0.004550,0.115558,276.682648,14.094887,1.155581,-1301.868530,0.115758,0.000000
122.030006,62.179131,-1301.912964,0.023274,0.004550,0.115558,276.586578,14.089992,1.155581,-1301.912964,0.115758,0.000000
122.350006,62.167213,-1301.868530,0.023282,0.004550,0.115558,276.533569,14.087292,1.155581,-1301.868530,0.115758,0.000000
122.670006,62.143379,-1301.868530,0.023282,0.004550,0.115558,276.427551,14.081891,1.155581,-1301.868530,0.115758,0.000000
122.990005,62.127365,-1301.868530,0.023287,0.004550,0.115558,276.356323,14.078262,1.155581,-1301.868530,0.115758,0.000000
123.310005,62.106888,-1301.957397,0.023265,0.004550,0.115558,276.265228,14.073622,1.155581,-1301.957397,0.115758,0.000000
123.630005,62.096092,-1301.868530,0.023274,0.004550,0.115558,276.217224,14.071176,1.155581,-1301.868530,0.115758,0.000000
123.950005,62.084549,-1301.868530,0.023304,0.004550,0.115558,276.165863,14.068560,1.155581,-1301.868530,0.115758,0.000000
124.270004,62.062576,-1301.823975,0.023287,0.004550,0.115558,276.068115,14.063581,1.155581,-1301.823975,0.115758,0.000000
124.590004,62.049545,-1301.912964,0.023304,0.004550,0.115558,276.010162,14.060628,1.155581,-1301.912964,0.115758,0.000000
124.910004,62.053642,-1301.957397,0.023252,0.004550,0.115558,276.028381,14.061557,1.155581,-1301.957397,0.115758,0.000000
125.230003,62.026825,-1301.823975,0.023256,0.004550,0.115558,275.909088,14.055480,1.155581,-1301.823975,0.115758,0.000000
125.550003,62.026825,-1301.912964,0.023291,0.004550,0.115558,275.909088,14.055480,1.155581,-1301.912964,0.115758,0.000000
125.870003,62.010445,-1301.912964,0.023278,0.004550,0.115558,275.836243,14.051767,1.155581,-1301.912964,0.115758,0.000000
126.190002,61.985123,-1301.912964,0.023243,0.004550,0.115558,275.723602,14.046030,1.155581,-1301.912964,0.115758,0.000000
126.510010,61.984009,-1301.868530,0.023269,0.004550,0.115558,275.718628,14.045777,1.155581,-1301.868530,0.115758,0.000000
126.830009,61.969482,-1301.957397,0.023291,0.004550,0.115558,275.654022,14.042485,1.155581,-1301.957397,0.115758,0.000000
127.150009,61.962036,-1301.868530,0.023308,0.004550,0.115558,275.620911,14.040798,1.155581,-1301.868530,0.115758,0.000000
127.470009,61.941185,-1301.912964,0.023243,0.004550,0.115558,275.528137,14.036074,1.155581,-1301.912964,0.115758,0.000000
127.790009,61.936714,-1301.957397,0.023291,0.004550,0.115558,275.508270,14.035061,1.155581,-1301.957397,0.115758,0.000000
128.110001,61.924797,-1301.957397,0.023261,0.004550,0.115558,275.455261,14.032360,1.155581,-1301.957397,0.115758,0.000000
128.430008,61.905434,-1301.912964,0.023252,0.004550,0.115558,275.369110,14.027972,1.155581,-1301.912964,0.115758,0.000000
128.750000,61.888306,-1301.868530,0.023317,0.004550,0.115558,275.292938,14.024090,1.155581,-1301.868530,0.115758,0.000000
129.070007,61.873413,-1301.868530,0.023243,0.004550,0.115558,275.226685,14.020716,1.155581,-1301.868530,0.115758,0.000000
129.389999,61.858887,-1301.912964,0.023308,0.004550,0.115558,275.162079,14.017424,1.155581,-1301.912964,0.115758,0.000000
129.710007,61.845856,-1301.912964,0.023265,0.004550,0.115558,275.104095,14.014471,1.155581,-1301.912964,0.115758,0.000000
130.029999,61.841011,-1301.912964,0.023308,0.004550,0.115558,275.082550,14.013373,1.155581,-1301.912964,0.115758,0.000000
130.100006,61.837662,-1301.912964,0.023274,0.004550,0.115558,275.067657,14.012614,1.155581,-1301.912964,0.115758,0.000000