File: Data/Automembrane/AutoNoheat12-2-2_12132023_183111.csv
Time (sec),S:Load (lbs),S:HL1 (DIM),S:LVDT (in),S:Position (in),Ch:Position (mm),Ch:Load (N),Ch:Stress (MPa),Ch:Strain (mm/mm),Ch:HL1 (DIM),Set Point (),Cycles ()
0.010000,-0.007446,-1304.403931,0.000065,-0.000000,-0.000000,-0.033123,-0.001687,-0.000000,-1304.403931,0.000165,0.000000
0.270000,0.002602,-1304.537354,0.000078,-0.000000,-0.000000,0.011573,0.000590,-0.000000,-1304.537354,0.000165,0.000000
0.530000,-0.000000,-1304.359375,0.000000,0.000078,0.001986,-0.000000,-0.000000,0.019859,-1304.359375,0.002627,0.000000
0.790000,0.015266,-1304.448364,0.000116,0.000228,0.005801,0.067908,0.003459,0.058015,-1304.448364,0.006964,0.000000
1.050000,0.001488,-1304.403931,0.000315,0.000399,0.010147,0.006618,0.000337,0.101465,-1304.403931,0.011300,0.000000
1.310000,-0.039474,-1304.359375,0.000483,0.000565,0.014361,-0.175591,-0.008945,0.143610,-1304.359375,0.015619,0.000000
1.570000,0.008560,-1304.448364,0.000569,0.000740,0.018793,0.038078,0.001940,0.187928,-1304.448364,0.019955,0.000000
1.830000,-0.014526,-1304.403931,0.000776,0.000914,0.023207,-0.064617,-0.003292,0.232067,-1304.403931,0.024291,0.000000
2.090000,-0.013779,-1304.448364,0.001022,0.001081,0.027456,-0.061291,-0.003122,0.274564,-1304.448364,0.028610,0.000000
2.350000,0.032394,-1304.448364,0.001138,0.001251,0.031766,0.144098,0.007341,0.317662,-1304.448364,0.032946,0.000000
2.610000,0.014893,-1304.448364,0.001350,0.001429,0.036302,0.066245,0.003375,0.363021,-1304.448364,0.037282,0.000000
2.870000,-0.000374,-1304.448364,0.001513,0.001594,0.040482,-0.001663,-0.000085,0.404821,-1304.448364,0.041618,0.000000
3.130000,0.011543,-1304.403931,0.001707,0.001757,0.044636,0.051347,0.002616,0.446360,-1304.403931,0.045937,0.000000
3.390000,-0.001488,-1304.492798,0.001845,0.001931,0.049042,-0.006618,-0.000337,0.490416,-1304.492798,0.050273,0.000000
3.650000,-0.008568,-1304.403931,0.002082,0.002109,0.053577,-0.038112,-0.001941,0.535771,-1304.403931,0.054609,0.000000
3.910000,0.014519,-1304.492798,0.002272,0.002277,0.057826,0.064583,0.003290,0.578264,-1304.492798,0.058945,0.000000
4.170000,-0.005585,-1304.537354,0.002384,0.002450,0.062232,-0.024842,-0.001266,0.622320,-1304.537354,0.063264,0.000000
4.430000,-0.000748,-1304.359375,0.002613,0.002618,0.066507,-0.003326,-0.000169,0.665074,-1304.359375,0.067600,0.000000
4.690000,0.026810,-1304.403931,0.002785,0.002784,0.070714,0.119255,0.006075,0.707136,-1304.403931,0.071936,0.000000
4.950000,0.003349,-1304.448364,0.002932,0.002963,0.075249,0.014898,0.000759,0.752490,-1304.448364,0.076272,0.000000
5.210000,0.002975,-1304.448364,0.003109,0.003129,0.079473,0.013236,0.000674,0.794726,-1304.448364,0.080591,0.000000
5.470000,0.015266,-1304.448364,0.003281,0.003294,0.083661,0.067908,0.003459,0.836609,-1304.448364,0.084927,0.000000
5.730000,-0.044312,-1304.448364,0.003436,0.003470,0.088145,-0.197107,-0.010041,0.881445,-1304.448364,0.089263,0.000000
5.990000,0.001488,-1304.448364,0.003613,0.003640,0.092446,0.006618,0.000337,0.924461,-1304.448364,0.093600,0.000000
6.250000,0.025688,-1304.403931,0.003833,0.003807,0.096695,0.114267,0.005821,0.966954,-1304.403931,0.097918,0.000000
6.510000,-0.005219,-1304.403931,0.004031,0.003985,0.101222,-0.023213,-0.001183,1.012225,-1304.403931,0.102255,0.000000
6.770000,0.011917,-1304.492798,0.004208,0.004158,0.105602,0.053010,0.002700,1.056020,-1304.492798,0.106591,0.000000
7.030000,0.025688,-1304.448364,0.004376,0.004323,0.109799,0.114267,0.005821,1.097994,-1304.448364,0.110909,0.000000
7.290000,-0.009682,-1304.492798,0.004566,0.004497,0.114213,-0.043066,-0.002194,1.142134,-1304.492798,0.115246,0.000000
7.550000,0.008934,-1304.359375,0.004678,0.004665,0.118480,0.039741,0.002024,1.184801,-1304.359375,0.119581,0.000000
7.810000,-0.008194,-1304.403931,0.004919,0.004839,0.122903,-0.036449,-0.001857,1.229031,-1304.403931,0.123918,0.000000
8.070001,-0.045807,-1304.448364,0.005079,0.005004,0.127101,-0.203759,-0.010380,1.271006,-1304.448364,0.128236,0.000000
8.330000,0.021225,-1304.359375,0.005290,0.005172,0.131367,0.094413,0.004810,1.313673,-1304.359375,0.132573,0.000000
8.590000,0.012283,-1304.448364,0.005411,0.005344,0.135738,0.054639,0.002783,1.357381,-1304.448364,0.136909,0.000000
8.850000,-0.014900,-1304.403931,0.005596,0.005518,0.140161,-0.066279,-0.003376,1.401607,-1304.403931,0.141245,0.000000
9.110001,0.006332,-1304.403931,0.005816,0.005690,0.144523,0.028168,0.001435,1.445232,-1304.403931,0.145564,0.000000
9.370001,0.017128,-1304.448364,0.005959,0.005864,0.148946,0.076189,0.003881,1.489458,-1304.448364,0.149900,0.000000
9.630000,-0.001488,-1304.314941,0.006127,0.006026,0.153048,-0.006618,-0.000337,1.530479,-1304.314941,0.154236,0.000000
9.890000,0.014145,-1304.492798,0.006338,0.006198,0.157436,0.062920,0.003205,1.574361,-1304.492798,0.158572,0.000000
10.150001,0.002975,-1304.403931,0.006497,0.006370,0.161798,0.013236,0.000674,1.617982,-1304.403931,0.162891,0.000000
10.410001,-0.014153,-1304.403931,0.006691,0.006540,0.166125,-0.062954,-0.003207,1.661255,-1304.403931,0.167227,0.000000
10.670000,0.057716,-1304.403931,0.006847,0.006710,0.170444,0.256735,0.013079,1.704444,-1304.403931,0.171563,0.000000
10.930000,0.194748,-1304.403931,0.007049,0.006887,0.174919,0.866282,0.044131,1.749193,-1304.403931,0.175882,0.000000
11.190001,0.471420,-1304.448364,0.007205,0.007053,0.179151,2.096982,0.106825,1.791512,-1304.448364,0.180218,0.000000
11.450001,0.626701,-1304.403931,0.007291,-0.000009,-0.000225,2.787707,0.142013,-0.002252,-1304.403931,-0.000069,0.000000
11.710001,0.595795,-1304.359375,0.007291,-0.000009,-0.000234,2.650227,0.135009,-0.002339,-1304.359375,-0.000069,0.000000
11.970000,0.605850,-1304.448364,0.007269,-0.000009,-0.000234,2.694956,0.137288,-0.002339,-1304.448364,0.000191,0.000000
12.230000,0.567497,-1304.359375,0.007286,-0.000008,-0.000191,2.524354,0.128597,-0.001908,-1304.359375,0.000625,0.000000
12.490001,0.659096,-1304.448364,0.007334,0.000010,0.000260,2.931804,0.149353,0.002604,-1304.448364,0.001058,0.000000
12.750001,0.756660,-1304.403931,0.007317,0.000027,0.000685,3.365794,0.171462,0.006851,-1304.403931,0.001492,0.000000
13.010000,0.803947,-1304.403931,0.007364,0.000046,0.001171,3.576137,0.182177,0.011710,-1304.403931,0.001925,0.000000
13.270000,0.843422,-1304.403931,0.007355,0.000056,0.001431,3.751728,0.191122,0.014311,-1304.403931,0.002359,0.000000
13.530001,0.973381,-1304.403931,0.007399,0.000079,0.001995,4.329815,0.220571,0.019946,-1304.403931,0.002792,0.000000
13.790001,1.014709,-1304.448364,0.007407,0.000094,0.002376,4.513653,0.229936,0.023762,-1304.448364,0.003226,0.000000
14.050000,1.073921,-1304.403931,0.007424,0.000103,0.002619,4.777040,0.243354,0.026191,-1304.403931,0.003660,0.000000
14.310000,1.220261,-1304.403931,0.007420,0.000129,0.003270,5.427990,0.276515,0.032698,-1304.403931,0.004093,0.000000
14.570001,1.284309,-1304.403931,0.007433,0.000145,0.003686,5.712893,0.291029,0.036857,-1304.403931,0.004527,0.000000
14.830001,1.400864,-1304.403931,0.007403,0.000162,0.004111,6.231353,0.317440,0.041108,-1304.403931,0.004960,0.000000
15.090001,1.481293,-1304.492798,0.007450,0.000177,0.004484,6.589119,0.335666,0.044836,-1304.492798,0.005394,0.000000
15.350000,1.614235,-1304.359375,0.007524,0.000196,0.004987,7.180476,0.365791,0.049866,-1304.359375,0.005828,0.000000
15.610001,1.715889,-1304.448364,0.007489,0.000210,0.005325,7.632655,0.388826,0.053250,-1304.448364,0.006261,0.000000
15.870001,1.731903,-1304.448364,0.007480,0.000217,0.005507,7.703890,0.392455,0.055070,-1304.448364,0.006695,0.000000
16.130001,1.984741,-1304.359375,0.007537,0.000243,0.006175,8.828569,0.449749,0.061747,-1304.359375,0.007129,0.000000
16.390001,2.147842,-1304.448364,0.007562,0.000263,0.006669,9.554080,0.486708,0.066690,-1304.448364,0.007562,0.000000
16.650002,2.196625,-1304.448364,0.007580,0.000277,0.007025,9.771075,0.497762,0.070248,-1304.448364,0.007996,0.000000
16.910002,2.331795,-1304.403931,0.007558,0.000294,0.007458,10.372341,0.528392,0.074581,-1304.403931,0.008430,0.000000
17.170000,2.427864,-1304.492798,0.007631,0.000307,0.007797,10.799679,0.550162,0.077965,-1304.492798,0.008863,0.000000
17.430000,2.690018,-1304.359375,0.007623,0.000328,0.008343,11.965796,0.609567,0.083427,-1304.359375,0.009297,0.000000
17.690001,2.795769,-1304.448364,0.007653,0.000343,0.008725,12.436200,0.633530,0.087246,-1304.448364,0.009731,0.000000
17.950001,2.942482,-1304.448364,0.007692,0.000358,0.009097,13.088814,0.666776,0.090974,-1304.448364,0.010164,0.000000
18.210001,3.101112,-1304.403931,0.007722,0.000377,0.009583,13.794436,0.702722,0.095830,-1304.403931,0.010598,0.000000
18.470001,3.298843,-1304.492798,0.007709,0.000396,0.010069,14.673988,0.747529,0.100686,-1304.492798,0.011031,0.000000
18.730001,3.325653,-1304.448364,0.007709,0.000407,0.010346,14.793243,0.753604,0.103460,-1304.448364,0.011465,0.000000
18.990002,3.479446,-1304.492798,0.007687,0.000428,0.010884,15.477350,0.788454,0.108838,-1304.492798,0.011899,0.000000
19.250000,3.671593,-1304.448364,0.007718,0.000446,0.011326,16.332060,0.831995,0.113263,-1304.448364,0.012332,0.000000
19.510000,3.784416,-1304.403931,0.007765,0.000462,0.011725,16.833923,0.857561,0.117248,-1304.403931,0.012766,0.000000
19.770000,4.010818,-1304.492798,0.007782,0.000481,0.012211,17.841011,0.908864,0.122108,-1304.492798,0.013199,0.000000
20.030001,4.199989,-1304.448364,0.007791,0.000502,0.012740,18.682486,0.951731,0.127396,-1304.448364,0.013633,0.000000
20.290001,4.331062,-1304.492798,0.007825,0.000521,0.013243,19.265528,0.981433,0.132426,-1304.492798,0.014067,0.000000
20.550001,4.363831,-1304.448364,0.007847,0.000533,0.013537,19.411287,0.988858,0.135374,-1304.448364,0.014500,0.000000
20.810001,4.534752,-1304.492798,0.007873,0.000551,0.013997,20.171583,1.027589,0.139973,-1304.492798,0.014925,0.000000
21.070002,4.745514,-1304.448364,0.007886,0.000570,0.014483,21.109100,1.075349,0.144829,-1304.448364,0.015359,0.000000
21.330002,4.900047,-1304.403931,0.007869,0.000588,0.014942,21.796499,1.110367,0.149424,-1304.403931,0.015792,0.000000
21.590000,4.937660,-1304.537354,0.007894,0.000600,0.015237,21.963810,1.118890,0.152372,-1304.537354,0.016226,0.000000
21.850000,5.148796,-1304.403931,0.007877,0.000619,0.015732,22.902988,1.166734,0.157315,-1304.403931,0.016660,0.000000
22.110001,5.212471,-1304.403931,0.007946,0.000635,0.016122,23.186230,1.181163,0.161218,-1304.403931,0.017093,0.000000
22.370001,5.488022,-1304.448364,0.007916,0.000656,0.016651,24.411940,1.243604,0.166509,-1304.448364,0.017527,0.000000
22.630001,5.364395,-1304.448364,0.007972,0.000665,0.016894,23.862020,1.215589,0.168939,-1304.448364,0.017960,0.000000
22.890001,5.687241,-1304.537354,0.007937,0.000687,0.017457,25.298109,1.288747,0.174574,-1304.537354,0.018394,0.000000
23.150002,5.577393,-1304.448364,0.008019,0.000694,0.017631,24.809481,1.263855,0.176308,-1304.448364,0.018828,0.000000
23.410002,5.914764,-1304.448364,0.008019,0.000715,0.018160,26.310186,1.340305,0.181599,-1304.448364,0.019261,0.000000
23.670002,6.109138,-1304.448364,0.008037,0.000736,0.018689,27.174805,1.384351,0.186887,-1304.448364,0.019695,0.000000
23.930000,6.169464,-1304.403931,0.008011,0.000755,0.019166,27.443148,1.398021,0.191660,-1304.403931,0.020128,0.000000
24.190001,6.497528,-1304.448364,0.008041,0.000774,0.019669,28.902449,1.472361,0.196690,-1304.448364,0.020562,0.000000
24.450001,6.367569,-1304.448364,0.008054,0.000783,0.019885,28.324362,1.442912,0.198855,-1304.448364,0.020996,0.000000
24.710001,6.749619,-1304.492798,0.008075,0.000808,0.020519,30.023802,1.529485,0.205187,-1304.492798,0.021429,0.000000
24.970001,6.744034,-1304.448364,0.008088,0.000822,0.020874,29.998960,1.528220,0.208745,-1304.448364,0.021863,0.000000
25.230001,6.902298,-1304.448364,0.008114,0.000838,0.021273,30.702955,1.564083,0.212730,-1304.448364,0.022296,0.000000
25.490002,7.073212,-1304.448364,0.008110,0.000854,0.021689,31.463217,1.602813,0.216893,-1304.448364,0.022730,0.000000
25.750002,7.242271,-1304.448364,0.008127,0.000869,0.022080,32.215233,1.641122,0.220796,-1304.448364,0.023164,0.000000
26.010002,7.493622,-1304.448364,0.008144,0.000893,0.022678,33.333294,1.698079,0.226780,-1304.448364,0.023597,0.000000
26.270000,7.696564,-1304.448364,0.008170,0.000913,0.023181,34.236027,1.744066,0.231810,-1304.448364,0.024031,0.000000
26.530001,7.755028,-1304.448364,0.008192,0.000929,0.023597,34.496086,1.757314,0.235973,-1304.448364,0.024464,0.000000
26.790001,7.835091,-1304.537354,0.008201,0.000942,0.023936,34.852222,1.775457,0.239357,-1304.537354,0.024898,0.000000
27.050001,8.140434,-1304.359375,0.008261,0.000964,0.024473,36.210461,1.844649,0.244731,-1304.359375,0.025332,0.000000
27.310001,8.189957,-1304.403931,0.008235,0.000976,0.024803,36.430748,1.855871,0.248028,-1304.403931,0.025765,0.000000
27.570002,8.357155,-1304.448364,0.008274,0.000993,0.025210,37.174480,1.893758,0.252104,-1304.448364,0.026199,0.000000
27.830002,8.337044,-1304.403931,0.008295,0.001007,0.025575,37.085022,1.889201,0.255745,-1304.403931,0.026633,0.000000
28.090002,8.925766,-1304.448364,0.008338,0.001033,0.026251,39.703789,2.022608,0.262509,-1304.448364,0.027066,0.000000
28.350002,8.895973,-1304.403931,0.008308,0.001050,0.026659,39.571266,2.015856,0.266585,-1304.403931,0.027500,0.000000
28.610001,9.057213,-1304.448364,0.008330,0.001068,0.027118,40.288494,2.052394,0.271184,-1304.448364,0.027934,0.000000
28.870001,9.053116,-1304.492798,0.008390,0.001080,0.027422,40.270271,2.051465,0.274219,-1304.492798,0.028367,0.000000
29.130001,9.362930,-1304.359375,0.008407,0.001097,0.027864,41.648396,2.121670,0.278640,-1304.359375,0.028801,0.000000
29.390001,9.443733,-1304.448364,0.008399,0.001112,0.028254,42.007824,2.139981,0.282542,-1304.448364,0.029234,0.000000
29.650002,9.667908,-1304.403931,0.008360,0.001132,0.028749,43.005001,2.190779,0.287485,-1304.403931,0.029668,0.000000
29.910002,10.089432,-1304.359375,0.008438,0.001156,0.029356,44.880035,2.286298,0.293556,-1304.359375,0.030093,0.000000
30.170002,10.042137,-1304.448364,0.008420,0.001172,0.029772,44.669659,2.275581,0.297720,-1304.448364,0.030526,0.000000
30.430002,10.018677,-1304.403931,0.008455,0.001186,0.030136,44.565300,2.270265,0.301361,-1304.403931,0.030960,0.000000
30.690001,10.122200,-1304.492798,0.008459,0.001201,0.030501,45.025795,2.293723,0.305006,-1304.492798,0.031394,0.000000
30.950001,10.466270,-1304.448364,0.008459,0.001222,0.031047,46.556297,2.371691,0.310467,-1304.448364,0.031827,0.000000
31.210001,10.472229,-1304.492798,0.008524,0.001237,0.031420,46.582802,2.373041,0.314195,-1304.492798,0.032261,0.000000
31.470001,10.457336,-1304.403931,0.008545,0.001248,0.031697,46.516556,2.369666,0.316974,-1304.403931,0.032695,0.000000
31.730001,10.916840,-1304.359375,0.008550,0.001274,0.032365,48.560528,2.473791,0.323650,-1304.359375,0.033128,0.000000
31.990002,10.935463,-1304.537354,0.008541,0.001289,0.032738,48.643368,2.478011,0.327378,-1304.537354,0.033562,0.000000
32.250000,11.082550,-1304.403931,0.008584,0.001308,0.033232,49.297646,2.511342,0.332321,-1304.403931,0.033996,0.000000
32.510002,11.127602,-1304.448364,0.008614,0.001322,0.033571,49.498043,2.521550,0.335705,-1304.448364,0.034429,0.000000
32.770000,11.332779,-1304.403931,0.008645,0.001340,0.034039,50.410717,2.568044,0.340387,-1304.403931,0.034863,0.000000
33.030003,11.464600,-1304.403931,0.008606,0.001356,0.034446,50.997086,2.597915,0.344463,-1304.403931,0.035296,0.000000
33.290001,11.432953,-1304.448364,0.008662,0.001367,0.034715,50.856316,2.590744,0.347151,-1304.448364,0.035730,0.000000
33.550003,11.643715,-1304.359375,0.008666,0.001383,0.035123,51.793831,2.638504,0.351227,-1304.359375,0.036164,0.000000
33.810001,12.057793,-1304.359375,0.008701,0.001407,0.035747,53.635742,2.732335,0.357472,-1304.359375,0.036597,0.000000
34.070004,12.152000,-1304.403931,0.008714,0.001426,0.036215,54.054798,2.753683,0.362154,-1304.403931,0.037031,0.000000
34.330002,12.264084,-1304.403931,0.008752,0.001445,0.036701,54.553371,2.779081,0.367010,-1304.403931,0.037464,0.000000
34.590000,12.090187,-1304.448364,0.008739,0.001456,0.036987,53.779839,2.739676,0.369871,-1304.448364,0.037898,0.000000
34.850002,12.539642,-1304.403931,0.008744,0.001477,0.037508,55.779114,2.841524,0.375076,-1304.403931,0.038332,0.000000
35.110001,12.410797,-1304.448364,0.008757,0.001489,0.037811,55.205982,2.812327,0.378111,-1304.448364,0.038765,0.000000
35.370003,12.454369,-1304.492798,0.008783,0.001502,0.038141,55.399799,2.822200,0.381408,-1304.492798,0.039199,0.000000
35.630001,13.028191,-1304.359375,0.008830,0.001527,0.038791,57.952286,2.952230,0.387910,-1304.359375,0.039632,0.000000
35.890003,12.987976,-1304.448364,0.008821,0.001543,0.039199,57.773403,2.943117,0.391986,-1304.448364,0.040066,0.000000
36.150002,13.124268,-1304.403931,0.008882,0.001561,0.039641,58.379658,2.974001,0.396411,-1304.403931,0.040500,0.000000
36.410000,13.054260,-1304.448364,0.008873,0.001575,0.040005,58.068249,2.958138,0.400052,-1304.448364,0.040933,0.000000
36.670002,13.296677,-1304.448364,0.008864,0.001593,0.040465,59.146572,3.013070,0.404651,-1304.448364,0.041367,0.000000
36.930000,13.363327,-1304.403931,0.008908,0.001608,0.040847,59.443047,3.028173,0.408466,-1304.403931,0.041800,0.000000
37.190002,13.122032,-1304.448364,0.008886,0.001615,0.041029,58.369713,2.973495,0.410286,-1304.448364,0.042234,0.000000
37.450001,13.626221,-1304.403931,0.008864,0.001640,0.041662,60.612457,3.087746,0.416619,-1304.403931,0.042667,0.000000
37.710003,13.998222,-1304.403931,0.008951,0.001661,0.042191,62.267204,3.172043,0.421906,-1304.403931,0.043101,0.000000
37.970001,13.794533,-1304.448364,0.008990,0.001675,0.042538,61.361145,3.125886,0.425377,-1304.448364,0.043535,0.000000
38.230003,13.891724,-1304.359375,0.008977,0.001693,0.043006,61.793472,3.147910,0.430059,-1304.359375,0.043968,0.000000
38.490002,13.768097,-1304.448364,0.008968,0.001704,0.043283,61.243553,3.119895,0.432833,-1304.448364,0.044402,0.000000
38.750000,14.235054,-1304.403931,0.009046,0.001728,0.043890,63.320683,3.225709,0.438904,-1304.403931,0.044827,0.000000
39.010002,14.282341,-1304.492798,0.009002,0.001744,0.044298,63.531025,3.236425,0.442980,-1304.492798,0.045261,0.000000
39.270000,14.232445,-1304.448364,0.009037,0.001757,0.044636,63.309074,3.225118,0.446364,-1304.448364,0.045694,0.000000
39.530003,14.405602,-1304.448364,0.009041,0.001776,0.045113,64.079315,3.264356,0.451133,-1304.448364,0.046128,0.000000
39.790001,14.615990,-1304.448364,0.009084,0.001795,0.045590,65.015167,3.312031,0.455902,-1304.448364,0.046561,0.000000
40.050003,14.522522,-1304.448364,0.009076,0.001809,0.045946,64.599403,3.290851,0.459456,-1304.448364,0.046995,0.000000
40.310001,14.658440,-1304.448364,0.009115,0.001829,0.046457,65.203995,3.321650,0.464573,-1304.448364,0.047429,0.000000
40.570004,14.916870,-1304.492798,0.009097,0.001849,0.046969,66.353554,3.380211,0.469690,-1304.492798,0.047862,0.000000
40.830002,14.825638,-1304.492798,0.009132,0.001860,0.047246,65.947731,3.359538,0.472465,-1304.492798,0.048296,0.000000
41.090000,14.989105,-1304.448364,0.009136,0.001880,0.047758,66.674873,3.396580,0.477582,-1304.448364,0.048729,0.000000
41.350002,15.310463,-1304.403931,0.009166,0.001901,0.048287,68.104340,3.469400,0.482873,-1304.403931,0.049163,0.000000
41.610001,15.304878,-1304.448364,0.009218,0.001921,0.048790,68.079498,3.468135,0.487903,-1304.448364,0.049597,0.000000
41.870003,15.072517,-1304.537354,0.009188,0.001932,0.049076,67.045906,3.415481,0.490765,-1304.537354,0.050030,0.000000
42.130001,15.192421,-1304.492798,0.009218,0.001950,0.049536,67.579262,3.442652,0.495359,-1304.492798,0.050464,0.000000
42.390003,15.372650,-1304.492798,0.009222,0.001968,0.049987,68.380966,3.483492,0.499871,-1304.492798,0.050898,0.000000
42.650002,15.631821,-1304.448364,0.009287,0.001988,0.050490,69.533813,3.542221,0.504901,-1304.448364,0.051331,0.000000
42.910004,15.419945,-1304.537354,0.009313,0.001999,0.050776,68.591339,3.494210,0.507763,-1304.537354,0.051765,0.000000
43.170002,15.657890,-1304.537354,0.009287,0.002018,0.051262,69.649773,3.548129,0.512619,-1304.537354,0.052199,0.000000
43.430000,15.746887,-1304.448364,0.009330,0.002035,0.051687,70.045654,3.568296,0.516869,-1304.448364,0.052632,0.000000
43.690002,16.039566,-1304.537354,0.009313,0.002054,0.052173,71.347549,3.634618,0.521725,-1304.537354,0.053066,0.000000
43.950001,15.648209,-1304.448364,0.009386,0.002065,0.052459,69.606705,3.545935,0.524586,-1304.448364,0.053499,0.000000
44.210003,16.027283,-1304.403931,0.009382,0.002086,0.052979,71.292915,3.631834,0.529791,-1304.403931,0.053933,0.000000
44.470001,15.599426,-1304.448364,0.009356,0.002092,0.053144,69.389717,3.534881,0.531437,-1304.448364,0.054367,0.000000
44.730003,16.222404,-1304.448364,0.009373,0.002116,0.053742,72.160858,3.676049,0.537421,-1304.448364,0.054800,0.000000
44.990002,16.428696,-1304.537354,0.009447,0.002134,0.054210,73.078491,3.722795,0.542103,-1304.537354,0.055234,0.000000
45.250004,16.280121,-1304.448364,0.009438,0.002151,0.054635,72.417595,3.689128,0.546353,-1304.448364,0.055667,0.000000
45.510002,16.656219,-1304.492798,0.009477,0.002172,0.055164,74.090561,3.774353,0.551645,-1304.492798,0.056101,0.000000
45.770000,16.329651,-1304.448364,0.009485,0.002181,0.055407,72.637917,3.700352,0.554071,-1304.448364,0.056535,0.000000
46.030003,16.775749,-1304.448364,0.009464,0.002207,0.056049,74.622261,3.801439,0.560490,-1304.448364,0.056968,0.000000
46.290001,16.605949,-1304.537354,0.009503,0.002221,0.056404,73.866951,3.762962,0.564044,-1304.537354,0.057402,0.000000
46.550003,16.652496,-1304.492798,0.009559,0.002239,0.056881,74.074005,3.773510,0.568813,-1304.492798,0.057835,0.000000
46.810001,16.669998,-1304.492798,0.009528,0.002253,0.057220,74.151855,3.777476,0.572197,-1304.492798,0.058269,0.000000
47.070004,16.758995,-1304.492798,0.009520,0.002271,0.057688,74.547729,3.797642,0.576879,-1304.492798,0.058703,0.000000
47.330002,17.142166,-1304.448364,0.009563,0.002294,0.058261,76.252167,3.884470,0.582605,-1304.448364,0.059136,0.000000
47.590004,17.303398,-1304.492798,0.009606,0.002311,0.058694,76.969360,3.921006,0.586939,-1304.492798,0.059570,0.000000
47.850002,17.202858,-1304.492798,0.009602,0.002328,0.059119,76.522133,3.898223,0.591189,-1304.492798,0.059995,0.000000
48.110001,17.049820,-1304.537354,0.009666,0.002340,0.059449,75.841385,3.863544,0.594486,-1304.537354,0.060428,0.000000
48.370003,17.416229,-1304.537354,0.009641,0.002363,0.060012,77.471260,3.946574,0.600122,-1304.537354,0.060862,0.000000
48.630001,17.256859,-1304.448364,0.009632,0.002375,0.060324,76.762344,3.910460,0.603244,-1304.448364,0.061296,0.000000
48.890003,17.273613,-1304.537354,0.009662,0.002392,0.060749,76.836868,3.914257,0.607495,-1304.537354,0.061729,0.000000
49.150002,17.074394,-1304.537354,0.009710,0.002406,0.061122,75.950699,3.869113,0.611223,-1304.537354,0.062163,0.000000
49.410004,17.903297,-1304.537354,0.009692,0.002432,0.061764,79.637848,4.056945,0.617638,-1304.537354,0.062596,0.000000
49.670002,17.683968,-1304.537354,0.009705,0.002448,0.062171,78.662216,4.007244,0.621714,-1304.537354,0.063030,0.000000
49.930004,17.746529,-1304.581787,0.009753,0.002465,0.062623,78.940498,4.021421,0.626226,-1304.581787,0.063464,0.000000
50.190002,17.492943,-1304.537354,0.009791,0.002475,0.062874,77.812492,3.963958,0.628739,-1304.537354,0.063897,0.000000
50.450001,17.797165,-1304.537354,0.009791,0.002495,0.063386,79.165741,4.032895,0.633856,-1304.537354,0.064331,0.000000
50.710003,17.724556,-1304.537354,0.009766,0.002510,0.063758,78.842766,4.016442,0.637585,-1304.537354,0.064764,0.000000
50.970001,18.063416,-1304.492798,0.009804,0.002532,0.064305,80.350082,4.093228,0.643050,-1304.492798,0.065198,0.000000
51.230003,18.440628,-1304.537354,0.009852,0.002554,0.064860,82.028008,4.178706,0.648599,-1304.537354,0.065632,0.000000
51.490002,18.329285,-1304.581787,0.009886,0.002570,0.065285,81.532730,4.153475,0.652849,-1304.581787,0.066065,0.000000
51.750004,18.093575,-1304.492798,0.009886,0.002585,0.065658,80.484238,4.100062,0.656577,-1304.492798,0.066499,0.000000
52.010002,18.013885,-1304.581787,0.009860,0.002599,0.066022,80.129768,4.082005,0.660222,-1304.581787,0.066932,0.000000
52.270004,18.387009,-1304.626343,0.009912,0.002621,0.066568,81.789497,4.166555,0.665684,-1304.626343,0.067366,0.000000
52.530003,18.171402,-1304.581787,0.009886,0.002635,0.066932,80.830437,4.117699,0.669325,-1304.581787,0.067800,0.000000
52.790001,18.009422,-1304.581787,0.009968,0.002647,0.067227,80.109909,4.080994,0.672273,-1304.581787,0.068233,0.000000
53.050003,18.515472,-1304.581787,0.009955,0.002671,0.067852,82.360931,4.195666,0.678518,-1304.581787,0.068667,0.000000
53.310001,18.509514,-1304.581787,0.009951,0.002687,0.068251,82.334427,4.194315,0.682507,-1304.581787,0.069101,0.000000
53.570004,18.540421,-1304.581787,0.009981,0.002707,0.068754,82.471909,4.201319,0.687538,-1304.581787,0.069534,0.000000
53.830002,18.379555,-1304.537354,0.009968,0.002720,0.069092,81.756340,4.164866,0.690921,-1304.537354,0.069968,0.000000
54.090004,18.548615,-1304.626343,0.010042,0.002740,0.069604,82.508362,4.203176,0.696038,-1304.626343,0.070402,0.000000
54.350002,18.549362,-1304.581787,0.010042,0.002755,0.069977,82.511681,4.203345,0.699767,-1304.581787,0.070835,0.000000
54.610004,18.306946,-1304.626343,0.010085,0.002765,0.070237,81.433365,4.148413,0.702367,-1304.626343,0.071269,0.000000
54.870003,18.740387,-1304.581787,0.010067,0.002787,0.070792,83.361404,4.246632,0.707919,-1304.581787,0.071702,0.000000
55.130001,19.023766,-1304.581787,0.010050,0.002807,0.071286,84.621933,4.310847,0.712862,-1304.581787,0.072136,0.000000
55.390003,19.066582,-1304.626343,0.010085,0.002824,0.071737,84.812393,4.320549,0.717370,-1304.626343,0.072570,0.000000
55.650002,18.983917,-1304.581787,0.010145,0.002842,0.072196,84.444679,4.301817,0.721965,-1304.581787,0.073003,0.000000
55.910004,18.512123,-1304.626343,0.010111,0.002853,0.072466,82.346039,4.194907,0.724656,-1304.626343,0.073437,0.000000
56.170002,19.144035,-1304.670776,0.010119,0.002874,0.073012,85.156921,4.338100,0.730118,-1304.670776,0.073871,0.000000
56.430004,18.807411,-1304.581787,0.010132,0.002886,0.073298,83.659546,4.261820,0.732979,-1304.581787,0.074304,0.000000
56.690002,18.793266,-1304.581787,0.010214,0.002900,0.073654,83.596626,4.258615,0.736537,-1304.581787,0.074738,0.000000
56.950005,19.523857,-1304.626343,0.010223,0.002927,0.074339,86.846451,4.424169,0.743387,-1304.626343,0.075163,0.000000
57.210003,19.401352,-1304.626343,0.010218,0.002943,0.074764,86.301521,4.396409,0.747638,-1304.626343,0.075596,0.000000
57.470001,19.523117,-1304.581787,0.010223,0.002962,0.075232,86.843163,4.424002,0.752320,-1304.581787,0.076030,0.000000
57.730003,19.250534,-1304.581787,0.010257,0.002974,0.075536,85.630653,4.362234,0.755355,-1304.581787,0.076464,0.000000
57.990002,19.559235,-1304.626343,0.010231,0.002993,0.076012,87.003822,4.432186,0.760124,-1304.626343,0.076897,0.000000
58.250004,19.580833,-1304.626343,0.010274,0.003007,0.076377,87.099899,4.437080,0.763765,-1304.626343,0.077331,0.000000
58.510002,19.107544,-1304.626343,0.010309,0.003014,0.076559,84.994598,4.329831,0.765590,-1304.626343,0.077764,0.000000
58.770004,19.876122,-1304.581787,0.010322,0.003040,0.077227,88.413406,4.503994,0.772266,-1304.581787,0.078198,0.000000
59.030003,20.333771,-1304.626343,0.010348,0.003060,0.077712,90.449127,4.607698,0.777122,-1304.626343,0.078632,0.000000
59.290001,20.028427,-1304.670776,0.010369,0.003073,0.078059,89.090897,4.538506,0.780593,-1304.670776,0.079065,0.000000
59.550003,20.121147,-1304.670776,0.010326,0.003092,0.078536,89.503334,4.559517,0.785362,-1304.670776,0.079499,0.000000
59.810001,19.992302,-1304.581787,0.010378,0.003105,0.078857,88.930199,4.530320,0.788572,-1304.581787,0.079932,0.000000
60.070004,20.523308,-1304.670776,0.010374,0.003126,0.079403,91.292236,4.650648,0.794033,-1304.670776,0.080366,0.000000
60.330002,20.626823,-1304.581787,0.010412,0.003143,0.079820,91.752693,4.674105,0.798196,-1304.581787,0.080800,0.000000
60.590004,20.592194,-1304.626343,0.010386,0.003157,0.080184,91.598656,4.666258,0.801838,-1304.626343,0.081233,0.000000
60.850002,20.857697,-1304.670776,0.010408,0.003175,0.080644,92.779671,4.726422,0.806436,-1304.670776,0.081667,0.000000
61.110004,21.125061,-1304.670776,0.010473,0.003194,0.081121,93.968964,4.787007,0.811205,-1304.670776,0.082100,0.000000
61.370003,21.133995,-1304.715210,0.010417,0.003209,0.081519,94.008705,4.789032,0.815194,-1304.715210,0.082534,0.000000
61.630001,21.505997,-1304.581787,0.010438,0.003229,0.082014,95.663452,4.873329,0.820138,-1304.581787,0.082968,0.000000
61.890003,20.851738,-1304.670776,0.010507,0.003238,0.082239,92.753166,4.725071,0.822393,-1304.670776,0.083401,0.000000
62.150002,21.628510,-1304.670776,0.010520,0.003259,0.082768,96.208412,4.901090,0.827681,-1304.670776,0.083835,0.000000
62.410004,22.038116,-1304.626343,0.010481,0.003278,0.083254,98.030441,4.993908,0.832537,-1304.626343,0.084268,0.000000
62.670002,22.509544,-1304.759766,0.010559,0.003299,0.083800,100.127457,5.100736,0.838002,-1304.759766,0.084702,0.000000
62.930004,22.870369,-1304.626343,0.010546,0.003321,0.084346,101.732483,5.182500,0.843464,-1304.626343,0.085136,0.000000
63.190002,22.434692,-1304.715210,0.010555,0.003331,0.084607,99.794495,5.083774,0.846068,-1304.715210,0.085569,0.000000
63.450005,22.732224,-1304.626343,0.010563,0.003350,0.085092,101.117981,5.151196,0.850924,-1304.626343,0.086003,0.000000
63.710003,23.081131,-1304.670776,0.010555,0.003367,0.085534,102.669998,5.230259,0.855345,-1304.670776,0.086436,0.000000
63.970001,23.573410,-1304.670776,0.010589,0.003387,0.086020,104.859764,5.341811,0.860204,-1304.670776,0.086870,0.000000
64.230003,23.375679,-1304.670776,0.010654,0.003397,0.086289,103.980217,5.297005,0.862892,-1304.670776,0.087304,0.000000
64.490005,23.881737,-1304.670776,0.010637,0.003416,0.086775,106.231270,5.411679,0.867748,-1304.670776,0.087737,0.000000
64.750000,23.989723,-1304.670776,0.010624,0.003431,0.087156,106.711617,5.436149,0.871563,-1304.670776,0.088171,0.000000
65.010002,24.872620,-1304.759766,0.010688,0.003452,0.087677,110.638939,5.636216,0.876767,-1304.759766,0.088605,0.000000
65.270004,24.575836,-1304.715210,0.010675,0.003463,0.087963,109.318779,5.568964,0.879629,-1304.715210,0.089038,0.000000
65.530006,25.322815,-1304.626343,0.010645,0.003484,0.088501,112.641510,5.738232,0.885007,-1304.626343,0.089472,0.000000
65.790001,25.038322,-1304.715210,0.010718,0.003491,0.088665,111.376022,5.673765,0.886653,-1304.715210,0.089897,0.000000
66.050003,26.322266,-1304.670776,0.010727,0.003517,0.089333,117.087288,5.964711,0.893330,-1304.670776,0.090330,0.000000
66.310005,26.687187,-1304.670776,0.010740,0.003533,0.089732,118.710541,6.047403,0.897319,-1304.670776,0.090764,0.000000
66.570000,26.857361,-1304.670776,0.010731,0.003551,0.090192,119.467506,6.085965,0.901918,-1304.670776,0.091197,0.000000
66.830002,27.336975,-1304.626343,0.010774,0.003570,0.090677,121.600937,6.194647,0.906774,-1304.626343,0.091631,0.000000
67.090004,27.633385,-1304.715210,0.010792,0.003580,0.090929,122.919434,6.261815,0.909287,-1304.715210,0.092065,0.000000
67.350006,28.552032,-1304.715210,0.010809,0.003605,0.091562,127.005783,6.469983,0.915619,-1304.715210,0.092498,0.000000
67.610001,28.912483,-1304.715210,0.010809,0.003618,0.091909,128.609146,6.551662,0.919086,-1304.715210,0.092932,0.000000
67.870003,29.271454,-1304.759766,0.010818,0.003635,0.092325,130.205933,6.633007,0.923249,-1304.759766,0.093366,0.000000
68.130005,29.647179,-1304.715210,0.010843,0.003651,0.092733,131.877243,6.718147,0.927326,-1304.715210,0.093799,0.000000
68.390007,30.187119,-1304.670776,0.010805,0.003666,0.093123,134.279007,6.840499,0.931228,-1304.670776,0.094233,0.000000
68.650002,30.944153,-1304.670776,0.010826,0.003688,0.093669,137.646469,7.012045,0.936693,-1304.670776,0.094667,0.000000
68.910004,32.118240,-1304.715210,0.010891,0.003710,0.094224,142.869064,7.278098,0.942242,-1304.715210,0.095100,0.000000
69.170006,32.441460,-1304.715210,0.010900,0.003726,0.094632,144.306824,7.351340,0.946318,-1304.715210,0.095534,0.000000
69.430000,32.755371,-1304.715210,0.010878,0.003739,0.094970,145.703171,7.422473,0.949702,-1304.715210,0.095968,0.000000
69.690002,33.715721,-1304.715210,0.010861,0.003759,0.095482,149.975021,7.640091,0.954815,-1304.715210,0.096401,0.000000
69.950005,34.171127,-1304.670776,0.010904,0.003773,0.095846,152.000763,7.743288,0.958460,-1304.670776,0.096835,0.000000
70.210007,34.687981,-1304.670776,0.010964,0.003790,0.096254,154.299850,7.860409,0.962537,-1304.670776,0.097268,0.000000
70.470001,35.056259,-1304.715210,0.010900,0.003807,0.096696,155.938034,7.943862,0.966957,-1304.715210,0.097702,0.000000
70.730003,36.700653,-1304.715210,0.010921,0.003830,0.097285,163.252655,8.316486,0.972854,-1304.715210,0.098136,0.000000
70.990005,37.233147,-1304.715210,0.010973,0.003847,0.097710,165.621307,8.437152,0.977105,-1304.715210,0.098569,0.000000
71.250000,38.031517,-1304.804199,0.010938,0.003865,0.098170,169.172638,8.618065,0.981700,-1304.804199,0.099003,0.000000
71.510002,38.294785,-1304.626343,0.011025,0.003874,0.098396,170.343704,8.677722,0.983955,-1304.626343,0.099436,0.000000
71.770004,39.369820,-1304.759766,0.011007,0.003894,0.098899,175.125702,8.921329,0.988985,-1304.759766,0.099870,0.000000
72.030006,40.032272,-1304.626343,0.010994,0.003908,0.099263,178.072433,9.071443,0.992627,-1304.626343,0.100304,0.000000
72.290001,40.652641,-1304.715210,0.011007,0.003926,0.099723,180.831985,9.212021,0.997225,-1304.715210,0.100737,0.000000
72.550003,42.503334,-1304.804199,0.010994,0.003952,0.100381,189.064270,9.631393,1.003815,-1304.804199,0.101171,0.000000
72.810005,43.517677,-1304.670776,0.011016,0.003968,0.100798,193.576294,9.861247,1.007978,-1304.670776,0.101604,0.000000
73.070000,44.057617,-1304.759766,0.011033,0.003983,0.101179,195.978073,9.983599,1.011793,-1304.759766,0.102038,0.000000
73.330002,44.777412,-1304.626343,0.011046,0.003997,0.101535,199.179871,10.146707,1.015351,-1304.626343,0.102471,0.000000
73.590004,46.204346,-1304.759766,0.011055,0.004019,0.102081,205.527191,10.470054,1.020813,-1304.759766,0.102905,0.000000
73.850006,46.768860,-1304.715210,0.011076,0.004032,0.102420,208.038284,10.597976,1.024196,-1304.715210,0.103339,0.000000
74.110001,47.359818,-1304.715210,0.011094,0.004045,0.102740,210.666992,10.731888,1.027402,-1304.715210,0.103772,0.000000
74.370003,49.052994,-1304.759766,0.011119,0.004068,0.103339,218.198608,11.115567,1.033386,-1304.759766,0.104206,0.000000
74.630005,50.223732,-1304.715210,0.011115,0.004086,0.103772,223.406311,11.380860,1.037724,-1304.715210,0.104639,0.000000
74.890007,51.232491,-1304.715210,0.011158,0.004103,0.104223,227.893494,11.609448,1.042231,-1304.715210,0.105065,0.000000
75.150002,52.208855,-1304.715210,0.011158,0.004118,0.104605,232.236588,11.830696,1.046050,-1304.715210,0.105498,0.000000
75.410004,53.271233,-1304.759766,0.011171,0.004136,0.105065,236.962280,12.071433,1.050645,-1304.759766,0.105932,0.000000
75.670006,54.390579,-1304.759766,0.011180,0.004151,0.105429,241.941376,12.325082,1.054286,-1304.759766,0.106365,0.000000
75.930000,54.778595,-1304.715210,0.011171,0.004164,0.105776,243.667358,12.413007,1.057757,-1304.715210,0.106799,0.000000
76.190002,56.406982,-1304.670776,0.011150,0.004183,0.106253,250.910782,12.782005,1.062526,-1304.670776,0.107233,0.000000
76.450005,58.170166,-1304.759766,0.011180,0.004204,0.106782,258.753815,13.181548,1.067817,-1304.759766,0.107666,0.000000
76.710007,59.544960,-1304.759766,0.011158,0.004222,0.107250,264.869202,13.493081,1.072499,-1304.759766,0.108100,0.000000
76.970001,60.780121,-1304.848755,0.011214,0.004240,0.107692,270.363495,13.772972,1.076924,-1304.848755,0.108533,0.000000
77.230003,61.390808,-1304.715210,0.011193,0.004249,0.107918,273.079956,13.911356,1.079176,-1304.715210,0.108967,0.000000
77.490005,63.318207,-1304.759766,0.011206,0.004273,0.108525,281.653442,14.348110,1.085247,-1304.759766,0.109400,0.000000
77.750000,64.201111,-1304.759766,0.011244,0.004285,0.108846,285.580811,14.548180,1.088456,-1304.759766,0.109834,0.000000
78.010002,65.038940,-1304.759766,0.011206,0.004297,0.109149,289.307648,14.738035,1.091492,-1304.759766,0.110268,0.000000
78.270004,67.315628,-1304.804199,0.011253,0.004323,0.109817,299.434875,15.253939,1.098168,-1304.804199,0.110701,0.000000
78.530006,67.170776,-1304.804199,0.011227,0.004319,0.109713,298.790527,15.221115,1.097128,-1304.804199,0.109895,0.000000
78.790001,66.774200,-1304.670776,0.011270,0.004319,0.109704,297.026489,15.131249,1.097040,-1304.670776,0.109713,0.000000
79.050003,66.440186,-1304.759766,0.011244,0.004319,0.109704,295.540710,15.055561,1.097040,-1304.759766,0.109713,0.000000
79.310005,66.143402,-1304.759766,0.011266,0.004319,0.109695,294.220551,14.988309,1.096953,-1304.759766,0.109713,0.000000
79.570007,65.904709,-1304.759766,0.011257,0.004319,0.109695,293.158783,14.934220,1.096953,-1304.759766,0.109713,0.000000
79.830002,65.686874,-1304.715210,0.011201,0.004319,0.109695,292.189819,14.884859,1.096953,-1304.715210,0.109713,0.000000
80.090004,65.511108,-1304.759766,0.011244,0.004319,0.109695,291.407959,14.845029,1.096953,-1304.759766,0.109713,0.000000
80.350006,65.340561,-1304.759766,0.011214,0.004319,0.109695,290.649323,14.806382,1.096953,-1304.759766,0.109713,0.000000
80.610001,65.185287,-1304.670776,0.011232,0.004319,0.109695,289.958649,14.771197,1.096953,-1304.670776,0.109713,0.000000
80.870003,65.057938,-1304.804199,0.011262,0.004319,0.109695,289.392151,14.742340,1.096953,-1304.804199,0.109713,0.000000
81.130005,64.922012,-1304.759766,0.011249,0.004318,0.109687,288.787537,14.711538,1.096870,-1304.759766,0.109713,0.000000
81.390007,64.822220,-1304.759766,0.011249,0.004318,0.109687,288.343628,14.688925,1.096870,-1304.759766,0.109713,0.000000
81.650002,64.707535,-1304.804199,0.011270,0.004318,0.109687,287.833496,14.662937,1.096870,-1304.804199,0.109713,0.000000
81.910004,64.618912,-1304.670776,0.011249,0.004318,0.109687,287.439270,14.642855,1.096870,-1304.670776,0.109713,0.000000
82.170006,64.531769,-1304.804199,0.011262,0.004318,0.109687,287.051636,14.623108,1.096870,-1304.804199,0.109713,0.000000
82.430000,64.440170,-1304.715210,0.011270,0.004318,0.109687,286.644196,14.602351,1.096870,-1304.715210,0.109713,0.000000
82.690002,64.374634,-1304.804199,0.011253,0.004318,0.109687,286.352661,14.587501,1.096870,-1304.804199,0.109713,0.000000
82.950005,64.284149,-1304.804199,0.011214,0.004318,0.109687,285.950165,14.566997,1.096870,-1304.804199,0.109713,0.000000
83.210007,64.218979,-1304.715210,0.011288,0.004318,0.109687,285.660278,14.552229,1.096870,-1304.715210,0.109713,0.000000
83.470001,64.139664,-1304.804199,0.011232,0.004318,0.109687,285.307465,14.534255,1.096870,-1304.804199,0.109713,0.000000
83.730003,64.081573,-1304.759766,0.011262,0.004318,0.109687,285.049072,14.521092,1.096870,-1304.759766,0.109713,0.000000
83.990005,64.033539,-1304.759766,0.011288,0.004318,0.109687,284.835419,14.510207,1.096870,-1304.759766,0.109713,0.000000
84.250008,63.974701,-1304.759766,0.011249,0.004318,0.109687,284.573669,14.496875,1.096870,-1304.759766,0.109713,0.000000
84.510002,63.906937,-1304.759766,0.011253,0.004318,0.109687,284.272247,14.481519,1.096870,-1304.759766,0.109713,0.000000
84.770004,63.869690,-1304.759766,0.011232,0.004318,0.109687,284.106567,14.473079,1.096870,-1304.759766,0.109713,0.000000
85.030006,63.814957,-1304.715210,0.011253,0.004318,0.109687,283.863098,14.460675,1.096870,-1304.715210,0.109713,0.000000
85.290001,63.768784,-1304.715210,0.011292,0.004318,0.109687,283.657715,14.450212,1.096870,-1304.715210,0.109713,0.000000
85.550003,63.722977,-1304.848755,0.011253,0.004318,0.109687,283.453949,14.439833,1.096870,-1304.848755,0.109713,0.000000
85.810005,63.682022,-1304.759766,0.011227,0.004318,0.109687,283.271790,14.430552,1.096870,-1304.759766,0.109713,0.000000
86.070007,63.631744,-1304.759766,0.011292,0.004318,0.109687,283.048126,14.419159,1.096870,-1304.759766,0.109713,0.000000
86.330002,63.599350,-1304.759766,0.011249,0.004318,0.109687,282.904053,14.411819,1.096870,-1304.759766,0.109713,0.000000
86.590004,63.561371,-1304.804199,0.011283,0.004318,0.109687,282.735107,14.403213,1.096870,-1304.804199,0.109713,0.000000
86.850006,63.518921,-1304.848755,0.011270,0.004318,0.109687,282.546265,14.393594,1.096870,-1304.848755,0.109713,0.000000
87.110001,63.489868,-1304.804199,0.011279,0.004318,0.109687,282.417053,14.387010,1.096870,-1304.804199,0.109713,0.000000
87.370003,63.444824,-1304.759766,0.011270,0.004318,0.109687,282.216675,14.376802,1.096870,-1304.759766,0.109713,0.000000
87.630005,63.408691,-1304.804199,0.011227,0.004318,0.109687,282.055939,14.368615,1.096870,-1304.804199,0.109713,0.000000
87.890007,63.388214,-1304.759766,0.011232,0.004318,0.109687,281.964844,14.363976,1.096870,-1304.759766,0.109713,0.000000
88.150002,63.348373,-1304.804199,0.011262,0.004318,0.109687,281.787628,14.354946,1.096870,-1304.804199,0.109713,0.000000
88.410004,63.320068,-1304.715210,0.011292,0.004318,0.109687,281.661743,14.348533,1.096870,-1304.715210,0.109713,0.000000
88.670006,63.288788,-1304.715210,0.011279,0.004318,0.109687,281.522583,14.341444,1.096870,-1304.715210,0.109713,0.000000
88.930008,63.266083,-1304.804199,0.011236,0.004318,0.109687,281.421600,14.336299,1.096870,-1304.804199,0.109713,0.000000
89.190002,63.247086,-1304.759766,0.011232,0.004318,0.109687,281.337097,14.331995,1.096870,-1304.759766,0.109713,0.000000
89.450005,63.202408,-1304.804199,0.011227,0.004318,0.109687,281.138336,14.321870,1.096870,-1304.804199,0.109713,0.000000
89.710007,63.189743,-1304.759766,0.011257,0.004318,0.109687,281.082001,14.319000,1.096870,-1304.759766,0.109713,0.000000
89.970001,63.166656,-1304.804199,0.011283,0.004318,0.109687,280.979309,14.313768,1.096870,-1304.804199,0.109713,0.000000
90.230003,63.134262,-1304.759766,0.011223,0.004318,0.109687,280.835236,14.306429,1.096870,-1304.759766,0.109713,0.000000
90.490005,63.126068,-1304.715210,0.011240,0.004318,0.109687,280.798767,14.304571,1.096870,-1304.715210,0.109713,0.000000
90.750008,63.091438,-1304.804199,0.011219,0.004318,0.109687,280.644745,14.296724,1.096870,-1304.804199,0.109713,0.000000
91.010002,63.059044,-1304.715210,0.011257,0.004318,0.109687,280.500641,14.289384,1.096870,-1304.715210,0.109713,0.000000
91.270004,63.048241,-1304.804199,0.011266,0.004318,0.109687,280.452576,14.286936,1.096870,-1304.804199,0.109713,0.000000
91.530006,63.018082,-1304.804199,0.011266,0.004318,0.109687,280.318420,14.280102,1.096870,-1304.804199,0.109713,0.000000
91.790001,63.010262,-1304.759766,0.011305,0.004318,0.109687,280.283630,14.278329,1.096870,-1304.759766,0.109713,0.000000
92.050003,62.983818,-1304.804199,0.011279,0.004318,0.109687,280.166016,14.272338,1.096870,-1304.804199,0.109713,0.000000
92.310005,62.963715,-1304.804199,0.011257,0.004318,0.109687,280.076599,14.267782,1.096870,-1304.804199,0.109713,0.000000
92.570007,62.945839,-1304.848755,0.011266,0.004318,0.109687,279.997070,14.263731,1.096870,-1304.848755,0.109713,0.000000
92.830002,62.925362,-1304.759766,0.011288,0.004318,0.109687,279.905975,14.259091,1.096870,-1304.759766,0.109713,0.000000
93.090004,62.898918,-1304.804199,0.011283,0.004318,0.109687,279.788361,14.253098,1.096870,-1304.804199,0.109713,0.000000
93.350006,62.891846,-1304.804199,0.011257,0.004318,0.109687,279.756897,14.251496,1.096870,-1304.804199,0.109713,0.000000
93.610008,62.860939,-1304.804199,0.011257,0.004318,0.109687,279.619415,14.244493,1.096870,-1304.804199,0.109713,0.000000
93.870003,62.859451,-1304.804199,0.011279,0.004318,0.109687,279.612793,14.244155,1.096870,-1304.804199,0.109713,0.000000
94.130005,62.840454,-1304.804199,0.011232,0.004318,0.109687,279.528290,14.239850,1.096870,-1304.804199,0.109713,0.000000
94.390007,62.819229,-1304.759766,0.011249,0.004318,0.109687,279.433899,14.235041,1.096870,-1304.759766,0.109713,0.000000
94.650002,62.805084,-1304.804199,0.011223,0.004318,0.109687,279.370972,14.231836,1.096870,-1304.804199,0.109713,0.000000
94.910004,62.787956,-1304.715210,0.011223,0.004318,0.109687,279.294769,14.227954,1.096870,-1304.715210,0.109713,0.000000
95.170006,62.752579,-1304.759766,0.011236,0.004318,0.109687,279.137421,14.219938,1.096870,-1304.759766,0.109713,0.000000
95.430008,62.752205,-1304.848755,0.011283,0.004318,0.109687,279.135742,14.219852,1.096870,-1304.848755,0.109713,0.000000
95.690002,62.739914,-1304.670776,0.011253,0.004318,0.109687,279.081085,14.217068,1.096870,-1304.670776,0.109713,0.000000
95.950005,62.709381,-1304.848755,0.011232,0.004318,0.109687,278.945251,14.210149,1.096870,-1304.848755,0.109713,0.000000
96.210007,62.697098,-1304.804199,0.011240,0.004318,0.109687,278.890625,14.207365,1.096870,-1304.804199,0.109713,0.000000
96.470001,62.682571,-1304.759766,0.011266,0.004318,0.109687,278.825989,14.204073,1.096870,-1304.759766,0.109713,0.000000
96.730003,62.660599,-1304.848755,0.011279,0.004318,0.109687,278.728271,14.199095,1.096870,-1304.848755,0.109713,0.000000
96.990005,62.661346,-1304.759766,0.011279,0.004318,0.109687,278.731598,14.199265,1.096870,-1304.759766,0.109713,0.000000
97.250008,62.614799,-1304.804199,0.011249,0.004318,0.109687,278.524536,14.188716,1.096870,-1304.804199,0.109713,0.000000
97.510002,62.612190,-1304.715210,0.011240,0.004318,0.109687,278.512939,14.188126,1.096870,-1304.715210,0.109713,0.000000
97.770004,62.608101,-1304.804199,0.011288,0.004318,0.109687,278.494751,14.187199,1.096870,-1304.804199,0.109713,0.000000
98.030006,62.564903,-1304.848755,0.011244,0.004318,0.109687,278.302582,14.177410,1.096870,-1304.848755,0.109713,0.000000
98.290001,62.566765,-1304.804199,0.011288,0.004318,0.109687,278.310883,14.177832,1.096870,-1304.804199,0.109713,0.000000
98.550003,62.551498,-1304.804199,0.011270,0.004318,0.109687,278.242950,14.174373,1.096870,-1304.804199,0.109713,0.000000
98.810005,62.533997,-1304.804199,0.011249,0.004318,0.109687,278.165100,14.170406,1.096870,-1304.804199,0.109713,0.000000
99.070007,62.520966,-1304.759766,0.011283,0.004318,0.109687,278.107147,14.167454,1.096870,-1304.759766,0.109713,0.000000
99.330002,62.507927,-1304.893188,0.011240,0.004318,0.109687,278.049133,14.164498,1.096870,-1304.893188,0.109713,0.000000
99.590004,62.475906,-1304.804199,0.011236,0.004318,0.109687,277.906708,14.157242,1.096870,-1304.804199,0.109713,0.000000
99.850006,62.481491,-1304.848755,0.011240,0.004318,0.109687,277.931549,14.158507,1.096870,-1304.848755,0.109713,0.000000
100.110008,62.461014,-1304.848755,0.011253,0.004318,0.109687,277.840454,14.153868,1.096870,-1304.848755,0.109713,0.000000
100.370003,62.435692,-1304.848755,0.011288,0.004318,0.109687,277.727814,14.148130,1.096870,-1304.848755,0.109713,0.000000
100.630005,62.433830,-1304.759766,0.011214,0.004318,0.109687,277.719543,14.147708,1.096870,-1304.759766,0.109713,0.000000
100.890007,62.430473,-1304.759766,0.011288,0.004318,0.109687,277.704620,14.146948,1.096870,-1304.759766,0.109713,0.000000
101.150002,62.401802,-1304.759766,0.011240,0.004318,0.109687,277.577087,14.140450,1.096870,-1304.759766,0.109713,0.000000
101.410004,62.391380,-1304.759766,0.011283,0.004318,0.109687,277.530731,14.138088,1.096870,-1304.759766,0.109713,0.000000
101.670006,62.378342,-1304.804199,0.011249,0.004318,0.109687,277.472717,14.135135,1.096870,-1304.804199,0.109713,0.000000
101.930008,62.357864,-1304.848755,0.011283,0.004318,0.109687,277.381622,14.130493,1.096870,-1304.848755,0.109713,0.000000
102.190002,62.357117,-1304.804199,0.011236,0.004318,0.109687,277.378296,14.130325,1.096870,-1304.804199,0.109713,0.000000
102.450005,62.341103,-1304.804199,0.011275,0.004318,0.109687,277.307068,14.126696,1.096870,-1304.804199,0.109713,0.000000
102.710007,62.312431,-1304.759766,0.011266,0.004318,0.109687,277.179535,14.120199,1.096870,-1304.759766,0.109713,0.000000
102.970001,62.321747,-1304.759766,0.011262,0.004318,0.109687,277.220978,14.122310,1.096870,-1304.759766,0.109713,0.000000
103.230003,62.303871,-1304.759766,0.011253,0.004318,0.109687,277.141449,14.118258,1.096870,-1304.759766,0.109713,0.000000
103.490005,62.284882,-1304.848755,0.011266,0.004318,0.109687,277.056976,14.113955,1.096870,-1304.848755,0.109713,0.000000
103.750008,62.282646,-1304.804199,0.011257,0.004318,0.109687,277.047058,14.113449,1.096870,-1304.804199,0.109713,0.000000
104.010002,62.276688,-1304.848755,0.011283,0.004318,0.109687,277.020538,14.112099,1.096870,-1304.848755,0.109713,0.000000
104.270004,62.272591,-1304.848755,0.011288,0.004318,0.109687,277.002319,14.111171,1.096870,-1304.848755,0.109713,0.000000
104.530006,62.243546,-1304.848755,0.011249,0.004318,0.109687,276.873108,14.104589,1.096870,-1304.848755,0.109713,0.000000
104.790009,62.256950,-1304.804199,0.011288,0.004318,0.109687,276.932739,14.107627,1.096870,-1304.804199,0.109713,0.000000
105.050003,62.234978,-1304.804199,0.011257,0.004318,0.109687,276.835022,14.102648,1.096870,-1304.804199,0.109713,0.000000
105.310005,62.214874,-1304.804199,0.011266,0.004318,0.109687,276.745575,14.098092,1.096870,-1304.804199,0.109713,0.000000
105.570007,62.211891,-1304.759766,0.011305,0.004318,0.109687,276.732300,14.097416,1.096870,-1304.759766,0.109713,0.000000
105.830002,62.208168,-1304.848755,0.011244,0.004318,0.109687,276.715759,14.096572,1.096870,-1304.848755,0.109713,0.000000
106.090004,62.182106,-1304.759766,0.011266,0.004318,0.109687,276.599823,14.090667,1.096870,-1304.759766,0.109713,0.000000
106.350006,62.180984,-1304.804199,0.011236,0.004318,0.109687,276.594818,14.090412,1.096870,-1304.804199,0.109713,0.000000
106.610008,62.180611,-1304.804199,0.011266,0.004318,0.109687,276.593170,14.090328,1.096870,-1304.804199,0.109713,0.000000
106.870003,62.153801,-1304.759766,0.011257,0.004318,0.109687,276.473907,14.084252,1.096870,-1304.759766,0.109713,0.000000
107.130005,62.161995,-1304.804199,0.011283,0.004318,0.109687,276.510376,14.086109,1.096870,-1304.804199,0.109713,0.000000
107.390007,62.149704,-1304.759766,0.011283,0.004318,0.109687,276.455688,14.083324,1.096870,-1304.759766,0.109713,0.000000
107.650002,62.127739,-1304.759766,0.011257,0.004318,0.109687,276.357971,14.078347,1.096870,-1304.759766,0.109713,0.000000
107.910004,62.120293,-1304.804199,0.011279,0.004318,0.109687,276.324860,14.076659,1.096870,-1304.804199,0.109713,0.000000
108.170006,62.131836,-1304.804199,0.011279,0.004318,0.109687,276.376221,14.079275,1.096870,-1304.804199,0.109713,0.000000
108.430008,62.102791,-1304.804199,0.011292,0.004318,0.109687,276.247009,14.072693,1.096870,-1304.804199,0.109713,0.000000
108.690002,62.104279,-1304.848755,0.011292,0.004318,0.109687,276.253632,14.073030,1.096870,-1304.848755,0.109713,0.000000
108.800003,62.100929,-1304.804199,0.011288,0.004318,0.109687,276.238739,14.072272,1.096870,-1304.804199,0.109713,0.000000