File: Data/Automembrane/AutoNoheat10-1-3_12132023_184911.csv
Time (sec),S:Load (lbs),S:HL1 (DIM),S:LVDT (in),S:Position (in),Ch:Position (mm),Ch:Load (N),Ch:Stress (MPa),Ch:Strain (mm/mm),Ch:HL1 (DIM),Set Point (),Cycles ()
0.110000,0.017128,-1305.115601,0.000030,-0.000000,-0.000000,0.076189,0.003881,-0.000000,-1305.115601,0.000226,0.000000
0.350000,0.013031,-1305.115601,-0.000039,-0.000000,-0.000000,0.057965,0.002953,-0.000000,-1305.115601,0.000226,0.000000
0.590000,0.031281,-1305.115601,0.000026,0.000107,0.002723,0.139143,0.007088,0.027232,-1305.115601,0.003660,0.000000
0.830000,0.035004,-1305.115601,0.000125,0.000256,0.006496,0.155704,0.007932,0.064956,-1305.115601,0.007649,0.000000
1.070000,0.031647,-1305.160034,0.000237,0.000417,0.010580,0.140772,0.007171,0.105803,-1305.160034,0.011656,0.000000
1.310000,0.005585,-1305.115601,0.000392,0.000567,0.014413,0.024842,0.001266,0.144133,-1305.115601,0.015645,0.000000
1.550000,0.050636,-1305.160034,0.000638,0.000735,0.018663,0.225241,0.011474,0.186629,-1305.160034,0.019652,0.000000
1.790000,0.065910,-1305.115601,0.000798,0.000886,0.022496,0.293184,0.014935,0.224959,-1305.115601,0.023641,0.000000
2.030000,0.084152,-1305.160034,0.000936,0.001049,0.026650,0.374328,0.019069,0.266498,-1305.160034,0.027647,0.000000
2.270000,0.136658,-1305.160034,0.001108,0.001200,0.030483,0.607884,0.030967,0.304832,-1305.160034,0.031636,0.000000
2.510000,0.218956,-1305.115601,0.001233,0.001362,0.034585,0.973965,0.049616,0.345849,-1305.115601,0.035643,0.000000
2.750000,0.320610,-1305.115601,0.001380,0.001513,0.038427,1.426145,0.072651,0.384269,-1305.115601,0.039632,0.000000
2.990000,0.408493,-1305.160034,0.001617,0.001679,0.042659,1.817068,0.092566,0.426588,-1305.160034,0.043639,0.000000
3.230000,0.472168,-1305.071045,0.001746,0.001832,0.046544,2.100308,0.106995,0.465440,-1305.071045,0.047645,0.000000
3.470000,0.620369,-1305.160034,0.001884,0.001986,0.050455,2.759539,0.140578,0.504553,-1305.160034,0.051635,0.000000
3.710000,0.577545,-1305.160034,0.001932,0.000004,0.000113,2.569049,0.130874,0.001128,-1305.160034,0.000321,0.000000
3.950000,0.555946,-1305.115601,0.001966,0.000004,0.000113,2.472973,0.125979,0.001128,-1305.115601,0.000321,0.000000
4.190000,0.522438,-1305.160034,0.001923,0.000004,0.000113,2.323920,0.118386,0.001128,-1305.160034,0.000520,0.000000
4.430000,0.519455,-1305.071045,0.002001,0.000004,0.000113,2.310651,0.117710,0.001128,-1305.071045,0.000919,0.000000
4.670000,0.525414,-1305.160034,0.001966,0.000015,0.000382,2.337156,0.119060,0.003815,-1305.160034,0.001318,0.000000
4.910000,0.582016,-1305.160034,0.001979,0.000032,0.000824,2.588936,0.131887,0.008236,-1305.160034,0.001717,0.000000
5.150000,0.607338,-1305.026611,0.001953,0.000045,0.001153,2.701574,0.137625,0.011533,-1305.026611,0.002116,0.000000
5.390000,0.629311,-1305.160034,0.002044,0.000059,0.001500,2.799313,0.142604,0.015003,-1305.160034,0.002515,0.000000
5.630000,0.646065,-1305.115601,0.002035,0.000080,0.002038,2.873840,0.146400,0.020378,-1305.115601,0.002922,0.000000
5.870000,0.693352,-1305.204590,0.002022,0.000099,0.002523,3.084183,0.157116,0.025234,-1305.204590,0.003321,0.000000
6.110000,0.700058,-1305.160034,0.002087,0.000114,0.002888,3.114013,0.158635,0.028879,-1305.160034,0.003720,0.000000
6.350000,0.710487,-1305.115601,0.002044,0.000126,0.003200,3.160406,0.160999,0.032001,-1305.115601,0.004119,0.000000
6.590000,0.725380,-1305.160034,0.002061,0.000145,0.003677,3.226651,0.164373,0.036770,-1305.160034,0.004518,0.000000
6.830000,0.751076,-1305.115601,0.002121,0.000161,0.004102,3.340952,0.170196,0.041017,-1305.115601,0.004917,0.000000
7.070000,0.755165,-1305.115601,0.002087,0.000176,0.004475,3.359142,0.171123,0.044749,-1305.115601,0.005316,0.000000
7.310000,0.733200,-1305.204590,0.002121,0.000188,0.004770,3.261437,0.166146,0.047697,-1305.204590,0.005715,0.000000
7.550000,0.747353,-1305.160034,0.002151,0.000205,0.005203,3.324390,0.169353,0.052031,-1305.160034,0.006122,0.000000
7.790000,0.811028,-1305.204590,0.002160,0.000225,0.005706,3.607631,0.183781,0.057061,-1305.204590,0.006521,0.000000
8.030001,0.827408,-1305.071045,0.002160,0.000241,0.006114,3.680494,0.187493,0.061137,-1305.071045,0.006920,0.000000
8.270000,0.828156,-1305.160034,0.002199,0.000252,0.006391,3.683820,0.187663,0.063912,-1305.160034,0.007319,0.000000
8.510000,0.843422,-1305.204590,0.002212,0.000266,0.006747,3.751728,0.191122,0.067470,-1305.204590,0.007718,0.000000
8.750000,0.891457,-1305.160034,0.002264,0.000289,0.007337,3.965397,0.202007,0.073366,-1305.160034,0.008117,0.000000
8.990001,0.885872,-1305.204590,0.002246,0.000304,0.007727,3.940555,0.200741,0.077269,-1305.204590,0.008516,0.000000
9.230000,0.854591,-1305.115601,0.002276,0.000315,0.007996,3.801412,0.193653,0.079956,-1305.115601,0.008915,0.000000
9.470000,0.883636,-1305.249023,0.002289,0.000336,0.008525,3.930611,0.200235,0.085247,-1305.249023,0.009323,0.000000
9.710000,0.949547,-1305.204590,0.002345,0.000352,0.008932,4.223795,0.215170,0.089324,-1305.204590,0.009722,0.000000
9.950001,0.974869,-1305.160034,0.002324,0.000366,0.009296,4.336433,0.220908,0.092965,-1305.160034,0.010120,0.000000
10.190001,1.005028,-1305.204590,0.002328,0.000379,0.009626,4.470587,0.227743,0.096261,-1305.204590,0.010519,0.000000
10.430000,1.032211,-1305.160034,0.002380,0.000394,0.009999,4.591505,0.233902,0.099989,-1305.160034,0.010918,0.000000
10.670000,1.051949,-1305.204590,0.002384,0.000411,0.010450,4.679301,0.238375,0.104501,-1305.204590,0.011317,0.000000
10.910001,1.067589,-1305.204590,0.002380,0.000430,0.010918,4.748872,0.241919,0.109183,-1305.204590,0.011716,0.000000
11.150001,1.053070,-1305.160034,0.002389,0.000442,0.011239,4.684289,0.238629,0.112392,-1305.160034,0.012115,0.000000
11.390000,1.081367,-1305.204590,0.002384,0.000458,0.011638,4.810163,0.245041,0.116382,-1305.204590,0.012523,0.000000
11.630000,1.114510,-1305.071045,0.002423,0.000473,0.012002,4.957586,0.252551,0.120023,-1305.071045,0.012922,0.000000
11.870001,1.178185,-1305.160034,0.002440,0.000489,0.012419,5.240827,0.266980,0.124186,-1305.160034,0.013321,0.000000
12.110001,1.201271,-1305.160034,0.002445,0.000502,0.012757,5.343521,0.272212,0.127566,-1305.160034,0.013719,0.000000
12.350000,1.225105,-1305.115601,0.002445,0.000516,0.013095,5.449541,0.277613,0.130950,-1305.115601,0.014118,0.000000
12.590000,1.237022,-1305.204590,0.002509,0.000530,0.013459,5.502551,0.280313,0.134591,-1305.204590,0.014517,0.000000
12.830001,1.325272,-1305.160034,0.002483,0.000557,0.014136,5.895103,0.300311,0.141358,-1305.160034,0.014916,0.000000
13.070001,1.304794,-1305.204590,0.002561,0.000566,0.014378,5.804015,0.295671,0.143784,-1305.204590,0.015315,0.000000
13.310000,1.316704,-1305.204590,0.002591,0.000584,0.014838,5.856991,0.298369,0.148383,-1305.204590,0.015723,0.000000
13.550000,1.351707,-1305.160034,0.002548,0.000600,0.015229,6.012695,0.306301,0.152285,-1305.160034,0.016122,0.000000
13.790001,1.419853,-1305.204590,0.002574,0.000619,0.015732,6.315823,0.321743,0.157315,-1305.204590,0.016521,0.000000
14.030001,1.419106,-1305.071045,0.002604,0.000631,0.016026,6.312497,0.321574,0.160264,-1305.071045,0.016920,0.000000
14.270000,1.472359,-1305.160034,0.002621,0.000644,0.016347,6.549378,0.333641,0.163470,-1305.160034,0.017319,0.000000
14.510000,1.546463,-1305.204590,0.002591,0.000664,0.016867,6.879011,0.350434,0.168674,-1305.204590,0.017717,0.000000
14.750001,1.563591,-1305.160034,0.002613,0.000684,0.017362,6.955200,0.354315,0.173617,-1305.160034,0.018116,0.000000
14.990001,1.564331,-1305.204590,0.002686,0.000700,0.017778,6.958492,0.354482,0.177780,-1305.204590,0.018524,0.000000
15.230000,1.597847,-1305.160034,0.002656,0.000714,0.018125,7.107578,0.362077,0.181251,-1305.160034,0.018923,0.000000
15.470000,1.610512,-1305.204590,0.002703,0.000728,0.018481,7.163914,0.364947,0.184805,-1305.204590,0.019322,0.000000
15.710001,1.682007,-1305.204590,0.002677,0.000744,0.018888,7.481940,0.381148,0.188881,-1305.204590,0.019720,0.000000
15.950001,1.736740,-1305.249023,0.002682,0.000756,0.019200,7.725406,0.393551,0.192004,-1305.249023,0.020119,0.000000
16.190001,1.782547,-1305.160034,0.002703,0.000769,0.019538,7.929165,0.403931,0.195384,-1305.160034,0.020518,0.000000
16.430000,1.887924,-1305.160034,0.002742,0.000794,0.020163,8.397906,0.427810,0.201629,-1305.160034,0.020917,0.000000
16.670000,1.902077,-1305.115601,0.002734,0.000810,0.020571,8.460860,0.431017,0.205705,-1305.115601,0.021316,0.000000
16.910002,1.865585,-1305.204590,0.002811,0.000826,0.020969,8.298538,0.422748,0.209695,-1305.204590,0.021724,0.000000
17.150002,1.884575,-1305.160034,0.002768,0.000838,0.021273,8.383008,0.427051,0.212730,-1305.160034,0.022123,0.000000
17.390001,1.952721,-1305.204590,0.002824,0.000855,0.021706,8.686135,0.442493,0.217064,-1305.204590,0.022522,0.000000
17.630001,2.062195,-1305.160034,0.002811,0.000871,0.022123,9.173100,0.467300,0.221227,-1305.160034,0.022921,0.000000
17.870001,2.081184,-1305.204590,0.002828,0.000885,0.022487,9.257570,0.471603,0.224872,-1305.204590,0.023319,0.000000
18.110001,2.107628,-1305.249023,0.002867,0.000896,0.022765,9.375197,0.477595,0.227646,-1305.249023,0.023718,0.000000
18.350000,2.252853,-1305.160034,0.002906,0.000919,0.023346,10.021193,0.510504,0.233456,-1305.160034,0.024117,0.000000
18.590000,2.262901,-1305.249023,0.002876,0.000936,0.023771,10.065887,0.512781,0.237707,-1305.249023,0.024516,0.000000
18.830002,2.268494,-1305.160034,0.002936,0.000951,0.024143,10.090764,0.514048,0.241435,-1305.160034,0.024924,0.000000
19.070002,2.340355,-1305.204590,0.002915,0.000966,0.024534,10.410419,0.530332,0.245337,-1305.204590,0.025323,0.000000
19.310001,2.372009,-1305.204590,0.002906,0.000978,0.024829,10.551225,0.537505,0.248285,-1305.204590,0.025722,0.000000
19.550001,2.463615,-1305.160034,0.002940,0.000998,0.025340,10.958709,0.558263,0.253403,-1305.160034,0.026121,0.000000
19.790001,2.482231,-1305.204590,0.003001,0.001010,0.025661,11.041515,0.562482,0.256612,-1305.204590,0.026520,0.000000
20.030001,2.501968,-1305.249023,0.002940,0.001021,0.025930,11.129312,0.566954,0.259299,-1305.249023,0.026919,0.000000
20.270000,2.683311,-1305.160034,0.002992,0.001046,0.026563,11.935966,0.608047,0.265631,-1305.160034,0.027317,0.000000
20.510000,2.688156,-1305.249023,0.003001,0.001060,0.026919,11.957516,0.609145,0.269186,-1305.249023,0.027716,0.000000
20.750002,2.706032,-1305.204590,0.003022,0.001076,0.027326,12.037030,0.613196,0.273262,-1305.204590,0.028124,0.000000
20.990002,2.759277,-1305.204590,0.003044,0.001094,0.027777,12.273879,0.625261,0.277770,-1305.204590,0.028523,0.000000
21.230001,2.739166,-1305.204590,0.003018,0.001102,0.027985,12.184420,0.620704,0.279851,-1305.204590,0.028922,0.000000
21.470001,2.891472,-1305.204590,0.003074,0.001122,0.028506,12.861909,0.655217,0.285056,-1305.204590,0.029321,0.000000
21.710001,2.880295,-1305.293457,0.003053,0.001136,0.028844,12.812191,0.652684,0.288439,-1305.293457,0.029720,0.000000
21.950001,2.926476,-1305.204590,0.003074,0.001148,0.029165,13.017613,0.663149,0.291649,-1305.204590,0.030119,0.000000
22.190001,3.088455,-1305.293457,0.003130,0.001171,0.029737,13.738135,0.699854,0.297372,-1305.293457,0.030518,0.000000
22.430000,3.081383,-1305.249023,0.003130,0.001186,0.030136,13.706675,0.698251,0.301361,-1305.249023,0.030917,0.000000
22.670002,3.072815,-1305.249023,0.003165,0.001198,0.030440,13.668564,0.696310,0.304396,-1305.249023,0.031324,0.000000
22.910002,3.119362,-1305.293457,0.003203,0.001215,0.030856,13.875614,0.706858,0.308560,-1305.293457,0.031723,0.000000
23.150002,3.145798,-1305.204590,0.003178,0.001228,0.031185,13.993207,0.712848,0.311853,-1305.204590,0.032122,0.000000
23.390001,3.304428,-1305.204590,0.003156,0.001249,0.031732,14.698831,0.748794,0.317318,-1305.204590,0.032521,0.000000
23.630001,3.252670,-1305.249023,0.003182,0.001259,0.031974,14.468600,0.737066,0.319744,-1305.249023,0.032920,0.000000
23.870001,3.324165,-1305.204590,0.003208,0.001274,0.032348,14.786626,0.753267,0.323476,-1305.204590,0.033319,0.000000
24.110001,3.512215,-1305.293457,0.003264,0.001294,0.032876,15.623111,0.795879,0.328764,-1305.293457,0.033718,0.000000
24.350000,3.588554,-1305.249023,0.003216,0.001314,0.033371,15.962687,0.813178,0.333707,-1305.249023,0.034117,0.000000
24.590002,3.530090,-1305.249023,0.003234,0.001327,0.033718,15.702626,0.799930,0.337177,-1305.249023,0.034524,0.000000
24.830002,3.546844,-1305.249023,0.003285,0.001341,0.034056,15.777152,0.803726,0.340557,-1305.249023,0.034923,0.000000
25.070002,3.581848,-1305.204590,0.003337,0.001352,0.034351,15.932857,0.811658,0.343506,-1305.204590,0.035322,0.000000
25.310001,3.723351,-1305.249023,0.003337,0.001370,0.034810,16.562290,0.843723,0.348104,-1305.249023,0.035721,0.000000
25.550001,3.849586,-1305.204590,0.003341,0.001390,0.035313,17.123816,0.872329,0.353134,-1305.204590,0.036120,0.000000
25.790001,3.830589,-1305.293457,0.003320,0.001402,0.035617,17.039312,0.868024,0.356170,-1305.293457,0.036519,0.000000
26.030001,3.879372,-1305.249023,0.003372,0.001416,0.035972,17.256308,0.879078,0.359724,-1305.249023,0.036918,0.000000
26.270000,3.877884,-1305.249023,0.003389,0.001429,0.036285,17.249689,0.878741,0.362847,-1305.249023,0.037317,0.000000
26.510002,3.916237,-1305.249023,0.003385,0.001445,0.036692,17.420292,0.887432,0.366923,-1305.249023,0.037724,0.000000
26.750002,4.050667,-1305.160034,0.003428,0.001462,0.037143,18.018267,0.917894,0.371431,-1305.160034,0.038123,0.000000
26.990002,4.208176,-1305.293457,0.003419,0.001484,0.037681,18.718901,0.953586,0.376809,-1305.293457,0.038522,0.000000
27.230001,4.252861,-1305.249023,0.003454,0.001501,0.038115,18.917671,0.963712,0.381146,-1305.249023,0.038921,0.000000
27.470001,4.230896,-1305.204590,0.003410,0.001514,0.038444,18.819965,0.958735,0.384439,-1305.204590,0.039320,0.000000
27.710001,4.278931,-1305.293457,0.003462,0.001528,0.038808,19.033634,0.969620,0.388084,-1305.293457,0.039719,0.000000
27.950001,4.432350,-1305.249023,0.003484,0.001547,0.039285,19.716078,1.004385,0.392853,-1305.249023,0.040118,0.000000
28.190001,4.476662,-1305.293457,0.003510,0.001565,0.039745,19.913185,1.014426,0.397448,-1305.293457,0.040525,0.000000
28.430002,4.442772,-1305.293457,0.003531,0.001577,0.040048,19.762436,1.006747,0.400484,-1305.293457,0.040924,0.000000
28.670002,4.513153,-1305.293457,0.003553,0.001592,0.040439,20.075508,1.022695,0.404386,-1305.293457,0.041323,0.000000
28.910002,4.520973,-1305.338013,0.003535,0.001605,0.040777,20.110292,1.024467,0.407769,-1305.338013,0.041722,0.000000
29.150002,4.751839,-1305.293457,0.003548,0.001627,0.041314,21.137234,1.076782,0.413144,-1305.293457,0.042121,0.000000
29.390001,4.816635,-1305.204590,0.003579,0.001643,0.041739,21.425463,1.091465,0.417394,-1305.204590,0.042520,0.000000
29.630001,4.781258,-1305.249023,0.003596,0.001655,0.042026,21.268097,1.083448,0.420256,-1305.249023,0.042919,0.000000
29.870001,4.819984,-1305.338013,0.003574,0.001669,0.042381,21.440361,1.092224,0.423814,-1305.338013,0.043318,0.000000
30.110001,5.056442,-1305.338013,0.003617,0.001691,0.042945,22.492178,1.145806,0.429449,-1305.338013,0.043725,0.000000
30.350002,5.006546,-1305.293457,0.003656,0.001706,0.043326,22.270229,1.134500,0.433264,-1305.293457,0.044124,0.000000
30.590002,4.955902,-1305.293457,0.003622,0.001718,0.043639,22.044954,1.123024,0.436387,-1305.293457,0.044523,0.000000
30.830002,5.114906,-1305.338013,0.003656,0.001736,0.044107,22.752239,1.159054,0.441069,-1305.338013,0.044922,0.000000
31.070002,5.264969,-1305.293457,0.003695,0.001754,0.044541,23.419752,1.193059,0.445406,-1305.293457,0.045321,0.000000
31.310001,5.286942,-1305.382446,0.003669,0.001770,0.044966,23.517490,1.198038,0.449657,-1305.382446,0.045720,0.000000
31.550001,5.305557,-1305.338013,0.003712,0.001783,0.045286,23.600298,1.202256,0.452863,-1305.338013,0.046119,0.000000
31.790001,5.327156,-1305.293457,0.003686,0.001795,0.045599,23.696373,1.207151,0.455985,-1305.293457,0.046518,0.000000
32.030003,5.541641,-1305.382446,0.003764,0.001817,0.046162,24.650452,1.255754,0.461625,-1305.382446,0.046926,0.000000
32.270000,5.488396,-1305.338013,0.003704,0.001830,0.046474,24.413603,1.243688,0.464743,-1305.338013,0.047324,0.000000
32.510002,5.463821,-1305.338013,0.003781,0.001844,0.046839,24.304291,1.238120,0.468388,-1305.338013,0.047723,0.000000
32.750000,5.553558,-1305.338013,0.003751,0.001861,0.047281,24.703461,1.258454,0.472809,-1305.338013,0.048122,0.000000
32.990002,5.528236,-1305.249023,0.003781,0.001874,0.047593,24.590824,1.252716,0.475932,-1305.249023,0.048521,0.000000
33.230003,5.712936,-1305.338013,0.003773,0.001890,0.048009,25.412411,1.294570,0.480095,-1305.338013,0.048920,0.000000
33.470001,5.782944,-1305.338013,0.003842,0.001905,0.048382,25.723818,1.310434,0.483823,-1305.338013,0.049319,0.000000
33.710003,5.805283,-1305.382446,0.003803,0.001919,0.048747,25.823187,1.315496,0.487468,-1305.382446,0.049718,0.000000
33.950001,5.823532,-1305.382446,0.003820,0.001936,0.049171,25.904364,1.319631,0.491715,-1305.382446,0.050126,0.000000
34.190002,6.071533,-1305.338013,0.003850,0.001957,0.049709,27.007528,1.375829,0.497093,-1305.338013,0.050525,0.000000
34.430000,5.950508,-1305.427002,0.003833,0.001969,0.050004,26.469183,1.348404,0.500041,-1305.427002,0.050923,0.000000
34.670002,6.077118,-1305.338013,0.003859,0.001987,0.050464,27.032372,1.377095,0.504636,-1305.338013,0.051322,0.000000
34.910000,6.182495,-1305.293457,0.003923,0.002004,0.050906,27.501112,1.400973,0.509061,-1305.293457,0.051721,0.000000
35.150002,6.212288,-1305.338013,0.003932,0.002020,0.051314,27.633636,1.407724,0.513137,-1305.338013,0.052120,0.000000
35.390003,6.178398,-1305.293457,0.003949,0.002033,0.051635,27.482887,1.400045,0.516347,-1305.293457,0.052519,0.000000
35.630001,6.202980,-1305.382446,0.003898,0.002045,0.051938,27.592234,1.405615,0.519382,-1305.382446,0.052918,0.000000
35.870003,6.472572,-1305.293457,0.003984,0.002068,0.052519,28.791439,1.466706,0.525192,-1305.293457,0.053326,0.000000
36.110001,6.544815,-1305.382446,0.003992,0.002085,0.052953,29.112791,1.483076,0.529526,-1305.382446,0.053725,0.000000
36.350002,6.519493,-1305.249023,0.004001,0.002100,0.053351,29.000154,1.477338,0.533515,-1305.249023,0.054124,0.000000
36.590000,6.468483,-1305.293457,0.004014,0.002115,0.053733,28.773249,1.465779,0.537330,-1305.293457,0.054523,0.000000
36.830002,6.532524,-1305.382446,0.004027,0.002130,0.054098,29.058119,1.480291,0.540975,-1305.382446,0.054921,0.000000
37.070004,6.602158,-1305.338013,0.004057,0.002144,0.054462,29.367865,1.496070,0.544616,-1305.338013,0.055320,0.000000
37.310001,6.644615,-1305.382446,0.004057,0.002159,0.054834,29.556725,1.505691,0.548344,-1305.382446,0.055719,0.000000
37.550003,6.605141,-1305.382446,0.004036,0.002171,0.055155,29.381134,1.496746,0.551554,-1305.382446,0.056118,0.000000
37.790001,6.929108,-1305.293457,0.004031,0.002195,0.055745,30.822210,1.570158,0.557451,-1305.293457,0.056526,0.000000
38.030003,6.916069,-1305.338013,0.004036,0.002212,0.056179,30.764212,1.567204,0.561788,-1305.338013,0.056924,0.000000
38.270000,6.817017,-1305.293457,0.004092,0.002226,0.056552,30.323605,1.544758,0.565516,-1305.293457,0.057323,0.000000
38.510002,6.806595,-1305.249023,0.004074,0.002240,0.056890,30.277246,1.542396,0.568900,-1305.249023,0.057722,0.000000
38.750000,7.003952,-1305.338013,0.004139,0.002258,0.057341,31.155134,1.587118,0.573408,-1305.338013,0.058121,0.000000
38.990002,7.004326,-1305.204590,0.004139,0.002272,0.057705,31.156797,1.587203,0.577053,-1305.204590,0.058520,0.000000
39.230003,7.033737,-1305.382446,0.004118,0.002286,0.058061,31.287626,1.593868,0.580607,-1305.382446,0.058919,0.000000
39.470001,7.062042,-1305.293457,0.004148,0.002301,0.058433,31.413532,1.600282,0.584335,-1305.293457,0.059318,0.000000
39.710003,7.327911,-1305.293457,0.004225,0.002322,0.058980,32.596176,1.660528,0.589800,-1305.293457,0.059726,0.000000
39.950001,7.298126,-1305.293457,0.004174,0.002337,0.059353,32.463688,1.653779,0.593528,-1305.293457,0.060125,0.000000
40.190002,7.307434,-1305.293457,0.004243,0.002352,0.059743,32.505089,1.655888,0.597431,-1305.293457,0.060523,0.000000
40.430000,7.312645,-1305.338013,0.004251,0.002366,0.060098,32.528271,1.657069,0.600985,-1305.338013,0.060922,0.000000
40.670002,7.385635,-1305.249023,0.004277,0.002383,0.060532,32.852947,1.673609,0.605322,-1305.249023,0.061321,0.000000
40.910004,7.582619,-1305.293457,0.004238,0.002399,0.060940,33.729172,1.718246,0.609398,-1305.293457,0.061720,0.000000
41.150002,7.496597,-1305.338013,0.004268,0.002412,0.061269,33.346531,1.698753,0.612695,-1305.338013,0.062119,0.000000
41.390003,7.320839,-1305.249023,0.004277,0.002420,0.061469,32.564716,1.658926,0.614690,-1305.249023,0.062527,0.000000
41.630001,7.849609,-1305.249023,0.004268,0.002444,0.062085,34.916805,1.778747,0.620848,-1305.249023,0.062926,0.000000
41.870003,7.854446,-1305.293457,0.004281,0.002462,0.062527,34.938324,1.779843,0.625268,-1305.293457,0.063325,0.000000
42.110001,7.845139,-1305.249023,0.004294,0.002478,0.062952,34.896919,1.777734,0.629519,-1305.249023,0.063724,0.000000
42.350002,7.944565,-1305.338013,0.004333,0.002495,0.063368,35.339188,1.800264,0.633682,-1305.338013,0.064123,0.000000
42.590000,7.707733,-1305.204590,0.004324,0.002504,0.063593,34.285709,1.746597,0.635934,-1305.204590,0.064521,0.000000
42.830002,8.094261,-1305.293457,0.004342,0.002524,0.064114,36.005074,1.834186,0.641138,-1305.293457,0.064920,0.000000
43.070004,8.076012,-1305.293457,0.004381,0.002539,0.064487,35.923893,1.830050,0.644867,-1305.293457,0.065319,0.000000
43.310001,7.989990,-1305.249023,0.004355,0.002550,0.064764,35.541252,1.810558,0.647645,-1305.249023,0.065727,0.000000
43.550003,8.325874,-1305.338013,0.004385,0.002571,0.065302,37.035339,1.886670,0.653019,-1305.338013,0.066126,0.000000
43.790001,8.338905,-1305.338013,0.004441,0.002588,0.065727,37.093304,1.889623,0.657270,-1305.338013,0.066525,0.000000
44.030003,8.188469,-1305.249023,0.004389,0.002597,0.065970,36.424129,1.855534,0.659696,-1305.249023,0.066924,0.000000
44.270000,8.364227,-1305.293457,0.004449,0.002615,0.066421,37.205940,1.895361,0.664207,-1305.293457,0.067323,0.000000
44.510002,8.416733,-1305.293457,0.004437,0.002631,0.066828,37.439499,1.907259,0.668284,-1305.293457,0.067722,0.000000
44.750004,8.706062,-1305.249023,0.004424,0.002648,0.067262,38.726498,1.972822,0.672617,-1305.249023,0.068121,0.000000
44.990002,8.526207,-1305.293457,0.004432,0.002660,0.067565,37.926464,1.932066,0.675653,-1305.293457,0.068519,0.000000
45.230003,8.758942,-1305.293457,0.004493,0.002676,0.067973,38.961720,1.984805,0.679729,-1305.293457,0.068927,0.000000
45.470001,9.005455,-1305.293457,0.004467,0.002694,0.068424,40.058266,2.040665,0.684241,-1305.293457,0.069326,0.000000
45.710003,9.088867,-1305.249023,0.004540,0.002714,0.068945,40.429302,2.059567,0.689445,-1305.249023,0.069725,0.000000
45.950001,8.935822,-1305.338013,0.004562,0.002727,0.069256,39.748520,2.024886,0.692564,-1305.338013,0.070124,0.000000
46.190002,9.005829,-1305.204590,0.004527,0.002743,0.069664,40.059929,2.040750,0.696640,-1305.204590,0.070523,0.000000
46.430000,8.957787,-1305.204590,0.004553,0.002753,0.069924,39.846226,2.029864,0.699244,-1305.204590,0.070922,0.000000
46.670002,9.243774,-1305.249023,0.004553,0.002771,0.070384,41.118362,2.094669,0.703839,-1305.249023,0.071321,0.000000
46.910004,9.515228,-1305.293457,0.004562,0.002789,0.070852,42.325848,2.156182,0.708521,-1305.293457,0.071720,0.000000
47.150002,9.444855,-1305.249023,0.004553,0.002803,0.071199,42.012814,2.140235,0.711992,-1305.249023,0.072127,0.000000
47.390003,9.430702,-1305.293457,0.004600,0.002819,0.071598,41.949860,2.137028,0.715981,-1305.293457,0.072526,0.000000
47.630001,9.549118,-1305.204590,0.004622,0.002833,0.071962,42.476597,2.163861,0.719622,-1305.204590,0.072925,0.000000
47.870003,9.596039,-1305.338013,0.004648,0.002848,0.072335,42.685314,2.174494,0.723350,-1305.338013,0.073324,0.000000
48.110001,9.736794,-1305.249023,0.004656,0.002864,0.072743,43.311420,2.206389,0.727427,-1305.249023,0.073723,0.000000
48.350002,10.079376,-1305.338013,0.004626,0.002886,0.073307,44.835304,2.284019,0.733066,-1305.338013,0.074122,0.000000
48.590004,10.107674,-1305.293457,0.004704,0.002903,0.073749,44.961178,2.290431,0.737487,-1305.293457,0.074520,0.000000
48.830002,9.879036,-1305.249023,0.004695,0.002913,0.074000,43.944145,2.238621,0.740004,-1305.249023,0.074919,0.000000
49.070004,10.000801,-1305.204590,0.004700,0.002928,0.074373,44.485786,2.266214,0.743732,-1305.204590,0.075327,0.000000
49.310001,10.322159,-1305.204590,0.004717,0.002947,0.074850,45.915257,2.339035,0.748501,-1305.204590,0.075726,0.000000
49.550003,10.455475,-1305.204590,0.004704,0.002965,0.075318,46.508274,2.369244,0.753183,-1305.204590,0.076125,0.000000
49.790001,10.421585,-1305.338013,0.004725,0.002979,0.075665,46.357525,2.361565,0.756653,-1305.338013,0.076524,0.000000
50.030003,10.637558,-1305.204590,0.004769,0.002996,0.076090,47.318222,2.410505,0.760904,-1305.204590,0.076923,0.000000
50.270004,10.736237,-1305.204590,0.004730,0.003011,0.076472,47.757164,2.432866,0.764719,-1305.204590,0.077322,0.000000
50.510002,11.057968,-1305.249023,0.004790,0.003029,0.076949,49.188297,2.505771,0.769488,-1305.249023,0.077721,0.000000
50.750004,11.070633,-1305.204590,0.004773,0.003045,0.077339,49.244637,2.508641,0.773390,-1305.204590,0.078119,0.000000
50.990002,10.988335,-1305.293457,0.004760,0.003054,0.077582,48.878555,2.489992,0.775820,-1305.293457,0.078527,0.000000
51.230003,11.176384,-1305.249023,0.004816,0.003071,0.077998,49.715038,2.532605,0.779984,-1305.249023,0.078926,0.000000
51.470001,11.686905,-1305.249023,0.004781,0.003093,0.078553,51.985950,2.648291,0.785532,-1305.249023,0.079325,0.000000
51.710003,11.548012,-1305.204590,0.004868,0.003105,0.078865,51.368122,2.616817,0.788655,-1305.204590,0.079724,0.000000
51.950001,11.589348,-1305.249023,0.004850,0.003119,0.079221,51.551994,2.626184,0.792209,-1305.249023,0.080123,0.000000
52.190002,11.920753,-1305.204590,0.004833,0.003136,0.079655,53.026161,2.701281,0.796546,-1305.204590,0.080522,0.000000
52.430004,12.213440,-1305.160034,0.004850,0.003154,0.080105,54.328094,2.767605,0.801054,-1305.160034,0.080921,0.000000
52.670002,12.341537,-1305.338013,0.004868,0.003169,0.080504,54.897900,2.796633,0.805043,-1305.338013,0.081320,0.000000
52.910004,12.383987,-1305.249023,0.004872,0.003182,0.080825,55.086727,2.806252,0.808253,-1305.249023,0.081727,0.000000
53.150002,12.415642,-1305.249023,0.004928,0.003194,0.081129,55.227531,2.813425,0.811288,-1305.249023,0.082126,0.000000
53.390003,13.266510,-1305.293457,0.004898,0.003220,0.081796,59.012383,3.006234,0.817965,-1305.293457,0.082525,0.000000
53.630001,12.999893,-1305.249023,0.004919,0.003228,0.081996,57.826412,2.945818,0.819960,-1305.249023,0.082924,0.000000
53.870003,13.205818,-1305.293457,0.004963,0.003247,0.082473,58.742413,2.992481,0.824732,-1305.293457,0.083323,0.000000
54.110004,13.562546,-1305.160034,0.004924,0.003264,0.082907,60.329216,3.073317,0.829066,-1305.160034,0.083722,0.000000
54.350002,13.518982,-1305.249023,0.004997,0.003274,0.083158,60.135433,3.063445,0.831583,-1305.249023,0.084121,0.000000
54.590004,13.877205,-1305.204590,0.004984,0.003290,0.083566,61.728889,3.144619,0.835659,-1305.204590,0.084528,0.000000
54.830002,14.096901,-1305.204590,0.004958,0.003303,0.083904,62.706146,3.194403,0.839039,-1305.204590,0.084927,0.000000
55.070004,14.331497,-1305.293457,0.005001,0.003318,0.084285,63.749683,3.247564,0.842854,-1305.293457,0.085326,0.000000
55.310001,14.792122,-1305.160034,0.005019,0.003340,0.084841,65.798645,3.351943,0.848407,-1305.160034,0.085725,0.000000
55.550003,15.333176,-1305.293457,0.004997,0.003358,0.085283,68.205368,3.474547,0.852828,-1305.293457,0.086124,0.000000
55.790001,15.208809,-1305.249023,0.005044,0.003369,0.085569,67.652161,3.446365,0.855689,-1305.249023,0.086523,0.000000
56.030003,15.746140,-1305.249023,0.005006,0.003387,0.086029,70.042328,3.568126,0.860288,-1305.249023,0.086922,0.000000
56.270004,16.209373,-1305.204590,0.005057,0.003406,0.086506,72.102898,3.673097,0.865057,-1305.204590,0.087321,0.000000
56.510002,16.523651,-1305.204590,0.005049,0.003421,0.086905,73.500870,3.744313,0.869046,-1305.204590,0.087729,0.000000
56.750004,16.629036,-1305.249023,0.005057,0.003434,0.087217,73.969643,3.768193,0.872168,-1305.249023,0.088127,0.000000
56.990002,16.722504,-1305.249023,0.005105,0.003444,0.087486,74.385414,3.789374,0.874856,-1305.249023,0.088526,0.000000
57.230003,17.742798,-1305.249023,0.005092,0.003467,0.088058,78.923904,4.020576,0.880579,-1305.249023,0.088925,0.000000
57.470001,18.210876,-1305.249023,0.005131,0.003486,0.088535,81.006027,4.126644,0.885351,-1305.249023,0.089324,0.000000
57.710003,18.497231,-1305.293457,0.005118,0.003502,0.088951,82.279793,4.191533,0.889511,-1305.293457,0.089723,0.000000
57.950005,18.713951,-1305.338013,0.005152,0.003515,0.089281,83.243813,4.240642,0.892808,-1305.338013,0.090122,0.000000
58.190002,19.225960,-1305.382446,0.005195,0.003533,0.089732,85.521339,4.356665,0.897319,-1305.382446,0.090521,0.000000
58.430004,19.466141,-1305.249023,0.005191,0.003543,0.089983,86.589722,4.411090,0.899832,-1305.249023,0.090929,0.000000
58.670002,19.968102,-1305.293457,0.005182,0.003558,0.090373,88.822548,4.524837,0.903735,-1305.293457,0.091328,0.000000
58.910004,20.370636,-1305.293457,0.005170,0.003573,0.090764,90.613113,4.616052,0.907637,-1305.293457,0.091727,0.000000
59.150002,21.601700,-1305.204590,0.005195,0.003598,0.091388,96.089157,4.895015,0.913882,-1305.204590,0.092125,0.000000
59.390003,22.124138,-1305.338013,0.005234,0.003615,0.091813,98.413078,5.013401,0.918132,-1305.338013,0.092524,0.000000
59.630001,22.270851,-1305.249023,0.005260,0.003626,0.092099,99.065697,5.046647,0.920994,-1305.249023,0.092923,0.000000
59.870003,22.680832,-1305.293457,0.005247,0.003641,0.092472,100.889381,5.139550,0.924722,-1305.293457,0.093322,0.000000
60.110004,23.564468,-1305.293457,0.005273,0.003660,0.092958,104.819992,5.339785,0.929578,-1305.293457,0.093721,0.000000
60.350002,24.030685,-1305.204590,0.005269,0.003672,0.093270,106.893829,5.445431,0.932700,-1305.204590,0.094128,0.000000
60.590004,24.522583,-1305.338013,0.005264,0.003684,0.093582,109.081894,5.556897,0.935823,-1305.338013,0.094527,0.000000
60.830002,25.361542,-1305.204590,0.005269,0.003704,0.094094,112.813774,5.747007,0.940940,-1305.204590,0.094926,0.000000
61.070004,26.523346,-1305.293457,0.005338,0.003724,0.094580,117.981735,6.010276,0.945796,-1305.293457,0.095325,0.000000
61.310001,27.041687,-1305.338013,0.005290,0.003737,0.094909,120.287430,6.127734,0.949093,-1305.338013,0.095724,0.000000
61.550003,27.732437,-1305.249023,0.005316,0.003754,0.095343,123.360039,6.284260,0.953426,-1305.249023,0.096123,0.000000
61.790005,28.343872,-1305.249023,0.005316,0.003767,0.095672,126.079842,6.422813,0.956723,-1305.249023,0.096522,0.000000
62.030003,29.146706,-1305.249023,0.005338,0.003782,0.096071,129.651016,6.604738,0.960712,-1305.249023,0.096921,0.000000
62.270004,30.040771,-1305.293457,0.005346,0.003799,0.096496,133.628021,6.807336,0.964963,-1305.293457,0.097329,0.000000
62.510002,30.665985,-1305.293457,0.005394,0.003811,0.096808,136.409119,6.949011,0.968082,-1305.293457,0.097727,0.000000
62.750004,31.124008,-1305.249023,0.005407,0.003826,0.097190,138.446503,7.052801,0.971900,-1305.249023,0.098126,0.000000
62.990002,32.691696,-1305.382446,0.005359,0.003847,0.097701,145.419922,7.408044,0.977014,-1305.382446,0.098525,0.000000
63.230003,33.506813,-1305.249023,0.005415,0.003863,0.098109,149.045746,7.592752,0.981090,-1305.249023,0.098924,0.000000
63.470001,34.568825,-1305.382446,0.005433,0.003880,0.098551,153.769806,7.833407,0.985515,-1305.382446,0.099323,0.000000
63.710003,35.440544,-1305.338013,0.005415,0.003894,0.098916,157.647415,8.030942,0.989156,-1305.338013,0.099722,0.000000
63.950005,35.794304,-1305.338013,0.005484,0.003903,0.099141,159.221008,8.111105,0.991412,-1305.338013,0.100121,0.000000
64.190002,37.206337,-1305.338013,0.005458,0.003925,0.099696,165.502060,8.431076,0.996960,-1305.338013,0.100529,0.000000
64.430000,38.027420,-1305.293457,0.005445,0.003937,0.100008,169.154419,8.617137,1.000083,-1305.293457,0.100928,0.000000
64.670006,38.595657,-1305.338013,0.005454,0.003949,0.100303,171.682053,8.745901,1.003031,-1305.338013,0.101327,0.000000
64.910004,40.331284,-1305.293457,0.005510,0.003971,0.100867,179.402512,9.139200,1.008671,-1305.293457,0.101725,0.000000
65.150002,41.451752,-1305.293457,0.005480,0.003987,0.101275,184.386597,9.393102,1.012747,-1305.293457,0.102124,0.000000
65.389999,41.994301,-1305.338013,0.005484,0.003996,0.101509,186.799973,9.516045,1.015086,-1305.338013,0.102523,0.000000
65.630005,43.181801,-1305.249023,0.005558,0.004013,0.101942,192.082245,9.785136,1.019424,-1305.249023,0.102922,0.000000
65.870003,44.111237,-1305.293457,0.005527,0.004030,0.102359,196.216583,9.995749,1.023587,-1305.293457,0.103321,0.000000
66.110001,45.766060,-1305.338013,0.005527,0.004047,0.102783,203.577606,10.370737,1.027834,-1305.338013,0.103729,0.000000
66.350006,46.456810,-1305.249023,0.005532,0.004059,0.103096,206.650208,10.527264,1.030956,-1305.249023,0.104128,0.000000
66.590004,47.710960,-1305.338013,0.005553,0.004075,0.103495,212.228958,10.811458,1.034945,-1305.338013,0.104527,0.000000
66.830002,49.279770,-1305.293457,0.005553,0.004094,0.103989,219.207367,11.166956,1.039889,-1305.293457,0.104926,0.000000
67.070000,50.997894,-1305.293457,0.005601,0.004114,0.104483,226.849960,11.556288,1.044832,-1305.293457,0.105325,0.000000
67.310005,51.946701,-1305.293457,0.005588,0.004125,0.104778,231.070465,11.771290,1.047780,-1305.293457,0.105723,0.000000
67.550003,53.065308,-1305.249023,0.005609,0.004141,0.105186,236.046280,12.024771,1.051856,-1305.249023,0.106122,0.000000
67.790001,53.902397,-1305.382446,0.005614,0.004151,0.105446,239.769836,12.214458,1.054460,-1305.382446,0.106530,0.000000
68.030006,55.430244,-1305.293457,0.005648,0.004172,0.105975,246.566040,12.560673,1.059748,-1305.293457,0.106929,0.000000
68.270004,57.020279,-1305.293457,0.005639,0.004188,0.106374,253.638870,12.920979,1.063737,-1305.293457,0.107328,0.000000
68.510002,57.980621,-1305.338013,0.005631,0.004202,0.106721,257.910675,13.138597,1.067208,-1305.338013,0.107727,0.000000
68.750000,59.375160,-1305.249023,0.005639,0.004217,0.107111,264.113892,13.454604,1.071110,-1305.249023,0.108126,0.000000
68.990005,60.603615,-1305.249023,0.005657,0.004232,0.107493,269.578339,13.732975,1.074925,-1305.249023,0.108525,0.000000
69.230003,61.677536,-1305.338013,0.005648,0.004246,0.107848,274.355377,13.976330,1.078479,-1305.338013,0.108924,0.000000
69.470001,63.095161,-1305.338013,0.005687,0.004262,0.108264,280.661285,14.297568,1.082643,-1305.338013,0.109323,0.000000
69.710007,65.039688,-1305.338013,0.005747,0.004284,0.108820,289.310974,14.738203,1.088195,-1305.338013,0.109730,0.000000
69.950005,66.739944,-1305.249023,0.005691,0.004302,0.109262,296.874115,15.123487,1.092616,-1305.249023,0.110129,0.000000
70.190002,67.393448,-1305.382446,0.005760,0.004302,0.109262,299.781036,15.271574,1.092616,-1305.382446,0.109478,0.000000
70.430000,67.063156,-1305.249023,0.005708,0.004302,0.109262,298.311829,15.196729,1.092616,-1305.249023,0.109478,0.000000
70.670006,66.893738,-1305.338013,0.005713,0.004301,0.109244,297.558197,15.158338,1.092442,-1305.338013,0.109262,0.000000
70.910004,66.683334,-1305.293457,0.005756,0.004301,0.109235,296.622284,15.110659,1.092355,-1305.293457,0.109262,0.000000
71.150002,66.505722,-1305.204590,0.005752,0.004300,0.109227,295.832214,15.070412,1.092271,-1305.204590,0.109262,0.000000
71.390007,66.344849,-1305.338013,0.005777,0.004300,0.109218,295.116638,15.033957,1.092184,-1305.338013,0.109262,0.000000
71.630005,66.226074,-1305.293457,0.005747,0.004300,0.109218,294.588287,15.007044,1.092184,-1305.293457,0.109262,0.000000
71.870003,66.118454,-1305.293457,0.005756,0.004300,0.109210,294.109558,14.982656,1.092097,-1305.293457,0.109262,0.000000
72.110001,65.983276,-1305.293457,0.005713,0.004300,0.109210,293.508270,14.952024,1.092097,-1305.293457,0.109262,0.000000
72.350006,65.917374,-1305.338013,0.005739,0.004300,0.109210,293.215118,14.937091,1.092097,-1305.338013,0.109262,0.000000
72.590004,65.809753,-1305.293457,0.005717,0.004300,0.109210,292.736389,14.912704,1.092097,-1305.293457,0.109262,0.000000
72.830002,65.727463,-1305.293457,0.005764,0.004299,0.109201,292.370361,14.894056,1.092010,-1305.293457,0.109262,0.000000
73.070000,65.664536,-1305.249023,0.005734,0.004299,0.109201,292.090454,14.879797,1.092010,-1305.249023,0.109262,0.000000
73.310005,65.579636,-1305.382446,0.005760,0.004299,0.109201,291.712799,14.860558,1.092010,-1305.382446,0.109262,0.000000
73.550003,65.532715,-1305.338013,0.005760,0.004299,0.109201,291.504089,14.849925,1.092010,-1305.338013,0.109262,0.000000
73.790001,65.467911,-1305.338013,0.005752,0.004299,0.109201,291.215820,14.835241,1.092010,-1305.338013,0.109262,0.000000
74.030006,65.388977,-1305.249023,0.005764,0.004299,0.109201,290.864685,14.817353,1.092010,-1305.249023,0.109262,0.000000
74.270004,65.362534,-1305.293457,0.005743,0.004299,0.109201,290.747070,14.811362,1.092010,-1305.293457,0.109262,0.000000
74.510002,65.319336,-1305.382446,0.005782,0.004299,0.109201,290.554932,14.801573,1.092010,-1305.382446,0.109262,0.000000
74.750000,65.259018,-1305.249023,0.005777,0.004299,0.109192,290.286621,14.787905,1.091923,-1305.249023,0.109262,0.000000
74.990005,65.228485,-1305.293457,0.005747,0.004299,0.109192,290.150787,14.780987,1.091923,-1305.293457,0.109262,0.000000
75.230003,65.177094,-1305.338013,0.005777,0.004299,0.109192,289.922180,14.769341,1.091923,-1305.338013,0.109262,0.000000
75.470001,65.139114,-1305.249023,0.005730,0.004299,0.109192,289.753265,14.760735,1.091923,-1305.249023,0.109262,0.000000
75.710007,65.092194,-1305.338013,0.005721,0.004299,0.109192,289.544525,14.750102,1.091923,-1305.338013,0.109262,0.000000
75.950005,65.050110,-1305.293457,0.005743,0.004299,0.109192,289.357330,14.740566,1.091923,-1305.293457,0.109262,0.000000
76.190002,65.024414,-1305.293457,0.005739,0.004299,0.109192,289.243042,14.734743,1.091923,-1305.293457,0.109262,0.000000
76.430000,64.977509,-1305.382446,0.005769,0.004299,0.109192,289.034393,14.724113,1.091923,-1305.382446,0.109262,0.000000
76.670006,64.952927,-1305.249023,0.005717,0.004299,0.109192,288.925049,14.718543,1.091923,-1305.249023,0.109262,0.000000
76.910004,64.906372,-1305.382446,0.005769,0.004299,0.109192,288.717957,14.707994,1.091923,-1305.382446,0.109262,0.000000
77.150002,64.876968,-1305.338013,0.005739,0.004299,0.109192,288.587158,14.701331,1.091923,-1305.338013,0.109262,0.000000
77.390007,64.859833,-1305.293457,0.005708,0.004299,0.109192,288.510956,14.697448,1.091923,-1305.293457,0.109262,0.000000
77.630005,64.821472,-1305.293457,0.005782,0.004299,0.109192,288.340302,14.688755,1.091923,-1305.293457,0.109262,0.000000
77.870003,64.800247,-1305.249023,0.005726,0.004299,0.109192,288.245911,14.683946,1.091923,-1305.249023,0.109262,0.000000
78.110001,64.768234,-1305.382446,0.005769,0.004299,0.109192,288.103485,14.676692,1.091923,-1305.382446,0.109262,0.000000
78.350006,64.739929,-1305.338013,0.005769,0.004299,0.109192,287.977600,14.670278,1.091923,-1305.338013,0.109262,0.000000
78.590004,64.723541,-1305.293457,0.005769,0.004299,0.109192,287.904694,14.666564,1.091923,-1305.293457,0.109262,0.000000
78.830002,64.680725,-1305.382446,0.005773,0.004299,0.109192,287.714233,14.656862,1.091923,-1305.382446,0.109262,0.000000
79.070007,64.659866,-1305.249023,0.005739,0.004299,0.109192,287.621460,14.652135,1.091923,-1305.249023,0.109262,0.000000
79.310005,64.654282,-1305.293457,0.005752,0.004299,0.109192,287.596619,14.650869,1.091923,-1305.293457,0.109262,0.000000
79.550003,64.621887,-1305.338013,0.005756,0.004299,0.109192,287.452515,14.643529,1.091923,-1305.338013,0.109262,0.000000
79.790001,64.601410,-1305.338013,0.005773,0.004299,0.109192,287.361420,14.638888,1.091923,-1305.338013,0.109262,0.000000
80.030006,64.563431,-1305.293457,0.005752,0.004299,0.109192,287.192474,14.630283,1.091923,-1305.293457,0.109262,0.000000
80.270004,64.558212,-1305.249023,0.005739,0.004299,0.109192,287.169281,14.629100,1.091923,-1305.249023,0.109262,0.000000
80.510002,64.540344,-1305.338013,0.005764,0.004299,0.109192,287.089783,14.625051,1.091923,-1305.338013,0.109262,0.000000
80.750008,64.515015,-1305.293457,0.005752,0.004299,0.109192,286.977112,14.619310,1.091923,-1305.293457,0.109262,0.000000
80.990005,64.516129,-1305.249023,0.005773,0.004299,0.109192,286.982086,14.619563,1.091923,-1305.249023,0.109262,0.000000
81.230003,64.473312,-1305.427002,0.005773,0.004299,0.109192,286.791626,14.609861,1.091923,-1305.427002,0.109262,0.000000
81.470001,64.458038,-1305.382446,0.005747,0.004299,0.109192,286.723663,14.606400,1.091923,-1305.382446,0.109262,0.000000
81.710007,64.459900,-1305.338013,0.005743,0.004299,0.109192,286.731964,14.606822,1.091923,-1305.338013,0.109262,0.000000
81.950005,64.405533,-1305.338013,0.005777,0.004299,0.109192,286.490112,14.594502,1.091923,-1305.338013,0.109262,0.000000
82.190002,64.414841,-1305.249023,0.005756,0.004299,0.109192,286.531525,14.596611,1.091923,-1305.249023,0.109262,0.000000
82.430000,64.391022,-1305.427002,0.005769,0.004299,0.109192,286.425568,14.591214,1.091923,-1305.427002,0.109262,0.000000
82.670006,64.367935,-1305.338013,0.005708,0.004299,0.109192,286.322876,14.585983,1.091923,-1305.338013,0.109262,0.000000
82.910004,64.379852,-1305.382446,0.005773,0.004299,0.109192,286.375885,14.588683,1.091923,-1305.382446,0.109262,0.000000
83.150002,64.336655,-1305.293457,0.005752,0.004299,0.109192,286.183746,14.578895,1.091923,-1305.293457,0.109262,0.000000
83.390007,64.332932,-1305.293457,0.005777,0.004299,0.109192,286.167175,14.578051,1.091923,-1305.293457,0.109262,0.000000
83.630005,64.304626,-1305.427002,0.005730,0.004299,0.109192,286.041260,14.571636,1.091923,-1305.427002,0.109262,0.000000
83.870003,64.300156,-1305.382446,0.005717,0.004299,0.109192,286.021362,14.570623,1.091923,-1305.382446,0.109262,0.000000
84.110001,64.291595,-1305.427002,0.005752,0.004299,0.109192,285.983307,14.568685,1.091923,-1305.427002,0.109262,0.000000
84.350006,64.269257,-1305.338013,0.005795,0.004299,0.109192,285.883942,14.563622,1.091923,-1305.338013,0.109262,0.000000
84.590004,64.262543,-1305.338013,0.005747,0.004299,0.109192,285.854065,14.562100,1.091923,-1305.338013,0.109262,0.000000
84.830002,64.251373,-1305.382446,0.005769,0.004299,0.109192,285.804382,14.559569,1.091923,-1305.382446,0.109262,0.000000
85.070007,64.224945,-1305.338013,0.005777,0.004299,0.109192,285.686829,14.553580,1.091923,-1305.338013,0.109262,0.000000
85.310005,64.228668,-1305.382446,0.005777,0.004299,0.109192,285.703400,14.554424,1.091923,-1305.382446,0.109262,0.000000
85.550003,64.198868,-1305.382446,0.005743,0.004299,0.109192,285.570831,14.547671,1.091923,-1305.382446,0.109262,0.000000
85.790001,64.192535,-1305.338013,0.005773,0.004299,0.109192,285.542664,14.546236,1.091923,-1305.338013,0.109262,0.000000
86.030006,64.179138,-1305.338013,0.005743,0.004299,0.109192,285.483063,14.543201,1.091923,-1305.338013,0.109262,0.000000
86.270004,64.156418,-1305.338013,0.005777,0.004299,0.109192,285.381989,14.538052,1.091923,-1305.338013,0.109262,0.000000
86.510002,64.171692,-1305.338013,0.005721,0.004299,0.109192,285.449951,14.541513,1.091923,-1305.338013,0.109262,0.000000
86.750008,64.133713,-1305.382446,0.005799,0.004299,0.109192,285.281006,14.532907,1.091923,-1305.382446,0.109262,0.000000
86.990005,64.146362,-1305.338013,0.005790,0.004299,0.109192,285.337280,14.535773,1.091923,-1305.338013,0.109262,0.000000
87.230003,64.125885,-1305.382446,0.005743,0.004299,0.109184,285.246185,14.531133,1.091836,-1305.382446,0.109262,0.000000
87.470001,64.099075,-1305.293457,0.005764,0.004299,0.109184,285.126923,14.525058,1.091836,-1305.293457,0.109262,0.000000
87.710007,64.100937,-1305.338013,0.005769,0.004299,0.109184,285.135193,14.525480,1.091836,-1305.338013,0.109262,0.000000
87.950005,64.080826,-1305.515869,0.005799,0.004299,0.109184,285.045746,14.520923,1.091836,-1305.515869,0.109262,0.000000
88.190002,64.078217,-1305.293457,0.005773,0.004299,0.109184,285.034149,14.520331,1.091836,-1305.293457,0.109262,0.000000
88.430008,64.054764,-1305.427002,0.005739,0.004299,0.109184,284.929810,14.515018,1.091836,-1305.427002,0.109262,0.000000
88.670006,64.048813,-1305.382446,0.005730,0.004299,0.109184,284.903351,14.513669,1.091836,-1305.382446,0.109262,0.000000
88.910004,64.047318,-1305.338013,0.005777,0.004299,0.109184,284.896698,14.513330,1.091836,-1305.338013,0.109262,0.000000
89.150002,64.023117,-1305.382446,0.005786,0.004299,0.109184,284.789062,14.507846,1.091836,-1305.382446,0.109262,0.000000
89.390007,64.027954,-1305.382446,0.005790,0.004299,0.109184,284.810577,14.508942,1.091836,-1305.382446,0.109262,0.000000
89.630005,64.011566,-1305.427002,0.005756,0.004299,0.109184,284.737671,14.505228,1.091836,-1305.427002,0.109262,0.000000
89.870003,63.991089,-1305.338013,0.005782,0.004299,0.109184,284.646576,14.500587,1.091836,-1305.338013,0.109262,0.000000
90.110001,64.000763,-1305.382446,0.005773,0.004299,0.109184,284.689606,14.502781,1.091836,-1305.382446,0.109262,0.000000
90.350006,63.970230,-1305.427002,0.005752,0.004299,0.109184,284.553802,14.495862,1.091836,-1305.427002,0.109262,0.000000
90.590004,63.967255,-1305.338013,0.005786,0.004299,0.109184,284.540558,14.495187,1.091836,-1305.338013,0.109262,0.000000
90.830002,63.947525,-1305.427002,0.005790,0.004299,0.109184,284.452789,14.490716,1.091836,-1305.427002,0.109262,0.000000
91.070007,63.941193,-1305.382446,0.005747,0.004299,0.109184,284.424622,14.489282,1.091836,-1305.382446,0.109262,0.000000
91.310005,63.937088,-1305.338013,0.005769,0.004299,0.109184,284.406372,14.488351,1.091836,-1305.338013,0.109262,0.000000
91.550003,63.913269,-1305.471436,0.005782,0.004299,0.109184,284.300415,14.482954,1.091836,-1305.471436,0.109262,0.000000
91.790001,63.922577,-1305.427002,0.005743,0.004299,0.109184,284.341827,14.485063,1.091836,-1305.427002,0.109262,0.000000
92.030006,63.894638,-1305.471436,0.005803,0.004299,0.109184,284.217560,14.478732,1.091836,-1305.471436,0.109262,0.000000
92.270004,63.892776,-1305.382446,0.005790,0.004299,0.109184,284.209259,14.478311,1.091836,-1305.382446,0.109262,0.000000
92.510002,63.886444,-1305.471436,0.005726,0.004299,0.109184,284.181091,14.476875,1.091836,-1305.471436,0.109262,0.000000
92.750008,63.870438,-1305.427002,0.005773,0.004299,0.109184,284.109894,14.473248,1.091836,-1305.427002,0.109262,0.000000
92.990005,63.881989,-1305.471436,0.005747,0.004299,0.109184,284.161285,14.475865,1.091836,-1305.471436,0.109262,0.000000
93.230003,63.860382,-1305.427002,0.005786,0.004299,0.109184,284.065155,14.470969,1.091836,-1305.427002,0.109262,0.000000
93.470001,63.843262,-1305.427002,0.005739,0.004299,0.109184,283.989014,14.467091,1.091836,-1305.427002,0.109262,0.000000
93.710007,63.837296,-1305.382446,0.005769,0.004299,0.109184,283.962463,14.465737,1.091836,-1305.382446,0.109262,0.000000
93.950005,63.821655,-1305.427002,0.005743,0.004299,0.109184,283.892914,14.462193,1.091836,-1305.427002,0.109262,0.000000
94.190002,63.825378,-1305.382446,0.005756,0.004299,0.109184,283.909454,14.463037,1.091836,-1305.382446,0.109262,0.000000
94.430008,63.801926,-1305.427002,0.005777,0.004299,0.109184,283.805145,14.457724,1.091836,-1305.427002,0.109262,0.000000
94.670006,63.798569,-1305.515869,0.005795,0.004299,0.109184,283.790222,14.456963,1.091836,-1305.515869,0.109262,0.000000
94.910004,63.785904,-1305.427002,0.005764,0.004299,0.109184,283.733856,14.454092,1.091836,-1305.427002,0.109262,0.000000
95.150002,63.770264,-1305.471436,0.005734,0.004299,0.109184,283.664307,14.450549,1.091836,-1305.471436,0.109262,0.000000
95.390007,63.771393,-1305.382446,0.005756,0.004299,0.109184,283.669312,14.450805,1.091836,-1305.382446,0.109262,0.000000
95.630005,63.744949,-1305.427002,0.005777,0.004299,0.109184,283.551697,14.444812,1.091836,-1305.427002,0.109262,0.000000
95.870003,63.749420,-1305.427002,0.005790,0.004299,0.109184,283.571594,14.445825,1.091836,-1305.427002,0.109262,0.000000
96.110008,63.723358,-1305.382446,0.005739,0.004299,0.109184,283.455658,14.439919,1.091836,-1305.382446,0.109262,0.000000
96.350006,63.720001,-1305.471436,0.005760,0.004299,0.109184,283.440735,14.439158,1.091836,-1305.471436,0.109262,0.000000
96.590004,63.714050,-1305.382446,0.005743,0.004299,0.109184,283.414246,14.437811,1.091836,-1305.382446,0.109262,0.000000
96.830002,63.699142,-1305.471436,0.005769,0.004299,0.109184,283.347931,14.434432,1.091836,-1305.471436,0.109262,0.000000
97.070007,63.699890,-1305.427002,0.005782,0.004299,0.109184,283.351257,14.434602,1.091836,-1305.427002,0.109262,0.000000
97.310005,63.690582,-1305.427002,0.005769,0.004299,0.109184,283.309845,14.432492,1.091836,-1305.427002,0.109262,0.000000
97.550003,63.693939,-1305.471436,0.005786,0.004299,0.109184,283.324799,14.433253,1.091836,-1305.471436,0.109262,0.000000
97.790001,63.679413,-1305.427002,0.005782,0.004299,0.109184,283.260162,14.429961,1.091836,-1305.427002,0.109262,0.000000
98.030006,63.655212,-1305.427002,0.005782,0.004299,0.109184,283.152527,14.424478,1.091836,-1305.427002,0.109262,0.000000
98.270004,63.673447,-1305.427002,0.005799,0.004299,0.109184,283.233643,14.428609,1.091836,-1305.427002,0.109262,0.000000
98.510002,63.637329,-1305.382446,0.005795,0.004299,0.109184,283.072968,14.420424,1.091836,-1305.382446,0.109262,0.000000
98.750008,63.645905,-1305.471436,0.005747,0.004299,0.109184,283.111115,14.422368,1.091836,-1305.471436,0.109262,0.000000
98.990005,63.641800,-1305.427002,0.005799,0.004299,0.109184,283.092865,14.421438,1.091836,-1305.427002,0.109262,0.000000
99.230003,63.629135,-1305.382446,0.005756,0.004299,0.109184,283.036530,14.418569,1.091836,-1305.382446,0.109262,0.000000
99.470001,63.626160,-1305.515869,0.005769,0.004299,0.109184,283.023285,14.417893,1.091836,-1305.515869,0.109262,0.000000
99.710007,63.610901,-1305.338013,0.005790,0.004299,0.109184,282.955414,14.414436,1.091836,-1305.338013,0.109262,0.000000
99.950005,63.609772,-1305.427002,0.005760,0.004299,0.109184,282.950409,14.414181,1.091836,-1305.427002,0.109262,0.000000
100.190002,63.609039,-1305.382446,0.005799,0.004299,0.109184,282.947144,14.414014,1.091836,-1305.382446,0.109262,0.000000
100.430008,63.590042,-1305.471436,0.005747,0.004299,0.109184,282.862640,14.409709,1.091836,-1305.471436,0.109262,0.000000
100.600006,63.604187,-1305.382446,0.005764,0.004299,0.109184,282.925568,14.412915,1.091836,-1305.382446,0.109262,0.000000