File: Data/Automembrane/AutoHeating-10wt-1-4_12152023_181010.csv
Time (sec),S:Load (lbs),S:HL1 (DIM),S:LVDT (in),S:Position (in),Ch:Position (mm),Ch:Load (N),Ch:Stress (MPa),Ch:Strain (mm/mm),Ch:HL1 (DIM),Set Point (),Cycles ()
0.110000,-0.002609,-263.949951,-0.000034,-0.000000,-0.000000,-0.011607,-0.000591,-0.000000,-263.949951,0.000182,0.000000
0.360000,-0.018623,-263.994446,-0.000004,0.000001,0.000026,-0.082841,-0.004220,0.000261,-263.994446,0.000442,0.000000
0.610000,0.001862,-263.949951,-0.000047,0.000142,0.003616,0.008281,0.000422,0.036161,-263.949951,0.004605,0.000000
0.860000,-0.057716,-263.994446,0.000103,0.000304,0.007709,-0.256735,-0.013079,0.077095,-263.994446,0.008768,0.000000
1.110000,0.017128,-263.949951,0.000241,0.000467,0.011855,0.076189,0.003881,0.118550,-263.949951,0.012948,0.000000
1.360000,0.011169,-263.994446,0.000418,0.000633,0.016087,0.049684,0.002531,0.160869,-263.994446,0.017110,0.000000
1.610000,-0.011169,-263.949951,0.000612,0.000797,0.020250,-0.049684,-0.002531,0.202496,-263.949951,0.021273,0.000000
1.860000,0.012283,-264.038940,0.000785,0.000958,0.024334,0.054639,0.002783,0.243342,-264.038940,0.025436,0.000000
2.110000,0.043190,-263.994446,0.000949,0.001117,0.028384,0.192119,0.009787,0.283841,-263.994446,0.029598,0.000000
2.360000,0.006332,-264.038940,0.001130,0.001291,0.032798,0.028168,0.001435,0.327984,-264.038940,0.033761,0.000000
2.610000,-0.002983,-263.994446,0.001285,0.001449,0.036814,-0.013269,-0.000676,0.368138,-263.994446,0.037924,0.000000
2.860000,0.010796,-263.994446,0.001457,0.001609,0.040881,0.048021,0.002446,0.408810,-263.994446,0.042087,0.000000
3.110000,-0.001488,-263.994446,0.001638,0.001778,0.045165,-0.006618,-0.000337,0.451652,-263.994446,0.046267,0.000000
3.360000,-0.004845,-264.083405,0.001802,0.001944,0.049380,-0.021550,-0.001098,0.493796,-264.083405,0.050429,0.000000
3.610000,0.009308,-264.083405,0.001983,0.002110,0.053594,0.041403,0.002109,0.535945,-264.083405,0.054592,0.000000
3.860000,0.051010,-264.083405,0.002134,0.002267,0.057592,0.226904,0.011559,0.575925,-264.083405,0.058754,0.000000
4.110000,0.026062,-264.083405,0.002324,0.002436,0.061885,0.115930,0.005906,0.618853,-264.083405,0.062917,0.000000
4.360000,0.011169,-264.083405,0.002470,0.002596,0.065926,0.049684,0.002531,0.659264,-264.083405,0.067080,0.000000
4.610000,0.030533,-264.038940,0.002656,0.002758,0.070046,0.135817,0.006919,0.700459,-264.038940,0.071243,0.000000
4.860000,0.017876,-264.083405,0.002820,0.002928,0.074382,0.079515,0.004051,0.743819,-264.083405,0.075422,0.000000
5.110000,-0.037239,-264.172363,0.002984,0.003091,0.078518,-0.165648,-0.008438,0.785184,-264.172363,0.079585,0.000000
5.360000,0.028671,-264.127899,0.003126,0.003258,0.082751,0.127536,0.006497,0.827507,-264.127899,0.083748,0.000000
5.610000,0.041702,-264.127899,0.003328,0.003416,0.086766,0.185501,0.009450,0.867657,-264.127899,0.087911,0.000000
5.860000,0.020103,-264.083405,0.003492,0.003587,0.091102,0.089425,0.004556,0.911020,-264.083405,0.092073,0.000000
6.110000,0.025696,-264.127899,0.003656,0.003743,0.095083,0.114301,0.005823,0.950826,-264.127899,0.096236,0.000000
6.360000,0.065163,-264.127899,0.003837,0.003906,0.099210,0.289858,0.014766,0.992104,-264.127899,0.100399,0.000000
6.610000,0.037605,-264.127899,0.004018,0.004080,0.103633,0.167277,0.008521,1.036335,-264.127899,0.104562,0.000000
6.860000,0.055107,-264.172363,0.004161,0.004234,0.107553,0.245129,0.012487,1.075531,-264.172363,0.108741,0.000000
7.110000,0.144478,-264.216858,0.004363,0.004403,0.111846,0.642670,0.032739,1.118459,-264.216858,0.112904,0.000000
7.360000,0.266991,-264.127899,0.004518,0.004561,0.115844,1.187634,0.060501,1.158439,-264.127899,0.117067,0.000000
7.610000,0.563400,-264.172363,0.004725,0.004730,0.120145,2.506130,0.127668,1.201454,-264.172363,0.121229,0.000000
7.860001,0.568985,-264.216858,0.004790,-0.000001,-0.000035,2.530972,0.128934,-0.000348,-264.216858,0.000130,0.000000
8.110001,0.517593,-264.172363,0.004760,-0.000002,-0.000044,2.302370,0.117288,-0.000435,-264.172363,0.000130,0.000000
8.360001,0.498978,-264.172363,0.004781,-0.000002,-0.000044,2.219563,0.113070,-0.000435,-264.172363,0.000373,0.000000
8.610001,0.439400,-264.216858,0.004760,-0.000001,-0.000035,1.954548,0.099569,-0.000348,-264.216858,0.000789,0.000000
8.860001,0.453545,-264.216858,0.004790,-0.000001,-0.000035,2.017467,0.102775,-0.000348,-264.216858,0.001205,0.000000
9.110001,0.455040,-264.216858,0.004777,-0.000001,-0.000035,2.024119,0.103114,-0.000348,-264.216858,0.001622,0.000000
9.360001,0.695961,-264.216858,0.004807,0.000050,0.001257,3.095789,0.157707,0.012573,-264.216858,0.002038,0.000000
9.610001,0.746605,-264.216858,0.004820,0.000067,0.001691,3.321064,0.169183,0.016911,-264.216858,0.002454,0.000000
9.860001,0.756660,-264.216858,0.004838,0.000081,0.002046,3.365794,0.171462,0.020465,-264.216858,0.002870,0.000000
10.110001,0.811768,-264.305817,0.004838,0.000097,0.002463,3.610923,0.183949,0.024628,-264.305817,0.003287,0.000000
10.360001,0.892204,-264.261322,0.004872,0.000112,0.002836,3.968723,0.202176,0.028356,-264.261322,0.003703,0.000000
10.610001,0.946198,-264.261322,0.004907,0.000130,0.003304,4.208897,0.214411,0.033042,-264.261322,0.004119,0.000000
10.860001,1.011734,-264.261322,0.004907,0.000142,0.003616,4.500418,0.229262,0.036165,-264.261322,0.004535,0.000000
11.110001,1.020668,-264.350281,0.004932,0.000152,0.003868,4.540158,0.231287,0.038678,-264.350281,0.004952,0.000000
11.360001,1.172226,-264.261322,0.004937,0.000180,0.004579,5.214322,0.265630,0.045790,-264.261322,0.005368,0.000000
11.610001,1.203506,-264.261322,0.004971,0.000198,0.005030,5.353464,0.272718,0.050297,-264.261322,0.005784,0.000000
11.860001,1.196800,-264.305817,0.004980,0.000212,0.005394,5.323633,0.271199,0.053942,-264.305817,0.006201,0.000000
12.110001,1.255638,-264.305817,0.005023,0.000227,0.005767,5.585357,0.284532,0.057670,-264.305817,0.006617,0.000000
12.360001,1.366234,-264.305817,0.005023,0.000248,0.006287,6.077312,0.309593,0.062875,-264.305817,0.007033,0.000000
12.610001,1.423950,-264.350281,0.005049,0.000262,0.006643,6.334047,0.322672,0.066429,-264.350281,0.007458,0.000000
12.860001,1.447411,-264.350281,0.005053,0.000272,0.006920,6.438404,0.327988,0.069203,-264.350281,0.007874,0.000000
13.110001,1.579231,-264.394775,0.005079,0.000292,0.007406,7.024772,0.357859,0.074059,-264.394775,0.008291,0.000000
13.360001,1.658173,-264.305817,0.005088,0.000313,0.007944,7.375920,0.375747,0.079437,-264.305817,0.008707,0.000000
13.610001,1.686104,-264.394775,0.005092,0.000327,0.008317,7.500165,0.382077,0.083165,-264.394775,0.009123,0.000000
13.860001,1.716263,-264.350281,0.005126,0.000343,0.008707,7.634318,0.388911,0.087068,-264.350281,0.009539,0.000000
14.110001,1.759834,-264.394775,0.005152,0.000356,0.009036,7.828134,0.398784,0.090364,-264.394775,0.009956,0.000000
14.360001,1.854042,-264.394775,0.005152,0.000373,0.009470,8.247190,0.420132,0.094702,-264.394775,0.010372,0.000000
14.610001,1.899841,-264.350281,0.005187,0.000389,0.009878,8.450916,0.430510,0.098778,-264.350281,0.010788,0.000000
14.860001,1.916229,-264.394775,0.005195,0.000400,0.010164,8.523813,0.434224,0.101640,-264.394775,0.011204,0.000000
15.110001,2.051399,-264.394775,0.005243,0.000422,0.010728,9.125079,0.464854,0.107275,-264.394775,0.011621,0.000000
15.360001,2.102043,-264.394775,0.005256,0.000438,0.011126,9.350355,0.476330,0.111265,-264.394775,0.012037,0.000000
15.610001,2.150826,-264.394775,0.005247,0.000458,0.011638,9.567349,0.487384,0.116382,-264.394775,0.012453,0.000000
15.860001,2.186569,-264.439240,0.005273,0.000474,0.012046,9.726346,0.495484,0.120458,-264.439240,0.012870,0.000000
16.110001,2.223434,-264.394775,0.005312,0.000489,0.012410,9.890330,0.503837,0.124099,-264.394775,0.013286,0.000000
16.360001,2.310570,-264.439240,0.005312,0.000508,0.012896,10.277927,0.523583,0.128955,-264.439240,0.013702,0.000000
16.610001,2.288597,-264.439240,0.005325,0.000517,0.013130,10.180188,0.518604,0.131298,-264.439240,0.014118,0.000000
16.860001,2.318764,-264.394775,0.005351,0.000530,0.013451,10.314376,0.525439,0.134508,-264.394775,0.014535,0.000000
17.110001,2.497131,-264.439240,0.005389,0.000555,0.014101,11.107795,0.565858,0.141010,-264.439240,0.014951,0.000000
17.360001,2.516495,-264.439240,0.005389,0.000575,0.014595,11.193928,0.570246,0.145953,-264.439240,0.015367,0.000000
17.610001,2.496384,-264.439240,0.005424,0.000586,0.014873,11.104469,0.565689,0.148727,-264.439240,0.015783,0.000000
17.860001,2.514259,-264.483734,0.005450,0.000602,0.015298,11.183984,0.569739,0.152978,-264.483734,0.016208,0.000000
18.110001,2.528778,-264.439240,0.005467,0.000616,0.015636,11.248567,0.573029,0.156362,-264.439240,0.016625,0.000000
18.360001,2.651665,-264.439240,0.005493,0.000637,0.016174,11.795194,0.600876,0.161736,-264.439240,0.017041,0.000000
18.610001,2.638626,-264.439240,0.005489,0.000649,0.016477,11.737195,0.597921,0.164772,-264.439240,0.017457,0.000000
18.860001,2.733955,-264.439240,0.005519,0.000668,0.016963,12.161241,0.619523,0.169628,-264.439240,0.017873,0.000000
19.110001,2.815132,-264.483734,0.005549,0.000690,0.017518,12.522333,0.637918,0.175180,-264.483734,0.018290,0.000000
19.360001,2.804337,-264.439240,0.005562,0.000705,0.017908,12.474312,0.635472,0.179082,-264.439240,0.018706,0.000000
19.610001,2.748856,-264.439240,0.005609,0.000718,0.018229,12.227520,0.622900,0.182292,-264.439240,0.019122,0.000000
19.860001,2.785347,-264.572693,0.005614,0.000733,0.018619,12.389842,0.631169,0.186194,-264.572693,0.019538,0.000000
20.110001,2.833008,-264.439240,0.005631,0.000751,0.019079,12.601849,0.641969,0.190789,-264.439240,0.019955,0.000000
20.360001,2.904129,-264.483734,0.005639,0.000768,0.019495,12.918211,0.658085,0.194952,-264.483734,0.020371,0.000000
20.610001,2.830032,-264.528229,0.005678,0.000775,0.019695,12.588613,0.641294,0.196947,-264.528229,0.020787,0.000000
20.860001,2.997597,-264.572693,0.005683,0.000798,0.020258,13.333976,0.679265,0.202583,-264.572693,0.021204,0.000000
21.110001,3.032600,-264.528229,0.005691,0.000818,0.020787,13.489680,0.687197,0.207874,-264.528229,0.021620,0.000000
21.360001,3.035950,-264.572693,0.005717,0.000834,0.021178,13.504579,0.687956,0.211776,-264.572693,0.022036,0.000000
21.610001,2.987915,-264.572693,0.005760,0.000848,0.021550,13.290910,0.677071,0.215504,-264.572693,0.022452,0.000000
21.860001,2.997971,-264.483734,0.005773,0.000863,0.021932,13.335639,0.679350,0.219320,-264.483734,0.022869,0.000000
22.110001,3.102234,-264.528229,0.005786,0.000883,0.022435,13.799425,0.702976,0.224350,-264.528229,0.023285,0.000000
22.360001,3.087708,-264.528229,0.005803,0.000899,0.022834,13.734809,0.699685,0.228339,-264.528229,0.023701,0.000000
22.610001,2.963715,-264.528229,0.005812,0.000906,0.023008,13.183261,0.671587,0.230076,-264.528229,0.024117,0.000000
22.860001,3.114151,-264.572693,0.005842,0.000930,0.023632,13.852435,0.705677,0.236317,-264.572693,0.024542,0.000000
23.110001,3.166283,-264.572693,0.005877,0.000949,0.024109,14.084329,0.717490,0.241090,-264.572693,0.024959,0.000000
23.360001,3.166283,-264.572693,0.005881,0.000965,0.024516,14.084329,0.717490,0.245163,-264.572693,0.025375,0.000000
23.610001,3.158836,-264.572693,0.005924,0.000981,0.024907,14.051206,0.715803,0.249065,-264.572693,0.025791,0.000000
23.860001,3.136490,-264.528229,0.005907,0.000997,0.025332,13.951804,0.710739,0.253315,-264.528229,0.026207,0.000000
24.110001,3.250435,-264.572693,0.005976,0.001016,0.025808,14.458656,0.736559,0.258084,-264.572693,0.026624,0.000000
24.360001,3.161812,-264.572693,0.005967,0.001027,0.026078,14.064442,0.716477,0.260775,-264.572693,0.027040,0.000000
24.610001,3.181549,-264.617187,0.005993,0.001043,0.026502,14.152237,0.720949,0.265022,-264.617187,0.027456,0.000000
24.860001,3.272781,-264.617187,0.006010,0.001063,0.027005,14.558059,0.741623,0.270052,-264.617187,0.027873,0.000000
25.110001,3.279480,-264.617187,0.006058,0.001080,0.027439,14.587855,0.743141,0.274390,-264.617187,0.028289,0.000000
25.360001,3.223999,-264.617187,0.006092,0.001096,0.027829,14.341063,0.730569,0.278292,-264.617187,0.028705,0.000000
25.610001,3.232193,-264.617187,0.006071,0.001113,0.028280,14.377513,0.732425,0.282804,-264.617187,0.029121,0.000000
25.860001,3.207985,-264.617187,0.006122,0.001127,0.028627,14.269830,0.726940,0.286271,-264.617187,0.029538,0.000000
26.110001,3.285065,-264.661652,0.006144,0.001146,0.029113,14.612698,0.744406,0.291127,-264.661652,0.029954,0.000000
26.360001,3.212456,-264.661652,0.006157,0.001155,0.029338,14.289717,0.727953,0.293382,-264.661652,0.030370,0.000000
26.610001,3.324539,-264.617187,0.006165,0.001174,0.029824,14.788289,0.753351,0.298238,-264.617187,0.030786,0.000000
26.860001,3.459709,-264.617187,0.006209,0.001200,0.030483,15.389555,0.783981,0.304828,-264.617187,0.031203,0.000000
27.110001,3.381142,-264.661652,0.006204,0.001215,0.030856,15.040070,0.766178,0.308560,-264.661652,0.031619,0.000000
27.360001,3.314857,-264.661652,0.006234,0.001229,0.031229,14.745222,0.751157,0.312288,-264.661652,0.032035,0.000000
27.610001,3.326027,-264.661652,0.006234,0.001247,0.031671,14.794907,0.753688,0.316709,-264.661652,0.032452,0.000000
27.860001,3.404602,-264.706146,0.006282,0.001264,0.032113,15.144426,0.771494,0.321133,-264.706146,0.032876,0.000000
28.110001,3.386353,-264.706146,0.006295,0.001279,0.032495,15.063249,0.767358,0.324948,-264.706146,0.033293,0.000000
28.360001,3.395660,-264.661652,0.006291,0.001293,0.032851,15.104651,0.769468,0.328506,-264.661652,0.033709,0.000000
28.610001,3.334969,-264.706146,0.006334,0.001302,0.033067,14.834682,0.755715,0.330671,-264.706146,0.034125,0.000000
28.860001,3.555038,-264.706146,0.006355,0.001330,0.033778,15.813601,0.805583,0.337783,-264.706146,0.034542,0.000000
29.110001,3.488014,-264.661652,0.006368,0.001345,0.034151,15.515462,0.790395,0.341515,-264.661652,0.034958,0.000000
29.360001,3.444443,-264.750610,0.006403,0.001359,0.034507,15.321647,0.780522,0.345069,-264.750610,0.035374,0.000000
29.610001,3.484657,-264.706146,0.006407,0.001377,0.034966,15.500530,0.789635,0.349664,-264.706146,0.035790,0.000000
29.860001,3.542007,-264.750610,0.006433,0.001394,0.035409,15.755636,0.802630,0.354088,-264.750610,0.036207,0.000000
30.110001,3.509979,-264.750610,0.006450,0.001409,0.035790,15.613168,0.795373,0.357903,-264.750610,0.036623,0.000000
30.360001,3.508492,-264.750610,0.006467,0.001420,0.036076,15.606549,0.795036,0.360765,-264.750610,0.037039,0.000000
30.610001,3.568443,-264.706146,0.006485,0.001441,0.036606,15.873229,0.808621,0.366056,-264.706146,0.037455,0.000000
30.860001,3.691330,-264.795105,0.006528,0.001461,0.037117,16.419855,0.836467,0.371173,-264.795105,0.037872,0.000000
31.110001,3.598602,-264.750610,0.006541,0.001473,0.037403,16.007383,0.815455,0.374035,-264.750610,0.038288,0.000000
31.360001,3.604561,-264.795105,0.006545,0.001490,0.037854,16.033888,0.816805,0.378542,-264.795105,0.038704,0.000000
31.610001,3.615364,-264.795105,0.006571,0.001506,0.038253,16.081944,0.819253,0.382532,-264.795105,0.039121,0.000000
31.860001,3.720375,-264.839569,0.006588,0.001527,0.038774,16.549055,0.843049,0.387736,-264.839569,0.039537,0.000000
32.110001,3.696915,-264.750610,0.006597,0.001539,0.039103,16.444698,0.837733,0.391033,-264.750610,0.039953,0.000000
32.360001,3.647011,-264.839569,0.006618,0.001550,0.039381,16.222713,0.826424,0.393807,-264.839569,0.040369,0.000000
32.610001,3.789261,-264.795105,0.006657,0.001571,0.039892,16.855474,0.858659,0.398924,-264.795105,0.040786,0.000000
32.860001,3.851074,-264.839569,0.006700,0.001593,0.040456,17.130434,0.872666,0.404560,-264.839569,0.041202,0.000000
33.110001,3.777718,-264.839569,0.006700,0.001608,0.040838,16.804127,0.856043,0.408375,-264.839569,0.041627,0.000000
33.360001,3.755745,-264.839569,0.006713,0.001623,0.041219,16.706388,0.851064,0.412190,-264.839569,0.042043,0.000000
33.610001,3.740852,-264.839569,0.006730,0.001637,0.041584,16.640142,0.847689,0.415835,-264.839569,0.042459,0.000000
33.860001,3.823143,-264.839569,0.006756,0.001655,0.042026,17.006189,0.866337,0.420256,-264.839569,0.042876,0.000000
34.110001,3.835808,-264.839569,0.006778,0.001670,0.042425,17.062525,0.869206,0.424245,-264.839569,0.043292,0.000000
34.360001,3.870811,-264.839569,0.006808,0.001687,0.042850,17.218229,0.877138,0.428496,-264.839569,0.043708,0.000000
34.610001,3.909538,-264.839569,0.006817,0.001703,0.043248,17.390495,0.885914,0.432485,-264.839569,0.044124,0.000000
34.860001,3.962784,-264.884064,0.006834,0.001723,0.043760,17.627342,0.897980,0.437602,-264.884064,0.044541,0.000000
35.110001,3.902832,-264.884064,0.006855,0.001738,0.044133,17.360664,0.884394,0.441330,-264.884064,0.044957,0.000000
35.360001,3.894646,-264.928558,0.006860,0.001753,0.044523,17.324249,0.882539,0.445232,-264.928558,0.045373,0.000000
35.610001,3.998161,-264.928558,0.006868,0.001769,0.044940,17.784710,0.905996,0.449396,-264.928558,0.045790,0.000000
35.860001,4.011192,-264.928558,0.006920,0.001786,0.045356,17.842674,0.908949,0.453559,-264.928558,0.046206,0.000000
36.110001,3.981033,-264.973022,0.006911,0.001799,0.045686,17.708521,0.902115,0.456856,-264.973022,0.046622,0.000000
36.360001,4.016777,-265.017517,0.006937,0.001812,0.046032,17.867517,0.910215,0.460323,-265.017517,0.047038,0.000000
36.610001,4.111366,-264.928558,0.006985,0.001834,0.046588,18.288271,0.931649,0.465875,-264.928558,0.047455,0.000000
36.860001,4.095726,-264.973022,0.006989,0.001850,0.046986,18.218699,0.928105,0.469861,-264.973022,0.047871,0.000000
37.110001,4.091629,-264.973022,0.007006,0.001868,0.047455,18.200476,0.927176,0.474546,-264.973022,0.048287,0.000000
37.360001,4.097588,-264.928558,0.007011,0.001882,0.047801,18.226980,0.928527,0.478013,-264.928558,0.048703,0.000000
37.610001,4.167961,-264.973022,0.007049,0.001902,0.048313,18.540016,0.944474,0.483130,-264.973022,0.049120,0.000000
37.860001,4.154182,-265.017517,0.007058,0.001915,0.048651,18.478725,0.941351,0.486514,-265.017517,0.049536,0.000000
38.110001,4.099449,-264.973022,0.007084,0.001928,0.048964,18.235260,0.928948,0.489637,-264.973022,0.049961,0.000000
38.360001,4.332176,-264.973022,0.007118,0.001953,0.049605,19.270483,0.981685,0.496052,-264.973022,0.050377,0.000000
38.610001,4.245415,-265.017517,0.007118,0.001968,0.049978,18.884548,0.962025,0.499780,-265.017517,0.050793,0.000000
38.860001,4.200363,-265.017517,0.007144,0.001981,0.050316,18.684149,0.951816,0.503164,-265.017517,0.051210,0.000000
39.110001,4.212646,-265.061981,0.007174,0.001998,0.050741,18.738787,0.954599,0.507414,-265.061981,0.051626,0.000000
39.360001,4.220467,-264.973022,0.007183,0.002014,0.051149,18.773573,0.956371,0.511491,-264.973022,0.052042,0.000000
39.610001,4.336273,-264.973022,0.007200,0.002031,0.051591,19.288706,0.982614,0.515911,-264.973022,0.052458,0.000000
39.860001,4.252121,-265.106476,0.007222,0.002045,0.051938,18.914379,0.963544,0.519382,-265.106476,0.052875,0.000000
40.110001,4.288612,-265.017517,0.007265,0.002057,0.052259,19.076700,0.971813,0.522588,-265.017517,0.053291,0.000000
40.360001,4.488579,-265.061981,0.007282,0.002081,0.052849,19.966196,1.017127,0.528489,-265.061981,0.053707,0.000000
40.610001,4.494164,-265.061981,0.007308,0.002101,0.053378,19.991037,1.018392,0.533776,-265.061981,0.054124,0.000000
40.860001,4.348938,-265.017517,0.007308,0.002113,0.053672,19.345043,0.985483,0.536725,-265.017517,0.054540,0.000000
41.110001,4.374634,-265.061981,0.007330,0.002128,0.054063,19.459343,0.991306,0.540627,-265.061981,0.054956,0.000000
41.360001,4.286377,-265.106476,0.007343,0.002139,0.054332,19.066757,0.971307,0.543318,-265.106476,0.055372,0.000000
41.610001,4.512779,-265.106476,0.007368,0.002162,0.054904,20.073845,1.022610,0.549041,-265.106476,0.055789,0.000000
41.860001,4.451340,-265.150940,0.007373,0.002174,0.055216,19.800549,1.008688,0.552163,-265.150940,0.056205,0.000000
42.110001,4.512039,-265.106476,0.007394,0.002191,0.055658,20.070553,1.022443,0.556584,-265.106476,0.056621,0.000000
42.360001,4.612206,-265.106476,0.007429,0.002210,0.056144,20.516115,1.045141,0.561440,-265.106476,0.057037,0.000000
42.610001,4.624863,-265.061981,0.007437,0.002228,0.056595,20.572416,1.048009,0.565952,-265.061981,0.057454,0.000000
42.860001,4.607361,-265.150940,0.007463,0.002245,0.057029,20.494564,1.044043,0.570289,-265.150940,0.057870,0.000000
43.110001,4.513527,-265.150940,0.007498,0.002259,0.057384,20.077171,1.022780,0.573843,-265.150940,0.058295,0.000000
43.360001,4.683327,-265.150940,0.007489,0.002277,0.057835,20.832478,1.061257,0.578351,-265.150940,0.058711,0.000000
43.610001,4.700081,-265.195435,0.007498,0.002293,0.058243,20.907003,1.065054,0.582427,-265.195435,0.059127,0.000000
43.860001,4.605125,-265.195435,0.007545,0.002304,0.058521,20.484621,1.043536,0.585205,-265.195435,0.059544,0.000000
44.110001,4.716469,-265.150940,0.007558,0.002322,0.058971,20.979900,1.068767,0.589713,-265.150940,0.059960,0.000000
44.360001,4.795784,-265.150940,0.007584,0.002341,0.059457,21.332712,1.086740,0.594569,-265.150940,0.060376,0.000000
44.610001,4.812538,-265.239899,0.007593,0.002357,0.059873,21.407238,1.090537,0.598733,-265.239899,0.060793,0.000000
44.860001,4.846428,-265.195435,0.007614,0.002375,0.060324,21.557987,1.098216,0.603240,-265.195435,0.061209,0.000000
45.110001,4.760780,-265.150940,0.007644,0.002388,0.060662,21.177008,1.078808,0.606624,-265.150940,0.061625,0.000000
45.360001,4.942871,-265.195435,0.007662,0.002410,0.061209,21.986988,1.120071,0.612086,-265.195435,0.062041,0.000000
45.610001,4.894089,-265.195435,0.007675,0.002424,0.061582,21.769995,1.109016,0.615818,-265.195435,0.062458,0.000000
45.860001,4.768600,-265.195435,0.007683,0.002433,0.061807,21.211794,1.080580,0.618070,-265.195435,0.062874,0.000000
46.110001,4.997978,-265.195435,0.007722,0.002455,0.062353,22.232117,1.132558,0.623535,-265.195435,0.063290,0.000000
46.360001,5.108200,-265.239899,0.007739,0.002474,0.062839,22.722408,1.157535,0.628391,-265.239899,0.063706,0.000000
46.610001,5.104111,-265.284393,0.007778,0.002492,0.063290,22.704218,1.156608,0.632903,-265.284393,0.064123,0.000000
46.860001,5.048996,-265.284393,0.007782,0.002505,0.063628,22.459055,1.144119,0.636283,-265.284393,0.064539,0.000000
47.110001,5.083252,-265.284393,0.007821,0.002522,0.064053,22.611435,1.151881,0.640533,-265.284393,0.064955,0.000000
47.360001,5.197205,-265.284393,0.007812,0.002538,0.064461,23.118320,1.177703,0.644609,-265.284393,0.065372,0.000000
47.610001,5.150658,-265.284393,0.007843,0.002553,0.064842,22.911270,1.167156,0.648424,-265.284393,0.065788,0.000000
47.860001,5.199066,-265.284393,0.007838,0.002567,0.065198,23.126602,1.178125,0.651978,-265.284393,0.066204,0.000000
48.110001,5.271301,-265.284393,0.007873,0.002585,0.065658,23.447920,1.194494,0.656577,-265.284393,0.066620,0.000000
48.360001,5.492867,-265.284393,0.007881,0.002610,0.066291,24.433491,1.244701,0.662905,-265.284393,0.067045,0.000000
48.610001,5.269814,-265.284393,0.007920,0.002618,0.066507,23.441301,1.194157,0.665074,-265.284393,0.067462,0.000000
48.860001,5.385994,-265.373352,0.007907,0.002640,0.067054,23.958097,1.220484,0.670540,-265.373352,0.067878,0.000000
49.110001,5.483185,-265.284393,0.007950,0.002657,0.067496,24.390425,1.242507,0.674960,-265.284393,0.068294,0.000000
49.360001,5.546486,-265.328888,0.007981,0.002672,0.067878,24.672001,1.256852,0.678775,-265.328888,0.068710,0.000000
49.610001,5.481323,-265.328888,0.007994,0.002683,0.068155,24.382143,1.242086,0.681554,-265.328888,0.069127,0.000000
49.860001,5.531219,-265.373352,0.008011,0.002698,0.068537,24.604094,1.253392,0.685369,-265.373352,0.069543,0.000000
50.110001,5.876038,-265.284393,0.008024,0.002721,0.069118,26.137920,1.331529,0.691179,-265.284393,0.069959,0.000000
50.360001,5.824280,-265.328888,0.008050,0.002738,0.069534,25.907690,1.319801,0.695342,-265.328888,0.070375,0.000000
50.610001,5.801933,-265.373352,0.008054,0.002751,0.069881,25.808289,1.314737,0.698809,-265.373352,0.070792,0.000000
50.860001,5.997055,-265.417847,0.008084,0.002771,0.070384,26.676233,1.358952,0.703839,-265.417847,0.071208,0.000000
51.110001,6.132225,-265.462311,0.008123,0.002790,0.070870,27.277500,1.389582,0.708695,-265.462311,0.071624,0.000000
51.360001,6.089775,-265.462311,0.008123,0.002803,0.071208,27.088673,1.379963,0.712079,-265.462311,0.072041,0.000000
51.610001,6.142281,-265.328888,0.008157,0.002817,0.071555,27.322229,1.391861,0.715546,-265.328888,0.072457,0.000000
51.860001,6.207077,-265.373352,0.008153,0.002831,0.071919,27.610458,1.406544,0.719191,-265.373352,0.072873,0.000000
52.110001,6.571625,-265.328888,0.008175,0.002856,0.072535,29.232046,1.489151,0.725349,-265.328888,0.073289,0.000000
52.360001,6.512421,-265.417847,0.008218,0.002870,0.072908,28.968695,1.475736,0.729077,-265.417847,0.073706,0.000000
52.610001,6.499763,-265.417847,0.008205,0.002886,0.073307,28.912392,1.472867,0.733066,-265.417847,0.074122,0.000000
52.860001,6.553757,-265.506805,0.008239,0.002900,0.073653,29.152565,1.485103,0.736533,-265.506805,0.074538,0.000000
53.110004,6.817390,-265.417847,0.008252,0.002920,0.074174,30.325268,1.544843,0.741737,-265.417847,0.074954,0.000000
53.360004,6.604393,-265.462311,0.008278,0.002929,0.074408,29.377808,1.496577,0.744080,-265.462311,0.075379,0.000000
53.610004,6.687065,-265.462311,0.008274,0.002942,0.074729,29.745552,1.515311,0.747290,-265.462311,0.075796,0.000000
53.860004,7.042679,-265.506805,0.008304,0.002963,0.075249,31.327400,1.595894,0.752490,-265.506805,0.076212,0.000000
54.110004,7.440376,-265.462311,0.008334,0.002987,0.075874,33.096447,1.686013,0.758735,-265.462311,0.076628,0.000000
54.360004,7.346161,-265.462311,0.008343,0.003003,0.076281,32.677357,1.664664,0.762812,-265.462311,0.077044,0.000000
54.610004,7.292168,-265.506805,0.008369,0.003017,0.076637,32.437183,1.652429,0.766366,-265.506805,0.077461,0.000000
54.860004,7.449310,-265.462311,0.008377,0.003031,0.076984,33.136189,1.688038,0.769836,-265.462311,0.077877,0.000000
55.110004,7.752792,-265.506805,0.008407,0.003052,0.077513,34.486141,1.756808,0.775128,-265.506805,0.078293,0.000000
55.360004,7.769180,-265.551270,0.008403,0.003064,0.077833,34.559040,1.760522,0.778333,-265.551270,0.078710,0.000000
55.610004,7.670868,-265.551270,0.008433,0.003075,0.078102,34.121723,1.738243,0.781024,-265.551270,0.079126,0.000000
55.860004,8.306885,-265.551270,0.008446,0.003099,0.078718,36.950871,1.882367,0.787179,-265.551270,0.079542,0.000000
56.110004,8.393646,-265.551270,0.008489,0.003117,0.079178,37.336803,1.902027,0.791777,-265.551270,0.079958,0.000000
56.360004,8.355667,-265.551270,0.008507,0.003131,0.079516,37.167862,1.893421,0.795157,-265.551270,0.080375,0.000000
56.610004,8.551163,-265.506805,0.008498,0.003147,0.079923,38.037472,1.937721,0.799234,-265.506805,0.080791,0.000000
56.860004,8.601433,-265.595764,0.008494,0.003160,0.080262,38.261086,1.949113,0.802617,-265.595764,0.081207,0.000000
57.110004,8.999123,-265.551270,0.008558,0.003182,0.080817,40.030098,2.039230,0.808166,-265.551270,0.081623,0.000000
57.360004,9.084023,-265.551270,0.008563,0.003195,0.081146,40.407749,2.058469,0.811463,-265.551270,0.082039,0.000000
57.610004,9.351761,-265.640228,0.008576,0.003210,0.081536,41.598709,2.119139,0.815365,-265.640228,0.082456,0.000000
57.860004,9.740143,-265.595764,0.008601,0.003230,0.082031,43.326321,2.207148,0.820308,-265.595764,0.082872,0.000000
58.110004,9.963196,-265.595764,0.008610,0.003246,0.082456,44.318508,2.257693,0.824558,-265.595764,0.083289,0.000000
58.360004,10.036552,-265.551270,0.008601,0.003263,0.082881,44.644814,2.274315,0.828809,-265.551270,0.083713,0.000000
58.610004,10.310989,-265.640228,0.008645,0.003280,0.083314,45.865570,2.336504,0.833142,-265.640228,0.084130,0.000000
58.860004,10.421585,-265.684723,0.008653,0.003296,0.083713,46.357525,2.361565,0.837132,-265.684723,0.084546,0.000000
59.110004,10.955940,-265.640228,0.008675,0.003314,0.084173,48.734455,2.482651,0.841730,-265.640228,0.084962,0.000000
59.360004,10.700119,-265.595764,0.008679,0.003322,0.084381,47.596508,2.424681,0.843812,-265.595764,0.085378,0.000000
59.610004,11.145477,-265.640228,0.008714,0.003341,0.084849,49.577560,2.525601,0.848494,-265.640228,0.085794,0.000000
59.860004,11.598282,-265.684723,0.008731,0.003361,0.085361,51.591736,2.628208,0.853611,-265.684723,0.086211,0.000000
60.110004,11.969170,-265.595764,0.008727,0.003378,0.085794,53.241524,2.712253,0.857945,-265.595764,0.086627,0.000000
60.360004,12.120720,-265.729187,0.008748,0.003392,0.086159,53.915653,2.746594,0.861590,-265.729187,0.087044,0.000000
60.610004,12.259621,-265.684723,0.008778,0.003404,0.086471,54.533516,2.778070,0.864712,-265.684723,0.087460,0.000000
60.860004,12.916855,-265.640228,0.008774,0.003425,0.086991,57.457039,2.927001,0.869913,-265.640228,0.087876,0.000000
61.110004,13.059097,-265.684723,0.008770,0.003440,0.087364,58.089767,2.959234,0.873645,-265.684723,0.088292,0.000000
61.360004,13.241936,-265.684723,0.008813,0.003450,0.087633,58.903072,3.000665,0.876332,-265.684723,0.088708,0.000000
61.610004,13.942368,-265.684723,0.008804,0.003470,0.088127,62.018749,3.159386,0.881275,-265.684723,0.089125,0.000000
61.860004,14.728447,-265.640228,0.008843,0.003494,0.088752,65.515404,3.337514,0.887520,-265.640228,0.089541,0.000000
62.110004,14.726959,-265.773682,0.008856,0.003507,0.089081,65.508789,3.337177,0.890813,-265.773682,0.089957,0.000000
62.360004,14.929527,-265.684723,0.008882,0.003522,0.089454,66.409851,3.383079,0.894545,-265.684723,0.090373,0.000000
62.610004,15.130234,-265.684723,0.008886,0.003534,0.089758,67.302643,3.428560,0.897577,-265.684723,0.090790,0.000000
62.860004,16.104362,-265.729187,0.008890,0.003557,0.090339,71.635780,3.649301,0.903390,-265.729187,0.091206,0.000000
63.110004,16.533707,-265.729187,0.008929,0.003572,0.090721,73.545601,3.746591,0.907205,-265.729187,0.091622,0.000000
63.360004,16.195969,-265.729187,0.008903,0.003578,0.090885,72.043266,3.670059,0.908852,-265.729187,0.092039,0.000000
63.610004,17.558105,-265.684723,0.008955,0.003602,0.091492,78.102356,3.978724,0.914923,-265.684723,0.092463,0.000000
63.860004,18.063416,-265.773682,0.008951,0.003621,0.091978,80.350082,4.093228,0.919779,-265.773682,0.092880,0.000000
64.110001,18.591438,-265.729187,0.008972,0.003638,0.092394,82.698845,4.212880,0.923942,-265.729187,0.093296,0.000000
64.360001,18.841675,-265.773682,0.008964,0.003651,0.092741,83.811958,4.269585,0.927409,-265.773682,0.093712,0.000000
64.610001,19.179039,-265.773682,0.008998,0.003666,0.093114,85.312630,4.346032,0.931141,-265.773682,0.094129,0.000000
64.860001,20.124496,-265.818176,0.008994,0.003685,0.093600,89.518234,4.560276,0.935997,-265.818176,0.094545,0.000000
65.110001,20.621239,-265.773682,0.009020,0.003700,0.093973,91.727852,4.672840,0.939725,-265.773682,0.094961,0.000000
65.360001,20.948555,-265.818176,0.009011,0.003713,0.094311,93.183830,4.747010,0.943109,-265.818176,0.095377,0.000000
65.610001,21.900337,-265.773682,0.009037,0.003731,0.094762,97.417564,4.962687,0.947617,-265.773682,0.095794,0.000000
65.860001,22.701317,-265.818176,0.009054,0.003750,0.095256,100.980499,5.144192,0.952560,-265.818176,0.096210,0.000000
66.110001,23.252426,-265.818176,0.009063,0.003767,0.095672,103.431961,5.269075,0.956723,-265.818176,0.096626,0.000000
66.360001,24.083191,-265.818176,0.009071,0.003785,0.096140,107.127380,5.457329,0.961405,-265.818176,0.097042,0.000000
66.610001,24.710632,-265.729187,0.009080,0.003799,0.096488,109.918381,5.599510,0.964876,-265.729187,0.097459,0.000000
66.860001,25.868340,-265.862640,0.009084,0.003820,0.097016,115.068123,5.861850,0.970163,-265.862640,0.097875,0.000000
67.110001,25.957336,-265.907135,0.009097,0.003828,0.097233,115.463997,5.882017,0.972332,-265.907135,0.098291,0.000000
67.360001,26.744904,-265.862640,0.009123,0.003843,0.097623,118.967270,6.060482,0.976234,-265.862640,0.098707,0.000000
67.610001,28.120453,-265.862640,0.009136,0.003867,0.098213,125.086021,6.372186,0.982131,-265.862640,0.099124,0.000000
67.860001,28.936317,-265.818176,0.009127,0.003883,0.098621,128.715164,6.557063,0.986207,-265.818176,0.099540,0.000000
68.110001,29.584991,-265.907135,0.009149,0.003899,0.099028,131.600616,6.704055,0.990284,-265.907135,0.099956,0.000000
68.360001,30.498421,-265.907135,0.009158,0.003916,0.099462,135.663757,6.911041,0.994621,-265.907135,0.100373,0.000000
68.610001,31.435310,-265.862640,0.009175,0.003933,0.099904,139.831238,7.123343,0.999042,-265.862640,0.100797,0.000000
68.860001,32.181915,-265.907135,0.009171,0.003946,0.100234,143.152313,7.292526,1.002339,-265.907135,0.101214,0.000000
69.110001,32.428055,-265.907135,0.009162,0.003954,0.100425,144.247192,7.348302,1.004246,-265.907135,0.101630,0.000000
69.360001,33.684441,-265.862640,0.009158,0.003973,0.100910,149.835876,7.633004,1.009102,-265.862640,0.102046,0.000000
69.610001,35.839729,-265.951599,0.009214,0.004001,0.101621,159.423080,8.121399,1.016214,-265.951599,0.102463,0.000000
69.860001,36.645920,-265.907135,0.009188,0.004016,0.101994,163.009186,8.304084,1.019942,-265.907135,0.102879,0.000000
70.110001,37.499397,-265.951599,0.009218,0.004032,0.102419,166.805649,8.497485,1.024193,-265.951599,0.103295,0.000000
70.360001,38.695457,-265.951599,0.009214,0.004049,0.102853,172.125992,8.768517,1.028530,-265.951599,0.103711,0.000000
70.610001,39.749268,-265.951599,0.009235,0.004065,0.103252,176.813568,9.007313,1.032519,-265.951599,0.104128,0.000000
70.860001,40.697701,-265.907135,0.009231,0.004080,0.103633,181.032410,9.222231,1.036335,-265.907135,0.104544,0.000000
71.110001,41.440582,-265.996094,0.009248,0.004092,0.103928,184.336914,9.390570,1.039283,-265.996094,0.104960,0.000000
71.360001,42.424393,-265.907135,0.009253,0.004110,0.104388,188.713120,9.613505,1.043878,-265.907135,0.105376,0.000000
71.610001,44.388283,-265.996094,0.009248,0.004131,0.104926,197.448944,10.058529,1.049256,-265.996094,0.105793,0.000000
71.860001,45.257027,-265.996094,0.009287,0.004145,0.105281,201.313309,10.255389,1.052810,-265.996094,0.106209,0.000000
72.110001,46.389046,-265.951599,0.009265,0.004160,0.105671,206.348785,10.511909,1.056712,-265.951599,0.106625,0.000000
72.360001,47.818954,-265.996094,0.009287,0.004181,0.106192,212.709335,10.835930,1.061917,-265.996094,0.107042,0.000000
72.610001,49.162102,-265.996094,0.009291,0.004198,0.106617,218.683945,11.140291,1.066167,-265.996094,0.107458,0.000000
72.860001,49.780235,-265.951599,0.009287,0.004208,0.106885,221.433548,11.280362,1.068854,-265.951599,0.107874,0.000000
73.110001,50.917465,-265.996094,0.009304,0.004225,0.107310,226.492203,11.538062,1.073105,-265.996094,0.108290,0.000000
73.360001,52.658302,-265.996094,0.009300,0.004243,0.107779,234.235825,11.932542,1.077787,-265.996094,0.108707,0.000000
73.610001,54.158966,-266.040558,0.009317,0.004261,0.108239,240.911118,12.272597,1.082385,-266.040558,0.109132,0.000000
73.860001,55.171448,-265.996094,0.009313,0.004276,0.108603,245.414856,12.502028,1.086026,-265.996094,0.109548,0.000000
74.110001,56.395439,-266.040558,0.009317,0.004292,0.109028,250.859436,12.779388,1.090277,-266.040558,0.109964,0.000000
74.360001,57.741562,-266.040558,0.009334,0.004307,0.109400,256.847290,13.084424,1.094005,-266.040558,0.110380,0.000000
74.610001,59.175194,-266.040558,0.009334,0.004323,0.109817,263.224396,13.409291,1.098168,-266.040558,0.110797,0.000000
74.860001,60.220444,-266.085052,0.009343,0.004339,0.110198,267.873901,13.646148,1.101984,-266.085052,0.111213,0.000000
75.110001,60.996094,-265.996094,0.009339,0.004349,0.110458,271.324188,13.821912,1.104584,-265.996094,0.111629,0.000000
75.360001,63.255287,-266.040558,0.009360,0.004375,0.111126,281.373566,14.333853,1.111264,-266.040558,0.112045,0.000000
75.610001,65.049370,-266.085052,0.009352,0.004393,0.111577,289.354034,14.740397,1.115772,-266.085052,0.112462,0.000000
75.860001,66.291985,-266.129517,0.009356,0.004407,0.111941,294.881470,15.021978,1.119413,-266.129517,0.112878,0.000000
76.110001,67.425850,-266.040558,0.009356,0.004420,0.112280,299.925171,15.278915,1.122797,-266.040558,0.113294,0.000000
76.360001,67.076561,-266.085052,0.009386,0.004413,0.112098,298.371460,15.199765,1.120976,-266.085052,0.112332,0.000000
76.610001,66.828194,-266.129517,0.009386,0.004413,0.112080,297.266663,15.143485,1.120802,-266.129517,0.112098,0.000000
76.860001,66.498268,-266.085052,0.009343,0.004412,0.112063,295.799072,15.068723,1.120628,-266.085052,0.112098,0.000000
77.110001,66.233894,-266.174011,0.009395,0.004412,0.112054,294.623077,15.008816,1.120541,-266.174011,0.112098,0.000000
77.360001,65.984398,-266.129517,0.009373,0.004412,0.112054,293.513275,14.952278,1.120541,-266.129517,0.112098,0.000000
77.610001,65.777733,-266.085052,0.009386,0.004411,0.112045,292.593964,14.905447,1.120454,-266.085052,0.112098,0.000000
77.860001,65.586708,-266.129517,0.009390,0.004411,0.112045,291.744263,14.862160,1.120454,-266.129517,0.112098,0.000000
78.110001,65.413185,-266.174011,0.009390,0.004411,0.112045,290.972382,14.822840,1.120454,-266.174011,0.112098,0.000000
78.360001,65.253807,-266.174011,0.009399,0.004411,0.112037,290.263428,14.786724,1.120367,-266.174011,0.112098,0.000000
78.610001,65.107460,-266.085052,0.009386,0.004411,0.112037,289.612457,14.753561,1.120367,-266.085052,0.112098,0.000000
78.860001,64.977135,-266.174011,0.009386,0.004411,0.112037,289.032745,14.724030,1.120367,-266.174011,0.112098,0.000000
79.110001,64.858345,-266.174011,0.009378,0.004411,0.112037,288.504333,14.697111,1.120367,-266.174011,0.112098,0.000000
79.360001,64.742165,-266.174011,0.009399,0.004411,0.112037,287.987518,14.670785,1.120367,-266.174011,0.112098,0.000000
79.610001,64.628593,-266.218506,0.009386,0.004411,0.112037,287.482330,14.645049,1.120367,-266.218506,0.112098,0.000000
79.860001,64.531029,-266.218506,0.009399,0.004411,0.112028,287.048340,14.622940,1.120283,-266.218506,0.112098,0.000000
80.110001,64.436073,-266.129517,0.009399,0.004411,0.112028,286.625977,14.601422,1.120283,-266.129517,0.112098,0.000000
80.360001,64.351921,-266.174011,0.009378,0.004411,0.112028,286.251648,14.582354,1.120283,-266.174011,0.112098,0.000000
80.610001,64.262169,-266.174011,0.009390,0.004411,0.112028,285.852417,14.562016,1.120283,-266.174011,0.112098,0.000000
80.860001,64.183601,-266.174011,0.009382,0.004411,0.112028,285.502930,14.544211,1.120283,-266.174011,0.112098,0.000000
81.110001,64.101311,-266.218506,0.009395,0.004411,0.112028,285.136871,14.525564,1.120283,-266.218506,0.112098,0.000000
81.360001,64.038383,-266.262970,0.009360,0.004411,0.112028,284.856964,14.511305,1.120283,-266.262970,0.112098,0.000000
81.610001,63.965401,-266.218506,0.009373,0.004411,0.112028,284.532318,14.494766,1.120283,-266.218506,0.112098,0.000000
81.860001,63.910652,-266.218506,0.009382,0.004411,0.112028,284.288788,14.482361,1.120283,-266.218506,0.112098,0.000000
82.110001,63.836555,-266.218506,0.009399,0.004411,0.112028,283.959167,14.465570,1.120283,-266.218506,0.112098,0.000000
82.360001,63.784416,-266.307465,0.009373,0.004411,0.112028,283.727264,14.453755,1.120283,-266.307465,0.112098,0.000000
82.610001,63.718880,-266.218506,0.009386,0.004411,0.112028,283.435730,14.438905,1.120283,-266.218506,0.112098,0.000000
82.860001,63.678291,-266.307465,0.009395,0.004411,0.112028,283.255188,14.429708,1.120283,-266.307465,0.112098,0.000000
83.110001,63.596748,-266.307465,0.009390,0.004411,0.112028,282.892456,14.411229,1.120283,-266.307465,0.112098,0.000000
83.360001,63.569191,-266.307465,0.009378,0.004411,0.112028,282.769897,14.404984,1.120283,-266.307465,0.112098,0.000000
83.610001,63.511101,-266.351929,0.009369,0.004411,0.112028,282.511475,14.391821,1.120283,-266.351929,0.112098,0.000000
83.860001,63.464928,-266.307465,0.009403,0.004411,0.112028,282.306091,14.381358,1.120283,-266.307465,0.112098,0.000000
84.110001,63.425087,-266.351929,0.009378,0.004411,0.112028,282.128876,14.372330,1.120283,-266.351929,0.112098,0.000000
84.360001,63.381889,-266.351929,0.009378,0.004411,0.112028,281.936737,14.362541,1.120283,-266.351929,0.112098,0.000000
84.610001,63.329018,-266.307465,0.009395,0.004411,0.112028,281.701538,14.350560,1.120283,-266.307465,0.112098,0.000000
84.860001,63.287682,-266.351929,0.009390,0.004411,0.112028,281.517670,14.341193,1.120283,-266.351929,0.112098,0.000000
85.110001,63.245232,-266.307465,0.009390,0.004411,0.112028,281.328827,14.331574,1.120283,-266.307465,0.112098,0.000000
85.360001,63.202034,-266.396423,0.009386,0.004411,0.112028,281.136688,14.321786,1.120283,-266.396423,0.112098,0.000000
85.610001,63.175591,-266.351929,0.009369,0.004410,0.112020,281.019073,14.315793,1.120196,-266.351929,0.112098,0.000000
85.860001,63.130531,-266.351929,0.009386,0.004410,0.112020,280.818634,14.305583,1.120196,-266.351929,0.112098,0.000000
86.110001,63.107445,-266.351929,0.009386,0.004410,0.112020,280.715942,14.300352,1.120196,-266.351929,0.112098,0.000000
86.360001,63.054573,-266.351929,0.009382,0.004410,0.112020,280.480743,14.288371,1.120196,-266.351929,0.112098,0.000000
86.610001,63.052711,-266.396423,0.009403,0.004410,0.112020,280.472473,14.287949,1.120196,-266.396423,0.112098,0.000000
86.860001,62.985313,-266.396423,0.009399,0.004410,0.112020,280.172668,14.272676,1.120196,-266.396423,0.112098,0.000000
87.110001,62.973022,-266.396423,0.009390,0.004410,0.112020,280.117981,14.269891,1.120196,-266.396423,0.112098,0.000000
87.360001,62.917168,-266.440887,0.009378,0.004410,0.112020,279.869537,14.257234,1.120196,-266.440887,0.112098,0.000000
87.610001,62.909721,-266.396423,0.009390,0.004410,0.112020,279.836426,14.255547,1.120196,-266.396423,0.112098,0.000000
87.860001,62.864662,-266.485382,0.009399,0.004410,0.112020,279.635986,14.245337,1.120196,-266.485382,0.112098,0.000000
88.110001,62.846046,-266.485382,0.009386,0.004410,0.112020,279.553162,14.241117,1.120196,-266.485382,0.112098,0.000000
88.360001,62.802101,-266.440887,0.009403,0.004410,0.112020,279.357697,14.231160,1.120196,-266.440887,0.112098,0.000000
88.610001,62.796143,-266.396423,0.009365,0.004410,0.112020,279.331207,14.229810,1.120196,-266.396423,0.112098,0.000000
88.860001,62.748108,-266.485382,0.009408,0.004410,0.112020,279.117523,14.218925,1.120196,-266.485382,0.112098,0.000000
89.110001,62.722420,-266.485382,0.009386,0.004410,0.112020,279.003265,14.213103,1.120196,-266.485382,0.112098,0.000000
89.360001,62.690765,-266.440887,0.009390,0.004410,0.112020,278.862457,14.205931,1.120196,-266.440887,0.112098,0.000000
89.610001,62.671028,-266.440887,0.009382,0.004410,0.112020,278.774658,14.201458,1.120196,-266.440887,0.112098,0.000000
89.860001,62.646828,-266.440887,0.009378,0.004410,0.112020,278.666992,14.195974,1.120196,-266.440887,0.112098,0.000000
90.110001,62.627464,-266.485382,0.009395,0.004410,0.112020,278.580872,14.191586,1.120196,-266.485382,0.112098,0.000000
90.360001,62.603256,-266.485382,0.009390,0.004410,0.112020,278.473206,14.186101,1.120196,-266.485382,0.112098,0.000000
90.610001,62.570862,-266.529846,0.009386,0.004410,0.112020,278.329102,14.178760,1.120196,-266.529846,0.112098,0.000000
90.860001,62.542931,-266.485382,0.009408,0.004410,0.112020,278.204865,14.172430,1.120196,-266.485382,0.112098,0.000000
91.110001,62.515747,-266.529846,0.009403,0.004410,0.112020,278.083923,14.166271,1.120196,-266.529846,0.112098,0.000000
91.360001,62.493782,-266.529846,0.009395,0.004410,0.112020,277.986237,14.161293,1.120196,-266.529846,0.112098,0.000000
91.610001,62.468086,-266.529846,0.009412,0.004410,0.112020,277.871918,14.155471,1.120196,-266.529846,0.112098,0.000000
91.860001,62.463989,-266.440887,0.009382,0.004410,0.112020,277.853699,14.154542,1.120196,-266.440887,0.112098,0.000000
92.110001,62.425636,-266.485382,0.009399,0.004410,0.112020,277.683105,14.145851,1.120196,-266.485382,0.112098,0.000000
92.360001,62.415955,-266.574341,0.009395,0.004410,0.112020,277.640045,14.143658,1.120196,-266.574341,0.112098,0.000000
92.610001,62.379463,-266.618835,0.009378,0.004410,0.112020,277.477722,14.135388,1.120196,-266.618835,0.112098,0.000000
92.860001,62.370522,-266.574341,0.009390,0.004410,0.112020,277.437927,14.133363,1.120196,-266.574341,0.112098,0.000000
93.110001,62.351532,-266.574341,0.009403,0.004410,0.112020,277.353455,14.129059,1.120196,-266.574341,0.112098,0.000000
93.360008,62.325096,-266.574341,0.009395,0.004410,0.112020,277.235870,14.123069,1.120196,-266.574341,0.112098,0.000000
93.610008,62.311317,-266.529846,0.009399,0.004410,0.112020,277.174591,14.119946,1.120196,-266.529846,0.112098,0.000000
93.860008,62.286369,-266.574341,0.009373,0.004410,0.112020,277.063599,14.114293,1.120196,-266.574341,0.112098,0.000000
94.110008,62.286743,-266.618835,0.009399,0.004410,0.112020,277.065277,14.114378,1.120196,-266.618835,0.112098,0.000000
94.360008,62.257698,-266.529846,0.009382,0.004410,0.112020,276.936066,14.107796,1.120196,-266.529846,0.112098,0.000000
94.610008,62.241310,-266.574341,0.009386,0.004410,0.112020,276.863190,14.104083,1.120196,-266.574341,0.112098,0.000000
94.860008,62.205933,-266.618835,0.009395,0.004410,0.112020,276.705811,14.096066,1.120196,-266.618835,0.112098,0.000000
95.110008,62.210403,-266.574341,0.009408,0.004410,0.112020,276.725708,14.097078,1.120196,-266.574341,0.112098,0.000000
95.360008,62.183594,-266.574341,0.009395,0.004410,0.112020,276.606445,14.091003,1.120196,-266.574341,0.112098,0.000000
95.610008,62.176147,-266.618835,0.009382,0.004410,0.112020,276.573303,14.089316,1.120196,-266.618835,0.112098,0.000000
95.860008,62.147842,-266.574341,0.009425,0.004410,0.112020,276.447418,14.082902,1.120196,-266.574341,0.112098,0.000000
96.110008,62.126991,-266.574341,0.009378,0.004410,0.112020,276.354645,14.078177,1.120196,-266.574341,0.112098,0.000000
96.360008,62.114334,-266.574341,0.009399,0.004410,0.112020,276.298370,14.075310,1.120196,-266.574341,0.112098,0.000000
96.610008,62.080818,-266.574341,0.009386,0.004410,0.112020,276.149261,14.067715,1.120196,-266.574341,0.112098,0.000000
96.860008,62.096458,-266.618835,0.009390,0.004410,0.112020,276.218842,14.071259,1.120196,-266.618835,0.112098,0.000000
97.110008,62.066299,-266.663300,0.009386,0.004410,0.112020,276.084686,14.064425,1.120196,-266.663300,0.112098,0.000000
97.360008,62.052147,-266.663300,0.009382,0.004410,0.112020,276.021729,14.061217,1.120196,-266.663300,0.112098,0.000000
97.610008,62.025337,-266.618835,0.009399,0.004410,0.112020,275.902466,14.055141,1.120196,-266.618835,0.112098,0.000000
97.860008,62.016396,-266.707794,0.009399,0.004410,0.112020,275.862701,14.053116,1.120196,-266.707794,0.112098,0.000000
98.110008,61.997406,-266.663300,0.009395,0.004410,0.112020,275.778229,14.048814,1.120196,-266.663300,0.112098,0.000000
98.360008,61.996658,-266.752258,0.009416,0.004410,0.112020,275.774902,14.048644,1.120196,-266.752258,0.112098,0.000000
98.610008,61.984375,-266.707794,0.009378,0.004410,0.112020,275.720276,14.045860,1.120196,-266.707794,0.112098,0.000000
98.860008,61.957565,-266.663300,0.009408,0.004410,0.112020,275.601013,14.039784,1.120196,-266.663300,0.112098,0.000000
99.110008,61.963524,-266.663300,0.009386,0.004410,0.112020,275.627533,14.041135,1.120196,-266.663300,0.112098,0.000000
99.360008,61.914742,-266.707794,0.009386,0.004410,0.112020,275.410522,14.030081,1.120196,-266.707794,0.112098,0.000000
99.610008,61.926659,-266.707794,0.009386,0.004410,0.112020,275.463531,14.032782,1.120196,-266.707794,0.112098,0.000000
99.860008,61.897614,-266.707794,0.009386,0.004410,0.112020,275.334351,14.026200,1.120196,-266.707794,0.112098,0.000000
100.110008,61.894257,-266.752258,0.009395,0.004410,0.112020,275.319397,14.025439,1.120196,-266.752258,0.112098,0.000000
100.360008,61.878616,-266.663300,0.009382,0.004410,0.112020,275.249847,14.021895,1.120196,-266.663300,0.112098,0.000000
100.610008,61.864845,-266.752258,0.009408,0.004410,0.112020,275.188568,14.018775,1.120196,-266.752258,0.112098,0.000000
100.860008,61.835800,-266.796753,0.009390,0.004410,0.112020,275.059387,14.012193,1.120196,-266.796753,0.112098,0.000000
101.110008,61.828720,-266.796753,0.009408,0.004410,0.112020,275.027893,14.010588,1.120196,-266.796753,0.112098,0.000000
101.360008,61.820160,-266.796753,0.009399,0.004410,0.112020,274.989807,14.008649,1.120196,-266.796753,0.112098,0.000000
101.610008,61.814575,-266.752258,0.009412,0.004410,0.112020,274.964966,14.007383,1.120196,-266.752258,0.112098,0.000000
101.860008,61.810844,-266.796753,0.009378,0.004410,0.112020,274.948364,14.006538,1.120196,-266.796753,0.112098,0.000000
102.110008,61.785530,-266.752258,0.009395,0.004410,0.112020,274.835754,14.000801,1.120196,-266.752258,0.112098,0.000000
102.360008,61.782173,-266.752258,0.009425,0.004410,0.112020,274.820831,14.000041,1.120196,-266.752258,0.112098,0.000000
102.610008,61.759087,-266.796753,0.009386,0.004410,0.112020,274.718140,13.994808,1.120196,-266.796753,0.112098,0.000000
102.860008,61.762070,-266.885712,0.009382,0.004410,0.112020,274.731415,13.995485,1.120196,-266.885712,0.112098,0.000000
103.110008,61.726692,-266.841217,0.009395,0.004410,0.112020,274.574036,13.987469,1.120196,-266.841217,0.112098,0.000000
103.360008,61.726318,-266.841217,0.009386,0.004410,0.112020,274.572388,13.987384,1.120196,-266.841217,0.112098,0.000000
103.610008,61.718872,-266.796753,0.009416,0.004410,0.112020,274.539246,13.985697,1.120196,-266.796753,0.112098,0.000000
103.860008,61.699883,-266.752258,0.009386,0.004410,0.112020,274.454773,13.981394,1.120196,-266.752258,0.112098,0.000000
104.110008,61.695412,-266.796753,0.009386,0.004410,0.112020,274.434906,13.980380,1.120196,-266.796753,0.112098,0.000000
104.360008,61.658546,-266.841217,0.009399,0.004410,0.112020,274.270905,13.972027,1.120196,-266.841217,0.112098,0.000000
104.610008,61.673439,-266.841217,0.009412,0.004410,0.112020,274.337158,13.975401,1.120196,-266.841217,0.112098,0.000000
104.860008,61.642166,-266.796753,0.009395,0.004410,0.112020,274.198059,13.968314,1.120196,-266.796753,0.112098,0.000000
105.110008,61.650726,-266.885712,0.009412,0.004410,0.112020,274.236115,13.970254,1.120196,-266.885712,0.112098,0.000000
105.360008,61.632851,-266.841217,0.009399,0.004410,0.112020,274.156616,13.966204,1.120196,-266.841217,0.112098,0.000000
105.610008,61.629501,-266.841217,0.009386,0.004410,0.112020,274.141724,13.965445,1.120196,-266.841217,0.112098,0.000000
105.860008,61.604553,-266.930176,0.009399,0.004410,0.112020,274.030731,13.959791,1.120196,-266.930176,0.112098,0.000000
106.110008,61.597855,-266.930176,0.009399,0.004410,0.112020,274.000946,13.958273,1.120196,-266.930176,0.112098,0.000000
106.360008,61.592262,-266.885712,0.009421,0.004410,0.112020,273.976074,13.957006,1.120196,-266.885712,0.112098,0.000000
106.600006,61.580353,-266.930176,0.009390,0.004410,0.112020,273.923096,13.954307,1.120196,-266.930176,0.112098,0.000000