File: Data/Automembrane/AutoHeating-12wt-1-4_12152023_175315.csv
Time (sec),S:Load (lbs),S:HL1 (DIM),S:LVDT (in),S:Position (in),Ch:Position (mm),Ch:Load (N),Ch:Stress (MPa),Ch:Strain (mm/mm),Ch:HL1 (DIM),Set Point (),Cycles ()
0.110000,-0.002975,-236.505219,0.000017,0.000000,0.000009,-0.013236,-0.000674,0.000087,-236.505219,0.000226,0.000000
0.370000,0.010803,-236.460739,-0.000009,0.000004,0.000095,0.048055,0.002448,0.000954,-236.460739,0.000729,0.000000
0.630000,0.035004,-236.460739,0.000030,0.000160,0.004059,0.155704,0.007932,0.040585,-236.460739,0.005065,0.000000
0.890000,0.005585,-236.460739,0.000177,0.000330,0.008386,0.024842,0.001266,0.083862,-236.460739,0.009401,0.000000
1.150000,0.008942,-236.549698,0.000401,0.000497,0.012635,0.039774,0.002026,0.126355,-236.549698,0.013737,0.000000
1.410000,0.015640,-236.460739,0.000569,0.000669,0.016989,0.069571,0.003544,0.169889,-236.460739,0.018055,0.000000
1.670000,-0.037979,-236.549698,0.000729,0.000840,0.021325,-0.168940,-0.008606,0.213252,-236.549698,0.022392,0.000000
1.930000,0.002235,-236.505219,0.000914,0.001010,0.025653,0.009944,0.000507,0.256525,-236.505219,0.026728,0.000000
2.190000,0.035004,-236.505219,0.001069,0.001172,0.029763,0.155704,0.007932,0.297633,-236.505219,0.031064,0.000000
2.450000,0.001862,-236.549698,0.001259,0.001352,0.034334,0.008281,0.000422,0.343335,-236.549698,0.035383,0.000000
2.710000,0.028671,-236.549698,0.001440,0.001523,0.038687,0.127536,0.006497,0.386869,-236.549698,0.039719,0.000000
2.970000,0.040962,-236.549698,0.001638,0.001690,0.042919,0.182209,0.009282,0.429192,-236.549698,0.044055,0.000000
3.230000,0.005585,-236.505219,0.001815,0.001860,0.047238,0.024842,0.001266,0.472378,-236.505219,0.048391,0.000000
3.490000,0.011543,-236.505219,0.001996,0.002035,0.051678,0.051347,0.002616,0.516778,-236.505219,0.052710,0.000000
3.750000,0.008194,-236.594177,0.002151,0.002206,0.056040,0.036449,0.001857,0.560403,-236.594177,0.057046,0.000000
4.010000,-0.040588,-236.549698,0.002341,0.002376,0.060350,-0.180546,-0.009197,0.603501,-236.549698,0.061382,0.000000
4.270000,0.028671,-236.549698,0.002514,0.002545,0.064634,0.127536,0.006497,0.646343,-236.549698,0.065718,0.000000
4.530000,0.018623,-236.549698,0.002695,0.002720,0.069100,0.082841,0.004220,0.691005,-236.549698,0.070037,0.000000
4.790000,-0.001114,-236.549698,0.002880,0.002884,0.073263,-0.004955,-0.000252,0.732631,-236.549698,0.074373,0.000000
5.050000,0.023834,-236.638657,0.003048,0.003053,0.077538,0.106020,0.005401,0.775385,-236.638657,0.078710,0.000000
5.310000,0.025696,-236.594177,0.003225,0.003231,0.082057,0.114301,0.005823,0.820569,-236.594177,0.083028,0.000000
5.570000,0.017502,-236.638657,0.003423,0.003393,0.086185,0.077852,0.003966,0.861851,-236.638657,0.087364,0.000000
5.830000,0.023460,-236.683136,0.003570,0.003565,0.090556,0.104357,0.005316,0.905559,-236.683136,0.091700,0.000000
6.090000,0.007080,-236.638657,0.003773,0.003741,0.095013,0.031494,0.001604,0.950134,-236.638657,0.096036,0.000000
6.350000,-0.022339,-236.638657,0.003941,0.003911,0.099332,-0.099368,-0.005062,0.993319,-236.638657,0.100355,0.000000
6.610000,0.049904,-236.638657,0.004105,0.004077,0.103547,0.221983,0.011308,1.035468,-236.638657,0.104691,0.000000
6.870000,0.045807,-236.594177,0.004324,0.004256,0.108108,0.203759,0.010380,1.081083,-236.594177,0.109028,0.000000
7.130000,0.024948,-236.638657,0.004480,0.004419,0.112237,0.110975,0.005653,1.122365,-236.638657,0.113364,0.000000
7.390000,0.052132,-236.638657,0.004643,0.004586,0.116495,0.231893,0.011813,1.164945,-236.638657,0.117683,0.000000
7.650001,0.027931,-236.638657,0.004846,0.004765,0.121039,0.124244,0.006329,1.210387,-236.638657,0.122019,0.000000
7.910000,0.011177,-236.638657,0.005023,0.004933,0.125297,0.049718,0.002533,1.252967,-236.638657,0.126355,0.000000
8.170000,0.041336,-236.727615,0.005187,0.005099,0.129503,0.183872,0.009367,1.295028,-236.727615,0.130691,0.000000
8.430000,0.056229,-236.727615,0.005359,0.005276,0.134013,0.250117,0.012742,1.340125,-236.727615,0.135010,0.000000
8.690001,0.161987,-236.727615,0.005566,0.005447,0.138366,0.720556,0.036707,1.383659,-236.727615,0.139346,0.000000
8.950001,0.367905,-236.727615,0.005704,0.005609,0.142477,1.636522,0.083368,1.424767,-236.727615,0.143682,0.000000
9.210000,0.652397,-236.727615,0.005864,-0.000002,-0.000052,2.902008,0.147835,-0.000519,-236.727615,0.001075,0.000000
9.470000,0.510529,-236.772110,0.005890,-0.000003,-0.000078,2.270944,0.115687,-0.000780,-236.772110,0.000078,0.000000
9.730000,0.478874,-236.816589,0.005881,-0.000003,-0.000078,2.130139,0.108514,-0.000780,-236.816589,0.000087,0.000000
9.990001,0.463234,-236.772110,0.005881,-0.000003,-0.000078,2.060568,0.104970,-0.000780,-236.772110,0.000520,0.000000
10.250001,0.450943,-236.772110,0.005864,-0.000003,-0.000078,2.005895,0.102185,-0.000780,-236.772110,0.000954,0.000000
10.510000,0.560051,-236.727615,0.005890,0.000022,0.000564,2.491231,0.126909,0.005639,-236.727615,0.001388,0.000000
10.770000,0.616280,-236.772110,0.005911,0.000037,0.000945,2.741349,0.139651,0.009455,-236.772110,0.001821,0.000000
11.030001,0.691124,-236.772110,0.005911,0.000056,0.001414,3.074273,0.156611,0.014137,-236.772110,0.002255,0.000000
11.290001,0.770439,-236.727615,0.005920,0.000072,0.001830,3.427084,0.174584,0.018300,-236.727615,0.002688,0.000000
11.550000,0.751823,-236.816589,0.005967,0.000082,0.002081,3.344278,0.170366,0.020813,-236.816589,0.003122,0.000000
11.810000,0.859810,-236.816589,0.005963,0.000104,0.002637,3.824625,0.194836,0.026366,-236.816589,0.003556,0.000000
12.070001,0.942848,-236.816589,0.005989,0.000123,0.003131,4.193998,0.213652,0.031309,-236.816589,0.003989,0.000000
12.330001,1.003548,-236.772110,0.006002,0.000141,0.003590,4.464003,0.227407,0.035904,-236.772110,0.004423,0.000000
12.590000,1.043762,-236.772110,0.006045,0.000157,0.003998,4.642886,0.236520,0.039980,-236.772110,0.004856,0.000000
12.850000,1.059402,-236.905548,0.006058,0.000171,0.004345,4.712458,0.240064,0.043451,-236.905548,0.005290,0.000000
13.110001,1.188240,-236.772110,0.006032,0.000192,0.004883,5.285556,0.269259,0.048825,-236.772110,0.005724,0.000000
13.370001,1.247826,-236.816589,0.006075,0.000206,0.005238,5.550606,0.282761,0.052383,-236.816589,0.006149,0.000000
13.630001,1.362885,-236.861069,0.006079,0.000224,0.005698,6.062413,0.308834,0.056978,-236.861069,0.006582,0.000000
13.890000,1.372192,-236.816589,0.006114,0.000240,0.006105,6.103817,0.310943,0.061054,-236.816589,0.007016,0.000000
14.150001,1.469383,-236.905548,0.006118,0.000261,0.006626,6.536143,0.332967,0.066258,-236.905548,0.007449,0.000000
14.410001,1.477203,-236.861069,0.006127,0.000274,0.006964,6.570929,0.334739,0.069638,-236.861069,0.007883,0.000000
14.670001,1.558006,-236.816589,0.006157,0.000290,0.007354,6.930358,0.353049,0.073541,-236.816589,0.008317,0.000000
14.930000,1.669724,-236.950027,0.006165,0.000307,0.007805,7.427301,0.378365,0.078052,-236.950027,0.008750,0.000000
15.190001,1.723343,-236.861069,0.006196,0.000325,0.008247,7.665812,0.390515,0.082473,-236.861069,0.009184,0.000000
15.450001,1.765793,-236.905548,0.006191,0.000337,0.008568,7.854639,0.400134,0.085682,-236.905548,0.009618,0.000000
15.710001,1.937080,-236.861069,0.006209,0.000362,0.009201,8.616564,0.438949,0.092015,-236.861069,0.010051,0.000000
15.970001,2.031670,-236.950027,0.006247,0.000384,0.009756,9.037318,0.460383,0.097563,-236.950027,0.010485,0.000000
16.230001,2.012672,-236.905548,0.006265,0.000397,0.010086,8.952814,0.456078,0.100860,-236.905548,0.010918,0.000000
16.490002,2.030174,-236.905548,0.006269,0.000411,0.010441,9.030666,0.460044,0.104414,-236.905548,0.011352,0.000000
16.750000,2.049911,-236.950027,0.006252,0.000425,0.010788,9.118462,0.464517,0.107885,-236.950027,0.011786,0.000000
17.010000,2.111351,-236.905548,0.006308,0.000442,0.011239,9.391758,0.478439,0.112392,-236.905548,0.012219,0.000000
17.270000,2.272217,-236.950027,0.006312,0.000461,0.011708,10.107326,0.514892,0.117078,-236.950027,0.012653,0.000000
17.530001,2.397705,-236.905548,0.006308,0.000480,0.012185,10.665524,0.543328,0.121847,-236.905548,0.013087,0.000000
17.790001,2.454308,-236.950027,0.006355,0.000499,0.012670,10.917305,0.556154,0.126703,-236.950027,0.013520,0.000000
18.050001,2.504951,-236.994507,0.006351,0.000517,0.013121,11.142581,0.567630,0.131211,-236.994507,0.013954,0.000000
18.310001,2.521706,-236.950027,0.006347,0.000531,0.013494,11.217107,0.571427,0.134943,-236.950027,0.014388,0.000000
18.570002,2.591339,-236.994507,0.006359,0.000547,0.013902,11.526852,0.587206,0.139015,-236.994507,0.014821,0.000000
18.830002,2.733215,-236.994507,0.006385,0.000566,0.014379,12.157949,0.619355,0.143788,-236.994507,0.015255,0.000000
19.090000,2.808807,-236.994507,0.006420,0.000583,0.014803,12.494199,0.636485,0.148035,-236.994507,0.015688,0.000000
19.350000,2.769333,-236.994507,0.006424,0.000594,0.015081,12.318608,0.627540,0.150813,-236.994507,0.016122,0.000000
19.610001,2.938766,-236.994507,0.006454,0.000615,0.015619,13.072287,0.665934,0.156187,-236.994507,0.016556,0.000000
19.870001,3.094414,-237.038986,0.006450,0.000634,0.016113,13.764640,0.701204,0.161131,-237.038986,0.016989,0.000000
20.130001,3.138733,-237.083466,0.006476,0.000652,0.016556,13.961782,0.711247,0.165555,-237.083466,0.017423,0.000000
20.390001,3.126442,-237.083466,0.006467,0.000666,0.016911,13.907108,0.708462,0.169109,-237.083466,0.017856,0.000000
20.650002,3.252678,-237.083466,0.006480,0.000683,0.017345,14.468634,0.737067,0.173447,-237.083466,0.018290,0.000000
20.910002,3.419502,-237.038986,0.006497,0.000705,0.017900,15.210706,0.774870,0.178995,-237.038986,0.018723,0.000000
21.170000,3.311142,-237.083466,0.006536,0.000713,0.018116,14.728695,0.750315,0.181164,-237.083466,0.019157,0.000000
21.430000,3.594139,-237.083466,0.006541,0.000736,0.018689,15.987529,0.814444,0.186887,-237.083466,0.019591,0.000000
21.690001,3.696175,-237.038986,0.006562,0.000755,0.019166,16.441406,0.837565,0.191660,-237.038986,0.020024,0.000000
21.950001,3.722984,-237.127945,0.006584,0.000771,0.019582,16.560661,0.843640,0.195819,-237.127945,0.020458,0.000000
22.210001,3.806396,-237.083466,0.006571,0.000789,0.020042,16.931698,0.862542,0.200418,-237.083466,0.020883,0.000000
22.470001,3.853683,-237.083466,0.006571,0.000806,0.020466,17.142040,0.873257,0.204664,-237.083466,0.021317,0.000000
22.730001,4.025719,-237.127945,0.006597,0.000824,0.020926,17.907291,0.912241,0.209263,-237.127945,0.021750,0.000000
22.990002,4.031303,-237.083466,0.006644,0.000838,0.021273,17.932133,0.913506,0.212730,-237.083466,0.022184,0.000000
23.250002,4.089767,-237.083466,0.006610,0.000852,0.021629,18.192194,0.926755,0.216288,-237.083466,0.022617,0.000000
23.510000,4.108391,-237.083466,0.006640,0.000865,0.021967,18.275036,0.930975,0.219668,-237.083466,0.023051,0.000000
23.770000,4.416710,-237.172424,0.006661,0.000892,0.022669,19.646507,1.000841,0.226692,-237.172424,0.023485,0.000000
24.030001,4.395485,-237.083466,0.006670,0.000909,0.023086,19.552094,0.996031,0.230856,-237.083466,0.023918,0.000000
24.290001,4.473686,-237.172424,0.006709,0.000926,0.023511,19.899950,1.013752,0.235106,-237.172424,0.024352,0.000000
24.550001,4.557472,-237.216919,0.006700,0.000944,0.023979,20.272650,1.032738,0.239788,-237.216919,0.024785,0.000000
24.810001,4.652420,-237.172424,0.006739,0.000959,0.024360,20.694998,1.054253,0.243603,-237.172424,0.025219,0.000000
25.070002,4.654655,-237.216919,0.006748,0.000973,0.024716,20.704941,1.054760,0.247161,-237.216919,0.025653,0.000000
25.330002,4.632317,-237.216919,0.006713,0.000985,0.025020,20.605574,1.049698,0.250197,-237.216919,0.026086,0.000000
25.590002,4.958885,-237.172424,0.006773,0.001009,0.025627,22.058224,1.123699,0.256268,-237.172424,0.026520,0.000000
25.850000,5.000961,-237.172424,0.006760,0.001027,0.026095,22.245386,1.133234,0.260950,-237.172424,0.026953,0.000000
26.110001,5.002823,-237.172424,0.006782,0.001044,0.026520,22.253668,1.133656,0.265200,-237.172424,0.027387,0.000000
26.370001,5.075066,-237.216919,0.006791,0.001062,0.026971,22.575020,1.150026,0.269708,-237.216919,0.027820,0.000000
26.630001,5.164062,-237.216919,0.006804,0.001082,0.027483,22.970898,1.170193,0.274825,-237.216919,0.028254,0.000000
26.890001,5.061661,-237.261398,0.006847,0.001092,0.027734,22.515392,1.146989,0.277338,-237.261398,0.028688,0.000000
27.150002,5.181938,-237.261398,0.006821,0.001111,0.028219,23.050413,1.174244,0.282194,-237.261398,0.029121,0.000000
27.410002,5.380783,-237.261398,0.006860,0.001131,0.028731,23.934919,1.219303,0.287311,-237.261398,0.029555,0.000000
27.670002,5.348015,-237.261398,0.006842,0.001147,0.029130,23.789158,1.211877,0.291301,-237.261398,0.029989,0.000000
27.930002,5.343178,-237.216919,0.006864,0.001164,0.029573,23.767641,1.210781,0.295725,-237.216919,0.030422,0.000000
28.190001,5.387489,-237.305878,0.006898,0.001180,0.029971,23.964750,1.220822,0.299714,-237.305878,0.030856,0.000000
28.450001,5.517448,-237.261398,0.006877,0.001201,0.030501,24.542837,1.250272,0.305006,-237.261398,0.031290,0.000000
28.710001,5.426590,-237.261398,0.006903,0.001212,0.030778,24.138678,1.229683,0.307780,-237.261398,0.031723,0.000000
28.970001,5.471642,-237.305878,0.006911,0.001230,0.031237,24.339077,1.239892,0.312375,-237.305878,0.032157,0.000000
29.230001,5.582237,-237.216919,0.006946,0.001246,0.031636,24.831032,1.264953,0.316364,-237.216919,0.032591,0.000000
29.490002,5.873436,-237.305878,0.006946,0.001271,0.032278,26.126348,1.330940,0.322783,-237.305878,0.033024,0.000000
29.750002,5.731934,-237.305878,0.006954,0.001287,0.032686,25.496914,1.298875,0.326860,-237.305878,0.033458,0.000000
30.010002,5.599365,-237.305878,0.006972,0.001300,0.033024,24.907221,1.268834,0.330240,-237.305878,0.033891,0.000000
30.270002,5.614265,-237.350357,0.006967,0.001316,0.033423,24.973499,1.272211,0.334229,-237.350357,0.034325,0.000000
30.530001,5.826141,-237.350357,0.007023,0.001337,0.033969,25.915972,1.320222,0.339694,-237.350357,0.034759,0.000000
30.790001,5.743103,-237.394836,0.006998,0.001351,0.034325,25.546598,1.301406,0.343248,-237.394836,0.035192,0.000000
31.050001,5.710709,-237.350357,0.007002,0.001367,0.034724,25.402500,1.294065,0.347238,-237.350357,0.035626,0.000000
31.310001,5.902847,-237.394836,0.007045,0.001386,0.035192,26.257175,1.337604,0.351920,-237.394836,0.036051,0.000000
31.570002,5.933388,-237.350357,0.007041,0.001406,0.035712,26.393026,1.344525,0.357124,-237.350357,0.036484,0.000000
31.830002,5.855934,-237.350357,0.007041,0.001421,0.036085,26.048496,1.326974,0.360852,-237.350357,0.036918,0.000000
32.090000,5.806778,-237.394836,0.007071,0.001436,0.036475,25.829838,1.315835,0.364754,-237.394836,0.037352,0.000000
32.350002,5.966530,-237.394836,0.007075,0.001454,0.036935,26.540451,1.352035,0.369353,-237.394836,0.037785,0.000000
32.610001,6.005997,-237.394836,0.007101,0.001471,0.037360,26.716007,1.360978,0.373603,-237.394836,0.038219,0.000000
32.870003,5.808640,-237.350357,0.007114,0.001480,0.037603,25.838120,1.316257,0.376029,-237.350357,0.038652,0.000000
33.130001,6.013817,-237.394836,0.007127,0.001503,0.038167,26.750793,1.362750,0.381665,-237.394836,0.039086,0.000000
33.390003,6.113617,-237.394836,0.007127,0.001522,0.038652,27.194727,1.385365,0.386525,-237.394836,0.039520,0.000000
33.650002,6.132233,-237.439316,0.007136,0.001540,0.039121,27.277533,1.389584,0.391207,-237.439316,0.039953,0.000000
33.910000,6.092758,-237.394836,0.007140,0.001556,0.039528,27.101942,1.380639,0.395283,-237.394836,0.040387,0.000000
34.170002,6.022385,-237.439316,0.007157,0.001572,0.039919,26.788904,1.364692,0.399185,-237.439316,0.040820,0.000000
34.430000,6.105049,-237.439316,0.007192,0.001588,0.040326,27.156614,1.383424,0.403262,-237.439316,0.041254,0.000000
34.690002,6.116219,-237.528275,0.007183,0.001606,0.040794,27.206299,1.385955,0.407944,-237.528275,0.041688,0.000000
34.950001,6.207077,-237.394836,0.007213,0.001622,0.041211,27.610458,1.406544,0.412107,-237.394836,0.042121,0.000000
35.210003,6.217133,-237.483795,0.007217,0.001642,0.041705,27.655188,1.408822,0.417050,-237.483795,0.042555,0.000000
35.470001,6.259956,-237.439316,0.007230,0.001659,0.042147,27.845676,1.418526,0.421471,-237.439316,0.042988,0.000000
35.730003,6.163887,-237.528275,0.007243,0.001674,0.042512,27.418339,1.396757,0.425116,-237.528275,0.043422,0.000000
35.990002,6.158295,-237.483795,0.007243,0.001689,0.042893,27.393463,1.395490,0.428931,-237.483795,0.043856,0.000000
36.250000,6.269264,-237.528275,0.007248,0.001707,0.043361,27.887079,1.420636,0.433613,-237.528275,0.044289,0.000000
36.510002,6.241707,-237.483795,0.007256,0.001722,0.043734,27.764500,1.414391,0.437345,-237.483795,0.044723,0.000000
36.770000,6.227188,-237.483795,0.007269,0.001736,0.044090,27.699917,1.411101,0.440899,-237.483795,0.045156,0.000000
37.030003,6.490082,-237.528275,0.007312,0.001759,0.044688,28.869326,1.470674,0.446883,-237.528275,0.045590,0.000000
37.290001,6.578331,-237.528275,0.007317,0.001783,0.045278,29.261877,1.490671,0.452779,-237.528275,0.046024,0.000000
37.550003,6.394012,-237.528275,0.007338,0.001796,0.045608,28.441988,1.448904,0.456076,-237.528275,0.046457,0.000000
37.810001,6.325493,-237.572754,0.007330,0.001811,0.045998,28.137197,1.433377,0.459978,-237.572754,0.046891,0.000000
38.070004,6.245804,-237.528275,0.007334,0.001825,0.046353,27.782722,1.415319,0.463532,-237.528275,0.047324,0.000000
38.330002,6.546684,-237.528275,0.007360,0.001846,0.046900,29.121105,1.483500,0.468998,-237.528275,0.047758,0.000000
38.590000,6.461037,-237.572754,0.007360,0.001860,0.047238,28.740126,1.464092,0.472378,-237.572754,0.048192,0.000000
38.850002,6.561577,-237.617233,0.007390,0.001878,0.047706,29.187351,1.486874,0.477063,-237.617233,0.048625,0.000000
39.110001,6.608871,-237.572754,0.007394,0.001898,0.048218,29.397728,1.497592,0.482177,-237.572754,0.049059,0.000000
39.370003,6.563065,-237.528275,0.007416,0.001915,0.048643,29.193970,1.487212,0.486427,-237.528275,0.049493,0.000000
39.630001,6.529922,-237.661728,0.007411,0.001930,0.049024,29.046545,1.479702,0.490242,-237.661728,0.049926,0.000000
39.890003,6.548546,-237.617233,0.007424,0.001946,0.049423,29.129387,1.483922,0.494232,-237.617233,0.050360,0.000000
40.150002,6.675522,-237.572754,0.007446,0.001965,0.049909,29.694204,1.512695,0.499088,-237.572754,0.050794,0.000000
40.410004,6.704193,-237.661728,0.007459,0.001982,0.050334,29.821741,1.519192,0.503338,-237.661728,0.051218,0.000000
40.670002,6.539604,-237.661728,0.007472,0.001994,0.050637,29.089613,1.481895,0.506374,-237.661728,0.051652,0.000000
40.930000,6.716110,-237.661728,0.007506,0.002013,0.051132,29.874750,1.521892,0.511317,-237.661728,0.052086,0.000000
41.190002,6.846069,-237.661728,0.007493,0.002033,0.051643,30.452837,1.551341,0.516434,-237.661728,0.052519,0.000000
41.450001,6.814789,-237.661728,0.007502,0.002050,0.052077,30.313694,1.544253,0.520771,-237.661728,0.052953,0.000000
41.710003,6.683342,-237.706207,0.007524,0.002065,0.052441,29.728991,1.514467,0.524412,-237.706207,0.053386,0.000000
41.970001,6.734360,-237.617233,0.007519,0.002081,0.052866,29.955929,1.526028,0.528663,-237.617233,0.053820,0.000000
42.230003,6.903786,-237.706207,0.007528,0.002103,0.053404,30.709572,1.564420,0.534037,-237.706207,0.054254,0.000000
42.490002,6.666214,-237.661728,0.007549,0.002112,0.053655,29.652802,1.510586,0.536554,-237.661728,0.054687,0.000000
42.750004,6.932831,-237.661728,0.007567,0.002134,0.054210,30.838772,1.571002,0.542103,-237.661728,0.055121,0.000000
43.010002,7.016991,-237.750687,0.007567,0.002153,0.054687,31.213133,1.590073,0.546872,-237.750687,0.055555,0.000000
43.270000,6.962250,-237.706207,0.007584,0.002171,0.055138,30.969633,1.577668,0.551383,-237.706207,0.055988,0.000000
43.530003,6.973045,-237.750687,0.007623,0.002188,0.055572,31.017654,1.580115,0.555717,-237.750687,0.056422,0.000000
43.790001,6.919052,-237.706207,0.007601,0.002204,0.055988,30.777481,1.567880,0.559881,-237.706207,0.056856,0.000000
44.050003,7.047897,-237.706207,0.007610,0.002223,0.056457,31.350613,1.597076,0.564566,-237.706207,0.057289,0.000000
44.310001,6.964859,-237.706207,0.007627,0.002236,0.056795,30.981239,1.578260,0.567946,-237.706207,0.057723,0.000000
44.570004,6.958900,-237.706207,0.007640,0.002251,0.057167,30.954735,1.576909,0.571674,-237.706207,0.058156,0.000000
44.830002,6.930229,-237.795166,0.007653,0.002266,0.057558,30.827200,1.570412,0.575580,-237.795166,0.058590,0.000000
45.090004,7.268341,-237.706207,0.007679,0.002292,0.058226,32.331196,1.647030,0.582257,-237.706207,0.059024,0.000000
45.350002,7.143967,-237.706207,0.007687,0.002308,0.058625,31.777950,1.618846,0.586246,-237.706207,0.059457,0.000000
45.610001,7.120132,-237.795166,0.007692,0.002325,0.059050,31.671930,1.613445,0.590497,-237.795166,0.059891,0.000000
45.870003,7.184555,-237.750687,0.007709,0.002344,0.059527,31.958496,1.628044,0.595266,-237.750687,0.060324,0.000000
46.130001,7.143227,-237.884125,0.007713,0.002359,0.059908,31.774658,1.618678,0.599081,-237.884125,0.060758,0.000000
46.390003,7.097794,-237.750687,0.007713,0.002371,0.060229,31.572563,1.608383,0.602290,-237.750687,0.061192,0.000000
46.650002,7.026299,-237.795166,0.007731,0.002384,0.060558,31.254538,1.592182,0.605583,-237.795166,0.061625,0.000000
46.910004,7.385635,-237.839645,0.007748,0.002408,0.061157,32.852947,1.673609,0.611567,-237.839645,0.062059,0.000000
47.170002,7.372231,-237.795166,0.007756,0.002426,0.061608,32.793320,1.670571,0.616079,-237.795166,0.062492,0.000000
47.430004,7.350266,-237.884125,0.007752,0.002443,0.062041,32.695614,1.665594,0.620412,-237.884125,0.062926,0.000000
47.690002,7.389359,-237.839645,0.007778,0.002461,0.062501,32.869507,1.674453,0.625011,-237.839645,0.063360,0.000000
47.950001,7.491394,-237.839645,0.007808,0.002481,0.063013,33.323383,1.697574,0.630128,-237.839645,0.063793,0.000000
48.210003,7.304459,-237.884125,0.007804,0.002491,0.063282,32.491856,1.655214,0.632816,-237.884125,0.064227,0.000000
48.470001,7.407982,-237.795166,0.007800,0.002510,0.063750,32.952351,1.678673,0.637497,-237.795166,0.064660,0.000000
48.730003,7.592308,-237.884125,0.007825,0.002530,0.064261,33.772274,1.720442,0.642615,-237.884125,0.065094,0.000000
48.990002,7.510384,-237.884125,0.007843,0.002545,0.064652,33.407856,1.701877,0.646517,-237.884125,0.065528,0.000000
49.250004,7.466812,-237.884125,0.007834,0.002562,0.065068,33.214039,1.692004,0.650680,-237.884125,0.065953,0.000000
49.510002,7.533096,-237.839645,0.007894,0.002578,0.065493,33.508884,1.707024,0.654931,-237.839645,0.066386,0.000000
49.770000,7.654861,-237.884125,0.007864,0.002600,0.066031,34.050526,1.734616,0.660305,-237.884125,0.066820,0.000000
50.030003,7.545387,-237.973083,0.007903,0.002611,0.066317,33.563560,1.709809,0.663167,-237.973083,0.067253,0.000000
50.290001,7.672363,-237.839645,0.007916,0.002629,0.066777,34.128376,1.738582,0.667765,-237.839645,0.067687,0.000000
50.550003,7.645180,-237.884125,0.007912,0.002643,0.067132,34.007458,1.732423,0.671319,-237.884125,0.068121,0.000000
50.810001,8.075272,-237.928604,0.007925,0.002670,0.067808,35.920601,1.829883,0.678083,-237.928604,0.068554,0.000000
51.070004,7.905098,-237.928604,0.007950,0.002685,0.068207,35.163631,1.791321,0.682072,-237.928604,0.068988,0.000000
51.330002,7.746841,-237.928604,0.007972,0.002699,0.068546,34.459671,1.755459,0.685456,-237.928604,0.069421,0.000000
51.590004,7.751305,-237.884125,0.007955,0.002714,0.068945,34.479527,1.756471,0.689445,-237.884125,0.069855,0.000000
51.850002,8.023140,-237.973083,0.007976,0.002736,0.069482,35.688709,1.818069,0.694823,-237.973083,0.070289,0.000000
52.110001,7.937492,-237.973083,0.007976,0.002750,0.069838,35.307728,1.798661,0.698377,-237.973083,0.070722,0.000000
52.370003,7.971748,-237.928604,0.007994,0.002767,0.070271,35.460106,1.806424,0.702715,-237.928604,0.071156,0.000000
52.630001,8.160919,-238.017563,0.008015,0.002784,0.070714,36.301582,1.849291,0.707136,-238.017563,0.071589,0.000000
52.890003,8.251404,-237.973083,0.007994,0.002805,0.071251,36.704079,1.869795,0.712514,-237.973083,0.072023,0.000000
53.150002,8.136711,-238.017563,0.008024,0.002820,0.071616,36.193897,1.843805,0.716155,-238.017563,0.072457,0.000000
53.410004,8.066704,-238.017563,0.008028,0.002835,0.071997,35.882492,1.827941,0.719970,-238.017563,0.072890,0.000000
53.670002,8.303162,-238.017563,0.008058,0.002853,0.072457,36.934307,1.881523,0.724569,-238.017563,0.073324,0.000000
53.930004,8.389557,-238.017563,0.008058,0.002869,0.072882,37.318611,1.901101,0.728816,-238.017563,0.073758,0.000000
54.190002,8.161659,-237.973083,0.008084,0.002879,0.073125,36.304874,1.849458,0.731246,-237.973083,0.074191,0.000000
54.450001,8.509460,-238.062057,0.008071,0.002901,0.073679,37.851971,1.928271,0.736794,-238.062057,0.074625,0.000000
54.710003,8.677773,-238.062057,0.008088,0.002920,0.074174,38.600658,1.966411,0.741737,-238.062057,0.075059,0.000000
54.970001,8.749268,-238.017563,0.008132,0.002939,0.074642,38.918686,1.982612,0.746423,-238.017563,0.075492,0.000000
55.230003,8.744423,-238.017563,0.008097,0.002955,0.075050,38.897137,1.981515,0.750499,-238.017563,0.075926,0.000000
55.490002,8.678886,-238.017563,0.008123,0.002970,0.075431,38.605614,1.966664,0.754314,-238.017563,0.076359,0.000000
55.750004,8.867310,-238.106537,0.008140,0.002986,0.075848,39.443764,2.009361,0.758478,-238.106537,0.076793,0.000000
56.010002,8.942154,-238.062057,0.008119,0.003004,0.076307,39.776688,2.026321,0.763073,-238.062057,0.077227,0.000000
56.270004,9.073975,-238.106537,0.008179,0.003021,0.076732,40.363056,2.056192,0.767323,-238.106537,0.077660,0.000000
56.530003,9.165581,-238.106537,0.008175,0.003040,0.077227,40.770538,2.076950,0.772266,-238.106537,0.078094,0.000000
56.790001,9.345062,-238.062057,0.008175,0.003059,0.077695,41.568913,2.117621,0.776948,-238.062057,0.078527,0.000000
57.050003,9.266861,-238.195496,0.008192,0.003072,0.078024,41.221058,2.099901,0.780245,-238.195496,0.078961,0.000000
57.310001,9.348412,-238.151016,0.008179,0.003087,0.078406,41.583813,2.118380,0.784060,-238.151016,0.079395,0.000000
57.570004,9.550240,-238.106537,0.008239,0.003104,0.078831,42.481586,2.164115,0.788310,-238.106537,0.079828,0.000000
57.830002,9.680199,-238.106537,0.008252,0.003120,0.079256,43.059673,2.193564,0.792557,-238.106537,0.080262,0.000000
58.090004,9.685410,-238.106537,0.008257,0.003134,0.079611,43.082855,2.194745,0.796115,-238.106537,0.080695,0.000000
58.350002,10.108055,-238.195496,0.008269,0.003158,0.080210,44.962875,2.290518,0.802099,-238.195496,0.081121,0.000000
58.610004,10.460320,-238.062057,0.008282,0.003181,0.080791,46.529823,2.370342,0.807909,-238.062057,0.081554,0.000000
58.870003,10.315834,-238.151016,0.008300,0.003194,0.081129,45.887123,2.337601,0.811292,-238.151016,0.081988,0.000000
59.130001,10.296844,-238.195496,0.008317,0.003209,0.081519,45.802650,2.333298,0.815194,-238.195496,0.082421,0.000000
59.390003,10.194817,-238.106537,0.008308,0.003220,0.081788,45.348808,2.310178,0.817882,-238.106537,0.082855,0.000000
59.650002,10.283440,-238.195496,0.008321,0.003232,0.082083,45.743023,2.330261,0.820830,-238.195496,0.083289,0.000000
59.910004,10.922806,-238.151016,0.008330,0.003258,0.082759,48.587067,2.475143,0.827594,-238.151016,0.083722,0.000000
60.170002,11.114204,-238.195496,0.008360,0.003276,0.083219,49.438450,2.518515,0.832192,-238.195496,0.084156,0.000000
60.430004,11.382683,-238.195496,0.008373,0.003296,0.083731,50.632702,2.579353,0.837306,-238.195496,0.084589,0.000000
60.690002,11.492531,-238.195496,0.008395,0.003315,0.084190,51.121330,2.604245,0.841904,-238.195496,0.085023,0.000000
60.950005,11.531631,-238.239975,0.008386,0.003329,0.084563,51.295258,2.613105,0.845633,-238.239975,0.085456,0.000000
61.210003,11.692123,-238.195496,0.008390,0.003345,0.084971,52.009163,2.649473,0.849709,-238.195496,0.085890,0.000000
61.470001,11.998962,-238.195496,0.008425,0.003364,0.085439,53.374050,2.719004,0.854391,-238.195496,0.086324,0.000000
61.730003,12.169136,-238.195496,0.008451,0.003379,0.085838,54.131020,2.757566,0.858380,-238.195496,0.086757,0.000000
61.990002,12.195198,-238.239975,0.008451,0.003393,0.086176,54.246952,2.763472,0.861764,-238.239975,0.087191,0.000000
62.250004,12.594757,-238.239975,0.008442,0.003412,0.086662,56.024277,2.854013,0.866620,-238.239975,0.087624,0.000000
62.510002,13.119431,-238.195496,0.008455,0.003432,0.087165,58.358143,2.972905,0.871650,-238.195496,0.088058,0.000000
62.770004,13.212151,-238.284454,0.008498,0.003448,0.087581,58.770580,2.993916,0.875813,-238.284454,0.088492,0.000000
63.030003,13.260559,-238.239975,0.008459,0.003463,0.087963,58.985912,3.004886,0.879629,-238.239975,0.088925,0.000000
63.290005,13.495895,-238.239975,0.008494,0.003479,0.088379,60.032742,3.058214,0.883792,-238.239975,0.089359,0.000000
63.550003,14.009026,-238.328934,0.008520,0.003500,0.088899,62.315258,3.174490,0.888992,-238.328934,0.089792,0.000000
63.810001,13.810181,-238.239975,0.008545,0.003510,0.089151,61.430752,3.129432,0.891509,-238.239975,0.090226,0.000000
64.070000,14.559395,-238.284454,0.008558,0.003532,0.089723,64.763420,3.299206,0.897232,-238.284454,0.090660,0.000000
64.330002,14.877769,-238.328934,0.008571,0.003551,0.090191,66.179626,3.371351,0.901914,-238.328934,0.091093,0.000000
64.590004,15.185722,-238.373413,0.008580,0.003567,0.090608,67.549469,3.441134,0.906077,-238.373413,0.091527,0.000000
64.850006,15.609108,-238.328934,0.008584,0.003586,0.091085,69.432777,3.537074,0.910846,-238.328934,0.091961,0.000000
65.110001,15.774445,-238.328934,0.008601,0.003602,0.091501,70.168236,3.574540,0.915010,-238.328934,0.092394,0.000000
65.370003,16.115166,-238.328934,0.008623,0.003619,0.091917,71.683838,3.651749,0.919173,-238.328934,0.092828,0.000000
65.630005,16.372475,-238.373413,0.008614,0.003633,0.092273,72.828407,3.710056,0.922727,-238.373413,0.093262,0.000000
65.889999,16.683037,-238.373413,0.008653,0.003648,0.092672,74.209854,3.780430,0.926716,-238.373413,0.093695,0.000000
66.150002,16.904221,-238.373413,0.008666,0.003664,0.093062,75.193726,3.830551,0.930622,-238.373413,0.094129,0.000000
66.410004,18.213112,-238.328934,0.008692,0.003692,0.093764,81.015968,4.127150,0.937643,-238.328934,0.094562,0.000000
66.670006,18.319984,-238.417892,0.008701,0.003706,0.094129,81.491364,4.151368,0.941288,-238.417892,0.094996,0.000000
66.930000,18.648788,-238.417892,0.008709,0.003723,0.094554,82.953957,4.225876,0.945539,-238.417892,0.095430,0.000000
67.190002,19.229317,-238.417892,0.008722,0.003741,0.095031,85.536270,4.357426,0.950308,-238.417892,0.095863,0.000000
67.450005,19.453110,-238.417892,0.008735,0.003756,0.095404,86.531754,4.408138,0.954036,-238.417892,0.096288,0.000000
67.710007,19.780426,-238.373413,0.008735,0.003770,0.095751,87.987732,4.482309,0.957507,-238.373413,0.096722,0.000000
67.970001,20.001991,-238.373413,0.008765,0.003782,0.096054,88.973297,4.532516,0.960538,-238.373413,0.097155,0.000000
68.230003,21.164536,-238.417892,0.008739,0.003806,0.096661,94.144554,4.795952,0.966609,-238.417892,0.097589,0.000000
68.490005,21.714157,-238.417892,0.008800,0.003824,0.097138,96.589394,4.920498,0.971382,-238.417892,0.098023,0.000000
68.750000,22.132706,-238.462372,0.008795,0.003841,0.097563,98.451195,5.015343,0.975629,-238.462372,0.098456,0.000000
69.010002,22.833511,-238.417892,0.008808,0.003859,0.098023,101.568535,5.174148,0.980227,-238.417892,0.098890,0.000000
69.270004,23.484413,-238.462372,0.008834,0.003878,0.098508,104.463890,5.321644,0.985083,-238.462372,0.099324,0.000000
69.530006,23.760719,-238.417892,0.008852,0.003890,0.098803,105.692955,5.384256,0.988032,-238.417892,0.099757,0.000000
69.790001,24.355392,-238.462372,0.008847,0.003907,0.099237,108.338196,5.519011,0.992365,-238.462372,0.100191,0.000000
70.050003,25.497093,-238.506866,0.008860,0.003929,0.099800,113.416733,5.777724,0.998005,-238.506866,0.100624,0.000000
70.310005,25.950264,-238.417892,0.008869,0.003943,0.100156,115.432541,5.880414,1.001559,-238.417892,0.101058,0.000000
70.570000,26.555374,-238.506866,0.008895,0.003962,0.100633,118.124207,6.017534,1.006328,-238.506866,0.101492,0.000000
70.830002,27.242401,-238.417892,0.008921,0.003977,0.101015,121.180252,6.173216,1.010147,-238.417892,0.101925,0.000000
71.090004,28.105560,-238.506866,0.008921,0.003998,0.101552,125.019775,6.368811,1.015521,-238.506866,0.102359,0.000000
71.350006,28.597092,-238.506866,0.008933,0.004008,0.101813,127.206215,6.480194,1.018125,-238.506866,0.102792,0.000000
71.610001,29.351891,-238.506866,0.008929,0.004027,0.102289,130.563736,6.651234,1.022894,-238.506866,0.103226,0.000000
71.870003,29.870232,-238.506866,0.008959,0.004041,0.102645,132.869431,6.768692,1.026448,-238.506866,0.103660,0.000000
72.130005,31.740662,-238.462372,0.008968,0.004067,0.103304,141.189514,7.192536,1.033042,-238.462372,0.104093,0.000000
72.390007,32.453011,-238.506866,0.009020,0.004083,0.103720,144.358200,7.353958,1.037201,-238.506866,0.104527,0.000000
72.650002,32.931137,-238.551346,0.008990,0.004096,0.104050,146.485016,7.462302,1.040498,-238.551346,0.104960,0.000000
72.910004,33.769714,-238.551346,0.009020,0.004112,0.104457,150.215195,7.652327,1.044574,-238.551346,0.105394,0.000000
73.170006,35.043602,-238.640305,0.009020,0.004134,0.104995,155.881729,7.940994,1.049953,-238.640305,0.105828,0.000000
73.430000,35.656525,-238.551346,0.009050,0.004147,0.105342,158.608139,8.079884,1.053420,-238.551346,0.106261,0.000000
73.690002,36.029274,-238.595825,0.009063,0.004159,0.105637,160.266220,8.164351,1.056368,-238.595825,0.106695,0.000000
73.950005,37.919060,-238.595825,0.009076,0.004182,0.106226,168.672409,8.592582,1.062265,-238.595825,0.107128,0.000000
74.210007,39.130386,-238.551346,0.009089,0.004202,0.106729,174.060654,8.867072,1.067295,-238.551346,0.107562,0.000000
74.470001,39.964134,-238.640305,0.009076,0.004217,0.107120,177.769348,9.056003,1.071197,-238.640305,0.107996,0.000000
74.730003,40.812027,-238.595825,0.009093,0.004231,0.107458,181.540970,9.248137,1.074581,-238.595825,0.108429,0.000000
74.990005,41.999893,-238.595825,0.009123,0.004250,0.107961,186.824860,9.517312,1.079611,-238.595825,0.108863,0.000000
75.250000,43.228722,-238.595825,0.009110,0.004267,0.108394,192.290955,9.795769,1.083945,-238.595825,0.109296,0.000000
75.510002,43.938835,-238.640305,0.009140,0.004278,0.108655,195.449707,9.956682,1.086549,-238.640305,0.109730,0.000000
75.770004,45.018341,-238.640305,0.009149,0.004295,0.109097,200.251587,10.201303,1.090969,-238.640305,0.110164,0.000000
76.030006,46.858978,-238.595825,0.009158,0.004318,0.109678,208.439148,10.618397,1.096779,-238.595825,0.110597,0.000000
76.290001,47.864388,-238.640305,0.009175,0.004334,0.110086,212.911423,10.846226,1.100856,-238.640305,0.111022,0.000000
76.550003,49.197479,-238.640305,0.009179,0.004352,0.110537,218.841324,11.148308,1.105367,-238.640305,0.111456,0.000000
76.810005,50.242729,-238.640305,0.009205,0.004366,0.110901,223.490814,11.385165,1.109008,-238.640305,0.111889,0.000000
77.070007,51.871483,-238.684784,0.009227,0.004385,0.111369,230.735886,11.754247,1.113690,-238.684784,0.112323,0.000000
77.330002,52.973335,-238.640305,0.009227,0.004402,0.111803,235.637161,12.003929,1.118028,-238.640305,0.112757,0.000000
77.590004,53.900917,-238.729263,0.009231,0.004415,0.112150,239.763260,12.214123,1.121498,-238.729263,0.113190,0.000000
77.850006,55.906143,-238.684784,0.009227,0.004436,0.112679,248.682938,12.668513,1.126786,-238.684784,0.113624,0.000000
78.110001,57.317062,-238.640305,0.009261,0.004455,0.113147,254.959030,12.988233,1.131472,-238.640305,0.114057,0.000000
78.370003,58.148941,-238.729263,0.009253,0.004468,0.113485,258.659393,13.176739,1.134852,-238.729263,0.114491,0.000000
78.630005,59.372559,-238.729263,0.009283,0.004483,0.113858,264.102325,13.454014,1.138580,-238.729263,0.114925,0.000000
78.890007,60.576813,-238.818222,0.009300,0.004500,0.114309,269.459106,13.726902,1.143091,-238.818222,0.115358,0.000000
79.150002,62.384308,-238.684784,0.009309,0.004518,0.114760,277.499268,14.136486,1.147599,-238.684784,0.115792,0.000000
79.410004,63.637337,-238.729263,0.009291,0.004532,0.115124,283.072998,14.420426,1.151244,-238.729263,0.116226,0.000000
79.670006,65.147682,-238.773743,0.009321,0.004551,0.115601,289.791351,14.762676,1.156013,-238.773743,0.116659,0.000000
79.930000,67.578529,-238.773743,0.009356,0.004573,0.116156,300.604309,15.313514,1.161562,-238.773743,0.117076,0.000000
80.190002,67.178978,-238.773743,0.009347,0.004569,0.116043,298.827026,15.222974,1.160434,-238.773743,0.116235,0.000000
80.450005,66.847191,-238.818222,0.009369,0.004568,0.116035,297.351166,15.147790,1.160350,-238.818222,0.116035,0.000000
80.710007,66.589134,-238.729263,0.009360,0.004568,0.116035,296.203278,15.089314,1.160350,-238.729263,0.116035,0.000000
80.970001,66.340019,-238.773743,0.009352,0.004568,0.116026,295.095154,15.032864,1.160263,-238.773743,0.116035,0.000000
81.230003,66.131859,-238.773743,0.009360,0.004568,0.116026,294.169189,14.985694,1.160263,-238.773743,0.116035,0.000000
81.490005,65.938606,-238.818222,0.009382,0.004568,0.116026,293.309570,14.941902,1.160263,-238.818222,0.116035,0.000000
81.750008,65.791893,-238.773743,0.009386,0.004568,0.116018,292.656952,14.908656,1.160176,-238.773743,0.116035,0.000000
82.010002,65.636604,-238.773743,0.009352,0.004568,0.116018,291.966187,14.873467,1.160176,-238.773743,0.116035,0.000000
82.270004,65.491753,-238.862701,0.009386,0.004568,0.116018,291.321869,14.840643,1.160176,-238.862701,0.116035,0.000000
82.530006,65.374458,-238.818222,0.009369,0.004568,0.116018,290.800110,14.814064,1.160176,-238.818222,0.116035,0.000000
82.790001,65.252312,-238.818222,0.009386,0.004568,0.116018,290.256775,14.786386,1.160176,-238.818222,0.116035,0.000000
83.050003,65.127953,-238.818222,0.009365,0.004568,0.116018,289.703613,14.758204,1.160176,-238.818222,0.116035,0.000000
83.310005,65.024803,-238.862701,0.009403,0.004568,0.116018,289.244781,14.734831,1.160176,-238.862701,0.116035,0.000000
83.570007,64.940269,-238.862701,0.009399,0.004568,0.116018,288.868744,14.715675,1.160176,-238.862701,0.116035,0.000000
83.830002,64.841957,-238.818222,0.009382,0.004568,0.116018,288.431427,14.693397,1.160176,-238.818222,0.116035,0.000000
84.090004,64.755943,-238.862701,0.009399,0.004568,0.116018,288.048828,14.673906,1.160176,-238.862701,0.116035,0.000000
84.350006,64.679604,-238.862701,0.009399,0.004568,0.116018,287.709259,14.656608,1.160176,-238.862701,0.116035,0.000000
84.610001,64.599922,-238.818222,0.009403,0.004568,0.116018,287.354797,14.638552,1.160176,-238.818222,0.116035,0.000000
84.870003,64.530663,-238.907181,0.009378,0.004568,0.116018,287.046722,14.622857,1.160176,-238.907181,0.116035,0.000000
85.130005,64.469597,-238.907181,0.009395,0.004568,0.116018,286.775085,14.609019,1.160176,-238.907181,0.116035,0.000000
85.390007,64.397346,-238.907181,0.009390,0.004568,0.116018,286.453705,14.592648,1.160176,-238.907181,0.116035,0.000000
85.650002,64.332191,-238.907181,0.009382,0.004568,0.116018,286.163879,14.577883,1.160176,-238.907181,0.116035,0.000000
85.910004,64.277824,-238.907181,0.009382,0.004568,0.116018,285.922058,14.565563,1.160176,-238.907181,0.116035,0.000000
86.170006,64.231651,-238.951675,0.009412,0.004568,0.116018,285.716644,14.555099,1.160176,-238.951675,0.116035,0.000000
86.430000,64.156059,-238.951675,0.009386,0.004567,0.116009,285.380402,14.537971,1.160089,-238.951675,0.116035,0.000000
86.690002,64.115837,-238.951675,0.009403,0.004567,0.116009,285.201477,14.528856,1.160089,-238.951675,0.116035,0.000000
86.950005,64.062584,-238.951675,0.009395,0.004567,0.116009,284.964600,14.516789,1.160089,-238.951675,0.116035,0.000000
87.210007,64.002266,-238.951675,0.009399,0.004567,0.116009,284.696289,14.503120,1.160089,-238.951675,0.116035,0.000000
87.470001,63.971733,-238.996155,0.009395,0.004567,0.116009,284.560486,14.496202,1.160089,-238.996155,0.116035,0.000000
87.730003,63.922569,-238.907181,0.009408,0.004567,0.116009,284.341797,14.485061,1.160089,-238.907181,0.116035,0.000000
87.990005,63.873421,-239.040634,0.009382,0.004567,0.116009,284.123169,14.473924,1.160089,-239.040634,0.116035,0.000000
88.250008,63.833580,-238.907181,0.009408,0.004567,0.116009,283.945953,14.464896,1.160089,-238.907181,0.116035,0.000000
88.510002,63.798943,-238.951675,0.009408,0.004567,0.116009,283.791870,14.457047,1.160089,-238.951675,0.116035,0.000000
88.770004,63.732292,-239.085114,0.009408,0.004567,0.116009,283.495392,14.441944,1.160089,-239.085114,0.116035,0.000000
89.030006,63.712181,-238.996155,0.009408,0.004567,0.116009,283.405945,14.437387,1.160089,-238.996155,0.116035,0.000000
89.290001,63.686867,-239.040634,0.009399,0.004567,0.116009,283.293335,14.431650,1.160089,-239.040634,0.116035,0.000000
89.550003,63.612755,-238.951675,0.009373,0.004567,0.116009,282.963654,14.414856,1.160089,-238.951675,0.116035,0.000000
89.810005,63.604942,-239.040634,0.009412,0.004567,0.116009,282.928925,14.413086,1.160089,-239.040634,0.116035,0.000000
90.070007,63.567329,-238.996155,0.009421,0.004567,0.116009,282.761597,14.404563,1.160089,-238.996155,0.116035,0.000000
90.330002,63.518547,-238.996155,0.009408,0.004567,0.116009,282.544617,14.393509,1.160089,-238.996155,0.116035,0.000000
90.590004,63.498817,-239.040634,0.009416,0.004567,0.116009,282.456848,14.389038,1.160089,-239.040634,0.116035,0.000000
90.850006,63.461952,-238.996155,0.009408,0.004567,0.116009,282.292877,14.380684,1.160089,-238.996155,0.116035,0.000000
91.110001,63.420250,-239.085114,0.009416,0.004567,0.116009,282.107361,14.371234,1.160089,-239.085114,0.116035,0.000000
91.370003,63.412422,-239.040634,0.009412,0.004567,0.116009,282.072540,14.369460,1.160089,-239.040634,0.116035,0.000000
91.630005,63.364769,-239.085114,0.009429,0.004567,0.116009,281.860565,14.358663,1.160089,-239.085114,0.116035,0.000000
91.890007,63.326775,-239.129593,0.009390,0.004567,0.116009,281.691559,14.350053,1.160089,-239.129593,0.116035,0.000000
92.150002,63.318214,-239.040634,0.009390,0.004567,0.116009,281.653473,14.348112,1.160089,-239.040634,0.116035,0.000000
92.410004,63.272789,-239.174072,0.009421,0.004567,0.116009,281.451416,14.337819,1.160089,-239.174072,0.116035,0.000000
92.670006,63.259010,-239.085114,0.009421,0.004567,0.116009,281.390137,14.334697,1.160089,-239.085114,0.116035,0.000000
92.930008,63.225868,-239.040634,0.009421,0.004567,0.116009,281.242706,14.327187,1.160089,-239.040634,0.116035,0.000000
93.190002,63.197197,-239.129593,0.009386,0.004567,0.116009,281.115173,14.320690,1.160089,-239.129593,0.116035,0.000000
93.450005,63.177086,-239.040634,0.009395,0.004567,0.116009,281.025726,14.316133,1.160089,-239.040634,0.116035,0.000000
93.710007,63.149910,-239.085114,0.009412,0.004567,0.116009,280.904816,14.309974,1.160089,-239.085114,0.116035,0.000000
93.970001,63.121605,-239.085114,0.009408,0.004567,0.116009,280.778931,14.303560,1.160089,-239.085114,0.116035,0.000000
94.230003,63.113411,-239.129593,0.009403,0.004567,0.116009,280.742462,14.301703,1.160089,-239.129593,0.116035,0.000000
94.490005,63.078773,-239.218552,0.009403,0.004567,0.116009,280.588409,14.293855,1.160089,-239.218552,0.116035,0.000000
94.750008,63.051971,-239.129593,0.009425,0.004567,0.116009,280.469177,14.287781,1.160089,-239.129593,0.116035,0.000000
95.010002,63.048248,-239.174072,0.009395,0.004567,0.116009,280.452606,14.286938,1.160089,-239.174072,0.116035,0.000000
95.270004,63.005424,-239.174072,0.009403,0.004567,0.116009,280.262115,14.277233,1.160089,-239.174072,0.116035,0.000000
95.530006,63.000954,-239.174072,0.009425,0.004567,0.116009,280.242249,14.276220,1.160089,-239.174072,0.116035,0.000000
95.790001,62.968933,-239.218552,0.009408,0.004567,0.116009,280.099792,14.268964,1.160089,-239.218552,0.116035,0.000000
96.050003,62.953293,-239.174072,0.009412,0.004567,0.116009,280.030243,14.265420,1.160089,-239.174072,0.116035,0.000000
96.310005,62.942863,-239.218552,0.009386,0.004567,0.116009,279.983826,14.263057,1.160089,-239.218552,0.116035,0.000000
96.570007,62.905258,-239.218552,0.009399,0.004567,0.116009,279.816559,14.254536,1.160089,-239.218552,0.116035,0.000000
96.830002,62.901161,-239.218552,0.009425,0.004567,0.116009,279.798340,14.253607,1.160089,-239.218552,0.116035,0.000000
97.090004,62.875839,-239.218552,0.009403,0.004567,0.116009,279.685699,14.247869,1.160089,-239.218552,0.116035,0.000000
97.350006,62.853493,-239.218552,0.009403,0.004567,0.116009,279.586304,14.242805,1.160089,-239.218552,0.116035,0.000000
97.610008,62.851257,-239.174072,0.009416,0.004567,0.116009,279.576355,14.242299,1.160089,-239.174072,0.116035,0.000000
97.870003,62.818123,-239.263031,0.009429,0.004567,0.116009,279.428955,14.234790,1.160089,-239.263031,0.116035,0.000000
98.130005,62.813278,-239.218552,0.009425,0.004567,0.116009,279.407410,14.233692,1.160089,-239.218552,0.116035,0.000000
98.390007,62.810669,-239.263031,0.009403,0.004567,0.116009,279.395813,14.233101,1.160089,-239.263031,0.116035,0.000000
98.650002,62.767105,-239.218552,0.009416,0.004567,0.116009,279.202026,14.223229,1.160089,-239.218552,0.116035,0.000000
98.910004,62.767105,-239.263031,0.009416,0.004567,0.116009,279.202026,14.223229,1.160089,-239.263031,0.116035,0.000000
99.170006,62.736946,-239.218552,0.009408,0.004567,0.116009,279.067871,14.216395,1.160089,-239.218552,0.116035,0.000000
99.430008,62.721306,-239.263031,0.009421,0.004567,0.116009,278.998291,14.212852,1.160089,-239.263031,0.116035,0.000000
99.690002,62.716461,-239.263031,0.009412,0.004567,0.116009,278.976746,14.211754,1.160089,-239.263031,0.116035,0.000000
99.950005,62.684807,-239.218552,0.009412,0.004567,0.116009,278.835937,14.204580,1.160089,-239.218552,0.116035,0.000000
100.210007,62.684807,-239.307510,0.009403,0.004567,0.116009,278.835937,14.204580,1.160089,-239.307510,0.116035,0.000000
100.470001,62.652039,-239.352005,0.009425,0.004567,0.116009,278.690186,14.197155,1.160089,-239.352005,0.116035,0.000000
100.730003,62.649437,-239.352005,0.009425,0.004567,0.116009,278.678619,14.196566,1.160089,-239.352005,0.116035,0.000000
100.990005,62.629326,-239.307510,0.009438,0.004567,0.116009,278.589142,14.192008,1.160089,-239.307510,0.116035,0.000000
101.250008,62.602142,-239.307510,0.009425,0.004567,0.116009,278.468231,14.185848,1.160089,-239.307510,0.116035,0.000000
101.510002,62.611084,-239.396484,0.009425,0.004567,0.116009,278.508026,14.187875,1.160089,-239.396484,0.116035,0.000000
101.770004,62.581291,-239.263031,0.009421,0.004567,0.116009,278.375488,14.181123,1.160089,-239.263031,0.116035,0.000000
102.030006,62.568626,-239.396484,0.009408,0.004567,0.116009,278.319153,14.178253,1.160089,-239.396484,0.116035,0.000000
102.290009,62.558578,-239.352005,0.009416,0.004567,0.116009,278.274445,14.175977,1.160089,-239.352005,0.116035,0.000000
102.550003,62.536606,-239.307510,0.009412,0.004567,0.116009,278.176727,14.170998,1.160089,-239.307510,0.116035,0.000000
102.810005,62.533630,-239.440964,0.009421,0.004567,0.116009,278.163483,14.170323,1.160089,-239.440964,0.116035,0.000000
103.070007,62.510170,-239.352005,0.009412,0.004567,0.116009,278.059113,14.165007,1.160089,-239.352005,0.116035,0.000000
103.330002,62.493782,-239.396484,0.009421,0.004567,0.116009,277.986237,14.161293,1.160089,-239.396484,0.116035,0.000000
103.590004,62.497131,-239.352005,0.009399,0.004567,0.116009,278.001129,14.162052,1.160089,-239.352005,0.116035,0.000000
103.850006,62.458038,-239.396484,0.009421,0.004567,0.116009,277.827240,14.153194,1.160089,-239.396484,0.116035,0.000000
104.110008,62.465485,-239.440964,0.009425,0.004567,0.116009,277.860352,14.154881,1.160089,-239.440964,0.116035,0.000000
104.370003,62.429733,-239.307510,0.009429,0.004567,0.116009,277.701324,14.146779,1.160089,-239.307510,0.116035,0.000000
104.630005,62.443512,-239.440964,0.009421,0.004567,0.116009,277.762604,14.149902,1.160089,-239.440964,0.116035,0.000000
104.890007,62.421173,-239.440964,0.009403,0.004567,0.116009,277.663239,14.144840,1.160089,-239.440964,0.116035,0.000000
105.150002,62.394730,-239.485443,0.009416,0.004567,0.116009,277.545624,14.138847,1.160089,-239.485443,0.116035,0.000000
105.410004,62.391006,-239.440964,0.009412,0.004567,0.116009,277.529053,14.138004,1.160089,-239.440964,0.116035,0.000000
105.670006,62.376488,-239.396484,0.009399,0.004567,0.116009,277.464478,14.134714,1.160089,-239.396484,0.116035,0.000000
105.930008,62.368294,-239.485443,0.009416,0.004567,0.116009,277.428040,14.132857,1.160089,-239.485443,0.116035,0.000000
106.190002,62.360100,-239.396484,0.009408,0.004567,0.116009,277.391571,14.131001,1.160089,-239.396484,0.116035,0.000000
106.450005,62.334038,-239.485443,0.009438,0.004567,0.116009,277.275635,14.125094,1.160089,-239.485443,0.116035,0.000000
106.710007,62.331429,-239.485443,0.009403,0.004567,0.116009,277.264038,14.124504,1.160089,-239.485443,0.116035,0.000000
106.970009,62.302757,-239.485443,0.009429,0.004567,0.116009,277.136505,14.118006,1.160089,-239.485443,0.116035,0.000000
107.230003,62.303131,-239.485443,0.009403,0.004567,0.116009,277.138184,14.118092,1.160089,-239.485443,0.116035,0.000000
107.490005,62.278923,-239.485443,0.009395,0.004567,0.116009,277.030487,14.112605,1.160089,-239.485443,0.116035,0.000000
107.750008,62.251366,-239.485443,0.009434,0.004567,0.116009,276.907898,14.106361,1.160089,-239.485443,0.116035,0.000000
108.010002,62.267754,-239.529922,0.009412,0.004567,0.116009,276.980804,14.110074,1.160089,-239.529922,0.116035,0.000000
108.270004,62.246529,-239.485443,0.009403,0.004567,0.116009,276.886383,14.105265,1.160089,-239.485443,0.116035,0.000000
108.530006,62.229027,-239.529922,0.009416,0.004567,0.116009,276.808533,14.101299,1.160089,-239.529922,0.116035,0.000000
108.790009,62.234985,-239.485443,0.009408,0.004567,0.116009,276.835052,14.102649,1.160089,-239.485443,0.116035,0.000000
109.050003,62.203331,-239.529922,0.009421,0.004567,0.116009,276.694244,14.095476,1.160089,-239.529922,0.116035,0.000000
109.310005,62.209290,-239.574402,0.009412,0.004567,0.116009,276.720734,14.096827,1.160089,-239.574402,0.116035,0.000000
109.570007,62.189552,-239.574402,0.009438,0.004567,0.116009,276.632935,14.092355,1.160089,-239.574402,0.116035,0.000000
109.830002,62.175774,-239.574402,0.009399,0.004567,0.116009,276.571655,14.089231,1.160089,-239.574402,0.116035,0.000000
110.090004,62.186951,-239.529922,0.009412,0.004567,0.116009,276.621368,14.091764,1.160089,-239.529922,0.116035,0.000000
110.350006,62.150085,-239.574402,0.009421,0.004567,0.116009,276.457397,14.083411,1.160089,-239.574402,0.116035,0.000000
110.500008,62.151947,-239.574402,0.009395,0.004567,0.116009,276.465668,14.083833,1.160089,-239.574402,0.116035,0.000000