File: Data/Automembrane/AutoNoheat10-1-2_12132023_184624.csv
Time (sec),S:Load (lbs),S:HL1 (DIM),S:LVDT (in),S:Position (in),Ch:Position (mm),Ch:Load (N),Ch:Stress (MPa),Ch:Strain (mm/mm),Ch:HL1 (DIM),Set Point (),Cycles ()
0.010000,0.005959,-1304.893188,0.000065,-0.000000,-0.000000,0.026505,0.001350,-0.000000,-1304.893188,0.000226,0.000000
0.290000,-0.015266,-1304.937622,0.000017,-0.000000,-0.000000,-0.067908,-0.003459,-0.000000,-1304.937622,0.000226,0.000000
0.570000,0.002983,-1304.893188,0.000017,0.000102,0.002602,0.013269,0.000676,0.026017,-1304.893188,0.003417,0.000000
0.850000,0.036499,-1304.893188,0.000142,0.000272,0.006921,0.162356,0.008271,0.069207,-1304.893188,0.008083,0.000000
1.130000,0.004097,-1304.848755,0.000341,0.000460,0.011682,0.018224,0.000928,0.116817,-1304.848755,0.012748,0.000000
1.410000,0.033890,-1304.982178,0.000526,0.000639,0.016235,0.150749,0.007680,0.162345,-1304.982178,0.017414,0.000000
1.690000,-0.005951,-1304.937622,0.000776,0.000828,0.021022,-0.026471,-0.001348,0.210217,-1304.937622,0.022080,0.000000
1.970000,0.010056,-1304.893188,0.000940,0.001012,0.025696,0.044729,0.002279,0.256960,-1304.893188,0.026745,0.000000
2.250000,0.046921,-1304.893188,0.001095,0.001192,0.030275,0.208714,0.010632,0.302750,-1304.893188,0.031411,0.000000
2.530000,0.027184,-1304.937622,0.001276,0.001378,0.035001,0.120918,0.006160,0.350012,-1304.937622,0.036076,0.000000
2.810000,0.073730,-1304.937622,0.001492,0.001564,0.039728,0.327969,0.016708,0.397278,-1304.937622,0.040742,0.000000
3.090000,0.076714,-1304.893188,0.001703,0.001746,0.044359,0.341239,0.017384,0.443586,-1304.893188,0.045408,0.000000
3.370000,0.158638,-1304.893188,0.001858,0.001922,0.048816,0.705657,0.035948,0.488161,-1304.893188,0.050074,0.000000
3.650000,0.190659,-1304.893188,0.002039,0.002106,0.053482,0.848092,0.043204,0.534817,-1304.893188,0.054739,0.000000
3.930000,0.367905,-1304.893188,0.002251,0.002295,0.058304,1.636522,0.083368,0.583037,-1304.893188,0.059405,0.000000
4.210000,0.510902,-1304.893188,0.002522,0.002478,0.062934,2.272607,0.115772,0.629345,-1304.893188,0.064071,0.000000
4.490000,0.609581,-1304.893188,0.002647,-0.000010,-0.000251,2.711552,0.138133,-0.002513,-1304.893188,-0.000034,0.000000
4.770000,0.564522,-1304.982178,0.002665,-0.000010,-0.000251,2.511118,0.127922,-0.002513,-1304.982178,-0.000034,0.000000
5.050000,0.468819,-1304.893188,0.002643,-0.000010,-0.000251,2.085410,0.106236,-0.002513,-1304.893188,0.000061,0.000000
5.330000,0.519089,-1304.804199,0.002673,-0.000010,-0.000243,2.309022,0.117627,-0.002426,-1304.804199,0.000529,0.000000
5.610000,0.513130,-1304.893188,0.002604,-0.000009,-0.000234,2.282517,0.116277,-0.002339,-1304.893188,0.000989,0.000000
5.890000,0.589096,-1304.982178,0.002669,0.000020,0.000520,2.620430,0.133491,0.005204,-1304.982178,0.001457,0.000000
6.170000,0.665436,-1304.937622,0.002682,0.000041,0.001041,2.960006,0.150790,0.010408,-1304.937622,0.001925,0.000000
6.450000,0.687027,-1304.937622,0.002682,0.000056,0.001431,3.056049,0.155683,0.014311,-1304.937622,0.002394,0.000000
6.730000,0.719803,-1304.937622,0.002677,0.000071,0.001813,3.201843,0.163110,0.018126,-1304.937622,0.002862,0.000000
7.010000,0.760391,-1304.893188,0.002759,0.000098,0.002489,3.382389,0.172307,0.024889,-1304.893188,0.003322,0.000000
7.290000,0.753311,-1304.848755,0.002721,0.000118,0.002992,3.350895,0.170703,0.029920,-1304.848755,0.003790,0.000000
7.570000,0.735435,-1304.937622,0.002790,0.000136,0.003461,3.271380,0.166652,0.034605,-1304.937622,0.004258,0.000000
7.850000,0.758896,-1304.937622,0.002772,0.000151,0.003833,3.375737,0.171968,0.038333,-1304.937622,0.004727,0.000000
8.130000,0.805443,-1304.937622,0.002815,0.000169,0.004302,3.582788,0.182516,0.043015,-1304.937622,0.005195,0.000000
8.410001,0.827789,-1304.893188,0.002841,0.000187,0.004744,3.682191,0.187580,0.047440,-1304.893188,0.005663,0.000000
8.690001,0.842682,-1304.982178,0.002871,0.000202,0.005134,3.748436,0.190954,0.051342,-1304.982178,0.006123,0.000000
8.970000,0.892578,-1304.982178,0.002871,0.000227,0.005767,3.970386,0.202261,0.057670,-1304.982178,0.006591,0.000000
9.250000,0.904869,-1304.937622,0.002880,0.000249,0.006322,4.025059,0.205046,0.063223,-1304.937622,0.007059,0.000000
9.530001,0.876938,-1304.982178,0.002897,0.000263,0.006678,3.900815,0.198717,0.066777,-1304.982178,0.007528,0.000000
9.810000,0.903381,-1304.848755,0.002945,0.000280,0.007111,4.018441,0.204709,0.071114,-1304.848755,0.007996,0.000000
10.090000,0.961472,-1304.982178,0.002928,0.000301,0.007649,4.276839,0.217873,0.076489,-1304.982178,0.008455,0.000000
10.370001,0.978973,-1304.937622,0.002949,0.000316,0.008031,4.354691,0.221839,0.080308,-1304.937622,0.008924,0.000000
10.650001,0.984932,-1304.848755,0.002975,0.000330,0.008386,4.381196,0.223189,0.083862,-1304.848755,0.009392,0.000000
10.930000,1.051582,-1304.893188,0.003018,0.000357,0.009080,4.677672,0.238292,0.090800,-1304.893188,0.009860,0.000000
11.210001,1.053818,-1304.937622,0.003061,0.000371,0.009435,4.687615,0.238799,0.094354,-1304.937622,0.010329,0.000000
11.490001,1.051956,-1304.937622,0.003065,0.000391,0.009930,4.679335,0.238377,0.099301,-1304.937622,0.010788,0.000000
11.770000,1.063126,-1304.937622,0.003044,0.000407,0.010337,4.729019,0.240908,0.103373,-1304.937622,0.011257,0.000000
12.050000,1.099251,-1304.893188,0.003126,0.000431,0.010944,4.889712,0.249094,0.109444,-1304.893188,0.011725,0.000000
12.330001,1.115631,-1304.804199,0.003139,0.000445,0.011300,4.962575,0.252806,0.113002,-1304.804199,0.012193,0.000000
12.610001,1.127174,-1304.982178,0.003113,0.000462,0.011734,5.013922,0.255421,0.117336,-1304.982178,0.012662,0.000000
12.890000,1.187500,-1304.982178,0.003186,0.000484,0.012306,5.282264,0.269091,0.123062,-1304.982178,0.013130,0.000000
13.170001,1.199043,-1304.937622,0.003208,0.000504,0.012792,5.333611,0.271707,0.127918,-1304.937622,0.013590,0.000000
13.450001,1.209473,-1304.893188,0.003178,0.000523,0.013286,5.380003,0.274070,0.132861,-1304.893188,0.014058,0.000000
13.730000,1.184517,-1304.982178,0.003268,0.000533,0.013537,5.268994,0.268415,0.135374,-1304.982178,0.014526,0.000000
14.010000,1.264580,-1304.937622,0.003212,0.000557,0.014153,5.625132,0.286558,0.141532,-1304.937622,0.014995,0.000000
14.290001,1.243729,-1304.982178,0.003260,0.000571,0.014500,5.532381,0.281833,0.145003,-1304.982178,0.015463,0.000000
14.570001,1.318573,-1304.937622,0.003251,0.000596,0.015142,5.865305,0.298793,0.151419,-1304.937622,0.015922,0.000000
14.850000,1.317085,-1304.982178,0.003281,0.000614,0.015593,5.858688,0.298456,0.155930,-1304.982178,0.016391,0.000000
15.130001,1.311874,-1304.937622,0.003307,0.000627,0.015922,5.835509,0.297275,0.159223,-1304.937622,0.016859,0.000000
15.410001,1.347244,-1304.848755,0.003341,0.000648,0.016469,5.992842,0.305290,0.164688,-1304.848755,0.017327,0.000000
15.690001,1.355812,-1304.982178,0.003354,0.000667,0.016946,6.030953,0.307231,0.169457,-1304.982178,0.017795,0.000000
15.970001,1.366608,-1304.982178,0.003346,0.000683,0.017336,6.078975,0.309678,0.173360,-1304.982178,0.018264,0.000000
16.250000,1.356926,-1304.937622,0.003389,0.000694,0.017640,6.035908,0.307484,0.176395,-1304.937622,0.018723,0.000000
16.530001,1.414650,-1304.937622,0.003372,0.000714,0.018134,6.292677,0.320564,0.181338,-1304.937622,0.019192,0.000000
16.810001,1.469757,-1304.982178,0.003488,0.000742,0.018845,6.537806,0.333052,0.188450,-1304.982178,0.019660,0.000000
17.090000,1.451515,-1305.026611,0.003471,0.000758,0.019261,6.456662,0.328918,0.192613,-1305.026611,0.020128,0.000000
17.370001,1.478691,-1304.982178,0.003510,0.000775,0.019686,6.577547,0.335076,0.196860,-1304.982178,0.020597,0.000000
17.650002,1.491730,-1305.026611,0.003514,0.000791,0.020102,6.635545,0.338031,0.201023,-1305.026611,0.021057,0.000000
17.930000,1.527847,-1304.982178,0.003484,0.000810,0.020571,6.796204,0.346215,0.205709,-1304.982178,0.021525,0.000000
18.210001,1.526360,-1304.982178,0.003544,0.000825,0.020961,6.789587,0.345878,0.209611,-1304.982178,0.021993,0.000000
18.490002,1.569557,-1305.071045,0.003600,0.000847,0.021525,6.981739,0.355667,0.215247,-1305.071045,0.022461,0.000000
18.770000,1.607162,-1304.982178,0.003566,0.000868,0.022054,7.149016,0.364188,0.220538,-1304.982178,0.022930,0.000000
19.050001,1.582214,-1304.937622,0.003592,0.000883,0.022418,7.038041,0.358535,0.224179,-1304.937622,0.023398,0.000000
19.330002,1.568062,-1305.071045,0.003617,0.000900,0.022869,6.975087,0.355328,0.228687,-1305.071045,0.023857,0.000000
19.610001,1.660782,-1304.982178,0.003635,0.000925,0.023485,7.387527,0.376339,0.234845,-1304.982178,0.024326,0.000000
19.890001,1.670464,-1305.071045,0.003682,0.000944,0.023988,7.430593,0.378532,0.239875,-1305.071045,0.024794,0.000000
20.170000,1.666367,-1304.982178,0.003656,0.000958,0.024326,7.412369,0.377604,0.243259,-1304.982178,0.025262,0.000000
20.450001,1.714775,-1304.982178,0.003717,0.000979,0.024855,7.627700,0.388574,0.248546,-1304.982178,0.025731,0.000000
20.730001,1.731537,-1304.982178,0.003725,0.001000,0.025392,7.702260,0.392372,0.253925,-1304.982178,0.026190,0.000000
21.010000,1.733025,-1305.071045,0.003712,0.001013,0.025731,7.708879,0.392709,0.257309,-1305.071045,0.026659,0.000000
21.290001,1.747177,-1305.026611,0.003768,0.001033,0.026234,7.771832,0.395916,0.262339,-1305.026611,0.027127,0.000000
21.570002,1.817924,-1305.026611,0.003798,0.001055,0.026789,8.086532,0.411948,0.267887,-1305.026611,0.027595,0.000000
21.850000,1.831329,-1305.071045,0.003773,0.001072,0.027231,8.146160,0.414985,0.272312,-1305.071045,0.028063,0.000000
22.130001,1.820534,-1304.982178,0.003803,0.001085,0.027552,8.098139,0.412539,0.275518,-1304.982178,0.028523,0.000000
22.410002,1.889793,-1304.982178,0.003837,0.001109,0.028159,8.406220,0.428233,0.281589,-1304.982178,0.028992,0.000000
22.690001,1.911766,-1305.026611,0.003829,0.001129,0.028671,8.503960,0.433212,0.286706,-1305.026611,0.029460,0.000000
22.970001,1.892403,-1305.026611,0.003898,0.001141,0.028974,8.417828,0.428825,0.289741,-1305.026611,0.029928,0.000000
23.250002,1.925545,-1304.982178,0.003945,0.001164,0.029573,8.565250,0.436335,0.295725,-1304.982178,0.030396,0.000000
23.530001,1.978416,-1305.026611,0.003941,0.001182,0.030023,8.800436,0.448316,0.300233,-1305.026611,0.030865,0.000000
23.810001,2.004112,-1305.026611,0.003958,0.001199,0.030466,8.914737,0.454138,0.304658,-1305.026611,0.031324,0.000000
24.090002,2.017143,-1305.026611,0.003980,0.001213,0.030813,8.972701,0.457091,0.308128,-1305.026611,0.031793,0.000000
24.370001,2.015282,-1305.071045,0.003945,0.001226,0.031142,8.964420,0.456669,0.311421,-1305.071045,0.032261,0.000000
24.650002,2.136673,-1305.071045,0.004044,0.001253,0.031836,9.504396,0.484177,0.318359,-1305.071045,0.032729,0.000000
24.930000,2.100182,-1304.982178,0.004061,0.001271,0.032296,9.342074,0.475908,0.322958,-1304.982178,0.033198,0.000000
25.210001,2.116196,-1305.026611,0.004036,0.001291,0.032790,9.413308,0.479537,0.327901,-1305.026611,0.033657,0.000000
25.490002,2.098320,-1305.071045,0.004031,0.001304,0.033128,9.333794,0.475486,0.331280,-1305.071045,0.034125,0.000000
25.770000,2.192162,-1305.115601,0.004061,0.001320,0.033527,9.751222,0.496751,0.335270,-1305.115601,0.034594,0.000000
26.050001,2.324356,-1304.937622,0.004070,0.001341,0.034074,10.339252,0.526707,0.340735,-1304.937622,0.035062,0.000000
26.330002,2.326958,-1304.982178,0.004122,0.001359,0.034516,10.350824,0.527296,0.345156,-1304.982178,0.035530,0.000000
26.610001,2.417076,-1305.026611,0.004143,0.001382,0.035105,10.751692,0.547717,0.351053,-1305.026611,0.035999,0.000000
26.890001,2.368668,-1305.026611,0.004161,0.001400,0.035548,10.536360,0.536748,0.355477,-1305.026611,0.036458,0.000000
27.170002,2.395477,-1305.026611,0.004199,0.001418,0.036007,10.655615,0.542823,0.360072,-1305.026611,0.036927,0.000000
27.450001,2.502716,-1305.026611,0.004191,0.001438,0.036536,11.132637,0.567124,0.365363,-1305.026611,0.037395,0.000000
27.730001,2.500854,-1304.982178,0.004234,0.001454,0.036927,11.124356,0.566702,0.369266,-1304.982178,0.037863,0.000000
28.010002,2.531395,-1305.115601,0.004199,0.001470,0.037343,11.260207,0.573622,0.373429,-1305.115601,0.038332,0.000000
28.290001,2.653160,-1305.026611,0.004255,0.001492,0.037898,11.801846,0.601215,0.378978,-1305.026611,0.038791,0.000000
28.570002,2.702682,-1305.071045,0.004307,0.001515,0.038487,12.022132,0.612437,0.384875,-1305.071045,0.039260,0.000000
28.850002,2.680344,-1305.026611,0.004273,0.001532,0.038921,11.922764,0.607375,0.389212,-1305.026611,0.039728,0.000000
29.130001,2.729118,-1305.026611,0.004312,0.001548,0.039320,12.139725,0.618427,0.393201,-1305.026611,0.040196,0.000000
29.410002,2.792427,-1304.937622,0.004372,0.001567,0.039797,12.421336,0.632773,0.397970,-1304.937622,0.040665,0.000000
29.690001,2.859077,-1305.071045,0.004329,0.001585,0.040248,12.717812,0.647876,0.402482,-1305.071045,0.041124,0.000000
29.970001,2.873230,-1305.026611,0.004372,0.001599,0.040604,12.780766,0.651083,0.406036,-1305.026611,0.041592,0.000000
30.250002,3.058296,-1304.982178,0.004359,0.001625,0.041280,13.603981,0.693020,0.412800,-1304.982178,0.042060,0.000000
30.530001,3.103355,-1305.026611,0.004449,0.001647,0.041826,13.804415,0.703230,0.418265,-1305.026611,0.042529,0.000000
30.810001,3.037819,-1305.026611,0.004441,0.001661,0.042199,13.512894,0.688380,0.421993,-1305.026611,0.042997,0.000000
31.090002,3.096649,-1305.026611,0.004449,0.001676,0.042563,13.774584,0.701711,0.425634,-1305.026611,0.043465,0.000000
31.370001,3.273903,-1305.026611,0.004462,0.001700,0.043171,14.563047,0.741877,0.431705,-1305.026611,0.043925,0.000000
31.650002,3.271294,-1304.982178,0.004462,0.001714,0.043535,14.551441,0.741286,0.435350,-1304.982178,0.044393,0.000000
31.930002,3.294380,-1305.026611,0.004514,0.001727,0.043864,14.654135,0.746517,0.438643,-1305.026611,0.044862,0.000000
32.210003,3.500305,-1304.982178,0.004536,0.001756,0.044593,15.570135,0.793180,0.445929,-1304.982178,0.045330,0.000000
32.490002,3.494347,-1305.115601,0.004566,0.001770,0.044966,15.543630,0.791830,0.449657,-1305.115601,0.045798,0.000000
32.770000,3.547226,-1305.071045,0.004570,0.001789,0.045451,15.778849,0.803813,0.454513,-1305.071045,0.046258,0.000000
33.050003,3.586319,-1304.982178,0.004553,0.001805,0.045859,15.952744,0.812672,0.458589,-1304.982178,0.046726,0.000000
33.330002,3.711815,-1304.937622,0.004622,0.001827,0.046414,16.510977,0.841109,0.464142,-1304.937622,0.047195,0.000000
33.610001,3.742722,-1304.982178,0.004596,0.001843,0.046813,16.648457,0.848113,0.468131,-1304.982178,0.047663,0.000000
33.890003,3.776230,-1304.982178,0.004674,0.001859,0.047212,16.797510,0.855706,0.472120,-1304.982178,0.048131,0.000000
34.170002,3.975449,-1305.071045,0.004626,0.001883,0.047819,17.683678,0.900850,0.478191,-1305.071045,0.048600,0.000000
34.450001,3.998169,-1304.982178,0.004665,0.001899,0.048235,17.784744,0.905998,0.482351,-1304.982178,0.049059,0.000000
34.730003,4.114349,-1304.893188,0.004717,0.001921,0.048782,18.301540,0.932325,0.487816,-1304.893188,0.049527,0.000000
35.010002,4.014175,-1304.982178,0.004721,0.001931,0.049042,17.855944,0.909625,0.490416,-1304.982178,0.049996,0.000000
35.290001,4.244308,-1305.026611,0.004717,0.001954,0.049640,18.879627,0.961774,0.496400,-1305.026611,0.050464,0.000000
35.570004,4.247658,-1305.071045,0.004760,0.001968,0.049987,18.894526,0.962533,0.499871,-1305.071045,0.050932,0.000000
35.850002,4.393257,-1304.982178,0.004790,0.001989,0.050533,19.542183,0.995526,0.505333,-1304.982178,0.051392,0.000000
36.130001,4.478157,-1304.937622,0.004829,0.002008,0.051010,19.919838,1.014765,0.510102,-1304.937622,0.051860,0.000000
36.410000,4.508316,-1304.893188,0.004807,0.002025,0.051435,20.053991,1.021599,0.514352,-1304.893188,0.052328,0.000000
36.690002,4.625618,-1304.982178,0.004833,0.002045,0.051947,20.575777,1.048180,0.519469,-1304.982178,0.052797,0.000000
36.970001,4.644981,-1304.937622,0.004855,0.002064,0.052424,20.661909,1.052568,0.524238,-1304.937622,0.053265,0.000000
37.250000,4.739929,-1304.937622,0.004850,0.002078,0.052780,21.084259,1.074083,0.527796,-1304.937622,0.053725,0.000000
37.530003,4.604385,-1304.848755,0.004842,0.002086,0.052996,20.481329,1.043369,0.529965,-1304.848755,0.054193,0.000000
37.810001,4.899307,-1304.937622,0.004898,0.002110,0.053586,21.793207,1.110199,0.535862,-1304.937622,0.054661,0.000000
38.090000,5.164810,-1304.893188,0.004872,0.002139,0.054332,22.974222,1.170363,0.543318,-1304.893188,0.055130,0.000000
38.370003,5.078789,-1304.982178,0.004963,0.002154,0.054713,22.591581,1.150870,0.547133,-1304.982178,0.055598,0.000000
38.650002,5.132782,-1304.937622,0.004963,0.002173,0.055190,22.831755,1.163105,0.551902,-1304.937622,0.056066,0.000000
38.930000,5.092194,-1304.937622,0.004950,0.002188,0.055563,22.651209,1.153908,0.555634,-1304.937622,0.056526,0.000000
39.210003,5.361053,-1304.937622,0.004980,0.002208,0.056075,23.847157,1.214832,0.560751,-1304.937622,0.056994,0.000000
39.490002,5.351372,-1304.937622,0.005027,0.002224,0.056491,23.804090,1.212638,0.564911,-1304.937622,0.057463,0.000000
39.770000,5.407593,-1304.937622,0.005053,0.002241,0.056934,24.054174,1.225378,0.569335,-1304.937622,0.057931,0.000000
40.050003,5.637726,-1304.893188,0.005075,0.002265,0.057541,25.077856,1.277527,0.575406,-1304.893188,0.058399,0.000000
40.330002,5.607185,-1304.893188,0.005105,0.002279,0.057879,24.942007,1.270606,0.578786,-1304.893188,0.058859,0.000000
40.610001,5.685013,-1304.893188,0.005079,0.002297,0.058347,25.288200,1.288242,0.583472,-1304.893188,0.059327,0.000000
40.890003,5.929665,-1304.937622,0.005113,0.002321,0.058963,26.376465,1.343681,0.589630,-1304.937622,0.059795,0.000000
41.170002,6.008232,-1304.937622,0.005157,0.002342,0.059474,26.725952,1.361485,0.594743,-1304.937622,0.060263,0.000000
41.450001,5.970253,-1304.848755,0.005131,0.002355,0.059821,26.557013,1.352879,0.598214,-1304.848755,0.060732,0.000000
41.730003,6.173943,-1304.848755,0.005152,0.002376,0.060351,27.463068,1.399035,0.603505,-1304.848755,0.061200,0.000000
42.010002,6.291985,-1304.893188,0.005174,0.002397,0.060879,27.988146,1.425784,0.608793,-1304.893188,0.061660,0.000000
42.290001,6.252510,-1304.893188,0.005230,0.002410,0.061226,27.812553,1.416839,0.612264,-1304.893188,0.062128,0.000000
42.570004,6.287888,-1304.893188,0.005238,0.002427,0.061651,27.969921,1.424856,0.616514,-1304.893188,0.062596,0.000000
42.850002,6.495667,-1304.848755,0.005208,0.002449,0.062198,28.894167,1.471939,0.621976,-1304.848755,0.063065,0.000000
43.130001,6.630470,-1304.848755,0.005217,0.002468,0.062692,29.493805,1.502486,0.626919,-1304.848755,0.063533,0.000000
43.410004,6.484871,-1304.848755,0.005290,0.002480,0.062987,28.846146,1.469493,0.629867,-1304.848755,0.063993,0.000000
43.690002,6.870651,-1304.848755,0.005307,0.002503,0.063568,30.562183,1.556912,0.635677,-1304.848755,0.064461,0.000000
43.970001,6.999115,-1304.893188,0.005286,0.002526,0.064157,31.133619,1.586022,0.641574,-1304.893188,0.064929,0.000000
44.250004,6.923149,-1304.804199,0.005325,0.002539,0.064487,30.795706,1.568808,0.644870,-1304.804199,0.065398,0.000000
44.530003,7.136520,-1304.893188,0.005325,0.002561,0.065059,31.744827,1.617159,0.650593,-1304.893188,0.065866,0.000000
44.810001,7.246742,-1304.848755,0.005415,0.002581,0.065554,32.235119,1.642135,0.655536,-1304.848755,0.066326,0.000000
45.090004,7.266106,-1304.937622,0.005394,0.002598,0.065979,32.321251,1.646523,0.659787,-1304.937622,0.066794,0.000000
45.370003,7.288818,-1304.893188,0.005372,0.002613,0.066369,32.422283,1.651670,0.663689,-1304.893188,0.067262,0.000000
45.650002,7.415428,-1304.848755,0.005437,0.002633,0.066872,32.985474,1.680360,0.668719,-1304.848755,0.067730,0.000000
45.930000,7.598633,-1304.848755,0.005411,0.002652,0.067349,33.800407,1.721875,0.673488,-1304.848755,0.068199,0.000000
46.210003,7.510384,-1304.937622,0.005445,0.002667,0.067730,33.407856,1.701877,0.677303,-1304.937622,0.068667,0.000000
46.490002,7.727104,-1304.937622,0.005484,0.002687,0.068251,34.371876,1.750987,0.682507,-1304.937622,0.069127,0.000000
46.770000,7.618370,-1304.937622,0.005536,0.002700,0.068580,33.888203,1.726347,0.685804,-1304.937622,0.069595,0.000000
47.050003,7.865257,-1304.937622,0.005489,0.002719,0.069057,34.986412,1.782293,0.690573,-1304.937622,0.070063,0.000000
47.330002,8.102829,-1304.893188,0.005553,0.002740,0.069595,36.043182,1.836127,0.695951,-1304.893188,0.070532,0.000000
47.610001,8.194061,-1304.848755,0.005558,0.002757,0.070029,36.449005,1.856801,0.700285,-1304.848755,0.071000,0.000000
47.890003,7.860039,-1304.937622,0.005583,0.002763,0.070185,34.963200,1.781110,0.701848,-1304.937622,0.071460,0.000000
48.170002,8.427536,-1304.937622,0.005609,0.002796,0.071017,37.487553,1.909707,0.710171,-1304.937622,0.071928,0.000000
48.450001,8.386948,-1304.893188,0.005644,0.002815,0.071503,37.307007,1.900510,0.715027,-1304.893188,0.072396,0.000000
48.730003,8.622658,-1304.893188,0.005661,0.002837,0.072049,38.355499,1.953922,0.720493,-1304.893188,0.072865,0.000000
49.010002,8.573883,-1304.893188,0.005683,0.002852,0.072448,38.138538,1.942870,0.724482,-1304.893188,0.073333,0.000000
49.290001,8.521744,-1304.982178,0.005683,0.002868,0.072838,37.906609,1.931055,0.728384,-1304.982178,0.073801,0.000000
49.570004,8.582443,-1304.893188,0.005665,0.002885,0.073281,38.176613,1.944809,0.732809,-1304.893188,0.074261,0.000000
49.850002,8.968964,-1304.893188,0.005687,0.002911,0.073931,39.895943,2.032396,0.739311,-1304.893188,0.074729,0.000000
50.130001,8.895607,-1304.804199,0.005726,0.002928,0.074382,39.569637,2.015773,0.743823,-1304.804199,0.075197,0.000000
50.410004,9.030411,-1304.893188,0.005743,0.002945,0.074798,40.169273,2.046320,0.747982,-1304.893188,0.075666,0.000000
50.690002,9.167816,-1304.893188,0.005812,0.002965,0.075301,40.780483,2.077457,0.753012,-1304.893188,0.076134,0.000000
50.970001,9.181221,-1304.937622,0.005795,0.002981,0.075718,40.840111,2.080494,0.757176,-1304.937622,0.076593,0.000000
51.250004,9.186432,-1304.848755,0.005799,0.002995,0.076073,40.863289,2.081675,0.760734,-1304.848755,0.077062,0.000000
51.530003,9.602745,-1304.804199,0.005812,0.003022,0.076750,42.715145,2.176013,0.767497,-1304.804199,0.077530,0.000000
51.810001,9.600510,-1304.937622,0.005864,0.003042,0.077261,42.705200,2.175507,0.772614,-1304.937622,0.077998,0.000000
52.090004,9.473160,-1304.937622,0.005846,0.003057,0.077652,42.138718,2.146649,0.776517,-1304.937622,0.078467,0.000000
52.370003,9.521194,-1304.893188,0.005838,0.003073,0.078059,42.352386,2.157533,0.780593,-1304.893188,0.078935,0.000000
52.650002,9.967300,-1304.893188,0.005877,0.003097,0.078666,44.336765,2.258623,0.786660,-1304.893188,0.079395,0.000000
52.930004,9.824303,-1304.982178,0.005946,0.003111,0.079030,43.700680,2.226219,0.790305,-1304.982178,0.079863,0.000000
53.210003,9.804573,-1304.937622,0.005915,0.003123,0.079334,43.612919,2.221748,0.793341,-1304.937622,0.080331,0.000000
53.490002,10.169121,-1304.937622,0.005989,0.003150,0.080002,45.234509,2.304356,0.800017,-1304.937622,0.080800,0.000000
53.770004,10.178429,-1304.893188,0.005941,0.003167,0.080444,45.275913,2.306465,0.804442,-1304.893188,0.081268,0.000000
54.050003,10.263336,-1304.893188,0.005950,0.003187,0.080938,45.653599,2.325705,0.809385,-1304.893188,0.081728,0.000000
54.330002,10.256630,-1304.893188,0.006023,0.003201,0.081311,45.623768,2.324186,0.813113,-1304.893188,0.082196,0.000000
54.610004,10.522507,-1304.937622,0.006062,0.003222,0.081832,46.806446,2.384434,0.818317,-1304.937622,0.082664,0.000000
54.890003,10.554153,-1305.026611,0.006053,0.003240,0.082309,46.947220,2.391605,0.823086,-1305.026611,0.083133,0.000000
55.170002,10.420845,-1305.026611,0.006084,0.003251,0.082577,46.354233,2.361397,0.825773,-1305.026611,0.083601,0.000000
55.450001,10.949989,-1304.893188,0.006079,0.003277,0.083236,48.707985,2.481303,0.832363,-1304.893188,0.084060,0.000000
55.730003,10.963394,-1304.937622,0.006101,0.003294,0.083670,48.767612,2.484341,0.836700,-1304.937622,0.084528,0.000000
56.010002,11.186073,-1304.982178,0.006153,0.003316,0.084234,49.758141,2.534801,0.842336,-1304.982178,0.084997,0.000000
56.290001,10.955574,-1304.982178,0.006170,0.003328,0.084520,48.732826,2.482569,0.845201,-1304.982178,0.085465,0.000000
56.570004,11.341721,-1304.982178,0.006187,0.003350,0.085092,50.450493,2.570071,0.850924,-1304.982178,0.085933,0.000000
56.850002,11.321617,-1304.893188,0.006174,0.003366,0.085491,50.361069,2.565515,0.854913,-1304.893188,0.086402,0.000000
57.130001,11.391991,-1304.893188,0.006222,0.003385,0.085968,50.674107,2.581462,0.859682,-1304.893188,0.086861,0.000000
57.410004,11.710747,-1304.982178,0.006234,0.003406,0.086506,52.092003,2.653693,0.865060,-1304.982178,0.087330,0.000000
57.690002,11.761017,-1305.026611,0.006247,0.003422,0.086922,52.315617,2.665085,0.869220,-1305.026611,0.087798,0.000000
57.970001,12.018700,-1304.937622,0.006226,0.003442,0.087425,53.461845,2.723476,0.874250,-1304.937622,0.088266,0.000000
58.250004,11.838097,-1304.982178,0.006269,0.003454,0.087737,52.658485,2.682551,0.877373,-1304.982178,0.088735,0.000000
58.530003,12.146049,-1305.026611,0.006256,0.003477,0.088318,54.028328,2.752334,0.883183,-1305.026611,0.089194,0.000000
58.810001,11.923370,-1304.937622,0.006312,0.003488,0.088605,53.037800,2.701874,0.886048,-1304.937622,0.089663,0.000000
59.090004,12.377663,-1305.026611,0.006359,0.003507,0.089073,55.058594,2.804818,0.890730,-1305.026611,0.090131,0.000000
59.370003,13.035271,-1304.982178,0.006312,0.003536,0.089819,57.983780,2.953835,0.898186,-1304.982178,0.090599,0.000000
59.650002,12.787643,-1304.982178,0.006342,0.003552,0.090209,56.882278,2.897722,0.902088,-1304.982178,0.091068,0.000000
59.930004,12.645401,-1304.893188,0.006407,0.003568,0.090616,56.249554,2.865489,0.906164,-1304.893188,0.091536,0.000000
60.210003,12.732910,-1304.982178,0.006416,0.003581,0.090964,56.638813,2.885319,0.909635,-1304.982178,0.091995,0.000000
60.490002,13.133583,-1305.026611,0.006398,0.003604,0.091553,58.421097,2.976113,0.915532,-1305.026611,0.092464,0.000000
60.770004,13.244545,-1304.937622,0.006428,0.003622,0.091987,58.914677,3.001257,0.919870,-1304.937622,0.092932,0.000000
61.050003,13.307106,-1304.893188,0.006472,0.003638,0.092394,59.192963,3.015433,0.923942,-1304.893188,0.093400,0.000000
61.330002,13.755814,-1304.982178,0.006476,0.003661,0.093001,61.188915,3.117112,0.930013,-1304.982178,0.093869,0.000000
61.610004,13.516006,-1304.982178,0.006463,0.003675,0.093357,60.122200,3.062771,0.933571,-1304.982178,0.094328,0.000000
61.890003,13.759163,-1305.026611,0.006476,0.003693,0.093808,61.203812,3.117871,0.938079,-1305.026611,0.094796,0.000000
62.170002,14.280487,-1305.026611,0.006532,0.003718,0.094432,63.522778,3.236005,0.944324,-1305.026611,0.095265,0.000000
62.450005,14.406349,-1304.982178,0.006554,0.003738,0.094935,64.082642,3.264525,0.949354,-1304.982178,0.095733,0.000000
62.730003,14.159836,-1304.937622,0.006554,0.003750,0.095248,62.986095,3.208665,0.952476,-1304.937622,0.096201,0.000000
63.010002,14.471146,-1305.026611,0.006575,0.003768,0.095716,64.370872,3.279208,0.957158,-1305.026611,0.096661,0.000000
63.290005,14.948151,-1305.026611,0.006592,0.003793,0.096340,66.492699,3.387299,0.963403,-1305.026611,0.097129,0.000000
63.570004,14.859528,-1304.982178,0.006601,0.003808,0.096722,66.098480,3.367217,0.967219,-1304.982178,0.097598,0.000000
63.850002,15.004753,-1304.982178,0.006670,0.003824,0.097138,66.744476,3.400126,0.971382,-1304.982178,0.098066,0.000000
64.130005,15.301903,-1305.026611,0.006640,0.003845,0.097658,68.066261,3.467461,0.976582,-1305.026611,0.098534,0.000000
64.410004,15.637413,-1305.026611,0.006670,0.003866,0.098196,69.558685,3.543489,0.981961,-1305.026611,0.099003,0.000000
64.690002,15.333183,-1305.071045,0.006722,0.003876,0.098456,68.205406,3.474549,0.984561,-1305.071045,0.099462,0.000000
64.970001,15.922279,-1305.026611,0.006679,0.003900,0.099054,70.825836,3.608040,0.990545,-1305.026611,0.099931,0.000000
65.250000,16.424980,-1304.982178,0.006760,0.003922,0.099610,73.061958,3.721954,0.996097,-1304.982178,0.100399,0.000000
65.530006,16.347527,-1304.937622,0.006756,0.003937,0.100009,72.717430,3.704402,1.000087,-1304.937622,0.100867,0.000000
65.810005,16.538185,-1304.982178,0.006791,0.003954,0.100442,73.565521,3.747606,1.004420,-1304.982178,0.101336,0.000000
66.090004,16.998062,-1304.982178,0.006821,0.003976,0.100980,75.611160,3.851816,1.009799,-1304.982178,0.101795,0.000000
66.370003,17.102699,-1304.982178,0.006795,0.003993,0.101431,76.076607,3.875527,1.014310,-1304.982178,0.102263,0.000000
66.650002,17.191322,-1304.937622,0.006825,0.004009,0.101821,76.470818,3.895609,1.018212,-1304.937622,0.102732,0.000000
66.930000,17.313461,-1304.982178,0.006860,0.004023,0.102185,77.014122,3.923286,1.021854,-1304.982178,0.103200,0.000000
67.210007,18.109222,-1304.982178,0.006916,0.004048,0.102810,80.553841,4.103609,1.028099,-1304.982178,0.103668,0.000000
67.490005,17.778923,-1305.026611,0.006847,0.004058,0.103061,79.084602,4.028761,1.030612,-1305.026611,0.104136,0.000000
67.770004,18.465210,-1305.026611,0.006903,0.004083,0.103703,82.137360,4.184277,1.037031,-1305.026611,0.104596,0.000000
68.050003,18.498726,-1304.982178,0.006885,0.004097,0.104067,82.286446,4.191871,1.040672,-1304.982178,0.105065,0.000000
68.330002,18.845398,-1304.982178,0.006946,0.004112,0.104457,83.828514,4.270428,1.044574,-1304.982178,0.105533,0.000000
68.610001,18.758636,-1304.982178,0.006920,0.004131,0.104917,83.442581,4.250768,1.049173,-1304.982178,0.106001,0.000000
68.890007,19.403214,-1305.071045,0.006976,0.004143,0.105238,86.309807,4.396831,1.052379,-1305.071045,0.106469,0.000000
69.170006,20.504692,-1304.982178,0.006959,0.004175,0.106053,91.209427,4.646430,1.060531,-1304.982178,0.106929,0.000000
69.450005,20.659225,-1304.937622,0.007023,0.004192,0.106478,91.896828,4.681447,1.064782,-1304.937622,0.107398,0.000000
69.730003,20.793655,-1304.982178,0.007036,0.004210,0.106938,92.494797,4.711910,1.069377,-1304.982178,0.107866,0.000000
70.010002,21.360779,-1305.071045,0.007023,0.004232,0.107484,95.017487,4.840422,1.074842,-1305.071045,0.108334,0.000000
70.290001,21.772247,-1305.115601,0.007088,0.004249,0.107935,96.847794,4.933662,1.079350,-1305.115601,0.108802,0.000000
70.570000,21.995300,-1305.026611,0.007023,0.004263,0.108282,97.839981,4.984206,1.082821,-1305.026611,0.109262,0.000000
70.850006,22.026955,-1305.071045,0.007036,0.004278,0.108664,97.980789,4.991379,1.086636,-1305.071045,0.109730,0.000000
71.130005,23.395424,-1305.071045,0.007084,0.004305,0.109340,104.068047,5.301479,1.093399,-1305.071045,0.110198,0.000000
71.410004,23.564850,-1304.982178,0.007127,0.004321,0.109756,104.821686,5.339871,1.097563,-1304.982178,0.110667,0.000000
71.690002,24.267143,-1305.026611,0.007127,0.004343,0.110320,107.945641,5.499013,1.103199,-1305.026611,0.111135,0.000000
71.970001,24.718834,-1305.026611,0.007187,0.004362,0.110788,109.954865,5.601367,1.107880,-1305.026611,0.111603,0.000000
72.250000,24.931831,-1304.982178,0.007183,0.004374,0.111109,110.902328,5.649633,1.111090,-1304.982178,0.112063,0.000000
72.530006,25.535446,-1305.026611,0.007174,0.004392,0.111569,113.587341,5.786415,1.115689,-1305.026611,0.112531,0.000000
72.810005,26.505478,-1304.982178,0.007209,0.004415,0.112141,117.902252,6.006227,1.121411,-1304.982178,0.113000,0.000000
73.090004,27.532478,-1305.026611,0.007213,0.004437,0.112705,122.470581,6.238949,1.127047,-1305.026611,0.113468,0.000000
73.370003,27.803192,-1304.982178,0.007200,0.004454,0.113121,123.674774,6.300293,1.131210,-1304.982178,0.113936,0.000000
73.650002,28.183762,-1304.982178,0.007217,0.004470,0.113529,125.367630,6.386532,1.135287,-1304.982178,0.114396,0.000000
73.930000,29.242043,-1305.026611,0.007282,0.004493,0.114110,130.075104,6.626341,1.141097,-1305.026611,0.114864,0.000000
74.210007,29.628937,-1304.982178,0.007286,0.004504,0.114413,131.796097,6.714013,1.144132,-1304.982178,0.115333,0.000000
74.490005,30.209091,-1305.026611,0.007321,0.004519,0.114795,134.376755,6.845478,1.147947,-1305.026611,0.115801,0.000000
74.770004,31.691505,-1305.026611,0.007338,0.004545,0.115437,140.970856,7.181398,1.154366,-1305.026611,0.116269,0.000000
75.050003,32.471252,-1305.026611,0.007338,0.004564,0.115914,144.439346,7.358091,1.159135,-1305.026611,0.116738,0.000000
75.330002,33.195518,-1304.982178,0.007347,0.004583,0.116399,147.661041,7.522212,1.163991,-1304.982178,0.117197,0.000000
75.610001,33.790939,-1305.115601,0.007343,0.004596,0.116746,150.309601,7.657136,1.167462,-1305.115601,0.117665,0.000000
75.890007,35.067436,-1305.071045,0.007321,0.004620,0.117353,155.987747,7.946395,1.173529,-1305.071045,0.118134,0.000000
76.170006,35.844208,-1304.982178,0.007364,0.004636,0.117752,159.442993,8.122414,1.177519,-1304.982178,0.118602,0.000000
76.450005,36.177109,-1305.026611,0.007407,0.004648,0.118064,160.923813,8.197850,1.180641,-1305.026611,0.119070,0.000000
76.730003,37.930237,-1305.071045,0.007420,0.004673,0.118706,168.722122,8.595115,1.187060,-1305.071045,0.119530,0.000000
77.010002,38.701042,-1305.071045,0.007412,0.004689,0.119105,172.150833,8.769782,1.191050,-1305.071045,0.119998,0.000000
77.290001,40.030045,-1305.071045,0.007420,0.004713,0.119703,178.062531,9.070938,1.197034,-1305.071045,0.120466,0.000000
77.570007,40.804947,-1305.026611,0.007455,0.004726,0.120041,181.509476,9.246532,1.200413,-1305.026611,0.120935,0.000000
77.850006,41.654701,-1304.982178,0.007459,0.004745,0.120536,185.289368,9.439091,1.205357,-1304.982178,0.121403,0.000000
78.130005,42.871620,-1305.071045,0.007463,0.004762,0.120943,190.702484,9.714849,1.209433,-1305.071045,0.121863,0.000000
78.410004,43.459221,-1305.071045,0.007502,0.004775,0.121282,193.316269,9.848001,1.212817,-1305.071045,0.122331,0.000000
78.690002,45.284218,-1304.982178,0.007489,0.004799,0.121906,201.434265,10.261550,1.219062,-1304.982178,0.122799,0.000000
78.970001,46.374901,-1304.982178,0.007511,0.004817,0.122348,206.285858,10.508702,1.223482,-1304.982178,0.123268,0.000000
79.250000,46.873131,-1304.982178,0.007489,0.004829,0.122652,208.502106,10.621604,1.226518,-1304.982178,0.123736,0.000000
79.530006,48.545456,-1304.982178,0.007506,0.004852,0.123233,215.940979,11.000558,1.232328,-1304.982178,0.124204,0.000000
79.810005,49.984306,-1304.982178,0.007537,0.004871,0.123718,222.341293,11.326606,1.237184,-1304.982178,0.124664,0.000000
80.090004,50.819160,-1305.071045,0.007567,0.004882,0.124014,226.054916,11.515786,1.240136,-1305.071045,0.125132,0.000000
80.370003,52.081505,-1305.026611,0.007549,0.004903,0.124534,231.670105,11.801838,1.245336,-1305.026611,0.125601,0.000000
80.650002,53.893471,-1304.982178,0.007606,0.004926,0.125115,239.730133,12.212435,1.251146,-1304.982178,0.126069,0.000000
80.930000,55.556114,-1305.026611,0.007571,0.004944,0.125566,247.125931,12.589195,1.255658,-1305.026611,0.126537,0.000000
81.210007,56.552582,-1305.071045,0.007584,0.004960,0.125973,251.558441,12.814998,1.259734,-1305.071045,0.126997,0.000000
81.490005,58.051010,-1305.071045,0.007597,0.004978,0.126433,258.223785,13.154547,1.264329,-1305.071045,0.127465,0.000000
81.770004,59.312233,-1305.026611,0.007575,0.004996,0.126893,263.833984,13.440345,1.268928,-1305.026611,0.127933,0.000000
82.050003,61.016586,-1304.937622,0.007649,0.005016,0.127396,271.415344,13.826556,1.273958,-1304.937622,0.128401,0.000000
82.330002,62.294937,-1305.026611,0.007675,0.005031,0.127794,277.101715,14.116234,1.277943,-1305.026611,0.128870,0.000000
82.610001,64.015297,-1305.071045,0.007623,0.005054,0.128367,284.754272,14.506074,1.283670,-1305.071045,0.129338,0.000000
82.890007,65.348763,-1305.026611,0.007662,0.005068,0.128722,290.685822,14.808242,1.287224,-1305.026611,0.129798,0.000000
83.170006,66.579079,-1305.026611,0.007670,0.005083,0.129113,296.158539,15.087035,1.291126,-1305.026611,0.130266,0.000000
83.450005,67.382286,-1304.937622,0.007713,0.005087,0.129199,299.731384,15.269045,1.291993,-1304.937622,0.129416,0.000000
83.730003,67.028160,-1305.026611,0.007683,0.005087,0.129199,298.156158,15.188798,1.291993,-1305.026611,0.129199,0.000000
84.010002,66.726540,-1305.071045,0.007718,0.005086,0.129191,296.814484,15.120450,1.291906,-1305.071045,0.129199,0.000000
84.290001,66.472588,-1305.026611,0.007683,0.005086,0.129182,295.684845,15.062903,1.291823,-1305.026611,0.129199,0.000000
84.570007,66.277092,-1305.026611,0.007675,0.005086,0.129182,294.815216,15.018603,1.291823,-1305.026611,0.129199,0.000000
84.850006,66.083824,-1305.026611,0.007700,0.005086,0.129182,293.955536,14.974809,1.291823,-1305.026611,0.129199,0.000000
85.130005,65.924446,-1305.071045,0.007692,0.005086,0.129174,293.246582,14.938693,1.291735,-1305.071045,0.129199,0.000000
85.410004,65.770287,-1305.071045,0.007662,0.005086,0.129174,292.560852,14.903760,1.291735,-1305.071045,0.129199,0.000000
85.690002,65.650764,-1305.071045,0.007670,0.005086,0.129174,292.029175,14.876676,1.291735,-1305.071045,0.129199,0.000000
85.970001,65.537560,-1304.982178,0.007731,0.005086,0.129174,291.525635,14.851024,1.291735,-1304.982178,0.129199,0.000000
86.250008,65.432549,-1305.026611,0.007670,0.005085,0.129165,291.058502,14.827228,1.291648,-1305.026611,0.129199,0.000000
86.530006,65.334618,-1305.071045,0.007748,0.005085,0.129165,290.622894,14.805036,1.291648,-1305.071045,0.129199,0.000000
86.810005,65.247856,-1305.071045,0.007662,0.005085,0.129165,290.236969,14.785376,1.291648,-1305.071045,0.129199,0.000000
87.090004,65.165550,-1305.026611,0.007718,0.005085,0.129165,289.870850,14.766726,1.291648,-1305.026611,0.129199,0.000000
87.370003,65.090340,-1305.026611,0.007722,0.005085,0.129165,289.536285,14.749682,1.291648,-1305.026611,0.129199,0.000000
87.650002,65.024055,-1305.071045,0.007743,0.005085,0.129165,289.241455,14.734662,1.291648,-1305.071045,0.129199,0.000000
87.930008,64.960381,-1305.071045,0.007675,0.005085,0.129165,288.958191,14.720233,1.291648,-1305.071045,0.129199,0.000000
88.210007,64.900063,-1305.115601,0.007705,0.005085,0.129165,288.689911,14.706564,1.291648,-1305.115601,0.129199,0.000000
88.490005,64.835258,-1305.026611,0.007696,0.005085,0.129165,288.401642,14.691880,1.291648,-1305.026611,0.129199,0.000000
88.770004,64.782021,-1305.071045,0.007696,0.005085,0.129165,288.164825,14.679815,1.291648,-1305.071045,0.129199,0.000000
89.050003,64.724663,-1305.071045,0.007743,0.005085,0.129165,287.909668,14.666818,1.291648,-1305.071045,0.129199,0.000000
89.330002,64.666954,-1305.160034,0.007687,0.005085,0.129165,287.652985,14.653742,1.291648,-1305.160034,0.129199,0.000000
89.610001,64.615562,-1305.160034,0.007687,0.005085,0.129165,287.424377,14.642096,1.291648,-1305.160034,0.129199,0.000000
89.890007,64.577950,-1305.115601,0.007726,0.005085,0.129165,287.257080,14.633573,1.291648,-1305.115601,0.129199,0.000000
90.170006,64.528801,-1305.071045,0.007743,0.005085,0.129165,287.038452,14.622436,1.291648,-1305.071045,0.129199,0.000000
90.450005,64.488579,-1305.071045,0.007726,0.005085,0.129165,286.859528,14.613321,1.291648,-1305.071045,0.129199,0.000000
90.730003,64.452095,-1305.071045,0.007743,0.005085,0.129165,286.697235,14.605054,1.291648,-1305.071045,0.129199,0.000000
91.010002,64.407402,-1305.115601,0.007718,0.005085,0.129165,286.498444,14.594926,1.291648,-1305.115601,0.129199,0.000000
91.290001,64.379112,-1305.115601,0.007726,0.005085,0.129165,286.372589,14.588515,1.291648,-1305.115601,0.129199,0.000000
91.570007,64.335915,-1305.071045,0.007718,0.005085,0.129165,286.180450,14.578727,1.291648,-1305.071045,0.129199,0.000000
91.850006,64.306496,-1305.071045,0.007739,0.005085,0.129165,286.049591,14.572061,1.291648,-1305.071045,0.129199,0.000000
92.130005,64.267387,-1305.115601,0.007705,0.005085,0.129165,285.875610,14.563198,1.291648,-1305.115601,0.129199,0.000000
92.410004,64.229042,-1305.026611,0.007735,0.005085,0.129165,285.705048,14.554509,1.291648,-1305.026611,0.129199,0.000000
92.690002,64.204094,-1305.160034,0.007743,0.005085,0.129165,285.594086,14.548856,1.291648,-1305.160034,0.129199,0.000000
92.970001,64.167595,-1305.071045,0.007726,0.005085,0.129165,285.431732,14.540585,1.291648,-1305.071045,0.129199,0.000000
93.250008,64.130730,-1305.115601,0.007752,0.005085,0.129165,285.267731,14.532230,1.291648,-1305.115601,0.129199,0.000000
93.530006,64.105034,-1305.160034,0.007739,0.005085,0.129165,285.153442,14.526409,1.291648,-1305.160034,0.129199,0.000000
93.810005,64.080086,-1305.115601,0.007739,0.005085,0.129165,285.042450,14.520755,1.291648,-1305.115601,0.129199,0.000000
94.090004,64.053658,-1305.160034,0.007705,0.005085,0.129156,284.924896,14.514767,1.291561,-1305.160034,0.129199,0.000000
94.370003,64.024239,-1305.204590,0.007731,0.005085,0.129156,284.794037,14.508101,1.291561,-1305.204590,0.129199,0.000000
94.650002,64.006355,-1305.249023,0.007722,0.005085,0.129156,284.714478,14.504047,1.291561,-1305.249023,0.129199,0.000000
94.930008,63.978065,-1305.204590,0.007670,0.005085,0.129156,284.588654,14.497637,1.291561,-1305.204590,0.129199,0.000000
95.210007,63.958702,-1305.160034,0.007731,0.005085,0.129156,284.502502,14.493249,1.291561,-1305.160034,0.129199,0.000000
95.490005,63.928169,-1305.115601,0.007687,0.005085,0.129156,284.366699,14.486330,1.291561,-1305.115601,0.129199,0.000000
95.770004,63.898750,-1305.115601,0.007713,0.005085,0.129156,284.235840,14.479664,1.291561,-1305.115601,0.129199,0.000000
96.050003,63.877892,-1305.160034,0.007735,0.005085,0.129156,284.143066,14.474936,1.291561,-1305.160034,0.129199,0.000000
96.330002,63.854057,-1305.204590,0.007709,0.005085,0.129156,284.037018,14.469536,1.291561,-1305.204590,0.129199,0.000000
96.610008,63.835442,-1305.160034,0.007687,0.005085,0.129156,283.954224,14.465318,1.291561,-1305.160034,0.129199,0.000000
96.890007,63.810860,-1305.115601,0.007748,0.005085,0.129156,283.844879,14.459747,1.291561,-1305.115601,0.129199,0.000000
97.170006,63.790016,-1305.160034,0.007713,0.005085,0.129156,283.752167,14.455024,1.291561,-1305.160034,0.129199,0.000000
97.450005,63.779213,-1305.249023,0.007731,0.005085,0.129156,283.704102,14.452577,1.291561,-1305.249023,0.129199,0.000000
97.730003,63.755760,-1305.204590,0.007748,0.005085,0.129156,283.599792,14.447262,1.291561,-1305.204590,0.129199,0.000000
98.010002,63.738258,-1305.204590,0.007735,0.005085,0.129156,283.521942,14.443295,1.291561,-1305.204590,0.129199,0.000000
98.290001,63.714043,-1305.204590,0.007700,0.005085,0.129156,283.414215,14.437809,1.291561,-1305.204590,0.129199,0.000000
98.570007,63.708458,-1305.204590,0.007713,0.005085,0.129156,283.389374,14.436543,1.291561,-1305.204590,0.129199,0.000000
98.850006,63.687233,-1305.204590,0.007726,0.005085,0.129156,283.294952,14.431733,1.291561,-1305.204590,0.129199,0.000000
99.130005,63.677559,-1305.249023,0.007731,0.005085,0.129156,283.251923,14.429541,1.291561,-1305.249023,0.129199,0.000000
99.410004,63.660805,-1305.204590,0.007709,0.005085,0.129156,283.177399,14.425744,1.291561,-1305.204590,0.129199,0.000000
99.690002,63.635857,-1305.160034,0.007752,0.005085,0.129156,283.066437,14.420092,1.291561,-1305.160034,0.129199,0.000000
99.970001,63.615364,-1305.204590,0.007743,0.005085,0.129156,282.975281,14.415448,1.291561,-1305.204590,0.129199,0.000000
100.250008,63.594521,-1305.204590,0.007735,0.005085,0.129156,282.882568,14.410724,1.291561,-1305.204590,0.129199,0.000000
100.530006,63.568077,-1305.204590,0.007739,0.005085,0.129156,282.764923,14.404733,1.291561,-1305.204590,0.129199,0.000000
100.810005,63.546486,-1305.204590,0.007705,0.005085,0.129156,282.668884,14.399839,1.291561,-1305.204590,0.129199,0.000000
101.090004,63.543495,-1305.204590,0.007709,0.005085,0.129156,282.655579,14.399162,1.291561,-1305.204590,0.129199,0.000000
101.370003,63.529350,-1305.249023,0.007739,0.005085,0.129156,282.592651,14.395956,1.291561,-1305.249023,0.129199,0.000000
101.650002,63.521904,-1305.249023,0.007718,0.005085,0.129156,282.559540,14.394270,1.291561,-1305.249023,0.129199,0.000000
101.930008,63.492867,-1305.204590,0.007756,0.005085,0.129156,282.430389,14.387690,1.291561,-1305.204590,0.129199,0.000000
102.210007,63.477592,-1305.160034,0.007696,0.005085,0.129156,282.362427,14.384228,1.291561,-1305.160034,0.129199,0.000000
102.490005,63.458229,-1305.204590,0.007739,0.005085,0.129156,282.276306,14.379840,1.291561,-1305.204590,0.129199,0.000000
102.770004,63.453758,-1305.204590,0.007705,0.005085,0.129156,282.256409,14.378827,1.291561,-1305.204590,0.129199,0.000000
103.050003,63.436256,-1305.160034,0.007756,0.005085,0.129156,282.178558,14.374861,1.291561,-1305.160034,0.129199,0.000000
103.330002,63.425835,-1305.338013,0.007683,0.005085,0.129156,282.132202,14.372499,1.291561,-1305.338013,0.129199,0.000000
103.610008,63.404976,-1305.249023,0.007743,0.005085,0.129156,282.039429,14.367772,1.291561,-1305.249023,0.129199,0.000000
103.890007,63.392326,-1305.249023,0.007743,0.005085,0.129156,281.983154,14.364906,1.291561,-1305.249023,0.129199,0.000000
104.170006,63.392693,-1305.249023,0.007726,0.005085,0.129156,281.984772,14.364990,1.291561,-1305.249023,0.129199,0.000000
104.450005,63.375191,-1305.204590,0.007700,0.005085,0.129156,281.906921,14.361024,1.291561,-1305.204590,0.129199,0.000000
104.730003,63.358437,-1305.338013,0.007748,0.005085,0.129156,281.832397,14.357227,1.291561,-1305.338013,0.129199,0.000000
105.010002,63.338692,-1305.204590,0.007705,0.005085,0.129156,281.744568,14.352753,1.291561,-1305.204590,0.129199,0.000000
105.290009,63.334969,-1305.249023,0.007752,0.005085,0.129156,281.727997,14.351909,1.291561,-1305.249023,0.129199,0.000000
105.570007,63.323799,-1305.204590,0.007722,0.005085,0.129156,281.678314,14.349378,1.291561,-1305.204590,0.129199,0.000000
105.850006,63.322319,-1305.293457,0.007748,0.005085,0.129156,281.671753,14.349043,1.291561,-1305.293457,0.129199,0.000000
106.130005,63.303322,-1305.293457,0.007756,0.005085,0.129156,281.587250,14.344738,1.291561,-1305.293457,0.129199,0.000000
106.410004,63.289543,-1305.249023,0.007743,0.005085,0.129156,281.525940,14.341616,1.291561,-1305.249023,0.129199,0.000000
106.690002,63.283592,-1305.249023,0.007713,0.005085,0.129156,281.499481,14.340266,1.291561,-1305.249023,0.129199,0.000000
106.970009,63.269814,-1305.249023,0.007765,0.005085,0.129156,281.438202,14.337145,1.291561,-1305.249023,0.129199,0.000000
107.250008,63.245232,-1305.249023,0.007735,0.005085,0.129156,281.328827,14.331574,1.291561,-1305.249023,0.129199,0.000000
107.530006,63.241875,-1305.338013,0.007696,0.005085,0.129156,281.313904,14.330813,1.291561,-1305.338013,0.129199,0.000000
107.810005,63.234062,-1305.249023,0.007726,0.005085,0.129156,281.279144,14.329043,1.291561,-1305.249023,0.129199,0.000000
108.090004,63.222145,-1305.293457,0.007761,0.005085,0.129156,281.226135,14.326344,1.291561,-1305.293457,0.129199,0.000000
108.370003,63.206139,-1305.204590,0.007739,0.005085,0.129156,281.154938,14.322716,1.291561,-1305.204590,0.129199,0.000000
108.650002,63.192726,-1305.293457,0.007765,0.005085,0.129156,281.095276,14.319676,1.291561,-1305.293457,0.129199,0.000000
108.930008,63.180443,-1305.338013,0.007722,0.005085,0.129156,281.040649,14.316894,1.291561,-1305.338013,0.129199,0.000000
109.210007,63.165169,-1305.293457,0.007739,0.005085,0.129156,280.972717,14.313432,1.291561,-1305.293457,0.129199,0.000000
109.490005,63.161079,-1305.249023,0.007752,0.005085,0.129156,280.954498,14.312505,1.291561,-1305.249023,0.129199,0.000000
109.770004,63.158836,-1305.338013,0.007774,0.005085,0.129156,280.944550,14.311996,1.291561,-1305.338013,0.129199,0.000000
110.050003,63.138733,-1305.338013,0.007748,0.005085,0.129156,280.855103,14.307441,1.291561,-1305.338013,0.129199,0.000000
110.330002,63.126076,-1305.293457,0.007739,0.005085,0.129156,280.798798,14.304573,1.291561,-1305.293457,0.129199,0.000000
110.610008,63.127190,-1305.249023,0.007726,0.005085,0.129156,280.803772,14.304826,1.291561,-1305.249023,0.129199,0.000000
110.890007,63.116760,-1305.293457,0.007718,0.005085,0.129156,280.757385,14.302463,1.291561,-1305.293457,0.129199,0.000000
111.170006,63.104851,-1305.249023,0.007748,0.005085,0.129156,280.704407,14.299764,1.291561,-1305.249023,0.129199,0.000000
111.450005,63.087349,-1305.382446,0.007683,0.005085,0.129156,280.626556,14.295797,1.291561,-1305.382446,0.129199,0.000000
111.730003,63.094795,-1305.293457,0.007718,0.005085,0.129156,280.659668,14.297484,1.291561,-1305.293457,0.129199,0.000000
112.010002,63.065750,-1305.293457,0.007743,0.005085,0.129156,280.530457,14.290904,1.291561,-1305.293457,0.129199,0.000000
112.290009,63.070587,-1305.249023,0.007735,0.005085,0.129156,280.551971,14.292000,1.291561,-1305.249023,0.129199,0.000000
112.570007,63.053085,-1305.293457,0.007692,0.005085,0.129156,280.474121,14.288033,1.291561,-1305.293457,0.129199,0.000000
112.850006,63.048622,-1305.338013,0.007752,0.005085,0.129156,280.454285,14.287022,1.291561,-1305.338013,0.129199,0.000000
113.130005,63.041542,-1305.338013,0.007743,0.005085,0.129156,280.422791,14.285418,1.291561,-1305.338013,0.129199,0.000000
113.410004,63.028885,-1305.293457,0.007752,0.005085,0.129156,280.366486,14.282550,1.291561,-1305.293457,0.129199,0.000000
113.690002,63.019577,-1305.249023,0.007700,0.005085,0.129156,280.325073,14.280439,1.291561,-1305.249023,0.129199,0.000000
113.800003,63.019203,-1305.293457,0.007735,0.005085,0.129156,280.323425,14.280355,1.291561,-1305.293457,0.129199,0.000000