File: Data/Automembrane/AutoNoheat12-2-3_12132023_183350.csv
Time (sec),S:Load (lbs),S:HL1 (DIM),S:LVDT (in),S:Position (in),Ch:Position (mm),Ch:Load (N),Ch:Stress (MPa),Ch:Strain (mm/mm),Ch:HL1 (DIM),Set Point (),Cycles ()
0.210000,0.003357,-1304.759766,-0.000056,-0.000000,-0.000000,0.014932,0.000761,-0.000000,-1304.759766,0.000208,0.000000
0.460000,0.020859,-1304.804199,-0.000056,0.000033,0.000841,0.092784,0.004727,0.008414,-1304.804199,0.001388,0.000000
0.710000,0.022720,-1304.759766,0.000013,0.000180,0.004579,0.101065,0.005149,0.045790,-1304.759766,0.005568,0.000000
0.960000,-0.017868,-1304.715210,0.000177,0.000341,0.008655,-0.079481,-0.004049,0.086549,-1304.715210,0.009731,0.000000
1.210000,-0.003349,-1304.759766,0.000302,0.000506,0.012852,-0.014898,-0.000759,0.128524,-1304.759766,0.013893,0.000000
1.460000,-0.010422,-1304.804199,0.000513,0.000670,0.017015,-0.046358,-0.002362,0.170150,-1304.804199,0.018056,0.000000
1.710000,-0.018990,-1304.759766,0.000681,0.000832,0.021143,-0.084470,-0.004303,0.211432,-1304.759766,0.022218,0.000000
1.960000,-0.021225,-1304.759766,0.000845,0.000996,0.025297,-0.094413,-0.004810,0.252971,-1304.759766,0.026381,0.000000
2.210000,0.029793,-1304.715210,0.001039,0.001158,0.029408,0.132525,0.006751,0.294079,-1304.715210,0.030544,0.000000
2.460000,0.030540,-1304.804199,0.001212,0.001328,0.033726,0.135851,0.006921,0.337264,-1304.804199,0.034706,0.000000
2.710000,-0.003349,-1304.715210,0.001324,0.001491,0.037863,-0.014898,-0.000759,0.378633,-1304.715210,0.038886,0.000000
2.960000,0.017876,-1304.759766,0.001548,0.001654,0.042009,0.079515,0.004051,0.420085,-1304.759766,0.043049,0.000000
3.210000,0.008942,-1304.759766,0.001686,0.001812,0.046033,0.039774,0.002026,0.460326,-1304.759766,0.047212,0.000000
3.460000,0.010056,-1304.759766,0.001901,0.001973,0.050109,0.044729,0.002279,0.501086,-1304.759766,0.051375,0.000000
3.710000,0.003357,-1304.804199,0.002048,0.002148,0.054549,0.014932,0.000761,0.545487,-1304.804199,0.055537,0.000000
3.960000,0.029793,-1304.626343,0.002238,0.002307,0.058590,0.132525,0.006751,0.585898,-1304.626343,0.059700,0.000000
4.210000,0.028679,-1304.759766,0.002371,0.002474,0.062839,0.127570,0.006499,0.628395,-1304.759766,0.063863,0.000000
4.460000,0.032028,-1304.759766,0.002578,0.002637,0.066976,0.142469,0.007258,0.669760,-1304.759766,0.068043,0.000000
4.710000,0.212631,-1304.759766,0.002751,0.002801,0.071147,0.945831,0.048183,0.711473,-1304.759766,0.072205,0.000000
4.960000,0.579788,-1304.715210,0.002915,0.002964,0.075276,2.579027,0.131382,0.752755,-1304.715210,0.076368,0.000000
5.210000,0.525795,-1304.715210,0.002962,-0.000000,-0.000000,2.338853,0.119147,-0.000000,-1304.715210,0.000234,0.000000
5.460000,0.525795,-1304.804199,0.003005,-0.000000,-0.000000,2.338853,0.119147,-0.000000,-1304.804199,0.000234,0.000000
5.710000,0.615532,-1304.804199,0.002953,-0.000000,-0.000000,2.738023,0.139482,-0.000000,-1304.804199,0.000451,0.000000
5.960001,0.576439,-1304.759766,0.002966,-0.000000,-0.000000,2.564128,0.130623,-0.000000,-1304.759766,0.000867,0.000000
6.210001,0.560425,-1304.759766,0.002997,0.000000,0.000009,2.492894,0.126994,0.000087,-1304.759766,0.001283,0.000000
6.460001,0.746239,-1304.715210,0.002971,0.000032,0.000815,3.319436,0.169100,0.008153,-1304.715210,0.001700,0.000000
6.710001,0.809914,-1304.804199,0.003009,0.000051,0.001283,3.602676,0.183529,0.012835,-1304.804199,0.002116,0.000000
6.960001,0.853111,-1304.804199,0.002988,0.000061,0.001544,3.794828,0.193318,0.015439,-1304.804199,0.002532,0.000000
7.210001,0.957375,-1304.804199,0.003053,0.000085,0.002168,4.258615,0.216944,0.021684,-1304.804199,0.002949,0.000000
7.460001,1.028870,-1304.759766,0.003087,0.000104,0.002645,4.576641,0.233145,0.026453,-1304.759766,0.003365,0.000000
7.710001,1.051956,-1304.759766,0.003031,0.000115,0.002914,4.679335,0.238377,0.029140,-1304.759766,0.003781,0.000000
7.960001,1.150261,-1304.759766,0.003053,0.000132,0.003356,5.116616,0.260653,0.033564,-1304.759766,0.004197,0.000000
8.210000,1.181915,-1304.715210,0.003096,0.000147,0.003729,5.257422,0.267826,0.037293,-1304.715210,0.004622,0.000000
8.460000,1.336823,-1304.759766,0.003143,0.000166,0.004224,5.946484,0.302928,0.042236,-1304.759766,0.005039,0.000000
8.710000,1.394539,-1304.804199,0.003152,0.000177,0.004484,6.203219,0.316007,0.044836,-1304.804199,0.005455,0.000000
8.960000,1.407944,-1304.759766,0.003109,0.000185,0.004700,6.262846,0.319045,0.047005,-1304.759766,0.005871,0.000000
9.210000,1.636208,-1304.759766,0.003191,0.000213,0.005403,7.278215,0.370770,0.054029,-1304.759766,0.006287,0.000000
9.460000,1.763931,-1304.804199,0.003199,0.000234,0.005932,7.846358,0.399713,0.059321,-1304.804199,0.006704,0.000000
9.710000,1.790741,-1304.759766,0.003186,0.000241,0.006123,7.965614,0.405788,0.061228,-1304.759766,0.007120,0.000000
9.960000,1.932991,-1304.759766,0.003169,0.000258,0.006556,8.598373,0.438022,0.065562,-1304.759766,0.007536,0.000000
10.210000,2.002991,-1304.759766,0.003242,0.000273,0.006929,8.909748,0.453884,0.069294,-1304.759766,0.007952,0.000000
10.460000,2.242805,-1304.804199,0.003268,0.000293,0.007441,9.976497,0.508227,0.074407,-1304.804199,0.008369,0.000000
10.710000,2.358986,-1304.715210,0.003225,0.000310,0.007866,10.493294,0.534554,0.078658,-1304.715210,0.008785,0.000000
10.960001,2.490799,-1304.759766,0.003242,0.000323,0.008204,11.079627,0.564423,0.082041,-1304.759766,0.009201,0.000000
11.210001,2.636024,-1304.759766,0.003311,0.000341,0.008672,11.725622,0.597332,0.086723,-1304.759766,0.009618,0.000000
11.460001,2.765984,-1304.759766,0.003281,0.000358,0.009097,12.303709,0.626781,0.090974,-1304.759766,0.010034,0.000000
11.710001,2.900414,-1304.715210,0.003320,0.000372,0.009444,12.901684,0.657243,0.094441,-1304.715210,0.010450,0.000000
11.960001,2.995369,-1304.670776,0.003363,0.000387,0.009817,13.324066,0.678760,0.098173,-1304.670776,0.010866,0.000000
12.210001,3.112289,-1304.759766,0.003359,0.000406,0.010320,13.844154,0.705255,0.103203,-1304.759766,0.011283,0.000000
12.460001,3.417641,-1304.759766,0.003324,0.000426,0.010815,15.202425,0.774448,0.108146,-1304.759766,0.011699,0.000000
12.710001,3.490623,-1304.759766,0.003376,0.000440,0.011179,15.527069,0.790987,0.111787,-1304.759766,0.012115,0.000000
12.960001,3.725220,-1304.759766,0.003432,0.000461,0.011708,16.570604,0.844147,0.117078,-1304.759766,0.012531,0.000000
13.210001,3.897255,-1304.804199,0.003454,0.000480,0.012185,17.335855,0.883131,0.121847,-1304.804199,0.012948,0.000000
13.460001,3.976196,-1304.759766,0.003415,0.000494,0.012549,17.687004,0.901019,0.125488,-1304.759766,0.013373,0.000000
13.710001,3.972473,-1304.759766,0.003423,0.000506,0.012844,17.670443,0.900175,0.128437,-1304.759766,0.013789,0.000000
13.960001,4.249519,-1304.759766,0.003492,0.000525,0.013338,18.902805,0.962955,0.133380,-1304.759766,0.014205,0.000000
14.210001,4.506081,-1304.804199,0.003458,0.000545,0.013832,20.044048,1.021092,0.138323,-1304.804199,0.014621,0.000000
14.460001,4.578323,-1304.715210,0.003466,0.000559,0.014188,20.365400,1.037463,0.141881,-1304.715210,0.015038,0.000000
14.710001,4.553001,-1304.804199,0.003462,0.000568,0.014431,20.252762,1.031725,0.144307,-1304.804199,0.015454,0.000000
14.960001,4.887016,-1304.759766,0.003544,0.000588,0.014942,21.738535,1.107414,0.149424,-1304.759766,0.015870,0.000000
15.210001,5.054214,-1304.715210,0.003553,0.000606,0.015394,22.482269,1.145301,0.153935,-1304.715210,0.016287,0.000000
15.460001,5.150658,-1304.759766,0.003591,0.000623,0.015818,22.911270,1.167156,0.158182,-1304.759766,0.016703,0.000000
15.710001,5.086983,-1304.715210,0.003579,0.000637,0.016174,22.628029,1.152727,0.161740,-1304.715210,0.017119,0.000000
15.960001,5.342804,-1304.759766,0.003622,0.000653,0.016599,23.765980,1.210697,0.165987,-1304.759766,0.017535,0.000000
16.210001,5.276520,-1304.759766,0.003579,0.000659,0.016729,23.471132,1.195676,0.167289,-1304.759766,0.017952,0.000000
16.460001,5.672722,-1304.759766,0.003570,0.000682,0.017319,25.233526,1.285457,0.173185,-1304.759766,0.018368,0.000000
16.710001,5.937851,-1304.759766,0.003630,0.000702,0.017822,26.412880,1.345536,0.178216,-1304.759766,0.018784,0.000000
16.960001,5.922958,-1304.715210,0.003613,0.000715,0.018160,26.346634,1.342162,0.181599,-1304.715210,0.019200,0.000000
17.210001,6.275597,-1304.804199,0.003648,0.000738,0.018750,27.915249,1.422071,0.187496,-1304.804199,0.019617,0.000000
17.460001,6.125526,-1304.759766,0.003734,0.000748,0.019010,27.247702,1.388064,0.190096,-1304.759766,0.020033,0.000000
17.710001,6.478912,-1304.759766,0.003712,0.000772,0.019608,28.819641,1.468143,0.196080,-1304.759766,0.020449,0.000000
17.960001,6.586899,-1304.759766,0.003682,0.000786,0.019973,29.299990,1.492613,0.199725,-1304.759766,0.020866,0.000000
18.210001,6.779785,-1304.759766,0.003721,0.000801,0.020354,30.157991,1.536321,0.203540,-1304.759766,0.021282,0.000000
18.460001,6.891129,-1304.759766,0.003704,0.000816,0.020736,30.653271,1.561552,0.207355,-1304.759766,0.021707,0.000000
18.710001,7.080292,-1304.715210,0.003721,0.000831,0.021117,31.494711,1.604417,0.211171,-1304.715210,0.022123,0.000000
18.960001,7.152534,-1304.804199,0.003794,0.000846,0.021499,31.816063,1.620788,0.214986,-1304.804199,0.022539,0.000000
19.210001,7.475006,-1304.804199,0.003816,0.000870,0.022097,33.250488,1.693861,0.220970,-1304.804199,0.022956,0.000000
19.460001,7.425110,-1304.759766,0.003781,0.000885,0.022478,33.028538,1.682554,0.224785,-1304.759766,0.023372,0.000000
19.710001,7.718910,-1304.759766,0.003811,0.000903,0.022930,34.335426,1.749130,0.229297,-1304.759766,0.023788,0.000000
19.960001,7.830620,-1304.759766,0.003829,0.000918,0.023311,34.832336,1.774444,0.233112,-1304.759766,0.024204,0.000000
20.210001,8.140068,-1304.804199,0.003846,0.000938,0.023814,36.208832,1.844566,0.238142,-1304.804199,0.024621,0.000000
20.460001,8.145653,-1304.759766,0.003876,0.000949,0.024100,36.233673,1.845831,0.241003,-1304.759766,0.025037,0.000000
20.710001,8.203743,-1304.804199,0.003859,0.000961,0.024421,36.492073,1.858995,0.244213,-1304.804199,0.025453,0.000000
20.960001,8.762299,-1304.759766,0.003880,0.000987,0.025072,38.976650,1.985565,0.250715,-1304.759766,0.025869,0.000000
21.210001,8.801025,-1304.715210,0.003923,0.001002,0.025462,39.148914,1.994341,0.254617,-1304.715210,0.026286,0.000000
21.460001,8.907524,-1304.804199,0.003941,0.001020,0.025895,39.622646,2.018474,0.258955,-1304.804199,0.026702,0.000000
21.710001,9.020355,-1304.759766,0.003911,0.001034,0.026260,40.124542,2.044042,0.262596,-1304.759766,0.027118,0.000000
21.960001,9.245270,-1304.715210,0.003954,0.001052,0.026728,41.125015,2.095008,0.267282,-1304.715210,0.027534,0.000000
22.210001,9.278404,-1304.804199,0.004005,0.001064,0.027032,41.272404,2.102517,0.270317,-1304.804199,0.027951,0.000000
22.460001,9.458633,-1304.715210,0.004001,0.001081,0.027448,42.074104,2.143357,0.274477,-1304.715210,0.028367,0.000000
22.710001,9.688759,-1304.670776,0.004018,0.001098,0.027881,43.097752,2.195504,0.278814,-1304.670776,0.028783,0.000000
22.960001,10.079750,-1304.759766,0.004010,0.001120,0.028454,44.836967,2.284104,0.284537,-1304.759766,0.029200,0.000000
23.210001,10.064484,-1304.759766,0.004061,0.001136,0.028861,44.769058,2.280644,0.288613,-1304.759766,0.029616,0.000000
23.460001,10.069328,-1304.759766,0.004066,0.001151,0.029243,44.790607,2.281743,0.292429,-1304.759766,0.030041,0.000000
23.710001,10.141197,-1304.759766,0.004049,0.001165,0.029590,45.110298,2.298028,0.295899,-1304.759766,0.030457,0.000000
23.960001,10.540749,-1304.759766,0.004148,0.001185,0.030110,46.887592,2.388568,0.301104,-1304.759766,0.030873,0.000000
24.210001,10.478195,-1304.759766,0.004087,0.001198,0.030422,46.609341,2.374393,0.304222,-1304.759766,0.031290,0.000000
24.460001,10.563461,-1304.804199,0.004152,0.001212,0.030778,46.988621,2.393715,0.307780,-1304.804199,0.031706,0.000000
24.710001,10.986481,-1304.715210,0.004186,0.001235,0.031359,48.870308,2.489572,0.313590,-1304.715210,0.032122,0.000000
24.960001,11.031166,-1304.759766,0.004148,0.001251,0.031775,49.069077,2.499698,0.317753,-1304.759766,0.032538,0.000000
25.210001,11.028557,-1304.759766,0.004161,0.001266,0.032157,49.057472,2.499107,0.321568,-1304.759766,0.032955,0.000000
25.460001,11.178627,-1304.759766,0.004221,0.001282,0.032556,49.725018,2.533113,0.325558,-1304.759766,0.033371,0.000000
25.710001,11.141014,-1304.715210,0.004178,0.001297,0.032955,49.557705,2.524590,0.329547,-1304.715210,0.033787,0.000000
25.960001,11.452690,-1304.759766,0.004208,0.001316,0.033414,50.944111,2.595217,0.334142,-1304.759766,0.034203,0.000000
26.210001,11.420670,-1304.759766,0.004204,0.001327,0.033718,50.801674,2.587961,0.337177,-1304.759766,0.034620,0.000000
26.460001,11.464233,-1304.759766,0.004238,0.001339,0.034021,50.995457,2.597832,0.340213,-1304.759766,0.035036,0.000000
26.710001,11.922623,-1304.715210,0.004286,0.001363,0.034628,53.034473,2.701705,0.346284,-1304.715210,0.035452,0.000000
26.960001,11.988533,-1304.759766,0.004329,0.001381,0.035071,53.327660,2.716640,0.350708,-1304.759766,0.035869,0.000000
27.210001,12.014603,-1304.804199,0.004337,0.001397,0.035478,53.443623,2.722548,0.354785,-1304.804199,0.036285,0.000000
27.460001,12.203018,-1304.759766,0.004350,0.001415,0.035929,54.281734,2.765243,0.359293,-1304.759766,0.036701,0.000000
27.710001,11.960609,-1304.759766,0.004359,0.001422,0.036111,53.203449,2.710313,0.361113,-1304.759766,0.037117,0.000000
27.960001,12.489372,-1304.759766,0.004381,0.001446,0.036718,55.555504,2.830132,0.367184,-1304.759766,0.037534,0.000000
28.210001,12.465172,-1304.715210,0.004389,0.001458,0.037022,55.447853,2.824648,0.370219,-1304.715210,0.037950,0.000000
28.460001,12.359421,-1304.759766,0.004398,0.001472,0.037386,54.977448,2.800685,0.373861,-1304.759766,0.038366,0.000000
28.710001,12.953720,-1304.759766,0.004419,0.001496,0.037993,57.621025,2.935355,0.379932,-1304.759766,0.038791,0.000000
28.960001,12.955956,-1304.804199,0.004449,0.001512,0.038409,57.630970,2.935861,0.384095,-1304.804199,0.039207,0.000000
29.210001,13.049797,-1304.759766,0.004424,0.001528,0.038808,58.048397,2.957126,0.388084,-1304.759766,0.039624,0.000000
29.460001,12.938454,-1304.715210,0.004428,0.001540,0.039112,57.553116,2.931895,0.391120,-1304.715210,0.040040,0.000000
29.710001,13.133949,-1304.715210,0.004493,0.001558,0.039563,58.422726,2.976196,0.395631,-1304.715210,0.040456,0.000000
29.960001,13.284760,-1304.804199,0.004449,0.001573,0.039953,59.093563,3.010370,0.399534,-1304.804199,0.040872,0.000000
30.210001,13.079582,-1304.715210,0.004480,0.001580,0.040135,58.180889,2.963876,0.401354,-1304.715210,0.041289,0.000000
30.460001,13.677246,-1304.759766,0.004527,0.001606,0.040786,60.839428,3.099308,0.407856,-1304.759766,0.041705,0.000000
30.710001,13.847794,-1304.759766,0.004493,0.001624,0.041254,61.598061,3.137955,0.412542,-1304.759766,0.042121,0.000000
30.960001,13.690277,-1304.715210,0.004549,0.001637,0.041592,60.897392,3.102261,0.415922,-1304.715210,0.042538,0.000000
31.210001,13.697350,-1304.759766,0.004523,0.001654,0.042009,60.928852,3.103864,0.420085,-1304.759766,0.042954,0.000000
31.460001,13.812790,-1304.804199,0.004605,0.001668,0.042364,61.442360,3.130023,0.423640,-1304.804199,0.043370,0.000000
31.710001,14.175850,-1304.759766,0.004562,0.001689,0.042893,63.057331,3.212293,0.428931,-1304.759766,0.043786,0.000000
31.960001,14.240273,-1304.670776,0.004570,0.001705,0.043318,63.343895,3.226892,0.433181,-1304.670776,0.044203,0.000000
32.210003,14.136009,-1304.759766,0.004583,0.001718,0.043639,62.880108,3.203265,0.436391,-1304.759766,0.044619,0.000000
32.460003,14.271553,-1304.759766,0.004613,0.001735,0.044072,63.483040,3.233980,0.440725,-1304.759766,0.045035,0.000000
32.710003,14.385124,-1304.759766,0.004665,0.001751,0.044471,63.988228,3.259716,0.444714,-1304.759766,0.045451,0.000000
32.960003,14.365013,-1304.759766,0.004648,0.001765,0.044827,63.898769,3.255158,0.448272,-1304.759766,0.045868,0.000000
33.210003,14.473007,-1304.759766,0.004674,0.001782,0.045252,64.379150,3.279630,0.452518,-1304.759766,0.046284,0.000000
33.460003,14.652489,-1304.759766,0.004717,0.001799,0.045686,65.177528,3.320302,0.456856,-1304.759766,0.046700,0.000000
33.710003,15.009590,-1304.804199,0.004712,0.001822,0.046275,66.765991,3.401222,0.462753,-1304.804199,0.047125,0.000000
33.960003,14.877769,-1304.804199,0.004751,0.001837,0.046657,66.179626,3.371351,0.466568,-1304.804199,0.047541,0.000000
34.210003,14.799202,-1304.759766,0.004751,0.001851,0.047013,65.830139,3.353547,0.470126,-1304.759766,0.047958,0.000000
34.460003,15.125397,-1304.715210,0.004751,0.001873,0.047576,67.281128,3.427464,0.475761,-1304.715210,0.048374,0.000000
34.710003,15.116463,-1304.759766,0.004816,0.001889,0.047992,67.241386,3.425439,0.479925,-1304.759766,0.048790,0.000000
34.960003,14.851707,-1304.804199,0.004786,0.001900,0.048252,66.063698,3.365445,0.482525,-1304.804199,0.049207,0.000000
35.210003,15.130615,-1304.759766,0.004794,0.001918,0.048729,67.304337,3.428647,0.487294,-1304.759766,0.049623,0.000000
35.460003,15.176788,-1304.759766,0.004846,0.001935,0.049137,67.509727,3.439109,0.491370,-1304.759766,0.050039,0.000000
35.710003,15.489578,-1304.759766,0.004838,0.001954,0.049640,68.901085,3.509989,0.496400,-1304.759766,0.050455,0.000000
35.960003,15.226311,-1304.759766,0.004863,0.001965,0.049909,67.730011,3.450331,0.499091,-1304.759766,0.050872,0.000000
36.210003,15.513039,-1304.670776,0.004850,0.001984,0.050386,69.005440,3.515305,0.503860,-1304.670776,0.051288,0.000000
36.460003,15.313820,-1304.759766,0.004859,0.001994,0.050655,68.119270,3.470161,0.506548,-1304.759766,0.051704,0.000000
36.710003,15.931961,-1304.804199,0.004902,0.002021,0.051322,70.868904,3.610234,0.513224,-1304.804199,0.052120,0.000000
36.960003,15.446014,-1304.715210,0.004915,0.002027,0.051479,68.707306,3.500117,0.514787,-1304.715210,0.052537,0.000000
37.210003,15.774818,-1304.715210,0.004915,0.002050,0.052060,70.169899,3.574625,0.520597,-1304.715210,0.052953,0.000000
37.460003,15.524582,-1304.804199,0.004937,0.002057,0.052250,69.056786,3.517920,0.522505,-1304.804199,0.053369,0.000000
37.710003,16.024681,-1304.804199,0.004967,0.002080,0.052823,71.281342,3.631245,0.528228,-1304.804199,0.053786,0.000000
37.960003,16.198204,-1304.759766,0.004980,0.002099,0.053317,72.053207,3.670566,0.533171,-1304.759766,0.054202,0.000000
38.210003,16.133041,-1304.759766,0.004963,0.002111,0.053621,71.763351,3.655799,0.536206,-1304.759766,0.054618,0.000000
38.460003,16.014252,-1304.759766,0.004984,0.002124,0.053942,71.234947,3.628881,0.539416,-1304.759766,0.055034,0.000000
38.710003,16.285339,-1304.715210,0.004997,0.002145,0.054479,72.440811,3.690311,0.544794,-1304.715210,0.055459,0.000000
38.960003,16.391838,-1304.759766,0.005036,0.002163,0.054930,72.914536,3.714443,0.549302,-1304.759766,0.055876,0.000000
39.210003,16.539673,-1304.848755,0.005062,0.002181,0.055398,73.572136,3.747944,0.553984,-1304.848755,0.056292,0.000000
39.460003,16.153145,-1304.804199,0.005092,0.002191,0.055659,71.852776,3.660355,0.556588,-1304.804199,0.056708,0.000000
39.710003,16.539673,-1304.804199,0.005101,0.002212,0.056188,73.572136,3.747944,0.561875,-1304.804199,0.057124,0.000000
39.960003,16.511368,-1304.848755,0.005088,0.002227,0.056578,73.446236,3.741529,0.565777,-1304.848755,0.057541,0.000000
40.210003,16.621964,-1304.804199,0.005105,0.002243,0.056960,73.938187,3.766591,0.569596,-1304.804199,0.057957,0.000000
40.460003,17.021523,-1304.759766,0.005122,0.002264,0.057515,75.715515,3.857132,0.575145,-1304.759766,0.058373,0.000000
40.710003,16.835709,-1304.848755,0.005105,0.002278,0.057853,74.888969,3.815026,0.578529,-1304.848755,0.058789,0.000000
40.960003,16.779480,-1304.804199,0.005144,0.002295,0.058295,74.638855,3.802284,0.582950,-1304.804199,0.059206,0.000000
41.210003,16.708359,-1304.848755,0.005157,0.002309,0.058659,74.322495,3.786168,0.586594,-1304.848755,0.059622,0.000000
41.460003,17.102699,-1304.848755,0.005174,0.002332,0.059232,76.076607,3.875527,0.592317,-1304.848755,0.060038,0.000000
41.710003,16.917259,-1304.848755,0.005226,0.002345,0.059570,75.251724,3.833506,0.595697,-1304.848755,0.060454,0.000000
41.960003,16.757133,-1304.804199,0.005251,0.002358,0.059891,74.539452,3.797221,0.598907,-1304.804199,0.060871,0.000000
42.210003,17.267288,-1304.893188,0.005251,0.002379,0.060428,76.808731,3.912823,0.604285,-1304.893188,0.061287,0.000000
42.460003,17.335060,-1304.759766,0.005264,0.002398,0.060905,77.110199,3.928181,0.609054,-1304.759766,0.061703,0.000000
42.710003,17.109032,-1304.804199,0.005221,0.002411,0.061252,76.104774,3.876962,0.612521,-1304.804199,0.062120,0.000000
42.960003,17.204727,-1304.893188,0.005264,0.002429,0.061686,76.530449,3.898647,0.616858,-1304.893188,0.062536,0.000000
43.210003,17.161163,-1304.804199,0.005303,0.002442,0.062033,76.336670,3.888775,0.620329,-1304.804199,0.062952,0.000000
43.460003,17.340645,-1304.893188,0.005307,0.002460,0.062475,77.135040,3.929446,0.624750,-1304.893188,0.063368,0.000000
43.710003,17.335434,-1304.804199,0.005282,0.002476,0.062883,77.111862,3.928266,0.628826,-1304.804199,0.063785,0.000000
43.960003,17.171211,-1304.893188,0.005351,0.002488,0.063186,76.381363,3.891052,0.631862,-1304.893188,0.064210,0.000000
44.210003,17.806480,-1304.893188,0.005342,0.002513,0.063836,79.207184,4.035006,0.638364,-1304.893188,0.064626,0.000000
44.460003,17.703705,-1304.848755,0.005398,0.002530,0.064253,78.750015,4.011717,0.642528,-1304.848755,0.065042,0.000000
44.710003,17.569283,-1304.848755,0.005355,0.002545,0.064634,78.152069,3.981256,0.646343,-1304.848755,0.065458,0.000000
44.960003,17.408043,-1304.848755,0.005411,0.002559,0.064990,77.434845,3.944719,0.649901,-1304.848755,0.065875,0.000000
45.210003,17.846695,-1304.893188,0.005424,0.002580,0.065528,79.386063,4.044119,0.655275,-1304.893188,0.066291,0.000000
45.460003,17.697746,-1304.893188,0.005441,0.002593,0.065857,78.723511,4.010366,0.658572,-1304.893188,0.066707,0.000000
45.710003,17.695885,-1304.937622,0.005450,0.002607,0.066230,78.715225,4.009945,0.662300,-1304.937622,0.067123,0.000000
45.960003,18.066399,-1304.893188,0.005445,0.002627,0.066716,80.363358,4.093904,0.667160,-1304.893188,0.067540,0.000000
46.210003,18.147575,-1304.848755,0.005437,0.002645,0.067193,80.724449,4.112299,0.671929,-1304.848755,0.067956,0.000000
46.460003,17.977028,-1304.804199,0.005489,0.002660,0.067557,79.965813,4.073653,0.675570,-1304.804199,0.068372,0.000000
46.710003,18.114059,-1304.848755,0.005506,0.002677,0.067999,80.575363,4.104704,0.679994,-1304.848755,0.068789,0.000000
46.960003,17.885056,-1304.893188,0.005549,0.002691,0.068346,79.556702,4.052812,0.683461,-1304.893188,0.069205,0.000000
47.210003,18.218323,-1304.893188,0.005558,0.002709,0.068806,81.039146,4.128331,0.688060,-1304.893188,0.069621,0.000000
47.460003,18.166191,-1304.848755,0.005566,0.002724,0.069187,80.807251,4.116518,0.691875,-1304.848755,0.070037,0.000000
47.710003,17.886169,-1304.848755,0.005575,0.002733,0.069413,79.561653,4.053064,0.694127,-1304.848755,0.070454,0.000000
47.960003,18.574684,-1304.848755,0.005579,0.002757,0.070029,82.624321,4.209084,0.700285,-1304.848755,0.070870,0.000000
48.210003,18.611923,-1304.982178,0.005601,0.002775,0.070497,82.789970,4.217522,0.704971,-1304.982178,0.071286,0.000000
48.460003,18.608948,-1304.848755,0.005609,0.002789,0.070852,82.776733,4.216848,0.708525,-1304.848755,0.071702,0.000000
48.710003,18.736298,-1304.848755,0.005639,0.002809,0.071347,83.343216,4.245706,0.713468,-1304.848755,0.072119,0.000000
48.960003,18.323334,-1304.893188,0.005661,0.002820,0.071616,81.506256,4.152127,0.716155,-1304.893188,0.072544,0.000000
49.210003,18.795128,-1304.848755,0.005631,0.002839,0.072110,83.604904,4.259037,0.721098,-1304.848755,0.072960,0.000000
49.460003,18.701294,-1304.893188,0.005674,0.002855,0.072526,83.187508,4.237774,0.725262,-1304.893188,0.073376,0.000000
49.710003,18.484947,-1304.893188,0.005665,0.002864,0.072752,82.225151,4.188749,0.727517,-1304.893188,0.073792,0.000000
49.960003,19.222244,-1304.893188,0.005665,0.002890,0.073402,85.504814,4.355823,0.734020,-1304.893188,0.074209,0.000000
50.210003,19.159309,-1304.893188,0.005734,0.002906,0.073818,85.224861,4.341561,0.738183,-1304.893188,0.074625,0.000000
50.460003,19.151115,-1304.804199,0.005717,0.002924,0.074269,85.188416,4.339705,0.742695,-1304.804199,0.075041,0.000000
50.710003,18.934029,-1304.937622,0.005756,0.002935,0.074556,84.222763,4.290512,0.745556,-1304.937622,0.075458,0.000000
50.960003,19.139946,-1304.848755,0.005760,0.002952,0.074972,85.138733,4.337174,0.749720,-1304.848755,0.075874,0.000000
51.210003,19.252403,-1304.848755,0.005752,0.002969,0.075414,85.638969,4.362657,0.754140,-1304.848755,0.076290,0.000000
51.460003,18.679695,-1304.893188,0.005795,0.002973,0.075527,83.091431,4.232879,0.755268,-1304.893188,0.076706,0.000000
51.710003,19.327248,-1304.848755,0.005777,0.002999,0.076186,85.971893,4.379617,0.761858,-1304.848755,0.077123,0.000000
51.960003,19.708191,-1304.804199,0.005855,0.003017,0.076628,87.666412,4.465940,0.766282,-1304.804199,0.077539,0.000000
52.210003,19.849319,-1304.804199,0.005799,0.003035,0.077088,88.294182,4.497920,0.770877,-1304.804199,0.077955,0.000000
52.460003,19.433006,-1304.893188,0.005872,0.003047,0.077383,86.442329,4.403583,0.773826,-1304.893188,0.078371,0.000000
52.710003,19.721596,-1304.848755,0.005851,0.003066,0.077868,87.726036,4.468977,0.778682,-1304.848755,0.078788,0.000000
52.960003,19.683235,-1304.848755,0.005920,0.003078,0.078172,87.555405,4.460285,0.781717,-1304.848755,0.079204,0.000000
53.210003,20.185196,-1304.804199,0.005898,0.003100,0.078744,89.788239,4.574031,0.787444,-1304.804199,0.079620,0.000000
53.460003,20.074226,-1304.804199,0.005898,0.003112,0.079039,89.294617,4.548885,0.790392,-1304.804199,0.080037,0.000000
53.710003,20.045555,-1304.804199,0.005971,0.003126,0.079403,89.167084,4.542388,0.794033,-1304.804199,0.080452,0.000000
53.960003,20.587357,-1304.848755,0.005920,0.003147,0.079932,91.577133,4.665162,0.799324,-1304.848755,0.080878,0.000000
54.210003,20.512138,-1304.848755,0.005928,0.003161,0.080288,91.242546,4.648117,0.802878,-1304.848755,0.081294,0.000000
54.460003,20.776154,-1304.804199,0.005959,0.003179,0.080739,92.416946,4.707944,0.807390,-1304.804199,0.081710,0.000000
54.710003,20.975746,-1304.848755,0.005997,0.003195,0.081155,93.304779,4.753172,0.811550,-1304.848755,0.082127,0.000000
54.960003,20.953026,-1304.848755,0.006036,0.003207,0.081450,93.203712,4.748024,0.814498,-1304.848755,0.082543,0.000000
55.210003,21.581963,-1304.848755,0.005989,0.003230,0.082039,96.001366,4.890543,0.820395,-1304.848755,0.082959,0.000000
55.460003,21.393173,-1304.804199,0.006010,0.003242,0.082335,95.161591,4.847763,0.823347,-1304.804199,0.083375,0.000000
55.710003,22.039612,-1304.848755,0.006084,0.003262,0.082863,98.037086,4.994247,0.828635,-1304.848755,0.083792,0.000000
55.960003,22.377724,-1304.848755,0.006049,0.003283,0.083393,99.541084,5.070865,0.833926,-1304.848755,0.084208,0.000000
56.210003,22.066795,-1304.848755,0.006092,0.003292,0.083627,98.158005,5.000407,0.836269,-1304.848755,0.084624,0.000000
56.460003,22.603012,-1304.804199,0.006140,0.003312,0.084130,100.543221,5.121916,0.841295,-1304.804199,0.085040,0.000000
56.710003,22.905380,-1304.848755,0.006101,0.003329,0.084546,101.888222,5.190434,0.845459,-1304.848755,0.085456,0.000000
56.960003,23.389091,-1304.804199,0.006165,0.003348,0.085040,104.039879,5.300044,0.850402,-1304.804199,0.085873,0.000000
57.210003,23.415154,-1304.804199,0.006122,0.003361,0.085379,104.155807,5.305949,0.853785,-1304.804199,0.086289,0.000000
57.460003,23.630013,-1304.893188,0.006109,0.003376,0.085751,105.111542,5.354638,0.857513,-1304.893188,0.086706,0.000000
57.710003,24.128250,-1304.759766,0.006196,0.003393,0.086194,107.327820,5.467540,0.861938,-1304.759766,0.087121,0.000000
57.960003,24.624252,-1304.759766,0.006222,0.003412,0.086671,109.534142,5.579936,0.866707,-1304.759766,0.087538,0.000000
58.210003,24.740433,-1304.804199,0.006161,0.003425,0.086992,110.050941,5.606262,0.869916,-1304.804199,0.087954,0.000000
58.460003,25.250580,-1304.759766,0.006243,0.003444,0.087477,112.320190,5.721863,0.874772,-1304.759766,0.088370,0.000000
58.710003,25.371971,-1304.804199,0.006217,0.003455,0.087763,112.860161,5.749371,0.877634,-1304.804199,0.088787,0.000000
58.960003,25.638222,-1304.804199,0.006252,0.003471,0.088162,114.044510,5.809704,0.881623,-1304.804199,0.089203,0.000000
59.210003,26.032188,-1304.804199,0.006260,0.003485,0.088526,115.796959,5.898978,0.885264,-1304.804199,0.089628,0.000000
59.460003,26.787735,-1304.804199,0.006278,0.003505,0.089029,119.157799,6.070188,0.890294,-1304.804199,0.090044,0.000000
59.710003,27.363052,-1304.848755,0.006316,0.003522,0.089454,121.716934,6.200557,0.894545,-1304.848755,0.090461,0.000000
59.960003,28.108536,-1304.804199,0.006308,0.003542,0.089975,125.033012,6.369485,0.899749,-1304.804199,0.090877,0.000000
60.210003,27.938736,-1304.848755,0.006325,0.003556,0.090322,124.277702,6.331008,0.903216,-1304.848755,0.091293,0.000000
60.460003,28.890518,-1304.759766,0.006342,0.003575,0.090798,128.511444,6.546685,0.907985,-1304.759766,0.091709,0.000000
60.710003,28.779556,-1304.804199,0.006338,0.003586,0.091076,128.017853,6.521541,0.910763,-1304.804199,0.092125,0.000000
60.960003,29.306458,-1304.804199,0.006321,0.003603,0.091527,130.361633,6.640938,0.915271,-1304.804199,0.092542,0.000000
61.210003,29.709740,-1304.759766,0.006351,0.003616,0.091839,132.155518,6.732323,0.918393,-1304.759766,0.092958,0.000000
61.460003,30.500290,-1304.804199,0.006377,0.003634,0.092316,135.672058,6.911464,0.923162,-1304.804199,0.093374,0.000000
61.710003,31.463989,-1304.804199,0.006433,0.003657,0.092889,139.958817,7.129842,0.928885,-1304.804199,0.093790,0.000000
61.960003,32.294006,-1304.804199,0.006381,0.003675,0.093357,143.650909,7.317927,0.933571,-1304.804199,0.094207,0.000000
62.210003,32.721863,-1304.848755,0.006420,0.003690,0.093739,145.554108,7.414880,0.937386,-1304.848755,0.094623,0.000000
62.460003,33.034653,-1304.804199,0.006411,0.003705,0.094103,146.945480,7.485759,0.941027,-1304.804199,0.095039,0.000000
62.710003,33.904518,-1304.804199,0.006493,0.003723,0.094563,150.814835,7.682874,0.945626,-1304.804199,0.095456,0.000000
62.960003,34.445572,-1304.804199,0.006450,0.003738,0.094953,153.221558,7.805478,0.949528,-1304.804199,0.095872,0.000000
63.210003,34.869705,-1304.759766,0.006506,0.003753,0.095334,155.108200,7.901588,0.953343,-1304.759766,0.096288,0.000000
63.460003,35.070786,-1304.804199,0.006485,0.003767,0.095672,156.002640,7.947154,0.956723,-1304.804199,0.096704,0.000000
63.710003,36.855568,-1304.848755,0.006510,0.003791,0.096297,163.941757,8.351591,0.962968,-1304.848755,0.097121,0.000000
63.960003,37.277840,-1304.848755,0.006480,0.003804,0.096626,165.820114,8.447279,0.966265,-1304.848755,0.097537,0.000000
64.210007,37.928375,-1304.893188,0.006502,0.003821,0.097043,168.713837,8.594693,0.970428,-1304.893188,0.097962,0.000000
64.460007,38.647049,-1304.759766,0.006545,0.003837,0.097459,171.910660,8.757546,0.974588,-1304.759766,0.098378,0.000000
64.710007,39.500526,-1304.804199,0.006584,0.003854,0.097884,175.707123,8.950947,0.978838,-1304.804199,0.098794,0.000000
64.960007,40.172287,-1304.804199,0.006545,0.003868,0.098257,178.695251,9.103170,0.982566,-1304.804199,0.099211,0.000000
65.210007,40.808304,-1304.848755,0.006554,0.003882,0.098604,181.524399,9.247293,0.986037,-1304.848755,0.099627,0.000000
65.460007,42.052773,-1304.893188,0.006571,0.003904,0.099159,187.060074,9.529294,0.991586,-1304.893188,0.100043,0.000000
65.710007,43.335594,-1304.804199,0.006610,0.003923,0.099653,192.766357,9.819986,0.996529,-1304.804199,0.100459,0.000000
65.960007,44.008095,-1304.804199,0.006575,0.003939,0.100043,195.757782,9.972377,1.000431,-1304.804199,0.100876,0.000000
66.210007,44.564423,-1304.804199,0.006640,0.003952,0.100390,198.232452,10.098443,1.003902,-1304.804199,0.101292,0.000000
66.460007,45.474129,-1304.759766,0.006618,0.003970,0.100841,202.279022,10.304585,1.008410,-1304.759766,0.101708,0.000000
66.710007,46.579704,-1304.848755,0.006640,0.003985,0.101214,207.196869,10.555112,1.012141,-1304.848755,0.102125,0.000000
66.960007,47.373230,-1304.804199,0.006661,0.004001,0.101613,210.726654,10.734927,1.016131,-1304.804199,0.102541,0.000000
67.210007,47.942955,-1304.804199,0.006631,0.004013,0.101934,213.260910,10.864029,1.019337,-1304.804199,0.102957,0.000000
67.460007,49.844292,-1304.893188,0.006635,0.004038,0.102558,221.718475,11.294878,1.025582,-1304.893188,0.103373,0.000000
67.710007,50.704842,-1304.893188,0.006683,0.004050,0.102870,225.546402,11.489882,1.028704,-1304.893188,0.103790,0.000000
67.960007,51.799248,-1304.893188,0.006640,0.004069,0.103356,230.414566,11.737877,1.033560,-1304.893188,0.104206,0.000000
68.210007,52.785660,-1304.937622,0.006709,0.004083,0.103703,234.802338,11.961401,1.037031,-1304.937622,0.104622,0.000000
68.460007,53.816391,-1304.893188,0.006722,0.004101,0.104163,239.387268,12.194969,1.041626,-1304.893188,0.105038,0.000000
68.710007,54.989731,-1304.848755,0.006679,0.004117,0.104562,244.606537,12.460851,1.045615,-1304.848755,0.105455,0.000000
68.960007,55.802620,-1304.937622,0.006691,0.004128,0.104856,248.222458,12.645055,1.048563,-1304.937622,0.105871,0.000000
69.210007,56.952507,-1304.848755,0.006683,0.004145,0.105290,253.337402,12.905622,1.052901,-1304.848755,0.106296,0.000000
69.460007,58.496735,-1304.848755,0.006713,0.004166,0.105828,260.206482,13.255549,1.058276,-1304.848755,0.106712,0.000000
69.710007,59.712532,-1304.937622,0.006752,0.004182,0.106226,265.614594,13.531054,1.062265,-1304.937622,0.107128,0.000000
69.960007,61.303680,-1304.893188,0.006778,0.004202,0.106729,272.692383,13.891612,1.067295,-1304.893188,0.107545,0.000000
70.210007,62.169823,-1304.893188,0.006726,0.004213,0.106999,276.545197,14.087883,1.069986,-1304.893188,0.107961,0.000000
70.460007,63.225121,-1304.893188,0.006786,0.004231,0.107467,281.239380,14.327017,1.074668,-1304.893188,0.108377,0.000000
70.710007,64.681847,-1304.937622,0.006730,0.004247,0.107874,287.719238,14.657116,1.078744,-1304.937622,0.108793,0.000000
70.960007,65.332375,-1304.804199,0.006799,0.004256,0.108091,290.612915,14.804527,1.080913,-1304.804199,0.109210,0.000000
71.210007,67.417290,-1304.893188,0.006821,0.004281,0.108733,299.887085,15.276977,1.087328,-1304.893188,0.109626,0.000000
71.460007,67.084389,-1304.937622,0.006778,0.004275,0.108577,298.406250,15.201539,1.085769,-1304.937622,0.108742,0.000000
71.710007,66.704201,-1304.848755,0.006782,0.004274,0.108559,296.715118,15.115388,1.085595,-1304.848755,0.108568,0.000000
71.960007,66.380974,-1304.937622,0.006791,0.004274,0.108551,295.277313,15.042143,1.085508,-1304.937622,0.108568,0.000000
72.210007,66.128136,-1304.937622,0.006812,0.004274,0.108551,294.152649,14.984849,1.085508,-1304.937622,0.108568,0.000000
72.460007,65.873436,-1304.893188,0.006812,0.004273,0.108542,293.019684,14.927135,1.085421,-1304.893188,0.108568,0.000000
72.710007,65.689491,-1304.937622,0.006782,0.004273,0.108542,292.201447,14.885451,1.085421,-1304.937622,0.108568,0.000000
72.960007,65.485802,-1304.982178,0.006834,0.004273,0.108542,291.295380,14.839295,1.085421,-1304.982178,0.108568,0.000000
73.210007,65.340569,-1304.893188,0.006743,0.004273,0.108542,290.649353,14.806384,1.085421,-1304.893188,0.108568,0.000000
73.460007,65.182686,-1304.893188,0.006752,0.004273,0.108542,289.947083,14.770608,1.085421,-1304.893188,0.108568,0.000000
73.710007,65.059059,-1304.937622,0.006804,0.004273,0.108542,289.397156,14.742594,1.085421,-1304.937622,0.108568,0.000000
73.960007,64.924263,-1304.893188,0.006752,0.004273,0.108542,288.797546,14.712049,1.085421,-1304.893188,0.108568,0.000000
74.210007,64.830055,-1304.937622,0.006812,0.004273,0.108542,288.378479,14.690701,1.085421,-1304.937622,0.108568,0.000000
74.460007,64.702690,-1304.893188,0.006795,0.004273,0.108533,287.811951,14.661839,1.085334,-1304.893188,0.108568,0.000000
74.710007,64.624123,-1304.893188,0.006817,0.004273,0.108533,287.462463,14.644036,1.085334,-1304.893188,0.108568,0.000000
74.960007,64.526558,-1304.982178,0.006821,0.004273,0.108533,287.028473,14.621927,1.085334,-1304.982178,0.108568,0.000000
75.210007,64.444649,-1304.982178,0.006782,0.004273,0.108533,286.664124,14.603366,1.085334,-1304.982178,0.108568,0.000000
75.460007,64.349693,-1305.026611,0.006804,0.004273,0.108533,286.241730,14.581848,1.085334,-1305.026611,0.108568,0.000000
75.710007,64.293831,-1304.982178,0.006773,0.004273,0.108533,285.993256,14.569191,1.085334,-1304.982178,0.108568,0.000000
75.960007,64.220482,-1305.026611,0.006825,0.004273,0.108533,285.666962,14.552568,1.085334,-1305.026611,0.108568,0.000000
76.210007,64.172813,-1304.982178,0.006782,0.004273,0.108533,285.454926,14.541767,1.085334,-1304.982178,0.108568,0.000000
76.460007,64.081947,-1305.026611,0.006804,0.004273,0.108533,285.050751,14.521176,1.085334,-1305.026611,0.108568,0.000000
76.710007,64.056633,-1304.982178,0.006821,0.004273,0.108533,284.938141,14.515441,1.085334,-1304.982178,0.108568,0.000000
76.960007,63.967628,-1305.026611,0.006782,0.004273,0.108533,284.542236,14.495272,1.085334,-1305.026611,0.108568,0.000000
77.210007,63.940819,-1304.982178,0.006799,0.004273,0.108533,284.422974,14.489196,1.085334,-1304.982178,0.108568,0.000000
77.460007,63.862251,-1305.026611,0.006821,0.004273,0.108533,284.073486,14.471393,1.085334,-1305.026611,0.108568,0.000000
77.710007,63.833214,-1305.026611,0.006812,0.004273,0.108533,283.944305,14.464813,1.085334,-1305.026611,0.108568,0.000000
77.960007,63.762459,-1305.026611,0.006782,0.004273,0.108533,283.629578,14.448780,1.085334,-1305.026611,0.108568,0.000000
78.210007,63.738625,-1304.937622,0.006817,0.004273,0.108533,283.523560,14.443378,1.085334,-1304.937622,0.108568,0.000000
78.460007,63.668251,-1304.982178,0.006804,0.004273,0.108533,283.210510,14.427432,1.085334,-1304.982178,0.108568,0.000000
78.710007,63.647758,-1305.026611,0.006778,0.004273,0.108533,283.119385,14.422789,1.085334,-1305.026611,0.108568,0.000000
78.960007,63.592659,-1305.026611,0.006795,0.004273,0.108533,282.874268,14.410303,1.085334,-1305.026611,0.108568,0.000000
79.210007,63.572914,-1305.026611,0.006817,0.004273,0.108533,282.786438,14.405828,1.085334,-1305.026611,0.108568,0.000000
79.460007,63.512962,-1305.071045,0.006778,0.004273,0.108533,282.519775,14.392243,1.085334,-1305.071045,0.108568,0.000000
79.710007,63.482811,-1304.937622,0.006829,0.004273,0.108533,282.385651,14.385410,1.085334,-1304.937622,0.108568,0.000000
79.960007,63.423973,-1305.026611,0.006808,0.004273,0.108533,282.123932,14.372077,1.085334,-1305.026611,0.108568,0.000000
80.210007,63.418388,-1305.071045,0.006817,0.004273,0.108533,282.099091,14.370811,1.085334,-1305.071045,0.108568,0.000000
80.460007,63.354332,-1304.982178,0.006773,0.004273,0.108533,281.814148,14.356297,1.085334,-1304.982178,0.108568,0.000000
80.710007,63.359184,-1304.982178,0.006812,0.004273,0.108533,281.835724,14.357397,1.085334,-1304.982178,0.108568,0.000000
80.960007,63.295876,-1305.026611,0.006769,0.004273,0.108533,281.554108,14.343050,1.085334,-1305.026611,0.108568,0.000000
81.210007,63.276512,-1304.937622,0.006829,0.004273,0.108533,281.467987,14.338662,1.085334,-1304.937622,0.108568,0.000000
81.460007,63.234810,-1304.982178,0.006825,0.004273,0.108533,281.282471,14.329213,1.085334,-1304.982178,0.108568,0.000000
81.710007,63.220284,-1304.982178,0.006825,0.004273,0.108533,281.217865,14.325921,1.085334,-1304.982178,0.108568,0.000000
81.960007,63.169273,-1304.982178,0.006838,0.004273,0.108533,280.990967,14.314363,1.085334,-1304.982178,0.108568,0.000000
82.210007,63.159218,-1305.071045,0.006773,0.004273,0.108533,280.946228,14.312083,1.085334,-1305.071045,0.108568,0.000000
82.460007,63.126442,-1305.026611,0.006773,0.004273,0.108533,280.800446,14.304657,1.085334,-1305.026611,0.108568,0.000000
82.710007,63.115273,-1304.982178,0.006808,0.004273,0.108533,280.750763,14.302126,1.085334,-1304.982178,0.108568,0.000000
82.960007,63.065002,-1304.937622,0.006778,0.004273,0.108533,280.527130,14.290734,1.085334,-1304.937622,0.108568,0.000000
83.210007,63.057556,-1304.937622,0.006829,0.004273,0.108533,280.494019,14.289046,1.085334,-1304.937622,0.108568,0.000000
83.460007,63.024414,-1304.982178,0.006773,0.004273,0.108533,280.346588,14.281537,1.085334,-1304.982178,0.108568,0.000000
83.710007,63.005798,-1305.026611,0.006825,0.004273,0.108533,280.263794,14.277318,1.085334,-1305.026611,0.108568,0.000000
83.960007,62.971909,-1304.982178,0.006829,0.004273,0.108533,280.113037,14.269638,1.085334,-1304.982178,0.108568,0.000000
84.210007,62.955528,-1304.982178,0.006829,0.004273,0.108533,280.040161,14.265926,1.085334,-1304.982178,0.108568,0.000000
84.460007,62.926483,-1304.982178,0.006821,0.004273,0.108533,279.910980,14.259345,1.085334,-1304.982178,0.108568,0.000000
84.710007,62.929085,-1304.937622,0.006821,0.004273,0.108533,279.922546,14.259934,1.085334,-1304.937622,0.108568,0.000000
84.960007,62.883659,-1304.937622,0.006808,0.004273,0.108533,279.720490,14.249640,1.085334,-1304.937622,0.108568,0.000000
85.210007,62.885521,-1304.982178,0.006782,0.004273,0.108533,279.728760,14.250063,1.085334,-1304.982178,0.108568,0.000000
85.460007,62.852753,-1304.982178,0.006821,0.004273,0.108533,279.583008,14.242638,1.085334,-1304.982178,0.108568,0.000000
85.710007,62.830032,-1304.982178,0.006795,0.004273,0.108533,279.481934,14.237489,1.085334,-1304.982178,0.108568,0.000000
85.960007,62.824081,-1305.026611,0.006808,0.004273,0.108533,279.455475,14.236140,1.085334,-1305.026611,0.108568,0.000000
86.210007,62.803223,-1304.937622,0.006778,0.004273,0.108533,279.362701,14.231414,1.085334,-1304.937622,0.108568,0.000000
86.460007,62.783493,-1305.071045,0.006804,0.004273,0.108533,279.274933,14.226943,1.085334,-1305.071045,0.108568,0.000000
86.710007,62.752586,-1304.937622,0.006821,0.004273,0.108533,279.137451,14.219939,1.085334,-1304.937622,0.108568,0.000000
86.960007,62.744392,-1304.937622,0.006799,0.004273,0.108533,279.100983,14.218083,1.085334,-1304.937622,0.108568,0.000000
87.210007,62.727631,-1305.071045,0.006782,0.004273,0.108533,279.026428,14.214285,1.085334,-1305.071045,0.108568,0.000000
87.460007,62.720932,-1305.071045,0.006778,0.004273,0.108533,278.996643,14.212767,1.085334,-1305.071045,0.108568,0.000000
87.710007,62.696724,-1305.026611,0.006817,0.004273,0.108533,278.888947,14.207281,1.085334,-1305.026611,0.108568,0.000000
87.960007,62.688164,-1305.071045,0.006769,0.004273,0.108533,278.850891,14.205340,1.085334,-1305.071045,0.108568,0.000000
88.210007,62.653900,-1305.026611,0.006804,0.004273,0.108533,278.698456,14.197577,1.085334,-1305.026611,0.108568,0.000000
88.460007,62.652412,-1305.026611,0.006847,0.004273,0.108533,278.691864,14.197240,1.085334,-1305.026611,0.108568,0.000000
88.710007,62.626724,-1304.982178,0.006795,0.004273,0.108533,278.577576,14.191419,1.085334,-1304.982178,0.108568,0.000000
88.960007,62.617783,-1305.071045,0.006799,0.004273,0.108533,278.537811,14.189392,1.085334,-1305.071045,0.108568,0.000000
89.210007,62.592087,-1305.026611,0.006829,0.004273,0.108533,278.423492,14.183570,1.085334,-1305.026611,0.108568,0.000000
89.460007,62.587997,-1305.071045,0.006791,0.004273,0.108533,278.405304,14.182643,1.085334,-1305.071045,0.108568,0.000000
89.710007,62.563416,-1305.026611,0.006821,0.004273,0.108533,278.295959,14.177073,1.085334,-1305.026611,0.108568,0.000000
89.960007,62.564903,-1304.982178,0.006786,0.004273,0.108533,278.302582,14.177410,1.085334,-1304.982178,0.108568,0.000000
90.210007,62.530647,-1305.071045,0.006799,0.004273,0.108533,278.150208,14.169647,1.085334,-1305.071045,0.108568,0.000000
90.460007,62.541451,-1305.071045,0.006778,0.004273,0.108533,278.198273,14.172095,1.085334,-1305.071045,0.108568,0.000000
90.710007,62.500114,-1305.026611,0.006799,0.004273,0.108533,278.014404,14.162728,1.085334,-1305.026611,0.108568,0.000000
90.960007,62.505699,-1305.071045,0.006786,0.004273,0.108533,278.039246,14.163994,1.085334,-1305.071045,0.108568,0.000000
91.210007,62.474045,-1305.071045,0.006842,0.004273,0.108533,277.898437,14.156821,1.085334,-1305.071045,0.108568,0.000000
91.460007,62.479263,-1305.115601,0.006804,0.004273,0.108533,277.921631,14.158004,1.085334,-1305.115601,0.108568,0.000000
91.710007,62.433456,-1305.071045,0.006782,0.004273,0.108533,277.717896,14.147624,1.085334,-1305.071045,0.108568,0.000000
91.960007,62.449097,-1305.026611,0.006778,0.004273,0.108533,277.787445,14.151168,1.085334,-1305.026611,0.108568,0.000000
92.210007,62.418938,-1305.115601,0.006825,0.004273,0.108533,277.653290,14.144334,1.085334,-1305.115601,0.108568,0.000000
92.460007,62.441650,-1305.026611,0.006838,0.004273,0.108533,277.754333,14.149480,1.085334,-1305.026611,0.108568,0.000000
92.710007,62.395477,-1305.115601,0.006786,0.004273,0.108533,277.548950,14.139017,1.085334,-1305.115601,0.108568,0.000000
92.960007,62.422661,-1305.071045,0.006821,0.004273,0.108533,277.669861,14.145177,1.085334,-1305.071045,0.108568,0.000000
93.210007,62.366058,-1305.026611,0.006834,0.004273,0.108533,277.418091,14.132351,1.085334,-1305.026611,0.108568,0.000000
93.460007,62.371643,-1305.115601,0.006808,0.004273,0.108533,277.442932,14.133616,1.085334,-1305.115601,0.108568,0.000000
93.710007,62.345955,-1305.071045,0.006817,0.004273,0.108533,277.328644,14.127795,1.085334,-1305.071045,0.108568,0.000000
93.960007,62.361595,-1305.115601,0.006842,0.004273,0.108533,277.398224,14.131340,1.085334,-1305.115601,0.108568,0.000000
94.210007,62.329193,-1305.026611,0.006773,0.004273,0.108533,277.254089,14.123997,1.085334,-1305.026611,0.108568,0.000000
94.460007,62.339249,-1305.115601,0.006769,0.004273,0.108533,277.298828,14.126276,1.085334,-1305.115601,0.108568,0.000000
94.710007,62.301270,-1305.115601,0.006821,0.004273,0.108533,277.129883,14.117669,1.085334,-1305.115601,0.108568,0.000000
94.960007,62.313927,-1305.071045,0.006855,0.004273,0.108533,277.186188,14.120538,1.085334,-1305.071045,0.108568,0.000000
95.210007,62.285255,-1305.026611,0.006786,0.004273,0.108533,277.058655,14.114040,1.085334,-1305.026611,0.108568,0.000000
95.460007,62.292702,-1305.115601,0.006778,0.004273,0.108533,277.091766,14.115727,1.085334,-1305.115601,0.108568,0.000000
95.710007,62.264404,-1305.026611,0.006808,0.004273,0.108533,276.965912,14.109316,1.085334,-1305.026611,0.108568,0.000000
95.960007,62.269615,-1305.115601,0.006786,0.004273,0.108533,276.989075,14.110497,1.085334,-1305.115601,0.108568,0.000000
96.210007,62.251366,-1305.026611,0.006769,0.004273,0.108533,276.907898,14.106361,1.085334,-1305.026611,0.108568,0.000000
96.460007,62.239082,-1305.026611,0.006834,0.004273,0.108533,276.853271,14.103578,1.085334,-1305.026611,0.108568,0.000000
96.710007,62.225677,-1305.071045,0.006773,0.004273,0.108533,276.793640,14.100540,1.085334,-1305.071045,0.108568,0.000000
96.960007,62.207428,-1305.026611,0.006842,0.004273,0.108533,276.712463,14.096405,1.085334,-1305.026611,0.108568,0.000000
97.210007,62.218597,-1305.026611,0.006786,0.004273,0.108533,276.762146,14.098935,1.085334,-1305.026611,0.108568,0.000000
97.460007,62.202591,-1305.026611,0.006786,0.004273,0.108533,276.690948,14.095308,1.085334,-1305.026611,0.108568,0.000000
97.710007,62.194023,-1304.982178,0.006817,0.004273,0.108533,276.652832,14.093368,1.085334,-1304.982178,0.108568,0.000000
97.960007,62.178757,-1305.026611,0.006855,0.004273,0.108533,276.584930,14.089908,1.085334,-1305.026611,0.108568,0.000000
98.210007,62.164604,-1304.982178,0.006782,0.004273,0.108533,276.521973,14.086700,1.085334,-1304.982178,0.108568,0.000000
98.460007,62.162003,-1305.026611,0.006778,0.004273,0.108533,276.510406,14.086111,1.085334,-1305.026611,0.108568,0.000000
98.710007,62.141144,-1305.071045,0.006804,0.004273,0.108533,276.417603,14.081385,1.085334,-1305.071045,0.108568,0.000000
98.960007,62.145615,-1304.982178,0.006778,0.004273,0.108533,276.437500,14.082398,1.085334,-1304.982178,0.108568,0.000000
99.210007,62.120293,-1305.026611,0.006847,0.004273,0.108533,276.324860,14.076659,1.085334,-1305.026611,0.108568,0.000000
99.460007,62.123276,-1305.115601,0.006817,0.004273,0.108533,276.338135,14.077335,1.085334,-1305.115601,0.108568,0.000000
99.710007,62.106148,-1305.071045,0.006834,0.004273,0.108533,276.261932,14.073454,1.085334,-1305.071045,0.108568,0.000000
99.960007,62.104652,-1305.026611,0.006847,0.004273,0.108533,276.255280,14.073115,1.085334,-1305.026611,0.108568,0.000000
100.210007,62.090874,-1305.071045,0.006786,0.004273,0.108533,276.194000,14.069993,1.085334,-1305.071045,0.108568,0.000000
100.460007,62.068535,-1305.026611,0.006778,0.004273,0.108533,276.094635,14.064931,1.085334,-1305.026611,0.108568,0.000000
100.710007,62.071884,-1305.071045,0.006773,0.004273,0.108533,276.109528,14.065690,1.085334,-1305.071045,0.108568,0.000000
100.960007,62.061829,-1304.937622,0.006778,0.004273,0.108533,276.064789,14.063412,1.085334,-1304.937622,0.108568,0.000000
101.210007,62.056244,-1305.071045,0.006795,0.004273,0.108533,276.039948,14.062146,1.085334,-1305.071045,0.108568,0.000000
101.460007,62.043961,-1305.026611,0.006769,0.004273,0.108533,275.985321,14.059362,1.085334,-1305.026611,0.108568,0.000000
101.700005,62.022736,-1304.982178,0.006786,0.004273,0.108533,275.890900,14.054553,1.085334,-1304.982178,0.108568,0.000000