File: Data/Automembrane/AutoHeating-17wt-1-1_12152023_163238.csv
Time (sec),S:Load (lbs),S:HL1 (DIM),S:LVDT (in),S:Position (in),Ch:Position (mm),Ch:Load (N),Ch:Stress (MPa),Ch:Strain (mm/mm),Ch:HL1 (DIM),Set Point (),Cycles ()
0.110000,0.015274,-91.541794,-0.000004,-0.000000,-0.000000,0.067942,0.003461,-0.000000,-91.541794,0.000234,0.000000
0.360000,0.050278,-91.586281,0.000000,-0.000000,-0.000000,0.223646,0.011393,-0.000000,-91.586281,0.000442,0.000000
0.610000,0.072990,-91.586281,0.000116,0.000140,0.003564,0.324678,0.016540,0.035642,-91.586281,0.004605,0.000000
0.860000,0.059586,-91.586281,0.000302,0.000300,0.007631,0.265050,0.013502,0.076315,-91.586281,0.008785,0.000000
1.110000,0.071129,-91.586281,0.000474,0.000463,0.011760,0.316397,0.016118,0.117597,-91.586281,0.012948,0.000000
1.360000,0.072243,-91.541794,0.000625,0.000633,0.016070,0.321352,0.016370,0.160699,-91.541794,0.017110,0.000000
1.610000,0.054001,-91.630760,0.000806,0.000791,0.020094,0.240208,0.012237,0.200936,-91.630760,0.021273,0.000000
1.860000,0.071129,-91.630760,0.000996,0.000958,0.024343,0.316397,0.016118,0.243429,-91.630760,0.025436,0.000000
2.110000,0.067772,-91.630760,0.001168,0.001116,0.028341,0.301465,0.015357,0.283409,-91.630760,0.029599,0.000000
2.360000,0.060699,-91.675240,0.001337,0.001285,0.032642,0.270005,0.013755,0.326424,-91.675240,0.033761,0.000000
2.610000,0.060699,-91.630760,0.001500,0.001447,0.036745,0.270005,0.013755,0.367445,-91.630760,0.037941,0.000000
2.860000,0.094589,-91.630760,0.001699,0.001609,0.040864,0.420754,0.021434,0.408636,-91.630760,0.042104,0.000000
3.110000,0.086021,-91.630760,0.001854,0.001782,0.045261,0.382642,0.019493,0.452605,-91.630760,0.046267,0.000000
3.360000,0.063309,-91.675240,0.002035,0.001943,0.049363,0.281611,0.014346,0.493626,-91.675240,0.050429,0.000000
3.610000,0.075966,-91.675240,0.002199,0.002104,0.053447,0.337913,0.017214,0.534473,-91.675240,0.054592,0.000000
3.860000,0.063683,-91.675240,0.002358,0.002268,0.057601,0.283274,0.014431,0.576012,-91.675240,0.058754,0.000000
4.110000,0.043945,-91.675240,0.002557,0.002432,0.061781,0.195479,0.009958,0.617812,-91.675240,0.062917,0.000000
4.360000,0.045807,-91.675240,0.002725,0.002599,0.066022,0.203759,0.010380,0.660218,-91.675240,0.067080,0.000000
4.610000,0.105759,-91.675240,0.002889,0.002759,0.070089,0.470438,0.023965,0.700891,-91.675240,0.071260,0.000000
4.860000,0.079689,-91.764198,0.003053,0.002930,0.074425,0.354474,0.018058,0.744254,-91.764198,0.075423,0.000000
5.110000,0.064423,-91.675240,0.003234,0.003087,0.078415,0.286566,0.014598,0.784147,-91.675240,0.079585,0.000000
5.360000,0.085274,-91.764198,0.003406,0.003254,0.082655,0.379317,0.019323,0.826553,-91.764198,0.083748,0.000000
5.610000,0.089745,-91.764198,0.003574,0.003418,0.086809,0.399204,0.020336,0.868092,-91.764198,0.087911,0.000000
5.860000,0.059212,-91.764198,0.003742,0.003581,0.090946,0.263387,0.013418,0.909461,-91.764198,0.092073,0.000000
6.110000,0.064049,-91.764198,0.003932,0.003747,0.095178,0.284903,0.014514,0.951780,-91.764198,0.096236,0.000000
6.360000,0.089745,-91.808685,0.004096,0.003904,0.099159,0.399204,0.020336,0.991586,-91.808685,0.100399,0.000000
6.610000,0.068520,-91.808685,0.004260,0.004074,0.103486,0.304790,0.015527,1.034862,-91.808685,0.104579,0.000000
6.860000,0.072243,-91.853165,0.004458,0.004234,0.107553,0.321352,0.016370,1.075535,-91.853165,0.108742,0.000000
7.110000,0.087135,-91.808685,0.004600,0.004400,0.111751,0.387597,0.019745,1.117509,-91.808685,0.112904,0.000000
7.360000,0.107994,-91.808685,0.004777,0.004567,0.115992,0.480382,0.024472,1.159915,-91.808685,0.117067,0.000000
7.610000,0.083412,-91.808685,0.004958,0.004729,0.120119,0.371036,0.018901,1.201193,-91.808685,0.121229,0.000000
7.860001,0.082672,-91.808685,0.005122,0.004891,0.124230,0.367744,0.018734,1.242301,-91.808685,0.125392,0.000000
8.110001,0.094215,-91.853165,0.005282,0.005052,0.128315,0.419091,0.021350,1.283148,-91.853165,0.129555,0.000000
8.360001,0.068146,-91.853165,0.005476,0.005222,0.132651,0.303127,0.015442,1.326507,-91.853165,0.133735,0.000000
8.610001,0.026443,-91.853165,0.005618,0.005383,0.136727,0.117626,0.005992,1.367267,-91.853165,0.137898,0.000000
8.860001,0.090118,-91.897644,0.005812,0.005548,0.140915,0.400867,0.020421,1.409154,-91.897644,0.142060,0.000000
9.110001,0.083046,-91.853165,0.005963,0.005711,0.145070,0.369407,0.018818,1.450697,-91.853165,0.146223,0.000000
9.360001,0.062187,-91.853165,0.006161,0.005877,0.149284,0.276622,0.014092,1.492842,-91.853165,0.150386,0.000000
9.610001,0.091232,-91.942123,0.006312,0.006041,0.153429,0.405822,0.020674,1.534294,-91.942123,0.154548,0.000000
9.860001,0.102409,-91.897644,0.006502,0.006201,0.157506,0.455540,0.023206,1.575058,-91.897644,0.158711,0.000000
10.110001,0.077454,-91.986610,0.006670,0.006371,0.161816,0.344531,0.017551,1.618156,-91.986610,0.162874,0.000000
10.360001,0.060326,-91.942123,0.006825,0.006533,0.165926,0.268342,0.013670,1.659264,-91.942123,0.167054,0.000000
10.610001,0.093094,-91.986610,0.007006,0.006693,0.169994,0.414102,0.021095,1.699936,-91.986610,0.171217,0.000000
10.860001,0.062187,-91.986610,0.007187,0.006859,0.174208,0.276622,0.014092,1.742085,-91.986610,0.175379,0.000000
11.110001,0.086021,-91.986610,0.007351,0.007022,0.178371,0.382642,0.019493,1.783711,-91.986610,0.179542,0.000000
11.360001,0.090492,-91.942123,0.007519,0.007189,0.182594,0.402530,0.020506,1.825943,-91.942123,0.183704,0.000000
11.610001,0.120277,-91.986610,0.007700,0.007352,0.186749,0.535021,0.027255,1.867486,-91.986610,0.187867,0.000000
11.860001,0.083786,-91.986610,0.007873,0.007518,0.190954,0.372699,0.018986,1.909544,-91.986610,0.192030,0.000000
12.110001,0.078575,-91.986610,0.008028,0.007679,0.195048,0.349520,0.017805,1.950477,-91.986610,0.196193,0.000000
12.360001,0.100548,-91.986610,0.008205,0.007837,0.199063,0.447259,0.022784,1.990631,-91.986610,0.200373,0.000000
12.610001,0.088631,-92.031090,0.008395,0.008009,0.203425,0.394249,0.020084,2.034252,-92.031090,0.204535,0.000000
12.860001,0.036125,-92.031090,0.008550,0.008168,0.207475,0.160693,0.008186,2.074751,-92.031090,0.208698,0.000000
13.110001,0.105011,-92.031090,0.008731,0.008335,0.211716,0.467112,0.023796,2.117157,-92.031090,0.212861,0.000000
13.360001,0.108734,-92.031090,0.008908,0.008496,0.215800,0.483674,0.024640,2.158003,-92.031090,0.217023,0.000000
13.610001,0.077827,-91.986610,0.009097,0.008668,0.220163,0.346194,0.017636,2.201628,-91.986610,0.221186,0.000000
13.860001,0.091980,-92.075569,0.009240,0.008829,0.224256,0.409147,0.020843,2.242558,-92.075569,0.225348,0.000000
14.110001,0.111717,-92.031090,0.009421,0.008991,0.228367,0.496943,0.025315,2.283666,-92.031090,0.229529,0.000000
14.360001,0.088257,-92.120049,0.009585,0.009159,0.232633,0.392586,0.019999,2.326333,-92.120049,0.233692,0.000000
14.610001,0.067032,-92.120049,0.009748,0.009318,0.236683,0.298173,0.015190,2.366831,-92.120049,0.237854,0.000000
14.860001,0.100174,-92.164528,0.009942,0.009485,0.240924,0.445596,0.022700,2.409241,-92.164528,0.242017,0.000000
15.110001,0.092728,-92.031090,0.010085,0.009642,0.244905,0.412473,0.021012,2.449047,-92.031090,0.246179,0.000000
15.360001,0.124748,-92.120049,0.010270,0.009810,0.249171,0.554908,0.028268,2.491714,-92.120049,0.250342,0.000000
15.610001,0.174271,-92.075569,0.010455,0.009977,0.253421,0.775194,0.039490,2.534207,-92.075569,0.254505,0.000000
15.860001,0.361206,-92.120049,0.010619,0.010137,0.257488,1.606725,0.081850,2.574879,-92.120049,0.258667,0.000000
16.110001,0.681816,-92.120049,0.010770,-0.000002,-0.000061,3.032870,0.154502,-0.000606,-92.120049,0.000087,0.000000
16.360001,0.606224,-92.253494,0.010757,-0.000005,-0.000130,2.696619,0.137372,-0.001298,-92.253494,0.000087,0.000000
16.610001,0.584259,-92.120049,0.010779,-0.000005,-0.000130,2.598914,0.132395,-0.001298,-92.120049,0.000087,0.000000
16.860001,0.576805,-92.164528,0.010757,-0.000005,-0.000121,2.565757,0.130706,-0.001211,-92.164528,0.000486,0.000000
17.110001,0.577179,-92.164528,0.010783,0.000005,0.000130,2.567420,0.130791,0.001302,-92.164528,0.000902,0.000000
17.360001,0.657616,-92.209015,0.010792,0.000019,0.000486,2.925220,0.149018,0.004856,-92.209015,0.001318,0.000000
17.610001,0.736557,-92.253494,0.010813,0.000033,0.000841,3.276369,0.166906,0.008414,-92.253494,0.001735,0.000000
17.860001,0.771561,-92.209015,0.010822,0.000049,0.001240,3.432073,0.174838,0.012403,-92.209015,0.002151,0.000000
18.110001,0.830025,-92.209015,0.010839,0.000065,0.001639,3.692134,0.188086,0.016392,-92.209015,0.002567,0.000000
18.360001,0.905983,-92.209015,0.010856,0.000084,0.002142,4.030014,0.205299,0.021423,-92.209015,0.002983,0.000000
18.610001,0.944710,-92.209015,0.010874,0.000098,0.002489,4.202279,0.214074,0.024889,-92.209015,0.003400,0.000000
18.860001,1.014343,-92.209015,0.010887,0.000114,0.002888,4.512024,0.229853,0.028879,-92.209015,0.003816,0.000000
19.110001,1.078392,-92.209015,0.010917,0.000134,0.003408,4.796927,0.244367,0.034083,-92.209015,0.004232,0.000000
19.360001,1.121964,-92.164528,0.010925,0.000150,0.003799,4.990743,0.254241,0.037985,-92.164528,0.004657,0.000000
19.610001,1.184517,-92.253494,0.010951,0.000166,0.004206,5.268994,0.268415,0.042062,-92.253494,0.005073,0.000000
19.860001,1.221756,-92.253494,0.010938,0.000180,0.004570,5.434642,0.276854,0.045703,-92.253494,0.005490,0.000000
20.110001,1.334213,-92.253494,0.010990,0.000196,0.004987,5.934877,0.302337,0.049866,-92.253494,0.005906,0.000000
20.360001,1.386345,-92.209015,0.010990,0.000212,0.005394,6.166770,0.314150,0.053942,-92.209015,0.006322,0.000000
20.610001,1.446297,-92.297974,0.011003,0.000222,0.005646,6.433449,0.327736,0.056459,-92.297974,0.006739,0.000000
20.860001,1.616470,-92.297974,0.010999,0.000244,0.006192,7.190419,0.366297,0.061921,-92.297974,0.007155,0.000000
21.110001,1.724091,-92.342453,0.011020,0.000262,0.006652,7.669138,0.390684,0.066516,-92.342453,0.007571,0.000000
21.360001,1.858139,-92.342453,0.011068,0.000281,0.007146,8.265415,0.421060,0.071459,-92.342453,0.007987,0.000000
21.610001,1.888306,-92.386932,0.011055,0.000294,0.007467,8.399603,0.427896,0.074668,-92.386932,0.008404,0.000000
21.860001,2.070023,-92.342453,0.011089,0.000310,0.007883,9.207920,0.469074,0.078832,-92.342453,0.008820,0.000000
22.110001,2.189178,-92.386932,0.011085,0.000326,0.008282,9.737952,0.496075,0.082821,-92.386932,0.009236,0.000000
22.360001,2.300896,-92.386932,0.011098,0.000340,0.008629,10.234895,0.521390,0.086292,-92.386932,0.009652,0.000000
22.610001,2.407394,-92.386932,0.011124,0.000352,0.008933,10.708625,0.545523,0.089327,-92.386932,0.010069,0.000000
22.860001,2.659859,-92.386932,0.011141,0.000374,0.009496,11.831642,0.602733,0.094963,-92.386932,0.010485,0.000000
23.110001,2.850143,-92.342453,0.011158,0.000392,0.009947,12.678071,0.645852,0.099471,-92.342453,0.010901,0.000000
23.360001,2.909348,-92.386932,0.011175,0.000406,0.010312,12.941424,0.659268,0.103116,-92.386932,0.011318,0.000000
23.610001,3.088837,-92.386932,0.011201,0.000422,0.010719,13.739832,0.699940,0.107192,-92.386932,0.011734,0.000000
23.860001,3.320076,-92.431419,0.011219,0.000440,0.011179,14.768435,0.752340,0.111787,-92.431419,0.012150,0.000000
24.110001,3.617233,-92.431419,0.011232,0.000460,0.011673,16.090258,0.819677,0.116730,-92.431419,0.012566,0.000000
24.360001,3.691330,-92.475899,0.011253,0.000472,0.011994,16.419855,0.836467,0.119940,-92.475899,0.012991,0.000000
24.610001,3.794853,-92.431419,0.011232,0.000484,0.012289,16.880350,0.859926,0.122888,-92.431419,0.013408,0.000000
24.860001,4.078598,-92.431419,0.011275,0.000503,0.012783,18.142509,0.924224,0.127831,-92.431419,0.013824,0.000000
25.110001,4.218613,-92.520378,0.011279,0.000522,0.013269,18.765326,0.955951,0.132687,-92.520378,0.014240,0.000000
25.360001,4.418945,-92.431419,0.011305,0.000538,0.013676,19.656450,1.001347,0.136763,-92.431419,0.014656,0.000000
25.610001,4.568642,-92.475899,0.011309,0.000553,0.014058,20.322332,1.035269,0.140579,-92.475899,0.015073,0.000000
25.860001,4.598061,-92.520378,0.011331,0.000568,0.014422,20.453196,1.041935,0.144220,-92.520378,0.015489,0.000000
26.110001,5.136139,-92.564857,0.011348,0.000593,0.015073,22.846687,1.163866,0.150726,-92.564857,0.015905,0.000000
26.360001,4.992027,-92.475899,0.011365,0.000601,0.015263,22.205647,1.131209,0.152633,-92.475899,0.016321,0.000000
26.610001,5.266098,-92.520378,0.011378,0.000619,0.015723,23.424774,1.193315,0.157228,-92.520378,0.016738,0.000000
26.860001,5.328651,-92.564857,0.011395,0.000632,0.016044,23.703026,1.207490,0.160438,-92.564857,0.017154,0.000000
27.110001,5.444832,-92.520378,0.011421,0.000650,0.016512,24.219822,1.233817,0.165120,-92.520378,0.017570,0.000000
27.360001,5.708473,-92.564857,0.011438,0.000664,0.016876,25.392557,1.293559,0.168765,-92.564857,0.017986,0.000000
27.610001,5.916626,-92.609337,0.011456,0.000685,0.017405,26.318466,1.340727,0.174052,-92.609337,0.018403,0.000000
27.860001,6.153831,-92.609337,0.011456,0.000704,0.017874,27.373610,1.394478,0.178738,-92.609337,0.018819,0.000000
28.110001,6.351562,-92.653824,0.011477,0.000721,0.018325,28.253160,1.439285,0.183246,-92.653824,0.019235,0.000000
28.360001,6.195908,-92.564857,0.011473,0.000730,0.018533,27.560774,1.404013,0.185327,-92.564857,0.019652,0.000000
28.610001,6.466995,-92.609337,0.011520,0.000742,0.018845,28.766632,1.465442,0.188450,-92.609337,0.020068,0.000000
28.860001,6.940651,-92.609337,0.011503,0.000769,0.019521,30.873558,1.572774,0.195214,-92.609337,0.020484,0.000000
29.110001,7.262009,-92.564857,0.011512,0.000788,0.020007,32.303028,1.645595,0.200070,-92.564857,0.020900,0.000000
29.360001,7.329414,-92.609337,0.011538,0.000803,0.020397,32.602863,1.660869,0.203972,-92.609337,0.021317,0.000000
29.610001,7.463089,-92.698303,0.011563,0.000817,0.020753,33.197479,1.691160,0.207530,-92.698303,0.021742,0.000000
29.860001,7.630661,-92.653824,0.011598,0.000833,0.021161,33.942875,1.729132,0.211606,-92.653824,0.022158,0.000000
30.110001,8.035057,-92.653824,0.011615,0.000852,0.021646,35.741718,1.820770,0.216462,-92.653824,0.022574,0.000000
30.360001,8.144905,-92.653824,0.011632,0.000865,0.021967,36.230347,1.845662,0.219668,-92.653824,0.022990,0.000000
30.610001,8.213051,-92.653824,0.011624,0.000875,0.022236,36.533474,1.861104,0.222359,-92.653824,0.023407,0.000000
30.860001,8.749268,-92.698303,0.011632,0.000899,0.022834,38.918686,1.982612,0.228343,-92.698303,0.023823,0.000000
31.110001,9.008064,-92.698303,0.011658,0.000917,0.023294,40.069870,2.041257,0.232938,-92.698303,0.024239,0.000000
31.360001,9.124245,-92.698303,0.011671,0.000932,0.023667,40.586666,2.067583,0.236666,-92.698303,0.024655,0.000000
31.610001,9.313042,-92.698303,0.011689,0.000947,0.024057,41.426479,2.110365,0.240568,-92.698303,0.025072,0.000000
31.860001,9.839203,-92.698303,0.011701,0.000969,0.024621,43.766960,2.229595,0.246207,-92.698303,0.025488,0.000000
32.110001,9.890961,-92.698303,0.011689,0.000982,0.024942,43.997192,2.241324,0.249417,-92.698303,0.025904,0.000000
32.360001,10.096512,-92.698303,0.011736,0.000997,0.025332,44.911530,2.287902,0.253319,-92.698303,0.026321,0.000000
32.610001,10.346375,-92.698303,0.011745,0.001014,0.025757,46.022972,2.344522,0.257566,-92.698303,0.026736,0.000000
32.860001,10.913872,-92.787262,0.011753,0.001036,0.026321,48.547325,2.473119,0.263205,-92.787262,0.027153,0.000000
33.110001,10.973450,-92.698303,0.011788,0.001050,0.026667,48.812344,2.486619,0.266672,-92.698303,0.027569,0.000000
33.360001,11.101913,-92.742783,0.011792,0.001065,0.027049,49.383778,2.515729,0.270488,-92.742783,0.027986,0.000000
33.610001,11.275444,-92.742783,0.011814,0.001081,0.027465,50.155682,2.555052,0.274651,-92.742783,0.028402,0.000000
33.860001,11.683189,-92.787262,0.011831,0.001099,0.027925,51.969421,2.647449,0.279250,-92.787262,0.028818,0.000000
34.110001,11.895439,-92.831741,0.011831,0.001113,0.028280,52.913555,2.695545,0.282804,-92.831741,0.029234,0.000000
34.360001,11.987793,-92.831741,0.011852,0.001126,0.028610,53.324368,2.716473,0.286100,-92.831741,0.029650,0.000000
34.610001,12.465546,-92.742783,0.011874,0.001146,0.029113,55.449516,2.824733,0.291130,-92.742783,0.030076,0.000000
34.860001,12.867706,-92.831741,0.011874,0.001169,0.029703,57.238415,2.915864,0.297027,-92.831741,0.030492,0.000000
35.110001,12.812592,-92.787262,0.011900,0.001183,0.030058,56.993252,2.903375,0.300581,-92.787262,0.030908,0.000000
35.360001,12.890419,-92.831741,0.011913,0.001198,0.030422,57.339447,2.921011,0.304222,-92.831741,0.031324,0.000000
35.610001,13.265404,-92.831741,0.011947,0.001217,0.030900,59.007462,3.005983,0.308995,-92.831741,0.031741,0.000000
35.860001,13.413605,-92.876228,0.011943,0.001232,0.031281,59.666695,3.039566,0.312810,-92.876228,0.032157,0.000000
36.110001,13.516754,-92.831741,0.011964,0.001245,0.031619,60.125526,3.062940,0.316190,-92.831741,0.032573,0.000000
36.360001,13.929337,-92.876228,0.011982,0.001264,0.032096,61.960785,3.156433,0.320963,-92.876228,0.032990,0.000000
36.610001,14.229469,-92.876228,0.011990,0.001284,0.032608,63.295841,3.224444,0.326076,-92.876228,0.033405,0.000000
36.860001,14.331505,-92.876228,0.012003,0.001298,0.032972,63.749718,3.247566,0.329721,-92.876228,0.033822,0.000000
37.110001,14.481941,-92.831741,0.012033,0.001315,0.033388,64.418892,3.281655,0.333885,-92.831741,0.034238,0.000000
37.360001,14.526253,-92.876228,0.012038,0.001327,0.033718,64.615997,3.291696,0.337177,-92.876228,0.034654,0.000000
37.610001,14.779091,-92.920708,0.012064,0.001344,0.034125,65.740677,3.348990,0.341254,-92.920708,0.035071,0.000000
37.860001,14.634239,-92.920708,0.012068,0.001352,0.034342,65.096344,3.316166,0.343422,-92.920708,0.035487,0.000000
38.110001,14.985016,-92.876228,0.012072,0.001371,0.034828,66.656677,3.395653,0.348278,-92.876228,0.035903,0.000000
38.360001,15.477669,-92.965187,0.012098,0.001392,0.035366,68.848106,3.507290,0.353657,-92.965187,0.036319,0.000000
38.610001,15.888763,-92.965187,0.012124,0.001412,0.035860,70.676750,3.600445,0.358600,-92.965187,0.036736,0.000000
38.860001,15.774818,-92.965187,0.012146,0.001424,0.036181,70.169899,3.574625,0.361809,-92.965187,0.037152,0.000000
39.110001,15.997498,-92.920708,0.012141,0.001444,0.036675,71.160423,3.625085,0.366753,-92.920708,0.037568,0.000000
39.360001,16.159477,-92.965187,0.012154,0.001459,0.037065,71.880943,3.661790,0.370655,-92.965187,0.037984,0.000000
39.610001,16.447693,-92.965187,0.012167,0.001477,0.037525,73.162994,3.727100,0.375250,-92.965187,0.038409,0.000000
39.860001,16.630905,-92.965187,0.012189,0.001494,0.037950,73.977959,3.768617,0.379500,-92.965187,0.038826,0.000000
40.110001,16.393326,-92.965187,0.012206,0.001505,0.038236,72.921158,3.714781,0.382361,-92.965187,0.039242,0.000000
40.360001,16.907204,-93.009666,0.012227,0.001526,0.038748,75.207001,3.831227,0.387479,-93.009666,0.039659,0.000000
40.610001,17.282181,-93.054146,0.012245,0.001545,0.039233,76.874977,3.916198,0.392335,-93.054146,0.040074,0.000000
40.860001,16.986519,-93.054146,0.012258,0.001554,0.039467,75.559807,3.849200,0.394674,-93.054146,0.040491,0.000000
41.110001,17.353676,-93.054146,0.012266,0.001575,0.039996,77.193008,3.932399,0.399965,-93.054146,0.040907,0.000000
41.360001,17.219994,-93.054146,0.012279,0.001586,0.040283,76.598358,3.902106,0.402826,-93.054146,0.041323,0.000000
41.610001,17.626251,-93.054146,0.012296,0.001603,0.040708,78.405479,3.994166,0.407077,-93.054146,0.041740,0.000000
41.860001,17.747650,-93.009666,0.012314,0.001621,0.041176,78.945488,4.021675,0.411759,-93.009666,0.042156,0.000000
42.110001,17.999374,-93.143112,0.012318,0.001635,0.041540,80.065216,4.078716,0.415404,-93.143112,0.042572,0.000000
42.360001,18.456642,-93.098633,0.012344,0.001655,0.042035,82.099243,4.182335,0.420347,-93.098633,0.042988,0.000000
42.610001,18.776512,-93.098633,0.012361,0.001676,0.042572,83.522095,4.254818,0.425721,-93.098633,0.043405,0.000000
42.860001,18.655861,-93.054146,0.012383,0.001688,0.042884,82.985413,4.227479,0.428844,-93.054146,0.043821,0.000000
43.110001,18.644691,-93.143112,0.012391,0.001702,0.043240,82.935730,4.224947,0.432402,-93.143112,0.044237,0.000000
43.360001,18.675224,-93.098633,0.012409,0.001718,0.043630,83.071548,4.231866,0.436304,-93.098633,0.044653,0.000000
43.610001,19.169365,-93.143112,0.012421,0.001736,0.044090,85.269592,4.343840,0.440899,-93.143112,0.045070,0.000000
43.860001,19.146652,-93.143112,0.012443,0.001748,0.044402,85.168564,4.338694,0.444021,-93.143112,0.045486,0.000000
44.110001,19.527962,-93.143112,0.012456,0.001769,0.044923,86.864716,4.425099,0.449225,-93.143112,0.045902,0.000000
44.360001,19.792343,-93.143112,0.012456,0.001787,0.045382,88.040741,4.485009,0.453820,-93.143112,0.046319,0.000000
44.610001,19.857140,-93.232071,0.012478,0.001801,0.045755,88.328972,4.499692,0.457548,-93.232071,0.046735,0.000000
44.860001,20.045189,-93.143112,0.012490,0.001818,0.046189,89.165451,4.542305,0.461886,-93.143112,0.047160,0.000000
45.110001,20.154289,-93.187592,0.012521,0.001836,0.046639,89.650757,4.567028,0.466394,-93.187592,0.047576,0.000000
45.360001,20.522942,-93.187592,0.012555,0.001855,0.047125,91.290604,4.650565,0.471253,-93.187592,0.047992,0.000000
45.610001,20.568367,-93.187592,0.012538,0.001869,0.047463,91.492668,4.660859,0.474633,-93.187592,0.048409,0.000000
45.860001,20.014648,-93.187592,0.012555,0.001879,0.047723,89.029602,4.535384,0.477234,-93.187592,0.048825,0.000000
46.110001,20.755669,-93.232071,0.012581,0.001899,0.048235,92.325829,4.703302,0.482351,-93.232071,0.049241,0.000000
46.360001,20.931061,-93.232071,0.012603,0.001915,0.048651,93.106010,4.743046,0.486514,-93.232071,0.049657,0.000000
46.610001,21.095650,-93.276558,0.012607,0.001933,0.049103,93.838135,4.780343,0.491026,-93.276558,0.050074,0.000000
46.860001,21.077774,-93.232071,0.012616,0.001949,0.049502,93.758621,4.776292,0.495015,-93.232071,0.050490,0.000000
47.110001,21.175339,-93.232071,0.012637,0.001959,0.049770,94.192612,4.798400,0.497702,-93.232071,0.050906,0.000000
47.360001,21.916733,-93.232071,0.012654,0.001986,0.050447,97.490494,4.966403,0.504466,-93.232071,0.051322,0.000000
47.610001,21.821777,-93.232071,0.012667,0.001996,0.050690,97.068115,4.944885,0.506896,-93.232071,0.051739,0.000000
47.860001,21.884331,-93.232071,0.012693,0.002013,0.051132,97.346367,4.959060,0.511317,-93.232071,0.052155,0.000000
48.110001,22.072754,-93.276558,0.012693,0.002028,0.051522,98.184509,5.001758,0.515219,-93.276558,0.052571,0.000000
48.360001,22.139412,-93.276558,0.012723,0.002041,0.051852,98.481026,5.016862,0.518515,-93.276558,0.052988,0.000000
48.610001,22.511040,-93.232071,0.012732,0.002061,0.052337,100.134109,5.101075,0.523372,-93.232071,0.053404,0.000000
48.860001,22.317406,-93.276558,0.012741,0.002079,0.052805,99.272781,5.057196,0.528053,-93.276558,0.053820,0.000000
49.110001,23.088585,-93.321037,0.012762,0.002098,0.053283,102.703156,5.231948,0.532826,-93.321037,0.054236,0.000000
49.360001,23.180565,-93.276558,0.012771,0.002112,0.053647,103.112305,5.252791,0.536467,-93.276558,0.054653,0.000000
49.610001,22.928467,-93.321037,0.012775,0.002123,0.053924,101.990913,5.195665,0.539242,-93.321037,0.055069,0.000000
49.860001,23.320572,-93.321037,0.012810,0.002143,0.054427,103.735085,5.284517,0.544272,-93.321037,0.055494,0.000000
50.110001,23.419250,-93.365517,0.012822,0.002157,0.054800,104.174026,5.306878,0.548000,-93.365517,0.055910,0.000000
50.360001,24.003502,-93.321037,0.012831,0.002181,0.055407,106.772911,5.439271,0.554071,-93.321037,0.056326,0.000000
50.610001,23.727577,-93.365517,0.012874,0.002192,0.055667,105.545532,5.376746,0.556675,-93.365517,0.056743,0.000000
50.860001,24.130486,-93.365517,0.012861,0.002210,0.056127,107.337761,5.468046,0.561270,-93.365517,0.057159,0.000000
51.110001,24.290604,-93.365517,0.012866,0.002227,0.056578,108.050003,5.504330,0.565777,-93.365517,0.057575,0.000000
51.360001,24.534508,-93.409996,0.012904,0.002245,0.057029,109.134941,5.559599,0.570289,-93.409996,0.057991,0.000000
51.610001,24.795540,-93.409996,0.012904,0.002261,0.057437,110.296066,5.618750,0.574365,-93.409996,0.058408,0.000000
51.860001,24.694626,-93.454475,0.012917,0.002273,0.057740,109.847183,5.595882,0.577401,-93.454475,0.058824,0.000000
52.110001,25.043167,-93.409996,0.012935,0.002294,0.058269,111.397568,5.674863,0.582688,-93.409996,0.059240,0.000000
52.360001,25.668381,-93.365517,0.012969,0.002314,0.058772,114.178658,5.816538,0.587718,-93.365517,0.059657,0.000000
52.610001,25.380539,-93.454475,0.012969,0.002325,0.059058,112.898277,5.751312,0.590584,-93.454475,0.060073,0.000000
52.860001,25.773392,-93.454475,0.012999,0.002344,0.059535,114.645775,5.840334,0.595353,-93.454475,0.060489,0.000000
53.110004,25.698174,-93.454475,0.013016,0.002362,0.059986,114.311188,5.823289,0.599860,-93.454475,0.060905,0.000000
53.360004,26.251892,-93.454475,0.013025,0.002377,0.060385,116.774246,5.948763,0.603850,-93.454475,0.061322,0.000000
53.610004,26.275719,-93.543442,0.013038,0.002393,0.060775,116.880234,5.954163,0.607752,-93.543442,0.061738,0.000000
53.860004,26.285774,-93.587921,0.013051,0.002406,0.061105,116.924965,5.956442,0.611049,-93.587921,0.062154,0.000000
54.110004,26.978020,-93.498962,0.013064,0.002429,0.061703,120.004227,6.113307,0.617033,-93.498962,0.062570,0.000000
54.360004,27.237930,-93.543442,0.013077,0.002445,0.062102,121.160362,6.172204,0.621022,-93.543442,0.062987,0.000000
54.610004,27.244637,-93.543442,0.013103,0.002461,0.062510,121.190193,6.173723,0.625098,-93.543442,0.063403,0.000000
54.860004,27.371986,-93.498962,0.013124,0.002474,0.062831,121.756676,6.202580,0.628308,-93.498962,0.063828,0.000000
55.110004,27.808777,-93.543442,0.013137,0.002493,0.063334,123.699615,6.301559,0.633338,-93.543442,0.064244,0.000000
55.360004,27.716805,-93.498962,0.013150,0.002506,0.063654,123.290504,6.280717,0.636544,-93.498962,0.064660,0.000000
55.610004,27.715683,-93.587921,0.013163,0.002520,0.064010,123.285515,6.280463,0.640101,-93.587921,0.065077,0.000000
55.860004,28.304031,-93.543442,0.013180,0.002540,0.064522,125.902618,6.413785,0.645219,-93.543442,0.065493,0.000000
56.110004,29.207779,-93.498962,0.013198,0.002563,0.065103,129.922684,6.618577,0.651028,-93.498962,0.065909,0.000000
56.360004,29.134422,-93.632401,0.013202,0.002577,0.065458,129.596390,6.601954,0.654582,-93.632401,0.066325,0.000000
56.610004,29.204430,-93.587921,0.013236,0.002592,0.065840,129.907791,6.617818,0.658398,-93.587921,0.066742,0.000000
56.860004,29.295288,-93.587921,0.013254,0.002607,0.066230,130.311951,6.638407,0.662300,-93.587921,0.067158,0.000000
57.110004,29.938377,-93.632401,0.013262,0.002626,0.066707,133.172546,6.784133,0.667073,-93.632401,0.067574,0.000000
57.360004,29.928696,-93.632401,0.013271,0.002640,0.067054,133.129486,6.781940,0.670540,-93.632401,0.067991,0.000000
57.610004,29.714211,-93.543442,0.013284,0.002654,0.067401,132.175415,6.733336,0.674010,-93.543442,0.068407,0.000000
57.860004,30.653702,-93.632401,0.013292,0.002673,0.067904,136.354477,6.946228,0.679040,-93.632401,0.068823,0.000000
58.110004,30.940804,-93.587921,0.013310,0.002690,0.068337,137.631561,7.011287,0.683374,-93.587921,0.069239,0.000000
58.360004,31.052887,-93.676880,0.013327,0.002708,0.068789,138.130142,7.036685,0.687886,-93.676880,0.069656,0.000000
58.610004,31.283012,-93.632401,0.013336,0.002722,0.069144,139.153793,7.088832,0.691440,-93.632401,0.070072,0.000000
58.860004,31.282272,-93.632401,0.013353,0.002739,0.069560,139.150497,7.088664,0.695603,-93.632401,0.070488,0.000000
59.110004,31.622246,-93.676880,0.013370,0.002751,0.069873,140.662781,7.165703,0.698726,-93.676880,0.070904,0.000000
59.360004,31.970039,-93.676880,0.013374,0.002768,0.070298,142.209839,7.244514,0.702976,-93.676880,0.071321,0.000000
59.610004,32.083984,-93.676880,0.013392,0.002783,0.070688,142.716690,7.270335,0.706878,-93.676880,0.071737,0.000000
59.860004,33.162376,-93.676880,0.013409,0.002807,0.071295,147.513611,7.514702,0.712949,-93.676880,0.072153,0.000000
60.110004,33.227547,-93.721367,0.013426,0.002820,0.071633,147.803513,7.529469,0.716329,-93.721367,0.072578,0.000000
60.360004,33.385056,-93.676880,0.013452,0.002836,0.072032,148.504150,7.565162,0.720318,-93.676880,0.072994,0.000000
60.610004,34.000214,-93.765846,0.013465,0.002855,0.072526,151.240509,7.704558,0.725262,-93.765846,0.073411,0.000000
60.860004,34.119377,-93.676880,0.013473,0.002870,0.072890,151.770569,7.731561,0.728903,-93.676880,0.073827,0.000000
61.110004,34.667511,-93.721367,0.013482,0.002886,0.073298,154.208786,7.855770,0.732979,-93.721367,0.074243,0.000000
61.360004,34.539413,-93.765846,0.013478,0.002897,0.073584,153.638977,7.826743,0.735840,-93.765846,0.074660,0.000000
61.610004,35.454704,-93.810326,0.013512,0.002920,0.074174,157.710403,8.034151,0.741741,-93.810326,0.075076,0.000000
61.860004,36.004326,-93.765846,0.013534,0.002940,0.074668,160.155243,8.158697,0.746684,-93.765846,0.075492,0.000000
62.110004,35.953682,-93.765846,0.013542,0.002950,0.074920,159.929962,8.147221,0.749197,-93.765846,0.075908,0.000000
62.360004,36.479469,-93.810326,0.013568,0.002968,0.075397,162.268784,8.266366,0.753966,-93.810326,0.076325,0.000000
62.610004,36.452286,-93.854805,0.013568,0.002981,0.075709,162.147873,8.260206,0.757089,-93.854805,0.076741,0.000000
62.860004,36.885361,-93.810326,0.013581,0.002998,0.076151,164.074280,8.358343,0.761513,-93.810326,0.077157,0.000000
63.110004,37.398491,-93.765846,0.013603,0.003014,0.076567,166.356796,8.474619,0.765673,-93.765846,0.077573,0.000000
63.360004,37.185860,-93.810326,0.013599,0.003025,0.076836,165.410965,8.426436,0.768364,-93.810326,0.077990,0.000000
63.610004,38.457512,-93.854805,0.013611,0.003050,0.077461,171.067551,8.714597,0.774609,-93.854805,0.078406,0.000000
63.860004,39.185875,-93.810326,0.013642,0.003070,0.077972,174.307480,8.879646,0.779722,-93.810326,0.078822,0.000000
64.110001,39.433502,-93.854805,0.013650,0.003084,0.078345,175.408981,8.935760,0.783454,-93.854805,0.079239,0.000000
64.360001,39.570908,-93.854805,0.013668,0.003096,0.078640,176.020187,8.966896,0.786403,-93.854805,0.079655,0.000000
64.610001,39.656181,-93.854805,0.013689,0.003108,0.078953,176.399506,8.986219,0.789525,-93.854805,0.080071,0.000000
64.860001,40.212135,-93.854805,0.013676,0.003129,0.079473,178.872513,9.112201,0.794726,-93.854805,0.080487,0.000000
65.110001,40.987411,-93.854805,0.013702,0.003146,0.079898,182.321106,9.287881,0.798976,-93.854805,0.080912,0.000000
65.360001,41.138969,-93.854805,0.013719,0.003161,0.080279,182.995270,9.322224,0.802791,-93.854805,0.081329,0.000000
65.610001,42.246033,-93.899284,0.013724,0.003180,0.080765,187.919739,9.573088,0.807647,-93.899284,0.081745,0.000000
65.860001,42.388649,-93.854805,0.013741,0.003196,0.081181,188.554123,9.605405,0.811811,-93.854805,0.082161,0.000000
66.110001,42.892845,-93.854805,0.013775,0.003211,0.081554,190.796906,9.719658,0.815539,-93.854805,0.082577,0.000000
66.360001,43.424217,-93.899284,0.013784,0.003227,0.081970,193.160568,9.840069,0.819702,-93.899284,0.082994,0.000000
66.610001,43.790260,-93.943771,0.013775,0.003243,0.082378,194.788803,9.923016,0.823779,-93.943771,0.083410,0.000000
66.860001,44.647835,-93.988251,0.013805,0.003261,0.082837,198.603485,10.117344,0.828373,-93.988251,0.083826,0.000000
67.110001,44.671295,-93.943771,0.013814,0.003276,0.083202,198.707840,10.122661,0.832018,-93.943771,0.084242,0.000000
67.360001,45.472641,-93.943771,0.013827,0.003293,0.083653,202.272415,10.304248,0.836526,-93.943771,0.084659,0.000000
67.610001,46.461288,-93.988251,0.013827,0.003312,0.084112,206.670135,10.528278,0.841125,-93.988251,0.085075,0.000000
67.860001,47.022079,-93.943771,0.013866,0.003328,0.084537,209.164658,10.655355,0.845371,-93.943771,0.085491,0.000000
68.110001,46.981865,-94.032730,0.013862,0.003339,0.084806,208.985779,10.646242,0.848063,-94.032730,0.085908,0.000000
68.360001,47.499466,-94.032730,0.013883,0.003354,0.085179,211.288177,10.763533,0.851791,-94.032730,0.086324,0.000000
68.610001,48.198036,-94.077209,0.013896,0.003372,0.085647,214.395569,10.921831,0.856473,-94.077209,0.086740,0.000000
68.860001,49.576927,-94.032730,0.013909,0.003393,0.086185,220.529190,11.234292,0.861851,-94.032730,0.087156,0.000000
69.110001,49.529266,-94.077209,0.013913,0.003404,0.086463,220.317184,11.223493,0.864625,-94.077209,0.087573,0.000000
69.360001,50.035316,-94.032730,0.013926,0.003420,0.086870,222.568207,11.338164,0.868702,-94.032730,0.087989,0.000000
69.610001,50.689949,-94.032730,0.013952,0.003434,0.087234,225.480148,11.486506,0.872343,-94.032730,0.088405,0.000000
69.860001,51.996231,-94.032730,0.013948,0.003457,0.087807,231.290787,11.782515,0.878065,-94.032730,0.088821,0.000000
70.110001,51.849144,-94.121689,0.013978,0.003464,0.087989,230.636505,11.749185,0.879890,-94.121689,0.089246,0.000000
70.360001,53.091011,-94.077209,0.013982,0.003490,0.088648,236.160614,12.030595,0.886479,-94.077209,0.089663,0.000000
70.610001,54.010025,-94.121689,0.013987,0.003505,0.089029,240.248596,12.238847,0.890294,-94.121689,0.090079,0.000000
70.860001,54.778229,-94.121689,0.013995,0.003521,0.089437,243.665726,12.412924,0.894371,-94.121689,0.090495,0.000000
71.110001,54.623695,-94.121689,0.014017,0.003533,0.089741,242.978333,12.377906,0.897406,-94.121689,0.090911,0.000000
71.360001,55.669685,-94.166176,0.014034,0.003547,0.090096,247.631134,12.614931,0.900960,-94.166176,0.091328,0.000000
71.610001,56.858673,-94.210655,0.014030,0.003570,0.090686,252.920013,12.884359,0.906861,-94.210655,0.091744,0.000000
71.860001,57.813805,-94.121689,0.014064,0.003586,0.091093,257.168640,13.100796,0.910933,-94.121689,0.092160,0.000000
72.110001,58.841927,-94.121689,0.014090,0.003607,0.091614,261.741974,13.333771,0.916138,-94.121689,0.092577,0.000000
72.360001,59.238503,-94.166176,0.014086,0.003619,0.091926,263.506012,13.423636,0.919260,-94.166176,0.092993,0.000000
72.610001,59.849197,-94.166176,0.014094,0.003635,0.092334,266.222534,13.562022,0.923337,-94.166176,0.093409,0.000000
72.860001,60.946953,-94.210655,0.014120,0.003653,0.092793,271.105591,13.810778,0.927931,-94.210655,0.093825,0.000000
73.110001,61.809364,-94.210655,0.014120,0.003669,0.093192,274.941772,14.006202,0.931921,-94.210655,0.094242,0.000000
73.360001,62.558578,-94.210655,0.014125,0.003684,0.093574,278.274445,14.175977,0.935740,-94.210655,0.094658,0.000000
73.610001,64.183983,-94.210655,0.014142,0.003709,0.094207,285.504608,14.544298,0.942068,-94.210655,0.095074,0.000000
73.860001,64.510185,-94.255135,0.014155,0.003720,0.094476,286.955627,14.618217,0.944755,-94.255135,0.095490,0.000000
74.110001,65.222908,-94.255135,0.014159,0.003735,0.094857,290.125977,14.779722,0.948574,-94.255135,0.095907,0.000000
74.360001,65.888329,-94.210655,0.014181,0.003750,0.095248,293.085937,14.930509,0.952476,-94.210655,0.096323,0.000000
74.610001,67.502937,-94.210655,0.014206,0.003768,0.095707,300.268066,15.296384,0.957071,-94.210655,0.096731,0.000000
74.860001,66.646477,-94.299614,0.014206,0.003760,0.095516,296.458344,15.102307,0.955164,-94.299614,0.095768,0.000000
75.110001,65.815712,-94.299614,0.014211,0.003759,0.095473,292.762909,14.914053,0.954728,-94.299614,0.095516,0.000000
75.360001,65.103004,-94.299614,0.014202,0.003757,0.095438,289.592621,14.752552,0.954384,-94.299614,0.095516,0.000000
75.610001,64.466240,-94.210655,0.014211,0.003757,0.095430,286.760162,14.608258,0.954297,-94.210655,0.095516,0.000000
75.860001,63.877525,-94.299614,0.014211,0.003756,0.095412,284.141418,14.474854,0.954123,-94.299614,0.095516,0.000000
76.110001,63.365501,-94.299614,0.014224,0.003756,0.095412,281.863831,14.358828,0.954123,-94.299614,0.095516,0.000000
76.360001,62.879936,-94.344101,0.014224,0.003756,0.095404,279.703918,14.248797,0.954036,-94.344101,0.095516,0.000000
76.610001,62.448357,-94.344101,0.014250,0.003756,0.095395,277.784149,14.151000,0.953949,-94.344101,0.095516,0.000000
76.860001,62.029808,-94.344101,0.014245,0.003756,0.095395,275.922363,14.056155,0.953949,-94.344101,0.095516,0.000000
77.110001,61.673073,-94.255135,0.014250,0.003755,0.095386,274.335541,13.975318,0.953862,-94.255135,0.095516,0.000000
77.360001,61.331612,-94.299614,0.014241,0.003755,0.095386,272.816620,13.897942,0.953862,-94.299614,0.095516,0.000000
77.610001,61.006905,-94.344101,0.014254,0.003755,0.095386,271.372253,13.824362,0.953862,-94.344101,0.095516,0.000000
77.860001,60.713470,-94.344101,0.014237,0.003755,0.095377,270.067017,13.757870,0.953775,-94.344101,0.095516,0.000000
78.110001,60.442383,-94.388580,0.014280,0.003755,0.095377,268.861145,13.696439,0.953775,-94.388580,0.095516,0.000000
78.360001,60.164597,-94.388580,0.014262,0.003755,0.095377,267.625488,13.633492,0.953775,-94.388580,0.095516,0.000000
78.610001,59.925156,-94.299614,0.014254,0.003755,0.095369,266.560394,13.579234,0.953688,-94.299614,0.095516,0.000000
78.860001,59.689445,-94.388580,0.014245,0.003755,0.095369,265.511902,13.525822,0.953688,-94.388580,0.095516,0.000000
79.110001,59.463417,-94.388580,0.014271,0.003755,0.095369,264.506500,13.474603,0.953688,-94.388580,0.095516,0.000000
79.360001,59.260475,-94.433060,0.014258,0.003755,0.095369,263.603760,13.428617,0.953688,-94.433060,0.095516,0.000000
79.610001,59.063858,-94.477539,0.014262,0.003754,0.095360,262.729156,13.384061,0.953604,-94.477539,0.095516,0.000000
79.860001,58.885864,-94.433060,0.014254,0.003754,0.095360,261.937408,13.343727,0.953604,-94.433060,0.095516,0.000000
80.110001,58.700050,-94.433060,0.014258,0.003754,0.095360,261.110870,13.301621,0.953604,-94.433060,0.095516,0.000000
80.360001,58.544403,-94.433060,0.014258,0.003754,0.095360,260.418518,13.266352,0.953604,-94.433060,0.095516,0.000000
80.610001,58.361565,-94.477539,0.014271,0.003754,0.095360,259.605194,13.224919,0.953604,-94.477539,0.095516,0.000000
80.860001,58.217087,-94.477539,0.014271,0.003754,0.095360,258.962524,13.192181,0.953604,-94.477539,0.095516,0.000000
81.110001,58.046913,-94.477539,0.014262,0.003754,0.095352,258.205566,13.153618,0.953517,-94.477539,0.095516,0.000000
81.360001,57.922165,-94.477539,0.014275,0.003754,0.095352,257.650665,13.125350,0.953517,-94.477539,0.095516,0.000000
81.610001,57.762421,-94.433060,0.014275,0.003754,0.095352,256.940094,13.089151,0.953517,-94.433060,0.095516,0.000000
81.860001,57.644379,-94.477539,0.014262,0.003754,0.095352,256.415009,13.062403,0.953517,-94.477539,0.095516,0.000000
82.110001,57.503250,-94.477539,0.014258,0.003754,0.095352,255.787231,13.030422,0.953517,-94.477539,0.095516,0.000000
82.360001,57.393028,-94.522018,0.014254,0.003754,0.095352,255.296936,13.005445,0.953517,-94.522018,0.095516,0.000000
82.610001,57.253761,-94.522018,0.014284,0.003754,0.095352,254.677444,12.973887,0.953517,-94.522018,0.095516,0.000000
82.860001,57.149124,-94.522018,0.014262,0.003754,0.095352,254.212006,12.950176,0.953517,-94.522018,0.095516,0.000000
83.110001,57.041504,-94.566505,0.014262,0.003754,0.095352,253.733276,12.925789,0.953517,-94.566505,0.095516,0.000000
83.360001,56.923836,-94.522018,0.014267,0.003754,0.095352,253.209869,12.899126,0.953517,-94.522018,0.095516,0.000000
83.610001,56.827766,-94.566505,0.014262,0.003754,0.095352,252.782532,12.877356,0.953517,-94.566505,0.095516,0.000000
83.860001,56.707863,-94.566505,0.014280,0.003754,0.095352,252.249176,12.850185,0.953517,-94.566505,0.095516,0.000000
84.110001,56.632271,-94.522018,0.014262,0.003754,0.095352,251.912918,12.833055,0.953517,-94.522018,0.095516,0.000000
84.360001,56.513855,-94.610985,0.014293,0.003754,0.095352,251.386185,12.806223,0.953517,-94.610985,0.095516,0.000000
84.610001,56.432304,-94.610985,0.014267,0.003754,0.095343,251.023422,12.787743,0.953430,-94.610985,0.095516,0.000000
84.860001,56.323944,-94.655464,0.014275,0.003754,0.095343,250.541412,12.763188,0.953430,-94.655464,0.095516,0.000000
85.110001,56.268463,-94.610985,0.014271,0.003754,0.095343,250.294632,12.750616,0.953430,-94.610985,0.095516,0.000000
85.360001,56.153397,-94.566505,0.014275,0.003754,0.095343,249.782776,12.724542,0.953430,-94.566505,0.095516,0.000000
85.610001,56.105736,-94.655464,0.014280,0.003754,0.095343,249.570770,12.713741,0.953430,-94.655464,0.095516,0.000000
85.860001,55.998863,-94.699944,0.014275,0.003754,0.095343,249.095383,12.689524,0.953430,-94.699944,0.095516,0.000000
86.110001,55.943756,-94.699944,0.014262,0.003754,0.095343,248.850250,12.677036,0.953430,-94.699944,0.095516,0.000000
86.360001,55.830925,-94.655464,0.014301,0.003754,0.095343,248.348358,12.651468,0.953430,-94.655464,0.095516,0.000000
86.610001,55.784378,-94.699944,0.014293,0.003754,0.095343,248.141312,12.640921,0.953430,-94.699944,0.095516,0.000000
86.860001,55.706924,-94.744423,0.014275,0.003754,0.095343,247.796768,12.623369,0.953430,-94.744423,0.095516,0.000000
87.110001,55.641388,-94.655464,0.014293,0.003754,0.095343,247.505249,12.608519,0.953430,-94.655464,0.095516,0.000000
87.360001,55.582550,-94.699944,0.014271,0.003754,0.095343,247.243530,12.595186,0.953430,-94.699944,0.095516,0.000000
87.610001,55.504356,-94.655464,0.014284,0.003753,0.095334,246.895706,12.577467,0.953343,-94.655464,0.095516,0.000000
87.860001,55.447006,-94.699944,0.014288,0.003753,0.095334,246.640594,12.564471,0.953343,-94.699944,0.095516,0.000000
88.110001,55.374023,-94.699944,0.014288,0.003753,0.095334,246.315964,12.547933,0.953343,-94.699944,0.095516,0.000000
88.360001,55.314072,-94.744423,0.014280,0.003753,0.095334,246.049286,12.534348,0.953343,-94.744423,0.095516,0.000000
88.610001,55.243317,-94.744423,0.014288,0.003753,0.095334,245.734543,12.518314,0.953343,-94.744423,0.095516,0.000000
88.860001,55.207947,-94.833389,0.014288,0.003753,0.095334,245.577209,12.510300,0.953343,-94.833389,0.095516,0.000000
89.110001,55.134590,-94.788910,0.014297,0.003753,0.095334,245.250900,12.493676,0.953343,-94.788910,0.095516,0.000000
89.360001,55.088783,-94.788910,0.014284,0.003753,0.095334,245.047150,12.483296,0.953343,-94.788910,0.095516,0.000000
89.610001,55.022507,-94.699944,0.014275,0.003753,0.095334,244.752335,12.468278,0.953343,-94.699944,0.095516,0.000000
89.860001,54.983406,-94.833389,0.014293,0.003753,0.095334,244.578400,12.459417,0.953343,-94.833389,0.095516,0.000000
90.110001,54.905952,-94.788910,0.014284,0.003753,0.095334,244.233871,12.441867,0.953343,-94.788910,0.095516,0.000000
90.360001,54.850464,-94.788910,0.014288,0.003753,0.095326,243.987045,12.429293,0.953256,-94.788910,0.095516,0.000000
90.610001,54.790886,-94.788910,0.014275,0.003753,0.095326,243.722031,12.415792,0.953256,-94.788910,0.095516,0.000000
90.860001,54.741737,-94.833389,0.014297,0.003753,0.095326,243.503403,12.404655,0.953256,-94.833389,0.095516,0.000000
91.110001,54.694443,-94.833389,0.014271,0.003753,0.095326,243.293030,12.393938,0.953256,-94.833389,0.095516,0.000000
91.360001,54.644547,-94.833389,0.014293,0.003753,0.095326,243.071075,12.382631,0.953256,-94.833389,0.095516,0.000000
91.610001,54.605072,-94.833389,0.014297,0.003753,0.095326,242.895493,12.373687,0.953256,-94.833389,0.095516,0.000000
91.860001,54.538788,-94.922348,0.014288,0.003753,0.095326,242.600647,12.358666,0.953256,-94.922348,0.095516,0.000000
92.110001,54.496712,-94.877869,0.014271,0.003753,0.095326,242.413483,12.349132,0.953256,-94.877869,0.095516,0.000000
92.360001,54.437508,-94.877869,0.014275,0.003753,0.095326,242.150131,12.335716,0.953256,-94.877869,0.095516,0.000000
92.610001,54.405113,-94.877869,0.014280,0.003753,0.095326,242.006027,12.328375,0.953256,-94.877869,0.095516,0.000000
92.860001,54.347023,-94.877869,0.014280,0.003753,0.095326,241.747635,12.315211,0.953256,-94.877869,0.095516,0.000000
93.110001,54.319839,-94.877869,0.014288,0.003753,0.095326,241.626709,12.309052,0.953256,-94.877869,0.095516,0.000000
93.360008,54.265472,-94.922348,0.014293,0.003753,0.095326,241.384872,12.296731,0.953256,-94.922348,0.095516,0.000000
93.610008,54.222275,-94.922348,0.014293,0.003753,0.095326,241.192719,12.286943,0.953256,-94.922348,0.095516,0.000000
93.860008,54.167534,-94.966827,0.014284,0.003753,0.095326,240.949219,12.274538,0.953256,-94.966827,0.095516,0.000000
94.110008,54.138489,-94.922348,0.014297,0.003753,0.095326,240.820023,12.267957,0.953256,-94.922348,0.095516,0.000000
94.360008,54.097900,-94.966827,0.014297,0.003753,0.095326,240.639481,12.258759,0.953256,-94.966827,0.095516,0.000000
94.610008,54.043167,-94.966827,0.014293,0.003753,0.095326,240.396011,12.246357,0.953256,-94.966827,0.095516,0.000000
94.860008,54.020821,-94.966827,0.014288,0.003753,0.095326,240.296616,12.241293,0.953256,-94.966827,0.095516,0.000000
95.110008,53.964218,-95.011314,0.014280,0.003753,0.095326,240.044830,12.228466,0.953256,-95.011314,0.095516,0.000000
95.360008,53.937782,-95.011314,0.014288,0.003753,0.095326,239.927231,12.222476,0.953256,-95.011314,0.095516,0.000000
95.610008,53.872246,-95.011314,0.014297,0.003753,0.095326,239.635712,12.207625,0.953256,-95.011314,0.095516,0.000000
95.860008,53.852135,-95.011314,0.014297,0.003753,0.095326,239.546265,12.203069,0.953256,-95.011314,0.095516,0.000000
96.110008,53.798141,-95.011314,0.014284,0.003753,0.095326,239.306091,12.190833,0.953256,-95.011314,0.095516,0.000000
96.360008,53.774307,-95.055794,0.014288,0.003753,0.095326,239.200058,12.185431,0.953256,-95.055794,0.095516,0.000000
96.610008,53.734093,-94.966827,0.014306,0.003753,0.095326,239.021179,12.176319,0.953256,-94.966827,0.095516,0.000000
96.860008,53.697227,-95.011314,0.014271,0.003753,0.095326,238.857193,12.167966,0.953256,-95.011314,0.095516,0.000000
97.110008,53.656265,-94.966827,0.014293,0.003753,0.095326,238.674988,12.158684,0.953256,-94.966827,0.095516,0.000000
97.360008,53.614937,-95.011314,0.014310,0.003753,0.095326,238.491150,12.149318,0.953256,-95.011314,0.095516,0.000000
97.610008,53.583282,-95.055794,0.014280,0.003753,0.095326,238.350342,12.142145,0.953256,-95.055794,0.095516,0.000000
97.860008,53.532639,-94.966827,0.014301,0.003753,0.095326,238.125076,12.130670,0.953256,-94.966827,0.095516,0.000000
98.110008,53.525566,-95.055794,0.014288,0.003753,0.095326,238.093613,12.129066,0.953256,-95.055794,0.095516,0.000000
98.360008,53.461891,-95.100273,0.014288,0.003753,0.095326,237.810364,12.114637,0.953256,-95.100273,0.095516,0.000000
98.610008,53.445137,-95.011314,0.014314,0.003753,0.095326,237.735840,12.110841,0.953256,-95.011314,0.095516,0.000000
98.860008,53.392998,-95.055794,0.014288,0.003753,0.095326,237.503922,12.099027,0.953256,-95.055794,0.095516,0.000000
99.110008,53.371407,-95.144753,0.014288,0.003753,0.095326,237.407867,12.094134,0.953256,-95.144753,0.095516,0.000000
99.360008,53.320015,-95.100273,0.014301,0.003753,0.095326,237.179276,12.082488,0.953256,-95.100273,0.095516,0.000000
99.610008,53.301025,-95.100273,0.014306,0.003753,0.095326,237.094803,12.078185,0.953256,-95.100273,0.095516,0.000000
99.860008,53.259689,-95.144753,0.014301,0.003753,0.095326,236.910934,12.068818,0.953256,-95.144753,0.095516,0.000000
100.110008,53.235115,-95.100273,0.014284,0.003753,0.095326,236.801620,12.063250,0.953256,-95.100273,0.095516,0.000000
100.360008,53.195641,-95.055794,0.014297,0.003753,0.095326,236.626022,12.054304,0.953256,-95.055794,0.095516,0.000000
100.610008,53.152077,-95.144753,0.014306,0.003753,0.095326,236.432251,12.044433,0.953256,-95.144753,0.095516,0.000000
100.860008,53.135323,-95.189232,0.014314,0.003753,0.095326,236.357712,12.040637,0.953256,-95.189232,0.095516,0.000000
101.110008,53.089142,-95.189232,0.014293,0.003753,0.095326,236.152298,12.030171,0.953256,-95.189232,0.095516,0.000000
101.360008,53.075371,-95.233719,0.014306,0.003753,0.095326,236.091034,12.027051,0.953256,-95.233719,0.095516,0.000000
101.610008,53.033661,-95.144753,0.014301,0.003753,0.095326,235.905502,12.017599,0.953256,-95.144753,0.095516,0.000000
101.860008,53.011322,-95.189232,0.014306,0.003753,0.095326,235.806137,12.012537,0.953256,-95.189232,0.095516,0.000000
102.110008,52.972595,-95.189232,0.014297,0.003753,0.095326,235.633865,12.003762,0.953256,-95.189232,0.095516,0.000000
102.360008,52.940193,-95.189232,0.014284,0.003753,0.095326,235.489746,11.996419,0.953256,-95.189232,0.095516,0.000000
102.610008,52.921951,-95.278198,0.014297,0.003753,0.095326,235.408600,11.992286,0.953256,-95.278198,0.095516,0.000000
102.860008,52.894020,-95.233719,0.014288,0.003753,0.095317,235.284348,11.985956,0.953169,-95.233719,0.095516,0.000000
103.110008,52.873169,-95.233719,0.014293,0.003753,0.095317,235.191605,11.981231,0.953169,-95.233719,0.095516,0.000000
103.360008,52.822899,-95.233719,0.014293,0.003753,0.095317,234.967987,11.969839,0.953169,-95.233719,0.095516,0.000000
103.610008,52.811729,-95.233719,0.014306,0.003753,0.095317,234.918304,11.967308,0.953169,-95.233719,0.095516,0.000000
103.860008,52.761833,-95.278198,0.014306,0.003753,0.095317,234.696350,11.956002,0.953169,-95.278198,0.095516,0.000000
104.110008,52.756615,-95.233719,0.014301,0.003753,0.095317,234.673141,11.954820,0.953169,-95.233719,0.095516,0.000000
104.360008,52.724594,-95.233719,0.014306,0.003753,0.095317,234.530701,11.947564,0.953169,-95.233719,0.095516,0.000000
104.610008,52.686981,-95.278198,0.014314,0.003753,0.095317,234.363403,11.939040,0.953169,-95.278198,0.095516,0.000000
104.860008,52.659431,-95.278198,0.014297,0.003753,0.095317,234.240845,11.932797,0.953169,-95.278198,0.095516,0.000000
105.100006,52.637833,-95.278198,0.014293,0.003753,0.095317,234.144775,11.927903,0.953169,-95.278198,0.095516,0.000000