File: Data/Automembrane/AutoNoheat15-1-2_12132023_190025.csv
Time (sec),S:Load (lbs),S:HL1 (DIM),S:LVDT (in),S:Position (in),Ch:Position (mm),Ch:Load (N),Ch:Stress (MPa),Ch:Strain (mm/mm),Ch:HL1 (DIM),Set Point (),Cycles ()
0.010000,0.007072,-1303.914551,0.000030,-0.000000,-0.000000,0.031460,0.001603,-0.000000,-1303.914551,0.000208,0.000000
0.260000,0.011543,-1303.825684,0.000043,-0.000000,-0.000000,0.051347,0.002616,-0.000000,-1303.825684,0.000208,0.000000
0.510000,0.023087,-1303.914551,0.000026,0.000063,0.001596,0.102694,0.005231,0.015957,-1303.914551,0.002411,0.000000
0.760000,0.011169,-1303.870117,0.000065,0.000215,0.005455,0.049684,0.002531,0.054548,-1303.870117,0.006574,0.000000
1.010000,-0.018250,-1303.914551,0.000216,0.000379,0.009617,-0.081178,-0.004135,0.096174,-1303.914551,0.010736,0.000000
1.260000,0.001488,-1303.825684,0.000414,0.000547,0.013902,0.006618,0.000337,0.139015,-1303.825684,0.014899,0.000000
1.510000,0.062561,-1303.914551,0.000569,0.000703,0.017865,0.278285,0.014177,0.178647,-1303.914551,0.019061,0.000000
1.760000,0.034256,-1303.825684,0.000729,0.000874,0.022210,0.152378,0.007763,0.222098,-1303.825684,0.023224,0.000000
2.010000,0.002235,-1303.825684,0.000936,0.001036,0.026311,0.009944,0.000507,0.263115,-1303.825684,0.027404,0.000000
2.260000,0.028297,-1303.825684,0.001065,0.001201,0.030500,0.125873,0.006412,0.305002,-1303.825684,0.031567,0.000000
2.510000,0.035378,-1303.781128,0.001224,0.001364,0.034654,0.157367,0.008017,0.346541,-1303.781128,0.035730,0.000000
2.760000,0.009682,-1303.825684,0.001475,0.001526,0.038765,0.043066,0.002194,0.387649,-1303.825684,0.039892,0.000000
3.010000,0.037613,-1303.825684,0.001608,0.001696,0.043075,0.167311,0.008523,0.430751,-1303.825684,0.044055,0.000000
3.260000,0.084526,-1303.870117,0.001802,0.001853,0.047056,0.375991,0.019154,0.470557,-1303.870117,0.048218,0.000000
3.510000,0.221191,-1303.914551,0.001979,0.002023,0.051374,0.983909,0.050123,0.513743,-1303.914551,0.052380,0.000000
3.760000,0.596169,-1303.914551,0.002087,0.002182,0.055416,2.651890,0.135094,0.554158,-1303.914551,0.056543,0.000000
4.010000,0.602867,-1303.870117,0.002130,-0.000010,-0.000243,2.681687,0.136612,-0.002430,-1303.870117,-0.000052,0.000000
4.260000,0.596542,-1303.870117,0.002169,-0.000010,-0.000243,2.653553,0.135178,-0.002430,-1303.870117,-0.000052,0.000000
4.510000,0.539192,-1303.870117,0.002139,-0.000010,-0.000243,2.398447,0.122183,-0.002430,-1303.870117,0.000277,0.000000
4.760000,0.568985,-1303.825684,0.002169,-0.000004,-0.000113,2.530972,0.128934,-0.001128,-1303.825684,0.000694,0.000000
5.010000,0.614784,-1303.825684,0.002139,0.000002,0.000061,2.734697,0.139312,0.000606,-1303.825684,0.001110,0.000000
5.260000,0.744370,-1303.914551,0.002151,0.000021,0.000537,3.311121,0.168677,0.005375,-1303.914551,0.001526,0.000000
5.510000,0.846031,-1303.914551,0.002208,0.000047,0.001197,3.763335,0.191713,0.011968,-1303.914551,0.001942,0.000000
5.760000,0.900398,-1303.870117,0.002195,0.000063,0.001596,4.005171,0.204033,0.015957,-1303.870117,0.002359,0.000000
6.010000,0.931305,-1303.914551,0.002229,0.000079,0.002012,4.142651,0.211037,0.020121,-1303.914551,0.002775,0.000000
6.260000,0.965561,-1303.959106,0.002281,0.000094,0.002385,4.295030,0.218799,0.023849,-1303.959106,0.003191,0.000000
6.510000,1.044876,-1303.825684,0.002272,0.000108,0.002740,4.647841,0.236772,0.027403,-1303.825684,0.003608,0.000000
6.760000,1.147652,-1303.825684,0.002307,0.000123,0.003130,5.105010,0.260062,0.031305,-1303.825684,0.004024,0.000000
7.010000,1.220634,-1303.914551,0.002315,0.000138,0.003504,5.429653,0.276600,0.035037,-1303.914551,0.004440,0.000000
7.260000,1.321548,-1303.914551,0.002320,0.000151,0.003842,5.878541,0.299467,0.038417,-1303.914551,0.004856,0.000000
7.510000,1.461937,-1303.825684,0.002358,0.000178,0.004527,6.503020,0.331280,0.045267,-1303.825684,0.005273,0.000000
7.760000,1.568436,-1303.825684,0.002341,0.000195,0.004960,6.976750,0.355413,0.049605,-1303.825684,0.005689,0.000000
8.010000,1.591888,-1303.870117,0.002402,0.000207,0.005255,7.081073,0.360727,0.052553,-1303.870117,0.006105,0.000000
8.260000,1.738609,-1303.870117,0.002389,0.000224,0.005689,7.733720,0.393974,0.056891,-1303.870117,0.006521,0.000000
8.510000,1.932610,-1303.870117,0.002419,0.000244,0.006192,8.596677,0.437936,0.061921,-1303.870117,0.006938,0.000000
8.760000,2.019379,-1303.870117,0.002427,0.000255,0.006470,8.982645,0.457598,0.064695,-1303.870117,0.007354,0.000000
9.010000,2.087151,-1303.914551,0.002449,0.000265,0.006730,9.284109,0.472955,0.067295,-1303.914551,0.007770,0.000000
9.260000,2.343338,-1303.870117,0.002436,0.000287,0.007302,10.423688,0.531008,0.073018,-1303.870117,0.008187,0.000000
9.510000,2.571602,-1303.914551,0.002492,0.000307,0.007788,11.439056,0.582733,0.077878,-1303.914551,0.008611,0.000000
9.760000,2.670280,-1303.914551,0.002514,0.000320,0.008126,11.878000,0.605094,0.081258,-1303.914551,0.009028,0.000000
10.010000,2.861679,-1303.781128,0.002522,0.000338,0.008586,12.729384,0.648466,0.085857,-1303.781128,0.009444,0.000000
10.260000,2.991638,-1303.914551,0.002548,0.000352,0.008932,13.307471,0.677915,0.089324,-1303.914551,0.009860,0.000000
10.510000,3.257515,-1303.825684,0.002518,0.000372,0.009453,14.490150,0.738163,0.094528,-1303.825684,0.010277,0.000000
10.760000,3.480568,-1303.914551,0.002522,0.000386,0.009817,15.482340,0.788708,0.098169,-1303.914551,0.010693,0.000000
11.010000,3.407211,-1303.870117,0.002552,0.000391,0.009938,15.156033,0.772085,0.099384,-1303.870117,0.011109,0.000000
11.260000,3.705475,-1303.870117,0.002561,0.000415,0.010537,16.482775,0.839673,0.105368,-1303.870117,0.011525,0.000000
11.510000,4.059601,-1303.914551,0.002639,0.000437,0.011092,18.058006,0.919919,0.110916,-1303.914551,0.011942,0.000000
11.760000,4.235733,-1303.870117,0.002643,0.000452,0.011473,18.841482,0.959831,0.114732,-1303.870117,0.012358,0.000000
12.010000,4.439049,-1303.959106,0.002617,0.000470,0.011950,19.745874,1.005903,0.119504,-1303.959106,0.012774,0.000000
12.260000,4.550392,-1303.870117,0.002639,0.000481,0.012228,20.241156,1.031134,0.122279,-1303.870117,0.013190,0.000000
12.510000,4.873238,-1303.870117,0.002682,0.000501,0.012731,21.677244,1.104291,0.127309,-1303.870117,0.013607,0.000000
12.760000,4.973778,-1303.914551,0.002716,0.000518,0.013164,22.124468,1.127074,0.131642,-1303.914551,0.014023,0.000000
13.010000,5.159592,-1303.870117,0.002669,0.000528,0.013416,22.951010,1.169180,0.134159,-1303.870117,0.014439,0.000000
13.260000,5.513344,-1303.914551,0.002690,0.000554,0.014084,24.524578,1.249342,0.140836,-1303.914551,0.014855,0.000000
13.510000,5.688362,-1303.914551,0.002712,0.000571,0.014491,25.303099,1.289001,0.144912,-1303.914551,0.015272,0.000000
13.760000,5.819435,-1303.870117,0.002764,0.000586,0.014873,25.886141,1.318703,0.148727,-1303.870117,0.015688,0.000000
14.010000,5.955727,-1303.914551,0.002777,0.000598,0.015185,26.492395,1.349587,0.151850,-1303.914551,0.016104,0.000000
14.260000,6.189575,-1303.914551,0.002772,0.000613,0.015575,27.532606,1.402578,0.155752,-1303.914551,0.016521,0.000000
14.510000,6.470718,-1303.914551,0.002824,0.000632,0.016044,28.783194,1.466286,0.160438,-1303.914551,0.016937,0.000000
14.760000,6.464760,-1303.914551,0.002785,0.000641,0.016278,28.756687,1.464936,0.162777,-1303.914551,0.017362,0.000000
15.010001,6.694511,-1303.870117,0.002833,0.000655,0.016642,29.778673,1.516998,0.166422,-1303.870117,0.017778,0.000000
15.260001,7.128326,-1303.914551,0.002828,0.000683,0.017344,31.708380,1.615302,0.173443,-1303.914551,0.018194,0.000000
15.510001,7.292168,-1303.870117,0.002880,0.000701,0.017795,32.437183,1.652429,0.177954,-1303.870117,0.018611,0.000000
15.760001,7.361801,-1303.870117,0.002863,0.000714,0.018125,32.746925,1.668208,0.181251,-1303.870117,0.019027,0.000000
16.010000,7.510010,-1303.825684,0.002867,0.000726,0.018446,33.406193,1.701792,0.184457,-1303.825684,0.019443,0.000000
16.260000,8.018669,-1303.870117,0.002880,0.000747,0.018966,35.668823,1.817056,0.189661,-1303.870117,0.019859,0.000000
16.510000,8.095749,-1303.914551,0.002915,0.000759,0.019287,36.011688,1.834523,0.192871,-1303.914551,0.020276,0.000000
16.760000,8.375404,-1303.914551,0.002945,0.000778,0.019764,37.255661,1.897894,0.197640,-1303.914551,0.020692,0.000000
17.010000,8.694153,-1303.825684,0.002953,0.000797,0.020232,38.673523,1.970123,0.202322,-1303.825684,0.021108,0.000000
17.260000,8.924278,-1303.870117,0.002910,0.000811,0.020597,39.697174,2.022270,0.205966,-1303.870117,0.021524,0.000000
17.510000,9.059822,-1303.870117,0.003001,0.000826,0.020978,40.300102,2.052985,0.209782,-1303.870117,0.021941,0.000000
17.760000,9.412834,-1303.825684,0.003005,0.000844,0.021438,41.870377,2.132979,0.214376,-1303.825684,0.022357,0.000000
18.010000,9.721153,-1303.870117,0.002962,0.000862,0.021906,43.241848,2.202845,0.219062,-1303.870117,0.022773,0.000000
18.260000,10.039536,-1303.870117,0.003035,0.000880,0.022340,44.658085,2.274991,0.223396,-1303.870117,0.023190,0.000000
18.510000,10.177315,-1303.914551,0.003061,0.000892,0.022669,45.270958,2.306212,0.226692,-1303.914551,0.023606,0.000000
18.760000,10.420471,-1303.870117,0.003078,0.000907,0.023042,46.352570,2.361313,0.230421,-1303.870117,0.024022,0.000000
19.010000,10.898224,-1303.914551,0.003044,0.000928,0.023580,48.477722,2.469573,0.235799,-1303.914551,0.024438,0.000000
19.260000,11.256821,-1303.870117,0.003078,0.000948,0.024083,50.072838,2.550832,0.240829,-1303.870117,0.024855,0.000000
19.510000,11.238197,-1303.959106,0.003074,0.000957,0.024317,49.989998,2.546612,0.243168,-1303.959106,0.025271,0.000000
19.760000,11.415451,-1303.959106,0.003104,0.000973,0.024716,50.778461,2.586778,0.247157,-1303.959106,0.025696,0.000000
20.010000,11.781494,-1303.870117,0.003139,0.000988,0.025089,52.406704,2.669725,0.250889,-1303.870117,0.026112,0.000000
20.260000,12.440964,-1303.870117,0.003130,0.001013,0.025722,55.340172,2.819163,0.257218,-1303.870117,0.026528,0.000000
20.510000,12.268181,-1303.870117,0.003147,0.001020,0.025904,54.571594,2.780010,0.259038,-1303.870117,0.026945,0.000000
20.760000,12.672951,-1303.870117,0.003152,0.001040,0.026407,56.372101,2.871732,0.264068,-1303.870117,0.027361,0.000000
21.010000,12.857651,-1303.914551,0.003143,0.001051,0.026693,57.193687,2.913585,0.266930,-1303.914551,0.027777,0.000000
21.260000,13.564781,-1303.870117,0.003216,0.001077,0.027361,60.339161,3.073823,0.273610,-1303.870117,0.028193,0.000000
21.510000,13.573723,-1303.914551,0.003186,0.001090,0.027682,60.378933,3.075850,0.276820,-1303.914551,0.028610,0.000000
21.760000,13.987053,-1303.914551,0.003242,0.001111,0.028211,62.217518,3.169512,0.282107,-1303.914551,0.029026,0.000000
22.010000,14.284950,-1303.914551,0.003272,0.001126,0.028601,63.542633,3.237016,0.286009,-1303.914551,0.029442,0.000000
22.260000,14.471886,-1303.914551,0.003212,0.001140,0.028965,64.374161,3.279376,0.289654,-1303.914551,0.029859,0.000000
22.510000,14.455498,-1303.914551,0.003281,0.001150,0.029199,64.301262,3.275663,0.291993,-1303.914551,0.030275,0.000000
22.760000,15.009964,-1303.959106,0.003320,0.001170,0.029711,66.767654,3.401306,0.297110,-1303.959106,0.030691,0.000000
23.010000,15.675392,-1303.914551,0.003303,0.001193,0.030301,69.727623,3.552094,0.303007,-1303.914551,0.031107,0.000000
23.260000,15.786362,-1303.914551,0.003337,0.001207,0.030665,70.221245,3.577241,0.306652,-1303.914551,0.031524,0.000000
23.510000,15.931580,-1303.870117,0.003320,0.001224,0.031090,70.867203,3.610147,0.310899,-1303.870117,0.031940,0.000000
23.760000,16.242516,-1303.914551,0.003350,0.001241,0.031524,72.250320,3.680607,0.315236,-1303.914551,0.032356,0.000000
24.010000,16.330391,-1303.870117,0.003363,0.001253,0.031827,72.641205,3.700519,0.318272,-1303.870117,0.032772,0.000000
24.260000,16.770538,-1303.914551,0.003402,0.001271,0.032295,74.599083,3.800258,0.322954,-1303.914551,0.033189,0.000000
24.510000,16.827515,-1303.914551,0.003402,0.001282,0.032573,74.852524,3.813169,0.325728,-1303.914551,0.033605,0.000000
24.760000,16.910553,-1303.959106,0.003410,0.001293,0.032851,75.221893,3.831986,0.328506,-1303.959106,0.034030,0.000000
25.010002,17.840363,-1303.914551,0.003402,0.001322,0.033579,79.357895,4.042684,0.335788,-1303.914551,0.034446,0.000000
25.260002,17.861961,-1303.959106,0.003475,0.001335,0.033908,79.453972,4.047578,0.339085,-1303.959106,0.034862,0.000000
25.510002,18.107353,-1303.914551,0.003471,0.001354,0.034385,80.545532,4.103185,0.343854,-1303.914551,0.035279,0.000000
25.760002,18.241035,-1303.959106,0.003441,0.001368,0.034741,81.140175,4.133478,0.347412,-1303.959106,0.035695,0.000000
26.010002,18.800339,-1303.914551,0.003454,0.001390,0.035296,83.628082,4.260218,0.352960,-1303.914551,0.036111,0.000000
26.260002,18.837578,-1303.870117,0.003497,0.001402,0.035617,83.793732,4.268656,0.356170,-1303.870117,0.036528,0.000000
26.510002,18.923225,-1303.914551,0.003501,0.001416,0.035972,84.174713,4.288064,0.359724,-1303.914551,0.036944,0.000000
26.760002,18.985413,-1303.914551,0.003518,0.001429,0.036293,84.451332,4.302156,0.362934,-1303.914551,0.037360,0.000000
27.010002,19.964752,-1303.825684,0.003523,0.001455,0.036961,88.807655,4.524077,0.369610,-1303.825684,0.037776,0.000000
27.260002,19.990440,-1303.914551,0.003609,0.001471,0.037360,88.921921,4.529899,0.373599,-1303.914551,0.038193,0.000000
27.510002,20.252594,-1304.003540,0.003587,0.001489,0.037811,90.088036,4.589303,0.378111,-1304.003540,0.038609,0.000000
27.760002,20.429474,-1303.870117,0.003609,0.001504,0.038201,90.874840,4.629385,0.382013,-1303.870117,0.039025,0.000000
28.010002,20.663322,-1303.914551,0.003604,0.001519,0.038583,91.915047,4.682376,0.385828,-1303.914551,0.039441,0.000000
28.260002,20.827164,-1303.914551,0.003652,0.001532,0.038921,92.643852,4.719502,0.389212,-1303.914551,0.039858,0.000000
28.510002,20.949303,-1303.870117,0.003656,0.001546,0.039259,93.187149,4.747180,0.392592,-1303.870117,0.040274,0.000000
28.760002,21.578613,-1303.959106,0.003673,0.001566,0.039788,95.986465,4.889784,0.397883,-1303.959106,0.040690,0.000000
29.010002,22.099190,-1303.870117,0.003712,0.001590,0.040378,98.302109,5.007748,0.403780,-1303.870117,0.041107,0.000000
29.260002,21.968483,-1303.914551,0.003717,0.001604,0.040733,97.720695,4.978129,0.407334,-1303.914551,0.041523,0.000000
29.510002,22.028435,-1303.914551,0.003691,0.001617,0.041080,97.987373,4.991715,0.410805,-1303.914551,0.041939,0.000000
29.760002,22.330803,-1303.914551,0.003747,0.001635,0.041540,99.332375,5.060232,0.415400,-1303.914551,0.042355,0.000000
30.010002,22.604126,-1303.959106,0.003751,0.001652,0.041956,100.548172,5.122169,0.419563,-1303.959106,0.042780,0.000000
30.260002,22.649551,-1303.914551,0.003760,0.001663,0.042242,100.750237,5.132462,0.422425,-1303.914551,0.043197,0.000000
30.510002,23.174973,-1303.870117,0.003751,0.001683,0.042737,103.087425,5.251524,0.427368,-1303.870117,0.043613,0.000000
30.760002,23.684753,-1303.914551,0.003794,0.001704,0.043275,105.355042,5.367042,0.432746,-1303.914551,0.044029,0.000000
31.010002,23.632988,-1303.914551,0.003777,0.001717,0.043613,105.124779,5.355311,0.436126,-1303.914551,0.044445,0.000000
31.260002,23.891792,-1303.914551,0.003803,0.001734,0.044038,106.276001,5.413958,0.440376,-1303.914551,0.044862,0.000000
31.510002,23.910408,-1303.870117,0.003837,0.001747,0.044367,106.358810,5.418176,0.443673,-1303.870117,0.045278,0.000000
31.760002,24.251503,-1303.914551,0.003846,0.001763,0.044792,107.876076,5.495469,0.447920,-1303.914551,0.045694,0.000000
32.010002,24.505089,-1303.959106,0.003863,0.001781,0.045234,109.004082,5.552933,0.452344,-1303.959106,0.046110,0.000000
32.260002,24.339752,-1303.914551,0.003880,0.001790,0.045460,108.268623,5.515467,0.454600,-1303.914551,0.046527,0.000000
32.510002,24.830910,-1303.959106,0.003863,0.001810,0.045972,110.453400,5.626765,0.459717,-1303.959106,0.046943,0.000000
32.760002,25.442719,-1303.959106,0.003889,0.001832,0.046527,113.174866,5.765402,0.465266,-1303.959106,0.047359,0.000000
33.010002,25.406227,-1303.959106,0.003928,0.001848,0.046943,113.012543,5.757133,0.469429,-1303.959106,0.047775,0.000000
33.260002,25.777115,-1303.914551,0.003971,0.001865,0.047368,114.662331,5.841177,0.473680,-1303.914551,0.048192,0.000000
33.510002,25.736893,-1303.870117,0.003988,0.001878,0.047706,114.483414,5.832064,0.477060,-1303.870117,0.048608,0.000000
33.760002,25.988617,-1303.870117,0.003958,0.001897,0.048183,115.603142,5.889105,0.481828,-1303.870117,0.049024,0.000000
34.010002,25.926064,-1303.870117,0.004001,0.001911,0.048530,115.324890,5.874930,0.485299,-1303.870117,0.049441,0.000000
34.260002,26.069420,-1303.959106,0.003984,0.001924,0.048868,115.962570,5.907415,0.488683,-1303.959106,0.049857,0.000000
34.510002,26.899071,-1304.003540,0.004036,0.001945,0.049397,119.653046,6.095417,0.493970,-1304.003540,0.050273,0.000000
34.760002,27.274422,-1303.870117,0.004053,0.001965,0.049900,121.322685,6.180472,0.499001,-1303.870117,0.050689,0.000000
35.010002,26.945244,-1303.914551,0.004031,0.001976,0.050186,119.858429,6.105880,0.501862,-1303.914551,0.051114,0.000000
35.260002,27.234573,-1303.959106,0.004036,0.001994,0.050655,121.145432,6.171443,0.506548,-1303.959106,0.051531,0.000000
35.510002,27.052490,-1303.914551,0.004096,0.002004,0.050906,120.335487,6.130182,0.509061,-1303.914551,0.051947,0.000000
35.760002,27.703018,-1303.914551,0.004083,0.002026,0.051453,123.229179,6.277594,0.514526,-1303.914551,0.052363,0.000000
36.010002,27.775635,-1303.914551,0.004096,0.002038,0.051764,123.552193,6.294049,0.517645,-1303.914551,0.052779,0.000000
36.260002,27.967033,-1303.914551,0.004156,0.002053,0.052155,124.403580,6.337420,0.521547,-1303.914551,0.053196,0.000000
36.510002,28.827217,-1303.870117,0.004156,0.002077,0.052753,128.229858,6.532341,0.527531,-1303.870117,0.053612,0.000000
36.760002,29.313530,-1303.914551,0.004143,0.002097,0.053265,130.393097,6.642541,0.532648,-1303.914551,0.054028,0.000000
37.010002,28.812691,-1303.959106,0.004217,0.002106,0.053499,128.165253,6.529049,0.534991,-1303.959106,0.054444,0.000000
37.260002,28.850304,-1303.870117,0.004225,0.002121,0.053872,128.332565,6.537572,0.538719,-1303.870117,0.054861,0.000000
37.510002,28.978027,-1303.825684,0.004195,0.002137,0.054280,128.900696,6.566514,0.542796,-1303.825684,0.055277,0.000000
37.760002,29.557434,-1303.914551,0.004273,0.002155,0.054731,131.478027,6.697810,0.547307,-1303.914551,0.055693,0.000000
38.010002,29.584618,-1304.003540,0.004299,0.002170,0.055112,131.598953,6.703970,0.551122,-1304.003540,0.056110,0.000000
38.260002,29.948051,-1303.914551,0.004251,0.002189,0.055589,133.215591,6.786325,0.555891,-1303.914551,0.056526,0.000000
38.510002,30.136101,-1303.914551,0.004312,0.002205,0.056014,134.052078,6.828938,0.560142,-1303.914551,0.056942,0.000000
38.760002,30.354317,-1303.914551,0.004303,0.002220,0.056387,135.022751,6.878386,0.563870,-1303.914551,0.057358,0.000000
39.010002,30.718864,-1303.959106,0.004333,0.002238,0.056846,136.644333,6.960994,0.568465,-1303.959106,0.057775,0.000000
39.260002,30.654442,-1303.959106,0.004316,0.002254,0.057245,136.357773,6.946396,0.572454,-1303.959106,0.058191,0.000000
39.510002,31.489304,-1303.959106,0.004342,0.002276,0.057809,140.071411,7.135578,0.578094,-1303.959106,0.058607,0.000000
39.760002,31.376106,-1304.003540,0.004342,0.002289,0.058130,139.567886,7.109927,0.581299,-1304.003540,0.059023,0.000000
40.010002,31.138527,-1303.914551,0.004355,0.002301,0.058433,138.511078,7.056091,0.584335,-1303.914551,0.059448,0.000000
40.260002,31.676979,-1303.959106,0.004424,0.002323,0.059014,140.906235,7.178106,0.590145,-1303.959106,0.059865,0.000000
40.510002,32.167397,-1303.959106,0.004471,0.002342,0.059483,143.087723,7.289236,0.594830,-1303.959106,0.060281,0.000000
40.760002,32.113770,-1303.870117,0.004424,0.002354,0.059795,142.849182,7.277084,0.597953,-1303.870117,0.060697,0.000000
41.010002,32.059776,-1303.914551,0.004449,0.002367,0.060125,142.609009,7.264849,0.601246,-1303.914551,0.061113,0.000000
41.260002,32.248947,-1303.914551,0.004501,0.002384,0.060541,143.450485,7.307716,0.605409,-1303.914551,0.061530,0.000000
41.510002,33.123276,-1303.959106,0.004506,0.002405,0.061087,147.339691,7.505842,0.610874,-1303.959106,0.061946,0.000000
41.760002,33.036888,-1303.914551,0.004536,0.002418,0.061417,146.955414,7.486266,0.614167,-1303.914551,0.062362,0.000000
42.010002,33.009705,-1303.870117,0.004527,0.002433,0.061790,146.834503,7.480106,0.617899,-1303.870117,0.062779,0.000000
42.260002,33.157532,-1303.914551,0.004536,0.002446,0.062137,147.492065,7.513604,0.621366,-1303.914551,0.063194,0.000000
42.510002,34.101868,-1303.959106,0.004579,0.002471,0.062770,151.692688,7.727594,0.627698,-1303.959106,0.063611,0.000000
42.760002,33.819237,-1303.914551,0.004557,0.002482,0.063047,150.435486,7.663549,0.630473,-1303.914551,0.064027,0.000000
43.010002,34.237785,-1303.914551,0.004557,0.002502,0.063559,152.297272,7.758393,0.635590,-1303.914551,0.064444,0.000000
43.260002,34.364395,-1303.959106,0.004613,0.002518,0.063949,152.860458,7.787083,0.639492,-1303.959106,0.064860,0.000000
43.510002,34.711441,-1303.914551,0.004587,0.002537,0.064435,154.404205,7.865725,0.644348,-1303.914551,0.065276,0.000000
43.760002,34.315239,-1303.914551,0.004613,0.002546,0.064669,152.641800,7.775944,0.646691,-1303.914551,0.065692,0.000000
44.010002,34.505898,-1303.870117,0.004618,0.002562,0.065068,153.489899,7.819148,0.650680,-1303.870117,0.066108,0.000000
44.260002,35.064453,-1303.959106,0.004626,0.002584,0.065623,155.974472,7.945718,0.656229,-1303.959106,0.066525,0.000000
44.510002,35.709404,-1303.914551,0.004648,0.002603,0.066117,158.843369,8.091866,0.661172,-1303.914551,0.066941,0.000000
44.760002,35.326973,-1303.825684,0.004695,0.002616,0.066447,157.142227,8.005206,0.664469,-1303.825684,0.067358,0.000000
45.010002,35.811806,-1304.003540,0.004674,0.002634,0.066906,159.298874,8.115071,0.669063,-1304.003540,0.067773,0.000000
45.260002,35.821861,-1303.959106,0.004734,0.002647,0.067236,159.343597,8.117350,0.672360,-1303.959106,0.068199,0.000000
45.510002,36.214714,-1304.003540,0.004747,0.002666,0.067722,161.091095,8.206371,0.677216,-1304.003540,0.068615,0.000000
45.760002,36.355469,-1303.959106,0.004773,0.002681,0.068086,161.717209,8.238267,0.680857,-1303.959106,0.069031,0.000000
46.010002,36.183060,-1303.959106,0.004773,0.002692,0.068372,160.950287,8.199199,0.683719,-1303.959106,0.069448,0.000000
46.260002,37.053665,-1303.870117,0.004773,0.002716,0.068996,164.822937,8.396481,0.689964,-1303.870117,0.069863,0.000000
46.510002,37.428642,-1303.914551,0.004812,0.002732,0.069404,166.490921,8.481452,0.694040,-1303.914551,0.070280,0.000000
46.760002,37.252144,-1303.914551,0.004846,0.002747,0.069777,165.705811,8.441457,0.697768,-1303.914551,0.070696,0.000000
47.010002,37.537003,-1303.959106,0.004829,0.002763,0.070176,166.972931,8.506006,0.701757,-1303.959106,0.071112,0.000000
47.260002,37.890388,-1303.959106,0.004889,0.002782,0.070670,168.544861,8.586084,0.706700,-1303.959106,0.071529,0.000000
47.510002,38.072105,-1303.959106,0.004915,0.002799,0.071086,169.353180,8.627262,0.710864,-1303.959106,0.071945,0.000000
47.760002,38.087746,-1303.959106,0.004941,0.002811,0.071407,169.422760,8.630807,0.714073,-1303.959106,0.072361,0.000000
48.010002,37.967094,-1303.914551,0.004932,0.002825,0.071745,168.886078,8.603466,0.717453,-1303.914551,0.072777,0.000000
48.260002,38.711838,-1303.959106,0.004941,0.002846,0.072283,172.198853,8.772227,0.722832,-1303.959106,0.073194,0.000000
48.510002,38.992607,-1303.959106,0.004941,0.002863,0.072708,173.447784,8.835851,0.727082,-1303.959106,0.073610,0.000000
48.760002,39.264816,-1303.959106,0.004997,0.002881,0.073168,174.658630,8.897534,0.731677,-1303.959106,0.074026,0.000000
49.010002,39.122940,-1303.914551,0.004993,0.002895,0.073523,174.027527,8.865385,0.735235,-1303.914551,0.074442,0.000000
49.260002,39.517654,-1303.914551,0.004984,0.002912,0.073974,175.783310,8.954828,0.739743,-1303.914551,0.074859,0.000000
49.510002,39.391792,-1303.825684,0.005057,0.002927,0.074347,175.223450,8.926308,0.743471,-1303.825684,0.075275,0.000000
49.760002,39.314713,-1303.914551,0.005066,0.002939,0.074642,174.880569,8.908841,0.746419,-1303.914551,0.075691,0.000000
50.010002,40.181969,-1303.959106,0.005053,0.002962,0.075223,178.738327,9.105365,0.752233,-1303.959106,0.076108,0.000000
50.260002,40.950546,-1303.914551,0.005083,0.002983,0.075761,182.157120,9.279527,0.757607,-1303.914551,0.076532,0.000000
50.510002,40.859688,-1303.914551,0.005126,0.002998,0.076151,181.752975,9.258938,0.761510,-1303.914551,0.076949,0.000000
50.760002,40.730843,-1303.914551,0.005126,0.003011,0.076481,181.179840,9.229740,0.764806,-1303.914551,0.077365,0.000000
51.010002,40.686157,-1304.003540,0.005161,0.003024,0.076810,180.981064,9.219615,0.768103,-1304.003540,0.077781,0.000000
51.260002,41.351219,-1303.959106,0.005135,0.003045,0.077348,183.939407,9.370320,0.773477,-1303.959106,0.078198,0.000000
51.510002,41.266319,-1303.914551,0.005174,0.003059,0.077695,183.561752,9.351082,0.776948,-1303.914551,0.078614,0.000000
51.760002,40.781860,-1303.914551,0.005200,0.003071,0.077998,181.406769,9.241302,0.779984,-1303.914551,0.079030,0.000000
52.010002,41.910896,-1303.959106,0.005208,0.003093,0.078571,186.428970,9.497145,0.785706,-1303.959106,0.079446,0.000000
52.260002,42.019257,-1303.914551,0.005195,0.003110,0.079004,186.910995,9.521700,0.790044,-1303.914551,0.079863,0.000000
52.510002,42.142136,-1303.959106,0.005260,0.003128,0.079446,187.457581,9.549545,0.794465,-1303.959106,0.080279,0.000000
52.760002,42.219215,-1303.914551,0.005234,0.003141,0.079785,187.800446,9.567011,0.797848,-1303.914551,0.080695,0.000000
53.010002,42.414711,-1303.914551,0.005290,0.003161,0.080288,188.670059,9.611311,0.802878,-1303.914551,0.081111,0.000000
53.260002,42.560310,-1303.959106,0.005329,0.003174,0.080617,189.317719,9.644304,0.806171,-1303.959106,0.081528,0.000000
53.510002,42.386414,-1303.959106,0.005320,0.003186,0.080912,188.544189,9.604898,0.809120,-1303.959106,0.081944,0.000000
53.760002,41.888550,-1303.959106,0.005329,0.003194,0.081120,186.329575,9.492082,0.811201,-1303.959106,0.082360,0.000000
54.010002,43.494591,-1303.959106,0.005351,0.003223,0.081866,193.473602,9.856015,0.818661,-1303.959106,0.082777,0.000000
54.260002,43.752274,-1303.870117,0.005364,0.003241,0.082326,194.619827,9.914407,0.823256,-1303.870117,0.083193,0.000000
54.510002,44.021873,-1303.959106,0.005415,0.003259,0.082785,195.819077,9.975499,0.827855,-1303.959106,0.083609,0.000000
54.760002,44.264656,-1303.914551,0.005389,0.003275,0.083184,196.899017,10.030515,0.831840,-1303.914551,0.084025,0.000000
55.010002,44.137680,-1303.870117,0.005450,0.003289,0.083531,196.334213,10.001741,0.835311,-1303.870117,0.084442,0.000000
55.260002,44.407280,-1303.914551,0.005437,0.003307,0.083999,197.533447,10.062834,0.839993,-1303.914551,0.084867,0.000000
55.510002,44.227425,-1303.959106,0.005484,0.003317,0.084242,196.733414,10.022078,0.842423,-1303.959106,0.085283,0.000000
55.760002,45.182182,-1303.959106,0.005471,0.003342,0.084884,200.980377,10.238428,0.848838,-1303.959106,0.085699,0.000000
56.010002,45.548599,-1303.870117,0.005476,0.003359,0.085318,202.610291,10.321461,0.853176,-1303.870117,0.086115,0.000000
56.260002,45.380287,-1303.914551,0.005558,0.003371,0.085621,201.861603,10.283320,0.856211,-1303.914551,0.086532,0.000000
56.510002,45.665894,-1303.959106,0.005540,0.003389,0.086081,203.132034,10.348040,0.860806,-1303.959106,0.086948,0.000000
56.760002,45.347893,-1303.959106,0.005558,0.003400,0.086350,201.717499,10.275979,0.863497,-1303.959106,0.087364,0.000000
57.010002,45.789894,-1303.825684,0.005536,0.003418,0.086809,203.683624,10.376138,0.868092,-1303.825684,0.087780,0.000000
57.260002,46.184242,-1303.914551,0.005570,0.003435,0.087252,205.437775,10.465499,0.872517,-1303.914551,0.088197,0.000000
57.510002,45.848358,-1303.914551,0.005605,0.003446,0.087520,203.943680,10.389386,0.875204,-1303.914551,0.088613,0.000000
57.760002,47.068626,-1303.914551,0.005605,0.003471,0.088171,209.371704,10.665904,0.881706,-1303.914551,0.089029,0.000000
58.010002,47.848373,-1303.914551,0.005644,0.003492,0.088691,212.840195,10.842597,0.886911,-1303.914551,0.089446,0.000000
58.260002,47.521057,-1303.870117,0.005639,0.003502,0.088960,211.384216,10.768425,0.889598,-1303.870117,0.089862,0.000000
58.510002,47.542282,-1303.914551,0.005713,0.003517,0.089324,211.478638,10.773235,0.893243,-1303.914551,0.090278,0.000000
58.760002,47.373970,-1303.914551,0.005691,0.003530,0.089654,210.729950,10.735095,0.896536,-1303.914551,0.090694,0.000000
59.010002,48.245323,-1303.914551,0.005739,0.003549,0.090148,214.605911,10.932547,0.901479,-1303.914551,0.091111,0.000000
59.260002,48.434486,-1303.914551,0.005769,0.003565,0.090556,215.447357,10.975411,0.905555,-1303.914551,0.091527,0.000000
59.510002,48.710411,-1304.003540,0.005730,0.003581,0.090963,216.674728,11.037937,0.909631,-1304.003540,0.091943,0.000000
59.760002,49.171783,-1303.870117,0.005777,0.003599,0.091414,218.727020,11.142486,0.914143,-1303.870117,0.092359,0.000000
60.010002,49.547134,-1303.870117,0.005799,0.003616,0.091848,220.396667,11.227542,0.918477,-1303.870117,0.092776,0.000000
60.260002,49.729225,-1303.959106,0.005816,0.003633,0.092290,221.206635,11.268804,0.922901,-1303.959106,0.093192,0.000000
60.510002,49.834976,-1303.914551,0.005859,0.003646,0.092602,221.677048,11.292768,0.926024,-1303.914551,0.093617,0.000000
60.760002,50.566315,-1303.959106,0.005838,0.003668,0.093175,224.930206,11.458491,0.931747,-1303.959106,0.094033,0.000000
61.010002,50.767403,-1303.914551,0.005872,0.003684,0.093582,225.824692,11.504058,0.935823,-1303.914551,0.094449,0.000000
61.260002,50.688454,-1303.914551,0.005898,0.003696,0.093886,225.473495,11.486168,0.938858,-1303.914551,0.094866,0.000000
61.510002,50.882462,-1303.914551,0.005911,0.003713,0.094311,226.336487,11.530130,0.943109,-1303.914551,0.095282,0.000000
61.760002,51.925850,-1303.959106,0.005950,0.003734,0.094831,230.977722,11.766566,0.948309,-1303.959106,0.095698,0.000000
62.010002,52.120232,-1303.870117,0.005915,0.003749,0.095230,231.842377,11.810614,0.952299,-1303.870117,0.096114,0.000000
62.260002,51.696098,-1303.914551,0.005997,0.003760,0.095508,229.955734,11.714503,0.955077,-1303.914551,0.096531,0.000000
62.510002,52.004051,-1303.959106,0.005993,0.003777,0.095924,231.325577,11.784286,0.959236,-1303.959106,0.096947,0.000000
62.760002,52.777092,-1303.870117,0.006019,0.003798,0.096479,234.764236,11.959460,0.964789,-1303.870117,0.097363,0.000000
63.010002,53.432838,-1303.959106,0.006058,0.003815,0.096912,237.681137,12.108054,0.969122,-1303.959106,0.097780,0.000000
63.260002,52.960304,-1303.914551,0.005997,0.003823,0.097095,235.579193,12.000977,0.970947,-1303.914551,0.098196,0.000000
63.510002,53.625359,-1303.914551,0.006019,0.003843,0.097606,238.537506,12.151680,0.976060,-1303.914551,0.098612,0.000000
63.760002,53.867401,-1303.959106,0.006036,0.003863,0.098109,239.614166,12.206528,0.981090,-1303.959106,0.099028,0.000000
64.010002,54.746941,-1303.959106,0.006114,0.003878,0.098491,243.526550,12.405834,0.984909,-1303.959106,0.099445,0.000000
64.260002,54.791260,-1303.914551,0.006118,0.003893,0.098872,243.723694,12.415876,0.988724,-1303.914551,0.099861,0.000000
64.510002,55.701332,-1303.959106,0.006144,0.003912,0.099367,247.771896,12.622102,0.993667,-1303.959106,0.100277,0.000000
64.760002,56.217445,-1303.914551,0.006127,0.003929,0.099800,250.067688,12.739056,0.998001,-1303.914551,0.100693,0.000000
65.010002,56.235687,-1303.914551,0.006170,0.003941,0.100104,250.148834,12.743189,1.001037,-1303.914551,0.101110,0.000000
65.260002,56.379051,-1303.914551,0.006144,0.003955,0.100459,250.786545,12.775676,1.004594,-1303.914551,0.101526,0.000000
65.510002,57.035919,-1303.914551,0.006204,0.003972,0.100884,253.708435,12.924523,1.008845,-1303.914551,0.101951,0.000000
65.760002,58.140373,-1303.870117,0.006196,0.003995,0.101474,258.621307,13.174796,1.014742,-1303.870117,0.102367,0.000000
66.010002,58.119896,-1303.914551,0.006239,0.004004,0.101708,258.530212,13.170156,1.017081,-1303.914551,0.102783,0.000000
66.260002,59.075027,-1303.914551,0.006256,0.004027,0.102280,262.778839,13.386592,1.022804,-1303.914551,0.103200,0.000000
66.510002,59.433250,-1303.870117,0.006230,0.004041,0.102645,264.372314,13.467767,1.026448,-1303.870117,0.103616,0.000000
66.760002,59.722214,-1303.914551,0.006252,0.004056,0.103035,265.657684,13.533247,1.030351,-1303.914551,0.104032,0.000000
67.010002,60.422646,-1303.870117,0.006291,0.004074,0.103477,268.773346,13.691967,1.034771,-1303.870117,0.104449,0.000000
67.260002,60.728363,-1303.914551,0.006325,0.004088,0.103824,270.133240,13.761244,1.038242,-1303.914551,0.104865,0.000000
67.510002,61.228462,-1303.914551,0.006347,0.004102,0.104197,272.357788,13.874568,1.041970,-1303.914551,0.105281,0.000000
67.760002,62.653900,-1303.914551,0.006334,0.004128,0.104848,278.698456,14.197577,1.048476,-1303.914551,0.105697,0.000000
68.010002,62.909721,-1303.914551,0.006325,0.004142,0.105194,279.836426,14.255547,1.051943,-1303.914551,0.106114,0.000000
68.260002,63.187508,-1303.914551,0.006364,0.004155,0.105541,281.072083,14.318494,1.055414,-1303.914551,0.106530,0.000000
68.510002,63.575890,-1303.914551,0.006368,0.004168,0.105879,282.799683,14.406503,1.058794,-1303.914551,0.106946,0.000000
68.760002,64.968575,-1303.914551,0.006446,0.004192,0.106469,288.994659,14.722089,1.064691,-1303.914551,0.107362,0.000000
69.010002,65.250832,-1303.959106,0.006446,0.004206,0.106842,290.250183,14.786049,1.068423,-1303.959106,0.107779,0.000000
69.260002,65.528236,-1303.870117,0.006476,0.004218,0.107137,291.484161,14.848910,1.071371,-1303.870117,0.108195,0.000000
69.510002,66.974907,-1303.914551,0.006441,0.004243,0.107761,297.919250,15.176731,1.077613,-1303.914551,0.108611,0.000000
69.760002,67.031883,-1303.870117,0.006463,0.004250,0.107952,298.172699,15.189642,1.079520,-1303.870117,0.109028,0.000000
70.010002,67.768806,-1303.914551,0.006502,0.004261,0.108239,301.450714,15.356631,1.082385,-1303.914551,0.108481,0.000000
70.260002,66.691902,-1303.825684,0.006485,0.004261,0.108239,296.660400,15.112601,1.082385,-1303.825684,0.108481,0.000000
70.510002,65.808647,-1303.914551,0.006493,0.004260,0.108195,292.731476,14.912453,1.081950,-1303.914551,0.108239,0.000000
70.760002,64.968941,-1303.914551,0.006532,0.004259,0.108186,288.996277,14.722173,1.081863,-1303.914551,0.108239,0.000000
71.010002,64.236488,-1303.959106,0.006493,0.004259,0.108178,285.738159,14.556196,1.081776,-1303.959106,0.108239,0.000000
71.260002,63.560249,-1303.914551,0.006541,0.004259,0.108178,282.730103,14.402959,1.081776,-1303.914551,0.108239,0.000000
71.510002,62.981964,-1303.870117,0.006528,0.004259,0.108178,280.157776,14.271917,1.081776,-1303.870117,0.108239,0.000000
71.760002,62.439041,-1303.870117,0.006545,0.004259,0.108169,277.742737,14.148890,1.081689,-1303.870117,0.108239,0.000000
72.010002,61.972458,-1303.914551,0.006510,0.004259,0.108169,275.667267,14.043159,1.081689,-1303.914551,0.108239,0.000000
72.260002,61.530083,-1303.870117,0.006510,0.004259,0.108169,273.699463,13.942916,1.081689,-1303.870117,0.108239,0.000000
72.510002,61.159195,-1303.870117,0.006536,0.004259,0.108169,272.049683,13.858871,1.081689,-1303.870117,0.108239,0.000000
72.760002,60.788315,-1303.825684,0.006566,0.004259,0.108169,270.399933,13.774829,1.081689,-1303.825684,0.108239,0.000000
73.010002,60.468445,-1303.959106,0.006532,0.004259,0.108169,268.977081,13.702346,1.081689,-1303.959106,0.108239,0.000000
73.260002,60.155655,-1303.870117,0.006541,0.004259,0.108169,267.585724,13.631466,1.081689,-1303.870117,0.108239,0.000000
73.510002,59.876373,-1303.914551,0.006579,0.004258,0.108160,266.343414,13.568180,1.081602,-1303.914551,0.108239,0.000000
73.760002,59.622047,-1303.870117,0.006554,0.004258,0.108160,265.212128,13.510549,1.081602,-1303.870117,0.108239,0.000000
74.010002,59.375908,-1303.825684,0.006592,0.004258,0.108160,264.117218,13.454773,1.081602,-1303.825684,0.108239,0.000000
74.260002,59.154343,-1303.870117,0.006554,0.004258,0.108160,263.131653,13.404566,1.081602,-1303.870117,0.108239,0.000000
74.510002,58.917885,-1303.870117,0.006618,0.004258,0.108160,262.079834,13.350983,1.081602,-1303.870117,0.108239,0.000000
74.760002,58.745476,-1303.914551,0.006562,0.004258,0.108160,261.312927,13.311915,1.081602,-1303.914551,0.108239,0.000000
75.010002,58.538071,-1303.914551,0.006597,0.004258,0.108160,260.390350,13.264916,1.081602,-1303.914551,0.108239,0.000000
75.260002,58.373482,-1303.870117,0.006584,0.004258,0.108160,259.658203,13.227620,1.081602,-1303.870117,0.108239,0.000000
75.510002,58.194366,-1303.870117,0.006575,0.004258,0.108160,258.861481,13.187033,1.081602,-1303.870117,0.108239,0.000000
75.760002,58.042068,-1303.914551,0.006588,0.004258,0.108160,258.184021,13.152521,1.081602,-1303.914551,0.108239,0.000000
76.010002,57.889397,-1303.914551,0.006558,0.004258,0.108160,257.504883,13.117925,1.081602,-1303.914551,0.108239,0.000000
76.260002,57.728157,-1303.914551,0.006554,0.004258,0.108160,256.787659,13.081388,1.081602,-1303.914551,0.108239,0.000000
76.510002,57.609001,-1303.914551,0.006614,0.004258,0.108160,256.257629,13.054387,1.081602,-1303.914551,0.108239,0.000000
76.760002,57.471222,-1303.870117,0.006588,0.004258,0.108160,255.644760,13.023165,1.081602,-1303.870117,0.108239,0.000000
77.010002,57.357277,-1304.003540,0.006601,0.004258,0.108160,255.137909,12.997344,1.081602,-1304.003540,0.108239,0.000000
77.260002,57.225456,-1303.825684,0.006575,0.004258,0.108160,254.551544,12.967474,1.081602,-1303.825684,0.108239,0.000000
77.510002,57.131248,-1303.914551,0.006597,0.004258,0.108160,254.132492,12.946126,1.081602,-1303.914551,0.108239,0.000000
77.760002,56.999428,-1303.914551,0.006566,0.004258,0.108160,253.546112,12.916255,1.081602,-1303.914551,0.108239,0.000000
78.010002,56.909683,-1303.870117,0.006579,0.004258,0.108160,253.146912,12.895919,1.081602,-1303.870117,0.108239,0.000000
78.260002,56.812119,-1303.825684,0.006579,0.004258,0.108160,252.712921,12.873810,1.081602,-1303.825684,0.108239,0.000000
78.510002,56.706741,-1303.825684,0.006588,0.004258,0.108160,252.244186,12.849931,1.081602,-1303.825684,0.108239,0.000000
78.760002,56.622215,-1303.914551,0.006622,0.004258,0.108160,251.868195,12.830777,1.081602,-1303.914551,0.108239,0.000000
79.010002,56.522789,-1303.825684,0.006562,0.004258,0.108160,251.425919,12.808248,1.081602,-1303.825684,0.108239,0.000000
79.260002,56.456505,-1303.870117,0.006592,0.004258,0.108160,251.131073,12.793227,1.081602,-1303.870117,0.108239,0.000000
79.510002,56.358948,-1303.870117,0.006597,0.004258,0.108160,250.697113,12.771120,1.081602,-1303.870117,0.108239,0.000000
79.760002,56.288567,-1303.914551,0.006661,0.004258,0.108160,250.384048,12.755172,1.081602,-1303.914551,0.108239,0.000000
80.010002,56.185043,-1303.825684,0.006627,0.004258,0.108160,249.923553,12.731712,1.081602,-1303.825684,0.108239,0.000000
80.260002,56.131424,-1303.914551,0.006579,0.004258,0.108160,249.685043,12.719563,1.081602,-1303.914551,0.108239,0.000000
80.510002,56.049133,-1303.870117,0.006610,0.004258,0.108160,249.319000,12.700915,1.081602,-1303.870117,0.108239,0.000000
80.760002,55.976143,-1303.914551,0.006592,0.004258,0.108160,248.994324,12.684375,1.081602,-1303.914551,0.108239,0.000000
81.010002,55.911354,-1303.914551,0.006635,0.004258,0.108160,248.706131,12.669694,1.081602,-1303.914551,0.108239,0.000000
81.260002,55.823097,-1303.914551,0.006627,0.004258,0.108160,248.313538,12.649694,1.081602,-1303.914551,0.108239,0.000000
81.510002,55.777672,-1303.870117,0.006597,0.004258,0.108160,248.111481,12.639400,1.081602,-1303.870117,0.108239,0.000000
81.760002,55.689049,-1303.914551,0.006592,0.004258,0.108151,247.717255,12.619319,1.081515,-1303.914551,0.108239,0.000000
82.010002,55.648460,-1303.825684,0.006640,0.004258,0.108151,247.536713,12.610121,1.081515,-1303.825684,0.108239,0.000000
82.260002,55.565048,-1303.870117,0.006601,0.004258,0.108151,247.165680,12.591220,1.081515,-1303.870117,0.108239,0.000000
82.510002,55.517380,-1303.914551,0.006579,0.004258,0.108151,246.953644,12.580419,1.081515,-1303.914551,0.108239,0.000000
82.760002,55.449242,-1303.959106,0.006588,0.004258,0.108151,246.650543,12.564978,1.081515,-1303.959106,0.108239,0.000000
83.010002,55.387794,-1303.870117,0.006588,0.004258,0.108151,246.377213,12.551053,1.081515,-1303.870117,0.108239,0.000000
83.260002,55.337898,-1303.914551,0.006627,0.004258,0.108151,246.155258,12.539747,1.081515,-1303.914551,0.108239,0.000000
83.510002,55.290611,-1303.914551,0.006592,0.004258,0.108151,245.944916,12.529032,1.081515,-1303.914551,0.108239,0.000000
83.760002,55.235497,-1303.914551,0.006601,0.004258,0.108151,245.699753,12.516542,1.081515,-1303.914551,0.108239,0.000000
84.010002,55.175919,-1303.870117,0.006648,0.004258,0.108151,245.434738,12.503042,1.081515,-1303.870117,0.108239,0.000000
84.260002,55.133469,-1303.870117,0.006614,0.004258,0.108151,245.245911,12.493423,1.081515,-1303.870117,0.108239,0.000000
84.510002,55.078728,-1303.914551,0.006592,0.004258,0.108151,245.002411,12.481018,1.081515,-1303.914551,0.108239,0.000000
84.760002,55.033669,-1303.914551,0.006644,0.004258,0.108151,244.801987,12.470807,1.081515,-1303.914551,0.108239,0.000000
85.010002,54.978561,-1303.870117,0.006605,0.004258,0.108151,244.556854,12.458320,1.081515,-1303.870117,0.108239,0.000000
85.260002,54.932755,-1303.914551,0.006601,0.004258,0.108151,244.353088,12.447940,1.081515,-1303.914551,0.108239,0.000000
85.510002,54.899246,-1303.914551,0.006657,0.004258,0.108151,244.204041,12.440348,1.081515,-1303.914551,0.108239,0.000000
85.760002,54.837059,-1303.914551,0.006640,0.004258,0.108151,243.927414,12.426255,1.081515,-1303.914551,0.108239,0.000000
86.010002,54.813972,-1303.914551,0.006618,0.004258,0.108151,243.824722,12.421024,1.081515,-1303.914551,0.108239,0.000000
86.260002,54.741730,-1303.825684,0.006670,0.004258,0.108151,243.503372,12.404653,1.081515,-1303.825684,0.108239,0.000000
86.510002,54.716034,-1303.870117,0.006635,0.004258,0.108151,243.389069,12.398830,1.081515,-1303.870117,0.108239,0.000000
86.760002,54.667625,-1303.870117,0.006618,0.004258,0.108151,243.173737,12.387860,1.081515,-1303.870117,0.108239,0.000000
87.010002,54.647148,-1303.914551,0.006605,0.004258,0.108151,243.082657,12.383221,1.081515,-1303.914551,0.108239,0.000000
87.260002,54.589806,-1303.825684,0.006640,0.004258,0.108151,242.827576,12.370227,1.081515,-1303.825684,0.108239,0.000000
87.510002,54.560760,-1303.825684,0.006640,0.004258,0.108151,242.698380,12.363645,1.081515,-1303.825684,0.108239,0.000000
87.760002,54.501175,-1303.825684,0.006635,0.004258,0.108151,242.433334,12.350142,1.081515,-1303.825684,0.108239,0.000000
88.010002,54.468040,-1303.825684,0.006610,0.004258,0.108151,242.285950,12.342634,1.081515,-1303.825684,0.108239,0.000000
88.260002,54.440483,-1303.914551,0.006622,0.004258,0.108151,242.163361,12.336390,1.081515,-1303.914551,0.108239,0.000000
88.510002,54.393188,-1303.870117,0.006644,0.004258,0.108151,241.952988,12.325672,1.081515,-1303.870117,0.108239,0.000000
88.760002,54.379784,-1303.870117,0.006592,0.004258,0.108151,241.893356,12.322635,1.081515,-1303.870117,0.108239,0.000000
89.010002,54.321693,-1303.914551,0.006627,0.004258,0.108151,241.634964,12.309471,1.081515,-1303.914551,0.108239,0.000000
89.260002,54.298233,-1303.870117,0.006592,0.004258,0.108151,241.530609,12.304156,1.081515,-1303.870117,0.108239,0.000000
89.510002,54.255043,-1303.914551,0.006640,0.004258,0.108151,241.338486,12.294369,1.081515,-1303.914551,0.108239,0.000000
89.760002,54.225998,-1303.914551,0.006605,0.004258,0.108151,241.209290,12.287786,1.081515,-1303.914551,0.108239,0.000000
90.010002,54.189133,-1303.825684,0.006622,0.004258,0.108151,241.045303,12.279432,1.081515,-1303.825684,0.108239,0.000000
90.260002,54.170509,-1303.825684,0.006644,0.004258,0.108151,240.962463,12.275213,1.081515,-1303.825684,0.108239,0.000000
90.510002,54.133644,-1303.870117,0.006644,0.004258,0.108151,240.798477,12.266859,1.081515,-1303.870117,0.108239,0.000000
90.760002,54.099388,-1303.914551,0.006597,0.004258,0.108151,240.646103,12.259097,1.081515,-1303.914551,0.108239,0.000000
91.010002,54.076302,-1303.825684,0.006648,0.004258,0.108151,240.543396,12.253865,1.081515,-1303.825684,0.108239,0.000000
91.260002,54.031616,-1303.914551,0.006592,0.004258,0.108151,240.344635,12.243739,1.081515,-1303.914551,0.108239,0.000000
91.510002,54.010391,-1303.914551,0.006610,0.004258,0.108151,240.250214,12.238929,1.081515,-1303.914551,0.108239,0.000000
91.760002,53.960495,-1303.870117,0.006640,0.004258,0.108151,240.028275,12.227623,1.081515,-1303.870117,0.108239,0.000000
92.010002,53.961983,-1303.914551,0.006661,0.004258,0.108151,240.034882,12.227960,1.081515,-1303.914551,0.108239,0.000000
92.260002,53.915062,-1303.914551,0.006610,0.004258,0.108151,239.826172,12.217328,1.081515,-1303.914551,0.108239,0.000000
92.510002,53.891975,-1303.870117,0.006661,0.004258,0.108151,239.723480,12.212096,1.081515,-1303.870117,0.108239,0.000000
92.760002,53.859955,-1303.870117,0.006657,0.004258,0.108151,239.581039,12.204840,1.081515,-1303.870117,0.108239,0.000000
93.010002,53.840965,-1303.870117,0.006610,0.004258,0.108151,239.496582,12.200538,1.081515,-1303.870117,0.108239,0.000000
93.260002,53.820480,-1303.870117,0.006618,0.004258,0.108151,239.405457,12.195895,1.081515,-1303.870117,0.108239,0.000000
93.510002,53.779144,-1303.914551,0.006610,0.004258,0.108151,239.221588,12.186529,1.081515,-1303.914551,0.108239,0.000000
93.760002,53.769836,-1303.914551,0.006635,0.004258,0.108151,239.180176,12.184419,1.081515,-1303.914551,0.108239,0.000000
94.010002,53.711006,-1303.914551,0.006614,0.004258,0.108151,238.918488,12.171088,1.081515,-1303.914551,0.108239,0.000000
94.260002,53.703560,-1303.870117,0.006601,0.004258,0.108151,238.885361,12.169400,1.081515,-1303.870117,0.108239,0.000000
94.510002,53.681961,-1303.870117,0.006653,0.004258,0.108151,238.789291,12.164506,1.081515,-1303.870117,0.108239,0.000000
94.760002,53.658501,-1303.959106,0.006635,0.004258,0.108151,238.684937,12.159190,1.081515,-1303.959106,0.108239,0.000000
95.010002,53.637650,-1303.825684,0.006627,0.004258,0.108151,238.592178,12.154466,1.081515,-1303.825684,0.108239,0.000000
95.260002,53.609718,-1303.870117,0.006666,0.004258,0.108151,238.467941,12.148136,1.081515,-1303.870117,0.108239,0.000000
95.510002,53.578064,-1303.825684,0.006627,0.004258,0.108151,238.327133,12.140964,1.081515,-1303.825684,0.108239,0.000000
95.760002,53.546417,-1303.914551,0.006640,0.004258,0.108151,238.186356,12.133791,1.081515,-1303.914551,0.108239,0.000000
96.010002,53.538597,-1303.870117,0.006653,0.004258,0.108151,238.151581,12.132019,1.081515,-1303.870117,0.108239,0.000000
96.260002,53.505829,-1303.914551,0.006597,0.004258,0.108151,238.005814,12.124594,1.081515,-1303.914551,0.108239,0.000000
96.510002,53.510292,-1303.870117,0.006631,0.004258,0.108151,238.025665,12.125606,1.081515,-1303.870117,0.108239,0.000000
96.760002,53.472687,-1303.825684,0.006622,0.004258,0.108151,237.858383,12.117085,1.081515,-1303.825684,0.108239,0.000000
97.010002,53.464119,-1303.825684,0.006605,0.004258,0.108151,237.820282,12.115143,1.081515,-1303.825684,0.108239,0.000000
97.260002,53.417572,-1303.825684,0.006605,0.004258,0.108151,237.613220,12.104595,1.081515,-1303.825684,0.108239,0.000000
97.510002,53.411613,-1303.870117,0.006592,0.004258,0.108151,237.586716,12.103244,1.081515,-1303.870117,0.108239,0.000000
97.760002,53.387413,-1303.870117,0.006631,0.004258,0.108151,237.479080,12.097761,1.081515,-1303.870117,0.108239,0.000000
98.010002,53.360603,-1303.825684,0.006631,0.004258,0.108151,237.359818,12.091685,1.081515,-1303.825684,0.108239,0.000000
98.260002,53.347565,-1303.870117,0.006644,0.004258,0.108151,237.301819,12.088731,1.081515,-1303.870117,0.108239,0.000000
98.510002,53.311447,-1303.870117,0.006661,0.004258,0.108151,237.141159,12.080546,1.081515,-1303.870117,0.108239,0.000000
98.760002,53.306236,-1303.870117,0.006601,0.004258,0.108151,237.117981,12.079366,1.081515,-1303.870117,0.108239,0.000000
99.010002,53.261551,-1303.870117,0.006640,0.004258,0.108151,236.919205,12.069240,1.081515,-1303.870117,0.108239,0.000000
99.260002,53.265648,-1303.825684,0.006657,0.004258,0.108151,236.937439,12.070168,1.081515,-1303.825684,0.108239,0.000000
99.510002,53.220215,-1303.825684,0.006666,0.004258,0.108151,236.735336,12.059873,1.081515,-1303.825684,0.108239,0.000000
99.760002,53.227661,-1303.870117,0.006640,0.004258,0.108151,236.768463,12.061561,1.081515,-1303.870117,0.108239,0.000000
100.010002,53.181114,-1303.825684,0.006597,0.004258,0.108151,236.561417,12.051012,1.081515,-1303.825684,0.108239,0.000000
100.260002,53.181488,-1303.870117,0.006614,0.004258,0.108151,236.563080,12.051098,1.081515,-1303.870117,0.108239,0.000000
100.400002,53.167343,-1303.825684,0.006618,0.004258,0.108151,236.500153,12.047893,1.081515,-1303.825684,0.108239,0.000000