File: Data/Automembrane/AutoHeating-12wt-1-2_12152023_174720.csv
Time (sec),S:Load (lbs),S:HL1 (DIM),S:LVDT (in),S:Position (in),Ch:Position (mm),Ch:Load (N),Ch:Stress (MPa),Ch:Strain (mm/mm),Ch:HL1 (DIM),Set Point (),Cycles ()
0.110000,-0.011169,-226.497009,-0.000009,-0.000000,-0.000000,-0.049684,-0.002531,-0.000000,-226.497009,0.000217,0.000000
0.370000,-0.024574,-226.497009,-0.000009,0.000004,0.000095,-0.109312,-0.005569,0.000954,-226.497009,0.000720,0.000000
0.630000,-0.002602,-226.497009,0.000009,0.000161,0.004102,-0.011573,-0.000590,0.041021,-226.497009,0.005056,0.000000
0.890000,-0.032768,-226.497009,0.000168,0.000329,0.008369,-0.145760,-0.007425,0.083688,-226.497009,0.009375,0.000000
1.150000,-0.024574,-226.541489,0.000332,0.000501,0.012713,-0.109312,-0.005569,0.127135,-226.541489,0.013711,0.000000
1.410000,0.001862,-226.541489,0.000509,0.000658,0.016720,0.008281,0.000422,0.167202,-226.541489,0.018047,0.000000
1.670000,-0.061066,-226.541489,0.000729,0.000842,0.021386,-0.271634,-0.013838,0.213858,-226.541489,0.022383,0.000000
1.930000,-0.005585,-226.541489,0.000845,0.001011,0.025687,-0.024842,-0.001266,0.256873,-226.541489,0.026702,0.000000
2.190000,0.004097,-226.541489,0.001026,0.001171,0.029755,0.018224,0.000928,0.297546,-226.541489,0.031038,0.000000
2.450000,-0.026436,-226.541489,0.001199,0.001350,0.034299,-0.117593,-0.005990,0.342987,-226.541489,0.035374,0.000000
2.710000,-0.002235,-226.585968,0.001401,0.001522,0.038652,-0.009944,-0.000507,0.386521,-226.585968,0.039710,0.000000
2.970000,-0.009682,-226.585968,0.001608,0.001693,0.043006,-0.043066,-0.002194,0.430059,-226.585968,0.044029,0.000000
3.230000,-0.032021,-226.585968,0.001755,0.001861,0.047273,-0.142435,-0.007256,0.472726,-226.585968,0.048365,0.000000
3.490000,-0.023460,-226.585968,0.001944,0.002030,0.051565,-0.104357,-0.005316,0.515650,-226.585968,0.052701,0.000000
3.750000,-0.021599,-226.585968,0.002095,0.002199,0.055858,-0.096076,-0.004894,0.558579,-226.585968,0.057037,0.000000
4.010000,-0.013405,-226.585968,0.002302,0.002373,0.060263,-0.059628,-0.003038,0.602635,-226.585968,0.061356,0.000000
4.270000,0.005585,-226.585968,0.002445,0.002542,0.064556,0.024842,0.001266,0.645563,-226.585968,0.065692,0.000000
4.530000,0.016762,-226.630447,0.002634,0.002717,0.069005,0.074560,0.003798,0.690051,-226.630447,0.070029,0.000000
4.790000,-0.008194,-226.630447,0.002820,0.002887,0.073324,-0.036449,-0.001857,0.733240,-226.630447,0.074364,0.000000
5.050000,-0.000000,-226.674927,0.002992,0.003054,0.077565,-0.000000,-0.000000,0.775646,-226.674927,0.078683,0.000000
5.310000,-0.007446,-226.674927,0.003186,0.003228,0.081988,-0.033123,-0.001687,0.819876,-226.674927,0.083019,0.000000
5.570000,-0.050644,-226.674927,0.003350,0.003397,0.086280,-0.225275,-0.011476,0.862801,-226.674927,0.087356,0.000000
5.830000,-0.006332,-226.630447,0.003518,0.003562,0.090478,-0.028168,-0.001435,0.904775,-226.630447,0.091674,0.000000
6.090000,0.005585,-226.630447,0.003734,0.003738,0.094935,0.024842,0.001266,0.949350,-226.630447,0.096011,0.000000
6.350000,-0.035378,-226.719406,0.003902,0.003908,0.099263,-0.157367,-0.008017,0.992627,-226.719406,0.100347,0.000000
6.610000,0.008942,-226.630447,0.004087,0.004076,0.103538,0.039774,0.002026,1.035381,-226.630447,0.104683,0.000000
6.870000,0.005585,-226.674927,0.004281,0.004250,0.107961,0.024842,0.001266,1.079607,-226.674927,0.109002,0.000000
7.130000,-0.013779,-226.674927,0.004445,0.004418,0.112228,-0.061291,-0.003122,1.122278,-226.674927,0.113338,0.000000
7.390000,0.004845,-226.674927,0.004592,0.004586,0.116486,0.021550,0.001098,1.164858,-226.674927,0.117674,0.000000
7.650001,-0.018242,-226.763885,0.004799,0.004765,0.121030,-0.081144,-0.004134,1.210300,-226.763885,0.122010,0.000000
7.910000,-0.041702,-226.674927,0.004971,0.004935,0.125340,-0.185501,-0.009450,1.253402,-226.674927,0.126329,0.000000
8.170000,0.070007,-226.719406,0.005152,0.005098,0.129494,0.311408,0.015864,1.294941,-226.719406,0.130665,0.000000
8.430000,0.122887,-226.674927,0.005338,0.005276,0.134004,0.546627,0.027847,1.340038,-226.674927,0.135001,0.000000
8.690001,0.222305,-226.719406,0.005484,0.005443,0.138244,0.988863,0.050375,1.382444,-226.719406,0.139337,0.000000
8.950001,0.491905,-226.763885,0.005670,0.005609,0.142468,2.188104,0.111467,1.424680,-226.763885,0.143656,0.000000
9.210000,0.480736,-226.719406,0.005752,-0.000003,-0.000078,2.138420,0.108936,-0.000783,-226.719406,0.000147,0.000000
9.470000,0.423019,-226.763885,0.005790,-0.000003,-0.000078,1.881684,0.095858,-0.000783,-226.763885,0.000147,0.000000
9.730000,0.445358,-226.852844,0.005773,-0.000003,-0.000078,1.981053,0.100920,-0.000783,-226.852844,0.000321,0.000000
9.990001,0.446106,-226.763885,0.005764,-0.000003,-0.000070,1.984378,0.101089,-0.000696,-226.763885,0.000754,0.000000
10.250001,0.447220,-226.852844,0.005777,-0.000003,-0.000070,1.989333,0.101341,-0.000696,-226.852844,0.001188,0.000000
10.510000,0.616653,-226.808365,0.005773,0.000029,0.000737,2.743011,0.139736,0.007369,-226.808365,0.001621,0.000000
10.770000,0.709373,-226.808365,0.005821,0.000047,0.001205,3.155451,0.160746,0.012055,-226.808365,0.002055,0.000000
11.030001,0.763367,-226.852844,0.005812,0.000068,0.001734,3.395625,0.172981,0.017342,-226.852844,0.002489,0.000000
11.290001,0.788689,-226.763885,0.005838,0.000081,0.002055,3.508262,0.178719,0.020552,-226.763885,0.002922,0.000000
11.550000,0.827415,-226.852844,0.005846,0.000098,0.002480,3.680528,0.187495,0.024802,-226.852844,0.003356,0.000000
11.810000,0.880661,-226.808365,0.005877,0.000115,0.002914,3.917376,0.199561,0.029136,-226.808365,0.003790,0.000000
12.070001,0.999451,-226.808365,0.005885,0.000136,0.003460,4.445779,0.226479,0.034602,-226.808365,0.004223,0.000000
12.330001,1.016205,-226.808365,0.005898,0.000149,0.003781,4.520305,0.230275,0.037811,-226.808365,0.004657,0.000000
12.590000,1.073181,-226.808365,0.005941,0.000162,0.004119,4.773748,0.243186,0.041191,-226.808365,0.005090,0.000000
12.850000,1.212074,-226.852844,0.005928,0.000185,0.004691,5.391576,0.274660,0.046914,-226.852844,0.005524,0.000000
13.110001,1.275375,-226.852844,0.005967,0.000205,0.005212,5.673153,0.289004,0.052118,-226.852844,0.005958,0.000000
13.370001,1.302185,-226.852844,0.005984,0.000219,0.005559,5.792408,0.295079,0.055589,-226.852844,0.006391,0.000000
13.630001,1.371078,-226.897339,0.006006,0.000234,0.005949,6.098862,0.310691,0.059491,-226.897339,0.006825,0.000000
13.890000,1.392677,-226.852844,0.005997,0.000248,0.006296,6.194938,0.315585,0.062958,-226.852844,0.007259,0.000000
14.150001,1.582581,-226.852844,0.006062,0.000271,0.006885,7.039670,0.358618,0.068855,-226.852844,0.007683,0.000000
14.410001,1.626152,-226.897339,0.006028,0.000284,0.007206,7.233486,0.368491,0.072064,-226.897339,0.008117,0.000000
14.670001,1.675308,-226.897339,0.006071,0.000298,0.007562,7.452143,0.379630,0.075622,-226.897339,0.008551,0.000000
14.930000,1.761696,-226.941818,0.006071,0.000317,0.008048,7.836414,0.399206,0.080478,-226.941818,0.008984,0.000000
15.190001,1.914742,-226.897339,0.006114,0.000337,0.008568,8.517196,0.433887,0.085682,-226.897339,0.009418,0.000000
15.450001,1.951607,-226.986298,0.006131,0.000355,0.009019,8.681180,0.442240,0.090190,-226.986298,0.009852,0.000000
15.710001,1.968361,-226.941818,0.006118,0.000369,0.009374,8.755707,0.446037,0.093744,-226.941818,0.010285,0.000000
15.970001,2.150078,-226.941818,0.006153,0.000389,0.009886,9.564024,0.487215,0.098861,-226.941818,0.010719,0.000000
16.230001,2.180618,-226.986298,0.006153,0.000404,0.010268,9.699875,0.494135,0.102677,-226.986298,0.011153,0.000000
16.490002,2.242798,-226.941818,0.006174,0.000417,0.010580,9.976463,0.508225,0.105799,-226.941818,0.011586,0.000000
16.750000,2.418564,-226.986298,0.006204,0.000437,0.011109,10.758309,0.548054,0.111090,-226.986298,0.012020,0.000000
17.010000,2.538094,-227.030777,0.006200,0.000459,0.011655,11.290004,0.575140,0.116552,-227.030777,0.012453,0.000000
17.270000,2.531387,-226.941818,0.006247,0.000473,0.012011,11.260173,0.573621,0.120110,-226.941818,0.012887,0.000000
17.530001,2.647194,-227.030777,0.006213,0.000491,0.012462,11.775307,0.599863,0.124618,-227.030777,0.013321,0.000000
17.790001,2.767845,-226.941818,0.006247,0.000509,0.012922,12.311990,0.627203,0.129216,-226.941818,0.013754,0.000000
18.050001,2.879189,-227.030777,0.006278,0.000528,0.013407,12.807270,0.652433,0.134072,-227.030777,0.014188,0.000000
18.310001,2.774551,-227.030777,0.006308,0.000535,0.013589,12.341821,0.628722,0.135893,-227.030777,0.014621,0.000000
18.570002,2.968552,-227.030777,0.006303,0.000554,0.014084,13.204777,0.672683,0.140836,-227.030777,0.015055,0.000000
18.830002,3.206871,-227.075256,0.006325,0.000578,0.014682,14.264874,0.726687,0.146820,-227.075256,0.015489,0.000000
19.090000,3.216179,-226.986298,0.006351,0.000593,0.015072,14.306278,0.728797,0.150722,-226.986298,0.015922,0.000000
19.350000,3.187508,-227.075256,0.006368,0.000607,0.015428,14.178742,0.722300,0.154280,-227.075256,0.016356,0.000000
19.610001,3.336456,-227.075256,0.006364,0.000625,0.015887,14.841299,0.756052,0.158875,-227.075256,0.016789,0.000000
19.870001,3.574036,-227.030777,0.006381,0.000647,0.016442,15.898105,0.809888,0.164423,-227.030777,0.017223,0.000000
20.130001,3.519669,-227.119736,0.006428,0.000660,0.016763,15.656268,0.797568,0.167633,-227.119736,0.017657,0.000000
20.390001,3.634727,-227.030777,0.006424,0.000673,0.017093,16.168076,0.823641,0.170930,-227.030777,0.018090,0.000000
20.650002,3.665260,-227.119736,0.006420,0.000684,0.017370,16.303892,0.830560,0.173704,-227.119736,0.018524,0.000000
20.910002,4.121048,-227.164215,0.006463,0.000716,0.018177,18.331337,0.933843,0.181770,-227.164215,0.018957,0.000000
21.170000,4.046204,-227.075256,0.006467,0.000731,0.018567,17.998413,0.916883,0.185672,-227.075256,0.019391,0.000000
21.430000,4.119186,-227.119736,0.006519,0.000747,0.018975,18.323057,0.933421,0.189748,-227.119736,0.019825,0.000000
21.690001,4.293083,-227.119736,0.006519,0.000766,0.019460,19.096588,0.972827,0.194604,-227.119736,0.020258,0.000000
21.950001,4.328461,-227.075256,0.006541,0.000779,0.019799,19.253954,0.980843,0.197988,-227.075256,0.020692,0.000000
22.210001,4.385063,-227.208694,0.006536,0.000793,0.020154,19.505735,0.993670,0.201542,-227.208694,0.021125,0.000000
22.470001,4.370537,-227.164215,0.006554,0.000806,0.020466,19.441118,0.990378,0.204664,-227.164215,0.021559,0.000000
22.730001,4.745140,-227.208694,0.006549,0.000830,0.021091,21.107437,1.075264,0.210909,-227.208694,0.021993,0.000000
22.990002,4.874733,-227.119736,0.006592,0.000850,0.021602,21.683895,1.104630,0.216023,-227.119736,0.022418,0.000000
23.250002,4.841217,-227.119736,0.006640,0.000864,0.021941,21.534809,1.097035,0.219407,-227.119736,0.022851,0.000000
23.510000,4.990166,-227.208694,0.006627,0.000882,0.022400,22.197365,1.130788,0.224001,-227.208694,0.023285,0.000000
23.770000,5.160713,-227.164215,0.006648,0.000903,0.022929,22.955999,1.169434,0.229293,-227.164215,0.023718,0.000000
24.030001,5.142838,-227.208694,0.006648,0.000916,0.023268,22.876484,1.165384,0.232676,-227.208694,0.024152,0.000000
24.290001,5.198318,-227.253174,0.006648,0.000930,0.023632,23.123276,1.177956,0.236317,-227.253174,0.024586,0.000000
24.550001,5.545746,-227.208694,0.006691,0.000954,0.024230,24.668709,1.256684,0.242301,-227.208694,0.025019,0.000000
24.810001,5.596390,-227.253174,0.006704,0.000970,0.024646,24.893986,1.268160,0.246465,-227.253174,0.025453,0.000000
25.070002,5.577766,-227.164215,0.006717,0.000986,0.025045,24.811144,1.263940,0.250454,-227.164215,0.025886,0.000000
25.330002,5.657829,-227.253174,0.006739,0.001003,0.025487,25.167282,1.282082,0.254875,-227.253174,0.026320,0.000000
25.590002,5.809387,-227.253174,0.006748,0.001020,0.025904,25.841444,1.316426,0.259038,-227.253174,0.026754,0.000000
25.850000,5.893913,-227.208694,0.006791,0.001036,0.026320,26.217436,1.335580,0.263202,-227.208694,0.027187,0.000000
26.110001,5.950142,-227.297653,0.006812,0.001052,0.026719,26.467552,1.348321,0.267191,-227.297653,0.027621,0.000000
26.370001,5.957588,-227.208694,0.006817,0.001066,0.027074,26.500675,1.350009,0.270745,-227.208694,0.028055,0.000000
26.630001,6.430870,-227.297653,0.006817,0.001093,0.027768,28.605938,1.457256,0.277683,-227.297653,0.028488,0.000000
26.890001,6.367195,-227.253174,0.006825,0.001110,0.028185,28.322699,1.442827,0.281846,-227.253174,0.028922,0.000000
27.150002,6.223465,-227.297653,0.006864,0.001123,0.028532,27.683355,1.410257,0.285317,-227.297653,0.029356,0.000000
27.410002,6.295700,-227.297653,0.006851,0.001138,0.028913,28.004673,1.426626,0.289132,-227.297653,0.029789,0.000000
27.670002,6.561577,-227.253174,0.006890,0.001160,0.029468,29.187351,1.486874,0.294681,-227.253174,0.030223,0.000000
27.930002,6.530296,-227.297653,0.006911,0.001174,0.029815,29.048208,1.479786,0.298151,-227.297653,0.030656,0.000000
28.190001,6.280434,-227.297653,0.006916,0.001181,0.030006,27.936764,1.423167,0.300059,-227.297653,0.031090,0.000000
28.450001,6.764145,-227.253174,0.006924,0.001209,0.030700,30.088419,1.532777,0.306997,-227.253174,0.031524,0.000000
28.710001,6.863945,-227.386627,0.006937,0.001227,0.031159,30.532352,1.555392,0.311591,-227.386627,0.031957,0.000000
28.970001,6.750740,-227.297653,0.006954,0.001241,0.031532,30.028791,1.529739,0.315323,-227.297653,0.032391,0.000000
29.230001,6.847183,-227.342148,0.006980,0.001258,0.031957,30.457792,1.551594,0.319570,-227.342148,0.032825,0.000000
29.490002,6.821861,-227.386627,0.006989,0.001275,0.032382,30.345154,1.545856,0.323820,-227.386627,0.033258,0.000000
29.750002,6.997993,-227.342148,0.007006,0.001293,0.032850,31.128630,1.585768,0.328502,-227.342148,0.033692,0.000000
30.010002,6.974167,-227.431107,0.006998,0.001307,0.033189,31.022644,1.580369,0.331886,-227.431107,0.034125,0.000000
30.270002,6.793190,-227.342148,0.006985,0.001321,0.033561,30.217619,1.539359,0.335614,-227.342148,0.034559,0.000000
30.530001,7.327919,-227.342148,0.007045,0.001346,0.034177,32.596210,1.660530,0.341772,-227.342148,0.034992,0.000000
30.790001,7.215462,-227.386627,0.007054,0.001361,0.034559,32.095978,1.635047,0.345587,-227.386627,0.035426,0.000000
31.050001,7.213226,-227.342148,0.007092,0.001377,0.034975,32.086033,1.634540,0.349751,-227.342148,0.035860,0.000000
31.310001,7.178970,-227.386627,0.007088,0.001392,0.035357,31.933655,1.626778,0.353566,-227.386627,0.036293,0.000000
31.570002,7.387123,-227.386627,0.007097,0.001413,0.035894,32.859566,1.673946,0.358944,-227.386627,0.036727,0.000000
31.830002,7.380798,-227.386627,0.007140,0.001429,0.036302,32.831432,1.672513,0.363021,-227.386627,0.037160,0.000000
32.090000,7.363670,-227.386627,0.007123,0.001444,0.036684,32.755241,1.668632,0.366836,-227.386627,0.037586,0.000000
32.350002,7.521927,-227.431107,0.007140,0.001464,0.037195,33.459202,1.704493,0.371953,-227.431107,0.038019,0.000000
32.610001,7.536446,-227.431107,0.007166,0.001482,0.037655,33.523785,1.707783,0.376548,-227.431107,0.038453,0.000000
32.870003,7.402397,-227.475586,0.007170,0.001496,0.038002,32.927505,1.677407,0.380019,-227.475586,0.038886,0.000000
33.130001,7.436653,-227.431107,0.007192,0.001513,0.038435,33.079884,1.685170,0.384352,-227.431107,0.039320,0.000000
33.390003,7.644432,-227.475586,0.007213,0.001534,0.038956,34.004131,1.732253,0.389557,-227.475586,0.039754,0.000000
33.650002,7.514847,-227.431107,0.007239,0.001546,0.039259,33.427708,1.702889,0.392592,-227.431107,0.040187,0.000000
33.910000,7.529747,-227.475586,0.007243,0.001561,0.039641,33.493988,1.706265,0.396407,-227.475586,0.040621,0.000000
34.170002,7.739761,-227.475586,0.007261,0.001581,0.040161,34.428177,1.753855,0.401611,-227.475586,0.041054,0.000000
34.430000,7.914406,-227.520065,0.007278,0.001604,0.040733,35.205036,1.793430,0.407334,-227.520065,0.041488,0.000000
34.690002,7.696938,-227.520065,0.007308,0.001617,0.041063,34.237690,1.744151,0.410631,-227.520065,0.041921,0.000000
34.950001,7.686890,-227.475586,0.007343,0.001633,0.041479,34.192993,1.741874,0.414794,-227.475586,0.042355,0.000000
35.210003,7.546127,-227.520065,0.007312,0.001646,0.041817,33.566853,1.709977,0.418174,-227.520065,0.042789,0.000000
35.470001,7.915154,-227.520065,0.007338,0.001670,0.042407,35.208363,1.793599,0.424071,-227.520065,0.043222,0.000000
35.730003,7.806046,-227.431107,0.007351,0.001683,0.042737,34.723026,1.768875,0.427368,-227.431107,0.043656,0.000000
35.990002,7.716301,-227.520065,0.007377,0.001695,0.043049,34.323822,1.748539,0.430490,-227.520065,0.044089,0.000000
36.250000,7.998932,-227.475586,0.007377,0.001720,0.043682,35.581024,1.812584,0.436819,-227.475586,0.044523,0.000000
36.510002,8.047340,-227.475586,0.007416,0.001736,0.044098,35.796356,1.823553,0.440982,-227.475586,0.044957,0.000000
36.770000,8.046967,-227.564545,0.007390,0.001754,0.044541,35.794697,1.823469,0.445406,-227.564545,0.045390,0.000000
37.030003,7.903610,-227.564545,0.007424,0.001769,0.044931,35.157013,1.790984,0.449309,-227.564545,0.045824,0.000000
37.290001,8.108788,-227.564545,0.007455,0.001788,0.045416,36.069687,1.837478,0.454165,-227.564545,0.046258,0.000000
37.550003,8.056282,-227.520065,0.007489,0.001804,0.045824,35.836132,1.825580,0.458241,-227.520065,0.046691,0.000000
37.810001,7.926323,-227.520065,0.007472,0.001815,0.046102,35.258045,1.796131,0.461015,-227.520065,0.047125,0.000000
38.070004,8.175064,-227.653503,0.007498,0.001836,0.046639,36.364502,1.852496,0.466394,-227.653503,0.047558,0.000000
38.330002,8.348221,-227.564545,0.007528,0.001857,0.047177,37.134743,1.891734,0.471768,-227.564545,0.047992,0.000000
38.590000,8.224220,-227.653503,0.007519,0.001872,0.047558,36.583160,1.863635,0.475583,-227.653503,0.048426,0.000000
38.850002,8.275978,-227.609024,0.007541,0.001889,0.047992,36.813389,1.875363,0.479921,-227.609024,0.048859,0.000000
39.110001,8.337418,-227.564545,0.007545,0.001907,0.048426,37.086685,1.889286,0.484258,-227.564545,0.049293,0.000000
39.370003,8.467377,-227.609024,0.007567,0.001926,0.048929,37.664772,1.918735,0.489289,-227.609024,0.049727,0.000000
39.630001,8.095749,-227.564545,0.007588,0.001934,0.049111,36.011688,1.834523,0.491109,-227.564545,0.050160,0.000000
39.890003,8.357529,-227.609024,0.007606,0.001954,0.049631,37.176144,1.893843,0.496313,-227.609024,0.050594,0.000000
40.150002,8.590263,-227.653503,0.007584,0.001976,0.050186,38.211399,1.946581,0.501862,-227.653503,0.051028,0.000000
40.410004,8.518768,-227.653503,0.007614,0.001993,0.050611,37.893375,1.930380,0.506112,-227.653503,0.051461,0.000000
40.670002,8.341141,-227.697983,0.007631,0.002007,0.050975,37.103249,1.890129,0.509753,-227.697983,0.051895,0.000000
40.930000,8.438332,-227.653503,0.007653,0.002024,0.051409,37.535572,1.912153,0.514091,-227.653503,0.052328,0.000000
41.190002,8.721336,-227.653503,0.007662,0.002047,0.051990,38.794441,1.976283,0.519901,-227.653503,0.052753,0.000000
41.450001,8.530685,-227.697983,0.007675,0.002059,0.052311,37.946384,1.933081,0.523110,-227.697983,0.053187,0.000000
41.710003,8.344872,-227.653503,0.007679,0.002072,0.052623,37.119843,1.890975,0.526233,-227.653503,0.053621,0.000000
41.970001,8.359390,-227.742462,0.007718,0.002083,0.052918,37.184425,1.894265,0.529181,-227.742462,0.054054,0.000000
42.230003,9.004715,-227.653503,0.007748,0.002114,0.053707,40.054974,2.040498,0.537073,-227.653503,0.054488,0.000000
42.490002,8.792084,-227.653503,0.007735,0.002129,0.054089,39.109142,1.992315,0.540888,-227.653503,0.054921,0.000000
42.750004,8.747032,-227.786957,0.007739,0.002146,0.054505,38.908741,1.982106,0.545051,-227.786957,0.055355,0.000000
43.010002,8.831184,-227.742462,0.007756,0.002165,0.054982,39.283070,2.001175,0.549820,-227.742462,0.055789,0.000000
43.270000,8.758202,-227.742462,0.007782,0.002179,0.055355,38.958427,1.984637,0.553548,-227.742462,0.056222,0.000000
43.530003,8.663620,-227.742462,0.007787,0.002191,0.055650,38.537708,1.963204,0.556497,-227.742462,0.056656,0.000000
43.790001,8.725807,-227.742462,0.007800,0.002208,0.056075,38.814327,1.977296,0.560747,-227.742462,0.057089,0.000000
44.050003,9.113441,-227.742462,0.007817,0.002231,0.056664,40.538612,2.065135,0.566644,-227.742462,0.057523,0.000000
44.310001,9.076210,-227.742462,0.007830,0.002249,0.057115,40.372997,2.056699,0.571152,-227.742462,0.057957,0.000000
44.570004,8.927261,-227.786957,0.007869,0.002262,0.057462,39.710442,2.022946,0.574623,-227.786957,0.058390,0.000000
44.830002,9.068764,-227.742462,0.007869,0.002280,0.057922,40.339874,2.055011,0.579218,-227.742462,0.058824,0.000000
45.090004,9.241913,-227.742462,0.007894,0.002302,0.058468,41.110081,2.094247,0.584683,-227.742462,0.059257,0.000000
45.350002,9.012535,-227.831436,0.007899,0.002315,0.058798,40.089760,2.042270,0.587976,-227.831436,0.059691,0.000000
45.610001,9.006203,-227.786957,0.007916,0.002331,0.059197,40.061592,2.040835,0.591965,-227.786957,0.060125,0.000000
45.870003,9.343201,-227.786957,0.007933,0.002353,0.059769,41.560631,2.117199,0.597692,-227.786957,0.060558,0.000000
46.130001,9.340218,-227.786957,0.007938,0.002369,0.060177,41.547363,2.116524,0.601768,-227.786957,0.060992,0.000000
46.390003,9.166321,-227.786957,0.007959,0.002385,0.060567,40.773830,2.077118,0.605670,-227.786957,0.061425,0.000000
46.650002,9.212868,-227.831436,0.007972,0.002402,0.061000,40.980881,2.087666,0.610004,-227.831436,0.061859,0.000000
46.910004,9.353256,-227.786957,0.007959,0.002419,0.061443,41.605362,2.119478,0.614429,-227.786957,0.062293,0.000000
47.170002,9.384529,-227.875916,0.008015,0.002435,0.061850,41.744469,2.126565,0.618505,-227.875916,0.062726,0.000000
47.430004,9.373360,-227.831436,0.008011,0.002451,0.062249,41.694786,2.124034,0.622494,-227.831436,0.063160,0.000000
47.690002,9.366661,-227.831436,0.008011,0.002466,0.062640,41.664989,2.122516,0.626396,-227.831436,0.063593,0.000000
47.950001,9.884628,-227.920395,0.008050,0.002492,0.063290,43.969021,2.239889,0.632899,-227.920395,0.064027,0.000000
48.210003,9.706261,-227.831436,0.008084,0.002508,0.063698,43.175602,2.199470,0.636975,-227.831436,0.064461,0.000000
48.470001,9.480232,-227.920395,0.008063,0.002521,0.064045,42.170177,2.148251,0.640446,-227.920395,0.064894,0.000000
48.730003,9.514488,-227.831436,0.008063,0.002537,0.064435,42.322556,2.156014,0.644348,-227.831436,0.065328,0.000000
48.990002,9.784462,-227.875916,0.008106,0.002559,0.064990,43.523460,2.217191,0.649897,-227.875916,0.065761,0.000000
49.250004,9.704025,-227.920395,0.008114,0.002572,0.065337,43.165661,2.198964,0.653368,-227.920395,0.066195,0.000000
49.510002,9.369263,-227.875916,0.008140,0.002583,0.065614,41.676563,2.123105,0.656142,-227.875916,0.066629,0.000000
49.770000,9.903244,-227.964874,0.008136,0.002607,0.066213,44.051830,2.244107,0.662126,-227.964874,0.067062,0.000000
50.030003,10.016075,-227.964874,0.008157,0.002625,0.066672,44.553726,2.269675,0.666721,-227.964874,0.067487,0.000000
50.290001,9.823189,-227.875916,0.008183,0.002641,0.067080,43.695724,2.225966,0.670797,-227.875916,0.067921,0.000000
50.550003,9.878296,-227.964874,0.008179,0.002657,0.067479,43.940853,2.238454,0.674786,-227.964874,0.068354,0.000000
50.810001,9.866013,-227.920395,0.008205,0.002675,0.067947,43.886215,2.235670,0.679472,-227.920395,0.068788,0.000000
51.070004,9.826912,-227.964874,0.008226,0.002686,0.068216,43.712288,2.226810,0.682159,-227.964874,0.069222,0.000000
51.330002,10.011978,-227.964874,0.008231,0.002704,0.068693,44.535503,2.268747,0.686928,-227.964874,0.069655,0.000000
51.590004,9.609444,-227.920395,0.008235,0.002712,0.068884,42.744942,2.177531,0.688836,-227.920395,0.070089,0.000000
51.850002,10.533302,-228.009354,0.008274,0.002745,0.069716,46.854469,2.386880,0.697163,-228.009354,0.070523,0.000000
52.110001,10.368340,-227.920395,0.008257,0.002760,0.070115,46.120678,2.349499,0.701152,-227.920395,0.070956,0.000000
52.370003,10.353447,-228.009354,0.008300,0.002776,0.070514,46.054432,2.346125,0.705141,-228.009354,0.071390,0.000000
52.630001,10.297592,-228.009354,0.008291,0.002791,0.070887,45.805977,2.333468,0.708869,-228.009354,0.071824,0.000000
52.890003,10.576126,-228.009354,0.008321,0.002812,0.071416,47.044960,2.396585,0.714161,-228.009354,0.072257,0.000000
53.150002,10.543358,-228.009354,0.008334,0.002828,0.071841,46.899197,2.389159,0.718407,-228.009354,0.072691,0.000000
53.410004,10.625275,-228.009354,0.008347,0.002845,0.072257,47.263580,2.407722,0.722571,-228.009354,0.073124,0.000000
53.670002,10.744812,-227.964874,0.008356,0.002863,0.072717,47.795311,2.434809,0.727169,-227.964874,0.073558,0.000000
53.930004,10.836037,-228.009354,0.008386,0.002881,0.073185,48.201099,2.455481,0.731851,-228.009354,0.073992,0.000000
54.190002,10.703476,-227.964874,0.008399,0.002895,0.073532,47.611439,2.425442,0.735318,-227.964874,0.074425,0.000000
54.450001,10.771622,-228.009354,0.008399,0.002912,0.073957,47.914566,2.440884,0.739568,-228.009354,0.074859,0.000000
54.710003,11.078453,-228.053833,0.008420,0.002931,0.074451,49.279419,2.510413,0.744512,-228.053833,0.075293,0.000000
54.970001,11.009567,-228.098312,0.008429,0.002945,0.074798,48.973000,2.494803,0.747982,-228.098312,0.075726,0.000000
55.230003,11.024460,-228.142792,0.008459,0.002959,0.075162,49.039246,2.498178,0.751623,-228.142792,0.076160,0.000000
55.490002,11.335022,-228.053833,0.008464,0.002980,0.075691,50.420696,2.568553,0.756915,-228.053833,0.076593,0.000000
55.750004,11.656380,-228.098312,0.008468,0.003002,0.076246,51.850166,2.641373,0.762463,-228.098312,0.077027,0.000000
56.010002,11.489929,-228.098312,0.008476,0.003015,0.076593,51.109756,2.603655,0.765934,-228.098312,0.077461,0.000000
56.270004,11.499611,-228.098312,0.008511,0.003032,0.077001,51.152824,2.605849,0.770007,-228.098312,0.077894,0.000000
56.530003,11.354012,-228.098312,0.008511,0.003045,0.077339,50.505165,2.572856,0.773390,-228.098312,0.078328,0.000000
56.790001,11.905495,-228.098312,0.008541,0.003068,0.077920,52.958286,2.697824,0.779200,-228.098312,0.078761,0.000000
57.050003,11.831390,-228.187286,0.008528,0.003081,0.078258,52.628654,2.681031,0.782584,-228.187286,0.079195,0.000000
57.310001,11.806442,-228.098312,0.008558,0.003093,0.078571,52.517677,2.675378,0.785706,-228.098312,0.079629,0.000000
57.570004,12.217545,-228.142792,0.008589,0.003116,0.079152,54.346352,2.768535,0.791516,-228.142792,0.080062,0.000000
57.830002,12.553047,-228.187286,0.008563,0.003135,0.079620,55.838741,2.844561,0.796198,-228.187286,0.080496,0.000000
58.090004,12.636459,-228.142792,0.008606,0.003153,0.080097,56.209778,2.863463,0.800967,-228.142792,0.080929,0.000000
58.350002,12.605927,-228.187286,0.008614,0.003169,0.080504,56.073963,2.856544,0.805043,-228.187286,0.081363,0.000000
58.610004,12.921326,-228.142792,0.008623,0.003187,0.080955,57.476929,2.928014,0.809555,-228.142792,0.081796,0.000000
58.870003,12.828232,-228.231766,0.008645,0.003199,0.081250,57.062824,2.906919,0.812503,-228.231766,0.082230,0.000000
59.130001,12.933617,-228.187286,0.008645,0.003214,0.081623,57.531601,2.930799,0.816232,-228.187286,0.082655,0.000000
59.390003,13.445625,-228.142792,0.008658,0.003235,0.082161,59.809128,3.046822,0.821610,-228.142792,0.083089,0.000000
59.650002,13.978493,-228.187286,0.008675,0.003256,0.082707,62.179440,3.167572,0.827071,-228.187286,0.083522,0.000000
59.910004,13.823959,-228.187286,0.008701,0.003269,0.083028,61.492043,3.132554,0.830281,-228.187286,0.083956,0.000000
60.170002,14.141960,-228.187286,0.008709,0.003288,0.083505,62.906582,3.204614,0.835050,-228.187286,0.084390,0.000000
60.430004,14.363899,-228.231766,0.008727,0.003305,0.083947,63.893814,3.254906,0.839475,-228.231766,0.084823,0.000000
60.690002,14.907188,-228.231766,0.008748,0.003325,0.084468,66.310486,3.378017,0.844675,-228.231766,0.085257,0.000000
60.950005,14.478958,-228.276245,0.008744,0.003333,0.084650,64.405624,3.280979,0.846499,-228.276245,0.085690,0.000000
61.210003,14.899368,-228.231766,0.008748,0.003351,0.085118,66.275703,3.376245,0.851181,-228.231766,0.086124,0.000000
61.470001,15.564423,-228.276245,0.008783,0.003373,0.085673,69.234009,3.526948,0.856730,-228.276245,0.086558,0.000000
61.730003,15.847427,-228.320724,0.008765,0.003390,0.086115,70.492874,3.591078,0.861154,-228.320724,0.086991,0.000000
61.990002,15.719330,-228.276245,0.008826,0.003404,0.086471,69.923073,3.562051,0.864708,-228.276245,0.087425,0.000000
62.250004,16.258530,-228.365204,0.008852,0.003422,0.086913,72.321548,3.684236,0.869133,-228.365204,0.087858,0.000000
62.510002,16.818947,-228.231766,0.008843,0.003443,0.087459,74.814415,3.811228,0.874595,-228.231766,0.088292,0.000000
62.770004,16.876663,-228.276245,0.008860,0.003457,0.087815,75.071144,3.824306,0.878152,-228.276245,0.088726,0.000000
63.030003,16.917999,-228.365204,0.008869,0.003470,0.088145,75.255020,3.833673,0.881445,-228.365204,0.089159,0.000000
63.290005,17.284042,-228.320724,0.008882,0.003486,0.088552,76.883263,3.916620,0.885522,-228.320724,0.089593,0.000000
63.550003,18.517342,-228.365204,0.008899,0.003513,0.089220,82.369247,4.196089,0.892202,-228.365204,0.090027,0.000000
63.810001,18.593300,-228.320724,0.008903,0.003528,0.089602,82.707130,4.213302,0.896017,-228.320724,0.090460,0.000000
64.070000,18.926949,-228.365204,0.008903,0.003544,0.090027,84.191269,4.288908,0.900268,-228.365204,0.090894,0.000000
64.330002,19.463913,-228.365204,0.008933,0.003563,0.090504,86.579811,4.410586,0.905037,-228.365204,0.091327,0.000000
64.590004,19.515671,-228.320724,0.008964,0.003575,0.090807,86.810036,4.422314,0.908072,-228.320724,0.091761,0.000000
64.850006,19.788620,-228.365204,0.008985,0.003590,0.091180,88.024178,4.484166,0.911800,-228.365204,0.092195,0.000000
65.110001,20.065292,-228.320724,0.008964,0.003604,0.091553,89.254875,4.546860,0.915528,-228.320724,0.092628,0.000000
65.370003,21.139961,-228.365204,0.009011,0.003628,0.092143,94.035248,4.790384,0.921425,-228.365204,0.093062,0.000000
65.630005,21.873901,-228.365204,0.009028,0.003647,0.092637,97.299973,4.956697,0.926368,-228.365204,0.093496,0.000000
65.889999,22.015404,-228.409683,0.009033,0.003660,0.092975,97.929405,4.988762,0.929752,-228.409683,0.093929,0.000000
66.150002,22.714722,-228.454163,0.009033,0.003679,0.093443,101.040131,5.147230,0.934434,-228.454163,0.094363,0.000000
66.410004,23.519417,-228.409683,0.009054,0.003699,0.093955,104.619591,5.329576,0.939551,-228.409683,0.094796,0.000000
66.670006,23.741356,-228.365204,0.009054,0.003713,0.094302,105.606827,5.379868,0.943022,-228.365204,0.095230,0.000000
66.930000,24.140160,-228.454163,0.009080,0.003729,0.094718,107.380791,5.470238,0.947181,-228.454163,0.095664,0.000000
67.190002,25.283348,-228.365204,0.009106,0.003751,0.095282,112.465950,5.729289,0.952821,-228.365204,0.096097,0.000000
67.450005,25.892174,-228.454163,0.009119,0.003767,0.095681,115.174141,5.867250,0.956810,-228.454163,0.096531,0.000000
67.710007,26.253380,-228.454163,0.009140,0.003782,0.096071,116.780869,5.949101,0.960712,-228.454163,0.096964,0.000000
67.970001,26.884552,-228.365204,0.009153,0.003801,0.096539,119.588463,6.092127,0.965394,-228.365204,0.097398,0.000000
68.230003,27.593170,-228.498642,0.009149,0.003817,0.096956,122.740555,6.252702,0.969558,-228.498642,0.097823,0.000000
68.490005,28.356537,-228.409683,0.009179,0.003833,0.097363,126.136177,6.425683,0.973634,-228.409683,0.098257,0.000000
68.750000,29.022339,-228.498642,0.009179,0.003849,0.097762,129.097809,6.576556,0.977623,-228.498642,0.098690,0.000000
69.010002,29.274437,-228.454163,0.009179,0.003860,0.098048,130.219193,6.633682,0.980485,-228.454163,0.099124,0.000000
69.270004,30.908401,-228.454163,0.009235,0.003888,0.098760,137.487442,7.003944,0.987596,-228.454163,0.099557,0.000000
69.530006,31.957748,-228.498642,0.009231,0.003906,0.099202,142.155167,7.241729,0.992017,-228.498642,0.099991,0.000000
69.790001,32.395287,-228.498642,0.009231,0.003919,0.099540,144.101425,7.340877,0.995401,-228.498642,0.100425,0.000000
70.050003,33.132584,-228.454163,0.009265,0.003935,0.099956,147.381088,7.507951,0.999564,-228.454163,0.100858,0.000000
70.310005,34.346519,-228.543121,0.009278,0.003956,0.100485,152.780945,7.783032,1.004852,-228.543121,0.101292,0.000000
70.570000,35.029823,-228.498642,0.009261,0.003971,0.100858,155.820435,7.937871,1.008584,-228.498642,0.101725,0.000000
70.830002,35.436455,-228.543121,0.009291,0.003982,0.101136,157.629227,8.030015,1.011358,-228.543121,0.102159,0.000000
71.090004,36.457497,-228.498642,0.009300,0.003999,0.101587,162.171051,8.261387,1.015866,-228.498642,0.102593,0.000000
71.350006,38.311913,-228.587601,0.009313,0.004023,0.102176,170.419891,8.681603,1.021763,-228.587601,0.103026,0.000000
71.610001,39.032829,-228.543121,0.009343,0.004037,0.102541,173.626694,8.844966,1.025408,-228.543121,0.103460,0.000000
71.870003,40.158134,-228.543121,0.009347,0.004055,0.103000,178.632309,9.099964,1.030002,-228.543121,0.103893,0.000000
72.130005,40.825058,-228.587601,0.009356,0.004069,0.103364,181.598923,9.251090,1.033643,-228.587601,0.104327,0.000000
72.390007,42.254967,-228.543121,0.009360,0.004090,0.103885,187.959473,9.575112,1.038848,-228.543121,0.104761,0.000000
72.650002,43.264839,-228.543121,0.009390,0.004103,0.104214,192.451614,9.803953,1.042144,-228.543121,0.105194,0.000000
72.910004,43.445068,-228.587601,0.009390,0.004108,0.104345,193.253311,9.844793,1.043446,-228.587601,0.105628,0.000000
73.170006,46.067688,-228.543121,0.009421,0.004142,0.105194,204.919312,10.439088,1.051943,-228.543121,0.106061,0.000000
73.430000,47.050377,-228.543121,0.009421,0.004157,0.105576,209.290527,10.661768,1.055759,-228.543121,0.106495,0.000000
73.690002,48.303040,-228.632095,0.009421,0.004174,0.106010,214.862656,10.945625,1.060096,-228.632095,0.106929,0.000000
73.950005,49.456650,-228.632095,0.009455,0.004189,0.106400,219.994171,11.207037,1.063998,-228.632095,0.107362,0.000000
74.210007,50.784531,-228.632095,0.009442,0.004209,0.106920,225.900879,11.507939,1.069203,-228.632095,0.107796,0.000000
74.470001,52.084106,-228.676575,0.009468,0.004225,0.107319,231.681671,11.802427,1.073192,-228.676575,0.108229,0.000000
74.730003,53.035896,-228.587601,0.009477,0.004239,0.107666,235.915451,12.018106,1.076659,-228.587601,0.108663,0.000000
74.990005,54.885841,-228.676575,0.009511,0.004260,0.108204,244.144409,12.437310,1.082037,-228.676575,0.109097,0.000000
75.250000,56.169411,-228.676575,0.009533,0.004277,0.108646,249.854019,12.728170,1.086458,-228.676575,0.109530,0.000000
75.510002,57.040016,-228.676575,0.009541,0.004290,0.108967,253.726669,12.925452,1.089667,-228.676575,0.109964,0.000000
75.770004,58.488174,-228.632095,0.009546,0.004307,0.109409,260.168396,13.253610,1.094092,-228.632095,0.110398,0.000000
76.030006,60.001495,-228.676575,0.009567,0.004327,0.109895,266.899994,13.596533,1.098948,-228.676575,0.110831,0.000000
76.290001,61.396400,-228.721054,0.009563,0.004342,0.110285,273.104828,13.912623,1.102850,-228.721054,0.111265,0.000000
76.550003,62.382446,-228.676575,0.009563,0.004355,0.110623,277.490967,14.136065,1.106230,-228.676575,0.111699,0.000000
76.810005,64.009712,-228.765533,0.009585,0.004374,0.111109,284.729431,14.504808,1.111090,-228.765533,0.112132,0.000000
77.070007,66.177284,-228.632095,0.009623,0.004398,0.111707,294.371277,14.995987,1.117074,-228.632095,0.112557,0.000000
77.330002,67.442238,-228.721054,0.009641,0.004413,0.112080,299.998047,15.282630,1.120802,-228.721054,0.112991,0.000000
77.590004,67.116035,-228.721054,0.009641,0.004405,0.111898,298.547028,15.208712,1.118981,-228.721054,0.112080,0.000000
77.850006,66.801384,-228.676575,0.009645,0.004405,0.111889,297.147400,15.137410,1.118894,-228.676575,0.111889,0.000000
78.110001,66.518761,-228.721054,0.009666,0.004405,0.111881,295.890228,15.073366,1.118807,-228.721054,0.111889,0.000000
78.370003,66.271873,-228.676575,0.009632,0.004405,0.111881,294.792023,15.017421,1.118807,-228.676575,0.111889,0.000000
78.630005,66.073769,-228.721054,0.009662,0.004404,0.111872,293.910797,14.972530,1.118720,-228.721054,0.111889,0.000000
78.890007,65.886101,-228.765533,0.009662,0.004404,0.111872,293.076019,14.930004,1.118720,-228.765533,0.111889,0.000000
79.150002,65.711830,-228.721054,0.009666,0.004404,0.111872,292.300812,14.890513,1.118720,-228.721054,0.111889,0.000000
79.410004,65.564369,-228.765533,0.009671,0.004404,0.111872,291.644867,14.857099,1.118720,-228.765533,0.111889,0.000000
79.670006,65.420631,-228.810013,0.009666,0.004404,0.111872,291.005493,14.824528,1.118720,-228.810013,0.111889,0.000000
79.930000,65.285454,-228.765533,0.009671,0.004404,0.111872,290.404205,14.793895,1.118720,-228.765533,0.111889,0.000000
80.190002,65.177101,-228.854492,0.009662,0.004404,0.111863,289.922211,14.769342,1.118633,-228.854492,0.111889,0.000000
80.450005,65.071342,-228.765533,0.009653,0.004404,0.111863,289.451782,14.745378,1.118633,-228.765533,0.111889,0.000000
80.710007,64.958519,-228.854492,0.009671,0.004404,0.111863,288.949921,14.719810,1.118633,-228.854492,0.111889,0.000000
80.970001,64.859459,-228.765533,0.009679,0.004404,0.111863,288.509277,14.697364,1.118633,-228.765533,0.111889,0.000000
81.230003,64.784248,-228.810013,0.009692,0.004404,0.111863,288.174744,14.680321,1.118633,-228.810013,0.111889,0.000000
81.490005,64.678871,-228.854492,0.009675,0.004404,0.111863,287.705994,14.656442,1.118633,-228.854492,0.111889,0.000000
81.750008,64.605873,-228.854492,0.009679,0.004404,0.111863,287.381287,14.639900,1.118633,-228.854492,0.111889,0.000000
82.010002,64.536247,-228.987930,0.009679,0.004404,0.111863,287.071564,14.624123,1.118633,-228.987930,0.111889,0.000000
82.270004,64.450233,-228.854492,0.009653,0.004404,0.111863,286.688965,14.604631,1.118633,-228.854492,0.111889,0.000000
82.530006,64.398094,-228.898972,0.009658,0.004404,0.111863,286.457031,14.592816,1.118633,-228.898972,0.111889,0.000000
82.790001,64.326607,-228.898972,0.009688,0.004404,0.111863,286.139038,14.576617,1.118633,-228.898972,0.111889,0.000000
83.050003,64.249519,-228.810013,0.009679,0.004404,0.111863,285.796143,14.559149,1.118633,-228.810013,0.111889,0.000000
83.310005,64.198128,-228.943451,0.009675,0.004404,0.111863,285.567535,14.547503,1.118633,-228.943451,0.111889,0.000000
83.570007,64.141151,-228.810013,0.009684,0.004404,0.111863,285.314087,14.534593,1.118633,-228.810013,0.111889,0.000000
83.830002,64.083061,-228.898972,0.009705,0.004404,0.111863,285.055695,14.521429,1.118633,-228.898972,0.111889,0.000000
84.090004,64.032051,-228.898972,0.009662,0.004404,0.111863,284.828796,14.509871,1.118633,-228.898972,0.111889,0.000000
84.350006,63.986244,-228.943451,0.009684,0.004404,0.111863,284.625031,14.499491,1.118633,-228.943451,0.111889,0.000000
84.610001,63.938591,-228.943451,0.009701,0.004404,0.111863,284.413055,14.488691,1.118633,-228.943451,0.111889,0.000000
84.870003,63.877144,-228.943451,0.009688,0.004404,0.111863,284.139740,14.474768,1.118633,-228.943451,0.111889,0.000000
85.130005,63.843636,-228.898972,0.009684,0.004404,0.111863,283.990662,14.467175,1.118633,-228.898972,0.111889,0.000000
85.390007,63.794472,-229.032410,0.009692,0.004404,0.111863,283.771973,14.456034,1.118633,-229.032410,0.111889,0.000000
85.650002,63.758736,-228.943451,0.009688,0.004404,0.111863,283.613007,14.447936,1.118633,-228.943451,0.111889,0.000000
85.910004,63.706230,-229.032410,0.009684,0.004404,0.111863,283.379456,14.436038,1.118633,-229.032410,0.111889,0.000000
86.170006,63.676811,-229.076904,0.009701,0.004404,0.111863,283.248596,14.429371,1.118633,-229.076904,0.111889,0.000000
86.430000,63.632866,-228.987930,0.009705,0.004404,0.111863,283.053131,14.419414,1.118633,-228.987930,0.111889,0.000000
86.690002,63.586693,-229.032410,0.009671,0.004404,0.111863,282.847748,14.408951,1.118633,-229.032410,0.111889,0.000000
86.950005,63.569191,-228.987930,0.009684,0.004404,0.111863,282.769897,14.404984,1.118633,-228.987930,0.111889,0.000000
87.210007,63.517433,-229.032410,0.009675,0.004404,0.111863,282.539642,14.393256,1.118633,-229.032410,0.111889,0.000000
87.470001,63.467171,-228.987930,0.009697,0.004404,0.111863,282.316071,14.381866,1.118633,-228.987930,0.111889,0.000000
87.730003,63.473869,-229.032410,0.009684,0.004404,0.111863,282.345886,14.383385,1.118633,-229.032410,0.111889,0.000000
87.990005,63.417641,-229.076904,0.009697,0.004404,0.111863,282.095764,14.370643,1.118633,-229.076904,0.111889,0.000000
88.250008,63.391197,-228.987930,0.009688,0.004404,0.111863,281.978119,14.364651,1.118633,-228.987930,0.111889,0.000000
88.510002,63.348747,-229.032410,0.009688,0.004404,0.111863,281.789307,14.355031,1.118633,-229.032410,0.111889,0.000000
88.770004,63.317467,-228.987930,0.009701,0.004404,0.111863,281.650146,14.347943,1.118633,-228.987930,0.111889,0.000000
89.030006,63.294762,-229.032410,0.009679,0.004404,0.111863,281.549164,14.342797,1.118633,-229.032410,0.111889,0.000000
89.290001,63.265709,-229.121384,0.009697,0.004404,0.111863,281.419922,14.336215,1.118633,-229.121384,0.111889,0.000000
89.550003,63.232201,-229.076904,0.009679,0.004404,0.111863,281.270874,14.328622,1.118633,-229.076904,0.111889,0.000000
89.810005,63.198677,-229.032410,0.009701,0.004404,0.111863,281.121765,14.321025,1.118633,-229.032410,0.111889,0.000000
90.070007,63.178581,-229.076904,0.009697,0.004404,0.111863,281.032379,14.316471,1.118633,-229.076904,0.111889,0.000000
90.330002,63.155861,-229.032410,0.009679,0.004404,0.111863,280.931305,14.311323,1.118633,-229.032410,0.111889,0.000000
90.590004,63.125694,-229.121384,0.009727,0.004404,0.111863,280.797119,14.304487,1.118633,-229.121384,0.111889,0.000000
90.850006,63.087349,-229.121384,0.009692,0.004404,0.111863,280.626556,14.295797,1.118633,-229.121384,0.111889,0.000000
91.110001,63.078407,-229.121384,0.009697,0.004404,0.111863,280.586761,14.293772,1.118633,-229.121384,0.111889,0.000000
91.370003,63.042656,-229.165863,0.009705,0.004404,0.111863,280.427734,14.285670,1.118633,-229.165863,0.111889,0.000000
91.630005,63.020691,-229.121384,0.009705,0.004404,0.111863,280.330048,14.280692,1.118633,-229.121384,0.111889,0.000000
91.890007,62.993134,-229.254822,0.009671,0.004404,0.111855,280.207458,14.274448,1.118546,-229.254822,0.111889,0.000000
92.150002,62.981964,-229.121384,0.009710,0.004404,0.111855,280.157776,14.271917,1.118546,-229.121384,0.111889,0.000000
92.410004,62.942863,-229.121384,0.009727,0.004404,0.111855,279.983826,14.263057,1.118546,-229.121384,0.111889,0.000000
92.670006,62.938393,-229.165863,0.009692,0.004404,0.111855,279.963959,14.262044,1.118546,-229.165863,0.111889,0.000000
92.930008,62.920151,-229.165863,0.009697,0.004404,0.111855,279.882812,14.257910,1.118546,-229.165863,0.111889,0.000000
93.190002,62.874718,-229.210342,0.009701,0.004404,0.111855,279.680725,14.247614,1.118546,-229.210342,0.111889,0.000000
93.450005,62.864662,-229.165863,0.009688,0.004404,0.111855,279.635986,14.245337,1.118546,-229.165863,0.111889,0.000000
93.710007,62.853493,-229.210342,0.009692,0.004404,0.111855,279.586304,14.242805,1.118546,-229.210342,0.111889,0.000000
93.970001,62.819977,-229.210342,0.009688,0.004404,0.111855,279.437225,14.235210,1.118546,-229.210342,0.111889,0.000000
94.230003,62.803970,-229.210342,0.009679,0.004404,0.111855,279.366028,14.231584,1.118546,-229.210342,0.111889,0.000000
94.490005,62.780136,-229.254822,0.009692,0.004404,0.111855,279.259979,14.226182,1.118546,-229.254822,0.111889,0.000000
94.750008,62.762634,-229.210342,0.009679,0.004404,0.111855,279.182129,14.222217,1.118546,-229.210342,0.111889,0.000000
95.010002,62.736198,-229.165863,0.009705,0.004404,0.111855,279.064545,14.216226,1.118546,-229.165863,0.111889,0.000000
95.270004,62.722794,-229.210342,0.009692,0.004404,0.111855,279.004913,14.213188,1.118546,-229.210342,0.111889,0.000000
95.530006,62.704544,-229.254822,0.009714,0.004404,0.111855,278.923737,14.209053,1.118546,-229.254822,0.111889,0.000000
95.790001,62.674759,-229.299301,0.009701,0.004404,0.111855,278.791260,14.202304,1.118546,-229.299301,0.111889,0.000000
96.050003,62.659859,-229.254822,0.009705,0.004404,0.111855,278.724976,14.198927,1.118546,-229.254822,0.111889,0.000000
96.310005,62.652412,-229.254822,0.009697,0.004404,0.111855,278.691864,14.197240,1.118546,-229.254822,0.111889,0.000000
96.570007,62.616669,-229.343781,0.009692,0.004404,0.111855,278.532867,14.189140,1.118546,-229.343781,0.111889,0.000000
96.830002,62.606613,-229.210342,0.009722,0.004404,0.111855,278.488129,14.186861,1.118546,-229.210342,0.111889,0.000000
97.090004,62.591713,-229.343781,0.009710,0.004404,0.111855,278.421844,14.183485,1.118546,-229.343781,0.111889,0.000000
97.350006,62.573097,-229.299301,0.009731,0.004404,0.111855,278.339050,14.179267,1.118546,-229.299301,0.111889,0.000000
97.610008,62.555222,-229.343781,0.009697,0.004404,0.111855,278.259521,14.175216,1.118546,-229.343781,0.111889,0.000000
97.870003,62.553734,-229.343781,0.009705,0.004404,0.111855,278.252899,14.174879,1.118546,-229.343781,0.111889,0.000000
98.130005,62.533257,-229.299301,0.009705,0.004404,0.111855,278.161804,14.170238,1.118546,-229.299301,0.111889,0.000000
98.390007,62.495644,-229.388260,0.009692,0.004404,0.111855,277.994507,14.161716,1.118546,-229.388260,0.111889,0.000000
98.650002,62.501602,-229.343781,0.009688,0.004404,0.111855,278.021027,14.163065,1.118546,-229.343781,0.111889,0.000000
98.910004,62.479630,-229.343781,0.009675,0.004404,0.111855,277.923279,14.158087,1.118546,-229.343781,0.111889,0.000000
99.170006,62.455429,-229.388260,0.009679,0.004404,0.111855,277.815613,14.152602,1.118546,-229.388260,0.111889,0.000000
99.430008,62.453568,-229.299301,0.009692,0.004404,0.111855,277.807343,14.152181,1.118546,-229.299301,0.111889,0.000000
99.690002,62.442024,-229.388260,0.009679,0.004404,0.111855,277.755981,14.149565,1.118546,-229.388260,0.111889,0.000000
99.950005,62.413353,-229.343781,0.009684,0.004404,0.111855,277.628448,14.143068,1.118546,-229.343781,0.111889,0.000000
100.210007,62.408134,-229.388260,0.009718,0.004404,0.111855,277.605255,14.141885,1.118546,-229.388260,0.111889,0.000000
100.470001,62.396217,-229.432739,0.009710,0.004404,0.111855,277.552246,14.139185,1.118546,-229.432739,0.111889,0.000000
100.730003,62.395477,-229.388260,0.009697,0.004404,0.111855,277.548950,14.139017,1.118546,-229.388260,0.111889,0.000000
100.990005,62.356377,-229.432739,0.009714,0.004404,0.111855,277.375031,14.130157,1.118546,-229.432739,0.111889,0.000000
101.250008,62.361588,-229.388260,0.009727,0.004404,0.111855,277.398193,14.131338,1.118546,-229.388260,0.111889,0.000000
101.510002,62.342972,-229.432739,0.009710,0.004404,0.111855,277.315399,14.127119,1.118546,-229.432739,0.111889,0.000000
101.770004,62.323982,-229.477234,0.009692,0.004404,0.111855,277.230927,14.122816,1.118546,-229.477234,0.111889,0.000000
102.030006,62.322861,-229.432739,0.009701,0.004404,0.111855,277.225922,14.122561,1.118546,-229.432739,0.111889,0.000000
102.290009,62.301636,-229.477234,0.009705,0.004404,0.111855,277.131531,14.117752,1.118546,-229.477234,0.111889,0.000000
102.550003,62.282646,-229.477234,0.009714,0.004404,0.111855,277.047058,14.113449,1.118546,-229.477234,0.111889,0.000000
102.810005,62.283394,-229.432739,0.009710,0.004404,0.111855,277.050385,14.113619,1.118546,-229.432739,0.111889,0.000000
103.070007,62.256210,-229.521713,0.009705,0.004404,0.111855,276.929443,14.107459,1.118546,-229.521713,0.111889,0.000000
103.330002,62.254723,-229.432739,0.009710,0.004404,0.111855,276.922852,14.107122,1.118546,-229.432739,0.111889,0.000000
103.590004,62.244293,-229.521713,0.009714,0.004404,0.111855,276.876434,14.104758,1.118546,-229.521713,0.111889,0.000000
103.850006,62.233124,-229.521713,0.009710,0.004404,0.111855,276.826752,14.102227,1.118546,-229.521713,0.111889,0.000000
104.110008,62.213013,-229.521713,0.009705,0.004404,0.111855,276.737305,14.097671,1.118546,-229.521713,0.111889,0.000000
104.370003,62.195511,-229.521713,0.009705,0.004404,0.111855,276.659454,14.093704,1.118546,-229.521713,0.111889,0.000000
104.630005,62.198494,-229.477234,0.009714,0.004404,0.111855,276.672729,14.094380,1.118546,-229.477234,0.111889,0.000000
104.890007,62.164230,-229.566193,0.009718,0.004404,0.111855,276.520294,14.086616,1.118546,-229.566193,0.111889,0.000000
105.150002,62.162369,-229.521713,0.009710,0.004404,0.111855,276.512024,14.086194,1.118546,-229.521713,0.111889,0.000000
105.410004,62.153061,-229.566193,0.009701,0.004404,0.111855,276.470612,14.084085,1.118546,-229.566193,0.111889,0.000000
105.670006,62.150085,-229.566193,0.009701,0.004404,0.111855,276.457397,14.083411,1.118546,-229.566193,0.111889,0.000000
105.930008,62.125877,-229.610672,0.009714,0.004404,0.111855,276.349701,14.077925,1.118546,-229.610672,0.111889,0.000000
106.190002,62.118431,-229.610672,0.009679,0.004404,0.111855,276.316589,14.076238,1.118546,-229.610672,0.111889,0.000000
106.450005,62.121040,-229.566193,0.009688,0.004404,0.111855,276.328186,14.076829,1.118546,-229.566193,0.111889,0.000000
106.710007,62.110237,-229.610672,0.009701,0.004404,0.111855,276.280121,14.074381,1.118546,-229.610672,0.111889,0.000000
106.970009,62.093109,-229.610672,0.009714,0.004404,0.111855,276.203949,14.070499,1.118546,-229.610672,0.111889,0.000000
107.230003,62.080452,-229.566193,0.009697,0.004404,0.111855,276.147644,14.067632,1.118546,-229.566193,0.111889,0.000000
107.490005,62.061455,-229.610672,0.009710,0.004404,0.111855,276.063141,14.063327,1.118546,-229.610672,0.111889,0.000000
107.750008,62.052895,-229.610672,0.009692,0.004404,0.111855,276.025055,14.061387,1.118546,-229.610672,0.111889,0.000000
107.800003,62.052895,-229.566193,0.009701,0.004404,0.111855,276.025055,14.061387,1.118546,-229.566193,0.111889,0.000000