File: Data/Automembrane/AutoHeating-17wt-1-2_12152023_163546.csv
Time (sec),S:Load (lbs),S:HL1 (DIM),S:LVDT (in),S:Position (in),Ch:Position (mm),Ch:Load (N),Ch:Stress (MPa),Ch:Strain (mm/mm),Ch:HL1 (DIM),Set Point (),Cycles ()
0.110000,-0.009682,-98.080498,0.000022,-0.000000,-0.000000,-0.043066,-0.002194,-0.000000,-98.080498,0.000260,0.000000
0.340000,-0.010422,-98.080498,-0.000009,-0.000000,-0.000000,-0.046358,-0.002362,-0.000000,-98.080498,0.000260,0.000000
0.570000,-0.016380,-98.124977,0.000026,0.000121,0.003061,-0.072863,-0.003712,0.030612,-98.124977,0.004076,0.000000
0.800000,-0.030159,-98.124977,0.000082,0.000268,0.006808,-0.134154,-0.006834,0.068079,-98.124977,0.007909,0.000000
1.030000,-0.034630,-98.124977,0.000289,0.000422,0.010719,-0.154041,-0.007847,0.107188,-98.124977,0.011742,0.000000
1.260000,-0.085274,-98.080498,0.000423,0.000571,0.014509,-0.379317,-0.019323,0.145086,-98.080498,0.015576,0.000000
1.490000,-0.027924,-98.124977,0.000599,0.000719,0.018273,-0.124210,-0.006328,0.182727,-98.124977,0.019409,0.000000
1.720000,-0.015640,-98.169456,0.000720,0.000872,0.022140,-0.069571,-0.003544,0.221405,-98.169456,0.023242,0.000000
1.950000,0.021973,-98.169456,0.000901,0.001018,0.025852,0.097739,0.004979,0.258520,-98.169456,0.027075,0.000000
2.180000,0.000374,-98.124977,0.001043,0.001172,0.029772,0.001663,0.000085,0.297720,-98.124977,0.030908,0.000000
2.410000,-0.042076,-98.169456,0.001233,0.001326,0.033675,-0.187164,-0.009535,0.336746,-98.169456,0.034741,0.000000
2.640000,-0.027184,-98.213943,0.001371,0.001472,0.037395,-0.120918,-0.006160,0.373948,-98.213943,0.038574,0.000000
2.870000,-0.011169,-98.213943,0.001518,0.001632,0.041445,-0.049684,-0.002531,0.414450,-98.213943,0.042407,0.000000
3.100000,-0.003349,-98.124977,0.001673,0.001773,0.045027,-0.014898,-0.000759,0.450266,-98.124977,0.046223,0.000000
3.330000,-0.028297,-98.124977,0.001858,0.001924,0.048868,-0.125873,-0.006412,0.488683,-98.124977,0.050056,0.000000
3.560000,0.001488,-98.169456,0.001992,0.002082,0.052884,0.006618,0.000337,0.528837,-98.169456,0.053889,0.000000
3.790000,-0.030159,-98.213943,0.002177,0.002231,0.056656,-0.134154,-0.006834,0.566561,-98.213943,0.057723,0.000000
4.020000,-0.017128,-98.213943,0.002311,0.002382,0.060506,-0.076189,-0.003881,0.605065,-98.213943,0.061556,0.000000
4.250000,-0.016754,-98.169456,0.002475,0.002531,0.064296,-0.074526,-0.003797,0.642963,-98.169456,0.065389,0.000000
4.480000,0.012291,-98.213943,0.002617,0.002680,0.068060,0.054673,0.002785,0.680600,-98.213943,0.069222,0.000000
4.710000,-0.014519,-98.169456,0.002790,0.002835,0.072014,-0.064583,-0.003290,0.720144,-98.169456,0.073055,0.000000
4.940000,-0.037979,-98.213943,0.002971,0.002985,0.075813,-0.168940,-0.008606,0.758130,-98.213943,0.076888,0.000000
5.170000,-0.041328,-98.258423,0.003130,0.003134,0.079603,-0.183838,-0.009365,0.796028,-98.258423,0.080722,0.000000
5.400000,-0.018242,-98.258423,0.003285,0.003288,0.083505,-0.081144,-0.004134,0.835054,-98.258423,0.084555,0.000000
5.630000,0.025696,-98.213943,0.003441,0.003431,0.087156,0.114301,0.005823,0.871563,-98.213943,0.088388,0.000000
5.860000,0.015640,-98.213943,0.003574,0.003589,0.091172,0.069571,0.003544,0.911717,-98.213943,0.092203,0.000000
6.090000,-0.016754,-98.258423,0.003768,0.003743,0.095083,-0.074526,-0.003797,0.950826,-98.258423,0.096037,0.000000
6.320000,-0.030907,-98.302902,0.003919,0.003890,0.098803,-0.137480,-0.007004,0.988032,-98.302902,0.099870,0.000000
6.550000,-0.007072,-98.302902,0.004061,0.004042,0.102662,-0.031460,-0.001603,1.026623,-98.302902,0.103703,0.000000
6.780000,0.012291,-98.258423,0.004208,0.004187,0.106348,0.054673,0.002785,1.063480,-98.258423,0.107536,0.000000
7.010000,-0.001488,-98.347382,0.004376,0.004341,0.110268,-0.006618,-0.000337,1.102680,-98.347382,0.111369,0.000000
7.240000,-0.017876,-98.302902,0.004540,0.004496,0.114205,-0.079515,-0.004051,1.142050,-98.302902,0.115202,0.000000
7.470000,-0.056602,-98.347382,0.004682,0.004643,0.117926,-0.251780,-0.012826,1.179256,-98.347382,0.119035,0.000000
7.700000,-0.017876,-98.347382,0.004846,0.004793,0.121732,-0.079515,-0.004051,1.217324,-98.347382,0.122869,0.000000
7.930000,0.033142,-98.302902,0.005014,0.004946,0.125618,0.147423,0.007510,1.256176,-98.302902,0.126702,0.000000
8.160001,0.160866,-98.391861,0.005178,0.005089,0.129269,0.715567,0.036453,1.292689,-98.391861,0.130535,0.000000
8.390000,0.529144,-98.347382,0.005351,0.005250,0.133362,2.353751,0.119906,1.333619,-98.347382,0.134368,0.000000
8.620001,0.580902,-98.391861,0.005415,-0.000004,-0.000113,2.583982,0.131634,-0.001128,-98.391861,0.000095,0.000000
8.850000,0.519089,-98.347382,0.005385,-0.000004,-0.000113,2.309022,0.117627,-0.001128,-98.347382,0.000095,0.000000
9.080001,0.440147,-98.302902,0.005394,-0.000005,-0.000121,1.957873,0.099739,-0.001215,-98.302902,0.000165,0.000000
9.310000,0.493019,-98.347382,0.005428,-0.000004,-0.000113,2.193058,0.111720,-0.001128,-98.347382,0.000546,0.000000
9.540001,0.456902,-98.347382,0.005398,-0.000004,-0.000113,2.032400,0.103535,-0.001128,-98.347382,0.000936,0.000000
9.770000,0.588348,-98.436348,0.005428,0.000018,0.000468,2.617104,0.133322,0.004682,-98.436348,0.001318,0.000000
10.000000,0.672882,-98.436348,0.005402,0.000031,0.000798,2.993129,0.152477,0.007979,-98.436348,0.001700,0.000000
10.230000,0.771927,-98.436348,0.005450,0.000048,0.001223,3.433702,0.174921,0.012229,-98.436348,0.002081,0.000000
10.460000,0.843422,-98.391861,0.005480,0.000065,0.001639,3.751728,0.191122,0.016389,-98.391861,0.002463,0.000000
10.690001,0.915291,-98.436348,0.005467,0.000079,0.002003,4.071417,0.207408,0.020033,-98.436348,0.002853,0.000000
10.920000,0.957001,-98.480827,0.005476,0.000094,0.002385,4.256952,0.216859,0.023849,-98.480827,0.003235,0.000000
11.150001,1.045624,-98.436348,0.005510,0.000111,0.002819,4.651167,0.236942,0.028186,-98.436348,0.003616,0.000000
11.380000,1.089935,-98.480827,0.005519,0.000123,0.003113,4.848274,0.246983,0.031135,-98.480827,0.003998,0.000000
11.610001,1.225853,-98.436348,0.005527,0.000141,0.003573,5.452867,0.277782,0.035729,-98.436348,0.004380,0.000000
11.840000,1.301819,-98.480827,0.005545,0.000152,0.003868,5.790780,0.294996,0.038678,-98.480827,0.004770,0.000000
12.070001,1.349106,-98.525307,0.005553,0.000162,0.004119,6.001122,0.305712,0.041191,-98.525307,0.005151,0.000000
12.300000,1.562103,-98.525307,0.005570,0.000185,0.004692,6.948582,0.353978,0.046918,-98.525307,0.005533,0.000000
12.530001,1.668976,-98.525307,0.005601,0.000202,0.005125,7.423975,0.378195,0.051251,-98.525307,0.005914,0.000000
12.760000,1.765793,-98.436348,0.005605,0.000213,0.005412,7.854639,0.400134,0.054116,-98.436348,0.006296,0.000000
12.990001,1.851440,-98.480827,0.005627,0.000227,0.005776,8.235619,0.419542,0.057757,-98.480827,0.006686,0.000000
13.220000,1.920326,-98.480827,0.005635,0.000238,0.006053,8.542038,0.435152,0.060532,-98.480827,0.007068,0.000000
13.450001,2.118431,-98.569786,0.005648,0.000254,0.006461,9.423252,0.480043,0.064608,-98.569786,0.007449,0.000000
13.680000,2.290092,-98.525307,0.005657,0.000273,0.006929,10.186840,0.518942,0.069290,-98.525307,0.007831,0.000000
13.910001,2.248016,-98.525307,0.005670,0.000281,0.007128,9.999676,0.509408,0.071285,-98.525307,0.008221,0.000000
14.140000,2.586876,-98.525307,0.005713,0.000301,0.007658,11.506999,0.586194,0.076576,-98.525307,0.008603,0.000000
14.370001,2.825188,-98.614265,0.005713,0.000319,0.008100,12.567062,0.640197,0.080997,-98.614265,0.008985,0.000000
14.600000,2.927963,-98.614265,0.005708,0.000336,0.008533,13.024231,0.663486,0.085334,-98.614265,0.009366,0.000000
14.830001,3.053459,-98.569786,0.005730,0.000349,0.008854,13.582465,0.691924,0.088544,-98.569786,0.009748,0.000000
15.060000,3.173363,-98.569786,0.005752,0.000362,0.009201,14.115823,0.719094,0.092011,-98.569786,0.010138,0.000000
15.290001,3.327896,-98.569786,0.005764,0.000375,0.009513,14.803222,0.754112,0.095133,-98.569786,0.010519,0.000000
15.520000,3.527115,-98.569786,0.005782,0.000391,0.009938,15.689390,0.799256,0.099384,-98.569786,0.010901,0.000000
15.750001,3.584084,-98.658752,0.005803,0.000404,0.010268,15.942800,0.812165,0.102680,-98.658752,0.011282,0.000000
15.980000,3.844002,-98.658752,0.005808,0.000420,0.010676,17.098974,0.871063,0.106757,-98.658752,0.011664,0.000000
16.210001,4.083435,-98.569786,0.005825,0.000441,0.011204,18.164026,0.925320,0.112044,-98.569786,0.012055,0.000000
16.440001,4.160522,-98.614265,0.005851,0.000455,0.011569,18.506927,0.942788,0.115689,-98.614265,0.012436,0.000000
16.670000,4.326973,-98.614265,0.005851,0.000472,0.011985,19.247337,0.980506,0.119849,-98.614265,0.012818,0.000000
16.900002,4.364578,-98.658752,0.005859,0.000484,0.012306,19.414614,0.989028,0.123058,-98.658752,0.013199,0.000000
17.130001,4.577576,-98.658752,0.005885,0.000503,0.012774,20.362074,1.037293,0.127740,-98.658752,0.013581,0.000000
17.360001,4.660240,-98.658752,0.005898,0.000517,0.013121,20.729784,1.056026,0.131211,-98.658752,0.013971,0.000000
17.590000,4.751099,-98.614265,0.005894,0.000529,0.013442,21.133942,1.076614,0.134421,-98.614265,0.014353,0.000000
17.820002,4.667320,-98.658752,0.005941,0.000537,0.013633,20.761278,1.057630,0.136328,-98.658752,0.014734,0.000000
18.050001,5.084000,-98.658752,0.005946,0.000560,0.014231,22.614759,1.152051,0.142312,-98.658752,0.015116,0.000000
18.280001,5.164810,-98.703232,0.005950,0.000574,0.014587,22.974222,1.170363,0.145866,-98.703232,0.015497,0.000000
18.510000,5.187523,-98.703232,0.005976,0.000586,0.014890,23.075254,1.175509,0.148902,-98.703232,0.015887,0.000000
18.740002,5.433289,-98.658752,0.005993,0.000605,0.015358,24.168474,1.231201,0.153583,-98.658752,0.016269,0.000000
18.970001,5.618355,-98.747711,0.006019,0.000620,0.015757,24.991690,1.273137,0.157573,-98.747711,0.016651,0.000000
19.200001,5.916626,-98.703232,0.006032,0.000639,0.016235,26.318466,1.340727,0.162345,-98.703232,0.017032,0.000000
19.430000,5.889442,-98.792191,0.006023,0.000651,0.016547,26.197548,1.334567,0.165468,-98.792191,0.017414,0.000000
19.660002,5.855934,-98.747711,0.006032,0.000660,0.016755,26.048496,1.326974,0.167546,-98.747711,0.017804,0.000000
19.890001,6.016792,-98.614265,0.006058,0.000673,0.017093,26.764029,1.363425,0.170930,-98.614265,0.018186,0.000000
20.120001,6.452469,-98.703232,0.006084,0.000695,0.017657,28.702015,1.462150,0.176565,-98.703232,0.018567,0.000000
20.350000,6.703819,-98.703232,0.006096,0.000713,0.018108,29.820078,1.519107,0.181077,-98.703232,0.018949,0.000000
20.580002,6.641640,-98.792191,0.006105,0.000723,0.018376,29.543489,1.505017,0.183764,-98.792191,0.019331,0.000000
20.810001,6.865059,-98.792191,0.006118,0.000742,0.018845,30.537308,1.555645,0.188446,-98.792191,0.019721,0.000000
21.040001,6.945862,-98.703232,0.006114,0.000754,0.019157,30.896736,1.573955,0.191569,-98.703232,0.020102,0.000000
21.270000,7.367760,-98.747711,0.006148,0.000774,0.019651,32.773434,1.669558,0.196512,-98.747711,0.020484,0.000000
21.500002,7.210251,-98.836670,0.006161,0.000779,0.019781,32.072796,1.633866,0.197814,-98.836670,0.020865,0.000000
21.730001,7.498466,-98.792191,0.006165,0.000795,0.020189,33.354843,1.699177,0.201890,-98.792191,0.021247,0.000000
21.960001,7.630287,-98.836670,0.006174,0.000810,0.020571,33.941212,1.729048,0.205705,-98.836670,0.021637,0.000000
22.190001,8.303535,-98.792191,0.006200,0.000832,0.021134,36.935970,1.881608,0.211341,-98.792191,0.022019,0.000000
22.420002,8.238373,-98.792191,0.006226,0.000843,0.021403,36.646114,1.866842,0.214032,-98.792191,0.022401,0.000000
22.650002,8.681496,-98.836670,0.006217,0.000864,0.021941,38.617222,1.967255,0.219407,-98.836670,0.022782,0.000000
22.880001,8.782776,-98.836670,0.006239,0.000875,0.022235,39.067738,1.990205,0.222355,-98.836670,0.023172,0.000000
23.110001,8.917206,-98.925636,0.006239,0.000890,0.022617,39.665714,2.020668,0.226174,-98.925636,0.023554,0.000000
23.340002,9.110840,-98.881157,0.006252,0.000903,0.022947,40.527039,2.064546,0.229467,-98.881157,0.023935,0.000000
23.570002,9.379692,-98.792191,0.006269,0.000917,0.023294,41.722954,2.125468,0.232938,-98.792191,0.024317,0.000000
23.800001,9.502571,-98.881157,0.006291,0.000928,0.023580,42.269547,2.153313,0.235799,-98.881157,0.024699,0.000000
24.030001,10.025383,-98.925636,0.006291,0.000947,0.024057,44.595131,2.271784,0.240568,-98.925636,0.025089,0.000000
24.260000,10.502022,-98.925636,0.006316,0.000970,0.024629,46.715324,2.379792,0.246291,-98.925636,0.025470,0.000000
24.490002,10.363129,-98.925636,0.006334,0.000980,0.024898,46.097500,2.348319,0.248982,-98.925636,0.025852,0.000000
24.720001,10.664375,-98.792191,0.006329,0.000999,0.025366,47.437511,2.416582,0.253664,-98.792191,0.026233,0.000000
24.950001,10.831573,-98.925636,0.006338,0.001013,0.025730,48.181244,2.454470,0.257305,-98.925636,0.026615,0.000000
25.180000,11.279533,-98.925636,0.006368,0.001030,0.026164,50.173870,2.555979,0.261642,-98.925636,0.027005,0.000000
25.410002,11.205437,-98.970116,0.006381,0.001040,0.026424,49.844273,2.539188,0.264242,-98.970116,0.027387,0.000000
25.640001,11.327202,-98.881157,0.006390,0.001053,0.026736,50.385910,2.566781,0.267365,-98.881157,0.027769,0.000000
25.870001,12.108437,-98.925636,0.006411,0.001075,0.027317,53.861015,2.743811,0.273175,-98.925636,0.028150,0.000000
26.100000,12.312126,-98.925636,0.006424,0.001093,0.027760,54.767071,2.789968,0.277599,-98.925636,0.028532,0.000000
26.330002,12.154984,-98.970116,0.006441,0.001105,0.028063,54.068066,2.754359,0.280635,-98.970116,0.028922,0.000000
26.560001,12.344521,-98.925636,0.006446,0.001120,0.028436,54.911171,2.797308,0.284363,-98.925636,0.029303,0.000000
26.790001,12.341545,-98.925636,0.006467,0.001131,0.028722,54.897934,2.796634,0.287224,-98.925636,0.029685,0.000000
27.020000,12.882225,-99.014595,0.006476,0.001151,0.029243,57.302998,2.919154,0.292429,-99.014595,0.030067,0.000000
27.250002,12.792488,-99.014595,0.006485,0.001164,0.029555,56.903828,2.898819,0.295551,-99.014595,0.030448,0.000000
27.480001,12.953346,-99.014595,0.006510,0.001175,0.029841,57.619362,2.935270,0.298412,-99.014595,0.030839,0.000000
27.710001,13.249756,-99.014595,0.006515,0.001192,0.030275,58.937859,3.002438,0.302750,-99.014595,0.031220,0.000000
27.940001,14.009399,-99.014595,0.006515,0.001215,0.030856,62.316921,3.174575,0.308560,-99.014595,0.031602,0.000000
28.170002,14.052223,-99.014595,0.006545,0.001230,0.031246,62.507412,3.184279,0.312462,-99.014595,0.031983,0.000000
28.400002,13.843323,-98.970116,0.006571,0.001240,0.031506,61.578175,3.136942,0.315062,-98.970116,0.032365,0.000000
28.630001,13.973648,-99.059074,0.006584,0.001256,0.031905,62.157890,3.166474,0.319052,-99.059074,0.032755,0.000000
28.860001,14.294632,-99.014595,0.006579,0.001274,0.032365,63.585697,3.239210,0.323650,-99.014595,0.033137,0.000000
29.090002,14.452896,-99.014595,0.006592,0.001288,0.032712,64.289696,3.275073,0.327117,-99.014595,0.033518,0.000000
29.320002,14.439857,-99.014595,0.006618,0.001299,0.032989,64.231697,3.272118,0.329891,-99.014595,0.033900,0.000000
29.550001,14.691216,-99.014595,0.006618,0.001315,0.033397,65.349792,3.329077,0.333968,-99.014595,0.034281,0.000000
29.780001,14.886337,-99.103561,0.006635,0.001330,0.033770,66.217735,3.373292,0.337696,-99.103561,0.034672,0.000000
30.010002,15.060982,-99.103561,0.006657,0.001344,0.034143,66.994591,3.412867,0.341428,-99.103561,0.035053,0.000000
30.240002,15.250885,-99.103561,0.006661,0.001363,0.034611,67.839325,3.455900,0.346110,-99.103561,0.035435,0.000000
30.470001,15.393883,-99.059074,0.006696,0.001376,0.034958,68.475410,3.488304,0.349577,-99.059074,0.035816,0.000000
30.700001,15.447876,-99.059074,0.006696,0.001389,0.035287,68.715584,3.500539,0.352873,-99.059074,0.036198,0.000000
30.930002,15.796043,-99.103561,0.006709,0.001405,0.035695,70.264313,3.579435,0.356950,-99.103561,0.036588,0.000000
31.160002,15.956909,-99.192520,0.006717,0.001421,0.036094,70.979874,3.615887,0.360939,-99.192520,0.036970,0.000000
31.390001,15.846687,-99.192520,0.006726,0.001433,0.036389,70.489586,3.590911,0.363887,-99.192520,0.037351,0.000000
31.620001,16.466309,-99.148041,0.006730,0.001453,0.036909,73.245796,3.731319,0.369092,-99.148041,0.037733,0.000000
31.850002,16.526634,-99.103561,0.006765,0.001467,0.037256,73.514137,3.744989,0.372559,-99.103561,0.038123,0.000000
32.080002,16.566483,-99.192520,0.006769,0.001481,0.037612,73.691391,3.754019,0.376116,-99.192520,0.038505,0.000000
32.310001,16.844269,-99.192520,0.006795,0.001498,0.038054,74.927048,3.816966,0.380537,-99.192520,0.038886,0.000000
32.540001,16.982796,-99.192520,0.006808,0.001513,0.038418,75.543251,3.848356,0.384182,-99.192520,0.039268,0.000000
32.770000,17.073654,-99.103561,0.006812,0.001527,0.038782,75.947411,3.868945,0.387823,-99.103561,0.039649,0.000000
33.000000,17.240471,-99.148041,0.006821,0.001541,0.039146,76.689445,3.906747,0.391464,-99.148041,0.040040,0.000000
33.230003,17.094131,-99.148041,0.006847,0.001551,0.039398,76.038498,3.873586,0.393981,-99.148041,0.040422,0.000000
33.460003,17.399475,-99.237000,0.006842,0.001569,0.039858,77.396729,3.942777,0.398576,-99.237000,0.040803,0.000000
33.690002,17.968086,-99.237000,0.006847,0.001589,0.040369,79.926041,4.071627,0.403693,-99.237000,0.041185,0.000000
33.920002,18.041817,-99.237000,0.006877,0.001604,0.040742,80.254005,4.088334,0.407421,-99.237000,0.041566,0.000000
34.150002,17.996017,-99.192520,0.006868,0.001618,0.041089,80.050285,4.077956,0.410892,-99.192520,0.041956,0.000000
34.380001,18.021713,-99.237000,0.006890,0.001631,0.041436,80.164581,4.083779,0.414359,-99.237000,0.042338,0.000000
34.610001,17.885422,-99.237000,0.006903,0.001644,0.041748,79.558327,4.052895,0.417481,-99.237000,0.042719,0.000000
34.840000,18.434303,-99.237000,0.006929,0.001662,0.042216,81.999878,4.177273,0.422163,-99.237000,0.043101,0.000000
35.070004,18.524788,-99.281487,0.006933,0.001674,0.042520,82.402374,4.197777,0.425199,-99.281487,0.043483,0.000000
35.300003,18.462227,-99.237000,0.006954,0.001687,0.042858,82.124084,4.183600,0.428583,-99.237000,0.043873,0.000000
35.530003,19.185005,-99.237000,0.006976,0.001707,0.043361,85.339165,4.347384,0.433613,-99.237000,0.044255,0.000000
35.760002,19.178299,-99.325966,0.006985,0.001721,0.043725,85.309334,4.345865,0.437254,-99.325966,0.044636,0.000000
35.990002,19.206230,-99.281487,0.006998,0.001736,0.044099,85.433578,4.352194,0.440986,-99.281487,0.045018,0.000000
36.220001,19.235275,-99.325966,0.007011,0.001750,0.044463,85.562775,4.358776,0.444627,-99.325966,0.045399,0.000000
36.450001,19.140694,-99.281487,0.007011,0.001762,0.044766,85.142059,4.337343,0.447662,-99.281487,0.045790,0.000000
36.680000,19.429283,-99.325966,0.007019,0.001779,0.045183,86.425766,4.402739,0.451826,-99.325966,0.046171,0.000000
36.910000,19.606155,-99.370445,0.007045,0.001796,0.045625,87.212532,4.442819,0.456246,-99.370445,0.046553,0.000000
37.140003,19.391296,-99.325966,0.007054,0.001805,0.045859,86.256798,4.394131,0.458589,-99.325966,0.046934,0.000000
37.370003,20.025444,-99.370445,0.007067,0.001829,0.046466,89.077621,4.537830,0.464660,-99.370445,0.047316,0.000000
37.600002,20.226158,-99.414925,0.007084,0.001843,0.046813,89.970444,4.583313,0.468127,-99.414925,0.047706,0.000000
37.830002,20.127106,-99.325966,0.007101,0.001857,0.047168,89.529839,4.560867,0.471685,-99.325966,0.048087,0.000000
38.060001,20.314034,-99.414925,0.007127,0.001873,0.047576,90.361336,4.603226,0.475761,-99.414925,0.048469,0.000000
38.290001,20.381065,-99.414925,0.007114,0.001890,0.048001,90.659508,4.618415,0.480008,-99.414925,0.048851,0.000000
38.520000,20.740402,-99.370445,0.007136,0.001907,0.048426,92.257919,4.699842,0.484258,-99.370445,0.049232,0.000000
38.750000,20.642471,-99.370445,0.007153,0.001920,0.048756,91.822296,4.677651,0.487555,-99.370445,0.049623,0.000000
38.980003,20.633530,-99.370445,0.007157,0.001932,0.049068,91.782524,4.675625,0.490678,-99.370445,0.050004,0.000000
39.210003,20.328560,-99.459404,0.007170,0.001944,0.049371,90.425949,4.606518,0.493713,-99.459404,0.050386,0.000000
39.440002,20.801476,-99.414925,0.007179,0.001962,0.049831,92.529587,4.713682,0.498308,-99.414925,0.050767,0.000000
39.670002,21.374550,-99.414925,0.007200,0.001982,0.050334,95.078743,4.843543,0.503338,-99.414925,0.051158,0.000000
39.900002,21.131393,-99.459404,0.007209,0.001993,0.050620,93.997131,4.788442,0.506199,-99.459404,0.051539,0.000000
40.130001,21.339920,-99.459404,0.007217,0.002008,0.051001,94.924706,4.835695,0.510015,-99.459404,0.051921,0.000000
40.360001,21.317955,-99.459404,0.007239,0.002020,0.051314,94.827003,4.830718,0.513137,-99.459404,0.052302,0.000000
40.590000,21.902580,-99.503891,0.007230,0.002040,0.051817,97.427544,4.963196,0.518167,-99.503891,0.052684,0.000000
40.820004,21.835548,-99.459404,0.007252,0.002052,0.052120,97.129372,4.948006,0.521203,-99.459404,0.053074,0.000000
41.050003,21.383492,-99.414925,0.007256,0.002059,0.052302,95.118523,4.845569,0.523023,-99.414925,0.053456,0.000000
41.280003,22.037750,-99.503891,0.007295,0.002081,0.052866,98.028809,4.993825,0.528659,-99.503891,0.053837,0.000000
41.510002,22.324844,-99.548370,0.007299,0.002098,0.053291,99.305870,5.058882,0.532909,-99.548370,0.054219,0.000000
41.740002,22.579178,-99.548370,0.007321,0.002114,0.053699,100.437202,5.116515,0.536986,-99.548370,0.054601,0.000000
41.970001,22.311440,-99.503891,0.007308,0.002128,0.054054,99.246239,5.055845,0.540540,-99.503891,0.054991,0.000000
42.200001,22.842445,-99.503891,0.007317,0.002146,0.054514,101.608269,5.176172,0.545138,-99.503891,0.055372,0.000000
42.430000,23.116142,-99.503891,0.007347,0.002164,0.054956,102.825737,5.238193,0.549559,-99.503891,0.055754,0.000000
42.660004,23.071823,-99.548370,0.007373,0.002176,0.055277,102.628593,5.228150,0.552769,-99.548370,0.056136,0.000000
42.890003,22.369904,-99.548370,0.007377,0.002183,0.055442,99.506302,5.069093,0.554415,-99.548370,0.056517,0.000000
43.120003,22.945221,-99.592850,0.007364,0.002200,0.055875,102.065437,5.199461,0.558753,-99.592850,0.056907,0.000000
43.350002,23.196945,-99.548370,0.007390,0.002217,0.056318,103.185165,5.256503,0.563177,-99.548370,0.057289,0.000000
43.580002,23.622940,-99.503891,0.007416,0.002233,0.056725,105.080086,5.353034,0.567254,-99.503891,0.057670,0.000000
43.810001,23.317596,-99.503891,0.007412,0.002242,0.056951,103.721848,5.283843,0.569506,-99.503891,0.058052,0.000000
44.040001,23.990097,-99.637329,0.007403,0.002267,0.057575,106.713280,5.436234,0.575751,-99.637329,0.058433,0.000000
44.270000,23.901848,-99.637329,0.007442,0.002277,0.057844,106.320732,5.416236,0.578438,-99.637329,0.058824,0.000000
44.500004,23.978928,-99.548370,0.007442,0.002293,0.058243,106.663597,5.433702,0.582427,-99.548370,0.059206,0.000000
44.730003,24.227295,-99.548370,0.007472,0.002308,0.058624,107.768387,5.489984,0.586242,-99.548370,0.059587,0.000000
44.960003,24.302147,-99.592850,0.007468,0.002322,0.058980,108.101349,5.506945,0.589800,-99.592850,0.059969,0.000000
45.190002,24.388535,-99.726295,0.007493,0.002337,0.059362,108.485619,5.526521,0.593615,-99.726295,0.060350,0.000000
45.420002,24.601532,-99.548370,0.007493,0.002353,0.059760,109.433083,5.574787,0.597605,-99.548370,0.060740,0.000000
45.650002,24.963478,-99.637329,0.007524,0.002368,0.060159,111.043098,5.656805,0.601594,-99.637329,0.061122,0.000000
45.880001,24.993645,-99.592850,0.007515,0.002384,0.060550,111.177284,5.663640,0.605496,-99.592850,0.061504,0.000000
46.110001,25.183182,-99.681808,0.007541,0.002398,0.060914,112.020386,5.706591,0.609137,-99.681808,0.061885,0.000000
46.340004,25.749184,-99.637329,0.007549,0.002420,0.061460,114.538086,5.834848,0.614603,-99.637329,0.062267,0.000000
46.570004,25.760353,-99.637329,0.007562,0.002434,0.061816,114.587776,5.837379,0.618157,-99.637329,0.062657,0.000000
46.800003,25.368996,-99.637329,0.007562,0.002442,0.062024,112.846931,5.748697,0.620238,-99.637329,0.063039,0.000000
47.030003,25.459480,-99.637329,0.007575,0.002457,0.062405,113.249428,5.769201,0.624053,-99.637329,0.063420,0.000000
47.260002,26.262314,-99.681808,0.007601,0.002477,0.062926,116.820610,5.951126,0.629258,-99.681808,0.063802,0.000000
47.490002,26.511429,-99.726295,0.007614,0.002496,0.063403,117.928726,6.007576,0.634027,-99.726295,0.064183,0.000000
47.720001,26.259338,-99.770775,0.007627,0.002508,0.063698,116.807373,5.950451,0.636975,-99.770775,0.064574,0.000000
47.950001,26.520370,-99.726295,0.007631,0.002522,0.064062,117.968498,6.009602,0.640620,-99.726295,0.064955,0.000000
48.180004,26.759430,-99.726295,0.007662,0.002539,0.064478,119.031891,6.063774,0.644783,-99.726295,0.065337,0.000000
48.410004,27.048767,-99.681808,0.007657,0.002553,0.064851,120.318924,6.129338,0.648511,-99.681808,0.065718,0.000000
48.640003,27.023445,-99.770775,0.007670,0.002565,0.065155,120.206291,6.123600,0.651547,-99.770775,0.066108,0.000000
48.870003,26.940033,-99.726295,0.007687,0.002577,0.065450,119.835251,6.104699,0.654495,-99.726295,0.066490,0.000000
49.100002,27.511253,-99.726295,0.007683,0.002598,0.065979,122.376167,6.234139,0.659787,-99.726295,0.066872,0.000000
49.330002,28.153595,-99.770775,0.007700,0.002617,0.066473,125.233444,6.379696,0.664730,-99.770775,0.067253,0.000000
49.560001,28.099602,-99.726295,0.007735,0.002630,0.066794,124.993271,6.367461,0.667936,-99.726295,0.067635,0.000000
49.790001,28.078751,-99.815254,0.007743,0.002644,0.067158,124.900520,6.362736,0.671580,-99.815254,0.068025,0.000000
50.020004,28.248924,-99.815254,0.007739,0.002658,0.067522,125.657494,6.401298,0.675222,-99.815254,0.068407,0.000000
50.250004,28.877113,-99.726295,0.007743,0.002678,0.068034,128.451813,6.543647,0.680339,-99.726295,0.068788,0.000000
50.480003,28.888657,-99.770775,0.007756,0.002691,0.068346,128.503159,6.546263,0.683461,-99.770775,0.069170,0.000000
50.710003,28.608261,-99.815254,0.007800,0.002700,0.068580,127.255898,6.482725,0.685800,-99.815254,0.069552,0.000000
50.940002,29.184692,-99.859734,0.007800,0.002720,0.069083,129.819992,6.613346,0.690830,-99.859734,0.069942,0.000000
51.170002,29.690376,-99.859734,0.007791,0.002738,0.069552,132.069397,6.727936,0.695516,-99.859734,0.070323,0.000000
51.400002,29.739159,-99.815254,0.007825,0.002752,0.069890,132.286377,6.738989,0.698896,-99.815254,0.070705,0.000000
51.630001,30.110413,-99.770775,0.007843,0.002766,0.070254,133.937805,6.823117,0.702541,-99.770775,0.071086,0.000000
51.860001,30.074661,-99.815254,0.007856,0.002779,0.070575,133.778778,6.815016,0.705747,-99.815254,0.071468,0.000000
52.090004,30.502892,-99.859734,0.007838,0.002794,0.070974,135.683640,6.912054,0.709736,-99.859734,0.071858,0.000000
52.320004,30.465279,-99.859734,0.007873,0.002807,0.071295,135.516327,6.903531,0.712946,-99.859734,0.072240,0.000000
52.550003,30.896492,-99.859734,0.007877,0.002822,0.071676,137.434464,7.001245,0.716761,-99.859734,0.072622,0.000000
52.780003,30.991814,-99.859734,0.007881,0.002835,0.072006,137.858475,7.022845,0.720057,-99.859734,0.073003,0.000000
53.010002,31.804337,-99.859734,0.007894,0.002856,0.072544,141.472748,7.206966,0.725436,-99.859734,0.073385,0.000000
53.240002,32.067604,-99.859734,0.007912,0.002871,0.072916,142.643829,7.266623,0.729164,-99.859734,0.073775,0.000000
53.470001,32.241127,-99.859734,0.007916,0.002883,0.073237,143.415695,7.305943,0.732373,-99.859734,0.074156,0.000000
53.700001,32.636215,-99.904213,0.007933,0.002902,0.073706,145.173141,7.395472,0.737055,-99.904213,0.074538,0.000000
53.930004,32.645149,-99.859734,0.007955,0.002911,0.073948,145.212875,7.397497,0.739481,-99.859734,0.074920,0.000000
54.160004,33.261429,-99.904213,0.007950,0.002930,0.074434,147.954224,7.537148,0.744341,-99.904213,0.075301,0.000000
54.390003,33.478149,-99.904213,0.007963,0.002945,0.074807,148.918243,7.586257,0.748069,-99.904213,0.075691,0.000000
54.620003,33.268501,-99.993179,0.007959,0.002954,0.075033,147.985687,7.538750,0.750325,-99.993179,0.076073,0.000000
54.850002,34.296623,-99.948700,0.007989,0.002976,0.075587,152.559006,7.771726,0.755874,-99.948700,0.076454,0.000000
55.080002,34.753525,-99.904213,0.008006,0.002994,0.076038,154.591400,7.875261,0.760382,-99.904213,0.076836,0.000000
55.310001,34.791130,-99.948700,0.008002,0.003004,0.076299,154.758682,7.883783,0.762986,-99.948700,0.077218,0.000000
55.540001,35.242821,-99.904213,0.008028,0.003022,0.076749,156.767899,7.986137,0.767493,-99.904213,0.077608,0.000000
55.770004,35.194786,-100.037659,0.008032,0.003032,0.077001,156.554230,7.975252,0.770010,-100.037659,0.077990,0.000000
56.000004,35.605141,-99.993179,0.008050,0.003046,0.077374,158.379578,8.068240,0.773739,-99.993179,0.078371,0.000000
56.230003,36.224770,-99.993179,0.008058,0.003063,0.077799,161.135818,8.208651,0.777989,-99.993179,0.078753,0.000000
56.460003,36.251205,-100.037659,0.008067,0.003073,0.078050,161.253418,8.214641,0.780502,-100.037659,0.079134,0.000000
56.690002,36.711456,-99.948700,0.008071,0.003089,0.078458,163.300720,8.318935,0.784578,-99.948700,0.079524,0.000000
56.920002,37.715004,-100.082138,0.008088,0.003111,0.079013,167.764709,8.546342,0.790131,-100.082138,0.079906,0.000000
57.150002,37.920181,-100.037659,0.008097,0.003127,0.079429,168.677383,8.592836,0.794290,-100.037659,0.080288,0.000000
57.380001,38.357719,-99.993179,0.008119,0.003140,0.079750,170.623657,8.691983,0.797500,-99.993179,0.080669,0.000000
57.610004,38.502945,-99.948700,0.008127,0.003153,0.080088,171.269653,8.724892,0.800884,-99.948700,0.081060,0.000000
57.840004,38.647797,-100.037659,0.008132,0.003165,0.080401,171.913986,8.757715,0.804006,-100.037659,0.081441,0.000000
58.070004,39.458824,-100.082138,0.008153,0.003184,0.080886,175.521622,8.941497,0.808862,-100.082138,0.081823,0.000000
58.300003,39.929131,-100.037659,0.008153,0.003199,0.081250,177.613647,9.048071,0.812503,-100.037659,0.082204,0.000000
58.530003,39.938065,-100.082138,0.008179,0.003210,0.081545,177.653381,9.050096,0.815452,-100.082138,0.082586,0.000000
58.760002,41.219398,-100.037659,0.008183,0.003232,0.082100,183.353043,9.340449,0.821001,-100.037659,0.082976,0.000000
58.990002,41.467026,-100.037659,0.008213,0.003245,0.082421,184.454544,9.396563,0.824210,-100.037659,0.083358,0.000000
59.220001,41.840141,-100.037659,0.008201,0.003258,0.082751,186.114243,9.481112,0.827507,-100.037659,0.083739,0.000000
59.450005,42.405403,-100.126617,0.008226,0.003276,0.083210,188.628647,9.609201,0.832102,-100.126617,0.084121,0.000000
59.680004,42.854111,-100.082138,0.008235,0.003290,0.083575,190.624603,9.710880,0.835746,-100.082138,0.084502,0.000000
59.910004,43.654343,-100.126617,0.008248,0.003309,0.084043,194.184219,9.892216,0.840428,-100.126617,0.084893,0.000000
60.140003,43.832710,-100.082138,0.008261,0.003321,0.084346,194.977631,9.932633,0.843464,-100.082138,0.085274,0.000000
60.370003,44.095604,-100.126617,0.008269,0.003333,0.084659,196.147049,9.992207,0.846586,-100.126617,0.085656,0.000000
60.600002,44.771088,-100.215584,0.008269,0.003351,0.085118,199.151749,10.145274,0.851181,-100.215584,0.086037,0.000000
60.830002,45.530724,-100.082138,0.008313,0.003366,0.085491,202.530777,10.317410,0.854909,-100.082138,0.086419,0.000000
61.060001,46.107903,-100.171104,0.008291,0.003380,0.085864,205.098190,10.448199,0.858641,-100.171104,0.086809,0.000000
61.290005,46.382339,-100.126617,0.008304,0.003393,0.086193,206.318954,10.510388,0.861934,-100.126617,0.087191,0.000000
61.520004,46.944626,-100.126617,0.008317,0.003409,0.086584,208.820129,10.637804,0.865836,-100.126617,0.087572,0.000000
61.750004,47.388863,-100.215584,0.008326,0.003424,0.086966,210.796188,10.738470,0.869655,-100.215584,0.087954,0.000000
61.980003,48.686958,-100.215584,0.008356,0.003444,0.087486,216.570404,11.032622,0.874856,-100.215584,0.088336,0.000000
62.210003,48.920433,-100.126617,0.008356,0.003456,0.087772,217.608948,11.085528,0.877717,-100.126617,0.088726,0.000000
62.440002,48.719353,-100.215584,0.008347,0.003464,0.087980,216.714508,11.039964,0.879799,-100.215584,0.089107,0.000000
62.670002,49.863281,-100.215584,0.008382,0.003483,0.088457,221.802948,11.299181,0.884572,-100.215584,0.089489,0.000000
62.900002,50.949493,-100.260063,0.008382,0.003503,0.088977,226.634659,11.545321,0.889772,-100.260063,0.089870,0.000000
63.130005,51.477890,-100.215584,0.008399,0.003514,0.089263,228.985092,11.665056,0.892633,-100.215584,0.090252,0.000000
63.360004,52.115387,-100.215584,0.008433,0.003532,0.089723,231.820816,11.809516,0.897232,-100.215584,0.090643,0.000000
63.590004,52.999405,-100.260063,0.008429,0.003547,0.090087,235.753128,12.009837,0.900873,-100.260063,0.091024,0.000000
63.820004,53.916183,-100.260063,0.008425,0.003564,0.090530,239.831161,12.217583,0.905298,-100.260063,0.091406,0.000000
64.050003,54.290787,-100.215584,0.008425,0.003575,0.090807,241.497482,12.302468,0.908072,-100.215584,0.091787,0.000000
64.280006,54.622948,-100.304543,0.008429,0.003587,0.091102,242.975006,12.377737,0.911020,-100.304543,0.092169,0.000000
64.510002,55.069046,-100.260063,0.008455,0.003600,0.091440,244.959351,12.478825,0.914404,-100.260063,0.092559,0.000000
64.740005,56.310539,-100.304543,0.008476,0.003619,0.091935,250.481781,12.760151,0.919347,-100.304543,0.092940,0.000000
64.970001,57.194550,-100.349022,0.008485,0.003637,0.092377,254.414062,12.960470,0.923768,-100.349022,0.093322,0.000000
65.200005,57.234390,-100.304543,0.008489,0.003646,0.092620,254.591278,12.969499,0.926198,-100.304543,0.093704,0.000000
65.430000,58.986778,-100.349022,0.008498,0.003668,0.093166,262.386292,13.366595,0.931659,-100.349022,0.094085,0.000000
65.660004,59.143173,-100.260063,0.008515,0.003676,0.093365,263.081970,13.402035,0.933654,-100.260063,0.094476,0.000000
65.889999,60.013779,-100.304543,0.008524,0.003693,0.093808,266.954620,13.599317,0.938079,-100.304543,0.094857,0.000000
66.120003,60.860558,-100.349022,0.008541,0.003707,0.094155,270.721283,13.791200,0.941546,-100.349022,0.095239,0.000000
66.350006,61.689461,-100.349022,0.008550,0.003723,0.094553,274.408417,13.979033,0.945535,-100.349022,0.095620,0.000000
66.580002,62.370903,-100.349022,0.008524,0.003736,0.094883,277.439636,14.133449,0.948832,-100.349022,0.096011,0.000000
66.810005,63.713676,-100.349022,0.008567,0.003757,0.095438,283.412598,14.437725,0.954380,-100.349022,0.096392,0.000000
67.040001,64.429008,-100.304543,0.008584,0.003769,0.095733,286.594543,14.599822,0.957329,-100.304543,0.096774,0.000000
67.270004,65.307808,-100.349022,0.008558,0.003786,0.096158,290.503632,14.798961,0.961579,-100.349022,0.097155,0.000000
67.500000,66.044350,-100.437988,0.008584,0.003798,0.096479,293.779938,14.965864,0.964789,-100.437988,0.097537,0.000000
67.730003,67.370003,-100.437988,0.008601,0.003809,0.096748,299.676727,15.266261,0.967476,-100.437988,0.096991,0.000000
67.960007,66.596214,-100.349022,0.008601,0.003809,0.096748,296.234741,15.090918,0.967476,-100.349022,0.096991,0.000000
68.190002,65.886833,-100.304543,0.008610,0.003806,0.096678,293.079285,14.930170,0.966783,-100.304543,0.096748,0.000000
68.420006,65.248970,-100.393509,0.008619,0.003805,0.096644,290.241913,14.785628,0.966435,-100.393509,0.096748,0.000000
68.650002,64.676262,-100.437988,0.008636,0.003804,0.096618,287.694366,14.655850,0.966178,-100.437988,0.096748,0.000000
68.880005,64.145256,-100.437988,0.008619,0.003803,0.096600,285.332336,14.535522,0.966004,-100.437988,0.096748,0.000000
69.110001,63.660805,-100.393509,0.008649,0.003803,0.096592,283.177399,14.425744,0.965917,-100.393509,0.096748,0.000000
69.340004,63.209114,-100.437988,0.008653,0.003803,0.096592,281.168182,14.323390,0.965917,-100.437988,0.096748,0.000000
69.570000,62.802483,-100.437988,0.008653,0.003802,0.096583,279.359406,14.231246,0.965829,-100.437988,0.096748,0.000000
69.800003,62.427124,-100.437988,0.008645,0.003802,0.096574,277.689728,14.146189,0.965742,-100.437988,0.096748,0.000000
70.030006,62.074860,-100.482468,0.008653,0.003802,0.096574,276.122772,14.066364,0.965742,-100.482468,0.096748,0.000000
70.260002,61.757599,-100.482468,0.008653,0.003802,0.096574,274.711517,13.994472,0.965742,-100.482468,0.096748,0.000000
70.490005,61.446671,-100.437988,0.008675,0.003802,0.096574,273.328430,13.924014,0.965742,-100.437988,0.096748,0.000000
70.720001,61.164413,-100.437988,0.008666,0.003802,0.096574,272.072906,13.860054,0.965742,-100.437988,0.096748,0.000000
70.950005,60.910080,-100.526947,0.008653,0.003802,0.096566,270.941559,13.802422,0.965655,-100.526947,0.096748,0.000000
71.180000,60.664314,-100.526947,0.008675,0.003802,0.096566,269.848358,13.746730,0.965655,-100.526947,0.096748,0.000000
71.410004,60.414085,-100.437988,0.008653,0.003802,0.096566,268.735260,13.690027,0.965655,-100.437988,0.096748,0.000000
71.640007,60.186935,-100.437988,0.008666,0.003802,0.096566,267.724854,13.638555,0.965655,-100.437988,0.096748,0.000000
71.870003,59.988457,-100.437988,0.008662,0.003802,0.096566,266.841980,13.593578,0.965655,-100.437988,0.096748,0.000000
72.100006,59.785149,-100.571434,0.008679,0.003802,0.096566,265.937622,13.547509,0.965655,-100.571434,0.096748,0.000000
72.330002,59.588531,-100.526947,0.008649,0.003802,0.096566,265.063019,13.502954,0.965655,-100.526947,0.096748,0.000000
72.560005,59.403465,-100.526947,0.008675,0.003802,0.096566,264.239807,13.461018,0.965655,-100.526947,0.096748,0.000000
72.790001,59.238129,-100.482468,0.008670,0.003801,0.096557,263.504364,13.423553,0.965568,-100.482468,0.096748,0.000000
73.020004,59.048592,-100.482468,0.008692,0.003801,0.096557,262.661255,13.380602,0.965568,-100.482468,0.096748,0.000000
73.250000,58.894058,-100.526947,0.008662,0.003801,0.096557,261.973846,13.345584,0.965568,-100.526947,0.096748,0.000000
73.480003,58.743988,-100.571434,0.008666,0.003801,0.096557,261.306305,13.311578,0.965568,-100.571434,0.096748,0.000000
73.710007,58.606216,-100.615913,0.008670,0.003801,0.096557,260.693481,13.280358,0.965568,-100.615913,0.096748,0.000000
73.940002,58.453545,-100.526947,0.008666,0.003801,0.096557,260.014343,13.245762,0.965568,-100.526947,0.096748,0.000000
74.170006,58.329910,-100.571434,0.008670,0.003801,0.096557,259.464386,13.217747,0.965568,-100.571434,0.096748,0.000000
74.400002,58.191391,-100.615913,0.008675,0.003801,0.096557,258.848236,13.186357,0.965568,-100.615913,0.096748,0.000000
74.630005,58.062920,-100.660393,0.008679,0.003801,0.096557,258.276764,13.157246,0.965568,-100.660393,0.096748,0.000000
74.860001,57.940041,-100.615913,0.008670,0.003801,0.096557,257.730164,13.129400,0.965568,-100.615913,0.096748,0.000000
75.090004,57.827957,-100.615913,0.008675,0.003801,0.096557,257.231598,13.104002,0.965568,-100.615913,0.096748,0.000000
75.320007,57.716614,-100.660393,0.008675,0.003801,0.096557,256.736328,13.078772,0.965568,-100.660393,0.096748,0.000000
75.550003,57.607140,-100.660393,0.008688,0.003801,0.096557,256.249359,13.053965,0.965568,-100.660393,0.096748,0.000000
75.780006,57.499153,-100.704872,0.008688,0.003801,0.096557,255.769012,13.029494,0.965568,-100.704872,0.096748,0.000000
76.010002,57.418716,-100.660393,0.008666,0.003801,0.096557,255.411209,13.011267,0.965568,-100.660393,0.096748,0.000000
76.240005,57.313339,-100.660393,0.008683,0.003801,0.096557,254.942459,12.987388,0.965568,-100.660393,0.096748,0.000000
76.470001,57.201996,-100.615913,0.008670,0.003801,0.096557,254.447189,12.962157,0.965568,-100.615913,0.096748,0.000000
76.700005,57.107414,-100.704872,0.008688,0.003801,0.096557,254.026459,12.940725,0.965568,-100.704872,0.096748,0.000000
76.930000,57.027351,-100.704872,0.008679,0.003801,0.096557,253.670334,12.922583,0.965568,-100.704872,0.096748,0.000000
77.160004,56.933891,-100.704872,0.008675,0.003801,0.096557,253.254593,12.901404,0.965568,-100.704872,0.096748,0.000000
77.390007,56.837814,-100.704872,0.008679,0.003801,0.096557,252.827225,12.879633,0.965568,-100.704872,0.096748,0.000000
77.620003,56.771904,-100.704872,0.008666,0.003801,0.096557,252.534042,12.864697,0.965568,-100.704872,0.096748,0.000000
77.850006,56.694084,-100.749352,0.008675,0.003801,0.096557,252.187881,12.847063,0.965568,-100.749352,0.096748,0.000000
78.080002,56.605453,-100.793839,0.008688,0.003801,0.096557,251.793640,12.826979,0.965568,-100.793839,0.096748,0.000000
78.310005,56.525024,-100.704872,0.008683,0.003801,0.096557,251.435867,12.808754,0.965568,-100.704872,0.096748,0.000000
78.540001,56.449432,-100.749352,0.008683,0.003801,0.096557,251.099609,12.791624,0.965568,-100.749352,0.096748,0.000000
78.770004,56.389107,-100.704872,0.008688,0.003801,0.096557,250.831268,12.777954,0.965568,-100.704872,0.096748,0.000000
79.000000,56.320595,-100.838318,0.008692,0.003801,0.096557,250.526520,12.762429,0.965568,-100.838318,0.096748,0.000000
79.230003,56.238297,-100.793839,0.008688,0.003801,0.096557,250.160431,12.743780,0.965568,-100.793839,0.096748,0.000000
79.460007,56.177597,-100.793839,0.008662,0.003801,0.096557,249.890427,12.730025,0.965568,-100.793839,0.096748,0.000000
79.690002,56.115784,-100.749352,0.008688,0.003801,0.096557,249.615479,12.716018,0.965568,-100.749352,0.096748,0.000000
79.920006,56.043549,-100.793839,0.008670,0.003801,0.096557,249.294159,12.699650,0.965568,-100.793839,0.096748,0.000000
80.150002,55.972794,-100.793839,0.008696,0.003801,0.096557,248.979416,12.683617,0.965568,-100.793839,0.096748,0.000000
80.380005,55.910240,-100.838318,0.008692,0.003801,0.096557,248.701172,12.669441,0.965568,-100.838318,0.096748,0.000000
80.610001,55.860336,-100.882797,0.008688,0.003801,0.096557,248.479187,12.658134,0.965568,-100.882797,0.096748,0.000000
80.840004,55.795174,-100.838318,0.008683,0.003801,0.096557,248.189331,12.643367,0.965568,-100.838318,0.096748,0.000000
81.070007,55.754211,-100.838318,0.008696,0.003801,0.096557,248.007126,12.634086,0.965568,-100.838318,0.096748,0.000000
81.300003,55.691284,-100.838318,0.008688,0.003801,0.096557,247.727203,12.619825,0.965568,-100.838318,0.096748,0.000000
81.530006,55.645851,-100.927277,0.008683,0.003801,0.096557,247.525101,12.609530,0.965568,-100.927277,0.096748,0.000000
81.760002,55.584038,-100.882797,0.008692,0.003801,0.096557,247.250153,12.595523,0.965568,-100.882797,0.096748,0.000000
81.990005,55.528183,-100.793839,0.008688,0.003801,0.096557,247.001694,12.582866,0.965568,-100.793839,0.096748,0.000000
82.220001,55.465996,-100.838318,0.008705,0.003801,0.096557,246.725067,12.568774,0.965568,-100.838318,0.096748,0.000000
82.450005,55.421310,-100.882797,0.008696,0.003801,0.096557,246.526306,12.558648,0.965568,-100.882797,0.096748,0.000000
82.680000,55.374023,-100.882797,0.008688,0.003801,0.096557,246.315964,12.547933,0.965568,-100.882797,0.096748,0.000000
82.910004,55.315933,-100.882797,0.008701,0.003801,0.096557,246.057556,12.534769,0.965568,-100.882797,0.096748,0.000000
83.140007,55.260445,-100.927277,0.008696,0.003801,0.096557,245.810730,12.522196,0.965568,-100.927277,0.096748,0.000000
83.370003,55.228798,-100.927277,0.008688,0.003801,0.096557,245.669968,12.515024,0.965568,-100.927277,0.096748,0.000000
83.600006,55.187088,-100.882797,0.008692,0.003801,0.096557,245.484421,12.505573,0.965568,-100.882797,0.096748,0.000000
83.830002,55.128258,-101.016243,0.008688,0.003801,0.096557,245.222733,12.492241,0.965568,-101.016243,0.096748,0.000000
84.060005,55.070534,-100.971756,0.008709,0.003801,0.096557,244.965973,12.479161,0.965568,-100.971756,0.096748,0.000000
84.290001,55.041862,-100.882797,0.008688,0.003801,0.096557,244.838440,12.472664,0.965568,-100.882797,0.096748,0.000000
84.520004,55.003510,-100.882797,0.008675,0.003801,0.096557,244.667831,12.463973,0.965568,-100.882797,0.096748,0.000000
84.750008,54.954727,-100.971756,0.008692,0.003801,0.096557,244.450836,12.452919,0.965568,-100.971756,0.096748,0.000000
84.980003,54.909676,-100.971756,0.008705,0.003801,0.096557,244.250443,12.442711,0.965568,-100.971756,0.096748,0.000000
85.210007,54.864616,-100.971756,0.008692,0.003801,0.096557,244.050003,12.432500,0.965568,-100.971756,0.096748,0.000000
85.440002,54.829987,-101.016243,0.008670,0.003801,0.096557,243.895966,12.424653,0.965568,-101.016243,0.096748,0.000000
85.670006,54.780090,-100.971756,0.008701,0.003801,0.096557,243.674011,12.413346,0.965568,-100.971756,0.096748,0.000000
85.900002,54.743225,-101.016243,0.008692,0.003801,0.096557,243.510025,12.404992,0.965568,-101.016243,0.096748,0.000000
86.130005,54.729073,-101.060722,0.008688,0.003801,0.096557,243.447067,12.401785,0.965568,-101.060722,0.096748,0.000000
86.360001,54.682526,-101.060722,0.008675,0.003801,0.096557,243.240021,12.391238,0.965568,-101.060722,0.096748,0.000000
86.590004,54.626671,-101.060722,0.008696,0.003801,0.096557,242.991562,12.378581,0.965568,-101.060722,0.096748,0.000000
86.820007,54.597626,-100.971756,0.008722,0.003801,0.096557,242.862366,12.371999,0.965568,-100.971756,0.096748,0.000000
87.050003,54.570816,-101.016243,0.008705,0.003801,0.096557,242.743118,12.365924,0.965568,-101.016243,0.096748,0.000000
87.280006,54.516075,-101.105202,0.008683,0.003801,0.096557,242.499619,12.353519,0.965568,-101.105202,0.096748,0.000000
87.510002,54.486656,-101.060722,0.008696,0.003801,0.096557,242.368744,12.346852,0.965568,-101.060722,0.096748,0.000000
87.740005,54.437874,-101.060722,0.008692,0.003801,0.096557,242.151764,12.335798,0.965568,-101.060722,0.096748,0.000000
87.970001,54.409950,-101.060722,0.008701,0.003801,0.096557,242.027542,12.329471,0.965568,-101.060722,0.096748,0.000000
88.200005,54.375320,-101.060722,0.008701,0.003801,0.096557,241.873505,12.321624,0.965568,-101.060722,0.096748,0.000000
88.430008,54.341805,-101.060722,0.008692,0.003801,0.096557,241.724426,12.314029,0.965568,-101.060722,0.096748,0.000000
88.660004,54.306427,-101.060722,0.008709,0.003801,0.096557,241.567047,12.306012,0.965568,-101.060722,0.096748,0.000000
88.890007,54.268822,-101.105202,0.008683,0.003801,0.096557,241.399780,12.297490,0.965568,-101.105202,0.096748,0.000000
89.120003,54.228600,-101.016243,0.008696,0.003801,0.096557,241.220856,12.288377,0.965568,-101.016243,0.096748,0.000000
89.350006,54.184288,-101.149681,0.008709,0.003801,0.096557,241.023758,12.278335,0.965568,-101.149681,0.096748,0.000000
89.580002,54.174980,-101.105202,0.008696,0.003801,0.096557,240.982346,12.276226,0.965568,-101.105202,0.096748,0.000000
89.810005,54.138489,-101.149681,0.008692,0.003801,0.096557,240.820023,12.267957,0.965568,-101.149681,0.096748,0.000000
90.040001,54.111305,-101.149681,0.008709,0.003801,0.096557,240.699112,12.261797,0.965568,-101.149681,0.096748,0.000000
90.270004,54.086731,-101.149681,0.008701,0.003801,0.096557,240.589798,12.256228,0.965568,-101.149681,0.096748,0.000000
90.500008,54.045021,-101.149681,0.008701,0.003801,0.096557,240.404266,12.246777,0.965568,-101.149681,0.096748,0.000000
90.730003,54.008530,-101.194160,0.008701,0.003801,0.096557,240.241943,12.238508,0.965568,-101.194160,0.096748,0.000000
90.960007,53.974274,-101.149681,0.008696,0.003801,0.096557,240.089554,12.230745,0.965568,-101.149681,0.096748,0.000000
91.190002,53.957146,-101.238647,0.008692,0.003801,0.096557,240.013367,12.226864,0.965568,-101.238647,0.096748,0.000000
91.420006,53.936661,-101.149681,0.008692,0.003801,0.096557,239.922256,12.222222,0.965568,-101.149681,0.096748,0.000000
91.650002,53.897568,-101.149681,0.008718,0.003801,0.096557,239.748352,12.213364,0.965568,-101.149681,0.096748,0.000000
91.880005,53.860329,-101.238647,0.008714,0.003801,0.096557,239.582703,12.204926,0.965568,-101.238647,0.096748,0.000000
92.110001,53.836494,-101.238647,0.008688,0.003801,0.096557,239.476685,12.199524,0.965568,-101.238647,0.096748,0.000000
92.340004,53.808197,-101.238647,0.008701,0.003801,0.096557,239.350815,12.193111,0.965568,-101.238647,0.096748,0.000000
92.570007,53.775429,-101.238647,0.008714,0.003801,0.096557,239.205048,12.185686,0.965568,-101.238647,0.096748,0.000000
92.800003,53.744888,-101.194160,0.008722,0.003801,0.096557,239.069199,12.178765,0.965568,-101.194160,0.096748,0.000000
93.030006,53.713982,-101.238647,0.008705,0.003801,0.096557,238.931717,12.171762,0.965568,-101.238647,0.096748,0.000000
93.260002,53.689034,-101.238647,0.008714,0.003801,0.096557,238.820755,12.166108,0.965568,-101.238647,0.096748,0.000000
93.490005,53.661110,-101.238647,0.008701,0.003801,0.096557,238.696533,12.159781,0.965568,-101.238647,0.096748,0.000000
93.720001,53.624985,-101.283127,0.008701,0.003801,0.096557,238.535843,12.151595,0.965568,-101.283127,0.096748,0.000000
93.950005,53.607857,-101.283127,0.008705,0.003801,0.096557,238.459656,12.147714,0.965568,-101.283127,0.096748,0.000000
94.180008,53.590355,-101.283127,0.008718,0.003801,0.096557,238.381805,12.143748,0.965568,-101.283127,0.096748,0.000000
94.410004,53.557961,-101.283127,0.008692,0.003801,0.096557,238.237701,12.136408,0.965568,-101.283127,0.096748,0.000000
94.640007,53.522209,-101.283127,0.008714,0.003801,0.096557,238.078674,12.128306,0.965568,-101.283127,0.096748,0.000000
94.870003,53.502106,-101.283127,0.008709,0.003801,0.096557,237.989258,12.123751,0.965568,-101.283127,0.096748,0.000000
95.100006,53.479019,-101.283127,0.008727,0.003801,0.096557,237.886551,12.118519,0.965568,-101.283127,0.096748,0.000000
95.330002,53.445129,-101.372086,0.008696,0.003801,0.096557,237.735809,12.110839,0.965568,-101.372086,0.096748,0.000000
95.560005,53.428375,-101.372086,0.008705,0.003801,0.096557,237.661285,12.107042,0.965568,-101.372086,0.096748,0.000000
95.790001,53.407524,-101.327606,0.008696,0.003801,0.096557,237.568527,12.102318,0.965568,-101.327606,0.096748,0.000000
96.020004,53.389648,-101.283127,0.008705,0.003801,0.096557,237.489014,12.098268,0.965568,-101.283127,0.096748,0.000000
96.250008,53.364700,-101.372086,0.008705,0.003801,0.096557,237.378036,12.092614,0.965568,-101.372086,0.096748,0.000000
96.480003,53.336029,-101.327606,0.008714,0.003801,0.096557,237.250504,12.086117,0.965568,-101.327606,0.096748,0.000000
96.710007,53.306984,-101.416565,0.008705,0.003801,0.096557,237.121307,12.079535,0.965568,-101.416565,0.096748,0.000000
96.940002,53.287621,-101.416565,0.008722,0.003801,0.096557,237.035172,12.075148,0.965568,-101.416565,0.096748,0.000000
97.170006,53.269371,-101.327606,0.008714,0.003801,0.096557,236.953995,12.071012,0.965568,-101.327606,0.096748,0.000000
97.400002,53.253731,-101.372086,0.008718,0.003801,0.096557,236.884430,12.067468,0.965568,-101.372086,0.096748,0.000000
97.630005,53.238091,-101.416565,0.008709,0.003801,0.096557,236.814850,12.063924,0.965568,-101.416565,0.096748,0.000000
97.860008,53.212029,-101.416565,0.008735,0.003801,0.096557,236.698929,12.058019,0.965568,-101.416565,0.096748,0.000000
98.090004,53.182610,-101.416565,0.008692,0.003801,0.096557,236.568069,12.051352,0.965568,-101.416565,0.096748,0.000000
98.200005,53.174416,-101.327606,0.008705,0.003801,0.096557,236.531616,12.049495,0.965568,-101.327606,0.096748,0.000000