File: Data/Automembrane/AutoHeating-12wt-1-1_12152023_174451.csv
Time (sec),S:Load (lbs),S:HL1 (DIM),S:LVDT (in),S:Position (in),Ch:Position (mm),Ch:Load (N),Ch:Stress (MPa),Ch:Strain (mm/mm),Ch:HL1 (DIM),Set Point (),Cycles ()
0.110000,0.015633,-222.271317,-0.000034,-0.000000,-0.000000,0.069537,0.003542,-0.000000,-222.271317,0.000148,0.000000
0.350000,0.011169,-222.360275,-0.000013,-0.000000,-0.000000,0.049684,0.002531,-0.000000,-222.360275,0.000286,0.000000
0.590000,0.027176,-222.315796,-0.000013,0.000135,0.003417,0.120884,0.006158,0.034170,-222.315796,0.004293,0.000000
0.830000,-0.000000,-222.315796,0.000112,0.000286,0.007276,-0.000000,-0.000000,0.072761,-222.315796,0.008282,0.000000
1.070000,-0.011177,-222.315796,0.000267,0.000442,0.011222,-0.049718,-0.002533,0.112218,-222.315796,0.012288,0.000000
1.310000,0.013031,-222.226837,0.000431,0.000599,0.015202,0.057965,0.002953,0.152024,-222.226837,0.016278,0.000000
1.550000,-0.002609,-222.404755,0.000612,0.000757,0.019235,-0.011607,-0.000591,0.192352,-222.404755,0.020284,0.000000
1.790000,-0.031281,-222.315796,0.000759,0.000914,0.023216,-0.139143,-0.007088,0.232158,-222.315796,0.024274,0.000000
2.030000,-0.020485,-222.360275,0.000927,0.001072,0.027222,-0.091121,-0.004642,0.272221,-222.360275,0.028280,0.000000
2.270000,0.024948,-222.315796,0.001099,0.001228,0.031203,0.110975,0.005653,0.312027,-222.315796,0.032270,0.000000
2.510000,0.082664,-222.404755,0.001224,0.001378,0.035010,0.367710,0.018732,0.350099,-222.404755,0.036276,0.000000
2.750000,0.245018,-222.360275,0.001397,0.001544,0.039216,1.089895,0.055522,0.392161,-222.360275,0.040265,0.000000
2.990000,0.483711,-222.315796,0.001591,0.001701,0.043197,2.151655,0.109611,0.431966,-222.315796,0.044272,0.000000
3.230000,0.590950,-222.404755,0.001664,-0.000005,-0.000121,2.628677,0.133911,-0.001215,-222.404755,-0.000035,0.000000
3.470000,0.539940,-222.404755,0.001690,-0.000005,-0.000121,2.401772,0.122352,-0.001215,-222.404755,-0.000035,0.000000
3.710000,0.517593,-222.360275,0.001669,-0.000005,-0.000121,2.302370,0.117288,-0.001215,-222.360275,0.000165,0.000000
3.950000,0.512009,-222.449234,0.001686,-0.000005,-0.000121,2.277528,0.116023,-0.001215,-222.449234,0.000564,0.000000
4.190000,0.540680,-222.360275,0.001686,0.000007,0.000173,2.405064,0.122520,0.001733,-222.360275,0.000962,0.000000
4.430000,0.628189,-222.493713,0.001673,0.000022,0.000555,2.794325,0.142350,0.005549,-222.493713,0.001361,0.000000
4.670000,0.693726,-222.404755,0.001694,0.000036,0.000919,3.085845,0.157200,0.009194,-222.404755,0.001760,0.000000
4.910000,0.745483,-222.449234,0.001725,0.000050,0.001266,3.316076,0.168929,0.012660,-222.449234,0.002168,0.000000
5.150000,0.832253,-222.493713,0.001729,0.000068,0.001717,3.702044,0.188591,0.017172,-222.493713,0.002567,0.000000
5.390000,0.906723,-222.449234,0.001746,0.000081,0.002046,4.033306,0.205466,0.020465,-222.449234,0.002966,0.000000
5.630000,0.920876,-222.449234,0.001742,0.000093,0.002359,4.096259,0.208673,0.023587,-222.449234,0.003365,0.000000
5.870000,0.994606,-222.449234,0.001776,0.000110,0.002784,4.424229,0.225381,0.027838,-222.449234,0.003764,0.000000
6.110000,1.128288,-222.449234,0.001768,0.000133,0.003382,5.018877,0.255674,0.033822,-222.449234,0.004163,0.000000
6.350000,1.164032,-222.538193,0.001811,0.000150,0.003799,5.177873,0.263773,0.037985,-222.538193,0.004562,0.000000
6.590000,1.211693,-222.404755,0.001832,0.000162,0.004111,5.389879,0.274574,0.041108,-222.404755,0.004960,0.000000
6.830000,1.260101,-222.538193,0.001850,0.000176,0.004466,5.605211,0.285543,0.044662,-222.538193,0.005368,0.000000
7.070000,1.310371,-222.449234,0.001850,0.000189,0.004813,5.828823,0.296934,0.048133,-222.449234,0.005767,0.000000
7.310000,1.451508,-222.493713,0.001854,0.000209,0.005316,6.456628,0.328916,0.053163,-222.493713,0.006166,0.000000
7.550000,1.447411,-222.538193,0.001871,0.000221,0.005620,6.438404,0.327988,0.056198,-222.538193,0.006565,0.000000
7.790000,1.587051,-222.493713,0.001901,0.000237,0.006018,7.059557,0.359631,0.060184,-222.493713,0.006964,0.000000
8.030001,1.626144,-222.493713,0.001919,0.000253,0.006435,7.233451,0.368490,0.064347,-222.493713,0.007363,0.000000
8.270000,1.743446,-222.493713,0.001919,0.000274,0.006955,7.755237,0.395071,0.069551,-222.493713,0.007762,0.000000
8.510000,1.756851,-222.493713,0.001936,0.000288,0.007311,7.814865,0.398108,0.073105,-222.493713,0.008161,0.000000
8.750000,1.767273,-222.582672,0.001966,0.000300,0.007614,7.861223,0.400470,0.076141,-222.582672,0.008568,0.000000
8.990001,1.905800,-222.493713,0.001970,0.000319,0.008091,8.477421,0.431860,0.080913,-222.493713,0.008967,0.000000
9.230000,2.010811,-222.538193,0.001992,0.000336,0.008533,8.944533,0.455656,0.085334,-222.538193,0.009366,0.000000
9.470000,1.981018,-222.493713,0.002001,0.000346,0.008785,8.812009,0.448905,0.087851,-222.493713,0.009765,0.000000
9.710000,2.160500,-222.538193,0.002031,0.000365,0.009279,9.610382,0.489576,0.092794,-222.538193,0.010164,0.000000
9.950001,2.151566,-222.582672,0.002035,0.000378,0.009600,9.570642,0.487552,0.096000,-222.582672,0.010563,0.000000
10.190001,2.268120,-222.582672,0.002070,0.000398,0.010112,10.089101,0.513963,0.101117,-222.582672,0.010962,0.000000
10.430000,2.256203,-222.538193,0.002082,0.000408,0.010372,10.036091,0.511263,0.103721,-222.538193,0.011361,0.000000
10.670000,2.366051,-222.582672,0.002095,0.000426,0.010814,10.524719,0.536155,0.108142,-222.582672,0.011768,0.000000
10.910001,2.516861,-222.627167,0.002087,0.000445,0.011309,11.195557,0.570329,0.113085,-222.627167,0.012167,0.000000
11.150001,2.606979,-222.582672,0.002143,0.000463,0.011768,11.596423,0.590750,0.117684,-222.582672,0.012566,0.000000
11.390000,2.559685,-222.627167,0.002139,0.000472,0.011994,11.386046,0.580033,0.119936,-222.627167,0.012965,0.000000
11.630000,2.703049,-222.627167,0.002164,0.000488,0.012393,12.023761,0.612520,0.123925,-222.627167,0.013364,0.000000
11.870001,2.830399,-222.582672,0.002182,0.000507,0.012878,12.590241,0.641378,0.128785,-222.582672,0.013763,0.000000
12.110001,2.918282,-222.671646,0.002177,0.000525,0.013329,12.981165,0.661292,0.133293,-222.671646,0.014162,0.000000
12.350000,2.922379,-222.671646,0.002190,0.000539,0.013702,12.999389,0.662220,0.137021,-222.671646,0.014561,0.000000
12.590000,2.938019,-222.671646,0.002207,0.000552,0.014023,13.068960,0.665765,0.140230,-222.671646,0.014969,0.000000
12.830001,3.086967,-222.671646,0.002229,0.000568,0.014439,13.731517,0.699517,0.144394,-222.671646,0.015367,0.000000
13.070001,3.261238,-222.627167,0.002281,0.000588,0.014942,14.506712,0.739007,0.149424,-222.627167,0.015766,0.000000
13.310000,3.209099,-222.671646,0.002259,0.000597,0.015159,14.274784,0.727192,0.151593,-222.671646,0.016165,0.000000
13.550000,3.377045,-222.716125,0.002259,0.000615,0.015627,15.021845,0.765249,0.156275,-222.716125,0.016564,0.000000
13.790001,3.412788,-222.716125,0.002285,0.000629,0.015983,15.180840,0.773349,0.159829,-222.716125,0.016963,0.000000
14.030001,3.674942,-222.716125,0.002302,0.000651,0.016547,16.346958,0.832754,0.165468,-222.716125,0.017362,0.000000
14.270000,3.660789,-222.671646,0.002333,0.000665,0.016894,16.284004,0.829547,0.168935,-222.671646,0.017769,0.000000
14.510000,3.727074,-222.716125,0.002328,0.000681,0.017292,16.578852,0.844567,0.172924,-222.716125,0.018168,0.000000
14.750001,3.875648,-222.760605,0.002363,0.000699,0.017761,17.239746,0.878235,0.177606,-222.760605,0.018567,0.000000
14.990001,3.985123,-222.716125,0.002380,0.000714,0.018134,17.726711,0.903042,0.181338,-222.716125,0.018966,0.000000
15.230000,4.044708,-222.760605,0.002393,0.000727,0.018472,17.991760,0.916544,0.184718,-222.760605,0.019365,0.000000
15.470000,4.079712,-222.716125,0.002402,0.000739,0.018758,18.147465,0.924476,0.187579,-222.716125,0.019764,0.000000
15.710001,4.153442,-222.760605,0.002423,0.000754,0.019140,18.475435,0.941183,0.191398,-222.760605,0.020163,0.000000
15.950001,4.477028,-222.716125,0.002440,0.000777,0.019738,19.914814,1.014509,0.197382,-222.716125,0.020562,0.000000
16.190001,4.478523,-222.760605,0.002471,0.000792,0.020111,19.921467,1.014848,0.201110,-222.760605,0.020969,0.000000
16.430000,4.478149,-222.805084,0.002471,0.000805,0.020440,19.919804,1.014763,0.204403,-222.805084,0.021368,0.000000
16.670000,4.550385,-222.760605,0.002462,0.000820,0.020822,20.241121,1.031132,0.208222,-222.760605,0.021767,0.000000
16.910002,4.791313,-222.760605,0.002501,0.000842,0.021394,21.312826,1.085727,0.213945,-222.760605,0.022166,0.000000
17.150002,4.765991,-222.805084,0.002505,0.000853,0.021672,21.200188,1.079989,0.216719,-222.805084,0.022565,0.000000
17.390001,4.814774,-222.760605,0.002518,0.000867,0.022028,21.417183,1.091043,0.220277,-222.760605,0.022964,0.000000
17.630001,4.796524,-222.805084,0.002557,0.000878,0.022305,21.336004,1.086908,0.223051,-222.805084,0.023363,0.000000
17.870001,5.248955,-222.760605,0.002570,0.000905,0.022990,23.348516,1.189430,0.229902,-222.760605,0.023762,0.000000
18.110001,5.186775,-222.849564,0.002557,0.000918,0.023328,23.071928,1.175340,0.233282,-222.849564,0.024170,0.000000
18.350000,5.280609,-222.849564,0.002574,0.000934,0.023727,23.489323,1.196603,0.237271,-222.849564,0.024569,0.000000
18.590000,5.231461,-222.849564,0.002621,0.000947,0.024048,23.270699,1.185466,0.240481,-222.849564,0.024967,0.000000
18.830002,5.496590,-222.894043,0.002647,0.000965,0.024508,24.450052,1.245545,0.245080,-222.894043,0.025366,0.000000
19.070002,5.538292,-222.805084,0.002639,0.000981,0.024924,24.635553,1.254995,0.249239,-222.805084,0.025765,0.000000
19.310001,5.556168,-222.805084,0.002652,0.000993,0.025210,24.715067,1.259046,0.252104,-222.805084,0.026164,0.000000
19.550001,5.700645,-222.849564,0.002669,0.001009,0.025618,25.357737,1.291785,0.256177,-222.849564,0.026563,0.000000
19.790001,5.985886,-222.849564,0.002677,0.001033,0.026233,26.626549,1.356421,0.262335,-222.849564,0.026962,0.000000
20.030001,5.935242,-222.938522,0.002712,0.001047,0.026598,26.401274,1.344945,0.265980,-222.938522,0.027370,0.000000
20.270000,5.833214,-222.849564,0.002734,0.001060,0.026919,25.947432,1.321825,0.269186,-222.849564,0.027769,0.000000
20.510000,5.882736,-222.894043,0.002751,0.001073,0.027257,26.167717,1.333047,0.272569,-222.894043,0.028168,0.000000
20.750002,6.127388,-222.849564,0.002768,0.001094,0.027786,27.255983,1.388486,0.277860,-222.849564,0.028566,0.000000
20.990002,6.154198,-222.849564,0.002768,0.001108,0.028133,27.375238,1.394561,0.281327,-222.849564,0.028965,0.000000
21.230001,6.136322,-222.938522,0.002781,0.001120,0.028436,27.295723,1.390510,0.284363,-222.938522,0.029364,0.000000
21.470001,6.341499,-222.894043,0.002811,0.001140,0.028948,28.208397,1.437004,0.289480,-222.894043,0.029763,0.000000
21.710001,6.463638,-222.938522,0.002824,0.001157,0.029390,28.751699,1.464681,0.293905,-222.938522,0.030162,0.000000
21.950001,6.512047,-222.849564,0.002833,0.001173,0.029798,28.967031,1.475651,0.297977,-222.849564,0.030570,0.000000
22.190001,6.423424,-222.938522,0.002859,0.001187,0.030145,28.572817,1.455569,0.301448,-222.938522,0.030969,0.000000
22.430000,6.390656,-222.938522,0.002854,0.001198,0.030422,28.427055,1.448143,0.304222,-222.938522,0.031368,0.000000
22.670002,6.579819,-222.938522,0.002884,0.001218,0.030943,29.268496,1.491008,0.309427,-222.938522,0.031767,0.000000
22.910002,6.622269,-222.983002,0.002889,0.001231,0.031272,29.457323,1.500628,0.312723,-222.983002,0.032166,0.000000
23.150002,6.666580,-222.938522,0.002915,0.001246,0.031654,29.654430,1.510669,0.316538,-222.938522,0.032564,0.000000
23.390001,6.606628,-222.938522,0.002915,0.001261,0.032018,29.387751,1.497083,0.320179,-222.938522,0.032963,0.000000
23.630001,6.878464,-222.983002,0.002928,0.001281,0.032547,30.596935,1.558682,0.325471,-222.983002,0.033362,0.000000
23.870001,6.803986,-222.983002,0.002953,0.001295,0.032894,30.265640,1.541805,0.328938,-222.983002,0.033770,0.000000
24.110001,6.913460,-222.983002,0.002988,0.001313,0.033362,30.752605,1.566612,0.333623,-222.983002,0.034169,0.000000
24.350000,6.887024,-222.938522,0.002997,0.001326,0.033683,30.635012,1.560622,0.336829,-222.938522,0.034567,0.000000
24.590002,7.000595,-222.938522,0.003009,0.001346,0.034177,31.140202,1.586357,0.341772,-222.938522,0.034966,0.000000
24.830002,6.952560,-223.027481,0.003022,0.001357,0.034463,30.926533,1.575473,0.344634,-223.027481,0.035365,0.000000
25.070002,6.853882,-222.938522,0.003048,0.001368,0.034750,30.487589,1.553112,0.347499,-222.938522,0.035764,0.000000
25.310001,7.250092,-223.027481,0.003078,0.001393,0.035391,32.250019,1.642894,0.353914,-223.027481,0.036163,0.000000
25.550001,7.189392,-223.027481,0.003074,0.001407,0.035738,31.980013,1.629140,0.357385,-223.027481,0.036562,0.000000
25.790001,7.176361,-223.071976,0.003096,0.001422,0.036120,31.922049,1.626187,0.361200,-223.071976,0.036970,0.000000
26.030001,7.240776,-223.027481,0.003113,0.001440,0.036579,32.208580,1.640783,0.365795,-223.027481,0.037369,0.000000
26.270000,7.122368,-223.027481,0.003122,0.001450,0.036840,31.681875,1.613952,0.368399,-223.027481,0.037768,0.000000
26.510002,7.233330,-223.071976,0.003134,0.001468,0.037299,32.175457,1.639096,0.372994,-223.071976,0.038167,0.000000
26.750002,7.235191,-223.116455,0.003152,0.001481,0.037620,32.183739,1.639518,0.376203,-223.116455,0.038565,0.000000
26.990002,7.298500,-223.027481,0.003156,0.001495,0.037976,32.465351,1.653864,0.379757,-223.027481,0.038964,0.000000
27.230001,7.619858,-223.071976,0.003203,0.001518,0.038565,33.894821,1.726684,0.385654,-223.071976,0.039363,0.000000
27.470001,7.653366,-223.027481,0.003212,0.001536,0.039017,34.043873,1.734278,0.390166,-223.027481,0.039771,0.000000
27.710001,7.540535,-223.027481,0.003216,0.001551,0.039389,33.541973,1.708710,0.393894,-223.027481,0.040170,0.000000
27.950001,7.463089,-223.071976,0.003238,0.001564,0.039719,33.197479,1.691160,0.397191,-223.071976,0.040569,0.000000
28.190001,7.489151,-223.116455,0.003238,0.001579,0.040101,33.313408,1.697066,0.401006,-223.116455,0.040968,0.000000
28.430002,7.527878,-223.071976,0.003264,0.001595,0.040508,33.485672,1.705842,0.405082,-223.071976,0.041367,0.000000
28.670002,7.655975,-223.071976,0.003272,0.001612,0.040942,34.055481,1.734869,0.409416,-223.071976,0.041766,0.000000
28.910002,7.502930,-223.116455,0.003298,0.001622,0.041193,33.374699,1.700188,0.411933,-223.116455,0.042164,0.000000
29.150002,7.720398,-223.116455,0.003303,0.001642,0.041696,34.342045,1.749467,0.416963,-223.116455,0.042563,0.000000
29.390001,7.728584,-223.160934,0.003324,0.001657,0.042095,34.378460,1.751322,0.420952,-223.160934,0.042971,0.000000
29.630001,7.861893,-223.116455,0.003333,0.001676,0.042581,34.971447,1.781530,0.425808,-223.116455,0.043370,0.000000
29.870001,7.767685,-223.116455,0.003376,0.001690,0.042928,34.552387,1.760183,0.429275,-223.116455,0.043769,0.000000
30.110001,7.572563,-223.160934,0.003350,0.001700,0.043171,33.684444,1.715967,0.431705,-223.160934,0.044168,0.000000
30.350002,7.928925,-223.160934,0.003380,0.001722,0.043751,35.269619,1.796720,0.437515,-223.160934,0.044567,0.000000
30.590002,7.922218,-223.160934,0.003406,0.001737,0.044124,35.239788,1.795200,0.441243,-223.160934,0.044966,0.000000
30.830002,7.760612,-223.205414,0.003415,0.001748,0.044402,34.520927,1.758580,0.444021,-223.205414,0.045365,0.000000
31.070002,7.956482,-223.160934,0.003436,0.001768,0.044905,35.392200,1.802965,0.449051,-223.160934,0.045764,0.000000
31.310001,8.022018,-223.205414,0.003462,0.001784,0.045321,35.683720,1.817815,0.453211,-223.205414,0.046171,0.000000
31.550001,8.072662,-223.116455,0.003462,0.001801,0.045755,35.908997,1.829291,0.457548,-223.116455,0.046570,0.000000
31.790001,8.050316,-223.205414,0.003462,0.001817,0.046162,35.809593,1.824228,0.461625,-223.205414,0.046969,0.000000
32.030003,7.871208,-223.249893,0.003479,0.001828,0.046431,35.012882,1.783641,0.464312,-223.249893,0.047368,0.000000
32.270000,8.008240,-223.160934,0.003497,0.001845,0.046865,35.622429,1.814693,0.468649,-223.160934,0.047767,0.000000
32.510002,8.220490,-223.294373,0.003523,0.001864,0.047351,36.566563,1.862790,0.473505,-223.294373,0.048166,0.000000
32.750000,8.014198,-223.160934,0.003523,0.001875,0.047619,35.648933,1.816043,0.476193,-223.160934,0.048565,0.000000
32.990002,8.105797,-223.294373,0.003523,0.001891,0.048027,36.056385,1.836800,0.480269,-223.294373,0.048964,0.000000
33.230003,8.264427,-223.249893,0.003574,0.001909,0.048495,36.762009,1.872746,0.484951,-223.249893,0.049371,0.000000
33.470001,8.296082,-223.294373,0.003570,0.001927,0.048946,36.902813,1.879919,0.489463,-223.294373,0.049770,0.000000
33.710003,8.246933,-223.338852,0.003604,0.001942,0.049336,36.684189,1.868782,0.493365,-223.338852,0.050169,0.000000
33.950001,8.151978,-223.205414,0.003600,0.001954,0.049623,36.261806,1.847265,0.496226,-223.205414,0.050568,0.000000
34.190002,8.226822,-223.294373,0.003617,0.001973,0.050117,36.594730,1.864224,0.501169,-223.294373,0.050967,0.000000
34.430000,8.459923,-223.294373,0.003656,0.001992,0.050594,37.631615,1.917046,0.505938,-223.294373,0.051366,0.000000
34.670002,8.130005,-223.205414,0.003652,0.002000,0.050802,36.164066,1.842286,0.508020,-223.205414,0.051765,0.000000
34.910000,8.287148,-223.294373,0.003656,0.002016,0.051201,36.863071,1.877895,0.512009,-223.294373,0.052164,0.000000
35.150002,8.574242,-223.249893,0.003686,0.002038,0.051765,38.140133,1.942951,0.517649,-223.249893,0.052571,0.000000
35.390003,8.619675,-223.338852,0.003704,0.002055,0.052198,38.342228,1.953246,0.521982,-223.338852,0.052970,0.000000
35.630001,8.472961,-223.294373,0.003712,0.002068,0.052519,37.689613,1.920001,0.525192,-223.294373,0.053369,0.000000
35.870003,8.432373,-223.294373,0.003704,0.002084,0.052944,37.509068,1.910803,0.529442,-223.294373,0.053768,0.000000
36.110001,8.519875,-223.383331,0.003729,0.002100,0.053352,37.898296,1.930631,0.533519,-223.383331,0.054167,0.000000
36.350002,8.573128,-223.294373,0.003747,0.002116,0.053742,38.135178,1.942698,0.537421,-223.294373,0.054566,0.000000
36.590000,8.478546,-223.338852,0.003773,0.002129,0.054089,37.714458,1.921266,0.540888,-223.338852,0.054965,0.000000
36.830002,8.350822,-223.338852,0.003790,0.002137,0.054280,37.146313,1.892323,0.542796,-223.338852,0.055364,0.000000
37.070004,8.519508,-223.294373,0.003798,0.002154,0.054713,37.896667,1.930548,0.547133,-223.294373,0.055771,0.000000
37.310001,8.920547,-223.383331,0.003807,0.002181,0.055390,39.680576,2.021425,0.553897,-223.383331,0.056170,0.000000
37.550003,8.719101,-223.338852,0.003842,0.002193,0.055693,38.784496,1.975777,0.556932,-223.338852,0.056569,0.000000
37.790001,8.655418,-223.383331,0.003829,0.002207,0.056049,38.501225,1.961346,0.560486,-223.383331,0.056968,0.000000
38.030003,8.846451,-223.338852,0.003850,0.002226,0.056535,39.350979,2.004634,0.565346,-223.338852,0.057367,0.000000
38.270000,8.976776,-223.338852,0.003872,0.002244,0.057003,39.930695,2.034167,0.570028,-223.338852,0.057766,0.000000
38.510002,8.757080,-223.383331,0.003906,0.002256,0.057298,38.953438,1.984383,0.572976,-223.383331,0.058165,0.000000
38.750000,8.735107,-223.338852,0.003906,0.002269,0.057636,38.855698,1.979404,0.576360,-223.338852,0.058564,0.000000
38.990002,8.885178,-223.427811,0.003932,0.002287,0.058095,39.523243,2.013410,0.580955,-223.427811,0.058971,0.000000
39.230003,9.048645,-223.383331,0.003954,0.002306,0.058564,40.250381,2.050452,0.585637,-223.383331,0.059370,0.000000
39.470001,8.891502,-223.383331,0.003958,0.002317,0.058859,39.551376,2.014843,0.588585,-223.383331,0.059769,0.000000
39.710003,8.970451,-223.427811,0.003949,0.002336,0.059327,39.902561,2.032733,0.593271,-223.427811,0.060168,0.000000
39.950001,8.980133,-223.383331,0.003988,0.002351,0.059717,39.945625,2.034927,0.597173,-223.383331,0.060567,0.000000
40.190002,9.093704,-223.427811,0.004001,0.002366,0.060108,40.450817,2.060663,0.601075,-223.427811,0.060966,0.000000
40.430000,9.178230,-223.383331,0.004010,0.002383,0.060532,40.826809,2.079817,0.605322,-223.383331,0.061365,0.000000
40.670002,8.983856,-223.472305,0.004001,0.002393,0.060784,39.962189,2.035771,0.607839,-223.472305,0.061773,0.000000
40.910004,9.209137,-223.472305,0.004040,0.002413,0.061278,40.964287,2.086820,0.612782,-223.472305,0.062171,0.000000
41.150002,9.393089,-223.427811,0.004066,0.002434,0.061816,41.782547,2.128505,0.618157,-223.427811,0.062570,0.000000
41.390003,9.192009,-223.516785,0.004053,0.002448,0.062189,40.888100,2.082939,0.621889,-223.516785,0.062969,0.000000
41.630001,9.165947,-223.472305,0.004070,0.002462,0.062536,40.772167,2.077033,0.625355,-223.472305,0.063368,0.000000
41.870003,9.078064,-223.427811,0.004083,0.002475,0.062865,40.381245,2.057119,0.628652,-223.427811,0.063767,0.000000
42.110001,9.423256,-223.472305,0.004087,0.002495,0.063368,41.916737,2.135340,0.633682,-223.472305,0.064166,0.000000
42.350002,9.311539,-223.472305,0.004135,0.002507,0.063680,41.419792,2.110025,0.636805,-223.472305,0.064565,0.000000
42.590000,9.174881,-223.472305,0.004135,0.002518,0.063967,40.811909,2.079058,0.639666,-223.472305,0.064973,0.000000
42.830002,9.554703,-223.516785,0.004174,0.002542,0.064556,42.501442,2.165127,0.645563,-223.516785,0.065372,0.000000
43.070004,9.598640,-223.516785,0.004178,0.002558,0.064981,42.696884,2.175083,0.649813,-223.516785,0.065770,0.000000
43.310001,9.472404,-223.561264,0.004195,0.002573,0.065345,42.135361,2.146477,0.653455,-223.561264,0.066169,0.000000
43.550003,9.402771,-223.516785,0.004199,0.002587,0.065701,41.825615,2.130698,0.657009,-223.516785,0.066568,0.000000
43.790001,9.359207,-223.561264,0.004191,0.002601,0.066074,41.631832,2.120826,0.660740,-223.561264,0.066967,0.000000
44.030003,9.524910,-223.516785,0.004225,0.002618,0.066499,42.368916,2.158376,0.664987,-223.516785,0.067366,0.000000
44.270000,9.461609,-223.650223,0.004243,0.002633,0.066889,42.087337,2.144031,0.668889,-223.650223,0.067765,0.000000
44.510002,9.451180,-223.516785,0.004260,0.002647,0.067227,42.040947,2.141668,0.672273,-223.516785,0.068173,0.000000
44.750004,9.717430,-223.516785,0.004255,0.002667,0.067730,43.225288,2.202001,0.677303,-223.516785,0.068572,0.000000
44.990002,9.697319,-223.561264,0.004277,0.002682,0.068112,43.135830,2.197444,0.681118,-223.561264,0.068971,0.000000
45.230003,9.788551,-223.516785,0.004290,0.002699,0.068563,43.541653,2.218117,0.685630,-223.516785,0.069370,0.000000
45.470001,9.770676,-223.561264,0.004333,0.002714,0.068927,43.462135,2.214067,0.689271,-223.561264,0.069768,0.000000
45.710003,9.621727,-223.561264,0.004363,0.002725,0.069205,42.799580,2.180315,0.692045,-223.561264,0.070167,0.000000
45.950001,9.943085,-223.650223,0.004350,0.002747,0.069768,44.229050,2.253135,0.697685,-223.650223,0.070566,0.000000
46.190002,9.735672,-223.650223,0.004355,0.002758,0.070055,43.306431,2.206135,0.700546,-223.650223,0.070965,0.000000
46.430000,9.636620,-223.561264,0.004389,0.002769,0.070332,42.865826,2.183689,0.703321,-223.561264,0.071373,0.000000
46.670002,10.181404,-223.650223,0.004415,0.002792,0.070922,45.289146,2.307139,0.709217,-223.650223,0.071771,0.000000
46.910004,10.197792,-223.605743,0.004428,0.002810,0.071381,45.362045,2.310853,0.713812,-223.605743,0.072170,0.000000
47.150002,10.098740,-223.605743,0.004428,0.002824,0.071728,44.921436,2.288407,0.717283,-223.605743,0.072569,0.000000
47.390003,10.247688,-223.605743,0.004449,0.002841,0.072153,45.583996,2.322160,0.721533,-223.605743,0.072968,0.000000
47.630001,10.103577,-223.605743,0.004441,0.002854,0.072500,44.942955,2.289503,0.725000,-223.605743,0.073367,0.000000
47.870003,10.232788,-223.694702,0.004484,0.002869,0.072864,45.517715,2.318783,0.728642,-223.694702,0.073766,0.000000
48.110001,10.406693,-223.650223,0.004475,0.002884,0.073263,46.291279,2.358190,0.732631,-223.650223,0.074165,0.000000
48.350002,10.200768,-223.650223,0.004506,0.002894,0.073506,45.375278,2.311527,0.735061,-223.650223,0.074573,0.000000
48.590004,10.811089,-223.694702,0.004518,0.002919,0.074131,48.090122,2.449828,0.741306,-223.694702,0.074972,0.000000
48.830002,10.934341,-223.694702,0.004523,0.002937,0.074590,48.638378,2.477757,0.745901,-223.694702,0.075371,0.000000
49.070004,10.821884,-223.694702,0.004557,0.002953,0.074998,48.138145,2.452274,0.749977,-223.694702,0.075769,0.000000
49.310001,10.802521,-223.694702,0.004566,0.002965,0.075310,48.052013,2.447886,0.753100,-223.694702,0.076168,0.000000
49.550003,10.826355,-223.739182,0.004570,0.002979,0.075657,48.158031,2.453287,0.756566,-223.739182,0.076567,0.000000
49.790001,11.126488,-223.694702,0.004579,0.002997,0.076117,49.493088,2.521298,0.761165,-223.694702,0.076966,0.000000
50.030003,11.282883,-223.694702,0.004622,0.003013,0.076541,50.188770,2.556738,0.765412,-223.694702,0.077365,0.000000
50.270004,10.985359,-223.783661,0.004613,0.003022,0.076758,48.865318,2.489318,0.767581,-223.783661,0.077773,0.000000
50.510002,11.509285,-223.739182,0.004618,0.003044,0.077313,51.195858,2.608041,0.773133,-223.739182,0.078172,0.000000
50.750004,11.658607,-223.739182,0.004652,0.003060,0.077721,51.860077,2.641878,0.777209,-223.739182,0.078571,0.000000
50.990002,11.897293,-223.739182,0.004669,0.003078,0.078180,52.921803,2.695965,0.781804,-223.739182,0.078970,0.000000
51.230003,11.788193,-223.739182,0.004678,0.003091,0.078501,52.436501,2.671242,0.785014,-223.739182,0.079368,0.000000
51.470001,11.940117,-223.828140,0.004691,0.003107,0.078909,53.112293,2.705669,0.789090,-223.828140,0.079767,0.000000
51.710003,12.248444,-223.739182,0.004717,0.003124,0.079351,54.483799,2.775537,0.793511,-223.739182,0.080166,0.000000
51.950001,12.257011,-223.783661,0.004725,0.003139,0.079724,54.521912,2.777479,0.797239,-223.783661,0.080565,0.000000
52.190002,12.173965,-223.783661,0.004734,0.003149,0.079993,54.152504,2.758660,0.799930,-223.783661,0.080973,0.000000
52.430004,12.672951,-223.783661,0.004764,0.003169,0.080487,56.372101,2.871732,0.804873,-223.783661,0.081372,0.000000
52.670002,12.886314,-223.872620,0.004760,0.003185,0.080904,57.321190,2.920081,0.809036,-223.872620,0.081771,0.000000
52.910004,13.174538,-223.783661,0.004777,0.003203,0.081346,58.603271,2.985393,0.813457,-223.783661,0.082170,0.000000
53.150002,13.244171,-223.872620,0.004790,0.003217,0.081701,58.913017,3.001172,0.817015,-223.872620,0.082569,0.000000
53.390003,13.280663,-223.828140,0.004803,0.003232,0.082083,59.075336,3.009441,0.820830,-223.828140,0.082968,0.000000
53.630001,13.737190,-223.783661,0.004829,0.003250,0.082560,61.106075,3.112892,0.825599,-223.783661,0.083366,0.000000
53.870003,13.934921,-223.917114,0.004825,0.003264,0.082898,61.985626,3.157698,0.828983,-223.917114,0.083774,0.000000
54.110004,13.782249,-223.828140,0.004850,0.003275,0.083176,61.306507,3.123102,0.831757,-223.828140,0.084173,0.000000
54.350002,14.277130,-223.872620,0.004863,0.003294,0.083679,63.507847,3.235244,0.836787,-223.872620,0.084572,0.000000
54.590004,14.843132,-223.828140,0.004898,0.003314,0.084182,66.025551,3.363502,0.841817,-223.828140,0.084971,0.000000
54.830002,14.909790,-223.828140,0.004894,0.003327,0.084494,66.322060,3.378607,0.844936,-223.828140,0.085370,0.000000
55.070004,15.091881,-223.917114,0.004894,0.003343,0.084910,67.132042,3.419869,0.849100,-223.917114,0.085769,0.000000
55.310001,15.079216,-223.872620,0.004915,0.003356,0.085248,67.075706,3.416999,0.852483,-223.872620,0.086168,0.000000
55.550003,15.721191,-223.917114,0.004950,0.003374,0.085708,69.931351,3.562473,0.857078,-223.917114,0.086567,0.000000
55.790001,16.118507,-223.917114,0.004941,0.003391,0.086133,71.698700,3.652506,0.861329,-223.917114,0.086974,0.000000
56.030003,15.864922,-223.917114,0.004958,0.003401,0.086393,70.570694,3.595043,0.863929,-223.917114,0.087373,0.000000
56.270004,16.250328,-223.872620,0.004984,0.003415,0.086731,72.285072,3.682377,0.867312,-223.872620,0.087772,0.000000
56.510002,17.225204,-223.872620,0.004980,0.003439,0.087347,76.621536,3.903287,0.873470,-223.872620,0.088171,0.000000
56.750004,17.544701,-224.006073,0.005001,0.003454,0.087737,78.042725,3.975686,0.877373,-224.006073,0.088570,0.000000
56.990002,17.540970,-223.961594,0.005032,0.003467,0.088058,78.026131,3.974840,0.880582,-223.961594,0.088968,0.000000
57.230003,18.061180,-223.917114,0.005027,0.003487,0.088570,80.340141,4.092722,0.885700,-223.917114,0.089367,0.000000
57.470001,18.368385,-224.006073,0.005070,0.003501,0.088917,81.706657,4.162335,0.889166,-224.006073,0.089766,0.000000
57.710003,18.682297,-223.917114,0.005083,0.003515,0.089272,83.103004,4.233469,0.892720,-223.917114,0.090174,0.000000
57.950005,18.898643,-223.961594,0.005083,0.003529,0.089645,84.065361,4.282494,0.896452,-223.961594,0.090573,0.000000
58.190002,18.878166,-223.872620,0.005109,0.003535,0.089801,83.974274,4.277854,0.898012,-223.872620,0.090972,0.000000
58.430004,19.618065,-223.961594,0.005092,0.003556,0.090313,87.265511,4.445517,0.903129,-223.961594,0.091371,0.000000
58.670002,20.932541,-223.961594,0.005105,0.003582,0.090981,93.112595,4.743382,0.909805,-223.961594,0.091770,0.000000
58.910004,20.910202,-224.006073,0.005126,0.003593,0.091267,93.013222,4.738319,0.912667,-224.006073,0.092169,0.000000
59.150002,21.211075,-224.050552,0.005157,0.003608,0.091649,94.351570,4.806499,0.916486,-224.050552,0.092568,0.000000
59.390003,22.317764,-223.961594,0.005182,0.003631,0.092238,99.274376,5.057278,0.922383,-223.961594,0.092966,0.000000
59.630001,22.683807,-224.006073,0.005191,0.003644,0.092568,100.902618,5.140224,0.925676,-224.006073,0.093374,0.000000
59.870003,22.813766,-224.050552,0.005221,0.003658,0.092906,101.480705,5.169673,0.929059,-224.050552,0.093773,0.000000
60.110004,23.349236,-224.050552,0.005213,0.003672,0.093270,103.862587,5.291012,0.932700,-224.050552,0.094172,0.000000
60.350002,23.970726,-224.050552,0.005230,0.003688,0.093686,106.627113,5.431844,0.936864,-224.050552,0.094571,0.000000
60.590004,24.766861,-224.006073,0.005243,0.003707,0.094146,110.168503,5.612251,0.941459,-224.006073,0.094970,0.000000
60.830002,25.128433,-224.050552,0.005243,0.003720,0.094493,111.776855,5.694184,0.944929,-224.050552,0.095369,0.000000
61.070004,25.805779,-224.095032,0.005264,0.003737,0.094909,114.789833,5.847673,0.949093,-224.095032,0.095768,0.000000
61.310001,26.328217,-224.050552,0.005269,0.003752,0.095299,117.113754,5.966059,0.952995,-224.050552,0.096167,0.000000
61.550003,27.029770,-224.095032,0.005269,0.003767,0.095690,120.234421,6.125033,0.956897,-224.095032,0.096574,0.000000
61.790005,27.815102,-224.050552,0.005299,0.003783,0.096089,123.727753,6.302992,0.960886,-224.050552,0.096973,0.000000
62.030003,27.979317,-224.139511,0.005303,0.003792,0.096306,124.458214,6.340204,0.963055,-224.139511,0.097372,0.000000
62.270004,29.035370,-224.095032,0.005333,0.003813,0.096852,129.155777,6.579509,0.968517,-224.095032,0.097771,0.000000
62.510002,30.382607,-224.095032,0.005342,0.003834,0.097390,135.148590,6.884797,0.973895,-224.095032,0.098170,0.000000
62.750004,30.938560,-224.139511,0.005364,0.003849,0.097762,137.621597,7.010778,0.977623,-224.139511,0.098569,0.000000
62.990002,31.396584,-224.139511,0.005385,0.003861,0.098066,139.658981,7.114568,0.980659,-224.139511,0.098968,0.000000
63.230003,31.973015,-224.095032,0.005368,0.003876,0.098447,142.223068,7.245189,0.984474,-224.095032,0.099367,0.000000
63.470001,33.246902,-224.095032,0.005402,0.003895,0.098924,147.889603,7.533856,0.989243,-224.095032,0.099774,0.000000
63.710003,33.719070,-224.095032,0.005407,0.003906,0.099211,149.989914,7.640851,0.992108,-224.095032,0.100173,0.000000
63.950005,34.267197,-224.183990,0.005420,0.003918,0.099514,152.428101,7.765058,0.995140,-224.183990,0.100572,0.000000
64.190002,35.862068,-224.095032,0.005428,0.003941,0.100112,159.522446,8.126461,1.001124,-224.095032,0.100971,0.000000
64.430000,36.852951,-224.139511,0.005445,0.003957,0.100520,163.930115,8.350999,1.005200,-224.139511,0.101370,0.000000
64.670006,37.652069,-224.183990,0.005463,0.003971,0.100867,167.484772,8.532081,1.008671,-224.183990,0.101769,0.000000
64.910004,38.444847,-224.228470,0.005454,0.003987,0.101266,171.011215,8.711727,1.012660,-224.228470,0.102168,0.000000
65.150002,39.223846,-224.228470,0.005484,0.004000,0.101604,174.476379,8.888250,1.016040,-224.228470,0.102567,0.000000
65.389999,40.499222,-224.095032,0.005497,0.004018,0.102064,180.149536,9.177255,1.020639,-224.095032,0.102974,0.000000
65.630005,41.428665,-224.228470,0.005501,0.004035,0.102480,184.283905,9.387869,1.024802,-224.228470,0.103373,0.000000
65.870003,42.333534,-224.183990,0.005536,0.004048,0.102809,188.308960,9.592916,1.028095,-224.183990,0.103772,0.000000
66.110001,43.480812,-224.183990,0.005527,0.004066,0.103278,193.412308,9.852893,1.032781,-224.183990,0.104171,0.000000
66.350006,44.896202,-224.183990,0.005553,0.004083,0.103720,199.708282,10.173625,1.037201,-224.183990,0.104570,0.000000
66.590004,45.859154,-224.228470,0.005558,0.004098,0.104093,203.991699,10.391832,1.040929,-224.228470,0.104969,0.000000
66.830002,46.985954,-224.228470,0.005549,0.004113,0.104466,209.003967,10.647169,1.044661,-224.228470,0.105368,0.000000
67.070000,47.845390,-224.228470,0.005601,0.004124,0.104761,212.826920,10.841921,1.047610,-224.228470,0.105776,0.000000
67.310005,49.473778,-224.272949,0.005588,0.004145,0.105290,220.070358,11.210917,1.052897,-224.272949,0.106175,0.000000
67.550003,50.125427,-224.228470,0.005609,0.004158,0.105602,222.969040,11.358583,1.056020,-224.228470,0.106573,0.000000
67.790001,50.957306,-224.272949,0.005601,0.004166,0.105828,226.669418,11.547091,1.058276,-224.272949,0.106972,0.000000
68.030006,52.957321,-224.317429,0.005588,0.004191,0.106461,235.565933,12.000300,1.064608,-224.317429,0.107371,0.000000
68.270004,54.230461,-224.272949,0.005631,0.004208,0.106885,241.229141,12.288798,1.068854,-224.272949,0.107770,0.000000
68.510002,55.261185,-224.272949,0.005648,0.004220,0.107198,245.814026,12.522364,1.071977,-224.272949,0.108169,0.000000
68.750000,56.574921,-224.272949,0.005657,0.004238,0.107658,251.657822,12.820060,1.076576,-224.272949,0.108568,0.000000
68.990005,57.278328,-224.183990,0.005683,0.004248,0.107909,254.786728,12.979454,1.079089,-224.183990,0.108975,0.000000
69.230003,58.834846,-224.317429,0.005691,0.004266,0.108360,261.710480,13.332168,1.083600,-224.317429,0.109374,0.000000
69.470001,60.101288,-224.228470,0.005683,0.004283,0.108785,267.343872,13.619146,1.087847,-224.228470,0.109773,0.000000
69.710007,60.946571,-224.317429,0.005691,0.004292,0.109028,271.103882,13.810690,1.090277,-224.317429,0.110172,0.000000
69.950005,62.831146,-224.317429,0.005696,0.004315,0.109609,279.486908,14.237741,1.096087,-224.317429,0.110571,0.000000
70.190002,64.642365,-224.272949,0.005717,0.004335,0.110103,287.543610,14.648170,1.101030,-224.272949,0.110970,0.000000
70.430000,65.753525,-224.361923,0.005739,0.004348,0.110450,292.486298,14.899961,1.104501,-224.361923,0.111369,0.000000
70.670006,66.743286,-224.272949,0.005752,0.004361,0.110779,296.888977,15.124245,1.107793,-224.272949,0.111768,0.000000
70.910004,67.409836,-224.361923,0.005773,0.004362,0.110805,299.853912,15.275287,1.108055,-224.361923,0.110996,0.000000
71.150002,67.095932,-224.406403,0.005777,0.004362,0.110788,298.457611,15.204156,1.107880,-224.406403,0.110996,0.000000
71.390007,66.805099,-224.406403,0.005790,0.004362,0.110788,297.163910,15.138252,1.107880,-224.406403,0.110788,0.000000
71.630005,66.563431,-224.361923,0.005782,0.004361,0.110779,296.088928,15.083489,1.107793,-224.361923,0.110788,0.000000
71.870003,66.377991,-224.361923,0.005795,0.004361,0.110779,295.264038,15.041468,1.107793,-224.361923,0.110788,0.000000
72.110001,66.169464,-224.406403,0.005777,0.004361,0.110771,294.336487,14.994215,1.107706,-224.406403,0.110788,0.000000
72.350006,66.009338,-224.361923,0.005799,0.004361,0.110771,293.624207,14.957931,1.107706,-224.361923,0.110788,0.000000
72.590004,65.840668,-224.317429,0.005795,0.004361,0.110771,292.873932,14.919708,1.107706,-224.317429,0.110788,0.000000
72.830002,65.702515,-224.450882,0.005808,0.004361,0.110771,292.259369,14.888402,1.107706,-224.450882,0.110788,0.000000
73.070000,65.572922,-224.406403,0.005799,0.004361,0.110771,291.682922,14.859036,1.107706,-224.406403,0.110788,0.000000
73.310005,65.445953,-224.450882,0.005799,0.004361,0.110771,291.118134,14.830265,1.107706,-224.450882,0.110788,0.000000
73.550003,65.345032,-224.406403,0.005825,0.004361,0.110771,290.669220,14.807396,1.107706,-224.406403,0.110788,0.000000
73.790001,65.235184,-224.450882,0.005795,0.004361,0.110771,290.180603,14.782503,1.107706,-224.450882,0.110788,0.000000
74.030006,65.126816,-224.450882,0.005799,0.004361,0.110762,289.698547,14.757947,1.107619,-224.450882,0.110788,0.000000
74.270004,65.051224,-224.450882,0.005782,0.004361,0.110762,289.362305,14.740818,1.107619,-224.450882,0.110788,0.000000
74.510002,64.945847,-224.495361,0.005821,0.004361,0.110762,288.893555,14.716939,1.107619,-224.495361,0.110788,0.000000
74.750000,64.883286,-224.406403,0.005812,0.004361,0.110762,288.615265,14.702763,1.107619,-224.406403,0.110788,0.000000
74.990005,64.798767,-224.495361,0.005786,0.004361,0.110762,288.239319,14.683610,1.107619,-224.495361,0.110788,0.000000
75.230003,64.729874,-224.495361,0.005812,0.004361,0.110762,287.932861,14.667999,1.107619,-224.495361,0.110788,0.000000
75.470001,64.659866,-224.406403,0.005821,0.004361,0.110762,287.621460,14.652135,1.107619,-224.406403,0.110788,0.000000
75.710007,64.590240,-224.539841,0.005808,0.004361,0.110762,287.311737,14.636357,1.107619,-224.539841,0.110788,0.000000
75.950005,64.542191,-224.450882,0.005808,0.004361,0.110762,287.097992,14.625470,1.107619,-224.450882,0.110788,0.000000
76.190002,64.474060,-224.539841,0.005786,0.004361,0.110762,286.794952,14.610031,1.107619,-224.539841,0.110788,0.000000
76.430000,64.407776,-224.495361,0.005799,0.004361,0.110762,286.500092,14.595011,1.107619,-224.495361,0.110788,0.000000
76.670006,64.372025,-224.450882,0.005821,0.004361,0.110762,286.341064,14.586909,1.107619,-224.450882,0.110788,0.000000
76.910004,64.293457,-224.539841,0.005786,0.004361,0.110762,285.991577,14.569105,1.107619,-224.539841,0.110788,0.000000
77.150002,64.260315,-224.539841,0.005825,0.004361,0.110762,285.844147,14.561596,1.107619,-224.539841,0.110788,0.000000
77.390007,64.201843,-224.539841,0.005799,0.004361,0.110762,285.584076,14.548346,1.107619,-224.539841,0.110788,0.000000
77.630005,64.154556,-224.495361,0.005812,0.004361,0.110762,285.373718,14.537631,1.107619,-224.495361,0.110788,0.000000
77.870003,64.128860,-224.495361,0.005799,0.004361,0.110762,285.259430,14.531808,1.107619,-224.495361,0.110788,0.000000
78.110001,64.066681,-224.584320,0.005816,0.004361,0.110762,284.982819,14.517717,1.107619,-224.584320,0.110788,0.000000
78.350006,64.038010,-224.539841,0.005821,0.004361,0.110762,284.855286,14.511221,1.107619,-224.539841,0.110788,0.000000
78.590004,63.990341,-224.539841,0.005816,0.004361,0.110762,284.643250,14.500418,1.107619,-224.539841,0.110788,0.000000
78.830002,63.953476,-224.628799,0.005821,0.004361,0.110762,284.479279,14.492065,1.107619,-224.628799,0.110788,0.000000
79.070007,63.909912,-224.539841,0.005821,0.004361,0.110762,284.285492,14.482193,1.107619,-224.539841,0.110788,0.000000
79.310005,63.874161,-224.584320,0.005799,0.004361,0.110762,284.126465,14.474092,1.107619,-224.584320,0.110788,0.000000
79.550003,63.833939,-224.584320,0.005812,0.004361,0.110762,283.947540,14.464977,1.107619,-224.584320,0.110788,0.000000
79.790001,63.792618,-224.539841,0.005808,0.004361,0.110762,283.763733,14.455614,1.107619,-224.539841,0.110788,0.000000
80.030006,63.751282,-224.628799,0.005803,0.004361,0.110762,283.579865,14.446247,1.107619,-224.628799,0.110788,0.000000
80.270004,63.742722,-224.584320,0.005825,0.004361,0.110762,283.541779,14.444307,1.107619,-224.584320,0.110788,0.000000
80.510002,63.684250,-224.628799,0.005829,0.004361,0.110762,283.281677,14.431057,1.107619,-224.628799,0.110788,0.000000
80.750008,63.657074,-224.584320,0.005816,0.004361,0.110762,283.160797,14.424899,1.107619,-224.584320,0.110788,0.000000
80.990005,63.638443,-224.584320,0.005821,0.004361,0.110762,283.077942,14.420677,1.107619,-224.584320,0.110788,0.000000
81.230003,63.597855,-224.628799,0.005816,0.004361,0.110762,282.897400,14.411480,1.107619,-224.628799,0.110788,0.000000
81.470001,63.565842,-224.628799,0.005829,0.004361,0.110762,282.754974,14.404226,1.107619,-224.628799,0.110788,0.000000
81.710007,63.555786,-224.673279,0.005821,0.004361,0.110762,282.710266,14.401947,1.107619,-224.673279,0.110788,0.000000
81.950005,63.507004,-224.584320,0.005799,0.004361,0.110762,282.493256,14.390892,1.107619,-224.584320,0.110788,0.000000
82.190002,63.498444,-224.628799,0.005821,0.004361,0.110762,282.455170,14.388953,1.107619,-224.628799,0.110788,0.000000
82.430000,63.445938,-224.673279,0.005812,0.004361,0.110762,282.221619,14.377055,1.107619,-224.673279,0.110788,0.000000
82.670006,63.429550,-224.628799,0.005846,0.004361,0.110762,282.148743,14.373342,1.107619,-224.628799,0.110788,0.000000
82.910004,63.399384,-224.717758,0.005812,0.004361,0.110762,282.014557,14.366506,1.107619,-224.717758,0.110788,0.000000
83.150002,63.376678,-224.628799,0.005821,0.004361,0.110762,281.913544,14.361361,1.107619,-224.628799,0.110788,0.000000
83.390007,63.345016,-224.673279,0.005808,0.004361,0.110762,281.772705,14.354186,1.107619,-224.673279,0.110788,0.000000
83.630005,63.308899,-224.628799,0.005829,0.004361,0.110762,281.612061,14.346002,1.107619,-224.628799,0.110788,0.000000
83.870003,63.290649,-224.628799,0.005812,0.004361,0.110762,281.530884,14.341866,1.107619,-224.628799,0.110788,0.000000
84.110001,63.277618,-224.717758,0.005821,0.004361,0.110762,281.472900,14.338913,1.107619,-224.717758,0.110788,0.000000
84.350006,63.231445,-224.717758,0.005795,0.004361,0.110762,281.267517,14.328450,1.107619,-224.717758,0.110788,0.000000
84.590004,63.232941,-224.717758,0.005816,0.004361,0.110762,281.274170,14.328789,1.107619,-224.717758,0.110788,0.000000
84.830002,63.200912,-224.717758,0.005821,0.004361,0.110762,281.131714,14.321531,1.107619,-224.717758,0.110788,0.000000
85.070007,63.175964,-224.717758,0.005829,0.004361,0.110762,281.020721,14.315879,1.107619,-224.717758,0.110788,0.000000
85.310005,63.158096,-224.806732,0.005838,0.004361,0.110762,280.941254,14.311830,1.107619,-224.806732,0.110788,0.000000
85.550003,63.125687,-224.762253,0.005829,0.004361,0.110762,280.797089,14.304485,1.107619,-224.762253,0.110788,0.000000
85.790001,63.105591,-224.762253,0.005829,0.004361,0.110762,280.707703,14.299932,1.107619,-224.762253,0.110788,0.000000
86.030006,63.092545,-224.762253,0.005825,0.004361,0.110762,280.649658,14.296974,1.107619,-224.762253,0.110788,0.000000
86.270004,63.056061,-224.806732,0.005833,0.004361,0.110762,280.487366,14.288708,1.107619,-224.806732,0.110788,0.000000
86.510002,63.044510,-224.806732,0.005821,0.004361,0.110762,280.435974,14.286091,1.107619,-224.806732,0.110788,0.000000
86.750008,63.028877,-224.717758,0.005808,0.004361,0.110762,280.366455,14.282548,1.107619,-224.717758,0.110788,0.000000
86.990005,62.999832,-224.851212,0.005795,0.004361,0.110762,280.237244,14.275967,1.107619,-224.851212,0.110788,0.000000
87.230003,62.978981,-224.851212,0.005821,0.004361,0.110762,280.144501,14.271241,1.107619,-224.851212,0.110788,0.000000
87.470001,62.957756,-224.851212,0.005829,0.004361,0.110762,280.050079,14.266431,1.107619,-224.851212,0.110788,0.000000
87.710007,62.940994,-224.895691,0.005829,0.004361,0.110762,279.975525,14.262632,1.107619,-224.895691,0.110788,0.000000
87.950005,62.925728,-224.806732,0.005812,0.004361,0.110762,279.907623,14.259174,1.107619,-224.806732,0.110788,0.000000
88.190002,62.895943,-224.806732,0.005803,0.004361,0.110762,279.775116,14.252424,1.107619,-224.806732,0.110788,0.000000
88.430008,62.879181,-224.806732,0.005821,0.004361,0.110762,279.700562,14.248626,1.107619,-224.806732,0.110788,0.000000
88.670006,62.870987,-224.806732,0.005821,0.004361,0.110762,279.664124,14.246769,1.107619,-224.806732,0.110788,0.000000
88.910004,62.844177,-224.806732,0.005821,0.004361,0.110762,279.544861,14.240694,1.107619,-224.806732,0.110788,0.000000
89.150002,62.841202,-224.851212,0.005795,0.004361,0.110762,279.531616,14.240020,1.107619,-224.851212,0.110788,0.000000
89.390007,62.810295,-224.895691,0.005821,0.004361,0.110762,279.394135,14.233016,1.107619,-224.895691,0.110788,0.000000
89.630005,62.799866,-224.851212,0.005833,0.004361,0.110762,279.347748,14.230653,1.107619,-224.851212,0.110788,0.000000
89.870003,62.792419,-224.806732,0.005812,0.004361,0.110762,279.314636,14.228966,1.107619,-224.806732,0.110788,0.000000
90.110001,62.766357,-224.895691,0.005833,0.004361,0.110762,279.198700,14.223060,1.107619,-224.895691,0.110788,0.000000
90.350006,62.746620,-224.895691,0.005829,0.004361,0.110762,279.110901,14.218587,1.107619,-224.895691,0.110788,0.000000
90.590004,62.738052,-224.851212,0.005799,0.004361,0.110762,279.072784,14.216646,1.107619,-224.851212,0.110788,0.000000
90.830002,62.713104,-224.940170,0.005821,0.004361,0.110762,278.961823,14.210993,1.107619,-224.940170,0.110788,0.000000
91.070007,62.707893,-224.895691,0.005808,0.004361,0.110762,278.938629,14.209812,1.107619,-224.895691,0.110788,0.000000
91.310005,62.695976,-224.895691,0.005816,0.004361,0.110762,278.885620,14.207111,1.107619,-224.895691,0.110788,0.000000
91.550003,62.671768,-224.806732,0.005833,0.004361,0.110762,278.777954,14.201626,1.107619,-224.806732,0.110788,0.000000
91.790001,62.663948,-224.940170,0.005816,0.004361,0.110762,278.743164,14.199854,1.107619,-224.940170,0.110788,0.000000
92.030006,62.650917,-224.895691,0.005833,0.004361,0.110762,278.685211,14.196900,1.107619,-224.895691,0.110788,0.000000
92.270004,62.637512,-224.940170,0.005846,0.004360,0.110753,278.625580,14.193863,1.107532,-224.940170,0.110788,0.000000
92.510002,62.628578,-224.984650,0.005833,0.004360,0.110753,278.585815,14.191838,1.107532,-224.984650,0.110788,0.000000
92.750008,62.598785,-224.940170,0.005825,0.004360,0.110753,278.453308,14.185087,1.107532,-224.940170,0.110788,0.000000
92.990005,62.594688,-224.984650,0.005812,0.004360,0.110753,278.435089,14.184159,1.107532,-224.984650,0.110788,0.000000
93.230003,62.577934,-224.984650,0.005821,0.004360,0.110753,278.360565,14.180363,1.107532,-224.984650,0.110788,0.000000
93.470001,62.554100,-224.984650,0.005808,0.004360,0.110753,278.254547,14.174962,1.107532,-224.984650,0.110788,0.000000
93.710007,62.561546,-224.984650,0.005808,0.004360,0.110753,278.287659,14.176649,1.107532,-224.984650,0.110788,0.000000
93.950005,62.538460,-224.895691,0.005821,0.004360,0.110753,278.184967,14.171417,1.107532,-224.895691,0.110788,0.000000
94.190002,62.530640,-225.073608,0.005808,0.004360,0.110753,278.150177,14.169645,1.107532,-225.073608,0.110788,0.000000
94.430008,62.514259,-224.984650,0.005808,0.004360,0.110753,278.077301,14.165934,1.107532,-224.984650,0.110788,0.000000
94.670006,62.502716,-224.940170,0.005821,0.004360,0.110753,278.025970,14.163318,1.107532,-224.940170,0.110788,0.000000
94.910004,62.499359,-225.029129,0.005833,0.004360,0.110753,278.011047,14.162557,1.107532,-225.029129,0.110788,0.000000
95.150002,62.487076,-224.940170,0.005808,0.004360,0.110753,277.956390,14.159774,1.107532,-224.940170,0.110788,0.000000
95.390007,62.467339,-225.029129,0.005812,0.004360,0.110753,277.868591,14.155301,1.107532,-225.029129,0.110788,0.000000
95.630005,62.455421,-225.029129,0.005829,0.004360,0.110753,277.815582,14.152600,1.107532,-225.029129,0.110788,0.000000
95.870003,62.455048,-224.984650,0.005808,0.004360,0.110753,277.813934,14.152516,1.107532,-224.984650,0.110788,0.000000
96.110008,62.430473,-225.029129,0.005838,0.004360,0.110753,277.704620,14.146948,1.107532,-225.029129,0.110788,0.000000
96.350006,62.420792,-224.984650,0.005821,0.004360,0.110753,277.661560,14.144753,1.107532,-224.984650,0.110788,0.000000
96.590004,62.417442,-225.029129,0.005808,0.004360,0.110753,277.646637,14.143994,1.107532,-225.029129,0.110788,0.000000
96.830002,62.390633,-225.029129,0.005829,0.004360,0.110753,277.527405,14.137919,1.107532,-225.029129,0.110788,0.000000
97.070007,62.393234,-225.073608,0.005812,0.004360,0.110753,277.538971,14.138509,1.107532,-225.073608,0.110788,0.000000
97.310005,62.370148,-225.073608,0.005821,0.004360,0.110753,277.436279,14.133277,1.107532,-225.073608,0.110788,0.000000
97.550003,62.364189,-225.029129,0.005829,0.004360,0.110753,277.409760,14.131927,1.107532,-225.029129,0.110788,0.000000
97.790001,62.353767,-225.118088,0.005821,0.004360,0.110753,277.363403,14.129566,1.107532,-225.118088,0.110788,0.000000
98.030006,62.335518,-225.118088,0.005851,0.004360,0.110753,277.282227,14.125431,1.107532,-225.118088,0.110788,0.000000
98.270004,62.321365,-225.073608,0.005833,0.004360,0.110753,277.219269,14.122223,1.107532,-225.073608,0.110788,0.000000
98.510002,62.318390,-225.118088,0.005851,0.004360,0.110753,277.206055,14.121549,1.107532,-225.118088,0.110788,0.000000
98.750008,62.287857,-225.073608,0.005821,0.004360,0.110753,277.070221,14.114630,1.107532,-225.073608,0.110788,0.000000
98.990005,62.288971,-225.162567,0.005825,0.004360,0.110753,277.075195,14.114882,1.107532,-225.162567,0.110788,0.000000
99.230003,62.279663,-225.073608,0.005816,0.004360,0.110753,277.033783,14.112774,1.107532,-225.073608,0.110788,0.000000
99.470001,62.261047,-225.118088,0.005825,0.004360,0.110753,276.950958,14.108555,1.107532,-225.118088,0.110788,0.000000
99.710007,62.258812,-225.118088,0.005825,0.004360,0.110753,276.941040,14.108048,1.107532,-225.118088,0.110788,0.000000
99.950005,62.243172,-225.118088,0.005812,0.004360,0.110753,276.871460,14.104504,1.107532,-225.118088,0.110788,0.000000
100.190002,62.226044,-225.162567,0.005829,0.004360,0.110753,276.795258,14.100623,1.107532,-225.162567,0.110788,0.000000
100.430008,62.228279,-225.118088,0.005829,0.004360,0.110753,276.805206,14.101130,1.107532,-225.118088,0.110788,0.000000
100.670006,62.202957,-225.207062,0.005816,0.004360,0.110753,276.692566,14.095392,1.107532,-225.207062,0.110788,0.000000
100.910004,62.185822,-225.118088,0.005842,0.004360,0.110753,276.616364,14.091508,1.107532,-225.118088,0.110788,0.000000
101.150002,62.181358,-225.207062,0.005825,0.004360,0.110753,276.596497,14.090497,1.107532,-225.207062,0.110788,0.000000
101.300003,62.175400,-225.207062,0.005795,0.004360,0.110753,276.569977,14.089147,1.107532,-225.207062,0.110788,0.000000