File: Data/Automembrane/AutoNoheat12-2-1_12132023_182727.csv
Time (sec),S:Load (lbs),S:HL1 (DIM),S:LVDT (in),S:Position (in),Ch:Position (mm),Ch:Load (N),Ch:Stress (MPa),Ch:Strain (mm/mm),Ch:HL1 (DIM),Set Point (),Cycles ()
0.010000,0.008568,-1304.092529,0.000065,-0.000000,-0.000000,0.038112,0.001941,-0.000000,-1304.092529,0.000148,0.000000
0.270000,-0.008568,-1304.048096,0.000052,-0.000000,-0.000000,-0.038112,-0.001941,-0.000000,-1304.048096,0.000148,0.000000
0.530000,0.004471,-1304.092529,0.000000,0.000081,0.002047,0.019887,0.001013,0.020469,-1304.092529,0.002645,0.000000
0.790000,0.016388,-1304.048096,0.000065,0.000227,0.005767,0.072897,0.003714,0.057670,-1304.048096,0.006981,0.000000
1.050000,-0.010796,-1304.048096,0.000224,0.000403,0.010242,-0.048021,-0.002446,0.102419,-1304.048096,0.011317,0.000000
1.310000,0.010796,-1304.048096,0.000423,0.000573,0.014543,0.048021,0.002446,0.145435,-1304.048096,0.015636,0.000000
1.570000,0.023087,-1304.136963,0.000578,0.000744,0.018906,0.102694,0.005231,0.189056,-1304.136963,0.019972,0.000000
1.830000,-0.006332,-1304.136963,0.000785,0.000912,0.023172,-0.028168,-0.001435,0.231723,-1304.136963,0.024308,0.000000
2.090000,0.018616,-1304.048096,0.000953,0.001084,0.027526,0.082807,0.004218,0.275256,-1304.048096,0.028644,0.000000
2.350000,-0.005211,-1304.092529,0.001160,0.001260,0.032001,-0.023179,-0.001181,0.320005,-1304.092529,0.032963,0.000000
2.610000,-0.039101,-1304.136963,0.001315,0.001428,0.036268,-0.173928,-0.008860,0.362676,-1304.136963,0.037299,0.000000
2.870000,0.022713,-1304.181519,0.001479,0.001589,0.040369,0.101031,0.005147,0.403693,-1304.181519,0.041636,0.000000
3.130000,0.037613,-1304.136963,0.001707,0.001770,0.044957,0.167311,0.008523,0.449570,-1304.136963,0.045972,0.000000
3.390000,-0.005959,-1304.092529,0.001845,0.001937,0.049189,-0.026505,-0.001350,0.491893,-1304.092529,0.050291,0.000000
3.650000,0.023834,-1304.092529,0.002035,0.002103,0.053421,0.106020,0.005401,0.534211,-1304.092529,0.054627,0.000000
3.910000,0.026436,-1304.048096,0.002216,0.002278,0.057861,0.117593,0.005990,0.578612,-1304.048096,0.058963,0.000000
4.170000,-0.000374,-1304.092529,0.002393,0.002443,0.062059,-0.001663,-0.000085,0.620587,-1304.092529,0.063299,0.000000
4.430000,0.017128,-1304.092529,0.002596,0.002619,0.066525,0.076189,0.003881,0.665248,-1304.092529,0.067618,0.000000
4.690000,0.011917,-1304.092529,0.002721,0.002795,0.070983,0.053010,0.002700,0.709827,-1304.092529,0.071954,0.000000
4.950000,-0.029045,-1304.092529,0.002871,0.002960,0.075188,-0.129199,-0.006582,0.751885,-1304.092529,0.076290,0.000000
5.210000,0.045799,-1304.048096,0.003078,0.003125,0.079377,0.203725,0.010378,0.793772,-1304.048096,0.080609,0.000000
5.470000,0.033890,-1304.136963,0.003277,0.003307,0.084000,0.150749,0.007680,0.839997,-1304.136963,0.084945,0.000000
5.730000,0.014526,-1304.003540,0.003432,0.003474,0.088240,0.064617,0.003292,0.882403,-1304.003540,0.089281,0.000000
5.990000,0.047661,-1304.003540,0.003660,0.003638,0.092403,0.212006,0.010800,0.924029,-1304.003540,0.093617,0.000000
6.250000,0.008934,-1304.136963,0.003790,0.003813,0.096860,0.039741,0.002024,0.968604,-1304.136963,0.097936,0.000000
6.510000,0.006332,-1304.048096,0.003997,0.003987,0.101257,0.028168,0.001435,1.012573,-1304.048096,0.102272,0.000000
6.770000,0.004845,-1304.048096,0.004195,0.004156,0.105559,0.021550,0.001098,1.055588,-1304.048096,0.106608,0.000000
7.030000,0.011917,-1304.048096,0.004303,0.004325,0.109852,0.053010,0.002700,1.098517,-1304.048096,0.110944,0.000000
7.290000,0.119530,-1304.048096,0.004544,0.004496,0.114196,0.531695,0.027086,1.141963,-1304.048096,0.115263,0.000000
7.550000,0.376839,-1304.092529,0.004730,0.004659,0.118333,1.676262,0.085393,1.183329,-1304.092529,0.119599,0.000000
7.810000,0.645325,-1304.048096,0.004838,-0.000000,-0.000000,2.870548,0.146233,-0.000000,-1304.048096,0.000165,0.000000
8.070001,0.589096,-1304.048096,0.004842,-0.000001,-0.000017,2.620430,0.133491,-0.000170,-1304.048096,0.000165,0.000000
8.330000,0.602501,-1304.092529,0.004825,-0.000001,-0.000017,2.680058,0.136529,-0.000170,-1304.092529,0.000260,0.000000
8.590000,0.574944,-1304.048096,0.004838,-0.000001,-0.000017,2.557477,0.130284,-0.000170,-1304.048096,0.000694,0.000000
8.850000,0.635643,-1304.225952,0.004855,0.000015,0.000391,2.827481,0.144039,0.003906,-1304.225952,0.001128,0.000000
9.110001,0.729103,-1304.048096,0.004863,0.000033,0.000833,3.243212,0.165217,0.008327,-1304.048096,0.001561,0.000000
9.370001,0.754051,-1304.136963,0.004868,0.000047,0.001205,3.354187,0.170870,0.012055,-1304.136963,0.001995,0.000000
9.630000,0.815498,-1304.136963,0.004850,0.000064,0.001613,3.627518,0.184795,0.016131,-1304.136963,0.002428,0.000000
9.890000,0.896301,-1304.092529,0.004919,0.000080,0.002038,3.986947,0.203105,0.020382,-1304.092529,0.002862,0.000000
10.150001,0.976730,-1304.092529,0.004894,0.000098,0.002498,4.344714,0.221330,0.024977,-1304.092529,0.003296,0.000000
10.410001,1.037056,-1304.048096,0.004919,0.000111,0.002827,4.613055,0.235000,0.028273,-1304.048096,0.003729,0.000000
10.670000,1.132011,-1304.092529,0.004997,0.000128,0.003252,5.035438,0.256517,0.032524,-1304.092529,0.004163,0.000000
10.930000,1.239258,-1304.136963,0.004971,0.000148,0.003755,5.512494,0.280820,0.037554,-1304.136963,0.004596,0.000000
11.190001,1.323410,-1304.136963,0.004993,0.000165,0.004197,5.886822,0.299889,0.041974,-1304.136963,0.005030,0.000000
11.450001,1.420601,-1304.092529,0.004997,0.000184,0.004674,6.319149,0.321913,0.046743,-1304.092529,0.005463,0.000000
11.710001,1.523376,-1304.136963,0.005040,0.000198,0.005021,6.776317,0.345202,0.050214,-1304.136963,0.005897,0.000000
11.970000,1.668976,-1304.136963,0.005088,0.000217,0.005516,7.423975,0.378195,0.055157,-1304.136963,0.006331,0.000000
12.230000,1.730415,-1304.092529,0.005053,0.000234,0.005949,7.697272,0.392118,0.059495,-1304.092529,0.006764,0.000000
12.490001,1.800423,-1304.136963,0.005070,0.000243,0.006166,8.008680,0.407982,0.061660,-1304.136963,0.007198,0.000000
12.750001,2.032410,-1304.092529,0.005139,0.000268,0.006817,9.040609,0.460551,0.068166,-1304.092529,0.007632,0.000000
13.010000,2.133324,-1304.048096,0.005118,0.000284,0.007216,9.489497,0.483418,0.072155,-1304.048096,0.008065,0.000000
13.270000,2.199974,-1304.136963,0.005113,0.000295,0.007502,9.785974,0.498521,0.075017,-1304.136963,0.008499,0.000000
13.530001,2.363075,-1304.181519,0.005101,0.000316,0.008022,10.511484,0.535480,0.080221,-1304.181519,0.008933,0.000000
13.790001,2.481491,-1304.048096,0.005170,0.000333,0.008447,11.038223,0.562314,0.084471,-1304.048096,0.009366,0.000000
14.050000,2.618896,-1304.092529,0.005170,0.000349,0.008872,11.649433,0.593450,0.088718,-1304.092529,0.009791,0.000000
14.310000,2.669540,-1304.092529,0.005226,0.000359,0.009115,11.874709,0.604927,0.091148,-1304.092529,0.010225,0.000000
14.570001,2.941368,-1304.136963,0.005234,0.000381,0.009670,13.083858,0.666524,0.096696,-1304.136963,0.010658,0.000000
14.830001,3.064255,-1304.136963,0.005260,0.000397,0.010095,13.630486,0.694370,0.100947,-1304.136963,0.011092,0.000000
15.090001,3.241127,-1304.092529,0.005260,0.000420,0.010676,14.417253,0.734450,0.106757,-1304.092529,0.011526,0.000000
15.350000,3.308899,-1304.136963,0.005295,0.000435,0.011057,14.718718,0.749807,0.110572,-1304.136963,0.011959,0.000000
15.610001,3.434761,-1304.092529,0.005338,0.000450,0.011430,15.278581,0.778328,0.114304,-1304.092529,0.012393,0.000000
15.870001,3.666382,-1304.181519,0.005333,0.000469,0.011916,16.308882,0.830814,0.119160,-1304.181519,0.012826,0.000000
16.130001,3.778839,-1304.092529,0.005359,0.000488,0.012384,16.809116,0.856297,0.123842,-1304.092529,0.013260,0.000000
16.390001,3.890923,-1304.092529,0.005320,0.000502,0.012740,17.307688,0.881696,0.127396,-1304.092529,0.013694,0.000000
16.650002,4.010078,-1304.225952,0.005346,0.000517,0.013139,17.837719,0.908697,0.131385,-1304.225952,0.014127,0.000000
16.910002,4.240204,-1304.092529,0.005389,0.000541,0.013737,18.861368,0.960844,0.137369,-1304.092529,0.014561,0.000000
17.170000,4.291595,-1304.181519,0.005402,0.000557,0.014136,19.089970,0.972489,0.141358,-1304.181519,0.014995,0.000000
17.430000,4.348564,-1304.181519,0.005411,0.000570,0.014465,19.343380,0.985399,0.144655,-1304.181519,0.015428,0.000000
17.690001,4.606995,-1304.136963,0.005420,0.000591,0.015012,20.492935,1.043960,0.150120,-1304.136963,0.015862,0.000000
17.950001,4.620399,-1304.136963,0.005420,0.000604,0.015333,20.552563,1.046998,0.153326,-1304.136963,0.016295,0.000000
18.210001,4.588745,-1304.136963,0.005458,0.000620,0.015749,20.411758,1.039824,0.157489,-1304.136963,0.016729,0.000000
18.470001,4.974525,-1304.181519,0.005458,0.000638,0.016208,22.127794,1.127244,0.162084,-1304.181519,0.017163,0.000000
18.730001,5.183426,-1304.225952,0.005510,0.000663,0.016833,23.057030,1.174581,0.168329,-1304.225952,0.017596,0.000000
18.990002,5.134644,-1304.092529,0.005540,0.000677,0.017197,22.840034,1.163527,0.171974,-1304.092529,0.018030,0.000000
19.250000,5.259392,-1304.181519,0.005514,0.000692,0.017588,23.394943,1.191795,0.175876,-1304.181519,0.018463,0.000000
19.510000,5.433662,-1304.136963,0.005592,0.000712,0.018073,24.170137,1.231285,0.180733,-1304.136963,0.018897,0.000000
19.770000,5.631020,-1304.136963,0.005596,0.000730,0.018533,25.048027,1.276007,0.185327,-1304.136963,0.019331,0.000000
20.030001,5.611656,-1304.181519,0.005583,0.000743,0.018880,24.961893,1.271619,0.188798,-1304.181519,0.019764,0.000000
20.290001,5.814598,-1304.136963,0.005575,0.000762,0.019348,25.864624,1.317607,0.193480,-1304.136963,0.020198,0.000000
20.550001,5.937103,-1304.225952,0.005618,0.000779,0.019782,26.409554,1.345367,0.197818,-1304.225952,0.020631,0.000000
20.810001,6.185478,-1304.136963,0.005674,0.000800,0.020319,27.514381,1.401649,0.203192,-1304.136963,0.021065,0.000000
21.070002,6.064461,-1304.181519,0.005652,0.000810,0.020580,26.976068,1.374226,0.205796,-1304.181519,0.021499,0.000000
21.330002,6.331451,-1304.181519,0.005700,0.000832,0.021134,28.163702,1.434727,0.211345,-1304.181519,0.021932,0.000000
21.590000,6.473320,-1304.181519,0.005717,0.000848,0.021542,28.794765,1.466875,0.215421,-1304.181519,0.022366,0.000000
21.850000,6.626366,-1304.181519,0.005730,0.000865,0.021975,29.475546,1.501556,0.219755,-1304.181519,0.022799,0.000000
22.110001,6.741432,-1304.181519,0.005717,0.000880,0.022357,29.987389,1.527630,0.223574,-1304.181519,0.023233,0.000000
22.370001,6.847183,-1304.181519,0.005734,0.000896,0.022756,30.457792,1.551594,0.227563,-1304.181519,0.023667,0.000000
22.630001,7.099281,-1304.181519,0.005743,0.000917,0.023302,31.579180,1.608720,0.233025,-1304.181519,0.024100,0.000000
22.890001,7.055717,-1304.181519,0.005799,0.000929,0.023589,31.385399,1.598848,0.235886,-1304.181519,0.024534,0.000000
23.150002,7.234077,-1304.225952,0.005795,0.000948,0.024083,32.178783,1.639265,0.240829,-1304.225952,0.024959,0.000000
23.410002,7.456757,-1304.181519,0.005816,0.000967,0.024551,33.169312,1.689725,0.245515,-1304.181519,0.025392,0.000000
23.670002,7.609062,-1304.181519,0.005890,0.000981,0.024916,33.846798,1.724238,0.249156,-1304.181519,0.025826,0.000000
23.930000,7.582245,-1304.225952,0.005838,0.000992,0.025184,33.727509,1.718161,0.251843,-1304.225952,0.026260,0.000000
24.190001,7.873444,-1304.181519,0.005894,0.001012,0.025705,35.022827,1.784148,0.257047,-1304.181519,0.026693,0.000000
24.450001,7.972870,-1304.181519,0.005872,0.001026,0.026069,35.465096,1.806678,0.260688,-1304.181519,0.027127,0.000000
24.710001,8.234276,-1304.181519,0.005890,0.001050,0.026667,36.627888,1.865914,0.266672,-1304.181519,0.027560,0.000000
24.970001,8.197777,-1304.181519,0.005928,0.001066,0.027075,36.465534,1.857643,0.270749,-1304.181519,0.027994,0.000000
25.230001,8.434608,-1304.225952,0.005915,0.001084,0.027535,37.519012,1.911310,0.275347,-1304.225952,0.028428,0.000000
25.490002,8.552277,-1304.136963,0.005920,0.001103,0.028020,38.042427,1.937974,0.280203,-1304.136963,0.028861,0.000000
25.750002,8.802887,-1304.270508,0.005984,0.001120,0.028445,39.157196,1.994763,0.284450,-1304.270508,0.029295,0.000000
26.010002,8.711281,-1304.225952,0.005980,0.001131,0.028740,38.749714,1.974005,0.287398,-1304.225952,0.029729,0.000000
26.270000,8.765274,-1304.136963,0.006015,0.001145,0.029078,38.989887,1.986239,0.290782,-1304.136963,0.030162,0.000000
26.530001,9.301491,-1304.225952,0.006084,0.001173,0.029798,41.375099,2.107748,0.297981,-1304.225952,0.030596,0.000000
26.790001,9.199463,-1304.181519,0.006075,0.001188,0.030180,40.921253,2.084628,0.301796,-1304.181519,0.031029,0.000000
27.050001,9.248985,-1304.181519,0.006105,0.001204,0.030587,41.141541,2.095850,0.305872,-1304.181519,0.031463,0.000000
27.310001,9.375595,-1304.225952,0.006118,0.001221,0.031021,41.704731,2.124540,0.310210,-1304.225952,0.031897,0.000000
27.570002,9.630295,-1304.136963,0.006118,0.001240,0.031498,42.837692,2.182256,0.314979,-1304.136963,0.032330,0.000000
27.830002,9.728600,-1304.181519,0.006114,0.001256,0.031897,43.274971,2.204532,0.318968,-1304.181519,0.032764,0.000000
28.090002,9.696205,-1304.225952,0.006148,0.001266,0.032148,43.130875,2.197191,0.321481,-1304.225952,0.033198,0.000000
28.350002,10.004158,-1304.136963,0.006226,0.001286,0.032669,44.500717,2.266975,0.326686,-1304.136963,0.033631,0.000000
28.610001,10.288277,-1304.225952,0.006187,0.001312,0.033336,45.764542,2.331357,0.333362,-1304.225952,0.034065,0.000000
28.870001,10.157951,-1304.181519,0.006226,0.001327,0.033701,45.184826,2.301825,0.337007,-1304.181519,0.034499,0.000000
29.130001,10.206726,-1304.225952,0.006243,0.001342,0.034082,45.401787,2.312877,0.340822,-1304.225952,0.034932,0.000000
29.390001,10.604424,-1304.225952,0.006247,0.001364,0.034637,47.170834,2.402997,0.346371,-1304.225952,0.035366,0.000000
29.650002,10.537399,-1304.225952,0.006299,0.001377,0.034967,46.872692,2.387809,0.349668,-1304.225952,0.035799,0.000000
29.910002,10.441696,-1304.225952,0.006321,0.001388,0.035253,46.446983,2.366122,0.352529,-1304.225952,0.036233,0.000000
30.170002,11.087021,-1304.136963,0.006286,0.001414,0.035912,49.317532,2.512355,0.359118,-1304.136963,0.036667,0.000000
30.430002,11.145111,-1304.270508,0.006347,0.001432,0.036363,49.575932,2.525518,0.363630,-1304.270508,0.037100,0.000000
30.690001,11.053505,-1304.181519,0.006377,0.001447,0.036753,49.168446,2.504760,0.367532,-1304.181519,0.037534,0.000000
30.950001,11.134308,-1304.136963,0.006368,0.001463,0.037152,49.527874,2.523070,0.371522,-1304.136963,0.037967,0.000000
31.210001,11.205063,-1304.225952,0.006407,0.001480,0.037594,49.842609,2.539104,0.375942,-1304.225952,0.038401,0.000000
31.470001,11.402046,-1304.092529,0.006398,0.001497,0.038019,50.718834,2.583741,0.380193,-1304.092529,0.038835,0.000000
31.730001,11.373741,-1304.225952,0.006454,0.001508,0.038305,50.592926,2.577327,0.383054,-1304.225952,0.039268,0.000000
31.990002,11.510406,-1304.225952,0.006441,0.001525,0.038739,51.200844,2.608295,0.387392,-1304.225952,0.039702,0.000000
32.250000,11.836235,-1304.181519,0.006502,0.001547,0.039285,52.650204,2.682129,0.392853,-1304.181519,0.040127,0.000000
32.510002,11.855225,-1304.181519,0.006485,0.001564,0.039728,52.734673,2.686432,0.397278,-1304.181519,0.040560,0.000000
32.770000,11.927460,-1304.181519,0.006519,0.001584,0.040222,53.055992,2.702801,0.402221,-1304.181519,0.040994,0.000000
33.030003,11.886131,-1304.270508,0.006528,0.001596,0.040543,52.872154,2.693436,0.405430,-1304.270508,0.041428,0.000000
33.290001,12.097633,-1304.225952,0.006536,0.001616,0.041037,53.812962,2.741363,0.410373,-1304.225952,0.041861,0.000000
33.550003,12.169502,-1304.225952,0.006532,0.001630,0.041401,54.132648,2.757649,0.414015,-1304.225952,0.042295,0.000000
33.810001,11.952782,-1304.270508,0.006610,0.001642,0.041705,53.168629,2.708539,0.417050,-1304.270508,0.042728,0.000000
34.070004,12.516556,-1304.181519,0.006562,0.001667,0.042338,55.676422,2.836292,0.423382,-1304.181519,0.043162,0.000000
34.330002,12.518044,-1304.225952,0.006588,0.001682,0.042728,55.683037,2.836629,0.427284,-1304.225952,0.043596,0.000000
34.590000,12.357552,-1304.270508,0.006597,0.001694,0.043032,54.969135,2.800261,0.430320,-1304.270508,0.044029,0.000000
34.850002,12.584702,-1304.181519,0.006696,0.001714,0.043544,55.979549,2.851734,0.435437,-1304.181519,0.044463,0.000000
35.110001,12.607040,-1304.270508,0.006666,0.001731,0.043960,56.078915,2.856796,0.439597,-1304.270508,0.044896,0.000000
35.370003,12.808121,-1304.225952,0.006683,0.001749,0.044420,56.973366,2.902362,0.444195,-1304.225952,0.045330,0.000000
35.630001,12.651352,-1304.314941,0.006704,0.001760,0.044697,56.276024,2.866838,0.446970,-1304.314941,0.045764,0.000000
35.890003,13.087402,-1304.225952,0.006704,0.001779,0.045191,58.215672,2.965648,0.451913,-1304.225952,0.046197,0.000000
36.150002,13.234489,-1304.225952,0.006739,0.001799,0.045694,58.869949,2.998978,0.456943,-1304.225952,0.046631,0.000000
36.410000,13.357742,-1304.270508,0.006778,0.001819,0.046197,59.418205,3.026908,0.461973,-1304.270508,0.047064,0.000000
36.670002,13.200974,-1304.225952,0.006782,0.001834,0.046579,58.720863,2.991383,0.465788,-1304.225952,0.047498,0.000000
36.930000,13.224434,-1304.314941,0.006778,0.001848,0.046952,58.825218,2.996700,0.469516,-1304.314941,0.047932,0.000000
37.190002,13.463501,-1304.270508,0.006791,0.001869,0.047463,59.888645,3.050873,0.474633,-1304.270508,0.048365,0.000000
37.450001,13.588615,-1304.270508,0.006881,0.001886,0.047906,60.445179,3.079224,0.479058,-1304.270508,0.048799,0.000000
37.710003,13.552498,-1304.225952,0.006903,0.001900,0.048252,60.284523,3.071040,0.482525,-1304.225952,0.049232,0.000000
37.970001,13.702934,-1304.225952,0.006864,0.001918,0.048712,60.953697,3.105129,0.487124,-1304.225952,0.049666,0.000000
38.230003,13.905876,-1304.225952,0.006885,0.001939,0.049250,61.856426,3.151117,0.492498,-1304.225952,0.050100,0.000000
38.490002,13.865662,-1304.270508,0.006972,0.001955,0.049666,61.677544,3.142004,0.496661,-1304.270508,0.050533,0.000000
38.750000,13.778526,-1304.270508,0.006954,0.001968,0.049987,61.289948,3.122259,0.499871,-1304.270508,0.050967,0.000000
39.010002,14.117760,-1304.314941,0.006954,0.001990,0.050542,62.798931,3.199130,0.505420,-1304.314941,0.051401,0.000000
39.270000,13.931572,-1304.270508,0.006963,0.002002,0.050846,61.970726,3.156940,0.508455,-1304.270508,0.051834,0.000000
39.530003,14.079773,-1304.270508,0.007049,0.002021,0.051331,62.629959,3.190522,0.513311,-1304.270508,0.052268,0.000000
39.790001,14.223511,-1304.359375,0.007054,0.002037,0.051739,63.269337,3.223094,0.517388,-1304.359375,0.052702,0.000000
40.050003,14.570190,-1304.270508,0.007054,0.002062,0.052372,64.811447,3.301652,0.523720,-1304.270508,0.053135,0.000000
40.310001,14.321815,-1304.314941,0.007101,0.002076,0.052727,63.706615,3.245370,0.527274,-1304.314941,0.053569,0.000000
40.570004,14.335220,-1304.270508,0.007105,0.002091,0.053109,63.766243,3.248407,0.531089,-1304.270508,0.054002,0.000000
40.830002,14.410072,-1304.359375,0.007131,0.002109,0.053569,64.099205,3.265369,0.535688,-1304.359375,0.054436,0.000000
41.090000,14.719513,-1304.314941,0.007105,0.002127,0.054028,65.475662,3.335489,0.540282,-1304.314941,0.054870,0.000000
41.350002,14.528114,-1304.270508,0.007131,0.002141,0.054375,64.624283,3.292118,0.543753,-1304.270508,0.055294,0.000000
41.610001,14.722862,-1304.225952,0.007166,0.002160,0.054870,65.490562,3.336248,0.548696,-1304.225952,0.055728,0.000000
41.870003,14.721001,-1304.270508,0.007174,0.002177,0.055303,65.482285,3.335826,0.553030,-1304.270508,0.056162,0.000000
42.130001,15.077362,-1304.359375,0.007226,0.002198,0.055841,67.067459,3.416579,0.558408,-1304.359375,0.056595,0.000000
42.390003,14.701263,-1304.225952,0.007217,0.002209,0.056110,65.394485,3.331354,0.561096,-1304.225952,0.057029,0.000000
42.650002,14.979431,-1304.270508,0.007243,0.002230,0.056647,66.631836,3.394388,0.566474,-1304.270508,0.057463,0.000000
42.910004,15.000282,-1304.314941,0.007243,0.002246,0.057055,66.724586,3.399113,0.570550,-1304.314941,0.057896,0.000000
43.170002,15.163750,-1304.225952,0.007343,0.002265,0.057541,67.451729,3.436155,0.575406,-1304.225952,0.058330,0.000000
43.430000,15.130241,-1304.359375,0.007269,0.002279,0.057887,67.302673,3.428562,0.578873,-1304.359375,0.058764,0.000000
43.690002,15.054649,-1304.359375,0.007347,0.002294,0.058278,66.966423,3.411432,0.582775,-1304.359375,0.059197,0.000000
43.950001,15.416595,-1304.225952,0.007338,0.002315,0.058807,68.576439,3.493450,0.588067,-1304.225952,0.059631,0.000000
44.210003,15.181252,-1304.359375,0.007377,0.002326,0.059093,67.529579,3.440121,0.590928,-1304.359375,0.060064,0.000000
44.470001,15.349190,-1304.314941,0.007351,0.002348,0.059639,68.276604,3.478176,0.596393,-1304.314941,0.060498,0.000000
44.730003,15.562935,-1304.225952,0.007429,0.002365,0.060073,69.227394,3.526612,0.600727,-1304.225952,0.060932,0.000000
44.990002,15.561821,-1304.359375,0.007450,0.002379,0.060437,69.222435,3.526359,0.604372,-1304.359375,0.061365,0.000000
45.250004,15.327225,-1304.225952,0.007455,0.002391,0.060732,68.178902,3.473199,0.607320,-1304.225952,0.061799,0.000000
45.510002,15.704437,-1304.314941,0.007463,0.002412,0.061252,69.856827,3.558676,0.612525,-1304.314941,0.062232,0.000000
45.770000,15.667198,-1304.270508,0.007472,0.002428,0.061677,69.691177,3.550238,0.616771,-1304.270508,0.062666,0.000000
46.030003,15.988556,-1304.270508,0.007493,0.002449,0.062206,71.120651,3.623059,0.622063,-1304.270508,0.063099,0.000000
46.290001,15.874237,-1304.270508,0.007506,0.002465,0.062605,70.612137,3.597153,0.626052,-1304.270508,0.063533,0.000000
46.550003,15.994888,-1304.270508,0.007567,0.002482,0.063048,71.148819,3.624494,0.630476,-1304.270508,0.063967,0.000000
46.810001,16.025047,-1304.270508,0.007593,0.002502,0.063559,71.282974,3.631328,0.635590,-1304.270508,0.064400,0.000000
47.070004,16.259644,-1304.314941,0.007575,0.002519,0.063984,72.326508,3.684488,0.639840,-1304.314941,0.064834,0.000000
47.330002,16.007545,-1304.225952,0.007571,0.002532,0.064322,71.205116,3.627362,0.643224,-1304.225952,0.065267,0.000000
47.590004,15.890999,-1304.359375,0.007644,0.002544,0.064609,70.686691,3.600952,0.646085,-1304.359375,0.065701,0.000000
47.850002,16.640205,-1304.270508,0.007653,0.002572,0.065328,74.019333,3.770724,0.653284,-1304.270508,0.066135,0.000000
48.110001,16.360184,-1304.181519,0.007662,0.002586,0.065684,72.773735,3.707271,0.656838,-1304.181519,0.066568,0.000000
48.370003,16.341194,-1304.314941,0.007726,0.002602,0.066100,72.689262,3.702968,0.661002,-1304.314941,0.067002,0.000000
48.630001,16.346405,-1304.270508,0.007662,0.002619,0.066534,72.712440,3.704148,0.665335,-1304.270508,0.067435,0.000000
48.890003,16.590309,-1304.314941,0.007752,0.002639,0.067028,73.797379,3.759418,0.670282,-1304.314941,0.067869,0.000000
49.150002,16.661064,-1304.225952,0.007700,0.002654,0.067418,74.112114,3.775451,0.674184,-1304.225952,0.068303,0.000000
49.410004,16.428703,-1304.314941,0.007761,0.002666,0.067713,73.078522,3.722797,0.677133,-1304.314941,0.068736,0.000000
49.670002,16.779106,-1304.270508,0.007743,0.002688,0.068277,74.637192,3.802200,0.682769,-1304.270508,0.069170,0.000000
49.930004,17.116470,-1304.225952,0.007834,0.002710,0.068832,76.137863,3.878648,0.688317,-1304.225952,0.069604,0.000000
50.190002,16.909065,-1304.270508,0.007856,0.002725,0.069214,75.215279,3.831649,0.692136,-1304.270508,0.070029,0.000000
50.450001,16.810379,-1304.270508,0.007812,0.002740,0.069604,74.776299,3.809286,0.696038,-1304.270508,0.070462,0.000000
50.710003,17.217010,-1304.270508,0.007869,0.002761,0.070141,76.585091,3.901430,0.701413,-1304.270508,0.070896,0.000000
50.970001,17.059128,-1304.314941,0.007864,0.002775,0.070480,75.882790,3.865654,0.704797,-1304.314941,0.071329,0.000000
51.230003,16.910927,-1304.314941,0.007847,0.002788,0.070818,75.223557,3.832071,0.708177,-1304.314941,0.071763,0.000000
51.490002,17.635559,-1304.314941,0.007886,0.002812,0.071433,78.446884,3.996275,0.714335,-1304.314941,0.072197,0.000000
51.750004,17.721207,-1304.270508,0.007963,0.002830,0.071885,78.827866,4.015683,0.718846,-1304.270508,0.072630,0.000000
52.010002,17.539490,-1304.225952,0.007998,0.002845,0.072275,78.019547,3.974505,0.722748,-1304.225952,0.073064,0.000000
52.270004,17.536507,-1304.225952,0.008011,0.002861,0.072665,78.006279,3.973829,0.726651,-1304.225952,0.073497,0.000000
52.530003,17.555504,-1304.181519,0.007989,0.002879,0.073116,78.090782,3.978134,0.731158,-1304.181519,0.073931,0.000000
52.790001,17.787117,-1304.225952,0.007981,0.002895,0.073541,79.121048,4.030618,0.735409,-1304.225952,0.074365,0.000000
53.050003,17.654922,-1304.270508,0.008037,0.002907,0.073827,78.533020,4.000663,0.738270,-1304.270508,0.074798,0.000000
53.310001,17.824722,-1304.270508,0.008032,0.002924,0.074269,79.288322,4.039140,0.742695,-1304.270508,0.075232,0.000000
53.570004,18.322212,-1304.270508,0.008011,0.002945,0.074798,81.501274,4.151873,0.747982,-1304.270508,0.075666,0.000000
53.830002,18.287956,-1304.225952,0.008101,0.002963,0.075267,81.348892,4.144110,0.752668,-1304.225952,0.076099,0.000000
54.090004,18.459251,-1304.270508,0.008050,0.002982,0.075752,82.110847,4.182926,0.757524,-1304.270508,0.076533,0.000000
54.350002,18.247742,-1304.314941,0.008144,0.002995,0.076065,81.170006,4.134997,0.760647,-1304.314941,0.076967,0.000000
54.610004,18.531113,-1304.225952,0.008119,0.003015,0.076585,82.430504,4.199210,0.765847,-1304.225952,0.077400,0.000000
54.870003,18.565002,-1304.270508,0.008127,0.003031,0.076975,82.581253,4.206890,0.769753,-1304.270508,0.077834,0.000000
55.130001,18.166939,-1304.270508,0.008175,0.003041,0.077235,80.810577,4.116687,0.772353,-1304.270508,0.078267,0.000000
55.390003,19.010361,-1304.314941,0.008132,0.003066,0.077869,84.562309,4.307809,0.778685,-1304.314941,0.078701,0.000000
55.650002,19.007011,-1304.225952,0.008192,0.003081,0.078267,84.547409,4.307050,0.782675,-1304.225952,0.079135,0.000000
55.910004,18.703156,-1304.225952,0.008162,0.003093,0.078571,83.195793,4.238195,0.785706,-1304.225952,0.079568,0.000000
56.170002,19.042755,-1304.314941,0.008162,0.003113,0.079074,84.706406,4.315150,0.790736,-1304.314941,0.080002,0.000000
56.430004,18.988762,-1304.225952,0.008209,0.003129,0.079473,84.466232,4.302915,0.794726,-1304.225952,0.080435,0.000000
56.690002,19.329109,-1304.270508,0.008235,0.003148,0.079950,85.980171,4.380039,0.799498,-1304.270508,0.080869,0.000000
56.950005,19.010361,-1304.225952,0.008261,0.003156,0.080166,84.562309,4.307809,0.801663,-1304.225952,0.081303,0.000000
57.210003,19.586044,-1304.270508,0.008248,0.003177,0.080704,87.123077,4.438261,0.807042,-1304.270508,0.081736,0.000000
57.470001,19.736115,-1304.314941,0.008248,0.003195,0.081155,87.790619,4.472268,0.811550,-1304.314941,0.082170,0.000000
57.730003,20.091728,-1304.181519,0.008308,0.003218,0.081728,89.372467,4.552851,0.817276,-1304.181519,0.082603,0.000000
57.990002,19.882454,-1304.225952,0.008295,0.003232,0.082100,88.441574,4.505429,0.821004,-1304.225952,0.083037,0.000000
58.250004,19.893623,-1304.181519,0.008300,0.003247,0.082473,88.491257,4.507959,0.824732,-1304.181519,0.083471,0.000000
58.510002,20.230255,-1304.225952,0.008287,0.003267,0.082985,89.988670,4.584241,0.829850,-1304.225952,0.083904,0.000000
58.770004,20.237328,-1304.359375,0.008360,0.003282,0.083375,90.020126,4.585844,0.833752,-1304.359375,0.084338,0.000000
59.030003,20.290207,-1304.225952,0.008334,0.003299,0.083792,90.255348,4.597826,0.837915,-1304.225952,0.084771,0.000000
59.290001,20.409737,-1304.270508,0.008338,0.003315,0.084208,90.787041,4.624912,0.842079,-1304.270508,0.085196,0.000000
59.550003,20.902756,-1304.270508,0.008386,0.003338,0.084780,92.980103,4.736632,0.847801,-1304.270508,0.085630,0.000000
59.810001,20.877434,-1304.270508,0.008369,0.003355,0.085205,92.867462,4.730894,0.852052,-1304.270508,0.086064,0.000000
60.070004,20.684174,-1304.270508,0.008377,0.003367,0.085517,92.007797,4.687101,0.855174,-1304.270508,0.086497,0.000000
60.330002,21.193581,-1304.181519,0.008451,0.003388,0.086055,94.273758,4.802534,0.860549,-1304.181519,0.086931,0.000000
60.590004,21.010368,-1304.225952,0.008412,0.003402,0.086402,93.458786,4.761017,0.864020,-1304.225952,0.087364,0.000000
60.850002,21.287041,-1304.225952,0.008442,0.003418,0.086818,94.689484,4.823712,0.868183,-1304.225952,0.087798,0.000000
61.110004,21.594627,-1304.181519,0.008468,0.003435,0.087252,96.057701,4.893413,0.872517,-1304.181519,0.088232,0.000000
61.370003,22.414963,-1304.181519,0.008459,0.003461,0.087911,99.706734,5.079303,0.879110,-1304.181519,0.088665,0.000000
61.630001,22.210899,-1304.181519,0.008528,0.003475,0.088266,98.799011,5.033062,0.882664,-1304.181519,0.089099,0.000000
61.890003,22.212387,-1304.181519,0.008554,0.003490,0.088657,98.805634,5.033399,0.886566,-1304.181519,0.089532,0.000000
62.150002,22.541565,-1304.225952,0.008472,0.003507,0.089082,100.269890,5.107992,0.890817,-1304.225952,0.089966,0.000000
62.410004,22.973892,-1304.181519,0.008541,0.003526,0.089550,102.192978,5.205958,0.895499,-1304.181519,0.090400,0.000000
62.670002,22.884521,-1304.136963,0.008524,0.003539,0.089888,101.795433,5.185707,0.898882,-1304.136963,0.090833,0.000000
62.930004,23.378288,-1304.181519,0.008541,0.003558,0.090374,103.991821,5.297596,0.903738,-1304.181519,0.091267,0.000000
63.190002,23.600967,-1304.270508,0.008545,0.003575,0.090816,104.982346,5.348055,0.908159,-1304.270508,0.091700,0.000000
63.450005,24.410507,-1304.181519,0.008558,0.003597,0.091354,108.583359,5.531500,0.913537,-1304.181519,0.092134,0.000000
63.710003,24.211288,-1304.181519,0.008580,0.003607,0.091622,107.697189,5.486357,0.916225,-1304.181519,0.092568,0.000000
63.970001,24.802238,-1304.225952,0.008567,0.003629,0.092169,110.325867,5.620268,0.921690,-1304.225952,0.093001,0.000000
64.230003,25.115036,-1304.136963,0.008606,0.003643,0.092533,111.717262,5.691149,0.925331,-1304.136963,0.093435,0.000000
64.490005,25.544006,-1304.270508,0.008606,0.003661,0.092993,113.625412,5.788354,0.929926,-1304.270508,0.093869,0.000000
64.750000,25.997559,-1304.225952,0.008623,0.003677,0.093400,115.642914,5.891131,0.934002,-1304.225952,0.094302,0.000000
65.010002,26.165497,-1304.181519,0.008670,0.003693,0.093790,116.389946,5.929186,0.937905,-1304.181519,0.094736,0.000000
65.270004,27.065895,-1304.225952,0.008666,0.003714,0.094337,120.395111,6.133219,0.943370,-1304.225952,0.095170,0.000000
65.530006,27.074081,-1304.136963,0.008692,0.003725,0.094614,120.431526,6.135075,0.946144,-1304.136963,0.095603,0.000000
65.790001,27.643440,-1304.181519,0.008692,0.003746,0.095161,122.964165,6.264093,0.951610,-1304.181519,0.096037,0.000000
66.050003,28.342010,-1304.136963,0.008666,0.003763,0.095586,126.071556,6.422391,0.955856,-1304.136963,0.096471,0.000000
66.310005,28.720345,-1304.225952,0.008714,0.003778,0.095959,127.754471,6.508123,0.959588,-1304.225952,0.096904,0.000000
66.570000,28.864082,-1304.270508,0.008731,0.003789,0.096236,128.393845,6.540695,0.962363,-1304.270508,0.097338,0.000000
66.830002,29.745857,-1304.225952,0.008765,0.003809,0.096757,132.316177,6.740508,0.967567,-1304.225952,0.097771,0.000000
67.090004,30.085464,-1304.225952,0.008744,0.003824,0.097121,133.826828,6.817464,0.971208,-1304.225952,0.098205,0.000000
67.350006,31.345566,-1304.181519,0.008783,0.003848,0.097745,139.432037,7.103007,0.977453,-1304.181519,0.098639,0.000000
67.610001,31.658737,-1304.225952,0.008804,0.003863,0.098118,140.825104,7.173973,0.981181,-1304.225952,0.099072,0.000000
67.870003,32.414276,-1304.225952,0.008826,0.003881,0.098569,144.185898,7.345180,0.985689,-1304.225952,0.099506,0.000000
68.130005,32.843254,-1304.181519,0.008800,0.003900,0.099055,146.094086,7.442388,0.990549,-1304.181519,0.099939,0.000000
68.390007,33.914566,-1304.270508,0.008830,0.003917,0.099497,150.859528,7.685150,0.994969,-1304.270508,0.100364,0.000000
68.650002,34.082878,-1304.225952,0.008852,0.003930,0.099818,151.608215,7.723290,0.998179,-1304.225952,0.100798,0.000000
68.910004,34.454506,-1304.181519,0.008860,0.003942,0.100130,153.261292,7.807503,1.001302,-1304.181519,0.101232,0.000000
69.170006,36.103371,-1304.314941,0.008830,0.003969,0.100815,160.595810,8.181141,1.008152,-1304.314941,0.101665,0.000000
69.430000,36.693207,-1304.270508,0.008899,0.003985,0.101223,163.219528,8.314799,1.012228,-1304.270508,0.102099,0.000000
69.690002,37.356407,-1304.225952,0.008852,0.004001,0.101613,166.169601,8.465083,1.016131,-1304.225952,0.102532,0.000000
69.950005,38.063171,-1304.270508,0.008895,0.004018,0.102064,169.313446,8.625238,1.020639,-1304.270508,0.102966,0.000000
70.210007,38.948296,-1304.225952,0.008912,0.004036,0.102506,173.250671,8.825810,1.025063,-1304.225952,0.103400,0.000000
70.470001,39.711662,-1304.225952,0.008951,0.004052,0.102923,176.646301,8.998791,1.029227,-1304.225952,0.103833,0.000000
70.730003,40.187180,-1304.225952,0.008929,0.004063,0.103191,178.761505,9.106544,1.031914,-1304.225952,0.104267,0.000000
70.990005,41.490860,-1304.270508,0.008933,0.004087,0.103798,184.560562,9.401963,1.037985,-1304.270508,0.104700,0.000000
71.250000,42.903641,-1304.225952,0.008977,0.004108,0.104336,190.844925,9.722104,1.043359,-1304.225952,0.105134,0.000000
71.510002,43.672585,-1304.270508,0.008972,0.004123,0.104726,194.265366,9.896349,1.047261,-1304.270508,0.105568,0.000000
71.770004,44.319397,-1304.314941,0.009002,0.004138,0.105099,197.142517,10.042918,1.050993,-1304.314941,0.106001,0.000000
72.030006,45.659195,-1304.270508,0.008968,0.004160,0.105654,203.102249,10.346521,1.056542,-1304.270508,0.106435,0.000000
72.290001,46.335426,-1304.270508,0.009033,0.004171,0.105949,206.110275,10.499758,1.059491,-1304.270508,0.106868,0.000000
72.550003,46.798653,-1304.359375,0.009028,0.004183,0.106253,208.170807,10.604726,1.062526,-1304.359375,0.107302,0.000000
72.810005,48.609505,-1304.314941,0.009020,0.004208,0.106895,216.225876,11.015071,1.068945,-1304.314941,0.107736,0.000000
73.070000,49.918762,-1304.359375,0.009007,0.004228,0.107380,222.049744,11.311752,1.073801,-1304.359375,0.108169,0.000000
73.330002,50.815811,-1304.270508,0.009050,0.004242,0.107744,226.040024,11.515027,1.077442,-1304.270508,0.108603,0.000000
73.590004,51.967560,-1304.314941,0.009024,0.004259,0.108178,231.163254,11.776017,1.081780,-1304.314941,0.109036,0.000000
73.850006,52.688469,-1304.225952,0.009063,0.004275,0.108577,234.370010,11.939378,1.085769,-1304.225952,0.109470,0.000000
74.110001,54.118752,-1304.314941,0.009015,0.004293,0.109054,240.732224,12.263485,1.090538,-1304.314941,0.109904,0.000000
74.370003,55.004257,-1304.314941,0.009058,0.004305,0.109357,244.671158,12.464143,1.093573,-1304.314941,0.110337,0.000000
74.630005,55.853638,-1304.314941,0.009084,0.004321,0.109765,248.449387,12.656615,1.097650,-1304.314941,0.110771,0.000000
74.890007,57.897591,-1304.314941,0.009046,0.004343,0.110320,257.541351,13.119781,1.103199,-1304.314941,0.111204,0.000000
75.150002,59.003906,-1304.314941,0.009097,0.004360,0.110736,262.462494,13.370476,1.107362,-1304.314941,0.111638,0.000000
75.410004,60.451691,-1304.359375,0.009084,0.004381,0.111265,268.902557,13.698549,1.112653,-1304.359375,0.112072,0.000000
75.670006,61.483536,-1304.359375,0.009067,0.004393,0.111586,273.492432,13.932368,1.115863,-1304.359375,0.112505,0.000000
75.930000,62.636024,-1304.359375,0.009123,0.004412,0.112063,278.618958,14.193526,1.120632,-1304.359375,0.112939,0.000000
76.190002,64.076736,-1304.359375,0.009110,0.004427,0.112445,285.027557,14.519996,1.124447,-1304.359375,0.113373,0.000000
76.450005,64.581299,-1304.359375,0.009106,0.004435,0.112662,287.271973,14.634331,1.126616,-1304.359375,0.113806,0.000000
76.710007,66.698990,-1304.359375,0.009153,0.004462,0.113329,296.691925,15.114206,1.133292,-1304.359375,0.114240,0.000000
76.970001,67.348022,-1304.359375,0.009162,0.004465,0.113407,299.578979,15.261280,1.134072,-1304.359375,0.113589,0.000000
77.230003,66.932083,-1304.314941,0.009158,0.004465,0.113398,297.728790,15.167027,1.133985,-1304.314941,0.113398,0.000000
77.490005,66.573486,-1304.403931,0.009145,0.004464,0.113390,296.133667,15.085768,1.133898,-1304.403931,0.113398,0.000000
77.750000,66.275970,-1304.270508,0.009153,0.004464,0.113390,294.810242,15.018350,1.133898,-1304.270508,0.113398,0.000000
78.010002,66.042862,-1304.314941,0.009184,0.004464,0.113381,293.773315,14.965526,1.133811,-1304.314941,0.113398,0.000000
78.270004,65.790771,-1304.359375,0.009123,0.004464,0.113381,292.651978,14.908401,1.133811,-1304.359375,0.113398,0.000000
78.530006,65.615005,-1304.359375,0.009175,0.004464,0.113381,291.870117,14.868573,1.133811,-1304.359375,0.113398,0.000000
78.790001,65.450790,-1304.403931,0.009132,0.004464,0.113381,291.139648,14.831361,1.133811,-1304.403931,0.113398,0.000000
79.050003,65.275406,-1304.314941,0.009140,0.004464,0.113381,290.359497,14.791618,1.133811,-1304.314941,0.113398,0.000000
79.310005,65.141342,-1304.359375,0.009119,0.004464,0.113381,289.763153,14.761239,1.133811,-1304.359375,0.113398,0.000000
79.570007,65.018463,-1304.359375,0.009196,0.004464,0.113381,289.216583,14.733395,1.133811,-1304.359375,0.113398,0.000000
79.830002,64.890366,-1304.359375,0.009145,0.004464,0.113381,288.646759,14.704368,1.133811,-1304.359375,0.113398,0.000000
80.090004,64.791687,-1304.359375,0.009184,0.004464,0.113381,288.207825,14.682007,1.133811,-1304.359375,0.113398,0.000000
80.350006,64.678864,-1304.359375,0.009123,0.004464,0.113381,287.705963,14.656440,1.133811,-1304.359375,0.113398,0.000000
80.610001,64.592850,-1304.359375,0.009127,0.004464,0.113381,287.323334,14.636950,1.133811,-1304.359375,0.113398,0.000000
80.870003,64.512787,-1304.359375,0.009140,0.004464,0.113381,286.967194,14.618807,1.133811,-1304.359375,0.113398,0.000000
81.130005,64.414856,-1304.403931,0.009179,0.004464,0.113381,286.531586,14.596615,1.133811,-1304.403931,0.113398,0.000000
81.390007,64.366821,-1304.359375,0.009158,0.004464,0.113381,286.317932,14.585731,1.133811,-1304.359375,0.113398,0.000000
81.650002,64.278931,-1304.359375,0.009123,0.004464,0.113381,285.926971,14.565814,1.133811,-1304.359375,0.113398,0.000000
81.910004,64.208923,-1304.359375,0.009153,0.004463,0.113373,285.615570,14.549950,1.133727,-1304.359375,0.113398,0.000000
82.170006,64.156799,-1304.403931,0.009132,0.004463,0.113373,285.383698,14.538138,1.133727,-1304.403931,0.113398,0.000000
82.430000,64.075623,-1304.359375,0.009184,0.004463,0.113373,285.022614,14.519743,1.133727,-1304.359375,0.113398,0.000000
82.690002,64.021622,-1304.403931,0.009171,0.004463,0.113373,284.782410,14.507506,1.133727,-1304.403931,0.113398,0.000000
82.950005,63.964645,-1304.448364,0.009205,0.004463,0.113373,284.528961,14.494596,1.133727,-1304.448364,0.113398,0.000000
83.210007,63.909546,-1304.359375,0.009158,0.004463,0.113373,284.283844,14.482110,1.133727,-1304.359375,0.113398,0.000000
83.470001,63.873795,-1304.403931,0.009149,0.004463,0.113373,284.124817,14.474009,1.133727,-1304.403931,0.113398,0.000000
83.730003,63.817566,-1304.359375,0.009175,0.004463,0.113373,283.874725,14.461267,1.133727,-1304.359375,0.113398,0.000000
83.990005,63.765060,-1304.492798,0.009110,0.004463,0.113373,283.641144,14.449369,1.133727,-1304.492798,0.113398,0.000000
84.250008,63.730423,-1304.359375,0.009127,0.004463,0.113373,283.487091,14.441520,1.133727,-1304.359375,0.113398,0.000000
84.510002,63.671967,-1304.448364,0.009158,0.004463,0.113373,283.227051,14.428274,1.133727,-1304.448364,0.113398,0.000000
84.770004,63.642929,-1304.359375,0.009171,0.004463,0.113373,283.097900,14.421694,1.133727,-1304.359375,0.113398,0.000000
85.030006,63.612762,-1304.448364,0.009184,0.004463,0.113373,282.963715,14.414858,1.133727,-1304.448364,0.113398,0.000000
85.290001,63.553558,-1304.448364,0.009145,0.004463,0.113373,282.700348,14.401443,1.133727,-1304.448364,0.113398,0.000000
85.550003,63.526001,-1304.448364,0.009192,0.004463,0.113373,282.577759,14.395197,1.133727,-1304.448364,0.113398,0.000000
85.810005,63.493225,-1304.448364,0.009149,0.004463,0.113373,282.431976,14.387771,1.133727,-1304.448364,0.113398,0.000000
86.070007,63.450775,-1304.403931,0.009188,0.004463,0.113373,282.243134,14.378151,1.133727,-1304.403931,0.113398,0.000000
86.330002,63.428436,-1304.403931,0.009110,0.004463,0.113373,282.143768,14.373089,1.133727,-1304.403931,0.113398,0.000000
86.590004,63.378159,-1304.537354,0.009149,0.004463,0.113373,281.920135,14.361696,1.133727,-1304.537354,0.113398,0.000000
86.850006,63.362900,-1304.403931,0.009192,0.004463,0.113373,281.852264,14.358238,1.133727,-1304.403931,0.113398,0.000000
87.110001,63.328644,-1304.537354,0.009196,0.004463,0.113373,281.699890,14.350476,1.133727,-1304.537354,0.113398,0.000000
87.370003,63.292145,-1304.403931,0.009136,0.004463,0.113373,281.537506,14.342205,1.133727,-1304.403931,0.113398,0.000000
87.630005,63.275757,-1304.403931,0.009158,0.004463,0.113373,281.464630,14.338491,1.133727,-1304.403931,0.113398,0.000000
87.890007,63.241882,-1304.492798,0.009188,0.004463,0.113373,281.313934,14.330815,1.133727,-1304.492798,0.113398,0.000000
88.150002,63.206131,-1304.403931,0.009153,0.004463,0.113373,281.154907,14.322714,1.133727,-1304.403931,0.113398,0.000000
88.410004,63.197937,-1304.492798,0.009140,0.004463,0.113373,281.118469,14.320857,1.133727,-1304.492798,0.113398,0.000000
88.670006,63.155121,-1304.448364,0.009196,0.004463,0.113373,280.928009,14.311154,1.133727,-1304.448364,0.113398,0.000000
88.930008,63.129417,-1304.492798,0.009166,0.004463,0.113373,280.813660,14.305330,1.133727,-1304.492798,0.113398,0.000000
89.190002,63.111923,-1304.492798,0.009158,0.004463,0.113373,280.735870,14.301367,1.133727,-1304.492798,0.113398,0.000000
89.450005,63.070961,-1304.403931,0.009166,0.004463,0.113373,280.553650,14.292084,1.133727,-1304.403931,0.113398,0.000000
89.710007,63.068726,-1304.492798,0.009192,0.004463,0.113373,280.543701,14.291577,1.133727,-1304.492798,0.113398,0.000000
89.970001,63.027016,-1304.537354,0.009145,0.004463,0.113373,280.358154,14.282125,1.133727,-1304.537354,0.113398,0.000000
90.230003,63.005051,-1304.448364,0.009188,0.004463,0.113373,280.260468,14.277149,1.133727,-1304.448364,0.113398,0.000000
90.490005,62.995369,-1304.492798,0.009127,0.004463,0.113373,280.217407,14.274955,1.133727,-1304.492798,0.113398,0.000000
90.750008,62.957382,-1304.448364,0.009175,0.004463,0.113373,280.048431,14.266347,1.133727,-1304.448364,0.113398,0.000000
91.010002,62.940254,-1304.492798,0.009132,0.004463,0.113373,279.972229,14.262465,1.133727,-1304.492798,0.113398,0.000000
91.270004,62.923874,-1304.403931,0.009179,0.004463,0.113373,279.899384,14.258754,1.133727,-1304.403931,0.113398,0.000000
91.530006,62.897064,-1304.448364,0.009158,0.004463,0.113373,279.780121,14.252678,1.133727,-1304.448364,0.113398,0.000000
91.790001,62.885147,-1304.448364,0.009179,0.004463,0.113373,279.727112,14.249978,1.133727,-1304.448364,0.113398,0.000000
92.050003,62.844185,-1304.448364,0.009179,0.004463,0.113373,279.544891,14.240696,1.133727,-1304.448364,0.113398,0.000000
92.310005,62.834877,-1304.537354,0.009140,0.004463,0.113373,279.503479,14.238586,1.133727,-1304.537354,0.113398,0.000000
92.570007,62.810669,-1304.492798,0.009136,0.004463,0.113373,279.395813,14.233101,1.133727,-1304.492798,0.113398,0.000000
92.830002,62.787582,-1304.403931,0.009184,0.004463,0.113373,279.293121,14.227870,1.133727,-1304.403931,0.113398,0.000000
93.090004,62.783112,-1304.492798,0.009188,0.004463,0.113373,279.273224,14.226856,1.133727,-1304.492798,0.113398,0.000000
93.350006,62.746620,-1304.537354,0.009140,0.004463,0.113373,279.110901,14.218587,1.133727,-1304.537354,0.113398,0.000000
93.610008,62.731354,-1304.492798,0.009158,0.004463,0.113373,279.042999,14.215128,1.133727,-1304.492798,0.113398,0.000000
93.870003,62.725395,-1304.492798,0.009149,0.004463,0.113373,279.016479,14.213778,1.133727,-1304.492798,0.113398,0.000000
94.130005,62.690765,-1304.448364,0.009175,0.004463,0.113373,278.862457,14.205931,1.133727,-1304.448364,0.113398,0.000000
94.390007,62.678474,-1304.537354,0.009132,0.004463,0.113373,278.807770,14.203146,1.133727,-1304.537354,0.113398,0.000000
94.650002,62.654274,-1304.448364,0.009158,0.004463,0.113373,278.700134,14.197661,1.133727,-1304.448364,0.113398,0.000000
94.910004,62.631187,-1304.581787,0.009145,0.004463,0.113373,278.597443,14.192430,1.133727,-1304.581787,0.113398,0.000000
95.170006,62.637886,-1304.492798,0.009162,0.004463,0.113373,278.627228,14.193948,1.133727,-1304.492798,0.113398,0.000000
95.430008,62.599159,-1304.492798,0.009166,0.004463,0.113373,278.454956,14.185172,1.133727,-1304.492798,0.113398,0.000000
95.690002,62.590225,-1304.492798,0.009158,0.004463,0.113373,278.415222,14.183147,1.133727,-1304.492798,0.113398,0.000000
95.950005,62.576820,-1304.537354,0.009136,0.004463,0.113373,278.355591,14.180110,1.133727,-1304.537354,0.113398,0.000000
96.210007,62.535858,-1304.537354,0.009175,0.004463,0.113373,278.173401,14.170828,1.133727,-1304.537354,0.113398,0.000000
96.470001,62.534370,-1304.537354,0.009184,0.004463,0.113373,278.166779,14.170491,1.133727,-1304.537354,0.113398,0.000000
96.730003,62.508675,-1304.537354,0.009158,0.004463,0.113373,278.052460,14.164668,1.133727,-1304.537354,0.113398,0.000000
96.990005,62.493782,-1304.537354,0.009149,0.004463,0.113373,277.986237,14.161293,1.133727,-1304.537354,0.113398,0.000000
97.250008,62.485962,-1304.537354,0.009175,0.004463,0.113373,277.951447,14.159521,1.133727,-1304.537354,0.113398,0.000000
97.510002,62.458031,-1304.581787,0.009179,0.004463,0.113373,277.827209,14.153193,1.133727,-1304.581787,0.113398,0.000000
97.770004,62.439415,-1304.492798,0.009166,0.004463,0.113373,277.744385,14.148973,1.133727,-1304.492798,0.113398,0.000000
98.030006,62.431969,-1304.492798,0.009158,0.004463,0.113373,277.711273,14.147285,1.133727,-1304.492798,0.113398,0.000000
98.290001,62.402176,-1304.581787,0.009188,0.004463,0.113373,277.578735,14.140535,1.133727,-1304.581787,0.113398,0.000000
98.550003,62.409256,-1304.492798,0.009162,0.004463,0.113373,277.610229,14.142139,1.133727,-1304.492798,0.113398,0.000000
98.810005,62.383934,-1304.537354,0.009175,0.004463,0.113373,277.497589,14.136402,1.133727,-1304.537354,0.113398,0.000000
99.070007,62.368668,-1304.537354,0.009123,0.004463,0.113373,277.429687,14.132942,1.133727,-1304.537354,0.113398,0.000000
99.330002,62.363449,-1304.581787,0.009196,0.004463,0.113373,277.406464,14.131760,1.133727,-1304.581787,0.113398,0.000000
99.590004,62.342598,-1304.537354,0.009136,0.004463,0.113373,277.313721,14.127035,1.133727,-1304.537354,0.113398,0.000000
99.850006,62.321373,-1304.581787,0.009184,0.004463,0.113373,277.219299,14.122225,1.133727,-1304.581787,0.113398,0.000000
100.110008,62.330307,-1304.581787,0.009171,0.004463,0.113373,277.259064,14.124249,1.133727,-1304.581787,0.113398,0.000000
100.370003,62.293816,-1304.448364,0.009127,0.004463,0.113373,277.096741,14.115980,1.133727,-1304.448364,0.113398,0.000000
100.630005,62.285255,-1304.626343,0.009145,0.004463,0.113373,277.058655,14.114040,1.133727,-1304.626343,0.113398,0.000000
100.890007,62.268867,-1304.537354,0.009192,0.004463,0.113373,276.985748,14.110327,1.133727,-1304.537354,0.113398,0.000000
101.150002,62.240944,-1304.581787,0.009153,0.004463,0.113373,276.861542,14.103999,1.133727,-1304.581787,0.113398,0.000000
101.410004,62.250626,-1304.537354,0.009184,0.004463,0.113373,276.904602,14.106194,1.133727,-1304.537354,0.113398,0.000000
101.670006,62.216362,-1304.492798,0.009175,0.004463,0.113373,276.752197,14.098429,1.133727,-1304.492798,0.113398,0.000000
101.930008,62.192162,-1304.537354,0.009196,0.004463,0.113373,276.644562,14.092945,1.133727,-1304.537354,0.113398,0.000000
102.190002,62.193649,-1304.581787,0.009132,0.004463,0.113373,276.651184,14.093282,1.133727,-1304.581787,0.113398,0.000000
102.450005,62.157532,-1304.581787,0.009188,0.004463,0.113373,276.490509,14.085098,1.133727,-1304.581787,0.113398,0.000000
102.710007,62.166840,-1304.581787,0.009201,0.004463,0.113373,276.531921,14.087207,1.133727,-1304.581787,0.113398,0.000000
102.970001,62.153809,-1304.492798,0.009166,0.004463,0.113373,276.473938,14.084254,1.133727,-1304.492798,0.113398,0.000000
103.230003,62.120293,-1304.581787,0.009175,0.004463,0.113373,276.324860,14.076659,1.133727,-1304.581787,0.113398,0.000000
103.490005,62.113960,-1304.581787,0.009184,0.004463,0.113373,276.296692,14.075224,1.133727,-1304.581787,0.113398,0.000000
103.750008,62.095718,-1304.537354,0.009149,0.004463,0.113373,276.215546,14.071091,1.133727,-1304.537354,0.113398,0.000000
104.010002,62.075981,-1304.581787,0.009175,0.004463,0.113373,276.127747,14.066619,1.133727,-1304.581787,0.113398,0.000000
104.270004,62.071136,-1304.537354,0.009158,0.004463,0.113373,276.106201,14.065520,1.133727,-1304.537354,0.113398,0.000000
104.530006,62.055870,-1304.626343,0.009175,0.004463,0.113373,276.038300,14.062061,1.133727,-1304.626343,0.113398,0.000000
104.790009,62.026451,-1304.581787,0.009184,0.004463,0.113373,275.907440,14.055394,1.133727,-1304.581787,0.113398,0.000000
105.050003,62.037628,-1304.626343,0.009158,0.004463,0.113373,275.957153,14.057927,1.133727,-1304.626343,0.113398,0.000000
105.310005,62.029060,-1304.626343,0.009132,0.004463,0.113373,275.919037,14.055986,1.133727,-1304.626343,0.113398,0.000000
105.570007,61.999268,-1304.537354,0.009196,0.004463,0.113373,275.786530,14.049234,1.133727,-1304.537354,0.113398,0.000000
105.830002,62.013794,-1304.581787,0.009196,0.004463,0.113373,275.851135,14.052526,1.133727,-1304.581787,0.113398,0.000000
106.090004,61.996666,-1304.581787,0.009158,0.004463,0.113373,275.774933,14.048645,1.133727,-1304.581787,0.113398,0.000000
106.350006,61.968735,-1304.581787,0.009179,0.004463,0.113373,275.650696,14.042315,1.133727,-1304.581787,0.113398,0.000000
106.610008,61.994431,-1304.626343,0.009127,0.004463,0.113373,275.765015,14.048139,1.133727,-1304.626343,0.113398,0.000000
106.870003,61.975815,-1304.626343,0.009158,0.004463,0.113373,275.682190,14.043920,1.133727,-1304.626343,0.113398,0.000000
107.130005,61.950859,-1304.537354,0.009140,0.004463,0.113373,275.571198,14.038265,1.133727,-1304.537354,0.113398,0.000000
107.300003,61.961288,-1304.626343,0.009196,0.004463,0.113373,275.617584,14.040628,1.133727,-1304.626343,0.113398,0.000000