File: Data/Automembrane/AutoHeating-17wt-1-3_12152023_163810.csv
Time (sec),S:Load (lbs),S:HL1 (DIM),S:LVDT (in),S:Position (in),Ch:Position (mm),Ch:Load (N),Ch:Stress (MPa),Ch:Strain (mm/mm),Ch:HL1 (DIM),Set Point (),Cycles ()
0.110000,0.008560,-102.928925,-0.000022,-0.000000,-0.000000,0.038078,0.001940,-0.000000,-102.928925,0.000226,0.000000
0.340000,-0.000748,-102.839958,-0.000017,-0.000000,-0.000000,-0.003326,-0.000169,-0.000000,-102.839958,0.000226,0.000000
0.570000,0.105751,-102.928925,-0.000009,0.000116,0.002949,0.470404,0.023964,0.029488,-102.928925,0.003903,0.000000
0.800000,0.060692,-102.928925,0.000108,0.000261,0.006617,0.269971,0.013753,0.066171,-102.928925,0.007736,0.000000
1.030000,0.075218,-102.928925,0.000259,0.000411,0.010433,0.334587,0.017045,0.104331,-102.928925,0.011569,0.000000
1.260000,0.110962,-102.973404,0.000418,0.000566,0.014388,0.493583,0.025144,0.143875,-102.973404,0.015402,0.000000
1.490000,0.156021,-102.928925,0.000560,0.000708,0.017987,0.694017,0.035355,0.179866,-102.928925,0.019235,0.000000
1.720000,0.140381,-102.973404,0.000729,0.000868,0.022036,0.624445,0.031811,0.220364,-102.973404,0.023069,0.000000
1.950000,0.125862,-103.017883,0.000901,0.001018,0.025852,0.559863,0.028521,0.258523,-103.017883,0.026902,0.000000
2.180000,0.090111,-102.973404,0.001052,0.001166,0.029616,0.400833,0.020419,0.296160,-102.973404,0.030734,0.000000
2.410000,0.112823,-102.973404,0.001212,0.001312,0.033319,0.501864,0.025566,0.333188,-102.973404,0.034568,0.000000
2.640000,0.107986,-102.973404,0.001371,0.001464,0.037196,0.480348,0.024470,0.371957,-102.973404,0.038401,0.000000
2.870000,0.107239,-103.017883,0.001518,0.001616,0.041037,0.477022,0.024301,0.410373,-103.017883,0.042234,0.000000
3.100000,0.098305,-103.017883,0.001694,0.001772,0.045018,0.437281,0.022276,0.450179,-103.017883,0.046067,0.000000
3.330000,0.111336,-103.062363,0.001832,0.001918,0.048721,0.495246,0.025229,0.487211,-103.062363,0.049900,0.000000
3.560000,0.107239,-103.017883,0.001988,0.002074,0.052676,0.477022,0.024301,0.526755,-103.017883,0.053716,0.000000
3.790000,0.128464,-103.017883,0.002169,0.002225,0.056526,0.571435,0.029110,0.565259,-103.017883,0.057549,0.000000
4.020000,0.131821,-102.973404,0.002315,0.002368,0.060160,0.586368,0.029871,0.601598,-102.973404,0.061382,0.000000
4.250000,0.123627,-103.062363,0.002496,0.002528,0.064218,0.549919,0.028014,0.642183,-103.062363,0.065216,0.000000
4.480000,0.096069,-103.017883,0.002652,0.002676,0.067965,0.427338,0.021770,0.679646,-103.017883,0.069049,0.000000
4.710000,0.095695,-103.062363,0.002790,0.002826,0.071772,0.425675,0.021685,0.717718,-103.062363,0.072882,0.000000
4.940000,0.124741,-103.062363,0.002953,0.002981,0.075718,0.554874,0.028267,0.757176,-103.062363,0.076715,0.000000
5.170000,0.136658,-103.017883,0.003096,0.003123,0.079334,0.607884,0.030967,0.793341,-103.017883,0.080548,0.000000
5.400000,0.145226,-103.062363,0.003247,0.003274,0.083167,0.645995,0.032909,0.831670,-103.062363,0.084381,0.000000
5.630000,0.157883,-103.151329,0.003436,0.003433,0.087209,0.702297,0.035777,0.872085,-103.151329,0.088215,0.000000
5.860000,0.230125,-103.062363,0.003570,0.003580,0.090929,1.023649,0.052147,0.909287,-103.062363,0.092048,0.000000
6.090000,0.590584,-103.062363,0.003738,0.003731,0.094779,2.627048,0.133828,0.947794,-103.062363,0.095880,0.000000
6.320000,0.576057,-103.062363,0.003781,-0.000000,-0.000000,2.562431,0.130536,-0.000000,-103.062363,0.000226,0.000000
6.550000,0.530632,-103.106842,0.003803,-0.000000,-0.000000,2.360369,0.120243,-0.000000,-103.106842,0.000226,0.000000
6.780000,0.538078,-103.106842,0.003798,-0.000000,-0.000000,2.393492,0.121930,-0.000000,-103.106842,0.000408,0.000000
7.010000,0.525040,-103.151329,0.003777,-0.000000,-0.000000,2.335493,0.118976,-0.000000,-103.151329,0.000798,0.000000
7.240000,0.533607,-103.151329,0.003773,-0.000000,-0.000000,2.373605,0.120917,-0.000000,-103.151329,0.001180,0.000000
7.470000,0.642715,-103.106842,0.003794,0.000030,0.000772,2.858941,0.145641,0.007721,-103.106842,0.001561,0.000000
7.700000,0.712723,-103.151329,0.003816,0.000041,0.001041,3.170349,0.161505,0.010408,-103.151329,0.001943,0.000000
7.930000,0.737671,-103.195808,0.003850,0.000055,0.001405,3.281324,0.167159,0.014050,-103.195808,0.002324,0.000000
8.160001,0.777512,-103.195808,0.003859,0.000073,0.001865,3.458544,0.176187,0.018648,-103.195808,0.002715,0.000000
8.390000,0.822571,-103.151329,0.003863,0.000087,0.002212,3.658978,0.186397,0.022115,-103.151329,0.003096,0.000000
8.620001,0.878426,-103.106842,0.003867,0.000103,0.002610,3.907432,0.199054,0.026104,-103.106842,0.003478,0.000000
8.850000,0.905609,-103.151329,0.003893,0.000120,0.003044,4.028351,0.205214,0.030442,-103.151329,0.003859,0.000000
9.080001,0.922363,-103.240288,0.003911,0.000129,0.003270,4.102877,0.209010,0.032698,-103.240288,0.004241,0.000000
9.310000,1.012482,-103.240288,0.003919,0.000150,0.003807,4.503744,0.229432,0.038072,-103.240288,0.004631,0.000000
9.540001,1.080254,-103.240288,0.003932,0.000166,0.004206,4.805208,0.244789,0.042062,-103.240288,0.005013,0.000000
9.770000,1.115997,-103.195808,0.003945,0.000179,0.004553,4.964204,0.252889,0.045532,-103.195808,0.005394,0.000000
10.000000,1.123444,-103.195808,0.003962,0.000191,0.004848,4.997327,0.254576,0.048481,-103.195808,0.005776,0.000000
10.230000,1.216911,-103.240288,0.003975,0.000208,0.005273,5.413092,0.275756,0.052727,-103.240288,0.006158,0.000000
10.460000,1.218773,-103.284767,0.003980,0.000219,0.005551,5.421372,0.276178,0.055505,-103.284767,0.006548,0.000000
10.690001,1.424698,-103.284767,0.004018,0.000239,0.006079,6.337373,0.322841,0.060793,-103.284767,0.006929,0.000000
10.920000,1.441452,-103.240288,0.004010,0.000250,0.006357,6.411899,0.326638,0.063571,-103.240288,0.007311,0.000000
11.150001,1.524117,-103.240288,0.004044,0.000262,0.006652,6.779609,0.345370,0.066520,-103.240288,0.007692,0.000000
11.380000,1.745682,-103.240288,0.004049,0.000285,0.007242,7.765180,0.395577,0.072416,-103.240288,0.008083,0.000000
11.610001,1.797813,-103.329247,0.004070,0.000298,0.007571,7.997074,0.407390,0.075709,-103.329247,0.008464,0.000000
11.840000,1.883461,-103.329247,0.004074,0.000312,0.007918,8.378053,0.426798,0.079180,-103.329247,0.008846,0.000000
12.070001,1.991821,-103.240288,0.004100,0.000327,0.008308,8.860064,0.451353,0.083082,-103.240288,0.009228,0.000000
12.300000,2.046928,-103.329247,0.004087,0.000338,0.008594,9.105192,0.463841,0.085944,-103.329247,0.009609,0.000000
12.530001,2.290092,-103.329247,0.004139,0.000356,0.009054,10.186840,0.518942,0.090538,-103.329247,0.009999,0.000000
12.760000,2.397331,-103.329247,0.004148,0.000371,0.009436,10.663862,0.543243,0.094357,-103.329247,0.010381,0.000000
12.990001,2.402916,-103.329247,0.004161,0.000380,0.009652,10.688704,0.544509,0.096522,-103.329247,0.010762,0.000000
13.220000,2.746986,-103.329247,0.004174,0.000401,0.010190,12.219206,0.622476,0.101901,-103.329247,0.011144,0.000000
13.450001,2.928337,-103.284767,0.004199,0.000420,0.010658,13.025894,0.663571,0.106583,-103.284767,0.011526,0.000000
13.680000,2.981209,-103.373734,0.004195,0.000433,0.010997,13.261079,0.675552,0.109966,-103.373734,0.011916,0.000000
13.910001,3.106705,-103.373734,0.004217,0.000448,0.011387,13.819313,0.703989,0.113869,-103.373734,0.012298,0.000000
14.140000,3.244476,-103.462692,0.004217,0.000462,0.011734,14.432152,0.735209,0.117336,-103.462692,0.012679,0.000000
14.370001,3.357307,-103.329247,0.004238,0.000478,0.012132,14.934050,0.760777,0.121325,-103.329247,0.013061,0.000000
14.600000,3.558014,-103.329247,0.004247,0.000493,0.012523,15.826837,0.806257,0.125231,-103.329247,0.013442,0.000000
14.830001,3.681648,-103.418213,0.004273,0.000507,0.012870,16.376789,0.834273,0.128698,-103.418213,0.013832,0.000000
15.060000,3.839905,-103.462692,0.004268,0.000525,0.013329,17.080750,0.870135,0.133293,-103.462692,0.014214,0.000000
15.290001,4.008217,-103.462692,0.004294,0.000541,0.013746,17.829439,0.908275,0.137456,-103.462692,0.014596,0.000000
15.520000,4.234993,-103.418213,0.004320,0.000558,0.014179,18.838190,0.959663,0.141794,-103.418213,0.014977,0.000000
15.750001,4.255844,-103.373734,0.004316,0.000569,0.014457,18.930941,0.964388,0.144568,-103.373734,0.015359,0.000000
15.980000,4.410378,-103.462692,0.004337,0.000585,0.014856,19.618340,0.999406,0.148557,-103.462692,0.015749,0.000000
16.210001,4.653168,-103.418213,0.004350,0.000603,0.015315,20.698324,1.054423,0.153152,-103.418213,0.016130,0.000000
16.440001,4.785355,-103.462692,0.004363,0.000619,0.015732,21.286320,1.084377,0.157315,-103.462692,0.016512,0.000000
16.670000,4.764503,-103.418213,0.004402,0.000629,0.015983,21.193569,1.079652,0.159832,-103.418213,0.016894,0.000000
16.900002,4.693008,-103.507172,0.004406,0.000637,0.016174,20.875544,1.063451,0.161740,-103.507172,0.017275,0.000000
17.130001,5.219917,-103.507172,0.004411,0.000661,0.016790,23.219353,1.182850,0.167898,-103.507172,0.017666,0.000000
17.360001,5.319336,-103.462692,0.004428,0.000675,0.017145,23.661589,1.205379,0.171452,-103.462692,0.018047,0.000000
17.590000,5.367744,-103.462692,0.004449,0.000689,0.017509,23.876921,1.216348,0.175093,-103.462692,0.018429,0.000000
17.820002,5.473129,-103.507172,0.004471,0.000706,0.017926,24.345695,1.240229,0.179256,-103.507172,0.018810,0.000000
18.050001,5.691711,-103.462692,0.004467,0.000722,0.018333,25.317997,1.289760,0.183333,-103.462692,0.019192,0.000000
18.280001,5.886833,-103.462692,0.004506,0.000737,0.018732,26.185942,1.333976,0.187322,-103.462692,0.019582,0.000000
18.510000,6.031685,-103.507172,0.004497,0.000753,0.019114,26.830275,1.366799,0.191137,-103.507172,0.019964,0.000000
18.740002,5.909546,-103.462692,0.004523,0.000761,0.019331,26.286974,1.339122,0.193306,-103.462692,0.020345,0.000000
18.970001,6.061104,-103.551651,0.004540,0.000772,0.019608,26.961136,1.373466,0.196080,-103.551651,0.020727,0.000000
19.200001,6.652802,-103.551651,0.004544,0.000795,0.020198,29.593140,1.507546,0.201977,-103.551651,0.021117,0.000000
19.430000,6.756699,-103.507172,0.004557,0.000810,0.020571,30.055296,1.531090,0.205709,-103.507172,0.021499,0.000000
19.660002,6.742920,-103.551651,0.004579,0.000823,0.020900,29.994005,1.527968,0.209002,-103.551651,0.021880,0.000000
19.890001,7.079918,-103.596138,0.004609,0.000839,0.021317,31.493048,1.604332,0.213165,-103.596138,0.022262,0.000000
20.120001,7.275040,-103.507172,0.004605,0.000855,0.021715,32.360992,1.648548,0.217155,-103.507172,0.022644,0.000000
20.350000,7.514099,-103.507172,0.004618,0.000870,0.022088,33.424381,1.702719,0.220883,-103.507172,0.023034,0.000000
20.580002,7.737526,-103.596138,0.004639,0.000885,0.022470,34.418236,1.753348,0.224702,-103.596138,0.023415,0.000000
20.810001,7.864502,-103.596138,0.004639,0.000898,0.022808,34.983051,1.782122,0.228082,-103.596138,0.023797,0.000000
21.040001,7.970261,-103.640617,0.004639,0.000911,0.023138,35.453491,1.806087,0.231378,-103.640617,0.024178,0.000000
21.270000,8.635315,-103.596138,0.004682,0.000935,0.023754,38.411800,1.956790,0.237536,-103.596138,0.024560,0.000000
21.500002,8.582809,-103.596138,0.004695,0.000946,0.024040,38.178242,1.944892,0.240398,-103.596138,0.024950,0.000000
21.730001,8.697502,-103.685097,0.004708,0.000961,0.024404,38.688423,1.970882,0.244039,-103.685097,0.025332,0.000000
21.960001,8.957420,-103.640617,0.004708,0.000975,0.024768,39.844597,2.029780,0.247680,-103.640617,0.025713,0.000000
22.190001,9.400543,-103.596138,0.004743,0.000994,0.025245,41.815704,2.130194,0.252452,-103.596138,0.026095,0.000000
22.420002,9.485443,-103.640617,0.004751,0.001009,0.025627,42.193359,2.149432,0.256268,-103.640617,0.026476,0.000000
22.650002,9.485443,-103.640617,0.004756,0.001019,0.025887,42.193359,2.149432,0.258868,-103.640617,0.026867,0.000000
22.880001,9.614655,-103.685097,0.004756,0.001032,0.026208,42.768120,2.178712,0.262077,-103.685097,0.027249,0.000000
23.110001,10.327003,-103.640617,0.004781,0.001055,0.026789,45.936806,2.340132,0.267887,-103.640617,0.027630,0.000000
23.340002,10.573517,-103.640617,0.004794,0.001072,0.027240,47.033352,2.395993,0.272399,-103.640617,0.028012,0.000000
23.570002,10.540375,-103.685097,0.004816,0.001086,0.027578,46.885929,2.388483,0.275779,-103.685097,0.028393,0.000000
23.800001,10.840881,-103.685097,0.004816,0.001099,0.027925,48.222649,2.456579,0.279250,-103.685097,0.028783,0.000000
24.030001,11.109734,-103.729576,0.004850,0.001115,0.028315,49.418564,2.517502,0.283152,-103.729576,0.029165,0.000000
24.260000,11.310066,-103.729576,0.004846,0.001130,0.028697,50.309689,2.562898,0.286967,-103.729576,0.029546,0.000000
24.490002,11.426994,-103.774055,0.004850,0.001144,0.029061,50.829811,2.589394,0.290608,-103.774055,0.029928,0.000000
24.720001,11.420288,-103.729576,0.004898,0.001154,0.029304,50.799980,2.587874,0.293038,-103.729576,0.030310,0.000000
24.950001,11.952408,-103.818542,0.004881,0.001173,0.029789,53.166965,2.708454,0.297894,-103.818542,0.030700,0.000000
25.180000,12.506874,-103.818542,0.004907,0.001194,0.030336,55.633354,2.834098,0.303356,-103.818542,0.031082,0.000000
25.410002,12.373566,-103.863022,0.004919,0.001206,0.030630,55.040367,2.803890,0.306304,-103.863022,0.031463,0.000000
25.640001,12.427933,-103.729576,0.004919,0.001221,0.031004,55.282207,2.816210,0.310036,-103.729576,0.031845,0.000000
25.870001,12.587677,-103.685097,0.004963,0.001235,0.031359,55.992783,2.852408,0.313590,-103.685097,0.032226,0.000000
26.100000,13.071762,-103.685097,0.004980,0.001255,0.031871,58.146103,2.962104,0.318707,-103.685097,0.032617,0.000000
26.330002,13.095963,-103.774055,0.004975,0.001267,0.032174,58.253750,2.967588,0.321743,-103.774055,0.032998,0.000000
26.560001,12.871056,-103.818542,0.004988,0.001275,0.032374,57.253315,2.916623,0.323737,-103.818542,0.033380,0.000000
26.790001,13.517120,-103.774055,0.004984,0.001298,0.032963,60.127155,3.063023,0.329634,-103.774055,0.033761,0.000000
27.020000,13.838852,-103.729576,0.005027,0.001315,0.033406,61.558289,3.135929,0.334059,-103.729576,0.034143,0.000000
27.250002,13.890610,-103.818542,0.005019,0.001327,0.033709,61.788517,3.147657,0.337094,-103.818542,0.034533,0.000000
27.480001,13.947952,-103.863022,0.005044,0.001343,0.034100,62.043591,3.160651,0.340996,-103.863022,0.034915,0.000000
27.710001,14.000458,-103.818542,0.005040,0.001354,0.034403,62.277145,3.172549,0.344032,-103.818542,0.035296,0.000000
27.940001,14.355698,-103.818542,0.005057,0.001370,0.034802,63.857334,3.253048,0.348021,-103.818542,0.035678,0.000000
28.170002,14.106209,-103.818542,0.005083,0.001377,0.034984,62.747551,3.196512,0.349842,-103.818542,0.036068,0.000000
28.400002,14.692696,-103.863022,0.005105,0.001399,0.035539,65.356377,3.329412,0.355390,-103.863022,0.036450,0.000000
28.630001,14.709084,-103.951981,0.005105,0.001411,0.035851,65.429268,3.333126,0.358513,-103.951981,0.036831,0.000000
28.860001,15.377121,-103.907501,0.005122,0.001433,0.036398,68.400848,3.484505,0.363978,-103.907501,0.037213,0.000000
29.090002,15.227798,-103.863022,0.005131,0.001447,0.036753,67.736633,3.450669,0.367532,-103.863022,0.037594,0.000000
29.320002,15.390152,-103.818542,0.005152,0.001460,0.037074,68.458817,3.487458,0.370742,-103.818542,0.037985,0.000000
29.550001,15.578201,-103.863022,0.005161,0.001475,0.037473,69.295303,3.530071,0.374731,-103.863022,0.038366,0.000000
29.780001,15.497025,-103.907501,0.005161,0.001486,0.037751,68.934212,3.511676,0.377505,-103.907501,0.038748,0.000000
30.010002,16.011642,-103.907501,0.005200,0.001507,0.038271,71.223343,3.628290,0.382710,-103.907501,0.039129,0.000000
30.240002,16.087608,-103.907501,0.005191,0.001522,0.038661,71.561256,3.645504,0.386612,-103.907501,0.039511,0.000000
30.470001,15.753212,-103.907501,0.005221,0.001527,0.038791,70.073784,3.569729,0.387910,-103.907501,0.039901,0.000000
30.700001,16.513229,-103.907501,0.005226,0.001550,0.039372,73.454514,3.741951,0.393724,-103.907501,0.040283,0.000000
30.930002,16.764580,-103.996460,0.005273,0.001569,0.039841,74.572578,3.798908,0.398406,-103.996460,0.040665,0.000000
31.160002,16.680054,-103.951981,0.005256,0.001580,0.040135,74.196587,3.779754,0.401354,-103.951981,0.041046,0.000000
31.390001,16.942574,-103.951981,0.005251,0.001598,0.040577,75.364334,3.839242,0.405775,-103.951981,0.041428,0.000000
31.620001,16.913155,-103.863022,0.005299,0.001609,0.040881,75.233467,3.832576,0.408810,-103.863022,0.041818,0.000000
31.850002,17.018539,-103.951981,0.005299,0.001622,0.041211,75.702248,3.856456,0.412107,-103.951981,0.042199,0.000000
32.080002,17.357765,-103.996460,0.005307,0.001639,0.041636,77.211197,3.933326,0.416357,-103.996460,0.042581,0.000000
32.310001,17.229301,-103.996460,0.005329,0.001649,0.041878,76.639763,3.904216,0.418783,-103.996460,0.042963,0.000000
32.540001,17.575981,-103.951981,0.005329,0.001665,0.042303,78.181870,3.982774,0.423034,-103.951981,0.043344,0.000000
32.770000,18.119644,-103.996460,0.005351,0.001687,0.042859,80.600204,4.105970,0.428586,-103.996460,0.043734,0.000000
33.000000,18.365036,-103.996460,0.005364,0.001705,0.043318,81.691757,4.161577,0.433181,-103.996460,0.044116,0.000000
33.230003,18.185181,-104.040947,0.005376,0.001716,0.043578,80.891724,4.120821,0.435781,-104.040947,0.044497,0.000000
33.460003,18.184433,-104.040947,0.005381,0.001729,0.043925,80.888397,4.120652,0.439252,-104.040947,0.044879,0.000000
33.690002,18.006065,-104.040947,0.005411,0.001741,0.044229,80.094978,4.080233,0.442288,-104.040947,0.045261,0.000000
33.920002,18.348648,-103.996460,0.005424,0.001755,0.044575,81.618866,4.157863,0.445755,-103.996460,0.045651,0.000000
34.150002,18.915771,-104.040947,0.005433,0.001775,0.045096,84.141556,4.286375,0.450959,-104.040947,0.046033,0.000000
34.380001,18.370621,-104.040947,0.005437,0.001783,0.045287,81.716599,4.162842,0.452866,-104.040947,0.046414,0.000000
34.610001,19.242348,-103.996460,0.005454,0.001806,0.045885,85.594238,4.360378,0.458850,-103.996460,0.046796,0.000000
34.840000,19.371185,-104.040947,0.005476,0.001822,0.046267,86.167336,4.389573,0.462666,-104.040947,0.047177,0.000000
35.070004,19.393898,-104.085426,0.005476,0.001834,0.046588,86.268364,4.394720,0.465875,-104.085426,0.047567,0.000000
35.300003,19.522369,-104.129906,0.005471,0.001851,0.047013,86.839836,4.423832,0.470126,-104.129906,0.047949,0.000000
35.530003,19.528328,-104.129906,0.005502,0.001866,0.047385,86.866341,4.425182,0.473854,-104.129906,0.048331,0.000000
35.760002,20.063057,-104.085426,0.005523,0.001885,0.047880,89.244934,4.546354,0.478797,-104.085426,0.048712,0.000000
35.990002,19.913361,-104.085426,0.005532,0.001896,0.048166,88.579048,4.512432,0.481658,-104.085426,0.049094,0.000000
36.220001,19.869789,-104.085426,0.005540,0.001909,0.048478,88.385239,4.502559,0.484781,-104.085426,0.049484,0.000000
36.450001,20.365417,-104.218872,0.005570,0.001928,0.048972,90.589905,4.614870,0.489724,-104.218872,0.049866,0.000000
36.680000,20.703911,-104.174385,0.005570,0.001946,0.049424,92.095596,4.691573,0.494235,-104.174385,0.050247,0.000000
36.910000,20.625336,-104.129906,0.005579,0.001958,0.049744,91.746078,4.673768,0.497441,-104.129906,0.050629,0.000000
37.140003,20.384415,-104.129906,0.005592,0.001970,0.050030,90.674408,4.619174,0.500303,-104.129906,0.051019,0.000000
37.370003,20.723640,-104.129906,0.005622,0.001988,0.050499,92.183357,4.696044,0.504988,-104.129906,0.051401,0.000000
37.600002,21.064362,-104.218872,0.005627,0.002004,0.050906,93.698959,4.773253,0.509065,-104.218872,0.051782,0.000000
37.830002,21.320557,-104.174385,0.005644,0.002021,0.051331,94.838570,4.831307,0.513311,-104.174385,0.052164,0.000000
38.060001,21.160805,-104.129906,0.005657,0.002032,0.051617,94.127960,4.795107,0.516173,-104.129906,0.052545,0.000000
38.290001,21.000313,-104.174385,0.005652,0.002042,0.051869,93.414055,4.758739,0.518690,-104.174385,0.052936,0.000000
38.520000,21.554779,-104.174385,0.005674,0.002063,0.052398,95.880447,4.884383,0.523981,-104.174385,0.053317,0.000000
38.750000,21.946144,-104.218872,0.005691,0.002081,0.052849,97.621323,4.973067,0.528489,-104.218872,0.053699,0.000000
38.980003,21.854538,-104.174385,0.005674,0.002091,0.053109,97.213837,4.952309,0.531089,-104.174385,0.054080,0.000000
39.210003,22.072372,-104.174385,0.005734,0.002108,0.053551,98.182816,5.001671,0.535513,-104.174385,0.054462,0.000000
39.440002,22.232124,-104.218872,0.005739,0.002124,0.053950,98.893425,5.037871,0.539503,-104.218872,0.054852,0.000000
39.670002,22.488686,-104.218872,0.005747,0.002140,0.054358,100.034668,5.096009,0.543579,-104.218872,0.055234,0.000000
39.900002,22.416077,-104.263351,0.005756,0.002153,0.054688,99.711685,5.079556,0.546876,-104.263351,0.055615,0.000000
40.130001,22.290962,-104.263351,0.005777,0.002165,0.054999,99.155151,5.051204,0.549994,-104.263351,0.055997,0.000000
40.360001,22.249626,-104.174385,0.005773,0.002176,0.055277,98.971283,5.041838,0.552773,-104.174385,0.056379,0.000000
40.590000,22.949310,-104.263351,0.005795,0.002197,0.055815,102.083633,5.200388,0.558147,-104.263351,0.056769,0.000000
40.820004,23.275513,-104.307831,0.005795,0.002215,0.056248,103.534653,5.274307,0.562485,-104.307831,0.057150,0.000000
41.050003,23.160820,-104.352310,0.005803,0.002226,0.056543,103.024475,5.248317,0.565433,-104.352310,0.057532,0.000000
41.280003,23.476967,-104.307831,0.005833,0.002243,0.056968,104.430763,5.319956,0.569683,-104.307831,0.057913,0.000000
41.510002,23.310516,-104.307831,0.005833,0.002254,0.057263,103.690353,5.282238,0.572632,-104.307831,0.058295,0.000000
41.740002,23.684006,-104.352310,0.005859,0.002273,0.057723,105.351723,5.366872,0.577227,-104.352310,0.058685,0.000000
41.970001,23.874283,-104.352310,0.005851,0.002289,0.058130,106.198112,5.409990,0.581303,-104.352310,0.059067,0.000000
42.200001,23.949135,-104.307831,0.005872,0.002301,0.058443,106.531075,5.426951,0.584426,-104.307831,0.059449,0.000000
42.430000,24.302139,-104.307831,0.005881,0.002319,0.058893,108.101311,5.506943,0.588933,-104.307831,0.059830,0.000000
42.660004,24.881180,-104.352310,0.005907,0.002337,0.059353,110.677017,5.638156,0.593532,-104.352310,0.060212,0.000000
42.890003,24.601898,-104.352310,0.005902,0.002348,0.059648,109.434708,5.574870,0.596481,-104.352310,0.060602,0.000000
43.120003,24.783623,-104.396790,0.005928,0.002362,0.060003,110.243057,5.616049,0.600035,-104.396790,0.060983,0.000000
43.350002,24.816017,-104.396790,0.005937,0.002376,0.060359,110.387154,5.623390,0.603592,-104.396790,0.061365,0.000000
43.580002,25.280365,-104.307831,0.005950,0.002393,0.060793,112.452682,5.728613,0.607926,-104.307831,0.061747,0.000000
43.810001,25.473251,-104.352310,0.005967,0.002408,0.061174,113.310684,5.772321,0.611741,-104.352310,0.062128,0.000000
44.040001,25.484055,-104.396790,0.005984,0.002422,0.061530,113.358734,5.774769,0.615299,-104.396790,0.062519,0.000000
44.270000,25.413300,-104.441277,0.005967,0.002433,0.061807,113.043999,5.758736,0.618073,-104.441277,0.062900,0.000000
44.500004,26.398972,-104.396790,0.005989,0.002461,0.062501,117.428490,5.982092,0.625011,-104.396790,0.063282,0.000000
44.730003,26.454453,-104.352310,0.006023,0.002473,0.062805,117.675285,5.994665,0.628047,-104.352310,0.063663,0.000000
44.960003,26.483131,-104.396790,0.006023,0.002486,0.063152,117.802849,6.001163,0.631517,-104.396790,0.064045,0.000000
45.190002,26.693146,-104.396790,0.006023,0.002502,0.063551,118.737045,6.048753,0.635507,-104.396790,0.064435,0.000000
45.420002,26.804115,-104.530235,0.006071,0.002518,0.063967,119.230659,6.073899,0.639666,-104.530235,0.064817,0.000000
45.650002,26.985832,-104.485756,0.006071,0.002531,0.064279,120.038979,6.115077,0.642789,-104.485756,0.065198,0.000000
45.880001,27.123978,-104.396790,0.006075,0.002544,0.064609,120.653481,6.146381,0.646085,-104.396790,0.065580,0.000000
46.110001,27.122864,-104.396790,0.006101,0.002557,0.064947,120.648521,6.146129,0.649465,-104.396790,0.065970,0.000000
46.340004,27.604713,-104.530235,0.006109,0.002574,0.065380,122.791901,6.255318,0.653803,-104.530235,0.066351,0.000000
46.570004,28.365097,-104.530235,0.006131,0.002597,0.065961,126.174255,6.427623,0.659613,-104.530235,0.066733,0.000000
46.800003,28.251152,-104.441277,0.006122,0.002610,0.066291,125.667404,6.401803,0.662909,-104.441277,0.067115,0.000000
47.030003,28.262321,-104.396790,0.006131,0.002622,0.066603,125.717087,6.404334,0.666032,-104.396790,0.067496,0.000000
47.260002,28.334564,-104.485756,0.006174,0.002637,0.066976,126.038437,6.420704,0.669760,-104.485756,0.067887,0.000000
47.490002,29.005203,-104.530235,0.006170,0.002655,0.067435,129.021591,6.572673,0.674355,-104.530235,0.068268,0.000000
47.720001,29.028664,-104.574715,0.006183,0.002669,0.067783,129.125946,6.577990,0.677826,-104.574715,0.068650,0.000000
47.950001,28.836891,-104.485756,0.006191,0.002677,0.068008,128.272903,6.534533,0.680081,-104.485756,0.069031,0.000000
48.180004,29.667656,-104.574715,0.006187,0.002701,0.068607,131.968323,6.722787,0.686065,-104.574715,0.069413,0.000000
48.410004,30.076523,-104.485756,0.006234,0.002717,0.069022,133.787048,6.815437,0.690225,-104.485756,0.069803,0.000000
48.640003,29.960342,-104.574715,0.006234,0.002728,0.069283,133.270264,6.789111,0.692829,-104.574715,0.070185,0.000000
48.870003,30.242599,-104.574715,0.006239,0.002744,0.069699,134.525803,6.853071,0.696992,-104.574715,0.070566,0.000000
49.100002,30.222862,-104.530235,0.006252,0.002757,0.070020,134.438004,6.848598,0.700198,-104.530235,0.070948,0.000000
49.330002,30.603798,-104.574715,0.006269,0.002774,0.070454,136.132492,6.934920,0.704535,-104.574715,0.071329,0.000000
49.560001,31.002983,-104.574715,0.006278,0.002788,0.070818,137.908157,7.025376,0.708177,-104.574715,0.071720,0.000000
49.790001,30.931114,-104.619194,0.006286,0.002798,0.071061,137.588470,7.009090,0.710606,-104.619194,0.072101,0.000000
50.020004,31.173531,-104.574715,0.006291,0.002813,0.071442,138.666794,7.064023,0.714422,-104.574715,0.072483,0.000000
50.250004,32.187126,-104.619194,0.006321,0.002836,0.072023,143.175491,7.293707,0.720231,-104.619194,0.072865,0.000000
50.480003,32.240379,-104.530235,0.006338,0.002849,0.072362,143.412369,7.305774,0.723615,-104.530235,0.073246,0.000000
50.710003,32.393799,-104.619194,0.006351,0.002863,0.072717,144.094818,7.340539,0.727169,-104.619194,0.073636,0.000000
50.940002,32.852562,-104.619194,0.006368,0.002880,0.073159,146.135498,7.444497,0.731594,-104.619194,0.074018,0.000000
51.170002,32.579979,-104.663681,0.006372,0.002888,0.073359,144.922989,7.382729,0.733588,-104.663681,0.074399,0.000000
51.400002,33.538094,-104.574715,0.006377,0.002909,0.073896,149.184891,7.599841,0.738963,-104.574715,0.074781,0.000000
51.630001,33.660233,-104.663681,0.006403,0.002922,0.074217,149.728195,7.627518,0.742172,-104.663681,0.075163,0.000000
51.860001,33.676620,-104.619194,0.006411,0.002934,0.074512,149.801086,7.631231,0.745121,-104.619194,0.075553,0.000000
52.090004,34.202782,-104.663681,0.006420,0.002951,0.074955,152.141571,7.750461,0.749545,-104.663681,0.075934,0.000000
52.320004,35.017906,-104.708160,0.006424,0.002972,0.075484,155.767426,7.935171,0.754837,-104.708160,0.076316,0.000000
52.550003,34.877518,-104.663681,0.006441,0.002982,0.075744,155.142944,7.903358,0.757437,-104.663681,0.076697,0.000000
52.780003,35.411133,-104.663681,0.006450,0.002998,0.076160,157.516586,8.024278,0.761600,-104.663681,0.077079,0.000000
53.010002,35.458420,-104.663681,0.006480,0.003010,0.076446,157.726929,8.034992,0.764462,-104.663681,0.077470,0.000000
53.240002,35.598061,-104.752640,0.006480,0.003021,0.076741,158.348083,8.066636,0.767410,-104.752640,0.077851,0.000000
53.470001,36.203537,-104.708160,0.006476,0.003038,0.077166,161.041382,8.203839,0.771661,-104.708160,0.078233,0.000000
53.700001,36.187897,-104.663681,0.006506,0.003048,0.077417,160.971802,8.200294,0.774174,-104.663681,0.078614,0.000000
53.930004,37.172455,-104.663681,0.006523,0.003072,0.078024,165.351334,8.423399,0.780245,-104.663681,0.078996,0.000000
54.160004,37.930603,-104.752640,0.006532,0.003090,0.078484,168.723755,8.595198,0.784840,-104.752640,0.079386,0.000000
54.390003,38.376335,-104.797119,0.006541,0.003105,0.078857,170.706467,8.696202,0.788572,-104.797119,0.079767,0.000000
54.620003,38.505547,-104.708160,0.006549,0.003119,0.079230,171.281219,8.725482,0.792300,-104.708160,0.080149,0.000000
54.850002,38.636620,-104.708160,0.006566,0.003131,0.079516,171.864273,8.755183,0.795161,-104.708160,0.080531,0.000000
55.080002,39.025002,-104.797119,0.006592,0.003146,0.079906,173.591873,8.843192,0.799063,-104.797119,0.080921,0.000000
55.310001,39.663994,-104.752640,0.006588,0.003160,0.080270,176.434250,8.987989,0.802704,-104.752640,0.081303,0.000000
55.540001,40.057968,-104.841599,0.006614,0.003175,0.080644,178.186737,9.077265,0.806436,-104.841599,0.081684,0.000000
55.770004,40.313789,-104.797119,0.006622,0.003190,0.081025,179.324692,9.135235,0.810251,-104.797119,0.082066,0.000000
56.000004,41.068588,-104.752640,0.006627,0.003206,0.081424,182.682205,9.306275,0.814241,-104.752640,0.082447,0.000000
56.230003,41.863976,-104.841599,0.006644,0.003226,0.081944,186.220261,9.486512,0.819445,-104.841599,0.082838,0.000000
56.460003,42.168945,-104.797119,0.006653,0.003241,0.082326,187.576843,9.555619,0.823260,-104.797119,0.083219,0.000000
56.690002,42.525681,-104.841599,0.006653,0.003253,0.082630,189.163681,9.636457,0.826296,-104.841599,0.083601,0.000000
56.920002,43.235046,-104.797119,0.006661,0.003271,0.083089,192.319092,9.797201,0.830890,-104.797119,0.083982,0.000000
57.150002,43.828979,-104.841599,0.006670,0.003286,0.083471,194.961044,9.931788,0.834706,-104.841599,0.084364,0.000000
57.380001,43.944786,-104.797119,0.006700,0.003300,0.083809,195.476166,9.958031,0.838089,-104.797119,0.084754,0.000000
57.610004,44.146988,-104.886086,0.006700,0.003309,0.084052,196.375610,10.003850,0.840515,-104.886086,0.085136,0.000000
57.840004,45.140480,-104.841599,0.006717,0.003330,0.084589,200.794876,10.228979,0.845894,-104.841599,0.085517,0.000000
58.070004,45.903839,-104.886086,0.006730,0.003346,0.084988,204.190475,10.401958,0.849883,-104.886086,0.085899,0.000000
58.300003,46.200996,-104.841599,0.006739,0.003358,0.085283,205.512299,10.469296,0.852831,-104.841599,0.086280,0.000000
58.530003,46.687683,-104.930565,0.006760,0.003376,0.085743,207.677185,10.579579,0.857426,-104.930565,0.086671,0.000000
58.760002,47.429077,-104.930565,0.006765,0.003389,0.086090,210.975067,10.747582,0.860897,-104.930565,0.087052,0.000000
58.990002,48.451988,-104.930565,0.006769,0.003410,0.086619,215.525208,10.979378,0.866188,-104.930565,0.087434,0.000000
59.220001,48.838882,-104.886086,0.006773,0.003422,0.086922,217.246201,11.067049,0.869224,-104.886086,0.087816,0.000000
59.450005,48.924530,-104.930565,0.006799,0.003432,0.087165,217.627182,11.086456,0.871650,-104.930565,0.088197,0.000000
59.680004,49.122627,-104.930565,0.006808,0.003442,0.087425,218.508362,11.131347,0.874250,-104.930565,0.088587,0.000000
59.910004,50.180908,-105.019524,0.006829,0.003463,0.087972,223.215820,11.371157,0.879716,-105.019524,0.088969,0.000000
60.140003,51.371010,-104.975044,0.006838,0.003482,0.088448,228.509659,11.640837,0.884485,-104.975044,0.089350,0.000000
60.370003,51.432083,-104.975044,0.006855,0.003489,0.088631,228.781326,11.654676,0.886305,-104.975044,0.089732,0.000000
60.600002,52.479568,-104.975044,0.006860,0.003511,0.089168,233.440781,11.892040,0.891683,-104.975044,0.090113,0.000000
60.830002,53.059723,-104.975044,0.006851,0.003524,0.089498,236.021439,12.023505,0.894980,-104.975044,0.090504,0.000000
61.060001,53.955276,-104.975044,0.006868,0.003542,0.089966,240.005051,12.226440,0.899662,-104.975044,0.090886,0.000000
61.290005,54.323929,-104.975044,0.006881,0.003551,0.090192,241.644897,12.309978,0.901918,-104.975044,0.091267,0.000000
61.520004,54.843018,-104.975044,0.006907,0.003567,0.090591,243.953934,12.427606,0.905907,-104.975044,0.091649,0.000000
61.750004,54.586075,-105.019524,0.006898,0.003568,0.090634,242.810989,12.369382,0.906339,-105.019524,0.092030,0.000000
61.980003,56.485176,-105.064003,0.006911,0.003599,0.091414,251.258606,12.799724,0.914143,-105.064003,0.092420,0.000000
62.210003,57.500633,-105.019524,0.006920,0.003614,0.091787,255.775589,13.029830,0.917875,-105.019524,0.092802,0.000000
62.440002,58.256927,-105.019524,0.006924,0.003632,0.092247,259.139771,13.201208,0.922470,-105.019524,0.093184,0.000000
62.670002,58.922729,-105.019524,0.006946,0.003643,0.092533,262.101379,13.352081,0.925331,-105.019524,0.093565,0.000000
62.900002,59.317818,-105.019524,0.006963,0.003654,0.092802,263.858826,13.441610,0.928018,-105.019524,0.093955,0.000000
63.130005,60.429718,-105.064003,0.006976,0.003673,0.093305,268.804810,13.693569,0.933049,-105.064003,0.094337,0.000000
63.360004,61.373314,-105.108490,0.006976,0.003688,0.093687,273.002136,13.907392,0.936867,-105.108490,0.094719,0.000000
63.590004,61.915855,-105.064003,0.006998,0.003699,0.093964,275.415466,14.030334,0.939642,-105.064003,0.095100,0.000000
63.820004,63.099251,-105.019524,0.006993,0.003720,0.094484,280.679474,14.298494,0.944842,-105.019524,0.095482,0.000000
64.050003,64.345589,-105.064003,0.007015,0.003739,0.094970,286.223480,14.580919,0.949702,-105.064003,0.095872,0.000000
64.280006,64.641258,-105.108490,0.007006,0.003748,0.095204,287.538666,14.647919,0.952041,-105.108490,0.096254,0.000000
64.510002,65.394936,-105.152969,0.007019,0.003763,0.095586,290.891205,14.818705,0.955856,-105.152969,0.096635,0.000000
64.740005,66.092384,-105.064003,0.007032,0.003778,0.095959,293.993622,14.976748,0.959588,-105.064003,0.097017,0.000000
64.970001,67.634377,-105.064003,0.007045,0.003792,0.096314,300.852722,15.326169,0.963142,-105.064003,0.097372,0.000000
65.200005,66.754845,-105.064003,0.007062,0.003788,0.096228,296.940369,15.126863,0.962276,-105.064003,0.096444,0.000000
65.430000,66.109520,-105.152969,0.007058,0.003786,0.096175,294.069824,14.980632,0.961753,-105.152969,0.096219,0.000000
65.660004,65.462700,-105.152969,0.007075,0.003785,0.096150,291.192627,14.834060,0.961496,-105.152969,0.096219,0.000000
65.889999,64.885155,-105.064003,0.007080,0.003785,0.096132,288.623596,14.703186,0.961322,-105.064003,0.096219,0.000000
66.120003,64.338142,-105.064003,0.007084,0.003784,0.096123,286.190338,14.579231,0.961235,-105.064003,0.096219,0.000000
66.350006,63.865227,-105.108490,0.007075,0.003784,0.096115,284.086731,14.472067,0.961148,-105.108490,0.096219,0.000000
66.580002,63.423225,-105.197449,0.007088,0.003784,0.096106,282.120605,14.371908,0.961061,-105.197449,0.096219,0.000000
66.810005,63.004303,-105.241928,0.007075,0.003784,0.096106,280.257141,14.276979,0.961061,-105.241928,0.096219,0.000000
67.040001,62.615913,-105.197449,0.007097,0.003784,0.096106,278.529480,14.188969,0.961061,-105.197449,0.096219,0.000000
67.270004,62.261787,-105.152969,0.007101,0.003783,0.096097,276.954254,14.108723,0.960974,-105.152969,0.096219,0.000000
67.500000,61.927773,-105.197449,0.007084,0.003783,0.096097,275.468475,14.033034,0.960974,-105.197449,0.096219,0.000000
67.730003,61.616096,-105.241928,0.007084,0.003783,0.096097,274.082092,13.962407,0.960974,-105.241928,0.096219,0.000000
67.960007,61.334587,-105.241928,0.007092,0.003783,0.096097,272.829865,13.898617,0.960974,-105.241928,0.096219,0.000000
68.190002,61.072060,-105.197449,0.007084,0.003783,0.096097,271.662079,13.839127,0.960974,-105.197449,0.096219,0.000000
68.420006,60.795013,-105.197449,0.007101,0.003783,0.096097,270.429718,13.776346,0.960974,-105.197449,0.096219,0.000000
68.650002,60.542549,-105.152969,0.007101,0.003783,0.096089,269.306702,13.719138,0.960886,-105.152969,0.096219,0.000000
68.880005,60.321732,-105.330894,0.007101,0.003783,0.096089,268.324463,13.669100,0.960886,-105.330894,0.096219,0.000000
69.110001,60.115807,-105.286407,0.007097,0.003783,0.096089,267.408478,13.622437,0.960886,-105.286407,0.096219,0.000000
69.340004,59.897224,-105.197449,0.007097,0.003783,0.096089,266.436157,13.572905,0.960886,-105.197449,0.096219,0.000000
69.570000,59.701355,-105.286407,0.007084,0.003783,0.096089,265.564880,13.528521,0.960886,-105.286407,0.096219,0.000000
69.800003,59.521133,-105.286407,0.007092,0.003783,0.096089,264.763214,13.487681,0.960886,-105.286407,0.096219,0.000000
70.030006,59.352448,-105.241928,0.007110,0.003783,0.096089,264.012878,13.449456,0.960886,-105.241928,0.096219,0.000000
70.260002,59.168121,-105.286407,0.007105,0.003783,0.096089,263.192963,13.407688,0.960886,-105.286407,0.096219,0.000000
70.490005,59.010605,-105.286407,0.007123,0.003783,0.096089,262.492279,13.371994,0.960886,-105.286407,0.096219,0.000000
70.720001,58.843781,-105.286407,0.007118,0.003783,0.096089,261.750214,13.334191,0.960886,-105.286407,0.096219,0.000000
70.950005,58.700790,-105.330894,0.007114,0.003783,0.096089,261.114166,13.301789,0.960886,-105.330894,0.096219,0.000000
71.180000,58.557800,-105.330894,0.007123,0.003783,0.096089,260.478119,13.269387,0.960886,-105.330894,0.096219,0.000000
71.410004,58.422630,-105.375374,0.007114,0.003783,0.096089,259.876831,13.238757,0.960886,-105.375374,0.096219,0.000000
71.640007,58.278152,-105.286407,0.007118,0.003783,0.096089,259.234161,13.206018,0.960886,-105.286407,0.096219,0.000000
71.870003,58.162712,-105.286407,0.007123,0.003783,0.096089,258.720673,13.179858,0.960886,-105.286407,0.096219,0.000000
72.100006,58.034622,-105.375374,0.007123,0.003783,0.096089,258.150879,13.150833,0.960886,-105.375374,0.096219,0.000000
72.330002,57.911362,-105.419853,0.007110,0.003783,0.096089,257.602600,13.122903,0.960886,-105.419853,0.096219,0.000000
72.560005,57.786987,-105.375374,0.007127,0.003783,0.096080,257.049347,13.094719,0.960799,-105.375374,0.096219,0.000000
72.790001,57.670815,-105.286407,0.007114,0.003783,0.096080,256.532593,13.068394,0.960799,-105.286407,0.096219,0.000000
73.020004,57.588142,-105.375374,0.007123,0.003783,0.096080,256.164856,13.049660,0.960799,-105.375374,0.096219,0.000000
73.250000,57.469727,-105.375374,0.007123,0.003783,0.096080,255.638107,13.022825,0.960799,-105.375374,0.096219,0.000000
73.480003,57.362862,-105.464333,0.007114,0.003783,0.096080,255.162750,12.998610,0.960799,-105.464333,0.096219,0.000000
73.710007,57.272369,-105.464333,0.007101,0.003783,0.096080,254.760223,12.978105,0.960799,-105.464333,0.096219,0.000000
73.940002,57.179649,-105.375374,0.007118,0.003783,0.096080,254.347778,12.957093,0.960799,-105.375374,0.096219,0.000000
74.170006,57.088051,-105.375374,0.007127,0.003783,0.096080,253.940338,12.936337,0.960799,-105.375374,0.096219,0.000000
74.400002,56.991600,-105.508820,0.007114,0.003783,0.096080,253.511292,12.914481,0.960799,-105.508820,0.096219,0.000000
74.630005,56.916382,-105.419853,0.007131,0.003783,0.096080,253.176712,12.897436,0.960799,-105.419853,0.096219,0.000000
74.860001,56.819939,-105.419853,0.007127,0.003783,0.096080,252.747711,12.875582,0.960799,-105.419853,0.096219,0.000000
75.090004,56.736526,-105.464333,0.007114,0.003783,0.096080,252.376678,12.856681,0.960799,-105.464333,0.096219,0.000000
75.320007,56.662056,-105.464333,0.007118,0.003783,0.096080,252.045410,12.839806,0.960799,-105.464333,0.096219,0.000000
75.550003,56.587204,-105.508820,0.007127,0.003783,0.096080,251.712448,12.822844,0.960799,-105.508820,0.096219,0.000000
75.780006,56.499329,-105.464333,0.007105,0.003783,0.096080,251.321564,12.802931,0.960799,-105.464333,0.096219,0.000000
76.010002,56.425598,-105.508820,0.007131,0.003783,0.096080,250.993591,12.786223,0.960799,-105.508820,0.096219,0.000000
76.240005,56.367508,-105.464333,0.007123,0.003783,0.096080,250.735199,12.773060,0.960799,-105.464333,0.096219,0.000000
76.470001,56.297501,-105.508820,0.007127,0.003783,0.096080,250.423782,12.757195,0.960799,-105.508820,0.096219,0.000000
76.700005,56.203667,-105.508820,0.007136,0.003783,0.096080,250.006393,12.735933,0.960799,-105.508820,0.096219,0.000000
76.930000,56.146317,-105.508820,0.007118,0.003783,0.096080,249.751297,12.722938,0.960799,-105.508820,0.096219,0.000000
77.160004,56.088226,-105.508820,0.007136,0.003783,0.096080,249.492889,12.709774,0.960799,-105.508820,0.096219,0.000000
77.390007,56.019714,-105.464333,0.007144,0.003783,0.096080,249.188141,12.694249,0.960799,-105.464333,0.096219,0.000000
77.620003,55.944862,-105.508820,0.007131,0.003783,0.096080,248.855179,12.677287,0.960799,-105.508820,0.096219,0.000000
77.850006,55.890495,-105.508820,0.007140,0.003783,0.096080,248.613342,12.664968,0.960799,-105.508820,0.096219,0.000000
78.080002,55.833900,-105.597778,0.007140,0.003783,0.096080,248.361588,12.652143,0.960799,-105.597778,0.096219,0.000000
78.310005,55.757561,-105.553299,0.007131,0.003783,0.096080,248.022018,12.634845,0.960799,-105.553299,0.096219,0.000000
78.540001,55.695000,-105.553299,0.007118,0.003783,0.096080,247.743729,12.620667,0.960799,-105.553299,0.096219,0.000000
78.770004,55.647339,-105.597778,0.007123,0.003783,0.096080,247.531723,12.609867,0.960799,-105.597778,0.096219,0.000000
79.000000,55.594460,-105.553299,0.007127,0.003783,0.096080,247.296509,12.597884,0.960799,-105.553299,0.096219,0.000000
79.230003,55.532272,-105.597778,0.007114,0.003783,0.096080,247.019882,12.583793,0.960799,-105.597778,0.096219,0.000000
79.460007,55.472694,-105.553299,0.007136,0.003783,0.096080,246.754868,12.570292,0.960799,-105.553299,0.096219,0.000000
79.690002,55.429131,-105.553299,0.007131,0.003783,0.096080,246.561081,12.560420,0.960799,-105.553299,0.096219,0.000000
79.920006,55.379974,-105.642258,0.007140,0.003783,0.096080,246.342422,12.549281,0.960799,-105.642258,0.096219,0.000000
80.150002,55.318535,-105.642258,0.007144,0.003783,0.096080,246.069138,12.535359,0.960799,-105.642258,0.096219,0.000000
80.380005,55.268639,-105.642258,0.007127,0.003783,0.096080,245.847183,12.524053,0.960799,-105.642258,0.096219,0.000000
80.610001,55.229164,-105.686737,0.007140,0.003783,0.096080,245.671585,12.515107,0.960799,-105.686737,0.096219,0.000000
80.840004,55.176659,-105.553299,0.007136,0.003783,0.096080,245.438034,12.503209,0.960799,-105.553299,0.096219,0.000000
81.070007,55.131233,-105.597778,0.007148,0.003783,0.096080,245.235977,12.492916,0.960799,-105.597778,0.096219,0.000000
81.300003,55.085060,-105.597778,0.007123,0.003783,0.096080,245.030579,12.482453,0.960799,-105.597778,0.096219,0.000000
81.530006,55.043724,-105.686737,0.007127,0.003783,0.096080,244.846710,12.473086,0.960799,-105.686737,0.096219,0.000000
81.760002,54.994942,-105.597778,0.007140,0.003783,0.096080,244.629715,12.462032,0.960799,-105.597778,0.096219,0.000000
81.990005,54.948021,-105.642258,0.007157,0.003783,0.096080,244.421005,12.451400,0.960799,-105.642258,0.096219,0.000000
82.220001,54.898125,-105.642258,0.007148,0.003783,0.096080,244.199051,12.440093,0.960799,-105.642258,0.096219,0.000000
82.450005,54.860146,-105.731224,0.007123,0.003783,0.096080,244.030121,12.431487,0.960799,-105.731224,0.096219,0.000000
82.680000,54.808754,-105.731224,0.007123,0.003783,0.096080,243.801514,12.419841,0.960799,-105.731224,0.096219,0.000000
82.910004,54.767052,-105.597778,0.007131,0.003783,0.096080,243.616013,12.410392,0.960799,-105.597778,0.096219,0.000000
83.140007,54.736519,-105.686737,0.007144,0.003783,0.096080,243.480194,12.403473,0.960799,-105.686737,0.096219,0.000000
83.370003,54.700768,-105.686737,0.007144,0.003783,0.096080,243.321167,12.395371,0.960799,-105.686737,0.096219,0.000000
83.600006,54.652359,-105.731224,0.007131,0.003783,0.096080,243.105835,12.384401,0.960799,-105.731224,0.096219,0.000000
83.830002,54.621452,-105.731224,0.007140,0.003783,0.096080,242.968353,12.377398,0.960799,-105.731224,0.096219,0.000000
84.060005,54.581978,-105.731224,0.007136,0.003783,0.096080,242.792770,12.368453,0.960799,-105.731224,0.096219,0.000000
84.290001,54.543999,-105.775703,0.007131,0.003783,0.096080,242.623825,12.359846,0.960799,-105.775703,0.096219,0.000000
84.520004,54.494476,-105.731224,0.007148,0.003783,0.096080,242.403534,12.348624,0.960799,-105.731224,0.096219,0.000000
84.750008,54.461334,-105.775703,0.007127,0.003783,0.096080,242.256119,12.341115,0.960799,-105.775703,0.096219,0.000000
84.980003,54.429306,-105.731224,0.007110,0.003783,0.096080,242.113647,12.333857,0.960799,-105.731224,0.096219,0.000000
85.210007,54.397285,-105.731224,0.007136,0.003783,0.096080,241.971207,12.326601,0.960799,-105.731224,0.096219,0.000000
85.440002,54.342545,-105.731224,0.007131,0.003783,0.096080,241.727707,12.314197,0.960799,-105.731224,0.096219,0.000000
85.670006,54.316109,-105.775703,0.007140,0.003783,0.096080,241.610123,12.308207,0.960799,-105.775703,0.096219,0.000000
85.900002,54.290039,-105.864662,0.007131,0.003783,0.096080,241.494156,12.302299,0.960799,-105.864662,0.096219,0.000000
86.130005,54.249451,-105.820183,0.007140,0.003783,0.096080,241.313614,12.293101,0.960799,-105.820183,0.096219,0.000000
86.360001,54.222641,-105.820183,0.007140,0.003783,0.096080,241.194351,12.287025,0.960799,-105.820183,0.096219,0.000000
86.590004,54.193970,-105.731224,0.007144,0.003783,0.096080,241.066818,12.280529,0.960799,-105.731224,0.096219,0.000000
86.820007,54.158966,-105.864662,0.007131,0.003783,0.096080,240.911118,12.272597,0.960799,-105.864662,0.096219,0.000000
87.050003,54.112793,-105.820183,0.007144,0.003783,0.096080,240.705719,12.262135,0.960799,-105.820183,0.096219,0.000000
87.280006,54.075554,-105.909142,0.007127,0.003783,0.096080,240.540070,12.253695,0.960799,-105.909142,0.096219,0.000000
87.510002,54.056564,-105.820183,0.007140,0.003783,0.096080,240.455612,12.249393,0.960799,-105.820183,0.096219,0.000000
87.740005,54.035339,-105.864662,0.007153,0.003783,0.096080,240.361191,12.244583,0.960799,-105.864662,0.096219,0.000000
87.970001,53.987679,-105.909142,0.007157,0.003783,0.096080,240.149185,12.233783,0.960799,-105.909142,0.096219,0.000000
88.200005,53.951180,-105.909142,0.007144,0.003783,0.096080,239.986832,12.225513,0.960799,-105.909142,0.096219,0.000000
88.430008,53.928093,-105.864662,0.007144,0.003783,0.096080,239.884140,12.220281,0.960799,-105.864662,0.096219,0.000000
88.660004,53.906868,-105.864662,0.007153,0.003783,0.096080,239.789719,12.215470,0.960799,-105.864662,0.096219,0.000000
88.890007,53.866653,-105.953629,0.007140,0.003783,0.096080,239.610840,12.206358,0.960799,-105.953629,0.096219,0.000000
89.120003,53.821594,-105.909142,0.007136,0.003783,0.096080,239.410416,12.196147,0.960799,-105.909142,0.096219,0.000000
89.350006,53.802605,-105.953629,0.007136,0.003783,0.096080,239.325943,12.191844,0.960799,-105.953629,0.096219,0.000000
89.580002,53.770210,-105.953629,0.007140,0.003783,0.096080,239.181839,12.184505,0.960799,-105.953629,0.096219,0.000000
89.810005,53.737816,-105.909142,0.007153,0.003783,0.096080,239.037750,12.177163,0.960799,-105.909142,0.096219,0.000000
90.040001,53.715843,-105.909142,0.007127,0.003783,0.096080,238.940002,12.172184,0.960799,-105.909142,0.096219,0.000000
90.270004,53.695366,-105.998108,0.007136,0.003783,0.096080,238.848923,12.167543,0.960799,-105.998108,0.096219,0.000000
90.500008,53.662964,-105.998108,0.007144,0.003783,0.096080,238.704788,12.160201,0.960799,-105.998108,0.096219,0.000000
90.730003,53.622749,-105.998108,0.007140,0.003783,0.096080,238.525909,12.151089,0.960799,-105.998108,0.096219,0.000000
90.960007,53.588867,-105.909142,0.007136,0.003783,0.096080,238.375183,12.143411,0.960799,-105.909142,0.096219,0.000000
91.190002,53.578064,-105.998108,0.007161,0.003783,0.096080,238.327133,12.140964,0.960799,-105.998108,0.096219,0.000000
91.420006,53.560188,-105.998108,0.007148,0.003783,0.096080,238.247620,12.136912,0.960799,-105.998108,0.096219,0.000000
91.650002,53.530777,-105.998108,0.007144,0.003783,0.096080,238.116791,12.130247,0.960799,-105.998108,0.096219,0.000000
91.880005,53.491676,-105.953629,0.007144,0.003783,0.096080,237.942856,12.121387,0.960799,-105.953629,0.096219,0.000000
92.110001,53.470078,-105.953629,0.007131,0.003783,0.096080,237.846786,12.116492,0.960799,-105.953629,0.096219,0.000000
92.340004,53.455185,-106.042587,0.007166,0.003783,0.096080,237.780533,12.113118,0.960799,-106.042587,0.096219,0.000000
92.570007,53.424644,-106.042587,0.007148,0.003783,0.096080,237.644684,12.106197,0.960799,-106.042587,0.096219,0.000000
92.800003,53.385178,-106.087067,0.007131,0.003783,0.096080,237.469131,12.097254,0.960799,-106.087067,0.096219,0.000000
93.030006,53.376610,-106.042587,0.007148,0.003783,0.096080,237.431015,12.095312,0.960799,-106.042587,0.096219,0.000000
93.260002,53.362465,-106.087067,0.007157,0.003783,0.096080,237.368103,12.092108,0.960799,-106.087067,0.096219,0.000000
93.490005,53.332298,-105.998108,0.007161,0.003783,0.096080,237.233917,12.085272,0.960799,-105.998108,0.096219,0.000000
93.720001,53.284637,-105.998108,0.007157,0.003783,0.096080,237.021912,12.074471,0.960799,-105.998108,0.096219,0.000000
93.950005,53.251495,-106.131546,0.007144,0.003783,0.096080,236.874481,12.066961,0.960799,-106.131546,0.096219,0.000000
94.180008,53.250748,-106.042587,0.007127,0.003783,0.096080,236.871155,12.066792,0.960799,-106.042587,0.096219,0.000000
94.410004,53.230644,-106.087067,0.007144,0.003783,0.096080,236.781738,12.062236,0.960799,-106.087067,0.096219,0.000000
94.640007,53.191544,-106.087067,0.007174,0.003783,0.096080,236.607803,12.053376,0.960799,-106.087067,0.096219,0.000000
94.870003,53.174042,-106.087067,0.007148,0.003783,0.096080,236.529953,12.049410,0.960799,-106.087067,0.096219,0.000000
95.100006,53.163612,-106.042587,0.007140,0.003783,0.096080,236.483551,12.047047,0.960799,-106.042587,0.096219,0.000000
95.330002,53.135689,-106.087067,0.007144,0.003783,0.096080,236.359344,12.040719,0.960799,-106.087067,0.096219,0.000000
95.400002,53.142014,-106.131546,0.007127,0.003783,0.096080,236.387482,12.042152,0.960799,-106.131546,0.096219,0.000000