File: Data/Automembrane/AutoNoheat12-1-3_12132023_181314.csv
Time (sec),S:Load (lbs),S:HL1 (DIM),S:LVDT (in),S:Position (in),Ch:Position (mm),Ch:Load (N),Ch:Stress (MPa),Ch:Strain (mm/mm),Ch:HL1 (DIM),Set Point (),Cycles ()
0.110000,-0.000748,-1302.090820,0.000022,-0.000000,-0.000000,-0.003326,-0.000169,-0.000000,-1302.090820,0.000269,0.000000
0.350000,0.003349,-1302.090820,0.000043,-0.000000,-0.000000,0.014898,0.000759,-0.000000,-1302.090820,0.000269,0.000000
0.590000,-0.038727,-1302.090820,0.000052,0.000103,0.002619,-0.172265,-0.008776,0.026191,-1302.090820,0.003495,0.000000
0.830000,-0.010056,-1302.090820,0.000073,0.000241,0.006114,-0.044729,-0.002279,0.061141,-1302.090820,0.007484,0.000000
1.070000,-0.013031,-1302.090820,0.000263,0.000406,0.010312,-0.057965,-0.002953,0.103116,-1302.090820,0.011491,0.000000
1.310000,-0.054367,-1302.046387,0.000410,0.000560,0.014231,-0.241837,-0.012320,0.142312,-1302.046387,0.015480,0.000000
1.550000,-0.027557,-1302.135376,0.000556,0.000722,0.018351,-0.122581,-0.006245,0.183507,-1302.135376,0.019487,0.000000
1.790000,-0.017876,-1302.135376,0.000789,0.000879,0.022323,-0.079515,-0.004051,0.223226,-1302.135376,0.023476,0.000000
2.030000,-0.040962,-1302.090820,0.000918,0.001035,0.026286,-0.182209,-0.009282,0.262857,-1302.090820,0.027483,0.000000
2.270000,-0.046547,-1302.179810,0.001078,0.001192,0.030266,-0.207051,-0.010548,0.302663,-1302.179810,0.031472,0.000000
2.510000,-0.032021,-1302.135376,0.001298,0.001351,0.034325,-0.142435,-0.007256,0.343248,-1302.135376,0.035478,0.000000
2.750000,0.001862,-1302.090820,0.001423,0.001508,0.038297,0.008281,0.000422,0.382967,-1302.090820,0.039467,0.000000
2.990000,-0.006332,-1302.090820,0.001561,0.001664,0.042277,-0.028168,-0.001435,0.422773,-1302.090820,0.043474,0.000000
3.230000,-0.038353,-1302.090820,0.001738,0.001820,0.046232,-0.170603,-0.008691,0.462317,-1302.090820,0.047463,0.000000
3.470000,-0.044685,-1302.179810,0.001863,0.001973,0.050126,-0.198770,-0.010126,0.501256,-1302.179810,0.051470,0.000000
3.710000,-0.018616,-1302.090820,0.002134,0.002141,0.054375,-0.082807,-0.004218,0.543753,-1302.090820,0.055459,0.000000
3.950000,-0.035004,-1302.179810,0.002251,0.002297,0.058347,-0.155704,-0.007932,0.583472,-1302.179810,0.059466,0.000000
4.190000,-0.016388,-1302.135376,0.002440,0.002453,0.062302,-0.072897,-0.003714,0.623016,-1302.135376,0.063472,0.000000
4.430000,-0.030159,-1302.179810,0.002539,0.002610,0.066282,-0.134154,-0.006834,0.662822,-1302.179810,0.067462,0.000000
4.670000,-0.016388,-1302.135376,0.002759,0.002769,0.070323,-0.072897,-0.003714,0.703233,-1302.135376,0.071468,0.000000
4.910000,0.003723,-1302.179810,0.002889,0.002921,0.074191,0.016561,0.000844,0.741911,-1302.179810,0.075458,0.000000
5.150000,0.001114,-1302.179810,0.003048,0.003084,0.078328,0.004955,0.000252,0.783280,-1302.179810,0.079464,0.000000
5.390000,-0.021973,-1302.135376,0.003234,0.003237,0.082213,-0.097739,-0.004979,0.822132,-1302.135376,0.083453,0.000000
5.630000,-0.017502,-1302.135376,0.003397,0.003392,0.086159,-0.077852,-0.003966,0.861590,-1302.135376,0.087460,0.000000
5.870000,-0.020111,-1302.224365,0.003596,0.003554,0.090270,-0.089459,-0.004557,0.902697,-1302.224365,0.091449,0.000000
6.110000,-0.014893,-1302.179810,0.003717,0.003710,0.094224,-0.066245,-0.003375,0.942242,-1302.179810,0.095456,0.000000
6.350000,-0.050270,-1302.179810,0.003867,0.003870,0.098300,-0.223612,-0.011391,0.983002,-1302.179810,0.099445,0.000000
6.590000,0.007820,-1302.224365,0.004061,0.004030,0.102367,0.034786,0.001772,1.023674,-1302.224365,0.103451,0.000000
6.830000,0.041336,-1302.090820,0.004230,0.004182,0.106226,0.183872,0.009367,1.062265,-1302.090820,0.107441,0.000000
7.070000,0.062187,-1302.179810,0.004389,0.004344,0.110346,0.276622,0.014092,1.103460,-1302.179810,0.111447,0.000000
7.310000,0.096069,-1302.179810,0.004544,0.004503,0.114378,0.427338,0.021770,1.143784,-1302.179810,0.115437,0.000000
7.550000,0.198845,-1302.224365,0.004747,0.004650,0.118116,0.884506,0.045059,1.181164,-1302.224365,0.119443,0.000000
7.790000,0.455414,-1302.135376,0.004919,0.004812,0.122227,2.025782,0.103198,1.222268,-1302.135376,0.123432,0.000000
8.030001,0.636009,-1302.224365,0.004980,-0.000003,-0.000087,2.829110,0.144122,-0.000867,-1302.224365,0.000165,0.000000
8.270000,0.562279,-1302.268799,0.005014,-0.000003,-0.000087,2.501141,0.127414,-0.000867,-1302.268799,0.000165,0.000000
8.510000,0.539192,-1302.135376,0.005036,-0.000003,-0.000087,2.398447,0.122183,-0.000867,-1302.135376,0.000165,0.000000
8.750000,0.548508,-1302.224365,0.004980,-0.000003,-0.000087,2.439884,0.124294,-0.000867,-1302.224365,0.000529,0.000000
8.990001,0.524673,-1302.135376,0.005027,-0.000003,-0.000087,2.333864,0.118893,-0.000867,-1302.135376,0.000928,0.000000
9.230000,0.520203,-1302.135376,0.005036,-0.000003,-0.000078,2.313977,0.117880,-0.000780,-1302.135376,0.001336,0.000000
9.470000,0.674736,-1302.268799,0.005036,0.000031,0.000780,3.001376,0.152897,0.007804,-1302.268799,0.001735,0.000000
9.710000,0.733948,-1302.179810,0.005027,0.000051,0.001301,3.264763,0.166315,0.013009,-1302.179810,0.002134,0.000000
9.950001,0.734322,-1302.224365,0.005079,0.000066,0.001665,3.266426,0.166400,0.016650,-1302.224365,0.002532,0.000000
10.190001,0.766716,-1302.135376,0.005092,0.000080,0.002021,3.410523,0.173740,0.020208,-1302.135376,0.002931,0.000000
10.430000,0.858688,-1302.224365,0.005066,0.000099,0.002515,3.819637,0.194582,0.025151,-1302.224365,0.003330,0.000000
10.670000,0.905235,-1302.224365,0.005126,0.000112,0.002853,4.026688,0.205129,0.028531,-1302.224365,0.003729,0.000000
10.910001,0.935402,-1302.135376,0.005148,0.000126,0.003200,4.160875,0.211965,0.032001,-1302.135376,0.004137,0.000000
11.150001,0.989395,-1302.313232,0.005152,0.000141,0.003573,4.401050,0.224200,0.035729,-1302.313232,0.004535,0.000000
11.390000,1.024025,-1302.268799,0.005148,0.000159,0.004032,4.555090,0.232047,0.040324,-1302.268799,0.004934,0.000000
11.630000,1.022903,-1302.224365,0.005148,0.000160,0.004067,4.550102,0.231793,0.040672,-1302.224365,0.005333,0.000000
11.870001,1.129036,-1302.224365,0.005238,0.000185,0.004692,5.022203,0.255843,0.046918,-1302.224365,0.005732,0.000000
12.110001,1.192337,-1302.224365,0.005238,0.000204,0.005186,5.303780,0.270187,0.051861,-1302.224365,0.006131,0.000000
12.350000,1.223991,-1302.224365,0.005178,0.000219,0.005550,5.444586,0.277360,0.055502,-1302.224365,0.006530,0.000000
12.590000,1.311867,-1302.179810,0.005286,0.000233,0.005906,5.835475,0.297273,0.059060,-1302.179810,0.006929,0.000000
12.830001,1.356178,-1302.224365,0.005234,0.000243,0.006175,6.032582,0.307314,0.061747,-1302.224365,0.007337,0.000000
13.070001,1.298088,-1302.224365,0.005282,0.000243,0.006183,5.774184,0.294151,0.061834,-1302.224365,0.007736,0.000000
13.310000,1.565826,-1302.224365,0.005243,0.000281,0.007128,6.965144,0.354821,0.071285,-1302.224365,0.008134,0.000000
13.550000,1.639557,-1302.268799,0.005290,0.000299,0.007597,7.293113,0.371529,0.075970,-1302.268799,0.008533,0.000000
13.790001,1.635834,-1302.224365,0.005342,0.000309,0.007840,7.276552,0.370685,0.078397,-1302.224365,0.008932,0.000000
14.030001,1.769142,-1302.179810,0.005307,0.000332,0.008429,7.869537,0.400893,0.084293,-1302.179810,0.009331,0.000000
14.270000,1.795578,-1302.268799,0.005355,0.000343,0.008715,7.987130,0.406884,0.087155,-1302.268799,0.009730,0.000000
14.510000,1.850319,-1302.224365,0.005355,0.000353,0.008976,8.230630,0.419288,0.089759,-1302.224365,0.010129,0.000000
14.750001,1.898727,-1302.268799,0.005389,0.000365,0.009262,8.445961,0.430258,0.092620,-1302.268799,0.010537,0.000000
14.990001,2.195511,-1302.224365,0.005394,0.000391,0.009930,9.766120,0.497510,0.099297,-1302.224365,0.010936,0.000000
15.230000,2.229019,-1302.224365,0.005372,0.000405,0.010294,9.915173,0.505103,0.102942,-1302.224365,0.011335,0.000000
15.470000,2.375366,-1302.313232,0.005420,0.000426,0.010814,10.566156,0.538266,0.108142,-1302.313232,0.011734,0.000000
15.710001,2.442017,-1302.313232,0.005411,0.000439,0.011161,10.862633,0.553369,0.111613,-1302.313232,0.012132,0.000000
15.950001,2.539581,-1302.268799,0.005381,0.000456,0.011595,11.296622,0.575477,0.115946,-1302.268799,0.012531,0.000000
16.190001,2.557823,-1302.224365,0.005445,0.000471,0.011959,11.377766,0.579611,0.119591,-1302.224365,0.012930,0.000000
16.430000,2.781624,-1302.313232,0.005450,0.000492,0.012505,12.373281,0.630325,0.125053,-1302.313232,0.013329,0.000000
16.670000,2.824074,-1302.268799,0.005454,0.000505,0.012818,12.562108,0.639944,0.128175,-1302.268799,0.013737,0.000000
16.910002,2.869499,-1302.224365,0.005476,0.000518,0.013147,12.764170,0.650238,0.131472,-1302.224365,0.014136,0.000000
17.150002,2.984940,-1302.313232,0.005476,0.000532,0.013511,13.277675,0.676397,0.135113,-1302.313232,0.014535,0.000000
17.390001,3.151390,-1302.313232,0.005527,0.000552,0.014014,14.018084,0.714115,0.140143,-1302.313232,0.014934,0.000000
17.630001,3.270920,-1302.179810,0.005553,0.000567,0.014413,14.549778,0.741201,0.144133,-1302.179810,0.015333,0.000000
17.870001,3.318954,-1302.313232,0.005588,0.000584,0.014830,14.763447,0.752086,0.148296,-1302.313232,0.015732,0.000000
18.110001,3.387848,-1302.224365,0.005588,0.000597,0.015168,15.069901,0.767697,0.151680,-1302.224365,0.016130,0.000000
18.350000,3.584457,-1302.313232,0.005639,0.000617,0.015662,15.944463,0.812250,0.156623,-1302.313232,0.016529,0.000000
18.590000,3.637703,-1302.268799,0.005605,0.000631,0.016018,16.181311,0.824315,0.160177,-1302.268799,0.016937,0.000000
18.830002,3.750908,-1302.313232,0.005609,0.000643,0.016330,16.684872,0.849968,0.163299,-1302.313232,0.017336,0.000000
19.070002,3.899109,-1302.313232,0.005665,0.000661,0.016781,17.344103,0.883551,0.167807,-1302.313232,0.017735,0.000000
19.310001,4.053276,-1302.224365,0.005627,0.000679,0.017249,18.029873,0.918485,0.172493,-1302.224365,0.018134,0.000000
19.550001,4.134079,-1302.313232,0.005696,0.000698,0.017717,18.389301,0.936796,0.177175,-1302.313232,0.018533,0.000000
19.790001,4.145248,-1302.357788,0.005665,0.000710,0.018038,18.438986,0.939327,0.180384,-1302.357788,0.018932,0.000000
20.030001,4.284142,-1302.313232,0.005739,0.000725,0.018411,19.056814,0.970800,0.184112,-1302.313232,0.019331,0.000000
20.270000,4.503471,-1302.357788,0.005721,0.000745,0.018932,20.032442,1.020501,0.189317,-1302.357788,0.019730,0.000000
20.510000,4.534004,-1302.268799,0.005773,0.000759,0.019278,20.168259,1.027420,0.192784,-1302.268799,0.020137,0.000000
20.750002,4.575340,-1302.357788,0.005756,0.000769,0.019539,20.352131,1.036787,0.195388,-1302.357788,0.020536,0.000000
20.990002,4.854988,-1302.313232,0.005760,0.000790,0.020068,21.596066,1.100156,0.200675,-1302.313232,0.020935,0.000000
21.230001,4.906754,-1302.313232,0.005764,0.000806,0.020475,21.826330,1.111886,0.204751,-1302.313232,0.021334,0.000000
21.470001,4.966331,-1302.357788,0.005821,0.000821,0.020865,22.091345,1.125387,0.208654,-1302.357788,0.021732,0.000000
21.710001,5.113792,-1302.313232,0.005786,0.000839,0.021299,22.747284,1.158802,0.212991,-1302.313232,0.022131,0.000000
21.950001,5.134644,-1302.313232,0.005790,0.000852,0.021646,22.840034,1.163527,0.216458,-1302.313232,0.022530,0.000000
22.190001,5.323067,-1302.313232,0.005816,0.000870,0.022106,23.678183,1.206224,0.221057,-1302.313232,0.022929,0.000000
22.430000,5.339447,-1302.268799,0.005799,0.000882,0.022392,23.751047,1.209936,0.223918,-1302.268799,0.023337,0.000000
22.670002,5.383385,-1302.446777,0.005851,0.000892,0.022652,23.946491,1.219893,0.226518,-1302.446777,0.023736,0.000000
22.910002,5.504784,-1302.268799,0.005846,0.000907,0.023033,24.486500,1.247402,0.230334,-1302.268799,0.024135,0.000000
23.150002,5.849968,-1302.357788,0.005872,0.000930,0.023615,26.021957,1.325622,0.236147,-1302.357788,0.024534,0.000000
23.390001,5.990356,-1302.268799,0.005915,0.000948,0.024083,26.646437,1.357434,0.240829,-1302.268799,0.024933,0.000000
23.630001,6.042488,-1302.357788,0.005881,0.000966,0.024525,26.878330,1.369247,0.245250,-1302.357788,0.025332,0.000000
23.870001,6.034668,-1302.268799,0.005920,0.000978,0.024846,26.843544,1.367475,0.248459,-1302.268799,0.025730,0.000000
24.110001,6.177658,-1302.268799,0.005971,0.000994,0.025254,27.479595,1.399877,0.252536,-1302.268799,0.026138,0.000000
24.350000,6.310593,-1302.268799,0.005950,0.001010,0.025661,28.070917,1.430001,0.256612,-1302.268799,0.026537,0.000000
24.590002,6.232025,-1302.268799,0.005933,0.001019,0.025878,27.721432,1.412197,0.258781,-1302.268799,0.026936,0.000000
24.830002,6.382088,-1302.313232,0.005954,0.001035,0.026286,28.388945,1.446202,0.262857,-1302.313232,0.027335,0.000000
25.070002,6.611847,-1302.313232,0.005993,0.001055,0.026797,29.410963,1.498266,0.267974,-1302.313232,0.027734,0.000000
25.310001,6.510185,-1302.224365,0.006006,0.001066,0.027084,28.958750,1.475229,0.270836,-1302.224365,0.028133,0.000000
25.550001,6.700470,-1302.357788,0.006040,0.001085,0.027552,29.805180,1.518348,0.275518,-1302.357788,0.028532,0.000000
25.790001,6.669937,-1302.313232,0.006053,0.001094,0.027786,29.669363,1.511429,0.277860,-1302.313232,0.028931,0.000000
26.030001,6.976768,-1302.313232,0.006002,0.001114,0.028306,31.034216,1.580958,0.283061,-1302.313232,0.029338,0.000000
26.270000,6.984962,-1302.313232,0.006079,0.001128,0.028662,31.070665,1.582815,0.286619,-1302.313232,0.029737,0.000000
26.510002,7.117523,-1302.357788,0.006066,0.001145,0.029087,31.660324,1.612854,0.290869,-1302.357788,0.030136,0.000000
26.750002,7.235565,-1302.268799,0.006092,0.001161,0.029494,32.185402,1.639603,0.294942,-1302.268799,0.030535,0.000000
26.990002,7.301849,-1302.268799,0.006114,0.001176,0.029876,32.480247,1.654623,0.298761,-1302.268799,0.030934,0.000000
27.230001,7.370369,-1302.268799,0.006053,0.001194,0.030318,32.785038,1.670150,0.303181,-1302.268799,0.031333,0.000000
27.470001,7.432930,-1302.357788,0.006165,0.001208,0.030683,33.063324,1.684326,0.306826,-1302.357788,0.031732,0.000000
27.710001,7.547989,-1302.313232,0.006127,0.001227,0.031168,33.575130,1.710399,0.311682,-1302.313232,0.032131,0.000000
27.950001,7.425476,-1302.313232,0.006140,0.001233,0.031315,33.030167,1.682637,0.313155,-1302.313232,0.032538,0.000000
28.190001,7.419151,-1302.357788,0.006204,0.001243,0.031576,33.002033,1.681204,0.315759,-1302.357788,0.032937,0.000000
28.430002,7.813118,-1302.313232,0.006165,0.001268,0.032217,34.754486,1.770478,0.322174,-1302.313232,0.033336,0.000000
28.670002,7.882378,-1302.313232,0.006178,0.001286,0.032669,35.062569,1.786172,0.326686,-1302.313232,0.033735,0.000000
28.910002,7.957596,-1302.357788,0.006209,0.001305,0.033145,35.397156,1.803217,0.331455,-1302.357788,0.034134,0.000000
29.150002,7.884613,-1302.357788,0.006209,0.001317,0.033440,35.072510,1.786679,0.334403,-1302.357788,0.034533,0.000000
29.390001,8.039520,-1302.313232,0.006196,0.001336,0.033943,35.761574,1.821781,0.339433,-1302.313232,0.034932,0.000000
29.630001,7.978821,-1302.313232,0.006269,0.001349,0.034273,35.491566,1.808027,0.342726,-1302.313232,0.035331,0.000000
29.870001,8.323639,-1302.357788,0.006252,0.001370,0.034802,37.025394,1.886164,0.348017,-1302.357788,0.035738,0.000000
30.110001,8.226822,-1302.357788,0.006278,0.001383,0.035140,36.594730,1.864224,0.351401,-1302.357788,0.036137,0.000000
30.350002,8.313217,-1302.402222,0.006273,0.001402,0.035608,36.979038,1.883802,0.356083,-1302.402222,0.036536,0.000000
30.590002,8.275230,-1302.357788,0.006260,0.001416,0.035964,36.810062,1.875194,0.359637,-1302.357788,0.036935,0.000000
30.830002,8.448761,-1302.357788,0.006256,0.001435,0.036458,37.581966,1.914517,0.364580,-1302.357788,0.037334,0.000000
31.070002,8.487854,-1302.402222,0.006312,0.001452,0.036883,37.755859,1.923375,0.368830,-1302.402222,0.037733,0.000000
31.310001,8.407799,-1302.313232,0.006308,0.001465,0.037213,37.399757,1.905234,0.372127,-1302.313232,0.038132,0.000000
31.550001,8.410034,-1302.357788,0.006291,0.001478,0.037551,37.409702,1.905741,0.375507,-1302.357788,0.038531,0.000000
31.790001,8.677399,-1302.357788,0.006308,0.001499,0.038071,38.598995,1.966327,0.380711,-1302.357788,0.038939,0.000000
32.030003,8.614090,-1302.402222,0.006329,0.001511,0.038375,38.317387,1.951981,0.383747,-1302.402222,0.039337,0.000000
32.270000,8.652077,-1302.402222,0.006334,0.001528,0.038800,38.486359,1.960589,0.387997,-1302.402222,0.039736,0.000000
32.510002,8.757454,-1302.402222,0.006347,0.001545,0.039242,38.955101,1.984468,0.392418,-1302.402222,0.040135,0.000000
32.750000,8.817780,-1302.402222,0.006377,0.001558,0.039580,39.223442,1.998137,0.395802,-1302.402222,0.040534,0.000000
32.990002,8.843849,-1302.357788,0.006416,0.001574,0.039979,39.339405,2.004045,0.399791,-1302.357788,0.040933,0.000000
33.230003,8.918694,-1302.402222,0.006377,0.001587,0.040300,39.672329,2.021005,0.403000,-1302.402222,0.041332,0.000000
33.470001,8.912361,-1302.446777,0.006381,0.001603,0.040725,39.644161,2.019570,0.407251,-1302.446777,0.041731,0.000000
33.710003,8.919434,-1302.357788,0.006433,0.001621,0.041167,39.675621,2.021173,0.411672,-1302.357788,0.042138,0.000000
33.950001,8.874382,-1302.402222,0.006463,0.001631,0.041427,39.475224,2.010964,0.414272,-1302.402222,0.042537,0.000000
34.190002,8.846077,-1302.357788,0.006472,0.001650,0.041904,39.349316,2.004550,0.419045,-1302.357788,0.042936,0.000000
34.430000,9.206161,-1302.402222,0.006433,0.001665,0.042286,40.951050,2.086146,0.422860,-1302.402222,0.043335,0.000000
34.670002,9.293671,-1302.402222,0.006476,0.001684,0.042780,41.340313,2.105976,0.427803,-1302.402222,0.043734,0.000000
34.910000,9.428467,-1302.357788,0.006502,0.001702,0.043222,41.939915,2.136521,0.432224,-1302.357788,0.044133,0.000000
35.150002,9.087753,-1302.402222,0.006467,0.001713,0.043517,40.424347,2.059314,0.435172,-1302.402222,0.044532,0.000000
35.390003,9.461609,-1302.446777,0.006515,0.001733,0.044029,42.087337,2.144031,0.440289,-1302.446777,0.044931,0.000000
35.630001,9.232605,-1302.402222,0.006480,0.001742,0.044237,41.068680,2.092138,0.442371,-1302.402222,0.045339,0.000000
35.870003,9.450813,-1302.446777,0.006541,0.001761,0.044723,42.039318,2.141585,0.447227,-1302.446777,0.045737,0.000000
36.110001,9.140251,-1302.357788,0.006554,0.001763,0.044784,40.657867,2.071211,0.447836,-1302.357788,0.046136,0.000000
36.350002,9.711472,-1302.491211,0.006549,0.001792,0.045512,43.198784,2.200651,0.455118,-1302.491211,0.046535,0.000000
36.590000,9.588966,-1302.357788,0.006562,0.001804,0.045824,42.653854,2.172891,0.458241,-1302.357788,0.046934,0.000000
36.830002,9.819832,-1302.446777,0.006575,0.001827,0.046414,43.680794,2.225206,0.464138,-1302.446777,0.047333,0.000000
37.070004,9.743500,-1302.446777,0.006588,0.001842,0.046787,43.341251,2.207909,0.467870,-1302.446777,0.047732,0.000000
37.310001,9.784088,-1302.313232,0.006549,0.001857,0.047177,43.521797,2.217106,0.471772,-1302.313232,0.048131,0.000000
37.550003,9.783340,-1302.491211,0.006644,0.001872,0.047550,43.518471,2.216937,0.475500,-1302.491211,0.048539,0.000000
37.790001,10.082726,-1302.402222,0.006622,0.001894,0.048096,44.850204,2.284778,0.480962,-1302.402222,0.048938,0.000000
38.030003,9.867500,-1302.446777,0.006657,0.001906,0.048400,43.892834,2.236007,0.483997,-1302.446777,0.049336,0.000000
38.270000,9.891327,-1302.446777,0.006614,0.001918,0.048729,43.998821,2.241407,0.487294,-1302.446777,0.049735,0.000000
38.510002,10.192581,-1302.357788,0.006661,0.001938,0.049232,45.338867,2.309672,0.492324,-1302.357788,0.050134,0.000000
38.750000,9.898773,-1302.491211,0.006644,0.001944,0.049380,44.031940,2.243094,0.493800,-1302.491211,0.050533,0.000000
38.990002,10.201515,-1302.402222,0.006679,0.001968,0.049995,45.378605,2.311696,0.499954,-1302.402222,0.050932,0.000000
39.230003,10.235405,-1302.446777,0.006674,0.001986,0.050438,45.529354,2.319376,0.504379,-1302.446777,0.051340,0.000000
39.470001,10.186623,-1302.446777,0.006687,0.001999,0.050785,45.312359,2.308322,0.507846,-1302.446777,0.051739,0.000000
39.710003,10.410042,-1302.402222,0.006704,0.002019,0.051279,46.306179,2.358949,0.512789,-1302.402222,0.052138,0.000000
39.950001,10.429405,-1302.535645,0.006726,0.002033,0.051643,46.392311,2.363337,0.516434,-1302.535645,0.052537,0.000000
40.190002,10.273010,-1302.446777,0.006748,0.002044,0.051921,45.696632,2.327898,0.519208,-1302.446777,0.052936,0.000000
40.430000,10.574631,-1302.446777,0.006713,0.002063,0.052406,47.038307,2.396246,0.524064,-1302.446777,0.053334,0.000000
40.670002,10.750023,-1302.446777,0.006722,0.002082,0.052875,47.818489,2.435990,0.528746,-1302.446777,0.053733,0.000000
40.910004,10.638680,-1302.402222,0.006752,0.002098,0.053300,47.323212,2.410759,0.532996,-1302.402222,0.054132,0.000000
41.150002,10.541862,-1302.491211,0.006804,0.002111,0.053612,46.892548,2.388820,0.536119,-1302.491211,0.054540,0.000000
41.390003,10.514679,-1302.446777,0.006739,0.002124,0.053950,46.771629,2.382660,0.539503,-1302.446777,0.054939,0.000000
41.630001,10.844604,-1302.491211,0.006748,0.002144,0.054453,48.239208,2.457422,0.544533,-1302.491211,0.055338,0.000000
41.870003,10.902321,-1302.446777,0.006782,0.002160,0.054869,48.495945,2.470501,0.548692,-1302.446777,0.055737,0.000000
42.110001,10.606659,-1302.491211,0.006825,0.002170,0.055130,47.180775,2.403503,0.551296,-1302.491211,0.056136,0.000000
42.350002,11.050522,-1302.535645,0.006804,0.002191,0.055650,49.155178,2.504084,0.556497,-1302.535645,0.056535,0.000000
42.590000,11.139153,-1302.491211,0.006864,0.002209,0.056101,49.549423,2.524168,0.561009,-1302.491211,0.056934,0.000000
42.830002,11.044197,-1302.491211,0.006825,0.002224,0.056491,49.127041,2.502651,0.564911,-1302.491211,0.057332,0.000000
43.070004,11.092606,-1302.446777,0.006885,0.002240,0.056907,49.342373,2.513620,0.569074,-1302.446777,0.057740,0.000000
43.310001,10.991692,-1302.491211,0.006855,0.002252,0.057202,48.893486,2.490753,0.572023,-1302.491211,0.058139,0.000000
43.550003,11.185326,-1302.535645,0.006864,0.002270,0.057670,49.754814,2.534631,0.576704,-1302.535645,0.058538,0.000000
43.790001,11.183464,-1302.491211,0.006864,0.002284,0.058018,49.746532,2.534209,0.580175,-1302.491211,0.058936,0.000000
44.030003,11.048294,-1302.491211,0.006885,0.002294,0.058269,49.145267,2.503579,0.582688,-1302.491211,0.059335,0.000000
44.270000,11.451569,-1302.446777,0.006920,0.002316,0.058815,50.939121,2.594963,0.588154,-1302.446777,0.059734,0.000000
44.510002,11.435928,-1302.535645,0.006890,0.002328,0.059136,50.869549,2.591418,0.591360,-1302.535645,0.060133,0.000000
44.750004,11.706642,-1302.535645,0.006894,0.002349,0.059656,52.073746,2.652763,0.596564,-1302.535645,0.060532,0.000000
44.990002,11.713722,-1302.446777,0.006976,0.002365,0.060081,52.105240,2.654367,0.600814,-1302.446777,0.060940,0.000000
45.230003,11.512268,-1302.491211,0.006916,0.002378,0.060402,51.209126,2.608717,0.604024,-1302.491211,0.061339,0.000000
45.470001,11.698082,-1302.535645,0.006942,0.002396,0.060853,52.035667,2.650823,0.608532,-1302.535645,0.061738,0.000000
45.710003,11.800110,-1302.491211,0.006972,0.002411,0.061243,52.489510,2.673943,0.612434,-1302.491211,0.062137,0.000000
45.950001,11.690262,-1302.535645,0.007011,0.002423,0.061547,52.000881,2.649051,0.615469,-1302.535645,0.062536,0.000000
46.190002,12.152000,-1302.491211,0.006976,0.002443,0.062059,54.054798,2.753683,0.620587,-1302.491211,0.062934,0.000000
46.430000,12.075668,-1302.580200,0.006976,0.002458,0.062431,53.715256,2.736386,0.624315,-1302.580200,0.063333,0.000000
46.670002,11.975494,-1302.624634,0.007028,0.002470,0.062735,53.269661,2.713686,0.627350,-1302.624634,0.063732,0.000000
46.910004,12.280472,-1302.446777,0.007011,0.002488,0.063204,54.626266,2.782795,0.632036,-1302.446777,0.064140,0.000000
47.150002,11.984436,-1302.535645,0.007006,0.002498,0.063437,53.309433,2.715712,0.634375,-1302.535645,0.064539,0.000000
47.390003,12.383621,-1302.491211,0.007062,0.002518,0.063949,55.085098,2.806169,0.639492,-1302.491211,0.064938,0.000000
47.630001,12.218658,-1302.580200,0.007097,0.002530,0.064253,54.351307,2.768788,0.642528,-1302.580200,0.065337,0.000000
47.870003,12.405586,-1302.535645,0.007075,0.002546,0.064660,55.182804,2.811146,0.646604,-1302.535645,0.065736,0.000000
48.110001,12.543739,-1302.580200,0.007062,0.002563,0.065094,55.797340,2.842452,0.650941,-1302.580200,0.066135,0.000000
48.350002,12.535545,-1302.580200,0.007105,0.002575,0.065406,55.760891,2.840595,0.654060,-1302.580200,0.066534,0.000000
48.590004,12.928024,-1302.535645,0.007092,0.002597,0.065970,57.506725,2.929532,0.659700,-1302.535645,0.066932,0.000000
48.830002,12.744446,-1302.580200,0.007101,0.002609,0.066256,56.690125,2.887933,0.662561,-1302.580200,0.067340,0.000000
49.070004,13.037132,-1302.491211,0.007144,0.002627,0.066716,57.992062,2.954256,0.667156,-1302.491211,0.067739,0.000000
49.310001,12.971970,-1302.535645,0.007127,0.002640,0.067063,57.702202,2.939490,0.670627,-1302.535645,0.068138,0.000000
49.550003,13.176399,-1302.669189,0.007110,0.002655,0.067427,58.611549,2.985815,0.674268,-1302.669189,0.068537,0.000000
49.790001,13.356255,-1302.491211,0.007105,0.002673,0.067904,59.411587,3.026571,0.679037,-1302.491211,0.068936,0.000000
50.030003,13.539459,-1302.669189,0.007205,0.002689,0.068311,60.226524,3.068085,0.683113,-1302.669189,0.069335,0.000000
50.270004,13.546165,-1302.580200,0.007166,0.002703,0.068667,60.256355,3.069605,0.686671,-1302.580200,0.069734,0.000000
50.510002,13.733467,-1302.624634,0.007170,0.002722,0.069127,61.089512,3.112048,0.691266,-1302.624634,0.070133,0.000000
50.750004,13.942741,-1302.624634,0.007200,0.002738,0.069534,62.020412,3.159470,0.695342,-1302.624634,0.070540,0.000000
50.990002,14.030624,-1302.580200,0.007222,0.002753,0.069916,62.411335,3.179385,0.699157,-1302.580200,0.070939,0.000000
51.230003,14.299477,-1302.669189,0.007187,0.002772,0.070410,63.607250,3.240308,0.704100,-1302.669189,0.071338,0.000000
51.470001,14.410072,-1302.580200,0.007286,0.002789,0.070852,64.099205,3.265369,0.708525,-1302.580200,0.071737,0.000000
51.710003,14.459595,-1302.580200,0.007222,0.002801,0.071139,64.319489,3.276591,0.711386,-1302.580200,0.072136,0.000000
51.950001,14.589554,-1302.624634,0.007265,0.002816,0.071538,64.897575,3.306040,0.715375,-1302.624634,0.072535,0.000000
52.190002,15.150719,-1302.580200,0.007274,0.002838,0.072092,67.393761,3.433202,0.720924,-1302.580200,0.072934,0.000000
52.430004,15.164497,-1302.669189,0.007256,0.002852,0.072431,67.455055,3.436324,0.724308,-1302.669189,0.073341,0.000000
52.670002,15.250885,-1302.535645,0.007304,0.002867,0.072812,67.839325,3.455900,0.728123,-1302.535645,0.073740,0.000000
52.910004,15.262054,-1302.580200,0.007330,0.002880,0.073159,67.889008,3.458431,0.731590,-1302.580200,0.074139,0.000000
53.150002,15.982971,-1302.624634,0.007351,0.002901,0.073688,71.095810,3.621793,0.736881,-1302.624634,0.074538,0.000000
53.390003,15.876099,-1302.580200,0.007338,0.002914,0.074009,70.620415,3.597575,0.740091,-1302.580200,0.074937,0.000000
53.630001,16.225754,-1302.580200,0.007347,0.002929,0.074399,72.175758,3.676808,0.743993,-1302.580200,0.075336,0.000000
53.870003,16.598129,-1302.669189,0.007355,0.002946,0.074833,73.832169,3.761190,0.748331,-1302.669189,0.075735,0.000000
54.110004,16.562012,-1302.580200,0.007338,0.002955,0.075067,73.671509,3.753006,0.750670,-1302.580200,0.076134,0.000000
54.350002,17.081841,-1302.624634,0.007381,0.002974,0.075536,75.983818,3.870800,0.755355,-1302.624634,0.076541,0.000000
54.590004,17.122429,-1302.535645,0.007381,0.002985,0.075830,76.164368,3.879998,0.758304,-1302.535645,0.076940,0.000000
54.830002,17.572258,-1302.624634,0.007437,0.003006,0.076359,78.165306,3.981930,0.763591,-1302.624634,0.077339,0.000000
55.070004,17.997131,-1302.580200,0.007394,0.003023,0.076793,80.055237,4.078208,0.767929,-1302.580200,0.077738,0.000000
55.310001,17.848930,-1302.580200,0.007411,0.003029,0.076949,79.396011,4.044626,0.769488,-1302.580200,0.078137,0.000000
55.550003,18.658836,-1302.624634,0.007459,0.003053,0.077547,82.998650,4.228153,0.775472,-1302.624634,0.078536,0.000000
55.790001,18.928810,-1302.580200,0.007468,0.003066,0.077877,84.199554,4.289330,0.778769,-1302.580200,0.078935,0.000000
56.030003,19.498169,-1302.624634,0.007485,0.003083,0.078319,86.732185,4.418348,0.783193,-1302.624634,0.079334,0.000000
56.270004,19.998634,-1302.624634,0.007450,0.003103,0.078805,88.958366,4.531755,0.788049,-1302.624634,0.079741,0.000000
56.510002,20.121887,-1302.624634,0.007480,0.003117,0.079178,89.506622,4.559685,0.791777,-1302.624634,0.080140,0.000000
56.750004,20.490913,-1302.624634,0.007532,0.003132,0.079559,91.148132,4.643308,0.795592,-1302.624634,0.080539,0.000000
56.990002,20.584747,-1302.580200,0.007515,0.003146,0.079915,91.565529,4.664570,0.799150,-1302.580200,0.080938,0.000000
57.230003,21.030479,-1302.669189,0.007502,0.003159,0.080244,93.548248,4.765574,0.802443,-1302.669189,0.081337,0.000000
57.470001,21.727188,-1302.624634,0.007545,0.003177,0.080704,96.647362,4.923451,0.807042,-1302.624634,0.081736,0.000000
57.710003,22.137917,-1302.624634,0.007580,0.003193,0.081103,98.474373,5.016524,0.811031,-1302.624634,0.082135,0.000000
57.950005,22.511406,-1302.669189,0.007588,0.003209,0.081519,100.135735,5.101158,0.815191,-1302.669189,0.082534,0.000000
58.190002,23.044640,-1302.580200,0.007545,0.003226,0.081944,102.507675,5.221990,0.819441,-1302.580200,0.082941,0.000000
58.430004,23.533569,-1302.669189,0.007571,0.003241,0.082317,104.682541,5.332783,0.823169,-1302.669189,0.083340,0.000000
58.670002,24.049675,-1302.624634,0.007618,0.003258,0.082742,106.978294,5.449734,0.827420,-1302.624634,0.083739,0.000000
58.910004,24.599297,-1302.580200,0.007618,0.003275,0.083193,109.423134,5.574280,0.831931,-1302.580200,0.084138,0.000000
59.150002,25.476234,-1302.669189,0.007597,0.003293,0.083644,113.323952,5.772997,0.836439,-1302.669189,0.084537,0.000000
59.390003,25.693329,-1302.580200,0.007644,0.003306,0.083974,114.289635,5.822192,0.839736,-1302.580200,0.084936,0.000000
59.630001,26.005745,-1302.669189,0.007623,0.003317,0.084260,115.679329,5.892986,0.842597,-1302.669189,0.085335,0.000000
59.870003,27.048759,-1302.580200,0.007627,0.003338,0.084780,120.318893,6.129336,0.847801,-1302.580200,0.085734,0.000000
60.110004,27.537315,-1302.669189,0.007692,0.003352,0.085144,122.492096,6.240045,0.851442,-1302.669189,0.086142,0.000000
60.350002,28.181519,-1302.669189,0.007653,0.003370,0.085587,125.357658,6.386023,0.855867,-1302.669189,0.086540,0.000000
60.590004,28.901314,-1302.624634,0.007718,0.003386,0.085994,128.559464,6.549131,0.859940,-1302.624634,0.086939,0.000000
60.830002,29.272202,-1302.713623,0.007662,0.003398,0.086315,130.209259,6.633176,0.863149,-1302.713623,0.087338,0.000000
61.070004,30.262711,-1302.624634,0.007748,0.003417,0.086801,134.615265,6.857628,0.868005,-1302.624634,0.087737,0.000000
61.310001,30.928139,-1302.713623,0.007700,0.003433,0.087199,137.575226,7.008417,0.871994,-1302.713623,0.088136,0.000000
61.550003,31.283752,-1302.624634,0.007726,0.003443,0.087442,139.157074,7.089000,0.874424,-1302.624634,0.088535,0.000000
61.790005,32.356560,-1302.624634,0.007748,0.003462,0.087945,143.929169,7.332101,0.879454,-1302.624634,0.088934,0.000000
62.030003,33.467720,-1302.713623,0.007769,0.003482,0.088448,148.871857,7.583894,0.884485,-1302.713623,0.089342,0.000000
62.270004,34.228104,-1302.669189,0.007743,0.003498,0.088839,152.254211,7.756199,0.888387,-1302.669189,0.089741,0.000000
62.510002,34.639206,-1302.624634,0.007743,0.003510,0.089151,154.082886,7.849356,0.891509,-1302.624634,0.090140,0.000000
62.750004,35.252876,-1302.669189,0.007795,0.003524,0.089515,156.812622,7.988416,0.895150,-1302.669189,0.090538,0.000000
62.990002,36.562881,-1302.669189,0.007787,0.003544,0.090018,162.639816,8.285267,0.900181,-1302.669189,0.090937,0.000000
63.230003,37.421196,-1302.669189,0.007765,0.003559,0.090391,166.457794,8.479764,0.903909,-1302.669189,0.091336,0.000000
63.470001,37.857246,-1302.624634,0.007825,0.003570,0.090668,168.397446,8.578575,0.906683,-1302.624634,0.091735,0.000000
63.710003,39.279709,-1302.669189,0.007808,0.003591,0.091224,174.724869,8.900909,0.912235,-1302.669189,0.092134,0.000000
63.950005,40.381561,-1302.758057,0.007873,0.003608,0.091649,179.626160,9.150592,0.916486,-1302.758057,0.092542,0.000000
64.190002,41.215302,-1302.669189,0.007812,0.003624,0.092039,183.334824,9.339521,0.920388,-1302.669189,0.092941,0.000000
64.430000,42.270233,-1302.669189,0.007860,0.003640,0.092463,188.027390,9.578572,0.924635,-1302.669189,0.093340,0.000000
64.670006,42.869751,-1302.669189,0.007838,0.003653,0.092784,190.694183,9.714424,0.927844,-1302.669189,0.093739,0.000000
64.910004,44.180504,-1302.713623,0.007869,0.003671,0.093244,196.524689,10.011445,0.932443,-1302.713623,0.094138,0.000000
65.150002,44.971046,-1302.713623,0.007907,0.003684,0.093565,200.041199,10.190584,0.935649,-1302.713623,0.094536,0.000000
65.389999,45.463699,-1302.713623,0.007899,0.003695,0.093842,202.232635,10.302221,0.938423,-1302.713623,0.094935,0.000000
65.630005,47.092827,-1302.758057,0.007881,0.003716,0.094380,209.479355,10.671387,0.943801,-1302.758057,0.095343,0.000000
65.870003,48.073288,-1302.624634,0.007881,0.003727,0.094658,213.840668,10.893563,0.946576,-1302.624634,0.095742,0.000000
66.110001,49.612671,-1302.669189,0.007881,0.003748,0.095187,220.688187,11.242392,0.951867,-1302.669189,0.096140,0.000000
66.350006,50.988213,-1302.624634,0.007933,0.003767,0.095681,226.806900,11.554093,0.956810,-1302.624634,0.096539,0.000000
66.590004,51.763870,-1302.713623,0.007950,0.003778,0.095967,230.257202,11.729861,0.959671,-1302.713623,0.096938,0.000000
66.830002,53.079086,-1302.713623,0.007912,0.003797,0.096444,236.107574,12.027892,0.964440,-1302.713623,0.097337,0.000000
67.070000,54.243126,-1302.624634,0.007959,0.003810,0.096774,241.285477,12.291669,0.967737,-1302.624634,0.097736,0.000000
67.310005,54.905205,-1302.758057,0.007946,0.003821,0.097060,244.230545,12.441697,0.970598,-1302.758057,0.098135,0.000000
67.550003,56.064774,-1302.713623,0.007959,0.003841,0.097563,249.388565,12.704459,0.975629,-1302.713623,0.098543,0.000000
67.790001,57.776939,-1302.669189,0.007938,0.003856,0.097944,257.004669,13.092442,0.979444,-1302.669189,0.098942,0.000000
68.030006,58.729095,-1302.713623,0.007942,0.003868,0.098257,261.240051,13.308203,0.982566,-1302.713623,0.099341,0.000000
68.270004,60.238319,-1302.713623,0.007989,0.003887,0.098725,267.953430,13.650198,0.987248,-1302.713623,0.099740,0.000000
68.510002,60.975243,-1302.713623,0.007963,0.003899,0.099028,271.231415,13.817187,0.990284,-1302.713623,0.100138,0.000000
68.750000,62.838600,-1302.624634,0.008011,0.003918,0.099523,279.520050,14.239430,0.995227,-1302.624634,0.100537,0.000000
68.990005,63.645523,-1302.758057,0.008015,0.003928,0.099774,283.109436,14.422282,0.997744,-1302.758057,0.100936,0.000000
69.230003,64.965210,-1302.713623,0.008015,0.003943,0.100165,288.979675,14.721327,1.001646,-1302.713623,0.101335,0.000000
69.470001,66.379486,-1302.713623,0.008019,0.003960,0.100590,295.270691,15.041806,1.005896,-1302.713623,0.101743,0.000000
69.710007,67.361801,-1302.758057,0.008011,0.003964,0.100694,299.640259,15.264402,1.006937,-1302.758057,0.100884,0.000000
69.950005,67.056458,-1302.669189,0.008054,0.003964,0.100676,298.282013,15.195210,1.006763,-1302.669189,0.100676,0.000000
70.190002,66.778305,-1302.713623,0.008058,0.003963,0.100668,297.044739,15.132180,1.006676,-1302.713623,0.100676,0.000000
70.430000,66.581314,-1302.758057,0.008063,0.003963,0.100659,296.168488,15.087542,1.006589,-1302.758057,0.100676,0.000000
70.670006,66.388794,-1302.713623,0.008071,0.003963,0.100650,295.312103,15.043916,1.006502,-1302.713623,0.100676,0.000000
70.910004,66.212296,-1302.713623,0.008054,0.003962,0.100641,294.527008,15.003921,1.006415,-1302.713623,0.100676,0.000000
71.150002,66.069305,-1302.713623,0.008028,0.003962,0.100641,293.890961,14.971519,1.006415,-1302.713623,0.100676,0.000000
71.390007,65.937851,-1302.713623,0.008032,0.003962,0.100633,293.306213,14.941730,1.006328,-1302.713623,0.100676,0.000000
71.630005,65.807892,-1302.758057,0.008050,0.003962,0.100633,292.728119,14.912281,1.006328,-1302.758057,0.100676,0.000000
71.870003,65.706238,-1302.758057,0.008024,0.003962,0.100624,292.275940,14.889247,1.006241,-1302.758057,0.100676,0.000000
72.110001,65.596756,-1302.802612,0.008067,0.003962,0.100624,291.788940,14.864437,1.006241,-1302.802612,0.100676,0.000000
72.350006,65.496597,-1302.669189,0.008028,0.003961,0.100615,291.343414,14.841741,1.006154,-1302.669189,0.100676,0.000000
72.590004,65.432922,-1302.758057,0.008045,0.003961,0.100615,291.060181,14.827312,1.006154,-1302.758057,0.100676,0.000000
72.830002,65.345779,-1302.758057,0.008032,0.003961,0.100615,290.672546,14.807566,1.006154,-1302.758057,0.100676,0.000000
73.070000,65.268326,-1302.713623,0.008037,0.003961,0.100615,290.328003,14.790014,1.006154,-1302.713623,0.100676,0.000000
73.310005,65.202789,-1302.847046,0.008045,0.003961,0.100615,290.036499,14.775164,1.006154,-1302.847046,0.100676,0.000000
73.550003,65.128311,-1302.758057,0.008067,0.003961,0.100615,289.705200,14.758286,1.006154,-1302.758057,0.100676,0.000000
73.790001,65.075806,-1302.758057,0.008037,0.003961,0.100607,289.471649,14.746388,1.006067,-1302.758057,0.100676,0.000000
74.030006,65.014740,-1302.802612,0.008063,0.003961,0.100607,289.200012,14.732551,1.006067,-1302.802612,0.100676,0.000000
74.270004,64.953674,-1302.758057,0.008011,0.003961,0.100607,288.928375,14.718713,1.006067,-1302.758057,0.100676,0.000000
74.510002,64.898560,-1302.802612,0.008075,0.003961,0.100607,288.683197,14.706223,1.006067,-1302.802612,0.100676,0.000000
74.750000,64.844940,-1302.713623,0.008080,0.003961,0.100607,288.444702,14.694074,1.006067,-1302.713623,0.100676,0.000000
74.990005,64.796158,-1302.758057,0.008075,0.003961,0.100607,288.227692,14.683020,1.006067,-1302.758057,0.100676,0.000000
75.230003,64.758545,-1302.802612,0.008015,0.003961,0.100607,288.060394,14.674496,1.006067,-1302.802612,0.100676,0.000000
75.470001,64.710144,-1302.758057,0.008058,0.003961,0.100607,287.845093,14.663528,1.006067,-1302.758057,0.100676,0.000000
75.710007,64.664337,-1302.802612,0.008084,0.003961,0.100607,287.641327,14.653148,1.006067,-1302.802612,0.100676,0.000000
75.950005,64.636414,-1302.713623,0.008032,0.003961,0.100607,287.517120,14.646821,1.006067,-1302.713623,0.100676,0.000000
76.190002,64.596939,-1302.758057,0.008019,0.003961,0.100607,287.341522,14.637876,1.006067,-1302.758057,0.100676,0.000000
76.430000,64.544434,-1302.713623,0.008045,0.003961,0.100607,287.107971,14.625978,1.006067,-1302.713623,0.100676,0.000000
76.670006,64.532150,-1302.713623,0.008067,0.003961,0.100607,287.053345,14.623195,1.006067,-1302.713623,0.100676,0.000000
76.910004,64.488953,-1302.802612,0.008045,0.003961,0.100607,286.861176,14.613405,1.006067,-1302.802612,0.100676,0.000000
77.150002,64.446869,-1302.802612,0.008045,0.003961,0.100607,286.673981,14.603869,1.006067,-1302.802612,0.100676,0.000000
77.390007,64.434586,-1302.802612,0.008063,0.003961,0.100598,286.619354,14.601086,1.005983,-1302.802612,0.100676,0.000000
77.630005,64.379852,-1302.758057,0.008058,0.003961,0.100598,286.375885,14.588683,1.005983,-1302.758057,0.100676,0.000000
77.870003,64.351547,-1302.758057,0.008054,0.003961,0.100598,286.249969,14.582269,1.005983,-1302.758057,0.100676,0.000000
78.110001,64.339996,-1302.802612,0.008032,0.003961,0.100598,286.198608,14.579652,1.005983,-1302.802612,0.100676,0.000000
78.350006,64.296066,-1302.758057,0.008067,0.003961,0.100598,286.003174,14.569697,1.005983,-1302.758057,0.100676,0.000000
78.590004,64.273346,-1302.713623,0.008011,0.003961,0.100598,285.902130,14.564548,1.005983,-1302.713623,0.100676,0.000000
78.830002,64.237976,-1302.802612,0.008032,0.003961,0.100598,285.744781,14.556534,1.005983,-1302.802612,0.100676,0.000000
79.070007,64.198502,-1302.758057,0.008019,0.003961,0.100598,285.569183,14.547588,1.005983,-1302.758057,0.100676,0.000000
79.310005,64.199997,-1302.802612,0.008037,0.003961,0.100598,285.575836,14.547927,1.005983,-1302.802612,0.100676,0.000000
79.550003,64.162384,-1302.758057,0.008067,0.003961,0.100598,285.408539,14.539404,1.005983,-1302.758057,0.100676,0.000000
79.790001,64.132599,-1302.802612,0.008067,0.003961,0.100598,285.276062,14.532655,1.005983,-1302.802612,0.100676,0.000000
80.030006,64.112488,-1302.802612,0.008063,0.003961,0.100598,285.186584,14.528097,1.005983,-1302.802612,0.100676,0.000000
80.270004,64.084183,-1302.802612,0.008054,0.003961,0.100598,285.060669,14.521684,1.005983,-1302.802612,0.100676,0.000000
80.510002,64.052536,-1302.936035,0.008037,0.003961,0.100598,284.919922,14.514512,1.005983,-1302.936035,0.100676,0.000000
80.750008,64.033920,-1302.802612,0.008067,0.003961,0.100598,284.837097,14.510293,1.005983,-1302.802612,0.100676,0.000000
80.990005,64.007095,-1302.847046,0.008054,0.003961,0.100598,284.717773,14.504215,1.005983,-1302.847046,0.100676,0.000000
81.230003,63.973221,-1302.802612,0.008071,0.003961,0.100598,284.567108,14.496539,1.005983,-1302.802612,0.100676,0.000000
81.470001,63.974701,-1302.802612,0.008071,0.003961,0.100598,284.573669,14.496875,1.005983,-1302.802612,0.100676,0.000000
81.710007,63.929276,-1302.847046,0.008071,0.003961,0.100598,284.371613,14.486581,1.005983,-1302.847046,0.100676,0.000000
81.950005,63.903961,-1302.802612,0.008088,0.003961,0.100598,284.259003,14.480844,1.005983,-1302.802612,0.100676,0.000000
82.190002,63.902100,-1302.847046,0.008011,0.003961,0.100598,284.250732,14.480423,1.005983,-1302.847046,0.100676,0.000000
82.430000,63.868576,-1302.802612,0.008037,0.003961,0.100598,284.101624,14.472826,1.005983,-1302.802612,0.100676,0.000000
82.670006,63.849594,-1302.802612,0.008054,0.003961,0.100598,284.017181,14.468525,1.005983,-1302.802612,0.100676,0.000000
82.910004,63.839157,-1302.847046,0.008084,0.003961,0.100598,283.970764,14.466160,1.005983,-1302.847046,0.100676,0.000000
83.150002,63.788513,-1302.802612,0.008041,0.003961,0.100598,283.745483,14.454684,1.005983,-1302.802612,0.100676,0.000000
83.390007,63.786285,-1302.847046,0.008019,0.003961,0.100598,283.735565,14.454179,1.005983,-1302.847046,0.100676,0.000000
83.630005,63.777725,-1302.847046,0.008032,0.003961,0.100598,283.697479,14.452239,1.005983,-1302.847046,0.100676,0.000000
83.870003,63.721863,-1302.802612,0.008093,0.003961,0.100598,283.449005,14.439581,1.005983,-1302.802612,0.100676,0.000000
84.110001,63.733032,-1302.891479,0.008067,0.003961,0.100598,283.498688,14.442111,1.005983,-1302.891479,0.100676,0.000000
84.350006,63.714783,-1302.758057,0.008028,0.003961,0.100598,283.417511,14.437976,1.005983,-1302.758057,0.100676,0.000000
84.590004,63.677917,-1302.891479,0.008058,0.003961,0.100598,283.253510,14.429622,1.005983,-1302.891479,0.100676,0.000000
84.830002,63.683884,-1302.802612,0.008101,0.003961,0.100598,283.280060,14.430975,1.005983,-1302.802612,0.100676,0.000000
85.070007,63.643661,-1302.802612,0.008080,0.003961,0.100598,283.101135,14.421860,1.005983,-1302.802612,0.100676,0.000000
85.310005,63.640686,-1302.847046,0.008080,0.003961,0.100598,283.087921,14.421185,1.005983,-1302.847046,0.100676,0.000000
85.550003,63.632874,-1302.802612,0.008071,0.003961,0.100598,283.053162,14.419415,1.005983,-1302.802612,0.100676,0.000000
85.790001,63.601593,-1302.936035,0.008080,0.003961,0.100598,282.914001,14.412328,1.005983,-1302.936035,0.100676,0.000000
86.030006,63.601593,-1302.847046,0.008050,0.003961,0.100598,282.914001,14.412328,1.005983,-1302.847046,0.100676,0.000000
86.270004,63.567703,-1302.802612,0.008054,0.003961,0.100598,282.763275,14.404647,1.005983,-1302.802612,0.100676,0.000000
86.510002,63.559875,-1302.847046,0.008015,0.003961,0.100598,282.728455,14.402873,1.005983,-1302.847046,0.100676,0.000000
86.750008,63.544250,-1302.847046,0.008058,0.003961,0.100598,282.658936,14.399333,1.005983,-1302.847046,0.100676,0.000000
86.990005,63.514832,-1302.847046,0.008050,0.003961,0.100598,282.528076,14.392666,1.005983,-1302.847046,0.100676,0.000000
87.230003,63.510361,-1302.758057,0.008093,0.003961,0.100598,282.508179,14.391653,1.005983,-1302.758057,0.100676,0.000000
87.470001,63.499191,-1302.847046,0.008037,0.003961,0.100598,282.458496,14.389122,1.005983,-1302.847046,0.100676,0.000000
87.710007,63.477966,-1302.847046,0.008063,0.003961,0.100598,282.364105,14.384313,1.005983,-1302.847046,0.100676,0.000000
87.950005,63.474976,-1302.802612,0.008088,0.003961,0.100598,282.350800,14.383636,1.005983,-1302.802612,0.100676,0.000000
88.190002,63.466049,-1302.847046,0.008097,0.003961,0.100598,282.311096,14.381613,1.005983,-1302.847046,0.100676,0.000000
88.430008,63.429550,-1302.802612,0.008032,0.003961,0.100598,282.148743,14.373342,1.005983,-1302.802612,0.100676,0.000000
88.670006,63.418015,-1302.802612,0.008032,0.003961,0.100598,282.097412,14.370728,1.005983,-1302.802612,0.100676,0.000000
88.910004,63.397156,-1302.891479,0.008084,0.003961,0.100598,282.004639,14.366000,1.005983,-1302.891479,0.100676,0.000000
89.150002,63.385986,-1302.802612,0.008075,0.003961,0.100598,281.954956,14.363470,1.005983,-1302.802612,0.100676,0.000000
89.390007,63.382629,-1302.847046,0.008050,0.003961,0.100598,281.940002,14.362710,1.005983,-1302.847046,0.100676,0.000000
89.630005,63.355072,-1302.847046,0.008080,0.003961,0.100598,281.817444,14.356464,1.005983,-1302.847046,0.100676,0.000000
89.870003,63.347626,-1302.847046,0.008097,0.003961,0.100598,281.784302,14.354776,1.005983,-1302.847046,0.100676,0.000000
90.110001,63.331619,-1302.891479,0.008058,0.003961,0.100598,281.713104,14.351150,1.005983,-1302.891479,0.100676,0.000000
90.350006,63.315231,-1302.802612,0.008024,0.003961,0.100598,281.640228,14.347437,1.005983,-1302.802612,0.100676,0.000000
90.590004,63.313751,-1302.847046,0.008080,0.003961,0.100598,281.633636,14.347101,1.005983,-1302.847046,0.100676,0.000000
90.830002,63.283951,-1302.802612,0.008045,0.003961,0.100598,281.501068,14.340348,1.005983,-1302.802612,0.100676,0.000000
91.070007,63.266083,-1302.802612,0.008024,0.003961,0.100598,281.421600,14.336299,1.005983,-1302.802612,0.100676,0.000000
91.310005,63.277252,-1302.847046,0.008058,0.003961,0.100598,281.471283,14.338831,1.005983,-1302.847046,0.100676,0.000000
91.550003,63.246719,-1302.891479,0.008015,0.003961,0.100598,281.335449,14.331912,1.005983,-1302.891479,0.100676,0.000000
91.790001,63.230331,-1302.847046,0.008045,0.003961,0.100598,281.262573,14.328197,1.005983,-1302.847046,0.100676,0.000000
92.030006,63.229965,-1302.847046,0.008093,0.003961,0.100598,281.260925,14.328115,1.005983,-1302.847046,0.100676,0.000000
92.270004,63.213943,-1302.758057,0.008080,0.003961,0.100598,281.189667,14.324484,1.005983,-1302.758057,0.100676,0.000000
92.510002,63.207245,-1302.936035,0.008019,0.003961,0.100598,281.159882,14.322966,1.005983,-1302.936035,0.100676,0.000000
92.750008,63.193466,-1302.847046,0.008045,0.003961,0.100598,281.098572,14.319844,1.005983,-1302.847046,0.100676,0.000000
92.990005,63.180801,-1302.847046,0.008063,0.003961,0.100598,281.042236,14.316975,1.005983,-1302.847046,0.100676,0.000000
93.230003,63.171494,-1302.847046,0.008063,0.003961,0.100598,281.000824,14.314865,1.005983,-1302.847046,0.100676,0.000000
93.470001,63.159958,-1302.758057,0.008019,0.003961,0.100598,280.949524,14.312251,1.005983,-1302.758057,0.100676,0.000000
93.710007,63.148788,-1302.891479,0.008067,0.003961,0.100598,280.899841,14.309720,1.005983,-1302.891479,0.100676,0.000000
93.950005,63.145065,-1302.802612,0.008058,0.003961,0.100598,280.883270,14.308876,1.005983,-1302.802612,0.100676,0.000000
94.190002,63.119736,-1302.847046,0.008045,0.003961,0.100598,280.770599,14.303137,1.005983,-1302.847046,0.100676,0.000000
94.430008,63.119370,-1302.802612,0.008045,0.003961,0.100598,280.768982,14.303053,1.005983,-1302.802612,0.100676,0.000000
94.670006,63.118622,-1302.802612,0.008041,0.003961,0.100598,280.765656,14.302884,1.005983,-1302.802612,0.100676,0.000000
94.910004,63.077660,-1302.891479,0.008050,0.003961,0.100598,280.583435,14.293602,1.005983,-1302.891479,0.100676,0.000000
95.150002,63.094421,-1302.847046,0.008101,0.003961,0.100598,280.657990,14.297400,1.005983,-1302.847046,0.100676,0.000000
95.390007,63.062393,-1302.891479,0.008050,0.003961,0.100598,280.515533,14.290143,1.005983,-1302.891479,0.100676,0.000000
95.630005,63.050476,-1302.891479,0.008058,0.003961,0.100598,280.462524,14.287442,1.005983,-1302.891479,0.100676,0.000000
95.870003,63.060158,-1302.891479,0.008075,0.003961,0.100598,280.505585,14.289637,1.005983,-1302.891479,0.100676,0.000000
96.110008,63.043030,-1302.847046,0.008050,0.003961,0.100598,280.429413,14.285754,1.005983,-1302.847046,0.100676,0.000000
96.350006,63.033722,-1302.847046,0.008050,0.003961,0.100598,280.388000,14.283646,1.005983,-1302.847046,0.100676,0.000000
96.590004,63.027016,-1302.802612,0.008028,0.003961,0.100598,280.358154,14.282125,1.005983,-1302.802612,0.100676,0.000000
96.830002,63.019569,-1302.758057,0.008093,0.003961,0.100598,280.325043,14.280438,1.005983,-1302.758057,0.100676,0.000000
97.070007,63.006912,-1302.802612,0.008093,0.003961,0.100598,280.268738,14.277570,1.005983,-1302.802612,0.100676,0.000000
97.310005,63.007278,-1302.847046,0.008084,0.003961,0.100598,280.270386,14.277653,1.005983,-1302.847046,0.100676,0.000000
97.550003,62.986427,-1302.847046,0.008041,0.003961,0.100598,280.177612,14.272928,1.005983,-1302.847046,0.100676,0.000000
97.790001,62.992760,-1302.847046,0.008080,0.003961,0.100598,280.205780,14.274364,1.005983,-1302.847046,0.100676,0.000000
98.030006,62.968552,-1302.847046,0.008106,0.003961,0.100598,280.098114,14.268878,1.005983,-1302.847046,0.100676,0.000000
98.270004,62.964828,-1302.802612,0.008088,0.003961,0.100598,280.081543,14.268034,1.005983,-1302.802612,0.100676,0.000000
98.510002,62.977119,-1302.847046,0.008024,0.003961,0.100598,280.136230,14.270820,1.005983,-1302.847046,0.100676,0.000000
98.750008,62.928337,-1302.847046,0.008050,0.003961,0.100598,279.919220,14.259765,1.005983,-1302.847046,0.100676,0.000000
98.990005,62.931694,-1302.847046,0.008071,0.003961,0.100598,279.934143,14.260526,1.005983,-1302.847046,0.100676,0.000000
99.230003,62.928337,-1302.802612,0.008067,0.003961,0.100598,279.919220,14.259765,1.005983,-1302.802612,0.100676,0.000000
99.470001,62.911957,-1302.847046,0.008032,0.003961,0.100598,279.846375,14.256054,1.005983,-1302.847046,0.100676,0.000000
99.710007,62.910835,-1302.936035,0.008088,0.003961,0.100598,279.841370,14.255799,1.005983,-1302.936035,0.100676,0.000000
99.950005,62.910835,-1302.891479,0.008058,0.003961,0.100598,279.841370,14.255799,1.005983,-1302.891479,0.100676,0.000000
100.000008,62.912697,-1302.847046,0.008041,0.003961,0.100598,279.849640,14.256221,1.005983,-1302.847046,0.100676,0.000000