File: Data/Automembrane/AutoNoheat15-1-4_12132023_190508.csv
Time (sec),S:Load (lbs),S:HL1 (DIM),S:LVDT (in),S:Position (in),Ch:Position (mm),Ch:Load (N),Ch:Stress (MPa),Ch:Strain (mm/mm),Ch:HL1 (DIM),Set Point (),Cycles ()
0.010000,-0.005959,-1303.514282,0.000000,-0.000000,-0.000000,-0.026505,-0.001350,-0.000000,-1303.514282,0.000260,0.000000
0.270000,-0.001862,-1303.469849,0.000052,-0.000000,-0.000000,-0.008281,-0.000422,-0.000000,-1303.469849,0.000260,0.000000
0.530000,-0.027924,-1303.469849,0.000000,0.000084,0.002133,-0.124210,-0.006328,0.021332,-1303.469849,0.002862,0.000000
0.790000,-0.008560,-1303.469849,0.000134,0.000247,0.006261,-0.038078,-0.001940,0.062614,-1303.469849,0.007198,0.000000
1.050000,-0.014153,-1303.558716,0.000267,0.000406,0.010311,-0.062954,-0.003207,0.103112,-1303.558716,0.011534,0.000000
1.310000,-0.059952,-1303.469849,0.000448,0.000585,0.014847,-0.266679,-0.013585,0.148470,-1303.469849,0.015870,0.000000
1.570000,-0.007446,-1303.558716,0.000668,0.000755,0.019166,-0.033123,-0.001687,0.191656,-1303.558716,0.020189,0.000000
1.830000,0.003723,-1303.425293,0.000828,0.000917,0.023294,0.016561,0.000844,0.232938,-1303.425293,0.024525,0.000000
2.090000,-0.027184,-1303.514282,0.000970,0.001095,0.027812,-0.120918,-0.006160,0.278118,-1303.514282,0.028861,0.000000
2.350000,-0.011543,-1303.425293,0.001160,0.001266,0.032165,-0.051347,-0.002616,0.321652,-1303.425293,0.033180,0.000000
2.610000,-0.013779,-1303.380859,0.001319,0.001432,0.036363,-0.061291,-0.003122,0.363626,-1303.380859,0.037516,0.000000
2.870000,-0.037605,-1303.469849,0.001535,0.001604,0.040751,-0.167277,-0.008521,0.407508,-1303.469849,0.041852,0.000000
3.130000,-0.008934,-1303.469849,0.001725,0.001780,0.045208,-0.039741,-0.002024,0.452083,-1303.469849,0.046188,0.000000
3.390000,-0.006332,-1303.425293,0.001871,0.001942,0.049328,-0.028168,-0.001435,0.493278,-1303.425293,0.050507,0.000000
3.650000,-0.028297,-1303.469849,0.002052,0.002117,0.053768,-0.125873,-0.006412,0.537678,-1303.469849,0.054843,0.000000
3.910000,-0.004837,-1303.425293,0.002246,0.002287,0.058078,-0.021516,-0.001096,0.580781,-1303.425293,0.059179,0.000000
4.170000,0.020477,-1303.514282,0.002410,0.002462,0.062544,0.091088,0.004640,0.625443,-1303.514282,0.063515,0.000000
4.430000,-0.008194,-1303.469849,0.002600,0.002631,0.066837,-0.036449,-0.001857,0.668371,-1303.469849,0.067834,0.000000
4.690000,-0.009682,-1303.380859,0.002790,0.002798,0.071069,-0.043066,-0.002194,0.710690,-1303.380859,0.072170,0.000000
4.950000,-0.006699,-1303.469849,0.002936,0.002969,0.075414,-0.029797,-0.001518,0.754140,-1303.469849,0.076507,0.000000
5.210000,-0.063301,-1303.425293,0.003160,0.003141,0.079776,-0.281577,-0.014344,0.797761,-1303.425293,0.080843,0.000000
5.470000,-0.020111,-1303.514282,0.003307,0.003310,0.084069,-0.089459,-0.004557,0.840690,-1303.514282,0.085162,0.000000
5.730000,0.014526,-1303.425293,0.003544,0.003482,0.088440,0.064617,0.003292,0.884398,-1303.425293,0.089498,0.000000
5.990000,-0.030533,-1303.425293,0.003669,0.003652,0.092767,-0.135817,-0.006919,0.927670,-1303.425293,0.093834,0.000000
6.250000,0.010056,-1303.425293,0.003876,0.003823,0.097112,0.044729,0.002279,0.971117,-1303.425293,0.098170,0.000000
6.510000,0.015266,-1303.469849,0.004040,0.003996,0.101500,0.067908,0.003459,1.014999,-1303.469849,0.102489,0.000000
6.770000,-0.021599,-1303.425293,0.004217,0.004161,0.105697,-0.096076,-0.004894,1.056974,-1303.425293,0.106825,0.000000
7.030000,0.017502,-1303.469849,0.004385,0.004333,0.110051,0.077852,0.003966,1.100507,-1303.469849,0.111161,0.000000
7.290000,0.003723,-1303.469849,0.004600,0.004508,0.114508,0.016561,0.000844,1.145082,-1303.469849,0.115480,0.000000
7.550000,-0.002235,-1303.514282,0.004721,0.004677,0.118792,-0.009944,-0.000507,1.187923,-1303.514282,0.119816,0.000000
7.810000,0.220818,-1303.380859,0.004915,0.004842,0.122981,0.982246,0.050038,1.229811,-1303.380859,0.124152,0.000000
8.070001,0.683304,-1303.425293,0.005122,0.005019,0.127491,3.039487,0.154839,1.274908,-1303.425293,0.128436,0.000000
8.330000,0.605103,-1303.469849,0.005148,-0.000001,-0.000035,2.691631,0.137118,-0.000348,-1303.469849,0.000156,0.000000
8.590000,0.591698,-1303.425293,0.005148,-0.000002,-0.000044,2.632003,0.134081,-0.000435,-1303.425293,0.000156,0.000000
8.850000,0.602875,-1303.425293,0.005152,-0.000002,-0.000044,2.681721,0.136613,-0.000435,-1303.425293,0.000590,0.000000
9.110001,0.566750,-1303.380859,0.005152,-0.000001,-0.000035,2.521028,0.128427,-0.000348,-1303.380859,0.001023,0.000000
9.370001,0.695961,-1303.469849,0.005165,0.000027,0.000676,3.095789,0.157707,0.006764,-1303.469849,0.001457,0.000000
9.630000,0.785706,-1303.380859,0.005144,0.000043,0.001101,3.494993,0.178043,0.011014,-1303.380859,0.001891,0.000000
9.890000,0.877312,-1303.380859,0.005144,0.000060,0.001518,3.902477,0.198802,0.015177,-1303.380859,0.002324,0.000000
10.150001,0.955505,-1303.469849,0.005208,0.000074,0.001882,4.250300,0.216521,0.018818,-1303.469849,0.002758,0.000000
10.410001,0.999077,-1303.425293,0.005165,0.000086,0.002177,4.444116,0.226394,0.021767,-1303.425293,0.003191,0.000000
10.670000,1.161430,-1303.514282,0.005200,0.000114,0.002897,5.166300,0.263184,0.028966,-1303.514282,0.003625,0.000000
10.930000,1.269043,-1303.425293,0.005238,0.000132,0.003347,5.644985,0.287569,0.033474,-1303.425293,0.004059,0.000000
11.190001,1.270164,-1303.425293,0.005286,0.000144,0.003668,5.649974,0.287823,0.036683,-1303.425293,0.004492,0.000000
11.450001,1.417625,-1303.425293,0.005247,0.000162,0.004111,6.305913,0.321239,0.041108,-1303.425293,0.004926,0.000000
11.710001,1.579231,-1303.380859,0.005264,0.000182,0.004614,7.024772,0.357859,0.046138,-1303.380859,0.005359,0.000000
11.970000,1.712540,-1303.425293,0.005282,0.000198,0.005021,7.617757,0.388067,0.050210,-1303.425293,0.005793,0.000000
12.230000,1.813080,-1303.425293,0.005307,0.000208,0.005290,8.064981,0.410850,0.052901,-1303.425293,0.006227,0.000000
12.490001,2.027939,-1303.380859,0.005359,0.000231,0.005871,9.020722,0.459538,0.058711,-1303.380859,0.006660,0.000000
12.750001,2.194016,-1303.425293,0.005342,0.000249,0.006322,9.759468,0.497171,0.063219,-1303.425293,0.007094,0.000000
13.010000,2.327698,-1303.380859,0.005355,0.000263,0.006678,10.354116,0.527464,0.066777,-1303.380859,0.007527,0.000000
13.270000,2.487450,-1303.469849,0.005333,0.000281,0.007128,11.064729,0.563664,0.071285,-1303.469849,0.007961,0.000000
13.530001,2.627090,-1303.425293,0.005394,0.000294,0.007467,11.685882,0.595307,0.074668,-1303.425293,0.008395,0.000000
13.790001,2.824448,-1303.425293,0.005437,0.000310,0.007883,12.563770,0.640029,0.078832,-1303.425293,0.008828,0.000000
14.050000,3.068726,-1303.380859,0.005454,0.000329,0.008360,13.650373,0.695383,0.083601,-1303.380859,0.009262,0.000000
14.310000,3.307785,-1303.425293,0.005407,0.000347,0.008802,14.713762,0.749555,0.088022,-1303.425293,0.009695,0.000000
14.570001,3.563232,-1303.469849,0.005497,0.000367,0.009331,15.850049,0.807440,0.093313,-1303.469849,0.010129,0.000000
14.830001,3.747185,-1303.380859,0.005471,0.000382,0.009713,16.668310,0.849124,0.097128,-1303.380859,0.010563,0.000000
15.090001,3.932999,-1303.469849,0.005497,0.000400,0.010173,17.494852,0.891230,0.101727,-1303.469849,0.010996,0.000000
15.350000,4.161263,-1303.380859,0.005514,0.000417,0.010589,18.510220,0.942956,0.105890,-1303.380859,0.011430,0.000000
15.610001,4.360481,-1303.425293,0.005523,0.000434,0.011031,19.396389,0.988099,0.110311,-1303.425293,0.011864,0.000000
15.870001,4.582047,-1303.469849,0.005566,0.000450,0.011439,20.381960,1.038307,0.114387,-1303.469849,0.012297,0.000000
16.130001,4.567894,-1303.425293,0.005545,0.000460,0.011682,20.319008,1.035100,0.116817,-1303.425293,0.012731,0.000000
16.390001,5.035591,-1303.380859,0.005553,0.000486,0.012349,22.399427,1.141081,0.123494,-1303.380859,0.013165,0.000000
16.650002,5.248589,-1303.469849,0.005631,0.000506,0.012844,23.346888,1.189347,0.128437,-1303.469849,0.013598,0.000000
16.910002,5.300354,-1303.469849,0.005652,0.000521,0.013234,23.577152,1.201077,0.132339,-1303.469849,0.014032,0.000000
17.170000,5.527122,-1303.469849,0.005609,0.000536,0.013607,24.585869,1.252464,0.136067,-1303.469849,0.014465,0.000000
17.430000,5.798210,-1303.336304,0.005644,0.000553,0.014049,25.791727,1.313893,0.140492,-1303.336304,0.014899,0.000000
17.690001,6.025360,-1303.425293,0.005639,0.000569,0.014448,26.802141,1.365366,0.144481,-1303.425293,0.015324,0.000000
17.950001,6.030945,-1303.380859,0.005635,0.000579,0.014708,26.826982,1.366632,0.147081,-1303.380859,0.015758,0.000000
18.210001,6.474442,-1303.336304,0.005700,0.000604,0.015333,28.799755,1.467129,0.153326,-1303.336304,0.016191,0.000000
18.470001,6.595093,-1303.469849,0.005726,0.000623,0.015818,29.336437,1.494469,0.158182,-1303.469849,0.016625,0.000000
18.730001,6.787979,-1303.380859,0.005726,0.000640,0.016260,30.194439,1.538178,0.162603,-1303.380859,0.017058,0.000000
18.990002,6.864685,-1303.469849,0.005721,0.000654,0.016616,30.535645,1.555560,0.166161,-1303.469849,0.017492,0.000000
19.250000,7.065399,-1303.425293,0.005721,0.000669,0.016980,31.428465,1.601042,0.169802,-1303.425293,0.017926,0.000000
19.510000,7.449310,-1303.425293,0.005734,0.000688,0.017483,33.136189,1.688038,0.174832,-1303.425293,0.018359,0.000000
19.770000,7.657471,-1303.425293,0.005739,0.000705,0.017908,34.062130,1.735208,0.179082,-1303.425293,0.018793,0.000000
20.030001,7.826897,-1303.380859,0.005782,0.000720,0.018298,34.815777,1.773600,0.182985,-1303.380859,0.019227,0.000000
20.290001,8.176186,-1303.380859,0.005846,0.000741,0.018810,36.369492,1.852750,0.188102,-1303.380859,0.019660,0.000000
20.550001,8.311356,-1303.380859,0.005808,0.000757,0.019235,36.970757,1.883380,0.192352,-1303.380859,0.020094,0.000000
20.810001,8.438705,-1303.380859,0.005821,0.000773,0.019642,37.537235,1.912238,0.196425,-1303.380859,0.020527,0.000000
21.070002,8.727669,-1303.469849,0.005838,0.000791,0.020102,38.822609,1.977718,0.201023,-1303.469849,0.020961,0.000000
21.330002,9.100037,-1303.425293,0.005846,0.000811,0.020605,40.478985,2.062098,0.206053,-1303.425293,0.021394,0.000000
21.590000,9.310059,-1303.425293,0.005890,0.000825,0.020961,41.413208,2.109689,0.209607,-1303.425293,0.021828,0.000000
21.850000,9.498848,-1303.380859,0.005898,0.000840,0.021342,42.252987,2.152470,0.213423,-1303.380859,0.022262,0.000000
22.110001,9.788925,-1303.380859,0.005894,0.000859,0.021820,43.543312,2.218202,0.218195,-1303.380859,0.022695,0.000000
22.370001,10.116989,-1303.380859,0.005924,0.000877,0.022270,45.002617,2.292542,0.222703,-1303.380859,0.023129,0.000000
22.630001,10.277855,-1303.380859,0.005959,0.000891,0.022634,45.718182,2.328995,0.226344,-1303.380859,0.023562,0.000000
22.890001,10.575752,-1303.425293,0.006002,0.000911,0.023129,47.043297,2.396500,0.231287,-1303.425293,0.023996,0.000000
23.150002,10.948120,-1303.380859,0.005993,0.000928,0.023580,48.699669,2.480879,0.235799,-1303.380859,0.024430,0.000000
23.410002,11.328316,-1303.336304,0.006028,0.000948,0.024083,50.390865,2.567033,0.240829,-1303.336304,0.024863,0.000000
23.670002,11.497002,-1303.469849,0.006028,0.000963,0.024456,51.141216,2.605258,0.244557,-1303.469849,0.025297,0.000000
23.930000,11.614670,-1303.380859,0.005989,0.000975,0.024768,51.664631,2.631922,0.247680,-1303.380859,0.025730,0.000000
24.190001,11.863785,-1303.380859,0.006062,0.000993,0.025219,52.772751,2.688372,0.252188,-1303.380859,0.026164,0.000000
24.450001,12.484535,-1303.425293,0.006062,0.001015,0.025791,55.533985,2.829036,0.257914,-1303.425293,0.026598,0.000000
24.710001,12.560493,-1303.425293,0.006049,0.001029,0.026138,55.871864,2.846248,0.261381,-1303.425293,0.027031,0.000000
24.970001,12.933243,-1303.425293,0.006075,0.001049,0.026650,57.529938,2.930715,0.266498,-1303.425293,0.027465,0.000000
25.230001,13.133949,-1303.380859,0.006122,0.001064,0.027014,58.422726,2.976196,0.270139,-1303.380859,0.027898,0.000000
25.490002,13.527176,-1303.469849,0.006071,0.001080,0.027439,60.171883,3.065302,0.274390,-1303.469849,0.028332,0.000000
25.750002,13.782249,-1303.380859,0.006144,0.001097,0.027864,61.306507,3.123102,0.278640,-1303.380859,0.028766,0.000000
26.010002,13.835869,-1303.291870,0.006105,0.001109,0.028159,61.545017,3.135253,0.281589,-1303.291870,0.029199,0.000000
26.270000,13.940880,-1303.469849,0.006148,0.001120,0.028454,62.012131,3.159049,0.284537,-1303.469849,0.029633,0.000000
26.530001,14.717651,-1303.336304,0.006140,0.001145,0.029095,65.467384,3.335067,0.290952,-1303.336304,0.030058,0.000000
26.790001,15.052414,-1303.425293,0.006226,0.001166,0.029624,66.956482,3.410926,0.296244,-1303.425293,0.030491,0.000000
27.050001,15.165611,-1303.380859,0.006187,0.001181,0.030006,67.460007,3.436577,0.300059,-1303.380859,0.030925,0.000000
27.310001,15.247536,-1303.336304,0.006183,0.001196,0.030387,67.824425,3.455141,0.303874,-1303.336304,0.031359,0.000000
27.570002,15.716354,-1303.380859,0.006204,0.001214,0.030830,69.909836,3.561377,0.308299,-1303.380859,0.031792,0.000000
27.830002,15.998611,-1303.425293,0.006243,0.001229,0.031229,71.165375,3.625337,0.312288,-1303.425293,0.032226,0.000000
28.090002,16.441734,-1303.380859,0.006273,0.001251,0.031784,73.136490,3.725750,0.317837,-1303.380859,0.032660,0.000000
28.350002,16.787666,-1303.380859,0.006239,0.001270,0.032270,74.675270,3.804139,0.322696,-1303.380859,0.033093,0.000000
28.610001,16.868477,-1303.380859,0.006278,0.001284,0.032625,75.034729,3.822451,0.326250,-1303.380859,0.033527,0.000000
28.870001,17.170837,-1303.380859,0.006334,0.001302,0.033067,76.379700,3.890967,0.330675,-1303.380859,0.033961,0.000000
29.130001,17.540604,-1303.336304,0.006347,0.001322,0.033588,78.024506,3.974757,0.335875,-1303.336304,0.034394,0.000000
29.390001,17.718971,-1303.425293,0.006286,0.001336,0.033935,78.817917,4.015176,0.339346,-1303.425293,0.034828,0.000000
29.650002,17.918938,-1303.425293,0.006312,0.001351,0.034325,79.707413,4.060489,0.343248,-1303.425293,0.035261,0.000000
29.910002,17.909996,-1303.380859,0.006312,0.001364,0.034646,79.667641,4.058463,0.346458,-1303.380859,0.035695,0.000000
30.170002,18.716187,-1303.380859,0.006338,0.001390,0.035313,83.253754,4.241148,0.353134,-1303.380859,0.036129,0.000000
30.430002,18.879654,-1303.380859,0.006390,0.001406,0.035712,83.980896,4.278191,0.357124,-1303.380859,0.036562,0.000000
30.690001,19.027863,-1303.380859,0.006416,0.001423,0.036154,84.640160,4.311775,0.361545,-1303.380859,0.036996,0.000000
30.950001,19.203247,-1303.336304,0.006390,0.001440,0.036571,85.420311,4.351518,0.365708,-1303.336304,0.037430,0.000000
31.210001,19.531677,-1303.380859,0.006416,0.001458,0.037022,86.881241,4.425941,0.370219,-1303.380859,0.037863,0.000000
31.470001,19.761810,-1303.380859,0.006476,0.001473,0.037403,87.904922,4.478090,0.374035,-1303.380859,0.038297,0.000000
31.730001,19.789360,-1303.380859,0.006420,0.001485,0.037724,88.027473,4.484333,0.377244,-1303.380859,0.038730,0.000000
31.990002,20.396706,-1303.425293,0.006476,0.001509,0.038332,90.729080,4.621960,0.383315,-1303.425293,0.039164,0.000000
32.250000,20.920258,-1303.380859,0.006472,0.001531,0.038878,93.057953,4.740598,0.388777,-1303.380859,0.039598,0.000000
32.510002,20.730721,-1303.380859,0.006480,0.001543,0.039199,92.214851,4.697649,0.391986,-1303.380859,0.040031,0.000000
32.770000,20.923607,-1303.425293,0.006480,0.001560,0.039632,93.072853,4.741357,0.396324,-1303.425293,0.040465,0.000000
33.030003,21.422218,-1303.380859,0.006545,0.001581,0.040152,95.290787,4.854344,0.401524,-1303.380859,0.040898,0.000000
33.290001,21.592392,-1303.380859,0.006571,0.001597,0.040551,96.047760,4.892906,0.405514,-1303.380859,0.041332,0.000000
33.550003,21.489243,-1303.336304,0.006579,0.001607,0.040812,95.588928,4.869532,0.408118,-1303.336304,0.041766,0.000000
33.810001,22.181114,-1303.380859,0.006545,0.001631,0.041436,98.666527,5.026312,0.414359,-1303.380859,0.042199,0.000000
34.070004,22.413475,-1303.514282,0.006592,0.001647,0.041844,99.700119,5.078966,0.418435,-1303.514282,0.042633,0.000000
34.330002,22.372887,-1303.336304,0.006610,0.001663,0.042234,99.519569,5.069768,0.422338,-1303.336304,0.043066,0.000000
34.590000,22.628334,-1303.425293,0.006648,0.001679,0.042659,100.655853,5.127654,0.426588,-1303.425293,0.043500,0.000000
34.850002,22.665192,-1303.380859,0.006635,0.001696,0.043075,100.819809,5.136006,0.430751,-1303.380859,0.043934,0.000000
35.110001,22.902023,-1303.380859,0.006648,0.001711,0.043448,101.873291,5.189672,0.434479,-1303.380859,0.044367,0.000000
35.370003,23.225990,-1303.380859,0.006610,0.001728,0.043882,103.314362,5.263085,0.438817,-1303.380859,0.044801,0.000000
35.630001,23.441223,-1303.336304,0.006696,0.001745,0.044324,104.271767,5.311857,0.443238,-1303.336304,0.045226,0.000000
35.890003,23.995682,-1303.425293,0.006704,0.001767,0.044870,106.738121,5.437499,0.448703,-1303.425293,0.045659,0.000000
36.150002,24.045578,-1303.336304,0.006683,0.001781,0.045243,106.960075,5.448806,0.452431,-1303.336304,0.046093,0.000000
36.410000,24.229904,-1303.425293,0.006709,0.001800,0.045729,107.779999,5.490575,0.457287,-1303.425293,0.046527,0.000000
36.670002,24.384064,-1303.425293,0.006713,0.001816,0.046119,108.465736,5.525508,0.461189,-1303.425293,0.046960,0.000000
36.930000,24.532646,-1303.380859,0.006782,0.001833,0.046570,109.126663,5.559177,0.465701,-1303.380859,0.047394,0.000000
37.190002,24.776176,-1303.380859,0.006769,0.001849,0.046960,110.209938,5.614362,0.469603,-1303.380859,0.047827,0.000000
37.450001,24.471573,-1303.380859,0.006765,0.001858,0.047203,108.854996,5.545338,0.472029,-1303.380859,0.048261,0.000000
37.710003,25.347763,-1303.425293,0.006748,0.001883,0.047836,112.752480,5.743886,0.478362,-1303.425293,0.048695,0.000000
37.970001,25.710831,-1303.425293,0.006808,0.001904,0.048357,114.367485,5.826158,0.483566,-1303.425293,0.049128,0.000000
38.230003,25.519806,-1303.469849,0.006821,0.001920,0.048764,113.517769,5.782871,0.487642,-1303.469849,0.049562,0.000000
38.490002,25.604706,-1303.425293,0.006847,0.001934,0.049128,113.895416,5.802109,0.491283,-1303.425293,0.049995,0.000000
38.750000,25.811745,-1303.291870,0.006842,0.001951,0.049562,114.816376,5.849025,0.495621,-1303.291870,0.050429,0.000000
39.010002,26.142784,-1303.469849,0.006808,0.001967,0.049970,116.288910,5.924039,0.499697,-1303.469849,0.050863,0.000000
39.270000,25.983406,-1303.425293,0.006885,0.001978,0.050230,115.579964,5.887924,0.502297,-1303.425293,0.051296,0.000000
39.530003,26.692780,-1303.336304,0.006829,0.002002,0.050846,118.735413,6.048670,0.508455,-1303.336304,0.051730,0.000000
39.790001,26.941521,-1303.425293,0.006903,0.002020,0.051314,119.841873,6.105036,0.513137,-1303.425293,0.052164,0.000000
40.050003,27.218567,-1303.336304,0.006916,0.002038,0.051756,121.074234,6.167815,0.517562,-1303.336304,0.052597,0.000000
40.310001,27.071480,-1303.469849,0.006920,0.002053,0.052138,120.419960,6.134485,0.521377,-1303.469849,0.053031,0.000000
40.570004,27.134041,-1303.425293,0.006950,0.002067,0.052502,120.698242,6.148662,0.525018,-1303.425293,0.053464,0.000000
40.830002,27.544395,-1303.380859,0.006924,0.002087,0.053005,122.523590,6.241649,0.530048,-1303.380859,0.053898,0.000000
41.090000,27.770050,-1303.425293,0.006985,0.002104,0.053430,123.527351,6.292783,0.534298,-1303.425293,0.054332,0.000000
41.350002,27.795372,-1303.336304,0.006942,0.002119,0.053820,123.639992,6.298522,0.538201,-1303.336304,0.054765,0.000000
41.610001,28.377014,-1303.469849,0.006959,0.002139,0.054332,126.227264,6.430323,0.543318,-1303.469849,0.055199,0.000000
41.870003,28.420959,-1303.380859,0.006989,0.002155,0.054748,126.422745,6.440281,0.547481,-1303.380859,0.055633,0.000000
42.130001,28.255249,-1303.425293,0.007036,0.002168,0.055060,125.685623,6.402731,0.550600,-1303.425293,0.056066,0.000000
42.390003,28.482399,-1303.425293,0.007041,0.002186,0.055520,126.696037,6.454204,0.555199,-1303.425293,0.056500,0.000000
42.650002,29.179482,-1303.425293,0.007023,0.002210,0.056136,129.796814,6.612165,0.561357,-1303.425293,0.056934,0.000000
42.910004,29.170914,-1303.514282,0.007036,0.002224,0.056500,129.758698,6.610224,0.564998,-1303.514282,0.057367,0.000000
43.170002,29.070747,-1303.425293,0.007054,0.002239,0.056864,129.313141,6.587525,0.568639,-1303.425293,0.057801,0.000000
43.430000,29.173897,-1303.380859,0.007114,0.002256,0.057315,129.771973,6.610899,0.573150,-1303.380859,0.058234,0.000000
43.690002,29.608078,-1303.425293,0.007118,0.002276,0.057801,131.703308,6.709286,0.578006,-1303.425293,0.058668,0.000000
43.950001,29.617760,-1303.336304,0.007105,0.002290,0.058165,131.746368,6.711480,0.581648,-1303.336304,0.059102,0.000000
44.210003,29.784210,-1303.425293,0.007118,0.002309,0.058642,132.486786,6.749199,0.586416,-1303.425293,0.059535,0.000000
44.470001,29.968536,-1303.380859,0.007136,0.002324,0.059041,133.306702,6.790967,0.590406,-1303.380859,0.059969,0.000000
44.730003,30.495445,-1303.469849,0.007161,0.002346,0.059587,135.650513,6.910367,0.595871,-1303.469849,0.060394,0.000000
44.990002,30.539383,-1303.425293,0.007192,0.002361,0.059977,135.845963,6.920323,0.599773,-1303.425293,0.060827,0.000000
45.250004,30.322662,-1303.380859,0.007166,0.002374,0.060290,134.881943,6.871213,0.602896,-1303.380859,0.061261,0.000000
45.510002,30.362877,-1303.469849,0.007170,0.002391,0.060723,135.060822,6.880326,0.607230,-1303.469849,0.061695,0.000000
45.770000,31.298279,-1303.469849,0.007196,0.002414,0.061321,139.221695,7.092291,0.613214,-1303.469849,0.062128,0.000000
46.030003,31.013786,-1303.425293,0.007252,0.002426,0.061616,137.956207,7.027824,0.616162,-1303.425293,0.062562,0.000000
46.290001,31.285248,-1303.469849,0.007217,0.002447,0.062145,139.163727,7.089339,0.621453,-1303.469849,0.062995,0.000000
46.550003,31.147469,-1303.469849,0.007235,0.002460,0.062475,138.550858,7.058117,0.624750,-1303.469849,0.063429,0.000000
46.810001,31.648682,-1303.425293,0.007265,0.002479,0.062969,140.780365,7.171694,0.629693,-1303.425293,0.063863,0.000000
47.070004,31.749596,-1303.425293,0.007226,0.002496,0.063403,141.229248,7.194561,0.634030,-1303.425293,0.064296,0.000000
47.330002,31.410736,-1303.469849,0.007243,0.002506,0.063663,139.721939,7.117774,0.636631,-1303.469849,0.064730,0.000000
47.590004,31.243164,-1303.425293,0.007295,0.002517,0.063941,138.976532,7.079803,0.639405,-1303.425293,0.065163,0.000000
47.850002,32.322678,-1303.425293,0.007312,0.002544,0.064617,143.778458,7.324424,0.646169,-1303.425293,0.065597,0.000000
48.110001,32.674568,-1303.469849,0.007343,0.002565,0.065146,145.343735,7.404163,0.651460,-1303.469849,0.066031,0.000000
48.370003,32.524132,-1303.425293,0.007308,0.002580,0.065536,144.674561,7.370073,0.655362,-1303.425293,0.066464,0.000000
48.630001,32.144310,-1303.469849,0.007351,0.002592,0.065848,142.985031,7.284005,0.658485,-1303.469849,0.066898,0.000000
48.890003,32.789261,-1303.425293,0.007330,0.002612,0.066343,145.853912,7.430152,0.663428,-1303.425293,0.067331,0.000000
49.150002,32.901344,-1303.380859,0.007351,0.002628,0.066750,146.352493,7.455551,0.667504,-1303.380859,0.067765,0.000000
49.410004,33.202217,-1303.514282,0.007403,0.002648,0.067271,147.690842,7.523730,0.672708,-1303.514282,0.068199,0.000000
49.670002,33.620766,-1303.380859,0.007351,0.002669,0.067782,149.552628,7.618574,0.677822,-1303.380859,0.068632,0.000000
49.930004,33.510544,-1303.469849,0.007377,0.002683,0.068147,149.062347,7.593598,0.681467,-1303.469849,0.069066,0.000000
50.190002,33.693748,-1303.514282,0.007364,0.002700,0.068589,149.877274,7.635112,0.685887,-1303.514282,0.069499,0.000000
50.450001,33.800621,-1303.425293,0.007390,0.002720,0.069092,150.352676,7.659330,0.690917,-1303.425293,0.069933,0.000000
50.710003,33.918289,-1303.469849,0.007390,0.002736,0.069482,150.876083,7.685994,0.694820,-1303.469849,0.070366,0.000000
50.970001,33.907494,-1303.469849,0.007437,0.002751,0.069872,150.828064,7.683548,0.698722,-1303.469849,0.070800,0.000000
51.230003,33.501976,-1303.469849,0.007450,0.002762,0.070159,149.024231,7.591656,0.701587,-1303.469849,0.071234,0.000000
51.490002,34.377052,-1303.469849,0.007450,0.002788,0.070826,152.916763,7.789951,0.708264,-1303.469849,0.071667,0.000000
51.750004,34.428444,-1303.514282,0.007506,0.002804,0.071225,153.145370,7.801597,0.712253,-1303.514282,0.072101,0.000000
52.010002,34.438492,-1303.469849,0.007468,0.002820,0.071624,153.190063,7.803874,0.716242,-1303.469849,0.072535,0.000000
52.270004,34.410942,-1303.469849,0.007506,0.002838,0.072084,153.067520,7.797631,0.720837,-1303.469849,0.072968,0.000000
52.530003,34.590050,-1303.425293,0.007502,0.002855,0.072517,153.864227,7.838217,0.725175,-1303.425293,0.073402,0.000000
52.790001,34.768044,-1303.469849,0.007541,0.002871,0.072925,154.655975,7.878551,0.729251,-1303.469849,0.073836,0.000000
53.050003,34.386734,-1303.469849,0.007558,0.002884,0.073246,152.959839,7.792145,0.732460,-1303.469849,0.074269,0.000000
53.310001,34.838799,-1303.469849,0.007541,0.002906,0.073801,154.970718,7.894585,0.738009,-1303.469849,0.074703,0.000000
53.570004,35.534386,-1303.425293,0.007532,0.002928,0.074373,158.064835,8.052207,0.743732,-1303.425293,0.075128,0.000000
53.830002,35.241699,-1303.425293,0.007584,0.002941,0.074703,156.762909,7.985883,0.747029,-1303.425293,0.075561,0.000000
54.090004,35.129616,-1303.469849,0.007567,0.002958,0.075137,156.264328,7.960485,0.751366,-1303.469849,0.075995,0.000000
54.350002,35.323997,-1303.425293,0.007571,0.002978,0.075631,157.128983,8.004532,0.756309,-1303.425293,0.076429,0.000000
54.610004,35.602905,-1303.469849,0.007644,0.002994,0.076056,158.369629,8.067734,0.760556,-1303.469849,0.076862,0.000000
54.870003,35.134460,-1303.469849,0.007644,0.003005,0.076325,156.285889,7.961583,0.763247,-1303.469849,0.077296,0.000000
55.130001,35.837502,-1303.469849,0.007640,0.003029,0.076931,159.413162,8.120893,0.769314,-1303.469849,0.077729,0.000000
55.390003,36.046028,-1303.469849,0.007614,0.003046,0.077365,160.340744,8.168146,0.773651,-1303.469849,0.078163,0.000000
55.650002,35.784248,-1303.336304,0.007627,0.003061,0.077747,159.176285,8.108827,0.777467,-1303.336304,0.078597,0.000000
55.910004,35.856865,-1303.514282,0.007692,0.003078,0.078172,159.499298,8.125282,0.781717,-1303.514282,0.079030,0.000000
56.170002,35.621895,-1303.380859,0.007653,0.003092,0.078536,158.454102,8.072037,0.785358,-1303.380859,0.079464,0.000000
56.430004,35.801750,-1303.425293,0.007657,0.003107,0.078909,159.254135,8.112792,0.789090,-1303.425293,0.079898,0.000000
56.690002,36.091827,-1303.425293,0.007696,0.003126,0.079403,160.544464,8.178525,0.794033,-1303.425293,0.080331,0.000000
56.950005,36.060181,-1303.469849,0.007713,0.003143,0.079828,160.403702,8.171354,0.798280,-1303.469849,0.080765,0.000000
57.210003,36.760979,-1303.469849,0.007722,0.003164,0.080375,163.520996,8.330157,0.803745,-1303.469849,0.081198,0.000000
57.470001,36.786674,-1303.425293,0.007743,0.003180,0.080773,163.635300,8.335980,0.807734,-1303.425293,0.081632,0.000000
57.730003,36.951637,-1303.469849,0.007752,0.003199,0.081250,164.369095,8.373361,0.812503,-1303.469849,0.082066,0.000000
57.990002,37.053665,-1303.514282,0.007765,0.003214,0.081641,164.822937,8.396481,0.816406,-1303.514282,0.082499,0.000000
58.250004,36.971748,-1303.425293,0.007778,0.003231,0.082066,164.458557,8.377917,0.820656,-1303.425293,0.082933,0.000000
58.510002,37.261826,-1303.514282,0.007756,0.003247,0.082473,165.748871,8.443651,0.824732,-1303.514282,0.083366,0.000000
58.770004,36.778481,-1303.380859,0.007791,0.003258,0.082759,163.598846,8.334123,0.827594,-1303.380859,0.083800,0.000000
59.030003,37.803627,-1303.469849,0.007756,0.003284,0.083401,168.158936,8.566424,0.834009,-1303.469849,0.084234,0.000000
59.290001,38.270584,-1303.514282,0.007791,0.003303,0.083895,170.236053,8.672237,0.838952,-1303.514282,0.084667,0.000000
59.550003,38.145462,-1303.425293,0.007869,0.003319,0.084303,169.679489,8.643886,0.843029,-1303.425293,0.085101,0.000000
59.810001,38.034492,-1303.469849,0.007812,0.003333,0.084650,169.185867,8.618739,0.846499,-1303.469849,0.085534,0.000000
60.070004,38.024071,-1303.380859,0.007860,0.003349,0.085058,169.139511,8.616378,0.850576,-1303.380859,0.085968,0.000000
60.330002,37.924271,-1303.514282,0.007890,0.003364,0.085439,168.695587,8.593762,0.854391,-1303.514282,0.086402,0.000000
60.590004,38.266487,-1303.514282,0.007881,0.003376,0.085751,170.217834,8.671310,0.857513,-1303.514282,0.086835,0.000000
60.850002,38.922607,-1303.425293,0.007877,0.003400,0.086367,173.136398,8.819989,0.863671,-1303.425293,0.087269,0.000000
61.110004,39.436478,-1303.514282,0.007925,0.003419,0.086853,175.422211,8.936434,0.868527,-1303.514282,0.087702,0.000000
61.370003,39.838272,-1303.469849,0.007912,0.003437,0.087295,177.209488,9.027482,0.872948,-1303.469849,0.088136,0.000000
61.630001,39.638306,-1303.469849,0.007938,0.003451,0.087659,176.319992,8.982168,0.876593,-1303.469849,0.088570,0.000000
61.890003,39.612236,-1303.514282,0.007938,0.003465,0.088006,176.204025,8.976261,0.880060,-1303.514282,0.089003,0.000000
62.150002,40.079941,-1303.425293,0.007881,0.003485,0.088509,178.284485,9.082245,0.885090,-1303.425293,0.089437,0.000000
62.410004,40.391983,-1303.514282,0.007976,0.003501,0.088934,179.672516,9.152954,0.889341,-1303.514282,0.089870,0.000000
62.670002,40.489922,-1303.514282,0.007942,0.003517,0.089324,180.108170,9.175147,0.893243,-1303.514282,0.090295,0.000000
62.930004,41.315842,-1303.425293,0.007985,0.003538,0.089870,183.782043,9.362304,0.898704,-1303.425293,0.090729,0.000000
63.190002,41.539635,-1303.514282,0.007989,0.003554,0.090278,184.777527,9.413015,0.902781,-1303.514282,0.091163,0.000000
63.450005,41.448410,-1303.425293,0.007989,0.003569,0.090651,184.371735,9.392344,0.906513,-1303.425293,0.091596,0.000000
63.710003,41.668854,-1303.514282,0.008015,0.003586,0.091076,185.352325,9.442297,0.910759,-1303.514282,0.092030,0.000000
63.970001,42.452324,-1303.469849,0.007985,0.003608,0.091631,188.837372,9.619835,0.916312,-1303.469849,0.092463,0.000000
64.230003,42.581909,-1303.469849,0.008032,0.003623,0.092013,189.413788,9.649199,0.920127,-1303.469849,0.092897,0.000000
64.490005,42.693619,-1303.514282,0.008054,0.003637,0.092377,189.910706,9.674512,0.923768,-1303.514282,0.093331,0.000000
64.750000,42.882042,-1303.425293,0.008084,0.003654,0.092819,190.748856,9.717210,0.928192,-1303.425293,0.093764,0.000000
65.010002,43.668495,-1303.514282,0.008114,0.003674,0.093314,194.247162,9.895422,0.933136,-1303.514282,0.094198,0.000000
65.270004,43.850578,-1303.469849,0.008041,0.003688,0.093678,195.057114,9.936683,0.936777,-1303.469849,0.094632,0.000000
65.530006,44.234871,-1303.469849,0.008097,0.003707,0.094155,196.766541,10.023765,0.941546,-1303.469849,0.095065,0.000000
65.790001,44.699219,-1303.514282,0.008119,0.003724,0.094588,198.832062,10.128988,0.945883,-1303.514282,0.095499,0.000000
66.050003,45.369492,-1303.469849,0.008101,0.003745,0.095117,201.813583,10.280873,0.951174,-1303.469849,0.095932,0.000000
66.310005,45.715424,-1303.514282,0.008166,0.003759,0.095490,203.352356,10.359263,0.954903,-1303.514282,0.096366,0.000000
66.570000,45.508011,-1303.425293,0.008183,0.003771,0.095776,202.429749,10.312263,0.957764,-1303.425293,0.096800,0.000000
66.830002,45.885597,-1303.469849,0.008179,0.003785,0.096140,204.109329,10.397825,0.961405,-1303.469849,0.097233,0.000000
67.090004,47.235451,-1303.514282,0.008192,0.003812,0.096826,210.113785,10.703706,0.968256,-1303.514282,0.097667,0.000000
67.350006,47.347534,-1303.425293,0.008153,0.003824,0.097138,210.612350,10.729105,0.971378,-1303.425293,0.098101,0.000000
67.610001,47.730331,-1303.514282,0.008205,0.003843,0.097606,212.315125,10.815848,0.976064,-1303.514282,0.098534,0.000000
67.870003,48.058388,-1303.514282,0.008179,0.003856,0.097953,213.774384,10.890186,0.979531,-1303.514282,0.098968,0.000000
68.130005,48.987091,-1303.514282,0.008244,0.003876,0.098456,217.905457,11.100634,0.984561,-1303.514282,0.099402,0.000000
68.390007,49.418297,-1303.514282,0.008201,0.003893,0.098872,219.823563,11.198346,0.988724,-1303.514282,0.099835,0.000000
68.650002,49.462608,-1303.514282,0.008257,0.003904,0.099159,220.020676,11.208386,0.991586,-1303.514282,0.100269,0.000000
68.910004,49.708374,-1303.514282,0.008231,0.003915,0.099436,221.113892,11.264078,0.994360,-1303.514282,0.100702,0.000000
69.170006,51.381073,-1303.514282,0.008269,0.003942,0.100130,228.554428,11.643118,1.001298,-1303.514282,0.101136,0.000000
69.430000,52.122467,-1303.558716,0.008274,0.003963,0.100659,231.852310,11.811120,1.006589,-1303.558716,0.101570,0.000000
69.690002,52.438980,-1303.469849,0.008300,0.003977,0.101006,233.260239,11.882843,1.010056,-1303.469849,0.102003,0.000000
69.950005,52.569679,-1303.469849,0.008313,0.003988,0.101292,233.841614,11.912459,1.012921,-1303.469849,0.102437,0.000000
70.210007,53.651794,-1303.514282,0.008326,0.004010,0.101856,238.655106,12.157670,1.018557,-1303.514282,0.102870,0.000000
70.470001,54.475487,-1303.425293,0.008326,0.004026,0.102272,242.319061,12.344321,1.022720,-1303.425293,0.103304,0.000000
70.730003,55.210548,-1303.514282,0.008321,0.004045,0.102740,245.588791,12.510889,1.027402,-1303.514282,0.103738,0.000000
70.990005,56.508270,-1303.514282,0.008343,0.004067,0.103304,251.361343,12.804957,1.033038,-1303.514282,0.104171,0.000000
71.250000,56.803558,-1303.425293,0.008364,0.004081,0.103660,252.674850,12.871871,1.036596,-1303.425293,0.104605,0.000000
71.510002,57.727043,-1303.514282,0.008399,0.004099,0.104110,256.782715,13.081136,1.041103,-1303.514282,0.105038,0.000000
71.770004,58.240913,-1303.469849,0.008399,0.004117,0.104579,259.068512,13.197579,1.045789,-1303.469849,0.105463,0.000000
72.030006,59.235519,-1303.558716,0.008364,0.004132,0.104960,263.492737,13.422960,1.049604,-1303.558716,0.105897,0.000000
72.290001,59.991814,-1303.514282,0.008399,0.004148,0.105368,266.856903,13.594338,1.053681,-1303.514282,0.106331,0.000000
72.550003,60.221191,-1303.469849,0.008407,0.004160,0.105672,267.877228,13.646317,1.056716,-1303.469849,0.106764,0.000000
72.810005,61.811592,-1303.558716,0.008468,0.004185,0.106296,274.951691,14.006707,1.062958,-1303.558716,0.107198,0.000000
73.070000,62.765984,-1303.425293,0.008420,0.004202,0.106738,279.197052,14.222976,1.067382,-1303.425293,0.107631,0.000000
73.330002,63.531578,-1303.514282,0.008438,0.004218,0.107146,282.602570,14.396461,1.071458,-1303.514282,0.108065,0.000000
73.590004,64.160515,-1303.514282,0.008451,0.004235,0.107570,285.400238,14.538980,1.075705,-1303.514282,0.108499,0.000000
73.850006,65.184914,-1303.469849,0.008438,0.004251,0.107978,289.956970,14.771112,1.079781,-1303.469849,0.108932,0.000000
74.110001,65.983284,-1303.469849,0.008446,0.004268,0.108412,293.508301,14.952025,1.084119,-1303.469849,0.109366,0.000000
74.370003,66.629723,-1303.514282,0.008459,0.004280,0.108715,296.383820,15.098511,1.087154,-1303.514282,0.109799,0.000000
74.630005,67.077309,-1303.469849,0.008541,0.004285,0.108846,298.374756,15.199935,1.088456,-1303.469849,0.109080,0.000000
74.890007,66.239845,-1303.514282,0.008485,0.004285,0.108846,294.649536,15.010163,1.088456,-1303.514282,0.109080,0.000000
75.150002,65.625435,-1303.514282,0.008507,0.004283,0.108793,291.916504,14.870936,1.087934,-1303.514282,0.108846,0.000000
75.410004,64.969307,-1303.514282,0.008481,0.004283,0.108776,288.997925,14.722256,1.087760,-1303.514282,0.108846,0.000000
75.670006,64.436073,-1303.380859,0.008541,0.004282,0.108767,286.625977,14.601422,1.087673,-1303.380859,0.108846,0.000000
75.930000,63.958321,-1303.514282,0.008524,0.004282,0.108767,284.500824,14.493162,1.087673,-1303.514282,0.108846,0.000000
76.190002,63.504402,-1303.558716,0.008554,0.004282,0.108759,282.481689,14.390304,1.087586,-1303.558716,0.108846,0.000000
76.450005,63.136864,-1303.469849,0.008532,0.004282,0.108759,280.846802,14.307018,1.087586,-1303.469849,0.108846,0.000000
76.710007,62.788704,-1303.514282,0.008524,0.004282,0.108759,279.298096,14.228124,1.087586,-1303.514282,0.108846,0.000000
76.970001,62.476280,-1303.514282,0.008541,0.004282,0.108759,277.908386,14.157328,1.087586,-1303.514282,0.108846,0.000000
77.230003,62.199982,-1303.514282,0.008524,0.004282,0.108750,276.679352,14.094717,1.087502,-1303.514282,0.108846,0.000000
77.490005,61.921074,-1303.514282,0.008563,0.004282,0.108750,275.438690,14.031516,1.087502,-1303.514282,0.108846,0.000000
77.750000,61.684242,-1303.425293,0.008541,0.004282,0.108750,274.385223,13.977849,1.087502,-1303.425293,0.108846,0.000000
78.010002,61.480553,-1303.514282,0.008554,0.004282,0.108750,273.479156,13.931693,1.087502,-1303.514282,0.108846,0.000000
78.270004,61.256386,-1303.514282,0.008532,0.004282,0.108750,272.482025,13.880896,1.087502,-1303.514282,0.108846,0.000000
78.530006,61.069832,-1303.469849,0.008580,0.004282,0.108750,271.652191,13.838622,1.087502,-1303.469849,0.108846,0.000000
78.790001,60.900772,-1303.558716,0.008558,0.004282,0.108750,270.900177,13.800312,1.087502,-1303.558716,0.108846,0.000000
79.050003,60.718307,-1303.469849,0.008567,0.004282,0.108750,270.088531,13.758965,1.087502,-1303.469849,0.108846,0.000000
79.310005,60.568245,-1303.558716,0.008563,0.004282,0.108750,269.421021,13.724961,1.087502,-1303.558716,0.108846,0.000000
79.570007,60.412216,-1303.514282,0.008520,0.004282,0.108750,268.726959,13.689604,1.087502,-1303.514282,0.108846,0.000000
79.830002,60.258430,-1303.469849,0.008571,0.004282,0.108750,268.042877,13.654756,1.087502,-1303.469849,0.108846,0.000000
80.090004,60.150444,-1303.514282,0.008520,0.004282,0.108750,267.562531,13.630286,1.087502,-1303.514282,0.108846,0.000000
80.350006,60.013039,-1303.425293,0.008532,0.004282,0.108750,266.951324,13.599149,1.087502,-1303.425293,0.108846,0.000000
80.610001,59.894997,-1303.469849,0.008589,0.004282,0.108750,266.426239,13.572400,1.087502,-1303.469849,0.108846,0.000000
80.870003,59.780304,-1303.514282,0.008532,0.004282,0.108750,265.916077,13.546411,1.087502,-1303.514282,0.108846,0.000000
81.130005,59.666733,-1303.558716,0.008550,0.004281,0.108742,265.410889,13.520675,1.087415,-1303.558716,0.108846,0.000000
81.390007,59.571030,-1303.558716,0.008554,0.004281,0.108742,264.985168,13.498988,1.087415,-1303.558716,0.108846,0.000000
81.650002,59.462669,-1303.469849,0.008593,0.004281,0.108742,264.503174,13.474433,1.087415,-1303.469849,0.108846,0.000000
81.910004,59.373672,-1303.425293,0.008597,0.004281,0.108742,264.107300,13.454267,1.087415,-1303.425293,0.108846,0.000000
82.170006,59.285789,-1303.514282,0.008589,0.004281,0.108742,263.716370,13.434352,1.087415,-1303.514282,0.108846,0.000000
82.430000,59.200516,-1303.558716,0.008545,0.004281,0.108742,263.337036,13.415029,1.087415,-1303.558716,0.108846,0.000000
82.690002,59.122696,-1303.558716,0.008558,0.004281,0.108742,262.990875,13.397394,1.087415,-1303.558716,0.108846,0.000000
82.950005,59.026253,-1303.514282,0.008576,0.004281,0.108742,262.561890,13.375540,1.087415,-1303.514282,0.108846,0.000000
83.210007,58.944328,-1303.558716,0.008567,0.004281,0.108742,262.197479,13.356976,1.087415,-1303.558716,0.108846,0.000000
83.470001,58.877670,-1303.469849,0.008550,0.004281,0.108742,261.900970,13.341871,1.087415,-1303.469849,0.108846,0.000000
83.730003,58.811760,-1303.514282,0.008601,0.004281,0.108742,261.607788,13.326935,1.087415,-1303.514282,0.108846,0.000000
83.990005,58.721649,-1303.558716,0.008550,0.004281,0.108742,261.206940,13.306516,1.087415,-1303.558716,0.108846,0.000000
84.250008,58.678825,-1303.469849,0.008580,0.004281,0.108742,261.016449,13.296812,1.087415,-1303.469849,0.108846,0.000000
84.510002,58.588715,-1303.558716,0.008614,0.004281,0.108742,260.615631,13.276393,1.087415,-1303.558716,0.108846,0.000000
84.770004,58.547379,-1303.558716,0.008563,0.004281,0.108742,260.431732,13.267026,1.087415,-1303.558716,0.108846,0.000000
85.030006,58.491150,-1303.469849,0.008584,0.004281,0.108742,260.181641,13.254284,1.087415,-1303.469849,0.108846,0.000000
85.290001,58.402901,-1303.514282,0.008545,0.004281,0.108742,259.789062,13.234286,1.087415,-1303.514282,0.108846,0.000000
85.550003,58.361938,-1303.514282,0.008610,0.004281,0.108742,259.606873,13.225004,1.087415,-1303.514282,0.108846,0.000000
85.810005,58.300125,-1303.603271,0.008563,0.004281,0.108742,259.331909,13.210998,1.087415,-1303.603271,0.108846,0.000000
86.070007,58.243149,-1303.514282,0.008593,0.004281,0.108742,259.078461,13.198086,1.087415,-1303.514282,0.108846,0.000000
86.330002,58.196228,-1303.514282,0.008610,0.004281,0.108742,258.869751,13.187453,1.087415,-1303.514282,0.108846,0.000000
86.590004,58.139999,-1303.514282,0.008597,0.004281,0.108742,258.619629,13.174712,1.087415,-1303.514282,0.108846,0.000000
86.850006,58.091965,-1303.469849,0.008601,0.004281,0.108742,258.405975,13.163827,1.087415,-1303.469849,0.108846,0.000000
87.110001,58.038719,-1303.514282,0.008571,0.004281,0.108742,258.169128,13.151762,1.087415,-1303.514282,0.108846,0.000000
87.370003,57.977646,-1303.514282,0.008567,0.004281,0.108742,257.897461,13.137922,1.087415,-1303.514282,0.108846,0.000000
87.630005,57.946365,-1303.514282,0.008580,0.004281,0.108742,257.758301,13.130835,1.087415,-1303.514282,0.108846,0.000000
87.890007,57.900940,-1303.558716,0.008563,0.004281,0.108742,257.556244,13.120541,1.087415,-1303.558716,0.108846,0.000000
88.150002,57.851418,-1303.469849,0.008601,0.004281,0.108742,257.335968,13.109319,1.087415,-1303.469849,0.108846,0.000000
88.410004,57.820503,-1303.514282,0.008550,0.004281,0.108742,257.198456,13.102314,1.087415,-1303.514282,0.108846,0.000000
88.670006,57.761673,-1303.469849,0.008550,0.004281,0.108742,256.936768,13.088982,1.087415,-1303.469849,0.108846,0.000000
88.930008,57.735237,-1303.469849,0.008554,0.004281,0.108742,256.819153,13.082992,1.087415,-1303.469849,0.108846,0.000000
89.190002,57.695389,-1303.514282,0.008589,0.004281,0.108742,256.641907,13.073961,1.087415,-1303.514282,0.108846,0.000000
89.450005,57.635811,-1303.514282,0.008545,0.004281,0.108742,256.376892,13.060461,1.087415,-1303.514282,0.108846,0.000000
89.710007,57.625755,-1303.514282,0.008589,0.004281,0.108742,256.332153,13.058183,1.087415,-1303.514282,0.108846,0.000000
89.970001,57.572876,-1303.514282,0.008567,0.004281,0.108742,256.096954,13.046200,1.087415,-1303.514282,0.108846,0.000000
90.230003,57.534149,-1303.558716,0.008610,0.004281,0.108742,255.924683,13.037425,1.087415,-1303.558716,0.108846,0.000000
90.490005,57.497658,-1303.603271,0.008584,0.004281,0.108742,255.762360,13.029155,1.087415,-1303.603271,0.108846,0.000000
90.750008,57.450745,-1303.514282,0.008619,0.004281,0.108742,255.553680,13.018525,1.087415,-1303.514282,0.108846,0.000000
91.010002,57.423187,-1303.558716,0.008580,0.004281,0.108742,255.431091,13.012280,1.087415,-1303.558716,0.108846,0.000000
91.270004,57.389297,-1303.469849,0.008571,0.004281,0.108742,255.280350,13.004601,1.087415,-1303.469849,0.108846,0.000000
91.530006,57.337166,-1303.514282,0.008593,0.004281,0.108742,255.048447,12.992788,1.087415,-1303.514282,0.108846,0.000000
91.790001,57.321159,-1303.603271,0.008571,0.004281,0.108742,254.977249,12.989161,1.087415,-1303.603271,0.108846,0.000000
92.050003,57.279449,-1303.469849,0.008541,0.004281,0.108742,254.791718,12.979709,1.087415,-1303.469849,0.108846,0.000000
92.310005,57.263069,-1303.558716,0.008567,0.004281,0.108742,254.718857,12.975997,1.087415,-1303.558716,0.108846,0.000000
92.570007,57.215775,-1303.558716,0.008563,0.004281,0.108742,254.508469,12.965280,1.087415,-1303.558716,0.108846,0.000000
92.830002,57.178162,-1303.514282,0.008571,0.004281,0.108742,254.341171,12.956757,1.087415,-1303.514282,0.108846,0.000000
93.090004,57.162155,-1303.514282,0.008589,0.004281,0.108742,254.269958,12.953130,1.087415,-1303.514282,0.108846,0.000000
93.350006,57.124168,-1303.558716,0.008601,0.004281,0.108742,254.100998,12.944522,1.087415,-1303.558716,0.108846,0.000000
93.610008,57.090660,-1303.514282,0.008567,0.004281,0.108742,253.951935,12.936929,1.087415,-1303.514282,0.108846,0.000000
93.870003,57.060120,-1303.514282,0.008567,0.004281,0.108742,253.816086,12.930008,1.087415,-1303.514282,0.108846,0.000000
94.130005,57.013947,-1303.558716,0.008558,0.004281,0.108742,253.610703,12.919545,1.087415,-1303.558716,0.108846,0.000000
94.390007,57.003891,-1303.558716,0.008614,0.004281,0.108742,253.565964,12.917267,1.087415,-1303.558716,0.108846,0.000000
94.650002,56.968895,-1303.469849,0.008563,0.004281,0.108742,253.410294,12.909336,1.087415,-1303.469849,0.108846,0.000000
94.910004,56.945435,-1303.558716,0.008597,0.004281,0.108742,253.305939,12.904020,1.087415,-1303.558716,0.108846,0.000000
95.170006,56.929794,-1303.558716,0.008558,0.004281,0.108742,253.236374,12.900476,1.087415,-1303.558716,0.108846,0.000000
95.430008,56.887711,-1303.469849,0.008597,0.004281,0.108742,253.049179,12.890939,1.087415,-1303.469849,0.108846,0.000000
95.690002,56.862396,-1303.603271,0.008558,0.004281,0.108742,252.936569,12.885203,1.087415,-1303.603271,0.108846,0.000000
95.950005,56.835953,-1303.514282,0.008584,0.004281,0.108742,252.818939,12.879210,1.087415,-1303.514282,0.108846,0.000000
96.210007,56.806534,-1303.514282,0.008614,0.004281,0.108742,252.688080,12.872544,1.087415,-1303.514282,0.108846,0.000000
96.470001,56.796486,-1303.514282,0.008601,0.004281,0.108742,252.643387,12.870267,1.087415,-1303.514282,0.108846,0.000000
96.730003,56.748077,-1303.469849,0.008606,0.004281,0.108742,252.428055,12.859298,1.087415,-1303.469849,0.108846,0.000000
96.990005,56.736160,-1303.558716,0.008541,0.004281,0.108733,252.375046,12.856598,1.087328,-1303.558716,0.108846,0.000000
97.250008,56.719032,-1303.469849,0.008563,0.004281,0.108733,252.298859,12.852716,1.087328,-1303.469849,0.108846,0.000000
97.510002,56.669128,-1303.469849,0.008593,0.004281,0.108733,252.076874,12.841408,1.087328,-1303.469849,0.108846,0.000000
97.770004,56.669502,-1303.469849,0.008584,0.004281,0.108733,252.078537,12.841493,1.087328,-1303.469849,0.108846,0.000000
98.030006,56.636360,-1303.469849,0.008563,0.004281,0.108733,251.931107,12.833982,1.087328,-1303.469849,0.108846,0.000000
98.290001,56.595772,-1303.514282,0.008580,0.004281,0.108733,251.750565,12.824785,1.087328,-1303.514282,0.108846,0.000000
98.550003,56.601730,-1303.425293,0.008593,0.004281,0.108733,251.777069,12.826136,1.087328,-1303.425293,0.108846,0.000000
98.810005,56.554443,-1303.469849,0.008584,0.004281,0.108733,251.566727,12.815420,1.087328,-1303.469849,0.108846,0.000000
99.070007,56.545502,-1303.425293,0.008558,0.004281,0.108733,251.526947,12.813394,1.087328,-1303.425293,0.108846,0.000000
99.330002,56.520927,-1303.514282,0.008563,0.004281,0.108733,251.417648,12.807825,1.087328,-1303.514282,0.108846,0.000000
99.590004,56.488159,-1303.469849,0.008576,0.004281,0.108733,251.271881,12.800400,1.087328,-1303.469849,0.108846,0.000000
99.850006,56.478851,-1303.425293,0.008614,0.004281,0.108733,251.230484,12.798291,1.087328,-1303.425293,0.108846,0.000000
100.110008,56.456879,-1303.514282,0.008601,0.004281,0.108733,251.132736,12.793311,1.087328,-1303.514282,0.108846,0.000000
100.370003,56.415543,-1303.425293,0.008563,0.004281,0.108733,250.948868,12.783944,1.087328,-1303.425293,0.108846,0.000000
100.630005,56.424484,-1303.425293,0.008576,0.004281,0.108733,250.988647,12.785971,1.087328,-1303.425293,0.108846,0.000000
100.890007,56.381660,-1303.514282,0.008576,0.004281,0.108733,250.798157,12.776267,1.087328,-1303.514282,0.108846,0.000000
101.150002,56.363045,-1303.425293,0.008576,0.004281,0.108733,250.715347,12.772048,1.087328,-1303.425293,0.108846,0.000000
101.410004,56.351868,-1303.514282,0.008584,0.004281,0.108733,250.665634,12.769516,1.087328,-1303.514282,0.108846,0.000000
101.670006,56.316124,-1303.469849,0.008610,0.004281,0.108733,250.506638,12.761416,1.087328,-1303.469849,0.108846,0.000000
101.930008,56.315002,-1303.469849,0.008545,0.004281,0.108733,250.501648,12.761162,1.087328,-1303.469849,0.108846,0.000000
102.190002,56.284843,-1303.514282,0.008576,0.004281,0.108733,250.367493,12.754328,1.087328,-1303.514282,0.108846,0.000000
102.450005,56.255798,-1303.425293,0.008597,0.004281,0.108733,250.238281,12.747746,1.087328,-1303.425293,0.108846,0.000000
102.710007,56.261383,-1303.469849,0.008541,0.004281,0.108733,250.263138,12.749012,1.087328,-1303.469849,0.108846,0.000000
102.970001,56.232712,-1303.469849,0.008558,0.004281,0.108733,250.135590,12.742515,1.087328,-1303.469849,0.108846,0.000000
103.230003,56.199944,-1303.514282,0.008619,0.004281,0.108733,249.989838,12.735089,1.087328,-1303.514282,0.108846,0.000000
103.490005,56.204041,-1303.514282,0.008541,0.004281,0.108733,250.008057,12.736017,1.087328,-1303.514282,0.108846,0.000000
103.750008,56.157867,-1303.380859,0.008606,0.004281,0.108733,249.802673,12.725554,1.087328,-1303.380859,0.108846,0.000000
104.010002,56.160095,-1303.469849,0.008589,0.004281,0.108733,249.812576,12.726060,1.087328,-1303.469849,0.108846,0.000000
104.270004,56.155258,-1303.425293,0.008576,0.004281,0.108733,249.791061,12.724964,1.087328,-1303.425293,0.108846,0.000000
104.530006,56.122864,-1303.469849,0.008563,0.004281,0.108733,249.646973,12.717623,1.087328,-1303.469849,0.108846,0.000000
104.790009,56.106102,-1303.469849,0.008571,0.004281,0.108733,249.572403,12.713824,1.087328,-1303.469849,0.108846,0.000000
105.000008,56.099403,-1303.469849,0.008627,0.004281,0.108733,249.542603,12.712307,1.087328,-1303.469849,0.108846,0.000000