File: Data/Automembrane/AutoHeating-15wt-1-4_12152023_165728.csv
Time (sec),S:Load (lbs),S:HL1 (DIM),S:LVDT (in),S:Position (in),Ch:Position (mm),Ch:Load (N),Ch:Stress (MPa),Ch:Strain (mm/mm),Ch:HL1 (DIM),Set Point (),Cycles ()
0.110000,-0.007072,-139.714661,-0.000017,-0.000000,-0.000000,-0.031460,-0.001603,-0.000000,-139.714661,0.000208,0.000000
0.350000,0.001488,-139.625702,-0.000004,0.000000,0.000008,0.006618,0.000337,0.000083,-139.625702,0.000295,0.000000
0.590000,-0.016754,-139.670181,0.000000,0.000135,0.003417,-0.074526,-0.003797,0.034166,-139.670181,0.004284,0.000000
0.830000,0.002235,-139.625702,0.000125,0.000277,0.007033,0.009944,0.000507,0.070331,-139.625702,0.008290,0.000000
1.070000,-0.028305,-139.625702,0.000280,0.000446,0.011326,-0.125907,-0.006414,0.113259,-139.625702,0.012280,0.000000
1.310000,-0.026810,-139.714661,0.000448,0.000601,0.015254,-0.119255,-0.006075,0.152543,-139.714661,0.016286,0.000000
1.550000,-0.015640,-139.714661,0.000617,0.000758,0.019244,-0.069571,-0.003544,0.192435,-139.714661,0.020276,0.000000
1.790000,0.000374,-139.759155,0.000789,0.000912,0.023164,0.001663,0.000085,0.231636,-139.759155,0.024282,0.000000
2.030000,0.007072,-139.714661,0.000949,0.001074,0.027283,0.031460,0.001603,0.272827,-139.714661,0.028271,0.000000
2.270000,-0.025322,-139.714661,0.001112,0.001233,0.031307,-0.112638,-0.005738,0.313068,-139.714661,0.032278,0.000000
2.510000,-0.014526,-139.759155,0.001281,0.001384,0.035148,-0.064617,-0.003292,0.351484,-139.759155,0.036267,0.000000
2.750000,-0.008194,-139.759155,0.001462,0.001543,0.039198,-0.036449,-0.001857,0.391983,-139.759155,0.040274,0.000000
2.990000,-0.023460,-139.803635,0.001587,0.001699,0.043144,-0.104357,-0.005316,0.431444,-139.803635,0.044280,0.000000
3.230000,-0.027184,-139.714661,0.001763,0.001861,0.047263,-0.120918,-0.006160,0.472635,-139.714661,0.048270,0.000000
3.470000,-0.006332,-139.803635,0.001914,0.002015,0.051175,-0.028168,-0.001435,0.511748,-139.803635,0.052276,0.000000
3.710000,0.003723,-139.803635,0.002113,0.002174,0.055225,0.016561,0.000844,0.552246,-139.803635,0.056265,0.000000
3.950000,0.030533,-139.759155,0.002264,0.002331,0.059197,0.135817,0.006919,0.591965,-139.759155,0.060272,0.000000
4.190000,0.002235,-139.759155,0.002427,0.002490,0.063255,0.009944,0.000507,0.632554,-139.759155,0.064261,0.000000
4.430000,-0.011543,-139.759155,0.002608,0.002645,0.067192,-0.051347,-0.002616,0.671925,-139.759155,0.068268,0.000000
4.670000,0.006332,-139.803635,0.002751,0.002805,0.071242,0.028168,0.001435,0.712423,-139.803635,0.072257,0.000000
4.910000,-0.002235,-139.848114,0.002897,0.002956,0.075084,-0.009944,-0.000507,0.750844,-139.848114,0.076264,0.000000
5.150000,-0.006706,-139.803635,0.003091,0.003121,0.079264,-0.029831,-0.001520,0.792644,-139.803635,0.080253,0.000000
5.390000,-0.042824,-139.848114,0.003247,0.003276,0.083210,-0.190490,-0.009704,0.832102,-139.848114,0.084259,0.000000
5.630000,0.030907,-139.848114,0.003428,0.003436,0.087286,0.137480,0.007004,0.872861,-139.848114,0.088249,0.000000
5.870000,0.162727,-139.803635,0.003579,0.003586,0.091076,0.723847,0.036875,0.910759,-139.803635,0.092255,0.000000
6.110000,0.368279,-139.892593,0.003760,0.003751,0.095273,1.638185,0.083453,0.952734,-139.892593,0.096245,0.000000
6.350000,0.633408,-139.848114,0.003876,-0.000007,-0.000173,2.817538,0.143532,-0.001733,-139.848114,-0.000026,0.000000
6.590000,0.534355,-139.848114,0.003863,-0.000007,-0.000182,2.376930,0.121087,-0.001821,-139.848114,-0.000026,0.000000
6.830000,0.485947,-139.892593,0.003880,-0.000008,-0.000191,2.161599,0.110117,-0.001908,-139.892593,-0.000026,0.000000
7.070000,0.483337,-139.892593,0.003867,-0.000007,-0.000182,2.149992,0.109526,-0.001821,-139.892593,0.000338,0.000000
7.310000,0.476265,-139.848114,0.003880,-0.000007,-0.000182,2.118532,0.107923,-0.001821,-139.848114,0.000737,0.000000
7.550000,0.593933,-139.892593,0.003911,0.000014,0.000347,2.641946,0.134587,0.003471,-139.892593,0.001136,0.000000
7.790000,0.667290,-139.981552,0.003902,0.000030,0.000763,2.968253,0.151210,0.007630,-139.981552,0.001535,0.000000
8.030001,0.764854,-139.937073,0.003919,0.000045,0.001154,3.402242,0.173318,0.011536,-139.937073,0.001934,0.000000
8.270000,0.850868,-139.892593,0.003949,0.000062,0.001587,3.784851,0.192810,0.015870,-139.892593,0.002333,0.000000
8.510000,0.904495,-139.892593,0.003958,0.000076,0.001943,4.023396,0.204962,0.019428,-139.892593,0.002732,0.000000
8.750000,0.959976,-139.937073,0.003962,0.000088,0.002229,4.270187,0.217534,0.022289,-139.937073,0.003140,0.000000
8.990001,1.083603,-139.937073,0.003962,0.000110,0.002801,4.820107,0.245548,0.028012,-139.937073,0.003538,0.000000
9.230000,1.121582,-139.981552,0.003984,0.000123,0.003131,4.989046,0.254154,0.031309,-139.981552,0.003937,0.000000
9.470000,1.215424,-139.937073,0.003997,0.000140,0.003564,5.406474,0.275419,0.035642,-139.937073,0.004336,0.000000
9.710000,1.267555,-139.981552,0.004027,0.000156,0.003963,5.638367,0.287232,0.039632,-139.981552,0.004735,0.000000
9.950001,1.337563,-139.937073,0.004040,0.000168,0.004275,5.949775,0.303096,0.042754,-139.937073,0.005134,0.000000
10.190001,1.501030,-139.981552,0.004053,0.000186,0.004718,6.676915,0.340138,0.047179,-139.981552,0.005533,0.000000
10.430000,1.537521,-139.981552,0.004074,0.000200,0.005082,6.839237,0.348407,0.050820,-139.981552,0.005932,0.000000
10.670000,1.535660,-140.026031,0.004087,0.000212,0.005394,6.830956,0.347986,0.053942,-140.026031,0.006339,0.000000
10.910001,1.776215,-139.981552,0.004096,0.000231,0.005862,7.900997,0.402496,0.058624,-139.981552,0.006738,0.000000
11.150001,1.934845,-140.026031,0.004122,0.000252,0.006400,8.606620,0.438442,0.064003,-140.026031,0.007137,0.000000
11.390000,1.997406,-140.070511,0.004126,0.000268,0.006808,8.884906,0.452619,0.068079,-140.070511,0.007536,0.000000
11.630000,1.999268,-140.026031,0.004161,0.000280,0.007120,8.893187,0.453041,0.071201,-140.026031,0.007935,0.000000
11.870001,2.141884,-140.026031,0.004165,0.000296,0.007527,9.527575,0.485358,0.075274,-140.026031,0.008334,0.000000
12.110001,2.253227,-140.114990,0.004169,0.000311,0.007901,10.022856,0.510589,0.079006,-140.114990,0.008733,0.000000
12.350000,2.356369,-139.981552,0.004186,0.000326,0.008273,10.481653,0.533961,0.082734,-139.981552,0.009132,0.000000
12.590000,2.424515,-140.070511,0.004199,0.000340,0.008629,10.784781,0.549403,0.086288,-140.070511,0.009539,0.000000
12.830001,2.522820,-140.026031,0.004217,0.000353,0.008976,11.222062,0.571679,0.089759,-140.026031,0.009938,0.000000
13.070001,2.625221,-140.026031,0.004238,0.000370,0.009392,11.677567,0.594884,0.093922,-140.026031,0.010337,0.000000
13.310000,2.867638,-140.070511,0.004238,0.000392,0.009964,12.755889,0.649816,0.099645,-140.070511,0.010736,0.000000
13.550000,2.838219,-140.070511,0.004273,0.000406,0.010320,12.625028,0.643150,0.103199,-140.070511,0.011135,0.000000
13.790001,2.887001,-140.070511,0.004268,0.000419,0.010632,12.842022,0.654204,0.106321,-140.070511,0.011534,0.000000
14.030001,3.012489,-140.070511,0.004299,0.000436,0.011066,13.400222,0.682640,0.110659,-140.070511,0.011933,0.000000
14.270000,3.163300,-140.070511,0.004316,0.000452,0.011482,14.071059,0.716814,0.114822,-140.070511,0.012332,0.000000
14.510000,3.237404,-140.114990,0.004320,0.000467,0.011872,14.400692,0.733606,0.118725,-140.114990,0.012740,0.000000
14.750001,3.217300,-140.070511,0.004329,0.000476,0.012089,14.311267,0.729051,0.120893,-140.070511,0.013139,0.000000
14.990001,3.488380,-140.114990,0.004359,0.000498,0.012662,15.517091,0.790478,0.126616,-140.114990,0.013537,0.000000
15.230000,3.586319,-140.203964,0.004372,0.000516,0.013104,15.952744,0.812672,0.131037,-140.203964,0.013936,0.000000
15.470000,3.628395,-140.070511,0.004389,0.000527,0.013381,16.139908,0.822206,0.133815,-140.070511,0.014335,0.000000
15.710001,3.805275,-140.159470,0.004398,0.000546,0.013867,16.926708,0.862288,0.138671,-140.159470,0.014734,0.000000
15.950001,3.978798,-140.159470,0.004415,0.000562,0.014283,17.698578,0.901608,0.142834,-140.159470,0.015133,0.000000
16.190001,4.125885,-140.159470,0.004432,0.000580,0.014734,18.352854,0.934939,0.147342,-140.159470,0.015532,0.000000
16.430000,3.956085,-140.248444,0.004437,0.000585,0.014856,17.597546,0.896462,0.148557,-140.248444,0.015940,0.000000
16.670000,4.130356,-140.203964,0.004445,0.000600,0.015237,18.372740,0.935952,0.152372,-140.203964,0.016339,0.000000
16.910002,4.519859,-140.159470,0.004467,0.000622,0.015801,20.105339,1.024215,0.158008,-140.159470,0.016738,0.000000
17.150002,4.717216,-140.159470,0.004467,0.000641,0.016286,20.983227,1.068936,0.162864,-140.159470,0.017136,0.000000
17.390001,4.779030,-140.159470,0.004497,0.000657,0.016694,21.258186,1.082944,0.166940,-140.159470,0.017535,0.000000
17.630001,4.962608,-140.248444,0.004523,0.000674,0.017110,22.074785,1.124543,0.171104,-140.248444,0.017934,0.000000
17.870001,5.089211,-140.159470,0.004531,0.000688,0.017474,22.637939,1.153232,0.174745,-140.159470,0.018333,0.000000
18.110001,5.256783,-140.248444,0.004549,0.000705,0.017900,23.383337,1.191204,0.178995,-140.248444,0.018732,0.000000
18.350000,5.285828,-140.292923,0.004557,0.000716,0.018177,23.512535,1.197786,0.181770,-140.292923,0.019140,0.000000
18.590000,5.477974,-140.248444,0.004562,0.000730,0.018550,24.367245,1.241327,0.185501,-140.248444,0.019539,0.000000
18.830002,5.485046,-140.248444,0.004570,0.000742,0.018854,24.398705,1.242929,0.188537,-140.248444,0.019938,0.000000
19.070002,6.177658,-140.203964,0.004605,0.000769,0.019539,27.479595,1.399877,0.195388,-140.203964,0.020337,0.000000
19.310001,6.019775,-140.292923,0.004635,0.000780,0.019807,26.777298,1.364101,0.198075,-140.292923,0.020736,0.000000
19.550001,6.252502,-140.248444,0.004648,0.000799,0.020302,27.812519,1.416837,0.203018,-140.248444,0.021134,0.000000
19.790001,6.471458,-140.248444,0.004639,0.000817,0.020744,28.786486,1.466453,0.207443,-140.248444,0.021533,0.000000
20.030001,6.547050,-140.248444,0.004669,0.000830,0.021074,29.122734,1.483583,0.210735,-140.248444,0.021932,0.000000
20.270000,6.664352,-140.203964,0.004665,0.000844,0.021447,29.644520,1.510164,0.214467,-140.203964,0.022340,0.000000
20.510000,6.803619,-140.292923,0.004691,0.000857,0.021759,30.264011,1.541722,0.217586,-140.292923,0.022739,0.000000
20.750002,6.891869,-140.337402,0.004674,0.000871,0.022114,30.656563,1.561720,0.221144,-140.337402,0.023138,0.000000
20.990002,7.569962,-140.292923,0.004734,0.000898,0.022799,33.672871,1.715378,0.227995,-140.292923,0.023537,0.000000
21.230001,7.343925,-140.337402,0.004721,0.000907,0.023034,32.667412,1.664157,0.230337,-140.337402,0.023936,0.000000
21.470001,7.517456,-140.292923,0.004743,0.000923,0.023450,33.439316,1.703480,0.234497,-140.292923,0.024335,0.000000
21.710001,7.743484,-140.337402,0.004764,0.000941,0.023901,34.444740,1.754699,0.239009,-140.337402,0.024733,0.000000
21.950001,7.917381,-140.381882,0.004781,0.000959,0.024352,35.218269,1.794104,0.243516,-140.381882,0.025132,0.000000
22.190001,7.911797,-140.292923,0.004794,0.000970,0.024638,35.193428,1.792839,0.246378,-140.292923,0.025540,0.000000
22.430000,8.039894,-140.337402,0.004773,0.000983,0.024976,35.763237,1.821866,0.249761,-140.337402,0.025939,0.000000
22.670002,8.463654,-140.292923,0.004816,0.001005,0.025531,37.648212,1.917891,0.255310,-140.292923,0.026338,0.000000
22.910002,8.744423,-140.337402,0.004829,0.001022,0.025965,38.897137,1.981515,0.259648,-140.337402,0.026736,0.000000
23.150002,8.630478,-140.337402,0.004855,0.001036,0.026312,38.390282,1.955694,0.263118,-140.337402,0.027135,0.000000
23.390001,8.855759,-140.292923,0.004850,0.001052,0.026719,39.392384,2.006744,0.267195,-140.292923,0.027534,0.000000
23.630001,8.819267,-140.426361,0.004863,0.001064,0.027031,39.230061,1.998475,0.270313,-140.426361,0.027933,0.000000
23.870001,9.205788,-140.381882,0.004876,0.001084,0.027534,40.949390,2.086061,0.275344,-140.381882,0.028341,0.000000
24.110001,9.213982,-140.426361,0.004881,0.001098,0.027881,40.985836,2.087918,0.278814,-140.426361,0.028740,0.000000
24.350000,9.321968,-140.426361,0.004932,0.001109,0.028168,41.466187,2.112388,0.281676,-140.426361,0.029139,0.000000
24.590002,9.591194,-140.381882,0.004945,0.001127,0.028618,42.663761,2.173396,0.286183,-140.381882,0.029538,0.000000
24.830002,10.224976,-140.470840,0.004932,0.001151,0.029243,45.482964,2.317013,0.292429,-140.470840,0.029937,0.000000
25.070002,10.099113,-140.426361,0.004954,0.001165,0.029599,44.923100,2.288492,0.295986,-140.426361,0.030336,0.000000
25.310001,10.020538,-140.426361,0.004967,0.001178,0.029919,44.573582,2.270686,0.299192,-140.426361,0.030734,0.000000
25.550001,10.156082,-140.470840,0.004993,0.001193,0.030309,45.176510,2.301401,0.303094,-140.470840,0.031133,0.000000
25.790001,10.545959,-140.470840,0.005010,0.001212,0.030778,46.910770,2.389749,0.307780,-140.470840,0.031541,0.000000
26.030001,10.621552,-140.470840,0.005027,0.001226,0.031151,47.247021,2.406878,0.311508,-140.470840,0.031940,0.000000
26.270000,10.399986,-140.470840,0.005010,0.001233,0.031324,46.261448,2.356671,0.313242,-140.470840,0.032339,0.000000
26.510002,10.929878,-140.470840,0.005027,0.001257,0.031923,48.618526,2.476746,0.319226,-140.470840,0.032738,0.000000
26.750002,11.308205,-140.515320,0.005057,0.001276,0.032399,50.301407,2.562476,0.323995,-140.515320,0.033137,0.000000
26.990002,11.271713,-140.470840,0.005066,0.001289,0.032738,50.139084,2.554207,0.327378,-140.470840,0.033536,0.000000
27.230001,11.353638,-140.515320,0.005066,0.001304,0.033111,50.503502,2.572771,0.331106,-140.515320,0.033935,0.000000
27.470001,11.348419,-140.470840,0.005126,0.001316,0.033414,50.480289,2.571589,0.334142,-140.470840,0.034334,0.000000
27.710001,11.732712,-140.470840,0.005118,0.001335,0.033908,52.189709,2.658670,0.339085,-140.470840,0.034741,0.000000
27.950001,11.924858,-140.559799,0.005118,0.001349,0.034273,53.044418,2.702211,0.342730,-140.559799,0.035140,0.000000
28.190001,11.976990,-140.515320,0.005131,0.001363,0.034628,53.276310,2.714025,0.346284,-140.515320,0.035539,0.000000
28.430002,12.165031,-140.559799,0.005157,0.001379,0.035036,54.112762,2.756635,0.350360,-140.559799,0.035938,0.000000
28.670002,12.505386,-140.604294,0.005178,0.001399,0.035530,55.626736,2.833761,0.355303,-140.604294,0.036337,0.000000
28.910002,12.571663,-140.515320,0.005191,0.001414,0.035903,55.921551,2.848780,0.359031,-140.515320,0.036736,0.000000
29.150002,12.710930,-140.559799,0.005187,0.001431,0.036337,56.541039,2.880338,0.363369,-140.559799,0.037135,0.000000
29.390001,12.844986,-140.470840,0.005226,0.001444,0.036675,57.137352,2.910715,0.366749,-140.470840,0.037534,0.000000
29.630001,13.089264,-140.648773,0.005213,0.001461,0.037109,58.223953,2.966070,0.371086,-140.648773,0.037941,0.000000
29.870001,13.176773,-140.559799,0.005243,0.001478,0.037542,58.613213,2.985899,0.375424,-140.559799,0.038340,0.000000
30.110001,13.068787,-140.604294,0.005260,0.001487,0.037776,58.132866,2.961429,0.377763,-140.604294,0.038739,0.000000
30.350002,13.687294,-140.648773,0.005269,0.001509,0.038340,60.884125,3.101585,0.383402,-140.648773,0.039138,0.000000
30.590002,13.718201,-140.604294,0.005277,0.001524,0.038704,61.021603,3.108589,0.387043,-140.604294,0.039537,0.000000
30.830002,13.953911,-140.604294,0.005295,0.001541,0.039147,62.070095,3.162001,0.391468,-140.604294,0.039936,0.000000
31.070002,14.055939,-140.604294,0.005325,0.001558,0.039563,62.523937,3.185121,0.395627,-140.604294,0.040335,0.000000
31.310001,13.931572,-140.604294,0.005342,0.001569,0.039841,61.970726,3.156940,0.398406,-140.604294,0.040734,0.000000
31.550001,14.201912,-140.648773,0.005333,0.001586,0.040283,63.173260,3.218199,0.402826,-140.648773,0.041141,0.000000
31.790001,14.307297,-140.559799,0.005364,0.001599,0.040612,63.642033,3.242080,0.406123,-140.559799,0.041540,0.000000
32.030003,14.450661,-140.648773,0.005372,0.001613,0.040976,64.279747,3.274567,0.409764,-140.648773,0.041939,0.000000
32.270000,14.896759,-140.693253,0.005402,0.001633,0.041488,66.264091,3.375654,0.414881,-140.693253,0.042338,0.000000
32.510002,15.304504,-140.604294,0.005398,0.001653,0.041982,68.077835,3.468050,0.419824,-140.604294,0.042737,0.000000
32.750000,15.323502,-140.693253,0.005420,0.001668,0.042355,68.162338,3.472355,0.423552,-140.693253,0.043136,0.000000
32.990002,15.222954,-140.693253,0.005428,0.001681,0.042694,67.715080,3.449571,0.426936,-140.693253,0.043535,0.000000
33.230003,15.383820,-140.693253,0.005441,0.001696,0.043066,68.430649,3.486023,0.430664,-140.693253,0.043934,0.000000
33.470001,15.346588,-140.737732,0.005458,0.001709,0.043414,68.265030,3.477587,0.434135,-140.737732,0.044341,0.000000
33.710003,15.645973,-140.648773,0.005463,0.001726,0.043830,69.596764,3.545428,0.438298,-140.648773,0.044740,0.000000
33.950001,15.733482,-140.693253,0.005471,0.001740,0.044194,69.986023,3.565258,0.441939,-140.693253,0.045139,0.000000
34.190002,15.844818,-140.693253,0.005514,0.001756,0.044610,70.481270,3.590487,0.446103,-140.693253,0.045538,0.000000
34.430000,16.290924,-140.693253,0.005506,0.001775,0.045078,72.465652,3.691576,0.450785,-140.693253,0.045937,0.000000
34.670002,16.568336,-140.737732,0.005519,0.001792,0.045521,73.699638,3.754439,0.455206,-140.737732,0.046336,0.000000
34.910000,16.582863,-140.693253,0.005523,0.001807,0.045902,73.764259,3.757730,0.459024,-140.693253,0.046735,0.000000
35.150002,16.518814,-140.782211,0.005540,0.001821,0.046258,73.479355,3.743217,0.462579,-140.782211,0.047134,0.000000
35.390003,16.866234,-140.782211,0.005553,0.001839,0.046717,75.024757,3.821943,0.467173,-140.782211,0.047541,0.000000
35.630001,16.995453,-140.782211,0.005583,0.001853,0.047073,75.599548,3.851225,0.470731,-140.782211,0.047940,0.000000
35.870003,17.028961,-140.871170,0.005592,0.001867,0.047429,75.748604,3.858818,0.474285,-140.871170,0.048339,0.000000
36.110001,16.971245,-140.737732,0.005588,0.001880,0.047749,75.491867,3.845739,0.477495,-140.737732,0.048738,0.000000
36.350002,17.524963,-140.782211,0.005609,0.001902,0.048305,77.954933,3.971214,0.483047,-140.782211,0.049137,0.000000
36.590000,17.793816,-140.782211,0.005631,0.001917,0.048695,79.150848,4.032136,0.486949,-140.782211,0.049536,0.000000
36.830002,17.585663,-140.782211,0.005635,0.001927,0.048938,78.224937,3.984968,0.489376,-140.782211,0.049935,0.000000
37.070004,17.966972,-140.826691,0.005670,0.001946,0.049423,79.921082,4.071374,0.494232,-140.826691,0.050343,0.000000
37.310001,18.153900,-140.826691,0.005665,0.001961,0.049805,80.752579,4.113732,0.498047,-140.826691,0.050741,0.000000
37.550003,18.572075,-140.826691,0.005683,0.001980,0.050299,82.612717,4.208492,0.502990,-140.826691,0.051140,0.000000
37.790001,18.006813,-140.871170,0.005687,0.001987,0.050464,80.098305,4.080402,0.504640,-140.871170,0.051539,0.000000
38.030003,18.238800,-140.782211,0.005704,0.002004,0.050889,81.130234,4.132971,0.508891,-140.782211,0.051938,0.000000
38.270000,18.774277,-140.871170,0.005721,0.002021,0.051340,83.512154,4.254312,0.513398,-140.871170,0.052337,0.000000
38.510002,19.221497,-140.871170,0.005747,0.002042,0.051860,85.501488,4.355653,0.518603,-140.871170,0.052736,0.000000
38.750000,19.265060,-140.871170,0.005747,0.002057,0.052250,85.695267,4.365525,0.522505,-140.871170,0.053135,0.000000
38.990002,19.453850,-140.915649,0.005760,0.002075,0.052701,86.535049,4.408306,0.527013,-140.915649,0.053543,0.000000
39.230003,19.459808,-140.826691,0.005777,0.002087,0.053005,86.561554,4.409656,0.530048,-140.826691,0.053942,0.000000
39.470001,19.793457,-140.915649,0.005795,0.002107,0.053525,88.045692,4.485261,0.535252,-140.915649,0.054340,0.000000
39.710003,19.652702,-140.871170,0.005808,0.002118,0.053785,87.419586,4.453366,0.537853,-140.871170,0.054739,0.000000
39.950001,19.599075,-140.826691,0.005790,0.002129,0.054072,87.181038,4.441214,0.540718,-140.826691,0.055138,0.000000
40.190002,19.676529,-140.915649,0.005812,0.002142,0.054410,87.525574,4.458765,0.544098,-140.915649,0.055537,0.000000
40.430000,20.754921,-140.871170,0.005825,0.002172,0.055164,92.322502,4.703133,0.551645,-140.871170,0.055936,0.000000
40.670002,20.585121,-141.004608,0.005842,0.002184,0.055485,91.567192,4.664655,0.554850,-141.004608,0.056335,0.000000
40.910004,20.686775,-140.871170,0.005864,0.002199,0.055867,92.019371,4.687690,0.558666,-140.871170,0.056743,0.000000
41.150002,20.996223,-140.960129,0.005877,0.002217,0.056309,93.395866,4.757812,0.563090,-140.960129,0.057142,0.000000
41.390003,20.786949,-140.960129,0.005881,0.002229,0.056613,92.464966,4.710390,0.566126,-140.960129,0.057541,0.000000
41.630001,21.080002,-140.915649,0.005890,0.002245,0.057020,93.768532,4.776796,0.570202,-140.915649,0.057940,0.000000
41.870003,21.099739,-141.004608,0.005911,0.002258,0.057350,93.856323,4.781270,0.573499,-141.004608,0.058338,0.000000
42.110001,21.260231,-141.004608,0.005933,0.002273,0.057723,94.570229,4.817637,0.577227,-141.004608,0.058737,0.000000
42.350002,22.102913,-140.960129,0.005928,0.002297,0.058347,98.318665,5.008592,0.583472,-140.960129,0.059136,0.000000
42.590000,21.746925,-140.960129,0.005946,0.002306,0.058572,96.735153,4.927924,0.585724,-140.960129,0.059535,0.000000
42.830002,22.034019,-140.960129,0.005976,0.002324,0.059024,98.012215,4.992980,0.590235,-140.960129,0.059943,0.000000
43.070004,22.315910,-140.960129,0.005963,0.002340,0.059440,99.266129,5.056858,0.594399,-140.960129,0.060341,0.000000
43.310001,22.721794,-140.960129,0.005989,0.002361,0.059960,101.071587,5.148832,0.599599,-140.960129,0.060740,0.000000
43.550003,22.469696,-140.960129,0.005997,0.002371,0.060212,99.950203,5.091706,0.602116,-140.960129,0.061139,0.000000
43.790001,22.610085,-141.049103,0.006015,0.002386,0.060602,100.574677,5.123518,0.606018,-141.049103,0.061538,0.000000
44.030003,23.161568,-141.004608,0.006010,0.002406,0.061114,103.027802,5.248486,0.611136,-141.004608,0.061937,0.000000
44.270000,23.422600,-141.049103,0.006015,0.002423,0.061538,104.188927,5.307637,0.615382,-141.049103,0.062336,0.000000
44.510002,23.381638,-141.049103,0.006049,0.002435,0.061859,104.006721,5.298355,0.618592,-141.049103,0.062735,0.000000
44.750004,23.550697,-141.049103,0.006062,0.002451,0.062249,104.758736,5.336664,0.622494,-141.049103,0.063143,0.000000
44.990002,23.514572,-141.093582,0.006075,0.002464,0.062596,104.598038,5.328478,0.625965,-141.093582,0.063542,0.000000
45.230003,24.114464,-141.049103,0.006075,0.002485,0.063108,107.266495,5.464416,0.631082,-141.049103,0.063941,0.000000
45.470001,24.234367,-141.093582,0.006079,0.002500,0.063498,107.799850,5.491586,0.634984,-141.093582,0.064339,0.000000
45.710003,23.979668,-141.004608,0.006101,0.002509,0.063741,106.666885,5.433870,0.637410,-141.004608,0.064738,0.000000
45.950001,24.525940,-141.138062,0.006114,0.002529,0.064235,109.096832,5.557658,0.642353,-141.138062,0.065137,0.000000
46.190002,25.237915,-141.182541,0.006131,0.002550,0.064782,112.263855,5.718993,0.647819,-141.182541,0.065536,0.000000
46.430000,25.203659,-141.093582,0.006131,0.002564,0.065120,112.111473,5.711231,0.651199,-141.093582,0.065935,0.000000
46.670002,25.089340,-141.093582,0.006131,0.002577,0.065458,111.602959,5.685326,0.654582,-141.093582,0.066343,0.000000
46.910004,25.255791,-141.093582,0.006161,0.002593,0.065857,112.343369,5.723044,0.658572,-141.093582,0.066742,0.000000
47.150002,25.700775,-141.138062,0.006191,0.002612,0.066334,114.322754,5.823879,0.663341,-141.138062,0.067141,0.000000
47.390003,25.796104,-141.182541,0.006191,0.002625,0.066681,114.746803,5.845481,0.666811,-141.182541,0.067540,0.000000
47.630001,25.474373,-141.138062,0.006213,0.002637,0.066967,113.315666,5.772575,0.669673,-141.138062,0.067938,0.000000
47.870003,26.308861,-141.138062,0.006213,0.002659,0.067531,117.027657,5.961673,0.675309,-141.138062,0.068337,0.000000
48.110001,26.655540,-141.182541,0.006230,0.002675,0.067956,118.569763,6.040232,0.679559,-141.182541,0.068736,0.000000
48.350002,26.670059,-141.138062,0.006217,0.002689,0.068294,118.634346,6.043522,0.682943,-141.138062,0.069135,0.000000
48.590004,26.721443,-141.227020,0.006278,0.002703,0.068667,118.862915,6.055165,0.686671,-141.227020,0.069543,0.000000
48.830002,26.623886,-141.093582,0.006247,0.002716,0.068988,118.428963,6.033059,0.689880,-141.093582,0.069942,0.000000
49.070004,27.101639,-141.182541,0.006256,0.002735,0.069474,120.554108,6.141319,0.694736,-141.182541,0.070341,0.000000
49.310001,27.292664,-141.182541,0.006295,0.002749,0.069820,121.403831,6.184606,0.698203,-141.182541,0.070740,0.000000
49.550003,27.272934,-141.182541,0.006278,0.002763,0.070185,121.316071,6.180135,0.701848,-141.182541,0.071139,0.000000
49.790001,27.712334,-141.227020,0.006299,0.002782,0.070653,123.270615,6.279705,0.706530,-141.227020,0.071538,0.000000
50.030003,28.199020,-141.182541,0.006308,0.002798,0.071078,125.435509,6.389989,0.710781,-141.182541,0.071936,0.000000
50.270004,28.407921,-141.227020,0.006334,0.002816,0.071538,126.364746,6.437326,0.715375,-141.227020,0.072344,0.000000
50.510002,28.589264,-141.227020,0.006355,0.002830,0.071884,127.171394,6.478420,0.718842,-141.227020,0.072743,0.000000
50.750004,28.613472,-141.227020,0.006338,0.002842,0.072196,127.279083,6.483905,0.721965,-141.227020,0.073142,0.000000
50.990002,28.917702,-141.271500,0.006368,0.002860,0.072656,128.632355,6.552845,0.726564,-141.271500,0.073541,0.000000
51.230003,29.258423,-141.227020,0.006359,0.002878,0.073090,130.147964,6.630054,0.730897,-141.227020,0.073940,0.000000
51.470001,28.918076,-141.271500,0.006377,0.002886,0.073298,128.634018,6.552930,0.732979,-141.271500,0.074339,0.000000
51.710003,29.779373,-141.271500,0.006398,0.002910,0.073922,132.465271,6.748102,0.739224,-141.271500,0.074738,0.000000
51.950001,29.792030,-141.271500,0.006416,0.002926,0.074313,132.521576,6.750970,0.743126,-141.271500,0.075137,0.000000
52.190002,30.125679,-141.315979,0.006424,0.002941,0.074703,134.005707,6.826576,0.747029,-141.315979,0.075544,0.000000
52.430004,30.345375,-141.271500,0.006428,0.002958,0.075137,134.982971,6.876360,0.751366,-141.271500,0.075943,0.000000
52.670002,30.148766,-141.360458,0.006437,0.002969,0.075405,134.108414,6.831808,0.754053,-141.360458,0.076342,0.000000
52.910004,30.549805,-141.315979,0.006441,0.002985,0.075830,135.892319,6.922685,0.758304,-141.315979,0.076741,0.000000
53.150002,30.613487,-141.271500,0.006433,0.003000,0.076194,136.175598,6.937116,0.761945,-141.271500,0.077140,0.000000
53.390003,30.719238,-141.360458,0.006472,0.003012,0.076498,136.645996,6.961079,0.764980,-141.360458,0.077539,0.000000
53.630001,31.377968,-141.271500,0.006467,0.003035,0.077079,139.576172,7.110349,0.770790,-141.271500,0.077938,0.000000
53.870003,32.072067,-141.315979,0.006489,0.003054,0.077573,142.663681,7.267634,0.775733,-141.315979,0.078337,0.000000
54.110004,32.082863,-141.360458,0.006515,0.003068,0.077938,142.711700,7.270081,0.779378,-141.360458,0.078744,0.000000
54.350002,32.016586,-141.315979,0.006497,0.003082,0.078284,142.416885,7.255062,0.782845,-141.315979,0.079143,0.000000
54.590004,32.134254,-141.404938,0.006515,0.003095,0.078614,142.940308,7.281726,0.786142,-141.404938,0.079542,0.000000
54.830002,32.358795,-141.404938,0.006515,0.003112,0.079039,143.939102,7.332608,0.790388,-141.404938,0.079941,0.000000
55.070004,32.606049,-141.404938,0.006515,0.003128,0.079446,145.038940,7.388636,0.794465,-141.404938,0.080340,0.000000
55.310001,32.604561,-141.404938,0.006541,0.003138,0.079716,145.032333,7.388299,0.797156,-141.404938,0.080739,0.000000
55.550003,32.998901,-141.404938,0.006566,0.003158,0.080210,146.786438,7.477658,0.802099,-141.404938,0.081138,0.000000
55.790001,33.515381,-141.404938,0.006558,0.003177,0.080687,149.083862,7.594694,0.806868,-141.404938,0.081536,0.000000
56.030003,33.903023,-141.360458,0.006575,0.003192,0.081086,150.808182,7.682535,0.810857,-141.360458,0.081944,0.000000
56.270004,34.026649,-141.404938,0.006597,0.003208,0.081476,151.358093,7.710549,0.814759,-141.404938,0.082343,0.000000
56.510002,34.137619,-141.449417,0.006618,0.003223,0.081866,151.851715,7.735695,0.818661,-141.449417,0.082742,0.000000
56.750004,34.567337,-141.404938,0.006605,0.003240,0.082309,153.763199,7.833070,0.823086,-141.404938,0.083141,0.000000
56.990002,34.549835,-141.538391,0.006614,0.003253,0.082638,153.685349,7.829104,0.826379,-141.538391,0.083540,0.000000
57.230003,34.756500,-141.360458,0.006618,0.003266,0.082968,154.604630,7.875936,0.829675,-141.360458,0.083939,0.000000
57.470001,34.908424,-141.493912,0.006627,0.003282,0.083375,155.280426,7.910362,0.833752,-141.493912,0.084338,0.000000
57.710003,35.696365,-141.449417,0.006648,0.003303,0.083887,158.785370,8.088912,0.838869,-141.449417,0.084737,0.000000
57.950005,35.897820,-141.404938,0.006657,0.003316,0.084216,159.681473,8.134562,0.842162,-141.404938,0.085144,0.000000
58.190002,35.752220,-141.449417,0.006653,0.003326,0.084485,159.033813,8.101569,0.844853,-141.449417,0.085543,0.000000
58.430004,36.290298,-141.493912,0.006687,0.003345,0.084962,161.427307,8.223499,0.849622,-141.493912,0.085942,0.000000
58.670002,36.545380,-141.449417,0.006666,0.003360,0.085335,162.561966,8.281301,0.853350,-141.449417,0.086341,0.000000
58.910004,37.359009,-141.493912,0.006700,0.003381,0.085873,166.181168,8.465672,0.858728,-141.493912,0.086740,0.000000
59.150002,36.787788,-141.493912,0.006696,0.003387,0.086029,163.640259,8.336232,0.860288,-141.493912,0.087139,0.000000
59.390003,37.150108,-141.449417,0.006696,0.003404,0.086454,165.251938,8.418335,0.864538,-141.449417,0.087538,0.000000
59.630001,38.031517,-141.493912,0.006722,0.003425,0.086992,169.172638,8.618065,0.869916,-141.493912,0.087937,0.000000
59.870003,38.863022,-141.493912,0.006717,0.003444,0.087477,172.871353,8.806487,0.874772,-141.493912,0.088344,0.000000
60.110004,39.025002,-141.538391,0.006730,0.003458,0.087824,173.591873,8.843192,0.878239,-141.538391,0.088743,0.000000
60.350002,39.515793,-141.538391,0.006748,0.003475,0.088258,175.775024,8.954407,0.882577,-141.538391,0.089142,0.000000
60.590004,39.559731,-141.538391,0.006743,0.003486,0.088553,175.970474,8.964363,0.885525,-141.538391,0.089541,0.000000
60.830002,40.316391,-141.493912,0.006760,0.003505,0.089029,179.336258,9.135824,0.890294,-141.493912,0.089940,0.000000
61.070004,40.244896,-141.582870,0.006773,0.003516,0.089316,179.018234,9.119624,0.893156,-141.582870,0.090339,0.000000
61.310001,40.460876,-141.582870,0.006782,0.003528,0.089610,179.978973,9.168566,0.896104,-141.582870,0.090738,0.000000
61.550003,40.681694,-141.538391,0.006773,0.003542,0.089966,180.961212,9.218604,0.899662,-141.538391,0.091137,0.000000
61.790005,42.522697,-141.627350,0.006821,0.003572,0.090721,189.150406,9.635780,0.907205,-141.627350,0.091544,0.000000
62.030003,42.654518,-141.582870,0.006829,0.003584,0.091041,189.736771,9.665652,0.910415,-141.582870,0.091943,0.000000
62.270004,43.208984,-141.671829,0.006821,0.003600,0.091449,192.203156,9.791296,0.914491,-141.671829,0.092342,0.000000
62.510002,43.782433,-141.627350,0.006838,0.003616,0.091857,194.753983,9.921242,0.918568,-141.627350,0.092741,0.000000
62.750004,44.057991,-141.627350,0.006847,0.003631,0.092221,195.979736,9.983684,0.922209,-141.627350,0.093140,0.000000
62.990002,44.501488,-141.627350,0.006855,0.003643,0.092542,197.952499,10.084182,0.925418,-141.627350,0.093539,0.000000
63.230003,44.842209,-141.627350,0.006873,0.003657,0.092897,199.468109,10.161390,0.928972,-141.627350,0.093938,0.000000
63.470001,45.280121,-141.627350,0.006885,0.003671,0.093236,201.416031,10.260622,0.932356,-141.627350,0.094346,0.000000
63.710003,47.021332,-141.627350,0.006894,0.003698,0.093938,209.161331,10.655186,0.939381,-141.627350,0.094745,0.000000
63.950005,47.088730,-141.627350,0.006890,0.003710,0.094233,209.461136,10.670458,0.942329,-141.627350,0.095144,0.000000
64.190002,47.520309,-141.671829,0.006907,0.003723,0.094571,211.380890,10.768256,0.945709,-141.671829,0.095542,0.000000
64.430000,48.389801,-141.671829,0.006916,0.003744,0.095100,215.248581,10.965286,0.951000,-141.671829,0.095941,0.000000
64.670006,49.399673,-141.627350,0.006942,0.003760,0.095516,219.740723,11.194125,0.955164,-141.627350,0.096340,0.000000
64.910004,49.478615,-141.716309,0.006959,0.003770,0.095768,220.091873,11.212015,0.957677,-141.716309,0.096739,0.000000
65.150002,50.143677,-141.671829,0.006950,0.003785,0.096149,223.050217,11.362720,0.961492,-141.671829,0.097138,0.000000
65.389999,51.397453,-141.716309,0.006959,0.003807,0.096704,228.627289,11.646830,0.967044,-141.716309,0.097545,0.000000
65.630005,52.168633,-141.760788,0.006989,0.003823,0.097095,232.057663,11.821581,0.970947,-141.760788,0.097944,0.000000
65.870003,52.678413,-141.716309,0.006980,0.003837,0.097459,234.325287,11.937099,0.974588,-141.716309,0.098343,0.000000
66.110001,53.388527,-141.627350,0.007002,0.003852,0.097840,237.484024,12.098013,0.978403,-141.627350,0.098742,0.000000
66.350006,53.971291,-141.671829,0.007002,0.003867,0.098231,240.076294,12.230070,0.982309,-141.671829,0.099141,0.000000
66.590004,55.133835,-141.805267,0.007011,0.003884,0.098664,245.247543,12.493505,0.986643,-141.805267,0.099540,0.000000
66.830002,55.811928,-141.716309,0.007036,0.003899,0.099029,248.263855,12.647163,0.990287,-141.716309,0.099939,0.000000
67.070000,56.281487,-141.671829,0.007041,0.003909,0.099297,250.352554,12.753568,0.992975,-141.671829,0.100338,0.000000
67.310005,57.434357,-141.805267,0.007058,0.003928,0.099774,255.480774,13.014812,0.997744,-141.805267,0.100746,0.000000
67.550003,59.020660,-141.805267,0.007049,0.003950,0.100329,262.537018,13.374272,1.003292,-141.805267,0.101145,0.000000
67.790001,59.705826,-141.849747,0.007088,0.003963,0.100659,265.584778,13.529533,1.006589,-141.849747,0.101543,0.000000
68.030006,60.285614,-141.805267,0.007097,0.003978,0.101032,268.163818,13.660915,1.010317,-141.805267,0.101942,0.000000
68.270004,61.209839,-141.760788,0.007071,0.003991,0.101379,272.274963,13.870348,1.013788,-141.760788,0.102341,0.000000
68.510002,62.626717,-141.760788,0.007088,0.004012,0.101916,278.577545,14.191417,1.019162,-141.760788,0.102740,0.000000
68.750000,63.332741,-141.760788,0.007097,0.004024,0.102203,281.718109,14.351404,1.022028,-141.760788,0.103139,0.000000
68.990005,63.880119,-141.849747,0.007123,0.004036,0.102506,284.152954,14.475442,1.025063,-141.849747,0.103538,0.000000
69.230003,65.597511,-141.849747,0.007127,0.004059,0.103087,291.792297,14.864609,1.030873,-141.849747,0.103946,0.000000
69.470001,66.782387,-141.849747,0.007144,0.004075,0.103504,297.062897,15.133105,1.035036,-141.849747,0.104345,0.000000
69.710007,67.422874,-141.760788,0.007148,0.004078,0.103590,299.911926,15.278242,1.035903,-141.760788,0.104683,0.000000
69.950005,66.717598,-141.805267,0.007179,0.004078,0.103573,296.774689,15.118423,1.035729,-141.805267,0.103790,0.000000
70.190002,66.181007,-141.938721,0.007179,0.004077,0.103564,294.387817,14.996830,1.035642,-141.938721,0.103573,0.000000
70.430000,65.661186,-141.760788,0.007200,0.004077,0.103555,292.075531,14.879038,1.035555,-141.760788,0.103573,0.000000
70.670006,65.204659,-141.894241,0.007183,0.004077,0.103555,290.044800,14.775586,1.035555,-141.894241,0.103573,0.000000
70.910004,64.808815,-141.894241,0.007187,0.004077,0.103555,288.283997,14.685887,1.035555,-141.894241,0.103573,0.000000
71.150002,64.436821,-141.849747,0.007205,0.004077,0.103547,286.629303,14.601592,1.035468,-141.849747,0.103573,0.000000
71.390007,64.109138,-141.894241,0.007200,0.004077,0.103547,285.171692,14.527338,1.035468,-141.894241,0.103573,0.000000
71.630005,63.814583,-141.894241,0.007200,0.004077,0.103547,283.861450,14.460591,1.035468,-141.894241,0.103573,0.000000
71.870003,63.520790,-141.938721,0.007205,0.004077,0.103547,282.554596,14.394017,1.035468,-141.938721,0.103573,0.000000
72.110001,63.278740,-141.894241,0.007213,0.004077,0.103547,281.477905,14.339168,1.035468,-141.894241,0.103573,0.000000
72.350006,63.044884,-141.894241,0.007217,0.004077,0.103547,280.437653,14.286175,1.035468,-141.894241,0.103573,0.000000
72.590004,62.825562,-142.027679,0.007205,0.004077,0.103547,279.462067,14.236476,1.035468,-142.027679,0.103573,0.000000
72.830002,62.624481,-141.894241,0.007222,0.004077,0.103547,278.567596,14.190910,1.035468,-141.894241,0.103573,0.000000
73.070000,62.421539,-141.983200,0.007213,0.004077,0.103547,277.664886,14.144923,1.035468,-141.983200,0.103573,0.000000
73.310005,62.262161,-141.938721,0.007226,0.004077,0.103547,276.955933,14.108808,1.035468,-141.938721,0.103573,0.000000
73.550003,62.070023,-141.894241,0.007187,0.004076,0.103538,276.101257,14.065268,1.035381,-141.894241,0.103573,0.000000
73.790001,61.937828,-142.027679,0.007226,0.004076,0.103538,275.513214,14.035313,1.035381,-142.027679,0.103573,0.000000
74.030006,61.783669,-141.938721,0.007230,0.004076,0.103538,274.827484,14.000379,1.035381,-141.938721,0.103573,0.000000
74.270004,61.631363,-141.983200,0.007226,0.004076,0.103538,274.149994,13.965867,1.035381,-141.983200,0.103573,0.000000
74.510002,61.522263,-142.027679,0.007222,0.004076,0.103538,273.664703,13.941144,1.035381,-142.027679,0.103573,0.000000
74.750000,61.385223,-141.983200,0.007222,0.004076,0.103538,273.055115,13.910090,1.035381,-141.983200,0.103573,0.000000
74.990005,61.256760,-141.983200,0.007213,0.004076,0.103538,272.483673,13.880980,1.035381,-141.983200,0.103573,0.000000
75.230003,61.169624,-141.938721,0.007222,0.004076,0.103538,272.096069,13.861236,1.035381,-141.938721,0.103573,0.000000
75.470001,61.030357,-142.072159,0.007217,0.004076,0.103538,271.476593,13.829677,1.035381,-142.072159,0.103573,0.000000
75.710007,60.927208,-141.983200,0.007235,0.004076,0.103538,271.017761,13.806303,1.035381,-141.983200,0.103573,0.000000
75.950005,60.830391,-142.027679,0.007230,0.004076,0.103538,270.587097,13.784364,1.035381,-142.027679,0.103573,0.000000
76.190002,60.723152,-142.072159,0.007226,0.004076,0.103538,270.110077,13.760062,1.035381,-142.072159,0.103573,0.000000
76.430000,60.643089,-142.027679,0.007226,0.004076,0.103538,269.753937,13.741920,1.035381,-142.027679,0.103573,0.000000
76.670006,60.534729,-142.116638,0.007217,0.004076,0.103538,269.271912,13.717366,1.035381,-142.116638,0.103573,0.000000
76.910004,60.455414,-142.072159,0.007243,0.004076,0.103538,268.919098,13.699392,1.035381,-142.072159,0.103573,0.000000
77.150002,60.367531,-142.072159,0.007235,0.004076,0.103538,268.528198,13.679479,1.035381,-142.072159,0.103573,0.000000
77.390007,60.297523,-142.072159,0.007230,0.004076,0.103538,268.216766,13.663614,1.035381,-142.072159,0.103573,0.000000
77.630005,60.221939,-142.116638,0.007209,0.004076,0.103538,267.880554,13.646486,1.035381,-142.116638,0.103573,0.000000
77.870003,60.136665,-142.072159,0.007230,0.004076,0.103538,267.501251,13.627163,1.035381,-142.072159,0.103573,0.000000
78.110001,60.075592,-142.116638,0.007222,0.004076,0.103538,267.229584,13.613324,1.035381,-142.116638,0.103573,0.000000
78.350006,60.010803,-142.116638,0.007230,0.004076,0.103538,266.941376,13.598642,1.035381,-142.116638,0.103573,0.000000
78.590004,59.922173,-142.161118,0.007226,0.004076,0.103538,266.547150,13.578558,1.035381,-142.161118,0.103573,0.000000
78.830002,59.876373,-142.116638,0.007230,0.004076,0.103538,266.343414,13.568180,1.035381,-142.116638,0.103573,0.000000
79.070007,59.804131,-142.161118,0.007226,0.004076,0.103538,266.022064,13.551809,1.035381,-142.161118,0.103573,0.000000
79.310005,59.741203,-142.161118,0.007235,0.004076,0.103538,265.742157,13.537550,1.035381,-142.161118,0.103573,0.000000
79.550003,59.683861,-142.072159,0.007243,0.004076,0.103538,265.487061,13.524556,1.035381,-142.072159,0.103573,0.000000
79.790001,59.625397,-142.205597,0.007213,0.004076,0.103538,265.227020,13.511308,1.035381,-142.205597,0.103573,0.000000
80.030006,59.575867,-142.116638,0.007248,0.004076,0.103538,265.006683,13.500084,1.035381,-142.116638,0.103573,0.000000
80.270004,59.508095,-142.205597,0.007235,0.004076,0.103538,264.705231,13.484727,1.035381,-142.205597,0.103573,0.000000
80.510002,59.460808,-142.161118,0.007261,0.004076,0.103538,264.494873,13.474011,1.035381,-142.161118,0.103573,0.000000
80.750008,59.409050,-142.205597,0.007243,0.004076,0.103538,264.264648,13.462283,1.035381,-142.205597,0.103573,0.000000
80.990005,59.346115,-142.205597,0.007235,0.004076,0.103538,263.984711,13.448022,1.035381,-142.205597,0.103573,0.000000
81.230003,59.324142,-142.161118,0.007243,0.004076,0.103538,263.886963,13.443043,1.035381,-142.161118,0.103573,0.000000
81.470001,59.266800,-142.205597,0.007239,0.004076,0.103538,263.631897,13.430049,1.035381,-142.205597,0.103573,0.000000
81.710007,59.210571,-142.161118,0.007265,0.004076,0.103538,263.381775,13.417307,1.035381,-142.161118,0.103573,0.000000
81.950005,59.186371,-142.205597,0.007226,0.004076,0.103538,263.274139,13.411824,1.035381,-142.205597,0.103573,0.000000
82.190002,59.111893,-142.250076,0.007222,0.004076,0.103538,262.942841,13.394946,1.035381,-142.250076,0.103573,0.000000
82.430000,59.076515,-142.250076,0.007248,0.004076,0.103538,262.785461,13.386930,1.035381,-142.250076,0.103573,0.000000
82.670006,59.029228,-142.250076,0.007243,0.004076,0.103538,262.575134,13.376215,1.035381,-142.250076,0.103573,0.000000
82.910004,58.972626,-142.250076,0.007243,0.004076,0.103538,262.323334,13.363388,1.035381,-142.250076,0.103573,0.000000
83.150002,58.942093,-142.250076,0.007226,0.004076,0.103538,262.187531,13.356469,1.035381,-142.250076,0.103573,0.000000
83.390007,58.897408,-142.294556,0.007243,0.004076,0.103538,261.988739,13.346343,1.035381,-142.294556,0.103573,0.000000
83.630005,58.865013,-142.294556,0.007252,0.004076,0.103538,261.844666,13.339003,1.035381,-142.294556,0.103573,0.000000
83.870003,58.820694,-142.294556,0.007222,0.004076,0.103538,261.647522,13.328959,1.035381,-142.294556,0.103573,0.000000
84.110001,58.775642,-142.294556,0.007248,0.004076,0.103538,261.447113,13.318751,1.035381,-142.294556,0.103573,0.000000
84.350006,58.756279,-142.383530,0.007239,0.004076,0.103538,261.360992,13.314363,1.035381,-142.383530,0.103573,0.000000
84.590004,58.698563,-142.339050,0.007248,0.004076,0.103538,261.104248,13.301284,1.035381,-142.339050,0.103573,0.000000
84.830002,58.660202,-142.339050,0.007243,0.004076,0.103538,260.933624,13.292592,1.035381,-142.339050,0.103573,0.000000
85.070007,58.643822,-142.383530,0.007239,0.004076,0.103538,260.860748,13.288880,1.035381,-142.383530,0.103573,0.000000
85.310005,58.577164,-142.294556,0.007248,0.004076,0.103538,260.564240,13.273775,1.035381,-142.294556,0.103573,0.000000
85.550003,58.560783,-142.339050,0.007239,0.004076,0.103538,260.491364,13.270063,1.035381,-142.339050,0.103573,0.000000
85.790001,58.518333,-142.428009,0.007256,0.004076,0.103538,260.302551,13.260444,1.035381,-142.428009,0.103573,0.000000
86.030006,58.479980,-142.339050,0.007256,0.004076,0.103538,260.131958,13.251753,1.035381,-142.339050,0.103573,0.000000
86.270004,58.452049,-142.339050,0.007248,0.004076,0.103538,260.007690,13.245424,1.035381,-142.339050,0.103573,0.000000
86.510002,58.419281,-142.339050,0.007239,0.004076,0.103538,259.861938,13.237999,1.035381,-142.339050,0.103573,0.000000
86.750008,58.388000,-142.383530,0.007226,0.004076,0.103538,259.722809,13.230910,1.035381,-142.383530,0.103573,0.000000
86.990005,58.344437,-142.428009,0.007243,0.004076,0.103538,259.529022,13.221038,1.035381,-142.428009,0.103573,0.000000
87.230003,58.323952,-142.428009,0.007235,0.004076,0.103538,259.437897,13.216396,1.035381,-142.428009,0.103573,0.000000
87.470001,58.301987,-142.428009,0.007239,0.004076,0.103538,259.340179,13.211419,1.035381,-142.428009,0.103573,0.000000
87.710007,58.249847,-142.428009,0.007239,0.004076,0.103538,259.108276,13.199604,1.035381,-142.428009,0.103573,0.000000
87.950005,58.235703,-142.428009,0.007230,0.004076,0.103538,259.045349,13.196399,1.035381,-142.428009,0.103573,0.000000
88.190002,58.210007,-142.428009,0.007230,0.004076,0.103538,258.931030,13.190576,1.035381,-142.428009,0.103573,0.000000
88.430008,58.179474,-142.383530,0.007248,0.004076,0.103538,258.795227,13.183657,1.035381,-142.383530,0.103573,0.000000
88.670006,58.164207,-142.472488,0.007239,0.004076,0.103538,258.727325,13.180198,1.035381,-142.472488,0.103573,0.000000
88.910004,58.119148,-142.472488,0.007243,0.004076,0.103538,258.526886,13.169988,1.035381,-142.472488,0.103573,0.000000
89.150002,58.100533,-142.383530,0.007243,0.004076,0.103538,258.444061,13.165769,1.035381,-142.383530,0.103573,0.000000
89.390007,58.058823,-142.472488,0.007261,0.004076,0.103538,258.258545,13.156318,1.035381,-142.472488,0.103573,0.000000
89.630005,58.026428,-142.472488,0.007243,0.004076,0.103538,258.114441,13.148976,1.035381,-142.472488,0.103573,0.000000
89.870003,58.011902,-142.516968,0.007261,0.004076,0.103538,258.049835,13.145685,1.035381,-142.516968,0.103573,0.000000
90.110001,57.977272,-142.516968,0.007252,0.004076,0.103538,257.895782,13.137837,1.035381,-142.516968,0.103573,0.000000
90.350006,57.950462,-142.428009,0.007252,0.004076,0.103538,257.776520,13.131763,1.035381,-142.428009,0.103573,0.000000
90.590004,57.930359,-142.516968,0.007230,0.004076,0.103538,257.687103,13.127208,1.035381,-142.516968,0.103573,0.000000
90.830002,57.906525,-142.516968,0.007265,0.004076,0.103538,257.581085,13.121806,1.035381,-142.516968,0.103573,0.000000
91.070007,57.889397,-142.516968,0.007256,0.004076,0.103538,257.504883,13.117925,1.035381,-142.516968,0.103573,0.000000
91.310005,57.861092,-142.516968,0.007261,0.004076,0.103538,257.378998,13.111511,1.035381,-142.516968,0.103573,0.000000
91.550003,57.845085,-142.516968,0.007243,0.004076,0.103538,257.307800,13.107884,1.035381,-142.516968,0.103573,0.000000
91.790001,57.798904,-142.561447,0.007243,0.004076,0.103538,257.102356,13.097420,1.035381,-142.561447,0.103573,0.000000
92.030006,57.799652,-142.605927,0.007256,0.004076,0.103538,257.105682,13.097589,1.035381,-142.605927,0.103573,0.000000
92.270004,57.760178,-142.561447,0.007235,0.004076,0.103538,256.930115,13.088643,1.035381,-142.561447,0.103573,0.000000
92.510002,57.737839,-142.561447,0.007265,0.004076,0.103538,256.830719,13.083581,1.035381,-142.561447,0.103573,0.000000
92.750008,57.722198,-142.561447,0.007239,0.004076,0.103538,256.761169,13.080037,1.035381,-142.561447,0.103573,0.000000
92.990005,57.688683,-142.605927,0.007269,0.004076,0.103538,256.612091,13.072442,1.035381,-142.605927,0.103573,0.000000
93.230003,57.688316,-142.605927,0.007265,0.004076,0.103538,256.610443,13.072359,1.035381,-142.605927,0.103573,0.000000
93.470001,57.650703,-142.605927,0.007256,0.004076,0.103538,256.443146,13.063836,1.035381,-142.605927,0.103573,0.000000
93.710007,57.627243,-142.650406,0.007261,0.004076,0.103538,256.338776,13.058520,1.035381,-142.650406,0.103573,0.000000
93.950005,57.609001,-142.605927,0.007239,0.004076,0.103538,256.257629,13.054387,1.035381,-142.605927,0.103573,0.000000
94.190002,57.578835,-142.605927,0.007235,0.004076,0.103538,256.123444,13.047551,1.035381,-142.605927,0.103573,0.000000
94.430008,57.574738,-142.561447,0.007261,0.004076,0.103538,256.105225,13.046622,1.035381,-142.561447,0.103573,0.000000
94.670006,57.543831,-142.561447,0.007252,0.004076,0.103538,255.967743,13.039618,1.035381,-142.561447,0.103573,0.000000
94.910004,57.535271,-142.650406,0.007248,0.004076,0.103538,255.929672,13.037679,1.035381,-142.650406,0.103573,0.000000
95.150002,57.515160,-142.605927,0.007265,0.004076,0.103538,255.840210,13.033121,1.035381,-142.605927,0.103573,0.000000
95.390007,57.489464,-142.694885,0.007256,0.004076,0.103538,255.725906,13.027299,1.035381,-142.694885,0.103573,0.000000
95.630005,57.465263,-142.650406,0.007248,0.004076,0.103538,255.618256,13.021815,1.035381,-142.650406,0.103573,0.000000
95.870003,57.436592,-142.694885,0.007256,0.004076,0.103538,255.490723,13.015318,1.035381,-142.694885,0.103573,0.000000
96.110008,57.436592,-142.694885,0.007265,0.004076,0.103538,255.490723,13.015318,1.035381,-142.694885,0.103573,0.000000
96.350006,57.404564,-142.650406,0.007252,0.004076,0.103538,255.348251,13.008060,1.035381,-142.650406,0.103573,0.000000
96.590004,57.389297,-142.694885,0.007261,0.004076,0.103538,255.280350,13.004601,1.035381,-142.694885,0.103573,0.000000
96.830002,57.368073,-142.694885,0.007248,0.004076,0.103538,255.185928,12.999791,1.035381,-142.694885,0.103573,0.000000
97.070007,57.354668,-142.739365,0.007239,0.004076,0.103538,255.126297,12.996754,1.035381,-142.739365,0.103573,0.000000
97.310005,57.345360,-142.783859,0.007261,0.004076,0.103538,255.084900,12.994644,1.035381,-142.783859,0.103573,0.000000
97.550003,57.311844,-142.739365,0.007252,0.004076,0.103538,254.935822,12.987049,1.035381,-142.739365,0.103573,0.000000
97.790001,57.301788,-142.828339,0.007261,0.004076,0.103538,254.891083,12.984771,1.035381,-142.828339,0.103573,0.000000
98.030006,57.286148,-142.739365,0.007248,0.004076,0.103538,254.821518,12.981227,1.035381,-142.739365,0.103573,0.000000
98.270004,57.275726,-142.694885,0.007252,0.004076,0.103538,254.775162,12.978866,1.035381,-142.694885,0.103573,0.000000
98.510002,57.248169,-142.739365,0.007252,0.004076,0.103538,254.652573,12.972620,1.035381,-142.739365,0.103573,0.000000
98.750008,57.234016,-142.739365,0.007239,0.004076,0.103538,254.589615,12.969414,1.035381,-142.739365,0.103573,0.000000
98.990005,57.221733,-142.828339,0.007252,0.004076,0.103538,254.534988,12.966630,1.035381,-142.828339,0.103573,0.000000
99.230003,57.193054,-142.739365,0.007269,0.004076,0.103538,254.407410,12.960131,1.035381,-142.739365,0.103573,0.000000
99.470001,57.183006,-142.783859,0.007252,0.004076,0.103538,254.362717,12.957854,1.035381,-142.783859,0.103573,0.000000
99.710007,57.157310,-142.783859,0.007256,0.004076,0.103538,254.248413,12.952031,1.035381,-142.783859,0.103573,0.000000
99.950005,57.143906,-142.739365,0.007252,0.004076,0.103538,254.188782,12.948995,1.035381,-142.739365,0.103573,0.000000
100.190002,57.122681,-142.828339,0.007252,0.004076,0.103538,254.094376,12.944185,1.035381,-142.828339,0.103573,0.000000
100.200005,57.119331,-142.783859,0.007261,0.004076,0.103538,254.079483,12.943426,1.035381,-142.783859,0.103573,0.000000