File: Data/Automembrane/AutoHeating-15wt-1-3_12152023_165505.csv
Time (sec),S:Load (lbs),S:HL1 (DIM),S:LVDT (in),S:Position (in),Ch:Position (mm),Ch:Load (N),Ch:Stress (MPa),Ch:Strain (mm/mm),Ch:HL1 (DIM),Set Point (),Cycles ()
0.110000,0.003723,-135.133133,0.000000,-0.000000,-0.000000,0.016561,0.000844,-0.000000,-135.133133,0.000208,0.000000
0.350000,0.008568,-135.133133,0.000000,-0.000000,-0.000000,0.038112,0.001941,-0.000000,-135.133133,0.000295,0.000000
0.590000,-0.032021,-135.133133,0.000000,0.000131,0.003322,-0.142435,-0.007256,0.033216,-135.133133,0.004284,0.000000
0.830000,-0.011917,-135.266571,0.000134,0.000287,0.007302,-0.053010,-0.002700,0.073022,-135.266571,0.008291,0.000000
1.070000,0.003357,-135.177612,0.000280,0.000439,0.011144,0.014932,0.000761,0.111439,-135.177612,0.012280,0.000000
1.310000,0.014153,-135.222092,0.000440,0.000593,0.015072,0.062954,0.003207,0.150722,-135.222092,0.016286,0.000000
1.550000,-0.014519,-135.222092,0.000617,0.000758,0.019244,-0.064583,-0.003290,0.192435,-135.222092,0.020276,0.000000
1.790000,-0.001862,-135.177612,0.000802,0.000913,0.023198,-0.008281,-0.000422,0.231984,-135.177612,0.024282,0.000000
2.030000,0.010803,-135.266571,0.000966,0.001070,0.027188,0.048055,0.002448,0.271877,-135.266571,0.028272,0.000000
2.270000,0.019737,-135.222092,0.001112,0.001229,0.031220,0.087796,0.004473,0.312201,-135.222092,0.032278,0.000000
2.510000,-0.006699,-135.222092,0.001276,0.001389,0.035287,-0.029797,-0.001518,0.352873,-135.222092,0.036267,0.000000
2.750000,-0.028671,-135.222092,0.001462,0.001542,0.039173,-0.127536,-0.006497,0.391725,-135.222092,0.040274,0.000000
2.990000,0.001495,-135.222092,0.001608,0.001701,0.043214,0.006652,0.000339,0.432137,-135.222092,0.044263,0.000000
3.230000,0.016388,-135.266571,0.001785,0.001855,0.047116,0.072897,0.003714,0.471163,-135.266571,0.048270,0.000000
3.470000,0.032028,-135.266571,0.001953,0.002018,0.051253,0.142469,0.007258,0.512532,-135.266571,0.052276,0.000000
3.710000,-0.018616,-135.266571,0.002104,0.002172,0.055181,-0.082807,-0.004218,0.551815,-135.266571,0.056265,0.000000
3.950000,0.007080,-135.311050,0.002276,0.002334,0.059284,0.031494,0.001604,0.592836,-135.311050,0.060272,0.000000
4.190000,0.027931,-135.222092,0.002436,0.002484,0.063091,0.124244,0.006329,0.630908,-135.222092,0.064261,0.000000
4.430000,0.017128,-135.311050,0.002617,0.002649,0.067280,0.076189,0.003881,0.672795,-135.311050,0.068268,0.000000
4.670000,-0.006699,-135.266571,0.002742,0.002802,0.071182,-0.029797,-0.001518,0.711818,-135.266571,0.072257,0.000000
4.910000,0.008568,-135.311050,0.002936,0.002964,0.075275,0.038112,0.001941,0.752751,-135.311050,0.076264,0.000000
5.150000,0.026810,-135.355530,0.003074,0.003113,0.079074,0.119255,0.006075,0.790736,-135.355530,0.080253,0.000000
5.390000,0.010429,-135.266571,0.003264,0.003279,0.083280,0.046392,0.002363,0.832798,-135.266571,0.084260,0.000000
5.630000,0.061813,-135.311050,0.003410,0.003430,0.087113,0.274960,0.014007,0.871128,-135.311050,0.088249,0.000000
5.870000,0.277046,-135.355530,0.003579,0.003591,0.091215,1.232363,0.062780,0.912148,-135.355530,0.092255,0.000000
6.110000,0.674744,-135.311050,0.003747,0.000004,0.000112,3.001410,0.152899,0.001124,-135.311050,0.001214,0.000000
6.350000,0.529144,-135.400009,0.003760,-0.000004,-0.000104,2.353751,0.119906,-0.001041,-135.400009,0.000112,0.000000
6.590000,0.499352,-135.355530,0.003764,-0.000004,-0.000104,2.221226,0.113155,-0.001041,-135.355530,0.000112,0.000000
6.830000,0.478127,-135.400009,0.003777,-0.000004,-0.000096,2.126813,0.108345,-0.000958,-135.400009,0.000416,0.000000
7.070000,0.489670,-135.400009,0.003768,-0.000004,-0.000096,2.178160,0.110961,-0.000958,-135.400009,0.000815,0.000000
7.310000,0.574570,-135.400009,0.003768,0.000015,0.000382,2.555814,0.130199,0.003815,-135.400009,0.001214,0.000000
7.550000,0.712349,-135.400009,0.003786,0.000037,0.000928,3.168686,0.161421,0.009277,-135.400009,0.001613,0.000000
7.790000,0.747726,-135.400009,0.003790,0.000048,0.001231,3.326053,0.169437,0.012312,-135.400009,0.002012,0.000000
8.030001,0.771187,-135.488983,0.003798,0.000063,0.001595,3.430410,0.174753,0.015953,-135.488983,0.002419,0.000000
8.270000,0.815872,-135.444489,0.003829,0.000077,0.001951,3.629181,0.184879,0.019511,-135.444489,0.002818,0.000000
8.510000,0.901146,-135.444489,0.003829,0.000094,0.002376,4.008497,0.204203,0.023762,-135.444489,0.003217,0.000000
8.750000,0.984558,-135.444489,0.003854,0.000111,0.002818,4.379533,0.223104,0.028182,-135.444489,0.003616,0.000000
8.990001,1.040413,-135.444489,0.003876,0.000122,0.003104,4.627988,0.235761,0.031044,-135.444489,0.004015,0.000000
9.230000,1.118980,-135.488983,0.003898,0.000137,0.003478,4.977473,0.253565,0.034776,-135.488983,0.004414,0.000000
9.470000,1.270538,-135.444489,0.003898,0.000160,0.004067,5.651637,0.287908,0.040672,-135.444489,0.004813,0.000000
9.710000,1.312988,-135.444489,0.003932,0.000173,0.004388,5.840464,0.297527,0.043878,-135.444489,0.005212,0.000000
9.950001,1.374054,-135.488983,0.003949,0.000185,0.004700,6.112097,0.311365,0.047001,-135.488983,0.005619,0.000000
10.190001,1.527100,-135.444489,0.003954,0.000206,0.005229,6.792878,0.346046,0.052292,-135.444489,0.006018,0.000000
10.430000,1.505135,-135.488983,0.003971,0.000212,0.005394,6.695173,0.341068,0.053939,-135.488983,0.006417,0.000000
10.670000,1.761322,-135.444489,0.004005,0.000237,0.006018,7.834752,0.399121,0.060184,-135.444489,0.006816,0.000000
10.910001,1.825371,-135.444489,0.004005,0.000249,0.006322,8.119655,0.413635,0.063219,-135.444489,0.007215,0.000000
11.150001,1.874153,-135.533463,0.004014,0.000259,0.006573,8.336650,0.424689,0.065732,-135.533463,0.007614,0.000000
11.390000,2.103165,-135.488983,0.004018,0.000284,0.007206,9.355344,0.476584,0.072064,-135.488983,0.008013,0.000000
11.630000,2.197746,-135.488983,0.004036,0.000300,0.007614,9.776064,0.498016,0.076141,-135.488983,0.008412,0.000000
11.870001,2.224556,-135.488983,0.004057,0.000311,0.007900,9.895319,0.504092,0.079002,-135.488983,0.008820,0.000000
12.110001,2.348557,-135.533463,0.004061,0.000327,0.008317,10.446901,0.532191,0.083165,-135.533463,0.009218,0.000000
12.350000,2.347069,-135.577942,0.004092,0.000338,0.008577,10.440284,0.531853,0.085766,-135.577942,0.009617,0.000000
12.590000,2.636398,-135.533463,0.004113,0.000361,0.009158,11.727285,0.597416,0.091576,-135.533463,0.010016,0.000000
12.830001,2.564156,-135.577942,0.004105,0.000367,0.009331,11.405933,0.581046,0.093313,-135.577942,0.010415,0.000000
13.070001,2.711617,-135.533463,0.004135,0.000382,0.009713,12.061872,0.614461,0.097128,-135.533463,0.010814,0.000000
13.310000,2.986427,-135.622421,0.004139,0.000410,0.010415,13.284292,0.676734,0.104153,-135.622421,0.011213,0.000000
13.550000,3.045639,-135.577942,0.004174,0.000427,0.010849,13.547679,0.690152,0.108486,-135.577942,0.011612,0.000000
13.790001,3.054199,-135.533463,0.004178,0.000440,0.011187,13.585756,0.692091,0.111870,-135.533463,0.012020,0.000000
14.030001,3.137238,-135.666901,0.004195,0.000455,0.011569,13.955130,0.710908,0.115685,-135.666901,0.012419,0.000000
14.270000,3.203896,-135.577942,0.004204,0.000469,0.011907,14.251639,0.726013,0.119069,-135.577942,0.012818,0.000000
14.510000,3.352470,-135.577942,0.004221,0.000485,0.012323,14.912533,0.759681,0.123232,-135.577942,0.013216,0.000000
14.750001,3.447800,-135.622421,0.004230,0.000498,0.012661,15.336579,0.781283,0.126612,-135.622421,0.013615,0.000000
14.990001,3.490623,-135.666901,0.004255,0.000514,0.013051,15.527069,0.790987,0.130515,-135.666901,0.014014,0.000000
15.230000,3.749420,-135.666901,0.004251,0.000536,0.013615,16.678253,0.849631,0.136154,-135.666901,0.014413,0.000000
15.470000,3.804901,-135.622421,0.004307,0.000552,0.014014,16.925045,0.862203,0.140143,-135.622421,0.014812,0.000000
15.710001,3.845863,-135.622421,0.004294,0.000566,0.014387,17.107254,0.871485,0.143871,-135.622421,0.015219,0.000000
15.950001,3.880127,-135.711380,0.004307,0.000578,0.014691,17.259666,0.879249,0.146907,-135.711380,0.015618,0.000000
16.190001,4.101685,-135.666901,0.004333,0.000597,0.015176,18.245205,0.929455,0.151763,-135.666901,0.016017,0.000000
16.430000,4.249146,-135.666901,0.004350,0.000613,0.015567,18.901144,0.962870,0.155665,-135.666901,0.016416,0.000000
16.670000,4.289360,-135.622421,0.004368,0.000626,0.015896,19.080027,0.971983,0.158962,-135.622421,0.016815,0.000000
16.910002,4.388039,-135.622421,0.004385,0.000638,0.016217,19.518970,0.994344,0.162168,-135.622421,0.017214,0.000000
17.150002,4.626732,-135.711380,0.004393,0.000657,0.016685,20.580730,1.048432,0.166853,-135.711380,0.017613,0.000000
17.390001,4.920158,-135.666901,0.004424,0.000679,0.017240,21.885958,1.114924,0.172402,-135.666901,0.018012,0.000000
17.630001,4.744400,-135.755859,0.004411,0.000686,0.017431,21.104145,1.075096,0.174310,-135.755859,0.018420,0.000000
17.870001,4.961868,-135.755859,0.004432,0.000704,0.017873,22.071493,1.124375,0.178734,-135.755859,0.018818,0.000000
18.110001,5.166298,-135.711380,0.004454,0.000721,0.018307,22.980841,1.170700,0.183068,-135.711380,0.019217,0.000000
18.350000,5.542763,-135.755859,0.004458,0.000742,0.018853,24.655439,1.256008,0.188533,-135.755859,0.019616,0.000000
18.590000,5.369987,-135.755859,0.004480,0.000751,0.019088,23.886898,1.216857,0.190876,-135.755859,0.020015,0.000000
18.830002,5.696182,-135.800339,0.004480,0.000768,0.019495,25.337885,1.290773,0.194949,-135.800339,0.020414,0.000000
19.070002,6.014931,-135.755859,0.004531,0.000787,0.019998,26.755749,1.363003,0.199979,-135.755859,0.020813,0.000000
19.310001,6.103188,-135.755859,0.004506,0.000804,0.020423,27.148335,1.383002,0.204229,-135.755859,0.021212,0.000000
19.550001,6.146385,-135.800339,0.004531,0.000817,0.020753,27.340487,1.392791,0.207526,-135.800339,0.021620,0.000000
19.790001,6.301659,-135.800339,0.004557,0.000831,0.021099,28.031178,1.427976,0.210993,-135.800339,0.022019,0.000000
20.030001,6.572372,-135.800339,0.004579,0.000849,0.021568,29.235373,1.489321,0.215678,-135.800339,0.022418,0.000000
20.270000,6.750740,-135.755859,0.004592,0.000864,0.021958,30.028791,1.529739,0.219581,-135.755859,0.022816,0.000000
20.510000,6.759308,-135.844818,0.004609,0.000875,0.022227,30.066902,1.531681,0.222268,-135.844818,0.023215,0.000000
20.750002,6.933578,-135.933792,0.004618,0.000890,0.022608,30.842098,1.571171,0.226083,-135.933792,0.023614,0.000000
20.990002,7.299248,-135.844818,0.004635,0.000911,0.023146,32.468674,1.654033,0.231461,-135.844818,0.024013,0.000000
21.230001,7.630661,-135.889313,0.004656,0.000931,0.023649,33.942875,1.729132,0.236492,-135.889313,0.024421,0.000000
21.470001,7.550224,-135.800339,0.004682,0.000943,0.023944,33.585075,1.710905,0.239440,-135.800339,0.024820,0.000000
21.710001,7.785934,-135.844818,0.004682,0.000960,0.024377,34.633568,1.764318,0.243774,-135.844818,0.025219,0.000000
21.950001,7.936378,-135.844818,0.004708,0.000976,0.024802,35.302776,1.798409,0.248024,-135.844818,0.025618,0.000000
22.190001,8.026489,-135.844818,0.004691,0.000989,0.025132,35.703606,1.818828,0.251321,-135.844818,0.026017,0.000000
22.430000,8.192940,-135.800339,0.004725,0.001005,0.025522,36.444016,1.856547,0.255223,-135.800339,0.026416,0.000000
22.670002,8.356415,-135.844818,0.004734,0.001018,0.025869,37.171188,1.893591,0.258690,-135.844818,0.026814,0.000000
22.910002,8.338913,-135.800339,0.004734,0.001031,0.026199,37.093338,1.889625,0.261987,-135.800339,0.027213,0.000000
23.150002,8.926888,-135.933792,0.004773,0.001054,0.026780,39.708778,2.022862,0.267796,-135.933792,0.027621,0.000000
23.390001,8.939545,-135.889313,0.004781,0.001068,0.027135,39.765079,2.025730,0.271354,-135.889313,0.028020,0.000000
23.630001,8.976410,-135.933792,0.004786,0.001082,0.027482,39.929066,2.034084,0.274821,-135.933792,0.028419,0.000000
23.870001,9.200211,-135.933792,0.004812,0.001099,0.027925,40.924580,2.084797,0.279246,-135.933792,0.028818,0.000000
24.110001,9.559174,-135.933792,0.004820,0.001120,0.028436,42.521328,2.166140,0.284363,-135.933792,0.029217,0.000000
24.350000,9.529015,-135.933792,0.004842,0.001133,0.028774,42.387173,2.159306,0.287743,-135.933792,0.029616,0.000000
24.590002,9.596039,-135.889313,0.004863,0.001145,0.029078,42.685314,2.174494,0.290778,-135.889313,0.030015,0.000000
24.830002,9.617638,-135.978271,0.004876,0.001156,0.029373,42.781387,2.179388,0.293727,-135.978271,0.030414,0.000000
25.070002,10.283813,-135.978271,0.004894,0.001184,0.030084,45.744686,2.330345,0.300839,-135.978271,0.030821,0.000000
25.310001,10.188110,-135.889313,0.004907,0.001197,0.030405,45.318977,2.308659,0.304048,-135.889313,0.031220,0.000000
25.550001,10.275993,-135.978271,0.004915,0.001213,0.030821,45.709900,2.328573,0.308212,-135.978271,0.031619,0.000000
25.790001,10.371323,-135.933792,0.004924,0.001224,0.031090,46.133945,2.350175,0.310899,-135.933792,0.032018,0.000000
26.030001,10.758217,-135.978271,0.004954,0.001243,0.031584,47.854939,2.437847,0.315842,-135.978271,0.032417,0.000000
26.270000,10.686348,-135.978271,0.004971,0.001256,0.031896,47.535252,2.421561,0.318964,-135.978271,0.032816,0.000000
26.510002,10.925041,-135.933792,0.004963,0.001271,0.032278,48.597012,2.475650,0.322780,-135.933792,0.033215,0.000000
26.750002,10.872902,-136.022751,0.005006,0.001283,0.032590,48.365082,2.463835,0.325902,-136.022751,0.033614,0.000000
26.990002,11.723030,-135.933792,0.005019,0.001312,0.033319,52.146641,2.656476,0.333188,-135.933792,0.034021,0.000000
27.230001,11.701431,-136.067230,0.005014,0.001327,0.033700,52.050568,2.651582,0.337003,-136.067230,0.034420,0.000000
27.470001,11.497375,-136.022751,0.005044,0.001338,0.033978,51.142879,2.605342,0.339778,-136.022751,0.034819,0.000000
27.710001,11.714836,-136.022751,0.005053,0.001354,0.034394,52.110195,2.654620,0.343941,-136.022751,0.035218,0.000000
27.950001,12.103226,-136.067230,0.005062,0.001373,0.034871,53.837837,2.742630,0.348710,-136.067230,0.035617,0.000000
28.190001,12.074554,-135.978271,0.005075,0.001386,0.035201,53.710300,2.736133,0.352007,-135.978271,0.036016,0.000000
28.430002,12.074554,-136.022751,0.005079,0.001398,0.035504,53.710300,2.736133,0.355042,-136.022751,0.036414,0.000000
28.670002,12.557892,-136.067230,0.005118,0.001418,0.036024,55.860294,2.845659,0.360243,-136.067230,0.036813,0.000000
28.910002,12.875900,-136.111710,0.005131,0.001436,0.036484,57.274864,2.917721,0.364841,-136.111710,0.037221,0.000000
29.150002,12.836052,-136.067230,0.005144,0.001449,0.036813,57.097610,2.908691,0.368134,-136.067230,0.037620,0.000000
29.390001,12.902710,-136.111710,0.005161,0.001464,0.037195,57.394119,2.923796,0.371953,-136.111710,0.038019,0.000000
29.630001,12.973457,-136.067230,0.005178,0.001477,0.037525,57.708820,2.939827,0.375246,-136.067230,0.038418,0.000000
29.870001,13.171562,-136.111710,0.005195,0.001492,0.037897,58.590034,2.984719,0.378974,-136.111710,0.038817,0.000000
30.110001,13.491432,-136.067230,0.005217,0.001511,0.038375,60.012886,3.057202,0.383747,-136.067230,0.039216,0.000000
30.350002,13.424774,-136.156189,0.005204,0.001523,0.038687,59.716377,3.042097,0.386869,-136.156189,0.039615,0.000000
30.590002,13.590851,-136.111710,0.005230,0.001538,0.039068,60.455124,3.079731,0.390684,-136.111710,0.040014,0.000000
30.830002,14.076050,-136.156189,0.005243,0.001559,0.039588,62.613396,3.189678,0.395885,-136.156189,0.040421,0.000000
31.070002,14.111801,-136.200668,0.005282,0.001573,0.039962,62.772427,3.197780,0.399617,-136.200668,0.040820,0.000000
31.310001,14.201172,-136.111710,0.005286,0.001589,0.040369,63.169968,3.218032,0.403693,-136.111710,0.041219,0.000000
31.550001,14.489761,-136.156189,0.005303,0.001606,0.040794,64.453674,3.283427,0.407940,-136.156189,0.041618,0.000000
31.790001,14.516197,-136.200668,0.005316,0.001622,0.041202,64.571274,3.289417,0.412016,-136.200668,0.042017,0.000000
32.030003,14.731056,-136.200668,0.005333,0.001636,0.041549,65.527008,3.338105,0.415487,-136.200668,0.042416,0.000000
32.270000,14.746323,-136.245148,0.005342,0.001649,0.041887,65.594917,3.341565,0.418867,-136.245148,0.042815,0.000000
32.510002,14.900116,-136.156189,0.005346,0.001667,0.042347,66.279030,3.376415,0.423465,-136.156189,0.043214,0.000000
32.750000,15.288498,-136.200668,0.005381,0.001685,0.042797,68.006638,3.464423,0.427973,-136.200668,0.043621,0.000000
32.990002,15.451973,-136.200668,0.005372,0.001700,0.043188,68.733810,3.501467,0.431875,-136.200668,0.044020,0.000000
33.230003,15.434097,-136.200668,0.005398,0.001715,0.043561,68.654297,3.497416,0.435607,-136.200668,0.044419,0.000000
33.470001,15.559959,-136.289627,0.005420,0.001729,0.043916,69.214157,3.525937,0.439161,-136.289627,0.044818,0.000000
33.710003,15.743538,-136.200668,0.005437,0.001745,0.044332,70.030754,3.567537,0.443325,-136.200668,0.045217,0.000000
33.950001,15.979622,-136.245148,0.005437,0.001759,0.044688,71.080910,3.621034,0.446879,-136.245148,0.045616,0.000000
34.190002,15.892860,-136.245148,0.005450,0.001771,0.044991,70.694977,3.601374,0.449914,-136.245148,0.046015,0.000000
34.430000,16.288315,-136.200668,0.005476,0.001791,0.045494,72.454041,3.690985,0.454944,-136.200668,0.046414,0.000000
34.670002,16.796982,-136.245148,0.005497,0.001812,0.046032,74.716705,3.806251,0.460323,-136.245148,0.046821,0.000000
34.910000,16.871078,-136.245148,0.005510,0.001827,0.046414,75.046303,3.823041,0.464138,-136.245148,0.047220,0.000000
35.150002,16.784317,-136.245148,0.005523,0.001840,0.046743,74.660370,3.803381,0.467435,-136.245148,0.047619,0.000000
35.390003,16.973114,-136.245148,0.005527,0.001857,0.047177,75.500183,3.846163,0.471768,-136.245148,0.048018,0.000000
35.630001,17.002899,-136.289627,0.005532,0.001869,0.047472,75.632675,3.852912,0.474717,-136.289627,0.048417,0.000000
35.870003,17.195793,-136.334122,0.005570,0.001884,0.047862,76.490707,3.896622,0.478619,-136.334122,0.048816,0.000000
36.110001,16.930664,-136.245148,0.005566,0.001899,0.048243,75.311356,3.836543,0.482434,-136.245148,0.049215,0.000000
36.350002,17.491829,-136.289627,0.005583,0.001915,0.048634,77.807541,3.963705,0.486340,-136.289627,0.049623,0.000000
36.590000,18.039215,-136.289627,0.005618,0.001937,0.049198,80.242439,4.087745,0.491976,-136.289627,0.050022,0.000000
36.830002,18.093956,-136.289627,0.005635,0.001951,0.049553,80.485939,4.100149,0.495530,-136.289627,0.050420,0.000000
37.070004,18.114807,-136.378601,0.005639,0.001966,0.049943,80.578690,4.104874,0.499432,-136.378601,0.050819,0.000000
37.310001,18.113686,-136.289627,0.005670,0.001979,0.050264,80.573700,4.104620,0.502642,-136.289627,0.051218,0.000000
37.550003,18.511383,-136.289627,0.005670,0.001999,0.050785,82.342743,4.194739,0.507846,-136.289627,0.051617,0.000000
37.790001,18.660332,-136.378601,0.005696,0.002014,0.051166,83.005302,4.228492,0.511661,-136.378601,0.052016,0.000000
38.030003,18.607826,-136.289627,0.005691,0.002028,0.051513,82.771744,4.216593,0.515132,-136.289627,0.052415,0.000000
38.270000,18.874069,-136.423080,0.005704,0.002044,0.051929,83.956055,4.276925,0.519291,-136.423080,0.052822,0.000000
38.510002,19.193565,-136.334122,0.005734,0.002063,0.052398,85.377243,4.349324,0.523977,-136.334122,0.053221,0.000000
38.750000,19.451996,-136.378601,0.005752,0.002079,0.052814,86.526802,4.407885,0.528137,-136.378601,0.053620,0.000000
38.990002,19.144791,-136.378601,0.005756,0.002088,0.053031,85.160278,4.338271,0.530305,-136.378601,0.054019,0.000000
39.230003,19.394279,-136.334122,0.005764,0.002104,0.053447,86.270065,4.394807,0.534469,-136.334122,0.054418,0.000000
39.470001,19.779312,-136.423080,0.005782,0.002123,0.053924,87.982773,4.482056,0.539238,-136.423080,0.054817,0.000000
39.710003,20.207535,-136.423080,0.005808,0.002142,0.054409,89.887604,4.579093,0.544094,-136.423080,0.055216,0.000000
39.950001,19.913734,-136.378601,0.005838,0.002153,0.054678,88.580711,4.512516,0.546785,-136.378601,0.055615,0.000000
40.190002,20.169930,-136.467560,0.005821,0.002168,0.055060,89.720329,4.570571,0.550600,-136.467560,0.056022,0.000000
40.430000,20.592201,-136.423080,0.005846,0.002188,0.055563,91.598686,4.666259,0.555630,-136.423080,0.056421,0.000000
40.670002,20.822327,-136.423080,0.005868,0.002205,0.056014,92.622337,4.718407,0.560138,-136.423080,0.056820,0.000000
40.910004,20.710983,-136.423080,0.005885,0.002218,0.056326,92.127052,4.693176,0.563260,-136.423080,0.057219,0.000000
41.150002,20.918770,-136.423080,0.005890,0.002233,0.056725,93.051338,4.740261,0.567250,-136.423080,0.057618,0.000000
41.390003,21.175705,-136.467560,0.005915,0.002251,0.057176,94.194237,4.798483,0.571761,-136.467560,0.058017,0.000000
41.630001,21.283691,-136.467560,0.005924,0.002265,0.057540,94.674591,4.822953,0.575402,-136.467560,0.058416,0.000000
41.870003,21.109795,-136.467560,0.005937,0.002275,0.057775,93.901054,4.783547,0.577745,-136.467560,0.058815,0.000000
42.110001,21.583824,-136.467560,0.005959,0.002294,0.058278,96.009644,4.890965,0.582775,-136.467560,0.059223,0.000000
42.350002,22.072006,-136.467560,0.005963,0.002314,0.058772,98.181190,5.001588,0.587718,-136.467560,0.059622,0.000000
42.590000,22.333412,-136.556519,0.005989,0.002332,0.059223,99.343979,5.060823,0.592226,-136.556519,0.060020,0.000000
42.830002,22.170311,-136.512039,0.006006,0.002342,0.059483,98.618469,5.023864,0.594827,-136.512039,0.060419,0.000000
43.070004,22.433952,-136.512039,0.005997,0.002360,0.059951,99.791206,5.083606,0.599512,-136.512039,0.060818,0.000000
43.310001,22.632797,-136.512039,0.006036,0.002377,0.060376,100.675713,5.128665,0.603759,-136.512039,0.061217,0.000000
43.550003,22.718819,-136.512039,0.006045,0.002391,0.060732,101.058350,5.148158,0.607317,-136.512039,0.061616,0.000000
43.790001,22.834251,-136.512039,0.006040,0.002405,0.061078,101.571823,5.174315,0.610784,-136.512039,0.062015,0.000000
44.030003,22.879684,-136.512039,0.006062,0.002418,0.061408,101.773918,5.184610,0.614080,-136.512039,0.062423,0.000000
44.270000,23.160454,-136.556519,0.006096,0.002434,0.061816,103.022842,5.248234,0.618157,-136.556519,0.062822,0.000000
44.510002,23.749176,-136.556519,0.006101,0.002455,0.062353,105.641609,5.381640,0.623535,-136.556519,0.063221,0.000000
44.750004,23.836311,-136.512039,0.006109,0.002469,0.062709,106.029205,5.401385,0.627089,-136.512039,0.063620,0.000000
44.990002,23.829605,-136.600998,0.006135,0.002484,0.063090,105.999374,5.399866,0.630904,-136.600998,0.064018,0.000000
45.230003,24.114098,-136.512039,0.006135,0.002500,0.063507,107.264862,5.464333,0.635068,-136.512039,0.064417,0.000000
45.470001,24.709152,-136.645477,0.006148,0.002521,0.064036,109.911797,5.599174,0.640359,-136.645477,0.064816,0.000000
45.710003,24.508072,-136.600998,0.006174,0.002532,0.064305,109.017349,5.553608,0.643046,-136.600998,0.065215,0.000000
45.950001,24.476044,-136.556519,0.006157,0.002545,0.064643,108.874878,5.546351,0.646430,-136.556519,0.065623,0.000000
46.190002,24.970924,-136.645477,0.006196,0.002567,0.065207,111.076218,5.658493,0.652066,-136.645477,0.066022,0.000000
46.430000,25.465065,-136.556519,0.006226,0.002584,0.065640,113.274269,5.770466,0.656403,-136.556519,0.066421,0.000000
46.670002,25.368248,-136.689957,0.006230,0.002596,0.065935,112.843605,5.748527,0.659351,-136.689957,0.066820,0.000000
46.910004,25.463203,-136.689957,0.006252,0.002612,0.066351,113.265984,5.770044,0.663511,-136.689957,0.067219,0.000000
47.150002,25.550339,-136.645477,0.006260,0.002625,0.066672,113.653580,5.789789,0.666721,-136.645477,0.067618,0.000000
47.390003,26.069801,-136.689957,0.006269,0.002645,0.067192,115.964272,5.907501,0.671925,-136.689957,0.068016,0.000000
47.630001,26.001282,-136.645477,0.006286,0.002658,0.067522,115.659477,5.891974,0.675222,-136.645477,0.068415,0.000000
47.870003,26.258965,-136.689957,0.006291,0.002671,0.067851,116.805710,5.950366,0.678514,-136.689957,0.068823,0.000000
48.110001,26.507339,-136.689957,0.006321,0.002689,0.068311,117.910538,6.006649,0.683113,-136.689957,0.069222,0.000000
48.350002,27.364540,-136.689957,0.006334,0.002712,0.068884,121.723557,6.200893,0.688836,-136.689957,0.069621,0.000000
48.590004,27.351875,-136.734436,0.006347,0.002726,0.069230,121.667221,6.198024,0.692303,-136.734436,0.070020,0.000000
48.830002,27.196228,-136.645477,0.006377,0.002738,0.069551,120.974861,6.162754,0.695512,-136.645477,0.070418,0.000000
49.070004,27.437149,-136.689957,0.006390,0.002754,0.069950,122.046532,6.217347,0.699502,-136.689957,0.070817,0.000000
49.310001,27.847130,-136.778931,0.006411,0.002772,0.070401,123.870216,6.310250,0.704013,-136.778931,0.071216,0.000000
49.550003,27.864632,-136.778931,0.006416,0.002786,0.070774,123.948074,6.314216,0.707741,-136.778931,0.071624,0.000000
49.790001,27.942459,-136.823410,0.006407,0.002798,0.071069,124.294266,6.331852,0.710690,-136.823410,0.072023,0.000000
50.030003,28.534157,-136.734436,0.006441,0.002819,0.071607,126.926270,6.465932,0.716068,-136.734436,0.072422,0.000000
50.270004,28.937439,-136.778931,0.006441,0.002837,0.072058,128.720154,6.557317,0.720576,-136.778931,0.072821,0.000000
50.510002,28.870041,-136.689957,0.006480,0.002848,0.072344,128.420349,6.542045,0.723437,-136.689957,0.073220,0.000000
50.750004,29.021591,-136.778931,0.006485,0.002865,0.072777,129.094482,6.576386,0.727775,-136.778931,0.073618,0.000000
50.990002,28.983238,-136.734436,0.006497,0.002877,0.073064,128.923889,6.567696,0.730636,-136.734436,0.074017,0.000000
51.230003,29.208900,-136.689957,0.006510,0.002892,0.073463,129.927673,6.618831,0.734625,-136.689957,0.074416,0.000000
51.470001,29.647179,-136.823410,0.006532,0.002909,0.073896,131.877243,6.718147,0.738963,-136.823410,0.074824,0.000000
51.710003,29.654259,-136.734436,0.006558,0.002924,0.074260,131.908737,6.719751,0.742604,-136.734436,0.075223,0.000000
51.950001,29.946938,-136.823410,0.006554,0.002940,0.074668,133.210632,6.786073,0.746680,-136.823410,0.075622,0.000000
52.190002,30.552048,-136.823410,0.006571,0.002959,0.075162,135.902298,6.923193,0.751623,-136.823410,0.076021,0.000000
52.430004,30.722595,-136.823410,0.006575,0.002973,0.075526,136.660934,6.961840,0.755264,-136.823410,0.076420,0.000000
52.670002,31.031662,-136.867889,0.006614,0.002991,0.075969,138.035721,7.031875,0.759689,-136.867889,0.076819,0.000000
52.910004,31.232742,-136.912369,0.006610,0.003006,0.076350,138.930176,7.077440,0.763504,-136.912369,0.077218,0.000000
53.150002,31.487442,-136.867889,0.006635,0.003022,0.076767,140.063141,7.135157,0.767668,-136.867889,0.077616,0.000000
53.390003,31.657990,-136.867889,0.006640,0.003038,0.077174,140.821777,7.173803,0.771744,-136.867889,0.078024,0.000000
53.630001,31.542183,-136.867889,0.006666,0.003048,0.077408,140.306641,7.147561,0.774083,-136.867889,0.078423,0.000000
53.870003,32.230331,-136.867889,0.006687,0.003070,0.077981,143.367676,7.303497,0.779806,-136.867889,0.078822,0.000000
54.110004,32.438858,-136.867889,0.006704,0.003085,0.078354,144.295242,7.350750,0.783538,-136.867889,0.079221,0.000000
54.350002,32.589294,-136.867889,0.006683,0.003100,0.078753,144.964417,7.384840,0.787527,-136.867889,0.079620,0.000000
54.590004,32.806389,-136.867889,0.006704,0.003118,0.079195,145.930099,7.434034,0.791948,-136.867889,0.080019,0.000000
54.830002,32.737503,-136.956848,0.006748,0.003128,0.079455,145.623688,7.418424,0.794552,-136.956848,0.080418,0.000000
55.070004,33.053642,-136.867889,0.006760,0.003145,0.079889,147.029938,7.490063,0.798885,-136.867889,0.080817,0.000000
55.310001,33.368668,-136.912369,0.006752,0.003160,0.080262,148.431244,7.561449,0.802617,-136.912369,0.081224,0.000000
55.550003,33.222328,-136.956848,0.006773,0.003170,0.080530,147.780304,7.528287,0.805305,-136.956848,0.081623,0.000000
55.790001,34.022560,-137.001328,0.006808,0.003193,0.081094,151.339905,7.709622,0.810940,-137.001328,0.082022,0.000000
56.030003,34.632500,-136.956848,0.006812,0.003212,0.081597,154.053055,7.847836,0.815970,-136.956848,0.082421,0.000000
56.270004,34.752777,-136.956848,0.006821,0.003226,0.081944,154.588074,7.875092,0.819441,-136.956848,0.082820,0.000000
56.510002,34.709587,-137.045807,0.006851,0.003241,0.082326,154.395950,7.865305,0.823256,-137.045807,0.083219,0.000000
56.750004,35.003387,-136.912369,0.006864,0.003256,0.082707,155.702850,7.931881,0.827071,-136.912369,0.083618,0.000000
56.990002,34.987373,-136.912369,0.006864,0.003271,0.083080,155.631607,7.928252,0.830800,-136.912369,0.084017,0.000000
57.230003,35.318787,-137.045807,0.006881,0.003284,0.083418,157.105804,8.003351,0.834183,-137.045807,0.084424,0.000000
57.470001,35.381348,-136.956848,0.006903,0.003299,0.083800,157.384094,8.017528,0.837998,-136.956848,0.084823,0.000000
57.710003,35.794304,-137.001328,0.006920,0.003317,0.084259,159.221008,8.111105,0.842593,-137.001328,0.085222,0.000000
57.950005,36.694328,-136.912369,0.006937,0.003338,0.084788,163.224518,8.315053,0.847885,-136.912369,0.085621,0.000000
58.190002,36.753906,-137.001328,0.006929,0.003352,0.085153,163.489548,8.328554,0.851526,-137.001328,0.086020,0.000000
58.430004,36.927063,-137.001328,0.006972,0.003368,0.085543,164.259781,8.367792,0.855428,-137.001328,0.086419,0.000000
58.670002,36.997444,-137.001328,0.006972,0.003380,0.085864,164.572845,8.383740,0.858638,-137.001328,0.086818,0.000000
58.910004,37.625633,-137.045807,0.007006,0.003401,0.086384,167.367172,8.526090,0.863842,-137.045807,0.087217,0.000000
59.150002,37.713882,-137.001328,0.006998,0.003413,0.086696,167.759735,8.546088,0.866964,-137.001328,0.087624,0.000000
59.390003,37.805489,-137.045807,0.007015,0.003428,0.087069,168.167206,8.566847,0.870692,-137.045807,0.088023,0.000000
59.630001,38.306328,-137.090286,0.007041,0.003445,0.087494,170.395050,8.680338,0.874943,-137.090286,0.088422,0.000000
59.870003,38.849991,-137.090286,0.007045,0.003462,0.087936,172.813385,8.803534,0.879364,-137.090286,0.088821,0.000000
60.110004,39.366844,-137.090286,0.007054,0.003479,0.088370,175.112473,8.920654,0.883701,-137.090286,0.089220,0.000000
60.350002,39.013840,-137.090286,0.007084,0.003487,0.088570,173.542221,8.840662,0.885696,-137.090286,0.089619,0.000000
60.590004,39.524734,-137.001328,0.007075,0.003506,0.089064,175.814804,8.956433,0.890639,-137.001328,0.090018,0.000000
60.830002,40.138031,-137.090286,0.007110,0.003525,0.089523,178.542877,9.095408,0.895234,-137.090286,0.090417,0.000000
61.070004,40.805695,-137.045807,0.007105,0.003542,0.089957,181.512802,9.246702,0.899571,-137.045807,0.090824,0.000000
61.310001,40.607964,-137.134766,0.007131,0.003552,0.090209,180.633240,9.201896,0.902088,-137.134766,0.091223,0.000000
61.550003,40.996346,-137.045807,0.007136,0.003567,0.090608,182.360855,9.289905,0.906077,-137.045807,0.091622,0.000000
61.790005,41.961906,-137.134766,0.007140,0.003589,0.091163,186.655884,9.508704,0.911626,-137.134766,0.092021,0.000000
62.030003,42.371895,-137.179260,0.007179,0.003605,0.091570,188.479599,9.601608,0.915702,-137.179260,0.092420,0.000000
62.270004,42.443016,-137.134766,0.007179,0.003616,0.091839,188.795959,9.617724,0.918390,-137.134766,0.092819,0.000000
62.510002,42.900658,-137.179260,0.007183,0.003632,0.092255,190.831650,9.721428,0.922553,-137.179260,0.093218,0.000000
62.750004,43.550079,-137.134766,0.007222,0.003652,0.092767,193.720428,9.868589,0.927670,-137.134766,0.093625,0.000000
62.990002,43.796593,-137.134766,0.007230,0.003664,0.093062,194.816971,9.924450,0.930619,-137.134766,0.094024,0.000000
63.230003,43.813347,-137.223740,0.007243,0.003673,0.093304,194.891495,9.928246,0.933045,-137.223740,0.094423,0.000000
63.470001,44.543198,-137.134766,0.007248,0.003693,0.093799,198.138046,10.093633,0.937988,-137.134766,0.094822,0.000000
63.710003,45.633133,-137.223740,0.007252,0.003713,0.094319,202.986313,10.340616,0.943192,-137.223740,0.095221,0.000000
63.950005,46.400589,-137.179260,0.007269,0.003732,0.094796,206.400131,10.514524,0.947961,-137.179260,0.095620,0.000000
64.190002,46.304893,-137.223740,0.007291,0.003742,0.095039,205.974457,10.492839,0.950391,-137.223740,0.096019,0.000000
64.430000,47.110703,-137.268219,0.007317,0.003762,0.095542,209.558868,10.675438,0.955421,-137.268219,0.096418,0.000000
64.670006,47.615273,-137.179260,0.007308,0.003776,0.095906,211.803314,10.789775,0.959062,-137.179260,0.096826,0.000000
64.910004,48.089668,-137.223740,0.007330,0.003791,0.096296,213.913528,10.897274,0.962964,-137.223740,0.097224,0.000000
65.150002,48.436722,-137.179260,0.007338,0.003803,0.096600,215.457306,10.975918,0.966000,-137.179260,0.097623,0.000000
65.389999,48.960281,-137.223740,0.007347,0.003818,0.096973,217.786209,11.094558,0.969732,-137.223740,0.098022,0.000000
65.630005,49.458885,-137.312698,0.007368,0.003833,0.097346,220.004105,11.207543,0.973460,-137.312698,0.098421,0.000000
65.870003,50.781555,-137.223740,0.007364,0.003856,0.097944,225.887634,11.507264,0.979444,-137.223740,0.098820,0.000000
66.110001,51.152809,-137.312698,0.007386,0.003867,0.098231,227.539062,11.591393,0.982305,-137.312698,0.099219,0.000000
66.350006,51.613434,-137.312698,0.007394,0.003884,0.098647,229.588013,11.695771,0.986469,-137.312698,0.099618,0.000000
66.590004,52.410683,-137.312698,0.007412,0.003899,0.099046,233.134354,11.876431,0.990458,-137.312698,0.100026,0.000000
66.830002,53.580673,-137.312698,0.007429,0.003921,0.099592,238.338745,12.141554,0.995919,-137.312698,0.100425,0.000000
67.070000,53.813034,-137.312698,0.007455,0.003931,0.099844,239.372330,12.194208,0.998436,-137.312698,0.100824,0.000000
67.310005,54.298607,-137.312698,0.007459,0.003946,0.100234,241.532272,12.304240,1.002339,-137.312698,0.101222,0.000000
67.550003,55.652184,-137.357178,0.007472,0.003967,0.100771,247.553268,12.610966,1.007713,-137.357178,0.101621,0.000000
67.790001,56.507523,-137.312698,0.007472,0.003984,0.101196,251.358017,12.804788,1.011964,-137.312698,0.102020,0.000000
68.030006,56.956230,-137.401657,0.007480,0.003996,0.101491,253.353958,12.906466,1.014912,-137.401657,0.102419,0.000000
68.270004,57.613098,-137.312698,0.007502,0.004011,0.101890,256.275848,13.055314,1.018901,-137.312698,0.102818,0.000000
68.510002,58.095695,-137.357178,0.007528,0.004024,0.102211,258.422546,13.164673,1.022111,-137.357178,0.103226,0.000000
68.750000,59.343513,-137.312698,0.007528,0.004044,0.102723,263.973145,13.447432,1.027228,-137.312698,0.103625,0.000000
68.990005,59.660400,-137.357178,0.007545,0.004056,0.103035,265.382721,13.519239,1.030351,-137.357178,0.104024,0.000000
69.230003,60.520210,-137.312698,0.007558,0.004070,0.103373,269.207336,13.714076,1.033731,-137.312698,0.104423,0.000000
69.470001,61.515564,-137.312698,0.007562,0.004089,0.103850,273.634888,13.939627,1.038499,-137.312698,0.104822,0.000000
69.710007,63.234436,-137.401657,0.007575,0.004111,0.104414,281.280823,14.329128,1.044139,-137.401657,0.105220,0.000000
69.950005,64.013428,-137.357178,0.007593,0.004124,0.104752,284.745941,14.505651,1.047519,-137.357178,0.105619,0.000000
70.190002,64.463257,-137.401657,0.007593,0.004137,0.105073,286.746887,14.607582,1.050728,-137.401657,0.106018,0.000000
70.430000,65.469040,-137.446136,0.007606,0.004152,0.105472,291.220825,14.835497,1.054718,-137.446136,0.106426,0.000000
70.670006,66.741058,-137.357178,0.007606,0.004172,0.105975,296.879059,15.123740,1.059748,-137.357178,0.106824,0.000000
70.910004,67.464951,-137.446136,0.007614,0.004185,0.106304,300.099091,15.287776,1.063045,-137.446136,0.107223,0.000000
71.150002,66.763031,-137.446136,0.007627,0.004176,0.106079,296.976807,15.128718,1.060789,-137.446136,0.106304,0.000000
71.390007,66.127014,-137.401657,0.007631,0.004175,0.106053,294.147644,14.984595,1.060528,-137.401657,0.106079,0.000000
71.630005,65.550583,-137.446136,0.007653,0.004175,0.106035,291.583557,14.853974,1.060354,-137.446136,0.106079,0.000000
71.870003,65.037827,-137.401657,0.007662,0.004175,0.106035,289.302704,14.737782,1.060354,-137.401657,0.106079,0.000000
72.110001,64.561188,-137.490616,0.007640,0.004174,0.106027,287.182495,14.629775,1.060266,-137.490616,0.106079,0.000000
72.350006,64.162384,-137.446136,0.007662,0.004174,0.106027,285.408539,14.539404,1.060266,-137.446136,0.106079,0.000000
72.590004,63.776978,-137.446136,0.007679,0.004174,0.106018,283.694153,14.452070,1.060183,-137.446136,0.106079,0.000000
72.830002,63.432541,-137.535095,0.007666,0.004174,0.106018,282.162048,14.374020,1.060183,-137.535095,0.106079,0.000000
73.070000,63.123840,-137.535095,0.007679,0.004174,0.106018,280.788879,14.304067,1.060183,-137.535095,0.106079,0.000000
73.310005,62.842323,-137.535095,0.007666,0.004174,0.106018,279.536621,14.240274,1.060183,-137.535095,0.106079,0.000000
73.550003,62.575706,-137.535095,0.007675,0.004174,0.106018,278.350647,14.179857,1.060183,-137.535095,0.106079,0.000000
73.790001,62.332176,-137.490616,0.007683,0.004174,0.106018,277.267365,14.124674,1.060183,-137.490616,0.106079,0.000000
74.030006,62.100182,-137.579575,0.007675,0.004174,0.106018,276.235413,14.072103,1.060183,-137.579575,0.106079,0.000000
74.270004,61.890167,-137.535095,0.007675,0.004174,0.106018,275.301208,14.024512,1.060183,-137.535095,0.106079,0.000000
74.510002,61.681267,-137.490616,0.007692,0.004174,0.106018,274.371979,13.977175,1.060183,-137.490616,0.106079,0.000000
74.750000,61.499176,-137.535095,0.007683,0.004174,0.106010,273.562012,13.935912,1.060096,-137.535095,0.106079,0.000000
74.990005,61.332726,-137.490616,0.007675,0.004174,0.106010,272.821594,13.898194,1.060096,-137.490616,0.106079,0.000000
75.230003,61.150635,-137.535095,0.007683,0.004174,0.106010,272.011597,13.856932,1.060096,-137.535095,0.106079,0.000000
75.470001,61.006157,-137.535095,0.007696,0.004174,0.106010,271.368927,13.824192,1.060096,-137.535095,0.106079,0.000000
75.710007,60.853111,-137.579575,0.007679,0.004174,0.106010,270.688171,13.789512,1.060096,-137.579575,0.106079,0.000000
75.950005,60.708260,-137.579575,0.007692,0.004174,0.106010,270.043823,13.756688,1.060096,-137.579575,0.106079,0.000000
76.190002,60.576813,-137.579575,0.007705,0.004174,0.106010,269.459106,13.726902,1.060096,-137.579575,0.106079,0.000000
76.430000,60.440895,-137.624069,0.007705,0.004174,0.106010,268.854523,13.696102,1.060096,-137.624069,0.106079,0.000000
76.670006,60.318382,-137.579575,0.007700,0.004174,0.106010,268.309570,13.668341,1.060096,-137.579575,0.106079,0.000000
76.910004,60.199593,-137.579575,0.007683,0.004174,0.106010,267.781158,13.641422,1.060096,-137.579575,0.106079,0.000000
77.150002,60.081551,-137.624069,0.007696,0.004174,0.106010,267.256073,13.614674,1.060096,-137.624069,0.106079,0.000000
77.390007,59.984734,-137.624069,0.007709,0.004174,0.106010,266.825409,13.592734,1.060096,-137.624069,0.106079,0.000000
77.630005,59.867065,-137.624069,0.007696,0.004174,0.106010,266.302002,13.566071,1.060096,-137.624069,0.106079,0.000000
77.870003,59.782913,-137.624069,0.007696,0.004174,0.106010,265.927673,13.547001,1.060096,-137.624069,0.106079,0.000000
78.110001,59.682373,-137.624069,0.007683,0.004174,0.106010,265.480469,13.524219,1.060096,-137.624069,0.106079,0.000000
78.350006,59.595612,-137.668549,0.007709,0.004174,0.106010,265.094513,13.504559,1.060096,-137.668549,0.106079,0.000000
78.590004,59.512566,-137.668549,0.007687,0.004174,0.106010,264.725128,13.485741,1.060096,-137.668549,0.106079,0.000000
78.830002,59.405701,-137.668549,0.007687,0.004174,0.106010,264.249756,13.461524,1.060096,-137.668549,0.106079,0.000000
79.070007,59.331970,-137.624069,0.007713,0.004174,0.106010,263.921783,13.444817,1.060096,-137.624069,0.106079,0.000000
79.310005,59.251534,-137.624069,0.007700,0.004174,0.106010,263.563995,13.426590,1.060096,-137.624069,0.106079,0.000000
79.550003,59.157326,-137.713028,0.007696,0.004174,0.106010,263.144928,13.405242,1.060096,-137.713028,0.106079,0.000000
79.790001,59.092903,-137.624069,0.007705,0.004174,0.106010,262.858368,13.390643,1.060096,-137.624069,0.106079,0.000000
80.030006,59.015076,-137.757507,0.007696,0.004174,0.106010,262.512177,13.373007,1.060096,-137.757507,0.106079,0.000000
80.270004,58.937630,-137.713028,0.007696,0.004174,0.106010,262.167664,13.355457,1.060096,-137.713028,0.106079,0.000000
80.510002,58.866875,-137.713028,0.007718,0.004174,0.106010,261.852936,13.339424,1.060096,-137.713028,0.106079,0.000000
80.750008,58.800591,-137.757507,0.007705,0.004174,0.106010,261.558075,13.324404,1.060096,-137.757507,0.106079,0.000000
80.990005,58.740265,-137.713028,0.007709,0.004174,0.106010,261.289734,13.310734,1.060096,-137.713028,0.106079,0.000000
81.230003,58.661324,-137.668549,0.007709,0.004174,0.106010,260.938599,13.292846,1.060096,-137.668549,0.106079,0.000000
81.470001,58.612175,-137.757507,0.007709,0.004174,0.106010,260.719971,13.281709,1.060096,-137.757507,0.106079,0.000000
81.710007,58.546265,-137.713028,0.007722,0.004174,0.106010,260.426788,13.266773,1.060096,-137.713028,0.106079,0.000000
81.950005,58.489662,-137.757507,0.007722,0.004174,0.106010,260.175018,13.253946,1.060096,-137.757507,0.106079,0.000000
82.190002,58.444977,-137.757507,0.007709,0.004174,0.106010,259.976227,13.243821,1.060096,-137.757507,0.106079,0.000000
82.430000,58.368637,-137.713028,0.007683,0.004174,0.106010,259.636658,13.226522,1.060096,-137.713028,0.106079,0.000000
82.670006,58.326561,-137.801987,0.007718,0.004174,0.106010,259.449493,13.216988,1.060096,-137.801987,0.106079,0.000000
82.910004,58.278152,-137.757507,0.007709,0.004174,0.106010,259.234161,13.206018,1.060096,-137.757507,0.106079,0.000000
83.150002,58.209641,-137.846466,0.007718,0.004174,0.106010,258.929413,13.190493,1.060096,-137.846466,0.106079,0.000000
83.390007,58.172028,-137.801987,0.007713,0.004174,0.106010,258.762115,13.181971,1.060096,-137.801987,0.106079,0.000000
83.630005,58.111328,-137.801987,0.007713,0.004174,0.106010,258.492096,13.168216,1.060096,-137.801987,0.106079,0.000000
83.870003,58.073349,-137.846466,0.007731,0.004174,0.106010,258.323151,13.159609,1.060096,-137.846466,0.106079,0.000000
84.110001,58.010048,-137.846466,0.007705,0.004174,0.106010,258.041595,13.145265,1.060096,-137.846466,0.106079,0.000000
84.350006,57.970200,-137.846466,0.007726,0.004174,0.106010,257.864319,13.136235,1.060096,-137.846466,0.106079,0.000000
84.590004,57.926262,-137.757507,0.007718,0.004174,0.106010,257.668884,13.126279,1.060096,-137.757507,0.106079,0.000000
84.830002,57.867058,-137.801987,0.007709,0.004174,0.106010,257.405518,13.112863,1.060096,-137.801987,0.106079,0.000000
85.070007,57.833542,-137.890945,0.007713,0.004174,0.106010,257.256439,13.105268,1.060096,-137.890945,0.106079,0.000000
85.310005,57.778801,-137.801987,0.007731,0.004174,0.106010,257.012939,13.092864,1.060096,-137.801987,0.106079,0.000000
85.550003,57.729652,-137.890945,0.007705,0.004174,0.106010,256.794312,13.081726,1.060096,-137.890945,0.106079,0.000000
85.790001,57.706566,-137.846466,0.007713,0.004174,0.106010,256.691620,13.076494,1.060096,-137.846466,0.106079,0.000000
86.030006,57.657784,-137.846466,0.007709,0.004174,0.106010,256.474640,13.065440,1.060096,-137.846466,0.106079,0.000000
86.270004,57.615334,-137.890945,0.007700,0.004174,0.106010,256.285797,13.055821,1.060096,-137.890945,0.106079,0.000000
86.510002,57.572510,-137.890945,0.007718,0.004174,0.106010,256.095306,13.046117,1.060096,-137.890945,0.106079,0.000000
86.750008,57.532295,-137.935425,0.007709,0.004174,0.106010,255.916428,13.037004,1.060096,-137.935425,0.106079,0.000000
86.990005,57.500641,-137.890945,0.007718,0.004174,0.106010,255.775620,13.029831,1.060096,-137.890945,0.106079,0.000000
87.230003,57.452980,-137.935425,0.007718,0.004174,0.106010,255.563614,13.019032,1.060096,-137.935425,0.106079,0.000000
87.470001,57.418716,-137.935425,0.007713,0.004174,0.106010,255.411209,13.011267,1.060096,-137.935425,0.106079,0.000000
87.710007,57.384834,-137.846466,0.007718,0.004174,0.106010,255.260498,13.003590,1.060096,-137.846466,0.106079,0.000000
87.950005,57.354668,-137.979904,0.007705,0.004174,0.106010,255.126297,12.996754,1.060096,-137.979904,0.106079,0.000000
88.190002,57.316315,-137.979904,0.007726,0.004174,0.106010,254.955704,12.988063,1.060096,-137.979904,0.106079,0.000000
88.430008,57.283173,-137.935425,0.007705,0.004174,0.106010,254.808273,12.980552,1.060096,-137.935425,0.106079,0.000000
88.670006,57.257484,-137.935425,0.007735,0.004174,0.106010,254.694016,12.974731,1.060096,-137.935425,0.106079,0.000000
88.910004,57.215401,-137.890945,0.007731,0.004174,0.106010,254.506821,12.965195,1.060096,-137.890945,0.106079,0.000000
89.150002,57.187103,-138.068878,0.007726,0.004174,0.106010,254.380936,12.958783,1.060096,-138.068878,0.106079,0.000000
89.390007,57.136833,-137.979904,0.007709,0.004174,0.106010,254.157333,12.947392,1.060096,-137.979904,0.106079,0.000000
89.630005,57.096992,-137.935425,0.007722,0.004174,0.106010,253.980103,12.938364,1.060096,-137.935425,0.106079,0.000000
89.870003,57.081718,-137.979904,0.007713,0.004174,0.106010,253.912170,12.934902,1.060096,-137.979904,0.106079,0.000000
90.110001,57.036293,-137.935425,0.007731,0.004174,0.106010,253.710098,12.924609,1.060096,-137.935425,0.106079,0.000000
90.350006,57.008362,-138.024384,0.007718,0.004174,0.106010,253.585861,12.918280,1.060096,-138.024384,0.106079,0.000000
90.590004,56.976341,-137.979904,0.007713,0.004174,0.106010,253.443420,12.911023,1.060096,-137.979904,0.106079,0.000000
90.830002,56.955856,-138.068878,0.007722,0.004174,0.106010,253.352295,12.906382,1.060096,-138.068878,0.106079,0.000000
91.070007,56.917130,-138.024384,0.007731,0.004174,0.106010,253.180038,12.897606,1.060096,-138.024384,0.106079,0.000000
91.310005,56.889954,-138.024384,0.007718,0.004174,0.106010,253.059158,12.891448,1.060096,-138.024384,0.106079,0.000000
91.550003,56.868355,-138.113358,0.007692,0.004174,0.106010,252.963074,12.886553,1.060096,-138.113358,0.106079,0.000000
91.790001,56.834465,-138.024384,0.007739,0.004174,0.106010,252.812332,12.878874,1.060096,-138.024384,0.106079,0.000000
92.030006,56.814728,-138.024384,0.007718,0.004174,0.106010,252.724533,12.874402,1.060096,-138.024384,0.106079,0.000000
92.270004,56.781960,-138.024384,0.007718,0.004174,0.106010,252.578766,12.866976,1.060096,-138.024384,0.106079,0.000000
92.510002,56.753288,-138.068878,0.007748,0.004174,0.106010,252.451233,12.860479,1.060096,-138.068878,0.106079,0.000000
92.750008,56.731316,-138.113358,0.007731,0.004174,0.106010,252.353500,12.855499,1.060096,-138.113358,0.106079,0.000000
92.990005,56.698921,-138.113358,0.007705,0.004174,0.106010,252.209396,12.848159,1.060096,-138.113358,0.106079,0.000000
93.230003,56.676956,-138.024384,0.007739,0.004174,0.106010,252.111694,12.843182,1.060096,-138.024384,0.106079,0.000000
93.470001,56.645676,-138.113358,0.007722,0.004174,0.106010,251.972549,12.836094,1.060096,-138.113358,0.106079,0.000000
93.710007,56.624077,-138.068878,0.007713,0.004174,0.106010,251.876480,12.831200,1.060096,-138.068878,0.106079,0.000000
93.950005,56.596893,-138.157837,0.007718,0.004174,0.106010,251.755554,12.825040,1.060096,-138.157837,0.106079,0.000000
94.190002,56.554817,-138.113358,0.007726,0.004174,0.106010,251.568390,12.815505,1.060096,-138.113358,0.106079,0.000000
94.430008,56.542900,-138.068878,0.007731,0.004174,0.106010,251.515381,12.812804,1.060096,-138.068878,0.106079,0.000000
94.670006,56.505287,-138.157837,0.007726,0.004174,0.106010,251.348068,12.804281,1.060096,-138.157837,0.106079,0.000000
94.910004,56.490021,-138.202316,0.007722,0.004174,0.106010,251.280167,12.800822,1.060096,-138.202316,0.106079,0.000000
95.150002,56.455765,-138.157837,0.007722,0.004174,0.106010,251.127777,12.793059,1.060096,-138.157837,0.106079,0.000000
95.390007,56.438263,-138.202316,0.007726,0.004174,0.106010,251.049927,12.789093,1.060096,-138.202316,0.106079,0.000000
95.630005,56.418900,-138.157837,0.007718,0.004174,0.106010,250.963806,12.784705,1.060096,-138.157837,0.106079,0.000000
95.870003,56.381287,-138.246796,0.007735,0.004174,0.106010,250.796494,12.776182,1.060096,-138.246796,0.106079,0.000000
96.110008,56.378685,-138.157837,0.007726,0.004174,0.106010,250.784912,12.775592,1.060096,-138.157837,0.106079,0.000000
96.350006,56.348145,-138.202316,0.007718,0.004174,0.106010,250.649063,12.768672,1.060096,-138.202316,0.106079,0.000000
96.590004,56.325432,-138.246796,0.007739,0.004174,0.106010,250.548035,12.763525,1.060096,-138.246796,0.106079,0.000000
96.830002,56.310165,-138.202316,0.007731,0.004174,0.106010,250.480133,12.760065,1.060096,-138.202316,0.106079,0.000000
97.070007,56.268463,-138.246796,0.007722,0.004174,0.106010,250.294632,12.750616,1.060096,-138.246796,0.106079,0.000000
97.310005,56.266968,-138.202316,0.007722,0.004174,0.106010,250.287979,12.750278,1.060096,-138.202316,0.106079,0.000000
97.550003,56.230103,-138.202316,0.007735,0.004174,0.106010,250.123993,12.741923,1.060096,-138.202316,0.106079,0.000000
97.790001,56.220795,-138.246796,0.007739,0.004174,0.106010,250.082581,12.739815,1.060096,-138.246796,0.106079,0.000000
98.030006,56.195473,-138.246796,0.007718,0.004174,0.106010,249.969940,12.734076,1.060096,-138.246796,0.106079,0.000000
98.270004,56.166061,-138.291275,0.007735,0.004174,0.106010,249.839127,12.727411,1.060096,-138.291275,0.106079,0.000000
98.510002,56.148560,-138.291275,0.007726,0.004174,0.106010,249.761261,12.723446,1.060096,-138.291275,0.106079,0.000000
98.750008,56.128822,-138.291275,0.007735,0.004174,0.106010,249.673477,12.718973,1.060096,-138.291275,0.106079,0.000000
98.990005,56.109085,-138.291275,0.007748,0.004174,0.106010,249.585678,12.714500,1.060096,-138.291275,0.106079,0.000000
99.230003,56.084877,-138.246796,0.007739,0.004174,0.106010,249.477997,12.709015,1.060096,-138.246796,0.106079,0.000000
99.470001,56.067383,-138.335754,0.007709,0.004174,0.106010,249.400177,12.705050,1.060096,-138.335754,0.106079,0.000000
99.710007,56.061790,-138.291275,0.007735,0.004174,0.106010,249.375305,12.703783,1.060096,-138.291275,0.106079,0.000000
99.950005,56.025299,-138.291275,0.007743,0.004174,0.106010,249.212982,12.695515,1.060096,-138.291275,0.106079,0.000000
100.190002,56.009293,-138.335754,0.007731,0.004174,0.106010,249.141769,12.691888,1.060096,-138.335754,0.106079,0.000000
100.430008,55.990295,-138.291275,0.007739,0.004174,0.106010,249.057266,12.687583,1.060096,-138.291275,0.106079,0.000000
100.670006,55.965721,-138.380234,0.007726,0.004174,0.106010,248.947968,12.682014,1.060096,-138.380234,0.106079,0.000000
100.910004,55.960136,-138.291275,0.007743,0.004174,0.106010,248.923126,12.680748,1.060096,-138.291275,0.106079,0.000000
101.150002,55.925507,-138.335754,0.007726,0.004174,0.106010,248.769073,12.672901,1.060096,-138.335754,0.106079,0.000000
101.390007,55.919174,-138.424713,0.007735,0.004174,0.106010,248.740906,12.671466,1.060096,-138.424713,0.106079,0.000000
101.400002,55.915077,-138.380234,0.007739,0.004174,0.106010,248.722687,12.670538,1.060096,-138.380234,0.106079,0.000000