File: Data/Automembrane/AutoNoheat10-1-1_12132023_184312.csv
Time (sec),S:Load (lbs),S:HL1 (DIM),S:LVDT (in),S:Position (in),Ch:Position (mm),Ch:Load (N),Ch:Stress (MPa),Ch:Strain (mm/mm),Ch:HL1 (DIM),Set Point (),Cycles ()
0.010000,0.009682,-1304.670776,0.000009,-0.000000,-0.000000,0.043066,0.002194,-0.000000,-1304.670776,0.000182,0.000000
0.280000,0.002975,-1304.715210,-0.000039,-0.000000,-0.000000,0.013236,0.000674,-0.000000,-1304.715210,0.000182,0.000000
0.550000,-0.002609,-1304.804199,0.000013,0.000088,0.002238,-0.011607,-0.000591,0.022376,-1304.804199,0.003009,0.000000
0.820000,0.016014,-1304.759766,0.000060,0.000251,0.006374,0.071234,0.003629,0.063741,-1304.759766,0.007502,0.000000
1.090000,-0.051392,-1304.759766,0.000259,0.000429,0.010901,-0.228601,-0.011646,0.109013,-1304.759766,0.012011,0.000000
1.360000,-0.014153,-1304.670776,0.000487,0.000608,0.015437,-0.062954,-0.003207,0.154367,-1304.670776,0.016503,0.000000
1.630000,0.005959,-1304.759766,0.000673,0.000780,0.019816,0.026505,0.001350,0.198162,-1304.759766,0.020996,0.000000
1.900000,-0.018623,-1304.759766,0.000780,0.000961,0.024421,-0.082841,-0.004220,0.244213,-1304.759766,0.025505,0.000000
2.170000,0.028297,-1304.759766,0.001026,0.001132,0.028749,0.125873,0.006412,0.287485,-1304.759766,0.029998,0.000000
2.440000,0.002975,-1304.759766,0.001212,0.001320,0.033518,0.013236,0.000674,0.335183,-1304.759766,0.034490,0.000000
2.710000,0.008194,-1304.715210,0.001375,0.001491,0.037872,0.036449,0.001857,0.378720,-1304.715210,0.038999,0.000000
2.980000,0.020851,-1304.715210,0.001556,0.001667,0.042330,0.092750,0.004725,0.423295,-1304.715210,0.043491,0.000000
3.250000,-0.027931,-1304.715210,0.001750,0.001846,0.046900,-0.124244,-0.006329,0.468998,-1304.715210,0.048001,0.000000
3.520000,0.009682,-1304.759766,0.001962,0.002024,0.051409,0.043066,0.002194,0.514091,-1304.759766,0.052493,0.000000
3.790000,0.004837,-1304.759766,0.002139,0.002202,0.055936,0.021516,0.001096,0.559362,-1304.759766,0.056985,0.000000
4.060000,0.020851,-1304.759766,0.002272,0.002379,0.060437,0.092750,0.004725,0.604372,-1304.759766,0.061495,0.000000
4.330000,0.030533,-1304.804199,0.002488,0.002558,0.064964,0.135817,0.006919,0.649639,-1304.804199,0.065987,0.000000
4.600000,0.018242,-1304.715210,0.002703,0.002736,0.069482,0.081144,0.004134,0.694823,-1304.715210,0.070480,0.000000
4.870000,0.004097,-1304.804199,0.002820,0.002899,0.073645,0.018224,0.000928,0.736450,-1304.804199,0.074989,0.000000
5.140000,0.010056,-1304.804199,0.003031,0.003081,0.078267,0.044729,0.002279,0.782671,-1304.804199,0.079481,0.000000
5.410000,0.001114,-1304.804199,0.003234,0.003266,0.082968,0.004955,0.000252,0.829675,-1304.804199,0.083974,0.000000
5.680000,0.007446,-1304.715210,0.003376,0.003436,0.087269,0.033123,0.001687,0.872691,-1304.715210,0.088483,0.000000
5.950000,0.004837,-1304.715210,0.003613,0.003617,0.091865,0.021516,0.001096,0.918655,-1304.715210,0.092976,0.000000
6.220000,0.036865,-1304.804199,0.003751,0.003794,0.096375,0.163985,0.008354,0.963748,-1304.804199,0.097467,0.000000
6.490000,0.059578,-1304.804199,0.004005,0.003977,0.101015,0.265016,0.013501,1.010147,-1304.804199,0.101977,0.000000
6.760000,0.056229,-1304.759766,0.004165,0.004149,0.105377,0.250117,0.012742,1.053768,-1304.759766,0.106469,0.000000
7.030000,0.097931,-1304.715210,0.004337,0.004319,0.109704,0.435618,0.022191,1.097040,-1304.715210,0.110962,0.000000
7.300000,0.109100,-1304.759766,0.004566,0.004496,0.114188,0.485303,0.024722,1.141876,-1304.759766,0.115471,0.000000
7.570000,0.224915,-1304.804199,0.004738,0.004683,0.118940,1.000470,0.050966,1.189399,-1304.804199,0.119963,0.000000
7.840000,0.296036,-1304.759766,0.004941,0.004854,0.123302,1.316833,0.067083,1.233024,-1304.759766,0.124456,0.000000
8.110001,0.398064,-1304.759766,0.005126,0.005031,0.127794,1.770676,0.090203,1.277943,-1304.759766,0.128965,0.000000
8.380000,0.522064,-1304.759766,0.005312,0.005205,0.132217,2.322258,0.118301,1.322174,-1304.759766,0.133458,0.000000
8.650001,0.600266,-1304.804199,0.005553,0.005390,0.136918,2.670114,0.136022,1.369178,-1304.804199,0.137950,0.000000
8.920000,0.590584,-1304.804199,0.005596,-0.000003,-0.000069,2.627048,0.133828,-0.000693,-1304.804199,0.000139,0.000000
9.190001,0.548874,-1304.804199,0.005661,-0.000003,-0.000069,2.441513,0.124377,-0.000693,-1304.804199,0.000139,0.000000
9.460000,0.520203,-1304.715210,0.005665,-0.000003,-0.000069,2.313977,0.117880,-0.000693,-1304.715210,0.000399,0.000000
9.730000,0.528770,-1304.759766,0.005635,-0.000002,-0.000061,2.352088,0.119821,-0.000606,-1304.759766,0.000850,0.000000
10.000000,0.504562,-1304.804199,0.005644,-0.000002,-0.000061,2.244406,0.114335,-0.000606,-1304.804199,0.001301,0.000000
10.270000,0.633034,-1304.804199,0.005661,0.000038,0.000954,2.815875,0.143448,0.009538,-1304.804199,0.001752,0.000000
10.540001,0.647179,-1304.804199,0.005708,0.000056,0.001422,2.878794,0.146653,0.014224,-1304.804199,0.002203,0.000000
10.810000,0.662079,-1304.715210,0.005674,0.000071,0.001804,2.945074,0.150029,0.018039,-1304.715210,0.002654,0.000000
11.080001,0.688889,-1304.759766,0.005674,0.000088,0.002238,3.064329,0.156104,0.022376,-1304.759766,0.003096,0.000000
11.350000,0.707130,-1304.804199,0.005726,0.000108,0.002732,3.145473,0.160238,0.027319,-1304.804199,0.003547,0.000000
11.620001,0.681808,-1304.804199,0.005777,0.000115,0.002923,3.032835,0.154500,0.029227,-1304.804199,0.003998,0.000000
11.890000,0.721657,-1304.759766,0.005773,0.000143,0.003625,3.210090,0.163530,0.036252,-1304.759766,0.004449,0.000000
12.160001,0.726868,-1304.759766,0.005795,0.000161,0.004093,3.233269,0.164711,0.040934,-1304.759766,0.004900,0.000000
12.430000,0.726494,-1304.715210,0.005833,0.000173,0.004397,3.231606,0.164626,0.043969,-1304.715210,0.005351,0.000000
12.700001,0.732452,-1304.715210,0.005829,0.000192,0.004874,3.258111,0.165976,0.048738,-1304.715210,0.005802,0.000000
12.970000,0.761871,-1304.804199,0.005816,0.000210,0.005333,3.388973,0.172643,0.053333,-1304.804199,0.006253,0.000000
13.240001,0.757401,-1304.804199,0.005864,0.000225,0.005724,3.369086,0.171629,0.057239,-1304.804199,0.006704,0.000000
13.510000,0.757774,-1304.759766,0.005915,0.000237,0.006027,3.370749,0.171714,0.060271,-1304.759766,0.007146,0.000000
13.780001,0.787941,-1304.759766,0.005937,0.000257,0.006530,3.504936,0.178550,0.065301,-1304.759766,0.007597,0.000000
14.050000,0.820709,-1304.759766,0.005946,0.000281,0.007137,3.650697,0.185975,0.071372,-1304.759766,0.008048,0.000000
14.320001,0.826294,-1304.759766,0.005963,0.000299,0.007588,3.675539,0.187241,0.075883,-1304.759766,0.008499,0.000000
14.590001,0.821083,-1304.759766,0.005950,0.000315,0.008005,3.652360,0.186060,0.080047,-1304.759766,0.008950,0.000000
14.860001,0.801720,-1304.759766,0.005946,0.000327,0.008308,3.566227,0.181672,0.083082,-1304.759766,0.009401,0.000000
15.130001,0.850128,-1304.715210,0.006032,0.000346,0.008785,3.781559,0.192642,0.087851,-1304.715210,0.009852,0.000000
15.400001,0.880287,-1304.804199,0.005997,0.000366,0.009288,3.915713,0.199476,0.092881,-1304.804199,0.010302,0.000000
15.670001,0.891830,-1304.759766,0.006002,0.000381,0.009678,3.967060,0.202092,0.096784,-1304.759766,0.010754,0.000000
15.940001,0.923851,-1304.759766,0.006088,0.000404,0.010268,4.109495,0.209348,0.102680,-1304.759766,0.011196,0.000000
16.210001,0.904121,-1304.759766,0.006079,0.000419,0.010632,4.021733,0.204877,0.106321,-1304.759766,0.011647,0.000000
16.480001,0.897415,-1304.759766,0.006122,0.000437,0.011092,3.991902,0.203357,0.110920,-1304.759766,0.012098,0.000000
16.750000,0.911942,-1304.848755,0.006127,0.000455,0.011551,4.056519,0.206649,0.115515,-1304.848755,0.012549,0.000000
17.020000,0.981575,-1304.848755,0.006118,0.000477,0.012124,4.366264,0.222428,0.121238,-1304.848755,0.013000,0.000000
17.290001,1.010246,-1304.759766,0.006140,0.000494,0.012558,4.493800,0.228925,0.125575,-1304.759766,0.013451,0.000000
17.560001,1.012482,-1304.759766,0.006187,0.000512,0.013008,4.503744,0.229432,0.130083,-1304.759766,0.013902,0.000000
17.830000,1.021790,-1304.715210,0.006209,0.000529,0.013433,4.545147,0.231541,0.134333,-1304.715210,0.014353,0.000000
18.100000,1.037804,-1304.759766,0.006204,0.000548,0.013919,4.616381,0.235170,0.139190,-1304.759766,0.014803,0.000000
18.370001,1.025887,-1304.759766,0.006230,0.000564,0.014335,4.563371,0.232469,0.143353,-1304.759766,0.015255,0.000000
18.640001,1.059029,-1304.715210,0.006260,0.000583,0.014821,4.710794,0.239979,0.148209,-1304.715210,0.015697,0.000000
18.910002,1.124939,-1304.759766,0.006308,0.000604,0.015350,5.003978,0.254915,0.153500,-1304.759766,0.016148,0.000000
19.180000,1.132385,-1304.804199,0.006278,0.000619,0.015723,5.037101,0.256602,0.157228,-1304.804199,0.016599,0.000000
19.450001,1.144302,-1304.804199,0.006338,0.000633,0.016087,5.090111,0.259303,0.160869,-1304.804199,0.017050,0.000000
19.720001,1.195686,-1304.848755,0.006351,0.000653,0.016590,5.318678,0.270946,0.165900,-1304.848755,0.017501,0.000000
19.990002,1.218773,-1304.670776,0.006411,0.000674,0.017110,5.421372,0.276178,0.171104,-1304.670776,0.017952,0.000000
20.260000,1.153236,-1304.715210,0.006364,0.000684,0.017370,5.129852,0.261327,0.173704,-1304.715210,0.018403,0.000000
20.530001,1.238136,-1304.715210,0.006355,0.000710,0.018038,5.507505,0.280566,0.180384,-1304.715210,0.018854,0.000000
20.800001,1.304420,-1304.848755,0.006377,0.000726,0.018437,5.802352,0.295586,0.184374,-1304.848755,0.019304,0.000000
21.070002,1.326759,-1304.804199,0.006407,0.000744,0.018906,5.901721,0.300648,0.189056,-1304.804199,0.019747,0.000000
21.340000,1.358040,-1304.759766,0.006433,0.000759,0.019287,6.040863,0.307736,0.192871,-1304.759766,0.020198,0.000000
21.610001,1.400864,-1304.759766,0.006467,0.000777,0.019730,6.231353,0.317440,0.197295,-1304.759766,0.020648,0.000000
21.880001,1.448524,-1304.759766,0.006463,0.000797,0.020241,6.443359,0.328240,0.202412,-1304.759766,0.021100,0.000000
22.150002,1.440704,-1304.848755,0.006476,0.000813,0.020657,6.408573,0.326468,0.206572,-1304.848755,0.021550,0.000000
22.420002,1.469383,-1304.804199,0.006497,0.000831,0.021100,6.536143,0.332967,0.210997,-1304.804199,0.022002,0.000000
22.690001,1.452621,-1304.804199,0.006502,0.000843,0.021412,6.461583,0.329169,0.214119,-1304.804199,0.022452,0.000000
22.960001,1.603432,-1304.715210,0.006528,0.000861,0.021863,7.132421,0.363343,0.218627,-1304.715210,0.022904,0.000000
23.230001,1.667107,-1304.715210,0.006588,0.000880,0.022357,7.415661,0.377772,0.223570,-1304.715210,0.023354,0.000000
23.500002,1.623543,-1304.804199,0.006575,0.000887,0.022531,7.221879,0.367900,0.225307,-1304.804199,0.023797,0.000000
23.770000,1.788879,-1304.715210,0.006644,0.000919,0.023354,7.957333,0.405366,0.233543,-1304.715210,0.024248,0.000000
24.040001,1.764297,-1304.715210,0.006666,0.000937,0.023797,7.847987,0.399796,0.237968,-1304.715210,0.024699,0.000000
24.310001,1.812332,-1304.759766,0.006640,0.000956,0.024274,8.061656,0.410680,0.242737,-1304.759766,0.025149,0.000000
24.580002,1.873405,-1304.759766,0.006653,0.000976,0.024785,8.333323,0.424520,0.247854,-1304.759766,0.025601,0.000000
24.850000,1.941177,-1304.804199,0.006670,0.000994,0.025245,8.634789,0.439877,0.252449,-1304.804199,0.026051,0.000000
25.120001,1.982140,-1304.759766,0.006687,0.001007,0.025583,8.816998,0.449159,0.255832,-1304.759766,0.026503,0.000000
25.390001,1.989212,-1304.759766,0.006735,0.001021,0.025939,8.848457,0.450762,0.259386,-1304.759766,0.026953,0.000000
25.660002,2.106140,-1304.759766,0.006795,0.001046,0.026581,9.368579,0.477258,0.265806,-1304.759766,0.027405,0.000000
25.930000,2.129227,-1304.804199,0.006735,0.001064,0.027023,9.471273,0.482490,0.270226,-1304.804199,0.027855,0.000000
26.200001,2.205933,-1304.848755,0.006821,0.001083,0.027509,9.812478,0.499871,0.275086,-1304.848755,0.028298,0.000000
26.470001,2.226410,-1304.804199,0.006778,0.001097,0.027873,9.903566,0.504512,0.278727,-1304.804199,0.028749,0.000000
26.740002,2.336266,-1304.715210,0.006851,0.001115,0.028332,10.392228,0.529405,0.283322,-1304.715210,0.029200,0.000000
27.010002,2.396957,-1304.759766,0.006834,0.001131,0.028731,10.662199,0.543158,0.287311,-1304.759766,0.029650,0.000000
27.280001,2.398453,-1304.759766,0.006817,0.001142,0.029000,10.668851,0.543497,0.290002,-1304.759766,0.030101,0.000000
27.550001,2.641235,-1304.804199,0.006916,0.001175,0.029833,11.748801,0.598512,0.298325,-1304.804199,0.030552,0.000000
27.820002,2.592827,-1304.804199,0.006903,0.001190,0.030223,11.533470,0.587543,0.302228,-1304.804199,0.031003,0.000000
28.090002,2.609581,-1304.804199,0.006894,0.001206,0.030630,11.607996,0.591340,0.306304,-1304.804199,0.031454,0.000000
28.360001,2.727623,-1304.804199,0.006937,0.001224,0.031099,12.133073,0.618088,0.310986,-1304.804199,0.031905,0.000000
28.630001,2.805824,-1304.848755,0.006976,0.001241,0.031532,12.480929,0.635809,0.315323,-1304.848755,0.032348,0.000000
28.900002,2.829659,-1304.804199,0.006946,0.001254,0.031853,12.586949,0.641210,0.318533,-1304.804199,0.032798,0.000000
29.170002,2.953285,-1304.759766,0.006985,0.001276,0.032399,13.136868,0.669224,0.323995,-1304.759766,0.033250,0.000000
29.440001,3.113777,-1304.759766,0.006993,0.001298,0.032972,13.850773,0.705592,0.329721,-1304.759766,0.033700,0.000000
29.710001,3.121597,-1304.759766,0.007062,0.001314,0.033379,13.885558,0.707364,0.333794,-1304.759766,0.034151,0.000000
29.980001,3.200912,-1304.804199,0.007084,0.001332,0.033839,14.238370,0.725337,0.338392,-1304.804199,0.034602,0.000000
30.250002,3.214317,-1304.804199,0.007084,0.001344,0.034143,14.297997,0.728375,0.341428,-1304.804199,0.035053,0.000000
30.520002,3.374435,-1304.759766,0.007097,0.001366,0.034706,15.010239,0.764658,0.347064,-1304.759766,0.035504,0.000000
30.790001,3.422844,-1304.715210,0.007088,0.001382,0.035105,15.225571,0.775627,0.351053,-1304.715210,0.035955,0.000000
31.060001,3.426201,-1304.759766,0.007110,0.001393,0.035383,15.240502,0.776388,0.353827,-1304.759766,0.036406,0.000000
31.330002,3.654091,-1304.804199,0.007127,0.001419,0.036051,16.254208,0.828029,0.360507,-1304.804199,0.036849,0.000000
31.600002,3.706596,-1304.759766,0.007192,0.001436,0.036484,16.487764,0.839927,0.364841,-1304.759766,0.037299,0.000000
31.870001,3.788513,-1304.715210,0.007183,0.001457,0.037005,16.852148,0.858489,0.370045,-1304.715210,0.037751,0.000000
32.140003,3.810860,-1304.759766,0.007213,0.001470,0.037334,16.951550,0.863553,0.373342,-1304.759766,0.038201,0.000000
32.410000,3.922569,-1304.759766,0.007230,0.001488,0.037802,17.448460,0.888867,0.378024,-1304.759766,0.038652,0.000000
32.680000,4.056999,-1304.804199,0.007235,0.001506,0.038253,18.046434,0.919329,0.382532,-1304.804199,0.039103,0.000000
32.950001,3.985130,-1304.759766,0.007230,0.001516,0.038514,17.726746,0.903043,0.385136,-1304.759766,0.039554,0.000000
33.220001,4.268875,-1304.715210,0.007304,0.001542,0.039155,18.988905,0.967341,0.391551,-1304.715210,0.040005,0.000000
33.490002,4.332550,-1304.759766,0.007269,0.001560,0.039632,19.272144,0.981770,0.396324,-1304.759766,0.040456,0.000000
33.760002,4.289726,-1304.804199,0.007308,0.001572,0.039936,19.081656,0.972066,0.399359,-1304.804199,0.040898,0.000000
34.030003,4.433464,-1304.848755,0.007291,0.001591,0.040404,19.721033,1.004637,0.404041,-1304.848755,0.041349,0.000000
34.300003,4.564911,-1304.804199,0.007304,0.001609,0.040872,20.305738,1.034424,0.408723,-1304.804199,0.041800,0.000000
34.570004,4.570122,-1304.759766,0.007347,0.001623,0.041219,20.328917,1.035604,0.412194,-1304.759766,0.042251,0.000000
34.840000,4.512039,-1304.759766,0.007347,0.001631,0.041419,20.070553,1.022443,0.414189,-1304.759766,0.042702,0.000000
35.110001,4.877708,-1304.804199,0.007360,0.001658,0.042121,21.697130,1.105304,0.421213,-1304.804199,0.043153,0.000000
35.380001,4.999100,-1304.804199,0.007442,0.001680,0.042676,22.237106,1.132812,0.426762,-1304.804199,0.043604,0.000000
35.650002,5.059792,-1304.848755,0.007411,0.001698,0.043119,22.507076,1.146565,0.431187,-1304.848755,0.044055,0.000000
35.920002,5.121979,-1304.759766,0.007455,0.001714,0.043535,22.783699,1.160657,0.435346,-1304.759766,0.044506,0.000000
36.190002,5.073944,-1304.759766,0.007476,0.001729,0.043908,22.570030,1.149772,0.439078,-1304.759766,0.044948,0.000000
36.460003,5.346519,-1304.848755,0.007463,0.001749,0.044437,23.782507,1.211539,0.444366,-1304.848755,0.045399,0.000000
36.730003,5.379662,-1304.804199,0.007476,0.001765,0.044827,23.929930,1.219049,0.448268,-1304.804199,0.045850,0.000000
37.000000,5.527122,-1304.848755,0.007498,0.001786,0.045365,24.585869,1.252464,0.453646,-1304.848755,0.046301,0.000000
37.270000,5.631012,-1304.804199,0.007562,0.001803,0.045790,25.047993,1.276006,0.457897,-1304.804199,0.046752,0.000000
37.540001,5.679054,-1304.715210,0.007502,0.001819,0.046206,25.261696,1.286892,0.462060,-1304.715210,0.047203,0.000000
37.810001,5.567711,-1304.804199,0.007554,0.001827,0.046405,24.766415,1.261661,0.464055,-1304.804199,0.047654,0.000000
38.080002,5.958702,-1304.804199,0.007618,0.001858,0.047186,26.505630,1.350261,0.471859,-1304.804199,0.048105,0.000000
38.350002,6.050682,-1304.759766,0.007597,0.001877,0.047680,26.914778,1.371104,0.476802,-1304.759766,0.048556,0.000000
38.620003,6.185478,-1304.759766,0.007666,0.001895,0.048131,27.514381,1.401649,0.481310,-1304.759766,0.049007,0.000000
38.890003,6.214149,-1304.759766,0.007627,0.001911,0.048530,27.641918,1.408146,0.485299,-1304.759766,0.049449,0.000000
39.160004,6.382835,-1304.804199,0.007687,0.001932,0.049085,28.392269,1.446371,0.490852,-1304.804199,0.049900,0.000000
39.430000,6.338524,-1304.848755,0.007705,0.001947,0.049449,28.195162,1.436330,0.494493,-1304.848755,0.050351,0.000000
39.700001,6.438690,-1304.804199,0.007731,0.001966,0.049926,28.640724,1.459028,0.499262,-1304.804199,0.050802,0.000000
39.970001,6.608864,-1304.804199,0.007748,0.001984,0.050394,29.397694,1.497590,0.503944,-1304.804199,0.051253,0.000000
40.240002,6.806221,-1304.804199,0.007748,0.002005,0.050915,30.275583,1.542312,0.509148,-1304.804199,0.051704,0.000000
40.510002,6.744034,-1304.893188,0.007774,0.002017,0.051244,29.998960,1.528220,0.512444,-1304.893188,0.052155,0.000000
40.780003,6.781647,-1304.804199,0.007756,0.002034,0.051669,30.166271,1.536743,0.516695,-1304.804199,0.052606,0.000000
41.050003,7.024429,-1304.759766,0.007787,0.002055,0.052207,31.246222,1.591758,0.522070,-1304.759766,0.053057,0.000000
41.320004,7.101143,-1304.804199,0.007838,0.002075,0.052701,31.587461,1.609142,0.527013,-1304.804199,0.053499,0.000000
41.590000,6.933205,-1304.804199,0.007817,0.002086,0.052979,30.840435,1.571087,0.529787,-1304.804199,0.053950,0.000000
41.860001,7.264610,-1304.893188,0.007838,0.002109,0.053568,32.314602,1.646184,0.535684,-1304.893188,0.054401,0.000000
42.130001,7.423241,-1304.804199,0.007847,0.002128,0.054054,33.020222,1.682130,0.540544,-1304.804199,0.054852,0.000000
42.400002,7.480591,-1304.848755,0.007899,0.002146,0.054514,33.275330,1.695126,0.545138,-1304.848755,0.055303,0.000000
42.670002,7.336105,-1304.759766,0.007907,0.002155,0.054748,32.632626,1.662385,0.547481,-1304.759766,0.055754,0.000000
42.940002,7.524529,-1304.804199,0.007899,0.002173,0.055199,33.470776,1.705083,0.551989,-1304.804199,0.056205,0.000000
43.210003,7.813118,-1304.848755,0.007937,0.002196,0.055780,34.754486,1.770478,0.557799,-1304.848755,0.056656,0.000000
43.480003,7.813866,-1304.848755,0.008002,0.002213,0.056222,34.757809,1.770647,0.562223,-1304.848755,0.057107,0.000000
43.750004,7.871582,-1304.804199,0.007963,0.002232,0.056699,35.014545,1.783726,0.566992,-1304.804199,0.057549,0.000000
44.020000,7.719650,-1304.804199,0.008045,0.002243,0.056977,34.338718,1.749298,0.569767,-1304.804199,0.058000,0.000000
44.290001,7.953499,-1304.804199,0.008032,0.002259,0.057384,35.378929,1.802289,0.573843,-1304.804199,0.058451,0.000000
44.560001,8.313583,-1304.804199,0.008067,0.002282,0.057965,36.980667,1.883885,0.579653,-1304.804199,0.058902,0.000000
44.830002,8.254753,-1304.937622,0.008088,0.002297,0.058356,36.718975,1.870554,0.583555,-1304.937622,0.059353,0.000000
45.100002,8.433861,-1304.848755,0.008097,0.002320,0.058919,37.515686,1.911140,0.589195,-1304.848755,0.059804,0.000000
45.370003,8.377632,-1304.848755,0.008127,0.002337,0.059370,37.265568,1.898399,0.593702,-1304.848755,0.060255,0.000000
45.640003,8.446526,-1304.848755,0.008084,0.002356,0.059838,37.572021,1.914010,0.598384,-1304.848755,0.060706,0.000000
45.910004,8.624146,-1304.893188,0.008149,0.002375,0.060333,38.362114,1.954259,0.603327,-1304.893188,0.061157,0.000000
46.180000,8.722824,-1304.893188,0.008140,0.002393,0.060775,38.801060,1.976620,0.607752,-1304.893188,0.061608,0.000000
46.450001,8.656914,-1304.893188,0.008183,0.002407,0.061148,38.507877,1.961685,0.611480,-1304.893188,0.062050,0.000000
46.720001,8.636436,-1304.804199,0.008192,0.002422,0.061521,38.416786,1.957044,0.615212,-1304.804199,0.062501,0.000000
46.990002,9.002472,-1304.804199,0.008179,0.002446,0.062137,40.044994,2.039989,0.621366,-1304.804199,0.062952,0.000000
47.260002,8.965240,-1304.848755,0.008239,0.002462,0.062544,39.879383,2.031553,0.625443,-1304.848755,0.063403,0.000000
47.530003,9.089241,-1304.848755,0.008295,0.002481,0.063030,40.430962,2.059651,0.630299,-1304.848755,0.063854,0.000000
47.800003,9.055351,-1304.804199,0.008291,0.002496,0.063394,40.280212,2.051972,0.633943,-1304.804199,0.064305,0.000000
48.070004,9.215103,-1304.804199,0.008304,0.002514,0.063854,40.990826,2.088172,0.638538,-1304.804199,0.064756,0.000000
48.340004,9.280266,-1304.848755,0.008321,0.002530,0.064270,41.280685,2.102938,0.642702,-1304.848755,0.065207,0.000000
48.610001,9.139137,-1304.893188,0.008295,0.002540,0.064521,40.652912,2.070958,0.645215,-1304.893188,0.065658,0.000000
48.880001,9.810524,-1304.893188,0.008334,0.002573,0.065354,43.639389,2.223096,0.653542,-1304.893188,0.066100,0.000000
49.150002,9.628059,-1304.893188,0.008407,0.002589,0.065753,42.827747,2.181749,0.657531,-1304.893188,0.066551,0.000000
49.420002,9.585609,-1304.804199,0.008412,0.002604,0.066152,42.638920,2.172130,0.661520,-1304.804199,0.067002,0.000000
49.690002,9.728973,-1304.893188,0.008386,0.002623,0.066629,43.276634,2.204617,0.666289,-1304.893188,0.067453,0.000000
49.960003,9.858932,-1304.893188,0.008442,0.002641,0.067071,43.854721,2.234066,0.670714,-1304.893188,0.067904,0.000000
50.230003,9.771797,-1304.937622,0.008420,0.002653,0.067375,43.467125,2.214321,0.673749,-1304.937622,0.068355,0.000000
50.500004,10.122940,-1304.804199,0.008459,0.002675,0.067947,45.029087,2.293891,0.679472,-1304.804199,0.068806,0.000000
50.770004,10.433128,-1304.893188,0.008494,0.002697,0.068511,46.408875,2.364181,0.685108,-1304.893188,0.069257,0.000000
51.040001,10.313225,-1304.848755,0.008511,0.002714,0.068945,45.875515,2.337010,0.689445,-1304.848755,0.069708,0.000000
51.310001,10.358284,-1304.893188,0.008520,0.002731,0.069361,46.075947,2.347221,0.693609,-1304.893188,0.070150,0.000000
51.580002,10.265564,-1304.937622,0.008532,0.002745,0.069716,45.663509,2.326210,0.697163,-1304.937622,0.070601,0.000000
51.850002,10.580215,-1304.848755,0.008545,0.002766,0.070263,47.063148,2.397511,0.702628,-1304.848755,0.071052,0.000000
52.120003,10.628250,-1304.893188,0.008610,0.002782,0.070653,47.276817,2.408396,0.706530,-1304.893188,0.071503,0.000000
52.390003,10.489357,-1304.937622,0.008584,0.002793,0.070939,46.658989,2.376922,0.709392,-1304.937622,0.071954,0.000000
52.660004,11.055367,-1304.937622,0.008610,0.002818,0.071572,49.176727,2.505182,0.715720,-1304.937622,0.072405,0.000000
52.930004,11.074730,-1304.937622,0.008632,0.002836,0.072032,49.262859,2.509570,0.720318,-1304.937622,0.072856,0.000000
53.200001,11.230377,-1304.848755,0.008714,0.002856,0.072544,49.955212,2.544840,0.725436,-1304.848755,0.073307,0.000000
53.470001,11.080688,-1304.893188,0.008683,0.002868,0.072856,49.289364,2.510920,0.728558,-1304.893188,0.073758,0.000000
53.740002,11.266129,-1304.893188,0.008731,0.002887,0.073341,50.114243,2.552941,0.733414,-1304.893188,0.074209,0.000000
54.010002,11.505562,-1304.937622,0.008744,0.002905,0.073783,51.179295,2.607198,0.737835,-1304.937622,0.074651,0.000000
54.280003,11.166328,-1304.982178,0.008757,0.002914,0.074026,49.670311,2.530326,0.740265,-1304.982178,0.075102,0.000000
54.550003,11.852615,-1304.937622,0.008787,0.002942,0.074729,52.723064,2.685841,0.747290,-1304.937622,0.075553,0.000000
54.820004,11.918152,-1304.848755,0.008800,0.002960,0.075180,53.014587,2.700692,0.751797,-1304.848755,0.076004,0.000000
55.090004,11.672386,-1304.848755,0.008752,0.002972,0.075483,51.921368,2.645000,0.754833,-1304.848755,0.076454,0.000000
55.360004,11.907356,-1304.937622,0.008778,0.002990,0.075934,52.966564,2.698246,0.759345,-1304.937622,0.076906,0.000000
55.630001,12.083488,-1304.893188,0.008770,0.003008,0.076394,53.750042,2.738158,0.763939,-1304.893188,0.077356,0.000000
55.900002,12.181793,-1304.848755,0.008847,0.003023,0.076784,54.187321,2.760434,0.767842,-1304.848755,0.077808,0.000000
56.170002,11.856339,-1304.848755,0.008843,0.003029,0.076940,52.739628,2.686685,0.769405,-1304.848755,0.078258,0.000000
56.440002,12.519157,-1304.848755,0.008916,0.003056,0.077634,55.687992,2.836882,0.776343,-1304.848755,0.078701,0.000000
56.710003,12.805145,-1304.893188,0.008916,0.003078,0.078189,56.960133,2.901687,0.781891,-1304.893188,0.079152,0.000000
56.980003,12.891907,-1304.982178,0.008890,0.003097,0.078657,57.346066,2.921348,0.786573,-1304.982178,0.079603,0.000000
57.250004,12.885201,-1304.848755,0.008929,0.003113,0.079065,57.316235,2.919828,0.790649,-1304.848755,0.080054,0.000000
57.520004,12.879242,-1304.893188,0.009011,0.003129,0.079473,57.289730,2.918478,0.794726,-1304.893188,0.080505,0.000000
57.790001,13.284012,-1304.893188,0.009024,0.003149,0.079984,59.090237,3.010200,0.799843,-1304.893188,0.080955,0.000000
58.060001,13.260925,-1305.026611,0.009050,0.003166,0.080409,58.987541,3.004969,0.804093,-1305.026611,0.081407,0.000000
58.330002,13.254227,-1305.026611,0.008990,0.003181,0.080808,58.957745,3.003451,0.808083,-1305.026611,0.081857,0.000000
58.600002,13.671280,-1304.982178,0.009046,0.003202,0.081328,60.812889,3.097956,0.813283,-1304.982178,0.082309,0.000000
58.870003,13.679100,-1304.893188,0.009063,0.003219,0.081753,60.847675,3.099728,0.817534,-1304.893188,0.082751,0.000000
59.140003,13.986305,-1304.937622,0.009054,0.003238,0.082256,62.214191,3.169342,0.822564,-1304.937622,0.083202,0.000000
59.410004,14.215317,-1304.982178,0.009140,0.003258,0.082751,63.232887,3.221237,0.827507,-1304.982178,0.083653,0.000000
59.680004,14.391075,-1305.026611,0.009102,0.003276,0.083219,64.014702,3.261064,0.832189,-1305.026611,0.084103,0.000000
59.950005,14.552689,-1304.937622,0.009175,0.003294,0.083661,64.733589,3.297686,0.836613,-1304.937622,0.084555,0.000000
60.220001,14.655090,-1304.937622,0.009179,0.003310,0.084078,65.189095,3.320891,0.840777,-1304.937622,0.085005,0.000000
60.490002,14.916122,-1304.893188,0.009162,0.003330,0.084589,66.350227,3.380042,0.845894,-1304.893188,0.085456,0.000000
60.760002,14.936600,-1304.937622,0.009175,0.003345,0.084971,66.441315,3.384682,0.849709,-1304.937622,0.085907,0.000000
61.030003,15.144760,-1304.937622,0.009201,0.003365,0.085465,67.367256,3.431852,0.854652,-1304.937622,0.086358,0.000000
61.300003,15.282539,-1304.893188,0.009209,0.003381,0.085882,67.980133,3.463073,0.858815,-1304.893188,0.086809,0.000000
61.570004,15.825081,-1304.937622,0.009265,0.003403,0.086436,70.393478,3.586015,0.864364,-1304.937622,0.087252,0.000000
61.840004,15.707787,-1304.982178,0.009339,0.003417,0.086783,69.871727,3.559435,0.867835,-1304.982178,0.087702,0.000000
62.110004,15.757309,-1304.982178,0.009339,0.003433,0.087199,70.092010,3.570657,0.871994,-1304.982178,0.088154,0.000000
62.380001,16.453278,-1304.982178,0.009309,0.003456,0.087789,73.187836,3.728366,0.877891,-1304.982178,0.088604,0.000000
62.650002,16.526260,-1304.893188,0.009360,0.003473,0.088205,73.512474,3.744904,0.882055,-1304.893188,0.089056,0.000000
62.920002,16.252937,-1304.937622,0.009347,0.003483,0.088475,72.296677,3.682968,0.884746,-1304.937622,0.089506,0.000000
63.190002,17.084816,-1304.893188,0.009425,0.003507,0.089090,75.997055,3.871475,0.890900,-1304.893188,0.089957,0.000000
63.460003,17.306381,-1304.982178,0.009390,0.003525,0.089532,76.982628,3.921682,0.895324,-1304.982178,0.090408,0.000000
63.730003,17.561081,-1304.982178,0.009425,0.003544,0.090027,78.115593,3.979398,0.900268,-1304.982178,0.090859,0.000000
64.000000,17.389046,-1304.937622,0.009472,0.003554,0.090269,77.350342,3.940414,0.902694,-1304.937622,0.091302,0.000000
64.270004,17.755836,-1304.893188,0.009438,0.003572,0.090721,78.981903,4.023530,0.907205,-1304.893188,0.091753,0.000000
64.540001,18.597771,-1304.937622,0.009533,0.003595,0.091310,82.727013,4.214315,0.913102,-1304.937622,0.092203,0.000000
64.810005,18.743362,-1304.937622,0.009507,0.003612,0.091744,83.374641,4.247307,0.917440,-1304.937622,0.092655,0.000000
65.080002,18.955620,-1304.937622,0.009533,0.003629,0.092186,84.318810,4.295405,0.921860,-1304.937622,0.093105,0.000000
65.350006,18.893059,-1304.937622,0.009550,0.003642,0.092498,84.040520,4.281228,0.924983,-1304.937622,0.093556,0.000000
65.620003,19.180901,-1304.893188,0.009567,0.003654,0.092802,85.320908,4.346455,0.928018,-1304.893188,0.094007,0.000000
65.889999,20.245514,-1304.937622,0.009585,0.003681,0.093487,90.056541,4.587699,0.934869,-1304.937622,0.094458,0.000000
66.160004,20.525543,-1304.937622,0.009572,0.003696,0.093877,91.302177,4.651155,0.938771,-1304.937622,0.094909,0.000000
66.430000,21.177940,-1305.026611,0.009632,0.003720,0.094476,94.204185,4.798990,0.944755,-1305.026611,0.095360,0.000000
66.700005,21.235283,-1304.982178,0.009585,0.003736,0.094892,94.459259,4.811984,0.948919,-1304.982178,0.095803,0.000000
66.970001,21.671700,-1304.848755,0.009619,0.003754,0.095360,96.400536,4.910877,0.953601,-1304.848755,0.096253,0.000000
67.240005,22.234360,-1304.982178,0.009653,0.003773,0.095829,98.903374,5.038378,0.958286,-1304.982178,0.096704,0.000000
67.510002,22.788818,-1304.982178,0.009688,0.003791,0.096288,101.369728,5.164020,0.962881,-1304.982178,0.097155,0.000000
67.780006,22.919525,-1304.982178,0.009701,0.003805,0.096644,101.951141,5.193639,0.966435,-1304.982178,0.097606,0.000000
68.050003,23.227844,-1304.937622,0.009740,0.003822,0.097077,103.322609,5.263505,0.970773,-1304.937622,0.098057,0.000000
68.320000,24.321877,-1304.982178,0.009727,0.003845,0.097667,108.189110,5.511416,0.976669,-1304.982178,0.098508,0.000000
68.590004,24.737076,-1304.893188,0.009770,0.003861,0.098075,110.036011,5.605502,0.980746,-1304.893188,0.098959,0.000000
68.860001,25.312759,-1304.982178,0.009761,0.003882,0.098595,112.596779,5.735953,0.985950,-1304.982178,0.099410,0.000000
69.130005,25.613640,-1304.982178,0.009783,0.003894,0.098916,113.935158,5.804134,0.989160,-1304.982178,0.099852,0.000000
69.400002,26.317795,-1305.026611,0.009800,0.003912,0.099375,117.067398,5.963698,0.993754,-1305.026611,0.100304,0.000000
69.670006,26.852890,-1304.982178,0.009804,0.003928,0.099774,119.447624,6.084952,0.997744,-1304.982178,0.100754,0.000000
69.940002,27.035355,-1304.937622,0.009843,0.003939,0.100043,120.259262,6.126299,1.000431,-1304.937622,0.101205,0.000000
70.210007,28.938927,-1304.982178,0.009822,0.003972,0.100893,128.726776,6.557654,1.008932,-1304.982178,0.101656,0.000000
70.480003,29.440880,-1305.026611,0.009860,0.003987,0.101275,130.959579,6.671399,1.012747,-1305.026611,0.102107,0.000000
70.750000,29.856819,-1304.982178,0.009869,0.004003,0.101674,132.809769,6.765652,1.016736,-1304.982178,0.102558,0.000000
71.020004,30.566193,-1304.893188,0.009921,0.004022,0.102151,135.965210,6.926398,1.021505,-1304.893188,0.103009,0.000000
71.290001,31.477386,-1304.893188,0.009947,0.004039,0.102593,140.018402,7.132878,1.025930,-1304.893188,0.103460,0.000000
71.560005,31.887367,-1304.937622,0.009947,0.004051,0.102897,141.842087,7.225781,1.028965,-1304.937622,0.103902,0.000000
71.830002,32.687599,-1305.026611,0.009964,0.004073,0.103443,145.401703,7.407116,1.034427,-1305.026611,0.104353,0.000000
72.100006,34.428436,-1304.982178,0.009977,0.004095,0.104024,153.145340,7.801595,1.040237,-1304.982178,0.104804,0.000000
72.370003,35.114349,-1304.982178,0.009968,0.004112,0.104449,156.196426,7.957025,1.044487,-1304.982178,0.105255,0.000000
72.640007,36.068367,-1304.982178,0.010011,0.004130,0.104891,160.440109,8.173209,1.048908,-1304.982178,0.105706,0.000000
72.910004,36.545006,-1304.982178,0.009981,0.004143,0.105238,162.560303,8.281218,1.052379,-1304.982178,0.106157,0.000000
73.180000,37.869904,-1304.982178,0.010033,0.004163,0.105750,168.453751,8.581443,1.057496,-1304.982178,0.106608,0.000000
73.450005,38.791901,-1305.026611,0.010016,0.004180,0.106175,172.554993,8.790370,1.061746,-1305.026611,0.107059,0.000000
73.720001,39.200768,-1305.026611,0.010063,0.004191,0.106452,174.373718,8.883020,1.064521,-1305.026611,0.107510,0.000000
73.990005,41.052200,-1304.982178,0.010029,0.004216,0.107094,182.609314,9.302561,1.070936,-1304.982178,0.107961,0.000000
74.260002,42.095215,-1304.937622,0.010072,0.004234,0.107545,187.248871,9.538912,1.075448,-1304.937622,0.108403,0.000000
74.530006,43.373573,-1304.937622,0.010115,0.004255,0.108065,192.935287,9.828592,1.080652,-1304.937622,0.108854,0.000000
74.800003,44.138420,-1304.982178,0.010080,0.004267,0.108377,196.337494,10.001908,1.083771,-1304.982178,0.109305,0.000000
75.070007,45.080894,-1304.982178,0.010089,0.004286,0.108863,200.529831,10.215476,1.088630,-1304.982178,0.109756,0.000000
75.340004,46.478043,-1305.026611,0.010154,0.004303,0.109296,206.744659,10.532075,1.092964,-1305.026611,0.110207,0.000000
75.610001,46.802750,-1304.937622,0.010154,0.004311,0.109496,208.189026,10.605655,1.094959,-1304.937622,0.110658,0.000000
75.880005,48.848938,-1305.026611,0.010167,0.004337,0.110164,217.290924,11.069327,1.101635,-1305.026611,0.111109,0.000000
76.150002,50.169739,-1305.071045,0.010162,0.004357,0.110658,223.166138,11.368626,1.106582,-1305.071045,0.111560,0.000000
76.420006,50.794952,-1304.982178,0.010184,0.004368,0.110936,225.947235,11.510301,1.109357,-1304.982178,0.112011,0.000000
76.690002,52.129906,-1305.026611,0.010175,0.004387,0.111430,231.885406,11.812806,1.114300,-1305.026611,0.112453,0.000000
76.960007,53.486092,-1304.937622,0.010175,0.004405,0.111889,237.918015,12.120122,1.118894,-1304.937622,0.112904,0.000000
77.230003,54.688477,-1304.982178,0.010175,0.004419,0.112237,243.266495,12.392586,1.122365,-1304.982178,0.113355,0.000000
77.500000,55.396362,-1305.071045,0.010218,0.004432,0.112575,246.415329,12.552995,1.125745,-1305.071045,0.113806,0.000000
77.770004,57.229919,-1305.026611,0.010231,0.004454,0.113121,254.571396,12.968485,1.131210,-1305.026611,0.114257,0.000000
78.040001,58.976349,-1305.026611,0.010248,0.004475,0.113676,262.339905,13.364232,1.136759,-1305.026611,0.114708,0.000000
78.310005,60.425247,-1305.071045,0.010214,0.004494,0.114153,268.784912,13.692556,1.141528,-1305.071045,0.115159,0.000000
78.580002,61.549072,-1304.982178,0.010270,0.004510,0.114560,273.783936,13.947220,1.145604,-1304.982178,0.115610,0.000000
78.850006,62.570114,-1305.026611,0.010279,0.004521,0.114821,278.325775,14.178590,1.148208,-1305.026611,0.116061,0.000000
79.120003,64.302025,-1305.071045,0.010292,0.004541,0.115350,286.029694,14.571047,1.153496,-1305.071045,0.116503,0.000000
79.390007,65.714424,-1304.982178,0.010296,0.004560,0.115818,292.312347,14.891101,1.158182,-1304.982178,0.116954,0.000000
79.660004,67.135399,-1305.026611,0.010322,0.004576,0.116243,298.633179,15.213099,1.162428,-1305.026611,0.117405,0.000000
79.930000,67.473885,-1305.026611,0.010287,0.004576,0.116243,300.138824,15.289801,1.162428,-1305.026611,0.116477,0.000000
80.200005,67.204659,-1305.071045,0.010317,0.004575,0.116217,298.941254,15.228794,1.162171,-1305.071045,0.116243,0.000000
80.470001,66.902672,-1305.071045,0.010287,0.004575,0.116200,297.597961,15.160362,1.161997,-1305.071045,0.116243,0.000000
80.740005,66.650200,-1304.982178,0.010348,0.004574,0.116191,296.474884,15.103151,1.161910,-1304.982178,0.116243,0.000000
81.010002,66.429756,-1304.982178,0.010335,0.004574,0.116182,295.494324,15.053198,1.161823,-1304.982178,0.116243,0.000000
81.280006,66.257347,-1305.071045,0.010296,0.004574,0.116174,294.727386,15.014129,1.161736,-1305.071045,0.116243,0.000000
81.550003,66.103935,-1305.026611,0.010339,0.004573,0.116165,294.044983,14.979366,1.161649,-1305.026611,0.116243,0.000000
81.820007,65.965782,-1304.982178,0.010313,0.004573,0.116165,293.430450,14.948060,1.161649,-1304.982178,0.116243,0.000000
82.090004,65.831352,-1305.071045,0.010348,0.004573,0.116156,292.832489,14.917598,1.161562,-1305.071045,0.116243,0.000000
82.360001,65.711082,-1305.026611,0.010339,0.004573,0.116156,292.297485,14.890344,1.161562,-1305.026611,0.116243,0.000000
82.630005,65.595634,-1305.026611,0.010369,0.004573,0.116156,291.783966,14.864182,1.161562,-1305.026611,0.116243,0.000000
82.900002,65.508141,-1305.115601,0.010322,0.004573,0.116156,291.394775,14.844357,1.161562,-1305.115601,0.116243,0.000000
83.170006,65.417641,-1305.071045,0.010330,0.004573,0.116147,290.992187,14.823850,1.161474,-1305.071045,0.116243,0.000000
83.440002,65.336845,-1305.071045,0.010309,0.004573,0.116147,290.632812,14.805541,1.161474,-1305.071045,0.116243,0.000000
83.710007,65.264595,-1304.982178,0.010287,0.004573,0.116147,290.311432,14.789169,1.161474,-1304.982178,0.116243,0.000000
83.980003,65.171516,-1305.071045,0.010330,0.004573,0.116147,289.897369,14.768077,1.161474,-1305.071045,0.116243,0.000000
84.250008,65.119743,-1305.160034,0.010330,0.004573,0.116147,289.667084,14.756345,1.161474,-1305.160034,0.116243,0.000000
84.520004,65.053474,-1305.115601,0.010287,0.004573,0.116147,289.372314,14.741328,1.161474,-1305.115601,0.116243,0.000000
84.790001,65.013618,-1305.071045,0.010296,0.004572,0.116139,289.195007,14.732296,1.161387,-1305.071045,0.116243,0.000000
85.060005,64.940636,-1305.071045,0.010309,0.004572,0.116139,288.870361,14.715758,1.161387,-1305.071045,0.116243,0.000000
85.330002,64.876595,-1305.071045,0.010365,0.004572,0.116139,288.585510,14.701246,1.161387,-1305.071045,0.116243,0.000000
85.600006,64.824089,-1305.115601,0.010356,0.004572,0.116139,288.351959,14.689349,1.161387,-1305.115601,0.116243,0.000000
85.870003,64.779396,-1305.026611,0.010322,0.004572,0.116139,288.153137,14.679221,1.161387,-1305.026611,0.116243,0.000000
86.140007,64.745522,-1305.071045,0.010330,0.004572,0.116139,288.002472,14.671545,1.161387,-1305.071045,0.116243,0.000000
86.410004,64.707161,-1305.026611,0.010330,0.004572,0.116139,287.831818,14.662852,1.161387,-1305.026611,0.116243,0.000000
86.680000,64.646461,-1305.115601,0.010365,0.004572,0.116139,287.561829,14.649097,1.161387,-1305.115601,0.116243,0.000000
86.950005,64.617790,-1305.071045,0.010339,0.004572,0.116139,287.434296,14.642601,1.161387,-1305.071045,0.116243,0.000000
87.220001,64.560814,-1305.160034,0.010309,0.004572,0.116139,287.180847,14.629689,1.161387,-1305.160034,0.116243,0.000000
87.490005,64.532524,-1305.071045,0.010287,0.004572,0.116139,287.054993,14.623279,1.161387,-1305.071045,0.116243,0.000000
87.760002,64.505333,-1304.982178,0.010361,0.004572,0.116139,286.934052,14.617118,1.161387,-1304.982178,0.116243,0.000000
88.030006,64.468102,-1305.071045,0.010309,0.004572,0.116139,286.768433,14.608681,1.161387,-1305.071045,0.116243,0.000000
88.300003,64.424156,-1305.115601,0.010317,0.004572,0.116139,286.572968,14.598722,1.161387,-1305.115601,0.116243,0.000000
88.570007,64.382454,-1305.115601,0.010300,0.004572,0.116139,286.387451,14.589273,1.161387,-1305.115601,0.116243,0.000000
88.840004,64.360115,-1305.026611,0.010348,0.004572,0.116139,286.288086,14.584210,1.161387,-1305.026611,0.116243,0.000000
89.110001,64.331444,-1305.071045,0.010335,0.004572,0.116139,286.160553,14.577713,1.161387,-1305.071045,0.116243,0.000000
89.380005,64.319145,-1305.071045,0.010335,0.004572,0.116139,286.105835,14.574926,1.161387,-1305.071045,0.116243,0.000000
89.650002,64.279671,-1305.071045,0.010309,0.004572,0.116139,285.930267,14.565982,1.161387,-1305.071045,0.116243,0.000000
89.920006,64.242805,-1305.071045,0.010300,0.004572,0.116139,285.766266,14.557628,1.161387,-1305.071045,0.116243,0.000000
90.190002,64.208931,-1305.071045,0.010352,0.004572,0.116139,285.615601,14.549952,1.161387,-1305.071045,0.116243,0.000000
90.460007,64.186211,-1304.982178,0.010343,0.004572,0.116130,285.514526,14.544804,1.161300,-1304.982178,0.116243,0.000000
90.730003,64.179131,-1305.115601,0.010352,0.004572,0.116130,285.483032,14.543199,1.161300,-1305.115601,0.116243,0.000000
91.000008,64.138924,-1305.071045,0.010313,0.004572,0.116130,285.304169,14.534088,1.161300,-1305.071045,0.116243,0.000000
91.270004,64.104668,-1305.071045,0.010339,0.004572,0.116130,285.151794,14.526325,1.161300,-1305.071045,0.116243,0.000000
91.540001,64.094612,-1305.115601,0.010374,0.004572,0.116130,285.107086,14.524046,1.161300,-1305.115601,0.116243,0.000000
91.810005,64.061470,-1305.071045,0.010326,0.004572,0.116130,284.959656,14.516537,1.161300,-1305.071045,0.116243,0.000000
92.080002,64.058861,-1305.026611,0.010391,0.004572,0.116130,284.948059,14.515944,1.161300,-1305.026611,0.116243,0.000000
92.350006,64.023109,-1305.160034,0.010313,0.004572,0.116130,284.789001,14.507844,1.161300,-1305.160034,0.116243,0.000000
92.620003,64.007851,-1305.115601,0.010356,0.004572,0.116130,284.721130,14.504386,1.161300,-1305.115601,0.116243,0.000000
92.890007,63.972847,-1305.071045,0.010356,0.004572,0.116130,284.565430,14.496454,1.161300,-1305.071045,0.116243,0.000000
93.160004,63.961678,-1305.071045,0.010287,0.004572,0.116130,284.515747,14.493923,1.161300,-1305.071045,0.116243,0.000000
93.430008,63.940071,-1305.115601,0.010369,0.004572,0.116130,284.419647,14.489027,1.161300,-1305.115601,0.116243,0.000000
93.700005,63.935234,-1305.071045,0.010326,0.004572,0.116130,284.398132,14.487930,1.161300,-1305.071045,0.116243,0.000000
93.970001,63.904320,-1305.115601,0.010326,0.004572,0.116130,284.260620,14.480926,1.161300,-1305.115601,0.116243,0.000000
94.240005,63.881981,-1305.071045,0.010300,0.004572,0.116130,284.161255,14.475863,1.161300,-1305.071045,0.116243,0.000000
94.510002,63.873421,-1305.026611,0.010317,0.004572,0.116130,284.123169,14.473924,1.161300,-1305.026611,0.116243,0.000000
94.780006,63.867088,-1305.071045,0.010343,0.004572,0.116130,284.095001,14.472489,1.161300,-1305.071045,0.116243,0.000000
95.050003,63.844002,-1305.071045,0.010322,0.004572,0.116130,283.992310,14.467257,1.161300,-1305.071045,0.116243,0.000000
95.320007,63.820915,-1305.071045,0.010317,0.004572,0.116130,283.889618,14.462027,1.161300,-1305.071045,0.116243,0.000000
95.590004,63.783302,-1305.026611,0.010309,0.004572,0.116130,283.722290,14.453503,1.161300,-1305.026611,0.116243,0.000000
95.860008,63.788521,-1305.026611,0.010356,0.004572,0.116130,283.745514,14.454685,1.161300,-1305.026611,0.116243,0.000000
96.130005,63.766182,-1305.026611,0.010309,0.004572,0.116130,283.646149,14.449623,1.161300,-1305.026611,0.116243,0.000000
96.400002,63.743828,-1305.071045,0.010343,0.004572,0.116130,283.546722,14.444558,1.161300,-1305.071045,0.116243,0.000000
96.670006,63.728569,-1305.071045,0.010365,0.004572,0.116130,283.478821,14.441101,1.161300,-1305.071045,0.116243,0.000000
96.940002,63.708458,-1305.071045,0.010330,0.004572,0.116130,283.389374,14.436543,1.161300,-1305.071045,0.116243,0.000000
97.210007,63.698784,-1305.026611,0.010322,0.004572,0.116130,283.346344,14.434351,1.161300,-1305.026611,0.116243,0.000000
97.480003,63.683510,-1305.026611,0.010343,0.004572,0.116130,283.278412,14.430889,1.161300,-1305.026611,0.116243,0.000000
97.750008,63.659309,-1305.071045,0.010335,0.004572,0.116130,283.170746,14.425406,1.161300,-1305.071045,0.116243,0.000000
98.020004,63.635094,-1305.026611,0.010343,0.004572,0.116130,283.063019,14.419918,1.161300,-1305.026611,0.116243,0.000000
98.290001,63.628029,-1305.026611,0.010339,0.004572,0.116130,283.031616,14.418318,1.161300,-1305.026611,0.116243,0.000000
98.560005,63.624672,-1304.982178,0.010339,0.004572,0.116130,283.016663,14.417557,1.161300,-1304.982178,0.116243,0.000000
98.830002,63.601219,-1305.026611,0.010356,0.004572,0.116130,282.912354,14.412242,1.161300,-1305.026611,0.116243,0.000000
99.100006,63.586327,-1305.071045,0.010365,0.004572,0.116130,282.846100,14.408868,1.161300,-1305.071045,0.116243,0.000000
99.370003,63.567696,-1305.026611,0.010343,0.004572,0.116130,282.763245,14.404646,1.161300,-1305.026611,0.116243,0.000000
99.640007,63.558388,-1305.071045,0.010343,0.004572,0.116130,282.721832,14.402536,1.161300,-1305.071045,0.116243,0.000000
99.910004,63.557640,-1305.026611,0.010361,0.004572,0.116130,282.718506,14.402367,1.161300,-1305.026611,0.116243,0.000000
100.180008,63.543129,-1304.982178,0.010365,0.004572,0.116130,282.653961,14.399078,1.161300,-1304.982178,0.116243,0.000000
100.450005,63.516685,-1305.071045,0.010335,0.004572,0.116130,282.536316,14.393086,1.161300,-1305.071045,0.116243,0.000000
100.720001,63.489128,-1305.026611,0.010369,0.004572,0.116130,282.413757,14.386842,1.161300,-1305.026611,0.116243,0.000000
100.990005,63.496956,-1305.071045,0.010352,0.004572,0.116130,282.448578,14.388616,1.161300,-1305.071045,0.116243,0.000000
101.260002,63.483925,-1304.982178,0.010378,0.004572,0.116130,282.390594,14.385663,1.161300,-1304.982178,0.116243,0.000000
101.530006,63.464928,-1305.026611,0.010296,0.004572,0.116130,282.306091,14.381358,1.161300,-1305.026611,0.116243,0.000000
101.800003,63.445564,-1305.071045,0.010292,0.004572,0.116130,282.219971,14.376970,1.161300,-1305.071045,0.116243,0.000000
102.070007,63.439232,-1305.071045,0.010326,0.004572,0.116130,282.191803,14.375535,1.161300,-1305.071045,0.116243,0.000000
102.340004,63.439980,-1305.026611,0.010356,0.004572,0.116130,282.195129,14.375705,1.161300,-1305.026611,0.116243,0.000000
102.610008,63.423592,-1304.982178,0.010322,0.004572,0.116130,282.122223,14.371991,1.161300,-1304.982178,0.116243,0.000000
102.880005,63.407585,-1305.026611,0.010322,0.004572,0.116130,282.051025,14.368364,1.161300,-1305.026611,0.116243,0.000000
103.150002,63.387474,-1305.026611,0.010356,0.004572,0.116130,281.961578,14.363807,1.161300,-1305.026611,0.116243,0.000000
103.420006,63.380028,-1305.071045,0.010330,0.004572,0.116130,281.928436,14.362120,1.161300,-1305.071045,0.116243,0.000000
103.690002,63.383369,-1305.026611,0.010313,0.004572,0.116130,281.943298,14.362877,1.161300,-1305.026611,0.116243,0.000000
103.960007,63.366615,-1304.982178,0.010313,0.004572,0.116130,281.868774,14.359080,1.161300,-1304.982178,0.116243,0.000000
104.230003,63.353218,-1305.026611,0.010305,0.004572,0.116130,281.809174,14.356044,1.161300,-1305.026611,0.116243,0.000000
104.500008,63.339439,-1305.071045,0.010313,0.004572,0.116130,281.747894,14.352922,1.161300,-1305.071045,0.116243,0.000000
104.770004,63.335716,-1305.026611,0.010322,0.004572,0.116130,281.731323,14.352078,1.161300,-1305.026611,0.116243,0.000000
105.040009,63.321190,-1304.982178,0.010305,0.004572,0.116130,281.666718,14.348787,1.161300,-1304.982178,0.116243,0.000000
105.310005,63.304054,-1305.026611,0.010382,0.004572,0.116130,281.590485,14.344904,1.161300,-1305.026611,0.116243,0.000000
105.580002,63.312248,-1304.982178,0.010365,0.004572,0.116130,281.626953,14.346761,1.161300,-1304.982178,0.116243,0.000000
105.850006,63.299965,-1305.071045,0.010287,0.004572,0.116130,281.572296,14.343977,1.161300,-1305.071045,0.116243,0.000000
106.120003,63.307793,-1305.071045,0.010343,0.004572,0.116130,281.607117,14.345751,1.161300,-1305.071045,0.116243,0.000000
106.390007,63.276878,-1305.026611,0.010369,0.004572,0.116130,281.469604,14.338745,1.161300,-1305.026611,0.116243,0.000000
106.660004,63.270546,-1305.026611,0.010335,0.004572,0.116130,281.441437,14.337311,1.161300,-1305.026611,0.116243,0.000000
106.930008,63.262733,-1304.982178,0.010317,0.004572,0.116130,281.406708,14.335541,1.161300,-1304.982178,0.116243,0.000000
107.200005,63.255287,-1305.071045,0.010326,0.004572,0.116130,281.373566,14.333853,1.161300,-1305.071045,0.116243,0.000000
107.470009,63.245598,-1305.115601,0.010374,0.004572,0.116130,281.330475,14.331657,1.161300,-1305.115601,0.116243,0.000000
107.740005,63.218788,-1305.071045,0.010330,0.004572,0.116130,281.211212,14.325583,1.161300,-1305.071045,0.116243,0.000000
108.010002,63.218422,-1305.026611,0.010313,0.004572,0.116130,281.209595,14.325499,1.161300,-1305.026611,0.116243,0.000000
108.280006,63.212456,-1304.982178,0.010395,0.004572,0.116130,281.183044,14.324147,1.161300,-1304.982178,0.116243,0.000000
108.550003,63.204262,-1305.115601,0.010348,0.004572,0.116130,281.146606,14.322290,1.161300,-1305.115601,0.116243,0.000000
108.820007,63.186012,-1305.026611,0.010335,0.004572,0.116130,281.065430,14.318155,1.161300,-1305.026611,0.116243,0.000000
109.090004,63.166649,-1305.115601,0.010352,0.004572,0.116130,280.979279,14.313767,1.161300,-1305.115601,0.116243,0.000000
109.360008,63.155479,-1305.026611,0.010330,0.004572,0.116130,280.929596,14.311235,1.161300,-1305.026611,0.116243,0.000000
109.630005,63.163673,-1305.026611,0.010361,0.004572,0.116130,280.966064,14.313093,1.161300,-1305.026611,0.116243,0.000000
109.900002,63.143562,-1305.115601,0.010365,0.004572,0.116130,280.876587,14.308536,1.161300,-1305.115601,0.116243,0.000000
110.170006,63.138725,-1305.071045,0.010352,0.004572,0.116130,280.855072,14.307439,1.161300,-1305.071045,0.116243,0.000000
110.200005,63.140968,-1305.026611,0.010343,0.004572,0.116130,280.865051,14.307947,1.161300,-1305.026611,0.116243,0.000000