File: Data/Automembrane/AutoNoheat12-1-1_12132023_180629.csv
Time (sec),S:Load (lbs),S:HL1 (DIM),S:LVDT (in),S:Position (in),Ch:Position (mm),Ch:Load (N),Ch:Stress (MPa),Ch:Strain (mm/mm),Ch:HL1 (DIM),Set Point (),Cycles ()
0.010000,-0.007072,-1298.265503,-0.000004,-0.000000,-0.000000,-0.031460,-0.001603,-0.000000,-1298.265503,0.000182,0.000000
0.280000,-0.009682,-1298.221069,0.000034,-0.000000,-0.000000,-0.043066,-0.002194,-0.000000,-1298.221069,0.000182,0.000000
0.550000,-0.077827,-1298.265503,0.000009,0.000067,0.001699,-0.346194,-0.017636,0.016994,-1298.265503,0.003009,0.000000
0.820000,0.006699,-1298.265503,0.000246,0.000245,0.006227,0.029797,0.001518,0.062265,-1298.265503,0.007519,0.000000
1.090000,-0.037239,-1298.221069,0.000397,0.000424,0.010762,-0.165648,-0.008438,0.107620,-1298.221069,0.012011,0.000000
1.360000,-0.018250,-1298.265503,0.000690,0.000602,0.015280,-0.081178,-0.004135,0.152804,-1298.265503,0.016503,0.000000
1.630000,-0.001488,-1298.176514,0.000763,0.000778,0.019755,-0.006618,-0.000337,0.197553,-1298.176514,0.021013,0.000000
1.900000,-0.043571,-1298.310059,0.000992,0.000955,0.024248,-0.193816,-0.009873,0.242476,-1298.310059,0.025505,0.000000
2.170000,-0.002983,-1298.310059,0.001177,0.001131,0.028731,-0.013269,-0.000676,0.287311,-1298.310059,0.029997,0.000000
2.440000,-0.052132,-1298.310059,0.001406,0.001314,0.033388,-0.231893,-0.011813,0.333881,-1298.310059,0.034507,0.000000
2.710000,-0.029793,-1298.265503,0.001582,0.001488,0.037794,-0.132525,-0.006751,0.377937,-1298.265503,0.038999,0.000000
2.980000,-0.007446,-1298.221069,0.001772,0.001660,0.042173,-0.033123,-0.001687,0.421728,-1298.221069,0.043509,0.000000
3.250000,-0.018250,-1298.310059,0.001932,0.001844,0.046830,-0.081178,-0.004135,0.468301,-1298.310059,0.048001,0.000000
3.520000,0.027557,-1298.310059,0.002117,0.002020,0.051305,0.122581,0.006245,0.513050,-1298.310059,0.052493,0.000000
3.790000,0.006332,-1298.310059,0.002358,0.002198,0.055832,0.028168,0.001435,0.558317,-1298.310059,0.057002,0.000000
4.060000,-0.010429,-1298.310059,0.002514,0.002374,0.060298,-0.046392,-0.002363,0.602979,-1298.310059,0.061495,0.000000
4.330000,-0.007072,-1298.310059,0.002708,0.002549,0.064747,-0.031460,-0.001603,0.647471,-1298.310059,0.065987,0.000000
4.600000,-0.052132,-1298.398926,0.002850,0.002727,0.069274,-0.231893,-0.011813,0.692738,-1298.398926,0.070497,0.000000
4.870000,-0.009308,-1298.354492,0.002984,0.002903,0.073749,-0.041403,-0.002109,0.737487,-1298.354492,0.074989,0.000000
5.140000,0.001862,-1298.265503,0.003225,0.003081,0.078250,0.008281,0.000422,0.782497,-1298.265503,0.079481,0.000000
5.410000,-0.013031,-1298.354492,0.003436,0.003259,0.082776,-0.057965,-0.002953,0.827764,-1298.354492,0.083991,0.000000
5.680000,0.017876,-1298.310059,0.003574,0.003436,0.087286,0.079515,0.004051,0.872861,-1298.310059,0.088483,0.000000
5.950000,-0.005585,-1298.398926,0.003773,0.003618,0.091900,-0.024842,-0.001266,0.918999,-1298.398926,0.092975,0.000000
6.220000,-0.010803,-1298.354492,0.004005,0.003787,0.096184,-0.048055,-0.002448,0.961836,-1298.354492,0.097485,0.000000
6.490000,-0.009308,-1298.310059,0.004096,0.003962,0.100624,-0.041403,-0.002109,1.006241,-1298.310059,0.101977,0.000000
6.760000,-0.029419,-1298.265503,0.004294,0.004145,0.105281,-0.130862,-0.006666,1.052810,-1298.265503,0.106469,0.000000
7.030000,-0.015640,-1298.310059,0.004510,0.004318,0.109678,-0.069571,-0.003544,1.096779,-1298.310059,0.110979,0.000000
7.300000,-0.016754,-1298.354492,0.004695,0.004497,0.114213,-0.074526,-0.003797,1.142134,-1298.354492,0.115471,0.000000
7.570000,0.005585,-1298.354492,0.004850,0.004675,0.118749,0.024842,0.001266,1.187492,-1298.354492,0.119963,0.000000
7.840000,0.031281,-1298.354492,0.005083,0.004856,0.123345,0.139143,0.007088,1.233452,-1298.354492,0.124473,0.000000
8.110001,0.012291,-1298.354492,0.005234,0.005031,0.127777,0.054673,0.002785,1.277769,-1298.354492,0.128965,0.000000
8.380000,0.024200,-1298.354492,0.005372,0.005201,0.132104,0.107649,0.005484,1.321042,-1298.354492,0.133457,0.000000
8.650001,-0.027931,-1298.354492,0.005631,0.005382,0.136701,-0.124244,-0.006329,1.367006,-1298.354492,0.137967,0.000000
8.920000,-0.001122,-1298.354492,0.005795,0.005563,0.141306,-0.004989,-0.000254,1.413056,-1298.354492,0.142459,0.000000
9.190001,-0.005959,-1298.398926,0.005959,0.005737,0.145720,-0.026505,-0.001350,1.457196,-1298.398926,0.146951,0.000000
9.460000,-0.023834,-1298.354492,0.006191,0.005913,0.150186,-0.106020,-0.005401,1.501861,-1298.354492,0.151461,0.000000
9.730000,0.027184,-1298.354492,0.006372,0.006091,0.154713,0.120918,0.006160,1.547129,-1298.354492,0.155953,0.000000
10.000000,-0.000374,-1298.443481,0.006579,0.006273,0.159344,-0.001663,-0.000085,1.593437,-1298.443481,0.160445,0.000000
10.270000,0.015640,-1298.443481,0.006726,0.006447,0.163749,0.069571,0.003544,1.637493,-1298.443481,0.164955,0.000000
10.540001,0.003349,-1298.398926,0.006903,0.006625,0.168268,0.014898,0.000759,1.682677,-1298.398926,0.169447,0.000000
10.810000,-0.027184,-1298.354492,0.007123,0.006799,0.172699,-0.120918,-0.006160,1.726991,-1298.354492,0.173939,0.000000
11.080001,0.024948,-1298.354492,0.007317,0.006979,0.177269,0.110975,0.005653,1.772693,-1298.354492,0.178449,0.000000
11.350000,-0.006332,-1298.443481,0.007489,0.007155,0.181727,-0.028168,-0.001435,1.817268,-1298.443481,0.182941,0.000000
11.620001,-0.011543,-1298.443481,0.007627,0.007331,0.186210,-0.051347,-0.002616,1.862104,-1298.443481,0.187433,0.000000
11.890000,0.024574,-1298.354492,0.007881,0.007507,0.190677,0.109312,0.005569,1.906766,-1298.354492,0.191943,0.000000
12.160001,0.000374,-1298.443481,0.008024,0.007688,0.195264,0.001663,0.000085,1.952642,-1298.443481,0.196435,0.000000
12.430000,0.018242,-1298.398926,0.008248,0.007860,0.199644,0.081144,0.004134,1.996437,-1298.398926,0.200927,0.000000
12.700001,0.013405,-1298.443481,0.008416,0.008041,0.204240,0.059628,0.003038,2.042401,-1298.443481,0.205437,0.000000
12.970000,-0.006332,-1298.443481,0.008606,0.008217,0.208724,-0.028168,-0.001435,2.087237,-1298.443481,0.209929,0.000000
13.240001,-0.001122,-1298.443481,0.008795,0.008394,0.213207,-0.004989,-0.000254,2.132073,-1298.443481,0.214421,0.000000
13.510000,-0.024948,-1298.443481,0.008964,0.008571,0.217708,-0.110975,-0.005653,2.177083,-1298.443481,0.218931,0.000000
13.780001,0.028297,-1298.487915,0.009123,0.008749,0.222218,0.125873,0.006412,2.222176,-1298.487915,0.223423,0.000000
14.050000,0.033516,-1298.443481,0.009317,0.008927,0.226753,0.149086,0.007595,2.267534,-1298.443481,0.227933,0.000000
14.320001,0.028297,-1298.576904,0.009516,0.009103,0.231228,0.125873,0.006412,2.312283,-1298.576904,0.232425,0.000000
14.590001,0.027557,-1298.443481,0.009697,0.009281,0.235729,0.122581,0.006245,2.357289,-1298.443481,0.236917,0.000000
14.860001,-0.017502,-1298.443481,0.009873,0.009454,0.240126,-0.077852,-0.003966,2.401258,-1298.443481,0.241427,0.000000
15.130001,0.021599,-1298.443481,0.010072,0.009639,0.244835,0.096076,0.004894,2.448350,-1298.443481,0.245919,0.000000
15.400001,0.008560,-1298.443481,0.010231,0.009809,0.249154,0.038078,0.001940,2.491536,-1298.443481,0.250411,0.000000
15.670001,-0.024948,-1298.576904,0.010425,0.009987,0.253672,-0.110975,-0.005653,2.536720,-1298.576904,0.254921,0.000000
15.940001,0.035004,-1298.443481,0.010602,0.010162,0.258121,0.155704,0.007932,2.581208,-1298.443481,0.259413,0.000000
16.210001,0.005211,-1298.532349,0.010818,0.010345,0.262769,0.023179,0.001181,2.627694,-1298.532349,0.263905,0.000000
16.480001,0.038353,-1298.487915,0.010994,0.010520,0.267218,0.170603,0.008691,2.672181,-1298.487915,0.268415,0.000000
16.750000,0.048409,-1298.443481,0.011137,0.010699,0.271745,0.215332,0.010970,2.717449,-1298.443481,0.272907,0.000000
17.020000,0.001488,-1298.532349,0.011365,0.010869,0.276073,0.006618,0.000337,2.760725,-1298.532349,0.277399,0.000000
17.290001,0.039101,-1298.487915,0.011533,0.011052,0.280721,0.173928,0.008860,2.807207,-1298.487915,0.281909,0.000000
17.560001,0.013031,-1298.487915,0.011740,0.011229,0.285204,0.057965,0.002953,2.852043,-1298.487915,0.286401,0.000000
17.830000,0.035744,-1298.532349,0.011917,0.011401,0.289593,0.158996,0.008100,2.895925,-1298.532349,0.290893,0.000000
18.100000,0.041336,-1298.487915,0.012094,0.011582,0.294180,0.183872,0.009367,2.941802,-1298.487915,0.295403,0.000000
18.370001,0.027557,-1298.576904,0.012223,0.011759,0.298681,0.122581,0.006245,2.986812,-1298.576904,0.299895,0.000000
18.640001,0.090858,-1298.532349,0.012417,0.011932,0.303069,0.404159,0.020589,3.030690,-1298.532349,0.304387,0.000000
18.910002,0.201454,-1298.487915,0.012572,0.012112,0.307648,0.896113,0.045650,3.076480,-1298.487915,0.308897,0.000000
19.180000,0.407005,-1298.532349,0.012801,0.012287,0.312080,1.810450,0.092229,3.120797,-1298.532349,0.313389,0.000000
19.450001,0.625214,-1298.487915,0.012956,-0.000011,-0.000286,2.781089,0.141675,-0.002861,-1298.487915,-0.000034,0.000000
19.720001,0.581276,-1298.576904,0.012947,-0.000011,-0.000286,2.585644,0.131719,-0.002861,-1298.576904,-0.000034,0.000000
19.990002,0.585365,-1298.576904,0.012952,-0.000011,-0.000286,2.603835,0.132646,-0.002861,-1298.576904,0.000087,0.000000
20.260000,0.561539,-1298.576904,0.012943,-0.000011,-0.000286,2.497849,0.127246,-0.002861,-1298.576904,0.000538,0.000000
20.530001,0.565636,-1298.487915,0.012991,-0.000011,-0.000286,2.516073,0.128175,-0.002861,-1298.487915,0.000989,0.000000
20.800001,0.545151,-1298.576904,0.012956,-0.000011,-0.000286,2.424952,0.123533,-0.002861,-1298.576904,0.001440,0.000000
21.070002,0.541054,-1298.576904,0.012973,-0.000011,-0.000286,2.406727,0.122605,-0.002861,-1298.576904,0.001891,0.000000
21.340000,0.808044,-1298.665894,0.013042,0.000055,0.001405,3.594361,0.183105,0.014050,-1298.665894,0.002342,0.000000
21.610001,0.796135,-1298.576904,0.012995,0.000072,0.001839,3.541385,0.180407,0.018387,-1298.576904,0.002784,0.000000
21.880001,0.886620,-1298.532349,0.013042,0.000090,0.002281,3.943881,0.200911,0.022812,-1298.532349,0.003235,0.000000
22.150002,0.955132,-1298.576904,0.013016,0.000106,0.002697,4.248637,0.216436,0.026971,-1298.576904,0.003686,0.000000
22.420002,0.984550,-1298.576904,0.013055,0.000121,0.003079,4.379499,0.223102,0.030786,-1298.576904,0.004137,0.000000
22.690001,1.063866,-1298.665894,0.013090,0.000141,0.003590,4.732311,0.241075,0.035904,-1298.665894,0.004588,0.000000
22.960001,1.099991,-1298.576904,0.013124,0.000153,0.003876,4.893003,0.249261,0.038765,-1298.576904,0.005039,0.000000
23.230001,1.112648,-1298.532349,0.013142,0.000159,0.004033,4.949306,0.252130,0.040328,-1298.532349,0.005490,0.000000
23.500002,1.284683,-1298.621338,0.013137,0.000196,0.004978,5.714556,0.291113,0.049779,-1298.621338,0.005941,0.000000
23.770000,1.212814,-1298.665894,0.013133,0.000199,0.005056,5.394867,0.274828,0.050562,-1298.665894,0.006392,0.000000
24.040001,1.313728,-1298.576904,0.013198,0.000213,0.005420,5.843755,0.297695,0.054203,-1298.576904,0.006843,0.000000
24.310001,1.588913,-1298.621338,0.013150,0.000244,0.006201,7.067838,0.360053,0.062008,-1298.621338,0.007285,0.000000
24.580002,1.629501,-1298.665894,0.013185,0.000263,0.006669,7.248384,0.369250,0.066690,-1298.665894,0.007736,0.000000
24.850000,1.750153,-1298.665894,0.013223,0.000284,0.007207,7.785068,0.396590,0.072068,-1298.665894,0.008187,0.000000
25.120001,1.797440,-1298.665894,0.013232,0.000300,0.007623,7.995410,0.407306,0.076232,-1298.665894,0.008638,0.000000
25.390001,1.909149,-1298.710327,0.013271,0.000319,0.008091,8.492320,0.432619,0.080913,-1298.710327,0.009089,0.000000
25.660002,1.933731,-1298.665894,0.013297,0.000335,0.008508,8.601665,0.438190,0.085077,-1298.665894,0.009540,0.000000
25.930000,2.040230,-1298.621338,0.013254,0.000351,0.008915,9.075396,0.462323,0.089153,-1298.621338,0.009991,0.000000
26.200001,2.144493,-1298.621338,0.013267,0.000361,0.009175,9.539182,0.485949,0.091753,-1298.621338,0.010441,0.000000
26.470001,2.384674,-1298.710327,0.013284,0.000387,0.009835,10.607560,0.540375,0.098347,-1298.710327,0.010893,0.000000
26.740002,2.471809,-1298.665894,0.013344,0.000406,0.010303,10.995157,0.560120,0.103029,-1298.665894,0.011335,0.000000
27.010002,2.596176,-1298.621338,0.013323,0.000425,0.010788,11.548368,0.588302,0.107885,-1298.621338,0.011786,0.000000
27.280001,2.561180,-1298.621338,0.013370,0.000437,0.011109,11.392698,0.580372,0.111094,-1298.621338,0.012237,0.000000
27.550001,2.743637,-1298.754761,0.013353,0.000458,0.011638,12.204308,0.621717,0.116382,-1298.754761,0.012688,0.000000
27.820002,2.923866,-1298.799316,0.013361,0.000480,0.012193,13.006007,0.662558,0.121934,-1298.799316,0.013139,0.000000
28.090002,3.011749,-1298.710327,0.013405,0.000496,0.012610,13.396930,0.682472,0.126098,-1298.710327,0.013590,0.000000
28.360001,3.102234,-1298.665894,0.013465,0.000511,0.012991,13.799425,0.702976,0.129913,-1298.665894,0.014040,0.000000
28.630001,3.271660,-1298.710327,0.013465,0.000532,0.013503,14.553070,0.741369,0.135030,-1298.710327,0.014492,0.000000
28.900002,3.391937,-1298.665894,0.013482,0.000551,0.014006,15.088091,0.768624,0.140060,-1298.665894,0.014942,0.000000
29.170002,3.394547,-1298.799316,0.013521,0.000566,0.014379,15.099697,0.769215,0.143788,-1298.799316,0.015385,0.000000
29.440001,3.536423,-1298.710327,0.013530,0.000586,0.014873,15.730794,0.801365,0.148731,-1298.710327,0.015836,0.000000
29.710001,3.568817,-1298.665894,0.013555,0.000595,0.015116,15.874891,0.808706,0.151157,-1298.665894,0.016287,0.000000
29.980001,3.803787,-1298.710327,0.013555,0.000618,0.015688,16.920090,0.861951,0.156884,-1298.710327,0.016738,0.000000
30.250002,3.919594,-1298.710327,0.013573,0.000636,0.016157,17.435225,0.888193,0.161566,-1298.710327,0.017189,0.000000
30.520002,4.096100,-1298.754761,0.013555,0.000654,0.016607,18.220362,0.928190,0.166074,-1298.754761,0.017640,0.000000
30.790001,4.239456,-1298.799316,0.013616,0.000674,0.017119,18.858044,0.960675,0.171191,-1298.799316,0.018091,0.000000
31.060001,4.318405,-1298.754761,0.013555,0.000693,0.017613,19.209225,0.978565,0.176134,-1298.754761,0.018541,0.000000
31.330002,4.376122,-1298.754761,0.013633,0.000709,0.018021,19.465961,0.991643,0.180210,-1298.754761,0.018992,0.000000
31.600002,4.538475,-1298.754761,0.013637,0.000725,0.018411,20.188145,1.028433,0.184112,-1298.754761,0.019443,0.000000
31.870001,4.694496,-1298.799316,0.013659,0.000745,0.018923,20.882162,1.063788,0.189230,-1298.799316,0.019886,0.000000
32.140003,4.833023,-1298.843750,0.013659,0.000762,0.019365,21.498360,1.095179,0.193654,-1298.843750,0.020337,0.000000
32.410000,4.852013,-1298.710327,0.013702,0.000774,0.019652,21.582830,1.099482,0.196516,-1298.710327,0.020787,0.000000
32.680000,5.184914,-1298.754761,0.013715,0.000799,0.020284,23.063648,1.174918,0.202844,-1298.754761,0.021239,0.000000
32.950001,5.302208,-1298.754761,0.013676,0.000819,0.020805,23.585400,1.201498,0.208048,-1298.754761,0.021689,0.000000
33.220001,5.409081,-1298.843750,0.013728,0.000836,0.021230,24.060791,1.225715,0.212299,-1298.843750,0.022140,0.000000
33.490002,5.502922,-1298.799316,0.013745,0.000853,0.021655,24.478220,1.246980,0.216549,-1298.799316,0.022591,0.000000
33.760002,5.543510,-1298.754761,0.013758,0.000867,0.022010,24.658766,1.256177,0.220103,-1298.754761,0.023042,0.000000
34.030003,5.666389,-1298.754761,0.013732,0.000880,0.022357,25.205359,1.284022,0.223574,-1298.754761,0.023493,0.000000
34.300003,5.844383,-1298.799316,0.013728,0.000898,0.022808,25.997114,1.324356,0.228082,-1298.799316,0.023936,0.000000
34.570004,6.111000,-1298.843750,0.013780,0.000920,0.023380,27.183086,1.384772,0.233804,-1298.843750,0.024386,0.000000
34.840000,6.140045,-1298.843750,0.013801,0.000936,0.023771,27.312284,1.391354,0.237707,-1298.843750,0.024838,0.000000
35.110001,6.376503,-1298.843750,0.013814,0.000959,0.024369,28.364101,1.444936,0.243690,-1298.843750,0.025288,0.000000
35.380001,6.359001,-1298.843750,0.013836,0.000975,0.024759,28.286249,1.440970,0.247593,-1298.843750,0.025740,0.000000
35.650002,6.449493,-1298.754761,0.013810,0.000993,0.025210,28.688780,1.461476,0.252104,-1298.754761,0.026190,0.000000
35.920002,6.585403,-1298.843750,0.013831,0.001007,0.025575,29.293337,1.492274,0.255745,-1298.843750,0.026641,0.000000
36.190002,6.752228,-1298.799316,0.013870,0.001026,0.026060,30.035410,1.530077,0.260601,-1298.799316,0.027092,0.000000
36.460003,6.965973,-1298.843750,0.013892,0.001048,0.026607,30.986195,1.578512,0.266067,-1298.843750,0.027543,0.000000
36.730003,6.835266,-1298.799316,0.013887,0.001059,0.026893,30.404781,1.548893,0.268928,-1298.799316,0.027994,0.000000
37.000000,7.140984,-1298.843750,0.013913,0.001083,0.027500,31.764681,1.618170,0.274999,-1298.843750,0.028437,0.000000
37.270000,7.042679,-1298.888306,0.013935,0.001092,0.027725,31.327400,1.595894,0.277255,-1298.888306,0.028887,0.000000
37.540001,7.334618,-1298.843750,0.013956,0.001114,0.028298,32.626007,1.662048,0.282978,-1298.843750,0.029338,0.000000
37.810001,7.311531,-1298.843750,0.013987,0.001129,0.028679,32.523315,1.656817,0.286793,-1298.843750,0.029789,0.000000
38.080002,7.493248,-1298.843750,0.013948,0.001148,0.029156,33.331631,1.697994,0.291562,-1298.843750,0.030240,0.000000
38.350002,7.787422,-1298.843750,0.013939,0.001170,0.029729,34.640182,1.764655,0.297288,-1298.843750,0.030691,0.000000
38.620003,7.657837,-1298.888306,0.014008,0.001184,0.030084,34.063759,1.735291,0.300842,-1298.888306,0.031142,0.000000
38.890003,7.710342,-1298.888306,0.013982,0.001201,0.030518,34.297318,1.747189,0.305180,-1298.888306,0.031593,0.000000
39.160004,7.742737,-1298.888306,0.014021,0.001214,0.030847,34.441414,1.754529,0.308473,-1298.888306,0.032044,0.000000
39.430000,7.954994,-1298.843750,0.013978,0.001237,0.031428,35.385582,1.802627,0.314283,-1298.843750,0.032487,0.000000
39.700001,7.992973,-1298.843750,0.014056,0.001254,0.031862,35.554520,1.811234,0.318620,-1298.843750,0.032937,0.000000
39.970001,8.251770,-1298.932739,0.014025,0.001274,0.032365,36.705708,1.869878,0.323650,-1298.932739,0.033388,0.000000
40.240002,8.267036,-1298.932739,0.014073,0.001293,0.032842,36.773613,1.873337,0.328419,-1298.932739,0.033839,0.000000
40.510002,8.210068,-1298.888306,0.014034,0.001306,0.033163,36.520206,1.860428,0.331629,-1298.888306,0.034290,0.000000
40.780003,8.482643,-1298.888306,0.014112,0.001327,0.033709,37.732681,1.922194,0.337094,-1298.888306,0.034741,0.000000
41.050003,8.404816,-1298.843750,0.014056,0.001344,0.034125,37.386486,1.904559,0.341254,-1298.843750,0.035192,0.000000
41.320004,8.115486,-1298.932739,0.014077,0.001351,0.034307,36.099483,1.838995,0.343074,-1298.932739,0.035643,0.000000
41.590000,8.351944,-1298.932739,0.014094,0.001369,0.034767,37.151302,1.892578,0.347673,-1298.932739,0.036094,0.000000
41.860001,8.719475,-1298.888306,0.014133,0.001395,0.035426,38.786160,1.975861,0.354262,-1298.888306,0.036536,0.000000
42.130001,8.674789,-1298.888306,0.014116,0.001417,0.035981,38.587391,1.965735,0.359815,-1298.888306,0.036988,0.000000
42.400002,9.018486,-1298.932739,0.014142,0.001439,0.036554,40.116230,2.043618,0.365538,-1298.932739,0.037438,0.000000
42.670002,8.870285,-1298.888306,0.014163,0.001454,0.036944,39.456997,2.010035,0.369440,-1298.888306,0.037889,0.000000
42.940002,8.806610,-1298.977173,0.014146,0.001471,0.037352,39.173759,1.995606,0.373516,-1298.977173,0.038340,0.000000
43.210003,8.926514,-1298.888306,0.014150,0.001488,0.037785,39.707115,2.022777,0.377854,-1298.888306,0.038791,0.000000
43.480003,9.049393,-1298.932739,0.014198,0.001505,0.038219,40.253708,2.050622,0.382187,-1298.932739,0.039242,0.000000
43.750004,9.059822,-1298.888306,0.014232,0.001522,0.038652,40.300102,2.052985,0.386525,-1298.888306,0.039693,0.000000
44.020000,9.145470,-1298.888306,0.014202,0.001540,0.039112,40.681080,2.072393,0.391120,-1298.888306,0.040144,0.000000
44.290001,9.055351,-1299.021729,0.014241,0.001556,0.039520,40.280212,2.051972,0.395196,-1299.021729,0.040595,0.000000
44.560001,9.509277,-1298.977173,0.014237,0.001578,0.040092,42.299377,2.154833,0.400919,-1298.977173,0.041037,0.000000
44.830002,9.363678,-1298.888306,0.014198,0.001595,0.040526,41.651718,2.121840,0.405256,-1298.888306,0.041488,0.000000
45.100002,8.973801,-1298.977173,0.014245,0.001598,0.040586,39.917458,2.033492,0.405862,-1298.977173,0.041939,0.000000
45.370003,9.445229,-1298.977173,0.014258,0.001622,0.041202,42.014477,2.140320,0.412020,-1298.977173,0.042390,0.000000
45.640003,9.321228,-1298.977173,0.014237,0.001637,0.041584,41.462894,2.112221,0.415835,-1298.977173,0.042841,0.000000
45.910004,9.610931,-1298.977173,0.014280,0.001663,0.042234,42.751556,2.177868,0.422341,-1298.977173,0.043292,0.000000
46.180000,9.795631,-1298.888306,0.014284,0.001685,0.042789,43.573143,2.219722,0.427890,-1298.888306,0.043743,0.000000
46.450001,9.662323,-1298.888306,0.014319,0.001698,0.043136,42.980160,2.189514,0.431361,-1298.888306,0.044194,0.000000
46.720001,9.700676,-1298.977173,0.014353,0.001717,0.043622,43.150761,2.198205,0.436217,-1298.977173,0.044645,0.000000
46.990002,9.597153,-1298.977173,0.014314,0.001734,0.044038,42.690266,2.174746,0.440380,-1298.977173,0.045087,0.000000
47.260002,9.876434,-1298.977173,0.014310,0.001754,0.044550,43.932575,2.238032,0.445497,-1298.977173,0.045538,0.000000
47.530003,9.636253,-1298.888306,0.014366,0.001760,0.044697,42.864197,2.183606,0.446970,-1298.888306,0.045989,0.000000
47.800003,10.088684,-1298.977173,0.014379,0.001786,0.045365,44.876709,2.286128,0.453646,-1298.977173,0.046440,0.000000
48.070004,10.132256,-1298.977173,0.014388,0.001804,0.045824,45.070522,2.296002,0.458245,-1298.977173,0.046891,0.000000
48.340004,10.210083,-1299.021729,0.014405,0.001826,0.046371,45.416718,2.313638,0.463706,-1299.021729,0.047342,0.000000
48.610001,10.012726,-1298.977173,0.014396,0.001837,0.046657,44.538830,2.268916,0.466568,-1298.977173,0.047793,0.000000
48.880001,10.230560,-1298.977173,0.014400,0.001857,0.047168,45.507805,2.318278,0.471685,-1298.977173,0.048244,0.000000
49.150002,10.489357,-1298.977173,0.014444,0.001878,0.047706,46.658989,2.376922,0.477063,-1298.977173,0.048695,0.000000
49.420002,10.478188,-1298.977173,0.014452,0.001897,0.048175,46.609306,2.374391,0.481745,-1298.977173,0.049137,0.000000
49.690002,10.395149,-1299.066162,0.014448,0.001912,0.048556,46.239933,2.355575,0.485560,-1299.066162,0.049588,0.000000
49.960003,10.526222,-1299.021729,0.014500,0.001931,0.049059,46.822975,2.385276,0.490591,-1299.021729,0.050039,0.000000
50.230003,10.632721,-1299.066162,0.014457,0.001950,0.049536,47.296703,2.409409,0.495359,-1299.066162,0.050490,0.000000
50.500004,10.521759,-1298.977173,0.014495,0.001965,0.049909,46.803123,2.384265,0.499091,-1298.977173,0.050941,0.000000
50.770004,10.613731,-1299.021729,0.014478,0.001984,0.050403,47.212234,2.405106,0.504034,-1299.021729,0.051392,0.000000
51.040001,10.486755,-1299.110596,0.014526,0.001995,0.050663,46.647419,2.376333,0.506635,-1299.110596,0.051843,0.000000
51.310001,10.783905,-1299.155151,0.014573,0.002016,0.051210,47.969204,2.443668,0.512100,-1299.155151,0.052294,0.000000
51.580002,10.882210,-1299.021729,0.014564,0.002036,0.051713,48.406487,2.465944,0.517130,-1299.021729,0.052745,0.000000
51.850002,10.936577,-1299.066162,0.014556,0.002052,0.052129,48.648323,2.478264,0.521290,-1299.066162,0.053196,0.000000
52.120003,11.148087,-1299.021729,0.014582,0.002075,0.052702,49.589165,2.526192,0.527016,-1299.021729,0.053638,0.000000
52.390003,11.127975,-1299.066162,0.014620,0.002092,0.053144,49.499706,2.521635,0.531437,-1299.066162,0.054089,0.000000
52.660004,11.074730,-1299.110596,0.014612,0.002109,0.053560,49.262859,2.509570,0.535600,-1299.110596,0.054540,0.000000
52.930004,11.054619,-1299.066162,0.014655,0.002123,0.053933,49.173401,2.505013,0.539329,-1299.066162,0.054991,0.000000
53.200001,11.171547,-1299.021729,0.014655,0.002143,0.054436,49.693523,2.531509,0.544359,-1299.021729,0.055442,0.000000
53.470001,11.314537,-1299.110596,0.014625,0.002161,0.054896,50.329575,2.563911,0.548957,-1299.110596,0.055893,0.000000
53.740002,11.125374,-1299.110596,0.014694,0.002172,0.055173,49.488136,2.521046,0.551732,-1299.110596,0.056344,0.000000
54.010002,11.534607,-1299.110596,0.014720,0.002197,0.055806,51.308495,2.613779,0.558060,-1299.110596,0.056795,0.000000
54.280003,11.637383,-1299.155151,0.014694,0.002218,0.056344,51.765663,2.637069,0.563438,-1299.155151,0.057246,0.000000
54.550003,11.583763,-1299.066162,0.014707,0.002235,0.056760,51.527153,2.624918,0.567602,-1299.066162,0.057688,0.000000
54.820004,11.606476,-1299.155151,0.014676,0.002252,0.057202,51.628181,2.630065,0.572023,-1299.155151,0.058139,0.000000
55.090004,11.567749,-1299.110596,0.014694,0.002267,0.057584,51.455917,2.621289,0.575838,-1299.110596,0.058590,0.000000
55.360004,11.566635,-1299.110596,0.014732,0.002280,0.057913,51.450962,2.621037,0.579134,-1299.110596,0.059041,0.000000
55.630001,11.711113,-1299.199585,0.014741,0.002297,0.058338,52.093632,2.653776,0.583385,-1299.199585,0.059492,0.000000
55.900002,12.001190,-1299.066162,0.014754,0.002320,0.058919,53.383961,2.719509,0.589195,-1299.066162,0.059943,0.000000
56.170002,11.897675,-1299.155151,0.014776,0.002335,0.059318,52.923500,2.696052,0.593184,-1299.155151,0.060394,0.000000
56.440002,12.158333,-1299.199585,0.014754,0.002358,0.059891,54.082966,2.755117,0.598907,-1299.199585,0.060845,0.000000
56.710003,12.035446,-1299.110596,0.014797,0.002373,0.060281,53.536339,2.727271,0.602809,-1299.110596,0.061296,0.000000
56.980003,12.195572,-1299.110596,0.014819,0.002391,0.060741,54.248611,2.763556,0.607408,-1299.110596,0.061738,0.000000
57.250004,12.083488,-1299.110596,0.014832,0.002406,0.061122,53.750042,2.738158,0.611223,-1299.110596,0.062189,0.000000
57.520004,12.338188,-1299.155151,0.014845,0.002425,0.061599,54.883003,2.795873,0.615992,-1299.155151,0.062640,0.000000
57.790001,12.519165,-1299.110596,0.014836,0.002446,0.062128,55.688026,2.836883,0.621283,-1299.110596,0.063091,0.000000
58.060001,12.359039,-1299.199585,0.014819,0.002462,0.062527,54.975754,2.800598,0.625272,-1299.199585,0.063542,0.000000
58.330002,12.682259,-1299.155151,0.014840,0.002482,0.063048,56.413506,2.873841,0.630476,-1299.155151,0.063993,0.000000
58.600002,12.353455,-1299.244141,0.014853,0.002493,0.063316,54.950909,2.799333,0.633164,-1299.244141,0.064444,0.000000
58.870003,12.781685,-1299.199585,0.014862,0.002516,0.063906,56.855774,2.896371,0.639061,-1299.199585,0.064895,0.000000
59.140003,12.763809,-1299.199585,0.014905,0.002530,0.064270,56.776260,2.892320,0.642702,-1299.199585,0.065345,0.000000
59.410004,12.952606,-1299.244141,0.014905,0.002548,0.064721,57.616070,2.935102,0.647213,-1299.244141,0.065797,0.000000
59.680004,13.173050,-1299.244141,0.014905,0.002570,0.065285,58.596653,2.985056,0.652849,-1299.244141,0.066239,0.000000
59.950005,12.941803,-1299.155151,0.014970,0.002583,0.065606,57.568016,2.932655,0.656059,-1299.155151,0.066690,0.000000
60.220001,13.032288,-1299.244141,0.014974,0.002600,0.066048,57.970512,2.953159,0.660479,-1299.244141,0.067141,0.000000
60.490002,13.145493,-1299.288574,0.014978,0.002620,0.066560,58.474072,2.978811,0.665596,-1299.288574,0.067592,0.000000
60.760002,12.760086,-1299.333008,0.014952,0.002625,0.066672,56.759697,2.891477,0.666724,-1299.333008,0.068043,0.000000
61.030003,13.542442,-1299.244141,0.014974,0.002654,0.067418,60.239792,3.068761,0.674184,-1299.244141,0.068494,0.000000
61.300003,13.706657,-1299.244141,0.015004,0.002674,0.067921,60.970257,3.105973,0.679215,-1299.244141,0.068945,0.000000
61.570004,13.796768,-1299.288574,0.015052,0.002693,0.068390,61.371090,3.126392,0.683896,-1299.288574,0.069396,0.000000
61.840004,13.420677,-1299.288574,0.015030,0.002699,0.068563,59.698154,3.041169,0.685630,-1299.288574,0.069846,0.000000
62.110004,14.096901,-1299.199585,0.015060,0.002726,0.069239,62.706146,3.194403,0.692394,-1299.199585,0.070289,0.000000
62.380001,14.118126,-1299.199585,0.015060,0.002745,0.069734,62.800560,3.199213,0.697337,-1299.199585,0.070740,0.000000
62.650002,13.571487,-1299.244141,0.015060,0.002749,0.069820,60.368992,3.075343,0.698203,-1299.244141,0.071191,0.000000
62.920002,14.391823,-1299.288574,0.015090,0.002782,0.070653,64.018028,3.261234,0.706530,-1299.288574,0.071642,0.000000
63.190002,14.409325,-1299.288574,0.015095,0.002796,0.071026,64.095879,3.265200,0.710258,-1299.288574,0.072093,0.000000
63.460003,14.766800,-1299.333008,0.015103,0.002817,0.071546,65.686005,3.346205,0.715463,-1299.333008,0.072544,0.000000
63.730003,15.105659,-1299.244141,0.015177,0.002838,0.072093,67.193329,3.422992,0.720928,-1299.244141,0.072995,0.000000
64.000000,15.103424,-1299.244141,0.015155,0.002855,0.072517,67.183388,3.422485,0.725175,-1299.244141,0.073446,0.000000
64.270004,15.176041,-1299.288574,0.015198,0.002870,0.072891,67.506401,3.438940,0.728906,-1299.288574,0.073896,0.000000
64.540001,15.422546,-1299.333008,0.015168,0.002888,0.073350,68.602913,3.494799,0.733501,-1299.333008,0.074339,0.000000
64.810005,15.633682,-1299.288574,0.015228,0.002903,0.073740,69.542091,3.542643,0.737404,-1299.288574,0.074790,0.000000
65.080002,15.676880,-1299.333008,0.015220,0.002919,0.074148,69.734245,3.552432,0.741480,-1299.333008,0.075241,0.000000
65.350006,16.147934,-1299.244141,0.015271,0.002939,0.074642,71.829597,3.659174,0.746423,-1299.244141,0.075691,0.000000
65.620003,16.372841,-1299.333008,0.015254,0.002956,0.075076,72.830032,3.710139,0.750760,-1299.333008,0.076143,0.000000
65.889999,16.876663,-1299.333008,0.015228,0.002974,0.075544,75.071144,3.824306,0.755442,-1299.333008,0.076593,0.000000
66.160004,17.206215,-1299.333008,0.015297,0.002995,0.076073,76.537064,3.898984,0.760734,-1299.333008,0.077045,0.000000
66.430000,17.334312,-1299.333008,0.015315,0.003009,0.076429,77.106873,3.928011,0.764288,-1299.333008,0.077495,0.000000
66.700005,16.577652,-1299.333008,0.015332,0.003010,0.076455,73.741081,3.756550,0.764549,-1299.333008,0.077947,0.000000
66.970001,17.617683,-1299.377563,0.015284,0.003036,0.077114,78.367371,3.992224,0.771138,-1299.377563,0.078397,0.000000
67.240005,18.403389,-1299.421997,0.015332,0.003062,0.077764,81.862366,4.170267,0.777645,-1299.421997,0.078840,0.000000
67.510002,18.915405,-1299.377563,0.015340,0.003083,0.078319,84.139923,4.286292,0.783193,-1299.377563,0.079291,0.000000
67.780006,18.549736,-1299.377563,0.015375,0.003096,0.078640,82.513344,4.203430,0.786403,-1299.377563,0.079742,0.000000
68.050003,19.351448,-1299.333008,0.015392,0.003117,0.079169,86.079536,4.385101,0.791690,-1299.333008,0.080192,0.000000
68.320000,19.249420,-1299.288574,0.015392,0.003126,0.079412,85.625694,4.361981,0.794120,-1299.288574,0.080644,0.000000
68.590004,20.229134,-1299.421997,0.015405,0.003152,0.080062,89.983681,4.583987,0.800623,-1299.421997,0.081094,0.000000
68.860001,20.761253,-1299.377563,0.015418,0.003168,0.080470,92.350670,4.704567,0.804699,-1299.377563,0.081546,0.000000
69.130005,21.165649,-1299.333008,0.015414,0.003185,0.080895,94.149513,4.796205,0.808949,-1299.333008,0.081996,0.000000
69.400002,21.632607,-1299.377563,0.015405,0.003203,0.081346,96.226639,4.902019,0.813461,-1299.377563,0.082447,0.000000
69.670006,22.337509,-1299.421997,0.015465,0.003225,0.081910,99.362206,5.061752,0.819097,-1299.421997,0.082890,0.000000
69.940002,22.232872,-1299.421997,0.015440,0.003235,0.082178,98.896751,5.038041,0.821784,-1299.421997,0.083341,0.000000
70.210007,23.024536,-1299.377563,0.015444,0.003256,0.082690,102.418251,5.217434,0.826901,-1299.377563,0.083792,0.000000
70.480003,23.818062,-1299.377563,0.015478,0.003276,0.083219,105.948029,5.397250,0.832192,-1299.377563,0.084242,0.000000
70.750000,24.495407,-1299.421997,0.015496,0.003295,0.083696,108.961014,5.550739,0.836961,-1299.421997,0.084693,0.000000
71.020004,24.834633,-1299.421997,0.015547,0.003310,0.084078,110.469963,5.627608,0.840777,-1299.421997,0.085144,0.000000
71.290001,25.671356,-1299.421997,0.015500,0.003331,0.084607,114.191895,5.817213,0.846068,-1299.421997,0.085595,0.000000
71.560005,26.097725,-1299.421997,0.015560,0.003348,0.085040,116.088478,5.913829,0.850402,-1299.421997,0.086046,0.000000
71.830002,26.693146,-1299.421997,0.015590,0.003364,0.085448,118.737045,6.048753,0.854478,-1299.421997,0.086497,0.000000
72.100006,27.342567,-1299.421997,0.015595,0.003383,0.085933,121.625816,6.195914,0.859334,-1299.421997,0.086948,0.000000
72.370003,27.618866,-1299.466553,0.015595,0.003393,0.086176,122.854851,6.258524,0.861764,-1299.466553,0.087391,0.000000
72.640007,28.507721,-1299.555420,0.015603,0.003415,0.086740,126.808678,6.459942,0.867400,-1299.555420,0.087841,0.000000
72.910004,29.659462,-1299.466553,0.015595,0.003434,0.087217,131.931870,6.720930,0.872172,-1299.466553,0.088293,0.000000
73.180000,30.531937,-1299.421997,0.015625,0.003451,0.087651,135.812836,6.918636,0.876506,-1299.421997,0.088743,0.000000
73.450005,31.293434,-1299.466553,0.015634,0.003472,0.088188,139.200150,7.091193,0.881884,-1299.466553,0.089194,0.000000
73.720001,32.369591,-1299.466553,0.015612,0.003490,0.088657,143.987137,7.335054,0.886566,-1299.466553,0.089645,0.000000
73.990005,33.168335,-1299.555420,0.015647,0.003507,0.089090,147.540115,7.516052,0.890904,-1299.555420,0.090096,0.000000
74.260002,33.934303,-1299.510986,0.015647,0.003526,0.089550,150.947327,7.689623,0.895499,-1299.510986,0.090547,0.000000
74.530006,34.682770,-1299.421997,0.015655,0.003541,0.089931,154.276672,7.859228,0.899314,-1299.421997,0.090998,0.000000
74.800003,35.832283,-1299.466553,0.015677,0.003559,0.090408,159.389954,8.119712,0.904083,-1299.466553,0.091440,0.000000
75.070007,36.316368,-1299.466553,0.015664,0.003571,0.090695,161.543274,8.229406,0.906948,-1299.466553,0.091892,0.000000
75.340004,38.060188,-1299.555420,0.015694,0.003596,0.091345,169.300171,8.624561,0.913450,-1299.555420,0.092342,0.000000
75.610001,38.903984,-1299.466553,0.015759,0.003614,0.091796,173.053558,8.815768,0.917962,-1299.466553,0.092793,0.000000
75.880005,40.177498,-1299.421997,0.015767,0.003632,0.092264,178.718430,9.104351,0.922644,-1299.421997,0.093244,0.000000
76.150002,41.049591,-1299.510986,0.015741,0.003649,0.092672,182.597702,9.301970,0.926720,-1299.510986,0.093695,0.000000
76.420006,42.141388,-1299.466553,0.015759,0.003665,0.093097,187.454254,9.549376,0.930967,-1299.466553,0.094146,0.000000
76.690002,42.909592,-1299.555420,0.015772,0.003680,0.093461,190.871399,9.723453,0.934612,-1299.555420,0.094597,0.000000
76.960007,43.915749,-1299.510986,0.015776,0.003694,0.093834,195.347000,9.951450,0.938340,-1299.510986,0.095048,0.000000
77.230003,45.399651,-1299.466553,0.015797,0.003715,0.094363,201.947739,10.287708,0.943631,-1299.466553,0.095490,0.000000
77.500000,46.782639,-1299.510986,0.015763,0.003732,0.094796,208.099564,10.601097,0.947965,-1299.510986,0.095941,0.000000
77.770004,48.488853,-1299.555420,0.015793,0.003756,0.095412,215.689194,10.987732,0.954123,-1299.555420,0.096392,0.000000
78.040001,49.507294,-1299.510986,0.015836,0.003772,0.095811,220.219437,11.218513,0.958112,-1299.510986,0.096843,0.000000
78.310005,50.813942,-1299.555420,0.015849,0.003790,0.096254,226.031708,11.514604,0.962537,-1299.555420,0.097294,0.000000
78.580002,51.858078,-1299.510986,0.015853,0.003804,0.096618,230.676254,11.751209,0.966178,-1299.510986,0.097745,0.000000
78.850006,52.872795,-1299.599976,0.015853,0.003818,0.096982,235.189941,11.981147,0.969819,-1299.599976,0.098196,0.000000
79.120003,54.897011,-1299.555420,0.015793,0.003843,0.097615,244.194107,12.439841,0.976151,-1299.555420,0.098647,0.000000
79.390007,55.879700,-1299.555420,0.015858,0.003858,0.097997,248.565323,12.662520,0.979966,-1299.555420,0.099098,0.000000
79.660004,57.457443,-1299.466553,0.015853,0.003878,0.098500,255.583466,13.020043,0.984996,-1299.466553,0.099549,0.000000
79.930000,58.317619,-1299.599976,0.015845,0.003889,0.098768,259.409729,13.214961,0.987683,-1299.599976,0.099991,0.000000
80.200005,60.280396,-1299.599976,0.015897,0.003911,0.099341,268.140594,13.659733,0.993410,-1299.599976,0.100442,0.000000
80.470001,61.181541,-1299.555420,0.015875,0.003922,0.099618,272.149078,13.863935,0.996184,-1299.555420,0.100893,0.000000
80.740005,62.849396,-1299.555420,0.015892,0.003944,0.100182,279.568085,14.241877,1.001820,-1299.555420,0.101344,0.000000
81.010002,64.979362,-1299.599976,0.015888,0.003967,0.100763,289.042633,14.724534,1.007630,-1299.599976,0.101795,0.000000
81.280006,66.274101,-1299.555420,0.015888,0.003981,0.101127,294.801941,15.017926,1.011275,-1299.555420,0.102246,0.000000
81.550003,67.467934,-1299.555420,0.015888,0.003989,0.101327,300.112366,15.288452,1.013269,-1299.555420,0.102654,0.000000
81.820007,67.075447,-1299.644409,0.015940,0.003988,0.101283,298.366486,15.199514,1.012834,-1299.644409,0.101492,0.000000
82.090004,66.776436,-1299.555420,0.015897,0.003987,0.101275,297.036407,15.131756,1.012747,-1299.555420,0.101283,0.000000
82.360001,66.519875,-1299.510986,0.015931,0.003987,0.101266,295.895172,15.073619,1.012660,-1299.510986,0.101283,0.000000
82.630005,66.307991,-1299.555420,0.015931,0.003987,0.101266,294.952667,15.025605,1.012660,-1299.555420,0.101283,0.000000
82.900002,66.131493,-1299.644409,0.015931,0.003987,0.101257,294.167572,14.985610,1.012573,-1299.644409,0.101283,0.000000
83.170006,65.976204,-1299.644409,0.015901,0.003987,0.101257,293.476807,14.950421,1.012573,-1299.644409,0.101283,0.000000
83.440002,65.820930,-1299.599976,0.015935,0.003987,0.101257,292.786133,14.915236,1.012573,-1299.599976,0.101283,0.000000
83.710007,65.693199,-1299.555420,0.015901,0.003987,0.101257,292.217957,14.886292,1.012573,-1299.555420,0.101283,0.000000
83.980003,65.571815,-1299.599976,0.015905,0.003987,0.101257,291.678009,14.858786,1.012573,-1299.599976,0.101283,0.000000
84.250008,65.467552,-1299.599976,0.015948,0.003987,0.101257,291.214203,14.835159,1.012573,-1299.599976,0.101283,0.000000
84.520004,65.366631,-1299.644409,0.015940,0.003987,0.101257,290.765289,14.812291,1.012573,-1299.644409,0.101283,0.000000
84.790001,65.275780,-1299.599976,0.015935,0.003986,0.101249,290.361176,14.791703,1.012486,-1299.599976,0.101283,0.000000
85.060005,65.182304,-1299.599976,0.015957,0.003986,0.101249,289.945374,14.770521,1.012486,-1299.599976,0.101283,0.000000
85.330002,65.109703,-1299.599976,0.015948,0.003986,0.101249,289.622437,14.754069,1.012486,-1299.599976,0.101283,0.000000
85.600006,65.043419,-1299.644409,0.015948,0.003986,0.101249,289.327576,14.739050,1.012486,-1299.644409,0.101283,0.000000
85.870003,64.976387,-1299.555420,0.015970,0.003986,0.101249,289.029419,14.723860,1.012486,-1299.555420,0.101283,0.000000
86.140007,64.898186,-1299.555420,0.015931,0.003986,0.101249,288.681549,14.706140,1.012486,-1299.555420,0.101283,0.000000
86.410004,64.840843,-1299.644409,0.015922,0.003986,0.101249,288.426483,14.693146,1.012486,-1299.644409,0.101283,0.000000
86.680000,64.779396,-1299.599976,0.015961,0.003986,0.101249,288.153137,14.679221,1.012486,-1299.599976,0.101283,0.000000
86.950005,64.746635,-1299.644409,0.015944,0.003986,0.101249,288.007416,14.671798,1.012486,-1299.644409,0.101283,0.000000
87.220001,64.685570,-1299.599976,0.015961,0.003986,0.101249,287.735779,14.657959,1.012486,-1299.599976,0.101283,0.000000
87.490005,64.617790,-1299.599976,0.015953,0.003986,0.101249,287.434296,14.642601,1.012486,-1299.599976,0.101283,0.000000
87.760002,64.570869,-1299.599976,0.015914,0.003986,0.101249,287.225586,14.631968,1.012486,-1299.599976,0.101283,0.000000
88.030006,64.548164,-1299.599976,0.015953,0.003986,0.101249,287.124573,14.626823,1.012486,-1299.599976,0.101283,0.000000
88.300003,64.513161,-1299.688965,0.015927,0.003986,0.101249,286.968872,14.618892,1.012486,-1299.688965,0.101283,0.000000
88.570007,64.454689,-1299.688965,0.015983,0.003986,0.101249,286.708771,14.605641,1.012486,-1299.688965,0.101283,0.000000
88.840004,64.396980,-1299.644409,0.015978,0.003986,0.101249,286.452087,14.592564,1.012486,-1299.644409,0.101283,0.000000
89.110001,64.362724,-1299.599976,0.015922,0.003986,0.101249,286.299683,14.584802,1.012486,-1299.599976,0.101283,0.000000
89.380005,64.334785,-1299.644409,0.015914,0.003986,0.101249,286.175415,14.578471,1.012486,-1299.644409,0.101283,0.000000
89.650002,64.304253,-1299.688965,0.015922,0.003986,0.101249,286.039612,14.571552,1.012486,-1299.688965,0.101283,0.000000
89.920006,64.264046,-1299.733398,0.015966,0.003986,0.101249,285.860748,14.562441,1.012486,-1299.733398,0.101283,0.000000
90.190002,64.227913,-1299.644409,0.015910,0.003986,0.101249,285.700012,14.554254,1.012486,-1299.644409,0.101283,0.000000
90.460007,64.205574,-1299.644409,0.015931,0.003986,0.101249,285.600647,14.549191,1.012486,-1299.644409,0.101283,0.000000
90.730003,64.175789,-1299.644409,0.015905,0.003986,0.101249,285.468170,14.542442,1.012486,-1299.644409,0.101283,0.000000
91.000008,64.129234,-1299.688965,0.015974,0.003986,0.101249,285.261078,14.531892,1.012486,-1299.688965,0.101283,0.000000
91.270004,64.108757,-1299.733398,0.016000,0.003986,0.101249,285.169983,14.527252,1.012486,-1299.733398,0.101283,0.000000
91.540001,64.082314,-1299.688965,0.015922,0.003986,0.101249,285.052368,14.521259,1.012486,-1299.688965,0.101283,0.000000
91.810005,64.050667,-1299.644409,0.015922,0.003986,0.101249,284.911591,14.514089,1.012486,-1299.644409,0.101283,0.000000
92.080002,64.020882,-1299.644409,0.015944,0.003986,0.101249,284.779114,14.507339,1.012486,-1299.644409,0.101283,0.000000
92.350006,63.979912,-1299.644409,0.015966,0.003986,0.101249,284.596863,14.498055,1.012486,-1299.644409,0.101283,0.000000
92.620003,63.961678,-1299.777832,0.015931,0.003986,0.101249,284.515747,14.493923,1.012486,-1299.777832,0.101283,0.000000
92.890007,63.933006,-1299.644409,0.015974,0.003986,0.101249,284.388214,14.487426,1.012486,-1299.644409,0.101283,0.000000
93.160004,63.925926,-1299.644409,0.015918,0.003986,0.101249,284.356720,14.485822,1.012486,-1299.644409,0.101283,0.000000
93.430008,63.879372,-1299.733398,0.015918,0.003986,0.101249,284.149628,14.475273,1.012486,-1299.733398,0.101283,0.000000
93.700005,63.855171,-1299.777832,0.015970,0.003986,0.101249,284.041992,14.469789,1.012486,-1299.777832,0.101283,0.000000
93.970001,63.825752,-1299.688965,0.015957,0.003986,0.101249,283.911133,14.463122,1.012486,-1299.688965,0.101283,0.000000
94.240005,63.813103,-1299.733398,0.015970,0.003986,0.101249,283.854858,14.460256,1.012486,-1299.733398,0.101283,0.000000
94.510002,63.797462,-1299.733398,0.015931,0.003986,0.101249,283.785278,14.456712,1.012486,-1299.733398,0.101283,0.000000
94.780006,63.763939,-1299.688965,0.015914,0.003986,0.101249,283.636169,14.449115,1.012486,-1299.688965,0.101283,0.000000
95.050003,63.740105,-1299.777832,0.015970,0.003986,0.101249,283.530151,14.443714,1.012486,-1299.777832,0.101283,0.000000
95.320007,63.730431,-1299.733398,0.015940,0.003986,0.101249,283.487122,14.441522,1.012486,-1299.733398,0.101283,0.000000
95.590004,63.717018,-1299.733398,0.015922,0.003986,0.101249,283.427460,14.438482,1.012486,-1299.733398,0.101283,0.000000
95.860008,63.687233,-1299.644409,0.015948,0.003986,0.101249,283.294952,14.431733,1.012486,-1299.644409,0.101283,0.000000
96.130005,63.666374,-1299.733398,0.015910,0.003986,0.101249,283.202179,14.427007,1.012486,-1299.733398,0.101283,0.000000
96.400002,63.638832,-1299.777832,0.015983,0.003986,0.101249,283.079651,14.420766,1.012486,-1299.777832,0.101283,0.000000
96.670006,63.630638,-1299.688965,0.015914,0.003986,0.101249,283.043213,14.418908,1.012486,-1299.688965,0.101283,0.000000
96.940002,63.616859,-1299.688965,0.015927,0.003986,0.101249,282.981934,14.415787,1.012486,-1299.688965,0.101283,0.000000
97.210007,63.588188,-1299.644409,0.015970,0.003986,0.101249,282.854401,14.409289,1.012486,-1299.644409,0.101283,0.000000
97.480003,63.584084,-1299.688965,0.015953,0.003986,0.101249,282.836121,14.408360,1.012486,-1299.688965,0.101283,0.000000
97.750008,63.576637,-1299.777832,0.015948,0.003986,0.101249,282.803009,14.406672,1.012486,-1299.777832,0.101283,0.000000
98.020004,63.549828,-1299.777832,0.015922,0.003986,0.101249,282.683746,14.400597,1.012486,-1299.777832,0.101283,0.000000
98.290001,63.527489,-1299.777832,0.015961,0.003986,0.101249,282.584381,14.395535,1.012486,-1299.777832,0.101283,0.000000
98.560005,63.507378,-1299.733398,0.015935,0.003986,0.101249,282.494934,14.390978,1.012486,-1299.733398,0.101283,0.000000
98.830002,63.498817,-1299.777832,0.015987,0.003986,0.101249,282.456848,14.389038,1.012486,-1299.777832,0.101283,0.000000
99.100006,63.480934,-1299.866821,0.015931,0.003986,0.101249,282.377289,14.384985,1.012486,-1299.866821,0.101283,0.000000
99.370003,63.468285,-1299.777832,0.015983,0.003986,0.101249,282.321045,14.382119,1.012486,-1299.777832,0.101283,0.000000
99.640007,63.429558,-1299.733398,0.015918,0.003986,0.101249,282.148773,14.373343,1.012486,-1299.733398,0.101283,0.000000
99.910004,63.435875,-1299.777832,0.015922,0.003986,0.101249,282.176880,14.374775,1.012486,-1299.777832,0.101283,0.000000
100.180008,63.419868,-1299.733398,0.015910,0.003986,0.101249,282.105652,14.371148,1.012486,-1299.733398,0.101283,0.000000
100.450005,63.393425,-1299.777832,0.015948,0.003986,0.101249,281.988037,14.365155,1.012486,-1299.777832,0.101283,0.000000
100.720001,63.378532,-1299.733398,0.015940,0.003986,0.101249,281.921783,14.361781,1.012486,-1299.733398,0.101283,0.000000
100.990005,63.357689,-1299.777832,0.015983,0.003986,0.101249,281.829071,14.357058,1.012486,-1299.777832,0.101283,0.000000
101.260002,63.356194,-1299.777832,0.015974,0.003986,0.101249,281.822418,14.356719,1.012486,-1299.777832,0.101283,0.000000
101.530006,63.350975,-1299.822388,0.015935,0.003986,0.101249,281.799225,14.355536,1.012486,-1299.822388,0.101283,0.000000
101.800003,63.318581,-1299.866821,0.015922,0.003986,0.101249,281.655121,14.348196,1.012486,-1299.866821,0.101283,0.000000
102.070007,63.318962,-1299.822388,0.015927,0.003986,0.101249,281.656799,14.348282,1.012486,-1299.822388,0.101283,0.000000
102.340004,63.303322,-1299.777832,0.015935,0.003986,0.101249,281.587250,14.344738,1.012486,-1299.777832,0.101283,0.000000
102.610008,63.291771,-1299.822388,0.015944,0.003986,0.101249,281.535858,14.342120,1.012486,-1299.822388,0.101283,0.000000
102.880005,63.271294,-1299.822388,0.015957,0.003986,0.101249,281.444763,14.337480,1.012486,-1299.822388,0.101283,0.000000
103.150002,63.256020,-1299.777832,0.015953,0.003986,0.101249,281.376831,14.334019,1.012486,-1299.777832,0.101283,0.000000
103.420006,63.252678,-1299.866821,0.015966,0.003986,0.101249,281.361969,14.333261,1.012486,-1299.866821,0.101283,0.000000
103.690002,63.241508,-1299.777832,0.015970,0.003986,0.101249,281.312286,14.330730,1.012486,-1299.777832,0.101283,0.000000
103.960007,63.231071,-1299.777832,0.015935,0.003986,0.101249,281.265839,14.328366,1.012486,-1299.777832,0.101283,0.000000
104.230003,63.209114,-1299.777832,0.015978,0.003986,0.101249,281.168182,14.323390,1.012486,-1299.777832,0.101283,0.000000
104.500008,63.213951,-1299.866821,0.015983,0.003986,0.101249,281.189697,14.324486,1.012486,-1299.866821,0.101283,0.000000
104.770004,63.205757,-1299.822388,0.015927,0.003986,0.101249,281.153259,14.322629,1.012486,-1299.822388,0.101283,0.000000
105.040009,63.181175,-1299.777832,0.015966,0.003986,0.101249,281.043915,14.317059,1.012486,-1299.777832,0.101283,0.000000
105.310005,63.176704,-1299.733398,0.015983,0.003986,0.101249,281.024017,14.316046,1.012486,-1299.733398,0.101283,0.000000
105.580002,63.161446,-1299.822388,0.015970,0.003986,0.101249,280.956146,14.312589,1.012486,-1299.822388,0.101283,0.000000
105.850006,63.179695,-1299.911255,0.015957,0.003986,0.101249,281.037323,14.316724,1.012486,-1299.911255,0.101283,0.000000
106.120003,63.156975,-1299.866821,0.015944,0.003986,0.101249,280.936249,14.311575,1.012486,-1299.866821,0.101283,0.000000
106.390007,63.135002,-1299.777832,0.015931,0.003986,0.101249,280.838501,14.306596,1.012486,-1299.777832,0.101283,0.000000
106.660004,63.136864,-1299.822388,0.015940,0.003986,0.101249,280.846802,14.307018,1.012486,-1299.822388,0.101283,0.000000
106.930008,63.132393,-1299.866821,0.015944,0.003986,0.101249,280.826904,14.306005,1.012486,-1299.866821,0.101283,0.000000
107.200005,63.123466,-1299.866821,0.015927,0.003986,0.101249,280.787201,14.303982,1.012486,-1299.866821,0.101283,0.000000
107.470009,63.095161,-1299.822388,0.015966,0.003986,0.101249,280.661285,14.297568,1.012486,-1299.822388,0.101283,0.000000
107.740005,63.105965,-1299.777832,0.015940,0.003986,0.101249,280.709351,14.300015,1.012486,-1299.777832,0.101283,0.000000
108.010002,63.110435,-1299.822388,0.015970,0.003986,0.101249,280.729248,14.301029,1.012486,-1299.822388,0.101283,0.000000
108.280006,63.078407,-1299.866821,0.015974,0.003986,0.101249,280.586761,14.293772,1.012486,-1299.866821,0.101283,0.000000
108.550003,63.063507,-1299.911255,0.015927,0.003986,0.101249,280.520477,14.290396,1.012486,-1299.911255,0.101283,0.000000
108.820007,63.072449,-1299.822388,0.015944,0.003986,0.101249,280.560272,14.292420,1.012486,-1299.822388,0.101283,0.000000
109.090004,63.062393,-1299.866821,0.015931,0.003986,0.101249,280.515533,14.290143,1.012486,-1299.866821,0.101283,0.000000
109.360008,63.054199,-1299.866821,0.015970,0.003986,0.101249,280.479095,14.288285,1.012486,-1299.866821,0.101283,0.000000
109.630005,63.040794,-1299.866821,0.015944,0.003986,0.101249,280.419464,14.285248,1.012486,-1299.866821,0.101283,0.000000
109.900002,63.037071,-1299.911255,0.015918,0.003986,0.101249,280.402893,14.284405,1.012486,-1299.911255,0.101283,0.000000
110.170006,63.025528,-1299.822388,0.015983,0.003986,0.101249,280.351562,14.281789,1.012486,-1299.822388,0.101283,0.000000
110.440002,63.017334,-1299.911255,0.015961,0.003986,0.101249,280.315094,14.279932,1.012486,-1299.911255,0.101283,0.000000
110.710007,63.003555,-1299.866821,0.015957,0.003986,0.101249,280.253815,14.276810,1.012486,-1299.866821,0.101283,0.000000
110.980003,63.001694,-1299.866821,0.015966,0.003986,0.101249,280.245544,14.276387,1.012486,-1299.866821,0.101283,0.000000
111.250008,63.010262,-1299.866821,0.015961,0.003986,0.101249,280.283630,14.278329,1.012486,-1299.866821,0.101283,0.000000
111.520004,62.991638,-1299.866821,0.015935,0.003986,0.101249,280.200806,14.274110,1.012486,-1299.866821,0.101283,0.000000
111.790009,62.965576,-1299.866821,0.015970,0.003986,0.101249,280.084869,14.268203,1.012486,-1299.866821,0.101283,0.000000
112.000008,62.968925,-1299.911255,0.015991,0.003986,0.101249,280.099762,14.268962,1.012486,-1299.911255,0.101283,0.000000