File: Data/Automembrane/AutoNoheat12-2-4_12132023_183653.csv
Time (sec),S:Load (lbs),S:HL1 (DIM),S:LVDT (in),S:Position (in),Ch:Position (mm),Ch:Load (N),Ch:Stress (MPa),Ch:Strain (mm/mm),Ch:HL1 (DIM),Set Point (),Cycles ()
0.110000,0.004463,-1305.115601,0.000022,-0.000000,-0.000000,0.019853,0.001011,-0.000000,-1305.115601,0.000173,0.000000
0.370000,0.001862,-1304.937622,-0.000056,-0.000000,-0.000000,0.008281,0.000422,-0.000000,-1304.937622,0.000173,0.000000
0.630000,-0.019737,-1304.982178,-0.000056,0.000125,0.003183,-0.087796,-0.004473,0.031827,-1304.982178,0.004180,0.000000
0.890000,-0.040962,-1305.026611,0.000116,0.000288,0.007319,-0.182209,-0.009282,0.073192,-1305.026611,0.008499,0.000000
1.150000,0.033134,-1305.026611,0.000315,0.000457,0.011603,0.147389,0.007508,0.116034,-1305.026611,0.012835,0.000000
1.410000,0.014519,-1305.115601,0.000448,0.000639,0.016226,0.064583,0.003290,0.162258,-1305.115601,0.017171,0.000000
1.670000,0.005585,-1304.937622,0.000660,0.000805,0.020441,0.024842,0.001266,0.204407,-1304.937622,0.021507,0.000000
1.930000,0.024574,-1305.071045,0.000849,0.000968,0.024586,0.109312,0.005569,0.245859,-1305.071045,0.025826,0.000000
2.190000,0.006325,-1305.026611,0.001022,0.001143,0.029043,0.028134,0.001433,0.290434,-1305.026611,0.030162,0.000000
2.450000,-0.003723,-1305.026611,0.001203,0.001312,0.033319,-0.016561,-0.000844,0.333188,-1305.026611,0.034498,0.000000
2.710000,0.006325,-1305.026611,0.001341,0.001483,0.037663,0.028134,0.001433,0.376635,-1305.026611,0.038835,0.000000
2.970000,-0.009315,-1305.026611,0.001552,0.001654,0.042000,-0.041437,-0.002111,0.419998,-1305.026611,0.043153,0.000000
3.230000,0.009682,-1305.026611,0.001703,0.001826,0.046388,0.043066,0.002194,0.463881,-1305.026611,0.047489,0.000000
3.490000,0.037979,-1304.982178,0.001854,0.001993,0.050611,0.168940,0.008606,0.506112,-1304.982178,0.051825,0.000000
3.750000,-0.017136,-1304.982178,0.002039,0.002171,0.055156,-0.076223,-0.003883,0.551558,-1304.982178,0.056161,0.000000
4.010000,0.002228,-1305.071045,0.002259,0.002341,0.059457,0.009910,0.000505,0.594569,-1305.071045,0.060480,0.000000
4.270000,0.014519,-1305.026611,0.002432,0.002504,0.063603,0.064583,0.003290,0.636025,-1305.026611,0.064816,0.000000
4.530000,-0.010803,-1305.071045,0.002643,0.002675,0.067938,-0.048055,-0.002448,0.679385,-1305.071045,0.069153,0.000000
4.790000,-0.002235,-1305.026611,0.002785,0.002853,0.072457,-0.009944,-0.000507,0.724569,-1305.026611,0.073471,0.000000
5.050000,-0.005219,-1304.937622,0.002962,0.003020,0.076697,-0.023213,-0.001183,0.766975,-1304.937622,0.077808,0.000000
5.310000,-0.016388,-1305.115601,0.003169,0.003193,0.081103,-0.072897,-0.003714,0.811031,-1305.115601,0.082144,0.000000
5.570000,0.000366,-1304.982178,0.003311,0.003363,0.085413,0.001629,0.000083,0.854130,-1304.982178,0.086480,0.000000
5.830000,0.034996,-1305.071045,0.003505,0.003534,0.089775,0.155670,0.007930,0.897751,-1305.071045,0.090798,0.000000
6.090000,0.008934,-1305.071045,0.003699,0.003707,0.094155,0.039741,0.002024,0.941546,-1305.071045,0.095135,0.000000
6.350000,0.011169,-1305.026611,0.003872,0.003873,0.098369,0.049684,0.002531,0.983694,-1305.026611,0.099471,0.000000
6.610000,0.006699,-1305.071045,0.004061,0.004039,0.102584,0.029797,0.001518,1.025843,-1305.071045,0.103807,0.000000
6.870000,-0.023087,-1304.937622,0.004191,0.004213,0.107016,-0.102694,-0.005231,1.070156,-1304.937622,0.108126,0.000000
7.130000,0.022339,-1305.026611,0.004398,0.004380,0.111256,0.099368,0.005062,1.112562,-1305.026611,0.112462,0.000000
7.390000,0.076706,-1305.071045,0.004562,0.004552,0.115610,0.341205,0.017382,1.156100,-1305.071045,0.116798,0.000000
7.650001,0.199585,-1304.937622,0.004747,0.004727,0.120076,0.887798,0.045227,1.200762,-1304.937622,0.121134,0.000000
7.910000,0.595047,-1305.115601,0.004919,0.004897,0.124395,2.646901,0.134840,1.243947,-1305.115601,0.125453,0.000000
8.170000,0.634148,-1304.937622,0.004967,-0.000000,-0.000000,2.820830,0.143700,-0.000000,-1304.937622,0.000121,0.000000
8.430000,0.610687,-1304.982178,0.005001,-0.000000,-0.000009,2.716473,0.138384,-0.000087,-1304.982178,0.000121,0.000000
8.690001,0.579033,-1305.026611,0.004958,-0.000000,-0.000009,2.575667,0.131211,-0.000087,-1305.026611,0.000486,0.000000
8.950001,0.608452,-1304.982178,0.004984,0.000000,0.000009,2.706529,0.137877,0.000087,-1304.982178,0.000919,0.000000
9.210000,0.712715,-1305.026611,0.005001,0.000023,0.000590,3.170315,0.161504,0.005897,-1305.026611,0.001353,0.000000
9.470000,0.790543,-1304.982178,0.004975,0.000039,0.000980,3.516509,0.179140,0.009799,-1304.982178,0.001786,0.000000
9.730000,0.855339,-1305.026611,0.005014,0.000054,0.001370,3.804738,0.193823,0.013701,-1305.026611,0.002220,0.000000
9.990001,0.952896,-1304.982178,0.004988,0.000073,0.001864,4.238694,0.215929,0.018644,-1304.982178,0.002654,0.000000
10.250001,1.039291,-1304.982178,0.005023,0.000090,0.002281,4.622999,0.235507,0.022808,-1304.982178,0.003087,0.000000
10.510000,1.069450,-1305.071045,0.005040,0.000100,0.002550,4.757153,0.242341,0.025495,-1305.071045,0.003521,0.000000
10.770000,1.249306,-1304.982178,0.005096,0.000121,0.003061,5.557189,0.283097,0.030612,-1304.982178,0.003954,0.000000
11.030001,1.350594,-1304.982178,0.005070,0.000141,0.003573,6.007740,0.306049,0.035729,-1304.982178,0.004388,0.000000
11.290001,1.438103,-1305.026611,0.005101,0.000155,0.003937,6.397000,0.325879,0.039370,-1305.026611,0.004822,0.000000
11.550000,1.551300,-1305.026611,0.005113,0.000176,0.004466,6.900527,0.351530,0.044662,-1305.026611,0.005255,0.000000
11.810000,1.649605,-1305.071045,0.005178,0.000188,0.004778,7.337809,0.373806,0.047784,-1305.071045,0.005689,0.000000
12.070001,1.820152,-1305.071045,0.005157,0.000210,0.005333,8.096441,0.412452,0.053333,-1305.071045,0.006122,0.000000
12.330001,1.926277,-1305.071045,0.005208,0.000225,0.005715,8.568509,0.436501,0.057152,-1305.071045,0.006556,0.000000
12.590000,2.013412,-1305.026611,0.005204,0.000237,0.006018,8.956106,0.456246,0.060184,-1305.026611,0.006990,0.000000
12.850000,2.242050,-1304.982178,0.005238,0.000262,0.006660,9.973137,0.508056,0.066603,-1304.982178,0.007423,0.000000
13.110001,2.339241,-1305.071045,0.005226,0.000278,0.007059,10.405464,0.530080,0.070592,-1305.071045,0.007857,0.000000
13.370001,2.415581,-1304.982178,0.005234,0.000295,0.007493,10.745040,0.547378,0.074930,-1304.982178,0.008291,0.000000
13.630001,2.554474,-1304.982178,0.005290,0.000308,0.007822,11.362867,0.578852,0.078222,-1304.982178,0.008724,0.000000
13.890000,2.745499,-1305.026611,0.005251,0.000326,0.008282,12.212588,0.622139,0.082821,-1305.026611,0.009158,0.000000
14.150001,2.865402,-1305.026611,0.005312,0.000342,0.008698,12.745946,0.649309,0.086984,-1305.026611,0.009592,0.000000
14.410001,2.918655,-1304.982178,0.005342,0.000352,0.008932,12.982827,0.661377,0.089324,-1304.982178,0.010025,0.000000
14.670001,3.205009,-1305.115601,0.005316,0.000376,0.009548,14.256594,0.726265,0.095482,-1305.115601,0.010459,0.000000
14.930000,3.371826,-1305.071045,0.005351,0.000396,0.010060,14.998631,0.764067,0.100599,-1305.071045,0.010892,0.000000
15.190001,3.420609,-1305.115601,0.005411,0.000411,0.010450,15.215627,0.775121,0.104501,-1305.115601,0.011326,0.000000
15.450001,3.489502,-1305.071045,0.005407,0.000425,0.010797,15.522079,0.790732,0.107968,-1305.071045,0.011760,0.000000
15.710001,3.641052,-1305.026611,0.005402,0.000441,0.011196,16.196209,0.825074,0.111957,-1305.026611,0.012193,0.000000
15.970001,3.812347,-1305.071045,0.005467,0.000458,0.011629,16.958168,0.863890,0.116295,-1305.071045,0.012627,0.000000
16.230001,4.012680,-1305.026611,0.005484,0.000479,0.012167,17.849293,0.909286,0.121673,-1305.026611,0.013061,0.000000
16.490002,4.099442,-1305.026611,0.005445,0.000493,0.012531,18.235228,0.928947,0.125314,-1305.026611,0.013494,0.000000
16.750000,4.200356,-1305.026611,0.005454,0.000509,0.012939,18.684114,0.951814,0.129390,-1305.026611,0.013928,0.000000
17.010000,4.338882,-1305.071045,0.005463,0.000528,0.013399,19.300314,0.983205,0.133985,-1305.071045,0.014353,0.000000
17.270000,4.394363,-1305.026611,0.005536,0.000542,0.013763,19.547104,0.995777,0.137630,-1305.026611,0.014786,0.000000
17.530001,4.520226,-1305.026611,0.005523,0.000557,0.014136,20.106968,1.024298,0.141358,-1305.026611,0.015220,0.000000
17.790001,4.799881,-1305.071045,0.005523,0.000578,0.014691,21.350937,1.087669,0.146907,-1305.071045,0.015654,0.000000
18.050001,4.541824,-1305.026611,0.005575,0.000580,0.014726,20.203043,1.029192,0.147255,-1305.026611,0.016087,0.000000
18.310001,5.034843,-1305.115601,0.005644,0.000614,0.015601,22.396103,1.140912,0.156013,-1305.115601,0.016521,0.000000
18.570002,5.083626,-1305.071045,0.005601,0.000628,0.015948,22.613096,1.151966,0.159484,-1305.071045,0.016954,0.000000
18.830002,5.389717,-1305.026611,0.005614,0.000652,0.016556,23.974659,1.221327,0.165555,-1305.026611,0.017388,0.000000
19.090000,5.389717,-1305.115601,0.005592,0.000666,0.016928,23.974659,1.221327,0.169283,-1305.115601,0.017822,0.000000
19.350000,5.458229,-1305.026611,0.005639,0.000683,0.017336,24.279415,1.236852,0.173360,-1305.026611,0.018255,0.000000
19.610001,5.661919,-1305.026611,0.005713,0.000702,0.017822,25.185472,1.283009,0.178216,-1305.026611,0.018689,0.000000
19.870001,5.913643,-1304.982178,0.005717,0.000721,0.018316,26.305197,1.340051,0.183159,-1304.982178,0.019122,0.000000
20.130001,5.930771,-1305.026611,0.005743,0.000735,0.018671,26.381386,1.343932,0.186713,-1305.026611,0.019556,0.000000
20.390001,6.019768,-1305.071045,0.005721,0.000749,0.019018,26.777264,1.364099,0.190183,-1305.071045,0.019990,0.000000
20.650002,6.061478,-1305.026611,0.005752,0.000762,0.019365,26.962799,1.373550,0.193650,-1305.026611,0.020423,0.000000
20.910002,6.475182,-1305.115601,0.005795,0.000788,0.020016,28.803045,1.467297,0.200157,-1305.115601,0.020857,0.000000
21.170000,6.406662,-1305.071045,0.005803,0.000799,0.020302,28.498257,1.451770,0.203018,-1305.071045,0.021290,0.000000
21.430000,6.646843,-1304.982178,0.005786,0.000822,0.020874,29.566633,1.506196,0.208741,-1304.982178,0.021724,0.000000
21.690001,6.548538,-1305.071045,0.005816,0.000830,0.021082,29.129353,1.483920,0.210822,-1305.071045,0.022158,0.000000
21.950001,6.649452,-1304.937622,0.005868,0.000842,0.021394,29.578241,1.506787,0.213945,-1304.937622,0.022591,0.000000
22.210001,7.233330,-1305.115601,0.005872,0.000870,0.022106,32.175457,1.639096,0.221057,-1305.115601,0.023025,0.000000
22.470001,7.162956,-1305.160034,0.005877,0.000884,0.022452,31.862421,1.623149,0.224524,-1305.160034,0.023458,0.000000
22.730001,7.156624,-1305.071045,0.005928,0.000896,0.022756,31.834253,1.621714,0.227559,-1305.071045,0.023892,0.000000
22.990002,7.454895,-1305.071045,0.005915,0.000917,0.023294,33.161030,1.689303,0.232938,-1305.071045,0.024326,0.000000
23.250002,7.790398,-1305.026611,0.005920,0.000941,0.023892,34.653419,1.765329,0.238921,-1305.026611,0.024759,0.000000
23.510000,7.697311,-1305.115601,0.005997,0.000956,0.024282,34.239349,1.744236,0.242824,-1305.115601,0.025193,0.000000
23.770000,7.582993,-1305.026611,0.005954,0.000965,0.024508,33.730835,1.718331,0.245080,-1305.026611,0.025626,0.000000
24.030001,7.914398,-1305.026611,0.005984,0.000980,0.024898,35.205002,1.793428,0.248982,-1305.026611,0.026060,0.000000
24.290001,8.149368,-1305.071045,0.006053,0.001002,0.025462,36.250202,1.846673,0.254617,-1305.071045,0.026494,0.000000
24.550001,8.166496,-1304.982178,0.006010,0.001016,0.025800,36.326389,1.850554,0.258001,-1304.982178,0.026927,0.000000
24.810001,8.609993,-1305.115601,0.006062,0.001046,0.026563,38.299160,1.951052,0.265631,-1305.115601,0.027361,0.000000
25.070002,8.468864,-1305.026611,0.006058,0.001058,0.026875,37.671391,1.919072,0.268754,-1305.026611,0.027795,0.000000
25.330002,8.624512,-1304.982178,0.006084,0.001074,0.027292,38.363743,1.954342,0.272917,-1304.982178,0.028228,0.000000
25.590002,8.891510,-1305.115601,0.006114,0.001096,0.027838,39.551411,2.014845,0.278379,-1305.115601,0.028662,0.000000
25.850000,8.994278,-1305.071045,0.006122,0.001111,0.028228,40.008545,2.038132,0.282281,-1305.071045,0.029095,0.000000
26.110001,9.014763,-1305.071045,0.006165,0.001124,0.028549,40.099667,2.042774,0.285491,-1305.071045,0.029520,0.000000
26.370001,9.022583,-1305.071045,0.006153,0.001136,0.028861,40.134453,2.044547,0.288613,-1305.071045,0.029954,0.000000
26.630001,9.560287,-1305.071045,0.006161,0.001166,0.029607,42.526283,2.166392,0.296070,-1305.071045,0.030387,0.000000
26.890001,9.435913,-1305.115601,0.006204,0.001179,0.029954,41.973038,2.138208,0.299540,-1305.115601,0.030821,0.000000
27.150002,9.501450,-1305.071045,0.006269,0.001197,0.030396,42.264557,2.153059,0.303961,-1305.071045,0.031255,0.000000
27.410002,9.682800,-1305.071045,0.006278,0.001214,0.030830,43.071247,2.194154,0.308299,-1305.071045,0.031688,0.000000
27.670002,9.932663,-1305.115601,0.006299,0.001232,0.031289,44.182690,2.250774,0.312893,-1305.115601,0.032122,0.000000
27.930002,10.005272,-1305.026611,0.006282,0.001247,0.031663,44.505672,2.267227,0.316625,-1305.026611,0.032556,0.000000
28.190001,9.977715,-1305.115601,0.006286,0.001259,0.031975,44.383091,2.260982,0.319748,-1305.115601,0.032989,0.000000
28.450001,10.453606,-1304.982178,0.006355,0.001285,0.032642,46.499962,2.368821,0.326424,-1304.982178,0.033423,0.000000
28.710001,10.494194,-1305.071045,0.006334,0.001305,0.033137,46.680508,2.378018,0.331368,-1305.071045,0.033857,0.000000
28.970001,10.349342,-1305.071045,0.006355,0.001319,0.033492,46.036175,2.345194,0.334922,-1305.071045,0.034290,0.000000
29.230001,10.426422,-1305.160034,0.006368,0.001333,0.033865,46.379044,2.362661,0.338653,-1305.160034,0.034724,0.000000
29.490002,10.802895,-1305.115601,0.006403,0.001355,0.034420,48.053677,2.447971,0.344202,-1305.115601,0.035158,0.000000
29.750002,10.790977,-1305.071045,0.006424,0.001368,0.034750,48.000664,2.445271,0.347499,-1305.071045,0.035591,0.000000
30.010002,10.786140,-1305.071045,0.006485,0.001380,0.035062,47.979149,2.444175,0.350618,-1305.071045,0.036025,0.000000
30.270002,11.208038,-1305.115601,0.006480,0.001405,0.035678,49.855843,2.539778,0.356776,-1305.115601,0.036458,0.000000
30.530001,11.289581,-1305.026611,0.006502,0.001422,0.036120,50.218567,2.558256,0.361200,-1305.026611,0.036892,0.000000
30.790001,11.259422,-1305.071045,0.006562,0.001438,0.036519,50.084412,2.551422,0.365189,-1305.071045,0.037325,0.000000
31.050001,11.308205,-1305.071045,0.006575,0.001453,0.036909,50.301407,2.562476,0.369092,-1305.071045,0.037759,0.000000
31.310001,11.510399,-1305.160034,0.006566,0.001473,0.037412,51.200809,2.608294,0.374122,-1305.160034,0.038193,0.000000
31.570002,11.600891,-1305.026611,0.006584,0.001488,0.037802,51.603340,2.628800,0.378024,-1305.026611,0.038626,0.000000
31.830002,11.469070,-1305.071045,0.006597,0.001499,0.038062,51.016972,2.598928,0.380624,-1305.071045,0.039060,0.000000
32.090000,11.746117,-1305.115601,0.006592,0.001518,0.038565,52.249336,2.661708,0.385654,-1305.115601,0.039493,0.000000
32.350002,12.090561,-1305.071045,0.006683,0.001541,0.039129,53.781502,2.739760,0.391294,-1305.071045,0.039927,0.000000
32.610001,11.986664,-1305.071045,0.006679,0.001554,0.039467,53.319344,2.716217,0.394674,-1305.071045,0.040361,0.000000
32.870003,12.180298,-1305.115601,0.006735,0.001576,0.040023,54.180672,2.760095,0.400226,-1305.115601,0.040794,0.000000
33.130001,12.026512,-1305.071045,0.006691,0.001587,0.040309,53.496597,2.725247,0.403088,-1305.071045,0.041228,0.000000
33.390003,12.047363,-1305.115601,0.006743,0.001604,0.040751,53.589348,2.729971,0.407508,-1305.115601,0.041661,0.000000
33.650002,12.379890,-1305.026611,0.006704,0.001623,0.041236,55.068504,2.805323,0.412364,-1305.026611,0.042095,0.000000
33.910000,12.294617,-1305.115601,0.006730,0.001635,0.041540,54.689186,2.786000,0.415400,-1305.115601,0.042529,0.000000
34.170002,12.715027,-1305.071045,0.006812,0.001659,0.042147,56.559265,2.881266,0.421471,-1305.071045,0.042962,0.000000
34.430000,12.708694,-1305.071045,0.006825,0.001676,0.042581,56.531097,2.879831,0.425808,-1305.071045,0.043396,0.000000
34.690002,12.695290,-1305.115601,0.006847,0.001694,0.043023,56.471470,2.876794,0.430229,-1305.115601,0.043829,0.000000
34.950001,12.666245,-1305.026611,0.006855,0.001707,0.043370,56.342270,2.870212,0.433700,-1305.026611,0.044255,0.000000
35.210003,12.888184,-1305.115601,0.006864,0.001724,0.043795,57.329502,2.920504,0.437950,-1305.115601,0.044688,0.000000
35.470001,12.797318,-1305.115601,0.006890,0.001736,0.044090,56.925312,2.899914,0.440899,-1305.115601,0.045122,0.000000
35.730003,12.821899,-1305.071045,0.006885,0.001751,0.044480,57.034657,2.905484,0.444801,-1305.071045,0.045555,0.000000
35.990002,13.349922,-1305.071045,0.006959,0.001774,0.045061,59.383419,3.025136,0.450611,-1305.071045,0.045989,0.000000
36.250000,13.490677,-1305.071045,0.006954,0.001794,0.045555,60.009529,3.057031,0.455554,-1305.071045,0.046422,0.000000
36.510002,13.409500,-1305.160034,0.006954,0.001810,0.045972,59.648437,3.038636,0.459717,-1305.160034,0.046856,0.000000
36.770000,13.197990,-1305.115601,0.007002,0.001824,0.046318,58.707592,2.990707,0.463184,-1305.115601,0.047290,0.000000
37.030003,13.371147,-1305.115601,0.007006,0.001841,0.046770,59.477833,3.029945,0.467696,-1305.115601,0.047723,0.000000
37.290001,13.621384,-1305.160034,0.007049,0.001861,0.047264,60.590942,3.086650,0.472639,-1305.160034,0.048157,0.000000
37.550003,13.657875,-1305.115601,0.007062,0.001876,0.047654,60.753262,3.094919,0.476541,-1305.115601,0.048590,0.000000
37.810001,13.720062,-1305.115601,0.007088,0.001892,0.048062,61.029884,3.109011,0.480617,-1305.115601,0.049024,0.000000
38.070004,13.699951,-1305.204590,0.007140,0.001907,0.048426,60.940426,3.104453,0.484258,-1305.204590,0.049458,0.000000
38.330002,13.860817,-1305.071045,0.007097,0.001927,0.048955,61.655994,3.140906,0.489550,-1305.071045,0.049891,0.000000
38.590000,13.952049,-1305.115601,0.007183,0.001942,0.049319,62.061813,3.161580,0.493191,-1305.115601,0.050325,0.000000
38.850002,13.868637,-1305.071045,0.007153,0.001955,0.049657,61.690781,3.142678,0.496574,-1305.071045,0.050759,0.000000
39.110001,14.293884,-1305.160034,0.007213,0.001980,0.050282,63.582375,3.239041,0.502816,-1305.160034,0.051192,0.000000
39.370003,14.478584,-1305.115601,0.007196,0.002000,0.050802,64.403961,3.280894,0.508020,-1305.115601,0.051626,0.000000
39.630001,14.215691,-1305.160034,0.007222,0.002013,0.051123,63.234550,3.221322,0.511230,-1305.160034,0.052060,0.000000
39.890003,14.169144,-1305.115601,0.007243,0.002026,0.051470,63.027500,3.210774,0.514700,-1305.115601,0.052493,0.000000
40.150002,14.578751,-1305.026611,0.007299,0.002050,0.052077,64.849518,3.303592,0.520768,-1305.026611,0.052927,0.000000
40.410004,14.389587,-1305.160034,0.007312,0.002064,0.052433,64.008080,3.260727,0.524325,-1305.160034,0.053360,0.000000
40.670002,14.478584,-1305.160034,0.007334,0.002081,0.052866,64.403961,3.280894,0.528659,-1305.160034,0.053794,0.000000
40.930000,14.620827,-1305.071045,0.007368,0.002099,0.053326,65.036682,3.313127,0.533258,-1305.071045,0.054228,0.000000
41.190002,14.889313,-1305.160034,0.007390,0.002119,0.053820,66.230972,3.373967,0.538201,-1305.160034,0.054661,0.000000
41.450001,14.772011,-1305.160034,0.007411,0.002134,0.054193,65.709183,3.347385,0.541929,-1305.160034,0.055095,0.000000
41.710003,14.699776,-1305.115601,0.007411,0.002148,0.054557,65.387871,3.331017,0.545570,-1305.115601,0.055529,0.000000
41.970001,14.584335,-1305.115601,0.007450,0.002160,0.054861,64.874367,3.304858,0.548605,-1305.115601,0.055962,0.000000
42.230003,15.213272,-1305.071045,0.007459,0.002188,0.055572,67.672012,3.447377,0.555717,-1305.071045,0.056396,0.000000
42.490002,14.893036,-1305.160034,0.007433,0.002197,0.055815,66.247536,3.374810,0.558147,-1305.160034,0.056829,0.000000
42.750004,15.163002,-1305.115601,0.007476,0.002221,0.056404,67.448402,3.435985,0.564044,-1305.115601,0.057263,0.000000
43.010002,14.881493,-1305.115601,0.007537,0.002232,0.056691,66.196182,3.372195,0.566905,-1305.115601,0.057697,0.000000
43.270000,15.036400,-1305.115601,0.007549,0.002246,0.057046,66.885246,3.407297,0.570459,-1305.115601,0.058130,0.000000
43.530003,15.499626,-1305.115601,0.007567,0.002269,0.057627,68.945778,3.512265,0.576273,-1305.115601,0.058564,0.000000
43.790001,15.372650,-1305.160034,0.007610,0.002283,0.057983,68.380966,3.483492,0.579827,-1305.160034,0.058997,0.000000
44.050003,15.212158,-1305.115601,0.007571,0.002295,0.058286,67.667061,3.447124,0.582862,-1305.115601,0.059422,0.000000
44.310001,15.459412,-1305.115601,0.007631,0.002315,0.058807,68.766899,3.503153,0.588067,-1305.115601,0.059856,0.000000
44.570004,15.828804,-1305.160034,0.007662,0.002340,0.059431,70.410034,3.586858,0.594308,-1305.160034,0.060290,0.000000
44.830002,15.614693,-1305.115601,0.007657,0.002354,0.059804,69.457619,3.538340,0.598040,-1305.115601,0.060723,0.000000
45.090004,15.176033,-1305.160034,0.007644,0.002362,0.059995,67.506363,3.438938,0.599948,-1305.160034,0.061157,0.000000
45.350002,15.075127,-1305.115601,0.007705,0.002372,0.060237,67.057510,3.416072,0.602374,-1305.115601,0.061590,0.000000
45.610001,15.926369,-1305.115601,0.007765,0.002403,0.061035,70.844025,3.608967,0.610352,-1305.115601,0.062024,0.000000
45.870003,15.871628,-1305.115601,0.007731,0.002419,0.061443,70.600525,3.596562,0.614429,-1305.115601,0.062458,0.000000
46.130001,16.297249,-1305.115601,0.007791,0.002444,0.062085,72.493782,3.693009,0.620848,-1305.115601,0.062891,0.000000
46.390003,15.956902,-1305.115601,0.007774,0.002458,0.062423,70.979843,3.615886,0.624228,-1305.115601,0.063325,0.000000
46.650002,15.982224,-1305.115601,0.007843,0.002473,0.062822,71.092484,3.621624,0.628217,-1305.115601,0.063758,0.000000
46.910004,16.282356,-1305.160034,0.007843,0.002494,0.063360,72.427536,3.689635,0.633595,-1305.160034,0.064192,0.000000
47.170002,16.294273,-1305.160034,0.007825,0.002510,0.063750,72.480545,3.692335,0.637497,-1305.160034,0.064626,0.000000
47.430004,16.122238,-1305.071045,0.007873,0.002523,0.064079,71.715294,3.653351,0.640794,-1305.071045,0.065059,0.000000
47.690002,15.967697,-1305.115601,0.007873,0.002536,0.064409,71.027863,3.618332,0.644087,-1305.115601,0.065493,0.000000
47.950001,16.755272,-1305.160034,0.007950,0.002564,0.065129,74.531174,3.796799,0.651286,-1305.160034,0.065926,0.000000
48.210003,16.464821,-1305.115601,0.007929,0.002577,0.065467,73.239182,3.730982,0.654670,-1305.115601,0.066360,0.000000
48.470001,16.412689,-1305.115601,0.007955,0.002593,0.065875,73.007286,3.719168,0.658746,-1305.115601,0.066794,0.000000
48.730003,16.586586,-1305.115601,0.008002,0.002611,0.066325,73.780823,3.758574,0.663254,-1305.115601,0.067227,0.000000
48.990002,16.875175,-1305.204590,0.007989,0.002631,0.066820,75.064529,3.823969,0.668197,-1305.204590,0.067661,0.000000
49.250004,16.819313,-1305.160034,0.008024,0.002645,0.067184,74.816040,3.811311,0.671842,-1305.160034,0.068094,0.000000
49.510002,16.705368,-1305.160034,0.008028,0.002658,0.067522,74.309189,3.785491,0.675222,-1305.160034,0.068528,0.000000
49.770000,17.300423,-1305.115601,0.008080,0.002684,0.068164,76.956123,3.920332,0.681641,-1305.115601,0.068962,0.000000
50.030003,17.311592,-1305.115601,0.008119,0.002703,0.068650,77.005806,3.922863,0.686497,-1305.115601,0.069395,0.000000
50.290001,17.059868,-1305.249023,0.008127,0.002717,0.069005,75.886086,3.865821,0.690051,-1305.249023,0.069829,0.000000
50.550003,17.015182,-1305.160034,0.008110,0.002731,0.069361,75.687309,3.855695,0.693609,-1305.160034,0.070263,0.000000
50.810001,17.492195,-1305.204590,0.008140,0.002753,0.069916,77.809174,3.963788,0.699157,-1305.204590,0.070696,0.000000
51.070004,17.439690,-1305.160034,0.008205,0.002767,0.070271,77.575615,3.951890,0.702711,-1305.160034,0.071130,0.000000
51.330002,17.332443,-1305.115601,0.008149,0.002779,0.070592,77.098557,3.927588,0.705921,-1305.115601,0.071563,0.000000
51.590004,17.876854,-1305.204590,0.008209,0.002803,0.071190,79.520218,4.050953,0.711905,-1305.204590,0.071997,0.000000
51.850002,17.994896,-1305.115601,0.008265,0.002820,0.071633,80.045296,4.077702,0.716329,-1305.115601,0.072431,0.000000
52.110001,17.867172,-1305.160034,0.008252,0.002836,0.072041,79.477150,4.048759,0.720406,-1305.160034,0.072864,0.000000
52.370003,17.837379,-1305.160034,0.008213,0.002851,0.072413,79.344627,4.042008,0.724134,-1305.160034,0.073298,0.000000
52.630001,18.057083,-1305.115601,0.008308,0.002871,0.072934,80.321915,4.091794,0.729338,-1305.115601,0.073732,0.000000
52.890003,18.172142,-1305.204590,0.008304,0.002887,0.073324,80.833725,4.117867,0.733240,-1305.204590,0.074165,0.000000
53.150002,17.920052,-1305.071045,0.008321,0.002897,0.073584,79.712372,4.060742,0.735840,-1305.071045,0.074590,0.000000
53.410004,18.257790,-1305.204590,0.008326,0.002917,0.074104,81.214706,4.137274,0.741045,-1305.204590,0.075024,0.000000
53.670002,18.652504,-1305.160034,0.008356,0.002939,0.074651,82.970482,4.226718,0.746506,-1305.160034,0.075457,0.000000
53.930004,18.539307,-1305.115601,0.008373,0.002953,0.074998,82.466957,4.201066,0.749977,-1305.115601,0.075891,0.000000
54.190002,18.789169,-1305.204590,0.008369,0.002974,0.075536,83.578400,4.257687,0.755355,-1305.204590,0.076325,0.000000
54.450001,18.507278,-1305.160034,0.008351,0.002985,0.075830,82.324486,4.193809,0.758304,-1305.160034,0.076758,0.000000
54.710003,18.632401,-1305.204590,0.008373,0.003005,0.076325,82.881058,4.222162,0.763247,-1305.204590,0.077192,0.000000
54.970001,18.854706,-1305.160034,0.008416,0.003022,0.076758,83.869919,4.272537,0.767581,-1305.160034,0.077626,0.000000
55.230003,18.636124,-1305.115601,0.008403,0.003034,0.077062,82.897621,4.223006,0.770616,-1305.115601,0.078059,0.000000
55.490002,19.243835,-1305.160034,0.008451,0.003059,0.077704,85.600853,4.360715,0.777035,-1305.160034,0.078493,0.000000
55.750004,19.170845,-1305.160034,0.008438,0.003076,0.078120,85.276176,4.344176,0.781199,-1305.160034,0.078926,0.000000
56.010002,19.122437,-1305.204590,0.008442,0.003092,0.078545,85.060844,4.333206,0.785445,-1305.204590,0.079360,0.000000
56.270004,18.966789,-1305.204590,0.008433,0.003106,0.078892,84.368492,4.297935,0.788916,-1305.204590,0.079794,0.000000
56.530003,19.222610,-1305.160034,0.008494,0.003122,0.079308,85.506439,4.355906,0.793079,-1305.160034,0.080227,0.000000
56.790001,19.300064,-1305.204590,0.008481,0.003139,0.079741,85.850975,4.373457,0.797413,-1305.204590,0.080661,0.000000
57.050003,19.025253,-1305.160034,0.008541,0.003150,0.080002,84.628555,4.311184,0.800017,-1305.160034,0.081094,0.000000
57.310001,19.729782,-1305.160034,0.008502,0.003173,0.080583,87.762451,4.470833,0.805827,-1305.160034,0.081528,0.000000
57.570004,19.934586,-1305.204590,0.008545,0.003193,0.081103,88.673462,4.517241,0.811031,-1305.204590,0.081962,0.000000
57.830002,19.842979,-1305.115601,0.008567,0.003209,0.081502,88.265984,4.496483,0.815020,-1305.115601,0.082395,0.000000
58.090004,19.518646,-1305.204590,0.008528,0.003223,0.081866,86.823273,4.422988,0.818661,-1305.204590,0.082829,0.000000
58.350002,19.656792,-1305.115601,0.008550,0.003238,0.082256,87.437775,4.454293,0.822564,-1305.115601,0.083262,0.000000
58.610004,20.079811,-1305.115601,0.008589,0.003259,0.082785,89.319458,4.550150,0.827855,-1305.115601,0.083696,0.000000
58.870003,20.092468,-1305.160034,0.008632,0.003275,0.083176,89.375763,4.553018,0.831757,-1305.160034,0.084130,0.000000
59.130001,20.133430,-1305.160034,0.008610,0.003291,0.083583,89.557968,4.562300,0.835833,-1305.160034,0.084563,0.000000
59.390003,20.245888,-1305.249023,0.008640,0.003307,0.083999,90.058205,4.587783,0.839993,-1305.249023,0.084997,0.000000
59.650002,20.551979,-1305.160034,0.008619,0.003326,0.084477,91.419769,4.657145,0.844766,-1305.160034,0.085430,0.000000
59.910004,20.616402,-1305.160034,0.008696,0.003340,0.084841,91.706337,4.671743,0.848407,-1305.160034,0.085864,0.000000
60.170002,20.578415,-1305.204590,0.008679,0.003354,0.085196,91.537361,4.663135,0.851961,-1305.204590,0.086297,0.000000
60.430004,20.700554,-1305.071045,0.008649,0.003375,0.085734,92.080666,4.690813,0.857339,-1305.071045,0.086731,0.000000
60.690002,21.586060,-1305.204590,0.008688,0.003398,0.086306,96.019592,4.891471,0.863062,-1305.204590,0.087165,0.000000
60.950005,21.352203,-1305.115601,0.008714,0.003411,0.086645,94.979347,4.838479,0.866446,-1305.115601,0.087598,0.000000
61.210003,21.496689,-1305.160034,0.008679,0.003426,0.087017,95.622047,4.871219,0.870174,-1305.160034,0.088032,0.000000
61.470001,22.211639,-1305.160034,0.008692,0.003450,0.087624,98.802307,5.033229,0.876245,-1305.160034,0.088466,0.000000
61.730003,22.147964,-1305.115601,0.008761,0.003463,0.087972,98.519066,5.018801,0.879716,-1305.115601,0.088899,0.000000
61.990002,22.377724,-1305.160034,0.008757,0.003481,0.088405,99.541084,5.070865,0.884049,-1305.160034,0.089324,0.000000
62.250004,22.777649,-1305.160034,0.008757,0.003499,0.088882,101.320045,5.161489,0.888818,-1305.160034,0.089758,0.000000
62.510002,23.278488,-1305.204590,0.008744,0.003518,0.089359,103.547890,5.274981,0.893591,-1305.204590,0.090191,0.000000
62.770004,23.304184,-1305.204590,0.008765,0.003532,0.089714,103.662186,5.280804,0.897145,-1305.204590,0.090625,0.000000
63.030003,23.433395,-1305.115601,0.008761,0.003546,0.090079,104.236946,5.310083,0.900786,-1305.115601,0.091059,0.000000
63.290005,23.519417,-1305.249023,0.008783,0.003559,0.090391,104.619591,5.329576,0.903909,-1305.249023,0.091492,0.000000
63.550003,24.682335,-1305.160034,0.008852,0.003585,0.091059,109.792511,5.593097,0.910585,-1305.160034,0.091926,0.000000
63.810001,24.564293,-1305.160034,0.008860,0.003596,0.091345,109.267433,5.566348,0.913450,-1305.160034,0.092359,0.000000
64.070000,25.299728,-1305.204590,0.008839,0.003618,0.091900,112.538811,5.733000,0.918999,-1305.204590,0.092793,0.000000
64.330002,25.053589,-1305.115601,0.008890,0.003627,0.092117,111.443932,5.677224,0.921168,-1305.115601,0.093227,0.000000
64.590004,25.693321,-1305.160034,0.008890,0.003645,0.092576,114.289604,5.822190,0.925763,-1305.160034,0.093660,0.000000
64.850006,26.626488,-1305.160034,0.008890,0.003667,0.093149,118.440536,6.033648,0.931485,-1305.160034,0.094094,0.000000
65.110001,26.805977,-1305.160034,0.008890,0.003681,0.093487,119.238937,6.074321,0.934869,-1305.160034,0.094528,0.000000
65.370003,26.914703,-1305.204590,0.008912,0.003693,0.093808,119.722580,6.098959,0.938079,-1305.204590,0.094961,0.000000
65.630005,27.709351,-1305.115601,0.008942,0.003714,0.094328,123.257347,6.279028,0.943283,-1305.115601,0.095395,0.000000
65.889999,28.703957,-1305.204590,0.008912,0.003740,0.094996,127.681580,6.504409,0.949959,-1305.204590,0.095829,0.000000
66.150002,28.838013,-1305.160034,0.008933,0.003753,0.095326,128.277893,6.534787,0.953256,-1305.160034,0.096262,0.000000
66.410004,28.668579,-1305.160034,0.009011,0.003762,0.095551,127.524208,6.496393,0.955508,-1305.160034,0.096696,0.000000
66.670006,29.374596,-1305.249023,0.008972,0.003777,0.095941,130.664734,6.656378,0.959410,-1305.249023,0.097129,0.000000
66.930000,30.477196,-1305.160034,0.009015,0.003801,0.096539,135.569336,6.906231,0.965394,-1305.160034,0.097563,0.000000
67.190002,30.787750,-1305.204590,0.009011,0.003816,0.096921,136.950760,6.976604,0.969213,-1305.204590,0.097997,0.000000
67.450005,32.263466,-1305.160034,0.009063,0.003842,0.097589,143.515060,7.311006,0.975890,-1305.160034,0.098430,0.000000
67.710007,32.378899,-1305.249023,0.009024,0.003855,0.097919,144.028534,7.337163,0.979186,-1305.249023,0.098864,0.000000
67.970001,32.959053,-1305.204590,0.009033,0.003871,0.098335,146.609192,7.468628,0.983346,-1305.204590,0.099297,0.000000
68.230003,33.725769,-1305.160034,0.009058,0.003892,0.098855,150.019714,7.642368,0.988550,-1305.160034,0.099731,0.000000
68.490005,34.502167,-1305.204590,0.009093,0.003908,0.099271,153.473297,7.818303,0.992714,-1305.204590,0.100165,0.000000
68.750000,34.868584,-1305.204590,0.009102,0.003921,0.099601,155.103210,7.901334,0.996010,-1305.204590,0.100598,0.000000
69.010002,35.147118,-1305.249023,0.009106,0.003933,0.099905,156.342194,7.964451,0.999046,-1305.249023,0.101032,0.000000
69.270004,36.992226,-1305.204590,0.009106,0.003962,0.100641,164.549637,8.382559,1.006415,-1305.204590,0.101465,0.000000
69.530006,37.401085,-1305.204590,0.009089,0.003975,0.100971,166.368332,8.475206,1.009712,-1305.204590,0.101899,0.000000
69.790001,37.987198,-1305.204590,0.009140,0.003993,0.101413,168.975494,8.608022,1.014132,-1305.204590,0.102333,0.000000
70.050003,38.849991,-1305.204590,0.009140,0.004010,0.101847,172.813385,8.803534,1.018470,-1305.204590,0.102766,0.000000
70.310005,39.839012,-1305.204590,0.009205,0.004028,0.102324,177.212784,9.027650,1.023239,-1305.204590,0.103200,0.000000
70.570000,40.353256,-1305.204590,0.009136,0.004043,0.102688,179.500244,9.144178,1.026884,-1305.204590,0.103633,0.000000
70.830002,40.988899,-1305.160034,0.009218,0.004055,0.103000,182.327728,9.288218,1.030002,-1305.160034,0.104067,0.000000
71.090004,42.506317,-1305.204590,0.009175,0.004079,0.103599,189.077545,9.632070,1.035986,-1305.204590,0.104492,0.000000
71.350006,43.753014,-1305.204590,0.009188,0.004100,0.104145,194.623123,9.914575,1.041452,-1305.204590,0.104926,0.000000
71.610001,44.327217,-1305.204590,0.009231,0.004113,0.104475,197.177307,10.044690,1.044748,-1305.204590,0.105359,0.000000
71.870003,45.070839,-1305.160034,0.009235,0.004128,0.104856,200.485107,10.213198,1.048563,-1305.160034,0.105793,0.000000
72.130005,46.489578,-1305.160034,0.009261,0.004151,0.105429,206.795975,10.534689,1.054286,-1305.160034,0.106226,0.000000
72.390007,47.195229,-1305.204590,0.009257,0.004164,0.105767,209.934860,10.694592,1.057670,-1305.204590,0.106660,0.000000
72.650002,47.833099,-1305.204590,0.009261,0.004177,0.106105,212.772247,10.839135,1.061050,-1305.204590,0.107094,0.000000
72.910004,49.368767,-1305.115601,0.009296,0.004199,0.106652,219.603241,11.187122,1.066515,-1305.115601,0.107527,0.000000
73.170006,50.725693,-1305.204590,0.009309,0.004218,0.107146,225.639145,11.494607,1.071458,-1305.204590,0.107961,0.000000
73.430000,51.576935,-1305.160034,0.009270,0.004233,0.107527,229.425659,11.687500,1.075274,-1305.160034,0.108394,0.000000
73.690002,52.738365,-1305.249023,0.009300,0.004249,0.107926,234.591965,11.950685,1.079263,-1305.249023,0.108828,0.000000
73.950005,53.623123,-1305.204590,0.009313,0.004268,0.108403,238.527557,12.151174,1.084032,-1305.204590,0.109262,0.000000
74.210007,55.120430,-1305.160034,0.009339,0.004285,0.108846,245.187912,12.490468,1.088456,-1305.160034,0.109695,0.000000
74.470001,55.874481,-1305.249023,0.009343,0.004298,0.109166,248.542099,12.661339,1.091662,-1305.249023,0.110129,0.000000
74.730003,56.797226,-1305.160034,0.009321,0.004314,0.109565,252.646683,12.870436,1.095651,-1305.160034,0.110562,0.000000
74.990005,58.695206,-1305.249023,0.009360,0.004336,0.110138,261.089325,13.300524,1.101378,-1305.249023,0.110996,0.000000
75.250000,59.806366,-1305.160034,0.009343,0.004350,0.110493,266.032013,13.552316,1.104932,-1305.160034,0.111430,0.000000
75.510002,61.353943,-1305.249023,0.009352,0.004372,0.111040,272.915955,13.903003,1.110397,-1305.249023,0.111863,0.000000
75.770004,62.371643,-1305.249023,0.009386,0.004384,0.111343,277.442932,14.133616,1.113433,-1305.249023,0.112297,0.000000
76.030006,63.613869,-1305.160034,0.009334,0.004403,0.111829,282.968628,14.415109,1.118289,-1305.160034,0.112731,0.000000
76.290001,65.033730,-1305.249023,0.009365,0.004420,0.112262,289.284485,14.736854,1.122623,-1305.249023,0.113164,0.000000
76.550003,65.757988,-1305.160034,0.009373,0.004432,0.112566,292.506134,14.900973,1.125658,-1305.160034,0.113598,0.000000
76.810005,67.417290,-1305.160034,0.009369,0.004444,0.112869,299.887085,15.276977,1.128694,-1305.160034,0.113043,0.000000
77.070007,66.958153,-1305.204590,0.009416,0.004442,0.112835,297.844727,15.172935,1.128349,-1305.204590,0.113043,0.000000
77.330002,66.552635,-1305.160034,0.009382,0.004442,0.112817,296.040894,15.081042,1.128175,-1305.160034,0.112835,0.000000
77.590004,66.239479,-1305.204590,0.009412,0.004441,0.112809,294.647919,15.010080,1.128088,-1305.204590,0.112835,0.000000
77.850006,65.967262,-1305.160034,0.009369,0.004441,0.112800,293.437042,14.948395,1.128001,-1305.160034,0.112835,0.000000
78.110001,65.738625,-1305.160034,0.009390,0.004441,0.112800,292.420013,14.896585,1.128001,-1305.160034,0.112835,0.000000
78.370003,65.525261,-1305.204590,0.009412,0.004441,0.112791,291.470917,14.848237,1.127914,-1305.204590,0.112835,0.000000
78.630005,65.346153,-1305.249023,0.009434,0.004441,0.112791,290.674194,14.807650,1.127914,-1305.249023,0.112835,0.000000
78.890007,65.180824,-1305.249023,0.009447,0.004441,0.112791,289.938782,14.770185,1.127914,-1305.249023,0.112835,0.000000
79.150002,65.030754,-1305.204590,0.009412,0.004441,0.112791,289.271240,14.736180,1.127914,-1305.204590,0.112835,0.000000
79.410004,64.895958,-1305.204590,0.009416,0.004440,0.112783,288.671631,14.705635,1.127827,-1305.204590,0.112835,0.000000
79.670006,64.753334,-1305.160034,0.009416,0.004440,0.112783,288.037201,14.673316,1.127827,-1305.160034,0.112835,0.000000
79.930000,64.660240,-1305.160034,0.009382,0.004440,0.112783,287.623108,14.652220,1.127827,-1305.160034,0.112835,0.000000
80.190002,64.544060,-1305.249023,0.009416,0.004440,0.112783,287.106323,14.625893,1.127827,-1305.249023,0.112835,0.000000
80.450005,64.456184,-1305.293457,0.009455,0.004440,0.112783,286.715424,14.605980,1.127827,-1305.293457,0.112835,0.000000
80.710007,64.375008,-1305.160034,0.009365,0.004440,0.112783,286.354340,14.587585,1.127827,-1305.160034,0.112835,0.000000
80.970001,64.269615,-1305.249023,0.009421,0.004440,0.112783,285.885529,14.563703,1.127827,-1305.249023,0.112835,0.000000
81.230003,64.197380,-1305.160034,0.009390,0.004440,0.112783,285.564209,14.547335,1.127827,-1305.160034,0.112835,0.000000
81.490005,64.115089,-1305.249023,0.009369,0.004440,0.112783,285.198151,14.528687,1.127827,-1305.249023,0.112835,0.000000
81.750008,64.040993,-1305.204590,0.009434,0.004440,0.112783,284.868561,14.511897,1.127827,-1305.204590,0.112835,0.000000
82.010002,63.989601,-1305.204590,0.009408,0.004440,0.112783,284.639954,14.500251,1.127827,-1305.204590,0.112835,0.000000
82.270004,63.904320,-1305.293457,0.009382,0.004440,0.112783,284.260620,14.480926,1.127827,-1305.293457,0.112835,0.000000
82.530006,63.858528,-1305.204590,0.009408,0.004440,0.112783,284.056915,14.470550,1.127827,-1305.204590,0.112835,0.000000
82.790001,63.790382,-1305.204590,0.009416,0.004440,0.112783,283.753784,14.455108,1.127827,-1305.204590,0.112835,0.000000
83.050003,63.735268,-1305.160034,0.009373,0.004440,0.112783,283.508636,14.442617,1.127827,-1305.160034,0.112835,0.000000
83.310005,63.687981,-1305.160034,0.009369,0.004440,0.112783,283.298279,14.431902,1.127827,-1305.160034,0.112835,0.000000
83.570007,63.631004,-1305.338013,0.009395,0.004440,0.112783,283.044830,14.418992,1.127827,-1305.338013,0.112835,0.000000
83.830002,63.595634,-1305.204590,0.009438,0.004440,0.112783,282.887512,14.410976,1.127827,-1305.204590,0.112835,0.000000
84.090004,63.541634,-1305.293457,0.009442,0.004440,0.112783,282.647308,14.398740,1.127827,-1305.293457,0.112835,0.000000
84.350006,63.492485,-1305.293457,0.009416,0.004440,0.112783,282.428680,14.387603,1.127827,-1305.293457,0.112835,0.000000
84.610001,63.454506,-1305.160034,0.009455,0.004440,0.112783,282.259735,14.378997,1.127827,-1305.160034,0.112835,0.000000
84.870003,63.402367,-1305.204590,0.009425,0.004440,0.112783,282.027802,14.367182,1.127827,-1305.204590,0.112835,0.000000
85.130005,63.365501,-1305.160034,0.009378,0.004440,0.112783,281.863831,14.358828,1.127827,-1305.160034,0.112835,0.000000
85.390007,63.319695,-1305.249023,0.009447,0.004440,0.112783,281.660065,14.348449,1.127827,-1305.249023,0.112835,0.000000
85.650002,63.277245,-1305.293457,0.009434,0.004440,0.112783,281.471252,14.338829,1.127827,-1305.293457,0.112835,0.000000
85.910004,63.252678,-1305.249023,0.009408,0.004440,0.112783,281.361969,14.333261,1.127827,-1305.249023,0.112835,0.000000
86.170006,63.209480,-1305.249023,0.009434,0.004440,0.112783,281.169800,14.323473,1.127827,-1305.249023,0.112835,0.000000
86.430000,63.183418,-1305.204590,0.009395,0.004440,0.112783,281.053894,14.317567,1.127827,-1305.204590,0.112835,0.000000
86.690002,63.150642,-1305.249023,0.009434,0.004440,0.112783,280.908081,14.310140,1.127827,-1305.249023,0.112835,0.000000
86.950005,63.114525,-1305.293457,0.009399,0.004440,0.112783,280.747437,14.301956,1.127827,-1305.293457,0.112835,0.000000
87.210007,63.082497,-1305.160034,0.009403,0.004440,0.112783,280.604950,14.294698,1.127827,-1305.160034,0.112835,0.000000
87.470001,63.047493,-1305.249023,0.009429,0.004440,0.112774,280.449249,14.286766,1.127740,-1305.249023,0.112835,0.000000
87.730003,63.021057,-1305.204590,0.009399,0.004440,0.112774,280.331665,14.280776,1.127740,-1305.204590,0.112835,0.000000
87.990005,62.981216,-1305.204590,0.009447,0.004440,0.112774,280.154449,14.271748,1.127740,-1305.204590,0.112835,0.000000
88.250008,62.962967,-1305.249023,0.009416,0.004440,0.112774,280.073273,14.267612,1.127740,-1305.249023,0.112835,0.000000
88.510002,62.918282,-1305.249023,0.009425,0.004440,0.112774,279.874481,14.257486,1.127740,-1305.249023,0.112835,0.000000
88.770004,62.894821,-1305.249023,0.009390,0.004440,0.112774,279.770142,14.252170,1.127740,-1305.249023,0.112835,0.000000
89.030006,62.847534,-1305.204590,0.009403,0.004440,0.112774,279.559784,14.241454,1.127740,-1305.204590,0.112835,0.000000
89.290001,62.833382,-1305.204590,0.009416,0.004440,0.112774,279.496826,14.238248,1.127740,-1305.204590,0.112835,0.000000
89.550003,62.797630,-1305.249023,0.009425,0.004440,0.112774,279.337799,14.230146,1.127740,-1305.249023,0.112835,0.000000
89.810005,62.773804,-1305.204590,0.009434,0.004440,0.112774,279.231812,14.224748,1.127740,-1305.204590,0.112835,0.000000
90.070007,62.752579,-1305.204590,0.009429,0.004440,0.112774,279.137421,14.219938,1.127740,-1305.204590,0.112835,0.000000
90.330002,62.723907,-1305.160034,0.009369,0.004440,0.112774,279.009888,14.213440,1.127740,-1305.160034,0.112835,0.000000
90.590004,62.704170,-1305.204590,0.009447,0.004440,0.112774,278.922089,14.208968,1.127740,-1305.204590,0.112835,0.000000
90.850006,62.672516,-1305.204590,0.009408,0.004440,0.112774,278.781281,14.201795,1.127740,-1305.204590,0.112835,0.000000
91.110001,62.645706,-1305.249023,0.009395,0.004440,0.112774,278.662018,14.195721,1.127740,-1305.249023,0.112835,0.000000
91.370003,62.629692,-1305.249023,0.009403,0.004440,0.112774,278.590790,14.192091,1.127740,-1305.249023,0.112835,0.000000
91.630005,62.613312,-1305.293457,0.009451,0.004440,0.112774,278.517914,14.188379,1.127740,-1305.293457,0.112835,0.000000
91.890007,62.592827,-1305.249023,0.009421,0.004440,0.112774,278.426788,14.183738,1.127740,-1305.249023,0.112835,0.000000
92.150002,62.564903,-1305.249023,0.009416,0.004440,0.112774,278.302582,14.177410,1.127740,-1305.249023,0.112835,0.000000
92.410004,62.534737,-1305.204590,0.009429,0.004440,0.112774,278.168396,14.170574,1.127740,-1305.204590,0.112835,0.000000
92.670006,62.527664,-1305.249023,0.009412,0.004440,0.112774,278.136932,14.168972,1.127740,-1305.249023,0.112835,0.000000
92.930008,62.503090,-1305.204590,0.009438,0.004440,0.112774,278.027618,14.163403,1.127740,-1305.204590,0.112835,0.000000
93.190002,62.488564,-1305.249023,0.009399,0.004440,0.112774,277.963013,14.160111,1.127740,-1305.249023,0.112835,0.000000
93.450005,62.472183,-1305.204590,0.009395,0.004440,0.112774,277.890137,14.156399,1.127740,-1305.204590,0.112835,0.000000
93.710007,62.462128,-1305.249023,0.009395,0.004440,0.112774,277.845428,14.154120,1.127740,-1305.249023,0.112835,0.000000
93.970001,62.431595,-1305.338013,0.009408,0.004440,0.112774,277.709595,14.147202,1.127740,-1305.338013,0.112835,0.000000
94.230003,62.421913,-1305.249023,0.009403,0.004440,0.112774,277.666534,14.145007,1.127740,-1305.249023,0.112835,0.000000
94.490005,62.399940,-1305.249023,0.009390,0.004440,0.112774,277.568787,14.140029,1.127740,-1305.249023,0.112835,0.000000
94.750008,62.382812,-1305.249023,0.009425,0.004440,0.112774,277.492615,14.136147,1.127740,-1305.249023,0.112835,0.000000
95.010002,62.364937,-1305.204590,0.009438,0.004440,0.112774,277.413086,14.132097,1.127740,-1305.204590,0.112835,0.000000
95.270004,62.347809,-1305.293457,0.009438,0.004440,0.112774,277.336914,14.128215,1.127740,-1305.293457,0.112835,0.000000
95.530006,62.321373,-1305.204590,0.009403,0.004440,0.112774,277.219299,14.122225,1.127740,-1305.204590,0.112835,0.000000
95.790001,62.323975,-1305.293457,0.009399,0.004440,0.112774,277.230896,14.122814,1.127740,-1305.293457,0.112835,0.000000
96.050003,62.310944,-1305.293457,0.009429,0.004440,0.112774,277.172913,14.119862,1.127740,-1305.293457,0.112835,0.000000
96.310005,62.290092,-1305.160034,0.009434,0.004440,0.112774,277.080170,14.115136,1.127740,-1305.160034,0.112835,0.000000
96.570007,62.275940,-1305.249023,0.009442,0.004440,0.112774,277.017212,14.111929,1.127740,-1305.249023,0.112835,0.000000
96.830002,62.263649,-1305.249023,0.009416,0.004440,0.112774,276.962555,14.109145,1.127740,-1305.249023,0.112835,0.000000
97.090004,62.242798,-1305.249023,0.009386,0.004440,0.112774,276.869781,14.104420,1.127740,-1305.249023,0.112835,0.000000
97.350006,62.233116,-1305.249023,0.009451,0.004440,0.112774,276.826721,14.102225,1.127740,-1305.249023,0.112835,0.000000
97.610008,62.219337,-1305.204590,0.009429,0.004440,0.112774,276.765442,14.099103,1.127740,-1305.204590,0.112835,0.000000
97.870003,62.202209,-1305.293457,0.009429,0.004440,0.112774,276.689240,14.095222,1.127740,-1305.293457,0.112835,0.000000
98.130005,62.186943,-1305.204590,0.009442,0.004440,0.112774,276.621338,14.091763,1.127740,-1305.204590,0.112835,0.000000
98.390007,62.174652,-1305.249023,0.009412,0.004440,0.112774,276.566650,14.088977,1.127740,-1305.249023,0.112835,0.000000
98.650002,62.157150,-1305.204590,0.009429,0.004440,0.112774,276.488800,14.085011,1.127740,-1305.204590,0.112835,0.000000
98.910004,62.151939,-1305.293457,0.009421,0.004440,0.112774,276.465637,14.083831,1.127740,-1305.293457,0.112835,0.000000
99.170006,62.134811,-1305.338013,0.009386,0.004440,0.112774,276.389435,14.079949,1.127740,-1305.338013,0.112835,0.000000
99.430008,62.119171,-1305.115601,0.009447,0.004440,0.112774,276.319885,14.076406,1.127740,-1305.115601,0.112835,0.000000
99.690002,62.103157,-1305.249023,0.009408,0.004440,0.112774,276.248627,14.072777,1.127740,-1305.249023,0.112835,0.000000
99.950005,62.090874,-1305.249023,0.009421,0.004440,0.112774,276.194000,14.069993,1.127740,-1305.249023,0.112835,0.000000
100.210007,62.091240,-1305.204590,0.009442,0.004440,0.112774,276.195618,14.070076,1.127740,-1305.204590,0.112835,0.000000
100.470001,62.063690,-1305.249023,0.009412,0.004440,0.112774,276.073090,14.063833,1.127740,-1305.249023,0.112835,0.000000
100.730003,62.053261,-1305.204590,0.009451,0.004440,0.112774,276.026703,14.061470,1.127740,-1305.204590,0.112835,0.000000
100.990005,62.020119,-1305.115601,0.009399,0.004440,0.112774,275.879272,14.053960,1.127740,-1305.115601,0.112835,0.000000
101.250008,62.019745,-1305.204590,0.009434,0.004440,0.112774,275.877594,14.053875,1.127740,-1305.204590,0.112835,0.000000
101.510002,62.014534,-1305.160034,0.009429,0.004440,0.112774,275.854431,14.052694,1.127740,-1305.160034,0.112835,0.000000
101.770004,61.988472,-1305.249023,0.009386,0.004440,0.112774,275.738495,14.046789,1.127740,-1305.249023,0.112835,0.000000
102.030006,61.978416,-1305.160034,0.009434,0.004440,0.112774,275.693756,14.044510,1.127740,-1305.160034,0.112835,0.000000
102.290009,61.972832,-1305.160034,0.009421,0.004440,0.112774,275.668915,14.043244,1.127740,-1305.160034,0.112835,0.000000
102.550003,61.958679,-1305.249023,0.009403,0.004440,0.112774,275.605957,14.040037,1.127740,-1305.249023,0.112835,0.000000
102.810005,61.965752,-1305.204590,0.009399,0.004440,0.112774,275.637421,14.041639,1.127740,-1305.204590,0.112835,0.000000
103.070007,61.950485,-1305.204590,0.009382,0.004440,0.112774,275.569519,14.038180,1.127740,-1305.204590,0.112835,0.000000
103.330002,61.922928,-1305.204590,0.009447,0.004440,0.112774,275.446930,14.031936,1.127740,-1305.204590,0.112835,0.000000
103.590004,61.943413,-1305.115601,0.009403,0.004440,0.112774,275.538055,14.036578,1.127740,-1305.115601,0.112835,0.000000
103.850006,61.895744,-1305.293457,0.009390,0.004440,0.112774,275.326019,14.025776,1.127740,-1305.293457,0.112835,0.000000
104.110008,61.906921,-1305.160034,0.009447,0.004440,0.112774,275.375732,14.028309,1.127740,-1305.160034,0.112835,0.000000
104.370003,61.904312,-1305.204590,0.009451,0.004440,0.112774,275.364136,14.027718,1.127740,-1305.204590,0.112835,0.000000
104.630005,61.868935,-1305.160034,0.009434,0.004440,0.112774,275.206757,14.019701,1.127740,-1305.160034,0.112835,0.000000
104.890007,61.864471,-1305.204590,0.009412,0.004440,0.112774,275.186920,14.018689,1.127740,-1305.204590,0.112835,0.000000
105.150002,61.864838,-1305.293457,0.009403,0.004440,0.112774,275.188538,14.018773,1.127740,-1305.293457,0.112835,0.000000
105.410004,61.851807,-1305.204590,0.009464,0.004440,0.112774,275.130585,14.015820,1.127740,-1305.204590,0.112835,0.000000
105.670006,61.826859,-1305.249023,0.009408,0.004440,0.112774,275.019592,14.010166,1.127740,-1305.249023,0.112835,0.000000
105.930008,61.835793,-1305.204590,0.009408,0.004440,0.112774,275.059357,14.012191,1.127740,-1305.204590,0.112835,0.000000
106.190002,61.824997,-1305.115601,0.009412,0.004440,0.112774,275.011322,14.009745,1.127740,-1305.115601,0.112835,0.000000
106.450005,61.815689,-1305.249023,0.009412,0.004440,0.112774,274.969910,14.007635,1.127740,-1305.249023,0.112835,0.000000
106.710007,61.809731,-1305.160034,0.009429,0.004440,0.112774,274.943420,14.006286,1.127740,-1305.160034,0.112835,0.000000
106.970009,61.791855,-1305.293457,0.009455,0.004440,0.112774,274.863892,14.002234,1.127740,-1305.293457,0.112835,0.000000
107.200005,61.774353,-1305.160034,0.009416,0.004440,0.112774,274.786041,13.998268,1.127740,-1305.160034,0.112835,0.000000