File: Data/Automembrane/AutoHeating-17wt-1-4_12152023_164019.csv
Time (sec),S:Load (lbs),S:HL1 (DIM),S:LVDT (in),S:Position (in),Ch:Position (mm),Ch:Load (N),Ch:Stress (MPa),Ch:Strain (mm/mm),Ch:HL1 (DIM),Set Point (),Cycles ()
0.110000,-0.003349,-107.199089,0.000022,-0.000000,-0.000000,-0.014898,-0.000759,-0.000000,-107.199089,0.000208,0.000000
0.350000,0.006699,-107.110130,0.000017,-0.000000,-0.000000,0.029797,0.001518,-0.000000,-107.110130,0.000226,0.000000
0.590000,0.013779,-107.199089,0.000039,0.000129,0.003278,0.061291,0.003122,0.032785,-107.199089,0.004215,0.000000
0.830000,0.004097,-107.243576,0.000155,0.000283,0.007181,0.018224,0.000928,0.071807,-107.243576,0.008222,0.000000
1.070000,0.015266,-107.154610,0.000306,0.000434,0.011031,0.067908,0.003459,0.110315,-107.154610,0.012211,0.000000
1.310000,-0.000374,-107.199089,0.000483,0.000596,0.015151,-0.001663,-0.000085,0.151506,-107.199089,0.016217,0.000000
1.550000,-0.036491,-107.199089,0.000660,0.000751,0.019088,-0.162322,-0.008269,0.190880,-107.199089,0.020206,0.000000
1.790000,-0.029045,-107.199089,0.000815,0.000912,0.023173,-0.129199,-0.006582,0.231726,-107.199089,0.024213,0.000000
2.030000,0.019363,-107.243576,0.000974,0.001066,0.027084,0.086133,0.004388,0.270836,-107.243576,0.028202,0.000000
2.270000,0.024574,-107.154610,0.001108,0.001219,0.030969,0.109312,0.005569,0.309688,-107.154610,0.032209,0.000000
2.510000,0.011543,-107.332535,0.001319,0.001388,0.035244,0.051347,0.002616,0.352442,-107.332535,0.036198,0.000000
2.750000,-0.010803,-107.154610,0.001457,0.001539,0.039086,-0.048055,-0.002448,0.390862,-107.154610,0.040205,0.000000
2.990000,0.018242,-107.199089,0.001608,0.001698,0.043136,0.081144,0.004134,0.431361,-107.199089,0.044194,0.000000
3.230000,0.013779,-107.243576,0.001789,0.001848,0.046943,0.061291,0.003122,0.469433,-107.243576,0.048201,0.000000
3.470000,0.005211,-107.199089,0.001966,0.002013,0.051123,0.023179,0.001181,0.511230,-107.199089,0.052190,0.000000
3.710000,-0.029419,-107.332535,0.002126,0.002170,0.055112,-0.130862,-0.006666,0.551122,-107.332535,0.056196,0.000000
3.950000,-0.001862,-107.288055,0.002276,0.002330,0.059188,-0.008281,-0.000422,0.591882,-107.288055,0.060186,0.000000
4.190000,0.040215,-107.288055,0.002449,0.002479,0.062961,0.178883,0.009113,0.629606,-107.288055,0.064192,0.000000
4.430000,0.013779,-107.332535,0.002604,0.002645,0.067193,0.061291,0.003122,0.671929,-107.332535,0.068181,0.000000
4.670000,-0.006706,-107.243576,0.002781,0.002799,0.071104,-0.029831,-0.001520,0.711042,-107.243576,0.072188,0.000000
4.910000,0.006699,-107.332535,0.002932,0.002958,0.075128,0.029797,0.001518,0.751279,-107.332535,0.076194,0.000000
5.150000,0.044685,-107.377014,0.003104,0.003110,0.078996,0.198770,0.010126,0.789957,-107.377014,0.080184,0.000000
5.390000,0.013779,-107.332535,0.003272,0.003273,0.083133,0.061291,0.003122,0.831326,-107.332535,0.084190,0.000000
5.630000,-0.025322,-107.332535,0.003441,0.003428,0.087070,-0.112638,-0.005738,0.870696,-107.332535,0.088180,0.000000
5.870000,0.003349,-107.288055,0.003609,0.003589,0.091163,0.014898,0.000759,0.911630,-107.288055,0.092186,0.000000
6.110000,0.007820,-107.421494,0.003768,0.003738,0.094944,0.034786,0.001772,0.949441,-107.421494,0.096176,0.000000
6.350000,0.029419,-107.332535,0.003949,0.003895,0.098942,0.130862,0.006666,0.989421,-107.332535,0.100182,0.000000
6.590000,-0.013031,-107.332535,0.004117,0.004062,0.103183,-0.057965,-0.002953,1.031827,-107.332535,0.104171,0.000000
6.830000,-0.005211,-107.377014,0.004260,0.004216,0.107094,-0.023179,-0.001181,1.070940,-107.377014,0.108178,0.000000
7.070000,0.030159,-107.332535,0.004445,0.004374,0.111092,0.134154,0.006834,1.110920,-107.332535,0.112167,0.000000
7.310000,0.037239,-107.421494,0.004587,0.004531,0.115081,0.165648,0.008438,1.150809,-107.421494,0.116174,0.000000
7.550000,0.008934,-107.377014,0.004773,0.004690,0.119131,0.039741,0.002024,1.191311,-107.377014,0.120163,0.000000
7.790000,-0.006706,-107.421494,0.004928,0.004845,0.123068,-0.029831,-0.001520,1.230681,-107.421494,0.124170,0.000000
8.030001,0.021599,-107.377014,0.005083,0.005005,0.127118,0.096076,0.004894,1.271180,-107.377014,0.128159,0.000000
8.270000,0.029045,-107.465981,0.005243,0.005154,0.130916,0.129199,0.006582,1.309165,-107.465981,0.132166,0.000000
8.510000,0.060326,-107.421494,0.005407,0.005318,0.135070,0.268342,0.013670,1.350704,-107.421494,0.136155,0.000000
8.750000,0.087875,-107.510460,0.005575,0.005477,0.139112,0.390889,0.019913,1.391119,-107.510460,0.140161,0.000000
8.990001,0.366043,-107.421494,0.005739,0.005637,0.143170,1.628241,0.082947,1.431705,-107.421494,0.144150,0.000000
9.230000,0.665428,-107.421494,0.005898,-0.000009,-0.000225,2.959972,0.150788,-0.002252,-107.421494,0.001041,0.000000
9.470000,0.562279,-107.377014,0.005907,-0.000010,-0.000243,2.501141,0.127414,-0.002426,-107.377014,-0.000026,0.000000
9.710000,0.532494,-107.510460,0.005907,-0.000010,-0.000243,2.368650,0.120665,-0.002426,-107.510460,-0.000026,0.000000
9.950001,0.487061,-107.465981,0.005907,-0.000009,-0.000234,2.166553,0.110369,-0.002339,-107.465981,0.000295,0.000000
10.190001,0.489296,-107.465981,0.005894,-0.000009,-0.000234,2.176497,0.110876,-0.002339,-107.465981,0.000694,0.000000
10.430000,0.566376,-107.510460,0.005920,0.000007,0.000174,2.519365,0.128343,0.001737,-107.510460,0.001101,0.000000
10.670000,0.593559,-107.465981,0.005915,0.000020,0.000512,2.640284,0.134502,0.005117,-107.465981,0.001500,0.000000
10.910001,0.706390,-107.510460,0.005941,0.000041,0.001032,3.142181,0.160070,0.010321,-107.510460,0.001899,0.000000
11.150001,0.760757,-107.510460,0.005967,0.000056,0.001414,3.384018,0.172390,0.014137,-107.510460,0.002298,0.000000
11.390000,0.785332,-107.510460,0.005984,0.000074,0.001874,3.493330,0.177959,0.018735,-107.510460,0.002697,0.000000
11.630000,0.829643,-107.554939,0.005989,0.000088,0.002229,3.690438,0.188000,0.022289,-107.554939,0.003096,0.000000
11.870001,0.895180,-107.510460,0.006015,0.000103,0.002610,3.981958,0.202851,0.026104,-107.510460,0.003495,0.000000
12.110001,0.945084,-107.599419,0.006019,0.000121,0.003079,4.203942,0.214159,0.030790,-107.599419,0.003894,0.000000
12.350000,0.934280,-107.554939,0.006015,0.000129,0.003287,4.155887,0.211711,0.032868,-107.554939,0.004302,0.000000
12.590000,1.055672,-107.554939,0.006053,0.000152,0.003851,4.695862,0.239219,0.038508,-107.554939,0.004700,0.000000
12.830001,1.128662,-107.554939,0.006066,0.000168,0.004275,5.020540,0.255758,0.042754,-107.554939,0.005099,0.000000
13.070001,1.160309,-107.599419,0.006084,0.000181,0.004588,5.161312,0.262930,0.045877,-107.599419,0.005498,0.000000
13.310000,1.241486,-107.554939,0.006101,0.000199,0.005048,5.522404,0.281325,0.050475,-107.554939,0.005897,0.000000
13.550000,1.281708,-107.688385,0.006109,0.000210,0.005334,5.701321,0.290439,0.053337,-107.688385,0.006296,0.000000
13.790001,1.392670,-107.643898,0.006122,0.000227,0.005767,6.194904,0.315583,0.057670,-107.643898,0.006695,0.000000
14.030001,1.479431,-107.732864,0.006153,0.000241,0.006123,6.580838,0.335244,0.061228,-107.732864,0.007094,0.000000
14.270000,1.500290,-107.554939,0.006148,0.000252,0.006392,6.673623,0.339971,0.063916,-107.554939,0.007502,0.000000
14.510000,1.676788,-107.643898,0.006157,0.000275,0.006973,7.458727,0.379966,0.069725,-107.643898,0.007901,0.000000
14.750001,1.814941,-107.688385,0.006222,0.000295,0.007484,8.073262,0.411272,0.074843,-107.688385,0.008300,0.000000
14.990001,1.904686,-107.643898,0.006200,0.000310,0.007874,8.472466,0.431608,0.078745,-107.643898,0.008698,0.000000
15.230000,1.995918,-107.732864,0.006213,0.000323,0.008213,8.878288,0.452282,0.082128,-107.732864,0.009097,0.000000
15.470000,2.096085,-107.732864,0.006247,0.000337,0.008568,9.323850,0.474980,0.085682,-107.732864,0.009496,0.000000
15.710001,2.182098,-107.643898,0.006239,0.000349,0.008863,9.706458,0.494471,0.088631,-107.643898,0.009895,0.000000
15.950001,2.362701,-107.688385,0.006252,0.000367,0.009314,10.509821,0.535396,0.093142,-107.688385,0.010294,0.000000
16.190001,2.408134,-107.643898,0.006265,0.000378,0.009600,10.711917,0.545691,0.096004,-107.643898,0.010702,0.000000
16.430000,2.707893,-107.732864,0.006295,0.000402,0.010199,12.045311,0.613617,0.101988,-107.732864,0.011101,0.000000
16.670000,2.865776,-107.732864,0.006325,0.000419,0.010650,12.747608,0.649394,0.106496,-107.732864,0.011500,0.000000
16.910002,2.953285,-107.732864,0.006334,0.000435,0.011040,13.136868,0.669224,0.110398,-107.732864,0.011899,0.000000
17.150002,3.066483,-107.732864,0.006342,0.000449,0.011396,13.640395,0.694875,0.113956,-107.732864,0.012298,0.000000
17.390001,3.191978,-107.732864,0.006359,0.000465,0.011803,14.198629,0.723313,0.118032,-107.732864,0.012696,0.000000
17.630001,3.355820,-107.732864,0.006385,0.000480,0.012193,14.927431,0.760440,0.121934,-107.732864,0.013095,0.000000
17.870001,3.525246,-107.732864,0.006398,0.000494,0.012558,15.681076,0.798832,0.125575,-107.732864,0.013494,0.000000
18.110001,3.563232,-107.821823,0.006407,0.000507,0.012878,15.850049,0.807440,0.128785,-107.821823,0.013902,0.000000
18.350000,3.941559,-107.732864,0.006411,0.000529,0.013425,17.532928,0.893170,0.134246,-107.732864,0.014301,0.000000
18.590000,4.080460,-107.732864,0.006437,0.000544,0.013824,18.150791,0.924645,0.138236,-107.732864,0.014700,0.000000
18.830002,4.094604,-107.732864,0.006433,0.000557,0.014145,18.213711,0.927851,0.141445,-107.732864,0.015099,0.000000
19.070002,4.151955,-107.777344,0.006463,0.000568,0.014431,18.468817,0.940846,0.144307,-107.777344,0.015498,0.000000
19.310001,4.359734,-107.866310,0.006480,0.000588,0.014942,19.393063,0.987930,0.149424,-107.866310,0.015897,0.000000
19.550001,4.532516,-107.866310,0.006497,0.000603,0.015324,20.161640,1.027083,0.153239,-107.866310,0.016295,0.000000
19.790001,4.826691,-107.777344,0.006510,0.000624,0.015844,21.470192,1.093744,0.158443,-107.777344,0.016694,0.000000
20.030001,4.697853,-107.821823,0.006536,0.000632,0.016044,20.897095,1.064549,0.160438,-107.821823,0.017102,0.000000
20.270000,4.849777,-107.866310,0.006554,0.000644,0.016365,21.572887,1.098975,0.163648,-107.866310,0.017501,0.000000
20.510000,5.085114,-107.777344,0.006566,0.000666,0.016920,22.619715,1.152303,0.169196,-107.777344,0.017900,0.000000
20.750002,5.365883,-107.866310,0.006579,0.000685,0.017388,23.868639,1.215926,0.173882,-107.866310,0.018298,0.000000
20.990002,5.439247,-107.866310,0.006605,0.000699,0.017752,24.194979,1.232551,0.177523,-107.866310,0.018697,0.000000
21.230001,5.575905,-107.866310,0.006605,0.000718,0.018238,24.802864,1.263518,0.182379,-107.866310,0.019096,0.000000
21.470001,5.638832,-107.910789,0.006631,0.000729,0.018524,25.082777,1.277778,0.185240,-107.910789,0.019495,0.000000
21.710001,5.981415,-107.866310,0.006622,0.000748,0.019001,26.606663,1.355408,0.190009,-107.866310,0.019903,0.000000
21.950001,5.869331,-107.910789,0.006631,0.000755,0.019166,26.108089,1.330009,0.191660,-107.910789,0.020302,0.000000
22.190001,6.230537,-107.866310,0.006670,0.000773,0.019634,27.714815,1.411860,0.196341,-107.866310,0.020701,0.000000
22.430000,6.327721,-107.866310,0.006691,0.000787,0.019981,28.147108,1.433882,0.199812,-107.866310,0.021100,0.000000
22.670002,6.898941,-107.866310,0.006704,0.000811,0.020597,30.688023,1.563322,0.205966,-107.866310,0.021499,0.000000
22.910002,6.922775,-107.866310,0.006704,0.000827,0.021004,30.794043,1.568723,0.210043,-107.866310,0.021898,0.000000
23.150002,7.114174,-107.999748,0.006713,0.000845,0.021455,31.645426,1.612095,0.214554,-107.999748,0.022296,0.000000
23.390001,7.191628,-107.910789,0.006756,0.000856,0.021742,31.989956,1.629646,0.217416,-107.910789,0.022695,0.000000
23.630001,7.444466,-107.910789,0.006760,0.000873,0.022175,33.114635,1.686940,0.221753,-107.910789,0.023103,0.000000
23.870001,7.574059,-107.910789,0.006760,0.000885,0.022478,33.691093,1.716306,0.224785,-107.910789,0.023502,0.000000
24.110001,7.771042,-107.910789,0.006773,0.000900,0.022869,34.567322,1.760943,0.228691,-107.910789,0.023901,0.000000
24.350000,8.064095,-107.999748,0.006804,0.000918,0.023329,35.870884,1.827350,0.233286,-107.999748,0.024300,0.000000
24.590002,8.587280,-107.955269,0.006812,0.000940,0.023883,38.198132,1.945906,0.238834,-107.955269,0.024699,0.000000
24.830002,8.476311,-107.999748,0.006821,0.000949,0.024109,37.704514,1.920760,0.241090,-107.999748,0.025098,0.000000
25.070002,8.691170,-107.999748,0.006842,0.000966,0.024543,38.660255,1.969447,0.245428,-107.999748,0.025497,0.000000
25.310001,8.913109,-107.955269,0.006877,0.000981,0.024916,39.647488,2.019739,0.249156,-107.955269,0.025895,0.000000
25.550001,9.434425,-107.999748,0.006864,0.001004,0.025505,41.966419,2.137871,0.255053,-107.999748,0.026303,0.000000
25.790001,9.329788,-107.999748,0.006881,0.001014,0.025748,41.500969,2.114160,0.257483,-107.999748,0.026702,0.000000
26.030001,9.542786,-107.999748,0.006898,0.001028,0.026121,42.448429,2.162426,0.261211,-107.999748,0.027101,0.000000
26.270000,10.101349,-108.044228,0.006937,0.001050,0.026659,44.933044,2.288998,0.266585,-108.044228,0.027500,0.000000
26.510002,10.299080,-107.999748,0.006946,0.001067,0.027101,45.812595,2.333805,0.271010,-107.999748,0.027899,0.000000
26.750002,10.329239,-108.044228,0.006937,0.001081,0.027456,45.946751,2.340639,0.274564,-108.044228,0.028298,0.000000
26.990002,10.595856,-107.999748,0.006942,0.001098,0.027881,47.132721,2.401055,0.278814,-107.999748,0.028697,0.000000
27.230001,10.755608,-107.999748,0.006980,0.001113,0.028280,47.843330,2.437255,0.282804,-107.999748,0.029096,0.000000
27.470001,11.044937,-108.088715,0.006998,0.001129,0.028679,49.130333,2.502819,0.286793,-108.088715,0.029503,0.000000
27.710001,11.212509,-108.044228,0.006998,0.001143,0.029035,49.875732,2.540791,0.290351,-108.044228,0.029902,0.000000
27.950001,10.850929,-108.044228,0.007023,0.001145,0.029087,48.267345,2.458856,0.290869,-108.044228,0.030301,0.000000
28.190001,11.704041,-108.088715,0.007019,0.001171,0.029755,52.062172,2.652174,0.297546,-108.088715,0.030700,0.000000
28.430002,12.202271,-108.133194,0.007062,0.001195,0.030344,54.278412,2.765074,0.303443,-108.133194,0.031099,0.000000
28.670002,12.032097,-108.133194,0.007058,0.001207,0.030657,53.521439,2.726512,0.306565,-108.133194,0.031498,0.000000
28.910002,12.152374,-108.133194,0.007092,0.001222,0.031038,54.056461,2.753767,0.310380,-108.133194,0.031897,0.000000
29.150002,12.228714,-108.133194,0.007101,0.001235,0.031368,54.396038,2.771066,0.313677,-108.133194,0.032296,0.000000
29.390001,12.739975,-108.133194,0.007084,0.001256,0.031914,56.670238,2.886919,0.319142,-108.133194,0.032703,0.000000
29.630001,12.743332,-108.088715,0.007105,0.001269,0.032244,56.685173,2.887680,0.322435,-108.088715,0.033102,0.000000
29.870001,12.624916,-108.133194,0.007148,0.001280,0.032521,56.158432,2.860847,0.325210,-108.133194,0.033501,0.000000
30.110001,13.292953,-108.133194,0.007144,0.001303,0.033094,59.130009,3.012226,0.330936,-108.133194,0.033900,0.000000
30.350002,13.471321,-108.177673,0.007153,0.001319,0.033493,59.923428,3.052645,0.334925,-108.177673,0.034299,0.000000
30.590002,13.421043,-108.222153,0.007187,0.001333,0.033848,59.699783,3.041252,0.338479,-108.222153,0.034698,0.000000
30.830002,13.628456,-108.177673,0.007187,0.001348,0.034238,60.622402,3.088252,0.342382,-108.177673,0.035097,0.000000
31.070002,13.716339,-108.222153,0.007187,0.001361,0.034577,61.013325,3.108167,0.345765,-108.222153,0.035496,0.000000
31.310001,14.075302,-108.222153,0.007226,0.001379,0.035036,62.610069,3.189509,0.350360,-108.222153,0.035903,0.000000
31.550001,14.244736,-108.177673,0.007226,0.001394,0.035409,63.363750,3.227903,0.354088,-108.177673,0.036302,0.000000
31.790001,14.156853,-108.222153,0.007239,0.001408,0.035756,62.972824,3.207989,0.357559,-108.222153,0.036701,0.000000
32.030003,14.626793,-108.222153,0.007243,0.001427,0.036250,65.063225,3.314479,0.362502,-108.222153,0.037100,0.000000
32.270000,14.702377,-108.222153,0.007269,0.001440,0.036580,65.399437,3.331606,0.365799,-108.222153,0.037499,0.000000
32.510002,14.846863,-108.177673,0.007291,0.001459,0.037048,66.042145,3.364347,0.370481,-108.177673,0.037898,0.000000
32.750000,15.032303,-108.222153,0.007304,0.001475,0.037456,66.867020,3.406368,0.374557,-108.222153,0.038297,0.000000
32.990002,14.981659,-108.311119,0.007325,0.001486,0.037751,66.641747,3.394892,0.377505,-108.311119,0.038696,0.000000
33.230003,15.311958,-108.222153,0.007334,0.001506,0.038262,68.110992,3.469739,0.382623,-108.222153,0.039103,0.000000
33.470001,15.455688,-108.266632,0.007360,0.001522,0.038652,68.750336,3.502309,0.386525,-108.266632,0.039502,0.000000
33.710003,15.139915,-108.266632,0.007355,0.001530,0.038869,67.345711,3.430754,0.388694,-108.266632,0.039901,0.000000
33.950001,15.793060,-108.222153,0.007373,0.001550,0.039372,70.251038,3.578758,0.393724,-108.222153,0.040300,0.000000
34.190002,16.065636,-108.311119,0.007390,0.001571,0.039892,71.463516,3.640525,0.398924,-108.311119,0.040699,0.000000
34.430000,15.890625,-108.266632,0.007416,0.001582,0.040170,70.685028,3.600867,0.401702,-108.266632,0.041098,0.000000
34.670002,16.130798,-108.266632,0.007429,0.001599,0.040612,71.753372,3.655291,0.406123,-108.266632,0.041497,0.000000
34.910000,15.993027,-108.311119,0.007450,0.001611,0.040907,71.140533,3.624072,0.409071,-108.311119,0.041904,0.000000
35.150002,16.217194,-108.266632,0.007446,0.001628,0.041341,72.137680,3.674869,0.413409,-108.266632,0.042303,0.000000
35.390003,16.341194,-108.400078,0.007463,0.001641,0.041688,72.689262,3.702968,0.416876,-108.400078,0.042702,0.000000
35.630001,16.195969,-108.311119,0.007485,0.001649,0.041887,72.043266,3.670059,0.418871,-108.311119,0.043101,0.000000
35.870003,17.014442,-108.311119,0.007502,0.001677,0.042590,75.684021,3.855528,0.425895,-108.311119,0.043500,0.000000
36.110001,17.332817,-108.400078,0.007515,0.001696,0.043066,77.100220,3.927672,0.430664,-108.400078,0.043899,0.000000
36.350002,17.249779,-108.311119,0.007537,0.001709,0.043405,76.730850,3.908856,0.434048,-108.311119,0.044298,0.000000
36.590000,17.213287,-108.400078,0.007532,0.001724,0.043786,76.568527,3.900587,0.437863,-108.400078,0.044697,0.000000
36.830002,17.196533,-108.355598,0.007562,0.001737,0.044116,76.494003,3.896790,0.441160,-108.355598,0.045105,0.000000
37.070004,17.128387,-108.355598,0.007580,0.001749,0.044437,76.190872,3.881348,0.444369,-108.355598,0.045504,0.000000
37.310001,17.525337,-108.444557,0.007593,0.001770,0.044949,77.956596,3.971298,0.449487,-108.444557,0.045902,0.000000
37.550003,17.346222,-108.355598,0.007601,0.001778,0.045165,77.159851,3.930710,0.451652,-108.355598,0.046301,0.000000
37.790001,18.007561,-108.444557,0.007610,0.001801,0.045747,80.101631,4.080572,0.457465,-108.444557,0.046700,0.000000
38.030003,18.216087,-108.400078,0.007610,0.001819,0.046215,81.029205,4.127824,0.462147,-108.400078,0.047099,0.000000
38.270000,18.228004,-108.444557,0.007636,0.001834,0.046588,81.082214,4.130525,0.465875,-108.444557,0.047498,0.000000
38.510002,18.224655,-108.444557,0.007657,0.001850,0.046986,81.067314,4.129766,0.469864,-108.444557,0.047897,0.000000
38.750000,18.343437,-108.444557,0.007683,0.001865,0.047359,81.595680,4.156682,0.473593,-108.444557,0.048305,0.000000
38.990002,18.626816,-108.444557,0.007683,0.001883,0.047837,82.856216,4.220897,0.478365,-108.444557,0.048704,0.000000
39.230003,18.535957,-108.400078,0.007705,0.001895,0.048140,82.452057,4.200308,0.481397,-108.400078,0.049103,0.000000
39.470001,18.483078,-108.444557,0.007709,0.001909,0.048478,82.216835,4.188325,0.484781,-108.444557,0.049502,0.000000
39.710003,18.858429,-108.578003,0.007718,0.001928,0.048972,83.886482,4.273381,0.489724,-108.578003,0.049900,0.000000
39.950001,18.984291,-108.444557,0.007769,0.001943,0.049354,84.446342,4.301902,0.493539,-108.444557,0.050299,0.000000
40.190002,18.935135,-108.533524,0.007735,0.001957,0.049718,84.227684,4.290763,0.497184,-108.533524,0.050698,0.000000
40.430000,18.807411,-108.489037,0.007778,0.001970,0.050039,83.659546,4.261820,0.500390,-108.489037,0.051097,0.000000
40.670002,19.217766,-108.489037,0.007800,0.001988,0.050499,85.484894,4.354808,0.504988,-108.489037,0.051505,0.000000
40.910004,19.173088,-108.578003,0.007817,0.002001,0.050837,85.286156,4.344684,0.508368,-108.578003,0.051904,0.000000
41.150002,19.788986,-108.533524,0.007821,0.002023,0.051375,88.025810,4.484248,0.513747,-108.533524,0.052303,0.000000
41.390003,19.220375,-108.578003,0.007825,0.002032,0.051600,85.496498,4.355399,0.516002,-108.578003,0.052702,0.000000
41.630001,19.564079,-108.533524,0.007847,0.002048,0.052025,87.025368,4.433284,0.520249,-108.533524,0.053101,0.000000
41.870003,20.074600,-108.489037,0.007873,0.002070,0.052571,89.296280,4.548970,0.525714,-108.489037,0.053499,0.000000
42.110001,20.064171,-108.622482,0.007881,0.002083,0.052918,89.249886,4.546606,0.529181,-108.622482,0.053898,0.000000
42.350002,19.996399,-108.578003,0.007899,0.002099,0.053308,88.948425,4.531249,0.533084,-108.578003,0.054297,0.000000
42.590000,20.351646,-108.578003,0.007920,0.002118,0.053794,90.528648,4.611749,0.537943,-108.578003,0.054705,0.000000
42.830002,20.112953,-108.578003,0.007929,0.002129,0.054072,89.466881,4.557661,0.540718,-108.578003,0.055104,0.000000
43.070004,20.493515,-108.533524,0.007942,0.002148,0.054557,91.159706,4.643897,0.545574,-108.533524,0.055502,0.000000
43.310001,20.067154,-108.578003,0.007942,0.002157,0.054783,89.263161,4.547282,0.547830,-108.578003,0.055901,0.000000
43.550003,20.297653,-108.578003,0.007963,0.002173,0.055182,90.288467,4.599514,0.551819,-108.578003,0.056300,0.000000
43.790001,20.432823,-108.666962,0.007976,0.002185,0.055511,90.889740,4.630144,0.555112,-108.666962,0.056699,0.000000
44.030003,21.338432,-108.622482,0.008019,0.002213,0.056222,94.918091,4.835358,0.562223,-108.622482,0.057098,0.000000
44.270000,21.273636,-108.533524,0.008024,0.002228,0.056604,94.629860,4.820675,0.566039,-108.533524,0.057497,0.000000
44.510002,21.378647,-108.666962,0.008019,0.002244,0.057003,95.096970,4.844471,0.570028,-108.666962,0.057905,0.000000
44.750004,21.149261,-108.622482,0.008054,0.002256,0.057315,94.076614,4.792491,0.573150,-108.622482,0.058304,0.000000
44.990002,21.490356,-108.622482,0.008045,0.002275,0.057792,95.593880,4.869784,0.577919,-108.622482,0.058703,0.000000
45.230003,21.608398,-108.666962,0.008067,0.002290,0.058165,96.118958,4.896533,0.581651,-108.666962,0.059102,0.000000
45.470001,21.554405,-108.711441,0.008088,0.002301,0.058451,95.878784,4.884298,0.584513,-108.711441,0.059500,0.000000
45.710003,21.936836,-108.711441,0.008101,0.002322,0.058989,97.579918,4.970958,0.589887,-108.711441,0.059899,0.000000
45.950001,22.409370,-108.666962,0.008119,0.002341,0.059457,99.681862,5.078036,0.594573,-108.666962,0.060298,0.000000
46.190002,22.203827,-108.666962,0.008140,0.002352,0.059752,98.767555,5.031459,0.597521,-108.666962,0.060697,0.000000
46.430000,22.255959,-108.711441,0.008149,0.002367,0.060134,98.999451,5.043272,0.601337,-108.711441,0.061105,0.000000
46.670002,22.350166,-108.711441,0.008157,0.002381,0.060480,99.418503,5.064620,0.604804,-108.711441,0.061504,0.000000
46.910004,23.055809,-108.800407,0.008153,0.002404,0.061062,102.557358,5.224521,0.610617,-108.800407,0.061903,0.000000
47.150002,22.885269,-108.666962,0.008175,0.002417,0.061391,101.798759,5.185876,0.613910,-108.666962,0.062302,0.000000
47.390003,23.027512,-108.711441,0.008201,0.002432,0.061764,102.431488,5.218109,0.617638,-108.711441,0.062701,0.000000
47.630001,23.405846,-108.711441,0.008231,0.002450,0.062224,104.114403,5.303841,0.622237,-108.711441,0.063099,0.000000
47.870003,23.708206,-108.711441,0.008239,0.002468,0.062692,105.459366,5.372356,0.626919,-108.711441,0.063498,0.000000
48.110001,23.620705,-108.755928,0.008239,0.002483,0.063056,105.070145,5.352528,0.630560,-108.755928,0.063897,0.000000
48.350002,23.859390,-108.711441,0.008261,0.002498,0.063447,106.131866,5.406615,0.634466,-108.711441,0.064305,0.000000
48.590004,24.103668,-108.711441,0.008269,0.002514,0.063846,107.218468,5.461969,0.638455,-108.711441,0.064704,0.000000
48.830002,24.301399,-108.800407,0.008300,0.002529,0.064236,108.098022,5.506776,0.642357,-108.800407,0.065103,0.000000
49.070004,24.401939,-108.800407,0.008313,0.002543,0.064591,108.545250,5.529559,0.645911,-108.800407,0.065502,0.000000
49.310001,23.603569,-108.889366,0.008295,0.002544,0.064609,104.993919,5.348645,0.646085,-108.889366,0.065901,0.000000
49.550003,24.936668,-108.800407,0.008343,0.002575,0.065398,110.923843,5.650730,0.653977,-108.800407,0.066300,0.000000
49.790001,25.473999,-108.844887,0.008356,0.002595,0.065909,113.314011,5.772491,0.659094,-108.844887,0.066699,0.000000
50.030003,25.358192,-108.800407,0.008364,0.002609,0.066256,112.798874,5.746248,0.662561,-108.800407,0.067106,0.000000
50.270004,25.404366,-108.800407,0.008377,0.002623,0.066621,113.004265,5.756711,0.666206,-108.800407,0.067505,0.000000
50.510002,25.409576,-108.844887,0.008399,0.002637,0.066985,113.027443,5.757893,0.669847,-108.844887,0.067904,0.000000
50.750004,26.059738,-108.800407,0.008416,0.002655,0.067435,115.919502,5.905221,0.674355,-108.800407,0.068303,0.000000
50.990002,26.130493,-108.800407,0.008438,0.002671,0.067843,116.234238,5.921254,0.678431,-108.800407,0.068702,0.000000
51.230003,25.927551,-108.889366,0.008442,0.002684,0.068164,115.331505,5.875267,0.681641,-108.889366,0.069101,0.000000
51.470001,26.750488,-108.844887,0.008464,0.002702,0.068624,118.992111,6.061748,0.686239,-108.844887,0.069500,0.000000
51.710003,27.002960,-108.889366,0.008464,0.002717,0.069022,120.115166,6.118958,0.690225,-108.889366,0.069899,0.000000
51.950001,27.005936,-108.844887,0.008494,0.002733,0.069421,120.128403,6.119633,0.694214,-108.844887,0.070306,0.000000
52.190002,27.290802,-108.889366,0.008485,0.002749,0.069820,121.395554,6.184184,0.698203,-108.889366,0.070705,0.000000
52.430004,27.318359,-108.889366,0.008498,0.002762,0.070150,121.518135,6.190429,0.701500,-108.889366,0.071104,0.000000
52.670002,27.776749,-108.844887,0.008515,0.002778,0.070558,123.557152,6.294302,0.705576,-108.844887,0.071503,0.000000
52.910004,28.127151,-108.978333,0.008532,0.002796,0.071017,125.115822,6.373704,0.710171,-108.978333,0.071902,0.000000
53.150002,28.185616,-108.889366,0.008558,0.002807,0.071304,125.375877,6.386952,0.713036,-108.889366,0.072301,0.000000
53.390003,28.861099,-108.978333,0.008558,0.002829,0.071859,128.380585,6.540019,0.718585,-108.978333,0.072700,0.000000
53.630001,29.103142,-109.022812,0.008580,0.002844,0.072240,129.457245,6.594866,0.722400,-109.022812,0.073099,0.000000
53.870003,29.369759,-108.978333,0.008589,0.002858,0.072596,130.643204,6.655282,0.725958,-108.978333,0.073506,0.000000
54.110004,29.688141,-108.933846,0.008610,0.002874,0.073003,132.059448,6.727429,0.730031,-108.933846,0.073905,0.000000
54.350002,29.636009,-108.933846,0.008632,0.002885,0.073281,131.827560,6.715616,0.732809,-108.933846,0.074304,0.000000
54.590004,30.299576,-109.022812,0.008640,0.002905,0.073793,134.779251,6.865982,0.737926,-109.022812,0.074703,0.000000
54.830002,30.603432,-108.978333,0.008649,0.002921,0.074192,136.130859,6.934837,0.741915,-108.978333,0.075102,0.000000
55.070004,30.595985,-108.933846,0.008662,0.002934,0.074512,136.097748,6.933149,0.745121,-108.933846,0.075501,0.000000
55.310001,31.148956,-109.022812,0.008670,0.002952,0.074972,138.557480,7.058455,0.749720,-109.022812,0.075900,0.000000
55.550003,31.856461,-108.978333,0.008683,0.002972,0.075484,141.704620,7.218777,0.754837,-108.978333,0.076299,0.000000
55.790001,31.729858,-109.022812,0.008683,0.002983,0.075779,141.141464,7.190089,0.757785,-109.022812,0.076706,0.000000
56.030003,32.162926,-109.111771,0.008735,0.002999,0.076169,143.067841,7.288223,0.761687,-109.111771,0.077105,0.000000
56.270004,32.148399,-109.022812,0.008735,0.003010,0.076446,143.003220,7.284931,0.764462,-109.022812,0.077504,0.000000
56.510002,32.637329,-109.067291,0.008739,0.003026,0.076863,145.178085,7.395725,0.768625,-109.067291,0.077903,0.000000
56.750004,33.091621,-109.022812,0.008757,0.003043,0.077287,147.198883,7.498668,0.772872,-109.022812,0.078302,0.000000
56.990002,32.873413,-109.067291,0.008770,0.003053,0.077556,146.228241,7.449222,0.775563,-109.067291,0.078701,0.000000
57.230003,34.242622,-109.111771,0.008778,0.003078,0.078180,152.318787,7.759489,0.781804,-109.111771,0.079100,0.000000
57.470001,34.862999,-109.067291,0.008808,0.003096,0.078632,155.078369,7.900069,0.786316,-109.067291,0.079499,0.000000
57.710003,34.953484,-109.067291,0.008804,0.003108,0.078935,155.480865,7.920573,0.789351,-109.067291,0.079906,0.000000
57.950005,35.230904,-109.067291,0.008826,0.003124,0.079351,156.714890,7.983437,0.793515,-109.067291,0.080305,0.000000
58.190002,35.392883,-109.111771,0.008834,0.003135,0.079638,157.435410,8.020143,0.796376,-109.111771,0.080704,0.000000
58.430004,35.872131,-109.067291,0.008847,0.003153,0.080097,159.567215,8.128741,0.800971,-109.067291,0.081103,0.000000
58.670002,36.375946,-109.111771,0.008877,0.003170,0.080513,161.808289,8.242908,0.805134,-109.111771,0.081502,0.000000
58.910004,36.335732,-109.156258,0.008869,0.003177,0.080695,161.629410,8.233794,0.806955,-109.156258,0.081901,0.000000
59.150002,37.593605,-109.156258,0.008899,0.003203,0.081363,167.224701,8.518833,0.813631,-109.156258,0.082300,0.000000
59.390003,38.107849,-109.111771,0.008916,0.003219,0.081753,169.512177,8.635363,0.817534,-109.111771,0.082699,0.000000
59.630001,38.451553,-109.156258,0.008921,0.003233,0.082109,171.041046,8.713247,0.821091,-109.156258,0.083106,0.000000
59.870003,38.978462,-109.156258,0.008929,0.003250,0.082560,173.384857,8.832646,0.825599,-109.156258,0.083505,0.000000
60.110004,39.242844,-109.111771,0.008942,0.003263,0.082881,174.560883,8.892555,0.828809,-109.111771,0.083904,0.000000
60.350002,40.011047,-109.111771,0.008959,0.003283,0.083393,177.978027,9.066633,0.833926,-109.111771,0.084303,0.000000
60.590004,40.199097,-109.156258,0.008968,0.003294,0.083679,178.814514,9.109245,0.836787,-109.156258,0.084702,0.000000
60.830002,40.594559,-109.200737,0.008981,0.003308,0.084035,180.573608,9.198858,0.840345,-109.200737,0.085101,0.000000
61.070004,41.446175,-109.200737,0.009011,0.003327,0.084494,184.361786,9.391837,0.844940,-109.200737,0.085500,0.000000
61.310001,41.990204,-109.156258,0.009015,0.003343,0.084910,186.781754,9.515116,0.849103,-109.156258,0.085899,0.000000
61.550003,42.406517,-109.200737,0.009020,0.003356,0.085248,188.633606,9.609454,0.852483,-109.200737,0.086307,0.000000
61.790005,42.588234,-109.200737,0.009050,0.003371,0.085613,189.441925,9.650632,0.856128,-109.200737,0.086706,0.000000
62.030003,43.704239,-109.245216,0.009037,0.003390,0.086107,194.406158,9.903522,0.861071,-109.245216,0.087104,0.000000
62.270004,43.945160,-109.245216,0.009050,0.003403,0.086428,195.477829,9.958116,0.864281,-109.245216,0.087503,0.000000
62.510002,45.181442,-109.289696,0.009067,0.003422,0.086922,200.977097,10.238261,0.869224,-109.289696,0.087902,0.000000
62.750004,45.142342,-109.245216,0.009084,0.003432,0.087165,200.803162,10.229401,0.871650,-109.245216,0.088301,0.000000
62.990002,45.823410,-109.289696,0.009097,0.003449,0.087607,203.832703,10.383733,0.876074,-109.289696,0.088700,0.000000
63.230003,46.964355,-109.245216,0.009097,0.003469,0.088119,208.907883,10.642275,0.881188,-109.245216,0.089108,0.000000
63.470001,47.545258,-109.289696,0.009127,0.003484,0.088492,211.491867,10.773910,0.884920,-109.289696,0.089507,0.000000
63.710003,48.079987,-109.245216,0.009132,0.003499,0.088865,213.870468,10.895081,0.888648,-109.245216,0.089906,0.000000
63.950005,49.142365,-109.334175,0.009158,0.003517,0.089333,218.596161,11.135818,0.893330,-109.334175,0.090305,0.000000
64.190002,49.395203,-109.245216,0.009153,0.003527,0.089585,219.720840,11.193112,0.895847,-109.245216,0.090703,0.000000
64.430000,50.461678,-109.334175,0.009175,0.003546,0.090070,224.464752,11.434780,0.900703,-109.334175,0.091102,0.000000
64.670006,50.655685,-109.289696,0.009184,0.003555,0.090305,225.327744,11.478742,0.903046,-109.289696,0.091501,0.000000
64.910004,51.327446,-109.378662,0.009188,0.003573,0.090755,228.315887,11.630965,0.907553,-109.378662,0.091900,0.000000
65.150002,52.204010,-109.334175,0.009201,0.003588,0.091137,232.215027,11.829598,0.911369,-109.334175,0.092308,0.000000
65.389999,54.002945,-109.423141,0.009218,0.003612,0.091744,240.217102,12.237243,0.917440,-109.423141,0.092706,0.000000
65.630005,54.568573,-109.378662,0.009248,0.003628,0.092152,242.733139,12.365416,0.921516,-109.378662,0.093105,0.000000
65.870003,55.577332,-109.334175,0.009248,0.003645,0.092594,247.220322,12.594004,0.925941,-109.334175,0.093504,0.000000
66.110001,55.940025,-109.334175,0.009253,0.003655,0.092837,248.833664,12.676191,0.928367,-109.334175,0.093903,0.000000
66.350006,57.003891,-109.334175,0.009265,0.003674,0.093314,253.565964,12.917267,0.933136,-109.334175,0.094302,0.000000
66.590004,57.929611,-109.378662,0.009283,0.003688,0.093678,257.683777,13.127038,0.936780,-109.378662,0.094701,0.000000
66.830002,58.508278,-109.423141,0.009309,0.003700,0.093982,260.257812,13.258165,0.939816,-109.423141,0.095100,0.000000
67.070000,59.532303,-109.378662,0.009309,0.003719,0.094467,264.812897,13.490212,0.944672,-109.378662,0.095508,0.000000
67.310005,61.218033,-109.423141,0.009322,0.003740,0.094987,272.311401,13.872205,0.949872,-109.423141,0.095907,0.000000
67.550003,61.616470,-109.423141,0.009339,0.003751,0.095282,274.083740,13.962492,0.952821,-109.423141,0.096306,0.000000
67.790001,62.466225,-109.423141,0.009360,0.003769,0.095742,277.863647,14.155049,0.957419,-109.423141,0.096704,0.000000
68.030006,63.181931,-109.467621,0.009343,0.003782,0.096072,281.047272,14.317230,0.960716,-109.467621,0.097103,0.000000
68.270004,65.009903,-109.334175,0.009373,0.003803,0.096600,289.178497,14.731455,0.966004,-109.334175,0.097502,0.000000
68.510002,65.689850,-109.378662,0.009369,0.003817,0.096947,292.203033,14.885532,0.969474,-109.378662,0.097901,0.000000
68.750000,66.576096,-109.423141,0.009403,0.003831,0.097303,296.145264,15.086359,0.973028,-109.423141,0.098300,0.000000
68.990005,67.337601,-109.423141,0.009399,0.003837,0.097459,299.532593,15.258919,0.974592,-109.423141,0.097667,0.000000
69.230003,66.642380,-109.467621,0.009408,0.003837,0.097450,296.440125,15.101379,0.974504,-109.467621,0.097667,0.000000
69.470001,66.030945,-109.423141,0.009429,0.003836,0.097433,293.720306,14.962826,0.974330,-109.423141,0.097450,0.000000
69.710007,65.456375,-109.467621,0.009412,0.003836,0.097424,291.164490,14.832626,0.974243,-109.467621,0.097450,0.000000
69.950005,64.972290,-109.423141,0.009434,0.003836,0.097424,289.011169,14.722932,0.974243,-109.423141,0.097450,0.000000
70.190002,64.530655,-109.512100,0.009421,0.003835,0.097416,287.046692,14.622855,0.974156,-109.512100,0.097450,0.000000
70.430000,64.095352,-109.556580,0.009438,0.003835,0.097416,285.110352,14.524215,0.974156,-109.556580,0.097450,0.000000
70.670006,63.740479,-109.556580,0.009434,0.003835,0.097416,283.531799,14.443799,0.974156,-109.556580,0.097450,0.000000
70.910004,63.387466,-109.512100,0.009438,0.003835,0.097416,281.961548,14.363806,0.974156,-109.512100,0.097450,0.000000
71.150002,63.062759,-109.556580,0.009442,0.003835,0.097407,280.517151,14.290226,0.974069,-109.556580,0.097450,0.000000
71.390007,62.780876,-109.512100,0.009438,0.003835,0.097407,279.263275,14.226350,0.974069,-109.512100,0.097450,0.000000
71.630005,62.483727,-109.556580,0.009425,0.003835,0.097407,277.941498,14.159015,0.974069,-109.556580,0.097450,0.000000
71.870003,62.243172,-109.512100,0.009464,0.003835,0.097407,276.871460,14.104504,0.974069,-109.512100,0.097450,0.000000
72.110001,62.001877,-109.556580,0.009451,0.003835,0.097407,275.798126,14.049827,0.974069,-109.556580,0.097450,0.000000
72.350006,61.762070,-109.601067,0.009442,0.003835,0.097407,274.731415,13.995485,0.974069,-109.601067,0.097450,0.000000
72.590004,61.570297,-109.512100,0.009451,0.003835,0.097407,273.878357,13.952028,0.974069,-109.512100,0.097450,0.000000
72.830002,61.355064,-109.601067,0.009447,0.003835,0.097407,272.920959,13.903256,0.974069,-109.601067,0.097450,0.000000
73.070000,61.164413,-109.556580,0.009468,0.003835,0.097407,272.072906,13.860054,0.974069,-109.556580,0.097450,0.000000
73.310005,61.007271,-109.645546,0.009442,0.003835,0.097407,271.373901,13.824445,0.974069,-109.645546,0.097450,0.000000
73.550003,60.805069,-109.601067,0.009459,0.003835,0.097398,270.474457,13.778625,0.973982,-109.601067,0.097450,0.000000
73.790001,60.642715,-109.601067,0.009459,0.003835,0.097398,269.752258,13.741836,0.973982,-109.601067,0.097450,0.000000
74.030006,60.495255,-109.690025,0.009464,0.003835,0.097398,269.096344,13.708421,0.973982,-109.690025,0.097450,0.000000
74.270004,60.334389,-109.645546,0.009459,0.003835,0.097398,268.380768,13.671968,0.973982,-109.645546,0.097450,0.000000
74.510002,60.215981,-109.645546,0.009459,0.003835,0.097398,267.854065,13.645136,0.973982,-109.645546,0.097450,0.000000
74.750000,60.055489,-109.645546,0.009468,0.003835,0.097398,267.140167,13.608768,0.973982,-109.645546,0.097450,0.000000
74.990005,59.925896,-109.601067,0.009459,0.003835,0.097398,266.563690,13.579402,0.973982,-109.601067,0.097450,0.000000
75.230003,59.805626,-109.690025,0.009468,0.003835,0.097398,266.028717,13.552149,0.973982,-109.690025,0.097450,0.000000
75.470001,59.685349,-109.734505,0.009477,0.003835,0.097398,265.493683,13.524894,0.973982,-109.734505,0.097450,0.000000
75.710007,59.574379,-109.690025,0.009468,0.003835,0.097398,265.000061,13.499747,0.973982,-109.690025,0.097450,0.000000
75.950005,59.462669,-109.645546,0.009468,0.003835,0.097398,264.503174,13.474433,0.973982,-109.645546,0.097450,0.000000
76.190002,59.337181,-109.645546,0.009451,0.003835,0.097398,263.944977,13.445997,0.973982,-109.645546,0.097450,0.000000
76.430000,59.246323,-109.778984,0.009459,0.003835,0.097398,263.540802,13.425408,0.973982,-109.778984,0.097450,0.000000
76.670006,59.126419,-109.690025,0.009485,0.003835,0.097398,263.007446,13.398238,0.973982,-109.690025,0.097450,0.000000
76.910004,59.018059,-109.734505,0.009472,0.003835,0.097398,262.525452,13.373684,0.973982,-109.734505,0.097450,0.000000
77.150002,58.955498,-109.734505,0.009472,0.003835,0.097398,262.247162,13.359507,0.973982,-109.734505,0.097450,0.000000
77.390007,58.844902,-109.778984,0.009481,0.003835,0.097398,261.755188,13.334446,0.973982,-109.778984,0.097450,0.000000
77.630005,58.774155,-109.778984,0.009451,0.003835,0.097398,261.440491,13.318414,0.973982,-109.778984,0.097450,0.000000
77.870003,58.688133,-109.734505,0.009472,0.003835,0.097398,261.057861,13.298921,0.973982,-109.734505,0.097450,0.000000
78.110001,58.581261,-109.734505,0.009472,0.003835,0.097398,260.582458,13.274704,0.973982,-109.734505,0.097450,0.000000
78.350006,58.526894,-109.778984,0.009477,0.003835,0.097398,260.340637,13.262383,0.973982,-109.778984,0.097450,0.000000
78.590004,58.435661,-109.778984,0.009459,0.003835,0.097398,259.934814,13.241710,0.973982,-109.778984,0.097450,0.000000
78.830002,58.339966,-109.823471,0.009459,0.003835,0.097398,259.509125,13.220025,0.973982,-109.823471,0.097450,0.000000
79.070007,58.286346,-109.823471,0.009472,0.003835,0.097398,259.270630,13.207874,0.973982,-109.823471,0.097450,0.000000
79.310005,58.208893,-109.778984,0.009477,0.003835,0.097398,258.926086,13.190323,0.973982,-109.778984,0.097450,0.000000
79.550003,58.130692,-109.867950,0.009468,0.003835,0.097398,258.578217,13.172604,0.973982,-109.867950,0.097450,0.000000
79.790001,58.081909,-109.778984,0.009477,0.003835,0.097398,258.361237,13.161549,0.973982,-109.778984,0.097450,0.000000
80.030006,57.995522,-109.823471,0.009477,0.003835,0.097398,257.976959,13.141973,0.973982,-109.823471,0.097450,0.000000
80.270004,57.927002,-109.867950,0.009477,0.003835,0.097398,257.672180,13.126447,0.973982,-109.867950,0.097450,0.000000
80.510002,57.882317,-109.778984,0.009468,0.003835,0.097398,257.473389,13.116321,0.973982,-109.778984,0.097450,0.000000
80.750008,57.809334,-109.867950,0.009477,0.003835,0.097398,257.148773,13.099783,0.973982,-109.867950,0.097450,0.000000
80.990005,57.750130,-109.867950,0.009477,0.003835,0.097398,256.885406,13.086367,0.973982,-109.867950,0.097450,0.000000
81.230003,57.667831,-109.867950,0.009468,0.003835,0.097398,256.519318,13.067718,0.973982,-109.867950,0.097450,0.000000
81.470001,57.633949,-109.823471,0.009494,0.003835,0.097398,256.368622,13.060040,0.973982,-109.823471,0.097450,0.000000
81.710007,57.579956,-109.912430,0.009472,0.003835,0.097398,256.128448,13.047805,0.973982,-109.912430,0.097450,0.000000
81.950005,57.502502,-109.912430,0.009481,0.003835,0.097398,255.783905,13.030253,0.973982,-109.912430,0.097450,0.000000
82.190002,57.460052,-109.867950,0.009477,0.003835,0.097398,255.595078,13.020634,0.973982,-109.867950,0.097450,0.000000
82.430000,57.404938,-109.956909,0.009472,0.003835,0.097398,255.349915,13.008145,0.973982,-109.956909,0.097450,0.000000
82.670006,57.344612,-109.912430,0.009485,0.003835,0.097398,255.081573,12.994474,0.973982,-109.912430,0.097450,0.000000
82.910004,57.311844,-109.912430,0.009490,0.003835,0.097398,254.935822,12.987049,0.973982,-109.912430,0.097450,0.000000
83.150002,57.235512,-110.001389,0.009490,0.003835,0.097398,254.596268,12.969752,0.973982,-110.001389,0.097450,0.000000
83.390007,57.200508,-109.956909,0.009481,0.003835,0.097398,254.440567,12.961821,0.973982,-109.956909,0.097450,0.000000
83.630005,57.138321,-109.956909,0.009494,0.003835,0.097398,254.163940,12.947729,0.973982,-109.956909,0.097450,0.000000
83.870003,57.088051,-109.956909,0.009481,0.003835,0.097398,253.940338,12.936337,0.973982,-109.956909,0.097450,0.000000
84.110001,57.055649,-109.867950,0.009477,0.003835,0.097398,253.796204,12.928995,0.973982,-109.867950,0.097450,0.000000
84.350006,56.990112,-109.956909,0.009472,0.003835,0.097398,253.504684,12.914145,0.973982,-109.956909,0.097450,0.000000
84.590004,56.951759,-109.956909,0.009477,0.003835,0.097398,253.334076,12.905453,0.973982,-109.956909,0.097450,0.000000
84.830002,56.895905,-110.001389,0.009481,0.003835,0.097398,253.085617,12.892797,0.973982,-110.001389,0.097450,0.000000
85.070007,56.859787,-110.001389,0.009494,0.003835,0.097398,252.924957,12.884612,0.973982,-110.001389,0.097450,0.000000
85.310005,56.838928,-110.001389,0.009494,0.003835,0.097398,252.832184,12.879886,0.973982,-110.001389,0.097450,0.000000
85.550003,56.770790,-110.045876,0.009494,0.003835,0.097398,252.529083,12.864445,0.973982,-110.045876,0.097450,0.000000
85.790001,56.734665,-110.001389,0.009490,0.003835,0.097398,252.368393,12.856258,0.973982,-110.001389,0.097450,0.000000
86.030006,56.690727,-110.045876,0.009498,0.003835,0.097398,252.172943,12.846302,0.973982,-110.045876,0.097450,0.000000
86.270004,56.654610,-110.001389,0.009490,0.003835,0.097398,252.012283,12.838118,0.973982,-110.001389,0.097450,0.000000
86.510002,56.621841,-110.045876,0.009485,0.003835,0.097398,251.866531,12.830693,0.973982,-110.045876,0.097450,0.000000
86.750008,56.559280,-110.045876,0.009494,0.003835,0.097398,251.588242,12.816516,0.973982,-110.045876,0.097450,0.000000
86.990005,56.542892,-110.045876,0.009490,0.003835,0.097398,251.515350,12.812803,0.973982,-110.045876,0.097450,0.000000
87.230003,56.492622,-110.134834,0.009485,0.003835,0.097398,251.291733,12.801412,0.973982,-110.134834,0.097450,0.000000
87.470001,56.443474,-110.001389,0.009490,0.003835,0.097398,251.073105,12.790274,0.973982,-110.001389,0.097450,0.000000
87.710007,56.432671,-110.090355,0.009468,0.003835,0.097398,251.025055,12.787826,0.973982,-110.090355,0.097450,0.000000
87.950005,56.373466,-110.090355,0.009485,0.003835,0.097398,250.761703,12.774410,0.973982,-110.090355,0.097450,0.000000
88.190002,56.339211,-110.045876,0.009498,0.003835,0.097398,250.609329,12.766647,0.973982,-110.045876,0.097450,0.000000
88.430008,56.314262,-110.090355,0.009498,0.003835,0.097398,250.498352,12.760994,0.973982,-110.090355,0.097450,0.000000
88.670006,56.258400,-110.134834,0.009481,0.003835,0.097398,250.249863,12.748335,0.973982,-110.134834,0.097450,0.000000
88.910004,56.235687,-110.090355,0.009503,0.003835,0.097398,250.148834,12.743189,0.973982,-110.090355,0.097450,0.000000
89.150002,56.185043,-110.179314,0.009485,0.003835,0.097398,249.923553,12.731712,0.973982,-110.179314,0.097450,0.000000
89.390007,56.171638,-110.090355,0.009498,0.003835,0.097398,249.863922,12.728675,0.973982,-110.090355,0.097450,0.000000
89.630005,56.134773,-110.179314,0.009481,0.003835,0.097398,249.699936,12.720321,0.973982,-110.179314,0.097450,0.000000
89.870003,56.098656,-110.179314,0.009494,0.003835,0.097398,249.539276,12.712137,0.973982,-110.179314,0.097450,0.000000
90.110001,56.080040,-110.179314,0.009477,0.003835,0.097398,249.456482,12.707919,0.973982,-110.179314,0.097450,0.000000
90.350006,56.024178,-110.134834,0.009507,0.003835,0.097398,249.207993,12.695260,0.973982,-110.134834,0.097450,0.000000
90.590004,56.026039,-110.134834,0.009481,0.003835,0.097398,249.216263,12.695682,0.973982,-110.134834,0.097450,0.000000
90.830002,55.972420,-110.223793,0.009494,0.003835,0.097398,248.977753,12.683532,0.973982,-110.223793,0.097450,0.000000
91.070007,55.950447,-110.134834,0.009485,0.003835,0.097398,248.880020,12.678553,0.973982,-110.134834,0.097450,0.000000
91.310005,55.924759,-110.134834,0.009494,0.003835,0.097398,248.765747,12.672731,0.973982,-110.134834,0.097450,0.000000
91.550003,55.896088,-110.223793,0.009490,0.003835,0.097398,248.638214,12.666235,0.973982,-110.223793,0.097450,0.000000
91.790001,55.867409,-110.268280,0.009498,0.003835,0.097398,248.510651,12.659736,0.973982,-110.268280,0.097450,0.000000
92.030006,55.833900,-110.268280,0.009472,0.003835,0.097398,248.361588,12.652143,0.973982,-110.268280,0.097450,0.000000
92.270004,55.815277,-110.179314,0.009498,0.003835,0.097398,248.278748,12.647923,0.973982,-110.179314,0.097450,0.000000
92.510002,55.767990,-110.179314,0.009485,0.003835,0.097398,248.068405,12.637207,0.973982,-110.179314,0.097450,0.000000
92.750008,55.757935,-110.223793,0.009481,0.003835,0.097398,248.023682,12.634929,0.973982,-110.223793,0.097450,0.000000
92.990005,55.730003,-110.223793,0.009498,0.003835,0.097398,247.899429,12.628599,0.973982,-110.223793,0.097450,0.000000
93.230003,55.703194,-110.312759,0.009485,0.003835,0.097398,247.780182,12.622524,0.973982,-110.312759,0.097450,0.000000
93.470001,55.685692,-110.312759,0.009498,0.003835,0.097398,247.702332,12.618559,0.973982,-110.312759,0.097450,0.000000
93.710007,55.634682,-110.223793,0.009498,0.003835,0.097398,247.475418,12.606998,0.973982,-110.223793,0.097450,0.000000
93.950005,55.626114,-110.312759,0.009507,0.003835,0.097398,247.437317,12.605058,0.973982,-110.312759,0.097450,0.000000
94.190002,55.591110,-110.312759,0.009485,0.003835,0.097398,247.281601,12.597125,0.973982,-110.312759,0.097450,0.000000
94.430008,55.574356,-110.312759,0.009494,0.003835,0.097398,247.207077,12.593328,0.973982,-110.312759,0.097450,0.000000
94.670006,55.545685,-110.312759,0.009494,0.003835,0.097398,247.079544,12.586832,0.973982,-110.312759,0.097450,0.000000
94.910004,55.518127,-110.312759,0.009481,0.003835,0.097398,246.956970,12.580587,0.973982,-110.312759,0.097450,0.000000
95.150002,55.496902,-110.401718,0.009494,0.003835,0.097398,246.862549,12.575778,0.973982,-110.401718,0.097450,0.000000
95.390007,55.464874,-110.312759,0.009485,0.003835,0.097398,246.720078,12.568521,0.973982,-110.312759,0.097450,0.000000
95.630005,55.462646,-110.357239,0.009485,0.003835,0.097398,246.710175,12.568015,0.973982,-110.357239,0.097450,0.000000
95.870003,55.417961,-110.357239,0.009503,0.003835,0.097398,246.511398,12.557889,0.973982,-110.357239,0.097450,0.000000
96.110008,55.401199,-110.312759,0.009507,0.003835,0.097398,246.436844,12.554090,0.973982,-110.312759,0.097450,0.000000
96.350006,55.376251,-110.357239,0.009494,0.003835,0.097398,246.325867,12.548438,0.973982,-110.357239,0.097450,0.000000
96.590004,55.343109,-110.357239,0.009498,0.003835,0.097398,246.178452,12.540928,0.973982,-110.357239,0.097450,0.000000
96.830002,55.333801,-110.357239,0.009490,0.003835,0.097398,246.137039,12.538818,0.973982,-110.357239,0.097450,0.000000
97.070007,55.300659,-110.401718,0.009490,0.003835,0.097398,245.989624,12.531308,0.973982,-110.401718,0.097450,0.000000
97.310005,55.286880,-110.357239,0.009490,0.003835,0.097398,245.928329,12.528187,0.973982,-110.357239,0.097450,0.000000
97.550003,55.250763,-110.401718,0.009520,0.003835,0.097398,245.767670,12.520001,0.973982,-110.401718,0.097450,0.000000
97.790001,55.234749,-110.357239,0.009494,0.003835,0.097398,245.696426,12.516373,0.973982,-110.357239,0.097450,0.000000
98.030006,55.223206,-110.446205,0.009477,0.003835,0.097398,245.645081,12.513758,0.973982,-110.446205,0.097450,0.000000
98.270004,55.181877,-110.446205,0.009490,0.003835,0.097398,245.461243,12.504392,0.973982,-110.446205,0.097450,0.000000
98.510002,55.176659,-110.446205,0.009498,0.003835,0.097398,245.438034,12.503209,0.973982,-110.446205,0.097450,0.000000
98.750008,55.144264,-110.446205,0.009490,0.003835,0.097398,245.293945,12.495870,0.973982,-110.446205,0.097450,0.000000
98.990005,55.142403,-110.446205,0.009481,0.003835,0.097398,245.285660,12.495447,0.973982,-110.446205,0.097450,0.000000
99.230003,55.107773,-110.490685,0.009490,0.003835,0.097398,245.131622,12.487599,0.973982,-110.490685,0.097450,0.000000
99.400002,55.091385,-110.490685,0.009485,0.003835,0.097398,245.058716,12.483887,0.973982,-110.490685,0.097450,0.000000