File: Data/Automembrane/AutoHeating-15wt-1-2_12152023_165240.csv
Time (sec),S:Load (lbs),S:HL1 (DIM),S:LVDT (in),S:Position (in),Ch:Position (mm),Ch:Load (N),Ch:Stress (MPa),Ch:Strain (mm/mm),Ch:HL1 (DIM),Set Point (),Cycles ()
0.110000,0.006699,-130.551590,-0.000009,-0.000000,-0.000000,0.029797,0.001518,-0.000000,-130.551590,0.000147,0.000000
0.360000,-0.005219,-130.596069,-0.000009,0.000000,0.000008,-0.023213,-0.001183,0.000083,-130.596069,0.000338,0.000000
0.610000,0.004089,-130.551590,-0.000004,0.000140,0.003547,0.018190,0.000927,0.035468,-130.551590,0.004501,0.000000
0.860000,-0.017502,-130.551590,0.000129,0.000297,0.007536,-0.077852,-0.003966,0.075361,-130.551590,0.008663,0.000000
1.110000,0.008934,-130.551590,0.000289,0.000463,0.011759,0.039741,0.002024,0.117593,-130.551590,0.012826,0.000000
1.360000,-0.002609,-130.596069,0.000483,0.000623,0.015818,-0.011607,-0.000591,0.158182,-130.596069,0.016989,0.000000
1.610000,-0.032402,-130.640549,0.000647,0.000787,0.019998,-0.144131,-0.007342,0.199979,-130.640549,0.021152,0.000000
1.860000,-0.018250,-130.596069,0.000811,0.000955,0.024248,-0.081178,-0.004135,0.242476,-130.596069,0.025314,0.000000
2.110000,0.039093,-130.640549,0.000992,0.001114,0.028289,0.173894,0.008859,0.282887,-130.640549,0.029477,0.000000
2.360000,0.032394,-130.596069,0.001151,0.001285,0.032651,0.144098,0.007341,0.326508,-130.596069,0.033657,0.000000
2.610000,-0.013412,-130.640549,0.001332,0.001444,0.036684,-0.059662,-0.003039,0.366836,-130.640549,0.037819,0.000000
2.860000,0.012283,-130.596069,0.001492,0.001612,0.040933,0.054639,0.002783,0.409329,-130.596069,0.041982,0.000000
3.110000,0.011909,-130.685028,0.001660,0.001770,0.044957,0.052976,0.002699,0.449570,-130.685028,0.046145,0.000000
3.360000,-0.029045,-130.685028,0.001845,0.001938,0.049232,-0.129199,-0.006582,0.492324,-130.685028,0.050308,0.000000
3.610000,0.002228,-130.640549,0.002018,0.002106,0.053490,0.009910,0.000505,0.534904,-130.640549,0.054470,0.000000
3.860000,0.027184,-130.685028,0.002169,0.002262,0.057445,0.120918,0.006160,0.574449,-130.685028,0.058633,0.000000
4.110000,0.010796,-130.685028,0.002341,0.002434,0.061824,0.048021,0.002446,0.618244,-130.685028,0.062796,0.000000
4.360000,-0.017136,-130.596069,0.002522,0.002594,0.065883,-0.076223,-0.003883,0.658829,-130.596069,0.066976,0.000000
4.610000,0.022339,-130.640549,0.002716,0.002760,0.070098,0.099368,0.005062,0.700978,-130.640549,0.071138,0.000000
4.860000,0.029045,-130.685028,0.002884,0.002924,0.074269,0.129199,0.006582,0.742691,-130.685028,0.075301,0.000000
5.110000,-0.008194,-130.685028,0.003031,0.003086,0.078388,-0.036449,-0.001857,0.783882,-130.685028,0.079464,0.000000
5.360000,0.013031,-130.729523,0.003212,0.003248,0.082490,0.057965,0.002953,0.824903,-130.729523,0.083626,0.000000
5.610000,0.025688,-130.685028,0.003372,0.003409,0.086584,0.114267,0.005821,0.865836,-130.685028,0.087789,0.000000
5.860000,0.004837,-130.729523,0.003535,0.003580,0.090920,0.021516,0.001096,0.909196,-130.729523,0.091952,0.000000
6.110000,-0.028305,-130.685028,0.003721,0.003743,0.095074,-0.125907,-0.006414,0.950739,-130.685028,0.096132,0.000000
6.360000,0.031273,-130.685028,0.003898,0.003906,0.099202,0.139109,0.007087,0.992017,-130.685028,0.100294,0.000000
6.610000,0.039841,-130.774002,0.004061,0.004073,0.103443,0.177220,0.009028,1.034427,-130.774002,0.104457,0.000000
6.860000,-0.002235,-130.774002,0.004243,0.004234,0.107544,-0.009944,-0.000507,1.075444,-130.774002,0.108620,0.000000
7.110000,0.021965,-130.774002,0.004411,0.004401,0.111794,0.097705,0.004977,1.117941,-130.774002,0.112783,0.000000
7.360000,0.032021,-130.774002,0.004579,0.004557,0.115749,0.142435,0.007256,1.157485,-130.774002,0.116945,0.000000
7.610000,0.016754,-130.774002,0.004738,0.004727,0.120058,0.074526,0.003797,1.200584,-130.774002,0.121108,0.000000
7.860001,-0.004471,-130.774002,0.004919,0.004890,0.124195,-0.019887,-0.001013,1.241953,-130.774002,0.125271,0.000000
8.110001,0.090858,-130.818481,0.005096,0.005050,0.128280,0.404159,0.020589,1.282799,-130.818481,0.129451,0.000000
8.360001,0.287842,-130.818481,0.005260,0.005217,0.132521,1.280384,0.065226,1.325205,-130.818481,0.133613,0.000000
8.610001,0.564140,-130.818481,0.005428,0.005383,0.136718,2.509422,0.127836,1.367180,-130.818481,0.137776,0.000000
8.860001,0.582016,-130.818481,0.005471,-0.000001,-0.000026,2.588936,0.131887,-0.000261,-130.818481,0.000182,0.000000
9.110001,0.529884,-130.818481,0.005497,-0.000001,-0.000026,2.357043,0.120074,-0.000261,-130.818481,0.000182,0.000000
9.360001,0.463600,-130.818481,0.005471,-0.000001,-0.000026,2.062196,0.105053,-0.000261,-130.818481,0.000468,0.000000
9.610001,0.498978,-130.818481,0.005484,-0.000001,-0.000026,2.219563,0.113070,-0.000261,-130.818481,0.000885,0.000000
9.860001,0.461365,-130.818481,0.005489,-0.000000,-0.000000,2.052253,0.104547,-0.000000,-130.818481,0.001301,0.000000
10.110001,0.673248,-130.862961,0.005506,0.000029,0.000737,2.994758,0.152560,0.007373,-130.862961,0.001717,0.000000
10.360001,0.814377,-130.862961,0.005523,0.000056,0.001431,3.622529,0.184540,0.014311,-130.862961,0.002134,0.000000
10.610001,0.872467,-130.862961,0.005558,0.000073,0.001847,3.880927,0.197704,0.018470,-130.862961,0.002550,0.000000
10.860001,0.857201,-130.818481,0.005553,0.000086,0.002194,3.813019,0.194244,0.021941,-130.818481,0.002966,0.000000
11.110001,0.928322,-130.862961,0.005570,0.000100,0.002541,4.129382,0.210361,0.025408,-130.862961,0.003382,0.000000
11.360001,1.032211,-130.907440,0.005614,0.000119,0.003018,4.591505,0.233902,0.030181,-130.907440,0.003799,0.000000
11.610001,1.090675,-130.907440,0.005614,0.000133,0.003391,4.851566,0.247151,0.033909,-130.907440,0.004215,0.000000
11.860001,1.171478,-130.862961,0.005631,0.000147,0.003729,5.210996,0.265461,0.037289,-130.862961,0.004631,0.000000
12.110001,1.286919,-130.862961,0.005644,0.000165,0.004197,5.724500,0.291620,0.041974,-130.862961,0.005047,0.000000
12.360001,1.394157,-130.951920,0.005670,0.000186,0.004726,6.201522,0.315921,0.047262,-130.951920,0.005463,0.000000
12.610001,1.450386,-130.951920,0.005696,0.000199,0.005047,6.451639,0.328662,0.050472,-130.951920,0.005889,0.000000
12.860001,1.521881,-131.040878,0.005696,0.000214,0.005437,6.769665,0.344863,0.054374,-131.040878,0.006305,0.000000
13.110001,1.613487,-130.907440,0.005691,0.000229,0.005819,7.177150,0.365621,0.058189,-130.907440,0.006721,0.000000
13.360001,1.711044,-130.951920,0.005713,0.000244,0.006201,7.611105,0.387728,0.062008,-130.951920,0.007137,0.000000
13.610001,1.838768,-130.951920,0.005726,0.000263,0.006678,8.179249,0.416671,0.066777,-130.951920,0.007554,0.000000
13.860001,1.829086,-130.951920,0.005743,0.000273,0.006929,8.136182,0.414477,0.069290,-130.951920,0.007970,0.000000
14.110001,1.967987,-130.951920,0.005773,0.000290,0.007371,8.754044,0.445952,0.073715,-130.951920,0.008386,0.000000
14.360001,2.141884,-130.951920,0.005769,0.000313,0.007944,9.527575,0.485358,0.079437,-130.951920,0.008802,0.000000
14.610001,2.199226,-130.951920,0.005790,0.000326,0.008291,9.782647,0.498352,0.082908,-130.951920,0.009218,0.000000
14.860001,2.305351,-130.996399,0.005808,0.000345,0.008768,10.254715,0.522400,0.087677,-130.996399,0.009635,0.000000
15.110001,2.382065,-131.040878,0.005825,0.000360,0.009141,10.595954,0.539784,0.091405,-131.040878,0.010051,0.000000
15.360001,2.536972,-130.951920,0.005838,0.000380,0.009661,11.285015,0.574886,0.096609,-130.951920,0.010468,0.000000
15.610001,2.581284,-130.996399,0.005855,0.000396,0.010069,11.482122,0.584927,0.100686,-130.996399,0.010884,0.000000
15.860001,2.596550,-130.996399,0.005864,0.000409,0.010381,11.550032,0.588387,0.103808,-130.996399,0.011300,0.000000
16.110001,2.793533,-131.040878,0.005894,0.000430,0.010910,12.426257,0.633024,0.109096,-131.040878,0.011716,0.000000
16.360001,2.926476,-131.040878,0.005915,0.000447,0.011361,13.017613,0.663149,0.113607,-131.040878,0.012132,0.000000
16.610001,2.932800,-131.040878,0.005915,0.000459,0.011664,13.045747,0.664582,0.116643,-131.040878,0.012549,0.000000
16.860001,3.022545,-131.040878,0.005941,0.000477,0.012106,13.444951,0.684918,0.121064,-131.040878,0.012965,0.000000
17.110001,3.002808,-131.085358,0.005950,0.000486,0.012349,13.357156,0.680446,0.123494,-131.085358,0.013381,0.000000
17.360001,3.311508,-131.085358,0.005976,0.000510,0.012956,14.730324,0.750398,0.129565,-131.085358,0.013797,0.000000
17.610001,3.316345,-131.040878,0.005984,0.000522,0.013269,14.751841,0.751495,0.132687,-131.040878,0.014214,0.000000
17.860001,3.323051,-131.129837,0.005984,0.000533,0.013529,14.781672,0.753014,0.135287,-131.129837,0.014639,0.000000
18.110001,3.688347,-131.040878,0.006015,0.000559,0.014196,16.406586,0.835791,0.141964,-131.040878,0.015055,0.000000
18.360001,3.822769,-131.040878,0.006049,0.000579,0.014708,17.004526,0.866252,0.147081,-131.040878,0.015471,0.000000
18.610001,3.830589,-131.129837,0.006036,0.000592,0.015029,17.039312,0.868024,0.150291,-131.129837,0.015887,0.000000
18.860001,3.917725,-131.129837,0.006053,0.000606,0.015384,17.426908,0.887769,0.153845,-131.129837,0.016304,0.000000
19.110001,4.040985,-131.129837,0.006084,0.000621,0.015775,17.975199,0.915700,0.157747,-131.129837,0.016720,0.000000
19.360001,4.202965,-131.129837,0.006109,0.000637,0.016191,18.695721,0.952405,0.161910,-131.129837,0.017136,0.000000
19.610001,4.290100,-131.129837,0.006118,0.000650,0.016512,19.083319,0.972151,0.165120,-131.129837,0.017552,0.000000
19.860001,4.528046,-131.129837,0.006135,0.000669,0.016998,20.141752,1.026070,0.169976,-131.129837,0.017969,0.000000
20.110001,4.651672,-131.129837,0.006157,0.000687,0.017457,20.691671,1.054084,0.174571,-131.129837,0.018385,0.000000
20.360001,4.812538,-131.085358,0.006165,0.000706,0.017934,21.407238,1.090537,0.179343,-131.085358,0.018801,0.000000
20.610001,4.927971,-131.218811,0.006157,0.000722,0.018342,21.920710,1.116694,0.183420,-131.218811,0.019218,0.000000
20.860001,4.989418,-131.174332,0.006196,0.000737,0.018723,22.194040,1.130618,0.187235,-131.174332,0.019634,0.000000
21.110001,5.344284,-131.174332,0.006217,0.000757,0.019235,23.772562,1.211032,0.192352,-131.174332,0.020050,0.000000
21.360001,5.387482,-131.174332,0.006222,0.000772,0.019608,23.964716,1.220821,0.196080,-131.174332,0.020466,0.000000
21.610001,5.410942,-131.174332,0.006234,0.000783,0.019877,24.069073,1.226137,0.198768,-131.174332,0.020883,0.000000
21.860001,5.711075,-131.218811,0.006243,0.000801,0.020354,25.404129,1.294148,0.203537,-131.218811,0.021299,0.000000
22.110001,5.883484,-131.174332,0.006278,0.000819,0.020805,26.171043,1.333217,0.208048,-131.174332,0.021715,0.000000
22.360001,5.939713,-131.218811,0.006286,0.000833,0.021160,26.421162,1.345958,0.211602,-131.218811,0.022131,0.000000
22.610001,5.874542,-131.218811,0.006291,0.000841,0.021360,26.131269,1.331190,0.213597,-131.218811,0.022548,0.000000
22.860001,6.302025,-131.218811,0.006325,0.000865,0.021967,28.032806,1.428059,0.219668,-131.218811,0.022973,0.000000
23.110001,6.656525,-131.218811,0.006359,0.000890,0.022600,29.609701,1.508390,0.226000,-131.218811,0.023389,0.000000
23.360001,6.537369,-131.218811,0.006355,0.000898,0.022799,29.079668,1.481389,0.227995,-131.218811,0.023805,0.000000
23.610001,6.536621,-131.307770,0.006372,0.000909,0.023077,29.076344,1.481219,0.230769,-131.307770,0.024221,0.000000
23.860001,7.038208,-131.218811,0.006390,0.000934,0.023727,31.307512,1.594881,0.237271,-131.218811,0.024638,0.000000
24.110001,7.259773,-131.263290,0.006407,0.000954,0.024239,32.293083,1.645088,0.242388,-131.263290,0.025054,0.000000
24.360001,7.220673,-131.218811,0.006416,0.000965,0.024508,32.119156,1.636228,0.245080,-131.218811,0.025470,0.000000
24.610001,7.384140,-131.218811,0.006450,0.000983,0.024976,32.846294,1.673270,0.249761,-131.218811,0.025887,0.000000
24.860001,7.587830,-131.307770,0.006454,0.001000,0.025410,33.752350,1.719427,0.254095,-131.307770,0.026303,0.000000
25.110001,7.810509,-131.352249,0.006472,0.001019,0.025878,34.742878,1.769887,0.258781,-131.352249,0.026719,0.000000
25.360001,7.689491,-131.307770,0.006493,0.001027,0.026095,34.204567,1.742464,0.260950,-131.307770,0.027135,0.000000
25.610001,7.939720,-131.307770,0.006489,0.001043,0.026485,35.317638,1.799166,0.264852,-131.307770,0.027552,0.000000
25.860001,8.054787,-131.307770,0.006493,0.001057,0.026858,35.829479,1.825241,0.268580,-131.307770,0.027968,0.000000
26.110001,8.553764,-131.352249,0.006523,0.001084,0.027534,38.049046,1.938311,0.275344,-131.352249,0.028384,0.000000
26.360001,8.574242,-131.352249,0.006562,0.001100,0.027933,38.140133,1.942951,0.279333,-131.352249,0.028800,0.000000
26.610001,8.702713,-131.352249,0.006562,0.001116,0.028350,38.711601,1.972063,0.283496,-131.352249,0.029217,0.000000
26.860001,8.747025,-131.307770,0.006575,0.001130,0.028696,38.908707,1.982104,0.286963,-131.307770,0.029633,0.000000
27.110001,8.936188,-131.396729,0.006610,0.001147,0.029130,39.750149,2.024969,0.291301,-131.396729,0.030049,0.000000
27.360001,9.022583,-131.396729,0.006610,0.001163,0.029529,40.134453,2.044547,0.295290,-131.396729,0.030466,0.000000
27.610001,9.153282,-131.352249,0.006627,0.001175,0.029841,40.715832,2.074163,0.298412,-131.352249,0.030882,0.000000
27.860001,9.587097,-131.396729,0.006631,0.001199,0.030457,42.645538,2.172467,0.304570,-131.396729,0.031307,0.000000
28.110001,9.774399,-131.352249,0.006648,0.001216,0.030882,43.478699,2.214910,0.308817,-131.352249,0.031723,0.000000
28.360001,9.648537,-131.396729,0.006679,0.001228,0.031194,42.918835,2.186390,0.311940,-131.396729,0.032139,0.000000
28.610001,9.969528,-131.396729,0.006674,0.001247,0.031671,44.346676,2.259127,0.316712,-131.396729,0.032556,0.000000
28.860001,10.228699,-131.396729,0.006700,0.001266,0.032157,45.499523,2.317856,0.321568,-131.396729,0.032972,0.000000
29.110001,10.302055,-131.441208,0.006726,0.001282,0.032564,45.825832,2.334479,0.325645,-131.441208,0.033388,0.000000
29.360001,10.332962,-131.485687,0.006735,0.001295,0.032885,45.963310,2.341483,0.328851,-131.485687,0.033804,0.000000
29.610001,10.424934,-131.485687,0.006752,0.001311,0.033301,46.372425,2.362324,0.333014,-131.485687,0.034221,0.000000
29.860001,10.978279,-131.485687,0.006773,0.001335,0.033908,48.833824,2.487714,0.339085,-131.485687,0.034637,0.000000
30.110001,10.949608,-131.396729,0.006791,0.001348,0.034229,48.706287,2.481217,0.342295,-131.396729,0.035053,0.000000
30.360001,10.998764,-131.485687,0.006812,0.001364,0.034654,48.924946,2.492356,0.346545,-131.485687,0.035469,0.000000
30.610001,11.074722,-131.441208,0.006808,0.001377,0.034966,49.262825,2.509568,0.349664,-131.441208,0.035886,0.000000
30.860001,11.402412,-131.485687,0.006838,0.001397,0.035478,50.720463,2.583824,0.354781,-131.485687,0.036302,0.000000
31.110001,11.496254,-131.485687,0.006842,0.001414,0.035903,51.137890,2.605088,0.359031,-131.485687,0.036718,0.000000
31.360001,11.510773,-131.485687,0.006868,0.001424,0.036172,51.202473,2.608378,0.361719,-131.485687,0.037135,0.000000
31.610001,11.882774,-131.485687,0.006864,0.001443,0.036649,52.857220,2.692675,0.366488,-131.485687,0.037551,0.000000
31.860001,12.300575,-131.530167,0.006924,0.001466,0.037247,54.715691,2.787350,0.372472,-131.530167,0.037967,0.000000
32.110001,12.116623,-131.530167,0.006894,0.001479,0.037568,53.897430,2.745666,0.375681,-131.530167,0.038383,0.000000
32.360001,12.188492,-131.574646,0.006933,0.001494,0.037950,54.217121,2.761952,0.379496,-131.574646,0.038800,0.000000
32.610001,12.245834,-131.574646,0.006937,0.001507,0.038279,54.472191,2.774946,0.382793,-131.574646,0.039216,0.000000
32.860001,12.665504,-131.574646,0.006963,0.001529,0.038826,56.338978,2.870044,0.388258,-131.574646,0.039632,0.000000
33.110001,12.722847,-131.574646,0.006985,0.001544,0.039225,56.594051,2.883038,0.392248,-131.574646,0.040057,0.000000
33.360001,12.718750,-131.574646,0.006993,0.001558,0.039563,56.575825,2.882110,0.395627,-131.574646,0.040473,0.000000
33.610001,13.136551,-131.574646,0.007011,0.001576,0.040031,58.434296,2.976785,0.400309,-131.574646,0.040890,0.000000
33.860001,13.216614,-131.574646,0.007041,0.001591,0.040413,58.790436,2.994927,0.404128,-131.574646,0.041306,0.000000
34.110001,13.329811,-131.619141,0.007049,0.001610,0.040898,59.293961,3.020578,0.408984,-131.619141,0.041722,0.000000
34.360001,13.467964,-131.574646,0.007062,0.001624,0.041245,59.908497,3.051884,0.412451,-131.574646,0.042138,0.000000
34.610001,13.720802,-131.663620,0.007080,0.001642,0.041714,61.033176,3.109178,0.417137,-131.663620,0.042555,0.000000
34.860001,13.808311,-131.619141,0.007097,0.001658,0.042104,61.422436,3.129008,0.421039,-131.619141,0.042971,0.000000
35.110001,13.925980,-131.574646,0.007127,0.001671,0.042451,61.945850,3.155672,0.424506,-131.574646,0.043387,0.000000
35.360001,13.981834,-131.619141,0.007118,0.001685,0.042806,62.194305,3.168329,0.428064,-131.619141,0.043804,0.000000
35.610001,14.497200,-131.663620,0.007144,0.001709,0.043413,64.486763,3.285112,0.434131,-131.663620,0.044220,0.000000
35.860001,14.471878,-131.619141,0.007174,0.001723,0.043769,64.374130,3.279374,0.437689,-131.619141,0.044636,0.000000
36.110001,14.675194,-131.663620,0.007166,0.001741,0.044220,65.278519,3.325446,0.442197,-131.663620,0.045052,0.000000
36.360001,14.904205,-131.619141,0.007174,0.001758,0.044662,66.297218,3.377341,0.446621,-131.619141,0.045469,0.000000
36.610001,14.996925,-131.663620,0.007222,0.001773,0.045044,66.709656,3.398352,0.450437,-131.663620,0.045885,0.000000
36.860001,15.166725,-131.708099,0.007243,0.001790,0.045477,67.464966,3.436829,0.454774,-131.708099,0.046301,0.000000
37.110001,14.984268,-131.663620,0.007252,0.001799,0.045703,66.653351,3.395484,0.457026,-131.663620,0.046717,0.000000
37.360001,15.512291,-131.663620,0.007269,0.001823,0.046301,69.002113,3.515136,0.463010,-131.663620,0.047134,0.000000
37.610001,15.581551,-131.663620,0.007282,0.001839,0.046700,69.310196,3.530830,0.466999,-131.663620,0.047550,0.000000
37.860001,15.661980,-131.708099,0.007308,0.001855,0.047108,69.667969,3.549055,0.471076,-131.708099,0.047966,0.000000
38.110001,15.826202,-131.708099,0.007304,0.001871,0.047533,70.398460,3.586269,0.475326,-131.708099,0.048391,0.000000
38.360001,15.762154,-131.708099,0.007351,0.001883,0.047836,70.113564,3.571755,0.478362,-131.708099,0.048807,0.000000
38.610001,16.045151,-131.752579,0.007343,0.001901,0.048287,71.372398,3.635883,0.482869,-131.752579,0.049224,0.000000
38.860001,16.242508,-131.752579,0.007355,0.001916,0.048669,72.250282,3.680605,0.486688,-131.752579,0.049640,0.000000
39.110001,16.132286,-131.797058,0.007364,0.001927,0.048938,71.759995,3.655628,0.489376,-131.797058,0.050056,0.000000
39.360001,16.674461,-131.752579,0.007386,0.001952,0.049579,74.171707,3.778487,0.495791,-131.752579,0.050472,0.000000
39.610001,17.050934,-131.752579,0.007416,0.001971,0.050074,75.846344,3.863797,0.500738,-131.752579,0.050889,0.000000
39.860001,17.036034,-131.797058,0.007437,0.001986,0.050447,75.780060,3.860420,0.504466,-131.797058,0.051305,0.000000
40.110001,16.987625,-131.752579,0.007455,0.002000,0.050802,75.564728,3.849451,0.508020,-131.752579,0.051721,0.000000
40.360001,16.898628,-131.797058,0.007468,0.002013,0.051132,75.168854,3.829284,0.511317,-131.797058,0.052138,0.000000
40.610001,17.501129,-131.797058,0.007476,0.002034,0.051669,77.848907,3.965813,0.516691,-131.797058,0.052554,0.000000
40.860001,17.349945,-131.841537,0.007493,0.002047,0.051981,77.176407,3.931554,0.519814,-131.841537,0.052970,0.000000
41.110001,17.554382,-131.797058,0.007498,0.002063,0.052398,78.085793,3.977880,0.523977,-131.797058,0.053386,0.000000
41.360001,17.879463,-131.752579,0.007528,0.002080,0.052823,79.531822,4.051544,0.528228,-131.752579,0.053803,0.000000
41.610001,18.287209,-131.841537,0.007549,0.002101,0.053369,81.345566,4.143941,0.533689,-131.841537,0.054219,0.000000
41.860001,18.262634,-131.841537,0.007567,0.002115,0.053733,81.236252,4.138372,0.537334,-131.841537,0.054635,0.000000
42.110001,18.233589,-131.930496,0.007584,0.002130,0.054106,81.107056,4.131790,0.541062,-131.930496,0.055051,0.000000
42.360001,18.540421,-131.841537,0.007597,0.002149,0.054592,82.471909,4.201319,0.545918,-131.841537,0.055468,0.000000
42.610001,18.651390,-131.886017,0.007618,0.002165,0.054982,82.965530,4.226465,0.549820,-131.886017,0.055884,0.000000
42.860001,18.705383,-131.797058,0.007653,0.002178,0.055329,83.205704,4.238700,0.553291,-131.797058,0.056300,0.000000
43.110001,18.906090,-131.886017,0.007653,0.002196,0.055789,84.098488,4.284181,0.557886,-131.886017,0.056725,0.000000
43.360001,19.238991,-131.886017,0.007679,0.002214,0.056231,85.579308,4.359618,0.562311,-131.886017,0.057141,0.000000
43.610001,19.392784,-131.886017,0.007683,0.002230,0.056630,86.263412,4.394468,0.566300,-131.886017,0.057558,0.000000
43.860001,19.016312,-131.930496,0.007700,0.002239,0.056873,84.588776,4.309158,0.568726,-131.930496,0.057974,0.000000
44.110001,19.445290,-131.886017,0.007722,0.002259,0.057384,86.496971,4.406365,0.573843,-131.886017,0.058390,0.000000
44.360001,19.899582,-131.974976,0.007743,0.002280,0.057905,88.517761,4.509310,0.579047,-131.974976,0.058807,0.000000
44.610001,20.120026,-131.886017,0.007765,0.002294,0.058278,89.498344,4.559263,0.582775,-131.886017,0.059223,0.000000
44.860001,19.844841,-131.930496,0.007765,0.002305,0.058555,88.274261,4.496905,0.585550,-131.930496,0.059639,0.000000
45.110001,20.243279,-131.974976,0.007808,0.002326,0.059093,90.046600,4.587193,0.590928,-131.974976,0.060055,0.000000
45.360001,20.762367,-131.974976,0.007791,0.002348,0.059639,92.355621,4.704820,0.596390,-131.974976,0.060472,0.000000
45.610001,20.707626,-132.019470,0.007843,0.002360,0.059951,92.112122,4.692415,0.599512,-132.019470,0.060888,0.000000
45.860001,20.756035,-132.019470,0.007847,0.002378,0.060394,92.327454,4.703385,0.603937,-132.019470,0.061304,0.000000
46.110001,21.108299,-132.019470,0.007856,0.002397,0.060879,93.894402,4.783209,0.608793,-132.019470,0.061720,0.000000
46.360001,21.325768,-131.974976,0.007881,0.002414,0.061313,94.861755,4.832488,0.613130,-131.974976,0.062137,0.000000
46.610001,21.145912,-132.019470,0.007894,0.002424,0.061564,94.061714,4.791732,0.615643,-132.019470,0.062553,0.000000
46.860001,21.263954,-132.019470,0.007925,0.002440,0.061981,94.586792,4.818481,0.619807,-132.019470,0.062969,0.000000
47.110001,21.164154,-131.974976,0.007925,0.002450,0.062241,94.142860,4.795866,0.622407,-131.974976,0.063386,0.000000
47.360001,22.168449,-131.974976,0.007942,0.002480,0.062987,98.610191,5.023442,0.629867,-131.974976,0.063802,0.000000
47.610001,22.092110,-132.019470,0.007963,0.002492,0.063307,98.270615,5.006144,0.633073,-132.019470,0.064218,0.000000
47.860001,22.306969,-132.063950,0.007998,0.002510,0.063750,99.226349,5.054832,0.637497,-132.063950,0.064634,0.000000
48.110001,22.434319,-132.108429,0.007989,0.002527,0.064192,99.792831,5.083689,0.641922,-132.108429,0.065051,0.000000
48.360001,22.444000,-132.063950,0.008019,0.002541,0.064539,99.835899,5.085883,0.645389,-132.063950,0.065476,0.000000
48.610001,22.541565,-132.019470,0.008041,0.002555,0.064903,100.269890,5.107992,0.649030,-132.019470,0.065892,0.000000
48.860001,22.640617,-132.063950,0.008054,0.002571,0.065302,100.710495,5.130437,0.653019,-132.063950,0.066308,0.000000
49.110001,22.823448,-132.108429,0.008063,0.002588,0.065727,101.523766,5.171867,0.657270,-132.108429,0.066724,0.000000
49.360001,23.526115,-132.063950,0.008088,0.002611,0.066317,104.649391,5.331094,0.663167,-132.063950,0.067141,0.000000
49.610001,23.212952,-132.152908,0.008093,0.002619,0.066534,103.256363,5.260130,0.665335,-132.152908,0.067557,0.000000
49.860001,23.400253,-132.152908,0.008114,0.002638,0.066993,104.089523,5.302573,0.669930,-132.152908,0.067973,0.000000
50.110001,23.567078,-132.108429,0.008132,0.002656,0.067462,104.831596,5.340376,0.674616,-132.108429,0.068389,0.000000
50.360001,24.182236,-132.152908,0.008179,0.002677,0.067990,107.567955,5.479773,0.679903,-132.152908,0.068806,0.000000
50.610001,23.981529,-132.197388,0.008175,0.002689,0.068303,106.675171,5.434292,0.683026,-132.197388,0.069222,0.000000
50.860001,24.095848,-132.152908,0.008183,0.002704,0.068693,107.183685,5.460197,0.686928,-132.152908,0.069638,0.000000
51.110001,24.716591,-132.197388,0.008244,0.002727,0.069257,109.944885,5.600860,0.692568,-132.197388,0.070055,0.000000
51.360001,24.870750,-132.197388,0.008252,0.002743,0.069681,110.630623,5.635793,0.696814,-132.197388,0.070471,0.000000
51.610001,24.754570,-132.197388,0.008261,0.002758,0.070046,110.113831,5.609466,0.700459,-132.197388,0.070887,0.000000
51.860001,24.906128,-132.197388,0.008287,0.002772,0.070419,110.787987,5.643809,0.704187,-132.197388,0.071303,0.000000
52.110001,25.219292,-132.241867,0.008304,0.002792,0.070904,112.181015,5.714773,0.709043,-132.241867,0.071720,0.000000
52.360001,25.214455,-132.197388,0.008313,0.002804,0.071217,112.159492,5.713677,0.712166,-132.197388,0.072136,0.000000
52.610001,25.384628,-132.197388,0.008326,0.002820,0.071624,112.916466,5.752239,0.716242,-132.197388,0.072552,0.000000
52.860001,25.385002,-132.286346,0.008356,0.002835,0.072014,112.918129,5.752324,0.720144,-132.286346,0.072968,0.000000
53.110004,26.454826,-132.241867,0.008373,0.002861,0.072673,117.676949,5.994750,0.726734,-132.241867,0.073385,0.000000
53.360004,26.386681,-132.241867,0.008382,0.002876,0.073038,117.373817,5.979307,0.730379,-132.241867,0.073810,0.000000
53.610004,26.089531,-132.286346,0.008416,0.002887,0.073341,116.052032,5.911972,0.733414,-132.286346,0.074226,0.000000
53.860004,26.267151,-132.330826,0.008438,0.002904,0.073757,116.842125,5.952222,0.737574,-132.330826,0.074642,0.000000
54.110004,26.712135,-132.286346,0.008433,0.002923,0.074252,118.821510,6.053057,0.742517,-132.286346,0.075058,0.000000
54.360004,26.745277,-132.286346,0.008459,0.002938,0.074616,118.968933,6.060566,0.746162,-132.286346,0.075475,0.000000
54.610004,26.647339,-132.286346,0.008489,0.002949,0.074902,118.533287,6.038373,0.749023,-132.286346,0.075891,0.000000
54.860004,27.244255,-132.286346,0.008515,0.002972,0.075483,121.188499,6.173636,0.754833,-132.286346,0.076307,0.000000
55.110004,27.537682,-132.286346,0.008524,0.002989,0.075917,122.493729,6.240128,0.759170,-132.286346,0.076724,0.000000
55.360004,27.401398,-132.330826,0.008554,0.003001,0.076238,121.887505,6.209246,0.762376,-132.330826,0.077140,0.000000
55.610004,27.527634,-132.375305,0.008558,0.003019,0.076680,122.449028,6.237851,0.766801,-132.375305,0.077556,0.000000
55.860004,27.552582,-132.375305,0.008576,0.003033,0.077035,122.560005,6.243505,0.770355,-132.375305,0.077972,0.000000
56.110004,27.742119,-132.330826,0.008580,0.003051,0.077487,123.403107,6.286454,0.774866,-132.330826,0.078389,0.000000
56.360004,27.949532,-132.375305,0.008636,0.003066,0.077868,124.325729,6.333454,0.778682,-132.375305,0.078805,0.000000
56.610004,27.716423,-132.375305,0.008619,0.003075,0.078111,123.288811,6.280631,0.781111,-132.375305,0.079221,0.000000
56.860004,28.731140,-132.419785,0.008636,0.003102,0.078796,127.802498,6.510570,0.787962,-132.419785,0.079637,0.000000
57.110004,28.851784,-132.286346,0.008670,0.003118,0.079195,128.339142,6.537908,0.791951,-132.286346,0.080054,0.000000
57.360004,28.817902,-132.419785,0.008701,0.003132,0.079559,128.188431,6.530230,0.795592,-132.419785,0.080470,0.000000
57.610004,29.187294,-132.419785,0.008709,0.003153,0.080080,129.831573,6.613935,0.800797,-132.419785,0.080886,0.000000
57.860004,28.684219,-132.330826,0.008731,0.003162,0.080305,127.593781,6.499937,0.803053,-132.330826,0.081303,0.000000
58.110004,29.538811,-132.375305,0.008757,0.003185,0.080895,131.395187,6.693590,0.808949,-132.375305,0.081719,0.000000
58.360004,29.410721,-132.375305,0.008774,0.003196,0.081190,130.825424,6.664565,0.811898,-132.375305,0.082144,0.000000
58.610004,29.399178,-132.419785,0.008774,0.003212,0.081597,130.774078,6.661949,0.815974,-132.419785,0.082560,0.000000
58.860004,30.127907,-132.419785,0.008817,0.003234,0.082152,134.015625,6.827081,0.821523,-132.419785,0.082976,0.000000
59.110004,30.206108,-132.464279,0.008830,0.003249,0.082534,134.363480,6.844802,0.825338,-132.464279,0.083393,0.000000
59.360004,30.238129,-132.464279,0.008869,0.003266,0.082959,134.505920,6.852058,0.829588,-132.464279,0.083809,0.000000
59.610004,30.229195,-132.508759,0.008877,0.003278,0.083262,134.466171,6.850034,0.832624,-132.508759,0.084225,0.000000
59.860004,30.301804,-132.508759,0.008890,0.003294,0.083661,134.789154,6.866487,0.836613,-132.508759,0.084641,0.000000
60.110004,30.816422,-132.464279,0.008908,0.003312,0.084121,137.078293,6.983101,0.841208,-132.464279,0.085058,0.000000
60.360004,30.793709,-132.464279,0.008938,0.003324,0.084433,136.977264,6.977954,0.844331,-132.464279,0.085474,0.000000
60.610004,31.263641,-132.464279,0.008933,0.003344,0.084927,139.067627,7.084442,0.849274,-132.464279,0.085890,0.000000
60.860004,31.872475,-132.508759,0.008972,0.003364,0.085456,141.775848,7.222406,0.854565,-132.508759,0.086306,0.000000
61.110004,31.998711,-132.553238,0.009011,0.003380,0.085847,142.337372,7.251011,0.858467,-132.553238,0.086723,0.000000
61.360004,31.995354,-132.553238,0.009002,0.003395,0.086228,142.322449,7.250251,0.862282,-132.553238,0.087139,0.000000
61.610004,31.982323,-132.508759,0.009011,0.003407,0.086549,142.264481,7.247298,0.865492,-132.508759,0.087555,0.000000
61.860004,32.336449,-132.553238,0.009028,0.003426,0.087017,143.839706,7.327544,0.870174,-132.553238,0.087971,0.000000
62.110004,32.729675,-132.553238,0.009071,0.003442,0.087434,145.588867,7.416650,0.874337,-132.553238,0.088388,0.000000
62.360004,32.584824,-132.508759,0.009080,0.003455,0.087763,144.944534,7.383826,0.877634,-132.508759,0.088804,0.000000
62.610004,33.349304,-132.597717,0.009093,0.003476,0.088283,148.345108,7.557060,0.882834,-132.597717,0.089220,0.000000
62.860004,33.992760,-132.642197,0.009115,0.003496,0.088804,151.207352,7.702870,0.888039,-132.642197,0.089637,0.000000
63.110004,33.998718,-132.597717,0.009145,0.003511,0.089177,151.233856,7.704220,0.891767,-132.597717,0.090053,0.000000
63.360004,34.272789,-132.597717,0.009145,0.003525,0.089541,152.452972,7.766325,0.895412,-132.597717,0.090469,0.000000
63.610004,34.473869,-132.553238,0.009166,0.003543,0.089983,153.347427,7.811891,0.899832,-132.553238,0.090894,0.000000
63.860004,34.966888,-132.597717,0.009175,0.003559,0.090391,155.540482,7.923610,0.903909,-132.597717,0.091310,0.000000
64.110001,35.288620,-132.597717,0.009192,0.003576,0.090825,156.971619,7.996515,0.908246,-132.597717,0.091727,0.000000
64.360001,35.086044,-132.597717,0.009227,0.003584,0.091041,156.070526,7.950612,0.910415,-132.597717,0.092143,0.000000
64.610001,35.815155,-132.642197,0.009209,0.003604,0.091536,159.313766,8.115830,0.915358,-132.642197,0.092559,0.000000
64.860001,36.622826,-132.686676,0.009248,0.003625,0.092082,162.906464,8.298851,0.920820,-132.686676,0.092975,0.000000
65.110001,36.312271,-132.642197,0.009274,0.003633,0.092281,161.525055,8.228477,0.922814,-132.642197,0.093392,0.000000
65.360001,36.984406,-132.642197,0.009274,0.003654,0.092819,164.514847,8.380787,0.928192,-132.642197,0.093808,0.000000
65.610001,37.591370,-132.642197,0.009304,0.003671,0.093236,167.214767,8.518326,0.932356,-132.642197,0.094224,0.000000
65.860001,38.475380,-132.686676,0.009317,0.003690,0.093730,171.147034,8.718646,0.937299,-132.686676,0.094640,0.000000
66.110001,38.070610,-132.642197,0.009334,0.003699,0.093964,169.346527,8.626924,0.939638,-132.642197,0.095056,0.000000
66.360001,38.465698,-132.642197,0.009352,0.003715,0.094371,171.103973,8.716452,0.943714,-132.642197,0.095473,0.000000
66.610001,39.720970,-132.686676,0.009369,0.003739,0.094970,176.687698,9.000900,0.949698,-132.686676,0.095889,0.000000
66.860001,40.278778,-132.642197,0.009395,0.003755,0.095386,179.168961,9.127301,0.953862,-132.642197,0.096306,0.000000
67.110001,40.244148,-132.731155,0.009399,0.003766,0.095664,179.014908,9.119454,0.956636,-132.731155,0.096721,0.000000
67.360001,40.802338,-132.731155,0.009412,0.003787,0.096184,181.497864,9.245942,0.961840,-132.731155,0.097138,0.000000
67.610001,41.323288,-132.731155,0.009429,0.003802,0.096574,183.815170,9.363991,0.965742,-132.731155,0.097554,0.000000
67.860001,42.219955,-132.731155,0.009464,0.003820,0.097017,187.803741,9.567179,0.970167,-132.731155,0.097970,0.000000
68.110001,41.961159,-132.731155,0.009468,0.003828,0.097233,186.652557,9.508534,0.972332,-132.731155,0.098387,0.000000
68.360001,42.361458,-132.731155,0.009481,0.003840,0.097545,188.433182,9.599244,0.975455,-132.731155,0.098803,0.000000
68.610001,43.695671,-132.775635,0.009485,0.003866,0.098187,194.368057,9.901580,0.981874,-132.775635,0.099228,0.000000
68.860001,44.912956,-132.775635,0.009528,0.003888,0.098751,199.782806,10.177422,0.987509,-132.775635,0.099644,0.000000
69.110001,45.120743,-132.731155,0.009546,0.003904,0.099167,200.707092,10.224506,0.991673,-132.731155,0.100061,0.000000
69.360001,45.689728,-132.731155,0.009550,0.003920,0.099566,203.238052,10.353440,0.995662,-132.731155,0.100477,0.000000
69.610001,46.248657,-132.731155,0.009567,0.003934,0.099913,205.724304,10.480096,0.999129,-132.731155,0.100893,0.000000
69.860001,46.990051,-132.820114,0.009589,0.003951,0.100355,209.022186,10.648098,1.003554,-132.820114,0.101309,0.000000
70.110001,47.285713,-132.775635,0.009602,0.003961,0.100598,210.337357,10.715096,1.005983,-132.775635,0.101725,0.000000
70.360001,47.652130,-132.820114,0.009610,0.003977,0.101014,211.967255,10.798127,1.010143,-132.820114,0.102142,0.000000
70.610001,49.527771,-132.820114,0.009645,0.004004,0.101691,220.310532,11.223153,1.016910,-132.820114,0.102558,0.000000
70.860001,49.973129,-132.820114,0.009641,0.004017,0.102029,222.291580,11.324073,1.020290,-132.820114,0.102974,0.000000
71.110001,50.408058,-132.864594,0.009671,0.004032,0.102402,224.226242,11.422629,1.024019,-132.864594,0.103390,0.000000
71.360001,51.185196,-132.864594,0.009688,0.004047,0.102784,227.683121,11.598731,1.027837,-132.864594,0.103807,0.000000
71.610001,52.514565,-132.864594,0.009692,0.004069,0.103356,233.596451,11.899970,1.033560,-132.864594,0.104223,0.000000
71.860001,52.975189,-132.775635,0.009701,0.004081,0.103651,235.645416,12.004350,1.036509,-132.775635,0.104639,0.000000
72.110001,53.627586,-132.864594,0.009705,0.004097,0.104067,238.547424,12.152185,1.040672,-132.864594,0.105056,0.000000
72.360001,55.104050,-132.864594,0.009744,0.004120,0.104639,245.115051,12.486756,1.046395,-132.864594,0.105472,0.000000
72.610001,56.008911,-132.909088,0.009748,0.004136,0.105065,249.140076,12.691800,1.050645,-132.909088,0.105888,0.000000
72.860001,56.390968,-132.864594,0.009779,0.004150,0.105403,250.839554,12.778376,1.054025,-132.864594,0.106304,0.000000
73.110001,57.193428,-132.864594,0.009783,0.004165,0.105793,254.409073,12.960217,1.057927,-132.864594,0.106721,0.000000
73.360001,58.103134,-132.864594,0.009791,0.004182,0.106235,258.455658,13.166358,1.062352,-132.864594,0.107137,0.000000
73.610001,59.047096,-132.909088,0.009809,0.004197,0.106608,262.654602,13.380262,1.066080,-132.909088,0.107562,0.000000
73.860001,59.954201,-132.909088,0.009813,0.004213,0.107007,266.689606,13.585816,1.070069,-132.909088,0.107978,0.000000
74.110001,60.454292,-132.953568,0.009822,0.004224,0.107302,268.914124,13.699139,1.073018,-132.953568,0.108394,0.000000
74.360001,62.579048,-132.953568,0.009852,0.004253,0.108022,278.365509,14.180614,1.080217,-132.953568,0.108811,0.000000
74.610001,63.562866,-132.953568,0.009873,0.004268,0.108412,282.741760,14.403551,1.084119,-132.953568,0.109227,0.000000
74.860001,64.302383,-132.998047,0.009860,0.004282,0.108767,286.031281,14.571128,1.087673,-132.998047,0.109643,0.000000
75.110001,65.016968,-132.953568,0.009882,0.004297,0.109132,289.209930,14.733055,1.091318,-132.953568,0.110059,0.000000
75.360001,66.465134,-132.953568,0.009912,0.004317,0.109643,295.651672,15.061214,1.096435,-132.953568,0.110476,0.000000
75.610001,67.330521,-132.953568,0.009904,0.004330,0.109973,299.501129,15.257315,1.099728,-132.953568,0.110892,0.000000
75.860001,66.799149,-132.998047,0.009916,0.004322,0.109782,297.137451,15.136904,1.097820,-132.998047,0.109999,0.000000
76.110001,66.264786,-132.998047,0.009929,0.004321,0.109765,294.760498,15.015815,1.097646,-132.998047,0.109782,0.000000
76.360001,65.707718,-132.953568,0.009925,0.004321,0.109748,292.282532,14.889582,1.097476,-132.953568,0.109782,0.000000
76.610001,65.241135,-132.998047,0.009934,0.004320,0.109739,290.207062,14.783853,1.097389,-132.998047,0.109782,0.000000
76.860001,64.809189,-133.042526,0.009951,0.004320,0.109721,288.285675,14.685972,1.097215,-133.042526,0.109782,0.000000
77.110001,64.449112,-133.042526,0.009938,0.004320,0.109721,286.683960,14.604378,1.097215,-133.042526,0.109782,0.000000
77.360001,64.083435,-132.998047,0.009938,0.004319,0.109713,285.057343,14.521514,1.097128,-132.998047,0.109782,0.000000
77.610001,63.794098,-133.087006,0.009955,0.004319,0.109713,283.770325,14.455950,1.097128,-133.087006,0.109782,0.000000
77.860001,63.524506,-133.087006,0.009947,0.004319,0.109713,282.571106,14.394859,1.097128,-133.087006,0.109782,0.000000
78.110001,63.235916,-133.042526,0.009964,0.004319,0.109713,281.287415,14.329463,1.097128,-133.042526,0.109782,0.000000
78.360001,63.004303,-133.042526,0.009955,0.004319,0.109713,280.257141,14.276979,1.097128,-133.042526,0.109782,0.000000
78.610001,62.781990,-133.087006,0.009977,0.004319,0.109704,279.268250,14.226603,1.097040,-133.087006,0.109782,0.000000
78.860001,62.588364,-133.087006,0.009964,0.004319,0.109704,278.406952,14.182726,1.097040,-133.087006,0.109782,0.000000
79.110001,62.384300,-133.131485,0.009973,0.004319,0.109704,277.499237,14.136484,1.097040,-133.131485,0.109782,0.000000
79.360001,62.217850,-133.087006,0.009960,0.004319,0.109704,276.758820,14.098766,1.097040,-133.087006,0.109782,0.000000
79.610001,62.031288,-133.087006,0.009985,0.004319,0.109704,275.928955,14.056491,1.097040,-133.087006,0.109782,0.000000
79.860001,61.884949,-133.131485,0.009955,0.004319,0.109704,275.278015,14.023330,1.097040,-133.131485,0.109782,0.000000
80.110001,61.730415,-133.131485,0.009968,0.004319,0.109704,274.590607,13.988312,1.097040,-133.131485,0.109782,0.000000
80.360001,61.597473,-133.175964,0.009955,0.004319,0.109704,273.999237,13.958187,1.097040,-133.175964,0.109782,0.000000
80.610001,61.462677,-133.175964,0.009960,0.004319,0.109704,273.399628,13.927642,1.097040,-133.175964,0.109782,0.000000
80.860001,61.326019,-133.131485,0.009981,0.004319,0.109704,272.791748,13.896674,1.097040,-133.131485,0.109782,0.000000
81.110001,61.221756,-133.131485,0.009973,0.004319,0.109704,272.327972,13.873048,1.097040,-133.131485,0.109782,0.000000
81.360001,61.100357,-133.087006,0.009981,0.004319,0.109704,271.787964,13.845539,1.097040,-133.087006,0.109782,0.000000
81.610001,60.988647,-133.175964,0.009973,0.004319,0.109704,271.291046,13.820226,1.097040,-133.175964,0.109782,0.000000
81.860001,60.889969,-133.131485,0.009960,0.004319,0.109704,270.852112,13.797864,1.097040,-133.131485,0.109782,0.000000
82.110001,60.787941,-133.220444,0.009977,0.004319,0.109704,270.398254,13.774744,1.097040,-133.220444,0.109782,0.000000
82.360001,60.698196,-133.175964,0.009960,0.004319,0.109704,269.999054,13.754408,1.097040,-133.175964,0.109782,0.000000
82.610001,60.592445,-133.264923,0.009990,0.004319,0.109704,269.528656,13.730444,1.097040,-133.264923,0.109782,0.000000
82.860001,60.503822,-133.220444,0.009973,0.004319,0.109704,269.134430,13.710361,1.097040,-133.220444,0.109782,0.000000
83.110001,60.422272,-133.220444,0.009985,0.004319,0.109704,268.771698,13.691883,1.097040,-133.220444,0.109782,0.000000
83.360001,60.326569,-133.220444,0.009990,0.004319,0.109704,268.345978,13.670196,1.097040,-133.220444,0.109782,0.000000
83.610001,60.251350,-133.264923,0.009981,0.004319,0.109704,268.011383,13.653151,1.097040,-133.264923,0.109782,0.000000
83.860001,60.180969,-133.264923,0.009981,0.004319,0.109704,267.698334,13.637203,1.097040,-133.264923,0.109782,0.000000
84.110001,60.104263,-133.264923,0.009985,0.004319,0.109704,267.357117,13.619822,1.097040,-133.264923,0.109782,0.000000
84.360001,60.036865,-133.220444,0.009981,0.004319,0.109704,267.057312,13.604548,1.097040,-133.220444,0.109782,0.000000
84.610001,59.956429,-133.264923,0.009977,0.004319,0.109704,266.699524,13.586321,1.097040,-133.264923,0.109782,0.000000
84.860001,59.896851,-133.264923,0.009981,0.004319,0.109704,266.434509,13.572821,1.097040,-133.264923,0.109782,0.000000
85.110001,59.834663,-133.264923,0.009981,0.004319,0.109704,266.157867,13.558729,1.097040,-133.264923,0.109782,0.000000
85.360001,59.769127,-133.264923,0.009981,0.004319,0.109704,265.866364,13.543878,1.097040,-133.264923,0.109782,0.000000
85.610001,59.701729,-133.309418,0.009990,0.004319,0.109704,265.566559,13.528605,1.097040,-133.309418,0.109782,0.000000
85.860001,59.637306,-133.353897,0.009968,0.004319,0.109704,265.279999,13.514007,1.097040,-133.353897,0.109782,0.000000
86.110001,59.575119,-133.353897,0.009981,0.004319,0.109704,265.003357,13.499914,1.097040,-133.353897,0.109782,0.000000
86.360001,59.527832,-133.264923,0.009994,0.004319,0.109704,264.793030,13.489199,1.097040,-133.264923,0.109782,0.000000
86.610001,59.459686,-133.309418,0.010003,0.004319,0.109704,264.489899,13.473758,1.097040,-133.309418,0.109782,0.000000
86.860001,59.419846,-133.353897,0.009994,0.004319,0.109704,264.312683,13.464729,1.097040,-133.353897,0.109782,0.000000
87.110001,59.358398,-133.353897,0.010007,0.004319,0.109704,264.039337,13.450806,1.097040,-133.353897,0.109782,0.000000
87.360001,59.296959,-133.309418,0.009981,0.004319,0.109704,263.766052,13.436883,1.097040,-133.309418,0.109782,0.000000
87.610001,59.248924,-133.398376,0.009985,0.004319,0.109704,263.552368,13.425998,1.097040,-133.398376,0.109782,0.000000
87.860001,59.207214,-133.353897,0.009977,0.004319,0.109704,263.366852,13.416547,1.097040,-133.353897,0.109782,0.000000
88.110001,59.159927,-133.309418,0.009994,0.004319,0.109704,263.156494,13.405831,1.097040,-133.309418,0.109782,0.000000
88.360001,59.114128,-133.442856,0.009985,0.004319,0.109695,262.952789,13.395452,1.096953,-133.442856,0.109782,0.000000
88.610001,59.061249,-133.353897,0.009990,0.004319,0.109695,262.717560,13.383471,1.096953,-133.353897,0.109782,0.000000
88.860001,59.029968,-133.442856,0.010016,0.004319,0.109695,262.578400,13.376382,1.096953,-133.442856,0.109782,0.000000
89.110001,58.962570,-133.398376,0.010003,0.004319,0.109695,262.278625,13.361109,1.096953,-133.398376,0.109782,0.000000
89.360001,58.927193,-133.398376,0.009998,0.004319,0.109695,262.121246,13.353093,1.096953,-133.398376,0.109782,0.000000
89.610001,58.903358,-133.442856,0.010011,0.004319,0.109695,262.015228,13.347692,1.096953,-133.442856,0.109782,0.000000
89.860001,58.842667,-133.398376,0.009985,0.004319,0.109695,261.745239,13.333940,1.096953,-133.398376,0.109782,0.000000
90.110001,58.800957,-133.442856,0.009973,0.004319,0.109695,261.559723,13.324487,1.096953,-133.442856,0.109782,0.000000
90.360001,58.748085,-133.442856,0.010007,0.004319,0.109695,261.324524,13.312506,1.096953,-133.442856,0.109782,0.000000
90.610001,58.701164,-133.487335,0.009994,0.004319,0.109695,261.115814,13.301874,1.096953,-133.487335,0.109782,0.000000
90.860001,58.672867,-133.487335,0.009998,0.004319,0.109695,260.989960,13.295462,1.096953,-133.487335,0.109782,0.000000
91.110001,58.644188,-133.487335,0.009973,0.004319,0.109695,260.862366,13.288963,1.096953,-133.487335,0.109782,0.000000
91.360001,58.589081,-133.487335,0.009985,0.004319,0.109695,260.617249,13.276476,1.096953,-133.487335,0.109782,0.000000
91.610001,58.560776,-133.487335,0.009990,0.004319,0.109695,260.491333,13.270061,1.096953,-133.487335,0.109782,0.000000
91.860001,58.520187,-133.487335,0.010003,0.004319,0.109695,260.310791,13.260863,1.096953,-133.487335,0.109782,0.000000
92.110001,58.491142,-133.487335,0.009998,0.004319,0.109695,260.181610,13.254283,1.096953,-133.487335,0.109782,0.000000
92.360001,58.450554,-133.487335,0.010003,0.004319,0.109695,260.001038,13.245086,1.096953,-133.487335,0.109782,0.000000
92.610001,58.434547,-133.531815,0.010003,0.004319,0.109695,259.929840,13.241457,1.096953,-133.531815,0.109782,0.000000
92.860001,58.380554,-133.487335,0.009994,0.004319,0.109695,259.689667,13.229222,1.096953,-133.487335,0.109782,0.000000
93.110001,58.346664,-133.576294,0.009994,0.004319,0.109695,259.538940,13.221543,1.096953,-133.576294,0.109782,0.000000
93.360008,58.319481,-133.576294,0.009994,0.004319,0.109695,259.417999,13.215384,1.096953,-133.576294,0.109782,0.000000
93.610008,58.284851,-133.531815,0.009998,0.004319,0.109695,259.263977,13.207536,1.096953,-133.531815,0.109782,0.000000
93.860008,58.250969,-133.576294,0.010003,0.004319,0.109695,259.113251,13.199859,1.096953,-133.576294,0.109782,0.000000
94.110008,58.222290,-133.531815,0.010024,0.004319,0.109695,258.985687,13.193359,1.096953,-133.531815,0.109782,0.000000
94.360008,58.211494,-133.576294,0.009990,0.004319,0.109695,258.937653,13.190913,1.096953,-133.576294,0.109782,0.000000
94.610008,58.163086,-133.576294,0.010003,0.004319,0.109695,258.722321,13.179944,1.096953,-133.576294,0.109782,0.000000
94.860008,58.131065,-133.576294,0.010007,0.004319,0.109695,258.579895,13.172688,1.096953,-133.576294,0.109782,0.000000
95.110008,58.113564,-133.576294,0.009985,0.004319,0.109695,258.502045,13.168722,1.096953,-133.576294,0.109782,0.000000
95.360008,58.076324,-133.620773,0.010016,0.004319,0.109695,258.336395,13.160283,1.096953,-133.620773,0.109782,0.000000
95.610008,58.027168,-133.576294,0.009998,0.004319,0.109695,258.117737,13.149144,1.096953,-133.576294,0.109782,0.000000
95.860008,58.020470,-133.576294,0.010003,0.004319,0.109695,258.087952,13.147627,1.096953,-133.576294,0.109782,0.000000
96.110008,57.980247,-133.620773,0.009990,0.004319,0.109695,257.909027,13.138512,1.096953,-133.620773,0.109782,0.000000
96.360008,57.963493,-133.620773,0.009981,0.004319,0.109695,257.834503,13.134715,1.096953,-133.620773,0.109782,0.000000
96.610008,57.917320,-133.665253,0.010003,0.004319,0.109695,257.629120,13.124252,1.096953,-133.665253,0.109782,0.000000
96.860008,57.903915,-133.576294,0.009998,0.004319,0.109695,257.569489,13.121215,1.096953,-133.576294,0.109782,0.000000
97.110008,57.882317,-133.709732,0.010007,0.004319,0.109695,257.473389,13.116321,1.096953,-133.709732,0.109782,0.000000
97.360008,57.845078,-133.620773,0.010011,0.004319,0.109695,257.307770,13.107882,1.096953,-133.620773,0.109782,0.000000
97.610008,57.826088,-133.665253,0.009994,0.004319,0.109695,257.223297,13.103580,1.096953,-133.665253,0.109782,0.000000
97.860008,57.796669,-133.665253,0.010011,0.004319,0.109695,257.092438,13.096913,1.096953,-133.665253,0.109782,0.000000
98.110008,57.766884,-133.665253,0.010011,0.004319,0.109695,256.959930,13.090163,1.096953,-133.665253,0.109782,0.000000
98.360008,57.755341,-133.665253,0.009990,0.004319,0.109695,256.908600,13.087547,1.096953,-133.665253,0.109782,0.000000
98.610008,57.713631,-133.709732,0.010007,0.004319,0.109695,256.723053,13.078096,1.096953,-133.709732,0.109782,0.000000
98.860008,57.703575,-133.754227,0.010003,0.004319,0.109695,256.678314,13.075817,1.096953,-133.754227,0.109782,0.000000
99.110008,57.676392,-133.709732,0.010011,0.004319,0.109695,256.557404,13.069656,1.096953,-133.709732,0.109782,0.000000
99.360008,57.652939,-133.709732,0.009994,0.004319,0.109695,256.453094,13.064343,1.096953,-133.709732,0.109782,0.000000
99.610008,57.615700,-133.709732,0.010011,0.004319,0.109695,256.287445,13.055903,1.096953,-133.709732,0.109782,0.000000
99.860008,57.596336,-133.709732,0.010003,0.004319,0.109695,256.201294,13.051517,1.096953,-133.709732,0.109782,0.000000
100.110008,57.586281,-133.798706,0.010007,0.004319,0.109695,256.156586,13.049237,1.096953,-133.798706,0.109782,0.000000
100.360008,57.545319,-133.709732,0.010003,0.004319,0.109695,255.974365,13.039956,1.096953,-133.709732,0.109782,0.000000
100.610008,57.524841,-133.754227,0.009994,0.004319,0.109695,255.883270,13.035316,1.096953,-133.754227,0.109782,0.000000
100.860008,57.504730,-133.798706,0.010007,0.004319,0.109695,255.793808,13.030759,1.096953,-133.798706,0.109782,0.000000
101.110008,57.483131,-133.798706,0.009994,0.004319,0.109695,255.697739,13.025864,1.096953,-133.798706,0.109782,0.000000
101.360008,57.462280,-133.798706,0.010003,0.004319,0.109695,255.604996,13.021139,1.096953,-133.798706,0.109782,0.000000
101.610008,57.443665,-133.798706,0.010003,0.004319,0.109695,255.522186,13.016920,1.096953,-133.798706,0.109782,0.000000
101.860008,57.420204,-133.798706,0.010029,0.004319,0.109695,255.417831,13.011603,1.096953,-133.798706,0.109782,0.000000
102.110008,57.393761,-133.798706,0.010011,0.004319,0.109695,255.300201,13.005612,1.096953,-133.798706,0.109782,0.000000
102.360008,57.370674,-133.798706,0.010016,0.004319,0.109695,255.197510,13.000381,1.096953,-133.798706,0.109782,0.000000
102.610008,57.360626,-133.754227,0.010011,0.004319,0.109695,255.152802,12.998103,1.096953,-133.754227,0.109782,0.000000
102.860008,57.336792,-133.843185,0.010011,0.004319,0.109695,255.046783,12.992702,1.096953,-133.843185,0.109782,0.000000
103.110008,57.322639,-133.843185,0.010003,0.004319,0.109695,254.983841,12.989496,1.096953,-133.843185,0.109782,0.000000
103.360008,57.297691,-133.843185,0.009994,0.004319,0.109695,254.872864,12.983842,1.096953,-133.843185,0.109782,0.000000
103.610008,57.287636,-133.932144,0.010011,0.004319,0.109695,254.828125,12.981564,1.096953,-133.932144,0.109782,0.000000
103.860008,57.249657,-133.798706,0.010024,0.004319,0.109695,254.659195,12.972958,1.096953,-133.798706,0.109782,0.000000
104.110008,57.241837,-133.932144,0.009998,0.004319,0.109695,254.624405,12.971186,1.096953,-133.932144,0.109782,0.000000
104.360008,57.214279,-133.843185,0.009998,0.004319,0.109695,254.501831,12.964941,1.096953,-133.843185,0.109782,0.000000
104.610008,57.215767,-133.887665,0.010011,0.004319,0.109695,254.508438,12.965278,1.096953,-133.887665,0.109782,0.000000
104.860008,57.165871,-133.887665,0.010016,0.004319,0.109695,254.286499,12.953972,1.096953,-133.887665,0.109782,0.000000
105.110008,57.173317,-133.887665,0.009998,0.004319,0.109695,254.319611,12.955659,1.096953,-133.887665,0.109782,0.000000
105.360008,57.133476,-133.932144,0.010029,0.004319,0.109695,254.142395,12.946630,1.096953,-133.932144,0.109782,0.000000
105.610008,57.134964,-133.843185,0.010007,0.004319,0.109695,254.149017,12.946968,1.096953,-133.843185,0.109782,0.000000
105.860008,57.103317,-133.976624,0.010020,0.004319,0.109695,254.008240,12.939796,1.096953,-133.976624,0.109782,0.000000
106.100006,57.094376,-133.932144,0.010003,0.004319,0.109695,253.968460,12.937770,1.096953,-133.932144,0.109782,0.000000