File: Data/Automembrane/AutoHeating-12wt-1-3_12152023_175002.csv
Time (sec),S:Load (lbs),S:HL1 (DIM),S:LVDT (in),S:Position (in),Ch:Position (mm),Ch:Load (N),Ch:Stress (MPa),Ch:Strain (mm/mm),Ch:HL1 (DIM),Set Point (),Cycles ()
0.110000,-0.002228,-231.078537,-0.000026,-0.000000,-0.000000,-0.009910,-0.000505,-0.000000,-231.078537,0.000269,0.000000
0.360000,-0.003349,-231.167496,-0.000009,0.000002,0.000044,-0.014898,-0.000759,0.000435,-231.167496,0.000616,0.000000
0.610000,-0.043564,-231.123016,-0.000004,0.000148,0.003764,-0.193782,-0.009872,0.037637,-231.123016,0.004778,0.000000
0.860000,-0.021591,-231.123016,0.000155,0.000310,0.007866,-0.096042,-0.004893,0.078658,-231.123016,0.008941,0.000000
1.110000,-0.074844,-231.078537,0.000285,0.000472,0.011994,-0.332924,-0.016960,0.119940,-231.078537,0.013121,0.000000
1.360000,-0.002975,-231.078537,0.000483,0.000637,0.016191,-0.013236,-0.000674,0.161910,-231.078537,0.017284,0.000000
1.610000,0.011177,-231.078537,0.000664,0.000797,0.020250,0.049718,0.002533,0.202499,-231.078537,0.021446,0.000000
1.860000,-0.000000,-231.123016,0.000828,0.000971,0.024655,-0.000000,-0.000000,0.246552,-231.123016,0.025609,0.000000
2.110000,-0.021965,-231.123016,0.000983,0.001127,0.028636,-0.097705,-0.004977,0.286358,-231.123016,0.029772,0.000000
2.360000,-0.002228,-231.167496,0.001186,0.001293,0.032851,-0.009910,-0.000505,0.328506,-231.167496,0.033935,0.000000
2.610000,-0.001488,-231.167496,0.001332,0.001455,0.036953,-0.006618,-0.000337,0.369527,-231.167496,0.038097,0.000000
2.860000,-0.049149,-231.167496,0.001544,0.001620,0.041141,-0.218624,-0.011137,0.411411,-231.167496,0.042260,0.000000
3.110000,-0.018616,-231.123016,0.001712,0.001789,0.045434,-0.082807,-0.004218,0.454339,-231.123016,0.046440,0.000000
3.360000,0.001495,-231.167496,0.001832,0.001942,0.049336,0.006652,0.000339,0.493365,-231.167496,0.050603,0.000000
3.610000,-0.003349,-231.167496,0.002048,0.002114,0.053690,-0.014898,-0.000759,0.536899,-231.167496,0.054765,0.000000
3.860000,-0.031647,-231.211990,0.002199,0.002278,0.057861,-0.140772,-0.007171,0.578612,-231.211990,0.058928,0.000000
4.110000,0.007820,-231.167496,0.002380,0.002440,0.061981,0.034786,0.001772,0.619807,-231.167496,0.063091,0.000000
4.360000,0.008194,-231.167496,0.002531,0.002605,0.066161,0.036449,0.001857,0.661607,-231.167496,0.067253,0.000000
4.610000,-0.006699,-231.211990,0.002725,0.002767,0.070289,-0.029797,-0.001518,0.702885,-231.211990,0.071416,0.000000
4.860000,-0.008934,-231.256470,0.002880,0.002932,0.074469,-0.039741,-0.002024,0.744686,-231.256470,0.075596,0.000000
5.110000,-0.000000,-231.167496,0.003048,0.003096,0.078632,-0.000000,-0.000000,0.786316,-231.167496,0.079759,0.000000
5.360000,-0.013031,-231.211990,0.003221,0.003261,0.082837,-0.057965,-0.002953,0.828373,-231.211990,0.083921,0.000000
5.610000,0.005219,-231.211990,0.003385,0.003426,0.087017,0.023213,0.001183,0.870174,-231.211990,0.088084,0.000000
5.860000,0.121025,-231.256470,0.003596,0.003586,0.091076,0.538346,0.027425,0.910759,-231.256470,0.092247,0.000000
6.110000,0.245399,-231.211990,0.003760,0.003754,0.095360,1.091591,0.055608,0.953601,-231.211990,0.096410,0.000000
6.360000,0.409241,-231.211990,0.003889,0.003916,0.099471,1.820394,0.092735,0.994708,-231.211990,0.100572,0.000000
6.610000,0.572708,-231.256470,0.004018,-0.000003,-0.000087,2.547533,0.129778,-0.000867,-231.256470,0.000121,0.000000
6.860000,0.497124,-231.300949,0.004044,-0.000004,-0.000095,2.211317,0.112650,-0.000954,-231.300949,0.000121,0.000000
7.110000,0.467331,-231.256470,0.004014,-0.000003,-0.000087,2.078792,0.105899,-0.000867,-231.256470,0.000234,0.000000
7.360000,0.432327,-231.300949,0.004010,-0.000003,-0.000087,1.923088,0.097967,-0.000867,-231.300949,0.000650,0.000000
7.610000,0.444244,-231.300949,0.004023,-0.000003,-0.000087,1.976098,0.100667,-0.000867,-231.300949,0.001067,0.000000
7.860001,0.566383,-231.300949,0.004036,0.000024,0.000598,2.519399,0.128344,0.005984,-231.300949,0.001483,0.000000
8.110001,0.626335,-231.211990,0.004057,0.000037,0.000945,2.786078,0.141930,0.009451,-231.211990,0.001899,0.000000
8.360001,0.735809,-231.300949,0.004074,0.000061,0.001543,3.273043,0.166737,0.015435,-231.300949,0.002324,0.000000
8.610001,0.769325,-231.256470,0.004066,0.000073,0.001847,3.422130,0.174332,0.018470,-231.256470,0.002740,0.000000
8.860001,0.811775,-231.300949,0.004070,0.000087,0.002212,3.610956,0.183951,0.022115,-231.300949,0.003157,0.000000
9.110001,0.880661,-231.345428,0.004143,0.000106,0.002688,3.917376,0.199561,0.026884,-231.345428,0.003573,0.000000
9.360001,0.948807,-231.300949,0.004130,0.000124,0.003157,4.220503,0.215003,0.031566,-231.300949,0.003989,0.000000
9.610001,0.971153,-231.345428,0.004156,0.000138,0.003504,4.319905,0.220066,0.035037,-231.345428,0.004406,0.000000
9.860001,1.027382,-231.345428,0.004178,0.000154,0.003911,4.570023,0.232808,0.039113,-231.345428,0.004822,0.000000
10.110001,1.024399,-231.389908,0.004178,0.000165,0.004197,4.556754,0.232132,0.041974,-231.389908,0.005238,0.000000
10.360001,1.200531,-231.345428,0.004182,0.000186,0.004717,5.340229,0.272044,0.047175,-231.345428,0.005654,0.000000
10.610001,1.223618,-231.345428,0.004191,0.000202,0.005134,5.442923,0.277276,0.051338,-231.345428,0.006071,0.000000
10.860001,1.370705,-231.300949,0.004230,0.000218,0.005541,6.097199,0.310606,0.055415,-231.300949,0.006487,0.000000
11.110001,1.439224,-231.389908,0.004230,0.000239,0.006071,6.401989,0.326133,0.060706,-231.389908,0.006903,0.000000
11.360001,1.499176,-231.345428,0.004238,0.000254,0.006461,6.668668,0.339718,0.064608,-231.345428,0.007319,0.000000
11.610001,1.530083,-231.434387,0.004286,0.000271,0.006877,6.806148,0.346722,0.068772,-231.434387,0.007736,0.000000
11.860001,1.589287,-231.389908,0.004281,0.000284,0.007224,7.069501,0.360138,0.072239,-231.389908,0.008152,0.000000
12.110001,1.682755,-231.434387,0.004316,0.000300,0.007623,7.485266,0.381318,0.076228,-231.434387,0.008568,0.000000
12.360001,1.799683,-231.434387,0.004320,0.000319,0.008108,8.005388,0.407814,0.081084,-231.434387,0.008985,0.000000
12.610001,1.762070,-231.434387,0.004350,0.000328,0.008343,7.838078,0.399291,0.083427,-231.434387,0.009401,0.000000
12.860001,1.973206,-231.389908,0.004333,0.000353,0.008976,8.777257,0.447135,0.089759,-231.389908,0.009817,0.000000
13.110001,2.019379,-231.434387,0.004359,0.000369,0.009384,8.982645,0.457598,0.093835,-231.434387,0.010233,0.000000
13.360001,2.034645,-231.478867,0.004376,0.000383,0.009739,9.050553,0.461057,0.097389,-231.478867,0.010650,0.000000
13.610001,2.079704,-231.478867,0.004411,0.000399,0.010138,9.250987,0.471268,0.101378,-231.478867,0.011075,0.000000
13.860001,2.171310,-231.478867,0.004406,0.000417,0.010597,9.658471,0.492026,0.105973,-231.478867,0.011491,0.000000
14.110001,2.313553,-231.478867,0.004415,0.000435,0.011040,10.291197,0.524259,0.110398,-231.478867,0.011907,0.000000
14.360001,2.334778,-231.478867,0.004432,0.000449,0.011404,10.385611,0.529068,0.114039,-231.478867,0.012323,0.000000
14.610001,2.349304,-231.478867,0.004454,0.000462,0.011742,10.450227,0.532360,0.117423,-231.478867,0.012740,0.000000
14.860001,2.517982,-231.523346,0.004501,0.000481,0.012228,11.200545,0.570583,0.122279,-231.523346,0.013156,0.000000
15.110001,2.667679,-231.434387,0.004488,0.000502,0.012757,11.866428,0.604505,0.127570,-231.434387,0.013572,0.000000
15.360001,2.654274,-231.478867,0.004514,0.000514,0.013061,11.806801,0.601467,0.130605,-231.478867,0.013988,0.000000
15.610001,2.743645,-231.523346,0.004523,0.000531,0.013485,12.204341,0.621719,0.134852,-231.523346,0.014405,0.000000
15.860001,2.897064,-231.523346,0.004536,0.000551,0.013997,12.886786,0.656484,0.139969,-231.523346,0.014821,0.000000
16.110001,2.993507,-231.478867,0.004544,0.000568,0.014431,13.315786,0.678338,0.144307,-231.478867,0.015237,0.000000
16.360001,2.906746,-231.567825,0.004562,0.000575,0.014613,12.929852,0.658678,0.146127,-231.567825,0.015653,0.000000
16.610001,3.105217,-231.478867,0.004579,0.000593,0.015072,13.812695,0.703652,0.150722,-231.478867,0.016070,0.000000
16.860001,3.317841,-231.523346,0.004643,0.000615,0.015619,14.758492,0.751833,0.156187,-231.523346,0.016486,0.000000
17.110001,3.317467,-231.612305,0.004609,0.000631,0.016018,14.756829,0.751749,0.160177,-231.612305,0.016902,0.000000
17.360001,3.385986,-231.478867,0.004648,0.000644,0.016356,15.061620,0.767275,0.163557,-231.478867,0.017319,0.000000
17.610001,3.511101,-231.612305,0.004678,0.000664,0.016876,15.618156,0.795627,0.168761,-231.612305,0.017735,0.000000
17.860001,3.624680,-231.523346,0.004652,0.000681,0.017292,16.123381,0.821364,0.172924,-231.523346,0.018151,0.000000
18.110001,3.719635,-231.523346,0.004678,0.000695,0.017657,16.545763,0.842881,0.176565,-231.523346,0.018567,0.000000
18.360001,3.711441,-231.523346,0.004695,0.000707,0.017951,16.509314,0.841025,0.179514,-231.523346,0.018984,0.000000
18.610001,3.774368,-231.612305,0.004700,0.000720,0.018298,16.789228,0.855284,0.182985,-231.612305,0.019409,0.000000
18.860001,4.219353,-231.523346,0.004751,0.000749,0.019035,18.768618,0.956119,0.190354,-231.523346,0.019825,0.000000
19.110001,4.198875,-231.612305,0.004751,0.000762,0.019365,18.677530,0.951479,0.193650,-231.612305,0.020241,0.000000
19.360001,4.200363,-231.612305,0.004764,0.000781,0.019833,18.684149,0.951816,0.198332,-231.612305,0.020657,0.000000
19.610001,4.224937,-231.656799,0.004760,0.000793,0.020137,18.793461,0.957384,0.201368,-231.656799,0.021074,0.000000
19.860001,4.503105,-231.656799,0.004786,0.000814,0.020683,20.030811,1.020418,0.206833,-231.656799,0.021490,0.000000
20.110001,4.533638,-231.612305,0.004803,0.000827,0.021013,20.166630,1.027337,0.210130,-231.612305,0.021906,0.000000
20.360001,4.528427,-231.701279,0.004820,0.000840,0.021325,20.143450,1.026156,0.213249,-231.701279,0.022322,0.000000
20.610001,4.558960,-231.701279,0.004842,0.000852,0.021646,20.279266,1.033075,0.216458,-231.701279,0.022739,0.000000
20.860001,4.947716,-231.612305,0.004838,0.000877,0.022279,22.008539,1.121168,0.222790,-231.612305,0.023155,0.000000
21.110001,4.953300,-231.656799,0.004846,0.000892,0.022661,22.033381,1.122434,0.226605,-231.656799,0.023571,0.000000
21.360001,4.941757,-231.656799,0.004876,0.000906,0.023025,21.982035,1.119818,0.230247,-231.656799,0.023988,0.000000
21.610001,5.168907,-231.701279,0.004907,0.000927,0.023554,22.992447,1.171291,0.235538,-231.701279,0.024403,0.000000
21.860001,5.295143,-231.701279,0.004915,0.000946,0.024039,23.553972,1.199897,0.240394,-231.701279,0.024820,0.000000
22.110001,5.224762,-231.745758,0.004919,0.000957,0.024308,23.240902,1.183948,0.243081,-231.745758,0.025236,0.000000
22.360001,5.323441,-231.656799,0.004919,0.000973,0.024707,23.679846,1.206309,0.247070,-231.656799,0.025653,0.000000
22.610001,5.619850,-231.656799,0.004932,0.000995,0.025262,24.998343,1.273476,0.252623,-231.656799,0.026069,0.000000
22.860001,5.629906,-231.745758,0.004950,0.001010,0.025653,25.043072,1.275755,0.256525,-231.745758,0.026485,0.000000
23.110001,5.625435,-231.701279,0.004984,0.001025,0.026043,25.023184,1.274742,0.260427,-231.701279,0.026901,0.000000
23.360001,5.685387,-231.745758,0.005006,0.001043,0.026485,25.289864,1.288327,0.264852,-231.745758,0.027317,0.000000
23.610001,5.810501,-231.745758,0.005027,0.001058,0.026875,25.846399,1.316678,0.268754,-231.745758,0.027743,0.000000
23.860001,5.920723,-231.745758,0.005019,0.001076,0.027335,26.336691,1.341655,0.273349,-231.745758,0.028159,0.000000
24.110001,5.973602,-231.701279,0.005036,0.001091,0.027708,26.571911,1.353638,0.277077,-231.701279,0.028575,0.000000
24.360001,5.836571,-231.745758,0.005036,0.001100,0.027933,25.962364,1.322586,0.279333,-231.745758,0.028991,0.000000
24.610001,6.089035,-231.745758,0.005036,0.001121,0.028471,27.085381,1.379795,0.284711,-231.745758,0.029407,0.000000
24.860001,6.322891,-231.745758,0.005088,0.001144,0.029061,28.125626,1.432788,0.290608,-231.745758,0.029824,0.000000
25.110001,6.182503,-231.834717,0.005113,0.001158,0.029425,27.501146,1.400975,0.294249,-231.834717,0.030240,0.000000
25.360001,6.227936,-231.745758,0.005109,0.001173,0.029798,27.703241,1.411270,0.297977,-231.745758,0.030657,0.000000
25.610001,6.313576,-231.790237,0.005118,0.001191,0.030258,28.084188,1.430677,0.302576,-231.790237,0.031072,0.000000
25.860001,6.399597,-231.745758,0.005139,0.001208,0.030674,28.466829,1.450169,0.306735,-231.745758,0.031489,0.000000
26.110001,6.390289,-231.834717,0.005152,0.001220,0.030977,28.425426,1.448060,0.309771,-231.834717,0.031905,0.000000
26.360001,6.499023,-231.879196,0.005165,0.001237,0.031420,28.909100,1.472700,0.314195,-231.879196,0.032321,0.000000
26.610001,6.549660,-231.834717,0.005161,0.001253,0.031818,29.134342,1.484174,0.318185,-231.834717,0.032738,0.000000
26.860001,6.716110,-231.834717,0.005191,0.001274,0.032356,29.874750,1.521892,0.323563,-231.834717,0.033154,0.000000
27.110001,6.659515,-231.834717,0.005208,0.001289,0.032747,29.623003,1.509068,0.327465,-231.834717,0.033570,0.000000
27.360001,6.630096,-231.834717,0.005213,0.001302,0.033076,29.492142,1.502401,0.330758,-231.834717,0.033986,0.000000
27.610001,6.781281,-231.834717,0.005243,0.001320,0.033527,30.164642,1.536660,0.335270,-231.834717,0.034403,0.000000
27.860001,6.819260,-231.790237,0.005238,0.001336,0.033943,30.333582,1.545266,0.339433,-231.790237,0.034819,0.000000
28.110001,6.745155,-231.879196,0.005256,0.001351,0.034307,30.003950,1.528474,0.343074,-231.879196,0.035235,0.000000
28.360001,6.665840,-231.879196,0.005282,0.001364,0.034637,29.651138,1.510501,0.346371,-231.879196,0.035651,0.000000
28.610001,7.029648,-231.834717,0.005307,0.001386,0.035209,31.269436,1.592941,0.352094,-231.834717,0.036068,0.000000
28.860001,6.865433,-231.879196,0.005295,0.001401,0.035573,30.538971,1.555729,0.355735,-231.879196,0.036493,0.000000
29.110001,6.984222,-231.879196,0.005320,0.001419,0.036050,31.067373,1.582647,0.360504,-231.879196,0.036909,0.000000
29.360001,6.915329,-232.012634,0.005312,0.001432,0.036380,30.760920,1.567036,0.363800,-232.012634,0.037325,0.000000
29.610001,7.119392,-231.923676,0.005351,0.001453,0.036900,31.668638,1.613277,0.369005,-231.923676,0.037741,0.000000
29.860001,7.020714,-231.968155,0.005381,0.001466,0.037247,31.229694,1.590917,0.372472,-231.968155,0.038158,0.000000
30.110001,6.956665,-231.968155,0.005359,0.001481,0.037629,30.944792,1.576403,0.376290,-231.968155,0.038574,0.000000
30.360001,7.251213,-231.923676,0.005372,0.001502,0.038158,32.255005,1.643148,0.381578,-231.923676,0.038990,0.000000
30.610001,7.199821,-231.923676,0.005381,0.001518,0.038557,32.026405,1.631503,0.385567,-231.923676,0.039407,0.000000
30.860001,7.117157,-231.968155,0.005424,0.001532,0.038904,31.658695,1.612771,0.389038,-231.968155,0.039823,0.000000
31.110001,7.145828,-231.968155,0.005415,0.001548,0.039311,31.786232,1.619268,0.393114,-231.968155,0.040239,0.000000
31.360001,7.001724,-231.968155,0.005407,0.001559,0.039598,31.145226,1.586613,0.395976,-231.968155,0.040655,0.000000
31.610001,7.332390,-231.968155,0.005437,0.001582,0.040187,32.616100,1.661543,0.401873,-231.968155,0.041072,0.000000
31.860001,7.295525,-231.968155,0.005480,0.001596,0.040534,32.452114,1.653190,0.405340,-231.968155,0.041488,0.000000
32.110001,6.983101,-232.012634,0.005454,0.001603,0.040716,31.062384,1.582393,0.407160,-232.012634,0.041904,0.000000
32.360001,7.443359,-232.012634,0.005506,0.001631,0.041418,33.109715,1.686689,0.414185,-232.012634,0.042320,0.000000
32.610001,7.495491,-232.057129,0.005489,0.001650,0.041913,33.341610,1.698503,0.419128,-232.057129,0.042737,0.000000
32.860001,7.387497,-231.968155,0.005510,0.001665,0.042295,32.861229,1.674031,0.422947,-231.968155,0.043153,0.000000
33.110001,7.297012,-231.968155,0.005527,0.001679,0.042659,32.458733,1.653527,0.426588,-231.968155,0.043569,0.000000
33.360001,7.271690,-231.968155,0.005527,0.001694,0.043023,32.346096,1.647789,0.430229,-231.968155,0.043986,0.000000
33.610001,7.556183,-232.057129,0.005558,0.001714,0.043535,33.611580,1.712255,0.435346,-232.057129,0.044402,0.000000
33.860001,7.414680,-232.012634,0.005575,0.001727,0.043864,32.982147,1.680191,0.438643,-232.012634,0.044827,0.000000
34.110001,7.503311,-232.012634,0.005545,0.001746,0.044341,33.376396,1.700275,0.443412,-232.012634,0.045243,0.000000
34.360001,7.560654,-232.057129,0.005601,0.001764,0.044818,33.631466,1.713269,0.448181,-232.057129,0.045659,0.000000
34.610001,7.440002,-232.012634,0.005605,0.001777,0.045148,33.094784,1.685929,0.451477,-232.012634,0.046076,0.000000
34.860001,7.507034,-232.101608,0.005618,0.001795,0.045599,33.392956,1.701118,0.455985,-232.101608,0.046492,0.000000
35.110001,7.568848,-232.101608,0.005614,0.001812,0.046015,33.667915,1.715125,0.460149,-232.101608,0.046908,0.000000
35.360001,7.688751,-232.057129,0.005657,0.001831,0.046518,34.201275,1.742296,0.465179,-232.057129,0.047324,0.000000
35.610001,7.547623,-232.057129,0.005648,0.001845,0.046865,33.573502,1.710316,0.468649,-232.057129,0.047741,0.000000
35.860001,7.441864,-232.101608,0.005661,0.001856,0.047151,33.103065,1.686350,0.471511,-232.101608,0.048157,0.000000
36.110001,7.608315,-232.057129,0.005661,0.001877,0.047672,33.843472,1.724069,0.476715,-232.057129,0.048573,0.000000
36.360001,7.780724,-232.146088,0.005704,0.001896,0.048166,34.610386,1.763137,0.481658,-232.146088,0.048989,0.000000
36.610001,7.629173,-232.057129,0.005726,0.001910,0.048513,33.936256,1.728795,0.485125,-232.057129,0.049406,0.000000
36.860001,7.674599,-232.146088,0.005721,0.001927,0.048938,34.138321,1.739089,0.489376,-232.146088,0.049822,0.000000
37.110001,7.617996,-232.146088,0.005713,0.001941,0.049302,33.886539,1.726263,0.493017,-232.146088,0.050238,0.000000
37.360001,7.890579,-232.190567,0.005739,0.001962,0.049831,35.099049,1.788031,0.498308,-232.190567,0.050655,0.000000
37.610001,7.585228,-232.190567,0.005752,0.001969,0.050022,33.740780,1.718837,0.500216,-232.190567,0.051071,0.000000
37.860001,7.578529,-232.235046,0.005777,0.001984,0.050394,33.710983,1.717319,0.503944,-232.235046,0.051487,0.000000
38.110001,7.892807,-232.146088,0.005795,0.002007,0.050967,35.108959,1.788536,0.509666,-232.146088,0.051903,0.000000
38.360001,7.920738,-232.190567,0.005799,0.002024,0.051400,35.233204,1.794865,0.514004,-232.190567,0.052320,0.000000
38.610001,7.951645,-232.190567,0.005803,0.002042,0.051869,35.370682,1.801869,0.518686,-232.190567,0.052736,0.000000
38.860001,7.881638,-232.146088,0.005803,0.002057,0.052259,35.059277,1.786005,0.522588,-232.146088,0.053161,0.000000
39.110001,7.927437,-232.190567,0.005833,0.002073,0.052649,35.263000,1.796383,0.526494,-232.190567,0.053577,0.000000
39.360001,7.960579,-232.190567,0.005833,0.002089,0.053065,35.410423,1.803893,0.530654,-232.190567,0.053993,0.000000
39.610001,7.876053,-232.235046,0.005859,0.002104,0.053439,35.034431,1.784739,0.534386,-232.235046,0.054410,0.000000
39.860001,7.904724,-232.235046,0.005868,0.002117,0.053759,35.161968,1.791236,0.537591,-232.235046,0.054826,0.000000
40.110001,7.880150,-232.235046,0.005881,0.002132,0.054158,35.052658,1.785668,0.541581,-232.235046,0.055242,0.000000
40.360001,8.296837,-232.235046,0.005920,0.002159,0.054835,36.906174,1.880090,0.548348,-232.235046,0.055658,0.000000
40.610001,8.157196,-232.235046,0.005915,0.002173,0.055190,36.285019,1.848447,0.551902,-232.235046,0.056075,0.000000
40.860001,8.117348,-232.235046,0.005902,0.002189,0.055598,36.107765,1.839417,0.555978,-232.235046,0.056491,0.000000
41.110001,8.186241,-232.235046,0.005933,0.002208,0.056075,36.414219,1.855029,0.560747,-232.235046,0.056907,0.000000
41.360001,8.137459,-232.235046,0.005963,0.002222,0.056448,36.197224,1.843974,0.564475,-232.235046,0.057324,0.000000
41.610001,8.167252,-232.235046,0.005946,0.002236,0.056803,36.329750,1.850726,0.568033,-232.235046,0.057740,0.000000
41.860001,8.028725,-232.324005,0.005967,0.002248,0.057098,35.713551,1.819335,0.570982,-232.324005,0.058156,0.000000
42.110001,8.446526,-232.279526,0.005993,0.002271,0.057688,37.572021,1.914010,0.576879,-232.279526,0.058572,0.000000
42.360001,8.367958,-232.235046,0.006002,0.002288,0.058113,37.222538,1.896206,0.581129,-232.235046,0.058989,0.000000
42.610001,8.269653,-232.279526,0.006019,0.002301,0.058451,36.785255,1.873930,0.584509,-232.279526,0.059405,0.000000
42.860001,8.479294,-232.279526,0.006027,0.002321,0.058963,37.717781,1.921435,0.589626,-232.279526,0.059821,0.000000
43.110001,8.579834,-232.324005,0.006049,0.002339,0.059422,38.165009,1.944218,0.594221,-232.324005,0.060237,0.000000
43.360001,8.437965,-232.279526,0.006045,0.002355,0.059812,37.533943,1.912070,0.598123,-232.279526,0.060654,0.000000
43.610001,8.345245,-232.324005,0.006084,0.002367,0.060133,37.121506,1.891060,0.601333,-232.324005,0.061070,0.000000
43.860001,8.520630,-232.368484,0.006088,0.002388,0.060645,37.901653,1.930802,0.606450,-232.368484,0.061486,0.000000
44.110001,8.593987,-232.368484,0.006092,0.002404,0.061061,38.227962,1.947425,0.610613,-232.368484,0.061911,0.000000
44.360001,8.592125,-232.368484,0.006122,0.002420,0.061478,38.219681,1.947003,0.614777,-232.368484,0.062327,0.000000
44.610001,8.606277,-232.324005,0.006109,0.002437,0.061902,38.282635,1.950210,0.619023,-232.324005,0.062744,0.000000
44.860001,8.494560,-232.368484,0.006140,0.002451,0.062258,37.785690,1.924895,0.622581,-232.368484,0.063160,0.000000
45.110001,8.748894,-232.324005,0.006153,0.002472,0.062779,38.917023,1.982528,0.627785,-232.324005,0.063576,0.000000
45.360001,8.644630,-232.412964,0.006170,0.002487,0.063160,38.453236,1.958901,0.631601,-232.412964,0.063992,0.000000
45.610001,8.484138,-232.412964,0.006183,0.002495,0.063386,37.739334,1.922533,0.633856,-232.412964,0.064409,0.000000
45.860001,8.561966,-232.412964,0.006170,0.002512,0.063802,38.085526,1.940169,0.638016,-232.412964,0.064825,0.000000
46.110001,9.084404,-232.368484,0.006183,0.002537,0.064444,40.409447,2.058555,0.644435,-232.368484,0.065241,0.000000
46.360001,8.868423,-232.412964,0.006217,0.002553,0.064834,39.448719,2.009614,0.648337,-232.412964,0.065658,0.000000
46.610001,8.831192,-232.412964,0.006234,0.002567,0.065198,39.283104,2.001177,0.651978,-232.412964,0.066074,0.000000
46.860001,8.733627,-232.412964,0.006247,0.002580,0.065528,38.849113,1.979068,0.655275,-232.412964,0.066490,0.000000
47.110001,9.061684,-232.412964,0.006252,0.002601,0.066074,40.308384,2.053407,0.660740,-232.412964,0.066906,0.000000
47.360001,8.925774,-232.412964,0.006269,0.002616,0.066447,39.703823,2.022609,0.664469,-232.412964,0.067323,0.000000
47.610001,8.705330,-232.457443,0.006269,0.002625,0.066672,38.723240,1.972656,0.666724,-232.457443,0.067739,0.000000
47.860001,9.165581,-232.412964,0.006303,0.002648,0.067262,40.770538,2.076950,0.672621,-232.412964,0.068155,0.000000
48.110001,9.178238,-232.457443,0.006303,0.002666,0.067704,40.826839,2.079818,0.677042,-232.457443,0.068571,0.000000
48.360001,9.095947,-232.457443,0.006325,0.002683,0.068155,40.460793,2.061171,0.681554,-232.457443,0.068988,0.000000
48.610001,9.098549,-232.457443,0.006316,0.002697,0.068493,40.472366,2.061761,0.684934,-232.457443,0.069404,0.000000
48.860001,9.079933,-232.457443,0.006364,0.002714,0.068936,40.389561,2.057542,0.689358,-232.457443,0.069820,0.000000
49.110001,9.058708,-232.457443,0.006355,0.002728,0.069300,40.295147,2.052733,0.692999,-232.457443,0.070245,0.000000
49.360001,9.206543,-232.501938,0.006368,0.002745,0.069725,40.952747,2.086232,0.697250,-232.501938,0.070661,0.000000
49.610001,9.178612,-232.412964,0.006368,0.002758,0.070055,40.828503,2.079903,0.700546,-232.412964,0.071078,0.000000
49.860001,9.632164,-232.457443,0.006394,0.002783,0.070679,42.846004,2.182679,0.706788,-232.457443,0.071494,0.000000
50.110001,9.536087,-232.457443,0.006411,0.002796,0.071026,42.418633,2.160908,0.710258,-232.457443,0.071910,0.000000
50.360001,9.557312,-232.546417,0.006411,0.002814,0.071477,42.513046,2.165718,0.714766,-232.546417,0.072327,0.000000
50.610001,9.626205,-232.546417,0.006411,0.002829,0.071867,42.819500,2.181329,0.718668,-232.546417,0.072743,0.000000
50.860001,9.769569,-232.457443,0.006437,0.002848,0.072344,43.457214,2.213816,0.723437,-232.457443,0.073159,0.000000
51.110001,9.704399,-232.546417,0.006441,0.002863,0.072717,43.167324,2.199048,0.727169,-232.546417,0.073575,0.000000
51.360001,9.534599,-232.546417,0.006463,0.002873,0.072977,42.412014,2.160571,0.729769,-232.546417,0.073992,0.000000
51.610001,10.098000,-232.546417,0.006489,0.002899,0.073636,44.918144,2.288239,0.736363,-232.546417,0.074408,0.000000
51.860001,9.832123,-232.590897,0.006489,0.002910,0.073914,43.735466,2.227991,0.739137,-232.590897,0.074824,0.000000
52.110001,9.960968,-232.546417,0.006506,0.002927,0.074338,44.308598,2.257188,0.743384,-232.546417,0.075240,0.000000
52.360001,10.098373,-232.546417,0.006510,0.002944,0.074772,44.919807,2.288324,0.747721,-232.546417,0.075657,0.000000
52.610001,9.972885,-232.546417,0.006536,0.002955,0.075067,44.361610,2.259888,0.750670,-232.546417,0.076073,0.000000
52.860001,10.272270,-232.546417,0.006528,0.002974,0.075535,45.693340,2.327730,0.755351,-232.546417,0.076489,0.000000
53.110004,10.374298,-232.546417,0.006562,0.002990,0.075951,46.147182,2.350849,0.759515,-232.546417,0.076906,0.000000
53.360004,10.173965,-232.590897,0.006584,0.003000,0.076194,45.256058,2.305454,0.761945,-232.590897,0.077322,0.000000
53.610004,10.901955,-232.635376,0.006558,0.003026,0.076862,48.494316,2.470418,0.768621,-232.635376,0.077738,0.000000
53.860004,11.018501,-232.590897,0.006592,0.003044,0.077322,49.012741,2.496828,0.773216,-232.590897,0.078154,0.000000
54.110004,10.871414,-232.635376,0.006592,0.003060,0.077712,48.358467,2.463498,0.777122,-232.635376,0.078579,0.000000
54.360004,10.851311,-232.679855,0.006635,0.003074,0.078076,48.269039,2.458942,0.780763,-232.679855,0.078996,0.000000
54.610004,10.701241,-232.590897,0.006622,0.003084,0.078345,47.601494,2.424936,0.783451,-232.590897,0.079412,0.000000
54.860004,11.273949,-232.635376,0.006622,0.003106,0.078900,50.149029,2.554713,0.789003,-232.635376,0.079828,0.000000
55.110004,11.303368,-232.635376,0.006657,0.003122,0.079291,50.279892,2.561380,0.792905,-232.635376,0.080244,0.000000
55.360004,11.419548,-232.590897,0.006657,0.003137,0.079689,50.796688,2.587707,0.796894,-232.590897,0.080661,0.000000
55.610004,11.714470,-232.635376,0.006674,0.003158,0.080209,52.108566,2.654537,0.802095,-232.635376,0.081077,0.000000
55.860004,11.934914,-232.590897,0.006674,0.003174,0.080626,53.089146,2.704490,0.806258,-232.590897,0.081493,0.000000
56.110004,12.001198,-232.679855,0.006696,0.003191,0.081042,53.383995,2.719510,0.810422,-232.679855,0.081909,0.000000
56.360004,11.932678,-232.590897,0.006713,0.003203,0.081354,53.079205,2.703984,0.813544,-232.590897,0.082326,0.000000
56.610004,12.410057,-232.724335,0.006730,0.003225,0.081927,55.202690,2.812159,0.819267,-232.724335,0.082742,0.000000
56.860004,12.381012,-232.679855,0.006726,0.003238,0.082256,55.073490,2.805577,0.822564,-232.679855,0.083158,0.000000
57.110004,12.486397,-232.724335,0.006765,0.003252,0.082594,55.542267,2.829458,0.825944,-232.724335,0.083575,0.000000
57.360004,12.807755,-232.768814,0.006752,0.003270,0.083054,56.971737,2.902279,0.830542,-232.768814,0.083991,0.000000
57.610004,13.224068,-232.724335,0.006756,0.003289,0.083531,58.823589,2.996617,0.835311,-232.724335,0.084407,0.000000
57.860004,13.326096,-232.768814,0.006799,0.003304,0.083921,59.277435,3.019737,0.839213,-232.768814,0.084823,0.000000
58.110004,13.322746,-232.768814,0.006799,0.003320,0.084320,59.262535,3.018977,0.843203,-232.768814,0.085240,0.000000
58.360004,13.696976,-232.724335,0.006808,0.003336,0.084728,60.927193,3.103779,0.847279,-232.724335,0.085656,0.000000
58.610004,14.226120,-232.768814,0.006825,0.003357,0.085257,63.280941,3.223685,0.852570,-232.768814,0.086072,0.000000
58.860004,14.180321,-232.724335,0.006834,0.003369,0.085561,63.077217,3.213306,0.855606,-232.724335,0.086488,0.000000
59.110004,13.925613,-232.724335,0.006855,0.003378,0.085812,61.944221,3.155589,0.858119,-232.724335,0.086905,0.000000
59.360004,14.659561,-232.768814,0.006873,0.003400,0.086358,65.208984,3.321904,0.863584,-232.768814,0.087330,0.000000
59.610004,15.144760,-232.813293,0.006851,0.003420,0.086861,67.367256,3.431852,0.868614,-232.813293,0.087746,0.000000
59.860004,15.192429,-232.768814,0.006890,0.003431,0.087148,67.579300,3.442654,0.871476,-232.768814,0.088162,0.000000
60.110004,15.488838,-232.813293,0.006898,0.003451,0.087659,68.897797,3.509821,0.876593,-232.813293,0.088578,0.000000
60.360004,15.637787,-232.813293,0.006924,0.003464,0.087980,69.560349,3.543573,0.879799,-232.813293,0.088995,0.000000
60.610004,16.208633,-232.768814,0.006929,0.003484,0.088483,72.099602,3.672929,0.884829,-232.768814,0.089411,0.000000
60.860004,16.349388,-232.768814,0.006946,0.003497,0.088821,72.725708,3.704824,0.888213,-232.768814,0.089827,0.000000
61.110004,16.736656,-232.813293,0.006924,0.003514,0.089255,74.448364,3.792581,0.892546,-232.813293,0.090244,0.000000
61.360004,16.306190,-232.857773,0.006954,0.003522,0.089454,72.533554,3.695035,0.894541,-232.857773,0.090660,0.000000
61.610004,18.187050,-232.768814,0.006976,0.003553,0.090252,80.900040,4.121244,0.902520,-232.768814,0.091076,0.000000
61.860004,17.981873,-232.857773,0.007011,0.003568,0.090625,79.987366,4.074750,0.906251,-232.857773,0.091492,0.000000
62.110004,18.485313,-232.902252,0.007006,0.003584,0.091024,82.226784,4.188832,0.910241,-232.902252,0.091909,0.000000
62.360004,18.769066,-232.813293,0.007019,0.003599,0.091423,83.488976,4.253131,0.914230,-232.813293,0.092325,0.000000
62.610004,19.233788,-232.857773,0.007045,0.003617,0.091865,85.556160,4.358438,0.918651,-232.857773,0.092741,0.000000
62.860004,19.427788,-232.857773,0.007054,0.003630,0.092203,86.419113,4.402400,0.922035,-232.857773,0.093157,0.000000
63.110004,19.761436,-232.902252,0.007084,0.003644,0.092550,87.903259,4.478005,0.925501,-232.902252,0.093574,0.000000
63.360004,20.486076,-232.857773,0.007084,0.003664,0.093053,91.126617,4.642211,0.930532,-232.857773,0.093990,0.000000
63.610004,21.203636,-232.946747,0.007084,0.003682,0.093530,94.318481,4.804813,0.935301,-232.946747,0.094406,0.000000
63.860004,21.546967,-232.946747,0.007127,0.003697,0.093912,95.845695,4.882613,0.939120,-232.946747,0.094822,0.000000
64.110001,21.844116,-232.902252,0.007114,0.003712,0.094276,97.167480,4.949948,0.942761,-232.902252,0.095239,0.000000
64.360001,22.804092,-232.902252,0.007148,0.003735,0.094857,101.437668,5.167481,0.948570,-232.902252,0.095664,0.000000
64.610001,23.365257,-232.902252,0.007127,0.003750,0.095239,103.933853,5.294643,0.952386,-232.902252,0.096080,0.000000
64.860001,23.437126,-232.991226,0.007157,0.003763,0.095568,104.253548,5.310929,0.955682,-232.991226,0.096496,0.000000
65.110001,24.126389,-232.902252,0.007183,0.003778,0.095950,107.319534,5.467118,0.959497,-232.902252,0.096912,0.000000
65.360001,25.005928,-232.946747,0.007196,0.003797,0.096444,111.231926,5.666424,0.964440,-232.946747,0.097329,0.000000
65.610001,25.664284,-232.946747,0.007217,0.003816,0.096921,114.160439,5.815609,0.969209,-232.946747,0.097745,0.000000
65.860001,26.220238,-232.991226,0.007230,0.003830,0.097294,116.633446,5.941591,0.972941,-232.991226,0.098161,0.000000
66.110001,26.646233,-232.991226,0.007235,0.003846,0.097693,118.528366,6.038123,0.976931,-232.991226,0.098578,0.000000
66.360001,27.691483,-232.946747,0.007239,0.003866,0.098187,123.177864,6.274980,0.981874,-232.946747,0.098994,0.000000
66.610001,27.968155,-233.035706,0.007256,0.003876,0.098439,124.408569,6.337675,0.984387,-233.035706,0.099410,0.000000
66.860001,28.585175,-232.991226,0.007269,0.003890,0.098803,127.153206,6.477493,0.988028,-232.991226,0.099826,0.000000
67.110001,28.991432,-232.946747,0.007299,0.003904,0.099150,128.960327,6.569552,0.991499,-232.946747,0.100243,0.000000
67.360001,30.792603,-233.035706,0.007291,0.003931,0.099835,136.972336,6.977704,0.998349,-233.035706,0.100659,0.000000
67.610001,31.667305,-233.035706,0.007291,0.003948,0.100269,140.863205,7.175914,1.002687,-233.035706,0.101075,0.000000
67.860001,32.101486,-233.035706,0.007299,0.003960,0.100590,142.794540,7.274301,1.005896,-233.035706,0.101491,0.000000
68.110001,32.825378,-233.035706,0.007343,0.003976,0.100989,146.014572,7.438337,1.009886,-233.035706,0.101908,0.000000
68.360001,34.050110,-232.991226,0.007347,0.003997,0.101517,151.462448,7.715865,1.015173,-232.991226,0.102324,0.000000
68.610001,34.728951,-233.035706,0.007360,0.004010,0.101864,154.482086,7.869693,1.018644,-233.035706,0.102740,0.000000
68.860001,35.130363,-233.035706,0.007394,0.004022,0.102151,156.267654,7.960654,1.021505,-233.035706,0.103157,0.000000
69.110001,36.308182,-232.991226,0.007390,0.004040,0.102627,161.506851,8.227551,1.026274,-232.991226,0.103573,0.000000
69.360001,37.850548,-233.124664,0.007381,0.004061,0.103157,168.367645,8.577057,1.031566,-233.124664,0.103998,0.000000
69.610001,38.661201,-233.035706,0.007411,0.004075,0.103495,171.973618,8.760754,1.034945,-233.035706,0.104414,0.000000
69.860001,39.531067,-233.080185,0.007420,0.004091,0.103911,175.842972,8.957868,1.039109,-233.080185,0.104830,0.000000
70.110001,40.333153,-233.080185,0.007463,0.004105,0.104275,179.410828,9.139623,1.042750,-233.080185,0.105247,0.000000
70.360001,41.522514,-233.080185,0.007455,0.004121,0.104666,184.701370,9.409136,1.046656,-233.080185,0.105663,0.000000
70.610001,42.633301,-233.080185,0.007463,0.004139,0.105134,189.642395,9.660844,1.051338,-233.080185,0.106079,0.000000
70.860001,43.350113,-233.080185,0.007459,0.004152,0.105455,192.830933,9.823277,1.054547,-233.080185,0.106495,0.000000
71.110001,44.937912,-233.124664,0.007489,0.004174,0.106018,199.893814,10.183076,1.060183,-233.124664,0.106912,0.000000
71.360001,45.927681,-233.080185,0.007489,0.004185,0.106287,204.296524,10.407361,1.062870,-233.080185,0.107328,0.000000
71.610001,47.296150,-233.124664,0.007532,0.004204,0.106781,210.383789,10.717461,1.067814,-233.124664,0.107744,0.000000
71.860001,48.476936,-233.169144,0.007541,0.004223,0.107267,215.636185,10.985031,1.072670,-233.169144,0.108160,0.000000
72.110001,49.503571,-233.124664,0.007532,0.004237,0.107614,220.202881,11.217669,1.076140,-233.124664,0.108577,0.000000
72.360001,51.219833,-233.124664,0.007549,0.004256,0.108108,227.837204,11.606581,1.081083,-233.124664,0.108993,0.000000
72.610001,52.092674,-233.124664,0.007558,0.004269,0.108429,231.719788,11.804368,1.084293,-233.124664,0.109409,0.000000
72.860001,52.934982,-233.213623,0.007558,0.004282,0.108759,235.466568,11.995238,1.087586,-233.213623,0.109826,0.000000
73.110001,54.730560,-233.169144,0.007580,0.004301,0.109253,243.453690,12.402122,1.092529,-233.169144,0.110241,0.000000
73.360001,56.134781,-233.213623,0.007601,0.004319,0.109713,249.699982,12.720323,1.097128,-233.213623,0.110658,0.000000
73.610001,57.054169,-233.258102,0.007627,0.004334,0.110086,253.789612,12.928659,1.100856,-233.258102,0.111074,0.000000
73.860001,58.337738,-233.124664,0.007623,0.004350,0.110493,259.499207,13.219521,1.104932,-233.124664,0.111491,0.000000
74.110001,59.081734,-233.213623,0.007627,0.004362,0.110805,262.808685,13.388112,1.108055,-233.213623,0.111907,0.000000
74.360001,61.101112,-233.213623,0.007640,0.004381,0.111274,271.791321,13.845710,1.112736,-233.213623,0.112323,0.000000
74.610001,62.379097,-233.213623,0.007657,0.004398,0.111699,277.476074,14.135305,1.116987,-233.213623,0.112748,0.000000
74.860001,62.478516,-233.213623,0.007649,0.004398,0.111716,277.918304,14.157834,1.117161,-233.213623,0.113164,0.000000
75.110001,65.615387,-233.213623,0.007670,0.004435,0.112652,291.871826,14.868659,1.126525,-233.213623,0.113581,0.000000
75.360001,67.274307,-233.258102,0.007670,0.004453,0.113104,299.251068,15.244576,1.131036,-233.258102,0.113997,0.000000
75.610001,67.164459,-233.258102,0.007670,0.004447,0.112947,298.762451,15.219685,1.129473,-233.258102,0.113129,0.000000
75.860001,66.862091,-233.258102,0.007700,0.004446,0.112939,297.417450,15.151167,1.129386,-233.258102,0.112939,0.000000
76.110001,66.561951,-233.213623,0.007696,0.004446,0.112930,296.082336,15.083153,1.129299,-233.213623,0.112939,0.000000
76.360001,66.338150,-233.302582,0.007718,0.004446,0.112930,295.086823,15.032439,1.129299,-233.302582,0.112939,0.000000
76.610001,66.114731,-233.258102,0.007696,0.004446,0.112930,294.093018,14.981812,1.129299,-233.258102,0.112939,0.000000
76.860001,65.950150,-233.258102,0.007726,0.004446,0.112922,293.360931,14.944517,1.129216,-233.258102,0.112939,0.000000
77.110001,65.740494,-233.302582,0.007726,0.004446,0.112922,292.428314,14.897009,1.129216,-233.302582,0.112939,0.000000
77.360001,65.628784,-233.347076,0.007731,0.004446,0.112922,291.931427,14.871696,1.129216,-233.347076,0.112939,0.000000
77.610001,65.451172,-233.302582,0.007718,0.004446,0.112922,291.141357,14.831448,1.129216,-233.302582,0.112939,0.000000
77.860001,65.359192,-233.391556,0.007722,0.004446,0.112922,290.732208,14.810605,1.129216,-233.391556,0.112939,0.000000
78.110001,65.212097,-233.302582,0.007718,0.004446,0.112922,290.077881,14.777272,1.129216,-233.302582,0.112939,0.000000
78.360001,65.130554,-233.302582,0.007731,0.004446,0.112922,289.715179,14.758794,1.129216,-233.302582,0.112939,0.000000
78.610001,64.996506,-233.347076,0.007726,0.004446,0.112922,289.118896,14.728418,1.129216,-233.347076,0.112939,0.000000
78.860001,64.924255,-233.302582,0.007731,0.004446,0.112922,288.797516,14.712047,1.129216,-233.302582,0.112939,0.000000
79.110001,64.811432,-233.347076,0.007722,0.004446,0.112922,288.295654,14.686480,1.129216,-233.347076,0.112939,0.000000
79.360001,64.752960,-233.347076,0.007726,0.004445,0.112913,288.035553,14.673230,1.129129,-233.347076,0.112939,0.000000
79.610001,64.644241,-233.347076,0.007731,0.004445,0.112913,287.551941,14.648595,1.129129,-233.347076,0.112939,0.000000
79.860001,64.593597,-233.391556,0.007718,0.004445,0.112913,287.326660,14.637119,1.129129,-233.391556,0.112939,0.000000
80.110001,64.494537,-233.347076,0.007731,0.004445,0.112913,286.886017,14.614671,1.129129,-233.347076,0.112939,0.000000
80.360001,64.442780,-233.347076,0.007722,0.004445,0.112913,286.655792,14.602942,1.129129,-233.347076,0.112939,0.000000
80.610001,64.361603,-233.436035,0.007713,0.004445,0.112913,286.294708,14.584548,1.129129,-233.436035,0.112939,0.000000
80.860001,64.313202,-233.436035,0.007722,0.004445,0.112913,286.079407,14.573580,1.129129,-233.436035,0.112939,0.000000
81.110001,64.238724,-233.436035,0.007713,0.004445,0.112913,285.748108,14.556704,1.129129,-233.436035,0.112939,0.000000
81.360001,64.195526,-233.391556,0.007739,0.004445,0.112913,285.555969,14.546914,1.129129,-233.391556,0.112939,0.000000
81.610001,64.119934,-233.480515,0.007743,0.004445,0.112913,285.219727,14.529785,1.129129,-233.480515,0.112939,0.000000
81.860001,64.086792,-233.436035,0.007743,0.004445,0.112913,285.072296,14.522274,1.129129,-233.436035,0.112939,0.000000
82.110001,64.004868,-233.480515,0.007739,0.004445,0.112913,284.707855,14.503710,1.129129,-233.480515,0.112939,0.000000
82.360001,63.987366,-233.480515,0.007731,0.004445,0.112913,284.630005,14.499744,1.129129,-233.480515,0.112939,0.000000
82.610001,63.919220,-233.480515,0.007739,0.004445,0.112913,284.326904,14.484303,1.129129,-233.480515,0.112939,0.000000
82.860001,63.881622,-233.436035,0.007726,0.004445,0.112913,284.159637,14.475782,1.129129,-233.436035,0.112939,0.000000
83.110001,63.817566,-233.480515,0.007748,0.004445,0.112913,283.874725,14.461267,1.129129,-233.480515,0.112939,0.000000
83.360001,63.796341,-233.524994,0.007726,0.004445,0.112913,283.780304,14.456458,1.129129,-233.524994,0.112939,0.000000
83.610001,63.739746,-233.524994,0.007722,0.004445,0.112913,283.528564,14.443632,1.129129,-233.524994,0.112939,0.000000
83.860001,63.711075,-233.569473,0.007739,0.004445,0.112913,283.401001,14.437136,1.129129,-233.569473,0.112939,0.000000
84.110001,63.657455,-233.569473,0.007739,0.004445,0.112913,283.162506,14.424985,1.129129,-233.569473,0.112939,0.000000
84.360001,63.619095,-233.480515,0.007731,0.004445,0.112913,282.991882,14.416293,1.129129,-233.480515,0.112939,0.000000
84.610001,63.581863,-233.524994,0.007752,0.004445,0.112913,282.826263,14.407856,1.129129,-233.524994,0.112939,0.000000
84.860001,63.531586,-233.524994,0.007731,0.004445,0.112913,282.602600,14.396463,1.129129,-233.524994,0.112939,0.000000
85.110001,63.524506,-233.524994,0.007713,0.004445,0.112913,282.571106,14.394859,1.129129,-233.524994,0.112939,0.000000
85.360001,63.476471,-233.524994,0.007739,0.004445,0.112913,282.357452,14.383974,1.129129,-233.524994,0.112939,0.000000
85.610001,63.448547,-233.524994,0.007731,0.004445,0.112913,282.233246,14.377646,1.129129,-233.524994,0.112939,0.000000
85.860001,63.407593,-233.569473,0.007735,0.004445,0.112913,282.051056,14.368366,1.129129,-233.569473,0.112939,0.000000
86.110001,63.393066,-233.613953,0.007739,0.004445,0.112913,281.986450,14.365074,1.129129,-233.613953,0.112939,0.000000
86.360001,63.345779,-233.613953,0.007743,0.004445,0.112913,281.776093,14.354359,1.129129,-233.613953,0.112939,0.000000
86.610001,63.328278,-233.613953,0.007713,0.004445,0.112913,281.698242,14.350392,1.129129,-233.613953,0.112939,0.000000
86.860001,63.274277,-233.613953,0.007752,0.004445,0.112913,281.458038,14.338156,1.129129,-233.613953,0.112939,0.000000
87.110001,63.275391,-233.613953,0.007769,0.004445,0.112913,281.462982,14.338408,1.129129,-233.613953,0.112939,0.000000
87.360001,63.231461,-233.613953,0.007743,0.004445,0.112913,281.267578,14.328454,1.129129,-233.613953,0.112939,0.000000
87.610001,63.219910,-233.613953,0.007756,0.004445,0.112913,281.216217,14.325836,1.129129,-233.613953,0.112939,0.000000
87.860001,63.168900,-233.702911,0.007743,0.004445,0.112913,280.989288,14.314277,1.129129,-233.702911,0.112939,0.000000
88.110001,63.169266,-233.747391,0.007743,0.004445,0.112913,280.990936,14.314361,1.129129,-233.747391,0.112939,0.000000
88.360001,63.123840,-233.658432,0.007769,0.004445,0.112913,280.788879,14.304067,1.129129,-233.658432,0.112939,0.000000
88.610001,63.116013,-233.658432,0.007739,0.004445,0.112913,280.754059,14.302293,1.129129,-233.658432,0.112939,0.000000
88.860001,63.076920,-233.702911,0.007756,0.004445,0.112913,280.580139,14.293434,1.129129,-233.702911,0.112939,0.000000
89.110001,63.058304,-233.613953,0.007752,0.004445,0.112913,280.497345,14.289216,1.129129,-233.613953,0.112939,0.000000
89.360001,63.026276,-233.702911,0.007756,0.004445,0.112913,280.354889,14.281958,1.129129,-233.702911,0.112939,0.000000
89.610001,63.008034,-233.702911,0.007756,0.004445,0.112913,280.273743,14.277824,1.129129,-233.702911,0.112939,0.000000
89.860001,62.990158,-233.658432,0.007743,0.004445,0.112913,280.194214,14.273773,1.129129,-233.658432,0.112939,0.000000
90.110001,62.974892,-233.747391,0.007756,0.004445,0.112913,280.126312,14.270315,1.129129,-233.747391,0.112939,0.000000
90.360001,62.933182,-233.702911,0.007748,0.004445,0.112913,279.940765,14.260863,1.129129,-233.702911,0.112939,0.000000
90.610001,62.925735,-233.702911,0.007739,0.004445,0.112913,279.907654,14.259175,1.129129,-233.702911,0.112939,0.000000
90.860001,62.880310,-233.747391,0.007752,0.004445,0.112913,279.705597,14.248881,1.129129,-233.747391,0.112939,0.000000
91.110001,62.869881,-233.747391,0.007743,0.004445,0.112913,279.659210,14.246518,1.129129,-233.747391,0.112939,0.000000
91.360001,62.847908,-233.747391,0.007743,0.004445,0.112913,279.561462,14.241540,1.129129,-233.747391,0.112939,0.000000
91.610001,62.835991,-233.791885,0.007713,0.004445,0.112913,279.508453,14.238839,1.129129,-233.791885,0.112939,0.000000
91.860001,62.811043,-233.747391,0.007739,0.004445,0.112913,279.397461,14.233186,1.129129,-233.747391,0.112939,0.000000
92.110001,62.798759,-233.791885,0.007769,0.004445,0.112913,279.342834,14.230402,1.129129,-233.791885,0.112939,0.000000
92.360001,62.772316,-233.791885,0.007718,0.004445,0.112913,279.225220,14.224410,1.129129,-233.791885,0.112939,0.000000
92.610001,62.764870,-233.747391,0.007722,0.004445,0.112913,279.192078,14.222723,1.129129,-233.747391,0.112939,0.000000
92.860001,62.730614,-233.791885,0.007731,0.004445,0.112913,279.039703,14.214960,1.129129,-233.791885,0.112939,0.000000
93.110001,62.728752,-233.747391,0.007735,0.004445,0.112913,279.031433,14.214539,1.129129,-233.747391,0.112939,0.000000
93.360008,62.688904,-233.747391,0.007748,0.004445,0.112913,278.854156,14.205508,1.129129,-233.747391,0.112939,0.000000
93.610008,62.685928,-233.791885,0.007743,0.004445,0.112913,278.840942,14.204834,1.129129,-233.791885,0.112939,0.000000
93.860008,62.666565,-233.791885,0.007735,0.004445,0.112913,278.754791,14.200446,1.129129,-233.791885,0.112939,0.000000
94.110008,62.641617,-233.791885,0.007739,0.004445,0.112913,278.643829,14.194794,1.129129,-233.791885,0.112939,0.000000
94.360008,62.624489,-233.836365,0.007756,0.004445,0.112913,278.567627,14.190912,1.129129,-233.836365,0.112939,0.000000
94.610008,62.615547,-233.836365,0.007735,0.004445,0.112913,278.527863,14.188886,1.129129,-233.836365,0.112939,0.000000
94.860008,62.595070,-233.836365,0.007748,0.004445,0.112913,278.436768,14.184246,1.129129,-233.836365,0.112939,0.000000
95.110008,62.580544,-233.836365,0.007743,0.004445,0.112913,278.372162,14.180954,1.129129,-233.836365,0.112939,0.000000
95.360008,62.577568,-233.836365,0.007735,0.004445,0.112913,278.358917,14.180280,1.129129,-233.836365,0.112939,0.000000
95.610008,62.546661,-233.836365,0.007722,0.004445,0.112913,278.221436,14.173277,1.129129,-233.836365,0.112939,0.000000
95.860008,62.529160,-233.880844,0.007743,0.004445,0.112913,278.143585,14.169311,1.129129,-233.880844,0.112939,0.000000
96.110008,62.521713,-233.925323,0.007726,0.004445,0.112913,278.110474,14.167623,1.129129,-233.925323,0.112939,0.000000
96.360008,62.497879,-233.880844,0.007739,0.004445,0.112913,278.004456,14.162222,1.129129,-233.880844,0.112939,0.000000
96.610008,62.483727,-233.836365,0.007761,0.004445,0.112913,277.941498,14.159015,1.129129,-233.836365,0.112939,0.000000
96.860008,62.468834,-233.836365,0.007748,0.004445,0.112913,277.875244,14.155640,1.129129,-233.836365,0.112939,0.000000
97.110008,62.464363,-233.925323,0.007731,0.004445,0.112913,277.855377,14.154627,1.129129,-233.925323,0.112939,0.000000
97.360008,62.434204,-233.925323,0.007769,0.004445,0.112913,277.721222,14.147793,1.129129,-233.925323,0.112939,0.000000
97.610008,62.433456,-233.880844,0.007765,0.004445,0.112913,277.717896,14.147624,1.129129,-233.880844,0.112939,0.000000
97.860008,62.421173,-233.880844,0.007761,0.004445,0.112913,277.663239,14.144840,1.129129,-233.880844,0.112939,0.000000
98.110008,62.414841,-233.925323,0.007718,0.004445,0.112913,277.635071,14.143405,1.129129,-233.925323,0.112939,0.000000
98.360008,62.388031,-233.925323,0.007765,0.004445,0.112913,277.515808,14.137330,1.129129,-233.925323,0.112939,0.000000
98.610008,62.382820,-233.925323,0.007735,0.004445,0.112913,277.492645,14.136149,1.129129,-233.925323,0.112939,0.000000
98.860008,62.362335,-233.969803,0.007739,0.004445,0.112913,277.401520,14.131507,1.129129,-233.969803,0.112939,0.000000
99.110008,62.360100,-233.925323,0.007756,0.004445,0.112913,277.391571,14.131001,1.129129,-233.925323,0.112939,0.000000
99.360008,62.319511,-233.880844,0.007761,0.004445,0.112913,277.211029,14.121803,1.129129,-233.880844,0.112939,0.000000
99.610008,62.335152,-233.969803,0.007743,0.004445,0.112913,277.280609,14.125347,1.129129,-233.969803,0.112939,0.000000
99.860008,62.306854,-233.969803,0.007726,0.004445,0.112913,277.154724,14.118935,1.129129,-233.969803,0.112939,0.000000
100.110008,62.319885,-233.925323,0.007739,0.004445,0.112913,277.212708,14.121888,1.129129,-233.925323,0.112939,0.000000
100.360008,62.297173,-233.969803,0.007743,0.004445,0.112913,277.111664,14.116740,1.129129,-233.969803,0.112939,0.000000
100.610008,62.282646,-233.969803,0.007748,0.004445,0.112913,277.047058,14.113449,1.129129,-233.969803,0.112939,0.000000
100.860008,62.263657,-233.969803,0.007765,0.004445,0.112913,276.962585,14.109147,1.129129,-233.969803,0.112939,0.000000
101.110008,62.260307,-234.014282,0.007769,0.004445,0.112913,276.947693,14.108388,1.129129,-234.014282,0.112939,0.000000
101.360008,62.256210,-234.014282,0.007756,0.004445,0.112913,276.929443,14.107459,1.129129,-234.014282,0.112939,0.000000
101.610008,62.229401,-234.014282,0.007769,0.004445,0.112913,276.810211,14.101383,1.129129,-234.014282,0.112939,0.000000
101.860008,62.242432,-234.058762,0.007756,0.004445,0.112913,276.868164,14.104337,1.129129,-234.058762,0.112939,0.000000
102.110008,62.221207,-234.014282,0.007752,0.004445,0.112913,276.773743,14.099527,1.129129,-234.014282,0.112939,0.000000
102.360008,62.218971,-234.014282,0.007735,0.004445,0.112913,276.763794,14.099021,1.129129,-234.014282,0.112939,0.000000
102.610008,62.186577,-234.058762,0.007748,0.004445,0.112913,276.619720,14.091680,1.129129,-234.058762,0.112939,0.000000
102.860008,62.194397,-234.014282,0.007739,0.004445,0.112913,276.654480,14.093451,1.129129,-234.014282,0.112939,0.000000
103.110008,62.171684,-234.103241,0.007748,0.004445,0.112913,276.553467,14.088305,1.129129,-234.103241,0.112939,0.000000
103.360008,62.167587,-234.058762,0.007748,0.004445,0.112913,276.535248,14.087377,1.129129,-234.058762,0.112939,0.000000
103.610008,62.176895,-234.103241,0.007748,0.004445,0.112913,276.576630,14.089485,1.129129,-234.103241,0.112939,0.000000
103.860008,62.147476,-234.058762,0.007743,0.004445,0.112913,276.445770,14.082819,1.129129,-234.058762,0.112939,0.000000
104.110008,62.143005,-234.103241,0.007756,0.004445,0.112913,276.425903,14.081806,1.129129,-234.103241,0.112939,0.000000
104.360008,62.127739,-234.103241,0.007756,0.004445,0.112913,276.357971,14.078347,1.129129,-234.103241,0.112939,0.000000
104.610008,62.118057,-234.103241,0.007748,0.004445,0.112913,276.314911,14.076153,1.129129,-234.103241,0.112939,0.000000
104.860008,62.106148,-234.103241,0.007743,0.004445,0.112913,276.261932,14.073454,1.129129,-234.103241,0.112939,0.000000
105.110008,62.114708,-234.103241,0.007731,0.004445,0.112913,276.300018,14.075394,1.129129,-234.103241,0.112939,0.000000
105.360008,62.090874,-234.103241,0.007739,0.004445,0.112913,276.194000,14.069993,1.129129,-234.103241,0.112939,0.000000
105.610008,62.085663,-234.192200,0.007739,0.004445,0.112913,276.170807,14.068812,1.129129,-234.192200,0.112939,0.000000
105.860008,62.084549,-234.147720,0.007752,0.004445,0.112913,276.165863,14.068560,1.129129,-234.147720,0.112939,0.000000
105.900002,62.066673,-234.103241,0.007748,0.004445,0.112913,276.086365,14.064509,1.129129,-234.103241,0.112939,0.000000