File: Data/10% 30min RT - 1 - 3_07262023_151144.csv
Time (sec),S:Load (lbs),S:HL1 (DIM),S:LVDT (in),S:Position (in),Ch:Position (mm),Ch:Load (N),Ch:Stress (MPa),Ch:Strain (mm/mm),Ch:HL1 (DIM),Set Point (),Cycles ()
0.010000,-0.003724,-15.701776,0.000004,-0.000000,-0.000000,-0.016564,-0.000844,-0.000000,-15.701776,0.000035,0.000000
0.290000,-0.004096,-15.657295,-0.000013,-0.000000,-0.000000,-0.018220,-0.000928,-0.000000,-15.657295,0.000035,0.000000
0.570000,-0.043195,-15.568333,0.000000,0.000129,0.003287,-0.192142,-0.009788,0.032866,-15.568333,0.003902,0.000000
0.850000,-0.001489,-15.612814,-0.000004,0.000296,0.007510,-0.006625,-0.000338,0.075100,-15.612814,0.008568,0.000000
1.130000,0.052132,-15.568333,0.000151,0.000476,0.012080,0.231895,0.011813,0.120804,-15.568333,0.013234,0.000000
1.410000,0.010799,-15.568333,0.000345,0.000660,0.016763,0.048036,0.002447,0.167633,-15.568333,0.017900,0.000000
1.690000,0.039099,-15.479371,0.000522,0.000843,0.021403,0.173922,0.008860,0.214030,-15.479371,0.022565,0.000000
1.970000,0.005586,-15.434890,0.000707,0.001030,0.026173,0.024846,0.001266,0.261727,-15.434890,0.027231,0.000000
2.250000,0.045057,-15.390409,0.000880,0.001211,0.030760,0.200424,0.010210,0.307604,-15.390409,0.031896,0.000000
2.530000,-0.036120,-15.434890,0.001069,0.001397,0.035487,-0.160670,-0.008185,0.354868,-15.434890,0.036562,0.000000
2.810000,0.053249,-15.390409,0.001233,0.001580,0.040127,0.236865,0.012066,0.401265,-15.390409,0.041228,0.000000
3.090000,0.061441,-15.345928,0.001397,0.001764,0.044809,0.273305,0.013923,0.448094,-15.345928,0.045876,0.000000
3.370000,0.034631,-15.301447,0.001604,0.001947,0.049458,0.154045,0.007847,0.494578,-15.301447,0.050542,0.000000
3.650000,0.056973,-15.256967,0.001789,0.002130,0.054098,0.253429,0.012910,0.540975,-15.256967,0.055207,0.000000
3.930000,0.030907,-15.256967,0.001962,0.002318,0.058867,0.137481,0.007004,0.588672,-15.256967,0.059873,0.000000
4.210000,0.041333,-15.256967,0.002147,0.002500,0.063490,0.183860,0.009366,0.634895,-15.256967,0.064539,0.000000
4.490000,-0.005213,-15.168004,0.002337,0.002682,0.068129,-0.023189,-0.001181,0.681292,-15.168004,0.069205,0.000000
4.770000,0.062931,-15.123524,0.002522,0.002867,0.072812,0.279931,0.014260,0.728121,-15.123524,0.073870,0.000000
5.050000,0.037610,-15.123524,0.002699,0.003051,0.077504,0.167296,0.008522,0.775039,-15.123524,0.078536,0.000000
5.330000,0.055856,-15.123524,0.002884,0.003233,0.082126,0.248459,0.012657,0.821262,-15.123524,0.083201,0.000000
5.610000,0.075219,-15.079042,0.003040,0.003418,0.086809,0.334592,0.017045,0.868092,-15.079042,0.087867,0.000000
5.890000,0.065538,-15.034561,0.003242,0.003605,0.091562,0.291526,0.014851,0.915615,-15.034561,0.092533,0.000000
6.170000,0.052877,-14.901118,0.003410,0.003788,0.096210,0.235208,0.011982,0.962099,-14.901118,0.097199,0.000000
6.450000,0.016757,-14.945600,0.003604,0.003963,0.100659,0.074538,0.003797,1.006587,-14.945600,0.101864,0.000000
6.730000,0.032769,-14.901118,0.003803,0.004149,0.105394,0.145763,0.007426,1.053938,-14.901118,0.106530,0.000000
7.010000,-0.002979,-14.901118,0.003980,0.004332,0.110025,-0.013251,-0.000675,1.100248,-14.901118,0.111196,0.000000
7.290000,0.077826,-14.812157,0.004169,0.004512,0.114612,0.346187,0.017636,1.146125,-14.812157,0.115861,0.000000
7.570000,0.014150,-14.767675,0.004376,0.004705,0.119504,0.062943,0.003206,1.195035,-14.767675,0.120527,0.000000
7.850000,0.059580,-14.723195,0.004549,0.004887,0.124117,0.265023,0.013501,1.241173,-14.723195,0.125193,0.000000
8.130000,0.121021,-14.723195,0.004738,0.005072,0.128835,0.538329,0.027424,1.288350,-14.723195,0.129841,0.000000
8.410001,0.407375,-14.723195,0.004902,0.005250,0.133362,1.812097,0.092313,1.333619,-14.723195,0.134507,0.000000
8.690001,0.559676,-14.678714,0.005010,-0.000000,-0.000000,2.489562,0.126824,-0.000000,-14.678714,0.000243,0.000000
8.970000,0.534355,-14.634233,0.005032,-0.000000,-0.000000,2.376928,0.121086,-0.000000,-14.634233,0.000243,0.000000
9.250000,0.548877,-14.545271,0.005032,-0.000000,-0.000000,2.441527,0.124377,-0.000000,-14.545271,0.000529,0.000000
9.530001,0.529514,-14.500790,0.005032,0.000006,0.000156,2.355394,0.119990,0.001561,-14.500790,0.000997,0.000000
9.810000,0.598775,-14.500790,0.005032,0.000022,0.000564,2.663484,0.135684,0.005638,-14.500790,0.001466,0.000000
10.090000,0.665057,-14.456309,0.005014,0.000036,0.000902,2.958322,0.150704,0.009019,-14.456309,0.001925,0.000000
10.370001,0.798739,-14.456309,0.005044,0.000055,0.001396,3.552968,0.180997,0.013962,-14.456309,0.002394,0.000000
10.650001,0.860180,-14.411828,0.005053,0.000072,0.001821,3.826273,0.194920,0.018213,-14.411828,0.002862,0.000000
10.930000,0.932048,-14.411828,0.005083,0.000092,0.002342,4.145958,0.211205,0.023415,-14.411828,0.003330,0.000000
11.210001,1.023652,-14.411828,0.005092,0.000115,0.002914,4.553432,0.231963,0.029140,-14.411828,0.003799,0.000000
11.490001,1.057165,-14.278385,0.005101,0.000129,0.003278,4.702507,0.239557,0.032781,-14.278385,0.004258,0.000000
11.770000,1.129778,-14.233904,0.005122,0.000149,0.003772,5.025504,0.256011,0.037724,-14.233904,0.004726,0.000000
12.050000,1.185261,-14.189424,0.005139,0.000163,0.004145,5.272306,0.268584,0.041454,-14.189424,0.005195,0.000000
12.330001,1.356181,-14.233904,0.005157,0.000186,0.004726,6.032592,0.307315,0.047264,-14.233904,0.005663,0.000000
12.610001,1.412781,-14.144942,0.005157,0.000201,0.005099,6.284364,0.320141,0.050994,-14.144942,0.006131,0.000000
12.890000,1.449274,-14.189424,0.005174,0.000214,0.005446,6.446691,0.328410,0.054463,-14.189424,0.006591,0.000000
13.170001,1.618703,-14.100462,0.005208,0.000241,0.006114,7.200351,0.366803,0.061139,-14.100462,0.007059,0.000000
13.450001,1.674559,-14.055981,0.005226,0.000258,0.006565,7.448811,0.379461,0.065649,-14.055981,0.007528,0.000000
13.730000,1.696157,-13.967019,0.005226,0.000275,0.006973,7.544881,0.384355,0.069725,-13.967019,0.007996,0.000000
14.010000,1.737862,-14.011499,0.005243,0.000289,0.007345,7.730398,0.393805,0.073453,-14.011499,0.008464,0.000000
14.290001,1.946018,-13.967019,0.005260,0.000308,0.007822,8.656322,0.440974,0.078224,-13.967019,0.008933,0.000000
14.570001,2.026079,-13.922538,0.005277,0.000326,0.008282,9.012448,0.459116,0.082821,-13.922538,0.009392,0.000000
14.850000,2.146727,-13.878057,0.005299,0.000348,0.008828,9.549119,0.486455,0.088285,-13.878057,0.009860,0.000000
15.130001,2.268493,-13.833576,0.005320,0.000366,0.009305,10.090761,0.514048,0.093054,-13.833576,0.010329,0.000000
15.410001,2.302751,-13.878057,0.005338,0.000382,0.009713,10.243150,0.521811,0.097130,-13.878057,0.010797,0.000000
15.690001,2.396217,-13.789095,0.005346,0.000401,0.010190,10.658905,0.542991,0.101899,-13.789095,0.011265,0.000000
15.970001,2.458403,-13.744614,0.005368,0.000417,0.010598,10.935523,0.557082,0.105975,-13.744614,0.011725,0.000000
16.250000,2.690763,-13.655652,0.005389,0.000438,0.011135,11.969113,0.609736,0.111352,-13.655652,0.012193,0.000000
16.530001,2.810668,-13.700133,0.005415,0.000458,0.011629,12.502474,0.636906,0.116295,-13.700133,0.012662,0.000000
16.810001,2.837106,-13.611171,0.005411,0.000470,0.011950,12.620077,0.642897,0.119504,-13.611171,0.013130,0.000000
17.090000,3.059412,-13.611171,0.005445,0.000493,0.012523,13.608944,0.693273,0.125227,-13.611171,0.013598,0.000000
17.370001,3.152878,-13.566690,0.005476,0.000516,0.013095,14.024701,0.714452,0.130952,-13.566690,0.014066,0.000000
17.650002,3.156229,-13.522209,0.005480,0.000530,0.013468,14.039608,0.715212,0.134680,-13.522209,0.014526,0.000000
17.930000,3.320445,-13.522209,0.005514,0.000550,0.013980,14.770078,0.752424,0.139797,-13.522209,0.014994,0.000000
18.210001,3.333851,-13.477728,0.005514,0.000564,0.014335,14.829709,0.755461,0.143353,-13.477728,0.015463,0.000000
18.490002,3.482427,-13.477728,0.005527,0.000581,0.014769,15.490609,0.789129,0.147688,-13.477728,0.015931,0.000000
18.770000,3.521526,-13.433248,0.005545,0.000594,0.015081,15.664532,0.797989,0.150811,-13.433248,0.016399,0.000000
19.050001,3.729310,-13.344285,0.005579,0.000619,0.015732,16.588800,0.845074,0.157315,-13.344285,0.016859,0.000000
19.330002,3.820169,-13.344285,0.005596,0.000642,0.016295,16.992960,0.865663,0.162953,-13.344285,0.017327,0.000000
19.610001,3.935605,-13.344285,0.005614,0.000661,0.016790,17.506443,0.891821,0.167896,-13.344285,0.017795,0.000000
19.890001,3.941190,-13.255323,0.005622,0.000677,0.017197,17.531290,0.893086,0.171970,-13.255323,0.018264,0.000000
20.170000,4.118812,-13.210842,0.005657,0.000699,0.017752,18.321388,0.933336,0.177521,-13.210842,0.018732,0.000000
20.450001,4.181370,-13.210842,0.005678,0.000709,0.018012,18.599665,0.947512,0.180123,-13.210842,0.019192,0.000000
20.730001,4.141899,-13.255323,0.005674,0.000725,0.018411,18.424088,0.938568,0.184112,-13.255323,0.019660,0.000000
21.010000,4.487088,-13.166362,0.005721,0.000753,0.019131,19.959566,1.016789,0.191311,-13.166362,0.020128,0.000000
21.290001,4.530283,-13.166362,0.005721,0.000773,0.019634,20.151707,1.026577,0.196340,-13.166362,0.020597,0.000000
21.570002,4.597682,-13.077399,0.005743,0.000790,0.020068,20.451513,1.041850,0.200677,-13.077399,0.021065,0.000000
21.850000,4.692266,-13.032919,0.005786,0.000806,0.020475,20.872240,1.063283,0.204751,-13.032919,0.021533,0.000000
22.130001,4.847545,-13.032919,0.005803,0.000825,0.020961,21.562956,1.098469,0.209609,-13.032919,0.021993,0.000000
22.410002,4.838608,-12.988438,0.005816,0.000839,0.021299,21.523203,1.096444,0.212991,-12.988438,0.022461,0.000000
22.690001,4.954043,-12.943956,0.005808,0.000858,0.021793,22.036684,1.122602,0.217934,-12.943956,0.022929,0.000000
22.970001,5.124590,-12.899476,0.005855,0.000880,0.022340,22.795315,1.161249,0.223398,-12.899476,0.023398,0.000000
23.250002,5.285455,-12.854995,0.005881,0.000902,0.022904,23.510878,1.197701,0.229035,-12.854995,0.023866,0.000000
23.530001,5.270932,-12.854995,0.005902,0.000916,0.023276,23.446278,1.194410,0.232763,-12.854995,0.024326,0.000000
23.810001,5.375569,-12.810513,0.005911,0.000936,0.023762,23.911724,1.218121,0.237619,-12.810513,0.024794,0.000000
24.090002,5.479833,-12.766033,0.005924,0.000954,0.024239,24.375515,1.241748,0.242390,-12.766033,0.025262,0.000000
24.370001,5.480578,-12.721552,0.005954,0.000968,0.024586,24.378828,1.241917,0.245859,-12.721552,0.025731,0.000000
24.650002,5.771400,-12.677071,0.005967,0.000994,0.025236,25.672472,1.307818,0.252364,-12.677071,0.026199,0.000000
24.930000,5.789275,-12.677071,0.006006,0.001011,0.025670,25.751980,1.311868,0.256699,-12.677071,0.026667,0.000000
25.210001,5.858908,-12.632590,0.006028,0.001029,0.026138,26.061726,1.327648,0.261383,-12.632590,0.027127,0.000000
25.490002,5.946043,-12.588109,0.006028,0.001048,0.026615,26.449322,1.347393,0.266152,-12.588109,0.027595,0.000000
25.770000,6.065575,-12.543628,0.006058,0.001068,0.027118,26.981026,1.374479,0.271182,-12.543628,0.028063,0.000000
26.050001,6.059245,-12.499147,0.006084,0.001083,0.027500,26.952866,1.373044,0.274997,-12.499147,0.028532,0.000000
26.330002,6.119569,-12.499147,0.006092,0.001099,0.027907,27.221201,1.386714,0.279074,-12.499147,0.029000,0.000000
26.610001,6.376506,-12.499147,0.006109,0.001123,0.028532,28.364115,1.444937,0.285317,-12.499147,0.029460,0.000000
26.890001,6.334055,-12.454666,0.006140,0.001140,0.028965,28.175285,1.435317,0.289654,-12.454666,0.029928,0.000000
27.170002,6.397731,-12.365705,0.006148,0.001160,0.029460,28.458530,1.449747,0.294597,-12.365705,0.030396,0.000000
27.450001,6.454704,-12.276743,0.006178,0.001177,0.029902,28.711958,1.462657,0.299020,-12.276743,0.030865,0.000000
27.730001,6.563437,-12.321223,0.006196,0.001196,0.030370,29.195625,1.487296,0.303704,-12.321223,0.031333,0.000000
28.010002,6.528061,-12.321223,0.006234,0.001210,0.030726,29.038267,1.479280,0.307258,-12.321223,0.031793,0.000000
28.290001,6.742176,-12.276743,0.006247,0.001231,0.031264,29.990694,1.527799,0.312636,-12.276743,0.032261,0.000000
28.570002,6.790584,-12.276743,0.006260,0.001250,0.031741,30.206026,1.538768,0.317405,-12.276743,0.032729,0.000000
28.850002,6.869899,-12.187780,0.006286,0.001269,0.032235,30.558838,1.556741,0.322348,-12.187780,0.033198,0.000000
29.130001,6.928362,-12.187780,0.006308,0.001287,0.032694,30.818893,1.569989,0.326945,-12.187780,0.033666,0.000000
29.410002,6.840482,-12.187780,0.006329,0.001299,0.033007,30.427984,1.550075,0.330066,-12.187780,0.034134,0.000000
29.690001,7.060182,-12.143300,0.006342,0.001321,0.033544,31.405256,1.599860,0.335444,-12.143300,0.034594,0.000000
29.970001,7.157371,-12.054338,0.006372,0.001340,0.034030,31.837576,1.621884,0.340300,-12.054338,0.035062,0.000000
30.250002,7.162212,-12.009857,0.006381,0.001355,0.034420,31.859110,1.622980,0.344202,-12.009857,0.035530,0.000000
30.530001,7.410957,-11.965376,0.006411,0.001381,0.035071,32.965584,1.679347,0.350706,-11.965376,0.035999,0.000000
30.810001,7.408350,-12.009857,0.006450,0.001398,0.035522,32.953987,1.678756,0.355216,-12.009857,0.036467,0.000000
31.090002,7.266849,-11.965376,0.006450,0.001413,0.035894,32.324558,1.646691,0.358944,-11.965376,0.036927,0.000000
31.370001,7.302224,-11.920895,0.006476,0.001429,0.036285,32.481915,1.654708,0.362848,-11.920895,0.037395,0.000000
31.650002,7.495113,-11.876414,0.006506,0.001450,0.036822,33.339928,1.698417,0.368225,-11.876414,0.037863,0.000000
31.930002,7.488410,-11.787452,0.006519,0.001466,0.037230,33.310112,1.696898,0.372301,-11.787452,0.038331,0.000000
32.210003,7.588951,-11.831933,0.006549,0.001482,0.037655,33.757339,1.719681,0.376550,-11.831933,0.038800,0.000000
32.490002,7.841419,-11.787452,0.006562,0.001508,0.038297,34.880375,1.776891,0.382967,-11.787452,0.039268,0.000000
32.770000,7.758008,-11.698490,0.006588,0.001523,0.038696,34.509342,1.757990,0.386956,-11.698490,0.039728,0.000000
33.050003,7.851846,-11.654009,0.006622,0.001544,0.039216,34.926754,1.779254,0.392161,-11.654009,0.040196,0.000000
33.330002,7.716674,-11.698490,0.006635,0.001557,0.039546,34.325481,1.748623,0.395455,-11.698490,0.040664,0.000000
33.610001,7.981431,-11.654009,0.006644,0.001580,0.040127,35.503181,1.808618,0.401265,-11.654009,0.041133,0.000000
33.890003,7.806044,-11.609529,0.006683,0.001591,0.040404,34.723015,1.768875,0.404041,-11.609529,0.041601,0.000000
34.170002,7.992602,-11.565047,0.006704,0.001611,0.040924,35.552872,1.811149,0.409244,-11.565047,0.042060,0.000000
34.450001,8.227198,-11.476086,0.006726,0.001635,0.041531,36.596401,1.864310,0.415315,-11.476086,0.042529,0.000000
34.730003,8.205227,-11.520566,0.006752,0.001653,0.041974,36.498672,1.859331,0.419737,-11.520566,0.042997,0.000000
35.010002,8.131497,-11.520566,0.006773,0.001670,0.042425,36.170708,1.842624,0.424247,-11.520566,0.043465,0.000000
35.290001,8.109156,-11.476086,0.006782,0.001684,0.042772,36.071327,1.837561,0.427716,-11.476086,0.043934,0.000000
35.570004,8.275233,-11.342643,0.006817,0.001704,0.043292,36.810078,1.875195,0.432920,-11.342643,0.044393,0.000000
35.850002,8.405936,-11.298162,0.006842,0.001721,0.043726,37.391472,1.904812,0.437256,-11.298162,0.044862,0.000000
36.130001,8.509083,-11.298162,0.006868,0.001744,0.044289,37.850292,1.928186,0.442893,-11.298162,0.045330,0.000000
36.410000,8.574248,-11.342643,0.006894,0.001762,0.044766,38.140160,1.942952,0.447662,-11.342643,0.045798,0.000000
36.690002,8.572015,-11.253680,0.006916,0.001779,0.045183,38.130226,1.942446,0.451826,-11.253680,0.046267,0.000000
36.970001,8.616699,-11.164719,0.006933,0.001798,0.045677,38.328991,1.952572,0.456769,-11.164719,0.046735,0.000000
37.250000,8.623030,-11.164719,0.006967,0.001815,0.046093,38.357151,1.954007,0.460930,-11.164719,0.047194,0.000000
37.530003,8.872519,-11.164719,0.006998,0.001836,0.046631,39.466938,2.010542,0.466309,-11.164719,0.047663,0.000000
37.810001,8.911618,-11.120237,0.007011,0.001852,0.047038,39.640858,2.019402,0.470383,-11.120237,0.048131,0.000000
38.090000,8.889276,-11.120237,0.007028,0.001869,0.047463,39.541473,2.014339,0.474633,-11.120237,0.048599,0.000000
38.370003,9.223666,-11.031276,0.007049,0.001892,0.048044,41.028915,2.090113,0.480443,-11.031276,0.049068,0.000000
38.650002,9.275426,-11.031276,0.007097,0.001912,0.048573,41.259155,2.101841,0.485733,-11.031276,0.049527,0.000000
38.930000,9.149937,-11.031276,0.007118,0.001928,0.048972,40.700951,2.073405,0.489722,-11.031276,0.049996,0.000000
39.210003,9.272075,-10.986794,0.007136,0.001949,0.049493,41.244247,2.101082,0.494926,-10.986794,0.050464,0.000000
39.490002,9.173023,-10.986794,0.007153,0.001963,0.049857,40.803646,2.078637,0.498569,-10.986794,0.050932,0.000000
39.770000,9.307822,-10.808871,0.007170,0.001979,0.050273,41.403259,2.109183,0.502731,-10.808871,0.051401,0.000000
40.050003,9.212868,-10.853352,0.007209,0.001992,0.050594,40.980881,2.087666,0.505940,-10.853352,0.051869,0.000000
40.330002,9.584867,-10.808871,0.007243,0.002018,0.051253,42.635620,2.171962,0.512532,-10.808871,0.052328,0.000000
40.610001,9.722646,-10.853352,0.007252,0.002040,0.051808,43.248489,2.203183,0.518080,-10.853352,0.052797,0.000000
40.890003,9.724134,-10.808871,0.007278,0.002059,0.052302,43.255112,2.203521,0.523023,-10.808871,0.053265,0.000000
41.170002,9.636627,-10.719910,0.007304,0.002075,0.052701,42.865860,2.183691,0.527013,-10.719910,0.053733,0.000000
41.450001,9.949048,-10.675428,0.007325,0.002097,0.053265,44.255577,2.254486,0.532650,-10.675428,0.054202,0.000000
41.730003,9.641468,-10.675428,0.007347,0.002108,0.053534,42.887390,2.184788,0.535339,-10.675428,0.054661,0.000000
42.010002,9.731583,-10.675428,0.007360,0.002125,0.053985,43.288242,2.205208,0.539849,-10.675428,0.055130,0.000000
42.290001,10.217528,-10.586467,0.007394,0.002151,0.054644,45.449837,2.315325,0.546439,-10.586467,0.055598,0.000000
42.570004,10.161673,-10.541986,0.007424,0.002170,0.055121,45.201378,2.302668,0.551209,-10.541986,0.056066,0.000000
42.850002,10.108423,-10.497504,0.007450,0.002188,0.055581,44.964512,2.290601,0.555806,-10.497504,0.056534,0.000000
43.130001,10.296844,-10.497504,0.007468,0.002205,0.055997,45.802647,2.333298,0.559968,-10.497504,0.057003,0.000000
43.410004,10.322537,-10.497504,0.007489,0.002222,0.056439,45.916939,2.339120,0.564390,-10.497504,0.057462,0.000000
43.690002,10.213059,-10.497504,0.007545,0.002236,0.056795,45.429958,2.314312,0.567946,-10.497504,0.057931,0.000000
43.970001,10.402597,-10.364061,0.007545,0.002255,0.057280,46.273064,2.357262,0.572802,-10.364061,0.058399,0.000000
44.250004,10.730286,-10.319581,0.007554,0.002277,0.057827,47.730694,2.431518,0.578266,-10.319581,0.058867,0.000000
44.530003,10.862105,-10.319581,0.007597,0.002298,0.058373,48.317059,2.461388,0.583729,-10.319581,0.059336,0.000000
44.810001,10.766778,-10.275100,0.007606,0.002315,0.058789,47.893021,2.439787,0.587893,-10.275100,0.059795,0.000000
45.090004,10.893757,-10.275100,0.007623,0.002334,0.059284,48.457851,2.468561,0.592836,-10.275100,0.060263,0.000000
45.370003,11.003607,-10.186138,0.007653,0.002353,0.059761,48.946487,2.493453,0.597607,-10.186138,0.060732,0.000000
45.650002,10.881841,-10.141657,0.007670,0.002366,0.060108,48.404846,2.465860,0.601075,-10.141657,0.061200,0.000000
45.930000,11.233733,-10.230618,0.007683,0.002390,0.060706,49.970142,2.545600,0.607059,-10.230618,0.061668,0.000000
46.210003,11.286238,-10.141657,0.007718,0.002409,0.061192,50.203693,2.557498,0.611915,-10.141657,0.062128,0.000000
46.490002,11.343583,-10.097176,0.007731,0.002428,0.061668,50.458778,2.570493,0.616684,-10.097176,0.062596,0.000000
46.770000,11.425505,-10.052695,0.007761,0.002447,0.062146,50.823185,2.589056,0.621455,-10.052695,0.063065,0.000000
47.050003,11.549132,-10.008214,0.007782,0.002466,0.062648,51.373108,2.617071,0.626483,-10.008214,0.063533,0.000000
47.330002,11.435931,-9.963733,0.007808,0.002481,0.063030,50.869564,2.591419,0.630300,-9.963733,0.064001,0.000000
47.610001,11.471679,-10.008214,0.007834,0.002497,0.063429,51.028576,2.599520,0.634290,-10.008214,0.064470,0.000000
47.890003,11.828412,-9.919252,0.007838,0.002521,0.064036,52.615406,2.680357,0.640361,-9.919252,0.064929,0.000000
48.170002,11.804953,-9.919252,0.007873,0.002538,0.064461,52.511051,2.675040,0.644609,-9.919252,0.065397,0.000000
48.450001,11.842935,-9.785810,0.007899,0.002557,0.064947,52.680004,2.683647,0.649465,-9.785810,0.065866,0.000000
48.730003,11.862297,-9.830290,0.007916,0.002574,0.065380,52.766132,2.688035,0.653803,-9.830290,0.066334,0.000000
49.010002,12.084604,-9.830290,0.007942,0.002595,0.065901,53.755005,2.738410,0.659005,-9.830290,0.066802,0.000000
49.290001,11.939006,-9.830290,0.007959,0.002608,0.066247,53.107349,2.705417,0.662474,-9.830290,0.067262,0.000000
49.570004,12.164291,-9.741328,0.007976,0.002628,0.066750,54.109470,2.756468,0.667504,-9.741328,0.067730,0.000000
49.850002,12.273025,-9.652367,0.008002,0.002646,0.067219,54.593140,2.781107,0.672188,-9.652367,0.068199,0.000000
50.130001,12.357553,-9.652367,0.008028,0.002667,0.067730,54.969139,2.800261,0.677303,-9.652367,0.068667,0.000000
50.410004,12.446550,-9.652367,0.008050,0.002685,0.068199,55.365021,2.820429,0.681987,-9.652367,0.069135,0.000000
50.690002,12.289409,-9.563404,0.008071,0.002697,0.068511,54.666019,2.784820,0.685109,-9.563404,0.069604,0.000000
50.970001,12.596989,-9.563404,0.008088,0.002719,0.069066,56.034203,2.854518,0.690658,-9.563404,0.070063,0.000000
51.250004,12.767907,-9.474442,0.008114,0.002738,0.069552,56.794487,2.893249,0.695516,-9.474442,0.070532,0.000000
51.530003,12.696039,-9.518924,0.008132,0.002754,0.069959,56.474804,2.876964,0.699591,-9.518924,0.071000,0.000000
51.810001,12.949998,-9.474442,0.008162,0.002776,0.070523,57.604469,2.934511,0.705228,-9.474442,0.071468,0.000000
52.090004,13.043836,-9.474442,0.008183,0.002796,0.071026,58.021877,2.955775,0.710258,-9.474442,0.071936,0.000000
52.370003,12.789132,-9.341000,0.008218,0.002811,0.071390,56.888901,2.898059,0.713901,-9.341000,0.072396,0.000000
52.650002,12.809240,-9.341000,0.008231,0.002827,0.071798,56.978348,2.902615,0.717976,-9.341000,0.072864,0.000000
52.930004,12.962658,-9.341000,0.008269,0.002845,0.072257,57.660782,2.937380,0.722572,-9.341000,0.073333,0.000000
53.210003,13.113841,-9.296518,0.008274,0.002862,0.072700,58.333279,2.971639,0.726995,-9.296518,0.073801,0.000000
53.490002,13.189060,-9.341000,0.008291,0.002881,0.073168,58.667870,2.988684,0.731679,-9.341000,0.074269,0.000000
53.770004,13.472436,-9.118595,0.008330,0.002904,0.073758,59.928387,3.052898,0.737576,-9.118595,0.074729,0.000000
54.050003,13.352532,-9.163075,0.008356,0.002920,0.074174,59.395031,3.025727,0.741739,-9.163075,0.075197,0.000000
54.330002,13.431475,-9.163075,0.008390,0.002940,0.074685,59.746181,3.043616,0.746854,-9.163075,0.075666,0.000000
54.610004,13.334286,-9.163075,0.008403,0.002955,0.075058,59.313866,3.021592,0.750584,-9.163075,0.076134,0.000000
54.890003,13.496640,-9.074114,0.008412,0.002974,0.075535,60.036053,3.058382,0.755353,-9.074114,0.076602,0.000000
55.170002,13.359607,-8.985152,0.008455,0.002988,0.075891,59.426498,3.027330,0.758909,-8.985152,0.077070,0.000000
55.450001,13.571115,-8.985152,0.008481,0.003009,0.076420,60.367332,3.075258,0.764201,-8.985152,0.077530,0.000000
55.730003,13.960989,-8.985152,0.008515,0.003033,0.077036,62.101582,3.163605,0.770357,-8.985152,0.077998,0.000000
56.010002,13.864172,-8.985152,0.008520,0.003051,0.077495,61.670918,3.141666,0.774953,-8.985152,0.078467,0.000000
56.290001,13.628833,-8.985152,0.008554,0.003068,0.077929,60.624077,3.088338,0.779289,-8.985152,0.078935,0.000000
56.570004,13.447860,-8.851709,0.008580,0.003082,0.078284,59.819069,3.047329,0.782845,-8.851709,0.079403,0.000000
56.850002,13.356256,-8.851709,0.008601,0.003095,0.078605,59.411591,3.026571,0.786055,-8.851709,0.079863,0.000000
57.130001,13.731235,-8.851709,0.008632,0.003117,0.079169,61.079582,3.111542,0.791690,-8.851709,0.080331,0.000000
57.410004,13.924124,-8.807228,0.008645,0.003140,0.079750,61.937595,3.155252,0.797502,-8.807228,0.080799,0.000000
57.690002,14.081637,-8.762748,0.008679,0.003161,0.080288,62.638252,3.190945,0.802878,-8.762748,0.081268,0.000000
57.970001,13.934178,-8.718266,0.008705,0.003177,0.080695,61.982323,3.157530,0.806955,-8.718266,0.081736,0.000000
58.250004,13.906995,-8.629305,0.008739,0.003196,0.081181,61.861404,3.151370,0.811811,-8.629305,0.082204,0.000000
58.530003,13.806827,-8.718266,0.008757,0.003212,0.081589,61.415833,3.128672,0.815887,-8.718266,0.082664,0.000000
58.810001,14.071956,-8.584824,0.008795,0.003233,0.082126,62.595184,3.188751,0.821264,-8.584824,0.083132,0.000000
59.090004,14.106214,-8.584824,0.008808,0.003250,0.082551,62.747570,3.196514,0.825512,-8.584824,0.083601,0.000000
59.370003,14.019079,-8.540342,0.008839,0.003266,0.082968,62.359978,3.176769,0.829675,-8.540342,0.084069,0.000000
59.650002,14.444328,-8.540342,0.008882,0.003289,0.083531,64.251579,3.273132,0.835313,-8.540342,0.084537,0.000000
59.930004,14.399271,-8.495862,0.008903,0.003307,0.084008,64.051155,3.262922,0.840082,-8.495862,0.084997,0.000000
60.210003,14.245109,-8.451381,0.008925,0.003325,0.084459,63.365406,3.227988,0.844592,-8.451381,0.085465,0.000000
60.490002,14.133397,-8.406899,0.008946,0.003343,0.084910,62.868488,3.202673,0.849101,-8.406899,0.085933,0.000000
60.770004,14.075680,-8.362419,0.008981,0.003359,0.085326,62.611752,3.189595,0.853263,-8.362419,0.086402,0.000000
61.050003,13.985938,-8.317938,0.009007,0.003376,0.085760,62.212559,3.169259,0.857600,-8.317938,0.086870,0.000000
61.330002,14.058550,-8.317938,0.009033,0.003390,0.086107,62.535553,3.185713,0.861069,-8.317938,0.087330,0.000000
61.610004,14.556413,-8.273457,0.009037,0.003415,0.086749,64.750160,3.298530,0.867487,-8.273457,0.087798,0.000000
61.890003,14.478586,-8.228976,0.009076,0.003435,0.087252,64.403969,3.280895,0.872517,-8.228976,0.088266,0.000000
62.170002,14.564232,-8.228976,0.009089,0.003455,0.087746,64.784943,3.300302,0.877460,-8.228976,0.088735,0.000000
62.450005,14.389217,-8.184495,0.009136,0.003471,0.088162,64.006439,3.260643,0.881621,-8.184495,0.089203,0.000000
62.730003,14.641685,-8.140014,0.009153,0.003492,0.088700,65.129471,3.317853,0.887000,-8.140014,0.089671,0.000000
63.010002,14.244737,-8.095533,0.009179,0.003504,0.088995,63.363754,3.227904,0.889948,-8.095533,0.090131,0.000000
63.290005,14.134514,-8.140014,0.009184,0.003516,0.089316,62.873459,3.202927,0.893156,-8.140014,0.090599,0.000000
63.570004,15.101193,-8.051052,0.009227,0.003548,0.090131,67.173462,3.421979,0.901308,-8.051052,0.091067,0.000000
63.850002,14.843139,-8.006571,0.009304,0.003566,0.090573,66.025581,3.363503,0.905731,-8.006571,0.091536,0.000000
64.130005,14.881494,-7.962090,0.009304,0.003584,0.091041,66.196190,3.372195,0.910415,-7.962090,0.092004,0.000000
64.410004,14.906815,-7.917609,0.009304,0.003603,0.091510,66.308823,3.377933,0.915097,-7.917609,0.092464,0.000000
64.690002,14.799944,-7.917609,0.009322,0.003617,0.091883,65.833435,3.353715,0.918827,-7.917609,0.092932,0.000000
64.970001,14.846491,-7.962090,0.009356,0.003633,0.092273,66.040489,3.364263,0.922729,-7.962090,0.093400,0.000000
65.250000,14.769782,-7.873128,0.009369,0.003646,0.092611,65.699272,3.346880,0.926111,-7.873128,0.093869,0.000000
65.530006,15.513037,-7.828648,0.009386,0.003675,0.093339,69.005432,3.515304,0.933395,-7.828648,0.094337,0.000000
65.810005,15.513037,-7.828648,0.009412,0.003693,0.093790,69.005432,3.515304,0.937905,-7.828648,0.094805,0.000000
66.090004,15.479152,-7.784166,0.009442,0.003711,0.094259,68.854706,3.507626,0.942588,-7.784166,0.095265,0.000000
66.370003,15.383824,-7.739686,0.009485,0.003726,0.094649,68.430672,3.486024,0.946491,-7.739686,0.095733,0.000000
66.650002,15.854875,-7.650723,0.009507,0.003750,0.095247,70.526001,3.592766,0.952474,-7.650723,0.096201,0.000000
66.930000,15.422550,-7.650723,0.009533,0.003761,0.095525,68.602928,3.494800,0.955249,-7.650723,0.096670,0.000000
67.210007,15.834394,-7.606243,0.009554,0.003782,0.096054,70.434906,3.588125,0.960540,-7.606243,0.097138,0.000000
67.490005,16.333000,-7.606243,0.009593,0.003806,0.096670,72.652817,3.701111,0.966696,-7.606243,0.097598,0.000000
67.770004,16.214958,-7.517281,0.009597,0.003824,0.097138,72.127739,3.674362,0.971380,-7.517281,0.098066,0.000000
68.050003,16.292784,-7.517281,0.009623,0.003842,0.097580,72.473923,3.691998,0.975803,-7.517281,0.098534,0.000000
68.330002,16.534454,-7.428319,0.009653,0.003862,0.098083,73.548927,3.746761,0.980833,-7.428319,0.099002,0.000000
68.610001,16.573553,-7.472800,0.009662,0.003878,0.098500,73.722847,3.755621,0.984996,-7.472800,0.099471,0.000000
68.890007,16.411943,-7.472800,0.009671,0.003892,0.098847,73.003967,3.719000,0.988465,-7.472800,0.099930,0.000000
69.170006,17.010719,-7.294876,0.009705,0.003913,0.099393,75.667458,3.854684,0.993929,-7.294876,0.100399,0.000000
69.450005,17.346600,-7.339357,0.009727,0.003936,0.099965,77.161530,3.930796,0.999651,-7.339357,0.100867,0.000000
69.730003,17.353674,-7.339357,0.009753,0.003953,0.100407,77.192993,3.932399,1.004074,-7.339357,0.101335,0.000000
70.010002,17.382347,-7.294876,0.009761,0.003970,0.100832,77.320541,3.938896,1.008324,-7.294876,0.101804,0.000000
70.290001,17.737217,-7.294876,0.009791,0.003990,0.101353,78.899078,4.019311,1.013527,-7.294876,0.102272,0.000000
70.570000,17.746899,-7.205914,0.009822,0.004005,0.101734,78.942146,4.021505,1.017342,-7.205914,0.102732,0.000000
70.850006,18.040329,-7.161433,0.009830,0.004025,0.102229,80.247391,4.087997,1.022287,-7.161433,0.103200,0.000000
71.130005,18.424618,-7.161433,0.009865,0.004044,0.102723,81.956795,4.175078,1.027230,-7.161433,0.103668,0.000000
71.410004,18.621603,-7.161433,0.009886,0.004062,0.103182,82.833031,4.219716,1.031825,-7.161433,0.104136,0.000000
71.690002,18.722515,-7.116952,0.009891,0.004079,0.103608,83.281906,4.242583,1.036075,-7.116952,0.104605,0.000000
71.970001,18.853590,-6.983510,0.009908,0.004096,0.104032,83.864960,4.272285,1.040324,-6.983510,0.105065,0.000000
72.250000,19.373423,-7.027990,0.009929,0.004115,0.104527,86.177284,4.390080,1.045267,-7.027990,0.105533,0.000000
72.530006,19.656054,-7.027990,0.009960,0.004135,0.105021,87.434494,4.454125,1.050210,-7.027990,0.106001,0.000000
72.810005,19.834419,-6.939028,0.009977,0.004150,0.105403,88.227905,4.494544,1.054027,-6.939028,0.106469,0.000000
73.090004,20.308823,-6.939028,0.009985,0.004171,0.105949,90.338158,4.602045,1.059491,-6.939028,0.106938,0.000000
73.370003,20.931429,-6.894547,0.010016,0.004195,0.106547,93.107643,4.743130,1.065474,-6.894547,0.107406,0.000000
73.650002,20.704655,-6.805585,0.010033,0.004208,0.106877,92.098907,4.691741,1.068769,-6.805585,0.107866,0.000000
73.930000,20.928078,-6.850067,0.010046,0.004224,0.107293,93.092735,4.742370,1.072933,-6.850067,0.108334,0.000000
74.210007,21.253159,-6.805585,0.010072,0.004240,0.107701,94.538773,4.816035,1.077009,-6.805585,0.108802,0.000000
74.490005,21.776342,-6.761105,0.010080,0.004260,0.108195,96.866013,4.934590,1.081952,-6.761105,0.109270,0.000000
74.770004,22.288355,-6.672143,0.010102,0.004277,0.108646,99.143555,5.050613,1.086462,-6.672143,0.109739,0.000000
75.050003,23.068102,-6.627662,0.010111,0.004301,0.109253,102.612045,5.227307,1.092531,-6.627662,0.110198,0.000000
75.330002,23.297483,-6.627662,0.010132,0.004318,0.109678,103.632385,5.279285,1.096781,-6.627662,0.110667,0.000000
75.610001,23.846733,-6.627662,0.010158,0.004340,0.110242,106.075569,5.403747,1.102417,-6.627662,0.111135,0.000000
75.890007,23.940199,-6.627662,0.010175,0.004354,0.110580,106.491325,5.424927,1.105801,-6.627662,0.111603,0.000000
76.170006,24.570253,-6.538700,0.010192,0.004374,0.111109,109.293945,5.567699,1.111090,-6.538700,0.112072,0.000000
76.450005,24.673773,-6.494219,0.010214,0.004386,0.111404,109.754425,5.591157,1.114038,-6.494219,0.112540,0.000000
76.730003,25.361916,-6.449738,0.010236,0.004407,0.111933,112.815437,5.747092,1.119328,-6.449738,0.113000,0.000000
77.010002,26.381100,-6.494219,0.010240,0.004431,0.112540,117.348991,5.978043,1.125399,-6.494219,0.113468,0.000000
77.290001,26.849916,-6.449738,0.010261,0.004449,0.113017,119.434395,6.084278,1.130170,-6.449738,0.113936,0.000000
77.570007,27.174253,-6.405257,0.010274,0.004466,0.113433,120.877113,6.157773,1.134331,-6.405257,0.114405,0.000000
77.850006,27.369749,-6.316295,0.010292,0.004480,0.113780,121.746727,6.202074,1.137800,-6.316295,0.114873,0.000000
78.130005,27.709352,-6.271814,0.010296,0.004493,0.114110,123.257355,6.279029,1.141097,-6.271814,0.115332,0.000000
78.410004,28.333076,-6.271814,0.010313,0.004510,0.114561,126.031822,6.420367,1.145606,-6.271814,0.115801,0.000000
78.690002,29.694469,-6.271814,0.010339,0.004537,0.115228,132.087601,6.728863,1.152283,-6.271814,0.116269,0.000000
78.970001,30.423203,-6.182852,0.010361,0.004558,0.115766,135.329163,6.893996,1.157659,-6.182852,0.116737,0.000000
79.250000,31.021605,-6.138371,0.010365,0.004574,0.116191,137.990982,7.029596,1.161910,-6.138371,0.117206,0.000000
79.530006,31.631552,-6.093890,0.010391,0.004594,0.116677,140.704163,7.167812,1.166766,-6.093890,0.117665,0.000000
79.810005,32.145424,-6.138371,0.010395,0.004610,0.117101,142.989990,7.284257,1.171014,-6.138371,0.118134,0.000000
80.090004,32.995926,-6.093890,0.010408,0.004630,0.117596,146.773209,7.476984,1.175959,-6.093890,0.118602,0.000000
80.370003,33.832645,-6.004929,0.010425,0.004648,0.118064,150.495117,7.666587,1.180641,-6.004929,0.119070,0.000000
80.650002,34.125702,-6.004929,0.010434,0.004661,0.118394,151.798706,7.732995,1.183938,-6.004929,0.119538,0.000000
80.930000,34.912151,-5.960447,0.010455,0.004683,0.118957,155.297012,7.911206,1.189574,-5.960447,0.120007,0.000000
81.210007,36.392334,-5.915967,0.010464,0.004704,0.119486,161.881180,8.246621,1.194865,-5.915967,0.120466,0.000000
81.490005,37.157185,-5.960447,0.010486,0.004722,0.119929,165.283417,8.419938,1.199288,-5.960447,0.120935,0.000000
81.770004,37.820381,-5.871486,0.010490,0.004738,0.120354,168.233459,8.570221,1.203536,-5.871486,0.121403,0.000000
82.050003,38.772537,-5.871486,0.010494,0.004757,0.120822,172.468857,8.785982,1.208220,-5.871486,0.121871,0.000000
82.330002,39.287529,-5.782524,0.010503,0.004771,0.121178,174.759659,8.902681,1.211776,-5.782524,0.122340,0.000000
82.610001,40.033764,-5.782524,0.010529,0.004789,0.121628,178.079071,9.071781,1.216284,-5.782524,0.122799,0.000000
82.890007,41.683746,-5.782524,0.010524,0.004813,0.122262,185.418564,9.445671,1.222616,-5.782524,0.123267,0.000000
83.170006,42.546162,-5.738043,0.010533,0.004832,0.122730,189.254776,9.641098,1.227298,-5.738043,0.123736,0.000000
83.450005,43.575027,-5.693562,0.010555,0.004851,0.123216,193.831406,9.874243,1.232156,-5.693562,0.124204,0.000000
83.730003,44.418823,-5.560119,0.010576,0.004867,0.123614,197.584793,10.065449,1.236145,-5.560119,0.124672,0.000000
84.010002,45.750427,-5.649081,0.010580,0.004890,0.124204,203.508072,10.367195,1.242042,-5.649081,0.125141,0.000000
84.290001,46.387928,-5.649081,0.010585,0.004902,0.124508,206.343811,10.511655,1.245077,-5.649081,0.125600,0.000000
84.570007,46.892120,-5.471157,0.010606,0.004915,0.124837,208.586563,10.625906,1.248372,-5.471157,0.126069,0.000000
84.850006,49.118534,-5.382195,0.010598,0.004946,0.125618,218.490158,11.130419,1.256176,-5.382195,0.126537,0.000000
85.130005,49.949299,-5.515638,0.010611,0.004961,0.125999,222.185577,11.318673,1.259993,-5.515638,0.127005,0.000000
85.410004,51.024338,-5.426676,0.010637,0.004979,0.126468,226.967590,11.562281,1.264675,-5.426676,0.127474,0.000000
85.690002,51.721046,-5.426676,0.010632,0.004995,0.126884,230.066711,11.720157,1.268839,-5.426676,0.127933,0.000000
85.970001,53.179630,-5.337714,0.010654,0.005013,0.127335,236.554810,12.050676,1.273348,-5.337714,0.128401,0.000000
86.250008,54.080399,-5.382195,0.010649,0.005028,0.127716,240.561630,12.254794,1.277164,-5.382195,0.128870,0.000000
86.530006,54.966270,-5.248752,0.010667,0.005044,0.128107,244.502182,12.455535,1.281066,-5.248752,0.129338,0.000000
86.810005,56.979317,-5.248752,0.010675,0.005071,0.128792,253.456665,12.911697,1.287917,-5.248752,0.129806,0.000000
87.090004,58.253948,-5.248752,0.010675,0.005089,0.129251,259.126495,13.200534,1.292513,-5.248752,0.130266,0.000000
87.370003,59.658165,-5.159791,0.010684,0.005108,0.129746,265.372772,13.518733,1.297456,-5.159791,0.130734,0.000000
87.650002,60.472916,-5.115309,0.010701,0.005123,0.130119,268.996948,13.703359,1.301186,-5.115309,0.131203,0.000000
87.930008,62.408882,-5.159791,0.010718,0.005146,0.130717,277.608582,14.142055,1.307170,-5.159791,0.131671,0.000000
88.210007,62.928341,-5.070828,0.010705,0.005156,0.130960,279.919250,14.259766,1.309598,-5.070828,0.132139,0.000000
88.490005,63.921455,-5.070828,0.010718,0.005171,0.131333,284.336823,14.484809,1.313326,-5.070828,0.132608,0.000000
88.770004,66.698242,-5.070828,0.010723,0.005202,0.132139,296.688599,15.114038,1.321392,-5.070828,0.133067,0.000000
89.050003,67.360313,-4.892905,0.010740,0.005205,0.132200,299.633636,15.264065,1.321999,-4.892905,0.132443,0.000000
89.330002,66.744041,-4.981866,0.010744,0.005205,0.132200,296.892334,15.124416,1.321999,-4.981866,0.132443,0.000000
89.610001,66.223839,-4.937386,0.010753,0.005202,0.132122,294.578339,15.006536,1.321218,-4.937386,0.132200,0.000000
89.890007,65.784439,-4.937386,0.010762,0.005201,0.132113,292.623810,14.906966,1.321133,-4.937386,0.132200,0.000000
90.170006,65.436638,-4.848423,0.010740,0.005201,0.132105,291.076691,14.828155,1.321046,-4.848423,0.132200,0.000000
90.450005,65.079910,-4.759462,0.010796,0.005201,0.132096,289.489899,14.747318,1.320959,-4.759462,0.132200,0.000000
90.730003,64.889626,-4.803943,0.010809,0.005201,0.132096,288.643463,14.704200,1.320959,-4.803943,0.132200,0.000000
91.010002,64.592476,-4.803943,0.010805,0.005201,0.132096,287.321686,14.636864,1.320959,-4.803943,0.132200,0.000000
91.290001,64.360481,-4.714981,0.010809,0.005200,0.132087,286.289734,14.584293,1.320872,-4.714981,0.132200,0.000000
91.570007,64.158287,-4.626019,0.010792,0.005200,0.132087,285.390320,14.538476,1.320872,-4.626019,0.132200,0.000000
91.850006,64.022369,-4.626019,0.010809,0.005200,0.132087,284.785736,14.507676,1.320872,-4.626019,0.132200,0.000000
92.130005,63.861134,-4.626019,0.010813,0.005200,0.132087,284.068512,14.471139,1.320872,-4.626019,0.132200,0.000000
92.410004,63.747932,-4.670500,0.010813,0.005200,0.132087,283.564972,14.445488,1.320872,-4.670500,0.132200,0.000000
92.690002,63.531956,-4.537057,0.010809,0.005200,0.132087,282.604248,14.396546,1.320872,-4.537057,0.132200,0.000000
92.970001,63.460087,-4.537057,0.010805,0.005200,0.132078,282.284576,14.380261,1.320785,-4.537057,0.132200,0.000000
93.250008,63.320076,-4.448095,0.010809,0.005200,0.132078,281.661774,14.348535,1.320785,-4.448095,0.132200,0.000000
93.530006,63.162563,-4.448095,0.010809,0.005200,0.132078,280.961121,14.312841,1.320785,-4.448095,0.132200,0.000000
93.810005,63.041168,-4.448095,0.010809,0.005200,0.132078,280.421112,14.285334,1.320785,-4.448095,0.132200,0.000000
94.090004,63.054203,-4.448095,0.010809,0.005200,0.132078,280.479095,14.288286,1.320785,-4.448095,0.132200,0.000000
94.370003,62.911957,-4.403614,0.010796,0.005200,0.132078,279.846375,14.256054,1.320785,-4.403614,0.132200,0.000000
94.650002,62.786095,-4.314652,0.010796,0.005200,0.132078,279.286499,14.227532,1.320785,-4.314652,0.132200,0.000000
94.930008,62.740292,-4.314652,0.010809,0.005200,0.132078,279.082764,14.217154,1.320785,-4.314652,0.132200,0.000000
95.210007,62.637146,-4.270171,0.010805,0.005200,0.132078,278.623932,14.193780,1.320785,-4.270171,0.132200,0.000000
95.490005,62.548893,-4.314652,0.010792,0.005200,0.132078,278.231384,14.173781,1.320785,-4.314652,0.132200,0.000000
95.770004,62.486706,-4.225690,0.010809,0.005200,0.132078,277.954742,14.159690,1.320785,-4.225690,0.132200,0.000000
96.050003,62.433456,-4.136728,0.010809,0.005200,0.132078,277.717896,14.147624,1.320785,-4.136728,0.132200,0.000000
96.330002,62.354885,-4.092247,0.010813,0.005200,0.132078,277.368378,14.129819,1.320785,-4.092247,0.132200,0.000000
96.610008,62.296051,-4.136728,0.010813,0.005200,0.132078,277.106689,14.116487,1.320785,-4.136728,0.132200,0.000000
96.890007,62.242802,-4.092247,0.010796,0.005200,0.132078,276.869812,14.104421,1.320785,-4.092247,0.132200,0.000000
97.170006,62.188808,-4.047767,0.010796,0.005200,0.132078,276.629639,14.092185,1.320785,-4.047767,0.132200,0.000000
97.450005,62.114704,-3.914324,0.010805,0.005200,0.132078,276.300018,14.075393,1.320785,-3.914324,0.132200,0.000000
97.730003,62.083054,-3.958805,0.010813,0.005200,0.132078,276.159210,14.068221,1.320785,-3.958805,0.132200,0.000000
98.010002,61.993687,-3.958805,0.010809,0.005200,0.132078,275.761688,14.047970,1.320785,-3.958805,0.132200,0.000000
98.290001,61.973949,-3.914324,0.010809,0.005200,0.132078,275.673889,14.043498,1.320785,-3.914324,0.132200,0.000000
98.570007,61.892029,-3.914324,0.010813,0.005200,0.132078,275.309509,14.024935,1.320785,-3.914324,0.132200,0.000000
98.850006,61.858143,-3.825362,0.010813,0.005200,0.132078,275.158752,14.017256,1.320785,-3.825362,0.132200,0.000000
99.130005,61.798561,-3.825362,0.010809,0.005200,0.132078,274.893738,14.003755,1.320785,-3.825362,0.132200,0.000000
99.410004,61.759090,-3.780881,0.010800,0.005200,0.132078,274.718140,13.994809,1.320785,-3.780881,0.132200,0.000000
99.690002,61.719990,-3.736400,0.010805,0.005200,0.132078,274.544220,13.985950,1.320785,-3.736400,0.132200,0.000000
99.970001,61.670094,-3.736400,0.010818,0.005200,0.132078,274.322266,13.974643,1.320785,-3.736400,0.132200,0.000000
100.250008,61.646263,-3.691919,0.010813,0.005200,0.132070,274.216278,13.969243,1.320697,-3.691919,0.132200,0.000000
100.530006,61.597107,-3.602957,0.010809,0.005200,0.132070,273.997620,13.958104,1.320697,-3.602957,0.132200,0.000000
100.810005,61.542370,-3.647438,0.010805,0.005200,0.132070,273.754120,13.945701,1.320697,-3.647438,0.132200,0.000000
101.090004,61.511089,-3.602957,0.010805,0.005200,0.132070,273.614990,13.938612,1.320697,-3.602957,0.132200,0.000000
101.370003,61.476460,-3.513995,0.010809,0.005200,0.132070,273.460937,13.930765,1.320697,-3.513995,0.132200,0.000000
101.650002,61.446671,-3.469514,0.010818,0.005200,0.132070,273.328430,13.924014,1.320697,-3.469514,0.132200,0.000000
101.930008,61.422092,-3.425033,0.010809,0.005200,0.132070,273.219116,13.918446,1.320697,-3.425033,0.132200,0.000000
102.210007,61.371452,-3.425033,0.010809,0.005200,0.132070,272.993866,13.906969,1.320697,-3.425033,0.132200,0.000000
102.490005,61.347248,-3.425033,0.010800,0.005200,0.132070,272.886200,13.901485,1.320697,-3.425033,0.132200,0.000000
102.770004,61.305542,-3.425033,0.010809,0.005200,0.132070,272.700684,13.892035,1.320697,-3.425033,0.132200,0.000000
103.050003,61.288040,-3.291590,0.010813,0.005200,0.132070,272.622833,13.888068,1.320697,-3.291590,0.132200,0.000000
103.330002,61.230694,-3.291590,0.010813,0.005200,0.132070,272.367737,13.875073,1.320697,-3.291590,0.132200,0.000000
103.610008,61.192711,-3.291590,0.010813,0.005200,0.132070,272.198761,13.866467,1.320697,-3.291590,0.132200,0.000000
103.890007,61.178562,-3.247109,0.010809,0.005200,0.132070,272.135834,13.863260,1.320697,-3.247109,0.132200,0.000000
104.170006,61.138718,-3.202628,0.010809,0.005200,0.132070,271.958588,13.854231,1.320697,-3.202628,0.132200,0.000000
104.450005,61.117493,-3.113667,0.010809,0.005200,0.132070,271.864197,13.849422,1.320697,-3.113667,0.132200,0.000000
104.730003,61.075787,-3.113667,0.010805,0.005200,0.132070,271.678680,13.839971,1.320697,-3.113667,0.132200,0.000000
105.010002,61.047859,-3.113667,0.010818,0.005200,0.132070,271.554443,13.833642,1.320697,-3.113667,0.132200,0.000000
105.290009,61.022911,-3.113667,0.010805,0.005200,0.132070,271.443451,13.827989,1.320697,-3.113667,0.132200,0.000000
105.570007,60.994236,-3.024705,0.010800,0.005200,0.132070,271.315918,13.821492,1.320697,-3.024705,0.132200,0.000000
105.850006,60.981205,-2.980224,0.010800,0.005200,0.132070,271.257935,13.818539,1.320697,-2.980224,0.132200,0.000000
106.130005,60.955509,-2.980224,0.010826,0.005200,0.132070,271.143646,13.812716,1.320697,-2.980224,0.132200,0.000000
106.410004,60.928699,-3.024705,0.010818,0.005200,0.132070,271.024384,13.806641,1.320697,-3.024705,0.132200,0.000000
106.690002,60.901516,-2.980224,0.010800,0.005200,0.132070,270.903473,13.800481,1.320697,-2.980224,0.132200,0.000000
106.970009,60.868748,-2.891262,0.010792,0.005200,0.132070,270.757721,13.793056,1.320697,-2.891262,0.132200,0.000000
107.250008,60.856087,-2.846781,0.010818,0.005200,0.132070,270.701385,13.790187,1.320697,-2.846781,0.132200,0.000000
107.530006,60.830395,-2.802300,0.010826,0.005200,0.132070,270.587097,13.784365,1.320697,-2.802300,0.132200,0.000000
107.810005,60.802837,-2.846781,0.010800,0.005200,0.132070,270.464539,13.778120,1.320697,-2.846781,0.132200,0.000000
108.090004,60.786453,-2.802300,0.010809,0.005200,0.132070,270.391663,13.774407,1.320697,-2.802300,0.132200,0.000000
108.370003,60.762249,-2.713338,0.010818,0.005200,0.132070,270.283997,13.768922,1.320697,-2.713338,0.132200,0.000000
108.650002,60.738789,-2.624376,0.010805,0.005200,0.132070,270.179626,13.763606,1.320697,-2.624376,0.132200,0.000000
108.930008,60.731716,-2.579895,0.010805,0.005200,0.132070,270.148163,13.762004,1.320697,-2.579895,0.132200,0.000000
109.210007,60.691498,-2.624376,0.010809,0.005200,0.132070,269.969269,13.752890,1.320697,-2.624376,0.132200,0.000000
109.490005,60.678467,-2.579895,0.010809,0.005200,0.132070,269.911316,13.749937,1.320697,-2.579895,0.132200,0.000000
109.770004,60.658356,-2.579895,0.010809,0.005200,0.132070,269.821838,13.745380,1.320697,-2.579895,0.132200,0.000000
110.050003,60.646442,-2.535414,0.010818,0.005200,0.132070,269.768860,13.742681,1.320697,-2.535414,0.132200,0.000000
110.330002,60.612556,-2.535414,0.010800,0.005200,0.132070,269.618103,13.735002,1.320697,-2.535414,0.132200,0.000000
110.610008,60.602501,-2.490933,0.010813,0.005200,0.132070,269.573395,13.732723,1.320697,-2.490933,0.132200,0.000000
110.890007,60.593937,-2.490933,0.010813,0.005200,0.132070,269.535278,13.730782,1.320697,-2.490933,0.132200,0.000000
111.170006,60.562656,-2.401971,0.010813,0.005200,0.132070,269.396149,13.723695,1.320697,-2.401971,0.132200,0.000000
111.450005,60.545155,-2.313010,0.010813,0.005200,0.132070,269.318298,13.719728,1.320697,-2.313010,0.132200,0.000000
111.730003,60.544411,-2.313010,0.010809,0.005200,0.132070,269.315002,13.719560,1.320697,-2.313010,0.132200,0.000000
112.010002,60.515366,-2.313010,0.010809,0.005200,0.132070,269.185791,13.712977,1.320697,-2.313010,0.132200,0.000000
112.290009,60.500099,-2.313010,0.010809,0.005200,0.132070,269.117889,13.709518,1.320697,-2.313010,0.132200,0.000000
112.570007,60.477383,-2.268528,0.010813,0.005200,0.132070,269.016846,13.704371,1.320697,-2.268528,0.132200,0.000000
112.850006,60.446476,-2.224048,0.010809,0.005200,0.132070,268.879364,13.697367,1.320697,-2.224048,0.132200,0.000000
113.130005,60.446106,-2.135086,0.010800,0.005200,0.132070,268.877716,13.697284,1.320697,-2.135086,0.132200,0.000000
113.410004,60.412964,-2.179567,0.010813,0.005200,0.132070,268.730286,13.689773,1.320697,-2.179567,0.132200,0.000000
113.690002,60.395462,-2.179567,0.010805,0.005200,0.132070,268.652435,13.685807,1.320697,-2.179567,0.132200,0.000000
113.970009,60.383175,-2.046124,0.010805,0.005200,0.132070,268.597778,13.683023,1.320697,-2.046124,0.132200,0.000000
114.250008,60.360832,-2.046124,0.010809,0.005200,0.132070,268.498383,13.677960,1.320697,-2.046124,0.132200,0.000000
114.530006,60.344074,-2.001643,0.010822,0.005200,0.132070,268.423859,13.674163,1.320697,-2.001643,0.132200,0.000000
114.810005,60.333649,-1.957162,0.010813,0.005200,0.132070,268.377472,13.671801,1.320697,-1.957162,0.132200,0.000000
115.090004,60.318752,-1.957162,0.010813,0.005200,0.132070,268.311218,13.668425,1.320697,-1.957162,0.132200,0.000000
115.370003,60.294922,-1.912681,0.010805,0.005200,0.132070,268.205200,13.663024,1.320697,-1.912681,0.132200,0.000000
115.650009,60.285984,-1.868200,0.010813,0.005200,0.132070,268.165436,13.660999,1.320697,-1.868200,0.132200,0.000000
115.930008,60.267738,-1.823719,0.010818,0.005200,0.132070,268.084290,13.656865,1.320697,-1.823719,0.132200,0.000000
116.210007,60.243908,-1.868200,0.010805,0.005200,0.132070,267.978271,13.651464,1.320697,-1.868200,0.132200,0.000000
116.490005,60.236458,-1.823719,0.010813,0.005200,0.132070,267.945160,13.649776,1.320697,-1.823719,0.132200,0.000000
116.770004,60.220448,-1.734757,0.010813,0.005199,0.132061,267.873932,13.646149,1.320612,-1.734757,0.132200,0.000000
117.050003,60.213371,-1.734757,0.010809,0.005199,0.132061,267.842438,13.644546,1.320612,-1.734757,0.132200,0.000000
117.330002,60.193264,-1.734757,0.010805,0.005199,0.132061,267.753021,13.639989,1.320612,-1.734757,0.132200,0.000000
117.610008,60.167942,-1.645795,0.010796,0.005199,0.132061,267.640381,13.634251,1.320612,-1.645795,0.132200,0.000000
117.890007,60.151188,-1.645795,0.010796,0.005199,0.132061,267.565857,13.630454,1.320612,-1.645795,0.132200,0.000000
118.170006,60.134800,-1.601314,0.010809,0.005199,0.132061,267.492950,13.626740,1.320612,-1.601314,0.132200,0.000000
118.450005,60.128845,-1.556833,0.010809,0.005199,0.132061,267.466461,13.625391,1.320612,-1.556833,0.132200,0.000000
118.730003,60.121769,-1.512352,0.010822,0.005199,0.132061,267.434998,13.623788,1.320612,-1.512352,0.132200,0.000000
119.010002,60.099800,-1.512352,0.010809,0.005199,0.132061,267.337250,13.618810,1.320612,-1.512352,0.132200,0.000000
119.290009,60.089001,-1.423390,0.010800,0.005199,0.132061,267.289215,13.616363,1.320612,-1.423390,0.132200,0.000000
119.400009,60.091606,-1.378909,0.010822,0.005199,0.132061,267.300812,13.616952,1.320612,-1.378909,0.132200,0.000000