File: Data/10% 30min RT - 1 - 2_07262023_150823.csv
Time (sec),S:Load (lbs),S:HL1 (DIM),S:LVDT (in),S:Position (in),Ch:Position (mm),Ch:Load (N),Ch:Stress (MPa),Ch:Strain (mm/mm),Ch:HL1 (DIM),Set Point (),Cycles ()
0.010000,-0.002979,-37.452961,0.000000,-0.000000,-0.000000,-0.013251,-0.000675,-0.000000,-37.452961,0.000113,0.000000
0.320000,0.001117,-37.452961,-0.000013,-0.000000,-0.000000,0.004969,0.000253,-0.000000,-37.452961,0.000113,0.000000
0.630000,-0.003351,-37.363998,-0.000013,0.000167,0.004241,-0.014907,-0.000759,0.042408,-37.363998,0.004935,0.000000
0.940000,0.012288,-37.275036,0.000009,0.000357,0.009071,0.054661,0.002785,0.090713,-37.275036,0.010103,0.000000
1.250000,0.027928,-37.408482,0.000254,0.000563,0.014301,0.124230,0.006329,0.143007,-37.408482,0.015272,0.000000
1.560000,0.020108,-37.230556,0.000470,0.000761,0.019339,0.089445,0.004557,0.193391,-37.230556,0.020441,0.000000
1.870000,-0.023832,-37.230556,0.000698,0.000964,0.024491,-0.106009,-0.005400,0.244905,-37.230556,0.025592,0.000000
2.180000,0.007075,-37.230556,0.000888,0.001160,0.029460,0.031471,0.001603,0.294597,-37.230556,0.030761,0.000000
2.490000,0.000745,-37.141594,0.001091,0.001367,0.034715,0.003313,0.000169,0.347151,-37.141594,0.035929,0.000000
2.800000,0.038354,-37.230556,0.001298,0.001579,0.040118,0.170609,0.008691,0.401180,-37.230556,0.041098,0.000000
3.110000,0.027183,-37.052631,0.001513,0.001773,0.045035,0.120917,0.006160,0.450351,-37.052631,0.046249,0.000000
3.420000,0.030907,-37.052631,0.001729,0.001983,0.050377,0.137481,0.007004,0.503771,-37.052631,0.051418,0.000000
3.730000,0.021970,-37.052631,0.001944,0.002188,0.055581,0.097727,0.004978,0.555806,-37.052631,0.056586,0.000000
4.040000,0.011544,-37.008152,0.002164,0.002385,0.060567,0.051348,0.002616,0.605670,-37.008152,0.061755,0.000000
4.350000,0.012661,-37.008152,0.002358,0.002592,0.065840,0.056318,0.002869,0.658398,-37.008152,0.066907,0.000000
4.660000,0.043568,-36.874710,0.002596,0.002792,0.070922,0.193798,0.009873,0.709217,-36.874710,0.072075,0.000000
4.970000,-0.006330,-36.919189,0.002794,0.003000,0.076203,-0.028159,-0.001434,0.762032,-36.919189,0.077244,0.000000
5.280000,0.049153,-36.830227,0.002992,0.003196,0.081190,0.218644,0.011138,0.811898,-36.830227,0.082412,0.000000
5.590000,0.035748,-36.830227,0.003208,0.003409,0.086593,0.159014,0.008101,0.865925,-36.830227,0.087564,0.000000
5.900000,0.018619,-36.830227,0.003415,0.003612,0.091752,0.082820,0.004219,0.917525,-36.830227,0.092733,0.000000
6.210001,0.033141,-36.696785,0.003604,0.003808,0.096730,0.147419,0.007510,0.967304,-36.696785,0.097901,0.000000
6.520000,-0.046174,-36.696785,0.003833,0.004017,0.102021,-0.205393,-0.010463,1.020205,-36.696785,0.103070,0.000000
6.830000,0.035375,-36.652302,0.004053,0.004212,0.106972,0.157358,0.008016,1.069723,-36.652302,0.108221,0.000000
7.140000,0.013405,-36.563343,0.004277,0.004423,0.112340,0.059630,0.003038,1.123404,-36.563343,0.113390,0.000000
7.450000,0.035748,-36.563343,0.004462,0.004627,0.117535,0.159014,0.008101,1.175352,-36.563343,0.118558,0.000000
7.760000,0.034258,-36.474380,0.004687,0.004828,0.122626,0.152389,0.007763,1.226257,-36.474380,0.123727,0.000000
8.070001,0.014150,-36.563343,0.004881,0.005035,0.127881,0.062943,0.003206,1.278812,-36.563343,0.128896,0.000000
8.380000,0.024204,-36.429897,0.005075,0.005231,0.132859,0.107666,0.005485,1.328591,-36.429897,0.134047,0.000000
8.690001,0.002234,-36.340939,0.005295,0.005434,0.138019,0.009938,0.000506,1.380190,-36.340939,0.139216,0.000000
9.000000,0.052132,-36.385418,0.005476,0.005641,0.143292,0.231895,0.011813,1.432918,-36.385418,0.144384,0.000000
9.310000,0.040589,-36.296455,0.005700,0.005842,0.148382,0.180547,0.009198,1.483824,-36.296455,0.149553,0.000000
9.620001,0.012288,-36.296455,0.005915,0.006049,0.153655,0.054661,0.002785,1.536550,-36.296455,0.154704,0.000000
9.930000,0.054739,-36.251976,0.006118,0.006254,0.158841,0.243490,0.012404,1.588411,-36.251976,0.159873,0.000000
10.240001,0.037237,-36.207493,0.006329,0.006454,0.163923,0.165640,0.008438,1.639230,-36.207493,0.165042,0.000000
10.550000,0.017129,-36.207493,0.006532,0.006660,0.169152,0.076194,0.003882,1.691524,-36.207493,0.170211,0.000000
10.860001,0.031652,-36.029572,0.006722,0.006858,0.174191,0.140794,0.007172,1.741911,-36.029572,0.175362,0.000000
11.170000,0.029045,-36.118534,0.006929,0.007066,0.179472,0.129199,0.006582,1.794723,-36.118534,0.180530,0.000000
11.480000,0.059207,-35.985088,0.007140,0.007260,0.184398,0.263367,0.013417,1.843982,-35.985088,0.185699,0.000000
11.790001,0.046919,-35.985088,0.007351,0.007470,0.189732,0.208706,0.010632,1.897317,-35.985088,0.190868,0.000000
12.100000,0.052505,-35.940609,0.007537,0.007680,0.195065,0.233552,0.011898,1.950652,-35.940609,0.196019,0.000000
12.410001,0.053249,-35.940609,0.007748,0.007877,0.200069,0.236865,0.012066,2.000690,-35.940609,0.201188,0.000000
12.720000,-0.007075,-35.851646,0.007942,0.008081,0.205255,-0.031471,-0.001603,2.052550,-35.851646,0.206356,0.000000
13.030001,0.032396,-35.807167,0.008144,0.008279,0.210276,0.144107,0.007341,2.102763,-35.807167,0.211525,0.000000
13.340001,0.042823,-35.762684,0.008360,0.008487,0.215575,0.190485,0.009704,2.155749,-35.762684,0.216676,0.000000
13.650001,0.070378,-35.718204,0.008558,0.008696,0.220882,0.313059,0.015948,2.208825,-35.718204,0.221845,0.000000
13.960001,0.061814,-35.718204,0.008770,0.008894,0.225912,0.274962,0.014007,2.259124,-35.718204,0.227014,0.000000
14.270000,0.035748,-35.718204,0.008968,0.009100,0.231133,0.159014,0.008101,2.311331,-35.718204,0.232182,0.000000
14.580001,0.046919,-35.584763,0.009149,0.009297,0.236154,0.208706,0.010632,2.361544,-35.584763,0.237351,0.000000
14.890000,0.026438,-35.584763,0.009360,0.009500,0.241306,0.117604,0.005991,2.413056,-35.584763,0.242502,0.000000
15.200001,0.034631,-35.540279,0.009550,0.009711,0.246648,0.154045,0.007847,2.466478,-35.540279,0.247671,0.000000
15.510001,0.072613,-35.451317,0.009757,0.009907,0.251625,0.322997,0.016454,2.516255,-35.451317,0.252840,0.000000
15.820001,0.024577,-35.451317,0.009968,0.010118,0.256985,0.109322,0.005569,2.569851,-35.451317,0.258008,0.000000
16.130001,0.072985,-35.362354,0.010158,0.010312,0.261919,0.324654,0.016539,2.619195,-35.362354,0.263160,0.000000
16.440001,0.046919,-35.317875,0.010374,0.010525,0.267340,0.208706,0.010632,2.673396,-35.317875,0.268328,0.000000
16.750000,0.056228,-35.317875,0.010568,0.010729,0.272517,0.250116,0.012742,2.725170,-35.317875,0.273497,0.000000
17.060001,0.063303,-35.273396,0.010774,0.010924,0.277460,0.281587,0.014345,2.774602,-35.273396,0.278666,0.000000
17.370001,-0.002607,-35.273396,0.010981,0.011131,0.282724,-0.011595,-0.000591,2.827243,-35.273396,0.283817,0.000000
17.680000,0.082667,-35.139950,0.011184,0.011330,0.287780,0.367720,0.018733,2.877801,-35.139950,0.288986,0.000000
17.990002,0.051760,-35.184433,0.011391,0.011538,0.293070,0.230239,0.011729,2.930703,-35.184433,0.294154,0.000000
18.300001,0.080805,-35.050991,0.011568,0.011746,0.298352,0.359438,0.018311,2.983517,-35.050991,0.299323,0.000000
18.610001,0.067027,-35.006508,0.011788,0.011946,0.303425,0.298151,0.015189,3.034250,-35.006508,0.304474,0.000000
18.920000,0.033141,-35.006508,0.011990,0.012148,0.308550,0.147419,0.007510,3.085503,-35.006508,0.309643,0.000000
19.230001,0.070378,-34.962029,0.012180,0.012345,0.313554,0.313059,0.015948,3.135541,-34.962029,0.314812,0.000000
19.540001,0.037237,-34.962029,0.012396,0.012553,0.318853,0.165640,0.008438,3.188530,-34.962029,0.319980,0.000000
19.850000,0.091976,-34.873066,0.012594,0.012758,0.324065,0.409130,0.020842,3.240650,-34.873066,0.325132,0.000000
20.160002,0.082667,-34.739624,0.012805,0.012959,0.329147,0.367720,0.018733,3.291470,-34.739624,0.330300,0.000000
20.470001,0.124372,-34.873066,0.013012,0.013166,0.334428,0.553236,0.028183,3.344282,-34.873066,0.335469,0.000000
20.780001,0.408493,-34.695141,0.013202,0.013369,0.339562,1.817066,0.092566,3.395622,-34.695141,0.340638,0.000000
21.090000,0.595424,-34.606178,0.013336,-0.000000,-0.000000,2.648576,0.134925,-0.000000,-34.606178,0.000243,0.000000
21.400002,0.552601,-34.606178,0.013340,-0.000000,-0.000000,2.458091,0.125221,-0.000000,-34.606178,0.000243,0.000000
21.710001,0.562282,-34.561699,0.013336,-0.000000,-0.000000,2.501157,0.127415,-0.000000,-34.561699,0.000642,0.000000
22.020000,0.546643,-34.517220,0.013318,-0.000000,-0.000000,2.431588,0.123871,-0.000000,-34.517220,0.001153,0.000000
22.330002,0.697826,-34.472736,0.013327,0.000026,0.000668,3.104085,0.158130,0.006677,-34.472736,0.001674,0.000000
22.640001,0.781610,-34.428257,0.013340,0.000049,0.001240,3.476774,0.177115,0.012401,-34.428257,0.002194,0.000000
22.950001,0.882895,-34.383774,0.013361,0.000074,0.001873,3.927314,0.200067,0.018731,-34.383774,0.002706,0.000000
23.260000,0.905237,-34.339294,0.013392,0.000090,0.002289,4.026697,0.205130,0.022895,-34.339294,0.003226,0.000000
23.570002,0.948805,-34.205853,0.013396,0.000107,0.002706,4.220496,0.215002,0.027056,-34.205853,0.003738,0.000000
23.880001,1.076529,-34.250332,0.013413,0.000127,0.003235,4.788639,0.243945,0.032348,-34.250332,0.004258,0.000000
24.190001,1.152865,-34.250332,0.013422,0.000147,0.003738,5.128201,0.261243,0.037376,-34.250332,0.004770,0.000000
24.500002,1.233298,-34.161369,0.013439,0.000168,0.004267,5.485981,0.279469,0.042667,-34.161369,0.005290,0.000000
24.810001,1.347988,-34.116890,0.013478,0.000194,0.004917,5.996152,0.305459,0.049171,-34.116890,0.005810,0.000000
25.120001,1.384853,-33.983448,0.013486,0.000209,0.005307,6.160134,0.313812,0.053074,-33.983448,0.006322,0.000000
25.430000,1.428793,-33.983448,0.013508,0.000228,0.005784,6.355589,0.323769,0.057843,-33.983448,0.006842,0.000000
25.740002,1.585934,-34.027927,0.013508,0.000249,0.006322,7.054588,0.359378,0.063219,-34.027927,0.007354,0.000000
26.050001,1.641045,-33.894485,0.013538,0.000266,0.006756,7.299735,0.371866,0.067557,-33.894485,0.007874,0.000000
26.360001,1.741214,-33.894485,0.013560,0.000283,0.007189,7.745305,0.394565,0.071892,-33.894485,0.008386,0.000000
26.670002,1.883832,-33.850002,0.013586,0.000311,0.007909,8.379704,0.426883,0.079091,-33.850002,0.008906,0.000000
26.980001,1.953466,-33.761044,0.013607,0.000333,0.008464,8.689450,0.442662,0.084640,-33.761044,0.009427,0.000000
27.290001,1.955328,-33.761044,0.013624,0.000352,0.008932,8.697733,0.443084,0.089324,-33.761044,0.009938,0.000000
27.600000,2.044325,-33.716560,0.013642,0.000369,0.009383,9.093611,0.463251,0.093833,-33.716560,0.010459,0.000000
27.910002,2.215616,-33.672081,0.013650,0.000390,0.009912,9.855554,0.502066,0.099123,-33.672081,0.010970,0.000000
28.220001,2.288229,-33.583118,0.013668,0.000408,0.010363,10.178550,0.518520,0.103632,-33.583118,0.011491,0.000000
28.530001,2.431220,-33.538635,0.013706,0.000430,0.010927,10.814606,0.550922,0.109270,-33.538635,0.012011,0.000000
28.840002,2.475160,-33.583118,0.013736,0.000454,0.011543,11.010060,0.560879,0.115428,-33.583118,0.012523,0.000000
29.150002,2.544421,-33.449677,0.013749,0.000473,0.012002,11.318150,0.576574,0.120023,-33.449677,0.013043,0.000000
29.460001,2.609959,-33.494156,0.013771,0.000491,0.012479,11.609676,0.591425,0.124794,-33.494156,0.013555,0.000000
29.770002,2.773430,-33.405193,0.013788,0.000512,0.013000,12.336833,0.628468,0.129996,-33.405193,0.014075,0.000000
30.080002,2.852001,-33.360714,0.013818,0.000530,0.013451,12.686333,0.646273,0.134506,-33.360714,0.014587,0.000000
30.390001,2.885142,-33.271751,0.013840,0.000546,0.013867,12.833752,0.653782,0.138669,-33.271751,0.015107,0.000000
30.700001,3.125695,-33.227272,0.013840,0.000573,0.014561,13.903784,0.708293,0.145607,-33.227272,0.015627,0.000000
31.010002,3.148782,-33.271751,0.013900,0.000594,0.015098,14.006480,0.713524,0.150983,-33.271751,0.016139,0.000000
31.320002,3.208734,-33.138309,0.013909,0.000615,0.015627,14.273160,0.727109,0.156273,-33.138309,0.016659,0.000000
31.630001,3.348746,-33.138309,0.013939,0.000636,0.016148,14.895965,0.758837,0.161477,-33.138309,0.017171,0.000000
31.940002,3.347628,-33.182789,0.013948,0.000648,0.016468,14.890995,0.758583,0.164685,-33.182789,0.017691,0.000000
32.250000,3.489502,-33.049347,0.013969,0.000670,0.017006,15.522082,0.790733,0.170063,-33.049347,0.018212,0.000000
32.560001,3.685370,-32.960384,0.014012,0.000695,0.017665,16.393345,0.835117,0.176652,-32.960384,0.018723,0.000000
32.870003,3.750163,-32.960384,0.014017,0.000718,0.018238,16.681559,0.849799,0.182377,-32.960384,0.019244,0.000000
33.180000,3.799316,-32.871422,0.014047,0.000738,0.018741,16.900202,0.860937,0.187407,-32.871422,0.019755,0.000000
33.490002,3.876025,-32.871422,0.014081,0.000758,0.019261,17.241421,0.878320,0.192610,-32.871422,0.020276,0.000000
33.800003,3.996301,-32.737980,0.014086,0.000776,0.019721,17.776436,0.905575,0.197206,-32.737980,0.020787,0.000000
34.110001,4.035773,-32.782459,0.014103,0.000791,0.020085,17.952015,0.914519,0.200849,-32.782459,0.021308,0.000000
34.420002,4.363088,-32.693501,0.014133,0.000821,0.020848,19.407986,0.988690,0.208480,-32.693501,0.021828,0.000000
34.730003,4.309839,-32.649017,0.014172,0.000840,0.021342,19.171120,0.976623,0.213423,-32.649017,0.022340,0.000000
35.040001,4.344842,-32.649017,0.014189,0.000860,0.021837,19.326822,0.984555,0.218368,-32.649017,0.022860,0.000000
35.350002,4.418571,-32.560055,0.014219,0.000880,0.022340,19.654787,1.001263,0.223396,-32.560055,0.023372,0.000000
35.660000,4.555605,-32.560055,0.014245,0.000898,0.022799,20.264343,1.032315,0.227993,-32.560055,0.023892,0.000000
35.970001,4.608854,-32.471096,0.014263,0.000915,0.023250,20.501207,1.044381,0.232502,-32.471096,0.024404,0.000000
36.280003,4.840097,-32.426613,0.014275,0.000938,0.023831,21.529829,1.096782,0.238312,-32.426613,0.024924,0.000000
36.590000,5.006548,-32.426613,0.014310,0.000961,0.024404,22.270237,1.134500,0.244037,-32.426613,0.025444,0.000000
36.900002,5.046391,-32.337650,0.014340,0.000983,0.024976,22.447470,1.143529,0.249760,-32.337650,0.025956,0.000000
37.210003,5.028518,-32.337650,0.014349,0.000999,0.025384,22.367964,1.139478,0.253836,-32.337650,0.026476,0.000000
37.520000,5.266836,-32.293171,0.014370,0.001024,0.025999,23.428057,1.193482,0.259994,-32.293171,0.026988,0.000000
37.830002,5.224758,-32.293171,0.014405,0.001038,0.026355,23.240885,1.183947,0.263550,-32.293171,0.027508,0.000000
38.140003,5.271677,-32.159729,0.014413,0.001054,0.026771,23.449591,1.194579,0.267711,-32.159729,0.028029,0.000000
38.450001,5.649635,-32.115246,0.014461,0.001086,0.027578,25.130833,1.280226,0.275777,-32.115246,0.028540,0.000000
38.760002,5.695065,-32.115246,0.014482,0.001106,0.028081,25.332912,1.290520,0.280807,-32.115246,0.029061,0.000000
39.070004,5.765071,-32.026283,0.014504,0.001125,0.028566,25.644316,1.306384,0.285663,-32.026283,0.029572,0.000000
39.380001,5.874920,-32.026283,0.014543,0.001147,0.029121,26.132948,1.331276,0.291214,-32.026283,0.030093,0.000000
39.690002,5.860770,-31.981804,0.014538,0.001162,0.029503,26.070007,1.328069,0.295029,-31.981804,0.030604,0.000000
40.000000,6.056266,-31.937323,0.014560,0.001184,0.030084,26.939615,1.372369,0.300840,-31.937323,0.031125,0.000000
40.310001,6.306128,-31.848360,0.014586,0.001210,0.030743,28.051056,1.428989,0.307430,-31.848360,0.031645,0.000000
40.620003,6.184361,-31.803881,0.014629,0.001227,0.031159,27.509413,1.401396,0.311593,-31.803881,0.032157,0.000000
40.930000,6.298680,-31.759399,0.014646,0.001247,0.031671,28.017929,1.427301,0.316711,-31.759399,0.032677,0.000000
41.240002,6.436458,-31.803881,0.014681,0.001269,0.032226,28.630793,1.458522,0.322261,-31.803881,0.033189,0.000000
41.550003,6.475929,-31.670437,0.014702,0.001286,0.032660,28.806372,1.467467,0.326597,-31.670437,0.033709,0.000000
41.860001,6.647965,-31.714918,0.014724,0.001308,0.033223,29.571627,1.506451,0.332234,-31.714918,0.034229,0.000000
42.170002,6.741803,-31.581474,0.014745,0.001330,0.033778,29.989038,1.527714,0.337783,-31.581474,0.034741,0.000000
42.480003,6.831545,-31.581474,0.014780,0.001350,0.034299,30.388229,1.548050,0.342987,-31.581474,0.035261,0.000000
42.790001,6.879953,-31.492514,0.014801,0.001370,0.034793,30.603561,1.559020,0.347930,-31.492514,0.035773,0.000000
43.100002,6.786860,-31.448032,0.014814,0.001382,0.035114,30.189463,1.537925,0.351140,-31.448032,0.036293,0.000000
43.410004,7.052362,-31.448032,0.014827,0.001407,0.035747,31.370476,1.598088,0.357470,-31.448032,0.036805,0.000000
43.720001,7.046404,-31.314590,0.014862,0.001423,0.036146,31.343969,1.596738,0.361459,-31.314590,0.037325,0.000000
44.030003,7.254560,-31.359070,0.014896,0.001447,0.036744,32.269897,1.643907,0.367443,-31.359070,0.037846,0.000000
44.340004,7.461972,-31.270109,0.014922,0.001473,0.037412,33.192509,1.690907,0.374120,-31.270109,0.038357,0.000000
44.650002,7.302224,-31.225628,0.014961,0.001489,0.037820,32.481915,1.654708,0.378196,-31.225628,0.038878,0.000000
44.960003,7.331269,-31.270109,0.014961,0.001506,0.038245,32.611115,1.661289,0.382447,-31.270109,0.039389,0.000000
45.270000,7.485432,-31.136665,0.015000,0.001526,0.038765,33.296864,1.696223,0.387649,-31.136665,0.039910,0.000000
45.580002,7.609431,-31.136665,0.015026,0.001546,0.039259,33.848442,1.724322,0.392592,-31.136665,0.040430,0.000000
45.890003,7.741251,-31.003223,0.015047,0.001567,0.039814,34.434803,1.754193,0.398143,-31.003223,0.040942,0.000000
46.200001,7.854452,-31.003223,0.015090,0.001593,0.040456,34.938347,1.779844,0.404560,-31.003223,0.041462,0.000000
46.510002,7.743857,-31.003223,0.015103,0.001608,0.040855,34.446400,1.754783,0.408549,-31.003223,0.041974,0.000000
46.820004,7.805672,-30.914261,0.015146,0.001631,0.041419,34.721363,1.768790,0.414187,-30.914261,0.042494,0.000000
47.130001,7.909936,-30.958742,0.015177,0.001650,0.041922,35.185154,1.792417,0.419217,-30.958742,0.043006,0.000000
47.440002,7.956482,-30.914261,0.015194,0.001668,0.042355,35.392200,1.802965,0.423552,-30.914261,0.043526,0.000000
47.750004,8.078248,-30.780819,0.015211,0.001687,0.042850,35.933842,1.830557,0.428496,-30.780819,0.044046,0.000000
48.060001,8.236879,-30.825298,0.015246,0.001712,0.043491,36.639469,1.866504,0.434913,-30.825298,0.044558,0.000000
48.370003,8.327738,-30.691856,0.015271,0.001734,0.044046,37.043629,1.887092,0.440463,-30.691856,0.045078,0.000000
48.680004,8.206345,-30.736338,0.015306,0.001753,0.044523,36.503643,1.859584,0.445232,-30.736338,0.045590,0.000000
48.990002,8.312843,-30.647375,0.015327,0.001771,0.044992,36.977375,1.883717,0.449916,-30.647375,0.046110,0.000000
49.300003,8.395882,-30.558413,0.015362,0.001792,0.045521,37.346748,1.902534,0.455206,-30.558413,0.046622,0.000000
49.610001,8.509083,-30.558413,0.015388,0.001811,0.046006,37.850292,1.928186,0.460063,-30.558413,0.047142,0.000000
49.920002,8.695642,-30.513933,0.015396,0.001834,0.046587,38.680145,1.970461,0.465873,-30.513933,0.047663,0.000000
50.230003,8.677396,-30.513933,0.015440,0.001854,0.047082,38.598984,1.966326,0.470816,-30.513933,0.048174,0.000000
50.540001,8.641648,-30.424971,0.015474,0.001874,0.047611,38.439972,1.958225,0.476106,-30.424971,0.048695,0.000000
50.850002,8.716867,-30.336008,0.015491,0.001894,0.048105,38.774563,1.975270,0.481049,-30.336008,0.049206,0.000000
51.160004,8.882200,-30.380489,0.015509,0.001914,0.048608,39.509998,2.012735,0.486079,-30.380489,0.049727,0.000000
51.470001,8.824855,-30.202566,0.015547,0.001931,0.049041,39.254913,1.999741,0.490415,-30.202566,0.050247,0.000000
51.780003,9.009552,-30.202566,0.015573,0.001951,0.049562,40.076488,2.041594,0.495619,-30.202566,0.050759,0.000000
52.090004,9.294789,-30.113604,0.015603,0.001978,0.050238,41.345287,2.106229,0.502382,-30.113604,0.051279,0.000000
52.400002,9.300747,-30.158085,0.015638,0.002001,0.050819,41.371788,2.107579,0.508194,-30.158085,0.051791,0.000000
52.710003,9.168555,-30.113604,0.015668,0.002018,0.051253,40.783772,2.077624,0.512530,-30.113604,0.052311,0.000000
53.020004,9.246009,-30.024641,0.015707,0.002036,0.051721,41.128300,2.095176,0.517213,-30.024641,0.052823,0.000000
53.330002,9.228134,-30.113604,0.015728,0.002055,0.052190,41.048790,2.091125,0.521895,-30.113604,0.053343,0.000000
53.640003,9.316387,-29.935680,0.015750,0.002073,0.052649,41.441360,2.111124,0.526492,-29.935680,0.053863,0.000000
53.950001,9.634021,-29.935680,0.015789,0.002100,0.053343,42.854263,2.183100,0.533430,-29.935680,0.054375,0.000000
54.260002,9.672375,-29.935680,0.015806,0.002122,0.053898,43.024872,2.191791,0.538980,-29.935680,0.054895,0.000000
54.570004,9.616892,-29.846718,0.015836,0.002140,0.054366,42.778072,2.179219,0.543662,-29.846718,0.055407,0.000000
54.880001,9.786321,-29.802237,0.015858,0.002163,0.054939,43.531727,2.217612,0.549387,-29.802237,0.055927,0.000000
55.190002,9.725997,-29.624313,0.015888,0.002181,0.055407,43.263393,2.203942,0.554069,-29.624313,0.056448,0.000000
55.500004,9.642958,-29.713276,0.015910,0.002194,0.055728,42.894016,2.185126,0.557278,-29.713276,0.056959,0.000000
55.810001,10.211571,-29.668795,0.015953,0.002227,0.056569,45.423336,2.313975,0.565690,-29.668795,0.057480,0.000000
56.120003,10.053312,-29.624313,0.015987,0.002245,0.057020,44.719368,2.278113,0.570200,-29.624313,0.057991,0.000000
56.430004,10.036927,-29.624313,0.016013,0.002265,0.057523,44.646481,2.274400,0.575230,-29.624313,0.058512,0.000000
56.740002,10.091666,-29.535351,0.016052,0.002282,0.057965,44.889973,2.286804,0.579653,-29.535351,0.059023,0.000000
57.050003,10.151246,-29.446390,0.016060,0.002302,0.058468,45.154999,2.300305,0.584683,-29.446390,0.059544,0.000000
57.360004,10.221996,-29.401909,0.016091,0.002320,0.058936,45.469711,2.316337,0.589365,-29.401909,0.060064,0.000000
57.670002,10.527715,-29.357428,0.016129,0.002344,0.059526,46.829613,2.385614,0.595264,-29.357428,0.060576,0.000000
57.980003,10.558993,-29.401909,0.016147,0.002365,0.060081,46.968750,2.392702,0.600812,-29.401909,0.061096,0.000000
58.290001,10.543727,-29.312946,0.016194,0.002388,0.060654,46.900841,2.389243,0.606537,-29.312946,0.061608,0.000000
58.600002,10.454729,-29.223986,0.016211,0.002403,0.061035,46.504959,2.369076,0.610352,-29.223986,0.062128,0.000000
58.910004,10.757468,-29.223986,0.016233,0.002429,0.061694,47.851608,2.437677,0.616944,-29.223986,0.062640,0.000000
59.220001,10.556015,-29.179504,0.016285,0.002444,0.062067,46.955502,2.392027,0.620674,-29.179504,0.063160,0.000000
59.530003,11.096327,-29.135023,0.016302,0.002472,0.062796,49.358929,2.514464,0.627958,-29.135023,0.063680,0.000000
59.840004,10.849072,-29.046061,0.016336,0.002490,0.063255,48.259079,2.458435,0.632554,-29.046061,0.064192,0.000000
60.150002,10.866946,-29.046061,0.016354,0.002510,0.063750,48.338593,2.462485,0.637497,-29.046061,0.064712,0.000000
60.460003,10.921312,-29.001579,0.016379,0.002531,0.064296,48.580425,2.474805,0.642961,-29.001579,0.065224,0.000000
60.770004,10.993180,-28.912619,0.016410,0.002553,0.064834,48.900108,2.491090,0.648337,-28.912619,0.065744,0.000000
61.080002,10.836783,-28.912619,0.016427,0.002566,0.065181,48.204422,2.455650,0.651806,-28.912619,0.066265,0.000000
61.390003,11.180111,-28.868137,0.016461,0.002592,0.065840,49.731617,2.533449,0.658398,-28.868137,0.066776,0.000000
61.700005,11.277673,-28.868137,0.016466,0.002614,0.066403,50.165592,2.555557,0.664033,-28.868137,0.067297,0.000000
62.010002,11.165961,-28.779175,0.016492,0.002632,0.066863,49.668674,2.530243,0.668630,-28.779175,0.067808,0.000000
62.320004,11.157024,-28.779175,0.016513,0.002652,0.067349,49.628922,2.528218,0.673486,-28.779175,0.068329,0.000000
62.630001,11.340976,-28.690214,0.016535,0.002674,0.067921,50.447178,2.569902,0.679211,-28.690214,0.068840,0.000000
62.940002,11.250862,-28.601252,0.016569,0.002692,0.068372,50.046333,2.549482,0.683720,-28.601252,0.069361,0.000000
63.250004,11.509288,-28.645733,0.016586,0.002715,0.068953,51.195869,2.608042,0.689530,-28.645733,0.069881,0.000000
63.560001,11.525300,-28.467808,0.016595,0.002735,0.069473,51.267094,2.611670,0.694735,-28.467808,0.070393,0.000000
63.870003,11.461625,-28.512289,0.016642,0.002754,0.069950,50.983856,2.597241,0.699503,-28.512289,0.070913,0.000000
64.180000,11.444868,-28.467808,0.016651,0.002772,0.070410,50.909317,2.593444,0.704100,-28.467808,0.071425,0.000000
64.490005,11.506310,-28.378847,0.016673,0.002791,0.070887,51.182621,2.607367,0.708869,-28.378847,0.071945,0.000000
64.800003,11.617276,-28.423328,0.016677,0.002811,0.071390,51.676224,2.632512,0.713899,-28.423328,0.072465,0.000000
65.110001,11.709624,-28.289885,0.016703,0.002829,0.071858,52.087009,2.653439,0.718583,-28.289885,0.072977,0.000000
65.420006,12.025769,-28.289885,0.016733,0.002856,0.072543,53.493294,2.725078,0.725434,-28.289885,0.073497,0.000000
65.730003,11.887246,-28.245403,0.016759,0.002874,0.073012,52.877113,2.693688,0.730116,-28.245403,0.074009,0.000000
66.040001,11.751330,-28.156443,0.016785,0.002893,0.073480,52.272530,2.662889,0.734800,-28.156443,0.074529,0.000000
66.350006,11.567751,-28.156443,0.016785,0.002906,0.073809,51.455925,2.621290,0.738094,-28.156443,0.075041,0.000000
66.660004,11.957997,-28.067480,0.016815,0.002932,0.074469,53.191830,2.709721,0.744686,-28.067480,0.075561,0.000000
66.970001,12.023907,-28.067480,0.016836,0.002952,0.074980,53.485008,2.724656,0.749803,-28.067480,0.076082,0.000000
67.280006,12.332603,-28.022999,0.016867,0.002977,0.075613,54.858158,2.794608,0.756133,-28.022999,0.076593,0.000000
67.590004,12.217541,-27.978518,0.016893,0.002995,0.076073,54.346336,2.768534,0.760730,-27.978518,0.077114,0.000000
67.900002,12.214934,-27.934038,0.016893,0.003016,0.076602,54.334743,2.767944,0.766019,-27.934038,0.077625,0.000000
68.210007,12.116256,-27.845076,0.016923,0.003031,0.076992,53.895798,2.745583,0.769921,-27.845076,0.078146,0.000000
68.520004,12.270417,-27.845076,0.016944,0.003052,0.077521,54.581543,2.780516,0.775213,-27.845076,0.078666,0.000000
68.830002,12.219402,-27.845076,0.016966,0.003070,0.077989,54.354614,2.768956,0.779895,-27.845076,0.079178,0.000000
69.140007,12.362766,-27.800594,0.016996,0.003092,0.078527,54.992332,2.801443,0.785273,-27.800594,0.079698,0.000000
69.450005,12.596616,-27.711632,0.017018,0.003115,0.079117,56.032547,2.854434,0.791170,-27.711632,0.080210,0.000000
69.760002,12.621565,-27.622671,0.017048,0.003139,0.079741,56.143524,2.860088,0.797413,-27.622671,0.080730,0.000000
70.070000,12.390694,-27.622671,0.017056,0.003155,0.080149,55.116558,2.807771,0.801489,-27.622671,0.081242,0.000000
70.380005,12.412292,-27.578190,0.017078,0.003174,0.080626,55.212631,2.812666,0.806258,-27.578190,0.081762,0.000000
70.690002,12.600712,-27.533709,0.017104,0.003193,0.081103,56.050766,2.855362,0.811029,-27.533709,0.082282,0.000000
71.000000,12.661781,-27.489227,0.017112,0.003212,0.081597,56.322414,2.869201,0.815972,-27.489227,0.082794,0.000000
71.310005,13.107511,-27.400267,0.017151,0.003242,0.082334,58.305119,2.970204,0.823343,-27.400267,0.083314,0.000000
71.620003,12.949997,-27.444746,0.017156,0.003260,0.082794,57.604462,2.934511,0.827940,-27.444746,0.083826,0.000000
71.930000,12.906802,-27.400267,0.017181,0.003279,0.083297,57.412323,2.924723,0.832970,-27.400267,0.084346,0.000000
72.240005,12.980532,-27.400267,0.017216,0.003299,0.083783,57.740288,2.941431,0.837826,-27.400267,0.084858,0.000000
72.550003,13.099319,-27.266823,0.017229,0.003319,0.084312,58.268681,2.968348,0.843116,-27.266823,0.085378,0.000000
72.860001,13.026706,-27.222342,0.017255,0.003335,0.084719,57.945683,2.951894,0.847192,-27.222342,0.085899,0.000000
73.170006,12.916856,-27.222342,0.017272,0.003350,0.085092,57.457043,2.927001,0.850922,-27.222342,0.086410,0.000000
73.480003,13.518238,-27.088900,0.017311,0.003383,0.085916,60.132126,3.063277,0.859160,-27.088900,0.086931,0.000000
73.790001,13.382694,-27.088900,0.017328,0.003403,0.086428,59.529198,3.032562,0.864277,-27.088900,0.087442,0.000000
74.100006,13.191668,-27.133381,0.017337,0.003421,0.086896,58.679466,2.989275,0.868959,-27.133381,0.087963,0.000000
74.410004,13.123151,-26.999937,0.017367,0.003439,0.087347,58.374691,2.973748,0.873469,-26.999937,0.088483,0.000000
74.720001,13.540953,-26.999937,0.017388,0.003462,0.087945,60.233166,3.068424,0.879453,-26.999937,0.088995,0.000000
75.030006,13.550634,-26.955456,0.017393,0.003481,0.088405,60.276234,3.070617,0.884049,-26.955456,0.089515,0.000000
75.340004,13.726767,-26.910975,0.017449,0.003504,0.089003,61.059708,3.110530,0.890033,-26.910975,0.090027,0.000000
75.650002,13.730863,-26.866495,0.017457,0.003525,0.089541,61.077927,3.111458,0.895410,-26.866495,0.090547,0.000000
75.960007,13.589733,-26.777533,0.017479,0.003544,0.090009,60.450153,3.079478,0.900093,-26.777533,0.091059,0.000000
76.270004,13.796772,-26.733051,0.017509,0.003568,0.090616,61.371105,3.126393,0.906163,-26.733051,0.091579,0.000000
76.580002,13.491426,-26.644089,0.017531,0.003581,0.090946,60.012863,3.057201,0.909459,-26.644089,0.092099,0.000000
76.890007,13.426262,-26.688570,0.017548,0.003599,0.091414,59.722996,3.042434,0.914141,-26.688570,0.092611,0.000000
77.200005,14.090574,-26.599609,0.017582,0.003627,0.092134,62.678005,3.192970,0.921340,-26.599609,0.093131,0.000000
77.510002,13.975883,-26.555128,0.017613,0.003648,0.092672,62.167835,3.166980,0.926716,-26.555128,0.093643,0.000000
77.820007,13.858213,-26.599609,0.017617,0.003667,0.093149,61.644413,3.140316,0.931487,-26.599609,0.094163,0.000000
78.130005,14.039559,-26.466166,0.017656,0.003689,0.093695,62.451080,3.181410,0.936951,-26.466166,0.094684,0.000000
78.440002,13.946838,-26.466166,0.017673,0.003706,0.094120,62.038635,3.160399,0.941199,-26.466166,0.095195,0.000000
78.750000,13.956893,-26.377205,0.017690,0.003722,0.094545,62.083359,3.162677,0.945448,-26.377205,0.095716,0.000000
79.060005,14.362034,-26.332724,0.017729,0.003749,0.095221,63.885517,3.254483,0.952213,-26.332724,0.096227,0.000000
79.370003,14.319956,-26.377205,0.017763,0.003769,0.095733,63.698345,3.244948,0.957331,-26.377205,0.096748,0.000000
79.680000,14.295007,-26.243761,0.017776,0.003789,0.096253,63.587364,3.239295,0.962533,-26.243761,0.097259,0.000000
79.990005,14.442466,-26.288242,0.017798,0.003810,0.096774,64.243294,3.272710,0.967737,-26.288242,0.097780,0.000000
80.300003,14.430178,-26.199280,0.017824,0.003829,0.097268,64.188637,3.269925,0.972680,-26.199280,0.098300,0.000000
80.610001,14.298358,-26.110319,0.017832,0.003845,0.097667,63.602272,3.240054,0.976669,-26.110319,0.098812,0.000000
80.920006,15.066935,-26.110319,0.017876,0.003875,0.098421,67.021072,3.414216,0.984215,-26.110319,0.099332,0.000000
81.230003,14.830106,-26.021357,0.017884,0.003892,0.098864,65.967606,3.360550,0.988637,-26.021357,0.099844,0.000000
81.540001,14.906815,-26.021357,0.017910,0.003914,0.099410,66.308823,3.377933,0.994101,-26.021357,0.100364,0.000000
81.850006,15.157794,-25.976875,0.017945,0.003936,0.099965,67.425232,3.434805,0.999649,-25.976875,0.100876,0.000000
82.160004,15.234130,-25.843433,0.017970,0.003955,0.100468,67.764793,3.452103,1.004680,-25.843433,0.101396,0.000000
82.470001,15.193542,-25.887913,0.017975,0.003972,0.100884,67.584251,3.442906,1.008843,-25.887913,0.101916,0.000000
82.780006,15.671295,-25.798952,0.018014,0.003995,0.101483,69.709404,3.551166,1.014827,-25.798952,0.102428,0.000000
83.090004,15.806466,-25.843433,0.018039,0.004016,0.102012,70.310677,3.581796,1.020116,-25.843433,0.102948,0.000000
83.400002,15.984088,-25.754471,0.018052,0.004037,0.102532,71.100777,3.622046,1.025321,-25.754471,0.103460,0.000000
83.710007,16.214586,-25.665508,0.018083,0.004058,0.103061,72.126083,3.674278,1.030610,-25.665508,0.103980,0.000000
84.020004,16.425722,-25.709990,0.018083,0.004077,0.103555,73.065262,3.722122,1.035553,-25.709990,0.104501,0.000000
84.330002,16.498707,-25.576548,0.018117,0.004094,0.103989,73.389915,3.738661,1.039890,-25.576548,0.105012,0.000000
84.640007,17.032688,-25.532066,0.018143,0.004118,0.104596,75.765182,3.859662,1.045959,-25.532066,0.105533,0.000000
84.950005,17.322395,-25.532066,0.018151,0.004139,0.105134,77.053864,3.925311,1.051338,-25.532066,0.106044,0.000000
85.260002,17.529062,-25.443104,0.018199,0.004159,0.105645,77.973160,3.972142,1.056453,-25.443104,0.106565,0.000000
85.570007,17.578587,-25.443104,0.018208,0.004174,0.106027,78.193459,3.983365,1.060270,-25.443104,0.107076,0.000000
85.880005,18.037350,-25.354141,0.018225,0.004195,0.106547,80.234138,4.087322,1.065472,-25.354141,0.107597,0.000000
86.190002,18.446960,-25.354141,0.018246,0.004214,0.107042,82.056175,4.180141,1.070416,-25.354141,0.108117,0.000000
86.500008,18.752678,-25.265181,0.018259,0.004233,0.107527,83.416077,4.249417,1.075272,-25.265181,0.108629,0.000000
86.810005,19.775585,-25.220699,0.018294,0.004262,0.108264,87.966194,4.481212,1.082645,-25.220699,0.109149,0.000000
87.120003,19.672438,-25.220699,0.018307,0.004278,0.108663,87.507370,4.457838,1.086634,-25.220699,0.109661,0.000000
87.430008,19.965122,-25.131737,0.018315,0.004298,0.109158,88.809296,4.524161,1.091577,-25.131737,0.110181,0.000000
87.740005,20.207909,-25.131737,0.018341,0.004315,0.109600,89.889267,4.579177,1.096000,-25.131737,0.110701,0.000000
88.050003,20.869987,-25.042776,0.018346,0.004336,0.110129,92.834343,4.729207,1.101289,-25.042776,0.111213,0.000000
88.360001,21.268799,-25.042776,0.018376,0.004354,0.110589,94.608345,4.819579,1.105886,-25.042776,0.111733,0.000000
88.670006,22.382193,-24.998295,0.018393,0.004382,0.111308,99.560966,5.071877,1.113083,-24.998295,0.112245,0.000000
88.980003,22.459646,-24.909332,0.018410,0.004400,0.111751,99.905495,5.089428,1.117505,-24.909332,0.112765,0.000000
89.290001,23.020065,-24.909332,0.018445,0.004421,0.112297,102.398361,5.216421,1.122971,-24.909332,0.113277,0.000000
89.600006,23.166037,-24.820372,0.018458,0.004437,0.112696,103.047676,5.249499,1.126958,-24.820372,0.113797,0.000000
89.910004,23.975201,-24.820372,0.018471,0.004458,0.113234,106.647018,5.432858,1.132336,-24.820372,0.114318,0.000000
90.220001,24.563923,-24.775890,0.018483,0.004478,0.113737,109.265785,5.566264,1.137367,-24.775890,0.114829,0.000000
90.530006,25.467670,-24.686928,0.018505,0.004501,0.114335,113.285858,5.771057,1.143350,-24.686928,0.115350,0.000000
90.840004,26.069052,-24.731409,0.018505,0.004521,0.114838,115.960930,5.907331,1.148379,-24.731409,0.115861,0.000000
91.150002,26.603407,-24.642447,0.018531,0.004543,0.115402,118.337868,6.028418,1.154016,-24.642447,0.116382,0.000000
91.460007,26.829435,-24.597965,0.018552,0.004558,0.115775,119.343292,6.079637,1.157746,-24.597965,0.116893,0.000000
91.770004,27.830374,-24.597965,0.018552,0.004581,0.116347,123.795685,6.306453,1.163469,-24.597965,0.117414,0.000000
92.080002,28.320787,-24.420042,0.018596,0.004598,0.116780,125.977158,6.417582,1.167805,-24.420042,0.117934,0.000000
92.390007,29.232729,-24.553486,0.018587,0.004623,0.117422,130.033676,6.624231,1.174222,-24.553486,0.118446,0.000000
92.700005,30.439587,-24.375561,0.018613,0.004646,0.118012,135.402039,6.897709,1.180121,-24.375561,0.118966,0.000000
93.010002,30.775467,-24.375561,0.018634,0.004665,0.118480,136.896118,6.973820,1.184803,-24.375561,0.119478,0.000000
93.320007,31.562662,-24.331079,0.018634,0.004684,0.118975,140.397736,7.152202,1.189746,-24.331079,0.119998,0.000000
93.630005,32.475346,-24.286600,0.018665,0.004704,0.119486,144.457550,7.359018,1.194863,-24.286600,0.120518,0.000000
93.940002,33.279671,-24.286600,0.018673,0.004723,0.119972,148.035370,7.541281,1.199719,-24.286600,0.121030,0.000000
94.250008,33.723911,-24.197638,0.018695,0.004738,0.120345,150.011444,7.641948,1.203449,-24.197638,0.121550,0.000000
94.560005,35.261810,-24.153156,0.018703,0.004765,0.121039,156.852371,7.990440,1.210387,-24.153156,0.122062,0.000000
94.870003,36.374084,-24.019714,0.018708,0.004789,0.121628,161.800003,8.242485,1.216284,-24.019714,0.122582,0.000000
95.180008,37.276344,-24.064194,0.018734,0.004807,0.122097,165.813461,8.446939,1.220966,-24.064194,0.123094,0.000000
95.490005,38.027420,-24.064194,0.018738,0.004827,0.122608,169.154419,8.617137,1.226083,-24.064194,0.123614,0.000000
95.800003,38.779610,-23.930752,0.018751,0.004843,0.123007,172.500320,8.787585,1.230072,-23.930752,0.124135,0.000000
96.110008,39.827839,-23.975233,0.018764,0.004862,0.123502,177.163071,9.025118,1.235015,-23.975233,0.124646,0.000000
96.420006,41.341160,-23.930752,0.018764,0.004890,0.124204,183.894669,9.368041,1.242040,-23.930752,0.125167,0.000000
96.730003,42.239323,-23.841789,0.018785,0.004908,0.124672,187.889893,9.571568,1.246724,-23.841789,0.125678,0.000000
97.040001,43.436501,-23.841789,0.018790,0.004930,0.125210,193.215210,9.842852,1.252100,-23.841789,0.126199,0.000000
97.350006,44.243431,-23.708347,0.018811,0.004946,0.125635,196.804611,10.025705,1.256349,-23.708347,0.126719,0.000000
97.660004,45.763458,-23.752829,0.018811,0.004970,0.126251,203.566025,10.370148,1.262507,-23.752829,0.127231,0.000000
97.970001,46.406544,-23.619385,0.018815,0.004986,0.126641,206.426620,10.515873,1.266409,-23.619385,0.127751,0.000000
98.280006,48.243832,-23.619385,0.018850,0.005012,0.127317,214.599274,10.932209,1.273172,-23.619385,0.128263,0.000000
98.590004,49.411591,-23.619385,0.018850,0.005032,0.127803,219.793732,11.196826,1.278030,-23.619385,0.128783,0.000000
98.900002,50.611000,-23.485943,0.018863,0.005052,0.128332,225.128967,11.468616,1.283320,-23.485943,0.129295,0.000000
99.210007,51.488682,-23.485943,0.018867,0.005068,0.128722,229.033096,11.667502,1.287222,-23.485943,0.129815,0.000000
99.520004,52.930138,-23.485943,0.018876,0.005090,0.129295,235.445007,11.994141,1.292947,-23.485943,0.130335,0.000000
99.830002,53.890488,-23.396980,0.018906,0.005106,0.129685,239.716858,12.211760,1.296849,-23.396980,0.130847,0.000000
100.140007,54.848228,-23.352499,0.018880,0.005124,0.130162,243.977112,12.428786,1.301618,-23.352499,0.131367,0.000000
100.450005,57.212048,-23.396980,0.018906,0.005153,0.130890,254.491898,12.964436,1.308904,-23.396980,0.131879,0.000000
100.760002,58.817719,-23.352499,0.018910,0.005176,0.131471,261.634277,13.328285,1.314714,-23.352499,0.132399,0.000000
101.070007,59.860363,-23.219057,0.018928,0.005192,0.131870,266.272186,13.564551,1.318703,-23.219057,0.132920,0.000000
101.380005,61.428795,-23.219057,0.018940,0.005215,0.132451,273.248932,13.919964,1.324513,-23.219057,0.133431,0.000000
101.690002,62.581287,-23.130095,0.018932,0.005231,0.132876,278.375458,14.181122,1.328763,-23.130095,0.133952,0.000000
102.000008,63.645901,-23.085613,0.018945,0.005247,0.133267,283.111115,14.422367,1.332665,-23.085613,0.134463,0.000000
102.310005,66.453590,-23.085613,0.018945,0.005278,0.134073,295.600342,15.058599,1.340731,-23.085613,0.134984,0.000000
102.620003,67.456017,-23.041132,0.018962,0.005286,0.134273,300.059357,15.285751,1.342726,-23.041132,0.135461,0.000000
102.930008,66.757812,-22.996653,0.018962,0.005284,0.134212,296.953583,15.127537,1.342118,-22.996653,0.134463,0.000000
103.240005,66.175423,-22.952171,0.018979,0.005281,0.134142,294.362976,14.995564,1.341424,-22.952171,0.134212,0.000000
103.550003,65.691711,-22.907690,0.018971,0.005281,0.134125,292.211334,14.885955,1.341251,-22.907690,0.134212,0.000000
103.860008,65.336845,-22.907690,0.018975,0.005280,0.134108,290.632812,14.805541,1.341077,-22.907690,0.134212,0.000000
104.170006,64.991653,-22.818727,0.018975,0.005279,0.134099,289.097321,14.727320,1.340990,-22.818727,0.134212,0.000000
104.480003,64.703064,-22.774246,0.018984,0.005279,0.134099,287.813599,14.661924,1.340990,-22.774246,0.134212,0.000000
104.790009,64.449112,-22.685286,0.018975,0.005279,0.134099,286.683960,14.604378,1.340990,-22.685286,0.134212,0.000000
105.100006,64.247284,-22.685286,0.018984,0.005279,0.134090,285.786194,14.558642,1.340903,-22.685286,0.134212,0.000000
105.410004,64.036522,-22.685286,0.018992,0.005279,0.134090,284.848663,14.510883,1.340903,-22.685286,0.134212,0.000000
105.720001,63.856289,-22.596323,0.018971,0.005279,0.134090,284.046967,14.470041,1.340903,-22.596323,0.134212,0.000000
106.030006,63.695427,-22.596323,0.018992,0.005279,0.134090,283.331421,14.433590,1.340903,-22.596323,0.134212,0.000000
106.340004,63.555412,-22.507360,0.018984,0.005279,0.134090,282.708588,14.401862,1.340903,-22.507360,0.134212,0.000000
106.650002,63.408699,-22.462881,0.019001,0.005279,0.134090,282.055969,14.368617,1.340903,-22.462881,0.134212,0.000000
106.960007,63.270920,-22.373919,0.018997,0.005279,0.134090,281.443115,14.337396,1.340903,-22.373919,0.134212,0.000000
107.270004,63.161442,-22.418400,0.018988,0.005279,0.134090,280.956116,14.312588,1.340903,-22.418400,0.134212,0.000000
107.580002,63.054573,-22.329437,0.018997,0.005279,0.134082,280.480743,14.288371,1.340816,-22.329437,0.134212,0.000000
107.890007,62.945465,-22.284956,0.018992,0.005279,0.134082,279.995422,14.263646,1.340816,-22.284956,0.134212,0.000000
108.200005,62.834499,-22.240475,0.018997,0.005279,0.134082,279.501801,14.238502,1.340816,-22.240475,0.134212,0.000000
108.510002,62.748482,-22.240475,0.018984,0.005279,0.134082,279.119202,14.219009,1.340816,-22.240475,0.134212,0.000000
108.820007,62.653900,-22.151514,0.018988,0.005279,0.134082,278.698456,14.197577,1.340816,-22.151514,0.134212,0.000000
109.130005,62.569000,-22.195995,0.018992,0.005279,0.134082,278.320801,14.178338,1.340816,-22.195995,0.134212,0.000000
109.440002,62.496014,-21.973589,0.018997,0.005279,0.134082,277.996155,14.161798,1.340816,-21.973589,0.134212,0.000000
109.750008,62.413719,-22.062551,0.018997,0.005279,0.134082,277.630096,14.143150,1.340816,-22.062551,0.134212,0.000000
110.060005,62.330307,-22.018070,0.018992,0.005279,0.134082,277.259064,14.124249,1.340816,-22.018070,0.134212,0.000000
110.370003,62.267750,-21.973589,0.019001,0.005279,0.134082,276.980774,14.110074,1.340816,-21.973589,0.134212,0.000000
110.680008,62.220085,-21.929110,0.019001,0.005279,0.134082,276.768768,14.099273,1.340816,-21.929110,0.134212,0.000000
110.990005,62.141144,-21.795666,0.019005,0.005279,0.134082,276.417603,14.081385,1.340816,-21.795666,0.134212,0.000000
111.300003,62.081562,-21.751184,0.019005,0.005279,0.134082,276.152588,14.067883,1.340816,-21.751184,0.134212,0.000000
111.610008,62.018261,-21.795666,0.018992,0.005279,0.134082,275.871002,14.053538,1.340816,-21.795666,0.134212,0.000000
111.920006,61.969479,-21.662224,0.018997,0.005279,0.134082,275.654022,14.042485,1.340816,-21.662224,0.134212,0.000000
112.230003,61.916973,-21.706703,0.018984,0.005279,0.134082,275.420441,14.030586,1.340816,-21.706703,0.134212,0.000000
112.540009,61.854042,-21.573261,0.018997,0.005279,0.134082,275.140533,14.016326,1.340816,-21.573261,0.134212,0.000000
112.850006,61.801910,-21.573261,0.019001,0.005278,0.134073,274.908630,14.004514,1.340731,-21.573261,0.134212,0.000000
113.160004,61.766163,-21.528780,0.018997,0.005278,0.134073,274.749603,13.996413,1.340731,-21.528780,0.134212,0.000000
113.470009,61.708073,-21.528780,0.019001,0.005278,0.134073,274.491211,13.983249,1.340731,-21.528780,0.134212,0.000000
113.780006,61.667110,-21.484299,0.018992,0.005278,0.134073,274.309021,13.973968,1.340731,-21.484299,0.134212,0.000000
114.090004,61.609394,-21.395338,0.018997,0.005278,0.134073,274.052277,13.960888,1.340731,-21.395338,0.134212,0.000000
114.400009,61.569550,-21.395338,0.019001,0.005278,0.134073,273.875031,13.951859,1.340731,-21.395338,0.134212,0.000000
114.710007,61.542366,-21.350857,0.018992,0.005278,0.134073,273.754120,13.945700,1.340731,-21.350857,0.134212,0.000000
115.020004,61.502895,-21.306376,0.019001,0.005278,0.134073,273.578552,13.936755,1.340731,-21.306376,0.134212,0.000000
115.330002,61.436985,-21.261894,0.018997,0.005278,0.134073,273.285370,13.921820,1.340731,-21.261894,0.134212,0.000000
115.640007,61.412781,-21.172934,0.019001,0.005278,0.134073,273.177704,13.916335,1.340731,-21.172934,0.134212,0.000000
115.950005,61.366982,-21.172934,0.019009,0.005278,0.134073,272.973969,13.905956,1.340731,-21.172934,0.134212,0.000000
116.260002,61.329369,-21.083971,0.018997,0.005278,0.134073,272.806671,13.897433,1.340731,-21.083971,0.134212,0.000000
116.570007,61.304794,-20.995008,0.019009,0.005278,0.134073,272.697357,13.891865,1.340731,-20.995008,0.134212,0.000000
116.880005,61.252289,-21.039490,0.018997,0.005278,0.134073,272.463776,13.879967,1.340731,-21.039490,0.134212,0.000000
117.190002,61.227715,-20.950527,0.019014,0.005278,0.134073,272.354462,13.874399,1.340731,-20.950527,0.134212,0.000000
117.500008,61.196434,-20.906048,0.018992,0.005278,0.134073,272.215332,13.867311,1.340731,-20.906048,0.134212,0.000000
117.810005,61.169250,-20.861567,0.018992,0.005278,0.134073,272.094421,13.861150,1.340731,-20.861567,0.134212,0.000000
118.120003,61.125309,-20.906048,0.019009,0.005278,0.134073,271.898956,13.851192,1.340731,-20.906048,0.134212,0.000000
118.430008,61.085468,-20.817085,0.018988,0.005278,0.134073,271.721741,13.842165,1.340731,-20.817085,0.134212,0.000000
118.740005,61.076900,-20.728123,0.019009,0.005278,0.134073,271.683624,13.840223,1.340731,-20.728123,0.134212,0.000000
119.050003,61.036312,-20.772604,0.019001,0.005278,0.134073,271.503082,13.831026,1.340731,-20.772604,0.134212,0.000000
119.360008,61.030727,-20.728123,0.019001,0.005278,0.134073,271.478241,13.829761,1.340731,-20.728123,0.134212,0.000000
119.670006,60.979340,-20.594681,0.019005,0.005278,0.134073,271.249664,13.818115,1.340731,-20.594681,0.134212,0.000000
119.980003,60.936890,-20.639162,0.019001,0.005278,0.134073,271.060822,13.808496,1.340731,-20.639162,0.134212,0.000000
120.290009,60.926834,-20.505718,0.019001,0.005278,0.134073,271.016083,13.806218,1.340731,-20.505718,0.134212,0.000000
120.600006,60.914547,-20.550200,0.019001,0.005278,0.134073,270.961426,13.803434,1.340731,-20.550200,0.134212,0.000000
120.910004,60.875820,-20.416756,0.018988,0.005278,0.134073,270.789185,13.794658,1.340731,-20.416756,0.134212,0.000000
121.220009,60.835232,-20.461237,0.019005,0.005278,0.134073,270.608612,13.785460,1.340731,-20.461237,0.134212,0.000000
121.530006,60.834488,-20.372276,0.019001,0.005278,0.134073,270.605316,13.785292,1.340731,-20.372276,0.134212,0.000000
121.840004,60.794270,-20.327795,0.019009,0.005278,0.134073,270.426422,13.776178,1.340731,-20.327795,0.134212,0.000000
122.150009,60.791294,-20.416756,0.019001,0.005278,0.134073,270.413177,13.775504,1.340731,-20.416756,0.134212,0.000000
122.460007,60.755917,-20.238832,0.019005,0.005278,0.134073,270.255829,13.767488,1.340731,-20.238832,0.134212,0.000000
122.770004,60.720169,-20.238832,0.019014,0.005278,0.134073,270.096802,13.759387,1.340731,-20.238832,0.134212,0.000000
123.080009,60.705273,-20.238832,0.019009,0.005278,0.134064,270.030548,13.756011,1.340644,-20.238832,0.134212,0.000000
123.390007,60.692242,-20.105391,0.019001,0.005278,0.134064,269.972565,13.753058,1.340644,-20.105391,0.134212,0.000000
123.700005,60.657238,-20.105391,0.018997,0.005278,0.134064,269.816864,13.745127,1.340644,-20.105391,0.134212,0.000000
124.010002,60.654633,-19.971947,0.019001,0.005278,0.134064,269.805267,13.744535,1.340644,-19.971947,0.134212,0.000000
124.320007,60.606968,-20.016428,0.019014,0.005278,0.134064,269.593262,13.733735,1.340644,-20.016428,0.134212,0.000000
124.630005,60.602501,-20.016428,0.019001,0.005278,0.134064,269.573395,13.732723,1.340644,-20.016428,0.134212,0.000000
124.940002,60.567867,-19.882986,0.019001,0.005278,0.134064,269.419342,13.724874,1.340644,-19.882986,0.134212,0.000000
125.250008,60.542549,-19.882986,0.019005,0.005278,0.134064,269.306702,13.719138,1.340644,-19.882986,0.134212,0.000000
125.560005,60.514618,-19.794024,0.019018,0.005278,0.134064,269.182465,13.712809,1.340644,-19.794024,0.134212,0.000000
125.870003,60.509407,-19.794024,0.019005,0.005278,0.134064,269.159271,13.711628,1.340644,-19.794024,0.134212,0.000000
126.180008,60.490788,-19.749542,0.018997,0.005278,0.134064,269.076447,13.707409,1.340644,-19.749542,0.134212,0.000000
126.490005,60.466583,-19.660580,0.019027,0.005278,0.134064,268.968781,13.701923,1.340644,-19.660580,0.134212,0.000000
126.800003,60.457275,-19.705061,0.019001,0.005278,0.134064,268.927399,13.699815,1.340644,-19.705061,0.134212,0.000000
127.110008,60.416687,-19.660580,0.019009,0.005278,0.134064,268.746857,13.690618,1.340644,-19.660580,0.134212,0.000000
127.420006,60.409985,-19.571619,0.019018,0.005278,0.134064,268.717041,13.689098,1.340644,-19.571619,0.134212,0.000000
127.730003,60.395088,-19.527138,0.019009,0.005278,0.134064,268.650757,13.685722,1.340644,-19.527138,0.134212,0.000000
128.040009,60.397694,-19.438175,0.019014,0.005278,0.134064,268.662354,13.686314,1.340644,-19.438175,0.134212,0.000000
128.350006,60.327316,-19.482656,0.019009,0.005278,0.134064,268.349304,13.670365,1.340644,-19.482656,0.134212,0.000000
128.660004,60.345936,-19.393694,0.019009,0.005278,0.134064,268.432129,13.674585,1.340644,-19.393694,0.134212,0.000000
128.970001,60.301994,-19.393694,0.019005,0.005278,0.134064,268.236664,13.664628,1.340644,-19.393694,0.134212,0.000000
129.279999,60.298271,-19.304733,0.019018,0.005278,0.134064,268.220093,13.663783,1.340644,-19.304733,0.134212,0.000000
129.590012,60.280396,-19.215771,0.019009,0.005278,0.134064,268.140594,13.659733,1.340644,-19.215771,0.134212,0.000000
129.900009,60.247257,-19.260252,0.019022,0.005278,0.134064,267.993195,13.652224,1.340644,-19.260252,0.134212,0.000000
130.210007,60.224171,-19.260252,0.019001,0.005278,0.134064,267.890503,13.646992,1.340644,-19.260252,0.134212,0.000000
130.520004,60.233852,-19.171289,0.019014,0.005278,0.134064,267.933563,13.649186,1.340644,-19.171289,0.134212,0.000000
130.830002,60.194752,-19.082329,0.019009,0.005278,0.134064,267.759644,13.640326,1.340644,-19.082329,0.134212,0.000000
131.139999,60.205177,-19.037848,0.019018,0.005278,0.134064,267.806000,13.642688,1.340644,-19.037848,0.134212,0.000000
131.450012,60.157513,-19.037848,0.018997,0.005278,0.134064,267.593994,13.631887,1.340644,-19.037848,0.134212,0.000000
131.760010,60.158260,-18.904404,0.019014,0.005278,0.134064,267.597321,13.632057,1.340644,-18.904404,0.134212,0.000000
132.070007,60.142620,-18.948885,0.019018,0.005278,0.134064,267.527740,13.628512,1.340644,-18.948885,0.134212,0.000000
132.380005,60.122139,-18.904404,0.019009,0.005278,0.134064,267.436646,13.623871,1.340644,-18.904404,0.134212,0.000000
132.690002,60.092350,-18.859922,0.019014,0.005278,0.134064,267.304138,13.617122,1.340644,-18.859922,0.134212,0.000000
133.000000,60.087879,-18.859922,0.019009,0.005278,0.134064,267.284241,13.616108,1.340644,-18.859922,0.134212,0.000000
133.100006,60.074848,-18.815443,0.019009,0.005278,0.134064,267.226257,13.613154,1.340644,-18.815443,0.134212,0.000000