File: Data/10% 30min RT - 1 - 1_07262023_150228.csv
Time (sec),S:Load (lbs),S:HL1 (DIM),S:LVDT (in),S:Position (in),Ch:Position (mm),Ch:Load (N),Ch:Stress (MPa),Ch:Strain (mm/mm),Ch:HL1 (DIM),Set Point (),Cycles ()
0.010000,0.006703,-93.632401,0.000000,-0.000000,-0.000000,0.029815,0.001519,-0.000000,-93.632401,0.000069,0.000000
0.320000,0.000745,-93.587921,0.000000,-0.000000,-0.000000,0.003313,0.000169,-0.000000,-93.587921,0.000069,0.000000
0.630000,0.002607,-93.454475,-0.000004,0.000161,0.004093,0.011595,0.000591,0.040934,-93.454475,0.004960,0.000000
0.940000,0.034258,-93.454475,0.000047,0.000361,0.009158,0.152388,0.007763,0.091579,-93.454475,0.010112,0.000000
1.250000,0.046919,-93.276558,0.000229,0.000551,0.014006,0.208706,0.010632,0.140056,-93.276558,0.015281,0.000000
1.560000,0.039844,-93.321037,0.000466,0.000764,0.019400,0.177234,0.009029,0.193999,-93.321037,0.020449,0.000000
1.870000,0.023087,-93.232071,0.000673,0.000969,0.024621,0.102696,0.005232,0.246206,-93.232071,0.025618,0.000000
2.180000,0.031279,-93.187592,0.000867,0.001162,0.029512,0.139137,0.007088,0.295118,-93.187592,0.030769,0.000000
2.490000,0.017874,-93.143112,0.001069,0.001369,0.034776,0.079507,0.004050,0.347758,-93.143112,0.035938,0.000000
2.800000,0.082667,-92.965187,0.001289,0.001569,0.039840,0.367720,0.018733,0.398404,-92.965187,0.041107,0.000000
3.110000,0.029417,-92.965187,0.001500,0.001779,0.045183,0.130855,0.006666,0.451826,-92.965187,0.046275,0.000000
3.420000,0.052132,-92.876228,0.001677,0.001981,0.050316,0.231895,0.011813,0.503164,-92.876228,0.051444,0.000000
3.730000,0.048781,-92.787262,0.001914,0.002185,0.055502,0.216988,0.011054,0.555025,-92.787262,0.056595,0.000000
4.040000,0.021598,-92.831741,0.002117,0.002392,0.060749,0.096071,0.004894,0.607493,-92.831741,0.061764,0.000000
4.350000,0.035375,-92.653824,0.002311,0.002587,0.065718,0.157357,0.008016,0.657185,-92.653824,0.066932,0.000000
4.660000,-0.020108,-92.609337,0.002531,0.002793,0.070939,-0.089446,-0.004557,0.709392,-92.609337,0.072101,0.000000
4.970000,0.055483,-92.520378,0.002738,0.002998,0.076160,0.246803,0.012573,0.761598,-92.520378,0.077253,0.000000
5.280000,0.040961,-92.431419,0.002949,0.003205,0.081406,0.182203,0.009282,0.814065,-92.431419,0.082421,0.000000
5.590000,0.035375,-92.431419,0.003160,0.003409,0.086584,0.157357,0.008016,0.865838,-92.431419,0.087590,0.000000
5.900000,0.064793,-92.297974,0.003350,0.003605,0.091570,0.288213,0.014682,0.915704,-92.297974,0.092758,0.000000
6.210001,0.025321,-92.253494,0.003574,0.003811,0.096791,0.112635,0.005738,0.967911,-92.253494,0.097910,0.000000
6.520000,0.024577,-92.209015,0.003773,0.004011,0.101890,0.109322,0.005569,1.018903,-92.209015,0.103078,0.000000
6.830000,0.044685,-92.075569,0.003988,0.004219,0.107172,0.198767,0.010126,1.071718,-92.075569,0.108247,0.000000
7.140000,0.033886,-92.075569,0.004217,0.004425,0.112384,0.150732,0.007679,1.123837,-92.075569,0.113416,0.000000
7.450000,0.080805,-91.942123,0.004398,0.004617,0.117275,0.359438,0.018311,1.172750,-91.942123,0.118567,0.000000
7.760000,0.042450,-91.897644,0.004609,0.004828,0.122634,0.188829,0.009619,1.226344,-91.897644,0.123736,0.000000
8.070001,0.055856,-91.853165,0.004829,0.005038,0.127977,0.248459,0.012657,1.279766,-91.853165,0.128904,0.000000
8.380000,0.056601,-91.808685,0.005019,0.005234,0.132954,0.251772,0.012826,1.329545,-91.808685,0.134073,0.000000
8.690001,0.039471,-91.719719,0.005230,0.005434,0.138036,0.175578,0.008944,1.380363,-91.719719,0.139225,0.000000
9.000000,0.070378,-91.586281,0.005437,0.005636,0.143162,0.313059,0.015948,1.431616,-91.586281,0.144393,0.000000
9.310000,0.027928,-91.630760,0.005648,0.005847,0.148521,0.124230,0.006329,1.485212,-91.630760,0.149562,0.000000
9.620001,0.070006,-91.497314,0.005825,0.006042,0.153473,0.311402,0.015864,1.534729,-91.497314,0.154730,0.000000
9.930000,0.056601,-91.363876,0.006053,0.006250,0.158746,0.251772,0.012826,1.587457,-91.363876,0.159899,0.000000
10.240001,0.041706,-91.363876,0.006278,0.006458,0.164027,0.185516,0.009451,1.640271,-91.363876,0.165050,0.000000
10.550000,0.062559,-91.319389,0.006446,0.006654,0.169022,0.278274,0.014176,1.690222,-91.319389,0.170219,0.000000
10.860001,0.012661,-91.185951,0.006670,0.006861,0.174260,0.056317,0.002869,1.742604,-91.185951,0.175388,0.000000
11.170000,0.032769,-91.185951,0.006864,0.007063,0.179394,0.145763,0.007425,1.793944,-91.185951,0.180556,0.000000
11.480000,0.059952,-91.052505,0.007080,0.007268,0.184606,0.266680,0.013585,1.846064,-91.052505,0.185708,0.000000
11.790001,0.061814,-91.096985,0.007291,0.007473,0.189818,0.274962,0.014007,1.898183,-91.096985,0.190876,0.000000
12.100000,0.074474,-90.919067,0.007476,0.007669,0.194796,0.331279,0.016876,1.947962,-90.919067,0.196045,0.000000
12.410001,0.049153,-90.874580,0.007696,0.007879,0.200130,0.218644,0.011138,2.001297,-90.874580,0.201214,0.000000
12.720000,0.051760,-90.830101,0.007890,0.008077,0.205160,0.230239,0.011729,2.051597,-90.830101,0.206365,0.000000
13.030001,0.064420,-90.696663,0.008080,0.008283,0.210380,0.286556,0.014598,2.103804,-90.696663,0.211534,0.000000
13.340001,0.037982,-90.652176,0.008300,0.008490,0.215636,0.168952,0.008607,2.156357,-90.652176,0.216702,0.000000
13.650001,0.077453,-90.652176,0.008481,0.008684,0.220579,0.344530,0.017551,2.205790,-90.652176,0.221871,0.000000
13.960001,0.023832,-90.474251,0.008709,0.008895,0.225938,0.106009,0.005400,2.259384,-90.474251,0.227022,0.000000
14.270000,0.074847,-90.474251,0.008899,0.009097,0.231064,0.332935,0.016961,2.310637,-90.474251,0.232191,0.000000
14.580001,0.058090,-90.429771,0.009115,0.009305,0.236345,0.258398,0.013163,2.363451,-90.429771,0.237360,0.000000
14.890000,0.051015,-90.251846,0.009300,0.009507,0.241488,0.226926,0.011560,2.414876,-90.251846,0.242528,0.000000
15.200001,0.073357,-90.207367,0.009485,0.009703,0.246466,0.326310,0.016623,2.464655,-90.207367,0.247680,0.000000
15.510001,0.019736,-90.118408,0.009722,0.009914,0.251808,0.087789,0.004472,2.518077,-90.118408,0.252848,0.000000
15.820001,0.075219,-90.118408,0.009925,0.010113,0.256881,0.334592,0.017045,2.568810,-90.118408,0.258017,0.000000
16.130001,0.082667,-90.029442,0.010115,0.010318,0.262076,0.367720,0.018733,2.620756,-90.029442,0.263186,0.000000
16.440001,0.076709,-89.940483,0.010339,0.010525,0.267322,0.341217,0.017382,2.673224,-89.940483,0.268354,0.000000
16.750000,0.084156,-89.984962,0.010533,0.010726,0.272430,0.374345,0.019070,2.724303,-89.984962,0.273506,0.000000
17.060001,0.045429,-89.762558,0.010731,0.010927,0.277538,0.202080,0.010294,2.775382,-89.762558,0.278674,0.000000
17.370001,0.062186,-89.718079,0.010947,0.011127,0.282620,0.276618,0.014092,2.826202,-89.718079,0.283843,0.000000
17.680000,0.082294,-89.673599,0.011141,0.011337,0.287954,0.366063,0.018648,2.879537,-89.673599,0.289012,0.000000
17.990002,0.088252,-89.540154,0.011339,0.011539,0.293088,0.392566,0.019998,2.930877,-89.540154,0.294163,0.000000
18.300001,0.087880,-89.584633,0.011542,0.011735,0.298065,0.390909,0.019914,2.980654,-89.584633,0.299332,0.000000
18.610001,0.126607,-89.406715,0.011740,0.011947,0.303451,0.563174,0.028689,3.034509,-89.406715,0.304500,0.000000
18.920000,0.331411,-89.406715,0.011956,0.012151,0.308637,1.474192,0.075099,3.086370,-89.406715,0.309669,0.000000
19.230001,0.584625,-89.317749,0.012137,-0.000000,-0.000000,2.600541,0.132478,-0.000000,-89.317749,0.000225,0.000000
19.540001,0.526907,-89.139824,0.012137,-0.000000,-0.000000,2.343800,0.119399,-0.000000,-89.139824,0.000225,0.000000
19.850000,0.547760,-89.139824,0.012141,-0.000000,-0.000000,2.436558,0.124124,-0.000000,-89.139824,0.000503,0.000000
20.160002,0.535099,-89.050865,0.012128,0.000001,0.000017,2.380240,0.121255,0.000172,-89.050865,0.001023,0.000000
20.470001,0.621490,-89.006386,0.012137,0.000025,0.000642,2.764524,0.140832,0.006417,-89.006386,0.001535,0.000000
20.780001,0.651279,-88.828461,0.012150,0.000039,0.000997,2.897035,0.147582,0.009973,-88.828461,0.002055,0.000000
21.090000,0.774162,-88.828461,0.012167,0.000060,0.001526,3.443646,0.175428,0.015263,-88.828461,0.002567,0.000000
21.400002,0.834487,-88.739494,0.012184,0.000082,0.002081,3.711982,0.189097,0.020813,-88.739494,0.003087,0.000000
21.710001,0.883267,-88.650536,0.012206,0.000101,0.002567,3.928970,0.200151,0.025669,-88.650536,0.003608,0.000000
22.020000,0.990138,-88.606056,0.012236,0.000126,0.003200,4.404356,0.224369,0.031999,-88.606056,0.004119,0.000000
22.330002,0.989021,-88.561577,0.012249,0.000139,0.003538,4.399386,0.224115,0.035381,-88.561577,0.004640,0.000000
22.640001,1.059400,-88.428131,0.012266,0.000165,0.004180,4.712445,0.240063,0.041800,-88.428131,0.005151,0.000000
22.950001,1.199784,-88.428131,0.012288,0.000186,0.004735,5.336906,0.271875,0.047349,-88.428131,0.005672,0.000000
23.260000,1.217286,-88.250206,0.012301,0.000203,0.005169,5.414757,0.275841,0.051687,-88.250206,0.006183,0.000000
23.570002,1.304793,-88.205727,0.012331,0.000219,0.005568,5.804009,0.295670,0.055676,-88.205727,0.006704,0.000000
23.880001,1.394907,-88.205727,0.012361,0.000246,0.006253,6.204857,0.316090,0.062526,-88.205727,0.007224,0.000000
24.190001,1.461190,-88.072281,0.012378,0.000267,0.006773,6.499696,0.331110,0.067729,-88.072281,0.007736,0.000000
24.500002,1.457466,-87.983322,0.012400,0.000286,0.007259,6.483131,0.330266,0.072587,-87.983322,0.008256,0.000000
24.810001,1.617586,-87.938843,0.012413,0.000309,0.007840,7.195382,0.366550,0.078397,-87.938843,0.008768,0.000000
25.120001,1.670835,-87.849876,0.012434,0.000326,0.008291,7.432246,0.378617,0.082906,-87.849876,0.009288,0.000000
25.430000,1.731904,-87.849876,0.012465,0.000344,0.008750,7.703895,0.392455,0.087503,-87.849876,0.009808,0.000000
25.740002,1.873778,-87.716438,0.012482,0.000370,0.009401,8.334981,0.424604,0.094007,-87.716438,0.010320,0.000000
26.050001,1.897610,-87.671951,0.012503,0.000387,0.009834,8.440990,0.430005,0.098343,-87.671951,0.010840,0.000000
26.360001,1.943039,-87.582993,0.012525,0.000408,0.010363,8.643071,0.440299,0.103632,-87.582993,0.011352,0.000000
26.670002,2.066295,-87.494034,0.012542,0.000431,0.010944,9.191338,0.468229,0.109442,-87.494034,0.011872,0.000000
26.980001,2.138907,-87.449547,0.012572,0.000447,0.011361,9.514336,0.484683,0.113606,-87.449547,0.012384,0.000000
27.290001,2.253598,-87.405067,0.012581,0.000467,0.011872,10.024506,0.510673,0.118723,-87.405067,0.012904,0.000000
27.600000,2.303868,-87.360588,0.012598,0.000484,0.012297,10.248118,0.522064,0.122971,-87.360588,0.013425,0.000000
27.910002,2.481490,-87.271629,0.012641,0.000514,0.013060,11.038219,0.562314,0.130603,-87.271629,0.013936,0.000000
28.220001,2.496385,-87.182663,0.012672,0.000533,0.013529,11.104474,0.565689,0.135287,-87.182663,0.014457,0.000000
28.530001,2.570487,-87.138184,0.012684,0.000551,0.014006,11.434097,0.582481,0.140056,-87.138184,0.014968,0.000000
28.840002,2.675869,-86.960258,0.012706,0.000571,0.014491,11.902858,0.606360,0.144912,-86.960258,0.015489,0.000000
29.150002,2.716085,-86.960258,0.012728,0.000586,0.014873,12.081748,0.615474,0.148727,-86.960258,0.016009,0.000000
29.460001,2.831148,-86.915779,0.012741,0.000606,0.015402,12.593574,0.641547,0.154019,-86.915779,0.016520,0.000000
29.770002,2.994992,-86.826813,0.012788,0.000633,0.016078,13.322388,0.678675,0.160782,-86.826813,0.017041,0.000000
30.080002,2.978607,-86.782333,0.012801,0.000651,0.016529,13.249506,0.674962,0.165292,-86.782333,0.017553,0.000000
30.390001,3.095532,-86.693375,0.012818,0.000672,0.017058,13.769615,0.701458,0.170583,-86.693375,0.018073,0.000000
30.700001,3.251929,-86.604408,0.012835,0.000695,0.017648,14.465301,0.736898,0.176480,-86.604408,0.018585,0.000000
31.010002,3.272037,-86.559929,0.012857,0.000712,0.018073,14.554747,0.741454,0.180729,-86.559929,0.019105,0.000000
31.320002,3.353214,-86.426491,0.012874,0.000726,0.018446,14.915841,0.759849,0.184459,-86.426491,0.019625,0.000000
31.630001,3.575520,-86.382004,0.012917,0.000755,0.019166,15.904709,0.810224,0.191656,-86.382004,0.020137,0.000000
31.940002,3.594884,-86.293045,0.012943,0.000773,0.019643,15.990841,0.814612,0.196427,-86.293045,0.020657,0.000000
32.250000,3.635100,-86.248566,0.012965,0.000795,0.020189,16.169731,0.823725,0.201890,-86.248566,0.021169,0.000000
32.560001,3.766175,-86.204086,0.012982,0.000816,0.020727,16.752783,0.853427,0.207267,-86.204086,0.021689,0.000000
32.870003,3.799316,-86.070641,0.013012,0.000833,0.021169,16.900202,0.860937,0.211689,-86.070641,0.022210,0.000000
33.180000,3.931508,-86.026161,0.013029,0.000852,0.021646,17.488222,0.890893,0.216458,-86.026161,0.022721,0.000000
33.490002,4.134451,-86.026161,0.013055,0.000877,0.022270,18.390959,0.936880,0.222703,-86.026161,0.023242,0.000000
33.800003,4.164614,-85.848236,0.013068,0.000896,0.022747,18.525127,0.943715,0.227472,-85.848236,0.023753,0.000000
34.110001,4.233130,-85.803757,0.013107,0.000918,0.023320,18.829903,0.959241,0.233197,-85.803757,0.024273,0.000000
34.420002,4.245046,-85.759277,0.013129,0.000935,0.023753,18.882908,0.961941,0.237532,-85.759277,0.024785,0.000000
34.730003,4.412241,-85.714790,0.013137,0.000958,0.024326,19.626631,0.999828,0.243255,-85.714790,0.025306,0.000000
35.040001,4.405166,-85.670311,0.013167,0.000972,0.024699,19.595158,0.998225,0.246985,-85.670311,0.025826,0.000000
35.350002,4.579809,-85.536865,0.013193,0.000996,0.025306,20.372007,1.037799,0.253056,-85.536865,0.026338,0.000000
35.660000,4.690776,-85.492386,0.013219,0.001019,0.025887,20.865614,1.062945,0.258866,-85.492386,0.026858,0.000000
35.970001,4.766740,-85.403427,0.013241,0.001040,0.026407,21.203518,1.080159,0.264070,-85.403427,0.027370,0.000000
36.280003,4.811052,-85.358948,0.013271,0.001059,0.026901,21.400629,1.090200,0.269013,-85.358948,0.027890,0.000000
36.590000,4.869514,-85.314461,0.013297,0.001079,0.027404,21.660683,1.103448,0.274043,-85.314461,0.028401,0.000000
36.900002,4.935052,-85.181023,0.013314,0.001097,0.027855,21.952209,1.118299,0.278551,-85.181023,0.028922,0.000000
37.210003,5.174860,-85.136543,0.013331,0.001122,0.028497,23.018927,1.172640,0.284970,-85.136543,0.029442,0.000000
37.520000,5.241515,-85.092056,0.013366,0.001146,0.029113,23.315422,1.187744,0.291127,-85.092056,0.029954,0.000000
37.830002,5.215076,-84.958618,0.013387,0.001163,0.029546,23.197819,1.181753,0.295462,-84.958618,0.030474,0.000000
38.140003,5.269443,-85.003098,0.013400,0.001182,0.030023,23.439651,1.194073,0.300233,-85.003098,0.030986,0.000000
38.450001,5.417274,-84.914139,0.013422,0.001204,0.030578,24.097240,1.227572,0.305784,-84.914139,0.031506,0.000000
38.760002,5.367377,-84.825172,0.013452,0.001220,0.030977,23.875284,1.216265,0.309773,-84.825172,0.032027,0.000000
39.070004,5.614632,-84.691734,0.013478,0.001246,0.031654,24.975132,1.272294,0.316536,-84.691734,0.032538,0.000000
39.380001,5.652986,-84.647247,0.013517,0.001266,0.032148,25.145739,1.280985,0.321480,-84.647247,0.033059,0.000000
39.690002,5.652242,-84.691734,0.013521,0.001285,0.032634,25.142427,1.280816,0.326336,-84.691734,0.033570,0.000000
40.000000,5.694320,-84.469330,0.013530,0.001303,0.033102,25.329599,1.290351,0.331019,-84.469330,0.034091,0.000000
40.310001,5.779965,-84.469330,0.013568,0.001323,0.033596,25.710569,1.309759,0.335962,-84.469330,0.034602,0.000000
40.620003,5.820181,-84.380363,0.013586,0.001340,0.034039,25.889460,1.318872,0.340385,-84.380363,0.035122,0.000000
40.930000,5.880506,-84.291405,0.013599,0.001360,0.034542,26.157797,1.332542,0.345415,-84.291405,0.035643,0.000000
41.240002,6.010836,-84.246918,0.013620,0.001382,0.035105,26.737534,1.362075,0.351053,-84.246918,0.036155,0.000000
41.550003,6.109515,-84.202438,0.013646,0.001406,0.035712,27.176479,1.384436,0.357122,-84.202438,0.036675,0.000000
41.860001,6.042860,-84.113480,0.013663,0.001423,0.036155,26.879984,1.369332,0.361546,-84.113480,0.037187,0.000000
42.170002,5.986632,-84.024513,0.013663,0.001438,0.036536,26.629869,1.356590,0.365362,-84.024513,0.037707,0.000000
42.480003,6.146752,-83.891075,0.013702,0.001459,0.037048,27.342119,1.392874,0.370479,-83.891075,0.038227,0.000000
42.790001,6.272614,-83.846596,0.013728,0.001481,0.037629,27.901981,1.421395,0.376289,-83.846596,0.038739,0.000000
43.100002,6.340758,-83.846596,0.013741,0.001502,0.038141,28.205101,1.436836,0.381406,-83.846596,0.039259,0.000000
43.410004,6.477791,-83.802109,0.013754,0.001527,0.038791,28.814655,1.467888,0.387910,-83.802109,0.039771,0.000000
43.720001,6.358632,-83.713150,0.013771,0.001545,0.039242,28.284609,1.440887,0.392418,-83.713150,0.040291,0.000000
44.030003,6.417840,-83.535225,0.013805,0.001565,0.039745,28.547976,1.454303,0.397448,-83.535225,0.040803,0.000000
44.340004,6.549659,-83.535225,0.013818,0.001587,0.040309,29.134340,1.484174,0.403086,-83.535225,0.041323,0.000000
44.650002,6.522104,-83.490746,0.013823,0.001602,0.040699,29.011766,1.477930,0.406988,-83.490746,0.041844,0.000000
44.960003,6.571629,-83.401787,0.013853,0.001622,0.041211,29.232065,1.489152,0.412105,-83.401787,0.042355,0.000000
45.270000,6.743293,-83.357300,0.013874,0.001648,0.041861,29.995665,1.528052,0.418609,-83.357300,0.042875,0.000000
45.580002,6.672542,-83.223862,0.013900,0.001667,0.042347,29.680950,1.512020,0.423465,-83.223862,0.043387,0.000000
45.890003,6.714620,-83.134895,0.013918,0.001688,0.042875,29.868122,1.521555,0.428755,-83.134895,0.043908,0.000000
46.200001,6.831917,-83.179375,0.013935,0.001709,0.043413,30.389885,1.548135,0.434133,-83.179375,0.044419,0.000000
46.510002,6.841227,-83.045937,0.013952,0.001728,0.043882,30.431295,1.550244,0.438815,-83.045937,0.044940,0.000000
46.820004,6.852398,-83.001457,0.013969,0.001744,0.044298,30.480988,1.552776,0.442978,-83.001457,0.045460,0.000000
47.130001,7.107101,-82.868011,0.013999,0.001773,0.045026,31.613964,1.610492,0.450262,-82.868011,0.045972,0.000000
47.440002,6.967834,-82.823532,0.014030,0.001788,0.045408,30.994471,1.578934,0.454078,-82.823532,0.046492,0.000000
47.750004,7.047894,-82.779053,0.014021,0.001812,0.046015,31.350595,1.597075,0.460149,-82.779053,0.047003,0.000000
48.060001,7.186416,-82.734566,0.014068,0.001834,0.046579,31.966776,1.628465,0.465786,-82.734566,0.047524,0.000000
48.370003,7.120134,-82.645607,0.014077,0.001851,0.047021,31.671938,1.613445,0.470209,-82.645607,0.048044,0.000000
48.680004,7.183065,-82.601128,0.014077,0.001868,0.047437,31.951868,1.627706,0.474372,-82.601128,0.048556,0.000000
48.990002,7.440001,-82.467682,0.014129,0.001896,0.048157,33.094780,1.685928,0.481569,-82.467682,0.049076,0.000000
49.300003,7.391221,-82.467682,0.014129,0.001915,0.048643,32.877792,1.674875,0.486425,-82.467682,0.049588,0.000000
49.610001,7.332386,-82.378723,0.014155,0.001935,0.049137,32.616081,1.661542,0.491368,-82.378723,0.050108,0.000000
49.920002,7.366644,-82.378723,0.014168,0.001954,0.049640,32.768471,1.669305,0.496398,-82.378723,0.050620,0.000000
50.230003,7.318981,-82.289757,0.014185,0.001971,0.050065,32.556454,1.658505,0.500649,-82.289757,0.051140,0.000000
50.540001,7.509635,-82.200798,0.014211,0.001992,0.050603,33.404526,1.701708,0.506025,-82.200798,0.051661,0.000000
50.850002,7.473887,-82.111839,0.014224,0.002009,0.051027,33.245510,1.693607,0.510274,-82.111839,0.052172,0.000000
51.160004,7.688002,-82.022873,0.014245,0.002037,0.051739,34.197941,1.742126,0.517386,-82.022873,0.052693,0.000000
51.470001,7.599005,-81.978394,0.014267,0.002055,0.052207,33.802063,1.721959,0.522070,-81.978394,0.053204,0.000000
51.780003,7.591558,-81.933914,0.014284,0.002073,0.052667,33.768936,1.720272,0.526666,-81.933914,0.053725,0.000000
52.090004,7.729335,-81.844948,0.014310,0.002098,0.053282,34.381802,1.751493,0.532822,-81.844948,0.054245,0.000000
52.400002,7.618741,-81.800468,0.014319,0.002113,0.053681,33.889851,1.726431,0.536812,-81.800468,0.054756,0.000000
52.710003,7.547245,-81.711510,0.014319,0.002125,0.053985,33.571823,1.710230,0.539847,-81.711510,0.055277,0.000000
53.020004,7.991113,-81.711510,0.014353,0.002158,0.054817,35.546246,1.810812,0.548172,-81.711510,0.055789,0.000000
53.330002,7.898392,-81.578064,0.014362,0.002179,0.055338,35.133804,1.789801,0.553376,-81.578064,0.056309,0.000000
53.640003,7.857059,-81.444618,0.014392,0.002197,0.055806,34.949944,1.780435,0.558058,-81.444618,0.056821,0.000000
53.950001,7.940098,-81.489105,0.014418,0.002219,0.056361,35.319321,1.799252,0.563609,-81.489105,0.057341,0.000000
54.260002,7.908819,-81.355659,0.014409,0.002235,0.056760,35.180183,1.792164,0.567598,-81.355659,0.057861,0.000000
54.570004,8.011594,-81.266701,0.014431,0.002254,0.057245,35.637348,1.815453,0.572454,-81.266701,0.058373,0.000000
54.880001,8.239486,-81.266701,0.014474,0.002279,0.057887,36.651062,1.867094,0.578873,-81.266701,0.058893,0.000000
55.190002,8.225335,-81.133255,0.014482,0.002300,0.058408,36.588120,1.863888,0.584076,-81.133255,0.059405,0.000000
55.500004,8.214909,-81.133255,0.014491,0.002321,0.058945,36.541737,1.861525,0.589452,-81.133255,0.059925,0.000000
55.810001,8.074152,-81.044296,0.014517,0.002337,0.059353,35.915623,1.829629,0.593528,-81.044296,0.060437,0.000000
56.120003,8.249912,-80.955330,0.014543,0.002360,0.059934,36.697441,1.869457,0.599338,-80.955330,0.060957,0.000000
56.430004,8.278584,-80.955330,0.014560,0.002378,0.060393,36.824982,1.875954,0.603935,-80.955330,0.061477,0.000000
56.740002,8.675906,-80.777405,0.014582,0.002406,0.061122,38.592358,1.965988,0.611219,-80.777405,0.061989,0.000000
57.050003,8.382477,-80.777405,0.014599,0.002421,0.061504,37.287121,1.899496,0.615036,-80.777405,0.062510,0.000000
57.360004,8.456951,-80.688446,0.014612,0.002445,0.062093,37.618397,1.916373,0.620933,-80.688446,0.063021,0.000000
57.670002,8.585420,-80.599480,0.014646,0.002466,0.062631,38.189854,1.945484,0.626309,-80.599480,0.063542,0.000000
57.980003,8.508711,-80.599480,0.014642,0.002483,0.063073,37.848637,1.928102,0.630732,-80.599480,0.064062,0.000000
58.290001,8.436098,-80.510521,0.014672,0.002500,0.063507,37.525639,1.911647,0.635069,-80.510521,0.064574,0.000000
58.600002,8.733996,-80.421562,0.014685,0.002526,0.064149,38.850758,1.979152,0.641487,-80.421562,0.065094,0.000000
58.910004,8.735113,-80.332596,0.014715,0.002547,0.064704,38.855724,1.979405,0.647035,-80.332596,0.065605,0.000000
59.220001,8.717984,-80.243637,0.014724,0.002567,0.065189,38.779530,1.975523,0.651893,-80.243637,0.066126,0.000000
59.530003,8.777191,-80.288116,0.014750,0.002587,0.065701,39.042896,1.988940,0.657009,-80.288116,0.066638,0.000000
59.840004,8.862837,-80.110191,0.014754,0.002607,0.066230,39.423866,2.008348,0.662300,-80.110191,0.067158,0.000000
60.150002,8.911990,-80.065712,0.014780,0.002626,0.066698,39.642513,2.019486,0.666982,-80.065712,0.067678,0.000000
60.460003,9.071365,-79.976753,0.014797,0.002650,0.067305,40.351448,2.055601,0.673053,-79.976753,0.068190,0.000000
60.770004,9.063173,-79.932266,0.014827,0.002670,0.067808,40.315010,2.053744,0.678083,-79.932266,0.068710,0.000000
61.080002,9.011414,-79.932266,0.014823,0.002689,0.068294,40.084770,2.042016,0.682939,-79.932266,0.069222,0.000000
61.390003,8.970080,-79.843307,0.014836,0.002705,0.068710,39.900909,2.032649,0.687102,-79.843307,0.069742,0.000000
61.700005,9.193131,-79.754349,0.014862,0.002727,0.069257,40.893089,2.083193,0.692566,-79.754349,0.070263,0.000000
62.010002,9.218825,-79.665382,0.014870,0.002745,0.069733,41.007381,2.089016,0.697335,-79.665382,0.070774,0.000000
62.320004,9.229996,-79.531944,0.014905,0.002764,0.070193,41.057072,2.091547,0.701931,-79.531944,0.071295,0.000000
62.630001,9.408362,-79.576424,0.014918,0.002788,0.070809,41.850487,2.131965,0.708090,-79.576424,0.071806,0.000000
62.940002,9.364423,-79.442978,0.014935,0.002809,0.071338,41.655033,2.122009,0.713379,-79.442978,0.072327,0.000000
63.250004,9.266116,-79.354019,0.014957,0.002827,0.071798,41.217743,2.099732,0.717976,-79.354019,0.072838,0.000000
63.560001,9.178981,-79.354019,0.014974,0.002843,0.072205,40.830147,2.079987,0.722052,-79.354019,0.073358,0.000000
63.870003,9.412458,-79.309532,0.014987,0.002863,0.072708,41.868706,2.132894,0.727082,-79.309532,0.073879,0.000000
64.180000,9.604975,-79.220573,0.015021,0.002885,0.073289,42.725063,2.176518,0.732892,-79.220573,0.074391,0.000000
64.490005,9.822068,-79.176094,0.015021,0.002909,0.073896,43.690742,2.225712,0.738963,-79.176094,0.074911,0.000000
64.800003,9.651150,-79.042648,0.015039,0.002928,0.074364,42.930458,2.186982,0.743645,-79.042648,0.075423,0.000000
65.110001,9.814993,-79.042648,0.015060,0.002951,0.074946,43.659267,2.224109,0.749457,-79.042648,0.075943,0.000000
65.420006,9.529756,-78.909210,0.015073,0.002964,0.075293,42.390469,2.159474,0.752925,-78.909210,0.076463,0.000000
65.730003,9.827654,-78.909210,0.015103,0.002989,0.075926,43.715588,2.226978,0.759256,-78.909210,0.076975,0.000000
66.040001,9.740519,-78.775764,0.015133,0.003005,0.076324,43.327991,2.207233,0.763245,-78.775764,0.077495,0.000000
66.350006,10.010117,-78.775764,0.015133,0.003031,0.076984,44.527222,2.268325,0.769836,-78.775764,0.078007,0.000000
66.660004,10.133744,-78.731285,0.015164,0.003054,0.077573,45.077145,2.296339,0.775733,-78.731285,0.078527,0.000000
66.970001,9.932291,-78.553360,0.015177,0.003073,0.078042,44.181038,2.250689,0.780415,-78.553360,0.079039,0.000000
67.280006,9.878297,-78.597839,0.015194,0.003091,0.078519,43.940861,2.238454,0.785186,-78.597839,0.079559,0.000000
67.590004,10.014957,-78.464401,0.015198,0.003111,0.079022,44.548756,2.269422,0.790216,-78.464401,0.080079,0.000000
67.900002,9.902501,-78.375435,0.015224,0.003126,0.079412,44.048527,2.243939,0.794118,-78.375435,0.080591,0.000000
68.210007,10.001180,-78.330956,0.015246,0.003147,0.079932,44.487469,2.266300,0.799321,-78.330956,0.081112,0.000000
68.520004,10.354934,-78.286476,0.015258,0.003176,0.080661,46.061047,2.346462,0.806607,-78.286476,0.081623,0.000000
68.830002,10.158693,-78.197510,0.015284,0.003192,0.081086,45.188126,2.301993,0.810855,-78.197510,0.082144,0.000000
69.140007,10.326261,-78.153030,0.015293,0.003217,0.081701,45.933502,2.339964,0.817013,-78.153030,0.082655,0.000000
69.450005,10.367594,-78.064072,0.015327,0.003237,0.082222,46.117359,2.349330,0.822215,-78.064072,0.083176,0.000000
69.760002,10.310621,-78.064072,0.015345,0.003254,0.082664,45.863934,2.336420,0.826638,-78.064072,0.083696,0.000000
70.070000,10.297960,-77.975105,0.015362,0.003271,0.083089,45.807613,2.333551,0.830889,-77.975105,0.084207,0.000000
70.380005,10.786885,-77.841667,0.015388,0.003299,0.083800,47.982464,2.444343,0.837998,-77.841667,0.084728,0.000000
70.690002,10.540748,-77.841667,0.015388,0.003319,0.084303,46.887589,2.388567,0.843029,-77.841667,0.085240,0.000000
71.000000,10.627137,-77.797180,0.015409,0.003340,0.084832,47.271866,2.408144,0.848320,-77.797180,0.085760,0.000000
71.310005,10.598093,-77.708221,0.015444,0.003359,0.085326,47.142673,2.401562,0.853263,-77.708221,0.086280,0.000000
71.620003,10.327377,-77.619263,0.015452,0.003372,0.085647,45.938469,2.340217,0.856471,-77.619263,0.086792,0.000000
71.930000,10.720231,-77.530296,0.015474,0.003395,0.086228,47.685970,2.429239,0.862282,-77.530296,0.087312,0.000000
72.240005,10.917215,-77.574776,0.015474,0.003419,0.086844,48.562199,2.473876,0.868438,-77.574776,0.087824,0.000000
72.550003,10.806622,-77.441338,0.015509,0.003437,0.087312,48.070255,2.448816,0.873122,-77.441338,0.088344,0.000000
72.860001,10.789865,-77.352371,0.015534,0.003457,0.087807,47.995716,2.445018,0.878065,-77.352371,0.088856,0.000000
73.170006,10.822261,-77.263412,0.015552,0.003479,0.088370,48.139820,2.452359,0.883703,-77.263412,0.089376,0.000000
73.480003,10.843486,-77.218933,0.015569,0.003500,0.088908,48.234234,2.457169,0.889079,-77.218933,0.089897,0.000000
73.790001,10.602561,-77.174454,0.015582,0.003512,0.089211,47.162548,2.402575,0.892115,-77.174454,0.090408,0.000000
74.100006,10.802897,-77.085487,0.015603,0.003532,0.089714,48.053688,2.447971,0.897145,-77.085487,0.090929,0.000000
74.410004,11.165588,-77.085487,0.015634,0.003560,0.090417,49.667019,2.530159,0.904168,-77.085487,0.091440,0.000000
74.720001,11.101168,-76.996529,0.015651,0.003582,0.090972,49.380459,2.515560,0.909718,-76.996529,0.091960,0.000000
75.030006,11.008447,-76.863083,0.015677,0.003599,0.091423,48.968018,2.494550,0.914228,-76.863083,0.092481,0.000000
75.340004,11.102657,-76.863083,0.015672,0.003620,0.091943,49.387085,2.515898,0.919432,-76.863083,0.092993,0.000000
75.650002,11.050898,-76.729637,0.015703,0.003637,0.092368,49.156849,2.504169,0.923681,-76.729637,0.093513,0.000000
75.960007,11.147715,-76.774124,0.015720,0.003654,0.092819,49.587513,2.526108,0.928191,-76.774124,0.094025,0.000000
76.270004,11.468699,-76.685158,0.015737,0.003681,0.093487,51.015324,2.598845,0.934869,-76.685158,0.094545,0.000000
76.580002,11.626585,-76.551720,0.015776,0.003704,0.094085,51.717632,2.634622,0.940853,-76.551720,0.095056,0.000000
76.890007,11.590093,-76.507233,0.015784,0.003722,0.094545,51.555305,2.626353,0.945448,-76.507233,0.095577,0.000000
77.200005,11.758405,-76.418274,0.015797,0.003743,0.095083,52.303997,2.664493,0.950826,-76.418274,0.096097,0.000000
77.510002,11.761757,-76.373795,0.015819,0.003761,0.095525,52.318909,2.665252,0.955249,-76.373795,0.096609,0.000000
77.820007,11.858946,-76.373795,0.015845,0.003778,0.095958,52.751225,2.687275,0.959584,-76.373795,0.097129,0.000000
78.130005,12.556771,-76.240349,0.015849,0.003809,0.096748,55.855309,2.845405,0.967476,-76.240349,0.097641,0.000000
78.440002,12.302069,-76.195869,0.015879,0.003825,0.097147,54.722336,2.787688,0.971465,-76.195869,0.098161,0.000000
78.750000,12.624916,-76.017944,0.015901,0.003847,0.097719,56.158432,2.860847,0.977190,-76.017944,0.098673,0.000000
79.060005,12.804027,-76.017944,0.015914,0.003868,0.098257,56.955154,2.901434,0.982566,-76.017944,0.099193,0.000000
79.370003,12.783546,-76.017944,0.015944,0.003885,0.098681,56.864056,2.896793,0.986815,-76.017944,0.099713,0.000000
79.680000,13.089264,-75.884506,0.015944,0.003904,0.099167,58.223953,2.966070,0.991671,-75.884506,0.100225,0.000000
79.990005,13.679102,-75.884506,0.015978,0.003932,0.099861,60.847683,3.099729,0.998610,-75.884506,0.100746,0.000000
80.300003,13.637397,-75.840019,0.015983,0.003949,0.100312,60.662170,3.090278,1.003118,-75.840019,0.101257,0.000000
80.610001,13.894334,-75.751060,0.016022,0.003969,0.100824,61.805084,3.148501,1.008235,-75.751060,0.101778,0.000000
80.920006,14.264099,-75.662094,0.016022,0.003992,0.101387,63.449883,3.232291,1.013873,-75.662094,0.102298,0.000000
81.230003,14.373577,-75.573135,0.016052,0.004010,0.101847,63.936863,3.257099,1.018470,-75.573135,0.102809,0.000000
81.540001,14.672219,-75.617615,0.016060,0.004030,0.102350,65.265289,3.324773,1.023498,-75.617615,0.103330,0.000000
81.850006,15.175667,-75.484177,0.016086,0.004053,0.102957,67.504738,3.438855,1.029569,-75.484177,0.103841,0.000000
82.160004,15.318286,-75.350731,0.016099,0.004072,0.103417,68.139137,3.471173,1.034166,-75.350731,0.104362,0.000000
82.470001,15.659007,-75.350731,0.016116,0.004092,0.103946,69.654739,3.548382,1.039455,-75.350731,0.104874,0.000000
82.780006,15.737577,-75.217285,0.016138,0.004106,0.104301,70.004242,3.566186,1.043011,-75.217285,0.105394,0.000000
83.090004,16.311031,-75.217285,0.016147,0.004128,0.104847,72.555092,3.696132,1.048475,-75.217285,0.105914,0.000000
83.400002,16.624197,-75.217285,0.016173,0.004148,0.105350,73.948120,3.767097,1.053505,-75.217285,0.106426,0.000000
83.710007,17.045349,-75.039368,0.016185,0.004168,0.105862,75.821503,3.862531,1.058622,-75.039368,0.106946,0.000000
84.020004,17.909626,-75.039368,0.016198,0.004195,0.106547,79.665993,4.058379,1.065472,-75.039368,0.107458,0.000000
84.330002,17.959896,-74.905922,0.016229,0.004213,0.107007,79.889610,4.069771,1.070069,-74.905922,0.107978,0.000000
84.640007,18.235453,-74.861443,0.016237,0.004230,0.107440,81.115341,4.132213,1.074405,-74.861443,0.108499,0.000000
84.950005,18.531488,-74.772476,0.016250,0.004248,0.107909,82.432175,4.199296,1.079089,-74.772476,0.109010,0.000000
85.260002,19.268785,-74.816963,0.016272,0.004271,0.108490,85.711838,4.366369,1.084898,-74.816963,0.109531,0.000000
85.570007,19.614719,-74.683517,0.016280,0.004285,0.108845,87.250633,4.444759,1.088454,-74.683517,0.110042,0.000000
85.880005,20.396330,-74.594559,0.016306,0.004309,0.109453,90.727409,4.621874,1.094525,-74.594559,0.110562,0.000000
86.190002,20.872593,-74.594559,0.016319,0.004332,0.110025,92.845932,4.729797,1.100248,-74.594559,0.111074,0.000000
86.500008,21.470997,-74.505592,0.016341,0.004354,0.110597,95.507767,4.865397,1.105973,-74.505592,0.111595,0.000000
86.810005,22.023598,-74.416634,0.016362,0.004375,0.111118,97.965858,4.990619,1.111175,-74.416634,0.112115,0.000000
87.120003,22.344210,-74.372147,0.016362,0.004391,0.111525,99.392006,5.063270,1.115251,-74.372147,0.112627,0.000000
87.430008,22.954155,-74.327667,0.016384,0.004409,0.111994,102.105179,5.201486,1.119935,-74.327667,0.113147,0.000000
87.740005,23.967381,-74.194229,0.016410,0.004436,0.112679,106.612236,5.431086,1.126786,-74.194229,0.113659,0.000000
88.050003,24.633183,-74.238708,0.016410,0.004456,0.113173,109.573868,5.581959,1.131729,-74.238708,0.114179,0.000000
88.360001,25.091574,-74.105263,0.016418,0.004476,0.113693,111.612892,5.685832,1.136931,-74.105263,0.114699,0.000000
88.670006,25.637844,-74.105263,0.016444,0.004495,0.114179,114.042824,5.809618,1.141789,-74.105263,0.115211,0.000000
88.980003,26.337532,-73.971825,0.016436,0.004515,0.114673,117.155197,5.968170,1.146732,-73.971825,0.115731,0.000000
89.290001,27.011154,-73.927338,0.016479,0.004534,0.115159,120.151611,6.120815,1.151588,-73.927338,0.116243,0.000000
89.600006,28.149868,-73.927338,0.016483,0.004558,0.115783,125.216866,6.378851,1.157832,-73.927338,0.116763,0.000000
89.910004,29.001856,-73.793900,0.016500,0.004579,0.116312,129.006699,6.571915,1.163123,-73.793900,0.117275,0.000000
90.220001,29.617762,-73.704933,0.016522,0.004599,0.116807,131.746384,6.711481,1.168066,-73.704933,0.117795,0.000000
90.530006,30.579599,-73.660454,0.016522,0.004621,0.117362,136.024857,6.929437,1.173616,-73.660454,0.118315,0.000000
90.840004,31.302746,-73.527016,0.016539,0.004639,0.117839,139.241562,7.093304,1.178385,-73.527016,0.118827,0.000000
91.150002,31.875456,-73.571495,0.016552,0.004655,0.118246,141.789108,7.223082,1.182462,-73.571495,0.119348,0.000000
91.460007,32.758724,-73.438049,0.016552,0.004675,0.118749,145.718079,7.423233,1.187492,-73.438049,0.119859,0.000000
91.770004,34.368862,-73.393570,0.016573,0.004703,0.119460,152.880341,7.788095,1.194602,-73.393570,0.120380,0.000000
92.080002,35.221222,-73.304604,0.016595,0.004723,0.119954,156.671814,7.981243,1.199545,-73.304604,0.120891,0.000000
92.390007,36.080658,-73.215645,0.016604,0.004743,0.120466,160.494781,8.175994,1.204662,-73.215645,0.121411,0.000000
92.700005,37.047710,-73.260124,0.016591,0.004762,0.120961,164.796448,8.395131,1.209605,-73.260124,0.121932,0.000000
93.010002,37.360500,-73.215645,0.016617,0.004774,0.121255,166.187805,8.466010,1.212554,-73.215645,0.122443,0.000000
93.320007,38.575924,-73.082199,0.016638,0.004794,0.121758,171.594284,8.741429,1.217584,-73.082199,0.122964,0.000000
93.630005,40.416561,-73.037720,0.016647,0.004823,0.122513,179.781845,9.158525,1.225129,-73.037720,0.123476,0.000000
93.940002,41.217163,-72.904282,0.016655,0.004842,0.122998,183.343094,9.339943,1.229985,-72.904282,0.123996,0.000000
94.250008,42.323109,-72.859795,0.016677,0.004863,0.123519,188.262589,9.590554,1.235189,-72.859795,0.124516,0.000000
94.560005,43.484913,-72.815315,0.016668,0.004882,0.124013,193.430557,9.853823,1.240132,-72.815315,0.125028,0.000000
94.870003,44.710018,-72.770836,0.016694,0.004903,0.124525,198.880096,10.131434,1.245249,-72.770836,0.125548,0.000000
95.180008,45.052601,-72.726357,0.016686,0.004916,0.124872,200.403976,10.209065,1.248718,-72.726357,0.126060,0.000000
95.490005,46.921909,-72.637390,0.016690,0.004942,0.125531,208.719070,10.632657,1.255308,-72.637390,0.126580,0.000000
95.800003,48.417728,-72.503952,0.016703,0.004963,0.126060,215.372818,10.971614,1.260599,-72.503952,0.127092,0.000000
96.110008,49.664059,-72.503952,0.016716,0.004984,0.126589,220.916763,11.254037,1.265888,-72.503952,0.127612,0.000000
96.420006,50.764050,-72.414986,0.016733,0.005003,0.127083,225.809769,11.503298,1.270831,-72.414986,0.128133,0.000000
96.730003,52.125813,-72.414986,0.016729,0.005022,0.127552,231.867187,11.811878,1.275515,-72.414986,0.128644,0.000000
97.040001,52.923435,-72.370506,0.016750,0.005037,0.127933,235.415192,11.992622,1.279330,-72.370506,0.129164,0.000000
97.350006,54.031242,-72.237068,0.016759,0.005054,0.128384,240.342972,12.243654,1.283840,-72.237068,0.129676,0.000000
97.660004,56.347027,-72.148102,0.016755,0.005083,0.129112,250.644089,12.768418,1.291124,-72.148102,0.130197,0.000000
97.970001,58.083775,-72.103622,0.016772,0.005108,0.129746,258.369537,13.161971,1.297456,-72.103622,0.130717,0.000000
98.280006,59.124928,-72.103622,0.016776,0.005124,0.130145,263.000824,13.397901,1.301446,-72.103622,0.131229,0.000000
98.590004,60.554466,-71.970177,0.016793,0.005145,0.130691,269.359711,13.721838,1.306909,-71.970177,0.131749,0.000000
98.900002,61.622803,-72.014656,0.016780,0.005160,0.131055,274.111908,13.963926,1.310550,-72.014656,0.132261,0.000000
99.210007,62.957756,-71.925697,0.016798,0.005179,0.131541,280.050079,14.266431,1.315406,-71.925697,0.132781,0.000000
99.520004,65.580376,-71.792252,0.016806,0.005209,0.132321,291.716095,14.860725,1.323213,-71.792252,0.133292,0.000000
99.830002,66.640144,-71.792252,0.016815,0.005227,0.132772,296.430176,15.100872,1.327722,-71.792252,0.133813,0.000000
100.140007,67.161842,-71.703293,0.016828,0.005227,0.132764,298.750793,15.219090,1.327635,-71.703293,0.133024,0.000000
100.450005,66.532158,-71.614334,0.016841,0.005225,0.132720,295.949829,15.076403,1.327202,-71.614334,0.132764,0.000000
100.760002,66.039886,-71.525368,0.016828,0.005223,0.132668,293.760101,14.964852,1.326681,-71.525368,0.132764,0.000000
101.070007,65.639214,-71.480888,0.016828,0.005222,0.132651,291.977814,14.874058,1.326507,-71.480888,0.132764,0.000000
101.380005,65.292534,-71.436409,0.016836,0.005222,0.132642,290.435699,14.795500,1.326420,-71.436409,0.132764,0.000000
101.690002,64.994637,-71.347443,0.016841,0.005222,0.132634,289.110596,14.727995,1.326335,-71.347443,0.132764,0.000000
102.000008,64.744774,-71.302963,0.016845,0.005222,0.132634,287.999146,14.671375,1.326335,-71.302963,0.132764,0.000000
102.310005,64.517624,-71.214005,0.016854,0.005222,0.132634,286.988739,14.619903,1.326335,-71.214005,0.132764,0.000000
102.620003,64.309845,-71.125038,0.016836,0.005221,0.132625,286.064484,14.572820,1.326248,-71.125038,0.132764,0.000000
102.930008,64.134453,-71.125038,0.016845,0.005221,0.132625,285.284302,14.533075,1.326248,-71.125038,0.132764,0.000000
103.240005,63.963905,-71.036079,0.016836,0.005221,0.132625,284.525665,14.494429,1.326248,-71.036079,0.132764,0.000000
103.550003,63.811234,-70.991600,0.016854,0.005221,0.132625,283.846558,14.459832,1.326248,-70.991600,0.132764,0.000000
103.860008,63.655956,-70.947121,0.016849,0.005221,0.132616,283.155823,14.424646,1.326161,-70.947121,0.132764,0.000000
104.170006,63.550945,-70.858154,0.016836,0.005221,0.132616,282.688721,14.400849,1.326161,-70.858154,0.132764,0.000000
104.480003,63.404232,-70.813675,0.016858,0.005221,0.132616,282.036102,14.367604,1.326161,-70.813675,0.132764,0.000000
104.790009,63.300339,-70.769196,0.016854,0.005221,0.132616,281.573975,14.344062,1.326161,-70.769196,0.132764,0.000000
105.100006,63.199055,-70.680229,0.016858,0.005221,0.132616,281.123444,14.321111,1.326161,-70.680229,0.132764,0.000000
105.410004,63.097771,-70.635750,0.016854,0.005221,0.132616,280.672913,14.298160,1.326161,-70.635750,0.132764,0.000000
105.720001,63.008770,-70.546791,0.016854,0.005221,0.132607,280.277008,14.277991,1.326074,-70.546791,0.132764,0.000000
106.030006,62.909721,-70.457825,0.016841,0.005221,0.132607,279.836426,14.255547,1.326074,-70.457825,0.132764,0.000000
106.340004,62.825935,-70.457825,0.016858,0.005221,0.132607,279.463715,14.236561,1.326074,-70.457825,0.132764,0.000000
106.650002,62.746994,-70.324387,0.016845,0.005221,0.132607,279.112579,14.218672,1.326074,-70.324387,0.132764,0.000000
106.960007,62.682945,-70.324387,0.016871,0.005221,0.132607,278.827667,14.204159,1.326074,-70.324387,0.132764,0.000000
107.270004,62.587990,-70.190941,0.016845,0.005221,0.132607,278.405273,14.182641,1.326074,-70.190941,0.132764,0.000000
107.580002,62.538837,-70.146461,0.016862,0.005221,0.132607,278.186646,14.171504,1.326074,-70.146461,0.132764,0.000000
107.890007,62.457287,-70.146461,0.016854,0.005221,0.132607,277.823883,14.153024,1.326074,-70.146461,0.132764,0.000000
108.200005,62.414467,-69.968536,0.016854,0.005221,0.132607,277.633423,14.143320,1.326074,-69.968536,0.132764,0.000000
108.510002,62.328075,-70.013016,0.016858,0.005221,0.132607,277.249115,14.123744,1.326074,-70.013016,0.132764,0.000000
108.820007,62.284508,-69.968536,0.016854,0.005221,0.132607,277.055328,14.113871,1.326074,-69.968536,0.132764,0.000000
109.130005,62.237961,-69.835091,0.016867,0.005221,0.132607,276.848267,14.103324,1.326074,-69.835091,0.132764,0.000000
109.440002,62.175030,-69.835091,0.016862,0.005221,0.132607,276.568359,14.089064,1.326074,-69.835091,0.132764,0.000000
109.750008,62.127739,-69.701653,0.016849,0.005221,0.132607,276.357971,14.078347,1.326074,-69.701653,0.132764,0.000000
110.060005,62.054008,-69.657173,0.016854,0.005221,0.132607,276.030029,14.061640,1.326074,-69.657173,0.132764,0.000000
110.370003,62.032040,-69.612686,0.016854,0.005221,0.132607,275.932281,14.056661,1.326074,-69.612686,0.132764,0.000000
110.680008,61.975811,-69.479248,0.016858,0.005220,0.132599,275.682190,14.043920,1.325987,-69.479248,0.132764,0.000000
110.990005,61.943413,-69.479248,0.016858,0.005220,0.132599,275.538055,14.036578,1.325987,-69.479248,0.132764,0.000000
111.300003,61.886814,-69.390282,0.016841,0.005220,0.132599,275.286285,14.023752,1.325987,-69.390282,0.132764,0.000000
111.610008,61.854046,-69.345802,0.016858,0.005220,0.132599,275.140533,14.016327,1.325987,-69.345802,0.132764,0.000000
111.920006,61.810848,-69.301323,0.016849,0.005220,0.132599,274.948395,14.006538,1.325987,-69.301323,0.132764,0.000000
112.230003,61.767281,-69.256844,0.016854,0.005220,0.132599,274.754578,13.996666,1.325987,-69.256844,0.132764,0.000000
112.540009,61.718128,-69.212357,0.016862,0.005220,0.132599,274.535950,13.985528,1.325987,-69.212357,0.132764,0.000000
112.850006,61.689457,-69.123398,0.016854,0.005220,0.132599,274.408417,13.979032,1.325987,-69.123398,0.132764,0.000000
113.160004,61.635834,-69.078918,0.016867,0.005220,0.132599,274.169891,13.966880,1.325987,-69.078918,0.132764,0.000000
113.470009,61.593384,-69.034439,0.016858,0.005220,0.132599,273.981049,13.957260,1.325987,-69.034439,0.132764,0.000000
113.780006,61.569180,-68.945473,0.016858,0.005220,0.132599,273.873383,13.951776,1.325987,-68.945473,0.132764,0.000000
114.090004,61.518536,-68.900993,0.016854,0.005220,0.132599,273.648102,13.940299,1.325987,-68.900993,0.132764,0.000000
114.400009,61.499920,-68.767548,0.016858,0.005220,0.132599,273.565308,13.936081,1.325987,-68.767548,0.132764,0.000000
114.710007,61.447414,-68.723068,0.016858,0.005220,0.132599,273.331757,13.924183,1.325987,-68.723068,0.132764,0.000000
115.020004,61.430656,-68.723068,0.016862,0.005220,0.132599,273.257202,13.920385,1.325987,-68.723068,0.132764,0.000000
115.330002,61.388950,-68.500664,0.016862,0.005220,0.132599,273.071686,13.910935,1.325987,-68.500664,0.132764,0.000000
115.640007,61.365120,-68.545143,0.016875,0.005220,0.132599,272.965698,13.905535,1.325987,-68.545143,0.132764,0.000000
115.950005,61.330116,-68.500664,0.016862,0.005220,0.132599,272.809967,13.897603,1.325987,-68.500664,0.132764,0.000000
116.260002,61.304794,-68.411705,0.016867,0.005220,0.132599,272.697357,13.891865,1.325987,-68.411705,0.132764,0.000000
116.570007,61.276123,-68.411705,0.016854,0.005220,0.132599,272.569794,13.885368,1.325987,-68.411705,0.132764,0.000000
116.880005,61.257504,-68.278259,0.016845,0.005220,0.132599,272.487000,13.881148,1.325987,-68.278259,0.132764,0.000000
117.190002,61.210957,-68.278259,0.016871,0.005220,0.132599,272.279938,13.870602,1.325987,-68.278259,0.132764,0.000000
117.500008,61.193455,-68.189301,0.016845,0.005220,0.132599,272.202087,13.866635,1.325987,-68.189301,0.132764,0.000000
117.810005,61.165901,-68.100334,0.016841,0.005220,0.132599,272.079529,13.860391,1.325987,-68.100334,0.132764,0.000000
118.120003,61.138344,-68.100334,0.016858,0.005220,0.132599,271.956940,13.854147,1.325987,-68.100334,0.132764,0.000000
118.430008,61.100735,-68.011375,0.016849,0.005220,0.132599,271.789642,13.845624,1.325987,-68.011375,0.132764,0.000000
118.740005,61.083607,-67.922409,0.016862,0.005220,0.132599,271.713440,13.841743,1.325987,-67.922409,0.132764,0.000000
119.050003,61.051208,-67.877930,0.016845,0.005220,0.132599,271.569336,13.834401,1.325987,-67.877930,0.132764,0.000000
119.360008,61.038177,-67.788971,0.016862,0.005220,0.132599,271.511383,13.831449,1.325987,-67.788971,0.132764,0.000000
119.670006,61.005035,-67.788971,0.016862,0.005220,0.132599,271.363953,13.823938,1.325987,-67.788971,0.132764,0.000000
119.980003,60.984184,-67.700005,0.016849,0.005220,0.132599,271.271210,13.819214,1.325987,-67.700005,0.132764,0.000000
120.290009,60.961094,-67.655525,0.016862,0.005220,0.132599,271.168488,13.813981,1.325987,-67.655525,0.132764,0.000000
120.600006,60.930187,-67.566566,0.016849,0.005220,0.132599,271.031006,13.806978,1.325987,-67.566566,0.132764,0.000000
120.910004,60.923485,-67.477600,0.016867,0.005220,0.132599,271.001190,13.805459,1.325987,-67.477600,0.132764,0.000000
121.220009,60.894440,-67.522087,0.016858,0.005220,0.132599,270.872009,13.798878,1.325987,-67.522087,0.132764,0.000000
121.530006,60.860184,-67.388641,0.016871,0.005220,0.132599,270.719604,13.791115,1.325987,-67.388641,0.132764,0.000000
121.840004,60.846405,-67.299683,0.016875,0.005220,0.132599,270.658325,13.787992,1.325987,-67.299683,0.132764,0.000000
122.150009,60.818478,-67.299683,0.016854,0.005220,0.132599,270.534088,13.781664,1.325987,-67.299683,0.132764,0.000000
122.460007,60.788689,-67.166237,0.016854,0.005220,0.132599,270.401581,13.774914,1.325987,-67.166237,0.132764,0.000000
122.770004,60.773418,-67.166237,0.016849,0.005220,0.132599,270.333679,13.771453,1.325987,-67.166237,0.132764,0.000000
123.080009,60.767464,-67.121758,0.016867,0.005220,0.132599,270.307190,13.770104,1.325987,-67.121758,0.132764,0.000000
123.390007,60.741024,-66.988312,0.016875,0.005220,0.132599,270.189575,13.764112,1.325987,-66.988312,0.132764,0.000000
123.700005,60.711235,-66.988312,0.016858,0.005220,0.132599,270.057068,13.757362,1.325987,-66.988312,0.132764,0.000000
124.010002,60.703785,-66.899353,0.016871,0.005220,0.132599,270.023926,13.755674,1.325987,-66.899353,0.132764,0.000000
124.320007,60.675858,-66.810387,0.016854,0.005220,0.132599,269.899689,13.749346,1.325987,-66.810387,0.132764,0.000000
124.630005,60.660965,-66.765907,0.016845,0.005220,0.132599,269.833435,13.745971,1.325987,-66.765907,0.132764,0.000000
124.940002,60.646069,-66.676949,0.016858,0.005220,0.132599,269.767181,13.742596,1.325987,-66.676949,0.132764,0.000000
125.250008,60.619259,-66.632462,0.016845,0.005220,0.132599,269.647919,13.736521,1.325987,-66.632462,0.132764,0.000000
125.560005,60.599522,-66.499023,0.016867,0.005220,0.132599,269.560150,13.732047,1.325987,-66.499023,0.132764,0.000000
125.870003,60.582394,-66.543503,0.016854,0.005220,0.132599,269.483948,13.728167,1.325987,-66.543503,0.132764,0.000000
126.180008,60.571594,-66.499023,0.016858,0.005220,0.132599,269.435913,13.725719,1.325987,-66.499023,0.132764,0.000000
126.490005,60.557072,-66.321098,0.016867,0.005220,0.132599,269.371307,13.722429,1.325987,-66.321098,0.132764,0.000000
126.800003,60.540314,-66.365578,0.016871,0.005220,0.132599,269.296753,13.718632,1.325987,-66.365578,0.132764,0.000000
127.110008,60.526539,-66.276619,0.016862,0.005220,0.132599,269.235504,13.715509,1.325987,-66.276619,0.132764,0.000000
127.420006,60.509781,-66.187653,0.016858,0.005220,0.132599,269.160950,13.711712,1.325987,-66.187653,0.132764,0.000000
127.730003,60.487812,-66.143173,0.016858,0.005220,0.132599,269.063232,13.706735,1.325987,-66.143173,0.132764,0.000000
128.040009,60.491161,-66.098694,0.016867,0.005220,0.132599,269.078125,13.707493,1.325987,-66.098694,0.132764,0.000000
128.350006,60.462860,-66.098694,0.016854,0.005220,0.132599,268.952240,13.701080,1.325987,-66.098694,0.132764,0.000000
128.660004,60.445732,-65.965248,0.016875,0.005220,0.132599,268.876038,13.697198,1.325987,-65.965248,0.132764,0.000000
128.970001,60.421902,-65.876289,0.016875,0.005220,0.132599,268.770050,13.691798,1.325987,-65.876289,0.132764,0.000000
129.279999,60.422646,-65.920769,0.016871,0.005220,0.132599,268.773346,13.691967,1.325987,-65.920769,0.132764,0.000000
129.590012,60.399559,-65.787323,0.016871,0.005220,0.132599,268.670654,13.686735,1.325987,-65.787323,0.132764,0.000000
129.900009,60.382801,-65.698364,0.016854,0.005220,0.132599,268.596100,13.682938,1.325987,-65.698364,0.132764,0.000000
130.210007,60.362694,-65.698364,0.016849,0.005220,0.132599,268.506683,13.678382,1.325987,-65.698364,0.132764,0.000000
130.400009,60.361576,-65.609406,0.016867,0.005220,0.132599,268.501709,13.678129,1.325987,-65.609406,0.132764,0.000000