File: Data/15% 30min RT - 1 - 2_07262023_145224.csv
Time (sec),S:Load (lbs),S:HL1 (DIM),S:LVDT (in),S:Position (in),Ch:Position (mm),Ch:Load (N),Ch:Stress (MPa),Ch:Strain (mm/mm),Ch:HL1 (DIM),Set Point (),Cycles ()
0.110000,0.014150,-133.131485,0.000013,-0.000000,-0.000000,0.062943,0.003206,-0.000000,-133.131485,0.000017,0.000000
0.380000,0.007820,-132.953568,-0.000004,-0.000000,-0.000000,0.034784,0.001772,-0.000000,-132.953568,0.000104,0.000000
0.650000,-0.016384,-132.953568,0.000009,0.000152,0.003851,-0.072881,-0.003713,0.038506,-132.953568,0.004596,0.000000
0.920000,0.026811,-132.909088,-0.000004,0.000307,0.007796,0.119261,0.006075,0.077963,-132.909088,0.009088,0.000000
1.190000,0.017502,-132.820114,0.000177,0.000486,0.012341,0.077851,0.003966,0.123406,-132.820114,0.013598,0.000000
1.460000,0.026438,-132.731155,0.000379,0.000670,0.017024,0.117604,0.005991,0.170237,-132.731155,0.018090,0.000000
1.730000,0.066655,-132.686676,0.000543,0.000836,0.021247,0.296495,0.015104,0.212471,-132.686676,0.022583,0.000000
2.000000,0.059580,-132.597717,0.000733,0.001018,0.025869,0.265023,0.013501,0.258694,-132.597717,0.027092,0.000000
2.270000,0.062186,-132.597717,0.000910,0.001200,0.030483,0.276618,0.014092,0.304830,-132.597717,0.031584,0.000000
2.540000,0.032024,-132.553238,0.001074,0.001379,0.035027,0.142450,0.007257,0.350273,-132.553238,0.036077,0.000000
2.810000,0.006703,-132.375305,0.001250,0.001552,0.039416,0.029815,0.001519,0.394155,-132.375305,0.040586,0.000000
3.080000,0.053622,-132.330826,0.001418,0.001725,0.043804,0.238521,0.012151,0.438035,-132.330826,0.045078,0.000000
3.350000,0.037982,-132.241867,0.001604,0.001909,0.048495,0.168952,0.008607,0.484953,-132.241867,0.049571,0.000000
3.620000,0.049153,-132.241867,0.001772,0.002084,0.052936,0.218644,0.011138,0.529355,-132.241867,0.054080,0.000000
3.890000,0.080060,-132.197388,0.001927,0.002253,0.057220,0.356125,0.018142,0.572197,-132.197388,0.058572,0.000000
4.160000,0.053622,-132.063950,0.002126,0.002442,0.062015,0.238521,0.012151,0.620153,-132.063950,0.063065,0.000000
4.430000,0.080805,-132.019470,0.002285,0.002612,0.066351,0.359438,0.018311,0.663515,-132.019470,0.067574,0.000000
4.700000,0.051760,-131.930496,0.002458,0.002796,0.071008,0.230239,0.011729,0.710084,-131.930496,0.072066,0.000000
4.970000,0.034631,-131.886017,0.002626,0.002963,0.075267,0.154045,0.007847,0.752666,-131.886017,0.076559,0.000000
5.240000,0.056228,-131.841537,0.002794,0.003143,0.079828,0.250116,0.012742,0.798282,-131.841537,0.081068,0.000000
5.510000,0.016384,-131.708099,0.002988,0.003323,0.084416,0.072882,0.003713,0.844158,-131.708099,0.085561,0.000000
5.780000,0.065165,-131.663620,0.003173,0.003496,0.088795,0.289869,0.014767,0.887953,-131.663620,0.090070,0.000000
6.050000,0.098306,-131.574646,0.003337,0.003676,0.093366,0.437289,0.022277,0.933656,-131.574646,0.094562,0.000000
6.320000,0.067027,-131.485687,0.003527,0.003856,0.097953,0.298151,0.015189,0.979531,-131.485687,0.099054,0.000000
6.590000,0.107616,-131.485687,0.003704,0.004031,0.102385,0.478698,0.024386,1.023846,-131.485687,0.103564,0.000000
6.860000,0.278907,-131.396729,0.003876,0.004212,0.106972,1.240640,0.063201,1.069723,-131.396729,0.108056,0.000000
7.130000,0.673249,-131.307770,0.004010,0.000003,0.000069,2.994763,0.152560,0.000695,-131.307770,0.000260,0.000000
7.400001,0.638619,-131.218811,0.004014,0.000002,0.000061,2.840718,0.144713,0.000607,-131.218811,0.000260,0.000000
7.670001,0.611808,-131.174332,0.004001,0.000002,0.000061,2.721458,0.138638,0.000607,-131.174332,0.000434,0.000000
7.940001,0.599520,-131.129837,0.004010,0.000002,0.000061,2.666797,0.135853,0.000607,-131.129837,0.000885,0.000000
8.210000,0.630054,-131.040878,0.004010,0.000013,0.000321,2.802621,0.142772,0.003210,-131.040878,0.001336,0.000000
8.480000,0.784589,-130.951920,0.004018,0.000034,0.000867,3.490025,0.177790,0.008673,-130.951920,0.001786,0.000000
8.750000,0.843796,-130.862961,0.004018,0.000047,0.001197,3.753392,0.191207,0.011968,-130.862961,0.002237,0.000000
9.020000,0.987159,-130.818481,0.004027,0.000062,0.001578,4.391104,0.223694,0.015785,-130.818481,0.002680,0.000000
9.290001,1.126054,-130.774002,0.004031,0.000085,0.002168,5.008940,0.255168,0.021682,-130.774002,0.003131,0.000000
9.560000,1.203135,-130.685028,0.004074,0.000098,0.002489,5.351814,0.272634,0.024889,-130.685028,0.003582,0.000000
9.830001,1.333093,-130.685028,0.004066,0.000117,0.002983,5.929895,0.302083,0.029833,-130.685028,0.004033,0.000000
10.100000,1.501406,-130.462631,0.004100,0.000137,0.003486,6.678586,0.340223,0.034863,-130.462631,0.004484,0.000000
10.370001,1.580349,-130.418152,0.004109,0.000151,0.003824,7.029742,0.358112,0.038244,-130.418152,0.004935,0.000000
10.640000,1.690199,-130.373672,0.004117,0.000171,0.004336,7.518379,0.383004,0.043362,-130.373672,0.005386,0.000000
10.910001,1.827976,-130.329193,0.004130,0.000183,0.004657,8.131246,0.414225,0.046571,-130.329193,0.005836,0.000000
11.180000,2.037622,-130.195740,0.004148,0.000202,0.005134,9.063795,0.461732,0.051340,-130.195740,0.006287,0.000000
11.450001,2.232001,-130.195740,0.004169,0.000223,0.005663,9.928434,0.505779,0.056630,-130.195740,0.006738,0.000000
11.720000,2.413718,-130.106781,0.004174,0.000242,0.006157,10.736754,0.546956,0.061573,-130.106781,0.007181,0.000000
11.990001,2.611076,-130.062302,0.004199,0.000264,0.006712,11.614644,0.591678,0.067123,-130.062302,0.007632,0.000000
12.260000,2.708265,-130.062302,0.004208,0.000282,0.007155,12.046964,0.613702,0.071546,-130.062302,0.008083,0.000000
12.530001,2.786835,-129.884384,0.004230,0.000294,0.007458,12.396463,0.631506,0.074581,-129.884384,0.008534,0.000000
12.800000,3.057550,-129.839890,0.004243,0.000314,0.007987,13.600662,0.692851,0.079873,-129.839890,0.008985,0.000000
13.070001,3.278367,-129.795410,0.004268,0.000333,0.008447,14.582906,0.742889,0.084468,-129.795410,0.009436,0.000000
13.340001,3.366992,-129.706451,0.004251,0.000346,0.008785,14.977127,0.762971,0.087851,-129.706451,0.009886,0.000000
13.610001,3.474607,-129.661972,0.004286,0.000361,0.009158,15.455826,0.787357,0.091579,-129.661972,0.010337,0.000000
13.880001,3.884589,-129.573013,0.004303,0.000387,0.009834,17.279516,0.880261,0.098345,-129.573013,0.010788,0.000000
14.150001,4.037262,-129.484055,0.004342,0.000404,0.010259,17.958637,0.914857,0.102593,-129.484055,0.011231,0.000000
14.420001,4.157911,-129.484055,0.004346,0.000421,0.010693,18.495312,0.942196,0.106929,-129.484055,0.011682,0.000000
14.690001,4.414848,-129.395081,0.004350,0.000440,0.011187,19.638224,1.000419,0.111872,-129.395081,0.012132,0.000000
14.960001,4.601406,-129.350601,0.004381,0.000456,0.011577,20.468077,1.042694,0.115774,-129.350601,0.012583,0.000000
15.230000,4.716842,-129.261642,0.004393,0.000470,0.011933,20.981560,1.068852,0.119330,-129.261642,0.013034,0.000000
15.500001,4.952554,-129.172684,0.004419,0.000486,0.012349,22.030060,1.122265,0.123494,-129.172684,0.013485,0.000000
15.770000,5.167413,-129.128204,0.004424,0.000505,0.012818,22.985800,1.170952,0.128177,-129.128204,0.013936,0.000000
16.040001,5.523773,-129.039246,0.004432,0.000531,0.013494,24.570971,1.251705,0.134941,-129.039246,0.014387,0.000000
16.310001,5.601972,-128.994751,0.004467,0.000547,0.013884,24.918814,1.269425,0.138843,-128.994751,0.014838,0.000000
16.580000,5.833587,-128.905792,0.004493,0.000565,0.014361,25.949089,1.321910,0.143612,-128.905792,0.015281,0.000000
16.850000,5.924818,-128.772354,0.004493,0.000578,0.014691,26.354906,1.342583,0.146909,-128.772354,0.015732,0.000000
17.120001,6.124410,-128.727875,0.004510,0.000594,0.015090,27.242735,1.387811,0.150898,-128.727875,0.016183,0.000000
17.390001,6.369803,-128.727875,0.004518,0.000611,0.015523,28.334301,1.443418,0.155234,-128.727875,0.016633,0.000000
17.660002,6.735101,-128.638916,0.004544,0.000635,0.016122,29.959225,1.526196,0.161218,-128.638916,0.017084,0.000000
17.930000,6.836759,-128.505463,0.004570,0.000651,0.016529,30.411421,1.549232,0.165294,-128.505463,0.017535,0.000000
18.200001,6.998740,-128.460983,0.004587,0.000671,0.017032,31.131950,1.585937,0.170324,-128.460983,0.017986,0.000000
18.470001,7.125719,-128.372025,0.004600,0.000688,0.017483,31.696781,1.614711,0.174834,-128.372025,0.018437,0.000000
18.740002,7.426597,-128.372025,0.004609,0.000708,0.017978,33.035152,1.682891,0.179777,-128.372025,0.018888,0.000000
19.010000,7.351005,-128.327545,0.004635,0.000719,0.018273,32.698902,1.665761,0.182725,-128.327545,0.019339,0.000000
19.280001,7.603101,-128.283066,0.004635,0.000734,0.018654,33.820282,1.722887,0.186540,-128.283066,0.019781,0.000000
19.550001,7.753539,-128.105133,0.004678,0.000748,0.018992,34.489464,1.756977,0.189922,-128.105133,0.020232,0.000000
19.820002,8.261083,-128.060654,0.004695,0.000777,0.019747,36.747131,1.871988,0.197467,-128.060654,0.020683,0.000000
20.090000,8.344122,-128.016174,0.004704,0.000797,0.020241,37.116508,1.890805,0.202411,-128.016174,0.021134,0.000000
20.360001,8.404074,-127.927216,0.004725,0.000812,0.020631,37.383186,1.904390,0.206313,-127.927216,0.021585,0.000000
20.630001,8.547066,-127.882736,0.004738,0.000830,0.021082,38.019249,1.936793,0.210822,-127.882736,0.022036,0.000000
20.900002,8.666224,-127.793770,0.004764,0.000843,0.021403,38.549294,1.963794,0.214032,-127.793770,0.022487,0.000000
21.170000,8.885924,-127.704811,0.004781,0.000860,0.021845,39.526566,2.013579,0.218455,-127.704811,0.022938,0.000000
21.440001,8.948855,-127.615852,0.004799,0.000872,0.022158,39.806496,2.027840,0.221577,-127.615852,0.023389,0.000000
21.710001,9.384159,-127.615852,0.004820,0.000896,0.022765,41.742825,2.126481,0.227648,-127.615852,0.023831,0.000000
21.980001,9.754297,-127.571365,0.004846,0.000921,0.023398,43.389282,2.210355,0.233978,-127.571365,0.024282,0.000000
22.250002,9.670885,-127.482407,0.004872,0.000936,0.023762,43.018246,2.191454,0.237619,-127.482407,0.024733,0.000000
22.520000,9.815366,-127.393440,0.004881,0.000953,0.024204,43.660927,2.224194,0.242044,-127.393440,0.025184,0.000000
22.790001,9.909948,-127.348961,0.004907,0.000969,0.024621,44.081654,2.245626,0.246206,-127.348961,0.025635,0.000000
23.060001,9.889468,-127.304482,0.004928,0.000980,0.024889,43.990551,2.240985,0.248895,-127.304482,0.026086,0.000000
23.330002,10.041396,-127.171036,0.004941,0.000997,0.025332,44.666359,2.275413,0.253317,-127.171036,0.026537,0.000000
23.600000,10.637565,-127.171036,0.004975,0.001026,0.026060,47.318253,2.410507,0.260601,-127.171036,0.026988,0.000000
23.870001,10.601816,-127.037598,0.004988,0.001042,0.026459,47.159233,2.402406,0.264591,-127.037598,0.027439,0.000000
24.140001,10.729541,-126.993118,0.005006,0.001059,0.026893,47.727383,2.431349,0.268928,-126.993118,0.027881,0.000000
24.410002,11.015522,-126.904152,0.005023,0.001080,0.027430,48.999489,2.496153,0.274305,-126.904152,0.028332,0.000000
24.680000,10.948868,-126.904152,0.005057,0.001094,0.027786,48.702995,2.481049,0.277860,-126.904152,0.028783,0.000000
24.950001,11.017012,-126.726227,0.005057,0.001108,0.028150,49.006115,2.496490,0.281502,-126.726227,0.029234,0.000000
25.220001,11.399066,-126.681747,0.005075,0.001133,0.028775,50.705578,2.583065,0.287747,-126.681747,0.029685,0.000000
25.490002,11.578177,-126.726227,0.005096,0.001154,0.029304,51.502304,2.623652,0.293036,-126.726227,0.030136,0.000000
25.760002,11.541312,-126.637268,0.005131,0.001169,0.029703,51.338322,2.615299,0.297025,-126.637268,0.030587,0.000000
26.030001,11.581529,-126.548309,0.005157,0.001185,0.030101,51.517212,2.624412,0.301015,-126.548309,0.031038,0.000000
26.300001,11.756916,-126.503822,0.005174,0.001204,0.030587,52.297375,2.664155,0.305871,-126.503822,0.031489,0.000000
26.570002,11.873468,-126.370384,0.005204,0.001221,0.031003,52.815826,2.690566,0.310034,-126.370384,0.031940,0.000000
26.840002,11.880171,-126.325897,0.005208,0.001236,0.031402,52.845638,2.692085,0.314023,-126.325897,0.032382,0.000000
27.110001,12.244351,-126.281418,0.005226,0.001259,0.031975,54.465595,2.774610,0.319746,-126.281418,0.032833,0.000000
27.380001,12.235787,-126.192459,0.005251,0.001275,0.032382,54.427502,2.772669,0.323822,-126.192459,0.033284,0.000000
27.650002,12.222010,-126.147980,0.005269,0.001292,0.032807,54.366215,2.769547,0.328073,-126.147980,0.033735,0.000000
27.920002,12.397769,-126.103493,0.005299,0.001309,0.033258,55.148029,2.809375,0.332583,-126.103493,0.034186,0.000000
28.190001,12.193709,-125.970055,0.005307,0.001319,0.033510,54.240330,2.763134,0.335096,-125.970055,0.034637,0.000000
28.460001,12.472988,-125.970055,0.005325,0.001340,0.034039,55.482624,2.826420,0.340387,-125.970055,0.035088,0.000000
28.730001,12.593265,-125.881088,0.005355,0.001358,0.034490,56.017639,2.853675,0.344897,-125.881088,0.035539,0.000000
29.000002,12.770514,-125.792130,0.005376,0.001374,0.034906,56.806080,2.893840,0.349058,-125.792130,0.035990,0.000000
29.270000,13.065433,-125.614204,0.005407,0.001397,0.035496,58.117947,2.960669,0.354957,-125.614204,0.036432,0.000000
29.540001,13.028195,-125.703171,0.005420,0.001414,0.035921,57.952309,2.952231,0.359205,-125.703171,0.036883,0.000000
29.810001,12.928400,-125.614204,0.005450,0.001430,0.036328,57.508396,2.929617,0.363282,-125.614204,0.037334,0.000000
30.080002,12.888556,-125.525246,0.005476,0.001445,0.036710,57.331158,2.920588,0.367097,-125.525246,0.037785,0.000000
30.350002,12.953721,-125.436279,0.005489,0.001461,0.037100,57.621029,2.935355,0.370999,-125.436279,0.038236,0.000000
30.620001,13.197252,-125.391800,0.005510,0.001482,0.037646,58.704311,2.990540,0.376463,-125.391800,0.038687,0.000000
30.890001,13.130225,-125.258362,0.005540,0.001497,0.038036,58.406158,2.975352,0.380365,-125.258362,0.039138,0.000000
31.160002,12.992076,-125.258362,0.005575,0.001512,0.038401,57.791641,2.944046,0.384008,-125.258362,0.039589,0.000000
31.430002,13.362959,-125.169395,0.005601,0.001534,0.038973,59.441410,3.028090,0.389733,-125.169395,0.040040,0.000000
31.700001,13.251991,-125.124916,0.005622,0.001550,0.039363,58.947800,3.002944,0.393635,-125.124916,0.040482,0.000000
31.970001,13.276196,-125.035950,0.005661,0.001569,0.039858,59.055466,3.008429,0.398578,-125.035950,0.040933,0.000000
32.240002,13.135439,-124.902512,0.005683,0.001582,0.040179,58.429352,2.976533,0.401786,-124.902512,0.041384,0.000000
32.510002,13.411366,-124.946991,0.005691,0.001602,0.040699,59.656738,3.039059,0.406990,-124.946991,0.041835,0.000000
32.780003,13.578190,-124.813545,0.005734,0.001621,0.041185,60.398804,3.076862,0.411846,-124.813545,0.042286,0.000000
33.050003,13.659739,-124.813545,0.005769,0.001641,0.041688,60.761555,3.095341,0.416876,-124.813545,0.042737,0.000000
33.320000,13.771451,-124.680107,0.005799,0.001663,0.042234,61.258472,3.120656,0.422339,-124.680107,0.043188,0.000000
33.590000,13.641121,-124.724586,0.005833,0.001681,0.042685,60.678738,3.091122,0.426849,-124.724586,0.043639,0.000000
33.860001,13.375247,-124.591141,0.005851,0.001692,0.042980,59.496071,3.030874,0.429798,-124.591141,0.044090,0.000000
34.130001,13.449721,-124.546661,0.005877,0.001712,0.043474,59.827347,3.047750,0.434741,-124.546661,0.044541,0.000000
34.400002,13.656015,-124.413223,0.005920,0.001731,0.043960,60.744991,3.094497,0.439597,-124.413223,0.044983,0.000000
34.670002,13.513397,-124.368736,0.005933,0.001745,0.044315,60.110592,3.062180,0.443153,-124.368736,0.045434,0.000000
34.940002,13.253109,-124.279778,0.005954,0.001753,0.044523,58.952774,3.003197,0.445234,-124.279778,0.045885,0.000000
35.210003,13.994502,-124.279778,0.005984,0.001786,0.045356,62.250652,3.171200,0.453559,-124.279778,0.046336,0.000000
35.480003,13.830286,-124.235298,0.006028,0.001802,0.045781,61.520184,3.133988,0.457810,-124.235298,0.046787,0.000000
35.750000,13.713361,-124.146332,0.006053,0.001819,0.046206,61.000076,3.107492,0.462058,-124.146332,0.047238,0.000000
36.020000,13.769961,-124.057373,0.006092,0.001838,0.046691,61.251846,3.120318,0.466914,-124.057373,0.047689,0.000000
36.290001,13.767727,-123.968414,0.006114,0.001854,0.047090,61.241909,3.119812,0.470903,-123.968414,0.048140,0.000000
36.560001,13.636280,-123.923927,0.006135,0.001868,0.047455,60.657204,3.090025,0.474546,-123.923927,0.048591,0.000000
36.830002,13.777037,-123.923927,0.006174,0.001886,0.047906,61.283321,3.121921,0.479056,-123.923927,0.049033,0.000000
37.100002,13.878695,-123.790489,0.006200,0.001907,0.048435,61.735516,3.144957,0.484345,-123.790489,0.049484,0.000000
37.370003,14.151271,-123.701523,0.006243,0.001929,0.049007,62.947998,3.206724,0.490070,-123.701523,0.049935,0.000000
37.640003,13.990406,-123.612564,0.006260,0.001946,0.049441,62.232433,3.170271,0.494406,-123.612564,0.050386,0.000000
37.910004,14.045517,-123.568085,0.006269,0.001965,0.049900,62.477581,3.182760,0.499002,-123.568085,0.050837,0.000000
38.180000,13.857469,-123.523598,0.006299,0.001978,0.050230,61.641098,3.140147,0.502297,-123.523598,0.051288,0.000000
38.450001,13.922262,-123.479118,0.006321,0.001993,0.050620,61.929314,3.154830,0.506199,-123.479118,0.051739,0.000000
38.720001,14.038442,-123.390160,0.006368,0.002010,0.051045,62.446106,3.181156,0.510450,-123.390160,0.052190,0.000000
38.990002,14.486033,-123.301193,0.006398,0.002034,0.051661,64.437096,3.282582,0.516606,-123.301193,0.052641,0.000000
39.260002,14.351607,-123.256714,0.006420,0.002050,0.052060,63.839138,3.252121,0.520595,-123.256714,0.053083,0.000000
39.530003,14.322562,-123.212234,0.006450,0.002069,0.052554,63.709938,3.245539,0.525538,-123.212234,0.053534,0.000000
39.800003,14.194467,-123.078789,0.006476,0.002086,0.052979,63.140141,3.216512,0.529789,-123.078789,0.053985,0.000000
40.070004,14.460340,-123.034309,0.006523,0.002107,0.053517,64.322807,3.276760,0.535165,-123.034309,0.054436,0.000000
40.340000,14.282346,-122.900871,0.006536,0.002120,0.053846,63.531048,3.236426,0.538462,-122.900871,0.054887,0.000000
40.610001,14.260004,-122.900871,0.006562,0.002133,0.054184,63.431667,3.231363,0.541844,-122.900871,0.055338,0.000000
40.880001,14.179571,-122.811905,0.006584,0.002147,0.054540,63.073883,3.213137,0.545400,-122.811905,0.055789,0.000000
41.150002,14.765685,-122.811905,0.006622,0.002176,0.055268,65.681046,3.345952,0.552684,-122.811905,0.056240,0.000000
41.420002,14.793613,-122.633980,0.006640,0.002195,0.055763,65.805283,3.352281,0.557627,-122.633980,0.056691,0.000000
41.690002,14.598863,-122.589500,0.006666,0.002211,0.056153,64.938988,3.308150,0.561529,-122.589500,0.057142,0.000000
41.960003,14.584712,-122.500542,0.006700,0.002228,0.056595,64.876038,3.304943,0.565952,-122.500542,0.057584,0.000000
42.230003,14.552316,-122.545021,0.006726,0.002240,0.056899,64.731934,3.297602,0.568987,-122.545021,0.058035,0.000000
42.500004,14.725470,-122.456055,0.006748,0.002258,0.057358,65.502159,3.336839,0.573584,-122.456055,0.058486,0.000000
42.770000,14.628280,-122.367096,0.006756,0.002272,0.057705,65.069839,3.314816,0.577053,-122.367096,0.058937,0.000000
43.040001,15.054646,-122.233650,0.006791,0.002294,0.058278,66.966415,3.411432,0.582775,-122.233650,0.059388,0.000000
43.310001,15.390899,-122.189171,0.006817,0.002318,0.058885,68.462135,3.487627,0.588846,-122.189171,0.059839,0.000000
43.580002,15.175668,-122.144691,0.006851,0.002333,0.059258,67.504738,3.438855,0.592576,-122.144691,0.060290,0.000000
43.850002,15.233013,-122.189171,0.006881,0.002351,0.059726,67.759827,3.451850,0.597258,-122.189171,0.060741,0.000000
44.120003,15.199872,-122.055733,0.006911,0.002368,0.060142,67.612404,3.444340,0.601422,-122.055733,0.061192,0.000000
44.390003,14.943307,-121.922287,0.006916,0.002379,0.060420,66.471146,3.386202,0.604196,-121.922287,0.061634,0.000000
44.660004,15.104917,-121.922287,0.006946,0.002400,0.060957,67.190025,3.422823,0.609574,-121.922287,0.062085,0.000000
44.930000,15.692893,-121.833328,0.006972,0.002424,0.061582,69.805473,3.556061,0.615818,-121.833328,0.062536,0.000000
45.200001,15.509686,-121.788841,0.006989,0.002442,0.062015,68.990524,3.514545,0.620153,-121.788841,0.062987,0.000000
45.470001,15.523463,-121.699883,0.007028,0.002458,0.062440,69.051811,3.517667,0.624404,-121.699883,0.063438,0.000000
45.740002,15.769229,-121.566437,0.007036,0.002479,0.062961,70.145035,3.573358,0.629606,-121.566437,0.063889,0.000000
46.010002,15.551764,-121.566437,0.007071,0.002491,0.063282,69.177696,3.524080,0.632816,-121.566437,0.064340,0.000000
46.280003,15.571500,-121.477478,0.007062,0.002507,0.063672,69.265488,3.528552,0.636718,-121.477478,0.064790,0.000000
46.550003,16.087606,-121.477478,0.007118,0.002531,0.064296,71.561249,3.645504,0.642961,-121.477478,0.065241,0.000000
46.820004,16.200064,-121.344032,0.007136,0.002552,0.064825,72.061485,3.670987,0.648252,-121.344032,0.065692,0.000000
47.090004,16.005686,-121.255074,0.007153,0.002568,0.065233,71.196846,3.626940,0.652329,-121.255074,0.066135,0.000000
47.360001,15.994143,-121.255074,0.007179,0.002584,0.065632,71.145500,3.624325,0.656318,-121.255074,0.066586,0.000000
47.630001,16.230227,-121.166107,0.007205,0.002604,0.066152,72.195656,3.677822,0.661520,-121.166107,0.067037,0.000000
47.900002,16.229481,-121.166107,0.007217,0.002621,0.066568,72.192337,3.677653,0.665684,-121.166107,0.067488,0.000000
48.170002,16.250334,-120.988190,0.007243,0.002637,0.066967,72.285095,3.682378,0.669673,-120.988190,0.067938,0.000000
48.440002,16.567968,-120.988190,0.007265,0.002658,0.067514,73.698006,3.754355,0.675136,-120.988190,0.068389,0.000000
48.710003,16.469290,-120.943703,0.007282,0.002673,0.067895,73.259056,3.731994,0.678952,-120.943703,0.068840,0.000000
48.980003,16.419020,-120.854744,0.007312,0.002689,0.068303,73.035446,3.720603,0.683028,-120.854744,0.069291,0.000000
49.250004,16.644304,-120.810265,0.007325,0.002708,0.068780,74.037560,3.771653,0.687797,-120.810265,0.069742,0.000000
49.520000,16.328905,-120.721298,0.007347,0.002717,0.069022,72.634598,3.700183,0.690225,-120.721298,0.070185,0.000000
49.790001,16.747824,-120.632339,0.007373,0.002740,0.069595,74.498039,3.795111,0.695949,-120.632339,0.070636,0.000000
50.060001,16.903103,-120.587860,0.007386,0.002756,0.070011,75.188759,3.830298,0.700111,-120.587860,0.071087,0.000000
50.330002,17.048328,-120.543381,0.007407,0.002773,0.070445,75.834755,3.863207,0.704448,-120.543381,0.071538,0.000000
50.600002,17.460917,-120.498894,0.007416,0.002796,0.071026,77.670036,3.956700,0.710258,-120.498894,0.071989,0.000000
50.870003,17.410646,-120.365456,0.007459,0.002813,0.071459,77.446426,3.945309,0.714594,-120.365456,0.072439,0.000000
51.140003,17.269146,-120.276489,0.007480,0.002829,0.071867,76.817001,3.913244,0.718670,-120.276489,0.072890,0.000000
51.410004,17.199139,-120.232010,0.007511,0.002844,0.072240,76.505592,3.897380,0.722400,-120.232010,0.073341,0.000000
51.680004,17.297819,-120.143051,0.007519,0.002859,0.072622,76.944542,3.919742,0.726215,-120.143051,0.073792,0.000000
51.950001,17.617313,-120.143051,0.007541,0.002881,0.073168,78.365723,3.992140,0.731679,-120.143051,0.074235,0.000000
52.220001,17.542095,-120.098564,0.007558,0.002895,0.073532,78.031136,3.975096,0.735322,-120.098564,0.074685,0.000000
52.490002,17.476929,-119.920647,0.007588,0.002913,0.073983,77.741264,3.960329,0.739832,-119.920647,0.075136,0.000000
52.760002,17.980749,-119.876160,0.007606,0.002934,0.074512,79.982368,4.074496,0.745121,-119.876160,0.075587,0.000000
53.030003,17.864569,-119.876160,0.007610,0.002947,0.074859,79.465569,4.048169,0.748590,-119.876160,0.076038,0.000000
53.300003,17.984472,-119.787201,0.007649,0.002967,0.075371,79.998932,4.075340,0.753707,-119.787201,0.076489,0.000000
53.570004,17.823980,-119.742722,0.007675,0.002980,0.075683,79.285027,4.038972,0.756828,-119.742722,0.076940,0.000000
53.840004,18.285351,-119.609276,0.007683,0.003001,0.076229,81.337303,4.143519,0.762291,-119.609276,0.077391,0.000000
54.110004,18.581758,-119.609276,0.007705,0.003020,0.076715,82.655792,4.210687,0.767149,-119.609276,0.077842,0.000000
54.380001,18.793266,-119.475838,0.007739,0.003041,0.077244,83.596626,4.258615,0.772438,-119.475838,0.078293,0.000000
54.650002,19.030094,-119.431351,0.007756,0.003063,0.077799,84.650085,4.312281,0.777989,-119.431351,0.078735,0.000000
54.920002,18.830132,-119.386871,0.007782,0.003079,0.078215,83.760605,4.266969,0.782150,-119.386871,0.079186,0.000000
55.190002,18.453291,-119.297913,0.007795,0.003092,0.078536,82.084335,4.181575,0.785360,-119.297913,0.079637,0.000000
55.460003,18.415680,-119.208946,0.007804,0.003107,0.078926,81.917038,4.173052,0.789262,-119.208946,0.080088,0.000000
55.730003,18.928438,-119.164467,0.007838,0.003129,0.079473,84.197899,4.289245,0.794726,-119.164467,0.080539,0.000000
56.000004,18.887848,-119.164467,0.007864,0.003145,0.079871,84.017342,4.280047,0.798715,-119.164467,0.080990,0.000000
56.270004,18.571333,-119.075508,0.007899,0.003156,0.080158,82.609413,4.208324,0.801576,-119.075508,0.081441,0.000000
56.540001,19.612858,-118.897583,0.007912,0.003184,0.080878,87.242348,4.444337,0.808775,-118.897583,0.081892,0.000000
56.810001,19.515297,-118.853104,0.007933,0.003201,0.081311,86.808372,4.422229,0.813111,-118.853104,0.082343,0.000000
57.080002,19.460186,-118.897583,0.007959,0.003219,0.081762,86.563232,4.409741,0.817621,-118.897583,0.082785,0.000000
57.350002,19.499657,-118.808617,0.007976,0.003236,0.082187,86.738808,4.418685,0.821871,-118.808617,0.083236,0.000000
57.620003,19.671320,-118.764137,0.008011,0.003252,0.082603,87.502403,4.457585,0.826033,-118.764137,0.083687,0.000000
57.890003,19.612486,-118.630699,0.008015,0.003267,0.082993,87.240692,4.444253,0.829935,-118.630699,0.084138,0.000000
58.160004,19.885435,-118.586212,0.008037,0.003286,0.083453,88.454834,4.506104,0.834531,-118.586212,0.084589,0.000000
58.430004,20.302492,-118.541733,0.008067,0.003308,0.084017,90.309998,4.600610,0.840169,-118.541733,0.085040,0.000000
58.700005,20.569111,-118.541733,0.008075,0.003328,0.084529,91.495972,4.661027,0.845286,-118.541733,0.085491,0.000000
58.970001,20.486816,-118.408295,0.008110,0.003346,0.084979,91.129913,4.642379,0.849794,-118.408295,0.085942,0.000000
59.240002,20.641724,-118.274849,0.008127,0.003363,0.085422,91.818970,4.677481,0.854219,-118.274849,0.086393,0.000000
59.510002,20.390743,-118.274849,0.008119,0.003376,0.085743,90.702553,4.620608,0.857426,-118.274849,0.086835,0.000000
59.780003,20.298767,-118.185890,0.008144,0.003391,0.086124,90.293427,4.599767,0.861242,-118.185890,0.087286,0.000000
60.050003,20.871105,-118.141403,0.008183,0.003408,0.086567,92.839310,4.729460,0.865666,-118.141403,0.087737,0.000000
60.320004,21.583826,-118.007965,0.008201,0.003433,0.087191,96.009651,4.890965,0.871909,-118.007965,0.088188,0.000000
60.590004,21.576750,-117.963486,0.008222,0.003448,0.087572,95.978180,4.889361,0.875724,-117.963486,0.088639,0.000000
60.860004,21.749531,-117.963486,0.008244,0.003468,0.088075,96.746742,4.928514,0.880755,-117.963486,0.089090,0.000000
61.130001,21.803152,-117.830040,0.008257,0.003485,0.088526,96.985268,4.940665,0.885264,-117.830040,0.089541,0.000000
61.400002,22.163982,-117.830040,0.008295,0.003505,0.089021,98.590317,5.022430,0.890207,-117.830040,0.089992,0.000000
61.670002,21.981892,-117.741081,0.008317,0.003518,0.089368,97.780334,4.981168,0.893676,-117.741081,0.090443,0.000000
61.940002,22.059717,-117.652115,0.008334,0.003532,0.089706,98.126526,4.998803,0.897058,-117.652115,0.090894,0.000000
62.210003,22.082804,-117.607635,0.008334,0.003547,0.090088,98.229218,5.004035,0.900875,-117.607635,0.091336,0.000000
62.480003,23.100126,-117.563156,0.008356,0.003574,0.090781,102.754494,5.234564,0.907813,-117.563156,0.091787,0.000000
62.750004,23.427441,-117.474190,0.008395,0.003594,0.091293,104.210457,5.308734,0.912930,-117.474190,0.092238,0.000000
63.020004,23.380896,-117.385231,0.008412,0.003610,0.091683,104.003418,5.298186,0.916832,-117.385231,0.092689,0.000000
63.290005,23.402864,-117.296265,0.008407,0.003627,0.092125,104.101143,5.303165,0.921255,-117.296265,0.093140,0.000000
63.560001,23.446432,-117.296265,0.008442,0.003639,0.092420,104.294937,5.313037,0.924203,-117.296265,0.093591,0.000000
63.830002,23.848967,-117.162827,0.008464,0.003658,0.092923,106.085503,5.404253,0.929233,-117.162827,0.094042,0.000000
64.100006,23.867212,-117.207306,0.008468,0.003671,0.093253,106.166664,5.408388,0.932528,-117.207306,0.094493,0.000000
64.370003,24.634300,-117.073860,0.008515,0.003694,0.093825,109.578842,5.582212,0.938253,-117.073860,0.094944,0.000000
64.639999,25.296379,-116.984901,0.008520,0.003717,0.094415,112.523911,5.732241,0.944150,-116.984901,0.095386,0.000000
64.910004,25.321327,-116.895943,0.008528,0.003732,0.094796,112.634888,5.737895,0.947965,-116.895943,0.095837,0.000000
65.180000,25.633003,-116.851456,0.008563,0.003750,0.095247,114.021294,5.808522,0.952474,-116.851456,0.096288,0.000000
65.450005,25.778229,-116.851456,0.008593,0.003766,0.095664,114.667290,5.841430,0.956638,-116.851456,0.096739,0.000000
65.720001,25.462084,-116.762497,0.008593,0.003776,0.095915,113.261009,5.769791,0.959153,-116.762497,0.097190,0.000000
65.990005,26.199755,-116.629051,0.008610,0.003802,0.096583,116.542328,5.936949,0.965829,-116.629051,0.097641,0.000000
66.260002,27.197340,-116.540092,0.008623,0.003823,0.097103,120.979813,6.163005,0.971034,-116.540092,0.098092,0.000000
66.530006,27.113928,-116.540092,0.008649,0.003839,0.097502,120.608772,6.144104,0.975023,-116.540092,0.098543,0.000000
66.800003,27.628176,-116.540092,0.008679,0.003857,0.097970,122.896263,6.260634,0.979705,-116.540092,0.098994,0.000000
67.070000,28.241472,-116.451126,0.008683,0.003878,0.098500,125.624344,6.399609,0.984996,-116.451126,0.099436,0.000000
67.340004,28.111515,-116.317688,0.008696,0.003890,0.098794,125.046265,6.370161,0.987945,-116.317688,0.099887,0.000000
67.610001,28.202002,-116.228722,0.008722,0.003905,0.099185,125.448769,6.390665,0.991847,-116.228722,0.100338,0.000000
67.880005,29.369017,-116.228722,0.008727,0.003930,0.099818,130.639908,6.655114,0.998177,-116.228722,0.100789,0.000000
68.150002,30.034447,-116.228722,0.008752,0.003952,0.100373,133.599884,6.805903,1.003728,-116.228722,0.101240,0.000000
68.420006,30.142807,-116.095284,0.008778,0.003968,0.100780,134.081909,6.830458,1.007804,-116.095284,0.101691,0.000000
68.690002,30.425810,-115.961838,0.008795,0.003984,0.101188,135.340759,6.894587,1.011880,-115.961838,0.102142,0.000000
68.960007,31.037617,-115.917358,0.008804,0.004004,0.101691,138.062210,7.033225,1.016909,-115.917358,0.102593,0.000000
69.230003,31.367912,-115.961838,0.008821,0.004020,0.102107,139.531448,7.108070,1.021072,-115.961838,0.103044,0.000000
69.500000,31.580536,-115.828400,0.008839,0.004034,0.102463,140.477234,7.156251,1.024628,-115.828400,0.103495,0.000000
69.770004,32.497688,-115.739433,0.008847,0.004057,0.103044,144.556931,7.364081,1.030438,-115.739433,0.103937,0.000000
70.040001,32.797821,-115.694954,0.008856,0.004073,0.103460,145.891998,7.432092,1.034601,-115.694954,0.104388,0.000000
70.310005,33.121784,-115.605995,0.008899,0.004090,0.103885,147.333054,7.505504,1.038850,-115.605995,0.104839,0.000000
70.580002,33.776417,-115.605995,0.008912,0.004107,0.104319,150.245010,7.653845,1.043187,-115.605995,0.105290,0.000000
70.850006,33.709389,-115.428070,0.008925,0.004117,0.104579,149.946854,7.638657,1.045787,-115.428070,0.105741,0.000000
71.120003,34.519669,-115.472549,0.008921,0.004138,0.105099,153.551147,7.822269,1.050992,-115.472549,0.106192,0.000000
71.390007,35.226807,-115.339104,0.008933,0.004155,0.105533,156.696655,7.982508,1.055327,-115.339104,0.106643,0.000000
71.660004,35.863934,-115.294624,0.008964,0.004172,0.105966,159.530746,8.126884,1.059663,-115.294624,0.107094,0.000000
71.930000,37.029835,-115.205666,0.008977,0.004197,0.106599,164.716934,8.391081,1.065995,-115.205666,0.107545,0.000000
72.200005,37.609615,-115.161179,0.008977,0.004213,0.107016,167.295929,8.522461,1.070156,-115.161179,0.107987,0.000000
72.470001,37.879959,-115.072220,0.009002,0.004229,0.107423,168.498474,8.583722,1.074233,-115.072220,0.108438,0.000000
72.740005,38.227757,-114.983261,0.009024,0.004243,0.107770,170.045547,8.662533,1.077702,-114.983261,0.108889,0.000000
73.010002,38.781101,-114.894295,0.009015,0.004258,0.108143,172.506958,8.787923,1.081432,-114.894295,0.109340,0.000000
73.280006,39.939178,-114.938774,0.009054,0.004281,0.108742,177.658340,9.050347,1.087415,-114.938774,0.109791,0.000000
73.550003,40.273197,-114.805336,0.009063,0.004295,0.109088,179.144135,9.126037,1.090884,-114.805336,0.110242,0.000000
73.820000,41.190350,-114.805336,0.009089,0.004314,0.109583,183.223831,9.333866,1.095827,-114.805336,0.110693,0.000000
74.090004,42.031914,-114.716370,0.009097,0.004334,0.110077,186.967285,9.524568,1.100770,-114.716370,0.111144,0.000000
74.360001,42.587494,-114.671890,0.009110,0.004351,0.110519,189.438629,9.650464,1.105193,-114.671890,0.111595,0.000000
74.630005,43.577629,-114.538452,0.009106,0.004370,0.110987,193.842972,9.874832,1.109875,-114.538452,0.112037,0.000000
74.900002,43.959312,-114.538452,0.009115,0.004383,0.111335,195.540787,9.961323,1.113346,-114.538452,0.112488,0.000000
75.170006,44.776299,-114.493965,0.009140,0.004400,0.111751,199.174927,10.146454,1.117507,-114.493965,0.112939,0.000000
75.440002,45.811867,-114.316048,0.009153,0.004419,0.112236,203.781357,10.381118,1.122363,-114.316048,0.113390,0.000000
75.710007,46.845200,-114.271561,0.009166,0.004440,0.112765,208.377853,10.615274,1.127655,-114.271561,0.113841,0.000000
75.980003,48.126904,-114.227081,0.009171,0.004461,0.113321,214.079163,10.905713,1.133205,-114.227081,0.114292,0.000000
76.250000,48.750999,-114.227081,0.009205,0.004478,0.113737,216.855270,11.047134,1.137367,-114.227081,0.114743,0.000000
76.520004,48.951710,-114.182602,0.009209,0.004491,0.114066,217.748077,11.092616,1.140663,-114.182602,0.115194,0.000000
76.790001,49.893440,-114.049156,0.009218,0.004511,0.114587,221.937103,11.306015,1.145866,-114.049156,0.115645,0.000000
77.060005,51.039600,-114.004677,0.009218,0.004529,0.115046,227.035477,11.565739,1.150462,-114.004677,0.116096,0.000000
77.330002,51.651783,-113.960197,0.009235,0.004545,0.115445,229.758606,11.704461,1.154452,-113.960197,0.116538,0.000000
77.600006,52.150017,-113.826752,0.009253,0.004560,0.115827,231.974854,11.817362,1.158267,-113.826752,0.116989,0.000000
77.870003,54.025658,-113.826752,0.009270,0.004583,0.116399,240.318130,12.242389,1.163991,-113.826752,0.117440,0.000000
78.140007,54.845623,-113.737793,0.009274,0.004600,0.116841,243.965515,12.428196,1.168414,-113.737793,0.117891,0.000000
78.410004,55.678619,-113.648827,0.009278,0.004618,0.117310,247.670868,12.616955,1.173096,-113.648827,0.118342,0.000000
78.680000,56.624073,-113.604347,0.009304,0.004636,0.117752,251.876450,12.831199,1.177519,-113.604347,0.118793,0.000000
78.950005,57.565056,-113.559868,0.009309,0.004653,0.118177,256.062164,13.044428,1.181769,-113.559868,0.119243,0.000000
79.220001,58.291927,-113.515388,0.009313,0.004667,0.118533,259.295441,13.209139,1.185325,-113.515388,0.119694,0.000000
79.490005,59.315578,-113.381943,0.009330,0.004684,0.118975,263.848877,13.441103,1.189748,-113.381943,0.120145,0.000000
79.760002,60.757408,-113.292984,0.009330,0.004707,0.119556,270.262451,13.767825,1.195557,-113.292984,0.120588,0.000000
80.030006,62.087147,-113.292984,0.009334,0.004727,0.120059,276.177429,14.069148,1.200588,-113.292984,0.121039,0.000000
80.300003,62.994621,-113.204018,0.009334,0.004744,0.120510,280.214081,14.274785,1.205097,-113.204018,0.121490,0.000000
80.570007,64.278938,-113.159538,0.009365,0.004763,0.120969,285.927002,14.565815,1.209694,-113.159538,0.121941,0.000000
80.840004,64.793556,-113.070580,0.009365,0.004774,0.121264,288.216125,14.682429,1.212643,-113.070580,0.122392,0.000000
81.110001,65.431427,-113.026100,0.009373,0.004790,0.121663,291.053528,14.826973,1.216632,-113.026100,0.122843,0.000000
81.380005,66.829315,-112.981613,0.009378,0.004807,0.122097,297.271637,15.143739,1.220967,-112.981613,0.123294,0.000000
81.650002,67.369629,-112.892654,0.009408,0.004811,0.122210,299.675079,15.266175,1.222095,-112.892654,0.122444,0.000000
81.920006,66.669197,-112.848175,0.009390,0.004811,0.122210,296.559387,15.107456,1.222095,-112.848175,0.122444,0.000000
82.190002,66.087921,-112.803696,0.009403,0.004807,0.122097,293.973755,14.975738,1.220967,-112.803696,0.122210,0.000000
82.460007,65.563248,-112.759209,0.009408,0.004806,0.122062,291.639893,14.856845,1.220621,-112.759209,0.122210,0.000000
82.730003,65.077675,-112.670250,0.009399,0.004805,0.122053,289.479950,14.746812,1.220534,-112.670250,0.122210,0.000000
83.000008,64.676628,-112.625771,0.009425,0.004805,0.122045,287.696014,14.655933,1.220447,-112.625771,0.122210,0.000000
83.270004,64.296432,-112.536804,0.009412,0.004805,0.122045,286.004822,14.569780,1.220447,-112.536804,0.122210,0.000000
83.540001,63.994068,-112.358879,0.009429,0.004805,0.122036,284.659821,14.501264,1.220360,-112.358879,0.122210,0.000000
83.810005,63.690956,-112.314400,0.009412,0.004805,0.122036,283.311523,14.432577,1.220360,-112.314400,0.122210,0.000000
84.080002,63.421360,-112.314400,0.009429,0.004805,0.122036,282.112305,14.371486,1.220360,-112.314400,0.122210,0.000000
84.350006,63.175594,-112.269920,0.009425,0.004804,0.122027,281.019073,14.315794,1.220275,-112.269920,0.122210,0.000000
84.620003,62.937649,-112.180962,0.009429,0.004804,0.122027,279.960632,14.261874,1.220275,-112.180962,0.122210,0.000000
84.890007,62.735821,-112.136475,0.009434,0.004804,0.122027,279.062866,14.216141,1.220275,-112.136475,0.122210,0.000000
85.160004,62.542931,-112.047516,0.009429,0.004804,0.122027,278.204865,14.172430,1.220275,-112.047516,0.122210,0.000000
85.430000,62.360470,-112.047516,0.009425,0.004804,0.122019,277.393219,14.131084,1.220188,-112.047516,0.122210,0.000000
85.700005,62.183964,-112.003036,0.009434,0.004804,0.122019,276.608093,14.091088,1.220188,-112.003036,0.122210,0.000000
85.970001,62.017513,-111.869591,0.009429,0.004804,0.122019,275.867676,14.053369,1.220188,-111.869591,0.122210,0.000000
86.240005,61.880108,-111.736153,0.009447,0.004804,0.122019,275.256470,14.022233,1.220188,-111.736153,0.122210,0.000000
86.510002,61.724087,-111.736153,0.009421,0.004804,0.122019,274.562439,13.986877,1.220188,-111.736153,0.122210,0.000000
86.780006,61.604183,-111.736153,0.009442,0.004804,0.122019,274.029083,13.959708,1.220188,-111.736153,0.122210,0.000000
87.050003,61.459702,-111.602707,0.009451,0.004804,0.122019,273.386414,13.926968,1.220188,-111.602707,0.122210,0.000000
87.320007,61.356552,-111.602707,0.009447,0.004804,0.122019,272.927582,13.903593,1.220188,-111.602707,0.122210,0.000000
87.590004,61.224361,-111.469261,0.009442,0.004804,0.122019,272.339569,13.873639,1.220188,-111.469261,0.122210,0.000000
87.860001,61.120098,-111.335823,0.009447,0.004804,0.122019,271.875763,13.850013,1.220188,-111.335823,0.122210,0.000000
88.130005,61.020302,-111.335823,0.009438,0.004804,0.122019,271.431854,13.827398,1.220188,-111.335823,0.122210,0.000000
88.400002,60.914547,-111.335823,0.009447,0.004804,0.122019,270.961426,13.803434,1.220188,-111.335823,0.122210,0.000000
88.670006,60.818104,-111.246857,0.009442,0.004804,0.122010,270.532440,13.781579,1.220101,-111.246857,0.122210,0.000000
88.940002,60.710114,-111.157898,0.009455,0.004804,0.122010,270.052063,13.757109,1.220101,-111.157898,0.122210,0.000000
89.210007,60.629311,-111.113419,0.009447,0.004804,0.122010,269.692657,13.738798,1.220101,-111.113419,0.122210,0.000000
89.480003,60.536217,-111.024452,0.009459,0.004804,0.122010,269.278534,13.717703,1.220101,-111.024452,0.122210,0.000000
89.750008,60.451317,-110.979973,0.009451,0.004804,0.122010,268.900879,13.698463,1.220101,-110.979973,0.122210,0.000000
90.020004,60.383915,-110.891014,0.009447,0.004804,0.122010,268.601074,13.683190,1.220101,-110.891014,0.122210,0.000000
90.290001,60.300507,-110.757568,0.009451,0.004804,0.122010,268.230042,13.664289,1.220101,-110.757568,0.122210,0.000000
90.560005,60.231987,-110.802048,0.009447,0.004804,0.122010,267.925262,13.648763,1.220101,-110.802048,0.122210,0.000000
90.830002,60.151184,-110.757568,0.009451,0.004804,0.122010,267.565826,13.630453,1.220101,-110.757568,0.122210,0.000000
91.100006,60.077827,-110.668610,0.009442,0.004804,0.122010,267.239532,13.613831,1.220101,-110.668610,0.122210,0.000000
91.370003,60.011543,-110.624123,0.009442,0.004804,0.122010,266.944672,13.598810,1.220101,-110.624123,0.122210,0.000000
91.640007,59.945633,-110.490685,0.009459,0.004804,0.122010,266.651489,13.583875,1.220101,-110.490685,0.122210,0.000000
91.910004,59.900578,-110.490685,0.009459,0.004804,0.122010,266.451080,13.573665,1.220101,-110.490685,0.122210,0.000000
92.180008,59.809345,-110.446205,0.009455,0.004804,0.122010,266.045258,13.552991,1.220101,-110.446205,0.122210,0.000000
92.450005,59.763546,-110.312759,0.009447,0.004804,0.122010,265.841522,13.542613,1.220101,-110.312759,0.122210,0.000000
92.720001,59.689072,-110.268280,0.009472,0.004804,0.122010,265.510254,13.525737,1.220101,-110.268280,0.122210,0.000000
92.990005,59.629864,-110.134834,0.009464,0.004804,0.122010,265.246887,13.512320,1.220101,-110.134834,0.122210,0.000000
93.260002,59.576984,-110.090355,0.009464,0.004804,0.122010,265.011658,13.500338,1.220101,-110.090355,0.122210,0.000000
93.530006,59.523735,-110.090355,0.009455,0.004804,0.122010,264.774811,13.488272,1.220101,-110.090355,0.122210,0.000000
93.800003,59.474583,-110.045876,0.009447,0.004804,0.122010,264.556152,13.477133,1.220101,-110.045876,0.122210,0.000000
94.070007,59.417984,-109.912430,0.009468,0.004804,0.122010,264.304382,13.464308,1.220101,-109.912430,0.122210,0.000000
94.340004,59.379257,-109.823471,0.009442,0.004804,0.122010,264.132141,13.455532,1.220101,-109.823471,0.122210,0.000000
94.610008,59.312229,-109.823471,0.009442,0.004804,0.122010,263.833984,13.440344,1.220101,-109.823471,0.122210,0.000000
94.880005,59.273876,-109.778984,0.009438,0.004804,0.122010,263.663361,13.431652,1.220101,-109.778984,0.122210,0.000000
95.150002,59.226212,-109.645546,0.009468,0.004804,0.122010,263.451355,13.420852,1.220101,-109.645546,0.122210,0.000000
95.420006,59.181152,-109.645546,0.009447,0.004804,0.122010,263.250916,13.410641,1.220101,-109.645546,0.122210,0.000000
95.690002,59.139076,-109.512100,0.009438,0.004804,0.122010,263.063751,13.401106,1.220101,-109.512100,0.122210,0.000000
95.960007,59.096996,-109.512100,0.009455,0.004804,0.122010,262.876556,13.391571,1.220101,-109.512100,0.122210,0.000000
96.230003,59.049706,-109.467621,0.009442,0.004804,0.122010,262.666199,13.380855,1.220101,-109.467621,0.122210,0.000000
96.500008,58.997574,-109.423141,0.009459,0.004804,0.122010,262.434326,13.369040,1.220101,-109.423141,0.122210,0.000000
96.770004,58.971508,-109.289696,0.009459,0.004804,0.122010,262.318359,13.363134,1.220101,-109.289696,0.122210,0.000000
97.040001,58.932037,-109.200737,0.009459,0.004804,0.122010,262.142792,13.354191,1.220101,-109.200737,0.122210,0.000000
97.310005,58.885117,-109.200737,0.009451,0.004804,0.122010,261.934082,13.343557,1.220101,-109.200737,0.122210,0.000000
97.580002,58.853092,-109.156258,0.009459,0.004804,0.122010,261.791626,13.336302,1.220101,-109.156258,0.122210,0.000000
97.850006,58.809898,-109.067291,0.009459,0.004804,0.122010,261.599487,13.326513,1.220101,-109.067291,0.122210,0.000000
98.120003,58.776756,-108.978333,0.009464,0.004804,0.122010,261.452057,13.319003,1.220101,-108.978333,0.122210,0.000000
98.390007,58.730957,-108.889366,0.009459,0.004804,0.122010,261.248352,13.308625,1.220101,-108.889366,0.122210,0.000000
98.660004,58.694462,-108.933846,0.009442,0.004804,0.122010,261.085999,13.300356,1.220101,-108.933846,0.122210,0.000000
98.930008,58.658714,-108.800407,0.009442,0.004804,0.122010,260.927002,13.292254,1.220101,-108.800407,0.122210,0.000000
99.200005,58.627438,-108.711441,0.009447,0.004804,0.122010,260.787872,13.285168,1.220101,-108.711441,0.122210,0.000000
99.470001,58.593178,-108.666962,0.009459,0.004804,0.122010,260.635468,13.277405,1.220101,-108.666962,0.122210,0.000000
99.740005,58.558548,-108.533524,0.009447,0.004804,0.122010,260.481445,13.269557,1.220101,-108.533524,0.122210,0.000000
100.010002,58.527641,-108.533524,0.009451,0.004804,0.122010,260.343964,13.262553,1.220101,-108.533524,0.122210,0.000000
100.280006,58.489658,-108.533524,0.009455,0.004804,0.122010,260.174988,13.253945,1.220101,-108.533524,0.122210,0.000000
100.550003,58.474762,-108.400078,0.009468,0.004804,0.122010,260.108734,13.250570,1.220101,-108.400078,0.122210,0.000000
100.820007,58.430824,-108.355598,0.009464,0.004804,0.122010,259.913300,13.240614,1.220101,-108.355598,0.122210,0.000000
101.090004,58.406620,-108.266632,0.009477,0.004804,0.122010,259.805634,13.235128,1.220101,-108.266632,0.122210,0.000000
101.360008,58.369381,-108.266632,0.009468,0.004804,0.122010,259.639984,13.226690,1.220101,-108.266632,0.122210,0.000000
101.630005,58.332890,-108.177673,0.009455,0.004804,0.122010,259.477661,13.218422,1.220101,-108.177673,0.122210,0.000000
101.900002,58.319855,-108.088715,0.009477,0.004804,0.122010,259.419678,13.215467,1.220101,-108.088715,0.122210,0.000000
102.170006,58.298630,-108.044228,0.009477,0.004804,0.122010,259.325256,13.210658,1.220101,-108.044228,0.122210,0.000000
102.440002,58.257671,-107.910789,0.009464,0.004804,0.122010,259.143066,13.201377,1.220101,-107.910789,0.122210,0.000000
102.710007,58.223785,-107.866310,0.009438,0.004804,0.122010,258.992340,13.193699,1.220101,-107.866310,0.122210,0.000000
102.980003,58.197346,-107.866310,0.009472,0.004804,0.122010,258.874725,13.187707,1.220101,-107.866310,0.122210,0.000000
103.250008,58.168301,-107.821823,0.009481,0.004804,0.122010,258.745514,13.181125,1.220101,-107.821823,0.122210,0.000000
103.520004,58.149681,-107.688385,0.009464,0.004804,0.122010,258.662689,13.176907,1.220101,-107.688385,0.122210,0.000000
103.790009,58.113564,-107.643898,0.009451,0.004804,0.122010,258.502045,13.168722,1.220101,-107.643898,0.122210,0.000000
104.060005,58.087498,-107.643898,0.009451,0.004804,0.122010,258.386108,13.162815,1.220101,-107.643898,0.122210,0.000000
104.330002,58.066269,-107.554939,0.009468,0.004804,0.122010,258.291656,13.158004,1.220101,-107.554939,0.122210,0.000000
104.600006,58.033501,-107.421494,0.009459,0.004804,0.122010,258.145905,13.150578,1.220101,-107.421494,0.122210,0.000000
104.870003,58.005947,-107.421494,0.009455,0.004804,0.122010,258.023346,13.144336,1.220101,-107.421494,0.122210,0.000000
105.140007,57.987701,-107.332535,0.009459,0.004804,0.122010,257.942169,13.140202,1.220101,-107.332535,0.122210,0.000000
105.410004,57.963497,-107.332535,0.009451,0.004804,0.122010,257.834503,13.134716,1.220101,-107.332535,0.122210,0.000000
105.680008,57.934078,-107.199089,0.009468,0.004804,0.122010,257.703644,13.128050,1.220101,-107.199089,0.122210,0.000000
105.950005,57.902798,-107.199089,0.009464,0.004804,0.122010,257.564514,13.120961,1.220101,-107.199089,0.122210,0.000000
106.220009,57.877850,-107.110130,0.009477,0.004804,0.122010,257.453522,13.115309,1.220101,-107.110130,0.122210,0.000000
106.490005,57.861839,-107.021172,0.009481,0.004804,0.122010,257.382324,13.111681,1.220101,-107.021172,0.122210,0.000000
106.760002,57.849548,-107.021172,0.009468,0.004804,0.122010,257.327637,13.108895,1.220101,-107.021172,0.122210,0.000000
107.030006,57.801888,-106.976685,0.009468,0.004804,0.122010,257.115631,13.098095,1.220101,-106.976685,0.122210,0.000000
107.300003,57.818272,-106.887726,0.009468,0.004804,0.122010,257.188507,13.101808,1.220101,-106.887726,0.122210,0.000000
107.570007,57.780289,-106.709801,0.009472,0.004804,0.122010,257.019562,13.093201,1.220101,-106.709801,0.122210,0.000000
107.840004,57.757202,-106.665321,0.009455,0.004804,0.122010,256.916870,13.087969,1.220101,-106.665321,0.122210,0.000000
108.110008,57.720711,-106.665321,0.009481,0.004804,0.122010,256.754547,13.079700,1.220101,-106.665321,0.122210,0.000000
108.380005,57.709164,-106.665321,0.009477,0.004804,0.122010,256.703186,13.077084,1.220101,-106.665321,0.122210,0.000000
108.650002,57.685707,-106.531876,0.009464,0.004804,0.122010,256.598846,13.071769,1.220101,-106.531876,0.122210,0.000000
108.920006,57.649586,-106.442917,0.009468,0.004804,0.122010,256.438171,13.063583,1.220101,-106.442917,0.122210,0.000000
109.190002,57.638786,-106.398437,0.009494,0.004804,0.122010,256.390137,13.061135,1.220101,-106.398437,0.122210,0.000000
109.460007,57.606392,-106.309471,0.009455,0.004804,0.122010,256.246033,13.053795,1.220101,-106.309471,0.122210,0.000000
109.730003,57.600060,-106.309471,0.009464,0.004804,0.122010,256.217865,13.052361,1.220101,-106.309471,0.122210,0.000000
110.000008,57.557610,-106.264992,0.009481,0.004804,0.122010,256.029022,13.042741,1.220101,-106.264992,0.122210,0.000000
110.270004,57.555374,-106.087067,0.009468,0.004804,0.122010,256.019104,13.042234,1.220101,-106.087067,0.122210,0.000000
110.540009,57.540108,-106.087067,0.009464,0.004804,0.122010,255.951187,13.038774,1.220101,-106.087067,0.122210,0.000000
110.810005,57.517021,-106.131546,0.009464,0.004804,0.122010,255.848495,13.033544,1.220101,-106.131546,0.122210,0.000000
111.080002,57.496540,-105.998108,0.009459,0.004804,0.122010,255.757385,13.028902,1.220101,-105.998108,0.122210,0.000000
111.350006,57.505478,-105.909142,0.009481,0.004804,0.122010,255.797134,13.030928,1.220101,-105.909142,0.122210,0.000000
111.620003,57.450367,-105.820183,0.009468,0.004804,0.122010,255.552002,13.018439,1.220101,-105.820183,0.122210,0.000000
111.890007,57.440685,-105.775703,0.009459,0.004804,0.122010,255.508926,13.016246,1.220101,-105.775703,0.122210,0.000000
112.000008,57.413876,-105.731224,0.009472,0.004804,0.122010,255.389679,13.010170,1.220101,-105.731224,0.122210,0.000000